setblock ~172 ~122 ~80 dirt
setblock ~172 ~122 ~81 dirt
setblock ~172 ~122 ~82 dirt
setblock ~172 ~122 ~101 dirt
setblock ~172 ~122 ~102 dirt
setblock ~172 ~122 ~103 dirt
setblock ~172 ~122 ~104 dirt
setblock ~172 ~122 ~105 dirt
setblock ~172 ~122 ~106 dirt
setblock ~172 ~122 ~107 dirt
setblock ~172 ~122 ~108 dirt
setblock ~172 ~122 ~137 dirt
setblock ~172 ~122 ~138 dirt
setblock ~172 ~122 ~139 dirt
setblock ~172 ~122 ~140 dirt
setblock ~172 ~122 ~141 dirt
setblock ~172 ~123 ~73 dirt
setblock ~172 ~123 ~74 dirt
setblock ~172 ~123 ~75 dirt
setblock ~172 ~123 ~76 dirt
setblock ~172 ~123 ~77 dirt
setblock ~172 ~123 ~78 dirt
setblock ~172 ~123 ~79 dirt
setblock ~172 ~123 ~80 dirt
setblock ~172 ~123 ~81 dirt
setblock ~172 ~123 ~82 dirt
setblock ~172 ~123 ~101 dirt
setblock ~172 ~123 ~102 dirt
setblock ~172 ~123 ~103 dirt
setblock ~172 ~123 ~104 dirt
setblock ~172 ~123 ~105 dirt
setblock ~172 ~123 ~106 dirt
setblock ~172 ~123 ~107 dirt
setblock ~172 ~123 ~108 dirt
setblock ~172 ~123 ~137 dirt
setblock ~172 ~123 ~138 dirt
setblock ~172 ~123 ~139 dirt
setblock ~172 ~123 ~140 dirt
setblock ~172 ~123 ~141 dirt
setblock ~172 ~124 ~73 dirt
setblock ~172 ~124 ~74 dirt
setblock ~172 ~124 ~75 dirt
setblock ~172 ~124 ~76 dirt
setblock ~172 ~124 ~77 dirt
setblock ~172 ~124 ~78 dirt
setblock ~172 ~124 ~79 dirt
setblock ~172 ~124 ~80 dirt
setblock ~172 ~124 ~81 dirt
setblock ~172 ~124 ~82 dirt
setblock ~172 ~124 ~101 grass_block
setblock ~172 ~124 ~102 dirt
setblock ~172 ~124 ~103 dirt
setblock ~172 ~124 ~104 dirt
setblock ~172 ~124 ~105 dirt
setblock ~172 ~124 ~106 dirt
setblock ~172 ~124 ~107 dirt
setblock ~172 ~124 ~108 dirt
setblock ~172 ~124 ~137 dirt
setblock ~172 ~124 ~138 dirt
setblock ~172 ~124 ~139 dirt
setblock ~172 ~124 ~140 dirt
setblock ~172 ~124 ~141 dirt
setblock ~172 ~125 ~73 grass_block
setblock ~172 ~125 ~74 grass_block
setblock ~172 ~125 ~75 dirt
setblock ~172 ~125 ~76 dirt
setblock ~172 ~125 ~77 dirt
setblock ~172 ~125 ~78 dirt
setblock ~172 ~125 ~79 dirt
setblock ~172 ~125 ~80 dirt
setblock ~172 ~125 ~81 dirt
setblock ~172 ~125 ~82 dirt
setblock ~172 ~125 ~102 grass_block
setblock ~172 ~125 ~103 grass_block
setblock ~172 ~125 ~104 dirt
setblock ~172 ~125 ~105 dirt
setblock ~172 ~125 ~106 dirt
setblock ~172 ~125 ~107 dirt
setblock ~172 ~125 ~108 dirt
setblock ~172 ~125 ~137 grass_block
setblock ~172 ~125 ~138 grass_block
setblock ~172 ~125 ~139 grass_block
setblock ~172 ~125 ~140 grass_block
setblock ~172 ~125 ~141 dirt
setblock ~172 ~126 ~75 grass_block
setblock ~172 ~126 ~76 grass_block
setblock ~172 ~126 ~77 grass_block
setblock ~172 ~126 ~78 grass_block
setblock ~172 ~126 ~79 grass_block
setblock ~172 ~126 ~80 grass_block
setblock ~172 ~126 ~81 grass_block
setblock ~172 ~126 ~82 dirt
setblock ~172 ~126 ~102 short_grass
setblock ~172 ~126 ~104 grass_block
setblock ~172 ~126 ~105 grass_block
setblock ~172 ~126 ~106 grass_block
setblock ~172 ~126 ~107 dirt
setblock ~172 ~126 ~108 dirt
setblock ~172 ~126 ~138 fern
setblock ~172 ~126 ~139 fern
setblock ~172 ~126 ~141 grass_block
setblock ~172 ~127 ~75 poppy
setblock ~172 ~127 ~76 short_grass
setblock ~172 ~127 ~82 grass_block
setblock ~172 ~127 ~104 short_grass
setblock ~172 ~127 ~105 short_grass
setblock ~172 ~127 ~107 grass_block
setblock ~172 ~127 ~108 grass_block
setblock ~173 ~117 ~78 dirt
setblock ~173 ~118 ~78 dirt
setblock ~173 ~118 ~106 dirt
setblock ~173 ~119 ~77 dirt
setblock ~173 ~119 ~78 dirt
setblock ~173 ~119 ~79 dirt
setblock ~173 ~119 ~103 dirt
setblock ~173 ~119 ~105 dirt
setblock ~173 ~119 ~106 dirt
setblock ~173 ~119 ~107 dirt
setblock ~173 ~120 ~74 dirt
setblock ~173 ~120 ~77 dirt
setblock ~173 ~120 ~78 dirt
setblock ~173 ~120 ~79 dirt
setblock ~173 ~120 ~80 dirt
setblock ~173 ~120 ~102 dirt
setblock ~173 ~120 ~103 dirt
setblock ~173 ~120 ~104 dirt
setblock ~173 ~120 ~105 dirt
setblock ~173 ~120 ~106 dirt
setblock ~173 ~120 ~107 dirt
setblock ~173 ~121 ~74 dirt
setblock ~173 ~121 ~76 dirt
setblock ~173 ~121 ~77 dirt
setblock ~173 ~121 ~78 dirt
setblock ~173 ~121 ~79 dirt
setblock ~173 ~121 ~80 dirt
setblock ~173 ~121 ~81 dirt
setblock ~173 ~121 ~101 dirt
setblock ~173 ~121 ~102 dirt
setblock ~173 ~121 ~103 dirt
setblock ~173 ~121 ~104 dirt
setblock ~173 ~121 ~105 dirt
setblock ~173 ~121 ~106 dirt
setblock ~173 ~121 ~107 dirt
setblock ~173 ~121 ~138 dirt
setblock ~173 ~121 ~139 dirt
setblock ~173 ~121 ~140 dirt
setblock ~173 ~122 ~74 dirt
setblock ~173 ~122 ~76 dirt
setblock ~173 ~122 ~77 dirt
setblock ~173 ~122 ~78 dirt
setblock ~173 ~122 ~79 dirt
setblock ~173 ~122 ~80 dirt
setblock ~173 ~122 ~81 dirt
setblock ~173 ~122 ~101 dirt
setblock ~173 ~122 ~102 dirt
setblock ~173 ~122 ~103 dirt
setblock ~173 ~122 ~104 dirt
setblock ~173 ~122 ~105 dirt
setblock ~173 ~122 ~106 dirt
setblock ~173 ~122 ~107 dirt
setblock ~173 ~122 ~138 dirt
setblock ~173 ~122 ~139 dirt
setblock ~173 ~122 ~140 dirt
setblock ~173 ~123 ~74 dirt
setblock ~173 ~123 ~76 dirt
setblock ~173 ~123 ~77 dirt
setblock ~173 ~123 ~78 dirt
setblock ~173 ~123 ~79 dirt
setblock ~173 ~123 ~80 dirt
setblock ~173 ~123 ~81 dirt
setblock ~173 ~123 ~101 dirt
setblock ~173 ~123 ~102 dirt
setblock ~173 ~123 ~103 dirt
setblock ~173 ~123 ~104 dirt
setblock ~173 ~123 ~105 dirt
setblock ~173 ~123 ~106 dirt
setblock ~173 ~123 ~107 dirt
setblock ~173 ~123 ~138 dirt
setblock ~173 ~123 ~139 dirt
setblock ~173 ~123 ~140 dirt
setblock ~173 ~124 ~74 dirt
setblock ~173 ~124 ~76 dirt
setblock ~173 ~124 ~77 dirt
setblock ~173 ~124 ~78 dirt
setblock ~173 ~124 ~79 dirt
setblock ~173 ~124 ~80 dirt
setblock ~173 ~124 ~81 dirt
setblock ~173 ~124 ~101 grass_block
setblock ~173 ~124 ~102 dirt
setblock ~173 ~124 ~103 dirt
setblock ~173 ~124 ~104 dirt
setblock ~173 ~124 ~105 dirt
setblock ~173 ~124 ~106 dirt
setblock ~173 ~124 ~107 dirt
setblock ~173 ~124 ~138 dirt
setblock ~173 ~124 ~139 dirt
setblock ~173 ~124 ~140 dirt
setblock ~173 ~125 ~74 grass_block
setblock ~173 ~125 ~76 dirt
setblock ~173 ~125 ~77 dirt
setblock ~173 ~125 ~78 dirt
setblock ~173 ~125 ~79 dirt
setblock ~173 ~125 ~80 dirt
setblock ~173 ~125 ~81 dirt
setblock ~173 ~125 ~102 grass_block
setblock ~173 ~125 ~103 grass_block
setblock ~173 ~125 ~104 dirt
setblock ~173 ~125 ~105 dirt
setblock ~173 ~125 ~106 dirt
setblock ~173 ~125 ~107 dirt
setblock ~173 ~125 ~138 grass_block
setblock ~173 ~125 ~139 grass_block
setblock ~173 ~125 ~140 grass_block
setblock ~173 ~126 ~76 grass_block
setblock ~173 ~126 ~77 grass_block
setblock ~173 ~126 ~78 grass_block
setblock ~173 ~126 ~79 grass_block
setblock ~173 ~126 ~80 grass_block
setblock ~173 ~126 ~81 grass_block
setblock ~173 ~126 ~104 grass_block
setblock ~173 ~126 ~105 grass_block
setblock ~173 ~126 ~106 dirt
setblock ~173 ~126 ~107 dirt
setblock ~173 ~126 ~139 short_grass
setblock ~173 ~127 ~105 fern
setblock ~173 ~127 ~106 grass_block
setblock ~173 ~127 ~107 grass_block
setblock ~173 ~128 ~106 short_grass
setblock ~173 ~128 ~107 short_grass
setblock ~174 ~119 ~78 dirt
setblock ~174 ~120 ~77 dirt
setblock ~174 ~120 ~78 dirt
setblock ~174 ~120 ~79 dirt
setblock ~174 ~120 ~103 dirt
setblock ~174 ~120 ~105 dirt
setblock ~174 ~121 ~77 dirt
setblock ~174 ~121 ~78 dirt
setblock ~174 ~121 ~79 dirt
setblock ~174 ~121 ~80 dirt
setblock ~174 ~121 ~102 dirt
setblock ~174 ~121 ~103 dirt
setblock ~174 ~121 ~104 dirt
setblock ~174 ~121 ~105 dirt
setblock ~174 ~121 ~106 dirt
setblock ~174 ~122 ~77 dirt
setblock ~174 ~122 ~78 dirt
setblock ~174 ~122 ~79 dirt
setblock ~174 ~122 ~80 dirt
setblock ~174 ~122 ~102 dirt
setblock ~174 ~122 ~103 dirt
setblock ~174 ~122 ~104 dirt
setblock ~174 ~122 ~105 dirt
setblock ~174 ~122 ~106 dirt
setblock ~174 ~123 ~77 dirt
setblock ~174 ~123 ~78 dirt
setblock ~174 ~123 ~79 dirt
setblock ~174 ~123 ~80 dirt
setblock ~174 ~123 ~102 dirt
setblock ~174 ~123 ~103 dirt
setblock ~174 ~123 ~104 dirt
setblock ~174 ~123 ~105 dirt
setblock ~174 ~123 ~106 dirt
setblock ~174 ~124 ~77 dirt
setblock ~174 ~124 ~78 dirt
setblock ~174 ~124 ~79 dirt
setblock ~174 ~124 ~80 dirt
setblock ~174 ~124 ~102 dirt
setblock ~174 ~124 ~103 dirt
setblock ~174 ~124 ~104 dirt
setblock ~174 ~124 ~105 dirt
setblock ~174 ~124 ~106 dirt
setblock ~174 ~125 ~77 dirt
setblock ~174 ~125 ~78 dirt
setblock ~174 ~125 ~79 dirt
setblock ~174 ~125 ~80 dirt
setblock ~174 ~125 ~102 grass_block
setblock ~174 ~125 ~103 grass_block
setblock ~174 ~125 ~104 dirt
setblock ~174 ~125 ~105 dirt
setblock ~174 ~125 ~106 dirt
setblock ~174 ~126 ~77 grass_block
setblock ~174 ~126 ~78 grass_block
setblock ~174 ~126 ~79 grass_block
setblock ~174 ~126 ~80 grass_block
setblock ~174 ~126 ~102 short_grass
setblock ~174 ~126 ~104 grass_block
setblock ~174 ~126 ~105 grass_block
setblock ~174 ~126 ~106 dirt
setblock ~174 ~127 ~77 short_grass
setblock ~174 ~127 ~105 short_grass
setblock ~174 ~127 ~106 grass_block
setblock ~175 ~120 ~78 dirt
setblock ~175 ~120 ~92 dirt
setblock ~175 ~120 ~94 dirt
setblock ~175 ~121 ~78 dirt
setblock ~175 ~121 ~79 dirt
setblock ~175 ~121 ~92 dirt
setblock ~175 ~121 ~94 dirt
setblock ~175 ~121 ~105 dirt
setblock ~175 ~122 ~78 dirt
setblock ~175 ~122 ~79 dirt
setblock ~175 ~122 ~92 dirt
setblock ~175 ~122 ~94 dirt
setblock ~175 ~122 ~105 dirt
setblock ~175 ~123 ~78 dirt
setblock ~175 ~123 ~79 dirt
setblock ~175 ~123 ~92 dirt
setblock ~175 ~123 ~94 dirt
setblock ~175 ~123 ~105 dirt
setblock ~175 ~124 ~78 dirt
setblock ~175 ~124 ~79 dirt
setblock ~175 ~124 ~92 dirt
setblock ~175 ~124 ~94 dirt
setblock ~175 ~124 ~105 dirt
setblock ~175 ~125 ~78 dirt
setblock ~175 ~125 ~79 dirt
setblock ~175 ~125 ~92 dirt
setblock ~175 ~125 ~94 grass_block
setblock ~175 ~125 ~105 dirt
setblock ~175 ~126 ~78 grass_block
setblock ~175 ~126 ~79 grass_block
setblock ~175 ~126 ~92 grass_block
setblock ~175 ~126 ~105 grass_block
setblock ~175 ~127 ~78 short_grass
setblock ~175 ~127 ~79 short_grass
setblock ~175 ~127 ~92 short_grass
setblock ~176 ~119 ~92 dirt
setblock ~176 ~119 ~93 dirt
setblock ~176 ~119 ~94 dirt
setblock ~176 ~120 ~91 dirt
setblock ~176 ~120 ~92 dirt
setblock ~176 ~120 ~93 dirt
setblock ~176 ~120 ~94 dirt
setblock ~176 ~120 ~95 dirt
setblock ~176 ~121 ~91 dirt
setblock ~176 ~121 ~92 dirt
setblock ~176 ~121 ~93 dirt
setblock ~176 ~121 ~94 dirt
setblock ~176 ~121 ~95 dirt
setblock ~176 ~122 ~91 dirt
setblock ~176 ~122 ~92 dirt
setblock ~176 ~122 ~93 dirt
setblock ~176 ~122 ~94 dirt
setblock ~176 ~122 ~95 dirt
setblock ~176 ~123 ~91 dirt
setblock ~176 ~123 ~92 dirt
setblock ~176 ~123 ~93 dirt
setblock ~176 ~123 ~94 dirt
setblock ~176 ~123 ~95 dirt
setblock ~176 ~124 ~91 dirt
setblock ~176 ~124 ~92 dirt
setblock ~176 ~124 ~93 dirt
setblock ~176 ~124 ~94 dirt
setblock ~176 ~124 ~95 dirt
setblock ~176 ~125 ~91 dirt
setblock ~176 ~125 ~92 grass_block
setblock ~176 ~125 ~93 grass_block
setblock ~176 ~125 ~94 grass_block
setblock ~176 ~125 ~95 grass_block
setblock ~176 ~126 ~91 grass_block
setblock ~177 ~118 ~92 dirt
setblock ~177 ~118 ~93 dirt
setblock ~177 ~118 ~94 dirt
setblock ~177 ~119 ~91 dirt
setblock ~177 ~119 ~92 dirt
setblock ~177 ~119 ~93 dirt
setblock ~177 ~119 ~94 dirt
setblock ~177 ~119 ~95 dirt
setblock ~177 ~120 ~91 dirt
setblock ~177 ~120 ~92 dirt
setblock ~177 ~120 ~93 dirt
setblock ~177 ~120 ~94 dirt
setblock ~177 ~120 ~95 dirt
setblock ~177 ~121 ~91 dirt
setblock ~177 ~121 ~92 dirt
setblock ~177 ~121 ~93 dirt
setblock ~177 ~121 ~94 dirt
setblock ~177 ~121 ~95 dirt
setblock ~177 ~121 ~96 dirt
setblock ~177 ~122 ~91 dirt
setblock ~177 ~122 ~92 dirt
setblock ~177 ~122 ~93 dirt
setblock ~177 ~122 ~94 dirt
setblock ~177 ~122 ~95 dirt
setblock ~177 ~122 ~96 dirt
setblock ~177 ~123 ~91 dirt
setblock ~177 ~123 ~92 dirt
setblock ~177 ~123 ~93 dirt
setblock ~177 ~123 ~94 dirt
setblock ~177 ~123 ~95 dirt
setblock ~177 ~123 ~96 dirt
setblock ~177 ~124 ~91 dirt
setblock ~177 ~124 ~92 dirt
setblock ~177 ~124 ~93 dirt
setblock ~177 ~124 ~94 dirt
setblock ~177 ~124 ~95 grass_block
setblock ~177 ~124 ~96 grass_block
setblock ~177 ~125 ~91 grass_block
setblock ~177 ~125 ~92 grass_block
setblock ~177 ~125 ~93 grass_block
setblock ~177 ~125 ~94 grass_block
setblock ~177 ~125 ~96 short_grass
setblock ~177 ~126 ~91 short_grass
setblock ~178 ~114 ~93 dirt
setblock ~178 ~115 ~93 dirt
setblock ~178 ~116 ~92 dirt
setblock ~178 ~116 ~93 dirt
setblock ~178 ~116 ~94 dirt
setblock ~178 ~117 ~92 dirt
setblock ~178 ~117 ~93 dirt
setblock ~178 ~117 ~94 dirt
setblock ~178 ~118 ~91 dirt
setblock ~178 ~118 ~92 dirt
setblock ~178 ~118 ~93 dirt
setblock ~178 ~118 ~94 dirt
setblock ~178 ~118 ~95 dirt
setblock ~178 ~119 ~90 dirt
setblock ~178 ~119 ~91 dirt
setblock ~178 ~119 ~92 dirt
setblock ~178 ~119 ~93 dirt
setblock ~178 ~119 ~94 dirt
setblock ~178 ~119 ~95 dirt
setblock ~178 ~120 ~90 dirt
setblock ~178 ~120 ~91 dirt
setblock ~178 ~120 ~92 dirt
setblock ~178 ~120 ~93 dirt
setblock ~178 ~120 ~94 dirt
setblock ~178 ~120 ~95 dirt
setblock ~178 ~121 ~90 dirt
setblock ~178 ~121 ~91 dirt
setblock ~178 ~121 ~92 dirt
setblock ~178 ~121 ~93 dirt
setblock ~178 ~121 ~94 dirt
setblock ~178 ~121 ~95 dirt
setblock ~178 ~121 ~96 dirt
setblock ~178 ~122 ~90 dirt
setblock ~178 ~122 ~91 dirt
setblock ~178 ~122 ~92 dirt
setblock ~178 ~122 ~93 dirt
setblock ~178 ~122 ~94 dirt
setblock ~178 ~122 ~95 dirt
setblock ~178 ~122 ~96 dirt
setblock ~178 ~123 ~90 dirt
setblock ~178 ~123 ~91 dirt
setblock ~178 ~123 ~92 dirt
setblock ~178 ~123 ~93 dirt
setblock ~178 ~123 ~94 dirt
setblock ~178 ~123 ~95 dirt
setblock ~178 ~123 ~96 dirt
setblock ~178 ~124 ~90 dirt
setblock ~178 ~124 ~91 dirt
setblock ~178 ~124 ~92 dirt
setblock ~178 ~124 ~93 dirt
setblock ~178 ~124 ~94 grass_block
setblock ~178 ~124 ~95 grass_block
setblock ~178 ~124 ~96 grass_block
setblock ~178 ~125 ~90 grass_block
setblock ~178 ~125 ~91 grass_block
setblock ~178 ~125 ~92 grass_block
setblock ~178 ~125 ~93 grass_block
setblock ~178 ~125 ~95 poppy
setblock ~178 ~125 ~96 short_grass
setblock ~178 ~126 ~90 short_grass
setblock ~178 ~126 ~91 short_grass
setblock ~179 ~113 ~93 dirt
setblock ~179 ~114 ~92 dirt
setblock ~179 ~114 ~93 dirt
setblock ~179 ~114 ~94 dirt
setblock ~179 ~115 ~92 dirt
setblock ~179 ~115 ~93 dirt
setblock ~179 ~115 ~94 dirt
setblock ~179 ~116 ~91 dirt
setblock ~179 ~116 ~92 dirt
setblock ~179 ~116 ~93 dirt
setblock ~179 ~116 ~94 dirt
setblock ~179 ~116 ~95 dirt
setblock ~179 ~117 ~91 dirt
setblock ~179 ~117 ~92 dirt
setblock ~179 ~117 ~93 dirt
setblock ~179 ~117 ~94 dirt
setblock ~179 ~117 ~95 dirt
setblock ~179 ~118 ~90 dirt
setblock ~179 ~118 ~91 dirt
setblock ~179 ~118 ~92 dirt
setblock ~179 ~118 ~93 dirt
setblock ~179 ~118 ~94 dirt
setblock ~179 ~118 ~95 dirt
setblock ~179 ~119 ~89 dirt
setblock ~179 ~119 ~90 dirt
setblock ~179 ~119 ~91 dirt
setblock ~179 ~119 ~92 dirt
setblock ~179 ~119 ~93 dirt
setblock ~179 ~119 ~94 dirt
setblock ~179 ~119 ~95 dirt
setblock ~179 ~119 ~96 dirt
setblock ~179 ~120 ~89 dirt
setblock ~179 ~120 ~90 dirt
setblock ~179 ~120 ~91 dirt
setblock ~179 ~120 ~92 dirt
setblock ~179 ~120 ~93 dirt
setblock ~179 ~120 ~94 dirt
setblock ~179 ~120 ~95 dirt
setblock ~179 ~120 ~96 dirt
setblock ~179 ~121 ~89 dirt
setblock ~179 ~121 ~90 dirt
setblock ~179 ~121 ~91 dirt
setblock ~179 ~121 ~92 dirt
setblock ~179 ~121 ~93 dirt
setblock ~179 ~121 ~94 dirt
setblock ~179 ~121 ~95 dirt
setblock ~179 ~121 ~96 dirt
setblock ~179 ~121 ~97 dirt
setblock ~179 ~122 ~89 dirt
setblock ~179 ~122 ~90 dirt
setblock ~179 ~122 ~91 dirt
setblock ~179 ~122 ~92 dirt
setblock ~179 ~122 ~93 dirt
setblock ~179 ~122 ~94 dirt
setblock ~179 ~122 ~95 dirt
setblock ~179 ~122 ~96 dirt
setblock ~179 ~122 ~97 dirt
setblock ~179 ~123 ~89 dirt
setblock ~179 ~123 ~90 dirt
setblock ~179 ~123 ~91 dirt
setblock ~179 ~123 ~92 dirt
setblock ~179 ~123 ~93 dirt
setblock ~179 ~123 ~94 dirt
setblock ~179 ~123 ~95 dirt
setblock ~179 ~123 ~96 dirt
setblock ~179 ~123 ~97 dirt
setblock ~179 ~124 ~89 dirt
setblock ~179 ~124 ~90 grass_block
setblock ~179 ~124 ~91 grass_block
setblock ~179 ~124 ~92 grass_block
setblock ~179 ~124 ~93 grass_block
setblock ~179 ~124 ~94 grass_block
setblock ~179 ~124 ~95 grass_block
setblock ~179 ~124 ~96 grass_block
setblock ~179 ~124 ~97 grass_block
setblock ~179 ~125 ~89 grass_block
setblock ~179 ~125 ~90 short_grass
setblock ~179 ~125 ~93 short_grass
setblock ~179 ~125 ~94 short_grass
setblock ~179 ~125 ~95 short_grass
setblock ~180 ~114 ~93 dirt
setblock ~180 ~115 ~93 dirt
setblock ~180 ~116 ~92 dirt
setblock ~180 ~116 ~93 dirt
setblock ~180 ~116 ~94 dirt
setblock ~180 ~117 ~92 dirt
setblock ~180 ~117 ~93 dirt
setblock ~180 ~117 ~94 dirt
setblock ~180 ~118 ~91 dirt
setblock ~180 ~118 ~92 dirt
setblock ~180 ~118 ~93 dirt
setblock ~180 ~118 ~94 dirt
setblock ~180 ~119 ~90 dirt
setblock ~180 ~119 ~91 dirt
setblock ~180 ~119 ~92 dirt
setblock ~180 ~119 ~93 dirt
setblock ~180 ~119 ~94 dirt
setblock ~180 ~119 ~95 dirt
setblock ~180 ~120 ~90 dirt
setblock ~180 ~120 ~91 dirt
setblock ~180 ~120 ~92 dirt
setblock ~180 ~120 ~93 dirt
setblock ~180 ~120 ~94 dirt
setblock ~180 ~120 ~95 dirt
setblock ~180 ~120 ~96 dirt
setblock ~180 ~121 ~90 dirt
setblock ~180 ~121 ~91 dirt
setblock ~180 ~121 ~92 dirt
setblock ~180 ~121 ~93 dirt
setblock ~180 ~121 ~94 dirt
setblock ~180 ~121 ~95 dirt
setblock ~180 ~121 ~96 dirt
setblock ~180 ~122 ~90 dirt
setblock ~180 ~122 ~91 dirt
setblock ~180 ~122 ~92 dirt
setblock ~180 ~122 ~93 dirt
setblock ~180 ~122 ~94 dirt
setblock ~180 ~122 ~95 dirt
setblock ~180 ~122 ~96 dirt
setblock ~180 ~123 ~90 dirt
setblock ~180 ~123 ~91 dirt
setblock ~180 ~123 ~92 dirt
setblock ~180 ~123 ~93 dirt
setblock ~180 ~123 ~94 dirt
setblock ~180 ~123 ~95 dirt
setblock ~180 ~123 ~96 dirt
setblock ~180 ~124 ~90 grass_block
setblock ~180 ~124 ~91 grass_block
setblock ~180 ~124 ~92 grass_block
setblock ~180 ~124 ~93 grass_block
setblock ~180 ~124 ~94 grass_block
setblock ~180 ~124 ~95 grass_block
setblock ~180 ~124 ~96 grass_block
setblock ~180 ~125 ~90 short_grass
setblock ~180 ~125 ~93 short_grass
setblock ~180 ~125 ~96 poppy
setblock ~181 ~118 ~93 dirt
setblock ~181 ~119 ~92 dirt
setblock ~181 ~119 ~93 dirt
setblock ~181 ~119 ~94 dirt
setblock ~181 ~120 ~92 dirt
setblock ~181 ~120 ~93 dirt
setblock ~181 ~120 ~94 dirt
setblock ~181 ~120 ~95 dirt
setblock ~181 ~121 ~91 dirt
setblock ~181 ~121 ~92 dirt
setblock ~181 ~121 ~93 dirt
setblock ~181 ~121 ~94 dirt
setblock ~181 ~121 ~95 dirt
setblock ~181 ~122 ~91 dirt
setblock ~181 ~122 ~92 dirt
setblock ~181 ~122 ~93 dirt
setblock ~181 ~122 ~94 dirt
setblock ~181 ~122 ~95 dirt
setblock ~181 ~123 ~91 dirt
setblock ~181 ~123 ~92 dirt
setblock ~181 ~123 ~93 dirt
setblock ~181 ~123 ~94 dirt
setblock ~181 ~123 ~95 dirt
setblock ~181 ~124 ~91 grass_block
setblock ~181 ~124 ~92 grass_block
setblock ~181 ~124 ~93 grass_block
setblock ~181 ~124 ~94 grass_block
setblock ~181 ~124 ~95 grass_block
setblock ~181 ~125 ~91 short_grass
setblock ~181 ~125 ~92 short_grass
setblock ~181 ~125 ~95 short_grass
setblock ~182 ~119 ~93 dirt
setblock ~182 ~120 ~93 dirt
setblock ~182 ~121 ~92 dirt
setblock ~182 ~121 ~93 dirt
setblock ~182 ~121 ~94 dirt
setblock ~182 ~122 ~92 dirt
setblock ~182 ~122 ~93 dirt
setblock ~182 ~122 ~94 dirt
setblock ~182 ~123 ~92 dirt
setblock ~182 ~123 ~93 dirt
setblock ~182 ~123 ~94 dirt
setblock ~182 ~124 ~92 grass_block
setblock ~182 ~124 ~93 grass_block
setblock ~182 ~124 ~94 grass_block
setblock ~182 ~125 ~94 short_grass
setblock ~183 ~121 ~93 dirt
setblock ~183 ~122 ~93 dirt
setblock ~183 ~123 ~93 dirt
setblock ~183 ~124 ~93 grass_block
setblock ~199 ~200 ~199 gold_block
