setblock ~0 ~1 ~0 gold_block
setblock ~27 ~120 ~101 dirt
setblock ~27 ~121 ~100 dirt
setblock ~27 ~121 ~101 dirt
setblock ~27 ~121 ~102 dirt
setblock ~27 ~122 ~100 dirt
setblock ~27 ~122 ~101 dirt
setblock ~27 ~122 ~102 dirt
setblock ~27 ~123 ~100 dirt
setblock ~27 ~123 ~101 dirt
setblock ~27 ~123 ~102 dirt
setblock ~27 ~124 ~100 dirt
setblock ~27 ~124 ~101 dirt
setblock ~27 ~124 ~102 dirt
setblock ~27 ~125 ~100 dirt
setblock ~27 ~125 ~101 grass_block
setblock ~27 ~125 ~102 grass_block
setblock ~27 ~126 ~100 grass_block
setblock ~28 ~119 ~101 dirt
setblock ~28 ~120 ~100 dirt
setblock ~28 ~120 ~101 dirt
setblock ~28 ~120 ~102 dirt
setblock ~28 ~121 ~99 dirt
setblock ~28 ~121 ~100 dirt
setblock ~28 ~121 ~101 dirt
setblock ~28 ~121 ~102 dirt
setblock ~28 ~121 ~103 dirt
setblock ~28 ~121 ~104 dirt
setblock ~28 ~122 ~99 dirt
setblock ~28 ~122 ~100 dirt
setblock ~28 ~122 ~101 dirt
setblock ~28 ~122 ~102 dirt
setblock ~28 ~122 ~103 dirt
setblock ~28 ~122 ~104 dirt
setblock ~28 ~123 ~99 dirt
setblock ~28 ~123 ~100 dirt
setblock ~28 ~123 ~101 dirt
setblock ~28 ~123 ~102 dirt
setblock ~28 ~123 ~103 dirt
setblock ~28 ~123 ~104 dirt
setblock ~28 ~124 ~99 dirt
setblock ~28 ~124 ~100 dirt
setblock ~28 ~124 ~101 dirt
setblock ~28 ~124 ~102 dirt
setblock ~28 ~124 ~103 grass_block
setblock ~28 ~124 ~104 grass_block
setblock ~28 ~125 ~99 grass_block
setblock ~28 ~125 ~100 grass_block
setblock ~28 ~125 ~101 grass_block
setblock ~28 ~125 ~102 grass_block
setblock ~28 ~125 ~103 short_grass
setblock ~28 ~126 ~100 poppy
setblock ~29 ~118 ~101 dirt
setblock ~29 ~119 ~100 dirt
setblock ~29 ~119 ~101 dirt
setblock ~29 ~119 ~102 dirt
setblock ~29 ~119 ~104 dirt
setblock ~29 ~119 ~105 dirt
setblock ~29 ~120 ~99 dirt
setblock ~29 ~120 ~100 dirt
setblock ~29 ~120 ~101 dirt
setblock ~29 ~120 ~102 dirt
setblock ~29 ~120 ~104 dirt
setblock ~29 ~120 ~105 dirt
setblock ~29 ~121 ~98 dirt
setblock ~29 ~121 ~99 dirt
setblock ~29 ~121 ~100 dirt
setblock ~29 ~121 ~101 dirt
setblock ~29 ~121 ~102 dirt
setblock ~29 ~121 ~103 dirt
setblock ~29 ~121 ~104 dirt
setblock ~29 ~121 ~105 dirt
setblock ~29 ~121 ~107 dirt
setblock ~29 ~122 ~98 dirt
setblock ~29 ~122 ~99 dirt
setblock ~29 ~122 ~100 dirt
setblock ~29 ~122 ~101 dirt
setblock ~29 ~122 ~102 dirt
setblock ~29 ~122 ~103 dirt
setblock ~29 ~122 ~104 dirt
setblock ~29 ~122 ~105 dirt
setblock ~29 ~122 ~107 dirt
setblock ~29 ~123 ~98 dirt
setblock ~29 ~123 ~99 dirt
setblock ~29 ~123 ~100 dirt
setblock ~29 ~123 ~101 dirt
setblock ~29 ~123 ~102 dirt
setblock ~29 ~123 ~103 dirt
setblock ~29 ~123 ~104 dirt
setblock ~29 ~123 ~105 dirt
setblock ~29 ~123 ~107 grass_block
setblock ~29 ~124 ~98 dirt
setblock ~29 ~124 ~99 dirt
setblock ~29 ~124 ~100 dirt
setblock ~29 ~124 ~101 dirt
setblock ~29 ~124 ~102 grass_block
setblock ~29 ~124 ~103 grass_block
setblock ~29 ~124 ~104 grass_block
setblock ~29 ~124 ~105 grass_block
setblock ~29 ~124 ~107 fern
setblock ~29 ~125 ~98 grass_block
setblock ~29 ~125 ~99 grass_block
setblock ~29 ~125 ~100 grass_block
setblock ~29 ~125 ~101 grass_block
setblock ~29 ~125 ~104 short_grass
setblock ~30 ~117 ~101 dirt
setblock ~30 ~117 ~102 dirt
setblock ~30 ~118 ~100 dirt
setblock ~30 ~118 ~101 dirt
setblock ~30 ~118 ~102 dirt
setblock ~30 ~118 ~103 dirt
setblock ~30 ~118 ~104 dirt
setblock ~30 ~118 ~105 dirt
setblock ~30 ~119 ~100 dirt
setblock ~30 ~119 ~101 dirt
setblock ~30 ~119 ~102 dirt
setblock ~30 ~119 ~103 dirt
setblock ~30 ~119 ~104 dirt
setblock ~30 ~119 ~105 dirt
setblock ~30 ~119 ~106 dirt
setblock ~30 ~119 ~107 dirt
setblock ~30 ~120 ~98 dirt
setblock ~30 ~120 ~99 dirt
setblock ~30 ~120 ~100 dirt
setblock ~30 ~120 ~101 dirt
setblock ~30 ~120 ~102 dirt
setblock ~30 ~120 ~103 dirt
setblock ~30 ~120 ~104 dirt
setblock ~30 ~120 ~105 dirt
setblock ~30 ~120 ~106 dirt
setblock ~30 ~120 ~107 dirt
setblock ~30 ~121 ~97 dirt
setblock ~30 ~121 ~98 dirt
setblock ~30 ~121 ~99 dirt
setblock ~30 ~121 ~100 dirt
setblock ~30 ~121 ~101 dirt
setblock ~30 ~121 ~102 dirt
setblock ~30 ~121 ~103 dirt
setblock ~30 ~121 ~104 dirt
setblock ~30 ~121 ~105 dirt
setblock ~30 ~121 ~106 dirt
setblock ~30 ~121 ~107 dirt
setblock ~30 ~121 ~108 dirt
setblock ~30 ~122 ~97 dirt
setblock ~30 ~122 ~98 dirt
setblock ~30 ~122 ~99 dirt
setblock ~30 ~122 ~100 dirt
setblock ~30 ~122 ~101 dirt
setblock ~30 ~122 ~102 dirt
setblock ~30 ~122 ~103 dirt
setblock ~30 ~122 ~104 dirt
setblock ~30 ~122 ~105 dirt
setblock ~30 ~122 ~106 dirt
setblock ~30 ~122 ~107 dirt
setblock ~30 ~122 ~108 dirt
setblock ~30 ~123 ~97 dirt
setblock ~30 ~123 ~98 dirt
setblock ~30 ~123 ~99 dirt
setblock ~30 ~123 ~100 dirt
setblock ~30 ~123 ~101 dirt
setblock ~30 ~123 ~102 dirt
setblock ~30 ~123 ~103 dirt
setblock ~30 ~123 ~104 dirt
setblock ~30 ~123 ~105 grass_block
setblock ~30 ~123 ~106 grass_block
setblock ~30 ~123 ~107 grass_block
setblock ~30 ~123 ~108 grass_block
setblock ~30 ~124 ~97 dirt
setblock ~30 ~124 ~98 dirt
setblock ~30 ~124 ~99 dirt
setblock ~30 ~124 ~100 dirt
setblock ~30 ~124 ~101 dirt
setblock ~30 ~124 ~102 grass_block
setblock ~30 ~124 ~103 grass_block
setblock ~30 ~124 ~104 grass_block
setblock ~30 ~124 ~107 short_grass
setblock ~30 ~125 ~97 grass_block
setblock ~30 ~125 ~98 grass_block
setblock ~30 ~125 ~99 grass_block
setblock ~30 ~125 ~100 grass_block
setblock ~30 ~125 ~101 grass_block
setblock ~30 ~126 ~99 short_grass
setblock ~31 ~115 ~104 dirt
setblock ~31 ~116 ~101 dirt
setblock ~31 ~116 ~102 dirt
setblock ~31 ~116 ~103 dirt
setblock ~31 ~116 ~104 dirt
setblock ~31 ~117 ~100 dirt
setblock ~31 ~117 ~101 dirt
setblock ~31 ~117 ~102 dirt
setblock ~31 ~117 ~103 dirt
setblock ~31 ~117 ~104 dirt
setblock ~31 ~117 ~105 dirt
setblock ~31 ~118 ~98 dirt
setblock ~31 ~118 ~99 dirt
setblock ~31 ~118 ~100 dirt
setblock ~31 ~118 ~101 dirt
setblock ~31 ~118 ~102 dirt
setblock ~31 ~118 ~103 dirt
setblock ~31 ~118 ~104 dirt
setblock ~31 ~118 ~105 dirt
setblock ~31 ~118 ~106 dirt
setblock ~31 ~118 ~107 dirt
setblock ~31 ~119 ~74 dirt
setblock ~31 ~119 ~97 dirt
setblock ~31 ~119 ~98 dirt
setblock ~31 ~119 ~99 dirt
setblock ~31 ~119 ~100 dirt
setblock ~31 ~119 ~101 dirt
setblock ~31 ~119 ~102 dirt
setblock ~31 ~119 ~103 dirt
setblock ~31 ~119 ~104 dirt
setblock ~31 ~119 ~105 dirt
setblock ~31 ~119 ~106 dirt
setblock ~31 ~119 ~107 dirt
setblock ~31 ~119 ~108 dirt
setblock ~31 ~120 ~74 dirt
setblock ~31 ~120 ~96 dirt
setblock ~31 ~120 ~97 dirt
setblock ~31 ~120 ~98 dirt
setblock ~31 ~120 ~99 dirt
setblock ~31 ~120 ~100 dirt
setblock ~31 ~120 ~101 dirt
setblock ~31 ~120 ~102 dirt
setblock ~31 ~120 ~103 dirt
setblock ~31 ~120 ~104 dirt
setblock ~31 ~120 ~105 dirt
setblock ~31 ~120 ~106 dirt
setblock ~31 ~120 ~107 dirt
setblock ~31 ~120 ~108 dirt
setblock ~31 ~121 ~71 dirt
setblock ~31 ~121 ~73 dirt
setblock ~31 ~121 ~74 dirt
setblock ~31 ~121 ~84 dirt
setblock ~31 ~121 ~95 dirt
setblock ~31 ~121 ~96 dirt
setblock ~31 ~121 ~97 dirt
setblock ~31 ~121 ~98 dirt
setblock ~31 ~121 ~99 dirt
setblock ~31 ~121 ~100 dirt
setblock ~31 ~121 ~101 dirt
setblock ~31 ~121 ~102 dirt
setblock ~31 ~121 ~103 dirt
setblock ~31 ~121 ~104 dirt
setblock ~31 ~121 ~105 dirt
setblock ~31 ~121 ~106 dirt
setblock ~31 ~121 ~107 dirt
setblock ~31 ~121 ~108 dirt
setblock ~31 ~121 ~109 dirt
setblock ~31 ~122 ~71 dirt
setblock ~31 ~122 ~73 dirt
setblock ~31 ~122 ~74 dirt
setblock ~31 ~122 ~84 dirt
setblock ~31 ~122 ~95 dirt
setblock ~31 ~122 ~96 dirt
setblock ~31 ~122 ~97 dirt
setblock ~31 ~122 ~98 dirt
setblock ~31 ~122 ~99 dirt
setblock ~31 ~122 ~100 dirt
setblock ~31 ~122 ~101 dirt
setblock ~31 ~122 ~102 dirt
setblock ~31 ~122 ~103 dirt
setblock ~31 ~122 ~104 dirt
setblock ~31 ~122 ~105 dirt
setblock ~31 ~122 ~106 dirt
setblock ~31 ~122 ~107 dirt
setblock ~31 ~122 ~108 dirt
setblock ~31 ~122 ~109 dirt
setblock ~31 ~123 ~71 dirt
setblock ~31 ~123 ~73 dirt
setblock ~31 ~123 ~74 dirt
setblock ~31 ~123 ~84 dirt
setblock ~31 ~123 ~95 dirt
setblock ~31 ~123 ~96 dirt
setblock ~31 ~123 ~97 dirt
setblock ~31 ~123 ~98 dirt
setblock ~31 ~123 ~99 dirt
setblock ~31 ~123 ~100 dirt
setblock ~31 ~123 ~101 dirt
setblock ~31 ~123 ~102 dirt
setblock ~31 ~123 ~103 dirt
setblock ~31 ~123 ~104 dirt
setblock ~31 ~123 ~105 dirt
setblock ~31 ~123 ~106 grass_block
setblock ~31 ~123 ~107 grass_block
setblock ~31 ~123 ~108 grass_block
setblock ~31 ~123 ~109 grass_block
setblock ~31 ~124 ~71 dirt
setblock ~31 ~124 ~73 dirt
setblock ~31 ~124 ~74 dirt
setblock ~31 ~124 ~84 dirt
setblock ~31 ~124 ~95 dirt
setblock ~31 ~124 ~96 dirt
setblock ~31 ~124 ~97 dirt
setblock ~31 ~124 ~98 dirt
setblock ~31 ~124 ~99 dirt
setblock ~31 ~124 ~100 dirt
setblock ~31 ~124 ~101 dirt
setblock ~31 ~124 ~102 grass_block
setblock ~31 ~124 ~103 grass_block
setblock ~31 ~124 ~104 grass_block
setblock ~31 ~124 ~105 grass_block
setblock ~31 ~124 ~108 short_grass
setblock ~31 ~125 ~71 dirt
setblock ~31 ~125 ~73 dirt
setblock ~31 ~125 ~74 dirt
setblock ~31 ~125 ~84 dirt
setblock ~31 ~125 ~95 grass_block
setblock ~31 ~125 ~96 grass_block
setblock ~31 ~125 ~97 grass_block
setblock ~31 ~125 ~98 grass_block
setblock ~31 ~125 ~99 grass_block
setblock ~31 ~125 ~100 grass_block
setblock ~31 ~125 ~101 grass_block
setblock ~31 ~125 ~102 poppy
setblock ~31 ~126 ~71 dirt
setblock ~31 ~126 ~73 dirt
setblock ~31 ~126 ~74 dirt
setblock ~31 ~126 ~84 dirt
setblock ~31 ~126 ~95 short_grass
setblock ~31 ~126 ~100 short_grass
setblock ~31 ~127 ~71 grass_block
setblock ~31 ~127 ~73 grass_block
setblock ~31 ~127 ~74 grass_block
setblock ~31 ~127 ~84 grass_block
setblock ~31 ~128 ~84 short_grass
setblock ~32 ~112 ~103 dirt
setblock ~32 ~113 ~102 dirt
setblock ~32 ~113 ~103 dirt
setblock ~32 ~114 ~100 dirt
setblock ~32 ~114 ~102 dirt
setblock ~32 ~114 ~103 dirt
setblock ~32 ~114 ~104 dirt
setblock ~32 ~115 ~100 dirt
setblock ~32 ~115 ~101 dirt
setblock ~32 ~115 ~102 dirt
setblock ~32 ~115 ~103 dirt
setblock ~32 ~115 ~104 dirt
setblock ~32 ~115 ~105 dirt
setblock ~32 ~116 ~100 dirt
setblock ~32 ~116 ~101 dirt
setblock ~32 ~116 ~102 dirt
setblock ~32 ~116 ~103 dirt
setblock ~32 ~116 ~104 dirt
setblock ~32 ~116 ~105 dirt
setblock ~32 ~116 ~106 dirt
setblock ~32 ~117 ~98 dirt
setblock ~32 ~117 ~99 dirt
setblock ~32 ~117 ~100 dirt
setblock ~32 ~117 ~101 dirt
setblock ~32 ~117 ~102 dirt
setblock ~32 ~117 ~103 dirt
setblock ~32 ~117 ~104 dirt
setblock ~32 ~117 ~105 dirt
setblock ~32 ~117 ~106 dirt
setblock ~32 ~117 ~107 dirt
setblock ~32 ~118 ~74 dirt
setblock ~32 ~118 ~97 dirt
setblock ~32 ~118 ~98 dirt
setblock ~32 ~118 ~99 dirt
setblock ~32 ~118 ~100 dirt
setblock ~32 ~118 ~101 dirt
setblock ~32 ~118 ~102 dirt
setblock ~32 ~118 ~103 dirt
setblock ~32 ~118 ~104 dirt
setblock ~32 ~118 ~105 dirt
setblock ~32 ~118 ~106 dirt
setblock ~32 ~118 ~107 dirt
setblock ~32 ~118 ~108 dirt
setblock ~32 ~119 ~71 dirt
setblock ~32 ~119 ~73 dirt
setblock ~32 ~119 ~74 dirt
setblock ~32 ~119 ~75 dirt
setblock ~32 ~119 ~96 dirt
setblock ~32 ~119 ~97 dirt
setblock ~32 ~119 ~98 dirt
setblock ~32 ~119 ~99 dirt
setblock ~32 ~119 ~100 dirt
setblock ~32 ~119 ~101 dirt
setblock ~32 ~119 ~102 dirt
setblock ~32 ~119 ~103 dirt
setblock ~32 ~119 ~104 dirt
setblock ~32 ~119 ~105 dirt
setblock ~32 ~119 ~106 dirt
setblock ~32 ~119 ~107 dirt
setblock ~32 ~119 ~108 dirt
setblock ~32 ~120 ~70 dirt
setblock ~32 ~120 ~71 dirt
setblock ~32 ~120 ~73 dirt
setblock ~32 ~120 ~74 dirt
setblock ~32 ~120 ~75 dirt
setblock ~32 ~120 ~84 dirt
setblock ~32 ~120 ~95 dirt
setblock ~32 ~120 ~96 dirt
setblock ~32 ~120 ~97 dirt
setblock ~32 ~120 ~98 dirt
setblock ~32 ~120 ~99 dirt
setblock ~32 ~120 ~100 dirt
setblock ~32 ~120 ~101 dirt
setblock ~32 ~120 ~102 dirt
setblock ~32 ~120 ~103 dirt
setblock ~32 ~120 ~104 dirt
setblock ~32 ~120 ~105 dirt
setblock ~32 ~120 ~106 dirt
setblock ~32 ~120 ~107 dirt
setblock ~32 ~120 ~108 dirt
setblock ~32 ~121 ~70 dirt
setblock ~32 ~121 ~71 dirt
setblock ~32 ~121 ~72 dirt
setblock ~32 ~121 ~73 dirt
setblock ~32 ~121 ~74 dirt
setblock ~32 ~121 ~75 dirt
setblock ~32 ~121 ~83 dirt
setblock ~32 ~121 ~84 dirt
setblock ~32 ~121 ~85 dirt
setblock ~32 ~121 ~94 dirt
setblock ~32 ~121 ~95 dirt
setblock ~32 ~121 ~96 dirt
setblock ~32 ~121 ~97 dirt
setblock ~32 ~121 ~98 dirt
setblock ~32 ~121 ~99 dirt
setblock ~32 ~121 ~100 dirt
setblock ~32 ~121 ~101 dirt
setblock ~32 ~121 ~102 dirt
setblock ~32 ~121 ~103 dirt
setblock ~32 ~121 ~104 dirt
setblock ~32 ~121 ~105 dirt
setblock ~32 ~121 ~106 dirt
setblock ~32 ~121 ~107 dirt
setblock ~32 ~121 ~108 dirt
setblock ~32 ~121 ~109 dirt
setblock ~32 ~122 ~70 dirt
setblock ~32 ~122 ~71 dirt
setblock ~32 ~122 ~72 dirt
setblock ~32 ~122 ~73 dirt
setblock ~32 ~122 ~74 dirt
setblock ~32 ~122 ~75 dirt
setblock ~32 ~122 ~83 dirt
setblock ~32 ~122 ~84 dirt
setblock ~32 ~122 ~85 dirt
setblock ~32 ~122 ~94 dirt
setblock ~32 ~122 ~95 dirt
setblock ~32 ~122 ~96 dirt
setblock ~32 ~122 ~97 dirt
setblock ~32 ~122 ~98 dirt
setblock ~32 ~122 ~99 dirt
setblock ~32 ~122 ~100 dirt
setblock ~32 ~122 ~101 dirt
setblock ~32 ~122 ~102 dirt
setblock ~32 ~122 ~103 dirt
setblock ~32 ~122 ~104 dirt
setblock ~32 ~122 ~105 dirt
setblock ~32 ~122 ~106 dirt
setblock ~32 ~122 ~107 dirt
setblock ~32 ~122 ~108 dirt
setblock ~32 ~122 ~109 dirt
setblock ~32 ~123 ~70 dirt
setblock ~32 ~123 ~71 dirt
setblock ~32 ~123 ~72 dirt
setblock ~32 ~123 ~73 dirt
setblock ~32 ~123 ~74 dirt
setblock ~32 ~123 ~75 dirt
setblock ~32 ~123 ~83 dirt
setblock ~32 ~123 ~84 dirt
setblock ~32 ~123 ~85 dirt
setblock ~32 ~123 ~94 dirt
setblock ~32 ~123 ~95 dirt
setblock ~32 ~123 ~96 dirt
setblock ~32 ~123 ~97 dirt
setblock ~32 ~123 ~98 dirt
setblock ~32 ~123 ~99 dirt
setblock ~32 ~123 ~100 dirt
setblock ~32 ~123 ~101 dirt
setblock ~32 ~123 ~102 dirt
setblock ~32 ~123 ~103 dirt
setblock ~32 ~123 ~104 dirt
setblock ~32 ~123 ~105 dirt
setblock ~32 ~123 ~106 dirt
setblock ~32 ~123 ~107 dirt
setblock ~32 ~123 ~108 grass_block
setblock ~32 ~123 ~109 grass_block
setblock ~32 ~124 ~70 dirt
setblock ~32 ~124 ~71 dirt
setblock ~32 ~124 ~72 dirt
setblock ~32 ~124 ~73 dirt
setblock ~32 ~124 ~74 dirt
setblock ~32 ~124 ~75 dirt
setblock ~32 ~124 ~83 dirt
setblock ~32 ~124 ~84 dirt
setblock ~32 ~124 ~85 dirt
setblock ~32 ~124 ~94 dirt
setblock ~32 ~124 ~95 dirt
setblock ~32 ~124 ~96 dirt
setblock ~32 ~124 ~97 dirt
setblock ~32 ~124 ~98 dirt
setblock ~32 ~124 ~99 dirt
setblock ~32 ~124 ~100 dirt
setblock ~32 ~124 ~101 dirt
setblock ~32 ~124 ~102 grass_block
setblock ~32 ~124 ~103 grass_block
setblock ~32 ~124 ~104 grass_block
setblock ~32 ~124 ~105 grass_block
setblock ~32 ~124 ~106 grass_block
setblock ~32 ~124 ~107 grass_block
setblock ~32 ~125 ~70 dirt
setblock ~32 ~125 ~71 dirt
setblock ~32 ~125 ~72 dirt
setblock ~32 ~125 ~73 dirt
setblock ~32 ~125 ~74 dirt
setblock ~32 ~125 ~75 dirt
setblock ~32 ~125 ~83 dirt
setblock ~32 ~125 ~84 dirt
setblock ~32 ~125 ~85 dirt
setblock ~32 ~125 ~94 grass_block
setblock ~32 ~125 ~95 grass_block
setblock ~32 ~125 ~96 grass_block
setblock ~32 ~125 ~97 grass_block
setblock ~32 ~125 ~98 grass_block
setblock ~32 ~125 ~99 grass_block
setblock ~32 ~125 ~100 grass_block
setblock ~32 ~125 ~101 grass_block
setblock ~32 ~126 ~70 dirt
setblock ~32 ~126 ~71 dirt
setblock ~32 ~126 ~72 dirt
setblock ~32 ~126 ~73 dirt
setblock ~32 ~126 ~74 dirt
setblock ~32 ~126 ~75 dirt
setblock ~32 ~126 ~83 dirt
setblock ~32 ~126 ~84 grass_block
setblock ~32 ~126 ~85 grass_block
setblock ~32 ~126 ~99 short_grass
setblock ~32 ~127 ~70 grass_block
setblock ~32 ~127 ~71 grass_block
setblock ~32 ~127 ~72 grass_block
setblock ~32 ~127 ~73 grass_block
setblock ~32 ~127 ~74 grass_block
setblock ~32 ~127 ~75 grass_block
setblock ~32 ~127 ~83 grass_block
setblock ~32 ~128 ~71 short_grass
setblock ~32 ~128 ~72 short_grass
setblock ~33 ~111 ~102 dirt
setblock ~33 ~111 ~103 dirt
setblock ~33 ~112 ~102 dirt
setblock ~33 ~112 ~103 dirt
setblock ~33 ~112 ~104 dirt
setblock ~33 ~113 ~98 dirt
setblock ~33 ~113 ~100 dirt
setblock ~33 ~113 ~101 dirt
setblock ~33 ~113 ~102 dirt
setblock ~33 ~113 ~103 dirt
setblock ~33 ~113 ~104 dirt
setblock ~33 ~113 ~105 dirt
setblock ~33 ~114 ~98 dirt
setblock ~33 ~114 ~99 dirt
setblock ~33 ~114 ~100 dirt
setblock ~33 ~114 ~101 dirt
setblock ~33 ~114 ~102 dirt
setblock ~33 ~114 ~103 dirt
setblock ~33 ~114 ~104 dirt
setblock ~33 ~114 ~105 dirt
setblock ~33 ~115 ~97 dirt
setblock ~33 ~115 ~98 dirt
setblock ~33 ~115 ~99 dirt
setblock ~33 ~115 ~100 dirt
setblock ~33 ~115 ~101 dirt
setblock ~33 ~115 ~102 dirt
setblock ~33 ~115 ~103 dirt
setblock ~33 ~115 ~104 dirt
setblock ~33 ~115 ~105 dirt
setblock ~33 ~115 ~106 dirt
setblock ~33 ~116 ~74 dirt
setblock ~33 ~116 ~97 dirt
setblock ~33 ~116 ~98 dirt
setblock ~33 ~116 ~99 dirt
setblock ~33 ~116 ~100 dirt
setblock ~33 ~116 ~101 dirt
setblock ~33 ~116 ~102 dirt
setblock ~33 ~116 ~103 dirt
setblock ~33 ~116 ~104 dirt
setblock ~33 ~116 ~105 dirt
setblock ~33 ~116 ~106 dirt
setblock ~33 ~116 ~107 dirt
setblock ~33 ~117 ~72 dirt
setblock ~33 ~117 ~73 dirt
setblock ~33 ~117 ~74 dirt
setblock ~33 ~117 ~96 dirt
setblock ~33 ~117 ~97 dirt
setblock ~33 ~117 ~98 dirt
setblock ~33 ~117 ~99 dirt
setblock ~33 ~117 ~100 dirt
setblock ~33 ~117 ~101 dirt
setblock ~33 ~117 ~102 dirt
setblock ~33 ~117 ~103 dirt
setblock ~33 ~117 ~104 dirt
setblock ~33 ~117 ~105 dirt
setblock ~33 ~117 ~106 dirt
setblock ~33 ~117 ~107 dirt
setblock ~33 ~117 ~108 dirt
setblock ~33 ~118 ~71 dirt
setblock ~33 ~118 ~72 dirt
setblock ~33 ~118 ~73 dirt
setblock ~33 ~118 ~74 dirt
setblock ~33 ~118 ~75 dirt
setblock ~33 ~118 ~84 dirt
setblock ~33 ~118 ~96 dirt
setblock ~33 ~118 ~97 dirt
setblock ~33 ~118 ~98 dirt
setblock ~33 ~118 ~99 dirt
setblock ~33 ~118 ~100 dirt
setblock ~33 ~118 ~101 dirt
setblock ~33 ~118 ~102 dirt
setblock ~33 ~118 ~103 dirt
setblock ~33 ~118 ~104 dirt
setblock ~33 ~118 ~105 dirt
setblock ~33 ~118 ~106 dirt
setblock ~33 ~118 ~107 dirt
setblock ~33 ~118 ~108 dirt
setblock ~33 ~119 ~70 dirt
setblock ~33 ~119 ~71 dirt
setblock ~33 ~119 ~72 dirt
setblock ~33 ~119 ~73 dirt
setblock ~33 ~119 ~74 dirt
setblock ~33 ~119 ~75 dirt
setblock ~33 ~119 ~83 dirt
setblock ~33 ~119 ~84 dirt
setblock ~33 ~119 ~86 dirt
setblock ~33 ~119 ~95 dirt
setblock ~33 ~119 ~96 dirt
setblock ~33 ~119 ~97 dirt
setblock ~33 ~119 ~98 dirt
setblock ~33 ~119 ~99 dirt
setblock ~33 ~119 ~100 dirt
setblock ~33 ~119 ~101 dirt
setblock ~33 ~119 ~102 dirt
setblock ~33 ~119 ~103 dirt
setblock ~33 ~119 ~104 dirt
setblock ~33 ~119 ~105 dirt
setblock ~33 ~119 ~106 dirt
setblock ~33 ~119 ~107 dirt
setblock ~33 ~119 ~108 dirt
setblock ~33 ~120 ~69 dirt
setblock ~33 ~120 ~70 dirt
setblock ~33 ~120 ~71 dirt
setblock ~33 ~120 ~72 dirt
setblock ~33 ~120 ~73 dirt
setblock ~33 ~120 ~74 dirt
setblock ~33 ~120 ~75 dirt
setblock ~33 ~120 ~76 dirt
setblock ~33 ~120 ~81 dirt
setblock ~33 ~120 ~82 dirt
setblock ~33 ~120 ~83 dirt
setblock ~33 ~120 ~84 dirt
setblock ~33 ~120 ~85 dirt
setblock ~33 ~120 ~86 dirt
setblock ~33 ~120 ~87 dirt
setblock ~33 ~120 ~95 dirt
setblock ~33 ~120 ~96 dirt
setblock ~33 ~120 ~97 dirt
setblock ~33 ~120 ~98 dirt
setblock ~33 ~120 ~99 dirt
setblock ~33 ~120 ~100 dirt
setblock ~33 ~120 ~101 dirt
setblock ~33 ~120 ~102 dirt
setblock ~33 ~120 ~103 dirt
setblock ~33 ~120 ~104 dirt
setblock ~33 ~120 ~105 dirt
setblock ~33 ~120 ~106 dirt
setblock ~33 ~120 ~107 dirt
setblock ~33 ~120 ~108 dirt
setblock ~33 ~121 ~68 dirt
setblock ~33 ~121 ~69 dirt
setblock ~33 ~121 ~70 dirt
setblock ~33 ~121 ~71 dirt
setblock ~33 ~121 ~72 dirt
setblock ~33 ~121 ~73 dirt
setblock ~33 ~121 ~74 dirt
setblock ~33 ~121 ~75 dirt
setblock ~33 ~121 ~76 dirt
setblock ~33 ~121 ~80 dirt
setblock ~33 ~121 ~81 dirt
setblock ~33 ~121 ~82 dirt
setblock ~33 ~121 ~83 dirt
setblock ~33 ~121 ~84 dirt
setblock ~33 ~121 ~85 dirt
setblock ~33 ~121 ~86 dirt
setblock ~33 ~121 ~87 dirt
setblock ~33 ~121 ~94 dirt
setblock ~33 ~121 ~95 dirt
setblock ~33 ~121 ~96 dirt
setblock ~33 ~121 ~97 dirt
setblock ~33 ~121 ~98 dirt
setblock ~33 ~121 ~99 dirt
setblock ~33 ~121 ~100 dirt
setblock ~33 ~121 ~101 dirt
setblock ~33 ~121 ~102 dirt
setblock ~33 ~121 ~103 dirt
setblock ~33 ~121 ~104 dirt
setblock ~33 ~121 ~105 dirt
setblock ~33 ~121 ~106 dirt
setblock ~33 ~121 ~107 dirt
setblock ~33 ~121 ~108 dirt
setblock ~33 ~121 ~109 dirt
setblock ~33 ~121 ~110 dirt
setblock ~33 ~121 ~112 dirt
setblock ~33 ~122 ~68 dirt
setblock ~33 ~122 ~69 dirt
setblock ~33 ~122 ~70 dirt
setblock ~33 ~122 ~71 dirt
setblock ~33 ~122 ~72 dirt
setblock ~33 ~122 ~73 dirt
setblock ~33 ~122 ~74 dirt
setblock ~33 ~122 ~75 dirt
setblock ~33 ~122 ~76 dirt
setblock ~33 ~122 ~80 dirt
setblock ~33 ~122 ~81 dirt
setblock ~33 ~122 ~82 dirt
setblock ~33 ~122 ~83 dirt
setblock ~33 ~122 ~84 dirt
setblock ~33 ~122 ~85 dirt
setblock ~33 ~122 ~86 dirt
setblock ~33 ~122 ~87 dirt
setblock ~33 ~122 ~94 dirt
setblock ~33 ~122 ~95 dirt
setblock ~33 ~122 ~96 dirt
setblock ~33 ~122 ~97 dirt
setblock ~33 ~122 ~98 dirt
setblock ~33 ~122 ~99 dirt
setblock ~33 ~122 ~100 dirt
setblock ~33 ~122 ~101 dirt
setblock ~33 ~122 ~102 dirt
setblock ~33 ~122 ~103 dirt
setblock ~33 ~122 ~104 dirt
setblock ~33 ~122 ~105 dirt
setblock ~33 ~122 ~106 dirt
setblock ~33 ~122 ~107 dirt
setblock ~33 ~122 ~108 dirt
setblock ~33 ~122 ~109 dirt
setblock ~33 ~122 ~110 dirt
setblock ~33 ~122 ~112 dirt
setblock ~33 ~123 ~68 dirt
setblock ~33 ~123 ~69 dirt
setblock ~33 ~123 ~70 dirt
setblock ~33 ~123 ~71 dirt
setblock ~33 ~123 ~72 dirt
setblock ~33 ~123 ~73 dirt
setblock ~33 ~123 ~74 dirt
setblock ~33 ~123 ~75 dirt
setblock ~33 ~123 ~76 dirt
setblock ~33 ~123 ~80 dirt
setblock ~33 ~123 ~81 dirt
setblock ~33 ~123 ~82 dirt
setblock ~33 ~123 ~83 dirt
setblock ~33 ~123 ~84 dirt
setblock ~33 ~123 ~85 dirt
setblock ~33 ~123 ~86 dirt
setblock ~33 ~123 ~87 dirt
setblock ~33 ~123 ~94 dirt
setblock ~33 ~123 ~95 dirt
setblock ~33 ~123 ~96 dirt
setblock ~33 ~123 ~97 dirt
setblock ~33 ~123 ~98 dirt
setblock ~33 ~123 ~99 dirt
setblock ~33 ~123 ~100 dirt
setblock ~33 ~123 ~101 dirt
setblock ~33 ~123 ~102 dirt
setblock ~33 ~123 ~103 dirt
setblock ~33 ~123 ~104 dirt
setblock ~33 ~123 ~105 dirt
setblock ~33 ~123 ~106 dirt
setblock ~33 ~123 ~107 dirt
setblock ~33 ~123 ~108 dirt
setblock ~33 ~123 ~109 dirt
setblock ~33 ~123 ~110 grass_block
setblock ~33 ~123 ~112 dirt
setblock ~33 ~124 ~68 dirt
setblock ~33 ~124 ~69 dirt
setblock ~33 ~124 ~70 dirt
setblock ~33 ~124 ~71 dirt
setblock ~33 ~124 ~72 dirt
setblock ~33 ~124 ~73 dirt
setblock ~33 ~124 ~74 dirt
setblock ~33 ~124 ~75 dirt
setblock ~33 ~124 ~76 dirt
setblock ~33 ~124 ~80 dirt
setblock ~33 ~124 ~81 dirt
setblock ~33 ~124 ~82 dirt
setblock ~33 ~124 ~83 dirt
setblock ~33 ~124 ~84 dirt
setblock ~33 ~124 ~85 dirt
setblock ~33 ~124 ~86 dirt
setblock ~33 ~124 ~87 dirt
setblock ~33 ~124 ~94 dirt
setblock ~33 ~124 ~95 dirt
setblock ~33 ~124 ~96 dirt
setblock ~33 ~124 ~97 dirt
setblock ~33 ~124 ~98 dirt
setblock ~33 ~124 ~99 dirt
setblock ~33 ~124 ~100 dirt
setblock ~33 ~124 ~101 dirt
setblock ~33 ~124 ~102 grass_block
setblock ~33 ~124 ~103 grass_block
setblock ~33 ~124 ~104 grass_block
setblock ~33 ~124 ~105 grass_block
setblock ~33 ~124 ~106 grass_block
setblock ~33 ~124 ~107 grass_block
setblock ~33 ~124 ~108 grass_block
setblock ~33 ~124 ~109 grass_block
setblock ~33 ~124 ~112 grass_block
setblock ~33 ~125 ~68 dirt
setblock ~33 ~125 ~69 dirt
setblock ~33 ~125 ~70 dirt
setblock ~33 ~125 ~71 dirt
setblock ~33 ~125 ~72 dirt
setblock ~33 ~125 ~73 dirt
setblock ~33 ~125 ~74 dirt
setblock ~33 ~125 ~75 dirt
setblock ~33 ~125 ~76 dirt
setblock ~33 ~125 ~80 dirt
setblock ~33 ~125 ~81 dirt
setblock ~33 ~125 ~82 dirt
setblock ~33 ~125 ~83 dirt
setblock ~33 ~125 ~84 dirt
setblock ~33 ~125 ~85 dirt
setblock ~33 ~125 ~86 dirt
setblock ~33 ~125 ~87 dirt
setblock ~33 ~125 ~94 grass_block
setblock ~33 ~125 ~95 grass_block
setblock ~33 ~125 ~96 grass_block
setblock ~33 ~125 ~97 grass_block
setblock ~33 ~125 ~98 grass_block
setblock ~33 ~125 ~99 grass_block
setblock ~33 ~125 ~100 grass_block
setblock ~33 ~125 ~101 grass_block
setblock ~33 ~125 ~105 short_grass
setblock ~33 ~125 ~108 short_grass
setblock ~33 ~126 ~68 grass_block
setblock ~33 ~126 ~69 grass_block
setblock ~33 ~126 ~70 dirt
setblock ~33 ~126 ~71 dirt
setblock ~33 ~126 ~72 dirt
setblock ~33 ~126 ~73 dirt
setblock ~33 ~126 ~74 dirt
setblock ~33 ~126 ~75 dirt
setblock ~33 ~126 ~76 dirt
setblock ~33 ~126 ~80 dirt
setblock ~33 ~126 ~81 dirt
setblock ~33 ~126 ~82 dirt
setblock ~33 ~126 ~83 grass_block
setblock ~33 ~126 ~84 grass_block
setblock ~33 ~126 ~85 grass_block
setblock ~33 ~126 ~86 grass_block
setblock ~33 ~126 ~87 grass_block
setblock ~33 ~126 ~98 short_grass
setblock ~33 ~127 ~69 short_grass
setblock ~33 ~127 ~70 grass_block
setblock ~33 ~127 ~71 grass_block
setblock ~33 ~127 ~72 grass_block
setblock ~33 ~127 ~73 grass_block
setblock ~33 ~127 ~74 grass_block
setblock ~33 ~127 ~75 grass_block
setblock ~33 ~127 ~76 grass_block
setblock ~33 ~127 ~80 grass_block
setblock ~33 ~127 ~81 grass_block
setblock ~33 ~127 ~82 grass_block
setblock ~33 ~127 ~83 short_grass
setblock ~33 ~127 ~84 poppy
setblock ~33 ~127 ~86 poppy
setblock ~33 ~128 ~74 poppy
setblock ~33 ~128 ~76 short_grass
setblock ~34 ~109 ~104 dirt
setblock ~34 ~110 ~102 dirt
setblock ~34 ~110 ~103 dirt
setblock ~34 ~110 ~104 dirt
setblock ~34 ~111 ~101 dirt
setblock ~34 ~111 ~102 dirt
setblock ~34 ~111 ~103 dirt
setblock ~34 ~111 ~104 dirt
setblock ~34 ~111 ~105 dirt
setblock ~34 ~112 ~98 dirt
setblock ~34 ~112 ~100 dirt
setblock ~34 ~112 ~101 dirt
setblock ~34 ~112 ~102 dirt
setblock ~34 ~112 ~103 dirt
setblock ~34 ~112 ~104 dirt
setblock ~34 ~112 ~105 dirt
setblock ~34 ~113 ~97 dirt
setblock ~34 ~113 ~98 dirt
setblock ~34 ~113 ~99 dirt
setblock ~34 ~113 ~100 dirt
setblock ~34 ~113 ~101 dirt
setblock ~34 ~113 ~102 dirt
setblock ~34 ~113 ~103 dirt
setblock ~34 ~113 ~104 dirt
setblock ~34 ~113 ~105 dirt
setblock ~34 ~113 ~106 dirt
setblock ~34 ~114 ~97 dirt
setblock ~34 ~114 ~98 dirt
setblock ~34 ~114 ~99 dirt
setblock ~34 ~114 ~100 dirt
setblock ~34 ~114 ~101 dirt
setblock ~34 ~114 ~102 dirt
setblock ~34 ~114 ~103 dirt
setblock ~34 ~114 ~104 dirt
setblock ~34 ~114 ~105 dirt
setblock ~34 ~114 ~106 dirt
setblock ~34 ~115 ~74 dirt
setblock ~34 ~115 ~84 dirt
setblock ~34 ~115 ~96 dirt
setblock ~34 ~115 ~97 dirt
setblock ~34 ~115 ~98 dirt
setblock ~34 ~115 ~99 dirt
setblock ~34 ~115 ~100 dirt
setblock ~34 ~115 ~101 dirt
setblock ~34 ~115 ~102 dirt
setblock ~34 ~115 ~103 dirt
setblock ~34 ~115 ~104 dirt
setblock ~34 ~115 ~105 dirt
setblock ~34 ~115 ~106 dirt
setblock ~34 ~115 ~107 dirt
setblock ~34 ~116 ~72 dirt
setblock ~34 ~116 ~73 dirt
setblock ~34 ~116 ~74 dirt
setblock ~34 ~116 ~75 dirt
setblock ~34 ~116 ~83 dirt
setblock ~34 ~116 ~84 dirt
setblock ~34 ~116 ~96 dirt
setblock ~34 ~116 ~97 dirt
setblock ~34 ~116 ~98 dirt
setblock ~34 ~116 ~99 dirt
setblock ~34 ~116 ~100 dirt
setblock ~34 ~116 ~101 dirt
setblock ~34 ~116 ~102 dirt
setblock ~34 ~116 ~103 dirt
setblock ~34 ~116 ~104 dirt
setblock ~34 ~116 ~105 dirt
setblock ~34 ~116 ~106 dirt
setblock ~34 ~116 ~107 dirt
setblock ~34 ~116 ~108 dirt
setblock ~34 ~117 ~70 dirt
setblock ~34 ~117 ~71 dirt
setblock ~34 ~117 ~72 dirt
setblock ~34 ~117 ~73 dirt
setblock ~34 ~117 ~74 dirt
setblock ~34 ~117 ~75 dirt
setblock ~34 ~117 ~83 dirt
setblock ~34 ~117 ~84 dirt
setblock ~34 ~117 ~95 dirt
setblock ~34 ~117 ~96 dirt
setblock ~34 ~117 ~97 dirt
setblock ~34 ~117 ~98 dirt
setblock ~34 ~117 ~99 dirt
setblock ~34 ~117 ~100 dirt
setblock ~34 ~117 ~101 dirt
setblock ~34 ~117 ~102 dirt
setblock ~34 ~117 ~103 dirt
setblock ~34 ~117 ~104 dirt
setblock ~34 ~117 ~105 dirt
setblock ~34 ~117 ~106 dirt
setblock ~34 ~117 ~107 dirt
setblock ~34 ~117 ~108 dirt
setblock ~34 ~118 ~70 dirt
setblock ~34 ~118 ~71 dirt
setblock ~34 ~118 ~72 dirt
setblock ~34 ~118 ~73 dirt
setblock ~34 ~118 ~74 dirt
setblock ~34 ~118 ~75 dirt
setblock ~34 ~118 ~76 dirt
setblock ~34 ~118 ~82 dirt
setblock ~34 ~118 ~83 dirt
setblock ~34 ~118 ~84 dirt
setblock ~34 ~118 ~85 dirt
setblock ~34 ~118 ~86 dirt
setblock ~34 ~118 ~87 dirt
setblock ~34 ~118 ~95 dirt
setblock ~34 ~118 ~96 dirt
setblock ~34 ~118 ~97 dirt
setblock ~34 ~118 ~98 dirt
setblock ~34 ~118 ~99 dirt
setblock ~34 ~118 ~100 dirt
setblock ~34 ~118 ~101 dirt
setblock ~34 ~118 ~102 dirt
setblock ~34 ~118 ~103 dirt
setblock ~34 ~118 ~104 dirt
setblock ~34 ~118 ~105 dirt
setblock ~34 ~118 ~106 dirt
setblock ~34 ~118 ~107 dirt
setblock ~34 ~118 ~108 dirt
setblock ~34 ~118 ~109 dirt
setblock ~34 ~119 ~70 dirt
setblock ~34 ~119 ~71 dirt
setblock ~34 ~119 ~72 dirt
setblock ~34 ~119 ~73 dirt
setblock ~34 ~119 ~74 dirt
setblock ~34 ~119 ~75 dirt
setblock ~34 ~119 ~76 dirt
setblock ~34 ~119 ~77 dirt
setblock ~34 ~119 ~80 dirt
setblock ~34 ~119 ~81 dirt
setblock ~34 ~119 ~82 dirt
setblock ~34 ~119 ~83 dirt
setblock ~34 ~119 ~84 dirt
setblock ~34 ~119 ~85 dirt
setblock ~34 ~119 ~86 dirt
setblock ~34 ~119 ~87 dirt
setblock ~34 ~119 ~88 dirt
setblock ~34 ~119 ~95 dirt
setblock ~34 ~119 ~96 dirt
setblock ~34 ~119 ~97 dirt
setblock ~34 ~119 ~98 dirt
setblock ~34 ~119 ~99 dirt
setblock ~34 ~119 ~100 dirt
setblock ~34 ~119 ~101 dirt
setblock ~34 ~119 ~102 dirt
setblock ~34 ~119 ~103 dirt
setblock ~34 ~119 ~104 dirt
setblock ~34 ~119 ~105 dirt
setblock ~34 ~119 ~106 dirt
setblock ~34 ~119 ~107 dirt
setblock ~34 ~119 ~108 dirt
setblock ~34 ~119 ~109 dirt
setblock ~34 ~119 ~110 dirt
setblock ~34 ~120 ~68 dirt
setblock ~34 ~120 ~69 dirt
setblock ~34 ~120 ~70 dirt
setblock ~34 ~120 ~71 dirt
setblock ~34 ~120 ~72 dirt
setblock ~34 ~120 ~73 dirt
setblock ~34 ~120 ~74 dirt
setblock ~34 ~120 ~75 dirt
setblock ~34 ~120 ~76 dirt
setblock ~34 ~120 ~77 dirt
setblock ~34 ~120 ~78 dirt
setblock ~34 ~120 ~80 dirt
setblock ~34 ~120 ~81 dirt
setblock ~34 ~120 ~82 dirt
setblock ~34 ~120 ~83 dirt
setblock ~34 ~120 ~84 dirt
setblock ~34 ~120 ~85 dirt
setblock ~34 ~120 ~86 dirt
setblock ~34 ~120 ~87 dirt
setblock ~34 ~120 ~88 dirt
setblock ~34 ~120 ~94 dirt
setblock ~34 ~120 ~95 dirt
setblock ~34 ~120 ~96 dirt
setblock ~34 ~120 ~97 dirt
setblock ~34 ~120 ~98 dirt
setblock ~34 ~120 ~99 dirt
setblock ~34 ~120 ~100 dirt
setblock ~34 ~120 ~101 dirt
setblock ~34 ~120 ~102 dirt
setblock ~34 ~120 ~103 dirt
setblock ~34 ~120 ~104 dirt
setblock ~34 ~120 ~105 dirt
setblock ~34 ~120 ~106 dirt
setblock ~34 ~120 ~107 dirt
setblock ~34 ~120 ~108 dirt
setblock ~34 ~120 ~109 dirt
setblock ~34 ~120 ~110 dirt
setblock ~34 ~120 ~112 dirt
setblock ~34 ~121 ~67 dirt
setblock ~34 ~121 ~68 dirt
setblock ~34 ~121 ~69 dirt
setblock ~34 ~121 ~70 dirt
setblock ~34 ~121 ~71 dirt
setblock ~34 ~121 ~72 dirt
setblock ~34 ~121 ~73 dirt
setblock ~34 ~121 ~74 dirt
setblock ~34 ~121 ~75 dirt
setblock ~34 ~121 ~76 dirt
setblock ~34 ~121 ~77 dirt
setblock ~34 ~121 ~78 dirt
setblock ~34 ~121 ~79 dirt
setblock ~34 ~121 ~80 dirt
setblock ~34 ~121 ~81 dirt
setblock ~34 ~121 ~82 dirt
setblock ~34 ~121 ~83 dirt
setblock ~34 ~121 ~84 dirt
setblock ~34 ~121 ~85 dirt
setblock ~34 ~121 ~86 dirt
setblock ~34 ~121 ~87 dirt
setblock ~34 ~121 ~88 dirt
setblock ~34 ~121 ~93 dirt
setblock ~34 ~121 ~94 dirt
setblock ~34 ~121 ~95 dirt
setblock ~34 ~121 ~96 dirt
setblock ~34 ~121 ~97 dirt
setblock ~34 ~121 ~98 dirt
setblock ~34 ~121 ~99 dirt
setblock ~34 ~121 ~100 dirt
setblock ~34 ~121 ~101 dirt
setblock ~34 ~121 ~102 dirt
setblock ~34 ~121 ~103 dirt
setblock ~34 ~121 ~104 dirt
setblock ~34 ~121 ~105 dirt
setblock ~34 ~121 ~106 dirt
setblock ~34 ~121 ~107 dirt
setblock ~34 ~121 ~108 dirt
setblock ~34 ~121 ~109 dirt
setblock ~34 ~121 ~110 dirt
setblock ~34 ~121 ~111 dirt
setblock ~34 ~121 ~112 dirt
setblock ~34 ~121 ~113 dirt
setblock ~34 ~122 ~67 dirt
setblock ~34 ~122 ~68 dirt
setblock ~34 ~122 ~69 dirt
setblock ~34 ~122 ~70 dirt
setblock ~34 ~122 ~71 dirt
setblock ~34 ~122 ~72 dirt
setblock ~34 ~122 ~73 dirt
setblock ~34 ~122 ~74 dirt
setblock ~34 ~122 ~75 dirt
setblock ~34 ~122 ~76 dirt
setblock ~34 ~122 ~77 dirt
setblock ~34 ~122 ~78 dirt
setblock ~34 ~122 ~79 dirt
setblock ~34 ~122 ~80 dirt
setblock ~34 ~122 ~81 dirt
setblock ~34 ~122 ~82 dirt
setblock ~34 ~122 ~83 dirt
setblock ~34 ~122 ~84 dirt
setblock ~34 ~122 ~85 dirt
setblock ~34 ~122 ~86 dirt
setblock ~34 ~122 ~87 dirt
setblock ~34 ~122 ~88 dirt
setblock ~34 ~122 ~93 dirt
setblock ~34 ~122 ~94 dirt
setblock ~34 ~122 ~95 dirt
setblock ~34 ~122 ~96 dirt
setblock ~34 ~122 ~97 dirt
setblock ~34 ~122 ~98 dirt
setblock ~34 ~122 ~99 dirt
setblock ~34 ~122 ~100 dirt
setblock ~34 ~122 ~101 dirt
setblock ~34 ~122 ~102 dirt
setblock ~34 ~122 ~103 dirt
setblock ~34 ~122 ~104 dirt
setblock ~34 ~122 ~105 dirt
setblock ~34 ~122 ~106 dirt
setblock ~34 ~122 ~107 dirt
setblock ~34 ~122 ~108 dirt
setblock ~34 ~122 ~109 dirt
setblock ~34 ~122 ~110 dirt
setblock ~34 ~122 ~111 dirt
setblock ~34 ~122 ~112 dirt
setblock ~34 ~122 ~113 dirt
setblock ~34 ~123 ~67 dirt
setblock ~34 ~123 ~68 dirt
setblock ~34 ~123 ~69 dirt
setblock ~34 ~123 ~70 dirt
setblock ~34 ~123 ~71 dirt
setblock ~34 ~123 ~72 dirt
setblock ~34 ~123 ~73 dirt
setblock ~34 ~123 ~74 dirt
setblock ~34 ~123 ~75 dirt
setblock ~34 ~123 ~76 dirt
setblock ~34 ~123 ~77 dirt
setblock ~34 ~123 ~78 dirt
setblock ~34 ~123 ~79 dirt
setblock ~34 ~123 ~80 dirt
setblock ~34 ~123 ~81 dirt
setblock ~34 ~123 ~82 dirt
setblock ~34 ~123 ~83 dirt
setblock ~34 ~123 ~84 dirt
setblock ~34 ~123 ~85 dirt
setblock ~34 ~123 ~86 dirt
setblock ~34 ~123 ~87 dirt
setblock ~34 ~123 ~88 dirt
setblock ~34 ~123 ~93 dirt
setblock ~34 ~123 ~94 dirt
setblock ~34 ~123 ~95 dirt
setblock ~34 ~123 ~96 dirt
setblock ~34 ~123 ~97 dirt
setblock ~34 ~123 ~98 dirt
setblock ~34 ~123 ~99 dirt
setblock ~34 ~123 ~100 dirt
setblock ~34 ~123 ~101 dirt
setblock ~34 ~123 ~102 dirt
setblock ~34 ~123 ~103 dirt
setblock ~34 ~123 ~104 dirt
setblock ~34 ~123 ~105 dirt
setblock ~34 ~123 ~106 dirt
setblock ~34 ~123 ~107 dirt
setblock ~34 ~123 ~108 dirt
setblock ~34 ~123 ~109 dirt
setblock ~34 ~123 ~110 dirt
setblock ~34 ~123 ~111 dirt
setblock ~34 ~123 ~112 dirt
setblock ~34 ~123 ~113 dirt
setblock ~34 ~124 ~67 dirt
setblock ~34 ~124 ~68 dirt
setblock ~34 ~124 ~69 dirt
setblock ~34 ~124 ~70 dirt
setblock ~34 ~124 ~71 dirt
setblock ~34 ~124 ~72 dirt
setblock ~34 ~124 ~73 dirt
setblock ~34 ~124 ~74 dirt
setblock ~34 ~124 ~75 dirt
setblock ~34 ~124 ~76 dirt
setblock ~34 ~124 ~77 dirt
setblock ~34 ~124 ~78 dirt
setblock ~34 ~124 ~79 dirt
setblock ~34 ~124 ~80 dirt
setblock ~34 ~124 ~81 dirt
setblock ~34 ~124 ~82 dirt
setblock ~34 ~124 ~83 dirt
setblock ~34 ~124 ~84 dirt
setblock ~34 ~124 ~85 dirt
setblock ~34 ~124 ~86 dirt
setblock ~34 ~124 ~87 dirt
setblock ~34 ~124 ~88 dirt
setblock ~34 ~124 ~93 dirt
setblock ~34 ~124 ~94 dirt
setblock ~34 ~124 ~95 dirt
setblock ~34 ~124 ~96 dirt
setblock ~34 ~124 ~97 dirt
setblock ~34 ~124 ~98 dirt
setblock ~34 ~124 ~99 dirt
setblock ~34 ~124 ~100 dirt
setblock ~34 ~124 ~101 dirt
setblock ~34 ~124 ~102 dirt
setblock ~34 ~124 ~103 grass_block
setblock ~34 ~124 ~104 grass_block
setblock ~34 ~124 ~105 grass_block
setblock ~34 ~124 ~106 grass_block
setblock ~34 ~124 ~107 grass_block
setblock ~34 ~124 ~108 grass_block
setblock ~34 ~124 ~109 grass_block
setblock ~34 ~124 ~110 grass_block
setblock ~34 ~124 ~111 grass_block
setblock ~34 ~124 ~112 grass_block
setblock ~34 ~124 ~113 grass_block
setblock ~34 ~125 ~67 grass_block
setblock ~34 ~125 ~68 dirt
setblock ~34 ~125 ~69 dirt
setblock ~34 ~125 ~70 dirt
setblock ~34 ~125 ~71 dirt
setblock ~34 ~125 ~72 dirt
setblock ~34 ~125 ~73 dirt
setblock ~34 ~125 ~74 dirt
setblock ~34 ~125 ~75 dirt
setblock ~34 ~125 ~76 dirt
setblock ~34 ~125 ~77 dirt
setblock ~34 ~125 ~78 dirt
setblock ~34 ~125 ~79 dirt
setblock ~34 ~125 ~80 dirt
setblock ~34 ~125 ~81 dirt
setblock ~34 ~125 ~82 dirt
setblock ~34 ~125 ~83 dirt
setblock ~34 ~125 ~84 dirt
setblock ~34 ~125 ~85 dirt
setblock ~34 ~125 ~86 dirt
setblock ~34 ~125 ~87 dirt
setblock ~34 ~125 ~88 grass_block
setblock ~34 ~125 ~93 grass_block
setblock ~34 ~125 ~94 grass_block
setblock ~34 ~125 ~95 grass_block
setblock ~34 ~125 ~96 grass_block
setblock ~34 ~125 ~97 grass_block
setblock ~34 ~125 ~98 grass_block
setblock ~34 ~125 ~99 grass_block
setblock ~34 ~125 ~100 grass_block
setblock ~34 ~125 ~101 grass_block
setblock ~34 ~125 ~102 grass_block
setblock ~34 ~125 ~104 short_grass
setblock ~34 ~125 ~105 short_grass
setblock ~34 ~125 ~109 poppy
setblock ~34 ~125 ~110 short_grass
setblock ~34 ~125 ~112 short_grass
setblock ~34 ~126 ~68 grass_block
setblock ~34 ~126 ~69 grass_block
setblock ~34 ~126 ~70 dirt
setblock ~34 ~126 ~71 dirt
setblock ~34 ~126 ~72 dirt
setblock ~34 ~126 ~73 dirt
setblock ~34 ~126 ~74 dirt
setblock ~34 ~126 ~75 dirt
setblock ~34 ~126 ~76 dirt
setblock ~34 ~126 ~77 dirt
setblock ~34 ~126 ~78 dirt
setblock ~34 ~126 ~79 dirt
setblock ~34 ~126 ~80 dirt
setblock ~34 ~126 ~81 grass_block
setblock ~34 ~126 ~82 grass_block
setblock ~34 ~126 ~83 grass_block
setblock ~34 ~126 ~84 grass_block
setblock ~34 ~126 ~85 grass_block
setblock ~34 ~126 ~86 grass_block
setblock ~34 ~126 ~87 grass_block
setblock ~34 ~126 ~102 poppy
setblock ~34 ~127 ~68 short_grass
setblock ~34 ~127 ~70 grass_block
setblock ~34 ~127 ~71 grass_block
setblock ~34 ~127 ~72 grass_block
setblock ~34 ~127 ~73 grass_block
setblock ~34 ~127 ~74 grass_block
setblock ~34 ~127 ~75 grass_block
setblock ~34 ~127 ~76 grass_block
setblock ~34 ~127 ~77 grass_block
setblock ~34 ~127 ~78 grass_block
setblock ~34 ~127 ~79 grass_block
setblock ~34 ~127 ~80 grass_block
setblock ~34 ~127 ~83 short_grass
setblock ~34 ~128 ~70 short_grass
setblock ~34 ~128 ~72 short_grass
setblock ~34 ~128 ~74 short_grass
setblock ~34 ~128 ~77 short_grass
setblock ~34 ~128 ~78 short_grass
setblock ~35 ~108 ~102 dirt
setblock ~35 ~108 ~103 dirt
setblock ~35 ~108 ~104 dirt
setblock ~35 ~109 ~102 dirt
setblock ~35 ~109 ~103 dirt
setblock ~35 ~109 ~104 dirt
setblock ~35 ~109 ~105 dirt
setblock ~35 ~110 ~101 dirt
setblock ~35 ~110 ~102 dirt
setblock ~35 ~110 ~103 dirt
setblock ~35 ~110 ~104 dirt
setblock ~35 ~110 ~105 dirt
setblock ~35 ~111 ~98 dirt
setblock ~35 ~111 ~99 dirt
setblock ~35 ~111 ~100 dirt
setblock ~35 ~111 ~101 dirt
setblock ~35 ~111 ~102 dirt
setblock ~35 ~111 ~103 dirt
setblock ~35 ~111 ~104 dirt
setblock ~35 ~111 ~105 dirt
setblock ~35 ~111 ~106 dirt
setblock ~35 ~112 ~97 dirt
setblock ~35 ~112 ~98 dirt
setblock ~35 ~112 ~99 dirt
setblock ~35 ~112 ~100 dirt
setblock ~35 ~112 ~101 dirt
setblock ~35 ~112 ~102 dirt
setblock ~35 ~112 ~103 dirt
setblock ~35 ~112 ~104 dirt
setblock ~35 ~112 ~105 dirt
setblock ~35 ~112 ~106 dirt
setblock ~35 ~112 ~107 dirt
setblock ~35 ~113 ~71 dirt
setblock ~35 ~113 ~72 dirt
setblock ~35 ~113 ~97 dirt
setblock ~35 ~113 ~98 dirt
setblock ~35 ~113 ~99 dirt
setblock ~35 ~113 ~100 dirt
setblock ~35 ~113 ~101 dirt
setblock ~35 ~113 ~102 dirt
setblock ~35 ~113 ~103 dirt
setblock ~35 ~113 ~104 dirt
setblock ~35 ~113 ~105 dirt
setblock ~35 ~113 ~106 dirt
setblock ~35 ~113 ~107 dirt
setblock ~35 ~113 ~108 dirt
setblock ~35 ~114 ~70 dirt
setblock ~35 ~114 ~71 dirt
setblock ~35 ~114 ~72 dirt
setblock ~35 ~114 ~73 dirt
setblock ~35 ~114 ~74 dirt
setblock ~35 ~114 ~84 dirt
setblock ~35 ~114 ~96 dirt
setblock ~35 ~114 ~97 dirt
setblock ~35 ~114 ~98 dirt
setblock ~35 ~114 ~99 dirt
setblock ~35 ~114 ~100 dirt
setblock ~35 ~114 ~101 dirt
setblock ~35 ~114 ~102 dirt
setblock ~35 ~114 ~103 dirt
setblock ~35 ~114 ~104 dirt
setblock ~35 ~114 ~105 dirt
setblock ~35 ~114 ~106 dirt
setblock ~35 ~114 ~107 dirt
setblock ~35 ~114 ~108 dirt
setblock ~35 ~114 ~109 dirt
setblock ~35 ~115 ~70 dirt
setblock ~35 ~115 ~71 dirt
setblock ~35 ~115 ~72 dirt
setblock ~35 ~115 ~73 dirt
setblock ~35 ~115 ~74 dirt
setblock ~35 ~115 ~75 dirt
setblock ~35 ~115 ~83 dirt
setblock ~35 ~115 ~84 dirt
setblock ~35 ~115 ~85 dirt
setblock ~35 ~115 ~95 dirt
setblock ~35 ~115 ~96 dirt
setblock ~35 ~115 ~97 dirt
setblock ~35 ~115 ~98 dirt
setblock ~35 ~115 ~99 dirt
setblock ~35 ~115 ~100 dirt
setblock ~35 ~115 ~101 dirt
setblock ~35 ~115 ~102 dirt
setblock ~35 ~115 ~103 dirt
setblock ~35 ~115 ~104 dirt
setblock ~35 ~115 ~105 dirt
setblock ~35 ~115 ~106 dirt
setblock ~35 ~115 ~107 dirt
setblock ~35 ~115 ~108 dirt
setblock ~35 ~115 ~109 dirt
setblock ~35 ~116 ~70 dirt
setblock ~35 ~116 ~71 dirt
setblock ~35 ~116 ~72 dirt
setblock ~35 ~116 ~73 dirt
setblock ~35 ~116 ~74 dirt
setblock ~35 ~116 ~75 dirt
setblock ~35 ~116 ~82 dirt
setblock ~35 ~116 ~83 dirt
setblock ~35 ~116 ~84 dirt
setblock ~35 ~116 ~85 dirt
setblock ~35 ~116 ~86 dirt
setblock ~35 ~116 ~95 dirt
setblock ~35 ~116 ~96 dirt
setblock ~35 ~116 ~97 dirt
setblock ~35 ~116 ~98 dirt
setblock ~35 ~116 ~99 dirt
setblock ~35 ~116 ~100 dirt
setblock ~35 ~116 ~101 dirt
setblock ~35 ~116 ~102 dirt
setblock ~35 ~116 ~103 dirt
setblock ~35 ~116 ~104 dirt
setblock ~35 ~116 ~105 dirt
setblock ~35 ~116 ~106 dirt
setblock ~35 ~116 ~107 dirt
setblock ~35 ~116 ~108 dirt
setblock ~35 ~116 ~109 dirt
setblock ~35 ~116 ~110 dirt
setblock ~35 ~117 ~68 dirt
setblock ~35 ~117 ~69 dirt
setblock ~35 ~117 ~70 dirt
setblock ~35 ~117 ~71 dirt
setblock ~35 ~117 ~72 dirt
setblock ~35 ~117 ~73 dirt
setblock ~35 ~117 ~74 dirt
setblock ~35 ~117 ~75 dirt
setblock ~35 ~117 ~76 dirt
setblock ~35 ~117 ~77 dirt
setblock ~35 ~117 ~82 dirt
setblock ~35 ~117 ~83 dirt
setblock ~35 ~117 ~84 dirt
setblock ~35 ~117 ~85 dirt
setblock ~35 ~117 ~86 dirt
setblock ~35 ~117 ~87 dirt
setblock ~35 ~117 ~94 dirt
setblock ~35 ~117 ~95 dirt
setblock ~35 ~117 ~96 dirt
setblock ~35 ~117 ~97 dirt
setblock ~35 ~117 ~98 dirt
setblock ~35 ~117 ~99 dirt
setblock ~35 ~117 ~100 dirt
setblock ~35 ~117 ~101 dirt
setblock ~35 ~117 ~102 dirt
setblock ~35 ~117 ~103 dirt
setblock ~35 ~117 ~104 dirt
setblock ~35 ~117 ~105 dirt
setblock ~35 ~117 ~106 dirt
setblock ~35 ~117 ~107 dirt
setblock ~35 ~117 ~108 dirt
setblock ~35 ~117 ~109 dirt
setblock ~35 ~117 ~110 dirt
setblock ~35 ~117 ~111 dirt
setblock ~35 ~118 ~68 dirt
setblock ~35 ~118 ~69 dirt
setblock ~35 ~118 ~70 dirt
setblock ~35 ~118 ~71 dirt
setblock ~35 ~118 ~72 dirt
setblock ~35 ~118 ~73 dirt
setblock ~35 ~118 ~74 dirt
setblock ~35 ~118 ~75 dirt
setblock ~35 ~118 ~76 dirt
setblock ~35 ~118 ~77 dirt
setblock ~35 ~118 ~78 dirt
setblock ~35 ~118 ~80 dirt
setblock ~35 ~118 ~81 dirt
setblock ~35 ~118 ~82 dirt
setblock ~35 ~118 ~83 dirt
setblock ~35 ~118 ~84 dirt
setblock ~35 ~118 ~85 dirt
setblock ~35 ~118 ~86 dirt
setblock ~35 ~118 ~87 dirt
setblock ~35 ~118 ~88 dirt
setblock ~35 ~118 ~93 dirt
setblock ~35 ~118 ~94 dirt
setblock ~35 ~118 ~95 dirt
setblock ~35 ~118 ~96 dirt
setblock ~35 ~118 ~97 dirt
setblock ~35 ~118 ~98 dirt
setblock ~35 ~118 ~99 dirt
setblock ~35 ~118 ~100 dirt
setblock ~35 ~118 ~101 dirt
setblock ~35 ~118 ~102 dirt
setblock ~35 ~118 ~103 dirt
setblock ~35 ~118 ~104 dirt
setblock ~35 ~118 ~105 dirt
setblock ~35 ~118 ~106 dirt
setblock ~35 ~118 ~107 dirt
setblock ~35 ~118 ~108 dirt
setblock ~35 ~118 ~109 dirt
setblock ~35 ~118 ~110 dirt
setblock ~35 ~118 ~111 dirt
setblock ~35 ~119 ~68 dirt
setblock ~35 ~119 ~69 dirt
setblock ~35 ~119 ~70 dirt
setblock ~35 ~119 ~71 dirt
setblock ~35 ~119 ~72 dirt
setblock ~35 ~119 ~73 dirt
setblock ~35 ~119 ~74 dirt
setblock ~35 ~119 ~75 dirt
setblock ~35 ~119 ~76 dirt
setblock ~35 ~119 ~77 dirt
setblock ~35 ~119 ~78 dirt
setblock ~35 ~119 ~79 dirt
setblock ~35 ~119 ~80 dirt
setblock ~35 ~119 ~81 dirt
setblock ~35 ~119 ~82 dirt
setblock ~35 ~119 ~83 dirt
setblock ~35 ~119 ~84 dirt
setblock ~35 ~119 ~85 dirt
setblock ~35 ~119 ~86 dirt
setblock ~35 ~119 ~87 dirt
setblock ~35 ~119 ~88 dirt
setblock ~35 ~119 ~89 dirt
setblock ~35 ~119 ~93 dirt
setblock ~35 ~119 ~94 dirt
setblock ~35 ~119 ~95 dirt
setblock ~35 ~119 ~96 dirt
setblock ~35 ~119 ~97 dirt
setblock ~35 ~119 ~98 dirt
setblock ~35 ~119 ~99 dirt
setblock ~35 ~119 ~100 dirt
setblock ~35 ~119 ~101 dirt
setblock ~35 ~119 ~102 dirt
setblock ~35 ~119 ~103 dirt
setblock ~35 ~119 ~104 dirt
setblock ~35 ~119 ~105 dirt
setblock ~35 ~119 ~106 dirt
setblock ~35 ~119 ~107 dirt
setblock ~35 ~119 ~108 dirt
setblock ~35 ~119 ~109 dirt
setblock ~35 ~119 ~110 dirt
setblock ~35 ~119 ~111 dirt
setblock ~35 ~119 ~112 dirt
setblock ~35 ~120 ~67 dirt
setblock ~35 ~120 ~68 dirt
setblock ~35 ~120 ~69 dirt
setblock ~35 ~120 ~70 dirt
setblock ~35 ~120 ~71 dirt
setblock ~35 ~120 ~72 dirt
setblock ~35 ~120 ~73 dirt
setblock ~35 ~120 ~74 dirt
setblock ~35 ~120 ~75 dirt
setblock ~35 ~120 ~76 dirt
setblock ~35 ~120 ~77 dirt
setblock ~35 ~120 ~78 dirt
setblock ~35 ~120 ~79 dirt
setblock ~35 ~120 ~80 dirt
setblock ~35 ~120 ~81 dirt
setblock ~35 ~120 ~82 dirt
setblock ~35 ~120 ~83 dirt
setblock ~35 ~120 ~84 dirt
setblock ~35 ~120 ~85 dirt
setblock ~35 ~120 ~86 dirt
setblock ~35 ~120 ~87 dirt
setblock ~35 ~120 ~88 dirt
setblock ~35 ~120 ~89 dirt
setblock ~35 ~120 ~92 dirt
setblock ~35 ~120 ~93 dirt
setblock ~35 ~120 ~94 dirt
setblock ~35 ~120 ~95 dirt
setblock ~35 ~120 ~96 dirt
setblock ~35 ~120 ~97 dirt
setblock ~35 ~120 ~98 dirt
setblock ~35 ~120 ~99 dirt
setblock ~35 ~120 ~100 dirt
setblock ~35 ~120 ~101 dirt
setblock ~35 ~120 ~102 dirt
setblock ~35 ~120 ~103 dirt
setblock ~35 ~120 ~104 dirt
setblock ~35 ~120 ~105 dirt
setblock ~35 ~120 ~106 dirt
setblock ~35 ~120 ~107 dirt
setblock ~35 ~120 ~108 dirt
setblock ~35 ~120 ~109 dirt
setblock ~35 ~120 ~110 dirt
setblock ~35 ~120 ~111 dirt
setblock ~35 ~120 ~112 dirt
setblock ~35 ~120 ~113 dirt
setblock ~35 ~121 ~66 dirt
setblock ~35 ~121 ~67 dirt
setblock ~35 ~121 ~68 dirt
setblock ~35 ~121 ~69 dirt
setblock ~35 ~121 ~70 dirt
setblock ~35 ~121 ~71 dirt
setblock ~35 ~121 ~72 dirt
setblock ~35 ~121 ~73 dirt
setblock ~35 ~121 ~74 dirt
setblock ~35 ~121 ~75 dirt
setblock ~35 ~121 ~76 dirt
setblock ~35 ~121 ~77 dirt
setblock ~35 ~121 ~78 dirt
setblock ~35 ~121 ~79 dirt
setblock ~35 ~121 ~80 dirt
setblock ~35 ~121 ~81 dirt
setblock ~35 ~121 ~82 dirt
setblock ~35 ~121 ~83 dirt
setblock ~35 ~121 ~84 dirt
setblock ~35 ~121 ~85 dirt
setblock ~35 ~121 ~86 dirt
setblock ~35 ~121 ~87 dirt
setblock ~35 ~121 ~88 dirt
setblock ~35 ~121 ~89 dirt
setblock ~35 ~121 ~90 dirt
setblock ~35 ~121 ~92 dirt
setblock ~35 ~121 ~93 dirt
setblock ~35 ~121 ~94 dirt
setblock ~35 ~121 ~95 dirt
setblock ~35 ~121 ~96 dirt
setblock ~35 ~121 ~97 dirt
setblock ~35 ~121 ~98 dirt
setblock ~35 ~121 ~99 dirt
setblock ~35 ~121 ~100 dirt
setblock ~35 ~121 ~101 dirt
setblock ~35 ~121 ~102 dirt
setblock ~35 ~121 ~103 dirt
setblock ~35 ~121 ~104 dirt
setblock ~35 ~121 ~105 dirt
setblock ~35 ~121 ~106 dirt
setblock ~35 ~121 ~107 dirt
setblock ~35 ~121 ~108 dirt
setblock ~35 ~121 ~109 dirt
setblock ~35 ~121 ~110 dirt
setblock ~35 ~121 ~111 dirt
setblock ~35 ~121 ~112 dirt
setblock ~35 ~121 ~113 dirt
setblock ~35 ~122 ~66 dirt
setblock ~35 ~122 ~67 dirt
setblock ~35 ~122 ~68 dirt
setblock ~35 ~122 ~69 dirt
setblock ~35 ~122 ~70 dirt
setblock ~35 ~122 ~71 dirt
setblock ~35 ~122 ~72 dirt
setblock ~35 ~122 ~73 dirt
setblock ~35 ~122 ~74 dirt
setblock ~35 ~122 ~75 dirt
setblock ~35 ~122 ~76 dirt
setblock ~35 ~122 ~77 dirt
setblock ~35 ~122 ~78 dirt
setblock ~35 ~122 ~79 dirt
setblock ~35 ~122 ~80 dirt
setblock ~35 ~122 ~81 dirt
setblock ~35 ~122 ~82 dirt
setblock ~35 ~122 ~83 dirt
setblock ~35 ~122 ~84 dirt
setblock ~35 ~122 ~85 dirt
setblock ~35 ~122 ~86 dirt
setblock ~35 ~122 ~87 dirt
setblock ~35 ~122 ~88 dirt
setblock ~35 ~122 ~89 dirt
setblock ~35 ~122 ~90 dirt
setblock ~35 ~122 ~92 dirt
setblock ~35 ~122 ~93 dirt
setblock ~35 ~122 ~94 dirt
setblock ~35 ~122 ~95 dirt
setblock ~35 ~122 ~96 dirt
setblock ~35 ~122 ~97 dirt
setblock ~35 ~122 ~98 dirt
setblock ~35 ~122 ~99 dirt
setblock ~35 ~122 ~100 dirt
setblock ~35 ~122 ~101 dirt
setblock ~35 ~122 ~102 dirt
setblock ~35 ~122 ~103 dirt
setblock ~35 ~122 ~104 dirt
setblock ~35 ~122 ~105 dirt
setblock ~35 ~122 ~106 dirt
setblock ~35 ~122 ~107 dirt
setblock ~35 ~122 ~108 dirt
setblock ~35 ~122 ~109 dirt
setblock ~35 ~122 ~110 dirt
setblock ~35 ~122 ~111 dirt
setblock ~35 ~122 ~112 dirt
setblock ~35 ~122 ~113 dirt
setblock ~35 ~123 ~66 dirt
setblock ~35 ~123 ~67 dirt
setblock ~35 ~123 ~68 dirt
setblock ~35 ~123 ~69 dirt
setblock ~35 ~123 ~70 dirt
setblock ~35 ~123 ~71 dirt
setblock ~35 ~123 ~72 dirt
setblock ~35 ~123 ~73 dirt
setblock ~35 ~123 ~74 dirt
setblock ~35 ~123 ~75 dirt
setblock ~35 ~123 ~76 dirt
setblock ~35 ~123 ~77 dirt
setblock ~35 ~123 ~78 dirt
setblock ~35 ~123 ~79 dirt
setblock ~35 ~123 ~80 dirt
setblock ~35 ~123 ~81 dirt
setblock ~35 ~123 ~82 dirt
setblock ~35 ~123 ~83 dirt
setblock ~35 ~123 ~84 dirt
setblock ~35 ~123 ~85 dirt
setblock ~35 ~123 ~86 dirt
setblock ~35 ~123 ~87 dirt
setblock ~35 ~123 ~88 dirt
setblock ~35 ~123 ~89 dirt
setblock ~35 ~123 ~90 dirt
setblock ~35 ~123 ~92 dirt
setblock ~35 ~123 ~93 dirt
setblock ~35 ~123 ~94 dirt
setblock ~35 ~123 ~95 dirt
setblock ~35 ~123 ~96 dirt
setblock ~35 ~123 ~97 dirt
setblock ~35 ~123 ~98 dirt
setblock ~35 ~123 ~99 dirt
setblock ~35 ~123 ~100 dirt
setblock ~35 ~123 ~101 dirt
setblock ~35 ~123 ~102 dirt
setblock ~35 ~123 ~103 dirt
setblock ~35 ~123 ~104 dirt
setblock ~35 ~123 ~105 dirt
setblock ~35 ~123 ~106 dirt
setblock ~35 ~123 ~107 dirt
setblock ~35 ~123 ~108 dirt
setblock ~35 ~123 ~109 dirt
setblock ~35 ~123 ~110 dirt
setblock ~35 ~123 ~111 dirt
setblock ~35 ~123 ~112 dirt
setblock ~35 ~123 ~113 dirt
setblock ~35 ~124 ~66 dirt
setblock ~35 ~124 ~67 dirt
setblock ~35 ~124 ~68 dirt
setblock ~35 ~124 ~69 dirt
setblock ~35 ~124 ~70 dirt
setblock ~35 ~124 ~71 dirt
setblock ~35 ~124 ~72 dirt
setblock ~35 ~124 ~73 dirt
setblock ~35 ~124 ~74 dirt
setblock ~35 ~124 ~75 dirt
setblock ~35 ~124 ~76 dirt
setblock ~35 ~124 ~77 dirt
setblock ~35 ~124 ~78 dirt
setblock ~35 ~124 ~79 dirt
setblock ~35 ~124 ~80 dirt
setblock ~35 ~124 ~81 dirt
setblock ~35 ~124 ~82 dirt
setblock ~35 ~124 ~83 dirt
setblock ~35 ~124 ~84 dirt
setblock ~35 ~124 ~85 dirt
setblock ~35 ~124 ~86 dirt
setblock ~35 ~124 ~87 dirt
setblock ~35 ~124 ~88 dirt
setblock ~35 ~124 ~89 dirt
setblock ~35 ~124 ~90 dirt
setblock ~35 ~124 ~92 dirt
setblock ~35 ~124 ~93 dirt
setblock ~35 ~124 ~94 dirt
setblock ~35 ~124 ~95 dirt
setblock ~35 ~124 ~96 dirt
setblock ~35 ~124 ~97 dirt
setblock ~35 ~124 ~98 dirt
setblock ~35 ~124 ~99 dirt
setblock ~35 ~124 ~100 dirt
setblock ~35 ~124 ~101 dirt
setblock ~35 ~124 ~102 dirt
setblock ~35 ~124 ~103 grass_block
setblock ~35 ~124 ~104 grass_block
setblock ~35 ~124 ~105 grass_block
setblock ~35 ~124 ~106 grass_block
setblock ~35 ~124 ~107 grass_block
setblock ~35 ~124 ~108 grass_block
setblock ~35 ~124 ~109 grass_block
setblock ~35 ~124 ~110 grass_block
setblock ~35 ~124 ~111 grass_block
setblock ~35 ~124 ~112 grass_block
setblock ~35 ~124 ~113 grass_block
setblock ~35 ~125 ~66 grass_block
setblock ~35 ~125 ~67 grass_block
setblock ~35 ~125 ~68 dirt
setblock ~35 ~125 ~69 dirt
setblock ~35 ~125 ~70 dirt
setblock ~35 ~125 ~71 dirt
setblock ~35 ~125 ~72 dirt
setblock ~35 ~125 ~73 dirt
setblock ~35 ~125 ~74 dirt
setblock ~35 ~125 ~75 dirt
setblock ~35 ~125 ~76 dirt
setblock ~35 ~125 ~77 dirt
setblock ~35 ~125 ~78 dirt
setblock ~35 ~125 ~79 dirt
setblock ~35 ~125 ~80 dirt
setblock ~35 ~125 ~81 dirt
setblock ~35 ~125 ~82 dirt
setblock ~35 ~125 ~83 dirt
setblock ~35 ~125 ~84 dirt
setblock ~35 ~125 ~85 dirt
setblock ~35 ~125 ~86 dirt
setblock ~35 ~125 ~87 dirt
setblock ~35 ~125 ~88 grass_block
setblock ~35 ~125 ~89 grass_block
setblock ~35 ~125 ~90 grass_block
setblock ~35 ~125 ~92 grass_block
setblock ~35 ~125 ~93 grass_block
setblock ~35 ~125 ~94 grass_block
setblock ~35 ~125 ~95 grass_block
setblock ~35 ~125 ~96 grass_block
setblock ~35 ~125 ~97 grass_block
setblock ~35 ~125 ~98 grass_block
setblock ~35 ~125 ~99 grass_block
setblock ~35 ~125 ~100 grass_block
setblock ~35 ~125 ~101 grass_block
setblock ~35 ~125 ~102 grass_block
setblock ~35 ~125 ~106 short_grass
setblock ~35 ~125 ~108 short_grass
setblock ~35 ~125 ~111 short_grass
setblock ~35 ~126 ~68 grass_block
setblock ~35 ~126 ~69 grass_block
setblock ~35 ~126 ~70 grass_block
setblock ~35 ~126 ~71 grass_block
setblock ~35 ~126 ~72 grass_block
setblock ~35 ~126 ~73 grass_block
setblock ~35 ~126 ~74 grass_block
setblock ~35 ~126 ~75 grass_block
setblock ~35 ~126 ~76 grass_block
setblock ~35 ~126 ~77 grass_block
setblock ~35 ~126 ~78 grass_block
setblock ~35 ~126 ~79 grass_block
setblock ~35 ~126 ~80 grass_block
setblock ~35 ~126 ~81 grass_block
setblock ~35 ~126 ~82 grass_block
setblock ~35 ~126 ~83 grass_block
setblock ~35 ~126 ~84 grass_block
setblock ~35 ~126 ~85 grass_block
setblock ~35 ~126 ~86 grass_block
setblock ~35 ~126 ~87 grass_block
setblock ~35 ~126 ~88 short_grass
setblock ~35 ~126 ~89 short_grass
setblock ~35 ~126 ~90 short_grass
setblock ~35 ~126 ~94 short_grass
setblock ~35 ~126 ~95 short_grass
setblock ~35 ~126 ~101 fern
setblock ~35 ~127 ~72 fern
setblock ~35 ~127 ~74 poppy
setblock ~35 ~127 ~85 short_grass
setblock ~36 ~106 ~102 dirt
setblock ~36 ~106 ~103 dirt
setblock ~36 ~107 ~102 dirt
setblock ~36 ~107 ~103 dirt
setblock ~36 ~107 ~104 dirt
setblock ~36 ~108 ~101 dirt
setblock ~36 ~108 ~102 dirt
setblock ~36 ~108 ~103 dirt
setblock ~36 ~108 ~104 dirt
setblock ~36 ~108 ~105 dirt
setblock ~36 ~109 ~98 dirt
setblock ~36 ~109 ~101 dirt
setblock ~36 ~109 ~102 dirt
setblock ~36 ~109 ~103 dirt
setblock ~36 ~109 ~104 dirt
setblock ~36 ~109 ~105 dirt
setblock ~36 ~109 ~106 dirt
setblock ~36 ~110 ~97 dirt
setblock ~36 ~110 ~98 dirt
setblock ~36 ~110 ~99 dirt
setblock ~36 ~110 ~100 dirt
setblock ~36 ~110 ~101 dirt
setblock ~36 ~110 ~102 dirt
setblock ~36 ~110 ~103 dirt
setblock ~36 ~110 ~104 dirt
setblock ~36 ~110 ~105 dirt
setblock ~36 ~110 ~106 dirt
setblock ~36 ~110 ~107 dirt
setblock ~36 ~111 ~97 dirt
setblock ~36 ~111 ~98 dirt
setblock ~36 ~111 ~99 dirt
setblock ~36 ~111 ~100 dirt
setblock ~36 ~111 ~101 dirt
setblock ~36 ~111 ~102 dirt
setblock ~36 ~111 ~103 dirt
setblock ~36 ~111 ~104 dirt
setblock ~36 ~111 ~105 dirt
setblock ~36 ~111 ~106 dirt
setblock ~36 ~111 ~107 dirt
setblock ~36 ~112 ~71 dirt
setblock ~36 ~112 ~72 dirt
setblock ~36 ~112 ~74 dirt
setblock ~36 ~112 ~96 dirt
setblock ~36 ~112 ~97 dirt
setblock ~36 ~112 ~98 dirt
setblock ~36 ~112 ~99 dirt
setblock ~36 ~112 ~100 dirt
setblock ~36 ~112 ~101 dirt
setblock ~36 ~112 ~102 dirt
setblock ~36 ~112 ~103 dirt
setblock ~36 ~112 ~104 dirt
setblock ~36 ~112 ~105 dirt
setblock ~36 ~112 ~106 dirt
setblock ~36 ~112 ~107 dirt
setblock ~36 ~112 ~108 dirt
setblock ~36 ~113 ~70 dirt
setblock ~36 ~113 ~71 dirt
setblock ~36 ~113 ~72 dirt
setblock ~36 ~113 ~73 dirt
setblock ~36 ~113 ~74 dirt
setblock ~36 ~113 ~75 dirt
setblock ~36 ~113 ~84 dirt
setblock ~36 ~113 ~96 dirt
setblock ~36 ~113 ~97 dirt
setblock ~36 ~113 ~98 dirt
setblock ~36 ~113 ~99 dirt
setblock ~36 ~113 ~100 dirt
setblock ~36 ~113 ~101 dirt
setblock ~36 ~113 ~102 dirt
setblock ~36 ~113 ~103 dirt
setblock ~36 ~113 ~104 dirt
setblock ~36 ~113 ~105 dirt
setblock ~36 ~113 ~106 dirt
setblock ~36 ~113 ~107 dirt
setblock ~36 ~113 ~108 dirt
setblock ~36 ~113 ~109 dirt
setblock ~36 ~114 ~69 dirt
setblock ~36 ~114 ~70 dirt
setblock ~36 ~114 ~71 dirt
setblock ~36 ~114 ~72 dirt
setblock ~36 ~114 ~73 dirt
setblock ~36 ~114 ~74 dirt
setblock ~36 ~114 ~75 dirt
setblock ~36 ~114 ~76 dirt
setblock ~36 ~114 ~83 dirt
setblock ~36 ~114 ~84 dirt
setblock ~36 ~114 ~85 dirt
setblock ~36 ~114 ~95 dirt
setblock ~36 ~114 ~96 dirt
setblock ~36 ~114 ~97 dirt
setblock ~36 ~114 ~98 dirt
setblock ~36 ~114 ~99 dirt
setblock ~36 ~114 ~100 dirt
setblock ~36 ~114 ~101 dirt
setblock ~36 ~114 ~102 dirt
setblock ~36 ~114 ~103 dirt
setblock ~36 ~114 ~104 dirt
setblock ~36 ~114 ~105 dirt
setblock ~36 ~114 ~106 dirt
setblock ~36 ~114 ~107 dirt
setblock ~36 ~114 ~108 dirt
setblock ~36 ~114 ~109 dirt
setblock ~36 ~114 ~110 dirt
setblock ~36 ~115 ~69 dirt
setblock ~36 ~115 ~70 dirt
setblock ~36 ~115 ~71 dirt
setblock ~36 ~115 ~72 dirt
setblock ~36 ~115 ~73 dirt
setblock ~36 ~115 ~74 dirt
setblock ~36 ~115 ~75 dirt
setblock ~36 ~115 ~76 dirt
setblock ~36 ~115 ~81 dirt
setblock ~36 ~115 ~82 dirt
setblock ~36 ~115 ~83 dirt
setblock ~36 ~115 ~84 dirt
setblock ~36 ~115 ~85 dirt
setblock ~36 ~115 ~86 dirt
setblock ~36 ~115 ~94 dirt
setblock ~36 ~115 ~95 dirt
setblock ~36 ~115 ~96 dirt
setblock ~36 ~115 ~97 dirt
setblock ~36 ~115 ~98 dirt
setblock ~36 ~115 ~99 dirt
setblock ~36 ~115 ~100 dirt
setblock ~36 ~115 ~101 dirt
setblock ~36 ~115 ~102 dirt
setblock ~36 ~115 ~103 dirt
setblock ~36 ~115 ~104 dirt
setblock ~36 ~115 ~105 dirt
setblock ~36 ~115 ~106 dirt
setblock ~36 ~115 ~107 dirt
setblock ~36 ~115 ~108 dirt
setblock ~36 ~115 ~109 dirt
setblock ~36 ~115 ~110 dirt
setblock ~36 ~116 ~68 dirt
setblock ~36 ~116 ~69 dirt
setblock ~36 ~116 ~70 dirt
setblock ~36 ~116 ~71 dirt
setblock ~36 ~116 ~72 dirt
setblock ~36 ~116 ~73 dirt
setblock ~36 ~116 ~74 dirt
setblock ~36 ~116 ~75 dirt
setblock ~36 ~116 ~76 dirt
setblock ~36 ~116 ~77 dirt
setblock ~36 ~116 ~78 dirt
setblock ~36 ~116 ~79 dirt
setblock ~36 ~116 ~80 dirt
setblock ~36 ~116 ~81 dirt
setblock ~36 ~116 ~82 dirt
setblock ~36 ~116 ~83 dirt
setblock ~36 ~116 ~84 dirt
setblock ~36 ~116 ~85 dirt
setblock ~36 ~116 ~86 dirt
setblock ~36 ~116 ~87 dirt
setblock ~36 ~116 ~94 dirt
setblock ~36 ~116 ~95 dirt
setblock ~36 ~116 ~96 dirt
setblock ~36 ~116 ~97 dirt
setblock ~36 ~116 ~98 dirt
setblock ~36 ~116 ~99 dirt
setblock ~36 ~116 ~100 dirt
