setblock ~176 ~129 ~72 jungle_leaves
setblock ~176 ~129 ~75 oak_leaves
setblock ~176 ~129 ~76 oak_leaves
setblock ~176 ~129 ~117 oak_leaves
setblock ~176 ~129 ~118 jungle_leaves
setblock ~176 ~130 ~62 oak_leaves
setblock ~176 ~130 ~63 oak_leaves
setblock ~176 ~130 ~65 oak_leaves
setblock ~176 ~130 ~67 jungle_leaves
setblock ~176 ~130 ~70 oak_leaves
setblock ~176 ~130 ~71 oak_wood
setblock ~176 ~130 ~72 oak_leaves
setblock ~176 ~130 ~112 jungle_leaves
setblock ~176 ~130 ~114 oak_leaves
setblock ~176 ~130 ~115 oak_leaves
setblock ~176 ~130 ~116 oak_leaves
setblock ~176 ~130 ~117 oak_leaves
setblock ~176 ~130 ~118 oak_leaves
setblock ~176 ~130 ~119 oak_leaves
setblock ~176 ~131 ~62 oak_leaves
setblock ~176 ~131 ~63 oak_wood
setblock ~176 ~131 ~64 oak_leaves
setblock ~176 ~131 ~65 oak_wood
setblock ~176 ~131 ~66 oak_leaves
setblock ~176 ~131 ~67 oak_leaves
setblock ~176 ~131 ~69 oak_leaves
setblock ~176 ~131 ~70 oak_wood
setblock ~176 ~131 ~71 oak_leaves
setblock ~176 ~131 ~72 oak_leaves
setblock ~176 ~131 ~104 oak_leaves
setblock ~176 ~131 ~105 oak_leaves
setblock ~176 ~131 ~106 oak_leaves
setblock ~176 ~131 ~111 oak_leaves
setblock ~176 ~131 ~112 oak_leaves
setblock ~176 ~131 ~113 oak_leaves
setblock ~176 ~131 ~114 oak_leaves
setblock ~176 ~131 ~115 oak_leaves
setblock ~176 ~131 ~116 oak_leaves
setblock ~176 ~131 ~117 oak_leaves
setblock ~176 ~131 ~118 jungle_leaves
setblock ~176 ~131 ~119 oak_leaves
setblock ~176 ~132 ~63 oak_leaves
setblock ~176 ~132 ~64 oak_leaves
setblock ~176 ~132 ~67 oak_leaves
setblock ~176 ~132 ~68 oak_leaves
setblock ~176 ~132 ~69 oak_leaves
setblock ~176 ~132 ~70 oak_leaves
setblock ~176 ~132 ~73 oak_leaves
setblock ~176 ~132 ~104 oak_leaves
setblock ~176 ~132 ~106 oak_leaves
setblock ~176 ~132 ~109 oak_leaves
setblock ~176 ~132 ~110 oak_leaves
setblock ~176 ~132 ~111 oak_leaves
setblock ~176 ~132 ~113 oak_wood
setblock ~176 ~132 ~114 oak_leaves
setblock ~176 ~132 ~115 oak_leaves
setblock ~176 ~132 ~116 oak_leaves
setblock ~176 ~132 ~118 oak_leaves
setblock ~176 ~133 ~64 jungle_leaves
setblock ~176 ~133 ~65 oak_leaves
setblock ~176 ~133 ~70 oak_leaves
setblock ~176 ~133 ~72 oak_leaves
setblock ~176 ~133 ~73 jungle_leaves
setblock ~176 ~133 ~105 oak_leaves
setblock ~176 ~133 ~106 oak_leaves
setblock ~176 ~133 ~110 jungle_leaves
setblock ~176 ~133 ~111 oak_wood
setblock ~176 ~133 ~112 oak_leaves
setblock ~176 ~133 ~113 oak_wood
setblock ~176 ~133 ~114 oak_wood
setblock ~176 ~133 ~115 oak_leaves
setblock ~176 ~133 ~116 jungle_leaves
setblock ~176 ~133 ~117 oak_leaves
setblock ~176 ~133 ~119 oak_leaves
setblock ~176 ~134 ~71 oak_leaves
setblock ~176 ~134 ~73 oak_leaves
setblock ~176 ~134 ~112 oak_leaves
setblock ~176 ~134 ~113 oak_wood
setblock ~176 ~134 ~115 oak_leaves
setblock ~176 ~134 ~116 oak_wood
setblock ~176 ~134 ~117 oak_wood
setblock ~176 ~134 ~119 oak_leaves
setblock ~176 ~135 ~68 oak_leaves
setblock ~176 ~135 ~70 oak_leaves
setblock ~176 ~135 ~71 oak_leaves
setblock ~176 ~135 ~72 jungle_leaves
setblock ~176 ~135 ~111 oak_leaves
setblock ~176 ~135 ~112 oak_leaves
setblock ~176 ~135 ~113 oak_leaves
setblock ~176 ~135 ~114 oak_leaves
setblock ~176 ~135 ~115 oak_wood
setblock ~176 ~136 ~63 jungle_leaves
setblock ~176 ~136 ~65 oak_leaves
setblock ~176 ~136 ~66 jungle_leaves
setblock ~176 ~136 ~68 jungle_leaves
setblock ~176 ~136 ~69 oak_leaves
setblock ~176 ~136 ~70 oak_leaves
setblock ~176 ~136 ~71 oak_leaves
setblock ~176 ~136 ~72 oak_leaves
setblock ~176 ~136 ~111 oak_leaves
setblock ~176 ~136 ~112 oak_leaves
setblock ~176 ~136 ~113 oak_leaves
setblock ~176 ~136 ~114 oak_leaves
setblock ~176 ~136 ~115 oak_leaves
setblock ~176 ~136 ~116 oak_wood
setblock ~176 ~136 ~118 oak_leaves
setblock ~176 ~136 ~119 oak_leaves
setblock ~176 ~137 ~63 oak_leaves
setblock ~176 ~137 ~64 oak_wood
setblock ~176 ~137 ~68 oak_leaves
setblock ~176 ~137 ~71 oak_leaves
setblock ~176 ~137 ~72 oak_leaves
setblock ~176 ~137 ~111 oak_leaves
setblock ~176 ~137 ~115 oak_leaves
setblock ~176 ~137 ~116 jungle_leaves
setblock ~176 ~137 ~117 jungle_leaves
setblock ~176 ~137 ~118 oak_leaves
setblock ~176 ~137 ~119 oak_leaves
setblock ~176 ~138 ~64 oak_leaves
setblock ~176 ~138 ~65 oak_leaves
setblock ~176 ~138 ~69 oak_leaves
setblock ~176 ~138 ~70 oak_leaves
setblock ~176 ~138 ~71 oak_leaves
setblock ~176 ~138 ~72 oak_leaves
setblock ~176 ~138 ~117 oak_leaves
setblock ~176 ~138 ~118 oak_leaves
setblock ~176 ~139 ~114 oak_leaves
setblock ~176 ~139 ~115 oak_leaves
setblock ~176 ~139 ~116 oak_leaves
setblock ~176 ~139 ~117 oak_leaves
setblock ~176 ~139 ~118 oak_leaves
setblock ~177 ~128 ~69 oak_leaves
setblock ~177 ~128 ~71 oak_leaves
setblock ~177 ~128 ~72 jungle_leaves
setblock ~177 ~129 ~62 oak_leaves
setblock ~177 ~129 ~64 oak_leaves
setblock ~177 ~129 ~66 oak_leaves
setblock ~177 ~129 ~70 oak_leaves
setblock ~177 ~129 ~71 oak_leaves
setblock ~177 ~129 ~72 oak_leaves
setblock ~177 ~129 ~73 oak_leaves
setblock ~177 ~129 ~108 oak_leaves
setblock ~177 ~129 ~109 oak_leaves
setblock ~177 ~129 ~111 oak_leaves
setblock ~177 ~130 ~63 oak_leaves
setblock ~177 ~130 ~64 oak_leaves
setblock ~177 ~130 ~65 oak_leaves
setblock ~177 ~130 ~69 oak_leaves
setblock ~177 ~130 ~71 oak_wood
setblock ~177 ~130 ~72 oak_leaves
setblock ~177 ~130 ~73 jungle_leaves
setblock ~177 ~130 ~109 oak_leaves
setblock ~177 ~130 ~110 oak_leaves
setblock ~177 ~130 ~111 oak_leaves
setblock ~177 ~130 ~112 oak_leaves
setblock ~177 ~130 ~113 oak_leaves
setblock ~177 ~131 ~62 oak_leaves
setblock ~177 ~131 ~63 oak_leaves
setblock ~177 ~131 ~65 oak_wood
setblock ~177 ~131 ~66 oak_leaves
setblock ~177 ~131 ~70 oak_leaves
setblock ~177 ~131 ~71 oak_leaves
setblock ~177 ~131 ~72 oak_leaves
setblock ~177 ~131 ~73 oak_leaves
setblock ~177 ~131 ~105 oak_leaves
setblock ~177 ~131 ~107 oak_leaves
setblock ~177 ~131 ~108 oak_leaves
setblock ~177 ~131 ~109 jungle_leaves
setblock ~177 ~131 ~110 oak_leaves
setblock ~177 ~131 ~112 oak_wood
setblock ~177 ~131 ~113 oak_leaves
setblock ~177 ~131 ~114 oak_leaves
setblock ~177 ~131 ~115 oak_leaves
setblock ~177 ~131 ~116 oak_leaves
setblock ~177 ~131 ~117 oak_leaves
setblock ~177 ~131 ~118 oak_leaves
setblock ~177 ~132 ~65 oak_leaves
setblock ~177 ~132 ~66 oak_leaves
setblock ~177 ~132 ~105 jungle_leaves
setblock ~177 ~132 ~106 oak_leaves
setblock ~177 ~132 ~107 oak_leaves
setblock ~177 ~132 ~110 oak_leaves
setblock ~177 ~132 ~111 oak_leaves
setblock ~177 ~132 ~112 oak_leaves
setblock ~177 ~132 ~113 jungle_leaves
setblock ~177 ~132 ~114 oak_leaves
setblock ~177 ~132 ~115 oak_leaves
setblock ~177 ~132 ~117 oak_leaves
setblock ~177 ~132 ~118 oak_leaves
setblock ~177 ~133 ~105 oak_leaves
setblock ~177 ~133 ~108 jungle_leaves
setblock ~177 ~133 ~109 oak_leaves
setblock ~177 ~133 ~110 oak_wood
setblock ~177 ~133 ~111 oak_leaves
setblock ~177 ~133 ~113 oak_wood
setblock ~177 ~133 ~114 oak_leaves
setblock ~177 ~133 ~116 jungle_leaves
setblock ~177 ~133 ~117 oak_wood
setblock ~177 ~133 ~118 oak_wood
setblock ~177 ~133 ~119 oak_leaves
setblock ~177 ~134 ~107 oak_leaves
setblock ~177 ~134 ~110 jungle_leaves
setblock ~177 ~134 ~111 oak_leaves
setblock ~177 ~134 ~114 oak_leaves
setblock ~177 ~134 ~115 oak_leaves
setblock ~177 ~134 ~116 oak_leaves
setblock ~177 ~134 ~117 oak_leaves
setblock ~177 ~134 ~118 oak_leaves
setblock ~177 ~135 ~110 oak_leaves
setblock ~177 ~135 ~112 oak_leaves
setblock ~177 ~135 ~113 oak_wood
setblock ~177 ~135 ~114 oak_wood
setblock ~177 ~135 ~116 oak_leaves
setblock ~177 ~135 ~117 oak_leaves
setblock ~177 ~135 ~118 jungle_leaves
setblock ~177 ~136 ~63 oak_leaves
setblock ~177 ~136 ~64 oak_leaves
setblock ~177 ~136 ~65 jungle_leaves
setblock ~177 ~136 ~111 oak_leaves
setblock ~177 ~136 ~112 oak_leaves
setblock ~177 ~136 ~113 oak_leaves
setblock ~177 ~136 ~114 oak_leaves
setblock ~177 ~136 ~115 jungle_leaves
setblock ~177 ~136 ~116 oak_leaves
setblock ~177 ~136 ~117 oak_leaves
setblock ~177 ~136 ~119 oak_leaves
setblock ~177 ~137 ~64 oak_leaves
setblock ~177 ~137 ~65 oak_leaves
setblock ~177 ~137 ~111 jungle_leaves
setblock ~177 ~137 ~112 oak_leaves
setblock ~177 ~137 ~115 oak_wood
setblock ~177 ~137 ~116 oak_wood
setblock ~177 ~138 ~63 jungle_leaves
setblock ~177 ~138 ~64 oak_leaves
setblock ~177 ~138 ~66 oak_leaves
setblock ~177 ~138 ~113 oak_leaves
setblock ~177 ~138 ~115 oak_leaves
setblock ~177 ~138 ~116 oak_leaves
setblock ~177 ~138 ~117 jungle_leaves
setblock ~178 ~129 ~62 oak_leaves
setblock ~178 ~129 ~63 jungle_leaves
setblock ~178 ~129 ~65 oak_leaves
setblock ~178 ~129 ~71 oak_leaves
setblock ~178 ~129 ~73 oak_leaves
setblock ~178 ~129 ~108 oak_leaves
setblock ~178 ~129 ~111 oak_leaves
setblock ~178 ~130 ~62 jungle_leaves
setblock ~178 ~130 ~63 jungle_leaves
setblock ~178 ~130 ~64 oak_leaves
setblock ~178 ~130 ~66 oak_leaves
setblock ~178 ~130 ~71 jungle_leaves
setblock ~178 ~130 ~72 jungle_leaves
setblock ~178 ~130 ~108 oak_leaves
setblock ~178 ~130 ~109 jungle_leaves
setblock ~178 ~130 ~112 oak_leaves
setblock ~178 ~130 ~113 oak_leaves
setblock ~178 ~131 ~62 oak_leaves
setblock ~178 ~131 ~63 oak_leaves
setblock ~178 ~131 ~64 jungle_leaves
setblock ~178 ~131 ~65 oak_leaves
setblock ~178 ~131 ~66 oak_leaves
setblock ~178 ~131 ~71 oak_leaves
setblock ~178 ~131 ~105 oak_leaves
setblock ~178 ~131 ~106 oak_leaves
setblock ~178 ~131 ~107 oak_leaves
setblock ~178 ~131 ~108 oak_leaves
setblock ~178 ~131 ~109 oak_leaves
setblock ~178 ~131 ~110 oak_leaves
setblock ~178 ~131 ~111 oak_wood
setblock ~178 ~131 ~112 oak_leaves
setblock ~178 ~131 ~113 oak_leaves
setblock ~178 ~131 ~118 oak_leaves
setblock ~178 ~132 ~62 oak_leaves
setblock ~178 ~132 ~63 oak_leaves
setblock ~178 ~132 ~64 oak_leaves
setblock ~178 ~132 ~65 oak_leaves
setblock ~178 ~132 ~106 oak_leaves
setblock ~178 ~132 ~107 jungle_leaves
setblock ~178 ~132 ~108 oak_leaves
setblock ~178 ~132 ~111 oak_leaves
setblock ~178 ~132 ~113 oak_leaves
setblock ~178 ~132 ~114 oak_leaves
setblock ~178 ~132 ~115 jungle_leaves
setblock ~178 ~132 ~116 oak_leaves
setblock ~178 ~132 ~118 oak_leaves
setblock ~178 ~133 ~105 oak_leaves
setblock ~178 ~133 ~106 oak_leaves
setblock ~178 ~133 ~108 oak_wood
setblock ~178 ~133 ~109 oak_wood
setblock ~178 ~133 ~110 oak_leaves
setblock ~178 ~133 ~111 oak_leaves
setblock ~178 ~133 ~112 oak_leaves
setblock ~178 ~133 ~113 oak_wood
setblock ~178 ~133 ~114 oak_leaves
setblock ~178 ~133 ~115 oak_leaves
setblock ~178 ~133 ~116 oak_leaves
setblock ~178 ~133 ~117 oak_leaves
setblock ~178 ~133 ~118 oak_leaves
setblock ~178 ~134 ~105 jungle_leaves
setblock ~178 ~134 ~106 oak_leaves
setblock ~178 ~134 ~107 oak_leaves
setblock ~178 ~134 ~108 oak_leaves
setblock ~178 ~134 ~109 oak_leaves
setblock ~178 ~134 ~111 oak_leaves
setblock ~178 ~134 ~112 oak_leaves
setblock ~178 ~134 ~114 oak_leaves
setblock ~178 ~134 ~117 oak_leaves
setblock ~178 ~134 ~118 oak_leaves
setblock ~178 ~135 ~112 oak_leaves
setblock ~178 ~135 ~113 jungle_leaves
setblock ~178 ~135 ~115 oak_leaves
setblock ~178 ~135 ~116 oak_leaves
setblock ~178 ~136 ~110 jungle_leaves
setblock ~178 ~136 ~111 oak_leaves
setblock ~178 ~136 ~112 oak_wood
setblock ~178 ~136 ~114 oak_wood
setblock ~178 ~136 ~115 oak_leaves
setblock ~178 ~136 ~117 oak_leaves
setblock ~178 ~137 ~110 oak_leaves
setblock ~178 ~137 ~111 oak_leaves
setblock ~178 ~137 ~112 oak_leaves
setblock ~178 ~137 ~114 oak_leaves
setblock ~178 ~137 ~116 oak_leaves
setblock ~178 ~138 ~114 oak_leaves
setblock ~178 ~138 ~115 jungle_leaves
setblock ~178 ~138 ~117 oak_leaves
setblock ~179 ~129 ~71 oak_leaves
setblock ~179 ~129 ~73 oak_leaves
setblock ~179 ~129 ~108 oak_leaves
setblock ~179 ~129 ~110 oak_leaves
setblock ~179 ~129 ~111 oak_leaves
setblock ~179 ~130 ~72 oak_leaves
setblock ~179 ~130 ~73 oak_leaves
setblock ~179 ~130 ~108 oak_leaves
setblock ~179 ~130 ~109 oak_leaves
setblock ~179 ~130 ~110 oak_leaves
setblock ~179 ~130 ~111 oak_leaves
setblock ~179 ~131 ~71 jungle_leaves
setblock ~179 ~131 ~72 oak_leaves
setblock ~179 ~131 ~73 oak_leaves
setblock ~179 ~131 ~105 oak_leaves
setblock ~179 ~131 ~106 oak_leaves
setblock ~179 ~131 ~107 oak_leaves
setblock ~179 ~131 ~109 oak_leaves
setblock ~179 ~131 ~110 oak_leaves
setblock ~179 ~131 ~111 oak_leaves
setblock ~179 ~131 ~112 jungle_leaves
setblock ~179 ~131 ~113 jungle_leaves
setblock ~179 ~131 ~114 oak_leaves
setblock ~179 ~132 ~106 oak_leaves
setblock ~179 ~132 ~107 jungle_leaves
setblock ~179 ~132 ~108 oak_leaves
setblock ~179 ~132 ~109 oak_leaves
setblock ~179 ~132 ~110 oak_leaves
setblock ~179 ~132 ~111 oak_leaves
setblock ~179 ~132 ~113 oak_leaves
setblock ~179 ~132 ~114 oak_leaves
setblock ~179 ~133 ~105 oak_leaves
setblock ~179 ~133 ~107 oak_leaves
setblock ~179 ~133 ~111 oak_leaves
setblock ~179 ~133 ~112 oak_leaves
setblock ~179 ~133 ~113 oak_wood
setblock ~179 ~134 ~105 oak_leaves
setblock ~179 ~134 ~106 oak_leaves
setblock ~179 ~134 ~107 jungle_leaves
setblock ~179 ~134 ~108 oak_leaves
setblock ~179 ~134 ~109 oak_leaves
setblock ~179 ~134 ~110 oak_leaves
setblock ~179 ~134 ~111 oak_leaves
setblock ~179 ~134 ~112 jungle_leaves
setblock ~179 ~134 ~115 oak_leaves
setblock ~179 ~135 ~111 oak_leaves
setblock ~179 ~135 ~112 oak_leaves
setblock ~179 ~135 ~114 oak_leaves
setblock ~179 ~136 ~110 oak_leaves
setblock ~179 ~136 ~111 jungle_leaves
setblock ~179 ~136 ~112 oak_leaves
setblock ~179 ~136 ~113 oak_wood
setblock ~179 ~136 ~114 oak_leaves
setblock ~179 ~136 ~115 oak_leaves
setblock ~179 ~137 ~110 jungle_leaves
setblock ~179 ~137 ~111 oak_leaves
setblock ~179 ~137 ~112 jungle_leaves
setblock ~179 ~137 ~113 oak_leaves
setblock ~179 ~137 ~115 oak_leaves
setblock ~180 ~129 ~109 oak_leaves
setblock ~180 ~129 ~110 oak_leaves
setblock ~180 ~129 ~111 oak_leaves
setblock ~180 ~130 ~108 oak_leaves
setblock ~180 ~130 ~109 oak_leaves
setblock ~180 ~130 ~110 jungle_leaves
setblock ~180 ~130 ~111 jungle_leaves
setblock ~180 ~131 ~106 jungle_leaves
setblock ~180 ~131 ~108 jungle_leaves
setblock ~180 ~131 ~109 jungle_leaves
setblock ~180 ~131 ~111 oak_leaves
setblock ~180 ~132 ~105 oak_leaves
setblock ~180 ~132 ~106 oak_leaves
setblock ~180 ~132 ~108 oak_leaves
setblock ~180 ~132 ~110 oak_leaves
setblock ~180 ~132 ~111 oak_leaves
setblock ~180 ~132 ~112 oak_leaves
setblock ~180 ~132 ~114 oak_leaves
setblock ~180 ~133 ~105 oak_leaves
setblock ~180 ~133 ~106 oak_leaves
setblock ~180 ~133 ~107 jungle_leaves
setblock ~180 ~133 ~113 oak_leaves
setblock ~180 ~133 ~114 oak_leaves
setblock ~180 ~134 ~105 oak_leaves
setblock ~180 ~134 ~106 oak_leaves
setblock ~180 ~134 ~108 jungle_leaves
setblock ~180 ~134 ~110 oak_leaves
setblock ~180 ~134 ~113 oak_leaves
setblock ~180 ~134 ~114 oak_leaves
setblock ~180 ~135 ~110 oak_leaves
setblock ~180 ~135 ~111 jungle_leaves
setblock ~180 ~135 ~112 oak_leaves
setblock ~180 ~135 ~113 oak_leaves
setblock ~180 ~136 ~111 oak_leaves
setblock ~180 ~136 ~112 oak_leaves
setblock ~180 ~136 ~113 jungle_leaves
setblock ~180 ~136 ~114 oak_leaves
setblock ~180 ~137 ~110 oak_leaves
setblock ~180 ~137 ~111 oak_leaves
setblock ~180 ~137 ~114 jungle_leaves
setblock ~199 ~200 ~199 gold_block
