setblock ~186 ~123 ~118 dirt
setblock ~186 ~123 ~119 dirt
setblock ~186 ~123 ~120 dirt
setblock ~186 ~123 ~121 dirt
setblock ~186 ~123 ~122 dirt
setblock ~186 ~123 ~123 dirt
setblock ~186 ~123 ~124 dirt
setblock ~186 ~123 ~125 dirt
setblock ~186 ~123 ~126 dirt
setblock ~186 ~123 ~127 dirt
setblock ~186 ~123 ~128 dirt
setblock ~186 ~123 ~129 dirt
setblock ~186 ~123 ~130 dirt
setblock ~186 ~123 ~131 dirt
setblock ~186 ~123 ~132 dirt
setblock ~186 ~123 ~133 dirt
setblock ~186 ~123 ~134 dirt
setblock ~186 ~123 ~135 grass_block
setblock ~186 ~123 ~136 grass_block
setblock ~186 ~123 ~137 grass_block
setblock ~186 ~123 ~138 grass_block
setblock ~186 ~123 ~139 grass_block
setblock ~186 ~123 ~140 grass_block
setblock ~186 ~123 ~141 grass_block
setblock ~186 ~123 ~142 grass_block
setblock ~186 ~123 ~143 grass_block
setblock ~186 ~123 ~144 grass_block
setblock ~186 ~123 ~145 dirt
setblock ~186 ~123 ~146 dirt
setblock ~186 ~124 ~58 dirt
setblock ~186 ~124 ~59 dirt
setblock ~186 ~124 ~60 dirt
setblock ~186 ~124 ~61 dirt
setblock ~186 ~124 ~62 dirt
setblock ~186 ~124 ~63 dirt
setblock ~186 ~124 ~64 dirt
setblock ~186 ~124 ~65 dirt
setblock ~186 ~124 ~66 dirt
setblock ~186 ~124 ~69 dirt
setblock ~186 ~124 ~70 dirt
setblock ~186 ~124 ~74 dirt
setblock ~186 ~124 ~75 dirt
setblock ~186 ~124 ~76 dirt
setblock ~186 ~124 ~77 dirt
setblock ~186 ~124 ~78 dirt
setblock ~186 ~124 ~79 dirt
setblock ~186 ~124 ~80 grass_block
setblock ~186 ~124 ~81 grass_block
setblock ~186 ~124 ~82 grass_block
setblock ~186 ~124 ~83 grass_block
setblock ~186 ~124 ~84 grass_block
setblock ~186 ~124 ~85 grass_block
setblock ~186 ~124 ~86 grass_block
setblock ~186 ~124 ~87 grass_block
setblock ~186 ~124 ~88 grass_block
setblock ~186 ~124 ~89 grass_block
setblock ~186 ~124 ~91 grass_block
setblock ~186 ~124 ~92 grass_block
setblock ~186 ~124 ~98 dirt
setblock ~186 ~124 ~99 dirt
setblock ~186 ~124 ~100 dirt
setblock ~186 ~124 ~101 dirt
setblock ~186 ~124 ~102 dirt
setblock ~186 ~124 ~103 dirt
setblock ~186 ~124 ~104 dirt
setblock ~186 ~124 ~105 dirt
setblock ~186 ~124 ~106 dirt
setblock ~186 ~124 ~107 dirt
setblock ~186 ~124 ~108 dirt
setblock ~186 ~124 ~109 dirt
setblock ~186 ~124 ~110 dirt
setblock ~186 ~124 ~111 dirt
setblock ~186 ~124 ~112 dirt
setblock ~186 ~124 ~113 dirt
setblock ~186 ~124 ~114 dirt
setblock ~186 ~124 ~115 grass_block
setblock ~186 ~124 ~116 grass_block
setblock ~186 ~124 ~117 grass_block
setblock ~186 ~124 ~118 grass_block
setblock ~186 ~124 ~119 grass_block
setblock ~186 ~124 ~120 grass_block
setblock ~186 ~124 ~121 grass_block
setblock ~186 ~124 ~122 grass_block
setblock ~186 ~124 ~123 grass_block
setblock ~186 ~124 ~124 grass_block
setblock ~186 ~124 ~125 grass_block
setblock ~186 ~124 ~126 grass_block
setblock ~186 ~124 ~127 grass_block
setblock ~186 ~124 ~128 grass_block
setblock ~186 ~124 ~129 grass_block
setblock ~186 ~124 ~130 grass_block
setblock ~186 ~124 ~131 grass_block
setblock ~186 ~124 ~132 grass_block
setblock ~186 ~124 ~133 grass_block
setblock ~186 ~124 ~134 grass_block
setblock ~186 ~124 ~137 poppy
setblock ~186 ~124 ~138 short_grass
setblock ~186 ~124 ~141 short_grass
setblock ~186 ~124 ~144 short_grass
setblock ~186 ~124 ~145 grass_block
setblock ~186 ~124 ~146 grass_block
setblock ~186 ~125 ~58 dirt
setblock ~186 ~125 ~59 dirt
setblock ~186 ~125 ~60 dirt
setblock ~186 ~125 ~61 dirt
setblock ~186 ~125 ~62 dirt
setblock ~186 ~125 ~63 dirt
setblock ~186 ~125 ~64 dirt
setblock ~186 ~125 ~65 dirt
setblock ~186 ~125 ~66 dirt
setblock ~186 ~125 ~69 dirt
setblock ~186 ~125 ~70 dirt
setblock ~186 ~125 ~74 dirt
setblock ~186 ~125 ~75 dirt
setblock ~186 ~125 ~76 dirt
setblock ~186 ~125 ~77 grass_block
setblock ~186 ~125 ~78 grass_block
setblock ~186 ~125 ~79 grass_block
setblock ~186 ~125 ~84 short_grass
setblock ~186 ~125 ~87 short_grass
setblock ~186 ~125 ~88 short_grass
setblock ~186 ~125 ~89 fern
setblock ~186 ~125 ~92 fern
setblock ~186 ~125 ~98 dirt
setblock ~186 ~125 ~99 dirt
setblock ~186 ~125 ~100 dirt
setblock ~186 ~125 ~101 dirt
setblock ~186 ~125 ~102 dirt
setblock ~186 ~125 ~103 dirt
setblock ~186 ~125 ~104 dirt
setblock ~186 ~125 ~105 dirt
setblock ~186 ~125 ~106 dirt
setblock ~186 ~125 ~107 dirt
setblock ~186 ~125 ~108 dirt
setblock ~186 ~125 ~109 dirt
setblock ~186 ~125 ~110 grass_block
setblock ~186 ~125 ~111 grass_block
setblock ~186 ~125 ~112 grass_block
setblock ~186 ~125 ~113 grass_block
setblock ~186 ~125 ~114 grass_block
setblock ~186 ~125 ~116 short_grass
setblock ~186 ~125 ~119 short_grass
setblock ~186 ~125 ~127 short_grass
setblock ~186 ~125 ~128 short_grass
setblock ~186 ~125 ~129 short_grass
setblock ~186 ~125 ~131 short_grass
setblock ~186 ~125 ~145 poppy
setblock ~186 ~126 ~58 grass_block
setblock ~186 ~126 ~59 grass_block
setblock ~186 ~126 ~60 grass_block
setblock ~186 ~126 ~61 grass_block
setblock ~186 ~126 ~62 grass_block
setblock ~186 ~126 ~63 grass_block
setblock ~186 ~126 ~64 dirt
setblock ~186 ~126 ~65 dirt
setblock ~186 ~126 ~66 dirt
setblock ~186 ~126 ~69 dirt
setblock ~186 ~126 ~70 dirt
setblock ~186 ~126 ~74 grass_block
setblock ~186 ~126 ~75 grass_block
setblock ~186 ~126 ~76 grass_block
setblock ~186 ~126 ~98 dirt
setblock ~186 ~126 ~99 dirt
setblock ~186 ~126 ~100 dirt
setblock ~186 ~126 ~101 dirt
setblock ~186 ~126 ~102 dirt
setblock ~186 ~126 ~103 dirt
setblock ~186 ~126 ~104 dirt
setblock ~186 ~126 ~105 dirt
setblock ~186 ~126 ~106 dirt
setblock ~186 ~126 ~107 dirt
setblock ~186 ~126 ~108 grass_block
setblock ~186 ~126 ~109 grass_block
setblock ~186 ~126 ~113 short_grass
setblock ~186 ~126 ~114 poppy
setblock ~186 ~127 ~58 short_grass
setblock ~186 ~127 ~60 fern
setblock ~186 ~127 ~61 short_grass
setblock ~186 ~127 ~63 short_grass
setblock ~186 ~127 ~64 grass_block
setblock ~186 ~127 ~65 grass_block
setblock ~186 ~127 ~66 grass_block
setblock ~186 ~127 ~69 grass_block
setblock ~186 ~127 ~70 grass_block
setblock ~186 ~127 ~98 grass_block
setblock ~186 ~127 ~99 dirt
setblock ~186 ~127 ~100 dirt
setblock ~186 ~127 ~101 dirt
setblock ~186 ~127 ~102 dirt
setblock ~186 ~127 ~103 dirt
setblock ~186 ~127 ~104 dirt
setblock ~186 ~127 ~105 dirt
setblock ~186 ~127 ~106 grass_block
setblock ~186 ~127 ~107 grass_block
setblock ~186 ~128 ~65 short_grass
setblock ~186 ~128 ~69 short_grass
setblock ~186 ~128 ~99 grass_block
setblock ~186 ~128 ~100 dirt
setblock ~186 ~128 ~101 dirt
setblock ~186 ~128 ~102 grass_block
setblock ~186 ~128 ~103 grass_block
setblock ~186 ~128 ~104 grass_block
setblock ~186 ~128 ~105 grass_block
setblock ~186 ~129 ~100 grass_block
setblock ~186 ~129 ~101 grass_block
setblock ~186 ~129 ~103 short_grass
setblock ~186 ~129 ~104 short_grass
setblock ~186 ~130 ~101 poppy
setblock ~187 ~111 ~103 dirt
setblock ~187 ~112 ~63 dirt
setblock ~187 ~112 ~103 dirt
setblock ~187 ~113 ~63 dirt
setblock ~187 ~113 ~102 dirt
setblock ~187 ~113 ~103 dirt
setblock ~187 ~113 ~104 dirt
setblock ~187 ~113 ~126 dirt
setblock ~187 ~114 ~62 dirt
setblock ~187 ~114 ~63 dirt
setblock ~187 ~114 ~64 dirt
setblock ~187 ~114 ~79 dirt
setblock ~187 ~114 ~102 dirt
setblock ~187 ~114 ~103 dirt
setblock ~187 ~114 ~104 dirt
setblock ~187 ~114 ~125 dirt
setblock ~187 ~114 ~126 dirt
setblock ~187 ~114 ~127 dirt
setblock ~187 ~115 ~61 dirt
setblock ~187 ~115 ~62 dirt
setblock ~187 ~115 ~63 dirt
setblock ~187 ~115 ~64 dirt
setblock ~187 ~115 ~79 dirt
setblock ~187 ~115 ~101 dirt
setblock ~187 ~115 ~102 dirt
setblock ~187 ~115 ~103 dirt
setblock ~187 ~115 ~104 dirt
setblock ~187 ~115 ~120 dirt
setblock ~187 ~115 ~122 dirt
setblock ~187 ~115 ~125 dirt
setblock ~187 ~115 ~126 dirt
setblock ~187 ~115 ~127 dirt
setblock ~187 ~115 ~130 dirt
setblock ~187 ~116 ~61 dirt
setblock ~187 ~116 ~62 dirt
setblock ~187 ~116 ~63 dirt
setblock ~187 ~116 ~64 dirt
setblock ~187 ~116 ~78 dirt
setblock ~187 ~116 ~79 dirt
setblock ~187 ~116 ~80 dirt
setblock ~187 ~116 ~101 dirt
setblock ~187 ~116 ~102 dirt
setblock ~187 ~116 ~103 dirt
setblock ~187 ~116 ~104 dirt
setblock ~187 ~116 ~105 dirt
setblock ~187 ~116 ~119 dirt
setblock ~187 ~116 ~120 dirt
setblock ~187 ~116 ~121 dirt
setblock ~187 ~116 ~122 dirt
setblock ~187 ~116 ~125 dirt
setblock ~187 ~116 ~126 dirt
setblock ~187 ~116 ~127 dirt
setblock ~187 ~116 ~128 dirt
setblock ~187 ~116 ~129 dirt
setblock ~187 ~116 ~130 dirt
setblock ~187 ~116 ~131 dirt
setblock ~187 ~116 ~132 dirt
setblock ~187 ~116 ~136 dirt
setblock ~187 ~117 ~60 dirt
setblock ~187 ~117 ~61 dirt
setblock ~187 ~117 ~62 dirt
setblock ~187 ~117 ~63 dirt
setblock ~187 ~117 ~64 dirt
setblock ~187 ~117 ~65 dirt
setblock ~187 ~117 ~78 dirt
setblock ~187 ~117 ~79 dirt
setblock ~187 ~117 ~80 dirt
setblock ~187 ~117 ~100 dirt
setblock ~187 ~117 ~101 dirt
setblock ~187 ~117 ~102 dirt
setblock ~187 ~117 ~103 dirt
setblock ~187 ~117 ~104 dirt
setblock ~187 ~117 ~105 dirt
setblock ~187 ~117 ~119 dirt
setblock ~187 ~117 ~120 dirt
setblock ~187 ~117 ~121 dirt
setblock ~187 ~117 ~122 dirt
setblock ~187 ~117 ~124 dirt
setblock ~187 ~117 ~125 dirt
setblock ~187 ~117 ~126 dirt
setblock ~187 ~117 ~127 dirt
setblock ~187 ~117 ~128 dirt
setblock ~187 ~117 ~129 dirt
setblock ~187 ~117 ~130 dirt
setblock ~187 ~117 ~131 dirt
setblock ~187 ~117 ~132 dirt
setblock ~187 ~117 ~133 dirt
setblock ~187 ~117 ~135 dirt
setblock ~187 ~117 ~136 dirt
setblock ~187 ~117 ~137 dirt
setblock ~187 ~117 ~139 dirt
setblock ~187 ~117 ~140 dirt
setblock ~187 ~118 ~59 dirt
setblock ~187 ~118 ~60 dirt
setblock ~187 ~118 ~61 dirt
setblock ~187 ~118 ~62 dirt
setblock ~187 ~118 ~63 dirt
setblock ~187 ~118 ~64 dirt
setblock ~187 ~118 ~65 dirt
setblock ~187 ~118 ~77 dirt
setblock ~187 ~118 ~78 dirt
setblock ~187 ~118 ~79 dirt
setblock ~187 ~118 ~80 dirt
setblock ~187 ~118 ~81 dirt
setblock ~187 ~118 ~100 dirt
setblock ~187 ~118 ~101 dirt
setblock ~187 ~118 ~102 dirt
setblock ~187 ~118 ~103 dirt
setblock ~187 ~118 ~104 dirt
setblock ~187 ~118 ~105 dirt
setblock ~187 ~118 ~117 dirt
setblock ~187 ~118 ~118 dirt
setblock ~187 ~118 ~119 dirt
setblock ~187 ~118 ~120 dirt
setblock ~187 ~118 ~121 dirt
setblock ~187 ~118 ~122 dirt
setblock ~187 ~118 ~123 dirt
setblock ~187 ~118 ~124 dirt
setblock ~187 ~118 ~125 dirt
setblock ~187 ~118 ~126 dirt
setblock ~187 ~118 ~127 dirt
setblock ~187 ~118 ~128 dirt
setblock ~187 ~118 ~129 dirt
setblock ~187 ~118 ~130 dirt
setblock ~187 ~118 ~131 dirt
setblock ~187 ~118 ~132 dirt
setblock ~187 ~118 ~133 dirt
setblock ~187 ~118 ~134 dirt
setblock ~187 ~118 ~135 dirt
setblock ~187 ~118 ~136 dirt
setblock ~187 ~118 ~137 dirt
setblock ~187 ~118 ~138 dirt
setblock ~187 ~118 ~139 dirt
setblock ~187 ~118 ~140 dirt
setblock ~187 ~118 ~141 dirt
setblock ~187 ~119 ~58 dirt
setblock ~187 ~119 ~59 dirt
setblock ~187 ~119 ~60 dirt
setblock ~187 ~119 ~61 dirt
setblock ~187 ~119 ~62 dirt
setblock ~187 ~119 ~63 dirt
setblock ~187 ~119 ~64 dirt
setblock ~187 ~119 ~65 dirt
setblock ~187 ~119 ~66 dirt
setblock ~187 ~119 ~70 dirt
setblock ~187 ~119 ~77 dirt
setblock ~187 ~119 ~78 dirt
setblock ~187 ~119 ~79 dirt
setblock ~187 ~119 ~80 dirt
setblock ~187 ~119 ~81 dirt
setblock ~187 ~119 ~82 dirt
setblock ~187 ~119 ~84 dirt
setblock ~187 ~119 ~99 dirt
setblock ~187 ~119 ~100 dirt
setblock ~187 ~119 ~101 dirt
setblock ~187 ~119 ~102 dirt
setblock ~187 ~119 ~103 dirt
setblock ~187 ~119 ~104 dirt
setblock ~187 ~119 ~105 dirt
setblock ~187 ~119 ~117 dirt
setblock ~187 ~119 ~118 dirt
setblock ~187 ~119 ~119 dirt
setblock ~187 ~119 ~120 dirt
setblock ~187 ~119 ~121 dirt
setblock ~187 ~119 ~122 dirt
setblock ~187 ~119 ~123 dirt
setblock ~187 ~119 ~124 dirt
setblock ~187 ~119 ~125 dirt
setblock ~187 ~119 ~126 dirt
setblock ~187 ~119 ~127 dirt
setblock ~187 ~119 ~128 dirt
setblock ~187 ~119 ~129 dirt
setblock ~187 ~119 ~130 dirt
setblock ~187 ~119 ~131 dirt
setblock ~187 ~119 ~132 dirt
setblock ~187 ~119 ~133 dirt
setblock ~187 ~119 ~134 dirt
setblock ~187 ~119 ~135 dirt
setblock ~187 ~119 ~136 dirt
setblock ~187 ~119 ~137 dirt
setblock ~187 ~119 ~138 dirt
setblock ~187 ~119 ~139 dirt
setblock ~187 ~119 ~140 dirt
setblock ~187 ~119 ~141 dirt
setblock ~187 ~120 ~58 dirt
setblock ~187 ~120 ~59 dirt
setblock ~187 ~120 ~60 dirt
setblock ~187 ~120 ~61 dirt
setblock ~187 ~120 ~62 dirt
setblock ~187 ~120 ~63 dirt
setblock ~187 ~120 ~64 dirt
setblock ~187 ~120 ~65 dirt
setblock ~187 ~120 ~66 dirt
setblock ~187 ~120 ~67 dirt
setblock ~187 ~120 ~69 dirt
setblock ~187 ~120 ~70 dirt
setblock ~187 ~120 ~71 dirt
setblock ~187 ~120 ~77 dirt
setblock ~187 ~120 ~78 dirt
setblock ~187 ~120 ~79 dirt
setblock ~187 ~120 ~80 dirt
setblock ~187 ~120 ~81 dirt
setblock ~187 ~120 ~82 dirt
setblock ~187 ~120 ~83 dirt
setblock ~187 ~120 ~84 dirt
setblock ~187 ~120 ~99 dirt
setblock ~187 ~120 ~100 dirt
setblock ~187 ~120 ~101 dirt
setblock ~187 ~120 ~102 dirt
setblock ~187 ~120 ~103 dirt
setblock ~187 ~120 ~104 dirt
setblock ~187 ~120 ~105 dirt
setblock ~187 ~120 ~106 dirt
setblock ~187 ~120 ~111 dirt
setblock ~187 ~120 ~117 dirt
setblock ~187 ~120 ~118 dirt
setblock ~187 ~120 ~119 dirt
setblock ~187 ~120 ~120 dirt
setblock ~187 ~120 ~121 dirt
setblock ~187 ~120 ~122 dirt
setblock ~187 ~120 ~123 dirt
setblock ~187 ~120 ~124 dirt
setblock ~187 ~120 ~125 dirt
setblock ~187 ~120 ~126 dirt
setblock ~187 ~120 ~127 dirt
setblock ~187 ~120 ~128 dirt
setblock ~187 ~120 ~129 dirt
setblock ~187 ~120 ~130 dirt
setblock ~187 ~120 ~131 dirt
setblock ~187 ~120 ~132 dirt
setblock ~187 ~120 ~133 dirt
setblock ~187 ~120 ~134 dirt
setblock ~187 ~120 ~135 dirt
setblock ~187 ~120 ~136 dirt
setblock ~187 ~120 ~137 dirt
setblock ~187 ~120 ~138 dirt
setblock ~187 ~120 ~139 dirt
setblock ~187 ~120 ~140 dirt
setblock ~187 ~120 ~141 dirt
setblock ~187 ~121 ~57 dirt
setblock ~187 ~121 ~58 dirt
setblock ~187 ~121 ~59 dirt
setblock ~187 ~121 ~60 dirt
setblock ~187 ~121 ~61 dirt
setblock ~187 ~121 ~62 dirt
setblock ~187 ~121 ~63 dirt
setblock ~187 ~121 ~64 dirt
setblock ~187 ~121 ~65 dirt
setblock ~187 ~121 ~66 dirt
setblock ~187 ~121 ~67 dirt
setblock ~187 ~121 ~68 dirt
setblock ~187 ~121 ~69 dirt
setblock ~187 ~121 ~70 dirt
setblock ~187 ~121 ~71 dirt
setblock ~187 ~121 ~76 dirt
setblock ~187 ~121 ~77 dirt
setblock ~187 ~121 ~78 dirt
setblock ~187 ~121 ~79 dirt
setblock ~187 ~121 ~80 dirt
setblock ~187 ~121 ~81 dirt
setblock ~187 ~121 ~82 dirt
setblock ~187 ~121 ~83 dirt
setblock ~187 ~121 ~84 dirt
setblock ~187 ~121 ~85 dirt
setblock ~187 ~121 ~87 dirt
setblock ~187 ~121 ~99 dirt
setblock ~187 ~121 ~100 dirt
setblock ~187 ~121 ~101 dirt
setblock ~187 ~121 ~102 dirt
setblock ~187 ~121 ~103 dirt
setblock ~187 ~121 ~104 dirt
setblock ~187 ~121 ~105 dirt
setblock ~187 ~121 ~106 dirt
setblock ~187 ~121 ~111 dirt
setblock ~187 ~121 ~116 dirt
setblock ~187 ~121 ~117 dirt
setblock ~187 ~121 ~118 dirt
setblock ~187 ~121 ~119 dirt
setblock ~187 ~121 ~120 dirt
setblock ~187 ~121 ~121 dirt
setblock ~187 ~121 ~122 dirt
setblock ~187 ~121 ~123 dirt
setblock ~187 ~121 ~124 dirt
setblock ~187 ~121 ~125 dirt
setblock ~187 ~121 ~126 dirt
setblock ~187 ~121 ~127 dirt
setblock ~187 ~121 ~128 dirt
setblock ~187 ~121 ~129 dirt
setblock ~187 ~121 ~130 dirt
setblock ~187 ~121 ~131 dirt
setblock ~187 ~121 ~132 dirt
setblock ~187 ~121 ~133 dirt
setblock ~187 ~121 ~134 dirt
setblock ~187 ~121 ~135 dirt
setblock ~187 ~121 ~136 dirt
setblock ~187 ~121 ~137 dirt
setblock ~187 ~121 ~138 dirt
setblock ~187 ~121 ~139 dirt
setblock ~187 ~121 ~140 dirt
setblock ~187 ~121 ~141 dirt
setblock ~187 ~121 ~142 dirt
setblock ~187 ~121 ~145 dirt
setblock ~187 ~122 ~57 dirt
setblock ~187 ~122 ~58 dirt
setblock ~187 ~122 ~59 dirt
setblock ~187 ~122 ~60 dirt
setblock ~187 ~122 ~61 dirt
setblock ~187 ~122 ~62 dirt
setblock ~187 ~122 ~63 dirt
setblock ~187 ~122 ~64 dirt
setblock ~187 ~122 ~65 dirt
setblock ~187 ~122 ~66 dirt
setblock ~187 ~122 ~67 dirt
setblock ~187 ~122 ~68 dirt
setblock ~187 ~122 ~69 dirt
setblock ~187 ~122 ~70 dirt
setblock ~187 ~122 ~71 dirt
setblock ~187 ~122 ~76 dirt
setblock ~187 ~122 ~77 dirt
setblock ~187 ~122 ~78 dirt
setblock ~187 ~122 ~79 dirt
setblock ~187 ~122 ~80 dirt
setblock ~187 ~122 ~81 dirt
setblock ~187 ~122 ~82 dirt
setblock ~187 ~122 ~83 dirt
setblock ~187 ~122 ~84 dirt
setblock ~187 ~122 ~85 dirt
setblock ~187 ~122 ~87 dirt
setblock ~187 ~122 ~99 dirt
setblock ~187 ~122 ~100 dirt
setblock ~187 ~122 ~101 dirt
setblock ~187 ~122 ~102 dirt
setblock ~187 ~122 ~103 dirt
setblock ~187 ~122 ~104 dirt
setblock ~187 ~122 ~105 dirt
setblock ~187 ~122 ~106 dirt
setblock ~187 ~122 ~111 dirt
setblock ~187 ~122 ~116 dirt
setblock ~187 ~122 ~117 dirt
setblock ~187 ~122 ~118 dirt
setblock ~187 ~122 ~119 dirt
setblock ~187 ~122 ~120 dirt
setblock ~187 ~122 ~121 dirt
setblock ~187 ~122 ~122 dirt
setblock ~187 ~122 ~123 dirt
setblock ~187 ~122 ~124 dirt
setblock ~187 ~122 ~125 dirt
setblock ~187 ~122 ~126 dirt
setblock ~187 ~122 ~127 dirt
setblock ~187 ~122 ~128 dirt
setblock ~187 ~122 ~129 dirt
setblock ~187 ~122 ~130 dirt
setblock ~187 ~122 ~131 dirt
setblock ~187 ~122 ~132 dirt
setblock ~187 ~122 ~133 dirt
setblock ~187 ~122 ~134 dirt
setblock ~187 ~122 ~135 dirt
setblock ~187 ~122 ~136 dirt
setblock ~187 ~122 ~137 dirt
setblock ~187 ~122 ~138 dirt
setblock ~187 ~122 ~139 dirt
setblock ~187 ~122 ~140 dirt
setblock ~187 ~122 ~141 dirt
setblock ~187 ~122 ~142 dirt
setblock ~187 ~122 ~145 dirt
setblock ~187 ~123 ~57 dirt
setblock ~187 ~123 ~58 dirt
setblock ~187 ~123 ~59 dirt
setblock ~187 ~123 ~60 dirt
setblock ~187 ~123 ~61 dirt
setblock ~187 ~123 ~62 dirt
setblock ~187 ~123 ~63 dirt
setblock ~187 ~123 ~64 dirt
setblock ~187 ~123 ~65 dirt
setblock ~187 ~123 ~66 dirt
setblock ~187 ~123 ~67 dirt
setblock ~187 ~123 ~68 dirt
setblock ~187 ~123 ~69 dirt
setblock ~187 ~123 ~70 dirt
setblock ~187 ~123 ~71 dirt
setblock ~187 ~123 ~76 dirt
setblock ~187 ~123 ~77 dirt
setblock ~187 ~123 ~78 dirt
setblock ~187 ~123 ~79 dirt
setblock ~187 ~123 ~80 dirt
setblock ~187 ~123 ~81 dirt
setblock ~187 ~123 ~82 dirt
setblock ~187 ~123 ~83 dirt
setblock ~187 ~123 ~84 dirt
setblock ~187 ~123 ~85 dirt
setblock ~187 ~123 ~87 dirt
setblock ~187 ~123 ~99 dirt
setblock ~187 ~123 ~100 dirt
setblock ~187 ~123 ~101 dirt
setblock ~187 ~123 ~102 dirt
setblock ~187 ~123 ~103 dirt
setblock ~187 ~123 ~104 dirt
setblock ~187 ~123 ~105 dirt
setblock ~187 ~123 ~106 dirt
setblock ~187 ~123 ~111 dirt
setblock ~187 ~123 ~116 dirt
setblock ~187 ~123 ~117 dirt
setblock ~187 ~123 ~118 dirt
setblock ~187 ~123 ~119 dirt
setblock ~187 ~123 ~120 dirt
setblock ~187 ~123 ~121 dirt
setblock ~187 ~123 ~122 dirt
setblock ~187 ~123 ~123 dirt
setblock ~187 ~123 ~124 dirt
setblock ~187 ~123 ~125 dirt
setblock ~187 ~123 ~126 dirt
setblock ~187 ~123 ~127 dirt
setblock ~187 ~123 ~128 dirt
setblock ~187 ~123 ~129 dirt
setblock ~187 ~123 ~130 dirt
setblock ~187 ~123 ~131 dirt
setblock ~187 ~123 ~132 dirt
setblock ~187 ~123 ~133 dirt
setblock ~187 ~123 ~134 dirt
setblock ~187 ~123 ~135 dirt
setblock ~187 ~123 ~136 grass_block
setblock ~187 ~123 ~137 grass_block
setblock ~187 ~123 ~138 grass_block
setblock ~187 ~123 ~139 grass_block
setblock ~187 ~123 ~140 grass_block
setblock ~187 ~123 ~141 grass_block
setblock ~187 ~123 ~142 grass_block
setblock ~187 ~123 ~145 dirt
setblock ~187 ~124 ~57 dirt
setblock ~187 ~124 ~58 dirt
setblock ~187 ~124 ~59 dirt
setblock ~187 ~124 ~60 dirt
setblock ~187 ~124 ~61 dirt
setblock ~187 ~124 ~62 dirt
setblock ~187 ~124 ~63 dirt
setblock ~187 ~124 ~64 dirt
setblock ~187 ~124 ~65 dirt
setblock ~187 ~124 ~66 dirt
setblock ~187 ~124 ~67 dirt
setblock ~187 ~124 ~68 dirt
setblock ~187 ~124 ~69 dirt
setblock ~187 ~124 ~70 dirt
setblock ~187 ~124 ~71 dirt
setblock ~187 ~124 ~76 dirt
setblock ~187 ~124 ~77 dirt
setblock ~187 ~124 ~78 dirt
setblock ~187 ~124 ~79 grass_block
setblock ~187 ~124 ~80 grass_block
setblock ~187 ~124 ~81 grass_block
setblock ~187 ~124 ~82 grass_block
setblock ~187 ~124 ~83 grass_block
setblock ~187 ~124 ~84 grass_block
setblock ~187 ~124 ~85 grass_block
setblock ~187 ~124 ~87 grass_block
setblock ~187 ~124 ~99 dirt
setblock ~187 ~124 ~100 dirt
setblock ~187 ~124 ~101 dirt
setblock ~187 ~124 ~102 dirt
setblock ~187 ~124 ~103 dirt
setblock ~187 ~124 ~104 dirt
setblock ~187 ~124 ~105 dirt
setblock ~187 ~124 ~106 dirt
setblock ~187 ~124 ~111 dirt
setblock ~187 ~124 ~116 grass_block
setblock ~187 ~124 ~117 grass_block
setblock ~187 ~124 ~118 grass_block
setblock ~187 ~124 ~119 grass_block
setblock ~187 ~124 ~120 grass_block
setblock ~187 ~124 ~121 grass_block
setblock ~187 ~124 ~122 grass_block
setblock ~187 ~124 ~123 grass_block
setblock ~187 ~124 ~124 grass_block
setblock ~187 ~124 ~125 grass_block
setblock ~187 ~124 ~126 grass_block
setblock ~187 ~124 ~127 grass_block
setblock ~187 ~124 ~128 grass_block
setblock ~187 ~124 ~129 grass_block
setblock ~187 ~124 ~130 grass_block
setblock ~187 ~124 ~131 grass_block
setblock ~187 ~124 ~132 grass_block
setblock ~187 ~124 ~133 grass_block
setblock ~187 ~124 ~134 grass_block
setblock ~187 ~124 ~135 grass_block
setblock ~187 ~124 ~136 short_grass
setblock ~187 ~124 ~145 grass_block
setblock ~187 ~125 ~57 dirt
setblock ~187 ~125 ~58 dirt
setblock ~187 ~125 ~59 dirt
setblock ~187 ~125 ~60 dirt
setblock ~187 ~125 ~61 dirt
setblock ~187 ~125 ~62 dirt
setblock ~187 ~125 ~63 dirt
setblock ~187 ~125 ~64 dirt
setblock ~187 ~125 ~65 dirt
setblock ~187 ~125 ~66 dirt
setblock ~187 ~125 ~67 dirt
setblock ~187 ~125 ~68 dirt
setblock ~187 ~125 ~69 dirt
setblock ~187 ~125 ~70 dirt
setblock ~187 ~125 ~71 dirt
setblock ~187 ~125 ~76 grass_block
setblock ~187 ~125 ~77 grass_block
setblock ~187 ~125 ~78 grass_block
setblock ~187 ~125 ~84 poppy
setblock ~187 ~125 ~87 short_grass
setblock ~187 ~125 ~99 dirt
setblock ~187 ~125 ~100 dirt
setblock ~187 ~125 ~101 dirt
setblock ~187 ~125 ~102 dirt
setblock ~187 ~125 ~103 dirt
setblock ~187 ~125 ~104 dirt
setblock ~187 ~125 ~105 dirt
setblock ~187 ~125 ~106 dirt
setblock ~187 ~125 ~111 grass_block
setblock ~187 ~125 ~117 short_grass
setblock ~187 ~125 ~119 fern
setblock ~187 ~125 ~120 fern
setblock ~187 ~125 ~123 short_grass
setblock ~187 ~125 ~124 short_grass
setblock ~187 ~125 ~126 short_grass
setblock ~187 ~125 ~128 poppy
setblock ~187 ~125 ~131 poppy
setblock ~187 ~125 ~135 short_grass
setblock ~187 ~126 ~57 grass_block
setblock ~187 ~126 ~58 grass_block
setblock ~187 ~126 ~59 grass_block
setblock ~187 ~126 ~60 dirt
setblock ~187 ~126 ~61 dirt
setblock ~187 ~126 ~62 dirt
setblock ~187 ~126 ~63 dirt
setblock ~187 ~126 ~64 dirt
setblock ~187 ~126 ~65 dirt
setblock ~187 ~126 ~66 dirt
setblock ~187 ~126 ~67 dirt
setblock ~187 ~126 ~68 dirt
setblock ~187 ~126 ~69 dirt
setblock ~187 ~126 ~70 dirt
setblock ~187 ~126 ~71 dirt
setblock ~187 ~126 ~99 dirt
setblock ~187 ~126 ~100 dirt
setblock ~187 ~126 ~101 dirt
setblock ~187 ~126 ~102 dirt
setblock ~187 ~126 ~103 dirt
setblock ~187 ~126 ~104 dirt
setblock ~187 ~126 ~105 dirt
setblock ~187 ~126 ~106 dirt
setblock ~187 ~127 ~59 short_grass
setblock ~187 ~127 ~60 grass_block
setblock ~187 ~127 ~61 grass_block
setblock ~187 ~127 ~62 grass_block
setblock ~187 ~127 ~63 grass_block
setblock ~187 ~127 ~64 grass_block
setblock ~187 ~127 ~65 grass_block
setblock ~187 ~127 ~66 grass_block
setblock ~187 ~127 ~67 grass_block
setblock ~187 ~127 ~68 grass_block
setblock ~187 ~127 ~69 grass_block
setblock ~187 ~127 ~70 grass_block
setblock ~187 ~127 ~71 grass_block
setblock ~187 ~127 ~99 dirt
setblock ~187 ~127 ~100 dirt
setblock ~187 ~127 ~101 dirt
setblock ~187 ~127 ~102 dirt
setblock ~187 ~127 ~103 dirt
setblock ~187 ~127 ~104 dirt
setblock ~187 ~127 ~105 dirt
setblock ~187 ~127 ~106 dirt
setblock ~187 ~128 ~61 fern
setblock ~187 ~128 ~62 short_grass
setblock ~187 ~128 ~65 short_grass
setblock ~187 ~128 ~69 short_grass
setblock ~187 ~128 ~70 short_grass
setblock ~187 ~128 ~71 short_grass
setblock ~187 ~128 ~99 dirt
setblock ~187 ~128 ~100 dirt
setblock ~187 ~128 ~101 dirt
setblock ~187 ~128 ~102 dirt
setblock ~187 ~128 ~103 dirt
setblock ~187 ~128 ~104 grass_block
setblock ~187 ~128 ~105 grass_block
setblock ~187 ~128 ~106 grass_block
setblock ~187 ~129 ~99 grass_block
setblock ~187 ~129 ~100 grass_block
setblock ~187 ~129 ~101 grass_block
setblock ~187 ~129 ~102 grass_block
setblock ~187 ~129 ~103 grass_block
setblock ~187 ~130 ~101 short_grass
setblock ~187 ~130 ~102 short_grass
setblock ~188 ~113 ~103 dirt
setblock ~188 ~114 ~63 dirt
setblock ~188 ~114 ~103 dirt
setblock ~188 ~114 ~126 dirt
setblock ~188 ~115 ~62 dirt
setblock ~188 ~115 ~63 dirt
setblock ~188 ~115 ~64 dirt
setblock ~188 ~115 ~102 dirt
setblock ~188 ~115 ~103 dirt
setblock ~188 ~115 ~104 dirt
setblock ~188 ~115 ~126 dirt
setblock ~188 ~116 ~61 dirt
setblock ~188 ~116 ~62 dirt
setblock ~188 ~116 ~63 dirt
setblock ~188 ~116 ~64 dirt
setblock ~188 ~116 ~101 dirt
setblock ~188 ~116 ~102 dirt
setblock ~188 ~116 ~103 dirt
setblock ~188 ~116 ~104 dirt
setblock ~188 ~116 ~126 dirt
setblock ~188 ~116 ~127 dirt
setblock ~188 ~116 ~130 dirt
setblock ~188 ~117 ~61 dirt
setblock ~188 ~117 ~62 dirt
setblock ~188 ~117 ~63 dirt
setblock ~188 ~117 ~64 dirt
setblock ~188 ~117 ~79 dirt
setblock ~188 ~117 ~100 dirt
setblock ~188 ~117 ~101 dirt
setblock ~188 ~117 ~102 dirt
setblock ~188 ~117 ~103 dirt
setblock ~188 ~117 ~104 dirt
setblock ~188 ~117 ~105 dirt
setblock ~188 ~117 ~120 dirt
setblock ~188 ~117 ~125 dirt
setblock ~188 ~117 ~126 dirt
setblock ~188 ~117 ~127 dirt
setblock ~188 ~117 ~128 dirt
setblock ~188 ~117 ~130 dirt
setblock ~188 ~117 ~131 dirt
setblock ~188 ~118 ~60 dirt
setblock ~188 ~118 ~61 dirt
setblock ~188 ~118 ~62 dirt
setblock ~188 ~118 ~63 dirt
setblock ~188 ~118 ~64 dirt
setblock ~188 ~118 ~70 dirt
setblock ~188 ~118 ~78 dirt
setblock ~188 ~118 ~79 dirt
setblock ~188 ~118 ~80 dirt
setblock ~188 ~118 ~100 dirt
setblock ~188 ~118 ~101 dirt
setblock ~188 ~118 ~102 dirt
setblock ~188 ~118 ~103 dirt
setblock ~188 ~118 ~104 dirt
setblock ~188 ~118 ~105 dirt
setblock ~188 ~118 ~119 dirt
setblock ~188 ~118 ~120 dirt
setblock ~188 ~118 ~124 dirt
setblock ~188 ~118 ~125 dirt
setblock ~188 ~118 ~126 dirt
setblock ~188 ~118 ~127 dirt
setblock ~188 ~118 ~128 dirt
setblock ~188 ~118 ~129 dirt
setblock ~188 ~118 ~130 dirt
setblock ~188 ~118 ~131 dirt
setblock ~188 ~118 ~132 dirt
setblock ~188 ~118 ~137 dirt
setblock ~188 ~119 ~59 dirt
setblock ~188 ~119 ~60 dirt
setblock ~188 ~119 ~61 dirt
setblock ~188 ~119 ~62 dirt
setblock ~188 ~119 ~63 dirt
setblock ~188 ~119 ~64 dirt
setblock ~188 ~119 ~65 dirt
setblock ~188 ~119 ~69 dirt
setblock ~188 ~119 ~70 dirt
setblock ~188 ~119 ~71 dirt
setblock ~188 ~119 ~77 dirt
setblock ~188 ~119 ~78 dirt
setblock ~188 ~119 ~79 dirt
setblock ~188 ~119 ~80 dirt
setblock ~188 ~119 ~81 dirt
setblock ~188 ~119 ~100 dirt
setblock ~188 ~119 ~101 dirt
setblock ~188 ~119 ~102 dirt
setblock ~188 ~119 ~103 dirt
setblock ~188 ~119 ~104 dirt
setblock ~188 ~119 ~105 dirt
setblock ~188 ~119 ~119 dirt
setblock ~188 ~119 ~120 dirt
setblock ~188 ~119 ~121 dirt
setblock ~188 ~119 ~122 dirt
setblock ~188 ~119 ~123 dirt
setblock ~188 ~119 ~124 dirt
setblock ~188 ~119 ~125 dirt
setblock ~188 ~119 ~126 dirt
setblock ~188 ~119 ~127 dirt
setblock ~188 ~119 ~128 dirt
setblock ~188 ~119 ~129 dirt
setblock ~188 ~119 ~130 dirt
setblock ~188 ~119 ~131 dirt
setblock ~188 ~119 ~132 dirt
setblock ~188 ~119 ~133 dirt
setblock ~188 ~119 ~137 dirt
setblock ~188 ~119 ~138 dirt
setblock ~188 ~119 ~139 dirt
setblock ~188 ~119 ~140 dirt
setblock ~188 ~120 ~59 dirt
setblock ~188 ~120 ~60 dirt
setblock ~188 ~120 ~61 dirt
setblock ~188 ~120 ~62 dirt
setblock ~188 ~120 ~63 dirt
setblock ~188 ~120 ~64 dirt
setblock ~188 ~120 ~65 dirt
setblock ~188 ~120 ~66 dirt
setblock ~188 ~120 ~68 dirt
setblock ~188 ~120 ~69 dirt
setblock ~188 ~120 ~70 dirt
setblock ~188 ~120 ~71 dirt
setblock ~188 ~120 ~72 dirt
setblock ~188 ~120 ~77 dirt
setblock ~188 ~120 ~78 dirt
setblock ~188 ~120 ~79 dirt
setblock ~188 ~120 ~80 dirt
setblock ~188 ~120 ~81 dirt
setblock ~188 ~120 ~82 dirt
setblock ~188 ~120 ~99 dirt
setblock ~188 ~120 ~100 dirt
setblock ~188 ~120 ~101 dirt
setblock ~188 ~120 ~102 dirt
setblock ~188 ~120 ~103 dirt
setblock ~188 ~120 ~104 dirt
setblock ~188 ~120 ~105 dirt
setblock ~188 ~120 ~106 dirt
setblock ~188 ~120 ~118 dirt
setblock ~188 ~120 ~119 dirt
setblock ~188 ~120 ~120 dirt
setblock ~188 ~120 ~121 dirt
setblock ~188 ~120 ~122 dirt
setblock ~188 ~120 ~123 dirt
setblock ~188 ~120 ~124 dirt
setblock ~188 ~120 ~125 dirt
setblock ~188 ~120 ~126 dirt
setblock ~188 ~120 ~127 dirt
setblock ~188 ~120 ~128 dirt
setblock ~188 ~120 ~129 dirt
setblock ~188 ~120 ~130 dirt
setblock ~188 ~120 ~131 dirt
setblock ~188 ~120 ~132 dirt
setblock ~188 ~120 ~133 dirt
setblock ~188 ~120 ~134 dirt
setblock ~188 ~120 ~135 dirt
setblock ~188 ~120 ~136 dirt
setblock ~188 ~120 ~137 dirt
setblock ~188 ~120 ~138 dirt
setblock ~188 ~120 ~139 dirt
setblock ~188 ~120 ~140 dirt
setblock ~188 ~121 ~58 dirt
setblock ~188 ~121 ~59 dirt
setblock ~188 ~121 ~60 dirt
setblock ~188 ~121 ~61 dirt
setblock ~188 ~121 ~62 dirt
setblock ~188 ~121 ~63 dirt
setblock ~188 ~121 ~64 dirt
setblock ~188 ~121 ~65 dirt
setblock ~188 ~121 ~66 dirt
setblock ~188 ~121 ~68 dirt
setblock ~188 ~121 ~69 dirt
setblock ~188 ~121 ~70 dirt
setblock ~188 ~121 ~71 dirt
setblock ~188 ~121 ~72 dirt
setblock ~188 ~121 ~77 dirt
setblock ~188 ~121 ~78 dirt
setblock ~188 ~121 ~79 dirt
setblock ~188 ~121 ~80 dirt
setblock ~188 ~121 ~81 dirt
setblock ~188 ~121 ~82 dirt
setblock ~188 ~121 ~83 dirt
setblock ~188 ~121 ~98 dirt
setblock ~188 ~121 ~99 dirt
setblock ~188 ~121 ~100 dirt
setblock ~188 ~121 ~101 dirt
setblock ~188 ~121 ~102 dirt
setblock ~188 ~121 ~103 dirt
setblock ~188 ~121 ~104 dirt
setblock ~188 ~121 ~105 dirt
setblock ~188 ~121 ~106 dirt
setblock ~188 ~121 ~117 dirt
setblock ~188 ~121 ~118 dirt
setblock ~188 ~121 ~119 dirt
setblock ~188 ~121 ~120 dirt
setblock ~188 ~121 ~121 dirt
setblock ~188 ~121 ~122 dirt
setblock ~188 ~121 ~123 dirt
setblock ~188 ~121 ~124 dirt
setblock ~188 ~121 ~125 dirt
setblock ~188 ~121 ~126 dirt
setblock ~188 ~121 ~127 dirt
setblock ~188 ~121 ~128 dirt
setblock ~188 ~121 ~129 dirt
setblock ~188 ~121 ~130 dirt
setblock ~188 ~121 ~131 dirt
setblock ~188 ~121 ~132 dirt
setblock ~188 ~121 ~133 dirt
setblock ~188 ~121 ~134 dirt
setblock ~188 ~121 ~135 dirt
setblock ~188 ~121 ~136 dirt
setblock ~188 ~121 ~137 dirt
setblock ~188 ~121 ~138 dirt
setblock ~188 ~121 ~139 dirt
setblock ~188 ~121 ~140 dirt
setblock ~188 ~121 ~141 dirt
setblock ~188 ~122 ~58 dirt
setblock ~188 ~122 ~59 dirt
setblock ~188 ~122 ~60 dirt
setblock ~188 ~122 ~61 dirt
setblock ~188 ~122 ~62 dirt
setblock ~188 ~122 ~63 dirt
setblock ~188 ~122 ~64 dirt
setblock ~188 ~122 ~65 dirt
setblock ~188 ~122 ~66 dirt
setblock ~188 ~122 ~68 dirt
setblock ~188 ~122 ~69 dirt
setblock ~188 ~122 ~70 dirt
setblock ~188 ~122 ~71 dirt
setblock ~188 ~122 ~72 dirt
setblock ~188 ~122 ~77 dirt
setblock ~188 ~122 ~78 dirt
setblock ~188 ~122 ~79 dirt
setblock ~188 ~122 ~80 dirt
setblock ~188 ~122 ~81 dirt
setblock ~188 ~122 ~82 dirt
setblock ~188 ~122 ~83 dirt
setblock ~188 ~122 ~98 dirt
setblock ~188 ~122 ~99 dirt
setblock ~188 ~122 ~100 dirt
setblock ~188 ~122 ~101 dirt
setblock ~188 ~122 ~102 dirt
setblock ~188 ~122 ~103 dirt
setblock ~188 ~122 ~104 dirt
setblock ~188 ~122 ~105 dirt
setblock ~188 ~122 ~106 dirt
setblock ~188 ~122 ~117 dirt
setblock ~188 ~122 ~118 dirt
setblock ~188 ~122 ~119 dirt
setblock ~188 ~122 ~120 dirt
setblock ~188 ~122 ~121 dirt
setblock ~188 ~122 ~122 dirt
setblock ~188 ~122 ~123 dirt
setblock ~188 ~122 ~124 dirt
setblock ~188 ~122 ~125 dirt
setblock ~188 ~122 ~126 dirt
setblock ~188 ~122 ~127 dirt
setblock ~188 ~122 ~128 dirt
setblock ~188 ~122 ~129 dirt
setblock ~188 ~122 ~130 dirt
setblock ~188 ~122 ~131 dirt
setblock ~188 ~122 ~132 dirt
setblock ~188 ~122 ~133 dirt
setblock ~188 ~122 ~134 dirt
setblock ~188 ~122 ~135 dirt
setblock ~188 ~122 ~136 dirt
setblock ~188 ~122 ~137 dirt
setblock ~188 ~122 ~138 dirt
setblock ~188 ~122 ~139 dirt
setblock ~188 ~122 ~140 dirt
setblock ~188 ~122 ~141 dirt
setblock ~188 ~123 ~58 dirt
setblock ~188 ~123 ~59 dirt
setblock ~188 ~123 ~60 dirt
setblock ~188 ~123 ~61 dirt
setblock ~188 ~123 ~62 dirt
setblock ~188 ~123 ~63 dirt
setblock ~188 ~123 ~64 dirt
setblock ~188 ~123 ~65 dirt
setblock ~188 ~123 ~66 dirt
setblock ~188 ~123 ~68 dirt
setblock ~188 ~123 ~69 dirt
setblock ~188 ~123 ~70 dirt
setblock ~188 ~123 ~71 dirt
setblock ~188 ~123 ~72 dirt
setblock ~188 ~123 ~77 dirt
setblock ~188 ~123 ~78 dirt
setblock ~188 ~123 ~79 dirt
setblock ~188 ~123 ~80 dirt
setblock ~188 ~123 ~81 dirt
setblock ~188 ~123 ~82 dirt
setblock ~188 ~123 ~83 dirt
setblock ~188 ~123 ~98 dirt
setblock ~188 ~123 ~99 dirt
setblock ~188 ~123 ~100 dirt
setblock ~188 ~123 ~101 dirt
setblock ~188 ~123 ~102 dirt
setblock ~188 ~123 ~103 dirt
setblock ~188 ~123 ~104 dirt
setblock ~188 ~123 ~105 dirt
setblock ~188 ~123 ~106 dirt
setblock ~188 ~123 ~117 dirt
setblock ~188 ~123 ~118 dirt
setblock ~188 ~123 ~119 dirt
setblock ~188 ~123 ~120 dirt
setblock ~188 ~123 ~121 dirt
setblock ~188 ~123 ~122 dirt
setblock ~188 ~123 ~123 dirt
setblock ~188 ~123 ~124 dirt
setblock ~188 ~123 ~125 dirt
setblock ~188 ~123 ~126 dirt
setblock ~188 ~123 ~127 dirt
setblock ~188 ~123 ~128 dirt
setblock ~188 ~123 ~129 dirt
setblock ~188 ~123 ~130 dirt
setblock ~188 ~123 ~131 dirt
setblock ~188 ~123 ~132 dirt
setblock ~188 ~123 ~133 dirt
setblock ~188 ~123 ~134 dirt
setblock ~188 ~123 ~135 grass_block
setblock ~188 ~123 ~136 grass_block
setblock ~188 ~123 ~137 grass_block
setblock ~188 ~123 ~138 grass_block
setblock ~188 ~123 ~139 grass_block
setblock ~188 ~123 ~140 grass_block
setblock ~188 ~123 ~141 grass_block
setblock ~188 ~124 ~58 dirt
setblock ~188 ~124 ~59 dirt
setblock ~188 ~124 ~60 dirt
setblock ~188 ~124 ~61 dirt
setblock ~188 ~124 ~62 dirt
setblock ~188 ~124 ~63 dirt
setblock ~188 ~124 ~64 dirt
setblock ~188 ~124 ~65 dirt
setblock ~188 ~124 ~66 dirt
setblock ~188 ~124 ~68 dirt
setblock ~188 ~124 ~69 dirt
setblock ~188 ~124 ~70 dirt
setblock ~188 ~124 ~71 dirt
setblock ~188 ~124 ~72 dirt
setblock ~188 ~124 ~77 dirt
setblock ~188 ~124 ~78 dirt
setblock ~188 ~124 ~79 grass_block
setblock ~188 ~124 ~80 grass_block
setblock ~188 ~124 ~81 grass_block
setblock ~188 ~124 ~82 grass_block
setblock ~188 ~124 ~83 grass_block
setblock ~188 ~124 ~98 dirt
setblock ~188 ~124 ~99 dirt
setblock ~188 ~124 ~100 dirt
setblock ~188 ~124 ~101 dirt
setblock ~188 ~124 ~102 dirt
setblock ~188 ~124 ~103 dirt
setblock ~188 ~124 ~104 dirt
setblock ~188 ~124 ~105 dirt
setblock ~188 ~124 ~106 dirt
setblock ~188 ~124 ~117 dirt
setblock ~188 ~124 ~118 grass_block
setblock ~188 ~124 ~119 grass_block
setblock ~188 ~124 ~120 grass_block
setblock ~188 ~124 ~121 grass_block
setblock ~188 ~124 ~122 grass_block
setblock ~188 ~124 ~123 grass_block
setblock ~188 ~124 ~124 grass_block
setblock ~188 ~124 ~125 grass_block
setblock ~188 ~124 ~126 grass_block
setblock ~188 ~124 ~127 grass_block
setblock ~188 ~124 ~128 grass_block
setblock ~188 ~124 ~129 grass_block
setblock ~188 ~124 ~130 grass_block
setblock ~188 ~124 ~131 grass_block
setblock ~188 ~124 ~132 grass_block
setblock ~188 ~124 ~133 grass_block
setblock ~188 ~124 ~134 grass_block
setblock ~188 ~124 ~135 fern
setblock ~188 ~124 ~139 short_grass
setblock ~188 ~124 ~141 short_grass
setblock ~188 ~125 ~58 dirt
setblock ~188 ~125 ~59 dirt
setblock ~188 ~125 ~60 dirt
setblock ~188 ~125 ~61 dirt
setblock ~188 ~125 ~62 dirt
setblock ~188 ~125 ~63 dirt
setblock ~188 ~125 ~64 dirt
setblock ~188 ~125 ~65 dirt
setblock ~188 ~125 ~66 dirt
setblock ~188 ~125 ~68 dirt
setblock ~188 ~125 ~69 dirt
setblock ~188 ~125 ~70 dirt
setblock ~188 ~125 ~71 dirt
setblock ~188 ~125 ~72 dirt
setblock ~188 ~125 ~77 grass_block
setblock ~188 ~125 ~78 grass_block
setblock ~188 ~125 ~82 short_grass
setblock ~188 ~125 ~83 fern
setblock ~188 ~125 ~98 dirt
setblock ~188 ~125 ~99 dirt
setblock ~188 ~125 ~100 dirt
setblock ~188 ~125 ~101 dirt
setblock ~188 ~125 ~102 dirt
setblock ~188 ~125 ~103 dirt
setblock ~188 ~125 ~104 dirt
setblock ~188 ~125 ~105 dirt
setblock ~188 ~125 ~106 dirt
setblock ~188 ~125 ~117 grass_block
setblock ~188 ~125 ~120 short_grass
setblock ~188 ~125 ~124 poppy
setblock ~188 ~125 ~128 short_grass
setblock ~188 ~125 ~132 short_grass
setblock ~188 ~125 ~133 short_grass
setblock ~188 ~126 ~58 grass_block
setblock ~188 ~126 ~59 dirt
setblock ~188 ~126 ~60 dirt
setblock ~188 ~126 ~61 dirt
setblock ~188 ~126 ~62 dirt
setblock ~188 ~126 ~63 dirt
setblock ~188 ~126 ~64 dirt
setblock ~188 ~126 ~65 dirt
setblock ~188 ~126 ~66 dirt
setblock ~188 ~126 ~68 dirt
setblock ~188 ~126 ~69 dirt
setblock ~188 ~126 ~70 dirt
setblock ~188 ~126 ~71 dirt
setblock ~188 ~126 ~72 dirt
setblock ~188 ~126 ~98 dirt
setblock ~188 ~126 ~99 dirt
setblock ~188 ~126 ~100 dirt
setblock ~188 ~126 ~101 dirt
setblock ~188 ~126 ~102 dirt
setblock ~188 ~126 ~103 dirt
setblock ~188 ~126 ~104 dirt
setblock ~188 ~126 ~105 dirt
setblock ~188 ~126 ~106 dirt
setblock ~188 ~127 ~59 grass_block
setblock ~188 ~127 ~60 grass_block
setblock ~188 ~127 ~61 grass_block
setblock ~188 ~127 ~62 grass_block
setblock ~188 ~127 ~63 grass_block
setblock ~188 ~127 ~64 grass_block
setblock ~188 ~127 ~65 dirt
setblock ~188 ~127 ~66 dirt
setblock ~188 ~127 ~68 dirt
setblock ~188 ~127 ~69 dirt
setblock ~188 ~127 ~70 dirt
setblock ~188 ~127 ~71 grass_block
setblock ~188 ~127 ~72 grass_block
setblock ~188 ~127 ~98 dirt
setblock ~188 ~127 ~99 dirt
setblock ~188 ~127 ~100 dirt
setblock ~188 ~127 ~101 dirt
setblock ~188 ~127 ~102 dirt
setblock ~188 ~127 ~103 dirt
setblock ~188 ~127 ~104 dirt
setblock ~188 ~127 ~105 dirt
setblock ~188 ~127 ~106 dirt
setblock ~188 ~128 ~61 short_grass
setblock ~188 ~128 ~63 fern
setblock ~188 ~128 ~65 grass_block
setblock ~188 ~128 ~66 grass_block
setblock ~188 ~128 ~68 grass_block
setblock ~188 ~128 ~69 grass_block
setblock ~188 ~128 ~70 grass_block
setblock ~188 ~128 ~72 short_grass
setblock ~188 ~128 ~98 grass_block
setblock ~188 ~128 ~99 dirt
setblock ~188 ~128 ~100 dirt
setblock ~188 ~128 ~101 dirt
setblock ~188 ~128 ~102 dirt
setblock ~188 ~128 ~103 dirt
setblock ~188 ~128 ~104 dirt
setblock ~188 ~128 ~105 grass_block
setblock ~188 ~128 ~106 grass_block
setblock ~188 ~129 ~70 short_grass
setblock ~188 ~129 ~98 short_grass
setblock ~188 ~129 ~99 grass_block
setblock ~188 ~129 ~100 dirt
setblock ~188 ~129 ~101 dirt
setblock ~188 ~129 ~102 grass_block
setblock ~188 ~129 ~103 grass_block
setblock ~188 ~129 ~104 grass_block
setblock ~188 ~129 ~105 short_grass
setblock ~188 ~130 ~100 grass_block
setblock ~188 ~130 ~101 grass_block
setblock ~188 ~130 ~104 short_grass
setblock ~188 ~131 ~100 short_grass
setblock ~189 ~115 ~63 dirt
setblock ~189 ~115 ~103 dirt
setblock ~189 ~116 ~62 dirt
setblock ~189 ~116 ~63 dirt
setblock ~189 ~116 ~70 dirt
setblock ~189 ~116 ~102 dirt
setblock ~189 ~116 ~103 dirt
setblock ~189 ~117 ~62 dirt
setblock ~189 ~117 ~63 dirt
setblock ~189 ~117 ~64 dirt
setblock ~189 ~117 ~70 dirt
setblock ~189 ~117 ~101 dirt
setblock ~189 ~117 ~102 dirt
setblock ~189 ~117 ~103 dirt
setblock ~189 ~117 ~104 dirt
setblock ~189 ~117 ~127 dirt
setblock ~189 ~118 ~61 dirt
setblock ~189 ~118 ~62 dirt
setblock ~189 ~118 ~63 dirt
setblock ~189 ~118 ~64 dirt
setblock ~189 ~118 ~69 dirt
setblock ~189 ~118 ~70 dirt
setblock ~189 ~118 ~71 dirt
setblock ~189 ~118 ~101 dirt
setblock ~189 ~118 ~102 dirt
setblock ~189 ~118 ~103 dirt
setblock ~189 ~118 ~104 dirt
setblock ~189 ~118 ~126 dirt
setblock ~189 ~118 ~127 dirt
setblock ~189 ~118 ~128 dirt
setblock ~189 ~119 ~61 dirt
setblock ~189 ~119 ~62 dirt
setblock ~189 ~119 ~63 dirt
setblock ~189 ~119 ~64 dirt
setblock ~189 ~119 ~65 dirt
setblock ~189 ~119 ~69 dirt
setblock ~189 ~119 ~70 dirt
setblock ~189 ~119 ~71 dirt
setblock ~189 ~119 ~78 dirt
setblock ~189 ~119 ~79 dirt
setblock ~189 ~119 ~100 dirt
setblock ~189 ~119 ~101 dirt
setblock ~189 ~119 ~102 dirt
setblock ~189 ~119 ~103 dirt
setblock ~189 ~119 ~104 dirt
setblock ~189 ~119 ~124 dirt
setblock ~189 ~119 ~125 dirt
setblock ~189 ~119 ~126 dirt
setblock ~189 ~119 ~127 dirt
setblock ~189 ~119 ~128 dirt
setblock ~189 ~119 ~130 dirt
setblock ~189 ~119 ~131 dirt
setblock ~189 ~119 ~132 dirt
setblock ~189 ~120 ~61 dirt
setblock ~189 ~120 ~62 dirt
setblock ~189 ~120 ~63 dirt
setblock ~189 ~120 ~64 dirt
setblock ~189 ~120 ~65 dirt
setblock ~189 ~120 ~69 dirt
setblock ~189 ~120 ~70 dirt
setblock ~189 ~120 ~71 dirt
setblock ~189 ~120 ~72 dirt
setblock ~189 ~120 ~78 dirt
setblock ~189 ~120 ~79 dirt
setblock ~189 ~120 ~80 dirt
setblock ~189 ~120 ~100 dirt
setblock ~189 ~120 ~101 dirt
setblock ~189 ~120 ~102 dirt
setblock ~189 ~120 ~103 dirt
setblock ~189 ~120 ~104 dirt
setblock ~189 ~120 ~105 dirt
setblock ~189 ~120 ~120 dirt
setblock ~189 ~120 ~124 dirt
setblock ~189 ~120 ~125 dirt
setblock ~189 ~120 ~126 dirt
setblock ~189 ~120 ~127 dirt
setblock ~189 ~120 ~128 dirt
setblock ~189 ~120 ~129 dirt
setblock ~189 ~120 ~130 dirt
setblock ~189 ~120 ~131 dirt
setblock ~189 ~120 ~132 dirt
setblock ~189 ~120 ~137 dirt
setblock ~189 ~121 ~59 dirt
setblock ~189 ~121 ~61 dirt
setblock ~189 ~121 ~62 dirt
setblock ~189 ~121 ~63 dirt
setblock ~189 ~121 ~64 dirt
setblock ~189 ~121 ~65 dirt
setblock ~189 ~121 ~69 dirt
setblock ~189 ~121 ~70 dirt
setblock ~189 ~121 ~71 dirt
setblock ~189 ~121 ~72 dirt
setblock ~189 ~121 ~78 dirt
setblock ~189 ~121 ~79 dirt
setblock ~189 ~121 ~80 dirt
setblock ~189 ~121 ~81 dirt
setblock ~189 ~121 ~99 dirt
setblock ~189 ~121 ~100 dirt
setblock ~189 ~121 ~101 dirt
setblock ~189 ~121 ~102 dirt
setblock ~189 ~121 ~103 dirt
setblock ~189 ~121 ~104 dirt
setblock ~189 ~121 ~105 dirt
setblock ~189 ~121 ~119 dirt
setblock ~189 ~121 ~120 dirt
setblock ~189 ~121 ~121 dirt
setblock ~189 ~121 ~123 dirt
setblock ~189 ~121 ~124 dirt
setblock ~189 ~121 ~125 dirt
setblock ~189 ~121 ~126 dirt
setblock ~189 ~121 ~127 dirt
setblock ~189 ~121 ~128 dirt
setblock ~189 ~121 ~129 dirt
setblock ~189 ~121 ~130 dirt
setblock ~189 ~121 ~131 dirt
setblock ~189 ~121 ~132 dirt
setblock ~189 ~121 ~133 dirt
setblock ~189 ~121 ~134 dirt
setblock ~189 ~121 ~137 dirt
setblock ~189 ~121 ~139 dirt
setblock ~189 ~122 ~59 dirt
setblock ~189 ~122 ~61 dirt
setblock ~189 ~122 ~62 dirt
setblock ~189 ~122 ~63 dirt
setblock ~189 ~122 ~64 dirt
setblock ~189 ~122 ~65 dirt
setblock ~189 ~122 ~69 dirt
setblock ~189 ~122 ~70 dirt
setblock ~189 ~122 ~71 dirt
setblock ~189 ~122 ~72 dirt
setblock ~189 ~122 ~78 dirt
setblock ~189 ~122 ~79 dirt
setblock ~189 ~122 ~80 dirt
setblock ~189 ~122 ~81 dirt
setblock ~189 ~122 ~99 dirt
setblock ~189 ~122 ~100 dirt
setblock ~189 ~122 ~101 dirt
setblock ~189 ~122 ~102 dirt
setblock ~189 ~122 ~103 dirt
setblock ~189 ~122 ~104 dirt
setblock ~189 ~122 ~105 dirt
setblock ~189 ~122 ~119 dirt
setblock ~189 ~122 ~120 dirt
setblock ~189 ~122 ~121 dirt
setblock ~189 ~122 ~123 dirt
setblock ~189 ~122 ~124 dirt
setblock ~189 ~122 ~125 dirt
setblock ~189 ~122 ~126 dirt
setblock ~189 ~122 ~127 dirt
setblock ~189 ~122 ~128 dirt
setblock ~189 ~122 ~129 dirt
setblock ~189 ~122 ~130 dirt
setblock ~189 ~122 ~131 dirt
setblock ~189 ~122 ~132 dirt
setblock ~189 ~122 ~133 dirt
setblock ~189 ~122 ~134 dirt
setblock ~189 ~122 ~137 dirt
setblock ~189 ~122 ~139 dirt
setblock ~189 ~123 ~59 dirt
setblock ~189 ~123 ~61 dirt
setblock ~189 ~123 ~62 dirt
setblock ~189 ~123 ~63 dirt
setblock ~189 ~123 ~64 dirt
setblock ~189 ~123 ~65 dirt
setblock ~189 ~123 ~69 dirt
setblock ~189 ~123 ~70 dirt
setblock ~189 ~123 ~71 dirt
setblock ~189 ~123 ~72 dirt
setblock ~189 ~123 ~78 dirt
setblock ~189 ~123 ~79 dirt
setblock ~189 ~123 ~80 dirt
setblock ~189 ~123 ~81 dirt
setblock ~189 ~123 ~99 dirt
setblock ~189 ~123 ~100 dirt
setblock ~189 ~123 ~101 dirt
setblock ~189 ~123 ~102 dirt
setblock ~189 ~123 ~103 dirt
setblock ~189 ~123 ~104 dirt
setblock ~189 ~123 ~105 dirt
setblock ~189 ~123 ~119 dirt
setblock ~189 ~123 ~120 dirt
setblock ~189 ~123 ~121 dirt
setblock ~189 ~123 ~123 dirt
setblock ~189 ~123 ~124 dirt
setblock ~189 ~123 ~125 dirt
setblock ~189 ~123 ~126 dirt
setblock ~189 ~123 ~127 dirt
setblock ~189 ~123 ~128 dirt
setblock ~189 ~123 ~129 dirt
setblock ~189 ~123 ~130 dirt
setblock ~189 ~123 ~131 dirt
setblock ~189 ~123 ~132 dirt
setblock ~189 ~123 ~133 dirt
setblock ~189 ~123 ~134 dirt
setblock ~189 ~123 ~137 grass_block
setblock ~189 ~123 ~139 grass_block
setblock ~189 ~124 ~59 dirt
setblock ~189 ~124 ~61 dirt
setblock ~189 ~124 ~62 dirt
setblock ~189 ~124 ~63 dirt
setblock ~189 ~124 ~64 dirt
setblock ~189 ~124 ~65 dirt
setblock ~189 ~124 ~69 dirt
setblock ~189 ~124 ~70 dirt
setblock ~189 ~124 ~71 dirt
setblock ~189 ~124 ~72 dirt
setblock ~189 ~124 ~78 grass_block
setblock ~189 ~124 ~79 grass_block
setblock ~189 ~124 ~80 grass_block
setblock ~189 ~124 ~81 grass_block
setblock ~189 ~124 ~99 dirt
setblock ~189 ~124 ~100 dirt
setblock ~189 ~124 ~101 dirt
setblock ~189 ~124 ~102 dirt
setblock ~189 ~124 ~103 dirt
setblock ~189 ~124 ~104 dirt
setblock ~189 ~124 ~105 dirt
setblock ~189 ~124 ~119 grass_block
setblock ~189 ~124 ~120 grass_block
setblock ~189 ~124 ~121 grass_block
setblock ~189 ~124 ~123 grass_block
setblock ~189 ~124 ~124 grass_block
setblock ~189 ~124 ~125 grass_block
setblock ~189 ~124 ~126 grass_block
setblock ~189 ~124 ~127 grass_block
setblock ~189 ~124 ~128 grass_block
setblock ~189 ~124 ~129 grass_block
setblock ~189 ~124 ~130 grass_block
setblock ~189 ~124 ~131 grass_block
setblock ~189 ~124 ~132 grass_block
setblock ~189 ~124 ~133 grass_block
setblock ~189 ~124 ~134 grass_block
setblock ~189 ~124 ~137 poppy
setblock ~189 ~125 ~59 dirt
setblock ~189 ~125 ~61 dirt
setblock ~189 ~125 ~62 dirt
setblock ~189 ~125 ~63 dirt
setblock ~189 ~125 ~64 dirt
setblock ~189 ~125 ~65 dirt
setblock ~189 ~125 ~69 dirt
setblock ~189 ~125 ~70 dirt
setblock ~189 ~125 ~71 dirt
setblock ~189 ~125 ~72 dirt
setblock ~189 ~125 ~80 short_grass
setblock ~189 ~125 ~81 short_grass
setblock ~189 ~125 ~99 dirt
setblock ~189 ~125 ~100 dirt
setblock ~189 ~125 ~101 dirt
setblock ~189 ~125 ~102 dirt
setblock ~189 ~125 ~103 dirt
setblock ~189 ~125 ~104 dirt
setblock ~189 ~125 ~105 dirt
setblock ~189 ~125 ~121 short_grass
setblock ~189 ~125 ~125 poppy
setblock ~189 ~125 ~126 short_grass
setblock ~189 ~125 ~129 short_grass
setblock ~189 ~125 ~132 short_grass
setblock ~189 ~126 ~59 dirt
setblock ~189 ~126 ~61 dirt
setblock ~189 ~126 ~62 dirt
setblock ~189 ~126 ~63 dirt
setblock ~189 ~126 ~64 dirt
setblock ~189 ~126 ~65 dirt
setblock ~189 ~126 ~69 dirt
setblock ~189 ~126 ~70 dirt
setblock ~189 ~126 ~71 dirt
setblock ~189 ~126 ~72 dirt
setblock ~189 ~126 ~99 dirt
setblock ~189 ~126 ~100 dirt
setblock ~189 ~126 ~101 dirt
setblock ~189 ~126 ~102 dirt
setblock ~189 ~126 ~103 dirt
setblock ~189 ~126 ~104 dirt
setblock ~189 ~126 ~105 dirt
setblock ~189 ~127 ~59 grass_block
setblock ~189 ~127 ~61 dirt
setblock ~189 ~127 ~62 dirt
setblock ~189 ~127 ~63 dirt
setblock ~189 ~127 ~64 dirt
setblock ~189 ~127 ~65 dirt
setblock ~189 ~127 ~69 dirt
setblock ~189 ~127 ~70 dirt
setblock ~189 ~127 ~71 dirt
setblock ~189 ~127 ~72 grass_block
setblock ~189 ~127 ~99 dirt
setblock ~189 ~127 ~100 dirt
setblock ~189 ~127 ~101 dirt
setblock ~189 ~127 ~102 dirt
setblock ~189 ~127 ~103 dirt
setblock ~189 ~127 ~104 dirt
setblock ~189 ~127 ~105 dirt
setblock ~189 ~128 ~61 grass_block
setblock ~189 ~128 ~62 grass_block
setblock ~189 ~128 ~63 grass_block
setblock ~189 ~128 ~64 grass_block
setblock ~189 ~128 ~65 grass_block
setblock ~189 ~128 ~69 grass_block
setblock ~189 ~128 ~70 grass_block
setblock ~189 ~128 ~71 grass_block
setblock ~189 ~128 ~99 dirt
setblock ~189 ~128 ~100 dirt
setblock ~189 ~128 ~101 dirt
setblock ~189 ~128 ~102 dirt
setblock ~189 ~128 ~103 dirt
setblock ~189 ~128 ~104 dirt
setblock ~189 ~128 ~105 dirt
setblock ~189 ~129 ~70 short_grass
setblock ~189 ~129 ~71 poppy
setblock ~189 ~129 ~99 grass_block
setblock ~189 ~129 ~100 dirt
setblock ~189 ~129 ~101 dirt
setblock ~189 ~129 ~102 dirt
setblock ~189 ~129 ~103 dirt
setblock ~189 ~129 ~104 grass_block
setblock ~189 ~129 ~105 grass_block
setblock ~189 ~130 ~99 poppy
setblock ~189 ~130 ~100 dirt
setblock ~189 ~130 ~101 grass_block
setblock ~189 ~130 ~102 grass_block
setblock ~189 ~130 ~103 grass_block
setblock ~189 ~130 ~105 short_grass
setblock ~189 ~131 ~100 grass_block
setblock ~189 ~131 ~101 short_grass
setblock ~189 ~131 ~103 poppy
setblock ~190 ~117 ~63 dirt
setblock ~190 ~117 ~102 dirt
setblock ~190 ~117 ~103 dirt
setblock ~190 ~118 ~62 dirt
setblock ~190 ~118 ~63 dirt
setblock ~190 ~118 ~70 dirt
setblock ~190 ~118 ~102 dirt
setblock ~190 ~118 ~103 dirt
setblock ~190 ~119 ~62 dirt
setblock ~190 ~119 ~63 dirt
setblock ~190 ~119 ~64 dirt
setblock ~190 ~119 ~70 dirt
setblock ~190 ~119 ~101 dirt
setblock ~190 ~119 ~102 dirt
setblock ~190 ~119 ~103 dirt
setblock ~190 ~119 ~126 dirt
setblock ~190 ~119 ~127 dirt
setblock ~190 ~120 ~61 dirt
setblock ~190 ~120 ~62 dirt
setblock ~190 ~120 ~63 dirt
setblock ~190 ~120 ~64 dirt
setblock ~190 ~120 ~65 dirt
setblock ~190 ~120 ~69 dirt
setblock ~190 ~120 ~70 dirt
setblock ~190 ~120 ~71 dirt
setblock ~190 ~120 ~79 dirt
setblock ~190 ~120 ~100 dirt
setblock ~190 ~120 ~101 dirt
setblock ~190 ~120 ~102 dirt
setblock ~190 ~120 ~103 dirt
setblock ~190 ~120 ~125 dirt
setblock ~190 ~120 ~126 dirt
setblock ~190 ~120 ~127 dirt
setblock ~190 ~121 ~60 dirt
setblock ~190 ~121 ~61 dirt
setblock ~190 ~121 ~62 dirt
setblock ~190 ~121 ~63 dirt
setblock ~190 ~121 ~64 dirt
setblock ~190 ~121 ~65 dirt
setblock ~190 ~121 ~69 dirt
setblock ~190 ~121 ~70 dirt
setblock ~190 ~121 ~71 dirt
setblock ~190 ~121 ~79 dirt
setblock ~190 ~121 ~80 dirt
setblock ~190 ~121 ~100 dirt
setblock ~190 ~121 ~101 dirt
setblock ~190 ~121 ~102 dirt
setblock ~190 ~121 ~103 dirt
setblock ~190 ~121 ~104 dirt
setblock ~190 ~121 ~125 dirt
setblock ~190 ~121 ~126 dirt
setblock ~190 ~121 ~127 dirt
setblock ~190 ~121 ~128 dirt
setblock ~190 ~121 ~131 dirt
setblock ~190 ~121 ~132 dirt
setblock ~190 ~122 ~60 dirt
setblock ~190 ~122 ~61 dirt
setblock ~190 ~122 ~62 dirt
setblock ~190 ~122 ~63 dirt
setblock ~190 ~122 ~64 dirt
setblock ~190 ~122 ~65 dirt
setblock ~190 ~122 ~69 dirt
setblock ~190 ~122 ~70 dirt
setblock ~190 ~122 ~71 dirt
setblock ~190 ~122 ~79 dirt
setblock ~190 ~122 ~80 dirt
setblock ~190 ~122 ~100 dirt
setblock ~190 ~122 ~101 dirt
setblock ~190 ~122 ~102 dirt
setblock ~190 ~122 ~103 dirt
setblock ~190 ~122 ~104 dirt
setblock ~190 ~122 ~125 dirt
setblock ~190 ~122 ~126 dirt
setblock ~190 ~122 ~127 dirt
setblock ~190 ~122 ~128 dirt
setblock ~190 ~122 ~131 dirt
setblock ~190 ~122 ~132 dirt
setblock ~190 ~123 ~60 dirt
setblock ~190 ~123 ~61 dirt
setblock ~190 ~123 ~62 dirt
setblock ~190 ~123 ~63 dirt
setblock ~190 ~123 ~64 dirt
setblock ~190 ~123 ~65 dirt
setblock ~190 ~123 ~69 dirt
setblock ~190 ~123 ~70 dirt
setblock ~190 ~123 ~71 dirt
setblock ~190 ~123 ~79 dirt
setblock ~190 ~123 ~80 grass_block
setblock ~190 ~123 ~100 dirt
setblock ~190 ~123 ~101 dirt
setblock ~190 ~123 ~102 dirt
setblock ~190 ~123 ~103 dirt
setblock ~190 ~123 ~104 dirt
setblock ~190 ~123 ~125 dirt
setblock ~190 ~123 ~126 dirt
setblock ~190 ~123 ~127 dirt
setblock ~190 ~123 ~128 dirt
setblock ~190 ~123 ~131 dirt
setblock ~190 ~123 ~132 dirt
setblock ~190 ~124 ~60 dirt
setblock ~190 ~124 ~61 dirt
setblock ~190 ~124 ~62 dirt
setblock ~190 ~124 ~63 dirt
setblock ~190 ~124 ~64 dirt
setblock ~190 ~124 ~65 dirt
setblock ~190 ~124 ~69 dirt
setblock ~190 ~124 ~70 dirt
setblock ~190 ~124 ~71 dirt
setblock ~190 ~124 ~79 grass_block
setblock ~190 ~124 ~100 dirt
setblock ~190 ~124 ~101 dirt
setblock ~190 ~124 ~102 dirt
setblock ~190 ~124 ~103 dirt
setblock ~190 ~124 ~104 dirt
setblock ~190 ~124 ~125 grass_block
setblock ~190 ~124 ~126 grass_block
setblock ~190 ~124 ~127 grass_block
setblock ~190 ~124 ~128 grass_block
setblock ~190 ~124 ~131 grass_block
setblock ~190 ~124 ~132 grass_block
setblock ~190 ~125 ~60 dirt
setblock ~190 ~125 ~61 dirt
setblock ~190 ~125 ~62 dirt
setblock ~190 ~125 ~63 dirt
setblock ~190 ~125 ~64 dirt
setblock ~190 ~125 ~65 dirt
setblock ~190 ~125 ~69 dirt
setblock ~190 ~125 ~70 dirt
setblock ~190 ~125 ~71 dirt
setblock ~190 ~125 ~100 dirt
setblock ~190 ~125 ~101 dirt
setblock ~190 ~125 ~102 dirt
setblock ~190 ~125 ~103 dirt
setblock ~190 ~125 ~104 dirt
setblock ~190 ~125 ~126 short_grass
setblock ~190 ~125 ~128 short_grass
setblock ~190 ~126 ~60 dirt
setblock ~190 ~126 ~61 dirt
setblock ~190 ~126 ~62 dirt
setblock ~190 ~126 ~63 dirt
setblock ~190 ~126 ~64 dirt
setblock ~190 ~126 ~65 dirt
setblock ~190 ~126 ~69 dirt
setblock ~190 ~126 ~70 dirt
setblock ~190 ~126 ~71 dirt
setblock ~190 ~126 ~100 dirt
setblock ~190 ~126 ~101 dirt
setblock ~190 ~126 ~102 dirt
setblock ~190 ~126 ~103 dirt
setblock ~190 ~126 ~104 dirt
setblock ~190 ~127 ~60 dirt
setblock ~190 ~127 ~61 dirt
setblock ~190 ~127 ~62 dirt
setblock ~190 ~127 ~63 dirt
setblock ~190 ~127 ~64 dirt
setblock ~190 ~127 ~65 dirt
setblock ~190 ~127 ~69 dirt
setblock ~190 ~127 ~70 dirt
setblock ~190 ~127 ~71 dirt
setblock ~190 ~127 ~100 dirt
setblock ~190 ~127 ~101 dirt
setblock ~190 ~127 ~102 dirt
setblock ~190 ~127 ~103 dirt
setblock ~190 ~127 ~104 dirt
setblock ~190 ~128 ~60 grass_block
setblock ~190 ~128 ~61 grass_block
setblock ~190 ~128 ~62 dirt
setblock ~190 ~128 ~63 dirt
setblock ~190 ~128 ~64 dirt
setblock ~190 ~128 ~65 dirt
setblock ~190 ~128 ~69 dirt
setblock ~190 ~128 ~70 dirt
setblock ~190 ~128 ~71 grass_block
setblock ~190 ~128 ~100 dirt
setblock ~190 ~128 ~101 dirt
setblock ~190 ~128 ~102 dirt
setblock ~190 ~128 ~103 dirt
setblock ~190 ~128 ~104 dirt
setblock ~190 ~129 ~60 short_grass
setblock ~190 ~129 ~62 grass_block
setblock ~190 ~129 ~63 grass_block
setblock ~190 ~129 ~64 grass_block
setblock ~190 ~129 ~65 grass_block
setblock ~190 ~129 ~69 grass_block
setblock ~190 ~129 ~70 grass_block
setblock ~190 ~129 ~71 poppy
setblock ~190 ~129 ~100 dirt
setblock ~190 ~129 ~101 dirt
setblock ~190 ~129 ~102 dirt
setblock ~190 ~129 ~103 dirt
setblock ~190 ~129 ~104 dirt
setblock ~190 ~130 ~100 dirt
setblock ~190 ~130 ~101 dirt
setblock ~190 ~130 ~102 dirt
setblock ~190 ~130 ~103 grass_block
setblock ~190 ~130 ~104 grass_block
setblock ~190 ~131 ~100 grass_block
setblock ~190 ~131 ~101 grass_block
setblock ~190 ~131 ~102 grass_block
setblock ~190 ~131 ~104 short_grass
setblock ~190 ~132 ~101 fern
setblock ~191 ~119 ~63 dirt
setblock ~191 ~119 ~102 dirt
setblock ~191 ~120 ~62 dirt
setblock ~191 ~120 ~63 dirt
setblock ~191 ~120 ~64 dirt
setblock ~191 ~120 ~70 dirt
setblock ~191 ~120 ~101 dirt
setblock ~191 ~120 ~102 dirt
setblock ~191 ~120 ~103 dirt
setblock ~191 ~120 ~126 dirt
setblock ~191 ~121 ~61 dirt
setblock ~191 ~121 ~62 dirt
setblock ~191 ~121 ~63 dirt
setblock ~191 ~121 ~64 dirt
setblock ~191 ~121 ~70 dirt
setblock ~191 ~121 ~101 dirt
setblock ~191 ~121 ~102 dirt
setblock ~191 ~121 ~103 dirt
setblock ~191 ~121 ~125 dirt
setblock ~191 ~121 ~126 dirt
setblock ~191 ~121 ~127 dirt
setblock ~191 ~122 ~61 dirt
setblock ~191 ~122 ~62 dirt
setblock ~191 ~122 ~63 dirt
setblock ~191 ~122 ~64 dirt
setblock ~191 ~122 ~70 dirt
setblock ~191 ~122 ~101 dirt
setblock ~191 ~122 ~102 dirt
setblock ~191 ~122 ~103 dirt
setblock ~191 ~122 ~125 dirt
setblock ~191 ~122 ~126 dirt
setblock ~191 ~122 ~127 dirt
setblock ~191 ~123 ~61 dirt
setblock ~191 ~123 ~62 dirt
setblock ~191 ~123 ~63 dirt
setblock ~191 ~123 ~64 dirt
setblock ~191 ~123 ~70 dirt
setblock ~191 ~123 ~101 dirt
setblock ~191 ~123 ~102 dirt
setblock ~191 ~123 ~103 dirt
setblock ~191 ~123 ~125 dirt
setblock ~191 ~123 ~126 dirt
setblock ~191 ~123 ~127 dirt
setblock ~191 ~124 ~61 dirt
setblock ~191 ~124 ~62 dirt
setblock ~191 ~124 ~63 dirt
setblock ~191 ~124 ~64 dirt
setblock ~191 ~124 ~70 dirt
setblock ~191 ~124 ~101 dirt
setblock ~191 ~124 ~102 dirt
setblock ~191 ~124 ~103 dirt
setblock ~191 ~124 ~125 grass_block
setblock ~191 ~124 ~126 grass_block
setblock ~191 ~124 ~127 grass_block
setblock ~191 ~125 ~61 dirt
setblock ~191 ~125 ~62 dirt
setblock ~191 ~125 ~63 dirt
setblock ~191 ~125 ~64 dirt
setblock ~191 ~125 ~70 dirt
setblock ~191 ~125 ~101 dirt
setblock ~191 ~125 ~102 dirt
setblock ~191 ~125 ~103 dirt
setblock ~191 ~125 ~125 short_grass
setblock ~191 ~126 ~61 dirt
setblock ~191 ~126 ~62 dirt
setblock ~191 ~126 ~63 dirt
setblock ~191 ~126 ~64 dirt
setblock ~191 ~126 ~70 dirt
setblock ~191 ~126 ~101 dirt
setblock ~191 ~126 ~102 dirt
setblock ~191 ~126 ~103 dirt
setblock ~191 ~127 ~61 dirt
setblock ~191 ~127 ~62 dirt
setblock ~191 ~127 ~63 dirt
setblock ~191 ~127 ~64 dirt
setblock ~191 ~127 ~70 dirt
setblock ~191 ~127 ~101 dirt
setblock ~191 ~127 ~102 dirt
setblock ~191 ~127 ~103 dirt
setblock ~191 ~128 ~61 grass_block
setblock ~191 ~128 ~62 grass_block
setblock ~191 ~128 ~63 grass_block
setblock ~191 ~128 ~64 grass_block
setblock ~191 ~128 ~70 grass_block
setblock ~191 ~128 ~101 dirt
setblock ~191 ~128 ~102 dirt
setblock ~191 ~128 ~103 dirt
setblock ~191 ~129 ~64 short_grass
setblock ~191 ~129 ~70 short_grass
setblock ~191 ~129 ~101 dirt
setblock ~191 ~129 ~102 dirt
setblock ~191 ~129 ~103 dirt
setblock ~191 ~130 ~101 dirt
setblock ~191 ~130 ~102 grass_block
setblock ~191 ~130 ~103 grass_block
setblock ~191 ~131 ~101 grass_block
setblock ~191 ~131 ~102 short_grass
setblock ~191 ~132 ~101 short_grass
setblock ~192 ~120 ~102 dirt
setblock ~192 ~121 ~62 dirt
setblock ~192 ~121 ~102 dirt
setblock ~192 ~121 ~126 dirt
setblock ~192 ~122 ~62 dirt
setblock ~192 ~122 ~102 dirt
setblock ~192 ~122 ~126 dirt
setblock ~192 ~123 ~62 dirt
setblock ~192 ~123 ~102 dirt
setblock ~192 ~123 ~126 dirt
setblock ~192 ~124 ~62 dirt
setblock ~192 ~124 ~102 dirt
setblock ~192 ~124 ~126 grass_block
setblock ~192 ~125 ~62 dirt
setblock ~192 ~125 ~102 dirt
setblock ~192 ~126 ~62 dirt
setblock ~192 ~126 ~102 dirt
setblock ~192 ~127 ~62 grass_block
setblock ~192 ~127 ~102 dirt
setblock ~192 ~128 ~102 dirt
setblock ~192 ~129 ~102 dirt
setblock ~192 ~130 ~102 grass_block
setblock ~199 ~200 ~199 gold_block
