setblock ~96 ~125 ~137 dirt
setblock ~96 ~125 ~138 dirt
setblock ~96 ~125 ~139 dirt
setblock ~96 ~125 ~140 dirt
setblock ~96 ~125 ~141 dirt
setblock ~96 ~125 ~142 dirt
setblock ~96 ~125 ~143 dirt
setblock ~96 ~125 ~144 dirt
setblock ~96 ~125 ~145 dirt
setblock ~96 ~125 ~146 dirt
setblock ~96 ~125 ~147 dirt
setblock ~96 ~125 ~148 dirt
setblock ~96 ~125 ~149 dirt
setblock ~96 ~125 ~150 dirt
setblock ~96 ~125 ~151 dirt
setblock ~96 ~125 ~152 dirt
setblock ~96 ~125 ~153 dirt
setblock ~96 ~125 ~154 dirt
setblock ~96 ~125 ~155 dirt
setblock ~96 ~125 ~156 dirt
setblock ~96 ~125 ~157 dirt
setblock ~96 ~125 ~158 dirt
setblock ~96 ~125 ~159 dirt
setblock ~96 ~125 ~160 grass_block
setblock ~96 ~125 ~161 grass_block
setblock ~96 ~125 ~162 grass_block
setblock ~96 ~125 ~163 grass_block
setblock ~96 ~125 ~164 poppy
setblock ~96 ~125 ~165 short_grass
setblock ~96 ~125 ~177 short_grass
setblock ~96 ~125 ~179 grass_block
setblock ~96 ~125 ~180 grass_block
setblock ~96 ~125 ~181 grass_block
setblock ~96 ~125 ~182 grass_block
setblock ~96 ~125 ~183 grass_block
setblock ~96 ~125 ~184 grass_block
setblock ~96 ~125 ~185 grass_block
setblock ~96 ~125 ~186 dirt
setblock ~96 ~125 ~187 dirt
setblock ~96 ~125 ~188 dirt
setblock ~96 ~125 ~189 dirt
setblock ~96 ~125 ~190 dirt
setblock ~96 ~125 ~191 grass_block
setblock ~96 ~125 ~192 grass_block
setblock ~96 ~125 ~193 grass_block
setblock ~96 ~125 ~194 grass_block
setblock ~96 ~125 ~195 grass_block
setblock ~96 ~125 ~199 short_grass
setblock ~96 ~126 ~3 poppy
setblock ~96 ~126 ~4 short_grass
setblock ~96 ~126 ~5 fern
setblock ~96 ~126 ~6 short_grass
setblock ~96 ~126 ~7 grass_block
setblock ~96 ~126 ~8 grass_block
setblock ~96 ~126 ~9 grass_block
setblock ~96 ~126 ~10 grass_block
setblock ~96 ~126 ~11 grass_block
setblock ~96 ~126 ~12 grass_block
setblock ~96 ~126 ~13 grass_block
setblock ~96 ~126 ~14 grass_block
setblock ~96 ~126 ~15 grass_block
setblock ~96 ~126 ~23 short_grass
setblock ~96 ~126 ~24 short_grass
setblock ~96 ~126 ~25 grass_block
setblock ~96 ~126 ~26 grass_block
setblock ~96 ~126 ~27 grass_block
setblock ~96 ~126 ~28 grass_block
setblock ~96 ~126 ~29 grass_block
setblock ~96 ~126 ~30 grass_block
setblock ~96 ~126 ~31 grass_block
setblock ~96 ~126 ~32 short_grass
setblock ~96 ~126 ~49 short_grass
setblock ~96 ~126 ~50 grass_block
setblock ~96 ~126 ~51 grass_block
setblock ~96 ~126 ~52 grass_block
setblock ~96 ~126 ~53 short_grass
setblock ~96 ~126 ~55 short_grass
setblock ~96 ~126 ~93 short_grass
setblock ~96 ~126 ~94 poppy
setblock ~96 ~126 ~96 poppy
setblock ~96 ~126 ~98 fern
setblock ~96 ~126 ~102 short_grass
setblock ~96 ~126 ~104 short_grass
setblock ~96 ~126 ~108 short_grass
setblock ~96 ~126 ~110 short_grass
setblock ~96 ~126 ~133 short_grass
setblock ~96 ~126 ~134 short_grass
setblock ~96 ~126 ~135 grass_block
setblock ~96 ~126 ~136 grass_block
setblock ~96 ~126 ~137 grass_block
setblock ~96 ~126 ~138 dirt
setblock ~96 ~126 ~139 dirt
setblock ~96 ~126 ~140 dirt
setblock ~96 ~126 ~141 dirt
setblock ~96 ~126 ~142 dirt
setblock ~96 ~126 ~143 dirt
setblock ~96 ~126 ~144 dirt
setblock ~96 ~126 ~145 dirt
setblock ~96 ~126 ~146 dirt
setblock ~96 ~126 ~147 dirt
setblock ~96 ~126 ~148 dirt
setblock ~96 ~126 ~149 grass_block
setblock ~96 ~126 ~150 grass_block
setblock ~96 ~126 ~151 grass_block
setblock ~96 ~126 ~152 grass_block
setblock ~96 ~126 ~153 grass_block
setblock ~96 ~126 ~154 grass_block
setblock ~96 ~126 ~155 grass_block
setblock ~96 ~126 ~156 grass_block
setblock ~96 ~126 ~157 grass_block
setblock ~96 ~126 ~158 grass_block
setblock ~96 ~126 ~159 grass_block
setblock ~96 ~126 ~160 short_grass
setblock ~96 ~126 ~161 short_grass
setblock ~96 ~126 ~179 fern
setblock ~96 ~126 ~184 short_grass
setblock ~96 ~126 ~186 grass_block
setblock ~96 ~126 ~187 grass_block
setblock ~96 ~126 ~188 grass_block
setblock ~96 ~126 ~189 grass_block
setblock ~96 ~126 ~190 grass_block
setblock ~96 ~126 ~192 short_grass
setblock ~96 ~127 ~14 fern
setblock ~96 ~127 ~26 fern
setblock ~96 ~127 ~27 short_grass
setblock ~96 ~127 ~30 short_grass
setblock ~96 ~127 ~51 short_grass
setblock ~96 ~127 ~52 short_grass
setblock ~96 ~127 ~138 grass_block
setblock ~96 ~127 ~139 grass_block
setblock ~96 ~127 ~140 grass_block
setblock ~96 ~127 ~141 grass_block
setblock ~96 ~127 ~142 grass_block
setblock ~96 ~127 ~143 grass_block
setblock ~96 ~127 ~144 grass_block
setblock ~96 ~127 ~145 grass_block
setblock ~96 ~127 ~146 grass_block
setblock ~96 ~127 ~147 grass_block
setblock ~96 ~127 ~148 grass_block
setblock ~96 ~127 ~149 short_grass
setblock ~96 ~127 ~150 short_grass
setblock ~96 ~127 ~151 poppy
setblock ~96 ~127 ~153 short_grass
setblock ~96 ~127 ~187 short_grass
setblock ~96 ~128 ~141 short_grass
setblock ~96 ~128 ~145 poppy
setblock ~96 ~128 ~146 short_grass
setblock ~97 ~122 ~0 dirt
setblock ~97 ~122 ~1 dirt
setblock ~97 ~122 ~2 dirt
setblock ~97 ~122 ~3 dirt
setblock ~97 ~122 ~4 dirt
setblock ~97 ~122 ~5 dirt
setblock ~97 ~122 ~6 dirt
setblock ~97 ~122 ~7 dirt
setblock ~97 ~122 ~8 dirt
setblock ~97 ~122 ~9 dirt
setblock ~97 ~122 ~10 dirt
setblock ~97 ~122 ~11 dirt
setblock ~97 ~122 ~12 dirt
setblock ~97 ~122 ~13 dirt
setblock ~97 ~122 ~14 dirt
setblock ~97 ~122 ~15 dirt
setblock ~97 ~122 ~16 dirt
setblock ~97 ~122 ~17 dirt
setblock ~97 ~122 ~18 dirt
setblock ~97 ~122 ~19 dirt
setblock ~97 ~122 ~20 dirt
setblock ~97 ~122 ~21 dirt
setblock ~97 ~122 ~22 dirt
setblock ~97 ~122 ~23 dirt
setblock ~97 ~122 ~24 dirt
setblock ~97 ~122 ~25 dirt
setblock ~97 ~122 ~26 dirt
setblock ~97 ~122 ~27 dirt
setblock ~97 ~122 ~28 dirt
setblock ~97 ~122 ~29 dirt
setblock ~97 ~122 ~30 dirt
setblock ~97 ~122 ~31 dirt
setblock ~97 ~122 ~32 dirt
setblock ~97 ~122 ~33 dirt
setblock ~97 ~122 ~34 dirt
setblock ~97 ~122 ~35 dirt
setblock ~97 ~122 ~36 dirt
setblock ~97 ~122 ~37 dirt
setblock ~97 ~122 ~38 dirt
setblock ~97 ~122 ~39 dirt
setblock ~97 ~122 ~40 dirt
setblock ~97 ~122 ~41 dirt
setblock ~97 ~122 ~42 dirt
setblock ~97 ~122 ~43 dirt
setblock ~97 ~122 ~44 dirt
setblock ~97 ~122 ~45 dirt
setblock ~97 ~122 ~46 dirt
setblock ~97 ~122 ~47 dirt
setblock ~97 ~122 ~48 dirt
setblock ~97 ~122 ~49 dirt
setblock ~97 ~122 ~50 dirt
setblock ~97 ~122 ~51 dirt
setblock ~97 ~122 ~52 dirt
setblock ~97 ~122 ~53 dirt
setblock ~97 ~122 ~54 dirt
setblock ~97 ~122 ~55 dirt
setblock ~97 ~122 ~56 dirt
setblock ~97 ~122 ~57 dirt
setblock ~97 ~122 ~58 dirt
setblock ~97 ~122 ~59 dirt
setblock ~97 ~122 ~60 dirt
setblock ~97 ~122 ~61 dirt
setblock ~97 ~122 ~62 dirt
setblock ~97 ~122 ~63 dirt
setblock ~97 ~122 ~64 dirt
setblock ~97 ~122 ~65 dirt
setblock ~97 ~122 ~66 dirt
setblock ~97 ~122 ~67 dirt
setblock ~97 ~122 ~68 dirt
setblock ~97 ~122 ~69 dirt
setblock ~97 ~122 ~70 dirt
setblock ~97 ~122 ~71 dirt
setblock ~97 ~122 ~72 dirt
setblock ~97 ~122 ~73 dirt
setblock ~97 ~122 ~74 dirt
setblock ~97 ~122 ~75 dirt
setblock ~97 ~122 ~76 dirt
setblock ~97 ~122 ~77 dirt
setblock ~97 ~122 ~78 dirt
setblock ~97 ~122 ~79 dirt
setblock ~97 ~122 ~80 dirt
setblock ~97 ~122 ~81 dirt
setblock ~97 ~122 ~82 dirt
setblock ~97 ~122 ~83 dirt
setblock ~97 ~122 ~84 dirt
setblock ~97 ~122 ~85 dirt
setblock ~97 ~122 ~86 dirt
setblock ~97 ~122 ~87 dirt
setblock ~97 ~122 ~88 dirt
setblock ~97 ~122 ~89 dirt
setblock ~97 ~122 ~90 dirt
setblock ~97 ~122 ~91 dirt
setblock ~97 ~122 ~92 dirt
setblock ~97 ~122 ~93 dirt
setblock ~97 ~122 ~94 dirt
setblock ~97 ~122 ~95 dirt
setblock ~97 ~122 ~96 dirt
setblock ~97 ~122 ~97 dirt
setblock ~97 ~122 ~98 dirt
setblock ~97 ~122 ~99 dirt
setblock ~97 ~122 ~100 dirt
setblock ~97 ~122 ~101 dirt
setblock ~97 ~122 ~102 dirt
setblock ~97 ~122 ~103 dirt
setblock ~97 ~122 ~104 dirt
setblock ~97 ~122 ~105 dirt
setblock ~97 ~122 ~106 dirt
setblock ~97 ~122 ~107 dirt
setblock ~97 ~122 ~108 dirt
setblock ~97 ~122 ~109 dirt
setblock ~97 ~122 ~110 dirt
setblock ~97 ~122 ~111 dirt
setblock ~97 ~122 ~112 dirt
setblock ~97 ~122 ~113 dirt
setblock ~97 ~122 ~114 dirt
setblock ~97 ~122 ~115 dirt
setblock ~97 ~122 ~116 dirt
setblock ~97 ~122 ~117 dirt
setblock ~97 ~122 ~118 dirt
setblock ~97 ~122 ~119 dirt
setblock ~97 ~122 ~120 dirt
setblock ~97 ~122 ~121 dirt
setblock ~97 ~122 ~122 dirt
setblock ~97 ~122 ~123 dirt
setblock ~97 ~122 ~124 dirt
setblock ~97 ~122 ~125 dirt
setblock ~97 ~122 ~126 dirt
setblock ~97 ~122 ~127 dirt
setblock ~97 ~122 ~128 dirt
setblock ~97 ~122 ~129 dirt
setblock ~97 ~122 ~130 dirt
setblock ~97 ~122 ~131 dirt
setblock ~97 ~122 ~132 dirt
setblock ~97 ~122 ~133 dirt
setblock ~97 ~122 ~134 dirt
setblock ~97 ~122 ~135 dirt
setblock ~97 ~122 ~136 dirt
setblock ~97 ~122 ~137 dirt
setblock ~97 ~122 ~138 dirt
setblock ~97 ~122 ~139 dirt
setblock ~97 ~122 ~140 dirt
setblock ~97 ~122 ~141 dirt
setblock ~97 ~122 ~142 dirt
setblock ~97 ~122 ~143 dirt
setblock ~97 ~122 ~144 dirt
setblock ~97 ~122 ~145 dirt
setblock ~97 ~122 ~146 dirt
setblock ~97 ~122 ~147 dirt
setblock ~97 ~122 ~148 dirt
setblock ~97 ~122 ~149 dirt
setblock ~97 ~122 ~150 dirt
setblock ~97 ~122 ~151 dirt
setblock ~97 ~122 ~152 dirt
setblock ~97 ~122 ~153 dirt
setblock ~97 ~122 ~154 dirt
setblock ~97 ~122 ~155 dirt
setblock ~97 ~122 ~156 dirt
setblock ~97 ~122 ~157 dirt
setblock ~97 ~122 ~158 dirt
setblock ~97 ~122 ~159 dirt
setblock ~97 ~122 ~160 dirt
setblock ~97 ~122 ~161 dirt
setblock ~97 ~122 ~162 dirt
setblock ~97 ~122 ~163 dirt
setblock ~97 ~122 ~164 dirt
setblock ~97 ~122 ~165 dirt
setblock ~97 ~122 ~166 dirt
setblock ~97 ~122 ~167 dirt
setblock ~97 ~122 ~168 dirt
setblock ~97 ~122 ~169 grass_block
setblock ~97 ~122 ~170 grass_block
setblock ~97 ~122 ~171 grass_block
setblock ~97 ~122 ~172 dirt
setblock ~97 ~122 ~173 dirt
setblock ~97 ~122 ~174 dirt
setblock ~97 ~122 ~175 dirt
setblock ~97 ~122 ~176 dirt
setblock ~97 ~122 ~177 dirt
setblock ~97 ~122 ~178 dirt
setblock ~97 ~122 ~179 dirt
setblock ~97 ~122 ~180 dirt
setblock ~97 ~122 ~181 dirt
setblock ~97 ~122 ~182 dirt
setblock ~97 ~122 ~183 dirt
setblock ~97 ~122 ~184 dirt
setblock ~97 ~122 ~185 dirt
setblock ~97 ~122 ~186 dirt
setblock ~97 ~122 ~187 dirt
setblock ~97 ~122 ~188 dirt
setblock ~97 ~122 ~189 dirt
setblock ~97 ~122 ~190 dirt
setblock ~97 ~122 ~191 dirt
setblock ~97 ~122 ~192 dirt
setblock ~97 ~122 ~193 dirt
setblock ~97 ~122 ~194 dirt
setblock ~97 ~122 ~195 dirt
setblock ~97 ~122 ~196 dirt
setblock ~97 ~122 ~197 dirt
setblock ~97 ~122 ~198 dirt
setblock ~97 ~122 ~199 dirt
setblock ~97 ~123 ~0 dirt
setblock ~97 ~123 ~1 dirt
setblock ~97 ~123 ~2 dirt
setblock ~97 ~123 ~3 dirt
setblock ~97 ~123 ~4 dirt
setblock ~97 ~123 ~5 dirt
setblock ~97 ~123 ~6 dirt
setblock ~97 ~123 ~7 dirt
setblock ~97 ~123 ~8 dirt
setblock ~97 ~123 ~9 dirt
setblock ~97 ~123 ~10 dirt
setblock ~97 ~123 ~11 dirt
setblock ~97 ~123 ~12 dirt
setblock ~97 ~123 ~13 dirt
setblock ~97 ~123 ~14 dirt
setblock ~97 ~123 ~15 dirt
setblock ~97 ~123 ~16 dirt
setblock ~97 ~123 ~17 dirt
setblock ~97 ~123 ~18 dirt
setblock ~97 ~123 ~19 dirt
setblock ~97 ~123 ~20 dirt
setblock ~97 ~123 ~21 dirt
setblock ~97 ~123 ~22 dirt
setblock ~97 ~123 ~23 dirt
setblock ~97 ~123 ~24 dirt
setblock ~97 ~123 ~25 dirt
setblock ~97 ~123 ~26 dirt
setblock ~97 ~123 ~27 dirt
setblock ~97 ~123 ~28 dirt
setblock ~97 ~123 ~29 dirt
setblock ~97 ~123 ~30 dirt
setblock ~97 ~123 ~31 dirt
setblock ~97 ~123 ~32 dirt
setblock ~97 ~123 ~33 dirt
setblock ~97 ~123 ~34 dirt
setblock ~97 ~123 ~35 dirt
setblock ~97 ~123 ~36 dirt
setblock ~97 ~123 ~37 dirt
setblock ~97 ~123 ~38 grass_block
setblock ~97 ~123 ~39 grass_block
setblock ~97 ~123 ~40 grass_block
setblock ~97 ~123 ~41 grass_block
setblock ~97 ~123 ~42 grass_block
setblock ~97 ~123 ~43 dirt
setblock ~97 ~123 ~44 dirt
setblock ~97 ~123 ~45 dirt
setblock ~97 ~123 ~46 dirt
setblock ~97 ~123 ~47 dirt
setblock ~97 ~123 ~48 dirt
setblock ~97 ~123 ~49 dirt
setblock ~97 ~123 ~50 dirt
setblock ~97 ~123 ~51 dirt
setblock ~97 ~123 ~52 dirt
setblock ~97 ~123 ~53 dirt
setblock ~97 ~123 ~54 dirt
setblock ~97 ~123 ~55 dirt
setblock ~97 ~123 ~56 dirt
setblock ~97 ~123 ~57 dirt
setblock ~97 ~123 ~58 dirt
setblock ~97 ~123 ~59 dirt
setblock ~97 ~123 ~60 dirt
setblock ~97 ~123 ~61 dirt
setblock ~97 ~123 ~62 dirt
setblock ~97 ~123 ~63 dirt
setblock ~97 ~123 ~64 dirt
setblock ~97 ~123 ~65 dirt
setblock ~97 ~123 ~66 dirt
setblock ~97 ~123 ~67 grass_block
setblock ~97 ~123 ~68 grass_block
setblock ~97 ~123 ~69 grass_block
setblock ~97 ~123 ~70 grass_block
setblock ~97 ~123 ~71 grass_block
setblock ~97 ~123 ~72 grass_block
setblock ~97 ~123 ~73 grass_block
setblock ~97 ~123 ~74 grass_block
setblock ~97 ~123 ~75 grass_block
setblock ~97 ~123 ~76 grass_block
setblock ~97 ~123 ~77 grass_block
setblock ~97 ~123 ~78 grass_block
setblock ~97 ~123 ~79 grass_block
setblock ~97 ~123 ~80 grass_block
setblock ~97 ~123 ~81 grass_block
setblock ~97 ~123 ~82 grass_block
setblock ~97 ~123 ~83 dirt
setblock ~97 ~123 ~84 dirt
setblock ~97 ~123 ~85 dirt
setblock ~97 ~123 ~86 dirt
setblock ~97 ~123 ~87 dirt
setblock ~97 ~123 ~88 dirt
setblock ~97 ~123 ~89 dirt
setblock ~97 ~123 ~90 dirt
setblock ~97 ~123 ~91 dirt
setblock ~97 ~123 ~92 dirt
setblock ~97 ~123 ~93 dirt
setblock ~97 ~123 ~94 dirt
setblock ~97 ~123 ~95 dirt
setblock ~97 ~123 ~96 dirt
setblock ~97 ~123 ~97 dirt
setblock ~97 ~123 ~98 dirt
setblock ~97 ~123 ~99 dirt
setblock ~97 ~123 ~100 dirt
setblock ~97 ~123 ~101 dirt
setblock ~97 ~123 ~102 dirt
setblock ~97 ~123 ~103 dirt
setblock ~97 ~123 ~104 dirt
setblock ~97 ~123 ~105 dirt
setblock ~97 ~123 ~106 dirt
setblock ~97 ~123 ~107 dirt
setblock ~97 ~123 ~108 dirt
setblock ~97 ~123 ~109 dirt
setblock ~97 ~123 ~110 dirt
setblock ~97 ~123 ~111 dirt
setblock ~97 ~123 ~112 dirt
setblock ~97 ~123 ~113 dirt
setblock ~97 ~123 ~114 dirt
setblock ~97 ~123 ~115 dirt
setblock ~97 ~123 ~116 dirt
setblock ~97 ~123 ~117 dirt
setblock ~97 ~123 ~118 grass_block
setblock ~97 ~123 ~119 grass_block
setblock ~97 ~123 ~120 grass_block
setblock ~97 ~123 ~121 grass_block
setblock ~97 ~123 ~122 grass_block
setblock ~97 ~123 ~123 grass_block
setblock ~97 ~123 ~124 grass_block
setblock ~97 ~123 ~125 grass_block
setblock ~97 ~123 ~126 grass_block
setblock ~97 ~123 ~127 grass_block
setblock ~97 ~123 ~128 grass_block
setblock ~97 ~123 ~129 grass_block
setblock ~97 ~123 ~130 grass_block
setblock ~97 ~123 ~131 grass_block
setblock ~97 ~123 ~132 dirt
setblock ~97 ~123 ~133 dirt
setblock ~97 ~123 ~134 dirt
setblock ~97 ~123 ~135 dirt
setblock ~97 ~123 ~136 dirt
setblock ~97 ~123 ~137 dirt
setblock ~97 ~123 ~138 dirt
setblock ~97 ~123 ~139 dirt
setblock ~97 ~123 ~140 dirt
setblock ~97 ~123 ~141 dirt
setblock ~97 ~123 ~142 dirt
setblock ~97 ~123 ~143 dirt
setblock ~97 ~123 ~144 dirt
setblock ~97 ~123 ~145 dirt
setblock ~97 ~123 ~146 dirt
setblock ~97 ~123 ~147 dirt
setblock ~97 ~123 ~148 dirt
setblock ~97 ~123 ~149 dirt
setblock ~97 ~123 ~150 dirt
setblock ~97 ~123 ~151 dirt
setblock ~97 ~123 ~152 dirt
setblock ~97 ~123 ~153 dirt
setblock ~97 ~123 ~154 dirt
setblock ~97 ~123 ~155 dirt
setblock ~97 ~123 ~156 dirt
setblock ~97 ~123 ~157 dirt
setblock ~97 ~123 ~158 dirt
setblock ~97 ~123 ~159 dirt
setblock ~97 ~123 ~160 dirt
setblock ~97 ~123 ~161 dirt
setblock ~97 ~123 ~162 dirt
setblock ~97 ~123 ~163 dirt
setblock ~97 ~123 ~164 dirt
setblock ~97 ~123 ~165 dirt
setblock ~97 ~123 ~166 grass_block
setblock ~97 ~123 ~167 grass_block
setblock ~97 ~123 ~168 grass_block
setblock ~97 ~123 ~171 short_grass
setblock ~97 ~123 ~172 grass_block
setblock ~97 ~123 ~173 grass_block
setblock ~97 ~123 ~174 grass_block
setblock ~97 ~123 ~175 dirt
setblock ~97 ~123 ~176 dirt
setblock ~97 ~123 ~177 dirt
setblock ~97 ~123 ~178 dirt
setblock ~97 ~123 ~179 dirt
setblock ~97 ~123 ~180 dirt
setblock ~97 ~123 ~181 dirt
setblock ~97 ~123 ~182 dirt
setblock ~97 ~123 ~183 dirt
setblock ~97 ~123 ~184 dirt
setblock ~97 ~123 ~185 dirt
setblock ~97 ~123 ~186 dirt
setblock ~97 ~123 ~187 dirt
setblock ~97 ~123 ~188 dirt
setblock ~97 ~123 ~189 dirt
setblock ~97 ~123 ~190 dirt
setblock ~97 ~123 ~191 dirt
setblock ~97 ~123 ~192 dirt
setblock ~97 ~123 ~193 dirt
setblock ~97 ~123 ~194 dirt
setblock ~97 ~123 ~195 dirt
setblock ~97 ~123 ~196 dirt
setblock ~97 ~123 ~197 dirt
setblock ~97 ~123 ~198 dirt
setblock ~97 ~123 ~199 dirt
setblock ~97 ~124 ~0 dirt
setblock ~97 ~124 ~1 dirt
setblock ~97 ~124 ~2 dirt
setblock ~97 ~124 ~3 dirt
setblock ~97 ~124 ~4 dirt
setblock ~97 ~124 ~5 dirt
setblock ~97 ~124 ~6 dirt
setblock ~97 ~124 ~7 dirt
setblock ~97 ~124 ~8 dirt
setblock ~97 ~124 ~9 dirt
setblock ~97 ~124 ~10 dirt
setblock ~97 ~124 ~11 dirt
setblock ~97 ~124 ~12 dirt
setblock ~97 ~124 ~13 dirt
setblock ~97 ~124 ~14 dirt
setblock ~97 ~124 ~15 dirt
setblock ~97 ~124 ~16 dirt
setblock ~97 ~124 ~17 dirt
setblock ~97 ~124 ~18 dirt
setblock ~97 ~124 ~19 dirt
setblock ~97 ~124 ~20 dirt
setblock ~97 ~124 ~21 dirt
setblock ~97 ~124 ~22 dirt
setblock ~97 ~124 ~23 dirt
setblock ~97 ~124 ~24 dirt
setblock ~97 ~124 ~25 dirt
setblock ~97 ~124 ~26 dirt
setblock ~97 ~124 ~27 dirt
setblock ~97 ~124 ~28 dirt
setblock ~97 ~124 ~29 dirt
setblock ~97 ~124 ~30 dirt
setblock ~97 ~124 ~31 dirt
setblock ~97 ~124 ~32 dirt
setblock ~97 ~124 ~33 dirt
setblock ~97 ~124 ~34 grass_block
setblock ~97 ~124 ~35 grass_block
setblock ~97 ~124 ~36 grass_block
setblock ~97 ~124 ~37 grass_block
setblock ~97 ~124 ~39 short_grass
setblock ~97 ~124 ~43 grass_block
setblock ~97 ~124 ~44 grass_block
setblock ~97 ~124 ~45 grass_block
setblock ~97 ~124 ~46 grass_block
setblock ~97 ~124 ~47 dirt
setblock ~97 ~124 ~48 dirt
setblock ~97 ~124 ~49 dirt
setblock ~97 ~124 ~50 dirt
setblock ~97 ~124 ~51 dirt
setblock ~97 ~124 ~52 dirt
setblock ~97 ~124 ~53 dirt
setblock ~97 ~124 ~54 dirt
setblock ~97 ~124 ~55 dirt
setblock ~97 ~124 ~56 dirt
setblock ~97 ~124 ~57 dirt
setblock ~97 ~124 ~58 dirt
setblock ~97 ~124 ~59 dirt
setblock ~97 ~124 ~60 dirt
setblock ~97 ~124 ~61 dirt
setblock ~97 ~124 ~62 dirt
setblock ~97 ~124 ~63 grass_block
setblock ~97 ~124 ~64 grass_block
setblock ~97 ~124 ~65 grass_block
setblock ~97 ~124 ~66 grass_block
setblock ~97 ~124 ~70 fern
setblock ~97 ~124 ~73 short_grass
setblock ~97 ~124 ~76 short_grass
setblock ~97 ~124 ~79 short_grass
setblock ~97 ~124 ~83 grass_block
setblock ~97 ~124 ~84 grass_block
setblock ~97 ~124 ~85 grass_block
setblock ~97 ~124 ~86 grass_block
setblock ~97 ~124 ~87 grass_block
setblock ~97 ~124 ~88 grass_block
setblock ~97 ~124 ~89 grass_block
setblock ~97 ~124 ~90 grass_block
setblock ~97 ~124 ~91 grass_block
setblock ~97 ~124 ~92 grass_block
setblock ~97 ~124 ~93 grass_block
setblock ~97 ~124 ~94 grass_block
setblock ~97 ~124 ~95 grass_block
setblock ~97 ~124 ~96 grass_block
setblock ~97 ~124 ~97 grass_block
setblock ~97 ~124 ~98 grass_block
setblock ~97 ~124 ~99 grass_block
setblock ~97 ~124 ~100 grass_block
setblock ~97 ~124 ~101 grass_block
setblock ~97 ~124 ~102 grass_block
setblock ~97 ~124 ~103 grass_block
setblock ~97 ~124 ~104 grass_block
setblock ~97 ~124 ~105 dirt
setblock ~97 ~124 ~106 dirt
setblock ~97 ~124 ~107 dirt
setblock ~97 ~124 ~108 dirt
setblock ~97 ~124 ~109 dirt
setblock ~97 ~124 ~110 dirt
setblock ~97 ~124 ~111 dirt
setblock ~97 ~124 ~112 dirt
setblock ~97 ~124 ~113 grass_block
setblock ~97 ~124 ~114 grass_block
setblock ~97 ~124 ~115 grass_block
setblock ~97 ~124 ~116 grass_block
setblock ~97 ~124 ~117 grass_block
setblock ~97 ~124 ~128 short_grass
setblock ~97 ~124 ~130 short_grass
setblock ~97 ~124 ~132 grass_block
setblock ~97 ~124 ~133 grass_block
setblock ~97 ~124 ~134 dirt
setblock ~97 ~124 ~135 dirt
setblock ~97 ~124 ~136 dirt
setblock ~97 ~124 ~137 dirt
setblock ~97 ~124 ~138 dirt
setblock ~97 ~124 ~139 dirt
setblock ~97 ~124 ~140 dirt
setblock ~97 ~124 ~141 dirt
setblock ~97 ~124 ~142 dirt
setblock ~97 ~124 ~143 dirt
setblock ~97 ~124 ~144 dirt
setblock ~97 ~124 ~145 dirt
setblock ~97 ~124 ~146 dirt
setblock ~97 ~124 ~147 dirt
setblock ~97 ~124 ~148 dirt
setblock ~97 ~124 ~149 dirt
setblock ~97 ~124 ~150 dirt
setblock ~97 ~124 ~151 dirt
setblock ~97 ~124 ~152 dirt
setblock ~97 ~124 ~153 dirt
setblock ~97 ~124 ~154 dirt
setblock ~97 ~124 ~155 dirt
setblock ~97 ~124 ~156 dirt
setblock ~97 ~124 ~157 dirt
setblock ~97 ~124 ~158 dirt
setblock ~97 ~124 ~159 dirt
setblock ~97 ~124 ~160 dirt
setblock ~97 ~124 ~161 dirt
setblock ~97 ~124 ~162 dirt
setblock ~97 ~124 ~163 grass_block
setblock ~97 ~124 ~164 grass_block
setblock ~97 ~124 ~165 grass_block
setblock ~97 ~124 ~174 short_grass
setblock ~97 ~124 ~175 grass_block
setblock ~97 ~124 ~176 grass_block
setblock ~97 ~124 ~177 grass_block
setblock ~97 ~124 ~178 grass_block
setblock ~97 ~124 ~179 dirt
setblock ~97 ~124 ~180 dirt
setblock ~97 ~124 ~181 dirt
setblock ~97 ~124 ~182 dirt
setblock ~97 ~124 ~183 dirt
setblock ~97 ~124 ~184 dirt
setblock ~97 ~124 ~185 dirt
setblock ~97 ~124 ~186 dirt
setblock ~97 ~124 ~187 dirt
setblock ~97 ~124 ~188 dirt
setblock ~97 ~124 ~189 dirt
setblock ~97 ~124 ~190 dirt
setblock ~97 ~124 ~191 dirt
setblock ~97 ~124 ~192 dirt
setblock ~97 ~124 ~193 dirt
setblock ~97 ~124 ~194 dirt
setblock ~97 ~124 ~195 grass_block
setblock ~97 ~124 ~196 grass_block
setblock ~97 ~124 ~197 grass_block
setblock ~97 ~124 ~198 grass_block
setblock ~97 ~124 ~199 grass_block
setblock ~97 ~125 ~0 grass_block
setblock ~97 ~125 ~1 grass_block
setblock ~97 ~125 ~2 grass_block
setblock ~97 ~125 ~3 grass_block
setblock ~97 ~125 ~4 grass_block
setblock ~97 ~125 ~5 grass_block
setblock ~97 ~125 ~6 grass_block
setblock ~97 ~125 ~7 grass_block
setblock ~97 ~125 ~8 dirt
setblock ~97 ~125 ~9 dirt
setblock ~97 ~125 ~10 dirt
setblock ~97 ~125 ~11 dirt
setblock ~97 ~125 ~12 dirt
setblock ~97 ~125 ~13 dirt
setblock ~97 ~125 ~14 grass_block
setblock ~97 ~125 ~15 grass_block
setblock ~97 ~125 ~16 grass_block
setblock ~97 ~125 ~17 grass_block
setblock ~97 ~125 ~18 grass_block
setblock ~97 ~125 ~19 grass_block
setblock ~97 ~125 ~20 grass_block
setblock ~97 ~125 ~21 grass_block
setblock ~97 ~125 ~22 grass_block
setblock ~97 ~125 ~23 grass_block
setblock ~97 ~125 ~24 grass_block
setblock ~97 ~125 ~25 grass_block
setblock ~97 ~125 ~26 dirt
setblock ~97 ~125 ~27 dirt
setblock ~97 ~125 ~28 dirt
setblock ~97 ~125 ~29 dirt
setblock ~97 ~125 ~30 dirt
setblock ~97 ~125 ~31 dirt
setblock ~97 ~125 ~32 grass_block
setblock ~97 ~125 ~33 grass_block
setblock ~97 ~125 ~36 short_grass
setblock ~97 ~125 ~45 short_grass
setblock ~97 ~125 ~46 fern
setblock ~97 ~125 ~47 grass_block
setblock ~97 ~125 ~48 grass_block
setblock ~97 ~125 ~49 grass_block
setblock ~97 ~125 ~50 dirt
setblock ~97 ~125 ~51 dirt
setblock ~97 ~125 ~52 dirt
setblock ~97 ~125 ~53 dirt
setblock ~97 ~125 ~54 grass_block
setblock ~97 ~125 ~55 grass_block
setblock ~97 ~125 ~56 grass_block
setblock ~97 ~125 ~57 grass_block
setblock ~97 ~125 ~58 grass_block
setblock ~97 ~125 ~59 grass_block
setblock ~97 ~125 ~60 grass_block
setblock ~97 ~125 ~61 grass_block
setblock ~97 ~125 ~62 grass_block
setblock ~97 ~125 ~66 short_grass
setblock ~97 ~125 ~86 short_grass
setblock ~97 ~125 ~89 short_grass
setblock ~97 ~125 ~94 short_grass
setblock ~97 ~125 ~95 short_grass
setblock ~97 ~125 ~98 short_grass
setblock ~97 ~125 ~99 short_grass
setblock ~97 ~125 ~105 grass_block
setblock ~97 ~125 ~106 grass_block
setblock ~97 ~125 ~107 grass_block
setblock ~97 ~125 ~108 grass_block
setblock ~97 ~125 ~109 grass_block
setblock ~97 ~125 ~110 grass_block
setblock ~97 ~125 ~111 grass_block
setblock ~97 ~125 ~112 grass_block
setblock ~97 ~125 ~114 short_grass
setblock ~97 ~125 ~133 poppy
setblock ~97 ~125 ~134 grass_block
setblock ~97 ~125 ~135 grass_block
setblock ~97 ~125 ~136 dirt
setblock ~97 ~125 ~137 dirt
setblock ~97 ~125 ~138 dirt
setblock ~97 ~125 ~139 dirt
setblock ~97 ~125 ~140 dirt
setblock ~97 ~125 ~141 dirt
setblock ~97 ~125 ~142 dirt
setblock ~97 ~125 ~143 dirt
setblock ~97 ~125 ~144 dirt
setblock ~97 ~125 ~145 dirt
setblock ~97 ~125 ~146 dirt
setblock ~97 ~125 ~147 dirt
setblock ~97 ~125 ~148 dirt
setblock ~97 ~125 ~149 dirt
setblock ~97 ~125 ~150 dirt
setblock ~97 ~125 ~151 dirt
setblock ~97 ~125 ~152 dirt
setblock ~97 ~125 ~153 dirt
setblock ~97 ~125 ~154 dirt
setblock ~97 ~125 ~155 dirt
setblock ~97 ~125 ~156 dirt
setblock ~97 ~125 ~157 dirt
setblock ~97 ~125 ~158 grass_block
setblock ~97 ~125 ~159 grass_block
setblock ~97 ~125 ~160 grass_block
setblock ~97 ~125 ~161 grass_block
setblock ~97 ~125 ~162 grass_block
setblock ~97 ~125 ~163 short_grass
setblock ~97 ~125 ~176 short_grass
setblock ~97 ~125 ~178 short_grass
setblock ~97 ~125 ~179 grass_block
setblock ~97 ~125 ~180 grass_block
setblock ~97 ~125 ~181 grass_block
setblock ~97 ~125 ~182 grass_block
setblock ~97 ~125 ~183 grass_block
setblock ~97 ~125 ~184 grass_block
setblock ~97 ~125 ~185 grass_block
setblock ~97 ~125 ~186 grass_block
setblock ~97 ~125 ~187 grass_block
setblock ~97 ~125 ~188 grass_block
setblock ~97 ~125 ~189 grass_block
setblock ~97 ~125 ~190 grass_block
setblock ~97 ~125 ~191 grass_block
setblock ~97 ~125 ~192 grass_block
setblock ~97 ~125 ~193 grass_block
setblock ~97 ~125 ~194 grass_block
setblock ~97 ~125 ~195 short_grass
setblock ~97 ~125 ~197 short_grass
setblock ~97 ~125 ~199 poppy
setblock ~97 ~126 ~6 short_grass
setblock ~97 ~126 ~7 poppy
setblock ~97 ~126 ~8 grass_block
setblock ~97 ~126 ~9 grass_block
setblock ~97 ~126 ~10 grass_block
setblock ~97 ~126 ~11 grass_block
setblock ~97 ~126 ~12 grass_block
setblock ~97 ~126 ~13 grass_block
setblock ~97 ~126 ~15 short_grass
setblock ~97 ~126 ~16 short_grass
setblock ~97 ~126 ~17 short_grass
setblock ~97 ~126 ~18 short_grass
setblock ~97 ~126 ~26 grass_block
setblock ~97 ~126 ~27 grass_block
setblock ~97 ~126 ~28 grass_block
setblock ~97 ~126 ~29 grass_block
setblock ~97 ~126 ~30 grass_block
setblock ~97 ~126 ~31 grass_block
setblock ~97 ~126 ~50 grass_block
setblock ~97 ~126 ~51 grass_block
setblock ~97 ~126 ~52 grass_block
setblock ~97 ~126 ~53 grass_block
setblock ~97 ~126 ~54 short_grass
setblock ~97 ~126 ~55 short_grass
setblock ~97 ~126 ~60 short_grass
setblock ~97 ~126 ~61 short_grass
setblock ~97 ~126 ~110 short_grass
setblock ~97 ~126 ~135 short_grass
setblock ~97 ~126 ~136 grass_block
setblock ~97 ~126 ~137 grass_block
setblock ~97 ~126 ~138 dirt
setblock ~97 ~126 ~139 dirt
setblock ~97 ~126 ~140 dirt
setblock ~97 ~126 ~141 dirt
setblock ~97 ~126 ~142 dirt
setblock ~97 ~126 ~143 dirt
setblock ~97 ~126 ~144 dirt
setblock ~97 ~126 ~145 dirt
setblock ~97 ~126 ~146 dirt
setblock ~97 ~126 ~147 dirt
setblock ~97 ~126 ~148 dirt
setblock ~97 ~126 ~149 dirt
setblock ~97 ~126 ~150 dirt
setblock ~97 ~126 ~151 dirt
setblock ~97 ~126 ~152 dirt
setblock ~97 ~126 ~153 grass_block
setblock ~97 ~126 ~154 grass_block
setblock ~97 ~126 ~155 grass_block
setblock ~97 ~126 ~156 grass_block
setblock ~97 ~126 ~157 grass_block
setblock ~97 ~126 ~158 poppy
setblock ~97 ~126 ~159 short_grass
setblock ~97 ~126 ~180 short_grass
setblock ~97 ~126 ~185 short_grass
setblock ~97 ~126 ~186 poppy
setblock ~97 ~126 ~188 short_grass
setblock ~97 ~127 ~11 short_grass
setblock ~97 ~127 ~12 short_grass
setblock ~97 ~127 ~30 short_grass
setblock ~97 ~127 ~52 short_grass
setblock ~97 ~127 ~138 grass_block
setblock ~97 ~127 ~139 grass_block
setblock ~97 ~127 ~140 dirt
setblock ~97 ~127 ~141 dirt
setblock ~97 ~127 ~142 dirt
setblock ~97 ~127 ~143 dirt
setblock ~97 ~127 ~144 dirt
setblock ~97 ~127 ~145 dirt
setblock ~97 ~127 ~146 grass_block
setblock ~97 ~127 ~147 grass_block
setblock ~97 ~127 ~148 grass_block
setblock ~97 ~127 ~149 grass_block
setblock ~97 ~127 ~150 grass_block
setblock ~97 ~127 ~151 grass_block
setblock ~97 ~127 ~152 grass_block
setblock ~97 ~127 ~155 short_grass
setblock ~97 ~128 ~140 grass_block
setblock ~97 ~128 ~141 grass_block
setblock ~97 ~128 ~142 grass_block
setblock ~97 ~128 ~143 grass_block
setblock ~97 ~128 ~144 grass_block
setblock ~97 ~128 ~145 grass_block
setblock ~97 ~129 ~141 short_grass
setblock ~97 ~129 ~142 poppy
setblock ~97 ~129 ~143 poppy
setblock ~97 ~129 ~144 short_grass
setblock ~98 ~122 ~0 dirt
setblock ~98 ~122 ~1 dirt
setblock ~98 ~122 ~2 dirt
setblock ~98 ~122 ~3 dirt
setblock ~98 ~122 ~4 dirt
setblock ~98 ~122 ~5 dirt
setblock ~98 ~122 ~6 dirt
setblock ~98 ~122 ~7 dirt
setblock ~98 ~122 ~8 dirt
setblock ~98 ~122 ~9 dirt
setblock ~98 ~122 ~10 dirt
setblock ~98 ~122 ~11 dirt
setblock ~98 ~122 ~12 dirt
setblock ~98 ~122 ~13 dirt
setblock ~98 ~122 ~14 dirt
setblock ~98 ~122 ~15 dirt
setblock ~98 ~122 ~16 dirt
setblock ~98 ~122 ~17 dirt
setblock ~98 ~122 ~18 dirt
setblock ~98 ~122 ~19 dirt
setblock ~98 ~122 ~20 dirt
setblock ~98 ~122 ~21 dirt
setblock ~98 ~122 ~22 dirt
setblock ~98 ~122 ~23 dirt
setblock ~98 ~122 ~24 dirt
setblock ~98 ~122 ~25 dirt
setblock ~98 ~122 ~26 dirt
setblock ~98 ~122 ~27 dirt
setblock ~98 ~122 ~28 dirt
setblock ~98 ~122 ~29 dirt
setblock ~98 ~122 ~30 dirt
setblock ~98 ~122 ~31 dirt
setblock ~98 ~122 ~32 dirt
setblock ~98 ~122 ~33 dirt
setblock ~98 ~122 ~34 dirt
setblock ~98 ~122 ~35 dirt
setblock ~98 ~122 ~36 dirt
setblock ~98 ~122 ~37 dirt
setblock ~98 ~122 ~38 dirt
setblock ~98 ~122 ~39 dirt
setblock ~98 ~122 ~40 dirt
setblock ~98 ~122 ~41 dirt
setblock ~98 ~122 ~42 dirt
setblock ~98 ~122 ~43 dirt
setblock ~98 ~122 ~44 dirt
setblock ~98 ~122 ~45 dirt
setblock ~98 ~122 ~46 dirt
setblock ~98 ~122 ~47 dirt
setblock ~98 ~122 ~48 dirt
setblock ~98 ~122 ~49 dirt
setblock ~98 ~122 ~50 dirt
setblock ~98 ~122 ~51 dirt
setblock ~98 ~122 ~52 dirt
setblock ~98 ~122 ~53 dirt
setblock ~98 ~122 ~54 dirt
setblock ~98 ~122 ~55 dirt
setblock ~98 ~122 ~56 dirt
setblock ~98 ~122 ~57 dirt
setblock ~98 ~122 ~58 dirt
setblock ~98 ~122 ~59 dirt
setblock ~98 ~122 ~60 dirt
setblock ~98 ~122 ~61 dirt
setblock ~98 ~122 ~62 dirt
setblock ~98 ~122 ~63 dirt
setblock ~98 ~122 ~64 dirt
setblock ~98 ~122 ~65 dirt
setblock ~98 ~122 ~66 dirt
setblock ~98 ~122 ~67 dirt
setblock ~98 ~122 ~68 dirt
setblock ~98 ~122 ~69 dirt
setblock ~98 ~122 ~70 dirt
setblock ~98 ~122 ~71 dirt
setblock ~98 ~122 ~72 dirt
setblock ~98 ~122 ~73 dirt
setblock ~98 ~122 ~74 dirt
setblock ~98 ~122 ~75 dirt
setblock ~98 ~122 ~76 dirt
setblock ~98 ~122 ~77 dirt
setblock ~98 ~122 ~78 dirt
setblock ~98 ~122 ~79 dirt
setblock ~98 ~122 ~80 dirt
setblock ~98 ~122 ~81 dirt
setblock ~98 ~122 ~82 dirt
setblock ~98 ~122 ~83 dirt
setblock ~98 ~122 ~84 dirt
setblock ~98 ~122 ~85 dirt
setblock ~98 ~122 ~86 dirt
setblock ~98 ~122 ~87 dirt
setblock ~98 ~122 ~88 dirt
setblock ~98 ~122 ~89 dirt
setblock ~98 ~122 ~90 dirt
setblock ~98 ~122 ~91 dirt
setblock ~98 ~122 ~92 dirt
setblock ~98 ~122 ~93 dirt
setblock ~98 ~122 ~94 dirt
setblock ~98 ~122 ~95 dirt
setblock ~98 ~122 ~96 dirt
setblock ~98 ~122 ~97 dirt
setblock ~98 ~122 ~98 dirt
setblock ~98 ~122 ~99 dirt
setblock ~98 ~122 ~100 dirt
setblock ~98 ~122 ~101 dirt
setblock ~98 ~122 ~102 dirt
setblock ~98 ~122 ~103 dirt
setblock ~98 ~122 ~104 dirt
setblock ~98 ~122 ~105 dirt
setblock ~98 ~122 ~106 dirt
setblock ~98 ~122 ~107 dirt
setblock ~98 ~122 ~108 dirt
setblock ~98 ~122 ~109 dirt
setblock ~98 ~122 ~110 dirt
setblock ~98 ~122 ~111 dirt
setblock ~98 ~122 ~112 dirt
setblock ~98 ~122 ~113 dirt
setblock ~98 ~122 ~114 dirt
setblock ~98 ~122 ~115 dirt
setblock ~98 ~122 ~116 dirt
setblock ~98 ~122 ~117 dirt
setblock ~98 ~122 ~118 dirt
setblock ~98 ~122 ~119 dirt
setblock ~98 ~122 ~120 dirt
setblock ~98 ~122 ~121 dirt
setblock ~98 ~122 ~122 dirt
setblock ~98 ~122 ~123 dirt
setblock ~98 ~122 ~124 dirt
setblock ~98 ~122 ~125 dirt
setblock ~98 ~122 ~126 dirt
setblock ~98 ~122 ~127 grass_block
setblock ~98 ~122 ~128 grass_block
setblock ~98 ~122 ~129 grass_block
setblock ~98 ~122 ~130 grass_block
setblock ~98 ~122 ~131 dirt
setblock ~98 ~122 ~132 dirt
setblock ~98 ~122 ~133 dirt
setblock ~98 ~122 ~134 dirt
setblock ~98 ~122 ~135 dirt
setblock ~98 ~122 ~136 dirt
setblock ~98 ~122 ~137 dirt
setblock ~98 ~122 ~138 dirt
setblock ~98 ~122 ~139 dirt
setblock ~98 ~122 ~140 dirt
setblock ~98 ~122 ~141 dirt
setblock ~98 ~122 ~142 dirt
setblock ~98 ~122 ~143 dirt
setblock ~98 ~122 ~144 dirt
setblock ~98 ~122 ~145 dirt
setblock ~98 ~122 ~146 dirt
setblock ~98 ~122 ~147 dirt
setblock ~98 ~122 ~148 dirt
setblock ~98 ~122 ~149 dirt
setblock ~98 ~122 ~150 dirt
setblock ~98 ~122 ~151 dirt
setblock ~98 ~122 ~152 dirt
setblock ~98 ~122 ~153 dirt
setblock ~98 ~122 ~154 dirt
setblock ~98 ~122 ~155 dirt
setblock ~98 ~122 ~156 dirt
setblock ~98 ~122 ~157 dirt
setblock ~98 ~122 ~158 dirt
setblock ~98 ~122 ~159 dirt
setblock ~98 ~122 ~160 dirt
setblock ~98 ~122 ~161 dirt
setblock ~98 ~122 ~162 dirt
setblock ~98 ~122 ~163 dirt
setblock ~98 ~122 ~164 dirt
setblock ~98 ~122 ~165 dirt
setblock ~98 ~122 ~166 dirt
setblock ~98 ~122 ~167 dirt
setblock ~98 ~122 ~168 grass_block
setblock ~98 ~122 ~169 grass_block
setblock ~98 ~122 ~170 grass_block
setblock ~98 ~122 ~171 grass_block
setblock ~98 ~122 ~172 dirt
setblock ~98 ~122 ~173 dirt
setblock ~98 ~122 ~174 dirt
setblock ~98 ~122 ~175 dirt
setblock ~98 ~122 ~176 dirt
setblock ~98 ~122 ~177 dirt
setblock ~98 ~122 ~178 dirt
setblock ~98 ~122 ~179 dirt
setblock ~98 ~122 ~180 dirt
setblock ~98 ~122 ~181 dirt
setblock ~98 ~122 ~182 dirt
setblock ~98 ~122 ~183 dirt
setblock ~98 ~122 ~184 dirt
setblock ~98 ~122 ~185 dirt
setblock ~98 ~122 ~186 dirt
setblock ~98 ~122 ~187 dirt
setblock ~98 ~122 ~188 dirt
setblock ~98 ~122 ~189 dirt
setblock ~98 ~122 ~190 dirt
setblock ~98 ~122 ~191 dirt
setblock ~98 ~122 ~192 dirt
setblock ~98 ~122 ~193 dirt
setblock ~98 ~122 ~194 dirt
setblock ~98 ~122 ~195 dirt
setblock ~98 ~122 ~196 dirt
setblock ~98 ~122 ~197 dirt
setblock ~98 ~122 ~198 dirt
setblock ~98 ~122 ~199 dirt
setblock ~98 ~123 ~0 dirt
setblock ~98 ~123 ~1 dirt
setblock ~98 ~123 ~2 dirt
setblock ~98 ~123 ~3 dirt
setblock ~98 ~123 ~4 dirt
setblock ~98 ~123 ~5 dirt
setblock ~98 ~123 ~6 dirt
setblock ~98 ~123 ~7 dirt
setblock ~98 ~123 ~8 dirt
setblock ~98 ~123 ~9 dirt
setblock ~98 ~123 ~10 dirt
setblock ~98 ~123 ~11 dirt
setblock ~98 ~123 ~12 dirt
setblock ~98 ~123 ~13 dirt
setblock ~98 ~123 ~14 dirt
setblock ~98 ~123 ~15 dirt
setblock ~98 ~123 ~16 dirt
setblock ~98 ~123 ~17 dirt
setblock ~98 ~123 ~18 dirt
setblock ~98 ~123 ~19 dirt
setblock ~98 ~123 ~20 dirt
setblock ~98 ~123 ~21 dirt
setblock ~98 ~123 ~22 dirt
setblock ~98 ~123 ~23 dirt
setblock ~98 ~123 ~24 dirt
setblock ~98 ~123 ~25 dirt
setblock ~98 ~123 ~26 dirt
setblock ~98 ~123 ~27 dirt
setblock ~98 ~123 ~28 dirt
setblock ~98 ~123 ~29 dirt
setblock ~98 ~123 ~30 dirt
setblock ~98 ~123 ~31 dirt
setblock ~98 ~123 ~32 dirt
setblock ~98 ~123 ~33 dirt
setblock ~98 ~123 ~34 dirt
setblock ~98 ~123 ~35 dirt
setblock ~98 ~123 ~36 dirt
setblock ~98 ~123 ~37 dirt
setblock ~98 ~123 ~38 grass_block
setblock ~98 ~123 ~39 grass_block
setblock ~98 ~123 ~40 grass_block
setblock ~98 ~123 ~41 grass_block
setblock ~98 ~123 ~42 grass_block
setblock ~98 ~123 ~43 dirt
setblock ~98 ~123 ~44 dirt
setblock ~98 ~123 ~45 dirt
setblock ~98 ~123 ~46 dirt
setblock ~98 ~123 ~47 dirt
setblock ~98 ~123 ~48 dirt
setblock ~98 ~123 ~49 dirt
setblock ~98 ~123 ~50 dirt
setblock ~98 ~123 ~51 dirt
setblock ~98 ~123 ~52 dirt
setblock ~98 ~123 ~53 dirt
setblock ~98 ~123 ~54 dirt
setblock ~98 ~123 ~55 dirt
setblock ~98 ~123 ~56 dirt
setblock ~98 ~123 ~57 dirt
setblock ~98 ~123 ~58 dirt
setblock ~98 ~123 ~59 dirt
setblock ~98 ~123 ~60 dirt
setblock ~98 ~123 ~61 dirt
setblock ~98 ~123 ~62 dirt
setblock ~98 ~123 ~63 dirt
setblock ~98 ~123 ~64 dirt
setblock ~98 ~123 ~65 dirt
setblock ~98 ~123 ~66 dirt
setblock ~98 ~123 ~67 grass_block
setblock ~98 ~123 ~68 grass_block
setblock ~98 ~123 ~69 grass_block
setblock ~98 ~123 ~70 grass_block
setblock ~98 ~123 ~71 grass_block
setblock ~98 ~123 ~72 grass_block
setblock ~98 ~123 ~73 grass_block
setblock ~98 ~123 ~74 grass_block
setblock ~98 ~123 ~75 grass_block
setblock ~98 ~123 ~76 grass_block
setblock ~98 ~123 ~77 grass_block
setblock ~98 ~123 ~78 grass_block
setblock ~98 ~123 ~79 grass_block
setblock ~98 ~123 ~80 grass_block
setblock ~98 ~123 ~81 grass_block
setblock ~98 ~123 ~82 grass_block
setblock ~98 ~123 ~83 grass_block
setblock ~98 ~123 ~84 dirt
setblock ~98 ~123 ~85 dirt
setblock ~98 ~123 ~86 dirt
setblock ~98 ~123 ~87 dirt
setblock ~98 ~123 ~88 dirt
setblock ~98 ~123 ~89 dirt
setblock ~98 ~123 ~90 dirt
setblock ~98 ~123 ~91 dirt
setblock ~98 ~123 ~92 dirt
setblock ~98 ~123 ~93 dirt
setblock ~98 ~123 ~94 dirt
setblock ~98 ~123 ~95 dirt
setblock ~98 ~123 ~96 dirt
setblock ~98 ~123 ~97 dirt
setblock ~98 ~123 ~98 dirt
setblock ~98 ~123 ~99 dirt
setblock ~98 ~123 ~100 dirt
setblock ~98 ~123 ~101 dirt
setblock ~98 ~123 ~102 dirt
setblock ~98 ~123 ~103 dirt
setblock ~98 ~123 ~104 dirt
setblock ~98 ~123 ~105 dirt
setblock ~98 ~123 ~106 dirt
setblock ~98 ~123 ~107 dirt
setblock ~98 ~123 ~108 dirt
setblock ~98 ~123 ~109 dirt
setblock ~98 ~123 ~110 dirt
setblock ~98 ~123 ~111 dirt
setblock ~98 ~123 ~112 dirt
setblock ~98 ~123 ~113 dirt
setblock ~98 ~123 ~114 dirt
setblock ~98 ~123 ~115 dirt
setblock ~98 ~123 ~116 dirt
setblock ~98 ~123 ~117 grass_block
setblock ~98 ~123 ~118 grass_block
setblock ~98 ~123 ~119 grass_block
setblock ~98 ~123 ~120 grass_block
setblock ~98 ~123 ~121 grass_block
setblock ~98 ~123 ~122 grass_block
setblock ~98 ~123 ~123 grass_block
setblock ~98 ~123 ~124 grass_block
setblock ~98 ~123 ~125 grass_block
setblock ~98 ~123 ~126 grass_block
setblock ~98 ~123 ~127 short_grass
setblock ~98 ~123 ~131 grass_block
setblock ~98 ~123 ~132 grass_block
setblock ~98 ~123 ~133 dirt
setblock ~98 ~123 ~134 dirt
setblock ~98 ~123 ~135 dirt
setblock ~98 ~123 ~136 dirt
setblock ~98 ~123 ~137 dirt
setblock ~98 ~123 ~138 dirt
setblock ~98 ~123 ~139 dirt
setblock ~98 ~123 ~140 dirt
setblock ~98 ~123 ~141 dirt
setblock ~98 ~123 ~142 dirt
setblock ~98 ~123 ~143 dirt
setblock ~98 ~123 ~144 dirt
setblock ~98 ~123 ~145 dirt
setblock ~98 ~123 ~146 dirt
setblock ~98 ~123 ~147 dirt
setblock ~98 ~123 ~148 dirt
setblock ~98 ~123 ~149 dirt
setblock ~98 ~123 ~150 dirt
setblock ~98 ~123 ~151 dirt
setblock ~98 ~123 ~152 dirt
setblock ~98 ~123 ~153 dirt
setblock ~98 ~123 ~154 dirt
setblock ~98 ~123 ~155 dirt
setblock ~98 ~123 ~156 dirt
setblock ~98 ~123 ~157 dirt
setblock ~98 ~123 ~158 dirt
setblock ~98 ~123 ~159 dirt
setblock ~98 ~123 ~160 dirt
setblock ~98 ~123 ~161 dirt
setblock ~98 ~123 ~162 dirt
setblock ~98 ~123 ~163 dirt
setblock ~98 ~123 ~164 dirt
setblock ~98 ~123 ~165 grass_block
setblock ~98 ~123 ~166 grass_block
setblock ~98 ~123 ~167 grass_block
setblock ~98 ~123 ~168 short_grass
setblock ~98 ~123 ~171 short_grass
setblock ~98 ~123 ~172 grass_block
setblock ~98 ~123 ~173 grass_block
setblock ~98 ~123 ~174 grass_block
setblock ~98 ~123 ~175 dirt
setblock ~98 ~123 ~176 dirt
setblock ~98 ~123 ~177 dirt
setblock ~98 ~123 ~178 dirt
setblock ~98 ~123 ~179 dirt
setblock ~98 ~123 ~180 dirt
setblock ~98 ~123 ~181 dirt
setblock ~98 ~123 ~182 dirt
setblock ~98 ~123 ~183 dirt
setblock ~98 ~123 ~184 dirt
setblock ~98 ~123 ~185 dirt
setblock ~98 ~123 ~186 dirt
setblock ~98 ~123 ~187 dirt
setblock ~98 ~123 ~188 dirt
setblock ~98 ~123 ~189 dirt
setblock ~98 ~123 ~190 dirt
setblock ~98 ~123 ~191 dirt
setblock ~98 ~123 ~192 dirt
setblock ~98 ~123 ~193 dirt
setblock ~98 ~123 ~194 dirt
setblock ~98 ~123 ~195 dirt
setblock ~98 ~123 ~196 dirt
setblock ~98 ~123 ~197 dirt
setblock ~98 ~123 ~198 dirt
setblock ~98 ~123 ~199 dirt
setblock ~98 ~124 ~0 dirt
setblock ~98 ~124 ~1 dirt
setblock ~98 ~124 ~2 dirt
setblock ~98 ~124 ~3 dirt
setblock ~98 ~124 ~4 dirt
setblock ~98 ~124 ~5 dirt
setblock ~98 ~124 ~6 dirt
setblock ~98 ~124 ~7 dirt
setblock ~98 ~124 ~8 dirt
setblock ~98 ~124 ~9 dirt
setblock ~98 ~124 ~10 dirt
setblock ~98 ~124 ~11 dirt
setblock ~98 ~124 ~12 dirt
setblock ~98 ~124 ~13 dirt
setblock ~98 ~124 ~14 dirt
setblock ~98 ~124 ~15 dirt
setblock ~98 ~124 ~16 dirt
setblock ~98 ~124 ~17 dirt
setblock ~98 ~124 ~18 dirt
setblock ~98 ~124 ~19 grass_block
setblock ~98 ~124 ~20 grass_block
setblock ~98 ~124 ~21 dirt
setblock ~98 ~124 ~22 dirt
setblock ~98 ~124 ~23 dirt
setblock ~98 ~124 ~24 dirt
setblock ~98 ~124 ~25 dirt
setblock ~98 ~124 ~26 dirt
setblock ~98 ~124 ~27 dirt
setblock ~98 ~124 ~28 dirt
setblock ~98 ~124 ~29 dirt
setblock ~98 ~124 ~30 dirt
setblock ~98 ~124 ~31 dirt
setblock ~98 ~124 ~32 dirt
setblock ~98 ~124 ~33 dirt
setblock ~98 ~124 ~34 dirt
setblock ~98 ~124 ~35 grass_block
setblock ~98 ~124 ~36 grass_block
setblock ~98 ~124 ~37 grass_block
setblock ~98 ~124 ~39 fern
setblock ~98 ~124 ~41 short_grass
setblock ~98 ~124 ~43 grass_block
setblock ~98 ~124 ~44 grass_block
setblock ~98 ~124 ~45 grass_block
setblock ~98 ~124 ~46 grass_block
setblock ~98 ~124 ~47 dirt
setblock ~98 ~124 ~48 dirt
setblock ~98 ~124 ~49 dirt
setblock ~98 ~124 ~50 dirt
setblock ~98 ~124 ~51 dirt
setblock ~98 ~124 ~52 dirt
setblock ~98 ~124 ~53 dirt
setblock ~98 ~124 ~54 dirt
setblock ~98 ~124 ~55 dirt
setblock ~98 ~124 ~56 dirt
setblock ~98 ~124 ~57 dirt
setblock ~98 ~124 ~58 dirt
setblock ~98 ~124 ~59 dirt
setblock ~98 ~124 ~60 dirt
setblock ~98 ~124 ~61 dirt
setblock ~98 ~124 ~62 dirt
setblock ~98 ~124 ~63 grass_block
setblock ~98 ~124 ~64 grass_block
setblock ~98 ~124 ~65 grass_block
setblock ~98 ~124 ~66 grass_block
setblock ~98 ~124 ~67 short_grass
setblock ~98 ~124 ~74 short_grass
setblock ~98 ~124 ~75 short_grass
setblock ~98 ~124 ~82 short_grass
setblock ~98 ~124 ~83 short_grass
setblock ~98 ~124 ~84 grass_block
setblock ~98 ~124 ~85 grass_block
setblock ~98 ~124 ~86 grass_block
setblock ~98 ~124 ~87 grass_block
setblock ~98 ~124 ~88 grass_block
setblock ~98 ~124 ~89 grass_block
setblock ~98 ~124 ~90 grass_block
setblock ~98 ~124 ~91 grass_block
setblock ~98 ~124 ~92 grass_block
setblock ~98 ~124 ~93 grass_block
setblock ~98 ~124 ~94 grass_block
setblock ~98 ~124 ~95 grass_block
setblock ~98 ~124 ~96 grass_block
setblock ~98 ~124 ~97 grass_block
setblock ~98 ~124 ~98 grass_block
setblock ~98 ~124 ~99 grass_block
setblock ~98 ~124 ~100 grass_block
setblock ~98 ~124 ~101 grass_block
setblock ~98 ~124 ~102 grass_block
setblock ~98 ~124 ~103 grass_block
setblock ~98 ~124 ~104 grass_block
setblock ~98 ~124 ~105 grass_block
setblock ~98 ~124 ~106 dirt
setblock ~98 ~124 ~107 dirt
setblock ~98 ~124 ~108 dirt
setblock ~98 ~124 ~109 dirt
setblock ~98 ~124 ~110 dirt
setblock ~98 ~124 ~111 dirt
setblock ~98 ~124 ~112 dirt
setblock ~98 ~124 ~113 grass_block
setblock ~98 ~124 ~114 grass_block
setblock ~98 ~124 ~115 grass_block
setblock ~98 ~124 ~116 grass_block
setblock ~98 ~124 ~118 short_grass
setblock ~98 ~124 ~121 short_grass
setblock ~98 ~124 ~125 short_grass
setblock ~98 ~124 ~126 fern
setblock ~98 ~124 ~132 short_grass
setblock ~98 ~124 ~133 grass_block
setblock ~98 ~124 ~134 dirt
setblock ~98 ~124 ~135 dirt
setblock ~98 ~124 ~136 dirt
setblock ~98 ~124 ~137 dirt
setblock ~98 ~124 ~138 dirt
setblock ~98 ~124 ~139 dirt
setblock ~98 ~124 ~140 dirt
setblock ~98 ~124 ~141 dirt
setblock ~98 ~124 ~142 dirt
setblock ~98 ~124 ~143 dirt
setblock ~98 ~124 ~144 dirt
setblock ~98 ~124 ~145 dirt
setblock ~98 ~124 ~146 dirt
setblock ~98 ~124 ~147 dirt
setblock ~98 ~124 ~148 dirt
setblock ~98 ~124 ~149 dirt
setblock ~98 ~124 ~150 dirt
setblock ~98 ~124 ~151 dirt
setblock ~98 ~124 ~152 dirt
setblock ~98 ~124 ~153 dirt
setblock ~98 ~124 ~154 dirt
setblock ~98 ~124 ~155 dirt
setblock ~98 ~124 ~156 dirt
setblock ~98 ~124 ~157 dirt
setblock ~98 ~124 ~158 dirt
setblock ~98 ~124 ~159 dirt
setblock ~98 ~124 ~160 dirt
setblock ~98 ~124 ~161 grass_block
setblock ~98 ~124 ~162 grass_block
setblock ~98 ~124 ~163 grass_block
setblock ~98 ~124 ~164 grass_block
setblock ~98 ~124 ~165 fern
setblock ~98 ~124 ~166 short_grass
setblock ~98 ~124 ~172 short_grass
setblock ~98 ~124 ~173 short_grass
setblock ~98 ~124 ~174 poppy
setblock ~98 ~124 ~175 grass_block
setblock ~98 ~124 ~176 grass_block
setblock ~98 ~124 ~177 grass_block
setblock ~98 ~124 ~178 dirt
setblock ~98 ~124 ~179 dirt
setblock ~98 ~124 ~180 dirt
setblock ~98 ~124 ~181 dirt
setblock ~98 ~124 ~182 dirt
setblock ~98 ~124 ~183 dirt
setblock ~98 ~124 ~184 dirt
setblock ~98 ~124 ~185 dirt
setblock ~98 ~124 ~186 dirt
setblock ~98 ~124 ~187 dirt
setblock ~98 ~124 ~188 dirt
setblock ~98 ~124 ~189 grass_block
setblock ~98 ~124 ~190 grass_block
setblock ~98 ~124 ~191 grass_block
setblock ~98 ~124 ~192 grass_block
setblock ~98 ~124 ~193 grass_block
setblock ~98 ~124 ~194 grass_block
setblock ~98 ~124 ~195 grass_block
setblock ~98 ~124 ~196 grass_block
setblock ~98 ~124 ~197 grass_block
setblock ~98 ~124 ~198 grass_block
setblock ~98 ~124 ~199 grass_block
setblock ~98 ~125 ~0 grass_block
setblock ~98 ~125 ~1 grass_block
setblock ~98 ~125 ~2 grass_block
setblock ~98 ~125 ~3 grass_block
setblock ~98 ~125 ~4 grass_block
setblock ~98 ~125 ~5 grass_block
setblock ~98 ~125 ~6 grass_block
setblock ~98 ~125 ~7 grass_block
setblock ~98 ~125 ~8 grass_block
setblock ~98 ~125 ~9 grass_block
setblock ~98 ~125 ~10 dirt
setblock ~98 ~125 ~11 grass_block
setblock ~98 ~125 ~12 grass_block
setblock ~98 ~125 ~13 grass_block
setblock ~98 ~125 ~14 grass_block
setblock ~98 ~125 ~15 grass_block
setblock ~98 ~125 ~16 grass_block
setblock ~98 ~125 ~17 grass_block
setblock ~98 ~125 ~18 grass_block
setblock ~98 ~125 ~21 grass_block
setblock ~98 ~125 ~22 grass_block
setblock ~98 ~125 ~23 grass_block
setblock ~98 ~125 ~24 grass_block
setblock ~98 ~125 ~25 grass_block
setblock ~98 ~125 ~26 dirt
setblock ~98 ~125 ~27 dirt
setblock ~98 ~125 ~28 dirt
setblock ~98 ~125 ~29 dirt
setblock ~98 ~125 ~30 dirt
setblock ~98 ~125 ~31 dirt
setblock ~98 ~125 ~32 grass_block
setblock ~98 ~125 ~33 grass_block
setblock ~98 ~125 ~34 grass_block
setblock ~98 ~125 ~36 short_grass
setblock ~98 ~125 ~47 grass_block
setblock ~98 ~125 ~48 grass_block
setblock ~98 ~125 ~49 dirt
setblock ~98 ~125 ~50 dirt
setblock ~98 ~125 ~51 dirt
setblock ~98 ~125 ~52 dirt
setblock ~98 ~125 ~53 dirt
setblock ~98 ~125 ~54 dirt
setblock ~98 ~125 ~55 grass_block
setblock ~98 ~125 ~56 grass_block
setblock ~98 ~125 ~57 grass_block
setblock ~98 ~125 ~58 grass_block
setblock ~98 ~125 ~59 grass_block
setblock ~98 ~125 ~60 grass_block
setblock ~98 ~125 ~61 grass_block
setblock ~98 ~125 ~62 grass_block
setblock ~98 ~125 ~88 fern
setblock ~98 ~125 ~90 short_grass
setblock ~98 ~125 ~95 poppy
setblock ~98 ~125 ~98 short_grass
setblock ~98 ~125 ~99 short_grass
setblock ~98 ~125 ~104 short_grass
setblock ~98 ~125 ~105 short_grass
setblock ~98 ~125 ~106 grass_block
setblock ~98 ~125 ~107 grass_block
setblock ~98 ~125 ~108 grass_block
setblock ~98 ~125 ~109 grass_block
setblock ~98 ~125 ~110 grass_block
setblock ~98 ~125 ~111 grass_block
setblock ~98 ~125 ~112 grass_block
setblock ~98 ~125 ~113 short_grass
setblock ~98 ~125 ~134 grass_block
setblock ~98 ~125 ~135 grass_block
setblock ~98 ~125 ~136 dirt
setblock ~98 ~125 ~137 dirt
setblock ~98 ~125 ~138 dirt
setblock ~98 ~125 ~139 dirt
setblock ~98 ~125 ~140 dirt
setblock ~98 ~125 ~141 dirt
setblock ~98 ~125 ~142 dirt
setblock ~98 ~125 ~143 dirt
setblock ~98 ~125 ~144 dirt
setblock ~98 ~125 ~145 dirt
setblock ~98 ~125 ~146 dirt
setblock ~98 ~125 ~147 dirt
setblock ~98 ~125 ~148 dirt
setblock ~98 ~125 ~149 dirt
setblock ~98 ~125 ~150 dirt
setblock ~98 ~125 ~151 dirt
setblock ~98 ~125 ~152 dirt
setblock ~98 ~125 ~153 dirt
setblock ~98 ~125 ~154 dirt
setblock ~98 ~125 ~155 dirt
setblock ~98 ~125 ~156 dirt
setblock ~98 ~125 ~157 grass_block
setblock ~98 ~125 ~158 grass_block
setblock ~98 ~125 ~159 grass_block
setblock ~98 ~125 ~160 grass_block
setblock ~98 ~125 ~177 short_grass
setblock ~98 ~125 ~178 grass_block
setblock ~98 ~125 ~179 grass_block
setblock ~98 ~125 ~180 grass_block
setblock ~98 ~125 ~181 grass_block
setblock ~98 ~125 ~182 grass_block
setblock ~98 ~125 ~183 grass_block
setblock ~98 ~125 ~184 grass_block
setblock ~98 ~125 ~185 grass_block
setblock ~98 ~125 ~186 grass_block
setblock ~98 ~125 ~187 grass_block
setblock ~98 ~125 ~188 grass_block
setblock ~98 ~125 ~191 short_grass
setblock ~98 ~125 ~193 fern
setblock ~98 ~125 ~194 short_grass
setblock ~98 ~126 ~1 short_grass
setblock ~98 ~126 ~2 short_grass
setblock ~98 ~126 ~3 poppy
setblock ~98 ~126 ~6 short_grass
setblock ~98 ~126 ~7 short_grass
setblock ~98 ~126 ~10 grass_block
setblock ~98 ~126 ~13 short_grass
setblock ~98 ~126 ~17 short_grass
setblock ~98 ~126 ~21 short_grass
setblock ~98 ~126 ~25 short_grass
setblock ~98 ~126 ~26 grass_block
setblock ~98 ~126 ~27 grass_block
setblock ~98 ~126 ~28 grass_block
setblock ~98 ~126 ~29 grass_block
setblock ~98 ~126 ~30 grass_block
setblock ~98 ~126 ~31 grass_block
setblock ~98 ~126 ~34 short_grass
setblock ~98 ~126 ~47 short_grass
setblock ~98 ~126 ~49 grass_block
setblock ~98 ~126 ~50 grass_block
setblock ~98 ~126 ~51 grass_block
setblock ~98 ~126 ~52 grass_block
setblock ~98 ~126 ~53 grass_block
setblock ~98 ~126 ~54 grass_block
setblock ~98 ~126 ~56 short_grass
setblock ~98 ~126 ~59 short_grass
setblock ~98 ~126 ~108 poppy
setblock ~98 ~126 ~109 short_grass
setblock ~98 ~126 ~136 grass_block
setblock ~98 ~126 ~137 grass_block
setblock ~98 ~126 ~138 dirt
setblock ~98 ~126 ~139 dirt
setblock ~98 ~126 ~140 dirt
setblock ~98 ~126 ~141 dirt
setblock ~98 ~126 ~142 dirt
setblock ~98 ~126 ~143 dirt
setblock ~98 ~126 ~144 dirt
setblock ~98 ~126 ~145 dirt
setblock ~98 ~126 ~146 dirt
setblock ~98 ~126 ~147 dirt
setblock ~98 ~126 ~148 dirt
setblock ~98 ~126 ~149 dirt
setblock ~98 ~126 ~150 dirt
setblock ~98 ~126 ~151 dirt
setblock ~98 ~126 ~152 dirt
setblock ~98 ~126 ~153 dirt
setblock ~98 ~126 ~154 grass_block
setblock ~98 ~126 ~155 grass_block
setblock ~98 ~126 ~156 grass_block
setblock ~98 ~126 ~159 poppy
setblock ~98 ~126 ~160 short_grass
setblock ~98 ~126 ~179 poppy
setblock ~98 ~126 ~183 short_grass
setblock ~98 ~126 ~185 short_grass
setblock ~98 ~127 ~10 fern
setblock ~98 ~127 ~26 short_grass
setblock ~98 ~127 ~29 poppy
setblock ~98 ~127 ~51 short_grass
setblock ~98 ~127 ~54 poppy
setblock ~98 ~127 ~137 fern
setblock ~98 ~127 ~138 grass_block
setblock ~98 ~127 ~139 dirt
setblock ~98 ~127 ~140 dirt
setblock ~98 ~127 ~141 dirt
setblock ~98 ~127 ~142 dirt
setblock ~98 ~127 ~143 dirt
setblock ~98 ~127 ~144 dirt
setblock ~98 ~127 ~145 dirt
setblock ~98 ~127 ~146 dirt
setblock ~98 ~127 ~147 dirt
setblock ~98 ~127 ~148 dirt
setblock ~98 ~127 ~149 dirt
setblock ~98 ~127 ~150 dirt
setblock ~98 ~127 ~151 dirt
setblock ~98 ~127 ~152 grass_block
setblock ~98 ~127 ~153 grass_block
setblock ~98 ~127 ~156 short_grass
setblock ~98 ~128 ~138 short_grass
setblock ~98 ~128 ~139 grass_block
setblock ~98 ~128 ~140 grass_block
setblock ~98 ~128 ~141 grass_block
setblock ~98 ~128 ~142 grass_block
setblock ~98 ~128 ~143 grass_block
setblock ~98 ~128 ~144 grass_block
setblock ~98 ~128 ~145 grass_block
setblock ~98 ~128 ~146 grass_block
setblock ~98 ~128 ~147 grass_block
setblock ~98 ~128 ~148 grass_block
setblock ~98 ~128 ~149 grass_block
setblock ~98 ~128 ~150 grass_block
setblock ~98 ~128 ~151 grass_block
setblock ~98 ~128 ~153 fern
setblock ~98 ~129 ~143 short_grass
setblock ~98 ~129 ~145 short_grass
setblock ~98 ~129 ~146 short_grass
setblock ~98 ~129 ~150 short_grass
setblock ~99 ~122 ~0 dirt
setblock ~99 ~122 ~1 dirt
setblock ~99 ~122 ~2 dirt
setblock ~99 ~122 ~3 dirt
setblock ~99 ~122 ~4 dirt
setblock ~99 ~122 ~5 dirt
setblock ~99 ~122 ~6 dirt
setblock ~99 ~122 ~7 dirt
setblock ~99 ~122 ~8 dirt
setblock ~99 ~122 ~9 dirt
setblock ~99 ~122 ~10 dirt
setblock ~99 ~122 ~11 dirt
setblock ~99 ~122 ~12 dirt
setblock ~99 ~122 ~13 dirt
setblock ~99 ~122 ~14 dirt
setblock ~99 ~122 ~15 dirt
setblock ~99 ~122 ~16 dirt
setblock ~99 ~122 ~17 dirt
setblock ~99 ~122 ~18 dirt
setblock ~99 ~122 ~19 dirt
setblock ~99 ~122 ~20 dirt
setblock ~99 ~122 ~21 dirt
setblock ~99 ~122 ~22 dirt
setblock ~99 ~122 ~23 dirt
setblock ~99 ~122 ~24 dirt
setblock ~99 ~122 ~25 dirt
setblock ~99 ~122 ~26 dirt
setblock ~99 ~122 ~27 dirt
setblock ~99 ~122 ~28 dirt
setblock ~99 ~122 ~29 dirt
setblock ~99 ~122 ~30 dirt
setblock ~99 ~122 ~31 dirt
setblock ~99 ~122 ~32 dirt
setblock ~99 ~122 ~33 dirt
setblock ~99 ~122 ~34 dirt
setblock ~99 ~122 ~35 dirt
setblock ~99 ~122 ~36 dirt
setblock ~99 ~122 ~37 dirt
setblock ~99 ~122 ~38 dirt
setblock ~99 ~122 ~39 dirt
setblock ~99 ~122 ~40 dirt
setblock ~99 ~122 ~41 dirt
setblock ~99 ~122 ~42 dirt
setblock ~99 ~122 ~43 dirt
setblock ~99 ~122 ~44 dirt
setblock ~99 ~122 ~45 dirt
setblock ~99 ~122 ~46 dirt
setblock ~99 ~122 ~47 dirt
setblock ~99 ~122 ~48 dirt
setblock ~99 ~122 ~49 dirt
setblock ~99 ~122 ~50 dirt
setblock ~99 ~122 ~51 dirt
setblock ~99 ~122 ~52 dirt
setblock ~99 ~122 ~53 dirt
setblock ~99 ~122 ~54 dirt
setblock ~99 ~122 ~55 dirt
setblock ~99 ~122 ~56 dirt
setblock ~99 ~122 ~57 dirt
setblock ~99 ~122 ~58 dirt
setblock ~99 ~122 ~59 dirt
setblock ~99 ~122 ~60 dirt
setblock ~99 ~122 ~61 dirt
setblock ~99 ~122 ~62 dirt
setblock ~99 ~122 ~63 dirt
setblock ~99 ~122 ~64 dirt
setblock ~99 ~122 ~65 dirt
setblock ~99 ~122 ~66 dirt
setblock ~99 ~122 ~67 dirt
setblock ~99 ~122 ~68 dirt
setblock ~99 ~122 ~69 dirt
setblock ~99 ~122 ~70 dirt
setblock ~99 ~122 ~71 dirt
setblock ~99 ~122 ~72 dirt
setblock ~99 ~122 ~73 dirt
setblock ~99 ~122 ~74 dirt
setblock ~99 ~122 ~75 dirt
setblock ~99 ~122 ~76 dirt
setblock ~99 ~122 ~77 dirt
setblock ~99 ~122 ~78 dirt
setblock ~99 ~122 ~79 dirt
setblock ~99 ~122 ~80 dirt
setblock ~99 ~122 ~81 dirt
setblock ~99 ~122 ~82 dirt
setblock ~99 ~122 ~83 dirt
setblock ~99 ~122 ~84 dirt
setblock ~99 ~122 ~85 dirt
setblock ~99 ~122 ~86 dirt
setblock ~99 ~122 ~87 dirt
setblock ~99 ~122 ~88 dirt
setblock ~99 ~122 ~89 dirt
setblock ~99 ~122 ~90 dirt
setblock ~99 ~122 ~91 dirt
setblock ~99 ~122 ~92 dirt
setblock ~99 ~122 ~93 dirt
setblock ~99 ~122 ~94 dirt
setblock ~99 ~122 ~95 dirt
setblock ~99 ~122 ~96 dirt
setblock ~99 ~122 ~97 dirt
setblock ~99 ~122 ~98 dirt
setblock ~99 ~122 ~99 dirt
setblock ~99 ~122 ~100 dirt
setblock ~99 ~122 ~101 dirt
setblock ~99 ~122 ~102 dirt
setblock ~99 ~122 ~103 dirt
setblock ~99 ~122 ~104 dirt
setblock ~99 ~122 ~105 dirt
setblock ~99 ~122 ~106 dirt
setblock ~99 ~122 ~107 dirt
setblock ~99 ~122 ~108 dirt
setblock ~99 ~122 ~109 dirt
setblock ~99 ~122 ~110 dirt
setblock ~99 ~122 ~111 dirt
setblock ~99 ~122 ~112 dirt
setblock ~99 ~122 ~113 dirt
setblock ~99 ~122 ~114 dirt
setblock ~99 ~122 ~115 dirt
setblock ~99 ~122 ~116 dirt
setblock ~99 ~122 ~117 dirt
setblock ~99 ~122 ~118 dirt
setblock ~99 ~122 ~119 dirt
setblock ~99 ~122 ~120 grass_block
setblock ~99 ~122 ~121 grass_block
setblock ~99 ~122 ~122 grass_block
setblock ~99 ~122 ~123 grass_block
setblock ~99 ~122 ~124 grass_block
setblock ~99 ~122 ~125 grass_block
setblock ~99 ~122 ~126 grass_block
setblock ~99 ~122 ~127 grass_block
setblock ~99 ~122 ~128 grass_block
setblock ~99 ~122 ~129 grass_block
setblock ~99 ~122 ~130 grass_block
setblock ~99 ~122 ~131 grass_block
setblock ~99 ~122 ~132 dirt
setblock ~99 ~122 ~133 dirt
setblock ~99 ~122 ~134 dirt
setblock ~99 ~122 ~135 dirt
setblock ~99 ~122 ~136 dirt
setblock ~99 ~122 ~137 dirt
setblock ~99 ~122 ~138 dirt
setblock ~99 ~122 ~139 dirt
setblock ~99 ~122 ~140 dirt
setblock ~99 ~122 ~141 dirt
setblock ~99 ~122 ~142 dirt
setblock ~99 ~122 ~143 dirt
setblock ~99 ~122 ~144 dirt
setblock ~99 ~122 ~145 dirt
setblock ~99 ~122 ~146 dirt
setblock ~99 ~122 ~147 dirt
setblock ~99 ~122 ~148 dirt
setblock ~99 ~122 ~149 dirt
setblock ~99 ~122 ~150 dirt
setblock ~99 ~122 ~151 dirt
setblock ~99 ~122 ~152 dirt
setblock ~99 ~122 ~153 dirt
setblock ~99 ~122 ~154 dirt
setblock ~99 ~122 ~155 dirt
setblock ~99 ~122 ~156 dirt
setblock ~99 ~122 ~157 dirt
setblock ~99 ~122 ~158 dirt
setblock ~99 ~122 ~159 dirt
setblock ~99 ~122 ~160 dirt
setblock ~99 ~122 ~161 dirt
setblock ~99 ~122 ~162 dirt
setblock ~99 ~122 ~163 dirt
setblock ~99 ~122 ~164 dirt
setblock ~99 ~122 ~165 dirt
setblock ~99 ~122 ~166 dirt
setblock ~99 ~122 ~167 dirt
setblock ~99 ~122 ~168 grass_block
setblock ~99 ~122 ~169 grass_block
setblock ~99 ~122 ~170 grass_block
setblock ~99 ~122 ~171 grass_block
setblock ~99 ~122 ~172 dirt
setblock ~99 ~122 ~173 dirt
setblock ~99 ~122 ~174 dirt
setblock ~99 ~122 ~175 dirt
setblock ~99 ~122 ~176 dirt
setblock ~99 ~122 ~177 dirt
setblock ~99 ~122 ~178 dirt
setblock ~99 ~122 ~179 dirt
setblock ~99 ~122 ~180 dirt
setblock ~99 ~122 ~181 dirt
setblock ~99 ~122 ~182 dirt
setblock ~99 ~122 ~183 dirt
setblock ~99 ~122 ~184 dirt
setblock ~99 ~122 ~185 dirt
setblock ~99 ~122 ~186 dirt
setblock ~99 ~122 ~187 dirt
setblock ~99 ~122 ~188 dirt
setblock ~99 ~122 ~189 dirt
setblock ~99 ~122 ~190 dirt
setblock ~99 ~122 ~191 dirt
setblock ~99 ~122 ~192 dirt
setblock ~99 ~122 ~193 dirt
setblock ~99 ~122 ~194 dirt
setblock ~99 ~122 ~195 dirt
setblock ~99 ~122 ~196 dirt
setblock ~99 ~122 ~197 dirt
setblock ~99 ~122 ~198 dirt
setblock ~99 ~122 ~199 dirt
setblock ~99 ~123 ~0 dirt
setblock ~99 ~123 ~1 dirt
setblock ~99 ~123 ~2 dirt
setblock ~99 ~123 ~3 dirt
setblock ~99 ~123 ~4 dirt
setblock ~99 ~123 ~5 dirt
setblock ~99 ~123 ~6 dirt
setblock ~99 ~123 ~7 dirt
setblock ~99 ~123 ~8 dirt
setblock ~99 ~123 ~9 dirt
setblock ~99 ~123 ~10 dirt
setblock ~99 ~123 ~11 dirt
setblock ~99 ~123 ~12 dirt
setblock ~99 ~123 ~13 dirt
setblock ~99 ~123 ~14 dirt
setblock ~99 ~123 ~15 dirt
setblock ~99 ~123 ~16 dirt
setblock ~99 ~123 ~17 dirt
setblock ~99 ~123 ~18 dirt
setblock ~99 ~123 ~19 dirt
setblock ~99 ~123 ~20 dirt
setblock ~99 ~123 ~21 dirt
setblock ~99 ~123 ~22 dirt
setblock ~99 ~123 ~23 dirt
setblock ~99 ~123 ~24 dirt
setblock ~99 ~123 ~25 dirt
setblock ~99 ~123 ~26 dirt
setblock ~99 ~123 ~27 dirt
setblock ~99 ~123 ~28 dirt
setblock ~99 ~123 ~29 dirt
setblock ~99 ~123 ~30 dirt
setblock ~99 ~123 ~31 dirt
setblock ~99 ~123 ~32 dirt
setblock ~99 ~123 ~33 dirt
setblock ~99 ~123 ~34 dirt
setblock ~99 ~123 ~35 dirt
setblock ~99 ~123 ~36 dirt
setblock ~99 ~123 ~37 dirt
setblock ~99 ~123 ~38 grass_block
setblock ~99 ~123 ~39 grass_block
setblock ~99 ~123 ~40 grass_block
setblock ~99 ~123 ~41 grass_block
setblock ~99 ~123 ~42 grass_block
setblock ~99 ~123 ~43 dirt
setblock ~99 ~123 ~44 dirt
setblock ~99 ~123 ~45 dirt
setblock ~99 ~123 ~46 dirt
setblock ~99 ~123 ~47 dirt
setblock ~99 ~123 ~48 dirt
setblock ~99 ~123 ~49 dirt
setblock ~99 ~123 ~50 dirt
setblock ~99 ~123 ~51 dirt
setblock ~99 ~123 ~52 dirt
setblock ~99 ~123 ~53 dirt
setblock ~99 ~123 ~54 dirt
setblock ~99 ~123 ~55 dirt
setblock ~99 ~123 ~56 dirt
setblock ~99 ~123 ~57 dirt
setblock ~99 ~123 ~58 dirt
setblock ~99 ~123 ~59 dirt
setblock ~99 ~123 ~60 dirt
setblock ~99 ~123 ~61 dirt
setblock ~99 ~123 ~62 dirt
setblock ~99 ~123 ~63 dirt
setblock ~99 ~123 ~64 dirt
setblock ~99 ~123 ~65 dirt
setblock ~99 ~123 ~66 dirt
setblock ~99 ~123 ~67 dirt
setblock ~99 ~123 ~68 grass_block
setblock ~99 ~123 ~69 grass_block
setblock ~99 ~123 ~70 grass_block
setblock ~99 ~123 ~71 grass_block
setblock ~99 ~123 ~72 grass_block
setblock ~99 ~123 ~73 grass_block
setblock ~99 ~123 ~74 grass_block
setblock ~99 ~123 ~75 grass_block
setblock ~99 ~123 ~76 grass_block
setblock ~99 ~123 ~77 grass_block
setblock ~99 ~123 ~78 grass_block
setblock ~99 ~123 ~79 grass_block
setblock ~99 ~123 ~80 grass_block
setblock ~99 ~123 ~81 grass_block
setblock ~99 ~123 ~82 grass_block
setblock ~99 ~123 ~83 grass_block
setblock ~99 ~123 ~84 dirt
setblock ~99 ~123 ~85 dirt
setblock ~99 ~123 ~86 dirt
setblock ~99 ~123 ~87 dirt
setblock ~99 ~123 ~88 dirt
setblock ~99 ~123 ~89 dirt
setblock ~99 ~123 ~90 dirt
setblock ~99 ~123 ~91 dirt
setblock ~99 ~123 ~92 dirt
setblock ~99 ~123 ~93 dirt
setblock ~99 ~123 ~94 dirt
setblock ~99 ~123 ~95 dirt
setblock ~99 ~123 ~96 dirt
setblock ~99 ~123 ~97 dirt
setblock ~99 ~123 ~98 dirt
setblock ~99 ~123 ~99 dirt
setblock ~99 ~123 ~100 grass_block
setblock ~99 ~123 ~101 dirt
setblock ~99 ~123 ~102 dirt
setblock ~99 ~123 ~103 dirt
setblock ~99 ~123 ~104 dirt
setblock ~99 ~123 ~105 dirt
setblock ~99 ~123 ~106 dirt
setblock ~99 ~123 ~107 dirt
setblock ~99 ~123 ~108 dirt
setblock ~99 ~123 ~109 dirt
setblock ~99 ~123 ~110 dirt
setblock ~99 ~123 ~111 dirt
setblock ~99 ~123 ~112 dirt
setblock ~99 ~123 ~113 dirt
setblock ~99 ~123 ~114 dirt
setblock ~99 ~123 ~115 dirt
setblock ~99 ~123 ~116 dirt
setblock ~99 ~123 ~117 grass_block
