setblock ~182 ~127 ~93 grass_block
setblock ~182 ~127 ~94 short_grass
setblock ~182 ~127 ~180 short_grass
setblock ~182 ~127 ~183 short_grass
setblock ~182 ~127 ~185 grass_block
setblock ~182 ~127 ~186 grass_block
setblock ~182 ~127 ~187 grass_block
setblock ~182 ~127 ~188 grass_block
setblock ~182 ~127 ~189 grass_block
setblock ~182 ~127 ~190 grass_block
setblock ~182 ~127 ~191 grass_block
setblock ~182 ~128 ~50 short_grass
setblock ~182 ~128 ~87 grass_block
setblock ~182 ~128 ~88 grass_block
setblock ~182 ~128 ~89 dirt
setblock ~182 ~128 ~90 dirt
setblock ~182 ~128 ~91 dirt
setblock ~182 ~128 ~92 grass_block
setblock ~182 ~129 ~88 short_grass
setblock ~182 ~129 ~89 grass_block
setblock ~182 ~129 ~90 dirt
setblock ~182 ~129 ~91 grass_block
setblock ~182 ~130 ~89 short_grass
setblock ~182 ~130 ~90 grass_block
setblock ~182 ~130 ~91 short_grass
setblock ~183 ~122 ~0 dirt
setblock ~183 ~122 ~1 dirt
setblock ~183 ~122 ~2 dirt
setblock ~183 ~122 ~3 dirt
setblock ~183 ~122 ~4 dirt
setblock ~183 ~122 ~5 dirt
setblock ~183 ~122 ~6 dirt
setblock ~183 ~122 ~7 dirt
setblock ~183 ~122 ~8 dirt
setblock ~183 ~122 ~9 dirt
setblock ~183 ~122 ~10 dirt
setblock ~183 ~122 ~11 dirt
setblock ~183 ~122 ~12 dirt
setblock ~183 ~122 ~13 dirt
setblock ~183 ~122 ~14 dirt
setblock ~183 ~122 ~15 dirt
setblock ~183 ~122 ~16 dirt
setblock ~183 ~122 ~17 dirt
setblock ~183 ~122 ~18 dirt
setblock ~183 ~122 ~19 dirt
setblock ~183 ~122 ~20 dirt
setblock ~183 ~122 ~21 dirt
setblock ~183 ~122 ~22 dirt
setblock ~183 ~122 ~23 dirt
setblock ~183 ~122 ~24 dirt
setblock ~183 ~122 ~25 dirt
setblock ~183 ~122 ~26 dirt
setblock ~183 ~122 ~27 dirt
setblock ~183 ~122 ~28 dirt
setblock ~183 ~122 ~29 dirt
setblock ~183 ~122 ~30 dirt
setblock ~183 ~122 ~31 dirt
setblock ~183 ~122 ~32 dirt
setblock ~183 ~122 ~33 dirt
setblock ~183 ~122 ~34 dirt
setblock ~183 ~122 ~35 dirt
setblock ~183 ~122 ~36 dirt
setblock ~183 ~122 ~37 dirt
setblock ~183 ~122 ~38 dirt
setblock ~183 ~122 ~39 dirt
setblock ~183 ~122 ~40 dirt
setblock ~183 ~122 ~41 dirt
setblock ~183 ~122 ~42 dirt
setblock ~183 ~122 ~43 dirt
setblock ~183 ~122 ~44 dirt
setblock ~183 ~122 ~45 dirt
setblock ~183 ~122 ~46 dirt
setblock ~183 ~122 ~47 dirt
setblock ~183 ~122 ~48 dirt
setblock ~183 ~122 ~49 dirt
setblock ~183 ~122 ~50 dirt
setblock ~183 ~122 ~51 dirt
setblock ~183 ~122 ~52 dirt
setblock ~183 ~122 ~53 dirt
setblock ~183 ~122 ~54 dirt
setblock ~183 ~122 ~55 dirt
setblock ~183 ~122 ~56 dirt
setblock ~183 ~122 ~57 dirt
setblock ~183 ~122 ~58 dirt
setblock ~183 ~122 ~59 dirt
setblock ~183 ~122 ~60 dirt
setblock ~183 ~122 ~61 dirt
setblock ~183 ~122 ~62 dirt
setblock ~183 ~122 ~63 dirt
setblock ~183 ~122 ~64 dirt
setblock ~183 ~122 ~65 dirt
setblock ~183 ~122 ~66 dirt
setblock ~183 ~122 ~67 dirt
setblock ~183 ~122 ~68 dirt
setblock ~183 ~122 ~69 dirt
setblock ~183 ~122 ~70 dirt
setblock ~183 ~122 ~71 dirt
setblock ~183 ~122 ~72 dirt
setblock ~183 ~122 ~73 dirt
setblock ~183 ~122 ~74 dirt
setblock ~183 ~122 ~75 dirt
setblock ~183 ~122 ~76 dirt
setblock ~183 ~122 ~77 dirt
setblock ~183 ~122 ~78 dirt
setblock ~183 ~122 ~79 dirt
setblock ~183 ~122 ~80 dirt
setblock ~183 ~122 ~81 dirt
setblock ~183 ~122 ~82 dirt
setblock ~183 ~122 ~83 dirt
setblock ~183 ~122 ~84 dirt
setblock ~183 ~122 ~85 dirt
setblock ~183 ~122 ~86 dirt
setblock ~183 ~122 ~87 dirt
setblock ~183 ~122 ~88 dirt
setblock ~183 ~122 ~89 dirt
setblock ~183 ~122 ~90 dirt
setblock ~183 ~122 ~91 dirt
setblock ~183 ~122 ~92 dirt
setblock ~183 ~122 ~93 dirt
setblock ~183 ~122 ~94 dirt
setblock ~183 ~122 ~95 dirt
setblock ~183 ~122 ~96 dirt
setblock ~183 ~122 ~97 dirt
setblock ~183 ~122 ~98 dirt
setblock ~183 ~122 ~99 dirt
setblock ~183 ~122 ~100 dirt
setblock ~183 ~122 ~101 dirt
setblock ~183 ~122 ~102 dirt
setblock ~183 ~122 ~103 dirt
setblock ~183 ~122 ~104 dirt
setblock ~183 ~122 ~105 dirt
setblock ~183 ~122 ~106 dirt
setblock ~183 ~122 ~107 dirt
setblock ~183 ~122 ~108 dirt
setblock ~183 ~122 ~109 dirt
setblock ~183 ~122 ~110 dirt
setblock ~183 ~122 ~111 dirt
setblock ~183 ~122 ~112 dirt
setblock ~183 ~122 ~113 dirt
setblock ~183 ~122 ~114 dirt
setblock ~183 ~122 ~115 dirt
setblock ~183 ~122 ~116 dirt
setblock ~183 ~122 ~117 dirt
setblock ~183 ~122 ~118 dirt
setblock ~183 ~122 ~119 dirt
setblock ~183 ~122 ~120 dirt
setblock ~183 ~122 ~121 dirt
setblock ~183 ~122 ~122 dirt
setblock ~183 ~122 ~123 dirt
setblock ~183 ~122 ~124 dirt
setblock ~183 ~122 ~125 dirt
setblock ~183 ~122 ~126 dirt
setblock ~183 ~122 ~127 dirt
setblock ~183 ~122 ~128 dirt
setblock ~183 ~122 ~129 dirt
setblock ~183 ~122 ~130 dirt
setblock ~183 ~122 ~131 dirt
setblock ~183 ~122 ~132 dirt
setblock ~183 ~122 ~133 dirt
setblock ~183 ~122 ~134 dirt
setblock ~183 ~122 ~135 dirt
setblock ~183 ~122 ~136 dirt
setblock ~183 ~122 ~137 dirt
setblock ~183 ~122 ~138 dirt
setblock ~183 ~122 ~139 dirt
setblock ~183 ~122 ~140 dirt
setblock ~183 ~122 ~141 dirt
setblock ~183 ~122 ~142 dirt
setblock ~183 ~122 ~143 dirt
setblock ~183 ~122 ~144 dirt
setblock ~183 ~122 ~145 dirt
setblock ~183 ~122 ~146 dirt
setblock ~183 ~122 ~147 dirt
setblock ~183 ~122 ~148 dirt
setblock ~183 ~122 ~149 dirt
setblock ~183 ~122 ~150 dirt
setblock ~183 ~122 ~151 dirt
setblock ~183 ~122 ~152 dirt
setblock ~183 ~122 ~153 dirt
setblock ~183 ~122 ~154 dirt
setblock ~183 ~122 ~155 dirt
setblock ~183 ~122 ~156 dirt
setblock ~183 ~122 ~157 dirt
setblock ~183 ~122 ~158 dirt
setblock ~183 ~122 ~159 dirt
setblock ~183 ~122 ~160 dirt
setblock ~183 ~122 ~161 dirt
setblock ~183 ~122 ~162 dirt
setblock ~183 ~122 ~163 dirt
setblock ~183 ~122 ~164 dirt
setblock ~183 ~122 ~165 dirt
setblock ~183 ~122 ~166 dirt
setblock ~183 ~122 ~167 dirt
setblock ~183 ~122 ~168 dirt
setblock ~183 ~122 ~169 dirt
setblock ~183 ~122 ~170 dirt
setblock ~183 ~122 ~171 dirt
setblock ~183 ~122 ~172 dirt
setblock ~183 ~122 ~173 dirt
setblock ~183 ~122 ~174 dirt
setblock ~183 ~122 ~175 dirt
setblock ~183 ~122 ~176 dirt
setblock ~183 ~122 ~177 dirt
setblock ~183 ~122 ~178 dirt
setblock ~183 ~122 ~179 dirt
setblock ~183 ~122 ~180 dirt
setblock ~183 ~122 ~181 dirt
setblock ~183 ~122 ~182 dirt
setblock ~183 ~122 ~183 dirt
setblock ~183 ~122 ~184 dirt
setblock ~183 ~122 ~185 dirt
setblock ~183 ~122 ~186 dirt
setblock ~183 ~122 ~187 dirt
setblock ~183 ~122 ~188 dirt
setblock ~183 ~122 ~189 dirt
setblock ~183 ~122 ~190 dirt
setblock ~183 ~122 ~191 dirt
setblock ~183 ~122 ~192 dirt
setblock ~183 ~122 ~193 dirt
setblock ~183 ~122 ~194 dirt
setblock ~183 ~122 ~195 dirt
setblock ~183 ~122 ~196 dirt
setblock ~183 ~122 ~197 dirt
setblock ~183 ~122 ~198 dirt
setblock ~183 ~122 ~199 dirt
setblock ~183 ~123 ~0 dirt
setblock ~183 ~123 ~1 dirt
setblock ~183 ~123 ~2 dirt
setblock ~183 ~123 ~3 dirt
setblock ~183 ~123 ~4 dirt
setblock ~183 ~123 ~5 dirt
setblock ~183 ~123 ~6 dirt
setblock ~183 ~123 ~7 dirt
setblock ~183 ~123 ~8 dirt
setblock ~183 ~123 ~9 dirt
setblock ~183 ~123 ~10 dirt
setblock ~183 ~123 ~11 dirt
setblock ~183 ~123 ~12 dirt
setblock ~183 ~123 ~13 dirt
setblock ~183 ~123 ~14 dirt
setblock ~183 ~123 ~15 dirt
setblock ~183 ~123 ~16 dirt
setblock ~183 ~123 ~17 dirt
setblock ~183 ~123 ~18 dirt
setblock ~183 ~123 ~19 dirt
setblock ~183 ~123 ~20 dirt
setblock ~183 ~123 ~21 dirt
setblock ~183 ~123 ~22 dirt
setblock ~183 ~123 ~23 dirt
setblock ~183 ~123 ~24 dirt
setblock ~183 ~123 ~25 dirt
setblock ~183 ~123 ~26 dirt
setblock ~183 ~123 ~27 dirt
setblock ~183 ~123 ~28 dirt
setblock ~183 ~123 ~29 dirt
setblock ~183 ~123 ~30 dirt
setblock ~183 ~123 ~31 dirt
setblock ~183 ~123 ~32 dirt
setblock ~183 ~123 ~33 dirt
setblock ~183 ~123 ~34 dirt
setblock ~183 ~123 ~35 dirt
setblock ~183 ~123 ~36 dirt
setblock ~183 ~123 ~37 grass_block
setblock ~183 ~123 ~38 grass_block
setblock ~183 ~123 ~39 grass_block
setblock ~183 ~123 ~40 grass_block
setblock ~183 ~123 ~41 dirt
setblock ~183 ~123 ~42 dirt
setblock ~183 ~123 ~43 dirt
setblock ~183 ~123 ~44 dirt
setblock ~183 ~123 ~45 dirt
setblock ~183 ~123 ~46 dirt
setblock ~183 ~123 ~47 dirt
setblock ~183 ~123 ~48 dirt
setblock ~183 ~123 ~49 dirt
setblock ~183 ~123 ~50 dirt
setblock ~183 ~123 ~51 dirt
setblock ~183 ~123 ~52 dirt
setblock ~183 ~123 ~53 dirt
setblock ~183 ~123 ~54 dirt
setblock ~183 ~123 ~55 dirt
setblock ~183 ~123 ~56 dirt
setblock ~183 ~123 ~57 dirt
setblock ~183 ~123 ~58 dirt
setblock ~183 ~123 ~59 dirt
setblock ~183 ~123 ~60 grass_block
setblock ~183 ~123 ~61 grass_block
setblock ~183 ~123 ~62 grass_block
setblock ~183 ~123 ~63 dirt
setblock ~183 ~123 ~64 dirt
setblock ~183 ~123 ~65 dirt
setblock ~183 ~123 ~66 dirt
setblock ~183 ~123 ~67 dirt
setblock ~183 ~123 ~68 dirt
setblock ~183 ~123 ~69 dirt
setblock ~183 ~123 ~70 dirt
setblock ~183 ~123 ~71 dirt
setblock ~183 ~123 ~72 dirt
setblock ~183 ~123 ~73 dirt
setblock ~183 ~123 ~74 dirt
setblock ~183 ~123 ~75 dirt
setblock ~183 ~123 ~76 dirt
setblock ~183 ~123 ~77 dirt
setblock ~183 ~123 ~78 dirt
setblock ~183 ~123 ~79 dirt
setblock ~183 ~123 ~80 dirt
setblock ~183 ~123 ~81 dirt
setblock ~183 ~123 ~82 dirt
setblock ~183 ~123 ~83 dirt
setblock ~183 ~123 ~84 dirt
setblock ~183 ~123 ~85 dirt
setblock ~183 ~123 ~86 dirt
setblock ~183 ~123 ~87 dirt
setblock ~183 ~123 ~88 dirt
setblock ~183 ~123 ~89 dirt
setblock ~183 ~123 ~90 dirt
setblock ~183 ~123 ~91 dirt
setblock ~183 ~123 ~92 dirt
setblock ~183 ~123 ~93 dirt
setblock ~183 ~123 ~94 dirt
setblock ~183 ~123 ~95 dirt
setblock ~183 ~123 ~96 dirt
setblock ~183 ~123 ~97 dirt
setblock ~183 ~123 ~98 dirt
setblock ~183 ~123 ~99 dirt
setblock ~183 ~123 ~100 dirt
setblock ~183 ~123 ~101 dirt
setblock ~183 ~123 ~102 dirt
setblock ~183 ~123 ~103 dirt
setblock ~183 ~123 ~104 dirt
setblock ~183 ~123 ~105 dirt
setblock ~183 ~123 ~106 dirt
setblock ~183 ~123 ~107 grass_block
setblock ~183 ~123 ~108 grass_block
setblock ~183 ~123 ~109 grass_block
setblock ~183 ~123 ~110 grass_block
setblock ~183 ~123 ~111 grass_block
setblock ~183 ~123 ~112 dirt
setblock ~183 ~123 ~113 dirt
setblock ~183 ~123 ~114 dirt
setblock ~183 ~123 ~115 grass_block
setblock ~183 ~123 ~116 grass_block
setblock ~183 ~123 ~117 grass_block
setblock ~183 ~123 ~118 grass_block
setblock ~183 ~123 ~119 grass_block
setblock ~183 ~123 ~120 grass_block
setblock ~183 ~123 ~121 grass_block
setblock ~183 ~123 ~122 grass_block
setblock ~183 ~123 ~123 grass_block
setblock ~183 ~123 ~124 dirt
setblock ~183 ~123 ~125 dirt
setblock ~183 ~123 ~126 dirt
setblock ~183 ~123 ~127 dirt
setblock ~183 ~123 ~128 dirt
setblock ~183 ~123 ~129 dirt
setblock ~183 ~123 ~130 dirt
setblock ~183 ~123 ~131 dirt
setblock ~183 ~123 ~132 dirt
setblock ~183 ~123 ~133 dirt
setblock ~183 ~123 ~134 dirt
setblock ~183 ~123 ~135 dirt
setblock ~183 ~123 ~136 dirt
setblock ~183 ~123 ~137 dirt
setblock ~183 ~123 ~138 dirt
setblock ~183 ~123 ~139 dirt
setblock ~183 ~123 ~140 dirt
setblock ~183 ~123 ~141 dirt
setblock ~183 ~123 ~142 dirt
setblock ~183 ~123 ~143 dirt
setblock ~183 ~123 ~144 dirt
setblock ~183 ~123 ~145 dirt
setblock ~183 ~123 ~146 dirt
setblock ~183 ~123 ~147 dirt
setblock ~183 ~123 ~148 dirt
setblock ~183 ~123 ~149 grass_block
setblock ~183 ~123 ~150 grass_block
setblock ~183 ~123 ~151 grass_block
setblock ~183 ~123 ~152 dirt
setblock ~183 ~123 ~153 dirt
setblock ~183 ~123 ~154 dirt
setblock ~183 ~123 ~155 dirt
setblock ~183 ~123 ~156 dirt
setblock ~183 ~123 ~157 dirt
setblock ~183 ~123 ~158 dirt
setblock ~183 ~123 ~159 dirt
setblock ~183 ~123 ~160 dirt
setblock ~183 ~123 ~161 dirt
setblock ~183 ~123 ~162 dirt
setblock ~183 ~123 ~163 dirt
setblock ~183 ~123 ~164 dirt
setblock ~183 ~123 ~165 dirt
setblock ~183 ~123 ~166 dirt
setblock ~183 ~123 ~167 dirt
setblock ~183 ~123 ~168 dirt
setblock ~183 ~123 ~169 grass_block
setblock ~183 ~123 ~170 grass_block
setblock ~183 ~123 ~171 dirt
setblock ~183 ~123 ~172 dirt
setblock ~183 ~123 ~173 dirt
setblock ~183 ~123 ~174 dirt
setblock ~183 ~123 ~175 dirt
setblock ~183 ~123 ~176 dirt
setblock ~183 ~123 ~177 dirt
setblock ~183 ~123 ~178 dirt
setblock ~183 ~123 ~179 dirt
setblock ~183 ~123 ~180 dirt
setblock ~183 ~123 ~181 dirt
setblock ~183 ~123 ~182 dirt
setblock ~183 ~123 ~183 dirt
setblock ~183 ~123 ~184 dirt
setblock ~183 ~123 ~185 dirt
setblock ~183 ~123 ~186 dirt
setblock ~183 ~123 ~187 dirt
setblock ~183 ~123 ~188 dirt
setblock ~183 ~123 ~189 dirt
setblock ~183 ~123 ~190 dirt
setblock ~183 ~123 ~191 dirt
setblock ~183 ~123 ~192 dirt
setblock ~183 ~123 ~193 dirt
setblock ~183 ~123 ~194 dirt
setblock ~183 ~123 ~195 dirt
setblock ~183 ~123 ~196 dirt
setblock ~183 ~123 ~197 dirt
setblock ~183 ~123 ~198 dirt
setblock ~183 ~123 ~199 grass_block
setblock ~183 ~124 ~0 dirt
setblock ~183 ~124 ~1 dirt
setblock ~183 ~124 ~2 dirt
setblock ~183 ~124 ~3 dirt
setblock ~183 ~124 ~4 dirt
setblock ~183 ~124 ~5 dirt
setblock ~183 ~124 ~6 dirt
setblock ~183 ~124 ~7 dirt
setblock ~183 ~124 ~8 dirt
setblock ~183 ~124 ~9 grass_block
setblock ~183 ~124 ~10 grass_block
setblock ~183 ~124 ~11 grass_block
setblock ~183 ~124 ~12 grass_block
setblock ~183 ~124 ~13 grass_block
setblock ~183 ~124 ~14 grass_block
setblock ~183 ~124 ~15 grass_block
setblock ~183 ~124 ~16 grass_block
setblock ~183 ~124 ~17 grass_block
setblock ~183 ~124 ~18 grass_block
setblock ~183 ~124 ~19 grass_block
setblock ~183 ~124 ~20 grass_block
setblock ~183 ~124 ~21 grass_block
setblock ~183 ~124 ~22 grass_block
setblock ~183 ~124 ~23 grass_block
setblock ~183 ~124 ~24 grass_block
setblock ~183 ~124 ~25 grass_block
setblock ~183 ~124 ~26 grass_block
setblock ~183 ~124 ~27 grass_block
setblock ~183 ~124 ~28 grass_block
setblock ~183 ~124 ~29 grass_block
setblock ~183 ~124 ~30 grass_block
setblock ~183 ~124 ~31 grass_block
setblock ~183 ~124 ~32 grass_block
setblock ~183 ~124 ~33 grass_block
setblock ~183 ~124 ~34 grass_block
setblock ~183 ~124 ~35 grass_block
setblock ~183 ~124 ~36 grass_block
setblock ~183 ~124 ~37 short_grass
setblock ~183 ~124 ~39 short_grass
setblock ~183 ~124 ~41 grass_block
setblock ~183 ~124 ~42 grass_block
setblock ~183 ~124 ~43 grass_block
setblock ~183 ~124 ~44 dirt
setblock ~183 ~124 ~45 dirt
setblock ~183 ~124 ~46 dirt
setblock ~183 ~124 ~47 dirt
setblock ~183 ~124 ~48 dirt
setblock ~183 ~124 ~49 dirt
setblock ~183 ~124 ~50 dirt
setblock ~183 ~124 ~51 dirt
setblock ~183 ~124 ~52 dirt
setblock ~183 ~124 ~53 dirt
setblock ~183 ~124 ~54 dirt
setblock ~183 ~124 ~55 dirt
setblock ~183 ~124 ~56 dirt
setblock ~183 ~124 ~57 dirt
setblock ~183 ~124 ~58 grass_block
setblock ~183 ~124 ~59 grass_block
setblock ~183 ~124 ~60 short_grass
setblock ~183 ~124 ~63 grass_block
setblock ~183 ~124 ~64 grass_block
setblock ~183 ~124 ~65 grass_block
setblock ~183 ~124 ~66 dirt
setblock ~183 ~124 ~67 dirt
setblock ~183 ~124 ~68 dirt
setblock ~183 ~124 ~69 dirt
setblock ~183 ~124 ~70 dirt
setblock ~183 ~124 ~71 dirt
setblock ~183 ~124 ~72 dirt
setblock ~183 ~124 ~73 dirt
setblock ~183 ~124 ~74 dirt
setblock ~183 ~124 ~75 dirt
setblock ~183 ~124 ~76 dirt
setblock ~183 ~124 ~77 dirt
setblock ~183 ~124 ~78 dirt
setblock ~183 ~124 ~79 dirt
setblock ~183 ~124 ~80 dirt
setblock ~183 ~124 ~81 dirt
setblock ~183 ~124 ~82 dirt
setblock ~183 ~124 ~83 dirt
setblock ~183 ~124 ~84 dirt
setblock ~183 ~124 ~85 dirt
setblock ~183 ~124 ~86 dirt
setblock ~183 ~124 ~87 dirt
setblock ~183 ~124 ~88 dirt
setblock ~183 ~124 ~89 dirt
setblock ~183 ~124 ~90 dirt
setblock ~183 ~124 ~91 dirt
setblock ~183 ~124 ~92 dirt
setblock ~183 ~124 ~93 dirt
setblock ~183 ~124 ~94 dirt
setblock ~183 ~124 ~95 dirt
setblock ~183 ~124 ~96 dirt
setblock ~183 ~124 ~97 dirt
setblock ~183 ~124 ~98 grass_block
setblock ~183 ~124 ~99 grass_block
setblock ~183 ~124 ~100 grass_block
setblock ~183 ~124 ~101 grass_block
setblock ~183 ~124 ~102 grass_block
setblock ~183 ~124 ~103 grass_block
setblock ~183 ~124 ~104 grass_block
setblock ~183 ~124 ~105 grass_block
setblock ~183 ~124 ~106 grass_block
setblock ~183 ~124 ~112 grass_block
setblock ~183 ~124 ~113 grass_block
setblock ~183 ~124 ~114 grass_block
setblock ~183 ~124 ~117 short_grass
setblock ~183 ~124 ~120 short_grass
setblock ~183 ~124 ~122 short_grass
setblock ~183 ~124 ~124 grass_block
setblock ~183 ~124 ~125 grass_block
setblock ~183 ~124 ~126 grass_block
setblock ~183 ~124 ~127 grass_block
setblock ~183 ~124 ~128 grass_block
setblock ~183 ~124 ~129 grass_block
setblock ~183 ~124 ~130 grass_block
setblock ~183 ~124 ~131 grass_block
setblock ~183 ~124 ~132 grass_block
setblock ~183 ~124 ~133 grass_block
setblock ~183 ~124 ~134 grass_block
setblock ~183 ~124 ~135 grass_block
setblock ~183 ~124 ~136 grass_block
setblock ~183 ~124 ~137 grass_block
setblock ~183 ~124 ~138 grass_block
setblock ~183 ~124 ~139 grass_block
setblock ~183 ~124 ~140 grass_block
setblock ~183 ~124 ~141 grass_block
setblock ~183 ~124 ~142 grass_block
setblock ~183 ~124 ~143 grass_block
setblock ~183 ~124 ~144 grass_block
setblock ~183 ~124 ~145 grass_block
setblock ~183 ~124 ~146 grass_block
setblock ~183 ~124 ~147 grass_block
setblock ~183 ~124 ~148 grass_block
setblock ~183 ~124 ~152 grass_block
setblock ~183 ~124 ~153 grass_block
setblock ~183 ~124 ~154 grass_block
setblock ~183 ~124 ~155 grass_block
setblock ~183 ~124 ~156 grass_block
setblock ~183 ~124 ~157 grass_block
setblock ~183 ~124 ~158 dirt
setblock ~183 ~124 ~159 dirt
setblock ~183 ~124 ~160 dirt
setblock ~183 ~124 ~161 dirt
setblock ~183 ~124 ~162 dirt
setblock ~183 ~124 ~163 grass_block
setblock ~183 ~124 ~164 grass_block
setblock ~183 ~124 ~165 grass_block
setblock ~183 ~124 ~166 grass_block
setblock ~183 ~124 ~167 grass_block
setblock ~183 ~124 ~168 grass_block
setblock ~183 ~124 ~171 grass_block
setblock ~183 ~124 ~172 grass_block
setblock ~183 ~124 ~173 grass_block
setblock ~183 ~124 ~174 dirt
setblock ~183 ~124 ~175 dirt
setblock ~183 ~124 ~176 dirt
setblock ~183 ~124 ~177 dirt
setblock ~183 ~124 ~178 dirt
setblock ~183 ~124 ~179 dirt
setblock ~183 ~124 ~180 dirt
setblock ~183 ~124 ~181 dirt
setblock ~183 ~124 ~182 dirt
setblock ~183 ~124 ~183 dirt
setblock ~183 ~124 ~184 dirt
setblock ~183 ~124 ~185 dirt
setblock ~183 ~124 ~186 dirt
setblock ~183 ~124 ~187 dirt
setblock ~183 ~124 ~188 dirt
setblock ~183 ~124 ~189 dirt
setblock ~183 ~124 ~190 dirt
setblock ~183 ~124 ~191 dirt
setblock ~183 ~124 ~192 dirt
setblock ~183 ~124 ~193 dirt
setblock ~183 ~124 ~194 dirt
setblock ~183 ~124 ~195 dirt
setblock ~183 ~124 ~196 grass_block
setblock ~183 ~124 ~197 grass_block
setblock ~183 ~124 ~198 grass_block
setblock ~183 ~125 ~0 grass_block
setblock ~183 ~125 ~1 grass_block
setblock ~183 ~125 ~2 grass_block
setblock ~183 ~125 ~3 grass_block
setblock ~183 ~125 ~4 grass_block
setblock ~183 ~125 ~5 grass_block
setblock ~183 ~125 ~6 grass_block
setblock ~183 ~125 ~7 grass_block
setblock ~183 ~125 ~8 grass_block
setblock ~183 ~125 ~9 short_grass
setblock ~183 ~125 ~12 short_grass
setblock ~183 ~125 ~16 short_grass
setblock ~183 ~125 ~30 short_grass
setblock ~183 ~125 ~33 short_grass
setblock ~183 ~125 ~43 short_grass
setblock ~183 ~125 ~44 grass_block
setblock ~183 ~125 ~45 grass_block
setblock ~183 ~125 ~46 grass_block
setblock ~183 ~125 ~47 dirt
setblock ~183 ~125 ~48 dirt
setblock ~183 ~125 ~49 dirt
setblock ~183 ~125 ~50 dirt
setblock ~183 ~125 ~51 dirt
setblock ~183 ~125 ~52 dirt
setblock ~183 ~125 ~53 dirt
setblock ~183 ~125 ~54 dirt
setblock ~183 ~125 ~55 grass_block
setblock ~183 ~125 ~56 grass_block
setblock ~183 ~125 ~57 grass_block
setblock ~183 ~125 ~59 poppy
setblock ~183 ~125 ~66 grass_block
setblock ~183 ~125 ~67 grass_block
setblock ~183 ~125 ~68 grass_block
setblock ~183 ~125 ~69 dirt
setblock ~183 ~125 ~70 dirt
setblock ~183 ~125 ~71 dirt
setblock ~183 ~125 ~72 dirt
setblock ~183 ~125 ~73 dirt
setblock ~183 ~125 ~74 grass_block
setblock ~183 ~125 ~75 grass_block
setblock ~183 ~125 ~76 grass_block
setblock ~183 ~125 ~77 grass_block
setblock ~183 ~125 ~78 grass_block
setblock ~183 ~125 ~79 grass_block
setblock ~183 ~125 ~80 grass_block
setblock ~183 ~125 ~81 grass_block
setblock ~183 ~125 ~82 dirt
setblock ~183 ~125 ~83 dirt
setblock ~183 ~125 ~84 dirt
setblock ~183 ~125 ~85 dirt
setblock ~183 ~125 ~86 dirt
setblock ~183 ~125 ~87 dirt
setblock ~183 ~125 ~88 dirt
setblock ~183 ~125 ~89 dirt
setblock ~183 ~125 ~90 dirt
setblock ~183 ~125 ~91 dirt
setblock ~183 ~125 ~92 dirt
setblock ~183 ~125 ~93 dirt
setblock ~183 ~125 ~94 dirt
setblock ~183 ~125 ~95 grass_block
setblock ~183 ~125 ~96 grass_block
setblock ~183 ~125 ~97 grass_block
setblock ~183 ~125 ~100 short_grass
setblock ~183 ~125 ~101 fern
setblock ~183 ~125 ~102 short_grass
setblock ~183 ~125 ~103 fern
setblock ~183 ~125 ~105 short_grass
setblock ~183 ~125 ~132 short_grass
setblock ~183 ~125 ~138 short_grass
setblock ~183 ~125 ~146 short_grass
setblock ~183 ~125 ~153 short_grass
setblock ~183 ~125 ~154 short_grass
setblock ~183 ~125 ~155 short_grass
setblock ~183 ~125 ~157 short_grass
setblock ~183 ~125 ~158 grass_block
setblock ~183 ~125 ~159 grass_block
setblock ~183 ~125 ~160 grass_block
setblock ~183 ~125 ~161 grass_block
setblock ~183 ~125 ~162 grass_block
setblock ~183 ~125 ~165 short_grass
setblock ~183 ~125 ~166 short_grass
setblock ~183 ~125 ~167 short_grass
setblock ~183 ~125 ~171 short_grass
setblock ~183 ~125 ~174 grass_block
setblock ~183 ~125 ~175 grass_block
setblock ~183 ~125 ~176 grass_block
setblock ~183 ~125 ~177 grass_block
setblock ~183 ~125 ~178 dirt
setblock ~183 ~125 ~179 dirt
setblock ~183 ~125 ~180 dirt
setblock ~183 ~125 ~181 dirt
setblock ~183 ~125 ~182 dirt
setblock ~183 ~125 ~183 dirt
setblock ~183 ~125 ~184 dirt
setblock ~183 ~125 ~185 dirt
setblock ~183 ~125 ~186 dirt
setblock ~183 ~125 ~187 dirt
setblock ~183 ~125 ~188 dirt
setblock ~183 ~125 ~189 dirt
setblock ~183 ~125 ~190 dirt
setblock ~183 ~125 ~191 dirt
setblock ~183 ~125 ~192 dirt
setblock ~183 ~125 ~193 dirt
setblock ~183 ~125 ~194 grass_block
setblock ~183 ~125 ~195 grass_block
setblock ~183 ~125 ~197 poppy
setblock ~183 ~126 ~3 short_grass
setblock ~183 ~126 ~5 fern
setblock ~183 ~126 ~7 fern
setblock ~183 ~126 ~46 short_grass
setblock ~183 ~126 ~47 grass_block
setblock ~183 ~126 ~48 grass_block
setblock ~183 ~126 ~49 grass_block
setblock ~183 ~126 ~50 dirt
setblock ~183 ~126 ~51 dirt
setblock ~183 ~126 ~52 grass_block
setblock ~183 ~126 ~53 grass_block
setblock ~183 ~126 ~54 grass_block
setblock ~183 ~126 ~68 short_grass
setblock ~183 ~126 ~69 grass_block
setblock ~183 ~126 ~70 grass_block
setblock ~183 ~126 ~71 grass_block
setblock ~183 ~126 ~72 grass_block
setblock ~183 ~126 ~73 grass_block
setblock ~183 ~126 ~75 short_grass
setblock ~183 ~126 ~78 short_grass
setblock ~183 ~126 ~82 grass_block
setblock ~183 ~126 ~83 grass_block
setblock ~183 ~126 ~84 grass_block
setblock ~183 ~126 ~85 dirt
setblock ~183 ~126 ~86 dirt
setblock ~183 ~126 ~87 dirt
setblock ~183 ~126 ~88 dirt
setblock ~183 ~126 ~89 dirt
setblock ~183 ~126 ~90 dirt
setblock ~183 ~126 ~91 dirt
setblock ~183 ~126 ~92 dirt
setblock ~183 ~126 ~93 dirt
setblock ~183 ~126 ~94 grass_block
setblock ~183 ~126 ~158 short_grass
setblock ~183 ~126 ~162 short_grass
setblock ~183 ~126 ~176 short_grass
setblock ~183 ~126 ~177 short_grass
setblock ~183 ~126 ~178 grass_block
setblock ~183 ~126 ~179 grass_block
setblock ~183 ~126 ~180 grass_block
setblock ~183 ~126 ~181 grass_block
setblock ~183 ~126 ~182 grass_block
setblock ~183 ~126 ~183 grass_block
setblock ~183 ~126 ~184 grass_block
setblock ~183 ~126 ~185 grass_block
setblock ~183 ~126 ~186 grass_block
setblock ~183 ~126 ~187 dirt
setblock ~183 ~126 ~188 dirt
setblock ~183 ~126 ~189 dirt
setblock ~183 ~126 ~190 dirt
setblock ~183 ~126 ~191 grass_block
setblock ~183 ~126 ~192 grass_block
setblock ~183 ~126 ~193 grass_block
setblock ~183 ~126 ~194 poppy
setblock ~183 ~126 ~195 short_grass
setblock ~183 ~127 ~48 poppy
setblock ~183 ~127 ~49 short_grass
setblock ~183 ~127 ~50 grass_block
setblock ~183 ~127 ~51 grass_block
setblock ~183 ~127 ~52 short_grass
setblock ~183 ~127 ~69 short_grass
setblock ~183 ~127 ~72 short_grass
setblock ~183 ~127 ~82 short_grass
setblock ~183 ~127 ~83 short_grass
setblock ~183 ~127 ~85 grass_block
setblock ~183 ~127 ~86 grass_block
setblock ~183 ~127 ~87 grass_block
setblock ~183 ~127 ~88 dirt
setblock ~183 ~127 ~89 dirt
setblock ~183 ~127 ~90 dirt
setblock ~183 ~127 ~91 dirt
setblock ~183 ~127 ~92 grass_block
setblock ~183 ~127 ~93 grass_block
setblock ~183 ~127 ~181 short_grass
setblock ~183 ~127 ~184 short_grass
setblock ~183 ~127 ~185 short_grass
setblock ~183 ~127 ~186 short_grass
setblock ~183 ~127 ~187 grass_block
setblock ~183 ~127 ~188 grass_block
setblock ~183 ~127 ~189 grass_block
setblock ~183 ~127 ~190 grass_block
setblock ~183 ~127 ~191 short_grass
setblock ~183 ~127 ~192 short_grass
setblock ~183 ~128 ~86 short_grass
setblock ~183 ~128 ~87 fern
setblock ~183 ~128 ~88 grass_block
setblock ~183 ~128 ~89 grass_block
setblock ~183 ~128 ~90 dirt
setblock ~183 ~128 ~91 grass_block
setblock ~183 ~128 ~189 short_grass
setblock ~183 ~129 ~90 grass_block
setblock ~184 ~122 ~0 dirt
setblock ~184 ~122 ~1 dirt
setblock ~184 ~122 ~2 dirt
setblock ~184 ~122 ~3 dirt
setblock ~184 ~122 ~4 dirt
setblock ~184 ~122 ~5 dirt
setblock ~184 ~122 ~6 dirt
setblock ~184 ~122 ~7 dirt
setblock ~184 ~122 ~8 dirt
setblock ~184 ~122 ~9 dirt
setblock ~184 ~122 ~10 dirt
setblock ~184 ~122 ~11 dirt
setblock ~184 ~122 ~12 dirt
setblock ~184 ~122 ~13 dirt
setblock ~184 ~122 ~14 dirt
setblock ~184 ~122 ~15 dirt
setblock ~184 ~122 ~16 dirt
setblock ~184 ~122 ~17 dirt
setblock ~184 ~122 ~18 dirt
setblock ~184 ~122 ~19 dirt
setblock ~184 ~122 ~20 dirt
setblock ~184 ~122 ~21 dirt
setblock ~184 ~122 ~22 dirt
setblock ~184 ~122 ~23 dirt
setblock ~184 ~122 ~24 dirt
setblock ~184 ~122 ~25 dirt
setblock ~184 ~122 ~26 dirt
setblock ~184 ~122 ~27 dirt
setblock ~184 ~122 ~28 dirt
setblock ~184 ~122 ~29 dirt
setblock ~184 ~122 ~30 dirt
setblock ~184 ~122 ~31 dirt
setblock ~184 ~122 ~32 dirt
setblock ~184 ~122 ~33 dirt
setblock ~184 ~122 ~34 dirt
setblock ~184 ~122 ~35 dirt
setblock ~184 ~122 ~36 dirt
setblock ~184 ~122 ~37 dirt
setblock ~184 ~122 ~38 dirt
setblock ~184 ~122 ~39 dirt
setblock ~184 ~122 ~40 dirt
setblock ~184 ~122 ~41 dirt
setblock ~184 ~122 ~42 dirt
setblock ~184 ~122 ~43 dirt
setblock ~184 ~122 ~44 dirt
setblock ~184 ~122 ~45 dirt
setblock ~184 ~122 ~46 dirt
setblock ~184 ~122 ~47 dirt
setblock ~184 ~122 ~48 dirt
setblock ~184 ~122 ~49 dirt
setblock ~184 ~122 ~50 dirt
setblock ~184 ~122 ~51 dirt
setblock ~184 ~122 ~52 dirt
setblock ~184 ~122 ~53 dirt
setblock ~184 ~122 ~54 dirt
setblock ~184 ~122 ~55 dirt
setblock ~184 ~122 ~56 dirt
setblock ~184 ~122 ~57 dirt
setblock ~184 ~122 ~58 dirt
setblock ~184 ~122 ~59 dirt
setblock ~184 ~122 ~60 dirt
setblock ~184 ~122 ~61 dirt
setblock ~184 ~122 ~62 dirt
setblock ~184 ~122 ~63 dirt
setblock ~184 ~122 ~64 dirt
setblock ~184 ~122 ~65 dirt
setblock ~184 ~122 ~66 dirt
setblock ~184 ~122 ~67 dirt
setblock ~184 ~122 ~68 dirt
setblock ~184 ~122 ~69 dirt
setblock ~184 ~122 ~70 dirt
setblock ~184 ~122 ~71 dirt
setblock ~184 ~122 ~72 dirt
setblock ~184 ~122 ~73 dirt
setblock ~184 ~122 ~74 dirt
setblock ~184 ~122 ~75 dirt
setblock ~184 ~122 ~76 dirt
setblock ~184 ~122 ~77 dirt
setblock ~184 ~122 ~78 dirt
setblock ~184 ~122 ~79 dirt
setblock ~184 ~122 ~80 dirt
setblock ~184 ~122 ~81 dirt
setblock ~184 ~122 ~82 dirt
setblock ~184 ~122 ~83 dirt
setblock ~184 ~122 ~84 dirt
setblock ~184 ~122 ~85 dirt
setblock ~184 ~122 ~86 dirt
setblock ~184 ~122 ~87 dirt
setblock ~184 ~122 ~88 dirt
setblock ~184 ~122 ~89 dirt
setblock ~184 ~122 ~90 dirt
setblock ~184 ~122 ~91 dirt
setblock ~184 ~122 ~92 dirt
setblock ~184 ~122 ~93 dirt
setblock ~184 ~122 ~94 dirt
setblock ~184 ~122 ~95 dirt
setblock ~184 ~122 ~96 dirt
setblock ~184 ~122 ~97 dirt
setblock ~184 ~122 ~98 dirt
setblock ~184 ~122 ~99 dirt
setblock ~184 ~122 ~100 dirt
setblock ~184 ~122 ~101 dirt
setblock ~184 ~122 ~102 dirt
setblock ~184 ~122 ~103 dirt
setblock ~184 ~122 ~104 dirt
setblock ~184 ~122 ~105 dirt
setblock ~184 ~122 ~106 dirt
setblock ~184 ~122 ~107 dirt
setblock ~184 ~122 ~108 dirt
setblock ~184 ~122 ~109 dirt
setblock ~184 ~122 ~110 dirt
setblock ~184 ~122 ~111 dirt
setblock ~184 ~122 ~112 dirt
setblock ~184 ~122 ~113 dirt
setblock ~184 ~122 ~114 dirt
setblock ~184 ~122 ~115 dirt
setblock ~184 ~122 ~116 dirt
setblock ~184 ~122 ~117 dirt
setblock ~184 ~122 ~118 dirt
setblock ~184 ~122 ~119 dirt
setblock ~184 ~122 ~120 dirt
setblock ~184 ~122 ~121 dirt
setblock ~184 ~122 ~122 dirt
setblock ~184 ~122 ~123 dirt
setblock ~184 ~122 ~124 dirt
setblock ~184 ~122 ~125 dirt
setblock ~184 ~122 ~126 dirt
setblock ~184 ~122 ~127 dirt
setblock ~184 ~122 ~128 dirt
setblock ~184 ~122 ~129 dirt
setblock ~184 ~122 ~130 dirt
setblock ~184 ~122 ~131 dirt
setblock ~184 ~122 ~132 dirt
setblock ~184 ~122 ~133 dirt
setblock ~184 ~122 ~134 dirt
setblock ~184 ~122 ~135 dirt
setblock ~184 ~122 ~136 dirt
setblock ~184 ~122 ~137 dirt
setblock ~184 ~122 ~138 dirt
setblock ~184 ~122 ~139 dirt
setblock ~184 ~122 ~140 dirt
setblock ~184 ~122 ~141 dirt
setblock ~184 ~122 ~142 dirt
setblock ~184 ~122 ~143 dirt
setblock ~184 ~122 ~144 dirt
setblock ~184 ~122 ~145 dirt
setblock ~184 ~122 ~146 dirt
setblock ~184 ~122 ~147 dirt
setblock ~184 ~122 ~148 dirt
setblock ~184 ~122 ~149 dirt
setblock ~184 ~122 ~150 dirt
setblock ~184 ~122 ~151 dirt
setblock ~184 ~122 ~152 dirt
setblock ~184 ~122 ~153 dirt
setblock ~184 ~122 ~154 dirt
setblock ~184 ~122 ~155 dirt
setblock ~184 ~122 ~156 dirt
setblock ~184 ~122 ~157 dirt
setblock ~184 ~122 ~158 dirt
setblock ~184 ~122 ~159 dirt
setblock ~184 ~122 ~160 dirt
setblock ~184 ~122 ~161 dirt
setblock ~184 ~122 ~162 dirt
setblock ~184 ~122 ~163 dirt
setblock ~184 ~122 ~164 dirt
setblock ~184 ~122 ~165 dirt
setblock ~184 ~122 ~166 dirt
setblock ~184 ~122 ~167 dirt
setblock ~184 ~122 ~168 dirt
setblock ~184 ~122 ~169 dirt
setblock ~184 ~122 ~170 dirt
setblock ~184 ~122 ~171 dirt
setblock ~184 ~122 ~172 dirt
setblock ~184 ~122 ~173 dirt
setblock ~184 ~122 ~174 dirt
setblock ~184 ~122 ~175 dirt
setblock ~184 ~122 ~176 dirt
setblock ~184 ~122 ~177 dirt
setblock ~184 ~122 ~178 dirt
setblock ~184 ~122 ~179 dirt
setblock ~184 ~122 ~180 dirt
setblock ~184 ~122 ~181 dirt
setblock ~184 ~122 ~182 dirt
setblock ~184 ~122 ~183 dirt
setblock ~184 ~122 ~184 dirt
setblock ~184 ~122 ~185 dirt
setblock ~184 ~122 ~186 dirt
setblock ~184 ~122 ~187 dirt
setblock ~184 ~122 ~188 dirt
setblock ~184 ~122 ~189 dirt
setblock ~184 ~122 ~190 dirt
setblock ~184 ~122 ~191 dirt
setblock ~184 ~122 ~192 dirt
setblock ~184 ~122 ~193 dirt
setblock ~184 ~122 ~194 dirt
setblock ~184 ~122 ~195 dirt
setblock ~184 ~122 ~196 dirt
setblock ~184 ~122 ~197 dirt
setblock ~184 ~122 ~198 dirt
setblock ~184 ~122 ~199 dirt
setblock ~184 ~123 ~0 dirt
setblock ~184 ~123 ~1 dirt
setblock ~184 ~123 ~2 dirt
setblock ~184 ~123 ~3 dirt
setblock ~184 ~123 ~4 dirt
setblock ~184 ~123 ~5 dirt
setblock ~184 ~123 ~6 dirt
setblock ~184 ~123 ~7 dirt
setblock ~184 ~123 ~8 dirt
setblock ~184 ~123 ~9 dirt
setblock ~184 ~123 ~10 dirt
setblock ~184 ~123 ~11 dirt
setblock ~184 ~123 ~12 dirt
setblock ~184 ~123 ~13 dirt
setblock ~184 ~123 ~14 dirt
setblock ~184 ~123 ~15 dirt
setblock ~184 ~123 ~16 dirt
setblock ~184 ~123 ~17 dirt
setblock ~184 ~123 ~18 dirt
setblock ~184 ~123 ~19 dirt
setblock ~184 ~123 ~20 dirt
setblock ~184 ~123 ~21 dirt
setblock ~184 ~123 ~22 dirt
setblock ~184 ~123 ~23 dirt
setblock ~184 ~123 ~24 dirt
setblock ~184 ~123 ~25 dirt
setblock ~184 ~123 ~26 dirt
setblock ~184 ~123 ~27 dirt
setblock ~184 ~123 ~28 dirt
setblock ~184 ~123 ~29 dirt
setblock ~184 ~123 ~30 dirt
setblock ~184 ~123 ~31 dirt
setblock ~184 ~123 ~32 dirt
setblock ~184 ~123 ~33 dirt
setblock ~184 ~123 ~34 dirt
setblock ~184 ~123 ~35 dirt
setblock ~184 ~123 ~36 dirt
setblock ~184 ~123 ~37 dirt
setblock ~184 ~123 ~38 dirt
setblock ~184 ~123 ~39 dirt
setblock ~184 ~123 ~40 dirt
setblock ~184 ~123 ~41 dirt
setblock ~184 ~123 ~42 dirt
setblock ~184 ~123 ~43 dirt
setblock ~184 ~123 ~44 dirt
setblock ~184 ~123 ~45 dirt
setblock ~184 ~123 ~46 dirt
setblock ~184 ~123 ~47 dirt
setblock ~184 ~123 ~48 dirt
setblock ~184 ~123 ~49 dirt
setblock ~184 ~123 ~50 dirt
setblock ~184 ~123 ~51 dirt
setblock ~184 ~123 ~52 dirt
setblock ~184 ~123 ~53 dirt
setblock ~184 ~123 ~54 dirt
setblock ~184 ~123 ~55 dirt
setblock ~184 ~123 ~56 dirt
setblock ~184 ~123 ~57 dirt
setblock ~184 ~123 ~58 dirt
setblock ~184 ~123 ~59 dirt
setblock ~184 ~123 ~60 grass_block
setblock ~184 ~123 ~61 grass_block
setblock ~184 ~123 ~62 dirt
setblock ~184 ~123 ~63 dirt
setblock ~184 ~123 ~64 dirt
setblock ~184 ~123 ~65 dirt
setblock ~184 ~123 ~66 dirt
setblock ~184 ~123 ~67 dirt
setblock ~184 ~123 ~68 dirt
setblock ~184 ~123 ~69 dirt
setblock ~184 ~123 ~70 dirt
setblock ~184 ~123 ~71 dirt
setblock ~184 ~123 ~72 dirt
setblock ~184 ~123 ~73 dirt
setblock ~184 ~123 ~74 dirt
setblock ~184 ~123 ~75 dirt
setblock ~184 ~123 ~76 dirt
setblock ~184 ~123 ~77 dirt
setblock ~184 ~123 ~78 dirt
setblock ~184 ~123 ~79 dirt
setblock ~184 ~123 ~80 dirt
setblock ~184 ~123 ~81 dirt
setblock ~184 ~123 ~82 dirt
setblock ~184 ~123 ~83 dirt
setblock ~184 ~123 ~84 dirt
setblock ~184 ~123 ~85 dirt
setblock ~184 ~123 ~86 dirt
setblock ~184 ~123 ~87 dirt
setblock ~184 ~123 ~88 dirt
setblock ~184 ~123 ~89 dirt
setblock ~184 ~123 ~90 dirt
setblock ~184 ~123 ~91 dirt
setblock ~184 ~123 ~92 dirt
setblock ~184 ~123 ~93 dirt
setblock ~184 ~123 ~94 dirt
setblock ~184 ~123 ~95 dirt
setblock ~184 ~123 ~96 dirt
setblock ~184 ~123 ~97 dirt
setblock ~184 ~123 ~98 dirt
setblock ~184 ~123 ~99 dirt
setblock ~184 ~123 ~100 dirt
setblock ~184 ~123 ~101 dirt
setblock ~184 ~123 ~102 dirt
setblock ~184 ~123 ~103 dirt
setblock ~184 ~123 ~104 dirt
setblock ~184 ~123 ~105 grass_block
setblock ~184 ~123 ~106 grass_block
setblock ~184 ~123 ~107 grass_block
setblock ~184 ~123 ~108 grass_block
setblock ~184 ~123 ~109 grass_block
setblock ~184 ~123 ~110 grass_block
setblock ~184 ~123 ~111 grass_block
setblock ~184 ~123 ~112 grass_block
setblock ~184 ~123 ~113 dirt
setblock ~184 ~123 ~114 dirt
setblock ~184 ~123 ~115 dirt
setblock ~184 ~123 ~116 grass_block
setblock ~184 ~123 ~117 grass_block
setblock ~184 ~123 ~118 grass_block
setblock ~184 ~123 ~119 grass_block
setblock ~184 ~123 ~120 grass_block
setblock ~184 ~123 ~121 grass_block
setblock ~184 ~123 ~122 grass_block
setblock ~184 ~123 ~123 grass_block
setblock ~184 ~123 ~124 grass_block
setblock ~184 ~123 ~125 dirt
setblock ~184 ~123 ~126 dirt
setblock ~184 ~123 ~127 dirt
setblock ~184 ~123 ~128 dirt
setblock ~184 ~123 ~129 dirt
setblock ~184 ~123 ~130 dirt
setblock ~184 ~123 ~131 dirt
setblock ~184 ~123 ~132 dirt
setblock ~184 ~123 ~133 dirt
setblock ~184 ~123 ~134 dirt
setblock ~184 ~123 ~135 dirt
setblock ~184 ~123 ~136 dirt
setblock ~184 ~123 ~137 dirt
setblock ~184 ~123 ~138 dirt
setblock ~184 ~123 ~139 dirt
setblock ~184 ~123 ~140 dirt
setblock ~184 ~123 ~141 dirt
setblock ~184 ~123 ~142 dirt
setblock ~184 ~123 ~143 dirt
setblock ~184 ~123 ~144 dirt
setblock ~184 ~123 ~145 dirt
setblock ~184 ~123 ~146 dirt
setblock ~184 ~123 ~147 dirt
setblock ~184 ~123 ~148 dirt
setblock ~184 ~123 ~149 dirt
setblock ~184 ~123 ~150 dirt
setblock ~184 ~123 ~151 dirt
setblock ~184 ~123 ~152 dirt
setblock ~184 ~123 ~153 dirt
setblock ~184 ~123 ~154 dirt
setblock ~184 ~123 ~155 dirt
setblock ~184 ~123 ~156 dirt
setblock ~184 ~123 ~157 dirt
setblock ~184 ~123 ~158 dirt
setblock ~184 ~123 ~159 dirt
setblock ~184 ~123 ~160 dirt
setblock ~184 ~123 ~161 dirt
setblock ~184 ~123 ~162 dirt
setblock ~184 ~123 ~163 dirt
setblock ~184 ~123 ~164 dirt
setblock ~184 ~123 ~165 dirt
setblock ~184 ~123 ~166 dirt
setblock ~184 ~123 ~167 dirt
setblock ~184 ~123 ~168 dirt
setblock ~184 ~123 ~169 dirt
setblock ~184 ~123 ~170 grass_block
setblock ~184 ~123 ~171 dirt
setblock ~184 ~123 ~172 dirt
setblock ~184 ~123 ~173 dirt
setblock ~184 ~123 ~174 dirt
setblock ~184 ~123 ~175 dirt
setblock ~184 ~123 ~176 dirt
setblock ~184 ~123 ~177 dirt
setblock ~184 ~123 ~178 dirt
setblock ~184 ~123 ~179 dirt
setblock ~184 ~123 ~180 dirt
setblock ~184 ~123 ~181 dirt
setblock ~184 ~123 ~182 dirt
setblock ~184 ~123 ~183 dirt
setblock ~184 ~123 ~184 dirt
setblock ~184 ~123 ~185 dirt
setblock ~184 ~123 ~186 dirt
setblock ~184 ~123 ~187 dirt
setblock ~184 ~123 ~188 dirt
setblock ~184 ~123 ~189 dirt
setblock ~184 ~123 ~190 dirt
setblock ~184 ~123 ~191 dirt
setblock ~184 ~123 ~192 dirt
setblock ~184 ~123 ~193 dirt
setblock ~184 ~123 ~194 dirt
setblock ~184 ~123 ~195 dirt
setblock ~184 ~123 ~196 dirt
setblock ~184 ~123 ~197 dirt
setblock ~184 ~123 ~198 dirt
setblock ~184 ~123 ~199 dirt
setblock ~184 ~124 ~0 dirt
setblock ~184 ~124 ~1 dirt
setblock ~184 ~124 ~2 dirt
setblock ~184 ~124 ~3 dirt
setblock ~184 ~124 ~4 dirt
setblock ~184 ~124 ~5 dirt
setblock ~184 ~124 ~6 dirt
setblock ~184 ~124 ~7 dirt
setblock ~184 ~124 ~8 dirt
setblock ~184 ~124 ~9 dirt
setblock ~184 ~124 ~10 grass_block
setblock ~184 ~124 ~11 grass_block
setblock ~184 ~124 ~12 grass_block
setblock ~184 ~124 ~13 grass_block
setblock ~184 ~124 ~14 grass_block
setblock ~184 ~124 ~15 grass_block
setblock ~184 ~124 ~16 grass_block
setblock ~184 ~124 ~17 grass_block
setblock ~184 ~124 ~18 grass_block
setblock ~184 ~124 ~19 grass_block
setblock ~184 ~124 ~20 grass_block
setblock ~184 ~124 ~21 grass_block
setblock ~184 ~124 ~22 grass_block
setblock ~184 ~124 ~23 grass_block
setblock ~184 ~124 ~24 grass_block
setblock ~184 ~124 ~25 grass_block
setblock ~184 ~124 ~26 grass_block
setblock ~184 ~124 ~27 grass_block
setblock ~184 ~124 ~28 grass_block
setblock ~184 ~124 ~29 grass_block
setblock ~184 ~124 ~30 grass_block
setblock ~184 ~124 ~31 grass_block
setblock ~184 ~124 ~32 grass_block
setblock ~184 ~124 ~33 grass_block
setblock ~184 ~124 ~34 grass_block
setblock ~184 ~124 ~35 grass_block
setblock ~184 ~124 ~36 grass_block
setblock ~184 ~124 ~37 grass_block
setblock ~184 ~124 ~38 grass_block
setblock ~184 ~124 ~39 grass_block
setblock ~184 ~124 ~40 grass_block
setblock ~184 ~124 ~41 grass_block
setblock ~184 ~124 ~42 dirt
setblock ~184 ~124 ~43 dirt
setblock ~184 ~124 ~44 dirt
setblock ~184 ~124 ~45 dirt
setblock ~184 ~124 ~46 dirt
setblock ~184 ~124 ~47 dirt
setblock ~184 ~124 ~48 dirt
setblock ~184 ~124 ~49 dirt
setblock ~184 ~124 ~50 dirt
setblock ~184 ~124 ~51 dirt
setblock ~184 ~124 ~52 dirt
setblock ~184 ~124 ~53 dirt
setblock ~184 ~124 ~54 dirt
setblock ~184 ~124 ~55 dirt
setblock ~184 ~124 ~56 dirt
setblock ~184 ~124 ~57 dirt
setblock ~184 ~124 ~58 grass_block
setblock ~184 ~124 ~59 grass_block
setblock ~184 ~124 ~61 short_grass
setblock ~184 ~124 ~62 grass_block
setblock ~184 ~124 ~63 grass_block
setblock ~184 ~124 ~64 grass_block
setblock ~184 ~124 ~65 grass_block
setblock ~184 ~124 ~66 grass_block
setblock ~184 ~124 ~67 dirt
setblock ~184 ~124 ~68 dirt
setblock ~184 ~124 ~69 dirt
setblock ~184 ~124 ~70 dirt
setblock ~184 ~124 ~71 dirt
setblock ~184 ~124 ~72 dirt
setblock ~184 ~124 ~73 dirt
setblock ~184 ~124 ~74 dirt
setblock ~184 ~124 ~75 dirt
setblock ~184 ~124 ~76 dirt
setblock ~184 ~124 ~77 dirt
setblock ~184 ~124 ~78 dirt
setblock ~184 ~124 ~79 dirt
setblock ~184 ~124 ~80 dirt
setblock ~184 ~124 ~81 dirt
setblock ~184 ~124 ~82 dirt
setblock ~184 ~124 ~83 dirt
setblock ~184 ~124 ~84 dirt
setblock ~184 ~124 ~85 dirt
setblock ~184 ~124 ~86 dirt
setblock ~184 ~124 ~87 dirt
setblock ~184 ~124 ~88 dirt
setblock ~184 ~124 ~89 dirt
setblock ~184 ~124 ~90 dirt
setblock ~184 ~124 ~91 dirt
setblock ~184 ~124 ~92 dirt
setblock ~184 ~124 ~93 dirt
setblock ~184 ~124 ~94 dirt
setblock ~184 ~124 ~95 dirt
setblock ~184 ~124 ~96 dirt
setblock ~184 ~124 ~97 dirt
setblock ~184 ~124 ~98 grass_block
setblock ~184 ~124 ~99 grass_block
setblock ~184 ~124 ~100 grass_block
setblock ~184 ~124 ~101 grass_block
setblock ~184 ~124 ~102 grass_block
setblock ~184 ~124 ~103 grass_block
setblock ~184 ~124 ~104 grass_block
setblock ~184 ~124 ~109 short_grass
setblock ~184 ~124 ~112 short_grass
setblock ~184 ~124 ~113 grass_block
setblock ~184 ~124 ~114 grass_block
setblock ~184 ~124 ~115 grass_block
setblock ~184 ~124 ~117 short_grass
setblock ~184 ~124 ~121 short_grass
setblock ~184 ~124 ~122 short_grass
setblock ~184 ~124 ~125 grass_block
setblock ~184 ~124 ~126 grass_block
setblock ~184 ~124 ~127 grass_block
setblock ~184 ~124 ~128 grass_block
setblock ~184 ~124 ~129 grass_block
setblock ~184 ~124 ~130 grass_block
setblock ~184 ~124 ~131 grass_block
setblock ~184 ~124 ~132 grass_block
setblock ~184 ~124 ~133 grass_block
setblock ~184 ~124 ~134 grass_block
setblock ~184 ~124 ~135 grass_block
setblock ~184 ~124 ~136 grass_block
setblock ~184 ~124 ~137 grass_block
setblock ~184 ~124 ~138 grass_block
setblock ~184 ~124 ~139 grass_block
setblock ~184 ~124 ~140 grass_block
setblock ~184 ~124 ~141 grass_block
setblock ~184 ~124 ~142 grass_block
setblock ~184 ~124 ~143 grass_block
setblock ~184 ~124 ~144 grass_block
setblock ~184 ~124 ~145 grass_block
setblock ~184 ~124 ~146 grass_block
setblock ~184 ~124 ~147 grass_block
setblock ~184 ~124 ~148 grass_block
setblock ~184 ~124 ~149 grass_block
setblock ~184 ~124 ~150 grass_block
setblock ~184 ~124 ~151 grass_block
setblock ~184 ~124 ~152 grass_block
setblock ~184 ~124 ~153 grass_block
setblock ~184 ~124 ~154 grass_block
setblock ~184 ~124 ~155 grass_block
setblock ~184 ~124 ~156 grass_block
setblock ~184 ~124 ~157 grass_block
setblock ~184 ~124 ~158 grass_block
setblock ~184 ~124 ~159 dirt
setblock ~184 ~124 ~160 dirt
setblock ~184 ~124 ~161 grass_block
setblock ~184 ~124 ~162 grass_block
setblock ~184 ~124 ~163 grass_block
setblock ~184 ~124 ~164 grass_block
setblock ~184 ~124 ~165 grass_block
setblock ~184 ~124 ~166 grass_block
setblock ~184 ~124 ~167 grass_block
setblock ~184 ~124 ~168 grass_block
setblock ~184 ~124 ~169 grass_block
setblock ~184 ~124 ~171 grass_block
setblock ~184 ~124 ~172 grass_block
setblock ~184 ~124 ~173 dirt
setblock ~184 ~124 ~174 dirt
setblock ~184 ~124 ~175 dirt
setblock ~184 ~124 ~176 dirt
setblock ~184 ~124 ~177 dirt
setblock ~184 ~124 ~178 dirt
setblock ~184 ~124 ~179 dirt
setblock ~184 ~124 ~180 dirt
setblock ~184 ~124 ~181 dirt
setblock ~184 ~124 ~182 dirt
setblock ~184 ~124 ~183 dirt
setblock ~184 ~124 ~184 dirt
setblock ~184 ~124 ~185 dirt
setblock ~184 ~124 ~186 dirt
setblock ~184 ~124 ~187 dirt
setblock ~184 ~124 ~188 dirt
setblock ~184 ~124 ~189 dirt
setblock ~184 ~124 ~190 dirt
setblock ~184 ~124 ~191 dirt
setblock ~184 ~124 ~192 dirt
setblock ~184 ~124 ~193 dirt
setblock ~184 ~124 ~194 dirt
setblock ~184 ~124 ~195 dirt
setblock ~184 ~124 ~196 dirt
setblock ~184 ~124 ~197 grass_block
setblock ~184 ~124 ~198 grass_block
setblock ~184 ~124 ~199 grass_block
setblock ~184 ~125 ~0 grass_block
setblock ~184 ~125 ~1 grass_block
setblock ~184 ~125 ~2 grass_block
setblock ~184 ~125 ~3 grass_block
setblock ~184 ~125 ~4 grass_block
setblock ~184 ~125 ~5 grass_block
setblock ~184 ~125 ~6 grass_block
setblock ~184 ~125 ~7 grass_block
setblock ~184 ~125 ~8 grass_block
setblock ~184 ~125 ~9 grass_block
setblock ~184 ~125 ~10 short_grass
setblock ~184 ~125 ~11 short_grass
setblock ~184 ~125 ~18 short_grass
setblock ~184 ~125 ~23 short_grass
setblock ~184 ~125 ~28 short_grass
setblock ~184 ~125 ~30 poppy
setblock ~184 ~125 ~32 short_grass
setblock ~184 ~125 ~35 short_grass
setblock ~184 ~125 ~36 short_grass
setblock ~184 ~125 ~40 short_grass
setblock ~184 ~125 ~42 grass_block
setblock ~184 ~125 ~43 grass_block
setblock ~184 ~125 ~44 grass_block
setblock ~184 ~125 ~45 dirt
setblock ~184 ~125 ~46 dirt
setblock ~184 ~125 ~47 dirt
setblock ~184 ~125 ~48 dirt
setblock ~184 ~125 ~49 dirt
setblock ~184 ~125 ~50 dirt
setblock ~184 ~125 ~51 dirt
setblock ~184 ~125 ~52 dirt
setblock ~184 ~125 ~53 dirt
setblock ~184 ~125 ~54 dirt
setblock ~184 ~125 ~55 dirt
setblock ~184 ~125 ~56 grass_block
setblock ~184 ~125 ~57 grass_block
setblock ~184 ~125 ~62 fern
setblock ~184 ~125 ~65 short_grass
setblock ~184 ~125 ~67 grass_block
setblock ~184 ~125 ~68 grass_block
setblock ~184 ~125 ~69 grass_block
setblock ~184 ~125 ~70 grass_block
setblock ~184 ~125 ~71 grass_block
setblock ~184 ~125 ~72 grass_block
setblock ~184 ~125 ~73 grass_block
setblock ~184 ~125 ~74 grass_block
setblock ~184 ~125 ~75 grass_block
setblock ~184 ~125 ~76 grass_block
setblock ~184 ~125 ~77 grass_block
setblock ~184 ~125 ~78 grass_block
setblock ~184 ~125 ~79 grass_block
setblock ~184 ~125 ~80 grass_block
setblock ~184 ~125 ~81 grass_block
setblock ~184 ~125 ~82 grass_block
setblock ~184 ~125 ~83 dirt
setblock ~184 ~125 ~84 dirt
setblock ~184 ~125 ~85 dirt
setblock ~184 ~125 ~86 dirt
setblock ~184 ~125 ~87 dirt
setblock ~184 ~125 ~88 dirt
setblock ~184 ~125 ~89 dirt
setblock ~184 ~125 ~90 dirt
setblock ~184 ~125 ~91 dirt
setblock ~184 ~125 ~92 dirt
setblock ~184 ~125 ~93 dirt
setblock ~184 ~125 ~94 dirt
setblock ~184 ~125 ~95 grass_block
setblock ~184 ~125 ~96 grass_block
setblock ~184 ~125 ~97 grass_block
setblock ~184 ~125 ~100 short_grass
setblock ~184 ~125 ~103 short_grass
setblock ~184 ~125 ~113 short_grass
setblock ~184 ~125 ~114 short_grass
setblock ~184 ~125 ~115 fern
setblock ~184 ~125 ~125 short_grass
setblock ~184 ~125 ~128 short_grass
setblock ~184 ~125 ~129 poppy
setblock ~184 ~125 ~133 short_grass
setblock ~184 ~125 ~134 short_grass
setblock ~184 ~125 ~136 fern
setblock ~184 ~125 ~138 short_grass
setblock ~184 ~125 ~141 fern
setblock ~184 ~125 ~142 fern
setblock ~184 ~125 ~146 short_grass
setblock ~184 ~125 ~150 fern
setblock ~184 ~125 ~152 short_grass
setblock ~184 ~125 ~155 short_grass
setblock ~184 ~125 ~159 grass_block
setblock ~184 ~125 ~160 grass_block
setblock ~184 ~125 ~168 short_grass
setblock ~184 ~125 ~171 short_grass
setblock ~184 ~125 ~173 grass_block
setblock ~184 ~125 ~174 grass_block
setblock ~184 ~125 ~175 grass_block
setblock ~184 ~125 ~176 grass_block
setblock ~184 ~125 ~177 dirt
setblock ~184 ~125 ~178 dirt
setblock ~184 ~125 ~179 dirt
setblock ~184 ~125 ~180 dirt
setblock ~184 ~125 ~181 dirt
setblock ~184 ~125 ~182 dirt
setblock ~184 ~125 ~183 dirt
setblock ~184 ~125 ~184 dirt
setblock ~184 ~125 ~185 dirt
setblock ~184 ~125 ~186 dirt
setblock ~184 ~125 ~187 dirt
setblock ~184 ~125 ~188 dirt
setblock ~184 ~125 ~189 dirt
setblock ~184 ~125 ~190 dirt
setblock ~184 ~125 ~191 dirt
setblock ~184 ~125 ~192 dirt
setblock ~184 ~125 ~193 dirt
setblock ~184 ~125 ~194 grass_block
setblock ~184 ~125 ~195 grass_block
setblock ~184 ~125 ~196 grass_block
setblock ~184 ~125 ~199 fern
setblock ~184 ~126 ~0 poppy
setblock ~184 ~126 ~3 short_grass
setblock ~184 ~126 ~4 short_grass
setblock ~184 ~126 ~45 grass_block
setblock ~184 ~126 ~46 grass_block
setblock ~184 ~126 ~47 grass_block
setblock ~184 ~126 ~48 grass_block
setblock ~184 ~126 ~49 grass_block
setblock ~184 ~126 ~50 dirt
setblock ~184 ~126 ~51 grass_block
setblock ~184 ~126 ~52 grass_block
setblock ~184 ~126 ~53 grass_block
setblock ~184 ~126 ~54 grass_block
setblock ~184 ~126 ~55 grass_block
setblock ~184 ~126 ~68 short_grass
setblock ~184 ~126 ~69 short_grass
setblock ~184 ~126 ~71 short_grass
setblock ~184 ~126 ~72 short_grass
setblock ~184 ~126 ~75 short_grass
setblock ~184 ~126 ~79 short_grass
setblock ~184 ~126 ~80 short_grass
setblock ~184 ~126 ~81 short_grass
setblock ~184 ~126 ~82 short_grass
setblock ~184 ~126 ~83 grass_block
setblock ~184 ~126 ~84 grass_block
setblock ~184 ~126 ~85 grass_block
setblock ~184 ~126 ~86 dirt
setblock ~184 ~126 ~87 dirt
setblock ~184 ~126 ~88 dirt
setblock ~184 ~126 ~89 dirt
setblock ~184 ~126 ~90 dirt
setblock ~184 ~126 ~91 dirt
setblock ~184 ~126 ~92 dirt
setblock ~184 ~126 ~93 grass_block
setblock ~184 ~126 ~94 grass_block
setblock ~184 ~126 ~159 short_grass
setblock ~184 ~126 ~173 short_grass
setblock ~184 ~126 ~176 fern
setblock ~184 ~126 ~177 grass_block
setblock ~184 ~126 ~178 grass_block
setblock ~184 ~126 ~179 grass_block
setblock ~184 ~126 ~180 grass_block
setblock ~184 ~126 ~181 grass_block
setblock ~184 ~126 ~182 grass_block
setblock ~184 ~126 ~183 grass_block
setblock ~184 ~126 ~184 grass_block
setblock ~184 ~126 ~185 grass_block
setblock ~184 ~126 ~186 grass_block
setblock ~184 ~126 ~187 grass_block
setblock ~184 ~126 ~188 grass_block
setblock ~184 ~126 ~189 grass_block
setblock ~184 ~126 ~190 grass_block
setblock ~184 ~126 ~191 grass_block
setblock ~184 ~126 ~192 grass_block
setblock ~184 ~126 ~193 grass_block
setblock ~184 ~127 ~45 short_grass
setblock ~184 ~127 ~49 fern
setblock ~184 ~127 ~50 grass_block
setblock ~184 ~127 ~52 short_grass
setblock ~184 ~127 ~83 poppy
setblock ~184 ~127 ~84 short_grass
setblock ~184 ~127 ~86 grass_block
setblock ~184 ~127 ~87 grass_block
setblock ~184 ~127 ~88 grass_block
setblock ~184 ~127 ~89 dirt
setblock ~184 ~127 ~90 dirt
setblock ~184 ~127 ~91 dirt
setblock ~184 ~127 ~92 grass_block
setblock ~184 ~127 ~179 short_grass
setblock ~184 ~127 ~186 fern
setblock ~184 ~127 ~187 poppy
setblock ~184 ~127 ~191 short_grass
setblock ~184 ~127 ~192 short_grass
setblock ~184 ~128 ~50 short_grass
setblock ~184 ~128 ~89 grass_block
setblock ~184 ~128 ~90 grass_block
setblock ~184 ~128 ~91 grass_block
setblock ~184 ~129 ~91 short_grass
setblock ~185 ~122 ~0 dirt
setblock ~185 ~122 ~1 dirt
setblock ~185 ~122 ~2 dirt
setblock ~185 ~122 ~3 dirt
setblock ~185 ~122 ~4 dirt
setblock ~185 ~122 ~5 dirt
setblock ~185 ~122 ~6 dirt
setblock ~185 ~122 ~7 dirt
setblock ~185 ~122 ~8 dirt
setblock ~185 ~122 ~9 dirt
setblock ~185 ~122 ~10 dirt
setblock ~185 ~122 ~11 dirt
setblock ~185 ~122 ~12 dirt
setblock ~185 ~122 ~13 dirt
setblock ~185 ~122 ~14 dirt
setblock ~185 ~122 ~15 dirt
setblock ~185 ~122 ~16 dirt
setblock ~185 ~122 ~17 dirt
setblock ~185 ~122 ~18 dirt
setblock ~185 ~122 ~19 dirt
setblock ~185 ~122 ~20 dirt
setblock ~185 ~122 ~21 dirt
setblock ~185 ~122 ~22 dirt
setblock ~185 ~122 ~23 dirt
setblock ~185 ~122 ~24 dirt
setblock ~185 ~122 ~25 dirt
setblock ~185 ~122 ~26 dirt
setblock ~185 ~122 ~27 dirt
setblock ~185 ~122 ~28 dirt
setblock ~185 ~122 ~29 dirt
setblock ~185 ~122 ~30 dirt
setblock ~185 ~122 ~31 dirt
setblock ~185 ~122 ~32 dirt
setblock ~185 ~122 ~33 dirt
setblock ~185 ~122 ~34 dirt
setblock ~185 ~122 ~35 dirt
setblock ~185 ~122 ~36 dirt
setblock ~185 ~122 ~37 dirt
setblock ~185 ~122 ~38 dirt
setblock ~185 ~122 ~39 dirt
setblock ~185 ~122 ~40 dirt
setblock ~185 ~122 ~41 dirt
setblock ~185 ~122 ~42 dirt
setblock ~185 ~122 ~43 dirt
setblock ~185 ~122 ~44 dirt
setblock ~185 ~122 ~45 dirt
setblock ~185 ~122 ~46 dirt
setblock ~185 ~122 ~47 dirt
setblock ~185 ~122 ~48 dirt
setblock ~185 ~122 ~49 dirt
setblock ~185 ~122 ~50 dirt
setblock ~185 ~122 ~51 dirt
setblock ~185 ~122 ~52 dirt
setblock ~185 ~122 ~53 dirt
setblock ~185 ~122 ~54 dirt
setblock ~185 ~122 ~55 dirt
setblock ~185 ~122 ~56 dirt
setblock ~185 ~122 ~57 dirt
setblock ~185 ~122 ~58 dirt
setblock ~185 ~122 ~59 dirt
setblock ~185 ~122 ~60 dirt
setblock ~185 ~122 ~61 dirt
setblock ~185 ~122 ~62 dirt
setblock ~185 ~122 ~63 dirt
setblock ~185 ~122 ~64 dirt
setblock ~185 ~122 ~65 dirt
setblock ~185 ~122 ~66 dirt
setblock ~185 ~122 ~67 dirt
setblock ~185 ~122 ~68 dirt
setblock ~185 ~122 ~69 dirt
setblock ~185 ~122 ~70 dirt
setblock ~185 ~122 ~71 dirt
setblock ~185 ~122 ~72 dirt
setblock ~185 ~122 ~73 dirt
setblock ~185 ~122 ~74 dirt
setblock ~185 ~122 ~75 dirt
setblock ~185 ~122 ~76 dirt
setblock ~185 ~122 ~77 dirt
setblock ~185 ~122 ~78 dirt
setblock ~185 ~122 ~79 dirt
setblock ~185 ~122 ~80 dirt
setblock ~185 ~122 ~81 dirt
setblock ~185 ~122 ~82 dirt
setblock ~185 ~122 ~83 dirt
setblock ~185 ~122 ~84 dirt
setblock ~185 ~122 ~85 dirt
setblock ~185 ~122 ~86 dirt
setblock ~185 ~122 ~87 dirt
setblock ~185 ~122 ~88 dirt
setblock ~185 ~122 ~89 dirt
setblock ~185 ~122 ~90 dirt
setblock ~185 ~122 ~91 dirt
setblock ~185 ~122 ~92 dirt
setblock ~185 ~122 ~93 dirt
setblock ~185 ~122 ~94 dirt
setblock ~185 ~122 ~95 dirt
setblock ~185 ~122 ~96 dirt
setblock ~185 ~122 ~97 dirt
setblock ~185 ~122 ~98 dirt
setblock ~185 ~122 ~99 dirt
setblock ~185 ~122 ~100 dirt
setblock ~185 ~122 ~101 dirt
setblock ~185 ~122 ~102 dirt
setblock ~185 ~122 ~103 dirt
setblock ~185 ~122 ~104 dirt
setblock ~185 ~122 ~105 dirt
setblock ~185 ~122 ~106 dirt
setblock ~185 ~122 ~107 dirt
setblock ~185 ~122 ~108 dirt
setblock ~185 ~122 ~109 dirt
setblock ~185 ~122 ~110 dirt
setblock ~185 ~122 ~111 dirt
setblock ~185 ~122 ~112 dirt
setblock ~185 ~122 ~113 dirt
setblock ~185 ~122 ~114 dirt
setblock ~185 ~122 ~115 dirt
setblock ~185 ~122 ~116 dirt
setblock ~185 ~122 ~117 dirt
setblock ~185 ~122 ~118 dirt
setblock ~185 ~122 ~119 dirt
setblock ~185 ~122 ~120 dirt
setblock ~185 ~122 ~121 dirt
setblock ~185 ~122 ~122 dirt
setblock ~185 ~122 ~123 dirt
setblock ~185 ~122 ~124 dirt
setblock ~185 ~122 ~125 dirt
setblock ~185 ~122 ~126 dirt
setblock ~185 ~122 ~127 dirt
setblock ~185 ~122 ~128 dirt
setblock ~185 ~122 ~129 dirt
setblock ~185 ~122 ~130 dirt
setblock ~185 ~122 ~131 dirt
setblock ~185 ~122 ~132 dirt
setblock ~185 ~122 ~133 dirt
setblock ~185 ~122 ~134 dirt
setblock ~185 ~122 ~135 dirt
setblock ~185 ~122 ~136 dirt
setblock ~185 ~122 ~137 dirt
setblock ~185 ~122 ~138 dirt
setblock ~185 ~122 ~139 dirt
setblock ~185 ~122 ~140 dirt
setblock ~185 ~122 ~141 dirt
setblock ~185 ~122 ~142 dirt
setblock ~185 ~122 ~143 dirt
setblock ~185 ~122 ~144 dirt
setblock ~185 ~122 ~145 dirt
setblock ~185 ~122 ~146 dirt
setblock ~185 ~122 ~147 dirt
setblock ~185 ~122 ~148 dirt
setblock ~185 ~122 ~149 dirt
setblock ~185 ~122 ~150 dirt
setblock ~185 ~122 ~151 dirt
setblock ~185 ~122 ~152 dirt
setblock ~185 ~122 ~153 dirt
setblock ~185 ~122 ~154 dirt
setblock ~185 ~122 ~155 dirt
setblock ~185 ~122 ~156 dirt
setblock ~185 ~122 ~157 dirt
setblock ~185 ~122 ~158 dirt
setblock ~185 ~122 ~159 dirt
setblock ~185 ~122 ~160 dirt
setblock ~185 ~122 ~161 dirt
setblock ~185 ~122 ~162 dirt
setblock ~185 ~122 ~163 dirt
setblock ~185 ~122 ~164 dirt
setblock ~185 ~122 ~165 dirt
setblock ~185 ~122 ~166 dirt
setblock ~185 ~122 ~167 dirt
setblock ~185 ~122 ~168 dirt
setblock ~185 ~122 ~169 dirt
setblock ~185 ~122 ~170 dirt
setblock ~185 ~122 ~171 dirt
setblock ~185 ~122 ~172 dirt
setblock ~185 ~122 ~173 dirt
setblock ~185 ~122 ~174 dirt
setblock ~185 ~122 ~175 dirt
setblock ~185 ~122 ~176 dirt
setblock ~185 ~122 ~177 dirt
setblock ~185 ~122 ~178 dirt
setblock ~185 ~122 ~179 dirt
setblock ~185 ~122 ~180 dirt
setblock ~185 ~122 ~181 dirt
setblock ~185 ~122 ~182 dirt
setblock ~185 ~122 ~183 dirt
setblock ~185 ~122 ~184 dirt
setblock ~185 ~122 ~185 dirt
setblock ~185 ~122 ~186 dirt
setblock ~185 ~122 ~187 dirt
setblock ~185 ~122 ~188 dirt
setblock ~185 ~122 ~189 dirt
setblock ~185 ~122 ~190 dirt
setblock ~185 ~122 ~191 dirt
setblock ~185 ~122 ~192 dirt
setblock ~185 ~122 ~193 dirt
setblock ~185 ~122 ~194 dirt
setblock ~185 ~122 ~195 dirt
setblock ~185 ~122 ~196 dirt
setblock ~185 ~122 ~197 dirt
setblock ~185 ~122 ~198 dirt
setblock ~185 ~122 ~199 dirt
setblock ~185 ~123 ~0 dirt
setblock ~185 ~123 ~1 dirt
setblock ~185 ~123 ~2 dirt
setblock ~185 ~123 ~3 dirt
setblock ~185 ~123 ~4 dirt
setblock ~185 ~123 ~5 dirt
setblock ~185 ~123 ~6 dirt
setblock ~185 ~123 ~7 dirt
setblock ~185 ~123 ~8 dirt
setblock ~185 ~123 ~9 dirt
setblock ~185 ~123 ~10 dirt
setblock ~185 ~123 ~11 dirt
setblock ~185 ~123 ~12 dirt
setblock ~185 ~123 ~13 dirt
setblock ~185 ~123 ~14 dirt
setblock ~185 ~123 ~15 dirt
setblock ~185 ~123 ~16 dirt
setblock ~185 ~123 ~17 dirt
setblock ~185 ~123 ~18 dirt
setblock ~185 ~123 ~19 dirt
setblock ~185 ~123 ~20 dirt
setblock ~185 ~123 ~21 dirt
setblock ~185 ~123 ~22 dirt
setblock ~185 ~123 ~23 dirt
setblock ~185 ~123 ~24 dirt
setblock ~185 ~123 ~25 dirt
setblock ~185 ~123 ~26 dirt
setblock ~185 ~123 ~27 dirt
setblock ~185 ~123 ~28 dirt
setblock ~185 ~123 ~29 dirt
setblock ~185 ~123 ~30 dirt
setblock ~185 ~123 ~31 dirt
setblock ~185 ~123 ~32 dirt
setblock ~185 ~123 ~33 dirt
setblock ~185 ~123 ~34 dirt
setblock ~185 ~123 ~35 dirt
setblock ~185 ~123 ~36 dirt
setblock ~185 ~123 ~37 dirt
setblock ~185 ~123 ~38 dirt
setblock ~185 ~123 ~39 dirt
setblock ~185 ~123 ~40 dirt
setblock ~185 ~123 ~41 dirt
setblock ~185 ~123 ~42 dirt
setblock ~185 ~123 ~43 dirt
setblock ~185 ~123 ~44 dirt
setblock ~185 ~123 ~45 dirt
setblock ~185 ~123 ~46 dirt
setblock ~185 ~123 ~47 dirt
setblock ~185 ~123 ~48 dirt
setblock ~185 ~123 ~49 dirt
setblock ~185 ~123 ~50 dirt
setblock ~185 ~123 ~51 dirt
setblock ~185 ~123 ~52 dirt
setblock ~185 ~123 ~53 dirt
setblock ~185 ~123 ~54 dirt
setblock ~185 ~123 ~55 dirt
setblock ~185 ~123 ~56 dirt
setblock ~185 ~123 ~57 dirt
setblock ~185 ~123 ~58 dirt
setblock ~185 ~123 ~59 dirt
setblock ~185 ~123 ~60 grass_block
setblock ~185 ~123 ~61 dirt
setblock ~185 ~123 ~62 dirt
setblock ~185 ~123 ~63 dirt
setblock ~185 ~123 ~64 dirt
setblock ~185 ~123 ~65 dirt
setblock ~185 ~123 ~66 dirt
setblock ~185 ~123 ~67 dirt
setblock ~185 ~123 ~68 dirt
setblock ~185 ~123 ~69 dirt
setblock ~185 ~123 ~70 dirt
setblock ~185 ~123 ~71 dirt
setblock ~185 ~123 ~72 dirt
setblock ~185 ~123 ~73 dirt
setblock ~185 ~123 ~74 dirt
setblock ~185 ~123 ~75 dirt
setblock ~185 ~123 ~76 dirt
setblock ~185 ~123 ~77 dirt
setblock ~185 ~123 ~78 dirt
setblock ~185 ~123 ~79 dirt
setblock ~185 ~123 ~80 dirt
setblock ~185 ~123 ~81 dirt
setblock ~185 ~123 ~82 dirt
setblock ~185 ~123 ~83 dirt
setblock ~185 ~123 ~84 dirt
setblock ~185 ~123 ~85 dirt
setblock ~185 ~123 ~86 dirt
setblock ~185 ~123 ~87 dirt
setblock ~185 ~123 ~88 dirt
setblock ~185 ~123 ~89 dirt
setblock ~185 ~123 ~90 dirt
setblock ~185 ~123 ~91 dirt
setblock ~185 ~123 ~92 dirt
setblock ~185 ~123 ~93 dirt
setblock ~185 ~123 ~94 dirt
setblock ~185 ~123 ~95 dirt
setblock ~185 ~123 ~96 dirt
setblock ~185 ~123 ~97 dirt
setblock ~185 ~123 ~98 dirt
setblock ~185 ~123 ~99 dirt
setblock ~185 ~123 ~100 dirt
setblock ~185 ~123 ~101 dirt
setblock ~185 ~123 ~102 dirt
setblock ~185 ~123 ~103 grass_block
setblock ~185 ~123 ~104 grass_block
setblock ~185 ~123 ~105 grass_block
setblock ~185 ~123 ~106 grass_block
setblock ~185 ~123 ~107 grass_block
setblock ~185 ~123 ~108 grass_block
setblock ~185 ~123 ~109 grass_block
setblock ~185 ~123 ~110 grass_block
setblock ~185 ~123 ~111 grass_block
setblock ~185 ~123 ~112 grass_block
setblock ~185 ~123 ~113 grass_block
setblock ~185 ~123 ~114 dirt
setblock ~185 ~123 ~115 dirt
setblock ~185 ~123 ~116 dirt
setblock ~185 ~123 ~117 grass_block
setblock ~185 ~123 ~118 grass_block
setblock ~185 ~123 ~119 grass_block
setblock ~185 ~123 ~120 grass_block
setblock ~185 ~123 ~121 grass_block
setblock ~185 ~123 ~122 grass_block
setblock ~185 ~123 ~123 grass_block
setblock ~185 ~123 ~124 grass_block
setblock ~185 ~123 ~125 dirt
setblock ~185 ~123 ~126 dirt
setblock ~185 ~123 ~127 dirt
setblock ~185 ~123 ~128 dirt
setblock ~185 ~123 ~129 dirt
setblock ~185 ~123 ~130 dirt
setblock ~185 ~123 ~131 dirt
setblock ~185 ~123 ~132 dirt
setblock ~185 ~123 ~133 dirt
setblock ~185 ~123 ~134 dirt
setblock ~185 ~123 ~135 dirt
setblock ~185 ~123 ~136 dirt
setblock ~185 ~123 ~137 dirt
setblock ~185 ~123 ~138 dirt
setblock ~185 ~123 ~139 dirt
setblock ~185 ~123 ~140 dirt
setblock ~185 ~123 ~141 dirt
setblock ~185 ~123 ~142 dirt
setblock ~185 ~123 ~143 dirt
setblock ~185 ~123 ~144 dirt
setblock ~185 ~123 ~145 dirt
setblock ~185 ~123 ~146 dirt
setblock ~185 ~123 ~147 dirt
setblock ~185 ~123 ~148 dirt
setblock ~185 ~123 ~149 dirt
setblock ~185 ~123 ~150 dirt
setblock ~185 ~123 ~151 dirt
setblock ~185 ~123 ~152 dirt
setblock ~185 ~123 ~153 dirt
setblock ~185 ~123 ~154 dirt
setblock ~185 ~123 ~155 dirt
setblock ~185 ~123 ~156 dirt
setblock ~185 ~123 ~157 dirt
setblock ~185 ~123 ~158 dirt
setblock ~185 ~123 ~159 dirt
setblock ~185 ~123 ~160 dirt
setblock ~185 ~123 ~161 dirt
setblock ~185 ~123 ~162 dirt
setblock ~185 ~123 ~163 dirt
setblock ~185 ~123 ~164 dirt
setblock ~185 ~123 ~165 dirt
setblock ~185 ~123 ~166 dirt
setblock ~185 ~123 ~167 dirt
setblock ~185 ~123 ~168 dirt
setblock ~185 ~123 ~169 dirt
setblock ~185 ~123 ~170 dirt
setblock ~185 ~123 ~171 dirt
setblock ~185 ~123 ~172 dirt
setblock ~185 ~123 ~173 dirt
setblock ~185 ~123 ~174 dirt
setblock ~185 ~123 ~175 dirt
setblock ~185 ~123 ~176 dirt
setblock ~185 ~123 ~177 dirt
setblock ~185 ~123 ~178 dirt
setblock ~185 ~123 ~179 dirt
setblock ~185 ~123 ~180 dirt
setblock ~185 ~123 ~181 dirt
setblock ~185 ~123 ~182 dirt
setblock ~185 ~123 ~183 dirt
setblock ~185 ~123 ~184 dirt
setblock ~185 ~123 ~185 dirt
setblock ~185 ~123 ~186 dirt
setblock ~185 ~123 ~187 dirt
setblock ~185 ~123 ~188 dirt
setblock ~185 ~123 ~189 dirt
setblock ~185 ~123 ~190 dirt
setblock ~185 ~123 ~191 dirt
setblock ~185 ~123 ~192 dirt
setblock ~185 ~123 ~193 dirt
setblock ~185 ~123 ~194 dirt
setblock ~185 ~123 ~195 dirt
setblock ~185 ~123 ~196 dirt
setblock ~185 ~123 ~197 dirt
setblock ~185 ~123 ~198 dirt
setblock ~185 ~123 ~199 dirt
setblock ~185 ~124 ~0 dirt
setblock ~185 ~124 ~1 dirt
setblock ~185 ~124 ~2 dirt
setblock ~185 ~124 ~3 dirt
setblock ~185 ~124 ~4 dirt
setblock ~185 ~124 ~5 dirt
setblock ~185 ~124 ~6 dirt
setblock ~185 ~124 ~7 dirt
setblock ~185 ~124 ~8 dirt
setblock ~185 ~124 ~9 dirt
setblock ~185 ~124 ~10 dirt
setblock ~185 ~124 ~11 dirt
setblock ~185 ~124 ~12 dirt
setblock ~185 ~124 ~13 dirt
setblock ~185 ~124 ~14 dirt
setblock ~185 ~124 ~15 dirt
setblock ~185 ~124 ~16 dirt
setblock ~185 ~124 ~17 grass_block
setblock ~185 ~124 ~18 grass_block
setblock ~185 ~124 ~19 grass_block
