setblock ~173 ~135 ~113 oak_leaves[persistent=true]
setblock ~173 ~135 ~114 oak_leaves[persistent=true]
setblock ~173 ~135 ~115 oak_leaves[persistent=true]
setblock ~173 ~135 ~116 jungle_leaves[persistent=true]
setblock ~173 ~135 ~117 oak_leaves[persistent=true]
setblock ~173 ~135 ~118 oak_leaves[persistent=true]
setblock ~173 ~135 ~119 oak_leaves[persistent=true]
setblock ~173 ~135 ~120 oak_leaves[persistent=true]
setblock ~173 ~135 ~121 oak_leaves[persistent=true]
setblock ~173 ~135 ~122 oak_leaves[persistent=true]
setblock ~173 ~136 ~67 oak_leaves[persistent=true]
setblock ~173 ~136 ~68 oak_leaves[persistent=true]
setblock ~173 ~136 ~69 oak_leaves[persistent=true]
setblock ~173 ~136 ~70 oak_leaves[persistent=true]
setblock ~173 ~136 ~74 oak_leaves[persistent=true]
setblock ~173 ~136 ~75 oak_wood
setblock ~173 ~136 ~77 oak_leaves[persistent=true]
setblock ~173 ~136 ~78 oak_wood
setblock ~173 ~136 ~79 oak_log
setblock ~173 ~136 ~80 oak_wood
setblock ~173 ~136 ~81 oak_wood
setblock ~173 ~136 ~82 oak_wood
setblock ~173 ~136 ~83 oak_leaves[persistent=true]
setblock ~173 ~136 ~85 oak_leaves[persistent=true]
setblock ~173 ~136 ~86 oak_leaves[persistent=true]
setblock ~173 ~136 ~87 oak_log
setblock ~173 ~136 ~88 jungle_leaves[persistent=true]
setblock ~173 ~136 ~89 oak_leaves[persistent=true]
setblock ~173 ~136 ~90 oak_wood
setblock ~173 ~136 ~91 oak_wood
setblock ~173 ~136 ~92 oak_log
setblock ~173 ~136 ~93 oak_leaves[persistent=true]
setblock ~173 ~136 ~95 oak_leaves[persistent=true]
setblock ~173 ~136 ~97 oak_wood
setblock ~173 ~136 ~98 oak_wood
setblock ~173 ~136 ~99 jungle_leaves[persistent=true]
setblock ~173 ~136 ~100 oak_leaves[persistent=true]
setblock ~173 ~136 ~101 oak_wood
setblock ~173 ~136 ~102 oak_wood
setblock ~173 ~136 ~103 oak_leaves[persistent=true]
setblock ~173 ~136 ~104 oak_wood
setblock ~173 ~136 ~105 oak_wood
setblock ~173 ~136 ~106 oak_wood
setblock ~173 ~136 ~107 oak_wood
setblock ~173 ~136 ~108 oak_leaves[persistent=true]
setblock ~173 ~136 ~109 oak_leaves[persistent=true]
setblock ~173 ~136 ~110 oak_leaves[persistent=true]
setblock ~173 ~136 ~111 oak_leaves[persistent=true]
setblock ~173 ~136 ~112 jungle_leaves[persistent=true]
setblock ~173 ~136 ~113 oak_wood
setblock ~173 ~136 ~114 oak_leaves[persistent=true]
setblock ~173 ~136 ~115 oak_leaves[persistent=true]
setblock ~173 ~136 ~116 oak_leaves[persistent=true]
setblock ~173 ~136 ~117 oak_leaves[persistent=true]
setblock ~173 ~136 ~118 oak_leaves[persistent=true]
setblock ~173 ~136 ~119 oak_leaves[persistent=true]
setblock ~173 ~136 ~120 oak_leaves[persistent=true]
setblock ~173 ~136 ~121 jungle_leaves[persistent=true]
setblock ~173 ~136 ~122 oak_leaves[persistent=true]
setblock ~173 ~137 ~66 oak_leaves[persistent=true]
setblock ~173 ~137 ~67 oak_leaves[persistent=true]
setblock ~173 ~137 ~68 oak_leaves[persistent=true]
setblock ~173 ~137 ~69 oak_leaves[persistent=true]
setblock ~173 ~137 ~70 oak_leaves[persistent=true]
setblock ~173 ~137 ~73 oak_leaves[persistent=true]
setblock ~173 ~137 ~74 oak_wood
setblock ~173 ~137 ~75 oak_leaves[persistent=true]
setblock ~173 ~137 ~76 oak_leaves[persistent=true]
setblock ~173 ~137 ~77 oak_wood
setblock ~173 ~137 ~78 oak_leaves[persistent=true]
setblock ~173 ~137 ~79 oak_log
setblock ~173 ~137 ~80 oak_leaves[persistent=true]
setblock ~173 ~137 ~82 oak_leaves[persistent=true]
setblock ~173 ~137 ~83 oak_log
setblock ~173 ~137 ~84 oak_leaves[persistent=true]
setblock ~173 ~137 ~85 oak_leaves[persistent=true]
setblock ~173 ~137 ~86 oak_leaves[persistent=true]
setblock ~173 ~137 ~87 oak_leaves[persistent=true]
setblock ~173 ~137 ~88 jungle_leaves[persistent=true]
setblock ~173 ~137 ~89 oak_leaves[persistent=true]
setblock ~173 ~137 ~91 oak_leaves[persistent=true]
setblock ~173 ~137 ~92 oak_wood
setblock ~173 ~137 ~93 oak_wood
setblock ~173 ~137 ~95 jungle_leaves[persistent=true]
setblock ~173 ~137 ~96 oak_leaves[persistent=true]
setblock ~173 ~137 ~97 oak_leaves[persistent=true]
setblock ~173 ~137 ~98 oak_leaves[persistent=true]
setblock ~173 ~137 ~99 oak_leaves[persistent=true]
setblock ~173 ~137 ~100 jungle_leaves[persistent=true]
setblock ~173 ~137 ~101 oak_leaves[persistent=true]
setblock ~173 ~137 ~102 jungle_leaves[persistent=true]
setblock ~173 ~137 ~103 jungle_leaves[persistent=true]
setblock ~173 ~137 ~104 oak_leaves[persistent=true]
setblock ~173 ~137 ~105 oak_leaves[persistent=true]
setblock ~173 ~137 ~106 oak_wood
setblock ~173 ~137 ~107 oak_wood
setblock ~173 ~137 ~108 oak_leaves[persistent=true]
setblock ~173 ~137 ~109 oak_leaves[persistent=true]
setblock ~173 ~137 ~110 oak_wood
setblock ~173 ~137 ~111 jungle_leaves[persistent=true]
setblock ~173 ~137 ~112 oak_leaves[persistent=true]
setblock ~173 ~137 ~113 oak_wood
setblock ~173 ~137 ~114 oak_leaves[persistent=true]
setblock ~173 ~137 ~115 oak_wood
setblock ~173 ~137 ~116 oak_leaves[persistent=true]
setblock ~173 ~137 ~117 oak_leaves[persistent=true]
setblock ~173 ~137 ~118 oak_leaves[persistent=true]
setblock ~173 ~137 ~119 oak_leaves[persistent=true]
setblock ~173 ~137 ~120 jungle_leaves[persistent=true]
setblock ~173 ~137 ~121 oak_leaves[persistent=true]
setblock ~173 ~137 ~122 jungle_leaves[persistent=true]
setblock ~173 ~138 ~64 oak_leaves[persistent=true]
setblock ~173 ~138 ~67 oak_wood
setblock ~173 ~138 ~68 oak_leaves[persistent=true]
setblock ~173 ~138 ~69 oak_wood
setblock ~173 ~138 ~70 oak_leaves[persistent=true]
setblock ~173 ~138 ~73 jungle_leaves[persistent=true]
setblock ~173 ~138 ~75 oak_leaves[persistent=true]
setblock ~173 ~138 ~76 oak_wood
setblock ~173 ~138 ~77 oak_leaves[persistent=true]
setblock ~173 ~138 ~78 jungle_leaves[persistent=true]
setblock ~173 ~138 ~79 oak_leaves[persistent=true]
setblock ~173 ~138 ~80 oak_leaves[persistent=true]
setblock ~173 ~138 ~81 oak_leaves[persistent=true]
setblock ~173 ~138 ~82 oak_leaves[persistent=true]
setblock ~173 ~138 ~83 oak_leaves[persistent=true]
setblock ~173 ~138 ~84 oak_leaves[persistent=true]
setblock ~173 ~138 ~85 oak_leaves[persistent=true]
setblock ~173 ~138 ~86 jungle_leaves[persistent=true]
setblock ~173 ~138 ~87 oak_leaves[persistent=true]
setblock ~173 ~138 ~88 oak_leaves[persistent=true]
setblock ~173 ~138 ~89 oak_leaves[persistent=true]
setblock ~173 ~138 ~90 oak_leaves[persistent=true]
setblock ~173 ~138 ~91 oak_leaves[persistent=true]
setblock ~173 ~138 ~92 oak_wood
setblock ~173 ~138 ~93 oak_leaves[persistent=true]
setblock ~173 ~138 ~96 jungle_leaves[persistent=true]
setblock ~173 ~138 ~97 oak_leaves[persistent=true]
setblock ~173 ~138 ~98 jungle_leaves[persistent=true]
setblock ~173 ~138 ~99 jungle_leaves[persistent=true]
setblock ~173 ~138 ~100 oak_leaves[persistent=true]
setblock ~173 ~138 ~101 oak_leaves[persistent=true]
setblock ~173 ~138 ~102 jungle_leaves[persistent=true]
setblock ~173 ~138 ~103 oak_leaves[persistent=true]
setblock ~173 ~138 ~104 jungle_leaves[persistent=true]
setblock ~173 ~138 ~105 oak_leaves[persistent=true]
setblock ~173 ~138 ~106 oak_leaves[persistent=true]
setblock ~173 ~138 ~107 oak_wood
setblock ~173 ~138 ~108 oak_leaves[persistent=true]
setblock ~173 ~138 ~109 oak_leaves[persistent=true]
setblock ~173 ~138 ~110 jungle_leaves[persistent=true]
setblock ~173 ~138 ~111 oak_leaves[persistent=true]
setblock ~173 ~138 ~112 oak_leaves[persistent=true]
setblock ~173 ~138 ~113 oak_leaves[persistent=true]
setblock ~173 ~138 ~114 jungle_leaves[persistent=true]
setblock ~173 ~138 ~115 jungle_leaves[persistent=true]
setblock ~173 ~138 ~116 oak_leaves[persistent=true]
setblock ~173 ~138 ~117 oak_leaves[persistent=true]
setblock ~173 ~138 ~118 oak_leaves[persistent=true]
setblock ~173 ~138 ~119 oak_leaves[persistent=true]
setblock ~173 ~138 ~120 oak_leaves[persistent=true]
setblock ~173 ~138 ~121 oak_leaves[persistent=true]
setblock ~173 ~139 ~64 oak_leaves[persistent=true]
setblock ~173 ~139 ~65 oak_leaves[persistent=true]
setblock ~173 ~139 ~66 oak_wood
setblock ~173 ~139 ~67 oak_leaves[persistent=true]
setblock ~173 ~139 ~68 oak_leaves[persistent=true]
setblock ~173 ~139 ~69 oak_leaves[persistent=true]
setblock ~173 ~139 ~70 oak_leaves[persistent=true]
setblock ~173 ~139 ~77 oak_leaves[persistent=true]
setblock ~173 ~139 ~78 oak_leaves[persistent=true]
setblock ~173 ~139 ~79 oak_leaves[persistent=true]
setblock ~173 ~139 ~80 oak_leaves[persistent=true]
setblock ~173 ~139 ~82 oak_leaves[persistent=true]
setblock ~173 ~139 ~83 jungle_leaves[persistent=true]
setblock ~173 ~139 ~84 oak_leaves[persistent=true]
setblock ~173 ~139 ~85 jungle_leaves[persistent=true]
setblock ~173 ~139 ~90 jungle_leaves[persistent=true]
setblock ~173 ~139 ~91 oak_leaves[persistent=true]
setblock ~173 ~139 ~92 oak_leaves[persistent=true]
setblock ~173 ~139 ~94 oak_leaves[persistent=true]
setblock ~173 ~139 ~97 oak_leaves[persistent=true]
setblock ~173 ~139 ~98 oak_leaves[persistent=true]
setblock ~173 ~139 ~99 oak_leaves[persistent=true]
setblock ~173 ~139 ~100 jungle_leaves[persistent=true]
setblock ~173 ~139 ~102 jungle_leaves[persistent=true]
setblock ~173 ~139 ~103 oak_leaves[persistent=true]
setblock ~173 ~139 ~104 oak_leaves[persistent=true]
setblock ~173 ~139 ~105 jungle_leaves[persistent=true]
setblock ~173 ~139 ~106 oak_leaves[persistent=true]
setblock ~173 ~139 ~108 oak_leaves[persistent=true]
setblock ~173 ~139 ~109 oak_leaves[persistent=true]
setblock ~173 ~139 ~110 oak_leaves[persistent=true]
setblock ~173 ~139 ~111 oak_leaves[persistent=true]
setblock ~173 ~139 ~112 oak_leaves[persistent=true]
setblock ~173 ~139 ~115 jungle_leaves[persistent=true]
setblock ~173 ~139 ~116 oak_leaves[persistent=true]
setblock ~173 ~140 ~65 oak_leaves[persistent=true]
setblock ~173 ~140 ~66 jungle_leaves[persistent=true]
setblock ~173 ~140 ~79 oak_leaves[persistent=true]
setblock ~173 ~140 ~81 oak_leaves[persistent=true]
setblock ~173 ~140 ~82 oak_leaves[persistent=true]
setblock ~173 ~140 ~83 oak_leaves[persistent=true]
setblock ~173 ~140 ~84 jungle_leaves[persistent=true]
setblock ~173 ~140 ~97 oak_leaves[persistent=true]
setblock ~173 ~140 ~98 oak_leaves[persistent=true]
setblock ~173 ~140 ~99 oak_leaves[persistent=true]
setblock ~173 ~140 ~100 oak_leaves[persistent=true]
setblock ~173 ~140 ~101 oak_leaves[persistent=true]
setblock ~173 ~140 ~102 oak_leaves[persistent=true]
setblock ~173 ~140 ~106 oak_leaves[persistent=true]
setblock ~173 ~140 ~107 oak_leaves[persistent=true]
setblock ~173 ~140 ~108 oak_leaves[persistent=true]
setblock ~173 ~140 ~109 oak_leaves[persistent=true]
setblock ~173 ~140 ~110 oak_leaves[persistent=true]
setblock ~174 ~120 ~82 dirt
setblock ~174 ~121 ~81 dirt
setblock ~174 ~121 ~82 dirt
setblock ~174 ~121 ~83 dirt
setblock ~174 ~122 ~81 dirt
setblock ~174 ~122 ~82 dirt
setblock ~174 ~122 ~83 dirt
setblock ~174 ~123 ~81 dirt
setblock ~174 ~123 ~82 dirt
setblock ~174 ~123 ~83 dirt
setblock ~174 ~124 ~81 dirt
setblock ~174 ~124 ~82 grass_block
setblock ~174 ~124 ~83 grass_block
setblock ~174 ~125 ~81 spruce_slab
setblock ~174 ~125 ~82 oak_log
setblock ~174 ~125 ~83 oak_log
setblock ~174 ~126 ~72 oak_leaves[persistent=true]
setblock ~174 ~126 ~73 oak_leaves[persistent=true]
setblock ~174 ~126 ~75 jungle_leaves[persistent=true]
setblock ~174 ~126 ~77 oak_leaves[persistent=true]
setblock ~174 ~126 ~79 oak_leaves[persistent=true]
setblock ~174 ~126 ~80 oak_leaves[persistent=true]
setblock ~174 ~126 ~81 spruce_slab
setblock ~174 ~126 ~82 oak_log
setblock ~174 ~126 ~83 oak_log
setblock ~174 ~127 ~72 oak_leaves[persistent=true]
setblock ~174 ~127 ~73 oak_leaves[persistent=true]
setblock ~174 ~127 ~74 oak_leaves[persistent=true]
setblock ~174 ~127 ~75 oak_leaves[persistent=true]
setblock ~174 ~127 ~76 oak_leaves[persistent=true]
setblock ~174 ~127 ~77 oak_leaves[persistent=true]
setblock ~174 ~127 ~78 oak_leaves[persistent=true]
setblock ~174 ~127 ~79 oak_leaves[persistent=true]
setblock ~174 ~127 ~80 oak_leaves[persistent=true]
setblock ~174 ~127 ~81 oak_log
setblock ~174 ~127 ~82 oak_log
setblock ~174 ~127 ~83 oak_log
setblock ~174 ~127 ~90 oak_leaves[persistent=true]
setblock ~174 ~127 ~91 oak_leaves[persistent=true]
setblock ~174 ~127 ~92 oak_leaves[persistent=true]
setblock ~174 ~127 ~93 oak_leaves[persistent=true]
setblock ~174 ~127 ~94 oak_leaves[persistent=true]
setblock ~174 ~127 ~95 oak_leaves[persistent=true]
setblock ~174 ~127 ~96 oak_leaves[persistent=true]
setblock ~174 ~127 ~97 oak_leaves[persistent=true]
setblock ~174 ~127 ~106 oak_leaves[persistent=true]
setblock ~174 ~127 ~107 jungle_leaves[persistent=true]
setblock ~174 ~127 ~108 oak_leaves[persistent=true]
setblock ~174 ~127 ~109 oak_leaves[persistent=true]
setblock ~174 ~127 ~128 oak_leaves[persistent=true]
setblock ~174 ~127 ~129 jungle_leaves[persistent=true]
setblock ~174 ~127 ~130 oak_leaves[persistent=true]
setblock ~174 ~127 ~131 oak_leaves[persistent=true]
setblock ~174 ~128 ~72 oak_leaves[persistent=true]
setblock ~174 ~128 ~73 oak_wood
setblock ~174 ~128 ~74 jungle_leaves[persistent=true]
setblock ~174 ~128 ~75 jungle_leaves[persistent=true]
setblock ~174 ~128 ~76 oak_leaves[persistent=true]
setblock ~174 ~128 ~77 oak_leaves[persistent=true]
setblock ~174 ~128 ~78 jungle_leaves[persistent=true]
setblock ~174 ~128 ~81 oak_log
setblock ~174 ~128 ~82 oak_log
setblock ~174 ~128 ~83 oak_log
setblock ~174 ~128 ~84 jungle_leaves[persistent=true]
setblock ~174 ~128 ~85 oak_leaves[persistent=true]
setblock ~174 ~128 ~86 jungle_leaves[persistent=true]
setblock ~174 ~128 ~87 oak_leaves[persistent=true]
setblock ~174 ~128 ~88 oak_leaves[persistent=true]
setblock ~174 ~128 ~91 oak_leaves[persistent=true]
setblock ~174 ~128 ~92 oak_leaves[persistent=true]
setblock ~174 ~128 ~94 oak_leaves[persistent=true]
setblock ~174 ~128 ~95 oak_leaves[persistent=true]
setblock ~174 ~128 ~96 oak_leaves[persistent=true]
setblock ~174 ~128 ~97 jungle_leaves[persistent=true]
setblock ~174 ~128 ~99 oak_leaves[persistent=true]
setblock ~174 ~128 ~100 oak_leaves[persistent=true]
setblock ~174 ~128 ~101 jungle_leaves[persistent=true]
setblock ~174 ~128 ~102 jungle_leaves[persistent=true]
setblock ~174 ~128 ~106 jungle_leaves[persistent=true]
setblock ~174 ~128 ~107 oak_leaves[persistent=true]
setblock ~174 ~128 ~108 oak_leaves[persistent=true]
setblock ~174 ~128 ~109 oak_leaves[persistent=true]
setblock ~174 ~128 ~118 oak_leaves[persistent=true]
setblock ~174 ~128 ~119 oak_leaves[persistent=true]
setblock ~174 ~128 ~120 oak_leaves[persistent=true]
setblock ~174 ~128 ~121 oak_leaves[persistent=true]
setblock ~174 ~128 ~128 jungle_leaves[persistent=true]
setblock ~174 ~128 ~129 oak_leaves[persistent=true]
setblock ~174 ~128 ~130 oak_leaves[persistent=true]
setblock ~174 ~128 ~131 oak_leaves[persistent=true]
setblock ~174 ~129 ~70 oak_leaves[persistent=true]
setblock ~174 ~129 ~71 oak_leaves[persistent=true]
setblock ~174 ~129 ~72 oak_leaves[persistent=true]
setblock ~174 ~129 ~73 oak_leaves[persistent=true]
setblock ~174 ~129 ~74 oak_leaves[persistent=true]
setblock ~174 ~129 ~75 oak_leaves[persistent=true]
setblock ~174 ~129 ~76 oak_leaves[persistent=true]
setblock ~174 ~129 ~77 oak_leaves[persistent=true]
setblock ~174 ~129 ~78 oak_leaves[persistent=true]
setblock ~174 ~129 ~79 oak_leaves[persistent=true]
setblock ~174 ~129 ~80 oak_wood
setblock ~174 ~129 ~81 oak_log
setblock ~174 ~129 ~82 oak_log
setblock ~174 ~129 ~83 oak_log
setblock ~174 ~129 ~84 oak_leaves[persistent=true]
setblock ~174 ~129 ~85 oak_leaves[persistent=true]
setblock ~174 ~129 ~86 oak_wood
setblock ~174 ~129 ~87 oak_leaves[persistent=true]
setblock ~174 ~129 ~88 oak_leaves[persistent=true]
setblock ~174 ~129 ~89 oak_leaves[persistent=true]
setblock ~174 ~129 ~90 oak_leaves[persistent=true]
setblock ~174 ~129 ~92 oak_leaves[persistent=true]
setblock ~174 ~129 ~93 oak_leaves[persistent=true]
setblock ~174 ~129 ~94 oak_leaves[persistent=true]
setblock ~174 ~129 ~95 jungle_leaves[persistent=true]
setblock ~174 ~129 ~96 oak_leaves[persistent=true]
setblock ~174 ~129 ~97 oak_wood
setblock ~174 ~129 ~98 jungle_leaves[persistent=true]
setblock ~174 ~129 ~99 oak_leaves[persistent=true]
setblock ~174 ~129 ~100 oak_leaves[persistent=true]
setblock ~174 ~129 ~101 oak_leaves[persistent=true]
setblock ~174 ~129 ~102 jungle_leaves[persistent=true]
setblock ~174 ~129 ~103 oak_leaves[persistent=true]
setblock ~174 ~129 ~104 oak_leaves[persistent=true]
setblock ~174 ~129 ~105 oak_leaves[persistent=true]
setblock ~174 ~129 ~106 jungle_leaves[persistent=true]
setblock ~174 ~129 ~107 oak_leaves[persistent=true]
setblock ~174 ~129 ~108 jungle_leaves[persistent=true]
setblock ~174 ~129 ~109 jungle_leaves[persistent=true]
setblock ~174 ~129 ~110 oak_leaves[persistent=true]
setblock ~174 ~129 ~111 oak_leaves[persistent=true]
setblock ~174 ~129 ~112 oak_leaves[persistent=true]
setblock ~174 ~129 ~114 oak_leaves[persistent=true]
setblock ~174 ~129 ~117 oak_leaves[persistent=true]
setblock ~174 ~129 ~118 oak_leaves[persistent=true]
setblock ~174 ~129 ~119 oak_leaves[persistent=true]
setblock ~174 ~129 ~120 oak_leaves[persistent=true]
setblock ~174 ~129 ~121 oak_leaves[persistent=true]
setblock ~174 ~129 ~128 oak_leaves[persistent=true]
setblock ~174 ~129 ~129 oak_wood
setblock ~174 ~129 ~130 oak_leaves[persistent=true]
setblock ~174 ~129 ~131 oak_leaves[persistent=true]
setblock ~174 ~130 ~70 oak_leaves[persistent=true]
setblock ~174 ~130 ~71 oak_leaves[persistent=true]
setblock ~174 ~130 ~72 oak_leaves[persistent=true]
setblock ~174 ~130 ~73 jungle_leaves[persistent=true]
setblock ~174 ~130 ~75 oak_leaves[persistent=true]
setblock ~174 ~130 ~76 oak_leaves[persistent=true]
setblock ~174 ~130 ~77 oak_wood
setblock ~174 ~130 ~78 oak_leaves[persistent=true]
setblock ~174 ~130 ~79 oak_leaves[persistent=true]
setblock ~174 ~130 ~80 oak_leaves[persistent=true]
setblock ~174 ~130 ~81 oak_log
setblock ~174 ~130 ~82 oak_log
setblock ~174 ~130 ~83 oak_leaves[persistent=true]
setblock ~174 ~130 ~84 oak_leaves[persistent=true]
setblock ~174 ~130 ~85 oak_leaves[persistent=true]
setblock ~174 ~130 ~86 oak_wood
setblock ~174 ~130 ~87 oak_leaves[persistent=true]
setblock ~174 ~130 ~88 oak_leaves[persistent=true]
setblock ~174 ~130 ~89 oak_leaves[persistent=true]
setblock ~174 ~130 ~90 oak_leaves[persistent=true]
setblock ~174 ~130 ~91 oak_wood
setblock ~174 ~130 ~92 oak_leaves[persistent=true]
setblock ~174 ~130 ~93 oak_leaves[persistent=true]
setblock ~174 ~130 ~94 oak_leaves[persistent=true]
setblock ~174 ~130 ~95 oak_leaves[persistent=true]
setblock ~174 ~130 ~96 oak_leaves[persistent=true]
setblock ~174 ~130 ~97 oak_wood
setblock ~174 ~130 ~98 oak_wood
setblock ~174 ~130 ~100 oak_wood
setblock ~174 ~130 ~102 jungle_leaves[persistent=true]
setblock ~174 ~130 ~103 oak_leaves[persistent=true]
setblock ~174 ~130 ~104 oak_leaves[persistent=true]
setblock ~174 ~130 ~105 oak_leaves[persistent=true]
setblock ~174 ~130 ~106 oak_leaves[persistent=true]
setblock ~174 ~130 ~108 oak_leaves[persistent=true]
setblock ~174 ~130 ~109 oak_leaves[persistent=true]
setblock ~174 ~130 ~110 oak_leaves[persistent=true]
setblock ~174 ~130 ~111 oak_leaves[persistent=true]
setblock ~174 ~130 ~112 oak_leaves[persistent=true]
setblock ~174 ~130 ~114 oak_leaves[persistent=true]
setblock ~174 ~130 ~115 oak_leaves[persistent=true]
setblock ~174 ~130 ~116 oak_leaves[persistent=true]
setblock ~174 ~130 ~117 oak_leaves[persistent=true]
setblock ~174 ~130 ~118 jungle_leaves[persistent=true]
setblock ~174 ~130 ~119 oak_leaves[persistent=true]
setblock ~174 ~130 ~120 oak_leaves[persistent=true]
setblock ~174 ~130 ~121 oak_leaves[persistent=true]
setblock ~174 ~130 ~128 oak_leaves[persistent=true]
setblock ~174 ~130 ~129 jungle_leaves[persistent=true]
setblock ~174 ~130 ~130 oak_leaves[persistent=true]
setblock ~174 ~130 ~131 oak_leaves[persistent=true]
setblock ~174 ~131 ~63 oak_leaves[persistent=true]
setblock ~174 ~131 ~64 oak_leaves[persistent=true]
setblock ~174 ~131 ~71 oak_leaves[persistent=true]
setblock ~174 ~131 ~72 oak_leaves[persistent=true]
setblock ~174 ~131 ~73 oak_wood
setblock ~174 ~131 ~74 oak_leaves[persistent=true]
setblock ~174 ~131 ~75 oak_leaves[persistent=true]
setblock ~174 ~131 ~76 jungle_leaves[persistent=true]
setblock ~174 ~131 ~77 oak_leaves[persistent=true]
setblock ~174 ~131 ~78 jungle_leaves[persistent=true]
setblock ~174 ~131 ~79 oak_wood
setblock ~174 ~131 ~80 oak_leaves[persistent=true]
setblock ~174 ~131 ~81 oak_leaves[persistent=true]
setblock ~174 ~131 ~82 oak_leaves[persistent=true]
setblock ~174 ~131 ~83 oak_log
setblock ~174 ~131 ~84 oak_leaves[persistent=true]
setblock ~174 ~131 ~85 oak_wood
setblock ~174 ~131 ~86 oak_wood
setblock ~174 ~131 ~87 oak_wood
setblock ~174 ~131 ~88 oak_leaves[persistent=true]
setblock ~174 ~131 ~89 oak_leaves[persistent=true]
setblock ~174 ~131 ~90 jungle_leaves[persistent=true]
setblock ~174 ~131 ~91 oak_leaves[persistent=true]
setblock ~174 ~131 ~93 jungle_leaves[persistent=true]
setblock ~174 ~131 ~94 oak_leaves[persistent=true]
setblock ~174 ~131 ~95 oak_leaves[persistent=true]
setblock ~174 ~131 ~96 oak_wood
setblock ~174 ~131 ~97 oak_wood
setblock ~174 ~131 ~98 oak_wood
setblock ~174 ~131 ~99 oak_wood
setblock ~174 ~131 ~100 oak_wood
setblock ~174 ~131 ~101 oak_wood
setblock ~174 ~131 ~102 oak_wood
setblock ~174 ~131 ~103 oak_leaves[persistent=true]
setblock ~174 ~131 ~104 oak_leaves[persistent=true]
setblock ~174 ~131 ~105 oak_leaves[persistent=true]
setblock ~174 ~131 ~106 oak_wood
setblock ~174 ~131 ~107 oak_leaves[persistent=true]
setblock ~174 ~131 ~108 jungle_leaves[persistent=true]
setblock ~174 ~131 ~109 oak_leaves[persistent=true]
setblock ~174 ~131 ~110 jungle_leaves[persistent=true]
setblock ~174 ~131 ~111 jungle_leaves[persistent=true]
setblock ~174 ~131 ~112 oak_leaves[persistent=true]
setblock ~174 ~131 ~113 oak_leaves[persistent=true]
setblock ~174 ~131 ~114 jungle_leaves[persistent=true]
setblock ~174 ~131 ~115 oak_wood
setblock ~174 ~131 ~116 oak_leaves[persistent=true]
setblock ~174 ~131 ~117 jungle_leaves[persistent=true]
setblock ~174 ~131 ~118 oak_leaves[persistent=true]
setblock ~174 ~131 ~119 oak_leaves[persistent=true]
setblock ~174 ~131 ~120 oak_leaves[persistent=true]
setblock ~174 ~131 ~121 jungle_leaves[persistent=true]
setblock ~174 ~132 ~63 oak_leaves[persistent=true]
setblock ~174 ~132 ~64 oak_leaves[persistent=true]
setblock ~174 ~132 ~70 oak_leaves[persistent=true]
setblock ~174 ~132 ~71 oak_leaves[persistent=true]
setblock ~174 ~132 ~73 oak_wood
setblock ~174 ~132 ~74 oak_leaves[persistent=true]
setblock ~174 ~132 ~75 oak_leaves[persistent=true]
setblock ~174 ~132 ~76 oak_wood
setblock ~174 ~132 ~77 oak_leaves[persistent=true]
setblock ~174 ~132 ~78 jungle_leaves[persistent=true]
setblock ~174 ~132 ~79 jungle_leaves[persistent=true]
setblock ~174 ~132 ~80 oak_wood
setblock ~174 ~132 ~81 oak_log
setblock ~174 ~132 ~82 oak_leaves[persistent=true]
setblock ~174 ~132 ~83 oak_log
setblock ~174 ~132 ~84 oak_leaves[persistent=true]
setblock ~174 ~132 ~85 oak_wood
setblock ~174 ~132 ~86 oak_wood
setblock ~174 ~132 ~87 oak_wood
setblock ~174 ~132 ~88 oak_wood
setblock ~174 ~132 ~89 oak_leaves[persistent=true]
setblock ~174 ~132 ~90 oak_wood
setblock ~174 ~132 ~91 oak_leaves[persistent=true]
setblock ~174 ~132 ~92 jungle_leaves[persistent=true]
setblock ~174 ~132 ~93 oak_wood
setblock ~174 ~132 ~94 oak_leaves[persistent=true]
setblock ~174 ~132 ~95 oak_leaves[persistent=true]
setblock ~174 ~132 ~96 oak_leaves[persistent=true]
setblock ~174 ~132 ~97 oak_wood
setblock ~174 ~132 ~98 oak_leaves[persistent=true]
setblock ~174 ~132 ~99 jungle_leaves[persistent=true]
setblock ~174 ~132 ~100 oak_wood
setblock ~174 ~132 ~102 oak_wood
setblock ~174 ~132 ~103 oak_leaves[persistent=true]
setblock ~174 ~132 ~104 oak_leaves[persistent=true]
setblock ~174 ~132 ~105 oak_leaves[persistent=true]
setblock ~174 ~132 ~106 jungle_leaves[persistent=true]
setblock ~174 ~132 ~107 oak_leaves[persistent=true]
setblock ~174 ~132 ~109 oak_leaves[persistent=true]
setblock ~174 ~132 ~110 jungle_leaves[persistent=true]
setblock ~174 ~132 ~111 oak_leaves[persistent=true]
setblock ~174 ~132 ~113 jungle_leaves[persistent=true]
setblock ~174 ~132 ~114 oak_leaves[persistent=true]
setblock ~174 ~132 ~115 oak_wood
setblock ~174 ~132 ~116 oak_leaves[persistent=true]
setblock ~174 ~132 ~117 oak_leaves[persistent=true]
setblock ~174 ~132 ~118 jungle_leaves[persistent=true]
setblock ~174 ~132 ~119 oak_leaves[persistent=true]
setblock ~174 ~132 ~120 jungle_leaves[persistent=true]
setblock ~174 ~133 ~71 oak_leaves[persistent=true]
setblock ~174 ~133 ~72 oak_leaves[persistent=true]
setblock ~174 ~133 ~73 oak_leaves[persistent=true]
setblock ~174 ~133 ~74 oak_leaves[persistent=true]
setblock ~174 ~133 ~75 oak_leaves[persistent=true]
setblock ~174 ~133 ~76 jungle_leaves[persistent=true]
setblock ~174 ~133 ~77 oak_leaves[persistent=true]
setblock ~174 ~133 ~78 oak_leaves[persistent=true]
setblock ~174 ~133 ~79 oak_leaves[persistent=true]
setblock ~174 ~133 ~80 oak_log
setblock ~174 ~133 ~81 oak_leaves[persistent=true]
setblock ~174 ~133 ~82 oak_wood
setblock ~174 ~133 ~83 oak_wood
setblock ~174 ~133 ~84 oak_wood
setblock ~174 ~133 ~85 oak_wood
setblock ~174 ~133 ~86 oak_leaves[persistent=true]
setblock ~174 ~133 ~87 oak_wood
setblock ~174 ~133 ~88 jungle_leaves[persistent=true]
setblock ~174 ~133 ~89 oak_wood
setblock ~174 ~133 ~90 oak_leaves[persistent=true]
setblock ~174 ~133 ~91 oak_wood
setblock ~174 ~133 ~92 oak_leaves[persistent=true]
setblock ~174 ~133 ~94 oak_leaves[persistent=true]
setblock ~174 ~133 ~96 oak_wood
setblock ~174 ~133 ~97 oak_wood
setblock ~174 ~133 ~98 oak_leaves[persistent=true]
setblock ~174 ~133 ~99 oak_leaves[persistent=true]
setblock ~174 ~133 ~100 jungle_leaves[persistent=true]
setblock ~174 ~133 ~101 oak_leaves[persistent=true]
setblock ~174 ~133 ~102 oak_wood
setblock ~174 ~133 ~103 oak_leaves[persistent=true]
setblock ~174 ~133 ~104 oak_wood
setblock ~174 ~133 ~105 oak_leaves[persistent=true]
setblock ~174 ~133 ~106 jungle_leaves[persistent=true]
setblock ~174 ~133 ~107 oak_wood
setblock ~174 ~133 ~108 oak_wood
setblock ~174 ~133 ~109 oak_wood
setblock ~174 ~133 ~111 jungle_leaves[persistent=true]
setblock ~174 ~133 ~112 oak_leaves[persistent=true]
setblock ~174 ~133 ~113 oak_leaves[persistent=true]
setblock ~174 ~133 ~114 oak_leaves[persistent=true]
setblock ~174 ~133 ~115 oak_leaves[persistent=true]
setblock ~174 ~133 ~117 oak_leaves[persistent=true]
setblock ~174 ~133 ~118 oak_leaves[persistent=true]
setblock ~174 ~133 ~119 oak_leaves[persistent=true]
setblock ~174 ~133 ~120 oak_leaves[persistent=true]
setblock ~174 ~134 ~73 oak_leaves[persistent=true]
setblock ~174 ~134 ~74 oak_leaves[persistent=true]
setblock ~174 ~134 ~75 oak_leaves[persistent=true]
setblock ~174 ~134 ~76 oak_wood
setblock ~174 ~134 ~77 oak_leaves[persistent=true]
setblock ~174 ~134 ~78 oak_wood
setblock ~174 ~134 ~79 jungle_leaves[persistent=true]
setblock ~174 ~134 ~80 oak_leaves[persistent=true]
setblock ~174 ~134 ~81 oak_wood
setblock ~174 ~134 ~82 oak_leaves[persistent=true]
setblock ~174 ~134 ~83 oak_leaves[persistent=true]
setblock ~174 ~134 ~84 oak_wood
setblock ~174 ~134 ~85 oak_wood
setblock ~174 ~134 ~86 oak_wood
setblock ~174 ~134 ~87 oak_wood
setblock ~174 ~134 ~88 oak_wood
setblock ~174 ~134 ~89 oak_leaves[persistent=true]
setblock ~174 ~134 ~90 oak_wood
setblock ~174 ~134 ~91 oak_leaves[persistent=true]
setblock ~174 ~134 ~92 oak_wood
setblock ~174 ~134 ~93 oak_leaves[persistent=true]
setblock ~174 ~134 ~94 oak_wood
setblock ~174 ~134 ~95 oak_wood
setblock ~174 ~134 ~96 oak_wood
setblock ~174 ~134 ~97 oak_wood
setblock ~174 ~134 ~98 oak_wood
setblock ~174 ~134 ~99 oak_wood
setblock ~174 ~134 ~100 oak_wood
setblock ~174 ~134 ~101 oak_leaves[persistent=true]
setblock ~174 ~134 ~102 oak_leaves[persistent=true]
setblock ~174 ~134 ~103 oak_leaves[persistent=true]
setblock ~174 ~134 ~104 oak_wood
setblock ~174 ~134 ~105 oak_leaves[persistent=true]
setblock ~174 ~134 ~106 jungle_leaves[persistent=true]
setblock ~174 ~134 ~108 jungle_leaves[persistent=true]
setblock ~174 ~134 ~109 oak_leaves[persistent=true]
setblock ~174 ~134 ~110 oak_wood
setblock ~174 ~134 ~111 oak_wood
setblock ~174 ~134 ~113 oak_leaves[persistent=true]
setblock ~174 ~134 ~114 jungle_leaves[persistent=true]
setblock ~174 ~134 ~117 oak_leaves[persistent=true]
setblock ~174 ~134 ~118 oak_leaves[persistent=true]
setblock ~174 ~134 ~119 jungle_leaves[persistent=true]
setblock ~174 ~134 ~120 jungle_leaves[persistent=true]
setblock ~174 ~135 ~68 oak_leaves[persistent=true]
setblock ~174 ~135 ~69 oak_leaves[persistent=true]
setblock ~174 ~135 ~70 jungle_leaves[persistent=true]
setblock ~174 ~135 ~73 oak_leaves[persistent=true]
setblock ~174 ~135 ~74 jungle_leaves[persistent=true]
setblock ~174 ~135 ~75 oak_leaves[persistent=true]
setblock ~174 ~135 ~77 oak_wood
setblock ~174 ~135 ~78 oak_wood
setblock ~174 ~135 ~79 oak_leaves[persistent=true]
setblock ~174 ~135 ~80 oak_log
setblock ~174 ~135 ~81 oak_leaves[persistent=true]
setblock ~174 ~135 ~82 oak_leaves[persistent=true]
setblock ~174 ~135 ~83 oak_wood
setblock ~174 ~135 ~84 oak_wood
setblock ~174 ~135 ~85 jungle_leaves[persistent=true]
setblock ~174 ~135 ~86 oak_log
setblock ~174 ~135 ~87 oak_leaves[persistent=true]
setblock ~174 ~135 ~88 jungle_leaves[persistent=true]
setblock ~174 ~135 ~89 oak_leaves[persistent=true]
setblock ~174 ~135 ~90 jungle_leaves[persistent=true]
setblock ~174 ~135 ~91 jungle_leaves[persistent=true]
setblock ~174 ~135 ~92 oak_wood
setblock ~174 ~135 ~93 oak_leaves[persistent=true]
setblock ~174 ~135 ~94 oak_leaves[persistent=true]
setblock ~174 ~135 ~95 oak_wood
setblock ~174 ~135 ~96 oak_wood
setblock ~174 ~135 ~97 jungle_leaves[persistent=true]
setblock ~174 ~135 ~98 oak_leaves[persistent=true]
setblock ~174 ~135 ~99 oak_wood
setblock ~174 ~135 ~100 oak_wood
setblock ~174 ~135 ~101 oak_wood
setblock ~174 ~135 ~102 oak_leaves[persistent=true]
setblock ~174 ~135 ~103 oak_leaves[persistent=true]
setblock ~174 ~135 ~104 oak_log
setblock ~174 ~135 ~105 jungle_leaves[persistent=true]
setblock ~174 ~135 ~106 oak_leaves[persistent=true]
setblock ~174 ~135 ~108 oak_leaves[persistent=true]
setblock ~174 ~135 ~109 oak_leaves[persistent=true]
setblock ~174 ~135 ~110 oak_wood
setblock ~174 ~135 ~111 jungle_leaves[persistent=true]
setblock ~174 ~135 ~112 oak_leaves[persistent=true]
setblock ~174 ~135 ~113 oak_leaves[persistent=true]
setblock ~174 ~135 ~114 oak_leaves[persistent=true]
setblock ~174 ~135 ~115 oak_leaves[persistent=true]
setblock ~174 ~135 ~116 oak_leaves[persistent=true]
setblock ~174 ~135 ~120 oak_leaves[persistent=true]
setblock ~174 ~135 ~121 oak_leaves[persistent=true]
setblock ~174 ~135 ~122 oak_leaves[persistent=true]
setblock ~174 ~136 ~67 jungle_leaves[persistent=true]
setblock ~174 ~136 ~68 oak_leaves[persistent=true]
setblock ~174 ~136 ~69 oak_leaves[persistent=true]
setblock ~174 ~136 ~73 oak_leaves[persistent=true]
setblock ~174 ~136 ~74 oak_leaves[persistent=true]
setblock ~174 ~136 ~75 oak_log
setblock ~174 ~136 ~76 oak_log
setblock ~174 ~136 ~77 oak_leaves[persistent=true]
setblock ~174 ~136 ~78 oak_leaves[persistent=true]
setblock ~174 ~136 ~79 oak_wood
setblock ~174 ~136 ~80 oak_log
setblock ~174 ~136 ~81 oak_wood
setblock ~174 ~136 ~82 oak_leaves[persistent=true]
setblock ~174 ~136 ~83 oak_wood
setblock ~174 ~136 ~84 oak_wood
setblock ~174 ~136 ~85 oak_wood
setblock ~174 ~136 ~86 oak_log
setblock ~174 ~136 ~87 oak_leaves[persistent=true]
setblock ~174 ~136 ~88 oak_leaves[persistent=true]
setblock ~174 ~136 ~89 oak_log
setblock ~174 ~136 ~90 oak_leaves[persistent=true]
setblock ~174 ~136 ~91 oak_leaves[persistent=true]
setblock ~174 ~136 ~92 oak_log
setblock ~174 ~136 ~93 oak_log
setblock ~174 ~136 ~94 oak_leaves[persistent=true]
setblock ~174 ~136 ~95 jungle_leaves[persistent=true]
setblock ~174 ~136 ~96 jungle_leaves[persistent=true]
setblock ~174 ~136 ~97 oak_leaves[persistent=true]
setblock ~174 ~136 ~100 oak_leaves[persistent=true]
setblock ~174 ~136 ~101 oak_wood
setblock ~174 ~136 ~102 oak_leaves[persistent=true]
setblock ~174 ~136 ~103 oak_wood
setblock ~174 ~136 ~104 oak_leaves[persistent=true]
setblock ~174 ~136 ~105 oak_leaves[persistent=true]
setblock ~174 ~136 ~106 oak_wood
setblock ~174 ~136 ~107 jungle_leaves[persistent=true]
setblock ~174 ~136 ~109 oak_leaves[persistent=true]
setblock ~174 ~136 ~110 oak_leaves[persistent=true]
setblock ~174 ~136 ~111 oak_leaves[persistent=true]
setblock ~174 ~136 ~112 oak_leaves[persistent=true]
setblock ~174 ~136 ~114 oak_leaves[persistent=true]
setblock ~174 ~136 ~115 jungle_leaves[persistent=true]
setblock ~174 ~136 ~116 oak_leaves[persistent=true]
setblock ~174 ~136 ~120 oak_leaves[persistent=true]
setblock ~174 ~136 ~121 oak_leaves[persistent=true]
setblock ~174 ~136 ~122 jungle_leaves[persistent=true]
setblock ~174 ~137 ~66 oak_leaves[persistent=true]
setblock ~174 ~137 ~67 jungle_leaves[persistent=true]
setblock ~174 ~137 ~68 jungle_leaves[persistent=true]
setblock ~174 ~137 ~69 oak_leaves[persistent=true]
setblock ~174 ~137 ~70 oak_leaves[persistent=true]
setblock ~174 ~137 ~73 oak_leaves[persistent=true]
setblock ~174 ~137 ~74 oak_leaves[persistent=true]
setblock ~174 ~137 ~75 oak_leaves[persistent=true]
setblock ~174 ~137 ~77 jungle_leaves[persistent=true]
setblock ~174 ~137 ~78 oak_leaves[persistent=true]
setblock ~174 ~137 ~79 oak_leaves[persistent=true]
setblock ~174 ~137 ~80 oak_log
setblock ~174 ~137 ~82 oak_wood
setblock ~174 ~137 ~83 oak_wood
setblock ~174 ~137 ~84 oak_wood
setblock ~174 ~137 ~85 oak_leaves[persistent=true]
setblock ~174 ~137 ~87 jungle_leaves[persistent=true]
setblock ~174 ~137 ~89 jungle_leaves[persistent=true]
setblock ~174 ~137 ~90 oak_leaves[persistent=true]
setblock ~174 ~137 ~91 oak_leaves[persistent=true]
setblock ~174 ~137 ~93 jungle_leaves[persistent=true]
setblock ~174 ~137 ~94 oak_wood
setblock ~174 ~137 ~95 oak_leaves[persistent=true]
setblock ~174 ~137 ~96 jungle_leaves[persistent=true]
setblock ~174 ~137 ~97 jungle_leaves[persistent=true]
setblock ~174 ~137 ~98 oak_wood
setblock ~174 ~137 ~99 oak_leaves[persistent=true]
setblock ~174 ~137 ~100 oak_leaves[persistent=true]
setblock ~174 ~137 ~101 oak_leaves[persistent=true]
setblock ~174 ~137 ~102 oak_leaves[persistent=true]
setblock ~174 ~137 ~103 oak_log
setblock ~174 ~137 ~104 oak_log
setblock ~174 ~137 ~105 jungle_leaves[persistent=true]
setblock ~174 ~137 ~106 oak_log
setblock ~174 ~137 ~107 jungle_leaves[persistent=true]
setblock ~174 ~137 ~108 oak_leaves[persistent=true]
setblock ~174 ~137 ~109 oak_leaves[persistent=true]
setblock ~174 ~137 ~110 oak_wood
setblock ~174 ~137 ~111 oak_leaves[persistent=true]
setblock ~174 ~137 ~112 oak_leaves[persistent=true]
setblock ~174 ~137 ~113 oak_wood
setblock ~174 ~137 ~114 oak_wood
setblock ~174 ~137 ~115 oak_leaves[persistent=true]
setblock ~174 ~137 ~116 oak_leaves[persistent=true]
setblock ~174 ~137 ~117 oak_leaves[persistent=true]
setblock ~174 ~137 ~120 oak_leaves[persistent=true]
setblock ~174 ~137 ~121 oak_leaves[persistent=true]
setblock ~174 ~137 ~122 oak_leaves[persistent=true]
setblock ~174 ~138 ~64 oak_leaves[persistent=true]
setblock ~174 ~138 ~65 jungle_leaves[persistent=true]
setblock ~174 ~138 ~66 jungle_leaves[persistent=true]
setblock ~174 ~138 ~67 oak_leaves[persistent=true]
setblock ~174 ~138 ~68 oak_leaves[persistent=true]
setblock ~174 ~138 ~69 oak_leaves[persistent=true]
setblock ~174 ~138 ~70 jungle_leaves[persistent=true]
setblock ~174 ~138 ~73 oak_leaves[persistent=true]
setblock ~174 ~138 ~74 oak_leaves[persistent=true]
setblock ~174 ~138 ~75 oak_leaves[persistent=true]
setblock ~174 ~138 ~76 oak_leaves[persistent=true]
setblock ~174 ~138 ~77 oak_leaves[persistent=true]
setblock ~174 ~138 ~78 oak_leaves[persistent=true]
setblock ~174 ~138 ~79 oak_leaves[persistent=true]
setblock ~174 ~138 ~80 jungle_leaves[persistent=true]
setblock ~174 ~138 ~81 oak_leaves[persistent=true]
setblock ~174 ~138 ~82 oak_leaves[persistent=true]
setblock ~174 ~138 ~83 oak_leaves[persistent=true]
setblock ~174 ~138 ~84 oak_leaves[persistent=true]
setblock ~174 ~138 ~85 oak_leaves[persistent=true]
setblock ~174 ~138 ~86 oak_leaves[persistent=true]
setblock ~174 ~138 ~88 jungle_leaves[persistent=true]
setblock ~174 ~138 ~89 oak_leaves[persistent=true]
setblock ~174 ~138 ~90 oak_leaves[persistent=true]
setblock ~174 ~138 ~91 oak_leaves[persistent=true]
setblock ~174 ~138 ~92 oak_leaves[persistent=true]
setblock ~174 ~138 ~93 oak_wood
setblock ~174 ~138 ~94 jungle_leaves[persistent=true]
setblock ~174 ~138 ~95 jungle_leaves[persistent=true]
setblock ~174 ~138 ~96 oak_leaves[persistent=true]
setblock ~174 ~138 ~97 oak_leaves[persistent=true]
setblock ~174 ~138 ~98 oak_leaves[persistent=true]
setblock ~174 ~138 ~100 oak_leaves[persistent=true]
setblock ~174 ~138 ~101 jungle_leaves[persistent=true]
setblock ~174 ~138 ~102 oak_leaves[persistent=true]
setblock ~174 ~138 ~103 oak_leaves[persistent=true]
setblock ~174 ~138 ~104 oak_leaves[persistent=true]
setblock ~174 ~138 ~105 jungle_leaves[persistent=true]
setblock ~174 ~138 ~106 oak_leaves[persistent=true]
setblock ~174 ~138 ~107 oak_wood
setblock ~174 ~138 ~108 oak_leaves[persistent=true]
setblock ~174 ~138 ~109 jungle_leaves[persistent=true]
setblock ~174 ~138 ~110 jungle_leaves[persistent=true]
setblock ~174 ~138 ~112 oak_leaves[persistent=true]
setblock ~174 ~138 ~113 oak_leaves[persistent=true]
setblock ~174 ~138 ~115 oak_leaves[persistent=true]
setblock ~174 ~138 ~116 oak_wood
setblock ~174 ~138 ~117 oak_leaves[persistent=true]
setblock ~174 ~138 ~118 oak_leaves[persistent=true]
setblock ~174 ~139 ~64 oak_leaves[persistent=true]
setblock ~174 ~139 ~65 oak_leaves[persistent=true]
setblock ~174 ~139 ~66 oak_leaves[persistent=true]
setblock ~174 ~139 ~67 oak_leaves[persistent=true]
setblock ~174 ~139 ~68 oak_wood
setblock ~174 ~139 ~69 oak_leaves[persistent=true]
setblock ~174 ~139 ~70 oak_leaves[persistent=true]
setblock ~174 ~139 ~73 jungle_leaves[persistent=true]
setblock ~174 ~139 ~74 oak_leaves[persistent=true]
setblock ~174 ~139 ~77 oak_leaves[persistent=true]
setblock ~174 ~139 ~78 oak_leaves[persistent=true]
setblock ~174 ~139 ~79 oak_leaves[persistent=true]
setblock ~174 ~139 ~81 oak_leaves[persistent=true]
setblock ~174 ~139 ~82 jungle_leaves[persistent=true]
setblock ~174 ~139 ~83 oak_leaves[persistent=true]
setblock ~174 ~139 ~84 oak_leaves[persistent=true]
setblock ~174 ~139 ~85 oak_leaves[persistent=true]
setblock ~174 ~139 ~90 jungle_leaves[persistent=true]
setblock ~174 ~139 ~91 oak_leaves[persistent=true]
setblock ~174 ~139 ~92 jungle_leaves[persistent=true]
setblock ~174 ~139 ~93 oak_leaves[persistent=true]
setblock ~174 ~139 ~94 oak_wood
setblock ~174 ~139 ~97 oak_leaves[persistent=true]
setblock ~174 ~139 ~98 oak_leaves[persistent=true]
setblock ~174 ~139 ~99 jungle_leaves[persistent=true]
setblock ~174 ~139 ~101 oak_leaves[persistent=true]
setblock ~174 ~139 ~102 oak_leaves[persistent=true]
setblock ~174 ~139 ~103 oak_leaves[persistent=true]
setblock ~174 ~139 ~105 oak_leaves[persistent=true]
setblock ~174 ~139 ~106 jungle_leaves[persistent=true]
setblock ~174 ~139 ~107 oak_leaves[persistent=true]
setblock ~174 ~139 ~108 oak_wood
setblock ~174 ~139 ~109 oak_leaves[persistent=true]
setblock ~174 ~139 ~110 oak_leaves[persistent=true]
setblock ~174 ~139 ~115 jungle_leaves[persistent=true]
setblock ~174 ~139 ~116 jungle_leaves[persistent=true]
setblock ~174 ~139 ~117 oak_leaves[persistent=true]
setblock ~174 ~139 ~118 oak_leaves[persistent=true]
setblock ~174 ~140 ~65 oak_leaves[persistent=true]
setblock ~174 ~140 ~66 jungle_leaves[persistent=true]
setblock ~174 ~140 ~67 oak_leaves[persistent=true]
setblock ~174 ~140 ~68 oak_leaves[persistent=true]
setblock ~174 ~140 ~79 oak_leaves[persistent=true]
setblock ~174 ~140 ~80 oak_leaves[persistent=true]
setblock ~174 ~140 ~82 oak_leaves[persistent=true]
setblock ~174 ~140 ~83 oak_leaves[persistent=true]
setblock ~174 ~140 ~84 oak_leaves[persistent=true]
setblock ~174 ~140 ~97 oak_leaves[persistent=true]
setblock ~174 ~140 ~98 jungle_leaves[persistent=true]
setblock ~174 ~140 ~99 jungle_leaves[persistent=true]
setblock ~174 ~140 ~100 jungle_leaves[persistent=true]
setblock ~174 ~140 ~101 oak_leaves[persistent=true]
setblock ~174 ~140 ~107 oak_leaves[persistent=true]
setblock ~174 ~140 ~109 oak_leaves[persistent=true]
setblock ~174 ~140 ~110 oak_leaves[persistent=true]
setblock ~175 ~121 ~82 dirt
setblock ~175 ~122 ~82 dirt
setblock ~175 ~123 ~82 dirt
setblock ~175 ~124 ~82 dirt
setblock ~175 ~125 ~82 grass_block
setblock ~175 ~125 ~84 spruce_slab
setblock ~175 ~126 ~72 oak_leaves[persistent=true]
setblock ~175 ~126 ~73 oak_leaves[persistent=true]
setblock ~175 ~126 ~74 oak_leaves[persistent=true]
setblock ~175 ~126 ~77 jungle_leaves[persistent=true]
setblock ~175 ~126 ~78 jungle_leaves[persistent=true]
setblock ~175 ~126 ~79 jungle_leaves[persistent=true]
setblock ~175 ~126 ~80 oak_leaves[persistent=true]
setblock ~175 ~126 ~81 spruce_slab
setblock ~175 ~126 ~82 oak_log
setblock ~175 ~127 ~72 jungle_leaves[persistent=true]
setblock ~175 ~127 ~73 jungle_leaves[persistent=true]
setblock ~175 ~127 ~74 jungle_leaves[persistent=true]
setblock ~175 ~127 ~75 jungle_leaves[persistent=true]
setblock ~175 ~127 ~76 jungle_leaves[persistent=true]
setblock ~175 ~127 ~77 jungle_leaves[persistent=true]
setblock ~175 ~127 ~78 oak_leaves[persistent=true]
setblock ~175 ~127 ~79 oak_leaves[persistent=true]
setblock ~175 ~127 ~80 jungle_leaves[persistent=true]
setblock ~175 ~127 ~82 oak_log
setblock ~175 ~127 ~94 jungle_leaves[persistent=true]
setblock ~175 ~127 ~95 oak_leaves[persistent=true]
setblock ~175 ~127 ~96 oak_leaves[persistent=true]
setblock ~175 ~127 ~97 jungle_leaves[persistent=true]
setblock ~175 ~127 ~129 oak_leaves[persistent=true]
setblock ~175 ~127 ~130 oak_leaves[persistent=true]
setblock ~175 ~128 ~72 oak_leaves[persistent=true]
setblock ~175 ~128 ~73 oak_leaves[persistent=true]
setblock ~175 ~128 ~74 oak_leaves[persistent=true]
setblock ~175 ~128 ~75 jungle_leaves[persistent=true]
setblock ~175 ~128 ~77 oak_leaves[persistent=true]
setblock ~175 ~128 ~79 oak_leaves[persistent=true]
setblock ~175 ~128 ~80 oak_wood
setblock ~175 ~128 ~81 oak_leaves[persistent=true]
setblock ~175 ~128 ~82 oak_log
setblock ~175 ~128 ~83 oak_leaves[persistent=true]
setblock ~175 ~128 ~84 jungle_leaves[persistent=true]
setblock ~175 ~128 ~85 oak_leaves[persistent=true]
setblock ~175 ~128 ~87 oak_leaves[persistent=true]
setblock ~175 ~128 ~91 oak_leaves[persistent=true]
setblock ~175 ~128 ~92 jungle_leaves[persistent=true]
setblock ~175 ~128 ~93 oak_leaves[persistent=true]
setblock ~175 ~128 ~94 oak_leaves[persistent=true]
setblock ~175 ~128 ~95 oak_leaves[persistent=true]
setblock ~175 ~128 ~97 oak_leaves[persistent=true]
setblock ~175 ~128 ~98 oak_leaves[persistent=true]
setblock ~175 ~128 ~99 oak_leaves[persistent=true]
setblock ~175 ~128 ~100 jungle_leaves[persistent=true]
setblock ~175 ~128 ~101 oak_leaves[persistent=true]
setblock ~175 ~128 ~119 oak_leaves[persistent=true]
setblock ~175 ~128 ~121 oak_leaves[persistent=true]
setblock ~175 ~128 ~128 oak_leaves[persistent=true]
setblock ~175 ~128 ~129 oak_leaves[persistent=true]
setblock ~175 ~129 ~70 jungle_leaves[persistent=true]
setblock ~175 ~129 ~71 oak_leaves[persistent=true]
setblock ~175 ~129 ~72 oak_leaves[persistent=true]
setblock ~175 ~129 ~74 oak_leaves[persistent=true]
setblock ~175 ~129 ~75 oak_leaves[persistent=true]
setblock ~175 ~129 ~76 oak_wood
setblock ~175 ~129 ~78 oak_leaves[persistent=true]
setblock ~175 ~129 ~79 oak_leaves[persistent=true]
setblock ~175 ~129 ~80 oak_leaves[persistent=true]
setblock ~175 ~129 ~81 oak_leaves[persistent=true]
setblock ~175 ~129 ~82 oak_log
setblock ~175 ~129 ~84 spruce_slab[type=top]
setblock ~175 ~129 ~85 oak_leaves[persistent=true]
setblock ~175 ~129 ~86 jungle_leaves[persistent=true]
setblock ~175 ~129 ~87 oak_leaves[persistent=true]
setblock ~175 ~129 ~88 oak_leaves[persistent=true]
setblock ~175 ~129 ~91 oak_leaves[persistent=true]
setblock ~175 ~129 ~93 jungle_leaves[persistent=true]
setblock ~175 ~129 ~94 jungle_leaves[persistent=true]
setblock ~175 ~129 ~95 oak_leaves[persistent=true]
setblock ~175 ~129 ~96 oak_wood
setblock ~175 ~129 ~97 oak_leaves[persistent=true]
setblock ~175 ~129 ~98 oak_leaves[persistent=true]
setblock ~175 ~129 ~99 oak_wood
setblock ~175 ~129 ~100 oak_leaves[persistent=true]
setblock ~175 ~129 ~101 oak_leaves[persistent=true]
setblock ~175 ~129 ~102 jungle_leaves[persistent=true]
setblock ~175 ~129 ~104 oak_leaves[persistent=true]
setblock ~175 ~129 ~105 oak_leaves[persistent=true]
setblock ~175 ~129 ~107 jungle_leaves[persistent=true]
setblock ~175 ~129 ~115 oak_leaves[persistent=true]
setblock ~175 ~129 ~116 oak_leaves[persistent=true]
setblock ~175 ~129 ~117 jungle_leaves[persistent=true]
setblock ~175 ~129 ~118 oak_leaves[persistent=true]
setblock ~175 ~129 ~119 oak_leaves[persistent=true]
setblock ~175 ~129 ~120 oak_leaves[persistent=true]
setblock ~175 ~129 ~121 oak_leaves[persistent=true]
setblock ~175 ~129 ~128 oak_leaves[persistent=true]
setblock ~175 ~129 ~129 oak_leaves[persistent=true]
setblock ~175 ~129 ~130 oak_leaves[persistent=true]
setblock ~175 ~129 ~131 jungle_leaves[persistent=true]
setblock ~175 ~130 ~70 oak_leaves[persistent=true]
setblock ~175 ~130 ~72 oak_leaves[persistent=true]
setblock ~175 ~130 ~73 oak_leaves[persistent=true]
setblock ~175 ~130 ~74 oak_leaves[persistent=true]
setblock ~175 ~130 ~76 jungle_leaves[persistent=true]
setblock ~175 ~130 ~77 oak_wood
setblock ~175 ~130 ~78 jungle_leaves[persistent=true]
setblock ~175 ~130 ~80 oak_leaves[persistent=true]
setblock ~175 ~130 ~81 jungle_leaves[persistent=true]
setblock ~175 ~130 ~82 oak_log
setblock ~175 ~130 ~83 oak_wood
setblock ~175 ~130 ~84 oak_log
setblock ~175 ~130 ~85 oak_leaves[persistent=true]
setblock ~175 ~130 ~86 oak_leaves[persistent=true]
setblock ~175 ~130 ~87 oak_wood
setblock ~175 ~130 ~88 oak_leaves[persistent=true]
setblock ~175 ~130 ~89 oak_leaves[persistent=true]
setblock ~175 ~130 ~90 oak_leaves[persistent=true]
setblock ~175 ~130 ~91 oak_leaves[persistent=true]
setblock ~175 ~130 ~92 oak_leaves[persistent=true]
setblock ~175 ~130 ~93 oak_leaves[persistent=true]
setblock ~175 ~130 ~94 oak_leaves[persistent=true]
setblock ~175 ~130 ~96 oak_wood
setblock ~175 ~130 ~97 oak_leaves[persistent=true]
setblock ~175 ~130 ~98 oak_leaves[persistent=true]
setblock ~175 ~130 ~99 oak_wood
setblock ~175 ~130 ~100 oak_wood
setblock ~175 ~130 ~101 oak_leaves[persistent=true]
setblock ~175 ~130 ~102 oak_leaves[persistent=true]
setblock ~175 ~130 ~104 jungle_leaves[persistent=true]
setblock ~175 ~130 ~105 jungle_leaves[persistent=true]
setblock ~175 ~130 ~106 oak_leaves[persistent=true]
setblock ~175 ~130 ~107 oak_leaves[persistent=true]
setblock ~175 ~130 ~114 jungle_leaves[persistent=true]
setblock ~175 ~130 ~115 oak_leaves[persistent=true]
setblock ~175 ~130 ~116 oak_leaves[persistent=true]
setblock ~175 ~130 ~117 oak_leaves[persistent=true]
setblock ~175 ~130 ~118 oak_leaves[persistent=true]
setblock ~175 ~130 ~119 oak_leaves[persistent=true]
setblock ~175 ~130 ~120 oak_leaves[persistent=true]
setblock ~175 ~130 ~128 oak_leaves[persistent=true]
setblock ~175 ~130 ~129 oak_leaves[persistent=true]
setblock ~175 ~130 ~130 oak_leaves[persistent=true]
setblock ~175 ~130 ~131 oak_leaves[persistent=true]
setblock ~175 ~131 ~70 oak_leaves[persistent=true]
setblock ~175 ~131 ~71 oak_leaves[persistent=true]
setblock ~175 ~131 ~72 oak_wood
setblock ~175 ~131 ~73 jungle_leaves[persistent=true]
setblock ~175 ~131 ~75 jungle_leaves[persistent=true]
setblock ~175 ~131 ~76 oak_leaves[persistent=true]
setblock ~175 ~131 ~77 oak_leaves[persistent=true]
setblock ~175 ~131 ~78 jungle_leaves[persistent=true]
setblock ~175 ~131 ~79 oak_leaves[persistent=true]
setblock ~175 ~131 ~80 oak_leaves[persistent=true]
setblock ~175 ~131 ~81 oak_wood
setblock ~175 ~131 ~82 oak_log
setblock ~175 ~131 ~83 oak_log
setblock ~175 ~131 ~84 oak_leaves[persistent=true]
setblock ~175 ~131 ~85 oak_wood
setblock ~175 ~131 ~86 oak_wood
setblock ~175 ~131 ~87 oak_wood
setblock ~175 ~131 ~88 oak_leaves[persistent=true]
setblock ~175 ~131 ~89 oak_leaves[persistent=true]
setblock ~175 ~131 ~90 oak_leaves[persistent=true]
setblock ~175 ~131 ~92 oak_leaves[persistent=true]
setblock ~175 ~131 ~93 oak_leaves[persistent=true]
setblock ~175 ~131 ~94 oak_wood
setblock ~175 ~131 ~95 oak_leaves[persistent=true]
setblock ~175 ~131 ~96 oak_leaves[persistent=true]
setblock ~175 ~131 ~97 oak_leaves[persistent=true]
setblock ~175 ~131 ~98 jungle_leaves[persistent=true]
setblock ~175 ~131 ~99 oak_leaves[persistent=true]
setblock ~175 ~131 ~100 oak_leaves[persistent=true]
setblock ~175 ~131 ~101 oak_leaves[persistent=true]
setblock ~175 ~131 ~102 jungle_leaves[persistent=true]
setblock ~175 ~131 ~104 oak_leaves[persistent=true]
setblock ~175 ~131 ~105 oak_leaves[persistent=true]
setblock ~175 ~131 ~107 oak_leaves[persistent=true]
setblock ~175 ~131 ~108 oak_leaves[persistent=true]
setblock ~175 ~131 ~110 jungle_leaves[persistent=true]
setblock ~175 ~131 ~111 oak_leaves[persistent=true]
setblock ~175 ~131 ~112 oak_leaves[persistent=true]
setblock ~175 ~131 ~115 jungle_leaves[persistent=true]
setblock ~175 ~131 ~116 oak_wood
setblock ~175 ~131 ~117 oak_leaves[persistent=true]
setblock ~175 ~131 ~118 oak_leaves[persistent=true]
setblock ~175 ~131 ~119 jungle_leaves[persistent=true]
setblock ~175 ~131 ~120 oak_leaves[persistent=true]
setblock ~175 ~131 ~121 oak_leaves[persistent=true]
setblock ~175 ~132 ~70 jungle_leaves[persistent=true]
setblock ~175 ~132 ~71 jungle_leaves[persistent=true]
setblock ~175 ~132 ~72 oak_wood
setblock ~175 ~132 ~74 jungle_leaves[persistent=true]
setblock ~175 ~132 ~75 oak_leaves[persistent=true]
setblock ~175 ~132 ~76 oak_wood
setblock ~175 ~132 ~78 oak_leaves[persistent=true]
setblock ~175 ~132 ~79 oak_leaves[persistent=true]
setblock ~175 ~132 ~80 oak_leaves[persistent=true]
setblock ~175 ~132 ~81 oak_leaves[persistent=true]
setblock ~175 ~132 ~82 oak_log
setblock ~175 ~132 ~83 jungle_leaves[persistent=true]
setblock ~175 ~132 ~84 oak_wood
setblock ~175 ~132 ~85 jungle_leaves[persistent=true]
setblock ~175 ~132 ~86 oak_wood
setblock ~175 ~132 ~87 oak_wood
setblock ~175 ~132 ~89 oak_leaves[persistent=true]
setblock ~175 ~132 ~90 oak_leaves[persistent=true]
setblock ~175 ~132 ~92 oak_leaves[persistent=true]
setblock ~175 ~132 ~93 oak_leaves[persistent=true]
setblock ~175 ~132 ~94 oak_leaves[persistent=true]
setblock ~175 ~132 ~95 oak_leaves[persistent=true]
setblock ~175 ~132 ~96 oak_wood
setblock ~175 ~132 ~98 jungle_leaves[persistent=true]
setblock ~175 ~132 ~99 oak_leaves[persistent=true]
setblock ~175 ~132 ~100 oak_leaves[persistent=true]
setblock ~175 ~132 ~101 jungle_leaves[persistent=true]
setblock ~175 ~132 ~102 oak_wood
setblock ~175 ~132 ~103 oak_leaves[persistent=true]
setblock ~175 ~132 ~104 oak_leaves[persistent=true]
setblock ~175 ~132 ~105 jungle_leaves[persistent=true]
setblock ~175 ~132 ~106 jungle_leaves[persistent=true]
setblock ~175 ~132 ~108 oak_wood
setblock ~175 ~132 ~109 oak_leaves[persistent=true]
setblock ~175 ~132 ~110 oak_leaves[persistent=true]
setblock ~175 ~132 ~111 oak_leaves[persistent=true]
setblock ~175 ~132 ~112 oak_leaves[persistent=true]
setblock ~175 ~132 ~114 oak_leaves[persistent=true]
setblock ~175 ~132 ~115 oak_leaves[persistent=true]
setblock ~175 ~132 ~116 oak_leaves[persistent=true]
setblock ~175 ~132 ~117 oak_leaves[persistent=true]
setblock ~175 ~133 ~70 oak_leaves[persistent=true]
setblock ~175 ~133 ~71 oak_leaves[persistent=true]
setblock ~175 ~133 ~72 oak_leaves[persistent=true]
setblock ~175 ~133 ~73 oak_leaves[persistent=true]
setblock ~175 ~133 ~74 oak_leaves[persistent=true]
setblock ~175 ~133 ~75 oak_leaves[persistent=true]
setblock ~175 ~133 ~76 oak_leaves[persistent=true]
setblock ~175 ~133 ~79 oak_leaves[persistent=true]
setblock ~175 ~133 ~80 oak_leaves[persistent=true]
setblock ~175 ~133 ~81 oak_leaves[persistent=true]
setblock ~175 ~133 ~82 oak_leaves[persistent=true]
setblock ~175 ~133 ~83 oak_leaves[persistent=true]
setblock ~175 ~133 ~84 oak_wood
setblock ~175 ~133 ~85 oak_wood
setblock ~175 ~133 ~86 oak_wood
setblock ~175 ~133 ~87 oak_wood
setblock ~175 ~133 ~88 oak_wood
setblock ~175 ~133 ~89 oak_leaves[persistent=true]
setblock ~175 ~133 ~90 oak_wood
setblock ~175 ~133 ~91 oak_leaves[persistent=true]
setblock ~175 ~133 ~92 oak_wood
setblock ~175 ~133 ~93 oak_wood
setblock ~175 ~133 ~95 oak_leaves[persistent=true]
setblock ~175 ~133 ~96 oak_leaves[persistent=true]
setblock ~175 ~133 ~97 oak_wood
setblock ~175 ~133 ~98 oak_leaves[persistent=true]
setblock ~175 ~133 ~99 oak_wood
setblock ~175 ~133 ~100 oak_leaves[persistent=true]
setblock ~175 ~133 ~101 jungle_leaves[persistent=true]
setblock ~175 ~133 ~102 oak_leaves[persistent=true]
setblock ~175 ~133 ~103 jungle_leaves[persistent=true]
setblock ~175 ~133 ~104 oak_wood
setblock ~175 ~133 ~105 oak_leaves[persistent=true]
setblock ~175 ~133 ~106 oak_leaves[persistent=true]
setblock ~175 ~133 ~107 oak_leaves[persistent=true]
setblock ~175 ~133 ~108 oak_wood
setblock ~175 ~133 ~109 jungle_leaves[persistent=true]
setblock ~175 ~133 ~110 oak_wood
setblock ~175 ~133 ~111 jungle_leaves[persistent=true]
setblock ~175 ~133 ~112 oak_leaves[persistent=true]
setblock ~175 ~133 ~113 jungle_leaves[persistent=true]
setblock ~175 ~134 ~73 oak_leaves[persistent=true]
setblock ~175 ~134 ~74 oak_leaves[persistent=true]
setblock ~175 ~134 ~75 oak_leaves[persistent=true]
setblock ~175 ~134 ~76 oak_wood
setblock ~175 ~134 ~77 oak_leaves[persistent=true]
setblock ~175 ~134 ~78 oak_leaves[persistent=true]
setblock ~175 ~134 ~80 oak_wood
setblock ~175 ~134 ~81 jungle_leaves[persistent=true]
setblock ~175 ~134 ~82 oak_wood
setblock ~175 ~134 ~83 oak_wood
setblock ~175 ~134 ~84 oak_wood
setblock ~175 ~134 ~85 oak_leaves[persistent=true]
setblock ~175 ~134 ~86 oak_wood
setblock ~175 ~134 ~87 oak_wood
setblock ~175 ~134 ~88 oak_wood
setblock ~175 ~134 ~89 oak_wood
setblock ~175 ~134 ~91 oak_leaves[persistent=true]
setblock ~175 ~134 ~92 oak_leaves[persistent=true]
setblock ~175 ~134 ~93 jungle_leaves[persistent=true]
setblock ~175 ~134 ~94 oak_leaves[persistent=true]
setblock ~175 ~134 ~96 oak_wood
setblock ~175 ~134 ~97 oak_wood
setblock ~175 ~134 ~98 oak_wood
setblock ~175 ~134 ~99 oak_leaves[persistent=true]
setblock ~175 ~134 ~100 oak_wood
setblock ~175 ~134 ~101 oak_wood
setblock ~175 ~134 ~102 jungle_leaves[persistent=true]
setblock ~175 ~134 ~103 oak_leaves[persistent=true]
setblock ~175 ~134 ~104 oak_leaves[persistent=true]
setblock ~175 ~134 ~105 jungle_leaves[persistent=true]
setblock ~175 ~134 ~106 jungle_leaves[persistent=true]
setblock ~175 ~134 ~107 oak_leaves[persistent=true]
setblock ~175 ~134 ~108 oak_leaves[persistent=true]
setblock ~175 ~134 ~109 oak_leaves[persistent=true]
setblock ~175 ~134 ~110 oak_leaves[persistent=true]
setblock ~175 ~134 ~111 oak_leaves[persistent=true]
setblock ~175 ~134 ~112 oak_leaves[persistent=true]
setblock ~175 ~134 ~113 jungle_leaves[persistent=true]
setblock ~175 ~135 ~74 oak_leaves[persistent=true]
setblock ~175 ~135 ~75 oak_leaves[persistent=true]
setblock ~175 ~135 ~76 jungle_leaves[persistent=true]
setblock ~175 ~135 ~77 oak_leaves[persistent=true]
setblock ~175 ~135 ~78 oak_wood
setblock ~175 ~135 ~79 oak_wood
setblock ~175 ~135 ~80 oak_leaves[persistent=true]
setblock ~175 ~135 ~81 oak_wood
setblock ~175 ~135 ~82 oak_log
setblock ~175 ~135 ~83 oak_wood
setblock ~175 ~135 ~84 oak_wood
setblock ~175 ~135 ~85 oak_wood
setblock ~175 ~135 ~86 oak_leaves[persistent=true]
setblock ~175 ~135 ~87 oak_leaves[persistent=true]
setblock ~175 ~135 ~88 oak_leaves[persistent=true]
setblock ~175 ~135 ~89 oak_leaves[persistent=true]
setblock ~175 ~135 ~90 oak_leaves[persistent=true]
setblock ~175 ~135 ~91 oak_leaves[persistent=true]
setblock ~175 ~135 ~93 oak_wood
setblock ~175 ~135 ~94 oak_leaves[persistent=true]
setblock ~175 ~135 ~95 oak_leaves[persistent=true]
setblock ~175 ~135 ~96 oak_leaves[persistent=true]
setblock ~175 ~135 ~97 oak_leaves[persistent=true]
setblock ~175 ~135 ~98 oak_wood
setblock ~175 ~135 ~100 oak_leaves[persistent=true]
setblock ~175 ~135 ~103 oak_leaves[persistent=true]
setblock ~175 ~135 ~104 jungle_leaves[persistent=true]
setblock ~175 ~135 ~105 jungle_leaves[persistent=true]
setblock ~175 ~135 ~106 oak_leaves[persistent=true]
setblock ~175 ~135 ~107 oak_leaves[persistent=true]
setblock ~175 ~135 ~108 jungle_leaves[persistent=true]
setblock ~175 ~135 ~109 oak_wood
setblock ~175 ~135 ~110 oak_leaves[persistent=true]
setblock ~175 ~135 ~111 oak_wood
setblock ~175 ~135 ~112 oak_leaves[persistent=true]
setblock ~175 ~135 ~113 oak_leaves[persistent=true]
setblock ~175 ~135 ~114 jungle_leaves[persistent=true]
setblock ~175 ~135 ~115 oak_leaves[persistent=true]
setblock ~175 ~135 ~116 oak_leaves[persistent=true]
setblock ~175 ~136 ~72 oak_leaves[persistent=true]
setblock ~175 ~136 ~73 oak_leaves[persistent=true]
setblock ~175 ~136 ~74 oak_wood
setblock ~175 ~136 ~75 oak_leaves[persistent=true]
setblock ~175 ~136 ~76 oak_leaves[persistent=true]
setblock ~175 ~136 ~77 jungle_leaves[persistent=true]
setblock ~175 ~136 ~78 oak_leaves[persistent=true]
setblock ~175 ~136 ~79 oak_wood
setblock ~175 ~136 ~80 jungle_leaves[persistent=true]
setblock ~175 ~136 ~81 jungle_leaves[persistent=true]
setblock ~175 ~136 ~82 oak_wood
setblock ~175 ~136 ~83 oak_log
setblock ~175 ~136 ~84 jungle_leaves[persistent=true]
setblock ~175 ~136 ~85 oak_wood
setblock ~175 ~136 ~86 jungle_leaves[persistent=true]
setblock ~175 ~136 ~87 oak_leaves[persistent=true]
setblock ~175 ~136 ~88 oak_leaves[persistent=true]
setblock ~175 ~136 ~89 oak_leaves[persistent=true]
setblock ~175 ~136 ~90 oak_leaves[persistent=true]
setblock ~175 ~136 ~91 jungle_leaves[persistent=true]
setblock ~175 ~136 ~92 oak_log
setblock ~175 ~136 ~93 jungle_leaves[persistent=true]
setblock ~175 ~136 ~95 oak_leaves[persistent=true]
setblock ~175 ~136 ~96 oak_wood
setblock ~175 ~136 ~97 oak_wood
setblock ~175 ~136 ~99 oak_leaves[persistent=true]
setblock ~175 ~136 ~100 oak_leaves[persistent=true]
setblock ~175 ~136 ~101 oak_wood
setblock ~175 ~136 ~102 oak_leaves[persistent=true]
setblock ~175 ~136 ~103 oak_wood
setblock ~175 ~136 ~104 oak_leaves[persistent=true]
setblock ~175 ~136 ~105 oak_leaves[persistent=true]
setblock ~175 ~136 ~107 oak_leaves[persistent=true]
setblock ~175 ~136 ~108 oak_wood
setblock ~175 ~136 ~110 oak_leaves[persistent=true]
setblock ~175 ~136 ~112 oak_leaves[persistent=true]
setblock ~175 ~136 ~113 oak_leaves[persistent=true]
setblock ~175 ~136 ~114 jungle_leaves[persistent=true]
setblock ~175 ~136 ~115 oak_leaves[persistent=true]
setblock ~175 ~136 ~116 oak_leaves[persistent=true]
setblock ~175 ~137 ~72 oak_leaves[persistent=true]
setblock ~175 ~137 ~73 oak_leaves[persistent=true]
setblock ~175 ~137 ~74 oak_leaves[persistent=true]
setblock ~175 ~137 ~75 oak_leaves[persistent=true]
setblock ~175 ~137 ~76 oak_leaves[persistent=true]
setblock ~175 ~137 ~77 jungle_leaves[persistent=true]
setblock ~175 ~137 ~78 jungle_leaves[persistent=true]
setblock ~175 ~137 ~79 oak_leaves[persistent=true]
setblock ~175 ~137 ~80 oak_wood
setblock ~175 ~137 ~81 oak_wood
setblock ~175 ~137 ~82 oak_wood
setblock ~175 ~137 ~83 oak_leaves[persistent=true]
setblock ~175 ~137 ~84 oak_leaves[persistent=true]
setblock ~175 ~137 ~85 oak_leaves[persistent=true]
setblock ~175 ~137 ~86 oak_leaves[persistent=true]
setblock ~175 ~137 ~87 oak_leaves[persistent=true]
setblock ~175 ~137 ~88 oak_wood
setblock ~175 ~137 ~89 oak_leaves[persistent=true]
setblock ~175 ~137 ~90 oak_leaves[persistent=true]
setblock ~175 ~137 ~91 oak_leaves[persistent=true]
setblock ~175 ~137 ~92 jungle_leaves[persistent=true]
setblock ~175 ~137 ~93 oak_leaves[persistent=true]
setblock ~175 ~137 ~94 oak_leaves[persistent=true]
setblock ~175 ~137 ~95 jungle_leaves[persistent=true]
setblock ~175 ~137 ~96 oak_leaves[persistent=true]
setblock ~175 ~137 ~97 jungle_leaves[persistent=true]
setblock ~175 ~137 ~98 oak_leaves[persistent=true]
setblock ~175 ~137 ~101 oak_leaves[persistent=true]
setblock ~175 ~137 ~102 jungle_leaves[persistent=true]
setblock ~175 ~137 ~103 oak_wood
setblock ~175 ~137 ~104 oak_leaves[persistent=true]
setblock ~175 ~137 ~105 oak_leaves[persistent=true]
setblock ~175 ~137 ~106 oak_wood
setblock ~175 ~137 ~107 oak_leaves[persistent=true]
setblock ~175 ~137 ~108 oak_leaves[persistent=true]
setblock ~175 ~137 ~109 oak_leaves[persistent=true]
setblock ~175 ~137 ~110 oak_leaves[persistent=true]
setblock ~175 ~137 ~111 oak_leaves[persistent=true]
setblock ~175 ~137 ~112 oak_leaves[persistent=true]
setblock ~175 ~137 ~113 oak_leaves[persistent=true]
setblock ~175 ~137 ~114 oak_wood
setblock ~175 ~137 ~115 oak_leaves[persistent=true]
setblock ~175 ~137 ~116 oak_leaves[persistent=true]
setblock ~175 ~137 ~117 oak_leaves[persistent=true]
setblock ~175 ~137 ~118 jungle_leaves[persistent=true]
setblock ~175 ~138 ~66 jungle_leaves[persistent=true]
setblock ~175 ~138 ~67 oak_leaves[persistent=true]
setblock ~175 ~138 ~68 oak_leaves[persistent=true]
setblock ~175 ~138 ~72 oak_leaves[persistent=true]
setblock ~175 ~138 ~73 oak_leaves[persistent=true]
setblock ~175 ~138 ~74 oak_leaves[persistent=true]
setblock ~175 ~138 ~75 oak_leaves[persistent=true]
setblock ~175 ~138 ~76 oak_leaves[persistent=true]
setblock ~175 ~138 ~77 oak_leaves[persistent=true]
setblock ~175 ~138 ~78 oak_leaves[persistent=true]
setblock ~175 ~138 ~79 oak_leaves[persistent=true]
setblock ~175 ~138 ~80 oak_leaves[persistent=true]
setblock ~175 ~138 ~81 jungle_leaves[persistent=true]
setblock ~175 ~138 ~82 oak_log
setblock ~175 ~138 ~83 oak_log
setblock ~175 ~138 ~84 oak_leaves[persistent=true]
setblock ~175 ~138 ~85 jungle_leaves[persistent=true]
setblock ~175 ~138 ~86 oak_leaves[persistent=true]
setblock ~175 ~138 ~87 oak_leaves[persistent=true]
setblock ~175 ~138 ~88 oak_leaves[persistent=true]
setblock ~175 ~138 ~89 oak_leaves[persistent=true]
setblock ~175 ~138 ~90 jungle_leaves[persistent=true]
setblock ~175 ~138 ~91 jungle_leaves[persistent=true]
setblock ~175 ~138 ~92 oak_leaves[persistent=true]
setblock ~175 ~138 ~93 oak_leaves[persistent=true]
setblock ~175 ~138 ~95 oak_leaves[persistent=true]
setblock ~175 ~138 ~96 oak_leaves[persistent=true]
setblock ~175 ~138 ~97 oak_leaves[persistent=true]
setblock ~175 ~138 ~98 oak_leaves[persistent=true]
setblock ~175 ~138 ~99 jungle_leaves[persistent=true]
setblock ~175 ~138 ~100 oak_leaves[persistent=true]
setblock ~175 ~138 ~101 oak_leaves[persistent=true]
setblock ~175 ~138 ~102 oak_leaves[persistent=true]
setblock ~175 ~138 ~103 oak_leaves[persistent=true]
setblock ~175 ~138 ~104 oak_leaves[persistent=true]
setblock ~175 ~138 ~105 oak_leaves[persistent=true]
setblock ~175 ~138 ~106 oak_leaves[persistent=true]
setblock ~175 ~138 ~107 oak_leaves[persistent=true]
setblock ~175 ~138 ~108 oak_leaves[persistent=true]
setblock ~175 ~138 ~109 oak_leaves[persistent=true]
setblock ~175 ~138 ~110 oak_leaves[persistent=true]
setblock ~175 ~138 ~112 jungle_leaves[persistent=true]
setblock ~175 ~138 ~113 oak_leaves[persistent=true]
setblock ~175 ~138 ~114 oak_leaves[persistent=true]
setblock ~175 ~138 ~115 oak_wood
setblock ~175 ~138 ~116 jungle_leaves[persistent=true]
setblock ~175 ~138 ~117 oak_wood
setblock ~175 ~138 ~118 oak_leaves[persistent=true]
setblock ~175 ~139 ~67 oak_leaves[persistent=true]
setblock ~175 ~139 ~68 oak_leaves[persistent=true]
setblock ~175 ~139 ~72 jungle_leaves[persistent=true]
setblock ~175 ~139 ~73 oak_leaves[persistent=true]
setblock ~175 ~139 ~75 oak_leaves[persistent=true]
setblock ~175 ~139 ~76 oak_leaves[persistent=true]
setblock ~175 ~139 ~77 oak_leaves[persistent=true]
setblock ~175 ~139 ~78 oak_leaves[persistent=true]
setblock ~175 ~139 ~79 oak_leaves[persistent=true]
setblock ~175 ~139 ~80 oak_leaves[persistent=true]
setblock ~175 ~139 ~81 oak_leaves[persistent=true]
setblock ~175 ~139 ~82 oak_leaves[persistent=true]
setblock ~175 ~139 ~83 oak_leaves[persistent=true]
setblock ~175 ~139 ~84 oak_leaves[persistent=true]
setblock ~175 ~139 ~85 oak_leaves[persistent=true]
setblock ~175 ~139 ~93 jungle_leaves[persistent=true]
setblock ~175 ~139 ~94 oak_leaves[persistent=true]
setblock ~175 ~139 ~102 oak_leaves[persistent=true]
setblock ~175 ~139 ~103 jungle_leaves[persistent=true]
setblock ~175 ~139 ~104 oak_leaves[persistent=true]
setblock ~175 ~139 ~105 oak_leaves[persistent=true]
setblock ~175 ~139 ~106 oak_leaves[persistent=true]
setblock ~175 ~139 ~107 oak_leaves[persistent=true]
setblock ~175 ~139 ~108 oak_leaves[persistent=true]
setblock ~175 ~139 ~109 jungle_leaves[persistent=true]
setblock ~175 ~139 ~110 oak_leaves[persistent=true]
setblock ~175 ~139 ~115 oak_leaves[persistent=true]
setblock ~175 ~139 ~116 oak_leaves[persistent=true]
setblock ~175 ~139 ~117 jungle_leaves[persistent=true]
setblock ~175 ~140 ~66 oak_leaves[persistent=true]
setblock ~175 ~140 ~67 oak_leaves[persistent=true]
setblock ~175 ~140 ~68 oak_leaves[persistent=true]
setblock ~175 ~140 ~79 oak_leaves[persistent=true]
setblock ~175 ~140 ~80 oak_leaves[persistent=true]
setblock ~175 ~140 ~81 oak_leaves[persistent=true]
setblock ~175 ~140 ~82 oak_leaves[persistent=true]
setblock ~175 ~140 ~83 oak_leaves[persistent=true]
setblock ~175 ~140 ~84 oak_leaves[persistent=true]
setblock ~175 ~140 ~107 oak_leaves[persistent=true]
setblock ~175 ~140 ~108 oak_leaves[persistent=true]
setblock ~175 ~140 ~109 oak_leaves[persistent=true]
setblock ~175 ~140 ~110 jungle_leaves[persistent=true]
setblock ~176 ~126 ~77 jungle_leaves[persistent=true]
setblock ~176 ~126 ~78 oak_leaves[persistent=true]
setblock ~176 ~126 ~79 oak_leaves[persistent=true]
setblock ~176 ~126 ~81 spruce_slab
setblock ~176 ~127 ~74 jungle_leaves[persistent=true]
setblock ~176 ~127 ~75 jungle_leaves[persistent=true]
setblock ~176 ~127 ~76 jungle_leaves[persistent=true]
setblock ~176 ~127 ~77 oak_leaves[persistent=true]
setblock ~176 ~127 ~78 oak_leaves[persistent=true]
setblock ~176 ~127 ~79 jungle_leaves[persistent=true]
setblock ~176 ~127 ~80 oak_leaves[persistent=true]
setblock ~176 ~127 ~81 oak_leaves[persistent=true]
setblock ~176 ~127 ~94 oak_leaves[persistent=true]
setblock ~176 ~127 ~95 oak_leaves[persistent=true]
setblock ~176 ~127 ~96 oak_leaves[persistent=true]
setblock ~176 ~127 ~97 oak_leaves[persistent=true]
setblock ~176 ~127 ~128 oak_leaves[persistent=true]
setblock ~176 ~127 ~129 jungle_leaves[persistent=true]
setblock ~176 ~127 ~130 jungle_leaves[persistent=true]
setblock ~176 ~127 ~131 oak_leaves[persistent=true]
setblock ~176 ~128 ~74 jungle_leaves[persistent=true]
setblock ~176 ~128 ~75 oak_leaves[persistent=true]
setblock ~176 ~128 ~76 oak_leaves[persistent=true]
setblock ~176 ~128 ~77 jungle_leaves[persistent=true]
setblock ~176 ~128 ~78 oak_leaves[persistent=true]
setblock ~176 ~128 ~79 oak_leaves[persistent=true]
setblock ~176 ~128 ~81 oak_leaves[persistent=true]
setblock ~176 ~128 ~83 oak_leaves[persistent=true]
setblock ~176 ~128 ~85 oak_leaves[persistent=true]
setblock ~176 ~128 ~86 oak_leaves[persistent=true]
setblock ~176 ~128 ~87 oak_leaves[persistent=true]
setblock ~176 ~128 ~88 oak_leaves[persistent=true]
setblock ~176 ~128 ~94 oak_leaves[persistent=true]
setblock ~176 ~128 ~95 oak_leaves[persistent=true]
setblock ~176 ~128 ~96 jungle_leaves[persistent=true]
setblock ~176 ~128 ~97 oak_leaves[persistent=true]
setblock ~176 ~128 ~98 oak_leaves[persistent=true]
setblock ~176 ~128 ~99 jungle_leaves[persistent=true]
setblock ~176 ~128 ~100 jungle_leaves[persistent=true]
setblock ~176 ~128 ~128 oak_leaves[persistent=true]
setblock ~176 ~128 ~129 oak_leaves[persistent=true]
setblock ~176 ~128 ~130 jungle_leaves[persistent=true]
setblock ~176 ~128 ~131 jungle_leaves[persistent=true]
setblock ~176 ~129 ~70 oak_leaves[persistent=true]
setblock ~176 ~129 ~71 oak_leaves[persistent=true]
setblock ~176 ~129 ~72 oak_leaves[persistent=true]
setblock ~176 ~129 ~73 oak_leaves[persistent=true]
setblock ~176 ~129 ~74 oak_leaves[persistent=true]
setblock ~176 ~129 ~75 oak_leaves[persistent=true]
setblock ~176 ~129 ~76 oak_leaves[persistent=true]
setblock ~176 ~129 ~77 oak_leaves[persistent=true]
setblock ~176 ~129 ~78 oak_leaves[persistent=true]
setblock ~176 ~129 ~79 oak_leaves[persistent=true]
setblock ~176 ~129 ~80 jungle_leaves[persistent=true]
setblock ~176 ~129 ~81 oak_leaves[persistent=true]
setblock ~176 ~129 ~82 jungle_leaves[persistent=true]
setblock ~176 ~129 ~83 oak_leaves[persistent=true]
setblock ~176 ~129 ~84 oak_leaves[persistent=true]
setblock ~176 ~129 ~85 oak_leaves[persistent=true]
setblock ~176 ~129 ~86 jungle_leaves[persistent=true]
setblock ~176 ~129 ~88 oak_leaves[persistent=true]
setblock ~176 ~129 ~92 oak_leaves[persistent=true]
setblock ~176 ~129 ~93 oak_leaves[persistent=true]
setblock ~176 ~129 ~94 oak_leaves[persistent=true]
setblock ~176 ~129 ~95 oak_leaves[persistent=true]
setblock ~176 ~129 ~96 jungle_leaves[persistent=true]
setblock ~176 ~129 ~97 jungle_leaves[persistent=true]
setblock ~176 ~129 ~98 oak_leaves[persistent=true]
setblock ~176 ~129 ~99 oak_leaves[persistent=true]
setblock ~176 ~129 ~100 oak_leaves[persistent=true]
setblock ~176 ~129 ~101 oak_leaves[persistent=true]
setblock ~176 ~129 ~102 oak_leaves[persistent=true]
setblock ~176 ~129 ~114 jungle_leaves[persistent=true]
setblock ~176 ~129 ~115 oak_leaves[persistent=true]
setblock ~176 ~129 ~116 oak_leaves[persistent=true]
setblock ~176 ~129 ~117 oak_leaves[persistent=true]
setblock ~176 ~129 ~128 oak_leaves[persistent=true]
setblock ~176 ~129 ~129 oak_leaves[persistent=true]
setblock ~176 ~129 ~130 oak_leaves[persistent=true]
setblock ~176 ~129 ~131 jungle_leaves[persistent=true]
setblock ~176 ~130 ~71 oak_wood
setblock ~176 ~130 ~72 oak_leaves[persistent=true]
setblock ~176 ~130 ~73 oak_leaves[persistent=true]
setblock ~176 ~130 ~74 oak_leaves[persistent=true]
setblock ~176 ~130 ~75 jungle_leaves[persistent=true]
setblock ~176 ~130 ~76 oak_leaves[persistent=true]
setblock ~176 ~130 ~77 oak_leaves[persistent=true]
setblock ~176 ~130 ~78 oak_leaves[persistent=true]
setblock ~176 ~130 ~79 oak_leaves[persistent=true]
setblock ~176 ~130 ~80 oak_leaves[persistent=true]
setblock ~176 ~130 ~81 oak_leaves[persistent=true]
setblock ~176 ~130 ~82 oak_leaves[persistent=true]
setblock ~176 ~130 ~83 oak_wood
setblock ~176 ~130 ~84 jungle_leaves[persistent=true]
setblock ~176 ~130 ~85 oak_leaves[persistent=true]
setblock ~176 ~130 ~86 oak_leaves[persistent=true]
setblock ~176 ~130 ~87 oak_wood
setblock ~176 ~130 ~88 oak_leaves[persistent=true]
setblock ~176 ~130 ~91 oak_leaves[persistent=true]
setblock ~176 ~130 ~92 oak_leaves[persistent=true]
setblock ~176 ~130 ~94 oak_leaves[persistent=true]
setblock ~176 ~130 ~95 oak_leaves[persistent=true]
setblock ~176 ~130 ~96 oak_leaves[persistent=true]
setblock ~176 ~130 ~97 oak_leaves[persistent=true]
setblock ~176 ~130 ~98 oak_leaves[persistent=true]
setblock ~176 ~130 ~99 oak_leaves[persistent=true]
setblock ~176 ~130 ~100 oak_wood
setblock ~176 ~130 ~101 oak_leaves[persistent=true]
setblock ~176 ~130 ~102 oak_leaves[persistent=true]
setblock ~176 ~130 ~103 oak_leaves[persistent=true]
setblock ~176 ~130 ~104 oak_leaves[persistent=true]
setblock ~176 ~130 ~105 oak_leaves[persistent=true]
setblock ~176 ~130 ~114 oak_leaves[persistent=true]
setblock ~176 ~130 ~115 oak_leaves[persistent=true]
setblock ~176 ~130 ~116 jungle_leaves[persistent=true]
setblock ~176 ~130 ~117 oak_leaves[persistent=true]
setblock ~176 ~130 ~128 oak_leaves[persistent=true]
setblock ~176 ~130 ~129 oak_leaves[persistent=true]
setblock ~176 ~130 ~130 oak_leaves[persistent=true]
setblock ~176 ~130 ~131 oak_leaves[persistent=true]
setblock ~176 ~131 ~70 oak_leaves[persistent=true]
setblock ~176 ~131 ~71 oak_leaves[persistent=true]
setblock ~176 ~131 ~72 oak_leaves[persistent=true]
setblock ~176 ~131 ~73 oak_leaves[persistent=true]
setblock ~176 ~131 ~74 oak_leaves[persistent=true]
setblock ~176 ~131 ~75 oak_leaves[persistent=true]
setblock ~176 ~131 ~76 oak_leaves[persistent=true]
setblock ~176 ~131 ~77 jungle_leaves[persistent=true]
setblock ~176 ~131 ~78 oak_leaves[persistent=true]
setblock ~176 ~131 ~79 oak_leaves[persistent=true]
setblock ~176 ~131 ~80 oak_leaves[persistent=true]
setblock ~176 ~131 ~81 oak_leaves[persistent=true]
setblock ~176 ~131 ~82 oak_leaves[persistent=true]
setblock ~176 ~131 ~83 oak_leaves[persistent=true]
setblock ~176 ~131 ~84 oak_leaves[persistent=true]
setblock ~176 ~131 ~85 oak_leaves[persistent=true]
setblock ~176 ~131 ~86 oak_wood
setblock ~176 ~131 ~87 oak_leaves[persistent=true]
setblock ~176 ~131 ~88 oak_leaves[persistent=true]
setblock ~176 ~131 ~89 jungle_leaves[persistent=true]
setblock ~176 ~131 ~90 oak_leaves[persistent=true]
setblock ~176 ~131 ~91 oak_leaves[persistent=true]
setblock ~176 ~131 ~92 oak_leaves[persistent=true]
setblock ~176 ~131 ~93 oak_wood
setblock ~176 ~131 ~94 oak_leaves[persistent=true]
setblock ~176 ~131 ~95 oak_leaves[persistent=true]
setblock ~176 ~131 ~96 oak_leaves[persistent=true]
setblock ~176 ~131 ~97 oak_leaves[persistent=true]
setblock ~176 ~131 ~98 jungle_leaves[persistent=true]
setblock ~176 ~131 ~99 oak_leaves[persistent=true]
setblock ~176 ~131 ~100 oak_leaves[persistent=true]
setblock ~176 ~131 ~101 oak_wood
setblock ~176 ~131 ~102 oak_leaves[persistent=true]
setblock ~176 ~131 ~103 oak_leaves[persistent=true]
setblock ~176 ~131 ~104 jungle_leaves[persistent=true]
setblock ~176 ~131 ~105 oak_leaves[persistent=true]
setblock ~176 ~131 ~106 oak_leaves[persistent=true]
setblock ~176 ~131 ~107 oak_leaves[persistent=true]
setblock ~176 ~131 ~108 jungle_leaves[persistent=true]
setblock ~176 ~131 ~109 oak_leaves[persistent=true]
setblock ~176 ~131 ~110 jungle_leaves[persistent=true]
setblock ~176 ~131 ~111 oak_leaves[persistent=true]
setblock ~176 ~131 ~112 oak_leaves[persistent=true]
setblock ~176 ~131 ~114 oak_leaves[persistent=true]
setblock ~176 ~131 ~115 oak_leaves[persistent=true]
setblock ~176 ~131 ~116 oak_leaves[persistent=true]
setblock ~176 ~131 ~117 oak_leaves[persistent=true]
setblock ~176 ~132 ~69 jungle_leaves[persistent=true]
setblock ~176 ~132 ~70 oak_leaves[persistent=true]
setblock ~176 ~132 ~71 oak_wood
setblock ~176 ~132 ~72 oak_leaves[persistent=true]
setblock ~176 ~132 ~73 oak_leaves[persistent=true]
setblock ~176 ~132 ~74 oak_leaves[persistent=true]
setblock ~176 ~132 ~75 oak_leaves[persistent=true]
setblock ~176 ~132 ~76 oak_leaves[persistent=true]
setblock ~176 ~132 ~78 oak_leaves[persistent=true]
setblock ~176 ~132 ~79 oak_leaves[persistent=true]
setblock ~176 ~132 ~80 jungle_leaves[persistent=true]
setblock ~176 ~132 ~81 oak_leaves[persistent=true]
setblock ~176 ~132 ~82 oak_leaves[persistent=true]
setblock ~176 ~132 ~83 oak_leaves[persistent=true]
setblock ~176 ~132 ~84 jungle_leaves[persistent=true]
setblock ~176 ~132 ~86 oak_leaves[persistent=true]
setblock ~176 ~132 ~87 oak_wood
setblock ~176 ~132 ~88 oak_leaves[persistent=true]
setblock ~176 ~132 ~89 oak_leaves[persistent=true]
setblock ~176 ~132 ~90 oak_leaves[persistent=true]
setblock ~176 ~132 ~91 oak_leaves[persistent=true]
setblock ~176 ~132 ~92 oak_leaves[persistent=true]
setblock ~176 ~132 ~93 oak_wood
setblock ~176 ~132 ~94 oak_leaves[persistent=true]
setblock ~176 ~132 ~96 oak_leaves[persistent=true]
setblock ~176 ~132 ~98 jungle_leaves[persistent=true]
setblock ~176 ~132 ~99 jungle_leaves[persistent=true]
setblock ~176 ~132 ~100 oak_leaves[persistent=true]
setblock ~176 ~132 ~101 oak_leaves[persistent=true]
setblock ~176 ~132 ~102 oak_leaves[persistent=true]
setblock ~176 ~132 ~103 oak_leaves[persistent=true]
setblock ~176 ~132 ~104 oak_wood
setblock ~176 ~132 ~105 oak_leaves[persistent=true]
setblock ~176 ~132 ~106 oak_leaves[persistent=true]
setblock ~176 ~132 ~107 oak_leaves[persistent=true]
setblock ~176 ~132 ~108 oak_leaves[persistent=true]
setblock ~176 ~132 ~110 oak_leaves[persistent=true]
setblock ~176 ~132 ~111 jungle_leaves[persistent=true]
setblock ~176 ~132 ~112 oak_leaves[persistent=true]
setblock ~176 ~132 ~114 jungle_leaves[persistent=true]
setblock ~176 ~132 ~115 oak_leaves[persistent=true]
setblock ~176 ~132 ~116 oak_leaves[persistent=true]
setblock ~176 ~132 ~117 oak_leaves[persistent=true]
setblock ~176 ~133 ~69 oak_leaves[persistent=true]
setblock ~176 ~133 ~71 oak_leaves[persistent=true]
setblock ~176 ~133 ~73 oak_leaves[persistent=true]
setblock ~176 ~133 ~74 oak_leaves[persistent=true]
setblock ~176 ~133 ~75 jungle_leaves[persistent=true]
setblock ~176 ~133 ~76 oak_leaves[persistent=true]
setblock ~176 ~133 ~77 oak_leaves[persistent=true]
setblock ~176 ~133 ~78 oak_leaves[persistent=true]
setblock ~176 ~133 ~79 oak_leaves[persistent=true]
setblock ~176 ~133 ~80 oak_wood
setblock ~176 ~133 ~82 oak_wood
setblock ~176 ~133 ~83 oak_wood
setblock ~176 ~133 ~84 oak_wood
setblock ~176 ~133 ~86 oak_wood
setblock ~176 ~133 ~87 jungle_leaves[persistent=true]
setblock ~176 ~133 ~88 oak_leaves[persistent=true]
setblock ~176 ~133 ~89 oak_wood
setblock ~176 ~133 ~90 oak_leaves[persistent=true]
setblock ~176 ~133 ~91 oak_leaves[persistent=true]
setblock ~176 ~133 ~92 oak_leaves[persistent=true]
setblock ~176 ~133 ~94 jungle_leaves[persistent=true]
setblock ~176 ~133 ~95 oak_leaves[persistent=true]
setblock ~176 ~133 ~96 oak_leaves[persistent=true]
setblock ~176 ~133 ~97 oak_leaves[persistent=true]
setblock ~176 ~133 ~98 oak_wood
setblock ~176 ~133 ~99 oak_leaves[persistent=true]
setblock ~176 ~133 ~100 jungle_leaves[persistent=true]
setblock ~176 ~133 ~101 jungle_leaves[persistent=true]
setblock ~176 ~133 ~102 oak_leaves[persistent=true]
setblock ~176 ~133 ~103 oak_leaves[persistent=true]
setblock ~176 ~133 ~104 oak_leaves[persistent=true]
setblock ~176 ~133 ~105 jungle_leaves[persistent=true]
setblock ~176 ~133 ~106 oak_leaves[persistent=true]
setblock ~176 ~133 ~107 oak_leaves[persistent=true]
setblock ~176 ~133 ~108 oak_leaves[persistent=true]
setblock ~176 ~133 ~109 oak_leaves[persistent=true]
setblock ~176 ~133 ~110 oak_leaves[persistent=true]
setblock ~176 ~133 ~111 oak_wood
setblock ~176 ~133 ~112 oak_leaves[persistent=true]
setblock ~176 ~134 ~73 oak_leaves[persistent=true]
setblock ~176 ~134 ~74 oak_leaves[persistent=true]
setblock ~176 ~134 ~75 oak_wood
setblock ~176 ~134 ~76 oak_leaves[persistent=true]
setblock ~176 ~134 ~77 oak_leaves[persistent=true]
setblock ~176 ~134 ~78 oak_leaves[persistent=true]
setblock ~176 ~134 ~79 oak_wood
setblock ~176 ~134 ~80 oak_leaves[persistent=true]
setblock ~176 ~134 ~81 oak_wood
setblock ~176 ~134 ~82 oak_leaves[persistent=true]
setblock ~176 ~134 ~83 oak_wood
setblock ~176 ~134 ~85 oak_wood
setblock ~176 ~134 ~86 oak_wood
setblock ~176 ~134 ~87 oak_wood
setblock ~176 ~134 ~88 oak_leaves[persistent=true]
setblock ~176 ~134 ~89 oak_leaves[persistent=true]
setblock ~176 ~134 ~90 oak_leaves[persistent=true]
setblock ~176 ~134 ~91 oak_leaves[persistent=true]
setblock ~176 ~134 ~92 oak_leaves[persistent=true]
setblock ~176 ~134 ~93 oak_leaves[persistent=true]
setblock ~176 ~134 ~94 oak_leaves[persistent=true]
setblock ~176 ~134 ~95 oak_wood
setblock ~176 ~134 ~96 jungle_leaves[persistent=true]
setblock ~176 ~134 ~97 jungle_leaves[persistent=true]
setblock ~176 ~134 ~98 oak_leaves[persistent=true]
setblock ~176 ~134 ~101 oak_leaves[persistent=true]
setblock ~176 ~134 ~102 oak_leaves[persistent=true]
setblock ~176 ~134 ~103 oak_leaves[persistent=true]
setblock ~176 ~134 ~104 jungle_leaves[persistent=true]
setblock ~176 ~134 ~105 oak_leaves[persistent=true]
setblock ~176 ~134 ~106 oak_leaves[persistent=true]
setblock ~176 ~134 ~107 oak_leaves[persistent=true]
setblock ~176 ~134 ~108 oak_leaves[persistent=true]
setblock ~176 ~134 ~109 oak_leaves[persistent=true]
setblock ~176 ~134 ~110 oak_leaves[persistent=true]
setblock ~176 ~134 ~111 oak_leaves[persistent=true]
setblock ~176 ~134 ~113 jungle_leaves[persistent=true]
setblock ~176 ~135 ~73 oak_leaves[persistent=true]
setblock ~176 ~135 ~74 jungle_leaves[persistent=true]
setblock ~176 ~135 ~75 oak_leaves[persistent=true]
setblock ~176 ~135 ~76 oak_leaves[persistent=true]
setblock ~176 ~135 ~78 oak_leaves[persistent=true]
setblock ~176 ~135 ~79 oak_wood
setblock ~176 ~135 ~80 oak_wood
setblock ~176 ~135 ~81 oak_wood
setblock ~176 ~135 ~82 oak_wood
setblock ~176 ~135 ~83 jungle_leaves[persistent=true]
setblock ~176 ~135 ~84 oak_leaves[persistent=true]
setblock ~176 ~135 ~85 oak_wood
setblock ~176 ~135 ~86 oak_wood
setblock ~176 ~135 ~87 oak_leaves[persistent=true]
setblock ~176 ~135 ~88 oak_leaves[persistent=true]
setblock ~176 ~135 ~89 oak_wood
setblock ~176 ~135 ~90 oak_leaves[persistent=true]
setblock ~176 ~135 ~91 oak_leaves[persistent=true]
setblock ~176 ~135 ~92 oak_leaves[persistent=true]
setblock ~176 ~135 ~93 oak_wood
setblock ~176 ~135 ~94 oak_leaves[persistent=true]
setblock ~176 ~135 ~95 oak_leaves[persistent=true]
setblock ~176 ~135 ~96 oak_leaves[persistent=true]
setblock ~176 ~135 ~97 oak_wood
setblock ~176 ~135 ~99 oak_leaves[persistent=true]
setblock ~176 ~135 ~100 oak_leaves[persistent=true]
setblock ~176 ~135 ~101 oak_leaves[persistent=true]
setblock ~176 ~135 ~102 oak_leaves[persistent=true]
setblock ~176 ~135 ~104 oak_leaves[persistent=true]
setblock ~176 ~135 ~105 jungle_leaves[persistent=true]
setblock ~176 ~135 ~106 oak_leaves[persistent=true]
setblock ~176 ~135 ~107 oak_leaves[persistent=true]
setblock ~176 ~135 ~108 oak_leaves[persistent=true]
setblock ~176 ~135 ~109 oak_leaves[persistent=true]
setblock ~176 ~135 ~110 oak_leaves[persistent=true]
setblock ~176 ~135 ~111 oak_leaves[persistent=true]
setblock ~176 ~135 ~112 oak_leaves[persistent=true]
setblock ~176 ~135 ~113 oak_leaves[persistent=true]
setblock ~176 ~135 ~114 oak_leaves[persistent=true]
setblock ~176 ~135 ~115 oak_leaves[persistent=true]
setblock ~176 ~136 ~72 oak_leaves[persistent=true]
setblock ~176 ~136 ~73 oak_leaves[persistent=true]
setblock ~176 ~136 ~74 oak_leaves[persistent=true]
setblock ~176 ~136 ~75 oak_leaves[persistent=true]
setblock ~176 ~136 ~77 oak_leaves[persistent=true]
setblock ~176 ~136 ~78 jungle_leaves[persistent=true]
setblock ~176 ~136 ~80 oak_leaves[persistent=true]
setblock ~176 ~136 ~81 oak_wood
setblock ~176 ~136 ~82 oak_log
setblock ~176 ~136 ~83 jungle_leaves[persistent=true]
setblock ~176 ~136 ~84 oak_leaves[persistent=true]
setblock ~176 ~136 ~85 oak_leaves[persistent=true]
setblock ~176 ~136 ~86 oak_leaves[persistent=true]
setblock ~176 ~136 ~87 oak_leaves[persistent=true]
setblock ~176 ~136 ~88 oak_leaves[persistent=true]
setblock ~176 ~136 ~90 oak_leaves[persistent=true]
setblock ~176 ~136 ~91 oak_leaves[persistent=true]
setblock ~176 ~136 ~92 oak_leaves[persistent=true]
setblock ~176 ~136 ~93 oak_leaves[persistent=true]
setblock ~176 ~136 ~94 oak_leaves[persistent=true]
setblock ~176 ~136 ~95 oak_leaves[persistent=true]
setblock ~176 ~136 ~96 oak_leaves[persistent=true]
setblock ~176 ~136 ~97 jungle_leaves[persistent=true]
setblock ~176 ~136 ~98 oak_leaves[persistent=true]
setblock ~176 ~136 ~99 oak_leaves[persistent=true]
setblock ~176 ~136 ~100 oak_leaves[persistent=true]
setblock ~176 ~136 ~101 oak_leaves[persistent=true]
setblock ~176 ~136 ~102 oak_wood
setblock ~176 ~136 ~103 jungle_leaves[persistent=true]
setblock ~176 ~136 ~104 oak_leaves[persistent=true]
setblock ~176 ~136 ~105 oak_leaves[persistent=true]
setblock ~176 ~136 ~106 jungle_leaves[persistent=true]
setblock ~176 ~136 ~107 oak_leaves[persistent=true]
setblock ~176 ~136 ~108 oak_wood
setblock ~176 ~136 ~111 oak_leaves[persistent=true]
setblock ~176 ~136 ~112 oak_leaves[persistent=true]
setblock ~176 ~136 ~113 oak_leaves[persistent=true]
setblock ~176 ~136 ~114 oak_leaves[persistent=true]
setblock ~176 ~136 ~115 jungle_leaves[persistent=true]
setblock ~176 ~136 ~116 oak_leaves[persistent=true]
setblock ~176 ~137 ~72 oak_leaves[persistent=true]
setblock ~176 ~137 ~73 jungle_leaves[persistent=true]
setblock ~176 ~137 ~74 jungle_leaves[persistent=true]
setblock ~176 ~137 ~75 jungle_leaves[persistent=true]
setblock ~176 ~137 ~76 oak_leaves[persistent=true]
setblock ~176 ~137 ~77 jungle_leaves[persistent=true]
setblock ~176 ~137 ~78 oak_wood
setblock ~176 ~137 ~79 oak_wood
setblock ~176 ~137 ~80 oak_wood
setblock ~176 ~137 ~81 oak_wood
setblock ~176 ~137 ~82 oak_wood
setblock ~176 ~137 ~83 oak_wood
setblock ~176 ~137 ~84 oak_wood
setblock ~176 ~137 ~85 oak_leaves[persistent=true]
setblock ~176 ~137 ~86 oak_leaves[persistent=true]
setblock ~176 ~137 ~87 oak_leaves[persistent=true]
setblock ~176 ~137 ~88 oak_leaves[persistent=true]
setblock ~176 ~137 ~89 oak_leaves[persistent=true]
setblock ~176 ~137 ~90 oak_leaves[persistent=true]
setblock ~176 ~137 ~91 oak_leaves[persistent=true]
setblock ~176 ~137 ~92 oak_leaves[persistent=true]
setblock ~176 ~137 ~94 jungle_leaves[persistent=true]
setblock ~176 ~137 ~95 jungle_leaves[persistent=true]
setblock ~176 ~137 ~96 oak_leaves[persistent=true]
setblock ~176 ~137 ~97 jungle_leaves[persistent=true]
setblock ~176 ~137 ~99 oak_leaves[persistent=true]
setblock ~176 ~137 ~100 jungle_leaves[persistent=true]
setblock ~176 ~137 ~101 oak_leaves[persistent=true]
setblock ~176 ~137 ~102 oak_leaves[persistent=true]
setblock ~176 ~137 ~103 oak_wood
setblock ~176 ~137 ~104 oak_leaves[persistent=true]
setblock ~176 ~137 ~105 oak_wood
setblock ~176 ~137 ~106 jungle_leaves[persistent=true]
setblock ~176 ~137 ~107 oak_leaves[persistent=true]
setblock ~176 ~137 ~108 oak_leaves[persistent=true]
setblock ~176 ~137 ~109 oak_leaves[persistent=true]
setblock ~176 ~137 ~110 oak_leaves[persistent=true]
setblock ~176 ~137 ~113 jungle_leaves[persistent=true]
setblock ~176 ~137 ~115 oak_leaves[persistent=true]
setblock ~176 ~137 ~118 oak_leaves[persistent=true]
setblock ~176 ~138 ~66 oak_leaves[persistent=true]
setblock ~176 ~138 ~67 oak_leaves[persistent=true]
setblock ~176 ~138 ~68 oak_leaves[persistent=true]
setblock ~176 ~138 ~72 oak_leaves[persistent=true]
setblock ~176 ~138 ~73 oak_leaves[persistent=true]
setblock ~176 ~138 ~74 oak_wood
setblock ~176 ~138 ~75 oak_wood
setblock ~176 ~138 ~76 oak_wood
setblock ~176 ~138 ~77 oak_wood
setblock ~176 ~138 ~78 oak_leaves[persistent=true]
setblock ~176 ~138 ~79 oak_wood
setblock ~176 ~138 ~80 oak_leaves[persistent=true]
setblock ~176 ~138 ~81 oak_leaves[persistent=true]
setblock ~176 ~138 ~82 oak_wood
setblock ~176 ~138 ~83 oak_log
setblock ~176 ~138 ~84 jungle_leaves[persistent=true]
setblock ~176 ~138 ~85 jungle_leaves[persistent=true]
setblock ~176 ~138 ~86 oak_leaves[persistent=true]
setblock ~176 ~138 ~87 oak_leaves[persistent=true]
setblock ~176 ~138 ~88 jungle_leaves[persistent=true]
setblock ~176 ~138 ~89 oak_leaves[persistent=true]
setblock ~176 ~138 ~90 oak_leaves[persistent=true]
setblock ~176 ~138 ~91 oak_leaves[persistent=true]
setblock ~176 ~138 ~92 jungle_leaves[persistent=true]
setblock ~176 ~138 ~93 oak_leaves[persistent=true]
setblock ~176 ~138 ~94 oak_leaves[persistent=true]
setblock ~176 ~138 ~95 oak_leaves[persistent=true]
setblock ~176 ~138 ~97 oak_leaves[persistent=true]
setblock ~176 ~138 ~98 oak_leaves[persistent=true]
setblock ~176 ~138 ~99 oak_leaves[persistent=true]
setblock ~176 ~138 ~100 jungle_leaves[persistent=true]
setblock ~176 ~138 ~101 jungle_leaves[persistent=true]
setblock ~176 ~138 ~102 oak_leaves[persistent=true]
setblock ~176 ~138 ~104 oak_leaves[persistent=true]
setblock ~176 ~138 ~105 oak_leaves[persistent=true]
setblock ~176 ~138 ~106 oak_leaves[persistent=true]
setblock ~176 ~138 ~107 oak_leaves[persistent=true]
setblock ~176 ~138 ~110 oak_leaves[persistent=true]
setblock ~176 ~138 ~113 oak_leaves[persistent=true]
setblock ~176 ~138 ~114 oak_leaves[persistent=true]
setblock ~176 ~138 ~115 oak_leaves[persistent=true]
setblock ~176 ~138 ~116 oak_wood
setblock ~176 ~138 ~118 oak_leaves[persistent=true]
setblock ~176 ~139 ~66 oak_leaves[persistent=true]
setblock ~176 ~139 ~67 oak_leaves[persistent=true]
setblock ~176 ~139 ~68 jungle_leaves[persistent=true]
setblock ~176 ~139 ~72 oak_leaves[persistent=true]
setblock ~176 ~139 ~73 oak_leaves[persistent=true]
setblock ~176 ~139 ~74 jungle_leaves[persistent=true]
setblock ~176 ~139 ~75 oak_leaves[persistent=true]
setblock ~176 ~139 ~76 oak_leaves[persistent=true]
setblock ~176 ~139 ~78 oak_leaves[persistent=true]
setblock ~176 ~139 ~80 oak_leaves[persistent=true]
setblock ~176 ~139 ~81 oak_leaves[persistent=true]
setblock ~176 ~139 ~82 oak_leaves[persistent=true]
setblock ~176 ~139 ~83 jungle_leaves[persistent=true]
setblock ~176 ~139 ~84 jungle_leaves[persistent=true]
setblock ~176 ~139 ~85 oak_leaves[persistent=true]
setblock ~176 ~139 ~102 oak_leaves[persistent=true]
setblock ~176 ~139 ~103 jungle_leaves[persistent=true]
setblock ~176 ~139 ~104 oak_leaves[persistent=true]
setblock ~176 ~139 ~105 oak_leaves[persistent=true]
setblock ~176 ~139 ~107 jungle_leaves[persistent=true]
setblock ~176 ~139 ~108 jungle_leaves[persistent=true]
setblock ~176 ~139 ~109 oak_leaves[persistent=true]
setblock ~176 ~139 ~115 oak_leaves[persistent=true]
setblock ~176 ~139 ~116 oak_leaves[persistent=true]
setblock ~176 ~139 ~117 oak_leaves[persistent=true]
setblock ~176 ~139 ~118 jungle_leaves[persistent=true]
setblock ~176 ~140 ~66 jungle_leaves[persistent=true]
setblock ~176 ~140 ~67 jungle_leaves[persistent=true]
setblock ~176 ~140 ~68 oak_leaves[persistent=true]
setblock ~176 ~140 ~75 oak_leaves[persistent=true]
setblock ~176 ~140 ~76 oak_leaves[persistent=true]
setblock ~176 ~140 ~77 jungle_leaves[persistent=true]
setblock ~176 ~140 ~78 oak_leaves[persistent=true]
setblock ~176 ~140 ~79 oak_leaves[persistent=true]
setblock ~176 ~140 ~80 oak_leaves[persistent=true]
setblock ~176 ~140 ~81 oak_leaves[persistent=true]
setblock ~176 ~140 ~82 jungle_leaves[persistent=true]
setblock ~176 ~140 ~83 oak_leaves[persistent=true]
setblock ~176 ~140 ~84 oak_leaves[persistent=true]
setblock ~176 ~140 ~107 oak_leaves[persistent=true]
setblock ~176 ~140 ~108 oak_leaves[persistent=true]
setblock ~176 ~140 ~109 oak_leaves[persistent=true]
setblock ~176 ~140 ~110 jungle_leaves[persistent=true]
setblock ~177 ~126 ~78 oak_leaves[persistent=true]
setblock ~177 ~126 ~79 oak_leaves[persistent=true]
setblock ~177 ~126 ~80 oak_leaves[persistent=true]
setblock ~177 ~127 ~77 oak_leaves[persistent=true]
setblock ~177 ~127 ~78 jungle_leaves[persistent=true]
setblock ~177 ~127 ~79 jungle_leaves[persistent=true]
setblock ~177 ~127 ~80 jungle_leaves[persistent=true]
setblock ~177 ~127 ~81 oak_leaves[persistent=true]
setblock ~177 ~127 ~82 oak_leaves[persistent=true]
setblock ~177 ~128 ~75 oak_leaves[persistent=true]
setblock ~177 ~128 ~77 oak_leaves[persistent=true]
setblock ~177 ~128 ~78 oak_leaves[persistent=true]
setblock ~177 ~128 ~79 oak_leaves[persistent=true]
setblock ~177 ~128 ~80 oak_leaves[persistent=true]
setblock ~177 ~128 ~81 oak_leaves[persistent=true]
setblock ~177 ~128 ~82 oak_leaves[persistent=true]
setblock ~177 ~128 ~83 oak_leaves[persistent=true]
setblock ~177 ~128 ~85 oak_leaves[persistent=true]
setblock ~177 ~128 ~86 oak_leaves[persistent=true]
setblock ~177 ~128 ~87 oak_leaves[persistent=true]
setblock ~177 ~128 ~88 oak_leaves[persistent=true]
setblock ~177 ~128 ~99 oak_leaves[persistent=true]
setblock ~177 ~128 ~100 oak_leaves[persistent=true]
setblock ~177 ~128 ~101 oak_leaves[persistent=true]
setblock ~177 ~129 ~70 oak_leaves[persistent=true]
setblock ~177 ~129 ~74 oak_leaves[persistent=true]
setblock ~177 ~129 ~75 oak_leaves[persistent=true]
setblock ~177 ~129 ~76 oak_leaves[persistent=true]
setblock ~177 ~129 ~77 oak_leaves[persistent=true]
setblock ~177 ~129 ~78 oak_leaves[persistent=true]
setblock ~177 ~129 ~79 oak_leaves[persistent=true]
setblock ~177 ~129 ~80 oak_leaves[persistent=true]
setblock ~177 ~129 ~81 oak_leaves[persistent=true]
setblock ~177 ~129 ~82 oak_wood
setblock ~177 ~129 ~83 oak_leaves[persistent=true]
setblock ~177 ~129 ~84 oak_leaves[persistent=true]
setblock ~177 ~129 ~85 jungle_leaves[persistent=true]
setblock ~177 ~129 ~86 oak_leaves[persistent=true]
setblock ~177 ~129 ~87 oak_leaves[persistent=true]
setblock ~177 ~129 ~88 jungle_leaves[persistent=true]
setblock ~177 ~129 ~91 jungle_leaves[persistent=true]
setblock ~177 ~129 ~92 oak_leaves[persistent=true]
setblock ~177 ~129 ~93 oak_leaves[persistent=true]
setblock ~177 ~129 ~94 jungle_leaves[persistent=true]
setblock ~177 ~129 ~99 oak_leaves[persistent=true]
setblock ~177 ~129 ~100 oak_wood
setblock ~177 ~129 ~101 oak_leaves[persistent=true]
setblock ~177 ~129 ~102 oak_leaves[persistent=true]
setblock ~177 ~129 ~103 jungle_leaves[persistent=true]
setblock ~177 ~129 ~104 oak_leaves[persistent=true]
setblock ~177 ~129 ~105 oak_leaves[persistent=true]
setblock ~177 ~130 ~70 oak_leaves[persistent=true]
setblock ~177 ~130 ~71 jungle_leaves[persistent=true]
setblock ~177 ~130 ~74 oak_leaves[persistent=true]
setblock ~177 ~130 ~75 oak_leaves[persistent=true]
setblock ~177 ~130 ~76 oak_leaves[persistent=true]
setblock ~177 ~130 ~77 jungle_leaves[persistent=true]
setblock ~177 ~130 ~79 oak_leaves[persistent=true]
setblock ~177 ~130 ~80 oak_leaves[persistent=true]
setblock ~177 ~130 ~81 oak_leaves[persistent=true]
setblock ~177 ~130 ~82 oak_leaves[persistent=true]
setblock ~177 ~130 ~83 oak_leaves[persistent=true]
setblock ~177 ~130 ~84 oak_leaves[persistent=true]
setblock ~177 ~130 ~85 oak_leaves[persistent=true]
setblock ~177 ~130 ~86 oak_leaves[persistent=true]
setblock ~177 ~130 ~87 oak_leaves[persistent=true]
setblock ~177 ~130 ~88 oak_leaves[persistent=true]
setblock ~177 ~130 ~92 oak_leaves[persistent=true]
setblock ~177 ~130 ~93 oak_leaves[persistent=true]
setblock ~177 ~130 ~94 jungle_leaves[persistent=true]
setblock ~177 ~130 ~99 oak_leaves[persistent=true]
setblock ~177 ~130 ~100 oak_leaves[persistent=true]
setblock ~177 ~130 ~101 oak_leaves[persistent=true]
setblock ~177 ~130 ~102 oak_leaves[persistent=true]
setblock ~177 ~130 ~103 oak_leaves[persistent=true]
setblock ~177 ~130 ~104 oak_leaves[persistent=true]
setblock ~177 ~130 ~105 oak_leaves[persistent=true]
setblock ~177 ~130 ~106 jungle_leaves[persistent=true]
setblock ~177 ~131 ~71 oak_leaves[persistent=true]
setblock ~177 ~131 ~72 oak_leaves[persistent=true]
setblock ~177 ~131 ~75 oak_leaves[persistent=true]
setblock ~177 ~131 ~76 oak_leaves[persistent=true]
setblock ~177 ~131 ~77 oak_leaves[persistent=true]
setblock ~177 ~131 ~78 oak_leaves[persistent=true]
setblock ~177 ~131 ~79 jungle_leaves[persistent=true]
setblock ~177 ~131 ~81 oak_leaves[persistent=true]
setblock ~177 ~131 ~82 oak_leaves[persistent=true]
setblock ~177 ~131 ~83 oak_leaves[persistent=true]
setblock ~177 ~131 ~84 oak_leaves[persistent=true]
setblock ~177 ~131 ~85 oak_leaves[persistent=true]
setblock ~177 ~131 ~86 oak_wood
setblock ~177 ~131 ~87 jungle_leaves[persistent=true]
setblock ~177 ~131 ~88 jungle_leaves[persistent=true]
setblock ~177 ~131 ~90 oak_leaves[persistent=true]
setblock ~177 ~131 ~91 oak_leaves[persistent=true]
setblock ~177 ~131 ~92 jungle_leaves[persistent=true]
setblock ~177 ~131 ~93 oak_leaves[persistent=true]
setblock ~177 ~131 ~94 oak_leaves[persistent=true]
setblock ~177 ~131 ~96 jungle_leaves[persistent=true]
setblock ~177 ~131 ~97 oak_leaves[persistent=true]
setblock ~177 ~131 ~98 oak_leaves[persistent=true]
setblock ~177 ~131 ~99 oak_leaves[persistent=true]
setblock ~177 ~131 ~100 oak_leaves[persistent=true]
setblock ~177 ~131 ~101 oak_wood
setblock ~177 ~131 ~102 oak_leaves[persistent=true]
setblock ~177 ~131 ~103 oak_leaves[persistent=true]
setblock ~177 ~131 ~104 oak_leaves[persistent=true]
setblock ~177 ~131 ~105 oak_leaves[persistent=true]
setblock ~177 ~131 ~106 oak_leaves[persistent=true]
setblock ~177 ~131 ~110 jungle_leaves[persistent=true]
setblock ~177 ~131 ~111 oak_leaves[persistent=true]
setblock ~177 ~131 ~112 oak_leaves[persistent=true]
setblock ~177 ~132 ~69 oak_leaves[persistent=true]
setblock ~177 ~132 ~70 jungle_leaves[persistent=true]
setblock ~177 ~132 ~71 oak_leaves[persistent=true]
setblock ~177 ~132 ~72 oak_leaves[persistent=true]
setblock ~177 ~132 ~74 oak_leaves[persistent=true]
setblock ~177 ~132 ~77 oak_leaves[persistent=true]
setblock ~177 ~132 ~78 oak_leaves[persistent=true]
setblock ~177 ~132 ~79 oak_wood
setblock ~177 ~132 ~80 oak_leaves[persistent=true]
setblock ~177 ~132 ~81 oak_leaves[persistent=true]
setblock ~177 ~132 ~82 oak_leaves[persistent=true]
setblock ~177 ~132 ~84 oak_leaves[persistent=true]
setblock ~177 ~132 ~87 oak_leaves[persistent=true]
setblock ~177 ~132 ~88 oak_wood
setblock ~177 ~132 ~89 oak_wood
setblock ~177 ~132 ~90 oak_leaves[persistent=true]
setblock ~177 ~132 ~91 oak_leaves[persistent=true]
setblock ~177 ~132 ~92 oak_leaves[persistent=true]
setblock ~177 ~132 ~93 oak_leaves[persistent=true]
setblock ~177 ~132 ~94 oak_leaves[persistent=true]
setblock ~177 ~132 ~95 oak_leaves[persistent=true]
setblock ~177 ~132 ~96 jungle_leaves[persistent=true]
setblock ~177 ~132 ~97 oak_leaves[persistent=true]
setblock ~177 ~132 ~98 oak_leaves[persistent=true]
setblock ~177 ~132 ~99 jungle_leaves[persistent=true]
setblock ~177 ~132 ~100 oak_leaves[persistent=true]
setblock ~177 ~132 ~101 oak_leaves[persistent=true]
setblock ~177 ~132 ~102 oak_leaves[persistent=true]
setblock ~177 ~132 ~103 oak_leaves[persistent=true]
setblock ~177 ~132 ~104 jungle_leaves[persistent=true]
