setblock ~170 ~124 ~82 dirt
setblock ~170 ~124 ~83 dirt
setblock ~170 ~124 ~84 dirt
setblock ~170 ~124 ~85 dirt
setblock ~170 ~124 ~86 dirt
setblock ~170 ~124 ~87 dirt
setblock ~170 ~124 ~88 dirt
setblock ~170 ~124 ~89 dirt
setblock ~170 ~124 ~90 dirt
setblock ~170 ~124 ~91 dirt
setblock ~170 ~124 ~92 dirt
setblock ~170 ~124 ~99 dirt
setblock ~170 ~124 ~100 dirt
setblock ~170 ~124 ~101 dirt
setblock ~170 ~124 ~106 dirt
setblock ~170 ~124 ~108 dirt
setblock ~170 ~125 ~72 dirt
setblock ~170 ~125 ~73 dirt
setblock ~170 ~125 ~74 dirt
setblock ~170 ~125 ~75 dirt
setblock ~170 ~125 ~76 dirt
setblock ~170 ~125 ~77 dirt
setblock ~170 ~125 ~78 dirt
setblock ~170 ~125 ~79 dirt
setblock ~170 ~125 ~80 dirt
setblock ~170 ~125 ~81 dirt
setblock ~170 ~125 ~82 dirt
setblock ~170 ~125 ~83 dirt
setblock ~170 ~125 ~84 dirt
setblock ~170 ~125 ~85 dirt
setblock ~170 ~125 ~86 dirt
setblock ~170 ~125 ~87 dirt
setblock ~170 ~125 ~88 dirt
setblock ~170 ~125 ~89 grass_block
setblock ~170 ~125 ~90 grass_block
setblock ~170 ~125 ~91 grass_block
setblock ~170 ~125 ~92 grass_block
setblock ~170 ~125 ~99 dirt
setblock ~170 ~125 ~100 dirt
setblock ~170 ~125 ~101 dirt
setblock ~170 ~125 ~106 dirt
setblock ~170 ~125 ~108 grass_block
setblock ~170 ~126 ~72 grass_block
setblock ~170 ~126 ~73 grass_block
setblock ~170 ~126 ~74 dirt
setblock ~170 ~126 ~75 dirt
setblock ~170 ~126 ~76 dirt
setblock ~170 ~126 ~77 dirt
setblock ~170 ~126 ~78 dirt
setblock ~170 ~126 ~79 dirt
setblock ~170 ~126 ~80 dirt
setblock ~170 ~126 ~81 dirt
setblock ~170 ~126 ~82 dirt
setblock ~170 ~126 ~83 dirt
setblock ~170 ~126 ~84 dirt
setblock ~170 ~126 ~85 dirt
setblock ~170 ~126 ~86 dirt
setblock ~170 ~126 ~87 grass_block
setblock ~170 ~126 ~88 grass_block
setblock ~170 ~126 ~90 short_grass
setblock ~170 ~126 ~91 short_grass
setblock ~170 ~126 ~92 short_grass
setblock ~170 ~126 ~99 dirt
setblock ~170 ~126 ~100 dirt
setblock ~170 ~126 ~101 dirt
setblock ~170 ~126 ~106 grass_block
setblock ~170 ~126 ~108 poppy
setblock ~170 ~127 ~74 grass_block
setblock ~170 ~127 ~75 dirt
setblock ~170 ~127 ~76 dirt
setblock ~170 ~127 ~77 dirt
setblock ~170 ~127 ~78 dirt
setblock ~170 ~127 ~79 dirt
setblock ~170 ~127 ~80 dirt
setblock ~170 ~127 ~81 dirt
setblock ~170 ~127 ~82 dirt
setblock ~170 ~127 ~83 dirt
setblock ~170 ~127 ~84 dirt
setblock ~170 ~127 ~85 grass_block
setblock ~170 ~127 ~86 grass_block
setblock ~170 ~127 ~99 grass_block
setblock ~170 ~127 ~100 grass_block
setblock ~170 ~127 ~101 grass_block
setblock ~170 ~128 ~74 short_grass
setblock ~170 ~128 ~75 grass_block
setblock ~170 ~128 ~76 dirt
setblock ~170 ~128 ~77 dirt
setblock ~170 ~128 ~78 dirt
setblock ~170 ~128 ~79 dirt
setblock ~170 ~128 ~80 dirt
setblock ~170 ~128 ~81 dirt
setblock ~170 ~128 ~82 dirt
setblock ~170 ~128 ~83 dirt
setblock ~170 ~128 ~84 grass_block
setblock ~170 ~128 ~86 poppy
setblock ~170 ~128 ~100 short_grass
setblock ~170 ~129 ~76 grass_block
setblock ~170 ~129 ~77 dirt
setblock ~170 ~129 ~78 dirt
setblock ~170 ~129 ~79 dirt
setblock ~170 ~129 ~80 dirt
setblock ~170 ~129 ~81 dirt
setblock ~170 ~129 ~82 dirt
setblock ~170 ~129 ~83 grass_block
setblock ~170 ~130 ~77 grass_block
setblock ~170 ~130 ~78 dirt
setblock ~170 ~130 ~79 dirt
setblock ~170 ~130 ~80 dirt
setblock ~170 ~130 ~81 dirt
setblock ~170 ~130 ~82 grass_block
setblock ~170 ~131 ~78 grass_block
setblock ~170 ~131 ~79 dirt
setblock ~170 ~131 ~80 dirt
setblock ~170 ~131 ~81 grass_block
setblock ~170 ~132 ~79 grass_block
setblock ~170 ~132 ~80 grass_block
setblock ~170 ~132 ~81 short_grass
setblock ~171 ~115 ~79 dirt
setblock ~171 ~115 ~80 dirt
setblock ~171 ~115 ~82 dirt
setblock ~171 ~115 ~84 dirt
setblock ~171 ~116 ~78 dirt
setblock ~171 ~116 ~79 dirt
setblock ~171 ~116 ~80 dirt
setblock ~171 ~116 ~81 dirt
setblock ~171 ~116 ~82 dirt
setblock ~171 ~116 ~83 dirt
setblock ~171 ~116 ~84 dirt
setblock ~171 ~116 ~85 dirt
setblock ~171 ~116 ~86 dirt
setblock ~171 ~117 ~78 dirt
setblock ~171 ~117 ~79 dirt
setblock ~171 ~117 ~80 dirt
setblock ~171 ~117 ~81 dirt
setblock ~171 ~117 ~82 dirt
setblock ~171 ~117 ~83 dirt
setblock ~171 ~117 ~84 dirt
setblock ~171 ~117 ~85 dirt
setblock ~171 ~117 ~86 dirt
setblock ~171 ~118 ~77 dirt
setblock ~171 ~118 ~78 dirt
setblock ~171 ~118 ~79 dirt
setblock ~171 ~118 ~80 dirt
setblock ~171 ~118 ~81 dirt
setblock ~171 ~118 ~82 dirt
setblock ~171 ~118 ~83 dirt
setblock ~171 ~118 ~84 dirt
setblock ~171 ~118 ~85 dirt
setblock ~171 ~118 ~86 dirt
setblock ~171 ~119 ~75 dirt
setblock ~171 ~119 ~77 dirt
setblock ~171 ~119 ~78 dirt
setblock ~171 ~119 ~79 dirt
setblock ~171 ~119 ~80 dirt
setblock ~171 ~119 ~81 dirt
setblock ~171 ~119 ~82 dirt
setblock ~171 ~119 ~83 dirt
setblock ~171 ~119 ~84 dirt
setblock ~171 ~119 ~85 dirt
setblock ~171 ~119 ~86 dirt
setblock ~171 ~119 ~87 dirt
setblock ~171 ~120 ~74 dirt
setblock ~171 ~120 ~75 dirt
setblock ~171 ~120 ~76 dirt
setblock ~171 ~120 ~77 dirt
setblock ~171 ~120 ~78 dirt
setblock ~171 ~120 ~79 dirt
setblock ~171 ~120 ~80 dirt
setblock ~171 ~120 ~81 dirt
setblock ~171 ~120 ~82 dirt
setblock ~171 ~120 ~83 dirt
setblock ~171 ~120 ~84 dirt
setblock ~171 ~120 ~85 dirt
setblock ~171 ~120 ~86 dirt
setblock ~171 ~120 ~87 dirt
setblock ~171 ~121 ~73 dirt
setblock ~171 ~121 ~74 dirt
setblock ~171 ~121 ~75 dirt
setblock ~171 ~121 ~76 dirt
setblock ~171 ~121 ~77 dirt
setblock ~171 ~121 ~78 dirt
setblock ~171 ~121 ~79 dirt
setblock ~171 ~121 ~80 dirt
setblock ~171 ~121 ~81 dirt
setblock ~171 ~121 ~82 dirt
setblock ~171 ~121 ~83 dirt
setblock ~171 ~121 ~84 dirt
setblock ~171 ~121 ~85 dirt
setblock ~171 ~121 ~86 dirt
setblock ~171 ~121 ~87 dirt
setblock ~171 ~121 ~88 dirt
setblock ~171 ~121 ~100 dirt
setblock ~171 ~122 ~73 dirt
setblock ~171 ~122 ~74 dirt
setblock ~171 ~122 ~75 dirt
setblock ~171 ~122 ~76 dirt
setblock ~171 ~122 ~77 dirt
setblock ~171 ~122 ~78 dirt
setblock ~171 ~122 ~79 dirt
setblock ~171 ~122 ~80 dirt
setblock ~171 ~122 ~81 dirt
setblock ~171 ~122 ~82 dirt
setblock ~171 ~122 ~83 dirt
setblock ~171 ~122 ~84 dirt
setblock ~171 ~122 ~85 dirt
setblock ~171 ~122 ~86 dirt
setblock ~171 ~122 ~87 dirt
setblock ~171 ~122 ~88 dirt
setblock ~171 ~122 ~100 dirt
setblock ~171 ~123 ~73 dirt
setblock ~171 ~123 ~74 dirt
setblock ~171 ~123 ~75 dirt
setblock ~171 ~123 ~76 dirt
setblock ~171 ~123 ~77 dirt
setblock ~171 ~123 ~78 dirt
setblock ~171 ~123 ~79 dirt
setblock ~171 ~123 ~80 dirt
setblock ~171 ~123 ~81 dirt
setblock ~171 ~123 ~82 dirt
setblock ~171 ~123 ~83 dirt
setblock ~171 ~123 ~84 dirt
setblock ~171 ~123 ~85 dirt
setblock ~171 ~123 ~86 dirt
setblock ~171 ~123 ~87 dirt
setblock ~171 ~123 ~88 dirt
setblock ~171 ~123 ~100 dirt
setblock ~171 ~124 ~73 dirt
setblock ~171 ~124 ~74 dirt
setblock ~171 ~124 ~75 dirt
setblock ~171 ~124 ~76 dirt
setblock ~171 ~124 ~77 dirt
setblock ~171 ~124 ~78 dirt
setblock ~171 ~124 ~79 dirt
setblock ~171 ~124 ~80 dirt
setblock ~171 ~124 ~81 dirt
setblock ~171 ~124 ~82 dirt
setblock ~171 ~124 ~83 dirt
setblock ~171 ~124 ~84 dirt
setblock ~171 ~124 ~85 dirt
setblock ~171 ~124 ~86 dirt
setblock ~171 ~124 ~87 dirt
setblock ~171 ~124 ~88 dirt
setblock ~171 ~124 ~100 dirt
setblock ~171 ~125 ~73 dirt
setblock ~171 ~125 ~74 dirt
setblock ~171 ~125 ~75 dirt
setblock ~171 ~125 ~76 dirt
setblock ~171 ~125 ~77 dirt
setblock ~171 ~125 ~78 dirt
setblock ~171 ~125 ~79 dirt
setblock ~171 ~125 ~80 dirt
setblock ~171 ~125 ~81 dirt
setblock ~171 ~125 ~82 dirt
setblock ~171 ~125 ~83 dirt
setblock ~171 ~125 ~84 dirt
setblock ~171 ~125 ~85 dirt
setblock ~171 ~125 ~86 dirt
setblock ~171 ~125 ~87 dirt
setblock ~171 ~125 ~88 dirt
setblock ~171 ~125 ~100 dirt
setblock ~171 ~126 ~73 grass_block
setblock ~171 ~126 ~74 dirt
setblock ~171 ~126 ~75 dirt
setblock ~171 ~126 ~76 dirt
setblock ~171 ~126 ~77 dirt
setblock ~171 ~126 ~78 dirt
setblock ~171 ~126 ~79 dirt
setblock ~171 ~126 ~80 dirt
setblock ~171 ~126 ~81 dirt
setblock ~171 ~126 ~82 dirt
setblock ~171 ~126 ~83 dirt
setblock ~171 ~126 ~84 dirt
setblock ~171 ~126 ~85 dirt
setblock ~171 ~126 ~86 dirt
setblock ~171 ~126 ~87 grass_block
setblock ~171 ~126 ~88 grass_block
setblock ~171 ~126 ~100 dirt
setblock ~171 ~127 ~73 fern
setblock ~171 ~127 ~74 grass_block
setblock ~171 ~127 ~75 dirt
setblock ~171 ~127 ~76 dirt
setblock ~171 ~127 ~77 dirt
setblock ~171 ~127 ~78 dirt
setblock ~171 ~127 ~79 dirt
setblock ~171 ~127 ~80 dirt
setblock ~171 ~127 ~81 dirt
setblock ~171 ~127 ~82 dirt
setblock ~171 ~127 ~83 dirt
setblock ~171 ~127 ~84 dirt
setblock ~171 ~127 ~85 grass_block
setblock ~171 ~127 ~86 grass_block
setblock ~171 ~127 ~87 short_grass
setblock ~171 ~127 ~100 grass_block
setblock ~171 ~128 ~74 short_grass
setblock ~171 ~128 ~75 grass_block
setblock ~171 ~128 ~76 dirt
setblock ~171 ~128 ~77 dirt
setblock ~171 ~128 ~78 dirt
setblock ~171 ~128 ~79 dirt
setblock ~171 ~128 ~80 dirt
setblock ~171 ~128 ~81 dirt
setblock ~171 ~128 ~82 dirt
setblock ~171 ~128 ~83 grass_block
setblock ~171 ~128 ~84 grass_block
setblock ~171 ~128 ~86 short_grass
setblock ~171 ~128 ~100 short_grass
setblock ~171 ~129 ~76 grass_block
setblock ~171 ~129 ~77 grass_block
setblock ~171 ~129 ~78 dirt
setblock ~171 ~129 ~79 dirt
setblock ~171 ~129 ~80 dirt
setblock ~171 ~129 ~81 dirt
setblock ~171 ~129 ~82 grass_block
setblock ~171 ~129 ~84 short_grass
setblock ~171 ~130 ~77 short_grass
setblock ~171 ~130 ~78 grass_block
setblock ~171 ~130 ~79 dirt
setblock ~171 ~130 ~80 dirt
setblock ~171 ~130 ~81 grass_block
setblock ~171 ~130 ~82 short_grass
setblock ~171 ~131 ~79 grass_block
setblock ~171 ~131 ~80 grass_block
setblock ~171 ~132 ~79 short_grass
setblock ~172 ~116 ~84 dirt
setblock ~172 ~117 ~79 dirt
setblock ~172 ~117 ~83 dirt
setblock ~172 ~117 ~84 dirt
setblock ~172 ~117 ~85 dirt
setblock ~172 ~118 ~78 dirt
setblock ~172 ~118 ~79 dirt
setblock ~172 ~118 ~80 dirt
setblock ~172 ~118 ~82 dirt
setblock ~172 ~118 ~83 dirt
setblock ~172 ~118 ~84 dirt
setblock ~172 ~118 ~85 dirt
setblock ~172 ~119 ~78 dirt
setblock ~172 ~119 ~79 dirt
setblock ~172 ~119 ~80 dirt
setblock ~172 ~119 ~81 dirt
setblock ~172 ~119 ~82 dirt
setblock ~172 ~119 ~83 dirt
setblock ~172 ~119 ~84 dirt
setblock ~172 ~119 ~85 dirt
setblock ~172 ~119 ~86 dirt
setblock ~172 ~120 ~75 dirt
setblock ~172 ~120 ~77 dirt
setblock ~172 ~120 ~78 dirt
setblock ~172 ~120 ~79 dirt
setblock ~172 ~120 ~80 dirt
setblock ~172 ~120 ~81 dirt
setblock ~172 ~120 ~82 dirt
setblock ~172 ~120 ~83 dirt
setblock ~172 ~120 ~84 dirt
setblock ~172 ~120 ~85 dirt
setblock ~172 ~120 ~86 dirt
setblock ~172 ~120 ~87 dirt
setblock ~172 ~121 ~75 dirt
setblock ~172 ~121 ~77 dirt
setblock ~172 ~121 ~78 dirt
setblock ~172 ~121 ~79 dirt
setblock ~172 ~121 ~80 dirt
setblock ~172 ~121 ~81 dirt
setblock ~172 ~121 ~82 dirt
setblock ~172 ~121 ~83 dirt
setblock ~172 ~121 ~84 dirt
setblock ~172 ~121 ~85 dirt
setblock ~172 ~121 ~86 dirt
setblock ~172 ~121 ~87 dirt
setblock ~172 ~121 ~88 dirt
setblock ~172 ~122 ~75 dirt
setblock ~172 ~122 ~77 dirt
setblock ~172 ~122 ~78 dirt
setblock ~172 ~122 ~79 dirt
setblock ~172 ~122 ~80 dirt
setblock ~172 ~122 ~81 dirt
setblock ~172 ~122 ~82 dirt
setblock ~172 ~122 ~83 dirt
setblock ~172 ~122 ~84 dirt
setblock ~172 ~122 ~85 dirt
setblock ~172 ~122 ~86 dirt
setblock ~172 ~122 ~87 dirt
setblock ~172 ~122 ~88 dirt
setblock ~172 ~123 ~75 dirt
setblock ~172 ~123 ~77 dirt
setblock ~172 ~123 ~78 dirt
setblock ~172 ~123 ~79 dirt
setblock ~172 ~123 ~80 dirt
setblock ~172 ~123 ~81 dirt
setblock ~172 ~123 ~82 dirt
setblock ~172 ~123 ~83 dirt
setblock ~172 ~123 ~84 dirt
setblock ~172 ~123 ~85 dirt
setblock ~172 ~123 ~86 dirt
setblock ~172 ~123 ~87 dirt
setblock ~172 ~123 ~88 dirt
setblock ~172 ~124 ~75 dirt
setblock ~172 ~124 ~77 dirt
setblock ~172 ~124 ~78 dirt
setblock ~172 ~124 ~79 dirt
setblock ~172 ~124 ~80 dirt
setblock ~172 ~124 ~81 dirt
setblock ~172 ~124 ~82 dirt
setblock ~172 ~124 ~83 dirt
setblock ~172 ~124 ~84 dirt
setblock ~172 ~124 ~85 dirt
setblock ~172 ~124 ~86 dirt
setblock ~172 ~124 ~87 dirt
setblock ~172 ~124 ~88 dirt
setblock ~172 ~125 ~75 dirt
setblock ~172 ~125 ~77 dirt
setblock ~172 ~125 ~78 dirt
setblock ~172 ~125 ~79 dirt
setblock ~172 ~125 ~80 dirt
setblock ~172 ~125 ~81 dirt
setblock ~172 ~125 ~82 dirt
setblock ~172 ~125 ~83 dirt
setblock ~172 ~125 ~84 dirt
setblock ~172 ~125 ~85 dirt
setblock ~172 ~125 ~86 dirt
setblock ~172 ~125 ~87 dirt
setblock ~172 ~125 ~88 dirt
setblock ~172 ~126 ~75 dirt
setblock ~172 ~126 ~77 dirt
setblock ~172 ~126 ~78 dirt
setblock ~172 ~126 ~79 dirt
setblock ~172 ~126 ~80 dirt
setblock ~172 ~126 ~81 dirt
setblock ~172 ~126 ~82 dirt
setblock ~172 ~126 ~83 dirt
setblock ~172 ~126 ~84 dirt
setblock ~172 ~126 ~85 dirt
setblock ~172 ~126 ~86 dirt
setblock ~172 ~126 ~87 grass_block
setblock ~172 ~126 ~88 grass_block
setblock ~172 ~127 ~75 dirt
setblock ~172 ~127 ~77 dirt
setblock ~172 ~127 ~78 dirt
setblock ~172 ~127 ~79 dirt
setblock ~172 ~127 ~80 dirt
setblock ~172 ~127 ~81 dirt
setblock ~172 ~127 ~82 dirt
setblock ~172 ~127 ~83 dirt
setblock ~172 ~127 ~84 grass_block
setblock ~172 ~127 ~85 grass_block
setblock ~172 ~127 ~86 grass_block
setblock ~172 ~128 ~75 grass_block
setblock ~172 ~128 ~77 dirt
setblock ~172 ~128 ~78 dirt
setblock ~172 ~128 ~79 dirt
setblock ~172 ~128 ~80 dirt
setblock ~172 ~128 ~81 dirt
setblock ~172 ~128 ~82 grass_block
setblock ~172 ~128 ~83 grass_block
setblock ~172 ~128 ~84 short_grass
setblock ~172 ~128 ~86 short_grass
setblock ~172 ~129 ~75 short_grass
setblock ~172 ~129 ~77 grass_block
setblock ~172 ~129 ~78 grass_block
setblock ~172 ~129 ~79 grass_block
setblock ~172 ~129 ~80 dirt
setblock ~172 ~129 ~81 grass_block
setblock ~172 ~130 ~80 grass_block
setblock ~172 ~131 ~80 short_grass
setblock ~173 ~117 ~84 dirt
setblock ~173 ~118 ~79 dirt
setblock ~173 ~118 ~84 dirt
setblock ~173 ~119 ~79 dirt
setblock ~173 ~119 ~80 dirt
setblock ~173 ~119 ~83 dirt
setblock ~173 ~119 ~84 dirt
setblock ~173 ~119 ~85 dirt
setblock ~173 ~120 ~78 dirt
setblock ~173 ~120 ~79 dirt
setblock ~173 ~120 ~80 dirt
setblock ~173 ~120 ~82 dirt
setblock ~173 ~120 ~83 dirt
setblock ~173 ~120 ~84 dirt
setblock ~173 ~120 ~85 dirt
setblock ~173 ~120 ~86 dirt
setblock ~173 ~121 ~77 dirt
setblock ~173 ~121 ~78 dirt
setblock ~173 ~121 ~79 dirt
setblock ~173 ~121 ~80 dirt
setblock ~173 ~121 ~81 dirt
setblock ~173 ~121 ~82 dirt
setblock ~173 ~121 ~83 dirt
setblock ~173 ~121 ~84 dirt
setblock ~173 ~121 ~85 dirt
setblock ~173 ~121 ~86 dirt
setblock ~173 ~121 ~87 dirt
setblock ~173 ~122 ~77 dirt
setblock ~173 ~122 ~78 dirt
setblock ~173 ~122 ~79 dirt
setblock ~173 ~122 ~80 dirt
setblock ~173 ~122 ~81 dirt
setblock ~173 ~122 ~82 dirt
setblock ~173 ~122 ~83 dirt
setblock ~173 ~122 ~84 dirt
setblock ~173 ~122 ~85 dirt
setblock ~173 ~122 ~86 dirt
setblock ~173 ~122 ~87 dirt
setblock ~173 ~123 ~77 dirt
setblock ~173 ~123 ~78 dirt
setblock ~173 ~123 ~79 dirt
setblock ~173 ~123 ~80 dirt
setblock ~173 ~123 ~81 dirt
setblock ~173 ~123 ~82 dirt
setblock ~173 ~123 ~83 dirt
setblock ~173 ~123 ~84 dirt
setblock ~173 ~123 ~85 dirt
setblock ~173 ~123 ~86 dirt
setblock ~173 ~123 ~87 dirt
setblock ~173 ~124 ~77 dirt
setblock ~173 ~124 ~78 dirt
setblock ~173 ~124 ~79 dirt
setblock ~173 ~124 ~80 dirt
setblock ~173 ~124 ~81 dirt
setblock ~173 ~124 ~82 dirt
setblock ~173 ~124 ~83 dirt
setblock ~173 ~124 ~84 dirt
setblock ~173 ~124 ~85 dirt
setblock ~173 ~124 ~86 dirt
setblock ~173 ~124 ~87 dirt
setblock ~173 ~125 ~77 dirt
setblock ~173 ~125 ~78 dirt
setblock ~173 ~125 ~79 dirt
setblock ~173 ~125 ~80 dirt
setblock ~173 ~125 ~81 dirt
setblock ~173 ~125 ~82 dirt
setblock ~173 ~125 ~83 dirt
setblock ~173 ~125 ~84 dirt
setblock ~173 ~125 ~85 dirt
setblock ~173 ~125 ~86 dirt
setblock ~173 ~125 ~87 dirt
setblock ~173 ~126 ~77 dirt
setblock ~173 ~126 ~78 dirt
setblock ~173 ~126 ~79 dirt
setblock ~173 ~126 ~80 dirt
setblock ~173 ~126 ~81 dirt
setblock ~173 ~126 ~82 dirt
setblock ~173 ~126 ~83 dirt
setblock ~173 ~126 ~84 dirt
setblock ~173 ~126 ~85 dirt
setblock ~173 ~126 ~86 grass_block
setblock ~173 ~126 ~87 grass_block
setblock ~173 ~127 ~77 dirt
setblock ~173 ~127 ~78 dirt
setblock ~173 ~127 ~79 dirt
setblock ~173 ~127 ~80 dirt
setblock ~173 ~127 ~81 dirt
setblock ~173 ~127 ~82 dirt
setblock ~173 ~127 ~83 grass_block
setblock ~173 ~127 ~84 grass_block
setblock ~173 ~127 ~85 grass_block
setblock ~173 ~127 ~86 short_grass
setblock ~173 ~127 ~87 short_grass
setblock ~173 ~128 ~77 grass_block
setblock ~173 ~128 ~78 grass_block
setblock ~173 ~128 ~79 grass_block
setblock ~173 ~128 ~80 dirt
setblock ~173 ~128 ~81 grass_block
setblock ~173 ~128 ~82 grass_block
setblock ~173 ~128 ~83 fern
setblock ~173 ~128 ~85 short_grass
setblock ~173 ~129 ~77 fern
setblock ~173 ~129 ~80 grass_block
setblock ~173 ~129 ~81 short_grass
setblock ~174 ~120 ~83 dirt
setblock ~174 ~121 ~78 dirt
setblock ~174 ~121 ~79 dirt
setblock ~174 ~121 ~80 dirt
setblock ~174 ~121 ~82 dirt
setblock ~174 ~121 ~83 dirt
setblock ~174 ~121 ~84 dirt
setblock ~174 ~121 ~85 dirt
setblock ~174 ~122 ~78 dirt
setblock ~174 ~122 ~79 dirt
setblock ~174 ~122 ~80 dirt
setblock ~174 ~122 ~82 dirt
setblock ~174 ~122 ~83 dirt
setblock ~174 ~122 ~84 dirt
setblock ~174 ~122 ~85 dirt
setblock ~174 ~123 ~78 dirt
setblock ~174 ~123 ~79 dirt
setblock ~174 ~123 ~80 dirt
setblock ~174 ~123 ~82 dirt
setblock ~174 ~123 ~83 dirt
setblock ~174 ~123 ~84 dirt
setblock ~174 ~123 ~85 dirt
setblock ~174 ~124 ~78 dirt
setblock ~174 ~124 ~79 dirt
setblock ~174 ~124 ~80 dirt
setblock ~174 ~124 ~82 dirt
setblock ~174 ~124 ~83 dirt
setblock ~174 ~124 ~84 dirt
setblock ~174 ~124 ~85 dirt
setblock ~174 ~125 ~78 dirt
setblock ~174 ~125 ~79 dirt
setblock ~174 ~125 ~80 dirt
setblock ~174 ~125 ~82 dirt
setblock ~174 ~125 ~83 dirt
setblock ~174 ~125 ~84 dirt
setblock ~174 ~125 ~85 dirt
setblock ~174 ~126 ~78 dirt
setblock ~174 ~126 ~79 dirt
setblock ~174 ~126 ~80 dirt
setblock ~174 ~126 ~82 dirt
setblock ~174 ~126 ~83 dirt
setblock ~174 ~126 ~84 dirt
setblock ~174 ~126 ~85 dirt
setblock ~174 ~127 ~78 grass_block
setblock ~174 ~127 ~79 grass_block
setblock ~174 ~127 ~80 grass_block
setblock ~174 ~127 ~82 grass_block
setblock ~174 ~127 ~83 grass_block
setblock ~174 ~127 ~84 grass_block
setblock ~174 ~127 ~85 grass_block
setblock ~174 ~128 ~78 short_grass
setblock ~174 ~128 ~82 fern
setblock ~174 ~128 ~83 short_grass
setblock ~174 ~128 ~85 short_grass
setblock ~199 ~200 ~199 gold_block
