setblock ~165 ~111 ~82 dirt
setblock ~165 ~111 ~83 dirt
setblock ~165 ~111 ~84 dirt
setblock ~165 ~111 ~85 dirt
setblock ~165 ~111 ~86 dirt
setblock ~165 ~111 ~87 dirt
setblock ~165 ~111 ~88 dirt
setblock ~165 ~111 ~89 dirt
setblock ~165 ~111 ~90 dirt
setblock ~165 ~111 ~98 dirt
setblock ~165 ~111 ~99 dirt
setblock ~165 ~111 ~100 dirt
setblock ~165 ~112 ~77 dirt
setblock ~165 ~112 ~78 dirt
setblock ~165 ~112 ~79 dirt
setblock ~165 ~112 ~80 dirt
setblock ~165 ~112 ~81 dirt
setblock ~165 ~112 ~82 dirt
setblock ~165 ~112 ~83 dirt
setblock ~165 ~112 ~84 dirt
setblock ~165 ~112 ~85 dirt
setblock ~165 ~112 ~86 dirt
setblock ~165 ~112 ~87 dirt
setblock ~165 ~112 ~88 dirt
setblock ~165 ~112 ~89 dirt
setblock ~165 ~112 ~90 dirt
setblock ~165 ~112 ~91 dirt
setblock ~165 ~112 ~97 dirt
setblock ~165 ~112 ~98 dirt
setblock ~165 ~112 ~99 dirt
setblock ~165 ~112 ~100 dirt
setblock ~165 ~112 ~101 dirt
setblock ~165 ~112 ~102 dirt
setblock ~165 ~112 ~105 dirt
setblock ~165 ~113 ~76 dirt
setblock ~165 ~113 ~77 dirt
setblock ~165 ~113 ~78 dirt
setblock ~165 ~113 ~79 dirt
setblock ~165 ~113 ~80 dirt
setblock ~165 ~113 ~81 dirt
setblock ~165 ~113 ~82 dirt
setblock ~165 ~113 ~83 dirt
setblock ~165 ~113 ~84 dirt
setblock ~165 ~113 ~85 dirt
setblock ~165 ~113 ~86 dirt
setblock ~165 ~113 ~87 dirt
setblock ~165 ~113 ~88 dirt
setblock ~165 ~113 ~89 dirt
setblock ~165 ~113 ~90 dirt
setblock ~165 ~113 ~91 dirt
setblock ~165 ~113 ~96 dirt
setblock ~165 ~113 ~97 dirt
setblock ~165 ~113 ~98 dirt
setblock ~165 ~113 ~99 dirt
setblock ~165 ~113 ~100 dirt
setblock ~165 ~113 ~101 dirt
setblock ~165 ~113 ~102 dirt
setblock ~165 ~113 ~103 dirt
setblock ~165 ~113 ~104 dirt
setblock ~165 ~113 ~105 dirt
setblock ~165 ~114 ~76 dirt
setblock ~165 ~114 ~77 dirt
setblock ~165 ~114 ~78 dirt
setblock ~165 ~114 ~79 dirt
setblock ~165 ~114 ~80 dirt
setblock ~165 ~114 ~81 dirt
setblock ~165 ~114 ~82 dirt
setblock ~165 ~114 ~83 dirt
setblock ~165 ~114 ~84 dirt
setblock ~165 ~114 ~85 dirt
setblock ~165 ~114 ~86 dirt
setblock ~165 ~114 ~87 dirt
setblock ~165 ~114 ~88 dirt
setblock ~165 ~114 ~89 dirt
setblock ~165 ~114 ~90 dirt
setblock ~165 ~114 ~91 dirt
setblock ~165 ~114 ~92 dirt
setblock ~165 ~114 ~95 dirt
setblock ~165 ~114 ~96 dirt
setblock ~165 ~114 ~97 dirt
setblock ~165 ~114 ~98 dirt
setblock ~165 ~114 ~99 dirt
setblock ~165 ~114 ~100 dirt
setblock ~165 ~114 ~101 dirt
setblock ~165 ~114 ~102 dirt
setblock ~165 ~114 ~103 dirt
setblock ~165 ~114 ~104 dirt
setblock ~165 ~114 ~105 dirt
setblock ~165 ~114 ~106 dirt
setblock ~165 ~114 ~107 dirt
setblock ~165 ~114 ~122 dirt
setblock ~165 ~114 ~123 dirt
setblock ~165 ~115 ~75 dirt
setblock ~165 ~115 ~76 dirt
setblock ~165 ~115 ~77 dirt
setblock ~165 ~115 ~78 dirt
setblock ~165 ~115 ~79 dirt
setblock ~165 ~115 ~80 dirt
setblock ~165 ~115 ~81 dirt
setblock ~165 ~115 ~82 dirt
setblock ~165 ~115 ~83 dirt
setblock ~165 ~115 ~84 dirt
setblock ~165 ~115 ~85 dirt
setblock ~165 ~115 ~86 dirt
setblock ~165 ~115 ~87 dirt
setblock ~165 ~115 ~88 dirt
setblock ~165 ~115 ~89 dirt
setblock ~165 ~115 ~90 dirt
setblock ~165 ~115 ~91 dirt
setblock ~165 ~115 ~92 dirt
setblock ~165 ~115 ~95 dirt
setblock ~165 ~115 ~96 dirt
setblock ~165 ~115 ~97 dirt
setblock ~165 ~115 ~98 dirt
setblock ~165 ~115 ~99 dirt
setblock ~165 ~115 ~100 dirt
setblock ~165 ~115 ~101 dirt
setblock ~165 ~115 ~102 dirt
setblock ~165 ~115 ~103 dirt
setblock ~165 ~115 ~104 dirt
setblock ~165 ~115 ~105 dirt
setblock ~165 ~115 ~106 dirt
setblock ~165 ~115 ~107 dirt
setblock ~165 ~115 ~121 dirt
setblock ~165 ~115 ~122 dirt
setblock ~165 ~115 ~123 dirt
setblock ~165 ~116 ~75 dirt
setblock ~165 ~116 ~76 dirt
setblock ~165 ~116 ~77 dirt
setblock ~165 ~116 ~78 dirt
setblock ~165 ~116 ~79 dirt
setblock ~165 ~116 ~80 dirt
setblock ~165 ~116 ~81 dirt
setblock ~165 ~116 ~82 dirt
setblock ~165 ~116 ~83 dirt
setblock ~165 ~116 ~84 dirt
setblock ~165 ~116 ~85 dirt
setblock ~165 ~116 ~86 dirt
setblock ~165 ~116 ~87 dirt
setblock ~165 ~116 ~88 dirt
setblock ~165 ~116 ~89 dirt
setblock ~165 ~116 ~90 dirt
setblock ~165 ~116 ~91 dirt
setblock ~165 ~116 ~92 dirt
setblock ~165 ~116 ~93 dirt
setblock ~165 ~116 ~94 dirt
setblock ~165 ~116 ~95 dirt
setblock ~165 ~116 ~96 dirt
setblock ~165 ~116 ~97 dirt
setblock ~165 ~116 ~98 dirt
setblock ~165 ~116 ~99 dirt
setblock ~165 ~116 ~100 dirt
setblock ~165 ~116 ~101 dirt
setblock ~165 ~116 ~102 dirt
setblock ~165 ~116 ~103 dirt
setblock ~165 ~116 ~104 dirt
setblock ~165 ~116 ~105 dirt
setblock ~165 ~116 ~106 dirt
setblock ~165 ~116 ~107 dirt
setblock ~165 ~116 ~108 dirt
setblock ~165 ~116 ~120 dirt
setblock ~165 ~116 ~121 dirt
setblock ~165 ~116 ~122 dirt
setblock ~165 ~116 ~123 dirt
setblock ~165 ~116 ~124 dirt
setblock ~165 ~117 ~75 dirt
setblock ~165 ~117 ~76 dirt
setblock ~165 ~117 ~77 dirt
setblock ~165 ~117 ~78 dirt
setblock ~165 ~117 ~79 dirt
setblock ~165 ~117 ~80 dirt
setblock ~165 ~117 ~81 dirt
setblock ~165 ~117 ~82 dirt
setblock ~165 ~117 ~83 dirt
setblock ~165 ~117 ~84 dirt
setblock ~165 ~117 ~85 dirt
setblock ~165 ~117 ~86 dirt
setblock ~165 ~117 ~87 dirt
setblock ~165 ~117 ~88 dirt
setblock ~165 ~117 ~89 dirt
setblock ~165 ~117 ~90 dirt
setblock ~165 ~117 ~91 dirt
setblock ~165 ~117 ~92 dirt
setblock ~165 ~117 ~93 dirt
setblock ~165 ~117 ~94 dirt
setblock ~165 ~117 ~95 dirt
setblock ~165 ~117 ~96 dirt
setblock ~165 ~117 ~97 dirt
setblock ~165 ~117 ~98 dirt
setblock ~165 ~117 ~99 dirt
setblock ~165 ~117 ~100 dirt
setblock ~165 ~117 ~101 dirt
setblock ~165 ~117 ~102 dirt
setblock ~165 ~117 ~103 dirt
setblock ~165 ~117 ~104 dirt
setblock ~165 ~117 ~105 dirt
setblock ~165 ~117 ~106 dirt
setblock ~165 ~117 ~107 dirt
setblock ~165 ~117 ~108 dirt
setblock ~165 ~117 ~119 dirt
setblock ~165 ~117 ~120 dirt
setblock ~165 ~117 ~121 dirt
setblock ~165 ~117 ~122 dirt
setblock ~165 ~117 ~123 dirt
setblock ~165 ~117 ~124 dirt
setblock ~165 ~117 ~127 dirt
setblock ~165 ~117 ~129 dirt
setblock ~165 ~118 ~74 dirt
setblock ~165 ~118 ~75 dirt
setblock ~165 ~118 ~76 dirt
setblock ~165 ~118 ~77 dirt
setblock ~165 ~118 ~78 dirt
setblock ~165 ~118 ~79 dirt
setblock ~165 ~118 ~80 dirt
setblock ~165 ~118 ~81 dirt
setblock ~165 ~118 ~82 dirt
setblock ~165 ~118 ~83 dirt
setblock ~165 ~118 ~84 dirt
setblock ~165 ~118 ~85 dirt
setblock ~165 ~118 ~86 dirt
setblock ~165 ~118 ~87 dirt
setblock ~165 ~118 ~88 dirt
setblock ~165 ~118 ~89 dirt
setblock ~165 ~118 ~90 dirt
setblock ~165 ~118 ~91 dirt
setblock ~165 ~118 ~92 dirt
setblock ~165 ~118 ~93 dirt
setblock ~165 ~118 ~94 dirt
setblock ~165 ~118 ~95 dirt
setblock ~165 ~118 ~96 dirt
setblock ~165 ~118 ~97 dirt
setblock ~165 ~118 ~98 dirt
setblock ~165 ~118 ~99 dirt
setblock ~165 ~118 ~100 dirt
setblock ~165 ~118 ~101 dirt
setblock ~165 ~118 ~102 dirt
setblock ~165 ~118 ~103 dirt
setblock ~165 ~118 ~104 dirt
setblock ~165 ~118 ~105 dirt
setblock ~165 ~118 ~106 dirt
setblock ~165 ~118 ~107 dirt
setblock ~165 ~118 ~108 dirt
setblock ~165 ~118 ~109 dirt
setblock ~165 ~118 ~117 dirt
setblock ~165 ~118 ~119 dirt
setblock ~165 ~118 ~120 dirt
setblock ~165 ~118 ~121 dirt
setblock ~165 ~118 ~122 dirt
setblock ~165 ~118 ~123 dirt
setblock ~165 ~118 ~124 dirt
setblock ~165 ~118 ~125 dirt
setblock ~165 ~118 ~127 dirt
setblock ~165 ~118 ~128 dirt
setblock ~165 ~118 ~129 dirt
setblock ~165 ~119 ~74 dirt
setblock ~165 ~119 ~75 dirt
setblock ~165 ~119 ~76 dirt
setblock ~165 ~119 ~77 dirt
setblock ~165 ~119 ~78 dirt
setblock ~165 ~119 ~79 dirt
setblock ~165 ~119 ~80 dirt
setblock ~165 ~119 ~81 dirt
setblock ~165 ~119 ~82 dirt
setblock ~165 ~119 ~83 dirt
setblock ~165 ~119 ~84 dirt
setblock ~165 ~119 ~85 dirt
setblock ~165 ~119 ~86 dirt
setblock ~165 ~119 ~87 dirt
setblock ~165 ~119 ~88 dirt
setblock ~165 ~119 ~89 dirt
setblock ~165 ~119 ~90 dirt
setblock ~165 ~119 ~91 dirt
setblock ~165 ~119 ~92 dirt
setblock ~165 ~119 ~93 dirt
setblock ~165 ~119 ~94 dirt
setblock ~165 ~119 ~95 dirt
setblock ~165 ~119 ~96 dirt
setblock ~165 ~119 ~97 dirt
setblock ~165 ~119 ~98 dirt
setblock ~165 ~119 ~99 dirt
setblock ~165 ~119 ~100 dirt
setblock ~165 ~119 ~101 dirt
setblock ~165 ~119 ~102 dirt
setblock ~165 ~119 ~103 dirt
setblock ~165 ~119 ~104 dirt
setblock ~165 ~119 ~105 dirt
setblock ~165 ~119 ~106 dirt
setblock ~165 ~119 ~107 dirt
setblock ~165 ~119 ~108 dirt
setblock ~165 ~119 ~109 dirt
setblock ~165 ~119 ~110 dirt
setblock ~165 ~119 ~111 dirt
setblock ~165 ~119 ~117 dirt
setblock ~165 ~119 ~118 dirt
setblock ~165 ~119 ~119 dirt
setblock ~165 ~119 ~120 dirt
setblock ~165 ~119 ~121 dirt
setblock ~165 ~119 ~122 dirt
setblock ~165 ~119 ~123 dirt
setblock ~165 ~119 ~124 dirt
setblock ~165 ~119 ~125 dirt
setblock ~165 ~119 ~126 dirt
setblock ~165 ~119 ~127 dirt
setblock ~165 ~119 ~128 dirt
setblock ~165 ~119 ~129 dirt
setblock ~165 ~120 ~73 dirt
setblock ~165 ~120 ~74 dirt
setblock ~165 ~120 ~75 dirt
setblock ~165 ~120 ~76 dirt
setblock ~165 ~120 ~77 dirt
setblock ~165 ~120 ~78 dirt
setblock ~165 ~120 ~79 dirt
setblock ~165 ~120 ~80 dirt
setblock ~165 ~120 ~81 dirt
setblock ~165 ~120 ~82 dirt
setblock ~165 ~120 ~83 dirt
setblock ~165 ~120 ~84 dirt
setblock ~165 ~120 ~85 dirt
setblock ~165 ~120 ~86 dirt
setblock ~165 ~120 ~87 dirt
setblock ~165 ~120 ~88 dirt
setblock ~165 ~120 ~89 dirt
setblock ~165 ~120 ~90 dirt
setblock ~165 ~120 ~91 dirt
setblock ~165 ~120 ~92 dirt
setblock ~165 ~120 ~93 dirt
setblock ~165 ~120 ~94 dirt
setblock ~165 ~120 ~95 dirt
setblock ~165 ~120 ~96 dirt
setblock ~165 ~120 ~97 dirt
setblock ~165 ~120 ~98 dirt
setblock ~165 ~120 ~99 dirt
setblock ~165 ~120 ~100 dirt
setblock ~165 ~120 ~101 dirt
setblock ~165 ~120 ~102 dirt
setblock ~165 ~120 ~103 dirt
setblock ~165 ~120 ~104 dirt
setblock ~165 ~120 ~105 dirt
setblock ~165 ~120 ~106 dirt
setblock ~165 ~120 ~107 dirt
setblock ~165 ~120 ~108 dirt
setblock ~165 ~120 ~109 dirt
setblock ~165 ~120 ~110 dirt
setblock ~165 ~120 ~111 dirt
setblock ~165 ~120 ~116 dirt
setblock ~165 ~120 ~117 dirt
setblock ~165 ~120 ~118 dirt
setblock ~165 ~120 ~119 dirt
setblock ~165 ~120 ~120 dirt
setblock ~165 ~120 ~121 dirt
setblock ~165 ~120 ~122 dirt
setblock ~165 ~120 ~123 dirt
setblock ~165 ~120 ~124 dirt
setblock ~165 ~120 ~125 dirt
setblock ~165 ~120 ~126 dirt
setblock ~165 ~120 ~127 dirt
setblock ~165 ~120 ~128 dirt
setblock ~165 ~120 ~129 dirt
setblock ~165 ~120 ~130 dirt
setblock ~165 ~121 ~73 dirt
setblock ~165 ~121 ~74 dirt
setblock ~165 ~121 ~75 dirt
setblock ~165 ~121 ~76 dirt
setblock ~165 ~121 ~77 dirt
setblock ~165 ~121 ~78 dirt
setblock ~165 ~121 ~79 dirt
setblock ~165 ~121 ~80 dirt
setblock ~165 ~121 ~81 dirt
setblock ~165 ~121 ~82 dirt
setblock ~165 ~121 ~83 dirt
setblock ~165 ~121 ~84 dirt
setblock ~165 ~121 ~85 dirt
setblock ~165 ~121 ~86 dirt
setblock ~165 ~121 ~87 dirt
setblock ~165 ~121 ~88 dirt
setblock ~165 ~121 ~89 dirt
setblock ~165 ~121 ~90 dirt
setblock ~165 ~121 ~91 dirt
setblock ~165 ~121 ~92 dirt
setblock ~165 ~121 ~93 dirt
setblock ~165 ~121 ~94 dirt
setblock ~165 ~121 ~95 dirt
setblock ~165 ~121 ~96 dirt
setblock ~165 ~121 ~97 dirt
setblock ~165 ~121 ~98 dirt
setblock ~165 ~121 ~99 dirt
setblock ~165 ~121 ~100 dirt
setblock ~165 ~121 ~101 dirt
setblock ~165 ~121 ~102 dirt
setblock ~165 ~121 ~103 dirt
setblock ~165 ~121 ~104 dirt
setblock ~165 ~121 ~105 dirt
setblock ~165 ~121 ~106 dirt
setblock ~165 ~121 ~107 dirt
setblock ~165 ~121 ~108 dirt
setblock ~165 ~121 ~109 dirt
setblock ~165 ~121 ~110 dirt
setblock ~165 ~121 ~111 dirt
setblock ~165 ~121 ~112 dirt
setblock ~165 ~121 ~113 dirt
setblock ~165 ~121 ~115 dirt
setblock ~165 ~121 ~116 dirt
setblock ~165 ~121 ~117 dirt
setblock ~165 ~121 ~118 dirt
setblock ~165 ~121 ~119 dirt
setblock ~165 ~121 ~120 dirt
setblock ~165 ~121 ~121 dirt
setblock ~165 ~121 ~122 dirt
setblock ~165 ~121 ~123 dirt
setblock ~165 ~121 ~124 dirt
setblock ~165 ~121 ~125 dirt
setblock ~165 ~121 ~126 dirt
setblock ~165 ~121 ~127 dirt
setblock ~165 ~121 ~128 dirt
setblock ~165 ~121 ~129 dirt
setblock ~165 ~121 ~130 dirt
setblock ~165 ~122 ~73 dirt
setblock ~165 ~122 ~74 dirt
setblock ~165 ~122 ~75 dirt
setblock ~165 ~122 ~76 dirt
setblock ~165 ~122 ~77 dirt
setblock ~165 ~122 ~78 dirt
setblock ~165 ~122 ~79 dirt
setblock ~165 ~122 ~80 dirt
setblock ~165 ~122 ~81 dirt
setblock ~165 ~122 ~82 dirt
setblock ~165 ~122 ~83 dirt
setblock ~165 ~122 ~84 dirt
setblock ~165 ~122 ~85 dirt
setblock ~165 ~122 ~86 dirt
setblock ~165 ~122 ~87 dirt
setblock ~165 ~122 ~88 dirt
setblock ~165 ~122 ~89 dirt
setblock ~165 ~122 ~90 dirt
setblock ~165 ~122 ~91 dirt
setblock ~165 ~122 ~92 dirt
setblock ~165 ~122 ~93 dirt
setblock ~165 ~122 ~94 dirt
setblock ~165 ~122 ~95 dirt
setblock ~165 ~122 ~96 dirt
setblock ~165 ~122 ~97 dirt
setblock ~165 ~122 ~98 dirt
setblock ~165 ~122 ~99 dirt
setblock ~165 ~122 ~100 dirt
setblock ~165 ~122 ~101 dirt
setblock ~165 ~122 ~102 dirt
setblock ~165 ~122 ~103 dirt
setblock ~165 ~122 ~104 dirt
setblock ~165 ~122 ~105 dirt
setblock ~165 ~122 ~106 dirt
setblock ~165 ~122 ~107 dirt
setblock ~165 ~122 ~108 dirt
setblock ~165 ~122 ~109 dirt
setblock ~165 ~122 ~110 dirt
setblock ~165 ~122 ~111 dirt
setblock ~165 ~122 ~112 dirt
setblock ~165 ~122 ~113 dirt
setblock ~165 ~122 ~115 dirt
setblock ~165 ~122 ~116 dirt
setblock ~165 ~122 ~117 dirt
setblock ~165 ~122 ~118 dirt
setblock ~165 ~122 ~119 dirt
setblock ~165 ~122 ~120 dirt
setblock ~165 ~122 ~121 dirt
setblock ~165 ~122 ~122 dirt
setblock ~165 ~122 ~123 dirt
setblock ~165 ~122 ~124 dirt
setblock ~165 ~122 ~125 dirt
setblock ~165 ~122 ~126 dirt
setblock ~165 ~122 ~127 dirt
setblock ~165 ~122 ~128 dirt
setblock ~165 ~122 ~129 dirt
setblock ~165 ~122 ~130 dirt
setblock ~165 ~123 ~73 dirt
setblock ~165 ~123 ~74 dirt
setblock ~165 ~123 ~75 dirt
setblock ~165 ~123 ~76 dirt
setblock ~165 ~123 ~77 dirt
setblock ~165 ~123 ~78 dirt
setblock ~165 ~123 ~79 dirt
setblock ~165 ~123 ~80 grass_block
setblock ~165 ~123 ~81 grass_block
setblock ~165 ~123 ~82 grass_block
setblock ~165 ~123 ~83 grass_block
setblock ~165 ~123 ~84 grass_block
setblock ~165 ~123 ~85 grass_block
setblock ~165 ~123 ~86 grass_block
setblock ~165 ~123 ~87 grass_block
setblock ~165 ~123 ~88 grass_block
setblock ~165 ~123 ~89 grass_block
setblock ~165 ~123 ~90 grass_block
setblock ~165 ~123 ~91 grass_block
setblock ~165 ~123 ~92 grass_block
setblock ~165 ~123 ~93 grass_block
setblock ~165 ~123 ~94 grass_block
setblock ~165 ~123 ~95 dirt
setblock ~165 ~123 ~96 dirt
setblock ~165 ~123 ~97 dirt
setblock ~165 ~123 ~98 dirt
setblock ~165 ~123 ~99 dirt
setblock ~165 ~123 ~100 dirt
setblock ~165 ~123 ~101 dirt
setblock ~165 ~123 ~102 dirt
setblock ~165 ~123 ~103 dirt
setblock ~165 ~123 ~104 dirt
setblock ~165 ~123 ~105 dirt
setblock ~165 ~123 ~106 dirt
setblock ~165 ~123 ~107 dirt
setblock ~165 ~123 ~108 dirt
setblock ~165 ~123 ~109 dirt
setblock ~165 ~123 ~110 dirt
setblock ~165 ~123 ~111 dirt
setblock ~165 ~123 ~112 dirt
setblock ~165 ~123 ~113 dirt
setblock ~165 ~123 ~115 dirt
setblock ~165 ~123 ~116 dirt
setblock ~165 ~123 ~117 dirt
setblock ~165 ~123 ~118 dirt
setblock ~165 ~123 ~119 dirt
setblock ~165 ~123 ~120 dirt
setblock ~165 ~123 ~121 dirt
setblock ~165 ~123 ~122 dirt
setblock ~165 ~123 ~123 dirt
setblock ~165 ~123 ~124 dirt
setblock ~165 ~123 ~125 dirt
setblock ~165 ~123 ~126 dirt
setblock ~165 ~123 ~127 dirt
setblock ~165 ~123 ~128 grass_block
setblock ~165 ~123 ~129 grass_block
setblock ~165 ~123 ~130 grass_block
setblock ~165 ~124 ~73 dirt
setblock ~165 ~124 ~74 dirt
setblock ~165 ~124 ~75 dirt
setblock ~165 ~124 ~76 dirt
setblock ~165 ~124 ~77 grass_block
setblock ~165 ~124 ~78 grass_block
setblock ~165 ~124 ~79 grass_block
setblock ~165 ~124 ~80 short_grass
setblock ~165 ~124 ~83 fern
setblock ~165 ~124 ~87 short_grass
setblock ~165 ~124 ~88 short_grass
setblock ~165 ~124 ~91 short_grass
setblock ~165 ~124 ~95 grass_block
setblock ~165 ~124 ~96 grass_block
setblock ~165 ~124 ~97 grass_block
setblock ~165 ~124 ~98 grass_block
setblock ~165 ~124 ~99 grass_block
setblock ~165 ~124 ~100 grass_block
setblock ~165 ~124 ~101 grass_block
setblock ~165 ~124 ~102 grass_block
setblock ~165 ~124 ~103 grass_block
setblock ~165 ~124 ~104 grass_block
setblock ~165 ~124 ~105 grass_block
setblock ~165 ~124 ~106 dirt
setblock ~165 ~124 ~107 dirt
setblock ~165 ~124 ~108 dirt
setblock ~165 ~124 ~109 dirt
setblock ~165 ~124 ~110 dirt
setblock ~165 ~124 ~111 dirt
setblock ~165 ~124 ~112 dirt
setblock ~165 ~124 ~113 dirt
setblock ~165 ~124 ~115 dirt
setblock ~165 ~124 ~116 dirt
setblock ~165 ~124 ~117 dirt
setblock ~165 ~124 ~118 dirt
setblock ~165 ~124 ~119 dirt
setblock ~165 ~124 ~120 dirt
setblock ~165 ~124 ~121 dirt
setblock ~165 ~124 ~122 dirt
setblock ~165 ~124 ~123 grass_block
setblock ~165 ~124 ~124 grass_block
setblock ~165 ~124 ~125 grass_block
setblock ~165 ~124 ~126 grass_block
setblock ~165 ~124 ~127 grass_block
setblock ~165 ~124 ~129 poppy
setblock ~165 ~125 ~73 dirt
setblock ~165 ~125 ~74 dirt
setblock ~165 ~125 ~75 grass_block
setblock ~165 ~125 ~76 grass_block
setblock ~165 ~125 ~79 short_grass
setblock ~165 ~125 ~98 short_grass
setblock ~165 ~125 ~102 short_grass
setblock ~165 ~125 ~103 poppy
setblock ~165 ~125 ~104 short_grass
setblock ~165 ~125 ~106 grass_block
setblock ~165 ~125 ~107 grass_block
setblock ~165 ~125 ~108 grass_block
setblock ~165 ~125 ~109 grass_block
setblock ~165 ~125 ~110 grass_block
setblock ~165 ~125 ~111 grass_block
setblock ~165 ~125 ~112 grass_block
setblock ~165 ~125 ~113 grass_block
setblock ~165 ~125 ~115 grass_block
setblock ~165 ~125 ~116 grass_block
setblock ~165 ~125 ~117 grass_block
setblock ~165 ~125 ~118 grass_block
setblock ~165 ~125 ~119 grass_block
setblock ~165 ~125 ~120 grass_block
setblock ~165 ~125 ~121 grass_block
setblock ~165 ~125 ~122 grass_block
setblock ~165 ~125 ~124 short_grass
setblock ~165 ~125 ~126 short_grass
setblock ~165 ~126 ~73 grass_block
setblock ~165 ~126 ~74 grass_block
setblock ~165 ~126 ~76 short_grass
setblock ~165 ~126 ~108 fern
setblock ~165 ~126 ~109 short_grass
setblock ~165 ~126 ~110 fern
setblock ~165 ~126 ~115 short_grass
setblock ~165 ~126 ~122 poppy
setblock ~166 ~107 ~83 dirt
setblock ~166 ~107 ~84 dirt
setblock ~166 ~108 ~83 dirt
setblock ~166 ~108 ~84 dirt
setblock ~166 ~109 ~82 dirt
setblock ~166 ~109 ~83 dirt
setblock ~166 ~109 ~84 dirt
setblock ~166 ~109 ~85 dirt
setblock ~166 ~110 ~80 dirt
setblock ~166 ~110 ~81 dirt
setblock ~166 ~110 ~82 dirt
setblock ~166 ~110 ~83 dirt
setblock ~166 ~110 ~84 dirt
setblock ~166 ~110 ~85 dirt
setblock ~166 ~111 ~79 dirt
setblock ~166 ~111 ~80 dirt
setblock ~166 ~111 ~81 dirt
setblock ~166 ~111 ~82 dirt
setblock ~166 ~111 ~83 dirt
setblock ~166 ~111 ~84 dirt
setblock ~166 ~111 ~85 dirt
setblock ~166 ~111 ~86 dirt
setblock ~166 ~111 ~99 dirt
setblock ~166 ~112 ~79 dirt
setblock ~166 ~112 ~80 dirt
setblock ~166 ~112 ~81 dirt
setblock ~166 ~112 ~82 dirt
setblock ~166 ~112 ~83 dirt
setblock ~166 ~112 ~84 dirt
setblock ~166 ~112 ~85 dirt
setblock ~166 ~112 ~86 dirt
setblock ~166 ~112 ~87 dirt
setblock ~166 ~112 ~88 dirt
setblock ~166 ~112 ~89 dirt
setblock ~166 ~112 ~90 dirt
setblock ~166 ~112 ~99 dirt
setblock ~166 ~112 ~100 dirt
setblock ~166 ~113 ~77 dirt
setblock ~166 ~113 ~78 dirt
setblock ~166 ~113 ~79 dirt
setblock ~166 ~113 ~80 dirt
setblock ~166 ~113 ~81 dirt
setblock ~166 ~113 ~82 dirt
setblock ~166 ~113 ~83 dirt
setblock ~166 ~113 ~84 dirt
setblock ~166 ~113 ~85 dirt
setblock ~166 ~113 ~86 dirt
setblock ~166 ~113 ~87 dirt
setblock ~166 ~113 ~88 dirt
setblock ~166 ~113 ~89 dirt
setblock ~166 ~113 ~90 dirt
setblock ~166 ~113 ~97 dirt
setblock ~166 ~113 ~98 dirt
setblock ~166 ~113 ~99 dirt
setblock ~166 ~113 ~100 dirt
setblock ~166 ~113 ~101 dirt
setblock ~166 ~114 ~76 dirt
setblock ~166 ~114 ~77 dirt
setblock ~166 ~114 ~78 dirt
setblock ~166 ~114 ~79 dirt
setblock ~166 ~114 ~80 dirt
setblock ~166 ~114 ~81 dirt
setblock ~166 ~114 ~82 dirt
setblock ~166 ~114 ~83 dirt
setblock ~166 ~114 ~84 dirt
setblock ~166 ~114 ~85 dirt
setblock ~166 ~114 ~86 dirt
setblock ~166 ~114 ~87 dirt
setblock ~166 ~114 ~88 dirt
setblock ~166 ~114 ~89 dirt
setblock ~166 ~114 ~90 dirt
setblock ~166 ~114 ~91 dirt
setblock ~166 ~114 ~97 dirt
setblock ~166 ~114 ~98 dirt
setblock ~166 ~114 ~99 dirt
setblock ~166 ~114 ~100 dirt
setblock ~166 ~114 ~101 dirt
setblock ~166 ~114 ~102 dirt
setblock ~166 ~114 ~103 dirt
setblock ~166 ~114 ~105 dirt
setblock ~166 ~115 ~76 dirt
setblock ~166 ~115 ~77 dirt
setblock ~166 ~115 ~78 dirt
setblock ~166 ~115 ~79 dirt
setblock ~166 ~115 ~80 dirt
setblock ~166 ~115 ~81 dirt
setblock ~166 ~115 ~82 dirt
setblock ~166 ~115 ~83 dirt
setblock ~166 ~115 ~84 dirt
setblock ~166 ~115 ~85 dirt
setblock ~166 ~115 ~86 dirt
setblock ~166 ~115 ~87 dirt
setblock ~166 ~115 ~88 dirt
setblock ~166 ~115 ~89 dirt
setblock ~166 ~115 ~90 dirt
setblock ~166 ~115 ~91 dirt
setblock ~166 ~115 ~92 dirt
setblock ~166 ~115 ~97 dirt
setblock ~166 ~115 ~98 dirt
setblock ~166 ~115 ~99 dirt
setblock ~166 ~115 ~100 dirt
setblock ~166 ~115 ~101 dirt
setblock ~166 ~115 ~102 dirt
setblock ~166 ~115 ~103 dirt
setblock ~166 ~115 ~104 dirt
setblock ~166 ~115 ~105 dirt
setblock ~166 ~115 ~106 dirt
setblock ~166 ~115 ~122 dirt
setblock ~166 ~116 ~76 dirt
setblock ~166 ~116 ~77 dirt
setblock ~166 ~116 ~78 dirt
setblock ~166 ~116 ~79 dirt
setblock ~166 ~116 ~80 dirt
setblock ~166 ~116 ~81 dirt
setblock ~166 ~116 ~82 dirt
setblock ~166 ~116 ~83 dirt
setblock ~166 ~116 ~84 dirt
setblock ~166 ~116 ~85 dirt
setblock ~166 ~116 ~86 dirt
setblock ~166 ~116 ~87 dirt
setblock ~166 ~116 ~88 dirt
setblock ~166 ~116 ~89 dirt
setblock ~166 ~116 ~90 dirt
setblock ~166 ~116 ~91 dirt
setblock ~166 ~116 ~92 dirt
setblock ~166 ~116 ~95 dirt
setblock ~166 ~116 ~96 dirt
setblock ~166 ~116 ~97 dirt
setblock ~166 ~116 ~98 dirt
setblock ~166 ~116 ~99 dirt
setblock ~166 ~116 ~100 dirt
setblock ~166 ~116 ~101 dirt
setblock ~166 ~116 ~102 dirt
setblock ~166 ~116 ~103 dirt
setblock ~166 ~116 ~104 dirt
setblock ~166 ~116 ~105 dirt
setblock ~166 ~116 ~106 dirt
setblock ~166 ~116 ~107 dirt
setblock ~166 ~116 ~121 dirt
setblock ~166 ~116 ~122 dirt
setblock ~166 ~116 ~123 dirt
setblock ~166 ~117 ~76 dirt
setblock ~166 ~117 ~77 dirt
setblock ~166 ~117 ~78 dirt
setblock ~166 ~117 ~79 dirt
setblock ~166 ~117 ~80 dirt
setblock ~166 ~117 ~81 dirt
setblock ~166 ~117 ~82 dirt
setblock ~166 ~117 ~83 dirt
setblock ~166 ~117 ~84 dirt
setblock ~166 ~117 ~85 dirt
setblock ~166 ~117 ~86 dirt
setblock ~166 ~117 ~87 dirt
setblock ~166 ~117 ~88 dirt
setblock ~166 ~117 ~89 dirt
setblock ~166 ~117 ~90 dirt
setblock ~166 ~117 ~91 dirt
setblock ~166 ~117 ~92 dirt
setblock ~166 ~117 ~94 dirt
setblock ~166 ~117 ~95 dirt
setblock ~166 ~117 ~96 dirt
setblock ~166 ~117 ~97 dirt
setblock ~166 ~117 ~98 dirt
setblock ~166 ~117 ~99 dirt
setblock ~166 ~117 ~100 dirt
setblock ~166 ~117 ~101 dirt
setblock ~166 ~117 ~102 dirt
setblock ~166 ~117 ~103 dirt
setblock ~166 ~117 ~104 dirt
setblock ~166 ~117 ~105 dirt
setblock ~166 ~117 ~106 dirt
setblock ~166 ~117 ~107 dirt
setblock ~166 ~117 ~120 dirt
setblock ~166 ~117 ~121 dirt
setblock ~166 ~117 ~122 dirt
setblock ~166 ~117 ~123 dirt
setblock ~166 ~118 ~75 dirt
setblock ~166 ~118 ~76 dirt
setblock ~166 ~118 ~77 dirt
setblock ~166 ~118 ~78 dirt
setblock ~166 ~118 ~79 dirt
setblock ~166 ~118 ~80 dirt
setblock ~166 ~118 ~81 dirt
setblock ~166 ~118 ~82 dirt
setblock ~166 ~118 ~83 dirt
setblock ~166 ~118 ~84 dirt
setblock ~166 ~118 ~85 dirt
setblock ~166 ~118 ~86 dirt
setblock ~166 ~118 ~87 dirt
setblock ~166 ~118 ~88 dirt
setblock ~166 ~118 ~89 dirt
setblock ~166 ~118 ~90 dirt
setblock ~166 ~118 ~91 dirt
setblock ~166 ~118 ~92 dirt
setblock ~166 ~118 ~93 dirt
setblock ~166 ~118 ~94 dirt
setblock ~166 ~118 ~95 dirt
setblock ~166 ~118 ~96 dirt
setblock ~166 ~118 ~97 dirt
setblock ~166 ~118 ~98 dirt
setblock ~166 ~118 ~99 dirt
setblock ~166 ~118 ~100 dirt
setblock ~166 ~118 ~101 dirt
setblock ~166 ~118 ~102 dirt
setblock ~166 ~118 ~103 dirt
setblock ~166 ~118 ~104 dirt
setblock ~166 ~118 ~105 dirt
setblock ~166 ~118 ~106 dirt
setblock ~166 ~118 ~107 dirt
setblock ~166 ~118 ~108 dirt
setblock ~166 ~118 ~120 dirt
setblock ~166 ~118 ~121 dirt
setblock ~166 ~118 ~122 dirt
setblock ~166 ~118 ~123 dirt
setblock ~166 ~119 ~75 dirt
setblock ~166 ~119 ~76 dirt
setblock ~166 ~119 ~77 dirt
setblock ~166 ~119 ~78 dirt
setblock ~166 ~119 ~79 dirt
setblock ~166 ~119 ~80 dirt
setblock ~166 ~119 ~81 dirt
setblock ~166 ~119 ~82 dirt
setblock ~166 ~119 ~83 dirt
setblock ~166 ~119 ~84 dirt
setblock ~166 ~119 ~85 dirt
setblock ~166 ~119 ~86 dirt
setblock ~166 ~119 ~87 dirt
setblock ~166 ~119 ~88 dirt
setblock ~166 ~119 ~89 dirt
setblock ~166 ~119 ~90 dirt
setblock ~166 ~119 ~91 dirt
setblock ~166 ~119 ~92 dirt
setblock ~166 ~119 ~93 dirt
setblock ~166 ~119 ~94 dirt
setblock ~166 ~119 ~95 dirt
setblock ~166 ~119 ~96 dirt
setblock ~166 ~119 ~97 dirt
setblock ~166 ~119 ~98 dirt
setblock ~166 ~119 ~99 dirt
setblock ~166 ~119 ~100 dirt
setblock ~166 ~119 ~101 dirt
setblock ~166 ~119 ~102 dirt
setblock ~166 ~119 ~103 dirt
setblock ~166 ~119 ~104 dirt
setblock ~166 ~119 ~105 dirt
setblock ~166 ~119 ~106 dirt
setblock ~166 ~119 ~107 dirt
setblock ~166 ~119 ~108 dirt
setblock ~166 ~119 ~109 dirt
setblock ~166 ~119 ~119 dirt
setblock ~166 ~119 ~120 dirt
setblock ~166 ~119 ~121 dirt
setblock ~166 ~119 ~122 dirt
setblock ~166 ~119 ~123 dirt
setblock ~166 ~119 ~124 dirt
setblock ~166 ~119 ~127 dirt
setblock ~166 ~120 ~75 dirt
setblock ~166 ~120 ~76 dirt
setblock ~166 ~120 ~77 dirt
setblock ~166 ~120 ~78 dirt
setblock ~166 ~120 ~79 dirt
setblock ~166 ~120 ~80 dirt
setblock ~166 ~120 ~81 dirt
setblock ~166 ~120 ~82 dirt
setblock ~166 ~120 ~83 dirt
setblock ~166 ~120 ~84 dirt
setblock ~166 ~120 ~85 dirt
setblock ~166 ~120 ~86 dirt
setblock ~166 ~120 ~87 dirt
setblock ~166 ~120 ~88 dirt
setblock ~166 ~120 ~89 dirt
setblock ~166 ~120 ~90 dirt
setblock ~166 ~120 ~91 dirt
setblock ~166 ~120 ~92 dirt
setblock ~166 ~120 ~93 dirt
setblock ~166 ~120 ~94 dirt
setblock ~166 ~120 ~95 dirt
setblock ~166 ~120 ~96 dirt
setblock ~166 ~120 ~97 dirt
setblock ~166 ~120 ~98 dirt
setblock ~166 ~120 ~99 dirt
setblock ~166 ~120 ~100 dirt
setblock ~166 ~120 ~101 dirt
setblock ~166 ~120 ~102 dirt
setblock ~166 ~120 ~103 dirt
setblock ~166 ~120 ~104 dirt
setblock ~166 ~120 ~105 dirt
setblock ~166 ~120 ~106 dirt
setblock ~166 ~120 ~107 dirt
setblock ~166 ~120 ~108 dirt
setblock ~166 ~120 ~109 dirt
setblock ~166 ~120 ~117 dirt
setblock ~166 ~120 ~119 dirt
setblock ~166 ~120 ~120 dirt
setblock ~166 ~120 ~121 dirt
setblock ~166 ~120 ~122 dirt
setblock ~166 ~120 ~123 dirt
setblock ~166 ~120 ~124 dirt
setblock ~166 ~120 ~125 dirt
setblock ~166 ~120 ~126 dirt
setblock ~166 ~120 ~127 dirt
setblock ~166 ~121 ~74 dirt
setblock ~166 ~121 ~75 dirt
setblock ~166 ~121 ~76 dirt
setblock ~166 ~121 ~77 dirt
setblock ~166 ~121 ~78 dirt
setblock ~166 ~121 ~79 dirt
setblock ~166 ~121 ~80 dirt
setblock ~166 ~121 ~81 dirt
setblock ~166 ~121 ~82 dirt
setblock ~166 ~121 ~83 dirt
setblock ~166 ~121 ~84 dirt
setblock ~166 ~121 ~85 dirt
setblock ~166 ~121 ~86 dirt
setblock ~166 ~121 ~87 dirt
setblock ~166 ~121 ~88 dirt
setblock ~166 ~121 ~89 dirt
setblock ~166 ~121 ~90 dirt
setblock ~166 ~121 ~91 dirt
setblock ~166 ~121 ~92 dirt
setblock ~166 ~121 ~93 dirt
setblock ~166 ~121 ~94 dirt
setblock ~166 ~121 ~95 dirt
setblock ~166 ~121 ~96 dirt
setblock ~166 ~121 ~97 dirt
setblock ~166 ~121 ~98 dirt
setblock ~166 ~121 ~99 dirt
setblock ~166 ~121 ~100 dirt
setblock ~166 ~121 ~101 dirt
setblock ~166 ~121 ~102 dirt
setblock ~166 ~121 ~103 dirt
setblock ~166 ~121 ~104 dirt
setblock ~166 ~121 ~105 dirt
setblock ~166 ~121 ~106 dirt
setblock ~166 ~121 ~107 dirt
setblock ~166 ~121 ~108 dirt
setblock ~166 ~121 ~109 dirt
setblock ~166 ~121 ~110 dirt
setblock ~166 ~121 ~111 dirt
setblock ~166 ~121 ~116 dirt
setblock ~166 ~121 ~117 dirt
setblock ~166 ~121 ~118 dirt
setblock ~166 ~121 ~119 dirt
setblock ~166 ~121 ~120 dirt
setblock ~166 ~121 ~121 dirt
setblock ~166 ~121 ~122 dirt
setblock ~166 ~121 ~123 dirt
setblock ~166 ~121 ~124 dirt
setblock ~166 ~121 ~125 dirt
setblock ~166 ~121 ~126 dirt
setblock ~166 ~121 ~127 dirt
setblock ~166 ~121 ~129 dirt
setblock ~166 ~122 ~74 dirt
setblock ~166 ~122 ~75 dirt
setblock ~166 ~122 ~76 dirt
setblock ~166 ~122 ~77 dirt
setblock ~166 ~122 ~78 dirt
setblock ~166 ~122 ~79 dirt
setblock ~166 ~122 ~80 dirt
setblock ~166 ~122 ~81 dirt
setblock ~166 ~122 ~82 dirt
setblock ~166 ~122 ~83 dirt
setblock ~166 ~122 ~84 dirt
setblock ~166 ~122 ~85 dirt
setblock ~166 ~122 ~86 dirt
setblock ~166 ~122 ~87 dirt
setblock ~166 ~122 ~88 dirt
setblock ~166 ~122 ~89 dirt
setblock ~166 ~122 ~90 dirt
setblock ~166 ~122 ~91 dirt
setblock ~166 ~122 ~92 dirt
setblock ~166 ~122 ~93 dirt
setblock ~166 ~122 ~94 dirt
setblock ~166 ~122 ~95 dirt
setblock ~166 ~122 ~96 dirt
setblock ~166 ~122 ~97 dirt
setblock ~166 ~122 ~98 dirt
setblock ~166 ~122 ~99 dirt
setblock ~166 ~122 ~100 dirt
setblock ~166 ~122 ~101 dirt
setblock ~166 ~122 ~102 dirt
setblock ~166 ~122 ~103 dirt
setblock ~166 ~122 ~104 dirt
setblock ~166 ~122 ~105 dirt
setblock ~166 ~122 ~106 dirt
setblock ~166 ~122 ~107 dirt
setblock ~166 ~122 ~108 dirt
setblock ~166 ~122 ~109 dirt
setblock ~166 ~122 ~110 dirt
setblock ~166 ~122 ~111 dirt
setblock ~166 ~122 ~116 dirt
setblock ~166 ~122 ~117 dirt
setblock ~166 ~122 ~118 dirt
setblock ~166 ~122 ~119 dirt
setblock ~166 ~122 ~120 dirt
setblock ~166 ~122 ~121 dirt
setblock ~166 ~122 ~122 dirt
setblock ~166 ~122 ~123 dirt
setblock ~166 ~122 ~124 dirt
setblock ~166 ~122 ~125 dirt
setblock ~166 ~122 ~126 dirt
setblock ~166 ~122 ~127 dirt
setblock ~166 ~122 ~129 dirt
setblock ~166 ~123 ~74 dirt
setblock ~166 ~123 ~75 dirt
setblock ~166 ~123 ~76 dirt
setblock ~166 ~123 ~77 dirt
setblock ~166 ~123 ~78 dirt
setblock ~166 ~123 ~79 grass_block
setblock ~166 ~123 ~80 grass_block
setblock ~166 ~123 ~81 grass_block
setblock ~166 ~123 ~82 grass_block
setblock ~166 ~123 ~83 grass_block
setblock ~166 ~123 ~84 grass_block
setblock ~166 ~123 ~85 grass_block
setblock ~166 ~123 ~86 grass_block
setblock ~166 ~123 ~87 grass_block
setblock ~166 ~123 ~88 grass_block
setblock ~166 ~123 ~89 dirt
setblock ~166 ~123 ~90 dirt
setblock ~166 ~123 ~91 dirt
setblock ~166 ~123 ~92 dirt
setblock ~166 ~123 ~93 dirt
setblock ~166 ~123 ~94 dirt
setblock ~166 ~123 ~95 dirt
setblock ~166 ~123 ~96 dirt
setblock ~166 ~123 ~97 dirt
setblock ~166 ~123 ~98 dirt
setblock ~166 ~123 ~99 dirt
setblock ~166 ~123 ~100 dirt
setblock ~166 ~123 ~101 dirt
setblock ~166 ~123 ~102 dirt
setblock ~166 ~123 ~103 dirt
setblock ~166 ~123 ~104 dirt
setblock ~166 ~123 ~105 dirt
setblock ~166 ~123 ~106 dirt
setblock ~166 ~123 ~107 dirt
setblock ~166 ~123 ~108 dirt
setblock ~166 ~123 ~109 dirt
setblock ~166 ~123 ~110 dirt
setblock ~166 ~123 ~111 dirt
setblock ~166 ~123 ~116 dirt
setblock ~166 ~123 ~117 dirt
setblock ~166 ~123 ~118 dirt
setblock ~166 ~123 ~119 dirt
setblock ~166 ~123 ~120 dirt
setblock ~166 ~123 ~121 dirt
setblock ~166 ~123 ~122 dirt
setblock ~166 ~123 ~123 dirt
setblock ~166 ~123 ~124 dirt
setblock ~166 ~123 ~125 dirt
setblock ~166 ~123 ~126 dirt
setblock ~166 ~123 ~127 grass_block
setblock ~166 ~123 ~129 grass_block
setblock ~166 ~124 ~74 dirt
setblock ~166 ~124 ~75 dirt
setblock ~166 ~124 ~76 grass_block
setblock ~166 ~124 ~77 grass_block
setblock ~166 ~124 ~78 grass_block
setblock ~166 ~124 ~85 short_grass
setblock ~166 ~124 ~89 grass_block
setblock ~166 ~124 ~90 grass_block
setblock ~166 ~124 ~91 grass_block
setblock ~166 ~124 ~92 grass_block
setblock ~166 ~124 ~93 grass_block
setblock ~166 ~124 ~94 grass_block
setblock ~166 ~124 ~95 grass_block
setblock ~166 ~124 ~96 grass_block
setblock ~166 ~124 ~97 grass_block
setblock ~166 ~124 ~98 grass_block
setblock ~166 ~124 ~99 grass_block
setblock ~166 ~124 ~100 grass_block
setblock ~166 ~124 ~101 grass_block
setblock ~166 ~124 ~102 grass_block
setblock ~166 ~124 ~103 grass_block
setblock ~166 ~124 ~104 grass_block
setblock ~166 ~124 ~105 grass_block
setblock ~166 ~124 ~106 grass_block
setblock ~166 ~124 ~107 grass_block
setblock ~166 ~124 ~108 grass_block
setblock ~166 ~124 ~109 grass_block
setblock ~166 ~124 ~110 grass_block
setblock ~166 ~124 ~111 dirt
setblock ~166 ~124 ~116 dirt
setblock ~166 ~124 ~117 dirt
setblock ~166 ~124 ~118 dirt
setblock ~166 ~124 ~119 dirt
setblock ~166 ~124 ~120 dirt
setblock ~166 ~124 ~121 dirt
setblock ~166 ~124 ~122 dirt
setblock ~166 ~124 ~123 grass_block
setblock ~166 ~124 ~124 grass_block
setblock ~166 ~124 ~125 grass_block
setblock ~166 ~124 ~126 grass_block
setblock ~166 ~124 ~127 short_grass
setblock ~166 ~125 ~74 grass_block
setblock ~166 ~125 ~75 grass_block
setblock ~166 ~125 ~78 fern
setblock ~166 ~125 ~92 short_grass
setblock ~166 ~125 ~101 short_grass
setblock ~166 ~125 ~102 short_grass
setblock ~166 ~125 ~107 short_grass
setblock ~166 ~125 ~109 fern
setblock ~166 ~125 ~111 grass_block
setblock ~166 ~125 ~116 grass_block
setblock ~166 ~125 ~117 grass_block
setblock ~166 ~125 ~118 grass_block
setblock ~166 ~125 ~119 grass_block
setblock ~166 ~125 ~120 grass_block
setblock ~166 ~125 ~121 grass_block
setblock ~166 ~125 ~122 grass_block
setblock ~166 ~125 ~123 short_grass
setblock ~166 ~126 ~117 short_grass
setblock ~166 ~126 ~118 poppy
setblock ~167 ~109 ~84 dirt
setblock ~167 ~110 ~82 dirt
setblock ~167 ~110 ~83 dirt
setblock ~167 ~110 ~84 dirt
setblock ~167 ~111 ~81 dirt
setblock ~167 ~111 ~82 dirt
setblock ~167 ~111 ~83 dirt
setblock ~167 ~111 ~84 dirt
setblock ~167 ~111 ~85 dirt
setblock ~167 ~112 ~80 dirt
setblock ~167 ~112 ~81 dirt
setblock ~167 ~112 ~82 dirt
setblock ~167 ~112 ~83 dirt
setblock ~167 ~112 ~84 dirt
setblock ~167 ~112 ~85 dirt
setblock ~167 ~113 ~79 dirt
setblock ~167 ~113 ~80 dirt
setblock ~167 ~113 ~81 dirt
setblock ~167 ~113 ~82 dirt
setblock ~167 ~113 ~83 dirt
setblock ~167 ~113 ~84 dirt
setblock ~167 ~113 ~85 dirt
setblock ~167 ~113 ~86 dirt
setblock ~167 ~113 ~99 dirt
setblock ~167 ~114 ~77 dirt
setblock ~167 ~114 ~78 dirt
setblock ~167 ~114 ~79 dirt
setblock ~167 ~114 ~80 dirt
setblock ~167 ~114 ~81 dirt
setblock ~167 ~114 ~82 dirt
setblock ~167 ~114 ~83 dirt
setblock ~167 ~114 ~84 dirt
setblock ~167 ~114 ~85 dirt
setblock ~167 ~114 ~86 dirt
setblock ~167 ~114 ~87 dirt
setblock ~167 ~114 ~88 dirt
setblock ~167 ~114 ~89 dirt
setblock ~167 ~114 ~98 dirt
setblock ~167 ~114 ~99 dirt
setblock ~167 ~114 ~100 dirt
setblock ~167 ~115 ~77 dirt
setblock ~167 ~115 ~78 dirt
setblock ~167 ~115 ~79 dirt
setblock ~167 ~115 ~80 dirt
setblock ~167 ~115 ~81 dirt
setblock ~167 ~115 ~82 dirt
setblock ~167 ~115 ~83 dirt
setblock ~167 ~115 ~84 dirt
setblock ~167 ~115 ~85 dirt
setblock ~167 ~115 ~86 dirt
setblock ~167 ~115 ~87 dirt
setblock ~167 ~115 ~88 dirt
setblock ~167 ~115 ~89 dirt
setblock ~167 ~115 ~90 dirt
setblock ~167 ~115 ~91 dirt
setblock ~167 ~115 ~98 dirt
setblock ~167 ~115 ~99 dirt
setblock ~167 ~115 ~100 dirt
setblock ~167 ~115 ~101 dirt
setblock ~167 ~115 ~103 dirt
setblock ~167 ~115 ~105 dirt
setblock ~167 ~116 ~77 dirt
setblock ~167 ~116 ~78 dirt
setblock ~167 ~116 ~79 dirt
setblock ~167 ~116 ~80 dirt
setblock ~167 ~116 ~81 dirt
setblock ~167 ~116 ~82 dirt
setblock ~167 ~116 ~83 dirt
setblock ~167 ~116 ~84 dirt
setblock ~167 ~116 ~85 dirt
setblock ~167 ~116 ~86 dirt
setblock ~167 ~116 ~87 dirt
setblock ~167 ~116 ~88 dirt
setblock ~167 ~116 ~89 dirt
setblock ~167 ~116 ~90 dirt
setblock ~167 ~116 ~91 dirt
setblock ~167 ~116 ~92 dirt
setblock ~167 ~116 ~97 dirt
setblock ~167 ~116 ~98 dirt
setblock ~167 ~116 ~99 dirt
setblock ~167 ~116 ~100 dirt
setblock ~167 ~116 ~101 dirt
setblock ~167 ~116 ~103 dirt
setblock ~167 ~116 ~104 dirt
setblock ~167 ~116 ~105 dirt
setblock ~167 ~116 ~106 dirt
setblock ~167 ~117 ~76 dirt
setblock ~167 ~117 ~77 dirt
setblock ~167 ~117 ~78 dirt
setblock ~167 ~117 ~79 dirt
setblock ~167 ~117 ~80 dirt
setblock ~167 ~117 ~81 dirt
setblock ~167 ~117 ~82 dirt
setblock ~167 ~117 ~83 dirt
setblock ~167 ~117 ~84 dirt
setblock ~167 ~117 ~85 dirt
setblock ~167 ~117 ~86 dirt
setblock ~167 ~117 ~87 dirt
setblock ~167 ~117 ~88 dirt
setblock ~167 ~117 ~89 dirt
setblock ~167 ~117 ~90 dirt
setblock ~167 ~117 ~91 dirt
setblock ~167 ~117 ~92 dirt
setblock ~167 ~117 ~93 dirt
setblock ~167 ~117 ~95 dirt
setblock ~167 ~117 ~97 dirt
setblock ~167 ~117 ~98 dirt
setblock ~167 ~117 ~99 dirt
setblock ~167 ~117 ~100 dirt
setblock ~167 ~117 ~101 dirt
setblock ~167 ~117 ~103 dirt
setblock ~167 ~117 ~104 dirt
setblock ~167 ~117 ~105 dirt
setblock ~167 ~117 ~106 dirt
setblock ~167 ~117 ~121 dirt
setblock ~167 ~118 ~76 dirt
setblock ~167 ~118 ~77 dirt
setblock ~167 ~118 ~78 dirt
setblock ~167 ~118 ~79 dirt
setblock ~167 ~118 ~80 dirt
setblock ~167 ~118 ~81 dirt
setblock ~167 ~118 ~82 dirt
setblock ~167 ~118 ~83 dirt
setblock ~167 ~118 ~84 dirt
setblock ~167 ~118 ~85 dirt
setblock ~167 ~118 ~86 dirt
setblock ~167 ~118 ~87 dirt
setblock ~167 ~118 ~88 dirt
setblock ~167 ~118 ~89 dirt
setblock ~167 ~118 ~90 dirt
setblock ~167 ~118 ~91 dirt
setblock ~167 ~118 ~92 dirt
setblock ~167 ~118 ~93 dirt
setblock ~167 ~118 ~94 dirt
setblock ~167 ~118 ~95 dirt
setblock ~167 ~118 ~96 dirt
setblock ~167 ~118 ~97 dirt
setblock ~167 ~118 ~98 dirt
setblock ~167 ~118 ~99 dirt
setblock ~167 ~118 ~100 dirt
setblock ~167 ~118 ~101 dirt
setblock ~167 ~118 ~102 dirt
setblock ~167 ~118 ~103 dirt
setblock ~167 ~118 ~104 dirt
setblock ~167 ~118 ~105 dirt
setblock ~167 ~118 ~106 dirt
setblock ~167 ~118 ~120 dirt
setblock ~167 ~118 ~121 dirt
setblock ~167 ~118 ~122 dirt
setblock ~167 ~119 ~75 dirt
setblock ~167 ~119 ~76 dirt
setblock ~167 ~119 ~77 dirt
setblock ~167 ~119 ~78 dirt
setblock ~167 ~119 ~79 dirt
setblock ~167 ~119 ~80 dirt
setblock ~167 ~119 ~81 dirt
setblock ~167 ~119 ~82 dirt
setblock ~167 ~119 ~83 dirt
setblock ~167 ~119 ~84 dirt
setblock ~167 ~119 ~85 dirt
setblock ~167 ~119 ~86 dirt
setblock ~167 ~119 ~87 dirt
setblock ~167 ~119 ~88 dirt
setblock ~167 ~119 ~89 dirt
setblock ~167 ~119 ~90 dirt
setblock ~167 ~119 ~91 dirt
setblock ~167 ~119 ~92 dirt
setblock ~167 ~119 ~93 dirt
setblock ~167 ~119 ~94 dirt
setblock ~167 ~119 ~95 dirt
setblock ~167 ~119 ~96 dirt
setblock ~167 ~119 ~97 dirt
setblock ~167 ~119 ~98 dirt
setblock ~167 ~119 ~99 dirt
setblock ~167 ~119 ~100 dirt
setblock ~167 ~119 ~101 dirt
setblock ~167 ~119 ~102 dirt
setblock ~167 ~119 ~103 dirt
setblock ~167 ~119 ~104 dirt
setblock ~167 ~119 ~105 dirt
setblock ~167 ~119 ~106 dirt
setblock ~167 ~119 ~107 dirt
setblock ~167 ~119 ~108 dirt
setblock ~167 ~119 ~120 dirt
setblock ~167 ~119 ~121 dirt
setblock ~167 ~119 ~122 dirt
setblock ~167 ~119 ~123 dirt
setblock ~167 ~120 ~74 dirt
setblock ~167 ~120 ~75 dirt
setblock ~167 ~120 ~76 dirt
setblock ~167 ~120 ~77 dirt
setblock ~167 ~120 ~78 dirt
setblock ~167 ~120 ~79 dirt
setblock ~167 ~120 ~80 dirt
setblock ~167 ~120 ~81 dirt
setblock ~167 ~120 ~82 dirt
setblock ~167 ~120 ~83 dirt
setblock ~167 ~120 ~84 dirt
setblock ~167 ~120 ~85 dirt
setblock ~167 ~120 ~86 dirt
setblock ~167 ~120 ~87 dirt
setblock ~167 ~120 ~88 dirt
setblock ~167 ~120 ~89 dirt
setblock ~167 ~120 ~90 dirt
setblock ~167 ~120 ~91 dirt
setblock ~167 ~120 ~92 dirt
setblock ~167 ~120 ~93 dirt
setblock ~167 ~120 ~94 dirt
setblock ~167 ~120 ~95 dirt
setblock ~167 ~120 ~96 dirt
setblock ~167 ~120 ~97 dirt
setblock ~167 ~120 ~98 dirt
setblock ~167 ~120 ~99 dirt
setblock ~167 ~120 ~100 dirt
setblock ~167 ~120 ~101 dirt
setblock ~167 ~120 ~102 dirt
setblock ~167 ~120 ~103 dirt
setblock ~167 ~120 ~104 dirt
setblock ~167 ~120 ~105 dirt
setblock ~167 ~120 ~106 dirt
setblock ~167 ~120 ~107 dirt
setblock ~167 ~120 ~108 dirt
setblock ~167 ~120 ~120 dirt
setblock ~167 ~120 ~121 dirt
setblock ~167 ~120 ~122 dirt
setblock ~167 ~120 ~123 dirt
setblock ~167 ~121 ~74 dirt
setblock ~167 ~121 ~75 dirt
setblock ~167 ~121 ~76 dirt
setblock ~167 ~121 ~77 dirt
setblock ~167 ~121 ~78 dirt
setblock ~167 ~121 ~79 dirt
setblock ~167 ~121 ~80 dirt
setblock ~167 ~121 ~81 dirt
setblock ~167 ~121 ~82 dirt
setblock ~167 ~121 ~83 dirt
setblock ~167 ~121 ~84 dirt
setblock ~167 ~121 ~85 dirt
setblock ~167 ~121 ~86 dirt
setblock ~167 ~121 ~87 dirt
setblock ~167 ~121 ~88 dirt
setblock ~167 ~121 ~89 dirt
setblock ~167 ~121 ~90 dirt
setblock ~167 ~121 ~91 dirt
setblock ~167 ~121 ~92 dirt
setblock ~167 ~121 ~93 dirt
setblock ~167 ~121 ~94 dirt
setblock ~167 ~121 ~95 dirt
setblock ~167 ~121 ~96 dirt
setblock ~167 ~121 ~97 dirt
setblock ~167 ~121 ~98 dirt
setblock ~167 ~121 ~99 dirt
setblock ~167 ~121 ~100 dirt
setblock ~167 ~121 ~101 dirt
setblock ~167 ~121 ~102 dirt
setblock ~167 ~121 ~103 dirt
setblock ~167 ~121 ~104 dirt
setblock ~167 ~121 ~105 dirt
setblock ~167 ~121 ~106 dirt
setblock ~167 ~121 ~107 dirt
setblock ~167 ~121 ~108 dirt
setblock ~167 ~121 ~109 dirt
setblock ~167 ~121 ~119 dirt
setblock ~167 ~121 ~120 dirt
setblock ~167 ~121 ~121 dirt
setblock ~167 ~121 ~122 dirt
setblock ~167 ~121 ~123 dirt
setblock ~167 ~121 ~124 dirt
setblock ~167 ~122 ~74 dirt
setblock ~167 ~122 ~75 dirt
setblock ~167 ~122 ~76 dirt
setblock ~167 ~122 ~77 dirt
setblock ~167 ~122 ~78 dirt
setblock ~167 ~122 ~79 dirt
setblock ~167 ~122 ~80 dirt
setblock ~167 ~122 ~81 dirt
setblock ~167 ~122 ~82 dirt
setblock ~167 ~122 ~83 dirt
setblock ~167 ~122 ~84 dirt
setblock ~167 ~122 ~85 dirt
setblock ~167 ~122 ~86 dirt
setblock ~167 ~122 ~87 dirt
setblock ~167 ~122 ~88 dirt
setblock ~167 ~122 ~89 dirt
setblock ~167 ~122 ~90 dirt
setblock ~167 ~122 ~91 dirt
setblock ~167 ~122 ~92 dirt
setblock ~167 ~122 ~93 dirt
setblock ~167 ~122 ~94 dirt
setblock ~167 ~122 ~95 dirt
setblock ~167 ~122 ~96 dirt
setblock ~167 ~122 ~97 dirt
setblock ~167 ~122 ~98 dirt
setblock ~167 ~122 ~99 dirt
setblock ~167 ~122 ~100 dirt
setblock ~167 ~122 ~101 dirt
setblock ~167 ~122 ~102 dirt
setblock ~167 ~122 ~103 dirt
setblock ~167 ~122 ~104 dirt
setblock ~167 ~122 ~105 dirt
setblock ~167 ~122 ~106 dirt
setblock ~167 ~122 ~107 dirt
setblock ~167 ~122 ~108 dirt
setblock ~167 ~122 ~109 dirt
setblock ~167 ~122 ~119 dirt
setblock ~167 ~122 ~120 dirt
setblock ~167 ~122 ~121 dirt
setblock ~167 ~122 ~122 dirt
setblock ~167 ~122 ~123 dirt
setblock ~167 ~122 ~124 dirt
setblock ~167 ~123 ~74 dirt
setblock ~167 ~123 ~75 dirt
setblock ~167 ~123 ~76 dirt
setblock ~167 ~123 ~77 dirt
setblock ~167 ~123 ~78 grass_block
setblock ~167 ~123 ~79 grass_block
setblock ~167 ~123 ~80 grass_block
setblock ~167 ~123 ~81 grass_block
setblock ~167 ~123 ~82 grass_block
setblock ~167 ~123 ~83 grass_block
setblock ~167 ~123 ~84 grass_block
setblock ~167 ~123 ~85 grass_block
setblock ~167 ~123 ~86 grass_block
setblock ~167 ~123 ~87 grass_block
setblock ~167 ~123 ~88 dirt
setblock ~167 ~123 ~89 dirt
setblock ~167 ~123 ~90 dirt
setblock ~167 ~123 ~91 dirt
setblock ~167 ~123 ~92 dirt
setblock ~167 ~123 ~93 dirt
setblock ~167 ~123 ~94 dirt
setblock ~167 ~123 ~95 dirt
setblock ~167 ~123 ~96 dirt
setblock ~167 ~123 ~97 dirt
setblock ~167 ~123 ~98 dirt
setblock ~167 ~123 ~99 dirt
setblock ~167 ~123 ~100 dirt
setblock ~167 ~123 ~101 dirt
setblock ~167 ~123 ~102 dirt
setblock ~167 ~123 ~103 dirt
setblock ~167 ~123 ~104 dirt
setblock ~167 ~123 ~105 dirt
setblock ~167 ~123 ~106 dirt
setblock ~167 ~123 ~107 dirt
setblock ~167 ~123 ~108 dirt
setblock ~167 ~123 ~109 dirt
setblock ~167 ~123 ~119 dirt
setblock ~167 ~123 ~120 dirt
setblock ~167 ~123 ~121 dirt
setblock ~167 ~123 ~122 dirt
setblock ~167 ~123 ~123 dirt
setblock ~167 ~123 ~124 dirt
setblock ~167 ~124 ~74 dirt
setblock ~167 ~124 ~75 grass_block
setblock ~167 ~124 ~76 grass_block
setblock ~167 ~124 ~77 grass_block
setblock ~167 ~124 ~79 short_grass
setblock ~167 ~124 ~82 short_grass
setblock ~167 ~124 ~83 short_grass
setblock ~167 ~124 ~85 short_grass
setblock ~167 ~124 ~86 short_grass
setblock ~167 ~124 ~88 grass_block
setblock ~167 ~124 ~89 grass_block
setblock ~167 ~124 ~90 grass_block
setblock ~167 ~124 ~91 grass_block
setblock ~167 ~124 ~92 grass_block
setblock ~167 ~124 ~93 grass_block
setblock ~167 ~124 ~94 grass_block
setblock ~167 ~124 ~95 grass_block
setblock ~167 ~124 ~96 grass_block
setblock ~167 ~124 ~97 grass_block
setblock ~167 ~124 ~98 grass_block
setblock ~167 ~124 ~99 grass_block
setblock ~167 ~124 ~100 grass_block
setblock ~167 ~124 ~101 grass_block
setblock ~167 ~124 ~102 grass_block
setblock ~167 ~124 ~103 grass_block
setblock ~167 ~124 ~104 grass_block
setblock ~167 ~124 ~105 grass_block
setblock ~167 ~124 ~106 grass_block
setblock ~167 ~124 ~107 grass_block
setblock ~167 ~124 ~108 grass_block
setblock ~167 ~124 ~109 grass_block
setblock ~167 ~124 ~119 dirt
setblock ~167 ~124 ~120 dirt
setblock ~167 ~124 ~121 dirt
setblock ~167 ~124 ~122 dirt
setblock ~167 ~124 ~123 dirt
setblock ~167 ~124 ~124 grass_block
setblock ~167 ~125 ~74 grass_block
setblock ~167 ~125 ~75 short_grass
setblock ~167 ~125 ~77 short_grass
setblock ~167 ~125 ~91 poppy
setblock ~167 ~125 ~95 short_grass
setblock ~167 ~125 ~96 short_grass
setblock ~167 ~125 ~99 short_grass
setblock ~167 ~125 ~100 short_grass
setblock ~167 ~125 ~102 short_grass
setblock ~167 ~125 ~104 fern
setblock ~167 ~125 ~105 poppy
setblock ~167 ~125 ~109 short_grass
setblock ~167 ~125 ~119 grass_block
setblock ~167 ~125 ~120 dirt
setblock ~167 ~125 ~121 grass_block
setblock ~167 ~125 ~122 grass_block
setblock ~167 ~125 ~123 grass_block
setblock ~167 ~125 ~124 short_grass
setblock ~167 ~126 ~74 short_grass
setblock ~167 ~126 ~119 poppy
setblock ~167 ~126 ~120 grass_block
setblock ~168 ~111 ~84 dirt
setblock ~168 ~112 ~82 dirt
setblock ~168 ~112 ~84 dirt
setblock ~168 ~113 ~81 dirt
setblock ~168 ~113 ~82 dirt
setblock ~168 ~113 ~83 dirt
setblock ~168 ~113 ~84 dirt
setblock ~168 ~113 ~85 dirt
setblock ~168 ~114 ~80 dirt
setblock ~168 ~114 ~81 dirt
setblock ~168 ~114 ~82 dirt
setblock ~168 ~114 ~83 dirt
setblock ~168 ~114 ~84 dirt
setblock ~168 ~114 ~85 dirt
setblock ~168 ~114 ~86 dirt
setblock ~168 ~114 ~99 dirt
setblock ~168 ~115 ~78 dirt
setblock ~168 ~115 ~79 dirt
setblock ~168 ~115 ~80 dirt
setblock ~168 ~115 ~81 dirt
setblock ~168 ~115 ~82 dirt
setblock ~168 ~115 ~83 dirt
setblock ~168 ~115 ~84 dirt
setblock ~168 ~115 ~85 dirt
setblock ~168 ~115 ~86 dirt
setblock ~168 ~115 ~87 dirt
setblock ~168 ~115 ~89 dirt
setblock ~168 ~115 ~98 dirt
setblock ~168 ~115 ~99 dirt
setblock ~168 ~115 ~100 dirt
setblock ~168 ~116 ~78 dirt
setblock ~168 ~116 ~79 dirt
setblock ~168 ~116 ~80 dirt
setblock ~168 ~116 ~81 dirt
setblock ~168 ~116 ~82 dirt
setblock ~168 ~116 ~83 dirt
setblock ~168 ~116 ~84 dirt
setblock ~168 ~116 ~85 dirt
setblock ~168 ~116 ~86 dirt
setblock ~168 ~116 ~87 dirt
setblock ~168 ~116 ~89 dirt
setblock ~168 ~116 ~90 dirt
setblock ~168 ~116 ~91 dirt
setblock ~168 ~116 ~98 dirt
setblock ~168 ~116 ~99 dirt
setblock ~168 ~116 ~100 dirt
setblock ~168 ~116 ~105 dirt
setblock ~168 ~117 ~77 dirt
setblock ~168 ~117 ~78 dirt
setblock ~168 ~117 ~79 dirt
setblock ~168 ~117 ~80 dirt
setblock ~168 ~117 ~81 dirt
setblock ~168 ~117 ~82 dirt
setblock ~168 ~117 ~83 dirt
setblock ~168 ~117 ~84 dirt
setblock ~168 ~117 ~85 dirt
setblock ~168 ~117 ~86 dirt
setblock ~168 ~117 ~87 dirt
setblock ~168 ~117 ~88 dirt
setblock ~168 ~117 ~89 dirt
setblock ~168 ~117 ~90 dirt
setblock ~168 ~117 ~91 dirt
setblock ~168 ~117 ~92 dirt
setblock ~168 ~117 ~98 dirt
setblock ~168 ~117 ~99 dirt
setblock ~168 ~117 ~100 dirt
setblock ~168 ~117 ~101 dirt
setblock ~168 ~117 ~104 dirt
setblock ~168 ~117 ~105 dirt
setblock ~168 ~118 ~77 dirt
setblock ~168 ~118 ~78 dirt
setblock ~168 ~118 ~79 dirt
setblock ~168 ~118 ~80 dirt
setblock ~168 ~118 ~81 dirt
setblock ~168 ~118 ~82 dirt
setblock ~168 ~118 ~83 dirt
setblock ~168 ~118 ~84 dirt
setblock ~168 ~118 ~85 dirt
setblock ~168 ~118 ~86 dirt
setblock ~168 ~118 ~87 dirt
setblock ~168 ~118 ~88 dirt
setblock ~168 ~118 ~89 dirt
setblock ~168 ~118 ~90 dirt
setblock ~168 ~118 ~91 dirt
setblock ~168 ~118 ~92 dirt
setblock ~168 ~118 ~95 dirt
setblock ~168 ~118 ~97 dirt
setblock ~168 ~118 ~98 dirt
setblock ~168 ~118 ~99 dirt
setblock ~168 ~118 ~100 dirt
setblock ~168 ~118 ~101 dirt
setblock ~168 ~118 ~102 dirt
setblock ~168 ~118 ~103 dirt
setblock ~168 ~118 ~104 dirt
setblock ~168 ~118 ~105 dirt
setblock ~168 ~118 ~121 dirt
setblock ~168 ~119 ~76 dirt
setblock ~168 ~119 ~77 dirt
setblock ~168 ~119 ~78 dirt
setblock ~168 ~119 ~79 dirt
setblock ~168 ~119 ~80 dirt
setblock ~168 ~119 ~81 dirt
setblock ~168 ~119 ~82 dirt
setblock ~168 ~119 ~83 dirt
setblock ~168 ~119 ~84 dirt
setblock ~168 ~119 ~85 dirt
setblock ~168 ~119 ~86 dirt
setblock ~168 ~119 ~87 dirt
setblock ~168 ~119 ~88 dirt
setblock ~168 ~119 ~89 dirt
setblock ~168 ~119 ~90 dirt
setblock ~168 ~119 ~91 dirt
setblock ~168 ~119 ~92 dirt
setblock ~168 ~119 ~93 dirt
setblock ~168 ~119 ~94 dirt
setblock ~168 ~119 ~95 dirt
setblock ~168 ~119 ~96 dirt
setblock ~168 ~119 ~97 dirt
setblock ~168 ~119 ~98 dirt
setblock ~168 ~119 ~99 dirt
setblock ~168 ~119 ~100 dirt
setblock ~168 ~119 ~101 dirt
setblock ~168 ~119 ~102 dirt
setblock ~168 ~119 ~103 dirt
setblock ~168 ~119 ~104 dirt
setblock ~168 ~119 ~105 dirt
setblock ~168 ~119 ~106 dirt
setblock ~168 ~119 ~120 dirt
setblock ~168 ~119 ~121 dirt
setblock ~168 ~119 ~122 dirt
setblock ~168 ~120 ~75 dirt
setblock ~168 ~120 ~76 dirt
setblock ~168 ~120 ~77 dirt
setblock ~168 ~120 ~78 dirt
setblock ~168 ~120 ~79 dirt
setblock ~168 ~120 ~80 dirt
setblock ~168 ~120 ~81 dirt
setblock ~168 ~120 ~82 dirt
setblock ~168 ~120 ~83 dirt
setblock ~168 ~120 ~84 dirt
setblock ~168 ~120 ~85 dirt
setblock ~168 ~120 ~86 dirt
setblock ~168 ~120 ~87 dirt
setblock ~168 ~120 ~88 dirt
setblock ~168 ~120 ~89 dirt
setblock ~168 ~120 ~90 dirt
setblock ~168 ~120 ~91 dirt
setblock ~168 ~120 ~92 dirt
setblock ~168 ~120 ~93 dirt
setblock ~168 ~120 ~94 dirt
setblock ~168 ~120 ~95 dirt
setblock ~168 ~120 ~96 dirt
setblock ~168 ~120 ~97 dirt
setblock ~168 ~120 ~98 dirt
setblock ~168 ~120 ~99 dirt
setblock ~168 ~120 ~100 dirt
setblock ~168 ~120 ~101 dirt
setblock ~168 ~120 ~102 dirt
setblock ~168 ~120 ~103 dirt
setblock ~168 ~120 ~104 dirt
setblock ~168 ~120 ~105 dirt
setblock ~168 ~120 ~106 dirt
setblock ~168 ~120 ~120 dirt
setblock ~168 ~120 ~121 dirt
setblock ~168 ~120 ~122 dirt
setblock ~168 ~120 ~123 dirt
setblock ~168 ~121 ~75 dirt
setblock ~168 ~121 ~76 dirt
setblock ~168 ~121 ~77 dirt
setblock ~168 ~121 ~78 dirt
setblock ~168 ~121 ~79 dirt
setblock ~168 ~121 ~80 dirt
setblock ~168 ~121 ~81 dirt
setblock ~168 ~121 ~82 dirt
setblock ~168 ~121 ~83 dirt
setblock ~168 ~121 ~84 dirt
setblock ~168 ~121 ~85 dirt
setblock ~168 ~121 ~86 dirt
setblock ~168 ~121 ~87 dirt
setblock ~168 ~121 ~88 dirt
setblock ~168 ~121 ~89 dirt
setblock ~168 ~121 ~90 dirt
setblock ~168 ~121 ~91 dirt
setblock ~168 ~121 ~92 dirt
setblock ~168 ~121 ~93 dirt
setblock ~168 ~121 ~94 dirt
setblock ~168 ~121 ~95 dirt
setblock ~168 ~121 ~96 dirt
setblock ~168 ~121 ~97 dirt
setblock ~168 ~121 ~98 dirt
setblock ~168 ~121 ~99 dirt
setblock ~168 ~121 ~100 dirt
setblock ~168 ~121 ~101 dirt
setblock ~168 ~121 ~102 dirt
setblock ~168 ~121 ~103 dirt
setblock ~168 ~121 ~104 dirt
setblock ~168 ~121 ~105 dirt
setblock ~168 ~121 ~106 dirt
setblock ~168 ~121 ~108 dirt
setblock ~168 ~121 ~120 dirt
setblock ~168 ~121 ~121 dirt
setblock ~168 ~121 ~122 dirt
setblock ~168 ~121 ~123 dirt
setblock ~168 ~122 ~75 dirt
setblock ~168 ~122 ~76 dirt
setblock ~168 ~122 ~77 dirt
setblock ~168 ~122 ~78 dirt
setblock ~168 ~122 ~79 dirt
setblock ~168 ~122 ~80 dirt
setblock ~168 ~122 ~81 dirt
setblock ~168 ~122 ~82 dirt
setblock ~168 ~122 ~83 dirt
setblock ~168 ~122 ~84 dirt
setblock ~168 ~122 ~85 dirt
setblock ~168 ~122 ~86 dirt
setblock ~168 ~122 ~87 dirt
setblock ~168 ~122 ~88 dirt
setblock ~168 ~122 ~89 dirt
setblock ~168 ~122 ~90 dirt
setblock ~168 ~122 ~91 dirt
setblock ~168 ~122 ~92 dirt
setblock ~168 ~122 ~93 dirt
setblock ~168 ~122 ~94 dirt
setblock ~168 ~122 ~95 dirt
setblock ~168 ~122 ~96 dirt
setblock ~168 ~122 ~97 dirt
setblock ~168 ~122 ~98 dirt
setblock ~168 ~122 ~99 dirt
setblock ~168 ~122 ~100 dirt
setblock ~168 ~122 ~101 dirt
setblock ~168 ~122 ~102 dirt
setblock ~168 ~122 ~103 dirt
setblock ~168 ~122 ~104 dirt
setblock ~168 ~122 ~105 dirt
setblock ~168 ~122 ~106 dirt
setblock ~168 ~122 ~108 dirt
setblock ~168 ~122 ~120 dirt
setblock ~168 ~122 ~121 dirt
setblock ~168 ~122 ~122 dirt
setblock ~168 ~122 ~123 dirt
setblock ~168 ~123 ~75 dirt
setblock ~168 ~123 ~76 dirt
setblock ~168 ~123 ~77 grass_block
setblock ~168 ~123 ~78 grass_block
setblock ~168 ~123 ~79 grass_block
setblock ~168 ~123 ~80 grass_block
setblock ~168 ~123 ~81 grass_block
setblock ~168 ~123 ~82 grass_block
setblock ~168 ~123 ~83 grass_block
setblock ~168 ~123 ~84 grass_block
setblock ~168 ~123 ~85 grass_block
setblock ~168 ~123 ~86 grass_block
setblock ~168 ~123 ~87 grass_block
setblock ~168 ~123 ~88 dirt
setblock ~168 ~123 ~89 dirt
setblock ~168 ~123 ~90 dirt
setblock ~168 ~123 ~91 dirt
setblock ~168 ~123 ~92 dirt
setblock ~168 ~123 ~93 dirt
setblock ~168 ~123 ~94 dirt
setblock ~168 ~123 ~95 dirt
setblock ~168 ~123 ~96 dirt
setblock ~168 ~123 ~97 dirt
setblock ~168 ~123 ~98 dirt
setblock ~168 ~123 ~99 dirt
setblock ~168 ~123 ~100 dirt
setblock ~168 ~123 ~101 dirt
setblock ~168 ~123 ~102 dirt
setblock ~168 ~123 ~103 dirt
setblock ~168 ~123 ~104 dirt
setblock ~168 ~123 ~105 dirt
setblock ~168 ~123 ~106 dirt
setblock ~168 ~123 ~108 dirt
setblock ~168 ~123 ~120 dirt
setblock ~168 ~123 ~121 dirt
setblock ~168 ~123 ~122 dirt
setblock ~168 ~123 ~123 dirt
setblock ~168 ~124 ~75 grass_block
setblock ~168 ~124 ~76 grass_block
setblock ~168 ~124 ~88 grass_block
setblock ~168 ~124 ~89 grass_block
setblock ~168 ~124 ~90 grass_block
setblock ~168 ~124 ~91 grass_block
setblock ~168 ~124 ~92 grass_block
setblock ~168 ~124 ~93 grass_block
setblock ~168 ~124 ~94 grass_block
setblock ~168 ~124 ~95 grass_block
setblock ~168 ~124 ~96 grass_block
setblock ~168 ~124 ~97 grass_block
setblock ~168 ~124 ~98 grass_block
setblock ~168 ~124 ~99 grass_block
setblock ~168 ~124 ~100 grass_block
setblock ~168 ~124 ~101 grass_block
setblock ~168 ~124 ~102 grass_block
setblock ~168 ~124 ~103 grass_block
setblock ~168 ~124 ~104 grass_block
setblock ~168 ~124 ~105 grass_block
setblock ~168 ~124 ~106 grass_block
setblock ~168 ~124 ~108 grass_block
setblock ~168 ~124 ~120 dirt
setblock ~168 ~124 ~121 dirt
setblock ~168 ~124 ~122 dirt
setblock ~168 ~124 ~123 dirt
setblock ~168 ~125 ~93 short_grass
setblock ~168 ~125 ~99 short_grass
setblock ~168 ~125 ~102 short_grass
setblock ~168 ~125 ~108 short_grass
setblock ~168 ~125 ~120 dirt
setblock ~168 ~125 ~121 grass_block
setblock ~168 ~125 ~122 grass_block
setblock ~168 ~125 ~123 grass_block
setblock ~168 ~126 ~120 grass_block
setblock ~168 ~127 ~120 fern
setblock ~169 ~113 ~84 dirt
setblock ~169 ~114 ~81 dirt
setblock ~169 ~114 ~82 dirt
setblock ~169 ~114 ~83 dirt
setblock ~169 ~114 ~84 dirt
setblock ~169 ~114 ~85 dirt
setblock ~169 ~115 ~80 dirt
setblock ~169 ~115 ~81 dirt
setblock ~169 ~115 ~82 dirt
setblock ~169 ~115 ~83 dirt
setblock ~169 ~115 ~84 dirt
setblock ~169 ~115 ~85 dirt
setblock ~169 ~115 ~86 dirt
setblock ~169 ~115 ~99 dirt
setblock ~169 ~116 ~80 dirt
setblock ~169 ~116 ~81 dirt
setblock ~169 ~116 ~82 dirt
setblock ~169 ~116 ~83 dirt
setblock ~169 ~116 ~84 dirt
setblock ~169 ~116 ~85 dirt
setblock ~169 ~116 ~86 dirt
setblock ~169 ~116 ~99 dirt
setblock ~169 ~117 ~78 dirt
setblock ~169 ~117 ~80 dirt
setblock ~169 ~117 ~81 dirt
setblock ~169 ~117 ~82 dirt
setblock ~169 ~117 ~83 dirt
setblock ~169 ~117 ~84 dirt
setblock ~169 ~117 ~85 dirt
setblock ~169 ~117 ~86 dirt
setblock ~169 ~117 ~87 dirt
setblock ~169 ~117 ~89 dirt
setblock ~169 ~117 ~99 dirt
setblock ~169 ~117 ~100 dirt
setblock ~169 ~118 ~78 dirt
setblock ~169 ~118 ~79 dirt
setblock ~169 ~118 ~80 dirt
setblock ~169 ~118 ~81 dirt
setblock ~169 ~118 ~82 dirt
setblock ~169 ~118 ~83 dirt
setblock ~169 ~118 ~84 dirt
setblock ~169 ~118 ~85 dirt
setblock ~169 ~118 ~86 dirt
setblock ~169 ~118 ~87 dirt
setblock ~169 ~118 ~88 dirt
setblock ~169 ~118 ~89 dirt
setblock ~169 ~118 ~98 dirt
setblock ~169 ~118 ~99 dirt
setblock ~169 ~118 ~100 dirt
setblock ~169 ~118 ~101 dirt
setblock ~169 ~119 ~77 dirt
setblock ~169 ~119 ~78 dirt
setblock ~169 ~119 ~79 dirt
setblock ~169 ~119 ~80 dirt
setblock ~169 ~119 ~81 dirt
setblock ~169 ~119 ~82 dirt
setblock ~169 ~119 ~83 dirt
setblock ~169 ~119 ~84 dirt
setblock ~169 ~119 ~85 dirt
setblock ~169 ~119 ~86 dirt
setblock ~169 ~119 ~87 dirt
setblock ~169 ~119 ~88 dirt
setblock ~169 ~119 ~89 dirt
setblock ~169 ~119 ~90 dirt
setblock ~169 ~119 ~95 dirt
setblock ~169 ~119 ~97 dirt
setblock ~169 ~119 ~98 dirt
setblock ~169 ~119 ~99 dirt
setblock ~169 ~119 ~100 dirt
setblock ~169 ~119 ~101 dirt
setblock ~169 ~119 ~102 dirt
setblock ~169 ~119 ~121 dirt
setblock ~169 ~120 ~77 dirt
setblock ~169 ~120 ~78 dirt
setblock ~169 ~120 ~79 dirt
setblock ~169 ~120 ~80 dirt
setblock ~169 ~120 ~81 dirt
setblock ~169 ~120 ~82 dirt
setblock ~169 ~120 ~83 dirt
setblock ~169 ~120 ~84 dirt
setblock ~169 ~120 ~85 dirt
setblock ~169 ~120 ~86 dirt
setblock ~169 ~120 ~87 dirt
setblock ~169 ~120 ~88 dirt
setblock ~169 ~120 ~89 dirt
setblock ~169 ~120 ~90 dirt
setblock ~169 ~120 ~91 dirt
setblock ~169 ~120 ~93 dirt
setblock ~169 ~120 ~94 dirt
setblock ~169 ~120 ~95 dirt
setblock ~169 ~120 ~96 dirt
setblock ~169 ~120 ~97 dirt
setblock ~169 ~120 ~98 dirt
setblock ~169 ~120 ~99 dirt
setblock ~169 ~120 ~100 dirt
setblock ~169 ~120 ~101 dirt
setblock ~169 ~120 ~102 dirt
setblock ~169 ~120 ~103 dirt
setblock ~169 ~120 ~105 dirt
setblock ~169 ~120 ~121 dirt
setblock ~169 ~120 ~122 dirt
setblock ~169 ~121 ~76 dirt
setblock ~169 ~121 ~77 dirt
setblock ~169 ~121 ~78 dirt
setblock ~169 ~121 ~79 dirt
setblock ~169 ~121 ~80 dirt
setblock ~169 ~121 ~81 dirt
setblock ~169 ~121 ~82 dirt
setblock ~169 ~121 ~83 dirt
setblock ~169 ~121 ~84 dirt
setblock ~169 ~121 ~85 dirt
setblock ~169 ~121 ~86 dirt
setblock ~169 ~121 ~87 dirt
setblock ~169 ~121 ~88 dirt
setblock ~169 ~121 ~89 dirt
setblock ~169 ~121 ~90 dirt
setblock ~169 ~121 ~91 dirt
setblock ~169 ~121 ~92 dirt
setblock ~169 ~121 ~93 dirt
setblock ~169 ~121 ~94 dirt
setblock ~169 ~121 ~95 dirt
setblock ~169 ~121 ~96 dirt
setblock ~169 ~121 ~97 dirt
setblock ~169 ~121 ~98 dirt
setblock ~169 ~121 ~99 dirt
setblock ~169 ~121 ~100 dirt
setblock ~169 ~121 ~101 dirt
setblock ~169 ~121 ~102 dirt
setblock ~169 ~121 ~103 dirt
setblock ~169 ~121 ~104 dirt
setblock ~169 ~121 ~105 dirt
setblock ~169 ~121 ~121 dirt
setblock ~169 ~121 ~122 dirt
setblock ~169 ~122 ~76 dirt
setblock ~169 ~122 ~77 dirt
setblock ~169 ~122 ~78 dirt
setblock ~169 ~122 ~79 dirt
setblock ~169 ~122 ~80 grass_block
setblock ~169 ~122 ~81 dirt
setblock ~169 ~122 ~82 dirt
setblock ~169 ~122 ~83 dirt
setblock ~169 ~122 ~84 dirt
setblock ~169 ~122 ~85 dirt
setblock ~169 ~122 ~86 dirt
setblock ~169 ~122 ~87 dirt
setblock ~169 ~122 ~88 dirt
setblock ~169 ~122 ~89 dirt
setblock ~169 ~122 ~90 dirt
setblock ~169 ~122 ~91 dirt
setblock ~169 ~122 ~92 dirt
setblock ~169 ~122 ~93 dirt
setblock ~169 ~122 ~94 dirt
setblock ~169 ~122 ~95 dirt
setblock ~169 ~122 ~96 dirt
