setblock ~142 ~124 ~112 dirt
setblock ~142 ~125 ~93 dirt
setblock ~142 ~125 ~94 dirt
setblock ~142 ~125 ~95 dirt
setblock ~142 ~125 ~96 dirt
setblock ~142 ~125 ~97 dirt
setblock ~142 ~125 ~98 dirt
setblock ~142 ~125 ~99 grass_block
setblock ~142 ~125 ~100 grass_block
setblock ~142 ~125 ~101 dirt
setblock ~142 ~125 ~102 dirt
setblock ~142 ~125 ~103 dirt
setblock ~142 ~125 ~104 dirt
setblock ~142 ~125 ~105 dirt
setblock ~142 ~125 ~106 dirt
setblock ~142 ~125 ~107 dirt
setblock ~142 ~125 ~108 dirt
setblock ~142 ~125 ~109 dirt
setblock ~142 ~125 ~110 dirt
setblock ~142 ~125 ~111 dirt
setblock ~142 ~125 ~112 dirt
setblock ~142 ~126 ~93 grass_block
setblock ~142 ~126 ~94 grass_block
setblock ~142 ~126 ~95 grass_block
setblock ~142 ~126 ~96 grass_block
setblock ~142 ~126 ~97 grass_block
setblock ~142 ~126 ~98 grass_block
setblock ~142 ~126 ~101 grass_block
setblock ~142 ~126 ~102 grass_block
setblock ~142 ~126 ~103 grass_block
setblock ~142 ~126 ~104 dirt
setblock ~142 ~126 ~105 dirt
setblock ~142 ~126 ~106 dirt
setblock ~142 ~126 ~107 dirt
setblock ~142 ~126 ~108 dirt
setblock ~142 ~126 ~109 dirt
setblock ~142 ~126 ~110 dirt
setblock ~142 ~126 ~111 dirt
setblock ~142 ~126 ~112 dirt
setblock ~142 ~127 ~93 short_grass
setblock ~142 ~127 ~94 short_grass
setblock ~142 ~127 ~96 short_grass
setblock ~142 ~127 ~98 short_grass
setblock ~142 ~127 ~104 grass_block
setblock ~142 ~127 ~105 grass_block
setblock ~142 ~127 ~106 grass_block
setblock ~142 ~127 ~107 grass_block
setblock ~142 ~127 ~108 grass_block
setblock ~142 ~127 ~109 dirt
setblock ~142 ~127 ~110 dirt
setblock ~142 ~127 ~111 dirt
setblock ~142 ~127 ~112 grass_block
setblock ~142 ~128 ~109 grass_block
setblock ~142 ~128 ~110 grass_block
setblock ~142 ~128 ~111 grass_block
setblock ~142 ~128 ~112 short_grass
setblock ~142 ~129 ~109 short_grass
setblock ~143 ~115 ~100 dirt
setblock ~143 ~116 ~99 dirt
setblock ~143 ~116 ~100 dirt
setblock ~143 ~116 ~101 dirt
setblock ~143 ~117 ~98 dirt
setblock ~143 ~117 ~99 dirt
setblock ~143 ~117 ~100 dirt
setblock ~143 ~117 ~101 dirt
setblock ~143 ~118 ~96 dirt
setblock ~143 ~118 ~97 dirt
setblock ~143 ~118 ~98 dirt
setblock ~143 ~118 ~99 dirt
setblock ~143 ~118 ~100 dirt
setblock ~143 ~118 ~101 dirt
setblock ~143 ~118 ~102 dirt
setblock ~143 ~118 ~103 dirt
setblock ~143 ~118 ~105 dirt
setblock ~143 ~118 ~106 dirt
setblock ~143 ~118 ~107 dirt
setblock ~143 ~119 ~95 dirt
setblock ~143 ~119 ~96 dirt
setblock ~143 ~119 ~97 dirt
setblock ~143 ~119 ~98 dirt
setblock ~143 ~119 ~99 dirt
setblock ~143 ~119 ~100 dirt
setblock ~143 ~119 ~101 dirt
setblock ~143 ~119 ~102 dirt
setblock ~143 ~119 ~103 dirt
setblock ~143 ~119 ~104 dirt
setblock ~143 ~119 ~105 dirt
setblock ~143 ~119 ~106 dirt
setblock ~143 ~119 ~107 dirt
setblock ~143 ~120 ~94 dirt
setblock ~143 ~120 ~95 dirt
setblock ~143 ~120 ~96 dirt
setblock ~143 ~120 ~97 dirt
setblock ~143 ~120 ~98 dirt
setblock ~143 ~120 ~99 dirt
setblock ~143 ~120 ~100 dirt
setblock ~143 ~120 ~101 dirt
setblock ~143 ~120 ~102 dirt
setblock ~143 ~120 ~103 dirt
setblock ~143 ~120 ~104 dirt
setblock ~143 ~120 ~105 dirt
setblock ~143 ~120 ~106 dirt
setblock ~143 ~120 ~107 dirt
setblock ~143 ~120 ~108 dirt
setblock ~143 ~121 ~94 dirt
setblock ~143 ~121 ~95 dirt
setblock ~143 ~121 ~96 dirt
setblock ~143 ~121 ~97 dirt
setblock ~143 ~121 ~98 dirt
setblock ~143 ~121 ~99 dirt
setblock ~143 ~121 ~100 dirt
setblock ~143 ~121 ~101 dirt
setblock ~143 ~121 ~102 dirt
setblock ~143 ~121 ~103 dirt
setblock ~143 ~121 ~104 dirt
setblock ~143 ~121 ~105 dirt
setblock ~143 ~121 ~106 dirt
setblock ~143 ~121 ~107 dirt
setblock ~143 ~121 ~108 dirt
setblock ~143 ~121 ~109 dirt
setblock ~143 ~121 ~111 dirt
setblock ~143 ~122 ~94 dirt
setblock ~143 ~122 ~95 dirt
setblock ~143 ~122 ~96 dirt
setblock ~143 ~122 ~97 dirt
setblock ~143 ~122 ~98 dirt
setblock ~143 ~122 ~99 dirt
setblock ~143 ~122 ~100 dirt
setblock ~143 ~122 ~101 dirt
setblock ~143 ~122 ~102 dirt
setblock ~143 ~122 ~103 dirt
setblock ~143 ~122 ~104 dirt
setblock ~143 ~122 ~105 dirt
setblock ~143 ~122 ~106 dirt
setblock ~143 ~122 ~107 dirt
setblock ~143 ~122 ~108 dirt
setblock ~143 ~122 ~109 dirt
setblock ~143 ~122 ~111 dirt
setblock ~143 ~123 ~94 dirt
setblock ~143 ~123 ~95 dirt
setblock ~143 ~123 ~96 dirt
setblock ~143 ~123 ~97 dirt
setblock ~143 ~123 ~98 dirt
setblock ~143 ~123 ~99 dirt
setblock ~143 ~123 ~100 dirt
setblock ~143 ~123 ~101 dirt
setblock ~143 ~123 ~102 dirt
setblock ~143 ~123 ~103 dirt
setblock ~143 ~123 ~104 dirt
setblock ~143 ~123 ~105 dirt
setblock ~143 ~123 ~106 dirt
setblock ~143 ~123 ~107 dirt
setblock ~143 ~123 ~108 dirt
setblock ~143 ~123 ~109 dirt
setblock ~143 ~123 ~111 dirt
setblock ~143 ~124 ~94 dirt
setblock ~143 ~124 ~95 dirt
setblock ~143 ~124 ~96 dirt
setblock ~143 ~124 ~97 dirt
setblock ~143 ~124 ~98 dirt
setblock ~143 ~124 ~99 dirt
setblock ~143 ~124 ~100 dirt
setblock ~143 ~124 ~101 dirt
setblock ~143 ~124 ~102 dirt
setblock ~143 ~124 ~103 dirt
setblock ~143 ~124 ~104 dirt
setblock ~143 ~124 ~105 dirt
setblock ~143 ~124 ~106 dirt
setblock ~143 ~124 ~107 dirt
setblock ~143 ~124 ~108 dirt
setblock ~143 ~124 ~109 dirt
setblock ~143 ~124 ~111 dirt
setblock ~143 ~125 ~94 dirt
setblock ~143 ~125 ~95 dirt
setblock ~143 ~125 ~96 dirt
setblock ~143 ~125 ~97 dirt
setblock ~143 ~125 ~98 dirt
setblock ~143 ~125 ~99 dirt
setblock ~143 ~125 ~100 dirt
setblock ~143 ~125 ~101 dirt
setblock ~143 ~125 ~102 dirt
setblock ~143 ~125 ~103 dirt
setblock ~143 ~125 ~104 dirt
setblock ~143 ~125 ~105 dirt
setblock ~143 ~125 ~106 dirt
setblock ~143 ~125 ~107 dirt
setblock ~143 ~125 ~108 dirt
setblock ~143 ~125 ~109 dirt
setblock ~143 ~125 ~111 dirt
setblock ~143 ~126 ~94 grass_block
setblock ~143 ~126 ~95 grass_block
setblock ~143 ~126 ~96 grass_block
setblock ~143 ~126 ~97 grass_block
setblock ~143 ~126 ~98 grass_block
setblock ~143 ~126 ~99 grass_block
setblock ~143 ~126 ~100 grass_block
setblock ~143 ~126 ~101 grass_block
setblock ~143 ~126 ~102 grass_block
setblock ~143 ~126 ~103 dirt
setblock ~143 ~126 ~104 dirt
setblock ~143 ~126 ~105 dirt
setblock ~143 ~126 ~106 dirt
setblock ~143 ~126 ~107 dirt
setblock ~143 ~126 ~108 dirt
setblock ~143 ~126 ~109 dirt
setblock ~143 ~126 ~111 dirt
setblock ~143 ~127 ~95 short_grass
setblock ~143 ~127 ~103 grass_block
setblock ~143 ~127 ~104 grass_block
setblock ~143 ~127 ~105 grass_block
setblock ~143 ~127 ~106 grass_block
setblock ~143 ~127 ~107 grass_block
setblock ~143 ~127 ~108 dirt
setblock ~143 ~127 ~109 dirt
setblock ~143 ~127 ~111 dirt
setblock ~143 ~128 ~105 short_grass
setblock ~143 ~128 ~108 grass_block
setblock ~143 ~128 ~109 grass_block
setblock ~143 ~128 ~111 grass_block
setblock ~143 ~129 ~108 short_grass
setblock ~144 ~116 ~100 dirt
setblock ~144 ~117 ~99 dirt
setblock ~144 ~117 ~100 dirt
setblock ~144 ~118 ~98 dirt
setblock ~144 ~118 ~99 dirt
setblock ~144 ~118 ~100 dirt
setblock ~144 ~118 ~101 dirt
setblock ~144 ~119 ~98 dirt
setblock ~144 ~119 ~99 dirt
setblock ~144 ~119 ~100 dirt
setblock ~144 ~119 ~101 dirt
setblock ~144 ~119 ~103 dirt
setblock ~144 ~120 ~97 dirt
setblock ~144 ~120 ~98 dirt
setblock ~144 ~120 ~99 dirt
setblock ~144 ~120 ~100 dirt
setblock ~144 ~120 ~101 dirt
setblock ~144 ~120 ~102 dirt
setblock ~144 ~120 ~103 dirt
setblock ~144 ~120 ~104 dirt
setblock ~144 ~120 ~105 dirt
setblock ~144 ~121 ~96 dirt
setblock ~144 ~121 ~97 dirt
setblock ~144 ~121 ~98 dirt
setblock ~144 ~121 ~99 dirt
setblock ~144 ~121 ~100 dirt
setblock ~144 ~121 ~101 dirt
setblock ~144 ~121 ~102 dirt
setblock ~144 ~121 ~103 dirt
setblock ~144 ~121 ~104 dirt
setblock ~144 ~121 ~105 dirt
setblock ~144 ~121 ~106 dirt
setblock ~144 ~121 ~107 dirt
setblock ~144 ~122 ~96 dirt
setblock ~144 ~122 ~97 dirt
setblock ~144 ~122 ~98 dirt
setblock ~144 ~122 ~99 dirt
setblock ~144 ~122 ~100 dirt
setblock ~144 ~122 ~101 dirt
setblock ~144 ~122 ~102 dirt
setblock ~144 ~122 ~103 dirt
setblock ~144 ~122 ~104 dirt
setblock ~144 ~122 ~105 dirt
setblock ~144 ~122 ~106 dirt
setblock ~144 ~122 ~107 dirt
setblock ~144 ~123 ~96 dirt
setblock ~144 ~123 ~97 dirt
setblock ~144 ~123 ~98 dirt
setblock ~144 ~123 ~99 dirt
setblock ~144 ~123 ~100 dirt
setblock ~144 ~123 ~101 dirt
setblock ~144 ~123 ~102 dirt
setblock ~144 ~123 ~103 dirt
setblock ~144 ~123 ~104 dirt
setblock ~144 ~123 ~105 dirt
setblock ~144 ~123 ~106 dirt
setblock ~144 ~123 ~107 dirt
setblock ~144 ~124 ~96 dirt
setblock ~144 ~124 ~97 dirt
setblock ~144 ~124 ~98 dirt
setblock ~144 ~124 ~99 dirt
setblock ~144 ~124 ~100 dirt
setblock ~144 ~124 ~101 dirt
setblock ~144 ~124 ~102 dirt
setblock ~144 ~124 ~103 dirt
setblock ~144 ~124 ~104 dirt
setblock ~144 ~124 ~105 dirt
setblock ~144 ~124 ~106 dirt
setblock ~144 ~124 ~107 dirt
setblock ~144 ~125 ~96 dirt
setblock ~144 ~125 ~97 dirt
setblock ~144 ~125 ~98 dirt
setblock ~144 ~125 ~99 dirt
setblock ~144 ~125 ~100 dirt
setblock ~144 ~125 ~101 dirt
setblock ~144 ~125 ~102 dirt
setblock ~144 ~125 ~103 dirt
setblock ~144 ~125 ~104 dirt
setblock ~144 ~125 ~105 dirt
setblock ~144 ~125 ~106 dirt
setblock ~144 ~125 ~107 dirt
setblock ~144 ~126 ~96 grass_block
setblock ~144 ~126 ~97 grass_block
setblock ~144 ~126 ~98 grass_block
setblock ~144 ~126 ~99 grass_block
setblock ~144 ~126 ~100 grass_block
setblock ~144 ~126 ~101 grass_block
setblock ~144 ~126 ~102 dirt
setblock ~144 ~126 ~103 dirt
setblock ~144 ~126 ~104 dirt
setblock ~144 ~126 ~105 dirt
setblock ~144 ~126 ~106 dirt
setblock ~144 ~126 ~107 dirt
setblock ~144 ~127 ~96 short_grass
setblock ~144 ~127 ~100 short_grass
setblock ~144 ~127 ~102 grass_block
setblock ~144 ~127 ~103 grass_block
setblock ~144 ~127 ~104 grass_block
setblock ~144 ~127 ~105 grass_block
setblock ~144 ~127 ~106 grass_block
setblock ~144 ~127 ~107 dirt
setblock ~144 ~128 ~102 short_grass
setblock ~144 ~128 ~107 grass_block
setblock ~145 ~119 ~99 dirt
setblock ~145 ~119 ~100 dirt
setblock ~145 ~120 ~98 dirt
setblock ~145 ~120 ~99 dirt
setblock ~145 ~120 ~100 dirt
setblock ~145 ~121 ~97 dirt
setblock ~145 ~121 ~98 dirt
setblock ~145 ~121 ~99 dirt
setblock ~145 ~121 ~100 dirt
setblock ~145 ~121 ~102 dirt
setblock ~145 ~121 ~103 dirt
setblock ~145 ~121 ~105 dirt
setblock ~145 ~122 ~97 dirt
setblock ~145 ~122 ~98 dirt
setblock ~145 ~122 ~99 dirt
setblock ~145 ~122 ~100 dirt
setblock ~145 ~122 ~102 dirt
setblock ~145 ~122 ~103 dirt
setblock ~145 ~122 ~105 dirt
setblock ~145 ~123 ~97 dirt
setblock ~145 ~123 ~98 dirt
setblock ~145 ~123 ~99 dirt
setblock ~145 ~123 ~100 dirt
setblock ~145 ~123 ~102 dirt
setblock ~145 ~123 ~103 dirt
setblock ~145 ~123 ~105 dirt
setblock ~145 ~124 ~97 dirt
setblock ~145 ~124 ~98 dirt
setblock ~145 ~124 ~99 dirt
setblock ~145 ~124 ~100 dirt
setblock ~145 ~124 ~102 dirt
setblock ~145 ~124 ~103 dirt
setblock ~145 ~124 ~105 dirt
setblock ~145 ~125 ~97 dirt
setblock ~145 ~125 ~98 dirt
setblock ~145 ~125 ~99 dirt
setblock ~145 ~125 ~100 dirt
setblock ~145 ~125 ~102 dirt
setblock ~145 ~125 ~103 dirt
setblock ~145 ~125 ~105 dirt
setblock ~145 ~126 ~97 grass_block
setblock ~145 ~126 ~98 grass_block
setblock ~145 ~126 ~99 grass_block
setblock ~145 ~126 ~100 grass_block
setblock ~145 ~126 ~102 dirt
setblock ~145 ~126 ~103 dirt
setblock ~145 ~126 ~105 dirt
setblock ~145 ~127 ~98 short_grass
setblock ~145 ~127 ~102 grass_block
setblock ~145 ~127 ~103 grass_block
setblock ~145 ~127 ~105 grass_block
setblock ~145 ~128 ~105 short_grass
setblock ~199 ~200 ~199 gold_block
