setblock ~168 ~139 ~105 oak_log
setblock ~168 ~139 ~106 oak_log
setblock ~168 ~139 ~107 oak_leaves[persistent=true]
setblock ~168 ~139 ~108 oak_leaves[persistent=true]
setblock ~168 ~139 ~109 oak_leaves[persistent=true]
setblock ~168 ~139 ~110 oak_leaves[persistent=true]
setblock ~168 ~139 ~111 jungle_leaves[persistent=true]
setblock ~168 ~139 ~112 oak_leaves[persistent=true]
setblock ~168 ~140 ~100 jungle_leaves[persistent=true]
setblock ~168 ~140 ~101 oak_leaves[persistent=true]
setblock ~168 ~140 ~102 oak_leaves[persistent=true]
setblock ~168 ~140 ~103 oak_leaves[persistent=true]
setblock ~168 ~140 ~104 oak_leaves[persistent=true]
setblock ~168 ~140 ~105 oak_leaves[persistent=true]
setblock ~168 ~140 ~106 oak_leaves[persistent=true]
setblock ~168 ~140 ~107 oak_leaves[persistent=true]
setblock ~168 ~140 ~108 oak_leaves[persistent=true]
setblock ~168 ~140 ~109 oak_leaves[persistent=true]
setblock ~168 ~140 ~110 oak_leaves[persistent=true]
setblock ~168 ~140 ~112 oak_leaves[persistent=true]
setblock ~168 ~141 ~103 oak_leaves[persistent=true]
setblock ~168 ~141 ~104 oak_leaves[persistent=true]
setblock ~168 ~141 ~105 oak_leaves[persistent=true]
setblock ~168 ~141 ~106 oak_leaves[persistent=true]
setblock ~168 ~141 ~108 jungle_leaves[persistent=true]
setblock ~168 ~141 ~109 jungle_leaves[persistent=true]
setblock ~168 ~141 ~110 jungle_leaves[persistent=true]
setblock ~168 ~141 ~111 oak_leaves[persistent=true]
setblock ~168 ~141 ~112 oak_leaves[persistent=true]
setblock ~169 ~111 ~98 dirt
setblock ~169 ~112 ~95 dirt
setblock ~169 ~112 ~97 dirt
setblock ~169 ~112 ~98 dirt
setblock ~169 ~112 ~99 dirt
setblock ~169 ~113 ~93 dirt
setblock ~169 ~113 ~94 dirt
setblock ~169 ~113 ~95 dirt
setblock ~169 ~113 ~96 dirt
setblock ~169 ~113 ~97 dirt
setblock ~169 ~113 ~98 dirt
setblock ~169 ~113 ~99 dirt
setblock ~169 ~114 ~92 dirt
setblock ~169 ~114 ~93 dirt
setblock ~169 ~114 ~94 dirt
setblock ~169 ~114 ~95 dirt
setblock ~169 ~114 ~96 dirt
setblock ~169 ~114 ~97 dirt
setblock ~169 ~114 ~98 dirt
setblock ~169 ~114 ~99 dirt
setblock ~169 ~115 ~92 dirt
setblock ~169 ~115 ~93 dirt
setblock ~169 ~115 ~94 dirt
setblock ~169 ~115 ~95 dirt
setblock ~169 ~115 ~96 dirt
setblock ~169 ~115 ~97 dirt
setblock ~169 ~115 ~98 dirt
setblock ~169 ~115 ~99 dirt
setblock ~169 ~115 ~102 dirt
setblock ~169 ~116 ~76 dirt
setblock ~169 ~116 ~91 dirt
setblock ~169 ~116 ~92 dirt
setblock ~169 ~116 ~93 dirt
setblock ~169 ~116 ~94 dirt
setblock ~169 ~116 ~95 dirt
setblock ~169 ~116 ~96 dirt
setblock ~169 ~116 ~97 dirt
setblock ~169 ~116 ~98 dirt
setblock ~169 ~116 ~99 dirt
setblock ~169 ~116 ~100 dirt
setblock ~169 ~116 ~102 dirt
setblock ~169 ~116 ~103 dirt
setblock ~169 ~117 ~75 dirt
setblock ~169 ~117 ~76 dirt
setblock ~169 ~117 ~77 dirt
setblock ~169 ~117 ~78 dirt
setblock ~169 ~117 ~91 dirt
setblock ~169 ~117 ~92 dirt
setblock ~169 ~117 ~93 dirt
setblock ~169 ~117 ~94 dirt
setblock ~169 ~117 ~95 dirt
setblock ~169 ~117 ~96 dirt
setblock ~169 ~117 ~97 dirt
setblock ~169 ~117 ~98 dirt
setblock ~169 ~117 ~99 dirt
setblock ~169 ~117 ~100 dirt
setblock ~169 ~117 ~101 dirt
setblock ~169 ~117 ~102 dirt
setblock ~169 ~117 ~103 dirt
setblock ~169 ~117 ~104 dirt
setblock ~169 ~118 ~74 dirt
setblock ~169 ~118 ~75 dirt
setblock ~169 ~118 ~76 dirt
setblock ~169 ~118 ~77 dirt
setblock ~169 ~118 ~78 dirt
setblock ~169 ~118 ~90 dirt
setblock ~169 ~118 ~91 dirt
setblock ~169 ~118 ~92 dirt
setblock ~169 ~118 ~93 dirt
setblock ~169 ~118 ~94 dirt
setblock ~169 ~118 ~95 dirt
setblock ~169 ~118 ~96 dirt
setblock ~169 ~118 ~97 dirt
setblock ~169 ~118 ~98 dirt
setblock ~169 ~118 ~99 dirt
setblock ~169 ~118 ~100 dirt
setblock ~169 ~118 ~101 dirt
setblock ~169 ~118 ~102 dirt
setblock ~169 ~118 ~103 dirt
setblock ~169 ~118 ~104 dirt
setblock ~169 ~118 ~105 dirt
setblock ~169 ~119 ~70 dirt
setblock ~169 ~119 ~73 dirt
setblock ~169 ~119 ~74 dirt
setblock ~169 ~119 ~75 dirt
setblock ~169 ~119 ~76 dirt
setblock ~169 ~119 ~77 dirt
setblock ~169 ~119 ~78 dirt
setblock ~169 ~119 ~79 dirt
setblock ~169 ~119 ~80 dirt
setblock ~169 ~119 ~89 dirt
setblock ~169 ~119 ~90 dirt
setblock ~169 ~119 ~91 dirt
setblock ~169 ~119 ~92 dirt
setblock ~169 ~119 ~93 dirt
setblock ~169 ~119 ~94 dirt
setblock ~169 ~119 ~95 dirt
setblock ~169 ~119 ~96 dirt
setblock ~169 ~119 ~97 dirt
setblock ~169 ~119 ~98 dirt
setblock ~169 ~119 ~99 dirt
setblock ~169 ~119 ~100 dirt
setblock ~169 ~119 ~101 dirt
setblock ~169 ~119 ~102 dirt
setblock ~169 ~119 ~103 dirt
setblock ~169 ~119 ~104 dirt
setblock ~169 ~119 ~105 dirt
setblock ~169 ~119 ~106 dirt
setblock ~169 ~120 ~70 dirt
setblock ~169 ~120 ~71 dirt
setblock ~169 ~120 ~72 dirt
setblock ~169 ~120 ~73 dirt
setblock ~169 ~120 ~74 dirt
setblock ~169 ~120 ~75 dirt
setblock ~169 ~120 ~76 dirt
setblock ~169 ~120 ~77 dirt
setblock ~169 ~120 ~78 dirt
setblock ~169 ~120 ~79 dirt
setblock ~169 ~120 ~80 dirt
setblock ~169 ~120 ~81 dirt
setblock ~169 ~120 ~88 dirt
setblock ~169 ~120 ~89 dirt
setblock ~169 ~120 ~90 dirt
setblock ~169 ~120 ~91 dirt
setblock ~169 ~120 ~92 dirt
setblock ~169 ~120 ~93 dirt
setblock ~169 ~120 ~94 dirt
setblock ~169 ~120 ~95 dirt
setblock ~169 ~120 ~96 dirt
setblock ~169 ~120 ~97 dirt
setblock ~169 ~120 ~98 dirt
setblock ~169 ~120 ~99 dirt
setblock ~169 ~120 ~100 dirt
setblock ~169 ~120 ~101 dirt
setblock ~169 ~120 ~102 dirt
setblock ~169 ~120 ~103 dirt
setblock ~169 ~120 ~104 dirt
setblock ~169 ~120 ~105 dirt
setblock ~169 ~120 ~106 dirt
setblock ~169 ~121 ~69 dirt
setblock ~169 ~121 ~70 dirt
setblock ~169 ~121 ~71 dirt
setblock ~169 ~121 ~72 dirt
setblock ~169 ~121 ~73 dirt
setblock ~169 ~121 ~74 dirt
setblock ~169 ~121 ~75 dirt
setblock ~169 ~121 ~76 dirt
setblock ~169 ~121 ~77 dirt
setblock ~169 ~121 ~78 dirt
setblock ~169 ~121 ~79 dirt
setblock ~169 ~121 ~80 dirt
setblock ~169 ~121 ~81 dirt
setblock ~169 ~121 ~87 dirt
setblock ~169 ~121 ~88 dirt
setblock ~169 ~121 ~89 dirt
setblock ~169 ~121 ~90 dirt
setblock ~169 ~121 ~91 dirt
setblock ~169 ~121 ~92 dirt
setblock ~169 ~121 ~93 dirt
setblock ~169 ~121 ~94 dirt
setblock ~169 ~121 ~95 dirt
setblock ~169 ~121 ~96 dirt
setblock ~169 ~121 ~97 dirt
setblock ~169 ~121 ~98 dirt
setblock ~169 ~121 ~99 dirt
setblock ~169 ~121 ~100 dirt
setblock ~169 ~121 ~101 dirt
setblock ~169 ~121 ~102 dirt
setblock ~169 ~121 ~103 dirt
setblock ~169 ~121 ~104 dirt
setblock ~169 ~121 ~105 dirt
setblock ~169 ~121 ~106 dirt
setblock ~169 ~121 ~107 dirt
setblock ~169 ~121 ~123 dirt
setblock ~169 ~121 ~124 dirt
setblock ~169 ~122 ~69 dirt
setblock ~169 ~122 ~70 dirt
setblock ~169 ~122 ~71 dirt
setblock ~169 ~122 ~72 dirt
setblock ~169 ~122 ~73 dirt
setblock ~169 ~122 ~74 dirt
setblock ~169 ~122 ~75 dirt
setblock ~169 ~122 ~76 dirt
setblock ~169 ~122 ~77 dirt
setblock ~169 ~122 ~78 dirt
setblock ~169 ~122 ~79 dirt
setblock ~169 ~122 ~80 dirt
setblock ~169 ~122 ~81 dirt
setblock ~169 ~122 ~87 dirt
setblock ~169 ~122 ~88 dirt
setblock ~169 ~122 ~89 dirt
setblock ~169 ~122 ~90 dirt
setblock ~169 ~122 ~91 dirt
setblock ~169 ~122 ~92 dirt
setblock ~169 ~122 ~93 dirt
setblock ~169 ~122 ~94 dirt
setblock ~169 ~122 ~95 dirt
setblock ~169 ~122 ~96 dirt
setblock ~169 ~122 ~97 dirt
setblock ~169 ~122 ~98 dirt
setblock ~169 ~122 ~99 dirt
setblock ~169 ~122 ~100 dirt
setblock ~169 ~122 ~101 dirt
setblock ~169 ~122 ~102 dirt
setblock ~169 ~122 ~103 dirt
setblock ~169 ~122 ~104 dirt
setblock ~169 ~122 ~105 dirt
setblock ~169 ~122 ~106 dirt
setblock ~169 ~122 ~107 dirt
setblock ~169 ~122 ~123 dirt
setblock ~169 ~122 ~124 dirt
setblock ~169 ~123 ~69 dirt
setblock ~169 ~123 ~70 dirt
setblock ~169 ~123 ~71 dirt
setblock ~169 ~123 ~72 dirt
setblock ~169 ~123 ~73 dirt
setblock ~169 ~123 ~74 dirt
setblock ~169 ~123 ~75 dirt
setblock ~169 ~123 ~76 grass_block
setblock ~169 ~123 ~77 grass_block
setblock ~169 ~123 ~78 grass_block
setblock ~169 ~123 ~79 grass_block
setblock ~169 ~123 ~80 grass_block
setblock ~169 ~123 ~81 grass_block
setblock ~169 ~123 ~87 dirt
setblock ~169 ~123 ~88 dirt
setblock ~169 ~123 ~89 dirt
setblock ~169 ~123 ~90 dirt
setblock ~169 ~123 ~91 dirt
setblock ~169 ~123 ~92 dirt
setblock ~169 ~123 ~93 dirt
setblock ~169 ~123 ~94 dirt
setblock ~169 ~123 ~95 dirt
setblock ~169 ~123 ~96 dirt
setblock ~169 ~123 ~97 dirt
setblock ~169 ~123 ~98 dirt
setblock ~169 ~123 ~99 dirt
setblock ~169 ~123 ~100 dirt
setblock ~169 ~123 ~101 dirt
setblock ~169 ~123 ~102 dirt
setblock ~169 ~123 ~103 dirt
setblock ~169 ~123 ~104 dirt
setblock ~169 ~123 ~105 dirt
setblock ~169 ~123 ~106 dirt
setblock ~169 ~123 ~107 dirt
setblock ~169 ~123 ~123 grass_block
setblock ~169 ~123 ~124 grass_block
setblock ~169 ~124 ~69 dirt
setblock ~169 ~124 ~70 dirt
setblock ~169 ~124 ~71 dirt
setblock ~169 ~124 ~72 grass_block
setblock ~169 ~124 ~73 grass_block
setblock ~169 ~124 ~74 grass_block
setblock ~169 ~124 ~75 grass_block
setblock ~169 ~124 ~77 poppy
setblock ~169 ~124 ~79 short_grass
setblock ~169 ~124 ~80 fern
setblock ~169 ~124 ~81 short_grass
setblock ~169 ~124 ~87 grass_block
setblock ~169 ~124 ~88 grass_block
setblock ~169 ~124 ~89 grass_block
setblock ~169 ~124 ~90 grass_block
setblock ~169 ~124 ~91 grass_block
setblock ~169 ~124 ~92 grass_block
setblock ~169 ~124 ~93 dirt
setblock ~169 ~124 ~94 dirt
setblock ~169 ~124 ~95 dirt
setblock ~169 ~124 ~96 dirt
setblock ~169 ~124 ~97 dirt
setblock ~169 ~124 ~98 dirt
setblock ~169 ~124 ~99 dirt
setblock ~169 ~124 ~100 dirt
setblock ~169 ~124 ~101 dirt
setblock ~169 ~124 ~102 dirt
setblock ~169 ~124 ~103 dirt
setblock ~169 ~124 ~104 dirt
setblock ~169 ~124 ~105 dirt
setblock ~169 ~124 ~106 dirt
setblock ~169 ~124 ~107 dirt
setblock ~169 ~124 ~123 poppy
setblock ~169 ~125 ~69 grass_block
setblock ~169 ~125 ~70 grass_block
setblock ~169 ~125 ~71 grass_block
setblock ~169 ~125 ~73 poppy
setblock ~169 ~125 ~74 short_grass
setblock ~169 ~125 ~88 poppy
setblock ~169 ~125 ~89 fern
setblock ~169 ~125 ~93 grass_block
setblock ~169 ~125 ~94 grass_block
setblock ~169 ~125 ~95 grass_block
setblock ~169 ~125 ~96 dirt
setblock ~169 ~125 ~97 dirt
setblock ~169 ~125 ~98 dirt
setblock ~169 ~125 ~99 dirt
setblock ~169 ~125 ~100 dirt
setblock ~169 ~125 ~101 dirt
setblock ~169 ~125 ~102 dirt
setblock ~169 ~125 ~103 dirt
setblock ~169 ~125 ~104 dirt
setblock ~169 ~125 ~105 dirt
setblock ~169 ~125 ~106 dirt
setblock ~169 ~125 ~107 grass_block
setblock ~169 ~126 ~93 short_grass
setblock ~169 ~126 ~96 grass_block
setblock ~169 ~126 ~97 grass_block
setblock ~169 ~126 ~98 dirt
setblock ~169 ~126 ~99 dirt
setblock ~169 ~126 ~100 dirt
setblock ~169 ~126 ~101 dirt
setblock ~169 ~126 ~102 dirt
setblock ~169 ~126 ~103 grass_block
setblock ~169 ~126 ~104 grass_block
setblock ~169 ~126 ~105 grass_block
setblock ~169 ~126 ~106 grass_block
setblock ~169 ~127 ~98 grass_block
setblock ~169 ~127 ~99 grass_block
setblock ~169 ~127 ~100 dirt
setblock ~169 ~127 ~101 grass_block
setblock ~169 ~127 ~102 grass_block
setblock ~169 ~128 ~98 short_grass
setblock ~169 ~128 ~100 grass_block
setblock ~169 ~128 ~102 short_grass
setblock ~169 ~130 ~103 oak_leaves[persistent=true]
setblock ~169 ~130 ~104 oak_leaves[persistent=true]
setblock ~169 ~130 ~105 oak_leaves[persistent=true]
setblock ~169 ~130 ~106 oak_leaves[persistent=true]
setblock ~169 ~131 ~103 oak_leaves[persistent=true]
setblock ~169 ~131 ~104 jungle_leaves[persistent=true]
setblock ~169 ~131 ~105 jungle_leaves[persistent=true]
setblock ~169 ~131 ~106 jungle_leaves[persistent=true]
setblock ~169 ~132 ~103 oak_leaves[persistent=true]
setblock ~169 ~132 ~104 oak_leaves[persistent=true]
setblock ~169 ~132 ~105 oak_leaves[persistent=true]
setblock ~169 ~132 ~106 jungle_leaves[persistent=true]
setblock ~169 ~132 ~107 oak_leaves[persistent=true]
setblock ~169 ~132 ~108 jungle_leaves[persistent=true]
setblock ~169 ~133 ~102 oak_leaves[persistent=true]
setblock ~169 ~133 ~103 jungle_leaves[persistent=true]
setblock ~169 ~133 ~104 oak_leaves[persistent=true]
setblock ~169 ~133 ~105 oak_leaves[persistent=true]
setblock ~169 ~133 ~106 oak_leaves[persistent=true]
setblock ~169 ~133 ~107 oak_leaves[persistent=true]
setblock ~169 ~133 ~108 oak_leaves[persistent=true]
setblock ~169 ~134 ~102 oak_leaves[persistent=true]
setblock ~169 ~134 ~103 oak_leaves[persistent=true]
setblock ~169 ~134 ~104 oak_leaves[persistent=true]
setblock ~169 ~134 ~105 oak_wood
setblock ~169 ~134 ~106 oak_leaves[persistent=true]
setblock ~169 ~134 ~107 oak_wood
setblock ~169 ~134 ~108 oak_leaves[persistent=true]
setblock ~169 ~134 ~109 oak_leaves[persistent=true]
setblock ~169 ~134 ~110 oak_leaves[persistent=true]
setblock ~169 ~134 ~111 oak_leaves[persistent=true]
setblock ~169 ~135 ~100 oak_leaves[persistent=true]
setblock ~169 ~135 ~101 oak_leaves[persistent=true]
setblock ~169 ~135 ~103 oak_leaves[persistent=true]
setblock ~169 ~135 ~105 oak_wood
setblock ~169 ~135 ~106 oak_leaves[persistent=true]
setblock ~169 ~135 ~107 oak_wood
setblock ~169 ~135 ~108 oak_leaves[persistent=true]
setblock ~169 ~135 ~109 oak_leaves[persistent=true]
setblock ~169 ~135 ~110 oak_leaves[persistent=true]
setblock ~169 ~135 ~111 jungle_leaves[persistent=true]
setblock ~169 ~135 ~113 oak_leaves[persistent=true]
setblock ~169 ~135 ~114 oak_leaves[persistent=true]
setblock ~169 ~136 ~100 jungle_leaves[persistent=true]
setblock ~169 ~136 ~101 oak_leaves[persistent=true]
setblock ~169 ~136 ~102 jungle_leaves[persistent=true]
setblock ~169 ~136 ~103 oak_leaves[persistent=true]
setblock ~169 ~136 ~104 oak_leaves[persistent=true]
setblock ~169 ~136 ~105 oak_wood
setblock ~169 ~136 ~106 oak_leaves[persistent=true]
setblock ~169 ~136 ~107 oak_wood
setblock ~169 ~136 ~108 oak_leaves[persistent=true]
setblock ~169 ~136 ~109 oak_leaves[persistent=true]
setblock ~169 ~136 ~110 oak_leaves[persistent=true]
setblock ~169 ~136 ~112 oak_leaves[persistent=true]
setblock ~169 ~136 ~113 jungle_leaves[persistent=true]
setblock ~169 ~136 ~114 oak_leaves[persistent=true]
setblock ~169 ~137 ~100 oak_leaves[persistent=true]
setblock ~169 ~137 ~101 oak_leaves[persistent=true]
setblock ~169 ~137 ~102 oak_leaves[persistent=true]
setblock ~169 ~137 ~103 oak_leaves[persistent=true]
setblock ~169 ~137 ~104 oak_wood
setblock ~169 ~137 ~105 oak_wood
setblock ~169 ~137 ~106 oak_wood
setblock ~169 ~137 ~107 oak_leaves[persistent=true]
setblock ~169 ~137 ~108 oak_leaves[persistent=true]
setblock ~169 ~137 ~109 oak_leaves[persistent=true]
setblock ~169 ~137 ~110 oak_leaves[persistent=true]
setblock ~169 ~137 ~111 oak_leaves[persistent=true]
setblock ~169 ~137 ~112 jungle_leaves[persistent=true]
setblock ~169 ~137 ~113 jungle_leaves[persistent=true]
setblock ~169 ~137 ~114 jungle_leaves[persistent=true]
setblock ~169 ~138 ~100 oak_leaves[persistent=true]
setblock ~169 ~138 ~101 oak_leaves[persistent=true]
setblock ~169 ~138 ~102 oak_leaves[persistent=true]
setblock ~169 ~138 ~103 oak_wood
setblock ~169 ~138 ~104 oak_leaves[persistent=true]
setblock ~169 ~138 ~105 oak_leaves[persistent=true]
setblock ~169 ~138 ~106 oak_log
setblock ~169 ~138 ~107 oak_leaves[persistent=true]
setblock ~169 ~138 ~108 oak_leaves[persistent=true]
setblock ~169 ~138 ~109 jungle_leaves[persistent=true]
setblock ~169 ~138 ~110 oak_leaves[persistent=true]
setblock ~169 ~138 ~111 oak_leaves[persistent=true]
setblock ~169 ~138 ~112 jungle_leaves[persistent=true]
setblock ~169 ~138 ~113 oak_leaves[persistent=true]
setblock ~169 ~138 ~114 oak_leaves[persistent=true]
setblock ~169 ~139 ~101 oak_wood
setblock ~169 ~139 ~102 oak_wood
setblock ~169 ~139 ~103 oak_leaves[persistent=true]
setblock ~169 ~139 ~104 oak_leaves[persistent=true]
setblock ~169 ~139 ~105 oak_leaves[persistent=true]
setblock ~169 ~139 ~106 oak_leaves[persistent=true]
setblock ~169 ~139 ~107 oak_log
setblock ~169 ~139 ~108 jungle_leaves[persistent=true]
setblock ~169 ~139 ~109 jungle_leaves[persistent=true]
setblock ~169 ~139 ~110 oak_leaves[persistent=true]
setblock ~169 ~139 ~111 oak_leaves[persistent=true]
setblock ~169 ~139 ~112 oak_leaves[persistent=true]
setblock ~169 ~140 ~100 jungle_leaves[persistent=true]
setblock ~169 ~140 ~101 oak_leaves[persistent=true]
setblock ~169 ~140 ~102 oak_leaves[persistent=true]
setblock ~169 ~140 ~103 jungle_leaves[persistent=true]
setblock ~169 ~140 ~104 oak_leaves[persistent=true]
setblock ~169 ~140 ~105 oak_leaves[persistent=true]
setblock ~169 ~140 ~106 oak_leaves[persistent=true]
setblock ~169 ~140 ~107 oak_leaves[persistent=true]
setblock ~169 ~140 ~109 oak_leaves[persistent=true]
setblock ~169 ~140 ~110 jungle_leaves[persistent=true]
setblock ~169 ~140 ~111 oak_leaves[persistent=true]
setblock ~169 ~140 ~112 oak_leaves[persistent=true]
setblock ~169 ~141 ~103 oak_leaves[persistent=true]
setblock ~169 ~141 ~104 oak_leaves[persistent=true]
setblock ~169 ~141 ~105 oak_leaves[persistent=true]
setblock ~169 ~141 ~106 oak_leaves[persistent=true]
setblock ~169 ~141 ~107 oak_leaves[persistent=true]
setblock ~169 ~141 ~108 jungle_leaves[persistent=true]
setblock ~169 ~141 ~109 oak_leaves[persistent=true]
setblock ~169 ~141 ~110 oak_leaves[persistent=true]
setblock ~169 ~141 ~111 jungle_leaves[persistent=true]
setblock ~170 ~113 ~95 dirt
setblock ~170 ~113 ~97 dirt
setblock ~170 ~114 ~94 dirt
setblock ~170 ~114 ~95 dirt
setblock ~170 ~114 ~97 dirt
setblock ~170 ~114 ~98 dirt
setblock ~170 ~115 ~93 dirt
setblock ~170 ~115 ~94 dirt
setblock ~170 ~115 ~95 dirt
setblock ~170 ~115 ~96 dirt
setblock ~170 ~115 ~97 dirt
setblock ~170 ~115 ~98 dirt
setblock ~170 ~116 ~92 dirt
setblock ~170 ~116 ~93 dirt
setblock ~170 ~116 ~94 dirt
setblock ~170 ~116 ~95 dirt
setblock ~170 ~116 ~96 dirt
setblock ~170 ~116 ~97 dirt
setblock ~170 ~116 ~98 dirt
setblock ~170 ~116 ~99 dirt
setblock ~170 ~117 ~76 dirt
setblock ~170 ~117 ~91 dirt
setblock ~170 ~117 ~92 dirt
setblock ~170 ~117 ~93 dirt
setblock ~170 ~117 ~94 dirt
setblock ~170 ~117 ~95 dirt
setblock ~170 ~117 ~96 dirt
setblock ~170 ~117 ~97 dirt
setblock ~170 ~117 ~98 dirt
setblock ~170 ~117 ~99 dirt
setblock ~170 ~117 ~100 dirt
setblock ~170 ~117 ~102 dirt
setblock ~170 ~117 ~103 dirt
setblock ~170 ~118 ~76 dirt
setblock ~170 ~118 ~77 dirt
setblock ~170 ~118 ~90 dirt
setblock ~170 ~118 ~91 dirt
setblock ~170 ~118 ~92 dirt
setblock ~170 ~118 ~93 dirt
setblock ~170 ~118 ~94 dirt
setblock ~170 ~118 ~95 dirt
setblock ~170 ~118 ~96 dirt
setblock ~170 ~118 ~97 dirt
setblock ~170 ~118 ~98 dirt
setblock ~170 ~118 ~99 dirt
setblock ~170 ~118 ~100 dirt
setblock ~170 ~118 ~102 dirt
setblock ~170 ~118 ~103 dirt
setblock ~170 ~118 ~104 dirt
setblock ~170 ~119 ~74 dirt
setblock ~170 ~119 ~75 dirt
setblock ~170 ~119 ~76 dirt
setblock ~170 ~119 ~77 dirt
setblock ~170 ~119 ~78 dirt
setblock ~170 ~119 ~90 dirt
setblock ~170 ~119 ~91 dirt
setblock ~170 ~119 ~92 dirt
setblock ~170 ~119 ~93 dirt
setblock ~170 ~119 ~94 dirt
setblock ~170 ~119 ~95 dirt
setblock ~170 ~119 ~96 dirt
setblock ~170 ~119 ~97 dirt
setblock ~170 ~119 ~98 dirt
setblock ~170 ~119 ~99 dirt
setblock ~170 ~119 ~100 dirt
setblock ~170 ~119 ~101 dirt
setblock ~170 ~119 ~102 dirt
setblock ~170 ~119 ~103 dirt
setblock ~170 ~119 ~104 dirt
setblock ~170 ~119 ~105 dirt
setblock ~170 ~120 ~74 dirt
setblock ~170 ~120 ~75 dirt
setblock ~170 ~120 ~76 dirt
setblock ~170 ~120 ~77 dirt
setblock ~170 ~120 ~78 dirt
setblock ~170 ~120 ~79 dirt
setblock ~170 ~120 ~80 dirt
setblock ~170 ~120 ~90 dirt
setblock ~170 ~120 ~91 dirt
setblock ~170 ~120 ~92 dirt
setblock ~170 ~120 ~93 dirt
setblock ~170 ~120 ~94 dirt
setblock ~170 ~120 ~95 dirt
setblock ~170 ~120 ~96 dirt
setblock ~170 ~120 ~97 dirt
setblock ~170 ~120 ~98 dirt
setblock ~170 ~120 ~99 dirt
setblock ~170 ~120 ~100 dirt
setblock ~170 ~120 ~101 dirt
setblock ~170 ~120 ~102 dirt
setblock ~170 ~120 ~103 dirt
setblock ~170 ~120 ~104 dirt
setblock ~170 ~120 ~105 dirt
setblock ~170 ~120 ~106 dirt
setblock ~170 ~121 ~70 dirt
setblock ~170 ~121 ~72 dirt
setblock ~170 ~121 ~73 dirt
setblock ~170 ~121 ~74 dirt
setblock ~170 ~121 ~75 dirt
setblock ~170 ~121 ~76 dirt
setblock ~170 ~121 ~77 dirt
setblock ~170 ~121 ~78 dirt
setblock ~170 ~121 ~79 dirt
setblock ~170 ~121 ~80 dirt
setblock ~170 ~121 ~88 dirt
setblock ~170 ~121 ~90 dirt
setblock ~170 ~121 ~91 dirt
setblock ~170 ~121 ~92 dirt
setblock ~170 ~121 ~93 dirt
setblock ~170 ~121 ~94 dirt
setblock ~170 ~121 ~95 dirt
setblock ~170 ~121 ~96 dirt
setblock ~170 ~121 ~97 dirt
setblock ~170 ~121 ~98 dirt
setblock ~170 ~121 ~99 dirt
setblock ~170 ~121 ~100 dirt
setblock ~170 ~121 ~101 dirt
setblock ~170 ~121 ~102 dirt
setblock ~170 ~121 ~103 dirt
setblock ~170 ~121 ~104 dirt
setblock ~170 ~121 ~105 dirt
setblock ~170 ~121 ~106 dirt
setblock ~170 ~122 ~70 dirt
setblock ~170 ~122 ~72 dirt
setblock ~170 ~122 ~73 dirt
setblock ~170 ~122 ~74 dirt
setblock ~170 ~122 ~75 dirt
setblock ~170 ~122 ~76 dirt
setblock ~170 ~122 ~77 dirt
setblock ~170 ~122 ~78 dirt
setblock ~170 ~122 ~79 dirt
setblock ~170 ~122 ~80 grass_block
setblock ~170 ~122 ~88 dirt
setblock ~170 ~122 ~90 dirt
setblock ~170 ~122 ~91 dirt
setblock ~170 ~122 ~92 dirt
setblock ~170 ~122 ~93 dirt
setblock ~170 ~122 ~94 dirt
setblock ~170 ~122 ~95 dirt
setblock ~170 ~122 ~96 dirt
setblock ~170 ~122 ~97 dirt
setblock ~170 ~122 ~98 dirt
setblock ~170 ~122 ~99 dirt
setblock ~170 ~122 ~100 dirt
setblock ~170 ~122 ~101 dirt
setblock ~170 ~122 ~102 dirt
setblock ~170 ~122 ~103 dirt
setblock ~170 ~122 ~104 dirt
setblock ~170 ~122 ~105 dirt
setblock ~170 ~122 ~106 dirt
setblock ~170 ~123 ~70 dirt
setblock ~170 ~123 ~72 dirt
setblock ~170 ~123 ~73 dirt
setblock ~170 ~123 ~74 dirt
setblock ~170 ~123 ~75 dirt
setblock ~170 ~123 ~76 grass_block
setblock ~170 ~123 ~77 grass_block
setblock ~170 ~123 ~78 grass_block
setblock ~170 ~123 ~79 grass_block
setblock ~170 ~123 ~88 grass_block
setblock ~170 ~123 ~90 dirt
setblock ~170 ~123 ~91 dirt
setblock ~170 ~123 ~92 dirt
setblock ~170 ~123 ~93 dirt
setblock ~170 ~123 ~94 dirt
setblock ~170 ~123 ~95 dirt
setblock ~170 ~123 ~96 dirt
setblock ~170 ~123 ~97 dirt
setblock ~170 ~123 ~98 dirt
setblock ~170 ~123 ~99 dirt
setblock ~170 ~123 ~100 dirt
setblock ~170 ~123 ~101 dirt
setblock ~170 ~123 ~102 dirt
setblock ~170 ~123 ~103 dirt
setblock ~170 ~123 ~104 dirt
setblock ~170 ~123 ~105 dirt
setblock ~170 ~123 ~106 dirt
setblock ~170 ~124 ~70 dirt
setblock ~170 ~124 ~72 dirt
setblock ~170 ~124 ~73 grass_block
setblock ~170 ~124 ~74 grass_block
setblock ~170 ~124 ~75 grass_block
setblock ~170 ~124 ~88 short_grass
setblock ~170 ~124 ~90 grass_block
setblock ~170 ~124 ~91 grass_block
setblock ~170 ~124 ~92 grass_block
setblock ~170 ~124 ~93 grass_block
setblock ~170 ~124 ~94 dirt
setblock ~170 ~124 ~95 dirt
setblock ~170 ~124 ~96 dirt
setblock ~170 ~124 ~97 dirt
setblock ~170 ~124 ~98 dirt
setblock ~170 ~124 ~99 dirt
setblock ~170 ~124 ~100 dirt
setblock ~170 ~124 ~101 dirt
setblock ~170 ~124 ~102 dirt
setblock ~170 ~124 ~103 dirt
setblock ~170 ~124 ~104 dirt
setblock ~170 ~124 ~105 dirt
setblock ~170 ~124 ~106 dirt
setblock ~170 ~125 ~70 grass_block
setblock ~170 ~125 ~72 grass_block
setblock ~170 ~125 ~74 short_grass
setblock ~170 ~125 ~92 short_grass
setblock ~170 ~125 ~94 grass_block
setblock ~170 ~125 ~95 grass_block
setblock ~170 ~125 ~96 grass_block
setblock ~170 ~125 ~97 dirt
setblock ~170 ~125 ~98 dirt
setblock ~170 ~125 ~99 dirt
setblock ~170 ~125 ~100 dirt
setblock ~170 ~125 ~101 dirt
setblock ~170 ~125 ~102 dirt
setblock ~170 ~125 ~103 dirt
setblock ~170 ~125 ~104 dirt
setblock ~170 ~125 ~105 dirt
setblock ~170 ~125 ~106 grass_block
setblock ~170 ~126 ~97 grass_block
setblock ~170 ~126 ~98 grass_block
setblock ~170 ~126 ~99 dirt
setblock ~170 ~126 ~100 dirt
setblock ~170 ~126 ~101 dirt
setblock ~170 ~126 ~102 grass_block
setblock ~170 ~126 ~103 grass_block
setblock ~170 ~126 ~104 grass_block
setblock ~170 ~126 ~105 grass_block
setblock ~170 ~126 ~106 short_grass
setblock ~170 ~127 ~97 poppy
setblock ~170 ~127 ~98 short_grass
setblock ~170 ~127 ~99 grass_block
setblock ~170 ~127 ~100 grass_block
setblock ~170 ~127 ~101 grass_block
setblock ~170 ~127 ~102 short_grass
setblock ~170 ~131 ~102 oak_leaves[persistent=true]
setblock ~170 ~131 ~103 oak_leaves[persistent=true]
setblock ~170 ~131 ~104 jungle_leaves[persistent=true]
setblock ~170 ~131 ~105 oak_leaves[persistent=true]
setblock ~170 ~131 ~106 jungle_leaves[persistent=true]
setblock ~170 ~131 ~107 oak_leaves[persistent=true]
setblock ~170 ~131 ~108 oak_leaves[persistent=true]
setblock ~170 ~131 ~109 oak_leaves[persistent=true]
setblock ~170 ~131 ~110 oak_leaves[persistent=true]
setblock ~170 ~132 ~104 oak_leaves[persistent=true]
setblock ~170 ~132 ~105 oak_leaves[persistent=true]
setblock ~170 ~132 ~107 jungle_leaves[persistent=true]
setblock ~170 ~132 ~108 jungle_leaves[persistent=true]
setblock ~170 ~132 ~109 oak_leaves[persistent=true]
setblock ~170 ~132 ~110 oak_leaves[persistent=true]
setblock ~170 ~133 ~102 jungle_leaves[persistent=true]
setblock ~170 ~133 ~103 oak_leaves[persistent=true]
setblock ~170 ~133 ~104 jungle_leaves[persistent=true]
setblock ~170 ~133 ~105 oak_leaves[persistent=true]
setblock ~170 ~133 ~106 oak_leaves[persistent=true]
setblock ~170 ~133 ~107 oak_leaves[persistent=true]
setblock ~170 ~133 ~108 oak_leaves[persistent=true]
setblock ~170 ~133 ~109 oak_leaves[persistent=true]
setblock ~170 ~133 ~110 oak_leaves[persistent=true]
setblock ~170 ~134 ~101 oak_leaves[persistent=true]
setblock ~170 ~134 ~102 oak_leaves[persistent=true]
setblock ~170 ~134 ~103 oak_leaves[persistent=true]
setblock ~170 ~134 ~104 oak_leaves[persistent=true]
setblock ~170 ~134 ~105 oak_wood
setblock ~170 ~134 ~106 oak_leaves[persistent=true]
setblock ~170 ~134 ~107 oak_leaves[persistent=true]
setblock ~170 ~134 ~108 oak_wood
setblock ~170 ~134 ~110 oak_leaves[persistent=true]
setblock ~170 ~134 ~111 jungle_leaves[persistent=true]
setblock ~170 ~135 ~102 oak_leaves[persistent=true]
setblock ~170 ~135 ~103 jungle_leaves[persistent=true]
setblock ~170 ~135 ~104 oak_leaves[persistent=true]
setblock ~170 ~135 ~105 oak_leaves[persistent=true]
setblock ~170 ~135 ~106 jungle_leaves[persistent=true]
setblock ~170 ~135 ~107 oak_leaves[persistent=true]
setblock ~170 ~135 ~108 oak_wood
setblock ~170 ~135 ~109 jungle_leaves[persistent=true]
setblock ~170 ~135 ~110 jungle_leaves[persistent=true]
setblock ~170 ~135 ~111 oak_leaves[persistent=true]
setblock ~170 ~136 ~101 jungle_leaves[persistent=true]
setblock ~170 ~136 ~102 jungle_leaves[persistent=true]
setblock ~170 ~136 ~103 oak_leaves[persistent=true]
setblock ~170 ~136 ~104 oak_wood
setblock ~170 ~136 ~105 oak_leaves[persistent=true]
setblock ~170 ~136 ~106 oak_leaves[persistent=true]
setblock ~170 ~136 ~107 oak_leaves[persistent=true]
setblock ~170 ~136 ~108 oak_leaves[persistent=true]
setblock ~170 ~136 ~109 oak_leaves[persistent=true]
setblock ~170 ~136 ~110 oak_leaves[persistent=true]
setblock ~170 ~137 ~100 oak_leaves[persistent=true]
setblock ~170 ~137 ~101 oak_leaves[persistent=true]
setblock ~170 ~137 ~102 oak_leaves[persistent=true]
setblock ~170 ~137 ~103 jungle_leaves[persistent=true]
setblock ~170 ~137 ~104 oak_leaves[persistent=true]
setblock ~170 ~137 ~105 oak_wood
setblock ~170 ~137 ~106 oak_leaves[persistent=true]
setblock ~170 ~137 ~107 oak_leaves[persistent=true]
setblock ~170 ~137 ~108 oak_leaves[persistent=true]
setblock ~170 ~137 ~109 oak_leaves[persistent=true]
setblock ~170 ~137 ~110 jungle_leaves[persistent=true]
setblock ~170 ~137 ~111 jungle_leaves[persistent=true]
setblock ~170 ~138 ~100 oak_leaves[persistent=true]
setblock ~170 ~138 ~101 oak_leaves[persistent=true]
setblock ~170 ~138 ~102 oak_leaves[persistent=true]
setblock ~170 ~138 ~104 oak_leaves[persistent=true]
setblock ~170 ~138 ~105 oak_leaves[persistent=true]
setblock ~170 ~138 ~106 jungle_leaves[persistent=true]
setblock ~170 ~138 ~107 oak_leaves[persistent=true]
setblock ~170 ~138 ~108 oak_leaves[persistent=true]
setblock ~170 ~138 ~109 oak_leaves[persistent=true]
setblock ~170 ~138 ~110 oak_leaves[persistent=true]
setblock ~170 ~138 ~111 oak_leaves[persistent=true]
setblock ~170 ~139 ~100 oak_leaves[persistent=true]
setblock ~170 ~139 ~101 jungle_leaves[persistent=true]
setblock ~170 ~139 ~102 oak_leaves[persistent=true]
setblock ~170 ~139 ~104 oak_leaves[persistent=true]
setblock ~170 ~139 ~105 oak_leaves[persistent=true]
setblock ~170 ~139 ~106 oak_leaves[persistent=true]
setblock ~170 ~139 ~107 jungle_leaves[persistent=true]
setblock ~170 ~139 ~108 oak_log
setblock ~170 ~140 ~100 oak_leaves[persistent=true]
setblock ~170 ~140 ~101 oak_leaves[persistent=true]
setblock ~170 ~140 ~102 oak_leaves[persistent=true]
setblock ~170 ~140 ~103 jungle_leaves[persistent=true]
setblock ~170 ~140 ~104 oak_leaves[persistent=true]
setblock ~170 ~140 ~105 oak_leaves[persistent=true]
setblock ~170 ~140 ~106 oak_leaves[persistent=true]
setblock ~170 ~140 ~107 oak_leaves[persistent=true]
setblock ~170 ~140 ~108 oak_leaves[persistent=true]
setblock ~170 ~140 ~109 jungle_leaves[persistent=true]
setblock ~170 ~141 ~103 jungle_leaves[persistent=true]
setblock ~170 ~141 ~104 oak_leaves[persistent=true]
setblock ~170 ~141 ~105 oak_leaves[persistent=true]
setblock ~170 ~141 ~106 oak_leaves[persistent=true]
setblock ~170 ~141 ~107 oak_leaves[persistent=true]
setblock ~170 ~141 ~108 oak_leaves[persistent=true]
setblock ~171 ~115 ~97 dirt
setblock ~171 ~116 ~96 dirt
setblock ~171 ~116 ~97 dirt
setblock ~171 ~116 ~98 dirt
setblock ~171 ~117 ~92 dirt
setblock ~171 ~117 ~94 dirt
setblock ~171 ~117 ~95 dirt
setblock ~171 ~117 ~96 dirt
setblock ~171 ~117 ~97 dirt
setblock ~171 ~117 ~98 dirt
setblock ~171 ~118 ~91 dirt
setblock ~171 ~118 ~92 dirt
setblock ~171 ~118 ~93 dirt
setblock ~171 ~118 ~94 dirt
setblock ~171 ~118 ~95 dirt
setblock ~171 ~118 ~96 dirt
setblock ~171 ~118 ~97 dirt
setblock ~171 ~118 ~98 dirt
setblock ~171 ~118 ~99 dirt
setblock ~171 ~119 ~76 dirt
setblock ~171 ~119 ~90 dirt
setblock ~171 ~119 ~91 dirt
setblock ~171 ~119 ~92 dirt
setblock ~171 ~119 ~93 dirt
setblock ~171 ~119 ~94 dirt
setblock ~171 ~119 ~95 dirt
setblock ~171 ~119 ~96 dirt
setblock ~171 ~119 ~97 dirt
setblock ~171 ~119 ~98 dirt
setblock ~171 ~119 ~99 dirt
setblock ~171 ~119 ~100 dirt
setblock ~171 ~119 ~102 dirt
setblock ~171 ~119 ~103 dirt
setblock ~171 ~120 ~76 dirt
setblock ~171 ~120 ~77 dirt
setblock ~171 ~120 ~90 dirt
setblock ~171 ~120 ~91 dirt
setblock ~171 ~120 ~92 dirt
setblock ~171 ~120 ~93 dirt
setblock ~171 ~120 ~94 dirt
setblock ~171 ~120 ~95 dirt
setblock ~171 ~120 ~96 dirt
setblock ~171 ~120 ~97 dirt
setblock ~171 ~120 ~98 dirt
setblock ~171 ~120 ~99 dirt
setblock ~171 ~120 ~100 dirt
setblock ~171 ~120 ~101 dirt
setblock ~171 ~120 ~102 dirt
setblock ~171 ~120 ~103 dirt
setblock ~171 ~120 ~105 dirt
setblock ~171 ~121 ~76 dirt
setblock ~171 ~121 ~77 dirt
setblock ~171 ~121 ~78 dirt
setblock ~171 ~121 ~90 dirt
setblock ~171 ~121 ~91 dirt
setblock ~171 ~121 ~92 dirt
setblock ~171 ~121 ~93 dirt
setblock ~171 ~121 ~94 dirt
setblock ~171 ~121 ~95 dirt
setblock ~171 ~121 ~96 dirt
setblock ~171 ~121 ~97 dirt
setblock ~171 ~121 ~98 dirt
setblock ~171 ~121 ~99 dirt
setblock ~171 ~121 ~100 dirt
setblock ~171 ~121 ~101 dirt
setblock ~171 ~121 ~102 dirt
setblock ~171 ~121 ~103 dirt
setblock ~171 ~121 ~104 dirt
setblock ~171 ~121 ~105 dirt
setblock ~171 ~122 ~76 dirt
setblock ~171 ~122 ~77 dirt
setblock ~171 ~122 ~78 dirt
setblock ~171 ~122 ~90 dirt
setblock ~171 ~122 ~91 dirt
setblock ~171 ~122 ~92 dirt
setblock ~171 ~122 ~93 dirt
setblock ~171 ~122 ~94 dirt
setblock ~171 ~122 ~95 dirt
setblock ~171 ~122 ~96 dirt
setblock ~171 ~122 ~97 dirt
setblock ~171 ~122 ~98 dirt
setblock ~171 ~122 ~99 dirt
setblock ~171 ~122 ~100 dirt
setblock ~171 ~122 ~101 dirt
setblock ~171 ~122 ~102 dirt
setblock ~171 ~122 ~103 dirt
setblock ~171 ~122 ~104 dirt
setblock ~171 ~122 ~105 dirt
setblock ~171 ~123 ~76 dirt
setblock ~171 ~123 ~77 grass_block
setblock ~171 ~123 ~78 grass_block
setblock ~171 ~123 ~90 dirt
setblock ~171 ~123 ~91 dirt
setblock ~171 ~123 ~92 dirt
setblock ~171 ~123 ~93 dirt
setblock ~171 ~123 ~94 dirt
setblock ~171 ~123 ~95 dirt
setblock ~171 ~123 ~96 dirt
setblock ~171 ~123 ~97 dirt
setblock ~171 ~123 ~98 dirt
setblock ~171 ~123 ~99 dirt
setblock ~171 ~123 ~100 dirt
setblock ~171 ~123 ~101 dirt
setblock ~171 ~123 ~102 dirt
setblock ~171 ~123 ~103 dirt
setblock ~171 ~123 ~104 dirt
setblock ~171 ~123 ~105 dirt
setblock ~171 ~124 ~76 grass_block
setblock ~171 ~124 ~78 poppy
setblock ~171 ~124 ~90 grass_block
setblock ~171 ~124 ~91 grass_block
setblock ~171 ~124 ~92 grass_block
setblock ~171 ~124 ~93 dirt
setblock ~171 ~124 ~94 dirt
setblock ~171 ~124 ~95 dirt
setblock ~171 ~124 ~96 dirt
setblock ~171 ~124 ~97 dirt
setblock ~171 ~124 ~98 dirt
setblock ~171 ~124 ~99 dirt
setblock ~171 ~124 ~100 dirt
setblock ~171 ~124 ~101 dirt
setblock ~171 ~124 ~102 dirt
setblock ~171 ~124 ~103 dirt
setblock ~171 ~124 ~104 dirt
setblock ~171 ~124 ~105 dirt
setblock ~171 ~125 ~90 short_grass
setblock ~171 ~125 ~91 fern
setblock ~171 ~125 ~93 grass_block
setblock ~171 ~125 ~94 grass_block
setblock ~171 ~125 ~95 grass_block
setblock ~171 ~125 ~96 grass_block
setblock ~171 ~125 ~97 dirt
setblock ~171 ~125 ~98 dirt
setblock ~171 ~125 ~99 dirt
setblock ~171 ~125 ~100 dirt
setblock ~171 ~125 ~101 dirt
setblock ~171 ~125 ~102 dirt
setblock ~171 ~125 ~103 dirt
setblock ~171 ~125 ~104 dirt
setblock ~171 ~125 ~105 dirt
setblock ~171 ~126 ~97 grass_block
setblock ~171 ~126 ~98 grass_block
setblock ~171 ~126 ~99 dirt
setblock ~171 ~126 ~100 dirt
setblock ~171 ~126 ~101 dirt
setblock ~171 ~126 ~102 grass_block
setblock ~171 ~126 ~103 grass_block
setblock ~171 ~126 ~104 grass_block
setblock ~171 ~126 ~105 grass_block
setblock ~171 ~127 ~99 grass_block
setblock ~171 ~127 ~100 grass_block
setblock ~171 ~127 ~101 grass_block
setblock ~171 ~127 ~103 short_grass
setblock ~171 ~128 ~100 poppy
setblock ~171 ~131 ~102 oak_leaves[persistent=true]
setblock ~171 ~131 ~103 oak_leaves[persistent=true]
setblock ~171 ~131 ~104 oak_leaves[persistent=true]
setblock ~171 ~131 ~105 jungle_leaves[persistent=true]
setblock ~171 ~131 ~106 oak_leaves[persistent=true]
setblock ~171 ~131 ~107 oak_leaves[persistent=true]
setblock ~171 ~131 ~109 oak_leaves[persistent=true]
setblock ~171 ~131 ~110 oak_leaves[persistent=true]
setblock ~171 ~132 ~102 oak_leaves[persistent=true]
setblock ~171 ~132 ~103 jungle_leaves[persistent=true]
setblock ~171 ~132 ~104 oak_leaves[persistent=true]
setblock ~171 ~132 ~105 jungle_leaves[persistent=true]
setblock ~171 ~132 ~106 jungle_leaves[persistent=true]
setblock ~171 ~132 ~107 oak_leaves[persistent=true]
setblock ~171 ~132 ~108 oak_leaves[persistent=true]
setblock ~171 ~132 ~109 oak_leaves[persistent=true]
setblock ~171 ~132 ~110 oak_leaves[persistent=true]
setblock ~171 ~133 ~102 jungle_leaves[persistent=true]
setblock ~171 ~133 ~103 oak_leaves[persistent=true]
setblock ~171 ~133 ~104 oak_wood
setblock ~171 ~133 ~105 oak_wood
setblock ~171 ~133 ~106 oak_leaves[persistent=true]
setblock ~171 ~133 ~107 oak_leaves[persistent=true]
setblock ~171 ~133 ~108 oak_wood
setblock ~171 ~133 ~109 oak_leaves[persistent=true]
setblock ~171 ~133 ~110 jungle_leaves[persistent=true]
setblock ~171 ~134 ~100 oak_leaves[persistent=true]
setblock ~171 ~134 ~101 jungle_leaves[persistent=true]
setblock ~171 ~134 ~102 oak_leaves[persistent=true]
setblock ~171 ~134 ~103 oak_leaves[persistent=true]
setblock ~171 ~134 ~104 oak_leaves[persistent=true]
setblock ~171 ~134 ~105 oak_leaves[persistent=true]
setblock ~171 ~134 ~106 jungle_leaves[persistent=true]
setblock ~171 ~134 ~107 jungle_leaves[persistent=true]
setblock ~171 ~134 ~108 jungle_leaves[persistent=true]
setblock ~171 ~134 ~109 jungle_leaves[persistent=true]
setblock ~171 ~134 ~110 oak_leaves[persistent=true]
setblock ~171 ~134 ~111 oak_leaves[persistent=true]
setblock ~171 ~134 ~112 oak_leaves[persistent=true]
setblock ~171 ~135 ~100 jungle_leaves[persistent=true]
setblock ~171 ~135 ~101 oak_leaves[persistent=true]
setblock ~171 ~135 ~102 oak_leaves[persistent=true]
setblock ~171 ~135 ~103 oak_leaves[persistent=true]
setblock ~171 ~135 ~104 oak_leaves[persistent=true]
setblock ~171 ~135 ~105 oak_leaves[persistent=true]
setblock ~171 ~135 ~106 oak_leaves[persistent=true]
setblock ~171 ~135 ~107 oak_leaves[persistent=true]
setblock ~171 ~135 ~108 oak_leaves[persistent=true]
setblock ~171 ~135 ~109 oak_leaves[persistent=true]
setblock ~171 ~135 ~110 jungle_leaves[persistent=true]
setblock ~171 ~135 ~111 jungle_leaves[persistent=true]
setblock ~171 ~135 ~112 jungle_leaves[persistent=true]
setblock ~171 ~136 ~100 oak_leaves[persistent=true]
setblock ~171 ~136 ~101 oak_leaves[persistent=true]
setblock ~171 ~136 ~103 oak_wood
setblock ~171 ~136 ~104 oak_leaves[persistent=true]
setblock ~171 ~136 ~105 oak_leaves[persistent=true]
setblock ~171 ~136 ~106 oak_leaves[persistent=true]
setblock ~171 ~136 ~107 oak_leaves[persistent=true]
setblock ~171 ~136 ~108 oak_leaves[persistent=true]
setblock ~171 ~136 ~109 oak_wood
setblock ~171 ~136 ~111 oak_leaves[persistent=true]
setblock ~171 ~136 ~112 oak_leaves[persistent=true]
setblock ~171 ~137 ~101 oak_leaves[persistent=true]
setblock ~171 ~137 ~102 jungle_leaves[persistent=true]
setblock ~171 ~137 ~103 jungle_leaves[persistent=true]
setblock ~171 ~137 ~104 oak_wood
setblock ~171 ~137 ~105 oak_leaves[persistent=true]
setblock ~171 ~137 ~106 jungle_leaves[persistent=true]
setblock ~171 ~137 ~107 oak_leaves[persistent=true]
setblock ~171 ~137 ~108 oak_leaves[persistent=true]
setblock ~171 ~137 ~109 oak_leaves[persistent=true]
setblock ~171 ~137 ~110 jungle_leaves[persistent=true]
setblock ~171 ~137 ~111 oak_leaves[persistent=true]
setblock ~171 ~137 ~112 jungle_leaves[persistent=true]
setblock ~171 ~138 ~100 oak_leaves[persistent=true]
setblock ~171 ~138 ~102 oak_leaves[persistent=true]
setblock ~171 ~138 ~103 jungle_leaves[persistent=true]
setblock ~171 ~138 ~104 oak_leaves[persistent=true]
setblock ~171 ~138 ~105 oak_leaves[persistent=true]
setblock ~171 ~138 ~106 oak_leaves[persistent=true]
setblock ~171 ~138 ~107 oak_leaves[persistent=true]
setblock ~171 ~138 ~108 oak_leaves[persistent=true]
setblock ~171 ~139 ~100 oak_leaves[persistent=true]
setblock ~171 ~139 ~101 jungle_leaves[persistent=true]
setblock ~171 ~139 ~102 jungle_leaves[persistent=true]
setblock ~171 ~139 ~103 oak_leaves[persistent=true]
setblock ~171 ~139 ~105 oak_leaves[persistent=true]
setblock ~171 ~139 ~106 oak_leaves[persistent=true]
setblock ~171 ~139 ~107 oak_leaves[persistent=true]
setblock ~171 ~139 ~108 oak_leaves[persistent=true]
setblock ~171 ~139 ~109 oak_leaves[persistent=true]
setblock ~171 ~140 ~100 oak_leaves[persistent=true]
setblock ~171 ~140 ~101 oak_leaves[persistent=true]
setblock ~171 ~140 ~102 oak_leaves[persistent=true]
setblock ~171 ~140 ~106 oak_leaves[persistent=true]
setblock ~171 ~140 ~107 oak_leaves[persistent=true]
setblock ~172 ~117 ~96 dirt
setblock ~172 ~118 ~95 dirt
setblock ~172 ~118 ~96 dirt
setblock ~172 ~118 ~97 dirt
setblock ~172 ~118 ~98 dirt
setblock ~172 ~119 ~91 dirt
setblock ~172 ~119 ~94 dirt
setblock ~172 ~119 ~95 dirt
setblock ~172 ~119 ~96 dirt
setblock ~172 ~119 ~97 dirt
setblock ~172 ~119 ~98 dirt
setblock ~172 ~120 ~91 dirt
setblock ~172 ~120 ~94 dirt
setblock ~172 ~120 ~95 dirt
setblock ~172 ~120 ~96 dirt
setblock ~172 ~120 ~97 dirt
setblock ~172 ~120 ~98 dirt
setblock ~172 ~120 ~99 dirt
setblock ~172 ~120 ~102 dirt
setblock ~172 ~121 ~77 dirt
setblock ~172 ~121 ~91 dirt
setblock ~172 ~121 ~92 dirt
setblock ~172 ~121 ~93 dirt
setblock ~172 ~121 ~94 dirt
setblock ~172 ~121 ~95 dirt
setblock ~172 ~121 ~96 dirt
setblock ~172 ~121 ~97 dirt
setblock ~172 ~121 ~98 dirt
setblock ~172 ~121 ~99 dirt
setblock ~172 ~121 ~101 dirt
setblock ~172 ~121 ~102 dirt
setblock ~172 ~122 ~77 dirt
setblock ~172 ~122 ~91 dirt
setblock ~172 ~122 ~92 dirt
setblock ~172 ~122 ~93 dirt
setblock ~172 ~122 ~94 dirt
setblock ~172 ~122 ~95 dirt
setblock ~172 ~122 ~96 dirt
setblock ~172 ~122 ~97 dirt
setblock ~172 ~122 ~98 dirt
setblock ~172 ~122 ~99 dirt
setblock ~172 ~122 ~101 dirt
setblock ~172 ~122 ~102 dirt
setblock ~172 ~123 ~77 dirt
setblock ~172 ~123 ~91 dirt
setblock ~172 ~123 ~92 dirt
setblock ~172 ~123 ~93 dirt
setblock ~172 ~123 ~94 dirt
setblock ~172 ~123 ~95 dirt
setblock ~172 ~123 ~96 dirt
setblock ~172 ~123 ~97 dirt
setblock ~172 ~123 ~98 dirt
setblock ~172 ~123 ~99 dirt
setblock ~172 ~123 ~101 dirt
setblock ~172 ~123 ~102 dirt
setblock ~172 ~124 ~77 grass_block
setblock ~172 ~124 ~91 grass_block
setblock ~172 ~124 ~92 grass_block
setblock ~172 ~124 ~93 dirt
setblock ~172 ~124 ~94 dirt
setblock ~172 ~124 ~95 dirt
setblock ~172 ~124 ~96 dirt
setblock ~172 ~124 ~97 dirt
setblock ~172 ~124 ~98 dirt
setblock ~172 ~124 ~99 dirt
setblock ~172 ~124 ~101 dirt
setblock ~172 ~124 ~102 dirt
setblock ~172 ~125 ~77 short_grass
setblock ~172 ~125 ~93 grass_block
setblock ~172 ~125 ~94 grass_block
setblock ~172 ~125 ~95 grass_block
setblock ~172 ~125 ~96 grass_block
setblock ~172 ~125 ~97 dirt
setblock ~172 ~125 ~98 dirt
setblock ~172 ~125 ~99 dirt
setblock ~172 ~125 ~101 dirt
setblock ~172 ~125 ~102 dirt
setblock ~172 ~126 ~93 short_grass
setblock ~172 ~126 ~94 poppy
setblock ~172 ~126 ~97 grass_block
setblock ~172 ~126 ~98 grass_block
setblock ~172 ~126 ~99 grass_block
setblock ~172 ~126 ~101 grass_block
setblock ~172 ~126 ~102 grass_block
setblock ~172 ~127 ~98 short_grass
setblock ~172 ~130 ~108 oak_leaves[persistent=true]
setblock ~172 ~130 ~110 oak_leaves[persistent=true]
setblock ~172 ~130 ~111 oak_leaves[persistent=true]
setblock ~172 ~131 ~102 oak_leaves[persistent=true]
setblock ~172 ~131 ~103 oak_leaves[persistent=true]
setblock ~172 ~131 ~104 oak_leaves[persistent=true]
setblock ~172 ~131 ~105 oak_leaves[persistent=true]
setblock ~172 ~131 ~106 oak_leaves[persistent=true]
setblock ~172 ~131 ~107 oak_leaves[persistent=true]
setblock ~172 ~131 ~108 jungle_leaves[persistent=true]
setblock ~172 ~131 ~109 oak_leaves[persistent=true]
setblock ~172 ~131 ~110 jungle_leaves[persistent=true]
setblock ~172 ~131 ~111 oak_leaves[persistent=true]
setblock ~172 ~132 ~102 oak_leaves[persistent=true]
setblock ~172 ~132 ~103 oak_leaves[persistent=true]
setblock ~172 ~132 ~104 oak_leaves[persistent=true]
setblock ~172 ~132 ~105 oak_leaves[persistent=true]
setblock ~172 ~132 ~107 jungle_leaves[persistent=true]
setblock ~172 ~132 ~108 oak_leaves[persistent=true]
setblock ~172 ~132 ~109 oak_leaves[persistent=true]
setblock ~172 ~132 ~110 oak_leaves[persistent=true]
setblock ~172 ~132 ~111 oak_leaves[persistent=true]
setblock ~172 ~133 ~102 oak_leaves[persistent=true]
setblock ~172 ~133 ~103 oak_leaves[persistent=true]
setblock ~172 ~133 ~104 jungle_leaves[persistent=true]
setblock ~172 ~133 ~105 oak_leaves[persistent=true]
setblock ~172 ~133 ~107 jungle_leaves[persistent=true]
setblock ~172 ~133 ~108 oak_leaves[persistent=true]
setblock ~172 ~133 ~109 oak_wood
setblock ~172 ~133 ~110 oak_leaves[persistent=true]
setblock ~172 ~133 ~111 jungle_leaves[persistent=true]
setblock ~172 ~134 ~101 oak_leaves[persistent=true]
setblock ~172 ~134 ~102 oak_leaves[persistent=true]
setblock ~172 ~134 ~103 oak_leaves[persistent=true]
setblock ~172 ~134 ~104 oak_leaves[persistent=true]
setblock ~172 ~134 ~105 oak_leaves[persistent=true]
setblock ~172 ~134 ~106 oak_leaves[persistent=true]
setblock ~172 ~134 ~107 oak_leaves[persistent=true]
setblock ~172 ~134 ~108 oak_leaves[persistent=true]
setblock ~172 ~134 ~109 oak_leaves[persistent=true]
setblock ~172 ~134 ~110 oak_leaves[persistent=true]
setblock ~172 ~134 ~111 jungle_leaves[persistent=true]
setblock ~172 ~134 ~112 jungle_leaves[persistent=true]
setblock ~172 ~135 ~100 oak_leaves[persistent=true]
setblock ~172 ~135 ~101 oak_leaves[persistent=true]
setblock ~172 ~135 ~102 oak_leaves[persistent=true]
setblock ~172 ~135 ~103 oak_leaves[persistent=true]
setblock ~172 ~135 ~104 jungle_leaves[persistent=true]
setblock ~172 ~135 ~105 oak_leaves[persistent=true]
setblock ~172 ~135 ~107 jungle_leaves[persistent=true]
setblock ~172 ~135 ~108 jungle_leaves[persistent=true]
setblock ~172 ~135 ~110 oak_leaves[persistent=true]
setblock ~172 ~135 ~111 oak_leaves[persistent=true]
setblock ~172 ~135 ~112 oak_leaves[persistent=true]
setblock ~172 ~136 ~100 oak_leaves[persistent=true]
setblock ~172 ~136 ~101 oak_leaves[persistent=true]
setblock ~172 ~136 ~102 oak_leaves[persistent=true]
setblock ~172 ~136 ~103 oak_wood
setblock ~172 ~136 ~104 oak_leaves[persistent=true]
setblock ~172 ~136 ~107 oak_leaves[persistent=true]
setblock ~172 ~136 ~108 oak_leaves[persistent=true]
setblock ~172 ~136 ~109 oak_leaves[persistent=true]
setblock ~172 ~136 ~110 oak_wood
setblock ~172 ~136 ~111 jungle_leaves[persistent=true]
setblock ~172 ~136 ~112 oak_leaves[persistent=true]
setblock ~172 ~137 ~100 oak_leaves[persistent=true]
setblock ~172 ~137 ~101 oak_leaves[persistent=true]
setblock ~172 ~137 ~102 oak_leaves[persistent=true]
setblock ~172 ~137 ~103 oak_leaves[persistent=true]
setblock ~172 ~137 ~104 oak_wood
setblock ~172 ~137 ~105 oak_leaves[persistent=true]
setblock ~172 ~137 ~107 oak_leaves[persistent=true]
setblock ~172 ~137 ~108 oak_leaves[persistent=true]
setblock ~172 ~137 ~109 oak_leaves[persistent=true]
setblock ~172 ~137 ~110 oak_leaves[persistent=true]
setblock ~172 ~137 ~111 oak_leaves[persistent=true]
setblock ~172 ~137 ~112 oak_leaves[persistent=true]
setblock ~172 ~138 ~102 oak_leaves[persistent=true]
setblock ~172 ~138 ~103 oak_leaves[persistent=true]
setblock ~172 ~138 ~104 oak_leaves[persistent=true]
setblock ~172 ~138 ~105 oak_leaves[persistent=true]
setblock ~173 ~119 ~95 dirt
setblock ~173 ~119 ~96 dirt
setblock ~173 ~120 ~95 dirt
setblock ~173 ~120 ~96 dirt
setblock ~173 ~120 ~97 dirt
setblock ~173 ~121 ~94 dirt
setblock ~173 ~121 ~95 dirt
setblock ~173 ~121 ~96 dirt
setblock ~173 ~121 ~97 dirt
setblock ~173 ~121 ~98 dirt
setblock ~173 ~122 ~94 dirt
setblock ~173 ~122 ~95 dirt
setblock ~173 ~122 ~96 dirt
setblock ~173 ~122 ~97 dirt
setblock ~173 ~122 ~98 dirt
setblock ~173 ~123 ~94 dirt
setblock ~173 ~123 ~95 dirt
setblock ~173 ~123 ~96 dirt
setblock ~173 ~123 ~97 dirt
setblock ~173 ~123 ~98 dirt
setblock ~173 ~124 ~94 dirt
setblock ~173 ~124 ~95 dirt
setblock ~173 ~124 ~96 dirt
setblock ~173 ~124 ~97 dirt
setblock ~173 ~124 ~98 dirt
setblock ~173 ~125 ~94 grass_block
setblock ~173 ~125 ~95 grass_block
setblock ~173 ~125 ~96 grass_block
setblock ~173 ~125 ~97 dirt
setblock ~173 ~125 ~98 dirt
setblock ~173 ~126 ~94 short_grass
setblock ~173 ~126 ~97 grass_block
setblock ~173 ~126 ~98 grass_block
setblock ~173 ~130 ~108 oak_leaves[persistent=true]
setblock ~173 ~130 ~109 oak_leaves[persistent=true]
setblock ~173 ~130 ~110 oak_leaves[persistent=true]
setblock ~173 ~130 ~111 oak_leaves[persistent=true]
setblock ~173 ~131 ~102 oak_leaves[persistent=true]
setblock ~173 ~131 ~103 oak_leaves[persistent=true]
setblock ~173 ~131 ~104 oak_leaves[persistent=true]
setblock ~173 ~131 ~105 oak_leaves[persistent=true]
setblock ~173 ~131 ~107 jungle_leaves[persistent=true]
setblock ~173 ~131 ~108 oak_leaves[persistent=true]
setblock ~173 ~131 ~109 oak_leaves[persistent=true]
setblock ~173 ~131 ~110 oak_leaves[persistent=true]
setblock ~173 ~131 ~111 oak_leaves[persistent=true]
setblock ~173 ~132 ~102 oak_leaves[persistent=true]
setblock ~173 ~132 ~103 oak_leaves[persistent=true]
setblock ~173 ~132 ~105 oak_leaves[persistent=true]
setblock ~173 ~132 ~107 oak_leaves[persistent=true]
setblock ~173 ~132 ~108 oak_leaves[persistent=true]
setblock ~173 ~132 ~109 oak_leaves[persistent=true]
setblock ~173 ~132 ~110 jungle_leaves[persistent=true]
setblock ~173 ~133 ~102 oak_leaves[persistent=true]
setblock ~173 ~133 ~103 oak_leaves[persistent=true]
setblock ~173 ~133 ~104 oak_leaves[persistent=true]
setblock ~173 ~133 ~105 oak_leaves[persistent=true]
setblock ~173 ~133 ~107 jungle_leaves[persistent=true]
setblock ~173 ~133 ~108 jungle_leaves[persistent=true]
setblock ~173 ~133 ~109 oak_wood
setblock ~173 ~133 ~111 oak_leaves[persistent=true]
setblock ~173 ~134 ~100 oak_leaves[persistent=true]
setblock ~173 ~134 ~101 jungle_leaves[persistent=true]
setblock ~173 ~134 ~102 oak_leaves[persistent=true]
setblock ~173 ~134 ~103 oak_leaves[persistent=true]
setblock ~173 ~134 ~104 oak_leaves[persistent=true]
setblock ~173 ~134 ~105 oak_leaves[persistent=true]
setblock ~173 ~134 ~107 oak_leaves[persistent=true]
setblock ~173 ~134 ~108 oak_leaves[persistent=true]
setblock ~173 ~134 ~110 oak_leaves[persistent=true]
setblock ~173 ~134 ~111 oak_leaves[persistent=true]
setblock ~173 ~134 ~112 oak_leaves[persistent=true]
setblock ~173 ~135 ~100 oak_leaves[persistent=true]
setblock ~173 ~135 ~101 oak_leaves[persistent=true]
setblock ~173 ~135 ~102 oak_leaves[persistent=true]
setblock ~173 ~135 ~103 oak_leaves[persistent=true]
setblock ~173 ~135 ~104 oak_leaves[persistent=true]
setblock ~173 ~135 ~105 oak_leaves[persistent=true]
setblock ~173 ~135 ~110 oak_leaves[persistent=true]
setblock ~173 ~135 ~111 oak_leaves[persistent=true]
setblock ~173 ~135 ~112 oak_leaves[persistent=true]
setblock ~173 ~136 ~100 jungle_leaves[persistent=true]
setblock ~173 ~136 ~101 oak_leaves[persistent=true]
setblock ~173 ~136 ~102 oak_wood
setblock ~173 ~136 ~103 oak_leaves[persistent=true]
setblock ~173 ~136 ~104 jungle_leaves[persistent=true]
setblock ~173 ~136 ~105 oak_leaves[persistent=true]
setblock ~173 ~136 ~109 oak_leaves[persistent=true]
setblock ~173 ~136 ~110 oak_leaves[persistent=true]
setblock ~173 ~136 ~111 oak_leaves[persistent=true]
setblock ~173 ~136 ~112 oak_leaves[persistent=true]
setblock ~173 ~137 ~100 oak_leaves[persistent=true]
setblock ~173 ~137 ~102 oak_leaves[persistent=true]
setblock ~173 ~137 ~103 oak_leaves[persistent=true]
setblock ~173 ~137 ~104 oak_wood
setblock ~173 ~137 ~105 oak_leaves[persistent=true]
setblock ~173 ~137 ~109 oak_leaves[persistent=true]
setblock ~173 ~137 ~110 oak_leaves[persistent=true]
setblock ~173 ~137 ~111 oak_leaves[persistent=true]
setblock ~173 ~137 ~112 oak_leaves[persistent=true]
setblock ~173 ~138 ~102 oak_leaves[persistent=true]
setblock ~173 ~138 ~103 oak_leaves[persistent=true]
setblock ~173 ~138 ~104 oak_leaves[persistent=true]
setblock ~173 ~138 ~105 jungle_leaves[persistent=true]
setblock ~174 ~121 ~95 dirt
setblock ~174 ~121 ~96 dirt
setblock ~174 ~122 ~95 dirt
setblock ~174 ~122 ~96 dirt
setblock ~174 ~123 ~95 dirt
setblock ~174 ~123 ~96 dirt
setblock ~174 ~124 ~95 dirt
setblock ~174 ~124 ~96 dirt
setblock ~174 ~125 ~95 grass_block
setblock ~174 ~125 ~96 grass_block
setblock ~174 ~126 ~96 short_grass
setblock ~174 ~130 ~108 oak_leaves[persistent=true]
setblock ~174 ~130 ~109 oak_leaves[persistent=true]
setblock ~174 ~130 ~110 jungle_leaves[persistent=true]
setblock ~174 ~130 ~111 jungle_leaves[persistent=true]
setblock ~174 ~131 ~108 oak_leaves[persistent=true]
setblock ~174 ~131 ~111 jungle_leaves[persistent=true]
setblock ~174 ~132 ~108 oak_leaves[persistent=true]
setblock ~174 ~132 ~109 oak_leaves[persistent=true]
setblock ~174 ~132 ~110 oak_wood
setblock ~174 ~132 ~111 oak_leaves[persistent=true]
setblock ~174 ~133 ~108 jungle_leaves[persistent=true]
setblock ~174 ~133 ~109 oak_leaves[persistent=true]
setblock ~174 ~133 ~110 oak_leaves[persistent=true]
setblock ~174 ~133 ~111 oak_leaves[persistent=true]
setblock ~174 ~134 ~100 oak_leaves[persistent=true]
setblock ~174 ~134 ~101 jungle_leaves[persistent=true]
setblock ~174 ~134 ~102 jungle_leaves[persistent=true]
setblock ~174 ~134 ~103 oak_leaves[persistent=true]
setblock ~174 ~134 ~108 oak_leaves[persistent=true]
setblock ~174 ~134 ~109 oak_leaves[persistent=true]
setblock ~174 ~134 ~110 oak_leaves[persistent=true]
setblock ~174 ~134 ~111 jungle_leaves[persistent=true]
setblock ~174 ~134 ~112 oak_leaves[persistent=true]
setblock ~174 ~135 ~100 oak_leaves[persistent=true]
setblock ~174 ~135 ~101 oak_leaves[persistent=true]
setblock ~174 ~135 ~102 jungle_leaves[persistent=true]
setblock ~174 ~135 ~103 oak_leaves[persistent=true]
setblock ~174 ~135 ~104 oak_leaves[persistent=true]
setblock ~174 ~135 ~105 oak_leaves[persistent=true]
setblock ~174 ~135 ~109 jungle_leaves[persistent=true]
setblock ~174 ~135 ~110 oak_leaves[persistent=true]
setblock ~174 ~135 ~111 oak_leaves[persistent=true]
setblock ~174 ~136 ~99 jungle_leaves[persistent=true]
setblock ~174 ~136 ~100 oak_leaves[persistent=true]
setblock ~174 ~136 ~101 oak_wood
setblock ~174 ~136 ~102 oak_leaves[persistent=true]
setblock ~174 ~136 ~103 oak_leaves[persistent=true]
setblock ~174 ~136 ~104 oak_leaves[persistent=true]
setblock ~174 ~136 ~105 oak_leaves[persistent=true]
setblock ~174 ~136 ~110 jungle_leaves[persistent=true]
setblock ~174 ~136 ~111 oak_leaves[persistent=true]
setblock ~174 ~137 ~99 oak_leaves[persistent=true]
setblock ~174 ~137 ~100 jungle_leaves[persistent=true]
setblock ~174 ~137 ~101 jungle_leaves[persistent=true]
setblock ~174 ~137 ~102 oak_leaves[persistent=true]
setblock ~174 ~137 ~103 oak_wood
setblock ~174 ~137 ~104 oak_leaves[persistent=true]
setblock ~174 ~137 ~105 jungle_leaves[persistent=true]
setblock ~174 ~137 ~109 oak_leaves[persistent=true]
setblock ~174 ~137 ~110 oak_leaves[persistent=true]
setblock ~174 ~137 ~111 jungle_leaves[persistent=true]
setblock ~174 ~138 ~99 jungle_leaves[persistent=true]
setblock ~174 ~138 ~100 oak_leaves[persistent=true]
setblock ~174 ~138 ~101 oak_leaves[persistent=true]
setblock ~174 ~138 ~102 jungle_leaves[persistent=true]
setblock ~174 ~138 ~103 jungle_leaves[persistent=true]
setblock ~174 ~138 ~104 oak_leaves[persistent=true]
setblock ~174 ~138 ~105 oak_leaves[persistent=true]
setblock ~175 ~130 ~108 oak_leaves[persistent=true]
setblock ~175 ~130 ~109 oak_leaves[persistent=true]
setblock ~175 ~130 ~110 jungle_leaves[persistent=true]
setblock ~175 ~130 ~111 oak_leaves[persistent=true]
setblock ~175 ~131 ~108 oak_leaves[persistent=true]
setblock ~175 ~131 ~110 oak_leaves[persistent=true]
setblock ~175 ~131 ~111 oak_leaves[persistent=true]
setblock ~175 ~132 ~108 oak_leaves[persistent=true]
setblock ~175 ~132 ~109 oak_leaves[persistent=true]
setblock ~175 ~132 ~110 oak_leaves[persistent=true]
setblock ~175 ~132 ~111 jungle_leaves[persistent=true]
setblock ~175 ~133 ~108 oak_leaves[persistent=true]
setblock ~175 ~133 ~109 oak_leaves[persistent=true]
setblock ~175 ~133 ~110 jungle_leaves[persistent=true]
setblock ~175 ~133 ~111 oak_leaves[persistent=true]
setblock ~175 ~135 ~100 oak_leaves[persistent=true]
setblock ~175 ~135 ~102 oak_leaves[persistent=true]
setblock ~175 ~135 ~103 oak_leaves[persistent=true]
setblock ~175 ~135 ~104 oak_leaves[persistent=true]
setblock ~175 ~136 ~98 oak_leaves[persistent=true]
setblock ~175 ~136 ~100 oak_leaves[persistent=true]
setblock ~175 ~136 ~101 jungle_leaves[persistent=true]
setblock ~175 ~136 ~102 oak_leaves[persistent=true]
setblock ~175 ~136 ~103 oak_leaves[persistent=true]
setblock ~175 ~136 ~104 oak_leaves[persistent=true]
setblock ~175 ~137 ~98 oak_leaves[persistent=true]
setblock ~175 ~137 ~99 oak_leaves[persistent=true]
setblock ~175 ~137 ~100 oak_wood
setblock ~175 ~137 ~103 oak_wood
setblock ~175 ~137 ~104 jungle_leaves[persistent=true]
setblock ~175 ~138 ~98 oak_leaves[persistent=true]
setblock ~175 ~138 ~99 jungle_leaves[persistent=true]
setblock ~175 ~138 ~100 oak_leaves[persistent=true]
setblock ~175 ~138 ~101 jungle_leaves[persistent=true]
setblock ~175 ~138 ~102 oak_leaves[persistent=true]
setblock ~175 ~138 ~103 jungle_leaves[persistent=true]
setblock ~175 ~138 ~104 oak_leaves[persistent=true]
setblock ~176 ~135 ~100 oak_leaves[persistent=true]
setblock ~176 ~135 ~101 jungle_leaves[persistent=true]
setblock ~176 ~135 ~102 oak_leaves[persistent=true]
setblock ~176 ~135 ~103 oak_leaves[persistent=true]
setblock ~176 ~135 ~104 oak_leaves[persistent=true]
setblock ~176 ~136 ~99 jungle_leaves[persistent=true]
setblock ~176 ~136 ~101 oak_leaves[persistent=true]
setblock ~176 ~136 ~102 oak_leaves[persistent=true]
setblock ~176 ~136 ~103 jungle_leaves[persistent=true]
setblock ~176 ~136 ~104 jungle_leaves[persistent=true]
setblock ~176 ~137 ~98 oak_leaves[persistent=true]
setblock ~176 ~137 ~99 oak_leaves[persistent=true]
setblock ~176 ~137 ~100 jungle_leaves[persistent=true]
setblock ~176 ~137 ~101 oak_leaves[persistent=true]
setblock ~176 ~137 ~102 oak_leaves[persistent=true]
setblock ~176 ~137 ~103 oak_wood
setblock ~176 ~137 ~104 oak_leaves[persistent=true]
setblock ~176 ~138 ~98 oak_leaves[persistent=true]
setblock ~176 ~138 ~99 oak_leaves[persistent=true]
setblock ~176 ~138 ~100 oak_leaves[persistent=true]
setblock ~176 ~138 ~101 oak_leaves[persistent=true]
setblock ~176 ~138 ~102 oak_leaves[persistent=true]
setblock ~176 ~138 ~103 oak_leaves[persistent=true]
setblock ~176 ~138 ~104 oak_leaves[persistent=true]
setblock ~177 ~135 ~100 oak_leaves[persistent=true]
setblock ~177 ~135 ~101 oak_leaves[persistent=true]
setblock ~177 ~135 ~102 oak_leaves[persistent=true]
setblock ~177 ~135 ~103 oak_leaves[persistent=true]
setblock ~177 ~136 ~98 oak_leaves[persistent=true]
setblock ~177 ~136 ~100 jungle_leaves[persistent=true]
setblock ~177 ~136 ~101 oak_leaves[persistent=true]
setblock ~177 ~136 ~102 oak_leaves[persistent=true]
setblock ~177 ~136 ~103 oak_leaves[persistent=true]
setblock ~177 ~136 ~104 oak_leaves[persistent=true]
setblock ~177 ~137 ~98 oak_leaves[persistent=true]
setblock ~177 ~137 ~99 oak_leaves[persistent=true]
setblock ~177 ~137 ~100 oak_leaves[persistent=true]
setblock ~177 ~137 ~101 oak_leaves[persistent=true]
setblock ~177 ~137 ~102 oak_leaves[persistent=true]
setblock ~177 ~137 ~103 jungle_leaves[persistent=true]
setblock ~177 ~137 ~104 oak_leaves[persistent=true]
setblock ~177 ~138 ~98 oak_leaves[persistent=true]
setblock ~177 ~138 ~99 oak_leaves[persistent=true]
setblock ~177 ~138 ~100 oak_leaves[persistent=true]
setblock ~177 ~138 ~101 oak_leaves[persistent=true]
setblock ~177 ~138 ~102 oak_leaves[persistent=true]
setblock ~177 ~138 ~103 oak_leaves[persistent=true]
setblock ~177 ~138 ~104 oak_leaves[persistent=true]
setblock ~178 ~135 ~100 oak_leaves[persistent=true]
setblock ~178 ~135 ~101 oak_leaves[persistent=true]
setblock ~178 ~135 ~102 oak_leaves[persistent=true]
setblock ~178 ~135 ~103 jungle_leaves[persistent=true]
setblock ~178 ~136 ~100 oak_leaves[persistent=true]
setblock ~178 ~136 ~101 oak_leaves[persistent=true]
setblock ~178 ~136 ~102 oak_leaves[persistent=true]
setblock ~178 ~136 ~103 jungle_leaves[persistent=true]
setblock ~178 ~137 ~100 oak_leaves[persistent=true]
setblock ~178 ~137 ~101 oak_leaves[persistent=true]
setblock ~178 ~137 ~102 oak_leaves[persistent=true]
setblock ~178 ~137 ~103 oak_leaves[persistent=true]
setblock ~178 ~138 ~100 jungle_leaves[persistent=true]
setblock ~178 ~138 ~101 oak_leaves[persistent=true]
setblock ~178 ~138 ~102 oak_leaves[persistent=true]
setblock ~178 ~138 ~103 oak_leaves[persistent=true]
setblock ~199 ~200 ~199 gold_block
