setblock ~185 ~123 ~96 dirt
setblock ~185 ~123 ~97 dirt
setblock ~185 ~123 ~98 dirt
setblock ~185 ~123 ~99 dirt
setblock ~185 ~123 ~100 dirt
setblock ~185 ~123 ~101 dirt
setblock ~185 ~123 ~108 dirt
setblock ~185 ~123 ~109 dirt
setblock ~185 ~123 ~110 dirt
setblock ~185 ~123 ~111 dirt
setblock ~185 ~123 ~112 dirt
setblock ~185 ~123 ~113 dirt
setblock ~185 ~123 ~114 dirt
setblock ~185 ~123 ~115 dirt
setblock ~185 ~123 ~116 dirt
setblock ~185 ~123 ~117 dirt
setblock ~185 ~123 ~118 dirt
setblock ~185 ~123 ~119 dirt
setblock ~185 ~123 ~120 dirt
setblock ~185 ~123 ~121 dirt
setblock ~185 ~123 ~122 dirt
setblock ~185 ~123 ~123 dirt
setblock ~185 ~123 ~124 dirt
setblock ~185 ~123 ~125 dirt
setblock ~185 ~123 ~126 dirt
setblock ~185 ~123 ~127 dirt
setblock ~185 ~124 ~68 dirt
setblock ~185 ~124 ~69 dirt
setblock ~185 ~124 ~70 dirt
setblock ~185 ~124 ~71 dirt
setblock ~185 ~124 ~72 dirt
setblock ~185 ~124 ~73 dirt
setblock ~185 ~124 ~74 dirt
setblock ~185 ~124 ~75 dirt
setblock ~185 ~124 ~79 dirt
setblock ~185 ~124 ~80 dirt
setblock ~185 ~124 ~81 dirt
setblock ~185 ~124 ~82 grass_block
setblock ~185 ~124 ~83 grass_block
setblock ~185 ~124 ~84 grass_block
setblock ~185 ~124 ~85 grass_block
setblock ~185 ~124 ~94 poppy
setblock ~185 ~124 ~95 grass_block
setblock ~185 ~124 ~96 grass_block
setblock ~185 ~124 ~97 grass_block
setblock ~185 ~124 ~98 dirt
setblock ~185 ~124 ~99 dirt
setblock ~185 ~124 ~100 dirt
setblock ~185 ~124 ~101 dirt
setblock ~185 ~124 ~108 grass_block
setblock ~185 ~124 ~109 grass_block
setblock ~185 ~124 ~110 grass_block
setblock ~185 ~124 ~111 grass_block
setblock ~185 ~124 ~112 grass_block
setblock ~185 ~124 ~113 grass_block
setblock ~185 ~124 ~114 grass_block
setblock ~185 ~124 ~115 dirt
setblock ~185 ~124 ~116 dirt
setblock ~185 ~124 ~117 dirt
setblock ~185 ~124 ~118 dirt
setblock ~185 ~124 ~119 dirt
setblock ~185 ~124 ~120 dirt
setblock ~185 ~124 ~121 dirt
setblock ~185 ~124 ~122 dirt
setblock ~185 ~124 ~123 dirt
setblock ~185 ~124 ~124 dirt
setblock ~185 ~124 ~125 grass_block
setblock ~185 ~124 ~126 grass_block
setblock ~185 ~124 ~127 grass_block
setblock ~185 ~125 ~68 grass_block
setblock ~185 ~125 ~69 grass_block
setblock ~185 ~125 ~70 dirt
setblock ~185 ~125 ~71 dirt
setblock ~185 ~125 ~72 grass_block
setblock ~185 ~125 ~73 grass_block
setblock ~185 ~125 ~74 grass_block
setblock ~185 ~125 ~75 grass_block
setblock ~185 ~125 ~79 grass_block
setblock ~185 ~125 ~80 grass_block
setblock ~185 ~125 ~81 grass_block
setblock ~185 ~125 ~84 fern
setblock ~185 ~125 ~96 short_grass
setblock ~185 ~125 ~98 grass_block
setblock ~185 ~125 ~99 grass_block
setblock ~185 ~125 ~100 dirt
setblock ~185 ~125 ~101 grass_block
setblock ~185 ~125 ~109 short_grass
setblock ~185 ~125 ~110 short_grass
setblock ~185 ~125 ~112 short_grass
setblock ~185 ~125 ~114 poppy
setblock ~185 ~125 ~115 grass_block
setblock ~185 ~125 ~116 grass_block
setblock ~185 ~125 ~117 grass_block
setblock ~185 ~125 ~118 grass_block
setblock ~185 ~125 ~119 grass_block
setblock ~185 ~125 ~120 grass_block
setblock ~185 ~125 ~121 grass_block
setblock ~185 ~125 ~122 grass_block
setblock ~185 ~125 ~123 grass_block
setblock ~185 ~125 ~124 grass_block
setblock ~185 ~125 ~125 short_grass
setblock ~185 ~125 ~126 short_grass
setblock ~185 ~126 ~68 short_grass
setblock ~185 ~126 ~70 grass_block
setblock ~185 ~126 ~71 grass_block
setblock ~185 ~126 ~73 fern
setblock ~185 ~126 ~80 fern
setblock ~185 ~126 ~81 short_grass
setblock ~185 ~126 ~100 grass_block
setblock ~185 ~126 ~101 short_grass
setblock ~185 ~126 ~115 fern
setblock ~185 ~126 ~120 poppy
setblock ~186 ~111 ~90 dirt
setblock ~186 ~112 ~88 dirt
setblock ~186 ~112 ~89 dirt
setblock ~186 ~112 ~90 dirt
setblock ~186 ~112 ~91 dirt
setblock ~186 ~113 ~87 dirt
setblock ~186 ~113 ~88 dirt
setblock ~186 ~113 ~89 dirt
setblock ~186 ~113 ~90 dirt
setblock ~186 ~113 ~91 dirt
setblock ~186 ~113 ~92 dirt
setblock ~186 ~113 ~116 dirt
setblock ~186 ~114 ~87 dirt
setblock ~186 ~114 ~88 dirt
setblock ~186 ~114 ~89 dirt
setblock ~186 ~114 ~90 dirt
setblock ~186 ~114 ~91 dirt
setblock ~186 ~114 ~92 dirt
setblock ~186 ~114 ~93 dirt
setblock ~186 ~114 ~115 dirt
setblock ~186 ~114 ~116 dirt
setblock ~186 ~114 ~117 dirt
setblock ~186 ~114 ~119 dirt
setblock ~186 ~115 ~86 dirt
setblock ~186 ~115 ~87 dirt
setblock ~186 ~115 ~88 dirt
setblock ~186 ~115 ~89 dirt
setblock ~186 ~115 ~90 dirt
setblock ~186 ~115 ~91 dirt
setblock ~186 ~115 ~92 dirt
setblock ~186 ~115 ~93 dirt
setblock ~186 ~115 ~94 dirt
setblock ~186 ~115 ~114 dirt
setblock ~186 ~115 ~115 dirt
setblock ~186 ~115 ~116 dirt
setblock ~186 ~115 ~117 dirt
setblock ~186 ~115 ~118 dirt
setblock ~186 ~115 ~119 dirt
setblock ~186 ~115 ~120 dirt
setblock ~186 ~116 ~85 dirt
setblock ~186 ~116 ~86 dirt
setblock ~186 ~116 ~87 dirt
setblock ~186 ~116 ~88 dirt
setblock ~186 ~116 ~89 dirt
setblock ~186 ~116 ~90 dirt
setblock ~186 ~116 ~91 dirt
setblock ~186 ~116 ~92 dirt
setblock ~186 ~116 ~93 dirt
setblock ~186 ~116 ~94 dirt
setblock ~186 ~116 ~95 dirt
setblock ~186 ~116 ~113 dirt
setblock ~186 ~116 ~114 dirt
setblock ~186 ~116 ~115 dirt
setblock ~186 ~116 ~116 dirt
setblock ~186 ~116 ~117 dirt
setblock ~186 ~116 ~118 dirt
setblock ~186 ~116 ~119 dirt
setblock ~186 ~116 ~120 dirt
setblock ~186 ~116 ~121 dirt
setblock ~186 ~117 ~83 dirt
setblock ~186 ~117 ~84 dirt
setblock ~186 ~117 ~85 dirt
setblock ~186 ~117 ~86 dirt
setblock ~186 ~117 ~87 dirt
setblock ~186 ~117 ~88 dirt
setblock ~186 ~117 ~89 dirt
setblock ~186 ~117 ~90 dirt
setblock ~186 ~117 ~91 dirt
setblock ~186 ~117 ~92 dirt
setblock ~186 ~117 ~93 dirt
setblock ~186 ~117 ~94 dirt
setblock ~186 ~117 ~95 dirt
setblock ~186 ~117 ~96 dirt
setblock ~186 ~117 ~112 dirt
setblock ~186 ~117 ~113 dirt
setblock ~186 ~117 ~114 dirt
setblock ~186 ~117 ~115 dirt
setblock ~186 ~117 ~116 dirt
setblock ~186 ~117 ~117 dirt
setblock ~186 ~117 ~118 dirt
setblock ~186 ~117 ~119 dirt
setblock ~186 ~117 ~120 dirt
setblock ~186 ~117 ~121 dirt
setblock ~186 ~117 ~122 dirt
setblock ~186 ~117 ~123 dirt
setblock ~186 ~118 ~82 dirt
setblock ~186 ~118 ~83 dirt
setblock ~186 ~118 ~84 dirt
setblock ~186 ~118 ~85 dirt
setblock ~186 ~118 ~86 dirt
setblock ~186 ~118 ~87 dirt
setblock ~186 ~118 ~88 dirt
setblock ~186 ~118 ~89 dirt
setblock ~186 ~118 ~90 dirt
setblock ~186 ~118 ~91 dirt
setblock ~186 ~118 ~92 dirt
setblock ~186 ~118 ~93 dirt
setblock ~186 ~118 ~94 dirt
setblock ~186 ~118 ~95 dirt
setblock ~186 ~118 ~96 dirt
setblock ~186 ~118 ~97 dirt
setblock ~186 ~118 ~112 dirt
setblock ~186 ~118 ~113 dirt
setblock ~186 ~118 ~114 dirt
setblock ~186 ~118 ~115 dirt
setblock ~186 ~118 ~116 dirt
setblock ~186 ~118 ~117 dirt
setblock ~186 ~118 ~118 dirt
setblock ~186 ~118 ~119 dirt
setblock ~186 ~118 ~120 dirt
setblock ~186 ~118 ~121 dirt
setblock ~186 ~118 ~122 dirt
setblock ~186 ~118 ~123 dirt
setblock ~186 ~118 ~124 dirt
setblock ~186 ~119 ~81 dirt
setblock ~186 ~119 ~82 dirt
setblock ~186 ~119 ~83 dirt
setblock ~186 ~119 ~84 dirt
setblock ~186 ~119 ~85 dirt
setblock ~186 ~119 ~86 dirt
setblock ~186 ~119 ~87 dirt
setblock ~186 ~119 ~88 dirt
setblock ~186 ~119 ~89 dirt
setblock ~186 ~119 ~90 dirt
setblock ~186 ~119 ~91 dirt
setblock ~186 ~119 ~92 dirt
setblock ~186 ~119 ~93 dirt
setblock ~186 ~119 ~94 dirt
setblock ~186 ~119 ~95 dirt
setblock ~186 ~119 ~96 dirt
setblock ~186 ~119 ~97 dirt
setblock ~186 ~119 ~98 dirt
setblock ~186 ~119 ~111 dirt
setblock ~186 ~119 ~112 dirt
setblock ~186 ~119 ~113 dirt
setblock ~186 ~119 ~114 dirt
setblock ~186 ~119 ~115 dirt
setblock ~186 ~119 ~116 dirt
setblock ~186 ~119 ~117 dirt
setblock ~186 ~119 ~118 dirt
setblock ~186 ~119 ~119 dirt
setblock ~186 ~119 ~120 dirt
setblock ~186 ~119 ~121 dirt
setblock ~186 ~119 ~122 dirt
setblock ~186 ~119 ~123 dirt
setblock ~186 ~119 ~124 dirt
setblock ~186 ~119 ~125 dirt
setblock ~186 ~120 ~80 dirt
setblock ~186 ~120 ~81 dirt
setblock ~186 ~120 ~82 dirt
setblock ~186 ~120 ~83 dirt
setblock ~186 ~120 ~84 dirt
setblock ~186 ~120 ~85 dirt
setblock ~186 ~120 ~86 dirt
setblock ~186 ~120 ~87 dirt
setblock ~186 ~120 ~88 dirt
setblock ~186 ~120 ~89 dirt
setblock ~186 ~120 ~90 dirt
setblock ~186 ~120 ~91 dirt
setblock ~186 ~120 ~92 dirt
setblock ~186 ~120 ~93 dirt
setblock ~186 ~120 ~94 dirt
setblock ~186 ~120 ~95 dirt
setblock ~186 ~120 ~96 dirt
setblock ~186 ~120 ~97 dirt
setblock ~186 ~120 ~98 dirt
setblock ~186 ~120 ~99 dirt
setblock ~186 ~120 ~110 dirt
setblock ~186 ~120 ~111 dirt
setblock ~186 ~120 ~112 dirt
setblock ~186 ~120 ~113 dirt
setblock ~186 ~120 ~114 dirt
setblock ~186 ~120 ~115 dirt
setblock ~186 ~120 ~116 dirt
setblock ~186 ~120 ~117 dirt
setblock ~186 ~120 ~118 dirt
setblock ~186 ~120 ~119 dirt
setblock ~186 ~120 ~120 dirt
setblock ~186 ~120 ~121 dirt
setblock ~186 ~120 ~122 dirt
setblock ~186 ~120 ~123 dirt
setblock ~186 ~120 ~124 dirt
setblock ~186 ~120 ~125 dirt
setblock ~186 ~120 ~126 dirt
setblock ~186 ~121 ~72 dirt
setblock ~186 ~121 ~73 dirt
setblock ~186 ~121 ~74 dirt
setblock ~186 ~121 ~79 dirt
setblock ~186 ~121 ~80 dirt
setblock ~186 ~121 ~81 dirt
setblock ~186 ~121 ~82 dirt
setblock ~186 ~121 ~83 dirt
setblock ~186 ~121 ~84 dirt
setblock ~186 ~121 ~85 dirt
setblock ~186 ~121 ~86 dirt
setblock ~186 ~121 ~87 dirt
setblock ~186 ~121 ~88 dirt
setblock ~186 ~121 ~89 dirt
setblock ~186 ~121 ~90 dirt
setblock ~186 ~121 ~91 dirt
setblock ~186 ~121 ~92 dirt
setblock ~186 ~121 ~93 dirt
setblock ~186 ~121 ~94 dirt
setblock ~186 ~121 ~95 dirt
setblock ~186 ~121 ~96 dirt
setblock ~186 ~121 ~97 dirt
setblock ~186 ~121 ~98 dirt
setblock ~186 ~121 ~99 dirt
setblock ~186 ~121 ~100 dirt
setblock ~186 ~121 ~109 dirt
setblock ~186 ~121 ~110 dirt
setblock ~186 ~121 ~111 dirt
setblock ~186 ~121 ~112 dirt
setblock ~186 ~121 ~113 dirt
setblock ~186 ~121 ~114 dirt
setblock ~186 ~121 ~115 dirt
setblock ~186 ~121 ~116 dirt
setblock ~186 ~121 ~117 dirt
setblock ~186 ~121 ~118 dirt
setblock ~186 ~121 ~119 dirt
setblock ~186 ~121 ~120 dirt
setblock ~186 ~121 ~121 dirt
setblock ~186 ~121 ~122 dirt
setblock ~186 ~121 ~123 dirt
setblock ~186 ~121 ~124 dirt
setblock ~186 ~121 ~125 dirt
setblock ~186 ~121 ~126 dirt
setblock ~186 ~121 ~127 dirt
setblock ~186 ~122 ~72 dirt
setblock ~186 ~122 ~73 dirt
setblock ~186 ~122 ~74 dirt
setblock ~186 ~122 ~79 dirt
setblock ~186 ~122 ~80 dirt
setblock ~186 ~122 ~81 dirt
setblock ~186 ~122 ~82 dirt
setblock ~186 ~122 ~83 dirt
setblock ~186 ~122 ~84 dirt
setblock ~186 ~122 ~85 dirt
setblock ~186 ~122 ~86 dirt
setblock ~186 ~122 ~87 dirt
setblock ~186 ~122 ~88 dirt
setblock ~186 ~122 ~89 dirt
setblock ~186 ~122 ~90 grass_block
setblock ~186 ~122 ~91 dirt
setblock ~186 ~122 ~92 dirt
setblock ~186 ~122 ~93 dirt
setblock ~186 ~122 ~94 dirt
setblock ~186 ~122 ~95 dirt
setblock ~186 ~122 ~96 dirt
setblock ~186 ~122 ~97 dirt
setblock ~186 ~122 ~98 dirt
setblock ~186 ~122 ~99 dirt
setblock ~186 ~122 ~100 dirt
setblock ~186 ~122 ~109 dirt
setblock ~186 ~122 ~110 dirt
setblock ~186 ~122 ~111 dirt
setblock ~186 ~122 ~112 dirt
setblock ~186 ~122 ~113 dirt
setblock ~186 ~122 ~114 dirt
setblock ~186 ~122 ~115 dirt
setblock ~186 ~122 ~116 dirt
setblock ~186 ~122 ~117 dirt
setblock ~186 ~122 ~118 dirt
setblock ~186 ~122 ~119 dirt
setblock ~186 ~122 ~120 dirt
setblock ~186 ~122 ~121 dirt
setblock ~186 ~122 ~122 dirt
setblock ~186 ~122 ~123 dirt
setblock ~186 ~122 ~124 dirt
setblock ~186 ~122 ~125 dirt
setblock ~186 ~122 ~126 dirt
setblock ~186 ~122 ~127 dirt
setblock ~186 ~123 ~72 dirt
setblock ~186 ~123 ~73 dirt
setblock ~186 ~123 ~74 dirt
setblock ~186 ~123 ~79 dirt
setblock ~186 ~123 ~80 dirt
setblock ~186 ~123 ~81 dirt
setblock ~186 ~123 ~82 dirt
setblock ~186 ~123 ~83 dirt
setblock ~186 ~123 ~84 dirt
setblock ~186 ~123 ~85 dirt
setblock ~186 ~123 ~86 grass_block
setblock ~186 ~123 ~87 grass_block
setblock ~186 ~123 ~88 grass_block
setblock ~186 ~123 ~89 grass_block
setblock ~186 ~123 ~91 grass_block
setblock ~186 ~123 ~92 grass_block
setblock ~186 ~123 ~93 grass_block
setblock ~186 ~123 ~94 grass_block
setblock ~186 ~123 ~95 dirt
setblock ~186 ~123 ~96 dirt
setblock ~186 ~123 ~97 dirt
setblock ~186 ~123 ~98 dirt
setblock ~186 ~123 ~99 dirt
setblock ~186 ~123 ~100 dirt
setblock ~186 ~123 ~109 dirt
setblock ~186 ~123 ~110 dirt
setblock ~186 ~123 ~111 dirt
setblock ~186 ~123 ~112 dirt
setblock ~186 ~123 ~113 dirt
setblock ~186 ~123 ~114 dirt
setblock ~186 ~123 ~115 dirt
setblock ~186 ~123 ~116 dirt
setblock ~186 ~123 ~117 dirt
setblock ~186 ~123 ~118 dirt
setblock ~186 ~123 ~119 dirt
setblock ~186 ~123 ~120 dirt
setblock ~186 ~123 ~121 dirt
setblock ~186 ~123 ~122 dirt
setblock ~186 ~123 ~123 dirt
setblock ~186 ~123 ~124 dirt
setblock ~186 ~123 ~125 dirt
setblock ~186 ~123 ~126 dirt
setblock ~186 ~123 ~127 dirt
setblock ~186 ~124 ~72 dirt
setblock ~186 ~124 ~73 dirt
setblock ~186 ~124 ~74 dirt
setblock ~186 ~124 ~79 dirt
setblock ~186 ~124 ~80 dirt
setblock ~186 ~124 ~81 dirt
setblock ~186 ~124 ~82 dirt
setblock ~186 ~124 ~83 grass_block
setblock ~186 ~124 ~84 grass_block
setblock ~186 ~124 ~85 grass_block
setblock ~186 ~124 ~87 short_grass
setblock ~186 ~124 ~92 short_grass
setblock ~186 ~124 ~95 grass_block
setblock ~186 ~124 ~96 grass_block
setblock ~186 ~124 ~97 grass_block
setblock ~186 ~124 ~98 dirt
setblock ~186 ~124 ~99 dirt
setblock ~186 ~124 ~100 dirt
setblock ~186 ~124 ~109 grass_block
setblock ~186 ~124 ~110 grass_block
setblock ~186 ~124 ~111 grass_block
setblock ~186 ~124 ~112 grass_block
setblock ~186 ~124 ~113 grass_block
setblock ~186 ~124 ~114 dirt
setblock ~186 ~124 ~115 dirt
setblock ~186 ~124 ~116 dirt
setblock ~186 ~124 ~117 dirt
setblock ~186 ~124 ~118 dirt
setblock ~186 ~124 ~119 dirt
setblock ~186 ~124 ~120 dirt
setblock ~186 ~124 ~121 dirt
setblock ~186 ~124 ~122 dirt
setblock ~186 ~124 ~123 dirt
setblock ~186 ~124 ~124 dirt
setblock ~186 ~124 ~125 dirt
setblock ~186 ~124 ~126 grass_block
setblock ~186 ~124 ~127 grass_block
setblock ~186 ~125 ~72 dirt
setblock ~186 ~125 ~73 dirt
setblock ~186 ~125 ~74 dirt
setblock ~186 ~125 ~79 grass_block
setblock ~186 ~125 ~80 grass_block
setblock ~186 ~125 ~81 grass_block
setblock ~186 ~125 ~82 grass_block
setblock ~186 ~125 ~84 short_grass
setblock ~186 ~125 ~85 short_grass
setblock ~186 ~125 ~97 short_grass
setblock ~186 ~125 ~98 grass_block
setblock ~186 ~125 ~99 grass_block
setblock ~186 ~125 ~100 dirt
setblock ~186 ~125 ~111 short_grass
setblock ~186 ~125 ~114 grass_block
setblock ~186 ~125 ~115 grass_block
setblock ~186 ~125 ~116 grass_block
setblock ~186 ~125 ~117 grass_block
setblock ~186 ~125 ~118 grass_block
setblock ~186 ~125 ~119 grass_block
setblock ~186 ~125 ~120 grass_block
setblock ~186 ~125 ~121 grass_block
setblock ~186 ~125 ~122 grass_block
setblock ~186 ~125 ~123 grass_block
setblock ~186 ~125 ~124 grass_block
setblock ~186 ~125 ~125 grass_block
setblock ~186 ~125 ~126 short_grass
setblock ~186 ~125 ~127 short_grass
setblock ~186 ~126 ~72 grass_block
setblock ~186 ~126 ~73 grass_block
setblock ~186 ~126 ~74 grass_block
setblock ~186 ~126 ~80 short_grass
setblock ~186 ~126 ~81 short_grass
setblock ~186 ~126 ~99 short_grass
setblock ~186 ~126 ~100 grass_block
setblock ~186 ~126 ~119 short_grass
setblock ~186 ~126 ~122 short_grass
setblock ~186 ~126 ~124 short_grass
setblock ~186 ~127 ~73 short_grass
setblock ~186 ~127 ~74 short_grass
setblock ~187 ~112 ~90 dirt
setblock ~187 ~113 ~90 dirt
setblock ~187 ~113 ~91 dirt
setblock ~187 ~114 ~88 dirt
setblock ~187 ~114 ~89 dirt
setblock ~187 ~114 ~90 dirt
setblock ~187 ~114 ~91 dirt
setblock ~187 ~114 ~92 dirt
setblock ~187 ~115 ~87 dirt
setblock ~187 ~115 ~88 dirt
setblock ~187 ~115 ~89 dirt
setblock ~187 ~115 ~90 dirt
setblock ~187 ~115 ~91 dirt
setblock ~187 ~115 ~92 dirt
setblock ~187 ~115 ~93 dirt
setblock ~187 ~115 ~115 dirt
setblock ~187 ~115 ~116 dirt
setblock ~187 ~115 ~117 dirt
setblock ~187 ~115 ~119 dirt
setblock ~187 ~116 ~86 dirt
setblock ~187 ~116 ~87 dirt
setblock ~187 ~116 ~88 dirt
setblock ~187 ~116 ~89 dirt
setblock ~187 ~116 ~90 dirt
setblock ~187 ~116 ~91 dirt
setblock ~187 ~116 ~92 dirt
setblock ~187 ~116 ~93 dirt
setblock ~187 ~116 ~94 dirt
setblock ~187 ~116 ~114 dirt
setblock ~187 ~116 ~115 dirt
setblock ~187 ~116 ~116 dirt
setblock ~187 ~116 ~117 dirt
setblock ~187 ~116 ~118 dirt
setblock ~187 ~116 ~119 dirt
setblock ~187 ~116 ~120 dirt
setblock ~187 ~117 ~85 dirt
setblock ~187 ~117 ~86 dirt
setblock ~187 ~117 ~87 dirt
setblock ~187 ~117 ~88 dirt
setblock ~187 ~117 ~89 dirt
setblock ~187 ~117 ~90 dirt
setblock ~187 ~117 ~91 dirt
setblock ~187 ~117 ~92 dirt
setblock ~187 ~117 ~93 dirt
setblock ~187 ~117 ~94 dirt
setblock ~187 ~117 ~95 dirt
setblock ~187 ~117 ~113 dirt
setblock ~187 ~117 ~114 dirt
setblock ~187 ~117 ~115 dirt
setblock ~187 ~117 ~116 dirt
setblock ~187 ~117 ~117 dirt
setblock ~187 ~117 ~118 dirt
setblock ~187 ~117 ~119 dirt
setblock ~187 ~117 ~120 dirt
setblock ~187 ~117 ~121 dirt
setblock ~187 ~118 ~83 dirt
setblock ~187 ~118 ~84 dirt
setblock ~187 ~118 ~85 dirt
setblock ~187 ~118 ~86 dirt
setblock ~187 ~118 ~87 dirt
setblock ~187 ~118 ~88 dirt
setblock ~187 ~118 ~89 dirt
setblock ~187 ~118 ~90 dirt
setblock ~187 ~118 ~91 dirt
setblock ~187 ~118 ~92 dirt
setblock ~187 ~118 ~93 dirt
setblock ~187 ~118 ~94 dirt
setblock ~187 ~118 ~95 dirt
setblock ~187 ~118 ~96 dirt
setblock ~187 ~118 ~112 dirt
setblock ~187 ~118 ~113 dirt
setblock ~187 ~118 ~114 dirt
setblock ~187 ~118 ~115 dirt
setblock ~187 ~118 ~116 dirt
setblock ~187 ~118 ~117 dirt
setblock ~187 ~118 ~118 dirt
setblock ~187 ~118 ~119 dirt
setblock ~187 ~118 ~120 dirt
setblock ~187 ~118 ~121 dirt
setblock ~187 ~118 ~122 dirt
setblock ~187 ~118 ~123 dirt
setblock ~187 ~119 ~82 dirt
setblock ~187 ~119 ~83 dirt
setblock ~187 ~119 ~84 dirt
setblock ~187 ~119 ~85 dirt
setblock ~187 ~119 ~86 dirt
setblock ~187 ~119 ~87 dirt
setblock ~187 ~119 ~88 dirt
setblock ~187 ~119 ~89 dirt
setblock ~187 ~119 ~90 dirt
setblock ~187 ~119 ~91 dirt
setblock ~187 ~119 ~92 dirt
setblock ~187 ~119 ~93 dirt
setblock ~187 ~119 ~94 dirt
setblock ~187 ~119 ~95 dirt
setblock ~187 ~119 ~96 dirt
setblock ~187 ~119 ~97 dirt
setblock ~187 ~119 ~112 dirt
setblock ~187 ~119 ~113 dirt
setblock ~187 ~119 ~114 dirt
setblock ~187 ~119 ~115 dirt
setblock ~187 ~119 ~116 dirt
setblock ~187 ~119 ~117 dirt
setblock ~187 ~119 ~118 dirt
setblock ~187 ~119 ~119 dirt
setblock ~187 ~119 ~120 dirt
setblock ~187 ~119 ~121 dirt
setblock ~187 ~119 ~122 dirt
setblock ~187 ~119 ~123 dirt
setblock ~187 ~119 ~124 dirt
setblock ~187 ~120 ~81 dirt
setblock ~187 ~120 ~82 dirt
setblock ~187 ~120 ~83 dirt
setblock ~187 ~120 ~84 dirt
setblock ~187 ~120 ~85 dirt
setblock ~187 ~120 ~86 dirt
setblock ~187 ~120 ~87 dirt
setblock ~187 ~120 ~88 dirt
setblock ~187 ~120 ~89 dirt
setblock ~187 ~120 ~90 dirt
setblock ~187 ~120 ~91 dirt
setblock ~187 ~120 ~92 dirt
setblock ~187 ~120 ~93 dirt
setblock ~187 ~120 ~94 dirt
setblock ~187 ~120 ~95 dirt
setblock ~187 ~120 ~96 dirt
setblock ~187 ~120 ~97 dirt
setblock ~187 ~120 ~98 dirt
setblock ~187 ~120 ~111 dirt
setblock ~187 ~120 ~112 dirt
setblock ~187 ~120 ~113 dirt
setblock ~187 ~120 ~114 dirt
setblock ~187 ~120 ~115 dirt
setblock ~187 ~120 ~116 dirt
setblock ~187 ~120 ~117 dirt
setblock ~187 ~120 ~118 dirt
setblock ~187 ~120 ~119 dirt
setblock ~187 ~120 ~120 dirt
setblock ~187 ~120 ~121 dirt
setblock ~187 ~120 ~122 dirt
setblock ~187 ~120 ~123 dirt
setblock ~187 ~120 ~124 dirt
setblock ~187 ~120 ~125 dirt
setblock ~187 ~121 ~80 dirt
setblock ~187 ~121 ~81 dirt
setblock ~187 ~121 ~82 dirt
setblock ~187 ~121 ~83 dirt
setblock ~187 ~121 ~84 dirt
setblock ~187 ~121 ~85 dirt
setblock ~187 ~121 ~86 dirt
setblock ~187 ~121 ~87 dirt
setblock ~187 ~121 ~88 dirt
setblock ~187 ~121 ~89 dirt
setblock ~187 ~121 ~90 dirt
setblock ~187 ~121 ~91 dirt
setblock ~187 ~121 ~92 dirt
setblock ~187 ~121 ~93 dirt
setblock ~187 ~121 ~94 dirt
setblock ~187 ~121 ~95 dirt
setblock ~187 ~121 ~96 dirt
setblock ~187 ~121 ~97 dirt
setblock ~187 ~121 ~98 dirt
setblock ~187 ~121 ~99 dirt
setblock ~187 ~121 ~110 dirt
setblock ~187 ~121 ~111 dirt
setblock ~187 ~121 ~112 dirt
setblock ~187 ~121 ~113 dirt
setblock ~187 ~121 ~114 dirt
setblock ~187 ~121 ~115 dirt
setblock ~187 ~121 ~116 dirt
setblock ~187 ~121 ~117 dirt
setblock ~187 ~121 ~118 dirt
setblock ~187 ~121 ~119 dirt
setblock ~187 ~121 ~120 dirt
setblock ~187 ~121 ~121 dirt
setblock ~187 ~121 ~122 dirt
setblock ~187 ~121 ~123 dirt
setblock ~187 ~121 ~124 dirt
setblock ~187 ~121 ~125 dirt
setblock ~187 ~121 ~126 dirt
setblock ~187 ~122 ~80 dirt
setblock ~187 ~122 ~81 dirt
setblock ~187 ~122 ~82 dirt
setblock ~187 ~122 ~83 dirt
setblock ~187 ~122 ~84 dirt
setblock ~187 ~122 ~85 dirt
setblock ~187 ~122 ~86 dirt
setblock ~187 ~122 ~87 dirt
setblock ~187 ~122 ~88 dirt
setblock ~187 ~122 ~89 dirt
setblock ~187 ~122 ~90 grass_block
setblock ~187 ~122 ~91 dirt
setblock ~187 ~122 ~92 dirt
setblock ~187 ~122 ~93 dirt
setblock ~187 ~122 ~94 dirt
setblock ~187 ~122 ~95 dirt
setblock ~187 ~122 ~96 dirt
setblock ~187 ~122 ~97 dirt
setblock ~187 ~122 ~98 dirt
setblock ~187 ~122 ~99 dirt
setblock ~187 ~122 ~110 dirt
setblock ~187 ~122 ~111 dirt
setblock ~187 ~122 ~112 dirt
setblock ~187 ~122 ~113 dirt
setblock ~187 ~122 ~114 dirt
setblock ~187 ~122 ~115 dirt
setblock ~187 ~122 ~116 dirt
setblock ~187 ~122 ~117 dirt
setblock ~187 ~122 ~118 dirt
setblock ~187 ~122 ~119 dirt
setblock ~187 ~122 ~120 dirt
setblock ~187 ~122 ~121 dirt
setblock ~187 ~122 ~122 dirt
setblock ~187 ~122 ~123 dirt
setblock ~187 ~122 ~124 dirt
setblock ~187 ~122 ~125 dirt
setblock ~187 ~122 ~126 dirt
setblock ~187 ~123 ~80 dirt
setblock ~187 ~123 ~81 dirt
setblock ~187 ~123 ~82 dirt
setblock ~187 ~123 ~83 dirt
setblock ~187 ~123 ~84 dirt
setblock ~187 ~123 ~85 dirt
setblock ~187 ~123 ~86 grass_block
setblock ~187 ~123 ~87 grass_block
setblock ~187 ~123 ~88 grass_block
setblock ~187 ~123 ~89 grass_block
setblock ~187 ~123 ~91 grass_block
setblock ~187 ~123 ~92 grass_block
setblock ~187 ~123 ~93 grass_block
setblock ~187 ~123 ~94 grass_block
setblock ~187 ~123 ~95 dirt
setblock ~187 ~123 ~96 dirt
setblock ~187 ~123 ~97 dirt
setblock ~187 ~123 ~98 dirt
setblock ~187 ~123 ~99 dirt
setblock ~187 ~123 ~110 dirt
setblock ~187 ~123 ~111 dirt
setblock ~187 ~123 ~112 dirt
setblock ~187 ~123 ~113 dirt
setblock ~187 ~123 ~114 dirt
setblock ~187 ~123 ~115 dirt
setblock ~187 ~123 ~116 dirt
setblock ~187 ~123 ~117 dirt
setblock ~187 ~123 ~118 dirt
setblock ~187 ~123 ~119 dirt
setblock ~187 ~123 ~120 dirt
setblock ~187 ~123 ~121 dirt
setblock ~187 ~123 ~122 dirt
setblock ~187 ~123 ~123 dirt
setblock ~187 ~123 ~124 dirt
setblock ~187 ~123 ~125 dirt
setblock ~187 ~123 ~126 dirt
setblock ~187 ~124 ~80 dirt
setblock ~187 ~124 ~81 dirt
setblock ~187 ~124 ~82 dirt
setblock ~187 ~124 ~83 grass_block
setblock ~187 ~124 ~84 grass_block
setblock ~187 ~124 ~85 grass_block
setblock ~187 ~124 ~89 short_grass
setblock ~187 ~124 ~93 short_grass
setblock ~187 ~124 ~95 grass_block
setblock ~187 ~124 ~96 grass_block
setblock ~187 ~124 ~97 grass_block
setblock ~187 ~124 ~98 dirt
setblock ~187 ~124 ~99 dirt
setblock ~187 ~124 ~110 grass_block
setblock ~187 ~124 ~111 grass_block
setblock ~187 ~124 ~112 grass_block
setblock ~187 ~124 ~113 dirt
setblock ~187 ~124 ~114 dirt
setblock ~187 ~124 ~115 dirt
setblock ~187 ~124 ~116 dirt
setblock ~187 ~124 ~117 dirt
setblock ~187 ~124 ~118 dirt
setblock ~187 ~124 ~119 dirt
setblock ~187 ~124 ~120 dirt
setblock ~187 ~124 ~121 dirt
setblock ~187 ~124 ~122 dirt
setblock ~187 ~124 ~123 dirt
setblock ~187 ~124 ~124 dirt
setblock ~187 ~124 ~125 dirt
setblock ~187 ~124 ~126 grass_block
setblock ~187 ~125 ~80 dirt
setblock ~187 ~125 ~81 grass_block
setblock ~187 ~125 ~82 grass_block
setblock ~187 ~125 ~85 fern
setblock ~187 ~125 ~96 short_grass
setblock ~187 ~125 ~98 grass_block
setblock ~187 ~125 ~99 grass_block
setblock ~187 ~125 ~110 short_grass
setblock ~187 ~125 ~113 grass_block
setblock ~187 ~125 ~114 grass_block
setblock ~187 ~125 ~115 grass_block
setblock ~187 ~125 ~116 grass_block
setblock ~187 ~125 ~117 grass_block
setblock ~187 ~125 ~118 grass_block
setblock ~187 ~125 ~119 grass_block
setblock ~187 ~125 ~120 grass_block
setblock ~187 ~125 ~121 grass_block
setblock ~187 ~125 ~122 grass_block
setblock ~187 ~125 ~123 grass_block
setblock ~187 ~125 ~124 grass_block
setblock ~187 ~125 ~125 grass_block
setblock ~187 ~125 ~126 short_grass
setblock ~187 ~126 ~80 grass_block
setblock ~187 ~126 ~81 short_grass
setblock ~187 ~126 ~82 short_grass
setblock ~187 ~126 ~121 poppy
setblock ~188 ~114 ~90 dirt
setblock ~188 ~114 ~91 dirt
setblock ~188 ~115 ~89 dirt
setblock ~188 ~115 ~90 dirt
setblock ~188 ~115 ~91 dirt
setblock ~188 ~115 ~92 dirt
setblock ~188 ~116 ~88 dirt
setblock ~188 ~116 ~89 dirt
setblock ~188 ~116 ~90 dirt
setblock ~188 ~116 ~91 dirt
setblock ~188 ~116 ~92 dirt
setblock ~188 ~116 ~93 dirt
setblock ~188 ~116 ~115 dirt
setblock ~188 ~117 ~86 dirt
setblock ~188 ~117 ~87 dirt
setblock ~188 ~117 ~88 dirt
setblock ~188 ~117 ~89 dirt
setblock ~188 ~117 ~90 dirt
setblock ~188 ~117 ~91 dirt
setblock ~188 ~117 ~92 dirt
setblock ~188 ~117 ~93 dirt
setblock ~188 ~117 ~94 dirt
setblock ~188 ~117 ~114 dirt
setblock ~188 ~117 ~115 dirt
setblock ~188 ~117 ~116 dirt
setblock ~188 ~117 ~117 dirt
setblock ~188 ~117 ~118 dirt
setblock ~188 ~117 ~119 dirt
setblock ~188 ~117 ~120 dirt
setblock ~188 ~118 ~85 dirt
setblock ~188 ~118 ~86 dirt
setblock ~188 ~118 ~87 dirt
setblock ~188 ~118 ~88 dirt
setblock ~188 ~118 ~89 dirt
setblock ~188 ~118 ~90 dirt
setblock ~188 ~118 ~91 dirt
setblock ~188 ~118 ~92 dirt
setblock ~188 ~118 ~93 dirt
setblock ~188 ~118 ~94 dirt
setblock ~188 ~118 ~95 dirt
setblock ~188 ~118 ~113 dirt
setblock ~188 ~118 ~114 dirt
setblock ~188 ~118 ~115 dirt
setblock ~188 ~118 ~116 dirt
setblock ~188 ~118 ~117 dirt
setblock ~188 ~118 ~118 dirt
setblock ~188 ~118 ~119 dirt
setblock ~188 ~118 ~120 dirt
setblock ~188 ~118 ~121 dirt
setblock ~188 ~119 ~83 dirt
setblock ~188 ~119 ~84 dirt
setblock ~188 ~119 ~85 dirt
setblock ~188 ~119 ~86 dirt
setblock ~188 ~119 ~87 dirt
setblock ~188 ~119 ~88 dirt
setblock ~188 ~119 ~89 dirt
setblock ~188 ~119 ~90 dirt
setblock ~188 ~119 ~91 dirt
setblock ~188 ~119 ~92 dirt
setblock ~188 ~119 ~93 dirt
setblock ~188 ~119 ~94 dirt
setblock ~188 ~119 ~95 dirt
setblock ~188 ~119 ~96 dirt
setblock ~188 ~119 ~112 dirt
setblock ~188 ~119 ~113 dirt
setblock ~188 ~119 ~114 dirt
setblock ~188 ~119 ~115 dirt
setblock ~188 ~119 ~116 dirt
setblock ~188 ~119 ~117 dirt
setblock ~188 ~119 ~118 dirt
setblock ~188 ~119 ~119 dirt
setblock ~188 ~119 ~120 dirt
setblock ~188 ~119 ~121 dirt
setblock ~188 ~119 ~122 dirt
setblock ~188 ~119 ~123 dirt
setblock ~188 ~120 ~82 dirt
setblock ~188 ~120 ~83 dirt
setblock ~188 ~120 ~84 dirt
setblock ~188 ~120 ~85 dirt
setblock ~188 ~120 ~86 dirt
setblock ~188 ~120 ~87 dirt
setblock ~188 ~120 ~88 dirt
setblock ~188 ~120 ~89 dirt
setblock ~188 ~120 ~90 dirt
setblock ~188 ~120 ~91 dirt
setblock ~188 ~120 ~92 dirt
setblock ~188 ~120 ~93 dirt
setblock ~188 ~120 ~94 dirt
setblock ~188 ~120 ~95 dirt
setblock ~188 ~120 ~96 dirt
setblock ~188 ~120 ~97 dirt
setblock ~188 ~120 ~111 dirt
setblock ~188 ~120 ~112 dirt
setblock ~188 ~120 ~113 dirt
setblock ~188 ~120 ~114 dirt
setblock ~188 ~120 ~115 dirt
setblock ~188 ~120 ~116 dirt
setblock ~188 ~120 ~117 dirt
setblock ~188 ~120 ~118 dirt
setblock ~188 ~120 ~119 dirt
setblock ~188 ~120 ~120 dirt
setblock ~188 ~120 ~121 dirt
setblock ~188 ~120 ~122 dirt
setblock ~188 ~120 ~123 dirt
setblock ~188 ~120 ~124 dirt
setblock ~188 ~121 ~81 dirt
setblock ~188 ~121 ~82 dirt
setblock ~188 ~121 ~83 dirt
setblock ~188 ~121 ~84 dirt
setblock ~188 ~121 ~85 dirt
setblock ~188 ~121 ~86 dirt
setblock ~188 ~121 ~87 dirt
setblock ~188 ~121 ~88 dirt
setblock ~188 ~121 ~89 dirt
setblock ~188 ~121 ~90 dirt
setblock ~188 ~121 ~91 dirt
setblock ~188 ~121 ~92 dirt
setblock ~188 ~121 ~93 dirt
setblock ~188 ~121 ~94 dirt
setblock ~188 ~121 ~95 dirt
setblock ~188 ~121 ~96 dirt
setblock ~188 ~121 ~97 dirt
setblock ~188 ~121 ~98 dirt
setblock ~188 ~121 ~110 dirt
setblock ~188 ~121 ~111 dirt
setblock ~188 ~121 ~112 dirt
setblock ~188 ~121 ~113 dirt
setblock ~188 ~121 ~114 dirt
setblock ~188 ~121 ~115 dirt
setblock ~188 ~121 ~116 dirt
setblock ~188 ~121 ~117 dirt
setblock ~188 ~121 ~118 dirt
setblock ~188 ~121 ~119 dirt
setblock ~188 ~121 ~120 dirt
setblock ~188 ~121 ~121 dirt
setblock ~188 ~121 ~122 dirt
setblock ~188 ~121 ~123 dirt
setblock ~188 ~121 ~124 dirt
setblock ~188 ~121 ~125 dirt
setblock ~188 ~122 ~81 dirt
setblock ~188 ~122 ~82 dirt
setblock ~188 ~122 ~83 dirt
setblock ~188 ~122 ~84 dirt
setblock ~188 ~122 ~85 dirt
setblock ~188 ~122 ~86 dirt
setblock ~188 ~122 ~87 dirt
setblock ~188 ~122 ~88 dirt
setblock ~188 ~122 ~89 dirt
setblock ~188 ~122 ~90 grass_block
setblock ~188 ~122 ~91 dirt
setblock ~188 ~122 ~92 dirt
setblock ~188 ~122 ~93 dirt
setblock ~188 ~122 ~94 dirt
setblock ~188 ~122 ~95 dirt
setblock ~188 ~122 ~96 dirt
setblock ~188 ~122 ~97 dirt
setblock ~188 ~122 ~98 dirt
setblock ~188 ~122 ~110 dirt
setblock ~188 ~122 ~111 dirt
setblock ~188 ~122 ~112 dirt
setblock ~188 ~122 ~113 dirt
setblock ~188 ~122 ~114 dirt
setblock ~188 ~122 ~115 dirt
setblock ~188 ~122 ~116 dirt
setblock ~188 ~122 ~117 dirt
setblock ~188 ~122 ~118 dirt
setblock ~188 ~122 ~119 dirt
setblock ~188 ~122 ~120 dirt
setblock ~188 ~122 ~121 dirt
setblock ~188 ~122 ~122 dirt
setblock ~188 ~122 ~123 dirt
setblock ~188 ~122 ~124 dirt
setblock ~188 ~122 ~125 dirt
setblock ~188 ~123 ~81 dirt
setblock ~188 ~123 ~82 dirt
setblock ~188 ~123 ~83 dirt
setblock ~188 ~123 ~84 dirt
setblock ~188 ~123 ~85 dirt
setblock ~188 ~123 ~86 dirt
setblock ~188 ~123 ~87 grass_block
setblock ~188 ~123 ~88 grass_block
setblock ~188 ~123 ~89 grass_block
setblock ~188 ~123 ~91 grass_block
setblock ~188 ~123 ~92 grass_block
setblock ~188 ~123 ~93 grass_block
setblock ~188 ~123 ~94 dirt
setblock ~188 ~123 ~95 dirt
setblock ~188 ~123 ~96 dirt
setblock ~188 ~123 ~97 dirt
setblock ~188 ~123 ~98 dirt
setblock ~188 ~123 ~110 dirt
setblock ~188 ~123 ~111 dirt
setblock ~188 ~123 ~112 dirt
setblock ~188 ~123 ~113 dirt
setblock ~188 ~123 ~114 dirt
setblock ~188 ~123 ~115 dirt
setblock ~188 ~123 ~116 dirt
setblock ~188 ~123 ~117 dirt
setblock ~188 ~123 ~118 dirt
setblock ~188 ~123 ~119 dirt
setblock ~188 ~123 ~120 dirt
setblock ~188 ~123 ~121 dirt
setblock ~188 ~123 ~122 dirt
setblock ~188 ~123 ~123 dirt
setblock ~188 ~123 ~124 dirt
setblock ~188 ~123 ~125 dirt
setblock ~188 ~124 ~81 dirt
setblock ~188 ~124 ~82 dirt
setblock ~188 ~124 ~83 dirt
setblock ~188 ~124 ~84 grass_block
setblock ~188 ~124 ~85 grass_block
setblock ~188 ~124 ~86 grass_block
setblock ~188 ~124 ~87 short_grass
setblock ~188 ~124 ~91 short_grass
setblock ~188 ~124 ~92 short_grass
setblock ~188 ~124 ~94 grass_block
setblock ~188 ~124 ~95 grass_block
setblock ~188 ~124 ~96 grass_block
setblock ~188 ~124 ~97 dirt
setblock ~188 ~124 ~98 dirt
setblock ~188 ~124 ~110 grass_block
setblock ~188 ~124 ~111 grass_block
setblock ~188 ~124 ~112 dirt
setblock ~188 ~124 ~113 dirt
setblock ~188 ~124 ~114 dirt
setblock ~188 ~124 ~115 dirt
setblock ~188 ~124 ~116 dirt
setblock ~188 ~124 ~117 dirt
setblock ~188 ~124 ~118 dirt
setblock ~188 ~124 ~119 dirt
setblock ~188 ~124 ~120 dirt
setblock ~188 ~124 ~121 dirt
setblock ~188 ~124 ~122 dirt
setblock ~188 ~124 ~123 dirt
setblock ~188 ~124 ~124 dirt
setblock ~188 ~124 ~125 dirt
setblock ~188 ~125 ~81 grass_block
setblock ~188 ~125 ~82 grass_block
setblock ~188 ~125 ~83 grass_block
setblock ~188 ~125 ~96 short_grass
setblock ~188 ~125 ~97 grass_block
setblock ~188 ~125 ~98 grass_block
setblock ~188 ~125 ~112 grass_block
setblock ~188 ~125 ~113 grass_block
setblock ~188 ~125 ~114 grass_block
setblock ~188 ~125 ~115 grass_block
setblock ~188 ~125 ~116 grass_block
setblock ~188 ~125 ~117 grass_block
setblock ~188 ~125 ~118 grass_block
setblock ~188 ~125 ~119 grass_block
setblock ~188 ~125 ~120 grass_block
setblock ~188 ~125 ~121 grass_block
setblock ~188 ~125 ~122 grass_block
setblock ~188 ~125 ~123 grass_block
setblock ~188 ~125 ~124 grass_block
setblock ~188 ~125 ~125 grass_block
setblock ~188 ~126 ~81 poppy
setblock ~188 ~126 ~82 fern
setblock ~188 ~126 ~98 short_grass
setblock ~188 ~126 ~118 short_grass
setblock ~188 ~126 ~121 short_grass
setblock ~189 ~115 ~89 dirt
setblock ~189 ~116 ~89 dirt
setblock ~189 ~116 ~90 dirt
setblock ~189 ~116 ~91 dirt
setblock ~189 ~116 ~92 dirt
setblock ~189 ~117 ~88 dirt
setblock ~189 ~117 ~89 dirt
setblock ~189 ~117 ~90 dirt
setblock ~189 ~117 ~91 dirt
setblock ~189 ~117 ~92 dirt
setblock ~189 ~117 ~93 dirt
setblock ~189 ~117 ~115 dirt
setblock ~189 ~118 ~86 dirt
setblock ~189 ~118 ~87 dirt
setblock ~189 ~118 ~88 dirt
setblock ~189 ~118 ~89 dirt
setblock ~189 ~118 ~90 dirt
setblock ~189 ~118 ~91 dirt
setblock ~189 ~118 ~92 dirt
setblock ~189 ~118 ~93 dirt
setblock ~189 ~118 ~94 dirt
setblock ~189 ~118 ~114 dirt
setblock ~189 ~118 ~115 dirt
setblock ~189 ~118 ~117 dirt
setblock ~189 ~118 ~119 dirt
setblock ~189 ~119 ~85 dirt
setblock ~189 ~119 ~86 dirt
setblock ~189 ~119 ~87 dirt
setblock ~189 ~119 ~88 dirt
setblock ~189 ~119 ~89 dirt
setblock ~189 ~119 ~90 dirt
setblock ~189 ~119 ~91 dirt
setblock ~189 ~119 ~92 dirt
setblock ~189 ~119 ~93 dirt
setblock ~189 ~119 ~94 dirt
setblock ~189 ~119 ~95 dirt
setblock ~189 ~119 ~113 dirt
setblock ~189 ~119 ~114 dirt
setblock ~189 ~119 ~115 dirt
setblock ~189 ~119 ~116 dirt
setblock ~189 ~119 ~117 dirt
setblock ~189 ~119 ~118 dirt
setblock ~189 ~119 ~119 dirt
setblock ~189 ~119 ~120 dirt
setblock ~189 ~119 ~121 dirt
setblock ~189 ~120 ~83 dirt
setblock ~189 ~120 ~84 dirt
setblock ~189 ~120 ~85 dirt
setblock ~189 ~120 ~86 dirt
setblock ~189 ~120 ~87 dirt
setblock ~189 ~120 ~88 dirt
setblock ~189 ~120 ~89 dirt
setblock ~189 ~120 ~90 dirt
setblock ~189 ~120 ~91 dirt
setblock ~189 ~120 ~92 dirt
setblock ~189 ~120 ~93 dirt
setblock ~189 ~120 ~94 dirt
setblock ~189 ~120 ~95 dirt
setblock ~189 ~120 ~96 dirt
setblock ~189 ~120 ~112 dirt
setblock ~189 ~120 ~113 dirt
setblock ~189 ~120 ~114 dirt
setblock ~189 ~120 ~115 dirt
setblock ~189 ~120 ~116 dirt
setblock ~189 ~120 ~117 dirt
setblock ~189 ~120 ~118 dirt
setblock ~189 ~120 ~119 dirt
setblock ~189 ~120 ~120 dirt
setblock ~189 ~120 ~121 dirt
setblock ~189 ~120 ~122 dirt
setblock ~189 ~120 ~123 dirt
setblock ~189 ~121 ~83 dirt
setblock ~189 ~121 ~84 dirt
setblock ~189 ~121 ~85 dirt
setblock ~189 ~121 ~86 dirt
setblock ~189 ~121 ~87 dirt
setblock ~189 ~121 ~88 dirt
setblock ~189 ~121 ~89 dirt
setblock ~189 ~121 ~90 dirt
setblock ~189 ~121 ~91 dirt
setblock ~189 ~121 ~92 dirt
setblock ~189 ~121 ~93 dirt
setblock ~189 ~121 ~94 dirt
setblock ~189 ~121 ~95 dirt
setblock ~189 ~121 ~96 dirt
setblock ~189 ~121 ~97 dirt
setblock ~189 ~121 ~111 dirt
setblock ~189 ~121 ~112 dirt
setblock ~189 ~121 ~113 dirt
setblock ~189 ~121 ~114 dirt
setblock ~189 ~121 ~115 dirt
setblock ~189 ~121 ~116 dirt
setblock ~189 ~121 ~117 dirt
setblock ~189 ~121 ~118 dirt
setblock ~189 ~121 ~119 dirt
setblock ~189 ~121 ~120 dirt
setblock ~189 ~121 ~121 dirt
setblock ~189 ~121 ~122 dirt
setblock ~189 ~121 ~123 dirt
setblock ~189 ~121 ~124 dirt
setblock ~189 ~122 ~83 dirt
setblock ~189 ~122 ~84 dirt
setblock ~189 ~122 ~85 dirt
setblock ~189 ~122 ~86 dirt
setblock ~189 ~122 ~87 dirt
setblock ~189 ~122 ~88 dirt
setblock ~189 ~122 ~89 dirt
setblock ~189 ~122 ~90 dirt
setblock ~189 ~122 ~91 dirt
setblock ~189 ~122 ~92 dirt
setblock ~189 ~122 ~93 dirt
setblock ~189 ~122 ~94 dirt
setblock ~189 ~122 ~95 dirt
setblock ~189 ~122 ~96 dirt
setblock ~189 ~122 ~97 dirt
setblock ~189 ~122 ~111 dirt
setblock ~189 ~122 ~112 dirt
setblock ~189 ~122 ~113 dirt
setblock ~189 ~122 ~114 dirt
setblock ~189 ~122 ~115 dirt
setblock ~189 ~122 ~116 dirt
setblock ~189 ~122 ~117 dirt
setblock ~189 ~122 ~118 dirt
setblock ~189 ~122 ~119 dirt
setblock ~189 ~122 ~120 dirt
setblock ~189 ~122 ~121 dirt
setblock ~189 ~122 ~122 dirt
setblock ~189 ~122 ~123 dirt
setblock ~189 ~122 ~124 dirt
setblock ~189 ~123 ~83 dirt
setblock ~189 ~123 ~84 dirt
setblock ~189 ~123 ~85 dirt
setblock ~189 ~123 ~86 dirt
setblock ~189 ~123 ~87 grass_block
setblock ~189 ~123 ~88 grass_block
setblock ~189 ~123 ~89 grass_block
setblock ~189 ~123 ~90 grass_block
setblock ~189 ~123 ~91 grass_block
setblock ~189 ~123 ~92 grass_block
setblock ~189 ~123 ~93 grass_block
setblock ~189 ~123 ~94 dirt
setblock ~189 ~123 ~95 dirt
setblock ~189 ~123 ~96 dirt
setblock ~189 ~123 ~97 dirt
setblock ~189 ~123 ~111 dirt
setblock ~189 ~123 ~112 dirt
setblock ~189 ~123 ~113 dirt
setblock ~189 ~123 ~114 dirt
setblock ~189 ~123 ~115 dirt
setblock ~189 ~123 ~116 dirt
setblock ~189 ~123 ~117 dirt
setblock ~189 ~123 ~118 dirt
setblock ~189 ~123 ~119 dirt
setblock ~189 ~123 ~120 dirt
setblock ~189 ~123 ~121 dirt
setblock ~189 ~123 ~122 dirt
setblock ~189 ~123 ~123 dirt
setblock ~189 ~123 ~124 dirt
setblock ~189 ~124 ~83 dirt
setblock ~189 ~124 ~84 dirt
setblock ~189 ~124 ~85 grass_block
setblock ~189 ~124 ~86 grass_block
setblock ~189 ~124 ~88 poppy
setblock ~189 ~124 ~93 short_grass
setblock ~189 ~124 ~94 grass_block
setblock ~189 ~124 ~95 grass_block
setblock ~189 ~124 ~96 grass_block
setblock ~189 ~124 ~97 dirt
setblock ~189 ~124 ~111 dirt
setblock ~189 ~124 ~112 dirt
setblock ~189 ~124 ~113 dirt
setblock ~189 ~124 ~114 dirt
setblock ~189 ~124 ~115 dirt
setblock ~189 ~124 ~116 dirt
setblock ~189 ~124 ~117 dirt
setblock ~189 ~124 ~118 dirt
setblock ~189 ~124 ~119 dirt
setblock ~189 ~124 ~120 dirt
setblock ~189 ~124 ~121 dirt
setblock ~189 ~124 ~122 dirt
setblock ~189 ~124 ~123 dirt
setblock ~189 ~124 ~124 dirt
setblock ~189 ~125 ~83 grass_block
setblock ~189 ~125 ~84 grass_block
setblock ~189 ~125 ~85 short_grass
setblock ~189 ~125 ~97 grass_block
setblock ~189 ~125 ~111 grass_block
setblock ~189 ~125 ~112 grass_block
setblock ~189 ~125 ~113 grass_block
setblock ~189 ~125 ~114 grass_block
setblock ~189 ~125 ~115 grass_block
setblock ~189 ~125 ~116 grass_block
setblock ~189 ~125 ~117 grass_block
setblock ~189 ~125 ~118 grass_block
setblock ~189 ~125 ~119 grass_block
setblock ~189 ~125 ~120 grass_block
setblock ~189 ~125 ~121 grass_block
setblock ~189 ~125 ~122 grass_block
setblock ~189 ~125 ~123 grass_block
setblock ~189 ~125 ~124 grass_block
setblock ~189 ~126 ~83 fern
setblock ~189 ~126 ~111 short_grass
setblock ~189 ~126 ~114 fern
setblock ~189 ~126 ~115 short_grass
setblock ~189 ~126 ~116 short_grass
setblock ~190 ~117 ~89 dirt
setblock ~190 ~117 ~91 dirt
setblock ~190 ~117 ~92 dirt
setblock ~190 ~118 ~88 dirt
setblock ~190 ~118 ~89 dirt
setblock ~190 ~118 ~90 dirt
setblock ~190 ~118 ~91 dirt
setblock ~190 ~118 ~92 dirt
setblock ~190 ~118 ~93 dirt
setblock ~190 ~119 ~87 dirt
setblock ~190 ~119 ~88 dirt
setblock ~190 ~119 ~89 dirt
setblock ~190 ~119 ~90 dirt
setblock ~190 ~119 ~91 dirt
setblock ~190 ~119 ~92 dirt
setblock ~190 ~119 ~93 dirt
setblock ~190 ~119 ~94 dirt
setblock ~190 ~119 ~115 dirt
setblock ~190 ~119 ~117 dirt
setblock ~190 ~120 ~85 dirt
setblock ~190 ~120 ~86 dirt
setblock ~190 ~120 ~87 dirt
setblock ~190 ~120 ~88 dirt
setblock ~190 ~120 ~89 dirt
setblock ~190 ~120 ~90 dirt
setblock ~190 ~120 ~91 dirt
setblock ~190 ~120 ~92 dirt
setblock ~190 ~120 ~93 dirt
setblock ~190 ~120 ~94 dirt
setblock ~190 ~120 ~95 dirt
setblock ~190 ~120 ~113 dirt
setblock ~190 ~120 ~114 dirt
setblock ~190 ~120 ~115 dirt
setblock ~190 ~120 ~116 dirt
setblock ~190 ~120 ~117 dirt
setblock ~190 ~120 ~118 dirt
setblock ~190 ~120 ~119 dirt
setblock ~190 ~120 ~120 dirt
setblock ~190 ~120 ~121 dirt
setblock ~190 ~121 ~84 dirt
setblock ~190 ~121 ~85 dirt
setblock ~190 ~121 ~86 dirt
setblock ~190 ~121 ~87 dirt
setblock ~190 ~121 ~88 dirt
setblock ~190 ~121 ~89 dirt
setblock ~190 ~121 ~90 dirt
setblock ~190 ~121 ~91 dirt
setblock ~190 ~121 ~92 dirt
setblock ~190 ~121 ~93 dirt
setblock ~190 ~121 ~94 dirt
setblock ~190 ~121 ~95 dirt
setblock ~190 ~121 ~96 dirt
setblock ~190 ~121 ~112 dirt
setblock ~190 ~121 ~113 dirt
setblock ~190 ~121 ~114 dirt
setblock ~190 ~121 ~115 dirt
setblock ~190 ~121 ~116 dirt
setblock ~190 ~121 ~117 dirt
setblock ~190 ~121 ~118 dirt
setblock ~190 ~121 ~119 dirt
setblock ~190 ~121 ~120 dirt
setblock ~190 ~121 ~121 dirt
setblock ~190 ~121 ~122 dirt
setblock ~190 ~121 ~123 dirt
setblock ~190 ~122 ~84 dirt
setblock ~190 ~122 ~85 dirt
setblock ~190 ~122 ~86 dirt
setblock ~190 ~122 ~87 dirt
setblock ~190 ~122 ~88 dirt
setblock ~190 ~122 ~89 dirt
setblock ~190 ~122 ~90 dirt
setblock ~190 ~122 ~91 dirt
setblock ~190 ~122 ~92 dirt
setblock ~190 ~122 ~93 dirt
setblock ~190 ~122 ~94 dirt
setblock ~190 ~122 ~95 dirt
setblock ~190 ~122 ~96 dirt
setblock ~190 ~122 ~112 dirt
setblock ~190 ~122 ~113 dirt
setblock ~190 ~122 ~114 dirt
setblock ~190 ~122 ~115 dirt
setblock ~190 ~122 ~116 dirt
setblock ~190 ~122 ~117 dirt
setblock ~190 ~122 ~118 dirt
setblock ~190 ~122 ~119 dirt
setblock ~190 ~122 ~120 dirt
setblock ~190 ~122 ~121 dirt
setblock ~190 ~122 ~122 dirt
setblock ~190 ~122 ~123 dirt
setblock ~190 ~123 ~84 dirt
setblock ~190 ~123 ~85 dirt
setblock ~190 ~123 ~86 dirt
setblock ~190 ~123 ~87 dirt
setblock ~190 ~123 ~88 grass_block
setblock ~190 ~123 ~89 grass_block
setblock ~190 ~123 ~90 grass_block
setblock ~190 ~123 ~91 grass_block
setblock ~190 ~123 ~92 grass_block
setblock ~190 ~123 ~93 dirt
setblock ~190 ~123 ~94 dirt
setblock ~190 ~123 ~95 dirt
setblock ~190 ~123 ~96 dirt
setblock ~190 ~123 ~112 dirt
setblock ~190 ~123 ~113 dirt
setblock ~190 ~123 ~114 dirt
setblock ~190 ~123 ~115 dirt
setblock ~190 ~123 ~116 dirt
setblock ~190 ~123 ~117 dirt
setblock ~190 ~123 ~118 dirt
setblock ~190 ~123 ~119 dirt
setblock ~190 ~123 ~120 dirt
setblock ~190 ~123 ~121 dirt
setblock ~190 ~123 ~122 dirt
setblock ~190 ~123 ~123 dirt
setblock ~190 ~124 ~84 dirt
setblock ~190 ~124 ~85 grass_block
setblock ~190 ~124 ~86 grass_block
setblock ~190 ~124 ~87 grass_block
setblock ~190 ~124 ~89 short_grass
setblock ~190 ~124 ~90 short_grass
setblock ~190 ~124 ~91 short_grass
setblock ~190 ~124 ~93 grass_block
setblock ~190 ~124 ~94 grass_block
setblock ~190 ~124 ~95 grass_block
setblock ~190 ~124 ~96 grass_block
setblock ~190 ~124 ~112 dirt
setblock ~190 ~124 ~113 dirt
setblock ~190 ~124 ~114 dirt
setblock ~190 ~124 ~115 dirt
setblock ~190 ~124 ~116 dirt
setblock ~190 ~124 ~117 dirt
setblock ~190 ~124 ~118 dirt
setblock ~190 ~124 ~119 dirt
setblock ~190 ~124 ~120 dirt
setblock ~190 ~124 ~121 dirt
setblock ~190 ~124 ~122 dirt
setblock ~190 ~124 ~123 dirt
setblock ~190 ~125 ~84 grass_block
setblock ~190 ~125 ~86 short_grass
setblock ~190 ~125 ~93 short_grass
setblock ~190 ~125 ~112 grass_block
setblock ~190 ~125 ~113 grass_block
setblock ~190 ~125 ~114 grass_block
setblock ~190 ~125 ~115 grass_block
setblock ~190 ~125 ~116 grass_block
setblock ~190 ~125 ~117 dirt
setblock ~190 ~125 ~118 dirt
setblock ~190 ~125 ~119 dirt
setblock ~190 ~125 ~120 dirt
setblock ~190 ~125 ~121 grass_block
setblock ~190 ~125 ~122 grass_block
setblock ~190 ~125 ~123 grass_block
setblock ~190 ~126 ~84 short_grass
setblock ~190 ~126 ~112 short_grass
setblock ~190 ~126 ~116 short_grass
setblock ~190 ~126 ~117 grass_block
setblock ~190 ~126 ~118 grass_block
setblock ~190 ~126 ~119 grass_block
setblock ~190 ~126 ~120 grass_block
setblock ~190 ~127 ~119 short_grass
setblock ~190 ~127 ~120 fern
setblock ~191 ~118 ~89 dirt
setblock ~191 ~118 ~92 dirt
setblock ~191 ~119 ~88 dirt
setblock ~191 ~119 ~89 dirt
setblock ~191 ~119 ~90 dirt
setblock ~191 ~119 ~91 dirt
setblock ~191 ~119 ~92 dirt
setblock ~191 ~119 ~93 dirt
setblock ~191 ~120 ~87 dirt
setblock ~191 ~120 ~88 dirt
setblock ~191 ~120 ~89 dirt
setblock ~191 ~120 ~90 dirt
setblock ~191 ~120 ~91 dirt
setblock ~191 ~120 ~92 dirt
setblock ~191 ~120 ~93 dirt
setblock ~191 ~120 ~94 dirt
setblock ~191 ~121 ~86 dirt
setblock ~191 ~121 ~87 dirt
setblock ~191 ~121 ~88 dirt
setblock ~191 ~121 ~89 dirt
setblock ~191 ~121 ~90 dirt
setblock ~191 ~121 ~91 dirt
setblock ~191 ~121 ~92 dirt
setblock ~191 ~121 ~93 dirt
setblock ~191 ~121 ~94 dirt
setblock ~191 ~121 ~95 dirt
setblock ~191 ~121 ~113 dirt
setblock ~191 ~121 ~115 dirt
setblock ~191 ~121 ~116 dirt
setblock ~191 ~121 ~117 dirt
setblock ~191 ~121 ~119 dirt
setblock ~191 ~121 ~120 dirt
setblock ~191 ~122 ~86 dirt
setblock ~191 ~122 ~87 dirt
setblock ~191 ~122 ~88 dirt
setblock ~191 ~122 ~89 dirt
setblock ~191 ~122 ~90 dirt
setblock ~191 ~122 ~91 dirt
setblock ~191 ~122 ~92 dirt
setblock ~191 ~122 ~93 dirt
setblock ~191 ~122 ~94 dirt
setblock ~191 ~122 ~95 dirt
setblock ~191 ~122 ~113 dirt
setblock ~191 ~122 ~115 dirt
setblock ~191 ~122 ~116 dirt
setblock ~191 ~122 ~117 dirt
setblock ~191 ~122 ~119 dirt
setblock ~191 ~122 ~120 dirt
setblock ~191 ~123 ~86 dirt
setblock ~191 ~123 ~87 dirt
setblock ~191 ~123 ~88 grass_block
setblock ~191 ~123 ~89 grass_block
setblock ~191 ~123 ~90 grass_block
setblock ~191 ~123 ~91 grass_block
setblock ~191 ~123 ~92 grass_block
setblock ~191 ~123 ~93 dirt
setblock ~191 ~123 ~94 dirt
setblock ~191 ~123 ~95 dirt
setblock ~191 ~123 ~113 dirt
setblock ~191 ~123 ~115 dirt
setblock ~191 ~123 ~116 dirt
setblock ~191 ~123 ~117 dirt
setblock ~191 ~123 ~119 dirt
setblock ~191 ~123 ~120 dirt
setblock ~191 ~124 ~86 grass_block
setblock ~191 ~124 ~87 grass_block
setblock ~191 ~124 ~92 short_grass
setblock ~191 ~124 ~93 grass_block
setblock ~191 ~124 ~94 grass_block
setblock ~191 ~124 ~95 grass_block
setblock ~191 ~124 ~113 dirt
setblock ~191 ~124 ~115 dirt
setblock ~191 ~124 ~116 dirt
setblock ~191 ~124 ~117 dirt
setblock ~191 ~124 ~119 dirt
setblock ~191 ~124 ~120 dirt
setblock ~191 ~125 ~94 short_grass
setblock ~191 ~125 ~113 grass_block
setblock ~191 ~125 ~115 grass_block
setblock ~191 ~125 ~116 dirt
setblock ~191 ~125 ~117 dirt
setblock ~191 ~125 ~119 dirt
setblock ~191 ~125 ~120 dirt
setblock ~191 ~126 ~116 grass_block
setblock ~191 ~126 ~117 grass_block
setblock ~191 ~126 ~119 grass_block
setblock ~191 ~126 ~120 grass_block
setblock ~192 ~120 ~88 dirt
setblock ~192 ~120 ~89 dirt
setblock ~192 ~120 ~90 dirt
setblock ~192 ~120 ~92 dirt
setblock ~192 ~121 ~88 dirt
setblock ~192 ~121 ~89 dirt
setblock ~192 ~121 ~90 dirt
setblock ~192 ~121 ~91 dirt
setblock ~192 ~121 ~92 dirt
setblock ~192 ~121 ~93 dirt
setblock ~192 ~121 ~94 dirt
setblock ~192 ~122 ~88 dirt
setblock ~192 ~122 ~89 dirt
setblock ~192 ~122 ~90 dirt
setblock ~192 ~122 ~91 dirt
setblock ~192 ~122 ~92 dirt
setblock ~192 ~122 ~93 dirt
setblock ~192 ~122 ~94 dirt
setblock ~192 ~123 ~88 dirt
setblock ~192 ~123 ~89 grass_block
setblock ~192 ~123 ~90 grass_block
setblock ~192 ~123 ~91 grass_block
setblock ~192 ~123 ~92 dirt
setblock ~192 ~123 ~93 dirt
setblock ~192 ~123 ~94 dirt
setblock ~192 ~124 ~88 grass_block
setblock ~192 ~124 ~89 short_grass
setblock ~192 ~124 ~92 grass_block
setblock ~192 ~124 ~93 grass_block
setblock ~192 ~124 ~94 grass_block
setblock ~193 ~121 ~89 dirt
setblock ~193 ~121 ~90 dirt
setblock ~193 ~122 ~89 dirt
setblock ~193 ~122 ~90 dirt
setblock ~193 ~123 ~89 dirt
setblock ~193 ~123 ~90 grass_block
setblock ~193 ~124 ~89 grass_block
setblock ~193 ~125 ~89 short_grass
setblock ~199 ~200 ~199 gold_block
