setblock ~122 ~125 ~53 grass_block
setblock ~122 ~125 ~54 grass_block
setblock ~122 ~125 ~55 grass_block
setblock ~122 ~125 ~56 dirt
setblock ~122 ~125 ~57 dirt
setblock ~122 ~125 ~58 dirt
setblock ~122 ~125 ~59 dirt
setblock ~122 ~125 ~60 dirt
setblock ~122 ~125 ~61 dirt
setblock ~122 ~125 ~62 dirt
setblock ~122 ~125 ~63 dirt
setblock ~122 ~125 ~64 dirt
setblock ~122 ~125 ~65 dirt
setblock ~122 ~125 ~66 dirt
setblock ~122 ~125 ~67 dirt
setblock ~122 ~125 ~68 dirt
setblock ~122 ~125 ~69 dirt
setblock ~122 ~125 ~70 dirt
setblock ~122 ~125 ~71 dirt
setblock ~122 ~125 ~72 dirt
setblock ~122 ~125 ~73 dirt
setblock ~122 ~125 ~74 dirt
setblock ~122 ~125 ~75 dirt
setblock ~122 ~125 ~76 dirt
setblock ~122 ~125 ~77 dirt
setblock ~122 ~125 ~78 dirt
setblock ~122 ~125 ~79 dirt
setblock ~122 ~125 ~80 dirt
setblock ~122 ~125 ~81 dirt
setblock ~122 ~125 ~82 dirt
setblock ~122 ~125 ~83 dirt
setblock ~122 ~125 ~84 dirt
setblock ~122 ~125 ~85 dirt
setblock ~122 ~125 ~86 dirt
setblock ~122 ~125 ~87 dirt
setblock ~122 ~125 ~88 dirt
setblock ~122 ~125 ~89 dirt
setblock ~122 ~125 ~90 dirt
setblock ~122 ~125 ~91 dirt
setblock ~122 ~125 ~92 dirt
setblock ~122 ~125 ~93 dirt
setblock ~122 ~125 ~94 dirt
setblock ~122 ~125 ~95 dirt
setblock ~122 ~125 ~96 grass_block
setblock ~122 ~125 ~97 grass_block
setblock ~122 ~125 ~98 grass_block
setblock ~122 ~125 ~99 grass_block
setblock ~122 ~125 ~103 short_grass
setblock ~122 ~125 ~105 short_grass
setblock ~122 ~125 ~106 fern
setblock ~122 ~125 ~127 short_grass
setblock ~122 ~125 ~129 short_grass
setblock ~122 ~125 ~131 short_grass
setblock ~122 ~125 ~132 grass_block
setblock ~122 ~125 ~133 grass_block
setblock ~122 ~125 ~134 grass_block
setblock ~122 ~125 ~135 grass_block
setblock ~122 ~125 ~136 grass_block
setblock ~122 ~125 ~137 dirt
setblock ~122 ~125 ~138 dirt
setblock ~122 ~125 ~139 dirt
setblock ~122 ~125 ~140 dirt
setblock ~122 ~125 ~141 dirt
setblock ~122 ~125 ~142 dirt
setblock ~122 ~125 ~143 grass_block
setblock ~122 ~125 ~144 grass_block
setblock ~122 ~125 ~145 grass_block
setblock ~122 ~125 ~146 grass_block
setblock ~122 ~125 ~150 short_grass
setblock ~122 ~125 ~151 short_grass
setblock ~122 ~125 ~155 fern
setblock ~122 ~125 ~160 short_grass
setblock ~122 ~125 ~161 grass_block
setblock ~122 ~125 ~162 grass_block
setblock ~122 ~125 ~163 grass_block
setblock ~122 ~125 ~164 grass_block
setblock ~122 ~125 ~165 dirt
setblock ~122 ~125 ~166 dirt
setblock ~122 ~125 ~167 dirt
setblock ~122 ~125 ~168 dirt
setblock ~122 ~125 ~169 dirt
setblock ~122 ~125 ~170 dirt
setblock ~122 ~125 ~171 dirt
setblock ~122 ~125 ~172 dirt
setblock ~122 ~125 ~173 dirt
setblock ~122 ~125 ~174 dirt
setblock ~122 ~125 ~175 dirt
setblock ~122 ~125 ~176 dirt
setblock ~122 ~125 ~177 dirt
setblock ~122 ~125 ~178 grass_block
setblock ~122 ~125 ~179 grass_block
setblock ~122 ~125 ~180 grass_block
setblock ~122 ~125 ~181 grass_block
setblock ~122 ~126 ~0 short_grass
setblock ~122 ~126 ~53 short_grass
setblock ~122 ~126 ~54 poppy
setblock ~122 ~126 ~56 grass_block
setblock ~122 ~126 ~57 grass_block
setblock ~122 ~126 ~58 grass_block
setblock ~122 ~126 ~59 dirt
setblock ~122 ~126 ~60 dirt
setblock ~122 ~126 ~61 dirt
setblock ~122 ~126 ~62 dirt
setblock ~122 ~126 ~63 dirt
setblock ~122 ~126 ~64 dirt
setblock ~122 ~126 ~65 dirt
setblock ~122 ~126 ~66 dirt
setblock ~122 ~126 ~67 dirt
setblock ~122 ~126 ~68 dirt
setblock ~122 ~126 ~69 dirt
setblock ~122 ~126 ~70 dirt
setblock ~122 ~126 ~71 dirt
setblock ~122 ~126 ~72 dirt
setblock ~122 ~126 ~73 dirt
setblock ~122 ~126 ~74 dirt
setblock ~122 ~126 ~75 grass_block
setblock ~122 ~126 ~76 grass_block
setblock ~122 ~126 ~77 grass_block
setblock ~122 ~126 ~78 grass_block
setblock ~122 ~126 ~79 grass_block
setblock ~122 ~126 ~80 grass_block
setblock ~122 ~126 ~81 grass_block
setblock ~122 ~126 ~82 grass_block
setblock ~122 ~126 ~83 dirt
setblock ~122 ~126 ~84 dirt
setblock ~122 ~126 ~85 dirt
setblock ~122 ~126 ~86 dirt
setblock ~122 ~126 ~87 dirt
setblock ~122 ~126 ~88 dirt
setblock ~122 ~126 ~89 dirt
setblock ~122 ~126 ~90 dirt
setblock ~122 ~126 ~91 dirt
setblock ~122 ~126 ~92 dirt
setblock ~122 ~126 ~93 grass_block
setblock ~122 ~126 ~94 grass_block
setblock ~122 ~126 ~95 grass_block
setblock ~122 ~126 ~97 short_grass
setblock ~122 ~126 ~98 short_grass
setblock ~122 ~126 ~132 short_grass
setblock ~122 ~126 ~135 short_grass
setblock ~122 ~126 ~137 grass_block
setblock ~122 ~126 ~138 grass_block
setblock ~122 ~126 ~139 grass_block
setblock ~122 ~126 ~140 dirt
setblock ~122 ~126 ~141 grass_block
setblock ~122 ~126 ~142 grass_block
setblock ~122 ~126 ~146 short_grass
setblock ~122 ~126 ~163 short_grass
setblock ~122 ~126 ~165 grass_block
setblock ~122 ~126 ~166 grass_block
setblock ~122 ~126 ~167 grass_block
setblock ~122 ~126 ~168 grass_block
setblock ~122 ~126 ~169 dirt
setblock ~122 ~126 ~170 dirt
setblock ~122 ~126 ~171 dirt
setblock ~122 ~126 ~172 dirt
setblock ~122 ~126 ~173 grass_block
setblock ~122 ~126 ~174 grass_block
setblock ~122 ~126 ~175 grass_block
setblock ~122 ~126 ~176 grass_block
setblock ~122 ~126 ~177 grass_block
setblock ~122 ~127 ~58 short_grass
setblock ~122 ~127 ~59 grass_block
setblock ~122 ~127 ~60 dirt
setblock ~122 ~127 ~61 dirt
setblock ~122 ~127 ~62 dirt
setblock ~122 ~127 ~63 grass_block
setblock ~122 ~127 ~64 grass_block
setblock ~122 ~127 ~65 grass_block
setblock ~122 ~127 ~66 grass_block
setblock ~122 ~127 ~67 grass_block
setblock ~122 ~127 ~68 grass_block
setblock ~122 ~127 ~69 grass_block
setblock ~122 ~127 ~70 grass_block
setblock ~122 ~127 ~71 grass_block
setblock ~122 ~127 ~72 grass_block
setblock ~122 ~127 ~73 grass_block
setblock ~122 ~127 ~74 grass_block
setblock ~122 ~127 ~75 short_grass
setblock ~122 ~127 ~79 short_grass
setblock ~122 ~127 ~80 short_grass
setblock ~122 ~127 ~83 grass_block
setblock ~122 ~127 ~84 grass_block
setblock ~122 ~127 ~85 grass_block
setblock ~122 ~127 ~86 grass_block
setblock ~122 ~127 ~87 grass_block
setblock ~122 ~127 ~88 grass_block
setblock ~122 ~127 ~89 grass_block
setblock ~122 ~127 ~90 grass_block
setblock ~122 ~127 ~91 grass_block
setblock ~122 ~127 ~92 grass_block
setblock ~122 ~127 ~140 grass_block
setblock ~122 ~127 ~141 short_grass
setblock ~122 ~127 ~165 short_grass
setblock ~122 ~127 ~169 grass_block
setblock ~122 ~127 ~170 grass_block
setblock ~122 ~127 ~171 grass_block
setblock ~122 ~127 ~172 grass_block
setblock ~122 ~127 ~174 short_grass
setblock ~122 ~127 ~177 short_grass
setblock ~122 ~128 ~60 grass_block
setblock ~122 ~128 ~61 grass_block
setblock ~122 ~128 ~62 grass_block
setblock ~122 ~128 ~65 short_grass
setblock ~122 ~128 ~66 short_grass
setblock ~122 ~128 ~68 poppy
setblock ~122 ~128 ~69 short_grass
setblock ~122 ~128 ~84 fern
setblock ~122 ~128 ~91 short_grass
setblock ~122 ~128 ~170 short_grass
setblock ~122 ~128 ~171 short_grass
setblock ~123 ~122 ~0 dirt
setblock ~123 ~122 ~1 dirt
setblock ~123 ~122 ~2 dirt
setblock ~123 ~122 ~3 dirt
setblock ~123 ~122 ~4 dirt
setblock ~123 ~122 ~5 dirt
setblock ~123 ~122 ~6 dirt
setblock ~123 ~122 ~7 dirt
setblock ~123 ~122 ~8 dirt
setblock ~123 ~122 ~9 dirt
setblock ~123 ~122 ~10 dirt
setblock ~123 ~122 ~11 dirt
setblock ~123 ~122 ~12 dirt
setblock ~123 ~122 ~13 dirt
setblock ~123 ~122 ~14 dirt
setblock ~123 ~122 ~15 dirt
setblock ~123 ~122 ~16 dirt
setblock ~123 ~122 ~17 dirt
setblock ~123 ~122 ~18 dirt
setblock ~123 ~122 ~19 dirt
setblock ~123 ~122 ~20 dirt
setblock ~123 ~122 ~21 dirt
setblock ~123 ~122 ~22 dirt
setblock ~123 ~122 ~23 dirt
setblock ~123 ~122 ~24 dirt
setblock ~123 ~122 ~25 dirt
setblock ~123 ~122 ~26 dirt
setblock ~123 ~122 ~27 dirt
setblock ~123 ~122 ~28 dirt
setblock ~123 ~122 ~29 dirt
setblock ~123 ~122 ~30 dirt
setblock ~123 ~122 ~31 dirt
setblock ~123 ~122 ~32 dirt
setblock ~123 ~122 ~33 dirt
setblock ~123 ~122 ~34 dirt
setblock ~123 ~122 ~35 dirt
setblock ~123 ~122 ~36 dirt
setblock ~123 ~122 ~37 dirt
setblock ~123 ~122 ~38 dirt
setblock ~123 ~122 ~39 dirt
setblock ~123 ~122 ~40 dirt
setblock ~123 ~122 ~41 dirt
setblock ~123 ~122 ~42 dirt
setblock ~123 ~122 ~43 dirt
setblock ~123 ~122 ~44 dirt
setblock ~123 ~122 ~45 dirt
setblock ~123 ~122 ~46 dirt
setblock ~123 ~122 ~47 dirt
setblock ~123 ~122 ~48 dirt
setblock ~123 ~122 ~49 dirt
setblock ~123 ~122 ~50 dirt
setblock ~123 ~122 ~51 dirt
setblock ~123 ~122 ~52 dirt
setblock ~123 ~122 ~53 dirt
setblock ~123 ~122 ~54 dirt
setblock ~123 ~122 ~55 dirt
setblock ~123 ~122 ~56 dirt
setblock ~123 ~122 ~57 dirt
setblock ~123 ~122 ~58 dirt
setblock ~123 ~122 ~59 dirt
setblock ~123 ~122 ~60 dirt
setblock ~123 ~122 ~61 dirt
setblock ~123 ~122 ~62 dirt
setblock ~123 ~122 ~63 dirt
setblock ~123 ~122 ~64 dirt
setblock ~123 ~122 ~65 dirt
setblock ~123 ~122 ~66 dirt
setblock ~123 ~122 ~67 dirt
setblock ~123 ~122 ~68 dirt
setblock ~123 ~122 ~69 dirt
setblock ~123 ~122 ~70 dirt
setblock ~123 ~122 ~71 dirt
setblock ~123 ~122 ~72 dirt
setblock ~123 ~122 ~73 dirt
setblock ~123 ~122 ~74 dirt
setblock ~123 ~122 ~75 dirt
setblock ~123 ~122 ~76 dirt
setblock ~123 ~122 ~77 dirt
setblock ~123 ~122 ~78 dirt
setblock ~123 ~122 ~79 dirt
setblock ~123 ~122 ~80 dirt
setblock ~123 ~122 ~81 dirt
setblock ~123 ~122 ~82 dirt
setblock ~123 ~122 ~83 dirt
setblock ~123 ~122 ~84 dirt
setblock ~123 ~122 ~85 dirt
setblock ~123 ~122 ~86 dirt
setblock ~123 ~122 ~87 dirt
setblock ~123 ~122 ~88 dirt
setblock ~123 ~122 ~89 dirt
setblock ~123 ~122 ~90 dirt
setblock ~123 ~122 ~91 dirt
setblock ~123 ~122 ~92 dirt
setblock ~123 ~122 ~93 dirt
setblock ~123 ~122 ~94 dirt
setblock ~123 ~122 ~95 dirt
setblock ~123 ~122 ~96 dirt
setblock ~123 ~122 ~97 dirt
setblock ~123 ~122 ~98 dirt
setblock ~123 ~122 ~99 dirt
setblock ~123 ~122 ~100 dirt
setblock ~123 ~122 ~101 dirt
setblock ~123 ~122 ~102 dirt
setblock ~123 ~122 ~103 dirt
setblock ~123 ~122 ~104 dirt
setblock ~123 ~122 ~105 dirt
setblock ~123 ~122 ~106 dirt
setblock ~123 ~122 ~107 dirt
setblock ~123 ~122 ~108 dirt
setblock ~123 ~122 ~109 dirt
setblock ~123 ~122 ~110 dirt
setblock ~123 ~122 ~111 dirt
setblock ~123 ~122 ~112 dirt
setblock ~123 ~122 ~113 dirt
setblock ~123 ~122 ~114 dirt
setblock ~123 ~122 ~115 dirt
setblock ~123 ~122 ~116 dirt
setblock ~123 ~122 ~117 dirt
setblock ~123 ~122 ~118 dirt
setblock ~123 ~122 ~119 dirt
setblock ~123 ~122 ~120 dirt
setblock ~123 ~122 ~121 dirt
setblock ~123 ~122 ~122 dirt
setblock ~123 ~122 ~123 dirt
setblock ~123 ~122 ~124 dirt
setblock ~123 ~122 ~125 dirt
setblock ~123 ~122 ~126 dirt
setblock ~123 ~122 ~127 dirt
setblock ~123 ~122 ~128 dirt
setblock ~123 ~122 ~129 dirt
setblock ~123 ~122 ~130 dirt
setblock ~123 ~122 ~131 dirt
setblock ~123 ~122 ~132 dirt
setblock ~123 ~122 ~133 dirt
setblock ~123 ~122 ~134 dirt
setblock ~123 ~122 ~135 dirt
setblock ~123 ~122 ~136 dirt
setblock ~123 ~122 ~137 dirt
setblock ~123 ~122 ~138 dirt
setblock ~123 ~122 ~139 dirt
setblock ~123 ~122 ~140 dirt
setblock ~123 ~122 ~141 dirt
setblock ~123 ~122 ~142 dirt
setblock ~123 ~122 ~143 dirt
setblock ~123 ~122 ~144 dirt
setblock ~123 ~122 ~145 dirt
setblock ~123 ~122 ~146 dirt
setblock ~123 ~122 ~147 dirt
setblock ~123 ~122 ~148 dirt
setblock ~123 ~122 ~149 dirt
setblock ~123 ~122 ~150 dirt
setblock ~123 ~122 ~151 dirt
setblock ~123 ~122 ~152 dirt
setblock ~123 ~122 ~153 dirt
setblock ~123 ~122 ~154 dirt
setblock ~123 ~122 ~155 dirt
setblock ~123 ~122 ~156 dirt
setblock ~123 ~122 ~157 dirt
setblock ~123 ~122 ~158 dirt
setblock ~123 ~122 ~159 dirt
setblock ~123 ~122 ~160 dirt
setblock ~123 ~122 ~161 dirt
setblock ~123 ~122 ~162 dirt
setblock ~123 ~122 ~163 dirt
setblock ~123 ~122 ~164 dirt
setblock ~123 ~122 ~165 dirt
setblock ~123 ~122 ~166 dirt
setblock ~123 ~122 ~167 dirt
setblock ~123 ~122 ~168 dirt
setblock ~123 ~122 ~169 dirt
setblock ~123 ~122 ~170 dirt
setblock ~123 ~122 ~171 dirt
setblock ~123 ~122 ~172 dirt
setblock ~123 ~122 ~173 dirt
setblock ~123 ~122 ~174 dirt
setblock ~123 ~122 ~175 dirt
setblock ~123 ~122 ~176 dirt
setblock ~123 ~122 ~177 dirt
setblock ~123 ~122 ~178 dirt
setblock ~123 ~122 ~179 dirt
setblock ~123 ~122 ~180 dirt
setblock ~123 ~122 ~181 dirt
setblock ~123 ~122 ~182 dirt
setblock ~123 ~122 ~183 dirt
setblock ~123 ~122 ~184 dirt
setblock ~123 ~122 ~185 dirt
setblock ~123 ~122 ~186 dirt
setblock ~123 ~122 ~187 dirt
setblock ~123 ~122 ~188 dirt
setblock ~123 ~122 ~189 dirt
setblock ~123 ~122 ~190 grass_block
setblock ~123 ~122 ~191 dirt
setblock ~123 ~122 ~192 dirt
setblock ~123 ~122 ~193 dirt
setblock ~123 ~122 ~194 dirt
setblock ~123 ~122 ~195 dirt
setblock ~123 ~122 ~196 dirt
setblock ~123 ~122 ~197 dirt
setblock ~123 ~122 ~198 dirt
setblock ~123 ~122 ~199 dirt
setblock ~123 ~123 ~0 dirt
setblock ~123 ~123 ~1 dirt
setblock ~123 ~123 ~2 dirt
setblock ~123 ~123 ~3 dirt
setblock ~123 ~123 ~4 dirt
setblock ~123 ~123 ~5 dirt
setblock ~123 ~123 ~6 dirt
setblock ~123 ~123 ~7 dirt
setblock ~123 ~123 ~8 dirt
setblock ~123 ~123 ~9 dirt
setblock ~123 ~123 ~10 dirt
setblock ~123 ~123 ~11 dirt
setblock ~123 ~123 ~12 dirt
setblock ~123 ~123 ~13 dirt
setblock ~123 ~123 ~14 dirt
setblock ~123 ~123 ~15 dirt
setblock ~123 ~123 ~16 dirt
setblock ~123 ~123 ~17 dirt
setblock ~123 ~123 ~18 dirt
setblock ~123 ~123 ~19 dirt
setblock ~123 ~123 ~20 dirt
setblock ~123 ~123 ~21 dirt
setblock ~123 ~123 ~22 dirt
setblock ~123 ~123 ~23 dirt
setblock ~123 ~123 ~24 grass_block
setblock ~123 ~123 ~25 grass_block
setblock ~123 ~123 ~26 grass_block
setblock ~123 ~123 ~27 grass_block
setblock ~123 ~123 ~28 grass_block
setblock ~123 ~123 ~29 grass_block
setblock ~123 ~123 ~30 grass_block
setblock ~123 ~123 ~31 grass_block
setblock ~123 ~123 ~32 grass_block
setblock ~123 ~123 ~33 grass_block
setblock ~123 ~123 ~34 grass_block
setblock ~123 ~123 ~35 dirt
setblock ~123 ~123 ~36 dirt
setblock ~123 ~123 ~37 dirt
setblock ~123 ~123 ~38 dirt
setblock ~123 ~123 ~39 dirt
setblock ~123 ~123 ~40 dirt
setblock ~123 ~123 ~41 dirt
setblock ~123 ~123 ~42 dirt
setblock ~123 ~123 ~43 dirt
setblock ~123 ~123 ~44 dirt
setblock ~123 ~123 ~45 dirt
setblock ~123 ~123 ~46 dirt
setblock ~123 ~123 ~47 dirt
setblock ~123 ~123 ~48 dirt
setblock ~123 ~123 ~49 dirt
setblock ~123 ~123 ~50 dirt
setblock ~123 ~123 ~51 dirt
setblock ~123 ~123 ~52 dirt
setblock ~123 ~123 ~53 dirt
setblock ~123 ~123 ~54 dirt
setblock ~123 ~123 ~55 dirt
setblock ~123 ~123 ~56 dirt
setblock ~123 ~123 ~57 dirt
setblock ~123 ~123 ~58 dirt
setblock ~123 ~123 ~59 dirt
setblock ~123 ~123 ~60 dirt
setblock ~123 ~123 ~61 dirt
setblock ~123 ~123 ~62 dirt
setblock ~123 ~123 ~63 dirt
setblock ~123 ~123 ~64 dirt
setblock ~123 ~123 ~65 dirt
setblock ~123 ~123 ~66 dirt
setblock ~123 ~123 ~67 dirt
setblock ~123 ~123 ~68 dirt
setblock ~123 ~123 ~69 dirt
setblock ~123 ~123 ~70 dirt
setblock ~123 ~123 ~71 dirt
setblock ~123 ~123 ~72 dirt
setblock ~123 ~123 ~73 dirt
setblock ~123 ~123 ~74 dirt
setblock ~123 ~123 ~75 dirt
setblock ~123 ~123 ~76 dirt
setblock ~123 ~123 ~77 dirt
setblock ~123 ~123 ~78 dirt
setblock ~123 ~123 ~79 dirt
setblock ~123 ~123 ~80 dirt
setblock ~123 ~123 ~81 dirt
setblock ~123 ~123 ~82 dirt
setblock ~123 ~123 ~83 dirt
setblock ~123 ~123 ~84 dirt
setblock ~123 ~123 ~85 dirt
setblock ~123 ~123 ~86 dirt
setblock ~123 ~123 ~87 dirt
setblock ~123 ~123 ~88 dirt
setblock ~123 ~123 ~89 dirt
setblock ~123 ~123 ~90 dirt
setblock ~123 ~123 ~91 dirt
setblock ~123 ~123 ~92 dirt
setblock ~123 ~123 ~93 dirt
setblock ~123 ~123 ~94 dirt
setblock ~123 ~123 ~95 dirt
setblock ~123 ~123 ~96 dirt
setblock ~123 ~123 ~97 dirt
setblock ~123 ~123 ~98 dirt
setblock ~123 ~123 ~99 dirt
setblock ~123 ~123 ~100 dirt
setblock ~123 ~123 ~101 dirt
setblock ~123 ~123 ~102 dirt
setblock ~123 ~123 ~103 dirt
setblock ~123 ~123 ~104 dirt
setblock ~123 ~123 ~105 dirt
setblock ~123 ~123 ~106 dirt
setblock ~123 ~123 ~107 dirt
setblock ~123 ~123 ~108 dirt
setblock ~123 ~123 ~109 grass_block
setblock ~123 ~123 ~110 grass_block
setblock ~123 ~123 ~111 grass_block
setblock ~123 ~123 ~112 grass_block
setblock ~123 ~123 ~113 grass_block
setblock ~123 ~123 ~114 dirt
setblock ~123 ~123 ~115 dirt
setblock ~123 ~123 ~116 dirt
setblock ~123 ~123 ~117 dirt
setblock ~123 ~123 ~118 dirt
setblock ~123 ~123 ~119 dirt
setblock ~123 ~123 ~120 dirt
setblock ~123 ~123 ~121 dirt
setblock ~123 ~123 ~122 dirt
setblock ~123 ~123 ~123 dirt
setblock ~123 ~123 ~124 dirt
setblock ~123 ~123 ~125 dirt
setblock ~123 ~123 ~126 dirt
setblock ~123 ~123 ~127 dirt
setblock ~123 ~123 ~128 dirt
setblock ~123 ~123 ~129 dirt
setblock ~123 ~123 ~130 dirt
setblock ~123 ~123 ~131 dirt
setblock ~123 ~123 ~132 dirt
setblock ~123 ~123 ~133 dirt
setblock ~123 ~123 ~134 dirt
setblock ~123 ~123 ~135 dirt
setblock ~123 ~123 ~136 dirt
setblock ~123 ~123 ~137 dirt
setblock ~123 ~123 ~138 dirt
setblock ~123 ~123 ~139 dirt
setblock ~123 ~123 ~140 dirt
setblock ~123 ~123 ~141 dirt
setblock ~123 ~123 ~142 dirt
setblock ~123 ~123 ~143 dirt
setblock ~123 ~123 ~144 dirt
setblock ~123 ~123 ~145 dirt
setblock ~123 ~123 ~146 dirt
setblock ~123 ~123 ~147 dirt
setblock ~123 ~123 ~148 dirt
setblock ~123 ~123 ~149 dirt
setblock ~123 ~123 ~150 dirt
setblock ~123 ~123 ~151 dirt
setblock ~123 ~123 ~152 dirt
setblock ~123 ~123 ~153 dirt
setblock ~123 ~123 ~154 dirt
setblock ~123 ~123 ~155 dirt
setblock ~123 ~123 ~156 dirt
setblock ~123 ~123 ~157 dirt
setblock ~123 ~123 ~158 dirt
setblock ~123 ~123 ~159 dirt
setblock ~123 ~123 ~160 dirt
setblock ~123 ~123 ~161 dirt
setblock ~123 ~123 ~162 dirt
setblock ~123 ~123 ~163 dirt
setblock ~123 ~123 ~164 dirt
setblock ~123 ~123 ~165 dirt
setblock ~123 ~123 ~166 dirt
setblock ~123 ~123 ~167 dirt
setblock ~123 ~123 ~168 dirt
setblock ~123 ~123 ~169 dirt
setblock ~123 ~123 ~170 dirt
setblock ~123 ~123 ~171 dirt
setblock ~123 ~123 ~172 dirt
setblock ~123 ~123 ~173 dirt
setblock ~123 ~123 ~174 dirt
setblock ~123 ~123 ~175 dirt
setblock ~123 ~123 ~176 dirt
setblock ~123 ~123 ~177 dirt
setblock ~123 ~123 ~178 dirt
setblock ~123 ~123 ~179 dirt
setblock ~123 ~123 ~180 dirt
setblock ~123 ~123 ~181 dirt
setblock ~123 ~123 ~182 dirt
setblock ~123 ~123 ~183 dirt
setblock ~123 ~123 ~184 grass_block
setblock ~123 ~123 ~185 grass_block
setblock ~123 ~123 ~186 grass_block
setblock ~123 ~123 ~187 grass_block
setblock ~123 ~123 ~188 grass_block
setblock ~123 ~123 ~189 grass_block
setblock ~123 ~123 ~191 grass_block
setblock ~123 ~123 ~192 grass_block
setblock ~123 ~123 ~193 grass_block
setblock ~123 ~123 ~194 grass_block
setblock ~123 ~123 ~195 grass_block
setblock ~123 ~123 ~196 grass_block
setblock ~123 ~123 ~197 grass_block
setblock ~123 ~123 ~198 grass_block
setblock ~123 ~123 ~199 grass_block
setblock ~123 ~124 ~0 dirt
setblock ~123 ~124 ~1 dirt
setblock ~123 ~124 ~2 dirt
setblock ~123 ~124 ~3 dirt
setblock ~123 ~124 ~4 dirt
setblock ~123 ~124 ~5 dirt
setblock ~123 ~124 ~6 dirt
setblock ~123 ~124 ~7 dirt
setblock ~123 ~124 ~8 dirt
setblock ~123 ~124 ~9 dirt
setblock ~123 ~124 ~10 dirt
setblock ~123 ~124 ~11 dirt
setblock ~123 ~124 ~12 dirt
setblock ~123 ~124 ~13 dirt
setblock ~123 ~124 ~14 dirt
setblock ~123 ~124 ~15 grass_block
setblock ~123 ~124 ~16 grass_block
setblock ~123 ~124 ~17 grass_block
setblock ~123 ~124 ~18 grass_block
setblock ~123 ~124 ~19 grass_block
setblock ~123 ~124 ~20 grass_block
setblock ~123 ~124 ~21 grass_block
setblock ~123 ~124 ~22 grass_block
setblock ~123 ~124 ~23 grass_block
setblock ~123 ~124 ~26 short_grass
setblock ~123 ~124 ~34 poppy
setblock ~123 ~124 ~35 grass_block
setblock ~123 ~124 ~36 grass_block
setblock ~123 ~124 ~37 grass_block
setblock ~123 ~124 ~38 grass_block
setblock ~123 ~124 ~39 dirt
setblock ~123 ~124 ~40 dirt
setblock ~123 ~124 ~41 dirt
setblock ~123 ~124 ~42 dirt
setblock ~123 ~124 ~43 dirt
setblock ~123 ~124 ~44 dirt
setblock ~123 ~124 ~45 dirt
setblock ~123 ~124 ~46 dirt
setblock ~123 ~124 ~47 dirt
setblock ~123 ~124 ~48 dirt
setblock ~123 ~124 ~49 dirt
setblock ~123 ~124 ~50 grass_block
setblock ~123 ~124 ~51 dirt
setblock ~123 ~124 ~52 dirt
setblock ~123 ~124 ~53 dirt
setblock ~123 ~124 ~54 dirt
setblock ~123 ~124 ~55 dirt
setblock ~123 ~124 ~56 dirt
setblock ~123 ~124 ~57 dirt
setblock ~123 ~124 ~58 dirt
setblock ~123 ~124 ~59 dirt
setblock ~123 ~124 ~60 dirt
setblock ~123 ~124 ~61 dirt
setblock ~123 ~124 ~62 dirt
setblock ~123 ~124 ~63 dirt
setblock ~123 ~124 ~64 dirt
setblock ~123 ~124 ~65 dirt
setblock ~123 ~124 ~66 dirt
setblock ~123 ~124 ~67 dirt
setblock ~123 ~124 ~68 dirt
setblock ~123 ~124 ~69 dirt
setblock ~123 ~124 ~70 dirt
setblock ~123 ~124 ~71 dirt
setblock ~123 ~124 ~72 dirt
setblock ~123 ~124 ~73 dirt
setblock ~123 ~124 ~74 dirt
setblock ~123 ~124 ~75 dirt
setblock ~123 ~124 ~76 dirt
setblock ~123 ~124 ~77 dirt
setblock ~123 ~124 ~78 dirt
setblock ~123 ~124 ~79 dirt
setblock ~123 ~124 ~80 dirt
setblock ~123 ~124 ~81 dirt
setblock ~123 ~124 ~82 dirt
setblock ~123 ~124 ~83 dirt
setblock ~123 ~124 ~84 dirt
setblock ~123 ~124 ~85 dirt
setblock ~123 ~124 ~86 dirt
setblock ~123 ~124 ~87 dirt
setblock ~123 ~124 ~88 dirt
setblock ~123 ~124 ~89 dirt
setblock ~123 ~124 ~90 dirt
setblock ~123 ~124 ~91 dirt
setblock ~123 ~124 ~92 dirt
setblock ~123 ~124 ~93 dirt
setblock ~123 ~124 ~94 dirt
setblock ~123 ~124 ~95 dirt
setblock ~123 ~124 ~96 dirt
setblock ~123 ~124 ~97 dirt
setblock ~123 ~124 ~98 dirt
setblock ~123 ~124 ~99 dirt
setblock ~123 ~124 ~100 grass_block
setblock ~123 ~124 ~101 grass_block
setblock ~123 ~124 ~102 grass_block
setblock ~123 ~124 ~103 grass_block
setblock ~123 ~124 ~104 grass_block
setblock ~123 ~124 ~105 grass_block
setblock ~123 ~124 ~106 grass_block
setblock ~123 ~124 ~107 grass_block
setblock ~123 ~124 ~108 grass_block
setblock ~123 ~124 ~110 short_grass
setblock ~123 ~124 ~111 short_grass
setblock ~123 ~124 ~114 grass_block
setblock ~123 ~124 ~115 grass_block
setblock ~123 ~124 ~116 grass_block
setblock ~123 ~124 ~117 grass_block
setblock ~123 ~124 ~118 grass_block
setblock ~123 ~124 ~119 dirt
setblock ~123 ~124 ~120 dirt
setblock ~123 ~124 ~121 dirt
setblock ~123 ~124 ~122 dirt
setblock ~123 ~124 ~123 dirt
setblock ~123 ~124 ~124 dirt
setblock ~123 ~124 ~125 dirt
setblock ~123 ~124 ~126 dirt
setblock ~123 ~124 ~127 dirt
setblock ~123 ~124 ~128 dirt
setblock ~123 ~124 ~129 grass_block
setblock ~123 ~124 ~130 grass_block
setblock ~123 ~124 ~131 dirt
setblock ~123 ~124 ~132 dirt
setblock ~123 ~124 ~133 dirt
setblock ~123 ~124 ~134 dirt
setblock ~123 ~124 ~135 dirt
setblock ~123 ~124 ~136 dirt
setblock ~123 ~124 ~137 dirt
setblock ~123 ~124 ~138 dirt
setblock ~123 ~124 ~139 dirt
setblock ~123 ~124 ~140 dirt
setblock ~123 ~124 ~141 dirt
setblock ~123 ~124 ~142 dirt
setblock ~123 ~124 ~143 dirt
setblock ~123 ~124 ~144 dirt
setblock ~123 ~124 ~145 dirt
setblock ~123 ~124 ~146 dirt
setblock ~123 ~124 ~147 grass_block
setblock ~123 ~124 ~148 grass_block
setblock ~123 ~124 ~149 grass_block
setblock ~123 ~124 ~150 grass_block
setblock ~123 ~124 ~151 grass_block
setblock ~123 ~124 ~152 grass_block
setblock ~123 ~124 ~153 grass_block
setblock ~123 ~124 ~154 grass_block
setblock ~123 ~124 ~155 grass_block
setblock ~123 ~124 ~156 grass_block
setblock ~123 ~124 ~157 grass_block
setblock ~123 ~124 ~158 grass_block
setblock ~123 ~124 ~159 grass_block
setblock ~123 ~124 ~160 grass_block
setblock ~123 ~124 ~161 dirt
setblock ~123 ~124 ~162 dirt
setblock ~123 ~124 ~163 dirt
setblock ~123 ~124 ~164 dirt
setblock ~123 ~124 ~165 dirt
setblock ~123 ~124 ~166 dirt
setblock ~123 ~124 ~167 dirt
setblock ~123 ~124 ~168 dirt
setblock ~123 ~124 ~169 dirt
setblock ~123 ~124 ~170 dirt
setblock ~123 ~124 ~171 dirt
setblock ~123 ~124 ~172 dirt
setblock ~123 ~124 ~173 dirt
setblock ~123 ~124 ~174 dirt
setblock ~123 ~124 ~175 dirt
setblock ~123 ~124 ~176 dirt
setblock ~123 ~124 ~177 dirt
setblock ~123 ~124 ~178 dirt
setblock ~123 ~124 ~179 dirt
setblock ~123 ~124 ~180 grass_block
setblock ~123 ~124 ~181 grass_block
setblock ~123 ~124 ~182 grass_block
setblock ~123 ~124 ~183 grass_block
setblock ~123 ~124 ~189 fern
setblock ~123 ~124 ~191 short_grass
setblock ~123 ~124 ~193 short_grass
setblock ~123 ~124 ~198 short_grass
setblock ~123 ~124 ~199 short_grass
setblock ~123 ~125 ~0 grass_block
setblock ~123 ~125 ~1 grass_block
setblock ~123 ~125 ~2 grass_block
setblock ~123 ~125 ~3 grass_block
setblock ~123 ~125 ~4 grass_block
setblock ~123 ~125 ~5 grass_block
setblock ~123 ~125 ~6 grass_block
setblock ~123 ~125 ~7 grass_block
setblock ~123 ~125 ~8 grass_block
setblock ~123 ~125 ~9 grass_block
setblock ~123 ~125 ~10 grass_block
setblock ~123 ~125 ~11 grass_block
setblock ~123 ~125 ~12 grass_block
setblock ~123 ~125 ~13 grass_block
setblock ~123 ~125 ~14 grass_block
setblock ~123 ~125 ~18 short_grass
setblock ~123 ~125 ~20 poppy
setblock ~123 ~125 ~38 short_grass
setblock ~123 ~125 ~39 grass_block
setblock ~123 ~125 ~40 grass_block
setblock ~123 ~125 ~41 grass_block
setblock ~123 ~125 ~42 grass_block
setblock ~123 ~125 ~43 grass_block
setblock ~123 ~125 ~44 grass_block
setblock ~123 ~125 ~45 grass_block
setblock ~123 ~125 ~46 grass_block
setblock ~123 ~125 ~47 grass_block
setblock ~123 ~125 ~48 grass_block
setblock ~123 ~125 ~49 grass_block
setblock ~123 ~125 ~50 short_grass
setblock ~123 ~125 ~51 grass_block
setblock ~123 ~125 ~52 grass_block
setblock ~123 ~125 ~53 grass_block
setblock ~123 ~125 ~54 grass_block
setblock ~123 ~125 ~55 grass_block
setblock ~123 ~125 ~56 dirt
setblock ~123 ~125 ~57 dirt
setblock ~123 ~125 ~58 dirt
setblock ~123 ~125 ~59 dirt
setblock ~123 ~125 ~60 dirt
setblock ~123 ~125 ~61 dirt
setblock ~123 ~125 ~62 dirt
setblock ~123 ~125 ~63 dirt
setblock ~123 ~125 ~64 dirt
setblock ~123 ~125 ~65 dirt
setblock ~123 ~125 ~66 dirt
setblock ~123 ~125 ~67 dirt
setblock ~123 ~125 ~68 dirt
setblock ~123 ~125 ~69 dirt
setblock ~123 ~125 ~70 dirt
setblock ~123 ~125 ~71 dirt
setblock ~123 ~125 ~72 dirt
setblock ~123 ~125 ~73 dirt
setblock ~123 ~125 ~74 dirt
setblock ~123 ~125 ~75 dirt
setblock ~123 ~125 ~76 dirt
setblock ~123 ~125 ~77 dirt
setblock ~123 ~125 ~78 dirt
setblock ~123 ~125 ~79 dirt
setblock ~123 ~125 ~80 dirt
setblock ~123 ~125 ~81 dirt
setblock ~123 ~125 ~82 dirt
setblock ~123 ~125 ~83 dirt
setblock ~123 ~125 ~84 dirt
setblock ~123 ~125 ~85 dirt
setblock ~123 ~125 ~86 dirt
setblock ~123 ~125 ~87 dirt
setblock ~123 ~125 ~88 dirt
setblock ~123 ~125 ~89 dirt
setblock ~123 ~125 ~90 dirt
setblock ~123 ~125 ~91 dirt
setblock ~123 ~125 ~92 dirt
setblock ~123 ~125 ~93 dirt
setblock ~123 ~125 ~94 dirt
setblock ~123 ~125 ~95 dirt
setblock ~123 ~125 ~96 grass_block
setblock ~123 ~125 ~97 grass_block
setblock ~123 ~125 ~98 grass_block
setblock ~123 ~125 ~99 grass_block
setblock ~123 ~125 ~102 short_grass
setblock ~123 ~125 ~104 short_grass
setblock ~123 ~125 ~105 short_grass
setblock ~123 ~125 ~114 poppy
setblock ~123 ~125 ~119 grass_block
setblock ~123 ~125 ~120 grass_block
setblock ~123 ~125 ~121 grass_block
setblock ~123 ~125 ~122 grass_block
setblock ~123 ~125 ~123 grass_block
setblock ~123 ~125 ~124 grass_block
setblock ~123 ~125 ~125 grass_block
setblock ~123 ~125 ~126 grass_block
setblock ~123 ~125 ~127 grass_block
setblock ~123 ~125 ~128 grass_block
setblock ~123 ~125 ~131 grass_block
setblock ~123 ~125 ~132 grass_block
setblock ~123 ~125 ~133 grass_block
setblock ~123 ~125 ~134 grass_block
setblock ~123 ~125 ~135 grass_block
setblock ~123 ~125 ~136 grass_block
setblock ~123 ~125 ~137 dirt
setblock ~123 ~125 ~138 dirt
setblock ~123 ~125 ~139 dirt
setblock ~123 ~125 ~140 dirt
setblock ~123 ~125 ~141 dirt
setblock ~123 ~125 ~142 dirt
setblock ~123 ~125 ~143 grass_block
setblock ~123 ~125 ~144 grass_block
setblock ~123 ~125 ~145 grass_block
setblock ~123 ~125 ~146 grass_block
setblock ~123 ~125 ~147 short_grass
setblock ~123 ~125 ~148 short_grass
setblock ~123 ~125 ~149 short_grass
setblock ~123 ~125 ~151 poppy
setblock ~123 ~125 ~157 short_grass
setblock ~123 ~125 ~159 fern
setblock ~123 ~125 ~161 grass_block
setblock ~123 ~125 ~162 grass_block
setblock ~123 ~125 ~163 grass_block
setblock ~123 ~125 ~164 grass_block
setblock ~123 ~125 ~165 dirt
setblock ~123 ~125 ~166 dirt
setblock ~123 ~125 ~167 dirt
setblock ~123 ~125 ~168 dirt
setblock ~123 ~125 ~169 dirt
setblock ~123 ~125 ~170 dirt
setblock ~123 ~125 ~171 dirt
setblock ~123 ~125 ~172 dirt
setblock ~123 ~125 ~173 dirt
setblock ~123 ~125 ~174 dirt
setblock ~123 ~125 ~175 dirt
setblock ~123 ~125 ~176 dirt
setblock ~123 ~125 ~177 grass_block
setblock ~123 ~125 ~178 grass_block
setblock ~123 ~125 ~179 grass_block
setblock ~123 ~125 ~181 short_grass
setblock ~123 ~125 ~183 short_grass
setblock ~123 ~126 ~0 short_grass
setblock ~123 ~126 ~1 short_grass
setblock ~123 ~126 ~4 short_grass
setblock ~123 ~126 ~5 short_grass
setblock ~123 ~126 ~8 fern
setblock ~123 ~126 ~9 short_grass
setblock ~123 ~126 ~11 short_grass
setblock ~123 ~126 ~13 poppy
setblock ~123 ~126 ~39 short_grass
setblock ~123 ~126 ~41 short_grass
setblock ~123 ~126 ~43 short_grass
setblock ~123 ~126 ~45 short_grass
setblock ~123 ~126 ~47 short_grass
setblock ~123 ~126 ~48 short_grass
setblock ~123 ~126 ~53 short_grass
setblock ~123 ~126 ~56 grass_block
setblock ~123 ~126 ~57 grass_block
setblock ~123 ~126 ~58 grass_block
setblock ~123 ~126 ~59 dirt
setblock ~123 ~126 ~60 dirt
setblock ~123 ~126 ~61 dirt
setblock ~123 ~126 ~62 dirt
setblock ~123 ~126 ~63 dirt
setblock ~123 ~126 ~64 dirt
setblock ~123 ~126 ~65 dirt
setblock ~123 ~126 ~66 dirt
setblock ~123 ~126 ~67 dirt
setblock ~123 ~126 ~68 dirt
setblock ~123 ~126 ~69 dirt
setblock ~123 ~126 ~70 dirt
setblock ~123 ~126 ~71 grass_block
setblock ~123 ~126 ~72 grass_block
setblock ~123 ~126 ~73 grass_block
setblock ~123 ~126 ~74 grass_block
setblock ~123 ~126 ~75 grass_block
setblock ~123 ~126 ~76 grass_block
setblock ~123 ~126 ~77 grass_block
setblock ~123 ~126 ~78 grass_block
setblock ~123 ~126 ~79 grass_block
setblock ~123 ~126 ~80 grass_block
setblock ~123 ~126 ~81 grass_block
setblock ~123 ~126 ~82 grass_block
setblock ~123 ~126 ~83 grass_block
setblock ~123 ~126 ~84 grass_block
setblock ~123 ~126 ~85 grass_block
setblock ~123 ~126 ~86 grass_block
setblock ~123 ~126 ~87 dirt
setblock ~123 ~126 ~88 dirt
setblock ~123 ~126 ~89 dirt
setblock ~123 ~126 ~90 dirt
setblock ~123 ~126 ~91 dirt
setblock ~123 ~126 ~92 grass_block
setblock ~123 ~126 ~93 grass_block
setblock ~123 ~126 ~94 grass_block
setblock ~123 ~126 ~95 grass_block
setblock ~123 ~126 ~97 short_grass
setblock ~123 ~126 ~99 short_grass
setblock ~123 ~126 ~122 short_grass
setblock ~123 ~126 ~126 fern
setblock ~123 ~126 ~128 fern
setblock ~123 ~126 ~131 short_grass
setblock ~123 ~126 ~137 grass_block
setblock ~123 ~126 ~138 grass_block
setblock ~123 ~126 ~139 grass_block
setblock ~123 ~126 ~140 grass_block
setblock ~123 ~126 ~141 grass_block
setblock ~123 ~126 ~142 grass_block
setblock ~123 ~126 ~145 fern
setblock ~123 ~126 ~163 short_grass
setblock ~123 ~126 ~165 grass_block
setblock ~123 ~126 ~166 grass_block
setblock ~123 ~126 ~167 grass_block
setblock ~123 ~126 ~168 grass_block
setblock ~123 ~126 ~169 dirt
setblock ~123 ~126 ~170 dirt
setblock ~123 ~126 ~171 dirt
setblock ~123 ~126 ~172 dirt
setblock ~123 ~126 ~173 grass_block
setblock ~123 ~126 ~174 grass_block
setblock ~123 ~126 ~175 grass_block
setblock ~123 ~126 ~176 grass_block
setblock ~123 ~127 ~57 short_grass
setblock ~123 ~127 ~58 poppy
setblock ~123 ~127 ~59 grass_block
setblock ~123 ~127 ~60 dirt
setblock ~123 ~127 ~61 grass_block
setblock ~123 ~127 ~62 grass_block
setblock ~123 ~127 ~63 grass_block
setblock ~123 ~127 ~64 grass_block
setblock ~123 ~127 ~65 grass_block
setblock ~123 ~127 ~66 grass_block
setblock ~123 ~127 ~67 grass_block
setblock ~123 ~127 ~68 grass_block
setblock ~123 ~127 ~69 grass_block
setblock ~123 ~127 ~70 grass_block
setblock ~123 ~127 ~78 short_grass
setblock ~123 ~127 ~81 fern
setblock ~123 ~127 ~84 poppy
setblock ~123 ~127 ~87 grass_block
setblock ~123 ~127 ~88 grass_block
setblock ~123 ~127 ~89 grass_block
setblock ~123 ~127 ~90 grass_block
setblock ~123 ~127 ~91 grass_block
setblock ~123 ~127 ~166 short_grass
setblock ~123 ~127 ~169 grass_block
setblock ~123 ~127 ~170 grass_block
setblock ~123 ~127 ~171 grass_block
setblock ~123 ~127 ~172 grass_block
setblock ~123 ~127 ~174 short_grass
setblock ~123 ~128 ~59 poppy
setblock ~123 ~128 ~60 grass_block
setblock ~123 ~128 ~62 poppy
setblock ~123 ~128 ~64 short_grass
setblock ~123 ~128 ~66 short_grass
setblock ~123 ~128 ~67 short_grass
setblock ~123 ~128 ~70 fern
setblock ~123 ~128 ~91 short_grass
setblock ~123 ~128 ~170 short_grass
setblock ~123 ~129 ~60 short_grass
setblock ~124 ~122 ~0 dirt
setblock ~124 ~122 ~1 dirt
setblock ~124 ~122 ~2 dirt
setblock ~124 ~122 ~3 dirt
setblock ~124 ~122 ~4 dirt
setblock ~124 ~122 ~5 dirt
setblock ~124 ~122 ~6 dirt
setblock ~124 ~122 ~7 dirt
setblock ~124 ~122 ~8 dirt
setblock ~124 ~122 ~9 dirt
setblock ~124 ~122 ~10 dirt
setblock ~124 ~122 ~11 dirt
setblock ~124 ~122 ~12 dirt
setblock ~124 ~122 ~13 dirt
setblock ~124 ~122 ~14 dirt
setblock ~124 ~122 ~15 dirt
setblock ~124 ~122 ~16 dirt
setblock ~124 ~122 ~17 dirt
setblock ~124 ~122 ~18 dirt
setblock ~124 ~122 ~19 dirt
setblock ~124 ~122 ~20 dirt
setblock ~124 ~122 ~21 dirt
setblock ~124 ~122 ~22 dirt
setblock ~124 ~122 ~23 dirt
setblock ~124 ~122 ~24 dirt
setblock ~124 ~122 ~25 dirt
setblock ~124 ~122 ~26 dirt
setblock ~124 ~122 ~27 dirt
setblock ~124 ~122 ~28 dirt
setblock ~124 ~122 ~29 dirt
setblock ~124 ~122 ~30 dirt
setblock ~124 ~122 ~31 dirt
setblock ~124 ~122 ~32 dirt
setblock ~124 ~122 ~33 dirt
setblock ~124 ~122 ~34 dirt
setblock ~124 ~122 ~35 dirt
setblock ~124 ~122 ~36 dirt
setblock ~124 ~122 ~37 dirt
setblock ~124 ~122 ~38 dirt
setblock ~124 ~122 ~39 dirt
setblock ~124 ~122 ~40 dirt
setblock ~124 ~122 ~41 dirt
setblock ~124 ~122 ~42 dirt
setblock ~124 ~122 ~43 dirt
setblock ~124 ~122 ~44 dirt
setblock ~124 ~122 ~45 dirt
setblock ~124 ~122 ~46 dirt
setblock ~124 ~122 ~47 dirt
setblock ~124 ~122 ~48 dirt
setblock ~124 ~122 ~49 dirt
setblock ~124 ~122 ~50 dirt
setblock ~124 ~122 ~51 dirt
setblock ~124 ~122 ~52 dirt
setblock ~124 ~122 ~53 dirt
setblock ~124 ~122 ~54 dirt
setblock ~124 ~122 ~55 dirt
setblock ~124 ~122 ~56 dirt
setblock ~124 ~122 ~57 dirt
setblock ~124 ~122 ~58 dirt
setblock ~124 ~122 ~59 dirt
setblock ~124 ~122 ~60 dirt
setblock ~124 ~122 ~61 dirt
setblock ~124 ~122 ~62 dirt
setblock ~124 ~122 ~63 dirt
setblock ~124 ~122 ~64 dirt
setblock ~124 ~122 ~65 dirt
setblock ~124 ~122 ~66 dirt
setblock ~124 ~122 ~67 dirt
setblock ~124 ~122 ~68 dirt
setblock ~124 ~122 ~69 dirt
setblock ~124 ~122 ~70 dirt
setblock ~124 ~122 ~71 dirt
setblock ~124 ~122 ~72 dirt
setblock ~124 ~122 ~73 dirt
setblock ~124 ~122 ~74 dirt
setblock ~124 ~122 ~75 dirt
setblock ~124 ~122 ~76 dirt
setblock ~124 ~122 ~77 dirt
setblock ~124 ~122 ~78 dirt
setblock ~124 ~122 ~79 dirt
setblock ~124 ~122 ~80 dirt
setblock ~124 ~122 ~81 dirt
setblock ~124 ~122 ~82 dirt
setblock ~124 ~122 ~83 dirt
setblock ~124 ~122 ~84 dirt
setblock ~124 ~122 ~85 dirt
setblock ~124 ~122 ~86 dirt
setblock ~124 ~122 ~87 dirt
setblock ~124 ~122 ~88 dirt
setblock ~124 ~122 ~89 dirt
setblock ~124 ~122 ~90 dirt
setblock ~124 ~122 ~91 dirt
setblock ~124 ~122 ~92 dirt
setblock ~124 ~122 ~93 dirt
setblock ~124 ~122 ~94 dirt
setblock ~124 ~122 ~95 dirt
setblock ~124 ~122 ~96 dirt
setblock ~124 ~122 ~97 dirt
setblock ~124 ~122 ~98 dirt
setblock ~124 ~122 ~99 dirt
setblock ~124 ~122 ~100 dirt
setblock ~124 ~122 ~101 dirt
setblock ~124 ~122 ~102 dirt
setblock ~124 ~122 ~103 dirt
setblock ~124 ~122 ~104 dirt
setblock ~124 ~122 ~105 dirt
setblock ~124 ~122 ~106 dirt
setblock ~124 ~122 ~107 dirt
setblock ~124 ~122 ~108 dirt
setblock ~124 ~122 ~109 dirt
setblock ~124 ~122 ~110 dirt
setblock ~124 ~122 ~111 dirt
setblock ~124 ~122 ~112 dirt
setblock ~124 ~122 ~113 dirt
setblock ~124 ~122 ~114 dirt
setblock ~124 ~122 ~115 dirt
setblock ~124 ~122 ~116 dirt
setblock ~124 ~122 ~117 dirt
setblock ~124 ~122 ~118 dirt
setblock ~124 ~122 ~119 dirt
setblock ~124 ~122 ~120 dirt
setblock ~124 ~122 ~121 dirt
setblock ~124 ~122 ~122 dirt
setblock ~124 ~122 ~123 dirt
setblock ~124 ~122 ~124 dirt
setblock ~124 ~122 ~125 dirt
setblock ~124 ~122 ~126 dirt
setblock ~124 ~122 ~127 dirt
setblock ~124 ~122 ~128 dirt
setblock ~124 ~122 ~129 dirt
setblock ~124 ~122 ~130 dirt
setblock ~124 ~122 ~131 dirt
setblock ~124 ~122 ~132 dirt
setblock ~124 ~122 ~133 dirt
setblock ~124 ~122 ~134 dirt
setblock ~124 ~122 ~135 dirt
setblock ~124 ~122 ~136 dirt
setblock ~124 ~122 ~137 dirt
setblock ~124 ~122 ~138 dirt
setblock ~124 ~122 ~139 dirt
setblock ~124 ~122 ~140 dirt
setblock ~124 ~122 ~141 dirt
setblock ~124 ~122 ~142 dirt
setblock ~124 ~122 ~143 dirt
setblock ~124 ~122 ~144 dirt
setblock ~124 ~122 ~145 dirt
setblock ~124 ~122 ~146 dirt
setblock ~124 ~122 ~147 dirt
setblock ~124 ~122 ~148 dirt
setblock ~124 ~122 ~149 dirt
setblock ~124 ~122 ~150 dirt
setblock ~124 ~122 ~151 dirt
setblock ~124 ~122 ~152 dirt
setblock ~124 ~122 ~153 dirt
setblock ~124 ~122 ~154 dirt
setblock ~124 ~122 ~155 dirt
setblock ~124 ~122 ~156 dirt
setblock ~124 ~122 ~157 dirt
setblock ~124 ~122 ~158 dirt
setblock ~124 ~122 ~159 dirt
setblock ~124 ~122 ~160 dirt
setblock ~124 ~122 ~161 dirt
setblock ~124 ~122 ~162 dirt
setblock ~124 ~122 ~163 dirt
setblock ~124 ~122 ~164 dirt
setblock ~124 ~122 ~165 dirt
setblock ~124 ~122 ~166 dirt
setblock ~124 ~122 ~167 dirt
setblock ~124 ~122 ~168 dirt
setblock ~124 ~122 ~169 dirt
setblock ~124 ~122 ~170 dirt
setblock ~124 ~122 ~171 dirt
setblock ~124 ~122 ~172 dirt
setblock ~124 ~122 ~173 dirt
setblock ~124 ~122 ~174 dirt
setblock ~124 ~122 ~175 dirt
setblock ~124 ~122 ~176 dirt
setblock ~124 ~122 ~177 dirt
setblock ~124 ~122 ~178 dirt
setblock ~124 ~122 ~179 dirt
setblock ~124 ~122 ~180 dirt
setblock ~124 ~122 ~181 dirt
setblock ~124 ~122 ~182 dirt
setblock ~124 ~122 ~183 dirt
setblock ~124 ~122 ~184 dirt
setblock ~124 ~122 ~185 dirt
setblock ~124 ~122 ~186 dirt
setblock ~124 ~122 ~187 dirt
setblock ~124 ~122 ~188 dirt
setblock ~124 ~122 ~189 dirt
setblock ~124 ~122 ~190 grass_block
setblock ~124 ~122 ~191 dirt
setblock ~124 ~122 ~192 dirt
setblock ~124 ~122 ~193 dirt
setblock ~124 ~122 ~194 dirt
setblock ~124 ~122 ~195 dirt
setblock ~124 ~122 ~196 dirt
setblock ~124 ~122 ~197 dirt
setblock ~124 ~122 ~198 dirt
setblock ~124 ~122 ~199 dirt
setblock ~124 ~123 ~0 dirt
setblock ~124 ~123 ~1 dirt
setblock ~124 ~123 ~2 dirt
setblock ~124 ~123 ~3 dirt
setblock ~124 ~123 ~4 dirt
setblock ~124 ~123 ~5 dirt
setblock ~124 ~123 ~6 dirt
setblock ~124 ~123 ~7 dirt
setblock ~124 ~123 ~8 dirt
setblock ~124 ~123 ~9 dirt
setblock ~124 ~123 ~10 dirt
setblock ~124 ~123 ~11 dirt
setblock ~124 ~123 ~12 dirt
setblock ~124 ~123 ~13 dirt
setblock ~124 ~123 ~14 dirt
setblock ~124 ~123 ~15 dirt
setblock ~124 ~123 ~16 dirt
setblock ~124 ~123 ~17 dirt
setblock ~124 ~123 ~18 dirt
setblock ~124 ~123 ~19 dirt
setblock ~124 ~123 ~20 dirt
setblock ~124 ~123 ~21 dirt
setblock ~124 ~123 ~22 dirt
setblock ~124 ~123 ~23 dirt
setblock ~124 ~123 ~24 dirt
setblock ~124 ~123 ~25 grass_block
setblock ~124 ~123 ~26 grass_block
setblock ~124 ~123 ~27 grass_block
setblock ~124 ~123 ~28 grass_block
setblock ~124 ~123 ~29 grass_block
setblock ~124 ~123 ~30 grass_block
setblock ~124 ~123 ~31 grass_block
setblock ~124 ~123 ~32 grass_block
setblock ~124 ~123 ~33 grass_block
setblock ~124 ~123 ~34 grass_block
setblock ~124 ~123 ~35 dirt
setblock ~124 ~123 ~36 dirt
setblock ~124 ~123 ~37 dirt
setblock ~124 ~123 ~38 dirt
setblock ~124 ~123 ~39 dirt
setblock ~124 ~123 ~40 dirt
setblock ~124 ~123 ~41 dirt
setblock ~124 ~123 ~42 dirt
setblock ~124 ~123 ~43 dirt
setblock ~124 ~123 ~44 dirt
setblock ~124 ~123 ~45 dirt
setblock ~124 ~123 ~46 dirt
setblock ~124 ~123 ~47 dirt
setblock ~124 ~123 ~48 dirt
setblock ~124 ~123 ~49 dirt
setblock ~124 ~123 ~50 dirt
setblock ~124 ~123 ~51 dirt
setblock ~124 ~123 ~52 dirt
setblock ~124 ~123 ~53 dirt
setblock ~124 ~123 ~54 dirt
setblock ~124 ~123 ~55 dirt
setblock ~124 ~123 ~56 dirt
setblock ~124 ~123 ~57 dirt
setblock ~124 ~123 ~58 dirt
setblock ~124 ~123 ~59 dirt
setblock ~124 ~123 ~60 dirt
setblock ~124 ~123 ~61 dirt
setblock ~124 ~123 ~62 dirt
setblock ~124 ~123 ~63 dirt
setblock ~124 ~123 ~64 dirt
setblock ~124 ~123 ~65 dirt
setblock ~124 ~123 ~66 dirt
setblock ~124 ~123 ~67 dirt
setblock ~124 ~123 ~68 dirt
setblock ~124 ~123 ~69 dirt
setblock ~124 ~123 ~70 dirt
setblock ~124 ~123 ~71 dirt
setblock ~124 ~123 ~72 dirt
setblock ~124 ~123 ~73 dirt
setblock ~124 ~123 ~74 dirt
setblock ~124 ~123 ~75 dirt
setblock ~124 ~123 ~76 dirt
setblock ~124 ~123 ~77 dirt
setblock ~124 ~123 ~78 dirt
setblock ~124 ~123 ~79 dirt
setblock ~124 ~123 ~80 dirt
setblock ~124 ~123 ~81 dirt
setblock ~124 ~123 ~82 dirt
setblock ~124 ~123 ~83 dirt
setblock ~124 ~123 ~84 dirt
setblock ~124 ~123 ~85 dirt
setblock ~124 ~123 ~86 dirt
setblock ~124 ~123 ~87 dirt
setblock ~124 ~123 ~88 dirt
setblock ~124 ~123 ~89 dirt
setblock ~124 ~123 ~90 dirt
setblock ~124 ~123 ~91 dirt
setblock ~124 ~123 ~92 dirt
setblock ~124 ~123 ~93 dirt
setblock ~124 ~123 ~94 dirt
setblock ~124 ~123 ~95 dirt
setblock ~124 ~123 ~96 dirt
setblock ~124 ~123 ~97 dirt
setblock ~124 ~123 ~98 dirt
setblock ~124 ~123 ~99 dirt
setblock ~124 ~123 ~100 dirt
setblock ~124 ~123 ~101 dirt
setblock ~124 ~123 ~102 dirt
setblock ~124 ~123 ~103 dirt
setblock ~124 ~123 ~104 dirt
setblock ~124 ~123 ~105 dirt
setblock ~124 ~123 ~106 dirt
setblock ~124 ~123 ~107 dirt
setblock ~124 ~123 ~108 dirt
setblock ~124 ~123 ~109 dirt
setblock ~124 ~123 ~110 grass_block
setblock ~124 ~123 ~111 grass_block
setblock ~124 ~123 ~112 dirt
setblock ~124 ~123 ~113 dirt
setblock ~124 ~123 ~114 dirt
setblock ~124 ~123 ~115 dirt
setblock ~124 ~123 ~116 dirt
setblock ~124 ~123 ~117 dirt
setblock ~124 ~123 ~118 dirt
setblock ~124 ~123 ~119 dirt
setblock ~124 ~123 ~120 dirt
setblock ~124 ~123 ~121 dirt
setblock ~124 ~123 ~122 dirt
setblock ~124 ~123 ~123 dirt
setblock ~124 ~123 ~124 dirt
setblock ~124 ~123 ~125 dirt
setblock ~124 ~123 ~126 dirt
setblock ~124 ~123 ~127 dirt
setblock ~124 ~123 ~128 dirt
setblock ~124 ~123 ~129 dirt
setblock ~124 ~123 ~130 dirt
setblock ~124 ~123 ~131 dirt
setblock ~124 ~123 ~132 dirt
setblock ~124 ~123 ~133 dirt
setblock ~124 ~123 ~134 dirt
setblock ~124 ~123 ~135 dirt
setblock ~124 ~123 ~136 dirt
setblock ~124 ~123 ~137 dirt
setblock ~124 ~123 ~138 dirt
setblock ~124 ~123 ~139 dirt
setblock ~124 ~123 ~140 dirt
setblock ~124 ~123 ~141 dirt
setblock ~124 ~123 ~142 dirt
setblock ~124 ~123 ~143 dirt
setblock ~124 ~123 ~144 dirt
setblock ~124 ~123 ~145 dirt
setblock ~124 ~123 ~146 dirt
setblock ~124 ~123 ~147 dirt
setblock ~124 ~123 ~148 dirt
setblock ~124 ~123 ~149 dirt
setblock ~124 ~123 ~150 dirt
setblock ~124 ~123 ~151 dirt
setblock ~124 ~123 ~152 dirt
setblock ~124 ~123 ~153 dirt
setblock ~124 ~123 ~154 dirt
setblock ~124 ~123 ~155 dirt
setblock ~124 ~123 ~156 dirt
setblock ~124 ~123 ~157 dirt
setblock ~124 ~123 ~158 dirt
setblock ~124 ~123 ~159 dirt
setblock ~124 ~123 ~160 dirt
setblock ~124 ~123 ~161 dirt
setblock ~124 ~123 ~162 dirt
setblock ~124 ~123 ~163 dirt
setblock ~124 ~123 ~164 dirt
setblock ~124 ~123 ~165 dirt
setblock ~124 ~123 ~166 dirt
setblock ~124 ~123 ~167 dirt
setblock ~124 ~123 ~168 dirt
setblock ~124 ~123 ~169 dirt
setblock ~124 ~123 ~170 dirt
setblock ~124 ~123 ~171 dirt
setblock ~124 ~123 ~172 dirt
setblock ~124 ~123 ~173 dirt
setblock ~124 ~123 ~174 dirt
setblock ~124 ~123 ~175 dirt
setblock ~124 ~123 ~176 dirt
setblock ~124 ~123 ~177 dirt
setblock ~124 ~123 ~178 dirt
setblock ~124 ~123 ~179 dirt
setblock ~124 ~123 ~180 dirt
setblock ~124 ~123 ~181 dirt
setblock ~124 ~123 ~182 dirt
setblock ~124 ~123 ~183 grass_block
setblock ~124 ~123 ~184 grass_block
setblock ~124 ~123 ~185 grass_block
setblock ~124 ~123 ~186 grass_block
setblock ~124 ~123 ~187 grass_block
setblock ~124 ~123 ~188 grass_block
setblock ~124 ~123 ~189 grass_block
setblock ~124 ~123 ~191 grass_block
setblock ~124 ~123 ~192 grass_block
setblock ~124 ~123 ~193 grass_block
setblock ~124 ~123 ~194 grass_block
setblock ~124 ~123 ~195 grass_block
setblock ~124 ~123 ~196 grass_block
setblock ~124 ~123 ~197 grass_block
setblock ~124 ~123 ~198 grass_block
setblock ~124 ~123 ~199 dirt
setblock ~124 ~124 ~0 dirt
setblock ~124 ~124 ~1 dirt
setblock ~124 ~124 ~2 dirt
setblock ~124 ~124 ~3 dirt
setblock ~124 ~124 ~4 dirt
setblock ~124 ~124 ~5 dirt
setblock ~124 ~124 ~6 dirt
setblock ~124 ~124 ~7 dirt
setblock ~124 ~124 ~8 dirt
setblock ~124 ~124 ~9 dirt
setblock ~124 ~124 ~10 dirt
setblock ~124 ~124 ~11 dirt
setblock ~124 ~124 ~12 dirt
setblock ~124 ~124 ~13 dirt
setblock ~124 ~124 ~14 dirt
setblock ~124 ~124 ~15 dirt
setblock ~124 ~124 ~16 dirt
setblock ~124 ~124 ~17 dirt
setblock ~124 ~124 ~18 dirt
setblock ~124 ~124 ~19 dirt
setblock ~124 ~124 ~20 grass_block
setblock ~124 ~124 ~21 grass_block
setblock ~124 ~124 ~22 grass_block
setblock ~124 ~124 ~23 grass_block
setblock ~124 ~124 ~24 grass_block
setblock ~124 ~124 ~25 short_grass
setblock ~124 ~124 ~27 short_grass
setblock ~124 ~124 ~35 grass_block
setblock ~124 ~124 ~36 grass_block
setblock ~124 ~124 ~37 grass_block
setblock ~124 ~124 ~38 dirt
setblock ~124 ~124 ~39 dirt
setblock ~124 ~124 ~40 dirt
setblock ~124 ~124 ~41 dirt
setblock ~124 ~124 ~42 dirt
setblock ~124 ~124 ~43 dirt
setblock ~124 ~124 ~44 dirt
setblock ~124 ~124 ~45 dirt
setblock ~124 ~124 ~46 dirt
setblock ~124 ~124 ~47 dirt
setblock ~124 ~124 ~48 dirt
setblock ~124 ~124 ~49 dirt
setblock ~124 ~124 ~50 dirt
setblock ~124 ~124 ~51 dirt
setblock ~124 ~124 ~52 dirt
setblock ~124 ~124 ~53 dirt
setblock ~124 ~124 ~54 dirt
setblock ~124 ~124 ~55 dirt
setblock ~124 ~124 ~56 dirt
setblock ~124 ~124 ~57 dirt
setblock ~124 ~124 ~58 dirt
setblock ~124 ~124 ~59 dirt
setblock ~124 ~124 ~60 dirt
setblock ~124 ~124 ~61 dirt
setblock ~124 ~124 ~62 dirt
setblock ~124 ~124 ~63 dirt
setblock ~124 ~124 ~64 dirt
setblock ~124 ~124 ~65 dirt
setblock ~124 ~124 ~66 dirt
setblock ~124 ~124 ~67 dirt
setblock ~124 ~124 ~68 dirt
setblock ~124 ~124 ~69 dirt
setblock ~124 ~124 ~70 dirt
setblock ~124 ~124 ~71 dirt
setblock ~124 ~124 ~72 dirt
setblock ~124 ~124 ~73 dirt
setblock ~124 ~124 ~74 dirt
setblock ~124 ~124 ~75 dirt
setblock ~124 ~124 ~76 dirt
setblock ~124 ~124 ~77 dirt
setblock ~124 ~124 ~78 dirt
setblock ~124 ~124 ~79 dirt
setblock ~124 ~124 ~80 dirt
setblock ~124 ~124 ~81 dirt
setblock ~124 ~124 ~82 dirt
setblock ~124 ~124 ~83 dirt
setblock ~124 ~124 ~84 dirt
setblock ~124 ~124 ~85 dirt
setblock ~124 ~124 ~86 dirt
setblock ~124 ~124 ~87 dirt
setblock ~124 ~124 ~88 dirt
setblock ~124 ~124 ~89 dirt
setblock ~124 ~124 ~90 dirt
setblock ~124 ~124 ~91 dirt
setblock ~124 ~124 ~92 dirt
setblock ~124 ~124 ~93 dirt
setblock ~124 ~124 ~94 dirt
setblock ~124 ~124 ~95 dirt
setblock ~124 ~124 ~96 dirt
setblock ~124 ~124 ~97 dirt
setblock ~124 ~124 ~98 dirt
setblock ~124 ~124 ~99 dirt
setblock ~124 ~124 ~100 dirt
setblock ~124 ~124 ~101 dirt
setblock ~124 ~124 ~102 dirt
setblock ~124 ~124 ~103 grass_block
setblock ~124 ~124 ~104 grass_block
setblock ~124 ~124 ~105 grass_block
setblock ~124 ~124 ~106 grass_block
setblock ~124 ~124 ~107 grass_block
setblock ~124 ~124 ~108 grass_block
setblock ~124 ~124 ~109 grass_block
setblock ~124 ~124 ~112 grass_block
setblock ~124 ~124 ~113 grass_block
setblock ~124 ~124 ~114 grass_block
setblock ~124 ~124 ~115 grass_block
setblock ~124 ~124 ~116 grass_block
setblock ~124 ~124 ~117 grass_block
setblock ~124 ~124 ~118 dirt
setblock ~124 ~124 ~119 dirt
setblock ~124 ~124 ~120 dirt
setblock ~124 ~124 ~121 dirt
setblock ~124 ~124 ~122 dirt
setblock ~124 ~124 ~123 dirt
setblock ~124 ~124 ~124 dirt
setblock ~124 ~124 ~125 dirt
setblock ~124 ~124 ~126 dirt
setblock ~124 ~124 ~127 dirt
setblock ~124 ~124 ~128 dirt
setblock ~124 ~124 ~129 dirt
setblock ~124 ~124 ~130 dirt
setblock ~124 ~124 ~131 dirt
setblock ~124 ~124 ~132 dirt
setblock ~124 ~124 ~133 dirt
setblock ~124 ~124 ~134 dirt
setblock ~124 ~124 ~135 dirt
setblock ~124 ~124 ~136 dirt
setblock ~124 ~124 ~137 dirt
setblock ~124 ~124 ~138 dirt
setblock ~124 ~124 ~139 dirt
setblock ~124 ~124 ~140 dirt
setblock ~124 ~124 ~141 dirt
setblock ~124 ~124 ~142 dirt
setblock ~124 ~124 ~143 dirt
setblock ~124 ~124 ~144 dirt
setblock ~124 ~124 ~145 dirt
setblock ~124 ~124 ~146 dirt
setblock ~124 ~124 ~147 grass_block
setblock ~124 ~124 ~148 grass_block
setblock ~124 ~124 ~149 grass_block
setblock ~124 ~124 ~150 grass_block
setblock ~124 ~124 ~151 grass_block
setblock ~124 ~124 ~152 grass_block
setblock ~124 ~124 ~153 grass_block
setblock ~124 ~124 ~154 grass_block
setblock ~124 ~124 ~155 grass_block
setblock ~124 ~124 ~156 grass_block
setblock ~124 ~124 ~157 grass_block
setblock ~124 ~124 ~158 grass_block
setblock ~124 ~124 ~159 grass_block
setblock ~124 ~124 ~160 grass_block
setblock ~124 ~124 ~161 grass_block
setblock ~124 ~124 ~162 dirt
setblock ~124 ~124 ~163 dirt
setblock ~124 ~124 ~164 dirt
setblock ~124 ~124 ~165 dirt
setblock ~124 ~124 ~166 dirt
setblock ~124 ~124 ~167 dirt
setblock ~124 ~124 ~168 dirt
setblock ~124 ~124 ~169 dirt
setblock ~124 ~124 ~170 dirt
setblock ~124 ~124 ~171 dirt
setblock ~124 ~124 ~172 dirt
setblock ~124 ~124 ~173 dirt
setblock ~124 ~124 ~174 dirt
setblock ~124 ~124 ~175 dirt
setblock ~124 ~124 ~176 dirt
setblock ~124 ~124 ~177 dirt
setblock ~124 ~124 ~178 dirt
setblock ~124 ~124 ~179 grass_block
setblock ~124 ~124 ~180 grass_block
setblock ~124 ~124 ~181 grass_block
setblock ~124 ~124 ~182 grass_block
setblock ~124 ~124 ~185 short_grass
setblock ~124 ~124 ~187 short_grass
setblock ~124 ~124 ~189 short_grass
setblock ~124 ~124 ~193 fern
setblock ~124 ~124 ~199 grass_block
setblock ~124 ~125 ~0 grass_block
setblock ~124 ~125 ~1 grass_block
setblock ~124 ~125 ~2 grass_block
setblock ~124 ~125 ~3 grass_block
setblock ~124 ~125 ~4 grass_block
setblock ~124 ~125 ~5 grass_block
setblock ~124 ~125 ~6 grass_block
setblock ~124 ~125 ~7 grass_block
setblock ~124 ~125 ~8 grass_block
setblock ~124 ~125 ~9 grass_block
setblock ~124 ~125 ~10 grass_block
setblock ~124 ~125 ~11 grass_block
setblock ~124 ~125 ~12 grass_block
setblock ~124 ~125 ~13 grass_block
setblock ~124 ~125 ~14 grass_block
setblock ~124 ~125 ~15 grass_block
setblock ~124 ~125 ~16 grass_block
setblock ~124 ~125 ~17 grass_block
setblock ~124 ~125 ~18 grass_block
setblock ~124 ~125 ~19 grass_block
setblock ~124 ~125 ~38 grass_block
setblock ~124 ~125 ~39 grass_block
setblock ~124 ~125 ~40 grass_block
setblock ~124 ~125 ~41 grass_block
setblock ~124 ~125 ~42 grass_block
setblock ~124 ~125 ~43 grass_block
setblock ~124 ~125 ~44 grass_block
setblock ~124 ~125 ~45 grass_block
setblock ~124 ~125 ~46 grass_block
setblock ~124 ~125 ~47 grass_block
setblock ~124 ~125 ~48 grass_block
setblock ~124 ~125 ~49 grass_block
setblock ~124 ~125 ~50 grass_block
setblock ~124 ~125 ~51 grass_block
setblock ~124 ~125 ~52 grass_block
setblock ~124 ~125 ~53 grass_block
setblock ~124 ~125 ~54 grass_block
setblock ~124 ~125 ~55 grass_block
setblock ~124 ~125 ~56 dirt
setblock ~124 ~125 ~57 dirt
setblock ~124 ~125 ~58 dirt
setblock ~124 ~125 ~59 dirt
setblock ~124 ~125 ~60 dirt
setblock ~124 ~125 ~61 dirt
setblock ~124 ~125 ~62 dirt
setblock ~124 ~125 ~63 dirt
setblock ~124 ~125 ~64 dirt
setblock ~124 ~125 ~65 dirt
setblock ~124 ~125 ~66 dirt
setblock ~124 ~125 ~67 dirt
setblock ~124 ~125 ~68 dirt
setblock ~124 ~125 ~69 dirt
setblock ~124 ~125 ~70 dirt
setblock ~124 ~125 ~71 dirt
setblock ~124 ~125 ~72 dirt
setblock ~124 ~125 ~73 dirt
setblock ~124 ~125 ~74 dirt
setblock ~124 ~125 ~75 dirt
setblock ~124 ~125 ~76 dirt
setblock ~124 ~125 ~77 dirt
setblock ~124 ~125 ~78 grass_block
setblock ~124 ~125 ~79 grass_block
setblock ~124 ~125 ~80 grass_block
setblock ~124 ~125 ~81 grass_block
setblock ~124 ~125 ~82 grass_block
setblock ~124 ~125 ~83 dirt
setblock ~124 ~125 ~84 dirt
setblock ~124 ~125 ~85 dirt
setblock ~124 ~125 ~86 dirt
setblock ~124 ~125 ~87 dirt
setblock ~124 ~125 ~88 dirt
setblock ~124 ~125 ~89 dirt
setblock ~124 ~125 ~90 dirt
setblock ~124 ~125 ~91 dirt
setblock ~124 ~125 ~92 dirt
setblock ~124 ~125 ~93 dirt
setblock ~124 ~125 ~94 dirt
setblock ~124 ~125 ~95 dirt
setblock ~124 ~125 ~96 grass_block
setblock ~124 ~125 ~97 grass_block
setblock ~124 ~125 ~98 grass_block
setblock ~124 ~125 ~99 grass_block
setblock ~124 ~125 ~100 grass_block
setblock ~124 ~125 ~101 grass_block
setblock ~124 ~125 ~102 grass_block
setblock ~124 ~125 ~118 grass_block
setblock ~124 ~125 ~119 grass_block
setblock ~124 ~125 ~120 grass_block
setblock ~124 ~125 ~121 grass_block
setblock ~124 ~125 ~122 grass_block
setblock ~124 ~125 ~123 grass_block
setblock ~124 ~125 ~124 grass_block
setblock ~124 ~125 ~125 grass_block
setblock ~124 ~125 ~126 grass_block
setblock ~124 ~125 ~127 grass_block
setblock ~124 ~125 ~128 grass_block
setblock ~124 ~125 ~129 grass_block
setblock ~124 ~125 ~130 grass_block
setblock ~124 ~125 ~131 grass_block
setblock ~124 ~125 ~132 grass_block
setblock ~124 ~125 ~133 grass_block
setblock ~124 ~125 ~134 grass_block
setblock ~124 ~125 ~135 grass_block
setblock ~124 ~125 ~136 grass_block
setblock ~124 ~125 ~137 grass_block
setblock ~124 ~125 ~138 dirt
setblock ~124 ~125 ~139 dirt
setblock ~124 ~125 ~140 dirt
setblock ~124 ~125 ~141 dirt
setblock ~124 ~125 ~142 grass_block
setblock ~124 ~125 ~143 grass_block
setblock ~124 ~125 ~144 grass_block
setblock ~124 ~125 ~145 grass_block
setblock ~124 ~125 ~146 grass_block
setblock ~124 ~125 ~151 short_grass
setblock ~124 ~125 ~154 short_grass
setblock ~124 ~125 ~156 short_grass
setblock ~124 ~125 ~158 short_grass
setblock ~124 ~125 ~160 short_grass
setblock ~124 ~125 ~162 grass_block
setblock ~124 ~125 ~163 grass_block
setblock ~124 ~125 ~164 grass_block
setblock ~124 ~125 ~165 grass_block
setblock ~124 ~125 ~166 dirt
setblock ~124 ~125 ~167 dirt
setblock ~124 ~125 ~168 dirt
setblock ~124 ~125 ~169 dirt
setblock ~124 ~125 ~170 dirt
setblock ~124 ~125 ~171 dirt
setblock ~124 ~125 ~172 dirt
setblock ~124 ~125 ~173 dirt
setblock ~124 ~125 ~174 dirt
setblock ~124 ~125 ~175 dirt
setblock ~124 ~125 ~176 grass_block
setblock ~124 ~125 ~177 grass_block
setblock ~124 ~125 ~178 grass_block
setblock ~124 ~125 ~181 short_grass
setblock ~124 ~125 ~182 poppy
setblock ~124 ~126 ~0 short_grass
setblock ~124 ~126 ~2 poppy
setblock ~124 ~126 ~3 short_grass
setblock ~124 ~126 ~5 short_grass
setblock ~124 ~126 ~7 fern
setblock ~124 ~126 ~8 short_grass
setblock ~124 ~126 ~9 short_grass
setblock ~124 ~126 ~12 fern
setblock ~124 ~126 ~14 poppy
setblock ~124 ~126 ~17 short_grass
setblock ~124 ~126 ~18 short_grass
setblock ~124 ~126 ~47 short_grass
setblock ~124 ~126 ~53 fern
setblock ~124 ~126 ~56 grass_block
setblock ~124 ~126 ~57 grass_block
setblock ~124 ~126 ~58 grass_block
setblock ~124 ~126 ~59 dirt
setblock ~124 ~126 ~60 dirt
setblock ~124 ~126 ~61 dirt
setblock ~124 ~126 ~62 dirt
setblock ~124 ~126 ~63 dirt
setblock ~124 ~126 ~64 dirt
setblock ~124 ~126 ~65 dirt
setblock ~124 ~126 ~66 dirt
setblock ~124 ~126 ~67 dirt
setblock ~124 ~126 ~68 dirt
setblock ~124 ~126 ~69 grass_block
setblock ~124 ~126 ~70 grass_block
setblock ~124 ~126 ~71 grass_block
setblock ~124 ~126 ~72 grass_block
setblock ~124 ~126 ~73 grass_block
setblock ~124 ~126 ~74 grass_block
setblock ~124 ~126 ~75 grass_block
setblock ~124 ~126 ~76 grass_block
setblock ~124 ~126 ~77 grass_block
setblock ~124 ~126 ~78 short_grass
setblock ~124 ~126 ~79 poppy
setblock ~124 ~126 ~81 short_grass
setblock ~124 ~126 ~83 grass_block
setblock ~124 ~126 ~84 grass_block
setblock ~124 ~126 ~85 grass_block
setblock ~124 ~126 ~86 grass_block
setblock ~124 ~126 ~87 grass_block
setblock ~124 ~126 ~88 grass_block
setblock ~124 ~126 ~89 dirt
setblock ~124 ~126 ~90 dirt
setblock ~124 ~126 ~91 grass_block
setblock ~124 ~126 ~92 grass_block
setblock ~124 ~126 ~93 grass_block
setblock ~124 ~126 ~94 grass_block
setblock ~124 ~126 ~95 grass_block
setblock ~124 ~126 ~98 fern
setblock ~124 ~126 ~101 short_grass
setblock ~124 ~126 ~121 short_grass
setblock ~124 ~126 ~122 short_grass
setblock ~124 ~126 ~124 short_grass
setblock ~124 ~126 ~125 short_grass
setblock ~124 ~126 ~126 short_grass
setblock ~124 ~126 ~132 short_grass
setblock ~124 ~126 ~133 short_grass
setblock ~124 ~126 ~134 short_grass
setblock ~124 ~126 ~138 grass_block
setblock ~124 ~126 ~139 grass_block
setblock ~124 ~126 ~140 grass_block
setblock ~124 ~126 ~141 grass_block
setblock ~124 ~126 ~142 poppy
setblock ~124 ~126 ~145 short_grass
setblock ~124 ~126 ~166 grass_block
setblock ~124 ~126 ~167 grass_block
setblock ~124 ~126 ~168 grass_block
setblock ~124 ~126 ~169 dirt
setblock ~124 ~126 ~170 dirt
setblock ~124 ~126 ~171 dirt
setblock ~124 ~126 ~172 dirt
setblock ~124 ~126 ~173 grass_block
setblock ~124 ~126 ~174 grass_block
setblock ~124 ~126 ~175 grass_block
setblock ~124 ~127 ~59 grass_block
setblock ~124 ~127 ~60 grass_block
setblock ~124 ~127 ~61 grass_block
setblock ~124 ~127 ~62 grass_block
setblock ~124 ~127 ~63 grass_block
setblock ~124 ~127 ~64 grass_block
setblock ~124 ~127 ~65 grass_block
setblock ~124 ~127 ~66 grass_block
setblock ~124 ~127 ~67 grass_block
setblock ~124 ~127 ~68 grass_block
setblock ~124 ~127 ~69 short_grass
setblock ~124 ~127 ~77 fern
setblock ~124 ~127 ~89 grass_block
setblock ~124 ~127 ~90 grass_block
setblock ~124 ~127 ~138 short_grass
setblock ~124 ~127 ~141 short_grass
setblock ~124 ~127 ~167 short_grass
setblock ~124 ~127 ~169 grass_block
setblock ~124 ~127 ~170 grass_block
setblock ~124 ~127 ~171 grass_block
setblock ~124 ~127 ~172 grass_block
setblock ~124 ~127 ~173 fern
setblock ~124 ~128 ~59 poppy
setblock ~124 ~128 ~61 short_grass
setblock ~124 ~128 ~63 short_grass
setblock ~124 ~128 ~67 short_grass
setblock ~124 ~128 ~169 short_grass
setblock ~124 ~128 ~172 short_grass
setblock ~125 ~122 ~0 dirt
setblock ~125 ~122 ~1 dirt
setblock ~125 ~122 ~2 dirt
setblock ~125 ~122 ~3 dirt
setblock ~125 ~122 ~4 dirt
setblock ~125 ~122 ~5 dirt
setblock ~125 ~122 ~6 dirt
setblock ~125 ~122 ~7 dirt
setblock ~125 ~122 ~8 dirt
setblock ~125 ~122 ~9 dirt
setblock ~125 ~122 ~10 dirt
setblock ~125 ~122 ~11 dirt
setblock ~125 ~122 ~12 dirt
setblock ~125 ~122 ~13 dirt
setblock ~125 ~122 ~14 dirt
setblock ~125 ~122 ~15 dirt
setblock ~125 ~122 ~16 dirt
setblock ~125 ~122 ~17 dirt
setblock ~125 ~122 ~18 dirt
setblock ~125 ~122 ~19 dirt
setblock ~125 ~122 ~20 dirt
setblock ~125 ~122 ~21 dirt
setblock ~125 ~122 ~22 dirt
setblock ~125 ~122 ~23 dirt
setblock ~125 ~122 ~24 dirt
setblock ~125 ~122 ~25 dirt
setblock ~125 ~122 ~26 dirt
setblock ~125 ~122 ~27 dirt
setblock ~125 ~122 ~28 dirt
setblock ~125 ~122 ~29 dirt
setblock ~125 ~122 ~30 dirt
setblock ~125 ~122 ~31 dirt
setblock ~125 ~122 ~32 dirt
setblock ~125 ~122 ~33 dirt
setblock ~125 ~122 ~34 dirt
setblock ~125 ~122 ~35 dirt
setblock ~125 ~122 ~36 dirt
setblock ~125 ~122 ~37 dirt
setblock ~125 ~122 ~38 dirt
setblock ~125 ~122 ~39 dirt
setblock ~125 ~122 ~40 dirt
setblock ~125 ~122 ~41 dirt
setblock ~125 ~122 ~42 dirt
setblock ~125 ~122 ~43 dirt
setblock ~125 ~122 ~44 dirt
setblock ~125 ~122 ~45 dirt
setblock ~125 ~122 ~46 dirt
setblock ~125 ~122 ~47 dirt
setblock ~125 ~122 ~48 dirt
setblock ~125 ~122 ~49 dirt
setblock ~125 ~122 ~50 dirt
setblock ~125 ~122 ~51 dirt
setblock ~125 ~122 ~52 dirt
setblock ~125 ~122 ~53 dirt
setblock ~125 ~122 ~54 dirt
setblock ~125 ~122 ~55 dirt
setblock ~125 ~122 ~56 dirt
setblock ~125 ~122 ~57 dirt
setblock ~125 ~122 ~58 dirt
setblock ~125 ~122 ~59 dirt
setblock ~125 ~122 ~60 dirt
setblock ~125 ~122 ~61 dirt
setblock ~125 ~122 ~62 dirt
setblock ~125 ~122 ~63 dirt
setblock ~125 ~122 ~64 dirt
setblock ~125 ~122 ~65 dirt
setblock ~125 ~122 ~66 dirt
setblock ~125 ~122 ~67 dirt
setblock ~125 ~122 ~68 dirt
setblock ~125 ~122 ~69 dirt
setblock ~125 ~122 ~70 dirt
setblock ~125 ~122 ~71 dirt
setblock ~125 ~122 ~72 dirt
setblock ~125 ~122 ~73 dirt
setblock ~125 ~122 ~74 dirt
setblock ~125 ~122 ~75 dirt
setblock ~125 ~122 ~76 dirt
setblock ~125 ~122 ~77 dirt
setblock ~125 ~122 ~78 dirt
setblock ~125 ~122 ~79 dirt
setblock ~125 ~122 ~80 dirt
setblock ~125 ~122 ~81 dirt
setblock ~125 ~122 ~82 dirt
setblock ~125 ~122 ~83 dirt
setblock ~125 ~122 ~84 dirt
setblock ~125 ~122 ~85 dirt
setblock ~125 ~122 ~86 dirt
setblock ~125 ~122 ~87 dirt
setblock ~125 ~122 ~88 dirt
setblock ~125 ~122 ~89 dirt
setblock ~125 ~122 ~90 dirt
setblock ~125 ~122 ~91 dirt
setblock ~125 ~122 ~92 dirt
setblock ~125 ~122 ~93 dirt
setblock ~125 ~122 ~94 dirt
setblock ~125 ~122 ~95 dirt
setblock ~125 ~122 ~96 dirt
setblock ~125 ~122 ~97 dirt
setblock ~125 ~122 ~98 dirt
setblock ~125 ~122 ~99 dirt
setblock ~125 ~122 ~100 dirt
setblock ~125 ~122 ~101 dirt
setblock ~125 ~122 ~102 dirt
setblock ~125 ~122 ~103 dirt
setblock ~125 ~122 ~104 dirt
setblock ~125 ~122 ~105 dirt
setblock ~125 ~122 ~106 dirt
setblock ~125 ~122 ~107 dirt
setblock ~125 ~122 ~108 dirt
setblock ~125 ~122 ~109 dirt
setblock ~125 ~122 ~110 dirt
setblock ~125 ~122 ~111 dirt
setblock ~125 ~122 ~112 dirt
setblock ~125 ~122 ~113 dirt
setblock ~125 ~122 ~114 dirt
setblock ~125 ~122 ~115 dirt
setblock ~125 ~122 ~116 dirt
setblock ~125 ~122 ~117 dirt
setblock ~125 ~122 ~118 dirt
setblock ~125 ~122 ~119 dirt
setblock ~125 ~122 ~120 dirt
setblock ~125 ~122 ~121 dirt
setblock ~125 ~122 ~122 dirt
setblock ~125 ~122 ~123 dirt
setblock ~125 ~122 ~124 dirt
setblock ~125 ~122 ~125 dirt
setblock ~125 ~122 ~126 dirt
setblock ~125 ~122 ~127 dirt
setblock ~125 ~122 ~128 dirt
setblock ~125 ~122 ~129 dirt
setblock ~125 ~122 ~130 dirt
setblock ~125 ~122 ~131 dirt
setblock ~125 ~122 ~132 dirt
setblock ~125 ~122 ~133 dirt
setblock ~125 ~122 ~134 dirt
setblock ~125 ~122 ~135 dirt
setblock ~125 ~122 ~136 dirt
setblock ~125 ~122 ~137 dirt
setblock ~125 ~122 ~138 dirt
