setblock ~166 ~122 ~72 dirt
setblock ~166 ~122 ~73 dirt
setblock ~166 ~122 ~74 dirt
setblock ~166 ~122 ~75 dirt
setblock ~166 ~122 ~76 dirt
setblock ~166 ~122 ~77 dirt
setblock ~166 ~122 ~78 dirt
setblock ~166 ~122 ~79 dirt
setblock ~166 ~122 ~80 dirt
setblock ~166 ~122 ~81 dirt
setblock ~166 ~122 ~82 dirt
setblock ~166 ~122 ~83 dirt
setblock ~166 ~122 ~84 dirt
setblock ~166 ~122 ~85 dirt
setblock ~166 ~122 ~86 dirt
setblock ~166 ~122 ~87 dirt
setblock ~166 ~122 ~88 dirt
setblock ~166 ~122 ~99 dirt
setblock ~166 ~122 ~100 dirt
setblock ~166 ~122 ~101 dirt
setblock ~166 ~122 ~102 dirt
setblock ~166 ~122 ~103 dirt
setblock ~166 ~122 ~104 dirt
setblock ~166 ~122 ~105 dirt
setblock ~166 ~122 ~106 dirt
setblock ~166 ~122 ~107 dirt
setblock ~166 ~122 ~108 dirt
setblock ~166 ~122 ~129 dirt
setblock ~166 ~122 ~138 dirt
setblock ~166 ~122 ~139 dirt
setblock ~166 ~122 ~140 dirt
setblock ~166 ~123 ~52 dirt
setblock ~166 ~123 ~53 dirt
setblock ~166 ~123 ~54 dirt
setblock ~166 ~123 ~55 dirt
setblock ~166 ~123 ~69 dirt
setblock ~166 ~123 ~70 dirt
setblock ~166 ~123 ~71 dirt
setblock ~166 ~123 ~72 dirt
setblock ~166 ~123 ~73 dirt
setblock ~166 ~123 ~74 dirt
setblock ~166 ~123 ~75 dirt
setblock ~166 ~123 ~76 dirt
setblock ~166 ~123 ~77 dirt
setblock ~166 ~123 ~78 dirt
setblock ~166 ~123 ~79 dirt
setblock ~166 ~123 ~80 dirt
setblock ~166 ~123 ~81 dirt
setblock ~166 ~123 ~82 dirt
setblock ~166 ~123 ~83 dirt
setblock ~166 ~123 ~84 dirt
setblock ~166 ~123 ~85 dirt
setblock ~166 ~123 ~86 dirt
setblock ~166 ~123 ~87 dirt
setblock ~166 ~123 ~88 dirt
setblock ~166 ~123 ~99 dirt
setblock ~166 ~123 ~100 dirt
setblock ~166 ~123 ~101 dirt
setblock ~166 ~123 ~102 dirt
setblock ~166 ~123 ~103 dirt
setblock ~166 ~123 ~104 dirt
setblock ~166 ~123 ~105 dirt
setblock ~166 ~123 ~106 dirt
setblock ~166 ~123 ~107 dirt
setblock ~166 ~123 ~108 dirt
setblock ~166 ~123 ~129 dirt
setblock ~166 ~123 ~138 dirt
setblock ~166 ~123 ~139 dirt
setblock ~166 ~123 ~140 dirt
setblock ~166 ~124 ~52 dirt
setblock ~166 ~124 ~53 dirt
setblock ~166 ~124 ~54 dirt
setblock ~166 ~124 ~55 dirt
setblock ~166 ~124 ~69 grass_block
setblock ~166 ~124 ~70 grass_block
setblock ~166 ~124 ~71 grass_block
setblock ~166 ~124 ~72 grass_block
setblock ~166 ~124 ~73 grass_block
setblock ~166 ~124 ~74 grass_block
setblock ~166 ~124 ~75 dirt
setblock ~166 ~124 ~76 dirt
setblock ~166 ~124 ~77 dirt
setblock ~166 ~124 ~78 dirt
setblock ~166 ~124 ~79 dirt
setblock ~166 ~124 ~80 dirt
setblock ~166 ~124 ~81 dirt
setblock ~166 ~124 ~82 dirt
setblock ~166 ~124 ~83 dirt
setblock ~166 ~124 ~84 dirt
setblock ~166 ~124 ~85 dirt
setblock ~166 ~124 ~86 dirt
setblock ~166 ~124 ~87 dirt
setblock ~166 ~124 ~88 dirt
setblock ~166 ~124 ~99 dirt
setblock ~166 ~124 ~100 grass_block
setblock ~166 ~124 ~101 dirt
setblock ~166 ~124 ~102 dirt
setblock ~166 ~124 ~103 dirt
setblock ~166 ~124 ~104 dirt
setblock ~166 ~124 ~105 dirt
setblock ~166 ~124 ~106 dirt
setblock ~166 ~124 ~107 dirt
setblock ~166 ~124 ~108 dirt
setblock ~166 ~124 ~129 dirt
setblock ~166 ~124 ~138 dirt
setblock ~166 ~124 ~139 dirt
setblock ~166 ~124 ~140 dirt
setblock ~166 ~125 ~52 dirt
setblock ~166 ~125 ~53 dirt
setblock ~166 ~125 ~54 dirt
setblock ~166 ~125 ~55 dirt
setblock ~166 ~125 ~70 short_grass
setblock ~166 ~125 ~73 poppy
setblock ~166 ~125 ~74 short_grass
setblock ~166 ~125 ~75 grass_block
setblock ~166 ~125 ~76 grass_block
setblock ~166 ~125 ~77 grass_block
setblock ~166 ~125 ~78 grass_block
setblock ~166 ~125 ~79 dirt
setblock ~166 ~125 ~80 dirt
setblock ~166 ~125 ~81 dirt
setblock ~166 ~125 ~82 dirt
setblock ~166 ~125 ~83 dirt
setblock ~166 ~125 ~84 dirt
setblock ~166 ~125 ~85 dirt
setblock ~166 ~125 ~86 dirt
setblock ~166 ~125 ~87 dirt
setblock ~166 ~125 ~88 dirt
setblock ~166 ~125 ~99 grass_block
setblock ~166 ~125 ~101 grass_block
setblock ~166 ~125 ~102 grass_block
setblock ~166 ~125 ~103 grass_block
setblock ~166 ~125 ~104 grass_block
setblock ~166 ~125 ~105 grass_block
setblock ~166 ~125 ~106 grass_block
setblock ~166 ~125 ~107 dirt
setblock ~166 ~125 ~108 dirt
setblock ~166 ~125 ~129 grass_block
setblock ~166 ~125 ~138 grass_block
setblock ~166 ~125 ~139 grass_block
setblock ~166 ~125 ~140 grass_block
setblock ~166 ~126 ~52 dirt
setblock ~166 ~126 ~53 dirt
setblock ~166 ~126 ~54 dirt
setblock ~166 ~126 ~55 dirt
setblock ~166 ~126 ~78 short_grass
setblock ~166 ~126 ~79 grass_block
setblock ~166 ~126 ~80 grass_block
setblock ~166 ~126 ~81 grass_block
setblock ~166 ~126 ~82 dirt
setblock ~166 ~126 ~83 dirt
setblock ~166 ~126 ~84 dirt
setblock ~166 ~126 ~85 dirt
setblock ~166 ~126 ~86 dirt
setblock ~166 ~126 ~87 dirt
setblock ~166 ~126 ~88 dirt
setblock ~166 ~126 ~106 fern
setblock ~166 ~126 ~107 grass_block
setblock ~166 ~126 ~108 grass_block
setblock ~166 ~126 ~138 short_grass
setblock ~166 ~127 ~52 grass_block
setblock ~166 ~127 ~53 grass_block
setblock ~166 ~127 ~54 grass_block
setblock ~166 ~127 ~55 grass_block
setblock ~166 ~127 ~81 fern
setblock ~166 ~127 ~82 grass_block
setblock ~166 ~127 ~83 grass_block
setblock ~166 ~127 ~84 grass_block
setblock ~166 ~127 ~85 dirt
setblock ~166 ~127 ~86 dirt
setblock ~166 ~127 ~87 dirt
setblock ~166 ~127 ~88 dirt
setblock ~166 ~128 ~54 fern
setblock ~166 ~128 ~85 grass_block
setblock ~166 ~128 ~86 dirt
setblock ~166 ~128 ~87 dirt
setblock ~166 ~128 ~88 dirt
setblock ~166 ~129 ~86 grass_block
setblock ~166 ~129 ~87 grass_block
setblock ~166 ~129 ~88 dirt
setblock ~166 ~130 ~87 short_grass
setblock ~166 ~130 ~88 grass_block
setblock ~167 ~106 ~80 dirt
setblock ~167 ~107 ~77 dirt
setblock ~167 ~107 ~80 dirt
setblock ~167 ~108 ~76 dirt
setblock ~167 ~108 ~77 dirt
setblock ~167 ~108 ~78 dirt
setblock ~167 ~108 ~80 dirt
setblock ~167 ~109 ~76 dirt
setblock ~167 ~109 ~77 dirt
setblock ~167 ~109 ~78 dirt
setblock ~167 ~109 ~79 dirt
setblock ~167 ~109 ~80 dirt
setblock ~167 ~109 ~81 dirt
setblock ~167 ~110 ~75 dirt
setblock ~167 ~110 ~76 dirt
setblock ~167 ~110 ~77 dirt
setblock ~167 ~110 ~78 dirt
setblock ~167 ~110 ~79 dirt
setblock ~167 ~110 ~80 dirt
setblock ~167 ~110 ~81 dirt
setblock ~167 ~110 ~82 dirt
setblock ~167 ~111 ~74 dirt
setblock ~167 ~111 ~75 dirt
setblock ~167 ~111 ~76 dirt
setblock ~167 ~111 ~77 dirt
setblock ~167 ~111 ~78 dirt
setblock ~167 ~111 ~79 dirt
setblock ~167 ~111 ~80 dirt
setblock ~167 ~111 ~81 dirt
setblock ~167 ~111 ~82 dirt
setblock ~167 ~112 ~74 dirt
setblock ~167 ~112 ~75 dirt
setblock ~167 ~112 ~76 dirt
setblock ~167 ~112 ~77 dirt
setblock ~167 ~112 ~78 dirt
setblock ~167 ~112 ~79 dirt
setblock ~167 ~112 ~80 dirt
setblock ~167 ~112 ~81 dirt
setblock ~167 ~112 ~82 dirt
setblock ~167 ~113 ~74 dirt
setblock ~167 ~113 ~75 dirt
setblock ~167 ~113 ~76 dirt
setblock ~167 ~113 ~77 dirt
setblock ~167 ~113 ~78 dirt
setblock ~167 ~113 ~79 dirt
setblock ~167 ~113 ~80 dirt
setblock ~167 ~113 ~81 dirt
setblock ~167 ~113 ~82 dirt
setblock ~167 ~113 ~83 dirt
setblock ~167 ~113 ~105 dirt
setblock ~167 ~114 ~73 dirt
setblock ~167 ~114 ~74 dirt
setblock ~167 ~114 ~75 dirt
setblock ~167 ~114 ~76 dirt
setblock ~167 ~114 ~77 dirt
setblock ~167 ~114 ~78 dirt
setblock ~167 ~114 ~79 dirt
setblock ~167 ~114 ~80 dirt
setblock ~167 ~114 ~81 dirt
setblock ~167 ~114 ~82 dirt
setblock ~167 ~114 ~83 dirt
setblock ~167 ~114 ~104 dirt
setblock ~167 ~114 ~105 dirt
setblock ~167 ~114 ~106 dirt
setblock ~167 ~115 ~73 dirt
setblock ~167 ~115 ~74 dirt
setblock ~167 ~115 ~75 dirt
setblock ~167 ~115 ~76 dirt
setblock ~167 ~115 ~77 dirt
setblock ~167 ~115 ~78 dirt
setblock ~167 ~115 ~79 dirt
setblock ~167 ~115 ~80 dirt
setblock ~167 ~115 ~81 dirt
setblock ~167 ~115 ~82 dirt
setblock ~167 ~115 ~83 dirt
setblock ~167 ~115 ~84 dirt
setblock ~167 ~115 ~104 dirt
setblock ~167 ~115 ~105 dirt
setblock ~167 ~115 ~106 dirt
setblock ~167 ~116 ~73 dirt
setblock ~167 ~116 ~74 dirt
setblock ~167 ~116 ~75 dirt
setblock ~167 ~116 ~76 dirt
setblock ~167 ~116 ~77 dirt
setblock ~167 ~116 ~78 dirt
setblock ~167 ~116 ~79 dirt
setblock ~167 ~116 ~80 dirt
setblock ~167 ~116 ~81 dirt
setblock ~167 ~116 ~82 dirt
setblock ~167 ~116 ~83 dirt
setblock ~167 ~116 ~84 dirt
setblock ~167 ~116 ~85 dirt
setblock ~167 ~116 ~104 dirt
setblock ~167 ~116 ~105 dirt
setblock ~167 ~116 ~106 dirt
setblock ~167 ~117 ~72 dirt
setblock ~167 ~117 ~73 dirt
setblock ~167 ~117 ~74 dirt
setblock ~167 ~117 ~75 dirt
setblock ~167 ~117 ~76 dirt
setblock ~167 ~117 ~77 dirt
setblock ~167 ~117 ~78 dirt
setblock ~167 ~117 ~79 dirt
setblock ~167 ~117 ~80 dirt
setblock ~167 ~117 ~81 dirt
setblock ~167 ~117 ~82 dirt
setblock ~167 ~117 ~83 dirt
setblock ~167 ~117 ~84 dirt
setblock ~167 ~117 ~85 dirt
setblock ~167 ~117 ~86 dirt
setblock ~167 ~117 ~104 dirt
setblock ~167 ~117 ~105 dirt
setblock ~167 ~117 ~106 dirt
setblock ~167 ~117 ~107 dirt
setblock ~167 ~118 ~71 dirt
setblock ~167 ~118 ~72 dirt
setblock ~167 ~118 ~73 dirt
setblock ~167 ~118 ~74 dirt
setblock ~167 ~118 ~75 dirt
setblock ~167 ~118 ~76 dirt
setblock ~167 ~118 ~77 dirt
setblock ~167 ~118 ~78 dirt
setblock ~167 ~118 ~79 dirt
setblock ~167 ~118 ~80 dirt
setblock ~167 ~118 ~81 dirt
setblock ~167 ~118 ~82 dirt
setblock ~167 ~118 ~83 dirt
setblock ~167 ~118 ~84 dirt
setblock ~167 ~118 ~85 dirt
setblock ~167 ~118 ~86 dirt
setblock ~167 ~118 ~103 dirt
setblock ~167 ~118 ~104 dirt
setblock ~167 ~118 ~105 dirt
setblock ~167 ~118 ~106 dirt
setblock ~167 ~118 ~107 dirt
setblock ~167 ~118 ~139 dirt
setblock ~167 ~119 ~70 dirt
setblock ~167 ~119 ~71 dirt
setblock ~167 ~119 ~72 dirt
setblock ~167 ~119 ~73 dirt
setblock ~167 ~119 ~74 dirt
setblock ~167 ~119 ~75 dirt
setblock ~167 ~119 ~76 dirt
setblock ~167 ~119 ~77 dirt
setblock ~167 ~119 ~78 dirt
setblock ~167 ~119 ~79 dirt
setblock ~167 ~119 ~80 dirt
setblock ~167 ~119 ~81 dirt
setblock ~167 ~119 ~82 dirt
setblock ~167 ~119 ~83 dirt
setblock ~167 ~119 ~84 dirt
setblock ~167 ~119 ~85 dirt
setblock ~167 ~119 ~86 dirt
setblock ~167 ~119 ~87 dirt
setblock ~167 ~119 ~102 dirt
setblock ~167 ~119 ~103 dirt
setblock ~167 ~119 ~104 dirt
setblock ~167 ~119 ~105 dirt
setblock ~167 ~119 ~106 dirt
setblock ~167 ~119 ~107 dirt
setblock ~167 ~119 ~108 dirt
setblock ~167 ~119 ~138 dirt
setblock ~167 ~119 ~139 dirt
setblock ~167 ~119 ~140 dirt
setblock ~167 ~120 ~70 dirt
setblock ~167 ~120 ~71 dirt
setblock ~167 ~120 ~72 dirt
setblock ~167 ~120 ~73 dirt
setblock ~167 ~120 ~74 dirt
setblock ~167 ~120 ~75 dirt
setblock ~167 ~120 ~76 dirt
setblock ~167 ~120 ~77 dirt
setblock ~167 ~120 ~78 dirt
setblock ~167 ~120 ~79 dirt
setblock ~167 ~120 ~80 dirt
setblock ~167 ~120 ~81 dirt
setblock ~167 ~120 ~82 dirt
setblock ~167 ~120 ~83 dirt
setblock ~167 ~120 ~84 dirt
setblock ~167 ~120 ~85 dirt
setblock ~167 ~120 ~86 dirt
setblock ~167 ~120 ~87 dirt
setblock ~167 ~120 ~88 dirt
setblock ~167 ~120 ~102 dirt
setblock ~167 ~120 ~103 dirt
setblock ~167 ~120 ~104 dirt
setblock ~167 ~120 ~105 dirt
setblock ~167 ~120 ~106 dirt
setblock ~167 ~120 ~107 dirt
setblock ~167 ~120 ~108 dirt
setblock ~167 ~120 ~109 dirt
setblock ~167 ~120 ~138 dirt
setblock ~167 ~120 ~139 dirt
setblock ~167 ~120 ~140 dirt
setblock ~167 ~121 ~53 dirt
setblock ~167 ~121 ~70 dirt
setblock ~167 ~121 ~71 dirt
setblock ~167 ~121 ~72 dirt
setblock ~167 ~121 ~73 dirt
setblock ~167 ~121 ~74 dirt
setblock ~167 ~121 ~75 dirt
setblock ~167 ~121 ~76 dirt
setblock ~167 ~121 ~77 dirt
setblock ~167 ~121 ~78 dirt
setblock ~167 ~121 ~79 dirt
setblock ~167 ~121 ~80 dirt
setblock ~167 ~121 ~81 dirt
setblock ~167 ~121 ~82 dirt
setblock ~167 ~121 ~83 dirt
setblock ~167 ~121 ~84 dirt
setblock ~167 ~121 ~85 dirt
setblock ~167 ~121 ~86 dirt
setblock ~167 ~121 ~87 dirt
setblock ~167 ~121 ~88 dirt
setblock ~167 ~121 ~89 dirt
setblock ~167 ~121 ~100 dirt
setblock ~167 ~121 ~101 dirt
setblock ~167 ~121 ~102 dirt
setblock ~167 ~121 ~103 dirt
setblock ~167 ~121 ~104 dirt
setblock ~167 ~121 ~105 dirt
setblock ~167 ~121 ~106 dirt
setblock ~167 ~121 ~107 dirt
setblock ~167 ~121 ~108 dirt
setblock ~167 ~121 ~109 dirt
setblock ~167 ~121 ~138 dirt
setblock ~167 ~121 ~139 dirt
setblock ~167 ~121 ~140 dirt
setblock ~167 ~121 ~141 dirt
setblock ~167 ~122 ~53 dirt
setblock ~167 ~122 ~70 dirt
setblock ~167 ~122 ~71 dirt
setblock ~167 ~122 ~72 dirt
setblock ~167 ~122 ~73 dirt
setblock ~167 ~122 ~74 dirt
setblock ~167 ~122 ~75 dirt
setblock ~167 ~122 ~76 dirt
setblock ~167 ~122 ~77 dirt
setblock ~167 ~122 ~78 dirt
setblock ~167 ~122 ~79 dirt
setblock ~167 ~122 ~80 dirt
setblock ~167 ~122 ~81 dirt
setblock ~167 ~122 ~82 dirt
setblock ~167 ~122 ~83 dirt
setblock ~167 ~122 ~84 dirt
setblock ~167 ~122 ~85 dirt
setblock ~167 ~122 ~86 dirt
setblock ~167 ~122 ~87 dirt
setblock ~167 ~122 ~88 dirt
setblock ~167 ~122 ~89 dirt
setblock ~167 ~122 ~100 dirt
setblock ~167 ~122 ~101 dirt
setblock ~167 ~122 ~102 dirt
setblock ~167 ~122 ~103 dirt
setblock ~167 ~122 ~104 dirt
setblock ~167 ~122 ~105 dirt
setblock ~167 ~122 ~106 dirt
setblock ~167 ~122 ~107 dirt
setblock ~167 ~122 ~108 dirt
setblock ~167 ~122 ~109 dirt
setblock ~167 ~122 ~138 dirt
setblock ~167 ~122 ~139 dirt
setblock ~167 ~122 ~140 dirt
setblock ~167 ~122 ~141 dirt
setblock ~167 ~123 ~53 dirt
setblock ~167 ~123 ~70 dirt
setblock ~167 ~123 ~71 dirt
setblock ~167 ~123 ~72 dirt
setblock ~167 ~123 ~73 dirt
setblock ~167 ~123 ~74 dirt
setblock ~167 ~123 ~75 dirt
setblock ~167 ~123 ~76 dirt
setblock ~167 ~123 ~77 dirt
setblock ~167 ~123 ~78 dirt
setblock ~167 ~123 ~79 dirt
setblock ~167 ~123 ~80 dirt
setblock ~167 ~123 ~81 dirt
setblock ~167 ~123 ~82 dirt
setblock ~167 ~123 ~83 dirt
setblock ~167 ~123 ~84 dirt
setblock ~167 ~123 ~85 dirt
setblock ~167 ~123 ~86 dirt
setblock ~167 ~123 ~87 dirt
setblock ~167 ~123 ~88 dirt
setblock ~167 ~123 ~89 dirt
setblock ~167 ~123 ~100 dirt
setblock ~167 ~123 ~101 dirt
setblock ~167 ~123 ~102 dirt
setblock ~167 ~123 ~103 dirt
setblock ~167 ~123 ~104 dirt
setblock ~167 ~123 ~105 dirt
setblock ~167 ~123 ~106 dirt
setblock ~167 ~123 ~107 dirt
setblock ~167 ~123 ~108 dirt
setblock ~167 ~123 ~109 dirt
setblock ~167 ~123 ~138 dirt
setblock ~167 ~123 ~139 dirt
setblock ~167 ~123 ~140 dirt
setblock ~167 ~123 ~141 dirt
setblock ~167 ~124 ~53 dirt
setblock ~167 ~124 ~70 grass_block
setblock ~167 ~124 ~71 grass_block
setblock ~167 ~124 ~72 grass_block
setblock ~167 ~124 ~73 dirt
setblock ~167 ~124 ~74 dirt
setblock ~167 ~124 ~75 dirt
setblock ~167 ~124 ~76 dirt
setblock ~167 ~124 ~77 dirt
setblock ~167 ~124 ~78 dirt
setblock ~167 ~124 ~79 dirt
setblock ~167 ~124 ~80 dirt
setblock ~167 ~124 ~81 dirt
setblock ~167 ~124 ~82 dirt
setblock ~167 ~124 ~83 dirt
setblock ~167 ~124 ~84 dirt
setblock ~167 ~124 ~85 dirt
setblock ~167 ~124 ~86 dirt
setblock ~167 ~124 ~87 dirt
setblock ~167 ~124 ~88 dirt
setblock ~167 ~124 ~89 dirt
setblock ~167 ~124 ~100 grass_block
setblock ~167 ~124 ~101 dirt
setblock ~167 ~124 ~102 dirt
setblock ~167 ~124 ~103 dirt
setblock ~167 ~124 ~104 dirt
setblock ~167 ~124 ~105 dirt
setblock ~167 ~124 ~106 dirt
setblock ~167 ~124 ~107 dirt
setblock ~167 ~124 ~108 dirt
setblock ~167 ~124 ~109 dirt
setblock ~167 ~124 ~138 dirt
setblock ~167 ~124 ~139 dirt
setblock ~167 ~124 ~140 dirt
setblock ~167 ~124 ~141 dirt
setblock ~167 ~125 ~53 dirt
setblock ~167 ~125 ~70 short_grass
setblock ~167 ~125 ~71 short_grass
setblock ~167 ~125 ~73 grass_block
setblock ~167 ~125 ~74 grass_block
setblock ~167 ~125 ~75 grass_block
setblock ~167 ~125 ~76 grass_block
setblock ~167 ~125 ~77 grass_block
setblock ~167 ~125 ~78 grass_block
setblock ~167 ~125 ~79 dirt
setblock ~167 ~125 ~80 dirt
setblock ~167 ~125 ~81 dirt
setblock ~167 ~125 ~82 dirt
setblock ~167 ~125 ~83 dirt
setblock ~167 ~125 ~84 dirt
setblock ~167 ~125 ~85 dirt
setblock ~167 ~125 ~86 dirt
setblock ~167 ~125 ~87 dirt
setblock ~167 ~125 ~88 dirt
setblock ~167 ~125 ~89 dirt
setblock ~167 ~125 ~101 grass_block
setblock ~167 ~125 ~102 grass_block
setblock ~167 ~125 ~103 grass_block
setblock ~167 ~125 ~104 grass_block
setblock ~167 ~125 ~105 grass_block
setblock ~167 ~125 ~106 dirt
setblock ~167 ~125 ~107 dirt
setblock ~167 ~125 ~108 dirt
setblock ~167 ~125 ~109 dirt
setblock ~167 ~125 ~138 grass_block
setblock ~167 ~125 ~139 grass_block
setblock ~167 ~125 ~140 grass_block
setblock ~167 ~125 ~141 grass_block
setblock ~167 ~126 ~53 dirt
setblock ~167 ~126 ~76 short_grass
setblock ~167 ~126 ~79 grass_block
setblock ~167 ~126 ~80 grass_block
setblock ~167 ~126 ~81 grass_block
setblock ~167 ~126 ~82 dirt
setblock ~167 ~126 ~83 dirt
setblock ~167 ~126 ~84 dirt
setblock ~167 ~126 ~85 dirt
setblock ~167 ~126 ~86 dirt
setblock ~167 ~126 ~87 dirt
setblock ~167 ~126 ~88 dirt
setblock ~167 ~126 ~89 dirt
setblock ~167 ~126 ~104 short_grass
setblock ~167 ~126 ~105 short_grass
setblock ~167 ~126 ~106 grass_block
setblock ~167 ~126 ~107 grass_block
setblock ~167 ~126 ~108 grass_block
setblock ~167 ~126 ~109 grass_block
setblock ~167 ~127 ~53 grass_block
setblock ~167 ~127 ~79 short_grass
setblock ~167 ~127 ~82 grass_block
setblock ~167 ~127 ~83 grass_block
setblock ~167 ~127 ~84 grass_block
setblock ~167 ~127 ~85 dirt
setblock ~167 ~127 ~86 dirt
setblock ~167 ~127 ~87 dirt
setblock ~167 ~127 ~88 dirt
setblock ~167 ~127 ~89 dirt
setblock ~167 ~128 ~53 short_grass
setblock ~167 ~128 ~85 grass_block
setblock ~167 ~128 ~86 grass_block
setblock ~167 ~128 ~87 dirt
setblock ~167 ~128 ~88 dirt
setblock ~167 ~128 ~89 dirt
setblock ~167 ~129 ~86 short_grass
setblock ~167 ~129 ~87 grass_block
setblock ~167 ~129 ~88 dirt
setblock ~167 ~129 ~89 dirt
setblock ~167 ~130 ~88 grass_block
setblock ~167 ~130 ~89 grass_block
setblock ~167 ~131 ~88 short_grass
setblock ~168 ~108 ~77 dirt
setblock ~168 ~109 ~77 dirt
setblock ~168 ~109 ~80 dirt
setblock ~168 ~110 ~76 dirt
setblock ~168 ~110 ~77 dirt
setblock ~168 ~110 ~78 dirt
setblock ~168 ~110 ~80 dirt
setblock ~168 ~110 ~81 dirt
setblock ~168 ~111 ~76 dirt
setblock ~168 ~111 ~77 dirt
setblock ~168 ~111 ~78 dirt
setblock ~168 ~111 ~80 dirt
setblock ~168 ~111 ~81 dirt
setblock ~168 ~112 ~75 dirt
setblock ~168 ~112 ~76 dirt
setblock ~168 ~112 ~77 dirt
setblock ~168 ~112 ~78 dirt
setblock ~168 ~112 ~79 dirt
setblock ~168 ~112 ~80 dirt
setblock ~168 ~112 ~81 dirt
setblock ~168 ~112 ~105 dirt
setblock ~168 ~113 ~75 dirt
setblock ~168 ~113 ~76 dirt
setblock ~168 ~113 ~77 dirt
setblock ~168 ~113 ~78 dirt
setblock ~168 ~113 ~79 dirt
setblock ~168 ~113 ~80 dirt
setblock ~168 ~113 ~81 dirt
setblock ~168 ~113 ~82 dirt
setblock ~168 ~113 ~104 dirt
setblock ~168 ~113 ~105 dirt
setblock ~168 ~113 ~106 dirt
setblock ~168 ~114 ~75 dirt
setblock ~168 ~114 ~76 dirt
setblock ~168 ~114 ~77 dirt
setblock ~168 ~114 ~78 dirt
setblock ~168 ~114 ~79 dirt
setblock ~168 ~114 ~80 dirt
setblock ~168 ~114 ~81 dirt
setblock ~168 ~114 ~82 dirt
setblock ~168 ~114 ~104 dirt
setblock ~168 ~114 ~105 dirt
setblock ~168 ~114 ~106 dirt
setblock ~168 ~115 ~74 dirt
setblock ~168 ~115 ~75 dirt
setblock ~168 ~115 ~76 dirt
setblock ~168 ~115 ~77 dirt
setblock ~168 ~115 ~78 dirt
setblock ~168 ~115 ~79 dirt
setblock ~168 ~115 ~80 dirt
setblock ~168 ~115 ~81 dirt
setblock ~168 ~115 ~82 dirt
setblock ~168 ~115 ~83 dirt
setblock ~168 ~115 ~104 dirt
setblock ~168 ~115 ~105 dirt
setblock ~168 ~115 ~106 dirt
setblock ~168 ~115 ~139 dirt
setblock ~168 ~116 ~74 dirt
setblock ~168 ~116 ~75 dirt
setblock ~168 ~116 ~76 dirt
setblock ~168 ~116 ~77 dirt
setblock ~168 ~116 ~78 dirt
setblock ~168 ~116 ~79 dirt
setblock ~168 ~116 ~80 dirt
setblock ~168 ~116 ~81 dirt
setblock ~168 ~116 ~82 dirt
setblock ~168 ~116 ~83 dirt
setblock ~168 ~116 ~84 dirt
setblock ~168 ~116 ~104 dirt
setblock ~168 ~116 ~105 dirt
setblock ~168 ~116 ~106 dirt
setblock ~168 ~116 ~107 dirt
setblock ~168 ~116 ~139 dirt
setblock ~168 ~117 ~73 dirt
setblock ~168 ~117 ~74 dirt
setblock ~168 ~117 ~75 dirt
setblock ~168 ~117 ~76 dirt
setblock ~168 ~117 ~77 dirt
setblock ~168 ~117 ~78 dirt
setblock ~168 ~117 ~79 dirt
setblock ~168 ~117 ~80 dirt
setblock ~168 ~117 ~81 dirt
setblock ~168 ~117 ~82 dirt
setblock ~168 ~117 ~83 dirt
setblock ~168 ~117 ~84 dirt
setblock ~168 ~117 ~85 dirt
setblock ~168 ~117 ~103 dirt
setblock ~168 ~117 ~104 dirt
setblock ~168 ~117 ~105 dirt
setblock ~168 ~117 ~106 dirt
setblock ~168 ~117 ~107 dirt
setblock ~168 ~117 ~108 dirt
setblock ~168 ~117 ~139 dirt
setblock ~168 ~117 ~140 dirt
setblock ~168 ~118 ~72 dirt
setblock ~168 ~118 ~73 dirt
setblock ~168 ~118 ~74 dirt
setblock ~168 ~118 ~75 dirt
setblock ~168 ~118 ~76 dirt
setblock ~168 ~118 ~77 dirt
setblock ~168 ~118 ~78 dirt
setblock ~168 ~118 ~79 dirt
setblock ~168 ~118 ~80 dirt
setblock ~168 ~118 ~81 dirt
setblock ~168 ~118 ~82 dirt
setblock ~168 ~118 ~83 dirt
setblock ~168 ~118 ~84 dirt
setblock ~168 ~118 ~85 dirt
setblock ~168 ~118 ~103 dirt
setblock ~168 ~118 ~104 dirt
setblock ~168 ~118 ~105 dirt
setblock ~168 ~118 ~106 dirt
setblock ~168 ~118 ~107 dirt
setblock ~168 ~118 ~108 dirt
setblock ~168 ~118 ~138 dirt
setblock ~168 ~118 ~139 dirt
setblock ~168 ~118 ~140 dirt
setblock ~168 ~119 ~71 dirt
setblock ~168 ~119 ~72 dirt
setblock ~168 ~119 ~73 dirt
setblock ~168 ~119 ~74 dirt
setblock ~168 ~119 ~75 dirt
setblock ~168 ~119 ~76 dirt
setblock ~168 ~119 ~77 dirt
setblock ~168 ~119 ~78 dirt
setblock ~168 ~119 ~79 dirt
setblock ~168 ~119 ~80 dirt
setblock ~168 ~119 ~81 dirt
setblock ~168 ~119 ~82 dirt
setblock ~168 ~119 ~83 dirt
setblock ~168 ~119 ~84 dirt
setblock ~168 ~119 ~85 dirt
setblock ~168 ~119 ~86 dirt
setblock ~168 ~119 ~102 dirt
setblock ~168 ~119 ~103 dirt
setblock ~168 ~119 ~104 dirt
setblock ~168 ~119 ~105 dirt
setblock ~168 ~119 ~106 dirt
setblock ~168 ~119 ~107 dirt
setblock ~168 ~119 ~108 dirt
setblock ~168 ~119 ~138 dirt
setblock ~168 ~119 ~139 dirt
setblock ~168 ~119 ~140 dirt
setblock ~168 ~119 ~141 dirt
setblock ~168 ~120 ~71 dirt
setblock ~168 ~120 ~72 dirt
setblock ~168 ~120 ~73 dirt
setblock ~168 ~120 ~74 dirt
setblock ~168 ~120 ~75 dirt
setblock ~168 ~120 ~76 dirt
setblock ~168 ~120 ~77 dirt
setblock ~168 ~120 ~78 dirt
setblock ~168 ~120 ~79 dirt
setblock ~168 ~120 ~80 dirt
setblock ~168 ~120 ~81 dirt
setblock ~168 ~120 ~82 dirt
setblock ~168 ~120 ~83 dirt
setblock ~168 ~120 ~84 dirt
setblock ~168 ~120 ~85 dirt
setblock ~168 ~120 ~86 dirt
setblock ~168 ~120 ~87 dirt
setblock ~168 ~120 ~102 dirt
setblock ~168 ~120 ~103 dirt
setblock ~168 ~120 ~104 dirt
setblock ~168 ~120 ~105 dirt
setblock ~168 ~120 ~106 dirt
setblock ~168 ~120 ~107 dirt
setblock ~168 ~120 ~108 dirt
setblock ~168 ~120 ~109 dirt
setblock ~168 ~120 ~137 dirt
setblock ~168 ~120 ~138 dirt
setblock ~168 ~120 ~139 dirt
setblock ~168 ~120 ~140 dirt
setblock ~168 ~120 ~141 dirt
setblock ~168 ~121 ~70 dirt
setblock ~168 ~121 ~71 dirt
setblock ~168 ~121 ~72 dirt
setblock ~168 ~121 ~73 dirt
setblock ~168 ~121 ~74 dirt
setblock ~168 ~121 ~75 dirt
setblock ~168 ~121 ~76 dirt
setblock ~168 ~121 ~77 dirt
setblock ~168 ~121 ~78 dirt
setblock ~168 ~121 ~79 dirt
setblock ~168 ~121 ~80 dirt
setblock ~168 ~121 ~81 dirt
setblock ~168 ~121 ~82 dirt
setblock ~168 ~121 ~83 dirt
setblock ~168 ~121 ~84 dirt
setblock ~168 ~121 ~85 dirt
setblock ~168 ~121 ~86 dirt
setblock ~168 ~121 ~87 dirt
setblock ~168 ~121 ~88 dirt
setblock ~168 ~121 ~101 dirt
setblock ~168 ~121 ~102 dirt
setblock ~168 ~121 ~103 dirt
setblock ~168 ~121 ~104 dirt
setblock ~168 ~121 ~105 dirt
setblock ~168 ~121 ~106 dirt
setblock ~168 ~121 ~107 dirt
setblock ~168 ~121 ~108 dirt
setblock ~168 ~121 ~109 dirt
setblock ~168 ~121 ~137 dirt
setblock ~168 ~121 ~138 dirt
setblock ~168 ~121 ~139 dirt
setblock ~168 ~121 ~140 dirt
setblock ~168 ~121 ~141 dirt
setblock ~168 ~121 ~142 dirt
setblock ~168 ~122 ~70 dirt
setblock ~168 ~122 ~71 dirt
setblock ~168 ~122 ~72 dirt
setblock ~168 ~122 ~73 dirt
setblock ~168 ~122 ~74 dirt
setblock ~168 ~122 ~75 dirt
setblock ~168 ~122 ~76 dirt
setblock ~168 ~122 ~77 dirt
setblock ~168 ~122 ~78 dirt
setblock ~168 ~122 ~79 dirt
setblock ~168 ~122 ~80 dirt
setblock ~168 ~122 ~81 dirt
setblock ~168 ~122 ~82 dirt
setblock ~168 ~122 ~83 dirt
setblock ~168 ~122 ~84 dirt
setblock ~168 ~122 ~85 dirt
setblock ~168 ~122 ~86 dirt
setblock ~168 ~122 ~87 dirt
setblock ~168 ~122 ~88 dirt
setblock ~168 ~122 ~101 dirt
setblock ~168 ~122 ~102 dirt
setblock ~168 ~122 ~103 dirt
setblock ~168 ~122 ~104 dirt
setblock ~168 ~122 ~105 dirt
setblock ~168 ~122 ~106 dirt
setblock ~168 ~122 ~107 dirt
setblock ~168 ~122 ~108 dirt
setblock ~168 ~122 ~109 dirt
setblock ~168 ~122 ~137 dirt
setblock ~168 ~122 ~138 dirt
setblock ~168 ~122 ~139 dirt
setblock ~168 ~122 ~140 dirt
setblock ~168 ~122 ~141 dirt
setblock ~168 ~122 ~142 dirt
setblock ~168 ~123 ~70 dirt
setblock ~168 ~123 ~71 dirt
setblock ~168 ~123 ~72 dirt
setblock ~168 ~123 ~73 dirt
setblock ~168 ~123 ~74 dirt
setblock ~168 ~123 ~75 dirt
setblock ~168 ~123 ~76 dirt
setblock ~168 ~123 ~77 dirt
setblock ~168 ~123 ~78 dirt
setblock ~168 ~123 ~79 dirt
setblock ~168 ~123 ~80 dirt
setblock ~168 ~123 ~81 dirt
setblock ~168 ~123 ~82 dirt
setblock ~168 ~123 ~83 dirt
setblock ~168 ~123 ~84 dirt
setblock ~168 ~123 ~85 dirt
setblock ~168 ~123 ~86 dirt
setblock ~168 ~123 ~87 dirt
setblock ~168 ~123 ~88 dirt
setblock ~168 ~123 ~101 dirt
setblock ~168 ~123 ~102 dirt
setblock ~168 ~123 ~103 dirt
setblock ~168 ~123 ~104 dirt
setblock ~168 ~123 ~105 dirt
setblock ~168 ~123 ~106 dirt
setblock ~168 ~123 ~107 dirt
setblock ~168 ~123 ~108 dirt
setblock ~168 ~123 ~109 dirt
setblock ~168 ~123 ~137 dirt
setblock ~168 ~123 ~138 dirt
setblock ~168 ~123 ~139 dirt
setblock ~168 ~123 ~140 dirt
setblock ~168 ~123 ~141 dirt
setblock ~168 ~123 ~142 dirt
setblock ~168 ~124 ~70 grass_block
setblock ~168 ~124 ~71 dirt
setblock ~168 ~124 ~72 dirt
setblock ~168 ~124 ~73 dirt
setblock ~168 ~124 ~74 dirt
setblock ~168 ~124 ~75 dirt
setblock ~168 ~124 ~76 dirt
setblock ~168 ~124 ~77 dirt
setblock ~168 ~124 ~78 dirt
setblock ~168 ~124 ~79 dirt
setblock ~168 ~124 ~80 dirt
setblock ~168 ~124 ~81 dirt
setblock ~168 ~124 ~82 dirt
setblock ~168 ~124 ~83 dirt
setblock ~168 ~124 ~84 dirt
setblock ~168 ~124 ~85 dirt
setblock ~168 ~124 ~86 dirt
setblock ~168 ~124 ~87 dirt
setblock ~168 ~124 ~88 dirt
setblock ~168 ~124 ~101 dirt
setblock ~168 ~124 ~102 dirt
setblock ~168 ~124 ~103 dirt
setblock ~168 ~124 ~104 dirt
setblock ~168 ~124 ~105 dirt
setblock ~168 ~124 ~106 dirt
setblock ~168 ~124 ~107 dirt
setblock ~168 ~124 ~108 dirt
setblock ~168 ~124 ~109 dirt
setblock ~168 ~124 ~137 dirt
setblock ~168 ~124 ~138 dirt
setblock ~168 ~124 ~139 dirt
setblock ~168 ~124 ~140 dirt
setblock ~168 ~124 ~141 dirt
setblock ~168 ~124 ~142 dirt
setblock ~168 ~125 ~71 grass_block
setblock ~168 ~125 ~72 grass_block
setblock ~168 ~125 ~73 grass_block
setblock ~168 ~125 ~74 grass_block
setblock ~168 ~125 ~75 grass_block
setblock ~168 ~125 ~76 grass_block
setblock ~168 ~125 ~77 dirt
setblock ~168 ~125 ~78 dirt
setblock ~168 ~125 ~79 dirt
setblock ~168 ~125 ~80 dirt
setblock ~168 ~125 ~81 dirt
setblock ~168 ~125 ~82 dirt
setblock ~168 ~125 ~83 dirt
setblock ~168 ~125 ~84 dirt
setblock ~168 ~125 ~85 dirt
setblock ~168 ~125 ~86 dirt
setblock ~168 ~125 ~87 dirt
setblock ~168 ~125 ~88 dirt
setblock ~168 ~125 ~101 grass_block
setblock ~168 ~125 ~102 grass_block
setblock ~168 ~125 ~103 grass_block
setblock ~168 ~125 ~104 grass_block
setblock ~168 ~125 ~105 dirt
setblock ~168 ~125 ~106 dirt
setblock ~168 ~125 ~107 dirt
setblock ~168 ~125 ~108 dirt
setblock ~168 ~125 ~109 dirt
setblock ~168 ~125 ~137 grass_block
setblock ~168 ~125 ~138 grass_block
setblock ~168 ~125 ~139 grass_block
setblock ~168 ~125 ~140 grass_block
setblock ~168 ~125 ~141 grass_block
setblock ~168 ~125 ~142 dirt
setblock ~168 ~126 ~77 grass_block
setblock ~168 ~126 ~78 grass_block
setblock ~168 ~126 ~79 grass_block
setblock ~168 ~126 ~80 grass_block
setblock ~168 ~126 ~81 grass_block
setblock ~168 ~126 ~82 dirt
setblock ~168 ~126 ~83 dirt
setblock ~168 ~126 ~84 dirt
setblock ~168 ~126 ~85 dirt
setblock ~168 ~126 ~86 dirt
setblock ~168 ~126 ~87 dirt
setblock ~168 ~126 ~88 dirt
setblock ~168 ~126 ~103 poppy
setblock ~168 ~126 ~105 grass_block
setblock ~168 ~126 ~106 grass_block
setblock ~168 ~126 ~107 grass_block
setblock ~168 ~126 ~108 grass_block
setblock ~168 ~126 ~109 grass_block
setblock ~168 ~126 ~137 poppy
setblock ~168 ~126 ~139 short_grass
setblock ~168 ~126 ~140 short_grass
setblock ~168 ~126 ~142 grass_block
setblock ~168 ~127 ~77 short_grass
setblock ~168 ~127 ~82 grass_block
setblock ~168 ~127 ~83 grass_block
setblock ~168 ~127 ~84 grass_block
setblock ~168 ~127 ~85 dirt
setblock ~168 ~127 ~86 dirt
setblock ~168 ~127 ~87 dirt
setblock ~168 ~127 ~88 dirt
setblock ~168 ~127 ~109 short_grass
setblock ~168 ~128 ~83 short_grass
setblock ~168 ~128 ~85 grass_block
setblock ~168 ~128 ~86 grass_block
setblock ~168 ~128 ~87 dirt
setblock ~168 ~128 ~88 dirt
setblock ~168 ~129 ~87 grass_block
setblock ~168 ~129 ~88 grass_block
setblock ~168 ~130 ~87 short_grass
setblock ~168 ~130 ~88 short_grass
setblock ~169 ~110 ~77 dirt
setblock ~169 ~111 ~76 dirt
setblock ~169 ~111 ~77 dirt
setblock ~169 ~111 ~78 dirt
setblock ~169 ~111 ~105 dirt
setblock ~169 ~112 ~76 dirt
setblock ~169 ~112 ~77 dirt
setblock ~169 ~112 ~78 dirt
setblock ~169 ~112 ~80 dirt
setblock ~169 ~112 ~104 dirt
setblock ~169 ~112 ~105 dirt
setblock ~169 ~112 ~106 dirt
setblock ~169 ~113 ~76 dirt
setblock ~169 ~113 ~77 dirt
setblock ~169 ~113 ~78 dirt
setblock ~169 ~113 ~79 dirt
setblock ~169 ~113 ~80 dirt
setblock ~169 ~113 ~81 dirt
setblock ~169 ~113 ~104 dirt
setblock ~169 ~113 ~105 dirt
setblock ~169 ~113 ~106 dirt
setblock ~169 ~113 ~139 dirt
setblock ~169 ~114 ~76 dirt
setblock ~169 ~114 ~77 dirt
setblock ~169 ~114 ~78 dirt
setblock ~169 ~114 ~79 dirt
setblock ~169 ~114 ~80 dirt
setblock ~169 ~114 ~81 dirt
setblock ~169 ~114 ~103 dirt
setblock ~169 ~114 ~104 dirt
setblock ~169 ~114 ~105 dirt
setblock ~169 ~114 ~106 dirt
setblock ~169 ~114 ~139 dirt
setblock ~169 ~115 ~75 dirt
setblock ~169 ~115 ~76 dirt
setblock ~169 ~115 ~77 dirt
setblock ~169 ~115 ~78 dirt
setblock ~169 ~115 ~79 dirt
setblock ~169 ~115 ~80 dirt
setblock ~169 ~115 ~81 dirt
setblock ~169 ~115 ~82 dirt
setblock ~169 ~115 ~103 dirt
setblock ~169 ~115 ~104 dirt
setblock ~169 ~115 ~105 dirt
setblock ~169 ~115 ~106 dirt
setblock ~169 ~115 ~138 dirt
setblock ~169 ~115 ~139 dirt
setblock ~169 ~115 ~140 dirt
setblock ~169 ~116 ~75 dirt
setblock ~169 ~116 ~76 dirt
setblock ~169 ~116 ~77 dirt
setblock ~169 ~116 ~78 dirt
setblock ~169 ~116 ~79 dirt
setblock ~169 ~116 ~80 dirt
setblock ~169 ~116 ~81 dirt
setblock ~169 ~116 ~82 dirt
setblock ~169 ~116 ~83 dirt
setblock ~169 ~116 ~103 dirt
setblock ~169 ~116 ~104 dirt
setblock ~169 ~116 ~105 dirt
setblock ~169 ~116 ~106 dirt
setblock ~169 ~116 ~107 dirt
setblock ~169 ~116 ~138 dirt
setblock ~169 ~116 ~139 dirt
setblock ~169 ~116 ~140 dirt
setblock ~169 ~117 ~74 dirt
setblock ~169 ~117 ~75 dirt
setblock ~169 ~117 ~76 dirt
setblock ~169 ~117 ~77 dirt
setblock ~169 ~117 ~78 dirt
setblock ~169 ~117 ~79 dirt
setblock ~169 ~117 ~80 dirt
setblock ~169 ~117 ~81 dirt
setblock ~169 ~117 ~82 dirt
setblock ~169 ~117 ~83 dirt
setblock ~169 ~117 ~103 dirt
setblock ~169 ~117 ~104 dirt
setblock ~169 ~117 ~105 dirt
setblock ~169 ~117 ~106 dirt
setblock ~169 ~117 ~107 dirt
setblock ~169 ~117 ~138 dirt
setblock ~169 ~117 ~139 dirt
setblock ~169 ~117 ~140 dirt
setblock ~169 ~117 ~141 dirt
setblock ~169 ~118 ~73 dirt
setblock ~169 ~118 ~74 dirt
setblock ~169 ~118 ~75 dirt
setblock ~169 ~118 ~76 dirt
setblock ~169 ~118 ~77 dirt
setblock ~169 ~118 ~78 dirt
setblock ~169 ~118 ~79 dirt
setblock ~169 ~118 ~80 dirt
setblock ~169 ~118 ~81 dirt
setblock ~169 ~118 ~82 dirt
setblock ~169 ~118 ~83 dirt
setblock ~169 ~118 ~102 dirt
setblock ~169 ~118 ~103 dirt
setblock ~169 ~118 ~104 dirt
setblock ~169 ~118 ~105 dirt
setblock ~169 ~118 ~106 dirt
setblock ~169 ~118 ~107 dirt
setblock ~169 ~118 ~108 dirt
setblock ~169 ~118 ~138 dirt
setblock ~169 ~118 ~139 dirt
setblock ~169 ~118 ~140 dirt
setblock ~169 ~118 ~141 dirt
setblock ~169 ~119 ~73 dirt
setblock ~169 ~119 ~74 dirt
setblock ~169 ~119 ~75 dirt
setblock ~169 ~119 ~76 dirt
setblock ~169 ~119 ~77 dirt
setblock ~169 ~119 ~78 dirt
setblock ~169 ~119 ~79 dirt
setblock ~169 ~119 ~80 dirt
setblock ~169 ~119 ~81 dirt
setblock ~169 ~119 ~82 dirt
setblock ~169 ~119 ~83 dirt
setblock ~169 ~119 ~84 dirt
setblock ~169 ~119 ~101 dirt
setblock ~169 ~119 ~102 dirt
setblock ~169 ~119 ~103 dirt
setblock ~169 ~119 ~104 dirt
setblock ~169 ~119 ~105 dirt
setblock ~169 ~119 ~106 dirt
setblock ~169 ~119 ~107 dirt
setblock ~169 ~119 ~108 dirt
setblock ~169 ~119 ~137 dirt
setblock ~169 ~119 ~138 dirt
setblock ~169 ~119 ~139 dirt
setblock ~169 ~119 ~140 dirt
setblock ~169 ~119 ~141 dirt
setblock ~169 ~120 ~72 dirt
setblock ~169 ~120 ~73 dirt
setblock ~169 ~120 ~74 dirt
setblock ~169 ~120 ~75 dirt
setblock ~169 ~120 ~76 dirt
setblock ~169 ~120 ~77 dirt
setblock ~169 ~120 ~78 dirt
setblock ~169 ~120 ~79 dirt
setblock ~169 ~120 ~80 dirt
setblock ~169 ~120 ~81 dirt
setblock ~169 ~120 ~82 dirt
setblock ~169 ~120 ~83 dirt
setblock ~169 ~120 ~84 dirt
setblock ~169 ~120 ~85 dirt
setblock ~169 ~120 ~101 dirt
setblock ~169 ~120 ~102 dirt
setblock ~169 ~120 ~103 dirt
setblock ~169 ~120 ~104 dirt
setblock ~169 ~120 ~105 dirt
setblock ~169 ~120 ~106 dirt
setblock ~169 ~120 ~107 dirt
setblock ~169 ~120 ~108 dirt
setblock ~169 ~120 ~137 dirt
setblock ~169 ~120 ~138 dirt
setblock ~169 ~120 ~139 dirt
setblock ~169 ~120 ~140 dirt
setblock ~169 ~120 ~141 dirt
setblock ~169 ~120 ~142 dirt
setblock ~169 ~121 ~71 dirt
setblock ~169 ~121 ~72 dirt
setblock ~169 ~121 ~73 dirt
setblock ~169 ~121 ~74 dirt
setblock ~169 ~121 ~75 dirt
setblock ~169 ~121 ~76 dirt
setblock ~169 ~121 ~77 dirt
setblock ~169 ~121 ~78 dirt
setblock ~169 ~121 ~79 dirt
setblock ~169 ~121 ~80 dirt
setblock ~169 ~121 ~81 dirt
setblock ~169 ~121 ~82 dirt
setblock ~169 ~121 ~83 dirt
setblock ~169 ~121 ~84 dirt
setblock ~169 ~121 ~85 dirt
setblock ~169 ~121 ~86 dirt
setblock ~169 ~121 ~100 dirt
setblock ~169 ~121 ~101 dirt
setblock ~169 ~121 ~102 dirt
setblock ~169 ~121 ~103 dirt
setblock ~169 ~121 ~104 dirt
setblock ~169 ~121 ~105 dirt
setblock ~169 ~121 ~106 dirt
setblock ~169 ~121 ~107 dirt
setblock ~169 ~121 ~108 dirt
setblock ~169 ~121 ~109 dirt
setblock ~169 ~121 ~137 dirt
setblock ~169 ~121 ~138 dirt
setblock ~169 ~121 ~139 dirt
setblock ~169 ~121 ~140 dirt
setblock ~169 ~121 ~141 dirt
setblock ~169 ~121 ~142 dirt
setblock ~169 ~121 ~143 dirt
setblock ~169 ~122 ~71 dirt
setblock ~169 ~122 ~72 dirt
setblock ~169 ~122 ~73 dirt
setblock ~169 ~122 ~74 dirt
setblock ~169 ~122 ~75 dirt
setblock ~169 ~122 ~76 dirt
setblock ~169 ~122 ~77 dirt
setblock ~169 ~122 ~78 dirt
setblock ~169 ~122 ~79 dirt
setblock ~169 ~122 ~80 dirt
setblock ~169 ~122 ~81 dirt
setblock ~169 ~122 ~82 dirt
setblock ~169 ~122 ~83 dirt
setblock ~169 ~122 ~84 dirt
setblock ~169 ~122 ~85 dirt
setblock ~169 ~122 ~86 dirt
setblock ~169 ~122 ~100 dirt
setblock ~169 ~122 ~101 dirt
setblock ~169 ~122 ~102 dirt
setblock ~169 ~122 ~103 dirt
setblock ~169 ~122 ~104 dirt
setblock ~169 ~122 ~105 dirt
setblock ~169 ~122 ~106 dirt
setblock ~169 ~122 ~107 dirt
setblock ~169 ~122 ~108 dirt
setblock ~169 ~122 ~109 dirt
setblock ~169 ~122 ~137 dirt
setblock ~169 ~122 ~138 dirt
setblock ~169 ~122 ~139 dirt
setblock ~169 ~122 ~140 dirt
setblock ~169 ~122 ~141 dirt
setblock ~169 ~122 ~142 dirt
setblock ~169 ~122 ~143 dirt
setblock ~169 ~123 ~71 dirt
setblock ~169 ~123 ~72 dirt
setblock ~169 ~123 ~73 dirt
setblock ~169 ~123 ~74 dirt
setblock ~169 ~123 ~75 dirt
setblock ~169 ~123 ~76 dirt
setblock ~169 ~123 ~77 dirt
setblock ~169 ~123 ~78 dirt
setblock ~169 ~123 ~79 dirt
setblock ~169 ~123 ~80 dirt
setblock ~169 ~123 ~81 dirt
setblock ~169 ~123 ~82 dirt
setblock ~169 ~123 ~83 dirt
setblock ~169 ~123 ~84 dirt
setblock ~169 ~123 ~85 dirt
setblock ~169 ~123 ~86 dirt
setblock ~169 ~123 ~100 dirt
setblock ~169 ~123 ~101 dirt
setblock ~169 ~123 ~102 dirt
setblock ~169 ~123 ~103 dirt
setblock ~169 ~123 ~104 dirt
setblock ~169 ~123 ~105 dirt
setblock ~169 ~123 ~106 dirt
setblock ~169 ~123 ~107 dirt
setblock ~169 ~123 ~108 dirt
setblock ~169 ~123 ~109 dirt
setblock ~169 ~123 ~137 dirt
setblock ~169 ~123 ~138 dirt
setblock ~169 ~123 ~139 dirt
setblock ~169 ~123 ~140 dirt
setblock ~169 ~123 ~141 dirt
setblock ~169 ~123 ~142 dirt
setblock ~169 ~123 ~143 dirt
setblock ~169 ~124 ~71 dirt
setblock ~169 ~124 ~72 dirt
setblock ~169 ~124 ~73 dirt
setblock ~169 ~124 ~74 dirt
setblock ~169 ~124 ~75 dirt
setblock ~169 ~124 ~76 dirt
setblock ~169 ~124 ~77 dirt
setblock ~169 ~124 ~78 dirt
setblock ~169 ~124 ~79 dirt
setblock ~169 ~124 ~80 dirt
setblock ~169 ~124 ~81 dirt
setblock ~169 ~124 ~82 dirt
setblock ~169 ~124 ~83 dirt
setblock ~169 ~124 ~84 dirt
setblock ~169 ~124 ~85 dirt
setblock ~169 ~124 ~86 dirt
setblock ~169 ~124 ~100 grass_block
setblock ~169 ~124 ~101 dirt
setblock ~169 ~124 ~102 dirt
setblock ~169 ~124 ~103 dirt
setblock ~169 ~124 ~104 dirt
setblock ~169 ~124 ~105 dirt
setblock ~169 ~124 ~106 dirt
setblock ~169 ~124 ~107 dirt
setblock ~169 ~124 ~108 dirt
setblock ~169 ~124 ~109 dirt
setblock ~169 ~124 ~137 dirt
setblock ~169 ~124 ~138 dirt
setblock ~169 ~124 ~139 dirt
setblock ~169 ~124 ~140 dirt
setblock ~169 ~124 ~141 dirt
setblock ~169 ~124 ~142 dirt
setblock ~169 ~124 ~143 dirt
setblock ~169 ~125 ~71 grass_block
setblock ~169 ~125 ~72 grass_block
setblock ~169 ~125 ~73 grass_block
setblock ~169 ~125 ~74 grass_block
setblock ~169 ~125 ~75 dirt
setblock ~169 ~125 ~76 dirt
setblock ~169 ~125 ~77 dirt
setblock ~169 ~125 ~78 dirt
setblock ~169 ~125 ~79 dirt
setblock ~169 ~125 ~80 dirt
setblock ~169 ~125 ~81 dirt
setblock ~169 ~125 ~82 dirt
setblock ~169 ~125 ~83 dirt
setblock ~169 ~125 ~84 dirt
setblock ~169 ~125 ~85 dirt
setblock ~169 ~125 ~86 dirt
setblock ~169 ~125 ~101 grass_block
setblock ~169 ~125 ~102 grass_block
setblock ~169 ~125 ~103 grass_block
setblock ~169 ~125 ~104 grass_block
setblock ~169 ~125 ~105 dirt
setblock ~169 ~125 ~106 dirt
setblock ~169 ~125 ~107 dirt
setblock ~169 ~125 ~108 dirt
setblock ~169 ~125 ~109 dirt
setblock ~169 ~125 ~137 grass_block
setblock ~169 ~125 ~138 grass_block
setblock ~169 ~125 ~139 grass_block
setblock ~169 ~125 ~140 grass_block
setblock ~169 ~125 ~141 grass_block
setblock ~169 ~125 ~142 dirt
setblock ~169 ~125 ~143 dirt
setblock ~169 ~126 ~73 short_grass
setblock ~169 ~126 ~75 grass_block
setblock ~169 ~126 ~76 grass_block
setblock ~169 ~126 ~77 grass_block
setblock ~169 ~126 ~78 grass_block
setblock ~169 ~126 ~79 grass_block
setblock ~169 ~126 ~80 grass_block
setblock ~169 ~126 ~81 grass_block
setblock ~169 ~126 ~82 dirt
setblock ~169 ~126 ~83 dirt
setblock ~169 ~126 ~84 dirt
setblock ~169 ~126 ~85 dirt
setblock ~169 ~126 ~86 dirt
setblock ~169 ~126 ~102 short_grass
setblock ~169 ~126 ~104 short_grass
setblock ~169 ~126 ~105 grass_block
setblock ~169 ~126 ~106 grass_block
setblock ~169 ~126 ~107 grass_block
setblock ~169 ~126 ~108 grass_block
setblock ~169 ~126 ~109 dirt
setblock ~169 ~126 ~138 short_grass
setblock ~169 ~126 ~142 grass_block
setblock ~169 ~126 ~143 grass_block
setblock ~169 ~127 ~76 short_grass
setblock ~169 ~127 ~82 grass_block
setblock ~169 ~127 ~83 grass_block
setblock ~169 ~127 ~84 grass_block
setblock ~169 ~127 ~85 dirt
setblock ~169 ~127 ~86 dirt
setblock ~169 ~127 ~108 short_grass
setblock ~169 ~127 ~109 grass_block
setblock ~169 ~128 ~82 short_grass
setblock ~169 ~128 ~83 short_grass
setblock ~169 ~128 ~85 grass_block
setblock ~169 ~128 ~86 grass_block
setblock ~170 ~111 ~77 dirt
setblock ~170 ~112 ~76 dirt
setblock ~170 ~112 ~77 dirt
setblock ~170 ~112 ~78 dirt
setblock ~170 ~112 ~105 dirt
setblock ~170 ~113 ~76 dirt
setblock ~170 ~113 ~77 dirt
setblock ~170 ~113 ~78 dirt
setblock ~170 ~113 ~104 dirt
setblock ~170 ~113 ~105 dirt
setblock ~170 ~113 ~106 dirt
setblock ~170 ~114 ~76 dirt
setblock ~170 ~114 ~77 dirt
setblock ~170 ~114 ~78 dirt
setblock ~170 ~114 ~103 dirt
setblock ~170 ~114 ~104 dirt
setblock ~170 ~114 ~105 dirt
setblock ~170 ~114 ~106 dirt
setblock ~170 ~115 ~75 dirt
setblock ~170 ~115 ~76 dirt
setblock ~170 ~115 ~77 dirt
setblock ~170 ~115 ~78 dirt
setblock ~170 ~115 ~79 dirt
setblock ~170 ~115 ~102 dirt
setblock ~170 ~115 ~103 dirt
setblock ~170 ~115 ~104 dirt
setblock ~170 ~115 ~105 dirt
setblock ~170 ~115 ~106 dirt
setblock ~170 ~115 ~139 dirt
setblock ~170 ~116 ~75 dirt
setblock ~170 ~116 ~76 dirt
setblock ~170 ~116 ~77 dirt
setblock ~170 ~116 ~78 dirt
setblock ~170 ~116 ~79 dirt
setblock ~170 ~116 ~80 dirt
setblock ~170 ~116 ~81 dirt
setblock ~170 ~116 ~82 dirt
setblock ~170 ~116 ~102 dirt
setblock ~170 ~116 ~103 dirt
setblock ~170 ~116 ~104 dirt
setblock ~170 ~116 ~105 dirt
setblock ~170 ~116 ~106 dirt
setblock ~170 ~116 ~107 dirt
setblock ~170 ~116 ~138 dirt
setblock ~170 ~116 ~139 dirt
setblock ~170 ~116 ~140 dirt
setblock ~170 ~117 ~74 dirt
setblock ~170 ~117 ~75 dirt
setblock ~170 ~117 ~76 dirt
setblock ~170 ~117 ~77 dirt
setblock ~170 ~117 ~78 dirt
setblock ~170 ~117 ~79 dirt
setblock ~170 ~117 ~80 dirt
setblock ~170 ~117 ~81 dirt
setblock ~170 ~117 ~82 dirt
setblock ~170 ~117 ~102 dirt
setblock ~170 ~117 ~103 dirt
setblock ~170 ~117 ~104 dirt
setblock ~170 ~117 ~105 dirt
setblock ~170 ~117 ~106 dirt
setblock ~170 ~117 ~107 dirt
setblock ~170 ~117 ~138 dirt
setblock ~170 ~117 ~139 dirt
setblock ~170 ~117 ~140 dirt
setblock ~170 ~117 ~141 dirt
setblock ~170 ~118 ~73 dirt
setblock ~170 ~118 ~74 dirt
setblock ~170 ~118 ~75 dirt
setblock ~170 ~118 ~76 dirt
setblock ~170 ~118 ~77 dirt
setblock ~170 ~118 ~78 dirt
setblock ~170 ~118 ~79 dirt
setblock ~170 ~118 ~80 dirt
setblock ~170 ~118 ~81 dirt
setblock ~170 ~118 ~82 dirt
setblock ~170 ~118 ~83 dirt
setblock ~170 ~118 ~101 dirt
setblock ~170 ~118 ~102 dirt
setblock ~170 ~118 ~103 dirt
setblock ~170 ~118 ~104 dirt
setblock ~170 ~118 ~105 dirt
setblock ~170 ~118 ~106 dirt
setblock ~170 ~118 ~107 dirt
setblock ~170 ~118 ~138 dirt
setblock ~170 ~118 ~139 dirt
setblock ~170 ~118 ~140 dirt
setblock ~170 ~118 ~141 dirt
setblock ~170 ~118 ~142 dirt
setblock ~170 ~119 ~73 dirt
setblock ~170 ~119 ~74 dirt
setblock ~170 ~119 ~75 dirt
setblock ~170 ~119 ~76 dirt
setblock ~170 ~119 ~77 dirt
setblock ~170 ~119 ~78 dirt
setblock ~170 ~119 ~79 dirt
setblock ~170 ~119 ~80 dirt
setblock ~170 ~119 ~81 dirt
setblock ~170 ~119 ~82 dirt
setblock ~170 ~119 ~83 dirt
setblock ~170 ~119 ~101 dirt
setblock ~170 ~119 ~102 dirt
setblock ~170 ~119 ~103 dirt
setblock ~170 ~119 ~104 dirt
setblock ~170 ~119 ~105 dirt
setblock ~170 ~119 ~106 dirt
setblock ~170 ~119 ~107 dirt
setblock ~170 ~119 ~108 dirt
setblock ~170 ~119 ~137 dirt
setblock ~170 ~119 ~138 dirt
setblock ~170 ~119 ~139 dirt
setblock ~170 ~119 ~140 dirt
setblock ~170 ~119 ~141 dirt
setblock ~170 ~119 ~142 dirt
setblock ~170 ~120 ~73 dirt
setblock ~170 ~120 ~74 dirt
setblock ~170 ~120 ~75 dirt
setblock ~170 ~120 ~76 dirt
setblock ~170 ~120 ~77 dirt
setblock ~170 ~120 ~78 dirt
setblock ~170 ~120 ~79 dirt
setblock ~170 ~120 ~80 dirt
setblock ~170 ~120 ~81 dirt
setblock ~170 ~120 ~82 dirt
setblock ~170 ~120 ~83 dirt
setblock ~170 ~120 ~84 dirt
setblock ~170 ~120 ~101 dirt
setblock ~170 ~120 ~102 dirt
setblock ~170 ~120 ~103 dirt
setblock ~170 ~120 ~104 dirt
setblock ~170 ~120 ~105 dirt
setblock ~170 ~120 ~106 dirt
setblock ~170 ~120 ~107 dirt
setblock ~170 ~120 ~108 dirt
setblock ~170 ~120 ~137 dirt
setblock ~170 ~120 ~138 dirt
setblock ~170 ~120 ~139 dirt
setblock ~170 ~120 ~140 dirt
setblock ~170 ~120 ~141 dirt
setblock ~170 ~120 ~142 dirt
setblock ~170 ~121 ~72 dirt
setblock ~170 ~121 ~73 dirt
setblock ~170 ~121 ~74 dirt
setblock ~170 ~121 ~75 dirt
setblock ~170 ~121 ~76 dirt
setblock ~170 ~121 ~77 dirt
setblock ~170 ~121 ~78 dirt
setblock ~170 ~121 ~79 dirt
setblock ~170 ~121 ~80 dirt
setblock ~170 ~121 ~81 dirt
setblock ~170 ~121 ~82 dirt
setblock ~170 ~121 ~83 dirt
setblock ~170 ~121 ~84 dirt
setblock ~170 ~121 ~85 dirt
setblock ~170 ~121 ~101 dirt
setblock ~170 ~121 ~102 dirt
setblock ~170 ~121 ~103 dirt
setblock ~170 ~121 ~104 dirt
setblock ~170 ~121 ~105 dirt
setblock ~170 ~121 ~106 dirt
setblock ~170 ~121 ~107 dirt
setblock ~170 ~121 ~108 dirt
setblock ~170 ~121 ~109 dirt
setblock ~170 ~121 ~136 dirt
setblock ~170 ~121 ~137 dirt
setblock ~170 ~121 ~138 dirt
setblock ~170 ~121 ~139 dirt
setblock ~170 ~121 ~140 dirt
setblock ~170 ~121 ~141 dirt
setblock ~170 ~121 ~142 dirt
setblock ~170 ~122 ~72 dirt
setblock ~170 ~122 ~73 dirt
setblock ~170 ~122 ~74 dirt
setblock ~170 ~122 ~75 dirt
setblock ~170 ~122 ~76 dirt
setblock ~170 ~122 ~77 dirt
setblock ~170 ~122 ~78 dirt
setblock ~170 ~122 ~79 dirt
setblock ~170 ~122 ~80 dirt
setblock ~170 ~122 ~81 dirt
setblock ~170 ~122 ~82 dirt
setblock ~170 ~122 ~83 dirt
setblock ~170 ~122 ~84 dirt
setblock ~170 ~122 ~85 dirt
setblock ~170 ~122 ~101 dirt
setblock ~170 ~122 ~102 dirt
setblock ~170 ~122 ~103 dirt
setblock ~170 ~122 ~104 dirt
setblock ~170 ~122 ~105 dirt
setblock ~170 ~122 ~106 dirt
setblock ~170 ~122 ~107 dirt
setblock ~170 ~122 ~108 dirt
setblock ~170 ~122 ~109 dirt
setblock ~170 ~122 ~136 dirt
setblock ~170 ~122 ~137 dirt
setblock ~170 ~122 ~138 dirt
setblock ~170 ~122 ~139 dirt
setblock ~170 ~122 ~140 dirt
setblock ~170 ~122 ~141 dirt
setblock ~170 ~122 ~142 dirt
setblock ~170 ~123 ~72 dirt
setblock ~170 ~123 ~73 dirt
setblock ~170 ~123 ~74 dirt
setblock ~170 ~123 ~75 dirt
setblock ~170 ~123 ~76 dirt
setblock ~170 ~123 ~77 dirt
setblock ~170 ~123 ~78 dirt
setblock ~170 ~123 ~79 dirt
setblock ~170 ~123 ~80 dirt
setblock ~170 ~123 ~81 dirt
setblock ~170 ~123 ~82 dirt
setblock ~170 ~123 ~83 dirt
setblock ~170 ~123 ~84 dirt
setblock ~170 ~123 ~85 dirt
setblock ~170 ~123 ~101 dirt
setblock ~170 ~123 ~102 dirt
setblock ~170 ~123 ~103 dirt
setblock ~170 ~123 ~104 dirt
setblock ~170 ~123 ~105 dirt
setblock ~170 ~123 ~106 dirt
setblock ~170 ~123 ~107 dirt
setblock ~170 ~123 ~108 dirt
setblock ~170 ~123 ~109 dirt
setblock ~170 ~123 ~136 dirt
setblock ~170 ~123 ~137 dirt
setblock ~170 ~123 ~138 dirt
setblock ~170 ~123 ~139 dirt
setblock ~170 ~123 ~140 dirt
setblock ~170 ~123 ~141 dirt
setblock ~170 ~123 ~142 dirt
setblock ~170 ~124 ~72 dirt
setblock ~170 ~124 ~73 dirt
setblock ~170 ~124 ~74 dirt
setblock ~170 ~124 ~75 dirt
setblock ~170 ~124 ~76 dirt
setblock ~170 ~124 ~77 dirt
setblock ~170 ~124 ~78 dirt
setblock ~170 ~124 ~79 dirt
setblock ~170 ~124 ~80 dirt
setblock ~170 ~124 ~81 dirt
setblock ~170 ~124 ~82 dirt
setblock ~170 ~124 ~83 dirt
setblock ~170 ~124 ~84 dirt
setblock ~170 ~124 ~85 dirt
setblock ~170 ~124 ~101 dirt
setblock ~170 ~124 ~102 dirt
setblock ~170 ~124 ~103 dirt
setblock ~170 ~124 ~104 dirt
setblock ~170 ~124 ~105 dirt
setblock ~170 ~124 ~106 dirt
setblock ~170 ~124 ~107 dirt
setblock ~170 ~124 ~108 dirt
setblock ~170 ~124 ~109 dirt
setblock ~170 ~124 ~136 dirt
setblock ~170 ~124 ~137 dirt
setblock ~170 ~124 ~138 dirt
setblock ~170 ~124 ~139 dirt
setblock ~170 ~124 ~140 dirt
setblock ~170 ~124 ~141 dirt
setblock ~170 ~124 ~142 dirt
setblock ~170 ~125 ~72 grass_block
setblock ~170 ~125 ~73 dirt
setblock ~170 ~125 ~74 dirt
setblock ~170 ~125 ~75 dirt
setblock ~170 ~125 ~76 dirt
setblock ~170 ~125 ~77 dirt
setblock ~170 ~125 ~78 dirt
setblock ~170 ~125 ~79 dirt
setblock ~170 ~125 ~80 dirt
setblock ~170 ~125 ~81 dirt
setblock ~170 ~125 ~82 dirt
setblock ~170 ~125 ~83 dirt
setblock ~170 ~125 ~84 dirt
setblock ~170 ~125 ~85 dirt
setblock ~170 ~125 ~101 grass_block
setblock ~170 ~125 ~102 grass_block
setblock ~170 ~125 ~103 grass_block
setblock ~170 ~125 ~104 dirt
setblock ~170 ~125 ~105 dirt
setblock ~170 ~125 ~106 dirt
setblock ~170 ~125 ~107 dirt
setblock ~170 ~125 ~108 dirt
setblock ~170 ~125 ~109 dirt
setblock ~170 ~125 ~136 grass_block
setblock ~170 ~125 ~137 grass_block
setblock ~170 ~125 ~138 grass_block
setblock ~170 ~125 ~139 grass_block
setblock ~170 ~125 ~140 grass_block
setblock ~170 ~125 ~141 dirt
setblock ~170 ~125 ~142 dirt
setblock ~170 ~126 ~73 grass_block
setblock ~170 ~126 ~74 grass_block
setblock ~170 ~126 ~75 grass_block
setblock ~170 ~126 ~76 grass_block
setblock ~170 ~126 ~77 grass_block
setblock ~170 ~126 ~78 grass_block
setblock ~170 ~126 ~79 grass_block
setblock ~170 ~126 ~80 grass_block
setblock ~170 ~126 ~81 grass_block
setblock ~170 ~126 ~82 dirt
setblock ~170 ~126 ~83 dirt
setblock ~170 ~126 ~84 dirt
setblock ~170 ~126 ~85 dirt
setblock ~170 ~126 ~101 short_grass
setblock ~170 ~126 ~102 short_grass
setblock ~170 ~126 ~104 grass_block
setblock ~170 ~126 ~105 grass_block
setblock ~170 ~126 ~106 grass_block
setblock ~170 ~126 ~107 grass_block
setblock ~170 ~126 ~108 dirt
setblock ~170 ~126 ~109 dirt
setblock ~170 ~126 ~137 short_grass
setblock ~170 ~126 ~141 grass_block
setblock ~170 ~126 ~142 grass_block
setblock ~170 ~127 ~73 poppy
setblock ~170 ~127 ~77 short_grass
setblock ~170 ~127 ~80 short_grass
setblock ~170 ~127 ~82 grass_block
setblock ~170 ~127 ~83 grass_block
setblock ~170 ~127 ~84 grass_block
setblock ~170 ~127 ~85 dirt
setblock ~170 ~127 ~105 short_grass
setblock ~170 ~127 ~106 short_grass
setblock ~170 ~127 ~107 short_grass
setblock ~170 ~127 ~108 grass_block
setblock ~170 ~127 ~109 grass_block
setblock ~170 ~127 ~141 short_grass
setblock ~170 ~128 ~83 short_grass
setblock ~170 ~128 ~85 grass_block
setblock ~170 ~128 ~109 short_grass
setblock ~171 ~112 ~77 dirt
setblock ~171 ~113 ~77 dirt
setblock ~171 ~113 ~105 dirt
setblock ~171 ~114 ~77 dirt
setblock ~171 ~114 ~104 dirt
setblock ~171 ~114 ~105 dirt
setblock ~171 ~115 ~76 dirt
setblock ~171 ~115 ~77 dirt
setblock ~171 ~115 ~78 dirt
setblock ~171 ~115 ~103 dirt
setblock ~171 ~115 ~104 dirt
setblock ~171 ~115 ~105 dirt
setblock ~171 ~116 ~76 dirt
setblock ~171 ~116 ~77 dirt
setblock ~171 ~116 ~78 dirt
setblock ~171 ~116 ~79 dirt
setblock ~171 ~116 ~103 dirt
setblock ~171 ~116 ~104 dirt
setblock ~171 ~116 ~105 dirt
setblock ~171 ~116 ~106 dirt
setblock ~171 ~116 ~139 dirt
setblock ~171 ~117 ~75 dirt
setblock ~171 ~117 ~76 dirt
setblock ~171 ~117 ~77 dirt
setblock ~171 ~117 ~78 dirt
setblock ~171 ~117 ~79 dirt
setblock ~171 ~117 ~103 dirt
setblock ~171 ~117 ~104 dirt
setblock ~171 ~117 ~105 dirt
setblock ~171 ~117 ~106 dirt
setblock ~171 ~117 ~107 dirt
setblock ~171 ~117 ~139 dirt
setblock ~171 ~117 ~140 dirt
setblock ~171 ~118 ~74 dirt
setblock ~171 ~118 ~75 dirt
setblock ~171 ~118 ~76 dirt
setblock ~171 ~118 ~77 dirt
setblock ~171 ~118 ~78 dirt
setblock ~171 ~118 ~79 dirt
setblock ~171 ~118 ~80 dirt
setblock ~171 ~118 ~82 dirt
setblock ~171 ~118 ~102 dirt
setblock ~171 ~118 ~103 dirt
setblock ~171 ~118 ~104 dirt
setblock ~171 ~118 ~105 dirt
setblock ~171 ~118 ~106 dirt
setblock ~171 ~118 ~107 dirt
setblock ~171 ~118 ~138 dirt
setblock ~171 ~118 ~139 dirt
setblock ~171 ~118 ~140 dirt
setblock ~171 ~118 ~141 dirt
setblock ~171 ~119 ~73 dirt
setblock ~171 ~119 ~74 dirt
setblock ~171 ~119 ~75 dirt
setblock ~171 ~119 ~76 dirt
setblock ~171 ~119 ~77 dirt
setblock ~171 ~119 ~78 dirt
setblock ~171 ~119 ~79 dirt
setblock ~171 ~119 ~80 dirt
setblock ~171 ~119 ~81 dirt
setblock ~171 ~119 ~82 dirt
setblock ~171 ~119 ~83 dirt
setblock ~171 ~119 ~101 dirt
setblock ~171 ~119 ~102 dirt
setblock ~171 ~119 ~103 dirt
setblock ~171 ~119 ~104 dirt
setblock ~171 ~119 ~105 dirt
setblock ~171 ~119 ~106 dirt
setblock ~171 ~119 ~107 dirt
setblock ~171 ~119 ~108 dirt
setblock ~171 ~119 ~138 dirt
setblock ~171 ~119 ~139 dirt
setblock ~171 ~119 ~140 dirt
setblock ~171 ~119 ~141 dirt
setblock ~171 ~120 ~73 dirt
setblock ~171 ~120 ~74 dirt
setblock ~171 ~120 ~75 dirt
setblock ~171 ~120 ~76 dirt
setblock ~171 ~120 ~77 dirt
setblock ~171 ~120 ~78 dirt
setblock ~171 ~120 ~79 dirt
setblock ~171 ~120 ~80 dirt
setblock ~171 ~120 ~81 dirt
setblock ~171 ~120 ~82 dirt
setblock ~171 ~120 ~83 dirt
setblock ~171 ~120 ~101 dirt
setblock ~171 ~120 ~102 dirt
setblock ~171 ~120 ~103 dirt
setblock ~171 ~120 ~104 dirt
setblock ~171 ~120 ~105 dirt
setblock ~171 ~120 ~106 dirt
setblock ~171 ~120 ~107 dirt
setblock ~171 ~120 ~108 dirt
setblock ~171 ~120 ~137 dirt
setblock ~171 ~120 ~138 dirt
setblock ~171 ~120 ~139 dirt
setblock ~171 ~120 ~140 dirt
setblock ~171 ~120 ~141 dirt
setblock ~171 ~121 ~73 dirt
setblock ~171 ~121 ~74 dirt
setblock ~171 ~121 ~75 dirt
setblock ~171 ~121 ~76 dirt
setblock ~171 ~121 ~77 dirt
setblock ~171 ~121 ~78 dirt
setblock ~171 ~121 ~79 dirt
setblock ~171 ~121 ~80 dirt
setblock ~171 ~121 ~81 dirt
setblock ~171 ~121 ~82 dirt
setblock ~171 ~121 ~83 dirt
setblock ~171 ~121 ~84 dirt
setblock ~171 ~121 ~101 dirt
setblock ~171 ~121 ~102 dirt
setblock ~171 ~121 ~103 dirt
setblock ~171 ~121 ~104 dirt
setblock ~171 ~121 ~105 dirt
setblock ~171 ~121 ~106 dirt
setblock ~171 ~121 ~107 dirt
setblock ~171 ~121 ~108 dirt
setblock ~171 ~121 ~109 dirt
setblock ~171 ~121 ~137 dirt
setblock ~171 ~121 ~138 dirt
setblock ~171 ~121 ~139 dirt
setblock ~171 ~121 ~140 dirt
setblock ~171 ~121 ~141 dirt
setblock ~171 ~122 ~73 dirt
setblock ~171 ~122 ~74 dirt
setblock ~171 ~122 ~75 dirt
setblock ~171 ~122 ~76 dirt
setblock ~171 ~122 ~77 dirt
setblock ~171 ~122 ~78 dirt
setblock ~171 ~122 ~79 dirt
setblock ~171 ~122 ~80 dirt
setblock ~171 ~122 ~81 dirt
setblock ~171 ~122 ~82 dirt
setblock ~171 ~122 ~83 dirt
setblock ~171 ~122 ~84 dirt
setblock ~171 ~122 ~101 dirt
setblock ~171 ~122 ~102 dirt
setblock ~171 ~122 ~103 dirt
setblock ~171 ~122 ~104 dirt
setblock ~171 ~122 ~105 dirt
setblock ~171 ~122 ~106 dirt
setblock ~171 ~122 ~107 dirt
setblock ~171 ~122 ~108 dirt
setblock ~171 ~122 ~109 dirt
setblock ~171 ~122 ~137 dirt
setblock ~171 ~122 ~138 dirt
setblock ~171 ~122 ~139 dirt
setblock ~171 ~122 ~140 dirt
setblock ~171 ~122 ~141 dirt
setblock ~171 ~123 ~73 dirt
setblock ~171 ~123 ~74 dirt
setblock ~171 ~123 ~75 dirt
setblock ~171 ~123 ~76 dirt
setblock ~171 ~123 ~77 dirt
setblock ~171 ~123 ~78 dirt
setblock ~171 ~123 ~79 dirt
setblock ~171 ~123 ~80 dirt
setblock ~171 ~123 ~81 dirt
setblock ~171 ~123 ~82 dirt
setblock ~171 ~123 ~83 dirt
setblock ~171 ~123 ~84 dirt
setblock ~171 ~123 ~101 dirt
setblock ~171 ~123 ~102 dirt
setblock ~171 ~123 ~103 dirt
setblock ~171 ~123 ~104 dirt
setblock ~171 ~123 ~105 dirt
setblock ~171 ~123 ~106 dirt
setblock ~171 ~123 ~107 dirt
setblock ~171 ~123 ~108 dirt
setblock ~171 ~123 ~109 dirt
setblock ~171 ~123 ~137 dirt
setblock ~171 ~123 ~138 dirt
setblock ~171 ~123 ~139 dirt
setblock ~171 ~123 ~140 dirt
setblock ~171 ~123 ~141 dirt
setblock ~171 ~124 ~73 dirt
setblock ~171 ~124 ~74 dirt
setblock ~171 ~124 ~75 dirt
setblock ~171 ~124 ~76 dirt
setblock ~171 ~124 ~77 dirt
setblock ~171 ~124 ~78 dirt
setblock ~171 ~124 ~79 dirt
setblock ~171 ~124 ~80 dirt
setblock ~171 ~124 ~81 dirt
setblock ~171 ~124 ~82 dirt
setblock ~171 ~124 ~83 dirt
setblock ~171 ~124 ~84 dirt
setblock ~171 ~124 ~101 dirt
setblock ~171 ~124 ~102 dirt
setblock ~171 ~124 ~103 dirt
setblock ~171 ~124 ~104 dirt
setblock ~171 ~124 ~105 dirt
setblock ~171 ~124 ~106 dirt
setblock ~171 ~124 ~107 dirt
setblock ~171 ~124 ~108 dirt
setblock ~171 ~124 ~109 dirt
setblock ~171 ~124 ~137 dirt
setblock ~171 ~124 ~138 dirt
setblock ~171 ~124 ~139 dirt
setblock ~171 ~124 ~140 dirt
setblock ~171 ~124 ~141 dirt
setblock ~171 ~125 ~73 grass_block
setblock ~171 ~125 ~74 dirt
setblock ~171 ~125 ~75 dirt
setblock ~171 ~125 ~76 dirt
setblock ~171 ~125 ~77 dirt
setblock ~171 ~125 ~78 dirt
setblock ~171 ~125 ~79 dirt
setblock ~171 ~125 ~80 dirt
setblock ~171 ~125 ~81 dirt
setblock ~171 ~125 ~82 dirt
setblock ~171 ~125 ~83 dirt
setblock ~171 ~125 ~84 dirt
setblock ~171 ~125 ~101 grass_block
setblock ~171 ~125 ~102 grass_block
setblock ~171 ~125 ~103 grass_block
setblock ~171 ~125 ~104 dirt
setblock ~171 ~125 ~105 dirt
setblock ~171 ~125 ~106 dirt
setblock ~171 ~125 ~107 dirt
setblock ~171 ~125 ~108 dirt
setblock ~171 ~125 ~109 dirt
setblock ~171 ~125 ~137 grass_block
setblock ~171 ~125 ~138 grass_block
setblock ~171 ~125 ~139 grass_block
setblock ~171 ~125 ~140 grass_block
setblock ~171 ~125 ~141 dirt
setblock ~171 ~126 ~74 grass_block
setblock ~171 ~126 ~75 grass_block
setblock ~171 ~126 ~76 grass_block
setblock ~171 ~126 ~77 grass_block
setblock ~171 ~126 ~78 grass_block
setblock ~171 ~126 ~79 grass_block
setblock ~171 ~126 ~80 grass_block
setblock ~171 ~126 ~81 grass_block
setblock ~171 ~126 ~82 dirt
setblock ~171 ~126 ~83 dirt
setblock ~171 ~126 ~84 dirt
setblock ~171 ~126 ~101 short_grass
setblock ~171 ~126 ~104 grass_block
setblock ~171 ~126 ~105 grass_block
setblock ~171 ~126 ~106 grass_block
setblock ~171 ~126 ~107 dirt
setblock ~171 ~126 ~108 dirt
setblock ~171 ~126 ~109 dirt
setblock ~171 ~126 ~141 grass_block
setblock ~171 ~127 ~76 short_grass
setblock ~171 ~127 ~82 grass_block
setblock ~171 ~127 ~83 grass_block
setblock ~171 ~127 ~84 grass_block
setblock ~171 ~127 ~107 grass_block
setblock ~171 ~127 ~108 grass_block
setblock ~171 ~127 ~109 grass_block
setblock ~171 ~128 ~84 poppy
setblock ~172 ~115 ~77 dirt
setblock ~172 ~116 ~77 dirt
setblock ~172 ~116 ~78 dirt
setblock ~172 ~117 ~77 dirt
setblock ~172 ~117 ~78 dirt
setblock ~172 ~117 ~79 dirt
setblock ~172 ~117 ~105 dirt
setblock ~172 ~117 ~106 dirt
setblock ~172 ~118 ~76 dirt
setblock ~172 ~118 ~77 dirt
setblock ~172 ~118 ~78 dirt
setblock ~172 ~118 ~79 dirt
setblock ~172 ~118 ~103 dirt
setblock ~172 ~118 ~104 dirt
setblock ~172 ~118 ~105 dirt
setblock ~172 ~118 ~106 dirt
setblock ~172 ~118 ~107 dirt
setblock ~172 ~118 ~139 dirt
setblock ~172 ~119 ~74 dirt
setblock ~172 ~119 ~76 dirt
setblock ~172 ~119 ~77 dirt
setblock ~172 ~119 ~78 dirt
setblock ~172 ~119 ~79 dirt
setblock ~172 ~119 ~80 dirt
setblock ~172 ~119 ~82 dirt
setblock ~172 ~119 ~102 dirt
setblock ~172 ~119 ~103 dirt
setblock ~172 ~119 ~104 dirt
setblock ~172 ~119 ~105 dirt
setblock ~172 ~119 ~106 dirt
setblock ~172 ~119 ~107 dirt
setblock ~172 ~119 ~108 dirt
setblock ~172 ~119 ~139 dirt
setblock ~172 ~119 ~140 dirt
setblock ~172 ~120 ~73 dirt
setblock ~172 ~120 ~74 dirt
setblock ~172 ~120 ~75 dirt
setblock ~172 ~120 ~76 dirt
setblock ~172 ~120 ~77 dirt
setblock ~172 ~120 ~78 dirt
setblock ~172 ~120 ~79 dirt
setblock ~172 ~120 ~80 dirt
setblock ~172 ~120 ~81 dirt
setblock ~172 ~120 ~82 dirt
setblock ~172 ~120 ~101 dirt
setblock ~172 ~120 ~102 dirt
setblock ~172 ~120 ~103 dirt
setblock ~172 ~120 ~104 dirt
setblock ~172 ~120 ~105 dirt
setblock ~172 ~120 ~106 dirt
setblock ~172 ~120 ~107 dirt
setblock ~172 ~120 ~108 dirt
setblock ~172 ~120 ~138 dirt
setblock ~172 ~120 ~139 dirt
setblock ~172 ~120 ~140 dirt
setblock ~172 ~121 ~73 dirt
setblock ~172 ~121 ~74 dirt
setblock ~172 ~121 ~75 dirt
setblock ~172 ~121 ~76 dirt
setblock ~172 ~121 ~77 dirt
setblock ~172 ~121 ~78 dirt
setblock ~172 ~121 ~79 dirt
setblock ~172 ~121 ~80 dirt
setblock ~172 ~121 ~81 dirt
setblock ~172 ~121 ~82 dirt
setblock ~172 ~121 ~101 dirt
setblock ~172 ~121 ~102 dirt
setblock ~172 ~121 ~103 dirt
setblock ~172 ~121 ~104 dirt
setblock ~172 ~121 ~105 dirt
setblock ~172 ~121 ~106 dirt
setblock ~172 ~121 ~107 dirt
setblock ~172 ~121 ~108 dirt
setblock ~172 ~121 ~137 dirt
setblock ~172 ~121 ~138 dirt
setblock ~172 ~121 ~139 dirt
setblock ~172 ~121 ~140 dirt
setblock ~172 ~121 ~141 dirt
setblock ~172 ~122 ~73 dirt
setblock ~172 ~122 ~74 dirt
setblock ~172 ~122 ~75 dirt
setblock ~172 ~122 ~76 dirt
setblock ~172 ~122 ~77 dirt
setblock ~172 ~122 ~78 dirt
setblock ~172 ~122 ~79 dirt
