setblock ~175 ~124 ~58 short_grass
setblock ~175 ~124 ~63 grass_block
setblock ~175 ~124 ~64 grass_block
setblock ~175 ~124 ~65 dirt
setblock ~175 ~124 ~66 dirt
setblock ~175 ~124 ~67 dirt
setblock ~175 ~124 ~68 dirt
setblock ~175 ~124 ~69 dirt
setblock ~175 ~124 ~70 dirt
setblock ~175 ~124 ~71 dirt
setblock ~175 ~124 ~72 dirt
setblock ~175 ~124 ~73 dirt
setblock ~175 ~124 ~74 dirt
setblock ~175 ~124 ~75 dirt
setblock ~175 ~124 ~76 dirt
setblock ~175 ~124 ~77 grass_block
setblock ~175 ~124 ~78 grass_block
setblock ~175 ~124 ~79 grass_block
setblock ~175 ~124 ~80 grass_block
setblock ~175 ~124 ~81 grass_block
setblock ~175 ~124 ~82 grass_block
setblock ~175 ~124 ~83 grass_block
setblock ~175 ~124 ~84 dirt
setblock ~175 ~124 ~85 dirt
setblock ~175 ~124 ~86 dirt
setblock ~175 ~124 ~87 dirt
setblock ~175 ~124 ~88 dirt
setblock ~175 ~124 ~89 dirt
setblock ~175 ~124 ~90 dirt
setblock ~175 ~124 ~91 dirt
setblock ~175 ~124 ~92 dirt
setblock ~175 ~124 ~93 dirt
setblock ~175 ~124 ~94 dirt
setblock ~175 ~124 ~95 dirt
setblock ~175 ~124 ~96 dirt
setblock ~175 ~124 ~97 dirt
setblock ~175 ~124 ~98 dirt
setblock ~175 ~124 ~99 dirt
setblock ~175 ~124 ~100 dirt
setblock ~175 ~124 ~101 grass_block
setblock ~175 ~124 ~102 grass_block
setblock ~175 ~124 ~103 grass_block
setblock ~175 ~124 ~104 grass_block
setblock ~175 ~124 ~105 grass_block
setblock ~175 ~124 ~106 grass_block
setblock ~175 ~124 ~107 grass_block
setblock ~175 ~124 ~108 grass_block
setblock ~175 ~124 ~109 short_grass
setblock ~175 ~124 ~110 short_grass
setblock ~175 ~124 ~112 grass_block
setblock ~175 ~124 ~113 grass_block
setblock ~175 ~124 ~114 grass_block
setblock ~175 ~124 ~115 grass_block
setblock ~175 ~124 ~116 grass_block
setblock ~175 ~124 ~117 grass_block
setblock ~175 ~124 ~118 grass_block
setblock ~175 ~124 ~119 grass_block
setblock ~175 ~124 ~120 grass_block
setblock ~175 ~124 ~121 grass_block
setblock ~175 ~124 ~122 grass_block
setblock ~175 ~124 ~123 dirt
setblock ~175 ~124 ~124 dirt
setblock ~175 ~124 ~125 dirt
setblock ~175 ~124 ~126 dirt
setblock ~175 ~124 ~127 dirt
setblock ~175 ~124 ~128 dirt
setblock ~175 ~124 ~129 dirt
setblock ~175 ~124 ~130 dirt
setblock ~175 ~124 ~131 dirt
setblock ~175 ~124 ~132 dirt
setblock ~175 ~124 ~133 dirt
setblock ~175 ~124 ~134 dirt
setblock ~175 ~124 ~135 dirt
setblock ~175 ~124 ~136 dirt
setblock ~175 ~124 ~137 grass_block
setblock ~175 ~124 ~138 grass_block
setblock ~175 ~124 ~139 grass_block
setblock ~175 ~124 ~140 grass_block
setblock ~175 ~124 ~141 grass_block
setblock ~175 ~124 ~142 grass_block
setblock ~175 ~124 ~143 grass_block
setblock ~175 ~124 ~144 grass_block
setblock ~175 ~124 ~145 grass_block
setblock ~175 ~124 ~146 grass_block
setblock ~175 ~124 ~147 grass_block
setblock ~175 ~124 ~148 grass_block
setblock ~175 ~124 ~149 dirt
setblock ~175 ~124 ~150 dirt
setblock ~175 ~124 ~151 dirt
setblock ~175 ~124 ~152 dirt
setblock ~175 ~124 ~153 dirt
setblock ~175 ~124 ~154 dirt
setblock ~175 ~124 ~155 grass_block
setblock ~175 ~124 ~156 grass_block
setblock ~175 ~124 ~157 grass_block
setblock ~175 ~124 ~158 grass_block
setblock ~175 ~124 ~159 grass_block
setblock ~175 ~124 ~160 grass_block
setblock ~175 ~124 ~161 grass_block
setblock ~175 ~124 ~162 dirt
setblock ~175 ~124 ~163 dirt
setblock ~175 ~124 ~164 dirt
setblock ~175 ~124 ~165 dirt
setblock ~175 ~124 ~166 dirt
setblock ~175 ~124 ~167 dirt
setblock ~175 ~124 ~168 dirt
setblock ~175 ~124 ~169 dirt
setblock ~175 ~124 ~170 dirt
setblock ~175 ~124 ~171 dirt
setblock ~175 ~124 ~172 dirt
setblock ~175 ~124 ~173 dirt
setblock ~175 ~124 ~174 dirt
setblock ~175 ~124 ~175 dirt
setblock ~175 ~124 ~176 dirt
setblock ~175 ~124 ~177 dirt
setblock ~175 ~124 ~178 dirt
setblock ~175 ~124 ~179 dirt
setblock ~175 ~124 ~180 dirt
setblock ~175 ~124 ~181 dirt
setblock ~175 ~124 ~182 dirt
setblock ~175 ~124 ~183 dirt
setblock ~175 ~124 ~184 dirt
setblock ~175 ~124 ~185 dirt
setblock ~175 ~124 ~186 dirt
setblock ~175 ~124 ~187 dirt
setblock ~175 ~124 ~188 dirt
setblock ~175 ~124 ~189 dirt
setblock ~175 ~124 ~190 dirt
setblock ~175 ~124 ~191 dirt
setblock ~175 ~124 ~192 dirt
setblock ~175 ~124 ~193 dirt
setblock ~175 ~124 ~194 dirt
setblock ~175 ~124 ~195 dirt
setblock ~175 ~124 ~196 dirt
setblock ~175 ~124 ~197 dirt
setblock ~175 ~124 ~198 dirt
setblock ~175 ~124 ~199 grass_block
setblock ~175 ~125 ~0 grass_block
setblock ~175 ~125 ~1 grass_block
setblock ~175 ~125 ~2 grass_block
setblock ~175 ~125 ~3 grass_block
setblock ~175 ~125 ~4 grass_block
setblock ~175 ~125 ~5 grass_block
setblock ~175 ~125 ~8 poppy
setblock ~175 ~125 ~9 short_grass
setblock ~175 ~125 ~14 short_grass
setblock ~175 ~125 ~22 short_grass
setblock ~175 ~125 ~23 grass_block
setblock ~175 ~125 ~24 grass_block
setblock ~175 ~125 ~25 grass_block
setblock ~175 ~125 ~26 grass_block
setblock ~175 ~125 ~27 grass_block
setblock ~175 ~125 ~28 grass_block
setblock ~175 ~125 ~29 grass_block
setblock ~175 ~125 ~30 grass_block
setblock ~175 ~125 ~31 grass_block
setblock ~175 ~125 ~34 short_grass
setblock ~175 ~125 ~38 short_grass
setblock ~175 ~125 ~40 short_grass
setblock ~175 ~125 ~43 short_grass
setblock ~175 ~125 ~49 short_grass
setblock ~175 ~125 ~50 short_grass
setblock ~175 ~125 ~54 short_grass
setblock ~175 ~125 ~64 short_grass
setblock ~175 ~125 ~65 grass_block
setblock ~175 ~125 ~66 grass_block
setblock ~175 ~125 ~67 dirt
setblock ~175 ~125 ~68 dirt
setblock ~175 ~125 ~69 dirt
setblock ~175 ~125 ~70 dirt
setblock ~175 ~125 ~71 dirt
setblock ~175 ~125 ~72 dirt
setblock ~175 ~125 ~73 dirt
setblock ~175 ~125 ~74 dirt
setblock ~175 ~125 ~75 grass_block
setblock ~175 ~125 ~76 grass_block
setblock ~175 ~125 ~77 poppy
setblock ~175 ~125 ~84 grass_block
setblock ~175 ~125 ~85 grass_block
setblock ~175 ~125 ~86 grass_block
setblock ~175 ~125 ~87 dirt
setblock ~175 ~125 ~88 dirt
setblock ~175 ~125 ~89 dirt
setblock ~175 ~125 ~90 dirt
setblock ~175 ~125 ~91 dirt
setblock ~175 ~125 ~92 dirt
setblock ~175 ~125 ~93 dirt
setblock ~175 ~125 ~94 dirt
setblock ~175 ~125 ~95 dirt
setblock ~175 ~125 ~96 grass_block
setblock ~175 ~125 ~97 grass_block
setblock ~175 ~125 ~98 grass_block
setblock ~175 ~125 ~99 grass_block
setblock ~175 ~125 ~100 grass_block
setblock ~175 ~125 ~102 short_grass
setblock ~175 ~125 ~105 short_grass
setblock ~175 ~125 ~117 fern
setblock ~175 ~125 ~119 short_grass
setblock ~175 ~125 ~122 short_grass
setblock ~175 ~125 ~123 grass_block
setblock ~175 ~125 ~124 grass_block
setblock ~175 ~125 ~125 grass_block
setblock ~175 ~125 ~126 grass_block
setblock ~175 ~125 ~127 grass_block
setblock ~175 ~125 ~128 grass_block
setblock ~175 ~125 ~129 dirt
setblock ~175 ~125 ~130 dirt
setblock ~175 ~125 ~131 dirt
setblock ~175 ~125 ~132 grass_block
setblock ~175 ~125 ~133 grass_block
setblock ~175 ~125 ~134 grass_block
setblock ~175 ~125 ~135 grass_block
setblock ~175 ~125 ~136 grass_block
setblock ~175 ~125 ~140 short_grass
setblock ~175 ~125 ~144 short_grass
setblock ~175 ~125 ~145 poppy
setblock ~175 ~125 ~149 grass_block
setblock ~175 ~125 ~150 grass_block
setblock ~175 ~125 ~151 grass_block
setblock ~175 ~125 ~152 grass_block
setblock ~175 ~125 ~153 grass_block
setblock ~175 ~125 ~154 grass_block
setblock ~175 ~125 ~159 short_grass
setblock ~175 ~125 ~162 grass_block
setblock ~175 ~125 ~163 grass_block
setblock ~175 ~125 ~164 grass_block
setblock ~175 ~125 ~165 grass_block
setblock ~175 ~125 ~166 grass_block
setblock ~175 ~125 ~167 grass_block
setblock ~175 ~125 ~168 grass_block
setblock ~175 ~125 ~169 grass_block
setblock ~175 ~125 ~170 grass_block
setblock ~175 ~125 ~171 grass_block
setblock ~175 ~125 ~172 grass_block
setblock ~175 ~125 ~173 grass_block
setblock ~175 ~125 ~174 grass_block
setblock ~175 ~125 ~175 grass_block
setblock ~175 ~125 ~176 grass_block
setblock ~175 ~125 ~177 grass_block
setblock ~175 ~125 ~178 grass_block
setblock ~175 ~125 ~179 grass_block
setblock ~175 ~125 ~180 grass_block
setblock ~175 ~125 ~181 dirt
setblock ~175 ~125 ~182 dirt
setblock ~175 ~125 ~183 dirt
setblock ~175 ~125 ~184 dirt
setblock ~175 ~125 ~185 dirt
setblock ~175 ~125 ~186 dirt
setblock ~175 ~125 ~187 dirt
setblock ~175 ~125 ~188 dirt
setblock ~175 ~125 ~189 dirt
setblock ~175 ~125 ~190 dirt
setblock ~175 ~125 ~191 dirt
setblock ~175 ~125 ~192 dirt
setblock ~175 ~125 ~193 dirt
setblock ~175 ~125 ~194 dirt
setblock ~175 ~125 ~195 dirt
setblock ~175 ~125 ~196 dirt
setblock ~175 ~125 ~197 grass_block
setblock ~175 ~125 ~198 grass_block
setblock ~175 ~125 ~199 short_grass
setblock ~175 ~126 ~3 short_grass
setblock ~175 ~126 ~23 short_grass
setblock ~175 ~126 ~24 short_grass
setblock ~175 ~126 ~27 short_grass
setblock ~175 ~126 ~67 grass_block
setblock ~175 ~126 ~68 dirt
setblock ~175 ~126 ~69 dirt
setblock ~175 ~126 ~70 dirt
setblock ~175 ~126 ~71 dirt
setblock ~175 ~126 ~72 dirt
setblock ~175 ~126 ~73 grass_block
setblock ~175 ~126 ~74 grass_block
setblock ~175 ~126 ~86 short_grass
setblock ~175 ~126 ~87 grass_block
setblock ~175 ~126 ~88 grass_block
setblock ~175 ~126 ~89 dirt
setblock ~175 ~126 ~90 dirt
setblock ~175 ~126 ~91 dirt
setblock ~175 ~126 ~92 dirt
setblock ~175 ~126 ~93 grass_block
setblock ~175 ~126 ~94 grass_block
setblock ~175 ~126 ~95 grass_block
setblock ~175 ~126 ~124 short_grass
setblock ~175 ~126 ~127 short_grass
setblock ~175 ~126 ~129 grass_block
setblock ~175 ~126 ~130 grass_block
setblock ~175 ~126 ~131 grass_block
setblock ~175 ~126 ~132 short_grass
setblock ~175 ~126 ~135 short_grass
setblock ~175 ~126 ~149 poppy
setblock ~175 ~126 ~165 short_grass
setblock ~175 ~126 ~169 short_grass
setblock ~175 ~126 ~170 short_grass
setblock ~175 ~126 ~171 short_grass
setblock ~175 ~126 ~172 short_grass
setblock ~175 ~126 ~173 fern
setblock ~175 ~126 ~177 short_grass
setblock ~175 ~126 ~179 short_grass
setblock ~175 ~126 ~181 grass_block
setblock ~175 ~126 ~182 grass_block
setblock ~175 ~126 ~183 grass_block
setblock ~175 ~126 ~184 grass_block
setblock ~175 ~126 ~185 grass_block
setblock ~175 ~126 ~186 dirt
setblock ~175 ~126 ~187 dirt
setblock ~175 ~126 ~188 dirt
setblock ~175 ~126 ~189 dirt
setblock ~175 ~126 ~190 dirt
setblock ~175 ~126 ~191 dirt
setblock ~175 ~126 ~192 dirt
setblock ~175 ~126 ~193 dirt
setblock ~175 ~126 ~194 grass_block
setblock ~175 ~126 ~195 grass_block
setblock ~175 ~126 ~196 grass_block
setblock ~175 ~126 ~198 short_grass
setblock ~175 ~127 ~68 grass_block
setblock ~175 ~127 ~69 grass_block
setblock ~175 ~127 ~70 dirt
setblock ~175 ~127 ~71 grass_block
setblock ~175 ~127 ~72 grass_block
setblock ~175 ~127 ~74 short_grass
setblock ~175 ~127 ~87 short_grass
setblock ~175 ~127 ~89 grass_block
setblock ~175 ~127 ~90 grass_block
setblock ~175 ~127 ~91 grass_block
setblock ~175 ~127 ~92 grass_block
setblock ~175 ~127 ~95 short_grass
setblock ~175 ~127 ~129 short_grass
setblock ~175 ~127 ~130 short_grass
setblock ~175 ~127 ~186 grass_block
setblock ~175 ~127 ~187 grass_block
setblock ~175 ~127 ~188 grass_block
setblock ~175 ~127 ~189 grass_block
setblock ~175 ~127 ~190 dirt
setblock ~175 ~127 ~191 grass_block
setblock ~175 ~127 ~192 grass_block
setblock ~175 ~127 ~193 grass_block
setblock ~175 ~127 ~195 short_grass
setblock ~175 ~128 ~69 short_grass
setblock ~175 ~128 ~70 grass_block
setblock ~175 ~128 ~190 grass_block
setblock ~175 ~128 ~193 short_grass
setblock ~176 ~122 ~0 dirt
setblock ~176 ~122 ~1 dirt
setblock ~176 ~122 ~2 dirt
setblock ~176 ~122 ~3 dirt
setblock ~176 ~122 ~4 dirt
setblock ~176 ~122 ~5 dirt
setblock ~176 ~122 ~6 dirt
setblock ~176 ~122 ~7 dirt
setblock ~176 ~122 ~8 dirt
setblock ~176 ~122 ~9 dirt
setblock ~176 ~122 ~10 dirt
setblock ~176 ~122 ~11 dirt
setblock ~176 ~122 ~12 dirt
setblock ~176 ~122 ~13 dirt
setblock ~176 ~122 ~14 dirt
setblock ~176 ~122 ~15 dirt
setblock ~176 ~122 ~16 dirt
setblock ~176 ~122 ~17 dirt
setblock ~176 ~122 ~18 dirt
setblock ~176 ~122 ~19 dirt
setblock ~176 ~122 ~20 dirt
setblock ~176 ~122 ~21 dirt
setblock ~176 ~122 ~22 dirt
setblock ~176 ~122 ~23 dirt
setblock ~176 ~122 ~24 dirt
setblock ~176 ~122 ~25 dirt
setblock ~176 ~122 ~26 dirt
setblock ~176 ~122 ~27 dirt
setblock ~176 ~122 ~28 dirt
setblock ~176 ~122 ~29 dirt
setblock ~176 ~122 ~30 dirt
setblock ~176 ~122 ~31 dirt
setblock ~176 ~122 ~32 dirt
setblock ~176 ~122 ~33 dirt
setblock ~176 ~122 ~34 dirt
setblock ~176 ~122 ~35 dirt
setblock ~176 ~122 ~36 dirt
setblock ~176 ~122 ~37 dirt
setblock ~176 ~122 ~38 dirt
setblock ~176 ~122 ~39 dirt
setblock ~176 ~122 ~40 dirt
setblock ~176 ~122 ~41 dirt
setblock ~176 ~122 ~42 dirt
setblock ~176 ~122 ~43 dirt
setblock ~176 ~122 ~44 dirt
setblock ~176 ~122 ~45 dirt
setblock ~176 ~122 ~46 dirt
setblock ~176 ~122 ~47 dirt
setblock ~176 ~122 ~48 dirt
setblock ~176 ~122 ~49 dirt
setblock ~176 ~122 ~50 dirt
setblock ~176 ~122 ~51 dirt
setblock ~176 ~122 ~52 dirt
setblock ~176 ~122 ~53 dirt
setblock ~176 ~122 ~54 dirt
setblock ~176 ~122 ~55 dirt
setblock ~176 ~122 ~56 dirt
setblock ~176 ~122 ~57 dirt
setblock ~176 ~122 ~58 dirt
setblock ~176 ~122 ~59 dirt
setblock ~176 ~122 ~60 grass_block
setblock ~176 ~122 ~61 dirt
setblock ~176 ~122 ~62 dirt
setblock ~176 ~122 ~63 dirt
setblock ~176 ~122 ~64 dirt
setblock ~176 ~122 ~65 dirt
setblock ~176 ~122 ~66 dirt
setblock ~176 ~122 ~67 dirt
setblock ~176 ~122 ~68 dirt
setblock ~176 ~122 ~69 dirt
setblock ~176 ~122 ~70 dirt
setblock ~176 ~122 ~71 dirt
setblock ~176 ~122 ~72 dirt
setblock ~176 ~122 ~73 dirt
setblock ~176 ~122 ~74 dirt
setblock ~176 ~122 ~75 dirt
setblock ~176 ~122 ~76 dirt
setblock ~176 ~122 ~77 dirt
setblock ~176 ~122 ~78 dirt
setblock ~176 ~122 ~79 dirt
setblock ~176 ~122 ~80 dirt
setblock ~176 ~122 ~81 dirt
setblock ~176 ~122 ~82 dirt
setblock ~176 ~122 ~83 dirt
setblock ~176 ~122 ~84 dirt
setblock ~176 ~122 ~85 dirt
setblock ~176 ~122 ~86 dirt
setblock ~176 ~122 ~87 dirt
setblock ~176 ~122 ~88 dirt
setblock ~176 ~122 ~89 dirt
setblock ~176 ~122 ~90 dirt
setblock ~176 ~122 ~91 dirt
setblock ~176 ~122 ~92 dirt
setblock ~176 ~122 ~93 dirt
setblock ~176 ~122 ~94 dirt
setblock ~176 ~122 ~95 dirt
setblock ~176 ~122 ~96 dirt
setblock ~176 ~122 ~97 dirt
setblock ~176 ~122 ~98 dirt
setblock ~176 ~122 ~99 dirt
setblock ~176 ~122 ~100 dirt
setblock ~176 ~122 ~101 dirt
setblock ~176 ~122 ~102 dirt
setblock ~176 ~122 ~103 dirt
setblock ~176 ~122 ~104 dirt
setblock ~176 ~122 ~105 dirt
setblock ~176 ~122 ~106 dirt
setblock ~176 ~122 ~107 dirt
setblock ~176 ~122 ~108 dirt
setblock ~176 ~122 ~109 dirt
setblock ~176 ~122 ~110 dirt
setblock ~176 ~122 ~111 dirt
setblock ~176 ~122 ~112 dirt
setblock ~176 ~122 ~113 dirt
setblock ~176 ~122 ~114 dirt
setblock ~176 ~122 ~115 dirt
setblock ~176 ~122 ~116 dirt
setblock ~176 ~122 ~117 dirt
setblock ~176 ~122 ~118 dirt
setblock ~176 ~122 ~119 dirt
setblock ~176 ~122 ~120 dirt
setblock ~176 ~122 ~121 dirt
setblock ~176 ~122 ~122 dirt
setblock ~176 ~122 ~123 dirt
setblock ~176 ~122 ~124 dirt
setblock ~176 ~122 ~125 dirt
setblock ~176 ~122 ~126 dirt
setblock ~176 ~122 ~127 dirt
setblock ~176 ~122 ~128 dirt
setblock ~176 ~122 ~129 dirt
setblock ~176 ~122 ~130 dirt
setblock ~176 ~122 ~131 dirt
setblock ~176 ~122 ~132 dirt
setblock ~176 ~122 ~133 dirt
setblock ~176 ~122 ~134 dirt
setblock ~176 ~122 ~135 dirt
setblock ~176 ~122 ~136 dirt
setblock ~176 ~122 ~137 dirt
setblock ~176 ~122 ~138 dirt
setblock ~176 ~122 ~139 dirt
setblock ~176 ~122 ~140 dirt
setblock ~176 ~122 ~141 dirt
setblock ~176 ~122 ~142 dirt
setblock ~176 ~122 ~143 dirt
setblock ~176 ~122 ~144 dirt
setblock ~176 ~122 ~145 dirt
setblock ~176 ~122 ~146 dirt
setblock ~176 ~122 ~147 dirt
setblock ~176 ~122 ~148 dirt
setblock ~176 ~122 ~149 dirt
setblock ~176 ~122 ~150 dirt
setblock ~176 ~122 ~151 dirt
setblock ~176 ~122 ~152 dirt
setblock ~176 ~122 ~153 dirt
setblock ~176 ~122 ~154 dirt
setblock ~176 ~122 ~155 dirt
setblock ~176 ~122 ~156 dirt
setblock ~176 ~122 ~157 dirt
setblock ~176 ~122 ~158 dirt
setblock ~176 ~122 ~159 dirt
setblock ~176 ~122 ~160 dirt
setblock ~176 ~122 ~161 dirt
setblock ~176 ~122 ~162 dirt
setblock ~176 ~122 ~163 dirt
setblock ~176 ~122 ~164 dirt
setblock ~176 ~122 ~165 dirt
setblock ~176 ~122 ~166 dirt
setblock ~176 ~122 ~167 dirt
setblock ~176 ~122 ~168 dirt
setblock ~176 ~122 ~169 dirt
setblock ~176 ~122 ~170 dirt
setblock ~176 ~122 ~171 dirt
setblock ~176 ~122 ~172 dirt
setblock ~176 ~122 ~173 dirt
setblock ~176 ~122 ~174 dirt
setblock ~176 ~122 ~175 dirt
setblock ~176 ~122 ~176 dirt
setblock ~176 ~122 ~177 dirt
setblock ~176 ~122 ~178 dirt
setblock ~176 ~122 ~179 dirt
setblock ~176 ~122 ~180 dirt
setblock ~176 ~122 ~181 dirt
setblock ~176 ~122 ~182 dirt
setblock ~176 ~122 ~183 dirt
setblock ~176 ~122 ~184 dirt
setblock ~176 ~122 ~185 dirt
setblock ~176 ~122 ~186 dirt
setblock ~176 ~122 ~187 dirt
setblock ~176 ~122 ~188 dirt
setblock ~176 ~122 ~189 dirt
setblock ~176 ~122 ~190 dirt
setblock ~176 ~122 ~191 dirt
setblock ~176 ~122 ~192 dirt
setblock ~176 ~122 ~193 dirt
setblock ~176 ~122 ~194 dirt
setblock ~176 ~122 ~195 dirt
setblock ~176 ~122 ~196 dirt
setblock ~176 ~122 ~197 dirt
setblock ~176 ~122 ~198 dirt
setblock ~176 ~122 ~199 dirt
setblock ~176 ~123 ~0 dirt
setblock ~176 ~123 ~1 dirt
setblock ~176 ~123 ~2 dirt
setblock ~176 ~123 ~3 dirt
setblock ~176 ~123 ~4 dirt
setblock ~176 ~123 ~5 dirt
setblock ~176 ~123 ~6 dirt
setblock ~176 ~123 ~7 dirt
setblock ~176 ~123 ~8 dirt
setblock ~176 ~123 ~9 dirt
setblock ~176 ~123 ~10 grass_block
setblock ~176 ~123 ~11 grass_block
setblock ~176 ~123 ~12 dirt
setblock ~176 ~123 ~13 dirt
setblock ~176 ~123 ~14 dirt
setblock ~176 ~123 ~15 dirt
setblock ~176 ~123 ~16 dirt
setblock ~176 ~123 ~17 dirt
setblock ~176 ~123 ~18 dirt
setblock ~176 ~123 ~19 dirt
setblock ~176 ~123 ~20 dirt
setblock ~176 ~123 ~21 dirt
setblock ~176 ~123 ~22 dirt
setblock ~176 ~123 ~23 dirt
setblock ~176 ~123 ~24 dirt
setblock ~176 ~123 ~25 dirt
setblock ~176 ~123 ~26 dirt
setblock ~176 ~123 ~27 dirt
setblock ~176 ~123 ~28 dirt
setblock ~176 ~123 ~29 dirt
setblock ~176 ~123 ~30 dirt
setblock ~176 ~123 ~31 dirt
setblock ~176 ~123 ~32 dirt
setblock ~176 ~123 ~33 dirt
setblock ~176 ~123 ~34 dirt
setblock ~176 ~123 ~35 dirt
setblock ~176 ~123 ~36 dirt
setblock ~176 ~123 ~37 dirt
setblock ~176 ~123 ~38 dirt
setblock ~176 ~123 ~39 grass_block
setblock ~176 ~123 ~40 grass_block
setblock ~176 ~123 ~41 dirt
setblock ~176 ~123 ~42 dirt
setblock ~176 ~123 ~43 dirt
setblock ~176 ~123 ~44 dirt
setblock ~176 ~123 ~45 dirt
setblock ~176 ~123 ~46 dirt
setblock ~176 ~123 ~47 dirt
setblock ~176 ~123 ~48 dirt
setblock ~176 ~123 ~49 dirt
setblock ~176 ~123 ~50 dirt
setblock ~176 ~123 ~51 dirt
setblock ~176 ~123 ~52 dirt
setblock ~176 ~123 ~53 dirt
setblock ~176 ~123 ~54 dirt
setblock ~176 ~123 ~55 dirt
setblock ~176 ~123 ~56 grass_block
setblock ~176 ~123 ~57 grass_block
setblock ~176 ~123 ~58 grass_block
setblock ~176 ~123 ~59 grass_block
setblock ~176 ~123 ~61 grass_block
setblock ~176 ~123 ~62 grass_block
setblock ~176 ~123 ~63 dirt
setblock ~176 ~123 ~64 dirt
setblock ~176 ~123 ~65 dirt
setblock ~176 ~123 ~66 dirt
setblock ~176 ~123 ~67 dirt
setblock ~176 ~123 ~68 dirt
setblock ~176 ~123 ~69 dirt
setblock ~176 ~123 ~70 dirt
setblock ~176 ~123 ~71 dirt
setblock ~176 ~123 ~72 dirt
setblock ~176 ~123 ~73 dirt
setblock ~176 ~123 ~74 dirt
setblock ~176 ~123 ~75 dirt
setblock ~176 ~123 ~76 dirt
setblock ~176 ~123 ~77 dirt
setblock ~176 ~123 ~78 dirt
setblock ~176 ~123 ~79 dirt
setblock ~176 ~123 ~80 dirt
setblock ~176 ~123 ~81 dirt
setblock ~176 ~123 ~82 dirt
setblock ~176 ~123 ~83 dirt
setblock ~176 ~123 ~84 dirt
setblock ~176 ~123 ~85 dirt
setblock ~176 ~123 ~86 dirt
setblock ~176 ~123 ~87 dirt
setblock ~176 ~123 ~88 dirt
setblock ~176 ~123 ~89 dirt
setblock ~176 ~123 ~90 dirt
setblock ~176 ~123 ~91 dirt
setblock ~176 ~123 ~92 dirt
setblock ~176 ~123 ~93 dirt
setblock ~176 ~123 ~94 dirt
setblock ~176 ~123 ~95 dirt
setblock ~176 ~123 ~96 dirt
setblock ~176 ~123 ~97 dirt
setblock ~176 ~123 ~98 dirt
setblock ~176 ~123 ~99 dirt
setblock ~176 ~123 ~100 dirt
setblock ~176 ~123 ~101 dirt
setblock ~176 ~123 ~102 dirt
setblock ~176 ~123 ~103 dirt
setblock ~176 ~123 ~104 dirt
setblock ~176 ~123 ~105 dirt
setblock ~176 ~123 ~106 dirt
setblock ~176 ~123 ~107 dirt
setblock ~176 ~123 ~108 dirt
setblock ~176 ~123 ~109 grass_block
setblock ~176 ~123 ~110 grass_block
setblock ~176 ~123 ~111 grass_block
setblock ~176 ~123 ~112 dirt
setblock ~176 ~123 ~113 dirt
setblock ~176 ~123 ~114 dirt
setblock ~176 ~123 ~115 dirt
setblock ~176 ~123 ~116 dirt
setblock ~176 ~123 ~117 dirt
setblock ~176 ~123 ~118 dirt
setblock ~176 ~123 ~119 dirt
setblock ~176 ~123 ~120 dirt
setblock ~176 ~123 ~121 dirt
setblock ~176 ~123 ~122 dirt
setblock ~176 ~123 ~123 dirt
setblock ~176 ~123 ~124 dirt
setblock ~176 ~123 ~125 dirt
setblock ~176 ~123 ~126 dirt
setblock ~176 ~123 ~127 dirt
setblock ~176 ~123 ~128 dirt
setblock ~176 ~123 ~129 dirt
setblock ~176 ~123 ~130 dirt
setblock ~176 ~123 ~131 dirt
setblock ~176 ~123 ~132 dirt
setblock ~176 ~123 ~133 dirt
setblock ~176 ~123 ~134 dirt
setblock ~176 ~123 ~135 dirt
setblock ~176 ~123 ~136 dirt
setblock ~176 ~123 ~137 dirt
setblock ~176 ~123 ~138 dirt
setblock ~176 ~123 ~139 dirt
setblock ~176 ~123 ~140 dirt
setblock ~176 ~123 ~141 dirt
setblock ~176 ~123 ~142 dirt
setblock ~176 ~123 ~143 dirt
setblock ~176 ~123 ~144 dirt
setblock ~176 ~123 ~145 dirt
setblock ~176 ~123 ~146 dirt
setblock ~176 ~123 ~147 dirt
setblock ~176 ~123 ~148 dirt
setblock ~176 ~123 ~149 dirt
setblock ~176 ~123 ~150 dirt
setblock ~176 ~123 ~151 dirt
setblock ~176 ~123 ~152 dirt
setblock ~176 ~123 ~153 dirt
setblock ~176 ~123 ~154 dirt
setblock ~176 ~123 ~155 dirt
setblock ~176 ~123 ~156 dirt
setblock ~176 ~123 ~157 dirt
setblock ~176 ~123 ~158 dirt
setblock ~176 ~123 ~159 dirt
setblock ~176 ~123 ~160 dirt
setblock ~176 ~123 ~161 dirt
setblock ~176 ~123 ~162 dirt
setblock ~176 ~123 ~163 dirt
setblock ~176 ~123 ~164 dirt
setblock ~176 ~123 ~165 dirt
setblock ~176 ~123 ~166 dirt
setblock ~176 ~123 ~167 dirt
setblock ~176 ~123 ~168 dirt
setblock ~176 ~123 ~169 dirt
setblock ~176 ~123 ~170 dirt
setblock ~176 ~123 ~171 dirt
setblock ~176 ~123 ~172 dirt
setblock ~176 ~123 ~173 dirt
setblock ~176 ~123 ~174 dirt
setblock ~176 ~123 ~175 dirt
setblock ~176 ~123 ~176 dirt
setblock ~176 ~123 ~177 dirt
setblock ~176 ~123 ~178 dirt
setblock ~176 ~123 ~179 dirt
setblock ~176 ~123 ~180 dirt
setblock ~176 ~123 ~181 dirt
setblock ~176 ~123 ~182 dirt
setblock ~176 ~123 ~183 dirt
setblock ~176 ~123 ~184 dirt
setblock ~176 ~123 ~185 dirt
setblock ~176 ~123 ~186 dirt
setblock ~176 ~123 ~187 dirt
setblock ~176 ~123 ~188 dirt
setblock ~176 ~123 ~189 dirt
setblock ~176 ~123 ~190 dirt
setblock ~176 ~123 ~191 dirt
setblock ~176 ~123 ~192 dirt
setblock ~176 ~123 ~193 dirt
setblock ~176 ~123 ~194 dirt
setblock ~176 ~123 ~195 dirt
setblock ~176 ~123 ~196 dirt
setblock ~176 ~123 ~197 dirt
setblock ~176 ~123 ~198 dirt
setblock ~176 ~123 ~199 dirt
setblock ~176 ~124 ~0 dirt
setblock ~176 ~124 ~1 dirt
setblock ~176 ~124 ~2 dirt
setblock ~176 ~124 ~3 dirt
setblock ~176 ~124 ~4 dirt
setblock ~176 ~124 ~5 dirt
setblock ~176 ~124 ~6 dirt
setblock ~176 ~124 ~7 grass_block
setblock ~176 ~124 ~8 grass_block
setblock ~176 ~124 ~9 grass_block
setblock ~176 ~124 ~11 short_grass
setblock ~176 ~124 ~12 grass_block
setblock ~176 ~124 ~13 grass_block
setblock ~176 ~124 ~14 grass_block
setblock ~176 ~124 ~15 grass_block
setblock ~176 ~124 ~16 grass_block
setblock ~176 ~124 ~17 grass_block
setblock ~176 ~124 ~18 grass_block
setblock ~176 ~124 ~19 grass_block
setblock ~176 ~124 ~20 grass_block
setblock ~176 ~124 ~21 dirt
setblock ~176 ~124 ~22 dirt
setblock ~176 ~124 ~23 dirt
setblock ~176 ~124 ~24 dirt
setblock ~176 ~124 ~25 dirt
setblock ~176 ~124 ~26 dirt
setblock ~176 ~124 ~27 dirt
setblock ~176 ~124 ~28 dirt
setblock ~176 ~124 ~29 dirt
setblock ~176 ~124 ~30 dirt
setblock ~176 ~124 ~31 dirt
setblock ~176 ~124 ~32 grass_block
setblock ~176 ~124 ~33 grass_block
setblock ~176 ~124 ~34 grass_block
setblock ~176 ~124 ~35 grass_block
setblock ~176 ~124 ~36 grass_block
setblock ~176 ~124 ~37 grass_block
setblock ~176 ~124 ~38 grass_block
setblock ~176 ~124 ~41 grass_block
setblock ~176 ~124 ~42 grass_block
setblock ~176 ~124 ~43 grass_block
setblock ~176 ~124 ~44 grass_block
setblock ~176 ~124 ~45 grass_block
setblock ~176 ~124 ~46 grass_block
setblock ~176 ~124 ~47 grass_block
setblock ~176 ~124 ~48 dirt
setblock ~176 ~124 ~49 dirt
setblock ~176 ~124 ~50 dirt
setblock ~176 ~124 ~51 dirt
setblock ~176 ~124 ~52 grass_block
setblock ~176 ~124 ~53 grass_block
setblock ~176 ~124 ~54 grass_block
setblock ~176 ~124 ~55 grass_block
setblock ~176 ~124 ~63 grass_block
setblock ~176 ~124 ~64 grass_block
setblock ~176 ~124 ~65 dirt
setblock ~176 ~124 ~66 dirt
setblock ~176 ~124 ~67 dirt
setblock ~176 ~124 ~68 dirt
setblock ~176 ~124 ~69 dirt
setblock ~176 ~124 ~70 dirt
setblock ~176 ~124 ~71 dirt
setblock ~176 ~124 ~72 dirt
setblock ~176 ~124 ~73 dirt
setblock ~176 ~124 ~74 dirt
setblock ~176 ~124 ~75 dirt
setblock ~176 ~124 ~76 dirt
setblock ~176 ~124 ~77 dirt
setblock ~176 ~124 ~78 grass_block
setblock ~176 ~124 ~79 grass_block
setblock ~176 ~124 ~80 grass_block
setblock ~176 ~124 ~81 grass_block
setblock ~176 ~124 ~82 grass_block
setblock ~176 ~124 ~83 dirt
setblock ~176 ~124 ~84 dirt
setblock ~176 ~124 ~85 dirt
setblock ~176 ~124 ~86 dirt
setblock ~176 ~124 ~87 dirt
setblock ~176 ~124 ~88 dirt
setblock ~176 ~124 ~89 dirt
setblock ~176 ~124 ~90 dirt
setblock ~176 ~124 ~91 dirt
setblock ~176 ~124 ~92 dirt
setblock ~176 ~124 ~93 dirt
setblock ~176 ~124 ~94 dirt
setblock ~176 ~124 ~95 dirt
setblock ~176 ~124 ~96 dirt
setblock ~176 ~124 ~97 dirt
setblock ~176 ~124 ~98 dirt
setblock ~176 ~124 ~99 dirt
setblock ~176 ~124 ~100 grass_block
setblock ~176 ~124 ~101 grass_block
setblock ~176 ~124 ~102 grass_block
setblock ~176 ~124 ~103 grass_block
setblock ~176 ~124 ~104 grass_block
setblock ~176 ~124 ~105 grass_block
setblock ~176 ~124 ~106 grass_block
setblock ~176 ~124 ~107 grass_block
setblock ~176 ~124 ~108 grass_block
setblock ~176 ~124 ~110 short_grass
setblock ~176 ~124 ~112 grass_block
setblock ~176 ~124 ~113 grass_block
setblock ~176 ~124 ~114 grass_block
setblock ~176 ~124 ~115 grass_block
setblock ~176 ~124 ~116 grass_block
setblock ~176 ~124 ~117 grass_block
setblock ~176 ~124 ~118 grass_block
setblock ~176 ~124 ~119 grass_block
setblock ~176 ~124 ~120 grass_block
setblock ~176 ~124 ~121 grass_block
setblock ~176 ~124 ~122 grass_block
setblock ~176 ~124 ~123 grass_block
setblock ~176 ~124 ~124 grass_block
setblock ~176 ~124 ~125 dirt
setblock ~176 ~124 ~126 dirt
setblock ~176 ~124 ~127 dirt
setblock ~176 ~124 ~128 dirt
setblock ~176 ~124 ~129 dirt
setblock ~176 ~124 ~130 dirt
setblock ~176 ~124 ~131 dirt
setblock ~176 ~124 ~132 dirt
setblock ~176 ~124 ~133 dirt
setblock ~176 ~124 ~134 dirt
setblock ~176 ~124 ~135 dirt
setblock ~176 ~124 ~136 dirt
setblock ~176 ~124 ~137 grass_block
setblock ~176 ~124 ~138 grass_block
setblock ~176 ~124 ~139 grass_block
setblock ~176 ~124 ~140 grass_block
setblock ~176 ~124 ~141 grass_block
setblock ~176 ~124 ~142 grass_block
setblock ~176 ~124 ~143 grass_block
setblock ~176 ~124 ~144 grass_block
setblock ~176 ~124 ~145 grass_block
setblock ~176 ~124 ~146 grass_block
setblock ~176 ~124 ~147 grass_block
setblock ~176 ~124 ~148 grass_block
setblock ~176 ~124 ~149 grass_block
setblock ~176 ~124 ~150 grass_block
setblock ~176 ~124 ~151 grass_block
setblock ~176 ~124 ~152 grass_block
setblock ~176 ~124 ~153 grass_block
setblock ~176 ~124 ~154 grass_block
setblock ~176 ~124 ~155 grass_block
setblock ~176 ~124 ~156 grass_block
setblock ~176 ~124 ~157 dirt
setblock ~176 ~124 ~158 dirt
setblock ~176 ~124 ~159 dirt
setblock ~176 ~124 ~160 dirt
setblock ~176 ~124 ~161 dirt
setblock ~176 ~124 ~162 dirt
setblock ~176 ~124 ~163 dirt
setblock ~176 ~124 ~164 dirt
setblock ~176 ~124 ~165 dirt
setblock ~176 ~124 ~166 dirt
setblock ~176 ~124 ~167 dirt
setblock ~176 ~124 ~168 dirt
setblock ~176 ~124 ~169 grass_block
setblock ~176 ~124 ~170 grass_block
setblock ~176 ~124 ~171 dirt
setblock ~176 ~124 ~172 dirt
setblock ~176 ~124 ~173 dirt
setblock ~176 ~124 ~174 dirt
setblock ~176 ~124 ~175 dirt
setblock ~176 ~124 ~176 dirt
setblock ~176 ~124 ~177 dirt
setblock ~176 ~124 ~178 dirt
setblock ~176 ~124 ~179 dirt
setblock ~176 ~124 ~180 dirt
setblock ~176 ~124 ~181 dirt
setblock ~176 ~124 ~182 dirt
setblock ~176 ~124 ~183 dirt
setblock ~176 ~124 ~184 dirt
setblock ~176 ~124 ~185 dirt
setblock ~176 ~124 ~186 dirt
setblock ~176 ~124 ~187 dirt
setblock ~176 ~124 ~188 dirt
setblock ~176 ~124 ~189 dirt
setblock ~176 ~124 ~190 dirt
setblock ~176 ~124 ~191 dirt
setblock ~176 ~124 ~192 dirt
setblock ~176 ~124 ~193 dirt
setblock ~176 ~124 ~194 dirt
setblock ~176 ~124 ~195 dirt
setblock ~176 ~124 ~196 dirt
setblock ~176 ~124 ~197 dirt
setblock ~176 ~124 ~198 grass_block
setblock ~176 ~124 ~199 grass_block
setblock ~176 ~125 ~0 grass_block
setblock ~176 ~125 ~1 grass_block
setblock ~176 ~125 ~2 grass_block
setblock ~176 ~125 ~3 grass_block
setblock ~176 ~125 ~4 grass_block
setblock ~176 ~125 ~5 grass_block
setblock ~176 ~125 ~6 grass_block
setblock ~176 ~125 ~9 short_grass
setblock ~176 ~125 ~12 short_grass
setblock ~176 ~125 ~17 short_grass
setblock ~176 ~125 ~18 short_grass
setblock ~176 ~125 ~21 grass_block
setblock ~176 ~125 ~22 grass_block
setblock ~176 ~125 ~23 grass_block
setblock ~176 ~125 ~24 grass_block
setblock ~176 ~125 ~25 grass_block
setblock ~176 ~125 ~26 grass_block
setblock ~176 ~125 ~27 grass_block
setblock ~176 ~125 ~28 grass_block
setblock ~176 ~125 ~29 grass_block
setblock ~176 ~125 ~30 grass_block
setblock ~176 ~125 ~31 grass_block
setblock ~176 ~125 ~32 fern
setblock ~176 ~125 ~33 fern
setblock ~176 ~125 ~38 poppy
setblock ~176 ~125 ~44 short_grass
setblock ~176 ~125 ~47 fern
setblock ~176 ~125 ~48 grass_block
setblock ~176 ~125 ~49 grass_block
setblock ~176 ~125 ~50 grass_block
setblock ~176 ~125 ~51 grass_block
setblock ~176 ~125 ~52 short_grass
setblock ~176 ~125 ~65 grass_block
setblock ~176 ~125 ~66 grass_block
setblock ~176 ~125 ~67 dirt
setblock ~176 ~125 ~68 dirt
setblock ~176 ~125 ~69 dirt
setblock ~176 ~125 ~70 dirt
setblock ~176 ~125 ~71 dirt
setblock ~176 ~125 ~72 dirt
setblock ~176 ~125 ~73 dirt
setblock ~176 ~125 ~74 dirt
setblock ~176 ~125 ~75 grass_block
setblock ~176 ~125 ~76 grass_block
setblock ~176 ~125 ~77 grass_block
setblock ~176 ~125 ~82 short_grass
setblock ~176 ~125 ~83 grass_block
setblock ~176 ~125 ~84 grass_block
setblock ~176 ~125 ~85 dirt
setblock ~176 ~125 ~86 dirt
setblock ~176 ~125 ~87 dirt
setblock ~176 ~125 ~88 dirt
setblock ~176 ~125 ~89 dirt
setblock ~176 ~125 ~90 dirt
setblock ~176 ~125 ~91 dirt
setblock ~176 ~125 ~92 dirt
setblock ~176 ~125 ~93 dirt
setblock ~176 ~125 ~94 dirt
setblock ~176 ~125 ~95 dirt
setblock ~176 ~125 ~96 grass_block
setblock ~176 ~125 ~97 grass_block
setblock ~176 ~125 ~98 grass_block
setblock ~176 ~125 ~99 grass_block
setblock ~176 ~125 ~103 short_grass
setblock ~176 ~125 ~107 short_grass
setblock ~176 ~125 ~115 short_grass
setblock ~176 ~125 ~118 short_grass
setblock ~176 ~125 ~123 short_grass
setblock ~176 ~125 ~125 grass_block
setblock ~176 ~125 ~126 grass_block
setblock ~176 ~125 ~127 grass_block
setblock ~176 ~125 ~128 grass_block
setblock ~176 ~125 ~129 grass_block
setblock ~176 ~125 ~130 dirt
setblock ~176 ~125 ~131 grass_block
setblock ~176 ~125 ~132 grass_block
setblock ~176 ~125 ~133 grass_block
setblock ~176 ~125 ~134 grass_block
setblock ~176 ~125 ~135 grass_block
setblock ~176 ~125 ~136 grass_block
setblock ~176 ~125 ~141 short_grass
setblock ~176 ~125 ~142 short_grass
setblock ~176 ~125 ~143 short_grass
setblock ~176 ~125 ~145 short_grass
setblock ~176 ~125 ~146 short_grass
setblock ~176 ~125 ~147 fern
setblock ~176 ~125 ~148 poppy
setblock ~176 ~125 ~157 grass_block
setblock ~176 ~125 ~158 grass_block
setblock ~176 ~125 ~159 grass_block
setblock ~176 ~125 ~160 grass_block
setblock ~176 ~125 ~161 grass_block
setblock ~176 ~125 ~162 grass_block
setblock ~176 ~125 ~163 grass_block
setblock ~176 ~125 ~164 grass_block
setblock ~176 ~125 ~165 grass_block
setblock ~176 ~125 ~166 grass_block
setblock ~176 ~125 ~167 grass_block
setblock ~176 ~125 ~168 grass_block
setblock ~176 ~125 ~169 short_grass
setblock ~176 ~125 ~171 grass_block
setblock ~176 ~125 ~172 grass_block
setblock ~176 ~125 ~173 grass_block
setblock ~176 ~125 ~174 grass_block
setblock ~176 ~125 ~175 grass_block
setblock ~176 ~125 ~176 grass_block
setblock ~176 ~125 ~177 grass_block
setblock ~176 ~125 ~178 grass_block
setblock ~176 ~125 ~179 grass_block
setblock ~176 ~125 ~180 dirt
setblock ~176 ~125 ~181 dirt
setblock ~176 ~125 ~182 dirt
setblock ~176 ~125 ~183 dirt
setblock ~176 ~125 ~184 dirt
setblock ~176 ~125 ~185 dirt
setblock ~176 ~125 ~186 dirt
setblock ~176 ~125 ~187 dirt
setblock ~176 ~125 ~188 dirt
setblock ~176 ~125 ~189 dirt
setblock ~176 ~125 ~190 dirt
setblock ~176 ~125 ~191 dirt
setblock ~176 ~125 ~192 dirt
setblock ~176 ~125 ~193 dirt
setblock ~176 ~125 ~194 dirt
setblock ~176 ~125 ~195 dirt
setblock ~176 ~125 ~196 grass_block
setblock ~176 ~125 ~197 grass_block
setblock ~176 ~126 ~4 short_grass
setblock ~176 ~126 ~5 short_grass
setblock ~176 ~126 ~23 poppy
setblock ~176 ~126 ~27 short_grass
setblock ~176 ~126 ~30 short_grass
setblock ~176 ~126 ~48 short_grass
setblock ~176 ~126 ~50 fern
setblock ~176 ~126 ~51 short_grass
setblock ~176 ~126 ~65 fern
setblock ~176 ~126 ~66 fern
setblock ~176 ~126 ~67 grass_block
setblock ~176 ~126 ~68 dirt
setblock ~176 ~126 ~69 dirt
setblock ~176 ~126 ~70 dirt
setblock ~176 ~126 ~71 dirt
setblock ~176 ~126 ~72 dirt
setblock ~176 ~126 ~73 grass_block
setblock ~176 ~126 ~74 grass_block
setblock ~176 ~126 ~76 short_grass
setblock ~176 ~126 ~83 short_grass
setblock ~176 ~126 ~85 grass_block
setblock ~176 ~126 ~86 grass_block
setblock ~176 ~126 ~87 grass_block
setblock ~176 ~126 ~88 dirt
setblock ~176 ~126 ~89 dirt
setblock ~176 ~126 ~90 dirt
setblock ~176 ~126 ~91 dirt
setblock ~176 ~126 ~92 dirt
setblock ~176 ~126 ~93 dirt
setblock ~176 ~126 ~94 grass_block
setblock ~176 ~126 ~95 grass_block
setblock ~176 ~126 ~97 short_grass
setblock ~176 ~126 ~125 short_grass
setblock ~176 ~126 ~128 short_grass
setblock ~176 ~126 ~129 short_grass
setblock ~176 ~126 ~130 grass_block
setblock ~176 ~126 ~158 short_grass
setblock ~176 ~126 ~160 short_grass
setblock ~176 ~126 ~161 short_grass
setblock ~176 ~126 ~163 short_grass
setblock ~176 ~126 ~165 short_grass
setblock ~176 ~126 ~172 fern
setblock ~176 ~126 ~173 short_grass
setblock ~176 ~126 ~176 short_grass
setblock ~176 ~126 ~177 short_grass
setblock ~176 ~126 ~179 poppy
setblock ~176 ~126 ~180 grass_block
setblock ~176 ~126 ~181 grass_block
setblock ~176 ~126 ~182 grass_block
setblock ~176 ~126 ~183 grass_block
setblock ~176 ~126 ~184 grass_block
setblock ~176 ~126 ~185 grass_block
setblock ~176 ~126 ~186 dirt
setblock ~176 ~126 ~187 dirt
setblock ~176 ~126 ~188 dirt
setblock ~176 ~126 ~189 dirt
setblock ~176 ~126 ~190 dirt
setblock ~176 ~126 ~191 dirt
setblock ~176 ~126 ~192 dirt
setblock ~176 ~126 ~193 grass_block
setblock ~176 ~126 ~194 grass_block
setblock ~176 ~126 ~195 grass_block
setblock ~176 ~126 ~196 short_grass
setblock ~176 ~127 ~68 grass_block
setblock ~176 ~127 ~69 dirt
setblock ~176 ~127 ~70 dirt
setblock ~176 ~127 ~71 dirt
setblock ~176 ~127 ~72 grass_block
setblock ~176 ~127 ~85 poppy
setblock ~176 ~127 ~88 grass_block
setblock ~176 ~127 ~89 grass_block
setblock ~176 ~127 ~90 dirt
setblock ~176 ~127 ~91 grass_block
setblock ~176 ~127 ~92 grass_block
setblock ~176 ~127 ~93 grass_block
setblock ~176 ~127 ~181 short_grass
setblock ~176 ~127 ~186 grass_block
setblock ~176 ~127 ~187 grass_block
setblock ~176 ~127 ~188 grass_block
setblock ~176 ~127 ~189 grass_block
setblock ~176 ~127 ~190 dirt
setblock ~176 ~127 ~191 grass_block
setblock ~176 ~127 ~192 grass_block
setblock ~176 ~127 ~193 fern
setblock ~176 ~128 ~68 short_grass
setblock ~176 ~128 ~69 grass_block
setblock ~176 ~128 ~70 grass_block
setblock ~176 ~128 ~71 grass_block
setblock ~176 ~128 ~88 poppy
setblock ~176 ~128 ~89 short_grass
setblock ~176 ~128 ~90 grass_block
setblock ~176 ~128 ~91 short_grass
setblock ~176 ~128 ~190 grass_block
setblock ~176 ~128 ~191 short_grass
setblock ~176 ~128 ~192 short_grass
setblock ~176 ~129 ~70 poppy
setblock ~176 ~129 ~90 short_grass
setblock ~176 ~129 ~190 short_grass
setblock ~177 ~122 ~0 dirt
setblock ~177 ~122 ~1 dirt
setblock ~177 ~122 ~2 dirt
setblock ~177 ~122 ~3 dirt
setblock ~177 ~122 ~4 dirt
setblock ~177 ~122 ~5 dirt
setblock ~177 ~122 ~6 dirt
setblock ~177 ~122 ~7 dirt
setblock ~177 ~122 ~8 dirt
setblock ~177 ~122 ~9 dirt
setblock ~177 ~122 ~10 dirt
setblock ~177 ~122 ~11 dirt
setblock ~177 ~122 ~12 dirt
setblock ~177 ~122 ~13 dirt
setblock ~177 ~122 ~14 dirt
setblock ~177 ~122 ~15 dirt
setblock ~177 ~122 ~16 dirt
setblock ~177 ~122 ~17 dirt
setblock ~177 ~122 ~18 dirt
setblock ~177 ~122 ~19 dirt
setblock ~177 ~122 ~20 dirt
setblock ~177 ~122 ~21 dirt
setblock ~177 ~122 ~22 dirt
setblock ~177 ~122 ~23 dirt
setblock ~177 ~122 ~24 dirt
setblock ~177 ~122 ~25 dirt
setblock ~177 ~122 ~26 dirt
setblock ~177 ~122 ~27 dirt
setblock ~177 ~122 ~28 dirt
setblock ~177 ~122 ~29 dirt
setblock ~177 ~122 ~30 dirt
setblock ~177 ~122 ~31 dirt
setblock ~177 ~122 ~32 dirt
setblock ~177 ~122 ~33 dirt
setblock ~177 ~122 ~34 dirt
setblock ~177 ~122 ~35 dirt
setblock ~177 ~122 ~36 dirt
setblock ~177 ~122 ~37 dirt
setblock ~177 ~122 ~38 dirt
setblock ~177 ~122 ~39 dirt
setblock ~177 ~122 ~40 dirt
setblock ~177 ~122 ~41 dirt
setblock ~177 ~122 ~42 dirt
setblock ~177 ~122 ~43 dirt
setblock ~177 ~122 ~44 dirt
setblock ~177 ~122 ~45 dirt
setblock ~177 ~122 ~46 dirt
setblock ~177 ~122 ~47 dirt
setblock ~177 ~122 ~48 dirt
setblock ~177 ~122 ~49 dirt
setblock ~177 ~122 ~50 dirt
setblock ~177 ~122 ~51 dirt
setblock ~177 ~122 ~52 dirt
setblock ~177 ~122 ~53 dirt
setblock ~177 ~122 ~54 dirt
setblock ~177 ~122 ~55 dirt
setblock ~177 ~122 ~56 dirt
setblock ~177 ~122 ~57 dirt
setblock ~177 ~122 ~58 dirt
setblock ~177 ~122 ~59 dirt
setblock ~177 ~122 ~60 grass_block
setblock ~177 ~122 ~61 dirt
setblock ~177 ~122 ~62 dirt
setblock ~177 ~122 ~63 dirt
setblock ~177 ~122 ~64 dirt
setblock ~177 ~122 ~65 dirt
setblock ~177 ~122 ~66 dirt
setblock ~177 ~122 ~67 dirt
setblock ~177 ~122 ~68 dirt
setblock ~177 ~122 ~69 dirt
setblock ~177 ~122 ~70 dirt
setblock ~177 ~122 ~71 dirt
setblock ~177 ~122 ~72 dirt
setblock ~177 ~122 ~73 dirt
setblock ~177 ~122 ~74 dirt
setblock ~177 ~122 ~75 dirt
setblock ~177 ~122 ~76 dirt
setblock ~177 ~122 ~77 dirt
setblock ~177 ~122 ~78 dirt
setblock ~177 ~122 ~79 dirt
setblock ~177 ~122 ~80 dirt
setblock ~177 ~122 ~81 dirt
setblock ~177 ~122 ~82 dirt
setblock ~177 ~122 ~83 dirt
setblock ~177 ~122 ~84 dirt
setblock ~177 ~122 ~85 dirt
setblock ~177 ~122 ~86 dirt
setblock ~177 ~122 ~87 dirt
setblock ~177 ~122 ~88 dirt
setblock ~177 ~122 ~89 dirt
setblock ~177 ~122 ~90 dirt
setblock ~177 ~122 ~91 dirt
setblock ~177 ~122 ~92 dirt
setblock ~177 ~122 ~93 dirt
setblock ~177 ~122 ~94 dirt
setblock ~177 ~122 ~95 dirt
setblock ~177 ~122 ~96 dirt
setblock ~177 ~122 ~97 dirt
setblock ~177 ~122 ~98 dirt
setblock ~177 ~122 ~99 dirt
setblock ~177 ~122 ~100 dirt
setblock ~177 ~122 ~101 dirt
setblock ~177 ~122 ~102 dirt
setblock ~177 ~122 ~103 dirt
setblock ~177 ~122 ~104 dirt
setblock ~177 ~122 ~105 dirt
setblock ~177 ~122 ~106 dirt
setblock ~177 ~122 ~107 dirt
setblock ~177 ~122 ~108 dirt
setblock ~177 ~122 ~109 dirt
setblock ~177 ~122 ~110 dirt
setblock ~177 ~122 ~111 dirt
setblock ~177 ~122 ~112 dirt
setblock ~177 ~122 ~113 dirt
setblock ~177 ~122 ~114 dirt
setblock ~177 ~122 ~115 dirt
setblock ~177 ~122 ~116 dirt
setblock ~177 ~122 ~117 dirt
setblock ~177 ~122 ~118 dirt
setblock ~177 ~122 ~119 dirt
setblock ~177 ~122 ~120 dirt
setblock ~177 ~122 ~121 dirt
setblock ~177 ~122 ~122 dirt
setblock ~177 ~122 ~123 dirt
setblock ~177 ~122 ~124 dirt
setblock ~177 ~122 ~125 dirt
setblock ~177 ~122 ~126 dirt
setblock ~177 ~122 ~127 dirt
setblock ~177 ~122 ~128 dirt
setblock ~177 ~122 ~129 dirt
setblock ~177 ~122 ~130 dirt
setblock ~177 ~122 ~131 dirt
setblock ~177 ~122 ~132 dirt
setblock ~177 ~122 ~133 dirt
setblock ~177 ~122 ~134 dirt
setblock ~177 ~122 ~135 dirt
setblock ~177 ~122 ~136 dirt
setblock ~177 ~122 ~137 dirt
setblock ~177 ~122 ~138 dirt
setblock ~177 ~122 ~139 dirt
setblock ~177 ~122 ~140 dirt
setblock ~177 ~122 ~141 dirt
setblock ~177 ~122 ~142 dirt
setblock ~177 ~122 ~143 dirt
setblock ~177 ~122 ~144 dirt
setblock ~177 ~122 ~145 dirt
setblock ~177 ~122 ~146 dirt
setblock ~177 ~122 ~147 dirt
setblock ~177 ~122 ~148 dirt
setblock ~177 ~122 ~149 dirt
setblock ~177 ~122 ~150 dirt
setblock ~177 ~122 ~151 dirt
setblock ~177 ~122 ~152 dirt
setblock ~177 ~122 ~153 dirt
setblock ~177 ~122 ~154 dirt
setblock ~177 ~122 ~155 dirt
setblock ~177 ~122 ~156 dirt
setblock ~177 ~122 ~157 dirt
setblock ~177 ~122 ~158 dirt
setblock ~177 ~122 ~159 dirt
setblock ~177 ~122 ~160 dirt
setblock ~177 ~122 ~161 dirt
setblock ~177 ~122 ~162 dirt
setblock ~177 ~122 ~163 dirt
setblock ~177 ~122 ~164 dirt
setblock ~177 ~122 ~165 dirt
setblock ~177 ~122 ~166 dirt
setblock ~177 ~122 ~167 dirt
setblock ~177 ~122 ~168 dirt
setblock ~177 ~122 ~169 dirt
setblock ~177 ~122 ~170 dirt
setblock ~177 ~122 ~171 dirt
setblock ~177 ~122 ~172 dirt
setblock ~177 ~122 ~173 dirt
setblock ~177 ~122 ~174 dirt
setblock ~177 ~122 ~175 dirt
setblock ~177 ~122 ~176 dirt
setblock ~177 ~122 ~177 dirt
setblock ~177 ~122 ~178 dirt
setblock ~177 ~122 ~179 dirt
setblock ~177 ~122 ~180 dirt
setblock ~177 ~122 ~181 dirt
setblock ~177 ~122 ~182 dirt
setblock ~177 ~122 ~183 dirt
setblock ~177 ~122 ~184 dirt
setblock ~177 ~122 ~185 dirt
setblock ~177 ~122 ~186 dirt
setblock ~177 ~122 ~187 dirt
setblock ~177 ~122 ~188 dirt
setblock ~177 ~122 ~189 dirt
setblock ~177 ~122 ~190 dirt
setblock ~177 ~122 ~191 dirt
setblock ~177 ~122 ~192 dirt
setblock ~177 ~122 ~193 dirt
setblock ~177 ~122 ~194 dirt
setblock ~177 ~122 ~195 dirt
setblock ~177 ~122 ~196 dirt
setblock ~177 ~122 ~197 dirt
setblock ~177 ~122 ~198 dirt
setblock ~177 ~122 ~199 dirt
setblock ~177 ~123 ~0 dirt
setblock ~177 ~123 ~1 dirt
setblock ~177 ~123 ~2 dirt
setblock ~177 ~123 ~3 dirt
setblock ~177 ~123 ~4 dirt
setblock ~177 ~123 ~5 dirt
setblock ~177 ~123 ~6 dirt
setblock ~177 ~123 ~7 dirt
setblock ~177 ~123 ~8 dirt
setblock ~177 ~123 ~9 dirt
setblock ~177 ~123 ~10 grass_block
setblock ~177 ~123 ~11 grass_block
setblock ~177 ~123 ~12 grass_block
setblock ~177 ~123 ~13 dirt
setblock ~177 ~123 ~14 dirt
setblock ~177 ~123 ~15 dirt
setblock ~177 ~123 ~16 dirt
setblock ~177 ~123 ~17 dirt
setblock ~177 ~123 ~18 dirt
setblock ~177 ~123 ~19 dirt
setblock ~177 ~123 ~20 dirt
setblock ~177 ~123 ~21 dirt
setblock ~177 ~123 ~22 dirt
setblock ~177 ~123 ~23 dirt
setblock ~177 ~123 ~24 dirt
setblock ~177 ~123 ~25 dirt
setblock ~177 ~123 ~26 dirt
setblock ~177 ~123 ~27 dirt
setblock ~177 ~123 ~28 dirt
setblock ~177 ~123 ~29 dirt
setblock ~177 ~123 ~30 dirt
setblock ~177 ~123 ~31 dirt
setblock ~177 ~123 ~32 dirt
setblock ~177 ~123 ~33 dirt
setblock ~177 ~123 ~34 dirt
setblock ~177 ~123 ~35 dirt
setblock ~177 ~123 ~36 dirt
setblock ~177 ~123 ~37 grass_block
setblock ~177 ~123 ~38 grass_block
setblock ~177 ~123 ~39 grass_block
setblock ~177 ~123 ~40 grass_block
setblock ~177 ~123 ~41 grass_block
setblock ~177 ~123 ~42 grass_block
setblock ~177 ~123 ~43 dirt
setblock ~177 ~123 ~44 dirt
setblock ~177 ~123 ~45 dirt
setblock ~177 ~123 ~46 dirt
setblock ~177 ~123 ~47 dirt
setblock ~177 ~123 ~48 dirt
setblock ~177 ~123 ~49 dirt
setblock ~177 ~123 ~50 dirt
setblock ~177 ~123 ~51 dirt
setblock ~177 ~123 ~52 dirt
setblock ~177 ~123 ~53 dirt
setblock ~177 ~123 ~54 dirt
setblock ~177 ~123 ~55 dirt
setblock ~177 ~123 ~56 dirt
setblock ~177 ~123 ~57 grass_block
setblock ~177 ~123 ~58 grass_block
setblock ~177 ~123 ~59 grass_block
setblock ~177 ~123 ~60 poppy
setblock ~177 ~123 ~61 grass_block
setblock ~177 ~123 ~62 grass_block
setblock ~177 ~123 ~63 dirt
setblock ~177 ~123 ~64 dirt
setblock ~177 ~123 ~65 dirt
setblock ~177 ~123 ~66 dirt
setblock ~177 ~123 ~67 dirt
setblock ~177 ~123 ~68 dirt
setblock ~177 ~123 ~69 dirt
setblock ~177 ~123 ~70 dirt
setblock ~177 ~123 ~71 dirt
setblock ~177 ~123 ~72 dirt
setblock ~177 ~123 ~73 dirt
setblock ~177 ~123 ~74 dirt
setblock ~177 ~123 ~75 dirt
setblock ~177 ~123 ~76 dirt
setblock ~177 ~123 ~77 dirt
setblock ~177 ~123 ~78 dirt
setblock ~177 ~123 ~79 dirt
setblock ~177 ~123 ~80 dirt
setblock ~177 ~123 ~81 dirt
setblock ~177 ~123 ~82 dirt
setblock ~177 ~123 ~83 dirt
setblock ~177 ~123 ~84 dirt
setblock ~177 ~123 ~85 dirt
setblock ~177 ~123 ~86 dirt
setblock ~177 ~123 ~87 dirt
setblock ~177 ~123 ~88 dirt
setblock ~177 ~123 ~89 dirt
setblock ~177 ~123 ~90 dirt
setblock ~177 ~123 ~91 dirt
setblock ~177 ~123 ~92 dirt
setblock ~177 ~123 ~93 dirt
setblock ~177 ~123 ~94 dirt
setblock ~177 ~123 ~95 dirt
setblock ~177 ~123 ~96 dirt
setblock ~177 ~123 ~97 dirt
setblock ~177 ~123 ~98 dirt
setblock ~177 ~123 ~99 dirt
setblock ~177 ~123 ~100 dirt
setblock ~177 ~123 ~101 dirt
setblock ~177 ~123 ~102 dirt
setblock ~177 ~123 ~103 dirt
setblock ~177 ~123 ~104 dirt
setblock ~177 ~123 ~105 dirt
setblock ~177 ~123 ~106 dirt
setblock ~177 ~123 ~107 dirt
setblock ~177 ~123 ~108 dirt
setblock ~177 ~123 ~109 dirt
setblock ~177 ~123 ~110 grass_block
setblock ~177 ~123 ~111 grass_block
setblock ~177 ~123 ~112 dirt
setblock ~177 ~123 ~113 dirt
setblock ~177 ~123 ~114 dirt
setblock ~177 ~123 ~115 dirt
setblock ~177 ~123 ~116 dirt
setblock ~177 ~123 ~117 dirt
setblock ~177 ~123 ~118 dirt
setblock ~177 ~123 ~119 dirt
setblock ~177 ~123 ~120 dirt
setblock ~177 ~123 ~121 dirt
setblock ~177 ~123 ~122 dirt
setblock ~177 ~123 ~123 dirt
setblock ~177 ~123 ~124 dirt
setblock ~177 ~123 ~125 dirt
setblock ~177 ~123 ~126 dirt
setblock ~177 ~123 ~127 dirt
setblock ~177 ~123 ~128 dirt
setblock ~177 ~123 ~129 dirt
setblock ~177 ~123 ~130 dirt
setblock ~177 ~123 ~131 dirt
setblock ~177 ~123 ~132 dirt
setblock ~177 ~123 ~133 dirt
setblock ~177 ~123 ~134 dirt
setblock ~177 ~123 ~135 dirt
setblock ~177 ~123 ~136 dirt
setblock ~177 ~123 ~137 dirt
setblock ~177 ~123 ~138 dirt
setblock ~177 ~123 ~139 dirt
setblock ~177 ~123 ~140 dirt
setblock ~177 ~123 ~141 dirt
setblock ~177 ~123 ~142 dirt
setblock ~177 ~123 ~143 dirt
setblock ~177 ~123 ~144 dirt
setblock ~177 ~123 ~145 dirt
setblock ~177 ~123 ~146 dirt
setblock ~177 ~123 ~147 dirt
setblock ~177 ~123 ~148 dirt
setblock ~177 ~123 ~149 dirt
setblock ~177 ~123 ~150 dirt
setblock ~177 ~123 ~151 dirt
setblock ~177 ~123 ~152 dirt
setblock ~177 ~123 ~153 dirt
setblock ~177 ~123 ~154 dirt
setblock ~177 ~123 ~155 dirt
setblock ~177 ~123 ~156 dirt
setblock ~177 ~123 ~157 dirt
setblock ~177 ~123 ~158 dirt
setblock ~177 ~123 ~159 dirt
setblock ~177 ~123 ~160 dirt
setblock ~177 ~123 ~161 dirt
setblock ~177 ~123 ~162 dirt
setblock ~177 ~123 ~163 dirt
setblock ~177 ~123 ~164 dirt
setblock ~177 ~123 ~165 dirt
setblock ~177 ~123 ~166 dirt
setblock ~177 ~123 ~167 dirt
setblock ~177 ~123 ~168 dirt
setblock ~177 ~123 ~169 dirt
setblock ~177 ~123 ~170 dirt
setblock ~177 ~123 ~171 dirt
setblock ~177 ~123 ~172 dirt
setblock ~177 ~123 ~173 dirt
setblock ~177 ~123 ~174 dirt
setblock ~177 ~123 ~175 dirt
setblock ~177 ~123 ~176 dirt
setblock ~177 ~123 ~177 dirt
setblock ~177 ~123 ~178 dirt
setblock ~177 ~123 ~179 dirt
setblock ~177 ~123 ~180 dirt
setblock ~177 ~123 ~181 dirt
setblock ~177 ~123 ~182 dirt
setblock ~177 ~123 ~183 dirt
setblock ~177 ~123 ~184 dirt
setblock ~177 ~123 ~185 dirt
setblock ~177 ~123 ~186 dirt
setblock ~177 ~123 ~187 dirt
setblock ~177 ~123 ~188 dirt
setblock ~177 ~123 ~189 dirt
setblock ~177 ~123 ~190 dirt
setblock ~177 ~123 ~191 dirt
setblock ~177 ~123 ~192 dirt
setblock ~177 ~123 ~193 dirt
setblock ~177 ~123 ~194 dirt
setblock ~177 ~123 ~195 dirt
setblock ~177 ~123 ~196 dirt
setblock ~177 ~123 ~197 dirt
setblock ~177 ~123 ~198 dirt
setblock ~177 ~123 ~199 grass_block
setblock ~177 ~124 ~0 dirt
setblock ~177 ~124 ~1 dirt
setblock ~177 ~124 ~2 dirt
setblock ~177 ~124 ~3 dirt
setblock ~177 ~124 ~4 dirt
setblock ~177 ~124 ~5 dirt
setblock ~177 ~124 ~6 dirt
setblock ~177 ~124 ~7 grass_block
setblock ~177 ~124 ~8 grass_block
setblock ~177 ~124 ~9 grass_block
setblock ~177 ~124 ~12 short_grass
setblock ~177 ~124 ~13 grass_block
setblock ~177 ~124 ~14 grass_block
setblock ~177 ~124 ~15 grass_block
setblock ~177 ~124 ~16 grass_block
setblock ~177 ~124 ~17 grass_block
setblock ~177 ~124 ~18 grass_block
setblock ~177 ~124 ~19 grass_block
setblock ~177 ~124 ~20 dirt
setblock ~177 ~124 ~21 dirt
setblock ~177 ~124 ~22 dirt
setblock ~177 ~124 ~23 dirt
setblock ~177 ~124 ~24 dirt
setblock ~177 ~124 ~25 dirt
setblock ~177 ~124 ~26 dirt
setblock ~177 ~124 ~27 dirt
setblock ~177 ~124 ~28 dirt
setblock ~177 ~124 ~29 dirt
setblock ~177 ~124 ~30 dirt
setblock ~177 ~124 ~31 dirt
setblock ~177 ~124 ~32 grass_block
setblock ~177 ~124 ~33 grass_block
setblock ~177 ~124 ~34 grass_block
setblock ~177 ~124 ~35 grass_block
setblock ~177 ~124 ~36 grass_block
setblock ~177 ~124 ~40 short_grass
setblock ~177 ~124 ~43 grass_block
setblock ~177 ~124 ~44 grass_block
setblock ~177 ~124 ~45 grass_block
setblock ~177 ~124 ~46 grass_block
setblock ~177 ~124 ~47 dirt
setblock ~177 ~124 ~48 dirt
setblock ~177 ~124 ~49 dirt
setblock ~177 ~124 ~50 dirt
setblock ~177 ~124 ~51 dirt
setblock ~177 ~124 ~52 dirt
setblock ~177 ~124 ~53 dirt
setblock ~177 ~124 ~54 grass_block
setblock ~177 ~124 ~55 grass_block
setblock ~177 ~124 ~56 grass_block
setblock ~177 ~124 ~57 short_grass
setblock ~177 ~124 ~59 short_grass
setblock ~177 ~124 ~61 short_grass
setblock ~177 ~124 ~63 grass_block
setblock ~177 ~124 ~64 grass_block
setblock ~177 ~124 ~65 dirt
setblock ~177 ~124 ~66 dirt
setblock ~177 ~124 ~67 dirt
setblock ~177 ~124 ~68 dirt
setblock ~177 ~124 ~69 dirt
setblock ~177 ~124 ~70 dirt
setblock ~177 ~124 ~71 dirt
setblock ~177 ~124 ~72 dirt
setblock ~177 ~124 ~73 dirt
setblock ~177 ~124 ~74 dirt
setblock ~177 ~124 ~75 dirt
setblock ~177 ~124 ~76 dirt
setblock ~177 ~124 ~77 dirt
setblock ~177 ~124 ~78 dirt
setblock ~177 ~124 ~79 grass_block
setblock ~177 ~124 ~80 grass_block
setblock ~177 ~124 ~81 grass_block
setblock ~177 ~124 ~82 dirt
setblock ~177 ~124 ~83 dirt
setblock ~177 ~124 ~84 dirt
setblock ~177 ~124 ~85 dirt
setblock ~177 ~124 ~86 dirt
setblock ~177 ~124 ~87 dirt
setblock ~177 ~124 ~88 dirt
setblock ~177 ~124 ~89 dirt
setblock ~177 ~124 ~90 dirt
setblock ~177 ~124 ~91 dirt
setblock ~177 ~124 ~92 dirt
setblock ~177 ~124 ~93 dirt
setblock ~177 ~124 ~94 dirt
setblock ~177 ~124 ~95 dirt
setblock ~177 ~124 ~96 dirt
setblock ~177 ~124 ~97 dirt
setblock ~177 ~124 ~98 dirt
setblock ~177 ~124 ~99 grass_block
setblock ~177 ~124 ~100 grass_block
setblock ~177 ~124 ~101 grass_block
setblock ~177 ~124 ~102 grass_block
setblock ~177 ~124 ~103 grass_block
setblock ~177 ~124 ~104 grass_block
setblock ~177 ~124 ~105 grass_block
setblock ~177 ~124 ~106 grass_block
setblock ~177 ~124 ~107 grass_block
setblock ~177 ~124 ~108 grass_block
setblock ~177 ~124 ~109 grass_block
setblock ~177 ~124 ~112 grass_block
setblock ~177 ~124 ~113 grass_block
setblock ~177 ~124 ~114 grass_block
setblock ~177 ~124 ~115 grass_block
setblock ~177 ~124 ~116 grass_block
setblock ~177 ~124 ~117 grass_block
setblock ~177 ~124 ~118 grass_block
setblock ~177 ~124 ~119 grass_block
setblock ~177 ~124 ~120 grass_block
setblock ~177 ~124 ~121 grass_block
setblock ~177 ~124 ~122 grass_block
setblock ~177 ~124 ~123 grass_block
setblock ~177 ~124 ~124 grass_block
setblock ~177 ~124 ~125 grass_block
setblock ~177 ~124 ~126 dirt
setblock ~177 ~124 ~127 dirt
setblock ~177 ~124 ~128 dirt
setblock ~177 ~124 ~129 dirt
setblock ~177 ~124 ~130 dirt
setblock ~177 ~124 ~131 dirt
setblock ~177 ~124 ~132 dirt
setblock ~177 ~124 ~133 dirt
setblock ~177 ~124 ~134 dirt
setblock ~177 ~124 ~135 dirt
setblock ~177 ~124 ~136 dirt
setblock ~177 ~124 ~137 grass_block
setblock ~177 ~124 ~138 grass_block
setblock ~177 ~124 ~139 grass_block
setblock ~177 ~124 ~140 grass_block
setblock ~177 ~124 ~141 grass_block
setblock ~177 ~124 ~142 grass_block
setblock ~177 ~124 ~143 grass_block
setblock ~177 ~124 ~144 grass_block
setblock ~177 ~124 ~145 grass_block
setblock ~177 ~124 ~146 grass_block
setblock ~177 ~124 ~147 grass_block
setblock ~177 ~124 ~148 grass_block
setblock ~177 ~124 ~149 grass_block
setblock ~177 ~124 ~150 grass_block
setblock ~177 ~124 ~151 grass_block
setblock ~177 ~124 ~152 grass_block
setblock ~177 ~124 ~153 grass_block
setblock ~177 ~124 ~154 grass_block
setblock ~177 ~124 ~155 grass_block
setblock ~177 ~124 ~156 grass_block
setblock ~177 ~124 ~157 dirt
setblock ~177 ~124 ~158 dirt
setblock ~177 ~124 ~159 dirt
setblock ~177 ~124 ~160 dirt
setblock ~177 ~124 ~161 dirt
setblock ~177 ~124 ~162 dirt
setblock ~177 ~124 ~163 dirt
setblock ~177 ~124 ~164 dirt
setblock ~177 ~124 ~165 grass_block
setblock ~177 ~124 ~166 grass_block
setblock ~177 ~124 ~167 grass_block
setblock ~177 ~124 ~168 grass_block
setblock ~177 ~124 ~169 grass_block
setblock ~177 ~124 ~170 grass_block
setblock ~177 ~124 ~171 grass_block
setblock ~177 ~124 ~172 grass_block
setblock ~177 ~124 ~173 grass_block
setblock ~177 ~124 ~174 dirt
setblock ~177 ~124 ~175 dirt
setblock ~177 ~124 ~176 dirt
setblock ~177 ~124 ~177 dirt
setblock ~177 ~124 ~178 dirt
setblock ~177 ~124 ~179 dirt
setblock ~177 ~124 ~180 dirt
setblock ~177 ~124 ~181 dirt
setblock ~177 ~124 ~182 dirt
setblock ~177 ~124 ~183 dirt
setblock ~177 ~124 ~184 dirt
setblock ~177 ~124 ~185 dirt
setblock ~177 ~124 ~186 dirt
setblock ~177 ~124 ~187 dirt
setblock ~177 ~124 ~188 dirt
setblock ~177 ~124 ~189 dirt
setblock ~177 ~124 ~190 dirt
setblock ~177 ~124 ~191 dirt
setblock ~177 ~124 ~192 dirt
setblock ~177 ~124 ~193 dirt
setblock ~177 ~124 ~194 dirt
setblock ~177 ~124 ~195 dirt
setblock ~177 ~124 ~196 dirt
setblock ~177 ~124 ~197 grass_block
setblock ~177 ~124 ~198 grass_block
setblock ~177 ~124 ~199 short_grass
setblock ~177 ~125 ~0 grass_block
setblock ~177 ~125 ~1 grass_block
setblock ~177 ~125 ~2 grass_block
setblock ~177 ~125 ~3 grass_block
setblock ~177 ~125 ~4 grass_block
setblock ~177 ~125 ~5 grass_block
setblock ~177 ~125 ~6 grass_block
setblock ~177 ~125 ~8 short_grass
setblock ~177 ~125 ~19 short_grass
setblock ~177 ~125 ~20 grass_block
setblock ~177 ~125 ~21 grass_block
setblock ~177 ~125 ~22 grass_block
setblock ~177 ~125 ~23 grass_block
setblock ~177 ~125 ~24 grass_block
setblock ~177 ~125 ~25 grass_block
setblock ~177 ~125 ~26 grass_block
setblock ~177 ~125 ~27 grass_block
setblock ~177 ~125 ~28 grass_block
setblock ~177 ~125 ~29 grass_block
setblock ~177 ~125 ~30 grass_block
setblock ~177 ~125 ~31 grass_block
setblock ~177 ~125 ~33 short_grass
setblock ~177 ~125 ~36 short_grass
setblock ~177 ~125 ~46 short_grass
setblock ~177 ~125 ~47 grass_block
setblock ~177 ~125 ~48 grass_block
setblock ~177 ~125 ~49 grass_block
setblock ~177 ~125 ~50 grass_block
setblock ~177 ~125 ~51 grass_block
setblock ~177 ~125 ~52 grass_block
setblock ~177 ~125 ~53 grass_block
setblock ~177 ~125 ~55 short_grass
setblock ~177 ~125 ~56 short_grass
setblock ~177 ~125 ~65 grass_block
setblock ~177 ~125 ~66 grass_block
setblock ~177 ~125 ~67 dirt
setblock ~177 ~125 ~68 dirt
setblock ~177 ~125 ~69 dirt
setblock ~177 ~125 ~70 dirt
setblock ~177 ~125 ~71 dirt
setblock ~177 ~125 ~72 dirt
setblock ~177 ~125 ~73 dirt
setblock ~177 ~125 ~74 dirt
setblock ~177 ~125 ~75 dirt
setblock ~177 ~125 ~76 grass_block
setblock ~177 ~125 ~77 grass_block
setblock ~177 ~125 ~78 grass_block
setblock ~177 ~125 ~82 grass_block
setblock ~177 ~125 ~83 grass_block
setblock ~177 ~125 ~84 dirt
setblock ~177 ~125 ~85 dirt
setblock ~177 ~125 ~86 dirt
setblock ~177 ~125 ~87 dirt
setblock ~177 ~125 ~88 dirt
setblock ~177 ~125 ~89 dirt
setblock ~177 ~125 ~90 dirt
setblock ~177 ~125 ~91 dirt
setblock ~177 ~125 ~92 dirt
setblock ~177 ~125 ~93 dirt
setblock ~177 ~125 ~94 dirt
setblock ~177 ~125 ~95 dirt
setblock ~177 ~125 ~96 grass_block
setblock ~177 ~125 ~97 grass_block
setblock ~177 ~125 ~98 grass_block
setblock ~177 ~125 ~100 short_grass
setblock ~177 ~125 ~101 short_grass
setblock ~177 ~125 ~105 short_grass
setblock ~177 ~125 ~107 short_grass
setblock ~177 ~125 ~113 poppy
setblock ~177 ~125 ~122 short_grass
setblock ~177 ~125 ~126 grass_block
setblock ~177 ~125 ~127 grass_block
setblock ~177 ~125 ~128 grass_block
setblock ~177 ~125 ~129 grass_block
setblock ~177 ~125 ~130 grass_block
setblock ~177 ~125 ~131 grass_block
setblock ~177 ~125 ~132 grass_block
setblock ~177 ~125 ~133 grass_block
setblock ~177 ~125 ~134 grass_block
setblock ~177 ~125 ~135 grass_block
setblock ~177 ~125 ~136 grass_block
setblock ~177 ~125 ~137 short_grass
setblock ~177 ~125 ~140 fern
setblock ~177 ~125 ~142 short_grass
setblock ~177 ~125 ~150 short_grass
setblock ~177 ~125 ~152 short_grass
setblock ~177 ~125 ~153 short_grass
setblock ~177 ~125 ~155 short_grass
setblock ~177 ~125 ~157 grass_block
setblock ~177 ~125 ~158 grass_block
setblock ~177 ~125 ~159 grass_block
setblock ~177 ~125 ~160 grass_block
setblock ~177 ~125 ~161 grass_block
setblock ~177 ~125 ~162 grass_block
setblock ~177 ~125 ~163 grass_block
setblock ~177 ~125 ~164 grass_block
setblock ~177 ~125 ~166 short_grass
setblock ~177 ~125 ~171 short_grass
setblock ~177 ~125 ~174 grass_block
setblock ~177 ~125 ~175 grass_block
setblock ~177 ~125 ~176 grass_block
setblock ~177 ~125 ~177 grass_block
setblock ~177 ~125 ~178 grass_block
setblock ~177 ~125 ~179 grass_block
setblock ~177 ~125 ~180 dirt
setblock ~177 ~125 ~181 dirt
setblock ~177 ~125 ~182 dirt
setblock ~177 ~125 ~183 dirt
setblock ~177 ~125 ~184 dirt
setblock ~177 ~125 ~185 dirt
setblock ~177 ~125 ~186 dirt
setblock ~177 ~125 ~187 dirt
setblock ~177 ~125 ~188 dirt
setblock ~177 ~125 ~189 dirt
setblock ~177 ~125 ~190 dirt
setblock ~177 ~125 ~191 dirt
setblock ~177 ~125 ~192 dirt
setblock ~177 ~125 ~193 dirt
setblock ~177 ~125 ~194 dirt
setblock ~177 ~125 ~195 grass_block
setblock ~177 ~125 ~196 grass_block
setblock ~177 ~125 ~198 fern
setblock ~177 ~126 ~2 short_grass
setblock ~177 ~126 ~6 short_grass
setblock ~177 ~126 ~21 short_grass
setblock ~177 ~126 ~22 poppy
setblock ~177 ~126 ~26 short_grass
setblock ~177 ~126 ~27 short_grass
setblock ~177 ~126 ~47 short_grass
setblock ~177 ~126 ~50 short_grass
setblock ~177 ~126 ~67 grass_block
setblock ~177 ~126 ~68 dirt
setblock ~177 ~126 ~69 dirt
setblock ~177 ~126 ~70 dirt
setblock ~177 ~126 ~71 dirt
setblock ~177 ~126 ~72 dirt
setblock ~177 ~126 ~73 dirt
setblock ~177 ~126 ~74 grass_block
setblock ~177 ~126 ~75 grass_block
setblock ~177 ~126 ~84 grass_block
setblock ~177 ~126 ~85 grass_block
setblock ~177 ~126 ~86 grass_block
setblock ~177 ~126 ~87 dirt
setblock ~177 ~126 ~88 dirt
setblock ~177 ~126 ~89 dirt
setblock ~177 ~126 ~90 dirt
setblock ~177 ~126 ~91 dirt
setblock ~177 ~126 ~92 dirt
setblock ~177 ~126 ~93 dirt
setblock ~177 ~126 ~94 grass_block
setblock ~177 ~126 ~95 grass_block
setblock ~177 ~126 ~96 short_grass
setblock ~177 ~126 ~126 short_grass
setblock ~177 ~126 ~130 short_grass
setblock ~177 ~126 ~157 short_grass
setblock ~177 ~126 ~160 short_grass
setblock ~177 ~126 ~164 short_grass
setblock ~177 ~126 ~174 short_grass
setblock ~177 ~126 ~180 grass_block
setblock ~177 ~126 ~181 grass_block
setblock ~177 ~126 ~182 grass_block
setblock ~177 ~126 ~183 grass_block
setblock ~177 ~126 ~184 grass_block
setblock ~177 ~126 ~185 dirt
setblock ~177 ~126 ~186 dirt
setblock ~177 ~126 ~187 dirt
setblock ~177 ~126 ~188 dirt
setblock ~177 ~126 ~189 dirt
setblock ~177 ~126 ~190 dirt
setblock ~177 ~126 ~191 dirt
setblock ~177 ~126 ~192 dirt
setblock ~177 ~126 ~193 grass_block
setblock ~177 ~126 ~194 grass_block
setblock ~177 ~126 ~196 short_grass
setblock ~177 ~127 ~68 grass_block
setblock ~177 ~127 ~69 dirt
setblock ~177 ~127 ~70 dirt
setblock ~177 ~127 ~71 dirt
setblock ~177 ~127 ~72 grass_block
setblock ~177 ~127 ~73 grass_block
setblock ~177 ~127 ~75 short_grass
setblock ~177 ~127 ~84 poppy
setblock ~177 ~127 ~87 grass_block
setblock ~177 ~127 ~88 grass_block
setblock ~177 ~127 ~89 dirt
setblock ~177 ~127 ~90 dirt
setblock ~177 ~127 ~91 dirt
setblock ~177 ~127 ~92 grass_block
setblock ~177 ~127 ~93 grass_block
setblock ~177 ~127 ~180 poppy
setblock ~177 ~127 ~183 short_grass
setblock ~177 ~127 ~185 grass_block
setblock ~177 ~127 ~186 grass_block
setblock ~177 ~127 ~187 grass_block
setblock ~177 ~127 ~188 grass_block
setblock ~177 ~127 ~189 dirt
setblock ~177 ~127 ~190 dirt
setblock ~177 ~127 ~191 grass_block
setblock ~177 ~127 ~192 grass_block
setblock ~177 ~128 ~69 grass_block
setblock ~177 ~128 ~70 dirt
setblock ~177 ~128 ~71 grass_block
setblock ~177 ~128 ~72 short_grass
setblock ~177 ~128 ~73 fern
setblock ~177 ~128 ~88 short_grass
setblock ~177 ~128 ~89 grass_block
setblock ~177 ~128 ~90 dirt
setblock ~177 ~128 ~91 grass_block
setblock ~177 ~128 ~93 short_grass
setblock ~177 ~128 ~185 short_grass
setblock ~177 ~128 ~189 grass_block
setblock ~177 ~128 ~190 grass_block
setblock ~177 ~128 ~191 fern
setblock ~177 ~128 ~192 short_grass
setblock ~177 ~129 ~70 grass_block
setblock ~177 ~129 ~90 grass_block
setblock ~177 ~129 ~190 short_grass
setblock ~177 ~130 ~70 short_grass
setblock ~178 ~122 ~0 dirt
setblock ~178 ~122 ~1 dirt
setblock ~178 ~122 ~2 dirt
setblock ~178 ~122 ~3 dirt
setblock ~178 ~122 ~4 dirt
setblock ~178 ~122 ~5 dirt
setblock ~178 ~122 ~6 dirt
setblock ~178 ~122 ~7 dirt
setblock ~178 ~122 ~8 dirt
setblock ~178 ~122 ~9 dirt
setblock ~178 ~122 ~10 dirt
setblock ~178 ~122 ~11 dirt
setblock ~178 ~122 ~12 dirt
setblock ~178 ~122 ~13 dirt
setblock ~178 ~122 ~14 dirt
setblock ~178 ~122 ~15 dirt
setblock ~178 ~122 ~16 dirt
setblock ~178 ~122 ~17 dirt
setblock ~178 ~122 ~18 dirt
setblock ~178 ~122 ~19 dirt
setblock ~178 ~122 ~20 dirt
setblock ~178 ~122 ~21 dirt
setblock ~178 ~122 ~22 dirt
setblock ~178 ~122 ~23 dirt
setblock ~178 ~122 ~24 dirt
setblock ~178 ~122 ~25 dirt
setblock ~178 ~122 ~26 dirt
setblock ~178 ~122 ~27 dirt
setblock ~178 ~122 ~28 dirt
setblock ~178 ~122 ~29 dirt
setblock ~178 ~122 ~30 dirt
setblock ~178 ~122 ~31 dirt
setblock ~178 ~122 ~32 dirt
setblock ~178 ~122 ~33 dirt
setblock ~178 ~122 ~34 dirt
setblock ~178 ~122 ~35 dirt
setblock ~178 ~122 ~36 dirt
setblock ~178 ~122 ~37 dirt
setblock ~178 ~122 ~38 dirt
setblock ~178 ~122 ~39 dirt
