setblock ~166 ~123 ~95 dirt
setblock ~166 ~123 ~96 dirt
setblock ~166 ~123 ~97 dirt
setblock ~166 ~123 ~98 dirt
setblock ~166 ~123 ~99 dirt
setblock ~166 ~123 ~100 dirt
setblock ~166 ~123 ~101 dirt
setblock ~166 ~123 ~102 dirt
setblock ~166 ~123 ~103 dirt
setblock ~166 ~123 ~104 dirt
setblock ~166 ~123 ~105 dirt
setblock ~166 ~123 ~106 grass_block
setblock ~166 ~123 ~107 grass_block
setblock ~166 ~123 ~108 grass_block
setblock ~166 ~123 ~109 grass_block
setblock ~166 ~124 ~79 dirt
setblock ~166 ~124 ~80 dirt
setblock ~166 ~124 ~81 dirt
setblock ~166 ~124 ~82 dirt
setblock ~166 ~124 ~83 dirt
setblock ~166 ~124 ~84 dirt
setblock ~166 ~124 ~85 dirt
setblock ~166 ~124 ~86 dirt
setblock ~166 ~124 ~87 dirt
setblock ~166 ~124 ~88 dirt
setblock ~166 ~124 ~89 dirt
setblock ~166 ~124 ~90 dirt
setblock ~166 ~124 ~91 dirt
setblock ~166 ~124 ~92 dirt
setblock ~166 ~124 ~93 dirt
setblock ~166 ~124 ~94 dirt
setblock ~166 ~124 ~95 dirt
setblock ~166 ~124 ~96 dirt
setblock ~166 ~124 ~97 dirt
setblock ~166 ~124 ~98 dirt
setblock ~166 ~124 ~99 dirt
setblock ~166 ~124 ~100 grass_block
setblock ~166 ~124 ~101 grass_block
setblock ~166 ~124 ~102 grass_block
setblock ~166 ~124 ~103 grass_block
setblock ~166 ~124 ~104 grass_block
setblock ~166 ~124 ~105 grass_block
setblock ~166 ~124 ~107 short_grass
setblock ~166 ~125 ~79 grass_block
setblock ~166 ~125 ~80 grass_block
setblock ~166 ~125 ~81 grass_block
setblock ~166 ~125 ~82 grass_block
setblock ~166 ~125 ~83 grass_block
setblock ~166 ~125 ~84 dirt
setblock ~166 ~125 ~85 dirt
setblock ~166 ~125 ~86 dirt
setblock ~166 ~125 ~87 dirt
setblock ~166 ~125 ~88 dirt
setblock ~166 ~125 ~89 dirt
setblock ~166 ~125 ~90 dirt
setblock ~166 ~125 ~91 dirt
setblock ~166 ~125 ~92 grass_block
setblock ~166 ~125 ~93 grass_block
setblock ~166 ~125 ~94 grass_block
setblock ~166 ~125 ~95 grass_block
setblock ~166 ~125 ~96 grass_block
setblock ~166 ~125 ~97 grass_block
setblock ~166 ~125 ~98 grass_block
setblock ~166 ~125 ~99 grass_block
setblock ~166 ~125 ~102 poppy
setblock ~166 ~125 ~103 short_grass
setblock ~166 ~125 ~104 short_grass
setblock ~166 ~126 ~80 short_grass
setblock ~166 ~126 ~81 short_grass
setblock ~166 ~126 ~84 grass_block
setblock ~166 ~126 ~85 grass_block
setblock ~166 ~126 ~86 grass_block
setblock ~166 ~126 ~87 grass_block
setblock ~166 ~126 ~88 grass_block
setblock ~166 ~126 ~89 grass_block
setblock ~166 ~126 ~90 grass_block
setblock ~166 ~126 ~91 grass_block
setblock ~166 ~126 ~93 short_grass
setblock ~166 ~126 ~98 short_grass
setblock ~166 ~127 ~84 short_grass
setblock ~166 ~127 ~87 short_grass
setblock ~166 ~127 ~90 fern
setblock ~167 ~110 ~93 dirt
setblock ~167 ~111 ~93 dirt
setblock ~167 ~111 ~94 dirt
setblock ~167 ~111 ~95 dirt
setblock ~167 ~112 ~92 dirt
setblock ~167 ~112 ~93 dirt
setblock ~167 ~112 ~94 dirt
setblock ~167 ~112 ~95 dirt
setblock ~167 ~112 ~96 dirt
setblock ~167 ~113 ~91 dirt
setblock ~167 ~113 ~92 dirt
setblock ~167 ~113 ~93 dirt
setblock ~167 ~113 ~94 dirt
setblock ~167 ~113 ~95 dirt
setblock ~167 ~113 ~96 dirt
setblock ~167 ~113 ~97 dirt
setblock ~167 ~113 ~100 dirt
setblock ~167 ~114 ~90 dirt
setblock ~167 ~114 ~91 dirt
setblock ~167 ~114 ~92 dirt
setblock ~167 ~114 ~93 dirt
setblock ~167 ~114 ~94 dirt
setblock ~167 ~114 ~95 dirt
setblock ~167 ~114 ~96 dirt
setblock ~167 ~114 ~97 dirt
setblock ~167 ~114 ~98 dirt
setblock ~167 ~114 ~100 dirt
setblock ~167 ~114 ~103 dirt
setblock ~167 ~115 ~90 dirt
setblock ~167 ~115 ~91 dirt
setblock ~167 ~115 ~92 dirt
setblock ~167 ~115 ~93 dirt
setblock ~167 ~115 ~94 dirt
setblock ~167 ~115 ~95 dirt
setblock ~167 ~115 ~96 dirt
setblock ~167 ~115 ~97 dirt
setblock ~167 ~115 ~98 dirt
setblock ~167 ~115 ~99 dirt
setblock ~167 ~115 ~100 dirt
setblock ~167 ~115 ~103 dirt
setblock ~167 ~116 ~87 dirt
setblock ~167 ~116 ~89 dirt
setblock ~167 ~116 ~90 dirt
setblock ~167 ~116 ~91 dirt
setblock ~167 ~116 ~92 dirt
setblock ~167 ~116 ~93 dirt
setblock ~167 ~116 ~94 dirt
setblock ~167 ~116 ~95 dirt
setblock ~167 ~116 ~96 dirt
setblock ~167 ~116 ~97 dirt
setblock ~167 ~116 ~98 dirt
setblock ~167 ~116 ~99 dirt
setblock ~167 ~116 ~100 dirt
setblock ~167 ~116 ~101 dirt
setblock ~167 ~116 ~102 dirt
setblock ~167 ~116 ~103 dirt
setblock ~167 ~117 ~87 dirt
setblock ~167 ~117 ~88 dirt
setblock ~167 ~117 ~89 dirt
setblock ~167 ~117 ~90 dirt
setblock ~167 ~117 ~91 dirt
setblock ~167 ~117 ~92 dirt
setblock ~167 ~117 ~93 dirt
setblock ~167 ~117 ~94 dirt
setblock ~167 ~117 ~95 dirt
setblock ~167 ~117 ~96 dirt
setblock ~167 ~117 ~97 dirt
setblock ~167 ~117 ~98 dirt
setblock ~167 ~117 ~99 dirt
setblock ~167 ~117 ~100 dirt
setblock ~167 ~117 ~101 dirt
setblock ~167 ~117 ~102 dirt
setblock ~167 ~117 ~103 dirt
setblock ~167 ~117 ~104 dirt
setblock ~167 ~118 ~84 dirt
setblock ~167 ~118 ~86 dirt
setblock ~167 ~118 ~87 dirt
setblock ~167 ~118 ~88 dirt
setblock ~167 ~118 ~89 dirt
setblock ~167 ~118 ~90 dirt
setblock ~167 ~118 ~91 dirt
setblock ~167 ~118 ~92 dirt
setblock ~167 ~118 ~93 dirt
setblock ~167 ~118 ~94 dirt
setblock ~167 ~118 ~95 dirt
setblock ~167 ~118 ~96 dirt
setblock ~167 ~118 ~97 dirt
setblock ~167 ~118 ~98 dirt
setblock ~167 ~118 ~99 dirt
setblock ~167 ~118 ~100 dirt
setblock ~167 ~118 ~101 dirt
setblock ~167 ~118 ~102 dirt
setblock ~167 ~118 ~103 dirt
setblock ~167 ~118 ~104 dirt
setblock ~167 ~119 ~83 dirt
setblock ~167 ~119 ~84 dirt
setblock ~167 ~119 ~85 dirt
setblock ~167 ~119 ~86 dirt
setblock ~167 ~119 ~87 dirt
setblock ~167 ~119 ~88 dirt
setblock ~167 ~119 ~89 dirt
setblock ~167 ~119 ~90 dirt
setblock ~167 ~119 ~91 dirt
setblock ~167 ~119 ~92 dirt
setblock ~167 ~119 ~93 dirt
setblock ~167 ~119 ~94 dirt
setblock ~167 ~119 ~95 dirt
setblock ~167 ~119 ~96 dirt
setblock ~167 ~119 ~97 dirt
setblock ~167 ~119 ~98 dirt
setblock ~167 ~119 ~99 dirt
setblock ~167 ~119 ~100 dirt
setblock ~167 ~119 ~101 dirt
setblock ~167 ~119 ~102 dirt
setblock ~167 ~119 ~103 dirt
setblock ~167 ~119 ~104 dirt
setblock ~167 ~119 ~105 dirt
setblock ~167 ~120 ~81 dirt
setblock ~167 ~120 ~83 dirt
setblock ~167 ~120 ~84 dirt
setblock ~167 ~120 ~85 dirt
setblock ~167 ~120 ~86 dirt
setblock ~167 ~120 ~87 dirt
setblock ~167 ~120 ~88 dirt
setblock ~167 ~120 ~89 dirt
setblock ~167 ~120 ~90 dirt
setblock ~167 ~120 ~91 dirt
setblock ~167 ~120 ~92 dirt
setblock ~167 ~120 ~93 dirt
setblock ~167 ~120 ~94 dirt
setblock ~167 ~120 ~95 dirt
setblock ~167 ~120 ~96 dirt
setblock ~167 ~120 ~97 dirt
setblock ~167 ~120 ~98 dirt
setblock ~167 ~120 ~99 dirt
setblock ~167 ~120 ~100 dirt
setblock ~167 ~120 ~101 dirt
setblock ~167 ~120 ~102 dirt
setblock ~167 ~120 ~103 dirt
setblock ~167 ~120 ~104 dirt
setblock ~167 ~120 ~105 dirt
setblock ~167 ~121 ~81 dirt
setblock ~167 ~121 ~82 dirt
setblock ~167 ~121 ~83 dirt
setblock ~167 ~121 ~84 dirt
setblock ~167 ~121 ~85 dirt
setblock ~167 ~121 ~86 dirt
setblock ~167 ~121 ~87 dirt
setblock ~167 ~121 ~88 dirt
setblock ~167 ~121 ~89 dirt
setblock ~167 ~121 ~90 dirt
setblock ~167 ~121 ~91 dirt
setblock ~167 ~121 ~92 dirt
setblock ~167 ~121 ~93 dirt
setblock ~167 ~121 ~94 dirt
setblock ~167 ~121 ~95 dirt
setblock ~167 ~121 ~96 dirt
setblock ~167 ~121 ~97 dirt
setblock ~167 ~121 ~98 dirt
setblock ~167 ~121 ~99 dirt
setblock ~167 ~121 ~100 dirt
setblock ~167 ~121 ~101 dirt
setblock ~167 ~121 ~102 dirt
setblock ~167 ~121 ~103 dirt
setblock ~167 ~121 ~104 dirt
setblock ~167 ~121 ~105 dirt
setblock ~167 ~121 ~108 dirt
setblock ~167 ~122 ~81 dirt
setblock ~167 ~122 ~82 dirt
setblock ~167 ~122 ~83 dirt
setblock ~167 ~122 ~84 dirt
setblock ~167 ~122 ~85 dirt
setblock ~167 ~122 ~86 dirt
setblock ~167 ~122 ~87 dirt
setblock ~167 ~122 ~88 dirt
setblock ~167 ~122 ~89 dirt
setblock ~167 ~122 ~90 dirt
setblock ~167 ~122 ~91 dirt
setblock ~167 ~122 ~92 dirt
setblock ~167 ~122 ~93 dirt
setblock ~167 ~122 ~94 dirt
setblock ~167 ~122 ~95 dirt
setblock ~167 ~122 ~96 dirt
setblock ~167 ~122 ~97 dirt
setblock ~167 ~122 ~98 dirt
setblock ~167 ~122 ~99 dirt
setblock ~167 ~122 ~100 dirt
setblock ~167 ~122 ~101 dirt
setblock ~167 ~122 ~102 dirt
setblock ~167 ~122 ~103 dirt
setblock ~167 ~122 ~104 dirt
setblock ~167 ~122 ~105 dirt
setblock ~167 ~122 ~108 dirt
setblock ~167 ~123 ~81 dirt
setblock ~167 ~123 ~82 dirt
setblock ~167 ~123 ~83 dirt
setblock ~167 ~123 ~84 dirt
setblock ~167 ~123 ~85 dirt
setblock ~167 ~123 ~86 dirt
setblock ~167 ~123 ~87 dirt
setblock ~167 ~123 ~88 dirt
setblock ~167 ~123 ~89 dirt
setblock ~167 ~123 ~90 dirt
setblock ~167 ~123 ~91 dirt
setblock ~167 ~123 ~92 dirt
setblock ~167 ~123 ~93 dirt
setblock ~167 ~123 ~94 dirt
setblock ~167 ~123 ~95 dirt
setblock ~167 ~123 ~96 dirt
setblock ~167 ~123 ~97 dirt
setblock ~167 ~123 ~98 dirt
setblock ~167 ~123 ~99 dirt
setblock ~167 ~123 ~100 dirt
setblock ~167 ~123 ~101 dirt
setblock ~167 ~123 ~102 dirt
setblock ~167 ~123 ~103 dirt
setblock ~167 ~123 ~104 dirt
setblock ~167 ~123 ~105 grass_block
setblock ~167 ~123 ~108 grass_block
setblock ~167 ~124 ~81 dirt
setblock ~167 ~124 ~82 dirt
setblock ~167 ~124 ~83 dirt
setblock ~167 ~124 ~84 dirt
setblock ~167 ~124 ~85 dirt
setblock ~167 ~124 ~86 dirt
setblock ~167 ~124 ~87 dirt
setblock ~167 ~124 ~88 dirt
setblock ~167 ~124 ~89 dirt
setblock ~167 ~124 ~90 dirt
setblock ~167 ~124 ~91 dirt
setblock ~167 ~124 ~92 dirt
setblock ~167 ~124 ~93 dirt
setblock ~167 ~124 ~94 dirt
setblock ~167 ~124 ~95 dirt
setblock ~167 ~124 ~96 dirt
setblock ~167 ~124 ~97 dirt
setblock ~167 ~124 ~98 dirt
setblock ~167 ~124 ~99 dirt
setblock ~167 ~124 ~100 grass_block
setblock ~167 ~124 ~101 grass_block
setblock ~167 ~124 ~102 grass_block
setblock ~167 ~124 ~103 grass_block
setblock ~167 ~124 ~104 grass_block
setblock ~167 ~125 ~81 grass_block
setblock ~167 ~125 ~82 grass_block
setblock ~167 ~125 ~83 grass_block
setblock ~167 ~125 ~84 grass_block
setblock ~167 ~125 ~85 dirt
setblock ~167 ~125 ~86 dirt
setblock ~167 ~125 ~87 dirt
setblock ~167 ~125 ~88 dirt
setblock ~167 ~125 ~89 dirt
setblock ~167 ~125 ~90 dirt
setblock ~167 ~125 ~91 dirt
setblock ~167 ~125 ~92 dirt
setblock ~167 ~125 ~93 grass_block
setblock ~167 ~125 ~94 grass_block
setblock ~167 ~125 ~95 grass_block
setblock ~167 ~125 ~96 grass_block
setblock ~167 ~125 ~97 grass_block
setblock ~167 ~125 ~98 grass_block
setblock ~167 ~125 ~99 grass_block
setblock ~167 ~125 ~101 fern
setblock ~167 ~125 ~102 fern
setblock ~167 ~126 ~83 short_grass
setblock ~167 ~126 ~85 grass_block
setblock ~167 ~126 ~86 grass_block
setblock ~167 ~126 ~87 grass_block
setblock ~167 ~126 ~88 grass_block
setblock ~167 ~126 ~89 grass_block
setblock ~167 ~126 ~90 grass_block
setblock ~167 ~126 ~91 grass_block
setblock ~167 ~126 ~92 grass_block
setblock ~167 ~126 ~93 short_grass
setblock ~167 ~126 ~95 short_grass
setblock ~167 ~126 ~99 short_grass
setblock ~167 ~127 ~90 short_grass
setblock ~168 ~113 ~93 dirt
setblock ~168 ~113 ~94 dirt
setblock ~168 ~113 ~95 dirt
setblock ~168 ~114 ~91 dirt
setblock ~168 ~114 ~92 dirt
setblock ~168 ~114 ~93 dirt
setblock ~168 ~114 ~94 dirt
setblock ~168 ~114 ~95 dirt
setblock ~168 ~114 ~96 dirt
setblock ~168 ~115 ~91 dirt
setblock ~168 ~115 ~92 dirt
setblock ~168 ~115 ~93 dirt
setblock ~168 ~115 ~94 dirt
setblock ~168 ~115 ~95 dirt
setblock ~168 ~115 ~96 dirt
setblock ~168 ~115 ~97 dirt
setblock ~168 ~116 ~91 dirt
setblock ~168 ~116 ~92 dirt
setblock ~168 ~116 ~93 dirt
setblock ~168 ~116 ~94 dirt
setblock ~168 ~116 ~95 dirt
setblock ~168 ~116 ~96 dirt
setblock ~168 ~116 ~97 dirt
setblock ~168 ~116 ~99 dirt
setblock ~168 ~116 ~100 dirt
setblock ~168 ~117 ~89 dirt
setblock ~168 ~117 ~90 dirt
setblock ~168 ~117 ~91 dirt
setblock ~168 ~117 ~92 dirt
setblock ~168 ~117 ~93 dirt
setblock ~168 ~117 ~94 dirt
setblock ~168 ~117 ~95 dirt
setblock ~168 ~117 ~96 dirt
setblock ~168 ~117 ~97 dirt
setblock ~168 ~117 ~98 dirt
setblock ~168 ~117 ~99 dirt
setblock ~168 ~117 ~100 dirt
setblock ~168 ~117 ~101 dirt
setblock ~168 ~117 ~103 dirt
setblock ~168 ~118 ~87 dirt
setblock ~168 ~118 ~89 dirt
setblock ~168 ~118 ~90 dirt
setblock ~168 ~118 ~91 dirt
setblock ~168 ~118 ~92 dirt
setblock ~168 ~118 ~93 dirt
setblock ~168 ~118 ~94 dirt
setblock ~168 ~118 ~95 dirt
setblock ~168 ~118 ~96 dirt
setblock ~168 ~118 ~97 dirt
setblock ~168 ~118 ~98 dirt
setblock ~168 ~118 ~99 dirt
setblock ~168 ~118 ~100 dirt
setblock ~168 ~118 ~101 dirt
setblock ~168 ~118 ~103 dirt
setblock ~168 ~119 ~84 dirt
setblock ~168 ~119 ~86 dirt
setblock ~168 ~119 ~87 dirt
setblock ~168 ~119 ~88 dirt
setblock ~168 ~119 ~89 dirt
setblock ~168 ~119 ~90 dirt
setblock ~168 ~119 ~91 dirt
setblock ~168 ~119 ~92 dirt
setblock ~168 ~119 ~93 dirt
setblock ~168 ~119 ~94 dirt
setblock ~168 ~119 ~95 dirt
setblock ~168 ~119 ~96 dirt
setblock ~168 ~119 ~97 dirt
setblock ~168 ~119 ~98 dirt
setblock ~168 ~119 ~99 dirt
setblock ~168 ~119 ~100 dirt
setblock ~168 ~119 ~101 dirt
setblock ~168 ~119 ~102 dirt
setblock ~168 ~119 ~103 dirt
setblock ~168 ~119 ~104 dirt
setblock ~168 ~120 ~84 dirt
setblock ~168 ~120 ~86 dirt
setblock ~168 ~120 ~87 dirt
setblock ~168 ~120 ~88 dirt
setblock ~168 ~120 ~89 dirt
setblock ~168 ~120 ~90 dirt
setblock ~168 ~120 ~91 dirt
setblock ~168 ~120 ~92 dirt
setblock ~168 ~120 ~93 dirt
setblock ~168 ~120 ~94 dirt
setblock ~168 ~120 ~95 dirt
setblock ~168 ~120 ~96 dirt
setblock ~168 ~120 ~97 dirt
setblock ~168 ~120 ~98 dirt
setblock ~168 ~120 ~99 dirt
setblock ~168 ~120 ~100 dirt
setblock ~168 ~120 ~101 dirt
setblock ~168 ~120 ~102 dirt
setblock ~168 ~120 ~103 dirt
setblock ~168 ~120 ~104 dirt
setblock ~168 ~121 ~84 dirt
setblock ~168 ~121 ~85 dirt
setblock ~168 ~121 ~86 dirt
setblock ~168 ~121 ~87 dirt
setblock ~168 ~121 ~88 dirt
setblock ~168 ~121 ~89 dirt
setblock ~168 ~121 ~90 dirt
setblock ~168 ~121 ~91 dirt
setblock ~168 ~121 ~92 dirt
setblock ~168 ~121 ~93 dirt
setblock ~168 ~121 ~94 dirt
setblock ~168 ~121 ~95 dirt
setblock ~168 ~121 ~96 dirt
setblock ~168 ~121 ~97 dirt
setblock ~168 ~121 ~98 dirt
setblock ~168 ~121 ~99 dirt
setblock ~168 ~121 ~100 dirt
setblock ~168 ~121 ~101 dirt
setblock ~168 ~121 ~102 dirt
setblock ~168 ~121 ~103 dirt
setblock ~168 ~121 ~104 dirt
setblock ~168 ~122 ~84 dirt
setblock ~168 ~122 ~85 dirt
setblock ~168 ~122 ~86 dirt
setblock ~168 ~122 ~87 dirt
setblock ~168 ~122 ~88 dirt
setblock ~168 ~122 ~89 dirt
setblock ~168 ~122 ~90 dirt
setblock ~168 ~122 ~91 dirt
setblock ~168 ~122 ~92 dirt
setblock ~168 ~122 ~93 dirt
setblock ~168 ~122 ~94 dirt
setblock ~168 ~122 ~95 dirt
setblock ~168 ~122 ~96 dirt
setblock ~168 ~122 ~97 dirt
setblock ~168 ~122 ~98 dirt
setblock ~168 ~122 ~99 dirt
setblock ~168 ~122 ~100 dirt
setblock ~168 ~122 ~101 dirt
setblock ~168 ~122 ~102 dirt
setblock ~168 ~122 ~103 dirt
setblock ~168 ~122 ~104 dirt
setblock ~168 ~123 ~84 dirt
setblock ~168 ~123 ~85 dirt
setblock ~168 ~123 ~86 dirt
setblock ~168 ~123 ~87 dirt
setblock ~168 ~123 ~88 dirt
setblock ~168 ~123 ~89 dirt
setblock ~168 ~123 ~90 dirt
setblock ~168 ~123 ~91 dirt
setblock ~168 ~123 ~92 dirt
setblock ~168 ~123 ~93 dirt
setblock ~168 ~123 ~94 dirt
setblock ~168 ~123 ~95 dirt
setblock ~168 ~123 ~96 dirt
setblock ~168 ~123 ~97 dirt
setblock ~168 ~123 ~98 dirt
setblock ~168 ~123 ~99 dirt
setblock ~168 ~123 ~100 dirt
setblock ~168 ~123 ~101 dirt
setblock ~168 ~123 ~102 dirt
setblock ~168 ~123 ~103 dirt
setblock ~168 ~123 ~104 dirt
setblock ~168 ~124 ~84 dirt
setblock ~168 ~124 ~85 dirt
setblock ~168 ~124 ~86 dirt
setblock ~168 ~124 ~87 dirt
setblock ~168 ~124 ~88 dirt
setblock ~168 ~124 ~89 dirt
setblock ~168 ~124 ~90 dirt
setblock ~168 ~124 ~91 dirt
setblock ~168 ~124 ~92 dirt
setblock ~168 ~124 ~93 dirt
setblock ~168 ~124 ~94 dirt
setblock ~168 ~124 ~95 dirt
setblock ~168 ~124 ~96 dirt
setblock ~168 ~124 ~97 dirt
setblock ~168 ~124 ~98 dirt
setblock ~168 ~124 ~99 grass_block
setblock ~168 ~124 ~100 grass_block
setblock ~168 ~124 ~101 grass_block
setblock ~168 ~124 ~102 grass_block
setblock ~168 ~124 ~103 grass_block
setblock ~168 ~124 ~104 grass_block
setblock ~168 ~125 ~84 grass_block
setblock ~168 ~125 ~85 grass_block
setblock ~168 ~125 ~86 dirt
setblock ~168 ~125 ~87 dirt
setblock ~168 ~125 ~88 dirt
setblock ~168 ~125 ~89 dirt
setblock ~168 ~125 ~90 dirt
setblock ~168 ~125 ~91 dirt
setblock ~168 ~125 ~92 dirt
setblock ~168 ~125 ~93 dirt
setblock ~168 ~125 ~94 grass_block
setblock ~168 ~125 ~95 grass_block
setblock ~168 ~125 ~96 grass_block
setblock ~168 ~125 ~97 grass_block
setblock ~168 ~125 ~98 grass_block
setblock ~168 ~125 ~102 short_grass
setblock ~168 ~125 ~104 fern
setblock ~168 ~126 ~85 short_grass
setblock ~168 ~126 ~86 grass_block
setblock ~168 ~126 ~87 grass_block
setblock ~168 ~126 ~88 grass_block
setblock ~168 ~126 ~89 grass_block
setblock ~168 ~126 ~90 grass_block
setblock ~168 ~126 ~91 grass_block
setblock ~168 ~126 ~92 grass_block
setblock ~168 ~126 ~93 grass_block
setblock ~168 ~126 ~95 poppy
setblock ~168 ~127 ~86 short_grass
setblock ~168 ~127 ~90 fern
setblock ~169 ~115 ~93 dirt
setblock ~169 ~115 ~95 dirt
setblock ~169 ~115 ~96 dirt
setblock ~169 ~116 ~92 dirt
setblock ~169 ~116 ~93 dirt
setblock ~169 ~116 ~94 dirt
setblock ~169 ~116 ~95 dirt
setblock ~169 ~116 ~96 dirt
setblock ~169 ~116 ~97 dirt
setblock ~169 ~117 ~91 dirt
setblock ~169 ~117 ~92 dirt
setblock ~169 ~117 ~93 dirt
setblock ~169 ~117 ~94 dirt
setblock ~169 ~117 ~95 dirt
setblock ~169 ~117 ~96 dirt
setblock ~169 ~117 ~97 dirt
setblock ~169 ~117 ~99 dirt
setblock ~169 ~118 ~90 dirt
setblock ~169 ~118 ~91 dirt
setblock ~169 ~118 ~92 dirt
setblock ~169 ~118 ~93 dirt
setblock ~169 ~118 ~94 dirt
setblock ~169 ~118 ~95 dirt
setblock ~169 ~118 ~96 dirt
setblock ~169 ~118 ~97 dirt
setblock ~169 ~118 ~99 dirt
setblock ~169 ~118 ~100 dirt
setblock ~169 ~119 ~89 dirt
setblock ~169 ~119 ~90 dirt
setblock ~169 ~119 ~91 dirt
setblock ~169 ~119 ~92 dirt
setblock ~169 ~119 ~93 dirt
setblock ~169 ~119 ~94 dirt
setblock ~169 ~119 ~95 dirt
setblock ~169 ~119 ~96 dirt
setblock ~169 ~119 ~97 dirt
setblock ~169 ~119 ~98 dirt
setblock ~169 ~119 ~99 dirt
setblock ~169 ~119 ~100 dirt
setblock ~169 ~120 ~89 dirt
setblock ~169 ~120 ~90 dirt
setblock ~169 ~120 ~91 dirt
setblock ~169 ~120 ~92 dirt
setblock ~169 ~120 ~93 dirt
setblock ~169 ~120 ~94 dirt
setblock ~169 ~120 ~95 dirt
setblock ~169 ~120 ~96 dirt
setblock ~169 ~120 ~97 dirt
setblock ~169 ~120 ~98 dirt
setblock ~169 ~120 ~99 dirt
setblock ~169 ~120 ~100 dirt
setblock ~169 ~120 ~101 dirt
setblock ~169 ~120 ~103 dirt
setblock ~169 ~121 ~87 dirt
setblock ~169 ~121 ~89 dirt
setblock ~169 ~121 ~90 dirt
setblock ~169 ~121 ~91 dirt
setblock ~169 ~121 ~92 dirt
setblock ~169 ~121 ~93 dirt
setblock ~169 ~121 ~94 dirt
setblock ~169 ~121 ~95 dirt
setblock ~169 ~121 ~96 dirt
setblock ~169 ~121 ~97 dirt
setblock ~169 ~121 ~98 dirt
setblock ~169 ~121 ~99 dirt
setblock ~169 ~121 ~100 dirt
setblock ~169 ~121 ~101 dirt
setblock ~169 ~121 ~102 dirt
setblock ~169 ~121 ~103 dirt
setblock ~169 ~121 ~104 dirt
setblock ~169 ~122 ~87 dirt
setblock ~169 ~122 ~89 dirt
setblock ~169 ~122 ~90 dirt
setblock ~169 ~122 ~91 dirt
setblock ~169 ~122 ~92 dirt
setblock ~169 ~122 ~93 dirt
setblock ~169 ~122 ~94 dirt
setblock ~169 ~122 ~95 dirt
setblock ~169 ~122 ~96 dirt
setblock ~169 ~122 ~97 dirt
setblock ~169 ~122 ~98 dirt
setblock ~169 ~122 ~99 dirt
setblock ~169 ~122 ~100 dirt
setblock ~169 ~122 ~101 dirt
setblock ~169 ~122 ~102 dirt
setblock ~169 ~122 ~103 dirt
setblock ~169 ~122 ~104 dirt
setblock ~169 ~123 ~87 dirt
setblock ~169 ~123 ~89 dirt
setblock ~169 ~123 ~90 dirt
setblock ~169 ~123 ~91 dirt
setblock ~169 ~123 ~92 dirt
setblock ~169 ~123 ~93 dirt
setblock ~169 ~123 ~94 dirt
setblock ~169 ~123 ~95 dirt
setblock ~169 ~123 ~96 dirt
setblock ~169 ~123 ~97 dirt
setblock ~169 ~123 ~98 dirt
setblock ~169 ~123 ~99 dirt
setblock ~169 ~123 ~100 dirt
setblock ~169 ~123 ~101 dirt
setblock ~169 ~123 ~102 dirt
setblock ~169 ~123 ~103 dirt
setblock ~169 ~123 ~104 dirt
setblock ~169 ~124 ~87 dirt
setblock ~169 ~124 ~89 dirt
setblock ~169 ~124 ~90 dirt
setblock ~169 ~124 ~91 dirt
setblock ~169 ~124 ~92 dirt
setblock ~169 ~124 ~93 dirt
setblock ~169 ~124 ~94 dirt
setblock ~169 ~124 ~95 dirt
setblock ~169 ~124 ~96 dirt
setblock ~169 ~124 ~97 dirt
setblock ~169 ~124 ~98 dirt
setblock ~169 ~124 ~99 grass_block
setblock ~169 ~124 ~100 grass_block
setblock ~169 ~124 ~101 grass_block
setblock ~169 ~124 ~102 grass_block
setblock ~169 ~124 ~103 grass_block
setblock ~169 ~124 ~104 grass_block
setblock ~169 ~125 ~87 dirt
setblock ~169 ~125 ~89 dirt
setblock ~169 ~125 ~90 dirt
setblock ~169 ~125 ~91 dirt
setblock ~169 ~125 ~92 dirt
setblock ~169 ~125 ~93 dirt
setblock ~169 ~125 ~94 grass_block
setblock ~169 ~125 ~95 grass_block
setblock ~169 ~125 ~96 grass_block
setblock ~169 ~125 ~97 grass_block
setblock ~169 ~125 ~98 grass_block
setblock ~169 ~125 ~104 poppy
setblock ~169 ~126 ~87 grass_block
setblock ~169 ~126 ~89 grass_block
setblock ~169 ~126 ~90 grass_block
setblock ~169 ~126 ~91 grass_block
setblock ~169 ~126 ~92 grass_block
setblock ~169 ~126 ~93 grass_block
setblock ~169 ~126 ~98 short_grass
setblock ~169 ~127 ~93 fern
setblock ~170 ~116 ~95 dirt
setblock ~170 ~116 ~96 dirt
setblock ~170 ~117 ~93 dirt
setblock ~170 ~117 ~95 dirt
setblock ~170 ~117 ~96 dirt
setblock ~170 ~118 ~92 dirt
setblock ~170 ~118 ~93 dirt
setblock ~170 ~118 ~94 dirt
setblock ~170 ~118 ~95 dirt
setblock ~170 ~118 ~96 dirt
setblock ~170 ~119 ~91 dirt
setblock ~170 ~119 ~92 dirt
setblock ~170 ~119 ~93 dirt
setblock ~170 ~119 ~94 dirt
setblock ~170 ~119 ~95 dirt
setblock ~170 ~119 ~96 dirt
setblock ~170 ~119 ~99 dirt
setblock ~170 ~120 ~90 dirt
setblock ~170 ~120 ~91 dirt
setblock ~170 ~120 ~92 dirt
setblock ~170 ~120 ~93 dirt
setblock ~170 ~120 ~94 dirt
setblock ~170 ~120 ~95 dirt
setblock ~170 ~120 ~96 dirt
setblock ~170 ~120 ~97 dirt
setblock ~170 ~120 ~99 dirt
setblock ~170 ~121 ~89 dirt
setblock ~170 ~121 ~90 dirt
setblock ~170 ~121 ~91 dirt
setblock ~170 ~121 ~92 dirt
setblock ~170 ~121 ~93 dirt
setblock ~170 ~121 ~94 dirt
setblock ~170 ~121 ~95 dirt
setblock ~170 ~121 ~96 dirt
setblock ~170 ~121 ~97 dirt
setblock ~170 ~121 ~98 dirt
setblock ~170 ~121 ~99 dirt
setblock ~170 ~121 ~103 dirt
setblock ~170 ~122 ~89 dirt
setblock ~170 ~122 ~90 dirt
setblock ~170 ~122 ~91 dirt
setblock ~170 ~122 ~92 dirt
setblock ~170 ~122 ~93 dirt
setblock ~170 ~122 ~94 dirt
setblock ~170 ~122 ~95 dirt
setblock ~170 ~122 ~96 dirt
setblock ~170 ~122 ~97 dirt
setblock ~170 ~122 ~98 dirt
setblock ~170 ~122 ~99 dirt
setblock ~170 ~122 ~103 dirt
setblock ~170 ~123 ~89 dirt
setblock ~170 ~123 ~90 dirt
setblock ~170 ~123 ~91 dirt
setblock ~170 ~123 ~92 dirt
setblock ~170 ~123 ~93 dirt
setblock ~170 ~123 ~94 dirt
setblock ~170 ~123 ~95 dirt
setblock ~170 ~123 ~96 dirt
setblock ~170 ~123 ~97 dirt
setblock ~170 ~123 ~98 dirt
setblock ~170 ~123 ~99 dirt
setblock ~170 ~123 ~103 dirt
setblock ~170 ~124 ~89 dirt
setblock ~170 ~124 ~90 dirt
setblock ~170 ~124 ~91 dirt
setblock ~170 ~124 ~92 dirt
setblock ~170 ~124 ~93 dirt
setblock ~170 ~124 ~94 dirt
setblock ~170 ~124 ~95 dirt
setblock ~170 ~124 ~96 dirt
setblock ~170 ~124 ~97 dirt
setblock ~170 ~124 ~98 grass_block
setblock ~170 ~124 ~99 grass_block
setblock ~170 ~124 ~103 grass_block
setblock ~170 ~125 ~89 dirt
setblock ~170 ~125 ~90 dirt
setblock ~170 ~125 ~91 dirt
setblock ~170 ~125 ~92 dirt
setblock ~170 ~125 ~93 dirt
setblock ~170 ~125 ~94 dirt
setblock ~170 ~125 ~95 grass_block
setblock ~170 ~125 ~96 grass_block
setblock ~170 ~125 ~97 grass_block
setblock ~170 ~125 ~99 fern
setblock ~170 ~126 ~89 grass_block
setblock ~170 ~126 ~90 grass_block
setblock ~170 ~126 ~91 grass_block
setblock ~170 ~126 ~92 grass_block
setblock ~170 ~126 ~93 grass_block
setblock ~170 ~126 ~94 grass_block
setblock ~170 ~127 ~91 poppy
setblock ~171 ~119 ~92 dirt
setblock ~171 ~119 ~93 dirt
setblock ~171 ~119 ~94 dirt
setblock ~171 ~119 ~95 dirt
setblock ~171 ~120 ~91 dirt
setblock ~171 ~120 ~92 dirt
setblock ~171 ~120 ~93 dirt
setblock ~171 ~120 ~94 dirt
setblock ~171 ~120 ~95 dirt
setblock ~171 ~120 ~96 dirt
setblock ~171 ~121 ~90 dirt
setblock ~171 ~121 ~91 dirt
setblock ~171 ~121 ~92 dirt
setblock ~171 ~121 ~93 dirt
setblock ~171 ~121 ~94 dirt
setblock ~171 ~121 ~95 dirt
setblock ~171 ~121 ~96 dirt
setblock ~171 ~121 ~97 dirt
setblock ~171 ~122 ~90 dirt
setblock ~171 ~122 ~91 dirt
setblock ~171 ~122 ~92 dirt
setblock ~171 ~122 ~93 dirt
setblock ~171 ~122 ~94 dirt
setblock ~171 ~122 ~95 dirt
setblock ~171 ~122 ~96 dirt
setblock ~171 ~122 ~97 dirt
setblock ~171 ~123 ~90 dirt
setblock ~171 ~123 ~91 dirt
setblock ~171 ~123 ~92 dirt
setblock ~171 ~123 ~93 dirt
setblock ~171 ~123 ~94 dirt
setblock ~171 ~123 ~95 dirt
setblock ~171 ~123 ~96 dirt
setblock ~171 ~123 ~97 dirt
setblock ~171 ~124 ~90 dirt
setblock ~171 ~124 ~91 dirt
setblock ~171 ~124 ~92 dirt
setblock ~171 ~124 ~93 dirt
setblock ~171 ~124 ~94 dirt
setblock ~171 ~124 ~95 dirt
setblock ~171 ~124 ~96 dirt
setblock ~171 ~124 ~97 dirt
setblock ~171 ~125 ~90 dirt
setblock ~171 ~125 ~91 dirt
setblock ~171 ~125 ~92 dirt
setblock ~171 ~125 ~93 dirt
setblock ~171 ~125 ~94 dirt
setblock ~171 ~125 ~95 grass_block
setblock ~171 ~125 ~96 grass_block
setblock ~171 ~125 ~97 grass_block
setblock ~171 ~126 ~90 grass_block
setblock ~171 ~126 ~91 grass_block
setblock ~171 ~126 ~92 grass_block
setblock ~171 ~126 ~93 grass_block
setblock ~171 ~126 ~94 grass_block
setblock ~171 ~127 ~91 short_grass
setblock ~171 ~127 ~94 short_grass
setblock ~172 ~121 ~94 dirt
setblock ~172 ~121 ~96 dirt
setblock ~172 ~122 ~94 dirt
setblock ~172 ~122 ~96 dirt
setblock ~172 ~123 ~94 dirt
setblock ~172 ~123 ~96 dirt
setblock ~172 ~124 ~94 dirt
setblock ~172 ~124 ~96 dirt
setblock ~172 ~125 ~94 dirt
setblock ~172 ~125 ~96 grass_block
setblock ~172 ~126 ~94 grass_block
setblock ~199 ~200 ~199 gold_block
