setblock ~178 ~123 ~145 grass_block
setblock ~178 ~123 ~146 grass_block
setblock ~178 ~124 ~53 dirt
setblock ~178 ~124 ~54 dirt
setblock ~178 ~124 ~55 dirt
setblock ~178 ~124 ~56 dirt
setblock ~178 ~124 ~57 dirt
setblock ~178 ~124 ~58 dirt
setblock ~178 ~124 ~59 dirt
setblock ~178 ~124 ~60 dirt
setblock ~178 ~124 ~61 dirt
setblock ~178 ~124 ~62 dirt
setblock ~178 ~124 ~63 dirt
setblock ~178 ~124 ~64 dirt
setblock ~178 ~124 ~65 dirt
setblock ~178 ~124 ~66 dirt
setblock ~178 ~124 ~67 dirt
setblock ~178 ~124 ~68 dirt
setblock ~178 ~124 ~69 grass_block
setblock ~178 ~124 ~70 grass_block
setblock ~178 ~124 ~71 grass_block
setblock ~178 ~124 ~72 grass_block
setblock ~178 ~124 ~85 fern
setblock ~178 ~124 ~89 short_grass
setblock ~178 ~124 ~91 grass_block
setblock ~178 ~124 ~92 grass_block
setblock ~178 ~124 ~93 dirt
setblock ~178 ~124 ~94 dirt
setblock ~178 ~124 ~95 dirt
setblock ~178 ~124 ~96 dirt
setblock ~178 ~124 ~97 dirt
setblock ~178 ~124 ~98 dirt
setblock ~178 ~124 ~99 dirt
setblock ~178 ~124 ~100 dirt
setblock ~178 ~124 ~101 dirt
setblock ~178 ~124 ~102 dirt
setblock ~178 ~124 ~103 dirt
setblock ~178 ~124 ~104 dirt
setblock ~178 ~124 ~105 dirt
setblock ~178 ~124 ~106 dirt
setblock ~178 ~124 ~107 dirt
setblock ~178 ~124 ~108 grass_block
setblock ~178 ~124 ~109 grass_block
setblock ~178 ~124 ~110 grass_block
setblock ~178 ~124 ~111 grass_block
setblock ~178 ~124 ~112 grass_block
setblock ~178 ~124 ~113 dirt
setblock ~178 ~124 ~114 dirt
setblock ~178 ~124 ~115 dirt
setblock ~178 ~124 ~116 dirt
setblock ~178 ~124 ~117 dirt
setblock ~178 ~124 ~118 dirt
setblock ~178 ~124 ~119 dirt
setblock ~178 ~124 ~120 dirt
setblock ~178 ~124 ~121 dirt
setblock ~178 ~124 ~122 dirt
setblock ~178 ~124 ~123 dirt
setblock ~178 ~124 ~124 dirt
setblock ~178 ~124 ~125 dirt
setblock ~178 ~124 ~126 dirt
setblock ~178 ~124 ~127 dirt
setblock ~178 ~124 ~128 dirt
setblock ~178 ~124 ~129 dirt
setblock ~178 ~124 ~130 grass_block
setblock ~178 ~124 ~131 grass_block
setblock ~178 ~124 ~146 short_grass
setblock ~178 ~125 ~53 dirt
setblock ~178 ~125 ~54 dirt
setblock ~178 ~125 ~55 dirt
setblock ~178 ~125 ~56 dirt
setblock ~178 ~125 ~57 dirt
setblock ~178 ~125 ~58 dirt
setblock ~178 ~125 ~59 dirt
setblock ~178 ~125 ~60 dirt
setblock ~178 ~125 ~61 dirt
setblock ~178 ~125 ~62 dirt
setblock ~178 ~125 ~63 dirt
setblock ~178 ~125 ~64 dirt
setblock ~178 ~125 ~65 dirt
setblock ~178 ~125 ~66 dirt
setblock ~178 ~125 ~67 grass_block
setblock ~178 ~125 ~68 grass_block
setblock ~178 ~125 ~70 fern
setblock ~178 ~125 ~72 poppy
setblock ~178 ~125 ~93 grass_block
setblock ~178 ~125 ~94 grass_block
setblock ~178 ~125 ~95 dirt
setblock ~178 ~125 ~96 dirt
setblock ~178 ~125 ~97 dirt
setblock ~178 ~125 ~98 dirt
setblock ~178 ~125 ~99 dirt
setblock ~178 ~125 ~100 dirt
setblock ~178 ~125 ~101 dirt
setblock ~178 ~125 ~102 dirt
setblock ~178 ~125 ~103 dirt
setblock ~178 ~125 ~104 dirt
setblock ~178 ~125 ~105 dirt
setblock ~178 ~125 ~106 grass_block
setblock ~178 ~125 ~107 grass_block
setblock ~178 ~125 ~108 short_grass
setblock ~178 ~125 ~113 grass_block
setblock ~178 ~125 ~114 grass_block
setblock ~178 ~125 ~115 dirt
setblock ~178 ~125 ~116 dirt
setblock ~178 ~125 ~117 dirt
setblock ~178 ~125 ~118 dirt
setblock ~178 ~125 ~119 dirt
setblock ~178 ~125 ~120 dirt
setblock ~178 ~125 ~121 dirt
setblock ~178 ~125 ~122 dirt
setblock ~178 ~125 ~123 dirt
setblock ~178 ~125 ~124 dirt
setblock ~178 ~125 ~125 dirt
setblock ~178 ~125 ~126 dirt
setblock ~178 ~125 ~127 grass_block
setblock ~178 ~125 ~128 grass_block
setblock ~178 ~125 ~129 grass_block
setblock ~178 ~126 ~53 dirt
setblock ~178 ~126 ~54 dirt
setblock ~178 ~126 ~55 dirt
setblock ~178 ~126 ~56 dirt
setblock ~178 ~126 ~57 dirt
setblock ~178 ~126 ~58 dirt
setblock ~178 ~126 ~59 dirt
setblock ~178 ~126 ~60 dirt
setblock ~178 ~126 ~61 dirt
setblock ~178 ~126 ~62 dirt
setblock ~178 ~126 ~63 dirt
setblock ~178 ~126 ~64 dirt
setblock ~178 ~126 ~65 grass_block
setblock ~178 ~126 ~66 grass_block
setblock ~178 ~126 ~68 short_grass
setblock ~178 ~126 ~93 short_grass
setblock ~178 ~126 ~95 grass_block
setblock ~178 ~126 ~96 grass_block
setblock ~178 ~126 ~97 grass_block
setblock ~178 ~126 ~98 grass_block
setblock ~178 ~126 ~99 dirt
setblock ~178 ~126 ~100 dirt
setblock ~178 ~126 ~101 dirt
setblock ~178 ~126 ~102 grass_block
setblock ~178 ~126 ~103 grass_block
setblock ~178 ~126 ~104 grass_block
setblock ~178 ~126 ~105 grass_block
setblock ~178 ~126 ~106 poppy
setblock ~178 ~126 ~113 short_grass
setblock ~178 ~126 ~115 grass_block
setblock ~178 ~126 ~116 grass_block
setblock ~178 ~126 ~117 grass_block
setblock ~178 ~126 ~118 dirt
setblock ~178 ~126 ~119 dirt
setblock ~178 ~126 ~120 dirt
setblock ~178 ~126 ~121 dirt
setblock ~178 ~126 ~122 dirt
setblock ~178 ~126 ~123 dirt
setblock ~178 ~126 ~124 grass_block
setblock ~178 ~126 ~125 grass_block
setblock ~178 ~126 ~126 grass_block
setblock ~178 ~126 ~129 short_grass
setblock ~178 ~127 ~53 grass_block
setblock ~178 ~127 ~54 grass_block
setblock ~178 ~127 ~55 grass_block
setblock ~178 ~127 ~56 grass_block
setblock ~178 ~127 ~57 dirt
setblock ~178 ~127 ~58 dirt
setblock ~178 ~127 ~59 dirt
setblock ~178 ~127 ~60 dirt
setblock ~178 ~127 ~61 dirt
setblock ~178 ~127 ~62 dirt
setblock ~178 ~127 ~63 grass_block
setblock ~178 ~127 ~64 grass_block
setblock ~178 ~127 ~98 poppy
setblock ~178 ~127 ~99 grass_block
setblock ~178 ~127 ~100 grass_block
setblock ~178 ~127 ~101 grass_block
setblock ~178 ~127 ~105 short_grass
setblock ~178 ~127 ~118 grass_block
setblock ~178 ~127 ~119 grass_block
setblock ~178 ~127 ~120 dirt
setblock ~178 ~127 ~121 grass_block
setblock ~178 ~127 ~122 grass_block
setblock ~178 ~127 ~123 grass_block
setblock ~178 ~128 ~54 short_grass
setblock ~178 ~128 ~57 grass_block
setblock ~178 ~128 ~58 grass_block
setblock ~178 ~128 ~59 grass_block
setblock ~178 ~128 ~60 dirt
setblock ~178 ~128 ~61 grass_block
setblock ~178 ~128 ~62 grass_block
setblock ~178 ~128 ~101 short_grass
setblock ~178 ~128 ~120 grass_block
setblock ~178 ~129 ~59 short_grass
setblock ~178 ~129 ~60 grass_block
setblock ~178 ~129 ~61 short_grass
setblock ~178 ~129 ~120 short_grass
setblock ~179 ~101 ~96 dirt
setblock ~179 ~102 ~96 dirt
setblock ~179 ~103 ~95 dirt
setblock ~179 ~103 ~96 dirt
setblock ~179 ~103 ~97 dirt
setblock ~179 ~104 ~95 dirt
setblock ~179 ~104 ~96 dirt
setblock ~179 ~104 ~97 dirt
setblock ~179 ~104 ~98 dirt
setblock ~179 ~105 ~94 dirt
setblock ~179 ~105 ~95 dirt
setblock ~179 ~105 ~96 dirt
setblock ~179 ~105 ~97 dirt
setblock ~179 ~105 ~98 dirt
setblock ~179 ~105 ~99 dirt
setblock ~179 ~106 ~93 dirt
setblock ~179 ~106 ~94 dirt
setblock ~179 ~106 ~95 dirt
setblock ~179 ~106 ~96 dirt
setblock ~179 ~106 ~97 dirt
setblock ~179 ~106 ~98 dirt
setblock ~179 ~106 ~99 dirt
setblock ~179 ~107 ~93 dirt
setblock ~179 ~107 ~94 dirt
setblock ~179 ~107 ~95 dirt
setblock ~179 ~107 ~96 dirt
setblock ~179 ~107 ~97 dirt
setblock ~179 ~107 ~98 dirt
setblock ~179 ~107 ~99 dirt
setblock ~179 ~107 ~100 dirt
setblock ~179 ~108 ~92 dirt
setblock ~179 ~108 ~93 dirt
setblock ~179 ~108 ~94 dirt
setblock ~179 ~108 ~95 dirt
setblock ~179 ~108 ~96 dirt
setblock ~179 ~108 ~97 dirt
setblock ~179 ~108 ~98 dirt
setblock ~179 ~108 ~99 dirt
setblock ~179 ~108 ~100 dirt
setblock ~179 ~109 ~92 dirt
setblock ~179 ~109 ~93 dirt
setblock ~179 ~109 ~94 dirt
setblock ~179 ~109 ~95 dirt
setblock ~179 ~109 ~96 dirt
setblock ~179 ~109 ~97 dirt
setblock ~179 ~109 ~98 dirt
setblock ~179 ~109 ~99 dirt
setblock ~179 ~109 ~100 dirt
setblock ~179 ~109 ~101 dirt
setblock ~179 ~109 ~106 dirt
setblock ~179 ~110 ~91 dirt
setblock ~179 ~110 ~92 dirt
setblock ~179 ~110 ~93 dirt
setblock ~179 ~110 ~94 dirt
setblock ~179 ~110 ~95 dirt
setblock ~179 ~110 ~96 dirt
setblock ~179 ~110 ~97 dirt
setblock ~179 ~110 ~98 dirt
setblock ~179 ~110 ~99 dirt
setblock ~179 ~110 ~100 dirt
setblock ~179 ~110 ~101 dirt
setblock ~179 ~110 ~103 dirt
setblock ~179 ~110 ~104 dirt
setblock ~179 ~110 ~105 dirt
setblock ~179 ~110 ~106 dirt
setblock ~179 ~110 ~107 dirt
setblock ~179 ~111 ~90 dirt
setblock ~179 ~111 ~91 dirt
setblock ~179 ~111 ~92 dirt
setblock ~179 ~111 ~93 dirt
setblock ~179 ~111 ~94 dirt
setblock ~179 ~111 ~95 dirt
setblock ~179 ~111 ~96 dirt
setblock ~179 ~111 ~97 dirt
setblock ~179 ~111 ~98 dirt
setblock ~179 ~111 ~99 dirt
setblock ~179 ~111 ~100 dirt
setblock ~179 ~111 ~101 dirt
setblock ~179 ~111 ~102 dirt
setblock ~179 ~111 ~103 dirt
setblock ~179 ~111 ~104 dirt
setblock ~179 ~111 ~105 dirt
setblock ~179 ~111 ~106 dirt
setblock ~179 ~111 ~107 dirt
setblock ~179 ~111 ~108 dirt
setblock ~179 ~112 ~89 dirt
setblock ~179 ~112 ~90 dirt
setblock ~179 ~112 ~91 dirt
setblock ~179 ~112 ~92 dirt
setblock ~179 ~112 ~93 dirt
setblock ~179 ~112 ~94 dirt
setblock ~179 ~112 ~95 dirt
setblock ~179 ~112 ~96 dirt
setblock ~179 ~112 ~97 dirt
setblock ~179 ~112 ~98 dirt
setblock ~179 ~112 ~99 dirt
setblock ~179 ~112 ~100 dirt
setblock ~179 ~112 ~101 dirt
setblock ~179 ~112 ~102 dirt
setblock ~179 ~112 ~103 dirt
setblock ~179 ~112 ~104 dirt
setblock ~179 ~112 ~105 dirt
setblock ~179 ~112 ~106 dirt
setblock ~179 ~112 ~107 dirt
setblock ~179 ~112 ~108 dirt
setblock ~179 ~112 ~109 dirt
setblock ~179 ~113 ~88 dirt
setblock ~179 ~113 ~89 dirt
setblock ~179 ~113 ~90 dirt
setblock ~179 ~113 ~91 dirt
setblock ~179 ~113 ~92 dirt
setblock ~179 ~113 ~93 dirt
setblock ~179 ~113 ~94 dirt
setblock ~179 ~113 ~95 dirt
setblock ~179 ~113 ~96 dirt
setblock ~179 ~113 ~97 dirt
setblock ~179 ~113 ~98 dirt
setblock ~179 ~113 ~99 dirt
setblock ~179 ~113 ~100 dirt
setblock ~179 ~113 ~101 dirt
setblock ~179 ~113 ~102 dirt
setblock ~179 ~113 ~103 dirt
setblock ~179 ~113 ~104 dirt
setblock ~179 ~113 ~105 dirt
setblock ~179 ~113 ~106 dirt
setblock ~179 ~113 ~107 dirt
setblock ~179 ~113 ~108 dirt
setblock ~179 ~113 ~109 dirt
setblock ~179 ~113 ~110 dirt
setblock ~179 ~113 ~120 dirt
setblock ~179 ~113 ~121 dirt
setblock ~179 ~114 ~87 dirt
setblock ~179 ~114 ~88 dirt
setblock ~179 ~114 ~89 dirt
setblock ~179 ~114 ~90 dirt
setblock ~179 ~114 ~91 dirt
setblock ~179 ~114 ~92 dirt
setblock ~179 ~114 ~93 dirt
setblock ~179 ~114 ~94 dirt
setblock ~179 ~114 ~95 dirt
setblock ~179 ~114 ~96 dirt
setblock ~179 ~114 ~97 dirt
setblock ~179 ~114 ~98 dirt
setblock ~179 ~114 ~99 dirt
setblock ~179 ~114 ~100 dirt
setblock ~179 ~114 ~101 dirt
setblock ~179 ~114 ~102 dirt
setblock ~179 ~114 ~103 dirt
setblock ~179 ~114 ~104 dirt
setblock ~179 ~114 ~105 dirt
setblock ~179 ~114 ~106 dirt
setblock ~179 ~114 ~107 dirt
setblock ~179 ~114 ~108 dirt
setblock ~179 ~114 ~109 dirt
setblock ~179 ~114 ~110 dirt
setblock ~179 ~114 ~111 dirt
setblock ~179 ~114 ~119 dirt
setblock ~179 ~114 ~120 dirt
setblock ~179 ~114 ~121 dirt
setblock ~179 ~114 ~122 dirt
setblock ~179 ~115 ~86 dirt
setblock ~179 ~115 ~87 dirt
setblock ~179 ~115 ~88 dirt
setblock ~179 ~115 ~89 dirt
setblock ~179 ~115 ~90 dirt
setblock ~179 ~115 ~91 dirt
setblock ~179 ~115 ~92 dirt
setblock ~179 ~115 ~93 dirt
setblock ~179 ~115 ~94 dirt
setblock ~179 ~115 ~95 dirt
setblock ~179 ~115 ~96 dirt
setblock ~179 ~115 ~97 dirt
setblock ~179 ~115 ~98 dirt
setblock ~179 ~115 ~99 dirt
setblock ~179 ~115 ~100 dirt
setblock ~179 ~115 ~101 dirt
setblock ~179 ~115 ~102 dirt
setblock ~179 ~115 ~103 dirt
setblock ~179 ~115 ~104 dirt
setblock ~179 ~115 ~105 dirt
setblock ~179 ~115 ~106 dirt
setblock ~179 ~115 ~107 dirt
setblock ~179 ~115 ~108 dirt
setblock ~179 ~115 ~109 dirt
setblock ~179 ~115 ~110 dirt
setblock ~179 ~115 ~111 dirt
setblock ~179 ~115 ~112 dirt
setblock ~179 ~115 ~118 dirt
setblock ~179 ~115 ~119 dirt
setblock ~179 ~115 ~120 dirt
setblock ~179 ~115 ~121 dirt
setblock ~179 ~115 ~122 dirt
setblock ~179 ~115 ~123 dirt
setblock ~179 ~115 ~124 dirt
setblock ~179 ~116 ~86 dirt
setblock ~179 ~116 ~87 dirt
setblock ~179 ~116 ~88 dirt
setblock ~179 ~116 ~89 dirt
setblock ~179 ~116 ~90 dirt
setblock ~179 ~116 ~91 dirt
setblock ~179 ~116 ~92 dirt
setblock ~179 ~116 ~93 dirt
setblock ~179 ~116 ~94 dirt
setblock ~179 ~116 ~95 dirt
setblock ~179 ~116 ~96 dirt
setblock ~179 ~116 ~97 dirt
setblock ~179 ~116 ~98 dirt
setblock ~179 ~116 ~99 dirt
setblock ~179 ~116 ~100 dirt
setblock ~179 ~116 ~101 dirt
setblock ~179 ~116 ~102 dirt
setblock ~179 ~116 ~103 dirt
setblock ~179 ~116 ~104 dirt
setblock ~179 ~116 ~105 dirt
setblock ~179 ~116 ~106 dirt
setblock ~179 ~116 ~107 dirt
setblock ~179 ~116 ~108 dirt
setblock ~179 ~116 ~109 dirt
setblock ~179 ~116 ~110 dirt
setblock ~179 ~116 ~111 dirt
setblock ~179 ~116 ~112 dirt
setblock ~179 ~116 ~113 dirt
setblock ~179 ~116 ~117 dirt
setblock ~179 ~116 ~118 dirt
setblock ~179 ~116 ~119 dirt
setblock ~179 ~116 ~120 dirt
setblock ~179 ~116 ~121 dirt
setblock ~179 ~116 ~122 dirt
setblock ~179 ~116 ~123 dirt
setblock ~179 ~116 ~124 dirt
setblock ~179 ~116 ~125 dirt
setblock ~179 ~117 ~60 dirt
setblock ~179 ~117 ~61 dirt
setblock ~179 ~117 ~85 dirt
setblock ~179 ~117 ~86 dirt
setblock ~179 ~117 ~87 dirt
setblock ~179 ~117 ~88 dirt
setblock ~179 ~117 ~89 dirt
setblock ~179 ~117 ~90 dirt
setblock ~179 ~117 ~91 dirt
setblock ~179 ~117 ~92 dirt
setblock ~179 ~117 ~93 dirt
setblock ~179 ~117 ~94 dirt
setblock ~179 ~117 ~95 dirt
setblock ~179 ~117 ~96 dirt
setblock ~179 ~117 ~97 dirt
setblock ~179 ~117 ~98 dirt
setblock ~179 ~117 ~99 dirt
setblock ~179 ~117 ~100 dirt
setblock ~179 ~117 ~101 dirt
setblock ~179 ~117 ~102 dirt
setblock ~179 ~117 ~103 dirt
setblock ~179 ~117 ~104 dirt
setblock ~179 ~117 ~105 dirt
setblock ~179 ~117 ~106 dirt
setblock ~179 ~117 ~107 dirt
setblock ~179 ~117 ~108 dirt
setblock ~179 ~117 ~109 dirt
setblock ~179 ~117 ~110 dirt
setblock ~179 ~117 ~111 dirt
setblock ~179 ~117 ~112 dirt
setblock ~179 ~117 ~113 dirt
setblock ~179 ~117 ~116 dirt
setblock ~179 ~117 ~117 dirt
setblock ~179 ~117 ~118 dirt
setblock ~179 ~117 ~119 dirt
setblock ~179 ~117 ~120 dirt
setblock ~179 ~117 ~121 dirt
setblock ~179 ~117 ~122 dirt
setblock ~179 ~117 ~123 dirt
setblock ~179 ~117 ~124 dirt
setblock ~179 ~117 ~125 dirt
setblock ~179 ~117 ~126 dirt
setblock ~179 ~118 ~57 dirt
setblock ~179 ~118 ~58 dirt
setblock ~179 ~118 ~59 dirt
setblock ~179 ~118 ~60 dirt
setblock ~179 ~118 ~61 dirt
setblock ~179 ~118 ~62 dirt
setblock ~179 ~118 ~63 dirt
setblock ~179 ~118 ~85 dirt
setblock ~179 ~118 ~86 dirt
setblock ~179 ~118 ~87 dirt
setblock ~179 ~118 ~88 dirt
setblock ~179 ~118 ~89 dirt
setblock ~179 ~118 ~90 dirt
setblock ~179 ~118 ~91 dirt
setblock ~179 ~118 ~92 dirt
setblock ~179 ~118 ~93 dirt
setblock ~179 ~118 ~94 dirt
setblock ~179 ~118 ~95 dirt
setblock ~179 ~118 ~96 dirt
setblock ~179 ~118 ~97 dirt
setblock ~179 ~118 ~98 dirt
setblock ~179 ~118 ~99 dirt
setblock ~179 ~118 ~100 dirt
setblock ~179 ~118 ~101 dirt
setblock ~179 ~118 ~102 dirt
setblock ~179 ~118 ~103 dirt
setblock ~179 ~118 ~104 dirt
setblock ~179 ~118 ~105 dirt
setblock ~179 ~118 ~106 dirt
setblock ~179 ~118 ~107 dirt
setblock ~179 ~118 ~108 dirt
setblock ~179 ~118 ~109 dirt
setblock ~179 ~118 ~110 dirt
setblock ~179 ~118 ~111 dirt
setblock ~179 ~118 ~112 dirt
setblock ~179 ~118 ~113 dirt
setblock ~179 ~118 ~114 dirt
setblock ~179 ~118 ~115 dirt
setblock ~179 ~118 ~116 dirt
setblock ~179 ~118 ~117 dirt
setblock ~179 ~118 ~118 dirt
setblock ~179 ~118 ~119 dirt
setblock ~179 ~118 ~120 dirt
setblock ~179 ~118 ~121 dirt
setblock ~179 ~118 ~122 dirt
setblock ~179 ~118 ~123 dirt
setblock ~179 ~118 ~124 dirt
setblock ~179 ~118 ~125 dirt
setblock ~179 ~118 ~126 dirt
setblock ~179 ~118 ~127 dirt
setblock ~179 ~119 ~57 dirt
setblock ~179 ~119 ~58 dirt
setblock ~179 ~119 ~59 dirt
setblock ~179 ~119 ~60 dirt
setblock ~179 ~119 ~61 dirt
setblock ~179 ~119 ~62 dirt
setblock ~179 ~119 ~63 dirt
setblock ~179 ~119 ~64 dirt
setblock ~179 ~119 ~65 dirt
setblock ~179 ~119 ~84 dirt
setblock ~179 ~119 ~85 dirt
setblock ~179 ~119 ~86 dirt
setblock ~179 ~119 ~87 dirt
setblock ~179 ~119 ~88 dirt
setblock ~179 ~119 ~89 dirt
setblock ~179 ~119 ~90 dirt
setblock ~179 ~119 ~91 dirt
setblock ~179 ~119 ~92 dirt
setblock ~179 ~119 ~93 dirt
setblock ~179 ~119 ~94 dirt
setblock ~179 ~119 ~95 dirt
setblock ~179 ~119 ~96 dirt
setblock ~179 ~119 ~97 dirt
setblock ~179 ~119 ~98 dirt
setblock ~179 ~119 ~99 dirt
setblock ~179 ~119 ~100 dirt
setblock ~179 ~119 ~101 dirt
setblock ~179 ~119 ~102 dirt
setblock ~179 ~119 ~103 dirt
setblock ~179 ~119 ~104 dirt
setblock ~179 ~119 ~105 dirt
setblock ~179 ~119 ~106 dirt
setblock ~179 ~119 ~107 dirt
setblock ~179 ~119 ~108 dirt
setblock ~179 ~119 ~109 dirt
setblock ~179 ~119 ~110 dirt
setblock ~179 ~119 ~111 dirt
setblock ~179 ~119 ~112 dirt
setblock ~179 ~119 ~113 dirt
setblock ~179 ~119 ~114 dirt
setblock ~179 ~119 ~115 dirt
setblock ~179 ~119 ~116 dirt
setblock ~179 ~119 ~117 dirt
setblock ~179 ~119 ~118 dirt
setblock ~179 ~119 ~119 dirt
setblock ~179 ~119 ~120 dirt
setblock ~179 ~119 ~121 dirt
setblock ~179 ~119 ~122 dirt
setblock ~179 ~119 ~123 dirt
setblock ~179 ~119 ~124 dirt
setblock ~179 ~119 ~125 dirt
setblock ~179 ~119 ~126 dirt
setblock ~179 ~119 ~127 dirt
setblock ~179 ~119 ~128 dirt
setblock ~179 ~120 ~56 dirt
setblock ~179 ~120 ~57 dirt
setblock ~179 ~120 ~58 dirt
setblock ~179 ~120 ~59 dirt
setblock ~179 ~120 ~60 dirt
setblock ~179 ~120 ~61 dirt
setblock ~179 ~120 ~62 dirt
setblock ~179 ~120 ~63 dirt
setblock ~179 ~120 ~64 dirt
setblock ~179 ~120 ~65 dirt
setblock ~179 ~120 ~66 dirt
setblock ~179 ~120 ~68 dirt
setblock ~179 ~120 ~71 dirt
setblock ~179 ~120 ~83 dirt
setblock ~179 ~120 ~84 dirt
setblock ~179 ~120 ~85 dirt
setblock ~179 ~120 ~86 dirt
setblock ~179 ~120 ~87 dirt
setblock ~179 ~120 ~88 dirt
setblock ~179 ~120 ~89 dirt
setblock ~179 ~120 ~90 dirt
setblock ~179 ~120 ~91 dirt
setblock ~179 ~120 ~92 dirt
setblock ~179 ~120 ~93 dirt
setblock ~179 ~120 ~94 dirt
setblock ~179 ~120 ~95 dirt
setblock ~179 ~120 ~96 dirt
setblock ~179 ~120 ~97 dirt
setblock ~179 ~120 ~98 dirt
setblock ~179 ~120 ~99 dirt
setblock ~179 ~120 ~100 dirt
setblock ~179 ~120 ~101 dirt
setblock ~179 ~120 ~102 dirt
setblock ~179 ~120 ~103 dirt
setblock ~179 ~120 ~104 dirt
setblock ~179 ~120 ~105 dirt
setblock ~179 ~120 ~106 dirt
setblock ~179 ~120 ~107 dirt
setblock ~179 ~120 ~108 dirt
setblock ~179 ~120 ~109 dirt
setblock ~179 ~120 ~110 dirt
setblock ~179 ~120 ~111 dirt
setblock ~179 ~120 ~112 dirt
setblock ~179 ~120 ~113 dirt
setblock ~179 ~120 ~114 dirt
setblock ~179 ~120 ~115 dirt
setblock ~179 ~120 ~116 dirt
setblock ~179 ~120 ~117 dirt
setblock ~179 ~120 ~118 dirt
setblock ~179 ~120 ~119 dirt
setblock ~179 ~120 ~120 dirt
setblock ~179 ~120 ~121 dirt
setblock ~179 ~120 ~122 dirt
setblock ~179 ~120 ~123 dirt
setblock ~179 ~120 ~124 dirt
setblock ~179 ~120 ~125 dirt
setblock ~179 ~120 ~126 dirt
setblock ~179 ~120 ~127 dirt
setblock ~179 ~120 ~128 dirt
setblock ~179 ~120 ~129 dirt
setblock ~179 ~121 ~55 dirt
setblock ~179 ~121 ~56 dirt
setblock ~179 ~121 ~57 dirt
setblock ~179 ~121 ~58 dirt
setblock ~179 ~121 ~59 dirt
setblock ~179 ~121 ~60 dirt
setblock ~179 ~121 ~61 dirt
setblock ~179 ~121 ~62 dirt
setblock ~179 ~121 ~63 dirt
setblock ~179 ~121 ~64 dirt
setblock ~179 ~121 ~65 dirt
setblock ~179 ~121 ~66 dirt
setblock ~179 ~121 ~67 dirt
setblock ~179 ~121 ~68 dirt
setblock ~179 ~121 ~69 dirt
setblock ~179 ~121 ~70 dirt
setblock ~179 ~121 ~71 dirt
setblock ~179 ~121 ~72 dirt
setblock ~179 ~121 ~73 dirt
setblock ~179 ~121 ~82 dirt
setblock ~179 ~121 ~83 dirt
setblock ~179 ~121 ~84 dirt
setblock ~179 ~121 ~85 dirt
setblock ~179 ~121 ~86 dirt
setblock ~179 ~121 ~87 dirt
setblock ~179 ~121 ~88 dirt
setblock ~179 ~121 ~89 dirt
setblock ~179 ~121 ~90 dirt
setblock ~179 ~121 ~91 dirt
setblock ~179 ~121 ~92 dirt
setblock ~179 ~121 ~93 dirt
setblock ~179 ~121 ~94 dirt
setblock ~179 ~121 ~95 dirt
setblock ~179 ~121 ~96 dirt
setblock ~179 ~121 ~97 dirt
setblock ~179 ~121 ~98 dirt
setblock ~179 ~121 ~99 dirt
setblock ~179 ~121 ~100 dirt
setblock ~179 ~121 ~101 dirt
setblock ~179 ~121 ~102 dirt
setblock ~179 ~121 ~103 dirt
setblock ~179 ~121 ~104 dirt
setblock ~179 ~121 ~105 dirt
setblock ~179 ~121 ~106 dirt
setblock ~179 ~121 ~107 dirt
setblock ~179 ~121 ~108 dirt
setblock ~179 ~121 ~109 dirt
setblock ~179 ~121 ~110 dirt
setblock ~179 ~121 ~111 dirt
setblock ~179 ~121 ~112 dirt
setblock ~179 ~121 ~113 dirt
setblock ~179 ~121 ~114 dirt
setblock ~179 ~121 ~115 dirt
setblock ~179 ~121 ~116 dirt
setblock ~179 ~121 ~117 dirt
setblock ~179 ~121 ~118 dirt
setblock ~179 ~121 ~119 dirt
setblock ~179 ~121 ~120 dirt
setblock ~179 ~121 ~121 dirt
setblock ~179 ~121 ~122 dirt
setblock ~179 ~121 ~123 dirt
setblock ~179 ~121 ~124 dirt
setblock ~179 ~121 ~125 dirt
setblock ~179 ~121 ~126 dirt
setblock ~179 ~121 ~127 dirt
setblock ~179 ~121 ~128 dirt
setblock ~179 ~121 ~129 dirt
setblock ~179 ~121 ~130 dirt
setblock ~179 ~122 ~55 dirt
setblock ~179 ~122 ~56 dirt
setblock ~179 ~122 ~57 dirt
setblock ~179 ~122 ~58 dirt
setblock ~179 ~122 ~59 dirt
setblock ~179 ~122 ~60 dirt
setblock ~179 ~122 ~61 dirt
setblock ~179 ~122 ~62 dirt
setblock ~179 ~122 ~63 dirt
setblock ~179 ~122 ~64 dirt
setblock ~179 ~122 ~65 dirt
setblock ~179 ~122 ~66 dirt
setblock ~179 ~122 ~67 dirt
setblock ~179 ~122 ~68 dirt
setblock ~179 ~122 ~69 dirt
setblock ~179 ~122 ~70 dirt
setblock ~179 ~122 ~71 dirt
setblock ~179 ~122 ~72 dirt
setblock ~179 ~122 ~73 dirt
setblock ~179 ~122 ~82 dirt
setblock ~179 ~122 ~83 dirt
setblock ~179 ~122 ~84 dirt
setblock ~179 ~122 ~85 dirt
setblock ~179 ~122 ~86 dirt
setblock ~179 ~122 ~87 dirt
setblock ~179 ~122 ~88 dirt
setblock ~179 ~122 ~89 dirt
setblock ~179 ~122 ~90 dirt
setblock ~179 ~122 ~91 dirt
setblock ~179 ~122 ~92 dirt
setblock ~179 ~122 ~93 dirt
setblock ~179 ~122 ~94 dirt
setblock ~179 ~122 ~95 dirt
setblock ~179 ~122 ~96 dirt
setblock ~179 ~122 ~97 dirt
setblock ~179 ~122 ~98 dirt
setblock ~179 ~122 ~99 dirt
setblock ~179 ~122 ~100 dirt
setblock ~179 ~122 ~101 dirt
setblock ~179 ~122 ~102 dirt
setblock ~179 ~122 ~103 dirt
setblock ~179 ~122 ~104 dirt
setblock ~179 ~122 ~105 dirt
setblock ~179 ~122 ~106 dirt
setblock ~179 ~122 ~107 dirt
setblock ~179 ~122 ~108 dirt
setblock ~179 ~122 ~109 dirt
setblock ~179 ~122 ~110 dirt
setblock ~179 ~122 ~111 dirt
setblock ~179 ~122 ~112 dirt
setblock ~179 ~122 ~113 dirt
setblock ~179 ~122 ~114 dirt
setblock ~179 ~122 ~115 dirt
setblock ~179 ~122 ~116 dirt
setblock ~179 ~122 ~117 dirt
setblock ~179 ~122 ~118 dirt
setblock ~179 ~122 ~119 dirt
setblock ~179 ~122 ~120 dirt
setblock ~179 ~122 ~121 dirt
setblock ~179 ~122 ~122 dirt
setblock ~179 ~122 ~123 dirt
setblock ~179 ~122 ~124 dirt
setblock ~179 ~122 ~125 dirt
setblock ~179 ~122 ~126 dirt
setblock ~179 ~122 ~127 dirt
setblock ~179 ~122 ~128 dirt
setblock ~179 ~122 ~129 dirt
setblock ~179 ~122 ~130 dirt
setblock ~179 ~123 ~55 dirt
setblock ~179 ~123 ~56 dirt
setblock ~179 ~123 ~57 dirt
setblock ~179 ~123 ~58 dirt
setblock ~179 ~123 ~59 dirt
setblock ~179 ~123 ~60 dirt
setblock ~179 ~123 ~61 dirt
setblock ~179 ~123 ~62 dirt
setblock ~179 ~123 ~63 dirt
setblock ~179 ~123 ~64 dirt
setblock ~179 ~123 ~65 dirt
setblock ~179 ~123 ~66 dirt
setblock ~179 ~123 ~67 dirt
setblock ~179 ~123 ~68 dirt
setblock ~179 ~123 ~69 dirt
setblock ~179 ~123 ~70 dirt
setblock ~179 ~123 ~71 dirt
setblock ~179 ~123 ~72 dirt
setblock ~179 ~123 ~73 grass_block
setblock ~179 ~123 ~82 grass_block
setblock ~179 ~123 ~83 grass_block
setblock ~179 ~123 ~84 grass_block
setblock ~179 ~123 ~85 grass_block
setblock ~179 ~123 ~86 grass_block
setblock ~179 ~123 ~87 grass_block
setblock ~179 ~123 ~88 grass_block
setblock ~179 ~123 ~89 grass_block
setblock ~179 ~123 ~90 grass_block
setblock ~179 ~123 ~91 grass_block
setblock ~179 ~123 ~92 dirt
setblock ~179 ~123 ~93 dirt
setblock ~179 ~123 ~94 dirt
setblock ~179 ~123 ~95 dirt
setblock ~179 ~123 ~96 dirt
setblock ~179 ~123 ~97 dirt
setblock ~179 ~123 ~98 dirt
setblock ~179 ~123 ~99 dirt
setblock ~179 ~123 ~100 dirt
setblock ~179 ~123 ~101 dirt
setblock ~179 ~123 ~102 dirt
setblock ~179 ~123 ~103 dirt
setblock ~179 ~123 ~104 dirt
setblock ~179 ~123 ~105 dirt
setblock ~179 ~123 ~106 dirt
setblock ~179 ~123 ~107 dirt
setblock ~179 ~123 ~108 dirt
setblock ~179 ~123 ~109 dirt
setblock ~179 ~123 ~110 dirt
setblock ~179 ~123 ~111 dirt
setblock ~179 ~123 ~112 dirt
setblock ~179 ~123 ~113 dirt
setblock ~179 ~123 ~114 dirt
setblock ~179 ~123 ~115 dirt
setblock ~179 ~123 ~116 dirt
setblock ~179 ~123 ~117 dirt
setblock ~179 ~123 ~118 dirt
setblock ~179 ~123 ~119 dirt
setblock ~179 ~123 ~120 dirt
setblock ~179 ~123 ~121 dirt
setblock ~179 ~123 ~122 dirt
setblock ~179 ~123 ~123 dirt
setblock ~179 ~123 ~124 dirt
setblock ~179 ~123 ~125 dirt
setblock ~179 ~123 ~126 dirt
setblock ~179 ~123 ~127 dirt
setblock ~179 ~123 ~128 dirt
setblock ~179 ~123 ~129 dirt
setblock ~179 ~123 ~130 dirt
setblock ~179 ~124 ~55 dirt
setblock ~179 ~124 ~56 dirt
setblock ~179 ~124 ~57 dirt
setblock ~179 ~124 ~58 dirt
setblock ~179 ~124 ~59 dirt
setblock ~179 ~124 ~60 dirt
setblock ~179 ~124 ~61 dirt
setblock ~179 ~124 ~62 dirt
setblock ~179 ~124 ~63 dirt
setblock ~179 ~124 ~64 dirt
setblock ~179 ~124 ~65 dirt
setblock ~179 ~124 ~66 dirt
setblock ~179 ~124 ~67 dirt
setblock ~179 ~124 ~68 dirt
setblock ~179 ~124 ~69 grass_block
setblock ~179 ~124 ~70 grass_block
setblock ~179 ~124 ~71 grass_block
setblock ~179 ~124 ~72 grass_block
setblock ~179 ~124 ~85 short_grass
setblock ~179 ~124 ~88 short_grass
setblock ~179 ~124 ~89 short_grass
setblock ~179 ~124 ~90 short_grass
setblock ~179 ~124 ~92 grass_block
setblock ~179 ~124 ~93 grass_block
setblock ~179 ~124 ~94 dirt
setblock ~179 ~124 ~95 dirt
setblock ~179 ~124 ~96 dirt
setblock ~179 ~124 ~97 dirt
setblock ~179 ~124 ~98 dirt
setblock ~179 ~124 ~99 dirt
setblock ~179 ~124 ~100 dirt
setblock ~179 ~124 ~101 dirt
setblock ~179 ~124 ~102 dirt
setblock ~179 ~124 ~103 dirt
setblock ~179 ~124 ~104 dirt
setblock ~179 ~124 ~105 dirt
setblock ~179 ~124 ~106 dirt
setblock ~179 ~124 ~107 dirt
setblock ~179 ~124 ~108 dirt
setblock ~179 ~124 ~109 grass_block
setblock ~179 ~124 ~110 grass_block
setblock ~179 ~124 ~111 grass_block
setblock ~179 ~124 ~112 dirt
setblock ~179 ~124 ~113 dirt
setblock ~179 ~124 ~114 dirt
setblock ~179 ~124 ~115 dirt
setblock ~179 ~124 ~116 dirt
setblock ~179 ~124 ~117 dirt
setblock ~179 ~124 ~118 dirt
setblock ~179 ~124 ~119 dirt
setblock ~179 ~124 ~120 dirt
setblock ~179 ~124 ~121 dirt
setblock ~179 ~124 ~122 dirt
setblock ~179 ~124 ~123 dirt
setblock ~179 ~124 ~124 dirt
setblock ~179 ~124 ~125 dirt
setblock ~179 ~124 ~126 dirt
setblock ~179 ~124 ~127 dirt
setblock ~179 ~124 ~128 grass_block
setblock ~179 ~124 ~129 grass_block
setblock ~179 ~124 ~130 grass_block
setblock ~179 ~125 ~55 dirt
setblock ~179 ~125 ~56 dirt
setblock ~179 ~125 ~57 dirt
setblock ~179 ~125 ~58 dirt
setblock ~179 ~125 ~59 dirt
setblock ~179 ~125 ~60 dirt
setblock ~179 ~125 ~61 dirt
setblock ~179 ~125 ~62 dirt
setblock ~179 ~125 ~63 dirt
setblock ~179 ~125 ~64 dirt
setblock ~179 ~125 ~65 dirt
setblock ~179 ~125 ~66 dirt
setblock ~179 ~125 ~67 grass_block
setblock ~179 ~125 ~68 grass_block
setblock ~179 ~125 ~70 fern
setblock ~179 ~125 ~94 grass_block
setblock ~179 ~125 ~95 grass_block
setblock ~179 ~125 ~96 dirt
setblock ~179 ~125 ~97 dirt
setblock ~179 ~125 ~98 dirt
setblock ~179 ~125 ~99 dirt
setblock ~179 ~125 ~100 dirt
setblock ~179 ~125 ~101 dirt
setblock ~179 ~125 ~102 dirt
setblock ~179 ~125 ~103 dirt
setblock ~179 ~125 ~104 dirt
setblock ~179 ~125 ~105 dirt
setblock ~179 ~125 ~106 grass_block
setblock ~179 ~125 ~107 grass_block
setblock ~179 ~125 ~108 grass_block
setblock ~179 ~125 ~110 short_grass
setblock ~179 ~125 ~111 short_grass
setblock ~179 ~125 ~112 grass_block
setblock ~179 ~125 ~113 grass_block
setblock ~179 ~125 ~114 grass_block
setblock ~179 ~125 ~115 dirt
setblock ~179 ~125 ~116 dirt
setblock ~179 ~125 ~117 dirt
setblock ~179 ~125 ~118 dirt
setblock ~179 ~125 ~119 dirt
setblock ~179 ~125 ~120 dirt
setblock ~179 ~125 ~121 dirt
setblock ~179 ~125 ~122 dirt
setblock ~179 ~125 ~123 dirt
setblock ~179 ~125 ~124 dirt
setblock ~179 ~125 ~125 dirt
setblock ~179 ~125 ~126 grass_block
setblock ~179 ~125 ~127 grass_block
setblock ~179 ~125 ~128 short_grass
setblock ~179 ~126 ~55 dirt
setblock ~179 ~126 ~56 dirt
setblock ~179 ~126 ~57 dirt
setblock ~179 ~126 ~58 dirt
setblock ~179 ~126 ~59 dirt
setblock ~179 ~126 ~60 dirt
setblock ~179 ~126 ~61 dirt
setblock ~179 ~126 ~62 dirt
setblock ~179 ~126 ~63 dirt
setblock ~179 ~126 ~64 grass_block
setblock ~179 ~126 ~65 grass_block
setblock ~179 ~126 ~66 grass_block
setblock ~179 ~126 ~68 short_grass
setblock ~179 ~126 ~96 grass_block
setblock ~179 ~126 ~97 grass_block
setblock ~179 ~126 ~98 grass_block
setblock ~179 ~126 ~99 grass_block
setblock ~179 ~126 ~100 grass_block
setblock ~179 ~126 ~101 grass_block
setblock ~179 ~126 ~102 grass_block
setblock ~179 ~126 ~103 grass_block
setblock ~179 ~126 ~104 grass_block
setblock ~179 ~126 ~105 grass_block
setblock ~179 ~126 ~113 short_grass
setblock ~179 ~126 ~115 grass_block
setblock ~179 ~126 ~116 grass_block
setblock ~179 ~126 ~117 dirt
setblock ~179 ~126 ~118 dirt
setblock ~179 ~126 ~119 dirt
setblock ~179 ~126 ~120 dirt
setblock ~179 ~126 ~121 dirt
setblock ~179 ~126 ~122 dirt
setblock ~179 ~126 ~123 dirt
setblock ~179 ~126 ~124 grass_block
setblock ~179 ~126 ~125 grass_block
setblock ~179 ~126 ~127 short_grass
setblock ~179 ~127 ~55 grass_block
setblock ~179 ~127 ~56 grass_block
setblock ~179 ~127 ~57 dirt
setblock ~179 ~127 ~58 dirt
setblock ~179 ~127 ~59 dirt
setblock ~179 ~127 ~60 dirt
setblock ~179 ~127 ~61 dirt
setblock ~179 ~127 ~62 dirt
setblock ~179 ~127 ~63 grass_block
setblock ~179 ~127 ~98 short_grass
setblock ~179 ~127 ~101 fern
setblock ~179 ~127 ~103 short_grass
setblock ~179 ~127 ~116 short_grass
setblock ~179 ~127 ~117 grass_block
setblock ~179 ~127 ~118 grass_block
setblock ~179 ~127 ~119 dirt
setblock ~179 ~127 ~120 dirt
setblock ~179 ~127 ~121 grass_block
setblock ~179 ~127 ~122 grass_block
setblock ~179 ~127 ~123 grass_block
setblock ~179 ~128 ~55 short_grass
setblock ~179 ~128 ~57 grass_block
setblock ~179 ~128 ~58 grass_block
setblock ~179 ~128 ~59 grass_block
setblock ~179 ~128 ~60 dirt
setblock ~179 ~128 ~61 grass_block
setblock ~179 ~128 ~62 grass_block
setblock ~179 ~128 ~117 fern
setblock ~179 ~128 ~119 grass_block
setblock ~179 ~128 ~120 grass_block
setblock ~179 ~128 ~121 short_grass
setblock ~179 ~129 ~57 short_grass
setblock ~179 ~129 ~60 grass_block
setblock ~179 ~129 ~120 short_grass
setblock ~180 ~103 ~96 dirt
setblock ~180 ~104 ~96 dirt
setblock ~180 ~104 ~97 dirt
setblock ~180 ~105 ~95 dirt
setblock ~180 ~105 ~96 dirt
setblock ~180 ~105 ~97 dirt
setblock ~180 ~105 ~98 dirt
setblock ~180 ~106 ~94 dirt
setblock ~180 ~106 ~95 dirt
setblock ~180 ~106 ~96 dirt
setblock ~180 ~106 ~97 dirt
setblock ~180 ~106 ~98 dirt
setblock ~180 ~106 ~99 dirt
setblock ~180 ~107 ~93 dirt
setblock ~180 ~107 ~94 dirt
setblock ~180 ~107 ~95 dirt
setblock ~180 ~107 ~96 dirt
setblock ~180 ~107 ~97 dirt
setblock ~180 ~107 ~98 dirt
setblock ~180 ~107 ~99 dirt
setblock ~180 ~107 ~100 dirt
setblock ~180 ~108 ~92 dirt
setblock ~180 ~108 ~93 dirt
setblock ~180 ~108 ~94 dirt
setblock ~180 ~108 ~95 dirt
setblock ~180 ~108 ~96 dirt
setblock ~180 ~108 ~97 dirt
setblock ~180 ~108 ~98 dirt
setblock ~180 ~108 ~99 dirt
setblock ~180 ~108 ~100 dirt
setblock ~180 ~108 ~101 dirt
setblock ~180 ~109 ~91 dirt
setblock ~180 ~109 ~92 dirt
setblock ~180 ~109 ~93 dirt
setblock ~180 ~109 ~94 dirt
setblock ~180 ~109 ~95 dirt
setblock ~180 ~109 ~96 dirt
setblock ~180 ~109 ~97 dirt
setblock ~180 ~109 ~98 dirt
setblock ~180 ~109 ~99 dirt
setblock ~180 ~109 ~100 dirt
setblock ~180 ~109 ~101 dirt
setblock ~180 ~110 ~91 dirt
setblock ~180 ~110 ~92 dirt
setblock ~180 ~110 ~93 dirt
setblock ~180 ~110 ~94 dirt
setblock ~180 ~110 ~95 dirt
setblock ~180 ~110 ~96 dirt
setblock ~180 ~110 ~97 dirt
setblock ~180 ~110 ~98 dirt
setblock ~180 ~110 ~99 dirt
setblock ~180 ~110 ~100 dirt
setblock ~180 ~110 ~101 dirt
setblock ~180 ~110 ~102 dirt
setblock ~180 ~110 ~106 dirt
setblock ~180 ~111 ~90 dirt
setblock ~180 ~111 ~91 dirt
setblock ~180 ~111 ~92 dirt
setblock ~180 ~111 ~93 dirt
setblock ~180 ~111 ~94 dirt
setblock ~180 ~111 ~95 dirt
setblock ~180 ~111 ~96 dirt
setblock ~180 ~111 ~97 dirt
setblock ~180 ~111 ~98 dirt
setblock ~180 ~111 ~99 dirt
setblock ~180 ~111 ~100 dirt
setblock ~180 ~111 ~101 dirt
setblock ~180 ~111 ~102 dirt
setblock ~180 ~111 ~103 dirt
setblock ~180 ~111 ~104 dirt
setblock ~180 ~111 ~106 dirt
setblock ~180 ~112 ~90 dirt
setblock ~180 ~112 ~91 dirt
setblock ~180 ~112 ~92 dirt
setblock ~180 ~112 ~93 dirt
setblock ~180 ~112 ~94 dirt
setblock ~180 ~112 ~95 dirt
setblock ~180 ~112 ~96 dirt
setblock ~180 ~112 ~97 dirt
setblock ~180 ~112 ~98 dirt
setblock ~180 ~112 ~99 dirt
setblock ~180 ~112 ~100 dirt
setblock ~180 ~112 ~101 dirt
setblock ~180 ~112 ~102 dirt
setblock ~180 ~112 ~103 dirt
setblock ~180 ~112 ~104 dirt
setblock ~180 ~112 ~105 dirt
setblock ~180 ~112 ~106 dirt
setblock ~180 ~112 ~107 dirt
setblock ~180 ~113 ~89 dirt
setblock ~180 ~113 ~90 dirt
setblock ~180 ~113 ~91 dirt
setblock ~180 ~113 ~92 dirt
setblock ~180 ~113 ~93 dirt
setblock ~180 ~113 ~94 dirt
setblock ~180 ~113 ~95 dirt
setblock ~180 ~113 ~96 dirt
setblock ~180 ~113 ~97 dirt
setblock ~180 ~113 ~98 dirt
setblock ~180 ~113 ~99 dirt
setblock ~180 ~113 ~100 dirt
setblock ~180 ~113 ~101 dirt
setblock ~180 ~113 ~102 dirt
setblock ~180 ~113 ~103 dirt
setblock ~180 ~113 ~104 dirt
setblock ~180 ~113 ~105 dirt
setblock ~180 ~113 ~106 dirt
setblock ~180 ~113 ~107 dirt
setblock ~180 ~113 ~108 dirt
setblock ~180 ~113 ~109 dirt
setblock ~180 ~114 ~88 dirt
setblock ~180 ~114 ~89 dirt
setblock ~180 ~114 ~90 dirt
setblock ~180 ~114 ~91 dirt
setblock ~180 ~114 ~92 dirt
setblock ~180 ~114 ~93 dirt
setblock ~180 ~114 ~94 dirt
setblock ~180 ~114 ~95 dirt
setblock ~180 ~114 ~96 dirt
setblock ~180 ~114 ~97 dirt
setblock ~180 ~114 ~98 dirt
setblock ~180 ~114 ~99 dirt
setblock ~180 ~114 ~100 dirt
setblock ~180 ~114 ~101 dirt
setblock ~180 ~114 ~102 dirt
setblock ~180 ~114 ~103 dirt
setblock ~180 ~114 ~104 dirt
setblock ~180 ~114 ~105 dirt
setblock ~180 ~114 ~106 dirt
setblock ~180 ~114 ~107 dirt
setblock ~180 ~114 ~108 dirt
setblock ~180 ~114 ~109 dirt
setblock ~180 ~114 ~110 dirt
setblock ~180 ~114 ~120 dirt
setblock ~180 ~114 ~121 dirt
setblock ~180 ~115 ~87 dirt
setblock ~180 ~115 ~88 dirt
setblock ~180 ~115 ~89 dirt
setblock ~180 ~115 ~90 dirt
setblock ~180 ~115 ~91 dirt
setblock ~180 ~115 ~92 dirt
setblock ~180 ~115 ~93 dirt
setblock ~180 ~115 ~94 dirt
setblock ~180 ~115 ~95 dirt
setblock ~180 ~115 ~96 dirt
setblock ~180 ~115 ~97 dirt
setblock ~180 ~115 ~98 dirt
setblock ~180 ~115 ~99 dirt
setblock ~180 ~115 ~100 dirt
setblock ~180 ~115 ~101 dirt
setblock ~180 ~115 ~102 dirt
setblock ~180 ~115 ~103 dirt
setblock ~180 ~115 ~104 dirt
setblock ~180 ~115 ~105 dirt
setblock ~180 ~115 ~106 dirt
setblock ~180 ~115 ~107 dirt
setblock ~180 ~115 ~108 dirt
setblock ~180 ~115 ~109 dirt
setblock ~180 ~115 ~110 dirt
setblock ~180 ~115 ~111 dirt
setblock ~180 ~115 ~119 dirt
setblock ~180 ~115 ~120 dirt
setblock ~180 ~115 ~121 dirt
setblock ~180 ~115 ~122 dirt
setblock ~180 ~116 ~86 dirt
setblock ~180 ~116 ~87 dirt
setblock ~180 ~116 ~88 dirt
setblock ~180 ~116 ~89 dirt
setblock ~180 ~116 ~90 dirt
setblock ~180 ~116 ~91 dirt
setblock ~180 ~116 ~92 dirt
setblock ~180 ~116 ~93 dirt
setblock ~180 ~116 ~94 dirt
setblock ~180 ~116 ~95 dirt
setblock ~180 ~116 ~96 dirt
setblock ~180 ~116 ~97 dirt
setblock ~180 ~116 ~98 dirt
setblock ~180 ~116 ~99 dirt
setblock ~180 ~116 ~100 dirt
setblock ~180 ~116 ~101 dirt
setblock ~180 ~116 ~102 dirt
setblock ~180 ~116 ~103 dirt
setblock ~180 ~116 ~104 dirt
setblock ~180 ~116 ~105 dirt
setblock ~180 ~116 ~106 dirt
setblock ~180 ~116 ~107 dirt
setblock ~180 ~116 ~108 dirt
setblock ~180 ~116 ~109 dirt
setblock ~180 ~116 ~110 dirt
setblock ~180 ~116 ~111 dirt
setblock ~180 ~116 ~112 dirt
setblock ~180 ~116 ~118 dirt
setblock ~180 ~116 ~119 dirt
setblock ~180 ~116 ~120 dirt
setblock ~180 ~116 ~121 dirt
setblock ~180 ~116 ~122 dirt
setblock ~180 ~116 ~123 dirt
setblock ~180 ~117 ~85 dirt
setblock ~180 ~117 ~86 dirt
setblock ~180 ~117 ~87 dirt
setblock ~180 ~117 ~88 dirt
setblock ~180 ~117 ~89 dirt
setblock ~180 ~117 ~90 dirt
setblock ~180 ~117 ~91 dirt
setblock ~180 ~117 ~92 dirt
setblock ~180 ~117 ~93 dirt
setblock ~180 ~117 ~94 dirt
setblock ~180 ~117 ~95 dirt
setblock ~180 ~117 ~96 dirt
setblock ~180 ~117 ~97 dirt
setblock ~180 ~117 ~98 dirt
setblock ~180 ~117 ~99 dirt
setblock ~180 ~117 ~100 dirt
setblock ~180 ~117 ~101 dirt
setblock ~180 ~117 ~102 dirt
setblock ~180 ~117 ~103 dirt
setblock ~180 ~117 ~104 dirt
setblock ~180 ~117 ~105 dirt
setblock ~180 ~117 ~106 dirt
setblock ~180 ~117 ~107 dirt
setblock ~180 ~117 ~108 dirt
setblock ~180 ~117 ~109 dirt
setblock ~180 ~117 ~110 dirt
setblock ~180 ~117 ~111 dirt
setblock ~180 ~117 ~112 dirt
setblock ~180 ~117 ~117 dirt
setblock ~180 ~117 ~118 dirt
setblock ~180 ~117 ~119 dirt
setblock ~180 ~117 ~120 dirt
setblock ~180 ~117 ~121 dirt
setblock ~180 ~117 ~122 dirt
setblock ~180 ~117 ~123 dirt
setblock ~180 ~117 ~124 dirt
setblock ~180 ~117 ~125 dirt
setblock ~180 ~118 ~60 dirt
setblock ~180 ~118 ~84 dirt
setblock ~180 ~118 ~85 dirt
setblock ~180 ~118 ~86 dirt
setblock ~180 ~118 ~87 dirt
setblock ~180 ~118 ~88 dirt
setblock ~180 ~118 ~89 dirt
setblock ~180 ~118 ~90 dirt
setblock ~180 ~118 ~91 dirt
setblock ~180 ~118 ~92 dirt
setblock ~180 ~118 ~93 dirt
setblock ~180 ~118 ~94 dirt
setblock ~180 ~118 ~95 dirt
setblock ~180 ~118 ~96 dirt
setblock ~180 ~118 ~97 dirt
setblock ~180 ~118 ~98 dirt
setblock ~180 ~118 ~99 dirt
setblock ~180 ~118 ~100 dirt
setblock ~180 ~118 ~101 dirt
setblock ~180 ~118 ~102 dirt
setblock ~180 ~118 ~103 dirt
setblock ~180 ~118 ~104 dirt
setblock ~180 ~118 ~105 dirt
setblock ~180 ~118 ~106 dirt
setblock ~180 ~118 ~107 dirt
setblock ~180 ~118 ~108 dirt
setblock ~180 ~118 ~109 dirt
setblock ~180 ~118 ~110 dirt
setblock ~180 ~118 ~111 dirt
setblock ~180 ~118 ~112 dirt
setblock ~180 ~118 ~113 dirt
setblock ~180 ~118 ~116 dirt
setblock ~180 ~118 ~117 dirt
setblock ~180 ~118 ~118 dirt
setblock ~180 ~118 ~119 dirt
setblock ~180 ~118 ~120 dirt
setblock ~180 ~118 ~121 dirt
setblock ~180 ~118 ~122 dirt
setblock ~180 ~118 ~123 dirt
setblock ~180 ~118 ~124 dirt
setblock ~180 ~118 ~125 dirt
setblock ~180 ~118 ~126 dirt
setblock ~180 ~119 ~59 dirt
setblock ~180 ~119 ~60 dirt
setblock ~180 ~119 ~61 dirt
setblock ~180 ~119 ~63 dirt
setblock ~180 ~119 ~84 dirt
setblock ~180 ~119 ~85 dirt
setblock ~180 ~119 ~86 dirt
setblock ~180 ~119 ~87 dirt
setblock ~180 ~119 ~88 dirt
setblock ~180 ~119 ~89 dirt
setblock ~180 ~119 ~90 dirt
setblock ~180 ~119 ~91 dirt
setblock ~180 ~119 ~92 dirt
setblock ~180 ~119 ~93 dirt
setblock ~180 ~119 ~94 dirt
setblock ~180 ~119 ~95 dirt
setblock ~180 ~119 ~96 dirt
setblock ~180 ~119 ~97 dirt
setblock ~180 ~119 ~98 dirt
setblock ~180 ~119 ~99 dirt
setblock ~180 ~119 ~100 dirt
setblock ~180 ~119 ~101 dirt
setblock ~180 ~119 ~102 dirt
setblock ~180 ~119 ~103 dirt
setblock ~180 ~119 ~104 dirt
setblock ~180 ~119 ~105 dirt
setblock ~180 ~119 ~106 dirt
setblock ~180 ~119 ~107 dirt
setblock ~180 ~119 ~108 dirt
setblock ~180 ~119 ~109 dirt
setblock ~180 ~119 ~110 dirt
setblock ~180 ~119 ~111 dirt
setblock ~180 ~119 ~112 dirt
setblock ~180 ~119 ~113 dirt
setblock ~180 ~119 ~114 dirt
setblock ~180 ~119 ~115 dirt
setblock ~180 ~119 ~116 dirt
setblock ~180 ~119 ~117 dirt
setblock ~180 ~119 ~118 dirt
setblock ~180 ~119 ~119 dirt
setblock ~180 ~119 ~120 dirt
setblock ~180 ~119 ~121 dirt
setblock ~180 ~119 ~122 dirt
setblock ~180 ~119 ~123 dirt
setblock ~180 ~119 ~124 dirt
setblock ~180 ~119 ~125 dirt
setblock ~180 ~119 ~126 dirt
setblock ~180 ~119 ~127 dirt
setblock ~180 ~120 ~57 dirt
setblock ~180 ~120 ~58 dirt
setblock ~180 ~120 ~59 dirt
setblock ~180 ~120 ~60 dirt
setblock ~180 ~120 ~61 dirt
setblock ~180 ~120 ~62 dirt
setblock ~180 ~120 ~63 dirt
setblock ~180 ~120 ~64 dirt
setblock ~180 ~120 ~65 dirt
setblock ~180 ~120 ~83 dirt
setblock ~180 ~120 ~84 dirt
setblock ~180 ~120 ~85 dirt
setblock ~180 ~120 ~86 dirt
setblock ~180 ~120 ~87 dirt
setblock ~180 ~120 ~88 dirt
setblock ~180 ~120 ~89 dirt
setblock ~180 ~120 ~90 dirt
setblock ~180 ~120 ~91 dirt
setblock ~180 ~120 ~92 dirt
setblock ~180 ~120 ~93 dirt
setblock ~180 ~120 ~94 dirt
setblock ~180 ~120 ~95 dirt
setblock ~180 ~120 ~96 dirt
setblock ~180 ~120 ~97 dirt
setblock ~180 ~120 ~98 dirt
setblock ~180 ~120 ~99 dirt
setblock ~180 ~120 ~100 dirt
setblock ~180 ~120 ~101 dirt
setblock ~180 ~120 ~102 dirt
setblock ~180 ~120 ~103 dirt
setblock ~180 ~120 ~104 dirt
setblock ~180 ~120 ~105 dirt
setblock ~180 ~120 ~106 dirt
setblock ~180 ~120 ~107 dirt
setblock ~180 ~120 ~108 dirt
setblock ~180 ~120 ~109 dirt
setblock ~180 ~120 ~110 dirt
setblock ~180 ~120 ~111 dirt
setblock ~180 ~120 ~112 dirt
setblock ~180 ~120 ~113 dirt
setblock ~180 ~120 ~114 dirt
setblock ~180 ~120 ~115 dirt
setblock ~180 ~120 ~116 dirt
setblock ~180 ~120 ~117 dirt
setblock ~180 ~120 ~118 dirt
setblock ~180 ~120 ~119 dirt
setblock ~180 ~120 ~120 dirt
setblock ~180 ~120 ~121 dirt
setblock ~180 ~120 ~122 dirt
setblock ~180 ~120 ~123 dirt
setblock ~180 ~120 ~124 dirt
setblock ~180 ~120 ~125 dirt
setblock ~180 ~120 ~126 dirt
setblock ~180 ~120 ~127 dirt
setblock ~180 ~120 ~128 dirt
setblock ~180 ~121 ~56 dirt
setblock ~180 ~121 ~57 dirt
setblock ~180 ~121 ~58 dirt
setblock ~180 ~121 ~59 dirt
setblock ~180 ~121 ~60 dirt
setblock ~180 ~121 ~61 dirt
setblock ~180 ~121 ~62 dirt
setblock ~180 ~121 ~63 dirt
setblock ~180 ~121 ~64 dirt
setblock ~180 ~121 ~65 dirt
setblock ~180 ~121 ~66 dirt
setblock ~180 ~121 ~71 dirt
setblock ~180 ~121 ~83 dirt
setblock ~180 ~121 ~84 dirt
setblock ~180 ~121 ~85 dirt
setblock ~180 ~121 ~86 dirt
setblock ~180 ~121 ~87 dirt
setblock ~180 ~121 ~88 dirt
setblock ~180 ~121 ~89 dirt
setblock ~180 ~121 ~90 dirt
setblock ~180 ~121 ~91 dirt
setblock ~180 ~121 ~92 dirt
setblock ~180 ~121 ~93 dirt
setblock ~180 ~121 ~94 dirt
setblock ~180 ~121 ~95 dirt
setblock ~180 ~121 ~96 dirt
setblock ~180 ~121 ~97 dirt
setblock ~180 ~121 ~98 dirt
setblock ~180 ~121 ~99 dirt
setblock ~180 ~121 ~100 dirt
setblock ~180 ~121 ~101 dirt
setblock ~180 ~121 ~102 dirt
setblock ~180 ~121 ~103 dirt
setblock ~180 ~121 ~104 dirt
setblock ~180 ~121 ~105 dirt
setblock ~180 ~121 ~106 dirt
setblock ~180 ~121 ~107 dirt
setblock ~180 ~121 ~108 dirt
setblock ~180 ~121 ~109 dirt
setblock ~180 ~121 ~110 dirt
setblock ~180 ~121 ~111 dirt
setblock ~180 ~121 ~112 dirt
setblock ~180 ~121 ~113 dirt
setblock ~180 ~121 ~114 dirt
setblock ~180 ~121 ~115 dirt
setblock ~180 ~121 ~116 dirt
setblock ~180 ~121 ~117 dirt
setblock ~180 ~121 ~118 dirt
setblock ~180 ~121 ~119 dirt
setblock ~180 ~121 ~120 dirt
setblock ~180 ~121 ~121 dirt
setblock ~180 ~121 ~122 dirt
setblock ~180 ~121 ~123 dirt
setblock ~180 ~121 ~124 dirt
setblock ~180 ~121 ~125 dirt
setblock ~180 ~121 ~126 dirt
setblock ~180 ~121 ~127 dirt
setblock ~180 ~121 ~128 dirt
setblock ~180 ~121 ~129 dirt
setblock ~180 ~122 ~56 dirt
setblock ~180 ~122 ~57 dirt
setblock ~180 ~122 ~58 dirt
setblock ~180 ~122 ~59 dirt
setblock ~180 ~122 ~60 dirt
setblock ~180 ~122 ~61 dirt
setblock ~180 ~122 ~62 dirt
setblock ~180 ~122 ~63 dirt
setblock ~180 ~122 ~64 dirt
setblock ~180 ~122 ~65 dirt
setblock ~180 ~122 ~66 dirt
setblock ~180 ~122 ~71 dirt
setblock ~180 ~122 ~83 dirt
setblock ~180 ~122 ~84 dirt
setblock ~180 ~122 ~85 dirt
setblock ~180 ~122 ~86 dirt
setblock ~180 ~122 ~87 grass_block
setblock ~180 ~122 ~88 grass_block
setblock ~180 ~122 ~89 grass_block
setblock ~180 ~122 ~90 grass_block
setblock ~180 ~122 ~91 dirt
setblock ~180 ~122 ~92 dirt
setblock ~180 ~122 ~93 dirt
setblock ~180 ~122 ~94 dirt
setblock ~180 ~122 ~95 dirt
setblock ~180 ~122 ~96 dirt
setblock ~180 ~122 ~97 dirt
setblock ~180 ~122 ~98 dirt
setblock ~180 ~122 ~99 dirt
setblock ~180 ~122 ~100 dirt
setblock ~180 ~122 ~101 dirt
setblock ~180 ~122 ~102 dirt
setblock ~180 ~122 ~103 dirt
setblock ~180 ~122 ~104 dirt
setblock ~180 ~122 ~105 dirt
setblock ~180 ~122 ~106 dirt
setblock ~180 ~122 ~107 dirt
setblock ~180 ~122 ~108 dirt
setblock ~180 ~122 ~109 dirt
setblock ~180 ~122 ~110 dirt
setblock ~180 ~122 ~111 dirt
setblock ~180 ~122 ~112 dirt
setblock ~180 ~122 ~113 dirt
setblock ~180 ~122 ~114 dirt
setblock ~180 ~122 ~115 dirt
setblock ~180 ~122 ~116 dirt
setblock ~180 ~122 ~117 dirt
setblock ~180 ~122 ~118 dirt
setblock ~180 ~122 ~119 dirt
setblock ~180 ~122 ~120 dirt
setblock ~180 ~122 ~121 dirt
setblock ~180 ~122 ~122 dirt
setblock ~180 ~122 ~123 dirt
setblock ~180 ~122 ~124 dirt
setblock ~180 ~122 ~125 dirt
setblock ~180 ~122 ~126 dirt
setblock ~180 ~122 ~127 dirt
setblock ~180 ~122 ~128 dirt
setblock ~180 ~122 ~129 dirt
setblock ~180 ~123 ~56 dirt
setblock ~180 ~123 ~57 dirt
setblock ~180 ~123 ~58 dirt
setblock ~180 ~123 ~59 dirt
setblock ~180 ~123 ~60 dirt
setblock ~180 ~123 ~61 dirt
setblock ~180 ~123 ~62 dirt
setblock ~180 ~123 ~63 dirt
setblock ~180 ~123 ~64 dirt
setblock ~180 ~123 ~65 dirt
setblock ~180 ~123 ~66 dirt
setblock ~180 ~123 ~71 dirt
setblock ~180 ~123 ~83 grass_block
setblock ~180 ~123 ~84 grass_block
setblock ~180 ~123 ~85 grass_block
setblock ~180 ~123 ~86 grass_block
setblock ~180 ~123 ~89 short_grass
setblock ~180 ~123 ~91 grass_block
setblock ~180 ~123 ~92 grass_block
setblock ~180 ~123 ~93 dirt
setblock ~180 ~123 ~94 dirt
setblock ~180 ~123 ~95 dirt
setblock ~180 ~123 ~96 dirt
setblock ~180 ~123 ~97 dirt
setblock ~180 ~123 ~98 dirt
setblock ~180 ~123 ~99 dirt
setblock ~180 ~123 ~100 dirt
setblock ~180 ~123 ~101 dirt
setblock ~180 ~123 ~102 dirt
setblock ~180 ~123 ~103 dirt
setblock ~180 ~123 ~104 dirt
setblock ~180 ~123 ~105 dirt
setblock ~180 ~123 ~106 dirt
setblock ~180 ~123 ~107 dirt
setblock ~180 ~123 ~108 dirt
setblock ~180 ~123 ~109 dirt
setblock ~180 ~123 ~110 dirt
setblock ~180 ~123 ~111 dirt
setblock ~180 ~123 ~112 dirt
setblock ~180 ~123 ~113 dirt
setblock ~180 ~123 ~114 dirt
setblock ~180 ~123 ~115 dirt
setblock ~180 ~123 ~116 dirt
setblock ~180 ~123 ~117 dirt
setblock ~180 ~123 ~118 dirt
setblock ~180 ~123 ~119 dirt
setblock ~180 ~123 ~120 dirt
setblock ~180 ~123 ~121 dirt
setblock ~180 ~123 ~122 dirt
setblock ~180 ~123 ~123 dirt
setblock ~180 ~123 ~124 dirt
setblock ~180 ~123 ~125 dirt
setblock ~180 ~123 ~126 dirt
setblock ~180 ~123 ~127 dirt
setblock ~180 ~123 ~128 dirt
setblock ~180 ~123 ~129 grass_block
setblock ~180 ~124 ~56 dirt
setblock ~180 ~124 ~57 dirt
setblock ~180 ~124 ~58 dirt
setblock ~180 ~124 ~59 dirt
setblock ~180 ~124 ~60 dirt
setblock ~180 ~124 ~61 dirt
setblock ~180 ~124 ~62 dirt
setblock ~180 ~124 ~63 dirt
setblock ~180 ~124 ~64 dirt
setblock ~180 ~124 ~65 dirt
setblock ~180 ~124 ~66 dirt
setblock ~180 ~124 ~71 grass_block
setblock ~180 ~124 ~83 short_grass
setblock ~180 ~124 ~86 short_grass
setblock ~180 ~124 ~91 short_grass
setblock ~180 ~124 ~93 grass_block
setblock ~180 ~124 ~94 grass_block
setblock ~180 ~124 ~95 dirt
setblock ~180 ~124 ~96 dirt
setblock ~180 ~124 ~97 dirt
setblock ~180 ~124 ~98 dirt
setblock ~180 ~124 ~99 dirt
setblock ~180 ~124 ~100 dirt
setblock ~180 ~124 ~101 dirt
setblock ~180 ~124 ~102 dirt
setblock ~180 ~124 ~103 dirt
setblock ~180 ~124 ~104 dirt
setblock ~180 ~124 ~105 dirt
setblock ~180 ~124 ~106 dirt
setblock ~180 ~124 ~107 dirt
setblock ~180 ~124 ~108 dirt
setblock ~180 ~124 ~109 grass_block
setblock ~180 ~124 ~110 grass_block
setblock ~180 ~124 ~111 grass_block
setblock ~180 ~124 ~112 dirt
setblock ~180 ~124 ~113 dirt
setblock ~180 ~124 ~114 dirt
setblock ~180 ~124 ~115 dirt
setblock ~180 ~124 ~116 dirt
setblock ~180 ~124 ~117 dirt
setblock ~180 ~124 ~118 dirt
setblock ~180 ~124 ~119 dirt
setblock ~180 ~124 ~120 dirt
setblock ~180 ~124 ~121 dirt
setblock ~180 ~124 ~122 dirt
setblock ~180 ~124 ~123 dirt
setblock ~180 ~124 ~124 dirt
setblock ~180 ~124 ~125 dirt
setblock ~180 ~124 ~126 dirt
setblock ~180 ~124 ~127 grass_block
setblock ~180 ~124 ~128 grass_block
setblock ~180 ~125 ~56 dirt
setblock ~180 ~125 ~57 dirt
setblock ~180 ~125 ~58 dirt
setblock ~180 ~125 ~59 dirt
setblock ~180 ~125 ~60 dirt
setblock ~180 ~125 ~61 dirt
setblock ~180 ~125 ~62 dirt
setblock ~180 ~125 ~63 dirt
setblock ~180 ~125 ~64 dirt
setblock ~180 ~125 ~65 dirt
setblock ~180 ~125 ~66 grass_block
setblock ~180 ~125 ~95 grass_block
setblock ~180 ~125 ~96 grass_block
setblock ~180 ~125 ~97 grass_block
setblock ~180 ~125 ~98 dirt
setblock ~180 ~125 ~99 dirt
setblock ~180 ~125 ~100 dirt
setblock ~180 ~125 ~101 dirt
setblock ~180 ~125 ~102 dirt
setblock ~180 ~125 ~103 dirt
setblock ~180 ~125 ~104 dirt
setblock ~180 ~125 ~105 dirt
setblock ~180 ~125 ~106 grass_block
setblock ~180 ~125 ~107 grass_block
setblock ~180 ~125 ~108 grass_block
setblock ~180 ~125 ~110 short_grass
setblock ~180 ~125 ~112 grass_block
setblock ~180 ~125 ~113 grass_block
setblock ~180 ~125 ~114 dirt
setblock ~180 ~125 ~115 dirt
setblock ~180 ~125 ~116 dirt
setblock ~180 ~125 ~117 dirt
setblock ~180 ~125 ~118 dirt
setblock ~180 ~125 ~119 dirt
setblock ~180 ~125 ~120 dirt
setblock ~180 ~125 ~121 dirt
setblock ~180 ~125 ~122 dirt
setblock ~180 ~125 ~123 dirt
setblock ~180 ~125 ~124 dirt
setblock ~180 ~125 ~125 grass_block
setblock ~180 ~125 ~126 grass_block
setblock ~180 ~126 ~56 dirt
setblock ~180 ~126 ~57 dirt
setblock ~180 ~126 ~58 dirt
setblock ~180 ~126 ~59 dirt
setblock ~180 ~126 ~60 dirt
setblock ~180 ~126 ~61 dirt
setblock ~180 ~126 ~62 dirt
setblock ~180 ~126 ~63 dirt
setblock ~180 ~126 ~64 grass_block
setblock ~180 ~126 ~65 grass_block
setblock ~180 ~126 ~96 short_grass
setblock ~180 ~126 ~98 grass_block
setblock ~180 ~126 ~99 grass_block
setblock ~180 ~126 ~100 grass_block
setblock ~180 ~126 ~101 grass_block
setblock ~180 ~126 ~102 grass_block
setblock ~180 ~126 ~103 grass_block
setblock ~180 ~126 ~104 grass_block
setblock ~180 ~126 ~105 grass_block
setblock ~180 ~126 ~112 short_grass
setblock ~180 ~126 ~114 grass_block
setblock ~180 ~126 ~115 grass_block
setblock ~180 ~126 ~116 dirt
setblock ~180 ~126 ~117 dirt
setblock ~180 ~126 ~118 dirt
setblock ~180 ~126 ~119 dirt
setblock ~180 ~126 ~120 dirt
setblock ~180 ~126 ~121 dirt
setblock ~180 ~126 ~122 dirt
setblock ~180 ~126 ~123 grass_block
setblock ~180 ~126 ~124 grass_block
setblock ~180 ~126 ~125 short_grass
setblock ~180 ~127 ~56 dirt
setblock ~180 ~127 ~57 dirt
setblock ~180 ~127 ~58 dirt
setblock ~180 ~127 ~59 dirt
setblock ~180 ~127 ~60 dirt
setblock ~180 ~127 ~61 dirt
setblock ~180 ~127 ~62 grass_block
setblock ~180 ~127 ~63 grass_block
setblock ~180 ~127 ~102 fern
setblock ~180 ~127 ~104 short_grass
setblock ~180 ~127 ~116 grass_block
setblock ~180 ~127 ~117 grass_block
setblock ~180 ~127 ~118 dirt
setblock ~180 ~127 ~119 dirt
setblock ~180 ~127 ~120 dirt
setblock ~180 ~127 ~121 dirt
setblock ~180 ~127 ~122 grass_block
setblock ~180 ~128 ~56 grass_block
setblock ~180 ~128 ~57 grass_block
setblock ~180 ~128 ~58 grass_block
setblock ~180 ~128 ~59 grass_block
setblock ~180 ~128 ~60 dirt
setblock ~180 ~128 ~61 grass_block
setblock ~180 ~128 ~118 grass_block
setblock ~180 ~128 ~119 grass_block
setblock ~180 ~128 ~120 grass_block
setblock ~180 ~128 ~121 grass_block
setblock ~180 ~129 ~56 short_grass
setblock ~180 ~129 ~58 short_grass
setblock ~180 ~129 ~60 grass_block
setblock ~181 ~105 ~96 dirt
setblock ~181 ~106 ~95 dirt
setblock ~181 ~106 ~96 dirt
setblock ~181 ~106 ~97 dirt
setblock ~181 ~106 ~98 dirt
setblock ~181 ~107 ~94 dirt
setblock ~181 ~107 ~95 dirt
setblock ~181 ~107 ~96 dirt
setblock ~181 ~107 ~97 dirt
setblock ~181 ~107 ~98 dirt
setblock ~181 ~107 ~99 dirt
setblock ~181 ~108 ~93 dirt
setblock ~181 ~108 ~94 dirt
setblock ~181 ~108 ~95 dirt
setblock ~181 ~108 ~96 dirt
setblock ~181 ~108 ~97 dirt
setblock ~181 ~108 ~98 dirt
setblock ~181 ~108 ~99 dirt
setblock ~181 ~108 ~100 dirt
setblock ~181 ~109 ~92 dirt
setblock ~181 ~109 ~93 dirt
setblock ~181 ~109 ~94 dirt
setblock ~181 ~109 ~95 dirt
setblock ~181 ~109 ~96 dirt
setblock ~181 ~109 ~97 dirt
setblock ~181 ~109 ~98 dirt
setblock ~181 ~109 ~99 dirt
setblock ~181 ~109 ~100 dirt
setblock ~181 ~109 ~101 dirt
setblock ~181 ~110 ~92 dirt
setblock ~181 ~110 ~93 dirt
setblock ~181 ~110 ~94 dirt
setblock ~181 ~110 ~95 dirt
setblock ~181 ~110 ~96 dirt
setblock ~181 ~110 ~97 dirt
setblock ~181 ~110 ~98 dirt
setblock ~181 ~110 ~99 dirt
setblock ~181 ~110 ~100 dirt
setblock ~181 ~110 ~101 dirt
setblock ~181 ~111 ~91 dirt
setblock ~181 ~111 ~92 dirt
setblock ~181 ~111 ~93 dirt
setblock ~181 ~111 ~94 dirt
setblock ~181 ~111 ~95 dirt
setblock ~181 ~111 ~96 dirt
setblock ~181 ~111 ~97 dirt
setblock ~181 ~111 ~98 dirt
setblock ~181 ~111 ~99 dirt
setblock ~181 ~111 ~100 dirt
setblock ~181 ~111 ~101 dirt
setblock ~181 ~111 ~102 dirt
setblock ~181 ~112 ~90 dirt
setblock ~181 ~112 ~91 dirt
setblock ~181 ~112 ~92 dirt
setblock ~181 ~112 ~93 dirt
setblock ~181 ~112 ~94 dirt
setblock ~181 ~112 ~95 dirt
setblock ~181 ~112 ~96 dirt
setblock ~181 ~112 ~97 dirt
setblock ~181 ~112 ~98 dirt
setblock ~181 ~112 ~99 dirt
setblock ~181 ~112 ~100 dirt
setblock ~181 ~112 ~101 dirt
setblock ~181 ~112 ~102 dirt
setblock ~181 ~112 ~103 dirt
setblock ~181 ~112 ~106 dirt
setblock ~181 ~113 ~90 dirt
setblock ~181 ~113 ~91 dirt
setblock ~181 ~113 ~92 dirt
setblock ~181 ~113 ~93 dirt
setblock ~181 ~113 ~94 dirt
setblock ~181 ~113 ~95 dirt
setblock ~181 ~113 ~96 dirt
setblock ~181 ~113 ~97 dirt
setblock ~181 ~113 ~98 dirt
setblock ~181 ~113 ~99 dirt
setblock ~181 ~113 ~100 dirt
setblock ~181 ~113 ~101 dirt
setblock ~181 ~113 ~102 dirt
setblock ~181 ~113 ~103 dirt
setblock ~181 ~113 ~104 dirt
setblock ~181 ~113 ~105 dirt
setblock ~181 ~113 ~106 dirt
setblock ~181 ~113 ~107 dirt
setblock ~181 ~114 ~89 dirt
setblock ~181 ~114 ~90 dirt
setblock ~181 ~114 ~91 dirt
setblock ~181 ~114 ~92 dirt
setblock ~181 ~114 ~93 dirt
setblock ~181 ~114 ~94 dirt
setblock ~181 ~114 ~95 dirt
setblock ~181 ~114 ~96 dirt
setblock ~181 ~114 ~97 dirt
setblock ~181 ~114 ~98 dirt
setblock ~181 ~114 ~99 dirt
setblock ~181 ~114 ~100 dirt
setblock ~181 ~114 ~101 dirt
setblock ~181 ~114 ~102 dirt
setblock ~181 ~114 ~103 dirt
setblock ~181 ~114 ~104 dirt
setblock ~181 ~114 ~105 dirt
setblock ~181 ~114 ~106 dirt
setblock ~181 ~114 ~107 dirt
setblock ~181 ~114 ~108 dirt
setblock ~181 ~115 ~88 dirt
setblock ~181 ~115 ~89 dirt
setblock ~181 ~115 ~90 dirt
setblock ~181 ~115 ~91 dirt
setblock ~181 ~115 ~92 dirt
setblock ~181 ~115 ~93 dirt
setblock ~181 ~115 ~94 dirt
setblock ~181 ~115 ~95 dirt
setblock ~181 ~115 ~96 dirt
setblock ~181 ~115 ~97 dirt
setblock ~181 ~115 ~98 dirt
setblock ~181 ~115 ~99 dirt
setblock ~181 ~115 ~100 dirt
setblock ~181 ~115 ~101 dirt
setblock ~181 ~115 ~102 dirt
setblock ~181 ~115 ~103 dirt
setblock ~181 ~115 ~104 dirt
setblock ~181 ~115 ~105 dirt
setblock ~181 ~115 ~106 dirt
setblock ~181 ~115 ~107 dirt
setblock ~181 ~115 ~108 dirt
setblock ~181 ~115 ~109 dirt
setblock ~181 ~115 ~120 dirt
setblock ~181 ~115 ~121 dirt
setblock ~181 ~116 ~87 dirt
setblock ~181 ~116 ~88 dirt
setblock ~181 ~116 ~89 dirt
setblock ~181 ~116 ~90 dirt
setblock ~181 ~116 ~91 dirt
setblock ~181 ~116 ~92 dirt
setblock ~181 ~116 ~93 dirt
setblock ~181 ~116 ~94 dirt
setblock ~181 ~116 ~95 dirt
setblock ~181 ~116 ~96 dirt
setblock ~181 ~116 ~97 dirt
setblock ~181 ~116 ~98 dirt
setblock ~181 ~116 ~99 dirt
setblock ~181 ~116 ~100 dirt
setblock ~181 ~116 ~101 dirt
setblock ~181 ~116 ~102 dirt
setblock ~181 ~116 ~103 dirt
setblock ~181 ~116 ~104 dirt
setblock ~181 ~116 ~105 dirt
setblock ~181 ~116 ~106 dirt
setblock ~181 ~116 ~107 dirt
setblock ~181 ~116 ~108 dirt
setblock ~181 ~116 ~109 dirt
setblock ~181 ~116 ~110 dirt
setblock ~181 ~116 ~119 dirt
setblock ~181 ~116 ~120 dirt
setblock ~181 ~116 ~121 dirt
setblock ~181 ~117 ~86 dirt
setblock ~181 ~117 ~87 dirt
setblock ~181 ~117 ~88 dirt
setblock ~181 ~117 ~89 dirt
setblock ~181 ~117 ~90 dirt
setblock ~181 ~117 ~91 dirt
setblock ~181 ~117 ~92 dirt
setblock ~181 ~117 ~93 dirt
setblock ~181 ~117 ~94 dirt
setblock ~181 ~117 ~95 dirt
setblock ~181 ~117 ~96 dirt
setblock ~181 ~117 ~97 dirt
setblock ~181 ~117 ~98 dirt
setblock ~181 ~117 ~99 dirt
setblock ~181 ~117 ~100 dirt
setblock ~181 ~117 ~101 dirt
setblock ~181 ~117 ~102 dirt
setblock ~181 ~117 ~103 dirt
setblock ~181 ~117 ~104 dirt
setblock ~181 ~117 ~105 dirt
setblock ~181 ~117 ~106 dirt
setblock ~181 ~117 ~107 dirt
setblock ~181 ~117 ~108 dirt
setblock ~181 ~117 ~109 dirt
setblock ~181 ~117 ~110 dirt
setblock ~181 ~117 ~111 dirt
setblock ~181 ~117 ~118 dirt
setblock ~181 ~117 ~119 dirt
setblock ~181 ~117 ~120 dirt
setblock ~181 ~117 ~121 dirt
setblock ~181 ~117 ~122 dirt
setblock ~181 ~117 ~123 dirt
setblock ~181 ~118 ~85 dirt
setblock ~181 ~118 ~86 dirt
setblock ~181 ~118 ~87 dirt
setblock ~181 ~118 ~88 dirt
setblock ~181 ~118 ~89 dirt
setblock ~181 ~118 ~90 dirt
setblock ~181 ~118 ~91 dirt
setblock ~181 ~118 ~92 dirt
setblock ~181 ~118 ~93 dirt
setblock ~181 ~118 ~94 dirt
setblock ~181 ~118 ~95 dirt
setblock ~181 ~118 ~96 dirt
setblock ~181 ~118 ~97 dirt
setblock ~181 ~118 ~98 dirt
setblock ~181 ~118 ~99 dirt
setblock ~181 ~118 ~100 dirt
setblock ~181 ~118 ~101 dirt
setblock ~181 ~118 ~102 dirt
setblock ~181 ~118 ~103 dirt
setblock ~181 ~118 ~104 dirt
setblock ~181 ~118 ~105 dirt
setblock ~181 ~118 ~106 dirt
setblock ~181 ~118 ~107 dirt
setblock ~181 ~118 ~108 dirt
setblock ~181 ~118 ~109 dirt
setblock ~181 ~118 ~110 dirt
setblock ~181 ~118 ~111 dirt
setblock ~181 ~118 ~112 dirt
setblock ~181 ~118 ~117 dirt
setblock ~181 ~118 ~118 dirt
setblock ~181 ~118 ~119 dirt
setblock ~181 ~118 ~120 dirt
setblock ~181 ~118 ~121 dirt
setblock ~181 ~118 ~122 dirt
setblock ~181 ~118 ~123 dirt
setblock ~181 ~118 ~124 dirt
setblock ~181 ~119 ~84 dirt
setblock ~181 ~119 ~85 dirt
setblock ~181 ~119 ~86 dirt
setblock ~181 ~119 ~87 dirt
setblock ~181 ~119 ~88 dirt
setblock ~181 ~119 ~89 dirt
setblock ~181 ~119 ~90 dirt
setblock ~181 ~119 ~91 dirt
setblock ~181 ~119 ~92 dirt
setblock ~181 ~119 ~93 dirt
setblock ~181 ~119 ~94 dirt
setblock ~181 ~119 ~95 dirt
setblock ~181 ~119 ~96 dirt
setblock ~181 ~119 ~97 dirt
setblock ~181 ~119 ~98 dirt
setblock ~181 ~119 ~99 dirt
setblock ~181 ~119 ~100 dirt
setblock ~181 ~119 ~101 dirt
setblock ~181 ~119 ~102 dirt
setblock ~181 ~119 ~103 dirt
setblock ~181 ~119 ~104 dirt
setblock ~181 ~119 ~105 dirt
setblock ~181 ~119 ~106 dirt
setblock ~181 ~119 ~107 dirt
setblock ~181 ~119 ~108 dirt
setblock ~181 ~119 ~109 dirt
setblock ~181 ~119 ~110 dirt
setblock ~181 ~119 ~111 dirt
setblock ~181 ~119 ~112 dirt
setblock ~181 ~119 ~113 dirt
setblock ~181 ~119 ~116 dirt
setblock ~181 ~119 ~117 dirt
setblock ~181 ~119 ~118 dirt
setblock ~181 ~119 ~119 dirt
setblock ~181 ~119 ~120 dirt
setblock ~181 ~119 ~121 dirt
setblock ~181 ~119 ~122 dirt
setblock ~181 ~119 ~123 dirt
setblock ~181 ~119 ~124 dirt
setblock ~181 ~119 ~125 dirt
setblock ~181 ~120 ~60 dirt
setblock ~181 ~120 ~61 dirt
setblock ~181 ~120 ~63 dirt
setblock ~181 ~120 ~83 dirt
setblock ~181 ~120 ~84 dirt
setblock ~181 ~120 ~85 dirt
setblock ~181 ~120 ~86 dirt
setblock ~181 ~120 ~87 dirt
setblock ~181 ~120 ~88 dirt
setblock ~181 ~120 ~89 dirt
setblock ~181 ~120 ~90 dirt
setblock ~181 ~120 ~91 dirt
setblock ~181 ~120 ~92 dirt
setblock ~181 ~120 ~93 dirt
setblock ~181 ~120 ~94 dirt
