setblock ~0 ~1 ~0 gold_block
setblock ~22 ~135 ~70 oak_leaves
setblock ~22 ~136 ~69 oak_leaves
setblock ~22 ~136 ~70 jungle_leaves
setblock ~23 ~135 ~69 oak_leaves
setblock ~23 ~135 ~71 oak_leaves
setblock ~23 ~136 ~69 oak_leaves
setblock ~23 ~136 ~70 jungle_leaves
setblock ~23 ~136 ~71 oak_leaves
setblock ~23 ~137 ~70 oak_leaves
setblock ~23 ~137 ~71 oak_leaves
setblock ~23 ~139 ~61 jungle_leaves
setblock ~23 ~139 ~62 oak_leaves
setblock ~23 ~140 ~62 oak_leaves
setblock ~24 ~135 ~69 jungle_leaves
setblock ~24 ~135 ~71 oak_leaves
setblock ~24 ~136 ~69 oak_leaves
setblock ~24 ~136 ~70 oak_wood
setblock ~24 ~136 ~71 oak_leaves
setblock ~24 ~137 ~69 oak_leaves
setblock ~24 ~137 ~70 jungle_leaves
setblock ~24 ~137 ~71 jungle_leaves
setblock ~24 ~138 ~62 oak_leaves
setblock ~24 ~138 ~63 oak_leaves
setblock ~24 ~139 ~61 oak_leaves
setblock ~24 ~139 ~63 jungle_leaves
setblock ~24 ~140 ~61 oak_leaves
setblock ~24 ~140 ~63 oak_leaves
setblock ~24 ~140 ~64 oak_leaves
setblock ~25 ~121 ~104 dirt
setblock ~25 ~122 ~104 dirt
setblock ~25 ~123 ~104 dirt
setblock ~25 ~124 ~104 dirt
setblock ~25 ~125 ~104 dirt
setblock ~25 ~126 ~104 grass_block
setblock ~25 ~131 ~59 oak_leaves
setblock ~25 ~131 ~61 jungle_leaves
setblock ~25 ~132 ~59 oak_leaves
setblock ~25 ~132 ~60 oak_leaves
setblock ~25 ~132 ~61 oak_leaves
setblock ~25 ~133 ~59 oak_leaves
setblock ~25 ~133 ~60 oak_leaves
setblock ~25 ~133 ~62 jungle_leaves
setblock ~25 ~134 ~59 oak_leaves
setblock ~25 ~134 ~60 oak_leaves
setblock ~25 ~134 ~61 oak_leaves
setblock ~25 ~135 ~60 oak_leaves
setblock ~25 ~135 ~61 jungle_leaves
setblock ~25 ~135 ~62 oak_leaves
setblock ~25 ~135 ~68 oak_leaves
setblock ~25 ~135 ~69 oak_leaves
setblock ~25 ~135 ~70 oak_leaves
setblock ~25 ~135 ~71 oak_leaves
setblock ~25 ~136 ~59 jungle_leaves
setblock ~25 ~136 ~61 oak_leaves
setblock ~25 ~136 ~62 oak_leaves
setblock ~25 ~136 ~69 oak_leaves
setblock ~25 ~136 ~70 oak_wood
setblock ~25 ~136 ~71 jungle_leaves
setblock ~25 ~137 ~63 jungle_leaves
setblock ~25 ~137 ~64 oak_leaves
setblock ~25 ~137 ~65 oak_leaves
setblock ~25 ~137 ~69 oak_leaves
setblock ~25 ~137 ~71 oak_leaves
setblock ~25 ~138 ~63 jungle_leaves
setblock ~25 ~138 ~65 jungle_leaves
setblock ~25 ~139 ~62 oak_leaves
setblock ~25 ~139 ~63 oak_wood
setblock ~25 ~139 ~64 oak_leaves
setblock ~25 ~139 ~65 jungle_leaves
setblock ~25 ~140 ~63 oak_leaves
setblock ~25 ~140 ~64 oak_leaves
setblock ~25 ~140 ~65 oak_leaves
setblock ~26 ~120 ~92 dirt
setblock ~26 ~120 ~99 dirt
setblock ~26 ~120 ~104 dirt
setblock ~26 ~121 ~91 dirt
setblock ~26 ~121 ~92 dirt
setblock ~26 ~121 ~98 dirt
setblock ~26 ~121 ~99 dirt
setblock ~26 ~121 ~100 dirt
setblock ~26 ~121 ~103 dirt
setblock ~26 ~121 ~104 dirt
setblock ~26 ~121 ~105 dirt
setblock ~26 ~122 ~91 dirt
setblock ~26 ~122 ~92 dirt
setblock ~26 ~122 ~98 dirt
setblock ~26 ~122 ~99 dirt
setblock ~26 ~122 ~100 dirt
setblock ~26 ~122 ~103 dirt
setblock ~26 ~122 ~104 dirt
setblock ~26 ~122 ~105 dirt
setblock ~26 ~123 ~91 dirt
setblock ~26 ~123 ~92 dirt
setblock ~26 ~123 ~98 dirt
setblock ~26 ~123 ~99 dirt
setblock ~26 ~123 ~100 dirt
setblock ~26 ~123 ~103 dirt
setblock ~26 ~123 ~104 dirt
setblock ~26 ~123 ~105 dirt
setblock ~26 ~124 ~91 dirt
setblock ~26 ~124 ~92 dirt
setblock ~26 ~124 ~98 dirt
setblock ~26 ~124 ~99 dirt
setblock ~26 ~124 ~100 dirt
setblock ~26 ~124 ~103 dirt
setblock ~26 ~124 ~104 dirt
setblock ~26 ~124 ~105 dirt
setblock ~26 ~125 ~91 dirt
setblock ~26 ~125 ~92 dirt
setblock ~26 ~125 ~98 dirt
setblock ~26 ~125 ~99 grass_block
setblock ~26 ~125 ~100 grass_block
setblock ~26 ~125 ~103 dirt
setblock ~26 ~125 ~104 dirt
setblock ~26 ~125 ~105 dirt
setblock ~26 ~126 ~91 dirt
setblock ~26 ~126 ~92 dirt
setblock ~26 ~126 ~98 grass_block
setblock ~26 ~126 ~103 grass_block
setblock ~26 ~126 ~104 grass_block
setblock ~26 ~126 ~105 dirt
setblock ~26 ~127 ~91 dirt
setblock ~26 ~127 ~92 dirt
setblock ~26 ~127 ~103 poppy
setblock ~26 ~127 ~104 short_grass
setblock ~26 ~127 ~105 grass_block
setblock ~26 ~128 ~91 grass_block
setblock ~26 ~128 ~92 grass_block
setblock ~26 ~129 ~91 poppy
setblock ~26 ~131 ~59 jungle_leaves
setblock ~26 ~131 ~60 jungle_leaves
setblock ~26 ~131 ~61 jungle_leaves
setblock ~26 ~132 ~59 oak_leaves
setblock ~26 ~132 ~60 jungle_leaves
setblock ~26 ~132 ~61 oak_leaves
setblock ~26 ~132 ~62 oak_leaves
setblock ~26 ~132 ~64 oak_leaves
setblock ~26 ~133 ~60 jungle_leaves
setblock ~26 ~133 ~62 oak_leaves
setblock ~26 ~133 ~63 oak_leaves
setblock ~26 ~133 ~64 oak_leaves
setblock ~26 ~134 ~60 oak_leaves
setblock ~26 ~134 ~61 oak_leaves
setblock ~26 ~134 ~63 jungle_leaves
setblock ~26 ~134 ~64 oak_leaves
setblock ~26 ~135 ~59 oak_leaves
setblock ~26 ~135 ~60 oak_leaves
setblock ~26 ~135 ~61 oak_leaves
setblock ~26 ~135 ~63 jungle_leaves
setblock ~26 ~135 ~64 oak_leaves
setblock ~26 ~135 ~65 oak_leaves
setblock ~26 ~135 ~66 oak_leaves
setblock ~26 ~135 ~68 oak_leaves
setblock ~26 ~135 ~69 oak_leaves
setblock ~26 ~135 ~70 jungle_leaves
setblock ~26 ~135 ~71 oak_leaves
setblock ~26 ~136 ~59 jungle_leaves
setblock ~26 ~136 ~60 oak_leaves
setblock ~26 ~136 ~61 oak_leaves
setblock ~26 ~136 ~63 oak_leaves
setblock ~26 ~136 ~65 oak_leaves
setblock ~26 ~136 ~66 oak_leaves
setblock ~26 ~136 ~69 oak_wood
setblock ~26 ~136 ~70 oak_leaves
setblock ~26 ~136 ~71 oak_leaves
setblock ~26 ~137 ~60 oak_leaves
setblock ~26 ~137 ~62 oak_leaves
setblock ~26 ~137 ~63 jungle_leaves
setblock ~26 ~137 ~64 jungle_leaves
setblock ~26 ~137 ~65 oak_leaves
setblock ~26 ~137 ~66 oak_leaves
setblock ~26 ~137 ~67 oak_leaves
setblock ~26 ~137 ~69 oak_leaves
setblock ~26 ~137 ~71 oak_leaves
setblock ~26 ~138 ~62 oak_leaves
setblock ~26 ~138 ~63 oak_leaves
setblock ~26 ~138 ~64 oak_wood
setblock ~26 ~138 ~66 oak_leaves
setblock ~26 ~138 ~67 oak_leaves
setblock ~26 ~139 ~63 oak_leaves
setblock ~26 ~139 ~64 oak_wood
setblock ~26 ~139 ~65 jungle_leaves
setblock ~26 ~139 ~66 oak_leaves
setblock ~26 ~140 ~62 oak_leaves
setblock ~26 ~140 ~63 jungle_leaves
setblock ~27 ~117 ~98 dirt
setblock ~27 ~117 ~99 dirt
setblock ~27 ~118 ~92 dirt
setblock ~27 ~118 ~98 dirt
setblock ~27 ~118 ~99 dirt
setblock ~27 ~119 ~92 dirt
setblock ~27 ~119 ~98 dirt
setblock ~27 ~119 ~99 dirt
setblock ~27 ~119 ~100 dirt
setblock ~27 ~119 ~103 dirt
setblock ~27 ~119 ~104 dirt
setblock ~27 ~120 ~80 dirt
setblock ~27 ~120 ~81 dirt
setblock ~27 ~120 ~91 dirt
setblock ~27 ~120 ~92 dirt
setblock ~27 ~120 ~93 dirt
setblock ~27 ~120 ~96 dirt
setblock ~27 ~120 ~98 dirt
setblock ~27 ~120 ~99 dirt
setblock ~27 ~120 ~100 dirt
setblock ~27 ~120 ~101 dirt
setblock ~27 ~120 ~103 dirt
setblock ~27 ~120 ~104 dirt
setblock ~27 ~120 ~105 dirt
setblock ~27 ~121 ~80 dirt
setblock ~27 ~121 ~81 dirt
setblock ~27 ~121 ~82 dirt
setblock ~27 ~121 ~90 dirt
setblock ~27 ~121 ~91 dirt
setblock ~27 ~121 ~92 dirt
setblock ~27 ~121 ~93 dirt
setblock ~27 ~121 ~95 dirt
setblock ~27 ~121 ~96 dirt
setblock ~27 ~121 ~97 dirt
setblock ~27 ~121 ~98 dirt
setblock ~27 ~121 ~99 dirt
setblock ~27 ~121 ~100 dirt
setblock ~27 ~121 ~101 dirt
setblock ~27 ~121 ~102 dirt
setblock ~27 ~121 ~103 dirt
setblock ~27 ~121 ~104 dirt
setblock ~27 ~121 ~105 dirt
setblock ~27 ~121 ~106 dirt
setblock ~27 ~121 ~108 dirt
setblock ~27 ~122 ~80 dirt
setblock ~27 ~122 ~81 dirt
setblock ~27 ~122 ~82 dirt
setblock ~27 ~122 ~90 dirt
setblock ~27 ~122 ~91 dirt
setblock ~27 ~122 ~92 dirt
setblock ~27 ~122 ~93 dirt
setblock ~27 ~122 ~95 dirt
setblock ~27 ~122 ~96 dirt
setblock ~27 ~122 ~97 dirt
setblock ~27 ~122 ~98 dirt
setblock ~27 ~122 ~99 dirt
setblock ~27 ~122 ~100 dirt
setblock ~27 ~122 ~101 dirt
setblock ~27 ~122 ~102 dirt
setblock ~27 ~122 ~103 dirt
setblock ~27 ~122 ~104 dirt
setblock ~27 ~122 ~105 dirt
setblock ~27 ~122 ~106 dirt
setblock ~27 ~122 ~108 dirt
setblock ~27 ~123 ~80 dirt
setblock ~27 ~123 ~81 dirt
setblock ~27 ~123 ~82 dirt
setblock ~27 ~123 ~90 dirt
setblock ~27 ~123 ~91 dirt
setblock ~27 ~123 ~92 dirt
setblock ~27 ~123 ~93 dirt
setblock ~27 ~123 ~95 dirt
setblock ~27 ~123 ~96 dirt
setblock ~27 ~123 ~97 dirt
setblock ~27 ~123 ~98 dirt
setblock ~27 ~123 ~99 dirt
setblock ~27 ~123 ~100 dirt
setblock ~27 ~123 ~101 dirt
setblock ~27 ~123 ~102 dirt
setblock ~27 ~123 ~103 dirt
setblock ~27 ~123 ~104 dirt
setblock ~27 ~123 ~105 dirt
setblock ~27 ~123 ~106 dirt
setblock ~27 ~123 ~108 dirt
setblock ~27 ~124 ~80 dirt
setblock ~27 ~124 ~81 dirt
setblock ~27 ~124 ~82 dirt
setblock ~27 ~124 ~90 dirt
setblock ~27 ~124 ~91 dirt
setblock ~27 ~124 ~92 dirt
setblock ~27 ~124 ~93 dirt
setblock ~27 ~124 ~95 dirt
setblock ~27 ~124 ~96 dirt
setblock ~27 ~124 ~97 dirt
setblock ~27 ~124 ~98 dirt
setblock ~27 ~124 ~99 dirt
setblock ~27 ~124 ~100 dirt
setblock ~27 ~124 ~101 dirt
setblock ~27 ~124 ~102 dirt
setblock ~27 ~124 ~103 dirt
setblock ~27 ~124 ~104 dirt
setblock ~27 ~124 ~105 dirt
setblock ~27 ~124 ~106 dirt
setblock ~27 ~124 ~108 dirt
setblock ~27 ~125 ~80 dirt
setblock ~27 ~125 ~81 dirt
setblock ~27 ~125 ~82 dirt
setblock ~27 ~125 ~90 dirt
setblock ~27 ~125 ~91 dirt
setblock ~27 ~125 ~92 dirt
setblock ~27 ~125 ~93 dirt
setblock ~27 ~125 ~95 dirt
setblock ~27 ~125 ~96 dirt
setblock ~27 ~125 ~97 dirt
setblock ~27 ~125 ~98 dirt
setblock ~27 ~125 ~99 dirt
setblock ~27 ~125 ~100 dirt
setblock ~27 ~125 ~101 dirt
setblock ~27 ~125 ~102 dirt
setblock ~27 ~125 ~103 dirt
setblock ~27 ~125 ~104 dirt
setblock ~27 ~125 ~105 dirt
setblock ~27 ~125 ~106 dirt
setblock ~27 ~125 ~108 dirt
setblock ~27 ~126 ~80 grass_block
setblock ~27 ~126 ~81 grass_block
setblock ~27 ~126 ~82 grass_block
setblock ~27 ~126 ~90 dirt
setblock ~27 ~126 ~91 dirt
setblock ~27 ~126 ~92 dirt
setblock ~27 ~126 ~93 dirt
setblock ~27 ~126 ~95 dirt
setblock ~27 ~126 ~96 dirt
setblock ~27 ~126 ~97 grass_block
setblock ~27 ~126 ~98 grass_block
setblock ~27 ~126 ~99 grass_block
setblock ~27 ~126 ~100 grass_block
setblock ~27 ~126 ~101 grass_block
setblock ~27 ~126 ~102 grass_block
setblock ~27 ~126 ~103 grass_block
setblock ~27 ~126 ~104 dirt
setblock ~27 ~126 ~105 dirt
setblock ~27 ~126 ~106 dirt
setblock ~27 ~126 ~108 dirt
setblock ~27 ~127 ~82 short_grass
setblock ~27 ~127 ~90 dirt
setblock ~27 ~127 ~91 dirt
setblock ~27 ~127 ~92 dirt
setblock ~27 ~127 ~93 grass_block
setblock ~27 ~127 ~95 grass_block
setblock ~27 ~127 ~96 grass_block
setblock ~27 ~127 ~99 short_grass
setblock ~27 ~127 ~101 short_grass
setblock ~27 ~127 ~102 short_grass
setblock ~27 ~127 ~104 grass_block
setblock ~27 ~127 ~105 grass_block
setblock ~27 ~127 ~106 grass_block
setblock ~27 ~127 ~108 dirt
setblock ~27 ~128 ~90 dirt
setblock ~27 ~128 ~91 grass_block
setblock ~27 ~128 ~92 grass_block
setblock ~27 ~128 ~95 fern
setblock ~27 ~128 ~104 short_grass
setblock ~27 ~128 ~105 short_grass
setblock ~27 ~128 ~108 grass_block
setblock ~27 ~129 ~90 grass_block
setblock ~27 ~130 ~90 poppy
setblock ~27 ~131 ~59 oak_leaves
setblock ~27 ~131 ~60 jungle_leaves
setblock ~27 ~131 ~61 jungle_leaves
setblock ~27 ~132 ~63 oak_leaves
setblock ~27 ~132 ~64 oak_leaves
setblock ~27 ~133 ~59 oak_leaves
setblock ~27 ~133 ~60 oak_leaves
setblock ~27 ~133 ~61 oak_wood
setblock ~27 ~133 ~62 jungle_leaves
setblock ~27 ~134 ~59 oak_leaves
setblock ~27 ~134 ~60 oak_leaves
setblock ~27 ~134 ~62 oak_leaves
setblock ~27 ~134 ~64 oak_leaves
setblock ~27 ~134 ~65 jungle_leaves
setblock ~27 ~134 ~66 oak_leaves
setblock ~27 ~134 ~67 oak_leaves
setblock ~27 ~135 ~59 jungle_leaves
setblock ~27 ~135 ~61 oak_wood
setblock ~27 ~135 ~62 jungle_leaves
setblock ~27 ~135 ~63 oak_leaves
setblock ~27 ~135 ~64 oak_leaves
setblock ~27 ~135 ~65 oak_leaves
setblock ~27 ~135 ~66 oak_leaves
setblock ~27 ~135 ~67 jungle_leaves
setblock ~27 ~136 ~59 jungle_leaves
setblock ~27 ~136 ~60 oak_leaves
setblock ~27 ~136 ~61 oak_leaves
setblock ~27 ~136 ~63 oak_leaves
setblock ~27 ~136 ~64 oak_leaves
setblock ~27 ~136 ~65 oak_leaves
setblock ~27 ~136 ~66 jungle_leaves
setblock ~27 ~136 ~67 oak_leaves
setblock ~27 ~136 ~68 jungle_leaves
setblock ~27 ~136 ~69 oak_wood
setblock ~27 ~137 ~60 oak_leaves
setblock ~27 ~137 ~61 oak_leaves
setblock ~27 ~137 ~62 oak_leaves
setblock ~27 ~137 ~63 jungle_leaves
setblock ~27 ~137 ~68 jungle_leaves
setblock ~27 ~137 ~69 oak_leaves
setblock ~27 ~138 ~63 oak_leaves
setblock ~27 ~138 ~65 oak_wood
setblock ~27 ~138 ~66 oak_leaves
setblock ~27 ~138 ~67 oak_leaves
setblock ~27 ~138 ~68 jungle_leaves
setblock ~27 ~138 ~69 oak_leaves
setblock ~27 ~139 ~64 oak_leaves
setblock ~27 ~139 ~65 oak_leaves
setblock ~27 ~139 ~67 jungle_leaves
setblock ~27 ~139 ~68 oak_leaves
setblock ~27 ~139 ~69 jungle_leaves
setblock ~27 ~140 ~63 oak_leaves
setblock ~27 ~140 ~65 jungle_leaves
setblock ~27 ~140 ~66 jungle_leaves
setblock ~27 ~140 ~67 oak_leaves
setblock ~27 ~140 ~68 oak_leaves
setblock ~28 ~115 ~99 dirt
setblock ~28 ~116 ~92 dirt
setblock ~28 ~116 ~98 dirt
setblock ~28 ~116 ~99 dirt
setblock ~28 ~117 ~81 dirt
setblock ~28 ~117 ~92 dirt
setblock ~28 ~117 ~96 dirt
setblock ~28 ~117 ~97 dirt
setblock ~28 ~117 ~98 dirt
setblock ~28 ~117 ~99 dirt
setblock ~28 ~117 ~100 dirt
setblock ~28 ~117 ~102 dirt
setblock ~28 ~117 ~104 dirt
setblock ~28 ~118 ~81 dirt
setblock ~28 ~118 ~91 dirt
setblock ~28 ~118 ~92 dirt
setblock ~28 ~118 ~93 dirt
setblock ~28 ~118 ~95 dirt
setblock ~28 ~118 ~96 dirt
setblock ~28 ~118 ~97 dirt
setblock ~28 ~118 ~98 dirt
setblock ~28 ~118 ~99 dirt
setblock ~28 ~118 ~100 dirt
setblock ~28 ~118 ~101 dirt
setblock ~28 ~118 ~102 dirt
setblock ~28 ~118 ~103 dirt
setblock ~28 ~118 ~104 dirt
setblock ~28 ~118 ~105 dirt
setblock ~28 ~118 ~124 dirt
setblock ~28 ~119 ~80 dirt
setblock ~28 ~119 ~81 dirt
setblock ~28 ~119 ~82 dirt
setblock ~28 ~119 ~83 dirt
setblock ~28 ~119 ~90 dirt
setblock ~28 ~119 ~91 dirt
setblock ~28 ~119 ~92 dirt
setblock ~28 ~119 ~93 dirt
setblock ~28 ~119 ~95 dirt
setblock ~28 ~119 ~96 dirt
setblock ~28 ~119 ~97 dirt
setblock ~28 ~119 ~98 dirt
setblock ~28 ~119 ~99 dirt
setblock ~28 ~119 ~100 dirt
setblock ~28 ~119 ~101 dirt
setblock ~28 ~119 ~102 dirt
setblock ~28 ~119 ~103 dirt
setblock ~28 ~119 ~104 dirt
setblock ~28 ~119 ~105 dirt
setblock ~28 ~119 ~124 dirt
setblock ~28 ~120 ~79 dirt
setblock ~28 ~120 ~80 dirt
setblock ~28 ~120 ~81 dirt
setblock ~28 ~120 ~82 dirt
setblock ~28 ~120 ~83 dirt
setblock ~28 ~120 ~90 dirt
setblock ~28 ~120 ~91 dirt
setblock ~28 ~120 ~92 dirt
setblock ~28 ~120 ~93 dirt
setblock ~28 ~120 ~95 dirt
setblock ~28 ~120 ~96 dirt
setblock ~28 ~120 ~97 dirt
setblock ~28 ~120 ~98 dirt
setblock ~28 ~120 ~99 dirt
setblock ~28 ~120 ~100 dirt
setblock ~28 ~120 ~101 dirt
setblock ~28 ~120 ~102 dirt
setblock ~28 ~120 ~103 dirt
setblock ~28 ~120 ~104 dirt
setblock ~28 ~120 ~105 dirt
setblock ~28 ~120 ~106 dirt
setblock ~28 ~120 ~107 dirt
setblock ~28 ~120 ~108 dirt
setblock ~28 ~120 ~124 dirt
setblock ~28 ~121 ~77 dirt
setblock ~28 ~121 ~79 dirt
setblock ~28 ~121 ~80 dirt
setblock ~28 ~121 ~81 dirt
setblock ~28 ~121 ~82 dirt
setblock ~28 ~121 ~83 dirt
setblock ~28 ~121 ~85 dirt
setblock ~28 ~121 ~88 dirt
setblock ~28 ~121 ~89 dirt
setblock ~28 ~121 ~90 dirt
setblock ~28 ~121 ~91 dirt
setblock ~28 ~121 ~92 dirt
setblock ~28 ~121 ~93 dirt
setblock ~28 ~121 ~94 dirt
setblock ~28 ~121 ~95 dirt
setblock ~28 ~121 ~96 dirt
setblock ~28 ~121 ~97 dirt
setblock ~28 ~121 ~98 dirt
setblock ~28 ~121 ~99 dirt
setblock ~28 ~121 ~100 dirt
setblock ~28 ~121 ~101 dirt
setblock ~28 ~121 ~102 dirt
setblock ~28 ~121 ~103 dirt
setblock ~28 ~121 ~104 dirt
setblock ~28 ~121 ~105 dirt
setblock ~28 ~121 ~106 dirt
setblock ~28 ~121 ~107 dirt
setblock ~28 ~121 ~108 dirt
setblock ~28 ~121 ~109 dirt
setblock ~28 ~121 ~124 dirt
setblock ~28 ~122 ~77 dirt
setblock ~28 ~122 ~79 dirt
setblock ~28 ~122 ~80 dirt
setblock ~28 ~122 ~81 dirt
setblock ~28 ~122 ~82 dirt
setblock ~28 ~122 ~83 dirt
setblock ~28 ~122 ~85 dirt
setblock ~28 ~122 ~88 dirt
setblock ~28 ~122 ~89 dirt
setblock ~28 ~122 ~90 dirt
setblock ~28 ~122 ~91 dirt
setblock ~28 ~122 ~92 dirt
setblock ~28 ~122 ~93 dirt
setblock ~28 ~122 ~94 dirt
setblock ~28 ~122 ~95 dirt
setblock ~28 ~122 ~96 dirt
setblock ~28 ~122 ~97 dirt
setblock ~28 ~122 ~98 dirt
setblock ~28 ~122 ~99 dirt
setblock ~28 ~122 ~100 dirt
setblock ~28 ~122 ~101 dirt
setblock ~28 ~122 ~102 dirt
setblock ~28 ~122 ~103 dirt
setblock ~28 ~122 ~104 dirt
setblock ~28 ~122 ~105 dirt
setblock ~28 ~122 ~106 dirt
setblock ~28 ~122 ~107 dirt
setblock ~28 ~122 ~108 dirt
setblock ~28 ~122 ~109 dirt
setblock ~28 ~122 ~124 dirt
setblock ~28 ~123 ~77 dirt
setblock ~28 ~123 ~79 dirt
setblock ~28 ~123 ~80 dirt
setblock ~28 ~123 ~81 dirt
setblock ~28 ~123 ~82 dirt
setblock ~28 ~123 ~83 dirt
setblock ~28 ~123 ~85 dirt
setblock ~28 ~123 ~88 dirt
setblock ~28 ~123 ~89 dirt
setblock ~28 ~123 ~90 dirt
setblock ~28 ~123 ~91 dirt
setblock ~28 ~123 ~92 dirt
setblock ~28 ~123 ~93 dirt
setblock ~28 ~123 ~94 dirt
setblock ~28 ~123 ~95 dirt
setblock ~28 ~123 ~96 dirt
setblock ~28 ~123 ~97 dirt
setblock ~28 ~123 ~98 dirt
setblock ~28 ~123 ~99 dirt
setblock ~28 ~123 ~100 dirt
setblock ~28 ~123 ~101 dirt
setblock ~28 ~123 ~102 dirt
setblock ~28 ~123 ~103 dirt
setblock ~28 ~123 ~104 dirt
setblock ~28 ~123 ~105 dirt
setblock ~28 ~123 ~106 dirt
setblock ~28 ~123 ~107 dirt
setblock ~28 ~123 ~108 dirt
setblock ~28 ~123 ~109 dirt
setblock ~28 ~123 ~124 dirt
setblock ~28 ~124 ~77 dirt
setblock ~28 ~124 ~79 dirt
setblock ~28 ~124 ~80 dirt
setblock ~28 ~124 ~81 dirt
setblock ~28 ~124 ~82 dirt
setblock ~28 ~124 ~83 dirt
setblock ~28 ~124 ~85 dirt
setblock ~28 ~124 ~88 dirt
setblock ~28 ~124 ~89 dirt
setblock ~28 ~124 ~90 dirt
setblock ~28 ~124 ~91 dirt
setblock ~28 ~124 ~92 dirt
setblock ~28 ~124 ~93 dirt
setblock ~28 ~124 ~94 dirt
setblock ~28 ~124 ~95 dirt
setblock ~28 ~124 ~96 dirt
setblock ~28 ~124 ~97 dirt
setblock ~28 ~124 ~98 dirt
setblock ~28 ~124 ~99 dirt
setblock ~28 ~124 ~100 dirt
setblock ~28 ~124 ~101 dirt
setblock ~28 ~124 ~102 dirt
setblock ~28 ~124 ~103 dirt
setblock ~28 ~124 ~104 dirt
setblock ~28 ~124 ~105 dirt
setblock ~28 ~124 ~106 dirt
setblock ~28 ~124 ~107 dirt
setblock ~28 ~124 ~108 dirt
setblock ~28 ~124 ~109 dirt
setblock ~28 ~124 ~124 dirt
setblock ~28 ~125 ~77 dirt
setblock ~28 ~125 ~79 dirt
setblock ~28 ~125 ~80 dirt
setblock ~28 ~125 ~81 dirt
setblock ~28 ~125 ~82 dirt
setblock ~28 ~125 ~83 dirt
setblock ~28 ~125 ~85 dirt
setblock ~28 ~125 ~88 dirt
setblock ~28 ~125 ~89 dirt
setblock ~28 ~125 ~90 dirt
setblock ~28 ~125 ~91 dirt
setblock ~28 ~125 ~92 dirt
setblock ~28 ~125 ~93 dirt
setblock ~28 ~125 ~94 dirt
setblock ~28 ~125 ~95 dirt
setblock ~28 ~125 ~96 dirt
setblock ~28 ~125 ~97 dirt
setblock ~28 ~125 ~98 dirt
setblock ~28 ~125 ~99 dirt
setblock ~28 ~125 ~100 dirt
setblock ~28 ~125 ~101 dirt
setblock ~28 ~125 ~102 dirt
setblock ~28 ~125 ~103 dirt
setblock ~28 ~125 ~104 dirt
setblock ~28 ~125 ~105 dirt
setblock ~28 ~125 ~106 dirt
setblock ~28 ~125 ~107 dirt
setblock ~28 ~125 ~108 dirt
setblock ~28 ~125 ~109 dirt
setblock ~28 ~125 ~124 dirt
setblock ~28 ~126 ~77 grass_block
setblock ~28 ~126 ~79 grass_block
setblock ~28 ~126 ~80 grass_block
setblock ~28 ~126 ~81 grass_block
setblock ~28 ~126 ~82 grass_block
setblock ~28 ~126 ~83 grass_block
setblock ~28 ~126 ~85 dirt
setblock ~28 ~126 ~88 dirt
setblock ~28 ~126 ~89 dirt
setblock ~28 ~126 ~90 dirt
setblock ~28 ~126 ~91 dirt
setblock ~28 ~126 ~92 dirt
setblock ~28 ~126 ~93 dirt
setblock ~28 ~126 ~94 dirt
setblock ~28 ~126 ~95 dirt
setblock ~28 ~126 ~96 dirt
setblock ~28 ~126 ~97 dirt
setblock ~28 ~126 ~98 dirt
setblock ~28 ~126 ~99 grass_block
setblock ~28 ~126 ~100 grass_block
setblock ~28 ~126 ~101 grass_block
setblock ~28 ~126 ~102 dirt
setblock ~28 ~126 ~103 dirt
setblock ~28 ~126 ~104 dirt
setblock ~28 ~126 ~105 dirt
setblock ~28 ~126 ~106 dirt
setblock ~28 ~126 ~107 dirt
setblock ~28 ~126 ~108 dirt
setblock ~28 ~126 ~109 dirt
setblock ~28 ~126 ~124 grass_block
setblock ~28 ~127 ~80 short_grass
setblock ~28 ~127 ~83 short_grass
setblock ~28 ~127 ~85 grass_block
setblock ~28 ~127 ~88 dirt
setblock ~28 ~127 ~89 dirt
setblock ~28 ~127 ~90 dirt
setblock ~28 ~127 ~91 dirt
setblock ~28 ~127 ~92 dirt
setblock ~28 ~127 ~93 dirt
setblock ~28 ~127 ~94 grass_block
setblock ~28 ~127 ~95 grass_block
setblock ~28 ~127 ~96 grass_block
setblock ~28 ~127 ~97 grass_block
setblock ~28 ~127 ~98 grass_block
setblock ~28 ~127 ~99 short_grass
setblock ~28 ~127 ~102 grass_block
setblock ~28 ~127 ~103 grass_block
setblock ~28 ~127 ~104 grass_block
setblock ~28 ~127 ~105 dirt
setblock ~28 ~127 ~106 dirt
setblock ~28 ~127 ~107 dirt
setblock ~28 ~127 ~108 dirt
setblock ~28 ~127 ~109 dirt
setblock ~28 ~128 ~88 grass_block
setblock ~28 ~128 ~89 grass_block
setblock ~28 ~128 ~90 dirt
setblock ~28 ~128 ~91 grass_block
setblock ~28 ~128 ~92 grass_block
setblock ~28 ~128 ~93 grass_block
setblock ~28 ~128 ~95 short_grass
setblock ~28 ~128 ~105 grass_block
setblock ~28 ~128 ~106 grass_block
setblock ~28 ~128 ~107 grass_block
setblock ~28 ~128 ~108 dirt
setblock ~28 ~128 ~109 dirt
setblock ~28 ~129 ~90 grass_block
setblock ~28 ~129 ~91 short_grass
setblock ~28 ~129 ~92 fern
setblock ~28 ~129 ~105 short_grass
setblock ~28 ~129 ~106 short_grass
setblock ~28 ~129 ~108 grass_block
setblock ~28 ~129 ~109 grass_block
setblock ~28 ~130 ~64 oak_leaves
setblock ~28 ~130 ~65 oak_leaves
setblock ~28 ~130 ~108 fern
setblock ~28 ~131 ~63 jungle_leaves
setblock ~28 ~131 ~64 oak_leaves
setblock ~28 ~131 ~65 oak_leaves
setblock ~28 ~131 ~66 oak_leaves
setblock ~28 ~131 ~67 oak_leaves
setblock ~28 ~131 ~68 oak_leaves
setblock ~28 ~131 ~69 oak_leaves
setblock ~28 ~132 ~61 oak_leaves
setblock ~28 ~132 ~62 jungle_leaves
setblock ~28 ~132 ~64 jungle_leaves
setblock ~28 ~132 ~66 oak_leaves
setblock ~28 ~132 ~67 oak_leaves
setblock ~28 ~132 ~69 oak_leaves
setblock ~28 ~133 ~59 oak_leaves
setblock ~28 ~133 ~61 jungle_leaves
setblock ~28 ~133 ~62 oak_wood
setblock ~28 ~133 ~63 oak_leaves
setblock ~28 ~133 ~64 oak_leaves
setblock ~28 ~133 ~65 jungle_leaves
setblock ~28 ~133 ~66 oak_leaves
setblock ~28 ~133 ~67 oak_leaves
setblock ~28 ~133 ~68 oak_leaves
setblock ~28 ~133 ~69 oak_leaves
setblock ~28 ~134 ~59 oak_leaves
setblock ~28 ~134 ~60 oak_leaves
setblock ~28 ~134 ~62 oak_leaves
setblock ~28 ~134 ~63 oak_wood
setblock ~28 ~134 ~65 jungle_leaves
setblock ~28 ~134 ~67 jungle_leaves
setblock ~28 ~134 ~69 jungle_leaves
setblock ~28 ~135 ~59 oak_leaves
setblock ~28 ~135 ~60 oak_leaves
setblock ~28 ~135 ~61 jungle_leaves
setblock ~28 ~135 ~62 oak_wood
setblock ~28 ~135 ~64 jungle_leaves
setblock ~28 ~135 ~65 jungle_leaves
setblock ~28 ~135 ~66 oak_leaves
setblock ~28 ~135 ~68 jungle_leaves
setblock ~28 ~136 ~59 oak_leaves
setblock ~28 ~136 ~60 oak_leaves
setblock ~28 ~136 ~62 oak_wood
setblock ~28 ~136 ~63 oak_leaves
setblock ~28 ~136 ~64 oak_leaves
setblock ~28 ~136 ~65 oak_leaves
setblock ~28 ~136 ~67 oak_leaves
setblock ~28 ~136 ~69 oak_wood
setblock ~28 ~137 ~60 oak_leaves
setblock ~28 ~137 ~61 jungle_leaves
setblock ~28 ~137 ~62 oak_leaves
setblock ~28 ~137 ~63 oak_leaves
setblock ~28 ~137 ~64 oak_leaves
setblock ~28 ~137 ~65 oak_wood
setblock ~28 ~137 ~66 oak_wood
setblock ~28 ~138 ~62 oak_leaves
setblock ~28 ~138 ~63 oak_leaves
setblock ~28 ~138 ~65 oak_leaves
setblock ~28 ~138 ~66 oak_leaves
setblock ~28 ~138 ~67 jungle_leaves
setblock ~28 ~138 ~68 jungle_leaves
setblock ~28 ~139 ~63 jungle_leaves
setblock ~28 ~139 ~65 oak_leaves
setblock ~28 ~139 ~66 oak_leaves
setblock ~28 ~139 ~67 oak_leaves
setblock ~28 ~139 ~69 oak_leaves
setblock ~28 ~140 ~64 oak_leaves
setblock ~28 ~140 ~65 oak_leaves
setblock ~28 ~140 ~66 oak_leaves
setblock ~29 ~112 ~98 dirt
setblock ~29 ~113 ~98 dirt
setblock ~29 ~113 ~99 dirt
setblock ~29 ~114 ~98 dirt
setblock ~29 ~114 ~99 dirt
setblock ~29 ~115 ~81 dirt
setblock ~29 ~115 ~91 dirt
setblock ~29 ~115 ~92 dirt
setblock ~29 ~115 ~93 dirt
setblock ~29 ~115 ~96 dirt
setblock ~29 ~115 ~98 dirt
setblock ~29 ~115 ~99 dirt
setblock ~29 ~115 ~100 dirt
setblock ~29 ~115 ~102 dirt
setblock ~29 ~115 ~104 dirt
setblock ~29 ~116 ~80 dirt
setblock ~29 ~116 ~81 dirt
setblock ~29 ~116 ~91 dirt
setblock ~29 ~116 ~92 dirt
setblock ~29 ~116 ~93 dirt
setblock ~29 ~116 ~95 dirt
setblock ~29 ~116 ~96 dirt
setblock ~29 ~116 ~97 dirt
setblock ~29 ~116 ~98 dirt
setblock ~29 ~116 ~99 dirt
setblock ~29 ~116 ~100 dirt
setblock ~29 ~116 ~102 dirt
setblock ~29 ~116 ~104 dirt
setblock ~29 ~117 ~80 dirt
setblock ~29 ~117 ~81 dirt
setblock ~29 ~117 ~82 dirt
setblock ~29 ~117 ~91 dirt
setblock ~29 ~117 ~92 dirt
setblock ~29 ~117 ~93 dirt
setblock ~29 ~117 ~95 dirt
setblock ~29 ~117 ~96 dirt
setblock ~29 ~117 ~97 dirt
setblock ~29 ~117 ~98 dirt
setblock ~29 ~117 ~99 dirt
setblock ~29 ~117 ~100 dirt
setblock ~29 ~117 ~101 dirt
setblock ~29 ~117 ~102 dirt
setblock ~29 ~117 ~103 dirt
setblock ~29 ~117 ~104 dirt
setblock ~29 ~117 ~105 dirt
setblock ~29 ~117 ~124 dirt
setblock ~29 ~118 ~79 dirt
setblock ~29 ~118 ~80 dirt
setblock ~29 ~118 ~81 dirt
setblock ~29 ~118 ~82 dirt
setblock ~29 ~118 ~83 dirt
setblock ~29 ~118 ~90 dirt
setblock ~29 ~118 ~91 dirt
setblock ~29 ~118 ~92 dirt
setblock ~29 ~118 ~93 dirt
setblock ~29 ~118 ~94 dirt
setblock ~29 ~118 ~95 dirt
setblock ~29 ~118 ~96 dirt
setblock ~29 ~118 ~97 dirt
setblock ~29 ~118 ~98 dirt
setblock ~29 ~118 ~99 dirt
setblock ~29 ~118 ~100 dirt
setblock ~29 ~118 ~101 dirt
setblock ~29 ~118 ~102 dirt
setblock ~29 ~118 ~103 dirt
setblock ~29 ~118 ~104 dirt
setblock ~29 ~118 ~105 dirt
setblock ~29 ~118 ~106 dirt
setblock ~29 ~118 ~107 dirt
setblock ~29 ~118 ~123 dirt
setblock ~29 ~118 ~124 dirt
setblock ~29 ~118 ~125 dirt
setblock ~29 ~119 ~79 dirt
setblock ~29 ~119 ~80 dirt
setblock ~29 ~119 ~81 dirt
setblock ~29 ~119 ~82 dirt
setblock ~29 ~119 ~83 dirt
setblock ~29 ~119 ~84 dirt
setblock ~29 ~119 ~89 dirt
setblock ~29 ~119 ~90 dirt
setblock ~29 ~119 ~91 dirt
setblock ~29 ~119 ~92 dirt
setblock ~29 ~119 ~93 dirt
setblock ~29 ~119 ~94 dirt
setblock ~29 ~119 ~95 dirt
setblock ~29 ~119 ~96 dirt
setblock ~29 ~119 ~97 dirt
setblock ~29 ~119 ~98 dirt
setblock ~29 ~119 ~99 dirt
setblock ~29 ~119 ~100 dirt
setblock ~29 ~119 ~101 dirt
setblock ~29 ~119 ~102 dirt
setblock ~29 ~119 ~103 dirt
setblock ~29 ~119 ~104 dirt
setblock ~29 ~119 ~105 dirt
setblock ~29 ~119 ~106 dirt
setblock ~29 ~119 ~107 dirt
setblock ~29 ~119 ~108 dirt
setblock ~29 ~119 ~123 dirt
setblock ~29 ~119 ~124 dirt
setblock ~29 ~119 ~125 dirt
setblock ~29 ~120 ~75 dirt
setblock ~29 ~120 ~76 dirt
setblock ~29 ~120 ~77 dirt
setblock ~29 ~120 ~79 dirt
setblock ~29 ~120 ~80 dirt
setblock ~29 ~120 ~81 dirt
setblock ~29 ~120 ~82 dirt
setblock ~29 ~120 ~83 dirt
setblock ~29 ~120 ~84 dirt
setblock ~29 ~120 ~85 dirt
setblock ~29 ~120 ~88 dirt
setblock ~29 ~120 ~89 dirt
setblock ~29 ~120 ~90 dirt
setblock ~29 ~120 ~91 dirt
setblock ~29 ~120 ~92 dirt
setblock ~29 ~120 ~93 dirt
setblock ~29 ~120 ~94 dirt
setblock ~29 ~120 ~95 dirt
setblock ~29 ~120 ~96 dirt
setblock ~29 ~120 ~97 dirt
setblock ~29 ~120 ~98 dirt
setblock ~29 ~120 ~99 dirt
setblock ~29 ~120 ~100 dirt
setblock ~29 ~120 ~101 dirt
setblock ~29 ~120 ~102 dirt
setblock ~29 ~120 ~103 dirt
setblock ~29 ~120 ~104 dirt
setblock ~29 ~120 ~105 dirt
setblock ~29 ~120 ~106 dirt
setblock ~29 ~120 ~107 dirt
setblock ~29 ~120 ~108 dirt
setblock ~29 ~120 ~109 dirt
setblock ~29 ~120 ~122 dirt
setblock ~29 ~120 ~123 dirt
setblock ~29 ~120 ~124 dirt
setblock ~29 ~120 ~125 dirt
setblock ~29 ~120 ~126 dirt
setblock ~29 ~121 ~75 dirt
setblock ~29 ~121 ~76 dirt
setblock ~29 ~121 ~77 dirt
setblock ~29 ~121 ~78 dirt
setblock ~29 ~121 ~79 dirt
setblock ~29 ~121 ~80 dirt
setblock ~29 ~121 ~81 dirt
setblock ~29 ~121 ~82 dirt
setblock ~29 ~121 ~83 dirt
setblock ~29 ~121 ~84 dirt
setblock ~29 ~121 ~85 dirt
setblock ~29 ~121 ~86 dirt
setblock ~29 ~121 ~87 dirt
setblock ~29 ~121 ~88 dirt
setblock ~29 ~121 ~89 dirt
setblock ~29 ~121 ~90 dirt
setblock ~29 ~121 ~91 dirt
setblock ~29 ~121 ~92 dirt
setblock ~29 ~121 ~93 dirt
setblock ~29 ~121 ~94 dirt
setblock ~29 ~121 ~95 dirt
setblock ~29 ~121 ~96 dirt
setblock ~29 ~121 ~97 dirt
setblock ~29 ~121 ~98 dirt
setblock ~29 ~121 ~99 dirt
setblock ~29 ~121 ~100 dirt
setblock ~29 ~121 ~101 dirt
setblock ~29 ~121 ~102 dirt
setblock ~29 ~121 ~103 dirt
setblock ~29 ~121 ~104 dirt
setblock ~29 ~121 ~105 dirt
setblock ~29 ~121 ~106 dirt
setblock ~29 ~121 ~107 dirt
setblock ~29 ~121 ~108 dirt
setblock ~29 ~121 ~109 dirt
setblock ~29 ~121 ~122 dirt
setblock ~29 ~121 ~123 dirt
setblock ~29 ~121 ~124 dirt
setblock ~29 ~121 ~125 dirt
setblock ~29 ~121 ~126 dirt
setblock ~29 ~121 ~127 dirt
setblock ~29 ~122 ~75 dirt
setblock ~29 ~122 ~76 dirt
setblock ~29 ~122 ~77 dirt
setblock ~29 ~122 ~78 dirt
setblock ~29 ~122 ~79 dirt
setblock ~29 ~122 ~80 dirt
setblock ~29 ~122 ~81 dirt
setblock ~29 ~122 ~82 dirt
setblock ~29 ~122 ~83 dirt
setblock ~29 ~122 ~84 dirt
setblock ~29 ~122 ~85 dirt
setblock ~29 ~122 ~86 dirt
setblock ~29 ~122 ~87 dirt
setblock ~29 ~122 ~88 dirt
setblock ~29 ~122 ~89 dirt
setblock ~29 ~122 ~90 dirt
setblock ~29 ~122 ~91 dirt
setblock ~29 ~122 ~92 dirt
setblock ~29 ~122 ~93 dirt
setblock ~29 ~122 ~94 dirt
setblock ~29 ~122 ~95 dirt
setblock ~29 ~122 ~96 dirt
setblock ~29 ~122 ~97 dirt
setblock ~29 ~122 ~98 dirt
setblock ~29 ~122 ~99 dirt
setblock ~29 ~122 ~100 dirt
setblock ~29 ~122 ~101 dirt
setblock ~29 ~122 ~102 dirt
setblock ~29 ~122 ~103 dirt
setblock ~29 ~122 ~104 dirt
setblock ~29 ~122 ~105 dirt
setblock ~29 ~122 ~106 dirt
setblock ~29 ~122 ~107 dirt
setblock ~29 ~122 ~108 dirt
setblock ~29 ~122 ~109 dirt
setblock ~29 ~122 ~122 dirt
setblock ~29 ~122 ~123 dirt
setblock ~29 ~122 ~124 dirt
setblock ~29 ~122 ~125 dirt
setblock ~29 ~122 ~126 dirt
setblock ~29 ~122 ~127 dirt
setblock ~29 ~123 ~75 dirt
setblock ~29 ~123 ~76 dirt
setblock ~29 ~123 ~77 dirt
setblock ~29 ~123 ~78 dirt
setblock ~29 ~123 ~79 dirt
setblock ~29 ~123 ~80 dirt
setblock ~29 ~123 ~81 dirt
setblock ~29 ~123 ~82 dirt
setblock ~29 ~123 ~83 dirt
setblock ~29 ~123 ~84 dirt
setblock ~29 ~123 ~85 dirt
setblock ~29 ~123 ~86 dirt
setblock ~29 ~123 ~87 dirt
setblock ~29 ~123 ~88 dirt
setblock ~29 ~123 ~89 dirt
setblock ~29 ~123 ~90 dirt
setblock ~29 ~123 ~91 dirt
setblock ~29 ~123 ~92 dirt
setblock ~29 ~123 ~93 dirt
setblock ~29 ~123 ~94 dirt
setblock ~29 ~123 ~95 dirt
setblock ~29 ~123 ~96 dirt
setblock ~29 ~123 ~97 dirt
setblock ~29 ~123 ~98 dirt
setblock ~29 ~123 ~99 dirt
setblock ~29 ~123 ~100 dirt
setblock ~29 ~123 ~101 dirt
setblock ~29 ~123 ~102 dirt
setblock ~29 ~123 ~103 dirt
setblock ~29 ~123 ~104 dirt
setblock ~29 ~123 ~105 dirt
setblock ~29 ~123 ~106 dirt
setblock ~29 ~123 ~107 dirt
setblock ~29 ~123 ~108 dirt
setblock ~29 ~123 ~109 dirt
setblock ~29 ~123 ~122 dirt
setblock ~29 ~123 ~123 dirt
setblock ~29 ~123 ~124 dirt
setblock ~29 ~123 ~125 dirt
setblock ~29 ~123 ~126 dirt
setblock ~29 ~123 ~127 dirt
setblock ~29 ~124 ~75 dirt
setblock ~29 ~124 ~76 dirt
setblock ~29 ~124 ~77 dirt
setblock ~29 ~124 ~78 dirt
setblock ~29 ~124 ~79 dirt
setblock ~29 ~124 ~80 dirt
setblock ~29 ~124 ~81 dirt
setblock ~29 ~124 ~82 dirt
setblock ~29 ~124 ~83 dirt
setblock ~29 ~124 ~84 dirt
setblock ~29 ~124 ~85 dirt
setblock ~29 ~124 ~86 dirt
setblock ~29 ~124 ~87 dirt
setblock ~29 ~124 ~88 dirt
setblock ~29 ~124 ~89 dirt
setblock ~29 ~124 ~90 dirt
setblock ~29 ~124 ~91 dirt
setblock ~29 ~124 ~92 dirt
setblock ~29 ~124 ~93 dirt
setblock ~29 ~124 ~94 dirt
setblock ~29 ~124 ~95 dirt
setblock ~29 ~124 ~96 dirt
setblock ~29 ~124 ~97 dirt
setblock ~29 ~124 ~98 dirt
setblock ~29 ~124 ~99 dirt
setblock ~29 ~124 ~100 dirt
setblock ~29 ~124 ~101 dirt
setblock ~29 ~124 ~102 dirt
setblock ~29 ~124 ~103 dirt
setblock ~29 ~124 ~104 dirt
setblock ~29 ~124 ~105 dirt
setblock ~29 ~124 ~106 dirt
setblock ~29 ~124 ~107 dirt
setblock ~29 ~124 ~108 dirt
setblock ~29 ~124 ~109 dirt
setblock ~29 ~124 ~122 dirt
setblock ~29 ~124 ~123 dirt
setblock ~29 ~124 ~124 dirt
setblock ~29 ~124 ~125 dirt
setblock ~29 ~124 ~126 dirt
setblock ~29 ~124 ~127 dirt
setblock ~29 ~125 ~75 grass_block
setblock ~29 ~125 ~76 grass_block
setblock ~29 ~125 ~77 dirt
setblock ~29 ~125 ~78 dirt
setblock ~29 ~125 ~79 dirt
setblock ~29 ~125 ~80 dirt
setblock ~29 ~125 ~81 dirt
setblock ~29 ~125 ~82 dirt
setblock ~29 ~125 ~83 dirt
setblock ~29 ~125 ~84 dirt
setblock ~29 ~125 ~85 dirt
setblock ~29 ~125 ~86 dirt
setblock ~29 ~125 ~87 dirt
setblock ~29 ~125 ~88 dirt
setblock ~29 ~125 ~89 dirt
setblock ~29 ~125 ~90 dirt
setblock ~29 ~125 ~91 dirt
setblock ~29 ~125 ~92 dirt
setblock ~29 ~125 ~93 dirt
setblock ~29 ~125 ~94 dirt
setblock ~29 ~125 ~95 dirt
setblock ~29 ~125 ~96 dirt
setblock ~29 ~125 ~97 dirt
setblock ~29 ~125 ~98 dirt
setblock ~29 ~125 ~99 dirt
setblock ~29 ~125 ~100 dirt
setblock ~29 ~125 ~101 dirt
setblock ~29 ~125 ~102 dirt
setblock ~29 ~125 ~103 dirt
setblock ~29 ~125 ~104 dirt
setblock ~29 ~125 ~105 dirt
setblock ~29 ~125 ~106 dirt
setblock ~29 ~125 ~107 dirt
setblock ~29 ~125 ~108 dirt
setblock ~29 ~125 ~109 dirt
setblock ~29 ~125 ~122 grass_block
setblock ~29 ~125 ~123 grass_block
setblock ~29 ~125 ~124 dirt
setblock ~29 ~125 ~125 dirt
setblock ~29 ~125 ~126 dirt
setblock ~29 ~125 ~127 dirt
setblock ~29 ~126 ~67 spruce_slab
setblock ~29 ~126 ~77 grass_block
setblock ~29 ~126 ~78 grass_block
setblock ~29 ~126 ~79 grass_block
setblock ~29 ~126 ~80 grass_block
setblock ~29 ~126 ~81 grass_block
setblock ~29 ~126 ~82 grass_block
setblock ~29 ~126 ~83 grass_block
setblock ~29 ~126 ~84 grass_block
setblock ~29 ~126 ~85 dirt
setblock ~29 ~126 ~86 dirt
setblock ~29 ~126 ~87 dirt
setblock ~29 ~126 ~88 dirt
setblock ~29 ~126 ~89 dirt
setblock ~29 ~126 ~90 dirt
setblock ~29 ~126 ~91 dirt
setblock ~29 ~126 ~92 dirt
setblock ~29 ~126 ~93 dirt
setblock ~29 ~126 ~94 dirt
setblock ~29 ~126 ~95 dirt
setblock ~29 ~126 ~96 dirt
setblock ~29 ~126 ~97 dirt
setblock ~29 ~126 ~98 dirt
setblock ~29 ~126 ~99 dirt
setblock ~29 ~126 ~100 dirt
setblock ~29 ~126 ~101 dirt
setblock ~29 ~126 ~102 dirt
setblock ~29 ~126 ~103 dirt
setblock ~29 ~126 ~104 dirt
setblock ~29 ~126 ~105 dirt
setblock ~29 ~126 ~106 dirt
setblock ~29 ~126 ~107 dirt
setblock ~29 ~126 ~108 dirt
setblock ~29 ~126 ~109 dirt
setblock ~29 ~126 ~123 short_grass
setblock ~29 ~126 ~124 grass_block
setblock ~29 ~126 ~125 grass_block
setblock ~29 ~126 ~126 dirt
setblock ~29 ~126 ~127 dirt
setblock ~29 ~127 ~79 short_grass
setblock ~29 ~127 ~80 poppy
setblock ~29 ~127 ~82 fern
setblock ~29 ~127 ~84 fern
setblock ~29 ~127 ~85 grass_block
setblock ~29 ~127 ~86 grass_block
setblock ~29 ~127 ~87 grass_block
setblock ~29 ~127 ~88 grass_block
setblock ~29 ~127 ~89 dirt
setblock ~29 ~127 ~90 dirt
setblock ~29 ~127 ~91 dirt
setblock ~29 ~127 ~92 dirt
setblock ~29 ~127 ~93 dirt
setblock ~29 ~127 ~94 dirt
setblock ~29 ~127 ~95 grass_block
setblock ~29 ~127 ~96 grass_block
setblock ~29 ~127 ~97 grass_block
setblock ~29 ~127 ~98 grass_block
setblock ~29 ~127 ~99 grass_block
setblock ~29 ~127 ~100 grass_block
setblock ~29 ~127 ~101 grass_block
setblock ~29 ~127 ~102 grass_block
setblock ~29 ~127 ~103 grass_block
setblock ~29 ~127 ~104 dirt
setblock ~29 ~127 ~105 dirt
setblock ~29 ~127 ~106 dirt
setblock ~29 ~127 ~107 dirt
setblock ~29 ~127 ~108 dirt
setblock ~29 ~127 ~109 dirt
setblock ~29 ~127 ~126 grass_block
setblock ~29 ~127 ~127 grass_block
setblock ~29 ~128 ~66 oak_leaves
setblock ~29 ~128 ~67 oak_leaves
setblock ~29 ~128 ~68 oak_leaves
setblock ~29 ~128 ~86 poppy
setblock ~29 ~128 ~87 poppy
setblock ~29 ~128 ~89 grass_block
setblock ~29 ~128 ~90 dirt
setblock ~29 ~128 ~91 grass_block
setblock ~29 ~128 ~92 grass_block
setblock ~29 ~128 ~93 grass_block
setblock ~29 ~128 ~94 grass_block
setblock ~29 ~128 ~97 short_grass
setblock ~29 ~128 ~102 short_grass
setblock ~29 ~128 ~104 grass_block
setblock ~29 ~128 ~105 grass_block
setblock ~29 ~128 ~106 grass_block
setblock ~29 ~128 ~107 grass_block
setblock ~29 ~128 ~108 dirt
setblock ~29 ~128 ~109 dirt
setblock ~29 ~128 ~126 short_grass
setblock ~29 ~129 ~65 oak_leaves
setblock ~29 ~129 ~66 oak_leaves
setblock ~29 ~129 ~67 jungle_leaves
setblock ~29 ~129 ~68 oak_leaves
setblock ~29 ~129 ~89 fern
setblock ~29 ~129 ~90 grass_block
setblock ~29 ~129 ~91 fern
setblock ~29 ~129 ~92 fern
setblock ~29 ~129 ~93 poppy
setblock ~29 ~129 ~94 fern
setblock ~29 ~129 ~105 short_grass
setblock ~29 ~129 ~108 grass_block
setblock ~29 ~129 ~109 grass_block
setblock ~29 ~130 ~64 oak_leaves
setblock ~29 ~130 ~65 oak_leaves
setblock ~29 ~130 ~66 oak_leaves
setblock ~29 ~130 ~67 jungle_leaves
setblock ~29 ~130 ~68 jungle_leaves
setblock ~29 ~130 ~69 oak_leaves
setblock ~29 ~130 ~90 short_grass
setblock ~29 ~130 ~109 short_grass
setblock ~29 ~131 ~61 oak_leaves
setblock ~29 ~131 ~62 oak_leaves
setblock ~29 ~131 ~65 oak_leaves
setblock ~29 ~131 ~67 oak_leaves
setblock ~29 ~131 ~69 jungle_leaves
setblock ~29 ~132 ~62 jungle_leaves
setblock ~29 ~132 ~64 oak_leaves
setblock ~29 ~132 ~65 jungle_leaves
setblock ~29 ~132 ~67 oak_leaves
setblock ~29 ~132 ~69 oak_leaves
setblock ~29 ~133 ~59 jungle_leaves
setblock ~29 ~133 ~60 jungle_leaves
setblock ~29 ~133 ~61 oak_wood
setblock ~29 ~133 ~62 oak_wood
setblock ~29 ~133 ~64 oak_leaves
setblock ~29 ~133 ~65 oak_leaves
setblock ~29 ~133 ~66 jungle_leaves
setblock ~29 ~133 ~68 jungle_leaves
setblock ~29 ~133 ~69 oak_leaves
setblock ~29 ~133 ~70 oak_leaves
setblock ~29 ~134 ~61 jungle_leaves
setblock ~29 ~134 ~64 oak_wood
setblock ~29 ~134 ~65 oak_leaves
setblock ~29 ~134 ~66 oak_leaves
setblock ~29 ~134 ~68 oak_leaves
setblock ~29 ~134 ~69 oak_leaves
setblock ~29 ~134 ~70 oak_leaves
setblock ~29 ~135 ~60 oak_leaves
setblock ~29 ~135 ~61 jungle_leaves
setblock ~29 ~135 ~62 oak_leaves
setblock ~29 ~135 ~65 jungle_leaves
setblock ~29 ~135 ~66 jungle_leaves
setblock ~29 ~135 ~67 oak_leaves
setblock ~29 ~135 ~68 jungle_leaves
setblock ~29 ~135 ~69 jungle_leaves
setblock ~29 ~135 ~70 jungle_leaves
setblock ~29 ~136 ~60 oak_leaves
setblock ~29 ~136 ~61 oak_leaves
setblock ~29 ~136 ~62 oak_leaves
setblock ~29 ~136 ~63 oak_wood
setblock ~29 ~136 ~66 oak_wood
setblock ~29 ~136 ~68 oak_wood
setblock ~29 ~136 ~69 oak_leaves
setblock ~29 ~136 ~70 oak_leaves
setblock ~29 ~137 ~60 oak_leaves
setblock ~29 ~137 ~61 oak_leaves
setblock ~29 ~137 ~62 oak_leaves
setblock ~29 ~137 ~63 jungle_leaves
setblock ~29 ~137 ~64 oak_leaves
setblock ~29 ~137 ~65 oak_leaves
setblock ~29 ~137 ~66 oak_leaves
setblock ~29 ~137 ~67 oak_leaves
setblock ~29 ~137 ~68 oak_leaves
setblock ~29 ~137 ~70 oak_leaves
setblock ~29 ~138 ~62 oak_leaves
setblock ~29 ~138 ~64 oak_leaves
setblock ~29 ~138 ~65 jungle_leaves
setblock ~29 ~138 ~66 oak_log
setblock ~29 ~138 ~67 oak_log
setblock ~29 ~138 ~68 oak_leaves
setblock ~29 ~138 ~69 oak_leaves
setblock ~29 ~139 ~62 oak_leaves
setblock ~29 ~139 ~63 oak_leaves
setblock ~29 ~139 ~65 oak_leaves
setblock ~29 ~139 ~66 oak_leaves
setblock ~29 ~139 ~67 oak_leaves
setblock ~29 ~139 ~68 oak_leaves
setblock ~29 ~139 ~70 oak_leaves
setblock ~29 ~140 ~62 oak_leaves
setblock ~29 ~140 ~63 oak_leaves
setblock ~29 ~140 ~66 oak_leaves
setblock ~29 ~140 ~67 oak_leaves
setblock ~29 ~140 ~68 oak_leaves
setblock ~29 ~140 ~69 oak_leaves
setblock ~30 ~110 ~98 dirt
setblock ~30 ~111 ~98 dirt
setblock ~30 ~111 ~99 dirt
setblock ~30 ~112 ~97 dirt
setblock ~30 ~112 ~98 dirt
setblock ~30 ~112 ~99 dirt
setblock ~30 ~112 ~100 dirt
setblock ~30 ~113 ~92 dirt
setblock ~30 ~113 ~97 dirt
setblock ~30 ~113 ~98 dirt
setblock ~30 ~113 ~99 dirt
setblock ~30 ~113 ~100 dirt
setblock ~30 ~113 ~101 dirt
setblock ~30 ~113 ~102 dirt
setblock ~30 ~113 ~104 dirt
setblock ~30 ~114 ~81 dirt
setblock ~30 ~114 ~91 dirt
setblock ~30 ~114 ~92 dirt
setblock ~30 ~114 ~93 dirt
setblock ~30 ~114 ~95 dirt
setblock ~30 ~114 ~96 dirt
setblock ~30 ~114 ~97 dirt
setblock ~30 ~114 ~98 dirt
setblock ~30 ~114 ~99 dirt
setblock ~30 ~114 ~100 dirt
setblock ~30 ~114 ~101 dirt
setblock ~30 ~114 ~102 dirt
setblock ~30 ~114 ~103 dirt
setblock ~30 ~114 ~104 dirt
setblock ~30 ~115 ~80 dirt
setblock ~30 ~115 ~81 dirt
setblock ~30 ~115 ~82 dirt
setblock ~30 ~115 ~90 dirt
setblock ~30 ~115 ~91 dirt
setblock ~30 ~115 ~92 dirt
setblock ~30 ~115 ~93 dirt
setblock ~30 ~115 ~94 dirt
setblock ~30 ~115 ~95 dirt
setblock ~30 ~115 ~96 dirt
setblock ~30 ~115 ~97 dirt
setblock ~30 ~115 ~98 dirt
setblock ~30 ~115 ~99 dirt
setblock ~30 ~115 ~100 dirt
setblock ~30 ~115 ~101 dirt
setblock ~30 ~115 ~102 dirt
setblock ~30 ~115 ~103 dirt
setblock ~30 ~115 ~104 dirt
setblock ~30 ~115 ~105 dirt
setblock ~30 ~116 ~79 dirt
setblock ~30 ~116 ~80 dirt
setblock ~30 ~116 ~81 dirt
setblock ~30 ~116 ~82 dirt
setblock ~30 ~116 ~90 dirt
setblock ~30 ~116 ~91 dirt
setblock ~30 ~116 ~92 dirt
setblock ~30 ~116 ~93 dirt
setblock ~30 ~116 ~94 dirt
setblock ~30 ~116 ~95 dirt
setblock ~30 ~116 ~96 dirt
setblock ~30 ~116 ~97 dirt
setblock ~30 ~116 ~98 dirt
setblock ~30 ~116 ~99 dirt
setblock ~30 ~116 ~100 dirt
setblock ~30 ~116 ~101 dirt
setblock ~30 ~116 ~102 dirt
setblock ~30 ~116 ~103 dirt
setblock ~30 ~116 ~104 dirt
setblock ~30 ~116 ~105 dirt
setblock ~30 ~116 ~124 dirt
setblock ~30 ~116 ~125 dirt
setblock ~30 ~117 ~78 dirt
setblock ~30 ~117 ~79 dirt
setblock ~30 ~117 ~80 dirt
setblock ~30 ~117 ~81 dirt
setblock ~30 ~117 ~82 dirt
setblock ~30 ~117 ~83 dirt
setblock ~30 ~117 ~90 dirt
setblock ~30 ~117 ~91 dirt
setblock ~30 ~117 ~92 dirt
setblock ~30 ~117 ~93 dirt
setblock ~30 ~117 ~94 dirt
setblock ~30 ~117 ~95 dirt
setblock ~30 ~117 ~96 dirt
setblock ~30 ~117 ~97 dirt
setblock ~30 ~117 ~98 dirt
setblock ~30 ~117 ~99 dirt
setblock ~30 ~117 ~100 dirt
setblock ~30 ~117 ~101 dirt
setblock ~30 ~117 ~102 dirt
setblock ~30 ~117 ~103 dirt
setblock ~30 ~117 ~104 dirt
setblock ~30 ~117 ~105 dirt
setblock ~30 ~117 ~106 dirt
setblock ~30 ~117 ~107 dirt
setblock ~30 ~117 ~123 dirt
setblock ~30 ~117 ~124 dirt
setblock ~30 ~117 ~125 dirt
setblock ~30 ~118 ~75 dirt
setblock ~30 ~118 ~78 dirt
setblock ~30 ~118 ~79 dirt
setblock ~30 ~118 ~80 dirt
setblock ~30 ~118 ~81 dirt
setblock ~30 ~118 ~82 dirt
setblock ~30 ~118 ~83 dirt
setblock ~30 ~118 ~84 dirt
setblock ~30 ~118 ~89 dirt
setblock ~30 ~118 ~90 dirt
setblock ~30 ~118 ~91 dirt
setblock ~30 ~118 ~92 dirt
setblock ~30 ~118 ~93 dirt
setblock ~30 ~118 ~94 dirt
setblock ~30 ~118 ~95 dirt
setblock ~30 ~118 ~96 dirt
setblock ~30 ~118 ~97 dirt
setblock ~30 ~118 ~98 dirt
setblock ~30 ~118 ~99 dirt
setblock ~30 ~118 ~100 dirt
setblock ~30 ~118 ~101 dirt
setblock ~30 ~118 ~102 dirt
setblock ~30 ~118 ~103 dirt
setblock ~30 ~118 ~104 dirt
setblock ~30 ~118 ~105 dirt
setblock ~30 ~118 ~106 dirt
setblock ~30 ~118 ~107 dirt
setblock ~30 ~118 ~108 dirt
setblock ~30 ~118 ~123 dirt
setblock ~30 ~118 ~124 dirt
setblock ~30 ~118 ~125 dirt
setblock ~30 ~119 ~74 dirt
setblock ~30 ~119 ~75 dirt
setblock ~30 ~119 ~76 dirt
setblock ~30 ~119 ~77 dirt
setblock ~30 ~119 ~78 dirt
setblock ~30 ~119 ~79 dirt
setblock ~30 ~119 ~80 dirt
setblock ~30 ~119 ~81 dirt
setblock ~30 ~119 ~82 dirt
setblock ~30 ~119 ~83 dirt
setblock ~30 ~119 ~84 dirt
setblock ~30 ~119 ~85 dirt
setblock ~30 ~119 ~87 dirt
setblock ~30 ~119 ~88 dirt
setblock ~30 ~119 ~89 dirt
setblock ~30 ~119 ~90 dirt
setblock ~30 ~119 ~91 dirt
setblock ~30 ~119 ~92 dirt
setblock ~30 ~119 ~93 dirt
setblock ~30 ~119 ~94 dirt
setblock ~30 ~119 ~95 dirt
setblock ~30 ~119 ~96 dirt
setblock ~30 ~119 ~97 dirt
setblock ~30 ~119 ~98 dirt
setblock ~30 ~119 ~99 dirt
setblock ~30 ~119 ~100 dirt
setblock ~30 ~119 ~101 dirt
setblock ~30 ~119 ~102 dirt
setblock ~30 ~119 ~103 dirt
setblock ~30 ~119 ~104 dirt
setblock ~30 ~119 ~105 dirt
setblock ~30 ~119 ~106 dirt
setblock ~30 ~119 ~107 dirt
setblock ~30 ~119 ~108 dirt
setblock ~30 ~119 ~109 dirt
setblock ~30 ~119 ~122 dirt
setblock ~30 ~119 ~123 dirt
setblock ~30 ~119 ~124 dirt
setblock ~30 ~119 ~125 dirt
setblock ~30 ~119 ~126 dirt
setblock ~30 ~120 ~72 dirt
setblock ~30 ~120 ~74 dirt
setblock ~30 ~120 ~75 dirt
setblock ~30 ~120 ~76 dirt
setblock ~30 ~120 ~77 dirt
setblock ~30 ~120 ~78 dirt
setblock ~30 ~120 ~79 dirt
setblock ~30 ~120 ~80 dirt
setblock ~30 ~120 ~81 dirt
setblock ~30 ~120 ~82 dirt
setblock ~30 ~120 ~83 dirt
setblock ~30 ~120 ~84 dirt
setblock ~30 ~120 ~85 dirt
setblock ~30 ~120 ~86 dirt
setblock ~30 ~120 ~87 dirt
setblock ~30 ~120 ~88 dirt
setblock ~30 ~120 ~89 dirt
setblock ~30 ~120 ~90 dirt
setblock ~30 ~120 ~91 dirt
setblock ~30 ~120 ~92 dirt
setblock ~30 ~120 ~93 dirt
setblock ~30 ~120 ~94 dirt
setblock ~30 ~120 ~95 dirt
setblock ~30 ~120 ~96 dirt
setblock ~30 ~120 ~97 dirt
setblock ~30 ~120 ~98 dirt
setblock ~30 ~120 ~99 dirt
setblock ~30 ~120 ~100 dirt
setblock ~30 ~120 ~101 dirt
setblock ~30 ~120 ~102 dirt
setblock ~30 ~120 ~103 dirt
setblock ~30 ~120 ~104 dirt
setblock ~30 ~120 ~105 dirt
setblock ~30 ~120 ~106 dirt
setblock ~30 ~120 ~107 dirt
setblock ~30 ~120 ~108 dirt
setblock ~30 ~120 ~109 dirt
setblock ~30 ~120 ~110 dirt
setblock ~30 ~120 ~121 dirt
setblock ~30 ~120 ~122 dirt
setblock ~30 ~120 ~123 dirt
setblock ~30 ~120 ~124 dirt
setblock ~30 ~120 ~125 dirt
setblock ~30 ~120 ~126 dirt
setblock ~30 ~120 ~127 dirt
setblock ~30 ~121 ~68 dirt
setblock ~30 ~121 ~69 dirt
setblock ~30 ~121 ~71 dirt
setblock ~30 ~121 ~72 dirt
setblock ~30 ~121 ~74 dirt
setblock ~30 ~121 ~75 dirt
setblock ~30 ~121 ~76 dirt
setblock ~30 ~121 ~77 dirt
setblock ~30 ~121 ~78 dirt
setblock ~30 ~121 ~79 dirt
setblock ~30 ~121 ~80 dirt
setblock ~30 ~121 ~81 dirt
setblock ~30 ~121 ~82 dirt
setblock ~30 ~121 ~83 dirt
setblock ~30 ~121 ~84 dirt
setblock ~30 ~121 ~85 dirt
setblock ~30 ~121 ~86 dirt
setblock ~30 ~121 ~87 dirt
setblock ~30 ~121 ~88 dirt
setblock ~30 ~121 ~89 dirt
setblock ~30 ~121 ~90 dirt
setblock ~30 ~121 ~91 dirt
setblock ~30 ~121 ~92 dirt
setblock ~30 ~121 ~93 dirt
setblock ~30 ~121 ~94 dirt
setblock ~30 ~121 ~95 dirt
setblock ~30 ~121 ~96 dirt
setblock ~30 ~121 ~97 dirt
setblock ~30 ~121 ~98 dirt
setblock ~30 ~121 ~99 dirt
setblock ~30 ~121 ~100 dirt
setblock ~30 ~121 ~101 dirt
setblock ~30 ~121 ~102 dirt
setblock ~30 ~121 ~103 dirt
setblock ~30 ~121 ~104 dirt
setblock ~30 ~121 ~105 dirt
setblock ~30 ~121 ~106 dirt
setblock ~30 ~121 ~107 dirt
setblock ~30 ~121 ~108 dirt
setblock ~30 ~121 ~109 dirt
setblock ~30 ~121 ~110 dirt
setblock ~30 ~121 ~121 dirt
setblock ~30 ~121 ~122 dirt
setblock ~30 ~121 ~123 dirt
setblock ~30 ~121 ~124 dirt
setblock ~30 ~121 ~125 dirt
setblock ~30 ~121 ~126 dirt
setblock ~30 ~121 ~127 dirt
setblock ~30 ~121 ~128 dirt
setblock ~30 ~122 ~68 dirt
setblock ~30 ~122 ~69 dirt
setblock ~30 ~122 ~71 dirt
setblock ~30 ~122 ~72 dirt
setblock ~30 ~122 ~74 dirt
setblock ~30 ~122 ~75 dirt
setblock ~30 ~122 ~76 dirt
setblock ~30 ~122 ~77 dirt
setblock ~30 ~122 ~78 dirt
setblock ~30 ~122 ~79 dirt
setblock ~30 ~122 ~80 dirt
setblock ~30 ~122 ~81 dirt
setblock ~30 ~122 ~82 dirt
setblock ~30 ~122 ~83 dirt
setblock ~30 ~122 ~84 dirt
setblock ~30 ~122 ~85 dirt
setblock ~30 ~122 ~86 dirt
setblock ~30 ~122 ~87 dirt
setblock ~30 ~122 ~88 dirt
setblock ~30 ~122 ~89 dirt
setblock ~30 ~122 ~90 dirt
setblock ~30 ~122 ~91 dirt
setblock ~30 ~122 ~92 dirt
setblock ~30 ~122 ~93 dirt
setblock ~30 ~122 ~94 dirt
setblock ~30 ~122 ~95 dirt
setblock ~30 ~122 ~96 dirt
setblock ~30 ~122 ~97 dirt
setblock ~30 ~122 ~98 dirt
setblock ~30 ~122 ~99 dirt
setblock ~30 ~122 ~100 dirt
setblock ~30 ~122 ~101 dirt
setblock ~30 ~122 ~102 dirt
setblock ~30 ~122 ~103 dirt
setblock ~30 ~122 ~104 dirt
setblock ~30 ~122 ~105 dirt
setblock ~30 ~122 ~106 dirt
setblock ~30 ~122 ~107 dirt
setblock ~30 ~122 ~108 dirt
setblock ~30 ~122 ~109 dirt
setblock ~30 ~122 ~110 dirt
setblock ~30 ~122 ~121 dirt
setblock ~30 ~122 ~122 dirt
setblock ~30 ~122 ~123 dirt
setblock ~30 ~122 ~124 dirt
setblock ~30 ~122 ~125 dirt
setblock ~30 ~122 ~126 dirt
setblock ~30 ~122 ~127 dirt
setblock ~30 ~122 ~128 dirt
setblock ~30 ~123 ~68 dirt
setblock ~30 ~123 ~69 dirt
setblock ~30 ~123 ~71 dirt
setblock ~30 ~123 ~72 dirt
setblock ~30 ~123 ~74 dirt
setblock ~30 ~123 ~75 dirt
setblock ~30 ~123 ~76 dirt
setblock ~30 ~123 ~77 dirt
setblock ~30 ~123 ~78 dirt
setblock ~30 ~123 ~79 dirt
setblock ~30 ~123 ~80 dirt
setblock ~30 ~123 ~81 dirt
setblock ~30 ~123 ~82 dirt
setblock ~30 ~123 ~83 dirt
setblock ~30 ~123 ~84 dirt
setblock ~30 ~123 ~85 dirt
setblock ~30 ~123 ~86 dirt
setblock ~30 ~123 ~87 dirt
setblock ~30 ~123 ~88 dirt
setblock ~30 ~123 ~89 dirt
setblock ~30 ~123 ~90 dirt
setblock ~30 ~123 ~91 dirt
setblock ~30 ~123 ~92 dirt
setblock ~30 ~123 ~93 dirt
setblock ~30 ~123 ~94 dirt
setblock ~30 ~123 ~95 dirt
setblock ~30 ~123 ~96 dirt
setblock ~30 ~123 ~97 dirt
setblock ~30 ~123 ~98 dirt
setblock ~30 ~123 ~99 dirt
setblock ~30 ~123 ~100 dirt
setblock ~30 ~123 ~101 dirt
setblock ~30 ~123 ~102 dirt
setblock ~30 ~123 ~103 dirt
setblock ~30 ~123 ~104 dirt
setblock ~30 ~123 ~105 dirt
setblock ~30 ~123 ~106 dirt
setblock ~30 ~123 ~107 dirt
setblock ~30 ~123 ~108 dirt
setblock ~30 ~123 ~109 dirt
setblock ~30 ~123 ~110 dirt
setblock ~30 ~123 ~121 dirt
setblock ~30 ~123 ~122 dirt
setblock ~30 ~123 ~123 dirt
setblock ~30 ~123 ~124 dirt
setblock ~30 ~123 ~125 dirt
setblock ~30 ~123 ~126 dirt
setblock ~30 ~123 ~127 dirt
setblock ~30 ~123 ~128 dirt
setblock ~30 ~124 ~68 dirt
setblock ~30 ~124 ~69 dirt
setblock ~30 ~124 ~71 dirt
setblock ~30 ~124 ~72 dirt
setblock ~30 ~124 ~74 dirt
setblock ~30 ~124 ~75 dirt
setblock ~30 ~124 ~76 dirt
setblock ~30 ~124 ~77 dirt
setblock ~30 ~124 ~78 dirt
setblock ~30 ~124 ~79 dirt
setblock ~30 ~124 ~80 dirt
setblock ~30 ~124 ~81 dirt
setblock ~30 ~124 ~82 dirt
setblock ~30 ~124 ~83 dirt
setblock ~30 ~124 ~84 dirt
setblock ~30 ~124 ~85 dirt
setblock ~30 ~124 ~86 dirt
setblock ~30 ~124 ~87 dirt
setblock ~30 ~124 ~88 dirt
setblock ~30 ~124 ~89 dirt
setblock ~30 ~124 ~90 dirt
setblock ~30 ~124 ~91 dirt
setblock ~30 ~124 ~92 dirt
setblock ~30 ~124 ~93 dirt
setblock ~30 ~124 ~94 dirt
setblock ~30 ~124 ~95 dirt
setblock ~30 ~124 ~96 dirt
setblock ~30 ~124 ~97 dirt
setblock ~30 ~124 ~98 dirt
setblock ~30 ~124 ~99 dirt
setblock ~30 ~124 ~100 dirt
setblock ~30 ~124 ~101 dirt
setblock ~30 ~124 ~102 dirt
setblock ~30 ~124 ~103 dirt
setblock ~30 ~124 ~104 dirt
setblock ~30 ~124 ~105 dirt
setblock ~30 ~124 ~106 dirt
setblock ~30 ~124 ~107 dirt
setblock ~30 ~124 ~108 dirt
setblock ~30 ~124 ~109 dirt
setblock ~30 ~124 ~110 dirt
setblock ~30 ~124 ~121 grass_block
setblock ~30 ~124 ~122 dirt
setblock ~30 ~124 ~123 dirt
setblock ~30 ~124 ~124 dirt
setblock ~30 ~124 ~125 dirt
setblock ~30 ~124 ~126 dirt
setblock ~30 ~124 ~127 dirt
setblock ~30 ~124 ~128 dirt
setblock ~30 ~125 ~68 grass_block
setblock ~30 ~125 ~69 grass_block
setblock ~30 ~125 ~71 grass_block
setblock ~30 ~125 ~72 grass_block
setblock ~30 ~125 ~74 grass_block
setblock ~30 ~125 ~75 grass_block
setblock ~30 ~125 ~76 grass_block
setblock ~30 ~125 ~77 dirt
setblock ~30 ~125 ~78 dirt
setblock ~30 ~125 ~79 dirt
setblock ~30 ~125 ~80 dirt
setblock ~30 ~125 ~81 dirt
setblock ~30 ~125 ~82 dirt
setblock ~30 ~125 ~83 dirt
setblock ~30 ~125 ~84 dirt
setblock ~30 ~125 ~85 dirt
setblock ~30 ~125 ~86 dirt
setblock ~30 ~125 ~87 dirt
setblock ~30 ~125 ~88 dirt
setblock ~30 ~125 ~89 dirt
setblock ~30 ~125 ~90 dirt
setblock ~30 ~125 ~91 dirt
setblock ~30 ~125 ~92 dirt
setblock ~30 ~125 ~93 dirt
setblock ~30 ~125 ~94 dirt
setblock ~30 ~125 ~95 dirt
setblock ~30 ~125 ~96 dirt
setblock ~30 ~125 ~97 dirt
setblock ~30 ~125 ~98 dirt
setblock ~30 ~125 ~99 dirt
setblock ~30 ~125 ~100 dirt
setblock ~30 ~125 ~101 dirt
setblock ~30 ~125 ~102 dirt
setblock ~30 ~125 ~103 dirt
setblock ~30 ~125 ~104 dirt
setblock ~30 ~125 ~105 dirt
setblock ~30 ~125 ~106 dirt
setblock ~30 ~125 ~107 dirt
setblock ~30 ~125 ~108 dirt
setblock ~30 ~125 ~109 dirt
setblock ~30 ~125 ~110 dirt
setblock ~30 ~125 ~122 grass_block
setblock ~30 ~125 ~123 grass_block
setblock ~30 ~125 ~124 dirt
setblock ~30 ~125 ~125 dirt
setblock ~30 ~125 ~126 dirt
setblock ~30 ~125 ~127 dirt
setblock ~30 ~125 ~128 dirt
setblock ~30 ~126 ~68 oak_log
setblock ~30 ~126 ~74 short_grass
setblock ~30 ~126 ~77 grass_block
setblock ~30 ~126 ~78 grass_block
setblock ~30 ~126 ~79 grass_block
setblock ~30 ~126 ~80 grass_block
setblock ~30 ~126 ~81 grass_block
setblock ~30 ~126 ~82 grass_block
setblock ~30 ~126 ~83 grass_block
setblock ~30 ~126 ~84 grass_block
setblock ~30 ~126 ~85 grass_block
setblock ~30 ~126 ~86 dirt
setblock ~30 ~126 ~87 dirt
setblock ~30 ~126 ~88 dirt
setblock ~30 ~126 ~89 dirt
setblock ~30 ~126 ~90 dirt
setblock ~30 ~126 ~91 dirt
setblock ~30 ~126 ~92 dirt
setblock ~30 ~126 ~93 dirt
setblock ~30 ~126 ~94 dirt
setblock ~30 ~126 ~95 dirt
setblock ~30 ~126 ~96 dirt
setblock ~30 ~126 ~97 dirt
setblock ~30 ~126 ~98 dirt
setblock ~30 ~126 ~99 dirt
setblock ~30 ~126 ~100 dirt
setblock ~30 ~126 ~101 dirt
setblock ~30 ~126 ~102 dirt
setblock ~30 ~126 ~103 dirt
setblock ~30 ~126 ~104 dirt
setblock ~30 ~126 ~105 dirt
setblock ~30 ~126 ~106 dirt
setblock ~30 ~126 ~107 dirt
setblock ~30 ~126 ~108 dirt
setblock ~30 ~126 ~109 dirt
setblock ~30 ~126 ~110 dirt
setblock ~30 ~126 ~124 grass_block
setblock ~30 ~126 ~125 grass_block
setblock ~30 ~126 ~126 dirt
setblock ~30 ~126 ~127 dirt
setblock ~30 ~126 ~128 dirt
setblock ~30 ~127 ~68 oak_log
setblock ~30 ~127 ~84 short_grass
setblock ~30 ~127 ~86 grass_block
setblock ~30 ~127 ~87 grass_block
setblock ~30 ~127 ~88 grass_block
setblock ~30 ~127 ~89 dirt
setblock ~30 ~127 ~90 dirt
setblock ~30 ~127 ~91 dirt
setblock ~30 ~127 ~92 dirt
setblock ~30 ~127 ~93 dirt
setblock ~30 ~127 ~94 dirt
setblock ~30 ~127 ~95 dirt
setblock ~30 ~127 ~96 dirt
setblock ~30 ~127 ~97 dirt
setblock ~30 ~127 ~98 dirt
setblock ~30 ~127 ~99 dirt
setblock ~30 ~127 ~100 grass_block
setblock ~30 ~127 ~101 dirt
setblock ~30 ~127 ~102 dirt
setblock ~30 ~127 ~103 dirt
setblock ~30 ~127 ~104 dirt
setblock ~30 ~127 ~105 dirt
setblock ~30 ~127 ~106 dirt
setblock ~30 ~127 ~107 dirt
setblock ~30 ~127 ~108 dirt
setblock ~30 ~127 ~109 dirt
setblock ~30 ~127 ~110 dirt
setblock ~30 ~127 ~124 short_grass
setblock ~30 ~127 ~126 grass_block
setblock ~30 ~127 ~127 grass_block
setblock ~30 ~127 ~128 dirt
setblock ~30 ~128 ~65 oak_leaves
setblock ~30 ~128 ~68 oak_log
setblock ~30 ~128 ~89 grass_block
setblock ~30 ~128 ~90 dirt
setblock ~30 ~128 ~91 grass_block
setblock ~30 ~128 ~92 grass_block
setblock ~30 ~128 ~93 grass_block
setblock ~30 ~128 ~94 grass_block
setblock ~30 ~128 ~95 grass_block
setblock ~30 ~128 ~96 grass_block
setblock ~30 ~128 ~97 grass_block
setblock ~30 ~128 ~98 grass_block
setblock ~30 ~128 ~99 grass_block
setblock ~30 ~128 ~101 grass_block
setblock ~30 ~128 ~102 grass_block
setblock ~30 ~128 ~103 grass_block
setblock ~30 ~128 ~104 grass_block
setblock ~30 ~128 ~105 grass_block
setblock ~30 ~128 ~106 dirt
setblock ~30 ~128 ~107 dirt
setblock ~30 ~128 ~108 dirt
setblock ~30 ~128 ~109 dirt
setblock ~30 ~128 ~110 dirt
setblock ~30 ~128 ~126 short_grass
setblock ~30 ~128 ~127 fern
setblock ~30 ~128 ~128 grass_block
setblock ~30 ~129 ~65 oak_leaves
setblock ~30 ~129 ~66 jungle_leaves
setblock ~30 ~129 ~67 oak_leaves
setblock ~30 ~129 ~68 oak_log
setblock ~30 ~129 ~90 grass_block
setblock ~30 ~129 ~91 poppy
setblock ~30 ~129 ~94 fern
setblock ~30 ~129 ~95 short_grass
setblock ~30 ~129 ~102 short_grass
setblock ~30 ~129 ~103 short_grass
setblock ~30 ~129 ~105 short_grass
setblock ~30 ~129 ~106 grass_block
setblock ~30 ~129 ~107 grass_block
setblock ~30 ~129 ~108 grass_block
setblock ~30 ~129 ~109 grass_block
setblock ~30 ~129 ~110 grass_block
setblock ~30 ~130 ~65 oak_leaves
setblock ~30 ~130 ~66 oak_leaves
setblock ~30 ~130 ~68 oak_log
setblock ~30 ~130 ~69 oak_leaves
setblock ~30 ~130 ~106 poppy
setblock ~30 ~130 ~110 short_grass
setblock ~30 ~131 ~61 jungle_leaves
setblock ~30 ~131 ~62 oak_leaves
setblock ~30 ~131 ~63 oak_leaves
setblock ~30 ~131 ~64 oak_leaves
setblock ~30 ~131 ~65 oak_leaves
setblock ~30 ~131 ~66 oak_leaves
setblock ~30 ~131 ~67 jungle_leaves
setblock ~30 ~131 ~68 oak_log
setblock ~30 ~131 ~69 oak_leaves
setblock ~30 ~132 ~60 oak_leaves
setblock ~30 ~132 ~61 jungle_leaves
setblock ~30 ~132 ~62 jungle_leaves
setblock ~30 ~132 ~65 oak_leaves
setblock ~30 ~132 ~66 oak_leaves
setblock ~30 ~132 ~67 oak_log
setblock ~30 ~132 ~68 oak_leaves
setblock ~30 ~132 ~69 oak_leaves
setblock ~30 ~133 ~59 oak_leaves
setblock ~30 ~133 ~61 oak_wood
setblock ~30 ~133 ~62 oak_wood
setblock ~30 ~133 ~63 oak_wood
setblock ~30 ~133 ~64 oak_wood
setblock ~30 ~133 ~65 oak_wood
setblock ~30 ~133 ~66 oak_leaves
setblock ~30 ~133 ~67 oak_leaves
setblock ~30 ~133 ~68 oak_leaves
setblock ~30 ~133 ~69 oak_leaves
setblock ~30 ~133 ~70 oak_leaves
setblock ~30 ~134 ~60 jungle_leaves
setblock ~30 ~134 ~61 oak_leaves
setblock ~30 ~134 ~62 oak_leaves
setblock ~30 ~134 ~63 oak_wood
setblock ~30 ~134 ~64 oak_wood
setblock ~30 ~134 ~65 oak_wood
setblock ~30 ~134 ~66 oak_leaves
setblock ~30 ~134 ~68 oak_leaves
setblock ~30 ~134 ~70 oak_leaves
setblock ~30 ~135 ~64 oak_wood
setblock ~30 ~135 ~65 oak_wood
setblock ~30 ~135 ~66 oak_leaves
setblock ~30 ~135 ~67 oak_leaves
setblock ~30 ~135 ~68 oak_leaves
setblock ~30 ~135 ~70 oak_leaves
setblock ~30 ~136 ~63 oak_wood
setblock ~30 ~136 ~64 oak_wood
setblock ~30 ~136 ~65 oak_wood
setblock ~30 ~136 ~66 oak_leaves
setblock ~30 ~136 ~67 oak_wood
setblock ~30 ~136 ~68 oak_wood
setblock ~30 ~136 ~69 oak_leaves
setblock ~30 ~136 ~70 oak_leaves
setblock ~30 ~136 ~100 oak_leaves
setblock ~30 ~136 ~101 jungle_leaves
setblock ~30 ~137 ~62 oak_leaves
setblock ~30 ~137 ~64 oak_leaves
setblock ~30 ~137 ~65 oak_wood
setblock ~30 ~137 ~66 oak_wood
setblock ~30 ~137 ~68 oak_leaves
setblock ~30 ~137 ~70 jungle_leaves
setblock ~30 ~137 ~100 oak_leaves
setblock ~30 ~138 ~62 jungle_leaves
setblock ~30 ~138 ~63 oak_leaves
setblock ~30 ~138 ~64 oak_leaves
setblock ~30 ~138 ~65 oak_leaves
setblock ~30 ~138 ~67 oak_log
setblock ~30 ~138 ~68 oak_leaves
setblock ~30 ~138 ~69 oak_leaves
setblock ~30 ~138 ~70 oak_leaves
setblock ~30 ~138 ~100 oak_leaves
setblock ~30 ~138 ~101 oak_leaves
setblock ~30 ~139 ~62 jungle_leaves
setblock ~30 ~139 ~65 oak_leaves
setblock ~30 ~139 ~67 oak_leaves
setblock ~30 ~139 ~68 oak_leaves
setblock ~30 ~139 ~69 oak_leaves
setblock ~30 ~139 ~70 oak_leaves
setblock ~30 ~140 ~63 oak_leaves
setblock ~30 ~140 ~66 jungle_leaves
setblock ~30 ~140 ~68 oak_leaves
setblock ~30 ~140 ~69 jungle_leaves
setblock ~30 ~140 ~70 jungle_leaves
setblock ~31 ~109 ~98 dirt
setblock ~31 ~110 ~93 dirt
setblock ~31 ~110 ~97 dirt
setblock ~31 ~110 ~98 dirt
setblock ~31 ~110 ~99 dirt
setblock ~31 ~111 ~93 dirt
setblock ~31 ~111 ~97 dirt
setblock ~31 ~111 ~98 dirt
setblock ~31 ~111 ~99 dirt
setblock ~31 ~111 ~100 dirt
setblock ~31 ~111 ~103 dirt
setblock ~31 ~111 ~104 dirt
setblock ~31 ~112 ~81 dirt
setblock ~31 ~112 ~91 dirt
setblock ~31 ~112 ~92 dirt
setblock ~31 ~112 ~93 dirt
setblock ~31 ~112 ~95 dirt
setblock ~31 ~112 ~97 dirt
setblock ~31 ~112 ~98 dirt
setblock ~31 ~112 ~99 dirt
setblock ~31 ~112 ~100 dirt
setblock ~31 ~112 ~101 dirt
setblock ~31 ~112 ~102 dirt
setblock ~31 ~112 ~103 dirt
setblock ~31 ~112 ~104 dirt
setblock ~31 ~113 ~81 dirt
setblock ~31 ~113 ~91 dirt
setblock ~31 ~113 ~92 dirt
setblock ~31 ~113 ~93 dirt
setblock ~31 ~113 ~94 dirt
setblock ~31 ~113 ~95 dirt
setblock ~31 ~113 ~96 dirt
setblock ~31 ~113 ~97 dirt
setblock ~31 ~113 ~98 dirt
setblock ~31 ~113 ~99 dirt
setblock ~31 ~113 ~100 dirt
setblock ~31 ~113 ~101 dirt
setblock ~31 ~113 ~102 dirt
setblock ~31 ~113 ~103 dirt
setblock ~31 ~113 ~104 dirt
setblock ~31 ~113 ~105 dirt
