setblock ~195 ~124 ~168 dirt
setblock ~195 ~124 ~169 dirt
setblock ~195 ~124 ~170 dirt
setblock ~195 ~124 ~171 dirt
setblock ~195 ~124 ~172 dirt
setblock ~195 ~124 ~173 dirt
setblock ~195 ~124 ~174 dirt
setblock ~195 ~124 ~175 dirt
setblock ~195 ~124 ~176 dirt
setblock ~195 ~124 ~177 dirt
setblock ~195 ~124 ~178 dirt
setblock ~195 ~124 ~179 dirt
setblock ~195 ~124 ~180 dirt
setblock ~195 ~124 ~181 dirt
setblock ~195 ~124 ~182 dirt
setblock ~195 ~124 ~183 dirt
setblock ~195 ~124 ~184 dirt
setblock ~195 ~124 ~185 dirt
setblock ~195 ~124 ~186 dirt
setblock ~195 ~124 ~187 dirt
setblock ~195 ~124 ~188 dirt
setblock ~195 ~124 ~189 dirt
setblock ~195 ~124 ~190 dirt
setblock ~195 ~124 ~191 dirt
setblock ~195 ~124 ~192 dirt
setblock ~195 ~124 ~193 dirt
setblock ~195 ~124 ~194 dirt
setblock ~195 ~124 ~195 dirt
setblock ~195 ~124 ~196 dirt
setblock ~195 ~124 ~197 dirt
setblock ~195 ~124 ~198 dirt
setblock ~195 ~124 ~199 dirt
setblock ~195 ~125 ~0 grass_block
setblock ~195 ~125 ~1 grass_block
setblock ~195 ~125 ~2 grass_block
setblock ~195 ~125 ~3 grass_block
setblock ~195 ~125 ~4 grass_block
setblock ~195 ~125 ~5 grass_block
setblock ~195 ~125 ~6 grass_block
setblock ~195 ~125 ~10 short_grass
setblock ~195 ~125 ~13 short_grass
setblock ~195 ~125 ~17 grass_block
setblock ~195 ~125 ~18 grass_block
setblock ~195 ~125 ~19 grass_block
setblock ~195 ~125 ~20 grass_block
setblock ~195 ~125 ~21 grass_block
setblock ~195 ~125 ~22 grass_block
setblock ~195 ~125 ~23 grass_block
setblock ~195 ~125 ~24 grass_block
setblock ~195 ~125 ~25 grass_block
setblock ~195 ~125 ~26 dirt
setblock ~195 ~125 ~27 dirt
setblock ~195 ~125 ~28 dirt
setblock ~195 ~125 ~29 dirt
setblock ~195 ~125 ~30 dirt
setblock ~195 ~125 ~31 dirt
setblock ~195 ~125 ~32 dirt
setblock ~195 ~125 ~33 dirt
setblock ~195 ~125 ~34 dirt
setblock ~195 ~125 ~35 dirt
setblock ~195 ~125 ~36 dirt
setblock ~195 ~125 ~37 dirt
setblock ~195 ~125 ~38 dirt
setblock ~195 ~125 ~39 dirt
setblock ~195 ~125 ~40 dirt
setblock ~195 ~125 ~41 dirt
setblock ~195 ~125 ~42 dirt
setblock ~195 ~125 ~43 dirt
setblock ~195 ~125 ~44 dirt
setblock ~195 ~125 ~45 dirt
setblock ~195 ~125 ~46 dirt
setblock ~195 ~125 ~47 dirt
setblock ~195 ~125 ~48 dirt
setblock ~195 ~125 ~49 dirt
setblock ~195 ~125 ~50 dirt
setblock ~195 ~125 ~51 dirt
setblock ~195 ~125 ~52 dirt
setblock ~195 ~125 ~53 dirt
setblock ~195 ~125 ~54 dirt
setblock ~195 ~125 ~55 dirt
setblock ~195 ~125 ~56 dirt
setblock ~195 ~125 ~57 grass_block
setblock ~195 ~125 ~77 short_grass
setblock ~195 ~125 ~81 poppy
setblock ~195 ~125 ~85 short_grass
setblock ~195 ~125 ~89 grass_block
setblock ~195 ~125 ~90 grass_block
setblock ~195 ~125 ~91 grass_block
setblock ~195 ~125 ~92 grass_block
setblock ~195 ~125 ~93 grass_block
setblock ~195 ~125 ~97 short_grass
setblock ~195 ~125 ~100 short_grass
setblock ~195 ~125 ~102 grass_block
setblock ~195 ~125 ~103 grass_block
setblock ~195 ~125 ~104 grass_block
setblock ~195 ~125 ~105 grass_block
setblock ~195 ~125 ~106 grass_block
setblock ~195 ~125 ~107 grass_block
setblock ~195 ~125 ~108 dirt
setblock ~195 ~125 ~109 dirt
setblock ~195 ~125 ~110 dirt
setblock ~195 ~125 ~111 dirt
setblock ~195 ~125 ~112 dirt
setblock ~195 ~125 ~113 grass_block
setblock ~195 ~125 ~114 grass_block
setblock ~195 ~125 ~115 grass_block
setblock ~195 ~125 ~116 grass_block
setblock ~195 ~125 ~117 grass_block
setblock ~195 ~125 ~118 poppy
setblock ~195 ~125 ~119 short_grass
setblock ~195 ~125 ~121 short_grass
setblock ~195 ~125 ~124 short_grass
setblock ~195 ~125 ~126 short_grass
setblock ~195 ~125 ~129 short_grass
setblock ~195 ~125 ~143 short_grass
setblock ~195 ~125 ~144 fern
setblock ~195 ~125 ~145 short_grass
setblock ~195 ~125 ~146 grass_block
setblock ~195 ~125 ~147 grass_block
setblock ~195 ~125 ~148 grass_block
setblock ~195 ~125 ~149 dirt
setblock ~195 ~125 ~150 dirt
setblock ~195 ~125 ~151 dirt
setblock ~195 ~125 ~152 dirt
setblock ~195 ~125 ~153 grass_block
setblock ~195 ~125 ~154 grass_block
setblock ~195 ~125 ~155 grass_block
setblock ~195 ~125 ~156 fern
setblock ~195 ~125 ~163 poppy
setblock ~195 ~125 ~164 short_grass
setblock ~195 ~125 ~167 grass_block
setblock ~195 ~125 ~168 grass_block
setblock ~195 ~125 ~169 grass_block
setblock ~195 ~125 ~170 grass_block
setblock ~195 ~125 ~171 grass_block
setblock ~195 ~125 ~172 grass_block
setblock ~195 ~125 ~173 grass_block
setblock ~195 ~125 ~174 grass_block
setblock ~195 ~125 ~175 grass_block
setblock ~195 ~125 ~176 grass_block
setblock ~195 ~125 ~177 grass_block
setblock ~195 ~125 ~178 grass_block
setblock ~195 ~125 ~179 grass_block
setblock ~195 ~125 ~180 grass_block
setblock ~195 ~125 ~181 grass_block
setblock ~195 ~125 ~182 grass_block
setblock ~195 ~125 ~183 grass_block
setblock ~195 ~125 ~184 grass_block
setblock ~195 ~125 ~185 grass_block
setblock ~195 ~125 ~186 grass_block
setblock ~195 ~125 ~187 grass_block
setblock ~195 ~125 ~188 grass_block
setblock ~195 ~125 ~189 grass_block
setblock ~195 ~125 ~190 grass_block
setblock ~195 ~125 ~191 grass_block
setblock ~195 ~125 ~192 dirt
setblock ~195 ~125 ~193 dirt
setblock ~195 ~125 ~194 dirt
setblock ~195 ~125 ~195 dirt
setblock ~195 ~125 ~196 dirt
setblock ~195 ~125 ~197 dirt
setblock ~195 ~125 ~198 dirt
setblock ~195 ~125 ~199 dirt
setblock ~195 ~126 ~4 poppy
setblock ~195 ~126 ~19 fern
setblock ~195 ~126 ~21 poppy
setblock ~195 ~126 ~26 grass_block
setblock ~195 ~126 ~27 grass_block
setblock ~195 ~126 ~28 grass_block
setblock ~195 ~126 ~29 grass_block
setblock ~195 ~126 ~30 dirt
setblock ~195 ~126 ~31 dirt
setblock ~195 ~126 ~32 dirt
setblock ~195 ~126 ~33 dirt
setblock ~195 ~126 ~34 dirt
setblock ~195 ~126 ~35 dirt
setblock ~195 ~126 ~36 dirt
setblock ~195 ~126 ~37 dirt
setblock ~195 ~126 ~38 dirt
setblock ~195 ~126 ~39 dirt
setblock ~195 ~126 ~40 dirt
setblock ~195 ~126 ~41 dirt
setblock ~195 ~126 ~42 dirt
setblock ~195 ~126 ~43 dirt
setblock ~195 ~126 ~44 dirt
setblock ~195 ~126 ~45 dirt
setblock ~195 ~126 ~46 dirt
setblock ~195 ~126 ~47 dirt
setblock ~195 ~126 ~48 dirt
setblock ~195 ~126 ~49 dirt
setblock ~195 ~126 ~50 dirt
setblock ~195 ~126 ~51 dirt
setblock ~195 ~126 ~52 dirt
setblock ~195 ~126 ~53 dirt
setblock ~195 ~126 ~54 dirt
setblock ~195 ~126 ~55 grass_block
setblock ~195 ~126 ~56 grass_block
setblock ~195 ~126 ~91 short_grass
setblock ~195 ~126 ~93 short_grass
setblock ~195 ~126 ~107 short_grass
setblock ~195 ~126 ~108 grass_block
setblock ~195 ~126 ~109 grass_block
setblock ~195 ~126 ~110 grass_block
setblock ~195 ~126 ~111 grass_block
setblock ~195 ~126 ~112 grass_block
setblock ~195 ~126 ~113 poppy
setblock ~195 ~126 ~115 short_grass
setblock ~195 ~126 ~116 short_grass
setblock ~195 ~126 ~117 short_grass
setblock ~195 ~126 ~149 grass_block
setblock ~195 ~126 ~150 grass_block
setblock ~195 ~126 ~151 grass_block
setblock ~195 ~126 ~152 grass_block
setblock ~195 ~126 ~153 short_grass
setblock ~195 ~126 ~181 short_grass
setblock ~195 ~126 ~185 fern
setblock ~195 ~126 ~187 poppy
setblock ~195 ~126 ~189 short_grass
setblock ~195 ~126 ~192 grass_block
setblock ~195 ~126 ~193 grass_block
setblock ~195 ~126 ~194 grass_block
setblock ~195 ~126 ~195 grass_block
setblock ~195 ~126 ~196 grass_block
setblock ~195 ~126 ~197 grass_block
setblock ~195 ~126 ~198 grass_block
setblock ~195 ~126 ~199 grass_block
setblock ~195 ~127 ~26 short_grass
setblock ~195 ~127 ~30 grass_block
setblock ~195 ~127 ~31 grass_block
setblock ~195 ~127 ~32 grass_block
setblock ~195 ~127 ~33 grass_block
setblock ~195 ~127 ~34 grass_block
setblock ~195 ~127 ~35 grass_block
setblock ~195 ~127 ~36 grass_block
setblock ~195 ~127 ~37 grass_block
setblock ~195 ~127 ~38 grass_block
setblock ~195 ~127 ~39 grass_block
setblock ~195 ~127 ~40 grass_block
setblock ~195 ~127 ~41 grass_block
setblock ~195 ~127 ~42 dirt
setblock ~195 ~127 ~43 dirt
setblock ~195 ~127 ~44 dirt
setblock ~195 ~127 ~45 dirt
setblock ~195 ~127 ~46 dirt
setblock ~195 ~127 ~47 dirt
setblock ~195 ~127 ~48 dirt
setblock ~195 ~127 ~49 dirt
setblock ~195 ~127 ~50 dirt
setblock ~195 ~127 ~51 dirt
setblock ~195 ~127 ~52 grass_block
setblock ~195 ~127 ~53 grass_block
setblock ~195 ~127 ~54 grass_block
setblock ~195 ~127 ~55 short_grass
setblock ~195 ~127 ~108 short_grass
setblock ~195 ~127 ~109 short_grass
setblock ~195 ~127 ~111 short_grass
setblock ~195 ~127 ~152 short_grass
setblock ~195 ~127 ~192 poppy
setblock ~195 ~128 ~36 short_grass
setblock ~195 ~128 ~37 short_grass
setblock ~195 ~128 ~40 short_grass
setblock ~195 ~128 ~42 grass_block
setblock ~195 ~128 ~43 grass_block
setblock ~195 ~128 ~44 grass_block
setblock ~195 ~128 ~45 grass_block
setblock ~195 ~128 ~46 grass_block
setblock ~195 ~128 ~47 grass_block
setblock ~195 ~128 ~48 grass_block
setblock ~195 ~128 ~49 grass_block
setblock ~195 ~128 ~50 grass_block
setblock ~195 ~128 ~51 grass_block
setblock ~195 ~128 ~53 short_grass
setblock ~195 ~128 ~54 fern
setblock ~195 ~129 ~42 short_grass
setblock ~195 ~129 ~43 short_grass
setblock ~195 ~129 ~44 short_grass
setblock ~195 ~129 ~45 short_grass
setblock ~195 ~129 ~46 short_grass
setblock ~195 ~129 ~47 poppy
setblock ~195 ~129 ~50 poppy
setblock ~196 ~122 ~0 dirt
setblock ~196 ~122 ~1 dirt
setblock ~196 ~122 ~2 dirt
setblock ~196 ~122 ~3 dirt
setblock ~196 ~122 ~4 dirt
setblock ~196 ~122 ~5 dirt
setblock ~196 ~122 ~6 dirt
setblock ~196 ~122 ~7 dirt
setblock ~196 ~122 ~8 dirt
setblock ~196 ~122 ~9 dirt
setblock ~196 ~122 ~10 dirt
setblock ~196 ~122 ~11 dirt
setblock ~196 ~122 ~12 dirt
setblock ~196 ~122 ~13 dirt
setblock ~196 ~122 ~14 dirt
setblock ~196 ~122 ~15 dirt
setblock ~196 ~122 ~16 dirt
setblock ~196 ~122 ~17 dirt
setblock ~196 ~122 ~18 dirt
setblock ~196 ~122 ~19 dirt
setblock ~196 ~122 ~20 dirt
setblock ~196 ~122 ~21 dirt
setblock ~196 ~122 ~22 dirt
setblock ~196 ~122 ~23 dirt
setblock ~196 ~122 ~24 dirt
setblock ~196 ~122 ~25 dirt
setblock ~196 ~122 ~26 dirt
setblock ~196 ~122 ~27 dirt
setblock ~196 ~122 ~28 dirt
setblock ~196 ~122 ~29 dirt
setblock ~196 ~122 ~30 dirt
setblock ~196 ~122 ~31 dirt
setblock ~196 ~122 ~32 dirt
setblock ~196 ~122 ~33 dirt
setblock ~196 ~122 ~34 dirt
setblock ~196 ~122 ~35 dirt
setblock ~196 ~122 ~36 dirt
setblock ~196 ~122 ~37 dirt
setblock ~196 ~122 ~38 dirt
setblock ~196 ~122 ~39 dirt
setblock ~196 ~122 ~40 dirt
setblock ~196 ~122 ~41 dirt
setblock ~196 ~122 ~42 dirt
setblock ~196 ~122 ~43 dirt
setblock ~196 ~122 ~44 dirt
setblock ~196 ~122 ~45 dirt
setblock ~196 ~122 ~46 dirt
setblock ~196 ~122 ~47 dirt
setblock ~196 ~122 ~48 dirt
setblock ~196 ~122 ~49 dirt
setblock ~196 ~122 ~50 dirt
setblock ~196 ~122 ~51 dirt
setblock ~196 ~122 ~52 dirt
setblock ~196 ~122 ~53 dirt
setblock ~196 ~122 ~54 dirt
setblock ~196 ~122 ~55 dirt
setblock ~196 ~122 ~56 dirt
setblock ~196 ~122 ~57 dirt
setblock ~196 ~122 ~58 dirt
setblock ~196 ~122 ~59 dirt
setblock ~196 ~122 ~60 dirt
setblock ~196 ~122 ~61 dirt
setblock ~196 ~122 ~62 dirt
setblock ~196 ~122 ~63 dirt
setblock ~196 ~122 ~64 dirt
setblock ~196 ~122 ~65 dirt
setblock ~196 ~122 ~66 dirt
setblock ~196 ~122 ~67 dirt
setblock ~196 ~122 ~68 dirt
setblock ~196 ~122 ~69 dirt
setblock ~196 ~122 ~70 dirt
setblock ~196 ~122 ~71 dirt
setblock ~196 ~122 ~72 dirt
setblock ~196 ~122 ~73 dirt
setblock ~196 ~122 ~74 dirt
setblock ~196 ~122 ~75 dirt
setblock ~196 ~122 ~76 dirt
setblock ~196 ~122 ~77 dirt
setblock ~196 ~122 ~78 dirt
setblock ~196 ~122 ~79 dirt
setblock ~196 ~122 ~80 dirt
setblock ~196 ~122 ~81 dirt
setblock ~196 ~122 ~82 dirt
setblock ~196 ~122 ~83 dirt
setblock ~196 ~122 ~84 dirt
setblock ~196 ~122 ~85 dirt
setblock ~196 ~122 ~86 dirt
setblock ~196 ~122 ~87 dirt
setblock ~196 ~122 ~88 dirt
setblock ~196 ~122 ~89 dirt
setblock ~196 ~122 ~90 dirt
setblock ~196 ~122 ~91 dirt
setblock ~196 ~122 ~92 dirt
setblock ~196 ~122 ~93 dirt
setblock ~196 ~122 ~94 dirt
setblock ~196 ~122 ~95 dirt
setblock ~196 ~122 ~96 dirt
setblock ~196 ~122 ~97 dirt
setblock ~196 ~122 ~98 dirt
setblock ~196 ~122 ~99 dirt
setblock ~196 ~122 ~100 dirt
setblock ~196 ~122 ~101 dirt
setblock ~196 ~122 ~102 dirt
setblock ~196 ~122 ~103 dirt
setblock ~196 ~122 ~104 dirt
setblock ~196 ~122 ~105 dirt
setblock ~196 ~122 ~106 dirt
setblock ~196 ~122 ~107 dirt
setblock ~196 ~122 ~108 dirt
setblock ~196 ~122 ~109 dirt
setblock ~196 ~122 ~110 dirt
setblock ~196 ~122 ~111 dirt
setblock ~196 ~122 ~112 dirt
setblock ~196 ~122 ~113 dirt
setblock ~196 ~122 ~114 dirt
setblock ~196 ~122 ~115 dirt
setblock ~196 ~122 ~116 dirt
setblock ~196 ~122 ~117 dirt
setblock ~196 ~122 ~118 dirt
setblock ~196 ~122 ~119 dirt
setblock ~196 ~122 ~120 dirt
setblock ~196 ~122 ~121 dirt
setblock ~196 ~122 ~122 dirt
setblock ~196 ~122 ~123 dirt
setblock ~196 ~122 ~124 dirt
setblock ~196 ~122 ~125 dirt
setblock ~196 ~122 ~126 dirt
setblock ~196 ~122 ~127 dirt
setblock ~196 ~122 ~128 dirt
setblock ~196 ~122 ~129 dirt
setblock ~196 ~122 ~130 dirt
setblock ~196 ~122 ~131 dirt
setblock ~196 ~122 ~132 dirt
setblock ~196 ~122 ~133 dirt
setblock ~196 ~122 ~134 dirt
setblock ~196 ~122 ~135 dirt
setblock ~196 ~122 ~136 dirt
setblock ~196 ~122 ~137 dirt
setblock ~196 ~122 ~138 dirt
setblock ~196 ~122 ~139 dirt
setblock ~196 ~122 ~140 dirt
setblock ~196 ~122 ~141 dirt
setblock ~196 ~122 ~142 dirt
setblock ~196 ~122 ~143 dirt
setblock ~196 ~122 ~144 dirt
setblock ~196 ~122 ~145 dirt
setblock ~196 ~122 ~146 dirt
setblock ~196 ~122 ~147 dirt
setblock ~196 ~122 ~148 dirt
setblock ~196 ~122 ~149 dirt
setblock ~196 ~122 ~150 dirt
setblock ~196 ~122 ~151 dirt
setblock ~196 ~122 ~152 dirt
setblock ~196 ~122 ~153 dirt
setblock ~196 ~122 ~154 dirt
setblock ~196 ~122 ~155 dirt
setblock ~196 ~122 ~156 dirt
setblock ~196 ~122 ~157 dirt
setblock ~196 ~122 ~158 dirt
setblock ~196 ~122 ~159 dirt
setblock ~196 ~122 ~160 dirt
setblock ~196 ~122 ~161 dirt
setblock ~196 ~122 ~162 dirt
setblock ~196 ~122 ~163 dirt
setblock ~196 ~122 ~164 dirt
setblock ~196 ~122 ~165 dirt
setblock ~196 ~122 ~166 dirt
setblock ~196 ~122 ~167 dirt
setblock ~196 ~122 ~168 dirt
setblock ~196 ~122 ~169 dirt
setblock ~196 ~122 ~170 dirt
setblock ~196 ~122 ~171 dirt
setblock ~196 ~122 ~172 dirt
setblock ~196 ~122 ~173 dirt
setblock ~196 ~122 ~174 dirt
setblock ~196 ~122 ~175 dirt
setblock ~196 ~122 ~176 dirt
setblock ~196 ~122 ~177 dirt
setblock ~196 ~122 ~178 dirt
setblock ~196 ~122 ~179 dirt
setblock ~196 ~122 ~180 dirt
setblock ~196 ~122 ~181 dirt
setblock ~196 ~122 ~182 dirt
setblock ~196 ~122 ~183 dirt
setblock ~196 ~122 ~184 dirt
setblock ~196 ~122 ~185 dirt
setblock ~196 ~122 ~186 dirt
setblock ~196 ~122 ~187 dirt
setblock ~196 ~122 ~188 dirt
setblock ~196 ~122 ~189 dirt
setblock ~196 ~122 ~190 dirt
setblock ~196 ~122 ~191 dirt
setblock ~196 ~122 ~192 dirt
setblock ~196 ~122 ~193 dirt
setblock ~196 ~122 ~194 dirt
setblock ~196 ~122 ~195 dirt
setblock ~196 ~122 ~196 dirt
setblock ~196 ~122 ~197 dirt
setblock ~196 ~122 ~198 dirt
setblock ~196 ~122 ~199 dirt
setblock ~196 ~123 ~0 dirt
setblock ~196 ~123 ~1 dirt
setblock ~196 ~123 ~2 dirt
setblock ~196 ~123 ~3 dirt
setblock ~196 ~123 ~4 dirt
setblock ~196 ~123 ~5 dirt
setblock ~196 ~123 ~6 dirt
setblock ~196 ~123 ~7 dirt
setblock ~196 ~123 ~8 dirt
setblock ~196 ~123 ~9 dirt
setblock ~196 ~123 ~10 grass_block
setblock ~196 ~123 ~11 dirt
setblock ~196 ~123 ~12 dirt
setblock ~196 ~123 ~13 dirt
setblock ~196 ~123 ~14 dirt
setblock ~196 ~123 ~15 dirt
setblock ~196 ~123 ~16 dirt
setblock ~196 ~123 ~17 dirt
setblock ~196 ~123 ~18 dirt
setblock ~196 ~123 ~19 dirt
setblock ~196 ~123 ~20 dirt
setblock ~196 ~123 ~21 dirt
setblock ~196 ~123 ~22 dirt
setblock ~196 ~123 ~23 dirt
setblock ~196 ~123 ~24 dirt
setblock ~196 ~123 ~25 dirt
setblock ~196 ~123 ~26 dirt
setblock ~196 ~123 ~27 dirt
setblock ~196 ~123 ~28 dirt
setblock ~196 ~123 ~29 dirt
setblock ~196 ~123 ~30 dirt
setblock ~196 ~123 ~31 dirt
setblock ~196 ~123 ~32 dirt
setblock ~196 ~123 ~33 dirt
setblock ~196 ~123 ~34 dirt
setblock ~196 ~123 ~35 dirt
setblock ~196 ~123 ~36 dirt
setblock ~196 ~123 ~37 dirt
setblock ~196 ~123 ~38 dirt
setblock ~196 ~123 ~39 dirt
setblock ~196 ~123 ~40 dirt
setblock ~196 ~123 ~41 dirt
setblock ~196 ~123 ~42 dirt
setblock ~196 ~123 ~43 dirt
setblock ~196 ~123 ~44 dirt
setblock ~196 ~123 ~45 dirt
setblock ~196 ~123 ~46 dirt
setblock ~196 ~123 ~47 dirt
setblock ~196 ~123 ~48 dirt
setblock ~196 ~123 ~49 dirt
setblock ~196 ~123 ~50 dirt
setblock ~196 ~123 ~51 dirt
setblock ~196 ~123 ~52 dirt
setblock ~196 ~123 ~53 dirt
setblock ~196 ~123 ~54 dirt
setblock ~196 ~123 ~55 dirt
setblock ~196 ~123 ~56 dirt
setblock ~196 ~123 ~57 dirt
setblock ~196 ~123 ~58 dirt
setblock ~196 ~123 ~59 dirt
setblock ~196 ~123 ~60 grass_block
setblock ~196 ~123 ~61 grass_block
setblock ~196 ~123 ~62 grass_block
setblock ~196 ~123 ~63 grass_block
setblock ~196 ~123 ~64 grass_block
setblock ~196 ~123 ~65 grass_block
setblock ~196 ~123 ~66 grass_block
setblock ~196 ~123 ~67 grass_block
setblock ~196 ~123 ~68 grass_block
setblock ~196 ~123 ~69 grass_block
setblock ~196 ~123 ~70 grass_block
setblock ~196 ~123 ~71 grass_block
setblock ~196 ~123 ~72 grass_block
setblock ~196 ~123 ~73 grass_block
setblock ~196 ~123 ~74 grass_block
setblock ~196 ~123 ~75 grass_block
setblock ~196 ~123 ~76 dirt
setblock ~196 ~123 ~77 dirt
setblock ~196 ~123 ~78 dirt
setblock ~196 ~123 ~79 dirt
setblock ~196 ~123 ~80 dirt
setblock ~196 ~123 ~81 dirt
setblock ~196 ~123 ~82 dirt
setblock ~196 ~123 ~83 dirt
setblock ~196 ~123 ~84 dirt
setblock ~196 ~123 ~85 dirt
setblock ~196 ~123 ~86 dirt
setblock ~196 ~123 ~87 dirt
setblock ~196 ~123 ~88 dirt
setblock ~196 ~123 ~89 dirt
setblock ~196 ~123 ~90 dirt
setblock ~196 ~123 ~91 dirt
setblock ~196 ~123 ~92 dirt
setblock ~196 ~123 ~93 dirt
setblock ~196 ~123 ~94 dirt
setblock ~196 ~123 ~95 dirt
setblock ~196 ~123 ~96 dirt
setblock ~196 ~123 ~97 dirt
setblock ~196 ~123 ~98 dirt
setblock ~196 ~123 ~99 dirt
setblock ~196 ~123 ~100 dirt
setblock ~196 ~123 ~101 dirt
setblock ~196 ~123 ~102 dirt
setblock ~196 ~123 ~103 dirt
setblock ~196 ~123 ~104 dirt
setblock ~196 ~123 ~105 dirt
setblock ~196 ~123 ~106 dirt
setblock ~196 ~123 ~107 dirt
setblock ~196 ~123 ~108 dirt
setblock ~196 ~123 ~109 dirt
setblock ~196 ~123 ~110 dirt
setblock ~196 ~123 ~111 dirt
setblock ~196 ~123 ~112 dirt
setblock ~196 ~123 ~113 dirt
setblock ~196 ~123 ~114 dirt
setblock ~196 ~123 ~115 dirt
setblock ~196 ~123 ~116 dirt
setblock ~196 ~123 ~117 dirt
setblock ~196 ~123 ~118 dirt
setblock ~196 ~123 ~119 dirt
setblock ~196 ~123 ~120 dirt
setblock ~196 ~123 ~121 dirt
setblock ~196 ~123 ~122 dirt
setblock ~196 ~123 ~123 dirt
setblock ~196 ~123 ~124 dirt
setblock ~196 ~123 ~125 dirt
setblock ~196 ~123 ~126 dirt
setblock ~196 ~123 ~127 dirt
setblock ~196 ~123 ~128 dirt
setblock ~196 ~123 ~129 dirt
setblock ~196 ~123 ~130 dirt
setblock ~196 ~123 ~131 dirt
setblock ~196 ~123 ~132 dirt
setblock ~196 ~123 ~133 dirt
setblock ~196 ~123 ~134 grass_block
setblock ~196 ~123 ~135 grass_block
setblock ~196 ~123 ~136 grass_block
setblock ~196 ~123 ~137 grass_block
setblock ~196 ~123 ~138 grass_block
setblock ~196 ~123 ~139 grass_block
setblock ~196 ~123 ~140 grass_block
setblock ~196 ~123 ~141 grass_block
setblock ~196 ~123 ~142 grass_block
setblock ~196 ~123 ~143 dirt
setblock ~196 ~123 ~144 dirt
setblock ~196 ~123 ~145 dirt
setblock ~196 ~123 ~146 dirt
setblock ~196 ~123 ~147 dirt
setblock ~196 ~123 ~148 dirt
setblock ~196 ~123 ~149 dirt
setblock ~196 ~123 ~150 dirt
setblock ~196 ~123 ~151 dirt
setblock ~196 ~123 ~152 dirt
setblock ~196 ~123 ~153 dirt
setblock ~196 ~123 ~154 dirt
setblock ~196 ~123 ~155 dirt
setblock ~196 ~123 ~156 dirt
setblock ~196 ~123 ~157 dirt
setblock ~196 ~123 ~158 dirt
setblock ~196 ~123 ~159 grass_block
setblock ~196 ~123 ~160 grass_block
setblock ~196 ~123 ~161 grass_block
setblock ~196 ~123 ~162 grass_block
setblock ~196 ~123 ~163 dirt
setblock ~196 ~123 ~164 dirt
setblock ~196 ~123 ~165 dirt
setblock ~196 ~123 ~166 dirt
setblock ~196 ~123 ~167 dirt
setblock ~196 ~123 ~168 dirt
setblock ~196 ~123 ~169 dirt
setblock ~196 ~123 ~170 dirt
setblock ~196 ~123 ~171 dirt
setblock ~196 ~123 ~172 dirt
setblock ~196 ~123 ~173 dirt
setblock ~196 ~123 ~174 dirt
setblock ~196 ~123 ~175 dirt
setblock ~196 ~123 ~176 dirt
setblock ~196 ~123 ~177 dirt
setblock ~196 ~123 ~178 dirt
setblock ~196 ~123 ~179 dirt
setblock ~196 ~123 ~180 dirt
setblock ~196 ~123 ~181 dirt
setblock ~196 ~123 ~182 dirt
setblock ~196 ~123 ~183 dirt
setblock ~196 ~123 ~184 dirt
setblock ~196 ~123 ~185 dirt
setblock ~196 ~123 ~186 dirt
setblock ~196 ~123 ~187 dirt
setblock ~196 ~123 ~188 dirt
setblock ~196 ~123 ~189 dirt
setblock ~196 ~123 ~190 dirt
setblock ~196 ~123 ~191 dirt
setblock ~196 ~123 ~192 dirt
setblock ~196 ~123 ~193 dirt
setblock ~196 ~123 ~194 dirt
setblock ~196 ~123 ~195 dirt
setblock ~196 ~123 ~196 dirt
setblock ~196 ~123 ~197 dirt
setblock ~196 ~123 ~198 dirt
setblock ~196 ~123 ~199 dirt
setblock ~196 ~124 ~0 dirt
setblock ~196 ~124 ~1 dirt
setblock ~196 ~124 ~2 dirt
setblock ~196 ~124 ~3 dirt
setblock ~196 ~124 ~4 dirt
setblock ~196 ~124 ~5 dirt
setblock ~196 ~124 ~6 dirt
setblock ~196 ~124 ~7 grass_block
setblock ~196 ~124 ~8 grass_block
setblock ~196 ~124 ~9 grass_block
setblock ~196 ~124 ~11 grass_block
setblock ~196 ~124 ~12 grass_block
setblock ~196 ~124 ~13 grass_block
setblock ~196 ~124 ~14 grass_block
setblock ~196 ~124 ~15 grass_block
setblock ~196 ~124 ~16 grass_block
setblock ~196 ~124 ~17 grass_block
setblock ~196 ~124 ~18 dirt
setblock ~196 ~124 ~19 dirt
setblock ~196 ~124 ~20 dirt
setblock ~196 ~124 ~21 dirt
setblock ~196 ~124 ~22 dirt
setblock ~196 ~124 ~23 dirt
setblock ~196 ~124 ~24 dirt
setblock ~196 ~124 ~25 dirt
setblock ~196 ~124 ~26 dirt
setblock ~196 ~124 ~27 dirt
setblock ~196 ~124 ~28 dirt
setblock ~196 ~124 ~29 dirt
setblock ~196 ~124 ~30 dirt
setblock ~196 ~124 ~31 dirt
setblock ~196 ~124 ~32 dirt
setblock ~196 ~124 ~33 dirt
setblock ~196 ~124 ~34 dirt
setblock ~196 ~124 ~35 dirt
setblock ~196 ~124 ~36 dirt
setblock ~196 ~124 ~37 dirt
setblock ~196 ~124 ~38 dirt
setblock ~196 ~124 ~39 dirt
setblock ~196 ~124 ~40 dirt
setblock ~196 ~124 ~41 dirt
setblock ~196 ~124 ~42 dirt
setblock ~196 ~124 ~43 dirt
setblock ~196 ~124 ~44 dirt
setblock ~196 ~124 ~45 dirt
setblock ~196 ~124 ~46 dirt
setblock ~196 ~124 ~47 dirt
setblock ~196 ~124 ~48 dirt
setblock ~196 ~124 ~49 dirt
setblock ~196 ~124 ~50 dirt
setblock ~196 ~124 ~51 dirt
setblock ~196 ~124 ~52 dirt
setblock ~196 ~124 ~53 dirt
setblock ~196 ~124 ~54 dirt
setblock ~196 ~124 ~55 dirt
setblock ~196 ~124 ~56 dirt
setblock ~196 ~124 ~57 dirt
setblock ~196 ~124 ~58 grass_block
setblock ~196 ~124 ~59 grass_block
setblock ~196 ~124 ~62 short_grass
setblock ~196 ~124 ~70 short_grass
setblock ~196 ~124 ~71 short_grass
setblock ~196 ~124 ~72 short_grass
setblock ~196 ~124 ~76 grass_block
setblock ~196 ~124 ~77 grass_block
setblock ~196 ~124 ~78 grass_block
setblock ~196 ~124 ~79 grass_block
setblock ~196 ~124 ~80 grass_block
setblock ~196 ~124 ~81 grass_block
setblock ~196 ~124 ~82 grass_block
setblock ~196 ~124 ~83 grass_block
setblock ~196 ~124 ~84 grass_block
setblock ~196 ~124 ~85 grass_block
setblock ~196 ~124 ~86 grass_block
setblock ~196 ~124 ~87 grass_block
setblock ~196 ~124 ~88 grass_block
setblock ~196 ~124 ~89 grass_block
setblock ~196 ~124 ~90 grass_block
setblock ~196 ~124 ~91 grass_block
setblock ~196 ~124 ~92 grass_block
setblock ~196 ~124 ~93 grass_block
setblock ~196 ~124 ~94 grass_block
setblock ~196 ~124 ~95 grass_block
setblock ~196 ~124 ~96 grass_block
setblock ~196 ~124 ~97 dirt
setblock ~196 ~124 ~98 dirt
setblock ~196 ~124 ~99 dirt
setblock ~196 ~124 ~100 dirt
setblock ~196 ~124 ~101 dirt
setblock ~196 ~124 ~102 dirt
setblock ~196 ~124 ~103 dirt
setblock ~196 ~124 ~104 dirt
setblock ~196 ~124 ~105 dirt
setblock ~196 ~124 ~106 dirt
setblock ~196 ~124 ~107 dirt
setblock ~196 ~124 ~108 dirt
setblock ~196 ~124 ~109 dirt
setblock ~196 ~124 ~110 dirt
setblock ~196 ~124 ~111 dirt
setblock ~196 ~124 ~112 dirt
setblock ~196 ~124 ~113 dirt
setblock ~196 ~124 ~114 dirt
setblock ~196 ~124 ~115 dirt
setblock ~196 ~124 ~116 dirt
setblock ~196 ~124 ~117 dirt
setblock ~196 ~124 ~118 dirt
setblock ~196 ~124 ~119 grass_block
setblock ~196 ~124 ~120 grass_block
setblock ~196 ~124 ~121 grass_block
setblock ~196 ~124 ~122 grass_block
setblock ~196 ~124 ~123 grass_block
setblock ~196 ~124 ~124 grass_block
setblock ~196 ~124 ~125 grass_block
setblock ~196 ~124 ~126 grass_block
setblock ~196 ~124 ~127 grass_block
setblock ~196 ~124 ~128 grass_block
setblock ~196 ~124 ~129 grass_block
setblock ~196 ~124 ~130 grass_block
setblock ~196 ~124 ~131 grass_block
setblock ~196 ~124 ~132 grass_block
setblock ~196 ~124 ~133 grass_block
setblock ~196 ~124 ~134 short_grass
setblock ~196 ~124 ~136 poppy
setblock ~196 ~124 ~137 short_grass
setblock ~196 ~124 ~139 short_grass
setblock ~196 ~124 ~140 poppy
setblock ~196 ~124 ~141 short_grass
setblock ~196 ~124 ~142 fern
setblock ~196 ~124 ~143 grass_block
setblock ~196 ~124 ~144 grass_block
setblock ~196 ~124 ~145 grass_block
setblock ~196 ~124 ~146 grass_block
setblock ~196 ~124 ~147 dirt
setblock ~196 ~124 ~148 dirt
setblock ~196 ~124 ~149 dirt
setblock ~196 ~124 ~150 dirt
setblock ~196 ~124 ~151 dirt
setblock ~196 ~124 ~152 dirt
setblock ~196 ~124 ~153 dirt
setblock ~196 ~124 ~154 dirt
setblock ~196 ~124 ~155 dirt
setblock ~196 ~124 ~156 grass_block
setblock ~196 ~124 ~157 grass_block
setblock ~196 ~124 ~158 grass_block
setblock ~196 ~124 ~161 short_grass
setblock ~196 ~124 ~162 short_grass
setblock ~196 ~124 ~163 grass_block
setblock ~196 ~124 ~164 grass_block
setblock ~196 ~124 ~165 grass_block
setblock ~196 ~124 ~166 grass_block
setblock ~196 ~124 ~167 grass_block
setblock ~196 ~124 ~168 dirt
setblock ~196 ~124 ~169 dirt
setblock ~196 ~124 ~170 dirt
setblock ~196 ~124 ~171 dirt
setblock ~196 ~124 ~172 dirt
setblock ~196 ~124 ~173 dirt
setblock ~196 ~124 ~174 dirt
setblock ~196 ~124 ~175 dirt
setblock ~196 ~124 ~176 dirt
setblock ~196 ~124 ~177 dirt
setblock ~196 ~124 ~178 dirt
setblock ~196 ~124 ~179 dirt
setblock ~196 ~124 ~180 dirt
setblock ~196 ~124 ~181 dirt
setblock ~196 ~124 ~182 dirt
setblock ~196 ~124 ~183 dirt
setblock ~196 ~124 ~184 dirt
setblock ~196 ~124 ~185 dirt
setblock ~196 ~124 ~186 dirt
setblock ~196 ~124 ~187 dirt
setblock ~196 ~124 ~188 dirt
setblock ~196 ~124 ~189 dirt
setblock ~196 ~124 ~190 dirt
setblock ~196 ~124 ~191 dirt
setblock ~196 ~124 ~192 dirt
setblock ~196 ~124 ~193 dirt
setblock ~196 ~124 ~194 dirt
setblock ~196 ~124 ~195 dirt
setblock ~196 ~124 ~196 dirt
setblock ~196 ~124 ~197 dirt
setblock ~196 ~124 ~198 dirt
setblock ~196 ~124 ~199 dirt
setblock ~196 ~125 ~0 dirt
setblock ~196 ~125 ~1 dirt
setblock ~196 ~125 ~2 dirt
setblock ~196 ~125 ~3 grass_block
setblock ~196 ~125 ~4 grass_block
setblock ~196 ~125 ~5 grass_block
setblock ~196 ~125 ~6 grass_block
setblock ~196 ~125 ~14 short_grass
setblock ~196 ~125 ~18 grass_block
setblock ~196 ~125 ~19 grass_block
setblock ~196 ~125 ~20 grass_block
setblock ~196 ~125 ~21 grass_block
setblock ~196 ~125 ~22 grass_block
setblock ~196 ~125 ~23 grass_block
setblock ~196 ~125 ~24 dirt
setblock ~196 ~125 ~25 dirt
setblock ~196 ~125 ~26 dirt
setblock ~196 ~125 ~27 dirt
setblock ~196 ~125 ~28 dirt
setblock ~196 ~125 ~29 dirt
setblock ~196 ~125 ~30 dirt
setblock ~196 ~125 ~31 dirt
setblock ~196 ~125 ~32 dirt
setblock ~196 ~125 ~33 dirt
setblock ~196 ~125 ~34 dirt
setblock ~196 ~125 ~35 dirt
setblock ~196 ~125 ~36 dirt
setblock ~196 ~125 ~37 dirt
setblock ~196 ~125 ~38 dirt
setblock ~196 ~125 ~39 dirt
setblock ~196 ~125 ~40 dirt
setblock ~196 ~125 ~41 dirt
setblock ~196 ~125 ~42 dirt
setblock ~196 ~125 ~43 dirt
setblock ~196 ~125 ~44 dirt
setblock ~196 ~125 ~45 dirt
setblock ~196 ~125 ~46 dirt
setblock ~196 ~125 ~47 dirt
setblock ~196 ~125 ~48 dirt
setblock ~196 ~125 ~49 dirt
setblock ~196 ~125 ~50 dirt
setblock ~196 ~125 ~51 dirt
setblock ~196 ~125 ~52 dirt
setblock ~196 ~125 ~53 dirt
setblock ~196 ~125 ~54 dirt
setblock ~196 ~125 ~55 dirt
setblock ~196 ~125 ~56 grass_block
setblock ~196 ~125 ~57 grass_block
setblock ~196 ~125 ~77 fern
setblock ~196 ~125 ~83 short_grass
setblock ~196 ~125 ~88 short_grass
setblock ~196 ~125 ~89 poppy
setblock ~196 ~125 ~92 short_grass
setblock ~196 ~125 ~93 short_grass
setblock ~196 ~125 ~95 short_grass
setblock ~196 ~125 ~97 grass_block
setblock ~196 ~125 ~98 grass_block
setblock ~196 ~125 ~99 grass_block
setblock ~196 ~125 ~100 grass_block
setblock ~196 ~125 ~101 grass_block
setblock ~196 ~125 ~102 grass_block
setblock ~196 ~125 ~103 grass_block
setblock ~196 ~125 ~104 grass_block
setblock ~196 ~125 ~105 dirt
setblock ~196 ~125 ~106 dirt
setblock ~196 ~125 ~107 dirt
setblock ~196 ~125 ~108 dirt
setblock ~196 ~125 ~109 dirt
setblock ~196 ~125 ~110 dirt
setblock ~196 ~125 ~111 dirt
setblock ~196 ~125 ~112 dirt
setblock ~196 ~125 ~113 dirt
setblock ~196 ~125 ~114 dirt
setblock ~196 ~125 ~115 grass_block
setblock ~196 ~125 ~116 grass_block
setblock ~196 ~125 ~117 grass_block
setblock ~196 ~125 ~118 grass_block
setblock ~196 ~125 ~123 short_grass
setblock ~196 ~125 ~125 short_grass
setblock ~196 ~125 ~130 fern
setblock ~196 ~125 ~131 short_grass
setblock ~196 ~125 ~143 short_grass
setblock ~196 ~125 ~146 poppy
setblock ~196 ~125 ~147 grass_block
setblock ~196 ~125 ~148 grass_block
setblock ~196 ~125 ~149 dirt
setblock ~196 ~125 ~150 dirt
setblock ~196 ~125 ~151 dirt
setblock ~196 ~125 ~152 dirt
setblock ~196 ~125 ~153 grass_block
setblock ~196 ~125 ~154 grass_block
setblock ~196 ~125 ~155 grass_block
setblock ~196 ~125 ~157 short_grass
setblock ~196 ~125 ~163 short_grass
setblock ~196 ~125 ~165 short_grass
setblock ~196 ~125 ~166 short_grass
setblock ~196 ~125 ~168 grass_block
setblock ~196 ~125 ~169 grass_block
setblock ~196 ~125 ~170 grass_block
setblock ~196 ~125 ~171 grass_block
setblock ~196 ~125 ~172 grass_block
setblock ~196 ~125 ~173 grass_block
setblock ~196 ~125 ~174 grass_block
setblock ~196 ~125 ~175 grass_block
setblock ~196 ~125 ~176 grass_block
setblock ~196 ~125 ~177 grass_block
setblock ~196 ~125 ~178 grass_block
setblock ~196 ~125 ~179 grass_block
setblock ~196 ~125 ~180 grass_block
setblock ~196 ~125 ~181 grass_block
setblock ~196 ~125 ~182 grass_block
setblock ~196 ~125 ~183 grass_block
setblock ~196 ~125 ~184 grass_block
setblock ~196 ~125 ~185 grass_block
setblock ~196 ~125 ~186 grass_block
setblock ~196 ~125 ~187 grass_block
setblock ~196 ~125 ~188 dirt
setblock ~196 ~125 ~189 dirt
setblock ~196 ~125 ~190 dirt
setblock ~196 ~125 ~191 dirt
setblock ~196 ~125 ~192 dirt
setblock ~196 ~125 ~193 dirt
setblock ~196 ~125 ~194 dirt
setblock ~196 ~125 ~195 grass_block
setblock ~196 ~125 ~196 grass_block
setblock ~196 ~125 ~197 grass_block
setblock ~196 ~125 ~198 grass_block
setblock ~196 ~125 ~199 grass_block
setblock ~196 ~126 ~0 grass_block
setblock ~196 ~126 ~1 grass_block
setblock ~196 ~126 ~2 grass_block
setblock ~196 ~126 ~5 short_grass
setblock ~196 ~126 ~20 short_grass
setblock ~196 ~126 ~21 short_grass
setblock ~196 ~126 ~22 short_grass
setblock ~196 ~126 ~23 short_grass
setblock ~196 ~126 ~24 grass_block
setblock ~196 ~126 ~25 grass_block
setblock ~196 ~126 ~26 grass_block
setblock ~196 ~126 ~27 grass_block
setblock ~196 ~126 ~28 dirt
setblock ~196 ~126 ~29 dirt
setblock ~196 ~126 ~30 dirt
setblock ~196 ~126 ~31 dirt
setblock ~196 ~126 ~32 dirt
setblock ~196 ~126 ~33 dirt
setblock ~196 ~126 ~34 dirt
setblock ~196 ~126 ~35 dirt
setblock ~196 ~126 ~36 dirt
setblock ~196 ~126 ~37 dirt
setblock ~196 ~126 ~38 dirt
setblock ~196 ~126 ~39 dirt
setblock ~196 ~126 ~40 dirt
setblock ~196 ~126 ~41 dirt
setblock ~196 ~126 ~42 dirt
setblock ~196 ~126 ~43 dirt
setblock ~196 ~126 ~44 dirt
setblock ~196 ~126 ~45 dirt
setblock ~196 ~126 ~46 dirt
setblock ~196 ~126 ~47 dirt
setblock ~196 ~126 ~48 dirt
setblock ~196 ~126 ~49 dirt
setblock ~196 ~126 ~50 dirt
setblock ~196 ~126 ~51 dirt
setblock ~196 ~126 ~52 dirt
setblock ~196 ~126 ~53 dirt
setblock ~196 ~126 ~54 dirt
setblock ~196 ~126 ~55 grass_block
setblock ~196 ~126 ~101 short_grass
setblock ~196 ~126 ~103 fern
setblock ~196 ~126 ~105 grass_block
setblock ~196 ~126 ~106 grass_block
setblock ~196 ~126 ~107 grass_block
setblock ~196 ~126 ~108 grass_block
setblock ~196 ~126 ~109 dirt
setblock ~196 ~126 ~110 dirt
setblock ~196 ~126 ~111 dirt
setblock ~196 ~126 ~112 grass_block
setblock ~196 ~126 ~113 grass_block
setblock ~196 ~126 ~114 grass_block
setblock ~196 ~126 ~147 short_grass
setblock ~196 ~126 ~149 grass_block
setblock ~196 ~126 ~150 grass_block
setblock ~196 ~126 ~151 grass_block
setblock ~196 ~126 ~152 grass_block
setblock ~196 ~126 ~153 short_grass
setblock ~196 ~126 ~155 fern
setblock ~196 ~126 ~173 fern
setblock ~196 ~126 ~178 short_grass
setblock ~196 ~126 ~179 short_grass
setblock ~196 ~126 ~188 grass_block
setblock ~196 ~126 ~189 grass_block
setblock ~196 ~126 ~190 grass_block
setblock ~196 ~126 ~191 grass_block
setblock ~196 ~126 ~192 grass_block
setblock ~196 ~126 ~193 grass_block
setblock ~196 ~126 ~194 grass_block
setblock ~196 ~126 ~197 short_grass
setblock ~196 ~127 ~27 short_grass
setblock ~196 ~127 ~28 grass_block
setblock ~196 ~127 ~29 grass_block
setblock ~196 ~127 ~30 dirt
setblock ~196 ~127 ~31 dirt
setblock ~196 ~127 ~32 dirt
setblock ~196 ~127 ~33 grass_block
setblock ~196 ~127 ~34 grass_block
setblock ~196 ~127 ~35 grass_block
setblock ~196 ~127 ~36 grass_block
setblock ~196 ~127 ~37 grass_block
setblock ~196 ~127 ~38 grass_block
setblock ~196 ~127 ~39 grass_block
setblock ~196 ~127 ~40 grass_block
setblock ~196 ~127 ~41 grass_block
setblock ~196 ~127 ~42 grass_block
setblock ~196 ~127 ~43 grass_block
setblock ~196 ~127 ~44 dirt
setblock ~196 ~127 ~45 dirt
setblock ~196 ~127 ~46 dirt
setblock ~196 ~127 ~47 dirt
setblock ~196 ~127 ~48 dirt
setblock ~196 ~127 ~49 dirt
setblock ~196 ~127 ~50 dirt
setblock ~196 ~127 ~51 dirt
setblock ~196 ~127 ~52 dirt
setblock ~196 ~127 ~53 grass_block
setblock ~196 ~127 ~54 grass_block
setblock ~196 ~127 ~105 short_grass
setblock ~196 ~127 ~107 short_grass
setblock ~196 ~127 ~108 short_grass
setblock ~196 ~127 ~109 grass_block
setblock ~196 ~127 ~110 grass_block
setblock ~196 ~127 ~111 grass_block
setblock ~196 ~127 ~149 short_grass
setblock ~196 ~128 ~28 poppy
setblock ~196 ~128 ~30 grass_block
setblock ~196 ~128 ~31 grass_block
setblock ~196 ~128 ~32 grass_block
setblock ~196 ~128 ~33 short_grass
setblock ~196 ~128 ~38 short_grass
setblock ~196 ~128 ~40 short_grass
setblock ~196 ~128 ~41 short_grass
setblock ~196 ~128 ~44 grass_block
setblock ~196 ~128 ~45 grass_block
setblock ~196 ~128 ~46 grass_block
setblock ~196 ~128 ~47 grass_block
setblock ~196 ~128 ~48 grass_block
setblock ~196 ~128 ~49 grass_block
setblock ~196 ~128 ~50 grass_block
setblock ~196 ~128 ~51 grass_block
setblock ~196 ~128 ~52 grass_block
setblock ~196 ~129 ~49 fern
setblock ~196 ~129 ~52 poppy
setblock ~197 ~122 ~0 dirt
setblock ~197 ~122 ~1 dirt
setblock ~197 ~122 ~2 dirt
setblock ~197 ~122 ~3 dirt
setblock ~197 ~122 ~4 dirt
setblock ~197 ~122 ~5 dirt
setblock ~197 ~122 ~6 dirt
setblock ~197 ~122 ~7 dirt
setblock ~197 ~122 ~8 dirt
setblock ~197 ~122 ~9 dirt
setblock ~197 ~122 ~10 dirt
setblock ~197 ~122 ~11 dirt
setblock ~197 ~122 ~12 dirt
setblock ~197 ~122 ~13 dirt
setblock ~197 ~122 ~14 dirt
setblock ~197 ~122 ~15 dirt
setblock ~197 ~122 ~16 dirt
setblock ~197 ~122 ~17 dirt
setblock ~197 ~122 ~18 dirt
setblock ~197 ~122 ~19 dirt
setblock ~197 ~122 ~20 dirt
setblock ~197 ~122 ~21 dirt
setblock ~197 ~122 ~22 dirt
setblock ~197 ~122 ~23 dirt
setblock ~197 ~122 ~24 dirt
setblock ~197 ~122 ~25 dirt
setblock ~197 ~122 ~26 dirt
setblock ~197 ~122 ~27 dirt
setblock ~197 ~122 ~28 dirt
setblock ~197 ~122 ~29 dirt
setblock ~197 ~122 ~30 dirt
setblock ~197 ~122 ~31 dirt
setblock ~197 ~122 ~32 dirt
setblock ~197 ~122 ~33 dirt
setblock ~197 ~122 ~34 dirt
setblock ~197 ~122 ~35 dirt
setblock ~197 ~122 ~36 dirt
setblock ~197 ~122 ~37 dirt
setblock ~197 ~122 ~38 dirt
setblock ~197 ~122 ~39 dirt
setblock ~197 ~122 ~40 dirt
setblock ~197 ~122 ~41 dirt
setblock ~197 ~122 ~42 dirt
setblock ~197 ~122 ~43 dirt
setblock ~197 ~122 ~44 dirt
setblock ~197 ~122 ~45 dirt
setblock ~197 ~122 ~46 dirt
setblock ~197 ~122 ~47 dirt
setblock ~197 ~122 ~48 dirt
setblock ~197 ~122 ~49 dirt
setblock ~197 ~122 ~50 dirt
setblock ~197 ~122 ~51 dirt
setblock ~197 ~122 ~52 dirt
setblock ~197 ~122 ~53 dirt
setblock ~197 ~122 ~54 dirt
setblock ~197 ~122 ~55 dirt
setblock ~197 ~122 ~56 dirt
setblock ~197 ~122 ~57 dirt
setblock ~197 ~122 ~58 dirt
setblock ~197 ~122 ~59 dirt
setblock ~197 ~122 ~60 dirt
setblock ~197 ~122 ~61 dirt
setblock ~197 ~122 ~62 dirt
setblock ~197 ~122 ~63 dirt
setblock ~197 ~122 ~64 dirt
setblock ~197 ~122 ~65 dirt
setblock ~197 ~122 ~66 dirt
setblock ~197 ~122 ~67 dirt
setblock ~197 ~122 ~68 dirt
setblock ~197 ~122 ~69 dirt
setblock ~197 ~122 ~70 dirt
setblock ~197 ~122 ~71 dirt
setblock ~197 ~122 ~72 dirt
setblock ~197 ~122 ~73 dirt
setblock ~197 ~122 ~74 dirt
setblock ~197 ~122 ~75 dirt
setblock ~197 ~122 ~76 dirt
setblock ~197 ~122 ~77 dirt
setblock ~197 ~122 ~78 dirt
setblock ~197 ~122 ~79 dirt
setblock ~197 ~122 ~80 dirt
setblock ~197 ~122 ~81 dirt
setblock ~197 ~122 ~82 dirt
setblock ~197 ~122 ~83 dirt
setblock ~197 ~122 ~84 dirt
setblock ~197 ~122 ~85 dirt
setblock ~197 ~122 ~86 dirt
setblock ~197 ~122 ~87 dirt
setblock ~197 ~122 ~88 dirt
setblock ~197 ~122 ~89 dirt
setblock ~197 ~122 ~90 dirt
setblock ~197 ~122 ~91 dirt
setblock ~197 ~122 ~92 dirt
setblock ~197 ~122 ~93 dirt
setblock ~197 ~122 ~94 dirt
setblock ~197 ~122 ~95 dirt
setblock ~197 ~122 ~96 dirt
setblock ~197 ~122 ~97 dirt
setblock ~197 ~122 ~98 dirt
setblock ~197 ~122 ~99 dirt
setblock ~197 ~122 ~100 dirt
setblock ~197 ~122 ~101 dirt
setblock ~197 ~122 ~102 dirt
setblock ~197 ~122 ~103 dirt
setblock ~197 ~122 ~104 dirt
setblock ~197 ~122 ~105 dirt
setblock ~197 ~122 ~106 dirt
setblock ~197 ~122 ~107 dirt
setblock ~197 ~122 ~108 dirt
setblock ~197 ~122 ~109 dirt
setblock ~197 ~122 ~110 dirt
setblock ~197 ~122 ~111 dirt
setblock ~197 ~122 ~112 dirt
setblock ~197 ~122 ~113 dirt
setblock ~197 ~122 ~114 dirt
setblock ~197 ~122 ~115 dirt
setblock ~197 ~122 ~116 dirt
setblock ~197 ~122 ~117 dirt
setblock ~197 ~122 ~118 dirt
setblock ~197 ~122 ~119 dirt
setblock ~197 ~122 ~120 dirt
setblock ~197 ~122 ~121 dirt
setblock ~197 ~122 ~122 dirt
setblock ~197 ~122 ~123 dirt
setblock ~197 ~122 ~124 dirt
setblock ~197 ~122 ~125 dirt
setblock ~197 ~122 ~126 dirt
setblock ~197 ~122 ~127 dirt
setblock ~197 ~122 ~128 dirt
setblock ~197 ~122 ~129 dirt
setblock ~197 ~122 ~130 dirt
setblock ~197 ~122 ~131 dirt
setblock ~197 ~122 ~132 dirt
setblock ~197 ~122 ~133 dirt
setblock ~197 ~122 ~134 dirt
setblock ~197 ~122 ~135 dirt
setblock ~197 ~122 ~136 dirt
setblock ~197 ~122 ~137 dirt
setblock ~197 ~122 ~138 dirt
setblock ~197 ~122 ~139 dirt
setblock ~197 ~122 ~140 dirt
setblock ~197 ~122 ~141 dirt
setblock ~197 ~122 ~142 dirt
setblock ~197 ~122 ~143 dirt
setblock ~197 ~122 ~144 dirt
setblock ~197 ~122 ~145 dirt
setblock ~197 ~122 ~146 dirt
setblock ~197 ~122 ~147 dirt
setblock ~197 ~122 ~148 dirt
setblock ~197 ~122 ~149 dirt
setblock ~197 ~122 ~150 dirt
setblock ~197 ~122 ~151 dirt
setblock ~197 ~122 ~152 dirt
setblock ~197 ~122 ~153 dirt
setblock ~197 ~122 ~154 dirt
setblock ~197 ~122 ~155 dirt
setblock ~197 ~122 ~156 dirt
setblock ~197 ~122 ~157 dirt
setblock ~197 ~122 ~158 dirt
setblock ~197 ~122 ~159 dirt
setblock ~197 ~122 ~160 dirt
setblock ~197 ~122 ~161 dirt
setblock ~197 ~122 ~162 dirt
setblock ~197 ~122 ~163 dirt
setblock ~197 ~122 ~164 dirt
setblock ~197 ~122 ~165 dirt
setblock ~197 ~122 ~166 dirt
setblock ~197 ~122 ~167 dirt
setblock ~197 ~122 ~168 dirt
setblock ~197 ~122 ~169 dirt
setblock ~197 ~122 ~170 dirt
setblock ~197 ~122 ~171 dirt
setblock ~197 ~122 ~172 dirt
setblock ~197 ~122 ~173 dirt
setblock ~197 ~122 ~174 dirt
setblock ~197 ~122 ~175 dirt
setblock ~197 ~122 ~176 dirt
setblock ~197 ~122 ~177 dirt
setblock ~197 ~122 ~178 dirt
setblock ~197 ~122 ~179 dirt
setblock ~197 ~122 ~180 dirt
setblock ~197 ~122 ~181 dirt
setblock ~197 ~122 ~182 dirt
setblock ~197 ~122 ~183 dirt
setblock ~197 ~122 ~184 dirt
setblock ~197 ~122 ~185 dirt
setblock ~197 ~122 ~186 dirt
setblock ~197 ~122 ~187 dirt
setblock ~197 ~122 ~188 dirt
setblock ~197 ~122 ~189 dirt
setblock ~197 ~122 ~190 dirt
setblock ~197 ~122 ~191 dirt
setblock ~197 ~122 ~192 dirt
setblock ~197 ~122 ~193 dirt
setblock ~197 ~122 ~194 dirt
setblock ~197 ~122 ~195 dirt
setblock ~197 ~122 ~196 dirt
setblock ~197 ~122 ~197 dirt
setblock ~197 ~122 ~198 dirt
setblock ~197 ~122 ~199 dirt
setblock ~197 ~123 ~0 dirt
setblock ~197 ~123 ~1 dirt
setblock ~197 ~123 ~2 dirt
setblock ~197 ~123 ~3 dirt
setblock ~197 ~123 ~4 dirt
setblock ~197 ~123 ~5 dirt
setblock ~197 ~123 ~6 dirt
setblock ~197 ~123 ~7 dirt
setblock ~197 ~123 ~8 dirt
setblock ~197 ~123 ~9 dirt
setblock ~197 ~123 ~10 grass_block
setblock ~197 ~123 ~11 dirt
setblock ~197 ~123 ~12 dirt
setblock ~197 ~123 ~13 dirt
setblock ~197 ~123 ~14 dirt
setblock ~197 ~123 ~15 dirt
setblock ~197 ~123 ~16 dirt
setblock ~197 ~123 ~17 dirt
setblock ~197 ~123 ~18 dirt
setblock ~197 ~123 ~19 dirt
setblock ~197 ~123 ~20 dirt
setblock ~197 ~123 ~21 dirt
setblock ~197 ~123 ~22 dirt
setblock ~197 ~123 ~23 dirt
setblock ~197 ~123 ~24 dirt
setblock ~197 ~123 ~25 dirt
setblock ~197 ~123 ~26 dirt
setblock ~197 ~123 ~27 dirt
setblock ~197 ~123 ~28 dirt
setblock ~197 ~123 ~29 dirt
setblock ~197 ~123 ~30 dirt
setblock ~197 ~123 ~31 dirt
setblock ~197 ~123 ~32 dirt
setblock ~197 ~123 ~33 dirt
setblock ~197 ~123 ~34 dirt
setblock ~197 ~123 ~35 dirt
setblock ~197 ~123 ~36 dirt
setblock ~197 ~123 ~37 dirt
setblock ~197 ~123 ~38 dirt
setblock ~197 ~123 ~39 dirt
setblock ~197 ~123 ~40 dirt
setblock ~197 ~123 ~41 dirt
setblock ~197 ~123 ~42 dirt
setblock ~197 ~123 ~43 dirt
setblock ~197 ~123 ~44 dirt
setblock ~197 ~123 ~45 dirt
setblock ~197 ~123 ~46 dirt
setblock ~197 ~123 ~47 dirt
setblock ~197 ~123 ~48 dirt
setblock ~197 ~123 ~49 dirt
setblock ~197 ~123 ~50 dirt
setblock ~197 ~123 ~51 dirt
setblock ~197 ~123 ~52 dirt
setblock ~197 ~123 ~53 dirt
setblock ~197 ~123 ~54 dirt
setblock ~197 ~123 ~55 dirt
setblock ~197 ~123 ~56 dirt
setblock ~197 ~123 ~57 dirt
setblock ~197 ~123 ~58 dirt
setblock ~197 ~123 ~59 dirt
setblock ~197 ~123 ~60 grass_block
setblock ~197 ~123 ~61 grass_block
setblock ~197 ~123 ~62 grass_block
setblock ~197 ~123 ~63 grass_block
setblock ~197 ~123 ~64 grass_block
setblock ~197 ~123 ~65 grass_block
setblock ~197 ~123 ~66 grass_block
setblock ~197 ~123 ~67 grass_block
setblock ~197 ~123 ~68 grass_block
setblock ~197 ~123 ~69 grass_block
setblock ~197 ~123 ~70 grass_block
setblock ~197 ~123 ~71 grass_block
setblock ~197 ~123 ~72 grass_block
setblock ~197 ~123 ~73 grass_block
setblock ~197 ~123 ~74 grass_block
setblock ~197 ~123 ~75 grass_block
setblock ~197 ~123 ~76 grass_block
setblock ~197 ~123 ~77 dirt
setblock ~197 ~123 ~78 dirt
setblock ~197 ~123 ~79 dirt
setblock ~197 ~123 ~80 dirt
setblock ~197 ~123 ~81 dirt
setblock ~197 ~123 ~82 dirt
setblock ~197 ~123 ~83 dirt
setblock ~197 ~123 ~84 dirt
setblock ~197 ~123 ~85 dirt
setblock ~197 ~123 ~86 dirt
setblock ~197 ~123 ~87 dirt
setblock ~197 ~123 ~88 dirt
setblock ~197 ~123 ~89 dirt
setblock ~197 ~123 ~90 dirt
setblock ~197 ~123 ~91 dirt
setblock ~197 ~123 ~92 dirt
setblock ~197 ~123 ~93 dirt
setblock ~197 ~123 ~94 dirt
setblock ~197 ~123 ~95 dirt
setblock ~197 ~123 ~96 dirt
setblock ~197 ~123 ~97 dirt
setblock ~197 ~123 ~98 dirt
setblock ~197 ~123 ~99 dirt
setblock ~197 ~123 ~100 dirt
setblock ~197 ~123 ~101 dirt
setblock ~197 ~123 ~102 dirt
setblock ~197 ~123 ~103 dirt
setblock ~197 ~123 ~104 dirt
setblock ~197 ~123 ~105 dirt
setblock ~197 ~123 ~106 dirt
setblock ~197 ~123 ~107 dirt
setblock ~197 ~123 ~108 dirt
setblock ~197 ~123 ~109 dirt
setblock ~197 ~123 ~110 dirt
setblock ~197 ~123 ~111 dirt
setblock ~197 ~123 ~112 dirt
setblock ~197 ~123 ~113 dirt
setblock ~197 ~123 ~114 dirt
setblock ~197 ~123 ~115 dirt
setblock ~197 ~123 ~116 dirt
setblock ~197 ~123 ~117 dirt
setblock ~197 ~123 ~118 dirt
setblock ~197 ~123 ~119 dirt
setblock ~197 ~123 ~120 dirt
setblock ~197 ~123 ~121 dirt
setblock ~197 ~123 ~122 dirt
setblock ~197 ~123 ~123 dirt
setblock ~197 ~123 ~124 dirt
setblock ~197 ~123 ~125 dirt
setblock ~197 ~123 ~126 dirt
setblock ~197 ~123 ~127 dirt
setblock ~197 ~123 ~128 dirt
setblock ~197 ~123 ~129 dirt
setblock ~197 ~123 ~130 dirt
setblock ~197 ~123 ~131 dirt
setblock ~197 ~123 ~132 dirt
setblock ~197 ~123 ~133 dirt
setblock ~197 ~123 ~134 dirt
setblock ~197 ~123 ~135 grass_block
setblock ~197 ~123 ~136 grass_block
setblock ~197 ~123 ~137 grass_block
setblock ~197 ~123 ~138 grass_block
setblock ~197 ~123 ~139 grass_block
setblock ~197 ~123 ~140 grass_block
setblock ~197 ~123 ~141 grass_block
setblock ~197 ~123 ~142 grass_block
setblock ~197 ~123 ~143 grass_block
setblock ~197 ~123 ~144 dirt
setblock ~197 ~123 ~145 dirt
setblock ~197 ~123 ~146 dirt
setblock ~197 ~123 ~147 dirt
setblock ~197 ~123 ~148 dirt
setblock ~197 ~123 ~149 dirt
setblock ~197 ~123 ~150 dirt
setblock ~197 ~123 ~151 dirt
setblock ~197 ~123 ~152 dirt
setblock ~197 ~123 ~153 dirt
setblock ~197 ~123 ~154 dirt
setblock ~197 ~123 ~155 dirt
setblock ~197 ~123 ~156 dirt
setblock ~197 ~123 ~157 dirt
setblock ~197 ~123 ~158 dirt
setblock ~197 ~123 ~159 grass_block
setblock ~197 ~123 ~160 grass_block
setblock ~197 ~123 ~161 grass_block
setblock ~197 ~123 ~162 grass_block
setblock ~197 ~123 ~163 grass_block
setblock ~197 ~123 ~164 dirt
setblock ~197 ~123 ~165 dirt
setblock ~197 ~123 ~166 dirt
setblock ~197 ~123 ~167 dirt
setblock ~197 ~123 ~168 dirt
setblock ~197 ~123 ~169 dirt
setblock ~197 ~123 ~170 dirt
setblock ~197 ~123 ~171 dirt
setblock ~197 ~123 ~172 dirt
setblock ~197 ~123 ~173 dirt
setblock ~197 ~123 ~174 dirt
setblock ~197 ~123 ~175 dirt
setblock ~197 ~123 ~176 dirt
setblock ~197 ~123 ~177 dirt
setblock ~197 ~123 ~178 dirt
setblock ~197 ~123 ~179 dirt
setblock ~197 ~123 ~180 dirt
setblock ~197 ~123 ~181 dirt
setblock ~197 ~123 ~182 dirt
setblock ~197 ~123 ~183 dirt
setblock ~197 ~123 ~184 dirt
setblock ~197 ~123 ~185 dirt
setblock ~197 ~123 ~186 dirt
setblock ~197 ~123 ~187 dirt
setblock ~197 ~123 ~188 dirt
setblock ~197 ~123 ~189 dirt
setblock ~197 ~123 ~190 dirt
setblock ~197 ~123 ~191 dirt
setblock ~197 ~123 ~192 dirt
setblock ~197 ~123 ~193 dirt
setblock ~197 ~123 ~194 dirt
setblock ~197 ~123 ~195 dirt
setblock ~197 ~123 ~196 dirt
setblock ~197 ~123 ~197 dirt
setblock ~197 ~123 ~198 dirt
setblock ~197 ~123 ~199 dirt
setblock ~197 ~124 ~0 dirt
setblock ~197 ~124 ~1 dirt
setblock ~197 ~124 ~2 dirt
setblock ~197 ~124 ~3 dirt
setblock ~197 ~124 ~4 dirt
setblock ~197 ~124 ~5 dirt
setblock ~197 ~124 ~6 dirt
setblock ~197 ~124 ~7 grass_block
setblock ~197 ~124 ~8 grass_block
setblock ~197 ~124 ~9 grass_block
setblock ~197 ~124 ~11 grass_block
setblock ~197 ~124 ~12 grass_block
setblock ~197 ~124 ~13 grass_block
setblock ~197 ~124 ~14 grass_block
setblock ~197 ~124 ~15 grass_block
setblock ~197 ~124 ~16 grass_block
setblock ~197 ~124 ~17 grass_block
setblock ~197 ~124 ~18 grass_block
setblock ~197 ~124 ~19 dirt
setblock ~197 ~124 ~20 dirt
setblock ~197 ~124 ~21 dirt
setblock ~197 ~124 ~22 dirt
setblock ~197 ~124 ~23 dirt
setblock ~197 ~124 ~24 dirt
setblock ~197 ~124 ~25 dirt
setblock ~197 ~124 ~26 dirt
setblock ~197 ~124 ~27 dirt
setblock ~197 ~124 ~28 dirt
setblock ~197 ~124 ~29 dirt
setblock ~197 ~124 ~30 dirt
setblock ~197 ~124 ~31 dirt
setblock ~197 ~124 ~32 dirt
setblock ~197 ~124 ~33 dirt
setblock ~197 ~124 ~34 dirt
setblock ~197 ~124 ~35 dirt
setblock ~197 ~124 ~36 dirt
setblock ~197 ~124 ~37 dirt
setblock ~197 ~124 ~38 dirt
setblock ~197 ~124 ~39 dirt
setblock ~197 ~124 ~40 dirt
setblock ~197 ~124 ~41 dirt
setblock ~197 ~124 ~42 dirt
setblock ~197 ~124 ~43 dirt
setblock ~197 ~124 ~44 dirt
setblock ~197 ~124 ~45 dirt
setblock ~197 ~124 ~46 dirt
setblock ~197 ~124 ~47 dirt
setblock ~197 ~124 ~48 dirt
setblock ~197 ~124 ~49 dirt
setblock ~197 ~124 ~50 dirt
setblock ~197 ~124 ~51 dirt
setblock ~197 ~124 ~52 dirt
setblock ~197 ~124 ~53 dirt
setblock ~197 ~124 ~54 dirt
setblock ~197 ~124 ~55 dirt
setblock ~197 ~124 ~56 dirt
setblock ~197 ~124 ~57 dirt
setblock ~197 ~124 ~58 grass_block
setblock ~197 ~124 ~59 grass_block
setblock ~197 ~124 ~60 short_grass
setblock ~197 ~124 ~64 short_grass
setblock ~197 ~124 ~65 short_grass
setblock ~197 ~124 ~66 short_grass
setblock ~197 ~124 ~73 short_grass
setblock ~197 ~124 ~74 short_grass
setblock ~197 ~124 ~75 short_grass
setblock ~197 ~124 ~76 poppy
setblock ~197 ~124 ~77 grass_block
setblock ~197 ~124 ~78 grass_block
setblock ~197 ~124 ~79 grass_block
setblock ~197 ~124 ~80 grass_block
setblock ~197 ~124 ~81 grass_block
setblock ~197 ~124 ~82 grass_block
setblock ~197 ~124 ~83 grass_block
setblock ~197 ~124 ~84 grass_block
setblock ~197 ~124 ~85 grass_block
setblock ~197 ~124 ~86 grass_block
setblock ~197 ~124 ~87 grass_block
setblock ~197 ~124 ~88 grass_block
setblock ~197 ~124 ~89 grass_block
setblock ~197 ~124 ~90 grass_block
setblock ~197 ~124 ~91 grass_block
setblock ~197 ~124 ~92 grass_block
setblock ~197 ~124 ~93 grass_block
setblock ~197 ~124 ~94 grass_block
setblock ~197 ~124 ~95 grass_block
setblock ~197 ~124 ~96 dirt
setblock ~197 ~124 ~97 dirt
setblock ~197 ~124 ~98 dirt
setblock ~197 ~124 ~99 dirt
setblock ~197 ~124 ~100 dirt
setblock ~197 ~124 ~101 dirt
setblock ~197 ~124 ~102 dirt
setblock ~197 ~124 ~103 dirt
setblock ~197 ~124 ~104 dirt
setblock ~197 ~124 ~105 dirt
setblock ~197 ~124 ~106 dirt
setblock ~197 ~124 ~107 dirt
setblock ~197 ~124 ~108 dirt
setblock ~197 ~124 ~109 dirt
setblock ~197 ~124 ~110 dirt
setblock ~197 ~124 ~111 dirt
setblock ~197 ~124 ~112 dirt
setblock ~197 ~124 ~113 dirt
setblock ~197 ~124 ~114 dirt
setblock ~197 ~124 ~115 dirt
setblock ~197 ~124 ~116 dirt
setblock ~197 ~124 ~117 dirt
setblock ~197 ~124 ~118 dirt
setblock ~197 ~124 ~119 grass_block
setblock ~197 ~124 ~120 grass_block
setblock ~197 ~124 ~121 grass_block
setblock ~197 ~124 ~122 grass_block
setblock ~197 ~124 ~123 grass_block
setblock ~197 ~124 ~124 grass_block
setblock ~197 ~124 ~125 grass_block
setblock ~197 ~124 ~126 grass_block
setblock ~197 ~124 ~127 grass_block
setblock ~197 ~124 ~128 grass_block
setblock ~197 ~124 ~129 grass_block
setblock ~197 ~124 ~130 grass_block
setblock ~197 ~124 ~131 grass_block
setblock ~197 ~124 ~132 grass_block
setblock ~197 ~124 ~133 grass_block
setblock ~197 ~124 ~134 grass_block
setblock ~197 ~124 ~136 short_grass
setblock ~197 ~124 ~137 poppy
setblock ~197 ~124 ~138 short_grass
setblock ~197 ~124 ~139 poppy
setblock ~197 ~124 ~142 short_grass
setblock ~197 ~124 ~144 grass_block
setblock ~197 ~124 ~145 grass_block
setblock ~197 ~124 ~146 grass_block
setblock ~197 ~124 ~147 dirt
setblock ~197 ~124 ~148 dirt
setblock ~197 ~124 ~149 dirt
setblock ~197 ~124 ~150 dirt
setblock ~197 ~124 ~151 dirt
setblock ~197 ~124 ~152 dirt
setblock ~197 ~124 ~153 dirt
setblock ~197 ~124 ~154 dirt
setblock ~197 ~124 ~155 dirt
setblock ~197 ~124 ~156 grass_block
setblock ~197 ~124 ~157 grass_block
setblock ~197 ~124 ~158 grass_block
setblock ~197 ~124 ~163 short_grass
setblock ~197 ~124 ~164 grass_block
setblock ~197 ~124 ~165 grass_block
setblock ~197 ~124 ~166 grass_block
setblock ~197 ~124 ~167 grass_block
setblock ~197 ~124 ~168 grass_block
setblock ~197 ~124 ~169 dirt
setblock ~197 ~124 ~170 dirt
setblock ~197 ~124 ~171 dirt
setblock ~197 ~124 ~172 dirt
setblock ~197 ~124 ~173 dirt
setblock ~197 ~124 ~174 dirt
setblock ~197 ~124 ~175 dirt
setblock ~197 ~124 ~176 dirt
setblock ~197 ~124 ~177 dirt
setblock ~197 ~124 ~178 dirt
setblock ~197 ~124 ~179 dirt
setblock ~197 ~124 ~180 dirt
setblock ~197 ~124 ~181 dirt
setblock ~197 ~124 ~182 dirt
setblock ~197 ~124 ~183 dirt
setblock ~197 ~124 ~184 dirt
setblock ~197 ~124 ~185 dirt
setblock ~197 ~124 ~186 dirt
setblock ~197 ~124 ~187 dirt
setblock ~197 ~124 ~188 dirt
setblock ~197 ~124 ~189 dirt
setblock ~197 ~124 ~190 dirt
setblock ~197 ~124 ~191 dirt
setblock ~197 ~124 ~192 dirt
setblock ~197 ~124 ~193 dirt
setblock ~197 ~124 ~194 dirt
setblock ~197 ~124 ~195 dirt
setblock ~197 ~124 ~196 dirt
setblock ~197 ~124 ~197 dirt
setblock ~197 ~124 ~198 dirt
setblock ~197 ~124 ~199 dirt
setblock ~197 ~125 ~0 dirt
setblock ~197 ~125 ~1 dirt
setblock ~197 ~125 ~2 dirt
setblock ~197 ~125 ~3 dirt
setblock ~197 ~125 ~4 grass_block
setblock ~197 ~125 ~5 grass_block
setblock ~197 ~125 ~6 grass_block
setblock ~197 ~125 ~8 fern
setblock ~197 ~125 ~12 poppy
setblock ~197 ~125 ~19 grass_block
setblock ~197 ~125 ~20 grass_block
setblock ~197 ~125 ~21 grass_block
setblock ~197 ~125 ~22 grass_block
setblock ~197 ~125 ~23 grass_block
setblock ~197 ~125 ~24 dirt
setblock ~197 ~125 ~25 dirt
setblock ~197 ~125 ~26 dirt
setblock ~197 ~125 ~27 dirt
setblock ~197 ~125 ~28 dirt
setblock ~197 ~125 ~29 dirt
setblock ~197 ~125 ~30 dirt
setblock ~197 ~125 ~31 dirt
setblock ~197 ~125 ~32 dirt
setblock ~197 ~125 ~33 dirt
setblock ~197 ~125 ~34 dirt
setblock ~197 ~125 ~35 dirt
setblock ~197 ~125 ~36 dirt
setblock ~197 ~125 ~37 dirt
setblock ~197 ~125 ~38 dirt
setblock ~197 ~125 ~39 dirt
setblock ~197 ~125 ~40 dirt
setblock ~197 ~125 ~41 dirt
setblock ~197 ~125 ~42 dirt
setblock ~197 ~125 ~43 dirt
setblock ~197 ~125 ~44 dirt
setblock ~197 ~125 ~45 dirt
setblock ~197 ~125 ~46 dirt
setblock ~197 ~125 ~47 dirt
setblock ~197 ~125 ~48 dirt
setblock ~197 ~125 ~49 dirt
setblock ~197 ~125 ~50 dirt
setblock ~197 ~125 ~51 dirt
setblock ~197 ~125 ~52 dirt
setblock ~197 ~125 ~53 dirt
setblock ~197 ~125 ~54 dirt
setblock ~197 ~125 ~55 dirt
setblock ~197 ~125 ~56 grass_block
setblock ~197 ~125 ~57 grass_block
setblock ~197 ~125 ~77 short_grass
setblock ~197 ~125 ~78 short_grass
setblock ~197 ~125 ~87 poppy
setblock ~197 ~125 ~88 short_grass
setblock ~197 ~125 ~89 short_grass
setblock ~197 ~125 ~91 fern
setblock ~197 ~125 ~92 short_grass
setblock ~197 ~125 ~95 short_grass
setblock ~197 ~125 ~96 grass_block
setblock ~197 ~125 ~97 grass_block
setblock ~197 ~125 ~98 grass_block
setblock ~197 ~125 ~99 grass_block
setblock ~197 ~125 ~100 grass_block
setblock ~197 ~125 ~101 grass_block
setblock ~197 ~125 ~102 grass_block
setblock ~197 ~125 ~103 dirt
setblock ~197 ~125 ~104 dirt
setblock ~197 ~125 ~105 dirt
setblock ~197 ~125 ~106 dirt
setblock ~197 ~125 ~107 dirt
setblock ~197 ~125 ~108 dirt
setblock ~197 ~125 ~109 dirt
setblock ~197 ~125 ~110 dirt
setblock ~197 ~125 ~111 dirt
setblock ~197 ~125 ~112 dirt
setblock ~197 ~125 ~113 dirt
setblock ~197 ~125 ~114 dirt
setblock ~197 ~125 ~115 dirt
setblock ~197 ~125 ~116 grass_block
setblock ~197 ~125 ~117 grass_block
setblock ~197 ~125 ~118 grass_block
setblock ~197 ~125 ~124 short_grass
setblock ~197 ~125 ~128 short_grass
setblock ~197 ~125 ~131 poppy
setblock ~197 ~125 ~147 grass_block
setblock ~197 ~125 ~148 grass_block
setblock ~197 ~125 ~149 dirt
setblock ~197 ~125 ~150 dirt
setblock ~197 ~125 ~151 dirt
setblock ~197 ~125 ~152 dirt
setblock ~197 ~125 ~153 grass_block
setblock ~197 ~125 ~154 grass_block
setblock ~197 ~125 ~155 grass_block
setblock ~197 ~125 ~157 fern
setblock ~197 ~125 ~169 grass_block
setblock ~197 ~125 ~170 grass_block
setblock ~197 ~125 ~171 grass_block
setblock ~197 ~125 ~172 grass_block
setblock ~197 ~125 ~173 grass_block
setblock ~197 ~125 ~174 grass_block
setblock ~197 ~125 ~175 grass_block
setblock ~197 ~125 ~176 grass_block
setblock ~197 ~125 ~177 grass_block
setblock ~197 ~125 ~178 grass_block
setblock ~197 ~125 ~179 grass_block
setblock ~197 ~125 ~180 grass_block
setblock ~197 ~125 ~181 grass_block
setblock ~197 ~125 ~182 grass_block
setblock ~197 ~125 ~183 grass_block
setblock ~197 ~125 ~184 grass_block
setblock ~197 ~125 ~185 grass_block
setblock ~197 ~125 ~186 grass_block
setblock ~197 ~125 ~187 dirt
setblock ~197 ~125 ~188 dirt
setblock ~197 ~125 ~189 dirt
setblock ~197 ~125 ~190 dirt
setblock ~197 ~125 ~191 dirt
setblock ~197 ~125 ~192 dirt
setblock ~197 ~125 ~193 dirt
setblock ~197 ~125 ~194 dirt
setblock ~197 ~125 ~195 grass_block
setblock ~197 ~125 ~196 grass_block
setblock ~197 ~125 ~197 grass_block
setblock ~197 ~125 ~198 grass_block
setblock ~197 ~125 ~199 grass_block
setblock ~197 ~126 ~0 dirt
setblock ~197 ~126 ~1 grass_block
setblock ~197 ~126 ~2 grass_block
setblock ~197 ~126 ~3 grass_block
setblock ~197 ~126 ~5 short_grass
setblock ~197 ~126 ~6 short_grass
setblock ~197 ~126 ~19 poppy
setblock ~197 ~126 ~20 short_grass
setblock ~197 ~126 ~21 short_grass
setblock ~197 ~126 ~22 poppy
setblock ~197 ~126 ~23 poppy
setblock ~197 ~126 ~24 grass_block
setblock ~197 ~126 ~25 grass_block
setblock ~197 ~126 ~26 dirt
setblock ~197 ~126 ~27 dirt
setblock ~197 ~126 ~28 dirt
setblock ~197 ~126 ~29 dirt
setblock ~197 ~126 ~30 dirt
setblock ~197 ~126 ~31 dirt
setblock ~197 ~126 ~32 dirt
setblock ~197 ~126 ~33 dirt
setblock ~197 ~126 ~34 dirt
setblock ~197 ~126 ~35 dirt
setblock ~197 ~126 ~36 dirt
setblock ~197 ~126 ~37 dirt
setblock ~197 ~126 ~38 dirt
setblock ~197 ~126 ~39 dirt
setblock ~197 ~126 ~40 grass_block
setblock ~197 ~126 ~41 dirt
setblock ~197 ~126 ~42 dirt
setblock ~197 ~126 ~43 dirt
setblock ~197 ~126 ~44 dirt
setblock ~197 ~126 ~45 dirt
setblock ~197 ~126 ~46 dirt
setblock ~197 ~126 ~47 dirt
setblock ~197 ~126 ~48 dirt
setblock ~197 ~126 ~49 dirt
setblock ~197 ~126 ~50 dirt
setblock ~197 ~126 ~51 dirt
setblock ~197 ~126 ~52 dirt
setblock ~197 ~126 ~53 dirt
setblock ~197 ~126 ~54 dirt
setblock ~197 ~126 ~55 grass_block
setblock ~197 ~126 ~56 fern
setblock ~197 ~126 ~57 short_grass
setblock ~197 ~126 ~98 short_grass
setblock ~197 ~126 ~101 poppy
setblock ~197 ~126 ~103 grass_block
setblock ~197 ~126 ~104 grass_block
setblock ~197 ~126 ~105 grass_block
setblock ~197 ~126 ~106 grass_block
setblock ~197 ~126 ~107 dirt
setblock ~197 ~126 ~108 dirt
setblock ~197 ~126 ~109 dirt
setblock ~197 ~126 ~110 dirt
setblock ~197 ~126 ~111 dirt
setblock ~197 ~126 ~112 dirt
setblock ~197 ~126 ~113 grass_block
setblock ~197 ~126 ~114 grass_block
setblock ~197 ~126 ~115 grass_block
setblock ~197 ~126 ~149 grass_block
setblock ~197 ~126 ~150 grass_block
setblock ~197 ~126 ~151 grass_block
setblock ~197 ~126 ~152 grass_block
setblock ~197 ~126 ~154 short_grass
setblock ~197 ~126 ~170 short_grass
setblock ~197 ~126 ~173 short_grass
setblock ~197 ~126 ~179 short_grass
setblock ~197 ~126 ~181 short_grass
setblock ~197 ~126 ~182 short_grass
setblock ~197 ~126 ~187 grass_block
setblock ~197 ~126 ~188 grass_block
setblock ~197 ~126 ~189 grass_block
setblock ~197 ~126 ~190 grass_block
setblock ~197 ~126 ~191 grass_block
setblock ~197 ~126 ~192 grass_block
setblock ~197 ~126 ~193 grass_block
setblock ~197 ~126 ~194 grass_block
setblock ~197 ~126 ~196 short_grass
setblock ~197 ~127 ~0 grass_block
setblock ~197 ~127 ~2 poppy
setblock ~197 ~127 ~25 short_grass
setblock ~197 ~127 ~26 grass_block
setblock ~197 ~127 ~27 grass_block
setblock ~197 ~127 ~28 dirt
setblock ~197 ~127 ~29 dirt
setblock ~197 ~127 ~30 dirt
setblock ~197 ~127 ~31 dirt
setblock ~197 ~127 ~32 dirt
setblock ~197 ~127 ~33 dirt
setblock ~197 ~127 ~34 dirt
setblock ~197 ~127 ~35 dirt
setblock ~197 ~127 ~36 grass_block
setblock ~197 ~127 ~37 grass_block
setblock ~197 ~127 ~38 grass_block
setblock ~197 ~127 ~39 grass_block
setblock ~197 ~127 ~40 short_grass
setblock ~197 ~127 ~41 grass_block
setblock ~197 ~127 ~42 grass_block
setblock ~197 ~127 ~43 grass_block
setblock ~197 ~127 ~44 grass_block
setblock ~197 ~127 ~45 dirt
setblock ~197 ~127 ~46 dirt
setblock ~197 ~127 ~47 dirt
setblock ~197 ~127 ~48 dirt
setblock ~197 ~127 ~49 dirt
setblock ~197 ~127 ~50 dirt
setblock ~197 ~127 ~51 dirt
setblock ~197 ~127 ~52 dirt
setblock ~197 ~127 ~53 grass_block
setblock ~197 ~127 ~54 grass_block
setblock ~197 ~127 ~107 grass_block
setblock ~197 ~127 ~108 grass_block
setblock ~197 ~127 ~109 grass_block
setblock ~197 ~127 ~110 dirt
setblock ~197 ~127 ~111 grass_block
setblock ~197 ~127 ~112 grass_block
setblock ~197 ~127 ~113 short_grass
setblock ~197 ~127 ~115 poppy
setblock ~197 ~127 ~152 short_grass
setblock ~197 ~127 ~191 fern
setblock ~197 ~127 ~192 fern
setblock ~197 ~127 ~194 short_grass
setblock ~197 ~128 ~28 grass_block
setblock ~197 ~128 ~29 grass_block
setblock ~197 ~128 ~30 dirt
setblock ~197 ~128 ~31 dirt
setblock ~197 ~128 ~32 grass_block
setblock ~197 ~128 ~33 grass_block
setblock ~197 ~128 ~34 grass_block
setblock ~197 ~128 ~35 grass_block
setblock ~197 ~128 ~37 short_grass
setblock ~197 ~128 ~42 poppy
setblock ~197 ~128 ~45 grass_block
setblock ~197 ~128 ~46 grass_block
setblock ~197 ~128 ~47 grass_block
setblock ~197 ~128 ~48 grass_block
setblock ~197 ~128 ~49 dirt
setblock ~197 ~128 ~50 dirt
setblock ~197 ~128 ~51 grass_block
setblock ~197 ~128 ~52 grass_block
setblock ~197 ~128 ~54 short_grass
setblock ~197 ~128 ~110 grass_block
setblock ~197 ~128 ~111 short_grass
setblock ~197 ~128 ~112 short_grass
setblock ~197 ~129 ~29 short_grass
setblock ~197 ~129 ~30 grass_block
setblock ~197 ~129 ~31 grass_block
setblock ~197 ~129 ~34 short_grass
setblock ~197 ~129 ~35 poppy
setblock ~197 ~129 ~46 short_grass
setblock ~197 ~129 ~48 short_grass
setblock ~197 ~129 ~49 grass_block
setblock ~197 ~129 ~50 grass_block
setblock ~197 ~129 ~52 short_grass
setblock ~197 ~130 ~49 short_grass
setblock ~198 ~122 ~0 dirt
setblock ~198 ~122 ~1 dirt
setblock ~198 ~122 ~2 dirt
setblock ~198 ~122 ~3 dirt
setblock ~198 ~122 ~4 dirt
setblock ~198 ~122 ~5 dirt
setblock ~198 ~122 ~6 dirt
setblock ~198 ~122 ~7 dirt
setblock ~198 ~122 ~8 dirt
setblock ~198 ~122 ~9 dirt
setblock ~198 ~122 ~10 dirt
setblock ~198 ~122 ~11 dirt
setblock ~198 ~122 ~12 dirt
setblock ~198 ~122 ~13 dirt
setblock ~198 ~122 ~14 dirt
setblock ~198 ~122 ~15 dirt
setblock ~198 ~122 ~16 dirt
setblock ~198 ~122 ~17 dirt
setblock ~198 ~122 ~18 dirt
setblock ~198 ~122 ~19 dirt
setblock ~198 ~122 ~20 dirt
setblock ~198 ~122 ~21 dirt
setblock ~198 ~122 ~22 dirt
setblock ~198 ~122 ~23 dirt
setblock ~198 ~122 ~24 dirt
