setblock ~99 ~123 ~118 grass_block
setblock ~99 ~123 ~119 grass_block
setblock ~99 ~123 ~121 short_grass
setblock ~99 ~123 ~124 short_grass
setblock ~99 ~123 ~125 fern
setblock ~99 ~123 ~127 short_grass
setblock ~99 ~123 ~130 short_grass
setblock ~99 ~123 ~132 grass_block
setblock ~99 ~123 ~133 dirt
setblock ~99 ~123 ~134 dirt
setblock ~99 ~123 ~135 dirt
setblock ~99 ~123 ~136 dirt
setblock ~99 ~123 ~137 dirt
setblock ~99 ~123 ~138 dirt
setblock ~99 ~123 ~139 dirt
setblock ~99 ~123 ~140 dirt
setblock ~99 ~123 ~141 dirt
setblock ~99 ~123 ~142 dirt
setblock ~99 ~123 ~143 dirt
setblock ~99 ~123 ~144 dirt
setblock ~99 ~123 ~145 dirt
setblock ~99 ~123 ~146 dirt
setblock ~99 ~123 ~147 dirt
setblock ~99 ~123 ~148 dirt
setblock ~99 ~123 ~149 dirt
setblock ~99 ~123 ~150 dirt
setblock ~99 ~123 ~151 dirt
setblock ~99 ~123 ~152 dirt
setblock ~99 ~123 ~153 dirt
setblock ~99 ~123 ~154 dirt
setblock ~99 ~123 ~155 dirt
setblock ~99 ~123 ~156 dirt
setblock ~99 ~123 ~157 dirt
setblock ~99 ~123 ~158 dirt
setblock ~99 ~123 ~159 dirt
setblock ~99 ~123 ~160 dirt
setblock ~99 ~123 ~161 dirt
setblock ~99 ~123 ~162 dirt
setblock ~99 ~123 ~163 dirt
setblock ~99 ~123 ~164 grass_block
setblock ~99 ~123 ~165 grass_block
setblock ~99 ~123 ~166 grass_block
setblock ~99 ~123 ~167 grass_block
setblock ~99 ~123 ~170 short_grass
setblock ~99 ~123 ~172 grass_block
setblock ~99 ~123 ~173 grass_block
setblock ~99 ~123 ~174 grass_block
setblock ~99 ~123 ~175 dirt
setblock ~99 ~123 ~176 dirt
setblock ~99 ~123 ~177 dirt
setblock ~99 ~123 ~178 dirt
setblock ~99 ~123 ~179 dirt
setblock ~99 ~123 ~180 dirt
setblock ~99 ~123 ~181 dirt
setblock ~99 ~123 ~182 dirt
setblock ~99 ~123 ~183 dirt
setblock ~99 ~123 ~184 dirt
setblock ~99 ~123 ~185 dirt
setblock ~99 ~123 ~186 dirt
setblock ~99 ~123 ~187 dirt
setblock ~99 ~123 ~188 dirt
setblock ~99 ~123 ~189 dirt
setblock ~99 ~123 ~190 dirt
setblock ~99 ~123 ~191 dirt
setblock ~99 ~123 ~192 dirt
setblock ~99 ~123 ~193 dirt
setblock ~99 ~123 ~194 dirt
setblock ~99 ~123 ~195 dirt
setblock ~99 ~123 ~196 dirt
setblock ~99 ~123 ~197 dirt
setblock ~99 ~123 ~198 dirt
setblock ~99 ~123 ~199 dirt
setblock ~99 ~124 ~0 dirt
setblock ~99 ~124 ~1 dirt
setblock ~99 ~124 ~2 dirt
setblock ~99 ~124 ~3 dirt
setblock ~99 ~124 ~4 dirt
setblock ~99 ~124 ~5 dirt
setblock ~99 ~124 ~6 dirt
setblock ~99 ~124 ~7 dirt
setblock ~99 ~124 ~8 dirt
setblock ~99 ~124 ~9 dirt
setblock ~99 ~124 ~10 dirt
setblock ~99 ~124 ~11 dirt
setblock ~99 ~124 ~12 dirt
setblock ~99 ~124 ~13 dirt
setblock ~99 ~124 ~14 dirt
setblock ~99 ~124 ~15 dirt
setblock ~99 ~124 ~16 dirt
setblock ~99 ~124 ~17 grass_block
setblock ~99 ~124 ~18 grass_block
setblock ~99 ~124 ~19 grass_block
setblock ~99 ~124 ~20 grass_block
setblock ~99 ~124 ~21 grass_block
setblock ~99 ~124 ~22 dirt
setblock ~99 ~124 ~23 dirt
setblock ~99 ~124 ~24 dirt
setblock ~99 ~124 ~25 dirt
setblock ~99 ~124 ~26 dirt
setblock ~99 ~124 ~27 dirt
setblock ~99 ~124 ~28 dirt
setblock ~99 ~124 ~29 dirt
setblock ~99 ~124 ~30 dirt
setblock ~99 ~124 ~31 dirt
setblock ~99 ~124 ~32 dirt
setblock ~99 ~124 ~33 dirt
setblock ~99 ~124 ~34 dirt
setblock ~99 ~124 ~35 grass_block
setblock ~99 ~124 ~36 grass_block
setblock ~99 ~124 ~37 grass_block
setblock ~99 ~124 ~39 poppy
setblock ~99 ~124 ~40 short_grass
setblock ~99 ~124 ~41 short_grass
setblock ~99 ~124 ~43 grass_block
setblock ~99 ~124 ~44 grass_block
setblock ~99 ~124 ~45 grass_block
setblock ~99 ~124 ~46 grass_block
setblock ~99 ~124 ~47 dirt
setblock ~99 ~124 ~48 dirt
setblock ~99 ~124 ~49 dirt
setblock ~99 ~124 ~50 dirt
setblock ~99 ~124 ~51 dirt
setblock ~99 ~124 ~52 dirt
setblock ~99 ~124 ~53 dirt
setblock ~99 ~124 ~54 dirt
setblock ~99 ~124 ~55 dirt
setblock ~99 ~124 ~56 dirt
setblock ~99 ~124 ~57 dirt
setblock ~99 ~124 ~58 dirt
setblock ~99 ~124 ~59 dirt
setblock ~99 ~124 ~60 dirt
setblock ~99 ~124 ~61 dirt
setblock ~99 ~124 ~62 dirt
setblock ~99 ~124 ~63 grass_block
setblock ~99 ~124 ~64 grass_block
setblock ~99 ~124 ~65 grass_block
setblock ~99 ~124 ~66 grass_block
setblock ~99 ~124 ~67 grass_block
setblock ~99 ~124 ~68 poppy
setblock ~99 ~124 ~69 short_grass
setblock ~99 ~124 ~71 fern
setblock ~99 ~124 ~72 poppy
setblock ~99 ~124 ~77 short_grass
setblock ~99 ~124 ~78 short_grass
setblock ~99 ~124 ~80 short_grass
setblock ~99 ~124 ~81 short_grass
setblock ~99 ~124 ~82 short_grass
setblock ~99 ~124 ~84 grass_block
setblock ~99 ~124 ~85 grass_block
setblock ~99 ~124 ~86 grass_block
setblock ~99 ~124 ~87 grass_block
setblock ~99 ~124 ~88 grass_block
setblock ~99 ~124 ~89 grass_block
setblock ~99 ~124 ~90 grass_block
setblock ~99 ~124 ~91 grass_block
setblock ~99 ~124 ~92 grass_block
setblock ~99 ~124 ~93 grass_block
setblock ~99 ~124 ~94 grass_block
setblock ~99 ~124 ~95 grass_block
setblock ~99 ~124 ~96 grass_block
setblock ~99 ~124 ~97 grass_block
setblock ~99 ~124 ~98 grass_block
setblock ~99 ~124 ~99 grass_block
setblock ~99 ~124 ~100 short_grass
setblock ~99 ~124 ~101 grass_block
setblock ~99 ~124 ~102 grass_block
setblock ~99 ~124 ~103 grass_block
setblock ~99 ~124 ~104 grass_block
setblock ~99 ~124 ~105 grass_block
setblock ~99 ~124 ~106 dirt
setblock ~99 ~124 ~107 dirt
setblock ~99 ~124 ~108 dirt
setblock ~99 ~124 ~109 dirt
setblock ~99 ~124 ~110 dirt
setblock ~99 ~124 ~111 dirt
setblock ~99 ~124 ~112 dirt
setblock ~99 ~124 ~113 grass_block
setblock ~99 ~124 ~114 grass_block
setblock ~99 ~124 ~115 grass_block
setblock ~99 ~124 ~116 grass_block
setblock ~99 ~124 ~119 short_grass
setblock ~99 ~124 ~133 grass_block
setblock ~99 ~124 ~134 grass_block
setblock ~99 ~124 ~135 dirt
setblock ~99 ~124 ~136 dirt
setblock ~99 ~124 ~137 dirt
setblock ~99 ~124 ~138 dirt
setblock ~99 ~124 ~139 dirt
setblock ~99 ~124 ~140 dirt
setblock ~99 ~124 ~141 dirt
setblock ~99 ~124 ~142 dirt
setblock ~99 ~124 ~143 dirt
setblock ~99 ~124 ~144 dirt
setblock ~99 ~124 ~145 dirt
setblock ~99 ~124 ~146 dirt
setblock ~99 ~124 ~147 dirt
setblock ~99 ~124 ~148 dirt
setblock ~99 ~124 ~149 dirt
setblock ~99 ~124 ~150 dirt
setblock ~99 ~124 ~151 dirt
setblock ~99 ~124 ~152 dirt
setblock ~99 ~124 ~153 dirt
setblock ~99 ~124 ~154 dirt
setblock ~99 ~124 ~155 dirt
setblock ~99 ~124 ~156 dirt
setblock ~99 ~124 ~157 dirt
setblock ~99 ~124 ~158 dirt
setblock ~99 ~124 ~159 dirt
setblock ~99 ~124 ~160 grass_block
setblock ~99 ~124 ~161 grass_block
setblock ~99 ~124 ~162 grass_block
setblock ~99 ~124 ~163 grass_block
setblock ~99 ~124 ~165 poppy
setblock ~99 ~124 ~172 short_grass
setblock ~99 ~124 ~173 fern
setblock ~99 ~124 ~175 grass_block
setblock ~99 ~124 ~176 grass_block
setblock ~99 ~124 ~177 grass_block
setblock ~99 ~124 ~178 dirt
setblock ~99 ~124 ~179 dirt
setblock ~99 ~124 ~180 dirt
setblock ~99 ~124 ~181 dirt
setblock ~99 ~124 ~182 dirt
setblock ~99 ~124 ~183 dirt
setblock ~99 ~124 ~184 dirt
setblock ~99 ~124 ~185 dirt
setblock ~99 ~124 ~186 grass_block
setblock ~99 ~124 ~187 grass_block
setblock ~99 ~124 ~188 grass_block
setblock ~99 ~124 ~189 grass_block
setblock ~99 ~124 ~190 grass_block
setblock ~99 ~124 ~191 grass_block
setblock ~99 ~124 ~192 grass_block
setblock ~99 ~124 ~193 grass_block
setblock ~99 ~124 ~194 grass_block
setblock ~99 ~124 ~195 grass_block
setblock ~99 ~124 ~196 grass_block
setblock ~99 ~124 ~197 grass_block
setblock ~99 ~124 ~198 grass_block
setblock ~99 ~124 ~199 grass_block
setblock ~99 ~125 ~0 grass_block
setblock ~99 ~125 ~1 grass_block
setblock ~99 ~125 ~2 grass_block
setblock ~99 ~125 ~3 grass_block
setblock ~99 ~125 ~4 grass_block
setblock ~99 ~125 ~5 grass_block
setblock ~99 ~125 ~6 grass_block
setblock ~99 ~125 ~7 grass_block
setblock ~99 ~125 ~8 grass_block
setblock ~99 ~125 ~9 grass_block
setblock ~99 ~125 ~10 grass_block
setblock ~99 ~125 ~11 grass_block
setblock ~99 ~125 ~12 grass_block
setblock ~99 ~125 ~13 grass_block
setblock ~99 ~125 ~14 grass_block
setblock ~99 ~125 ~15 grass_block
setblock ~99 ~125 ~16 grass_block
setblock ~99 ~125 ~22 grass_block
setblock ~99 ~125 ~23 grass_block
setblock ~99 ~125 ~24 grass_block
setblock ~99 ~125 ~25 grass_block
setblock ~99 ~125 ~26 grass_block
setblock ~99 ~125 ~27 dirt
setblock ~99 ~125 ~28 dirt
setblock ~99 ~125 ~29 dirt
setblock ~99 ~125 ~30 dirt
setblock ~99 ~125 ~31 dirt
setblock ~99 ~125 ~32 grass_block
setblock ~99 ~125 ~33 grass_block
setblock ~99 ~125 ~34 grass_block
setblock ~99 ~125 ~37 short_grass
setblock ~99 ~125 ~46 short_grass
setblock ~99 ~125 ~47 grass_block
setblock ~99 ~125 ~48 grass_block
setblock ~99 ~125 ~49 dirt
setblock ~99 ~125 ~50 dirt
setblock ~99 ~125 ~51 dirt
setblock ~99 ~125 ~52 dirt
setblock ~99 ~125 ~53 dirt
setblock ~99 ~125 ~54 dirt
setblock ~99 ~125 ~55 grass_block
setblock ~99 ~125 ~56 grass_block
setblock ~99 ~125 ~57 grass_block
setblock ~99 ~125 ~58 grass_block
setblock ~99 ~125 ~59 grass_block
setblock ~99 ~125 ~60 grass_block
setblock ~99 ~125 ~61 grass_block
setblock ~99 ~125 ~62 grass_block
setblock ~99 ~125 ~64 short_grass
setblock ~99 ~125 ~65 fern
setblock ~99 ~125 ~66 short_grass
setblock ~99 ~125 ~88 short_grass
setblock ~99 ~125 ~90 short_grass
setblock ~99 ~125 ~91 short_grass
setblock ~99 ~125 ~95 short_grass
setblock ~99 ~125 ~96 short_grass
setblock ~99 ~125 ~102 short_grass
setblock ~99 ~125 ~106 grass_block
setblock ~99 ~125 ~107 grass_block
setblock ~99 ~125 ~108 grass_block
setblock ~99 ~125 ~109 grass_block
setblock ~99 ~125 ~110 grass_block
setblock ~99 ~125 ~111 grass_block
setblock ~99 ~125 ~112 grass_block
setblock ~99 ~125 ~116 short_grass
setblock ~99 ~125 ~134 short_grass
setblock ~99 ~125 ~135 grass_block
setblock ~99 ~125 ~136 dirt
setblock ~99 ~125 ~137 dirt
setblock ~99 ~125 ~138 dirt
setblock ~99 ~125 ~139 dirt
setblock ~99 ~125 ~140 dirt
setblock ~99 ~125 ~141 dirt
setblock ~99 ~125 ~142 dirt
setblock ~99 ~125 ~143 dirt
setblock ~99 ~125 ~144 dirt
setblock ~99 ~125 ~145 dirt
setblock ~99 ~125 ~146 dirt
setblock ~99 ~125 ~147 dirt
setblock ~99 ~125 ~148 dirt
setblock ~99 ~125 ~149 dirt
setblock ~99 ~125 ~150 dirt
setblock ~99 ~125 ~151 dirt
setblock ~99 ~125 ~152 dirt
setblock ~99 ~125 ~153 dirt
setblock ~99 ~125 ~154 dirt
setblock ~99 ~125 ~155 dirt
setblock ~99 ~125 ~156 dirt
setblock ~99 ~125 ~157 grass_block
setblock ~99 ~125 ~158 grass_block
setblock ~99 ~125 ~159 grass_block
setblock ~99 ~125 ~161 short_grass
setblock ~99 ~125 ~176 short_grass
setblock ~99 ~125 ~177 poppy
setblock ~99 ~125 ~178 grass_block
setblock ~99 ~125 ~179 grass_block
setblock ~99 ~125 ~180 grass_block
setblock ~99 ~125 ~181 grass_block
setblock ~99 ~125 ~182 grass_block
setblock ~99 ~125 ~183 grass_block
setblock ~99 ~125 ~184 grass_block
setblock ~99 ~125 ~185 grass_block
setblock ~99 ~125 ~194 short_grass
setblock ~99 ~125 ~198 short_grass
setblock ~99 ~126 ~4 short_grass
setblock ~99 ~126 ~8 short_grass
setblock ~99 ~126 ~11 poppy
setblock ~99 ~126 ~12 short_grass
setblock ~99 ~126 ~22 short_grass
setblock ~99 ~126 ~23 short_grass
setblock ~99 ~126 ~27 grass_block
setblock ~99 ~126 ~28 grass_block
setblock ~99 ~126 ~29 grass_block
setblock ~99 ~126 ~30 grass_block
setblock ~99 ~126 ~31 grass_block
setblock ~99 ~126 ~33 short_grass
setblock ~99 ~126 ~34 poppy
setblock ~99 ~126 ~49 grass_block
setblock ~99 ~126 ~50 dirt
setblock ~99 ~126 ~51 grass_block
setblock ~99 ~126 ~52 grass_block
setblock ~99 ~126 ~53 grass_block
setblock ~99 ~126 ~54 grass_block
setblock ~99 ~126 ~56 short_grass
setblock ~99 ~126 ~106 fern
setblock ~99 ~126 ~108 short_grass
setblock ~99 ~126 ~110 fern
setblock ~99 ~126 ~111 fern
setblock ~99 ~126 ~112 short_grass
setblock ~99 ~126 ~135 short_grass
setblock ~99 ~126 ~136 grass_block
setblock ~99 ~126 ~137 dirt
setblock ~99 ~126 ~138 dirt
setblock ~99 ~126 ~139 dirt
setblock ~99 ~126 ~140 dirt
setblock ~99 ~126 ~141 dirt
setblock ~99 ~126 ~142 dirt
setblock ~99 ~126 ~143 dirt
setblock ~99 ~126 ~144 dirt
setblock ~99 ~126 ~145 dirt
setblock ~99 ~126 ~146 dirt
setblock ~99 ~126 ~147 dirt
setblock ~99 ~126 ~148 dirt
setblock ~99 ~126 ~149 dirt
setblock ~99 ~126 ~150 dirt
setblock ~99 ~126 ~151 dirt
setblock ~99 ~126 ~152 dirt
setblock ~99 ~126 ~153 dirt
setblock ~99 ~126 ~154 dirt
setblock ~99 ~126 ~155 grass_block
setblock ~99 ~126 ~156 grass_block
setblock ~99 ~126 ~157 short_grass
setblock ~99 ~126 ~159 short_grass
setblock ~99 ~126 ~178 short_grass
setblock ~99 ~126 ~180 short_grass
setblock ~99 ~126 ~184 short_grass
setblock ~99 ~126 ~185 short_grass
setblock ~99 ~127 ~50 grass_block
setblock ~99 ~127 ~53 short_grass
setblock ~99 ~127 ~137 grass_block
setblock ~99 ~127 ~138 grass_block
setblock ~99 ~127 ~139 dirt
setblock ~99 ~127 ~140 dirt
setblock ~99 ~127 ~141 dirt
setblock ~99 ~127 ~142 dirt
setblock ~99 ~127 ~143 dirt
setblock ~99 ~127 ~144 dirt
setblock ~99 ~127 ~145 dirt
setblock ~99 ~127 ~146 dirt
setblock ~99 ~127 ~147 dirt
setblock ~99 ~127 ~148 dirt
setblock ~99 ~127 ~149 dirt
setblock ~99 ~127 ~150 dirt
setblock ~99 ~127 ~151 dirt
setblock ~99 ~127 ~152 dirt
setblock ~99 ~127 ~153 grass_block
setblock ~99 ~127 ~154 grass_block
setblock ~99 ~127 ~156 short_grass
setblock ~99 ~128 ~139 grass_block
setblock ~99 ~128 ~140 dirt
setblock ~99 ~128 ~141 dirt
setblock ~99 ~128 ~142 dirt
setblock ~99 ~128 ~143 dirt
setblock ~99 ~128 ~144 dirt
setblock ~99 ~128 ~145 dirt
setblock ~99 ~128 ~146 dirt
setblock ~99 ~128 ~147 dirt
setblock ~99 ~128 ~148 dirt
setblock ~99 ~128 ~149 dirt
setblock ~99 ~128 ~150 dirt
setblock ~99 ~128 ~151 dirt
setblock ~99 ~128 ~152 grass_block
setblock ~99 ~128 ~153 short_grass
setblock ~99 ~128 ~154 short_grass
setblock ~99 ~129 ~140 grass_block
setblock ~99 ~129 ~141 grass_block
setblock ~99 ~129 ~142 grass_block
setblock ~99 ~129 ~143 grass_block
setblock ~99 ~129 ~144 grass_block
setblock ~99 ~129 ~145 grass_block
setblock ~99 ~129 ~146 grass_block
setblock ~99 ~129 ~147 grass_block
setblock ~99 ~129 ~148 grass_block
setblock ~99 ~129 ~149 dirt
setblock ~99 ~129 ~150 dirt
setblock ~99 ~129 ~151 grass_block
setblock ~99 ~130 ~149 grass_block
setblock ~99 ~130 ~150 grass_block
setblock ~99 ~131 ~149 short_grass
setblock ~99 ~131 ~150 poppy
setblock ~100 ~122 ~0 dirt
setblock ~100 ~122 ~1 dirt
setblock ~100 ~122 ~2 dirt
setblock ~100 ~122 ~3 dirt
setblock ~100 ~122 ~4 dirt
setblock ~100 ~122 ~5 dirt
setblock ~100 ~122 ~6 dirt
setblock ~100 ~122 ~7 dirt
setblock ~100 ~122 ~8 dirt
setblock ~100 ~122 ~9 dirt
setblock ~100 ~122 ~10 dirt
setblock ~100 ~122 ~11 dirt
setblock ~100 ~122 ~12 dirt
setblock ~100 ~122 ~13 dirt
setblock ~100 ~122 ~14 dirt
setblock ~100 ~122 ~15 dirt
setblock ~100 ~122 ~16 dirt
setblock ~100 ~122 ~17 dirt
setblock ~100 ~122 ~18 dirt
setblock ~100 ~122 ~19 dirt
setblock ~100 ~122 ~20 dirt
setblock ~100 ~122 ~21 dirt
setblock ~100 ~122 ~22 dirt
setblock ~100 ~122 ~23 dirt
setblock ~100 ~122 ~24 dirt
setblock ~100 ~122 ~25 dirt
setblock ~100 ~122 ~26 dirt
setblock ~100 ~122 ~27 dirt
setblock ~100 ~122 ~28 dirt
setblock ~100 ~122 ~29 dirt
setblock ~100 ~122 ~30 dirt
setblock ~100 ~122 ~31 dirt
setblock ~100 ~122 ~32 dirt
setblock ~100 ~122 ~33 dirt
setblock ~100 ~122 ~34 dirt
setblock ~100 ~122 ~35 dirt
setblock ~100 ~122 ~36 dirt
setblock ~100 ~122 ~37 dirt
setblock ~100 ~122 ~38 dirt
setblock ~100 ~122 ~39 dirt
setblock ~100 ~122 ~40 dirt
setblock ~100 ~122 ~41 dirt
setblock ~100 ~122 ~42 dirt
setblock ~100 ~122 ~43 dirt
setblock ~100 ~122 ~44 dirt
setblock ~100 ~122 ~45 dirt
setblock ~100 ~122 ~46 dirt
setblock ~100 ~122 ~47 dirt
setblock ~100 ~122 ~48 dirt
setblock ~100 ~122 ~49 dirt
setblock ~100 ~122 ~50 dirt
setblock ~100 ~122 ~51 dirt
setblock ~100 ~122 ~52 dirt
setblock ~100 ~122 ~53 dirt
setblock ~100 ~122 ~54 dirt
setblock ~100 ~122 ~55 dirt
setblock ~100 ~122 ~56 dirt
setblock ~100 ~122 ~57 dirt
setblock ~100 ~122 ~58 dirt
setblock ~100 ~122 ~59 dirt
setblock ~100 ~122 ~60 dirt
setblock ~100 ~122 ~61 dirt
setblock ~100 ~122 ~62 dirt
setblock ~100 ~122 ~63 dirt
setblock ~100 ~122 ~64 dirt
setblock ~100 ~122 ~65 dirt
setblock ~100 ~122 ~66 dirt
setblock ~100 ~122 ~67 dirt
setblock ~100 ~122 ~68 dirt
setblock ~100 ~122 ~69 dirt
setblock ~100 ~122 ~70 dirt
setblock ~100 ~122 ~71 dirt
setblock ~100 ~122 ~72 dirt
setblock ~100 ~122 ~73 dirt
setblock ~100 ~122 ~74 dirt
setblock ~100 ~122 ~75 dirt
setblock ~100 ~122 ~76 dirt
setblock ~100 ~122 ~77 dirt
setblock ~100 ~122 ~78 dirt
setblock ~100 ~122 ~79 dirt
setblock ~100 ~122 ~80 dirt
setblock ~100 ~122 ~81 dirt
setblock ~100 ~122 ~82 dirt
setblock ~100 ~122 ~83 dirt
setblock ~100 ~122 ~84 dirt
setblock ~100 ~122 ~85 dirt
setblock ~100 ~122 ~86 dirt
setblock ~100 ~122 ~87 dirt
setblock ~100 ~122 ~88 dirt
setblock ~100 ~122 ~89 dirt
setblock ~100 ~122 ~90 dirt
setblock ~100 ~122 ~91 dirt
setblock ~100 ~122 ~92 dirt
setblock ~100 ~122 ~93 dirt
setblock ~100 ~122 ~94 dirt
setblock ~100 ~122 ~95 dirt
setblock ~100 ~122 ~96 dirt
setblock ~100 ~122 ~97 dirt
setblock ~100 ~122 ~98 dirt
setblock ~100 ~122 ~99 dirt
setblock ~100 ~122 ~100 dirt
setblock ~100 ~122 ~101 dirt
setblock ~100 ~122 ~102 dirt
setblock ~100 ~122 ~103 dirt
setblock ~100 ~122 ~104 dirt
setblock ~100 ~122 ~105 dirt
setblock ~100 ~122 ~106 dirt
setblock ~100 ~122 ~107 dirt
setblock ~100 ~122 ~108 dirt
setblock ~100 ~122 ~109 dirt
setblock ~100 ~122 ~110 dirt
setblock ~100 ~122 ~111 dirt
setblock ~100 ~122 ~112 dirt
setblock ~100 ~122 ~113 dirt
setblock ~100 ~122 ~114 dirt
setblock ~100 ~122 ~115 dirt
setblock ~100 ~122 ~116 dirt
setblock ~100 ~122 ~117 dirt
setblock ~100 ~122 ~118 dirt
setblock ~100 ~122 ~119 grass_block
setblock ~100 ~122 ~120 grass_block
setblock ~100 ~122 ~121 grass_block
setblock ~100 ~122 ~122 grass_block
setblock ~100 ~122 ~123 grass_block
setblock ~100 ~122 ~124 grass_block
setblock ~100 ~122 ~125 grass_block
setblock ~100 ~122 ~126 grass_block
setblock ~100 ~122 ~127 grass_block
setblock ~100 ~122 ~128 grass_block
setblock ~100 ~122 ~129 grass_block
setblock ~100 ~122 ~130 grass_block
setblock ~100 ~122 ~131 grass_block
setblock ~100 ~122 ~132 dirt
setblock ~100 ~122 ~133 dirt
setblock ~100 ~122 ~134 dirt
setblock ~100 ~122 ~135 dirt
setblock ~100 ~122 ~136 dirt
setblock ~100 ~122 ~137 dirt
setblock ~100 ~122 ~138 dirt
setblock ~100 ~122 ~139 dirt
setblock ~100 ~122 ~140 dirt
setblock ~100 ~122 ~141 dirt
setblock ~100 ~122 ~142 dirt
setblock ~100 ~122 ~143 dirt
setblock ~100 ~122 ~144 dirt
setblock ~100 ~122 ~145 dirt
setblock ~100 ~122 ~146 dirt
setblock ~100 ~122 ~147 dirt
setblock ~100 ~122 ~148 dirt
setblock ~100 ~122 ~149 dirt
setblock ~100 ~122 ~150 dirt
setblock ~100 ~122 ~151 dirt
setblock ~100 ~122 ~152 dirt
setblock ~100 ~122 ~153 dirt
setblock ~100 ~122 ~154 dirt
setblock ~100 ~122 ~155 dirt
setblock ~100 ~122 ~156 dirt
setblock ~100 ~122 ~157 dirt
setblock ~100 ~122 ~158 dirt
setblock ~100 ~122 ~159 dirt
setblock ~100 ~122 ~160 dirt
setblock ~100 ~122 ~161 dirt
setblock ~100 ~122 ~162 dirt
setblock ~100 ~122 ~163 dirt
setblock ~100 ~122 ~164 dirt
setblock ~100 ~122 ~165 dirt
setblock ~100 ~122 ~166 dirt
setblock ~100 ~122 ~167 grass_block
setblock ~100 ~122 ~168 grass_block
setblock ~100 ~122 ~169 grass_block
setblock ~100 ~122 ~170 grass_block
setblock ~100 ~122 ~171 grass_block
setblock ~100 ~122 ~172 dirt
setblock ~100 ~122 ~173 dirt
setblock ~100 ~122 ~174 dirt
setblock ~100 ~122 ~175 dirt
setblock ~100 ~122 ~176 dirt
setblock ~100 ~122 ~177 dirt
setblock ~100 ~122 ~178 dirt
setblock ~100 ~122 ~179 dirt
setblock ~100 ~122 ~180 dirt
setblock ~100 ~122 ~181 dirt
setblock ~100 ~122 ~182 dirt
setblock ~100 ~122 ~183 dirt
setblock ~100 ~122 ~184 dirt
setblock ~100 ~122 ~185 dirt
setblock ~100 ~122 ~186 dirt
setblock ~100 ~122 ~187 dirt
setblock ~100 ~122 ~188 dirt
setblock ~100 ~122 ~189 dirt
setblock ~100 ~122 ~190 dirt
setblock ~100 ~122 ~191 dirt
setblock ~100 ~122 ~192 dirt
setblock ~100 ~122 ~193 dirt
setblock ~100 ~122 ~194 dirt
setblock ~100 ~122 ~195 dirt
setblock ~100 ~122 ~196 dirt
setblock ~100 ~122 ~197 dirt
setblock ~100 ~122 ~198 dirt
setblock ~100 ~122 ~199 dirt
setblock ~100 ~123 ~0 dirt
setblock ~100 ~123 ~1 dirt
setblock ~100 ~123 ~2 dirt
setblock ~100 ~123 ~3 dirt
setblock ~100 ~123 ~4 dirt
setblock ~100 ~123 ~5 dirt
setblock ~100 ~123 ~6 dirt
setblock ~100 ~123 ~7 dirt
setblock ~100 ~123 ~8 dirt
setblock ~100 ~123 ~9 dirt
setblock ~100 ~123 ~10 dirt
setblock ~100 ~123 ~11 dirt
setblock ~100 ~123 ~12 dirt
setblock ~100 ~123 ~13 dirt
setblock ~100 ~123 ~14 dirt
setblock ~100 ~123 ~15 dirt
setblock ~100 ~123 ~16 dirt
setblock ~100 ~123 ~17 dirt
setblock ~100 ~123 ~18 dirt
setblock ~100 ~123 ~19 dirt
setblock ~100 ~123 ~20 dirt
setblock ~100 ~123 ~21 dirt
setblock ~100 ~123 ~22 dirt
setblock ~100 ~123 ~23 dirt
setblock ~100 ~123 ~24 dirt
setblock ~100 ~123 ~25 dirt
setblock ~100 ~123 ~26 dirt
setblock ~100 ~123 ~27 dirt
setblock ~100 ~123 ~28 dirt
setblock ~100 ~123 ~29 dirt
setblock ~100 ~123 ~30 dirt
setblock ~100 ~123 ~31 dirt
setblock ~100 ~123 ~32 dirt
setblock ~100 ~123 ~33 dirt
setblock ~100 ~123 ~34 dirt
setblock ~100 ~123 ~35 dirt
setblock ~100 ~123 ~36 dirt
setblock ~100 ~123 ~37 dirt
setblock ~100 ~123 ~38 grass_block
setblock ~100 ~123 ~39 grass_block
setblock ~100 ~123 ~40 grass_block
setblock ~100 ~123 ~41 grass_block
setblock ~100 ~123 ~42 grass_block
setblock ~100 ~123 ~43 dirt
setblock ~100 ~123 ~44 dirt
setblock ~100 ~123 ~45 dirt
setblock ~100 ~123 ~46 dirt
setblock ~100 ~123 ~47 dirt
setblock ~100 ~123 ~48 dirt
setblock ~100 ~123 ~49 dirt
setblock ~100 ~123 ~50 dirt
setblock ~100 ~123 ~51 dirt
setblock ~100 ~123 ~52 dirt
setblock ~100 ~123 ~53 dirt
setblock ~100 ~123 ~54 dirt
setblock ~100 ~123 ~55 dirt
setblock ~100 ~123 ~56 dirt
setblock ~100 ~123 ~57 dirt
setblock ~100 ~123 ~58 dirt
setblock ~100 ~123 ~59 dirt
setblock ~100 ~123 ~60 dirt
setblock ~100 ~123 ~61 dirt
setblock ~100 ~123 ~62 dirt
setblock ~100 ~123 ~63 dirt
setblock ~100 ~123 ~64 dirt
setblock ~100 ~123 ~65 dirt
setblock ~100 ~123 ~66 dirt
setblock ~100 ~123 ~67 dirt
setblock ~100 ~123 ~68 grass_block
setblock ~100 ~123 ~69 grass_block
setblock ~100 ~123 ~70 grass_block
setblock ~100 ~123 ~71 grass_block
setblock ~100 ~123 ~72 grass_block
setblock ~100 ~123 ~73 grass_block
setblock ~100 ~123 ~74 grass_block
setblock ~100 ~123 ~75 grass_block
setblock ~100 ~123 ~76 grass_block
setblock ~100 ~123 ~77 grass_block
setblock ~100 ~123 ~78 grass_block
setblock ~100 ~123 ~79 grass_block
setblock ~100 ~123 ~80 grass_block
setblock ~100 ~123 ~81 grass_block
setblock ~100 ~123 ~82 grass_block
setblock ~100 ~123 ~83 grass_block
setblock ~100 ~123 ~84 dirt
setblock ~100 ~123 ~85 dirt
setblock ~100 ~123 ~86 dirt
setblock ~100 ~123 ~87 dirt
setblock ~100 ~123 ~88 dirt
setblock ~100 ~123 ~89 dirt
setblock ~100 ~123 ~90 dirt
setblock ~100 ~123 ~91 dirt
setblock ~100 ~123 ~92 dirt
setblock ~100 ~123 ~93 dirt
setblock ~100 ~123 ~94 dirt
setblock ~100 ~123 ~95 dirt
setblock ~100 ~123 ~96 dirt
setblock ~100 ~123 ~97 dirt
setblock ~100 ~123 ~98 dirt
setblock ~100 ~123 ~99 grass_block
setblock ~100 ~123 ~100 grass_block
setblock ~100 ~123 ~101 grass_block
setblock ~100 ~123 ~102 dirt
setblock ~100 ~123 ~103 dirt
setblock ~100 ~123 ~104 dirt
setblock ~100 ~123 ~105 dirt
setblock ~100 ~123 ~106 dirt
setblock ~100 ~123 ~107 dirt
setblock ~100 ~123 ~108 dirt
setblock ~100 ~123 ~109 dirt
setblock ~100 ~123 ~110 dirt
setblock ~100 ~123 ~111 dirt
setblock ~100 ~123 ~112 dirt
setblock ~100 ~123 ~113 dirt
setblock ~100 ~123 ~114 dirt
setblock ~100 ~123 ~115 dirt
setblock ~100 ~123 ~116 grass_block
setblock ~100 ~123 ~117 grass_block
setblock ~100 ~123 ~118 grass_block
setblock ~100 ~123 ~119 short_grass
setblock ~100 ~123 ~125 short_grass
setblock ~100 ~123 ~129 short_grass
setblock ~100 ~123 ~131 short_grass
setblock ~100 ~123 ~132 grass_block
setblock ~100 ~123 ~133 grass_block
setblock ~100 ~123 ~134 dirt
setblock ~100 ~123 ~135 dirt
setblock ~100 ~123 ~136 dirt
setblock ~100 ~123 ~137 dirt
setblock ~100 ~123 ~138 dirt
setblock ~100 ~123 ~139 dirt
setblock ~100 ~123 ~140 dirt
setblock ~100 ~123 ~141 dirt
setblock ~100 ~123 ~142 dirt
setblock ~100 ~123 ~143 dirt
setblock ~100 ~123 ~144 dirt
setblock ~100 ~123 ~145 dirt
setblock ~100 ~123 ~146 dirt
setblock ~100 ~123 ~147 dirt
setblock ~100 ~123 ~148 dirt
setblock ~100 ~123 ~149 dirt
setblock ~100 ~123 ~150 dirt
setblock ~100 ~123 ~151 dirt
setblock ~100 ~123 ~152 dirt
setblock ~100 ~123 ~153 dirt
setblock ~100 ~123 ~154 dirt
setblock ~100 ~123 ~155 dirt
setblock ~100 ~123 ~156 dirt
setblock ~100 ~123 ~157 dirt
setblock ~100 ~123 ~158 dirt
setblock ~100 ~123 ~159 dirt
setblock ~100 ~123 ~160 dirt
setblock ~100 ~123 ~161 dirt
setblock ~100 ~123 ~162 dirt
setblock ~100 ~123 ~163 grass_block
setblock ~100 ~123 ~164 grass_block
setblock ~100 ~123 ~165 grass_block
setblock ~100 ~123 ~166 grass_block
setblock ~100 ~123 ~167 short_grass
setblock ~100 ~123 ~170 short_grass
setblock ~100 ~123 ~172 grass_block
setblock ~100 ~123 ~173 grass_block
setblock ~100 ~123 ~174 grass_block
setblock ~100 ~123 ~175 dirt
setblock ~100 ~123 ~176 dirt
setblock ~100 ~123 ~177 dirt
setblock ~100 ~123 ~178 dirt
setblock ~100 ~123 ~179 dirt
setblock ~100 ~123 ~180 dirt
setblock ~100 ~123 ~181 dirt
setblock ~100 ~123 ~182 dirt
setblock ~100 ~123 ~183 dirt
setblock ~100 ~123 ~184 dirt
setblock ~100 ~123 ~185 dirt
setblock ~100 ~123 ~186 dirt
setblock ~100 ~123 ~187 dirt
setblock ~100 ~123 ~188 dirt
setblock ~100 ~123 ~189 grass_block
setblock ~100 ~123 ~190 grass_block
setblock ~100 ~123 ~191 grass_block
setblock ~100 ~123 ~192 grass_block
setblock ~100 ~123 ~193 dirt
setblock ~100 ~123 ~194 dirt
setblock ~100 ~123 ~195 dirt
setblock ~100 ~123 ~196 dirt
setblock ~100 ~123 ~197 dirt
setblock ~100 ~123 ~198 dirt
setblock ~100 ~123 ~199 dirt
setblock ~100 ~124 ~0 dirt
setblock ~100 ~124 ~1 dirt
setblock ~100 ~124 ~2 dirt
setblock ~100 ~124 ~3 dirt
setblock ~100 ~124 ~4 dirt
setblock ~100 ~124 ~5 dirt
setblock ~100 ~124 ~6 dirt
setblock ~100 ~124 ~7 dirt
setblock ~100 ~124 ~8 dirt
setblock ~100 ~124 ~9 dirt
setblock ~100 ~124 ~10 grass_block
setblock ~100 ~124 ~11 grass_block
setblock ~100 ~124 ~12 grass_block
setblock ~100 ~124 ~13 grass_block
setblock ~100 ~124 ~14 grass_block
setblock ~100 ~124 ~15 grass_block
setblock ~100 ~124 ~16 grass_block
setblock ~100 ~124 ~17 grass_block
setblock ~100 ~124 ~18 grass_block
setblock ~100 ~124 ~19 grass_block
setblock ~100 ~124 ~20 grass_block
setblock ~100 ~124 ~21 grass_block
setblock ~100 ~124 ~22 grass_block
setblock ~100 ~124 ~23 dirt
setblock ~100 ~124 ~24 dirt
setblock ~100 ~124 ~25 dirt
setblock ~100 ~124 ~26 dirt
setblock ~100 ~124 ~27 dirt
setblock ~100 ~124 ~28 dirt
setblock ~100 ~124 ~29 dirt
setblock ~100 ~124 ~30 dirt
setblock ~100 ~124 ~31 dirt
setblock ~100 ~124 ~32 dirt
setblock ~100 ~124 ~33 dirt
setblock ~100 ~124 ~34 dirt
setblock ~100 ~124 ~35 grass_block
setblock ~100 ~124 ~36 grass_block
setblock ~100 ~124 ~37 grass_block
setblock ~100 ~124 ~41 short_grass
setblock ~100 ~124 ~43 grass_block
setblock ~100 ~124 ~44 grass_block
setblock ~100 ~124 ~45 grass_block
setblock ~100 ~124 ~46 grass_block
setblock ~100 ~124 ~47 dirt
setblock ~100 ~124 ~48 dirt
setblock ~100 ~124 ~49 dirt
setblock ~100 ~124 ~50 dirt
setblock ~100 ~124 ~51 dirt
setblock ~100 ~124 ~52 dirt
setblock ~100 ~124 ~53 dirt
setblock ~100 ~124 ~54 dirt
setblock ~100 ~124 ~55 dirt
setblock ~100 ~124 ~56 dirt
setblock ~100 ~124 ~57 dirt
setblock ~100 ~124 ~58 dirt
setblock ~100 ~124 ~59 dirt
setblock ~100 ~124 ~60 dirt
setblock ~100 ~124 ~61 dirt
setblock ~100 ~124 ~62 dirt
setblock ~100 ~124 ~63 grass_block
setblock ~100 ~124 ~64 grass_block
setblock ~100 ~124 ~65 grass_block
setblock ~100 ~124 ~66 grass_block
setblock ~100 ~124 ~67 grass_block
setblock ~100 ~124 ~72 short_grass
setblock ~100 ~124 ~73 short_grass
setblock ~100 ~124 ~74 short_grass
setblock ~100 ~124 ~77 short_grass
setblock ~100 ~124 ~81 short_grass
setblock ~100 ~124 ~82 short_grass
setblock ~100 ~124 ~84 grass_block
setblock ~100 ~124 ~85 grass_block
setblock ~100 ~124 ~86 grass_block
setblock ~100 ~124 ~87 grass_block
setblock ~100 ~124 ~88 grass_block
setblock ~100 ~124 ~89 grass_block
setblock ~100 ~124 ~90 grass_block
setblock ~100 ~124 ~91 grass_block
setblock ~100 ~124 ~92 grass_block
setblock ~100 ~124 ~93 grass_block
setblock ~100 ~124 ~94 grass_block
setblock ~100 ~124 ~95 grass_block
setblock ~100 ~124 ~96 grass_block
setblock ~100 ~124 ~97 grass_block
setblock ~100 ~124 ~98 grass_block
setblock ~100 ~124 ~102 grass_block
setblock ~100 ~124 ~103 grass_block
setblock ~100 ~124 ~104 grass_block
setblock ~100 ~124 ~105 grass_block
setblock ~100 ~124 ~106 grass_block
setblock ~100 ~124 ~107 dirt
setblock ~100 ~124 ~108 dirt
setblock ~100 ~124 ~109 dirt
setblock ~100 ~124 ~110 dirt
setblock ~100 ~124 ~111 dirt
setblock ~100 ~124 ~112 dirt
setblock ~100 ~124 ~113 grass_block
setblock ~100 ~124 ~114 grass_block
setblock ~100 ~124 ~115 grass_block
setblock ~100 ~124 ~118 short_grass
setblock ~100 ~124 ~133 short_grass
setblock ~100 ~124 ~134 grass_block
setblock ~100 ~124 ~135 dirt
setblock ~100 ~124 ~136 dirt
setblock ~100 ~124 ~137 dirt
setblock ~100 ~124 ~138 dirt
setblock ~100 ~124 ~139 dirt
setblock ~100 ~124 ~140 dirt
setblock ~100 ~124 ~141 dirt
setblock ~100 ~124 ~142 dirt
setblock ~100 ~124 ~143 dirt
setblock ~100 ~124 ~144 dirt
setblock ~100 ~124 ~145 dirt
setblock ~100 ~124 ~146 dirt
setblock ~100 ~124 ~147 dirt
setblock ~100 ~124 ~148 dirt
setblock ~100 ~124 ~149 dirt
setblock ~100 ~124 ~150 dirt
setblock ~100 ~124 ~151 dirt
setblock ~100 ~124 ~152 dirt
setblock ~100 ~124 ~153 dirt
setblock ~100 ~124 ~154 dirt
setblock ~100 ~124 ~155 dirt
setblock ~100 ~124 ~156 dirt
setblock ~100 ~124 ~157 dirt
setblock ~100 ~124 ~158 dirt
setblock ~100 ~124 ~159 grass_block
setblock ~100 ~124 ~160 grass_block
setblock ~100 ~124 ~161 grass_block
setblock ~100 ~124 ~162 grass_block
setblock ~100 ~124 ~174 short_grass
setblock ~100 ~124 ~175 grass_block
setblock ~100 ~124 ~176 grass_block
setblock ~100 ~124 ~177 grass_block
setblock ~100 ~124 ~178 dirt
setblock ~100 ~124 ~179 dirt
setblock ~100 ~124 ~180 dirt
setblock ~100 ~124 ~181 dirt
setblock ~100 ~124 ~182 dirt
setblock ~100 ~124 ~183 dirt
setblock ~100 ~124 ~184 dirt
setblock ~100 ~124 ~185 grass_block
setblock ~100 ~124 ~186 grass_block
setblock ~100 ~124 ~187 grass_block
setblock ~100 ~124 ~188 grass_block
setblock ~100 ~124 ~193 grass_block
setblock ~100 ~124 ~194 grass_block
setblock ~100 ~124 ~195 grass_block
setblock ~100 ~124 ~196 grass_block
setblock ~100 ~124 ~197 grass_block
setblock ~100 ~124 ~198 grass_block
setblock ~100 ~124 ~199 dirt
setblock ~100 ~125 ~0 grass_block
setblock ~100 ~125 ~1 grass_block
setblock ~100 ~125 ~2 grass_block
setblock ~100 ~125 ~3 grass_block
setblock ~100 ~125 ~4 grass_block
setblock ~100 ~125 ~5 grass_block
setblock ~100 ~125 ~6 grass_block
setblock ~100 ~125 ~7 grass_block
setblock ~100 ~125 ~8 grass_block
setblock ~100 ~125 ~9 grass_block
setblock ~100 ~125 ~10 short_grass
setblock ~100 ~125 ~12 short_grass
setblock ~100 ~125 ~13 short_grass
setblock ~100 ~125 ~14 short_grass
setblock ~100 ~125 ~18 short_grass
setblock ~100 ~125 ~23 grass_block
setblock ~100 ~125 ~24 grass_block
setblock ~100 ~125 ~25 grass_block
setblock ~100 ~125 ~26 grass_block
setblock ~100 ~125 ~27 dirt
setblock ~100 ~125 ~28 dirt
setblock ~100 ~125 ~29 dirt
setblock ~100 ~125 ~30 dirt
setblock ~100 ~125 ~31 dirt
setblock ~100 ~125 ~32 grass_block
setblock ~100 ~125 ~33 grass_block
setblock ~100 ~125 ~34 grass_block
setblock ~100 ~125 ~36 short_grass
setblock ~100 ~125 ~46 short_grass
setblock ~100 ~125 ~47 grass_block
setblock ~100 ~125 ~48 grass_block
setblock ~100 ~125 ~49 dirt
setblock ~100 ~125 ~50 dirt
setblock ~100 ~125 ~51 dirt
setblock ~100 ~125 ~52 dirt
setblock ~100 ~125 ~53 dirt
setblock ~100 ~125 ~54 dirt
setblock ~100 ~125 ~55 dirt
setblock ~100 ~125 ~56 grass_block
setblock ~100 ~125 ~57 grass_block
setblock ~100 ~125 ~58 grass_block
setblock ~100 ~125 ~59 grass_block
setblock ~100 ~125 ~60 grass_block
setblock ~100 ~125 ~61 grass_block
setblock ~100 ~125 ~62 grass_block
setblock ~100 ~125 ~64 short_grass
setblock ~100 ~125 ~65 short_grass
setblock ~100 ~125 ~67 short_grass
setblock ~100 ~125 ~90 short_grass
setblock ~100 ~125 ~92 short_grass
setblock ~100 ~125 ~97 short_grass
setblock ~100 ~125 ~102 short_grass
setblock ~100 ~125 ~106 fern
setblock ~100 ~125 ~107 grass_block
setblock ~100 ~125 ~108 grass_block
setblock ~100 ~125 ~109 grass_block
setblock ~100 ~125 ~110 grass_block
setblock ~100 ~125 ~111 grass_block
setblock ~100 ~125 ~112 grass_block
setblock ~100 ~125 ~135 grass_block
setblock ~100 ~125 ~136 dirt
setblock ~100 ~125 ~137 dirt
setblock ~100 ~125 ~138 dirt
setblock ~100 ~125 ~139 dirt
setblock ~100 ~125 ~140 dirt
setblock ~100 ~125 ~141 dirt
setblock ~100 ~125 ~142 dirt
setblock ~100 ~125 ~143 dirt
setblock ~100 ~125 ~144 dirt
setblock ~100 ~125 ~145 dirt
setblock ~100 ~125 ~146 dirt
setblock ~100 ~125 ~147 dirt
setblock ~100 ~125 ~148 dirt
setblock ~100 ~125 ~149 dirt
setblock ~100 ~125 ~150 dirt
setblock ~100 ~125 ~151 dirt
setblock ~100 ~125 ~152 dirt
setblock ~100 ~125 ~153 dirt
setblock ~100 ~125 ~154 dirt
setblock ~100 ~125 ~155 dirt
setblock ~100 ~125 ~156 dirt
setblock ~100 ~125 ~157 grass_block
setblock ~100 ~125 ~158 grass_block
setblock ~100 ~125 ~159 poppy
setblock ~100 ~125 ~178 grass_block
setblock ~100 ~125 ~179 grass_block
setblock ~100 ~125 ~180 grass_block
setblock ~100 ~125 ~181 grass_block
setblock ~100 ~125 ~182 grass_block
setblock ~100 ~125 ~183 grass_block
setblock ~100 ~125 ~184 grass_block
setblock ~100 ~125 ~187 short_grass
setblock ~100 ~125 ~196 short_grass
setblock ~100 ~125 ~199 grass_block
setblock ~100 ~126 ~8 poppy
setblock ~100 ~126 ~23 short_grass
setblock ~100 ~126 ~25 short_grass
setblock ~100 ~126 ~27 grass_block
setblock ~100 ~126 ~28 grass_block
setblock ~100 ~126 ~29 grass_block
setblock ~100 ~126 ~30 grass_block
setblock ~100 ~126 ~31 grass_block
setblock ~100 ~126 ~47 short_grass
setblock ~100 ~126 ~49 grass_block
setblock ~100 ~126 ~50 dirt
setblock ~100 ~126 ~51 dirt
setblock ~100 ~126 ~52 grass_block
setblock ~100 ~126 ~53 grass_block
setblock ~100 ~126 ~54 grass_block
setblock ~100 ~126 ~55 grass_block
setblock ~100 ~126 ~109 short_grass
setblock ~100 ~126 ~111 poppy
setblock ~100 ~126 ~112 short_grass
setblock ~100 ~126 ~136 grass_block
setblock ~100 ~126 ~137 dirt
setblock ~100 ~126 ~138 dirt
setblock ~100 ~126 ~139 dirt
setblock ~100 ~126 ~140 dirt
setblock ~100 ~126 ~141 dirt
setblock ~100 ~126 ~142 dirt
setblock ~100 ~126 ~143 dirt
setblock ~100 ~126 ~144 dirt
setblock ~100 ~126 ~145 dirt
setblock ~100 ~126 ~146 dirt
setblock ~100 ~126 ~147 dirt
setblock ~100 ~126 ~148 dirt
setblock ~100 ~126 ~149 dirt
setblock ~100 ~126 ~150 dirt
setblock ~100 ~126 ~151 dirt
setblock ~100 ~126 ~152 dirt
setblock ~100 ~126 ~153 dirt
setblock ~100 ~126 ~154 dirt
setblock ~100 ~126 ~155 grass_block
setblock ~100 ~126 ~156 grass_block
setblock ~100 ~126 ~181 short_grass
setblock ~100 ~126 ~183 short_grass
setblock ~100 ~127 ~28 short_grass
setblock ~100 ~127 ~31 fern
setblock ~100 ~127 ~49 fern
setblock ~100 ~127 ~50 grass_block
setblock ~100 ~127 ~51 grass_block
setblock ~100 ~127 ~136 short_grass
setblock ~100 ~127 ~137 grass_block
setblock ~100 ~127 ~138 dirt
setblock ~100 ~127 ~139 dirt
setblock ~100 ~127 ~140 dirt
setblock ~100 ~127 ~141 dirt
setblock ~100 ~127 ~142 dirt
setblock ~100 ~127 ~143 dirt
setblock ~100 ~127 ~144 dirt
setblock ~100 ~127 ~145 dirt
setblock ~100 ~127 ~146 dirt
setblock ~100 ~127 ~147 dirt
setblock ~100 ~127 ~148 dirt
setblock ~100 ~127 ~149 dirt
setblock ~100 ~127 ~150 dirt
setblock ~100 ~127 ~151 dirt
setblock ~100 ~127 ~152 dirt
setblock ~100 ~127 ~153 dirt
setblock ~100 ~127 ~154 grass_block
setblock ~100 ~127 ~155 short_grass
setblock ~100 ~128 ~51 short_grass
setblock ~100 ~128 ~138 grass_block
setblock ~100 ~128 ~139 dirt
setblock ~100 ~128 ~140 dirt
setblock ~100 ~128 ~141 dirt
setblock ~100 ~128 ~142 dirt
setblock ~100 ~128 ~143 dirt
setblock ~100 ~128 ~144 dirt
setblock ~100 ~128 ~145 dirt
setblock ~100 ~128 ~146 dirt
setblock ~100 ~128 ~147 dirt
setblock ~100 ~128 ~148 dirt
setblock ~100 ~128 ~149 dirt
setblock ~100 ~128 ~150 dirt
setblock ~100 ~128 ~151 dirt
setblock ~100 ~128 ~152 dirt
setblock ~100 ~128 ~153 grass_block
setblock ~100 ~129 ~139 grass_block
setblock ~100 ~129 ~140 dirt
setblock ~100 ~129 ~141 dirt
setblock ~100 ~129 ~142 dirt
setblock ~100 ~129 ~143 dirt
setblock ~100 ~129 ~144 dirt
setblock ~100 ~129 ~145 dirt
setblock ~100 ~129 ~146 dirt
setblock ~100 ~129 ~147 dirt
setblock ~100 ~129 ~148 dirt
setblock ~100 ~129 ~149 dirt
setblock ~100 ~129 ~150 dirt
setblock ~100 ~129 ~151 dirt
setblock ~100 ~129 ~152 grass_block
setblock ~100 ~129 ~153 short_grass
setblock ~100 ~130 ~139 fern
setblock ~100 ~130 ~140 grass_block
setblock ~100 ~130 ~141 grass_block
setblock ~100 ~130 ~142 grass_block
setblock ~100 ~130 ~143 grass_block
setblock ~100 ~130 ~144 grass_block
setblock ~100 ~130 ~145 grass_block
setblock ~100 ~130 ~146 dirt
setblock ~100 ~130 ~147 dirt
setblock ~100 ~130 ~148 dirt
setblock ~100 ~130 ~149 dirt
setblock ~100 ~130 ~150 dirt
setblock ~100 ~130 ~151 grass_block
setblock ~100 ~130 ~152 short_grass
setblock ~100 ~131 ~143 poppy
setblock ~100 ~131 ~146 grass_block
setblock ~100 ~131 ~147 grass_block
setblock ~100 ~131 ~148 grass_block
setblock ~100 ~131 ~149 grass_block
setblock ~100 ~131 ~150 grass_block
setblock ~100 ~132 ~147 short_grass
setblock ~100 ~132 ~149 short_grass
setblock ~101 ~122 ~0 dirt
setblock ~101 ~122 ~1 dirt
setblock ~101 ~122 ~2 dirt
setblock ~101 ~122 ~3 dirt
setblock ~101 ~122 ~4 dirt
setblock ~101 ~122 ~5 dirt
setblock ~101 ~122 ~6 dirt
setblock ~101 ~122 ~7 dirt
setblock ~101 ~122 ~8 dirt
setblock ~101 ~122 ~9 dirt
setblock ~101 ~122 ~10 dirt
setblock ~101 ~122 ~11 dirt
setblock ~101 ~122 ~12 dirt
setblock ~101 ~122 ~13 dirt
setblock ~101 ~122 ~14 dirt
setblock ~101 ~122 ~15 dirt
setblock ~101 ~122 ~16 dirt
setblock ~101 ~122 ~17 dirt
setblock ~101 ~122 ~18 dirt
setblock ~101 ~122 ~19 dirt
setblock ~101 ~122 ~20 dirt
setblock ~101 ~122 ~21 dirt
setblock ~101 ~122 ~22 dirt
setblock ~101 ~122 ~23 dirt
setblock ~101 ~122 ~24 dirt
setblock ~101 ~122 ~25 dirt
setblock ~101 ~122 ~26 dirt
setblock ~101 ~122 ~27 dirt
setblock ~101 ~122 ~28 dirt
setblock ~101 ~122 ~29 dirt
setblock ~101 ~122 ~30 dirt
setblock ~101 ~122 ~31 dirt
setblock ~101 ~122 ~32 dirt
setblock ~101 ~122 ~33 dirt
setblock ~101 ~122 ~34 dirt
setblock ~101 ~122 ~35 dirt
setblock ~101 ~122 ~36 dirt
setblock ~101 ~122 ~37 dirt
setblock ~101 ~122 ~38 dirt
setblock ~101 ~122 ~39 dirt
setblock ~101 ~122 ~40 dirt
setblock ~101 ~122 ~41 dirt
setblock ~101 ~122 ~42 dirt
setblock ~101 ~122 ~43 dirt
setblock ~101 ~122 ~44 dirt
setblock ~101 ~122 ~45 dirt
setblock ~101 ~122 ~46 dirt
setblock ~101 ~122 ~47 dirt
setblock ~101 ~122 ~48 dirt
setblock ~101 ~122 ~49 dirt
setblock ~101 ~122 ~50 dirt
setblock ~101 ~122 ~51 dirt
setblock ~101 ~122 ~52 dirt
setblock ~101 ~122 ~53 dirt
setblock ~101 ~122 ~54 dirt
setblock ~101 ~122 ~55 dirt
setblock ~101 ~122 ~56 dirt
setblock ~101 ~122 ~57 dirt
setblock ~101 ~122 ~58 dirt
setblock ~101 ~122 ~59 dirt
setblock ~101 ~122 ~60 dirt
setblock ~101 ~122 ~61 dirt
setblock ~101 ~122 ~62 dirt
setblock ~101 ~122 ~63 dirt
setblock ~101 ~122 ~64 dirt
setblock ~101 ~122 ~65 dirt
setblock ~101 ~122 ~66 dirt
setblock ~101 ~122 ~67 dirt
setblock ~101 ~122 ~68 dirt
setblock ~101 ~122 ~69 dirt
setblock ~101 ~122 ~70 dirt
setblock ~101 ~122 ~71 dirt
setblock ~101 ~122 ~72 dirt
setblock ~101 ~122 ~73 dirt
setblock ~101 ~122 ~74 dirt
setblock ~101 ~122 ~75 dirt
setblock ~101 ~122 ~76 dirt
setblock ~101 ~122 ~77 dirt
setblock ~101 ~122 ~78 dirt
setblock ~101 ~122 ~79 dirt
setblock ~101 ~122 ~80 dirt
setblock ~101 ~122 ~81 dirt
setblock ~101 ~122 ~82 dirt
setblock ~101 ~122 ~83 dirt
setblock ~101 ~122 ~84 dirt
setblock ~101 ~122 ~85 dirt
setblock ~101 ~122 ~86 dirt
setblock ~101 ~122 ~87 dirt
setblock ~101 ~122 ~88 dirt
setblock ~101 ~122 ~89 dirt
setblock ~101 ~122 ~90 dirt
setblock ~101 ~122 ~91 dirt
setblock ~101 ~122 ~92 dirt
setblock ~101 ~122 ~93 dirt
setblock ~101 ~122 ~94 dirt
setblock ~101 ~122 ~95 dirt
setblock ~101 ~122 ~96 dirt
setblock ~101 ~122 ~97 dirt
setblock ~101 ~122 ~98 dirt
setblock ~101 ~122 ~99 dirt
setblock ~101 ~122 ~100 dirt
setblock ~101 ~122 ~101 dirt
setblock ~101 ~122 ~102 dirt
setblock ~101 ~122 ~103 dirt
setblock ~101 ~122 ~104 dirt
setblock ~101 ~122 ~105 dirt
setblock ~101 ~122 ~106 dirt
setblock ~101 ~122 ~107 dirt
setblock ~101 ~122 ~108 dirt
setblock ~101 ~122 ~109 dirt
setblock ~101 ~122 ~110 dirt
setblock ~101 ~122 ~111 dirt
setblock ~101 ~122 ~112 dirt
setblock ~101 ~122 ~113 dirt
setblock ~101 ~122 ~114 dirt
setblock ~101 ~122 ~115 dirt
setblock ~101 ~122 ~116 dirt
setblock ~101 ~122 ~117 dirt
setblock ~101 ~122 ~118 dirt
setblock ~101 ~122 ~119 dirt
setblock ~101 ~122 ~120 dirt
setblock ~101 ~122 ~121 dirt
setblock ~101 ~122 ~122 grass_block
setblock ~101 ~122 ~123 grass_block
setblock ~101 ~122 ~124 grass_block
setblock ~101 ~122 ~125 grass_block
setblock ~101 ~122 ~126 grass_block
setblock ~101 ~122 ~127 grass_block
setblock ~101 ~122 ~128 grass_block
setblock ~101 ~122 ~129 grass_block
setblock ~101 ~122 ~130 grass_block
setblock ~101 ~122 ~131 grass_block
setblock ~101 ~122 ~132 dirt
setblock ~101 ~122 ~133 dirt
setblock ~101 ~122 ~134 dirt
setblock ~101 ~122 ~135 dirt
setblock ~101 ~122 ~136 dirt
setblock ~101 ~122 ~137 dirt
setblock ~101 ~122 ~138 dirt
setblock ~101 ~122 ~139 dirt
setblock ~101 ~122 ~140 dirt
setblock ~101 ~122 ~141 dirt
setblock ~101 ~122 ~142 dirt
setblock ~101 ~122 ~143 dirt
setblock ~101 ~122 ~144 dirt
setblock ~101 ~122 ~145 dirt
setblock ~101 ~122 ~146 dirt
setblock ~101 ~122 ~147 dirt
setblock ~101 ~122 ~148 dirt
setblock ~101 ~122 ~149 dirt
setblock ~101 ~122 ~150 dirt
setblock ~101 ~122 ~151 dirt
setblock ~101 ~122 ~152 dirt
setblock ~101 ~122 ~153 dirt
setblock ~101 ~122 ~154 dirt
setblock ~101 ~122 ~155 dirt
setblock ~101 ~122 ~156 dirt
setblock ~101 ~122 ~157 dirt
setblock ~101 ~122 ~158 dirt
setblock ~101 ~122 ~159 dirt
setblock ~101 ~122 ~160 dirt
setblock ~101 ~122 ~161 dirt
setblock ~101 ~122 ~162 dirt
setblock ~101 ~122 ~163 dirt
setblock ~101 ~122 ~164 dirt
setblock ~101 ~122 ~165 dirt
setblock ~101 ~122 ~166 dirt
setblock ~101 ~122 ~167 dirt
setblock ~101 ~122 ~168 dirt
setblock ~101 ~122 ~169 grass_block
setblock ~101 ~122 ~170 grass_block
setblock ~101 ~122 ~171 dirt
setblock ~101 ~122 ~172 dirt
setblock ~101 ~122 ~173 dirt
setblock ~101 ~122 ~174 dirt
setblock ~101 ~122 ~175 dirt
setblock ~101 ~122 ~176 dirt
setblock ~101 ~122 ~177 dirt
setblock ~101 ~122 ~178 dirt
setblock ~101 ~122 ~179 dirt
setblock ~101 ~122 ~180 dirt
setblock ~101 ~122 ~181 dirt
setblock ~101 ~122 ~182 dirt
setblock ~101 ~122 ~183 dirt
setblock ~101 ~122 ~184 dirt
setblock ~101 ~122 ~185 dirt
setblock ~101 ~122 ~186 dirt
setblock ~101 ~122 ~187 dirt
setblock ~101 ~122 ~188 dirt
setblock ~101 ~122 ~189 dirt
setblock ~101 ~122 ~190 dirt
setblock ~101 ~122 ~191 dirt
setblock ~101 ~122 ~192 dirt
setblock ~101 ~122 ~193 dirt
setblock ~101 ~122 ~194 dirt
setblock ~101 ~122 ~195 dirt
setblock ~101 ~122 ~196 dirt
setblock ~101 ~122 ~197 dirt
setblock ~101 ~122 ~198 dirt
setblock ~101 ~122 ~199 dirt
setblock ~101 ~123 ~0 dirt
setblock ~101 ~123 ~1 dirt
setblock ~101 ~123 ~2 dirt
setblock ~101 ~123 ~3 dirt
setblock ~101 ~123 ~4 dirt
setblock ~101 ~123 ~5 dirt
setblock ~101 ~123 ~6 dirt
setblock ~101 ~123 ~7 dirt
setblock ~101 ~123 ~8 dirt
setblock ~101 ~123 ~9 dirt
setblock ~101 ~123 ~10 dirt
setblock ~101 ~123 ~11 dirt
setblock ~101 ~123 ~12 dirt
setblock ~101 ~123 ~13 dirt
setblock ~101 ~123 ~14 dirt
setblock ~101 ~123 ~15 dirt
setblock ~101 ~123 ~16 dirt
setblock ~101 ~123 ~17 dirt
setblock ~101 ~123 ~18 dirt
setblock ~101 ~123 ~19 dirt
setblock ~101 ~123 ~20 dirt
setblock ~101 ~123 ~21 dirt
setblock ~101 ~123 ~22 dirt
setblock ~101 ~123 ~23 dirt
setblock ~101 ~123 ~24 dirt
setblock ~101 ~123 ~25 dirt
setblock ~101 ~123 ~26 dirt
setblock ~101 ~123 ~27 dirt
setblock ~101 ~123 ~28 dirt
setblock ~101 ~123 ~29 dirt
setblock ~101 ~123 ~30 dirt
setblock ~101 ~123 ~31 dirt
setblock ~101 ~123 ~32 dirt
setblock ~101 ~123 ~33 dirt
setblock ~101 ~123 ~34 dirt
setblock ~101 ~123 ~35 dirt
setblock ~101 ~123 ~36 dirt
setblock ~101 ~123 ~37 dirt
setblock ~101 ~123 ~38 dirt
setblock ~101 ~123 ~39 grass_block
setblock ~101 ~123 ~40 grass_block
setblock ~101 ~123 ~41 grass_block
setblock ~101 ~123 ~42 dirt
setblock ~101 ~123 ~43 dirt
setblock ~101 ~123 ~44 dirt
setblock ~101 ~123 ~45 dirt
setblock ~101 ~123 ~46 dirt
setblock ~101 ~123 ~47 dirt
setblock ~101 ~123 ~48 dirt
setblock ~101 ~123 ~49 dirt
setblock ~101 ~123 ~50 dirt
setblock ~101 ~123 ~51 dirt
setblock ~101 ~123 ~52 dirt
setblock ~101 ~123 ~53 dirt
setblock ~101 ~123 ~54 dirt
setblock ~101 ~123 ~55 dirt
setblock ~101 ~123 ~56 dirt
setblock ~101 ~123 ~57 dirt
setblock ~101 ~123 ~58 dirt
setblock ~101 ~123 ~59 dirt
setblock ~101 ~123 ~60 dirt
setblock ~101 ~123 ~61 dirt
setblock ~101 ~123 ~62 dirt
setblock ~101 ~123 ~63 dirt
setblock ~101 ~123 ~64 dirt
setblock ~101 ~123 ~65 dirt
setblock ~101 ~123 ~66 dirt
setblock ~101 ~123 ~67 dirt
setblock ~101 ~123 ~68 dirt
setblock ~101 ~123 ~69 dirt
setblock ~101 ~123 ~70 grass_block
setblock ~101 ~123 ~71 grass_block
setblock ~101 ~123 ~72 grass_block
setblock ~101 ~123 ~73 grass_block
setblock ~101 ~123 ~74 grass_block
setblock ~101 ~123 ~75 grass_block
setblock ~101 ~123 ~76 grass_block
setblock ~101 ~123 ~77 grass_block
setblock ~101 ~123 ~78 grass_block
setblock ~101 ~123 ~79 grass_block
setblock ~101 ~123 ~80 grass_block
setblock ~101 ~123 ~81 grass_block
setblock ~101 ~123 ~82 grass_block
setblock ~101 ~123 ~83 dirt
setblock ~101 ~123 ~84 dirt
setblock ~101 ~123 ~85 dirt
setblock ~101 ~123 ~86 dirt
setblock ~101 ~123 ~87 dirt
setblock ~101 ~123 ~88 dirt
setblock ~101 ~123 ~89 dirt
setblock ~101 ~123 ~90 dirt
setblock ~101 ~123 ~91 dirt
setblock ~101 ~123 ~92 dirt
setblock ~101 ~123 ~93 dirt
setblock ~101 ~123 ~94 dirt
setblock ~101 ~123 ~95 dirt
setblock ~101 ~123 ~96 dirt
setblock ~101 ~123 ~97 dirt
setblock ~101 ~123 ~98 dirt
setblock ~101 ~123 ~99 grass_block
setblock ~101 ~123 ~100 grass_block
setblock ~101 ~123 ~101 grass_block
setblock ~101 ~123 ~102 dirt
setblock ~101 ~123 ~103 dirt
setblock ~101 ~123 ~104 dirt
setblock ~101 ~123 ~105 dirt
setblock ~101 ~123 ~106 dirt
setblock ~101 ~123 ~107 dirt
setblock ~101 ~123 ~108 dirt
setblock ~101 ~123 ~109 dirt
setblock ~101 ~123 ~110 dirt
setblock ~101 ~123 ~111 dirt
setblock ~101 ~123 ~112 dirt
setblock ~101 ~123 ~113 dirt
setblock ~101 ~123 ~114 dirt
setblock ~101 ~123 ~115 dirt
setblock ~101 ~123 ~116 dirt
setblock ~101 ~123 ~117 grass_block
setblock ~101 ~123 ~118 grass_block
setblock ~101 ~123 ~119 grass_block
setblock ~101 ~123 ~120 grass_block
setblock ~101 ~123 ~121 grass_block
setblock ~101 ~123 ~122 fern
setblock ~101 ~123 ~125 short_grass
setblock ~101 ~123 ~128 fern
setblock ~101 ~123 ~132 grass_block
setblock ~101 ~123 ~133 grass_block
setblock ~101 ~123 ~134 dirt
setblock ~101 ~123 ~135 dirt
setblock ~101 ~123 ~136 dirt
setblock ~101 ~123 ~137 dirt
setblock ~101 ~123 ~138 dirt
setblock ~101 ~123 ~139 dirt
setblock ~101 ~123 ~140 dirt
setblock ~101 ~123 ~141 dirt
setblock ~101 ~123 ~142 dirt
setblock ~101 ~123 ~143 dirt
setblock ~101 ~123 ~144 dirt
setblock ~101 ~123 ~145 dirt
setblock ~101 ~123 ~146 dirt
setblock ~101 ~123 ~147 dirt
setblock ~101 ~123 ~148 dirt
setblock ~101 ~123 ~149 dirt
setblock ~101 ~123 ~150 dirt
setblock ~101 ~123 ~151 dirt
setblock ~101 ~123 ~152 dirt
setblock ~101 ~123 ~153 dirt
setblock ~101 ~123 ~154 dirt
setblock ~101 ~123 ~155 dirt
setblock ~101 ~123 ~156 dirt
setblock ~101 ~123 ~157 dirt
setblock ~101 ~123 ~158 dirt
setblock ~101 ~123 ~159 dirt
setblock ~101 ~123 ~160 dirt
setblock ~101 ~123 ~161 dirt
setblock ~101 ~123 ~162 dirt
setblock ~101 ~123 ~163 dirt
setblock ~101 ~123 ~164 grass_block
setblock ~101 ~123 ~165 grass_block
setblock ~101 ~123 ~166 grass_block
setblock ~101 ~123 ~167 grass_block
setblock ~101 ~123 ~168 grass_block
setblock ~101 ~123 ~170 fern
setblock ~101 ~123 ~171 grass_block
setblock ~101 ~123 ~172 grass_block
setblock ~101 ~123 ~173 grass_block
setblock ~101 ~123 ~174 dirt
setblock ~101 ~123 ~175 dirt
setblock ~101 ~123 ~176 dirt
setblock ~101 ~123 ~177 dirt
setblock ~101 ~123 ~178 dirt
setblock ~101 ~123 ~179 dirt
setblock ~101 ~123 ~180 dirt
setblock ~101 ~123 ~181 dirt
setblock ~101 ~123 ~182 dirt
setblock ~101 ~123 ~183 dirt
setblock ~101 ~123 ~184 dirt
setblock ~101 ~123 ~185 dirt
setblock ~101 ~123 ~186 dirt
setblock ~101 ~123 ~187 dirt
setblock ~101 ~123 ~188 dirt
setblock ~101 ~123 ~189 dirt
setblock ~101 ~123 ~190 dirt
setblock ~101 ~123 ~191 dirt
setblock ~101 ~123 ~192 dirt
setblock ~101 ~123 ~193 dirt
setblock ~101 ~123 ~194 dirt
setblock ~101 ~123 ~195 dirt
setblock ~101 ~123 ~196 dirt
setblock ~101 ~123 ~197 dirt
setblock ~101 ~123 ~198 dirt
setblock ~101 ~123 ~199 dirt
setblock ~101 ~124 ~0 dirt
setblock ~101 ~124 ~1 dirt
setblock ~101 ~124 ~2 dirt
setblock ~101 ~124 ~3 dirt
setblock ~101 ~124 ~4 dirt
setblock ~101 ~124 ~5 dirt
setblock ~101 ~124 ~6 dirt
setblock ~101 ~124 ~7 dirt
setblock ~101 ~124 ~8 dirt
setblock ~101 ~124 ~9 dirt
setblock ~101 ~124 ~10 dirt
setblock ~101 ~124 ~11 dirt
setblock ~101 ~124 ~12 dirt
setblock ~101 ~124 ~13 dirt
setblock ~101 ~124 ~14 dirt
setblock ~101 ~124 ~15 dirt
setblock ~101 ~124 ~16 dirt
setblock ~101 ~124 ~17 grass_block
setblock ~101 ~124 ~18 grass_block
setblock ~101 ~124 ~19 grass_block
setblock ~101 ~124 ~20 grass_block
setblock ~101 ~124 ~21 grass_block
setblock ~101 ~124 ~22 dirt
setblock ~101 ~124 ~23 dirt
setblock ~101 ~124 ~24 dirt
setblock ~101 ~124 ~25 dirt
setblock ~101 ~124 ~26 dirt
setblock ~101 ~124 ~27 dirt
setblock ~101 ~124 ~28 dirt
setblock ~101 ~124 ~29 dirt
setblock ~101 ~124 ~30 dirt
setblock ~101 ~124 ~31 dirt
setblock ~101 ~124 ~32 dirt
setblock ~101 ~124 ~33 dirt
setblock ~101 ~124 ~34 dirt
setblock ~101 ~124 ~35 grass_block
setblock ~101 ~124 ~36 grass_block
setblock ~101 ~124 ~37 grass_block
setblock ~101 ~124 ~38 grass_block
setblock ~101 ~124 ~40 short_grass
setblock ~101 ~124 ~42 grass_block
setblock ~101 ~124 ~43 grass_block
setblock ~101 ~124 ~44 grass_block
setblock ~101 ~124 ~45 grass_block
setblock ~101 ~124 ~46 dirt
setblock ~101 ~124 ~47 dirt
setblock ~101 ~124 ~48 dirt
setblock ~101 ~124 ~49 dirt
setblock ~101 ~124 ~50 dirt
setblock ~101 ~124 ~51 dirt
setblock ~101 ~124 ~52 dirt
setblock ~101 ~124 ~53 dirt
setblock ~101 ~124 ~54 dirt
setblock ~101 ~124 ~55 dirt
setblock ~101 ~124 ~56 dirt
setblock ~101 ~124 ~57 dirt
setblock ~101 ~124 ~58 dirt
setblock ~101 ~124 ~59 dirt
setblock ~101 ~124 ~60 dirt
setblock ~101 ~124 ~61 dirt
setblock ~101 ~124 ~62 dirt
setblock ~101 ~124 ~63 dirt
setblock ~101 ~124 ~64 grass_block
setblock ~101 ~124 ~65 grass_block
setblock ~101 ~124 ~66 grass_block
setblock ~101 ~124 ~67 grass_block
setblock ~101 ~124 ~68 grass_block
setblock ~101 ~124 ~69 grass_block
setblock ~101 ~124 ~70 fern
setblock ~101 ~124 ~74 short_grass
setblock ~101 ~124 ~76 short_grass
setblock ~101 ~124 ~79 fern
setblock ~101 ~124 ~83 grass_block
setblock ~101 ~124 ~84 grass_block
setblock ~101 ~124 ~85 grass_block
setblock ~101 ~124 ~86 grass_block
setblock ~101 ~124 ~87 grass_block
setblock ~101 ~124 ~88 grass_block
setblock ~101 ~124 ~89 grass_block
setblock ~101 ~124 ~90 dirt
setblock ~101 ~124 ~91 dirt
setblock ~101 ~124 ~92 grass_block
setblock ~101 ~124 ~93 grass_block
setblock ~101 ~124 ~94 grass_block
setblock ~101 ~124 ~95 grass_block
setblock ~101 ~124 ~96 grass_block
setblock ~101 ~124 ~97 grass_block
setblock ~101 ~124 ~98 grass_block
setblock ~101 ~124 ~100 short_grass
setblock ~101 ~124 ~102 grass_block
setblock ~101 ~124 ~103 grass_block
setblock ~101 ~124 ~104 grass_block
setblock ~101 ~124 ~105 grass_block
setblock ~101 ~124 ~106 dirt
setblock ~101 ~124 ~107 dirt
setblock ~101 ~124 ~108 dirt
setblock ~101 ~124 ~109 dirt
setblock ~101 ~124 ~110 dirt
setblock ~101 ~124 ~111 dirt
setblock ~101 ~124 ~112 dirt
setblock ~101 ~124 ~113 dirt
setblock ~101 ~124 ~114 grass_block
setblock ~101 ~124 ~115 grass_block
setblock ~101 ~124 ~116 grass_block
setblock ~101 ~124 ~118 short_grass
setblock ~101 ~124 ~120 poppy
setblock ~101 ~124 ~132 poppy
setblock ~101 ~124 ~134 grass_block
setblock ~101 ~124 ~135 dirt
setblock ~101 ~124 ~136 dirt
setblock ~101 ~124 ~137 dirt
setblock ~101 ~124 ~138 dirt
setblock ~101 ~124 ~139 dirt
setblock ~101 ~124 ~140 dirt
setblock ~101 ~124 ~141 dirt
setblock ~101 ~124 ~142 dirt
setblock ~101 ~124 ~143 dirt
setblock ~101 ~124 ~144 dirt
setblock ~101 ~124 ~145 dirt
setblock ~101 ~124 ~146 dirt
setblock ~101 ~124 ~147 dirt
setblock ~101 ~124 ~148 dirt
setblock ~101 ~124 ~149 dirt
setblock ~101 ~124 ~150 dirt
setblock ~101 ~124 ~151 dirt
setblock ~101 ~124 ~152 dirt
setblock ~101 ~124 ~153 dirt
setblock ~101 ~124 ~154 dirt
setblock ~101 ~124 ~155 dirt
setblock ~101 ~124 ~156 dirt
setblock ~101 ~124 ~157 dirt
setblock ~101 ~124 ~158 dirt
setblock ~101 ~124 ~159 grass_block
setblock ~101 ~124 ~160 grass_block
setblock ~101 ~124 ~161 grass_block
setblock ~101 ~124 ~162 grass_block
setblock ~101 ~124 ~163 grass_block
setblock ~101 ~124 ~166 short_grass
setblock ~101 ~124 ~168 short_grass
setblock ~101 ~124 ~172 short_grass
setblock ~101 ~124 ~174 grass_block
setblock ~101 ~124 ~175 grass_block
setblock ~101 ~124 ~176 grass_block
setblock ~101 ~124 ~177 grass_block
setblock ~101 ~124 ~178 grass_block
setblock ~101 ~124 ~179 dirt
setblock ~101 ~124 ~180 dirt
setblock ~101 ~124 ~181 dirt
setblock ~101 ~124 ~182 dirt
setblock ~101 ~124 ~183 dirt
setblock ~101 ~124 ~184 dirt
setblock ~101 ~124 ~185 dirt
setblock ~101 ~124 ~186 grass_block
setblock ~101 ~124 ~187 grass_block
setblock ~101 ~124 ~188 grass_block
setblock ~101 ~124 ~189 grass_block
setblock ~101 ~124 ~190 grass_block
setblock ~101 ~124 ~191 grass_block
setblock ~101 ~124 ~192 grass_block
setblock ~101 ~124 ~193 grass_block
setblock ~101 ~124 ~194 grass_block
setblock ~101 ~124 ~195 grass_block
setblock ~101 ~124 ~196 grass_block
setblock ~101 ~124 ~197 grass_block
setblock ~101 ~124 ~198 grass_block
setblock ~101 ~124 ~199 grass_block
setblock ~101 ~125 ~0 dirt
setblock ~101 ~125 ~1 dirt
setblock ~101 ~125 ~2 dirt
setblock ~101 ~125 ~3 dirt
setblock ~101 ~125 ~4 dirt
setblock ~101 ~125 ~5 grass_block
setblock ~101 ~125 ~6 grass_block
setblock ~101 ~125 ~7 grass_block
setblock ~101 ~125 ~8 grass_block
setblock ~101 ~125 ~9 grass_block
setblock ~101 ~125 ~10 grass_block
setblock ~101 ~125 ~11 grass_block
setblock ~101 ~125 ~12 grass_block
setblock ~101 ~125 ~13 grass_block
setblock ~101 ~125 ~14 grass_block
setblock ~101 ~125 ~15 grass_block
setblock ~101 ~125 ~16 grass_block
setblock ~101 ~125 ~21 short_grass
setblock ~101 ~125 ~22 grass_block
setblock ~101 ~125 ~23 grass_block
setblock ~101 ~125 ~24 grass_block
setblock ~101 ~125 ~25 grass_block
setblock ~101 ~125 ~26 grass_block
setblock ~101 ~125 ~27 grass_block
setblock ~101 ~125 ~28 dirt
setblock ~101 ~125 ~29 dirt
setblock ~101 ~125 ~30 dirt
setblock ~101 ~125 ~31 dirt
setblock ~101 ~125 ~32 grass_block
setblock ~101 ~125 ~33 grass_block
setblock ~101 ~125 ~34 grass_block
setblock ~101 ~125 ~37 short_grass
setblock ~101 ~125 ~42 poppy
setblock ~101 ~125 ~46 grass_block
setblock ~101 ~125 ~47 grass_block
setblock ~101 ~125 ~48 grass_block
setblock ~101 ~125 ~49 dirt
setblock ~101 ~125 ~50 dirt
setblock ~101 ~125 ~51 dirt
setblock ~101 ~125 ~52 dirt
setblock ~101 ~125 ~53 dirt
setblock ~101 ~125 ~54 dirt
setblock ~101 ~125 ~55 grass_block
setblock ~101 ~125 ~56 grass_block
setblock ~101 ~125 ~57 grass_block
setblock ~101 ~125 ~58 grass_block
setblock ~101 ~125 ~59 grass_block
setblock ~101 ~125 ~60 grass_block
setblock ~101 ~125 ~61 grass_block
setblock ~101 ~125 ~62 grass_block
setblock ~101 ~125 ~63 grass_block
setblock ~101 ~125 ~66 short_grass
setblock ~101 ~125 ~83 short_grass
setblock ~101 ~125 ~84 short_grass
setblock ~101 ~125 ~85 short_grass
setblock ~101 ~125 ~87 short_grass
setblock ~101 ~125 ~90 grass_block
setblock ~101 ~125 ~91 grass_block
setblock ~101 ~125 ~92 fern
setblock ~101 ~125 ~102 short_grass
setblock ~101 ~125 ~104 short_grass
setblock ~101 ~125 ~105 fern
setblock ~101 ~125 ~106 grass_block
setblock ~101 ~125 ~107 grass_block
setblock ~101 ~125 ~108 grass_block
setblock ~101 ~125 ~109 grass_block
setblock ~101 ~125 ~110 grass_block
setblock ~101 ~125 ~111 grass_block
setblock ~101 ~125 ~112 grass_block
setblock ~101 ~125 ~113 grass_block
setblock ~101 ~125 ~116 poppy
setblock ~101 ~125 ~135 grass_block
setblock ~101 ~125 ~136 dirt
setblock ~101 ~125 ~137 dirt
setblock ~101 ~125 ~138 dirt
setblock ~101 ~125 ~139 dirt
setblock ~101 ~125 ~140 dirt
setblock ~101 ~125 ~141 dirt
setblock ~101 ~125 ~142 dirt
setblock ~101 ~125 ~143 dirt
setblock ~101 ~125 ~144 dirt
setblock ~101 ~125 ~145 dirt
setblock ~101 ~125 ~146 dirt
setblock ~101 ~125 ~147 dirt
setblock ~101 ~125 ~148 dirt
setblock ~101 ~125 ~149 dirt
setblock ~101 ~125 ~150 dirt
setblock ~101 ~125 ~151 dirt
setblock ~101 ~125 ~152 dirt
setblock ~101 ~125 ~153 dirt
setblock ~101 ~125 ~154 dirt
setblock ~101 ~125 ~155 dirt
setblock ~101 ~125 ~156 grass_block
setblock ~101 ~125 ~157 grass_block
setblock ~101 ~125 ~158 grass_block
setblock ~101 ~125 ~162 poppy
setblock ~101 ~125 ~176 short_grass
setblock ~101 ~125 ~179 grass_block
setblock ~101 ~125 ~180 grass_block
setblock ~101 ~125 ~181 grass_block
setblock ~101 ~125 ~182 grass_block
setblock ~101 ~125 ~183 grass_block
setblock ~101 ~125 ~184 grass_block
setblock ~101 ~125 ~185 grass_block
setblock ~101 ~125 ~186 short_grass
setblock ~101 ~125 ~189 fern
setblock ~101 ~125 ~190 short_grass
setblock ~101 ~125 ~191 short_grass
setblock ~101 ~125 ~196 short_grass
setblock ~101 ~125 ~197 short_grass
setblock ~101 ~125 ~199 short_grass
setblock ~101 ~126 ~0 grass_block
setblock ~101 ~126 ~1 grass_block
setblock ~101 ~126 ~2 grass_block
setblock ~101 ~126 ~3 grass_block
setblock ~101 ~126 ~4 grass_block
setblock ~101 ~126 ~5 short_grass
setblock ~101 ~126 ~15 short_grass
setblock ~101 ~126 ~23 short_grass
setblock ~101 ~126 ~28 grass_block
setblock ~101 ~126 ~29 grass_block
setblock ~101 ~126 ~30 grass_block
setblock ~101 ~126 ~31 grass_block
setblock ~101 ~126 ~46 short_grass
setblock ~101 ~126 ~49 grass_block
setblock ~101 ~126 ~50 dirt
setblock ~101 ~126 ~51 grass_block
setblock ~101 ~126 ~52 grass_block
setblock ~101 ~126 ~53 grass_block
setblock ~101 ~126 ~54 grass_block
setblock ~101 ~126 ~91 short_grass
setblock ~101 ~126 ~106 poppy
setblock ~101 ~126 ~112 fern
setblock ~101 ~126 ~135 short_grass
setblock ~101 ~126 ~136 grass_block
setblock ~101 ~126 ~137 grass_block
setblock ~101 ~126 ~138 dirt
setblock ~101 ~126 ~139 dirt
setblock ~101 ~126 ~140 dirt
setblock ~101 ~126 ~141 dirt
setblock ~101 ~126 ~142 dirt
setblock ~101 ~126 ~143 dirt
setblock ~101 ~126 ~144 dirt
setblock ~101 ~126 ~145 dirt
setblock ~101 ~126 ~146 dirt
setblock ~101 ~126 ~147 dirt
setblock ~101 ~126 ~148 dirt
setblock ~101 ~126 ~149 dirt
setblock ~101 ~126 ~150 dirt
setblock ~101 ~126 ~151 dirt
setblock ~101 ~126 ~152 dirt
setblock ~101 ~126 ~153 dirt
setblock ~101 ~126 ~154 grass_block
setblock ~101 ~126 ~155 grass_block
setblock ~101 ~126 ~156 short_grass
setblock ~101 ~126 ~185 short_grass
setblock ~101 ~127 ~2 short_grass
setblock ~101 ~127 ~4 short_grass
setblock ~101 ~127 ~28 short_grass
setblock ~101 ~127 ~30 fern
setblock ~101 ~127 ~50 grass_block
setblock ~101 ~127 ~136 short_grass
setblock ~101 ~127 ~138 grass_block
setblock ~101 ~127 ~139 dirt
setblock ~101 ~127 ~140 dirt
setblock ~101 ~127 ~141 dirt
setblock ~101 ~127 ~142 dirt
setblock ~101 ~127 ~143 dirt
setblock ~101 ~127 ~144 dirt
setblock ~101 ~127 ~145 dirt
setblock ~101 ~127 ~146 dirt
setblock ~101 ~127 ~147 dirt
setblock ~101 ~127 ~148 dirt
setblock ~101 ~127 ~149 dirt
setblock ~101 ~127 ~150 dirt
setblock ~101 ~127 ~151 dirt
setblock ~101 ~127 ~152 dirt
setblock ~101 ~127 ~153 grass_block
setblock ~101 ~128 ~139 grass_block
setblock ~101 ~128 ~140 dirt
setblock ~101 ~128 ~141 dirt
setblock ~101 ~128 ~142 dirt
setblock ~101 ~128 ~143 dirt
setblock ~101 ~128 ~144 dirt
setblock ~101 ~128 ~145 dirt
setblock ~101 ~128 ~146 dirt
setblock ~101 ~128 ~147 dirt
setblock ~101 ~128 ~148 dirt
setblock ~101 ~128 ~149 dirt
setblock ~101 ~128 ~150 dirt
setblock ~101 ~128 ~151 dirt
setblock ~101 ~128 ~152 grass_block
setblock ~101 ~129 ~139 short_grass
setblock ~101 ~129 ~140 grass_block
setblock ~101 ~129 ~141 grass_block
setblock ~101 ~129 ~142 grass_block
setblock ~101 ~129 ~143 grass_block
setblock ~101 ~129 ~144 grass_block
setblock ~101 ~129 ~145 grass_block
setblock ~101 ~129 ~146 grass_block
setblock ~101 ~129 ~147 dirt
setblock ~101 ~129 ~148 dirt
setblock ~101 ~129 ~149 dirt
setblock ~101 ~129 ~150 dirt
setblock ~101 ~129 ~151 grass_block
setblock ~101 ~130 ~140 short_grass
setblock ~101 ~130 ~141 short_grass
setblock ~101 ~130 ~147 grass_block
setblock ~101 ~130 ~148 grass_block
setblock ~101 ~130 ~149 grass_block
setblock ~101 ~130 ~150 grass_block
setblock ~102 ~122 ~0 dirt
setblock ~102 ~122 ~1 dirt
setblock ~102 ~122 ~2 dirt
setblock ~102 ~122 ~3 dirt
setblock ~102 ~122 ~4 dirt
setblock ~102 ~122 ~5 dirt
setblock ~102 ~122 ~6 dirt
setblock ~102 ~122 ~7 dirt
setblock ~102 ~122 ~8 dirt
setblock ~102 ~122 ~9 dirt
setblock ~102 ~122 ~10 dirt
setblock ~102 ~122 ~11 dirt
setblock ~102 ~122 ~12 dirt
setblock ~102 ~122 ~13 dirt
setblock ~102 ~122 ~14 dirt
setblock ~102 ~122 ~15 dirt
setblock ~102 ~122 ~16 dirt
setblock ~102 ~122 ~17 dirt
setblock ~102 ~122 ~18 dirt
setblock ~102 ~122 ~19 dirt
setblock ~102 ~122 ~20 dirt
setblock ~102 ~122 ~21 dirt
setblock ~102 ~122 ~22 dirt
setblock ~102 ~122 ~23 dirt
setblock ~102 ~122 ~24 dirt
setblock ~102 ~122 ~25 dirt
setblock ~102 ~122 ~26 dirt
