setblock ~169 ~161 ~79 oak_leaves[persistent=true]
setblock ~169 ~161 ~80 jungle_leaves[persistent=true]
setblock ~169 ~161 ~81 oak_leaves[persistent=true]
setblock ~169 ~161 ~82 oak_wood
setblock ~169 ~161 ~83 oak_leaves[persistent=true]
setblock ~169 ~161 ~84 oak_leaves[persistent=true]
setblock ~169 ~161 ~86 oak_wood
setblock ~169 ~161 ~87 oak_wood
setblock ~169 ~161 ~88 oak_wood
setblock ~169 ~161 ~89 oak_wood
setblock ~169 ~161 ~90 oak_wood
setblock ~169 ~161 ~91 oak_wood
setblock ~169 ~161 ~92 oak_wood
setblock ~169 ~161 ~93 oak_wood
setblock ~169 ~161 ~94 oak_wood
setblock ~169 ~161 ~95 oak_wood
setblock ~169 ~161 ~96 jungle_leaves[persistent=true]
setblock ~169 ~161 ~97 oak_leaves[persistent=true]
setblock ~169 ~161 ~98 oak_leaves[persistent=true]
setblock ~169 ~161 ~99 oak_wood
setblock ~169 ~161 ~100 oak_leaves[persistent=true]
setblock ~169 ~161 ~101 oak_leaves[persistent=true]
setblock ~169 ~161 ~102 oak_leaves[persistent=true]
setblock ~169 ~161 ~103 oak_leaves[persistent=true]
setblock ~169 ~161 ~104 oak_leaves[persistent=true]
setblock ~169 ~161 ~105 oak_leaves[persistent=true]
setblock ~169 ~162 ~79 jungle_leaves[persistent=true]
setblock ~169 ~162 ~80 oak_leaves[persistent=true]
setblock ~169 ~162 ~81 oak_leaves[persistent=true]
setblock ~169 ~162 ~82 oak_leaves[persistent=true]
setblock ~169 ~162 ~83 oak_wood
setblock ~169 ~162 ~84 oak_leaves[persistent=true]
setblock ~169 ~162 ~85 oak_wood
setblock ~169 ~162 ~86 oak_leaves[persistent=true]
setblock ~169 ~162 ~87 oak_wood
setblock ~169 ~162 ~88 oak_wood
setblock ~169 ~162 ~89 oak_wood
setblock ~169 ~162 ~90 oak_wood
setblock ~169 ~162 ~91 oak_wood
setblock ~169 ~162 ~92 oak_wood
setblock ~169 ~162 ~93 oak_wood
setblock ~169 ~162 ~94 oak_wood
setblock ~169 ~162 ~95 oak_wood
setblock ~169 ~162 ~96 oak_wood
setblock ~169 ~162 ~97 oak_log
setblock ~169 ~162 ~98 oak_wood
setblock ~169 ~162 ~99 oak_wood
setblock ~169 ~162 ~100 oak_wood
setblock ~169 ~162 ~101 oak_wood
setblock ~169 ~162 ~102 oak_leaves[persistent=true]
setblock ~169 ~162 ~103 oak_leaves[persistent=true]
setblock ~169 ~162 ~105 oak_leaves[persistent=true]
setblock ~169 ~163 ~81 oak_leaves[persistent=true]
setblock ~169 ~163 ~82 oak_leaves[persistent=true]
setblock ~169 ~163 ~83 oak_leaves[persistent=true]
setblock ~169 ~163 ~84 oak_wood
setblock ~169 ~163 ~85 oak_leaves[persistent=true]
setblock ~169 ~163 ~86 oak_leaves[persistent=true]
setblock ~169 ~163 ~87 oak_wood
setblock ~169 ~163 ~88 oak_wood
setblock ~169 ~163 ~89 oak_wood
setblock ~169 ~163 ~90 oak_log
setblock ~169 ~163 ~91 oak_wood
setblock ~169 ~163 ~92 oak_wood
setblock ~169 ~163 ~93 oak_wood
setblock ~169 ~163 ~94 oak_leaves[persistent=true]
setblock ~169 ~163 ~95 oak_wood
setblock ~169 ~163 ~96 oak_wood
setblock ~169 ~163 ~97 oak_wood
setblock ~169 ~163 ~98 oak_wood
setblock ~169 ~163 ~99 oak_wood
setblock ~169 ~163 ~100 oak_wood
setblock ~169 ~163 ~101 oak_wood
setblock ~169 ~163 ~102 oak_wood
setblock ~169 ~163 ~103 oak_wood
setblock ~169 ~163 ~104 oak_leaves[persistent=true]
setblock ~169 ~163 ~105 oak_leaves[persistent=true]
setblock ~169 ~163 ~106 jungle_leaves[persistent=true]
setblock ~169 ~164 ~81 oak_leaves[persistent=true]
setblock ~169 ~164 ~82 oak_leaves[persistent=true]
setblock ~169 ~164 ~83 oak_leaves[persistent=true]
setblock ~169 ~164 ~84 oak_leaves[persistent=true]
setblock ~169 ~164 ~85 oak_leaves[persistent=true]
setblock ~169 ~164 ~86 oak_leaves[persistent=true]
setblock ~169 ~164 ~87 oak_wood
setblock ~169 ~164 ~88 oak_wood
setblock ~169 ~164 ~89 oak_wood
setblock ~169 ~164 ~90 oak_wood
setblock ~169 ~164 ~91 oak_log
setblock ~169 ~164 ~93 oak_wood
setblock ~169 ~164 ~94 oak_wood
setblock ~169 ~164 ~95 oak_wood
setblock ~169 ~164 ~96 oak_wood
setblock ~169 ~164 ~97 oak_leaves[persistent=true]
setblock ~169 ~164 ~98 oak_wood
setblock ~169 ~164 ~99 oak_wood
setblock ~169 ~164 ~100 oak_wood
setblock ~169 ~164 ~101 oak_wood
setblock ~169 ~164 ~102 oak_wood
setblock ~169 ~164 ~103 oak_wood
setblock ~169 ~164 ~104 oak_leaves[persistent=true]
setblock ~169 ~164 ~105 oak_leaves[persistent=true]
setblock ~169 ~164 ~106 oak_leaves[persistent=true]
setblock ~169 ~165 ~80 oak_leaves[persistent=true]
setblock ~169 ~165 ~82 oak_leaves[persistent=true]
setblock ~169 ~165 ~83 oak_leaves[persistent=true]
setblock ~169 ~165 ~84 oak_leaves[persistent=true]
setblock ~169 ~165 ~85 oak_leaves[persistent=true]
setblock ~169 ~165 ~86 oak_wood
setblock ~169 ~165 ~87 oak_wood
setblock ~169 ~165 ~88 oak_wood
setblock ~169 ~165 ~89 oak_leaves[persistent=true]
setblock ~169 ~165 ~90 oak_wood
setblock ~169 ~165 ~91 oak_wood
setblock ~169 ~165 ~92 oak_wood
setblock ~169 ~165 ~93 oak_wood
setblock ~169 ~165 ~94 oak_wood
setblock ~169 ~165 ~95 oak_leaves[persistent=true]
setblock ~169 ~165 ~96 oak_wood
setblock ~169 ~165 ~97 oak_wood
setblock ~169 ~165 ~98 oak_wood
setblock ~169 ~165 ~99 oak_wood
setblock ~169 ~165 ~100 oak_wood
setblock ~169 ~165 ~101 oak_wood
setblock ~169 ~165 ~102 oak_leaves[persistent=true]
setblock ~169 ~165 ~103 oak_wood
setblock ~169 ~165 ~104 oak_leaves[persistent=true]
setblock ~169 ~165 ~105 oak_leaves[persistent=true]
setblock ~169 ~165 ~106 oak_leaves[persistent=true]
setblock ~169 ~166 ~80 oak_leaves[persistent=true]
setblock ~169 ~166 ~81 jungle_leaves[persistent=true]
setblock ~169 ~166 ~82 oak_wood
setblock ~169 ~166 ~83 oak_wood
setblock ~169 ~166 ~84 jungle_leaves[persistent=true]
setblock ~169 ~166 ~85 oak_leaves[persistent=true]
setblock ~169 ~166 ~86 oak_wood
setblock ~169 ~166 ~87 oak_wood
setblock ~169 ~166 ~88 oak_wood
setblock ~169 ~166 ~89 oak_wood
setblock ~169 ~166 ~90 oak_wood
setblock ~169 ~166 ~91 oak_wood
setblock ~169 ~166 ~92 oak_wood
setblock ~169 ~166 ~93 oak_wood
setblock ~169 ~166 ~94 oak_wood
setblock ~169 ~166 ~95 oak_wood
setblock ~169 ~166 ~96 oak_wood
setblock ~169 ~166 ~97 oak_leaves[persistent=true]
setblock ~169 ~166 ~98 oak_wood
setblock ~169 ~166 ~99 oak_wood
setblock ~169 ~166 ~100 oak_wood
setblock ~169 ~166 ~101 oak_wood
setblock ~169 ~166 ~102 oak_log
setblock ~169 ~166 ~103 oak_leaves[persistent=true]
setblock ~169 ~166 ~104 oak_leaves[persistent=true]
setblock ~169 ~166 ~105 oak_leaves[persistent=true]
setblock ~169 ~166 ~106 oak_leaves[persistent=true]
setblock ~169 ~167 ~80 oak_leaves[persistent=true]
setblock ~169 ~167 ~81 jungle_leaves[persistent=true]
setblock ~169 ~167 ~83 oak_wood
setblock ~169 ~167 ~84 oak_wood
setblock ~169 ~167 ~85 oak_leaves[persistent=true]
setblock ~169 ~167 ~86 oak_log
setblock ~169 ~167 ~87 oak_wood
setblock ~169 ~167 ~88 oak_wood
setblock ~169 ~167 ~89 oak_wood
setblock ~169 ~167 ~90 oak_wood
setblock ~169 ~167 ~91 oak_wood
setblock ~169 ~167 ~92 oak_wood
setblock ~169 ~167 ~93 oak_leaves[persistent=true]
setblock ~169 ~167 ~94 oak_wood
setblock ~169 ~167 ~95 jungle_leaves[persistent=true]
setblock ~169 ~167 ~96 oak_wood
setblock ~169 ~167 ~97 oak_wood
setblock ~169 ~167 ~98 oak_wood
setblock ~169 ~167 ~99 oak_log
setblock ~169 ~167 ~100 oak_log
setblock ~169 ~167 ~101 oak_wood
setblock ~169 ~167 ~102 oak_wood
setblock ~169 ~167 ~103 oak_leaves[persistent=true]
setblock ~169 ~167 ~104 oak_leaves[persistent=true]
setblock ~169 ~167 ~105 oak_leaves[persistent=true]
setblock ~169 ~167 ~106 jungle_leaves[persistent=true]
setblock ~169 ~168 ~80 oak_leaves[persistent=true]
setblock ~169 ~168 ~81 jungle_leaves[persistent=true]
setblock ~169 ~168 ~83 oak_leaves[persistent=true]
setblock ~169 ~168 ~84 oak_leaves[persistent=true]
setblock ~169 ~168 ~85 oak_wood
setblock ~169 ~168 ~86 oak_wood
setblock ~169 ~168 ~87 oak_wood
setblock ~169 ~168 ~88 oak_wood
setblock ~169 ~168 ~89 oak_wood
setblock ~169 ~168 ~90 oak_wood
setblock ~169 ~168 ~91 oak_wood
setblock ~169 ~168 ~92 oak_log
setblock ~169 ~168 ~93 jungle_leaves[persistent=true]
setblock ~169 ~168 ~94 oak_log
setblock ~169 ~168 ~95 oak_wood
setblock ~169 ~168 ~96 jungle_leaves[persistent=true]
setblock ~169 ~168 ~97 oak_leaves[persistent=true]
setblock ~169 ~168 ~98 oak_leaves[persistent=true]
setblock ~169 ~168 ~99 oak_leaves[persistent=true]
setblock ~169 ~168 ~100 oak_log
setblock ~169 ~168 ~101 oak_log
setblock ~169 ~168 ~102 oak_wood
setblock ~169 ~168 ~103 oak_wood
setblock ~169 ~168 ~104 oak_wood
setblock ~169 ~168 ~105 oak_leaves[persistent=true]
setblock ~169 ~168 ~106 oak_leaves[persistent=true]
setblock ~169 ~169 ~80 oak_leaves[persistent=true]
setblock ~169 ~169 ~81 jungle_leaves[persistent=true]
setblock ~169 ~169 ~82 oak_leaves[persistent=true]
setblock ~169 ~169 ~83 oak_leaves[persistent=true]
setblock ~169 ~169 ~84 oak_log
setblock ~169 ~169 ~85 oak_leaves[persistent=true]
setblock ~169 ~169 ~86 oak_log
setblock ~169 ~169 ~87 oak_leaves[persistent=true]
setblock ~169 ~169 ~88 jungle_leaves[persistent=true]
setblock ~169 ~169 ~89 oak_leaves[persistent=true]
setblock ~169 ~169 ~90 oak_leaves[persistent=true]
setblock ~169 ~169 ~91 oak_log
setblock ~169 ~169 ~92 jungle_leaves[persistent=true]
setblock ~169 ~169 ~93 oak_log
setblock ~169 ~169 ~94 oak_leaves[persistent=true]
setblock ~169 ~169 ~95 oak_log
setblock ~169 ~169 ~96 oak_log
setblock ~169 ~169 ~97 oak_log
setblock ~169 ~169 ~98 oak_log
setblock ~169 ~169 ~99 oak_log
setblock ~169 ~169 ~100 oak_leaves[persistent=true]
setblock ~169 ~169 ~101 oak_log
setblock ~169 ~169 ~102 jungle_leaves[persistent=true]
setblock ~169 ~169 ~103 oak_leaves[persistent=true]
setblock ~169 ~169 ~104 jungle_leaves[persistent=true]
setblock ~169 ~169 ~105 jungle_leaves[persistent=true]
setblock ~169 ~169 ~106 oak_leaves[persistent=true]
setblock ~169 ~170 ~82 jungle_leaves[persistent=true]
setblock ~169 ~170 ~83 oak_leaves[persistent=true]
setblock ~169 ~170 ~85 oak_leaves[persistent=true]
setblock ~169 ~170 ~86 jungle_leaves[persistent=true]
setblock ~169 ~170 ~87 oak_leaves[persistent=true]
setblock ~169 ~170 ~88 jungle_leaves[persistent=true]
setblock ~169 ~170 ~89 jungle_leaves[persistent=true]
setblock ~169 ~170 ~90 oak_leaves[persistent=true]
setblock ~169 ~170 ~92 oak_leaves[persistent=true]
setblock ~169 ~170 ~93 oak_wood
setblock ~169 ~170 ~94 oak_leaves[persistent=true]
setblock ~169 ~170 ~95 oak_leaves[persistent=true]
setblock ~169 ~170 ~96 oak_leaves[persistent=true]
setblock ~169 ~170 ~97 oak_wood
setblock ~169 ~170 ~99 jungle_leaves[persistent=true]
setblock ~169 ~170 ~100 oak_leaves[persistent=true]
setblock ~169 ~170 ~101 oak_leaves[persistent=true]
setblock ~169 ~170 ~102 jungle_leaves[persistent=true]
setblock ~169 ~170 ~103 jungle_leaves[persistent=true]
setblock ~169 ~170 ~104 oak_leaves[persistent=true]
setblock ~169 ~171 ~82 oak_leaves[persistent=true]
setblock ~169 ~171 ~83 oak_leaves[persistent=true]
setblock ~169 ~171 ~84 oak_leaves[persistent=true]
setblock ~169 ~171 ~85 oak_leaves[persistent=true]
setblock ~169 ~171 ~86 oak_leaves[persistent=true]
setblock ~169 ~171 ~87 jungle_leaves[persistent=true]
setblock ~169 ~171 ~88 oak_leaves[persistent=true]
setblock ~169 ~171 ~89 jungle_leaves[persistent=true]
setblock ~169 ~171 ~90 oak_leaves[persistent=true]
setblock ~169 ~171 ~91 jungle_leaves[persistent=true]
setblock ~169 ~171 ~92 oak_leaves[persistent=true]
setblock ~169 ~171 ~93 oak_leaves[persistent=true]
setblock ~169 ~171 ~94 oak_leaves[persistent=true]
setblock ~169 ~171 ~95 oak_leaves[persistent=true]
setblock ~169 ~171 ~96 jungle_leaves[persistent=true]
setblock ~169 ~171 ~97 oak_leaves[persistent=true]
setblock ~169 ~171 ~98 oak_leaves[persistent=true]
setblock ~169 ~171 ~100 oak_leaves[persistent=true]
setblock ~169 ~171 ~101 jungle_leaves[persistent=true]
setblock ~169 ~171 ~102 oak_leaves[persistent=true]
setblock ~169 ~171 ~103 oak_leaves[persistent=true]
setblock ~170 ~115 ~115 dirt
setblock ~170 ~115 ~118 dirt
setblock ~170 ~116 ~114 dirt
setblock ~170 ~116 ~115 dirt
setblock ~170 ~116 ~116 dirt
setblock ~170 ~116 ~118 dirt
setblock ~170 ~116 ~119 dirt
setblock ~170 ~117 ~114 dirt
setblock ~170 ~117 ~115 dirt
setblock ~170 ~117 ~116 dirt
setblock ~170 ~117 ~117 dirt
setblock ~170 ~117 ~118 dirt
setblock ~170 ~117 ~119 dirt
setblock ~170 ~117 ~120 dirt
setblock ~170 ~117 ~121 dirt
setblock ~170 ~118 ~92 dirt
setblock ~170 ~118 ~113 dirt
setblock ~170 ~118 ~114 dirt
setblock ~170 ~118 ~115 dirt
setblock ~170 ~118 ~116 dirt
setblock ~170 ~118 ~117 dirt
setblock ~170 ~118 ~118 dirt
setblock ~170 ~118 ~119 dirt
setblock ~170 ~118 ~120 dirt
setblock ~170 ~118 ~121 dirt
setblock ~170 ~118 ~122 dirt
setblock ~170 ~119 ~91 dirt
setblock ~170 ~119 ~92 dirt
setblock ~170 ~119 ~94 dirt
setblock ~170 ~119 ~111 dirt
setblock ~170 ~119 ~112 dirt
setblock ~170 ~119 ~113 dirt
setblock ~170 ~119 ~114 dirt
setblock ~170 ~119 ~115 dirt
setblock ~170 ~119 ~116 dirt
setblock ~170 ~119 ~117 dirt
setblock ~170 ~119 ~118 dirt
setblock ~170 ~119 ~119 dirt
setblock ~170 ~119 ~120 dirt
setblock ~170 ~119 ~121 dirt
setblock ~170 ~119 ~122 dirt
setblock ~170 ~120 ~91 dirt
setblock ~170 ~120 ~92 dirt
setblock ~170 ~120 ~94 dirt
setblock ~170 ~120 ~95 dirt
setblock ~170 ~120 ~111 dirt
setblock ~170 ~120 ~112 dirt
setblock ~170 ~120 ~113 dirt
setblock ~170 ~120 ~114 dirt
setblock ~170 ~120 ~115 dirt
setblock ~170 ~120 ~116 dirt
setblock ~170 ~120 ~117 dirt
setblock ~170 ~120 ~118 dirt
setblock ~170 ~120 ~119 dirt
setblock ~170 ~120 ~120 dirt
setblock ~170 ~120 ~121 dirt
setblock ~170 ~120 ~122 dirt
setblock ~170 ~120 ~123 dirt
setblock ~170 ~121 ~90 dirt
setblock ~170 ~121 ~91 dirt
setblock ~170 ~121 ~92 dirt
setblock ~170 ~121 ~94 dirt
setblock ~170 ~121 ~95 dirt
setblock ~170 ~121 ~100 dirt
setblock ~170 ~121 ~110 dirt
setblock ~170 ~121 ~111 dirt
setblock ~170 ~121 ~112 dirt
setblock ~170 ~121 ~113 dirt
setblock ~170 ~121 ~114 dirt
setblock ~170 ~121 ~115 dirt
setblock ~170 ~121 ~116 dirt
setblock ~170 ~121 ~117 dirt
setblock ~170 ~121 ~118 dirt
setblock ~170 ~121 ~119 dirt
setblock ~170 ~121 ~120 dirt
setblock ~170 ~121 ~121 dirt
setblock ~170 ~121 ~122 dirt
setblock ~170 ~121 ~123 dirt
setblock ~170 ~121 ~124 dirt
setblock ~170 ~122 ~90 dirt
setblock ~170 ~122 ~91 dirt
setblock ~170 ~122 ~92 dirt
setblock ~170 ~122 ~94 dirt
setblock ~170 ~122 ~95 dirt
setblock ~170 ~122 ~100 dirt
setblock ~170 ~122 ~110 dirt
setblock ~170 ~122 ~111 dirt
setblock ~170 ~122 ~112 dirt
setblock ~170 ~122 ~113 dirt
setblock ~170 ~122 ~114 dirt
setblock ~170 ~122 ~115 dirt
setblock ~170 ~122 ~116 dirt
setblock ~170 ~122 ~117 dirt
setblock ~170 ~122 ~118 dirt
setblock ~170 ~122 ~119 dirt
setblock ~170 ~122 ~120 dirt
setblock ~170 ~122 ~121 dirt
setblock ~170 ~122 ~122 dirt
setblock ~170 ~122 ~123 dirt
setblock ~170 ~122 ~124 dirt
setblock ~170 ~123 ~90 dirt
setblock ~170 ~123 ~91 dirt
setblock ~170 ~123 ~92 dirt
setblock ~170 ~123 ~94 dirt
setblock ~170 ~123 ~95 dirt
setblock ~170 ~123 ~100 dirt
setblock ~170 ~123 ~110 dirt
setblock ~170 ~123 ~111 dirt
setblock ~170 ~123 ~112 dirt
setblock ~170 ~123 ~113 dirt
setblock ~170 ~123 ~114 dirt
setblock ~170 ~123 ~115 dirt
setblock ~170 ~123 ~116 dirt
setblock ~170 ~123 ~117 dirt
setblock ~170 ~123 ~118 dirt
setblock ~170 ~123 ~119 dirt
setblock ~170 ~123 ~120 dirt
setblock ~170 ~123 ~121 dirt
setblock ~170 ~123 ~122 dirt
setblock ~170 ~123 ~123 dirt
setblock ~170 ~123 ~124 dirt
setblock ~170 ~124 ~90 dirt
setblock ~170 ~124 ~91 dirt
setblock ~170 ~124 ~92 dirt
setblock ~170 ~124 ~94 dirt
setblock ~170 ~124 ~95 dirt
setblock ~170 ~124 ~100 grass_block
setblock ~170 ~124 ~110 dirt
setblock ~170 ~124 ~111 dirt
setblock ~170 ~124 ~112 dirt
setblock ~170 ~124 ~113 dirt
setblock ~170 ~124 ~114 dirt
setblock ~170 ~124 ~115 dirt
setblock ~170 ~124 ~116 dirt
setblock ~170 ~124 ~117 dirt
setblock ~170 ~124 ~118 grass_block
setblock ~170 ~124 ~119 grass_block
setblock ~170 ~124 ~120 grass_block
setblock ~170 ~124 ~121 grass_block
setblock ~170 ~124 ~122 dirt
setblock ~170 ~124 ~123 dirt
setblock ~170 ~124 ~124 dirt
setblock ~170 ~125 ~90 dirt
setblock ~170 ~125 ~91 dirt
setblock ~170 ~125 ~92 dirt
setblock ~170 ~125 ~94 dirt
setblock ~170 ~125 ~95 dirt
setblock ~170 ~125 ~110 dirt
setblock ~170 ~125 ~111 dirt
setblock ~170 ~125 ~112 dirt
setblock ~170 ~125 ~113 dirt
setblock ~170 ~125 ~114 grass_block
setblock ~170 ~125 ~115 grass_block
setblock ~170 ~125 ~116 grass_block
setblock ~170 ~125 ~117 grass_block
setblock ~170 ~125 ~119 short_grass
setblock ~170 ~125 ~121 short_grass
setblock ~170 ~125 ~122 grass_block
setblock ~170 ~125 ~123 grass_block
setblock ~170 ~125 ~124 grass_block
setblock ~170 ~126 ~90 dirt
setblock ~170 ~126 ~91 dirt
setblock ~170 ~126 ~92 dirt
setblock ~170 ~126 ~94 dirt
setblock ~170 ~126 ~95 dirt
setblock ~170 ~126 ~110 grass_block
setblock ~170 ~126 ~111 grass_block
setblock ~170 ~126 ~112 grass_block
setblock ~170 ~126 ~113 grass_block
setblock ~170 ~127 ~90 dirt
setblock ~170 ~127 ~91 dirt
setblock ~170 ~127 ~92 dirt
setblock ~170 ~127 ~94 grass_block
setblock ~170 ~127 ~95 grass_block
setblock ~170 ~128 ~90 dirt
setblock ~170 ~128 ~91 dirt
setblock ~170 ~128 ~92 grass_block
setblock ~170 ~129 ~90 grass_block
setblock ~170 ~129 ~91 grass_block
setblock ~170 ~130 ~91 short_grass
setblock ~170 ~137 ~96 jungle_leaves[persistent=true]
setblock ~170 ~137 ~97 oak_leaves[persistent=true]
setblock ~170 ~137 ~98 oak_leaves[persistent=true]
setblock ~170 ~138 ~89 oak_leaves[persistent=true]
setblock ~170 ~138 ~90 oak_leaves[persistent=true]
setblock ~170 ~138 ~91 oak_leaves[persistent=true]
setblock ~170 ~138 ~92 oak_leaves[persistent=true]
setblock ~170 ~138 ~95 jungle_leaves[persistent=true]
setblock ~170 ~138 ~96 oak_leaves[persistent=true]
setblock ~170 ~138 ~97 oak_leaves[persistent=true]
setblock ~170 ~138 ~98 jungle_leaves[persistent=true]
setblock ~170 ~139 ~88 oak_leaves[persistent=true]
setblock ~170 ~139 ~89 oak_leaves[persistent=true]
setblock ~170 ~139 ~90 oak_leaves[persistent=true]
setblock ~170 ~139 ~91 oak_leaves[persistent=true]
setblock ~170 ~139 ~92 oak_leaves[persistent=true]
setblock ~170 ~139 ~93 jungle_leaves[persistent=true]
setblock ~170 ~139 ~94 oak_leaves[persistent=true]
setblock ~170 ~139 ~95 oak_leaves[persistent=true]
setblock ~170 ~139 ~96 jungle_leaves[persistent=true]
setblock ~170 ~139 ~97 oak_leaves[persistent=true]
setblock ~170 ~140 ~88 oak_leaves[persistent=true]
setblock ~170 ~140 ~89 oak_leaves[persistent=true]
setblock ~170 ~140 ~91 oak_wood
setblock ~170 ~140 ~92 jungle_leaves[persistent=true]
setblock ~170 ~140 ~93 oak_leaves[persistent=true]
setblock ~170 ~140 ~94 oak_leaves[persistent=true]
setblock ~170 ~140 ~95 oak_wood
setblock ~170 ~140 ~96 oak_leaves[persistent=true]
setblock ~170 ~140 ~98 jungle_leaves[persistent=true]
setblock ~170 ~141 ~88 oak_leaves[persistent=true]
setblock ~170 ~141 ~90 oak_wood
setblock ~170 ~141 ~91 oak_leaves[persistent=true]
setblock ~170 ~141 ~92 jungle_leaves[persistent=true]
setblock ~170 ~141 ~93 oak_leaves[persistent=true]
setblock ~170 ~141 ~94 oak_leaves[persistent=true]
setblock ~170 ~141 ~95 oak_leaves[persistent=true]
setblock ~170 ~141 ~96 oak_leaves[persistent=true]
setblock ~170 ~141 ~97 oak_leaves[persistent=true]
setblock ~170 ~141 ~98 oak_leaves[persistent=true]
setblock ~170 ~141 ~100 oak_leaves[persistent=true]
setblock ~170 ~142 ~88 jungle_leaves[persistent=true]
setblock ~170 ~142 ~89 oak_leaves[persistent=true]
setblock ~170 ~142 ~90 jungle_leaves[persistent=true]
setblock ~170 ~142 ~91 oak_leaves[persistent=true]
setblock ~170 ~142 ~92 oak_leaves[persistent=true]
setblock ~170 ~142 ~93 oak_leaves[persistent=true]
setblock ~170 ~142 ~94 oak_leaves[persistent=true]
setblock ~170 ~142 ~95 oak_leaves[persistent=true]
setblock ~170 ~142 ~96 oak_wood
setblock ~170 ~142 ~99 oak_leaves[persistent=true]
setblock ~170 ~142 ~100 oak_leaves[persistent=true]
setblock ~170 ~143 ~88 jungle_leaves[persistent=true]
setblock ~170 ~143 ~89 oak_leaves[persistent=true]
setblock ~170 ~143 ~90 jungle_leaves[persistent=true]
setblock ~170 ~143 ~92 oak_leaves[persistent=true]
setblock ~170 ~143 ~93 oak_leaves[persistent=true]
setblock ~170 ~143 ~94 oak_leaves[persistent=true]
setblock ~170 ~143 ~95 oak_leaves[persistent=true]
setblock ~170 ~143 ~96 oak_leaves[persistent=true]
setblock ~170 ~143 ~97 oak_wood
setblock ~170 ~143 ~98 oak_leaves[persistent=true]
setblock ~170 ~143 ~99 oak_leaves[persistent=true]
setblock ~170 ~143 ~100 jungle_leaves[persistent=true]
setblock ~170 ~144 ~86 jungle_leaves[persistent=true]
setblock ~170 ~144 ~87 oak_leaves[persistent=true]
setblock ~170 ~144 ~89 jungle_leaves[persistent=true]
setblock ~170 ~144 ~91 jungle_leaves[persistent=true]
setblock ~170 ~144 ~92 oak_leaves[persistent=true]
setblock ~170 ~144 ~93 oak_leaves[persistent=true]
setblock ~170 ~144 ~94 oak_leaves[persistent=true]
setblock ~170 ~144 ~95 oak_leaves[persistent=true]
setblock ~170 ~144 ~97 oak_leaves[persistent=true]
setblock ~170 ~144 ~98 oak_leaves[persistent=true]
setblock ~170 ~144 ~99 oak_leaves[persistent=true]
setblock ~170 ~144 ~100 oak_leaves[persistent=true]
setblock ~170 ~145 ~86 jungle_leaves[persistent=true]
setblock ~170 ~145 ~87 oak_leaves[persistent=true]
setblock ~170 ~145 ~88 oak_leaves[persistent=true]
setblock ~170 ~145 ~89 oak_leaves[persistent=true]
setblock ~170 ~145 ~90 oak_wood
setblock ~170 ~145 ~91 oak_leaves[persistent=true]
setblock ~170 ~145 ~93 oak_leaves[persistent=true]
setblock ~170 ~145 ~95 oak_leaves[persistent=true]
setblock ~170 ~145 ~96 oak_leaves[persistent=true]
setblock ~170 ~145 ~97 oak_leaves[persistent=true]
setblock ~170 ~145 ~98 oak_leaves[persistent=true]
setblock ~170 ~145 ~99 oak_leaves[persistent=true]
setblock ~170 ~145 ~100 oak_leaves[persistent=true]
setblock ~170 ~145 ~101 oak_leaves[persistent=true]
setblock ~170 ~146 ~86 jungle_leaves[persistent=true]
setblock ~170 ~146 ~87 oak_leaves[persistent=true]
setblock ~170 ~146 ~88 oak_leaves[persistent=true]
setblock ~170 ~146 ~90 oak_leaves[persistent=true]
setblock ~170 ~146 ~91 oak_leaves[persistent=true]
setblock ~170 ~146 ~92 oak_leaves[persistent=true]
setblock ~170 ~146 ~93 oak_leaves[persistent=true]
setblock ~170 ~146 ~94 jungle_leaves[persistent=true]
setblock ~170 ~146 ~95 oak_leaves[persistent=true]
setblock ~170 ~146 ~96 jungle_leaves[persistent=true]
setblock ~170 ~146 ~97 oak_leaves[persistent=true]
setblock ~170 ~146 ~99 oak_leaves[persistent=true]
setblock ~170 ~146 ~100 oak_leaves[persistent=true]
setblock ~170 ~146 ~101 jungle_leaves[persistent=true]
setblock ~170 ~147 ~87 oak_leaves[persistent=true]
setblock ~170 ~147 ~88 oak_leaves[persistent=true]
setblock ~170 ~147 ~89 oak_leaves[persistent=true]
setblock ~170 ~147 ~90 oak_leaves[persistent=true]
setblock ~170 ~147 ~91 oak_wood
setblock ~170 ~147 ~92 oak_leaves[persistent=true]
setblock ~170 ~147 ~93 jungle_leaves[persistent=true]
setblock ~170 ~147 ~94 oak_leaves[persistent=true]
setblock ~170 ~147 ~95 oak_leaves[persistent=true]
setblock ~170 ~147 ~96 oak_leaves[persistent=true]
setblock ~170 ~147 ~97 oak_leaves[persistent=true]
setblock ~170 ~147 ~98 oak_leaves[persistent=true]
setblock ~170 ~147 ~99 jungle_leaves[persistent=true]
setblock ~170 ~147 ~100 jungle_leaves[persistent=true]
setblock ~170 ~147 ~101 jungle_leaves[persistent=true]
setblock ~170 ~148 ~85 oak_leaves[persistent=true]
setblock ~170 ~148 ~87 oak_leaves[persistent=true]
setblock ~170 ~148 ~88 oak_leaves[persistent=true]
setblock ~170 ~148 ~90 jungle_leaves[persistent=true]
setblock ~170 ~148 ~91 oak_leaves[persistent=true]
setblock ~170 ~148 ~92 oak_leaves[persistent=true]
setblock ~170 ~148 ~93 oak_wood
setblock ~170 ~148 ~94 oak_leaves[persistent=true]
setblock ~170 ~148 ~95 oak_log
setblock ~170 ~148 ~96 oak_leaves[persistent=true]
setblock ~170 ~148 ~97 oak_leaves[persistent=true]
setblock ~170 ~148 ~98 oak_leaves[persistent=true]
setblock ~170 ~148 ~99 oak_leaves[persistent=true]
setblock ~170 ~148 ~100 oak_leaves[persistent=true]
setblock ~170 ~148 ~101 oak_leaves[persistent=true]
setblock ~170 ~149 ~86 jungle_leaves[persistent=true]
setblock ~170 ~149 ~87 oak_leaves[persistent=true]
setblock ~170 ~149 ~88 oak_leaves[persistent=true]
setblock ~170 ~149 ~89 jungle_leaves[persistent=true]
setblock ~170 ~149 ~90 oak_leaves[persistent=true]
setblock ~170 ~149 ~91 oak_leaves[persistent=true]
setblock ~170 ~149 ~92 oak_leaves[persistent=true]
setblock ~170 ~149 ~93 oak_wood
setblock ~170 ~149 ~94 oak_wood
setblock ~170 ~149 ~96 oak_wood
setblock ~170 ~149 ~97 oak_leaves[persistent=true]
setblock ~170 ~149 ~98 jungle_leaves[persistent=true]
setblock ~170 ~149 ~99 oak_leaves[persistent=true]
setblock ~170 ~149 ~100 oak_leaves[persistent=true]
setblock ~170 ~150 ~85 oak_leaves[persistent=true]
setblock ~170 ~150 ~86 jungle_leaves[persistent=true]
setblock ~170 ~150 ~87 oak_leaves[persistent=true]
setblock ~170 ~150 ~88 oak_leaves[persistent=true]
setblock ~170 ~150 ~89 oak_leaves[persistent=true]
setblock ~170 ~150 ~90 oak_leaves[persistent=true]
setblock ~170 ~150 ~92 oak_leaves[persistent=true]
setblock ~170 ~150 ~93 oak_wood
setblock ~170 ~150 ~94 oak_leaves[persistent=true]
setblock ~170 ~150 ~95 oak_leaves[persistent=true]
setblock ~170 ~150 ~96 oak_wood
setblock ~170 ~150 ~97 oak_wood
setblock ~170 ~150 ~98 oak_wood
setblock ~170 ~150 ~99 oak_leaves[persistent=true]
setblock ~170 ~150 ~100 oak_leaves[persistent=true]
setblock ~170 ~151 ~84 oak_leaves[persistent=true]
setblock ~170 ~151 ~85 oak_leaves[persistent=true]
setblock ~170 ~151 ~86 oak_leaves[persistent=true]
setblock ~170 ~151 ~87 oak_leaves[persistent=true]
setblock ~170 ~151 ~88 oak_leaves[persistent=true]
setblock ~170 ~151 ~89 oak_leaves[persistent=true]
setblock ~170 ~151 ~90 oak_leaves[persistent=true]
setblock ~170 ~151 ~91 jungle_leaves[persistent=true]
setblock ~170 ~151 ~92 oak_wood
setblock ~170 ~151 ~93 oak_wood
setblock ~170 ~151 ~94 oak_wood
setblock ~170 ~151 ~95 oak_wood
setblock ~170 ~151 ~96 oak_wood
setblock ~170 ~151 ~97 jungle_leaves[persistent=true]
setblock ~170 ~151 ~98 oak_leaves[persistent=true]
setblock ~170 ~151 ~99 oak_leaves[persistent=true]
setblock ~170 ~151 ~100 oak_leaves[persistent=true]
setblock ~170 ~152 ~85 oak_leaves[persistent=true]
setblock ~170 ~152 ~86 oak_leaves[persistent=true]
setblock ~170 ~152 ~87 oak_leaves[persistent=true]
setblock ~170 ~152 ~88 oak_leaves[persistent=true]
setblock ~170 ~152 ~89 oak_wood
setblock ~170 ~152 ~90 oak_leaves[persistent=true]
setblock ~170 ~152 ~91 oak_leaves[persistent=true]
setblock ~170 ~152 ~92 oak_leaves[persistent=true]
setblock ~170 ~152 ~93 oak_wood
setblock ~170 ~152 ~94 jungle_leaves[persistent=true]
setblock ~170 ~152 ~96 oak_wood
setblock ~170 ~152 ~97 oak_wood
setblock ~170 ~152 ~98 oak_leaves[persistent=true]
setblock ~170 ~152 ~99 oak_leaves[persistent=true]
setblock ~170 ~153 ~83 oak_leaves[persistent=true]
setblock ~170 ~153 ~84 oak_leaves[persistent=true]
setblock ~170 ~153 ~85 oak_leaves[persistent=true]
setblock ~170 ~153 ~86 oak_leaves[persistent=true]
setblock ~170 ~153 ~87 oak_leaves[persistent=true]
setblock ~170 ~153 ~88 oak_wood
setblock ~170 ~153 ~89 oak_wood
setblock ~170 ~153 ~90 oak_wood
setblock ~170 ~153 ~91 oak_leaves[persistent=true]
setblock ~170 ~153 ~92 oak_wood
setblock ~170 ~153 ~93 oak_wood
setblock ~170 ~153 ~94 oak_wood
setblock ~170 ~153 ~95 oak_wood
setblock ~170 ~153 ~96 oak_leaves[persistent=true]
setblock ~170 ~153 ~97 oak_leaves[persistent=true]
setblock ~170 ~153 ~99 oak_wood
setblock ~170 ~153 ~100 oak_leaves[persistent=true]
setblock ~170 ~154 ~82 oak_leaves[persistent=true]
setblock ~170 ~154 ~84 oak_leaves[persistent=true]
setblock ~170 ~154 ~85 oak_leaves[persistent=true]
setblock ~170 ~154 ~86 oak_leaves[persistent=true]
setblock ~170 ~154 ~87 oak_leaves[persistent=true]
setblock ~170 ~154 ~88 oak_leaves[persistent=true]
setblock ~170 ~154 ~89 oak_wood
setblock ~170 ~154 ~90 oak_leaves[persistent=true]
setblock ~170 ~154 ~91 oak_leaves[persistent=true]
setblock ~170 ~154 ~92 oak_wood
setblock ~170 ~154 ~93 oak_wood
setblock ~170 ~154 ~94 oak_wood
setblock ~170 ~154 ~95 oak_leaves[persistent=true]
setblock ~170 ~154 ~96 oak_wood
setblock ~170 ~154 ~97 oak_wood
setblock ~170 ~154 ~98 oak_wood
setblock ~170 ~154 ~99 oak_leaves[persistent=true]
setblock ~170 ~154 ~100 jungle_leaves[persistent=true]
setblock ~170 ~155 ~82 oak_leaves[persistent=true]
setblock ~170 ~155 ~83 jungle_leaves[persistent=true]
setblock ~170 ~155 ~84 oak_leaves[persistent=true]
setblock ~170 ~155 ~85 oak_leaves[persistent=true]
setblock ~170 ~155 ~86 oak_leaves[persistent=true]
setblock ~170 ~155 ~87 oak_wood
setblock ~170 ~155 ~88 oak_leaves[persistent=true]
setblock ~170 ~155 ~89 oak_wood
setblock ~170 ~155 ~90 oak_wood
setblock ~170 ~155 ~91 oak_wood
setblock ~170 ~155 ~92 oak_wood
setblock ~170 ~155 ~93 oak_wood
setblock ~170 ~155 ~94 jungle_leaves[persistent=true]
setblock ~170 ~155 ~95 oak_wood
setblock ~170 ~155 ~96 oak_leaves[persistent=true]
setblock ~170 ~155 ~97 oak_wood
setblock ~170 ~155 ~98 oak_leaves[persistent=true]
setblock ~170 ~155 ~99 oak_leaves[persistent=true]
setblock ~170 ~155 ~100 oak_leaves[persistent=true]
setblock ~170 ~155 ~101 oak_leaves[persistent=true]
setblock ~170 ~156 ~82 oak_leaves[persistent=true]
setblock ~170 ~156 ~83 oak_leaves[persistent=true]
setblock ~170 ~156 ~84 oak_leaves[persistent=true]
setblock ~170 ~156 ~85 oak_leaves[persistent=true]
setblock ~170 ~156 ~86 jungle_leaves[persistent=true]
setblock ~170 ~156 ~87 oak_wood
setblock ~170 ~156 ~89 oak_wood
setblock ~170 ~156 ~90 oak_log
setblock ~170 ~156 ~91 oak_leaves[persistent=true]
setblock ~170 ~156 ~92 oak_wood
setblock ~170 ~156 ~93 oak_wood
setblock ~170 ~156 ~94 oak_wood
setblock ~170 ~156 ~95 jungle_leaves[persistent=true]
setblock ~170 ~156 ~96 oak_leaves[persistent=true]
setblock ~170 ~156 ~97 oak_log
setblock ~170 ~156 ~98 oak_wood
setblock ~170 ~156 ~99 oak_leaves[persistent=true]
setblock ~170 ~156 ~100 jungle_leaves[persistent=true]
setblock ~170 ~156 ~101 oak_leaves[persistent=true]
setblock ~170 ~156 ~102 oak_leaves[persistent=true]
setblock ~170 ~156 ~103 oak_leaves[persistent=true]
setblock ~170 ~157 ~82 oak_leaves[persistent=true]
setblock ~170 ~157 ~83 oak_leaves[persistent=true]
setblock ~170 ~157 ~84 oak_leaves[persistent=true]
setblock ~170 ~157 ~85 oak_leaves[persistent=true]
setblock ~170 ~157 ~86 jungle_leaves[persistent=true]
setblock ~170 ~157 ~87 oak_leaves[persistent=true]
setblock ~170 ~157 ~88 oak_leaves[persistent=true]
setblock ~170 ~157 ~89 oak_leaves[persistent=true]
setblock ~170 ~157 ~90 oak_leaves[persistent=true]
setblock ~170 ~157 ~91 oak_wood
setblock ~170 ~157 ~92 oak_leaves[persistent=true]
setblock ~170 ~157 ~93 oak_wood
setblock ~170 ~157 ~94 oak_leaves[persistent=true]
setblock ~170 ~157 ~95 oak_log
setblock ~170 ~157 ~96 oak_wood
setblock ~170 ~157 ~97 oak_wood
setblock ~170 ~157 ~98 oak_wood
setblock ~170 ~157 ~99 oak_leaves[persistent=true]
setblock ~170 ~157 ~100 oak_leaves[persistent=true]
setblock ~170 ~157 ~101 jungle_leaves[persistent=true]
setblock ~170 ~157 ~102 oak_leaves[persistent=true]
setblock ~170 ~157 ~103 oak_leaves[persistent=true]
setblock ~170 ~158 ~82 oak_leaves[persistent=true]
setblock ~170 ~158 ~83 jungle_leaves[persistent=true]
setblock ~170 ~158 ~84 oak_wood
setblock ~170 ~158 ~85 oak_leaves[persistent=true]
setblock ~170 ~158 ~86 oak_leaves[persistent=true]
setblock ~170 ~158 ~87 oak_leaves[persistent=true]
setblock ~170 ~158 ~88 oak_leaves[persistent=true]
setblock ~170 ~158 ~89 oak_wood
setblock ~170 ~158 ~90 oak_wood
setblock ~170 ~158 ~91 oak_wood
setblock ~170 ~158 ~92 oak_wood
setblock ~170 ~158 ~93 oak_wood
setblock ~170 ~158 ~94 oak_wood
setblock ~170 ~158 ~95 oak_log
setblock ~170 ~158 ~96 oak_wood
setblock ~170 ~158 ~97 oak_leaves[persistent=true]
setblock ~170 ~158 ~98 oak_wood
setblock ~170 ~158 ~99 oak_wood
setblock ~170 ~158 ~100 oak_leaves[persistent=true]
setblock ~170 ~158 ~101 oak_leaves[persistent=true]
setblock ~170 ~158 ~102 oak_leaves[persistent=true]
setblock ~170 ~158 ~103 oak_leaves[persistent=true]
setblock ~170 ~159 ~80 oak_leaves[persistent=true]
setblock ~170 ~159 ~81 jungle_leaves[persistent=true]
setblock ~170 ~159 ~82 oak_leaves[persistent=true]
setblock ~170 ~159 ~83 oak_leaves[persistent=true]
setblock ~170 ~159 ~84 jungle_leaves[persistent=true]
setblock ~170 ~159 ~85 oak_leaves[persistent=true]
setblock ~170 ~159 ~86 jungle_leaves[persistent=true]
setblock ~170 ~159 ~87 oak_wood
setblock ~170 ~159 ~88 oak_wood
setblock ~170 ~159 ~89 oak_wood
setblock ~170 ~159 ~90 oak_wood
setblock ~170 ~159 ~91 oak_wood
setblock ~170 ~159 ~92 oak_wood
setblock ~170 ~159 ~93 oak_wood
setblock ~170 ~159 ~94 oak_log
setblock ~170 ~159 ~95 oak_log
setblock ~170 ~159 ~96 oak_leaves[persistent=true]
setblock ~170 ~159 ~97 jungle_leaves[persistent=true]
setblock ~170 ~159 ~98 oak_log
setblock ~170 ~159 ~99 oak_wood
setblock ~170 ~159 ~100 jungle_leaves[persistent=true]
setblock ~170 ~159 ~101 oak_leaves[persistent=true]
setblock ~170 ~159 ~102 oak_leaves[persistent=true]
setblock ~170 ~159 ~103 oak_leaves[persistent=true]
setblock ~170 ~159 ~104 oak_leaves[persistent=true]
setblock ~170 ~159 ~105 oak_leaves[persistent=true]
setblock ~170 ~160 ~79 oak_leaves[persistent=true]
setblock ~170 ~160 ~80 oak_leaves[persistent=true]
setblock ~170 ~160 ~81 jungle_leaves[persistent=true]
setblock ~170 ~160 ~82 oak_leaves[persistent=true]
setblock ~170 ~160 ~83 jungle_leaves[persistent=true]
setblock ~170 ~160 ~84 oak_leaves[persistent=true]
setblock ~170 ~160 ~85 jungle_leaves[persistent=true]
setblock ~170 ~160 ~86 oak_wood
setblock ~170 ~160 ~87 jungle_leaves[persistent=true]
setblock ~170 ~160 ~88 oak_wood
setblock ~170 ~160 ~89 oak_wood
setblock ~170 ~160 ~90 oak_wood
setblock ~170 ~160 ~91 oak_wood
setblock ~170 ~160 ~92 oak_log
setblock ~170 ~160 ~93 oak_wood
setblock ~170 ~160 ~94 oak_log
setblock ~170 ~160 ~95 oak_wood
setblock ~170 ~160 ~97 oak_leaves[persistent=true]
setblock ~170 ~160 ~98 oak_wood
setblock ~170 ~160 ~99 oak_wood
setblock ~170 ~160 ~100 oak_leaves[persistent=true]
setblock ~170 ~160 ~101 oak_leaves[persistent=true]
setblock ~170 ~160 ~102 oak_leaves[persistent=true]
setblock ~170 ~160 ~104 oak_leaves[persistent=true]
setblock ~170 ~160 ~105 oak_leaves[persistent=true]
setblock ~170 ~161 ~79 jungle_leaves[persistent=true]
setblock ~170 ~161 ~80 oak_leaves[persistent=true]
setblock ~170 ~161 ~81 oak_leaves[persistent=true]
setblock ~170 ~161 ~82 jungle_leaves[persistent=true]
setblock ~170 ~161 ~83 jungle_leaves[persistent=true]
setblock ~170 ~161 ~84 oak_leaves[persistent=true]
setblock ~170 ~161 ~86 oak_leaves[persistent=true]
setblock ~170 ~161 ~87 oak_wood
setblock ~170 ~161 ~88 oak_wood
setblock ~170 ~161 ~89 oak_wood
setblock ~170 ~161 ~90 oak_wood
setblock ~170 ~161 ~91 oak_wood
setblock ~170 ~161 ~92 oak_wood
setblock ~170 ~161 ~94 oak_wood
setblock ~170 ~161 ~95 jungle_leaves[persistent=true]
setblock ~170 ~161 ~96 oak_wood
setblock ~170 ~161 ~97 oak_log
setblock ~170 ~161 ~98 oak_wood
setblock ~170 ~161 ~99 oak_wood
setblock ~170 ~161 ~100 oak_leaves[persistent=true]
setblock ~170 ~161 ~101 jungle_leaves[persistent=true]
setblock ~170 ~161 ~102 oak_leaves[persistent=true]
setblock ~170 ~161 ~103 oak_wood
setblock ~170 ~161 ~105 jungle_leaves[persistent=true]
setblock ~170 ~162 ~79 oak_leaves[persistent=true]
setblock ~170 ~162 ~80 oak_leaves[persistent=true]
setblock ~170 ~162 ~81 jungle_leaves[persistent=true]
setblock ~170 ~162 ~82 oak_leaves[persistent=true]
setblock ~170 ~162 ~84 oak_wood
setblock ~170 ~162 ~85 oak_leaves[persistent=true]
setblock ~170 ~162 ~86 oak_wood
setblock ~170 ~162 ~87 oak_wood
setblock ~170 ~162 ~88 oak_wood
setblock ~170 ~162 ~89 oak_leaves[persistent=true]
setblock ~170 ~162 ~90 oak_wood
setblock ~170 ~162 ~91 oak_wood
setblock ~170 ~162 ~92 oak_wood
setblock ~170 ~162 ~93 oak_wood
setblock ~170 ~162 ~94 oak_wood
setblock ~170 ~162 ~95 oak_wood
setblock ~170 ~162 ~96 jungle_leaves[persistent=true]
setblock ~170 ~162 ~97 oak_leaves[persistent=true]
setblock ~170 ~162 ~98 oak_wood
setblock ~170 ~162 ~99 oak_wood
setblock ~170 ~162 ~100 oak_wood
setblock ~170 ~162 ~101 oak_leaves[persistent=true]
setblock ~170 ~162 ~102 oak_wood
setblock ~170 ~162 ~103 oak_leaves[persistent=true]
setblock ~170 ~162 ~104 oak_leaves[persistent=true]
setblock ~170 ~162 ~105 oak_leaves[persistent=true]
setblock ~170 ~163 ~82 oak_leaves[persistent=true]
setblock ~170 ~163 ~83 oak_leaves[persistent=true]
setblock ~170 ~163 ~84 oak_leaves[persistent=true]
setblock ~170 ~163 ~85 oak_wood
setblock ~170 ~163 ~86 oak_wood
setblock ~170 ~163 ~87 oak_wood
setblock ~170 ~163 ~88 oak_wood
setblock ~170 ~163 ~89 oak_wood
setblock ~170 ~163 ~90 oak_leaves[persistent=true]
setblock ~170 ~163 ~91 oak_wood
setblock ~170 ~163 ~92 oak_leaves[persistent=true]
setblock ~170 ~163 ~93 oak_wood
setblock ~170 ~163 ~94 oak_log
setblock ~170 ~163 ~95 oak_wood
setblock ~170 ~163 ~96 oak_wood
setblock ~170 ~163 ~97 oak_wood
setblock ~170 ~163 ~98 oak_wood
setblock ~170 ~163 ~99 oak_wood
setblock ~170 ~163 ~100 oak_wood
setblock ~170 ~163 ~101 oak_leaves[persistent=true]
setblock ~170 ~163 ~102 oak_wood
setblock ~170 ~163 ~103 oak_leaves[persistent=true]
setblock ~170 ~163 ~104 oak_leaves[persistent=true]
setblock ~170 ~163 ~105 oak_leaves[persistent=true]
setblock ~170 ~163 ~106 jungle_leaves[persistent=true]
setblock ~170 ~164 ~81 oak_leaves[persistent=true]
setblock ~170 ~164 ~83 oak_wood
setblock ~170 ~164 ~84 jungle_leaves[persistent=true]
setblock ~170 ~164 ~85 oak_wood
setblock ~170 ~164 ~86 oak_wood
setblock ~170 ~164 ~87 oak_leaves[persistent=true]
setblock ~170 ~164 ~88 oak_wood
setblock ~170 ~164 ~89 oak_wood
setblock ~170 ~164 ~90 oak_wood
setblock ~170 ~164 ~91 oak_wood
setblock ~170 ~164 ~92 jungle_leaves[persistent=true]
setblock ~170 ~164 ~93 oak_wood
setblock ~170 ~164 ~94 jungle_leaves[persistent=true]
setblock ~170 ~164 ~95 oak_wood
setblock ~170 ~164 ~96 oak_wood
setblock ~170 ~164 ~97 oak_wood
setblock ~170 ~164 ~98 oak_wood
setblock ~170 ~164 ~99 oak_log
setblock ~170 ~164 ~100 oak_wood
setblock ~170 ~164 ~102 oak_leaves[persistent=true]
setblock ~170 ~164 ~103 oak_leaves[persistent=true]
setblock ~170 ~164 ~104 oak_leaves[persistent=true]
setblock ~170 ~164 ~105 jungle_leaves[persistent=true]
setblock ~170 ~164 ~106 oak_leaves[persistent=true]
setblock ~170 ~165 ~80 jungle_leaves[persistent=true]
setblock ~170 ~165 ~82 oak_leaves[persistent=true]
setblock ~170 ~165 ~83 oak_leaves[persistent=true]
setblock ~170 ~165 ~84 oak_leaves[persistent=true]
setblock ~170 ~165 ~85 jungle_leaves[persistent=true]
setblock ~170 ~165 ~86 oak_wood
setblock ~170 ~165 ~87 oak_leaves[persistent=true]
setblock ~170 ~165 ~88 oak_wood
setblock ~170 ~165 ~89 oak_log
setblock ~170 ~165 ~90 oak_wood
setblock ~170 ~165 ~91 oak_leaves[persistent=true]
setblock ~170 ~165 ~92 oak_wood
setblock ~170 ~165 ~93 oak_wood
setblock ~170 ~165 ~94 oak_wood
setblock ~170 ~165 ~95 oak_wood
setblock ~170 ~165 ~96 oak_leaves[persistent=true]
setblock ~170 ~165 ~97 oak_leaves[persistent=true]
setblock ~170 ~165 ~98 oak_wood
setblock ~170 ~165 ~99 oak_wood
setblock ~170 ~165 ~100 oak_wood
setblock ~170 ~165 ~101 oak_wood
setblock ~170 ~165 ~102 oak_wood
setblock ~170 ~165 ~103 oak_wood
setblock ~170 ~165 ~104 jungle_leaves[persistent=true]
setblock ~170 ~165 ~105 oak_leaves[persistent=true]
setblock ~170 ~165 ~106 oak_leaves[persistent=true]
setblock ~170 ~166 ~80 oak_leaves[persistent=true]
setblock ~170 ~166 ~81 oak_leaves[persistent=true]
setblock ~170 ~166 ~82 oak_leaves[persistent=true]
setblock ~170 ~166 ~83 jungle_leaves[persistent=true]
setblock ~170 ~166 ~84 oak_wood
setblock ~170 ~166 ~85 oak_wood
setblock ~170 ~166 ~86 oak_wood
setblock ~170 ~166 ~87 oak_leaves[persistent=true]
setblock ~170 ~166 ~88 oak_wood
setblock ~170 ~166 ~89 oak_leaves[persistent=true]
setblock ~170 ~166 ~90 oak_leaves[persistent=true]
setblock ~170 ~166 ~91 oak_wood
setblock ~170 ~166 ~92 oak_leaves[persistent=true]
setblock ~170 ~166 ~93 oak_wood
setblock ~170 ~166 ~94 oak_wood
setblock ~170 ~166 ~95 oak_leaves[persistent=true]
setblock ~170 ~166 ~96 oak_wood
setblock ~170 ~166 ~97 oak_wood
setblock ~170 ~166 ~98 oak_wood
setblock ~170 ~166 ~99 oak_wood
setblock ~170 ~166 ~100 oak_wood
setblock ~170 ~166 ~101 oak_wood
setblock ~170 ~166 ~102 oak_wood
setblock ~170 ~166 ~103 oak_leaves[persistent=true]
setblock ~170 ~166 ~104 oak_leaves[persistent=true]
setblock ~170 ~166 ~105 oak_leaves[persistent=true]
setblock ~170 ~166 ~106 oak_leaves[persistent=true]
setblock ~170 ~167 ~80 oak_leaves[persistent=true]
setblock ~170 ~167 ~82 oak_leaves[persistent=true]
setblock ~170 ~167 ~83 jungle_leaves[persistent=true]
setblock ~170 ~167 ~84 oak_leaves[persistent=true]
setblock ~170 ~167 ~85 oak_leaves[persistent=true]
setblock ~170 ~167 ~86 oak_wood
setblock ~170 ~167 ~87 oak_wood
setblock ~170 ~167 ~88 oak_wood
setblock ~170 ~167 ~89 oak_wood
setblock ~170 ~167 ~90 oak_wood
setblock ~170 ~167 ~91 oak_wood
setblock ~170 ~167 ~92 oak_leaves[persistent=true]
setblock ~170 ~167 ~93 oak_wood
setblock ~170 ~167 ~94 oak_wood
setblock ~170 ~167 ~95 oak_wood
setblock ~170 ~167 ~96 oak_wood
setblock ~170 ~167 ~97 oak_log
setblock ~170 ~167 ~98 oak_leaves[persistent=true]
setblock ~170 ~167 ~99 oak_wood
setblock ~170 ~167 ~100 oak_wood
setblock ~170 ~167 ~101 oak_wood
setblock ~170 ~167 ~102 jungle_leaves[persistent=true]
setblock ~170 ~167 ~103 oak_wood
setblock ~170 ~168 ~81 oak_leaves[persistent=true]
setblock ~170 ~168 ~82 oak_leaves[persistent=true]
setblock ~170 ~168 ~83 oak_wood
setblock ~170 ~168 ~84 oak_wood
setblock ~170 ~168 ~85 oak_wood
setblock ~170 ~168 ~86 oak_wood
setblock ~170 ~168 ~87 oak_log
setblock ~170 ~168 ~88 oak_wood
setblock ~170 ~168 ~89 oak_leaves[persistent=true]
setblock ~170 ~168 ~90 oak_wood
setblock ~170 ~168 ~91 oak_log
setblock ~170 ~168 ~92 oak_wood
setblock ~170 ~168 ~93 oak_leaves[persistent=true]
setblock ~170 ~168 ~94 oak_log
setblock ~170 ~168 ~95 oak_log
setblock ~170 ~168 ~96 oak_wood
setblock ~170 ~168 ~97 oak_wood
setblock ~170 ~168 ~98 oak_wood
setblock ~170 ~168 ~100 oak_wood
setblock ~170 ~168 ~101 oak_wood
setblock ~170 ~168 ~102 oak_wood
setblock ~170 ~168 ~103 jungle_leaves[persistent=true]
setblock ~170 ~168 ~104 oak_leaves[persistent=true]
setblock ~170 ~168 ~105 oak_leaves[persistent=true]
setblock ~170 ~169 ~80 oak_leaves[persistent=true]
setblock ~170 ~169 ~81 oak_leaves[persistent=true]
setblock ~170 ~169 ~82 oak_leaves[persistent=true]
setblock ~170 ~169 ~83 oak_leaves[persistent=true]
setblock ~170 ~169 ~84 oak_leaves[persistent=true]
setblock ~170 ~169 ~85 oak_log
setblock ~170 ~169 ~86 oak_wood
setblock ~170 ~169 ~87 oak_log
setblock ~170 ~169 ~88 oak_wood
setblock ~170 ~169 ~89 oak_log
setblock ~170 ~169 ~90 oak_log
setblock ~170 ~169 ~91 oak_log
setblock ~170 ~169 ~92 oak_wood
setblock ~170 ~169 ~93 oak_log
setblock ~170 ~169 ~95 oak_log
setblock ~170 ~169 ~96 oak_wood
setblock ~170 ~169 ~97 jungle_leaves[persistent=true]
setblock ~170 ~169 ~98 oak_log
setblock ~170 ~169 ~99 oak_log
setblock ~170 ~169 ~100 oak_log
setblock ~170 ~169 ~101 jungle_leaves[persistent=true]
setblock ~170 ~169 ~102 oak_log
setblock ~170 ~169 ~103 oak_leaves[persistent=true]
setblock ~170 ~169 ~104 oak_leaves[persistent=true]
setblock ~170 ~169 ~105 jungle_leaves[persistent=true]
setblock ~170 ~170 ~82 oak_leaves[persistent=true]
setblock ~170 ~170 ~83 oak_leaves[persistent=true]
setblock ~170 ~170 ~84 oak_leaves[persistent=true]
setblock ~170 ~170 ~85 oak_leaves[persistent=true]
setblock ~170 ~170 ~86 jungle_leaves[persistent=true]
setblock ~170 ~170 ~87 oak_leaves[persistent=true]
setblock ~170 ~170 ~88 oak_leaves[persistent=true]
setblock ~170 ~170 ~89 jungle_leaves[persistent=true]
setblock ~170 ~170 ~90 oak_leaves[persistent=true]
setblock ~170 ~170 ~91 oak_leaves[persistent=true]
setblock ~170 ~170 ~92 oak_leaves[persistent=true]
setblock ~170 ~170 ~94 oak_leaves[persistent=true]
setblock ~170 ~170 ~96 jungle_leaves[persistent=true]
setblock ~170 ~170 ~97 oak_leaves[persistent=true]
setblock ~170 ~170 ~98 oak_leaves[persistent=true]
setblock ~170 ~170 ~99 oak_leaves[persistent=true]
setblock ~170 ~170 ~100 oak_leaves[persistent=true]
setblock ~170 ~170 ~102 oak_leaves[persistent=true]
setblock ~170 ~171 ~83 jungle_leaves[persistent=true]
setblock ~170 ~171 ~84 oak_leaves[persistent=true]
setblock ~170 ~171 ~85 oak_leaves[persistent=true]
setblock ~170 ~171 ~86 oak_leaves[persistent=true]
setblock ~170 ~171 ~87 jungle_leaves[persistent=true]
setblock ~170 ~171 ~88 oak_leaves[persistent=true]
setblock ~170 ~171 ~89 oak_leaves[persistent=true]
setblock ~170 ~171 ~90 oak_leaves[persistent=true]
setblock ~170 ~171 ~91 oak_leaves[persistent=true]
setblock ~170 ~171 ~92 oak_leaves[persistent=true]
setblock ~170 ~171 ~93 oak_leaves[persistent=true]
setblock ~170 ~171 ~94 oak_leaves[persistent=true]
setblock ~170 ~171 ~95 jungle_leaves[persistent=true]
setblock ~170 ~171 ~96 oak_leaves[persistent=true]
setblock ~170 ~171 ~97 oak_leaves[persistent=true]
setblock ~170 ~171 ~98 oak_leaves[persistent=true]
setblock ~170 ~171 ~99 oak_leaves[persistent=true]
setblock ~170 ~171 ~101 oak_leaves[persistent=true]
setblock ~170 ~171 ~103 oak_leaves[persistent=true]
setblock ~171 ~116 ~115 dirt
setblock ~171 ~117 ~115 dirt
setblock ~171 ~117 ~119 dirt
setblock ~171 ~118 ~114 dirt
setblock ~171 ~118 ~115 dirt
setblock ~171 ~118 ~117 dirt
setblock ~171 ~118 ~118 dirt
setblock ~171 ~118 ~119 dirt
setblock ~171 ~118 ~120 dirt
setblock ~171 ~119 ~113 dirt
setblock ~171 ~119 ~114 dirt
setblock ~171 ~119 ~115 dirt
setblock ~171 ~119 ~116 dirt
setblock ~171 ~119 ~117 dirt
setblock ~171 ~119 ~118 dirt
setblock ~171 ~119 ~119 dirt
setblock ~171 ~119 ~120 dirt
setblock ~171 ~120 ~113 dirt
setblock ~171 ~120 ~114 dirt
setblock ~171 ~120 ~115 dirt
setblock ~171 ~120 ~116 dirt
setblock ~171 ~120 ~117 dirt
setblock ~171 ~120 ~118 dirt
setblock ~171 ~120 ~119 dirt
setblock ~171 ~120 ~120 dirt
setblock ~171 ~120 ~121 dirt
setblock ~171 ~121 ~112 dirt
setblock ~171 ~121 ~113 dirt
setblock ~171 ~121 ~114 dirt
setblock ~171 ~121 ~115 dirt
setblock ~171 ~121 ~116 dirt
setblock ~171 ~121 ~117 dirt
setblock ~171 ~121 ~118 dirt
setblock ~171 ~121 ~119 dirt
setblock ~171 ~121 ~120 dirt
setblock ~171 ~121 ~121 dirt
setblock ~171 ~121 ~122 dirt
setblock ~171 ~122 ~112 dirt
setblock ~171 ~122 ~113 dirt
setblock ~171 ~122 ~114 dirt
setblock ~171 ~122 ~115 dirt
setblock ~171 ~122 ~116 dirt
setblock ~171 ~122 ~117 dirt
setblock ~171 ~122 ~118 dirt
setblock ~171 ~122 ~119 dirt
setblock ~171 ~122 ~120 dirt
setblock ~171 ~122 ~121 dirt
setblock ~171 ~122 ~122 dirt
setblock ~171 ~123 ~112 dirt
setblock ~171 ~123 ~113 dirt
setblock ~171 ~123 ~114 dirt
setblock ~171 ~123 ~115 dirt
setblock ~171 ~123 ~116 dirt
setblock ~171 ~123 ~117 dirt
setblock ~171 ~123 ~118 dirt
setblock ~171 ~123 ~119 dirt
setblock ~171 ~123 ~120 dirt
setblock ~171 ~123 ~121 dirt
setblock ~171 ~123 ~122 dirt
setblock ~171 ~124 ~112 dirt
setblock ~171 ~124 ~113 dirt
setblock ~171 ~124 ~114 dirt
setblock ~171 ~124 ~115 dirt
setblock ~171 ~124 ~116 dirt
setblock ~171 ~124 ~117 dirt
setblock ~171 ~124 ~118 dirt
setblock ~171 ~124 ~119 grass_block
setblock ~171 ~124 ~120 grass_block
setblock ~171 ~124 ~121 grass_block
setblock ~171 ~124 ~122 dirt
setblock ~171 ~125 ~112 dirt
setblock ~171 ~125 ~113 dirt
setblock ~171 ~125 ~114 dirt
setblock ~171 ~125 ~115 grass_block
setblock ~171 ~125 ~116 grass_block
setblock ~171 ~125 ~117 grass_block
setblock ~171 ~125 ~118 grass_block
setblock ~171 ~125 ~119 short_grass
setblock ~171 ~125 ~122 grass_block
setblock ~171 ~126 ~112 grass_block
setblock ~171 ~126 ~113 grass_block
setblock ~171 ~126 ~114 grass_block
setblock ~171 ~126 ~116 fern
setblock ~171 ~138 ~89 oak_leaves[persistent=true]
setblock ~171 ~138 ~90 oak_leaves[persistent=true]
setblock ~171 ~138 ~91 oak_leaves[persistent=true]
setblock ~171 ~138 ~92 oak_leaves[persistent=true]
setblock ~171 ~139 ~88 jungle_leaves[persistent=true]
setblock ~171 ~139 ~89 oak_leaves[persistent=true]
setblock ~171 ~139 ~90 jungle_leaves[persistent=true]
setblock ~171 ~139 ~91 oak_leaves[persistent=true]
setblock ~171 ~139 ~92 oak_leaves[persistent=true]
setblock ~171 ~139 ~94 oak_leaves[persistent=true]
setblock ~171 ~139 ~95 oak_leaves[persistent=true]
setblock ~171 ~139 ~97 oak_leaves[persistent=true]
setblock ~171 ~140 ~89 oak_leaves[persistent=true]
setblock ~171 ~140 ~90 oak_leaves[persistent=true]
setblock ~171 ~140 ~91 oak_wood
setblock ~171 ~140 ~92 oak_leaves[persistent=true]
setblock ~171 ~140 ~93 oak_leaves[persistent=true]
setblock ~171 ~140 ~94 jungle_leaves[persistent=true]
setblock ~171 ~140 ~95 oak_leaves[persistent=true]
setblock ~171 ~140 ~96 jungle_leaves[persistent=true]
setblock ~171 ~140 ~97 oak_leaves[persistent=true]
setblock ~171 ~140 ~98 oak_leaves[persistent=true]
setblock ~171 ~141 ~88 oak_leaves[persistent=true]
setblock ~171 ~141 ~89 oak_leaves[persistent=true]
setblock ~171 ~141 ~90 oak_wood
setblock ~171 ~141 ~91 oak_leaves[persistent=true]
setblock ~171 ~141 ~92 oak_leaves[persistent=true]
setblock ~171 ~141 ~93 jungle_leaves[persistent=true]
setblock ~171 ~141 ~96 oak_leaves[persistent=true]
setblock ~171 ~141 ~97 oak_leaves[persistent=true]
setblock ~171 ~141 ~98 jungle_leaves[persistent=true]
setblock ~171 ~141 ~99 oak_leaves[persistent=true]
setblock ~171 ~141 ~100 oak_leaves[persistent=true]
setblock ~171 ~142 ~88 oak_leaves[persistent=true]
setblock ~171 ~142 ~89 oak_leaves[persistent=true]
setblock ~171 ~142 ~90 oak_leaves[persistent=true]
setblock ~171 ~142 ~91 oak_leaves[persistent=true]
setblock ~171 ~142 ~92 oak_leaves[persistent=true]
setblock ~171 ~142 ~93 oak_leaves[persistent=true]
setblock ~171 ~142 ~94 oak_leaves[persistent=true]
setblock ~171 ~142 ~95 oak_leaves[persistent=true]
setblock ~171 ~142 ~96 oak_leaves[persistent=true]
setblock ~171 ~142 ~97 oak_wood
setblock ~171 ~142 ~98 oak_leaves[persistent=true]
setblock ~171 ~142 ~100 oak_leaves[persistent=true]
setblock ~171 ~143 ~89 oak_leaves[persistent=true]
setblock ~171 ~143 ~92 oak_leaves[persistent=true]
setblock ~171 ~143 ~93 jungle_leaves[persistent=true]
setblock ~171 ~143 ~94 oak_leaves[persistent=true]
setblock ~171 ~143 ~95 jungle_leaves[persistent=true]
setblock ~171 ~143 ~96 oak_leaves[persistent=true]
setblock ~171 ~143 ~97 oak_leaves[persistent=true]
setblock ~171 ~143 ~98 oak_leaves[persistent=true]
setblock ~171 ~143 ~99 oak_leaves[persistent=true]
setblock ~171 ~144 ~88 jungle_leaves[persistent=true]
setblock ~171 ~144 ~89 oak_leaves[persistent=true]
setblock ~171 ~144 ~90 oak_leaves[persistent=true]
setblock ~171 ~144 ~91 oak_leaves[persistent=true]
setblock ~171 ~144 ~92 jungle_leaves[persistent=true]
setblock ~171 ~144 ~93 jungle_leaves[persistent=true]
setblock ~171 ~144 ~94 oak_leaves[persistent=true]
setblock ~171 ~144 ~95 oak_leaves[persistent=true]
setblock ~171 ~144 ~96 oak_leaves[persistent=true]
setblock ~171 ~144 ~98 oak_leaves[persistent=true]
setblock ~171 ~144 ~100 oak_leaves[persistent=true]
setblock ~171 ~145 ~89 jungle_leaves[persistent=true]
setblock ~171 ~145 ~90 oak_leaves[persistent=true]
setblock ~171 ~145 ~91 oak_leaves[persistent=true]
setblock ~171 ~145 ~92 jungle_leaves[persistent=true]
setblock ~171 ~145 ~94 oak_leaves[persistent=true]
setblock ~171 ~145 ~95 oak_leaves[persistent=true]
setblock ~171 ~145 ~96 oak_leaves[persistent=true]
setblock ~171 ~145 ~97 oak_leaves[persistent=true]
setblock ~171 ~145 ~98 oak_leaves[persistent=true]
setblock ~171 ~145 ~99 oak_leaves[persistent=true]
setblock ~171 ~145 ~100 oak_leaves[persistent=true]
setblock ~171 ~145 ~101 oak_leaves[persistent=true]
setblock ~171 ~146 ~89 oak_leaves[persistent=true]
setblock ~171 ~146 ~90 oak_leaves[persistent=true]
setblock ~171 ~146 ~91 jungle_leaves[persistent=true]
setblock ~171 ~146 ~93 jungle_leaves[persistent=true]
setblock ~171 ~146 ~94 oak_leaves[persistent=true]
setblock ~171 ~146 ~96 oak_leaves[persistent=true]
setblock ~171 ~146 ~97 oak_leaves[persistent=true]
setblock ~171 ~146 ~98 oak_leaves[persistent=true]
setblock ~171 ~146 ~99 oak_leaves[persistent=true]
setblock ~171 ~146 ~100 oak_leaves[persistent=true]
setblock ~171 ~146 ~101 oak_leaves[persistent=true]
setblock ~171 ~147 ~90 jungle_leaves[persistent=true]
setblock ~171 ~147 ~91 oak_leaves[persistent=true]
setblock ~171 ~147 ~92 oak_wood
setblock ~171 ~147 ~93 jungle_leaves[persistent=true]
setblock ~171 ~147 ~94 jungle_leaves[persistent=true]
setblock ~171 ~147 ~95 oak_leaves[persistent=true]
setblock ~171 ~147 ~96 oak_leaves[persistent=true]
setblock ~171 ~147 ~97 oak_leaves[persistent=true]
setblock ~171 ~147 ~98 oak_leaves[persistent=true]
setblock ~171 ~147 ~99 oak_leaves[persistent=true]
setblock ~171 ~147 ~100 oak_leaves[persistent=true]
setblock ~171 ~148 ~90 jungle_leaves[persistent=true]
setblock ~171 ~148 ~91 jungle_leaves[persistent=true]
setblock ~171 ~148 ~92 oak_leaves[persistent=true]
setblock ~171 ~148 ~93 jungle_leaves[persistent=true]
setblock ~171 ~148 ~94 oak_leaves[persistent=true]
setblock ~171 ~148 ~95 oak_leaves[persistent=true]
setblock ~171 ~148 ~96 oak_leaves[persistent=true]
setblock ~171 ~148 ~97 oak_leaves[persistent=true]
setblock ~171 ~148 ~98 jungle_leaves[persistent=true]
setblock ~171 ~148 ~99 oak_leaves[persistent=true]
setblock ~171 ~148 ~100 oak_leaves[persistent=true]
setblock ~171 ~148 ~101 oak_leaves[persistent=true]
setblock ~171 ~149 ~90 oak_leaves[persistent=true]
setblock ~171 ~149 ~92 oak_leaves[persistent=true]
setblock ~171 ~149 ~93 oak_wood
setblock ~171 ~149 ~94 oak_leaves[persistent=true]
setblock ~171 ~149 ~95 oak_wood
setblock ~171 ~149 ~96 oak_wood
setblock ~171 ~149 ~97 jungle_leaves[persistent=true]
setblock ~171 ~149 ~98 oak_wood
setblock ~171 ~149 ~100 oak_leaves[persistent=true]
setblock ~171 ~150 ~83 jungle_leaves[persistent=true]
setblock ~171 ~150 ~84 oak_leaves[persistent=true]
setblock ~171 ~150 ~85 oak_leaves[persistent=true]
setblock ~171 ~150 ~86 oak_leaves[persistent=true]
setblock ~171 ~150 ~87 jungle_leaves[persistent=true]
setblock ~171 ~150 ~88 oak_leaves[persistent=true]
setblock ~171 ~150 ~89 jungle_leaves[persistent=true]
setblock ~171 ~150 ~90 oak_leaves[persistent=true]
setblock ~171 ~150 ~91 jungle_leaves[persistent=true]
setblock ~171 ~150 ~92 jungle_leaves[persistent=true]
setblock ~171 ~150 ~93 jungle_leaves[persistent=true]
setblock ~171 ~150 ~94 oak_leaves[persistent=true]
setblock ~171 ~150 ~95 oak_log
setblock ~171 ~150 ~96 oak_leaves[persistent=true]
setblock ~171 ~150 ~97 oak_wood
setblock ~171 ~150 ~98 oak_leaves[persistent=true]
setblock ~171 ~150 ~99 oak_leaves[persistent=true]
setblock ~171 ~150 ~100 oak_leaves[persistent=true]
setblock ~171 ~151 ~84 oak_leaves[persistent=true]
setblock ~171 ~151 ~85 oak_leaves[persistent=true]
setblock ~171 ~151 ~86 oak_leaves[persistent=true]
setblock ~171 ~151 ~87 oak_leaves[persistent=true]
setblock ~171 ~151 ~88 oak_leaves[persistent=true]
setblock ~171 ~151 ~89 oak_leaves[persistent=true]
setblock ~171 ~151 ~90 oak_leaves[persistent=true]
setblock ~171 ~151 ~91 jungle_leaves[persistent=true]
setblock ~171 ~151 ~92 oak_leaves[persistent=true]
setblock ~171 ~151 ~93 oak_leaves[persistent=true]
setblock ~171 ~151 ~94 oak_leaves[persistent=true]
setblock ~171 ~151 ~95 oak_leaves[persistent=true]
setblock ~171 ~151 ~96 oak_wood
setblock ~171 ~151 ~98 oak_leaves[persistent=true]
setblock ~171 ~151 ~99 oak_leaves[persistent=true]
setblock ~171 ~151 ~100 oak_leaves[persistent=true]
setblock ~171 ~152 ~83 oak_leaves[persistent=true]
setblock ~171 ~152 ~84 jungle_leaves[persistent=true]
setblock ~171 ~152 ~85 jungle_leaves[persistent=true]
setblock ~171 ~152 ~87 oak_leaves[persistent=true]
setblock ~171 ~152 ~88 oak_wood
setblock ~171 ~152 ~89 oak_leaves[persistent=true]
setblock ~171 ~152 ~90 oak_leaves[persistent=true]
setblock ~171 ~152 ~91 jungle_leaves[persistent=true]
setblock ~171 ~152 ~92 oak_wood
setblock ~171 ~152 ~93 oak_wood
setblock ~171 ~152 ~94 oak_wood
setblock ~171 ~152 ~95 oak_wood
setblock ~171 ~152 ~96 oak_wood
setblock ~171 ~152 ~97 jungle_leaves[persistent=true]
setblock ~171 ~152 ~98 jungle_leaves[persistent=true]
setblock ~171 ~152 ~99 jungle_leaves[persistent=true]
setblock ~171 ~152 ~100 oak_leaves[persistent=true]
setblock ~171 ~153 ~83 oak_leaves[persistent=true]
setblock ~171 ~153 ~84 oak_leaves[persistent=true]
setblock ~171 ~153 ~86 oak_leaves[persistent=true]
setblock ~171 ~153 ~87 oak_wood
setblock ~171 ~153 ~88 oak_wood
setblock ~171 ~153 ~89 oak_wood
setblock ~171 ~153 ~90 oak_leaves[persistent=true]
setblock ~171 ~153 ~91 oak_leaves[persistent=true]
setblock ~171 ~153 ~92 oak_leaves[persistent=true]
setblock ~171 ~153 ~93 oak_wood
setblock ~171 ~153 ~94 oak_wood
setblock ~171 ~153 ~95 oak_leaves[persistent=true]
setblock ~171 ~153 ~96 oak_log
setblock ~171 ~153 ~97 oak_leaves[persistent=true]
setblock ~171 ~153 ~98 oak_leaves[persistent=true]
setblock ~171 ~153 ~99 oak_leaves[persistent=true]
setblock ~171 ~153 ~100 oak_leaves[persistent=true]
setblock ~171 ~154 ~84 oak_leaves[persistent=true]
setblock ~171 ~154 ~85 oak_leaves[persistent=true]
setblock ~171 ~154 ~86 oak_leaves[persistent=true]
setblock ~171 ~154 ~87 jungle_leaves[persistent=true]
setblock ~171 ~154 ~88 jungle_leaves[persistent=true]
setblock ~171 ~154 ~89 oak_leaves[persistent=true]
setblock ~171 ~154 ~90 oak_leaves[persistent=true]
setblock ~171 ~154 ~91 oak_leaves[persistent=true]
setblock ~171 ~154 ~92 oak_leaves[persistent=true]
setblock ~171 ~154 ~93 oak_wood
setblock ~171 ~154 ~94 oak_wood
setblock ~171 ~154 ~95 oak_leaves[persistent=true]
setblock ~171 ~154 ~96 oak_log
setblock ~171 ~154 ~98 oak_wood
setblock ~171 ~154 ~99 oak_leaves[persistent=true]
setblock ~171 ~154 ~100 oak_leaves[persistent=true]
setblock ~171 ~155 ~85 jungle_leaves[persistent=true]
setblock ~171 ~155 ~86 oak_leaves[persistent=true]
setblock ~171 ~155 ~88 oak_wood
setblock ~171 ~155 ~89 oak_wood
setblock ~171 ~155 ~90 oak_wood
setblock ~171 ~155 ~91 oak_wood
setblock ~171 ~155 ~92 oak_leaves[persistent=true]
setblock ~171 ~155 ~93 oak_wood
setblock ~171 ~155 ~94 oak_wood
setblock ~171 ~155 ~95 oak_leaves[persistent=true]
setblock ~171 ~155 ~96 jungle_leaves[persistent=true]
setblock ~171 ~155 ~97 oak_leaves[persistent=true]
setblock ~171 ~155 ~98 oak_leaves[persistent=true]
setblock ~171 ~155 ~99 jungle_leaves[persistent=true]
setblock ~171 ~155 ~100 jungle_leaves[persistent=true]
setblock ~171 ~156 ~82 oak_leaves[persistent=true]
setblock ~171 ~156 ~83 jungle_leaves[persistent=true]
setblock ~171 ~156 ~84 jungle_leaves[persistent=true]
setblock ~171 ~156 ~85 oak_leaves[persistent=true]
setblock ~171 ~156 ~86 oak_leaves[persistent=true]
setblock ~171 ~156 ~88 oak_wood
setblock ~171 ~156 ~89 oak_leaves[persistent=true]
setblock ~171 ~156 ~91 jungle_leaves[persistent=true]
setblock ~171 ~156 ~92 oak_leaves[persistent=true]
setblock ~171 ~156 ~93 oak_wood
setblock ~171 ~156 ~94 oak_wood
setblock ~171 ~156 ~95 oak_wood
setblock ~171 ~156 ~96 oak_leaves[persistent=true]
setblock ~171 ~156 ~97 oak_leaves[persistent=true]
setblock ~171 ~156 ~98 oak_leaves[persistent=true]
setblock ~171 ~156 ~99 oak_leaves[persistent=true]
setblock ~171 ~157 ~82 oak_leaves[persistent=true]
setblock ~171 ~157 ~83 oak_leaves[persistent=true]
setblock ~171 ~157 ~85 oak_leaves[persistent=true]
setblock ~171 ~157 ~86 oak_leaves[persistent=true]
setblock ~171 ~157 ~87 oak_leaves[persistent=true]
setblock ~171 ~157 ~88 oak_wood
setblock ~171 ~157 ~89 oak_leaves[persistent=true]
setblock ~171 ~157 ~90 jungle_leaves[persistent=true]
setblock ~171 ~157 ~91 oak_wood
setblock ~171 ~157 ~92 oak_wood
setblock ~171 ~157 ~93 oak_wood
setblock ~171 ~157 ~94 oak_wood
setblock ~171 ~157 ~96 oak_wood
setblock ~171 ~157 ~97 oak_wood
setblock ~171 ~157 ~98 oak_leaves[persistent=true]
setblock ~171 ~157 ~99 oak_wood
setblock ~171 ~157 ~100 oak_leaves[persistent=true]
setblock ~171 ~158 ~84 oak_leaves[persistent=true]
setblock ~171 ~158 ~85 oak_leaves[persistent=true]
setblock ~171 ~158 ~87 oak_leaves[persistent=true]
setblock ~171 ~158 ~88 oak_wood
setblock ~171 ~158 ~89 oak_wood
setblock ~171 ~158 ~90 oak_wood
setblock ~171 ~158 ~91 oak_wood
setblock ~171 ~158 ~92 oak_wood
setblock ~171 ~158 ~93 oak_wood
setblock ~171 ~158 ~94 jungle_leaves[persistent=true]
setblock ~171 ~158 ~95 oak_wood
setblock ~171 ~158 ~96 oak_wood
setblock ~171 ~158 ~99 oak_leaves[persistent=true]
setblock ~171 ~159 ~82 oak_leaves[persistent=true]
setblock ~171 ~159 ~83 oak_leaves[persistent=true]
setblock ~171 ~159 ~84 oak_leaves[persistent=true]
setblock ~171 ~159 ~85 oak_leaves[persistent=true]
setblock ~171 ~159 ~86 oak_leaves[persistent=true]
setblock ~171 ~159 ~87 oak_leaves[persistent=true]
setblock ~171 ~159 ~88 oak_wood
setblock ~171 ~159 ~89 oak_wood
setblock ~171 ~159 ~90 oak_wood
setblock ~171 ~159 ~91 oak_wood
setblock ~171 ~159 ~92 oak_wood
setblock ~171 ~159 ~93 oak_leaves[persistent=true]
setblock ~171 ~159 ~94 oak_wood
setblock ~171 ~159 ~95 oak_wood
setblock ~171 ~159 ~96 oak_wood
setblock ~171 ~159 ~97 oak_wood
setblock ~171 ~159 ~98 oak_leaves[persistent=true]
setblock ~171 ~159 ~99 oak_wood
setblock ~171 ~159 ~100 oak_leaves[persistent=true]
setblock ~171 ~159 ~101 oak_leaves[persistent=true]
setblock ~171 ~159 ~102 oak_leaves[persistent=true]
setblock ~171 ~159 ~103 oak_leaves[persistent=true]
setblock ~171 ~159 ~104 oak_leaves[persistent=true]
setblock ~171 ~160 ~83 oak_leaves[persistent=true]
setblock ~171 ~160 ~84 jungle_leaves[persistent=true]
setblock ~171 ~160 ~85 oak_leaves[persistent=true]
setblock ~171 ~160 ~86 oak_leaves[persistent=true]
setblock ~171 ~160 ~87 oak_leaves[persistent=true]
setblock ~171 ~160 ~88 oak_wood
setblock ~171 ~160 ~89 oak_wood
setblock ~171 ~160 ~90 oak_log
setblock ~171 ~160 ~91 oak_leaves[persistent=true]
setblock ~171 ~160 ~92 oak_wood
setblock ~171 ~160 ~93 oak_wood
setblock ~171 ~160 ~94 oak_wood
setblock ~171 ~160 ~95 oak_wood
setblock ~171 ~160 ~96 oak_wood
setblock ~171 ~160 ~97 oak_log
setblock ~171 ~160 ~98 oak_leaves[persistent=true]
setblock ~171 ~160 ~99 oak_wood
setblock ~171 ~160 ~100 oak_wood
setblock ~171 ~160 ~101 oak_leaves[persistent=true]
setblock ~171 ~160 ~102 oak_leaves[persistent=true]
setblock ~171 ~160 ~104 jungle_leaves[persistent=true]
setblock ~171 ~160 ~105 oak_leaves[persistent=true]
setblock ~171 ~161 ~83 oak_leaves[persistent=true]
setblock ~171 ~161 ~84 oak_leaves[persistent=true]
setblock ~171 ~161 ~86 oak_leaves[persistent=true]
setblock ~171 ~161 ~87 oak_leaves[persistent=true]
setblock ~171 ~161 ~88 oak_wood
setblock ~171 ~161 ~89 oak_leaves[persistent=true]
setblock ~171 ~161 ~90 oak_leaves[persistent=true]
setblock ~171 ~161 ~91 oak_wood
setblock ~171 ~161 ~92 oak_wood
setblock ~171 ~161 ~93 oak_log
setblock ~171 ~161 ~94 oak_wood
setblock ~171 ~161 ~95 oak_leaves[persistent=true]
setblock ~171 ~161 ~96 oak_wood
setblock ~171 ~161 ~97 oak_leaves[persistent=true]
setblock ~171 ~161 ~98 oak_wood
setblock ~171 ~161 ~99 oak_leaves[persistent=true]
setblock ~171 ~161 ~100 oak_leaves[persistent=true]
setblock ~171 ~161 ~101 oak_leaves[persistent=true]
setblock ~171 ~161 ~102 oak_leaves[persistent=true]
setblock ~171 ~161 ~103 jungle_leaves[persistent=true]
setblock ~171 ~161 ~104 oak_leaves[persistent=true]
setblock ~171 ~161 ~105 jungle_leaves[persistent=true]
setblock ~171 ~162 ~81 oak_leaves[persistent=true]
setblock ~171 ~162 ~82 oak_leaves[persistent=true]
setblock ~171 ~162 ~83 jungle_leaves[persistent=true]
setblock ~171 ~162 ~84 jungle_leaves[persistent=true]
setblock ~171 ~162 ~85 jungle_leaves[persistent=true]
setblock ~171 ~162 ~86 oak_leaves[persistent=true]
setblock ~171 ~162 ~87 jungle_leaves[persistent=true]
setblock ~171 ~162 ~88 oak_leaves[persistent=true]
setblock ~171 ~162 ~89 oak_wood
setblock ~171 ~162 ~90 oak_wood
setblock ~171 ~162 ~91 oak_wood
setblock ~171 ~162 ~92 oak_wood
setblock ~171 ~162 ~93 oak_leaves[persistent=true]
setblock ~171 ~162 ~94 oak_wood
setblock ~171 ~162 ~95 oak_wood
setblock ~171 ~162 ~96 oak_leaves[persistent=true]
setblock ~171 ~162 ~97 jungle_leaves[persistent=true]
setblock ~171 ~162 ~98 oak_wood
setblock ~171 ~162 ~99 oak_wood
setblock ~171 ~162 ~100 oak_wood
setblock ~171 ~162 ~101 oak_leaves[persistent=true]
setblock ~171 ~162 ~102 jungle_leaves[persistent=true]
setblock ~171 ~162 ~103 oak_leaves[persistent=true]
setblock ~171 ~162 ~104 jungle_leaves[persistent=true]
setblock ~171 ~163 ~81 oak_leaves[persistent=true]
setblock ~171 ~163 ~82 oak_leaves[persistent=true]
setblock ~171 ~163 ~83 oak_leaves[persistent=true]
setblock ~171 ~163 ~85 oak_leaves[persistent=true]
setblock ~171 ~163 ~87 oak_wood
setblock ~171 ~163 ~88 oak_wood
setblock ~171 ~163 ~89 oak_wood
setblock ~171 ~163 ~90 oak_wood
setblock ~171 ~163 ~91 oak_wood
setblock ~171 ~163 ~92 oak_log
setblock ~171 ~163 ~93 oak_wood
setblock ~171 ~163 ~94 oak_wood
setblock ~171 ~163 ~95 oak_wood
setblock ~171 ~163 ~96 oak_wood
setblock ~171 ~163 ~97 oak_wood
setblock ~171 ~163 ~98 jungle_leaves[persistent=true]
setblock ~171 ~163 ~99 oak_leaves[persistent=true]
setblock ~171 ~163 ~100 oak_leaves[persistent=true]
setblock ~171 ~163 ~101 oak_wood
setblock ~171 ~163 ~102 oak_leaves[persistent=true]
setblock ~171 ~163 ~103 oak_leaves[persistent=true]
setblock ~171 ~163 ~104 jungle_leaves[persistent=true]
setblock ~171 ~163 ~105 oak_leaves[persistent=true]
setblock ~171 ~164 ~81 oak_leaves[persistent=true]
setblock ~171 ~164 ~82 oak_leaves[persistent=true]
setblock ~171 ~164 ~83 jungle_leaves[persistent=true]
setblock ~171 ~164 ~84 oak_leaves[persistent=true]
setblock ~171 ~164 ~85 oak_leaves[persistent=true]
setblock ~171 ~164 ~87 oak_leaves[persistent=true]
setblock ~171 ~164 ~88 oak_wood
setblock ~171 ~164 ~89 oak_wood
setblock ~171 ~164 ~90 oak_wood
setblock ~171 ~164 ~91 oak_wood
setblock ~171 ~164 ~92 oak_wood
setblock ~171 ~164 ~93 oak_wood
setblock ~171 ~164 ~94 oak_wood
setblock ~171 ~164 ~95 oak_log
setblock ~171 ~164 ~96 oak_wood
setblock ~171 ~164 ~97 oak_wood
setblock ~171 ~164 ~98 jungle_leaves[persistent=true]
setblock ~171 ~164 ~99 oak_log
setblock ~171 ~164 ~100 oak_wood
setblock ~171 ~164 ~101 oak_leaves[persistent=true]
setblock ~171 ~164 ~102 oak_leaves[persistent=true]
setblock ~171 ~164 ~103 oak_leaves[persistent=true]
setblock ~171 ~164 ~104 oak_leaves[persistent=true]
setblock ~171 ~164 ~105 oak_leaves[persistent=true]
setblock ~171 ~165 ~81 oak_leaves[persistent=true]
setblock ~171 ~165 ~82 oak_leaves[persistent=true]
setblock ~171 ~165 ~83 jungle_leaves[persistent=true]
setblock ~171 ~165 ~84 oak_wood
setblock ~171 ~165 ~85 oak_wood
setblock ~171 ~165 ~86 oak_wood
setblock ~171 ~165 ~87 oak_wood
setblock ~171 ~165 ~88 oak_wood
setblock ~171 ~165 ~89 oak_wood
setblock ~171 ~165 ~90 oak_wood
setblock ~171 ~165 ~91 oak_wood
setblock ~171 ~165 ~92 oak_wood
setblock ~171 ~165 ~93 oak_wood
setblock ~171 ~165 ~94 oak_wood
setblock ~171 ~165 ~95 oak_wood
setblock ~171 ~165 ~96 oak_wood
setblock ~171 ~165 ~97 oak_wood
setblock ~171 ~165 ~98 oak_leaves[persistent=true]
setblock ~171 ~165 ~99 oak_leaves[persistent=true]
setblock ~171 ~165 ~100 jungle_leaves[persistent=true]
setblock ~171 ~165 ~101 jungle_leaves[persistent=true]
setblock ~171 ~165 ~102 oak_wood
setblock ~171 ~165 ~103 oak_leaves[persistent=true]
setblock ~171 ~165 ~104 oak_leaves[persistent=true]
setblock ~171 ~165 ~105 oak_leaves[persistent=true]
setblock ~171 ~166 ~81 oak_leaves[persistent=true]
setblock ~171 ~166 ~83 jungle_leaves[persistent=true]
setblock ~171 ~166 ~84 oak_wood
setblock ~171 ~166 ~85 oak_wood
setblock ~171 ~166 ~86 jungle_leaves[persistent=true]
setblock ~171 ~166 ~87 oak_leaves[persistent=true]
setblock ~171 ~166 ~88 oak_wood
setblock ~171 ~166 ~89 oak_wood
setblock ~171 ~166 ~90 oak_wood
setblock ~171 ~166 ~91 oak_log
setblock ~171 ~166 ~92 oak_wood
setblock ~171 ~166 ~93 oak_wood
setblock ~171 ~166 ~94 oak_wood
setblock ~171 ~166 ~95 oak_wood
setblock ~171 ~166 ~96 oak_leaves[persistent=true]
setblock ~171 ~166 ~97 oak_wood
setblock ~171 ~166 ~98 oak_wood
setblock ~171 ~166 ~99 oak_wood
setblock ~171 ~166 ~100 oak_wood
setblock ~171 ~166 ~101 oak_leaves[persistent=true]
setblock ~171 ~166 ~102 oak_leaves[persistent=true]
setblock ~171 ~166 ~103 oak_leaves[persistent=true]
setblock ~171 ~166 ~104 oak_leaves[persistent=true]
setblock ~171 ~167 ~81 oak_leaves[persistent=true]
setblock ~171 ~167 ~82 oak_leaves[persistent=true]
setblock ~171 ~167 ~83 jungle_leaves[persistent=true]
setblock ~171 ~167 ~84 oak_leaves[persistent=true]
setblock ~171 ~167 ~85 oak_leaves[persistent=true]
setblock ~171 ~167 ~86 oak_leaves[persistent=true]
setblock ~171 ~167 ~87 oak_wood
setblock ~171 ~167 ~88 oak_wood
setblock ~171 ~167 ~89 oak_wood
setblock ~171 ~167 ~90 oak_wood
setblock ~171 ~167 ~91 oak_wood
setblock ~171 ~167 ~92 oak_wood
setblock ~171 ~167 ~93 oak_wood
setblock ~171 ~167 ~94 oak_wood
setblock ~171 ~167 ~95 oak_wood
setblock ~171 ~167 ~96 oak_wood
setblock ~171 ~167 ~97 oak_wood
setblock ~171 ~167 ~98 oak_leaves[persistent=true]
setblock ~171 ~167 ~99 oak_wood
setblock ~171 ~167 ~100 oak_wood
setblock ~171 ~167 ~101 oak_wood
setblock ~171 ~167 ~102 oak_wood
setblock ~171 ~167 ~103 oak_leaves[persistent=true]
setblock ~171 ~167 ~104 oak_leaves[persistent=true]
setblock ~171 ~168 ~81 oak_leaves[persistent=true]
setblock ~171 ~168 ~83 oak_leaves[persistent=true]
setblock ~171 ~168 ~84 oak_leaves[persistent=true]
setblock ~171 ~168 ~85 oak_wood
setblock ~171 ~168 ~86 oak_wood
setblock ~171 ~168 ~87 oak_wood
setblock ~171 ~168 ~88 oak_wood
setblock ~171 ~168 ~89 oak_wood
setblock ~171 ~168 ~90 oak_leaves[persistent=true]
setblock ~171 ~168 ~91 oak_wood
setblock ~171 ~168 ~92 oak_leaves[persistent=true]
setblock ~171 ~168 ~93 oak_leaves[persistent=true]
setblock ~171 ~168 ~94 oak_wood
setblock ~171 ~168 ~95 oak_wood
setblock ~171 ~168 ~96 oak_wood
setblock ~171 ~168 ~97 oak_leaves[persistent=true]
setblock ~171 ~168 ~98 oak_wood
setblock ~171 ~168 ~99 oak_leaves[persistent=true]
setblock ~171 ~168 ~100 oak_wood
setblock ~171 ~168 ~101 oak_wood
setblock ~171 ~168 ~102 oak_wood
setblock ~171 ~168 ~103 oak_wood
setblock ~171 ~168 ~104 oak_leaves[persistent=true]
setblock ~171 ~169 ~81 jungle_leaves[persistent=true]
setblock ~171 ~169 ~82 oak_leaves[persistent=true]
setblock ~171 ~169 ~83 oak_leaves[persistent=true]
setblock ~171 ~169 ~84 oak_leaves[persistent=true]
setblock ~171 ~169 ~85 oak_leaves[persistent=true]
setblock ~171 ~169 ~86 oak_log
setblock ~171 ~169 ~87 oak_log
setblock ~171 ~169 ~88 oak_wood
setblock ~171 ~169 ~89 oak_log
setblock ~171 ~169 ~90 oak_log
setblock ~171 ~169 ~91 oak_log
setblock ~171 ~169 ~92 oak_log
setblock ~171 ~169 ~93 oak_log
setblock ~171 ~169 ~94 oak_wood
setblock ~171 ~169 ~95 oak_log
setblock ~171 ~169 ~96 jungle_leaves[persistent=true]
setblock ~171 ~169 ~97 oak_log
setblock ~171 ~169 ~98 oak_log
setblock ~171 ~169 ~99 oak_log
setblock ~171 ~169 ~100 oak_log
setblock ~171 ~169 ~101 oak_log
setblock ~171 ~169 ~103 oak_leaves[persistent=true]
setblock ~171 ~170 ~82 oak_leaves[persistent=true]
setblock ~171 ~170 ~83 jungle_leaves[persistent=true]
setblock ~171 ~170 ~84 oak_leaves[persistent=true]
setblock ~171 ~170 ~86 oak_leaves[persistent=true]
setblock ~171 ~170 ~87 oak_leaves[persistent=true]
setblock ~171 ~170 ~88 oak_wood
setblock ~171 ~170 ~89 oak_leaves[persistent=true]
setblock ~171 ~170 ~90 oak_wood
setblock ~171 ~170 ~91 oak_leaves[persistent=true]
setblock ~171 ~170 ~92 oak_leaves[persistent=true]
setblock ~171 ~170 ~93 oak_leaves[persistent=true]
setblock ~171 ~170 ~94 oak_leaves[persistent=true]
setblock ~171 ~170 ~95 oak_wood
setblock ~171 ~170 ~96 oak_leaves[persistent=true]
setblock ~171 ~170 ~97 oak_leaves[persistent=true]
setblock ~171 ~170 ~98 oak_leaves[persistent=true]
setblock ~171 ~170 ~99 oak_leaves[persistent=true]
setblock ~171 ~170 ~100 oak_leaves[persistent=true]
setblock ~171 ~170 ~101 oak_leaves[persistent=true]
setblock ~171 ~170 ~102 oak_leaves[persistent=true]
setblock ~171 ~170 ~103 oak_leaves[persistent=true]
setblock ~171 ~170 ~104 oak_leaves[persistent=true]
setblock ~171 ~171 ~82 oak_leaves[persistent=true]
setblock ~171 ~171 ~83 oak_leaves[persistent=true]
setblock ~171 ~171 ~84 oak_leaves[persistent=true]
setblock ~171 ~171 ~85 oak_leaves[persistent=true]
setblock ~171 ~171 ~86 oak_leaves[persistent=true]
setblock ~171 ~171 ~87 oak_leaves[persistent=true]
setblock ~171 ~171 ~88 oak_leaves[persistent=true]
setblock ~171 ~171 ~89 oak_leaves[persistent=true]
setblock ~171 ~171 ~90 oak_leaves[persistent=true]
setblock ~171 ~171 ~91 jungle_leaves[persistent=true]
setblock ~171 ~171 ~92 oak_leaves[persistent=true]
setblock ~171 ~171 ~93 jungle_leaves[persistent=true]
setblock ~171 ~171 ~94 oak_leaves[persistent=true]
setblock ~171 ~171 ~95 oak_leaves[persistent=true]
setblock ~171 ~171 ~96 oak_leaves[persistent=true]
setblock ~171 ~171 ~97 oak_leaves[persistent=true]
setblock ~171 ~171 ~98 oak_leaves[persistent=true]
setblock ~171 ~171 ~99 oak_leaves[persistent=true]
setblock ~171 ~171 ~100 jungle_leaves[persistent=true]
setblock ~171 ~171 ~101 jungle_leaves[persistent=true]
setblock ~171 ~171 ~102 oak_leaves[persistent=true]
setblock ~171 ~171 ~103 oak_leaves[persistent=true]
setblock ~172 ~118 ~119 dirt
setblock ~172 ~119 ~114 dirt
setblock ~172 ~119 ~115 dirt
setblock ~172 ~119 ~118 dirt
setblock ~172 ~119 ~119 dirt
setblock ~172 ~120 ~114 dirt
setblock ~172 ~120 ~115 dirt
setblock ~172 ~120 ~116 dirt
setblock ~172 ~120 ~117 dirt
setblock ~172 ~120 ~118 dirt
setblock ~172 ~120 ~119 dirt
setblock ~172 ~120 ~120 dirt
setblock ~172 ~121 ~113 dirt
setblock ~172 ~121 ~114 dirt
setblock ~172 ~121 ~115 dirt
setblock ~172 ~121 ~116 dirt
setblock ~172 ~121 ~117 dirt
setblock ~172 ~121 ~118 dirt
setblock ~172 ~121 ~119 dirt
setblock ~172 ~121 ~120 dirt
setblock ~172 ~121 ~121 dirt
setblock ~172 ~122 ~113 dirt
setblock ~172 ~122 ~114 dirt
setblock ~172 ~122 ~115 dirt
setblock ~172 ~122 ~116 dirt
setblock ~172 ~122 ~117 dirt
setblock ~172 ~122 ~118 dirt
setblock ~172 ~122 ~119 dirt
setblock ~172 ~122 ~120 dirt
setblock ~172 ~122 ~121 dirt
setblock ~172 ~123 ~113 dirt
setblock ~172 ~123 ~114 dirt
setblock ~172 ~123 ~115 dirt
setblock ~172 ~123 ~116 dirt
setblock ~172 ~123 ~117 dirt
setblock ~172 ~123 ~118 dirt
setblock ~172 ~123 ~119 dirt
setblock ~172 ~123 ~120 dirt
setblock ~172 ~123 ~121 dirt
setblock ~172 ~124 ~113 dirt
setblock ~172 ~124 ~114 dirt
setblock ~172 ~124 ~115 dirt
setblock ~172 ~124 ~116 dirt
setblock ~172 ~124 ~117 dirt
setblock ~172 ~124 ~118 dirt
setblock ~172 ~124 ~119 dirt
setblock ~172 ~124 ~120 grass_block
setblock ~172 ~124 ~121 dirt
setblock ~172 ~125 ~113 dirt
setblock ~172 ~125 ~114 dirt
setblock ~172 ~125 ~115 dirt
setblock ~172 ~125 ~116 grass_block
setblock ~172 ~125 ~117 grass_block
setblock ~172 ~125 ~118 grass_block
setblock ~172 ~125 ~119 grass_block
setblock ~172 ~125 ~121 grass_block
setblock ~172 ~126 ~113 grass_block
setblock ~172 ~126 ~114 grass_block
setblock ~172 ~126 ~115 grass_block
setblock ~172 ~126 ~117 short_grass
setblock ~172 ~126 ~121 short_grass
setblock ~172 ~127 ~113 short_grass
setblock ~172 ~139 ~88 oak_leaves[persistent=true]
setblock ~172 ~139 ~89 jungle_leaves[persistent=true]
setblock ~172 ~139 ~90 jungle_leaves[persistent=true]
setblock ~172 ~139 ~91 oak_leaves[persistent=true]
setblock ~172 ~139 ~92 jungle_leaves[persistent=true]
setblock ~172 ~140 ~89 oak_leaves[persistent=true]
setblock ~172 ~140 ~90 oak_leaves[persistent=true]
setblock ~172 ~140 ~91 oak_leaves[persistent=true]
setblock ~172 ~140 ~95 oak_leaves[persistent=true]
setblock ~172 ~140 ~96 jungle_leaves[persistent=true]
setblock ~172 ~140 ~97 oak_leaves[persistent=true]
setblock ~172 ~141 ~89 oak_leaves[persistent=true]
setblock ~172 ~141 ~91 oak_leaves[persistent=true]
setblock ~172 ~141 ~92 jungle_leaves[persistent=true]
setblock ~172 ~141 ~95 jungle_leaves[persistent=true]
setblock ~172 ~141 ~96 jungle_leaves[persistent=true]
setblock ~172 ~141 ~97 oak_leaves[persistent=true]
setblock ~172 ~141 ~98 oak_leaves[persistent=true]
setblock ~172 ~142 ~88 oak_leaves[persistent=true]
setblock ~172 ~142 ~89 oak_leaves[persistent=true]
setblock ~172 ~142 ~90 oak_leaves[persistent=true]
setblock ~172 ~142 ~91 oak_leaves[persistent=true]
setblock ~172 ~142 ~95 oak_leaves[persistent=true]
setblock ~172 ~142 ~96 jungle_leaves[persistent=true]
setblock ~172 ~142 ~97 oak_wood
setblock ~172 ~142 ~98 oak_leaves[persistent=true]
setblock ~172 ~143 ~97 oak_leaves[persistent=true]
setblock ~172 ~143 ~98 oak_leaves[persistent=true]
setblock ~172 ~145 ~92 oak_leaves[persistent=true]
setblock ~172 ~145 ~93 jungle_leaves[persistent=true]
setblock ~172 ~145 ~94 oak_leaves[persistent=true]
setblock ~172 ~145 ~95 jungle_leaves[persistent=true]
setblock ~172 ~145 ~96 jungle_leaves[persistent=true]
setblock ~172 ~145 ~97 oak_leaves[persistent=true]
setblock ~172 ~146 ~91 jungle_leaves[persistent=true]
setblock ~172 ~146 ~93 oak_leaves[persistent=true]
setblock ~172 ~146 ~94 oak_leaves[persistent=true]
setblock ~172 ~146 ~95 jungle_leaves[persistent=true]
setblock ~172 ~146 ~96 oak_leaves[persistent=true]
setblock ~172 ~146 ~97 oak_leaves[persistent=true]
setblock ~172 ~147 ~91 jungle_leaves[persistent=true]
setblock ~172 ~147 ~92 jungle_leaves[persistent=true]
setblock ~172 ~147 ~93 oak_leaves[persistent=true]
setblock ~172 ~147 ~94 oak_leaves[persistent=true]
setblock ~172 ~147 ~95 oak_leaves[persistent=true]
setblock ~172 ~147 ~98 oak_leaves[persistent=true]
setblock ~172 ~147 ~99 jungle_leaves[persistent=true]
setblock ~172 ~148 ~91 oak_leaves[persistent=true]
setblock ~172 ~148 ~92 oak_leaves[persistent=true]
setblock ~172 ~148 ~93 oak_leaves[persistent=true]
setblock ~172 ~148 ~94 oak_leaves[persistent=true]
setblock ~172 ~148 ~95 oak_leaves[persistent=true]
setblock ~172 ~148 ~96 jungle_leaves[persistent=true]
setblock ~172 ~148 ~97 oak_leaves[persistent=true]
setblock ~172 ~148 ~98 oak_leaves[persistent=true]
setblock ~172 ~148 ~99 oak_leaves[persistent=true]
setblock ~172 ~148 ~100 oak_leaves[persistent=true]
setblock ~172 ~149 ~91 oak_leaves[persistent=true]
setblock ~172 ~149 ~92 oak_leaves[persistent=true]
setblock ~172 ~149 ~93 jungle_leaves[persistent=true]
setblock ~172 ~149 ~94 oak_leaves[persistent=true]
setblock ~172 ~149 ~95 oak_leaves[persistent=true]
setblock ~172 ~149 ~96 oak_leaves[persistent=true]
setblock ~172 ~149 ~97 oak_leaves[persistent=true]
setblock ~172 ~149 ~98 oak_wood
setblock ~172 ~149 ~100 jungle_leaves[persistent=true]
setblock ~172 ~150 ~83 oak_leaves[persistent=true]
setblock ~172 ~150 ~84 oak_leaves[persistent=true]
setblock ~172 ~150 ~85 oak_leaves[persistent=true]
setblock ~172 ~150 ~90 oak_leaves[persistent=true]
setblock ~172 ~150 ~91 oak_leaves[persistent=true]
setblock ~172 ~150 ~92 oak_leaves[persistent=true]
setblock ~172 ~150 ~93 oak_leaves[persistent=true]
setblock ~172 ~150 ~94 oak_wood
setblock ~172 ~150 ~95 oak_leaves[persistent=true]
setblock ~172 ~150 ~96 oak_leaves[persistent=true]
setblock ~172 ~150 ~97 oak_leaves[persistent=true]
setblock ~172 ~150 ~98 oak_wood
setblock ~172 ~150 ~99 oak_leaves[persistent=true]
setblock ~172 ~150 ~100 oak_leaves[persistent=true]
setblock ~172 ~151 ~83 oak_leaves[persistent=true]
setblock ~172 ~151 ~84 oak_leaves[persistent=true]
setblock ~172 ~151 ~85 oak_leaves[persistent=true]
setblock ~172 ~151 ~86 oak_leaves[persistent=true]
setblock ~172 ~151 ~87 oak_leaves[persistent=true]
setblock ~172 ~151 ~88 oak_leaves[persistent=true]
setblock ~172 ~151 ~89 oak_leaves[persistent=true]
setblock ~172 ~151 ~91 oak_leaves[persistent=true]
setblock ~172 ~151 ~92 oak_leaves[persistent=true]
setblock ~172 ~151 ~93 oak_leaves[persistent=true]
setblock ~172 ~151 ~94 oak_leaves[persistent=true]
setblock ~172 ~151 ~96 oak_wood
setblock ~172 ~151 ~97 oak_leaves[persistent=true]
setblock ~172 ~151 ~98 oak_leaves[persistent=true]
setblock ~172 ~151 ~99 oak_leaves[persistent=true]
setblock ~172 ~152 ~83 jungle_leaves[persistent=true]
setblock ~172 ~152 ~85 oak_leaves[persistent=true]
setblock ~172 ~152 ~87 oak_leaves[persistent=true]
setblock ~172 ~152 ~88 oak_leaves[persistent=true]
setblock ~172 ~152 ~89 oak_leaves[persistent=true]
setblock ~172 ~152 ~90 oak_leaves[persistent=true]
setblock ~172 ~152 ~91 oak_leaves[persistent=true]
setblock ~172 ~152 ~92 oak_wood
setblock ~172 ~152 ~93 oak_wood
setblock ~172 ~152 ~94 oak_wood
setblock ~172 ~152 ~96 oak_leaves[persistent=true]
setblock ~172 ~152 ~97 oak_leaves[persistent=true]
setblock ~172 ~152 ~99 oak_leaves[persistent=true]
setblock ~172 ~153 ~83 oak_leaves[persistent=true]
setblock ~172 ~153 ~85 jungle_leaves[persistent=true]
setblock ~172 ~153 ~86 oak_wood
setblock ~172 ~153 ~87 oak_wood
setblock ~172 ~153 ~88 oak_leaves[persistent=true]
setblock ~172 ~153 ~89 oak_leaves[persistent=true]
setblock ~172 ~153 ~90 oak_leaves[persistent=true]
setblock ~172 ~153 ~91 oak_leaves[persistent=true]
setblock ~172 ~153 ~92 oak_leaves[persistent=true]
setblock ~172 ~153 ~93 oak_wood
setblock ~172 ~153 ~94 oak_leaves[persistent=true]
setblock ~172 ~153 ~95 oak_wood
setblock ~172 ~153 ~96 oak_wood
setblock ~172 ~153 ~97 oak_wood
setblock ~172 ~153 ~98 oak_leaves[persistent=true]
setblock ~172 ~154 ~84 oak_leaves[persistent=true]
setblock ~172 ~154 ~85 oak_leaves[persistent=true]
setblock ~172 ~154 ~86 oak_leaves[persistent=true]
setblock ~172 ~154 ~87 oak_leaves[persistent=true]
setblock ~172 ~154 ~88 oak_leaves[persistent=true]
setblock ~172 ~154 ~89 jungle_leaves[persistent=true]
setblock ~172 ~154 ~90 jungle_leaves[persistent=true]
setblock ~172 ~154 ~91 oak_leaves[persistent=true]
setblock ~172 ~154 ~92 jungle_leaves[persistent=true]
setblock ~172 ~154 ~93 oak_leaves[persistent=true]
setblock ~172 ~154 ~94 oak_leaves[persistent=true]
setblock ~172 ~154 ~95 oak_leaves[persistent=true]
setblock ~172 ~154 ~96 jungle_leaves[persistent=true]
setblock ~172 ~154 ~98 jungle_leaves[persistent=true]
setblock ~172 ~154 ~99 oak_wood
setblock ~172 ~155 ~85 oak_leaves[persistent=true]
setblock ~172 ~155 ~86 oak_leaves[persistent=true]
setblock ~172 ~155 ~87 oak_leaves[persistent=true]
setblock ~172 ~155 ~88 oak_leaves[persistent=true]
setblock ~172 ~155 ~89 oak_wood
setblock ~172 ~155 ~91 oak_leaves[persistent=true]
setblock ~172 ~155 ~92 oak_wood
setblock ~172 ~155 ~93 jungle_leaves[persistent=true]
setblock ~172 ~155 ~94 oak_wood
setblock ~172 ~155 ~95 oak_log
setblock ~172 ~155 ~96 oak_leaves[persistent=true]
setblock ~172 ~155 ~97 oak_leaves[persistent=true]
setblock ~172 ~155 ~98 oak_leaves[persistent=true]
setblock ~172 ~155 ~99 oak_leaves[persistent=true]
setblock ~172 ~156 ~85 oak_leaves[persistent=true]
setblock ~172 ~156 ~86 oak_leaves[persistent=true]
setblock ~172 ~156 ~88 oak_wood
setblock ~172 ~156 ~89 oak_leaves[persistent=true]
setblock ~172 ~156 ~91 oak_leaves[persistent=true]
setblock ~172 ~156 ~92 jungle_leaves[persistent=true]
setblock ~172 ~156 ~93 oak_wood
setblock ~172 ~156 ~94 oak_wood
setblock ~172 ~156 ~95 oak_leaves[persistent=true]
setblock ~172 ~156 ~96 jungle_leaves[persistent=true]
setblock ~172 ~156 ~97 jungle_leaves[persistent=true]
setblock ~172 ~156 ~98 oak_leaves[persistent=true]
setblock ~172 ~156 ~99 oak_leaves[persistent=true]
setblock ~172 ~156 ~100 jungle_leaves[persistent=true]
setblock ~172 ~157 ~84 oak_leaves[persistent=true]
setblock ~172 ~157 ~85 oak_leaves[persistent=true]
setblock ~172 ~157 ~86 oak_leaves[persistent=true]
setblock ~172 ~157 ~87 oak_leaves[persistent=true]
setblock ~172 ~157 ~88 oak_leaves[persistent=true]
setblock ~172 ~157 ~89 oak_leaves[persistent=true]
setblock ~172 ~157 ~90 oak_leaves[persistent=true]
setblock ~172 ~157 ~91 oak_wood
setblock ~172 ~157 ~92 oak_wood
setblock ~172 ~157 ~93 oak_wood
setblock ~172 ~157 ~94 oak_wood
setblock ~172 ~157 ~96 oak_leaves[persistent=true]
setblock ~172 ~157 ~97 oak_wood
setblock ~172 ~157 ~98 oak_leaves[persistent=true]
setblock ~172 ~157 ~99 jungle_leaves[persistent=true]
setblock ~172 ~157 ~100 oak_leaves[persistent=true]
setblock ~172 ~158 ~83 jungle_leaves[persistent=true]
setblock ~172 ~158 ~84 oak_leaves[persistent=true]
setblock ~172 ~158 ~85 oak_leaves[persistent=true]
setblock ~172 ~158 ~86 oak_leaves[persistent=true]
setblock ~172 ~158 ~88 oak_leaves[persistent=true]
setblock ~172 ~158 ~90 oak_wood
setblock ~172 ~158 ~91 oak_wood
setblock ~172 ~158 ~92 oak_wood
setblock ~172 ~158 ~93 oak_wood
setblock ~172 ~158 ~94 oak_log
setblock ~172 ~158 ~95 oak_leaves[persistent=true]
setblock ~172 ~158 ~96 oak_wood
setblock ~172 ~158 ~97 oak_wood
setblock ~172 ~158 ~98 oak_leaves[persistent=true]
setblock ~172 ~158 ~99 oak_leaves[persistent=true]
setblock ~172 ~158 ~101 oak_leaves[persistent=true]
setblock ~172 ~159 ~83 oak_leaves[persistent=true]
setblock ~172 ~159 ~84 oak_leaves[persistent=true]
setblock ~172 ~159 ~85 oak_leaves[persistent=true]
setblock ~172 ~159 ~86 oak_leaves[persistent=true]
setblock ~172 ~159 ~87 oak_leaves[persistent=true]
setblock ~172 ~159 ~88 oak_wood
setblock ~172 ~159 ~89 jungle_leaves[persistent=true]
setblock ~172 ~159 ~90 oak_wood
setblock ~172 ~159 ~91 oak_wood
setblock ~172 ~159 ~92 oak_log
setblock ~172 ~159 ~93 oak_wood
setblock ~172 ~159 ~94 oak_wood
