setblock ~67 ~124 ~84 grass_block
setblock ~67 ~124 ~85 grass_block
setblock ~67 ~124 ~86 grass_block
setblock ~67 ~124 ~87 grass_block
setblock ~67 ~124 ~88 short_grass
setblock ~67 ~124 ~92 grass_block
setblock ~67 ~124 ~93 grass_block
setblock ~67 ~124 ~94 grass_block
setblock ~67 ~124 ~95 dirt
setblock ~67 ~124 ~96 dirt
setblock ~67 ~124 ~97 dirt
setblock ~67 ~124 ~98 dirt
setblock ~67 ~124 ~99 dirt
setblock ~67 ~124 ~100 dirt
setblock ~67 ~124 ~101 dirt
setblock ~67 ~124 ~102 dirt
setblock ~67 ~124 ~103 dirt
setblock ~67 ~124 ~104 dirt
setblock ~67 ~124 ~105 grass_block
setblock ~67 ~124 ~106 grass_block
setblock ~67 ~124 ~107 grass_block
setblock ~67 ~124 ~112 grass_block
setblock ~67 ~124 ~113 grass_block
setblock ~67 ~124 ~114 grass_block
setblock ~67 ~124 ~115 dirt
setblock ~67 ~124 ~116 dirt
setblock ~67 ~124 ~117 dirt
setblock ~67 ~124 ~118 dirt
setblock ~67 ~124 ~119 dirt
setblock ~67 ~124 ~120 dirt
setblock ~67 ~124 ~121 dirt
setblock ~67 ~124 ~122 dirt
setblock ~67 ~124 ~123 dirt
setblock ~67 ~124 ~124 dirt
setblock ~67 ~124 ~125 dirt
setblock ~67 ~124 ~126 grass_block
setblock ~67 ~124 ~127 grass_block
setblock ~67 ~124 ~128 grass_block
setblock ~67 ~124 ~135 short_grass
setblock ~67 ~124 ~141 grass_block
setblock ~67 ~124 ~142 grass_block
setblock ~67 ~124 ~143 grass_block
setblock ~67 ~124 ~144 grass_block
setblock ~67 ~124 ~145 grass_block
setblock ~67 ~124 ~146 grass_block
setblock ~67 ~124 ~147 grass_block
setblock ~67 ~124 ~148 dirt
setblock ~67 ~124 ~149 dirt
setblock ~67 ~124 ~150 dirt
setblock ~67 ~124 ~151 dirt
setblock ~67 ~124 ~152 dirt
setblock ~67 ~124 ~153 dirt
setblock ~67 ~124 ~154 dirt
setblock ~67 ~124 ~155 grass_block
setblock ~67 ~124 ~156 grass_block
setblock ~67 ~124 ~157 grass_block
setblock ~67 ~124 ~158 grass_block
setblock ~67 ~124 ~159 grass_block
setblock ~67 ~124 ~160 grass_block
setblock ~67 ~124 ~161 grass_block
setblock ~67 ~124 ~162 dirt
setblock ~67 ~124 ~163 dirt
setblock ~67 ~124 ~164 dirt
setblock ~67 ~124 ~165 dirt
setblock ~67 ~124 ~166 dirt
setblock ~67 ~124 ~167 dirt
setblock ~67 ~124 ~168 dirt
setblock ~67 ~124 ~169 dirt
setblock ~67 ~124 ~170 dirt
setblock ~67 ~124 ~171 dirt
setblock ~67 ~124 ~172 dirt
setblock ~67 ~124 ~173 dirt
setblock ~67 ~124 ~174 dirt
setblock ~67 ~124 ~175 dirt
setblock ~67 ~124 ~176 dirt
setblock ~67 ~124 ~177 dirt
setblock ~67 ~124 ~178 grass_block
setblock ~67 ~124 ~179 grass_block
setblock ~67 ~124 ~180 grass_block
setblock ~67 ~124 ~181 grass_block
setblock ~67 ~124 ~182 grass_block
setblock ~67 ~124 ~183 grass_block
setblock ~67 ~124 ~184 grass_block
setblock ~67 ~124 ~185 grass_block
setblock ~67 ~124 ~186 grass_block
setblock ~67 ~124 ~187 grass_block
setblock ~67 ~124 ~188 grass_block
setblock ~67 ~124 ~189 grass_block
setblock ~67 ~124 ~190 grass_block
setblock ~67 ~124 ~191 grass_block
setblock ~67 ~124 ~192 grass_block
setblock ~67 ~124 ~193 grass_block
setblock ~67 ~124 ~194 grass_block
setblock ~67 ~124 ~195 grass_block
setblock ~67 ~124 ~196 grass_block
setblock ~67 ~124 ~197 grass_block
setblock ~67 ~124 ~198 dirt
setblock ~67 ~124 ~199 dirt
setblock ~67 ~125 ~6 grass_block
setblock ~67 ~125 ~7 grass_block
setblock ~67 ~125 ~8 grass_block
setblock ~67 ~125 ~9 dirt
setblock ~67 ~125 ~10 dirt
setblock ~67 ~125 ~11 dirt
setblock ~67 ~125 ~12 dirt
setblock ~67 ~125 ~13 dirt
setblock ~67 ~125 ~14 dirt
setblock ~67 ~125 ~15 dirt
setblock ~67 ~125 ~16 dirt
setblock ~67 ~125 ~17 dirt
setblock ~67 ~125 ~18 dirt
setblock ~67 ~125 ~19 dirt
setblock ~67 ~125 ~20 dirt
setblock ~67 ~125 ~21 dirt
setblock ~67 ~125 ~22 dirt
setblock ~67 ~125 ~23 dirt
setblock ~67 ~125 ~24 dirt
setblock ~67 ~125 ~25 dirt
setblock ~67 ~125 ~26 grass_block
setblock ~67 ~125 ~27 grass_block
setblock ~67 ~125 ~28 grass_block
setblock ~67 ~125 ~29 grass_block
setblock ~67 ~125 ~30 grass_block
setblock ~67 ~125 ~31 grass_block
setblock ~67 ~125 ~32 grass_block
setblock ~67 ~125 ~33 grass_block
setblock ~67 ~125 ~34 grass_block
setblock ~67 ~125 ~35 grass_block
setblock ~67 ~125 ~36 grass_block
setblock ~67 ~125 ~37 grass_block
setblock ~67 ~125 ~38 grass_block
setblock ~67 ~125 ~40 short_grass
setblock ~67 ~125 ~41 short_grass
setblock ~67 ~125 ~42 short_grass
setblock ~67 ~125 ~45 short_grass
setblock ~67 ~125 ~46 poppy
setblock ~67 ~125 ~47 fern
setblock ~67 ~125 ~48 short_grass
setblock ~67 ~125 ~53 grass_block
setblock ~67 ~125 ~54 grass_block
setblock ~67 ~125 ~55 grass_block
setblock ~67 ~125 ~56 grass_block
setblock ~67 ~125 ~57 dirt
setblock ~67 ~125 ~58 dirt
setblock ~67 ~125 ~59 dirt
setblock ~67 ~125 ~60 dirt
setblock ~67 ~125 ~61 dirt
setblock ~67 ~125 ~62 dirt
setblock ~67 ~125 ~63 dirt
setblock ~67 ~125 ~64 dirt
setblock ~67 ~125 ~65 dirt
setblock ~67 ~125 ~66 dirt
setblock ~67 ~125 ~67 dirt
setblock ~67 ~125 ~68 dirt
setblock ~67 ~125 ~69 dirt
setblock ~67 ~125 ~70 dirt
setblock ~67 ~125 ~71 dirt
setblock ~67 ~125 ~72 dirt
setblock ~67 ~125 ~73 dirt
setblock ~67 ~125 ~74 dirt
setblock ~67 ~125 ~75 grass_block
setblock ~67 ~125 ~76 grass_block
setblock ~67 ~125 ~77 grass_block
setblock ~67 ~125 ~78 grass_block
setblock ~67 ~125 ~79 grass_block
setblock ~67 ~125 ~80 grass_block
setblock ~67 ~125 ~81 grass_block
setblock ~67 ~125 ~82 grass_block
setblock ~67 ~125 ~84 short_grass
setblock ~67 ~125 ~85 short_grass
setblock ~67 ~125 ~93 short_grass
setblock ~67 ~125 ~94 short_grass
setblock ~67 ~125 ~95 grass_block
setblock ~67 ~125 ~96 grass_block
setblock ~67 ~125 ~97 grass_block
setblock ~67 ~125 ~98 grass_block
setblock ~67 ~125 ~99 grass_block
setblock ~67 ~125 ~100 grass_block
setblock ~67 ~125 ~101 grass_block
setblock ~67 ~125 ~102 grass_block
setblock ~67 ~125 ~103 grass_block
setblock ~67 ~125 ~104 grass_block
setblock ~67 ~125 ~106 short_grass
setblock ~67 ~125 ~115 grass_block
setblock ~67 ~125 ~116 grass_block
setblock ~67 ~125 ~117 dirt
setblock ~67 ~125 ~118 dirt
setblock ~67 ~125 ~119 dirt
setblock ~67 ~125 ~120 dirt
setblock ~67 ~125 ~121 dirt
setblock ~67 ~125 ~122 dirt
setblock ~67 ~125 ~123 dirt
setblock ~67 ~125 ~124 grass_block
setblock ~67 ~125 ~125 grass_block
setblock ~67 ~125 ~142 short_grass
setblock ~67 ~125 ~146 short_grass
setblock ~67 ~125 ~147 short_grass
setblock ~67 ~125 ~148 grass_block
setblock ~67 ~125 ~149 grass_block
setblock ~67 ~125 ~150 grass_block
setblock ~67 ~125 ~151 grass_block
setblock ~67 ~125 ~152 grass_block
setblock ~67 ~125 ~153 grass_block
setblock ~67 ~125 ~154 grass_block
setblock ~67 ~125 ~157 short_grass
setblock ~67 ~125 ~162 grass_block
setblock ~67 ~125 ~163 grass_block
setblock ~67 ~125 ~164 dirt
setblock ~67 ~125 ~165 dirt
setblock ~67 ~125 ~166 dirt
setblock ~67 ~125 ~167 dirt
setblock ~67 ~125 ~168 dirt
setblock ~67 ~125 ~169 dirt
setblock ~67 ~125 ~170 dirt
setblock ~67 ~125 ~171 dirt
setblock ~67 ~125 ~172 dirt
setblock ~67 ~125 ~173 dirt
setblock ~67 ~125 ~174 dirt
setblock ~67 ~125 ~175 dirt
setblock ~67 ~125 ~176 grass_block
setblock ~67 ~125 ~177 grass_block
setblock ~67 ~125 ~178 fern
setblock ~67 ~125 ~179 fern
setblock ~67 ~125 ~183 short_grass
setblock ~67 ~125 ~184 short_grass
setblock ~67 ~125 ~185 short_grass
setblock ~67 ~125 ~186 short_grass
setblock ~67 ~125 ~188 short_grass
setblock ~67 ~125 ~191 short_grass
setblock ~67 ~125 ~192 short_grass
setblock ~67 ~125 ~193 poppy
setblock ~67 ~125 ~198 grass_block
setblock ~67 ~125 ~199 grass_block
setblock ~67 ~126 ~7 short_grass
setblock ~67 ~126 ~9 grass_block
setblock ~67 ~126 ~10 grass_block
setblock ~67 ~126 ~11 grass_block
setblock ~67 ~126 ~12 grass_block
setblock ~67 ~126 ~13 grass_block
setblock ~67 ~126 ~14 grass_block
setblock ~67 ~126 ~15 grass_block
setblock ~67 ~126 ~16 grass_block
setblock ~67 ~126 ~17 grass_block
setblock ~67 ~126 ~18 grass_block
setblock ~67 ~126 ~19 grass_block
setblock ~67 ~126 ~20 grass_block
setblock ~67 ~126 ~21 grass_block
setblock ~67 ~126 ~22 grass_block
setblock ~67 ~126 ~23 grass_block
setblock ~67 ~126 ~24 grass_block
setblock ~67 ~126 ~25 grass_block
setblock ~67 ~126 ~31 short_grass
setblock ~67 ~126 ~36 short_grass
setblock ~67 ~126 ~53 short_grass
setblock ~67 ~126 ~56 short_grass
setblock ~67 ~126 ~57 grass_block
setblock ~67 ~126 ~58 grass_block
setblock ~67 ~126 ~59 grass_block
setblock ~67 ~126 ~60 grass_block
setblock ~67 ~126 ~61 grass_block
setblock ~67 ~126 ~62 grass_block
setblock ~67 ~126 ~63 grass_block
setblock ~67 ~126 ~64 grass_block
setblock ~67 ~126 ~65 grass_block
setblock ~67 ~126 ~66 grass_block
setblock ~67 ~126 ~67 grass_block
setblock ~67 ~126 ~68 grass_block
setblock ~67 ~126 ~69 grass_block
setblock ~67 ~126 ~70 grass_block
setblock ~67 ~126 ~71 grass_block
setblock ~67 ~126 ~72 grass_block
setblock ~67 ~126 ~73 grass_block
setblock ~67 ~126 ~74 grass_block
setblock ~67 ~126 ~76 short_grass
setblock ~67 ~126 ~77 poppy
setblock ~67 ~126 ~78 short_grass
setblock ~67 ~126 ~80 short_grass
setblock ~67 ~126 ~82 short_grass
setblock ~67 ~126 ~95 poppy
setblock ~67 ~126 ~96 short_grass
setblock ~67 ~126 ~97 short_grass
setblock ~67 ~126 ~104 short_grass
setblock ~67 ~126 ~115 short_grass
setblock ~67 ~126 ~117 grass_block
setblock ~67 ~126 ~118 grass_block
setblock ~67 ~126 ~119 dirt
setblock ~67 ~126 ~120 dirt
setblock ~67 ~126 ~121 dirt
setblock ~67 ~126 ~122 grass_block
setblock ~67 ~126 ~123 grass_block
setblock ~67 ~126 ~125 short_grass
setblock ~67 ~126 ~151 poppy
setblock ~67 ~126 ~154 short_grass
setblock ~67 ~126 ~163 short_grass
setblock ~67 ~126 ~164 grass_block
setblock ~67 ~126 ~165 grass_block
setblock ~67 ~126 ~166 dirt
setblock ~67 ~126 ~167 dirt
setblock ~67 ~126 ~168 dirt
setblock ~67 ~126 ~169 dirt
setblock ~67 ~126 ~170 dirt
setblock ~67 ~126 ~171 dirt
setblock ~67 ~126 ~172 dirt
setblock ~67 ~126 ~173 dirt
setblock ~67 ~126 ~174 grass_block
setblock ~67 ~126 ~175 grass_block
setblock ~67 ~127 ~10 short_grass
setblock ~67 ~127 ~13 short_grass
setblock ~67 ~127 ~14 poppy
setblock ~67 ~127 ~16 short_grass
setblock ~67 ~127 ~17 short_grass
setblock ~67 ~127 ~18 short_grass
setblock ~67 ~127 ~20 short_grass
setblock ~67 ~127 ~22 short_grass
setblock ~67 ~127 ~23 short_grass
setblock ~67 ~127 ~24 fern
setblock ~67 ~127 ~60 short_grass
setblock ~67 ~127 ~61 short_grass
setblock ~67 ~127 ~73 short_grass
setblock ~67 ~127 ~118 short_grass
setblock ~67 ~127 ~119 grass_block
setblock ~67 ~127 ~120 grass_block
setblock ~67 ~127 ~121 grass_block
setblock ~67 ~127 ~123 short_grass
setblock ~67 ~127 ~165 short_grass
setblock ~67 ~127 ~166 grass_block
setblock ~67 ~127 ~167 grass_block
setblock ~67 ~127 ~168 grass_block
setblock ~67 ~127 ~169 dirt
setblock ~67 ~127 ~170 dirt
setblock ~67 ~127 ~171 dirt
setblock ~67 ~127 ~172 grass_block
setblock ~67 ~127 ~173 grass_block
setblock ~67 ~127 ~175 short_grass
setblock ~67 ~128 ~119 short_grass
setblock ~67 ~128 ~120 short_grass
setblock ~67 ~128 ~121 short_grass
setblock ~67 ~128 ~169 grass_block
setblock ~67 ~128 ~170 grass_block
setblock ~67 ~128 ~171 grass_block
setblock ~67 ~128 ~173 short_grass
setblock ~68 ~122 ~0 grass_block
setblock ~68 ~122 ~1 dirt
setblock ~68 ~122 ~2 dirt
setblock ~68 ~122 ~3 dirt
setblock ~68 ~122 ~4 dirt
setblock ~68 ~122 ~5 dirt
setblock ~68 ~122 ~6 dirt
setblock ~68 ~122 ~7 dirt
setblock ~68 ~122 ~8 dirt
setblock ~68 ~122 ~9 dirt
setblock ~68 ~122 ~10 dirt
setblock ~68 ~122 ~11 dirt
setblock ~68 ~122 ~12 dirt
setblock ~68 ~122 ~13 dirt
setblock ~68 ~122 ~14 dirt
setblock ~68 ~122 ~15 dirt
setblock ~68 ~122 ~16 dirt
setblock ~68 ~122 ~17 dirt
setblock ~68 ~122 ~18 dirt
setblock ~68 ~122 ~19 dirt
setblock ~68 ~122 ~20 dirt
setblock ~68 ~122 ~21 dirt
setblock ~68 ~122 ~22 dirt
setblock ~68 ~122 ~23 dirt
setblock ~68 ~122 ~24 dirt
setblock ~68 ~122 ~25 dirt
setblock ~68 ~122 ~26 dirt
setblock ~68 ~122 ~27 dirt
setblock ~68 ~122 ~28 dirt
setblock ~68 ~122 ~29 dirt
setblock ~68 ~122 ~30 dirt
setblock ~68 ~122 ~31 dirt
setblock ~68 ~122 ~32 dirt
setblock ~68 ~122 ~33 dirt
setblock ~68 ~122 ~34 dirt
setblock ~68 ~122 ~35 dirt
setblock ~68 ~122 ~36 dirt
setblock ~68 ~122 ~37 dirt
setblock ~68 ~122 ~38 dirt
setblock ~68 ~122 ~39 dirt
setblock ~68 ~122 ~40 dirt
setblock ~68 ~122 ~41 dirt
setblock ~68 ~122 ~42 dirt
setblock ~68 ~122 ~43 dirt
setblock ~68 ~122 ~44 dirt
setblock ~68 ~122 ~45 dirt
setblock ~68 ~122 ~46 dirt
setblock ~68 ~122 ~47 dirt
setblock ~68 ~122 ~48 dirt
setblock ~68 ~122 ~49 dirt
setblock ~68 ~122 ~50 dirt
setblock ~68 ~122 ~51 dirt
setblock ~68 ~122 ~52 dirt
setblock ~68 ~122 ~53 dirt
setblock ~68 ~122 ~54 dirt
setblock ~68 ~122 ~55 dirt
setblock ~68 ~122 ~56 dirt
setblock ~68 ~122 ~57 dirt
setblock ~68 ~122 ~58 dirt
setblock ~68 ~122 ~59 dirt
setblock ~68 ~122 ~60 dirt
setblock ~68 ~122 ~61 dirt
setblock ~68 ~122 ~62 dirt
setblock ~68 ~122 ~63 dirt
setblock ~68 ~122 ~64 dirt
setblock ~68 ~122 ~65 dirt
setblock ~68 ~122 ~66 dirt
setblock ~68 ~122 ~67 dirt
setblock ~68 ~122 ~68 dirt
setblock ~68 ~122 ~69 dirt
setblock ~68 ~122 ~70 dirt
setblock ~68 ~122 ~71 dirt
setblock ~68 ~122 ~72 dirt
setblock ~68 ~122 ~73 dirt
setblock ~68 ~122 ~74 dirt
setblock ~68 ~122 ~75 dirt
setblock ~68 ~122 ~76 dirt
setblock ~68 ~122 ~77 dirt
setblock ~68 ~122 ~78 dirt
setblock ~68 ~122 ~79 dirt
setblock ~68 ~122 ~80 dirt
setblock ~68 ~122 ~81 dirt
setblock ~68 ~122 ~82 dirt
setblock ~68 ~122 ~83 dirt
setblock ~68 ~122 ~84 dirt
setblock ~68 ~122 ~85 dirt
setblock ~68 ~122 ~86 dirt
setblock ~68 ~122 ~87 dirt
setblock ~68 ~122 ~88 dirt
setblock ~68 ~122 ~89 dirt
setblock ~68 ~122 ~90 dirt
setblock ~68 ~122 ~91 dirt
setblock ~68 ~122 ~92 dirt
setblock ~68 ~122 ~93 dirt
setblock ~68 ~122 ~94 dirt
setblock ~68 ~122 ~95 dirt
setblock ~68 ~122 ~96 dirt
setblock ~68 ~122 ~97 dirt
setblock ~68 ~122 ~98 dirt
setblock ~68 ~122 ~99 dirt
setblock ~68 ~122 ~100 dirt
setblock ~68 ~122 ~101 dirt
setblock ~68 ~122 ~102 dirt
setblock ~68 ~122 ~103 dirt
setblock ~68 ~122 ~104 dirt
setblock ~68 ~122 ~105 dirt
setblock ~68 ~122 ~106 dirt
setblock ~68 ~122 ~107 dirt
setblock ~68 ~122 ~108 dirt
setblock ~68 ~122 ~109 dirt
setblock ~68 ~122 ~110 dirt
setblock ~68 ~122 ~111 dirt
setblock ~68 ~122 ~112 dirt
setblock ~68 ~122 ~113 dirt
setblock ~68 ~122 ~114 dirt
setblock ~68 ~122 ~115 dirt
setblock ~68 ~122 ~116 dirt
setblock ~68 ~122 ~117 dirt
setblock ~68 ~122 ~118 dirt
setblock ~68 ~122 ~119 dirt
setblock ~68 ~122 ~120 dirt
setblock ~68 ~122 ~121 dirt
setblock ~68 ~122 ~122 dirt
setblock ~68 ~122 ~123 dirt
setblock ~68 ~122 ~124 dirt
setblock ~68 ~122 ~125 dirt
setblock ~68 ~122 ~126 dirt
setblock ~68 ~122 ~127 dirt
setblock ~68 ~122 ~128 dirt
setblock ~68 ~122 ~129 dirt
setblock ~68 ~122 ~130 grass_block
setblock ~68 ~122 ~131 dirt
setblock ~68 ~122 ~132 dirt
setblock ~68 ~122 ~133 dirt
setblock ~68 ~122 ~134 dirt
setblock ~68 ~122 ~135 dirt
setblock ~68 ~122 ~136 dirt
setblock ~68 ~122 ~137 dirt
setblock ~68 ~122 ~138 dirt
setblock ~68 ~122 ~139 dirt
setblock ~68 ~122 ~140 dirt
setblock ~68 ~122 ~141 dirt
setblock ~68 ~122 ~142 dirt
setblock ~68 ~122 ~143 dirt
setblock ~68 ~122 ~144 dirt
setblock ~68 ~122 ~145 dirt
setblock ~68 ~122 ~146 dirt
setblock ~68 ~122 ~147 dirt
setblock ~68 ~122 ~148 dirt
setblock ~68 ~122 ~149 dirt
setblock ~68 ~122 ~150 dirt
setblock ~68 ~122 ~151 dirt
setblock ~68 ~122 ~152 dirt
setblock ~68 ~122 ~153 dirt
setblock ~68 ~122 ~154 dirt
setblock ~68 ~122 ~155 dirt
setblock ~68 ~122 ~156 dirt
setblock ~68 ~122 ~157 dirt
setblock ~68 ~122 ~158 dirt
setblock ~68 ~122 ~159 dirt
setblock ~68 ~122 ~160 dirt
setblock ~68 ~122 ~161 dirt
setblock ~68 ~122 ~162 dirt
setblock ~68 ~122 ~163 dirt
setblock ~68 ~122 ~164 dirt
setblock ~68 ~122 ~165 dirt
setblock ~68 ~122 ~166 dirt
setblock ~68 ~122 ~167 dirt
setblock ~68 ~122 ~168 dirt
setblock ~68 ~122 ~169 dirt
setblock ~68 ~122 ~170 dirt
setblock ~68 ~122 ~171 dirt
setblock ~68 ~122 ~172 dirt
setblock ~68 ~122 ~173 dirt
setblock ~68 ~122 ~174 dirt
setblock ~68 ~122 ~175 dirt
setblock ~68 ~122 ~176 dirt
setblock ~68 ~122 ~177 dirt
setblock ~68 ~122 ~178 dirt
setblock ~68 ~122 ~179 dirt
setblock ~68 ~122 ~180 dirt
setblock ~68 ~122 ~181 dirt
setblock ~68 ~122 ~182 dirt
setblock ~68 ~122 ~183 dirt
setblock ~68 ~122 ~184 dirt
setblock ~68 ~122 ~185 dirt
setblock ~68 ~122 ~186 dirt
setblock ~68 ~122 ~187 dirt
setblock ~68 ~122 ~188 dirt
setblock ~68 ~122 ~189 dirt
setblock ~68 ~122 ~190 dirt
setblock ~68 ~122 ~191 dirt
setblock ~68 ~122 ~192 dirt
setblock ~68 ~122 ~193 dirt
setblock ~68 ~122 ~194 dirt
setblock ~68 ~122 ~195 dirt
setblock ~68 ~122 ~196 dirt
setblock ~68 ~122 ~197 dirt
setblock ~68 ~122 ~198 dirt
setblock ~68 ~122 ~199 dirt
setblock ~68 ~123 ~1 grass_block
setblock ~68 ~123 ~2 grass_block
setblock ~68 ~123 ~3 grass_block
setblock ~68 ~123 ~4 dirt
setblock ~68 ~123 ~5 dirt
setblock ~68 ~123 ~6 dirt
setblock ~68 ~123 ~7 dirt
setblock ~68 ~123 ~8 dirt
setblock ~68 ~123 ~9 dirt
setblock ~68 ~123 ~10 dirt
setblock ~68 ~123 ~11 dirt
setblock ~68 ~123 ~12 dirt
setblock ~68 ~123 ~13 dirt
setblock ~68 ~123 ~14 dirt
setblock ~68 ~123 ~15 dirt
setblock ~68 ~123 ~16 dirt
setblock ~68 ~123 ~17 dirt
setblock ~68 ~123 ~18 dirt
setblock ~68 ~123 ~19 dirt
setblock ~68 ~123 ~20 dirt
setblock ~68 ~123 ~21 dirt
setblock ~68 ~123 ~22 dirt
setblock ~68 ~123 ~23 dirt
setblock ~68 ~123 ~24 dirt
setblock ~68 ~123 ~25 dirt
setblock ~68 ~123 ~26 dirt
setblock ~68 ~123 ~27 dirt
setblock ~68 ~123 ~28 dirt
setblock ~68 ~123 ~29 dirt
setblock ~68 ~123 ~30 dirt
setblock ~68 ~123 ~31 dirt
setblock ~68 ~123 ~32 dirt
setblock ~68 ~123 ~33 dirt
setblock ~68 ~123 ~34 dirt
setblock ~68 ~123 ~35 dirt
setblock ~68 ~123 ~36 dirt
setblock ~68 ~123 ~37 dirt
setblock ~68 ~123 ~38 dirt
setblock ~68 ~123 ~39 dirt
setblock ~68 ~123 ~40 dirt
setblock ~68 ~123 ~41 dirt
setblock ~68 ~123 ~42 dirt
setblock ~68 ~123 ~43 dirt
setblock ~68 ~123 ~44 dirt
setblock ~68 ~123 ~45 dirt
setblock ~68 ~123 ~46 dirt
setblock ~68 ~123 ~47 dirt
setblock ~68 ~123 ~48 dirt
setblock ~68 ~123 ~49 dirt
setblock ~68 ~123 ~50 dirt
setblock ~68 ~123 ~51 dirt
setblock ~68 ~123 ~52 dirt
setblock ~68 ~123 ~53 dirt
setblock ~68 ~123 ~54 dirt
setblock ~68 ~123 ~55 dirt
setblock ~68 ~123 ~56 dirt
setblock ~68 ~123 ~57 dirt
setblock ~68 ~123 ~58 dirt
setblock ~68 ~123 ~59 dirt
setblock ~68 ~123 ~60 dirt
setblock ~68 ~123 ~61 dirt
setblock ~68 ~123 ~62 dirt
setblock ~68 ~123 ~63 dirt
setblock ~68 ~123 ~64 dirt
setblock ~68 ~123 ~65 dirt
setblock ~68 ~123 ~66 dirt
setblock ~68 ~123 ~67 dirt
setblock ~68 ~123 ~68 dirt
setblock ~68 ~123 ~69 dirt
setblock ~68 ~123 ~70 dirt
setblock ~68 ~123 ~71 dirt
setblock ~68 ~123 ~72 dirt
setblock ~68 ~123 ~73 dirt
setblock ~68 ~123 ~74 dirt
setblock ~68 ~123 ~75 dirt
setblock ~68 ~123 ~76 dirt
setblock ~68 ~123 ~77 dirt
setblock ~68 ~123 ~78 dirt
setblock ~68 ~123 ~79 dirt
setblock ~68 ~123 ~80 dirt
setblock ~68 ~123 ~81 dirt
setblock ~68 ~123 ~82 dirt
setblock ~68 ~123 ~83 dirt
setblock ~68 ~123 ~84 dirt
setblock ~68 ~123 ~85 dirt
setblock ~68 ~123 ~86 dirt
setblock ~68 ~123 ~87 grass_block
setblock ~68 ~123 ~88 grass_block
setblock ~68 ~123 ~89 grass_block
setblock ~68 ~123 ~90 grass_block
setblock ~68 ~123 ~91 grass_block
setblock ~68 ~123 ~92 dirt
setblock ~68 ~123 ~93 dirt
setblock ~68 ~123 ~94 dirt
setblock ~68 ~123 ~95 dirt
setblock ~68 ~123 ~96 dirt
setblock ~68 ~123 ~97 dirt
setblock ~68 ~123 ~98 dirt
setblock ~68 ~123 ~99 dirt
setblock ~68 ~123 ~100 dirt
setblock ~68 ~123 ~101 dirt
setblock ~68 ~123 ~102 dirt
setblock ~68 ~123 ~103 dirt
setblock ~68 ~123 ~104 dirt
setblock ~68 ~123 ~105 dirt
setblock ~68 ~123 ~106 dirt
setblock ~68 ~123 ~107 dirt
setblock ~68 ~123 ~108 grass_block
setblock ~68 ~123 ~109 grass_block
setblock ~68 ~123 ~110 grass_block
setblock ~68 ~123 ~111 grass_block
setblock ~68 ~123 ~112 dirt
setblock ~68 ~123 ~113 dirt
setblock ~68 ~123 ~114 dirt
setblock ~68 ~123 ~115 dirt
setblock ~68 ~123 ~116 dirt
setblock ~68 ~123 ~117 dirt
setblock ~68 ~123 ~118 dirt
setblock ~68 ~123 ~119 dirt
setblock ~68 ~123 ~120 dirt
setblock ~68 ~123 ~121 dirt
setblock ~68 ~123 ~122 dirt
setblock ~68 ~123 ~123 dirt
setblock ~68 ~123 ~124 dirt
setblock ~68 ~123 ~125 dirt
setblock ~68 ~123 ~126 dirt
setblock ~68 ~123 ~127 dirt
setblock ~68 ~123 ~128 dirt
setblock ~68 ~123 ~129 grass_block
setblock ~68 ~123 ~130 poppy
setblock ~68 ~123 ~131 grass_block
setblock ~68 ~123 ~132 grass_block
setblock ~68 ~123 ~133 grass_block
setblock ~68 ~123 ~134 grass_block
setblock ~68 ~123 ~135 grass_block
setblock ~68 ~123 ~136 grass_block
setblock ~68 ~123 ~137 grass_block
setblock ~68 ~123 ~138 grass_block
setblock ~68 ~123 ~139 dirt
setblock ~68 ~123 ~140 dirt
setblock ~68 ~123 ~141 dirt
setblock ~68 ~123 ~142 dirt
setblock ~68 ~123 ~143 dirt
setblock ~68 ~123 ~144 dirt
setblock ~68 ~123 ~145 dirt
setblock ~68 ~123 ~146 dirt
setblock ~68 ~123 ~147 dirt
setblock ~68 ~123 ~148 dirt
setblock ~68 ~123 ~149 dirt
setblock ~68 ~123 ~150 dirt
setblock ~68 ~123 ~151 dirt
setblock ~68 ~123 ~152 dirt
setblock ~68 ~123 ~153 dirt
setblock ~68 ~123 ~154 dirt
setblock ~68 ~123 ~155 dirt
setblock ~68 ~123 ~156 dirt
setblock ~68 ~123 ~157 dirt
setblock ~68 ~123 ~158 dirt
setblock ~68 ~123 ~159 dirt
setblock ~68 ~123 ~160 dirt
setblock ~68 ~123 ~161 dirt
setblock ~68 ~123 ~162 dirt
setblock ~68 ~123 ~163 dirt
setblock ~68 ~123 ~164 dirt
setblock ~68 ~123 ~165 dirt
setblock ~68 ~123 ~166 dirt
setblock ~68 ~123 ~167 dirt
setblock ~68 ~123 ~168 dirt
setblock ~68 ~123 ~169 dirt
setblock ~68 ~123 ~170 dirt
setblock ~68 ~123 ~171 dirt
setblock ~68 ~123 ~172 dirt
setblock ~68 ~123 ~173 dirt
setblock ~68 ~123 ~174 dirt
setblock ~68 ~123 ~175 dirt
setblock ~68 ~123 ~176 dirt
setblock ~68 ~123 ~177 dirt
setblock ~68 ~123 ~178 dirt
setblock ~68 ~123 ~179 dirt
setblock ~68 ~123 ~180 grass_block
setblock ~68 ~123 ~181 grass_block
setblock ~68 ~123 ~182 dirt
setblock ~68 ~123 ~183 dirt
setblock ~68 ~123 ~184 dirt
setblock ~68 ~123 ~185 dirt
setblock ~68 ~123 ~186 dirt
setblock ~68 ~123 ~187 dirt
setblock ~68 ~123 ~188 dirt
setblock ~68 ~123 ~189 dirt
setblock ~68 ~123 ~190 dirt
setblock ~68 ~123 ~191 dirt
setblock ~68 ~123 ~192 dirt
setblock ~68 ~123 ~193 dirt
setblock ~68 ~123 ~194 dirt
setblock ~68 ~123 ~195 dirt
setblock ~68 ~123 ~196 dirt
setblock ~68 ~123 ~197 dirt
setblock ~68 ~123 ~198 dirt
setblock ~68 ~123 ~199 dirt
setblock ~68 ~124 ~1 short_grass
setblock ~68 ~124 ~4 grass_block
setblock ~68 ~124 ~5 grass_block
setblock ~68 ~124 ~6 dirt
setblock ~68 ~124 ~7 dirt
setblock ~68 ~124 ~8 dirt
setblock ~68 ~124 ~9 dirt
setblock ~68 ~124 ~10 dirt
setblock ~68 ~124 ~11 dirt
setblock ~68 ~124 ~12 dirt
setblock ~68 ~124 ~13 dirt
setblock ~68 ~124 ~14 dirt
setblock ~68 ~124 ~15 dirt
setblock ~68 ~124 ~16 dirt
setblock ~68 ~124 ~17 dirt
setblock ~68 ~124 ~18 dirt
setblock ~68 ~124 ~19 dirt
setblock ~68 ~124 ~20 dirt
setblock ~68 ~124 ~21 dirt
setblock ~68 ~124 ~22 dirt
setblock ~68 ~124 ~23 dirt
setblock ~68 ~124 ~24 dirt
setblock ~68 ~124 ~25 dirt
setblock ~68 ~124 ~26 dirt
setblock ~68 ~124 ~27 dirt
setblock ~68 ~124 ~28 dirt
setblock ~68 ~124 ~29 dirt
setblock ~68 ~124 ~30 grass_block
setblock ~68 ~124 ~31 grass_block
setblock ~68 ~124 ~32 grass_block
setblock ~68 ~124 ~33 grass_block
setblock ~68 ~124 ~34 grass_block
setblock ~68 ~124 ~35 grass_block
setblock ~68 ~124 ~36 grass_block
setblock ~68 ~124 ~37 grass_block
setblock ~68 ~124 ~38 grass_block
setblock ~68 ~124 ~39 grass_block
setblock ~68 ~124 ~40 grass_block
setblock ~68 ~124 ~41 grass_block
setblock ~68 ~124 ~42 grass_block
setblock ~68 ~124 ~43 grass_block
setblock ~68 ~124 ~44 grass_block
setblock ~68 ~124 ~45 grass_block
setblock ~68 ~124 ~46 grass_block
setblock ~68 ~124 ~47 grass_block
setblock ~68 ~124 ~48 grass_block
setblock ~68 ~124 ~49 grass_block
setblock ~68 ~124 ~50 grass_block
setblock ~68 ~124 ~51 grass_block
setblock ~68 ~124 ~52 grass_block
setblock ~68 ~124 ~53 grass_block
setblock ~68 ~124 ~54 dirt
setblock ~68 ~124 ~55 dirt
setblock ~68 ~124 ~56 dirt
setblock ~68 ~124 ~57 dirt
setblock ~68 ~124 ~58 dirt
setblock ~68 ~124 ~59 dirt
setblock ~68 ~124 ~60 dirt
setblock ~68 ~124 ~61 dirt
setblock ~68 ~124 ~62 dirt
setblock ~68 ~124 ~63 dirt
setblock ~68 ~124 ~64 dirt
setblock ~68 ~124 ~65 dirt
setblock ~68 ~124 ~66 dirt
setblock ~68 ~124 ~67 dirt
setblock ~68 ~124 ~68 dirt
setblock ~68 ~124 ~69 dirt
setblock ~68 ~124 ~70 dirt
setblock ~68 ~124 ~71 dirt
setblock ~68 ~124 ~72 dirt
setblock ~68 ~124 ~73 dirt
setblock ~68 ~124 ~74 dirt
setblock ~68 ~124 ~75 dirt
setblock ~68 ~124 ~76 dirt
setblock ~68 ~124 ~77 dirt
setblock ~68 ~124 ~78 dirt
setblock ~68 ~124 ~79 dirt
setblock ~68 ~124 ~80 dirt
setblock ~68 ~124 ~81 grass_block
setblock ~68 ~124 ~82 grass_block
setblock ~68 ~124 ~83 grass_block
setblock ~68 ~124 ~84 grass_block
setblock ~68 ~124 ~85 grass_block
setblock ~68 ~124 ~86 grass_block
setblock ~68 ~124 ~87 poppy
setblock ~68 ~124 ~88 fern
setblock ~68 ~124 ~91 short_grass
setblock ~68 ~124 ~92 grass_block
setblock ~68 ~124 ~93 grass_block
setblock ~68 ~124 ~94 grass_block
setblock ~68 ~124 ~95 dirt
setblock ~68 ~124 ~96 dirt
setblock ~68 ~124 ~97 dirt
setblock ~68 ~124 ~98 dirt
setblock ~68 ~124 ~99 dirt
setblock ~68 ~124 ~100 dirt
setblock ~68 ~124 ~101 dirt
setblock ~68 ~124 ~102 dirt
setblock ~68 ~124 ~103 dirt
setblock ~68 ~124 ~104 dirt
setblock ~68 ~124 ~105 grass_block
setblock ~68 ~124 ~106 grass_block
setblock ~68 ~124 ~107 grass_block
setblock ~68 ~124 ~109 short_grass
setblock ~68 ~124 ~110 short_grass
setblock ~68 ~124 ~111 short_grass
setblock ~68 ~124 ~112 grass_block
setblock ~68 ~124 ~113 grass_block
setblock ~68 ~124 ~114 dirt
setblock ~68 ~124 ~115 dirt
setblock ~68 ~124 ~116 dirt
setblock ~68 ~124 ~117 dirt
setblock ~68 ~124 ~118 dirt
setblock ~68 ~124 ~119 dirt
setblock ~68 ~124 ~120 dirt
setblock ~68 ~124 ~121 dirt
setblock ~68 ~124 ~122 dirt
setblock ~68 ~124 ~123 dirt
setblock ~68 ~124 ~124 dirt
setblock ~68 ~124 ~125 dirt
setblock ~68 ~124 ~126 dirt
setblock ~68 ~124 ~127 grass_block
setblock ~68 ~124 ~128 grass_block
setblock ~68 ~124 ~133 short_grass
setblock ~68 ~124 ~138 short_grass
setblock ~68 ~124 ~139 grass_block
setblock ~68 ~124 ~140 grass_block
setblock ~68 ~124 ~141 grass_block
setblock ~68 ~124 ~142 grass_block
setblock ~68 ~124 ~143 grass_block
setblock ~68 ~124 ~144 grass_block
setblock ~68 ~124 ~145 grass_block
setblock ~68 ~124 ~146 grass_block
setblock ~68 ~124 ~147 grass_block
setblock ~68 ~124 ~148 grass_block
setblock ~68 ~124 ~149 grass_block
setblock ~68 ~124 ~150 grass_block
setblock ~68 ~124 ~151 grass_block
setblock ~68 ~124 ~152 grass_block
setblock ~68 ~124 ~153 grass_block
setblock ~68 ~124 ~154 grass_block
setblock ~68 ~124 ~155 grass_block
setblock ~68 ~124 ~156 grass_block
setblock ~68 ~124 ~157 grass_block
setblock ~68 ~124 ~158 grass_block
setblock ~68 ~124 ~159 grass_block
setblock ~68 ~124 ~160 grass_block
setblock ~68 ~124 ~161 grass_block
setblock ~68 ~124 ~162 dirt
setblock ~68 ~124 ~163 dirt
setblock ~68 ~124 ~164 dirt
setblock ~68 ~124 ~165 dirt
setblock ~68 ~124 ~166 dirt
setblock ~68 ~124 ~167 dirt
setblock ~68 ~124 ~168 dirt
setblock ~68 ~124 ~169 dirt
setblock ~68 ~124 ~170 dirt
setblock ~68 ~124 ~171 dirt
setblock ~68 ~124 ~172 dirt
setblock ~68 ~124 ~173 dirt
setblock ~68 ~124 ~174 dirt
setblock ~68 ~124 ~175 dirt
setblock ~68 ~124 ~176 dirt
setblock ~68 ~124 ~177 dirt
setblock ~68 ~124 ~178 grass_block
setblock ~68 ~124 ~179 grass_block
setblock ~68 ~124 ~182 grass_block
setblock ~68 ~124 ~183 grass_block
setblock ~68 ~124 ~184 grass_block
setblock ~68 ~124 ~185 grass_block
setblock ~68 ~124 ~186 grass_block
setblock ~68 ~124 ~187 grass_block
setblock ~68 ~124 ~188 grass_block
setblock ~68 ~124 ~189 grass_block
setblock ~68 ~124 ~190 grass_block
setblock ~68 ~124 ~191 grass_block
setblock ~68 ~124 ~192 grass_block
setblock ~68 ~124 ~193 grass_block
setblock ~68 ~124 ~194 grass_block
setblock ~68 ~124 ~195 grass_block
setblock ~68 ~124 ~196 grass_block
setblock ~68 ~124 ~197 grass_block
setblock ~68 ~124 ~198 dirt
setblock ~68 ~124 ~199 dirt
setblock ~68 ~125 ~6 grass_block
setblock ~68 ~125 ~7 grass_block
setblock ~68 ~125 ~8 grass_block
setblock ~68 ~125 ~9 dirt
setblock ~68 ~125 ~10 dirt
setblock ~68 ~125 ~11 dirt
setblock ~68 ~125 ~12 dirt
setblock ~68 ~125 ~13 dirt
setblock ~68 ~125 ~14 dirt
setblock ~68 ~125 ~15 dirt
setblock ~68 ~125 ~16 dirt
setblock ~68 ~125 ~17 dirt
setblock ~68 ~125 ~18 dirt
setblock ~68 ~125 ~19 dirt
setblock ~68 ~125 ~20 dirt
setblock ~68 ~125 ~21 dirt
setblock ~68 ~125 ~22 dirt
setblock ~68 ~125 ~23 dirt
setblock ~68 ~125 ~24 grass_block
setblock ~68 ~125 ~25 grass_block
setblock ~68 ~125 ~26 grass_block
setblock ~68 ~125 ~27 grass_block
setblock ~68 ~125 ~28 grass_block
setblock ~68 ~125 ~29 grass_block
setblock ~68 ~125 ~32 short_grass
setblock ~68 ~125 ~34 poppy
setblock ~68 ~125 ~35 short_grass
setblock ~68 ~125 ~46 short_grass
setblock ~68 ~125 ~49 short_grass
setblock ~68 ~125 ~50 short_grass
setblock ~68 ~125 ~51 short_grass
setblock ~68 ~125 ~54 grass_block
setblock ~68 ~125 ~55 grass_block
setblock ~68 ~125 ~56 grass_block
setblock ~68 ~125 ~57 grass_block
setblock ~68 ~125 ~58 dirt
setblock ~68 ~125 ~59 dirt
setblock ~68 ~125 ~60 dirt
setblock ~68 ~125 ~61 dirt
setblock ~68 ~125 ~62 dirt
setblock ~68 ~125 ~63 dirt
setblock ~68 ~125 ~64 dirt
setblock ~68 ~125 ~65 dirt
setblock ~68 ~125 ~66 dirt
setblock ~68 ~125 ~67 dirt
setblock ~68 ~125 ~68 dirt
setblock ~68 ~125 ~69 dirt
setblock ~68 ~125 ~70 dirt
setblock ~68 ~125 ~71 dirt
setblock ~68 ~125 ~72 dirt
setblock ~68 ~125 ~73 dirt
setblock ~68 ~125 ~74 grass_block
setblock ~68 ~125 ~75 grass_block
setblock ~68 ~125 ~76 grass_block
setblock ~68 ~125 ~77 grass_block
setblock ~68 ~125 ~78 grass_block
setblock ~68 ~125 ~79 grass_block
setblock ~68 ~125 ~80 grass_block
setblock ~68 ~125 ~81 short_grass
setblock ~68 ~125 ~84 short_grass
setblock ~68 ~125 ~85 short_grass
setblock ~68 ~125 ~95 grass_block
setblock ~68 ~125 ~96 grass_block
setblock ~68 ~125 ~97 grass_block
setblock ~68 ~125 ~98 grass_block
setblock ~68 ~125 ~99 grass_block
setblock ~68 ~125 ~100 grass_block
setblock ~68 ~125 ~101 grass_block
setblock ~68 ~125 ~102 grass_block
setblock ~68 ~125 ~103 grass_block
setblock ~68 ~125 ~104 grass_block
setblock ~68 ~125 ~112 short_grass
setblock ~68 ~125 ~114 grass_block
setblock ~68 ~125 ~115 grass_block
setblock ~68 ~125 ~116 dirt
setblock ~68 ~125 ~117 dirt
setblock ~68 ~125 ~118 dirt
setblock ~68 ~125 ~119 dirt
setblock ~68 ~125 ~120 dirt
setblock ~68 ~125 ~121 dirt
setblock ~68 ~125 ~122 dirt
setblock ~68 ~125 ~123 dirt
setblock ~68 ~125 ~124 dirt
setblock ~68 ~125 ~125 grass_block
setblock ~68 ~125 ~126 grass_block
setblock ~68 ~125 ~144 short_grass
setblock ~68 ~125 ~146 poppy
setblock ~68 ~125 ~148 short_grass
setblock ~68 ~125 ~150 short_grass
setblock ~68 ~125 ~153 short_grass
setblock ~68 ~125 ~154 fern
setblock ~68 ~125 ~156 short_grass
setblock ~68 ~125 ~158 fern
setblock ~68 ~125 ~159 short_grass
setblock ~68 ~125 ~162 grass_block
setblock ~68 ~125 ~163 grass_block
setblock ~68 ~125 ~164 dirt
setblock ~68 ~125 ~165 dirt
setblock ~68 ~125 ~166 dirt
setblock ~68 ~125 ~167 dirt
setblock ~68 ~125 ~168 dirt
setblock ~68 ~125 ~169 dirt
setblock ~68 ~125 ~170 dirt
setblock ~68 ~125 ~171 dirt
setblock ~68 ~125 ~172 dirt
setblock ~68 ~125 ~173 dirt
setblock ~68 ~125 ~174 dirt
setblock ~68 ~125 ~175 dirt
setblock ~68 ~125 ~176 grass_block
setblock ~68 ~125 ~177 grass_block
setblock ~68 ~125 ~178 short_grass
setblock ~68 ~125 ~183 short_grass
setblock ~68 ~125 ~188 short_grass
setblock ~68 ~125 ~192 short_grass
setblock ~68 ~125 ~193 short_grass
setblock ~68 ~125 ~195 short_grass
setblock ~68 ~125 ~198 grass_block
setblock ~68 ~125 ~199 grass_block
setblock ~68 ~126 ~9 grass_block
setblock ~68 ~126 ~10 grass_block
setblock ~68 ~126 ~11 grass_block
setblock ~68 ~126 ~12 grass_block
setblock ~68 ~126 ~13 grass_block
setblock ~68 ~126 ~14 grass_block
setblock ~68 ~126 ~15 grass_block
setblock ~68 ~126 ~16 grass_block
setblock ~68 ~126 ~17 grass_block
setblock ~68 ~126 ~18 grass_block
setblock ~68 ~126 ~19 grass_block
setblock ~68 ~126 ~20 grass_block
setblock ~68 ~126 ~21 grass_block
setblock ~68 ~126 ~22 grass_block
setblock ~68 ~126 ~23 grass_block
setblock ~68 ~126 ~27 short_grass
setblock ~68 ~126 ~54 short_grass
setblock ~68 ~126 ~55 fern
setblock ~68 ~126 ~58 grass_block
setblock ~68 ~126 ~59 grass_block
setblock ~68 ~126 ~60 grass_block
setblock ~68 ~126 ~61 grass_block
setblock ~68 ~126 ~62 grass_block
setblock ~68 ~126 ~63 grass_block
setblock ~68 ~126 ~64 grass_block
setblock ~68 ~126 ~65 grass_block
setblock ~68 ~126 ~66 grass_block
setblock ~68 ~126 ~67 grass_block
setblock ~68 ~126 ~68 grass_block
setblock ~68 ~126 ~69 grass_block
setblock ~68 ~126 ~70 grass_block
setblock ~68 ~126 ~71 grass_block
setblock ~68 ~126 ~72 grass_block
setblock ~68 ~126 ~73 grass_block
setblock ~68 ~126 ~74 short_grass
setblock ~68 ~126 ~76 short_grass
setblock ~68 ~126 ~80 fern
setblock ~68 ~126 ~95 short_grass
setblock ~68 ~126 ~98 short_grass
setblock ~68 ~126 ~99 short_grass
setblock ~68 ~126 ~101 fern
setblock ~68 ~126 ~114 short_grass
setblock ~68 ~126 ~116 grass_block
setblock ~68 ~126 ~117 grass_block
setblock ~68 ~126 ~118 dirt
setblock ~68 ~126 ~119 dirt
setblock ~68 ~126 ~120 dirt
setblock ~68 ~126 ~121 dirt
setblock ~68 ~126 ~122 dirt
setblock ~68 ~126 ~123 grass_block
setblock ~68 ~126 ~124 grass_block
setblock ~68 ~126 ~125 short_grass
setblock ~68 ~126 ~164 grass_block
setblock ~68 ~126 ~165 grass_block
setblock ~68 ~126 ~166 grass_block
setblock ~68 ~126 ~167 dirt
setblock ~68 ~126 ~168 dirt
setblock ~68 ~126 ~169 dirt
setblock ~68 ~126 ~170 dirt
setblock ~68 ~126 ~171 dirt
setblock ~68 ~126 ~172 dirt
setblock ~68 ~126 ~173 dirt
setblock ~68 ~126 ~174 grass_block
setblock ~68 ~126 ~175 grass_block
setblock ~68 ~126 ~177 poppy
setblock ~68 ~126 ~199 short_grass
setblock ~68 ~127 ~13 short_grass
setblock ~68 ~127 ~60 short_grass
setblock ~68 ~127 ~61 short_grass
setblock ~68 ~127 ~62 short_grass
setblock ~68 ~127 ~63 short_grass
setblock ~68 ~127 ~68 short_grass
setblock ~68 ~127 ~69 short_grass
setblock ~68 ~127 ~70 poppy
setblock ~68 ~127 ~116 short_grass
setblock ~68 ~127 ~118 grass_block
setblock ~68 ~127 ~119 grass_block
setblock ~68 ~127 ~120 dirt
setblock ~68 ~127 ~121 grass_block
setblock ~68 ~127 ~122 grass_block
setblock ~68 ~127 ~123 poppy
setblock ~68 ~127 ~167 grass_block
setblock ~68 ~127 ~168 grass_block
setblock ~68 ~127 ~169 dirt
setblock ~68 ~127 ~170 dirt
setblock ~68 ~127 ~171 dirt
setblock ~68 ~127 ~172 grass_block
setblock ~68 ~127 ~173 grass_block
setblock ~68 ~128 ~118 short_grass
setblock ~68 ~128 ~119 short_grass
setblock ~68 ~128 ~120 grass_block
setblock ~68 ~128 ~169 grass_block
setblock ~68 ~128 ~170 grass_block
setblock ~68 ~128 ~171 grass_block
setblock ~69 ~122 ~0 grass_block
setblock ~69 ~122 ~1 grass_block
setblock ~69 ~122 ~2 dirt
setblock ~69 ~122 ~3 dirt
setblock ~69 ~122 ~4 dirt
setblock ~69 ~122 ~5 dirt
setblock ~69 ~122 ~6 dirt
setblock ~69 ~122 ~7 dirt
setblock ~69 ~122 ~8 dirt
setblock ~69 ~122 ~9 dirt
setblock ~69 ~122 ~10 dirt
setblock ~69 ~122 ~11 dirt
setblock ~69 ~122 ~12 dirt
setblock ~69 ~122 ~13 dirt
setblock ~69 ~122 ~14 dirt
setblock ~69 ~122 ~15 dirt
setblock ~69 ~122 ~16 dirt
setblock ~69 ~122 ~17 dirt
setblock ~69 ~122 ~18 dirt
setblock ~69 ~122 ~19 dirt
setblock ~69 ~122 ~20 dirt
setblock ~69 ~122 ~21 dirt
setblock ~69 ~122 ~22 dirt
setblock ~69 ~122 ~23 dirt
setblock ~69 ~122 ~24 dirt
setblock ~69 ~122 ~25 dirt
setblock ~69 ~122 ~26 dirt
setblock ~69 ~122 ~27 dirt
setblock ~69 ~122 ~28 dirt
setblock ~69 ~122 ~29 dirt
setblock ~69 ~122 ~30 dirt
setblock ~69 ~122 ~31 dirt
setblock ~69 ~122 ~32 dirt
setblock ~69 ~122 ~33 dirt
setblock ~69 ~122 ~34 dirt
setblock ~69 ~122 ~35 dirt
setblock ~69 ~122 ~36 dirt
setblock ~69 ~122 ~37 dirt
setblock ~69 ~122 ~38 dirt
setblock ~69 ~122 ~39 dirt
setblock ~69 ~122 ~40 dirt
setblock ~69 ~122 ~41 dirt
setblock ~69 ~122 ~42 dirt
setblock ~69 ~122 ~43 dirt
setblock ~69 ~122 ~44 dirt
setblock ~69 ~122 ~45 dirt
setblock ~69 ~122 ~46 dirt
setblock ~69 ~122 ~47 dirt
setblock ~69 ~122 ~48 dirt
setblock ~69 ~122 ~49 dirt
setblock ~69 ~122 ~50 dirt
setblock ~69 ~122 ~51 dirt
setblock ~69 ~122 ~52 dirt
setblock ~69 ~122 ~53 dirt
setblock ~69 ~122 ~54 dirt
setblock ~69 ~122 ~55 dirt
setblock ~69 ~122 ~56 dirt
setblock ~69 ~122 ~57 dirt
setblock ~69 ~122 ~58 dirt
setblock ~69 ~122 ~59 dirt
setblock ~69 ~122 ~60 dirt
setblock ~69 ~122 ~61 dirt
setblock ~69 ~122 ~62 dirt
setblock ~69 ~122 ~63 dirt
setblock ~69 ~122 ~64 dirt
setblock ~69 ~122 ~65 dirt
setblock ~69 ~122 ~66 dirt
setblock ~69 ~122 ~67 dirt
setblock ~69 ~122 ~68 dirt
setblock ~69 ~122 ~69 dirt
setblock ~69 ~122 ~70 dirt
setblock ~69 ~122 ~71 dirt
setblock ~69 ~122 ~72 dirt
setblock ~69 ~122 ~73 dirt
setblock ~69 ~122 ~74 dirt
setblock ~69 ~122 ~75 dirt
setblock ~69 ~122 ~76 dirt
setblock ~69 ~122 ~77 dirt
setblock ~69 ~122 ~78 dirt
setblock ~69 ~122 ~79 dirt
setblock ~69 ~122 ~80 dirt
setblock ~69 ~122 ~81 dirt
setblock ~69 ~122 ~82 dirt
setblock ~69 ~122 ~83 dirt
setblock ~69 ~122 ~84 dirt
setblock ~69 ~122 ~85 dirt
setblock ~69 ~122 ~86 dirt
setblock ~69 ~122 ~87 dirt
setblock ~69 ~122 ~88 dirt
setblock ~69 ~122 ~89 dirt
setblock ~69 ~122 ~90 dirt
setblock ~69 ~122 ~91 dirt
setblock ~69 ~122 ~92 dirt
setblock ~69 ~122 ~93 dirt
setblock ~69 ~122 ~94 dirt
setblock ~69 ~122 ~95 dirt
setblock ~69 ~122 ~96 dirt
setblock ~69 ~122 ~97 dirt
setblock ~69 ~122 ~98 dirt
setblock ~69 ~122 ~99 dirt
setblock ~69 ~122 ~100 dirt
setblock ~69 ~122 ~101 dirt
setblock ~69 ~122 ~102 dirt
setblock ~69 ~122 ~103 dirt
setblock ~69 ~122 ~104 dirt
setblock ~69 ~122 ~105 dirt
setblock ~69 ~122 ~106 dirt
setblock ~69 ~122 ~107 dirt
setblock ~69 ~122 ~108 dirt
setblock ~69 ~122 ~109 dirt
setblock ~69 ~122 ~110 dirt
setblock ~69 ~122 ~111 dirt
setblock ~69 ~122 ~112 dirt
setblock ~69 ~122 ~113 dirt
setblock ~69 ~122 ~114 dirt
setblock ~69 ~122 ~115 dirt
setblock ~69 ~122 ~116 dirt
setblock ~69 ~122 ~117 dirt
setblock ~69 ~122 ~118 dirt
setblock ~69 ~122 ~119 dirt
setblock ~69 ~122 ~120 dirt
setblock ~69 ~122 ~121 dirt
setblock ~69 ~122 ~122 dirt
setblock ~69 ~122 ~123 dirt
setblock ~69 ~122 ~124 dirt
setblock ~69 ~122 ~125 dirt
setblock ~69 ~122 ~126 dirt
setblock ~69 ~122 ~127 dirt
setblock ~69 ~122 ~128 dirt
setblock ~69 ~122 ~129 dirt
setblock ~69 ~122 ~130 grass_block
setblock ~69 ~122 ~131 dirt
setblock ~69 ~122 ~132 dirt
setblock ~69 ~122 ~133 dirt
setblock ~69 ~122 ~134 dirt
setblock ~69 ~122 ~135 dirt
setblock ~69 ~122 ~136 dirt
setblock ~69 ~122 ~137 dirt
setblock ~69 ~122 ~138 dirt
setblock ~69 ~122 ~139 dirt
setblock ~69 ~122 ~140 dirt
setblock ~69 ~122 ~141 dirt
setblock ~69 ~122 ~142 dirt
setblock ~69 ~122 ~143 dirt
setblock ~69 ~122 ~144 dirt
setblock ~69 ~122 ~145 dirt
setblock ~69 ~122 ~146 dirt
setblock ~69 ~122 ~147 dirt
setblock ~69 ~122 ~148 dirt
setblock ~69 ~122 ~149 dirt
setblock ~69 ~122 ~150 dirt
setblock ~69 ~122 ~151 dirt
setblock ~69 ~122 ~152 dirt
setblock ~69 ~122 ~153 dirt
setblock ~69 ~122 ~154 dirt
setblock ~69 ~122 ~155 dirt
setblock ~69 ~122 ~156 dirt
setblock ~69 ~122 ~157 dirt
setblock ~69 ~122 ~158 dirt
setblock ~69 ~122 ~159 dirt
setblock ~69 ~122 ~160 dirt
setblock ~69 ~122 ~161 dirt
setblock ~69 ~122 ~162 dirt
setblock ~69 ~122 ~163 dirt
setblock ~69 ~122 ~164 dirt
setblock ~69 ~122 ~165 dirt
setblock ~69 ~122 ~166 dirt
setblock ~69 ~122 ~167 dirt
setblock ~69 ~122 ~168 dirt
setblock ~69 ~122 ~169 dirt
setblock ~69 ~122 ~170 dirt
setblock ~69 ~122 ~171 dirt
setblock ~69 ~122 ~172 dirt
setblock ~69 ~122 ~173 dirt
setblock ~69 ~122 ~174 dirt
setblock ~69 ~122 ~175 dirt
setblock ~69 ~122 ~176 dirt
setblock ~69 ~122 ~177 dirt
setblock ~69 ~122 ~178 dirt
setblock ~69 ~122 ~179 dirt
setblock ~69 ~122 ~180 dirt
setblock ~69 ~122 ~181 dirt
setblock ~69 ~122 ~182 dirt
setblock ~69 ~122 ~183 dirt
setblock ~69 ~122 ~184 dirt
setblock ~69 ~122 ~185 dirt
setblock ~69 ~122 ~186 dirt
setblock ~69 ~122 ~187 dirt
setblock ~69 ~122 ~188 dirt
setblock ~69 ~122 ~189 dirt
setblock ~69 ~122 ~190 dirt
setblock ~69 ~122 ~191 dirt
setblock ~69 ~122 ~192 dirt
setblock ~69 ~122 ~193 dirt
setblock ~69 ~122 ~194 dirt
setblock ~69 ~122 ~195 dirt
setblock ~69 ~122 ~196 dirt
setblock ~69 ~122 ~197 dirt
setblock ~69 ~122 ~198 dirt
setblock ~69 ~122 ~199 dirt
setblock ~69 ~123 ~0 short_grass
setblock ~69 ~123 ~2 grass_block
setblock ~69 ~123 ~3 grass_block
setblock ~69 ~123 ~4 dirt
setblock ~69 ~123 ~5 dirt
setblock ~69 ~123 ~6 dirt
setblock ~69 ~123 ~7 dirt
setblock ~69 ~123 ~8 dirt
setblock ~69 ~123 ~9 dirt
setblock ~69 ~123 ~10 dirt
setblock ~69 ~123 ~11 dirt
setblock ~69 ~123 ~12 dirt
setblock ~69 ~123 ~13 dirt
setblock ~69 ~123 ~14 dirt
setblock ~69 ~123 ~15 dirt
setblock ~69 ~123 ~16 dirt
setblock ~69 ~123 ~17 dirt
setblock ~69 ~123 ~18 dirt
setblock ~69 ~123 ~19 dirt
setblock ~69 ~123 ~20 dirt
setblock ~69 ~123 ~21 dirt
setblock ~69 ~123 ~22 dirt
setblock ~69 ~123 ~23 dirt
setblock ~69 ~123 ~24 dirt
setblock ~69 ~123 ~25 dirt
setblock ~69 ~123 ~26 dirt
setblock ~69 ~123 ~27 dirt
setblock ~69 ~123 ~28 dirt
setblock ~69 ~123 ~29 dirt
setblock ~69 ~123 ~30 dirt
setblock ~69 ~123 ~31 dirt
setblock ~69 ~123 ~32 dirt
setblock ~69 ~123 ~33 dirt
setblock ~69 ~123 ~34 dirt
setblock ~69 ~123 ~35 dirt
setblock ~69 ~123 ~36 dirt
setblock ~69 ~123 ~37 grass_block
setblock ~69 ~123 ~38 grass_block
setblock ~69 ~123 ~39 grass_block
setblock ~69 ~123 ~40 grass_block
setblock ~69 ~123 ~41 grass_block
setblock ~69 ~123 ~42 dirt
setblock ~69 ~123 ~43 dirt
setblock ~69 ~123 ~44 dirt
setblock ~69 ~123 ~45 dirt
setblock ~69 ~123 ~46 dirt
setblock ~69 ~123 ~47 dirt
setblock ~69 ~123 ~48 dirt
setblock ~69 ~123 ~49 dirt
setblock ~69 ~123 ~50 grass_block
setblock ~69 ~123 ~51 dirt
setblock ~69 ~123 ~52 dirt
setblock ~69 ~123 ~53 dirt
setblock ~69 ~123 ~54 dirt
setblock ~69 ~123 ~55 dirt
setblock ~69 ~123 ~56 dirt
setblock ~69 ~123 ~57 dirt
setblock ~69 ~123 ~58 dirt
setblock ~69 ~123 ~59 dirt
setblock ~69 ~123 ~60 dirt
setblock ~69 ~123 ~61 dirt
setblock ~69 ~123 ~62 dirt
setblock ~69 ~123 ~63 dirt
setblock ~69 ~123 ~64 dirt
setblock ~69 ~123 ~65 dirt
setblock ~69 ~123 ~66 dirt
setblock ~69 ~123 ~67 dirt
setblock ~69 ~123 ~68 dirt
setblock ~69 ~123 ~69 dirt
setblock ~69 ~123 ~70 dirt
setblock ~69 ~123 ~71 dirt
setblock ~69 ~123 ~72 dirt
setblock ~69 ~123 ~73 dirt
setblock ~69 ~123 ~74 dirt
setblock ~69 ~123 ~75 dirt
setblock ~69 ~123 ~76 dirt
setblock ~69 ~123 ~77 dirt
setblock ~69 ~123 ~78 dirt
setblock ~69 ~123 ~79 dirt
setblock ~69 ~123 ~80 dirt
setblock ~69 ~123 ~81 dirt
setblock ~69 ~123 ~82 dirt
setblock ~69 ~123 ~83 dirt
setblock ~69 ~123 ~84 dirt
setblock ~69 ~123 ~85 grass_block
setblock ~69 ~123 ~86 grass_block
setblock ~69 ~123 ~87 grass_block
setblock ~69 ~123 ~88 grass_block
setblock ~69 ~123 ~89 grass_block
setblock ~69 ~123 ~90 grass_block
setblock ~69 ~123 ~91 grass_block
setblock ~69 ~123 ~92 dirt
setblock ~69 ~123 ~93 dirt
setblock ~69 ~123 ~94 dirt
setblock ~69 ~123 ~95 dirt
setblock ~69 ~123 ~96 dirt
setblock ~69 ~123 ~97 dirt
setblock ~69 ~123 ~98 dirt
setblock ~69 ~123 ~99 dirt
setblock ~69 ~123 ~100 dirt
setblock ~69 ~123 ~101 dirt
setblock ~69 ~123 ~102 dirt
setblock ~69 ~123 ~103 dirt
setblock ~69 ~123 ~104 dirt
setblock ~69 ~123 ~105 dirt
setblock ~69 ~123 ~106 dirt
setblock ~69 ~123 ~107 dirt
setblock ~69 ~123 ~108 grass_block
setblock ~69 ~123 ~109 grass_block
setblock ~69 ~123 ~110 grass_block
setblock ~69 ~123 ~111 grass_block
setblock ~69 ~123 ~112 dirt
setblock ~69 ~123 ~113 dirt
setblock ~69 ~123 ~114 dirt
setblock ~69 ~123 ~115 dirt
setblock ~69 ~123 ~116 dirt
setblock ~69 ~123 ~117 dirt
setblock ~69 ~123 ~118 dirt
setblock ~69 ~123 ~119 dirt
setblock ~69 ~123 ~120 dirt
setblock ~69 ~123 ~121 dirt
setblock ~69 ~123 ~122 dirt
setblock ~69 ~123 ~123 dirt
setblock ~69 ~123 ~124 dirt
setblock ~69 ~123 ~125 dirt
setblock ~69 ~123 ~126 dirt
setblock ~69 ~123 ~127 dirt
setblock ~69 ~123 ~128 dirt
setblock ~69 ~123 ~129 grass_block
setblock ~69 ~123 ~131 grass_block
setblock ~69 ~123 ~132 grass_block
setblock ~69 ~123 ~133 grass_block
setblock ~69 ~123 ~134 grass_block
setblock ~69 ~123 ~135 grass_block
setblock ~69 ~123 ~136 grass_block
setblock ~69 ~123 ~137 dirt
setblock ~69 ~123 ~138 dirt
setblock ~69 ~123 ~139 dirt
setblock ~69 ~123 ~140 dirt
setblock ~69 ~123 ~141 dirt
setblock ~69 ~123 ~142 dirt
setblock ~69 ~123 ~143 dirt
setblock ~69 ~123 ~144 dirt
setblock ~69 ~123 ~145 dirt
setblock ~69 ~123 ~146 dirt
setblock ~69 ~123 ~147 dirt
setblock ~69 ~123 ~148 dirt
setblock ~69 ~123 ~149 dirt
setblock ~69 ~123 ~150 dirt
setblock ~69 ~123 ~151 dirt
setblock ~69 ~123 ~152 dirt
setblock ~69 ~123 ~153 dirt
setblock ~69 ~123 ~154 dirt
setblock ~69 ~123 ~155 dirt
setblock ~69 ~123 ~156 dirt
setblock ~69 ~123 ~157 dirt
setblock ~69 ~123 ~158 dirt
setblock ~69 ~123 ~159 dirt
setblock ~69 ~123 ~160 dirt
setblock ~69 ~123 ~161 dirt
setblock ~69 ~123 ~162 dirt
setblock ~69 ~123 ~163 dirt
setblock ~69 ~123 ~164 dirt
setblock ~69 ~123 ~165 dirt
setblock ~69 ~123 ~166 dirt
setblock ~69 ~123 ~167 dirt
setblock ~69 ~123 ~168 dirt
setblock ~69 ~123 ~169 dirt
setblock ~69 ~123 ~170 dirt
setblock ~69 ~123 ~171 dirt
setblock ~69 ~123 ~172 dirt
setblock ~69 ~123 ~173 dirt
setblock ~69 ~123 ~174 dirt
setblock ~69 ~123 ~175 dirt
setblock ~69 ~123 ~176 dirt
setblock ~69 ~123 ~177 dirt
setblock ~69 ~123 ~178 dirt
setblock ~69 ~123 ~179 dirt
setblock ~69 ~123 ~180 grass_block
setblock ~69 ~123 ~181 grass_block
setblock ~69 ~123 ~182 grass_block
setblock ~69 ~123 ~183 grass_block
setblock ~69 ~123 ~184 grass_block
setblock ~69 ~123 ~185 grass_block
setblock ~69 ~123 ~186 grass_block
setblock ~69 ~123 ~187 grass_block
setblock ~69 ~123 ~188 grass_block
setblock ~69 ~123 ~189 grass_block
setblock ~69 ~123 ~190 grass_block
setblock ~69 ~123 ~191 grass_block
setblock ~69 ~123 ~192 dirt
setblock ~69 ~123 ~193 dirt
setblock ~69 ~123 ~194 dirt
setblock ~69 ~123 ~195 dirt
setblock ~69 ~123 ~196 dirt
setblock ~69 ~123 ~197 dirt
setblock ~69 ~123 ~198 dirt
setblock ~69 ~123 ~199 dirt
setblock ~69 ~124 ~2 poppy
setblock ~69 ~124 ~4 grass_block
setblock ~69 ~124 ~5 grass_block
setblock ~69 ~124 ~6 dirt
setblock ~69 ~124 ~7 dirt
setblock ~69 ~124 ~8 dirt
setblock ~69 ~124 ~9 dirt
setblock ~69 ~124 ~10 dirt
setblock ~69 ~124 ~11 dirt
setblock ~69 ~124 ~12 dirt
setblock ~69 ~124 ~13 dirt
setblock ~69 ~124 ~14 dirt
setblock ~69 ~124 ~15 dirt
setblock ~69 ~124 ~16 dirt
setblock ~69 ~124 ~17 dirt
setblock ~69 ~124 ~18 dirt
setblock ~69 ~124 ~19 dirt
setblock ~69 ~124 ~20 dirt
setblock ~69 ~124 ~21 dirt
setblock ~69 ~124 ~22 dirt
setblock ~69 ~124 ~23 dirt
setblock ~69 ~124 ~24 dirt
setblock ~69 ~124 ~25 dirt
setblock ~69 ~124 ~26 dirt
setblock ~69 ~124 ~27 dirt
setblock ~69 ~124 ~28 grass_block
setblock ~69 ~124 ~29 grass_block
setblock ~69 ~124 ~30 grass_block
setblock ~69 ~124 ~31 grass_block
setblock ~69 ~124 ~32 grass_block
setblock ~69 ~124 ~33 grass_block
setblock ~69 ~124 ~34 grass_block
setblock ~69 ~124 ~35 grass_block
setblock ~69 ~124 ~36 grass_block
setblock ~69 ~124 ~40 short_grass
setblock ~69 ~124 ~42 grass_block
setblock ~69 ~124 ~43 grass_block
setblock ~69 ~124 ~44 grass_block
setblock ~69 ~124 ~45 grass_block
setblock ~69 ~124 ~46 grass_block
setblock ~69 ~124 ~47 grass_block
setblock ~69 ~124 ~48 grass_block
setblock ~69 ~124 ~49 grass_block
setblock ~69 ~124 ~51 grass_block
setblock ~69 ~124 ~52 grass_block
setblock ~69 ~124 ~53 grass_block
setblock ~69 ~124 ~54 grass_block
setblock ~69 ~124 ~55 dirt
setblock ~69 ~124 ~56 dirt
setblock ~69 ~124 ~57 dirt
setblock ~69 ~124 ~58 dirt
setblock ~69 ~124 ~59 dirt
setblock ~69 ~124 ~60 dirt
setblock ~69 ~124 ~61 dirt
setblock ~69 ~124 ~62 dirt
setblock ~69 ~124 ~63 dirt
setblock ~69 ~124 ~64 dirt
setblock ~69 ~124 ~65 dirt
setblock ~69 ~124 ~66 dirt
setblock ~69 ~124 ~67 dirt
setblock ~69 ~124 ~68 dirt
setblock ~69 ~124 ~69 dirt
setblock ~69 ~124 ~70 dirt
setblock ~69 ~124 ~71 dirt
setblock ~69 ~124 ~72 dirt
setblock ~69 ~124 ~73 dirt
setblock ~69 ~124 ~74 dirt
setblock ~69 ~124 ~75 dirt
setblock ~69 ~124 ~76 dirt
setblock ~69 ~124 ~77 dirt
setblock ~69 ~124 ~78 dirt
setblock ~69 ~124 ~79 grass_block
setblock ~69 ~124 ~80 grass_block
setblock ~69 ~124 ~81 grass_block
setblock ~69 ~124 ~82 grass_block
setblock ~69 ~124 ~83 grass_block
setblock ~69 ~124 ~84 grass_block
setblock ~69 ~124 ~85 short_grass
setblock ~69 ~124 ~87 short_grass
setblock ~69 ~124 ~90 short_grass
setblock ~69 ~124 ~91 short_grass
setblock ~69 ~124 ~92 grass_block
setblock ~69 ~124 ~93 grass_block
setblock ~69 ~124 ~94 grass_block
setblock ~69 ~124 ~95 dirt
setblock ~69 ~124 ~96 dirt
setblock ~69 ~124 ~97 dirt
setblock ~69 ~124 ~98 dirt
setblock ~69 ~124 ~99 dirt
setblock ~69 ~124 ~100 dirt
setblock ~69 ~124 ~101 dirt
setblock ~69 ~124 ~102 dirt
setblock ~69 ~124 ~103 dirt
setblock ~69 ~124 ~104 dirt
setblock ~69 ~124 ~105 grass_block
setblock ~69 ~124 ~106 grass_block
setblock ~69 ~124 ~107 grass_block
setblock ~69 ~124 ~110 short_grass
setblock ~69 ~124 ~111 short_grass
setblock ~69 ~124 ~112 grass_block
setblock ~69 ~124 ~113 grass_block
setblock ~69 ~124 ~114 dirt
setblock ~69 ~124 ~115 dirt
setblock ~69 ~124 ~116 dirt
setblock ~69 ~124 ~117 dirt
setblock ~69 ~124 ~118 dirt
setblock ~69 ~124 ~119 dirt
setblock ~69 ~124 ~120 dirt
setblock ~69 ~124 ~121 dirt
setblock ~69 ~124 ~122 dirt
setblock ~69 ~124 ~123 dirt
setblock ~69 ~124 ~124 dirt
setblock ~69 ~124 ~125 dirt
setblock ~69 ~124 ~126 dirt
setblock ~69 ~124 ~127 grass_block
setblock ~69 ~124 ~128 grass_block
setblock ~69 ~124 ~134 short_grass
setblock ~69 ~124 ~135 short_grass
setblock ~69 ~124 ~137 grass_block
setblock ~69 ~124 ~138 grass_block
setblock ~69 ~124 ~139 grass_block
setblock ~69 ~124 ~140 grass_block
setblock ~69 ~124 ~141 grass_block
setblock ~69 ~124 ~142 grass_block
setblock ~69 ~124 ~143 grass_block
setblock ~69 ~124 ~144 grass_block
setblock ~69 ~124 ~145 grass_block
setblock ~69 ~124 ~146 grass_block
setblock ~69 ~124 ~147 grass_block
setblock ~69 ~124 ~148 grass_block
setblock ~69 ~124 ~149 grass_block
setblock ~69 ~124 ~150 grass_block
setblock ~69 ~124 ~151 grass_block
setblock ~69 ~124 ~152 grass_block
setblock ~69 ~124 ~153 grass_block
setblock ~69 ~124 ~154 grass_block
setblock ~69 ~124 ~155 grass_block
setblock ~69 ~124 ~156 grass_block
setblock ~69 ~124 ~157 grass_block
setblock ~69 ~124 ~158 grass_block
setblock ~69 ~124 ~159 grass_block
setblock ~69 ~124 ~160 grass_block
setblock ~69 ~124 ~161 grass_block
setblock ~69 ~124 ~162 dirt
setblock ~69 ~124 ~163 dirt
setblock ~69 ~124 ~164 dirt
setblock ~69 ~124 ~165 dirt
setblock ~69 ~124 ~166 dirt
setblock ~69 ~124 ~167 dirt
setblock ~69 ~124 ~168 dirt
setblock ~69 ~124 ~169 dirt
setblock ~69 ~124 ~170 dirt
setblock ~69 ~124 ~171 dirt
setblock ~69 ~124 ~172 dirt
setblock ~69 ~124 ~173 dirt
setblock ~69 ~124 ~174 dirt
setblock ~69 ~124 ~175 dirt
setblock ~69 ~124 ~176 dirt
setblock ~69 ~124 ~177 grass_block
setblock ~69 ~124 ~178 grass_block
setblock ~69 ~124 ~179 grass_block
setblock ~69 ~124 ~185 short_grass
setblock ~69 ~124 ~186 short_grass
setblock ~69 ~124 ~192 grass_block
setblock ~69 ~124 ~193 grass_block
setblock ~69 ~124 ~194 grass_block
setblock ~69 ~124 ~195 grass_block
setblock ~69 ~124 ~196 grass_block
setblock ~69 ~124 ~197 grass_block
setblock ~69 ~124 ~198 grass_block
setblock ~69 ~124 ~199 dirt
setblock ~69 ~125 ~6 grass_block
setblock ~69 ~125 ~7 grass_block
setblock ~69 ~125 ~8 grass_block
setblock ~69 ~125 ~9 dirt
setblock ~69 ~125 ~10 dirt
setblock ~69 ~125 ~11 dirt
setblock ~69 ~125 ~12 dirt
setblock ~69 ~125 ~13 dirt
setblock ~69 ~125 ~14 dirt
setblock ~69 ~125 ~15 dirt
setblock ~69 ~125 ~16 dirt
setblock ~69 ~125 ~17 dirt
setblock ~69 ~125 ~18 dirt
setblock ~69 ~125 ~19 dirt
setblock ~69 ~125 ~20 dirt
setblock ~69 ~125 ~21 dirt
setblock ~69 ~125 ~22 dirt
setblock ~69 ~125 ~23 grass_block
setblock ~69 ~125 ~24 grass_block
setblock ~69 ~125 ~25 grass_block
setblock ~69 ~125 ~26 grass_block
setblock ~69 ~125 ~27 grass_block
setblock ~69 ~125 ~30 short_grass
setblock ~69 ~125 ~31 short_grass
setblock ~69 ~125 ~32 short_grass
setblock ~69 ~125 ~33 short_grass
setblock ~69 ~125 ~34 fern
setblock ~69 ~125 ~35 short_grass
setblock ~69 ~125 ~36 short_grass
setblock ~69 ~125 ~42 short_grass
setblock ~69 ~125 ~45 short_grass
setblock ~69 ~125 ~53 short_grass
setblock ~69 ~125 ~54 fern
setblock ~69 ~125 ~55 grass_block
setblock ~69 ~125 ~56 grass_block
setblock ~69 ~125 ~57 grass_block
setblock ~69 ~125 ~58 dirt
setblock ~69 ~125 ~59 dirt
setblock ~69 ~125 ~60 dirt
setblock ~69 ~125 ~61 dirt
setblock ~69 ~125 ~62 dirt
setblock ~69 ~125 ~63 dirt
setblock ~69 ~125 ~64 dirt
setblock ~69 ~125 ~65 dirt
setblock ~69 ~125 ~66 dirt
setblock ~69 ~125 ~67 dirt
setblock ~69 ~125 ~68 dirt
setblock ~69 ~125 ~69 dirt
setblock ~69 ~125 ~70 dirt
setblock ~69 ~125 ~71 dirt
setblock ~69 ~125 ~72 dirt
setblock ~69 ~125 ~73 grass_block
setblock ~69 ~125 ~74 grass_block
setblock ~69 ~125 ~75 grass_block
setblock ~69 ~125 ~76 grass_block
setblock ~69 ~125 ~77 grass_block
setblock ~69 ~125 ~78 grass_block
setblock ~69 ~125 ~79 short_grass
setblock ~69 ~125 ~83 short_grass
setblock ~69 ~125 ~93 short_grass
setblock ~69 ~125 ~94 short_grass
setblock ~69 ~125 ~95 grass_block
setblock ~69 ~125 ~96 grass_block
setblock ~69 ~125 ~97 grass_block
setblock ~69 ~125 ~98 grass_block
setblock ~69 ~125 ~99 grass_block
setblock ~69 ~125 ~100 grass_block
setblock ~69 ~125 ~101 grass_block
setblock ~69 ~125 ~102 grass_block
setblock ~69 ~125 ~103 grass_block
setblock ~69 ~125 ~104 grass_block
setblock ~69 ~125 ~107 short_grass
setblock ~69 ~125 ~114 grass_block
setblock ~69 ~125 ~115 grass_block
setblock ~69 ~125 ~116 dirt
setblock ~69 ~125 ~117 dirt
setblock ~69 ~125 ~118 dirt
setblock ~69 ~125 ~119 dirt
setblock ~69 ~125 ~120 dirt
setblock ~69 ~125 ~121 dirt
setblock ~69 ~125 ~122 dirt
setblock ~69 ~125 ~123 dirt
setblock ~69 ~125 ~124 dirt
setblock ~69 ~125 ~125 grass_block
setblock ~69 ~125 ~126 grass_block
setblock ~69 ~125 ~137 short_grass
setblock ~69 ~125 ~138 short_grass
setblock ~69 ~125 ~141 short_grass
setblock ~69 ~125 ~142 fern
setblock ~69 ~125 ~144 short_grass
setblock ~69 ~125 ~150 fern
setblock ~69 ~125 ~155 fern
setblock ~69 ~125 ~159 short_grass
setblock ~69 ~125 ~161 poppy
setblock ~69 ~125 ~162 grass_block
setblock ~69 ~125 ~163 grass_block
setblock ~69 ~125 ~164 grass_block
setblock ~69 ~125 ~165 dirt
setblock ~69 ~125 ~166 dirt
setblock ~69 ~125 ~167 dirt
setblock ~69 ~125 ~168 dirt
setblock ~69 ~125 ~169 dirt
setblock ~69 ~125 ~170 dirt
setblock ~69 ~125 ~171 dirt
setblock ~69 ~125 ~172 dirt
setblock ~69 ~125 ~173 dirt
setblock ~69 ~125 ~174 dirt
setblock ~69 ~125 ~175 grass_block
setblock ~69 ~125 ~176 grass_block
setblock ~69 ~125 ~198 short_grass
setblock ~69 ~125 ~199 grass_block
setblock ~69 ~126 ~9 grass_block
setblock ~69 ~126 ~10 grass_block
setblock ~69 ~126 ~11 grass_block
setblock ~69 ~126 ~12 grass_block
setblock ~69 ~126 ~13 grass_block
setblock ~69 ~126 ~14 grass_block
setblock ~69 ~126 ~15 grass_block
setblock ~69 ~126 ~16 grass_block
setblock ~69 ~126 ~17 grass_block
setblock ~69 ~126 ~18 grass_block
setblock ~69 ~126 ~19 grass_block
setblock ~69 ~126 ~20 grass_block
setblock ~69 ~126 ~21 grass_block
setblock ~69 ~126 ~22 grass_block
setblock ~69 ~126 ~26 short_grass
setblock ~69 ~126 ~56 short_grass
setblock ~69 ~126 ~58 grass_block
setblock ~69 ~126 ~59 grass_block
setblock ~69 ~126 ~60 grass_block
setblock ~69 ~126 ~61 grass_block
setblock ~69 ~126 ~62 grass_block
setblock ~69 ~126 ~63 grass_block
setblock ~69 ~126 ~64 grass_block
setblock ~69 ~126 ~65 grass_block
setblock ~69 ~126 ~66 grass_block
setblock ~69 ~126 ~67 grass_block
setblock ~69 ~126 ~68 grass_block
setblock ~69 ~126 ~69 grass_block
setblock ~69 ~126 ~70 grass_block
setblock ~69 ~126 ~71 grass_block
setblock ~69 ~126 ~72 grass_block
setblock ~69 ~126 ~74 short_grass
setblock ~69 ~126 ~75 short_grass
setblock ~69 ~126 ~76 short_grass
setblock ~69 ~126 ~95 poppy
setblock ~69 ~126 ~96 short_grass
setblock ~69 ~126 ~97 short_grass
setblock ~69 ~126 ~99 fern
setblock ~69 ~126 ~100 fern
setblock ~69 ~126 ~104 short_grass
setblock ~69 ~126 ~114 short_grass
setblock ~69 ~126 ~116 grass_block
setblock ~69 ~126 ~117 grass_block
setblock ~69 ~126 ~118 dirt
setblock ~69 ~126 ~119 dirt
setblock ~69 ~126 ~120 dirt
setblock ~69 ~126 ~121 dirt
setblock ~69 ~126 ~122 dirt
setblock ~69 ~126 ~123 dirt
setblock ~69 ~126 ~124 grass_block
setblock ~69 ~126 ~125 short_grass
setblock ~69 ~126 ~163 short_grass
setblock ~69 ~126 ~164 short_grass
setblock ~69 ~126 ~165 grass_block
setblock ~69 ~126 ~166 grass_block
setblock ~69 ~126 ~167 dirt
setblock ~69 ~126 ~168 dirt
setblock ~69 ~126 ~169 dirt
setblock ~69 ~126 ~170 dirt
setblock ~69 ~126 ~171 dirt
setblock ~69 ~126 ~172 dirt
setblock ~69 ~126 ~173 grass_block
setblock ~69 ~126 ~174 grass_block
setblock ~69 ~126 ~176 fern
setblock ~69 ~127 ~9 short_grass
setblock ~69 ~127 ~10 short_grass
setblock ~69 ~127 ~13 short_grass
setblock ~69 ~127 ~15 short_grass
setblock ~69 ~127 ~16 short_grass
setblock ~69 ~127 ~17 poppy
setblock ~69 ~127 ~19 poppy
setblock ~69 ~127 ~58 short_grass
setblock ~69 ~127 ~59 short_grass
setblock ~69 ~127 ~64 short_grass
setblock ~69 ~127 ~69 fern
setblock ~69 ~127 ~70 short_grass
setblock ~69 ~127 ~116 short_grass
setblock ~69 ~127 ~118 grass_block
setblock ~69 ~127 ~119 dirt
setblock ~69 ~127 ~120 dirt
setblock ~69 ~127 ~121 dirt
setblock ~69 ~127 ~122 grass_block
setblock ~69 ~127 ~123 grass_block
setblock ~69 ~127 ~165 short_grass
setblock ~69 ~127 ~167 grass_block
setblock ~69 ~127 ~168 grass_block
setblock ~69 ~127 ~169 dirt
setblock ~69 ~127 ~170 dirt
setblock ~69 ~127 ~171 grass_block
setblock ~69 ~127 ~172 grass_block
setblock ~69 ~127 ~173 short_grass
setblock ~69 ~128 ~118 short_grass
setblock ~69 ~128 ~119 grass_block
setblock ~69 ~128 ~120 grass_block
setblock ~69 ~128 ~121 grass_block
setblock ~69 ~128 ~167 poppy
setblock ~69 ~128 ~169 grass_block
setblock ~69 ~128 ~170 grass_block
setblock ~69 ~129 ~120 short_grass
setblock ~70 ~122 ~0 grass_block
setblock ~70 ~122 ~1 grass_block
setblock ~70 ~122 ~2 dirt
setblock ~70 ~122 ~3 dirt
setblock ~70 ~122 ~4 dirt
setblock ~70 ~122 ~5 dirt
setblock ~70 ~122 ~6 dirt
setblock ~70 ~122 ~7 dirt
setblock ~70 ~122 ~8 dirt
setblock ~70 ~122 ~9 dirt
setblock ~70 ~122 ~10 dirt
setblock ~70 ~122 ~11 dirt
setblock ~70 ~122 ~12 dirt
setblock ~70 ~122 ~13 dirt
setblock ~70 ~122 ~14 dirt
setblock ~70 ~122 ~15 dirt
setblock ~70 ~122 ~16 dirt
setblock ~70 ~122 ~17 dirt
setblock ~70 ~122 ~18 dirt
setblock ~70 ~122 ~19 dirt
setblock ~70 ~122 ~20 dirt
setblock ~70 ~122 ~21 dirt
setblock ~70 ~122 ~22 dirt
setblock ~70 ~122 ~23 dirt
setblock ~70 ~122 ~24 dirt
setblock ~70 ~122 ~25 dirt
setblock ~70 ~122 ~26 dirt
setblock ~70 ~122 ~27 dirt
setblock ~70 ~122 ~28 dirt
setblock ~70 ~122 ~29 dirt
setblock ~70 ~122 ~30 dirt
setblock ~70 ~122 ~31 dirt
setblock ~70 ~122 ~32 dirt
setblock ~70 ~122 ~33 dirt
setblock ~70 ~122 ~34 dirt
setblock ~70 ~122 ~35 dirt
setblock ~70 ~122 ~36 dirt
setblock ~70 ~122 ~37 dirt
setblock ~70 ~122 ~38 dirt
setblock ~70 ~122 ~39 dirt
setblock ~70 ~122 ~40 dirt
setblock ~70 ~122 ~41 dirt
setblock ~70 ~122 ~42 dirt
setblock ~70 ~122 ~43 dirt
setblock ~70 ~122 ~44 dirt
setblock ~70 ~122 ~45 dirt
setblock ~70 ~122 ~46 dirt
setblock ~70 ~122 ~47 dirt
setblock ~70 ~122 ~48 dirt
setblock ~70 ~122 ~49 dirt
setblock ~70 ~122 ~50 dirt
setblock ~70 ~122 ~51 dirt
setblock ~70 ~122 ~52 dirt
setblock ~70 ~122 ~53 dirt
setblock ~70 ~122 ~54 dirt
setblock ~70 ~122 ~55 dirt
setblock ~70 ~122 ~56 dirt
setblock ~70 ~122 ~57 dirt
setblock ~70 ~122 ~58 dirt
setblock ~70 ~122 ~59 dirt
setblock ~70 ~122 ~60 dirt
setblock ~70 ~122 ~61 dirt
setblock ~70 ~122 ~62 dirt
setblock ~70 ~122 ~63 dirt
setblock ~70 ~122 ~64 dirt
setblock ~70 ~122 ~65 dirt
setblock ~70 ~122 ~66 dirt
setblock ~70 ~122 ~67 dirt
setblock ~70 ~122 ~68 dirt
setblock ~70 ~122 ~69 dirt
setblock ~70 ~122 ~70 dirt
setblock ~70 ~122 ~71 dirt
setblock ~70 ~122 ~72 dirt
setblock ~70 ~122 ~73 dirt
setblock ~70 ~122 ~74 dirt
setblock ~70 ~122 ~75 dirt
setblock ~70 ~122 ~76 dirt
setblock ~70 ~122 ~77 dirt
setblock ~70 ~122 ~78 dirt
setblock ~70 ~122 ~79 dirt
setblock ~70 ~122 ~80 dirt
setblock ~70 ~122 ~81 dirt
setblock ~70 ~122 ~82 dirt
setblock ~70 ~122 ~83 dirt
setblock ~70 ~122 ~84 dirt
setblock ~70 ~122 ~85 dirt
