setblock ~169 ~122 ~97 dirt
setblock ~169 ~122 ~98 dirt
setblock ~169 ~122 ~99 dirt
setblock ~169 ~122 ~100 dirt
setblock ~169 ~122 ~101 dirt
setblock ~169 ~122 ~102 dirt
setblock ~169 ~122 ~103 dirt
setblock ~169 ~122 ~104 dirt
setblock ~169 ~122 ~105 dirt
setblock ~169 ~122 ~121 dirt
setblock ~169 ~122 ~122 dirt
setblock ~169 ~123 ~76 grass_block
setblock ~169 ~123 ~77 grass_block
setblock ~169 ~123 ~78 grass_block
setblock ~169 ~123 ~79 grass_block
setblock ~169 ~123 ~81 grass_block
setblock ~169 ~123 ~82 grass_block
setblock ~169 ~123 ~83 grass_block
setblock ~169 ~123 ~84 grass_block
setblock ~169 ~123 ~85 grass_block
setblock ~169 ~123 ~86 grass_block
setblock ~169 ~123 ~87 grass_block
setblock ~169 ~123 ~88 dirt
setblock ~169 ~123 ~89 dirt
setblock ~169 ~123 ~90 dirt
setblock ~169 ~123 ~91 dirt
setblock ~169 ~123 ~92 dirt
setblock ~169 ~123 ~93 dirt
setblock ~169 ~123 ~94 dirt
setblock ~169 ~123 ~95 dirt
setblock ~169 ~123 ~96 dirt
setblock ~169 ~123 ~97 dirt
setblock ~169 ~123 ~98 dirt
setblock ~169 ~123 ~99 dirt
setblock ~169 ~123 ~100 grass_block
setblock ~169 ~123 ~101 grass_block
setblock ~169 ~123 ~102 grass_block
setblock ~169 ~123 ~103 grass_block
setblock ~169 ~123 ~104 grass_block
setblock ~169 ~123 ~105 grass_block
setblock ~169 ~123 ~121 dirt
setblock ~169 ~123 ~122 dirt
setblock ~169 ~124 ~76 poppy
setblock ~169 ~124 ~78 short_grass
setblock ~169 ~124 ~79 short_grass
setblock ~169 ~124 ~81 short_grass
setblock ~169 ~124 ~82 short_grass
setblock ~169 ~124 ~88 grass_block
setblock ~169 ~124 ~89 grass_block
setblock ~169 ~124 ~90 grass_block
setblock ~169 ~124 ~91 grass_block
setblock ~169 ~124 ~92 grass_block
setblock ~169 ~124 ~93 grass_block
setblock ~169 ~124 ~94 grass_block
setblock ~169 ~124 ~95 grass_block
setblock ~169 ~124 ~96 grass_block
setblock ~169 ~124 ~97 grass_block
setblock ~169 ~124 ~98 grass_block
setblock ~169 ~124 ~99 grass_block
setblock ~169 ~124 ~104 poppy
setblock ~169 ~124 ~121 dirt
setblock ~169 ~124 ~122 dirt
setblock ~169 ~125 ~92 short_grass
setblock ~169 ~125 ~94 short_grass
setblock ~169 ~125 ~99 short_grass
setblock ~169 ~125 ~121 dirt
setblock ~169 ~125 ~122 grass_block
setblock ~169 ~126 ~121 grass_block
setblock ~169 ~126 ~122 short_grass
setblock ~170 ~114 ~84 dirt
setblock ~170 ~115 ~84 dirt
setblock ~170 ~115 ~85 dirt
setblock ~170 ~116 ~82 dirt
setblock ~170 ~116 ~83 dirt
setblock ~170 ~116 ~84 dirt
setblock ~170 ~116 ~85 dirt
setblock ~170 ~116 ~86 dirt
setblock ~170 ~117 ~81 dirt
setblock ~170 ~117 ~82 dirt
setblock ~170 ~117 ~83 dirt
setblock ~170 ~117 ~84 dirt
setblock ~170 ~117 ~85 dirt
setblock ~170 ~117 ~86 dirt
setblock ~170 ~118 ~80 dirt
setblock ~170 ~118 ~81 dirt
setblock ~170 ~118 ~82 dirt
setblock ~170 ~118 ~83 dirt
setblock ~170 ~118 ~84 dirt
setblock ~170 ~118 ~85 dirt
setblock ~170 ~118 ~86 dirt
setblock ~170 ~118 ~87 dirt
setblock ~170 ~118 ~99 dirt
setblock ~170 ~119 ~80 dirt
setblock ~170 ~119 ~81 dirt
setblock ~170 ~119 ~82 dirt
setblock ~170 ~119 ~83 dirt
setblock ~170 ~119 ~84 dirt
setblock ~170 ~119 ~85 dirt
setblock ~170 ~119 ~86 dirt
setblock ~170 ~119 ~87 dirt
setblock ~170 ~119 ~89 dirt
setblock ~170 ~119 ~98 dirt
setblock ~170 ~119 ~99 dirt
setblock ~170 ~119 ~101 dirt
setblock ~170 ~120 ~79 dirt
setblock ~170 ~120 ~80 dirt
setblock ~170 ~120 ~81 dirt
setblock ~170 ~120 ~82 dirt
setblock ~170 ~120 ~83 dirt
setblock ~170 ~120 ~84 dirt
setblock ~170 ~120 ~85 dirt
setblock ~170 ~120 ~86 dirt
setblock ~170 ~120 ~87 dirt
setblock ~170 ~120 ~88 dirt
setblock ~170 ~120 ~89 dirt
setblock ~170 ~120 ~90 dirt
setblock ~170 ~120 ~95 dirt
setblock ~170 ~120 ~97 dirt
setblock ~170 ~120 ~98 dirt
setblock ~170 ~120 ~99 dirt
setblock ~170 ~120 ~100 dirt
setblock ~170 ~120 ~101 dirt
setblock ~170 ~120 ~102 dirt
setblock ~170 ~121 ~77 dirt
setblock ~170 ~121 ~78 dirt
setblock ~170 ~121 ~79 dirt
setblock ~170 ~121 ~80 dirt
setblock ~170 ~121 ~81 dirt
setblock ~170 ~121 ~82 dirt
setblock ~170 ~121 ~83 dirt
setblock ~170 ~121 ~84 dirt
setblock ~170 ~121 ~85 dirt
setblock ~170 ~121 ~86 dirt
setblock ~170 ~121 ~87 dirt
setblock ~170 ~121 ~88 dirt
setblock ~170 ~121 ~89 dirt
setblock ~170 ~121 ~90 dirt
setblock ~170 ~121 ~91 dirt
setblock ~170 ~121 ~94 dirt
setblock ~170 ~121 ~95 dirt
setblock ~170 ~121 ~96 dirt
setblock ~170 ~121 ~97 dirt
setblock ~170 ~121 ~98 dirt
setblock ~170 ~121 ~99 dirt
setblock ~170 ~121 ~100 dirt
setblock ~170 ~121 ~101 dirt
setblock ~170 ~121 ~102 dirt
setblock ~170 ~122 ~77 dirt
setblock ~170 ~122 ~78 dirt
setblock ~170 ~122 ~79 grass_block
setblock ~170 ~122 ~80 grass_block
setblock ~170 ~122 ~81 grass_block
setblock ~170 ~122 ~82 grass_block
setblock ~170 ~122 ~83 dirt
setblock ~170 ~122 ~84 dirt
setblock ~170 ~122 ~85 dirt
setblock ~170 ~122 ~86 dirt
setblock ~170 ~122 ~87 dirt
setblock ~170 ~122 ~88 dirt
setblock ~170 ~122 ~89 dirt
setblock ~170 ~122 ~90 dirt
setblock ~170 ~122 ~91 dirt
setblock ~170 ~122 ~94 dirt
setblock ~170 ~122 ~95 dirt
setblock ~170 ~122 ~96 dirt
setblock ~170 ~122 ~97 dirt
setblock ~170 ~122 ~98 dirt
setblock ~170 ~122 ~99 dirt
setblock ~170 ~122 ~100 dirt
setblock ~170 ~122 ~101 dirt
setblock ~170 ~122 ~102 dirt
setblock ~170 ~123 ~77 grass_block
setblock ~170 ~123 ~78 grass_block
setblock ~170 ~123 ~80 short_grass
setblock ~170 ~123 ~81 fern
setblock ~170 ~123 ~83 grass_block
setblock ~170 ~123 ~84 grass_block
setblock ~170 ~123 ~85 grass_block
setblock ~170 ~123 ~86 grass_block
setblock ~170 ~123 ~87 grass_block
setblock ~170 ~123 ~88 dirt
setblock ~170 ~123 ~89 dirt
setblock ~170 ~123 ~90 dirt
setblock ~170 ~123 ~91 dirt
setblock ~170 ~123 ~94 dirt
setblock ~170 ~123 ~95 dirt
setblock ~170 ~123 ~96 dirt
setblock ~170 ~123 ~97 dirt
setblock ~170 ~123 ~98 dirt
setblock ~170 ~123 ~99 dirt
setblock ~170 ~123 ~100 grass_block
setblock ~170 ~123 ~101 grass_block
setblock ~170 ~123 ~102 grass_block
setblock ~170 ~124 ~83 fern
setblock ~170 ~124 ~84 poppy
setblock ~170 ~124 ~88 grass_block
setblock ~170 ~124 ~89 grass_block
setblock ~170 ~124 ~90 grass_block
setblock ~170 ~124 ~91 grass_block
setblock ~170 ~124 ~94 grass_block
setblock ~170 ~124 ~95 grass_block
setblock ~170 ~124 ~96 grass_block
setblock ~170 ~124 ~97 grass_block
setblock ~170 ~124 ~98 grass_block
setblock ~170 ~124 ~99 grass_block
setblock ~170 ~124 ~102 short_grass
setblock ~170 ~125 ~88 short_grass
setblock ~170 ~125 ~90 short_grass
setblock ~170 ~125 ~94 short_grass
setblock ~170 ~125 ~96 short_grass
setblock ~170 ~125 ~97 short_grass
setblock ~171 ~116 ~84 dirt
setblock ~171 ~116 ~85 dirt
setblock ~171 ~117 ~83 dirt
setblock ~171 ~117 ~84 dirt
setblock ~171 ~117 ~85 dirt
setblock ~171 ~118 ~81 dirt
setblock ~171 ~118 ~83 dirt
setblock ~171 ~118 ~84 dirt
setblock ~171 ~118 ~85 dirt
setblock ~171 ~118 ~86 dirt
setblock ~171 ~119 ~81 dirt
setblock ~171 ~119 ~82 dirt
setblock ~171 ~119 ~83 dirt
setblock ~171 ~119 ~84 dirt
setblock ~171 ~119 ~85 dirt
setblock ~171 ~119 ~86 dirt
setblock ~171 ~120 ~80 dirt
setblock ~171 ~120 ~81 dirt
setblock ~171 ~120 ~82 dirt
setblock ~171 ~120 ~83 dirt
setblock ~171 ~120 ~84 dirt
setblock ~171 ~120 ~85 dirt
setblock ~171 ~120 ~86 dirt
setblock ~171 ~120 ~87 dirt
setblock ~171 ~121 ~80 dirt
setblock ~171 ~121 ~81 dirt
setblock ~171 ~121 ~82 dirt
setblock ~171 ~121 ~83 dirt
setblock ~171 ~121 ~84 dirt
setblock ~171 ~121 ~85 dirt
setblock ~171 ~121 ~86 dirt
setblock ~171 ~121 ~87 dirt
setblock ~171 ~121 ~88 dirt
setblock ~171 ~121 ~90 dirt
setblock ~171 ~121 ~95 dirt
setblock ~171 ~121 ~99 dirt
setblock ~171 ~122 ~80 grass_block
setblock ~171 ~122 ~81 grass_block
setblock ~171 ~122 ~82 dirt
setblock ~171 ~122 ~83 dirt
setblock ~171 ~122 ~84 dirt
setblock ~171 ~122 ~85 dirt
setblock ~171 ~122 ~86 dirt
setblock ~171 ~122 ~87 dirt
setblock ~171 ~122 ~88 dirt
setblock ~171 ~122 ~90 dirt
setblock ~171 ~122 ~95 dirt
setblock ~171 ~122 ~99 dirt
setblock ~171 ~123 ~81 short_grass
setblock ~171 ~123 ~82 grass_block
setblock ~171 ~123 ~83 grass_block
setblock ~171 ~123 ~84 grass_block
setblock ~171 ~123 ~85 grass_block
setblock ~171 ~123 ~86 grass_block
setblock ~171 ~123 ~87 grass_block
setblock ~171 ~123 ~88 dirt
setblock ~171 ~123 ~90 dirt
setblock ~171 ~123 ~95 dirt
setblock ~171 ~123 ~99 dirt
setblock ~171 ~124 ~85 short_grass
setblock ~171 ~124 ~86 short_grass
setblock ~171 ~124 ~87 fern
setblock ~171 ~124 ~88 grass_block
setblock ~171 ~124 ~90 grass_block
setblock ~171 ~124 ~95 grass_block
setblock ~171 ~124 ~99 grass_block
setblock ~171 ~125 ~95 short_grass
setblock ~171 ~125 ~99 short_grass
setblock ~172 ~118 ~85 dirt
setblock ~172 ~119 ~83 dirt
setblock ~172 ~119 ~84 dirt
setblock ~172 ~119 ~85 dirt
setblock ~172 ~120 ~81 dirt
setblock ~172 ~120 ~83 dirt
setblock ~172 ~120 ~84 dirt
setblock ~172 ~120 ~85 dirt
setblock ~172 ~120 ~86 dirt
setblock ~172 ~121 ~81 dirt
setblock ~172 ~121 ~82 dirt
setblock ~172 ~121 ~83 dirt
setblock ~172 ~121 ~84 dirt
setblock ~172 ~121 ~85 dirt
setblock ~172 ~121 ~86 dirt
setblock ~172 ~122 ~81 dirt
setblock ~172 ~122 ~82 dirt
setblock ~172 ~122 ~83 dirt
setblock ~172 ~122 ~84 dirt
setblock ~172 ~122 ~85 dirt
setblock ~172 ~122 ~86 dirt
setblock ~172 ~123 ~81 grass_block
setblock ~172 ~123 ~82 grass_block
setblock ~172 ~123 ~83 grass_block
setblock ~172 ~123 ~84 grass_block
setblock ~172 ~123 ~85 grass_block
setblock ~172 ~123 ~86 grass_block
setblock ~172 ~124 ~84 fern
setblock ~173 ~121 ~83 dirt
setblock ~173 ~121 ~84 dirt
setblock ~173 ~121 ~85 dirt
setblock ~173 ~122 ~83 dirt
setblock ~173 ~122 ~84 dirt
setblock ~173 ~122 ~85 dirt
setblock ~173 ~123 ~83 grass_block
setblock ~173 ~123 ~84 grass_block
setblock ~173 ~123 ~85 grass_block
setblock ~173 ~124 ~83 short_grass
setblock ~173 ~124 ~85 short_grass
setblock ~199 ~200 ~199 gold_block
