setblock ~117 ~125 ~97 grass_block
setblock ~117 ~125 ~102 short_grass
setblock ~117 ~125 ~103 short_grass
setblock ~117 ~125 ~108 short_grass
setblock ~117 ~125 ~109 short_grass
setblock ~117 ~125 ~113 short_grass
setblock ~117 ~125 ~117 short_grass
setblock ~117 ~125 ~119 grass_block
setblock ~117 ~125 ~120 grass_block
setblock ~117 ~125 ~121 grass_block
setblock ~117 ~125 ~122 grass_block
setblock ~117 ~125 ~127 short_grass
setblock ~117 ~125 ~128 fern
setblock ~117 ~125 ~130 short_grass
setblock ~117 ~125 ~131 poppy
setblock ~117 ~125 ~133 short_grass
setblock ~117 ~125 ~134 grass_block
setblock ~117 ~125 ~135 grass_block
setblock ~117 ~125 ~136 grass_block
setblock ~117 ~125 ~137 dirt
setblock ~117 ~125 ~138 dirt
setblock ~117 ~125 ~139 dirt
setblock ~117 ~125 ~140 dirt
setblock ~117 ~125 ~141 dirt
setblock ~117 ~125 ~142 dirt
setblock ~117 ~125 ~143 grass_block
setblock ~117 ~125 ~144 grass_block
setblock ~117 ~125 ~145 grass_block
setblock ~117 ~125 ~150 short_grass
setblock ~117 ~125 ~153 poppy
setblock ~117 ~125 ~154 short_grass
setblock ~117 ~125 ~156 short_grass
setblock ~117 ~125 ~160 fern
setblock ~117 ~125 ~161 grass_block
setblock ~117 ~125 ~162 grass_block
setblock ~117 ~125 ~163 grass_block
setblock ~117 ~125 ~164 grass_block
setblock ~117 ~125 ~165 dirt
setblock ~117 ~125 ~166 dirt
setblock ~117 ~125 ~167 dirt
setblock ~117 ~125 ~168 dirt
setblock ~117 ~125 ~169 dirt
setblock ~117 ~125 ~170 dirt
setblock ~117 ~125 ~171 dirt
setblock ~117 ~125 ~172 dirt
setblock ~117 ~125 ~173 dirt
setblock ~117 ~125 ~174 dirt
setblock ~117 ~125 ~175 dirt
setblock ~117 ~125 ~176 grass_block
setblock ~117 ~125 ~177 grass_block
setblock ~117 ~125 ~178 grass_block
setblock ~117 ~125 ~179 grass_block
setblock ~117 ~125 ~180 short_grass
setblock ~117 ~125 ~181 short_grass
setblock ~117 ~125 ~182 short_grass
setblock ~117 ~125 ~185 grass_block
setblock ~117 ~125 ~186 grass_block
setblock ~117 ~125 ~187 grass_block
setblock ~117 ~125 ~188 grass_block
setblock ~117 ~125 ~189 grass_block
setblock ~117 ~125 ~190 grass_block
setblock ~117 ~125 ~194 short_grass
setblock ~117 ~126 ~0 grass_block
setblock ~117 ~126 ~1 short_grass
setblock ~117 ~126 ~5 short_grass
setblock ~117 ~126 ~54 fern
setblock ~117 ~126 ~57 grass_block
setblock ~117 ~126 ~58 grass_block
setblock ~117 ~126 ~59 dirt
setblock ~117 ~126 ~60 dirt
setblock ~117 ~126 ~61 dirt
setblock ~117 ~126 ~62 dirt
setblock ~117 ~126 ~63 dirt
setblock ~117 ~126 ~64 dirt
setblock ~117 ~126 ~65 dirt
setblock ~117 ~126 ~66 dirt
setblock ~117 ~126 ~67 dirt
setblock ~117 ~126 ~68 dirt
setblock ~117 ~126 ~69 dirt
setblock ~117 ~126 ~70 dirt
setblock ~117 ~126 ~71 dirt
setblock ~117 ~126 ~72 dirt
setblock ~117 ~126 ~73 dirt
setblock ~117 ~126 ~74 dirt
setblock ~117 ~126 ~75 dirt
setblock ~117 ~126 ~76 dirt
setblock ~117 ~126 ~77 dirt
setblock ~117 ~126 ~78 dirt
setblock ~117 ~126 ~79 dirt
setblock ~117 ~126 ~80 dirt
setblock ~117 ~126 ~81 dirt
setblock ~117 ~126 ~82 dirt
setblock ~117 ~126 ~83 dirt
setblock ~117 ~126 ~84 dirt
setblock ~117 ~126 ~85 dirt
setblock ~117 ~126 ~86 dirt
setblock ~117 ~126 ~87 dirt
setblock ~117 ~126 ~88 dirt
setblock ~117 ~126 ~89 dirt
setblock ~117 ~126 ~90 dirt
setblock ~117 ~126 ~91 dirt
setblock ~117 ~126 ~92 dirt
setblock ~117 ~126 ~93 grass_block
setblock ~117 ~126 ~94 grass_block
setblock ~117 ~126 ~97 short_grass
setblock ~117 ~126 ~122 short_grass
setblock ~117 ~126 ~136 short_grass
setblock ~117 ~126 ~137 grass_block
setblock ~117 ~126 ~138 grass_block
setblock ~117 ~126 ~139 grass_block
setblock ~117 ~126 ~140 dirt
setblock ~117 ~126 ~141 grass_block
setblock ~117 ~126 ~142 grass_block
setblock ~117 ~126 ~144 short_grass
setblock ~117 ~126 ~165 grass_block
setblock ~117 ~126 ~166 grass_block
setblock ~117 ~126 ~167 grass_block
setblock ~117 ~126 ~168 grass_block
setblock ~117 ~126 ~169 grass_block
setblock ~117 ~126 ~170 dirt
setblock ~117 ~126 ~171 dirt
setblock ~117 ~126 ~172 grass_block
setblock ~117 ~126 ~173 grass_block
setblock ~117 ~126 ~174 grass_block
setblock ~117 ~126 ~175 grass_block
setblock ~117 ~127 ~59 grass_block
setblock ~117 ~127 ~60 grass_block
setblock ~117 ~127 ~61 grass_block
setblock ~117 ~127 ~62 grass_block
setblock ~117 ~127 ~63 grass_block
setblock ~117 ~127 ~64 grass_block
setblock ~117 ~127 ~65 grass_block
setblock ~117 ~127 ~66 grass_block
setblock ~117 ~127 ~67 grass_block
setblock ~117 ~127 ~68 grass_block
setblock ~117 ~127 ~69 grass_block
setblock ~117 ~127 ~70 grass_block
setblock ~117 ~127 ~71 grass_block
setblock ~117 ~127 ~72 grass_block
setblock ~117 ~127 ~73 grass_block
setblock ~117 ~127 ~74 grass_block
setblock ~117 ~127 ~75 grass_block
setblock ~117 ~127 ~76 grass_block
setblock ~117 ~127 ~77 grass_block
setblock ~117 ~127 ~78 grass_block
setblock ~117 ~127 ~79 grass_block
setblock ~117 ~127 ~80 grass_block
setblock ~117 ~127 ~81 grass_block
setblock ~117 ~127 ~82 grass_block
setblock ~117 ~127 ~83 grass_block
setblock ~117 ~127 ~84 grass_block
setblock ~117 ~127 ~85 grass_block
setblock ~117 ~127 ~86 grass_block
setblock ~117 ~127 ~87 grass_block
setblock ~117 ~127 ~88 grass_block
setblock ~117 ~127 ~89 grass_block
setblock ~117 ~127 ~90 grass_block
setblock ~117 ~127 ~91 grass_block
setblock ~117 ~127 ~92 grass_block
setblock ~117 ~127 ~93 short_grass
setblock ~117 ~127 ~94 poppy
setblock ~117 ~127 ~140 grass_block
setblock ~117 ~127 ~167 short_grass
setblock ~117 ~127 ~170 grass_block
setblock ~117 ~127 ~171 grass_block
setblock ~117 ~127 ~172 short_grass
setblock ~117 ~127 ~173 short_grass
setblock ~117 ~127 ~175 fern
setblock ~117 ~128 ~59 short_grass
setblock ~117 ~128 ~61 short_grass
setblock ~117 ~128 ~62 poppy
setblock ~117 ~128 ~65 short_grass
setblock ~117 ~128 ~72 poppy
setblock ~117 ~128 ~73 short_grass
setblock ~117 ~128 ~74 short_grass
setblock ~117 ~128 ~75 short_grass
setblock ~117 ~128 ~76 short_grass
setblock ~117 ~128 ~81 fern
setblock ~117 ~128 ~89 short_grass
setblock ~117 ~128 ~170 short_grass
setblock ~117 ~128 ~171 short_grass
setblock ~118 ~122 ~0 dirt
setblock ~118 ~122 ~1 dirt
setblock ~118 ~122 ~2 dirt
setblock ~118 ~122 ~3 dirt
setblock ~118 ~122 ~4 dirt
setblock ~118 ~122 ~5 dirt
setblock ~118 ~122 ~6 dirt
setblock ~118 ~122 ~7 dirt
setblock ~118 ~122 ~8 dirt
setblock ~118 ~122 ~9 dirt
setblock ~118 ~122 ~10 dirt
setblock ~118 ~122 ~11 dirt
setblock ~118 ~122 ~12 dirt
setblock ~118 ~122 ~13 dirt
setblock ~118 ~122 ~14 dirt
setblock ~118 ~122 ~15 dirt
setblock ~118 ~122 ~16 dirt
setblock ~118 ~122 ~17 dirt
setblock ~118 ~122 ~18 dirt
setblock ~118 ~122 ~19 dirt
setblock ~118 ~122 ~20 dirt
setblock ~118 ~122 ~21 dirt
setblock ~118 ~122 ~22 dirt
setblock ~118 ~122 ~23 dirt
setblock ~118 ~122 ~24 dirt
setblock ~118 ~122 ~25 dirt
setblock ~118 ~122 ~26 dirt
setblock ~118 ~122 ~27 dirt
setblock ~118 ~122 ~28 dirt
setblock ~118 ~122 ~29 dirt
setblock ~118 ~122 ~30 dirt
setblock ~118 ~122 ~31 dirt
setblock ~118 ~122 ~32 dirt
setblock ~118 ~122 ~33 dirt
setblock ~118 ~122 ~34 dirt
setblock ~118 ~122 ~35 dirt
setblock ~118 ~122 ~36 dirt
setblock ~118 ~122 ~37 dirt
setblock ~118 ~122 ~38 dirt
setblock ~118 ~122 ~39 dirt
setblock ~118 ~122 ~40 dirt
setblock ~118 ~122 ~41 dirt
setblock ~118 ~122 ~42 dirt
setblock ~118 ~122 ~43 dirt
setblock ~118 ~122 ~44 dirt
setblock ~118 ~122 ~45 dirt
setblock ~118 ~122 ~46 dirt
setblock ~118 ~122 ~47 dirt
setblock ~118 ~122 ~48 dirt
setblock ~118 ~122 ~49 dirt
setblock ~118 ~122 ~50 dirt
setblock ~118 ~122 ~51 dirt
setblock ~118 ~122 ~52 dirt
setblock ~118 ~122 ~53 dirt
setblock ~118 ~122 ~54 dirt
setblock ~118 ~122 ~55 dirt
setblock ~118 ~122 ~56 dirt
setblock ~118 ~122 ~57 dirt
setblock ~118 ~122 ~58 dirt
setblock ~118 ~122 ~59 dirt
setblock ~118 ~122 ~60 dirt
setblock ~118 ~122 ~61 dirt
setblock ~118 ~122 ~62 dirt
setblock ~118 ~122 ~63 dirt
setblock ~118 ~122 ~64 dirt
setblock ~118 ~122 ~65 dirt
setblock ~118 ~122 ~66 dirt
setblock ~118 ~122 ~67 dirt
setblock ~118 ~122 ~68 dirt
setblock ~118 ~122 ~69 dirt
setblock ~118 ~122 ~70 dirt
setblock ~118 ~122 ~71 dirt
setblock ~118 ~122 ~72 dirt
setblock ~118 ~122 ~73 dirt
setblock ~118 ~122 ~74 dirt
setblock ~118 ~122 ~75 dirt
setblock ~118 ~122 ~76 dirt
setblock ~118 ~122 ~77 dirt
setblock ~118 ~122 ~78 dirt
setblock ~118 ~122 ~79 dirt
setblock ~118 ~122 ~80 dirt
setblock ~118 ~122 ~81 dirt
setblock ~118 ~122 ~82 dirt
setblock ~118 ~122 ~83 dirt
setblock ~118 ~122 ~84 dirt
setblock ~118 ~122 ~85 dirt
setblock ~118 ~122 ~86 dirt
setblock ~118 ~122 ~87 dirt
setblock ~118 ~122 ~88 dirt
setblock ~118 ~122 ~89 dirt
setblock ~118 ~122 ~90 dirt
setblock ~118 ~122 ~91 dirt
setblock ~118 ~122 ~92 dirt
setblock ~118 ~122 ~93 dirt
setblock ~118 ~122 ~94 dirt
setblock ~118 ~122 ~95 dirt
setblock ~118 ~122 ~96 dirt
setblock ~118 ~122 ~97 dirt
setblock ~118 ~122 ~98 dirt
setblock ~118 ~122 ~99 dirt
setblock ~118 ~122 ~100 dirt
setblock ~118 ~122 ~101 dirt
setblock ~118 ~122 ~102 dirt
setblock ~118 ~122 ~103 dirt
setblock ~118 ~122 ~104 dirt
setblock ~118 ~122 ~105 dirt
setblock ~118 ~122 ~106 dirt
setblock ~118 ~122 ~107 dirt
setblock ~118 ~122 ~108 dirt
setblock ~118 ~122 ~109 dirt
setblock ~118 ~122 ~110 dirt
setblock ~118 ~122 ~111 dirt
setblock ~118 ~122 ~112 dirt
setblock ~118 ~122 ~113 dirt
setblock ~118 ~122 ~114 dirt
setblock ~118 ~122 ~115 dirt
setblock ~118 ~122 ~116 dirt
setblock ~118 ~122 ~117 dirt
setblock ~118 ~122 ~118 dirt
setblock ~118 ~122 ~119 dirt
setblock ~118 ~122 ~120 dirt
setblock ~118 ~122 ~121 dirt
setblock ~118 ~122 ~122 dirt
setblock ~118 ~122 ~123 dirt
setblock ~118 ~122 ~124 dirt
setblock ~118 ~122 ~125 dirt
setblock ~118 ~122 ~126 dirt
setblock ~118 ~122 ~127 dirt
setblock ~118 ~122 ~128 dirt
setblock ~118 ~122 ~129 dirt
setblock ~118 ~122 ~130 dirt
setblock ~118 ~122 ~131 dirt
setblock ~118 ~122 ~132 dirt
setblock ~118 ~122 ~133 dirt
setblock ~118 ~122 ~134 dirt
setblock ~118 ~122 ~135 dirt
setblock ~118 ~122 ~136 dirt
setblock ~118 ~122 ~137 dirt
setblock ~118 ~122 ~138 dirt
setblock ~118 ~122 ~139 dirt
setblock ~118 ~122 ~140 dirt
setblock ~118 ~122 ~141 dirt
setblock ~118 ~122 ~142 dirt
setblock ~118 ~122 ~143 dirt
setblock ~118 ~122 ~144 dirt
setblock ~118 ~122 ~145 dirt
setblock ~118 ~122 ~146 dirt
setblock ~118 ~122 ~147 dirt
setblock ~118 ~122 ~148 dirt
setblock ~118 ~122 ~149 dirt
setblock ~118 ~122 ~150 dirt
setblock ~118 ~122 ~151 dirt
setblock ~118 ~122 ~152 dirt
setblock ~118 ~122 ~153 dirt
setblock ~118 ~122 ~154 dirt
setblock ~118 ~122 ~155 dirt
setblock ~118 ~122 ~156 dirt
setblock ~118 ~122 ~157 dirt
setblock ~118 ~122 ~158 dirt
setblock ~118 ~122 ~159 dirt
setblock ~118 ~122 ~160 dirt
setblock ~118 ~122 ~161 dirt
setblock ~118 ~122 ~162 dirt
setblock ~118 ~122 ~163 dirt
setblock ~118 ~122 ~164 dirt
setblock ~118 ~122 ~165 dirt
setblock ~118 ~122 ~166 dirt
setblock ~118 ~122 ~167 dirt
setblock ~118 ~122 ~168 dirt
setblock ~118 ~122 ~169 dirt
setblock ~118 ~122 ~170 dirt
setblock ~118 ~122 ~171 dirt
setblock ~118 ~122 ~172 dirt
setblock ~118 ~122 ~173 dirt
setblock ~118 ~122 ~174 dirt
setblock ~118 ~122 ~175 dirt
setblock ~118 ~122 ~176 dirt
setblock ~118 ~122 ~177 dirt
setblock ~118 ~122 ~178 dirt
setblock ~118 ~122 ~179 dirt
setblock ~118 ~122 ~180 dirt
setblock ~118 ~122 ~181 dirt
setblock ~118 ~122 ~182 dirt
setblock ~118 ~122 ~183 dirt
setblock ~118 ~122 ~184 dirt
setblock ~118 ~122 ~185 dirt
setblock ~118 ~122 ~186 dirt
setblock ~118 ~122 ~187 dirt
setblock ~118 ~122 ~188 dirt
setblock ~118 ~122 ~189 dirt
setblock ~118 ~122 ~190 dirt
setblock ~118 ~122 ~191 dirt
setblock ~118 ~122 ~192 dirt
setblock ~118 ~122 ~193 dirt
setblock ~118 ~122 ~194 dirt
setblock ~118 ~122 ~195 dirt
setblock ~118 ~122 ~196 dirt
setblock ~118 ~122 ~197 dirt
setblock ~118 ~122 ~198 dirt
setblock ~118 ~122 ~199 grass_block
setblock ~118 ~123 ~0 dirt
setblock ~118 ~123 ~1 dirt
setblock ~118 ~123 ~2 dirt
setblock ~118 ~123 ~3 dirt
setblock ~118 ~123 ~4 dirt
setblock ~118 ~123 ~5 dirt
setblock ~118 ~123 ~6 dirt
setblock ~118 ~123 ~7 dirt
setblock ~118 ~123 ~8 dirt
setblock ~118 ~123 ~9 dirt
setblock ~118 ~123 ~10 dirt
setblock ~118 ~123 ~11 dirt
setblock ~118 ~123 ~12 dirt
setblock ~118 ~123 ~13 dirt
setblock ~118 ~123 ~14 dirt
setblock ~118 ~123 ~15 dirt
setblock ~118 ~123 ~16 dirt
setblock ~118 ~123 ~17 dirt
setblock ~118 ~123 ~18 dirt
setblock ~118 ~123 ~19 dirt
setblock ~118 ~123 ~20 dirt
setblock ~118 ~123 ~21 dirt
setblock ~118 ~123 ~22 dirt
setblock ~118 ~123 ~23 dirt
setblock ~118 ~123 ~24 dirt
setblock ~118 ~123 ~25 grass_block
setblock ~118 ~123 ~26 grass_block
setblock ~118 ~123 ~27 grass_block
setblock ~118 ~123 ~28 grass_block
setblock ~118 ~123 ~29 grass_block
setblock ~118 ~123 ~30 grass_block
setblock ~118 ~123 ~31 grass_block
setblock ~118 ~123 ~32 grass_block
setblock ~118 ~123 ~33 grass_block
setblock ~118 ~123 ~34 dirt
setblock ~118 ~123 ~35 dirt
setblock ~118 ~123 ~36 dirt
setblock ~118 ~123 ~37 dirt
setblock ~118 ~123 ~38 dirt
setblock ~118 ~123 ~39 dirt
setblock ~118 ~123 ~40 dirt
setblock ~118 ~123 ~41 dirt
setblock ~118 ~123 ~42 dirt
setblock ~118 ~123 ~43 dirt
setblock ~118 ~123 ~44 dirt
setblock ~118 ~123 ~45 dirt
setblock ~118 ~123 ~46 dirt
setblock ~118 ~123 ~47 dirt
setblock ~118 ~123 ~48 dirt
setblock ~118 ~123 ~49 dirt
setblock ~118 ~123 ~50 dirt
setblock ~118 ~123 ~51 dirt
setblock ~118 ~123 ~52 dirt
setblock ~118 ~123 ~53 dirt
setblock ~118 ~123 ~54 dirt
setblock ~118 ~123 ~55 dirt
setblock ~118 ~123 ~56 dirt
setblock ~118 ~123 ~57 dirt
setblock ~118 ~123 ~58 dirt
setblock ~118 ~123 ~59 dirt
setblock ~118 ~123 ~60 dirt
setblock ~118 ~123 ~61 dirt
setblock ~118 ~123 ~62 dirt
setblock ~118 ~123 ~63 dirt
setblock ~118 ~123 ~64 dirt
setblock ~118 ~123 ~65 dirt
setblock ~118 ~123 ~66 dirt
setblock ~118 ~123 ~67 dirt
setblock ~118 ~123 ~68 dirt
setblock ~118 ~123 ~69 dirt
setblock ~118 ~123 ~70 dirt
setblock ~118 ~123 ~71 dirt
setblock ~118 ~123 ~72 dirt
setblock ~118 ~123 ~73 dirt
setblock ~118 ~123 ~74 dirt
setblock ~118 ~123 ~75 dirt
setblock ~118 ~123 ~76 dirt
setblock ~118 ~123 ~77 dirt
setblock ~118 ~123 ~78 dirt
setblock ~118 ~123 ~79 dirt
setblock ~118 ~123 ~80 dirt
setblock ~118 ~123 ~81 dirt
setblock ~118 ~123 ~82 dirt
setblock ~118 ~123 ~83 dirt
setblock ~118 ~123 ~84 dirt
setblock ~118 ~123 ~85 dirt
setblock ~118 ~123 ~86 dirt
setblock ~118 ~123 ~87 dirt
setblock ~118 ~123 ~88 dirt
setblock ~118 ~123 ~89 dirt
setblock ~118 ~123 ~90 dirt
setblock ~118 ~123 ~91 dirt
setblock ~118 ~123 ~92 dirt
setblock ~118 ~123 ~93 dirt
setblock ~118 ~123 ~94 dirt
setblock ~118 ~123 ~95 dirt
setblock ~118 ~123 ~96 dirt
setblock ~118 ~123 ~97 dirt
setblock ~118 ~123 ~98 dirt
setblock ~118 ~123 ~99 dirt
setblock ~118 ~123 ~100 dirt
setblock ~118 ~123 ~101 dirt
setblock ~118 ~123 ~102 dirt
setblock ~118 ~123 ~103 dirt
setblock ~118 ~123 ~104 dirt
setblock ~118 ~123 ~105 dirt
setblock ~118 ~123 ~106 dirt
setblock ~118 ~123 ~107 dirt
setblock ~118 ~123 ~108 dirt
setblock ~118 ~123 ~109 grass_block
setblock ~118 ~123 ~110 grass_block
setblock ~118 ~123 ~111 grass_block
setblock ~118 ~123 ~112 grass_block
setblock ~118 ~123 ~113 dirt
setblock ~118 ~123 ~114 dirt
setblock ~118 ~123 ~115 dirt
setblock ~118 ~123 ~116 dirt
setblock ~118 ~123 ~117 dirt
setblock ~118 ~123 ~118 dirt
setblock ~118 ~123 ~119 dirt
setblock ~118 ~123 ~120 dirt
setblock ~118 ~123 ~121 dirt
setblock ~118 ~123 ~122 dirt
setblock ~118 ~123 ~123 dirt
setblock ~118 ~123 ~124 dirt
setblock ~118 ~123 ~125 dirt
setblock ~118 ~123 ~126 dirt
setblock ~118 ~123 ~127 dirt
setblock ~118 ~123 ~128 dirt
setblock ~118 ~123 ~129 dirt
setblock ~118 ~123 ~130 dirt
setblock ~118 ~123 ~131 dirt
setblock ~118 ~123 ~132 dirt
setblock ~118 ~123 ~133 dirt
setblock ~118 ~123 ~134 dirt
setblock ~118 ~123 ~135 dirt
setblock ~118 ~123 ~136 dirt
setblock ~118 ~123 ~137 dirt
setblock ~118 ~123 ~138 dirt
setblock ~118 ~123 ~139 dirt
setblock ~118 ~123 ~140 dirt
setblock ~118 ~123 ~141 dirt
setblock ~118 ~123 ~142 dirt
setblock ~118 ~123 ~143 dirt
setblock ~118 ~123 ~144 dirt
setblock ~118 ~123 ~145 dirt
setblock ~118 ~123 ~146 dirt
setblock ~118 ~123 ~147 dirt
setblock ~118 ~123 ~148 dirt
setblock ~118 ~123 ~149 dirt
setblock ~118 ~123 ~150 dirt
setblock ~118 ~123 ~151 dirt
setblock ~118 ~123 ~152 dirt
setblock ~118 ~123 ~153 dirt
setblock ~118 ~123 ~154 dirt
setblock ~118 ~123 ~155 dirt
setblock ~118 ~123 ~156 dirt
setblock ~118 ~123 ~157 dirt
setblock ~118 ~123 ~158 dirt
setblock ~118 ~123 ~159 dirt
setblock ~118 ~123 ~160 dirt
setblock ~118 ~123 ~161 dirt
setblock ~118 ~123 ~162 dirt
setblock ~118 ~123 ~163 dirt
setblock ~118 ~123 ~164 dirt
setblock ~118 ~123 ~165 dirt
setblock ~118 ~123 ~166 dirt
setblock ~118 ~123 ~167 dirt
setblock ~118 ~123 ~168 dirt
setblock ~118 ~123 ~169 dirt
setblock ~118 ~123 ~170 dirt
setblock ~118 ~123 ~171 dirt
setblock ~118 ~123 ~172 dirt
setblock ~118 ~123 ~173 dirt
setblock ~118 ~123 ~174 dirt
setblock ~118 ~123 ~175 dirt
setblock ~118 ~123 ~176 dirt
setblock ~118 ~123 ~177 dirt
setblock ~118 ~123 ~178 dirt
setblock ~118 ~123 ~179 dirt
setblock ~118 ~123 ~180 dirt
setblock ~118 ~123 ~181 dirt
setblock ~118 ~123 ~182 dirt
setblock ~118 ~123 ~183 dirt
setblock ~118 ~123 ~184 dirt
setblock ~118 ~123 ~185 dirt
setblock ~118 ~123 ~186 dirt
setblock ~118 ~123 ~187 dirt
setblock ~118 ~123 ~188 dirt
setblock ~118 ~123 ~189 dirt
setblock ~118 ~123 ~190 dirt
setblock ~118 ~123 ~191 dirt
setblock ~118 ~123 ~192 dirt
setblock ~118 ~123 ~193 grass_block
setblock ~118 ~123 ~194 grass_block
setblock ~118 ~123 ~195 grass_block
setblock ~118 ~123 ~196 grass_block
setblock ~118 ~123 ~197 grass_block
setblock ~118 ~123 ~198 grass_block
setblock ~118 ~124 ~0 dirt
setblock ~118 ~124 ~1 dirt
setblock ~118 ~124 ~2 dirt
setblock ~118 ~124 ~3 dirt
setblock ~118 ~124 ~4 dirt
setblock ~118 ~124 ~5 dirt
setblock ~118 ~124 ~6 dirt
setblock ~118 ~124 ~7 dirt
setblock ~118 ~124 ~8 grass_block
setblock ~118 ~124 ~9 grass_block
setblock ~118 ~124 ~10 grass_block
setblock ~118 ~124 ~11 grass_block
setblock ~118 ~124 ~12 grass_block
setblock ~118 ~124 ~13 grass_block
setblock ~118 ~124 ~14 grass_block
setblock ~118 ~124 ~15 grass_block
setblock ~118 ~124 ~16 grass_block
setblock ~118 ~124 ~17 grass_block
setblock ~118 ~124 ~18 grass_block
setblock ~118 ~124 ~19 grass_block
setblock ~118 ~124 ~20 grass_block
setblock ~118 ~124 ~21 grass_block
setblock ~118 ~124 ~22 grass_block
setblock ~118 ~124 ~23 grass_block
setblock ~118 ~124 ~24 grass_block
setblock ~118 ~124 ~26 short_grass
setblock ~118 ~124 ~29 short_grass
setblock ~118 ~124 ~32 short_grass
setblock ~118 ~124 ~34 grass_block
setblock ~118 ~124 ~35 grass_block
setblock ~118 ~124 ~36 grass_block
setblock ~118 ~124 ~37 grass_block
setblock ~118 ~124 ~38 grass_block
setblock ~118 ~124 ~39 grass_block
setblock ~118 ~124 ~40 grass_block
setblock ~118 ~124 ~41 grass_block
setblock ~118 ~124 ~42 grass_block
setblock ~118 ~124 ~43 grass_block
setblock ~118 ~124 ~44 grass_block
setblock ~118 ~124 ~45 grass_block
setblock ~118 ~124 ~46 grass_block
setblock ~118 ~124 ~47 grass_block
setblock ~118 ~124 ~48 grass_block
setblock ~118 ~124 ~49 grass_block
setblock ~118 ~124 ~50 grass_block
setblock ~118 ~124 ~51 grass_block
setblock ~118 ~124 ~52 grass_block
setblock ~118 ~124 ~53 grass_block
setblock ~118 ~124 ~54 dirt
setblock ~118 ~124 ~55 dirt
setblock ~118 ~124 ~56 dirt
setblock ~118 ~124 ~57 dirt
setblock ~118 ~124 ~58 dirt
setblock ~118 ~124 ~59 dirt
setblock ~118 ~124 ~60 dirt
setblock ~118 ~124 ~61 dirt
setblock ~118 ~124 ~62 dirt
setblock ~118 ~124 ~63 dirt
setblock ~118 ~124 ~64 dirt
setblock ~118 ~124 ~65 dirt
setblock ~118 ~124 ~66 dirt
setblock ~118 ~124 ~67 dirt
setblock ~118 ~124 ~68 dirt
setblock ~118 ~124 ~69 dirt
setblock ~118 ~124 ~70 dirt
setblock ~118 ~124 ~71 dirt
setblock ~118 ~124 ~72 dirt
setblock ~118 ~124 ~73 dirt
setblock ~118 ~124 ~74 dirt
setblock ~118 ~124 ~75 dirt
setblock ~118 ~124 ~76 dirt
setblock ~118 ~124 ~77 dirt
setblock ~118 ~124 ~78 dirt
setblock ~118 ~124 ~79 dirt
setblock ~118 ~124 ~80 dirt
setblock ~118 ~124 ~81 dirt
setblock ~118 ~124 ~82 dirt
setblock ~118 ~124 ~83 dirt
setblock ~118 ~124 ~84 dirt
setblock ~118 ~124 ~85 dirt
setblock ~118 ~124 ~86 dirt
setblock ~118 ~124 ~87 dirt
setblock ~118 ~124 ~88 dirt
setblock ~118 ~124 ~89 dirt
setblock ~118 ~124 ~90 dirt
setblock ~118 ~124 ~91 dirt
setblock ~118 ~124 ~92 dirt
setblock ~118 ~124 ~93 dirt
setblock ~118 ~124 ~94 dirt
setblock ~118 ~124 ~95 dirt
setblock ~118 ~124 ~96 dirt
setblock ~118 ~124 ~97 dirt
setblock ~118 ~124 ~98 grass_block
setblock ~118 ~124 ~99 grass_block
setblock ~118 ~124 ~100 grass_block
setblock ~118 ~124 ~101 grass_block
setblock ~118 ~124 ~102 grass_block
setblock ~118 ~124 ~103 grass_block
setblock ~118 ~124 ~104 grass_block
setblock ~118 ~124 ~105 grass_block
setblock ~118 ~124 ~106 grass_block
setblock ~118 ~124 ~107 grass_block
setblock ~118 ~124 ~108 grass_block
setblock ~118 ~124 ~113 grass_block
setblock ~118 ~124 ~114 grass_block
setblock ~118 ~124 ~115 grass_block
setblock ~118 ~124 ~116 grass_block
setblock ~118 ~124 ~117 grass_block
setblock ~118 ~124 ~118 grass_block
setblock ~118 ~124 ~119 grass_block
setblock ~118 ~124 ~120 grass_block
setblock ~118 ~124 ~121 grass_block
setblock ~118 ~124 ~122 grass_block
setblock ~118 ~124 ~123 grass_block
setblock ~118 ~124 ~124 grass_block
setblock ~118 ~124 ~125 grass_block
setblock ~118 ~124 ~126 grass_block
setblock ~118 ~124 ~127 grass_block
setblock ~118 ~124 ~128 grass_block
setblock ~118 ~124 ~129 grass_block
setblock ~118 ~124 ~130 grass_block
setblock ~118 ~124 ~131 grass_block
setblock ~118 ~124 ~132 grass_block
setblock ~118 ~124 ~133 dirt
setblock ~118 ~124 ~134 dirt
setblock ~118 ~124 ~135 dirt
setblock ~118 ~124 ~136 dirt
setblock ~118 ~124 ~137 dirt
setblock ~118 ~124 ~138 dirt
setblock ~118 ~124 ~139 dirt
setblock ~118 ~124 ~140 dirt
setblock ~118 ~124 ~141 dirt
setblock ~118 ~124 ~142 dirt
setblock ~118 ~124 ~143 dirt
setblock ~118 ~124 ~144 dirt
setblock ~118 ~124 ~145 dirt
setblock ~118 ~124 ~146 grass_block
setblock ~118 ~124 ~147 grass_block
setblock ~118 ~124 ~148 grass_block
setblock ~118 ~124 ~149 grass_block
setblock ~118 ~124 ~150 grass_block
setblock ~118 ~124 ~151 grass_block
setblock ~118 ~124 ~152 grass_block
setblock ~118 ~124 ~153 grass_block
setblock ~118 ~124 ~154 grass_block
setblock ~118 ~124 ~155 grass_block
setblock ~118 ~124 ~156 grass_block
setblock ~118 ~124 ~157 grass_block
setblock ~118 ~124 ~158 grass_block
setblock ~118 ~124 ~159 grass_block
setblock ~118 ~124 ~160 grass_block
setblock ~118 ~124 ~161 dirt
setblock ~118 ~124 ~162 dirt
setblock ~118 ~124 ~163 dirt
setblock ~118 ~124 ~164 dirt
setblock ~118 ~124 ~165 dirt
setblock ~118 ~124 ~166 dirt
setblock ~118 ~124 ~167 dirt
setblock ~118 ~124 ~168 dirt
setblock ~118 ~124 ~169 dirt
setblock ~118 ~124 ~170 dirt
setblock ~118 ~124 ~171 dirt
setblock ~118 ~124 ~172 dirt
setblock ~118 ~124 ~173 dirt
setblock ~118 ~124 ~174 dirt
setblock ~118 ~124 ~175 dirt
setblock ~118 ~124 ~176 dirt
setblock ~118 ~124 ~177 dirt
setblock ~118 ~124 ~178 dirt
setblock ~118 ~124 ~179 dirt
setblock ~118 ~124 ~180 dirt
setblock ~118 ~124 ~181 dirt
setblock ~118 ~124 ~182 dirt
setblock ~118 ~124 ~183 grass_block
setblock ~118 ~124 ~184 grass_block
setblock ~118 ~124 ~185 grass_block
setblock ~118 ~124 ~186 grass_block
setblock ~118 ~124 ~187 grass_block
setblock ~118 ~124 ~188 grass_block
setblock ~118 ~124 ~189 grass_block
setblock ~118 ~124 ~190 grass_block
setblock ~118 ~124 ~191 grass_block
setblock ~118 ~124 ~192 grass_block
setblock ~118 ~124 ~196 short_grass
setblock ~118 ~125 ~0 grass_block
setblock ~118 ~125 ~1 grass_block
setblock ~118 ~125 ~2 grass_block
setblock ~118 ~125 ~3 grass_block
setblock ~118 ~125 ~4 grass_block
setblock ~118 ~125 ~5 grass_block
setblock ~118 ~125 ~6 grass_block
setblock ~118 ~125 ~7 grass_block
setblock ~118 ~125 ~10 poppy
setblock ~118 ~125 ~12 short_grass
setblock ~118 ~125 ~14 short_grass
setblock ~118 ~125 ~17 short_grass
setblock ~118 ~125 ~35 short_grass
setblock ~118 ~125 ~37 poppy
setblock ~118 ~125 ~39 short_grass
setblock ~118 ~125 ~42 poppy
setblock ~118 ~125 ~43 poppy
setblock ~118 ~125 ~44 short_grass
setblock ~118 ~125 ~49 short_grass
setblock ~118 ~125 ~51 poppy
setblock ~118 ~125 ~52 short_grass
setblock ~118 ~125 ~54 grass_block
setblock ~118 ~125 ~55 grass_block
setblock ~118 ~125 ~56 grass_block
setblock ~118 ~125 ~57 dirt
setblock ~118 ~125 ~58 dirt
setblock ~118 ~125 ~59 dirt
setblock ~118 ~125 ~60 dirt
setblock ~118 ~125 ~61 dirt
setblock ~118 ~125 ~62 dirt
setblock ~118 ~125 ~63 dirt
setblock ~118 ~125 ~64 dirt
setblock ~118 ~125 ~65 dirt
setblock ~118 ~125 ~66 dirt
setblock ~118 ~125 ~67 dirt
setblock ~118 ~125 ~68 dirt
setblock ~118 ~125 ~69 dirt
setblock ~118 ~125 ~70 dirt
setblock ~118 ~125 ~71 dirt
setblock ~118 ~125 ~72 dirt
setblock ~118 ~125 ~73 dirt
setblock ~118 ~125 ~74 dirt
setblock ~118 ~125 ~75 dirt
setblock ~118 ~125 ~76 dirt
setblock ~118 ~125 ~77 dirt
setblock ~118 ~125 ~78 dirt
setblock ~118 ~125 ~79 dirt
setblock ~118 ~125 ~80 dirt
setblock ~118 ~125 ~81 dirt
setblock ~118 ~125 ~82 dirt
setblock ~118 ~125 ~83 dirt
setblock ~118 ~125 ~84 dirt
setblock ~118 ~125 ~85 dirt
setblock ~118 ~125 ~86 dirt
setblock ~118 ~125 ~87 dirt
setblock ~118 ~125 ~88 dirt
setblock ~118 ~125 ~89 dirt
setblock ~118 ~125 ~90 dirt
setblock ~118 ~125 ~91 dirt
setblock ~118 ~125 ~92 dirt
setblock ~118 ~125 ~93 dirt
setblock ~118 ~125 ~94 dirt
setblock ~118 ~125 ~95 dirt
setblock ~118 ~125 ~96 grass_block
setblock ~118 ~125 ~97 grass_block
setblock ~118 ~125 ~99 short_grass
setblock ~118 ~125 ~103 short_grass
setblock ~118 ~125 ~108 short_grass
setblock ~118 ~125 ~114 short_grass
setblock ~118 ~125 ~115 short_grass
setblock ~118 ~125 ~117 short_grass
setblock ~118 ~125 ~119 short_grass
setblock ~118 ~125 ~121 short_grass
setblock ~118 ~125 ~122 short_grass
setblock ~118 ~125 ~125 short_grass
setblock ~118 ~125 ~127 poppy
setblock ~118 ~125 ~128 short_grass
setblock ~118 ~125 ~130 short_grass
setblock ~118 ~125 ~132 short_grass
setblock ~118 ~125 ~133 grass_block
setblock ~118 ~125 ~134 grass_block
setblock ~118 ~125 ~135 grass_block
setblock ~118 ~125 ~136 grass_block
setblock ~118 ~125 ~137 dirt
setblock ~118 ~125 ~138 dirt
setblock ~118 ~125 ~139 dirt
setblock ~118 ~125 ~140 dirt
setblock ~118 ~125 ~141 dirt
setblock ~118 ~125 ~142 dirt
setblock ~118 ~125 ~143 grass_block
setblock ~118 ~125 ~144 grass_block
setblock ~118 ~125 ~145 grass_block
setblock ~118 ~125 ~147 short_grass
setblock ~118 ~125 ~149 fern
setblock ~118 ~125 ~152 short_grass
setblock ~118 ~125 ~153 short_grass
setblock ~118 ~125 ~161 grass_block
setblock ~118 ~125 ~162 grass_block
setblock ~118 ~125 ~163 grass_block
setblock ~118 ~125 ~164 grass_block
setblock ~118 ~125 ~165 dirt
setblock ~118 ~125 ~166 dirt
setblock ~118 ~125 ~167 dirt
setblock ~118 ~125 ~168 dirt
setblock ~118 ~125 ~169 dirt
setblock ~118 ~125 ~170 dirt
setblock ~118 ~125 ~171 dirt
setblock ~118 ~125 ~172 dirt
setblock ~118 ~125 ~173 dirt
setblock ~118 ~125 ~174 dirt
setblock ~118 ~125 ~175 dirt
setblock ~118 ~125 ~176 dirt
setblock ~118 ~125 ~177 grass_block
setblock ~118 ~125 ~178 grass_block
setblock ~118 ~125 ~179 grass_block
setblock ~118 ~125 ~180 grass_block
setblock ~118 ~125 ~181 grass_block
setblock ~118 ~125 ~182 grass_block
setblock ~118 ~125 ~183 poppy
setblock ~118 ~125 ~186 short_grass
setblock ~118 ~125 ~187 short_grass
setblock ~118 ~126 ~2 short_grass
setblock ~118 ~126 ~57 grass_block
setblock ~118 ~126 ~58 grass_block
setblock ~118 ~126 ~59 dirt
setblock ~118 ~126 ~60 dirt
setblock ~118 ~126 ~61 dirt
setblock ~118 ~126 ~62 dirt
setblock ~118 ~126 ~63 dirt
setblock ~118 ~126 ~64 dirt
setblock ~118 ~126 ~65 dirt
setblock ~118 ~126 ~66 dirt
setblock ~118 ~126 ~67 dirt
setblock ~118 ~126 ~68 dirt
setblock ~118 ~126 ~69 dirt
setblock ~118 ~126 ~70 dirt
setblock ~118 ~126 ~71 dirt
setblock ~118 ~126 ~72 dirt
setblock ~118 ~126 ~73 dirt
setblock ~118 ~126 ~74 dirt
setblock ~118 ~126 ~75 dirt
setblock ~118 ~126 ~76 dirt
setblock ~118 ~126 ~77 dirt
setblock ~118 ~126 ~78 dirt
setblock ~118 ~126 ~79 dirt
setblock ~118 ~126 ~80 dirt
setblock ~118 ~126 ~81 dirt
setblock ~118 ~126 ~82 dirt
setblock ~118 ~126 ~83 dirt
setblock ~118 ~126 ~84 dirt
setblock ~118 ~126 ~85 dirt
setblock ~118 ~126 ~86 dirt
setblock ~118 ~126 ~87 dirt
setblock ~118 ~126 ~88 dirt
setblock ~118 ~126 ~89 dirt
setblock ~118 ~126 ~90 dirt
setblock ~118 ~126 ~91 dirt
setblock ~118 ~126 ~92 dirt
setblock ~118 ~126 ~93 grass_block
setblock ~118 ~126 ~94 grass_block
setblock ~118 ~126 ~95 grass_block
setblock ~118 ~126 ~134 short_grass
setblock ~118 ~126 ~135 short_grass
setblock ~118 ~126 ~137 grass_block
setblock ~118 ~126 ~138 grass_block
setblock ~118 ~126 ~139 grass_block
setblock ~118 ~126 ~140 dirt
setblock ~118 ~126 ~141 grass_block
setblock ~118 ~126 ~142 grass_block
setblock ~118 ~126 ~145 short_grass
setblock ~118 ~126 ~161 short_grass
setblock ~118 ~126 ~165 grass_block
setblock ~118 ~126 ~166 grass_block
setblock ~118 ~126 ~167 grass_block
setblock ~118 ~126 ~168 grass_block
setblock ~118 ~126 ~169 dirt
setblock ~118 ~126 ~170 dirt
setblock ~118 ~126 ~171 dirt
setblock ~118 ~126 ~172 grass_block
setblock ~118 ~126 ~173 grass_block
setblock ~118 ~126 ~174 grass_block
setblock ~118 ~126 ~175 grass_block
setblock ~118 ~126 ~176 grass_block
setblock ~118 ~126 ~178 short_grass
setblock ~118 ~126 ~181 short_grass
setblock ~118 ~127 ~57 short_grass
setblock ~118 ~127 ~59 grass_block
setblock ~118 ~127 ~60 dirt
setblock ~118 ~127 ~61 dirt
setblock ~118 ~127 ~62 grass_block
setblock ~118 ~127 ~63 grass_block
setblock ~118 ~127 ~64 grass_block
setblock ~118 ~127 ~65 grass_block
setblock ~118 ~127 ~66 grass_block
setblock ~118 ~127 ~67 grass_block
setblock ~118 ~127 ~68 grass_block
setblock ~118 ~127 ~69 grass_block
setblock ~118 ~127 ~70 grass_block
setblock ~118 ~127 ~71 grass_block
setblock ~118 ~127 ~72 grass_block
setblock ~118 ~127 ~73 grass_block
setblock ~118 ~127 ~74 grass_block
setblock ~118 ~127 ~75 grass_block
setblock ~118 ~127 ~76 grass_block
setblock ~118 ~127 ~77 grass_block
setblock ~118 ~127 ~78 grass_block
setblock ~118 ~127 ~79 grass_block
setblock ~118 ~127 ~80 grass_block
setblock ~118 ~127 ~81 grass_block
setblock ~118 ~127 ~82 grass_block
setblock ~118 ~127 ~83 grass_block
setblock ~118 ~127 ~84 grass_block
setblock ~118 ~127 ~85 grass_block
setblock ~118 ~127 ~86 grass_block
setblock ~118 ~127 ~87 grass_block
setblock ~118 ~127 ~88 grass_block
setblock ~118 ~127 ~89 grass_block
setblock ~118 ~127 ~90 grass_block
setblock ~118 ~127 ~91 grass_block
setblock ~118 ~127 ~92 grass_block
setblock ~118 ~127 ~93 poppy
setblock ~118 ~127 ~95 short_grass
setblock ~118 ~127 ~139 short_grass
setblock ~118 ~127 ~140 grass_block
setblock ~118 ~127 ~169 grass_block
setblock ~118 ~127 ~170 grass_block
setblock ~118 ~127 ~171 grass_block
setblock ~118 ~127 ~173 poppy
setblock ~118 ~127 ~176 short_grass
setblock ~118 ~128 ~60 grass_block
setblock ~118 ~128 ~61 grass_block
setblock ~118 ~128 ~63 short_grass
setblock ~118 ~128 ~67 short_grass
setblock ~118 ~128 ~68 short_grass
setblock ~118 ~128 ~69 short_grass
setblock ~118 ~128 ~70 fern
setblock ~118 ~128 ~71 short_grass
setblock ~118 ~128 ~83 short_grass
setblock ~118 ~128 ~84 poppy
setblock ~118 ~128 ~88 poppy
setblock ~118 ~128 ~89 poppy
setblock ~118 ~128 ~90 short_grass
setblock ~118 ~129 ~60 short_grass
setblock ~118 ~129 ~61 poppy
setblock ~119 ~122 ~0 dirt
setblock ~119 ~122 ~1 dirt
setblock ~119 ~122 ~2 dirt
setblock ~119 ~122 ~3 dirt
setblock ~119 ~122 ~4 dirt
setblock ~119 ~122 ~5 dirt
setblock ~119 ~122 ~6 dirt
setblock ~119 ~122 ~7 dirt
setblock ~119 ~122 ~8 dirt
setblock ~119 ~122 ~9 dirt
setblock ~119 ~122 ~10 dirt
setblock ~119 ~122 ~11 dirt
setblock ~119 ~122 ~12 dirt
setblock ~119 ~122 ~13 dirt
setblock ~119 ~122 ~14 dirt
setblock ~119 ~122 ~15 dirt
setblock ~119 ~122 ~16 dirt
setblock ~119 ~122 ~17 dirt
setblock ~119 ~122 ~18 dirt
setblock ~119 ~122 ~19 dirt
setblock ~119 ~122 ~20 dirt
setblock ~119 ~122 ~21 dirt
setblock ~119 ~122 ~22 dirt
setblock ~119 ~122 ~23 dirt
setblock ~119 ~122 ~24 dirt
setblock ~119 ~122 ~25 dirt
setblock ~119 ~122 ~26 dirt
setblock ~119 ~122 ~27 dirt
setblock ~119 ~122 ~28 dirt
setblock ~119 ~122 ~29 dirt
setblock ~119 ~122 ~30 dirt
setblock ~119 ~122 ~31 dirt
setblock ~119 ~122 ~32 dirt
setblock ~119 ~122 ~33 dirt
setblock ~119 ~122 ~34 dirt
setblock ~119 ~122 ~35 dirt
setblock ~119 ~122 ~36 dirt
setblock ~119 ~122 ~37 dirt
setblock ~119 ~122 ~38 dirt
setblock ~119 ~122 ~39 dirt
setblock ~119 ~122 ~40 dirt
setblock ~119 ~122 ~41 dirt
setblock ~119 ~122 ~42 dirt
setblock ~119 ~122 ~43 dirt
setblock ~119 ~122 ~44 dirt
setblock ~119 ~122 ~45 dirt
setblock ~119 ~122 ~46 dirt
setblock ~119 ~122 ~47 dirt
setblock ~119 ~122 ~48 dirt
setblock ~119 ~122 ~49 dirt
setblock ~119 ~122 ~50 dirt
setblock ~119 ~122 ~51 dirt
setblock ~119 ~122 ~52 dirt
setblock ~119 ~122 ~53 dirt
setblock ~119 ~122 ~54 dirt
setblock ~119 ~122 ~55 dirt
setblock ~119 ~122 ~56 dirt
setblock ~119 ~122 ~57 dirt
setblock ~119 ~122 ~58 dirt
setblock ~119 ~122 ~59 dirt
setblock ~119 ~122 ~60 dirt
setblock ~119 ~122 ~61 dirt
setblock ~119 ~122 ~62 dirt
setblock ~119 ~122 ~63 dirt
setblock ~119 ~122 ~64 dirt
setblock ~119 ~122 ~65 dirt
setblock ~119 ~122 ~66 dirt
setblock ~119 ~122 ~67 dirt
setblock ~119 ~122 ~68 dirt
setblock ~119 ~122 ~69 dirt
setblock ~119 ~122 ~70 dirt
setblock ~119 ~122 ~71 dirt
setblock ~119 ~122 ~72 dirt
setblock ~119 ~122 ~73 dirt
setblock ~119 ~122 ~74 dirt
setblock ~119 ~122 ~75 dirt
setblock ~119 ~122 ~76 dirt
setblock ~119 ~122 ~77 dirt
setblock ~119 ~122 ~78 dirt
setblock ~119 ~122 ~79 dirt
setblock ~119 ~122 ~80 dirt
setblock ~119 ~122 ~81 dirt
setblock ~119 ~122 ~82 dirt
setblock ~119 ~122 ~83 dirt
setblock ~119 ~122 ~84 dirt
setblock ~119 ~122 ~85 dirt
setblock ~119 ~122 ~86 dirt
setblock ~119 ~122 ~87 dirt
setblock ~119 ~122 ~88 dirt
setblock ~119 ~122 ~89 dirt
setblock ~119 ~122 ~90 dirt
setblock ~119 ~122 ~91 dirt
setblock ~119 ~122 ~92 dirt
setblock ~119 ~122 ~93 dirt
setblock ~119 ~122 ~94 dirt
setblock ~119 ~122 ~95 dirt
setblock ~119 ~122 ~96 dirt
setblock ~119 ~122 ~97 dirt
setblock ~119 ~122 ~98 dirt
setblock ~119 ~122 ~99 dirt
setblock ~119 ~122 ~100 dirt
setblock ~119 ~122 ~101 dirt
setblock ~119 ~122 ~102 dirt
setblock ~119 ~122 ~103 dirt
setblock ~119 ~122 ~104 dirt
setblock ~119 ~122 ~105 dirt
setblock ~119 ~122 ~106 dirt
setblock ~119 ~122 ~107 dirt
setblock ~119 ~122 ~108 dirt
setblock ~119 ~122 ~109 dirt
setblock ~119 ~122 ~110 dirt
setblock ~119 ~122 ~111 dirt
setblock ~119 ~122 ~112 dirt
setblock ~119 ~122 ~113 dirt
setblock ~119 ~122 ~114 dirt
setblock ~119 ~122 ~115 dirt
setblock ~119 ~122 ~116 dirt
setblock ~119 ~122 ~117 dirt
setblock ~119 ~122 ~118 dirt
setblock ~119 ~122 ~119 dirt
setblock ~119 ~122 ~120 dirt
setblock ~119 ~122 ~121 dirt
setblock ~119 ~122 ~122 dirt
setblock ~119 ~122 ~123 dirt
setblock ~119 ~122 ~124 dirt
setblock ~119 ~122 ~125 dirt
setblock ~119 ~122 ~126 dirt
setblock ~119 ~122 ~127 dirt
setblock ~119 ~122 ~128 dirt
setblock ~119 ~122 ~129 dirt
setblock ~119 ~122 ~130 dirt
setblock ~119 ~122 ~131 dirt
setblock ~119 ~122 ~132 dirt
setblock ~119 ~122 ~133 dirt
setblock ~119 ~122 ~134 dirt
setblock ~119 ~122 ~135 dirt
setblock ~119 ~122 ~136 dirt
setblock ~119 ~122 ~137 dirt
setblock ~119 ~122 ~138 dirt
setblock ~119 ~122 ~139 dirt
setblock ~119 ~122 ~140 dirt
setblock ~119 ~122 ~141 dirt
setblock ~119 ~122 ~142 dirt
setblock ~119 ~122 ~143 dirt
setblock ~119 ~122 ~144 dirt
setblock ~119 ~122 ~145 dirt
setblock ~119 ~122 ~146 dirt
setblock ~119 ~122 ~147 dirt
setblock ~119 ~122 ~148 dirt
setblock ~119 ~122 ~149 dirt
setblock ~119 ~122 ~150 dirt
setblock ~119 ~122 ~151 dirt
setblock ~119 ~122 ~152 dirt
setblock ~119 ~122 ~153 dirt
setblock ~119 ~122 ~154 dirt
setblock ~119 ~122 ~155 dirt
setblock ~119 ~122 ~156 dirt
setblock ~119 ~122 ~157 dirt
setblock ~119 ~122 ~158 dirt
setblock ~119 ~122 ~159 dirt
setblock ~119 ~122 ~160 dirt
setblock ~119 ~122 ~161 dirt
setblock ~119 ~122 ~162 dirt
setblock ~119 ~122 ~163 dirt
setblock ~119 ~122 ~164 dirt
setblock ~119 ~122 ~165 dirt
setblock ~119 ~122 ~166 dirt
setblock ~119 ~122 ~167 dirt
setblock ~119 ~122 ~168 dirt
setblock ~119 ~122 ~169 dirt
setblock ~119 ~122 ~170 dirt
setblock ~119 ~122 ~171 dirt
setblock ~119 ~122 ~172 dirt
setblock ~119 ~122 ~173 dirt
setblock ~119 ~122 ~174 dirt
setblock ~119 ~122 ~175 dirt
setblock ~119 ~122 ~176 dirt
setblock ~119 ~122 ~177 dirt
setblock ~119 ~122 ~178 dirt
setblock ~119 ~122 ~179 dirt
setblock ~119 ~122 ~180 dirt
setblock ~119 ~122 ~181 dirt
setblock ~119 ~122 ~182 dirt
setblock ~119 ~122 ~183 dirt
setblock ~119 ~122 ~184 dirt
setblock ~119 ~122 ~185 dirt
setblock ~119 ~122 ~186 dirt
setblock ~119 ~122 ~187 dirt
setblock ~119 ~122 ~188 dirt
setblock ~119 ~122 ~189 dirt
setblock ~119 ~122 ~190 dirt
setblock ~119 ~122 ~191 dirt
setblock ~119 ~122 ~192 dirt
setblock ~119 ~122 ~193 dirt
setblock ~119 ~122 ~194 dirt
setblock ~119 ~122 ~195 dirt
setblock ~119 ~122 ~196 dirt
setblock ~119 ~122 ~197 dirt
setblock ~119 ~122 ~198 dirt
setblock ~119 ~122 ~199 grass_block
setblock ~119 ~123 ~0 dirt
setblock ~119 ~123 ~1 dirt
setblock ~119 ~123 ~2 dirt
setblock ~119 ~123 ~3 dirt
setblock ~119 ~123 ~4 dirt
setblock ~119 ~123 ~5 dirt
setblock ~119 ~123 ~6 dirt
setblock ~119 ~123 ~7 dirt
setblock ~119 ~123 ~8 dirt
setblock ~119 ~123 ~9 dirt
setblock ~119 ~123 ~10 dirt
setblock ~119 ~123 ~11 dirt
setblock ~119 ~123 ~12 dirt
setblock ~119 ~123 ~13 dirt
setblock ~119 ~123 ~14 dirt
setblock ~119 ~123 ~15 dirt
setblock ~119 ~123 ~16 dirt
setblock ~119 ~123 ~17 dirt
setblock ~119 ~123 ~18 grass_block
setblock ~119 ~123 ~19 grass_block
setblock ~119 ~123 ~20 grass_block
setblock ~119 ~123 ~21 grass_block
setblock ~119 ~123 ~22 grass_block
setblock ~119 ~123 ~23 grass_block
setblock ~119 ~123 ~24 grass_block
setblock ~119 ~123 ~25 grass_block
setblock ~119 ~123 ~26 grass_block
setblock ~119 ~123 ~27 grass_block
setblock ~119 ~123 ~28 grass_block
setblock ~119 ~123 ~29 grass_block
setblock ~119 ~123 ~30 grass_block
setblock ~119 ~123 ~31 grass_block
setblock ~119 ~123 ~32 grass_block
setblock ~119 ~123 ~33 grass_block
setblock ~119 ~123 ~34 grass_block
setblock ~119 ~123 ~35 grass_block
setblock ~119 ~123 ~36 dirt
setblock ~119 ~123 ~37 dirt
setblock ~119 ~123 ~38 dirt
setblock ~119 ~123 ~39 dirt
setblock ~119 ~123 ~40 dirt
setblock ~119 ~123 ~41 dirt
setblock ~119 ~123 ~42 dirt
setblock ~119 ~123 ~43 dirt
setblock ~119 ~123 ~44 dirt
setblock ~119 ~123 ~45 dirt
setblock ~119 ~123 ~46 dirt
setblock ~119 ~123 ~47 dirt
setblock ~119 ~123 ~48 dirt
setblock ~119 ~123 ~49 dirt
setblock ~119 ~123 ~50 dirt
setblock ~119 ~123 ~51 dirt
setblock ~119 ~123 ~52 dirt
setblock ~119 ~123 ~53 dirt
setblock ~119 ~123 ~54 dirt
setblock ~119 ~123 ~55 dirt
setblock ~119 ~123 ~56 dirt
setblock ~119 ~123 ~57 dirt
setblock ~119 ~123 ~58 dirt
setblock ~119 ~123 ~59 dirt
setblock ~119 ~123 ~60 dirt
setblock ~119 ~123 ~61 dirt
setblock ~119 ~123 ~62 dirt
setblock ~119 ~123 ~63 dirt
setblock ~119 ~123 ~64 dirt
setblock ~119 ~123 ~65 dirt
setblock ~119 ~123 ~66 dirt
setblock ~119 ~123 ~67 dirt
setblock ~119 ~123 ~68 dirt
setblock ~119 ~123 ~69 dirt
setblock ~119 ~123 ~70 dirt
setblock ~119 ~123 ~71 dirt
setblock ~119 ~123 ~72 dirt
setblock ~119 ~123 ~73 dirt
setblock ~119 ~123 ~74 dirt
setblock ~119 ~123 ~75 dirt
setblock ~119 ~123 ~76 dirt
setblock ~119 ~123 ~77 dirt
setblock ~119 ~123 ~78 dirt
setblock ~119 ~123 ~79 dirt
setblock ~119 ~123 ~80 dirt
setblock ~119 ~123 ~81 dirt
setblock ~119 ~123 ~82 dirt
setblock ~119 ~123 ~83 dirt
setblock ~119 ~123 ~84 dirt
setblock ~119 ~123 ~85 dirt
setblock ~119 ~123 ~86 dirt
setblock ~119 ~123 ~87 dirt
setblock ~119 ~123 ~88 dirt
setblock ~119 ~123 ~89 dirt
setblock ~119 ~123 ~90 dirt
setblock ~119 ~123 ~91 dirt
setblock ~119 ~123 ~92 dirt
setblock ~119 ~123 ~93 dirt
setblock ~119 ~123 ~94 dirt
setblock ~119 ~123 ~95 dirt
setblock ~119 ~123 ~96 dirt
setblock ~119 ~123 ~97 dirt
setblock ~119 ~123 ~98 dirt
setblock ~119 ~123 ~99 dirt
setblock ~119 ~123 ~100 dirt
setblock ~119 ~123 ~101 dirt
setblock ~119 ~123 ~102 dirt
setblock ~119 ~123 ~103 dirt
setblock ~119 ~123 ~104 dirt
setblock ~119 ~123 ~105 dirt
setblock ~119 ~123 ~106 grass_block
setblock ~119 ~123 ~107 grass_block
setblock ~119 ~123 ~108 grass_block
setblock ~119 ~123 ~109 grass_block
setblock ~119 ~123 ~110 grass_block
setblock ~119 ~123 ~111 grass_block
setblock ~119 ~123 ~112 grass_block
setblock ~119 ~123 ~113 grass_block
setblock ~119 ~123 ~114 grass_block
setblock ~119 ~123 ~115 grass_block
setblock ~119 ~123 ~116 grass_block
setblock ~119 ~123 ~117 dirt
setblock ~119 ~123 ~118 dirt
setblock ~119 ~123 ~119 dirt
setblock ~119 ~123 ~120 dirt
setblock ~119 ~123 ~121 dirt
setblock ~119 ~123 ~122 dirt
setblock ~119 ~123 ~123 dirt
setblock ~119 ~123 ~124 dirt
setblock ~119 ~123 ~125 dirt
setblock ~119 ~123 ~126 dirt
setblock ~119 ~123 ~127 dirt
setblock ~119 ~123 ~128 dirt
setblock ~119 ~123 ~129 dirt
setblock ~119 ~123 ~130 dirt
setblock ~119 ~123 ~131 dirt
setblock ~119 ~123 ~132 dirt
setblock ~119 ~123 ~133 dirt
setblock ~119 ~123 ~134 dirt
setblock ~119 ~123 ~135 dirt
setblock ~119 ~123 ~136 dirt
setblock ~119 ~123 ~137 dirt
setblock ~119 ~123 ~138 dirt
setblock ~119 ~123 ~139 dirt
setblock ~119 ~123 ~140 dirt
setblock ~119 ~123 ~141 dirt
setblock ~119 ~123 ~142 dirt
setblock ~119 ~123 ~143 dirt
setblock ~119 ~123 ~144 dirt
setblock ~119 ~123 ~145 dirt
setblock ~119 ~123 ~146 dirt
setblock ~119 ~123 ~147 dirt
setblock ~119 ~123 ~148 dirt
setblock ~119 ~123 ~149 dirt
setblock ~119 ~123 ~150 dirt
setblock ~119 ~123 ~151 dirt
setblock ~119 ~123 ~152 dirt
setblock ~119 ~123 ~153 dirt
setblock ~119 ~123 ~154 dirt
setblock ~119 ~123 ~155 dirt
setblock ~119 ~123 ~156 dirt
setblock ~119 ~123 ~157 dirt
setblock ~119 ~123 ~158 dirt
setblock ~119 ~123 ~159 dirt
setblock ~119 ~123 ~160 dirt
setblock ~119 ~123 ~161 dirt
setblock ~119 ~123 ~162 dirt
setblock ~119 ~123 ~163 dirt
setblock ~119 ~123 ~164 dirt
setblock ~119 ~123 ~165 dirt
setblock ~119 ~123 ~166 dirt
setblock ~119 ~123 ~167 dirt
setblock ~119 ~123 ~168 dirt
setblock ~119 ~123 ~169 dirt
setblock ~119 ~123 ~170 dirt
setblock ~119 ~123 ~171 dirt
setblock ~119 ~123 ~172 dirt
setblock ~119 ~123 ~173 dirt
setblock ~119 ~123 ~174 dirt
setblock ~119 ~123 ~175 dirt
setblock ~119 ~123 ~176 dirt
setblock ~119 ~123 ~177 dirt
setblock ~119 ~123 ~178 dirt
setblock ~119 ~123 ~179 dirt
setblock ~119 ~123 ~180 dirt
setblock ~119 ~123 ~181 dirt
setblock ~119 ~123 ~182 dirt
setblock ~119 ~123 ~183 dirt
setblock ~119 ~123 ~184 dirt
setblock ~119 ~123 ~185 dirt
setblock ~119 ~123 ~186 dirt
setblock ~119 ~123 ~187 dirt
setblock ~119 ~123 ~188 dirt
setblock ~119 ~123 ~189 grass_block
setblock ~119 ~123 ~190 grass_block
setblock ~119 ~123 ~191 grass_block
setblock ~119 ~123 ~192 grass_block
setblock ~119 ~123 ~193 grass_block
setblock ~119 ~123 ~194 grass_block
setblock ~119 ~123 ~195 grass_block
setblock ~119 ~123 ~196 grass_block
setblock ~119 ~123 ~197 grass_block
setblock ~119 ~123 ~198 grass_block
setblock ~119 ~123 ~199 poppy
setblock ~119 ~124 ~0 grass_block
setblock ~119 ~124 ~1 grass_block
setblock ~119 ~124 ~2 grass_block
setblock ~119 ~124 ~3 grass_block
setblock ~119 ~124 ~4 grass_block
setblock ~119 ~124 ~5 grass_block
setblock ~119 ~124 ~6 grass_block
setblock ~119 ~124 ~7 grass_block
setblock ~119 ~124 ~8 grass_block
setblock ~119 ~124 ~9 grass_block
setblock ~119 ~124 ~10 grass_block
setblock ~119 ~124 ~11 grass_block
setblock ~119 ~124 ~12 grass_block
setblock ~119 ~124 ~13 grass_block
setblock ~119 ~124 ~14 grass_block
setblock ~119 ~124 ~15 grass_block
setblock ~119 ~124 ~16 grass_block
setblock ~119 ~124 ~17 grass_block
setblock ~119 ~124 ~18 short_grass
setblock ~119 ~124 ~20 short_grass
setblock ~119 ~124 ~23 short_grass
setblock ~119 ~124 ~26 short_grass
setblock ~119 ~124 ~30 short_grass
setblock ~119 ~124 ~35 poppy
setblock ~119 ~124 ~36 grass_block
setblock ~119 ~124 ~37 grass_block
setblock ~119 ~124 ~38 grass_block
setblock ~119 ~124 ~39 grass_block
setblock ~119 ~124 ~40 grass_block
setblock ~119 ~124 ~41 grass_block
setblock ~119 ~124 ~42 grass_block
setblock ~119 ~124 ~43 grass_block
setblock ~119 ~124 ~44 grass_block
setblock ~119 ~124 ~45 grass_block
setblock ~119 ~124 ~46 grass_block
setblock ~119 ~124 ~47 grass_block
setblock ~119 ~124 ~48 grass_block
setblock ~119 ~124 ~49 grass_block
setblock ~119 ~124 ~50 grass_block
setblock ~119 ~124 ~51 grass_block
setblock ~119 ~124 ~52 grass_block
setblock ~119 ~124 ~53 grass_block
setblock ~119 ~124 ~54 dirt
setblock ~119 ~124 ~55 dirt
setblock ~119 ~124 ~56 dirt
setblock ~119 ~124 ~57 dirt
setblock ~119 ~124 ~58 dirt
setblock ~119 ~124 ~59 dirt
setblock ~119 ~124 ~60 dirt
setblock ~119 ~124 ~61 dirt
setblock ~119 ~124 ~62 dirt
setblock ~119 ~124 ~63 dirt
setblock ~119 ~124 ~64 dirt
setblock ~119 ~124 ~65 dirt
setblock ~119 ~124 ~66 dirt
setblock ~119 ~124 ~67 dirt
setblock ~119 ~124 ~68 dirt
setblock ~119 ~124 ~69 dirt
setblock ~119 ~124 ~70 dirt
setblock ~119 ~124 ~71 dirt
setblock ~119 ~124 ~72 dirt
setblock ~119 ~124 ~73 dirt
setblock ~119 ~124 ~74 dirt
setblock ~119 ~124 ~75 dirt
setblock ~119 ~124 ~76 dirt
setblock ~119 ~124 ~77 dirt
setblock ~119 ~124 ~78 dirt
setblock ~119 ~124 ~79 dirt
setblock ~119 ~124 ~80 dirt
setblock ~119 ~124 ~81 dirt
setblock ~119 ~124 ~82 dirt
setblock ~119 ~124 ~83 dirt
setblock ~119 ~124 ~84 dirt
setblock ~119 ~124 ~85 dirt
setblock ~119 ~124 ~86 dirt
setblock ~119 ~124 ~87 dirt
setblock ~119 ~124 ~88 dirt
setblock ~119 ~124 ~89 dirt
setblock ~119 ~124 ~90 dirt
setblock ~119 ~124 ~91 dirt
setblock ~119 ~124 ~92 dirt
setblock ~119 ~124 ~93 dirt
setblock ~119 ~124 ~94 dirt
setblock ~119 ~124 ~95 dirt
setblock ~119 ~124 ~96 dirt
setblock ~119 ~124 ~97 dirt
setblock ~119 ~124 ~98 dirt
setblock ~119 ~124 ~99 grass_block
setblock ~119 ~124 ~100 grass_block
setblock ~119 ~124 ~101 grass_block
setblock ~119 ~124 ~102 grass_block
setblock ~119 ~124 ~103 grass_block
setblock ~119 ~124 ~104 grass_block
setblock ~119 ~124 ~105 grass_block
setblock ~119 ~124 ~113 short_grass
setblock ~119 ~124 ~117 grass_block
setblock ~119 ~124 ~118 grass_block
setblock ~119 ~124 ~119 grass_block
setblock ~119 ~124 ~120 grass_block
setblock ~119 ~124 ~121 grass_block
setblock ~119 ~124 ~122 grass_block
setblock ~119 ~124 ~123 grass_block
setblock ~119 ~124 ~124 grass_block
setblock ~119 ~124 ~125 grass_block
setblock ~119 ~124 ~126 grass_block
setblock ~119 ~124 ~127 grass_block
setblock ~119 ~124 ~128 grass_block
setblock ~119 ~124 ~129 grass_block
setblock ~119 ~124 ~130 grass_block
setblock ~119 ~124 ~131 grass_block
setblock ~119 ~124 ~132 grass_block
setblock ~119 ~124 ~133 dirt
setblock ~119 ~124 ~134 dirt
setblock ~119 ~124 ~135 dirt
setblock ~119 ~124 ~136 dirt
setblock ~119 ~124 ~137 dirt
setblock ~119 ~124 ~138 dirt
setblock ~119 ~124 ~139 dirt
setblock ~119 ~124 ~140 dirt
setblock ~119 ~124 ~141 dirt
setblock ~119 ~124 ~142 dirt
setblock ~119 ~124 ~143 dirt
setblock ~119 ~124 ~144 dirt
setblock ~119 ~124 ~145 dirt
setblock ~119 ~124 ~146 dirt
setblock ~119 ~124 ~147 grass_block
setblock ~119 ~124 ~148 grass_block
setblock ~119 ~124 ~149 grass_block
setblock ~119 ~124 ~150 grass_block
setblock ~119 ~124 ~151 grass_block
setblock ~119 ~124 ~152 grass_block
setblock ~119 ~124 ~153 grass_block
setblock ~119 ~124 ~154 grass_block
setblock ~119 ~124 ~155 grass_block
setblock ~119 ~124 ~156 grass_block
setblock ~119 ~124 ~157 grass_block
setblock ~119 ~124 ~158 grass_block
setblock ~119 ~124 ~159 grass_block
setblock ~119 ~124 ~160 dirt
setblock ~119 ~124 ~161 dirt
setblock ~119 ~124 ~162 dirt
setblock ~119 ~124 ~163 dirt
setblock ~119 ~124 ~164 dirt
setblock ~119 ~124 ~165 dirt
setblock ~119 ~124 ~166 dirt
setblock ~119 ~124 ~167 dirt
setblock ~119 ~124 ~168 dirt
setblock ~119 ~124 ~169 dirt
setblock ~119 ~124 ~170 dirt
setblock ~119 ~124 ~171 dirt
setblock ~119 ~124 ~172 dirt
setblock ~119 ~124 ~173 dirt
setblock ~119 ~124 ~174 dirt
setblock ~119 ~124 ~175 dirt
setblock ~119 ~124 ~176 dirt
setblock ~119 ~124 ~177 dirt
setblock ~119 ~124 ~178 dirt
setblock ~119 ~124 ~179 dirt
setblock ~119 ~124 ~180 dirt
setblock ~119 ~124 ~181 dirt
setblock ~119 ~124 ~182 dirt
setblock ~119 ~124 ~183 grass_block
setblock ~119 ~124 ~184 grass_block
setblock ~119 ~124 ~185 grass_block
setblock ~119 ~124 ~186 grass_block
setblock ~119 ~124 ~187 grass_block
setblock ~119 ~124 ~188 grass_block
setblock ~119 ~124 ~190 short_grass
setblock ~119 ~124 ~197 poppy
setblock ~119 ~125 ~1 short_grass
setblock ~119 ~125 ~6 short_grass
setblock ~119 ~125 ~7 short_grass
setblock ~119 ~125 ~14 short_grass
setblock ~119 ~125 ~16 short_grass
setblock ~119 ~125 ~42 short_grass
setblock ~119 ~125 ~44 short_grass
setblock ~119 ~125 ~49 short_grass
setblock ~119 ~125 ~53 short_grass
setblock ~119 ~125 ~54 grass_block
setblock ~119 ~125 ~55 grass_block
setblock ~119 ~125 ~56 grass_block
setblock ~119 ~125 ~57 dirt
setblock ~119 ~125 ~58 dirt
setblock ~119 ~125 ~59 dirt
setblock ~119 ~125 ~60 dirt
setblock ~119 ~125 ~61 dirt
setblock ~119 ~125 ~62 dirt
setblock ~119 ~125 ~63 dirt
setblock ~119 ~125 ~64 dirt
setblock ~119 ~125 ~65 dirt
setblock ~119 ~125 ~66 dirt
setblock ~119 ~125 ~67 dirt
setblock ~119 ~125 ~68 dirt
setblock ~119 ~125 ~69 dirt
setblock ~119 ~125 ~70 dirt
setblock ~119 ~125 ~71 dirt
setblock ~119 ~125 ~72 dirt
setblock ~119 ~125 ~73 dirt
setblock ~119 ~125 ~74 dirt
setblock ~119 ~125 ~75 dirt
setblock ~119 ~125 ~76 dirt
setblock ~119 ~125 ~77 dirt
setblock ~119 ~125 ~78 dirt
setblock ~119 ~125 ~79 dirt
setblock ~119 ~125 ~80 dirt
setblock ~119 ~125 ~81 dirt
setblock ~119 ~125 ~82 dirt
setblock ~119 ~125 ~83 dirt
setblock ~119 ~125 ~84 dirt
setblock ~119 ~125 ~85 dirt
setblock ~119 ~125 ~86 dirt
setblock ~119 ~125 ~87 dirt
setblock ~119 ~125 ~88 dirt
setblock ~119 ~125 ~89 dirt
setblock ~119 ~125 ~90 dirt
setblock ~119 ~125 ~91 dirt
setblock ~119 ~125 ~92 dirt
setblock ~119 ~125 ~93 dirt
setblock ~119 ~125 ~94 dirt
setblock ~119 ~125 ~95 dirt
setblock ~119 ~125 ~96 grass_block
setblock ~119 ~125 ~97 grass_block
setblock ~119 ~125 ~98 grass_block
setblock ~119 ~125 ~103 fern
setblock ~119 ~125 ~119 short_grass
setblock ~119 ~125 ~127 short_grass
setblock ~119 ~125 ~132 short_grass
setblock ~119 ~125 ~133 grass_block
setblock ~119 ~125 ~134 grass_block
setblock ~119 ~125 ~135 grass_block
setblock ~119 ~125 ~136 grass_block
setblock ~119 ~125 ~137 dirt
setblock ~119 ~125 ~138 dirt
setblock ~119 ~125 ~139 dirt
setblock ~119 ~125 ~140 dirt
setblock ~119 ~125 ~141 dirt
setblock ~119 ~125 ~142 dirt
setblock ~119 ~125 ~143 grass_block
setblock ~119 ~125 ~144 grass_block
setblock ~119 ~125 ~145 grass_block
setblock ~119 ~125 ~146 grass_block
setblock ~119 ~125 ~147 short_grass
setblock ~119 ~125 ~149 short_grass
setblock ~119 ~125 ~151 poppy
setblock ~119 ~125 ~153 short_grass
setblock ~119 ~125 ~157 short_grass
setblock ~119 ~125 ~158 short_grass
setblock ~119 ~125 ~160 grass_block
setblock ~119 ~125 ~161 grass_block
setblock ~119 ~125 ~162 grass_block
setblock ~119 ~125 ~163 grass_block
setblock ~119 ~125 ~164 dirt
setblock ~119 ~125 ~165 dirt
setblock ~119 ~125 ~166 dirt
setblock ~119 ~125 ~167 dirt
setblock ~119 ~125 ~168 dirt
setblock ~119 ~125 ~169 dirt
setblock ~119 ~125 ~170 dirt
setblock ~119 ~125 ~171 dirt
setblock ~119 ~125 ~172 dirt
setblock ~119 ~125 ~173 dirt
setblock ~119 ~125 ~174 dirt
setblock ~119 ~125 ~175 dirt
setblock ~119 ~125 ~176 dirt
setblock ~119 ~125 ~177 dirt
setblock ~119 ~125 ~178 grass_block
setblock ~119 ~125 ~179 grass_block
setblock ~119 ~125 ~180 grass_block
setblock ~119 ~125 ~181 grass_block
setblock ~119 ~125 ~182 grass_block
setblock ~119 ~126 ~57 grass_block
setblock ~119 ~126 ~58 grass_block
setblock ~119 ~126 ~59 dirt
setblock ~119 ~126 ~60 dirt
setblock ~119 ~126 ~61 dirt
setblock ~119 ~126 ~62 dirt
setblock ~119 ~126 ~63 dirt
setblock ~119 ~126 ~64 dirt
setblock ~119 ~126 ~65 dirt
setblock ~119 ~126 ~66 dirt
setblock ~119 ~126 ~67 dirt
setblock ~119 ~126 ~68 dirt
setblock ~119 ~126 ~69 dirt
setblock ~119 ~126 ~70 dirt
setblock ~119 ~126 ~71 dirt
setblock ~119 ~126 ~72 dirt
setblock ~119 ~126 ~73 dirt
setblock ~119 ~126 ~74 dirt
setblock ~119 ~126 ~75 dirt
setblock ~119 ~126 ~76 dirt
setblock ~119 ~126 ~77 dirt
setblock ~119 ~126 ~78 dirt
setblock ~119 ~126 ~79 dirt
setblock ~119 ~126 ~80 dirt
setblock ~119 ~126 ~81 dirt
setblock ~119 ~126 ~82 dirt
setblock ~119 ~126 ~83 dirt
setblock ~119 ~126 ~84 dirt
setblock ~119 ~126 ~85 dirt
setblock ~119 ~126 ~86 dirt
setblock ~119 ~126 ~87 dirt
setblock ~119 ~126 ~88 dirt
setblock ~119 ~126 ~89 dirt
setblock ~119 ~126 ~90 dirt
setblock ~119 ~126 ~91 dirt
setblock ~119 ~126 ~92 dirt
setblock ~119 ~126 ~93 grass_block
setblock ~119 ~126 ~94 grass_block
setblock ~119 ~126 ~95 grass_block
setblock ~119 ~126 ~97 short_grass
setblock ~119 ~126 ~137 grass_block
setblock ~119 ~126 ~138 grass_block
setblock ~119 ~126 ~139 dirt
setblock ~119 ~126 ~140 dirt
setblock ~119 ~126 ~141 dirt
setblock ~119 ~126 ~142 grass_block
setblock ~119 ~126 ~164 grass_block
setblock ~119 ~126 ~165 grass_block
setblock ~119 ~126 ~166 grass_block
setblock ~119 ~126 ~167 grass_block
setblock ~119 ~126 ~168 grass_block
setblock ~119 ~126 ~169 dirt
setblock ~119 ~126 ~170 dirt
setblock ~119 ~126 ~171 dirt
setblock ~119 ~126 ~172 dirt
setblock ~119 ~126 ~173 grass_block
setblock ~119 ~126 ~174 grass_block
setblock ~119 ~126 ~175 grass_block
setblock ~119 ~126 ~176 grass_block
setblock ~119 ~126 ~177 grass_block
setblock ~119 ~127 ~59 grass_block
setblock ~119 ~127 ~60 dirt
setblock ~119 ~127 ~61 dirt
setblock ~119 ~127 ~62 dirt
setblock ~119 ~127 ~63 dirt
setblock ~119 ~127 ~64 grass_block
setblock ~119 ~127 ~65 grass_block
setblock ~119 ~127 ~66 grass_block
setblock ~119 ~127 ~67 grass_block
setblock ~119 ~127 ~68 grass_block
setblock ~119 ~127 ~69 grass_block
setblock ~119 ~127 ~70 grass_block
setblock ~119 ~127 ~71 grass_block
setblock ~119 ~127 ~72 grass_block
setblock ~119 ~127 ~73 grass_block
setblock ~119 ~127 ~74 grass_block
setblock ~119 ~127 ~75 grass_block
setblock ~119 ~127 ~76 grass_block
setblock ~119 ~127 ~77 grass_block
setblock ~119 ~127 ~78 grass_block
setblock ~119 ~127 ~79 grass_block
setblock ~119 ~127 ~80 grass_block
setblock ~119 ~127 ~81 grass_block
setblock ~119 ~127 ~82 grass_block
setblock ~119 ~127 ~83 grass_block
setblock ~119 ~127 ~84 grass_block
setblock ~119 ~127 ~85 grass_block
setblock ~119 ~127 ~86 grass_block
setblock ~119 ~127 ~87 grass_block
setblock ~119 ~127 ~88 grass_block
setblock ~119 ~127 ~89 grass_block
setblock ~119 ~127 ~90 grass_block
setblock ~119 ~127 ~91 grass_block
setblock ~119 ~127 ~92 grass_block
setblock ~119 ~127 ~95 short_grass
setblock ~119 ~127 ~139 grass_block
setblock ~119 ~127 ~140 grass_block
setblock ~119 ~127 ~141 grass_block
setblock ~119 ~127 ~142 short_grass
setblock ~119 ~127 ~166 fern
setblock ~119 ~127 ~168 short_grass
setblock ~119 ~127 ~169 grass_block
setblock ~119 ~127 ~170 grass_block
setblock ~119 ~127 ~171 grass_block
setblock ~119 ~127 ~172 grass_block
setblock ~119 ~127 ~173 short_grass
setblock ~119 ~127 ~175 short_grass
setblock ~119 ~127 ~176 fern
setblock ~119 ~128 ~59 short_grass
setblock ~119 ~128 ~60 grass_block
setblock ~119 ~128 ~61 grass_block
setblock ~119 ~128 ~62 grass_block
setblock ~119 ~128 ~63 grass_block
setblock ~119 ~128 ~68 short_grass
setblock ~119 ~128 ~69 short_grass
setblock ~119 ~128 ~72 short_grass
setblock ~119 ~128 ~74 short_grass
setblock ~119 ~128 ~78 short_grass
setblock ~119 ~128 ~80 short_grass
setblock ~119 ~128 ~82 short_grass
setblock ~119 ~128 ~139 poppy
setblock ~119 ~128 ~170 short_grass
setblock ~119 ~128 ~172 short_grass
setblock ~119 ~129 ~62 poppy
setblock ~120 ~122 ~0 dirt
setblock ~120 ~122 ~1 dirt
setblock ~120 ~122 ~2 dirt
setblock ~120 ~122 ~3 dirt
setblock ~120 ~122 ~4 dirt
setblock ~120 ~122 ~5 dirt
setblock ~120 ~122 ~6 dirt
setblock ~120 ~122 ~7 dirt
setblock ~120 ~122 ~8 dirt
setblock ~120 ~122 ~9 dirt
setblock ~120 ~122 ~10 dirt
setblock ~120 ~122 ~11 dirt
setblock ~120 ~122 ~12 dirt
setblock ~120 ~122 ~13 dirt
setblock ~120 ~122 ~14 dirt
setblock ~120 ~122 ~15 dirt
setblock ~120 ~122 ~16 dirt
setblock ~120 ~122 ~17 dirt
setblock ~120 ~122 ~18 dirt
setblock ~120 ~122 ~19 dirt
setblock ~120 ~122 ~20 dirt
setblock ~120 ~122 ~21 dirt
setblock ~120 ~122 ~22 dirt
setblock ~120 ~122 ~23 dirt
setblock ~120 ~122 ~24 dirt
setblock ~120 ~122 ~25 dirt
setblock ~120 ~122 ~26 dirt
setblock ~120 ~122 ~27 dirt
setblock ~120 ~122 ~28 dirt
setblock ~120 ~122 ~29 dirt
setblock ~120 ~122 ~30 dirt
setblock ~120 ~122 ~31 dirt
setblock ~120 ~122 ~32 dirt
setblock ~120 ~122 ~33 dirt
setblock ~120 ~122 ~34 dirt
setblock ~120 ~122 ~35 dirt
setblock ~120 ~122 ~36 dirt
setblock ~120 ~122 ~37 dirt
setblock ~120 ~122 ~38 dirt
setblock ~120 ~122 ~39 dirt
setblock ~120 ~122 ~40 dirt
setblock ~120 ~122 ~41 dirt
setblock ~120 ~122 ~42 dirt
setblock ~120 ~122 ~43 dirt
setblock ~120 ~122 ~44 dirt
setblock ~120 ~122 ~45 dirt
setblock ~120 ~122 ~46 dirt
setblock ~120 ~122 ~47 dirt
setblock ~120 ~122 ~48 dirt
setblock ~120 ~122 ~49 dirt
setblock ~120 ~122 ~50 dirt
setblock ~120 ~122 ~51 dirt
setblock ~120 ~122 ~52 dirt
setblock ~120 ~122 ~53 dirt
setblock ~120 ~122 ~54 dirt
setblock ~120 ~122 ~55 dirt
setblock ~120 ~122 ~56 dirt
setblock ~120 ~122 ~57 dirt
setblock ~120 ~122 ~58 dirt
setblock ~120 ~122 ~59 dirt
setblock ~120 ~122 ~60 dirt
setblock ~120 ~122 ~61 dirt
setblock ~120 ~122 ~62 dirt
setblock ~120 ~122 ~63 dirt
setblock ~120 ~122 ~64 dirt
setblock ~120 ~122 ~65 dirt
setblock ~120 ~122 ~66 dirt
setblock ~120 ~122 ~67 dirt
setblock ~120 ~122 ~68 dirt
setblock ~120 ~122 ~69 dirt
setblock ~120 ~122 ~70 dirt
setblock ~120 ~122 ~71 dirt
setblock ~120 ~122 ~72 dirt
setblock ~120 ~122 ~73 dirt
setblock ~120 ~122 ~74 dirt
setblock ~120 ~122 ~75 dirt
setblock ~120 ~122 ~76 dirt
setblock ~120 ~122 ~77 dirt
setblock ~120 ~122 ~78 dirt
setblock ~120 ~122 ~79 dirt
setblock ~120 ~122 ~80 dirt
setblock ~120 ~122 ~81 dirt
setblock ~120 ~122 ~82 dirt
setblock ~120 ~122 ~83 dirt
setblock ~120 ~122 ~84 dirt
setblock ~120 ~122 ~85 dirt
setblock ~120 ~122 ~86 dirt
setblock ~120 ~122 ~87 dirt
setblock ~120 ~122 ~88 dirt
setblock ~120 ~122 ~89 dirt
setblock ~120 ~122 ~90 dirt
setblock ~120 ~122 ~91 dirt
setblock ~120 ~122 ~92 dirt
setblock ~120 ~122 ~93 dirt
setblock ~120 ~122 ~94 dirt
setblock ~120 ~122 ~95 dirt
setblock ~120 ~122 ~96 dirt
setblock ~120 ~122 ~97 dirt
setblock ~120 ~122 ~98 dirt
setblock ~120 ~122 ~99 dirt
setblock ~120 ~122 ~100 dirt
setblock ~120 ~122 ~101 dirt
setblock ~120 ~122 ~102 dirt
setblock ~120 ~122 ~103 dirt
setblock ~120 ~122 ~104 dirt
setblock ~120 ~122 ~105 dirt
setblock ~120 ~122 ~106 dirt
setblock ~120 ~122 ~107 dirt
setblock ~120 ~122 ~108 dirt
setblock ~120 ~122 ~109 dirt
setblock ~120 ~122 ~110 dirt
setblock ~120 ~122 ~111 dirt
setblock ~120 ~122 ~112 dirt
setblock ~120 ~122 ~113 dirt
setblock ~120 ~122 ~114 dirt
setblock ~120 ~122 ~115 dirt
setblock ~120 ~122 ~116 dirt
setblock ~120 ~122 ~117 dirt
setblock ~120 ~122 ~118 dirt
setblock ~120 ~122 ~119 dirt
setblock ~120 ~122 ~120 dirt
setblock ~120 ~122 ~121 dirt
setblock ~120 ~122 ~122 dirt
setblock ~120 ~122 ~123 dirt
setblock ~120 ~122 ~124 dirt
setblock ~120 ~122 ~125 dirt
setblock ~120 ~122 ~126 dirt
setblock ~120 ~122 ~127 dirt
setblock ~120 ~122 ~128 dirt
setblock ~120 ~122 ~129 dirt
setblock ~120 ~122 ~130 dirt
setblock ~120 ~122 ~131 dirt
setblock ~120 ~122 ~132 dirt
setblock ~120 ~122 ~133 dirt
setblock ~120 ~122 ~134 dirt
setblock ~120 ~122 ~135 dirt
setblock ~120 ~122 ~136 dirt
setblock ~120 ~122 ~137 dirt
setblock ~120 ~122 ~138 dirt
setblock ~120 ~122 ~139 dirt
setblock ~120 ~122 ~140 dirt
setblock ~120 ~122 ~141 dirt
setblock ~120 ~122 ~142 dirt
setblock ~120 ~122 ~143 dirt
setblock ~120 ~122 ~144 dirt
setblock ~120 ~122 ~145 dirt
setblock ~120 ~122 ~146 dirt
setblock ~120 ~122 ~147 dirt
setblock ~120 ~122 ~148 dirt
setblock ~120 ~122 ~149 dirt
setblock ~120 ~122 ~150 dirt
setblock ~120 ~122 ~151 dirt
setblock ~120 ~122 ~152 dirt
setblock ~120 ~122 ~153 dirt
setblock ~120 ~122 ~154 dirt
setblock ~120 ~122 ~155 dirt
setblock ~120 ~122 ~156 dirt
setblock ~120 ~122 ~157 dirt
setblock ~120 ~122 ~158 dirt
setblock ~120 ~122 ~159 dirt
setblock ~120 ~122 ~160 dirt
setblock ~120 ~122 ~161 dirt
setblock ~120 ~122 ~162 dirt
setblock ~120 ~122 ~163 dirt
setblock ~120 ~122 ~164 dirt
setblock ~120 ~122 ~165 dirt
setblock ~120 ~122 ~166 dirt
setblock ~120 ~122 ~167 dirt
setblock ~120 ~122 ~168 dirt
setblock ~120 ~122 ~169 dirt
setblock ~120 ~122 ~170 dirt
setblock ~120 ~122 ~171 dirt
setblock ~120 ~122 ~172 dirt
setblock ~120 ~122 ~173 dirt
setblock ~120 ~122 ~174 dirt
setblock ~120 ~122 ~175 dirt
setblock ~120 ~122 ~176 dirt
setblock ~120 ~122 ~177 dirt
setblock ~120 ~122 ~178 dirt
setblock ~120 ~122 ~179 dirt
setblock ~120 ~122 ~180 dirt
setblock ~120 ~122 ~181 dirt
setblock ~120 ~122 ~182 dirt
setblock ~120 ~122 ~183 dirt
setblock ~120 ~122 ~184 dirt
setblock ~120 ~122 ~185 dirt
setblock ~120 ~122 ~186 dirt
setblock ~120 ~122 ~187 dirt
setblock ~120 ~122 ~188 dirt
setblock ~120 ~122 ~189 dirt
setblock ~120 ~122 ~190 dirt
setblock ~120 ~122 ~191 dirt
setblock ~120 ~122 ~192 dirt
setblock ~120 ~122 ~193 dirt
setblock ~120 ~122 ~194 dirt
setblock ~120 ~122 ~195 dirt
setblock ~120 ~122 ~196 dirt
setblock ~120 ~122 ~197 dirt
setblock ~120 ~122 ~198 grass_block
