setblock ~150 ~123 ~183 dirt
setblock ~150 ~123 ~184 dirt
setblock ~150 ~123 ~185 dirt
setblock ~150 ~123 ~186 dirt
setblock ~150 ~123 ~187 dirt
setblock ~150 ~123 ~188 dirt
setblock ~150 ~123 ~189 dirt
setblock ~150 ~123 ~190 dirt
setblock ~150 ~123 ~191 dirt
setblock ~150 ~123 ~192 dirt
setblock ~150 ~123 ~193 dirt
setblock ~150 ~123 ~194 dirt
setblock ~150 ~123 ~195 dirt
setblock ~150 ~123 ~196 dirt
setblock ~150 ~123 ~197 dirt
setblock ~150 ~123 ~198 dirt
setblock ~150 ~123 ~199 grass_block
setblock ~150 ~124 ~3 short_grass
setblock ~150 ~124 ~4 fern
setblock ~150 ~124 ~6 short_grass
setblock ~150 ~124 ~8 short_grass
setblock ~150 ~124 ~11 poppy
setblock ~150 ~124 ~13 short_grass
setblock ~150 ~124 ~15 short_grass
setblock ~150 ~124 ~32 grass_block
setblock ~150 ~124 ~33 grass_block
setblock ~150 ~124 ~34 grass_block
setblock ~150 ~124 ~35 grass_block
setblock ~150 ~124 ~36 grass_block
setblock ~150 ~124 ~37 grass_block
setblock ~150 ~124 ~38 dirt
setblock ~150 ~124 ~39 dirt
setblock ~150 ~124 ~40 dirt
setblock ~150 ~124 ~41 dirt
setblock ~150 ~124 ~42 dirt
setblock ~150 ~124 ~43 dirt
setblock ~150 ~124 ~44 dirt
setblock ~150 ~124 ~45 dirt
setblock ~150 ~124 ~46 dirt
setblock ~150 ~124 ~47 dirt
setblock ~150 ~124 ~48 dirt
setblock ~150 ~124 ~49 dirt
setblock ~150 ~124 ~50 dirt
setblock ~150 ~124 ~51 dirt
setblock ~150 ~124 ~52 dirt
setblock ~150 ~124 ~53 dirt
setblock ~150 ~124 ~54 dirt
setblock ~150 ~124 ~55 dirt
setblock ~150 ~124 ~56 dirt
setblock ~150 ~124 ~57 dirt
setblock ~150 ~124 ~58 dirt
setblock ~150 ~124 ~59 dirt
setblock ~150 ~124 ~60 dirt
setblock ~150 ~124 ~61 grass_block
setblock ~150 ~124 ~62 grass_block
setblock ~150 ~124 ~63 grass_block
setblock ~150 ~124 ~64 grass_block
setblock ~150 ~124 ~65 grass_block
setblock ~150 ~124 ~66 grass_block
setblock ~150 ~124 ~69 fern
setblock ~150 ~124 ~71 short_grass
setblock ~150 ~124 ~72 grass_block
setblock ~150 ~124 ~73 grass_block
setblock ~150 ~124 ~74 grass_block
setblock ~150 ~124 ~75 dirt
setblock ~150 ~124 ~76 dirt
setblock ~150 ~124 ~77 dirt
setblock ~150 ~124 ~78 dirt
setblock ~150 ~124 ~79 dirt
setblock ~150 ~124 ~80 dirt
setblock ~150 ~124 ~81 dirt
setblock ~150 ~124 ~82 dirt
setblock ~150 ~124 ~83 dirt
setblock ~150 ~124 ~84 dirt
setblock ~150 ~124 ~85 dirt
setblock ~150 ~124 ~86 grass_block
setblock ~150 ~124 ~87 grass_block
setblock ~150 ~124 ~88 grass_block
setblock ~150 ~124 ~90 short_grass
setblock ~150 ~124 ~92 grass_block
setblock ~150 ~124 ~93 grass_block
setblock ~150 ~124 ~94 dirt
setblock ~150 ~124 ~95 dirt
setblock ~150 ~124 ~96 dirt
setblock ~150 ~124 ~97 dirt
setblock ~150 ~124 ~98 dirt
setblock ~150 ~124 ~99 dirt
setblock ~150 ~124 ~100 dirt
setblock ~150 ~124 ~101 dirt
setblock ~150 ~124 ~102 dirt
setblock ~150 ~124 ~103 dirt
setblock ~150 ~124 ~104 dirt
setblock ~150 ~124 ~105 dirt
setblock ~150 ~124 ~106 dirt
setblock ~150 ~124 ~107 dirt
setblock ~150 ~124 ~108 grass_block
setblock ~150 ~124 ~110 short_grass
setblock ~150 ~124 ~112 short_grass
setblock ~150 ~124 ~115 fern
setblock ~150 ~124 ~118 short_grass
setblock ~150 ~124 ~123 poppy
setblock ~150 ~124 ~126 grass_block
setblock ~150 ~124 ~127 grass_block
setblock ~150 ~124 ~128 dirt
setblock ~150 ~124 ~129 dirt
setblock ~150 ~124 ~130 dirt
setblock ~150 ~124 ~131 dirt
setblock ~150 ~124 ~132 dirt
setblock ~150 ~124 ~133 grass_block
setblock ~150 ~124 ~134 short_grass
setblock ~150 ~124 ~142 poppy
setblock ~150 ~124 ~144 grass_block
setblock ~150 ~124 ~145 grass_block
setblock ~150 ~124 ~146 dirt
setblock ~150 ~124 ~147 dirt
setblock ~150 ~124 ~148 dirt
setblock ~150 ~124 ~149 dirt
setblock ~150 ~124 ~150 dirt
setblock ~150 ~124 ~151 dirt
setblock ~150 ~124 ~152 dirt
setblock ~150 ~124 ~153 dirt
setblock ~150 ~124 ~154 dirt
setblock ~150 ~124 ~155 dirt
setblock ~150 ~124 ~156 dirt
setblock ~150 ~124 ~157 dirt
setblock ~150 ~124 ~158 grass_block
setblock ~150 ~124 ~159 grass_block
setblock ~150 ~124 ~160 grass_block
setblock ~150 ~124 ~161 grass_block
setblock ~150 ~124 ~162 grass_block
setblock ~150 ~124 ~167 fern
setblock ~150 ~124 ~175 grass_block
setblock ~150 ~124 ~176 grass_block
setblock ~150 ~124 ~177 dirt
setblock ~150 ~124 ~178 dirt
setblock ~150 ~124 ~179 dirt
setblock ~150 ~124 ~180 dirt
setblock ~150 ~124 ~181 dirt
setblock ~150 ~124 ~182 dirt
setblock ~150 ~124 ~183 dirt
setblock ~150 ~124 ~184 dirt
setblock ~150 ~124 ~185 dirt
setblock ~150 ~124 ~186 dirt
setblock ~150 ~124 ~187 dirt
setblock ~150 ~124 ~188 dirt
setblock ~150 ~124 ~189 dirt
setblock ~150 ~124 ~190 grass_block
setblock ~150 ~124 ~191 grass_block
setblock ~150 ~124 ~192 grass_block
setblock ~150 ~124 ~193 grass_block
setblock ~150 ~124 ~194 grass_block
setblock ~150 ~124 ~195 grass_block
setblock ~150 ~124 ~196 grass_block
setblock ~150 ~124 ~197 grass_block
setblock ~150 ~124 ~198 grass_block
setblock ~150 ~125 ~32 short_grass
setblock ~150 ~125 ~38 grass_block
setblock ~150 ~125 ~39 grass_block
setblock ~150 ~125 ~40 grass_block
setblock ~150 ~125 ~41 grass_block
setblock ~150 ~125 ~42 dirt
setblock ~150 ~125 ~43 dirt
setblock ~150 ~125 ~44 dirt
setblock ~150 ~125 ~45 dirt
setblock ~150 ~125 ~46 dirt
setblock ~150 ~125 ~47 dirt
setblock ~150 ~125 ~48 dirt
setblock ~150 ~125 ~49 dirt
setblock ~150 ~125 ~50 dirt
setblock ~150 ~125 ~51 dirt
setblock ~150 ~125 ~52 dirt
setblock ~150 ~125 ~53 dirt
setblock ~150 ~125 ~54 dirt
setblock ~150 ~125 ~55 dirt
setblock ~150 ~125 ~56 dirt
setblock ~150 ~125 ~57 dirt
setblock ~150 ~125 ~58 grass_block
setblock ~150 ~125 ~59 grass_block
setblock ~150 ~125 ~60 grass_block
setblock ~150 ~125 ~61 short_grass
setblock ~150 ~125 ~62 short_grass
setblock ~150 ~125 ~64 short_grass
setblock ~150 ~125 ~73 short_grass
setblock ~150 ~125 ~74 fern
setblock ~150 ~125 ~75 grass_block
setblock ~150 ~125 ~76 dirt
setblock ~150 ~125 ~77 dirt
setblock ~150 ~125 ~78 dirt
setblock ~150 ~125 ~79 dirt
setblock ~150 ~125 ~80 dirt
setblock ~150 ~125 ~81 dirt
setblock ~150 ~125 ~82 dirt
setblock ~150 ~125 ~83 dirt
setblock ~150 ~125 ~84 grass_block
setblock ~150 ~125 ~85 grass_block
setblock ~150 ~125 ~92 short_grass
setblock ~150 ~125 ~94 grass_block
setblock ~150 ~125 ~95 dirt
setblock ~150 ~125 ~96 dirt
setblock ~150 ~125 ~97 dirt
setblock ~150 ~125 ~98 dirt
setblock ~150 ~125 ~99 dirt
setblock ~150 ~125 ~100 dirt
setblock ~150 ~125 ~101 dirt
setblock ~150 ~125 ~102 dirt
setblock ~150 ~125 ~103 dirt
setblock ~150 ~125 ~104 dirt
setblock ~150 ~125 ~105 dirt
setblock ~150 ~125 ~106 grass_block
setblock ~150 ~125 ~107 grass_block
setblock ~150 ~125 ~108 poppy
setblock ~150 ~125 ~126 fern
setblock ~150 ~125 ~128 grass_block
setblock ~150 ~125 ~129 dirt
setblock ~150 ~125 ~130 dirt
setblock ~150 ~125 ~131 dirt
setblock ~150 ~125 ~132 grass_block
setblock ~150 ~125 ~133 short_grass
setblock ~150 ~125 ~146 grass_block
setblock ~150 ~125 ~147 grass_block
setblock ~150 ~125 ~148 dirt
setblock ~150 ~125 ~149 dirt
setblock ~150 ~125 ~150 dirt
setblock ~150 ~125 ~151 dirt
setblock ~150 ~125 ~152 dirt
setblock ~150 ~125 ~153 dirt
setblock ~150 ~125 ~154 grass_block
setblock ~150 ~125 ~155 grass_block
setblock ~150 ~125 ~156 grass_block
setblock ~150 ~125 ~157 grass_block
setblock ~150 ~125 ~158 short_grass
setblock ~150 ~125 ~175 short_grass
setblock ~150 ~125 ~177 grass_block
setblock ~150 ~125 ~178 grass_block
setblock ~150 ~125 ~179 dirt
setblock ~150 ~125 ~180 dirt
setblock ~150 ~125 ~181 dirt
setblock ~150 ~125 ~182 dirt
setblock ~150 ~125 ~183 dirt
setblock ~150 ~125 ~184 grass_block
setblock ~150 ~125 ~185 grass_block
setblock ~150 ~125 ~186 grass_block
setblock ~150 ~125 ~187 grass_block
setblock ~150 ~125 ~188 grass_block
setblock ~150 ~125 ~189 grass_block
setblock ~150 ~125 ~193 fern
setblock ~150 ~125 ~196 short_grass
setblock ~150 ~125 ~197 short_grass
setblock ~150 ~126 ~42 grass_block
setblock ~150 ~126 ~43 grass_block
setblock ~150 ~126 ~44 grass_block
setblock ~150 ~126 ~45 dirt
setblock ~150 ~126 ~46 dirt
setblock ~150 ~126 ~47 dirt
setblock ~150 ~126 ~48 dirt
setblock ~150 ~126 ~49 dirt
setblock ~150 ~126 ~50 dirt
setblock ~150 ~126 ~51 dirt
setblock ~150 ~126 ~52 dirt
setblock ~150 ~126 ~53 dirt
setblock ~150 ~126 ~54 dirt
setblock ~150 ~126 ~55 grass_block
setblock ~150 ~126 ~56 grass_block
setblock ~150 ~126 ~57 grass_block
setblock ~150 ~126 ~76 grass_block
setblock ~150 ~126 ~77 grass_block
setblock ~150 ~126 ~78 dirt
setblock ~150 ~126 ~79 dirt
setblock ~150 ~126 ~80 dirt
setblock ~150 ~126 ~81 dirt
setblock ~150 ~126 ~82 dirt
setblock ~150 ~126 ~83 grass_block
setblock ~150 ~126 ~94 short_grass
setblock ~150 ~126 ~95 grass_block
setblock ~150 ~126 ~96 grass_block
setblock ~150 ~126 ~97 dirt
setblock ~150 ~126 ~98 dirt
setblock ~150 ~126 ~99 dirt
setblock ~150 ~126 ~100 dirt
setblock ~150 ~126 ~101 dirt
setblock ~150 ~126 ~102 dirt
setblock ~150 ~126 ~103 dirt
setblock ~150 ~126 ~104 dirt
setblock ~150 ~126 ~105 grass_block
setblock ~150 ~126 ~129 dirt
setblock ~150 ~126 ~130 dirt
setblock ~150 ~126 ~131 grass_block
setblock ~150 ~126 ~148 grass_block
setblock ~150 ~126 ~149 grass_block
setblock ~150 ~126 ~150 grass_block
setblock ~150 ~126 ~151 grass_block
setblock ~150 ~126 ~152 grass_block
setblock ~150 ~126 ~153 grass_block
setblock ~150 ~126 ~179 grass_block
setblock ~150 ~126 ~180 grass_block
setblock ~150 ~126 ~181 grass_block
setblock ~150 ~126 ~182 grass_block
setblock ~150 ~126 ~183 grass_block
setblock ~150 ~126 ~189 short_grass
setblock ~150 ~127 ~42 short_grass
setblock ~150 ~127 ~45 grass_block
setblock ~150 ~127 ~46 grass_block
setblock ~150 ~127 ~47 dirt
setblock ~150 ~127 ~48 dirt
setblock ~150 ~127 ~49 dirt
setblock ~150 ~127 ~50 dirt
setblock ~150 ~127 ~51 dirt
setblock ~150 ~127 ~52 dirt
setblock ~150 ~127 ~53 grass_block
setblock ~150 ~127 ~54 grass_block
setblock ~150 ~127 ~56 short_grass
setblock ~150 ~127 ~57 short_grass
setblock ~150 ~127 ~76 short_grass
setblock ~150 ~127 ~78 grass_block
setblock ~150 ~127 ~79 grass_block
setblock ~150 ~127 ~80 dirt
setblock ~150 ~127 ~81 grass_block
setblock ~150 ~127 ~82 grass_block
setblock ~150 ~127 ~83 short_grass
setblock ~150 ~127 ~96 short_grass
setblock ~150 ~127 ~97 grass_block
setblock ~150 ~127 ~98 dirt
setblock ~150 ~127 ~99 dirt
setblock ~150 ~127 ~100 dirt
setblock ~150 ~127 ~101 dirt
setblock ~150 ~127 ~102 dirt
setblock ~150 ~127 ~103 dirt
setblock ~150 ~127 ~104 grass_block
setblock ~150 ~127 ~105 short_grass
setblock ~150 ~127 ~129 grass_block
setblock ~150 ~127 ~130 dirt
setblock ~150 ~127 ~149 poppy
setblock ~150 ~127 ~180 poppy
setblock ~150 ~127 ~181 short_grass
setblock ~150 ~128 ~47 grass_block
setblock ~150 ~128 ~48 grass_block
setblock ~150 ~128 ~49 dirt
setblock ~150 ~128 ~50 dirt
setblock ~150 ~128 ~51 dirt
setblock ~150 ~128 ~52 grass_block
setblock ~150 ~128 ~79 short_grass
setblock ~150 ~128 ~80 grass_block
setblock ~150 ~128 ~98 grass_block
setblock ~150 ~128 ~99 dirt
setblock ~150 ~128 ~100 dirt
setblock ~150 ~128 ~101 dirt
setblock ~150 ~128 ~102 dirt
setblock ~150 ~128 ~103 grass_block
setblock ~150 ~128 ~104 short_grass
setblock ~150 ~128 ~130 dirt
setblock ~150 ~129 ~49 grass_block
setblock ~150 ~129 ~50 grass_block
setblock ~150 ~129 ~51 grass_block
setblock ~150 ~129 ~80 poppy
setblock ~150 ~129 ~99 grass_block
setblock ~150 ~129 ~100 dirt
setblock ~150 ~129 ~101 grass_block
setblock ~150 ~129 ~102 grass_block
setblock ~150 ~129 ~103 short_grass
setblock ~150 ~129 ~130 grass_block
setblock ~150 ~130 ~49 short_grass
setblock ~150 ~130 ~50 short_grass
setblock ~150 ~130 ~99 fern
setblock ~150 ~130 ~100 grass_block
setblock ~150 ~131 ~100 poppy
setblock ~151 ~122 ~0 dirt
setblock ~151 ~122 ~1 dirt
setblock ~151 ~122 ~2 dirt
setblock ~151 ~122 ~3 dirt
setblock ~151 ~122 ~4 dirt
setblock ~151 ~122 ~5 dirt
setblock ~151 ~122 ~6 dirt
setblock ~151 ~122 ~7 dirt
setblock ~151 ~122 ~8 dirt
setblock ~151 ~122 ~9 dirt
setblock ~151 ~122 ~10 dirt
setblock ~151 ~122 ~11 dirt
setblock ~151 ~122 ~12 dirt
setblock ~151 ~122 ~13 dirt
setblock ~151 ~122 ~14 dirt
setblock ~151 ~122 ~15 dirt
setblock ~151 ~122 ~16 dirt
setblock ~151 ~122 ~17 dirt
setblock ~151 ~122 ~18 dirt
setblock ~151 ~122 ~19 dirt
setblock ~151 ~122 ~20 dirt
setblock ~151 ~122 ~21 dirt
setblock ~151 ~122 ~22 dirt
setblock ~151 ~122 ~23 dirt
setblock ~151 ~122 ~24 dirt
setblock ~151 ~122 ~25 dirt
setblock ~151 ~122 ~26 dirt
setblock ~151 ~122 ~27 dirt
setblock ~151 ~122 ~28 dirt
setblock ~151 ~122 ~29 dirt
setblock ~151 ~122 ~30 dirt
setblock ~151 ~122 ~31 dirt
setblock ~151 ~122 ~32 dirt
setblock ~151 ~122 ~33 dirt
setblock ~151 ~122 ~34 dirt
setblock ~151 ~122 ~35 dirt
setblock ~151 ~122 ~36 dirt
setblock ~151 ~122 ~37 dirt
setblock ~151 ~122 ~38 dirt
setblock ~151 ~122 ~39 dirt
setblock ~151 ~122 ~40 dirt
setblock ~151 ~122 ~41 dirt
setblock ~151 ~122 ~42 dirt
setblock ~151 ~122 ~43 dirt
setblock ~151 ~122 ~44 dirt
setblock ~151 ~122 ~45 dirt
setblock ~151 ~122 ~46 dirt
setblock ~151 ~122 ~47 dirt
setblock ~151 ~122 ~48 dirt
setblock ~151 ~122 ~49 dirt
setblock ~151 ~122 ~50 dirt
setblock ~151 ~122 ~51 dirt
setblock ~151 ~122 ~52 dirt
setblock ~151 ~122 ~53 dirt
setblock ~151 ~122 ~54 dirt
setblock ~151 ~122 ~55 dirt
setblock ~151 ~122 ~56 dirt
setblock ~151 ~122 ~57 dirt
setblock ~151 ~122 ~58 dirt
setblock ~151 ~122 ~59 dirt
setblock ~151 ~122 ~60 dirt
setblock ~151 ~122 ~61 dirt
setblock ~151 ~122 ~62 dirt
setblock ~151 ~122 ~63 dirt
setblock ~151 ~122 ~64 dirt
setblock ~151 ~122 ~65 dirt
setblock ~151 ~122 ~66 dirt
setblock ~151 ~122 ~67 dirt
setblock ~151 ~122 ~68 dirt
setblock ~151 ~122 ~69 dirt
setblock ~151 ~122 ~70 dirt
setblock ~151 ~122 ~71 dirt
setblock ~151 ~122 ~72 dirt
setblock ~151 ~122 ~73 dirt
setblock ~151 ~122 ~74 dirt
setblock ~151 ~122 ~75 dirt
setblock ~151 ~122 ~76 dirt
setblock ~151 ~122 ~77 dirt
setblock ~151 ~122 ~78 dirt
setblock ~151 ~122 ~79 dirt
setblock ~151 ~122 ~80 dirt
setblock ~151 ~122 ~81 dirt
setblock ~151 ~122 ~82 dirt
setblock ~151 ~122 ~83 dirt
setblock ~151 ~122 ~84 dirt
setblock ~151 ~122 ~85 dirt
setblock ~151 ~122 ~86 dirt
setblock ~151 ~122 ~87 dirt
setblock ~151 ~122 ~88 dirt
setblock ~151 ~122 ~89 dirt
setblock ~151 ~122 ~90 dirt
setblock ~151 ~122 ~91 dirt
setblock ~151 ~122 ~92 dirt
setblock ~151 ~122 ~93 dirt
setblock ~151 ~122 ~94 dirt
setblock ~151 ~122 ~95 dirt
setblock ~151 ~122 ~96 dirt
setblock ~151 ~122 ~97 dirt
setblock ~151 ~122 ~98 dirt
setblock ~151 ~122 ~99 dirt
setblock ~151 ~122 ~100 dirt
setblock ~151 ~122 ~101 dirt
setblock ~151 ~122 ~102 dirt
setblock ~151 ~122 ~103 dirt
setblock ~151 ~122 ~104 dirt
setblock ~151 ~122 ~105 dirt
setblock ~151 ~122 ~106 dirt
setblock ~151 ~122 ~107 dirt
setblock ~151 ~122 ~108 dirt
setblock ~151 ~122 ~109 dirt
setblock ~151 ~122 ~110 dirt
setblock ~151 ~122 ~111 dirt
setblock ~151 ~122 ~112 dirt
setblock ~151 ~122 ~113 dirt
setblock ~151 ~122 ~114 dirt
setblock ~151 ~122 ~115 dirt
setblock ~151 ~122 ~116 dirt
setblock ~151 ~122 ~117 dirt
setblock ~151 ~122 ~118 dirt
setblock ~151 ~122 ~119 dirt
setblock ~151 ~122 ~120 dirt
setblock ~151 ~122 ~121 dirt
setblock ~151 ~122 ~122 dirt
setblock ~151 ~122 ~123 dirt
setblock ~151 ~122 ~124 dirt
setblock ~151 ~122 ~125 dirt
setblock ~151 ~122 ~126 dirt
setblock ~151 ~122 ~127 dirt
setblock ~151 ~122 ~128 dirt
setblock ~151 ~122 ~129 dirt
setblock ~151 ~122 ~130 dirt
setblock ~151 ~122 ~131 dirt
setblock ~151 ~122 ~132 dirt
setblock ~151 ~122 ~133 dirt
setblock ~151 ~122 ~134 dirt
setblock ~151 ~122 ~135 dirt
setblock ~151 ~122 ~136 dirt
setblock ~151 ~122 ~137 grass_block
setblock ~151 ~122 ~138 grass_block
setblock ~151 ~122 ~139 grass_block
setblock ~151 ~122 ~140 grass_block
setblock ~151 ~122 ~141 grass_block
setblock ~151 ~122 ~142 dirt
setblock ~151 ~122 ~143 dirt
setblock ~151 ~122 ~144 dirt
setblock ~151 ~122 ~145 dirt
setblock ~151 ~122 ~146 dirt
setblock ~151 ~122 ~147 dirt
setblock ~151 ~122 ~148 dirt
setblock ~151 ~122 ~149 dirt
setblock ~151 ~122 ~150 dirt
setblock ~151 ~122 ~151 dirt
setblock ~151 ~122 ~152 dirt
setblock ~151 ~122 ~153 dirt
setblock ~151 ~122 ~154 dirt
setblock ~151 ~122 ~155 dirt
setblock ~151 ~122 ~156 dirt
setblock ~151 ~122 ~157 dirt
setblock ~151 ~122 ~158 dirt
setblock ~151 ~122 ~159 dirt
setblock ~151 ~122 ~160 dirt
setblock ~151 ~122 ~161 dirt
setblock ~151 ~122 ~162 dirt
setblock ~151 ~122 ~163 dirt
setblock ~151 ~122 ~164 dirt
setblock ~151 ~122 ~165 dirt
setblock ~151 ~122 ~166 dirt
setblock ~151 ~122 ~167 dirt
setblock ~151 ~122 ~168 dirt
setblock ~151 ~122 ~169 grass_block
setblock ~151 ~122 ~170 grass_block
setblock ~151 ~122 ~171 grass_block
setblock ~151 ~122 ~172 dirt
setblock ~151 ~122 ~173 dirt
setblock ~151 ~122 ~174 dirt
setblock ~151 ~122 ~175 dirt
setblock ~151 ~122 ~176 dirt
setblock ~151 ~122 ~177 dirt
setblock ~151 ~122 ~178 dirt
setblock ~151 ~122 ~179 dirt
setblock ~151 ~122 ~180 dirt
setblock ~151 ~122 ~181 dirt
setblock ~151 ~122 ~182 dirt
setblock ~151 ~122 ~183 dirt
setblock ~151 ~122 ~184 dirt
setblock ~151 ~122 ~185 dirt
setblock ~151 ~122 ~186 dirt
setblock ~151 ~122 ~187 dirt
setblock ~151 ~122 ~188 dirt
setblock ~151 ~122 ~189 dirt
setblock ~151 ~122 ~190 dirt
setblock ~151 ~122 ~191 dirt
setblock ~151 ~122 ~192 dirt
setblock ~151 ~122 ~193 dirt
setblock ~151 ~122 ~194 dirt
setblock ~151 ~122 ~195 dirt
setblock ~151 ~122 ~196 dirt
setblock ~151 ~122 ~197 dirt
setblock ~151 ~122 ~198 dirt
setblock ~151 ~122 ~199 dirt
setblock ~151 ~123 ~0 grass_block
setblock ~151 ~123 ~1 grass_block
setblock ~151 ~123 ~2 grass_block
setblock ~151 ~123 ~3 grass_block
setblock ~151 ~123 ~4 grass_block
setblock ~151 ~123 ~5 grass_block
setblock ~151 ~123 ~6 grass_block
setblock ~151 ~123 ~7 grass_block
setblock ~151 ~123 ~8 grass_block
setblock ~151 ~123 ~9 grass_block
setblock ~151 ~123 ~10 grass_block
setblock ~151 ~123 ~11 grass_block
setblock ~151 ~123 ~12 grass_block
setblock ~151 ~123 ~13 grass_block
setblock ~151 ~123 ~14 grass_block
setblock ~151 ~123 ~15 grass_block
setblock ~151 ~123 ~16 grass_block
setblock ~151 ~123 ~17 grass_block
setblock ~151 ~123 ~18 grass_block
setblock ~151 ~123 ~19 grass_block
setblock ~151 ~123 ~20 grass_block
setblock ~151 ~123 ~21 grass_block
setblock ~151 ~123 ~22 grass_block
setblock ~151 ~123 ~23 grass_block
setblock ~151 ~123 ~24 grass_block
setblock ~151 ~123 ~25 grass_block
setblock ~151 ~123 ~26 grass_block
setblock ~151 ~123 ~27 grass_block
setblock ~151 ~123 ~28 grass_block
setblock ~151 ~123 ~29 grass_block
setblock ~151 ~123 ~30 grass_block
setblock ~151 ~123 ~31 grass_block
setblock ~151 ~123 ~32 dirt
setblock ~151 ~123 ~33 dirt
setblock ~151 ~123 ~34 dirt
setblock ~151 ~123 ~35 dirt
setblock ~151 ~123 ~36 dirt
setblock ~151 ~123 ~37 dirt
setblock ~151 ~123 ~38 dirt
setblock ~151 ~123 ~39 dirt
setblock ~151 ~123 ~40 dirt
setblock ~151 ~123 ~41 dirt
setblock ~151 ~123 ~42 dirt
setblock ~151 ~123 ~43 dirt
setblock ~151 ~123 ~44 dirt
setblock ~151 ~123 ~45 dirt
setblock ~151 ~123 ~46 dirt
setblock ~151 ~123 ~47 dirt
setblock ~151 ~123 ~48 dirt
setblock ~151 ~123 ~49 dirt
setblock ~151 ~123 ~50 dirt
setblock ~151 ~123 ~51 dirt
setblock ~151 ~123 ~52 dirt
setblock ~151 ~123 ~53 dirt
setblock ~151 ~123 ~54 dirt
setblock ~151 ~123 ~55 dirt
setblock ~151 ~123 ~56 dirt
setblock ~151 ~123 ~57 dirt
setblock ~151 ~123 ~58 dirt
setblock ~151 ~123 ~59 dirt
setblock ~151 ~123 ~60 dirt
setblock ~151 ~123 ~61 dirt
setblock ~151 ~123 ~62 dirt
setblock ~151 ~123 ~63 dirt
setblock ~151 ~123 ~64 dirt
setblock ~151 ~123 ~65 dirt
setblock ~151 ~123 ~66 dirt
setblock ~151 ~123 ~67 dirt
setblock ~151 ~123 ~68 grass_block
setblock ~151 ~123 ~69 grass_block
setblock ~151 ~123 ~70 grass_block
setblock ~151 ~123 ~71 grass_block
setblock ~151 ~123 ~72 dirt
setblock ~151 ~123 ~73 dirt
setblock ~151 ~123 ~74 dirt
setblock ~151 ~123 ~75 dirt
setblock ~151 ~123 ~76 dirt
setblock ~151 ~123 ~77 dirt
setblock ~151 ~123 ~78 dirt
setblock ~151 ~123 ~79 dirt
setblock ~151 ~123 ~80 dirt
setblock ~151 ~123 ~81 dirt
setblock ~151 ~123 ~82 dirt
setblock ~151 ~123 ~83 dirt
setblock ~151 ~123 ~84 dirt
setblock ~151 ~123 ~85 dirt
setblock ~151 ~123 ~86 dirt
setblock ~151 ~123 ~87 dirt
setblock ~151 ~123 ~88 dirt
setblock ~151 ~123 ~89 dirt
setblock ~151 ~123 ~90 grass_block
setblock ~151 ~123 ~91 dirt
setblock ~151 ~123 ~92 dirt
setblock ~151 ~123 ~93 dirt
setblock ~151 ~123 ~94 dirt
setblock ~151 ~123 ~95 dirt
setblock ~151 ~123 ~96 dirt
setblock ~151 ~123 ~97 dirt
setblock ~151 ~123 ~98 dirt
setblock ~151 ~123 ~99 dirt
setblock ~151 ~123 ~100 dirt
setblock ~151 ~123 ~101 dirt
setblock ~151 ~123 ~102 dirt
setblock ~151 ~123 ~103 dirt
setblock ~151 ~123 ~104 dirt
setblock ~151 ~123 ~105 dirt
setblock ~151 ~123 ~106 dirt
setblock ~151 ~123 ~107 dirt
setblock ~151 ~123 ~108 dirt
setblock ~151 ~123 ~109 grass_block
setblock ~151 ~123 ~110 grass_block
setblock ~151 ~123 ~111 grass_block
setblock ~151 ~123 ~112 grass_block
setblock ~151 ~123 ~113 grass_block
setblock ~151 ~123 ~114 grass_block
setblock ~151 ~123 ~115 grass_block
setblock ~151 ~123 ~116 grass_block
setblock ~151 ~123 ~117 grass_block
setblock ~151 ~123 ~118 grass_block
setblock ~151 ~123 ~119 grass_block
setblock ~151 ~123 ~120 grass_block
setblock ~151 ~123 ~121 grass_block
setblock ~151 ~123 ~122 grass_block
setblock ~151 ~123 ~123 grass_block
setblock ~151 ~123 ~124 grass_block
setblock ~151 ~123 ~125 grass_block
setblock ~151 ~123 ~126 dirt
setblock ~151 ~123 ~127 dirt
setblock ~151 ~123 ~128 dirt
setblock ~151 ~123 ~129 dirt
setblock ~151 ~123 ~130 dirt
setblock ~151 ~123 ~131 dirt
setblock ~151 ~123 ~132 dirt
setblock ~151 ~123 ~133 dirt
setblock ~151 ~123 ~134 grass_block
setblock ~151 ~123 ~135 grass_block
setblock ~151 ~123 ~136 grass_block
setblock ~151 ~123 ~139 short_grass
setblock ~151 ~123 ~142 grass_block
setblock ~151 ~123 ~143 grass_block
setblock ~151 ~123 ~144 dirt
setblock ~151 ~123 ~145 dirt
setblock ~151 ~123 ~146 dirt
setblock ~151 ~123 ~147 dirt
setblock ~151 ~123 ~148 dirt
setblock ~151 ~123 ~149 dirt
setblock ~151 ~123 ~150 dirt
setblock ~151 ~123 ~151 dirt
setblock ~151 ~123 ~152 dirt
setblock ~151 ~123 ~153 dirt
setblock ~151 ~123 ~154 dirt
setblock ~151 ~123 ~155 dirt
setblock ~151 ~123 ~156 dirt
setblock ~151 ~123 ~157 dirt
setblock ~151 ~123 ~158 dirt
setblock ~151 ~123 ~159 dirt
setblock ~151 ~123 ~160 dirt
setblock ~151 ~123 ~161 dirt
setblock ~151 ~123 ~162 dirt
setblock ~151 ~123 ~163 dirt
setblock ~151 ~123 ~164 grass_block
setblock ~151 ~123 ~165 grass_block
setblock ~151 ~123 ~166 grass_block
setblock ~151 ~123 ~167 grass_block
setblock ~151 ~123 ~168 grass_block
setblock ~151 ~123 ~172 grass_block
setblock ~151 ~123 ~173 grass_block
setblock ~151 ~123 ~174 grass_block
setblock ~151 ~123 ~175 dirt
setblock ~151 ~123 ~176 dirt
setblock ~151 ~123 ~177 dirt
setblock ~151 ~123 ~178 dirt
setblock ~151 ~123 ~179 dirt
setblock ~151 ~123 ~180 dirt
setblock ~151 ~123 ~181 dirt
setblock ~151 ~123 ~182 dirt
setblock ~151 ~123 ~183 dirt
setblock ~151 ~123 ~184 dirt
setblock ~151 ~123 ~185 dirt
setblock ~151 ~123 ~186 dirt
setblock ~151 ~123 ~187 dirt
setblock ~151 ~123 ~188 dirt
setblock ~151 ~123 ~189 dirt
setblock ~151 ~123 ~190 dirt
setblock ~151 ~123 ~191 dirt
setblock ~151 ~123 ~192 dirt
setblock ~151 ~123 ~193 dirt
setblock ~151 ~123 ~194 dirt
setblock ~151 ~123 ~195 dirt
setblock ~151 ~123 ~196 dirt
setblock ~151 ~123 ~197 dirt
setblock ~151 ~123 ~198 dirt
setblock ~151 ~123 ~199 dirt
setblock ~151 ~124 ~2 fern
setblock ~151 ~124 ~4 short_grass
setblock ~151 ~124 ~7 short_grass
setblock ~151 ~124 ~17 fern
setblock ~151 ~124 ~18 short_grass
setblock ~151 ~124 ~19 short_grass
setblock ~151 ~124 ~29 short_grass
setblock ~151 ~124 ~30 short_grass
setblock ~151 ~124 ~32 grass_block
setblock ~151 ~124 ~33 grass_block
setblock ~151 ~124 ~34 grass_block
setblock ~151 ~124 ~35 grass_block
setblock ~151 ~124 ~36 dirt
setblock ~151 ~124 ~37 dirt
setblock ~151 ~124 ~38 dirt
setblock ~151 ~124 ~39 dirt
setblock ~151 ~124 ~40 dirt
setblock ~151 ~124 ~41 dirt
setblock ~151 ~124 ~42 dirt
setblock ~151 ~124 ~43 dirt
setblock ~151 ~124 ~44 dirt
setblock ~151 ~124 ~45 dirt
setblock ~151 ~124 ~46 dirt
setblock ~151 ~124 ~47 dirt
setblock ~151 ~124 ~48 dirt
setblock ~151 ~124 ~49 dirt
setblock ~151 ~124 ~50 dirt
setblock ~151 ~124 ~51 dirt
setblock ~151 ~124 ~52 dirt
setblock ~151 ~124 ~53 dirt
setblock ~151 ~124 ~54 dirt
setblock ~151 ~124 ~55 dirt
setblock ~151 ~124 ~56 dirt
setblock ~151 ~124 ~57 dirt
setblock ~151 ~124 ~58 dirt
setblock ~151 ~124 ~59 dirt
setblock ~151 ~124 ~60 grass_block
setblock ~151 ~124 ~61 grass_block
setblock ~151 ~124 ~62 grass_block
setblock ~151 ~124 ~63 grass_block
setblock ~151 ~124 ~64 grass_block
setblock ~151 ~124 ~65 grass_block
setblock ~151 ~124 ~66 grass_block
setblock ~151 ~124 ~67 grass_block
setblock ~151 ~124 ~69 short_grass
setblock ~151 ~124 ~71 short_grass
setblock ~151 ~124 ~72 grass_block
setblock ~151 ~124 ~73 grass_block
setblock ~151 ~124 ~74 dirt
setblock ~151 ~124 ~75 dirt
setblock ~151 ~124 ~76 dirt
setblock ~151 ~124 ~77 dirt
setblock ~151 ~124 ~78 dirt
setblock ~151 ~124 ~79 dirt
setblock ~151 ~124 ~80 dirt
setblock ~151 ~124 ~81 dirt
setblock ~151 ~124 ~82 dirt
setblock ~151 ~124 ~83 dirt
setblock ~151 ~124 ~84 dirt
setblock ~151 ~124 ~85 dirt
setblock ~151 ~124 ~86 dirt
setblock ~151 ~124 ~87 grass_block
setblock ~151 ~124 ~88 grass_block
setblock ~151 ~124 ~89 grass_block
setblock ~151 ~124 ~91 grass_block
setblock ~151 ~124 ~92 grass_block
setblock ~151 ~124 ~93 dirt
setblock ~151 ~124 ~94 dirt
setblock ~151 ~124 ~95 dirt
setblock ~151 ~124 ~96 dirt
setblock ~151 ~124 ~97 dirt
setblock ~151 ~124 ~98 dirt
setblock ~151 ~124 ~99 dirt
setblock ~151 ~124 ~100 dirt
setblock ~151 ~124 ~101 dirt
setblock ~151 ~124 ~102 dirt
setblock ~151 ~124 ~103 dirt
setblock ~151 ~124 ~104 dirt
setblock ~151 ~124 ~105 dirt
setblock ~151 ~124 ~106 dirt
setblock ~151 ~124 ~107 grass_block
setblock ~151 ~124 ~108 grass_block
setblock ~151 ~124 ~114 short_grass
setblock ~151 ~124 ~117 short_grass
setblock ~151 ~124 ~120 short_grass
setblock ~151 ~124 ~121 short_grass
setblock ~151 ~124 ~123 fern
setblock ~151 ~124 ~125 short_grass
setblock ~151 ~124 ~126 grass_block
setblock ~151 ~124 ~127 grass_block
setblock ~151 ~124 ~128 dirt
setblock ~151 ~124 ~129 dirt
setblock ~151 ~124 ~130 dirt
setblock ~151 ~124 ~131 dirt
setblock ~151 ~124 ~132 grass_block
setblock ~151 ~124 ~133 grass_block
setblock ~151 ~124 ~144 grass_block
setblock ~151 ~124 ~145 grass_block
setblock ~151 ~124 ~146 dirt
setblock ~151 ~124 ~147 dirt
setblock ~151 ~124 ~148 dirt
setblock ~151 ~124 ~149 dirt
setblock ~151 ~124 ~150 dirt
setblock ~151 ~124 ~151 dirt
setblock ~151 ~124 ~152 dirt
setblock ~151 ~124 ~153 dirt
setblock ~151 ~124 ~154 dirt
setblock ~151 ~124 ~155 dirt
setblock ~151 ~124 ~156 dirt
setblock ~151 ~124 ~157 dirt
setblock ~151 ~124 ~158 dirt
setblock ~151 ~124 ~159 grass_block
setblock ~151 ~124 ~160 grass_block
setblock ~151 ~124 ~161 grass_block
setblock ~151 ~124 ~162 grass_block
setblock ~151 ~124 ~163 grass_block
setblock ~151 ~124 ~164 fern
setblock ~151 ~124 ~167 short_grass
setblock ~151 ~124 ~168 fern
setblock ~151 ~124 ~175 grass_block
setblock ~151 ~124 ~176 grass_block
setblock ~151 ~124 ~177 dirt
setblock ~151 ~124 ~178 dirt
setblock ~151 ~124 ~179 dirt
setblock ~151 ~124 ~180 dirt
setblock ~151 ~124 ~181 dirt
setblock ~151 ~124 ~182 dirt
setblock ~151 ~124 ~183 dirt
setblock ~151 ~124 ~184 dirt
setblock ~151 ~124 ~185 dirt
setblock ~151 ~124 ~186 dirt
setblock ~151 ~124 ~187 dirt
setblock ~151 ~124 ~188 dirt
setblock ~151 ~124 ~189 dirt
setblock ~151 ~124 ~190 dirt
setblock ~151 ~124 ~191 dirt
setblock ~151 ~124 ~192 dirt
setblock ~151 ~124 ~193 dirt
setblock ~151 ~124 ~194 dirt
setblock ~151 ~124 ~195 dirt
setblock ~151 ~124 ~196 grass_block
setblock ~151 ~124 ~197 grass_block
setblock ~151 ~124 ~198 grass_block
setblock ~151 ~124 ~199 grass_block
setblock ~151 ~125 ~34 short_grass
setblock ~151 ~125 ~36 grass_block
setblock ~151 ~125 ~37 grass_block
setblock ~151 ~125 ~38 grass_block
setblock ~151 ~125 ~39 grass_block
setblock ~151 ~125 ~40 grass_block
setblock ~151 ~125 ~41 grass_block
setblock ~151 ~125 ~42 dirt
setblock ~151 ~125 ~43 dirt
setblock ~151 ~125 ~44 dirt
setblock ~151 ~125 ~45 dirt
setblock ~151 ~125 ~46 dirt
setblock ~151 ~125 ~47 dirt
setblock ~151 ~125 ~48 dirt
setblock ~151 ~125 ~49 dirt
setblock ~151 ~125 ~50 dirt
setblock ~151 ~125 ~51 dirt
setblock ~151 ~125 ~52 dirt
setblock ~151 ~125 ~53 dirt
setblock ~151 ~125 ~54 dirt
setblock ~151 ~125 ~55 dirt
setblock ~151 ~125 ~56 dirt
setblock ~151 ~125 ~57 grass_block
setblock ~151 ~125 ~58 grass_block
setblock ~151 ~125 ~59 grass_block
setblock ~151 ~125 ~66 fern
setblock ~151 ~125 ~67 short_grass
setblock ~151 ~125 ~74 grass_block
setblock ~151 ~125 ~75 grass_block
setblock ~151 ~125 ~76 dirt
setblock ~151 ~125 ~77 dirt
setblock ~151 ~125 ~78 dirt
setblock ~151 ~125 ~79 dirt
setblock ~151 ~125 ~80 dirt
setblock ~151 ~125 ~81 dirt
setblock ~151 ~125 ~82 dirt
setblock ~151 ~125 ~83 dirt
setblock ~151 ~125 ~84 dirt
setblock ~151 ~125 ~85 grass_block
setblock ~151 ~125 ~86 grass_block
setblock ~151 ~125 ~87 short_grass
setblock ~151 ~125 ~89 short_grass
setblock ~151 ~125 ~93 grass_block
setblock ~151 ~125 ~94 grass_block
setblock ~151 ~125 ~95 dirt
setblock ~151 ~125 ~96 dirt
setblock ~151 ~125 ~97 dirt
setblock ~151 ~125 ~98 dirt
setblock ~151 ~125 ~99 dirt
setblock ~151 ~125 ~100 dirt
setblock ~151 ~125 ~101 dirt
setblock ~151 ~125 ~102 dirt
setblock ~151 ~125 ~103 dirt
setblock ~151 ~125 ~104 dirt
setblock ~151 ~125 ~105 dirt
setblock ~151 ~125 ~106 grass_block
setblock ~151 ~125 ~128 grass_block
setblock ~151 ~125 ~129 grass_block
setblock ~151 ~125 ~130 dirt
setblock ~151 ~125 ~131 grass_block
setblock ~151 ~125 ~145 short_grass
setblock ~151 ~125 ~146 grass_block
setblock ~151 ~125 ~147 grass_block
setblock ~151 ~125 ~148 grass_block
setblock ~151 ~125 ~149 dirt
setblock ~151 ~125 ~150 dirt
setblock ~151 ~125 ~151 dirt
setblock ~151 ~125 ~152 dirt
setblock ~151 ~125 ~153 dirt
setblock ~151 ~125 ~154 grass_block
setblock ~151 ~125 ~155 grass_block
setblock ~151 ~125 ~156 grass_block
setblock ~151 ~125 ~157 grass_block
setblock ~151 ~125 ~158 grass_block
setblock ~151 ~125 ~160 short_grass
setblock ~151 ~125 ~161 fern
setblock ~151 ~125 ~175 short_grass
setblock ~151 ~125 ~176 short_grass
setblock ~151 ~125 ~177 grass_block
setblock ~151 ~125 ~178 grass_block
setblock ~151 ~125 ~179 dirt
setblock ~151 ~125 ~180 dirt
setblock ~151 ~125 ~181 dirt
setblock ~151 ~125 ~182 dirt
setblock ~151 ~125 ~183 dirt
setblock ~151 ~125 ~184 grass_block
setblock ~151 ~125 ~185 grass_block
setblock ~151 ~125 ~186 grass_block
setblock ~151 ~125 ~187 grass_block
setblock ~151 ~125 ~188 grass_block
setblock ~151 ~125 ~189 grass_block
setblock ~151 ~125 ~190 grass_block
setblock ~151 ~125 ~191 grass_block
setblock ~151 ~125 ~192 grass_block
setblock ~151 ~125 ~193 grass_block
setblock ~151 ~125 ~194 grass_block
setblock ~151 ~125 ~195 grass_block
setblock ~151 ~125 ~196 fern
setblock ~151 ~125 ~199 short_grass
setblock ~151 ~126 ~41 short_grass
setblock ~151 ~126 ~42 grass_block
setblock ~151 ~126 ~43 grass_block
setblock ~151 ~126 ~44 grass_block
setblock ~151 ~126 ~45 dirt
setblock ~151 ~126 ~46 dirt
setblock ~151 ~126 ~47 dirt
setblock ~151 ~126 ~48 dirt
setblock ~151 ~126 ~49 dirt
setblock ~151 ~126 ~50 dirt
setblock ~151 ~126 ~51 dirt
setblock ~151 ~126 ~52 dirt
setblock ~151 ~126 ~53 dirt
setblock ~151 ~126 ~54 dirt
setblock ~151 ~126 ~55 grass_block
setblock ~151 ~126 ~56 grass_block
setblock ~151 ~126 ~75 short_grass
setblock ~151 ~126 ~76 grass_block
setblock ~151 ~126 ~77 grass_block
setblock ~151 ~126 ~78 dirt
setblock ~151 ~126 ~79 dirt
setblock ~151 ~126 ~80 dirt
setblock ~151 ~126 ~81 dirt
setblock ~151 ~126 ~82 dirt
setblock ~151 ~126 ~83 grass_block
setblock ~151 ~126 ~84 grass_block
setblock ~151 ~126 ~94 short_grass
setblock ~151 ~126 ~95 grass_block
setblock ~151 ~126 ~96 grass_block
setblock ~151 ~126 ~97 dirt
setblock ~151 ~126 ~98 dirt
setblock ~151 ~126 ~99 dirt
setblock ~151 ~126 ~100 dirt
setblock ~151 ~126 ~101 dirt
setblock ~151 ~126 ~102 dirt
setblock ~151 ~126 ~103 dirt
setblock ~151 ~126 ~104 dirt
setblock ~151 ~126 ~105 grass_block
setblock ~151 ~126 ~106 fern
setblock ~151 ~126 ~129 short_grass
setblock ~151 ~126 ~130 grass_block
setblock ~151 ~126 ~147 short_grass
setblock ~151 ~126 ~149 grass_block
setblock ~151 ~126 ~150 grass_block
setblock ~151 ~126 ~151 grass_block
setblock ~151 ~126 ~152 grass_block
setblock ~151 ~126 ~153 grass_block
setblock ~151 ~126 ~154 short_grass
setblock ~151 ~126 ~155 short_grass
setblock ~151 ~126 ~157 short_grass
setblock ~151 ~126 ~179 grass_block
setblock ~151 ~126 ~180 grass_block
setblock ~151 ~126 ~181 grass_block
setblock ~151 ~126 ~182 grass_block
setblock ~151 ~126 ~183 grass_block
setblock ~151 ~126 ~184 short_grass
setblock ~151 ~126 ~185 short_grass
setblock ~151 ~126 ~189 fern
setblock ~151 ~126 ~190 poppy
setblock ~151 ~126 ~191 short_grass
setblock ~151 ~126 ~194 short_grass
setblock ~151 ~127 ~42 short_grass
setblock ~151 ~127 ~44 short_grass
setblock ~151 ~127 ~45 grass_block
setblock ~151 ~127 ~46 grass_block
setblock ~151 ~127 ~47 dirt
setblock ~151 ~127 ~48 dirt
setblock ~151 ~127 ~49 dirt
setblock ~151 ~127 ~50 dirt
setblock ~151 ~127 ~51 dirt
setblock ~151 ~127 ~52 dirt
setblock ~151 ~127 ~53 grass_block
setblock ~151 ~127 ~54 grass_block
setblock ~151 ~127 ~55 short_grass
setblock ~151 ~127 ~77 short_grass
setblock ~151 ~127 ~78 grass_block
setblock ~151 ~127 ~79 grass_block
setblock ~151 ~127 ~80 dirt
setblock ~151 ~127 ~81 grass_block
setblock ~151 ~127 ~82 grass_block
setblock ~151 ~127 ~83 short_grass
setblock ~151 ~127 ~95 short_grass
setblock ~151 ~127 ~97 grass_block
setblock ~151 ~127 ~98 dirt
setblock ~151 ~127 ~99 dirt
setblock ~151 ~127 ~100 dirt
setblock ~151 ~127 ~101 dirt
setblock ~151 ~127 ~102 dirt
setblock ~151 ~127 ~103 grass_block
setblock ~151 ~127 ~104 grass_block
setblock ~151 ~127 ~152 poppy
setblock ~151 ~127 ~180 short_grass
setblock ~151 ~128 ~47 grass_block
setblock ~151 ~128 ~48 grass_block
setblock ~151 ~128 ~49 dirt
setblock ~151 ~128 ~50 dirt
setblock ~151 ~128 ~51 grass_block
setblock ~151 ~128 ~52 grass_block
setblock ~151 ~128 ~80 grass_block
setblock ~151 ~128 ~97 short_grass
setblock ~151 ~128 ~98 grass_block
setblock ~151 ~128 ~99 grass_block
setblock ~151 ~128 ~100 dirt
setblock ~151 ~128 ~101 dirt
setblock ~151 ~128 ~102 grass_block
setblock ~151 ~129 ~49 grass_block
setblock ~151 ~129 ~50 grass_block
setblock ~151 ~129 ~80 short_grass
setblock ~151 ~129 ~100 grass_block
setblock ~151 ~129 ~101 grass_block
setblock ~151 ~130 ~49 fern
setblock ~152 ~122 ~0 dirt
setblock ~152 ~122 ~1 dirt
setblock ~152 ~122 ~2 dirt
setblock ~152 ~122 ~3 dirt
setblock ~152 ~122 ~4 dirt
setblock ~152 ~122 ~5 dirt
setblock ~152 ~122 ~6 dirt
setblock ~152 ~122 ~7 dirt
setblock ~152 ~122 ~8 dirt
setblock ~152 ~122 ~9 dirt
setblock ~152 ~122 ~10 dirt
setblock ~152 ~122 ~11 dirt
setblock ~152 ~122 ~12 dirt
setblock ~152 ~122 ~13 dirt
setblock ~152 ~122 ~14 dirt
setblock ~152 ~122 ~15 dirt
setblock ~152 ~122 ~16 dirt
setblock ~152 ~122 ~17 dirt
setblock ~152 ~122 ~18 dirt
setblock ~152 ~122 ~19 dirt
setblock ~152 ~122 ~20 dirt
setblock ~152 ~122 ~21 dirt
setblock ~152 ~122 ~22 dirt
setblock ~152 ~122 ~23 dirt
setblock ~152 ~122 ~24 dirt
setblock ~152 ~122 ~25 dirt
setblock ~152 ~122 ~26 dirt
setblock ~152 ~122 ~27 dirt
setblock ~152 ~122 ~28 dirt
setblock ~152 ~122 ~29 dirt
setblock ~152 ~122 ~30 dirt
setblock ~152 ~122 ~31 dirt
setblock ~152 ~122 ~32 dirt
setblock ~152 ~122 ~33 dirt
setblock ~152 ~122 ~34 dirt
setblock ~152 ~122 ~35 dirt
setblock ~152 ~122 ~36 dirt
setblock ~152 ~122 ~37 dirt
setblock ~152 ~122 ~38 dirt
setblock ~152 ~122 ~39 dirt
setblock ~152 ~122 ~40 dirt
setblock ~152 ~122 ~41 dirt
setblock ~152 ~122 ~42 dirt
setblock ~152 ~122 ~43 dirt
setblock ~152 ~122 ~44 dirt
setblock ~152 ~122 ~45 dirt
setblock ~152 ~122 ~46 dirt
setblock ~152 ~122 ~47 dirt
setblock ~152 ~122 ~48 dirt
setblock ~152 ~122 ~49 dirt
setblock ~152 ~122 ~50 dirt
setblock ~152 ~122 ~51 dirt
setblock ~152 ~122 ~52 dirt
setblock ~152 ~122 ~53 dirt
setblock ~152 ~122 ~54 dirt
setblock ~152 ~122 ~55 dirt
setblock ~152 ~122 ~56 dirt
setblock ~152 ~122 ~57 dirt
setblock ~152 ~122 ~58 dirt
setblock ~152 ~122 ~59 dirt
setblock ~152 ~122 ~60 dirt
setblock ~152 ~122 ~61 dirt
setblock ~152 ~122 ~62 dirt
setblock ~152 ~122 ~63 dirt
setblock ~152 ~122 ~64 dirt
setblock ~152 ~122 ~65 dirt
setblock ~152 ~122 ~66 dirt
setblock ~152 ~122 ~67 dirt
setblock ~152 ~122 ~68 dirt
setblock ~152 ~122 ~69 dirt
setblock ~152 ~122 ~70 dirt
setblock ~152 ~122 ~71 dirt
setblock ~152 ~122 ~72 dirt
setblock ~152 ~122 ~73 dirt
setblock ~152 ~122 ~74 dirt
setblock ~152 ~122 ~75 dirt
setblock ~152 ~122 ~76 dirt
setblock ~152 ~122 ~77 dirt
setblock ~152 ~122 ~78 dirt
setblock ~152 ~122 ~79 dirt
setblock ~152 ~122 ~80 dirt
setblock ~152 ~122 ~81 dirt
setblock ~152 ~122 ~82 dirt
setblock ~152 ~122 ~83 dirt
setblock ~152 ~122 ~84 dirt
setblock ~152 ~122 ~85 dirt
setblock ~152 ~122 ~86 dirt
setblock ~152 ~122 ~87 dirt
setblock ~152 ~122 ~88 dirt
setblock ~152 ~122 ~89 dirt
setblock ~152 ~122 ~90 dirt
setblock ~152 ~122 ~91 dirt
setblock ~152 ~122 ~92 dirt
setblock ~152 ~122 ~93 dirt
setblock ~152 ~122 ~94 dirt
setblock ~152 ~122 ~95 dirt
setblock ~152 ~122 ~96 dirt
setblock ~152 ~122 ~97 dirt
setblock ~152 ~122 ~98 dirt
setblock ~152 ~122 ~99 dirt
setblock ~152 ~122 ~100 dirt
setblock ~152 ~122 ~101 dirt
setblock ~152 ~122 ~102 dirt
setblock ~152 ~122 ~103 dirt
setblock ~152 ~122 ~104 dirt
setblock ~152 ~122 ~105 dirt
setblock ~152 ~122 ~106 dirt
setblock ~152 ~122 ~107 dirt
setblock ~152 ~122 ~108 dirt
setblock ~152 ~122 ~109 dirt
setblock ~152 ~122 ~110 dirt
setblock ~152 ~122 ~111 dirt
setblock ~152 ~122 ~112 dirt
setblock ~152 ~122 ~113 dirt
setblock ~152 ~122 ~114 dirt
setblock ~152 ~122 ~115 dirt
setblock ~152 ~122 ~116 dirt
setblock ~152 ~122 ~117 dirt
setblock ~152 ~122 ~118 dirt
setblock ~152 ~122 ~119 dirt
setblock ~152 ~122 ~120 dirt
setblock ~152 ~122 ~121 dirt
setblock ~152 ~122 ~122 dirt
setblock ~152 ~122 ~123 dirt
setblock ~152 ~122 ~124 dirt
setblock ~152 ~122 ~125 dirt
setblock ~152 ~122 ~126 dirt
setblock ~152 ~122 ~127 dirt
setblock ~152 ~122 ~128 dirt
setblock ~152 ~122 ~129 dirt
setblock ~152 ~122 ~130 dirt
setblock ~152 ~122 ~131 dirt
setblock ~152 ~122 ~132 dirt
setblock ~152 ~122 ~133 dirt
setblock ~152 ~122 ~134 dirt
setblock ~152 ~122 ~135 dirt
setblock ~152 ~122 ~136 dirt
setblock ~152 ~122 ~137 grass_block
setblock ~152 ~122 ~138 grass_block
setblock ~152 ~122 ~139 grass_block
setblock ~152 ~122 ~140 grass_block
setblock ~152 ~122 ~141 grass_block
setblock ~152 ~122 ~142 dirt
setblock ~152 ~122 ~143 dirt
setblock ~152 ~122 ~144 dirt
setblock ~152 ~122 ~145 dirt
setblock ~152 ~122 ~146 dirt
setblock ~152 ~122 ~147 dirt
setblock ~152 ~122 ~148 dirt
setblock ~152 ~122 ~149 dirt
setblock ~152 ~122 ~150 dirt
setblock ~152 ~122 ~151 dirt
setblock ~152 ~122 ~152 dirt
setblock ~152 ~122 ~153 dirt
setblock ~152 ~122 ~154 dirt
setblock ~152 ~122 ~155 dirt
setblock ~152 ~122 ~156 dirt
setblock ~152 ~122 ~157 dirt
setblock ~152 ~122 ~158 dirt
setblock ~152 ~122 ~159 dirt
setblock ~152 ~122 ~160 dirt
setblock ~152 ~122 ~161 dirt
setblock ~152 ~122 ~162 dirt
setblock ~152 ~122 ~163 dirt
setblock ~152 ~122 ~164 dirt
setblock ~152 ~122 ~165 dirt
setblock ~152 ~122 ~166 dirt
setblock ~152 ~122 ~167 dirt
setblock ~152 ~122 ~168 dirt
setblock ~152 ~122 ~169 dirt
setblock ~152 ~122 ~170 grass_block
setblock ~152 ~122 ~171 dirt
setblock ~152 ~122 ~172 dirt
setblock ~152 ~122 ~173 dirt
setblock ~152 ~122 ~174 dirt
setblock ~152 ~122 ~175 dirt
setblock ~152 ~122 ~176 dirt
setblock ~152 ~122 ~177 dirt
setblock ~152 ~122 ~178 dirt
setblock ~152 ~122 ~179 dirt
setblock ~152 ~122 ~180 dirt
setblock ~152 ~122 ~181 dirt
setblock ~152 ~122 ~182 dirt
setblock ~152 ~122 ~183 dirt
setblock ~152 ~122 ~184 dirt
setblock ~152 ~122 ~185 dirt
setblock ~152 ~122 ~186 dirt
setblock ~152 ~122 ~187 dirt
setblock ~152 ~122 ~188 dirt
setblock ~152 ~122 ~189 dirt
setblock ~152 ~122 ~190 dirt
setblock ~152 ~122 ~191 dirt
setblock ~152 ~122 ~192 dirt
setblock ~152 ~122 ~193 dirt
setblock ~152 ~122 ~194 dirt
setblock ~152 ~122 ~195 dirt
setblock ~152 ~122 ~196 dirt
setblock ~152 ~122 ~197 dirt
setblock ~152 ~122 ~198 dirt
setblock ~152 ~122 ~199 dirt
setblock ~152 ~123 ~0 grass_block
setblock ~152 ~123 ~1 grass_block
setblock ~152 ~123 ~2 grass_block
setblock ~152 ~123 ~3 grass_block
setblock ~152 ~123 ~4 grass_block
setblock ~152 ~123 ~5 grass_block
setblock ~152 ~123 ~6 grass_block
setblock ~152 ~123 ~7 grass_block
setblock ~152 ~123 ~8 grass_block
setblock ~152 ~123 ~9 grass_block
setblock ~152 ~123 ~10 grass_block
setblock ~152 ~123 ~11 grass_block
setblock ~152 ~123 ~12 grass_block
setblock ~152 ~123 ~13 grass_block
setblock ~152 ~123 ~14 grass_block
setblock ~152 ~123 ~15 grass_block
setblock ~152 ~123 ~16 grass_block
setblock ~152 ~123 ~17 grass_block
setblock ~152 ~123 ~18 grass_block
setblock ~152 ~123 ~19 grass_block
setblock ~152 ~123 ~20 grass_block
setblock ~152 ~123 ~21 grass_block
setblock ~152 ~123 ~22 grass_block
setblock ~152 ~123 ~23 grass_block
setblock ~152 ~123 ~24 grass_block
setblock ~152 ~123 ~25 grass_block
setblock ~152 ~123 ~26 grass_block
setblock ~152 ~123 ~27 grass_block
setblock ~152 ~123 ~28 grass_block
setblock ~152 ~123 ~29 grass_block
setblock ~152 ~123 ~30 grass_block
setblock ~152 ~123 ~31 grass_block
setblock ~152 ~123 ~32 dirt
setblock ~152 ~123 ~33 dirt
setblock ~152 ~123 ~34 dirt
setblock ~152 ~123 ~35 dirt
setblock ~152 ~123 ~36 dirt
setblock ~152 ~123 ~37 dirt
setblock ~152 ~123 ~38 dirt
setblock ~152 ~123 ~39 dirt
setblock ~152 ~123 ~40 dirt
setblock ~152 ~123 ~41 dirt
setblock ~152 ~123 ~42 dirt
setblock ~152 ~123 ~43 dirt
setblock ~152 ~123 ~44 dirt
setblock ~152 ~123 ~45 dirt
setblock ~152 ~123 ~46 dirt
setblock ~152 ~123 ~47 dirt
setblock ~152 ~123 ~48 dirt
setblock ~152 ~123 ~49 dirt
setblock ~152 ~123 ~50 dirt
setblock ~152 ~123 ~51 dirt
setblock ~152 ~123 ~52 dirt
setblock ~152 ~123 ~53 dirt
setblock ~152 ~123 ~54 dirt
setblock ~152 ~123 ~55 dirt
setblock ~152 ~123 ~56 dirt
setblock ~152 ~123 ~57 dirt
setblock ~152 ~123 ~58 dirt
setblock ~152 ~123 ~59 dirt
setblock ~152 ~123 ~60 dirt
setblock ~152 ~123 ~61 dirt
setblock ~152 ~123 ~62 dirt
setblock ~152 ~123 ~63 dirt
setblock ~152 ~123 ~64 dirt
setblock ~152 ~123 ~65 dirt
setblock ~152 ~123 ~66 dirt
setblock ~152 ~123 ~67 dirt
setblock ~152 ~123 ~68 dirt
setblock ~152 ~123 ~69 grass_block
setblock ~152 ~123 ~70 grass_block
setblock ~152 ~123 ~71 dirt
setblock ~152 ~123 ~72 dirt
setblock ~152 ~123 ~73 dirt
setblock ~152 ~123 ~74 dirt
setblock ~152 ~123 ~75 dirt
setblock ~152 ~123 ~76 dirt
setblock ~152 ~123 ~77 dirt
setblock ~152 ~123 ~78 dirt
setblock ~152 ~123 ~79 dirt
setblock ~152 ~123 ~80 dirt
setblock ~152 ~123 ~81 dirt
setblock ~152 ~123 ~82 dirt
setblock ~152 ~123 ~83 dirt
setblock ~152 ~123 ~84 dirt
setblock ~152 ~123 ~85 dirt
setblock ~152 ~123 ~86 dirt
setblock ~152 ~123 ~87 dirt
setblock ~152 ~123 ~88 dirt
setblock ~152 ~123 ~89 dirt
setblock ~152 ~123 ~90 dirt
setblock ~152 ~123 ~91 dirt
setblock ~152 ~123 ~92 dirt
setblock ~152 ~123 ~93 dirt
setblock ~152 ~123 ~94 dirt
setblock ~152 ~123 ~95 dirt
setblock ~152 ~123 ~96 dirt
setblock ~152 ~123 ~97 dirt
setblock ~152 ~123 ~98 dirt
setblock ~152 ~123 ~99 dirt
setblock ~152 ~123 ~100 dirt
setblock ~152 ~123 ~101 dirt
setblock ~152 ~123 ~102 dirt
setblock ~152 ~123 ~103 dirt
setblock ~152 ~123 ~104 dirt
setblock ~152 ~123 ~105 dirt
setblock ~152 ~123 ~106 dirt
setblock ~152 ~123 ~107 dirt
setblock ~152 ~123 ~108 dirt
setblock ~152 ~123 ~109 grass_block
setblock ~152 ~123 ~110 grass_block
setblock ~152 ~123 ~111 grass_block
setblock ~152 ~123 ~112 grass_block
setblock ~152 ~123 ~113 grass_block
setblock ~152 ~123 ~114 grass_block
setblock ~152 ~123 ~115 grass_block
setblock ~152 ~123 ~116 grass_block
setblock ~152 ~123 ~117 grass_block
setblock ~152 ~123 ~118 grass_block
setblock ~152 ~123 ~119 grass_block
setblock ~152 ~123 ~120 grass_block
setblock ~152 ~123 ~121 grass_block
setblock ~152 ~123 ~122 grass_block
setblock ~152 ~123 ~123 grass_block
setblock ~152 ~123 ~124 grass_block
setblock ~152 ~123 ~125 dirt
setblock ~152 ~123 ~126 dirt
setblock ~152 ~123 ~127 dirt
setblock ~152 ~123 ~128 dirt
setblock ~152 ~123 ~129 dirt
setblock ~152 ~123 ~130 dirt
setblock ~152 ~123 ~131 dirt
setblock ~152 ~123 ~132 dirt
setblock ~152 ~123 ~133 grass_block
setblock ~152 ~123 ~134 grass_block
setblock ~152 ~123 ~135 grass_block
setblock ~152 ~123 ~136 grass_block
setblock ~152 ~123 ~137 poppy
setblock ~152 ~123 ~139 short_grass
setblock ~152 ~123 ~142 grass_block
setblock ~152 ~123 ~143 grass_block
setblock ~152 ~123 ~144 dirt
setblock ~152 ~123 ~145 dirt
setblock ~152 ~123 ~146 dirt
setblock ~152 ~123 ~147 dirt
setblock ~152 ~123 ~148 dirt
setblock ~152 ~123 ~149 dirt
setblock ~152 ~123 ~150 dirt
setblock ~152 ~123 ~151 dirt
setblock ~152 ~123 ~152 dirt
setblock ~152 ~123 ~153 dirt
setblock ~152 ~123 ~154 dirt
setblock ~152 ~123 ~155 dirt
setblock ~152 ~123 ~156 dirt
setblock ~152 ~123 ~157 dirt
setblock ~152 ~123 ~158 dirt
setblock ~152 ~123 ~159 dirt
setblock ~152 ~123 ~160 dirt
setblock ~152 ~123 ~161 dirt
setblock ~152 ~123 ~162 dirt
setblock ~152 ~123 ~163 dirt
setblock ~152 ~123 ~164 dirt
setblock ~152 ~123 ~165 grass_block
setblock ~152 ~123 ~166 grass_block
setblock ~152 ~123 ~167 grass_block
setblock ~152 ~123 ~168 grass_block
setblock ~152 ~123 ~169 grass_block
setblock ~152 ~123 ~171 grass_block
setblock ~152 ~123 ~172 grass_block
setblock ~152 ~123 ~173 grass_block
setblock ~152 ~123 ~174 grass_block
setblock ~152 ~123 ~175 dirt
setblock ~152 ~123 ~176 dirt
setblock ~152 ~123 ~177 dirt
setblock ~152 ~123 ~178 dirt
setblock ~152 ~123 ~179 dirt
setblock ~152 ~123 ~180 dirt
setblock ~152 ~123 ~181 dirt
setblock ~152 ~123 ~182 dirt
setblock ~152 ~123 ~183 dirt
setblock ~152 ~123 ~184 dirt
setblock ~152 ~123 ~185 dirt
setblock ~152 ~123 ~186 dirt
setblock ~152 ~123 ~187 dirt
setblock ~152 ~123 ~188 dirt
setblock ~152 ~123 ~189 dirt
setblock ~152 ~123 ~190 dirt
setblock ~152 ~123 ~191 dirt
setblock ~152 ~123 ~192 dirt
setblock ~152 ~123 ~193 dirt
setblock ~152 ~123 ~194 dirt
setblock ~152 ~123 ~195 dirt
setblock ~152 ~123 ~196 dirt
setblock ~152 ~123 ~197 dirt
setblock ~152 ~123 ~198 dirt
setblock ~152 ~123 ~199 dirt
setblock ~152 ~124 ~0 short_grass
setblock ~152 ~124 ~4 short_grass
setblock ~152 ~124 ~5 short_grass
setblock ~152 ~124 ~7 short_grass
setblock ~152 ~124 ~15 fern
setblock ~152 ~124 ~18 fern
setblock ~152 ~124 ~23 poppy
setblock ~152 ~124 ~24 short_grass
setblock ~152 ~124 ~29 poppy
setblock ~152 ~124 ~32 grass_block
setblock ~152 ~124 ~33 grass_block
setblock ~152 ~124 ~34 grass_block
setblock ~152 ~124 ~35 grass_block
setblock ~152 ~124 ~36 dirt
setblock ~152 ~124 ~37 dirt
setblock ~152 ~124 ~38 dirt
setblock ~152 ~124 ~39 dirt
setblock ~152 ~124 ~40 dirt
setblock ~152 ~124 ~41 dirt
setblock ~152 ~124 ~42 dirt
setblock ~152 ~124 ~43 dirt
setblock ~152 ~124 ~44 dirt
setblock ~152 ~124 ~45 dirt
setblock ~152 ~124 ~46 dirt
setblock ~152 ~124 ~47 dirt
setblock ~152 ~124 ~48 dirt
setblock ~152 ~124 ~49 dirt
setblock ~152 ~124 ~50 dirt
setblock ~152 ~124 ~51 dirt
setblock ~152 ~124 ~52 dirt
setblock ~152 ~124 ~53 dirt
setblock ~152 ~124 ~54 dirt
setblock ~152 ~124 ~55 dirt
setblock ~152 ~124 ~56 dirt
setblock ~152 ~124 ~57 dirt
setblock ~152 ~124 ~58 dirt
setblock ~152 ~124 ~59 dirt
setblock ~152 ~124 ~60 grass_block
setblock ~152 ~124 ~61 grass_block
setblock ~152 ~124 ~62 grass_block
setblock ~152 ~124 ~63 grass_block
setblock ~152 ~124 ~64 grass_block
setblock ~152 ~124 ~65 grass_block
setblock ~152 ~124 ~66 grass_block
setblock ~152 ~124 ~67 grass_block
setblock ~152 ~124 ~68 grass_block
setblock ~152 ~124 ~69 short_grass
setblock ~152 ~124 ~71 grass_block
setblock ~152 ~124 ~72 grass_block
setblock ~152 ~124 ~73 grass_block
setblock ~152 ~124 ~74 dirt
setblock ~152 ~124 ~75 dirt
setblock ~152 ~124 ~76 dirt
setblock ~152 ~124 ~77 dirt
setblock ~152 ~124 ~78 dirt
setblock ~152 ~124 ~79 dirt
setblock ~152 ~124 ~80 dirt
setblock ~152 ~124 ~81 dirt
setblock ~152 ~124 ~82 dirt
setblock ~152 ~124 ~83 dirt
setblock ~152 ~124 ~84 dirt
setblock ~152 ~124 ~85 dirt
setblock ~152 ~124 ~86 dirt
setblock ~152 ~124 ~87 dirt
setblock ~152 ~124 ~88 grass_block
setblock ~152 ~124 ~89 grass_block
setblock ~152 ~124 ~90 grass_block
setblock ~152 ~124 ~91 grass_block
setblock ~152 ~124 ~92 grass_block
setblock ~152 ~124 ~93 dirt
setblock ~152 ~124 ~94 dirt
setblock ~152 ~124 ~95 dirt
setblock ~152 ~124 ~96 dirt
setblock ~152 ~124 ~97 dirt
setblock ~152 ~124 ~98 dirt
setblock ~152 ~124 ~99 dirt
setblock ~152 ~124 ~100 dirt
setblock ~152 ~124 ~101 dirt
setblock ~152 ~124 ~102 dirt
setblock ~152 ~124 ~103 dirt
setblock ~152 ~124 ~104 dirt
setblock ~152 ~124 ~105 dirt
setblock ~152 ~124 ~106 dirt
setblock ~152 ~124 ~107 grass_block
setblock ~152 ~124 ~108 grass_block
setblock ~152 ~124 ~113 short_grass
setblock ~152 ~124 ~117 short_grass
setblock ~152 ~124 ~120 fern
setblock ~152 ~124 ~121 short_grass
setblock ~152 ~124 ~123 poppy
setblock ~152 ~124 ~125 grass_block
setblock ~152 ~124 ~126 grass_block
setblock ~152 ~124 ~127 grass_block
setblock ~152 ~124 ~128 grass_block
setblock ~152 ~124 ~129 dirt
setblock ~152 ~124 ~130 dirt
setblock ~152 ~124 ~131 grass_block
setblock ~152 ~124 ~132 grass_block
setblock ~152 ~124 ~134 short_grass
setblock ~152 ~124 ~135 fern
setblock ~152 ~124 ~144 grass_block
setblock ~152 ~124 ~145 grass_block
setblock ~152 ~124 ~146 dirt
setblock ~152 ~124 ~147 dirt
setblock ~152 ~124 ~148 dirt
setblock ~152 ~124 ~149 dirt
setblock ~152 ~124 ~150 dirt
setblock ~152 ~124 ~151 dirt
setblock ~152 ~124 ~152 dirt
setblock ~152 ~124 ~153 dirt
setblock ~152 ~124 ~154 dirt
setblock ~152 ~124 ~155 dirt
setblock ~152 ~124 ~156 dirt
setblock ~152 ~124 ~157 dirt
setblock ~152 ~124 ~158 dirt
setblock ~152 ~124 ~159 dirt
setblock ~152 ~124 ~160 grass_block
setblock ~152 ~124 ~161 grass_block
setblock ~152 ~124 ~162 grass_block
setblock ~152 ~124 ~163 grass_block
setblock ~152 ~124 ~164 grass_block
setblock ~152 ~124 ~169 short_grass
setblock ~152 ~124 ~174 short_grass
setblock ~152 ~124 ~175 grass_block
setblock ~152 ~124 ~176 grass_block
setblock ~152 ~124 ~177 grass_block
setblock ~152 ~124 ~178 dirt
setblock ~152 ~124 ~179 dirt
setblock ~152 ~124 ~180 dirt
setblock ~152 ~124 ~181 dirt
setblock ~152 ~124 ~182 dirt
setblock ~152 ~124 ~183 dirt
setblock ~152 ~124 ~184 dirt
setblock ~152 ~124 ~185 dirt
setblock ~152 ~124 ~186 dirt
setblock ~152 ~124 ~187 dirt
setblock ~152 ~124 ~188 dirt
setblock ~152 ~124 ~189 dirt
setblock ~152 ~124 ~190 dirt
setblock ~152 ~124 ~191 dirt
setblock ~152 ~124 ~192 dirt
setblock ~152 ~124 ~193 dirt
setblock ~152 ~124 ~194 dirt
setblock ~152 ~124 ~195 dirt
setblock ~152 ~124 ~196 dirt
setblock ~152 ~124 ~197 dirt
setblock ~152 ~124 ~198 dirt
setblock ~152 ~124 ~199 grass_block
setblock ~152 ~125 ~33 short_grass
setblock ~152 ~125 ~36 grass_block
setblock ~152 ~125 ~37 grass_block
setblock ~152 ~125 ~38 grass_block
setblock ~152 ~125 ~39 grass_block
setblock ~152 ~125 ~40 grass_block
setblock ~152 ~125 ~41 dirt
setblock ~152 ~125 ~42 dirt
setblock ~152 ~125 ~43 dirt
setblock ~152 ~125 ~44 dirt
setblock ~152 ~125 ~45 dirt
setblock ~152 ~125 ~46 dirt
setblock ~152 ~125 ~47 dirt
setblock ~152 ~125 ~48 dirt
setblock ~152 ~125 ~49 dirt
setblock ~152 ~125 ~50 dirt
setblock ~152 ~125 ~51 dirt
setblock ~152 ~125 ~52 dirt
setblock ~152 ~125 ~53 dirt
setblock ~152 ~125 ~54 dirt
setblock ~152 ~125 ~55 dirt
setblock ~152 ~125 ~56 dirt
setblock ~152 ~125 ~57 grass_block
setblock ~152 ~125 ~58 grass_block
setblock ~152 ~125 ~59 grass_block
setblock ~152 ~125 ~61 short_grass
setblock ~152 ~125 ~66 short_grass
setblock ~152 ~125 ~67 short_grass
setblock ~152 ~125 ~74 grass_block
setblock ~152 ~125 ~75 grass_block
setblock ~152 ~125 ~76 dirt
setblock ~152 ~125 ~77 dirt
setblock ~152 ~125 ~78 dirt
setblock ~152 ~125 ~79 dirt
setblock ~152 ~125 ~80 dirt
setblock ~152 ~125 ~81 dirt
setblock ~152 ~125 ~82 dirt
setblock ~152 ~125 ~83 dirt
setblock ~152 ~125 ~84 dirt
setblock ~152 ~125 ~85 grass_block
setblock ~152 ~125 ~86 grass_block
setblock ~152 ~125 ~87 grass_block
setblock ~152 ~125 ~90 short_grass
setblock ~152 ~125 ~93 grass_block
setblock ~152 ~125 ~94 grass_block
setblock ~152 ~125 ~95 dirt
setblock ~152 ~125 ~96 dirt
setblock ~152 ~125 ~97 dirt
setblock ~152 ~125 ~98 dirt
setblock ~152 ~125 ~99 dirt
setblock ~152 ~125 ~100 dirt
setblock ~152 ~125 ~101 dirt
setblock ~152 ~125 ~102 dirt
setblock ~152 ~125 ~103 dirt
setblock ~152 ~125 ~104 dirt
setblock ~152 ~125 ~105 dirt
setblock ~152 ~125 ~106 grass_block
setblock ~152 ~125 ~128 short_grass
setblock ~152 ~125 ~129 grass_block
setblock ~152 ~125 ~130 grass_block
setblock ~152 ~125 ~132 short_grass
setblock ~152 ~125 ~146 grass_block
setblock ~152 ~125 ~147 grass_block
setblock ~152 ~125 ~148 grass_block
setblock ~152 ~125 ~149 dirt
setblock ~152 ~125 ~150 dirt
setblock ~152 ~125 ~151 dirt
setblock ~152 ~125 ~152 dirt
setblock ~152 ~125 ~153 dirt
setblock ~152 ~125 ~154 grass_block
setblock ~152 ~125 ~155 grass_block
setblock ~152 ~125 ~156 grass_block
setblock ~152 ~125 ~157 grass_block
setblock ~152 ~125 ~158 grass_block
setblock ~152 ~125 ~159 grass_block
setblock ~152 ~125 ~175 short_grass
setblock ~152 ~125 ~178 grass_block
setblock ~152 ~125 ~179 grass_block
setblock ~152 ~125 ~180 dirt
setblock ~152 ~125 ~181 dirt
setblock ~152 ~125 ~182 dirt
setblock ~152 ~125 ~183 grass_block
setblock ~152 ~125 ~184 grass_block
setblock ~152 ~125 ~185 grass_block
setblock ~152 ~125 ~186 grass_block
setblock ~152 ~125 ~187 grass_block
setblock ~152 ~125 ~188 grass_block
setblock ~152 ~125 ~189 grass_block
setblock ~152 ~125 ~190 grass_block
setblock ~152 ~125 ~191 grass_block
setblock ~152 ~125 ~192 grass_block
setblock ~152 ~125 ~193 grass_block
setblock ~152 ~125 ~194 grass_block
setblock ~152 ~125 ~195 grass_block
setblock ~152 ~125 ~196 grass_block
setblock ~152 ~125 ~197 grass_block
setblock ~152 ~125 ~198 grass_block
setblock ~152 ~125 ~199 fern
setblock ~152 ~126 ~39 poppy
setblock ~152 ~126 ~40 short_grass
setblock ~152 ~126 ~41 grass_block
setblock ~152 ~126 ~42 grass_block
setblock ~152 ~126 ~43 grass_block
setblock ~152 ~126 ~44 grass_block
setblock ~152 ~126 ~45 dirt
setblock ~152 ~126 ~46 dirt
setblock ~152 ~126 ~47 dirt
setblock ~152 ~126 ~48 dirt
setblock ~152 ~126 ~49 dirt
setblock ~152 ~126 ~50 dirt
setblock ~152 ~126 ~51 dirt
setblock ~152 ~126 ~52 dirt
setblock ~152 ~126 ~53 dirt
setblock ~152 ~126 ~54 grass_block
setblock ~152 ~126 ~55 grass_block
setblock ~152 ~126 ~56 grass_block
setblock ~152 ~126 ~74 short_grass
setblock ~152 ~126 ~76 grass_block
setblock ~152 ~126 ~77 grass_block
setblock ~152 ~126 ~78 dirt
setblock ~152 ~126 ~79 dirt
setblock ~152 ~126 ~80 dirt
setblock ~152 ~126 ~81 dirt
setblock ~152 ~126 ~82 dirt
setblock ~152 ~126 ~83 grass_block
setblock ~152 ~126 ~84 grass_block
setblock ~152 ~126 ~93 short_grass
setblock ~152 ~126 ~95 grass_block
setblock ~152 ~126 ~96 grass_block
setblock ~152 ~126 ~97 dirt
setblock ~152 ~126 ~98 dirt
setblock ~152 ~126 ~99 dirt
setblock ~152 ~126 ~100 dirt
setblock ~152 ~126 ~101 dirt
setblock ~152 ~126 ~102 dirt
setblock ~152 ~126 ~103 dirt
setblock ~152 ~126 ~104 grass_block
setblock ~152 ~126 ~105 grass_block
setblock ~152 ~126 ~147 short_grass
setblock ~152 ~126 ~148 short_grass
setblock ~152 ~126 ~149 grass_block
setblock ~152 ~126 ~150 grass_block
setblock ~152 ~126 ~151 grass_block
setblock ~152 ~126 ~152 grass_block
setblock ~152 ~126 ~153 grass_block
setblock ~152 ~126 ~156 short_grass
setblock ~152 ~126 ~157 short_grass
setblock ~152 ~126 ~178 short_grass
setblock ~152 ~126 ~179 short_grass
setblock ~152 ~126 ~180 grass_block
setblock ~152 ~126 ~181 grass_block
setblock ~152 ~126 ~182 grass_block
setblock ~152 ~126 ~183 short_grass
setblock ~152 ~126 ~184 fern
setblock ~152 ~126 ~186 short_grass
setblock ~152 ~126 ~187 short_grass
setblock ~152 ~126 ~191 poppy
setblock ~152 ~126 ~194 short_grass
setblock ~152 ~126 ~195 short_grass
setblock ~152 ~126 ~196 fern
setblock ~152 ~126 ~197 fern
setblock ~152 ~127 ~42 short_grass
setblock ~152 ~127 ~45 grass_block
setblock ~152 ~127 ~46 grass_block
setblock ~152 ~127 ~47 grass_block
setblock ~152 ~127 ~48 dirt
setblock ~152 ~127 ~49 dirt
setblock ~152 ~127 ~50 dirt
setblock ~152 ~127 ~51 dirt
setblock ~152 ~127 ~52 grass_block
setblock ~152 ~127 ~53 grass_block
setblock ~152 ~127 ~76 short_grass
setblock ~152 ~127 ~78 grass_block
setblock ~152 ~127 ~79 dirt
setblock ~152 ~127 ~80 dirt
setblock ~152 ~127 ~81 grass_block
setblock ~152 ~127 ~82 grass_block
setblock ~152 ~127 ~95 short_grass
setblock ~152 ~127 ~96 short_grass
setblock ~152 ~127 ~97 grass_block
setblock ~152 ~127 ~98 grass_block
setblock ~152 ~127 ~99 dirt
setblock ~152 ~127 ~100 dirt
setblock ~152 ~127 ~101 dirt
setblock ~152 ~127 ~102 grass_block
setblock ~152 ~127 ~103 grass_block
setblock ~152 ~127 ~151 short_grass
setblock ~152 ~127 ~152 short_grass
setblock ~152 ~128 ~45 fern
setblock ~152 ~128 ~48 grass_block
setblock ~152 ~128 ~49 grass_block
setblock ~152 ~128 ~50 dirt
setblock ~152 ~128 ~51 grass_block
setblock ~152 ~128 ~53 short_grass
setblock ~152 ~128 ~78 short_grass
setblock ~152 ~128 ~79 grass_block
setblock ~152 ~128 ~80 grass_block
setblock ~152 ~128 ~98 short_grass
setblock ~152 ~128 ~99 grass_block
setblock ~152 ~128 ~100 dirt
setblock ~152 ~128 ~101 grass_block
setblock ~152 ~129 ~50 grass_block
setblock ~152 ~129 ~99 poppy
setblock ~152 ~129 ~100 grass_block
setblock ~152 ~130 ~50 poppy
setblock ~153 ~122 ~0 dirt
setblock ~153 ~122 ~1 dirt
setblock ~153 ~122 ~2 dirt
setblock ~153 ~122 ~3 dirt
setblock ~153 ~122 ~4 dirt
setblock ~153 ~122 ~5 dirt
setblock ~153 ~122 ~6 dirt
setblock ~153 ~122 ~7 dirt
setblock ~153 ~122 ~8 dirt
setblock ~153 ~122 ~9 dirt
setblock ~153 ~122 ~10 dirt
setblock ~153 ~122 ~11 dirt
setblock ~153 ~122 ~12 dirt
setblock ~153 ~122 ~13 dirt
setblock ~153 ~122 ~14 dirt
setblock ~153 ~122 ~15 dirt
setblock ~153 ~122 ~16 dirt
setblock ~153 ~122 ~17 dirt
setblock ~153 ~122 ~18 dirt
setblock ~153 ~122 ~19 dirt
setblock ~153 ~122 ~20 dirt
setblock ~153 ~122 ~21 dirt
setblock ~153 ~122 ~22 dirt
setblock ~153 ~122 ~23 dirt
setblock ~153 ~122 ~24 dirt
setblock ~153 ~122 ~25 dirt
setblock ~153 ~122 ~26 dirt
setblock ~153 ~122 ~27 dirt
setblock ~153 ~122 ~28 dirt
setblock ~153 ~122 ~29 dirt
setblock ~153 ~122 ~30 dirt
setblock ~153 ~122 ~31 dirt
setblock ~153 ~122 ~32 dirt
setblock ~153 ~122 ~33 dirt
setblock ~153 ~122 ~34 dirt
setblock ~153 ~122 ~35 dirt
setblock ~153 ~122 ~36 dirt
setblock ~153 ~122 ~37 dirt
setblock ~153 ~122 ~38 dirt
setblock ~153 ~122 ~39 dirt
setblock ~153 ~122 ~40 dirt
setblock ~153 ~122 ~41 dirt
setblock ~153 ~122 ~42 dirt
setblock ~153 ~122 ~43 dirt
setblock ~153 ~122 ~44 dirt
setblock ~153 ~122 ~45 dirt
setblock ~153 ~122 ~46 dirt
setblock ~153 ~122 ~47 dirt
setblock ~153 ~122 ~48 dirt
setblock ~153 ~122 ~49 dirt
setblock ~153 ~122 ~50 dirt
setblock ~153 ~122 ~51 dirt
setblock ~153 ~122 ~52 dirt
setblock ~153 ~122 ~53 dirt
setblock ~153 ~122 ~54 dirt
setblock ~153 ~122 ~55 dirt
setblock ~153 ~122 ~56 dirt
setblock ~153 ~122 ~57 dirt
setblock ~153 ~122 ~58 dirt
setblock ~153 ~122 ~59 dirt
setblock ~153 ~122 ~60 dirt
setblock ~153 ~122 ~61 dirt
setblock ~153 ~122 ~62 dirt
setblock ~153 ~122 ~63 dirt
setblock ~153 ~122 ~64 dirt
setblock ~153 ~122 ~65 dirt
setblock ~153 ~122 ~66 dirt
setblock ~153 ~122 ~67 dirt
setblock ~153 ~122 ~68 dirt
setblock ~153 ~122 ~69 dirt
setblock ~153 ~122 ~70 dirt
setblock ~153 ~122 ~71 dirt
setblock ~153 ~122 ~72 dirt
setblock ~153 ~122 ~73 dirt
setblock ~153 ~122 ~74 dirt
setblock ~153 ~122 ~75 dirt
setblock ~153 ~122 ~76 dirt
setblock ~153 ~122 ~77 dirt
setblock ~153 ~122 ~78 dirt
setblock ~153 ~122 ~79 dirt
setblock ~153 ~122 ~80 dirt
setblock ~153 ~122 ~81 dirt
setblock ~153 ~122 ~82 dirt
setblock ~153 ~122 ~83 dirt
setblock ~153 ~122 ~84 dirt
setblock ~153 ~122 ~85 dirt
setblock ~153 ~122 ~86 dirt
setblock ~153 ~122 ~87 dirt
setblock ~153 ~122 ~88 dirt
setblock ~153 ~122 ~89 dirt
setblock ~153 ~122 ~90 dirt
setblock ~153 ~122 ~91 dirt
setblock ~153 ~122 ~92 dirt
setblock ~153 ~122 ~93 dirt
setblock ~153 ~122 ~94 dirt
setblock ~153 ~122 ~95 dirt
setblock ~153 ~122 ~96 dirt
setblock ~153 ~122 ~97 dirt
setblock ~153 ~122 ~98 dirt
setblock ~153 ~122 ~99 dirt
setblock ~153 ~122 ~100 dirt
setblock ~153 ~122 ~101 dirt
setblock ~153 ~122 ~102 dirt
setblock ~153 ~122 ~103 dirt
setblock ~153 ~122 ~104 dirt
setblock ~153 ~122 ~105 dirt
setblock ~153 ~122 ~106 dirt
setblock ~153 ~122 ~107 dirt
setblock ~153 ~122 ~108 dirt
setblock ~153 ~122 ~109 dirt
setblock ~153 ~122 ~110 dirt
setblock ~153 ~122 ~111 dirt
setblock ~153 ~122 ~112 dirt
setblock ~153 ~122 ~113 dirt
setblock ~153 ~122 ~114 dirt
setblock ~153 ~122 ~115 dirt
setblock ~153 ~122 ~116 dirt
setblock ~153 ~122 ~117 dirt
setblock ~153 ~122 ~118 dirt
setblock ~153 ~122 ~119 dirt
setblock ~153 ~122 ~120 dirt
setblock ~153 ~122 ~121 dirt
setblock ~153 ~122 ~122 dirt
setblock ~153 ~122 ~123 dirt
setblock ~153 ~122 ~124 dirt
setblock ~153 ~122 ~125 dirt
setblock ~153 ~122 ~126 dirt
setblock ~153 ~122 ~127 dirt
setblock ~153 ~122 ~128 dirt
setblock ~153 ~122 ~129 dirt
setblock ~153 ~122 ~130 dirt
setblock ~153 ~122 ~131 dirt
setblock ~153 ~122 ~132 dirt
setblock ~153 ~122 ~133 dirt
setblock ~153 ~122 ~134 dirt
setblock ~153 ~122 ~135 dirt
setblock ~153 ~122 ~136 dirt
setblock ~153 ~122 ~137 grass_block
setblock ~153 ~122 ~138 grass_block
setblock ~153 ~122 ~139 grass_block
