setblock ~17 ~119 ~120 dirt
setblock ~17 ~120 ~56 dirt
setblock ~17 ~120 ~94 dirt
setblock ~17 ~120 ~95 dirt
setblock ~17 ~120 ~96 dirt
setblock ~17 ~120 ~97 dirt
setblock ~17 ~120 ~98 dirt
setblock ~17 ~120 ~99 dirt
setblock ~17 ~120 ~100 dirt
setblock ~17 ~120 ~101 dirt
setblock ~17 ~120 ~102 dirt
setblock ~17 ~120 ~103 dirt
setblock ~17 ~120 ~104 dirt
setblock ~17 ~120 ~105 dirt
setblock ~17 ~120 ~106 dirt
setblock ~17 ~120 ~107 dirt
setblock ~17 ~120 ~108 dirt
setblock ~17 ~120 ~109 dirt
setblock ~17 ~120 ~110 dirt
setblock ~17 ~120 ~111 dirt
setblock ~17 ~120 ~112 dirt
setblock ~17 ~120 ~113 dirt
setblock ~17 ~120 ~114 dirt
setblock ~17 ~120 ~115 dirt
setblock ~17 ~120 ~116 dirt
setblock ~17 ~120 ~117 dirt
setblock ~17 ~120 ~118 dirt
setblock ~17 ~120 ~119 dirt
setblock ~17 ~120 ~120 dirt
setblock ~17 ~120 ~121 dirt
setblock ~17 ~121 ~55 dirt
setblock ~17 ~121 ~56 dirt
setblock ~17 ~121 ~57 dirt
setblock ~17 ~121 ~94 dirt
setblock ~17 ~121 ~95 dirt
setblock ~17 ~121 ~96 dirt
setblock ~17 ~121 ~97 dirt
setblock ~17 ~121 ~98 dirt
setblock ~17 ~121 ~99 dirt
setblock ~17 ~121 ~100 dirt
setblock ~17 ~121 ~101 dirt
setblock ~17 ~121 ~102 dirt
setblock ~17 ~121 ~103 dirt
setblock ~17 ~121 ~104 dirt
setblock ~17 ~121 ~105 dirt
setblock ~17 ~121 ~106 dirt
setblock ~17 ~121 ~107 dirt
setblock ~17 ~121 ~108 dirt
setblock ~17 ~121 ~109 dirt
setblock ~17 ~121 ~110 dirt
setblock ~17 ~121 ~111 dirt
setblock ~17 ~121 ~112 dirt
setblock ~17 ~121 ~113 dirt
setblock ~17 ~121 ~114 dirt
setblock ~17 ~121 ~115 dirt
setblock ~17 ~121 ~116 dirt
setblock ~17 ~121 ~117 dirt
setblock ~17 ~121 ~118 dirt
setblock ~17 ~121 ~119 dirt
setblock ~17 ~121 ~120 dirt
setblock ~17 ~121 ~121 dirt
setblock ~17 ~122 ~55 dirt
setblock ~17 ~122 ~56 dirt
setblock ~17 ~122 ~57 dirt
setblock ~17 ~122 ~94 dirt
setblock ~17 ~122 ~95 dirt
setblock ~17 ~122 ~96 dirt
setblock ~17 ~122 ~97 dirt
setblock ~17 ~122 ~98 dirt
setblock ~17 ~122 ~99 dirt
setblock ~17 ~122 ~100 dirt
setblock ~17 ~122 ~101 dirt
setblock ~17 ~122 ~102 dirt
setblock ~17 ~122 ~103 dirt
setblock ~17 ~122 ~104 dirt
setblock ~17 ~122 ~105 dirt
setblock ~17 ~122 ~106 dirt
setblock ~17 ~122 ~107 dirt
setblock ~17 ~122 ~108 dirt
setblock ~17 ~122 ~109 dirt
setblock ~17 ~122 ~110 dirt
setblock ~17 ~122 ~111 dirt
setblock ~17 ~122 ~112 dirt
setblock ~17 ~122 ~113 dirt
setblock ~17 ~122 ~114 dirt
setblock ~17 ~122 ~115 dirt
setblock ~17 ~122 ~116 dirt
setblock ~17 ~122 ~117 dirt
setblock ~17 ~122 ~118 dirt
setblock ~17 ~122 ~119 dirt
setblock ~17 ~122 ~120 dirt
setblock ~17 ~122 ~121 dirt
setblock ~17 ~123 ~55 dirt
setblock ~17 ~123 ~56 dirt
setblock ~17 ~123 ~57 dirt
setblock ~17 ~123 ~94 dirt
setblock ~17 ~123 ~95 dirt
setblock ~17 ~123 ~96 dirt
setblock ~17 ~123 ~97 dirt
setblock ~17 ~123 ~98 dirt
setblock ~17 ~123 ~99 dirt
setblock ~17 ~123 ~100 dirt
setblock ~17 ~123 ~101 dirt
setblock ~17 ~123 ~102 dirt
setblock ~17 ~123 ~103 dirt
setblock ~17 ~123 ~104 dirt
setblock ~17 ~123 ~105 dirt
setblock ~17 ~123 ~106 dirt
setblock ~17 ~123 ~107 dirt
setblock ~17 ~123 ~108 dirt
setblock ~17 ~123 ~109 dirt
setblock ~17 ~123 ~110 dirt
setblock ~17 ~123 ~111 dirt
setblock ~17 ~123 ~112 dirt
setblock ~17 ~123 ~113 dirt
setblock ~17 ~123 ~114 dirt
setblock ~17 ~123 ~115 dirt
setblock ~17 ~123 ~116 dirt
setblock ~17 ~123 ~117 dirt
setblock ~17 ~123 ~118 dirt
setblock ~17 ~123 ~119 grass_block
setblock ~17 ~123 ~120 grass_block
setblock ~17 ~123 ~121 grass_block
setblock ~17 ~124 ~55 dirt
setblock ~17 ~124 ~56 dirt
setblock ~17 ~124 ~57 grass_block
setblock ~17 ~124 ~94 dirt
setblock ~17 ~124 ~95 dirt
setblock ~17 ~124 ~96 dirt
setblock ~17 ~124 ~97 grass_block
setblock ~17 ~124 ~98 grass_block
setblock ~17 ~124 ~99 grass_block
setblock ~17 ~124 ~100 grass_block
setblock ~17 ~124 ~101 grass_block
setblock ~17 ~124 ~102 grass_block
setblock ~17 ~124 ~103 grass_block
setblock ~17 ~124 ~104 dirt
setblock ~17 ~124 ~105 dirt
setblock ~17 ~124 ~106 dirt
setblock ~17 ~124 ~107 dirt
setblock ~17 ~124 ~108 dirt
setblock ~17 ~124 ~109 dirt
setblock ~17 ~124 ~110 dirt
setblock ~17 ~124 ~111 dirt
setblock ~17 ~124 ~112 dirt
setblock ~17 ~124 ~113 dirt
setblock ~17 ~124 ~114 dirt
setblock ~17 ~124 ~115 grass_block
setblock ~17 ~124 ~116 grass_block
setblock ~17 ~124 ~117 grass_block
setblock ~17 ~124 ~118 grass_block
setblock ~17 ~124 ~119 short_grass
setblock ~17 ~125 ~55 grass_block
setblock ~17 ~125 ~56 grass_block
setblock ~17 ~125 ~57 short_grass
setblock ~17 ~125 ~94 grass_block
setblock ~17 ~125 ~95 grass_block
setblock ~17 ~125 ~96 grass_block
setblock ~17 ~125 ~102 poppy
setblock ~17 ~125 ~104 grass_block
setblock ~17 ~125 ~105 grass_block
setblock ~17 ~125 ~106 grass_block
setblock ~17 ~125 ~107 grass_block
setblock ~17 ~125 ~108 dirt
setblock ~17 ~125 ~109 dirt
setblock ~17 ~125 ~110 dirt
setblock ~17 ~125 ~111 dirt
setblock ~17 ~125 ~112 grass_block
setblock ~17 ~125 ~113 grass_block
setblock ~17 ~125 ~114 grass_block
setblock ~17 ~125 ~118 short_grass
setblock ~17 ~126 ~106 short_grass
setblock ~17 ~126 ~107 short_grass
setblock ~17 ~126 ~108 grass_block
setblock ~17 ~126 ~109 grass_block
setblock ~17 ~126 ~110 grass_block
setblock ~17 ~126 ~111 grass_block
setblock ~17 ~126 ~113 fern
setblock ~17 ~126 ~114 short_grass
setblock ~17 ~127 ~108 short_grass
setblock ~17 ~127 ~110 fern
setblock ~18 ~105 ~108 dirt
setblock ~18 ~105 ~109 dirt
setblock ~18 ~106 ~106 dirt
setblock ~18 ~106 ~107 dirt
setblock ~18 ~106 ~108 dirt
setblock ~18 ~106 ~109 dirt
setblock ~18 ~106 ~110 dirt
setblock ~18 ~107 ~105 dirt
setblock ~18 ~107 ~106 dirt
setblock ~18 ~107 ~107 dirt
setblock ~18 ~107 ~108 dirt
setblock ~18 ~107 ~109 dirt
setblock ~18 ~107 ~110 dirt
setblock ~18 ~107 ~111 dirt
setblock ~18 ~108 ~105 dirt
setblock ~18 ~108 ~106 dirt
setblock ~18 ~108 ~107 dirt
setblock ~18 ~108 ~108 dirt
setblock ~18 ~108 ~109 dirt
setblock ~18 ~108 ~110 dirt
setblock ~18 ~108 ~111 dirt
setblock ~18 ~108 ~112 dirt
setblock ~18 ~109 ~103 dirt
setblock ~18 ~109 ~104 dirt
setblock ~18 ~109 ~105 dirt
setblock ~18 ~109 ~106 dirt
setblock ~18 ~109 ~107 dirt
setblock ~18 ~109 ~108 dirt
setblock ~18 ~109 ~109 dirt
setblock ~18 ~109 ~110 dirt
setblock ~18 ~109 ~111 dirt
setblock ~18 ~109 ~112 dirt
setblock ~18 ~110 ~102 dirt
setblock ~18 ~110 ~103 dirt
setblock ~18 ~110 ~104 dirt
setblock ~18 ~110 ~105 dirt
setblock ~18 ~110 ~106 dirt
setblock ~18 ~110 ~107 dirt
setblock ~18 ~110 ~108 dirt
setblock ~18 ~110 ~109 dirt
setblock ~18 ~110 ~110 dirt
setblock ~18 ~110 ~111 dirt
setblock ~18 ~110 ~112 dirt
setblock ~18 ~110 ~113 dirt
setblock ~18 ~111 ~101 dirt
setblock ~18 ~111 ~102 dirt
setblock ~18 ~111 ~103 dirt
setblock ~18 ~111 ~104 dirt
setblock ~18 ~111 ~105 dirt
setblock ~18 ~111 ~106 dirt
setblock ~18 ~111 ~107 dirt
setblock ~18 ~111 ~108 dirt
setblock ~18 ~111 ~109 dirt
setblock ~18 ~111 ~110 dirt
setblock ~18 ~111 ~111 dirt
setblock ~18 ~111 ~112 dirt
setblock ~18 ~111 ~113 dirt
setblock ~18 ~111 ~114 dirt
setblock ~18 ~112 ~100 dirt
setblock ~18 ~112 ~101 dirt
setblock ~18 ~112 ~102 dirt
setblock ~18 ~112 ~103 dirt
setblock ~18 ~112 ~104 dirt
setblock ~18 ~112 ~105 dirt
setblock ~18 ~112 ~106 dirt
setblock ~18 ~112 ~107 dirt
setblock ~18 ~112 ~108 dirt
setblock ~18 ~112 ~109 dirt
setblock ~18 ~112 ~110 dirt
setblock ~18 ~112 ~111 dirt
setblock ~18 ~112 ~112 dirt
setblock ~18 ~112 ~113 dirt
setblock ~18 ~112 ~114 dirt
setblock ~18 ~112 ~115 dirt
setblock ~18 ~113 ~99 dirt
setblock ~18 ~113 ~100 dirt
setblock ~18 ~113 ~101 dirt
setblock ~18 ~113 ~102 dirt
setblock ~18 ~113 ~103 dirt
setblock ~18 ~113 ~104 dirt
setblock ~18 ~113 ~105 dirt
setblock ~18 ~113 ~106 dirt
setblock ~18 ~113 ~107 dirt
setblock ~18 ~113 ~108 dirt
setblock ~18 ~113 ~109 dirt
setblock ~18 ~113 ~110 dirt
setblock ~18 ~113 ~111 dirt
setblock ~18 ~113 ~112 dirt
setblock ~18 ~113 ~113 dirt
setblock ~18 ~113 ~114 dirt
setblock ~18 ~113 ~115 dirt
setblock ~18 ~114 ~98 dirt
setblock ~18 ~114 ~99 dirt
setblock ~18 ~114 ~100 dirt
setblock ~18 ~114 ~101 dirt
setblock ~18 ~114 ~102 dirt
setblock ~18 ~114 ~103 dirt
setblock ~18 ~114 ~104 dirt
setblock ~18 ~114 ~105 dirt
setblock ~18 ~114 ~106 dirt
setblock ~18 ~114 ~107 dirt
setblock ~18 ~114 ~108 dirt
setblock ~18 ~114 ~109 dirt
setblock ~18 ~114 ~110 dirt
setblock ~18 ~114 ~111 dirt
setblock ~18 ~114 ~112 dirt
setblock ~18 ~114 ~113 dirt
setblock ~18 ~114 ~114 dirt
setblock ~18 ~114 ~115 dirt
setblock ~18 ~114 ~116 dirt
setblock ~18 ~115 ~97 dirt
setblock ~18 ~115 ~98 dirt
setblock ~18 ~115 ~99 dirt
setblock ~18 ~115 ~100 dirt
setblock ~18 ~115 ~101 dirt
setblock ~18 ~115 ~102 dirt
setblock ~18 ~115 ~103 dirt
setblock ~18 ~115 ~104 dirt
setblock ~18 ~115 ~105 dirt
setblock ~18 ~115 ~106 dirt
setblock ~18 ~115 ~107 dirt
setblock ~18 ~115 ~108 dirt
setblock ~18 ~115 ~109 dirt
setblock ~18 ~115 ~110 dirt
setblock ~18 ~115 ~111 dirt
setblock ~18 ~115 ~112 dirt
setblock ~18 ~115 ~113 dirt
setblock ~18 ~115 ~114 dirt
setblock ~18 ~115 ~115 dirt
setblock ~18 ~115 ~116 dirt
setblock ~18 ~115 ~117 dirt
setblock ~18 ~116 ~97 dirt
setblock ~18 ~116 ~98 dirt
setblock ~18 ~116 ~99 dirt
setblock ~18 ~116 ~100 dirt
setblock ~18 ~116 ~101 dirt
setblock ~18 ~116 ~102 dirt
setblock ~18 ~116 ~103 dirt
setblock ~18 ~116 ~104 dirt
setblock ~18 ~116 ~105 dirt
setblock ~18 ~116 ~106 dirt
setblock ~18 ~116 ~107 dirt
setblock ~18 ~116 ~108 dirt
setblock ~18 ~116 ~109 dirt
setblock ~18 ~116 ~110 dirt
setblock ~18 ~116 ~111 dirt
setblock ~18 ~116 ~112 dirt
setblock ~18 ~116 ~113 dirt
setblock ~18 ~116 ~114 dirt
setblock ~18 ~116 ~115 dirt
setblock ~18 ~116 ~116 dirt
setblock ~18 ~116 ~117 dirt
setblock ~18 ~116 ~118 dirt
setblock ~18 ~117 ~96 dirt
setblock ~18 ~117 ~97 dirt
setblock ~18 ~117 ~98 dirt
setblock ~18 ~117 ~99 dirt
setblock ~18 ~117 ~100 dirt
setblock ~18 ~117 ~101 dirt
setblock ~18 ~117 ~102 dirt
setblock ~18 ~117 ~103 dirt
setblock ~18 ~117 ~104 dirt
setblock ~18 ~117 ~105 dirt
setblock ~18 ~117 ~106 dirt
setblock ~18 ~117 ~107 dirt
setblock ~18 ~117 ~108 dirt
setblock ~18 ~117 ~109 dirt
setblock ~18 ~117 ~110 dirt
setblock ~18 ~117 ~111 dirt
setblock ~18 ~117 ~112 dirt
setblock ~18 ~117 ~113 dirt
setblock ~18 ~117 ~114 dirt
setblock ~18 ~117 ~115 dirt
setblock ~18 ~117 ~116 dirt
setblock ~18 ~117 ~117 dirt
setblock ~18 ~117 ~118 dirt
setblock ~18 ~117 ~119 dirt
setblock ~18 ~118 ~95 dirt
setblock ~18 ~118 ~96 dirt
setblock ~18 ~118 ~97 dirt
setblock ~18 ~118 ~98 dirt
setblock ~18 ~118 ~99 dirt
setblock ~18 ~118 ~100 dirt
setblock ~18 ~118 ~101 dirt
setblock ~18 ~118 ~102 dirt
setblock ~18 ~118 ~103 dirt
setblock ~18 ~118 ~104 dirt
setblock ~18 ~118 ~105 dirt
setblock ~18 ~118 ~106 dirt
setblock ~18 ~118 ~107 dirt
setblock ~18 ~118 ~108 dirt
setblock ~18 ~118 ~109 dirt
setblock ~18 ~118 ~110 dirt
setblock ~18 ~118 ~111 dirt
setblock ~18 ~118 ~112 dirt
setblock ~18 ~118 ~113 dirt
setblock ~18 ~118 ~114 dirt
setblock ~18 ~118 ~115 dirt
setblock ~18 ~118 ~116 dirt
setblock ~18 ~118 ~117 dirt
setblock ~18 ~118 ~118 dirt
setblock ~18 ~118 ~119 dirt
setblock ~18 ~118 ~120 dirt
setblock ~18 ~119 ~56 dirt
setblock ~18 ~119 ~95 dirt
setblock ~18 ~119 ~96 dirt
setblock ~18 ~119 ~97 dirt
setblock ~18 ~119 ~98 dirt
setblock ~18 ~119 ~99 dirt
setblock ~18 ~119 ~100 dirt
setblock ~18 ~119 ~101 dirt
setblock ~18 ~119 ~102 dirt
setblock ~18 ~119 ~103 dirt
setblock ~18 ~119 ~104 dirt
setblock ~18 ~119 ~105 dirt
setblock ~18 ~119 ~106 dirt
setblock ~18 ~119 ~107 dirt
setblock ~18 ~119 ~108 dirt
setblock ~18 ~119 ~109 dirt
setblock ~18 ~119 ~110 dirt
setblock ~18 ~119 ~111 dirt
setblock ~18 ~119 ~112 dirt
setblock ~18 ~119 ~113 dirt
setblock ~18 ~119 ~114 dirt
setblock ~18 ~119 ~115 dirt
setblock ~18 ~119 ~116 dirt
setblock ~18 ~119 ~117 dirt
setblock ~18 ~119 ~118 dirt
setblock ~18 ~119 ~119 dirt
setblock ~18 ~119 ~120 dirt
setblock ~18 ~119 ~121 dirt
setblock ~18 ~120 ~55 dirt
setblock ~18 ~120 ~56 dirt
setblock ~18 ~120 ~57 dirt
setblock ~18 ~120 ~94 dirt
setblock ~18 ~120 ~95 dirt
setblock ~18 ~120 ~96 dirt
setblock ~18 ~120 ~97 dirt
setblock ~18 ~120 ~98 dirt
setblock ~18 ~120 ~99 dirt
setblock ~18 ~120 ~100 dirt
setblock ~18 ~120 ~101 dirt
setblock ~18 ~120 ~102 dirt
setblock ~18 ~120 ~103 dirt
setblock ~18 ~120 ~104 dirt
setblock ~18 ~120 ~105 dirt
setblock ~18 ~120 ~106 dirt
setblock ~18 ~120 ~107 dirt
setblock ~18 ~120 ~108 dirt
setblock ~18 ~120 ~109 dirt
setblock ~18 ~120 ~110 dirt
setblock ~18 ~120 ~111 dirt
setblock ~18 ~120 ~112 dirt
setblock ~18 ~120 ~113 dirt
setblock ~18 ~120 ~114 dirt
setblock ~18 ~120 ~115 dirt
setblock ~18 ~120 ~116 dirt
setblock ~18 ~120 ~117 dirt
setblock ~18 ~120 ~118 dirt
setblock ~18 ~120 ~119 dirt
setblock ~18 ~120 ~120 dirt
setblock ~18 ~120 ~121 dirt
setblock ~18 ~120 ~122 dirt
setblock ~18 ~121 ~54 dirt
setblock ~18 ~121 ~55 dirt
setblock ~18 ~121 ~56 dirt
setblock ~18 ~121 ~57 dirt
setblock ~18 ~121 ~58 dirt
setblock ~18 ~121 ~93 dirt
setblock ~18 ~121 ~94 dirt
setblock ~18 ~121 ~95 dirt
setblock ~18 ~121 ~96 dirt
setblock ~18 ~121 ~97 dirt
setblock ~18 ~121 ~98 dirt
setblock ~18 ~121 ~99 dirt
setblock ~18 ~121 ~100 dirt
setblock ~18 ~121 ~101 dirt
setblock ~18 ~121 ~102 dirt
setblock ~18 ~121 ~103 dirt
setblock ~18 ~121 ~104 dirt
setblock ~18 ~121 ~105 dirt
setblock ~18 ~121 ~106 dirt
setblock ~18 ~121 ~107 dirt
setblock ~18 ~121 ~108 dirt
setblock ~18 ~121 ~109 dirt
setblock ~18 ~121 ~110 dirt
setblock ~18 ~121 ~111 dirt
setblock ~18 ~121 ~112 dirt
setblock ~18 ~121 ~113 dirt
setblock ~18 ~121 ~114 dirt
setblock ~18 ~121 ~115 dirt
setblock ~18 ~121 ~116 dirt
setblock ~18 ~121 ~117 dirt
setblock ~18 ~121 ~118 dirt
setblock ~18 ~121 ~119 dirt
setblock ~18 ~121 ~120 dirt
setblock ~18 ~121 ~121 dirt
setblock ~18 ~121 ~122 dirt
setblock ~18 ~122 ~54 dirt
setblock ~18 ~122 ~55 dirt
setblock ~18 ~122 ~56 dirt
setblock ~18 ~122 ~57 dirt
setblock ~18 ~122 ~58 dirt
setblock ~18 ~122 ~93 dirt
setblock ~18 ~122 ~94 dirt
setblock ~18 ~122 ~95 dirt
setblock ~18 ~122 ~96 dirt
setblock ~18 ~122 ~97 dirt
setblock ~18 ~122 ~98 dirt
setblock ~18 ~122 ~99 dirt
setblock ~18 ~122 ~100 dirt
setblock ~18 ~122 ~101 dirt
setblock ~18 ~122 ~102 dirt
setblock ~18 ~122 ~103 dirt
setblock ~18 ~122 ~104 dirt
setblock ~18 ~122 ~105 dirt
setblock ~18 ~122 ~106 dirt
setblock ~18 ~122 ~107 dirt
setblock ~18 ~122 ~108 dirt
setblock ~18 ~122 ~109 dirt
setblock ~18 ~122 ~110 dirt
setblock ~18 ~122 ~111 dirt
setblock ~18 ~122 ~112 dirt
setblock ~18 ~122 ~113 dirt
setblock ~18 ~122 ~114 dirt
setblock ~18 ~122 ~115 dirt
setblock ~18 ~122 ~116 dirt
setblock ~18 ~122 ~117 dirt
setblock ~18 ~122 ~118 dirt
setblock ~18 ~122 ~119 dirt
setblock ~18 ~122 ~120 dirt
setblock ~18 ~122 ~121 dirt
setblock ~18 ~122 ~122 dirt
setblock ~18 ~123 ~54 dirt
setblock ~18 ~123 ~55 dirt
setblock ~18 ~123 ~56 dirt
setblock ~18 ~123 ~57 dirt
setblock ~18 ~123 ~58 dirt
setblock ~18 ~123 ~93 dirt
setblock ~18 ~123 ~94 dirt
setblock ~18 ~123 ~95 dirt
setblock ~18 ~123 ~96 dirt
setblock ~18 ~123 ~97 dirt
setblock ~18 ~123 ~98 dirt
setblock ~18 ~123 ~99 dirt
setblock ~18 ~123 ~100 dirt
setblock ~18 ~123 ~101 dirt
setblock ~18 ~123 ~102 dirt
setblock ~18 ~123 ~103 dirt
setblock ~18 ~123 ~104 dirt
setblock ~18 ~123 ~105 dirt
setblock ~18 ~123 ~106 dirt
setblock ~18 ~123 ~107 dirt
setblock ~18 ~123 ~108 dirt
setblock ~18 ~123 ~109 dirt
setblock ~18 ~123 ~110 dirt
setblock ~18 ~123 ~111 dirt
setblock ~18 ~123 ~112 dirt
setblock ~18 ~123 ~113 dirt
setblock ~18 ~123 ~114 dirt
setblock ~18 ~123 ~115 dirt
setblock ~18 ~123 ~116 dirt
setblock ~18 ~123 ~117 dirt
setblock ~18 ~123 ~118 grass_block
setblock ~18 ~123 ~119 grass_block
setblock ~18 ~123 ~120 grass_block
setblock ~18 ~123 ~121 grass_block
setblock ~18 ~123 ~122 grass_block
setblock ~18 ~124 ~54 dirt
setblock ~18 ~124 ~55 grass_block
setblock ~18 ~124 ~56 grass_block
setblock ~18 ~124 ~57 grass_block
setblock ~18 ~124 ~58 grass_block
setblock ~18 ~124 ~93 dirt
setblock ~18 ~124 ~94 dirt
setblock ~18 ~124 ~95 dirt
setblock ~18 ~124 ~96 dirt
setblock ~18 ~124 ~97 dirt
setblock ~18 ~124 ~98 grass_block
setblock ~18 ~124 ~99 grass_block
setblock ~18 ~124 ~100 grass_block
setblock ~18 ~124 ~101 grass_block
setblock ~18 ~124 ~102 grass_block
setblock ~18 ~124 ~103 dirt
setblock ~18 ~124 ~104 dirt
setblock ~18 ~124 ~105 dirt
setblock ~18 ~124 ~106 dirt
setblock ~18 ~124 ~107 dirt
setblock ~18 ~124 ~108 dirt
setblock ~18 ~124 ~109 dirt
setblock ~18 ~124 ~110 dirt
setblock ~18 ~124 ~111 dirt
setblock ~18 ~124 ~112 dirt
setblock ~18 ~124 ~113 dirt
setblock ~18 ~124 ~114 dirt
setblock ~18 ~124 ~115 grass_block
setblock ~18 ~124 ~116 grass_block
setblock ~18 ~124 ~117 grass_block
setblock ~18 ~124 ~118 poppy
setblock ~18 ~124 ~119 short_grass
setblock ~18 ~125 ~54 grass_block
setblock ~18 ~125 ~58 fern
setblock ~18 ~125 ~93 dirt
setblock ~18 ~125 ~94 grass_block
setblock ~18 ~125 ~95 grass_block
setblock ~18 ~125 ~96 grass_block
setblock ~18 ~125 ~97 grass_block
setblock ~18 ~125 ~98 short_grass
setblock ~18 ~125 ~101 short_grass
setblock ~18 ~125 ~103 grass_block
setblock ~18 ~125 ~104 grass_block
setblock ~18 ~125 ~105 grass_block
setblock ~18 ~125 ~106 grass_block
setblock ~18 ~125 ~107 dirt
setblock ~18 ~125 ~108 dirt
setblock ~18 ~125 ~109 dirt
setblock ~18 ~125 ~110 dirt
setblock ~18 ~125 ~111 dirt
setblock ~18 ~125 ~112 dirt
setblock ~18 ~125 ~113 grass_block
setblock ~18 ~125 ~114 grass_block
setblock ~18 ~126 ~93 grass_block
setblock ~18 ~126 ~97 short_grass
setblock ~18 ~126 ~106 short_grass
setblock ~18 ~126 ~107 grass_block
setblock ~18 ~126 ~108 grass_block
setblock ~18 ~126 ~109 grass_block
setblock ~18 ~126 ~110 grass_block
setblock ~18 ~126 ~111 grass_block
setblock ~18 ~126 ~112 grass_block
setblock ~18 ~127 ~93 fern
setblock ~18 ~127 ~112 short_grass
setblock ~19 ~103 ~108 dirt
setblock ~19 ~104 ~108 dirt
setblock ~19 ~104 ~109 dirt
setblock ~19 ~105 ~106 dirt
setblock ~19 ~105 ~107 dirt
setblock ~19 ~105 ~108 dirt
setblock ~19 ~105 ~109 dirt
setblock ~19 ~105 ~110 dirt
setblock ~19 ~106 ~105 dirt
setblock ~19 ~106 ~106 dirt
setblock ~19 ~106 ~107 dirt
setblock ~19 ~106 ~108 dirt
setblock ~19 ~106 ~109 dirt
setblock ~19 ~106 ~110 dirt
setblock ~19 ~106 ~111 dirt
setblock ~19 ~107 ~104 dirt
setblock ~19 ~107 ~105 dirt
setblock ~19 ~107 ~106 dirt
setblock ~19 ~107 ~107 dirt
setblock ~19 ~107 ~108 dirt
setblock ~19 ~107 ~109 dirt
setblock ~19 ~107 ~110 dirt
setblock ~19 ~107 ~111 dirt
setblock ~19 ~107 ~112 dirt
setblock ~19 ~108 ~103 dirt
setblock ~19 ~108 ~104 dirt
setblock ~19 ~108 ~105 dirt
setblock ~19 ~108 ~106 dirt
setblock ~19 ~108 ~107 dirt
setblock ~19 ~108 ~108 dirt
setblock ~19 ~108 ~109 dirt
setblock ~19 ~108 ~110 dirt
setblock ~19 ~108 ~111 dirt
setblock ~19 ~108 ~112 dirt
setblock ~19 ~109 ~102 dirt
setblock ~19 ~109 ~103 dirt
setblock ~19 ~109 ~104 dirt
setblock ~19 ~109 ~105 dirt
setblock ~19 ~109 ~106 dirt
setblock ~19 ~109 ~107 dirt
setblock ~19 ~109 ~108 dirt
setblock ~19 ~109 ~109 dirt
setblock ~19 ~109 ~110 dirt
setblock ~19 ~109 ~111 dirt
setblock ~19 ~109 ~112 dirt
setblock ~19 ~109 ~113 dirt
setblock ~19 ~110 ~101 dirt
setblock ~19 ~110 ~102 dirt
setblock ~19 ~110 ~103 dirt
setblock ~19 ~110 ~104 dirt
setblock ~19 ~110 ~105 dirt
setblock ~19 ~110 ~106 dirt
setblock ~19 ~110 ~107 dirt
setblock ~19 ~110 ~108 dirt
setblock ~19 ~110 ~109 dirt
setblock ~19 ~110 ~110 dirt
setblock ~19 ~110 ~111 dirt
setblock ~19 ~110 ~112 dirt
setblock ~19 ~110 ~113 dirt
setblock ~19 ~110 ~114 dirt
setblock ~19 ~111 ~101 dirt
setblock ~19 ~111 ~102 dirt
setblock ~19 ~111 ~103 dirt
setblock ~19 ~111 ~104 dirt
setblock ~19 ~111 ~105 dirt
setblock ~19 ~111 ~106 dirt
setblock ~19 ~111 ~107 dirt
setblock ~19 ~111 ~108 dirt
setblock ~19 ~111 ~109 dirt
setblock ~19 ~111 ~110 dirt
setblock ~19 ~111 ~111 dirt
setblock ~19 ~111 ~112 dirt
setblock ~19 ~111 ~113 dirt
setblock ~19 ~111 ~114 dirt
setblock ~19 ~111 ~115 dirt
setblock ~19 ~112 ~100 dirt
setblock ~19 ~112 ~101 dirt
setblock ~19 ~112 ~102 dirt
setblock ~19 ~112 ~103 dirt
setblock ~19 ~112 ~104 dirt
setblock ~19 ~112 ~105 dirt
setblock ~19 ~112 ~106 dirt
setblock ~19 ~112 ~107 dirt
setblock ~19 ~112 ~108 dirt
setblock ~19 ~112 ~109 dirt
setblock ~19 ~112 ~110 dirt
setblock ~19 ~112 ~111 dirt
setblock ~19 ~112 ~112 dirt
setblock ~19 ~112 ~113 dirt
setblock ~19 ~112 ~114 dirt
setblock ~19 ~112 ~115 dirt
setblock ~19 ~113 ~99 dirt
setblock ~19 ~113 ~100 dirt
setblock ~19 ~113 ~101 dirt
setblock ~19 ~113 ~102 dirt
setblock ~19 ~113 ~103 dirt
setblock ~19 ~113 ~104 dirt
setblock ~19 ~113 ~105 dirt
setblock ~19 ~113 ~106 dirt
setblock ~19 ~113 ~107 dirt
setblock ~19 ~113 ~108 dirt
setblock ~19 ~113 ~109 dirt
setblock ~19 ~113 ~110 dirt
setblock ~19 ~113 ~111 dirt
setblock ~19 ~113 ~112 dirt
setblock ~19 ~113 ~113 dirt
setblock ~19 ~113 ~114 dirt
setblock ~19 ~113 ~115 dirt
setblock ~19 ~113 ~116 dirt
setblock ~19 ~114 ~98 dirt
setblock ~19 ~114 ~99 dirt
setblock ~19 ~114 ~100 dirt
setblock ~19 ~114 ~101 dirt
setblock ~19 ~114 ~102 dirt
setblock ~19 ~114 ~103 dirt
setblock ~19 ~114 ~104 dirt
setblock ~19 ~114 ~105 dirt
setblock ~19 ~114 ~106 dirt
setblock ~19 ~114 ~107 dirt
setblock ~19 ~114 ~108 dirt
setblock ~19 ~114 ~109 dirt
setblock ~19 ~114 ~110 dirt
setblock ~19 ~114 ~111 dirt
setblock ~19 ~114 ~112 dirt
setblock ~19 ~114 ~113 dirt
setblock ~19 ~114 ~114 dirt
setblock ~19 ~114 ~115 dirt
setblock ~19 ~114 ~116 dirt
setblock ~19 ~114 ~117 dirt
setblock ~19 ~115 ~97 dirt
setblock ~19 ~115 ~98 dirt
setblock ~19 ~115 ~99 dirt
setblock ~19 ~115 ~100 dirt
setblock ~19 ~115 ~101 dirt
setblock ~19 ~115 ~102 dirt
setblock ~19 ~115 ~103 dirt
setblock ~19 ~115 ~104 dirt
setblock ~19 ~115 ~105 dirt
setblock ~19 ~115 ~106 dirt
setblock ~19 ~115 ~107 dirt
setblock ~19 ~115 ~108 dirt
setblock ~19 ~115 ~109 dirt
setblock ~19 ~115 ~110 dirt
setblock ~19 ~115 ~111 dirt
setblock ~19 ~115 ~112 dirt
setblock ~19 ~115 ~113 dirt
setblock ~19 ~115 ~114 dirt
setblock ~19 ~115 ~115 dirt
setblock ~19 ~115 ~116 dirt
setblock ~19 ~115 ~117 dirt
setblock ~19 ~115 ~118 dirt
setblock ~19 ~116 ~97 dirt
setblock ~19 ~116 ~98 dirt
setblock ~19 ~116 ~99 dirt
setblock ~19 ~116 ~100 dirt
setblock ~19 ~116 ~101 dirt
setblock ~19 ~116 ~102 dirt
setblock ~19 ~116 ~103 dirt
setblock ~19 ~116 ~104 dirt
setblock ~19 ~116 ~105 dirt
setblock ~19 ~116 ~106 dirt
setblock ~19 ~116 ~107 dirt
setblock ~19 ~116 ~108 dirt
setblock ~19 ~116 ~109 dirt
setblock ~19 ~116 ~110 dirt
setblock ~19 ~116 ~111 dirt
setblock ~19 ~116 ~112 dirt
setblock ~19 ~116 ~113 dirt
setblock ~19 ~116 ~114 dirt
setblock ~19 ~116 ~115 dirt
setblock ~19 ~116 ~116 dirt
setblock ~19 ~116 ~117 dirt
setblock ~19 ~116 ~118 dirt
setblock ~19 ~116 ~119 dirt
setblock ~19 ~117 ~96 dirt
setblock ~19 ~117 ~97 dirt
setblock ~19 ~117 ~98 dirt
setblock ~19 ~117 ~99 dirt
setblock ~19 ~117 ~100 dirt
setblock ~19 ~117 ~101 dirt
setblock ~19 ~117 ~102 dirt
setblock ~19 ~117 ~103 dirt
setblock ~19 ~117 ~104 dirt
setblock ~19 ~117 ~105 dirt
setblock ~19 ~117 ~106 dirt
setblock ~19 ~117 ~107 dirt
setblock ~19 ~117 ~108 dirt
setblock ~19 ~117 ~109 dirt
setblock ~19 ~117 ~110 dirt
setblock ~19 ~117 ~111 dirt
setblock ~19 ~117 ~112 dirt
setblock ~19 ~117 ~113 dirt
setblock ~19 ~117 ~114 dirt
setblock ~19 ~117 ~115 dirt
setblock ~19 ~117 ~116 dirt
setblock ~19 ~117 ~117 dirt
setblock ~19 ~117 ~118 dirt
setblock ~19 ~117 ~119 dirt
setblock ~19 ~118 ~56 dirt
setblock ~19 ~118 ~95 dirt
setblock ~19 ~118 ~96 dirt
setblock ~19 ~118 ~97 dirt
setblock ~19 ~118 ~98 dirt
setblock ~19 ~118 ~99 dirt
setblock ~19 ~118 ~100 dirt
setblock ~19 ~118 ~101 dirt
setblock ~19 ~118 ~102 dirt
setblock ~19 ~118 ~103 dirt
setblock ~19 ~118 ~104 dirt
setblock ~19 ~118 ~105 dirt
setblock ~19 ~118 ~106 dirt
setblock ~19 ~118 ~107 dirt
setblock ~19 ~118 ~108 dirt
setblock ~19 ~118 ~109 dirt
setblock ~19 ~118 ~110 dirt
setblock ~19 ~118 ~111 dirt
setblock ~19 ~118 ~112 dirt
setblock ~19 ~118 ~113 dirt
setblock ~19 ~118 ~114 dirt
setblock ~19 ~118 ~115 dirt
setblock ~19 ~118 ~116 dirt
setblock ~19 ~118 ~117 dirt
setblock ~19 ~118 ~118 dirt
setblock ~19 ~118 ~119 dirt
setblock ~19 ~118 ~120 dirt
setblock ~19 ~119 ~55 dirt
setblock ~19 ~119 ~56 dirt
setblock ~19 ~119 ~57 dirt
setblock ~19 ~119 ~95 dirt
setblock ~19 ~119 ~96 dirt
setblock ~19 ~119 ~97 dirt
setblock ~19 ~119 ~98 dirt
setblock ~19 ~119 ~99 dirt
setblock ~19 ~119 ~100 dirt
setblock ~19 ~119 ~101 dirt
setblock ~19 ~119 ~102 dirt
setblock ~19 ~119 ~103 dirt
setblock ~19 ~119 ~104 dirt
setblock ~19 ~119 ~105 dirt
setblock ~19 ~119 ~106 dirt
setblock ~19 ~119 ~107 dirt
setblock ~19 ~119 ~108 dirt
setblock ~19 ~119 ~109 dirt
setblock ~19 ~119 ~110 dirt
setblock ~19 ~119 ~111 dirt
setblock ~19 ~119 ~112 dirt
setblock ~19 ~119 ~113 dirt
setblock ~19 ~119 ~114 dirt
setblock ~19 ~119 ~115 dirt
setblock ~19 ~119 ~116 dirt
setblock ~19 ~119 ~117 dirt
setblock ~19 ~119 ~118 dirt
setblock ~19 ~119 ~119 dirt
setblock ~19 ~119 ~120 dirt
setblock ~19 ~119 ~121 dirt
setblock ~19 ~120 ~55 dirt
setblock ~19 ~120 ~56 dirt
setblock ~19 ~120 ~57 dirt
setblock ~19 ~120 ~58 dirt
setblock ~19 ~120 ~94 dirt
setblock ~19 ~120 ~95 dirt
setblock ~19 ~120 ~96 dirt
setblock ~19 ~120 ~97 dirt
setblock ~19 ~120 ~98 dirt
setblock ~19 ~120 ~99 dirt
setblock ~19 ~120 ~100 dirt
setblock ~19 ~120 ~101 dirt
setblock ~19 ~120 ~102 dirt
setblock ~19 ~120 ~103 dirt
setblock ~19 ~120 ~104 dirt
setblock ~19 ~120 ~105 dirt
setblock ~19 ~120 ~106 dirt
setblock ~19 ~120 ~107 dirt
setblock ~19 ~120 ~108 dirt
setblock ~19 ~120 ~109 dirt
setblock ~19 ~120 ~110 dirt
setblock ~19 ~120 ~111 dirt
setblock ~19 ~120 ~112 dirt
setblock ~19 ~120 ~113 dirt
setblock ~19 ~120 ~114 dirt
setblock ~19 ~120 ~115 dirt
setblock ~19 ~120 ~116 dirt
setblock ~19 ~120 ~117 dirt
setblock ~19 ~120 ~118 dirt
setblock ~19 ~120 ~119 dirt
setblock ~19 ~120 ~120 dirt
setblock ~19 ~120 ~121 dirt
setblock ~19 ~121 ~54 dirt
setblock ~19 ~121 ~55 dirt
setblock ~19 ~121 ~56 dirt
setblock ~19 ~121 ~57 dirt
setblock ~19 ~121 ~58 dirt
setblock ~19 ~121 ~59 dirt
setblock ~19 ~121 ~93 dirt
setblock ~19 ~121 ~94 dirt
setblock ~19 ~121 ~95 dirt
setblock ~19 ~121 ~96 dirt
setblock ~19 ~121 ~97 dirt
setblock ~19 ~121 ~98 dirt
setblock ~19 ~121 ~99 dirt
setblock ~19 ~121 ~100 dirt
setblock ~19 ~121 ~101 dirt
setblock ~19 ~121 ~102 dirt
setblock ~19 ~121 ~103 dirt
setblock ~19 ~121 ~104 dirt
setblock ~19 ~121 ~105 dirt
setblock ~19 ~121 ~106 dirt
setblock ~19 ~121 ~107 dirt
setblock ~19 ~121 ~108 dirt
setblock ~19 ~121 ~109 dirt
setblock ~19 ~121 ~110 dirt
setblock ~19 ~121 ~111 dirt
setblock ~19 ~121 ~112 dirt
setblock ~19 ~121 ~113 dirt
setblock ~19 ~121 ~114 dirt
setblock ~19 ~121 ~115 dirt
setblock ~19 ~121 ~116 dirt
setblock ~19 ~121 ~117 dirt
setblock ~19 ~121 ~118 dirt
setblock ~19 ~121 ~119 dirt
setblock ~19 ~121 ~120 dirt
setblock ~19 ~121 ~121 dirt
setblock ~19 ~121 ~122 dirt
setblock ~19 ~122 ~54 dirt
setblock ~19 ~122 ~55 dirt
setblock ~19 ~122 ~56 dirt
setblock ~19 ~122 ~57 dirt
setblock ~19 ~122 ~58 dirt
setblock ~19 ~122 ~59 dirt
setblock ~19 ~122 ~93 dirt
setblock ~19 ~122 ~94 dirt
setblock ~19 ~122 ~95 dirt
setblock ~19 ~122 ~96 dirt
setblock ~19 ~122 ~97 dirt
setblock ~19 ~122 ~98 dirt
setblock ~19 ~122 ~99 dirt
setblock ~19 ~122 ~100 dirt
setblock ~19 ~122 ~101 dirt
setblock ~19 ~122 ~102 dirt
setblock ~19 ~122 ~103 dirt
setblock ~19 ~122 ~104 dirt
setblock ~19 ~122 ~105 dirt
setblock ~19 ~122 ~106 dirt
setblock ~19 ~122 ~107 dirt
setblock ~19 ~122 ~108 dirt
setblock ~19 ~122 ~109 dirt
setblock ~19 ~122 ~110 dirt
setblock ~19 ~122 ~111 dirt
setblock ~19 ~122 ~112 dirt
setblock ~19 ~122 ~113 dirt
setblock ~19 ~122 ~114 dirt
setblock ~19 ~122 ~115 dirt
setblock ~19 ~122 ~116 dirt
setblock ~19 ~122 ~117 dirt
setblock ~19 ~122 ~118 dirt
setblock ~19 ~122 ~119 dirt
setblock ~19 ~122 ~120 dirt
setblock ~19 ~122 ~121 dirt
setblock ~19 ~122 ~122 dirt
setblock ~19 ~123 ~54 dirt
setblock ~19 ~123 ~55 dirt
setblock ~19 ~123 ~56 dirt
setblock ~19 ~123 ~57 dirt
setblock ~19 ~123 ~58 dirt
setblock ~19 ~123 ~59 grass_block
setblock ~19 ~123 ~93 dirt
setblock ~19 ~123 ~94 dirt
setblock ~19 ~123 ~95 dirt
setblock ~19 ~123 ~96 dirt
setblock ~19 ~123 ~97 dirt
setblock ~19 ~123 ~98 dirt
setblock ~19 ~123 ~99 dirt
setblock ~19 ~123 ~100 dirt
setblock ~19 ~123 ~101 dirt
setblock ~19 ~123 ~102 dirt
setblock ~19 ~123 ~103 dirt
setblock ~19 ~123 ~104 dirt
setblock ~19 ~123 ~105 dirt
setblock ~19 ~123 ~106 dirt
setblock ~19 ~123 ~107 dirt
setblock ~19 ~123 ~108 dirt
setblock ~19 ~123 ~109 dirt
setblock ~19 ~123 ~110 dirt
setblock ~19 ~123 ~111 dirt
setblock ~19 ~123 ~112 dirt
setblock ~19 ~123 ~113 dirt
setblock ~19 ~123 ~114 dirt
setblock ~19 ~123 ~115 dirt
setblock ~19 ~123 ~116 dirt
setblock ~19 ~123 ~117 grass_block
setblock ~19 ~123 ~118 grass_block
setblock ~19 ~123 ~119 grass_block
setblock ~19 ~123 ~120 grass_block
setblock ~19 ~123 ~121 grass_block
setblock ~19 ~123 ~122 grass_block
setblock ~19 ~124 ~54 grass_block
setblock ~19 ~124 ~55 grass_block
setblock ~19 ~124 ~56 grass_block
setblock ~19 ~124 ~57 grass_block
setblock ~19 ~124 ~58 grass_block
setblock ~19 ~124 ~59 short_grass
setblock ~19 ~124 ~93 dirt
setblock ~19 ~124 ~94 dirt
setblock ~19 ~124 ~95 dirt
setblock ~19 ~124 ~96 dirt
setblock ~19 ~124 ~97 dirt
setblock ~19 ~124 ~98 dirt
setblock ~19 ~124 ~99 grass_block
setblock ~19 ~124 ~100 grass_block
setblock ~19 ~124 ~101 grass_block
setblock ~19 ~124 ~102 dirt
setblock ~19 ~124 ~103 dirt
setblock ~19 ~124 ~104 dirt
setblock ~19 ~124 ~105 dirt
setblock ~19 ~124 ~106 dirt
setblock ~19 ~124 ~107 dirt
setblock ~19 ~124 ~108 dirt
setblock ~19 ~124 ~109 dirt
setblock ~19 ~124 ~110 dirt
setblock ~19 ~124 ~111 dirt
setblock ~19 ~124 ~112 dirt
setblock ~19 ~124 ~113 dirt
setblock ~19 ~124 ~114 dirt
setblock ~19 ~124 ~115 grass_block
setblock ~19 ~124 ~116 grass_block
setblock ~19 ~124 ~117 short_grass
setblock ~19 ~125 ~93 dirt
setblock ~19 ~125 ~94 grass_block
setblock ~19 ~125 ~95 grass_block
setblock ~19 ~125 ~96 grass_block
setblock ~19 ~125 ~97 grass_block
setblock ~19 ~125 ~98 grass_block
setblock ~19 ~125 ~100 short_grass
setblock ~19 ~125 ~102 grass_block
setblock ~19 ~125 ~103 grass_block
setblock ~19 ~125 ~104 grass_block
setblock ~19 ~125 ~105 grass_block
setblock ~19 ~125 ~106 dirt
setblock ~19 ~125 ~107 dirt
setblock ~19 ~125 ~108 dirt
setblock ~19 ~125 ~109 dirt
setblock ~19 ~125 ~110 dirt
setblock ~19 ~125 ~111 dirt
setblock ~19 ~125 ~112 grass_block
setblock ~19 ~125 ~113 grass_block
setblock ~19 ~125 ~114 grass_block
setblock ~19 ~126 ~93 grass_block
setblock ~19 ~126 ~94 poppy
setblock ~19 ~126 ~104 fern
setblock ~19 ~126 ~106 grass_block
setblock ~19 ~126 ~107 grass_block
setblock ~19 ~126 ~108 grass_block
setblock ~19 ~126 ~109 grass_block
setblock ~19 ~126 ~110 grass_block
setblock ~19 ~126 ~111 grass_block
setblock ~19 ~126 ~112 short_grass
setblock ~19 ~126 ~114 short_grass
setblock ~19 ~127 ~93 short_grass
setblock ~19 ~127 ~109 short_grass
setblock ~20 ~102 ~108 dirt
setblock ~20 ~103 ~107 dirt
setblock ~20 ~103 ~108 dirt
setblock ~20 ~103 ~109 dirt
setblock ~20 ~104 ~106 dirt
setblock ~20 ~104 ~107 dirt
setblock ~20 ~104 ~108 dirt
setblock ~20 ~104 ~109 dirt
setblock ~20 ~104 ~110 dirt
setblock ~20 ~105 ~105 dirt
setblock ~20 ~105 ~106 dirt
setblock ~20 ~105 ~107 dirt
setblock ~20 ~105 ~108 dirt
setblock ~20 ~105 ~109 dirt
setblock ~20 ~105 ~110 dirt
setblock ~20 ~105 ~111 dirt
setblock ~20 ~106 ~104 dirt
setblock ~20 ~106 ~105 dirt
setblock ~20 ~106 ~106 dirt
setblock ~20 ~106 ~107 dirt
setblock ~20 ~106 ~108 dirt
setblock ~20 ~106 ~109 dirt
setblock ~20 ~106 ~110 dirt
setblock ~20 ~106 ~111 dirt
setblock ~20 ~106 ~112 dirt
setblock ~20 ~107 ~103 dirt
setblock ~20 ~107 ~104 dirt
setblock ~20 ~107 ~105 dirt
setblock ~20 ~107 ~106 dirt
setblock ~20 ~107 ~107 dirt
setblock ~20 ~107 ~108 dirt
setblock ~20 ~107 ~109 dirt
setblock ~20 ~107 ~110 dirt
setblock ~20 ~107 ~111 dirt
setblock ~20 ~107 ~112 dirt
setblock ~20 ~108 ~102 dirt
setblock ~20 ~108 ~103 dirt
setblock ~20 ~108 ~104 dirt
setblock ~20 ~108 ~105 dirt
setblock ~20 ~108 ~106 dirt
setblock ~20 ~108 ~107 dirt
setblock ~20 ~108 ~108 dirt
setblock ~20 ~108 ~109 dirt
setblock ~20 ~108 ~110 dirt
setblock ~20 ~108 ~111 dirt
setblock ~20 ~108 ~112 dirt
setblock ~20 ~108 ~113 dirt
setblock ~20 ~109 ~102 dirt
setblock ~20 ~109 ~103 dirt
setblock ~20 ~109 ~104 dirt
setblock ~20 ~109 ~105 dirt
setblock ~20 ~109 ~106 dirt
setblock ~20 ~109 ~107 dirt
setblock ~20 ~109 ~108 dirt
setblock ~20 ~109 ~109 dirt
setblock ~20 ~109 ~110 dirt
setblock ~20 ~109 ~111 dirt
setblock ~20 ~109 ~112 dirt
setblock ~20 ~109 ~113 dirt
setblock ~20 ~110 ~101 dirt
setblock ~20 ~110 ~102 dirt
setblock ~20 ~110 ~103 dirt
setblock ~20 ~110 ~104 dirt
setblock ~20 ~110 ~105 dirt
setblock ~20 ~110 ~106 dirt
setblock ~20 ~110 ~107 dirt
setblock ~20 ~110 ~108 dirt
setblock ~20 ~110 ~109 dirt
setblock ~20 ~110 ~110 dirt
setblock ~20 ~110 ~111 dirt
setblock ~20 ~110 ~112 dirt
setblock ~20 ~110 ~113 dirt
setblock ~20 ~110 ~114 dirt
setblock ~20 ~111 ~101 dirt
setblock ~20 ~111 ~102 dirt
setblock ~20 ~111 ~103 dirt
setblock ~20 ~111 ~104 dirt
setblock ~20 ~111 ~105 dirt
setblock ~20 ~111 ~106 dirt
setblock ~20 ~111 ~107 dirt
setblock ~20 ~111 ~108 dirt
setblock ~20 ~111 ~109 dirt
setblock ~20 ~111 ~110 dirt
setblock ~20 ~111 ~111 dirt
setblock ~20 ~111 ~112 dirt
setblock ~20 ~111 ~113 dirt
setblock ~20 ~111 ~114 dirt
setblock ~20 ~111 ~115 dirt
setblock ~20 ~112 ~100 dirt
setblock ~20 ~112 ~101 dirt
setblock ~20 ~112 ~102 dirt
setblock ~20 ~112 ~103 dirt
setblock ~20 ~112 ~104 dirt
setblock ~20 ~112 ~105 dirt
setblock ~20 ~112 ~106 dirt
setblock ~20 ~112 ~107 dirt
setblock ~20 ~112 ~108 dirt
setblock ~20 ~112 ~109 dirt
setblock ~20 ~112 ~110 dirt
setblock ~20 ~112 ~111 dirt
setblock ~20 ~112 ~112 dirt
setblock ~20 ~112 ~113 dirt
setblock ~20 ~112 ~114 dirt
setblock ~20 ~112 ~115 dirt
setblock ~20 ~112 ~116 dirt
setblock ~20 ~113 ~99 dirt
setblock ~20 ~113 ~100 dirt
setblock ~20 ~113 ~101 dirt
setblock ~20 ~113 ~102 dirt
setblock ~20 ~113 ~103 dirt
setblock ~20 ~113 ~104 dirt
setblock ~20 ~113 ~105 dirt
setblock ~20 ~113 ~106 dirt
setblock ~20 ~113 ~107 dirt
setblock ~20 ~113 ~108 dirt
setblock ~20 ~113 ~109 dirt
setblock ~20 ~113 ~110 dirt
setblock ~20 ~113 ~111 dirt
setblock ~20 ~113 ~112 dirt
setblock ~20 ~113 ~113 dirt
setblock ~20 ~113 ~114 dirt
setblock ~20 ~113 ~115 dirt
setblock ~20 ~113 ~116 dirt
setblock ~20 ~113 ~117 dirt
setblock ~20 ~114 ~99 dirt
setblock ~20 ~114 ~100 dirt
setblock ~20 ~114 ~101 dirt
setblock ~20 ~114 ~102 dirt
setblock ~20 ~114 ~103 dirt
setblock ~20 ~114 ~104 dirt
setblock ~20 ~114 ~105 dirt
setblock ~20 ~114 ~106 dirt
setblock ~20 ~114 ~107 dirt
setblock ~20 ~114 ~108 dirt
setblock ~20 ~114 ~109 dirt
setblock ~20 ~114 ~110 dirt
setblock ~20 ~114 ~111 dirt
setblock ~20 ~114 ~112 dirt
setblock ~20 ~114 ~113 dirt
setblock ~20 ~114 ~114 dirt
setblock ~20 ~114 ~115 dirt
setblock ~20 ~114 ~116 dirt
setblock ~20 ~114 ~117 dirt
setblock ~20 ~114 ~118 dirt
setblock ~20 ~115 ~98 dirt
setblock ~20 ~115 ~99 dirt
setblock ~20 ~115 ~100 dirt
setblock ~20 ~115 ~101 dirt
setblock ~20 ~115 ~102 dirt
setblock ~20 ~115 ~103 dirt
setblock ~20 ~115 ~104 dirt
setblock ~20 ~115 ~105 dirt
setblock ~20 ~115 ~106 dirt
setblock ~20 ~115 ~107 dirt
setblock ~20 ~115 ~108 dirt
setblock ~20 ~115 ~109 dirt
setblock ~20 ~115 ~110 dirt
setblock ~20 ~115 ~111 dirt
setblock ~20 ~115 ~112 dirt
setblock ~20 ~115 ~113 dirt
setblock ~20 ~115 ~114 dirt
setblock ~20 ~115 ~115 dirt
setblock ~20 ~115 ~116 dirt
setblock ~20 ~115 ~117 dirt
setblock ~20 ~115 ~118 dirt
setblock ~20 ~116 ~97 dirt
setblock ~20 ~116 ~98 dirt
setblock ~20 ~116 ~99 dirt
setblock ~20 ~116 ~100 dirt
setblock ~20 ~116 ~101 dirt
setblock ~20 ~116 ~102 dirt
setblock ~20 ~116 ~103 dirt
setblock ~20 ~116 ~104 dirt
setblock ~20 ~116 ~105 dirt
setblock ~20 ~116 ~106 dirt
setblock ~20 ~116 ~107 dirt
setblock ~20 ~116 ~108 dirt
setblock ~20 ~116 ~109 dirt
setblock ~20 ~116 ~110 dirt
setblock ~20 ~116 ~111 dirt
setblock ~20 ~116 ~112 dirt
setblock ~20 ~116 ~113 dirt
setblock ~20 ~116 ~114 dirt
setblock ~20 ~116 ~115 dirt
setblock ~20 ~116 ~116 dirt
setblock ~20 ~116 ~117 dirt
setblock ~20 ~116 ~118 dirt
setblock ~20 ~116 ~119 dirt
setblock ~20 ~117 ~55 dirt
setblock ~20 ~117 ~56 dirt
setblock ~20 ~117 ~96 dirt
setblock ~20 ~117 ~97 dirt
setblock ~20 ~117 ~98 dirt
setblock ~20 ~117 ~99 dirt
setblock ~20 ~117 ~100 dirt
setblock ~20 ~117 ~101 dirt
setblock ~20 ~117 ~102 dirt
setblock ~20 ~117 ~103 dirt
setblock ~20 ~117 ~104 dirt
setblock ~20 ~117 ~105 dirt
setblock ~20 ~117 ~106 dirt
setblock ~20 ~117 ~107 dirt
setblock ~20 ~117 ~108 dirt
setblock ~20 ~117 ~109 dirt
setblock ~20 ~117 ~110 dirt
setblock ~20 ~117 ~111 dirt
setblock ~20 ~117 ~112 dirt
setblock ~20 ~117 ~113 dirt
setblock ~20 ~117 ~114 dirt
setblock ~20 ~117 ~115 dirt
setblock ~20 ~117 ~116 dirt
setblock ~20 ~117 ~117 dirt
setblock ~20 ~117 ~118 dirt
setblock ~20 ~117 ~119 dirt
setblock ~20 ~117 ~120 dirt
setblock ~20 ~118 ~54 dirt
setblock ~20 ~118 ~55 dirt
setblock ~20 ~118 ~56 dirt
setblock ~20 ~118 ~57 dirt
setblock ~20 ~118 ~95 dirt
setblock ~20 ~118 ~96 dirt
setblock ~20 ~118 ~97 dirt
setblock ~20 ~118 ~98 dirt
setblock ~20 ~118 ~99 dirt
setblock ~20 ~118 ~100 dirt
setblock ~20 ~118 ~101 dirt
setblock ~20 ~118 ~102 dirt
setblock ~20 ~118 ~103 dirt
setblock ~20 ~118 ~104 dirt
setblock ~20 ~118 ~105 dirt
setblock ~20 ~118 ~106 dirt
setblock ~20 ~118 ~107 dirt
setblock ~20 ~118 ~108 dirt
setblock ~20 ~118 ~109 dirt
setblock ~20 ~118 ~110 dirt
setblock ~20 ~118 ~111 dirt
setblock ~20 ~118 ~112 dirt
setblock ~20 ~118 ~113 dirt
setblock ~20 ~118 ~114 dirt
setblock ~20 ~118 ~115 dirt
setblock ~20 ~118 ~116 dirt
setblock ~20 ~118 ~117 dirt
setblock ~20 ~118 ~118 dirt
setblock ~20 ~118 ~119 dirt
setblock ~20 ~118 ~120 dirt
setblock ~20 ~118 ~121 dirt
setblock ~20 ~119 ~53 dirt
setblock ~20 ~119 ~54 dirt
setblock ~20 ~119 ~55 dirt
setblock ~20 ~119 ~56 dirt
setblock ~20 ~119 ~57 dirt
setblock ~20 ~119 ~58 dirt
setblock ~20 ~119 ~94 dirt
setblock ~20 ~119 ~95 dirt
setblock ~20 ~119 ~96 dirt
setblock ~20 ~119 ~97 dirt
setblock ~20 ~119 ~98 dirt
setblock ~20 ~119 ~99 dirt
setblock ~20 ~119 ~100 dirt
setblock ~20 ~119 ~101 dirt
setblock ~20 ~119 ~102 dirt
setblock ~20 ~119 ~103 dirt
setblock ~20 ~119 ~104 dirt
setblock ~20 ~119 ~105 dirt
setblock ~20 ~119 ~106 dirt
setblock ~20 ~119 ~107 dirt
setblock ~20 ~119 ~108 dirt
setblock ~20 ~119 ~109 dirt
setblock ~20 ~119 ~110 dirt
setblock ~20 ~119 ~111 dirt
setblock ~20 ~119 ~112 dirt
setblock ~20 ~119 ~113 dirt
setblock ~20 ~119 ~114 dirt
setblock ~20 ~119 ~115 dirt
setblock ~20 ~119 ~116 dirt
setblock ~20 ~119 ~117 dirt
setblock ~20 ~119 ~118 dirt
setblock ~20 ~119 ~119 dirt
setblock ~20 ~119 ~120 dirt
setblock ~20 ~119 ~121 dirt
setblock ~20 ~120 ~53 dirt
setblock ~20 ~120 ~54 dirt
setblock ~20 ~120 ~55 dirt
setblock ~20 ~120 ~56 dirt
setblock ~20 ~120 ~57 dirt
setblock ~20 ~120 ~58 dirt
setblock ~20 ~120 ~59 dirt
setblock ~20 ~120 ~93 dirt
setblock ~20 ~120 ~94 dirt
setblock ~20 ~120 ~95 dirt
setblock ~20 ~120 ~96 dirt
setblock ~20 ~120 ~97 dirt
setblock ~20 ~120 ~98 dirt
setblock ~20 ~120 ~99 dirt
setblock ~20 ~120 ~100 dirt
setblock ~20 ~120 ~101 dirt
setblock ~20 ~120 ~102 dirt
setblock ~20 ~120 ~103 dirt
setblock ~20 ~120 ~104 dirt
setblock ~20 ~120 ~105 dirt
setblock ~20 ~120 ~106 dirt
setblock ~20 ~120 ~107 dirt
setblock ~20 ~120 ~108 dirt
setblock ~20 ~120 ~109 dirt
setblock ~20 ~120 ~110 dirt
setblock ~20 ~120 ~111 dirt
setblock ~20 ~120 ~112 dirt
setblock ~20 ~120 ~113 dirt
setblock ~20 ~120 ~114 dirt
setblock ~20 ~120 ~115 dirt
setblock ~20 ~120 ~116 dirt
setblock ~20 ~120 ~117 dirt
setblock ~20 ~120 ~118 dirt
setblock ~20 ~120 ~119 dirt
setblock ~20 ~120 ~120 dirt
setblock ~20 ~120 ~121 dirt
setblock ~20 ~120 ~122 dirt
setblock ~20 ~121 ~53 dirt
setblock ~20 ~121 ~54 dirt
setblock ~20 ~121 ~55 dirt
setblock ~20 ~121 ~56 dirt
setblock ~20 ~121 ~57 dirt
setblock ~20 ~121 ~58 dirt
setblock ~20 ~121 ~59 dirt
setblock ~20 ~121 ~60 dirt
setblock ~20 ~121 ~92 dirt
setblock ~20 ~121 ~93 dirt
setblock ~20 ~121 ~94 dirt
setblock ~20 ~121 ~95 dirt
setblock ~20 ~121 ~96 dirt
setblock ~20 ~121 ~97 dirt
setblock ~20 ~121 ~98 dirt
setblock ~20 ~121 ~99 dirt
setblock ~20 ~121 ~100 dirt
setblock ~20 ~121 ~101 dirt
setblock ~20 ~121 ~102 dirt
setblock ~20 ~121 ~103 dirt
setblock ~20 ~121 ~104 dirt
setblock ~20 ~121 ~105 dirt
setblock ~20 ~121 ~106 dirt
setblock ~20 ~121 ~107 dirt
setblock ~20 ~121 ~108 dirt
setblock ~20 ~121 ~109 dirt
setblock ~20 ~121 ~110 dirt
setblock ~20 ~121 ~111 dirt
setblock ~20 ~121 ~112 dirt
setblock ~20 ~121 ~113 dirt
setblock ~20 ~121 ~114 dirt
setblock ~20 ~121 ~115 dirt
setblock ~20 ~121 ~116 dirt
setblock ~20 ~121 ~117 dirt
setblock ~20 ~121 ~118 dirt
setblock ~20 ~121 ~119 dirt
setblock ~20 ~121 ~120 dirt
setblock ~20 ~121 ~121 dirt
setblock ~20 ~121 ~122 dirt
setblock ~20 ~121 ~123 dirt
setblock ~20 ~122 ~53 dirt
setblock ~20 ~122 ~54 dirt
setblock ~20 ~122 ~55 dirt
setblock ~20 ~122 ~56 dirt
setblock ~20 ~122 ~57 dirt
setblock ~20 ~122 ~58 dirt
setblock ~20 ~122 ~59 dirt
setblock ~20 ~122 ~60 dirt
setblock ~20 ~122 ~92 dirt
setblock ~20 ~122 ~93 dirt
setblock ~20 ~122 ~94 dirt
setblock ~20 ~122 ~95 dirt
setblock ~20 ~122 ~96 dirt
setblock ~20 ~122 ~97 dirt
setblock ~20 ~122 ~98 dirt
setblock ~20 ~122 ~99 dirt
setblock ~20 ~122 ~100 dirt
setblock ~20 ~122 ~101 dirt
setblock ~20 ~122 ~102 dirt
setblock ~20 ~122 ~103 dirt
setblock ~20 ~122 ~104 dirt
setblock ~20 ~122 ~105 dirt
setblock ~20 ~122 ~106 dirt
setblock ~20 ~122 ~107 dirt
setblock ~20 ~122 ~108 dirt
setblock ~20 ~122 ~109 dirt
setblock ~20 ~122 ~110 dirt
setblock ~20 ~122 ~111 dirt
setblock ~20 ~122 ~112 dirt
setblock ~20 ~122 ~113 dirt
setblock ~20 ~122 ~114 dirt
setblock ~20 ~122 ~115 dirt
setblock ~20 ~122 ~116 dirt
setblock ~20 ~122 ~117 dirt
setblock ~20 ~122 ~118 dirt
setblock ~20 ~122 ~119 dirt
setblock ~20 ~122 ~120 grass_block
setblock ~20 ~122 ~121 dirt
setblock ~20 ~122 ~122 dirt
setblock ~20 ~122 ~123 dirt
setblock ~20 ~123 ~53 dirt
setblock ~20 ~123 ~54 dirt
setblock ~20 ~123 ~55 dirt
setblock ~20 ~123 ~56 dirt
setblock ~20 ~123 ~57 grass_block
setblock ~20 ~123 ~58 grass_block
setblock ~20 ~123 ~59 grass_block
setblock ~20 ~123 ~60 grass_block
setblock ~20 ~123 ~92 dirt
setblock ~20 ~123 ~93 dirt
setblock ~20 ~123 ~94 dirt
setblock ~20 ~123 ~95 dirt
setblock ~20 ~123 ~96 dirt
setblock ~20 ~123 ~97 dirt
setblock ~20 ~123 ~98 dirt
setblock ~20 ~123 ~99 dirt
setblock ~20 ~123 ~100 dirt
setblock ~20 ~123 ~101 dirt
setblock ~20 ~123 ~102 dirt
setblock ~20 ~123 ~103 dirt
setblock ~20 ~123 ~104 dirt
setblock ~20 ~123 ~105 dirt
setblock ~20 ~123 ~106 dirt
setblock ~20 ~123 ~107 dirt
setblock ~20 ~123 ~108 dirt
setblock ~20 ~123 ~109 dirt
setblock ~20 ~123 ~110 dirt
setblock ~20 ~123 ~111 dirt
setblock ~20 ~123 ~112 dirt
setblock ~20 ~123 ~113 dirt
setblock ~20 ~123 ~114 dirt
setblock ~20 ~123 ~115 dirt
setblock ~20 ~123 ~116 dirt
setblock ~20 ~123 ~117 grass_block
setblock ~20 ~123 ~118 grass_block
setblock ~20 ~123 ~119 grass_block
setblock ~20 ~123 ~121 grass_block
setblock ~20 ~123 ~122 grass_block
setblock ~20 ~123 ~123 grass_block
setblock ~20 ~124 ~53 dirt
setblock ~20 ~124 ~54 grass_block
setblock ~20 ~124 ~55 grass_block
setblock ~20 ~124 ~56 grass_block
setblock ~20 ~124 ~57 short_grass
setblock ~20 ~124 ~92 dirt
setblock ~20 ~124 ~93 dirt
setblock ~20 ~124 ~94 dirt
setblock ~20 ~124 ~95 dirt
setblock ~20 ~124 ~96 dirt
setblock ~20 ~124 ~97 dirt
setblock ~20 ~124 ~98 dirt
setblock ~20 ~124 ~99 dirt
setblock ~20 ~124 ~100 dirt
setblock ~20 ~124 ~101 dirt
setblock ~20 ~124 ~102 dirt
setblock ~20 ~124 ~103 dirt
setblock ~20 ~124 ~104 dirt
setblock ~20 ~124 ~105 dirt
setblock ~20 ~124 ~106 dirt
setblock ~20 ~124 ~107 dirt
setblock ~20 ~124 ~108 dirt
setblock ~20 ~124 ~109 dirt
setblock ~20 ~124 ~110 dirt
setblock ~20 ~124 ~111 dirt
setblock ~20 ~124 ~112 dirt
setblock ~20 ~124 ~113 dirt
setblock ~20 ~124 ~114 grass_block
setblock ~20 ~124 ~115 grass_block
setblock ~20 ~124 ~116 grass_block
setblock ~20 ~124 ~118 short_grass
setblock ~20 ~125 ~53 grass_block
setblock ~20 ~125 ~92 dirt
setblock ~20 ~125 ~93 dirt
setblock ~20 ~125 ~94 grass_block
setblock ~20 ~125 ~95 grass_block
setblock ~20 ~125 ~96 grass_block
setblock ~20 ~125 ~97 grass_block
setblock ~20 ~125 ~98 grass_block
setblock ~20 ~125 ~99 grass_block
setblock ~20 ~125 ~100 grass_block
setblock ~20 ~125 ~101 grass_block
setblock ~20 ~125 ~102 grass_block
setblock ~20 ~125 ~103 grass_block
setblock ~20 ~125 ~104 grass_block
setblock ~20 ~125 ~105 dirt
setblock ~20 ~125 ~106 dirt
setblock ~20 ~125 ~107 dirt
setblock ~20 ~125 ~108 dirt
setblock ~20 ~125 ~109 dirt
setblock ~20 ~125 ~110 dirt
setblock ~20 ~125 ~111 dirt
setblock ~20 ~125 ~112 grass_block
setblock ~20 ~125 ~113 grass_block
setblock ~20 ~125 ~116 short_grass
setblock ~20 ~126 ~53 short_grass
setblock ~20 ~126 ~92 grass_block
setblock ~20 ~126 ~93 grass_block
setblock ~20 ~126 ~96 short_grass
setblock ~20 ~126 ~97 short_grass
setblock ~20 ~126 ~98 short_grass
setblock ~20 ~126 ~101 fern
setblock ~20 ~126 ~105 grass_block
setblock ~20 ~126 ~106 grass_block
setblock ~20 ~126 ~107 grass_block
setblock ~20 ~126 ~108 grass_block
setblock ~20 ~126 ~109 grass_block
setblock ~20 ~126 ~110 grass_block
setblock ~20 ~126 ~111 grass_block
setblock ~20 ~126 ~112 short_grass
setblock ~20 ~126 ~113 short_grass
setblock ~20 ~127 ~110 short_grass
setblock ~20 ~127 ~111 poppy
setblock ~21 ~101 ~108 dirt
setblock ~21 ~102 ~107 dirt
setblock ~21 ~102 ~108 dirt
setblock ~21 ~102 ~109 dirt
setblock ~21 ~103 ~106 dirt
setblock ~21 ~103 ~107 dirt
setblock ~21 ~103 ~108 dirt
setblock ~21 ~103 ~109 dirt
setblock ~21 ~103 ~110 dirt
setblock ~21 ~104 ~105 dirt
setblock ~21 ~104 ~106 dirt
setblock ~21 ~104 ~107 dirt
setblock ~21 ~104 ~108 dirt
setblock ~21 ~104 ~109 dirt
setblock ~21 ~104 ~110 dirt
setblock ~21 ~104 ~111 dirt
setblock ~21 ~105 ~104 dirt
setblock ~21 ~105 ~105 dirt
setblock ~21 ~105 ~106 dirt
setblock ~21 ~105 ~107 dirt
setblock ~21 ~105 ~108 dirt
setblock ~21 ~105 ~109 dirt
setblock ~21 ~105 ~110 dirt
setblock ~21 ~105 ~111 dirt
setblock ~21 ~106 ~103 dirt
setblock ~21 ~106 ~104 dirt
setblock ~21 ~106 ~105 dirt
setblock ~21 ~106 ~106 dirt
setblock ~21 ~106 ~107 dirt
setblock ~21 ~106 ~108 dirt
setblock ~21 ~106 ~109 dirt
setblock ~21 ~106 ~110 dirt
setblock ~21 ~106 ~111 dirt
setblock ~21 ~106 ~112 dirt
setblock ~21 ~107 ~103 dirt
setblock ~21 ~107 ~104 dirt
setblock ~21 ~107 ~105 dirt
setblock ~21 ~107 ~106 dirt
setblock ~21 ~107 ~107 dirt
setblock ~21 ~107 ~108 dirt
setblock ~21 ~107 ~109 dirt
setblock ~21 ~107 ~110 dirt
setblock ~21 ~107 ~111 dirt
setblock ~21 ~107 ~112 dirt
setblock ~21 ~107 ~113 dirt
setblock ~21 ~108 ~102 dirt
setblock ~21 ~108 ~103 dirt
setblock ~21 ~108 ~104 dirt
setblock ~21 ~108 ~105 dirt
setblock ~21 ~108 ~106 dirt
setblock ~21 ~108 ~107 dirt
setblock ~21 ~108 ~108 dirt
setblock ~21 ~108 ~109 dirt
setblock ~21 ~108 ~110 dirt
setblock ~21 ~108 ~111 dirt
setblock ~21 ~108 ~112 dirt
setblock ~21 ~108 ~113 dirt
setblock ~21 ~109 ~101 dirt
setblock ~21 ~109 ~102 dirt
setblock ~21 ~109 ~103 dirt
setblock ~21 ~109 ~104 dirt
setblock ~21 ~109 ~105 dirt
setblock ~21 ~109 ~106 dirt
setblock ~21 ~109 ~107 dirt
setblock ~21 ~109 ~108 dirt
setblock ~21 ~109 ~109 dirt
setblock ~21 ~109 ~110 dirt
setblock ~21 ~109 ~111 dirt
setblock ~21 ~109 ~112 dirt
setblock ~21 ~109 ~113 dirt
setblock ~21 ~109 ~114 dirt
setblock ~21 ~110 ~101 dirt
setblock ~21 ~110 ~102 dirt
setblock ~21 ~110 ~103 dirt
setblock ~21 ~110 ~104 dirt
setblock ~21 ~110 ~105 dirt
setblock ~21 ~110 ~106 dirt
setblock ~21 ~110 ~107 dirt
setblock ~21 ~110 ~108 dirt
setblock ~21 ~110 ~109 dirt
setblock ~21 ~110 ~110 dirt
setblock ~21 ~110 ~111 dirt
setblock ~21 ~110 ~112 dirt
setblock ~21 ~110 ~113 dirt
setblock ~21 ~110 ~114 dirt
setblock ~21 ~110 ~115 dirt
setblock ~21 ~111 ~100 dirt
setblock ~21 ~111 ~101 dirt
setblock ~21 ~111 ~102 dirt
setblock ~21 ~111 ~103 dirt
setblock ~21 ~111 ~104 dirt
setblock ~21 ~111 ~105 dirt
setblock ~21 ~111 ~106 dirt
setblock ~21 ~111 ~107 dirt
setblock ~21 ~111 ~108 dirt
setblock ~21 ~111 ~109 dirt
setblock ~21 ~111 ~110 dirt
setblock ~21 ~111 ~111 dirt
setblock ~21 ~111 ~112 dirt
setblock ~21 ~111 ~113 dirt
setblock ~21 ~111 ~114 dirt
setblock ~21 ~111 ~115 dirt
setblock ~21 ~111 ~116 dirt
setblock ~21 ~112 ~100 dirt
setblock ~21 ~112 ~101 dirt
setblock ~21 ~112 ~102 dirt
setblock ~21 ~112 ~103 dirt
setblock ~21 ~112 ~104 dirt
setblock ~21 ~112 ~105 dirt
setblock ~21 ~112 ~106 dirt
setblock ~21 ~112 ~107 dirt
setblock ~21 ~112 ~108 dirt
setblock ~21 ~112 ~109 dirt
setblock ~21 ~112 ~110 dirt
setblock ~21 ~112 ~111 dirt
setblock ~21 ~112 ~112 dirt
setblock ~21 ~112 ~113 dirt
setblock ~21 ~112 ~114 dirt
setblock ~21 ~112 ~115 dirt
setblock ~21 ~112 ~116 dirt
setblock ~21 ~112 ~117 dirt
setblock ~21 ~113 ~99 dirt
setblock ~21 ~113 ~100 dirt
setblock ~21 ~113 ~101 dirt
setblock ~21 ~113 ~102 dirt
setblock ~21 ~113 ~103 dirt
setblock ~21 ~113 ~104 dirt
setblock ~21 ~113 ~105 dirt
setblock ~21 ~113 ~106 dirt
setblock ~21 ~113 ~107 dirt
setblock ~21 ~113 ~108 dirt
setblock ~21 ~113 ~109 dirt
setblock ~21 ~113 ~110 dirt
setblock ~21 ~113 ~111 dirt
setblock ~21 ~113 ~112 dirt
setblock ~21 ~113 ~113 dirt
setblock ~21 ~113 ~114 dirt
setblock ~21 ~113 ~115 dirt
setblock ~21 ~113 ~116 dirt
setblock ~21 ~113 ~117 dirt
setblock ~21 ~113 ~118 dirt
setblock ~21 ~114 ~55 dirt
setblock ~21 ~114 ~56 dirt
setblock ~21 ~114 ~98 dirt
setblock ~21 ~114 ~99 dirt
setblock ~21 ~114 ~100 dirt
setblock ~21 ~114 ~101 dirt
setblock ~21 ~114 ~102 dirt
setblock ~21 ~114 ~103 dirt
setblock ~21 ~114 ~104 dirt
setblock ~21 ~114 ~105 dirt
setblock ~21 ~114 ~106 dirt
setblock ~21 ~114 ~107 dirt
setblock ~21 ~114 ~108 dirt
setblock ~21 ~114 ~109 dirt
setblock ~21 ~114 ~110 dirt
setblock ~21 ~114 ~111 dirt
setblock ~21 ~114 ~112 dirt
setblock ~21 ~114 ~113 dirt
setblock ~21 ~114 ~114 dirt
setblock ~21 ~114 ~115 dirt
setblock ~21 ~114 ~116 dirt
setblock ~21 ~114 ~117 dirt
setblock ~21 ~114 ~118 dirt
setblock ~21 ~115 ~54 dirt
setblock ~21 ~115 ~55 dirt
setblock ~21 ~115 ~56 dirt
setblock ~21 ~115 ~57 dirt
setblock ~21 ~115 ~98 dirt
setblock ~21 ~115 ~99 dirt
setblock ~21 ~115 ~100 dirt
setblock ~21 ~115 ~101 dirt
setblock ~21 ~115 ~102 dirt
setblock ~21 ~115 ~103 dirt
setblock ~21 ~115 ~104 dirt
setblock ~21 ~115 ~105 dirt
setblock ~21 ~115 ~106 dirt
setblock ~21 ~115 ~107 dirt
setblock ~21 ~115 ~108 dirt
setblock ~21 ~115 ~109 dirt
setblock ~21 ~115 ~110 dirt
setblock ~21 ~115 ~111 dirt
setblock ~21 ~115 ~112 dirt
setblock ~21 ~115 ~113 dirt
setblock ~21 ~115 ~114 dirt
setblock ~21 ~115 ~115 dirt
setblock ~21 ~115 ~116 dirt
setblock ~21 ~115 ~117 dirt
setblock ~21 ~115 ~118 dirt
setblock ~21 ~115 ~119 dirt
setblock ~21 ~116 ~54 dirt
setblock ~21 ~116 ~55 dirt
setblock ~21 ~116 ~56 dirt
setblock ~21 ~116 ~57 dirt
setblock ~21 ~116 ~97 dirt
setblock ~21 ~116 ~98 dirt
setblock ~21 ~116 ~99 dirt
setblock ~21 ~116 ~100 dirt
setblock ~21 ~116 ~101 dirt
setblock ~21 ~116 ~102 dirt
setblock ~21 ~116 ~103 dirt
setblock ~21 ~116 ~104 dirt
setblock ~21 ~116 ~105 dirt
setblock ~21 ~116 ~106 dirt
setblock ~21 ~116 ~107 dirt
setblock ~21 ~116 ~108 dirt
setblock ~21 ~116 ~109 dirt
setblock ~21 ~116 ~110 dirt
setblock ~21 ~116 ~111 dirt
setblock ~21 ~116 ~112 dirt
setblock ~21 ~116 ~113 dirt
setblock ~21 ~116 ~114 dirt
setblock ~21 ~116 ~115 dirt
setblock ~21 ~116 ~116 dirt
setblock ~21 ~116 ~117 dirt
setblock ~21 ~116 ~118 dirt
setblock ~21 ~116 ~119 dirt
setblock ~21 ~116 ~120 dirt
setblock ~21 ~117 ~54 dirt
setblock ~21 ~117 ~55 dirt
setblock ~21 ~117 ~56 dirt
setblock ~21 ~117 ~57 dirt
setblock ~21 ~117 ~96 dirt
setblock ~21 ~117 ~97 dirt
setblock ~21 ~117 ~98 dirt
setblock ~21 ~117 ~99 dirt
setblock ~21 ~117 ~100 dirt
setblock ~21 ~117 ~101 dirt
setblock ~21 ~117 ~102 dirt
setblock ~21 ~117 ~103 dirt
setblock ~21 ~117 ~104 dirt
setblock ~21 ~117 ~105 dirt
setblock ~21 ~117 ~106 dirt
setblock ~21 ~117 ~107 dirt
setblock ~21 ~117 ~108 dirt
setblock ~21 ~117 ~109 dirt
setblock ~21 ~117 ~110 dirt
setblock ~21 ~117 ~111 dirt
setblock ~21 ~117 ~112 dirt
setblock ~21 ~117 ~113 dirt
setblock ~21 ~117 ~114 dirt
setblock ~21 ~117 ~115 dirt
setblock ~21 ~117 ~116 dirt
setblock ~21 ~117 ~117 dirt
setblock ~21 ~117 ~118 dirt
setblock ~21 ~117 ~119 dirt
setblock ~21 ~117 ~120 dirt
setblock ~21 ~118 ~53 dirt
setblock ~21 ~118 ~54 dirt
setblock ~21 ~118 ~55 dirt
setblock ~21 ~118 ~56 dirt
setblock ~21 ~118 ~57 dirt
setblock ~21 ~118 ~58 dirt
setblock ~21 ~118 ~95 dirt
setblock ~21 ~118 ~96 dirt
setblock ~21 ~118 ~97 dirt
setblock ~21 ~118 ~98 dirt
setblock ~21 ~118 ~99 dirt
setblock ~21 ~118 ~100 dirt
setblock ~21 ~118 ~101 dirt
setblock ~21 ~118 ~102 dirt
setblock ~21 ~118 ~103 dirt
setblock ~21 ~118 ~104 dirt
setblock ~21 ~118 ~105 dirt
setblock ~21 ~118 ~106 dirt
setblock ~21 ~118 ~107 dirt
setblock ~21 ~118 ~108 dirt
setblock ~21 ~118 ~109 dirt
setblock ~21 ~118 ~110 dirt
setblock ~21 ~118 ~111 dirt
setblock ~21 ~118 ~112 dirt
setblock ~21 ~118 ~113 dirt
setblock ~21 ~118 ~114 dirt
setblock ~21 ~118 ~115 dirt
setblock ~21 ~118 ~116 dirt
setblock ~21 ~118 ~117 dirt
setblock ~21 ~118 ~118 dirt
setblock ~21 ~118 ~119 dirt
setblock ~21 ~118 ~120 dirt
setblock ~21 ~118 ~121 dirt
setblock ~21 ~119 ~52 dirt
setblock ~21 ~119 ~53 dirt
setblock ~21 ~119 ~54 dirt
setblock ~21 ~119 ~55 dirt
setblock ~21 ~119 ~56 dirt
setblock ~21 ~119 ~57 dirt
setblock ~21 ~119 ~58 dirt
setblock ~21 ~119 ~94 dirt
setblock ~21 ~119 ~95 dirt
setblock ~21 ~119 ~96 dirt
setblock ~21 ~119 ~97 dirt
setblock ~21 ~119 ~98 dirt
setblock ~21 ~119 ~99 dirt
setblock ~21 ~119 ~100 dirt
setblock ~21 ~119 ~101 dirt
setblock ~21 ~119 ~102 dirt
setblock ~21 ~119 ~103 dirt
setblock ~21 ~119 ~104 dirt
setblock ~21 ~119 ~105 dirt
setblock ~21 ~119 ~106 dirt
setblock ~21 ~119 ~107 dirt
setblock ~21 ~119 ~108 dirt
setblock ~21 ~119 ~109 dirt
setblock ~21 ~119 ~110 dirt
setblock ~21 ~119 ~111 dirt
setblock ~21 ~119 ~112 dirt
setblock ~21 ~119 ~113 dirt
setblock ~21 ~119 ~114 dirt
setblock ~21 ~119 ~115 dirt
setblock ~21 ~119 ~116 dirt
setblock ~21 ~119 ~117 dirt
setblock ~21 ~119 ~118 dirt
setblock ~21 ~119 ~119 dirt
setblock ~21 ~119 ~120 dirt
setblock ~21 ~119 ~121 dirt
setblock ~21 ~119 ~122 dirt
setblock ~21 ~120 ~52 dirt
setblock ~21 ~120 ~53 dirt
setblock ~21 ~120 ~54 dirt
setblock ~21 ~120 ~55 dirt
setblock ~21 ~120 ~56 dirt
setblock ~21 ~120 ~57 dirt
setblock ~21 ~120 ~58 dirt
setblock ~21 ~120 ~59 dirt
setblock ~21 ~120 ~60 dirt
setblock ~21 ~120 ~94 dirt
setblock ~21 ~120 ~95 dirt
setblock ~21 ~120 ~96 dirt
setblock ~21 ~120 ~97 dirt
setblock ~21 ~120 ~98 dirt
setblock ~21 ~120 ~99 dirt
setblock ~21 ~120 ~100 dirt
setblock ~21 ~120 ~101 dirt
setblock ~21 ~120 ~102 dirt
setblock ~21 ~120 ~103 dirt
setblock ~21 ~120 ~104 dirt
setblock ~21 ~120 ~105 dirt
setblock ~21 ~120 ~106 dirt
setblock ~21 ~120 ~107 dirt
setblock ~21 ~120 ~108 dirt
setblock ~21 ~120 ~109 dirt
setblock ~21 ~120 ~110 dirt
setblock ~21 ~120 ~111 dirt
setblock ~21 ~120 ~112 dirt
setblock ~21 ~120 ~113 dirt
setblock ~21 ~120 ~114 dirt
setblock ~21 ~120 ~115 dirt
setblock ~21 ~120 ~116 dirt
setblock ~21 ~120 ~117 dirt
setblock ~21 ~120 ~118 dirt
setblock ~21 ~120 ~119 dirt
setblock ~21 ~120 ~120 dirt
setblock ~21 ~120 ~121 dirt
setblock ~21 ~120 ~122 dirt
setblock ~21 ~120 ~123 dirt
setblock ~21 ~121 ~52 dirt
setblock ~21 ~121 ~53 dirt
setblock ~21 ~121 ~54 dirt
setblock ~21 ~121 ~55 dirt
setblock ~21 ~121 ~56 dirt
setblock ~21 ~121 ~57 dirt
setblock ~21 ~121 ~58 dirt
setblock ~21 ~121 ~59 dirt
setblock ~21 ~121 ~60 dirt
setblock ~21 ~121 ~61 dirt
setblock ~21 ~121 ~62 dirt
setblock ~21 ~121 ~63 dirt
setblock ~21 ~121 ~93 dirt
setblock ~21 ~121 ~94 dirt
setblock ~21 ~121 ~95 dirt
setblock ~21 ~121 ~96 dirt
setblock ~21 ~121 ~97 dirt
setblock ~21 ~121 ~98 dirt
setblock ~21 ~121 ~99 dirt
setblock ~21 ~121 ~100 dirt
setblock ~21 ~121 ~101 dirt
setblock ~21 ~121 ~102 dirt
setblock ~21 ~121 ~103 dirt
setblock ~21 ~121 ~104 dirt
setblock ~21 ~121 ~105 dirt
setblock ~21 ~121 ~106 dirt
setblock ~21 ~121 ~107 dirt
setblock ~21 ~121 ~108 dirt
setblock ~21 ~121 ~109 dirt
setblock ~21 ~121 ~110 dirt
setblock ~21 ~121 ~111 dirt
setblock ~21 ~121 ~112 dirt
setblock ~21 ~121 ~113 dirt
setblock ~21 ~121 ~114 dirt
setblock ~21 ~121 ~115 dirt
setblock ~21 ~121 ~116 dirt
setblock ~21 ~121 ~117 dirt
setblock ~21 ~121 ~118 dirt
setblock ~21 ~121 ~119 dirt
setblock ~21 ~121 ~120 dirt
setblock ~21 ~121 ~121 dirt
setblock ~21 ~121 ~122 dirt
setblock ~21 ~121 ~123 dirt
setblock ~21 ~121 ~124 dirt
setblock ~21 ~122 ~52 dirt
setblock ~21 ~122 ~53 dirt
setblock ~21 ~122 ~54 dirt
setblock ~21 ~122 ~55 dirt
setblock ~21 ~122 ~56 dirt
setblock ~21 ~122 ~57 dirt
setblock ~21 ~122 ~58 dirt
setblock ~21 ~122 ~59 dirt
setblock ~21 ~122 ~60 dirt
setblock ~21 ~122 ~61 dirt
setblock ~21 ~122 ~62 dirt
setblock ~21 ~122 ~63 dirt
setblock ~21 ~122 ~93 dirt
setblock ~21 ~122 ~94 dirt
setblock ~21 ~122 ~95 dirt
setblock ~21 ~122 ~96 dirt
setblock ~21 ~122 ~97 dirt
setblock ~21 ~122 ~98 dirt
setblock ~21 ~122 ~99 dirt
setblock ~21 ~122 ~100 dirt
setblock ~21 ~122 ~101 dirt
