setblock ~16 ~120 ~123 dirt
setblock ~16 ~120 ~124 dirt
setblock ~16 ~120 ~125 dirt
setblock ~16 ~120 ~126 dirt
setblock ~16 ~120 ~127 dirt
setblock ~16 ~120 ~128 dirt
setblock ~16 ~120 ~129 dirt
setblock ~16 ~120 ~130 dirt
setblock ~16 ~120 ~131 dirt
setblock ~16 ~120 ~132 dirt
setblock ~16 ~121 ~61 dirt
setblock ~16 ~121 ~62 dirt
setblock ~16 ~121 ~63 dirt
setblock ~16 ~121 ~64 dirt
setblock ~16 ~121 ~65 dirt
setblock ~16 ~121 ~66 dirt
setblock ~16 ~121 ~67 dirt
setblock ~16 ~121 ~68 dirt
setblock ~16 ~121 ~69 dirt
setblock ~16 ~121 ~70 dirt
setblock ~16 ~121 ~71 dirt
setblock ~16 ~121 ~72 dirt
setblock ~16 ~121 ~73 dirt
setblock ~16 ~121 ~88 dirt
setblock ~16 ~121 ~89 dirt
setblock ~16 ~121 ~90 dirt
setblock ~16 ~121 ~91 dirt
setblock ~16 ~121 ~92 dirt
setblock ~16 ~121 ~93 dirt
setblock ~16 ~121 ~94 dirt
setblock ~16 ~121 ~95 dirt
setblock ~16 ~121 ~96 dirt
setblock ~16 ~121 ~97 dirt
setblock ~16 ~121 ~98 dirt
setblock ~16 ~121 ~99 dirt
setblock ~16 ~121 ~100 dirt
setblock ~16 ~121 ~101 dirt
setblock ~16 ~121 ~102 dirt
setblock ~16 ~121 ~103 dirt
setblock ~16 ~121 ~104 dirt
setblock ~16 ~121 ~105 dirt
setblock ~16 ~121 ~106 dirt
setblock ~16 ~121 ~107 dirt
setblock ~16 ~121 ~108 dirt
setblock ~16 ~121 ~109 dirt
setblock ~16 ~121 ~110 dirt
setblock ~16 ~121 ~111 dirt
setblock ~16 ~121 ~112 dirt
setblock ~16 ~121 ~113 dirt
setblock ~16 ~121 ~114 dirt
setblock ~16 ~121 ~115 dirt
setblock ~16 ~121 ~116 dirt
setblock ~16 ~121 ~119 dirt
setblock ~16 ~121 ~120 dirt
setblock ~16 ~121 ~121 dirt
setblock ~16 ~121 ~122 dirt
setblock ~16 ~121 ~123 dirt
setblock ~16 ~121 ~124 dirt
setblock ~16 ~121 ~125 dirt
setblock ~16 ~121 ~126 dirt
setblock ~16 ~121 ~127 dirt
setblock ~16 ~121 ~128 dirt
setblock ~16 ~121 ~129 dirt
setblock ~16 ~121 ~130 dirt
setblock ~16 ~121 ~131 dirt
setblock ~16 ~121 ~132 dirt
setblock ~16 ~122 ~61 dirt
setblock ~16 ~122 ~62 dirt
setblock ~16 ~122 ~63 dirt
setblock ~16 ~122 ~64 dirt
setblock ~16 ~122 ~65 dirt
setblock ~16 ~122 ~66 dirt
setblock ~16 ~122 ~67 dirt
setblock ~16 ~122 ~68 dirt
setblock ~16 ~122 ~69 dirt
setblock ~16 ~122 ~70 dirt
setblock ~16 ~122 ~71 dirt
setblock ~16 ~122 ~72 dirt
setblock ~16 ~122 ~73 dirt
setblock ~16 ~122 ~88 dirt
setblock ~16 ~122 ~89 dirt
setblock ~16 ~122 ~90 dirt
setblock ~16 ~122 ~91 dirt
setblock ~16 ~122 ~92 dirt
setblock ~16 ~122 ~93 dirt
setblock ~16 ~122 ~94 dirt
setblock ~16 ~122 ~95 dirt
setblock ~16 ~122 ~96 dirt
setblock ~16 ~122 ~97 dirt
setblock ~16 ~122 ~98 dirt
setblock ~16 ~122 ~99 dirt
setblock ~16 ~122 ~100 dirt
setblock ~16 ~122 ~101 dirt
setblock ~16 ~122 ~102 dirt
setblock ~16 ~122 ~103 dirt
setblock ~16 ~122 ~104 dirt
setblock ~16 ~122 ~105 dirt
setblock ~16 ~122 ~106 dirt
setblock ~16 ~122 ~107 dirt
setblock ~16 ~122 ~108 dirt
setblock ~16 ~122 ~109 dirt
setblock ~16 ~122 ~110 dirt
setblock ~16 ~122 ~111 dirt
setblock ~16 ~122 ~112 dirt
setblock ~16 ~122 ~113 dirt
setblock ~16 ~122 ~114 dirt
setblock ~16 ~122 ~115 dirt
setblock ~16 ~122 ~116 dirt
setblock ~16 ~122 ~119 dirt
setblock ~16 ~122 ~120 dirt
setblock ~16 ~122 ~121 dirt
setblock ~16 ~122 ~122 dirt
setblock ~16 ~122 ~123 dirt
setblock ~16 ~122 ~124 dirt
setblock ~16 ~122 ~125 dirt
setblock ~16 ~122 ~126 dirt
setblock ~16 ~122 ~127 dirt
setblock ~16 ~122 ~128 dirt
setblock ~16 ~122 ~129 dirt
setblock ~16 ~122 ~130 dirt
setblock ~16 ~122 ~131 dirt
setblock ~16 ~122 ~132 dirt
setblock ~16 ~123 ~61 dirt
setblock ~16 ~123 ~62 dirt
setblock ~16 ~123 ~63 dirt
setblock ~16 ~123 ~64 dirt
setblock ~16 ~123 ~65 dirt
setblock ~16 ~123 ~66 dirt
setblock ~16 ~123 ~67 dirt
setblock ~16 ~123 ~68 dirt
setblock ~16 ~123 ~69 dirt
setblock ~16 ~123 ~70 grass_block
setblock ~16 ~123 ~71 grass_block
setblock ~16 ~123 ~72 dirt
setblock ~16 ~123 ~73 dirt
setblock ~16 ~123 ~88 dirt
setblock ~16 ~123 ~89 dirt
setblock ~16 ~123 ~90 dirt
setblock ~16 ~123 ~91 dirt
setblock ~16 ~123 ~92 dirt
setblock ~16 ~123 ~93 dirt
setblock ~16 ~123 ~94 dirt
setblock ~16 ~123 ~95 dirt
setblock ~16 ~123 ~96 dirt
setblock ~16 ~123 ~97 dirt
setblock ~16 ~123 ~98 dirt
setblock ~16 ~123 ~99 dirt
setblock ~16 ~123 ~100 dirt
setblock ~16 ~123 ~101 dirt
setblock ~16 ~123 ~102 dirt
setblock ~16 ~123 ~103 dirt
setblock ~16 ~123 ~104 dirt
setblock ~16 ~123 ~105 dirt
setblock ~16 ~123 ~106 dirt
setblock ~16 ~123 ~107 dirt
setblock ~16 ~123 ~108 dirt
setblock ~16 ~123 ~109 dirt
setblock ~16 ~123 ~110 dirt
setblock ~16 ~123 ~111 dirt
setblock ~16 ~123 ~112 dirt
setblock ~16 ~123 ~113 dirt
setblock ~16 ~123 ~114 dirt
setblock ~16 ~123 ~115 dirt
setblock ~16 ~123 ~116 dirt
setblock ~16 ~123 ~119 dirt
setblock ~16 ~123 ~120 dirt
setblock ~16 ~123 ~121 dirt
setblock ~16 ~123 ~122 dirt
setblock ~16 ~123 ~123 dirt
setblock ~16 ~123 ~124 dirt
setblock ~16 ~123 ~125 dirt
setblock ~16 ~123 ~126 dirt
setblock ~16 ~123 ~127 dirt
setblock ~16 ~123 ~128 grass_block
setblock ~16 ~123 ~129 grass_block
setblock ~16 ~123 ~130 grass_block
setblock ~16 ~123 ~131 grass_block
setblock ~16 ~123 ~132 grass_block
setblock ~16 ~124 ~61 dirt
setblock ~16 ~124 ~62 dirt
setblock ~16 ~124 ~63 dirt
setblock ~16 ~124 ~64 dirt
setblock ~16 ~124 ~65 dirt
setblock ~16 ~124 ~66 grass_block
setblock ~16 ~124 ~67 grass_block
setblock ~16 ~124 ~68 grass_block
setblock ~16 ~124 ~69 grass_block
setblock ~16 ~124 ~71 fern
setblock ~16 ~124 ~72 grass_block
setblock ~16 ~124 ~73 grass_block
setblock ~16 ~124 ~88 dirt
setblock ~16 ~124 ~89 dirt
setblock ~16 ~124 ~90 dirt
setblock ~16 ~124 ~91 dirt
setblock ~16 ~124 ~92 dirt
setblock ~16 ~124 ~93 dirt
setblock ~16 ~124 ~94 dirt
setblock ~16 ~124 ~95 dirt
setblock ~16 ~124 ~96 grass_block
setblock ~16 ~124 ~97 grass_block
setblock ~16 ~124 ~98 grass_block
setblock ~16 ~124 ~99 grass_block
setblock ~16 ~124 ~100 grass_block
setblock ~16 ~124 ~101 grass_block
setblock ~16 ~124 ~102 dirt
setblock ~16 ~124 ~103 dirt
setblock ~16 ~124 ~104 dirt
setblock ~16 ~124 ~105 dirt
setblock ~16 ~124 ~106 dirt
setblock ~16 ~124 ~107 dirt
setblock ~16 ~124 ~108 dirt
setblock ~16 ~124 ~109 dirt
setblock ~16 ~124 ~110 dirt
setblock ~16 ~124 ~111 dirt
setblock ~16 ~124 ~112 dirt
setblock ~16 ~124 ~113 dirt
setblock ~16 ~124 ~114 dirt
setblock ~16 ~124 ~115 dirt
setblock ~16 ~124 ~116 dirt
setblock ~16 ~124 ~119 dirt
setblock ~16 ~124 ~120 dirt
setblock ~16 ~124 ~121 dirt
setblock ~16 ~124 ~122 dirt
setblock ~16 ~124 ~123 grass_block
setblock ~16 ~124 ~124 grass_block
setblock ~16 ~124 ~125 grass_block
setblock ~16 ~124 ~126 grass_block
setblock ~16 ~124 ~127 grass_block
setblock ~16 ~124 ~128 short_grass
setblock ~16 ~124 ~129 fern
setblock ~16 ~124 ~131 short_grass
setblock ~16 ~125 ~61 dirt
setblock ~16 ~125 ~62 dirt
setblock ~16 ~125 ~63 grass_block
setblock ~16 ~125 ~64 grass_block
setblock ~16 ~125 ~65 grass_block
setblock ~16 ~125 ~72 short_grass
setblock ~16 ~125 ~88 dirt
setblock ~16 ~125 ~89 dirt
setblock ~16 ~125 ~90 dirt
setblock ~16 ~125 ~91 dirt
setblock ~16 ~125 ~92 grass_block
setblock ~16 ~125 ~93 grass_block
setblock ~16 ~125 ~94 grass_block
setblock ~16 ~125 ~95 grass_block
setblock ~16 ~125 ~98 short_grass
setblock ~16 ~125 ~102 grass_block
setblock ~16 ~125 ~103 grass_block
setblock ~16 ~125 ~104 grass_block
setblock ~16 ~125 ~105 grass_block
setblock ~16 ~125 ~106 dirt
setblock ~16 ~125 ~107 dirt
setblock ~16 ~125 ~108 dirt
setblock ~16 ~125 ~109 dirt
setblock ~16 ~125 ~110 dirt
setblock ~16 ~125 ~111 dirt
setblock ~16 ~125 ~112 dirt
setblock ~16 ~125 ~113 dirt
setblock ~16 ~125 ~114 dirt
setblock ~16 ~125 ~115 grass_block
setblock ~16 ~125 ~116 grass_block
setblock ~16 ~125 ~119 grass_block
setblock ~16 ~125 ~120 grass_block
setblock ~16 ~125 ~121 grass_block
setblock ~16 ~125 ~122 grass_block
setblock ~16 ~125 ~125 short_grass
setblock ~16 ~126 ~61 grass_block
setblock ~16 ~126 ~62 grass_block
setblock ~16 ~126 ~63 short_grass
setblock ~16 ~126 ~65 poppy
setblock ~16 ~126 ~88 grass_block
setblock ~16 ~126 ~89 grass_block
setblock ~16 ~126 ~90 grass_block
setblock ~16 ~126 ~91 grass_block
setblock ~16 ~126 ~92 short_grass
setblock ~16 ~126 ~93 fern
setblock ~16 ~126 ~94 short_grass
setblock ~16 ~126 ~104 short_grass
setblock ~16 ~126 ~106 grass_block
setblock ~16 ~126 ~107 grass_block
setblock ~16 ~126 ~108 grass_block
setblock ~16 ~126 ~109 grass_block
setblock ~16 ~126 ~110 grass_block
setblock ~16 ~126 ~111 grass_block
setblock ~16 ~126 ~112 grass_block
setblock ~16 ~126 ~113 grass_block
setblock ~16 ~126 ~114 grass_block
setblock ~16 ~126 ~115 short_grass
setblock ~16 ~126 ~119 fern
setblock ~16 ~127 ~61 poppy
setblock ~16 ~127 ~62 short_grass
setblock ~16 ~127 ~88 short_grass
setblock ~16 ~127 ~90 short_grass
setblock ~16 ~127 ~106 poppy
setblock ~16 ~127 ~111 fern
setblock ~16 ~127 ~112 short_grass
setblock ~17 ~107 ~100 dirt
setblock ~17 ~107 ~101 dirt
setblock ~17 ~108 ~98 dirt
setblock ~17 ~108 ~99 dirt
setblock ~17 ~108 ~100 dirt
setblock ~17 ~108 ~101 dirt
setblock ~17 ~108 ~102 dirt
setblock ~17 ~109 ~97 dirt
setblock ~17 ~109 ~98 dirt
setblock ~17 ~109 ~99 dirt
setblock ~17 ~109 ~100 dirt
setblock ~17 ~109 ~101 dirt
setblock ~17 ~109 ~102 dirt
setblock ~17 ~109 ~103 dirt
setblock ~17 ~110 ~97 dirt
setblock ~17 ~110 ~98 dirt
setblock ~17 ~110 ~99 dirt
setblock ~17 ~110 ~100 dirt
setblock ~17 ~110 ~101 dirt
setblock ~17 ~110 ~102 dirt
setblock ~17 ~110 ~103 dirt
setblock ~17 ~110 ~104 dirt
setblock ~17 ~111 ~96 dirt
setblock ~17 ~111 ~97 dirt
setblock ~17 ~111 ~98 dirt
setblock ~17 ~111 ~99 dirt
setblock ~17 ~111 ~100 dirt
setblock ~17 ~111 ~101 dirt
setblock ~17 ~111 ~102 dirt
setblock ~17 ~111 ~103 dirt
setblock ~17 ~111 ~104 dirt
setblock ~17 ~111 ~105 dirt
setblock ~17 ~112 ~95 dirt
setblock ~17 ~112 ~96 dirt
setblock ~17 ~112 ~97 dirt
setblock ~17 ~112 ~98 dirt
setblock ~17 ~112 ~99 dirt
setblock ~17 ~112 ~100 dirt
setblock ~17 ~112 ~101 dirt
setblock ~17 ~112 ~102 dirt
setblock ~17 ~112 ~103 dirt
setblock ~17 ~112 ~104 dirt
setblock ~17 ~112 ~105 dirt
setblock ~17 ~112 ~106 dirt
setblock ~17 ~113 ~94 dirt
setblock ~17 ~113 ~95 dirt
setblock ~17 ~113 ~96 dirt
setblock ~17 ~113 ~97 dirt
setblock ~17 ~113 ~98 dirt
setblock ~17 ~113 ~99 dirt
setblock ~17 ~113 ~100 dirt
setblock ~17 ~113 ~101 dirt
setblock ~17 ~113 ~102 dirt
setblock ~17 ~113 ~103 dirt
setblock ~17 ~113 ~104 dirt
setblock ~17 ~113 ~105 dirt
setblock ~17 ~113 ~106 dirt
setblock ~17 ~113 ~107 dirt
setblock ~17 ~114 ~93 dirt
setblock ~17 ~114 ~94 dirt
setblock ~17 ~114 ~95 dirt
setblock ~17 ~114 ~96 dirt
setblock ~17 ~114 ~97 dirt
setblock ~17 ~114 ~98 dirt
setblock ~17 ~114 ~99 dirt
setblock ~17 ~114 ~100 dirt
setblock ~17 ~114 ~101 dirt
setblock ~17 ~114 ~102 dirt
setblock ~17 ~114 ~103 dirt
setblock ~17 ~114 ~104 dirt
setblock ~17 ~114 ~105 dirt
setblock ~17 ~114 ~106 dirt
setblock ~17 ~114 ~107 dirt
setblock ~17 ~114 ~108 dirt
setblock ~17 ~115 ~70 dirt
setblock ~17 ~115 ~92 dirt
setblock ~17 ~115 ~93 dirt
setblock ~17 ~115 ~94 dirt
setblock ~17 ~115 ~95 dirt
setblock ~17 ~115 ~96 dirt
setblock ~17 ~115 ~97 dirt
setblock ~17 ~115 ~98 dirt
setblock ~17 ~115 ~99 dirt
setblock ~17 ~115 ~100 dirt
setblock ~17 ~115 ~101 dirt
setblock ~17 ~115 ~102 dirt
setblock ~17 ~115 ~103 dirt
setblock ~17 ~115 ~104 dirt
setblock ~17 ~115 ~105 dirt
setblock ~17 ~115 ~106 dirt
setblock ~17 ~115 ~107 dirt
setblock ~17 ~115 ~108 dirt
setblock ~17 ~115 ~109 dirt
setblock ~17 ~116 ~69 dirt
setblock ~17 ~116 ~70 dirt
setblock ~17 ~116 ~71 dirt
setblock ~17 ~116 ~91 dirt
setblock ~17 ~116 ~92 dirt
setblock ~17 ~116 ~93 dirt
setblock ~17 ~116 ~94 dirt
setblock ~17 ~116 ~95 dirt
setblock ~17 ~116 ~96 dirt
setblock ~17 ~116 ~97 dirt
setblock ~17 ~116 ~98 dirt
setblock ~17 ~116 ~99 dirt
setblock ~17 ~116 ~100 dirt
setblock ~17 ~116 ~101 dirt
setblock ~17 ~116 ~102 dirt
setblock ~17 ~116 ~103 dirt
setblock ~17 ~116 ~104 dirt
setblock ~17 ~116 ~105 dirt
setblock ~17 ~116 ~106 dirt
setblock ~17 ~116 ~107 dirt
setblock ~17 ~116 ~108 dirt
setblock ~17 ~116 ~109 dirt
setblock ~17 ~116 ~125 dirt
setblock ~17 ~116 ~128 dirt
setblock ~17 ~117 ~69 dirt
setblock ~17 ~117 ~70 dirt
setblock ~17 ~117 ~71 dirt
setblock ~17 ~117 ~72 dirt
setblock ~17 ~117 ~91 dirt
setblock ~17 ~117 ~92 dirt
setblock ~17 ~117 ~93 dirt
setblock ~17 ~117 ~94 dirt
setblock ~17 ~117 ~95 dirt
setblock ~17 ~117 ~96 dirt
setblock ~17 ~117 ~97 dirt
setblock ~17 ~117 ~98 dirt
setblock ~17 ~117 ~99 dirt
setblock ~17 ~117 ~100 dirt
setblock ~17 ~117 ~101 dirt
setblock ~17 ~117 ~102 dirt
setblock ~17 ~117 ~103 dirt
setblock ~17 ~117 ~104 dirt
setblock ~17 ~117 ~105 dirt
setblock ~17 ~117 ~106 dirt
setblock ~17 ~117 ~107 dirt
setblock ~17 ~117 ~108 dirt
setblock ~17 ~117 ~109 dirt
setblock ~17 ~117 ~110 dirt
setblock ~17 ~117 ~113 dirt
setblock ~17 ~117 ~122 dirt
setblock ~17 ~117 ~125 dirt
setblock ~17 ~117 ~127 dirt
setblock ~17 ~117 ~128 dirt
setblock ~17 ~117 ~129 dirt
setblock ~17 ~118 ~63 dirt
setblock ~17 ~118 ~66 dirt
setblock ~17 ~118 ~67 dirt
setblock ~17 ~118 ~68 dirt
setblock ~17 ~118 ~69 dirt
setblock ~17 ~118 ~70 dirt
setblock ~17 ~118 ~71 dirt
setblock ~17 ~118 ~72 dirt
setblock ~17 ~118 ~73 dirt
setblock ~17 ~118 ~90 dirt
setblock ~17 ~118 ~91 dirt
setblock ~17 ~118 ~92 dirt
setblock ~17 ~118 ~93 dirt
setblock ~17 ~118 ~94 dirt
setblock ~17 ~118 ~95 dirt
setblock ~17 ~118 ~96 dirt
setblock ~17 ~118 ~97 dirt
setblock ~17 ~118 ~98 dirt
setblock ~17 ~118 ~99 dirt
setblock ~17 ~118 ~100 dirt
setblock ~17 ~118 ~101 dirt
setblock ~17 ~118 ~102 dirt
setblock ~17 ~118 ~103 dirt
setblock ~17 ~118 ~104 dirt
setblock ~17 ~118 ~105 dirt
setblock ~17 ~118 ~106 dirt
setblock ~17 ~118 ~107 dirt
setblock ~17 ~118 ~108 dirt
setblock ~17 ~118 ~109 dirt
setblock ~17 ~118 ~110 dirt
setblock ~17 ~118 ~111 dirt
setblock ~17 ~118 ~112 dirt
setblock ~17 ~118 ~113 dirt
setblock ~17 ~118 ~114 dirt
setblock ~17 ~118 ~121 dirt
setblock ~17 ~118 ~122 dirt
setblock ~17 ~118 ~123 dirt
setblock ~17 ~118 ~124 dirt
setblock ~17 ~118 ~125 dirt
setblock ~17 ~118 ~126 dirt
setblock ~17 ~118 ~127 dirt
setblock ~17 ~118 ~128 dirt
setblock ~17 ~118 ~129 dirt
setblock ~17 ~118 ~130 dirt
setblock ~17 ~118 ~131 dirt
setblock ~17 ~119 ~62 dirt
setblock ~17 ~119 ~63 dirt
setblock ~17 ~119 ~64 dirt
setblock ~17 ~119 ~66 dirt
setblock ~17 ~119 ~67 dirt
setblock ~17 ~119 ~68 dirt
setblock ~17 ~119 ~69 dirt
setblock ~17 ~119 ~70 dirt
setblock ~17 ~119 ~71 dirt
setblock ~17 ~119 ~72 dirt
setblock ~17 ~119 ~73 dirt
setblock ~17 ~119 ~89 dirt
setblock ~17 ~119 ~90 dirt
setblock ~17 ~119 ~91 dirt
setblock ~17 ~119 ~92 dirt
setblock ~17 ~119 ~93 dirt
setblock ~17 ~119 ~94 dirt
setblock ~17 ~119 ~95 dirt
setblock ~17 ~119 ~96 dirt
setblock ~17 ~119 ~97 dirt
setblock ~17 ~119 ~98 dirt
setblock ~17 ~119 ~99 dirt
setblock ~17 ~119 ~100 dirt
setblock ~17 ~119 ~101 dirt
setblock ~17 ~119 ~102 dirt
setblock ~17 ~119 ~103 dirt
setblock ~17 ~119 ~104 dirt
setblock ~17 ~119 ~105 dirt
setblock ~17 ~119 ~106 dirt
setblock ~17 ~119 ~107 dirt
setblock ~17 ~119 ~108 dirt
setblock ~17 ~119 ~109 dirt
setblock ~17 ~119 ~110 dirt
setblock ~17 ~119 ~111 dirt
setblock ~17 ~119 ~112 dirt
setblock ~17 ~119 ~113 dirt
setblock ~17 ~119 ~114 dirt
setblock ~17 ~119 ~115 dirt
setblock ~17 ~119 ~120 dirt
setblock ~17 ~119 ~121 dirt
setblock ~17 ~119 ~122 dirt
setblock ~17 ~119 ~123 dirt
setblock ~17 ~119 ~124 dirt
setblock ~17 ~119 ~125 dirt
setblock ~17 ~119 ~126 dirt
setblock ~17 ~119 ~127 dirt
setblock ~17 ~119 ~128 dirt
setblock ~17 ~119 ~129 dirt
setblock ~17 ~119 ~130 dirt
setblock ~17 ~119 ~131 dirt
setblock ~17 ~119 ~132 dirt
setblock ~17 ~120 ~61 dirt
setblock ~17 ~120 ~62 dirt
setblock ~17 ~120 ~63 dirt
setblock ~17 ~120 ~64 dirt
setblock ~17 ~120 ~65 dirt
setblock ~17 ~120 ~66 dirt
setblock ~17 ~120 ~67 dirt
setblock ~17 ~120 ~68 dirt
setblock ~17 ~120 ~69 dirt
setblock ~17 ~120 ~70 dirt
setblock ~17 ~120 ~71 dirt
setblock ~17 ~120 ~72 dirt
setblock ~17 ~120 ~73 dirt
setblock ~17 ~120 ~88 dirt
setblock ~17 ~120 ~89 dirt
setblock ~17 ~120 ~90 dirt
setblock ~17 ~120 ~91 dirt
setblock ~17 ~120 ~92 dirt
setblock ~17 ~120 ~93 dirt
setblock ~17 ~120 ~94 dirt
setblock ~17 ~120 ~95 dirt
setblock ~17 ~120 ~96 dirt
setblock ~17 ~120 ~97 dirt
setblock ~17 ~120 ~98 dirt
setblock ~17 ~120 ~99 dirt
setblock ~17 ~120 ~100 dirt
setblock ~17 ~120 ~101 dirt
setblock ~17 ~120 ~102 dirt
setblock ~17 ~120 ~103 dirt
setblock ~17 ~120 ~104 dirt
setblock ~17 ~120 ~105 dirt
setblock ~17 ~120 ~106 dirt
setblock ~17 ~120 ~107 dirt
setblock ~17 ~120 ~108 dirt
setblock ~17 ~120 ~109 dirt
setblock ~17 ~120 ~110 dirt
setblock ~17 ~120 ~111 dirt
setblock ~17 ~120 ~112 dirt
setblock ~17 ~120 ~113 dirt
setblock ~17 ~120 ~114 dirt
setblock ~17 ~120 ~115 dirt
setblock ~17 ~120 ~116 dirt
setblock ~17 ~120 ~120 dirt
setblock ~17 ~120 ~121 dirt
setblock ~17 ~120 ~122 dirt
setblock ~17 ~120 ~123 dirt
setblock ~17 ~120 ~124 dirt
setblock ~17 ~120 ~125 dirt
setblock ~17 ~120 ~126 dirt
setblock ~17 ~120 ~127 dirt
setblock ~17 ~120 ~128 dirt
setblock ~17 ~120 ~129 dirt
setblock ~17 ~120 ~130 dirt
setblock ~17 ~120 ~131 dirt
setblock ~17 ~120 ~132 dirt
setblock ~17 ~120 ~133 dirt
setblock ~17 ~121 ~59 dirt
setblock ~17 ~121 ~60 dirt
setblock ~17 ~121 ~61 dirt
setblock ~17 ~121 ~62 dirt
setblock ~17 ~121 ~63 dirt
setblock ~17 ~121 ~64 dirt
setblock ~17 ~121 ~65 dirt
setblock ~17 ~121 ~66 dirt
setblock ~17 ~121 ~67 dirt
setblock ~17 ~121 ~68 dirt
setblock ~17 ~121 ~69 dirt
setblock ~17 ~121 ~70 dirt
setblock ~17 ~121 ~71 dirt
setblock ~17 ~121 ~72 dirt
setblock ~17 ~121 ~73 dirt
setblock ~17 ~121 ~74 dirt
setblock ~17 ~121 ~88 dirt
setblock ~17 ~121 ~89 dirt
setblock ~17 ~121 ~90 dirt
setblock ~17 ~121 ~91 dirt
setblock ~17 ~121 ~92 dirt
setblock ~17 ~121 ~93 dirt
setblock ~17 ~121 ~94 dirt
setblock ~17 ~121 ~95 dirt
setblock ~17 ~121 ~96 dirt
setblock ~17 ~121 ~97 dirt
setblock ~17 ~121 ~98 dirt
setblock ~17 ~121 ~99 dirt
setblock ~17 ~121 ~100 dirt
setblock ~17 ~121 ~101 dirt
setblock ~17 ~121 ~102 dirt
setblock ~17 ~121 ~103 dirt
setblock ~17 ~121 ~104 dirt
setblock ~17 ~121 ~105 dirt
setblock ~17 ~121 ~106 dirt
setblock ~17 ~121 ~107 dirt
setblock ~17 ~121 ~108 dirt
setblock ~17 ~121 ~109 dirt
setblock ~17 ~121 ~110 dirt
setblock ~17 ~121 ~111 dirt
setblock ~17 ~121 ~112 dirt
setblock ~17 ~121 ~113 dirt
setblock ~17 ~121 ~114 dirt
setblock ~17 ~121 ~115 dirt
setblock ~17 ~121 ~116 dirt
setblock ~17 ~121 ~117 dirt
setblock ~17 ~121 ~118 dirt
setblock ~17 ~121 ~119 dirt
setblock ~17 ~121 ~120 dirt
setblock ~17 ~121 ~121 dirt
setblock ~17 ~121 ~122 dirt
setblock ~17 ~121 ~123 dirt
setblock ~17 ~121 ~124 dirt
setblock ~17 ~121 ~125 dirt
setblock ~17 ~121 ~126 dirt
setblock ~17 ~121 ~127 dirt
setblock ~17 ~121 ~128 dirt
setblock ~17 ~121 ~129 dirt
setblock ~17 ~121 ~130 dirt
setblock ~17 ~121 ~131 dirt
setblock ~17 ~121 ~132 dirt
setblock ~17 ~121 ~133 dirt
setblock ~17 ~121 ~134 dirt
setblock ~17 ~122 ~59 dirt
setblock ~17 ~122 ~60 dirt
setblock ~17 ~122 ~61 dirt
setblock ~17 ~122 ~62 dirt
setblock ~17 ~122 ~63 dirt
setblock ~17 ~122 ~64 dirt
setblock ~17 ~122 ~65 dirt
setblock ~17 ~122 ~66 dirt
setblock ~17 ~122 ~67 dirt
setblock ~17 ~122 ~68 dirt
setblock ~17 ~122 ~69 dirt
setblock ~17 ~122 ~70 dirt
setblock ~17 ~122 ~71 dirt
setblock ~17 ~122 ~72 dirt
setblock ~17 ~122 ~73 dirt
setblock ~17 ~122 ~74 dirt
setblock ~17 ~122 ~88 dirt
setblock ~17 ~122 ~89 dirt
setblock ~17 ~122 ~90 dirt
setblock ~17 ~122 ~91 dirt
setblock ~17 ~122 ~92 dirt
setblock ~17 ~122 ~93 dirt
setblock ~17 ~122 ~94 dirt
setblock ~17 ~122 ~95 dirt
setblock ~17 ~122 ~96 dirt
setblock ~17 ~122 ~97 dirt
setblock ~17 ~122 ~98 dirt
setblock ~17 ~122 ~99 dirt
setblock ~17 ~122 ~100 dirt
setblock ~17 ~122 ~101 dirt
setblock ~17 ~122 ~102 dirt
setblock ~17 ~122 ~103 dirt
setblock ~17 ~122 ~104 dirt
setblock ~17 ~122 ~105 dirt
setblock ~17 ~122 ~106 dirt
setblock ~17 ~122 ~107 dirt
setblock ~17 ~122 ~108 dirt
setblock ~17 ~122 ~109 dirt
setblock ~17 ~122 ~110 dirt
setblock ~17 ~122 ~111 dirt
setblock ~17 ~122 ~112 dirt
setblock ~17 ~122 ~113 dirt
setblock ~17 ~122 ~114 dirt
setblock ~17 ~122 ~115 dirt
setblock ~17 ~122 ~116 dirt
setblock ~17 ~122 ~117 dirt
setblock ~17 ~122 ~118 dirt
setblock ~17 ~122 ~119 dirt
setblock ~17 ~122 ~120 dirt
setblock ~17 ~122 ~121 dirt
setblock ~17 ~122 ~122 dirt
setblock ~17 ~122 ~123 dirt
setblock ~17 ~122 ~124 dirt
setblock ~17 ~122 ~125 dirt
setblock ~17 ~122 ~126 dirt
setblock ~17 ~122 ~127 dirt
setblock ~17 ~122 ~128 dirt
setblock ~17 ~122 ~129 dirt
setblock ~17 ~122 ~130 dirt
setblock ~17 ~122 ~131 dirt
setblock ~17 ~122 ~132 dirt
setblock ~17 ~122 ~133 dirt
setblock ~17 ~122 ~134 dirt
setblock ~17 ~123 ~59 dirt
setblock ~17 ~123 ~60 dirt
setblock ~17 ~123 ~61 dirt
setblock ~17 ~123 ~62 dirt
setblock ~17 ~123 ~63 dirt
setblock ~17 ~123 ~64 dirt
setblock ~17 ~123 ~65 dirt
setblock ~17 ~123 ~66 dirt
setblock ~17 ~123 ~67 dirt
setblock ~17 ~123 ~68 dirt
setblock ~17 ~123 ~69 dirt
setblock ~17 ~123 ~70 grass_block
setblock ~17 ~123 ~71 grass_block
setblock ~17 ~123 ~72 grass_block
setblock ~17 ~123 ~73 dirt
setblock ~17 ~123 ~74 dirt
setblock ~17 ~123 ~88 dirt
setblock ~17 ~123 ~89 dirt
setblock ~17 ~123 ~90 dirt
setblock ~17 ~123 ~91 dirt
setblock ~17 ~123 ~92 dirt
setblock ~17 ~123 ~93 dirt
setblock ~17 ~123 ~94 dirt
setblock ~17 ~123 ~95 dirt
setblock ~17 ~123 ~96 dirt
setblock ~17 ~123 ~97 dirt
setblock ~17 ~123 ~98 dirt
setblock ~17 ~123 ~99 dirt
setblock ~17 ~123 ~100 grass_block
setblock ~17 ~123 ~101 dirt
setblock ~17 ~123 ~102 dirt
setblock ~17 ~123 ~103 dirt
setblock ~17 ~123 ~104 dirt
setblock ~17 ~123 ~105 dirt
setblock ~17 ~123 ~106 dirt
setblock ~17 ~123 ~107 dirt
setblock ~17 ~123 ~108 dirt
setblock ~17 ~123 ~109 dirt
setblock ~17 ~123 ~110 dirt
setblock ~17 ~123 ~111 dirt
setblock ~17 ~123 ~112 dirt
setblock ~17 ~123 ~113 dirt
setblock ~17 ~123 ~114 dirt
setblock ~17 ~123 ~115 dirt
setblock ~17 ~123 ~116 dirt
setblock ~17 ~123 ~117 dirt
setblock ~17 ~123 ~118 dirt
setblock ~17 ~123 ~119 dirt
setblock ~17 ~123 ~120 dirt
setblock ~17 ~123 ~121 dirt
setblock ~17 ~123 ~122 dirt
setblock ~17 ~123 ~123 dirt
setblock ~17 ~123 ~124 dirt
setblock ~17 ~123 ~125 dirt
setblock ~17 ~123 ~126 dirt
setblock ~17 ~123 ~127 dirt
setblock ~17 ~123 ~128 dirt
setblock ~17 ~123 ~129 grass_block
setblock ~17 ~123 ~130 grass_block
setblock ~17 ~123 ~131 grass_block
setblock ~17 ~123 ~132 grass_block
setblock ~17 ~123 ~133 grass_block
setblock ~17 ~123 ~134 grass_block
setblock ~17 ~124 ~59 dirt
setblock ~17 ~124 ~60 dirt
setblock ~17 ~124 ~61 dirt
setblock ~17 ~124 ~62 dirt
setblock ~17 ~124 ~63 dirt
setblock ~17 ~124 ~64 dirt
setblock ~17 ~124 ~65 dirt
setblock ~17 ~124 ~66 grass_block
setblock ~17 ~124 ~67 grass_block
setblock ~17 ~124 ~68 grass_block
setblock ~17 ~124 ~69 grass_block
setblock ~17 ~124 ~72 short_grass
setblock ~17 ~124 ~73 grass_block
setblock ~17 ~124 ~74 grass_block
setblock ~17 ~124 ~88 dirt
setblock ~17 ~124 ~89 dirt
setblock ~17 ~124 ~90 dirt
setblock ~17 ~124 ~91 dirt
setblock ~17 ~124 ~92 dirt
setblock ~17 ~124 ~93 dirt
setblock ~17 ~124 ~94 dirt
setblock ~17 ~124 ~95 dirt
setblock ~17 ~124 ~96 grass_block
setblock ~17 ~124 ~97 grass_block
setblock ~17 ~124 ~98 grass_block
setblock ~17 ~124 ~99 grass_block
setblock ~17 ~124 ~101 grass_block
setblock ~17 ~124 ~102 grass_block
setblock ~17 ~124 ~103 grass_block
setblock ~17 ~124 ~104 dirt
setblock ~17 ~124 ~105 dirt
setblock ~17 ~124 ~106 dirt
setblock ~17 ~124 ~107 dirt
setblock ~17 ~124 ~108 dirt
setblock ~17 ~124 ~109 dirt
setblock ~17 ~124 ~110 dirt
setblock ~17 ~124 ~111 dirt
setblock ~17 ~124 ~112 dirt
setblock ~17 ~124 ~113 dirt
setblock ~17 ~124 ~114 dirt
setblock ~17 ~124 ~115 dirt
setblock ~17 ~124 ~116 dirt
setblock ~17 ~124 ~117 dirt
setblock ~17 ~124 ~118 dirt
setblock ~17 ~124 ~119 dirt
setblock ~17 ~124 ~120 dirt
setblock ~17 ~124 ~121 dirt
setblock ~17 ~124 ~122 dirt
setblock ~17 ~124 ~123 dirt
setblock ~17 ~124 ~124 dirt
setblock ~17 ~124 ~125 grass_block
setblock ~17 ~124 ~126 grass_block
setblock ~17 ~124 ~127 grass_block
setblock ~17 ~124 ~128 grass_block
setblock ~17 ~124 ~134 short_grass
setblock ~17 ~125 ~59 dirt
setblock ~17 ~125 ~60 dirt
setblock ~17 ~125 ~61 dirt
setblock ~17 ~125 ~62 dirt
setblock ~17 ~125 ~63 dirt
setblock ~17 ~125 ~64 grass_block
setblock ~17 ~125 ~65 grass_block
setblock ~17 ~125 ~66 short_grass
setblock ~17 ~125 ~69 short_grass
setblock ~17 ~125 ~88 dirt
setblock ~17 ~125 ~89 dirt
setblock ~17 ~125 ~90 dirt
setblock ~17 ~125 ~91 dirt
setblock ~17 ~125 ~92 dirt
setblock ~17 ~125 ~93 grass_block
setblock ~17 ~125 ~94 grass_block
setblock ~17 ~125 ~95 grass_block
setblock ~17 ~125 ~97 short_grass
setblock ~17 ~125 ~101 short_grass
setblock ~17 ~125 ~104 grass_block
setblock ~17 ~125 ~105 grass_block
setblock ~17 ~125 ~106 grass_block
setblock ~17 ~125 ~107 dirt
setblock ~17 ~125 ~108 dirt
setblock ~17 ~125 ~109 dirt
setblock ~17 ~125 ~110 dirt
setblock ~17 ~125 ~111 dirt
setblock ~17 ~125 ~112 dirt
setblock ~17 ~125 ~113 dirt
setblock ~17 ~125 ~114 dirt
setblock ~17 ~125 ~115 dirt
setblock ~17 ~125 ~116 dirt
setblock ~17 ~125 ~117 grass_block
setblock ~17 ~125 ~118 grass_block
setblock ~17 ~125 ~119 grass_block
setblock ~17 ~125 ~120 grass_block
setblock ~17 ~125 ~121 grass_block
setblock ~17 ~125 ~122 grass_block
setblock ~17 ~125 ~123 grass_block
setblock ~17 ~125 ~124 grass_block
setblock ~17 ~125 ~125 short_grass
setblock ~17 ~125 ~126 short_grass
setblock ~17 ~126 ~59 dirt
setblock ~17 ~126 ~60 dirt
setblock ~17 ~126 ~61 grass_block
setblock ~17 ~126 ~62 grass_block
setblock ~17 ~126 ~63 grass_block
setblock ~17 ~126 ~88 grass_block
setblock ~17 ~126 ~89 dirt
setblock ~17 ~126 ~90 dirt
setblock ~17 ~126 ~91 dirt
setblock ~17 ~126 ~92 grass_block
setblock ~17 ~126 ~93 fern
setblock ~17 ~126 ~105 short_grass
setblock ~17 ~126 ~107 grass_block
setblock ~17 ~126 ~108 grass_block
setblock ~17 ~126 ~109 grass_block
setblock ~17 ~126 ~110 grass_block
setblock ~17 ~126 ~111 grass_block
setblock ~17 ~126 ~112 grass_block
setblock ~17 ~126 ~113 grass_block
setblock ~17 ~126 ~114 grass_block
setblock ~17 ~126 ~115 grass_block
setblock ~17 ~126 ~116 grass_block
setblock ~17 ~126 ~118 fern
setblock ~17 ~126 ~121 short_grass
setblock ~17 ~127 ~59 grass_block
setblock ~17 ~127 ~60 grass_block
setblock ~17 ~127 ~61 short_grass
setblock ~17 ~127 ~88 short_grass
setblock ~17 ~127 ~89 grass_block
setblock ~17 ~127 ~90 dirt
setblock ~17 ~127 ~91 grass_block
setblock ~17 ~127 ~108 fern
setblock ~17 ~127 ~110 fern
setblock ~17 ~127 ~115 short_grass
setblock ~17 ~128 ~90 grass_block
setblock ~18 ~105 ~100 dirt
setblock ~18 ~106 ~99 dirt
setblock ~18 ~106 ~100 dirt
setblock ~18 ~106 ~101 dirt
setblock ~18 ~107 ~98 dirt
setblock ~18 ~107 ~99 dirt
setblock ~18 ~107 ~100 dirt
setblock ~18 ~107 ~101 dirt
setblock ~18 ~107 ~102 dirt
setblock ~18 ~108 ~97 dirt
setblock ~18 ~108 ~98 dirt
setblock ~18 ~108 ~99 dirt
setblock ~18 ~108 ~100 dirt
setblock ~18 ~108 ~101 dirt
setblock ~18 ~108 ~102 dirt
setblock ~18 ~108 ~103 dirt
setblock ~18 ~109 ~97 dirt
setblock ~18 ~109 ~98 dirt
setblock ~18 ~109 ~99 dirt
setblock ~18 ~109 ~100 dirt
setblock ~18 ~109 ~101 dirt
setblock ~18 ~109 ~102 dirt
setblock ~18 ~109 ~103 dirt
setblock ~18 ~109 ~104 dirt
setblock ~18 ~110 ~96 dirt
setblock ~18 ~110 ~97 dirt
setblock ~18 ~110 ~98 dirt
setblock ~18 ~110 ~99 dirt
setblock ~18 ~110 ~100 dirt
setblock ~18 ~110 ~101 dirt
setblock ~18 ~110 ~102 dirt
setblock ~18 ~110 ~103 dirt
setblock ~18 ~110 ~104 dirt
setblock ~18 ~110 ~105 dirt
setblock ~18 ~111 ~95 dirt
setblock ~18 ~111 ~96 dirt
setblock ~18 ~111 ~97 dirt
setblock ~18 ~111 ~98 dirt
setblock ~18 ~111 ~99 dirt
setblock ~18 ~111 ~100 dirt
setblock ~18 ~111 ~101 dirt
setblock ~18 ~111 ~102 dirt
setblock ~18 ~111 ~103 dirt
setblock ~18 ~111 ~104 dirt
setblock ~18 ~111 ~105 dirt
setblock ~18 ~111 ~106 dirt
setblock ~18 ~112 ~94 dirt
setblock ~18 ~112 ~95 dirt
setblock ~18 ~112 ~96 dirt
setblock ~18 ~112 ~97 dirt
setblock ~18 ~112 ~98 dirt
setblock ~18 ~112 ~99 dirt
setblock ~18 ~112 ~100 dirt
setblock ~18 ~112 ~101 dirt
setblock ~18 ~112 ~102 dirt
setblock ~18 ~112 ~103 dirt
setblock ~18 ~112 ~104 dirt
setblock ~18 ~112 ~105 dirt
setblock ~18 ~112 ~106 dirt
setblock ~18 ~112 ~107 dirt
setblock ~18 ~113 ~93 dirt
setblock ~18 ~113 ~94 dirt
setblock ~18 ~113 ~95 dirt
setblock ~18 ~113 ~96 dirt
setblock ~18 ~113 ~97 dirt
setblock ~18 ~113 ~98 dirt
setblock ~18 ~113 ~99 dirt
setblock ~18 ~113 ~100 dirt
setblock ~18 ~113 ~101 dirt
setblock ~18 ~113 ~102 dirt
setblock ~18 ~113 ~103 dirt
setblock ~18 ~113 ~104 dirt
setblock ~18 ~113 ~105 dirt
setblock ~18 ~113 ~106 dirt
setblock ~18 ~113 ~107 dirt
setblock ~18 ~113 ~108 dirt
setblock ~18 ~114 ~92 dirt
setblock ~18 ~114 ~93 dirt
setblock ~18 ~114 ~94 dirt
setblock ~18 ~114 ~95 dirt
setblock ~18 ~114 ~96 dirt
setblock ~18 ~114 ~97 dirt
setblock ~18 ~114 ~98 dirt
setblock ~18 ~114 ~99 dirt
setblock ~18 ~114 ~100 dirt
setblock ~18 ~114 ~101 dirt
setblock ~18 ~114 ~102 dirt
setblock ~18 ~114 ~103 dirt
setblock ~18 ~114 ~104 dirt
setblock ~18 ~114 ~105 dirt
setblock ~18 ~114 ~106 dirt
setblock ~18 ~114 ~107 dirt
setblock ~18 ~114 ~108 dirt
setblock ~18 ~115 ~91 dirt
setblock ~18 ~115 ~92 dirt
setblock ~18 ~115 ~93 dirt
setblock ~18 ~115 ~94 dirt
setblock ~18 ~115 ~95 dirt
setblock ~18 ~115 ~96 dirt
setblock ~18 ~115 ~97 dirt
setblock ~18 ~115 ~98 dirt
setblock ~18 ~115 ~99 dirt
setblock ~18 ~115 ~100 dirt
setblock ~18 ~115 ~101 dirt
setblock ~18 ~115 ~102 dirt
setblock ~18 ~115 ~103 dirt
setblock ~18 ~115 ~104 dirt
setblock ~18 ~115 ~105 dirt
setblock ~18 ~115 ~106 dirt
setblock ~18 ~115 ~107 dirt
setblock ~18 ~115 ~108 dirt
setblock ~18 ~115 ~109 dirt
setblock ~18 ~115 ~125 dirt
setblock ~18 ~115 ~128 dirt
setblock ~18 ~116 ~70 dirt
setblock ~18 ~116 ~91 dirt
setblock ~18 ~116 ~92 dirt
setblock ~18 ~116 ~93 dirt
setblock ~18 ~116 ~94 dirt
setblock ~18 ~116 ~95 dirt
setblock ~18 ~116 ~96 dirt
setblock ~18 ~116 ~97 dirt
setblock ~18 ~116 ~98 dirt
setblock ~18 ~116 ~99 dirt
setblock ~18 ~116 ~100 dirt
setblock ~18 ~116 ~101 dirt
setblock ~18 ~116 ~102 dirt
setblock ~18 ~116 ~103 dirt
setblock ~18 ~116 ~104 dirt
setblock ~18 ~116 ~105 dirt
setblock ~18 ~116 ~106 dirt
setblock ~18 ~116 ~107 dirt
setblock ~18 ~116 ~108 dirt
setblock ~18 ~116 ~109 dirt
setblock ~18 ~116 ~110 dirt
setblock ~18 ~116 ~113 dirt
setblock ~18 ~116 ~122 dirt
setblock ~18 ~116 ~124 dirt
setblock ~18 ~116 ~125 dirt
setblock ~18 ~116 ~126 dirt
setblock ~18 ~116 ~127 dirt
setblock ~18 ~116 ~128 dirt
setblock ~18 ~116 ~129 dirt
setblock ~18 ~117 ~63 dirt
setblock ~18 ~117 ~64 dirt
setblock ~18 ~117 ~66 dirt
setblock ~18 ~117 ~67 dirt
setblock ~18 ~117 ~68 dirt
setblock ~18 ~117 ~70 dirt
setblock ~18 ~117 ~71 dirt
setblock ~18 ~117 ~90 dirt
setblock ~18 ~117 ~91 dirt
setblock ~18 ~117 ~92 dirt
setblock ~18 ~117 ~93 dirt
setblock ~18 ~117 ~94 dirt
setblock ~18 ~117 ~95 dirt
setblock ~18 ~117 ~96 dirt
setblock ~18 ~117 ~97 dirt
setblock ~18 ~117 ~98 dirt
setblock ~18 ~117 ~99 dirt
setblock ~18 ~117 ~100 dirt
setblock ~18 ~117 ~101 dirt
setblock ~18 ~117 ~102 dirt
setblock ~18 ~117 ~103 dirt
setblock ~18 ~117 ~104 dirt
setblock ~18 ~117 ~105 dirt
setblock ~18 ~117 ~106 dirt
setblock ~18 ~117 ~107 dirt
setblock ~18 ~117 ~108 dirt
setblock ~18 ~117 ~109 dirt
setblock ~18 ~117 ~110 dirt
setblock ~18 ~117 ~111 dirt
setblock ~18 ~117 ~112 dirt
setblock ~18 ~117 ~113 dirt
setblock ~18 ~117 ~114 dirt
setblock ~18 ~117 ~121 dirt
setblock ~18 ~117 ~122 dirt
setblock ~18 ~117 ~123 dirt
setblock ~18 ~117 ~124 dirt
setblock ~18 ~117 ~125 dirt
setblock ~18 ~117 ~126 dirt
setblock ~18 ~117 ~127 dirt
setblock ~18 ~117 ~128 dirt
setblock ~18 ~117 ~129 dirt
setblock ~18 ~117 ~130 dirt
setblock ~18 ~117 ~131 dirt
setblock ~18 ~118 ~62 dirt
setblock ~18 ~118 ~63 dirt
setblock ~18 ~118 ~64 dirt
setblock ~18 ~118 ~65 dirt
setblock ~18 ~118 ~66 dirt
setblock ~18 ~118 ~67 dirt
setblock ~18 ~118 ~68 dirt
setblock ~18 ~118 ~69 dirt
setblock ~18 ~118 ~70 dirt
setblock ~18 ~118 ~71 dirt
setblock ~18 ~118 ~72 dirt
setblock ~18 ~118 ~90 dirt
setblock ~18 ~118 ~91 dirt
setblock ~18 ~118 ~92 dirt
setblock ~18 ~118 ~93 dirt
setblock ~18 ~118 ~94 dirt
setblock ~18 ~118 ~95 dirt
setblock ~18 ~118 ~96 dirt
setblock ~18 ~118 ~97 dirt
setblock ~18 ~118 ~98 dirt
setblock ~18 ~118 ~99 dirt
setblock ~18 ~118 ~100 dirt
setblock ~18 ~118 ~101 dirt
setblock ~18 ~118 ~102 dirt
setblock ~18 ~118 ~103 dirt
setblock ~18 ~118 ~104 dirt
setblock ~18 ~118 ~105 dirt
setblock ~18 ~118 ~106 dirt
setblock ~18 ~118 ~107 dirt
setblock ~18 ~118 ~108 dirt
setblock ~18 ~118 ~109 dirt
setblock ~18 ~118 ~110 dirt
setblock ~18 ~118 ~111 dirt
setblock ~18 ~118 ~112 dirt
setblock ~18 ~118 ~113 dirt
setblock ~18 ~118 ~114 dirt
setblock ~18 ~118 ~115 dirt
setblock ~18 ~118 ~120 dirt
setblock ~18 ~118 ~121 dirt
setblock ~18 ~118 ~122 dirt
setblock ~18 ~118 ~123 dirt
setblock ~18 ~118 ~124 dirt
setblock ~18 ~118 ~125 dirt
setblock ~18 ~118 ~126 dirt
setblock ~18 ~118 ~127 dirt
setblock ~18 ~118 ~128 dirt
setblock ~18 ~118 ~129 dirt
setblock ~18 ~118 ~130 dirt
setblock ~18 ~118 ~131 dirt
setblock ~18 ~118 ~132 dirt
setblock ~18 ~119 ~61 dirt
setblock ~18 ~119 ~62 dirt
setblock ~18 ~119 ~63 dirt
setblock ~18 ~119 ~64 dirt
setblock ~18 ~119 ~65 dirt
setblock ~18 ~119 ~66 dirt
setblock ~18 ~119 ~67 dirt
setblock ~18 ~119 ~68 dirt
setblock ~18 ~119 ~69 dirt
setblock ~18 ~119 ~70 dirt
setblock ~18 ~119 ~71 dirt
setblock ~18 ~119 ~72 dirt
setblock ~18 ~119 ~89 dirt
setblock ~18 ~119 ~90 dirt
setblock ~18 ~119 ~91 dirt
setblock ~18 ~119 ~92 dirt
setblock ~18 ~119 ~93 dirt
setblock ~18 ~119 ~94 dirt
setblock ~18 ~119 ~95 dirt
setblock ~18 ~119 ~96 dirt
setblock ~18 ~119 ~97 dirt
setblock ~18 ~119 ~98 dirt
setblock ~18 ~119 ~99 dirt
setblock ~18 ~119 ~100 dirt
setblock ~18 ~119 ~101 dirt
setblock ~18 ~119 ~102 dirt
setblock ~18 ~119 ~103 dirt
setblock ~18 ~119 ~104 dirt
setblock ~18 ~119 ~105 dirt
setblock ~18 ~119 ~106 dirt
setblock ~18 ~119 ~107 dirt
setblock ~18 ~119 ~108 dirt
setblock ~18 ~119 ~109 dirt
setblock ~18 ~119 ~110 dirt
setblock ~18 ~119 ~111 dirt
setblock ~18 ~119 ~112 dirt
setblock ~18 ~119 ~113 dirt
setblock ~18 ~119 ~114 dirt
setblock ~18 ~119 ~115 dirt
setblock ~18 ~119 ~116 dirt
setblock ~18 ~119 ~118 dirt
setblock ~18 ~119 ~119 dirt
setblock ~18 ~119 ~120 dirt
setblock ~18 ~119 ~121 dirt
setblock ~18 ~119 ~122 dirt
setblock ~18 ~119 ~123 dirt
setblock ~18 ~119 ~124 dirt
setblock ~18 ~119 ~125 dirt
setblock ~18 ~119 ~126 dirt
setblock ~18 ~119 ~127 dirt
setblock ~18 ~119 ~128 dirt
setblock ~18 ~119 ~129 dirt
setblock ~18 ~119 ~130 dirt
setblock ~18 ~119 ~131 dirt
setblock ~18 ~119 ~132 dirt
setblock ~18 ~119 ~133 dirt
setblock ~18 ~120 ~59 dirt
setblock ~18 ~120 ~60 dirt
setblock ~18 ~120 ~61 dirt
setblock ~18 ~120 ~62 dirt
setblock ~18 ~120 ~63 dirt
setblock ~18 ~120 ~64 dirt
setblock ~18 ~120 ~65 dirt
setblock ~18 ~120 ~66 dirt
setblock ~18 ~120 ~67 dirt
setblock ~18 ~120 ~68 dirt
setblock ~18 ~120 ~69 dirt
setblock ~18 ~120 ~70 dirt
setblock ~18 ~120 ~71 dirt
setblock ~18 ~120 ~72 dirt
setblock ~18 ~120 ~88 dirt
setblock ~18 ~120 ~89 dirt
setblock ~18 ~120 ~90 dirt
setblock ~18 ~120 ~91 dirt
setblock ~18 ~120 ~92 dirt
setblock ~18 ~120 ~93 dirt
setblock ~18 ~120 ~94 dirt
setblock ~18 ~120 ~95 dirt
setblock ~18 ~120 ~96 dirt
setblock ~18 ~120 ~97 dirt
setblock ~18 ~120 ~98 dirt
setblock ~18 ~120 ~99 dirt
setblock ~18 ~120 ~100 dirt
setblock ~18 ~120 ~101 dirt
setblock ~18 ~120 ~102 dirt
setblock ~18 ~120 ~103 dirt
setblock ~18 ~120 ~104 dirt
setblock ~18 ~120 ~105 dirt
setblock ~18 ~120 ~106 dirt
setblock ~18 ~120 ~107 dirt
setblock ~18 ~120 ~108 dirt
setblock ~18 ~120 ~109 dirt
setblock ~18 ~120 ~110 dirt
setblock ~18 ~120 ~111 dirt
setblock ~18 ~120 ~112 dirt
setblock ~18 ~120 ~113 dirt
setblock ~18 ~120 ~114 dirt
setblock ~18 ~120 ~115 dirt
setblock ~18 ~120 ~116 dirt
setblock ~18 ~120 ~117 dirt
setblock ~18 ~120 ~118 dirt
setblock ~18 ~120 ~119 dirt
setblock ~18 ~120 ~120 dirt
setblock ~18 ~120 ~121 dirt
setblock ~18 ~120 ~122 dirt
setblock ~18 ~120 ~123 dirt
setblock ~18 ~120 ~124 dirt
setblock ~18 ~120 ~125 dirt
setblock ~18 ~120 ~126 dirt
setblock ~18 ~120 ~127 dirt
setblock ~18 ~120 ~128 dirt
setblock ~18 ~120 ~129 dirt
setblock ~18 ~120 ~130 dirt
setblock ~18 ~120 ~131 dirt
setblock ~18 ~120 ~132 dirt
setblock ~18 ~120 ~133 dirt
setblock ~18 ~120 ~134 dirt
setblock ~18 ~121 ~58 dirt
setblock ~18 ~121 ~59 dirt
setblock ~18 ~121 ~60 dirt
setblock ~18 ~121 ~61 dirt
setblock ~18 ~121 ~62 dirt
setblock ~18 ~121 ~63 dirt
setblock ~18 ~121 ~64 dirt
setblock ~18 ~121 ~65 dirt
setblock ~18 ~121 ~66 dirt
setblock ~18 ~121 ~67 dirt
setblock ~18 ~121 ~68 dirt
setblock ~18 ~121 ~69 dirt
setblock ~18 ~121 ~70 dirt
setblock ~18 ~121 ~71 dirt
setblock ~18 ~121 ~72 dirt
setblock ~18 ~121 ~73 dirt
setblock ~18 ~121 ~87 dirt
setblock ~18 ~121 ~88 dirt
setblock ~18 ~121 ~89 dirt
setblock ~18 ~121 ~90 dirt
setblock ~18 ~121 ~91 dirt
setblock ~18 ~121 ~92 dirt
setblock ~18 ~121 ~93 dirt
setblock ~18 ~121 ~94 dirt
setblock ~18 ~121 ~95 dirt
setblock ~18 ~121 ~96 dirt
setblock ~18 ~121 ~97 dirt
setblock ~18 ~121 ~98 dirt
setblock ~18 ~121 ~99 dirt
setblock ~18 ~121 ~100 dirt
setblock ~18 ~121 ~101 dirt
setblock ~18 ~121 ~102 dirt
setblock ~18 ~121 ~103 dirt
setblock ~18 ~121 ~104 dirt
setblock ~18 ~121 ~105 dirt
setblock ~18 ~121 ~106 dirt
setblock ~18 ~121 ~107 dirt
setblock ~18 ~121 ~108 dirt
setblock ~18 ~121 ~109 dirt
setblock ~18 ~121 ~110 dirt
setblock ~18 ~121 ~111 dirt
setblock ~18 ~121 ~112 dirt
setblock ~18 ~121 ~113 dirt
setblock ~18 ~121 ~114 dirt
setblock ~18 ~121 ~115 dirt
setblock ~18 ~121 ~116 dirt
setblock ~18 ~121 ~117 dirt
setblock ~18 ~121 ~118 dirt
setblock ~18 ~121 ~119 dirt
setblock ~18 ~121 ~120 dirt
setblock ~18 ~121 ~121 dirt
setblock ~18 ~121 ~122 dirt
setblock ~18 ~121 ~123 dirt
setblock ~18 ~121 ~124 dirt
setblock ~18 ~121 ~125 dirt
setblock ~18 ~121 ~126 dirt
setblock ~18 ~121 ~127 dirt
setblock ~18 ~121 ~128 dirt
setblock ~18 ~121 ~129 dirt
setblock ~18 ~121 ~130 dirt
setblock ~18 ~121 ~131 dirt
setblock ~18 ~121 ~132 dirt
setblock ~18 ~121 ~133 dirt
setblock ~18 ~121 ~134 dirt
setblock ~18 ~121 ~135 dirt
setblock ~18 ~122 ~58 dirt
setblock ~18 ~122 ~59 dirt
setblock ~18 ~122 ~60 dirt
setblock ~18 ~122 ~61 dirt
setblock ~18 ~122 ~62 dirt
setblock ~18 ~122 ~63 dirt
setblock ~18 ~122 ~64 dirt
setblock ~18 ~122 ~65 dirt
setblock ~18 ~122 ~66 dirt
setblock ~18 ~122 ~67 dirt
setblock ~18 ~122 ~68 dirt
setblock ~18 ~122 ~69 dirt
setblock ~18 ~122 ~70 dirt
setblock ~18 ~122 ~71 dirt
setblock ~18 ~122 ~72 dirt
setblock ~18 ~122 ~73 dirt
setblock ~18 ~122 ~87 dirt
setblock ~18 ~122 ~88 dirt
setblock ~18 ~122 ~89 dirt
setblock ~18 ~122 ~90 dirt
setblock ~18 ~122 ~91 dirt
setblock ~18 ~122 ~92 dirt
setblock ~18 ~122 ~93 dirt
setblock ~18 ~122 ~94 dirt
setblock ~18 ~122 ~95 dirt
setblock ~18 ~122 ~96 dirt
setblock ~18 ~122 ~97 dirt
setblock ~18 ~122 ~98 dirt
setblock ~18 ~122 ~99 dirt
setblock ~18 ~122 ~100 dirt
setblock ~18 ~122 ~101 dirt
setblock ~18 ~122 ~102 dirt
setblock ~18 ~122 ~103 dirt
setblock ~18 ~122 ~104 dirt
setblock ~18 ~122 ~105 dirt
setblock ~18 ~122 ~106 dirt
setblock ~18 ~122 ~107 dirt
setblock ~18 ~122 ~108 dirt
setblock ~18 ~122 ~109 dirt
setblock ~18 ~122 ~110 dirt
setblock ~18 ~122 ~111 dirt
setblock ~18 ~122 ~112 dirt
setblock ~18 ~122 ~113 dirt
setblock ~18 ~122 ~114 dirt
setblock ~18 ~122 ~115 dirt
setblock ~18 ~122 ~116 dirt
setblock ~18 ~122 ~117 dirt
setblock ~18 ~122 ~118 dirt
setblock ~18 ~122 ~119 dirt
setblock ~18 ~122 ~120 dirt
setblock ~18 ~122 ~121 dirt
setblock ~18 ~122 ~122 dirt
setblock ~18 ~122 ~123 dirt
setblock ~18 ~122 ~124 dirt
setblock ~18 ~122 ~125 dirt
setblock ~18 ~122 ~126 dirt
setblock ~18 ~122 ~127 dirt
setblock ~18 ~122 ~128 dirt
setblock ~18 ~122 ~129 dirt
setblock ~18 ~122 ~130 dirt
setblock ~18 ~122 ~131 dirt
setblock ~18 ~122 ~132 dirt
setblock ~18 ~122 ~133 dirt
setblock ~18 ~122 ~134 dirt
setblock ~18 ~122 ~135 dirt
setblock ~18 ~123 ~58 dirt
setblock ~18 ~123 ~59 dirt
setblock ~18 ~123 ~60 dirt
setblock ~18 ~123 ~61 dirt
setblock ~18 ~123 ~62 dirt
setblock ~18 ~123 ~63 dirt
setblock ~18 ~123 ~64 dirt
setblock ~18 ~123 ~65 dirt
setblock ~18 ~123 ~66 dirt
setblock ~18 ~123 ~67 dirt
setblock ~18 ~123 ~68 dirt
setblock ~18 ~123 ~69 dirt
setblock ~18 ~123 ~70 grass_block
setblock ~18 ~123 ~71 grass_block
setblock ~18 ~123 ~72 grass_block
setblock ~18 ~123 ~73 dirt
setblock ~18 ~123 ~87 dirt
setblock ~18 ~123 ~88 dirt
setblock ~18 ~123 ~89 dirt
setblock ~18 ~123 ~90 dirt
setblock ~18 ~123 ~91 dirt
setblock ~18 ~123 ~92 dirt
setblock ~18 ~123 ~93 dirt
setblock ~18 ~123 ~94 dirt
setblock ~18 ~123 ~95 dirt
setblock ~18 ~123 ~96 dirt
setblock ~18 ~123 ~97 dirt
setblock ~18 ~123 ~98 grass_block
setblock ~18 ~123 ~99 grass_block
setblock ~18 ~123 ~100 grass_block
setblock ~18 ~123 ~101 grass_block
setblock ~18 ~123 ~102 dirt
setblock ~18 ~123 ~103 dirt
setblock ~18 ~123 ~104 dirt
setblock ~18 ~123 ~105 dirt
setblock ~18 ~123 ~106 dirt
setblock ~18 ~123 ~107 dirt
setblock ~18 ~123 ~108 dirt
setblock ~18 ~123 ~109 dirt
setblock ~18 ~123 ~110 dirt
setblock ~18 ~123 ~111 dirt
setblock ~18 ~123 ~112 dirt
setblock ~18 ~123 ~113 dirt
setblock ~18 ~123 ~114 dirt
setblock ~18 ~123 ~115 dirt
setblock ~18 ~123 ~116 dirt
setblock ~18 ~123 ~117 dirt
setblock ~18 ~123 ~118 dirt
setblock ~18 ~123 ~119 dirt
setblock ~18 ~123 ~120 dirt
setblock ~18 ~123 ~121 dirt
setblock ~18 ~123 ~122 dirt
setblock ~18 ~123 ~123 dirt
setblock ~18 ~123 ~124 dirt
setblock ~18 ~123 ~125 dirt
setblock ~18 ~123 ~126 dirt
setblock ~18 ~123 ~127 dirt
setblock ~18 ~123 ~128 dirt
setblock ~18 ~123 ~129 dirt
setblock ~18 ~123 ~130 grass_block
setblock ~18 ~123 ~131 grass_block
setblock ~18 ~123 ~132 grass_block
setblock ~18 ~123 ~133 grass_block
setblock ~18 ~123 ~134 grass_block
setblock ~18 ~123 ~135 grass_block
setblock ~18 ~124 ~58 dirt
setblock ~18 ~124 ~59 dirt
setblock ~18 ~124 ~60 dirt
setblock ~18 ~124 ~61 dirt
setblock ~18 ~124 ~62 dirt
setblock ~18 ~124 ~63 dirt
setblock ~18 ~124 ~64 dirt
setblock ~18 ~124 ~65 dirt
setblock ~18 ~124 ~66 dirt
setblock ~18 ~124 ~67 grass_block
setblock ~18 ~124 ~68 grass_block
setblock ~18 ~124 ~69 grass_block
setblock ~18 ~124 ~71 short_grass
setblock ~18 ~124 ~73 grass_block
setblock ~18 ~124 ~87 dirt
setblock ~18 ~124 ~88 dirt
setblock ~18 ~124 ~89 dirt
setblock ~18 ~124 ~90 dirt
setblock ~18 ~124 ~91 dirt
setblock ~18 ~124 ~92 dirt
setblock ~18 ~124 ~93 dirt
setblock ~18 ~124 ~94 dirt
setblock ~18 ~124 ~95 dirt
setblock ~18 ~124 ~96 grass_block
setblock ~18 ~124 ~97 grass_block
setblock ~18 ~124 ~99 poppy
setblock ~18 ~124 ~100 short_grass
setblock ~18 ~124 ~102 grass_block
setblock ~18 ~124 ~103 grass_block
setblock ~18 ~124 ~104 dirt
setblock ~18 ~124 ~105 dirt
setblock ~18 ~124 ~106 dirt
setblock ~18 ~124 ~107 dirt
setblock ~18 ~124 ~108 dirt
setblock ~18 ~124 ~109 dirt
setblock ~18 ~124 ~110 dirt
setblock ~18 ~124 ~111 dirt
setblock ~18 ~124 ~112 dirt
setblock ~18 ~124 ~113 dirt
setblock ~18 ~124 ~114 dirt
setblock ~18 ~124 ~115 dirt
setblock ~18 ~124 ~116 dirt
setblock ~18 ~124 ~117 dirt
setblock ~18 ~124 ~118 dirt
setblock ~18 ~124 ~119 dirt
setblock ~18 ~124 ~120 dirt
setblock ~18 ~124 ~121 dirt
setblock ~18 ~124 ~122 dirt
setblock ~18 ~124 ~123 dirt
setblock ~18 ~124 ~124 dirt
setblock ~18 ~124 ~125 dirt
setblock ~18 ~124 ~126 grass_block
setblock ~18 ~124 ~127 grass_block
setblock ~18 ~124 ~128 grass_block
setblock ~18 ~124 ~129 grass_block
setblock ~18 ~124 ~134 short_grass
setblock ~18 ~125 ~58 dirt
setblock ~18 ~125 ~59 dirt
setblock ~18 ~125 ~60 dirt
setblock ~18 ~125 ~61 dirt
setblock ~18 ~125 ~62 dirt
setblock ~18 ~125 ~63 dirt
setblock ~18 ~125 ~64 grass_block
setblock ~18 ~125 ~65 grass_block
setblock ~18 ~125 ~66 grass_block
setblock ~18 ~125 ~87 dirt
setblock ~18 ~125 ~88 dirt
setblock ~18 ~125 ~89 dirt
setblock ~18 ~125 ~90 dirt
setblock ~18 ~125 ~91 dirt
setblock ~18 ~125 ~92 dirt
setblock ~18 ~125 ~93 dirt
setblock ~18 ~125 ~94 grass_block
setblock ~18 ~125 ~95 grass_block
setblock ~18 ~125 ~104 grass_block
setblock ~18 ~125 ~105 grass_block
setblock ~18 ~125 ~106 grass_block
setblock ~18 ~125 ~107 grass_block
setblock ~18 ~125 ~108 dirt
setblock ~18 ~125 ~109 dirt
setblock ~18 ~125 ~110 dirt
setblock ~18 ~125 ~111 dirt
setblock ~18 ~125 ~112 dirt
setblock ~18 ~125 ~113 dirt
setblock ~18 ~125 ~114 dirt
setblock ~18 ~125 ~115 dirt
setblock ~18 ~125 ~116 dirt
setblock ~18 ~125 ~117 dirt
setblock ~18 ~125 ~118 dirt
setblock ~18 ~125 ~119 grass_block
setblock ~18 ~125 ~120 grass_block
setblock ~18 ~125 ~121 grass_block
setblock ~18 ~125 ~122 grass_block
setblock ~18 ~125 ~123 grass_block
setblock ~18 ~125 ~124 grass_block
setblock ~18 ~125 ~125 grass_block
setblock ~18 ~125 ~126 fern
setblock ~18 ~125 ~127 short_grass
setblock ~18 ~125 ~129 short_grass
setblock ~18 ~126 ~58 dirt
setblock ~18 ~126 ~59 dirt
setblock ~18 ~126 ~60 dirt
setblock ~18 ~126 ~61 dirt
setblock ~18 ~126 ~62 grass_block
setblock ~18 ~126 ~63 grass_block
setblock ~18 ~126 ~64 short_grass
setblock ~18 ~126 ~66 fern
setblock ~18 ~126 ~87 dirt
setblock ~18 ~126 ~88 dirt
setblock ~18 ~126 ~89 dirt
setblock ~18 ~126 ~90 dirt
setblock ~18 ~126 ~91 dirt
setblock ~18 ~126 ~92 dirt
setblock ~18 ~126 ~93 grass_block
setblock ~18 ~126 ~104 fern
setblock ~18 ~126 ~105 short_grass
setblock ~18 ~126 ~108 grass_block
setblock ~18 ~126 ~109 grass_block
setblock ~18 ~126 ~110 grass_block
setblock ~18 ~126 ~111 grass_block
setblock ~18 ~126 ~112 grass_block
setblock ~18 ~126 ~113 grass_block
setblock ~18 ~126 ~114 grass_block
setblock ~18 ~126 ~115 grass_block
setblock ~18 ~126 ~116 grass_block
setblock ~18 ~126 ~117 grass_block
setblock ~18 ~126 ~118 grass_block
setblock ~18 ~126 ~123 short_grass
setblock ~18 ~127 ~58 grass_block
setblock ~18 ~127 ~59 grass_block
setblock ~18 ~127 ~60 grass_block
setblock ~18 ~127 ~61 grass_block
setblock ~18 ~127 ~87 grass_block
setblock ~18 ~127 ~88 grass_block
setblock ~18 ~127 ~89 dirt
setblock ~18 ~127 ~90 dirt
setblock ~18 ~127 ~91 dirt
setblock ~18 ~127 ~92 grass_block
setblock ~18 ~127 ~93 short_grass
setblock ~18 ~127 ~109 fern
setblock ~18 ~127 ~111 short_grass
setblock ~18 ~127 ~116 fern
setblock ~18 ~128 ~58 short_grass
setblock ~18 ~128 ~89 grass_block
setblock ~18 ~128 ~90 dirt
setblock ~18 ~128 ~91 grass_block
setblock ~18 ~129 ~90 grass_block
setblock ~18 ~129 ~91 short_grass
setblock ~19 ~104 ~100 dirt
setblock ~19 ~105 ~99 dirt
setblock ~19 ~105 ~100 dirt
setblock ~19 ~105 ~101 dirt
setblock ~19 ~106 ~98 dirt
setblock ~19 ~106 ~99 dirt
setblock ~19 ~106 ~100 dirt
setblock ~19 ~106 ~101 dirt
setblock ~19 ~106 ~102 dirt
setblock ~19 ~107 ~97 dirt
setblock ~19 ~107 ~98 dirt
setblock ~19 ~107 ~99 dirt
setblock ~19 ~107 ~100 dirt
setblock ~19 ~107 ~101 dirt
setblock ~19 ~107 ~102 dirt
setblock ~19 ~107 ~103 dirt
setblock ~19 ~108 ~97 dirt
setblock ~19 ~108 ~98 dirt
setblock ~19 ~108 ~99 dirt
setblock ~19 ~108 ~100 dirt
setblock ~19 ~108 ~101 dirt
setblock ~19 ~108 ~102 dirt
setblock ~19 ~108 ~103 dirt
setblock ~19 ~108 ~104 dirt
setblock ~19 ~109 ~96 dirt
setblock ~19 ~109 ~97 dirt
setblock ~19 ~109 ~98 dirt
setblock ~19 ~109 ~99 dirt
setblock ~19 ~109 ~100 dirt
setblock ~19 ~109 ~101 dirt
setblock ~19 ~109 ~102 dirt
setblock ~19 ~109 ~103 dirt
setblock ~19 ~109 ~104 dirt
setblock ~19 ~109 ~105 dirt
setblock ~19 ~110 ~95 dirt
setblock ~19 ~110 ~96 dirt
setblock ~19 ~110 ~97 dirt
setblock ~19 ~110 ~98 dirt
setblock ~19 ~110 ~99 dirt
setblock ~19 ~110 ~100 dirt
setblock ~19 ~110 ~101 dirt
setblock ~19 ~110 ~102 dirt
setblock ~19 ~110 ~103 dirt
setblock ~19 ~110 ~104 dirt
setblock ~19 ~110 ~105 dirt
setblock ~19 ~110 ~106 dirt
setblock ~19 ~111 ~94 dirt
setblock ~19 ~111 ~95 dirt
setblock ~19 ~111 ~96 dirt
setblock ~19 ~111 ~97 dirt
setblock ~19 ~111 ~98 dirt
setblock ~19 ~111 ~99 dirt
setblock ~19 ~111 ~100 dirt
setblock ~19 ~111 ~101 dirt
setblock ~19 ~111 ~102 dirt
setblock ~19 ~111 ~103 dirt
setblock ~19 ~111 ~104 dirt
setblock ~19 ~111 ~105 dirt
setblock ~19 ~111 ~106 dirt
setblock ~19 ~111 ~107 dirt
setblock ~19 ~112 ~93 dirt
setblock ~19 ~112 ~94 dirt
setblock ~19 ~112 ~95 dirt
setblock ~19 ~112 ~96 dirt
setblock ~19 ~112 ~97 dirt
setblock ~19 ~112 ~98 dirt
setblock ~19 ~112 ~99 dirt
setblock ~19 ~112 ~100 dirt
setblock ~19 ~112 ~101 dirt
setblock ~19 ~112 ~102 dirt
setblock ~19 ~112 ~103 dirt
setblock ~19 ~112 ~104 dirt
setblock ~19 ~112 ~105 dirt
setblock ~19 ~112 ~106 dirt
setblock ~19 ~112 ~107 dirt
setblock ~19 ~112 ~108 dirt
setblock ~19 ~113 ~93 dirt
setblock ~19 ~113 ~94 dirt
setblock ~19 ~113 ~95 dirt
setblock ~19 ~113 ~96 dirt
setblock ~19 ~113 ~97 dirt
setblock ~19 ~113 ~98 dirt
setblock ~19 ~113 ~99 dirt
setblock ~19 ~113 ~100 dirt
setblock ~19 ~113 ~101 dirt
setblock ~19 ~113 ~102 dirt
setblock ~19 ~113 ~103 dirt
setblock ~19 ~113 ~104 dirt
setblock ~19 ~113 ~105 dirt
setblock ~19 ~113 ~106 dirt
setblock ~19 ~113 ~107 dirt
setblock ~19 ~113 ~108 dirt
setblock ~19 ~114 ~92 dirt
setblock ~19 ~114 ~93 dirt
setblock ~19 ~114 ~94 dirt
setblock ~19 ~114 ~95 dirt
setblock ~19 ~114 ~96 dirt
setblock ~19 ~114 ~97 dirt
setblock ~19 ~114 ~98 dirt
setblock ~19 ~114 ~99 dirt
setblock ~19 ~114 ~100 dirt
setblock ~19 ~114 ~101 dirt
setblock ~19 ~114 ~102 dirt
setblock ~19 ~114 ~103 dirt
setblock ~19 ~114 ~104 dirt
setblock ~19 ~114 ~105 dirt
setblock ~19 ~114 ~106 dirt
setblock ~19 ~114 ~107 dirt
setblock ~19 ~114 ~108 dirt
setblock ~19 ~114 ~109 dirt
setblock ~19 ~114 ~125 dirt
setblock ~19 ~114 ~128 dirt
setblock ~19 ~115 ~63 dirt
setblock ~19 ~115 ~66 dirt
setblock ~19 ~115 ~67 dirt
setblock ~19 ~115 ~91 dirt
setblock ~19 ~115 ~92 dirt
setblock ~19 ~115 ~93 dirt
setblock ~19 ~115 ~94 dirt
setblock ~19 ~115 ~95 dirt
setblock ~19 ~115 ~96 dirt
setblock ~19 ~115 ~97 dirt
setblock ~19 ~115 ~98 dirt
setblock ~19 ~115 ~99 dirt
setblock ~19 ~115 ~100 dirt
setblock ~19 ~115 ~101 dirt
setblock ~19 ~115 ~102 dirt
setblock ~19 ~115 ~103 dirt
setblock ~19 ~115 ~104 dirt
setblock ~19 ~115 ~105 dirt
setblock ~19 ~115 ~106 dirt
setblock ~19 ~115 ~107 dirt
setblock ~19 ~115 ~108 dirt
setblock ~19 ~115 ~109 dirt
setblock ~19 ~115 ~113 dirt
setblock ~19 ~115 ~122 dirt
setblock ~19 ~115 ~124 dirt
setblock ~19 ~115 ~125 dirt
setblock ~19 ~115 ~126 dirt
setblock ~19 ~115 ~127 dirt
setblock ~19 ~115 ~128 dirt
setblock ~19 ~115 ~129 dirt
setblock ~19 ~116 ~62 dirt
setblock ~19 ~116 ~63 dirt
setblock ~19 ~116 ~64 dirt
setblock ~19 ~116 ~65 dirt
setblock ~19 ~116 ~66 dirt
setblock ~19 ~116 ~67 dirt
setblock ~19 ~116 ~68 dirt
setblock ~19 ~116 ~91 dirt
setblock ~19 ~116 ~92 dirt
setblock ~19 ~116 ~93 dirt
setblock ~19 ~116 ~94 dirt
setblock ~19 ~116 ~95 dirt
setblock ~19 ~116 ~96 dirt
setblock ~19 ~116 ~97 dirt
setblock ~19 ~116 ~98 dirt
setblock ~19 ~116 ~99 dirt
setblock ~19 ~116 ~100 dirt
setblock ~19 ~116 ~101 dirt
setblock ~19 ~116 ~102 dirt
setblock ~19 ~116 ~103 dirt
setblock ~19 ~116 ~104 dirt
setblock ~19 ~116 ~105 dirt
setblock ~19 ~116 ~106 dirt
setblock ~19 ~116 ~107 dirt
setblock ~19 ~116 ~108 dirt
setblock ~19 ~116 ~109 dirt
setblock ~19 ~116 ~110 dirt
setblock ~19 ~116 ~112 dirt
setblock ~19 ~116 ~113 dirt
setblock ~19 ~116 ~114 dirt
setblock ~19 ~116 ~115 dirt
setblock ~19 ~116 ~121 dirt
setblock ~19 ~116 ~122 dirt
setblock ~19 ~116 ~123 dirt
setblock ~19 ~116 ~124 dirt
setblock ~19 ~116 ~125 dirt
setblock ~19 ~116 ~126 dirt
setblock ~19 ~116 ~127 dirt
setblock ~19 ~116 ~128 dirt
setblock ~19 ~116 ~129 dirt
setblock ~19 ~116 ~130 dirt
setblock ~19 ~116 ~131 dirt
setblock ~19 ~117 ~61 dirt
setblock ~19 ~117 ~62 dirt
setblock ~19 ~117 ~63 dirt
setblock ~19 ~117 ~64 dirt
setblock ~19 ~117 ~65 dirt
setblock ~19 ~117 ~66 dirt
setblock ~19 ~117 ~67 dirt
setblock ~19 ~117 ~68 dirt
setblock ~19 ~117 ~69 dirt
setblock ~19 ~117 ~90 dirt
setblock ~19 ~117 ~91 dirt
setblock ~19 ~117 ~92 dirt
setblock ~19 ~117 ~93 dirt
setblock ~19 ~117 ~94 dirt
setblock ~19 ~117 ~95 dirt
setblock ~19 ~117 ~96 dirt
setblock ~19 ~117 ~97 dirt
setblock ~19 ~117 ~98 dirt
setblock ~19 ~117 ~99 dirt
setblock ~19 ~117 ~100 dirt
setblock ~19 ~117 ~101 dirt
setblock ~19 ~117 ~102 dirt
setblock ~19 ~117 ~103 dirt
setblock ~19 ~117 ~104 dirt
setblock ~19 ~117 ~105 dirt
setblock ~19 ~117 ~106 dirt
setblock ~19 ~117 ~107 dirt
setblock ~19 ~117 ~108 dirt
setblock ~19 ~117 ~109 dirt
setblock ~19 ~117 ~110 dirt
setblock ~19 ~117 ~111 dirt
setblock ~19 ~117 ~112 dirt
setblock ~19 ~117 ~113 dirt
setblock ~19 ~117 ~114 dirt
setblock ~19 ~117 ~115 dirt
setblock ~19 ~117 ~120 dirt
setblock ~19 ~117 ~121 dirt
setblock ~19 ~117 ~122 dirt
setblock ~19 ~117 ~123 dirt
setblock ~19 ~117 ~124 dirt
setblock ~19 ~117 ~125 dirt
setblock ~19 ~117 ~126 dirt
setblock ~19 ~117 ~127 dirt
setblock ~19 ~117 ~128 dirt
setblock ~19 ~117 ~129 dirt
setblock ~19 ~117 ~130 dirt
setblock ~19 ~117 ~131 dirt
setblock ~19 ~117 ~132 dirt
setblock ~19 ~118 ~60 dirt
setblock ~19 ~118 ~61 dirt
setblock ~19 ~118 ~62 dirt
setblock ~19 ~118 ~63 dirt
setblock ~19 ~118 ~64 dirt
setblock ~19 ~118 ~65 dirt
setblock ~19 ~118 ~66 dirt
setblock ~19 ~118 ~67 dirt
setblock ~19 ~118 ~68 dirt
setblock ~19 ~118 ~69 dirt
setblock ~19 ~118 ~70 dirt
setblock ~19 ~118 ~89 dirt
setblock ~19 ~118 ~90 dirt
setblock ~19 ~118 ~91 dirt
setblock ~19 ~118 ~92 dirt
setblock ~19 ~118 ~93 dirt
setblock ~19 ~118 ~94 dirt
setblock ~19 ~118 ~95 dirt
setblock ~19 ~118 ~96 dirt
setblock ~19 ~118 ~97 dirt
setblock ~19 ~118 ~98 dirt
setblock ~19 ~118 ~99 dirt
setblock ~19 ~118 ~100 dirt
setblock ~19 ~118 ~101 dirt
setblock ~19 ~118 ~102 dirt
setblock ~19 ~118 ~103 dirt
setblock ~19 ~118 ~104 dirt
setblock ~19 ~118 ~105 dirt
setblock ~19 ~118 ~106 dirt
setblock ~19 ~118 ~107 dirt
setblock ~19 ~118 ~108 dirt
setblock ~19 ~118 ~109 dirt
setblock ~19 ~118 ~110 dirt
setblock ~19 ~118 ~111 dirt
setblock ~19 ~118 ~112 dirt
setblock ~19 ~118 ~113 dirt
setblock ~19 ~118 ~114 dirt
setblock ~19 ~118 ~115 dirt
setblock ~19 ~118 ~116 dirt
setblock ~19 ~118 ~118 dirt
setblock ~19 ~118 ~119 dirt
setblock ~19 ~118 ~120 dirt
setblock ~19 ~118 ~121 dirt
setblock ~19 ~118 ~122 dirt
setblock ~19 ~118 ~123 dirt
setblock ~19 ~118 ~124 dirt
setblock ~19 ~118 ~125 dirt
setblock ~19 ~118 ~126 dirt
setblock ~19 ~118 ~127 dirt
setblock ~19 ~118 ~128 dirt
setblock ~19 ~118 ~129 dirt
setblock ~19 ~118 ~130 dirt
setblock ~19 ~118 ~131 dirt
setblock ~19 ~118 ~132 dirt
setblock ~19 ~118 ~133 dirt
setblock ~19 ~119 ~59 dirt
setblock ~19 ~119 ~60 dirt
setblock ~19 ~119 ~61 dirt
setblock ~19 ~119 ~62 dirt
setblock ~19 ~119 ~63 dirt
setblock ~19 ~119 ~64 dirt
setblock ~19 ~119 ~65 dirt
setblock ~19 ~119 ~66 dirt
setblock ~19 ~119 ~67 dirt
setblock ~19 ~119 ~68 dirt
setblock ~19 ~119 ~69 dirt
setblock ~19 ~119 ~70 dirt
setblock ~19 ~119 ~71 dirt
setblock ~19 ~119 ~88 dirt
setblock ~19 ~119 ~89 dirt
setblock ~19 ~119 ~90 dirt
setblock ~19 ~119 ~91 dirt
setblock ~19 ~119 ~92 dirt
setblock ~19 ~119 ~93 dirt
setblock ~19 ~119 ~94 dirt
setblock ~19 ~119 ~95 dirt
setblock ~19 ~119 ~96 dirt
setblock ~19 ~119 ~97 dirt
setblock ~19 ~119 ~98 dirt
setblock ~19 ~119 ~99 dirt
setblock ~19 ~119 ~100 dirt
setblock ~19 ~119 ~101 dirt
setblock ~19 ~119 ~102 dirt
setblock ~19 ~119 ~103 dirt
setblock ~19 ~119 ~104 dirt
setblock ~19 ~119 ~105 dirt
setblock ~19 ~119 ~106 dirt
setblock ~19 ~119 ~107 dirt
setblock ~19 ~119 ~108 dirt
setblock ~19 ~119 ~109 dirt
setblock ~19 ~119 ~110 dirt
setblock ~19 ~119 ~111 dirt
setblock ~19 ~119 ~112 dirt
setblock ~19 ~119 ~113 dirt
setblock ~19 ~119 ~114 dirt
setblock ~19 ~119 ~115 dirt
setblock ~19 ~119 ~116 dirt
setblock ~19 ~119 ~117 dirt
setblock ~19 ~119 ~118 dirt
setblock ~19 ~119 ~119 dirt
setblock ~19 ~119 ~120 dirt
setblock ~19 ~119 ~121 dirt
setblock ~19 ~119 ~122 dirt
setblock ~19 ~119 ~123 dirt
setblock ~19 ~119 ~124 dirt
setblock ~19 ~119 ~125 dirt
setblock ~19 ~119 ~126 dirt
setblock ~19 ~119 ~127 dirt
setblock ~19 ~119 ~128 dirt
setblock ~19 ~119 ~129 dirt
setblock ~19 ~119 ~130 dirt
setblock ~19 ~119 ~131 dirt
setblock ~19 ~119 ~132 dirt
setblock ~19 ~119 ~133 dirt
setblock ~19 ~119 ~134 dirt
setblock ~19 ~120 ~58 dirt
setblock ~19 ~120 ~59 dirt
setblock ~19 ~120 ~60 dirt
setblock ~19 ~120 ~61 dirt
setblock ~19 ~120 ~62 dirt
setblock ~19 ~120 ~63 dirt
setblock ~19 ~120 ~64 dirt
setblock ~19 ~120 ~65 dirt
setblock ~19 ~120 ~66 dirt
setblock ~19 ~120 ~67 dirt
setblock ~19 ~120 ~68 dirt
setblock ~19 ~120 ~69 dirt
setblock ~19 ~120 ~70 dirt
setblock ~19 ~120 ~71 dirt
setblock ~19 ~120 ~72 dirt
setblock ~19 ~120 ~87 dirt
setblock ~19 ~120 ~88 dirt
setblock ~19 ~120 ~89 dirt
setblock ~19 ~120 ~90 dirt
setblock ~19 ~120 ~91 dirt
setblock ~19 ~120 ~92 dirt
setblock ~19 ~120 ~93 dirt
setblock ~19 ~120 ~94 dirt
setblock ~19 ~120 ~95 dirt
setblock ~19 ~120 ~96 dirt
setblock ~19 ~120 ~97 dirt
setblock ~19 ~120 ~98 dirt
setblock ~19 ~120 ~99 dirt
setblock ~19 ~120 ~100 dirt
setblock ~19 ~120 ~101 dirt
setblock ~19 ~120 ~102 dirt
setblock ~19 ~120 ~103 dirt
setblock ~19 ~120 ~104 dirt
setblock ~19 ~120 ~105 dirt
setblock ~19 ~120 ~106 dirt
setblock ~19 ~120 ~107 dirt
setblock ~19 ~120 ~108 dirt
setblock ~19 ~120 ~109 dirt
setblock ~19 ~120 ~110 dirt
setblock ~19 ~120 ~111 dirt
setblock ~19 ~120 ~112 dirt
setblock ~19 ~120 ~113 dirt
