setblock ~168 ~113 ~95 dirt
setblock ~168 ~113 ~96 dirt
setblock ~168 ~113 ~97 dirt
setblock ~168 ~113 ~98 dirt
setblock ~168 ~113 ~99 dirt
setblock ~168 ~113 ~100 dirt
setblock ~168 ~113 ~101 dirt
setblock ~168 ~113 ~102 dirt
setblock ~168 ~114 ~86 dirt
setblock ~168 ~114 ~87 dirt
setblock ~168 ~114 ~88 dirt
setblock ~168 ~114 ~89 dirt
setblock ~168 ~114 ~90 dirt
setblock ~168 ~114 ~91 dirt
setblock ~168 ~114 ~92 dirt
setblock ~168 ~114 ~93 dirt
setblock ~168 ~114 ~94 dirt
setblock ~168 ~114 ~95 dirt
setblock ~168 ~114 ~96 dirt
setblock ~168 ~114 ~97 dirt
setblock ~168 ~114 ~98 dirt
setblock ~168 ~114 ~99 dirt
setblock ~168 ~114 ~100 dirt
setblock ~168 ~114 ~101 dirt
setblock ~168 ~114 ~102 dirt
setblock ~168 ~114 ~112 dirt
setblock ~168 ~115 ~86 dirt
setblock ~168 ~115 ~87 dirt
setblock ~168 ~115 ~88 dirt
setblock ~168 ~115 ~89 dirt
setblock ~168 ~115 ~90 dirt
setblock ~168 ~115 ~91 dirt
setblock ~168 ~115 ~92 dirt
setblock ~168 ~115 ~93 dirt
setblock ~168 ~115 ~94 dirt
setblock ~168 ~115 ~95 dirt
setblock ~168 ~115 ~96 dirt
setblock ~168 ~115 ~97 dirt
setblock ~168 ~115 ~98 dirt
setblock ~168 ~115 ~99 dirt
setblock ~168 ~115 ~100 dirt
setblock ~168 ~115 ~101 dirt
setblock ~168 ~115 ~102 dirt
setblock ~168 ~115 ~111 dirt
setblock ~168 ~115 ~112 dirt
setblock ~168 ~115 ~113 dirt
setblock ~168 ~116 ~82 dirt
setblock ~168 ~116 ~85 dirt
setblock ~168 ~116 ~86 dirt
setblock ~168 ~116 ~87 dirt
setblock ~168 ~116 ~88 dirt
setblock ~168 ~116 ~89 dirt
setblock ~168 ~116 ~90 dirt
setblock ~168 ~116 ~91 dirt
setblock ~168 ~116 ~92 dirt
setblock ~168 ~116 ~93 dirt
setblock ~168 ~116 ~94 dirt
setblock ~168 ~116 ~95 dirt
setblock ~168 ~116 ~96 dirt
setblock ~168 ~116 ~97 dirt
setblock ~168 ~116 ~98 dirt
setblock ~168 ~116 ~99 dirt
setblock ~168 ~116 ~100 dirt
setblock ~168 ~116 ~101 dirt
setblock ~168 ~116 ~102 dirt
setblock ~168 ~116 ~110 dirt
setblock ~168 ~116 ~111 dirt
setblock ~168 ~116 ~112 dirt
setblock ~168 ~116 ~113 dirt
setblock ~168 ~116 ~114 dirt
setblock ~168 ~117 ~82 dirt
setblock ~168 ~117 ~85 dirt
setblock ~168 ~117 ~86 dirt
setblock ~168 ~117 ~87 dirt
setblock ~168 ~117 ~88 dirt
setblock ~168 ~117 ~89 dirt
setblock ~168 ~117 ~90 dirt
setblock ~168 ~117 ~91 dirt
setblock ~168 ~117 ~92 dirt
setblock ~168 ~117 ~93 dirt
setblock ~168 ~117 ~94 dirt
setblock ~168 ~117 ~95 dirt
setblock ~168 ~117 ~96 dirt
setblock ~168 ~117 ~97 dirt
setblock ~168 ~117 ~98 dirt
setblock ~168 ~117 ~99 dirt
setblock ~168 ~117 ~100 dirt
setblock ~168 ~117 ~101 dirt
setblock ~168 ~117 ~102 dirt
setblock ~168 ~117 ~103 dirt
setblock ~168 ~117 ~109 dirt
setblock ~168 ~117 ~110 dirt
setblock ~168 ~117 ~111 dirt
setblock ~168 ~117 ~112 dirt
setblock ~168 ~117 ~113 dirt
setblock ~168 ~117 ~114 dirt
setblock ~168 ~117 ~115 dirt
setblock ~168 ~118 ~80 dirt
setblock ~168 ~118 ~82 dirt
setblock ~168 ~118 ~83 dirt
setblock ~168 ~118 ~84 dirt
setblock ~168 ~118 ~85 dirt
setblock ~168 ~118 ~86 dirt
setblock ~168 ~118 ~87 dirt
setblock ~168 ~118 ~88 dirt
setblock ~168 ~118 ~89 dirt
setblock ~168 ~118 ~90 dirt
setblock ~168 ~118 ~91 dirt
setblock ~168 ~118 ~92 dirt
setblock ~168 ~118 ~93 dirt
setblock ~168 ~118 ~94 dirt
setblock ~168 ~118 ~95 dirt
setblock ~168 ~118 ~96 dirt
setblock ~168 ~118 ~97 dirt
setblock ~168 ~118 ~98 dirt
setblock ~168 ~118 ~99 dirt
setblock ~168 ~118 ~100 dirt
setblock ~168 ~118 ~101 dirt
setblock ~168 ~118 ~102 dirt
setblock ~168 ~118 ~103 dirt
setblock ~168 ~118 ~109 dirt
setblock ~168 ~118 ~110 dirt
setblock ~168 ~118 ~111 dirt
setblock ~168 ~118 ~112 dirt
setblock ~168 ~118 ~113 dirt
setblock ~168 ~118 ~114 dirt
setblock ~168 ~118 ~115 dirt
setblock ~168 ~118 ~116 dirt
setblock ~168 ~119 ~67 dirt
setblock ~168 ~119 ~73 dirt
setblock ~168 ~119 ~74 dirt
setblock ~168 ~119 ~79 dirt
setblock ~168 ~119 ~80 dirt
setblock ~168 ~119 ~81 dirt
setblock ~168 ~119 ~82 dirt
setblock ~168 ~119 ~83 dirt
setblock ~168 ~119 ~84 dirt
setblock ~168 ~119 ~85 dirt
setblock ~168 ~119 ~86 dirt
setblock ~168 ~119 ~87 dirt
setblock ~168 ~119 ~88 dirt
setblock ~168 ~119 ~89 dirt
setblock ~168 ~119 ~90 dirt
setblock ~168 ~119 ~91 dirt
setblock ~168 ~119 ~92 dirt
setblock ~168 ~119 ~93 dirt
setblock ~168 ~119 ~94 dirt
setblock ~168 ~119 ~95 dirt
setblock ~168 ~119 ~96 dirt
setblock ~168 ~119 ~97 dirt
setblock ~168 ~119 ~98 dirt
setblock ~168 ~119 ~99 dirt
setblock ~168 ~119 ~100 dirt
setblock ~168 ~119 ~101 dirt
setblock ~168 ~119 ~102 dirt
setblock ~168 ~119 ~103 dirt
setblock ~168 ~119 ~104 dirt
setblock ~168 ~119 ~108 dirt
setblock ~168 ~119 ~109 dirt
setblock ~168 ~119 ~110 dirt
setblock ~168 ~119 ~111 dirt
setblock ~168 ~119 ~112 dirt
setblock ~168 ~119 ~113 dirt
setblock ~168 ~119 ~114 dirt
setblock ~168 ~119 ~115 dirt
setblock ~168 ~119 ~116 dirt
setblock ~168 ~120 ~66 dirt
setblock ~168 ~120 ~67 dirt
setblock ~168 ~120 ~68 dirt
setblock ~168 ~120 ~73 dirt
setblock ~168 ~120 ~74 dirt
setblock ~168 ~120 ~75 dirt
setblock ~168 ~120 ~78 dirt
setblock ~168 ~120 ~79 dirt
setblock ~168 ~120 ~80 dirt
setblock ~168 ~120 ~81 dirt
setblock ~168 ~120 ~82 dirt
setblock ~168 ~120 ~83 dirt
setblock ~168 ~120 ~84 dirt
setblock ~168 ~120 ~85 dirt
setblock ~168 ~120 ~86 dirt
setblock ~168 ~120 ~87 dirt
setblock ~168 ~120 ~88 dirt
setblock ~168 ~120 ~89 dirt
setblock ~168 ~120 ~90 dirt
setblock ~168 ~120 ~91 dirt
setblock ~168 ~120 ~92 dirt
setblock ~168 ~120 ~93 dirt
setblock ~168 ~120 ~94 dirt
setblock ~168 ~120 ~95 dirt
setblock ~168 ~120 ~96 dirt
setblock ~168 ~120 ~97 dirt
setblock ~168 ~120 ~98 dirt
setblock ~168 ~120 ~99 dirt
setblock ~168 ~120 ~100 dirt
setblock ~168 ~120 ~101 dirt
setblock ~168 ~120 ~102 dirt
setblock ~168 ~120 ~103 dirt
setblock ~168 ~120 ~104 dirt
setblock ~168 ~120 ~106 dirt
setblock ~168 ~120 ~107 dirt
setblock ~168 ~120 ~108 dirt
setblock ~168 ~120 ~109 dirt
setblock ~168 ~120 ~110 dirt
setblock ~168 ~120 ~111 dirt
setblock ~168 ~120 ~112 dirt
setblock ~168 ~120 ~113 dirt
setblock ~168 ~120 ~114 dirt
setblock ~168 ~120 ~115 dirt
setblock ~168 ~120 ~116 dirt
setblock ~168 ~120 ~160 dirt
setblock ~168 ~121 ~66 dirt
setblock ~168 ~121 ~67 dirt
setblock ~168 ~121 ~68 dirt
setblock ~168 ~121 ~71 dirt
setblock ~168 ~121 ~72 dirt
setblock ~168 ~121 ~73 dirt
setblock ~168 ~121 ~74 dirt
setblock ~168 ~121 ~75 dirt
setblock ~168 ~121 ~78 dirt
setblock ~168 ~121 ~79 dirt
setblock ~168 ~121 ~80 dirt
setblock ~168 ~121 ~81 dirt
setblock ~168 ~121 ~82 dirt
setblock ~168 ~121 ~83 dirt
setblock ~168 ~121 ~84 dirt
setblock ~168 ~121 ~85 dirt
setblock ~168 ~121 ~86 dirt
setblock ~168 ~121 ~87 dirt
setblock ~168 ~121 ~88 dirt
setblock ~168 ~121 ~89 dirt
setblock ~168 ~121 ~90 dirt
setblock ~168 ~121 ~91 dirt
setblock ~168 ~121 ~92 dirt
setblock ~168 ~121 ~93 dirt
setblock ~168 ~121 ~94 dirt
setblock ~168 ~121 ~95 dirt
setblock ~168 ~121 ~96 dirt
setblock ~168 ~121 ~97 dirt
setblock ~168 ~121 ~98 dirt
setblock ~168 ~121 ~99 dirt
setblock ~168 ~121 ~100 dirt
setblock ~168 ~121 ~101 dirt
setblock ~168 ~121 ~102 dirt
setblock ~168 ~121 ~103 dirt
setblock ~168 ~121 ~104 dirt
setblock ~168 ~121 ~105 dirt
setblock ~168 ~121 ~106 dirt
setblock ~168 ~121 ~107 dirt
setblock ~168 ~121 ~108 dirt
setblock ~168 ~121 ~109 dirt
setblock ~168 ~121 ~110 dirt
setblock ~168 ~121 ~111 dirt
setblock ~168 ~121 ~112 dirt
setblock ~168 ~121 ~113 dirt
setblock ~168 ~121 ~114 dirt
setblock ~168 ~121 ~115 dirt
setblock ~168 ~121 ~116 dirt
setblock ~168 ~121 ~117 dirt
setblock ~168 ~121 ~160 dirt
setblock ~168 ~122 ~66 dirt
setblock ~168 ~122 ~67 dirt
setblock ~168 ~122 ~68 dirt
setblock ~168 ~122 ~71 dirt
setblock ~168 ~122 ~72 dirt
setblock ~168 ~122 ~73 dirt
setblock ~168 ~122 ~74 dirt
setblock ~168 ~122 ~75 dirt
setblock ~168 ~122 ~78 dirt
setblock ~168 ~122 ~79 dirt
setblock ~168 ~122 ~80 dirt
setblock ~168 ~122 ~81 dirt
setblock ~168 ~122 ~82 dirt
setblock ~168 ~122 ~83 dirt
setblock ~168 ~122 ~84 dirt
setblock ~168 ~122 ~85 dirt
setblock ~168 ~122 ~86 dirt
setblock ~168 ~122 ~87 dirt
setblock ~168 ~122 ~88 dirt
setblock ~168 ~122 ~89 dirt
setblock ~168 ~122 ~90 dirt
setblock ~168 ~122 ~91 dirt
setblock ~168 ~122 ~92 dirt
setblock ~168 ~122 ~93 dirt
setblock ~168 ~122 ~94 dirt
setblock ~168 ~122 ~95 dirt
setblock ~168 ~122 ~96 dirt
setblock ~168 ~122 ~97 dirt
setblock ~168 ~122 ~98 dirt
setblock ~168 ~122 ~99 dirt
setblock ~168 ~122 ~100 dirt
setblock ~168 ~122 ~101 dirt
setblock ~168 ~122 ~102 dirt
setblock ~168 ~122 ~103 dirt
setblock ~168 ~122 ~104 dirt
setblock ~168 ~122 ~105 dirt
setblock ~168 ~122 ~106 dirt
setblock ~168 ~122 ~107 dirt
setblock ~168 ~122 ~108 dirt
setblock ~168 ~122 ~109 dirt
setblock ~168 ~122 ~110 dirt
setblock ~168 ~122 ~111 dirt
setblock ~168 ~122 ~112 dirt
setblock ~168 ~122 ~113 dirt
setblock ~168 ~122 ~114 dirt
setblock ~168 ~122 ~115 dirt
setblock ~168 ~122 ~116 dirt
setblock ~168 ~122 ~117 dirt
setblock ~168 ~122 ~160 dirt
setblock ~168 ~123 ~66 dirt
setblock ~168 ~123 ~67 dirt
setblock ~168 ~123 ~68 dirt
setblock ~168 ~123 ~71 dirt
setblock ~168 ~123 ~72 dirt
setblock ~168 ~123 ~73 dirt
setblock ~168 ~123 ~74 dirt
setblock ~168 ~123 ~75 dirt
setblock ~168 ~123 ~78 dirt
setblock ~168 ~123 ~79 dirt
setblock ~168 ~123 ~80 dirt
setblock ~168 ~123 ~81 dirt
setblock ~168 ~123 ~82 dirt
setblock ~168 ~123 ~83 dirt
setblock ~168 ~123 ~84 dirt
setblock ~168 ~123 ~85 dirt
setblock ~168 ~123 ~86 dirt
setblock ~168 ~123 ~87 dirt
setblock ~168 ~123 ~88 dirt
setblock ~168 ~123 ~89 dirt
setblock ~168 ~123 ~90 dirt
setblock ~168 ~123 ~91 dirt
setblock ~168 ~123 ~92 dirt
setblock ~168 ~123 ~93 dirt
setblock ~168 ~123 ~94 dirt
setblock ~168 ~123 ~95 dirt
setblock ~168 ~123 ~96 dirt
setblock ~168 ~123 ~97 dirt
setblock ~168 ~123 ~98 dirt
setblock ~168 ~123 ~99 dirt
setblock ~168 ~123 ~100 dirt
setblock ~168 ~123 ~101 dirt
setblock ~168 ~123 ~102 dirt
setblock ~168 ~123 ~103 dirt
setblock ~168 ~123 ~104 dirt
setblock ~168 ~123 ~105 dirt
setblock ~168 ~123 ~106 dirt
setblock ~168 ~123 ~107 dirt
setblock ~168 ~123 ~108 dirt
setblock ~168 ~123 ~109 dirt
setblock ~168 ~123 ~110 dirt
setblock ~168 ~123 ~111 dirt
setblock ~168 ~123 ~112 dirt
setblock ~168 ~123 ~113 dirt
setblock ~168 ~123 ~114 dirt
setblock ~168 ~123 ~115 dirt
setblock ~168 ~123 ~116 dirt
setblock ~168 ~123 ~117 dirt
setblock ~168 ~123 ~160 dirt
setblock ~168 ~124 ~66 dirt
setblock ~168 ~124 ~67 dirt
setblock ~168 ~124 ~68 dirt
setblock ~168 ~124 ~71 dirt
setblock ~168 ~124 ~72 dirt
setblock ~168 ~124 ~73 dirt
setblock ~168 ~124 ~74 dirt
setblock ~168 ~124 ~75 dirt
setblock ~168 ~124 ~78 dirt
setblock ~168 ~124 ~79 dirt
setblock ~168 ~124 ~80 dirt
setblock ~168 ~124 ~81 dirt
setblock ~168 ~124 ~82 dirt
setblock ~168 ~124 ~83 dirt
setblock ~168 ~124 ~84 dirt
setblock ~168 ~124 ~85 dirt
setblock ~168 ~124 ~86 dirt
setblock ~168 ~124 ~87 dirt
setblock ~168 ~124 ~88 dirt
setblock ~168 ~124 ~89 dirt
setblock ~168 ~124 ~90 dirt
setblock ~168 ~124 ~91 dirt
setblock ~168 ~124 ~92 dirt
setblock ~168 ~124 ~93 dirt
setblock ~168 ~124 ~94 dirt
setblock ~168 ~124 ~95 dirt
setblock ~168 ~124 ~96 dirt
setblock ~168 ~124 ~97 dirt
setblock ~168 ~124 ~98 dirt
setblock ~168 ~124 ~99 dirt
setblock ~168 ~124 ~100 dirt
setblock ~168 ~124 ~101 dirt
setblock ~168 ~124 ~102 dirt
setblock ~168 ~124 ~103 dirt
setblock ~168 ~124 ~104 dirt
setblock ~168 ~124 ~105 dirt
setblock ~168 ~124 ~106 dirt
setblock ~168 ~124 ~107 dirt
setblock ~168 ~124 ~108 dirt
setblock ~168 ~124 ~109 dirt
setblock ~168 ~124 ~110 dirt
setblock ~168 ~124 ~111 dirt
setblock ~168 ~124 ~112 dirt
setblock ~168 ~124 ~113 dirt
setblock ~168 ~124 ~114 dirt
setblock ~168 ~124 ~115 dirt
setblock ~168 ~124 ~116 dirt
setblock ~168 ~124 ~117 grass_block
setblock ~168 ~124 ~160 grass_block
setblock ~168 ~125 ~66 grass_block
setblock ~168 ~125 ~67 grass_block
setblock ~168 ~125 ~68 grass_block
setblock ~168 ~125 ~71 grass_block
setblock ~168 ~125 ~72 grass_block
setblock ~168 ~125 ~73 grass_block
setblock ~168 ~125 ~74 grass_block
setblock ~168 ~125 ~75 grass_block
setblock ~168 ~125 ~78 grass_block
setblock ~168 ~125 ~79 grass_block
setblock ~168 ~125 ~80 dirt
setblock ~168 ~125 ~81 dirt
setblock ~168 ~125 ~82 dirt
setblock ~168 ~125 ~83 dirt
setblock ~168 ~125 ~84 dirt
setblock ~168 ~125 ~85 dirt
setblock ~168 ~125 ~86 dirt
setblock ~168 ~125 ~87 dirt
setblock ~168 ~125 ~88 dirt
setblock ~168 ~125 ~89 dirt
setblock ~168 ~125 ~90 grass_block
setblock ~168 ~125 ~91 grass_block
setblock ~168 ~125 ~92 grass_block
setblock ~168 ~125 ~93 grass_block
setblock ~168 ~125 ~94 grass_block
setblock ~168 ~125 ~95 grass_block
setblock ~168 ~125 ~96 grass_block
setblock ~168 ~125 ~97 grass_block
setblock ~168 ~125 ~98 grass_block
setblock ~168 ~125 ~99 grass_block
setblock ~168 ~125 ~100 grass_block
setblock ~168 ~125 ~101 dirt
setblock ~168 ~125 ~102 dirt
setblock ~168 ~125 ~103 dirt
setblock ~168 ~125 ~104 dirt
setblock ~168 ~125 ~105 dirt
setblock ~168 ~125 ~106 dirt
setblock ~168 ~125 ~107 dirt
setblock ~168 ~125 ~108 dirt
setblock ~168 ~125 ~109 dirt
setblock ~168 ~125 ~110 dirt
setblock ~168 ~125 ~111 dirt
setblock ~168 ~125 ~112 dirt
setblock ~168 ~125 ~113 dirt
setblock ~168 ~125 ~114 grass_block
setblock ~168 ~125 ~115 grass_block
setblock ~168 ~125 ~116 grass_block
setblock ~168 ~125 ~117 short_grass
setblock ~168 ~125 ~160 fern
setblock ~168 ~126 ~67 short_grass
setblock ~168 ~126 ~80 grass_block
setblock ~168 ~126 ~81 grass_block
setblock ~168 ~126 ~82 grass_block
setblock ~168 ~126 ~83 grass_block
setblock ~168 ~126 ~84 grass_block
setblock ~168 ~126 ~85 grass_block
setblock ~168 ~126 ~86 grass_block
setblock ~168 ~126 ~87 grass_block
setblock ~168 ~126 ~88 grass_block
setblock ~168 ~126 ~89 grass_block
setblock ~168 ~126 ~99 short_grass
setblock ~168 ~126 ~100 fern
setblock ~168 ~126 ~101 grass_block
setblock ~168 ~126 ~102 grass_block
setblock ~168 ~126 ~103 grass_block
setblock ~168 ~126 ~104 grass_block
setblock ~168 ~126 ~105 grass_block
setblock ~168 ~126 ~106 dirt
setblock ~168 ~126 ~107 dirt
setblock ~168 ~126 ~108 dirt
setblock ~168 ~126 ~109 dirt
setblock ~168 ~126 ~110 dirt
setblock ~168 ~126 ~111 dirt
setblock ~168 ~126 ~112 grass_block
setblock ~168 ~126 ~113 grass_block
setblock ~168 ~126 ~116 short_grass
setblock ~168 ~127 ~86 short_grass
setblock ~168 ~127 ~87 short_grass
setblock ~168 ~127 ~88 short_grass
setblock ~168 ~127 ~101 fern
setblock ~168 ~127 ~102 poppy
setblock ~168 ~127 ~105 short_grass
setblock ~168 ~127 ~106 grass_block
setblock ~168 ~127 ~107 grass_block
setblock ~168 ~127 ~108 grass_block
setblock ~168 ~127 ~109 grass_block
setblock ~168 ~127 ~110 grass_block
setblock ~168 ~127 ~111 grass_block
setblock ~168 ~127 ~112 short_grass
setblock ~168 ~128 ~108 short_grass
setblock ~169 ~108 ~90 dirt
setblock ~169 ~108 ~97 dirt
setblock ~169 ~109 ~90 dirt
setblock ~169 ~109 ~91 dirt
setblock ~169 ~109 ~94 dirt
setblock ~169 ~109 ~96 dirt
setblock ~169 ~109 ~97 dirt
setblock ~169 ~109 ~98 dirt
setblock ~169 ~110 ~89 dirt
setblock ~169 ~110 ~90 dirt
setblock ~169 ~110 ~91 dirt
setblock ~169 ~110 ~93 dirt
setblock ~169 ~110 ~94 dirt
setblock ~169 ~110 ~95 dirt
setblock ~169 ~110 ~96 dirt
setblock ~169 ~110 ~97 dirt
setblock ~169 ~110 ~98 dirt
setblock ~169 ~110 ~99 dirt
setblock ~169 ~111 ~88 dirt
setblock ~169 ~111 ~89 dirt
setblock ~169 ~111 ~90 dirt
setblock ~169 ~111 ~91 dirt
setblock ~169 ~111 ~92 dirt
setblock ~169 ~111 ~93 dirt
setblock ~169 ~111 ~94 dirt
setblock ~169 ~111 ~95 dirt
setblock ~169 ~111 ~96 dirt
setblock ~169 ~111 ~97 dirt
setblock ~169 ~111 ~98 dirt
setblock ~169 ~111 ~99 dirt
setblock ~169 ~111 ~100 dirt
setblock ~169 ~112 ~87 dirt
setblock ~169 ~112 ~88 dirt
setblock ~169 ~112 ~89 dirt
setblock ~169 ~112 ~90 dirt
setblock ~169 ~112 ~91 dirt
setblock ~169 ~112 ~92 dirt
setblock ~169 ~112 ~93 dirt
setblock ~169 ~112 ~94 dirt
setblock ~169 ~112 ~95 dirt
setblock ~169 ~112 ~96 dirt
setblock ~169 ~112 ~97 dirt
setblock ~169 ~112 ~98 dirt
setblock ~169 ~112 ~99 dirt
setblock ~169 ~112 ~100 dirt
setblock ~169 ~113 ~86 dirt
setblock ~169 ~113 ~87 dirt
setblock ~169 ~113 ~88 dirt
setblock ~169 ~113 ~89 dirt
setblock ~169 ~113 ~90 dirt
setblock ~169 ~113 ~91 dirt
setblock ~169 ~113 ~92 dirt
setblock ~169 ~113 ~93 dirt
setblock ~169 ~113 ~94 dirt
setblock ~169 ~113 ~95 dirt
setblock ~169 ~113 ~96 dirt
setblock ~169 ~113 ~97 dirt
setblock ~169 ~113 ~98 dirt
setblock ~169 ~113 ~99 dirt
setblock ~169 ~113 ~100 dirt
setblock ~169 ~113 ~101 dirt
setblock ~169 ~114 ~86 dirt
setblock ~169 ~114 ~87 dirt
setblock ~169 ~114 ~88 dirt
setblock ~169 ~114 ~89 dirt
setblock ~169 ~114 ~90 dirt
setblock ~169 ~114 ~91 dirt
setblock ~169 ~114 ~92 dirt
setblock ~169 ~114 ~93 dirt
setblock ~169 ~114 ~94 dirt
setblock ~169 ~114 ~95 dirt
setblock ~169 ~114 ~96 dirt
setblock ~169 ~114 ~97 dirt
setblock ~169 ~114 ~98 dirt
setblock ~169 ~114 ~99 dirt
setblock ~169 ~114 ~100 dirt
setblock ~169 ~114 ~101 dirt
setblock ~169 ~115 ~85 dirt
setblock ~169 ~115 ~86 dirt
setblock ~169 ~115 ~87 dirt
setblock ~169 ~115 ~88 dirt
setblock ~169 ~115 ~89 dirt
setblock ~169 ~115 ~90 dirt
setblock ~169 ~115 ~91 dirt
setblock ~169 ~115 ~92 dirt
setblock ~169 ~115 ~93 dirt
setblock ~169 ~115 ~94 dirt
setblock ~169 ~115 ~95 dirt
setblock ~169 ~115 ~96 dirt
setblock ~169 ~115 ~97 dirt
setblock ~169 ~115 ~98 dirt
setblock ~169 ~115 ~99 dirt
setblock ~169 ~115 ~100 dirt
setblock ~169 ~115 ~101 dirt
setblock ~169 ~115 ~102 dirt
setblock ~169 ~115 ~112 dirt
setblock ~169 ~116 ~84 dirt
setblock ~169 ~116 ~85 dirt
setblock ~169 ~116 ~86 dirt
setblock ~169 ~116 ~87 dirt
setblock ~169 ~116 ~88 dirt
setblock ~169 ~116 ~89 dirt
setblock ~169 ~116 ~90 dirt
setblock ~169 ~116 ~91 dirt
setblock ~169 ~116 ~92 dirt
setblock ~169 ~116 ~93 dirt
setblock ~169 ~116 ~94 dirt
setblock ~169 ~116 ~95 dirt
setblock ~169 ~116 ~96 dirt
setblock ~169 ~116 ~97 dirt
setblock ~169 ~116 ~98 dirt
setblock ~169 ~116 ~99 dirt
setblock ~169 ~116 ~100 dirt
setblock ~169 ~116 ~101 dirt
setblock ~169 ~116 ~102 dirt
setblock ~169 ~116 ~103 dirt
setblock ~169 ~116 ~111 dirt
setblock ~169 ~116 ~112 dirt
setblock ~169 ~116 ~113 dirt
setblock ~169 ~117 ~84 dirt
setblock ~169 ~117 ~85 dirt
setblock ~169 ~117 ~86 dirt
setblock ~169 ~117 ~87 dirt
setblock ~169 ~117 ~88 dirt
setblock ~169 ~117 ~89 dirt
setblock ~169 ~117 ~90 dirt
setblock ~169 ~117 ~91 dirt
setblock ~169 ~117 ~92 dirt
setblock ~169 ~117 ~93 dirt
setblock ~169 ~117 ~94 dirt
setblock ~169 ~117 ~95 dirt
setblock ~169 ~117 ~96 dirt
setblock ~169 ~117 ~97 dirt
setblock ~169 ~117 ~98 dirt
setblock ~169 ~117 ~99 dirt
setblock ~169 ~117 ~100 dirt
setblock ~169 ~117 ~101 dirt
setblock ~169 ~117 ~102 dirt
setblock ~169 ~117 ~103 dirt
setblock ~169 ~117 ~104 dirt
setblock ~169 ~117 ~110 dirt
setblock ~169 ~117 ~111 dirt
setblock ~169 ~117 ~112 dirt
setblock ~169 ~117 ~113 dirt
setblock ~169 ~118 ~67 dirt
setblock ~169 ~118 ~84 dirt
setblock ~169 ~118 ~85 dirt
setblock ~169 ~118 ~86 dirt
setblock ~169 ~118 ~87 dirt
setblock ~169 ~118 ~88 dirt
setblock ~169 ~118 ~89 dirt
setblock ~169 ~118 ~90 dirt
setblock ~169 ~118 ~91 dirt
setblock ~169 ~118 ~92 dirt
setblock ~169 ~118 ~93 dirt
setblock ~169 ~118 ~94 dirt
setblock ~169 ~118 ~95 dirt
setblock ~169 ~118 ~96 dirt
setblock ~169 ~118 ~97 dirt
setblock ~169 ~118 ~98 dirt
setblock ~169 ~118 ~99 dirt
setblock ~169 ~118 ~100 dirt
setblock ~169 ~118 ~101 dirt
setblock ~169 ~118 ~102 dirt
setblock ~169 ~118 ~103 dirt
setblock ~169 ~118 ~104 dirt
setblock ~169 ~118 ~110 dirt
setblock ~169 ~118 ~111 dirt
setblock ~169 ~118 ~112 dirt
setblock ~169 ~118 ~113 dirt
setblock ~169 ~118 ~114 dirt
setblock ~169 ~118 ~115 dirt
setblock ~169 ~119 ~66 dirt
setblock ~169 ~119 ~67 dirt
setblock ~169 ~119 ~68 dirt
setblock ~169 ~119 ~80 dirt
setblock ~169 ~119 ~83 dirt
setblock ~169 ~119 ~84 dirt
setblock ~169 ~119 ~85 dirt
setblock ~169 ~119 ~86 dirt
setblock ~169 ~119 ~87 dirt
setblock ~169 ~119 ~88 dirt
setblock ~169 ~119 ~89 dirt
setblock ~169 ~119 ~90 dirt
setblock ~169 ~119 ~91 dirt
setblock ~169 ~119 ~92 dirt
setblock ~169 ~119 ~93 dirt
setblock ~169 ~119 ~94 dirt
setblock ~169 ~119 ~95 dirt
setblock ~169 ~119 ~96 dirt
setblock ~169 ~119 ~97 dirt
setblock ~169 ~119 ~98 dirt
setblock ~169 ~119 ~99 dirt
setblock ~169 ~119 ~100 dirt
setblock ~169 ~119 ~101 dirt
setblock ~169 ~119 ~102 dirt
setblock ~169 ~119 ~103 dirt
setblock ~169 ~119 ~104 dirt
setblock ~169 ~119 ~105 dirt
setblock ~169 ~119 ~109 dirt
setblock ~169 ~119 ~110 dirt
setblock ~169 ~119 ~111 dirt
setblock ~169 ~119 ~112 dirt
setblock ~169 ~119 ~113 dirt
setblock ~169 ~119 ~114 dirt
setblock ~169 ~119 ~115 dirt
setblock ~169 ~120 ~66 dirt
setblock ~169 ~120 ~67 dirt
setblock ~169 ~120 ~68 dirt
setblock ~169 ~120 ~79 dirt
setblock ~169 ~120 ~80 dirt
setblock ~169 ~120 ~81 dirt
setblock ~169 ~120 ~82 dirt
setblock ~169 ~120 ~83 dirt
setblock ~169 ~120 ~84 dirt
setblock ~169 ~120 ~85 dirt
setblock ~169 ~120 ~86 dirt
setblock ~169 ~120 ~87 dirt
setblock ~169 ~120 ~88 dirt
setblock ~169 ~120 ~89 dirt
setblock ~169 ~120 ~90 dirt
setblock ~169 ~120 ~91 dirt
setblock ~169 ~120 ~92 dirt
setblock ~169 ~120 ~93 dirt
setblock ~169 ~120 ~94 dirt
setblock ~169 ~120 ~95 dirt
setblock ~169 ~120 ~96 dirt
setblock ~169 ~120 ~97 dirt
setblock ~169 ~120 ~98 dirt
setblock ~169 ~120 ~99 dirt
setblock ~169 ~120 ~100 dirt
setblock ~169 ~120 ~101 dirt
setblock ~169 ~120 ~102 dirt
setblock ~169 ~120 ~103 dirt
setblock ~169 ~120 ~104 dirt
setblock ~169 ~120 ~105 dirt
setblock ~169 ~120 ~108 dirt
setblock ~169 ~120 ~109 dirt
setblock ~169 ~120 ~110 dirt
setblock ~169 ~120 ~111 dirt
setblock ~169 ~120 ~112 dirt
setblock ~169 ~120 ~113 dirt
setblock ~169 ~120 ~114 dirt
setblock ~169 ~120 ~115 dirt
setblock ~169 ~121 ~66 dirt
setblock ~169 ~121 ~67 dirt
setblock ~169 ~121 ~68 dirt
setblock ~169 ~121 ~69 dirt
setblock ~169 ~121 ~73 dirt
setblock ~169 ~121 ~74 dirt
setblock ~169 ~121 ~79 dirt
setblock ~169 ~121 ~80 dirt
setblock ~169 ~121 ~81 dirt
setblock ~169 ~121 ~82 dirt
setblock ~169 ~121 ~83 dirt
setblock ~169 ~121 ~84 dirt
setblock ~169 ~121 ~85 dirt
setblock ~169 ~121 ~86 dirt
setblock ~169 ~121 ~87 dirt
setblock ~169 ~121 ~88 dirt
setblock ~169 ~121 ~89 dirt
setblock ~169 ~121 ~90 dirt
setblock ~169 ~121 ~91 dirt
setblock ~169 ~121 ~92 dirt
setblock ~169 ~121 ~93 dirt
setblock ~169 ~121 ~94 dirt
setblock ~169 ~121 ~95 dirt
setblock ~169 ~121 ~96 dirt
setblock ~169 ~121 ~97 dirt
setblock ~169 ~121 ~98 dirt
setblock ~169 ~121 ~99 dirt
setblock ~169 ~121 ~100 dirt
setblock ~169 ~121 ~101 dirt
setblock ~169 ~121 ~102 dirt
setblock ~169 ~121 ~103 dirt
setblock ~169 ~121 ~104 dirt
setblock ~169 ~121 ~105 dirt
setblock ~169 ~121 ~106 dirt
setblock ~169 ~121 ~108 dirt
setblock ~169 ~121 ~109 dirt
setblock ~169 ~121 ~110 dirt
setblock ~169 ~121 ~111 dirt
setblock ~169 ~121 ~112 dirt
setblock ~169 ~121 ~113 dirt
setblock ~169 ~121 ~114 dirt
setblock ~169 ~121 ~115 dirt
setblock ~169 ~121 ~116 dirt
setblock ~169 ~122 ~66 dirt
setblock ~169 ~122 ~67 dirt
setblock ~169 ~122 ~68 dirt
setblock ~169 ~122 ~69 dirt
setblock ~169 ~122 ~73 dirt
setblock ~169 ~122 ~74 dirt
setblock ~169 ~122 ~79 dirt
setblock ~169 ~122 ~80 dirt
setblock ~169 ~122 ~81 dirt
setblock ~169 ~122 ~82 dirt
setblock ~169 ~122 ~83 dirt
setblock ~169 ~122 ~84 dirt
setblock ~169 ~122 ~85 dirt
setblock ~169 ~122 ~86 dirt
setblock ~169 ~122 ~87 dirt
setblock ~169 ~122 ~88 dirt
setblock ~169 ~122 ~89 dirt
setblock ~169 ~122 ~90 dirt
setblock ~169 ~122 ~91 dirt
setblock ~169 ~122 ~92 dirt
setblock ~169 ~122 ~93 dirt
setblock ~169 ~122 ~94 dirt
setblock ~169 ~122 ~95 dirt
setblock ~169 ~122 ~96 dirt
setblock ~169 ~122 ~97 dirt
setblock ~169 ~122 ~98 dirt
setblock ~169 ~122 ~99 dirt
setblock ~169 ~122 ~100 dirt
setblock ~169 ~122 ~101 dirt
setblock ~169 ~122 ~102 dirt
setblock ~169 ~122 ~103 dirt
setblock ~169 ~122 ~104 dirt
setblock ~169 ~122 ~105 dirt
setblock ~169 ~122 ~106 dirt
setblock ~169 ~122 ~108 dirt
setblock ~169 ~122 ~109 dirt
setblock ~169 ~122 ~110 dirt
setblock ~169 ~122 ~111 dirt
setblock ~169 ~122 ~112 dirt
setblock ~169 ~122 ~113 dirt
setblock ~169 ~122 ~114 dirt
setblock ~169 ~122 ~115 dirt
setblock ~169 ~122 ~116 dirt
setblock ~169 ~123 ~66 dirt
setblock ~169 ~123 ~67 dirt
setblock ~169 ~123 ~68 dirt
setblock ~169 ~123 ~69 dirt
setblock ~169 ~123 ~73 dirt
setblock ~169 ~123 ~74 dirt
setblock ~169 ~123 ~79 dirt
setblock ~169 ~123 ~80 dirt
setblock ~169 ~123 ~81 dirt
setblock ~169 ~123 ~82 dirt
setblock ~169 ~123 ~83 dirt
setblock ~169 ~123 ~84 dirt
setblock ~169 ~123 ~85 dirt
setblock ~169 ~123 ~86 dirt
setblock ~169 ~123 ~87 dirt
setblock ~169 ~123 ~88 dirt
setblock ~169 ~123 ~89 dirt
setblock ~169 ~123 ~90 dirt
setblock ~169 ~123 ~91 dirt
setblock ~169 ~123 ~92 dirt
setblock ~169 ~123 ~93 dirt
setblock ~169 ~123 ~94 dirt
setblock ~169 ~123 ~95 dirt
setblock ~169 ~123 ~96 dirt
setblock ~169 ~123 ~97 dirt
setblock ~169 ~123 ~98 dirt
setblock ~169 ~123 ~99 dirt
setblock ~169 ~123 ~100 dirt
setblock ~169 ~123 ~101 dirt
setblock ~169 ~123 ~102 dirt
setblock ~169 ~123 ~103 dirt
setblock ~169 ~123 ~104 dirt
setblock ~169 ~123 ~105 dirt
setblock ~169 ~123 ~106 dirt
setblock ~169 ~123 ~108 dirt
setblock ~169 ~123 ~109 dirt
setblock ~169 ~123 ~110 dirt
setblock ~169 ~123 ~111 dirt
setblock ~169 ~123 ~112 dirt
setblock ~169 ~123 ~113 dirt
setblock ~169 ~123 ~114 dirt
setblock ~169 ~123 ~115 dirt
setblock ~169 ~123 ~116 dirt
setblock ~169 ~124 ~66 dirt
setblock ~169 ~124 ~67 dirt
setblock ~169 ~124 ~68 dirt
setblock ~169 ~124 ~69 dirt
setblock ~169 ~124 ~73 dirt
setblock ~169 ~124 ~74 dirt
setblock ~169 ~124 ~79 dirt
setblock ~169 ~124 ~80 dirt
setblock ~169 ~124 ~81 dirt
setblock ~169 ~124 ~82 dirt
setblock ~169 ~124 ~83 dirt
setblock ~169 ~124 ~84 dirt
setblock ~169 ~124 ~85 dirt
setblock ~169 ~124 ~86 dirt
setblock ~169 ~124 ~87 dirt
setblock ~169 ~124 ~88 dirt
setblock ~169 ~124 ~89 dirt
setblock ~169 ~124 ~90 dirt
setblock ~169 ~124 ~91 dirt
setblock ~169 ~124 ~92 dirt
setblock ~169 ~124 ~93 dirt
setblock ~169 ~124 ~94 dirt
setblock ~169 ~124 ~95 dirt
setblock ~169 ~124 ~96 dirt
setblock ~169 ~124 ~97 dirt
setblock ~169 ~124 ~98 dirt
setblock ~169 ~124 ~99 dirt
setblock ~169 ~124 ~100 dirt
setblock ~169 ~124 ~101 dirt
setblock ~169 ~124 ~102 dirt
setblock ~169 ~124 ~103 dirt
setblock ~169 ~124 ~104 dirt
setblock ~169 ~124 ~105 dirt
setblock ~169 ~124 ~106 dirt
setblock ~169 ~124 ~108 dirt
setblock ~169 ~124 ~109 dirt
setblock ~169 ~124 ~110 dirt
setblock ~169 ~124 ~111 dirt
setblock ~169 ~124 ~112 dirt
setblock ~169 ~124 ~113 dirt
setblock ~169 ~124 ~114 dirt
setblock ~169 ~124 ~115 dirt
setblock ~169 ~124 ~116 grass_block
setblock ~169 ~125 ~66 grass_block
setblock ~169 ~125 ~67 grass_block
setblock ~169 ~125 ~68 grass_block
setblock ~169 ~125 ~69 grass_block
setblock ~169 ~125 ~73 grass_block
setblock ~169 ~125 ~74 grass_block
setblock ~169 ~125 ~79 grass_block
setblock ~169 ~125 ~80 grass_block
setblock ~169 ~125 ~81 grass_block
setblock ~169 ~125 ~82 grass_block
setblock ~169 ~125 ~83 grass_block
setblock ~169 ~125 ~84 grass_block
setblock ~169 ~125 ~85 grass_block
setblock ~169 ~125 ~86 grass_block
setblock ~169 ~125 ~87 grass_block
setblock ~169 ~125 ~88 dirt
setblock ~169 ~125 ~89 dirt
setblock ~169 ~125 ~90 grass_block
setblock ~169 ~125 ~91 grass_block
setblock ~169 ~125 ~92 grass_block
setblock ~169 ~125 ~93 grass_block
setblock ~169 ~125 ~94 grass_block
setblock ~169 ~125 ~95 grass_block
setblock ~169 ~125 ~96 grass_block
setblock ~169 ~125 ~97 grass_block
setblock ~169 ~125 ~98 grass_block
setblock ~169 ~125 ~99 grass_block
setblock ~169 ~125 ~100 grass_block
setblock ~169 ~125 ~101 dirt
setblock ~169 ~125 ~102 dirt
setblock ~169 ~125 ~103 dirt
setblock ~169 ~125 ~104 dirt
setblock ~169 ~125 ~105 dirt
setblock ~169 ~125 ~106 dirt
setblock ~169 ~125 ~108 dirt
setblock ~169 ~125 ~109 dirt
setblock ~169 ~125 ~110 dirt
setblock ~169 ~125 ~111 dirt
setblock ~169 ~125 ~112 dirt
setblock ~169 ~125 ~113 dirt
setblock ~169 ~125 ~114 grass_block
setblock ~169 ~125 ~115 grass_block
setblock ~169 ~126 ~69 short_grass
setblock ~169 ~126 ~73 short_grass
setblock ~169 ~126 ~74 short_grass
setblock ~169 ~126 ~80 short_grass
setblock ~169 ~126 ~83 short_grass
setblock ~169 ~126 ~85 poppy
setblock ~169 ~126 ~88 grass_block
setblock ~169 ~126 ~89 grass_block
setblock ~169 ~126 ~90 short_grass
setblock ~169 ~126 ~92 short_grass
setblock ~169 ~126 ~95 short_grass
setblock ~169 ~126 ~98 short_grass
setblock ~169 ~126 ~101 grass_block
setblock ~169 ~126 ~102 grass_block
setblock ~169 ~126 ~103 grass_block
setblock ~169 ~126 ~104 grass_block
setblock ~169 ~126 ~105 grass_block
setblock ~169 ~126 ~106 dirt
setblock ~169 ~126 ~108 dirt
setblock ~169 ~126 ~109 dirt
setblock ~169 ~126 ~110 dirt
setblock ~169 ~126 ~111 grass_block
setblock ~169 ~126 ~112 grass_block
setblock ~169 ~126 ~113 grass_block
setblock ~169 ~126 ~115 short_grass
setblock ~169 ~127 ~101 short_grass
setblock ~169 ~127 ~106 grass_block
setblock ~169 ~127 ~108 grass_block
setblock ~169 ~127 ~109 grass_block
setblock ~169 ~127 ~110 grass_block
setblock ~169 ~127 ~111 short_grass
setblock ~169 ~127 ~112 short_grass
setblock ~169 ~128 ~106 short_grass
setblock ~170 ~110 ~90 dirt
setblock ~170 ~110 ~94 dirt
setblock ~170 ~110 ~96 dirt
setblock ~170 ~110 ~98 dirt
setblock ~170 ~111 ~89 dirt
setblock ~170 ~111 ~90 dirt
setblock ~170 ~111 ~91 dirt
setblock ~170 ~111 ~93 dirt
setblock ~170 ~111 ~94 dirt
setblock ~170 ~111 ~95 dirt
setblock ~170 ~111 ~96 dirt
setblock ~170 ~111 ~98 dirt
setblock ~170 ~112 ~88 dirt
setblock ~170 ~112 ~89 dirt
setblock ~170 ~112 ~90 dirt
setblock ~170 ~112 ~91 dirt
setblock ~170 ~112 ~92 dirt
setblock ~170 ~112 ~93 dirt
setblock ~170 ~112 ~94 dirt
setblock ~170 ~112 ~95 dirt
setblock ~170 ~112 ~96 dirt
setblock ~170 ~112 ~97 dirt
setblock ~170 ~112 ~98 dirt
setblock ~170 ~112 ~99 dirt
setblock ~170 ~113 ~87 dirt
setblock ~170 ~113 ~88 dirt
setblock ~170 ~113 ~89 dirt
setblock ~170 ~113 ~90 dirt
setblock ~170 ~113 ~91 dirt
setblock ~170 ~113 ~92 dirt
setblock ~170 ~113 ~93 dirt
setblock ~170 ~113 ~94 dirt
setblock ~170 ~113 ~95 dirt
setblock ~170 ~113 ~96 dirt
setblock ~170 ~113 ~97 dirt
setblock ~170 ~113 ~98 dirt
setblock ~170 ~113 ~99 dirt
setblock ~170 ~113 ~100 dirt
setblock ~170 ~114 ~86 dirt
setblock ~170 ~114 ~87 dirt
setblock ~170 ~114 ~88 dirt
setblock ~170 ~114 ~89 dirt
setblock ~170 ~114 ~90 dirt
setblock ~170 ~114 ~91 dirt
setblock ~170 ~114 ~92 dirt
setblock ~170 ~114 ~93 dirt
setblock ~170 ~114 ~94 dirt
setblock ~170 ~114 ~95 dirt
setblock ~170 ~114 ~96 dirt
setblock ~170 ~114 ~97 dirt
setblock ~170 ~114 ~98 dirt
setblock ~170 ~114 ~99 dirt
setblock ~170 ~114 ~100 dirt
setblock ~170 ~115 ~86 dirt
setblock ~170 ~115 ~87 dirt
setblock ~170 ~115 ~88 dirt
setblock ~170 ~115 ~89 dirt
setblock ~170 ~115 ~90 dirt
setblock ~170 ~115 ~91 dirt
setblock ~170 ~115 ~92 dirt
setblock ~170 ~115 ~93 dirt
setblock ~170 ~115 ~94 dirt
setblock ~170 ~115 ~95 dirt
setblock ~170 ~115 ~96 dirt
setblock ~170 ~115 ~97 dirt
setblock ~170 ~115 ~98 dirt
setblock ~170 ~115 ~99 dirt
setblock ~170 ~115 ~100 dirt
setblock ~170 ~115 ~101 dirt
setblock ~170 ~116 ~85 dirt
setblock ~170 ~116 ~86 dirt
setblock ~170 ~116 ~87 dirt
setblock ~170 ~116 ~88 dirt
setblock ~170 ~116 ~89 dirt
setblock ~170 ~116 ~90 dirt
setblock ~170 ~116 ~91 dirt
setblock ~170 ~116 ~92 dirt
setblock ~170 ~116 ~93 dirt
setblock ~170 ~116 ~94 dirt
setblock ~170 ~116 ~95 dirt
setblock ~170 ~116 ~96 dirt
setblock ~170 ~116 ~97 dirt
setblock ~170 ~116 ~98 dirt
setblock ~170 ~116 ~99 dirt
setblock ~170 ~116 ~100 dirt
setblock ~170 ~116 ~101 dirt
setblock ~170 ~116 ~102 dirt
setblock ~170 ~117 ~67 dirt
setblock ~170 ~117 ~85 dirt
setblock ~170 ~117 ~86 dirt
setblock ~170 ~117 ~87 dirt
setblock ~170 ~117 ~88 dirt
setblock ~170 ~117 ~89 dirt
setblock ~170 ~117 ~90 dirt
setblock ~170 ~117 ~91 dirt
setblock ~170 ~117 ~92 dirt
setblock ~170 ~117 ~93 dirt
setblock ~170 ~117 ~94 dirt
setblock ~170 ~117 ~95 dirt
setblock ~170 ~117 ~96 dirt
setblock ~170 ~117 ~97 dirt
setblock ~170 ~117 ~98 dirt
setblock ~170 ~117 ~99 dirt
setblock ~170 ~117 ~100 dirt
setblock ~170 ~117 ~101 dirt
setblock ~170 ~117 ~102 dirt
setblock ~170 ~117 ~103 dirt
setblock ~170 ~117 ~112 dirt
setblock ~170 ~118 ~66 dirt
setblock ~170 ~118 ~67 dirt
setblock ~170 ~118 ~68 dirt
setblock ~170 ~118 ~85 dirt
setblock ~170 ~118 ~86 dirt
setblock ~170 ~118 ~87 dirt
setblock ~170 ~118 ~88 dirt
setblock ~170 ~118 ~89 dirt
setblock ~170 ~118 ~90 dirt
setblock ~170 ~118 ~91 dirt
setblock ~170 ~118 ~92 dirt
setblock ~170 ~118 ~93 dirt
setblock ~170 ~118 ~94 dirt
setblock ~170 ~118 ~95 dirt
setblock ~170 ~118 ~96 dirt
setblock ~170 ~118 ~97 dirt
setblock ~170 ~118 ~98 dirt
setblock ~170 ~118 ~99 dirt
setblock ~170 ~118 ~100 dirt
setblock ~170 ~118 ~101 dirt
setblock ~170 ~118 ~102 dirt
setblock ~170 ~118 ~103 dirt
setblock ~170 ~118 ~111 dirt
setblock ~170 ~118 ~112 dirt
setblock ~170 ~118 ~113 dirt
setblock ~170 ~119 ~66 dirt
setblock ~170 ~119 ~67 dirt
setblock ~170 ~119 ~68 dirt
setblock ~170 ~119 ~84 dirt
setblock ~170 ~119 ~85 dirt
setblock ~170 ~119 ~86 dirt
setblock ~170 ~119 ~87 dirt
setblock ~170 ~119 ~88 dirt
setblock ~170 ~119 ~89 dirt
setblock ~170 ~119 ~90 dirt
setblock ~170 ~119 ~91 dirt
setblock ~170 ~119 ~92 dirt
setblock ~170 ~119 ~93 dirt
setblock ~170 ~119 ~94 dirt
setblock ~170 ~119 ~95 dirt
setblock ~170 ~119 ~96 dirt
setblock ~170 ~119 ~97 dirt
setblock ~170 ~119 ~98 dirt
setblock ~170 ~119 ~99 dirt
setblock ~170 ~119 ~100 dirt
setblock ~170 ~119 ~101 dirt
setblock ~170 ~119 ~102 dirt
setblock ~170 ~119 ~103 dirt
setblock ~170 ~119 ~104 dirt
setblock ~170 ~119 ~110 dirt
setblock ~170 ~119 ~111 dirt
setblock ~170 ~119 ~112 dirt
setblock ~170 ~119 ~113 dirt
setblock ~170 ~119 ~114 dirt
setblock ~170 ~120 ~65 dirt
setblock ~170 ~120 ~66 dirt
setblock ~170 ~120 ~67 dirt
setblock ~170 ~120 ~68 dirt
setblock ~170 ~120 ~69 dirt
setblock ~170 ~120 ~83 dirt
setblock ~170 ~120 ~84 dirt
setblock ~170 ~120 ~85 dirt
setblock ~170 ~120 ~86 dirt
setblock ~170 ~120 ~87 dirt
setblock ~170 ~120 ~88 dirt
setblock ~170 ~120 ~89 dirt
setblock ~170 ~120 ~90 dirt
setblock ~170 ~120 ~91 dirt
setblock ~170 ~120 ~92 dirt
setblock ~170 ~120 ~93 dirt
setblock ~170 ~120 ~94 dirt
setblock ~170 ~120 ~95 dirt
setblock ~170 ~120 ~96 dirt
setblock ~170 ~120 ~97 dirt
setblock ~170 ~120 ~98 dirt
setblock ~170 ~120 ~99 dirt
setblock ~170 ~120 ~100 dirt
setblock ~170 ~120 ~101 dirt
setblock ~170 ~120 ~102 dirt
setblock ~170 ~120 ~103 dirt
setblock ~170 ~120 ~104 dirt
setblock ~170 ~120 ~105 dirt
setblock ~170 ~120 ~110 dirt
setblock ~170 ~120 ~111 dirt
setblock ~170 ~120 ~112 dirt
setblock ~170 ~120 ~113 dirt
setblock ~170 ~120 ~114 dirt
setblock ~170 ~121 ~64 dirt
setblock ~170 ~121 ~65 dirt
setblock ~170 ~121 ~66 dirt
setblock ~170 ~121 ~67 dirt
setblock ~170 ~121 ~68 dirt
setblock ~170 ~121 ~69 dirt
setblock ~170 ~121 ~70 dirt
setblock ~170 ~121 ~80 dirt
setblock ~170 ~121 ~82 dirt
setblock ~170 ~121 ~83 dirt
setblock ~170 ~121 ~84 dirt
setblock ~170 ~121 ~85 dirt
setblock ~170 ~121 ~86 dirt
setblock ~170 ~121 ~87 dirt
setblock ~170 ~121 ~88 dirt
setblock ~170 ~121 ~89 dirt
setblock ~170 ~121 ~90 dirt
setblock ~170 ~121 ~91 dirt
setblock ~170 ~121 ~92 dirt
setblock ~170 ~121 ~93 dirt
setblock ~170 ~121 ~94 dirt
setblock ~170 ~121 ~95 dirt
setblock ~170 ~121 ~96 dirt
setblock ~170 ~121 ~97 dirt
setblock ~170 ~121 ~98 dirt
setblock ~170 ~121 ~99 dirt
setblock ~170 ~121 ~100 dirt
setblock ~170 ~121 ~101 dirt
setblock ~170 ~121 ~102 dirt
setblock ~170 ~121 ~103 dirt
setblock ~170 ~121 ~104 dirt
setblock ~170 ~121 ~105 dirt
setblock ~170 ~121 ~106 dirt
setblock ~170 ~121 ~110 dirt
setblock ~170 ~121 ~111 dirt
setblock ~170 ~121 ~112 dirt
setblock ~170 ~121 ~113 dirt
setblock ~170 ~121 ~114 dirt
setblock ~170 ~121 ~115 dirt
setblock ~170 ~122 ~64 dirt
setblock ~170 ~122 ~65 dirt
setblock ~170 ~122 ~66 dirt
setblock ~170 ~122 ~67 dirt
setblock ~170 ~122 ~68 dirt
setblock ~170 ~122 ~69 dirt
setblock ~170 ~122 ~70 dirt
setblock ~170 ~122 ~80 dirt
setblock ~170 ~122 ~82 dirt
setblock ~170 ~122 ~83 dirt
setblock ~170 ~122 ~84 dirt
setblock ~170 ~122 ~85 dirt
setblock ~170 ~122 ~86 dirt
setblock ~170 ~122 ~87 dirt
setblock ~170 ~122 ~88 dirt
setblock ~170 ~122 ~89 dirt
setblock ~170 ~122 ~90 dirt
setblock ~170 ~122 ~91 dirt
setblock ~170 ~122 ~92 dirt
setblock ~170 ~122 ~93 dirt
setblock ~170 ~122 ~94 dirt
setblock ~170 ~122 ~95 dirt
setblock ~170 ~122 ~96 dirt
setblock ~170 ~122 ~97 dirt
setblock ~170 ~122 ~98 dirt
setblock ~170 ~122 ~99 dirt
setblock ~170 ~122 ~100 dirt
setblock ~170 ~122 ~101 dirt
setblock ~170 ~122 ~102 dirt
setblock ~170 ~122 ~103 dirt
setblock ~170 ~122 ~104 dirt
setblock ~170 ~122 ~105 dirt
setblock ~170 ~122 ~106 dirt
setblock ~170 ~122 ~110 dirt
setblock ~170 ~122 ~111 dirt
setblock ~170 ~122 ~112 dirt
setblock ~170 ~122 ~113 dirt
setblock ~170 ~122 ~114 dirt
setblock ~170 ~122 ~115 dirt
setblock ~170 ~123 ~64 dirt
setblock ~170 ~123 ~65 dirt
setblock ~170 ~123 ~66 dirt
setblock ~170 ~123 ~67 dirt
setblock ~170 ~123 ~68 dirt
setblock ~170 ~123 ~69 dirt
setblock ~170 ~123 ~70 dirt
setblock ~170 ~123 ~80 dirt
setblock ~170 ~123 ~82 dirt
setblock ~170 ~123 ~83 dirt
setblock ~170 ~123 ~84 dirt
setblock ~170 ~123 ~85 dirt
setblock ~170 ~123 ~86 dirt
setblock ~170 ~123 ~87 dirt
setblock ~170 ~123 ~88 dirt
setblock ~170 ~123 ~89 dirt
setblock ~170 ~123 ~90 dirt
setblock ~170 ~123 ~91 dirt
setblock ~170 ~123 ~92 dirt
setblock ~170 ~123 ~93 dirt
setblock ~170 ~123 ~94 dirt
setblock ~170 ~123 ~95 dirt
setblock ~170 ~123 ~96 dirt
setblock ~170 ~123 ~97 dirt
setblock ~170 ~123 ~98 dirt
setblock ~170 ~123 ~99 dirt
setblock ~170 ~123 ~100 dirt
setblock ~170 ~123 ~101 dirt
setblock ~170 ~123 ~102 dirt
setblock ~170 ~123 ~103 dirt
setblock ~170 ~123 ~104 dirt
setblock ~170 ~123 ~105 dirt
setblock ~170 ~123 ~106 dirt
setblock ~170 ~123 ~110 dirt
setblock ~170 ~123 ~111 dirt
setblock ~170 ~123 ~112 dirt
setblock ~170 ~123 ~113 dirt
setblock ~170 ~123 ~114 dirt
setblock ~170 ~123 ~115 dirt
setblock ~170 ~124 ~64 dirt
setblock ~170 ~124 ~65 dirt
setblock ~170 ~124 ~66 dirt
setblock ~170 ~124 ~67 dirt
setblock ~170 ~124 ~68 dirt
setblock ~170 ~124 ~69 dirt
setblock ~170 ~124 ~70 dirt
setblock ~170 ~124 ~80 dirt
setblock ~170 ~124 ~82 dirt
setblock ~170 ~124 ~83 dirt
setblock ~170 ~124 ~84 dirt
setblock ~170 ~124 ~85 dirt
setblock ~170 ~124 ~86 dirt
setblock ~170 ~124 ~87 dirt
setblock ~170 ~124 ~88 dirt
setblock ~170 ~124 ~89 dirt
setblock ~170 ~124 ~90 dirt
setblock ~170 ~124 ~91 dirt
setblock ~170 ~124 ~92 dirt
setblock ~170 ~124 ~93 dirt
setblock ~170 ~124 ~94 dirt
setblock ~170 ~124 ~95 dirt
setblock ~170 ~124 ~96 dirt
setblock ~170 ~124 ~97 dirt
setblock ~170 ~124 ~98 dirt
setblock ~170 ~124 ~99 dirt
setblock ~170 ~124 ~100 dirt
setblock ~170 ~124 ~101 dirt
setblock ~170 ~124 ~102 dirt
setblock ~170 ~124 ~103 dirt
setblock ~170 ~124 ~104 dirt
setblock ~170 ~124 ~105 dirt
setblock ~170 ~124 ~106 dirt
setblock ~170 ~124 ~110 dirt
setblock ~170 ~124 ~111 dirt
setblock ~170 ~124 ~112 dirt
setblock ~170 ~124 ~113 dirt
setblock ~170 ~124 ~114 dirt
setblock ~170 ~124 ~115 dirt
setblock ~170 ~125 ~64 grass_block
setblock ~170 ~125 ~65 grass_block
setblock ~170 ~125 ~66 grass_block
setblock ~170 ~125 ~67 grass_block
setblock ~170 ~125 ~68 grass_block
setblock ~170 ~125 ~69 grass_block
setblock ~170 ~125 ~70 grass_block
setblock ~170 ~125 ~80 grass_block
setblock ~170 ~125 ~82 grass_block
setblock ~170 ~125 ~83 grass_block
setblock ~170 ~125 ~84 grass_block
setblock ~170 ~125 ~85 grass_block
setblock ~170 ~125 ~86 grass_block
setblock ~170 ~125 ~87 grass_block
setblock ~170 ~125 ~88 grass_block
setblock ~170 ~125 ~89 grass_block
setblock ~170 ~125 ~90 grass_block
setblock ~170 ~125 ~91 grass_block
setblock ~170 ~125 ~92 grass_block
setblock ~170 ~125 ~93 grass_block
setblock ~170 ~125 ~94 grass_block
setblock ~170 ~125 ~95 grass_block
setblock ~170 ~125 ~96 grass_block
setblock ~170 ~125 ~97 grass_block
setblock ~170 ~125 ~98 grass_block
setblock ~170 ~125 ~99 grass_block
setblock ~170 ~125 ~100 grass_block
setblock ~170 ~125 ~101 dirt
setblock ~170 ~125 ~102 dirt
setblock ~170 ~125 ~103 dirt
setblock ~170 ~125 ~104 dirt
setblock ~170 ~125 ~105 dirt
setblock ~170 ~125 ~106 dirt
setblock ~170 ~125 ~110 dirt
setblock ~170 ~125 ~111 dirt
setblock ~170 ~125 ~112 dirt
setblock ~170 ~125 ~113 dirt
setblock ~170 ~125 ~114 grass_block
setblock ~170 ~125 ~115 grass_block
setblock ~170 ~126 ~64 fern
setblock ~170 ~126 ~66 poppy
setblock ~170 ~126 ~67 short_grass
setblock ~170 ~126 ~82 fern
setblock ~170 ~126 ~83 short_grass
setblock ~170 ~126 ~84 short_grass
setblock ~170 ~126 ~85 fern
setblock ~170 ~126 ~87 poppy
setblock ~170 ~126 ~89 short_grass
setblock ~170 ~126 ~91 short_grass
setblock ~170 ~126 ~94 short_grass
setblock ~170 ~126 ~97 fern
setblock ~170 ~126 ~101 grass_block
setblock ~170 ~126 ~102 grass_block
setblock ~170 ~126 ~103 grass_block
setblock ~170 ~126 ~104 grass_block
setblock ~170 ~126 ~105 grass_block
setblock ~170 ~126 ~106 grass_block
setblock ~170 ~126 ~110 grass_block
setblock ~170 ~126 ~111 grass_block
setblock ~170 ~126 ~112 grass_block
setblock ~170 ~126 ~113 grass_block
setblock ~170 ~126 ~115 fern
setblock ~170 ~127 ~103 fern
setblock ~170 ~127 ~112 short_grass
setblock ~171 ~111 ~90 dirt
setblock ~171 ~111 ~94 dirt
setblock ~171 ~112 ~89 dirt
setblock ~171 ~112 ~90 dirt
setblock ~171 ~112 ~91 dirt
setblock ~171 ~112 ~94 dirt
setblock ~171 ~112 ~96 dirt
setblock ~171 ~113 ~89 dirt
setblock ~171 ~113 ~90 dirt
setblock ~171 ~113 ~91 dirt
setblock ~171 ~113 ~92 dirt
setblock ~171 ~113 ~93 dirt
setblock ~171 ~113 ~94 dirt
setblock ~171 ~113 ~96 dirt
setblock ~171 ~113 ~97 dirt
setblock ~171 ~114 ~87 dirt
setblock ~171 ~114 ~88 dirt
setblock ~171 ~114 ~89 dirt
setblock ~171 ~114 ~90 dirt
setblock ~171 ~114 ~91 dirt
setblock ~171 ~114 ~92 dirt
setblock ~171 ~114 ~93 dirt
setblock ~171 ~114 ~94 dirt
setblock ~171 ~114 ~95 dirt
setblock ~171 ~114 ~96 dirt
setblock ~171 ~114 ~97 dirt
setblock ~171 ~114 ~98 dirt
setblock ~171 ~115 ~67 dirt
setblock ~171 ~115 ~87 dirt
setblock ~171 ~115 ~88 dirt
setblock ~171 ~115 ~89 dirt
setblock ~171 ~115 ~90 dirt
setblock ~171 ~115 ~91 dirt
setblock ~171 ~115 ~92 dirt
setblock ~171 ~115 ~93 dirt
setblock ~171 ~115 ~94 dirt
setblock ~171 ~115 ~95 dirt
setblock ~171 ~115 ~96 dirt
setblock ~171 ~115 ~97 dirt
setblock ~171 ~115 ~98 dirt
setblock ~171 ~115 ~99 dirt
setblock ~171 ~116 ~66 dirt
setblock ~171 ~116 ~67 dirt
setblock ~171 ~116 ~86 dirt
setblock ~171 ~116 ~87 dirt
setblock ~171 ~116 ~88 dirt
setblock ~171 ~116 ~89 dirt
setblock ~171 ~116 ~90 dirt
setblock ~171 ~116 ~91 dirt
setblock ~171 ~116 ~92 dirt
setblock ~171 ~116 ~93 dirt
setblock ~171 ~116 ~94 dirt
setblock ~171 ~116 ~95 dirt
setblock ~171 ~116 ~96 dirt
setblock ~171 ~116 ~97 dirt
setblock ~171 ~116 ~98 dirt
setblock ~171 ~116 ~99 dirt
setblock ~171 ~116 ~100 dirt
setblock ~171 ~117 ~66 dirt
setblock ~171 ~117 ~67 dirt
setblock ~171 ~117 ~68 dirt
setblock ~171 ~117 ~86 dirt
setblock ~171 ~117 ~87 dirt
setblock ~171 ~117 ~88 dirt
setblock ~171 ~117 ~89 dirt
setblock ~171 ~117 ~90 dirt
setblock ~171 ~117 ~91 dirt
setblock ~171 ~117 ~92 dirt
setblock ~171 ~117 ~93 dirt
setblock ~171 ~117 ~94 dirt
setblock ~171 ~117 ~95 dirt
setblock ~171 ~117 ~96 dirt
setblock ~171 ~117 ~97 dirt
setblock ~171 ~117 ~98 dirt
setblock ~171 ~117 ~99 dirt
setblock ~171 ~117 ~100 dirt
setblock ~171 ~117 ~101 dirt
setblock ~171 ~118 ~65 dirt
setblock ~171 ~118 ~66 dirt
setblock ~171 ~118 ~67 dirt
setblock ~171 ~118 ~68 dirt
setblock ~171 ~118 ~69 dirt
setblock ~171 ~118 ~85 dirt
setblock ~171 ~118 ~86 dirt
setblock ~171 ~118 ~87 dirt
setblock ~171 ~118 ~88 dirt
setblock ~171 ~118 ~89 dirt
setblock ~171 ~118 ~90 dirt
setblock ~171 ~118 ~91 dirt
setblock ~171 ~118 ~92 dirt
setblock ~171 ~118 ~93 dirt
setblock ~171 ~118 ~94 dirt
setblock ~171 ~118 ~95 dirt
setblock ~171 ~118 ~96 dirt
setblock ~171 ~118 ~97 dirt
setblock ~171 ~118 ~98 dirt
setblock ~171 ~118 ~99 dirt
setblock ~171 ~118 ~100 dirt
setblock ~171 ~118 ~101 dirt
setblock ~171 ~118 ~102 dirt
setblock ~171 ~119 ~65 dirt
setblock ~171 ~119 ~66 dirt
setblock ~171 ~119 ~67 dirt
setblock ~171 ~119 ~68 dirt
setblock ~171 ~119 ~69 dirt
setblock ~171 ~119 ~85 dirt
setblock ~171 ~119 ~86 dirt
setblock ~171 ~119 ~87 dirt
setblock ~171 ~119 ~88 dirt
setblock ~171 ~119 ~89 dirt
setblock ~171 ~119 ~90 dirt
setblock ~171 ~119 ~91 dirt
setblock ~171 ~119 ~92 dirt
setblock ~171 ~119 ~93 dirt
setblock ~171 ~119 ~94 dirt
setblock ~171 ~119 ~95 dirt
setblock ~171 ~119 ~96 dirt
setblock ~171 ~119 ~97 dirt
setblock ~171 ~119 ~98 dirt
setblock ~171 ~119 ~99 dirt
setblock ~171 ~119 ~100 dirt
setblock ~171 ~119 ~101 dirt
setblock ~171 ~119 ~102 dirt
setblock ~171 ~119 ~111 dirt
setblock ~171 ~119 ~112 dirt
setblock ~171 ~119 ~113 dirt
setblock ~171 ~120 ~49 dirt
setblock ~171 ~120 ~64 dirt
setblock ~171 ~120 ~65 dirt
setblock ~171 ~120 ~66 dirt
setblock ~171 ~120 ~67 dirt
setblock ~171 ~120 ~68 dirt
setblock ~171 ~120 ~69 dirt
setblock ~171 ~120 ~70 dirt
setblock ~171 ~120 ~84 dirt
setblock ~171 ~120 ~85 dirt
setblock ~171 ~120 ~86 dirt
setblock ~171 ~120 ~87 dirt
setblock ~171 ~120 ~88 dirt
setblock ~171 ~120 ~89 dirt
setblock ~171 ~120 ~90 dirt
setblock ~171 ~120 ~91 dirt
setblock ~171 ~120 ~92 dirt
setblock ~171 ~120 ~93 dirt
setblock ~171 ~120 ~94 dirt
setblock ~171 ~120 ~95 dirt
setblock ~171 ~120 ~96 dirt
setblock ~171 ~120 ~97 dirt
setblock ~171 ~120 ~98 dirt
setblock ~171 ~120 ~99 dirt
setblock ~171 ~120 ~100 dirt
setblock ~171 ~120 ~101 dirt
setblock ~171 ~120 ~102 dirt
setblock ~171 ~120 ~103 dirt
setblock ~171 ~120 ~104 dirt
setblock ~171 ~120 ~111 dirt
setblock ~171 ~120 ~112 dirt
setblock ~171 ~120 ~113 dirt
setblock ~171 ~120 ~128 dirt
setblock ~171 ~121 ~48 dirt
setblock ~171 ~121 ~49 dirt
setblock ~171 ~121 ~50 dirt
setblock ~171 ~121 ~63 dirt
setblock ~171 ~121 ~64 dirt
setblock ~171 ~121 ~65 dirt
setblock ~171 ~121 ~66 dirt
setblock ~171 ~121 ~67 dirt
setblock ~171 ~121 ~68 dirt
setblock ~171 ~121 ~69 dirt
setblock ~171 ~121 ~70 dirt
setblock ~171 ~121 ~71 dirt
setblock ~171 ~121 ~83 dirt
setblock ~171 ~121 ~84 dirt
setblock ~171 ~121 ~85 dirt
setblock ~171 ~121 ~86 dirt
setblock ~171 ~121 ~87 dirt
setblock ~171 ~121 ~88 dirt
setblock ~171 ~121 ~89 dirt
setblock ~171 ~121 ~90 dirt
setblock ~171 ~121 ~91 dirt
setblock ~171 ~121 ~92 dirt
setblock ~171 ~121 ~93 dirt
setblock ~171 ~121 ~94 dirt
setblock ~171 ~121 ~95 dirt
setblock ~171 ~121 ~96 dirt
setblock ~171 ~121 ~97 dirt
setblock ~171 ~121 ~98 dirt
setblock ~171 ~121 ~99 dirt
setblock ~171 ~121 ~100 dirt
setblock ~171 ~121 ~101 dirt
setblock ~171 ~121 ~102 dirt
setblock ~171 ~121 ~103 dirt
setblock ~171 ~121 ~104 dirt
setblock ~171 ~121 ~105 dirt
setblock ~171 ~121 ~111 dirt
setblock ~171 ~121 ~112 dirt
setblock ~171 ~121 ~113 dirt
setblock ~171 ~121 ~114 dirt
setblock ~171 ~121 ~127 dirt
setblock ~171 ~121 ~128 dirt
setblock ~171 ~121 ~129 dirt
setblock ~171 ~122 ~48 dirt
setblock ~171 ~122 ~49 dirt
setblock ~171 ~122 ~50 dirt
setblock ~171 ~122 ~63 dirt
setblock ~171 ~122 ~64 dirt
setblock ~171 ~122 ~65 dirt
setblock ~171 ~122 ~66 dirt
setblock ~171 ~122 ~67 dirt
setblock ~171 ~122 ~68 dirt
setblock ~171 ~122 ~69 dirt
setblock ~171 ~122 ~70 dirt
setblock ~171 ~122 ~71 dirt
setblock ~171 ~122 ~83 dirt
setblock ~171 ~122 ~84 dirt
setblock ~171 ~122 ~85 dirt
setblock ~171 ~122 ~86 dirt
setblock ~171 ~122 ~87 dirt
setblock ~171 ~122 ~88 dirt
setblock ~171 ~122 ~89 dirt
setblock ~171 ~122 ~90 dirt
setblock ~171 ~122 ~91 dirt
setblock ~171 ~122 ~92 dirt
setblock ~171 ~122 ~93 dirt
setblock ~171 ~122 ~94 dirt
setblock ~171 ~122 ~95 dirt
setblock ~171 ~122 ~96 dirt
setblock ~171 ~122 ~97 dirt
setblock ~171 ~122 ~98 dirt
setblock ~171 ~122 ~99 dirt
setblock ~171 ~122 ~100 dirt
setblock ~171 ~122 ~101 dirt
setblock ~171 ~122 ~102 dirt
setblock ~171 ~122 ~103 dirt
setblock ~171 ~122 ~104 dirt
setblock ~171 ~122 ~105 dirt
setblock ~171 ~122 ~111 dirt
setblock ~171 ~122 ~112 dirt
setblock ~171 ~122 ~113 dirt
setblock ~171 ~122 ~114 dirt
setblock ~171 ~122 ~127 dirt
setblock ~171 ~122 ~128 dirt
setblock ~171 ~122 ~129 dirt
setblock ~171 ~123 ~48 dirt
setblock ~171 ~123 ~49 grass_block
setblock ~171 ~123 ~50 grass_block
setblock ~171 ~123 ~63 dirt
setblock ~171 ~123 ~64 dirt
setblock ~171 ~123 ~65 dirt
setblock ~171 ~123 ~66 dirt
setblock ~171 ~123 ~67 dirt
setblock ~171 ~123 ~68 dirt
setblock ~171 ~123 ~69 dirt
setblock ~171 ~123 ~70 dirt
setblock ~171 ~123 ~71 dirt
setblock ~171 ~123 ~83 dirt
setblock ~171 ~123 ~84 dirt
setblock ~171 ~123 ~85 dirt
setblock ~171 ~123 ~86 dirt
setblock ~171 ~123 ~87 dirt
setblock ~171 ~123 ~88 dirt
setblock ~171 ~123 ~89 dirt
setblock ~171 ~123 ~90 dirt
setblock ~171 ~123 ~91 dirt
setblock ~171 ~123 ~92 dirt
setblock ~171 ~123 ~93 dirt
setblock ~171 ~123 ~94 dirt
setblock ~171 ~123 ~95 dirt
setblock ~171 ~123 ~96 dirt
setblock ~171 ~123 ~97 dirt
setblock ~171 ~123 ~98 dirt
setblock ~171 ~123 ~99 dirt
setblock ~171 ~123 ~100 dirt
setblock ~171 ~123 ~101 dirt
setblock ~171 ~123 ~102 dirt
setblock ~171 ~123 ~103 dirt
setblock ~171 ~123 ~104 dirt
setblock ~171 ~123 ~105 dirt
setblock ~171 ~123 ~111 dirt
setblock ~171 ~123 ~112 dirt
setblock ~171 ~123 ~113 dirt
setblock ~171 ~123 ~114 dirt
setblock ~171 ~123 ~127 dirt
setblock ~171 ~123 ~128 dirt
setblock ~171 ~123 ~129 dirt
setblock ~171 ~124 ~48 grass_block
setblock ~171 ~124 ~50 short_grass
setblock ~171 ~124 ~63 dirt
setblock ~171 ~124 ~64 dirt
setblock ~171 ~124 ~65 dirt
setblock ~171 ~124 ~66 dirt
setblock ~171 ~124 ~67 dirt
setblock ~171 ~124 ~68 dirt
setblock ~171 ~124 ~69 dirt
setblock ~171 ~124 ~70 dirt
setblock ~171 ~124 ~71 dirt
setblock ~171 ~124 ~83 dirt
setblock ~171 ~124 ~84 dirt
setblock ~171 ~124 ~85 dirt
setblock ~171 ~124 ~86 dirt
setblock ~171 ~124 ~87 dirt
setblock ~171 ~124 ~88 dirt
setblock ~171 ~124 ~89 dirt
setblock ~171 ~124 ~90 dirt
setblock ~171 ~124 ~91 dirt
setblock ~171 ~124 ~92 dirt
setblock ~171 ~124 ~93 dirt
setblock ~171 ~124 ~94 dirt
setblock ~171 ~124 ~95 dirt
setblock ~171 ~124 ~96 dirt
setblock ~171 ~124 ~97 dirt
setblock ~171 ~124 ~98 dirt
setblock ~171 ~124 ~99 dirt
setblock ~171 ~124 ~100 dirt
setblock ~171 ~124 ~101 dirt
setblock ~171 ~124 ~102 dirt
setblock ~171 ~124 ~103 dirt
setblock ~171 ~124 ~104 dirt
setblock ~171 ~124 ~105 dirt
setblock ~171 ~124 ~111 dirt
setblock ~171 ~124 ~112 dirt
setblock ~171 ~124 ~113 dirt
setblock ~171 ~124 ~114 dirt
setblock ~171 ~124 ~127 grass_block
setblock ~171 ~124 ~128 dirt
setblock ~171 ~124 ~129 dirt
setblock ~171 ~125 ~63 grass_block
setblock ~171 ~125 ~64 grass_block
setblock ~171 ~125 ~65 grass_block
setblock ~171 ~125 ~66 grass_block
setblock ~171 ~125 ~67 grass_block
setblock ~171 ~125 ~68 grass_block
setblock ~171 ~125 ~69 grass_block
setblock ~171 ~125 ~70 grass_block
setblock ~171 ~125 ~71 grass_block
setblock ~171 ~125 ~83 grass_block
setblock ~171 ~125 ~84 grass_block
setblock ~171 ~125 ~85 grass_block
setblock ~171 ~125 ~86 grass_block
setblock ~171 ~125 ~87 grass_block
setblock ~171 ~125 ~88 grass_block
setblock ~171 ~125 ~89 grass_block
setblock ~171 ~125 ~90 grass_block
setblock ~171 ~125 ~91 grass_block
setblock ~171 ~125 ~92 grass_block
setblock ~171 ~125 ~93 grass_block
setblock ~171 ~125 ~94 grass_block
setblock ~171 ~125 ~95 grass_block
setblock ~171 ~125 ~96 grass_block
setblock ~171 ~125 ~97 grass_block
setblock ~171 ~125 ~98 grass_block
setblock ~171 ~125 ~99 grass_block
setblock ~171 ~125 ~100 grass_block
setblock ~171 ~125 ~101 grass_block
setblock ~171 ~125 ~102 dirt
setblock ~171 ~125 ~103 dirt
setblock ~171 ~125 ~104 dirt
setblock ~171 ~125 ~105 dirt
setblock ~171 ~125 ~111 dirt
setblock ~171 ~125 ~112 dirt
setblock ~171 ~125 ~113 grass_block
setblock ~171 ~125 ~114 grass_block
setblock ~171 ~125 ~128 grass_block
setblock ~171 ~125 ~129 grass_block
setblock ~171 ~126 ~64 fern
setblock ~171 ~126 ~66 short_grass
setblock ~171 ~126 ~67 short_grass
setblock ~171 ~126 ~69 short_grass
setblock ~171 ~126 ~70 short_grass
setblock ~171 ~126 ~85 short_grass
setblock ~171 ~126 ~88 short_grass
setblock ~171 ~126 ~89 poppy
setblock ~171 ~126 ~91 short_grass
setblock ~171 ~126 ~92 short_grass
setblock ~171 ~126 ~93 poppy
setblock ~171 ~126 ~97 short_grass
setblock ~171 ~126 ~98 poppy
setblock ~171 ~126 ~102 grass_block
setblock ~171 ~126 ~103 grass_block
setblock ~171 ~126 ~104 grass_block
setblock ~171 ~126 ~105 grass_block
setblock ~171 ~126 ~111 grass_block
setblock ~171 ~126 ~112 grass_block
setblock ~171 ~126 ~113 short_grass
setblock ~171 ~127 ~102 fern
setblock ~171 ~127 ~111 short_grass
setblock ~171 ~127 ~112 short_grass
setblock ~172 ~112 ~90 dirt
setblock ~172 ~113 ~90 dirt
setblock ~172 ~113 ~91 dirt
setblock ~172 ~114 ~67 dirt
setblock ~172 ~114 ~89 dirt
setblock ~172 ~114 ~90 dirt
setblock ~172 ~114 ~91 dirt
setblock ~172 ~114 ~92 dirt
setblock ~172 ~114 ~97 dirt
setblock ~172 ~115 ~66 dirt
setblock ~172 ~115 ~67 dirt
setblock ~172 ~115 ~68 dirt
setblock ~172 ~115 ~89 dirt
setblock ~172 ~115 ~90 dirt
setblock ~172 ~115 ~91 dirt
setblock ~172 ~115 ~92 dirt
setblock ~172 ~115 ~93 dirt
setblock ~172 ~115 ~94 dirt
setblock ~172 ~115 ~95 dirt
setblock ~172 ~115 ~96 dirt
setblock ~172 ~115 ~97 dirt
setblock ~172 ~115 ~98 dirt
setblock ~172 ~116 ~49 dirt
setblock ~172 ~116 ~65 dirt
setblock ~172 ~116 ~66 dirt
setblock ~172 ~116 ~67 dirt
setblock ~172 ~116 ~68 dirt
setblock ~172 ~116 ~88 dirt
setblock ~172 ~116 ~89 dirt
setblock ~172 ~116 ~90 dirt
setblock ~172 ~116 ~91 dirt
setblock ~172 ~116 ~92 dirt
setblock ~172 ~116 ~93 dirt
setblock ~172 ~116 ~94 dirt
setblock ~172 ~116 ~95 dirt
setblock ~172 ~116 ~96 dirt
setblock ~172 ~116 ~97 dirt
setblock ~172 ~116 ~98 dirt
setblock ~172 ~116 ~99 dirt
setblock ~172 ~117 ~48 dirt
setblock ~172 ~117 ~49 dirt
setblock ~172 ~117 ~65 dirt
setblock ~172 ~117 ~66 dirt
setblock ~172 ~117 ~67 dirt
setblock ~172 ~117 ~68 dirt
setblock ~172 ~117 ~69 dirt
setblock ~172 ~117 ~88 dirt
setblock ~172 ~117 ~89 dirt
setblock ~172 ~117 ~90 dirt
setblock ~172 ~117 ~91 dirt
setblock ~172 ~117 ~92 dirt
setblock ~172 ~117 ~93 dirt
setblock ~172 ~117 ~94 dirt
setblock ~172 ~117 ~95 dirt
setblock ~172 ~117 ~96 dirt
setblock ~172 ~117 ~97 dirt
setblock ~172 ~117 ~98 dirt
setblock ~172 ~117 ~99 dirt
setblock ~172 ~118 ~48 dirt
setblock ~172 ~118 ~49 dirt
setblock ~172 ~118 ~50 dirt
setblock ~172 ~118 ~64 dirt
setblock ~172 ~118 ~65 dirt
setblock ~172 ~118 ~66 dirt
setblock ~172 ~118 ~67 dirt
setblock ~172 ~118 ~68 dirt
setblock ~172 ~118 ~69 dirt
setblock ~172 ~118 ~86 dirt
setblock ~172 ~118 ~87 dirt
setblock ~172 ~118 ~88 dirt
setblock ~172 ~118 ~89 dirt
setblock ~172 ~118 ~90 dirt
setblock ~172 ~118 ~91 dirt
setblock ~172 ~118 ~92 dirt
setblock ~172 ~118 ~93 dirt
setblock ~172 ~118 ~94 dirt
setblock ~172 ~118 ~95 dirt
setblock ~172 ~118 ~96 dirt
setblock ~172 ~118 ~97 dirt
setblock ~172 ~118 ~98 dirt
setblock ~172 ~118 ~99 dirt
setblock ~172 ~118 ~100 dirt
setblock ~172 ~118 ~128 dirt
setblock ~172 ~119 ~47 dirt
setblock ~172 ~119 ~48 dirt
setblock ~172 ~119 ~49 dirt
setblock ~172 ~119 ~50 dirt
setblock ~172 ~119 ~64 dirt
setblock ~172 ~119 ~65 dirt
setblock ~172 ~119 ~66 dirt
setblock ~172 ~119 ~67 dirt
setblock ~172 ~119 ~68 dirt
setblock ~172 ~119 ~69 dirt
setblock ~172 ~119 ~86 dirt
setblock ~172 ~119 ~87 dirt
setblock ~172 ~119 ~88 dirt
setblock ~172 ~119 ~89 dirt
setblock ~172 ~119 ~90 dirt
setblock ~172 ~119 ~91 dirt
setblock ~172 ~119 ~92 dirt
setblock ~172 ~119 ~93 dirt
setblock ~172 ~119 ~94 dirt
setblock ~172 ~119 ~95 dirt
setblock ~172 ~119 ~96 dirt
setblock ~172 ~119 ~97 dirt
setblock ~172 ~119 ~98 dirt
setblock ~172 ~119 ~99 dirt
setblock ~172 ~119 ~100 dirt
setblock ~172 ~119 ~128 dirt
setblock ~172 ~120 ~47 dirt
setblock ~172 ~120 ~48 dirt
setblock ~172 ~120 ~49 dirt
setblock ~172 ~120 ~50 dirt
setblock ~172 ~120 ~63 dirt
setblock ~172 ~120 ~64 dirt
setblock ~172 ~120 ~65 dirt
setblock ~172 ~120 ~66 dirt
setblock ~172 ~120 ~67 dirt
setblock ~172 ~120 ~68 dirt
setblock ~172 ~120 ~69 dirt
setblock ~172 ~120 ~70 dirt
setblock ~172 ~120 ~86 dirt
setblock ~172 ~120 ~87 dirt
setblock ~172 ~120 ~88 dirt
setblock ~172 ~120 ~89 dirt
setblock ~172 ~120 ~90 dirt
setblock ~172 ~120 ~91 dirt
setblock ~172 ~120 ~92 dirt
setblock ~172 ~120 ~93 dirt
setblock ~172 ~120 ~94 dirt
setblock ~172 ~120 ~95 dirt
setblock ~172 ~120 ~96 dirt
setblock ~172 ~120 ~97 dirt
setblock ~172 ~120 ~98 dirt
setblock ~172 ~120 ~99 dirt
setblock ~172 ~120 ~100 dirt
setblock ~172 ~120 ~101 dirt
setblock ~172 ~120 ~127 dirt
setblock ~172 ~120 ~128 dirt
setblock ~172 ~120 ~129 dirt
setblock ~172 ~121 ~46 dirt
setblock ~172 ~121 ~47 dirt
setblock ~172 ~121 ~48 dirt
setblock ~172 ~121 ~49 dirt
setblock ~172 ~121 ~50 dirt
setblock ~172 ~121 ~51 dirt
setblock ~172 ~121 ~62 dirt
setblock ~172 ~121 ~63 dirt
setblock ~172 ~121 ~64 dirt
setblock ~172 ~121 ~65 dirt
setblock ~172 ~121 ~66 dirt
setblock ~172 ~121 ~67 dirt
setblock ~172 ~121 ~68 dirt
setblock ~172 ~121 ~69 dirt
setblock ~172 ~121 ~70 dirt
setblock ~172 ~121 ~71 dirt
setblock ~172 ~121 ~85 dirt
setblock ~172 ~121 ~86 dirt
setblock ~172 ~121 ~87 dirt
setblock ~172 ~121 ~88 dirt
setblock ~172 ~121 ~89 dirt
setblock ~172 ~121 ~90 dirt
setblock ~172 ~121 ~91 dirt
setblock ~172 ~121 ~92 dirt
setblock ~172 ~121 ~93 dirt
setblock ~172 ~121 ~94 dirt
setblock ~172 ~121 ~95 dirt
setblock ~172 ~121 ~96 dirt
setblock ~172 ~121 ~97 dirt
setblock ~172 ~121 ~98 dirt
setblock ~172 ~121 ~99 dirt
setblock ~172 ~121 ~100 dirt
setblock ~172 ~121 ~101 dirt
setblock ~172 ~121 ~102 dirt
setblock ~172 ~121 ~103 dirt
setblock ~172 ~121 ~126 dirt
setblock ~172 ~121 ~127 dirt
setblock ~172 ~121 ~128 dirt
setblock ~172 ~121 ~129 dirt
setblock ~172 ~121 ~130 dirt
setblock ~172 ~122 ~46 dirt
setblock ~172 ~122 ~47 dirt
setblock ~172 ~122 ~48 dirt
setblock ~172 ~122 ~49 dirt
setblock ~172 ~122 ~50 dirt
setblock ~172 ~122 ~51 dirt
setblock ~172 ~122 ~62 dirt
setblock ~172 ~122 ~63 dirt
setblock ~172 ~122 ~64 dirt
setblock ~172 ~122 ~65 dirt
setblock ~172 ~122 ~66 dirt
setblock ~172 ~122 ~67 dirt
setblock ~172 ~122 ~68 dirt
setblock ~172 ~122 ~69 dirt
setblock ~172 ~122 ~70 dirt
setblock ~172 ~122 ~71 dirt
setblock ~172 ~122 ~85 dirt
setblock ~172 ~122 ~86 dirt
setblock ~172 ~122 ~87 dirt
setblock ~172 ~122 ~88 dirt
setblock ~172 ~122 ~89 dirt
setblock ~172 ~122 ~90 dirt
setblock ~172 ~122 ~91 dirt
setblock ~172 ~122 ~92 dirt
setblock ~172 ~122 ~93 dirt
setblock ~172 ~122 ~94 dirt
setblock ~172 ~122 ~95 dirt
setblock ~172 ~122 ~96 dirt
setblock ~172 ~122 ~97 dirt
setblock ~172 ~122 ~98 dirt
setblock ~172 ~122 ~99 dirt
