setblock ~0 ~1 ~0 gold_block
setblock ~7 ~120 ~103 dirt
setblock ~7 ~121 ~96 dirt
setblock ~7 ~121 ~97 dirt
setblock ~7 ~121 ~98 dirt
setblock ~7 ~121 ~99 dirt
setblock ~7 ~121 ~100 dirt
setblock ~7 ~121 ~101 dirt
setblock ~7 ~121 ~102 dirt
setblock ~7 ~121 ~103 dirt
setblock ~7 ~122 ~96 dirt
setblock ~7 ~122 ~97 dirt
setblock ~7 ~122 ~98 dirt
setblock ~7 ~122 ~99 dirt
setblock ~7 ~122 ~100 dirt
setblock ~7 ~122 ~101 dirt
setblock ~7 ~122 ~102 dirt
setblock ~7 ~122 ~103 dirt
setblock ~7 ~123 ~96 dirt
setblock ~7 ~123 ~97 dirt
setblock ~7 ~123 ~98 dirt
setblock ~7 ~123 ~99 dirt
setblock ~7 ~123 ~100 dirt
setblock ~7 ~123 ~101 dirt
setblock ~7 ~123 ~102 dirt
setblock ~7 ~123 ~103 dirt
setblock ~7 ~124 ~96 dirt
setblock ~7 ~124 ~97 dirt
setblock ~7 ~124 ~98 dirt
setblock ~7 ~124 ~99 dirt
setblock ~7 ~124 ~100 dirt
setblock ~7 ~124 ~101 dirt
setblock ~7 ~124 ~102 dirt
setblock ~7 ~124 ~103 dirt
setblock ~7 ~125 ~96 dirt
setblock ~7 ~125 ~97 dirt
setblock ~7 ~125 ~98 dirt
setblock ~7 ~125 ~99 dirt
setblock ~7 ~125 ~100 dirt
setblock ~7 ~125 ~101 dirt
setblock ~7 ~125 ~102 dirt
setblock ~7 ~125 ~103 dirt
setblock ~7 ~126 ~96 grass_block
setblock ~7 ~126 ~97 grass_block
setblock ~7 ~126 ~98 grass_block
setblock ~7 ~126 ~99 dirt
setblock ~7 ~126 ~100 dirt
setblock ~7 ~126 ~101 dirt
setblock ~7 ~126 ~102 dirt
setblock ~7 ~126 ~103 dirt
setblock ~7 ~127 ~97 fern
setblock ~7 ~127 ~99 grass_block
setblock ~7 ~127 ~100 dirt
setblock ~7 ~127 ~101 grass_block
setblock ~7 ~127 ~102 grass_block
setblock ~7 ~127 ~103 grass_block
setblock ~7 ~128 ~100 grass_block
setblock ~7 ~128 ~102 fern
setblock ~8 ~119 ~98 dirt
setblock ~8 ~119 ~101 dirt
setblock ~8 ~119 ~103 dirt
setblock ~8 ~120 ~96 dirt
setblock ~8 ~120 ~97 dirt
setblock ~8 ~120 ~98 dirt
setblock ~8 ~120 ~99 dirt
setblock ~8 ~120 ~100 dirt
setblock ~8 ~120 ~101 dirt
setblock ~8 ~120 ~102 dirt
setblock ~8 ~120 ~103 dirt
setblock ~8 ~120 ~104 dirt
setblock ~8 ~121 ~95 dirt
setblock ~8 ~121 ~96 dirt
setblock ~8 ~121 ~97 dirt
setblock ~8 ~121 ~98 dirt
setblock ~8 ~121 ~99 dirt
setblock ~8 ~121 ~100 dirt
setblock ~8 ~121 ~101 dirt
setblock ~8 ~121 ~102 dirt
setblock ~8 ~121 ~103 dirt
setblock ~8 ~121 ~104 dirt
setblock ~8 ~122 ~95 dirt
setblock ~8 ~122 ~96 dirt
setblock ~8 ~122 ~97 dirt
setblock ~8 ~122 ~98 dirt
setblock ~8 ~122 ~99 dirt
setblock ~8 ~122 ~100 dirt
setblock ~8 ~122 ~101 dirt
setblock ~8 ~122 ~102 dirt
setblock ~8 ~122 ~103 dirt
setblock ~8 ~122 ~104 dirt
setblock ~8 ~123 ~95 dirt
setblock ~8 ~123 ~96 dirt
setblock ~8 ~123 ~97 dirt
setblock ~8 ~123 ~98 dirt
setblock ~8 ~123 ~99 dirt
setblock ~8 ~123 ~100 dirt
setblock ~8 ~123 ~101 dirt
setblock ~8 ~123 ~102 dirt
setblock ~8 ~123 ~103 dirt
setblock ~8 ~123 ~104 dirt
setblock ~8 ~124 ~95 dirt
setblock ~8 ~124 ~96 dirt
setblock ~8 ~124 ~97 dirt
setblock ~8 ~124 ~98 dirt
setblock ~8 ~124 ~99 dirt
setblock ~8 ~124 ~100 dirt
setblock ~8 ~124 ~101 dirt
setblock ~8 ~124 ~102 dirt
setblock ~8 ~124 ~103 dirt
setblock ~8 ~124 ~104 dirt
setblock ~8 ~125 ~95 grass_block
setblock ~8 ~125 ~96 grass_block
setblock ~8 ~125 ~97 dirt
setblock ~8 ~125 ~98 dirt
setblock ~8 ~125 ~99 dirt
setblock ~8 ~125 ~100 dirt
setblock ~8 ~125 ~101 dirt
setblock ~8 ~125 ~102 dirt
setblock ~8 ~125 ~103 dirt
setblock ~8 ~125 ~104 dirt
setblock ~8 ~126 ~97 grass_block
setblock ~8 ~126 ~98 dirt
setblock ~8 ~126 ~99 dirt
setblock ~8 ~126 ~100 dirt
setblock ~8 ~126 ~101 dirt
setblock ~8 ~126 ~102 dirt
setblock ~8 ~126 ~103 dirt
setblock ~8 ~126 ~104 dirt
setblock ~8 ~127 ~98 grass_block
setblock ~8 ~127 ~99 grass_block
setblock ~8 ~127 ~100 dirt
setblock ~8 ~127 ~101 dirt
setblock ~8 ~127 ~102 grass_block
setblock ~8 ~127 ~103 grass_block
setblock ~8 ~127 ~104 grass_block
setblock ~8 ~128 ~100 grass_block
setblock ~8 ~128 ~101 grass_block
setblock ~9 ~118 ~97 dirt
setblock ~9 ~118 ~98 dirt
setblock ~9 ~118 ~99 dirt
setblock ~9 ~118 ~101 dirt
setblock ~9 ~118 ~102 dirt
setblock ~9 ~118 ~103 dirt
setblock ~9 ~119 ~96 dirt
setblock ~9 ~119 ~97 dirt
setblock ~9 ~119 ~98 dirt
setblock ~9 ~119 ~99 dirt
setblock ~9 ~119 ~100 dirt
setblock ~9 ~119 ~101 dirt
setblock ~9 ~119 ~102 dirt
setblock ~9 ~119 ~103 dirt
setblock ~9 ~119 ~104 dirt
setblock ~9 ~120 ~95 dirt
setblock ~9 ~120 ~96 dirt
setblock ~9 ~120 ~97 dirt
setblock ~9 ~120 ~98 dirt
setblock ~9 ~120 ~99 dirt
setblock ~9 ~120 ~100 dirt
setblock ~9 ~120 ~101 dirt
setblock ~9 ~120 ~102 dirt
setblock ~9 ~120 ~103 dirt
setblock ~9 ~120 ~104 dirt
setblock ~9 ~121 ~94 dirt
setblock ~9 ~121 ~95 dirt
setblock ~9 ~121 ~96 dirt
setblock ~9 ~121 ~97 dirt
setblock ~9 ~121 ~98 dirt
setblock ~9 ~121 ~99 dirt
setblock ~9 ~121 ~100 dirt
setblock ~9 ~121 ~101 dirt
setblock ~9 ~121 ~102 dirt
setblock ~9 ~121 ~103 dirt
setblock ~9 ~121 ~104 dirt
setblock ~9 ~121 ~105 dirt
setblock ~9 ~121 ~106 dirt
setblock ~9 ~121 ~107 dirt
setblock ~9 ~122 ~94 dirt
setblock ~9 ~122 ~95 dirt
setblock ~9 ~122 ~96 dirt
setblock ~9 ~122 ~97 dirt
setblock ~9 ~122 ~98 dirt
setblock ~9 ~122 ~99 dirt
setblock ~9 ~122 ~100 dirt
setblock ~9 ~122 ~101 dirt
setblock ~9 ~122 ~102 dirt
setblock ~9 ~122 ~103 dirt
setblock ~9 ~122 ~104 dirt
setblock ~9 ~122 ~105 dirt
setblock ~9 ~122 ~106 dirt
setblock ~9 ~122 ~107 dirt
setblock ~9 ~123 ~94 dirt
setblock ~9 ~123 ~95 dirt
setblock ~9 ~123 ~96 dirt
setblock ~9 ~123 ~97 dirt
setblock ~9 ~123 ~98 dirt
setblock ~9 ~123 ~99 dirt
setblock ~9 ~123 ~100 dirt
setblock ~9 ~123 ~101 dirt
setblock ~9 ~123 ~102 dirt
setblock ~9 ~123 ~103 dirt
setblock ~9 ~123 ~104 dirt
setblock ~9 ~123 ~105 dirt
setblock ~9 ~123 ~106 dirt
setblock ~9 ~123 ~107 dirt
setblock ~9 ~124 ~94 grass_block
setblock ~9 ~124 ~95 dirt
setblock ~9 ~124 ~96 dirt
setblock ~9 ~124 ~97 dirt
setblock ~9 ~124 ~98 dirt
setblock ~9 ~124 ~99 dirt
setblock ~9 ~124 ~100 dirt
setblock ~9 ~124 ~101 dirt
setblock ~9 ~124 ~102 dirt
setblock ~9 ~124 ~103 dirt
setblock ~9 ~124 ~104 dirt
setblock ~9 ~124 ~105 dirt
setblock ~9 ~124 ~106 dirt
setblock ~9 ~124 ~107 dirt
setblock ~9 ~125 ~95 grass_block
setblock ~9 ~125 ~96 grass_block
setblock ~9 ~125 ~97 dirt
setblock ~9 ~125 ~98 dirt
setblock ~9 ~125 ~99 dirt
setblock ~9 ~125 ~100 dirt
setblock ~9 ~125 ~101 dirt
setblock ~9 ~125 ~102 dirt
setblock ~9 ~125 ~103 dirt
setblock ~9 ~125 ~104 dirt
setblock ~9 ~125 ~105 dirt
setblock ~9 ~125 ~106 dirt
setblock ~9 ~125 ~107 dirt
setblock ~9 ~126 ~97 grass_block
setblock ~9 ~126 ~98 dirt
setblock ~9 ~126 ~99 dirt
setblock ~9 ~126 ~100 dirt
setblock ~9 ~126 ~101 dirt
setblock ~9 ~126 ~102 dirt
setblock ~9 ~126 ~103 dirt
setblock ~9 ~126 ~104 dirt
setblock ~9 ~126 ~105 dirt
setblock ~9 ~126 ~106 grass_block
setblock ~9 ~126 ~107 grass_block
setblock ~9 ~127 ~97 fern
setblock ~9 ~127 ~98 grass_block
setblock ~9 ~127 ~99 dirt
setblock ~9 ~127 ~100 dirt
setblock ~9 ~127 ~101 dirt
setblock ~9 ~127 ~102 dirt
setblock ~9 ~127 ~103 grass_block
setblock ~9 ~127 ~104 grass_block
setblock ~9 ~127 ~105 grass_block
setblock ~9 ~127 ~106 short_grass
setblock ~9 ~127 ~107 short_grass
setblock ~9 ~128 ~99 grass_block
setblock ~9 ~128 ~100 dirt
setblock ~9 ~128 ~101 grass_block
setblock ~9 ~128 ~102 grass_block
setblock ~9 ~128 ~104 short_grass
setblock ~9 ~128 ~105 poppy
setblock ~9 ~129 ~99 poppy
setblock ~9 ~129 ~100 grass_block
setblock ~10 ~116 ~98 dirt
setblock ~10 ~116 ~101 dirt
setblock ~10 ~116 ~102 dirt
setblock ~10 ~117 ~97 dirt
setblock ~10 ~117 ~98 dirt
setblock ~10 ~117 ~99 dirt
setblock ~10 ~117 ~100 dirt
setblock ~10 ~117 ~101 dirt
setblock ~10 ~117 ~102 dirt
setblock ~10 ~117 ~103 dirt
setblock ~10 ~118 ~96 dirt
setblock ~10 ~118 ~97 dirt
setblock ~10 ~118 ~98 dirt
setblock ~10 ~118 ~99 dirt
setblock ~10 ~118 ~100 dirt
setblock ~10 ~118 ~101 dirt
setblock ~10 ~118 ~102 dirt
setblock ~10 ~118 ~103 dirt
setblock ~10 ~118 ~104 dirt
setblock ~10 ~119 ~95 dirt
setblock ~10 ~119 ~96 dirt
setblock ~10 ~119 ~97 dirt
setblock ~10 ~119 ~98 dirt
setblock ~10 ~119 ~99 dirt
setblock ~10 ~119 ~100 dirt
setblock ~10 ~119 ~101 dirt
setblock ~10 ~119 ~102 dirt
setblock ~10 ~119 ~103 dirt
setblock ~10 ~119 ~104 dirt
setblock ~10 ~119 ~105 dirt
setblock ~10 ~120 ~94 dirt
setblock ~10 ~120 ~95 dirt
setblock ~10 ~120 ~96 dirt
setblock ~10 ~120 ~97 dirt
setblock ~10 ~120 ~98 dirt
setblock ~10 ~120 ~99 dirt
setblock ~10 ~120 ~100 dirt
setblock ~10 ~120 ~101 dirt
setblock ~10 ~120 ~102 dirt
setblock ~10 ~120 ~103 dirt
setblock ~10 ~120 ~104 dirt
setblock ~10 ~120 ~105 dirt
setblock ~10 ~120 ~106 dirt
setblock ~10 ~120 ~107 dirt
setblock ~10 ~121 ~93 dirt
setblock ~10 ~121 ~94 dirt
setblock ~10 ~121 ~95 dirt
setblock ~10 ~121 ~96 dirt
setblock ~10 ~121 ~97 dirt
setblock ~10 ~121 ~98 dirt
setblock ~10 ~121 ~99 dirt
setblock ~10 ~121 ~100 dirt
setblock ~10 ~121 ~101 dirt
setblock ~10 ~121 ~102 dirt
setblock ~10 ~121 ~103 dirt
setblock ~10 ~121 ~104 dirt
setblock ~10 ~121 ~105 dirt
setblock ~10 ~121 ~106 dirt
setblock ~10 ~121 ~107 dirt
setblock ~10 ~121 ~108 dirt
setblock ~10 ~122 ~93 dirt
setblock ~10 ~122 ~94 dirt
setblock ~10 ~122 ~95 dirt
setblock ~10 ~122 ~96 dirt
setblock ~10 ~122 ~97 dirt
setblock ~10 ~122 ~98 dirt
setblock ~10 ~122 ~99 dirt
setblock ~10 ~122 ~100 dirt
setblock ~10 ~122 ~101 dirt
setblock ~10 ~122 ~102 dirt
setblock ~10 ~122 ~103 dirt
setblock ~10 ~122 ~104 dirt
setblock ~10 ~122 ~105 dirt
setblock ~10 ~122 ~106 dirt
setblock ~10 ~122 ~107 dirt
setblock ~10 ~122 ~108 dirt
setblock ~10 ~123 ~93 grass_block
setblock ~10 ~123 ~94 dirt
setblock ~10 ~123 ~95 dirt
setblock ~10 ~123 ~96 dirt
setblock ~10 ~123 ~97 dirt
setblock ~10 ~123 ~98 dirt
setblock ~10 ~123 ~99 dirt
setblock ~10 ~123 ~100 dirt
setblock ~10 ~123 ~101 dirt
setblock ~10 ~123 ~102 dirt
setblock ~10 ~123 ~103 dirt
setblock ~10 ~123 ~104 dirt
setblock ~10 ~123 ~105 dirt
setblock ~10 ~123 ~106 dirt
setblock ~10 ~123 ~107 dirt
setblock ~10 ~123 ~108 dirt
setblock ~10 ~124 ~94 grass_block
setblock ~10 ~124 ~95 dirt
setblock ~10 ~124 ~96 dirt
setblock ~10 ~124 ~97 dirt
setblock ~10 ~124 ~98 dirt
setblock ~10 ~124 ~99 dirt
setblock ~10 ~124 ~100 dirt
setblock ~10 ~124 ~101 dirt
setblock ~10 ~124 ~102 dirt
setblock ~10 ~124 ~103 dirt
setblock ~10 ~124 ~104 dirt
setblock ~10 ~124 ~105 dirt
setblock ~10 ~124 ~106 dirt
setblock ~10 ~124 ~107 dirt
setblock ~10 ~124 ~108 dirt
setblock ~10 ~125 ~95 grass_block
setblock ~10 ~125 ~96 grass_block
setblock ~10 ~125 ~97 dirt
setblock ~10 ~125 ~98 dirt
setblock ~10 ~125 ~99 dirt
setblock ~10 ~125 ~100 dirt
setblock ~10 ~125 ~101 dirt
setblock ~10 ~125 ~102 dirt
setblock ~10 ~125 ~103 dirt
setblock ~10 ~125 ~104 dirt
setblock ~10 ~125 ~105 dirt
setblock ~10 ~125 ~106 dirt
setblock ~10 ~125 ~107 dirt
setblock ~10 ~125 ~108 dirt
setblock ~10 ~126 ~97 grass_block
setblock ~10 ~126 ~98 dirt
setblock ~10 ~126 ~99 dirt
setblock ~10 ~126 ~100 dirt
setblock ~10 ~126 ~101 dirt
setblock ~10 ~126 ~102 dirt
setblock ~10 ~126 ~103 dirt
setblock ~10 ~126 ~104 dirt
setblock ~10 ~126 ~105 dirt
setblock ~10 ~126 ~106 dirt
setblock ~10 ~126 ~107 grass_block
setblock ~10 ~126 ~108 grass_block
setblock ~10 ~127 ~97 short_grass
setblock ~10 ~127 ~98 grass_block
setblock ~10 ~127 ~99 dirt
setblock ~10 ~127 ~100 dirt
setblock ~10 ~127 ~101 dirt
setblock ~10 ~127 ~102 dirt
setblock ~10 ~127 ~103 dirt
setblock ~10 ~127 ~104 grass_block
setblock ~10 ~127 ~105 grass_block
setblock ~10 ~127 ~106 grass_block
setblock ~10 ~128 ~98 short_grass
setblock ~10 ~128 ~99 grass_block
setblock ~10 ~128 ~100 dirt
setblock ~10 ~128 ~101 dirt
setblock ~10 ~128 ~102 grass_block
setblock ~10 ~128 ~103 grass_block
setblock ~10 ~129 ~99 short_grass
setblock ~10 ~129 ~100 grass_block
setblock ~10 ~129 ~101 grass_block
setblock ~11 ~115 ~98 dirt
setblock ~11 ~115 ~101 dirt
setblock ~11 ~115 ~102 dirt
setblock ~11 ~116 ~97 dirt
setblock ~11 ~116 ~98 dirt
setblock ~11 ~116 ~99 dirt
setblock ~11 ~116 ~100 dirt
setblock ~11 ~116 ~101 dirt
setblock ~11 ~116 ~102 dirt
setblock ~11 ~116 ~103 dirt
setblock ~11 ~116 ~104 dirt
setblock ~11 ~117 ~96 dirt
setblock ~11 ~117 ~97 dirt
setblock ~11 ~117 ~98 dirt
setblock ~11 ~117 ~99 dirt
setblock ~11 ~117 ~100 dirt
setblock ~11 ~117 ~101 dirt
setblock ~11 ~117 ~102 dirt
setblock ~11 ~117 ~103 dirt
setblock ~11 ~117 ~104 dirt
setblock ~11 ~117 ~105 dirt
setblock ~11 ~118 ~95 dirt
setblock ~11 ~118 ~96 dirt
setblock ~11 ~118 ~97 dirt
setblock ~11 ~118 ~98 dirt
setblock ~11 ~118 ~99 dirt
setblock ~11 ~118 ~100 dirt
setblock ~11 ~118 ~101 dirt
setblock ~11 ~118 ~102 dirt
setblock ~11 ~118 ~103 dirt
setblock ~11 ~118 ~104 dirt
setblock ~11 ~118 ~105 dirt
setblock ~11 ~118 ~106 dirt
setblock ~11 ~119 ~94 dirt
setblock ~11 ~119 ~95 dirt
setblock ~11 ~119 ~96 dirt
setblock ~11 ~119 ~97 dirt
setblock ~11 ~119 ~98 dirt
setblock ~11 ~119 ~99 dirt
setblock ~11 ~119 ~100 dirt
setblock ~11 ~119 ~101 dirt
setblock ~11 ~119 ~102 dirt
setblock ~11 ~119 ~103 dirt
setblock ~11 ~119 ~104 dirt
setblock ~11 ~119 ~105 dirt
setblock ~11 ~119 ~106 dirt
setblock ~11 ~119 ~107 dirt
setblock ~11 ~120 ~94 dirt
setblock ~11 ~120 ~95 dirt
setblock ~11 ~120 ~96 dirt
setblock ~11 ~120 ~97 dirt
setblock ~11 ~120 ~98 dirt
setblock ~11 ~120 ~99 dirt
setblock ~11 ~120 ~100 dirt
setblock ~11 ~120 ~101 dirt
setblock ~11 ~120 ~102 dirt
setblock ~11 ~120 ~103 dirt
setblock ~11 ~120 ~104 dirt
setblock ~11 ~120 ~105 dirt
setblock ~11 ~120 ~106 dirt
setblock ~11 ~120 ~107 dirt
setblock ~11 ~120 ~108 dirt
setblock ~11 ~121 ~93 dirt
setblock ~11 ~121 ~94 dirt
setblock ~11 ~121 ~95 dirt
setblock ~11 ~121 ~96 dirt
setblock ~11 ~121 ~97 dirt
setblock ~11 ~121 ~98 dirt
setblock ~11 ~121 ~99 dirt
setblock ~11 ~121 ~100 dirt
setblock ~11 ~121 ~101 dirt
setblock ~11 ~121 ~102 dirt
setblock ~11 ~121 ~103 dirt
setblock ~11 ~121 ~104 dirt
setblock ~11 ~121 ~105 dirt
setblock ~11 ~121 ~106 dirt
setblock ~11 ~121 ~107 dirt
setblock ~11 ~121 ~108 dirt
setblock ~11 ~121 ~109 dirt
setblock ~11 ~122 ~93 dirt
setblock ~11 ~122 ~94 dirt
setblock ~11 ~122 ~95 dirt
setblock ~11 ~122 ~96 dirt
setblock ~11 ~122 ~97 dirt
setblock ~11 ~122 ~98 dirt
setblock ~11 ~122 ~99 dirt
setblock ~11 ~122 ~100 dirt
setblock ~11 ~122 ~101 dirt
setblock ~11 ~122 ~102 dirt
setblock ~11 ~122 ~103 dirt
setblock ~11 ~122 ~104 dirt
setblock ~11 ~122 ~105 dirt
setblock ~11 ~122 ~106 dirt
setblock ~11 ~122 ~107 dirt
setblock ~11 ~122 ~108 dirt
setblock ~11 ~122 ~109 dirt
setblock ~11 ~123 ~93 grass_block
setblock ~11 ~123 ~94 dirt
setblock ~11 ~123 ~95 dirt
setblock ~11 ~123 ~96 dirt
setblock ~11 ~123 ~97 dirt
setblock ~11 ~123 ~98 dirt
setblock ~11 ~123 ~99 dirt
setblock ~11 ~123 ~100 dirt
setblock ~11 ~123 ~101 dirt
setblock ~11 ~123 ~102 dirt
setblock ~11 ~123 ~103 dirt
setblock ~11 ~123 ~104 dirt
setblock ~11 ~123 ~105 dirt
setblock ~11 ~123 ~106 dirt
setblock ~11 ~123 ~107 dirt
setblock ~11 ~123 ~108 dirt
setblock ~11 ~123 ~109 dirt
setblock ~11 ~124 ~94 grass_block
setblock ~11 ~124 ~95 dirt
setblock ~11 ~124 ~96 dirt
setblock ~11 ~124 ~97 dirt
setblock ~11 ~124 ~98 dirt
setblock ~11 ~124 ~99 dirt
setblock ~11 ~124 ~100 dirt
setblock ~11 ~124 ~101 dirt
setblock ~11 ~124 ~102 dirt
setblock ~11 ~124 ~103 dirt
setblock ~11 ~124 ~104 dirt
setblock ~11 ~124 ~105 dirt
setblock ~11 ~124 ~106 dirt
setblock ~11 ~124 ~107 dirt
setblock ~11 ~124 ~108 dirt
setblock ~11 ~124 ~109 dirt
setblock ~11 ~125 ~95 grass_block
setblock ~11 ~125 ~96 grass_block
setblock ~11 ~125 ~97 dirt
setblock ~11 ~125 ~98 dirt
setblock ~11 ~125 ~99 dirt
setblock ~11 ~125 ~100 dirt
setblock ~11 ~125 ~101 dirt
setblock ~11 ~125 ~102 dirt
setblock ~11 ~125 ~103 dirt
setblock ~11 ~125 ~104 dirt
setblock ~11 ~125 ~105 dirt
setblock ~11 ~125 ~106 dirt
setblock ~11 ~125 ~107 dirt
setblock ~11 ~125 ~108 dirt
setblock ~11 ~125 ~109 dirt
setblock ~11 ~126 ~97 grass_block
setblock ~11 ~126 ~98 dirt
setblock ~11 ~126 ~99 dirt
setblock ~11 ~126 ~100 dirt
setblock ~11 ~126 ~101 dirt
setblock ~11 ~126 ~102 dirt
setblock ~11 ~126 ~103 dirt
setblock ~11 ~126 ~104 dirt
setblock ~11 ~126 ~105 dirt
setblock ~11 ~126 ~106 grass_block
setblock ~11 ~126 ~107 grass_block
setblock ~11 ~126 ~108 grass_block
setblock ~11 ~126 ~109 grass_block
setblock ~11 ~127 ~98 grass_block
setblock ~11 ~127 ~99 grass_block
setblock ~11 ~127 ~100 dirt
setblock ~11 ~127 ~101 dirt
setblock ~11 ~127 ~102 grass_block
setblock ~11 ~127 ~103 grass_block
setblock ~11 ~127 ~104 grass_block
setblock ~11 ~127 ~105 grass_block
setblock ~11 ~128 ~100 grass_block
setblock ~11 ~128 ~101 grass_block
setblock ~11 ~128 ~103 short_grass
setblock ~11 ~129 ~100 short_grass
setblock ~11 ~129 ~101 short_grass
setblock ~12 ~114 ~98 dirt
setblock ~12 ~114 ~101 dirt
setblock ~12 ~114 ~102 dirt
setblock ~12 ~114 ~103 dirt
setblock ~12 ~115 ~97 dirt
setblock ~12 ~115 ~98 dirt
setblock ~12 ~115 ~99 dirt
setblock ~12 ~115 ~100 dirt
setblock ~12 ~115 ~101 dirt
setblock ~12 ~115 ~102 dirt
setblock ~12 ~115 ~103 dirt
setblock ~12 ~115 ~104 dirt
setblock ~12 ~116 ~96 dirt
setblock ~12 ~116 ~97 dirt
setblock ~12 ~116 ~98 dirt
setblock ~12 ~116 ~99 dirt
setblock ~12 ~116 ~100 dirt
setblock ~12 ~116 ~101 dirt
setblock ~12 ~116 ~102 dirt
setblock ~12 ~116 ~103 dirt
setblock ~12 ~116 ~104 dirt
setblock ~12 ~116 ~105 dirt
setblock ~12 ~117 ~95 dirt
setblock ~12 ~117 ~96 dirt
setblock ~12 ~117 ~97 dirt
setblock ~12 ~117 ~98 dirt
setblock ~12 ~117 ~99 dirt
setblock ~12 ~117 ~100 dirt
setblock ~12 ~117 ~101 dirt
setblock ~12 ~117 ~102 dirt
setblock ~12 ~117 ~103 dirt
setblock ~12 ~117 ~104 dirt
setblock ~12 ~117 ~105 dirt
setblock ~12 ~117 ~106 dirt
setblock ~12 ~118 ~94 dirt
setblock ~12 ~118 ~95 dirt
setblock ~12 ~118 ~96 dirt
setblock ~12 ~118 ~97 dirt
setblock ~12 ~118 ~98 dirt
setblock ~12 ~118 ~99 dirt
setblock ~12 ~118 ~100 dirt
setblock ~12 ~118 ~101 dirt
setblock ~12 ~118 ~102 dirt
setblock ~12 ~118 ~103 dirt
setblock ~12 ~118 ~104 dirt
setblock ~12 ~118 ~105 dirt
setblock ~12 ~118 ~106 dirt
setblock ~12 ~118 ~107 dirt
setblock ~12 ~119 ~70 dirt
setblock ~12 ~119 ~93 dirt
setblock ~12 ~119 ~94 dirt
setblock ~12 ~119 ~95 dirt
setblock ~12 ~119 ~96 dirt
setblock ~12 ~119 ~97 dirt
setblock ~12 ~119 ~98 dirt
setblock ~12 ~119 ~99 dirt
setblock ~12 ~119 ~100 dirt
setblock ~12 ~119 ~101 dirt
setblock ~12 ~119 ~102 dirt
setblock ~12 ~119 ~103 dirt
setblock ~12 ~119 ~104 dirt
setblock ~12 ~119 ~105 dirt
setblock ~12 ~119 ~106 dirt
setblock ~12 ~119 ~107 dirt
setblock ~12 ~119 ~108 dirt
setblock ~12 ~120 ~70 dirt
setblock ~12 ~120 ~93 dirt
setblock ~12 ~120 ~94 dirt
setblock ~12 ~120 ~95 dirt
setblock ~12 ~120 ~96 dirt
setblock ~12 ~120 ~97 dirt
setblock ~12 ~120 ~98 dirt
setblock ~12 ~120 ~99 dirt
setblock ~12 ~120 ~100 dirt
setblock ~12 ~120 ~101 dirt
setblock ~12 ~120 ~102 dirt
setblock ~12 ~120 ~103 dirt
setblock ~12 ~120 ~104 dirt
setblock ~12 ~120 ~105 dirt
setblock ~12 ~120 ~106 dirt
setblock ~12 ~120 ~107 dirt
setblock ~12 ~120 ~108 dirt
setblock ~12 ~120 ~109 dirt
setblock ~12 ~121 ~70 dirt
setblock ~12 ~121 ~71 dirt
setblock ~12 ~121 ~92 dirt
setblock ~12 ~121 ~93 dirt
setblock ~12 ~121 ~94 dirt
setblock ~12 ~121 ~95 dirt
setblock ~12 ~121 ~96 dirt
setblock ~12 ~121 ~97 dirt
setblock ~12 ~121 ~98 dirt
setblock ~12 ~121 ~99 dirt
setblock ~12 ~121 ~100 dirt
setblock ~12 ~121 ~101 dirt
setblock ~12 ~121 ~102 dirt
setblock ~12 ~121 ~103 dirt
setblock ~12 ~121 ~104 dirt
setblock ~12 ~121 ~105 dirt
setblock ~12 ~121 ~106 dirt
setblock ~12 ~121 ~107 dirt
setblock ~12 ~121 ~108 dirt
setblock ~12 ~121 ~109 dirt
setblock ~12 ~121 ~110 dirt
setblock ~12 ~122 ~70 dirt
setblock ~12 ~122 ~71 dirt
setblock ~12 ~122 ~92 dirt
setblock ~12 ~122 ~93 dirt
setblock ~12 ~122 ~94 dirt
setblock ~12 ~122 ~95 dirt
setblock ~12 ~122 ~96 dirt
setblock ~12 ~122 ~97 dirt
setblock ~12 ~122 ~98 dirt
setblock ~12 ~122 ~99 dirt
setblock ~12 ~122 ~100 dirt
setblock ~12 ~122 ~101 dirt
setblock ~12 ~122 ~102 dirt
setblock ~12 ~122 ~103 dirt
setblock ~12 ~122 ~104 dirt
setblock ~12 ~122 ~105 dirt
setblock ~12 ~122 ~106 dirt
setblock ~12 ~122 ~107 dirt
setblock ~12 ~122 ~108 dirt
setblock ~12 ~122 ~109 dirt
setblock ~12 ~122 ~110 dirt
setblock ~12 ~123 ~70 grass_block
setblock ~12 ~123 ~71 grass_block
setblock ~12 ~123 ~92 grass_block
setblock ~12 ~123 ~93 dirt
setblock ~12 ~123 ~94 dirt
setblock ~12 ~123 ~95 dirt
setblock ~12 ~123 ~96 dirt
setblock ~12 ~123 ~97 dirt
setblock ~12 ~123 ~98 dirt
setblock ~12 ~123 ~99 dirt
setblock ~12 ~123 ~100 dirt
setblock ~12 ~123 ~101 dirt
setblock ~12 ~123 ~102 dirt
setblock ~12 ~123 ~103 dirt
setblock ~12 ~123 ~104 dirt
setblock ~12 ~123 ~105 dirt
setblock ~12 ~123 ~106 dirt
setblock ~12 ~123 ~107 dirt
setblock ~12 ~123 ~108 dirt
setblock ~12 ~123 ~109 dirt
setblock ~12 ~123 ~110 dirt
setblock ~12 ~124 ~71 short_grass
setblock ~12 ~124 ~93 grass_block
setblock ~12 ~124 ~94 grass_block
setblock ~12 ~124 ~95 dirt
setblock ~12 ~124 ~96 dirt
setblock ~12 ~124 ~97 dirt
setblock ~12 ~124 ~98 dirt
setblock ~12 ~124 ~99 dirt
setblock ~12 ~124 ~100 dirt
setblock ~12 ~124 ~101 dirt
setblock ~12 ~124 ~102 dirt
setblock ~12 ~124 ~103 dirt
setblock ~12 ~124 ~104 dirt
setblock ~12 ~124 ~105 dirt
setblock ~12 ~124 ~106 dirt
setblock ~12 ~124 ~107 dirt
setblock ~12 ~124 ~108 dirt
setblock ~12 ~124 ~109 dirt
setblock ~12 ~124 ~110 dirt
setblock ~12 ~125 ~94 fern
setblock ~12 ~125 ~95 grass_block
setblock ~12 ~125 ~96 grass_block
setblock ~12 ~125 ~97 dirt
setblock ~12 ~125 ~98 dirt
setblock ~12 ~125 ~99 dirt
setblock ~12 ~125 ~100 dirt
setblock ~12 ~125 ~101 dirt
setblock ~12 ~125 ~102 dirt
setblock ~12 ~125 ~103 dirt
setblock ~12 ~125 ~104 dirt
setblock ~12 ~125 ~105 dirt
setblock ~12 ~125 ~106 dirt
setblock ~12 ~125 ~107 dirt
setblock ~12 ~125 ~108 dirt
setblock ~12 ~125 ~109 dirt
setblock ~12 ~125 ~110 dirt
setblock ~12 ~126 ~97 grass_block
setblock ~12 ~126 ~98 grass_block
setblock ~12 ~126 ~99 grass_block
setblock ~12 ~126 ~100 dirt
setblock ~12 ~126 ~101 dirt
setblock ~12 ~126 ~102 dirt
setblock ~12 ~126 ~103 dirt
setblock ~12 ~126 ~104 grass_block
setblock ~12 ~126 ~105 grass_block
setblock ~12 ~126 ~106 grass_block
setblock ~12 ~126 ~107 grass_block
setblock ~12 ~126 ~108 grass_block
setblock ~12 ~126 ~109 grass_block
setblock ~12 ~126 ~110 grass_block
setblock ~12 ~127 ~97 fern
setblock ~12 ~127 ~98 short_grass
setblock ~12 ~127 ~100 grass_block
setblock ~12 ~127 ~101 grass_block
setblock ~12 ~127 ~102 grass_block
setblock ~12 ~127 ~103 grass_block
setblock ~12 ~127 ~104 short_grass
setblock ~12 ~127 ~105 short_grass
setblock ~12 ~127 ~107 short_grass
setblock ~13 ~112 ~102 dirt
setblock ~13 ~113 ~98 dirt
setblock ~13 ~113 ~99 dirt
setblock ~13 ~113 ~101 dirt
setblock ~13 ~113 ~102 dirt
setblock ~13 ~113 ~103 dirt
setblock ~13 ~114 ~97 dirt
setblock ~13 ~114 ~98 dirt
setblock ~13 ~114 ~99 dirt
setblock ~13 ~114 ~100 dirt
setblock ~13 ~114 ~101 dirt
setblock ~13 ~114 ~102 dirt
setblock ~13 ~114 ~103 dirt
setblock ~13 ~114 ~104 dirt
setblock ~13 ~115 ~96 dirt
setblock ~13 ~115 ~97 dirt
setblock ~13 ~115 ~98 dirt
setblock ~13 ~115 ~99 dirt
setblock ~13 ~115 ~100 dirt
setblock ~13 ~115 ~101 dirt
setblock ~13 ~115 ~102 dirt
setblock ~13 ~115 ~103 dirt
setblock ~13 ~115 ~104 dirt
setblock ~13 ~115 ~105 dirt
setblock ~13 ~116 ~95 dirt
setblock ~13 ~116 ~96 dirt
setblock ~13 ~116 ~97 dirt
setblock ~13 ~116 ~98 dirt
setblock ~13 ~116 ~99 dirt
setblock ~13 ~116 ~100 dirt
setblock ~13 ~116 ~101 dirt
setblock ~13 ~116 ~102 dirt
setblock ~13 ~116 ~103 dirt
setblock ~13 ~116 ~104 dirt
setblock ~13 ~116 ~105 dirt
setblock ~13 ~116 ~106 dirt
setblock ~13 ~117 ~94 dirt
setblock ~13 ~117 ~95 dirt
setblock ~13 ~117 ~96 dirt
setblock ~13 ~117 ~97 dirt
setblock ~13 ~117 ~98 dirt
setblock ~13 ~117 ~99 dirt
setblock ~13 ~117 ~100 dirt
setblock ~13 ~117 ~101 dirt
setblock ~13 ~117 ~102 dirt
setblock ~13 ~117 ~103 dirt
setblock ~13 ~117 ~104 dirt
setblock ~13 ~117 ~105 dirt
setblock ~13 ~117 ~106 dirt
setblock ~13 ~117 ~107 dirt
setblock ~13 ~118 ~70 dirt
setblock ~13 ~118 ~94 dirt
setblock ~13 ~118 ~95 dirt
setblock ~13 ~118 ~96 dirt
setblock ~13 ~118 ~97 dirt
setblock ~13 ~118 ~98 dirt
setblock ~13 ~118 ~99 dirt
setblock ~13 ~118 ~100 dirt
setblock ~13 ~118 ~101 dirt
setblock ~13 ~118 ~102 dirt
setblock ~13 ~118 ~103 dirt
setblock ~13 ~118 ~104 dirt
setblock ~13 ~118 ~105 dirt
setblock ~13 ~118 ~106 dirt
setblock ~13 ~118 ~107 dirt
setblock ~13 ~118 ~108 dirt
setblock ~13 ~119 ~69 dirt
setblock ~13 ~119 ~70 dirt
setblock ~13 ~119 ~71 dirt
setblock ~13 ~119 ~93 dirt
setblock ~13 ~119 ~94 dirt
setblock ~13 ~119 ~95 dirt
setblock ~13 ~119 ~96 dirt
setblock ~13 ~119 ~97 dirt
setblock ~13 ~119 ~98 dirt
setblock ~13 ~119 ~99 dirt
setblock ~13 ~119 ~100 dirt
setblock ~13 ~119 ~101 dirt
setblock ~13 ~119 ~102 dirt
setblock ~13 ~119 ~103 dirt
setblock ~13 ~119 ~104 dirt
setblock ~13 ~119 ~105 dirt
setblock ~13 ~119 ~106 dirt
setblock ~13 ~119 ~107 dirt
setblock ~13 ~119 ~108 dirt
setblock ~13 ~119 ~109 dirt
setblock ~13 ~120 ~69 dirt
setblock ~13 ~120 ~70 dirt
setblock ~13 ~120 ~71 dirt
setblock ~13 ~120 ~92 dirt
setblock ~13 ~120 ~93 dirt
setblock ~13 ~120 ~94 dirt
setblock ~13 ~120 ~95 dirt
setblock ~13 ~120 ~96 dirt
setblock ~13 ~120 ~97 dirt
setblock ~13 ~120 ~98 dirt
setblock ~13 ~120 ~99 dirt
setblock ~13 ~120 ~100 dirt
setblock ~13 ~120 ~101 dirt
setblock ~13 ~120 ~102 dirt
setblock ~13 ~120 ~103 dirt
setblock ~13 ~120 ~104 dirt
setblock ~13 ~120 ~105 dirt
setblock ~13 ~120 ~106 dirt
setblock ~13 ~120 ~107 dirt
setblock ~13 ~120 ~108 dirt
setblock ~13 ~120 ~109 dirt
setblock ~13 ~120 ~110 dirt
setblock ~13 ~121 ~68 dirt
setblock ~13 ~121 ~69 dirt
setblock ~13 ~121 ~70 dirt
setblock ~13 ~121 ~71 dirt
setblock ~13 ~121 ~72 dirt
setblock ~13 ~121 ~91 dirt
setblock ~13 ~121 ~92 dirt
setblock ~13 ~121 ~93 dirt
setblock ~13 ~121 ~94 dirt
setblock ~13 ~121 ~95 dirt
setblock ~13 ~121 ~96 dirt
setblock ~13 ~121 ~97 dirt
setblock ~13 ~121 ~98 dirt
setblock ~13 ~121 ~99 dirt
setblock ~13 ~121 ~100 dirt
setblock ~13 ~121 ~101 dirt
setblock ~13 ~121 ~102 dirt
setblock ~13 ~121 ~103 dirt
setblock ~13 ~121 ~104 dirt
setblock ~13 ~121 ~105 dirt
setblock ~13 ~121 ~106 dirt
setblock ~13 ~121 ~107 dirt
setblock ~13 ~121 ~108 dirt
setblock ~13 ~121 ~109 dirt
setblock ~13 ~121 ~110 dirt
setblock ~13 ~121 ~111 dirt
setblock ~13 ~121 ~122 dirt
setblock ~13 ~122 ~68 dirt
setblock ~13 ~122 ~69 dirt
setblock ~13 ~122 ~70 dirt
setblock ~13 ~122 ~71 dirt
setblock ~13 ~122 ~72 dirt
setblock ~13 ~122 ~91 dirt
setblock ~13 ~122 ~92 dirt
setblock ~13 ~122 ~93 dirt
setblock ~13 ~122 ~94 dirt
setblock ~13 ~122 ~95 dirt
setblock ~13 ~122 ~96 dirt
setblock ~13 ~122 ~97 dirt
setblock ~13 ~122 ~98 dirt
setblock ~13 ~122 ~99 dirt
setblock ~13 ~122 ~100 dirt
setblock ~13 ~122 ~101 dirt
setblock ~13 ~122 ~102 dirt
setblock ~13 ~122 ~103 dirt
setblock ~13 ~122 ~104 dirt
setblock ~13 ~122 ~105 dirt
setblock ~13 ~122 ~106 dirt
setblock ~13 ~122 ~107 dirt
setblock ~13 ~122 ~108 dirt
setblock ~13 ~122 ~109 dirt
setblock ~13 ~122 ~110 dirt
setblock ~13 ~122 ~111 dirt
setblock ~13 ~122 ~122 dirt
setblock ~13 ~123 ~68 dirt
setblock ~13 ~123 ~69 dirt
setblock ~13 ~123 ~70 grass_block
setblock ~13 ~123 ~71 grass_block
setblock ~13 ~123 ~72 dirt
setblock ~13 ~123 ~91 grass_block
setblock ~13 ~123 ~92 dirt
setblock ~13 ~123 ~93 dirt
setblock ~13 ~123 ~94 dirt
setblock ~13 ~123 ~95 dirt
setblock ~13 ~123 ~96 dirt
setblock ~13 ~123 ~97 dirt
setblock ~13 ~123 ~98 dirt
setblock ~13 ~123 ~99 dirt
setblock ~13 ~123 ~100 dirt
setblock ~13 ~123 ~101 dirt
setblock ~13 ~123 ~102 dirt
setblock ~13 ~123 ~103 dirt
setblock ~13 ~123 ~104 dirt
setblock ~13 ~123 ~105 dirt
setblock ~13 ~123 ~106 dirt
setblock ~13 ~123 ~107 dirt
setblock ~13 ~123 ~108 dirt
setblock ~13 ~123 ~109 dirt
setblock ~13 ~123 ~110 dirt
setblock ~13 ~123 ~111 dirt
setblock ~13 ~123 ~122 dirt
setblock ~13 ~124 ~68 grass_block
setblock ~13 ~124 ~69 grass_block
setblock ~13 ~124 ~72 grass_block
setblock ~13 ~124 ~91 short_grass
setblock ~13 ~124 ~92 grass_block
setblock ~13 ~124 ~93 grass_block
setblock ~13 ~124 ~94 grass_block
setblock ~13 ~124 ~95 dirt
setblock ~13 ~124 ~96 dirt
setblock ~13 ~124 ~97 dirt
setblock ~13 ~124 ~98 dirt
setblock ~13 ~124 ~99 dirt
setblock ~13 ~124 ~100 dirt
setblock ~13 ~124 ~101 dirt
setblock ~13 ~124 ~102 dirt
setblock ~13 ~124 ~103 dirt
setblock ~13 ~124 ~104 dirt
setblock ~13 ~124 ~105 dirt
setblock ~13 ~124 ~106 dirt
setblock ~13 ~124 ~107 dirt
setblock ~13 ~124 ~108 dirt
setblock ~13 ~124 ~109 dirt
setblock ~13 ~124 ~110 dirt
setblock ~13 ~124 ~111 dirt
setblock ~13 ~124 ~122 grass_block
setblock ~13 ~125 ~95 grass_block
setblock ~13 ~125 ~96 grass_block
setblock ~13 ~125 ~97 grass_block
setblock ~13 ~125 ~98 dirt
setblock ~13 ~125 ~99 dirt
setblock ~13 ~125 ~100 dirt
setblock ~13 ~125 ~101 dirt
setblock ~13 ~125 ~102 dirt
setblock ~13 ~125 ~103 dirt
setblock ~13 ~125 ~104 dirt
setblock ~13 ~125 ~105 dirt
setblock ~13 ~125 ~106 dirt
setblock ~13 ~125 ~107 dirt
setblock ~13 ~125 ~108 dirt
setblock ~13 ~125 ~109 dirt
setblock ~13 ~125 ~110 dirt
setblock ~13 ~125 ~111 dirt
setblock ~13 ~125 ~122 short_grass
setblock ~13 ~126 ~98 grass_block
setblock ~13 ~126 ~99 grass_block
setblock ~13 ~126 ~100 grass_block
setblock ~13 ~126 ~101 grass_block
setblock ~13 ~126 ~102 grass_block
setblock ~13 ~126 ~103 grass_block
setblock ~13 ~126 ~104 grass_block
setblock ~13 ~126 ~105 grass_block
setblock ~13 ~126 ~106 grass_block
setblock ~13 ~126 ~107 grass_block
setblock ~13 ~126 ~108 grass_block
setblock ~13 ~126 ~109 grass_block
setblock ~13 ~126 ~110 grass_block
setblock ~13 ~126 ~111 grass_block
setblock ~13 ~127 ~106 poppy
setblock ~13 ~127 ~111 short_grass
setblock ~14 ~111 ~98 dirt
setblock ~14 ~111 ~102 dirt
setblock ~14 ~112 ~98 dirt
setblock ~14 ~112 ~99 dirt
setblock ~14 ~112 ~100 dirt
setblock ~14 ~112 ~101 dirt
setblock ~14 ~112 ~102 dirt
setblock ~14 ~112 ~103 dirt
setblock ~14 ~113 ~97 dirt
setblock ~14 ~113 ~98 dirt
setblock ~14 ~113 ~99 dirt
setblock ~14 ~113 ~100 dirt
setblock ~14 ~113 ~101 dirt
setblock ~14 ~113 ~102 dirt
setblock ~14 ~113 ~103 dirt
setblock ~14 ~113 ~104 dirt
setblock ~14 ~114 ~96 dirt
setblock ~14 ~114 ~97 dirt
setblock ~14 ~114 ~98 dirt
setblock ~14 ~114 ~99 dirt
setblock ~14 ~114 ~100 dirt
setblock ~14 ~114 ~101 dirt
setblock ~14 ~114 ~102 dirt
setblock ~14 ~114 ~103 dirt
setblock ~14 ~114 ~104 dirt
setblock ~14 ~114 ~105 dirt
setblock ~14 ~115 ~95 dirt
setblock ~14 ~115 ~96 dirt
setblock ~14 ~115 ~97 dirt
setblock ~14 ~115 ~98 dirt
setblock ~14 ~115 ~99 dirt
setblock ~14 ~115 ~100 dirt
setblock ~14 ~115 ~101 dirt
setblock ~14 ~115 ~102 dirt
setblock ~14 ~115 ~103 dirt
setblock ~14 ~115 ~104 dirt
setblock ~14 ~115 ~105 dirt
setblock ~14 ~115 ~106 dirt
setblock ~14 ~116 ~94 dirt
setblock ~14 ~116 ~95 dirt
setblock ~14 ~116 ~96 dirt
setblock ~14 ~116 ~97 dirt
setblock ~14 ~116 ~98 dirt
setblock ~14 ~116 ~99 dirt
setblock ~14 ~116 ~100 dirt
setblock ~14 ~116 ~101 dirt
setblock ~14 ~116 ~102 dirt
setblock ~14 ~116 ~103 dirt
setblock ~14 ~116 ~104 dirt
setblock ~14 ~116 ~105 dirt
setblock ~14 ~116 ~106 dirt
setblock ~14 ~116 ~107 dirt
setblock ~14 ~117 ~70 dirt
setblock ~14 ~117 ~93 dirt
setblock ~14 ~117 ~94 dirt
setblock ~14 ~117 ~95 dirt
setblock ~14 ~117 ~96 dirt
setblock ~14 ~117 ~97 dirt
setblock ~14 ~117 ~98 dirt
setblock ~14 ~117 ~99 dirt
setblock ~14 ~117 ~100 dirt
setblock ~14 ~117 ~101 dirt
setblock ~14 ~117 ~102 dirt
setblock ~14 ~117 ~103 dirt
setblock ~14 ~117 ~104 dirt
setblock ~14 ~117 ~105 dirt
setblock ~14 ~117 ~106 dirt
setblock ~14 ~117 ~107 dirt
setblock ~14 ~117 ~108 dirt
setblock ~14 ~118 ~69 dirt
setblock ~14 ~118 ~70 dirt
setblock ~14 ~118 ~71 dirt
setblock ~14 ~118 ~93 dirt
setblock ~14 ~118 ~94 dirt
setblock ~14 ~118 ~95 dirt
setblock ~14 ~118 ~96 dirt
setblock ~14 ~118 ~97 dirt
setblock ~14 ~118 ~98 dirt
setblock ~14 ~118 ~99 dirt
setblock ~14 ~118 ~100 dirt
setblock ~14 ~118 ~101 dirt
setblock ~14 ~118 ~102 dirt
setblock ~14 ~118 ~103 dirt
setblock ~14 ~118 ~104 dirt
setblock ~14 ~118 ~105 dirt
setblock ~14 ~118 ~106 dirt
setblock ~14 ~118 ~107 dirt
setblock ~14 ~118 ~108 dirt
setblock ~14 ~118 ~109 dirt
setblock ~14 ~119 ~68 dirt
setblock ~14 ~119 ~69 dirt
setblock ~14 ~119 ~70 dirt
setblock ~14 ~119 ~71 dirt
setblock ~14 ~119 ~92 dirt
setblock ~14 ~119 ~93 dirt
setblock ~14 ~119 ~94 dirt
setblock ~14 ~119 ~95 dirt
setblock ~14 ~119 ~96 dirt
setblock ~14 ~119 ~97 dirt
setblock ~14 ~119 ~98 dirt
setblock ~14 ~119 ~99 dirt
setblock ~14 ~119 ~100 dirt
setblock ~14 ~119 ~101 dirt
setblock ~14 ~119 ~102 dirt
setblock ~14 ~119 ~103 dirt
setblock ~14 ~119 ~104 dirt
setblock ~14 ~119 ~105 dirt
setblock ~14 ~119 ~106 dirt
setblock ~14 ~119 ~107 dirt
setblock ~14 ~119 ~108 dirt
setblock ~14 ~119 ~109 dirt
setblock ~14 ~119 ~110 dirt
setblock ~14 ~120 ~68 dirt
setblock ~14 ~120 ~69 dirt
setblock ~14 ~120 ~70 dirt
setblock ~14 ~120 ~71 dirt
setblock ~14 ~120 ~91 dirt
setblock ~14 ~120 ~92 dirt
setblock ~14 ~120 ~93 dirt
setblock ~14 ~120 ~94 dirt
setblock ~14 ~120 ~95 dirt
setblock ~14 ~120 ~96 dirt
setblock ~14 ~120 ~97 dirt
setblock ~14 ~120 ~98 dirt
setblock ~14 ~120 ~99 dirt
setblock ~14 ~120 ~100 dirt
setblock ~14 ~120 ~101 dirt
setblock ~14 ~120 ~102 dirt
setblock ~14 ~120 ~103 dirt
setblock ~14 ~120 ~104 dirt
setblock ~14 ~120 ~105 dirt
setblock ~14 ~120 ~106 dirt
setblock ~14 ~120 ~107 dirt
setblock ~14 ~120 ~108 dirt
setblock ~14 ~120 ~109 dirt
setblock ~14 ~120 ~110 dirt
setblock ~14 ~120 ~111 dirt
setblock ~14 ~120 ~122 dirt
setblock ~14 ~121 ~67 dirt
setblock ~14 ~121 ~68 dirt
setblock ~14 ~121 ~69 dirt
setblock ~14 ~121 ~70 dirt
setblock ~14 ~121 ~71 dirt
setblock ~14 ~121 ~72 dirt
setblock ~14 ~121 ~90 dirt
setblock ~14 ~121 ~91 dirt
setblock ~14 ~121 ~92 dirt
setblock ~14 ~121 ~93 dirt
setblock ~14 ~121 ~94 dirt
setblock ~14 ~121 ~95 dirt
setblock ~14 ~121 ~96 dirt
setblock ~14 ~121 ~97 dirt
setblock ~14 ~121 ~98 dirt
setblock ~14 ~121 ~99 dirt
setblock ~14 ~121 ~100 dirt
setblock ~14 ~121 ~101 dirt
setblock ~14 ~121 ~102 dirt
setblock ~14 ~121 ~103 dirt
setblock ~14 ~121 ~104 dirt
setblock ~14 ~121 ~105 dirt
setblock ~14 ~121 ~106 dirt
setblock ~14 ~121 ~107 dirt
setblock ~14 ~121 ~108 dirt
setblock ~14 ~121 ~109 dirt
setblock ~14 ~121 ~110 dirt
setblock ~14 ~121 ~111 dirt
setblock ~14 ~121 ~112 dirt
setblock ~14 ~121 ~121 dirt
setblock ~14 ~121 ~122 dirt
setblock ~14 ~121 ~123 dirt
setblock ~14 ~121 ~124 dirt
setblock ~14 ~121 ~127 dirt
setblock ~14 ~122 ~67 dirt
setblock ~14 ~122 ~68 dirt
setblock ~14 ~122 ~69 dirt
setblock ~14 ~122 ~70 dirt
setblock ~14 ~122 ~71 dirt
setblock ~14 ~122 ~72 dirt
setblock ~14 ~122 ~90 dirt
setblock ~14 ~122 ~91 dirt
setblock ~14 ~122 ~92 dirt
setblock ~14 ~122 ~93 dirt
setblock ~14 ~122 ~94 dirt
setblock ~14 ~122 ~95 dirt
setblock ~14 ~122 ~96 dirt
setblock ~14 ~122 ~97 dirt
setblock ~14 ~122 ~98 dirt
setblock ~14 ~122 ~99 dirt
setblock ~14 ~122 ~100 dirt
setblock ~14 ~122 ~101 dirt
setblock ~14 ~122 ~102 dirt
setblock ~14 ~122 ~103 dirt
setblock ~14 ~122 ~104 dirt
setblock ~14 ~122 ~105 dirt
setblock ~14 ~122 ~106 dirt
setblock ~14 ~122 ~107 dirt
setblock ~14 ~122 ~108 dirt
setblock ~14 ~122 ~109 dirt
setblock ~14 ~122 ~110 dirt
setblock ~14 ~122 ~111 dirt
setblock ~14 ~122 ~112 dirt
setblock ~14 ~122 ~121 dirt
setblock ~14 ~122 ~122 dirt
setblock ~14 ~122 ~123 dirt
setblock ~14 ~122 ~124 dirt
setblock ~14 ~122 ~127 dirt
setblock ~14 ~123 ~67 dirt
setblock ~14 ~123 ~68 dirt
setblock ~14 ~123 ~69 dirt
setblock ~14 ~123 ~70 grass_block
setblock ~14 ~123 ~71 grass_block
setblock ~14 ~123 ~72 dirt
setblock ~14 ~123 ~90 dirt
setblock ~14 ~123 ~91 dirt
setblock ~14 ~123 ~92 dirt
setblock ~14 ~123 ~93 dirt
setblock ~14 ~123 ~94 dirt
setblock ~14 ~123 ~95 dirt
setblock ~14 ~123 ~96 dirt
setblock ~14 ~123 ~97 dirt
setblock ~14 ~123 ~98 dirt
setblock ~14 ~123 ~99 dirt
setblock ~14 ~123 ~100 dirt
setblock ~14 ~123 ~101 dirt
setblock ~14 ~123 ~102 dirt
setblock ~14 ~123 ~103 dirt
setblock ~14 ~123 ~104 dirt
setblock ~14 ~123 ~105 dirt
setblock ~14 ~123 ~106 dirt
setblock ~14 ~123 ~107 dirt
setblock ~14 ~123 ~108 dirt
setblock ~14 ~123 ~109 dirt
setblock ~14 ~123 ~110 dirt
setblock ~14 ~123 ~111 dirt
setblock ~14 ~123 ~112 dirt
setblock ~14 ~123 ~121 dirt
setblock ~14 ~123 ~122 dirt
setblock ~14 ~123 ~123 dirt
setblock ~14 ~123 ~124 dirt
setblock ~14 ~123 ~127 grass_block
setblock ~14 ~124 ~67 grass_block
setblock ~14 ~124 ~68 grass_block
setblock ~14 ~124 ~69 grass_block
setblock ~14 ~124 ~70 short_grass
setblock ~14 ~124 ~72 grass_block
setblock ~14 ~124 ~90 grass_block
setblock ~14 ~124 ~91 grass_block
setblock ~14 ~124 ~92 grass_block
setblock ~14 ~124 ~93 grass_block
setblock ~14 ~124 ~94 dirt
setblock ~14 ~124 ~95 dirt
setblock ~14 ~124 ~96 dirt
setblock ~14 ~124 ~97 dirt
setblock ~14 ~124 ~98 dirt
setblock ~14 ~124 ~99 dirt
setblock ~14 ~124 ~100 dirt
setblock ~14 ~124 ~101 dirt
setblock ~14 ~124 ~102 dirt
setblock ~14 ~124 ~103 dirt
setblock ~14 ~124 ~104 dirt
setblock ~14 ~124 ~105 dirt
setblock ~14 ~124 ~106 dirt
setblock ~14 ~124 ~107 dirt
setblock ~14 ~124 ~108 dirt
setblock ~14 ~124 ~109 dirt
setblock ~14 ~124 ~110 dirt
setblock ~14 ~124 ~111 dirt
setblock ~14 ~124 ~112 dirt
setblock ~14 ~124 ~121 grass_block
setblock ~14 ~124 ~122 grass_block
setblock ~14 ~124 ~123 grass_block
setblock ~14 ~124 ~124 grass_block
setblock ~14 ~125 ~67 short_grass
setblock ~14 ~125 ~68 short_grass
setblock ~14 ~125 ~94 grass_block
setblock ~14 ~125 ~95 grass_block
setblock ~14 ~125 ~96 grass_block
setblock ~14 ~125 ~97 grass_block
setblock ~14 ~125 ~98 grass_block
setblock ~14 ~125 ~99 grass_block
setblock ~14 ~125 ~100 grass_block
setblock ~14 ~125 ~101 grass_block
setblock ~14 ~125 ~102 grass_block
setblock ~14 ~125 ~103 dirt
setblock ~14 ~125 ~104 dirt
setblock ~14 ~125 ~105 dirt
setblock ~14 ~125 ~106 dirt
setblock ~14 ~125 ~107 dirt
setblock ~14 ~125 ~108 dirt
setblock ~14 ~125 ~109 dirt
setblock ~14 ~125 ~110 dirt
setblock ~14 ~125 ~111 dirt
setblock ~14 ~125 ~112 dirt
setblock ~14 ~125 ~121 poppy
setblock ~14 ~125 ~122 short_grass
setblock ~14 ~125 ~123 poppy
setblock ~14 ~126 ~95 short_grass
setblock ~14 ~126 ~98 short_grass
setblock ~14 ~126 ~100 short_grass
setblock ~14 ~126 ~102 short_grass
setblock ~14 ~126 ~103 grass_block
setblock ~14 ~126 ~104 grass_block
setblock ~14 ~126 ~105 grass_block
setblock ~14 ~126 ~106 grass_block
setblock ~14 ~126 ~107 grass_block
setblock ~14 ~126 ~108 grass_block
setblock ~14 ~126 ~109 grass_block
setblock ~14 ~126 ~110 grass_block
setblock ~14 ~126 ~111 grass_block
setblock ~14 ~126 ~112 grass_block
setblock ~14 ~127 ~106 short_grass
setblock ~14 ~127 ~107 short_grass
setblock ~14 ~127 ~110 short_grass
setblock ~15 ~110 ~98 dirt
setblock ~15 ~110 ~102 dirt
setblock ~15 ~111 ~97 dirt
setblock ~15 ~111 ~98 dirt
setblock ~15 ~111 ~99 dirt
setblock ~15 ~111 ~100 dirt
setblock ~15 ~111 ~101 dirt
setblock ~15 ~111 ~102 dirt
setblock ~15 ~111 ~103 dirt
setblock ~15 ~112 ~97 dirt
setblock ~15 ~112 ~98 dirt
setblock ~15 ~112 ~99 dirt
setblock ~15 ~112 ~100 dirt
setblock ~15 ~112 ~101 dirt
setblock ~15 ~112 ~102 dirt
setblock ~15 ~112 ~103 dirt
setblock ~15 ~112 ~104 dirt
setblock ~15 ~113 ~96 dirt
setblock ~15 ~113 ~97 dirt
setblock ~15 ~113 ~98 dirt
setblock ~15 ~113 ~99 dirt
setblock ~15 ~113 ~100 dirt
setblock ~15 ~113 ~101 dirt
setblock ~15 ~113 ~102 dirt
setblock ~15 ~113 ~103 dirt
setblock ~15 ~113 ~104 dirt
setblock ~15 ~113 ~105 dirt
setblock ~15 ~114 ~95 dirt
setblock ~15 ~114 ~96 dirt
setblock ~15 ~114 ~97 dirt
setblock ~15 ~114 ~98 dirt
setblock ~15 ~114 ~99 dirt
setblock ~15 ~114 ~100 dirt
setblock ~15 ~114 ~101 dirt
setblock ~15 ~114 ~102 dirt
setblock ~15 ~114 ~103 dirt
setblock ~15 ~114 ~104 dirt
setblock ~15 ~114 ~105 dirt
setblock ~15 ~114 ~106 dirt
setblock ~15 ~115 ~70 dirt
setblock ~15 ~115 ~95 dirt
setblock ~15 ~115 ~96 dirt
setblock ~15 ~115 ~97 dirt
setblock ~15 ~115 ~98 dirt
setblock ~15 ~115 ~99 dirt
setblock ~15 ~115 ~100 dirt
setblock ~15 ~115 ~101 dirt
setblock ~15 ~115 ~102 dirt
setblock ~15 ~115 ~103 dirt
setblock ~15 ~115 ~104 dirt
setblock ~15 ~115 ~105 dirt
setblock ~15 ~115 ~106 dirt
setblock ~15 ~115 ~107 dirt
setblock ~15 ~116 ~70 dirt
setblock ~15 ~116 ~94 dirt
setblock ~15 ~116 ~95 dirt
setblock ~15 ~116 ~96 dirt
setblock ~15 ~116 ~97 dirt
setblock ~15 ~116 ~98 dirt
setblock ~15 ~116 ~99 dirt
setblock ~15 ~116 ~100 dirt
setblock ~15 ~116 ~101 dirt
setblock ~15 ~116 ~102 dirt
setblock ~15 ~116 ~103 dirt
setblock ~15 ~116 ~104 dirt
setblock ~15 ~116 ~105 dirt
setblock ~15 ~116 ~106 dirt
setblock ~15 ~116 ~107 dirt
setblock ~15 ~116 ~108 dirt
setblock ~15 ~117 ~69 dirt
setblock ~15 ~117 ~70 dirt
setblock ~15 ~117 ~71 dirt
setblock ~15 ~117 ~92 dirt
setblock ~15 ~117 ~93 dirt
setblock ~15 ~117 ~94 dirt
setblock ~15 ~117 ~95 dirt
setblock ~15 ~117 ~96 dirt
setblock ~15 ~117 ~97 dirt
setblock ~15 ~117 ~98 dirt
setblock ~15 ~117 ~99 dirt
setblock ~15 ~117 ~100 dirt
setblock ~15 ~117 ~101 dirt
setblock ~15 ~117 ~102 dirt
setblock ~15 ~117 ~103 dirt
setblock ~15 ~117 ~104 dirt
setblock ~15 ~117 ~105 dirt
setblock ~15 ~117 ~106 dirt
setblock ~15 ~117 ~107 dirt
setblock ~15 ~117 ~108 dirt
setblock ~15 ~117 ~109 dirt
setblock ~15 ~118 ~69 dirt
setblock ~15 ~118 ~70 dirt
setblock ~15 ~118 ~71 dirt
setblock ~15 ~118 ~91 dirt
setblock ~15 ~118 ~92 dirt
setblock ~15 ~118 ~93 dirt
setblock ~15 ~118 ~94 dirt
setblock ~15 ~118 ~95 dirt
setblock ~15 ~118 ~96 dirt
setblock ~15 ~118 ~97 dirt
setblock ~15 ~118 ~98 dirt
setblock ~15 ~118 ~99 dirt
setblock ~15 ~118 ~100 dirt
setblock ~15 ~118 ~101 dirt
setblock ~15 ~118 ~102 dirt
setblock ~15 ~118 ~103 dirt
setblock ~15 ~118 ~104 dirt
setblock ~15 ~118 ~105 dirt
setblock ~15 ~118 ~106 dirt
setblock ~15 ~118 ~107 dirt
setblock ~15 ~118 ~108 dirt
setblock ~15 ~118 ~109 dirt
setblock ~15 ~118 ~110 dirt
setblock ~15 ~119 ~69 dirt
setblock ~15 ~119 ~70 dirt
setblock ~15 ~119 ~71 dirt
setblock ~15 ~119 ~91 dirt
setblock ~15 ~119 ~92 dirt
setblock ~15 ~119 ~93 dirt
setblock ~15 ~119 ~94 dirt
setblock ~15 ~119 ~95 dirt
setblock ~15 ~119 ~96 dirt
setblock ~15 ~119 ~97 dirt
setblock ~15 ~119 ~98 dirt
setblock ~15 ~119 ~99 dirt
setblock ~15 ~119 ~100 dirt
setblock ~15 ~119 ~101 dirt
setblock ~15 ~119 ~102 dirt
setblock ~15 ~119 ~103 dirt
setblock ~15 ~119 ~104 dirt
setblock ~15 ~119 ~105 dirt
setblock ~15 ~119 ~106 dirt
setblock ~15 ~119 ~107 dirt
setblock ~15 ~119 ~108 dirt
setblock ~15 ~119 ~109 dirt
setblock ~15 ~119 ~110 dirt
setblock ~15 ~119 ~111 dirt
setblock ~15 ~119 ~122 dirt
setblock ~15 ~120 ~67 dirt
setblock ~15 ~120 ~68 dirt
setblock ~15 ~120 ~69 dirt
setblock ~15 ~120 ~70 dirt
setblock ~15 ~120 ~71 dirt
setblock ~15 ~120 ~72 dirt
setblock ~15 ~120 ~90 dirt
setblock ~15 ~120 ~91 dirt
setblock ~15 ~120 ~92 dirt
setblock ~15 ~120 ~93 dirt
setblock ~15 ~120 ~94 dirt
setblock ~15 ~120 ~95 dirt
setblock ~15 ~120 ~96 dirt
setblock ~15 ~120 ~97 dirt
setblock ~15 ~120 ~98 dirt
setblock ~15 ~120 ~99 dirt
setblock ~15 ~120 ~100 dirt
setblock ~15 ~120 ~101 dirt
setblock ~15 ~120 ~102 dirt
setblock ~15 ~120 ~103 dirt
setblock ~15 ~120 ~104 dirt
setblock ~15 ~120 ~105 dirt
setblock ~15 ~120 ~106 dirt
setblock ~15 ~120 ~107 dirt
setblock ~15 ~120 ~108 dirt
setblock ~15 ~120 ~109 dirt
setblock ~15 ~120 ~110 dirt
setblock ~15 ~120 ~111 dirt
setblock ~15 ~120 ~112 dirt
setblock ~15 ~120 ~114 dirt
setblock ~15 ~120 ~121 dirt
setblock ~15 ~120 ~122 dirt
setblock ~15 ~120 ~123 dirt
setblock ~15 ~120 ~124 dirt
setblock ~15 ~120 ~125 dirt
setblock ~15 ~120 ~126 dirt
setblock ~15 ~120 ~127 dirt
setblock ~15 ~120 ~128 dirt
setblock ~15 ~120 ~129 dirt
setblock ~15 ~121 ~62 dirt
setblock ~15 ~121 ~63 dirt
setblock ~15 ~121 ~66 dirt
setblock ~15 ~121 ~67 dirt
setblock ~15 ~121 ~68 dirt
setblock ~15 ~121 ~69 dirt
setblock ~15 ~121 ~70 dirt
setblock ~15 ~121 ~71 dirt
setblock ~15 ~121 ~72 dirt
setblock ~15 ~121 ~73 dirt
setblock ~15 ~121 ~89 dirt
setblock ~15 ~121 ~90 dirt
setblock ~15 ~121 ~91 dirt
setblock ~15 ~121 ~92 dirt
setblock ~15 ~121 ~93 dirt
setblock ~15 ~121 ~94 dirt
setblock ~15 ~121 ~95 dirt
setblock ~15 ~121 ~96 dirt
setblock ~15 ~121 ~97 dirt
setblock ~15 ~121 ~98 dirt
setblock ~15 ~121 ~99 dirt
setblock ~15 ~121 ~100 dirt
setblock ~15 ~121 ~101 dirt
setblock ~15 ~121 ~102 dirt
setblock ~15 ~121 ~103 dirt
setblock ~15 ~121 ~104 dirt
setblock ~15 ~121 ~105 dirt
setblock ~15 ~121 ~106 dirt
setblock ~15 ~121 ~107 dirt
setblock ~15 ~121 ~108 dirt
setblock ~15 ~121 ~109 dirt
setblock ~15 ~121 ~110 dirt
setblock ~15 ~121 ~111 dirt
setblock ~15 ~121 ~112 dirt
setblock ~15 ~121 ~113 dirt
setblock ~15 ~121 ~114 dirt
setblock ~15 ~121 ~115 dirt
setblock ~15 ~121 ~120 dirt
setblock ~15 ~121 ~121 dirt
setblock ~15 ~121 ~122 dirt
setblock ~15 ~121 ~123 dirt
setblock ~15 ~121 ~124 dirt
setblock ~15 ~121 ~125 dirt
setblock ~15 ~121 ~126 dirt
setblock ~15 ~121 ~127 dirt
setblock ~15 ~121 ~128 dirt
setblock ~15 ~121 ~129 dirt
setblock ~15 ~121 ~130 dirt
setblock ~15 ~121 ~131 dirt
setblock ~15 ~122 ~62 dirt
setblock ~15 ~122 ~63 dirt
setblock ~15 ~122 ~66 dirt
setblock ~15 ~122 ~67 dirt
setblock ~15 ~122 ~68 dirt
setblock ~15 ~122 ~69 dirt
setblock ~15 ~122 ~70 dirt
setblock ~15 ~122 ~71 dirt
setblock ~15 ~122 ~72 dirt
setblock ~15 ~122 ~73 dirt
setblock ~15 ~122 ~89 dirt
setblock ~15 ~122 ~90 dirt
setblock ~15 ~122 ~91 dirt
setblock ~15 ~122 ~92 dirt
setblock ~15 ~122 ~93 dirt
setblock ~15 ~122 ~94 dirt
setblock ~15 ~122 ~95 dirt
setblock ~15 ~122 ~96 dirt
setblock ~15 ~122 ~97 dirt
setblock ~15 ~122 ~98 dirt
setblock ~15 ~122 ~99 dirt
setblock ~15 ~122 ~100 dirt
setblock ~15 ~122 ~101 dirt
setblock ~15 ~122 ~102 dirt
setblock ~15 ~122 ~103 dirt
setblock ~15 ~122 ~104 dirt
setblock ~15 ~122 ~105 dirt
setblock ~15 ~122 ~106 dirt
setblock ~15 ~122 ~107 dirt
setblock ~15 ~122 ~108 dirt
setblock ~15 ~122 ~109 dirt
setblock ~15 ~122 ~110 dirt
setblock ~15 ~122 ~111 dirt
setblock ~15 ~122 ~112 dirt
setblock ~15 ~122 ~113 dirt
setblock ~15 ~122 ~114 dirt
setblock ~15 ~122 ~115 dirt
setblock ~15 ~122 ~120 dirt
setblock ~15 ~122 ~121 dirt
setblock ~15 ~122 ~122 dirt
setblock ~15 ~122 ~123 dirt
setblock ~15 ~122 ~124 dirt
setblock ~15 ~122 ~125 dirt
setblock ~15 ~122 ~126 dirt
setblock ~15 ~122 ~127 dirt
setblock ~15 ~122 ~128 dirt
setblock ~15 ~122 ~129 dirt
setblock ~15 ~122 ~130 dirt
setblock ~15 ~122 ~131 dirt
setblock ~15 ~123 ~62 dirt
setblock ~15 ~123 ~63 dirt
setblock ~15 ~123 ~66 dirt
setblock ~15 ~123 ~67 dirt
setblock ~15 ~123 ~68 dirt
setblock ~15 ~123 ~69 dirt
setblock ~15 ~123 ~70 grass_block
setblock ~15 ~123 ~71 grass_block
setblock ~15 ~123 ~72 dirt
setblock ~15 ~123 ~73 dirt
setblock ~15 ~123 ~89 dirt
setblock ~15 ~123 ~90 dirt
setblock ~15 ~123 ~91 dirt
setblock ~15 ~123 ~92 dirt
setblock ~15 ~123 ~93 dirt
setblock ~15 ~123 ~94 dirt
setblock ~15 ~123 ~95 dirt
setblock ~15 ~123 ~96 dirt
setblock ~15 ~123 ~97 dirt
setblock ~15 ~123 ~98 dirt
setblock ~15 ~123 ~99 dirt
setblock ~15 ~123 ~100 dirt
setblock ~15 ~123 ~101 dirt
setblock ~15 ~123 ~102 dirt
setblock ~15 ~123 ~103 dirt
setblock ~15 ~123 ~104 dirt
setblock ~15 ~123 ~105 dirt
setblock ~15 ~123 ~106 dirt
setblock ~15 ~123 ~107 dirt
setblock ~15 ~123 ~108 dirt
setblock ~15 ~123 ~109 dirt
setblock ~15 ~123 ~110 dirt
setblock ~15 ~123 ~111 dirt
setblock ~15 ~123 ~112 dirt
setblock ~15 ~123 ~113 dirt
setblock ~15 ~123 ~114 dirt
setblock ~15 ~123 ~115 dirt
setblock ~15 ~123 ~120 dirt
setblock ~15 ~123 ~121 dirt
setblock ~15 ~123 ~122 dirt
setblock ~15 ~123 ~123 dirt
setblock ~15 ~123 ~124 dirt
setblock ~15 ~123 ~125 dirt
setblock ~15 ~123 ~126 dirt
setblock ~15 ~123 ~127 grass_block
setblock ~15 ~123 ~128 grass_block
setblock ~15 ~123 ~129 grass_block
setblock ~15 ~123 ~130 grass_block
setblock ~15 ~123 ~131 grass_block
setblock ~15 ~124 ~62 dirt
setblock ~15 ~124 ~63 dirt
setblock ~15 ~124 ~66 grass_block
setblock ~15 ~124 ~67 grass_block
setblock ~15 ~124 ~68 grass_block
setblock ~15 ~124 ~69 grass_block
setblock ~15 ~124 ~72 grass_block
setblock ~15 ~124 ~73 grass_block
setblock ~15 ~124 ~89 dirt
setblock ~15 ~124 ~90 dirt
setblock ~15 ~124 ~91 dirt
setblock ~15 ~124 ~92 dirt
setblock ~15 ~124 ~93 dirt
setblock ~15 ~124 ~94 dirt
setblock ~15 ~124 ~95 dirt
setblock ~15 ~124 ~96 dirt
setblock ~15 ~124 ~97 dirt
setblock ~15 ~124 ~98 dirt
setblock ~15 ~124 ~99 dirt
setblock ~15 ~124 ~100 dirt
setblock ~15 ~124 ~101 dirt
setblock ~15 ~124 ~102 dirt
setblock ~15 ~124 ~103 dirt
setblock ~15 ~124 ~104 dirt
setblock ~15 ~124 ~105 dirt
setblock ~15 ~124 ~106 dirt
setblock ~15 ~124 ~107 dirt
setblock ~15 ~124 ~108 dirt
setblock ~15 ~124 ~109 dirt
setblock ~15 ~124 ~110 dirt
setblock ~15 ~124 ~111 dirt
setblock ~15 ~124 ~112 dirt
setblock ~15 ~124 ~113 dirt
setblock ~15 ~124 ~114 dirt
setblock ~15 ~124 ~115 dirt
setblock ~15 ~124 ~120 dirt
setblock ~15 ~124 ~121 grass_block
setblock ~15 ~124 ~122 grass_block
setblock ~15 ~124 ~123 grass_block
setblock ~15 ~124 ~124 grass_block
setblock ~15 ~124 ~125 grass_block
setblock ~15 ~124 ~126 grass_block
setblock ~15 ~125 ~62 dirt
setblock ~15 ~125 ~63 grass_block
setblock ~15 ~125 ~66 short_grass
setblock ~15 ~125 ~67 short_grass
setblock ~15 ~125 ~73 short_grass
setblock ~15 ~125 ~89 grass_block
setblock ~15 ~125 ~90 grass_block
setblock ~15 ~125 ~91 grass_block
setblock ~15 ~125 ~92 grass_block
setblock ~15 ~125 ~93 grass_block
setblock ~15 ~125 ~94 grass_block
setblock ~15 ~125 ~95 grass_block
setblock ~15 ~125 ~96 grass_block
setblock ~15 ~125 ~97 grass_block
setblock ~15 ~125 ~98 grass_block
setblock ~15 ~125 ~99 grass_block
setblock ~15 ~125 ~100 grass_block
setblock ~15 ~125 ~101 grass_block
setblock ~15 ~125 ~102 grass_block
setblock ~15 ~125 ~103 grass_block
setblock ~15 ~125 ~104 grass_block
setblock ~15 ~125 ~105 dirt
setblock ~15 ~125 ~106 dirt
setblock ~15 ~125 ~107 dirt
setblock ~15 ~125 ~108 dirt
setblock ~15 ~125 ~109 dirt
setblock ~15 ~125 ~110 dirt
setblock ~15 ~125 ~111 dirt
setblock ~15 ~125 ~112 dirt
setblock ~15 ~125 ~113 dirt
setblock ~15 ~125 ~114 grass_block
setblock ~15 ~125 ~115 grass_block
setblock ~15 ~125 ~120 grass_block
setblock ~15 ~125 ~122 short_grass
setblock ~15 ~126 ~62 grass_block
setblock ~15 ~126 ~63 short_grass
setblock ~15 ~126 ~90 fern
setblock ~15 ~126 ~96 short_grass
setblock ~15 ~126 ~97 poppy
setblock ~15 ~126 ~98 short_grass
setblock ~15 ~126 ~102 short_grass
setblock ~15 ~126 ~104 short_grass
setblock ~15 ~126 ~105 grass_block
setblock ~15 ~126 ~106 grass_block
setblock ~15 ~126 ~107 grass_block
setblock ~15 ~126 ~108 grass_block
setblock ~15 ~126 ~109 grass_block
setblock ~15 ~126 ~110 grass_block
setblock ~15 ~126 ~111 grass_block
setblock ~15 ~126 ~112 grass_block
setblock ~15 ~126 ~113 grass_block
setblock ~15 ~126 ~115 short_grass
setblock ~15 ~126 ~120 poppy
setblock ~15 ~127 ~107 short_grass
setblock ~15 ~127 ~111 fern
setblock ~16 ~109 ~98 dirt
setblock ~16 ~109 ~100 dirt
setblock ~16 ~109 ~101 dirt
setblock ~16 ~109 ~102 dirt
setblock ~16 ~110 ~97 dirt
setblock ~16 ~110 ~98 dirt
setblock ~16 ~110 ~99 dirt
setblock ~16 ~110 ~100 dirt
setblock ~16 ~110 ~101 dirt
setblock ~16 ~110 ~102 dirt
setblock ~16 ~110 ~103 dirt
setblock ~16 ~111 ~97 dirt
setblock ~16 ~111 ~98 dirt
setblock ~16 ~111 ~99 dirt
setblock ~16 ~111 ~100 dirt
setblock ~16 ~111 ~101 dirt
setblock ~16 ~111 ~102 dirt
setblock ~16 ~111 ~103 dirt
setblock ~16 ~111 ~104 dirt
setblock ~16 ~112 ~96 dirt
setblock ~16 ~112 ~97 dirt
setblock ~16 ~112 ~98 dirt
setblock ~16 ~112 ~99 dirt
setblock ~16 ~112 ~100 dirt
setblock ~16 ~112 ~101 dirt
setblock ~16 ~112 ~102 dirt
setblock ~16 ~112 ~103 dirt
setblock ~16 ~112 ~104 dirt
setblock ~16 ~112 ~105 dirt
setblock ~16 ~113 ~96 dirt
setblock ~16 ~113 ~97 dirt
setblock ~16 ~113 ~98 dirt
setblock ~16 ~113 ~99 dirt
setblock ~16 ~113 ~100 dirt
setblock ~16 ~113 ~101 dirt
setblock ~16 ~113 ~102 dirt
setblock ~16 ~113 ~103 dirt
setblock ~16 ~113 ~104 dirt
setblock ~16 ~113 ~105 dirt
setblock ~16 ~113 ~106 dirt
setblock ~16 ~114 ~70 dirt
setblock ~16 ~114 ~95 dirt
setblock ~16 ~114 ~96 dirt
setblock ~16 ~114 ~97 dirt
setblock ~16 ~114 ~98 dirt
setblock ~16 ~114 ~99 dirt
setblock ~16 ~114 ~100 dirt
setblock ~16 ~114 ~101 dirt
setblock ~16 ~114 ~102 dirt
setblock ~16 ~114 ~103 dirt
setblock ~16 ~114 ~104 dirt
setblock ~16 ~114 ~105 dirt
setblock ~16 ~114 ~106 dirt
setblock ~16 ~114 ~107 dirt
setblock ~16 ~115 ~69 dirt
setblock ~16 ~115 ~70 dirt
setblock ~16 ~115 ~71 dirt
setblock ~16 ~115 ~93 dirt
setblock ~16 ~115 ~94 dirt
setblock ~16 ~115 ~95 dirt
setblock ~16 ~115 ~96 dirt
setblock ~16 ~115 ~97 dirt
setblock ~16 ~115 ~98 dirt
setblock ~16 ~115 ~99 dirt
setblock ~16 ~115 ~100 dirt
setblock ~16 ~115 ~101 dirt
setblock ~16 ~115 ~102 dirt
setblock ~16 ~115 ~103 dirt
setblock ~16 ~115 ~104 dirt
setblock ~16 ~115 ~105 dirt
setblock ~16 ~115 ~106 dirt
setblock ~16 ~115 ~107 dirt
setblock ~16 ~115 ~108 dirt
setblock ~16 ~116 ~69 dirt
setblock ~16 ~116 ~70 dirt
setblock ~16 ~116 ~71 dirt
setblock ~16 ~116 ~92 dirt
setblock ~16 ~116 ~93 dirt
setblock ~16 ~116 ~94 dirt
setblock ~16 ~116 ~95 dirt
setblock ~16 ~116 ~96 dirt
setblock ~16 ~116 ~97 dirt
setblock ~16 ~116 ~98 dirt
setblock ~16 ~116 ~99 dirt
setblock ~16 ~116 ~100 dirt
setblock ~16 ~116 ~101 dirt
setblock ~16 ~116 ~102 dirt
setblock ~16 ~116 ~103 dirt
setblock ~16 ~116 ~104 dirt
setblock ~16 ~116 ~105 dirt
setblock ~16 ~116 ~106 dirt
setblock ~16 ~116 ~107 dirt
setblock ~16 ~116 ~108 dirt
setblock ~16 ~116 ~109 dirt
setblock ~16 ~117 ~69 dirt
setblock ~16 ~117 ~70 dirt
setblock ~16 ~117 ~71 dirt
setblock ~16 ~117 ~91 dirt
setblock ~16 ~117 ~92 dirt
setblock ~16 ~117 ~93 dirt
setblock ~16 ~117 ~94 dirt
setblock ~16 ~117 ~95 dirt
setblock ~16 ~117 ~96 dirt
setblock ~16 ~117 ~97 dirt
setblock ~16 ~117 ~98 dirt
setblock ~16 ~117 ~99 dirt
setblock ~16 ~117 ~100 dirt
setblock ~16 ~117 ~101 dirt
setblock ~16 ~117 ~102 dirt
setblock ~16 ~117 ~103 dirt
setblock ~16 ~117 ~104 dirt
setblock ~16 ~117 ~105 dirt
setblock ~16 ~117 ~106 dirt
setblock ~16 ~117 ~107 dirt
setblock ~16 ~117 ~108 dirt
setblock ~16 ~117 ~109 dirt
setblock ~16 ~117 ~110 dirt
setblock ~16 ~118 ~69 dirt
setblock ~16 ~118 ~70 dirt
setblock ~16 ~118 ~71 dirt
setblock ~16 ~118 ~72 dirt
setblock ~16 ~118 ~90 dirt
setblock ~16 ~118 ~91 dirt
setblock ~16 ~118 ~92 dirt
setblock ~16 ~118 ~93 dirt
setblock ~16 ~118 ~94 dirt
setblock ~16 ~118 ~95 dirt
setblock ~16 ~118 ~96 dirt
setblock ~16 ~118 ~97 dirt
setblock ~16 ~118 ~98 dirt
setblock ~16 ~118 ~99 dirt
setblock ~16 ~118 ~100 dirt
setblock ~16 ~118 ~101 dirt
setblock ~16 ~118 ~102 dirt
setblock ~16 ~118 ~103 dirt
setblock ~16 ~118 ~104 dirt
setblock ~16 ~118 ~105 dirt
setblock ~16 ~118 ~106 dirt
setblock ~16 ~118 ~107 dirt
setblock ~16 ~118 ~108 dirt
setblock ~16 ~118 ~109 dirt
setblock ~16 ~118 ~110 dirt
setblock ~16 ~118 ~111 dirt
setblock ~16 ~118 ~122 dirt
setblock ~16 ~118 ~125 dirt
setblock ~16 ~118 ~127 dirt
setblock ~16 ~118 ~128 dirt
setblock ~16 ~118 ~129 dirt
setblock ~16 ~119 ~67 dirt
setblock ~16 ~119 ~68 dirt
setblock ~16 ~119 ~69 dirt
setblock ~16 ~119 ~70 dirt
setblock ~16 ~119 ~71 dirt
setblock ~16 ~119 ~72 dirt
setblock ~16 ~119 ~90 dirt
setblock ~16 ~119 ~91 dirt
setblock ~16 ~119 ~92 dirt
setblock ~16 ~119 ~93 dirt
setblock ~16 ~119 ~94 dirt
setblock ~16 ~119 ~95 dirt
setblock ~16 ~119 ~96 dirt
setblock ~16 ~119 ~97 dirt
setblock ~16 ~119 ~98 dirt
setblock ~16 ~119 ~99 dirt
setblock ~16 ~119 ~100 dirt
setblock ~16 ~119 ~101 dirt
setblock ~16 ~119 ~102 dirt
setblock ~16 ~119 ~103 dirt
setblock ~16 ~119 ~104 dirt
setblock ~16 ~119 ~105 dirt
setblock ~16 ~119 ~106 dirt
setblock ~16 ~119 ~107 dirt
setblock ~16 ~119 ~108 dirt
setblock ~16 ~119 ~109 dirt
setblock ~16 ~119 ~110 dirt
setblock ~16 ~119 ~111 dirt
setblock ~16 ~119 ~112 dirt
setblock ~16 ~119 ~113 dirt
setblock ~16 ~119 ~114 dirt
setblock ~16 ~119 ~121 dirt
setblock ~16 ~119 ~122 dirt
setblock ~16 ~119 ~123 dirt
setblock ~16 ~119 ~124 dirt
setblock ~16 ~119 ~125 dirt
setblock ~16 ~119 ~126 dirt
setblock ~16 ~119 ~127 dirt
setblock ~16 ~119 ~128 dirt
setblock ~16 ~119 ~129 dirt
setblock ~16 ~119 ~130 dirt
setblock ~16 ~119 ~131 dirt
setblock ~16 ~120 ~62 dirt
setblock ~16 ~120 ~63 dirt
setblock ~16 ~120 ~64 dirt
setblock ~16 ~120 ~66 dirt
setblock ~16 ~120 ~67 dirt
setblock ~16 ~120 ~68 dirt
setblock ~16 ~120 ~69 dirt
setblock ~16 ~120 ~70 dirt
setblock ~16 ~120 ~71 dirt
setblock ~16 ~120 ~72 dirt
setblock ~16 ~120 ~73 dirt
setblock ~16 ~120 ~89 dirt
setblock ~16 ~120 ~90 dirt
setblock ~16 ~120 ~91 dirt
setblock ~16 ~120 ~92 dirt
setblock ~16 ~120 ~93 dirt
setblock ~16 ~120 ~94 dirt
setblock ~16 ~120 ~95 dirt
setblock ~16 ~120 ~96 dirt
setblock ~16 ~120 ~97 dirt
setblock ~16 ~120 ~98 dirt
setblock ~16 ~120 ~99 dirt
setblock ~16 ~120 ~100 dirt
setblock ~16 ~120 ~101 dirt
setblock ~16 ~120 ~102 dirt
setblock ~16 ~120 ~103 dirt
setblock ~16 ~120 ~104 dirt
setblock ~16 ~120 ~105 dirt
setblock ~16 ~120 ~106 dirt
setblock ~16 ~120 ~107 dirt
setblock ~16 ~120 ~108 dirt
setblock ~16 ~120 ~109 dirt
setblock ~16 ~120 ~110 dirt
setblock ~16 ~120 ~111 dirt
setblock ~16 ~120 ~112 dirt
setblock ~16 ~120 ~113 dirt
setblock ~16 ~120 ~114 dirt
setblock ~16 ~120 ~115 dirt
setblock ~16 ~120 ~120 dirt
setblock ~16 ~120 ~121 dirt
setblock ~16 ~120 ~122 dirt
