setblock ~0 ~1 ~0 gold_block
setblock ~9 ~100 ~122 dirt
setblock ~9 ~101 ~117 grass_block
setblock ~9 ~101 ~119 grass_block
setblock ~9 ~101 ~120 grass_block
setblock ~9 ~101 ~121 grass_block
setblock ~9 ~101 ~122 grass_block
setblock ~9 ~101 ~123 grass_block
setblock ~9 ~102 ~121 short_grass
setblock ~9 ~102 ~122 short_grass
setblock ~9 ~102 ~123 short_grass
setblock ~9 ~119 ~97 dirt
setblock ~9 ~120 ~97 dirt
setblock ~9 ~120 ~98 dirt
setblock ~9 ~121 ~96 dirt
setblock ~9 ~121 ~97 dirt
setblock ~9 ~121 ~98 dirt
setblock ~9 ~122 ~96 dirt
setblock ~9 ~122 ~97 dirt
setblock ~9 ~122 ~98 dirt
setblock ~9 ~123 ~96 dirt
setblock ~9 ~123 ~97 dirt
setblock ~9 ~123 ~98 dirt
setblock ~9 ~124 ~96 dirt
setblock ~9 ~124 ~97 dirt
setblock ~9 ~124 ~98 dirt
setblock ~9 ~125 ~96 grass_block
setblock ~9 ~125 ~97 grass_block
setblock ~9 ~125 ~98 grass_block
setblock ~9 ~126 ~98 short_grass
setblock ~10 ~97 ~121 dirt
setblock ~10 ~98 ~117 dirt
setblock ~10 ~98 ~120 dirt
setblock ~10 ~98 ~121 dirt
setblock ~10 ~99 ~116 dirt
setblock ~10 ~99 ~117 dirt
setblock ~10 ~99 ~120 dirt
setblock ~10 ~99 ~121 dirt
setblock ~10 ~99 ~122 dirt
setblock ~10 ~100 ~116 dirt
setblock ~10 ~100 ~117 dirt
setblock ~10 ~100 ~119 dirt
setblock ~10 ~100 ~120 dirt
setblock ~10 ~100 ~121 dirt
setblock ~10 ~100 ~122 dirt
setblock ~10 ~100 ~123 dirt
setblock ~10 ~101 ~115 grass_block
setblock ~10 ~101 ~116 grass_block
setblock ~10 ~101 ~117 grass_block
setblock ~10 ~101 ~118 grass_block
setblock ~10 ~101 ~119 grass_block
setblock ~10 ~101 ~120 grass_block
setblock ~10 ~101 ~121 grass_block
setblock ~10 ~101 ~122 grass_block
setblock ~10 ~101 ~123 grass_block
setblock ~10 ~101 ~124 grass_block
setblock ~10 ~102 ~121 short_grass
setblock ~10 ~102 ~123 short_grass
setblock ~10 ~117 ~97 dirt
setblock ~10 ~118 ~97 dirt
setblock ~10 ~119 ~96 dirt
setblock ~10 ~119 ~97 dirt
setblock ~10 ~119 ~98 dirt
setblock ~10 ~120 ~96 dirt
setblock ~10 ~120 ~97 dirt
setblock ~10 ~120 ~98 dirt
setblock ~10 ~120 ~99 dirt
setblock ~10 ~120 ~105 dirt
setblock ~10 ~121 ~95 dirt
setblock ~10 ~121 ~96 dirt
setblock ~10 ~121 ~97 dirt
setblock ~10 ~121 ~98 dirt
setblock ~10 ~121 ~99 dirt
setblock ~10 ~121 ~102 dirt
setblock ~10 ~121 ~104 dirt
setblock ~10 ~121 ~105 dirt
setblock ~10 ~122 ~95 dirt
setblock ~10 ~122 ~96 dirt
setblock ~10 ~122 ~97 dirt
setblock ~10 ~122 ~98 dirt
setblock ~10 ~122 ~99 dirt
setblock ~10 ~122 ~102 dirt
setblock ~10 ~122 ~104 dirt
setblock ~10 ~122 ~105 dirt
setblock ~10 ~123 ~95 dirt
setblock ~10 ~123 ~96 dirt
setblock ~10 ~123 ~97 dirt
setblock ~10 ~123 ~98 dirt
setblock ~10 ~123 ~99 dirt
setblock ~10 ~123 ~102 dirt
setblock ~10 ~123 ~104 dirt
setblock ~10 ~123 ~105 dirt
setblock ~10 ~124 ~95 dirt
setblock ~10 ~124 ~96 dirt
setblock ~10 ~124 ~97 dirt
setblock ~10 ~124 ~98 dirt
setblock ~10 ~124 ~99 grass_block
setblock ~10 ~124 ~102 dirt
setblock ~10 ~124 ~104 dirt
setblock ~10 ~124 ~105 dirt
setblock ~10 ~125 ~95 grass_block
setblock ~10 ~125 ~96 grass_block
setblock ~10 ~125 ~97 grass_block
setblock ~10 ~125 ~98 grass_block
setblock ~10 ~125 ~102 grass_block
setblock ~10 ~125 ~104 grass_block
setblock ~10 ~125 ~105 grass_block
setblock ~10 ~126 ~96 poppy
setblock ~10 ~126 ~105 short_grass
setblock ~11 ~95 ~121 dirt
setblock ~11 ~96 ~119 dirt
setblock ~11 ~96 ~121 dirt
setblock ~11 ~96 ~122 dirt
setblock ~11 ~97 ~117 dirt
setblock ~11 ~97 ~119 dirt
setblock ~11 ~97 ~120 dirt
setblock ~11 ~97 ~121 dirt
setblock ~11 ~97 ~122 dirt
setblock ~11 ~98 ~116 dirt
setblock ~11 ~98 ~117 dirt
setblock ~11 ~98 ~118 dirt
setblock ~11 ~98 ~119 dirt
setblock ~11 ~98 ~120 dirt
setblock ~11 ~98 ~121 dirt
setblock ~11 ~98 ~122 dirt
setblock ~11 ~98 ~123 dirt
setblock ~11 ~99 ~115 dirt
setblock ~11 ~99 ~116 dirt
setblock ~11 ~99 ~117 dirt
setblock ~11 ~99 ~118 dirt
setblock ~11 ~99 ~119 dirt
setblock ~11 ~99 ~120 dirt
setblock ~11 ~99 ~121 dirt
setblock ~11 ~99 ~122 dirt
setblock ~11 ~99 ~123 dirt
setblock ~11 ~100 ~113 dirt
setblock ~11 ~100 ~115 dirt
setblock ~11 ~100 ~116 dirt
setblock ~11 ~100 ~117 dirt
setblock ~11 ~100 ~118 dirt
setblock ~11 ~100 ~119 dirt
setblock ~11 ~100 ~120 dirt
setblock ~11 ~100 ~121 dirt
setblock ~11 ~100 ~122 dirt
setblock ~11 ~100 ~123 dirt
setblock ~11 ~100 ~124 dirt
setblock ~11 ~101 ~113 grass_block
setblock ~11 ~101 ~114 grass_block
setblock ~11 ~101 ~115 dirt
setblock ~11 ~101 ~116 grass_block
setblock ~11 ~101 ~117 grass_block
setblock ~11 ~101 ~118 grass_block
setblock ~11 ~101 ~119 dirt
setblock ~11 ~101 ~120 grass_block
setblock ~11 ~101 ~121 grass_block
setblock ~11 ~101 ~122 grass_block
setblock ~11 ~101 ~123 grass_block
setblock ~11 ~101 ~124 grass_block
setblock ~11 ~101 ~125 grass_block
setblock ~11 ~102 ~125 short_grass
setblock ~11 ~116 ~97 dirt
setblock ~11 ~117 ~96 dirt
setblock ~11 ~117 ~97 dirt
setblock ~11 ~117 ~98 dirt
setblock ~11 ~118 ~96 dirt
setblock ~11 ~118 ~97 dirt
setblock ~11 ~118 ~98 dirt
setblock ~11 ~118 ~101 dirt
setblock ~11 ~119 ~96 dirt
setblock ~11 ~119 ~97 dirt
setblock ~11 ~119 ~98 dirt
setblock ~11 ~119 ~101 dirt
setblock ~11 ~119 ~105 dirt
setblock ~11 ~120 ~95 dirt
setblock ~11 ~120 ~96 dirt
setblock ~11 ~120 ~97 dirt
setblock ~11 ~120 ~98 dirt
setblock ~11 ~120 ~99 dirt
setblock ~11 ~120 ~101 dirt
setblock ~11 ~120 ~102 dirt
setblock ~11 ~120 ~104 dirt
setblock ~11 ~120 ~105 dirt
setblock ~11 ~120 ~106 dirt
setblock ~11 ~121 ~94 dirt
setblock ~11 ~121 ~95 dirt
setblock ~11 ~121 ~96 dirt
setblock ~11 ~121 ~97 dirt
setblock ~11 ~121 ~98 dirt
setblock ~11 ~121 ~99 dirt
setblock ~11 ~121 ~100 dirt
setblock ~11 ~121 ~101 dirt
setblock ~11 ~121 ~102 dirt
setblock ~11 ~121 ~103 dirt
setblock ~11 ~121 ~104 dirt
setblock ~11 ~121 ~105 dirt
setblock ~11 ~121 ~106 dirt
setblock ~11 ~121 ~107 dirt
setblock ~11 ~121 ~115 dirt
setblock ~11 ~121 ~119 dirt
setblock ~11 ~122 ~94 dirt
setblock ~11 ~122 ~95 dirt
setblock ~11 ~122 ~96 dirt
setblock ~11 ~122 ~97 dirt
setblock ~11 ~122 ~98 dirt
setblock ~11 ~122 ~99 dirt
setblock ~11 ~122 ~100 dirt
setblock ~11 ~122 ~101 dirt
setblock ~11 ~122 ~102 dirt
setblock ~11 ~122 ~103 dirt
setblock ~11 ~122 ~104 dirt
setblock ~11 ~122 ~105 dirt
setblock ~11 ~122 ~106 dirt
setblock ~11 ~122 ~107 dirt
setblock ~11 ~122 ~115 dirt
setblock ~11 ~122 ~119 dirt
setblock ~11 ~123 ~94 dirt
setblock ~11 ~123 ~95 dirt
setblock ~11 ~123 ~96 dirt
setblock ~11 ~123 ~97 dirt
setblock ~11 ~123 ~98 dirt
setblock ~11 ~123 ~99 dirt
setblock ~11 ~123 ~100 dirt
setblock ~11 ~123 ~101 dirt
setblock ~11 ~123 ~102 dirt
setblock ~11 ~123 ~103 dirt
setblock ~11 ~123 ~104 dirt
setblock ~11 ~123 ~105 dirt
setblock ~11 ~123 ~106 dirt
setblock ~11 ~123 ~107 dirt
setblock ~11 ~123 ~115 dirt
setblock ~11 ~123 ~119 dirt
setblock ~11 ~124 ~94 grass_block
setblock ~11 ~124 ~95 grass_block
setblock ~11 ~124 ~96 dirt
setblock ~11 ~124 ~97 dirt
setblock ~11 ~124 ~98 grass_block
setblock ~11 ~124 ~99 grass_block
setblock ~11 ~124 ~100 grass_block
setblock ~11 ~124 ~101 grass_block
setblock ~11 ~124 ~102 dirt
setblock ~11 ~124 ~103 dirt
setblock ~11 ~124 ~104 dirt
setblock ~11 ~124 ~105 dirt
setblock ~11 ~124 ~106 dirt
setblock ~11 ~124 ~107 dirt
setblock ~11 ~124 ~115 dirt
setblock ~11 ~124 ~119 dirt
setblock ~11 ~125 ~94 short_grass
setblock ~11 ~125 ~96 grass_block
setblock ~11 ~125 ~97 grass_block
setblock ~11 ~125 ~99 short_grass
setblock ~11 ~125 ~101 short_grass
setblock ~11 ~125 ~102 grass_block
setblock ~11 ~125 ~103 grass_block
setblock ~11 ~125 ~104 grass_block
setblock ~11 ~125 ~105 grass_block
setblock ~11 ~125 ~106 grass_block
setblock ~11 ~125 ~107 grass_block
setblock ~11 ~125 ~115 dirt
setblock ~11 ~125 ~119 dirt
setblock ~11 ~126 ~102 short_grass
setblock ~11 ~126 ~105 short_grass
setblock ~11 ~126 ~115 grass_block
setblock ~11 ~126 ~119 dirt
setblock ~11 ~127 ~119 dirt
setblock ~11 ~128 ~119 grass_block
setblock ~12 ~91 ~121 dirt
setblock ~12 ~92 ~121 dirt
setblock ~12 ~93 ~121 dirt
setblock ~12 ~94 ~118 dirt
setblock ~12 ~94 ~120 dirt
setblock ~12 ~94 ~121 dirt
setblock ~12 ~94 ~122 dirt
setblock ~12 ~95 ~117 dirt
setblock ~12 ~95 ~118 dirt
setblock ~12 ~95 ~119 dirt
setblock ~12 ~95 ~120 dirt
setblock ~12 ~95 ~121 dirt
setblock ~12 ~95 ~122 dirt
setblock ~12 ~96 ~117 dirt
setblock ~12 ~96 ~118 dirt
setblock ~12 ~96 ~119 dirt
setblock ~12 ~96 ~120 dirt
setblock ~12 ~96 ~121 dirt
setblock ~12 ~96 ~122 dirt
setblock ~12 ~96 ~123 dirt
setblock ~12 ~97 ~116 dirt
setblock ~12 ~97 ~117 dirt
setblock ~12 ~97 ~118 dirt
setblock ~12 ~97 ~119 dirt
setblock ~12 ~97 ~120 dirt
setblock ~12 ~97 ~121 dirt
setblock ~12 ~97 ~122 dirt
setblock ~12 ~97 ~123 dirt
setblock ~12 ~98 ~115 dirt
setblock ~12 ~98 ~116 dirt
setblock ~12 ~98 ~117 dirt
setblock ~12 ~98 ~118 dirt
setblock ~12 ~98 ~119 dirt
setblock ~12 ~98 ~120 dirt
setblock ~12 ~98 ~121 dirt
setblock ~12 ~98 ~122 dirt
setblock ~12 ~98 ~123 dirt
setblock ~12 ~98 ~124 dirt
setblock ~12 ~99 ~72 dirt
setblock ~12 ~99 ~112 dirt
setblock ~12 ~99 ~113 dirt
setblock ~12 ~99 ~115 dirt
setblock ~12 ~99 ~116 dirt
setblock ~12 ~99 ~117 dirt
setblock ~12 ~99 ~118 dirt
setblock ~12 ~99 ~119 dirt
setblock ~12 ~99 ~120 dirt
setblock ~12 ~99 ~121 dirt
setblock ~12 ~99 ~122 dirt
setblock ~12 ~99 ~123 dirt
setblock ~12 ~99 ~124 dirt
setblock ~12 ~99 ~125 dirt
setblock ~12 ~100 ~72 dirt
setblock ~12 ~100 ~73 dirt
setblock ~12 ~100 ~98 dirt
setblock ~12 ~100 ~111 dirt
setblock ~12 ~100 ~112 dirt
setblock ~12 ~100 ~113 dirt
setblock ~12 ~100 ~114 dirt
setblock ~12 ~100 ~115 dirt
setblock ~12 ~100 ~116 dirt
setblock ~12 ~100 ~117 dirt
setblock ~12 ~100 ~118 dirt
setblock ~12 ~100 ~119 dirt
setblock ~12 ~100 ~120 dirt
setblock ~12 ~100 ~121 dirt
setblock ~12 ~100 ~122 dirt
setblock ~12 ~100 ~123 dirt
setblock ~12 ~100 ~124 dirt
setblock ~12 ~100 ~125 dirt
setblock ~12 ~101 ~71 grass_block
setblock ~12 ~101 ~72 grass_block
setblock ~12 ~101 ~73 grass_block
setblock ~12 ~101 ~74 grass_block
setblock ~12 ~101 ~97 dirt
setblock ~12 ~101 ~98 dirt
setblock ~12 ~101 ~99 dirt
setblock ~12 ~101 ~110 grass_block
setblock ~12 ~101 ~111 grass_block
setblock ~12 ~101 ~112 grass_block
setblock ~12 ~101 ~113 grass_block
setblock ~12 ~101 ~114 dirt
setblock ~12 ~101 ~115 dirt
setblock ~12 ~101 ~116 dirt
setblock ~12 ~101 ~117 grass_block
setblock ~12 ~101 ~118 dirt
setblock ~12 ~101 ~119 dirt
setblock ~12 ~101 ~120 dirt
setblock ~12 ~101 ~121 dirt
setblock ~12 ~101 ~122 dirt
setblock ~12 ~101 ~123 grass_block
setblock ~12 ~101 ~124 grass_block
setblock ~12 ~101 ~125 grass_block
setblock ~12 ~101 ~126 grass_block
setblock ~12 ~102 ~73 short_grass
setblock ~12 ~102 ~112 poppy
setblock ~12 ~102 ~113 short_grass
setblock ~12 ~102 ~124 short_grass
setblock ~12 ~117 ~97 dirt
setblock ~12 ~117 ~101 dirt
setblock ~12 ~118 ~97 dirt
setblock ~12 ~118 ~100 dirt
setblock ~12 ~118 ~101 dirt
setblock ~12 ~118 ~102 dirt
setblock ~12 ~118 ~105 dirt
setblock ~12 ~118 ~119 dirt
setblock ~12 ~118 ~121 dirt
setblock ~12 ~119 ~96 dirt
setblock ~12 ~119 ~97 dirt
setblock ~12 ~119 ~98 dirt
setblock ~12 ~119 ~100 dirt
setblock ~12 ~119 ~101 dirt
setblock ~12 ~119 ~102 dirt
setblock ~12 ~119 ~104 dirt
setblock ~12 ~119 ~105 dirt
setblock ~12 ~119 ~106 dirt
setblock ~12 ~119 ~115 dirt
setblock ~12 ~119 ~119 dirt
setblock ~12 ~119 ~121 dirt
setblock ~12 ~120 ~95 dirt
setblock ~12 ~120 ~96 dirt
setblock ~12 ~120 ~97 dirt
setblock ~12 ~120 ~98 dirt
setblock ~12 ~120 ~99 dirt
setblock ~12 ~120 ~100 dirt
setblock ~12 ~120 ~101 dirt
setblock ~12 ~120 ~102 dirt
setblock ~12 ~120 ~103 dirt
setblock ~12 ~120 ~104 dirt
setblock ~12 ~120 ~105 dirt
setblock ~12 ~120 ~106 dirt
setblock ~12 ~120 ~107 dirt
setblock ~12 ~120 ~115 dirt
setblock ~12 ~120 ~116 dirt
setblock ~12 ~120 ~118 dirt
setblock ~12 ~120 ~119 dirt
setblock ~12 ~120 ~121 dirt
setblock ~12 ~120 ~122 dirt
setblock ~12 ~121 ~95 dirt
setblock ~12 ~121 ~96 dirt
setblock ~12 ~121 ~97 dirt
setblock ~12 ~121 ~98 dirt
setblock ~12 ~121 ~99 dirt
setblock ~12 ~121 ~100 dirt
setblock ~12 ~121 ~101 dirt
setblock ~12 ~121 ~102 dirt
setblock ~12 ~121 ~103 dirt
setblock ~12 ~121 ~104 dirt
setblock ~12 ~121 ~105 dirt
setblock ~12 ~121 ~106 dirt
setblock ~12 ~121 ~107 dirt
setblock ~12 ~121 ~108 dirt
setblock ~12 ~121 ~114 dirt
setblock ~12 ~121 ~115 dirt
setblock ~12 ~121 ~116 dirt
setblock ~12 ~121 ~118 dirt
setblock ~12 ~121 ~119 dirt
setblock ~12 ~121 ~120 dirt
setblock ~12 ~121 ~121 dirt
setblock ~12 ~121 ~122 dirt
setblock ~12 ~122 ~95 dirt
setblock ~12 ~122 ~96 dirt
setblock ~12 ~122 ~97 dirt
setblock ~12 ~122 ~98 dirt
setblock ~12 ~122 ~99 dirt
setblock ~12 ~122 ~100 dirt
setblock ~12 ~122 ~101 dirt
setblock ~12 ~122 ~102 dirt
setblock ~12 ~122 ~103 dirt
setblock ~12 ~122 ~104 dirt
setblock ~12 ~122 ~105 dirt
setblock ~12 ~122 ~106 dirt
setblock ~12 ~122 ~107 dirt
setblock ~12 ~122 ~108 dirt
setblock ~12 ~122 ~114 dirt
setblock ~12 ~122 ~115 dirt
setblock ~12 ~122 ~116 dirt
setblock ~12 ~122 ~118 dirt
setblock ~12 ~122 ~119 dirt
setblock ~12 ~122 ~120 dirt
setblock ~12 ~122 ~121 dirt
setblock ~12 ~122 ~122 dirt
setblock ~12 ~123 ~95 dirt
setblock ~12 ~123 ~96 dirt
setblock ~12 ~123 ~97 dirt
setblock ~12 ~123 ~98 dirt
setblock ~12 ~123 ~99 dirt
setblock ~12 ~123 ~100 dirt
setblock ~12 ~123 ~101 dirt
setblock ~12 ~123 ~102 dirt
setblock ~12 ~123 ~103 dirt
setblock ~12 ~123 ~104 dirt
setblock ~12 ~123 ~105 dirt
setblock ~12 ~123 ~106 dirt
setblock ~12 ~123 ~107 dirt
setblock ~12 ~123 ~108 dirt
setblock ~12 ~123 ~114 dirt
setblock ~12 ~123 ~115 dirt
setblock ~12 ~123 ~116 dirt
setblock ~12 ~123 ~118 dirt
setblock ~12 ~123 ~119 dirt
setblock ~12 ~123 ~120 dirt
setblock ~12 ~123 ~121 dirt
setblock ~12 ~123 ~122 dirt
setblock ~12 ~124 ~95 grass_block
setblock ~12 ~124 ~96 grass_block
setblock ~12 ~124 ~97 grass_block
setblock ~12 ~124 ~98 grass_block
setblock ~12 ~124 ~99 grass_block
setblock ~12 ~124 ~100 grass_block
setblock ~12 ~124 ~101 grass_block
setblock ~12 ~124 ~102 grass_block
setblock ~12 ~124 ~103 dirt
setblock ~12 ~124 ~104 dirt
setblock ~12 ~124 ~105 dirt
setblock ~12 ~124 ~106 dirt
setblock ~12 ~124 ~107 dirt
setblock ~12 ~124 ~108 dirt
setblock ~12 ~124 ~114 dirt
setblock ~12 ~124 ~115 dirt
setblock ~12 ~124 ~116 dirt
setblock ~12 ~124 ~118 dirt
setblock ~12 ~124 ~119 dirt
setblock ~12 ~124 ~120 dirt
setblock ~12 ~124 ~121 dirt
setblock ~12 ~124 ~122 dirt
setblock ~12 ~125 ~96 short_grass
setblock ~12 ~125 ~97 short_grass
setblock ~12 ~125 ~100 poppy
setblock ~12 ~125 ~101 short_grass
setblock ~12 ~125 ~103 grass_block
setblock ~12 ~125 ~104 grass_block
setblock ~12 ~125 ~105 grass_block
setblock ~12 ~125 ~106 grass_block
setblock ~12 ~125 ~107 grass_block
setblock ~12 ~125 ~108 grass_block
setblock ~12 ~125 ~114 dirt
setblock ~12 ~125 ~115 dirt
setblock ~12 ~125 ~116 dirt
setblock ~12 ~125 ~118 dirt
setblock ~12 ~125 ~119 dirt
setblock ~12 ~125 ~120 dirt
setblock ~12 ~125 ~121 dirt
setblock ~12 ~125 ~122 dirt
setblock ~12 ~126 ~106 short_grass
setblock ~12 ~126 ~107 short_grass
setblock ~12 ~126 ~114 grass_block
setblock ~12 ~126 ~115 grass_block
setblock ~12 ~126 ~116 grass_block
setblock ~12 ~126 ~118 dirt
setblock ~12 ~126 ~119 dirt
setblock ~12 ~126 ~120 dirt
setblock ~12 ~126 ~121 dirt
setblock ~12 ~126 ~122 dirt
setblock ~12 ~127 ~114 fern
setblock ~12 ~127 ~115 short_grass
setblock ~12 ~127 ~116 poppy
setblock ~12 ~127 ~118 grass_block
setblock ~12 ~127 ~119 grass_block
setblock ~12 ~127 ~120 dirt
setblock ~12 ~127 ~121 grass_block
setblock ~12 ~127 ~122 grass_block
setblock ~12 ~128 ~119 short_grass
setblock ~12 ~128 ~120 grass_block
setblock ~13 ~90 ~121 dirt
setblock ~13 ~91 ~120 dirt
setblock ~13 ~91 ~121 dirt
setblock ~13 ~91 ~122 dirt
setblock ~13 ~92 ~118 dirt
setblock ~13 ~92 ~119 dirt
setblock ~13 ~92 ~120 dirt
setblock ~13 ~92 ~121 dirt
setblock ~13 ~92 ~122 dirt
setblock ~13 ~93 ~118 dirt
setblock ~13 ~93 ~119 dirt
setblock ~13 ~93 ~120 dirt
setblock ~13 ~93 ~121 dirt
setblock ~13 ~93 ~122 dirt
setblock ~13 ~94 ~116 dirt
setblock ~13 ~94 ~117 dirt
setblock ~13 ~94 ~118 dirt
setblock ~13 ~94 ~119 dirt
setblock ~13 ~94 ~120 dirt
setblock ~13 ~94 ~121 dirt
setblock ~13 ~94 ~122 dirt
setblock ~13 ~94 ~123 dirt
setblock ~13 ~95 ~115 dirt
setblock ~13 ~95 ~116 dirt
setblock ~13 ~95 ~117 dirt
setblock ~13 ~95 ~118 dirt
setblock ~13 ~95 ~119 dirt
setblock ~13 ~95 ~120 dirt
setblock ~13 ~95 ~121 dirt
setblock ~13 ~95 ~122 dirt
setblock ~13 ~95 ~123 dirt
setblock ~13 ~96 ~115 dirt
setblock ~13 ~96 ~116 dirt
setblock ~13 ~96 ~117 dirt
setblock ~13 ~96 ~118 dirt
setblock ~13 ~96 ~119 dirt
setblock ~13 ~96 ~120 dirt
setblock ~13 ~96 ~121 dirt
setblock ~13 ~96 ~122 dirt
setblock ~13 ~96 ~123 dirt
setblock ~13 ~96 ~125 dirt
setblock ~13 ~97 ~113 dirt
setblock ~13 ~97 ~114 dirt
setblock ~13 ~97 ~115 dirt
setblock ~13 ~97 ~116 dirt
setblock ~13 ~97 ~117 dirt
setblock ~13 ~97 ~118 dirt
setblock ~13 ~97 ~119 dirt
setblock ~13 ~97 ~120 dirt
setblock ~13 ~97 ~121 dirt
setblock ~13 ~97 ~122 dirt
setblock ~13 ~97 ~123 dirt
setblock ~13 ~97 ~124 dirt
setblock ~13 ~97 ~125 dirt
setblock ~13 ~98 ~72 dirt
setblock ~13 ~98 ~76 dirt
setblock ~13 ~98 ~112 dirt
setblock ~13 ~98 ~113 dirt
setblock ~13 ~98 ~114 dirt
setblock ~13 ~98 ~115 dirt
setblock ~13 ~98 ~116 dirt
setblock ~13 ~98 ~117 dirt
setblock ~13 ~98 ~118 dirt
setblock ~13 ~98 ~119 dirt
setblock ~13 ~98 ~120 dirt
setblock ~13 ~98 ~121 dirt
setblock ~13 ~98 ~122 dirt
setblock ~13 ~98 ~123 dirt
setblock ~13 ~98 ~124 dirt
setblock ~13 ~98 ~125 dirt
setblock ~13 ~98 ~126 dirt
setblock ~13 ~99 ~71 dirt
setblock ~13 ~99 ~72 dirt
setblock ~13 ~99 ~73 dirt
setblock ~13 ~99 ~76 dirt
setblock ~13 ~99 ~77 dirt
setblock ~13 ~99 ~98 dirt
setblock ~13 ~99 ~111 dirt
setblock ~13 ~99 ~112 dirt
setblock ~13 ~99 ~113 dirt
setblock ~13 ~99 ~114 dirt
setblock ~13 ~99 ~115 dirt
setblock ~13 ~99 ~116 dirt
setblock ~13 ~99 ~117 dirt
setblock ~13 ~99 ~118 dirt
setblock ~13 ~99 ~119 dirt
setblock ~13 ~99 ~120 dirt
setblock ~13 ~99 ~121 dirt
setblock ~13 ~99 ~122 dirt
setblock ~13 ~99 ~123 dirt
setblock ~13 ~99 ~124 dirt
setblock ~13 ~99 ~125 dirt
setblock ~13 ~99 ~126 dirt
setblock ~13 ~100 ~70 dirt
setblock ~13 ~100 ~71 dirt
setblock ~13 ~100 ~72 dirt
setblock ~13 ~100 ~73 dirt
setblock ~13 ~100 ~74 dirt
setblock ~13 ~100 ~76 dirt
setblock ~13 ~100 ~77 dirt
setblock ~13 ~100 ~79 dirt
setblock ~13 ~100 ~97 dirt
setblock ~13 ~100 ~98 dirt
setblock ~13 ~100 ~99 dirt
setblock ~13 ~100 ~101 dirt
setblock ~13 ~100 ~102 dirt
setblock ~13 ~100 ~110 dirt
setblock ~13 ~100 ~111 dirt
setblock ~13 ~100 ~112 dirt
setblock ~13 ~100 ~113 dirt
setblock ~13 ~100 ~114 dirt
setblock ~13 ~100 ~115 dirt
setblock ~13 ~100 ~116 dirt
setblock ~13 ~100 ~117 dirt
setblock ~13 ~100 ~118 dirt
setblock ~13 ~100 ~119 dirt
setblock ~13 ~100 ~120 dirt
setblock ~13 ~100 ~121 dirt
setblock ~13 ~100 ~122 dirt
setblock ~13 ~100 ~123 dirt
setblock ~13 ~100 ~124 dirt
setblock ~13 ~100 ~125 dirt
setblock ~13 ~100 ~126 dirt
setblock ~13 ~100 ~127 dirt
setblock ~13 ~101 ~70 grass_block
setblock ~13 ~101 ~71 grass_block
setblock ~13 ~101 ~72 grass_block
setblock ~13 ~101 ~73 grass_block
setblock ~13 ~101 ~74 dirt
setblock ~13 ~101 ~75 grass_block
setblock ~13 ~101 ~76 dirt
setblock ~13 ~101 ~77 grass_block
setblock ~13 ~101 ~78 grass_block
setblock ~13 ~101 ~79 grass_block
setblock ~13 ~101 ~80 grass_block
setblock ~13 ~101 ~91 grass_block
setblock ~13 ~101 ~96 dirt
setblock ~13 ~101 ~97 dirt
setblock ~13 ~101 ~98 dirt
setblock ~13 ~101 ~99 dirt
setblock ~13 ~101 ~100 dirt
setblock ~13 ~101 ~101 dirt
setblock ~13 ~101 ~102 dirt
setblock ~13 ~101 ~109 grass_block
setblock ~13 ~101 ~110 grass_block
setblock ~13 ~101 ~111 dirt
setblock ~13 ~101 ~112 grass_block
setblock ~13 ~101 ~113 dirt
setblock ~13 ~101 ~114 dirt
setblock ~13 ~101 ~115 dirt
setblock ~13 ~101 ~116 dirt
setblock ~13 ~101 ~117 dirt
setblock ~13 ~101 ~118 dirt
setblock ~13 ~101 ~119 dirt
setblock ~13 ~101 ~120 dirt
setblock ~13 ~101 ~121 dirt
setblock ~13 ~101 ~122 dirt
setblock ~13 ~101 ~123 dirt
setblock ~13 ~101 ~124 grass_block
setblock ~13 ~101 ~125 grass_block
setblock ~13 ~101 ~126 grass_block
setblock ~13 ~101 ~127 grass_block
setblock ~13 ~101 ~128 grass_block
setblock ~13 ~101 ~130 grass_block
setblock ~13 ~102 ~72 short_grass
setblock ~13 ~102 ~73 short_grass
setblock ~13 ~102 ~109 short_grass
setblock ~13 ~102 ~125 short_grass
setblock ~13 ~102 ~126 short_grass
setblock ~13 ~102 ~128 short_grass
setblock ~13 ~116 ~101 dirt
setblock ~13 ~116 ~102 dirt
setblock ~13 ~117 ~100 dirt
setblock ~13 ~117 ~101 dirt
setblock ~13 ~117 ~102 dirt
setblock ~13 ~117 ~103 dirt
setblock ~13 ~117 ~105 dirt
setblock ~13 ~117 ~118 dirt
setblock ~13 ~117 ~119 dirt
setblock ~13 ~117 ~121 dirt
setblock ~13 ~118 ~100 dirt
setblock ~13 ~118 ~101 dirt
setblock ~13 ~118 ~102 dirt
setblock ~13 ~118 ~103 dirt
setblock ~13 ~118 ~104 dirt
setblock ~13 ~118 ~105 dirt
setblock ~13 ~118 ~106 dirt
setblock ~13 ~118 ~107 dirt
setblock ~13 ~118 ~115 dirt
setblock ~13 ~118 ~116 dirt
setblock ~13 ~118 ~118 dirt
setblock ~13 ~118 ~119 dirt
setblock ~13 ~118 ~120 dirt
setblock ~13 ~118 ~121 dirt
setblock ~13 ~118 ~122 dirt
setblock ~13 ~119 ~97 dirt
setblock ~13 ~119 ~99 dirt
setblock ~13 ~119 ~100 dirt
setblock ~13 ~119 ~101 dirt
setblock ~13 ~119 ~102 dirt
setblock ~13 ~119 ~103 dirt
setblock ~13 ~119 ~104 dirt
setblock ~13 ~119 ~105 dirt
setblock ~13 ~119 ~106 dirt
setblock ~13 ~119 ~107 dirt
setblock ~13 ~119 ~114 dirt
setblock ~13 ~119 ~115 dirt
setblock ~13 ~119 ~116 dirt
setblock ~13 ~119 ~117 dirt
setblock ~13 ~119 ~118 dirt
setblock ~13 ~119 ~119 dirt
setblock ~13 ~119 ~120 dirt
setblock ~13 ~119 ~121 dirt
setblock ~13 ~119 ~122 dirt
setblock ~13 ~120 ~96 dirt
setblock ~13 ~120 ~97 dirt
setblock ~13 ~120 ~98 dirt
setblock ~13 ~120 ~99 dirt
setblock ~13 ~120 ~100 dirt
setblock ~13 ~120 ~101 dirt
setblock ~13 ~120 ~102 dirt
setblock ~13 ~120 ~103 dirt
setblock ~13 ~120 ~104 dirt
setblock ~13 ~120 ~105 dirt
setblock ~13 ~120 ~106 dirt
setblock ~13 ~120 ~107 dirt
setblock ~13 ~120 ~108 dirt
setblock ~13 ~120 ~113 dirt
setblock ~13 ~120 ~114 dirt
setblock ~13 ~120 ~115 dirt
setblock ~13 ~120 ~116 dirt
setblock ~13 ~120 ~117 dirt
setblock ~13 ~120 ~118 dirt
setblock ~13 ~120 ~119 dirt
setblock ~13 ~120 ~120 dirt
setblock ~13 ~120 ~121 dirt
setblock ~13 ~120 ~122 dirt
setblock ~13 ~120 ~123 dirt
setblock ~13 ~121 ~74 dirt
setblock ~13 ~121 ~76 dirt
setblock ~13 ~121 ~94 dirt
setblock ~13 ~121 ~96 dirt
setblock ~13 ~121 ~97 dirt
setblock ~13 ~121 ~98 dirt
setblock ~13 ~121 ~99 dirt
setblock ~13 ~121 ~100 dirt
setblock ~13 ~121 ~101 dirt
setblock ~13 ~121 ~102 dirt
setblock ~13 ~121 ~103 dirt
setblock ~13 ~121 ~104 dirt
setblock ~13 ~121 ~105 dirt
setblock ~13 ~121 ~106 dirt
setblock ~13 ~121 ~107 dirt
setblock ~13 ~121 ~108 dirt
setblock ~13 ~121 ~111 dirt
setblock ~13 ~121 ~113 dirt
setblock ~13 ~121 ~114 dirt
setblock ~13 ~121 ~115 dirt
setblock ~13 ~121 ~116 dirt
setblock ~13 ~121 ~117 dirt
setblock ~13 ~121 ~118 dirt
setblock ~13 ~121 ~119 dirt
setblock ~13 ~121 ~120 dirt
setblock ~13 ~121 ~121 dirt
setblock ~13 ~121 ~122 dirt
setblock ~13 ~121 ~123 dirt
setblock ~13 ~122 ~74 dirt
setblock ~13 ~122 ~76 dirt
setblock ~13 ~122 ~94 dirt
setblock ~13 ~122 ~96 dirt
setblock ~13 ~122 ~97 dirt
setblock ~13 ~122 ~98 dirt
setblock ~13 ~122 ~99 dirt
setblock ~13 ~122 ~100 dirt
setblock ~13 ~122 ~101 dirt
setblock ~13 ~122 ~102 dirt
setblock ~13 ~122 ~103 dirt
setblock ~13 ~122 ~104 dirt
setblock ~13 ~122 ~105 dirt
setblock ~13 ~122 ~106 dirt
setblock ~13 ~122 ~107 dirt
setblock ~13 ~122 ~108 dirt
setblock ~13 ~122 ~111 dirt
setblock ~13 ~122 ~113 dirt
setblock ~13 ~122 ~114 dirt
setblock ~13 ~122 ~115 dirt
setblock ~13 ~122 ~116 dirt
setblock ~13 ~122 ~117 dirt
setblock ~13 ~122 ~118 dirt
setblock ~13 ~122 ~119 dirt
setblock ~13 ~122 ~120 dirt
setblock ~13 ~122 ~121 dirt
setblock ~13 ~122 ~122 dirt
setblock ~13 ~122 ~123 dirt
setblock ~13 ~123 ~74 grass_block
setblock ~13 ~123 ~76 dirt
setblock ~13 ~123 ~94 dirt
setblock ~13 ~123 ~96 dirt
setblock ~13 ~123 ~97 dirt
setblock ~13 ~123 ~98 dirt
setblock ~13 ~123 ~99 dirt
setblock ~13 ~123 ~100 dirt
setblock ~13 ~123 ~101 dirt
setblock ~13 ~123 ~102 dirt
setblock ~13 ~123 ~103 dirt
setblock ~13 ~123 ~104 dirt
setblock ~13 ~123 ~105 dirt
setblock ~13 ~123 ~106 dirt
setblock ~13 ~123 ~107 dirt
setblock ~13 ~123 ~108 dirt
setblock ~13 ~123 ~111 dirt
setblock ~13 ~123 ~113 dirt
setblock ~13 ~123 ~114 dirt
setblock ~13 ~123 ~115 dirt
setblock ~13 ~123 ~116 dirt
setblock ~13 ~123 ~117 dirt
setblock ~13 ~123 ~118 dirt
setblock ~13 ~123 ~119 dirt
setblock ~13 ~123 ~120 dirt
setblock ~13 ~123 ~121 dirt
setblock ~13 ~123 ~122 dirt
setblock ~13 ~123 ~123 dirt
setblock ~13 ~124 ~76 grass_block
setblock ~13 ~124 ~94 grass_block
setblock ~13 ~124 ~96 grass_block
setblock ~13 ~124 ~97 grass_block
setblock ~13 ~124 ~98 grass_block
setblock ~13 ~124 ~99 grass_block
setblock ~13 ~124 ~100 grass_block
setblock ~13 ~124 ~101 grass_block
setblock ~13 ~124 ~102 grass_block
setblock ~13 ~124 ~103 grass_block
setblock ~13 ~124 ~104 dirt
setblock ~13 ~124 ~105 dirt
setblock ~13 ~124 ~106 dirt
setblock ~13 ~124 ~107 dirt
setblock ~13 ~124 ~108 dirt
setblock ~13 ~124 ~111 dirt
setblock ~13 ~124 ~113 dirt
setblock ~13 ~124 ~114 dirt
setblock ~13 ~124 ~115 dirt
setblock ~13 ~124 ~116 dirt
setblock ~13 ~124 ~117 dirt
setblock ~13 ~124 ~118 dirt
setblock ~13 ~124 ~119 dirt
setblock ~13 ~124 ~120 dirt
setblock ~13 ~124 ~121 dirt
setblock ~13 ~124 ~122 dirt
setblock ~13 ~124 ~123 dirt
setblock ~13 ~125 ~76 short_grass
setblock ~13 ~125 ~97 short_grass
setblock ~13 ~125 ~98 short_grass
setblock ~13 ~125 ~99 short_grass
setblock ~13 ~125 ~104 grass_block
setblock ~13 ~125 ~105 grass_block
setblock ~13 ~125 ~106 grass_block
setblock ~13 ~125 ~107 grass_block
setblock ~13 ~125 ~108 grass_block
setblock ~13 ~125 ~111 grass_block
setblock ~13 ~125 ~113 grass_block
setblock ~13 ~125 ~114 dirt
setblock ~13 ~125 ~115 dirt
setblock ~13 ~125 ~116 dirt
setblock ~13 ~125 ~117 dirt
setblock ~13 ~125 ~118 dirt
setblock ~13 ~125 ~119 dirt
setblock ~13 ~125 ~120 dirt
setblock ~13 ~125 ~121 dirt
setblock ~13 ~125 ~122 dirt
setblock ~13 ~125 ~123 dirt
setblock ~13 ~126 ~105 fern
setblock ~13 ~126 ~106 short_grass
setblock ~13 ~126 ~114 grass_block
setblock ~13 ~126 ~115 grass_block
setblock ~13 ~126 ~116 grass_block
setblock ~13 ~126 ~117 grass_block
setblock ~13 ~126 ~118 grass_block
setblock ~13 ~126 ~119 dirt
setblock ~13 ~126 ~120 dirt
setblock ~13 ~126 ~121 dirt
setblock ~13 ~126 ~122 dirt
setblock ~13 ~126 ~123 grass_block
setblock ~13 ~127 ~117 short_grass
setblock ~13 ~127 ~118 short_grass
setblock ~13 ~127 ~119 grass_block
setblock ~13 ~127 ~120 grass_block
setblock ~13 ~127 ~121 grass_block
setblock ~13 ~127 ~122 grass_block
setblock ~13 ~128 ~121 short_grass
setblock ~14 ~89 ~119 dirt
setblock ~14 ~89 ~120 dirt
setblock ~14 ~89 ~121 dirt
setblock ~14 ~90 ~119 dirt
setblock ~14 ~90 ~120 dirt
setblock ~14 ~90 ~121 dirt
setblock ~14 ~90 ~122 dirt
setblock ~14 ~91 ~118 dirt
setblock ~14 ~91 ~119 dirt
setblock ~14 ~91 ~120 dirt
setblock ~14 ~91 ~121 dirt
setblock ~14 ~91 ~122 dirt
setblock ~14 ~92 ~117 dirt
setblock ~14 ~92 ~118 dirt
setblock ~14 ~92 ~119 dirt
setblock ~14 ~92 ~120 dirt
setblock ~14 ~92 ~121 dirt
setblock ~14 ~92 ~122 dirt
setblock ~14 ~93 ~116 dirt
setblock ~14 ~93 ~117 dirt
setblock ~14 ~93 ~118 dirt
setblock ~14 ~93 ~119 dirt
setblock ~14 ~93 ~120 dirt
setblock ~14 ~93 ~121 dirt
setblock ~14 ~93 ~122 dirt
setblock ~14 ~93 ~123 dirt
setblock ~14 ~93 ~124 dirt
setblock ~14 ~93 ~125 dirt
setblock ~14 ~94 ~115 dirt
setblock ~14 ~94 ~116 dirt
setblock ~14 ~94 ~117 dirt
setblock ~14 ~94 ~118 dirt
setblock ~14 ~94 ~119 dirt
setblock ~14 ~94 ~120 dirt
setblock ~14 ~94 ~121 dirt
setblock ~14 ~94 ~122 dirt
setblock ~14 ~94 ~123 dirt
setblock ~14 ~94 ~124 dirt
setblock ~14 ~94 ~125 dirt
setblock ~14 ~95 ~114 dirt
setblock ~14 ~95 ~115 dirt
setblock ~14 ~95 ~116 dirt
setblock ~14 ~95 ~117 dirt
setblock ~14 ~95 ~118 dirt
setblock ~14 ~95 ~119 dirt
setblock ~14 ~95 ~120 dirt
setblock ~14 ~95 ~121 dirt
setblock ~14 ~95 ~122 dirt
setblock ~14 ~95 ~123 dirt
setblock ~14 ~95 ~124 dirt
setblock ~14 ~95 ~125 dirt
setblock ~14 ~96 ~77 dirt
setblock ~14 ~96 ~79 dirt
setblock ~14 ~96 ~113 dirt
setblock ~14 ~96 ~114 dirt
setblock ~14 ~96 ~115 dirt
setblock ~14 ~96 ~116 dirt
setblock ~14 ~96 ~117 dirt
setblock ~14 ~96 ~118 dirt
setblock ~14 ~96 ~119 dirt
setblock ~14 ~96 ~120 dirt
setblock ~14 ~96 ~121 dirt
setblock ~14 ~96 ~122 dirt
setblock ~14 ~96 ~123 dirt
setblock ~14 ~96 ~124 dirt
setblock ~14 ~96 ~125 dirt
setblock ~14 ~96 ~126 dirt
setblock ~14 ~97 ~72 dirt
setblock ~14 ~97 ~76 dirt
setblock ~14 ~97 ~77 dirt
setblock ~14 ~97 ~79 dirt
setblock ~14 ~97 ~98 dirt
setblock ~14 ~97 ~99 dirt
setblock ~14 ~97 ~100 dirt
setblock ~14 ~97 ~112 dirt
setblock ~14 ~97 ~113 dirt
setblock ~14 ~97 ~114 dirt
setblock ~14 ~97 ~115 dirt
setblock ~14 ~97 ~116 dirt
setblock ~14 ~97 ~117 dirt
setblock ~14 ~97 ~118 dirt
setblock ~14 ~97 ~119 dirt
setblock ~14 ~97 ~120 dirt
setblock ~14 ~97 ~121 dirt
setblock ~14 ~97 ~122 dirt
setblock ~14 ~97 ~123 dirt
setblock ~14 ~97 ~124 dirt
setblock ~14 ~97 ~125 dirt
setblock ~14 ~97 ~126 dirt
setblock ~14 ~98 ~71 dirt
setblock ~14 ~98 ~72 dirt
setblock ~14 ~98 ~73 dirt
setblock ~14 ~98 ~75 dirt
setblock ~14 ~98 ~76 dirt
setblock ~14 ~98 ~77 dirt
setblock ~14 ~98 ~78 dirt
setblock ~14 ~98 ~79 dirt
setblock ~14 ~98 ~97 dirt
setblock ~14 ~98 ~98 dirt
setblock ~14 ~98 ~99 dirt
setblock ~14 ~98 ~100 dirt
setblock ~14 ~98 ~101 dirt
setblock ~14 ~98 ~111 dirt
setblock ~14 ~98 ~112 dirt
setblock ~14 ~98 ~113 dirt
setblock ~14 ~98 ~114 dirt
setblock ~14 ~98 ~115 dirt
setblock ~14 ~98 ~116 dirt
setblock ~14 ~98 ~117 dirt
setblock ~14 ~98 ~118 dirt
setblock ~14 ~98 ~119 dirt
setblock ~14 ~98 ~120 dirt
setblock ~14 ~98 ~121 dirt
setblock ~14 ~98 ~122 dirt
setblock ~14 ~98 ~123 dirt
setblock ~14 ~98 ~124 dirt
setblock ~14 ~98 ~125 dirt
setblock ~14 ~98 ~126 dirt
setblock ~14 ~98 ~127 dirt
setblock ~14 ~99 ~70 dirt
setblock ~14 ~99 ~71 dirt
setblock ~14 ~99 ~72 dirt
setblock ~14 ~99 ~73 dirt
setblock ~14 ~99 ~74 dirt
setblock ~14 ~99 ~75 dirt
setblock ~14 ~99 ~76 dirt
setblock ~14 ~99 ~77 dirt
setblock ~14 ~99 ~78 dirt
setblock ~14 ~99 ~79 dirt
setblock ~14 ~99 ~80 dirt
setblock ~14 ~99 ~91 dirt
setblock ~14 ~99 ~92 dirt
setblock ~14 ~99 ~97 dirt
setblock ~14 ~99 ~98 dirt
setblock ~14 ~99 ~99 dirt
setblock ~14 ~99 ~100 dirt
setblock ~14 ~99 ~101 dirt
setblock ~14 ~99 ~102 dirt
setblock ~14 ~99 ~110 dirt
setblock ~14 ~99 ~111 dirt
setblock ~14 ~99 ~112 dirt
setblock ~14 ~99 ~113 dirt
setblock ~14 ~99 ~114 dirt
setblock ~14 ~99 ~115 dirt
setblock ~14 ~99 ~116 dirt
setblock ~14 ~99 ~117 dirt
setblock ~14 ~99 ~118 dirt
setblock ~14 ~99 ~119 dirt
setblock ~14 ~99 ~120 dirt
setblock ~14 ~99 ~121 dirt
setblock ~14 ~99 ~122 dirt
setblock ~14 ~99 ~123 dirt
setblock ~14 ~99 ~124 dirt
setblock ~14 ~99 ~125 dirt
setblock ~14 ~99 ~126 dirt
setblock ~14 ~99 ~127 dirt
setblock ~14 ~100 ~69 dirt
setblock ~14 ~100 ~70 dirt
setblock ~14 ~100 ~71 dirt
setblock ~14 ~100 ~72 dirt
setblock ~14 ~100 ~73 dirt
setblock ~14 ~100 ~74 dirt
setblock ~14 ~100 ~75 dirt
setblock ~14 ~100 ~76 dirt
setblock ~14 ~100 ~77 dirt
setblock ~14 ~100 ~78 dirt
setblock ~14 ~100 ~79 dirt
setblock ~14 ~100 ~80 dirt
setblock ~14 ~100 ~81 dirt
setblock ~14 ~100 ~82 dirt
setblock ~14 ~100 ~90 dirt
setblock ~14 ~100 ~91 dirt
setblock ~14 ~100 ~92 dirt
setblock ~14 ~100 ~96 dirt
setblock ~14 ~100 ~97 dirt
setblock ~14 ~100 ~98 dirt
setblock ~14 ~100 ~99 dirt
setblock ~14 ~100 ~100 dirt
setblock ~14 ~100 ~101 dirt
setblock ~14 ~100 ~102 dirt
setblock ~14 ~100 ~103 dirt
setblock ~14 ~100 ~110 dirt
setblock ~14 ~100 ~111 dirt
setblock ~14 ~100 ~112 dirt
setblock ~14 ~100 ~113 dirt
setblock ~14 ~100 ~114 dirt
setblock ~14 ~100 ~115 dirt
setblock ~14 ~100 ~116 dirt
setblock ~14 ~100 ~117 dirt
setblock ~14 ~100 ~118 dirt
setblock ~14 ~100 ~119 dirt
setblock ~14 ~100 ~120 dirt
setblock ~14 ~100 ~121 dirt
setblock ~14 ~100 ~122 dirt
setblock ~14 ~100 ~123 dirt
setblock ~14 ~100 ~124 dirt
setblock ~14 ~100 ~125 dirt
setblock ~14 ~100 ~126 dirt
setblock ~14 ~100 ~127 dirt
setblock ~14 ~100 ~128 dirt
setblock ~14 ~100 ~129 dirt
setblock ~14 ~100 ~130 dirt
setblock ~14 ~100 ~131 dirt
setblock ~14 ~101 ~69 grass_block
setblock ~14 ~101 ~70 grass_block
setblock ~14 ~101 ~71 grass_block
setblock ~14 ~101 ~72 grass_block
setblock ~14 ~101 ~73 dirt
setblock ~14 ~101 ~74 dirt
setblock ~14 ~101 ~75 dirt
setblock ~14 ~101 ~76 dirt
setblock ~14 ~101 ~77 dirt
setblock ~14 ~101 ~78 dirt
setblock ~14 ~101 ~79 dirt
setblock ~14 ~101 ~80 dirt
setblock ~14 ~101 ~81 dirt
setblock ~14 ~101 ~82 grass_block
setblock ~14 ~101 ~85 grass_block
setblock ~14 ~101 ~89 grass_block
setblock ~14 ~101 ~90 grass_block
setblock ~14 ~101 ~91 grass_block
setblock ~14 ~101 ~92 dirt
setblock ~14 ~101 ~93 dirt
setblock ~14 ~101 ~95 dirt
setblock ~14 ~101 ~96 dirt
setblock ~14 ~101 ~97 dirt
setblock ~14 ~101 ~98 dirt
setblock ~14 ~101 ~99 dirt
setblock ~14 ~101 ~100 dirt
setblock ~14 ~101 ~101 dirt
setblock ~14 ~101 ~102 dirt
setblock ~14 ~101 ~103 dirt
setblock ~14 ~101 ~109 dirt
setblock ~14 ~101 ~110 dirt
setblock ~14 ~101 ~111 dirt
setblock ~14 ~101 ~112 dirt
setblock ~14 ~101 ~113 dirt
setblock ~14 ~101 ~114 dirt
setblock ~14 ~101 ~115 dirt
setblock ~14 ~101 ~116 dirt
setblock ~14 ~101 ~117 dirt
setblock ~14 ~101 ~118 dirt
setblock ~14 ~101 ~119 dirt
setblock ~14 ~101 ~120 dirt
setblock ~14 ~101 ~121 dirt
setblock ~14 ~101 ~122 dirt
setblock ~14 ~101 ~123 dirt
setblock ~14 ~101 ~124 dirt
setblock ~14 ~101 ~125 grass_block
setblock ~14 ~101 ~126 grass_block
setblock ~14 ~101 ~127 grass_block
setblock ~14 ~101 ~128 grass_block
setblock ~14 ~101 ~129 grass_block
setblock ~14 ~101 ~130 grass_block
setblock ~14 ~101 ~131 grass_block
setblock ~14 ~102 ~70 short_grass
setblock ~14 ~102 ~72 short_grass
setblock ~14 ~102 ~85 short_grass
setblock ~14 ~102 ~125 short_grass
setblock ~14 ~102 ~127 short_grass
setblock ~14 ~102 ~128 fern
setblock ~14 ~114 ~101 dirt
setblock ~14 ~114 ~102 dirt
setblock ~14 ~114 ~119 dirt
setblock ~14 ~115 ~100 dirt
setblock ~14 ~115 ~101 dirt
setblock ~14 ~115 ~102 dirt
setblock ~14 ~115 ~103 dirt
setblock ~14 ~115 ~105 dirt
setblock ~14 ~115 ~119 dirt
setblock ~14 ~115 ~121 dirt
setblock ~14 ~116 ~100 dirt
setblock ~14 ~116 ~101 dirt
setblock ~14 ~116 ~102 dirt
setblock ~14 ~116 ~103 dirt
setblock ~14 ~116 ~105 dirt
setblock ~14 ~116 ~116 dirt
setblock ~14 ~116 ~117 dirt
setblock ~14 ~116 ~118 dirt
setblock ~14 ~116 ~119 dirt
setblock ~14 ~116 ~121 dirt
setblock ~14 ~116 ~122 dirt
setblock ~14 ~117 ~99 dirt
setblock ~14 ~117 ~100 dirt
setblock ~14 ~117 ~101 dirt
setblock ~14 ~117 ~102 dirt
setblock ~14 ~117 ~103 dirt
setblock ~14 ~117 ~104 dirt
setblock ~14 ~117 ~105 dirt
setblock ~14 ~117 ~106 dirt
setblock ~14 ~117 ~107 dirt
setblock ~14 ~117 ~115 dirt
setblock ~14 ~117 ~116 dirt
setblock ~14 ~117 ~117 dirt
setblock ~14 ~117 ~118 dirt
setblock ~14 ~117 ~119 dirt
setblock ~14 ~117 ~120 dirt
setblock ~14 ~117 ~121 dirt
setblock ~14 ~117 ~122 dirt
setblock ~14 ~118 ~75 dirt
setblock ~14 ~118 ~98 dirt
setblock ~14 ~118 ~99 dirt
setblock ~14 ~118 ~100 dirt
setblock ~14 ~118 ~101 dirt
setblock ~14 ~118 ~102 dirt
setblock ~14 ~118 ~103 dirt
setblock ~14 ~118 ~104 dirt
setblock ~14 ~118 ~105 dirt
setblock ~14 ~118 ~106 dirt
setblock ~14 ~118 ~107 dirt
setblock ~14 ~118 ~108 dirt
setblock ~14 ~118 ~114 dirt
setblock ~14 ~118 ~115 dirt
setblock ~14 ~118 ~116 dirt
setblock ~14 ~118 ~117 dirt
setblock ~14 ~118 ~118 dirt
setblock ~14 ~118 ~119 dirt
setblock ~14 ~118 ~120 dirt
setblock ~14 ~118 ~121 dirt
setblock ~14 ~118 ~122 dirt
setblock ~14 ~118 ~123 dirt
setblock ~14 ~118 ~124 dirt
setblock ~14 ~119 ~75 dirt
setblock ~14 ~119 ~76 dirt
setblock ~14 ~119 ~80 dirt
setblock ~14 ~119 ~95 dirt
setblock ~14 ~119 ~98 dirt
setblock ~14 ~119 ~99 dirt
setblock ~14 ~119 ~100 dirt
setblock ~14 ~119 ~101 dirt
setblock ~14 ~119 ~102 dirt
setblock ~14 ~119 ~103 dirt
setblock ~14 ~119 ~104 dirt
setblock ~14 ~119 ~105 dirt
setblock ~14 ~119 ~106 dirt
setblock ~14 ~119 ~107 dirt
setblock ~14 ~119 ~108 dirt
setblock ~14 ~119 ~113 dirt
setblock ~14 ~119 ~114 dirt
setblock ~14 ~119 ~115 dirt
setblock ~14 ~119 ~116 dirt
setblock ~14 ~119 ~117 dirt
setblock ~14 ~119 ~118 dirt
setblock ~14 ~119 ~119 dirt
setblock ~14 ~119 ~120 dirt
setblock ~14 ~119 ~121 dirt
setblock ~14 ~119 ~122 dirt
setblock ~14 ~119 ~123 dirt
setblock ~14 ~119 ~124 dirt
setblock ~14 ~120 ~74 dirt
setblock ~14 ~120 ~75 dirt
setblock ~14 ~120 ~76 dirt
setblock ~14 ~120 ~79 dirt
setblock ~14 ~120 ~80 dirt
setblock ~14 ~120 ~81 dirt
setblock ~14 ~120 ~93 dirt
setblock ~14 ~120 ~94 dirt
setblock ~14 ~120 ~95 dirt
setblock ~14 ~120 ~96 dirt
setblock ~14 ~120 ~97 dirt
setblock ~14 ~120 ~98 dirt
setblock ~14 ~120 ~99 dirt
setblock ~14 ~120 ~100 dirt
setblock ~14 ~120 ~101 dirt
setblock ~14 ~120 ~102 dirt
setblock ~14 ~120 ~103 dirt
setblock ~14 ~120 ~104 dirt
setblock ~14 ~120 ~105 dirt
setblock ~14 ~120 ~106 dirt
setblock ~14 ~120 ~107 dirt
setblock ~14 ~120 ~108 dirt
setblock ~14 ~120 ~109 dirt
setblock ~14 ~120 ~110 dirt
setblock ~14 ~120 ~111 dirt
setblock ~14 ~120 ~112 dirt
setblock ~14 ~120 ~113 dirt
setblock ~14 ~120 ~114 dirt
setblock ~14 ~120 ~115 dirt
setblock ~14 ~120 ~116 dirt
setblock ~14 ~120 ~117 dirt
setblock ~14 ~120 ~118 dirt
setblock ~14 ~120 ~119 dirt
setblock ~14 ~120 ~120 dirt
setblock ~14 ~120 ~121 dirt
setblock ~14 ~120 ~122 dirt
setblock ~14 ~120 ~123 dirt
setblock ~14 ~120 ~124 dirt
setblock ~14 ~121 ~73 dirt
setblock ~14 ~121 ~74 dirt
setblock ~14 ~121 ~75 dirt
setblock ~14 ~121 ~76 dirt
setblock ~14 ~121 ~77 dirt
setblock ~14 ~121 ~78 dirt
setblock ~14 ~121 ~79 dirt
setblock ~14 ~121 ~80 dirt
setblock ~14 ~121 ~81 dirt
setblock ~14 ~121 ~92 dirt
setblock ~14 ~121 ~93 dirt
setblock ~14 ~121 ~94 dirt
setblock ~14 ~121 ~95 dirt
setblock ~14 ~121 ~96 dirt
setblock ~14 ~121 ~97 dirt
setblock ~14 ~121 ~98 dirt
setblock ~14 ~121 ~99 dirt
setblock ~14 ~121 ~100 dirt
setblock ~14 ~121 ~101 dirt
setblock ~14 ~121 ~102 dirt
setblock ~14 ~121 ~103 dirt
setblock ~14 ~121 ~104 dirt
setblock ~14 ~121 ~105 dirt
setblock ~14 ~121 ~106 dirt
setblock ~14 ~121 ~107 dirt
setblock ~14 ~121 ~108 dirt
setblock ~14 ~121 ~109 dirt
setblock ~14 ~121 ~110 dirt
setblock ~14 ~121 ~111 dirt
setblock ~14 ~121 ~112 dirt
setblock ~14 ~121 ~113 dirt
setblock ~14 ~121 ~114 dirt
setblock ~14 ~121 ~115 dirt
setblock ~14 ~121 ~116 dirt
setblock ~14 ~121 ~117 dirt
setblock ~14 ~121 ~118 dirt
setblock ~14 ~121 ~119 dirt
setblock ~14 ~121 ~120 dirt
setblock ~14 ~121 ~121 dirt
setblock ~14 ~121 ~122 dirt
setblock ~14 ~121 ~123 dirt
setblock ~14 ~121 ~124 dirt
setblock ~14 ~122 ~73 dirt
setblock ~14 ~122 ~74 dirt
setblock ~14 ~122 ~75 dirt
setblock ~14 ~122 ~76 dirt
setblock ~14 ~122 ~77 dirt
setblock ~14 ~122 ~78 dirt
setblock ~14 ~122 ~79 dirt
setblock ~14 ~122 ~80 dirt
setblock ~14 ~122 ~81 dirt
setblock ~14 ~122 ~92 dirt
setblock ~14 ~122 ~93 dirt
setblock ~14 ~122 ~94 dirt
setblock ~14 ~122 ~95 dirt
setblock ~14 ~122 ~96 dirt
setblock ~14 ~122 ~97 dirt
setblock ~14 ~122 ~98 dirt
setblock ~14 ~122 ~99 dirt
setblock ~14 ~122 ~100 dirt
setblock ~14 ~122 ~101 dirt
setblock ~14 ~122 ~102 dirt
setblock ~14 ~122 ~103 dirt
setblock ~14 ~122 ~104 dirt
setblock ~14 ~122 ~105 dirt
setblock ~14 ~122 ~106 dirt
setblock ~14 ~122 ~107 dirt
setblock ~14 ~122 ~108 dirt
setblock ~14 ~122 ~109 dirt
setblock ~14 ~122 ~110 dirt
setblock ~14 ~122 ~111 dirt
setblock ~14 ~122 ~112 dirt
setblock ~14 ~122 ~113 dirt
setblock ~14 ~122 ~114 dirt
setblock ~14 ~122 ~115 dirt
setblock ~14 ~122 ~116 dirt
setblock ~14 ~122 ~117 dirt
setblock ~14 ~122 ~118 dirt
setblock ~14 ~122 ~119 dirt
setblock ~14 ~122 ~120 dirt
setblock ~14 ~122 ~121 dirt
setblock ~14 ~122 ~122 dirt
setblock ~14 ~122 ~123 dirt
setblock ~14 ~122 ~124 dirt
setblock ~14 ~123 ~73 grass_block
setblock ~14 ~123 ~74 grass_block
setblock ~14 ~123 ~75 grass_block
setblock ~14 ~123 ~76 grass_block
setblock ~14 ~123 ~77 dirt
setblock ~14 ~123 ~78 dirt
setblock ~14 ~123 ~79 dirt
setblock ~14 ~123 ~80 dirt
setblock ~14 ~123 ~81 dirt
setblock ~14 ~123 ~92 dirt
setblock ~14 ~123 ~93 dirt
setblock ~14 ~123 ~94 dirt
setblock ~14 ~123 ~95 dirt
setblock ~14 ~123 ~96 dirt
setblock ~14 ~123 ~97 dirt
setblock ~14 ~123 ~98 dirt
setblock ~14 ~123 ~99 dirt
setblock ~14 ~123 ~100 dirt
setblock ~14 ~123 ~101 dirt
setblock ~14 ~123 ~102 dirt
setblock ~14 ~123 ~103 dirt
setblock ~14 ~123 ~104 dirt
setblock ~14 ~123 ~105 dirt
setblock ~14 ~123 ~106 dirt
setblock ~14 ~123 ~107 dirt
setblock ~14 ~123 ~108 dirt
setblock ~14 ~123 ~109 dirt
setblock ~14 ~123 ~110 dirt
setblock ~14 ~123 ~111 dirt
setblock ~14 ~123 ~112 dirt
setblock ~14 ~123 ~113 dirt
setblock ~14 ~123 ~114 dirt
setblock ~14 ~123 ~115 dirt
setblock ~14 ~123 ~116 dirt
setblock ~14 ~123 ~117 dirt
setblock ~14 ~123 ~118 dirt
setblock ~14 ~123 ~119 dirt
setblock ~14 ~123 ~120 dirt
setblock ~14 ~123 ~121 dirt
setblock ~14 ~123 ~122 dirt
setblock ~14 ~123 ~123 dirt
setblock ~14 ~123 ~124 dirt
setblock ~14 ~124 ~75 short_grass
setblock ~14 ~124 ~77 grass_block
setblock ~14 ~124 ~78 grass_block
setblock ~14 ~124 ~79 grass_block
setblock ~14 ~124 ~80 grass_block
setblock ~14 ~124 ~81 grass_block
setblock ~14 ~124 ~92 grass_block
setblock ~14 ~124 ~93 grass_block
setblock ~14 ~124 ~94 grass_block
setblock ~14 ~124 ~95 grass_block
setblock ~14 ~124 ~96 grass_block
setblock ~14 ~124 ~97 grass_block
setblock ~14 ~124 ~98 grass_block
setblock ~14 ~124 ~99 grass_block
setblock ~14 ~124 ~100 grass_block
setblock ~14 ~124 ~101 grass_block
setblock ~14 ~124 ~102 grass_block
setblock ~14 ~124 ~103 grass_block
setblock ~14 ~124 ~104 grass_block
setblock ~14 ~124 ~105 grass_block
setblock ~14 ~124 ~106 dirt
setblock ~14 ~124 ~107 dirt
setblock ~14 ~124 ~108 dirt
setblock ~14 ~124 ~109 dirt
setblock ~14 ~124 ~110 dirt
setblock ~14 ~124 ~111 dirt
setblock ~14 ~124 ~112 dirt
setblock ~14 ~124 ~113 dirt
setblock ~14 ~124 ~114 dirt
setblock ~14 ~124 ~115 dirt
setblock ~14 ~124 ~116 dirt
setblock ~14 ~124 ~117 dirt
setblock ~14 ~124 ~118 dirt
setblock ~14 ~124 ~119 dirt
setblock ~14 ~124 ~120 dirt
setblock ~14 ~124 ~121 dirt
setblock ~14 ~124 ~122 dirt
setblock ~14 ~124 ~123 dirt
setblock ~14 ~124 ~124 dirt
setblock ~14 ~125 ~95 poppy
setblock ~14 ~125 ~101 fern
setblock ~14 ~125 ~102 short_grass
setblock ~14 ~125 ~105 short_grass
setblock ~14 ~125 ~106 grass_block
setblock ~14 ~125 ~107 grass_block
setblock ~14 ~125 ~108 grass_block
setblock ~14 ~125 ~109 grass_block
setblock ~14 ~125 ~110 grass_block
setblock ~14 ~125 ~111 grass_block
setblock ~14 ~125 ~112 grass_block
setblock ~14 ~125 ~113 grass_block
setblock ~14 ~125 ~114 grass_block
setblock ~14 ~125 ~115 grass_block
setblock ~14 ~125 ~116 dirt
setblock ~14 ~125 ~117 dirt
setblock ~14 ~125 ~118 dirt
setblock ~14 ~125 ~119 dirt
setblock ~14 ~125 ~120 dirt
setblock ~14 ~125 ~121 dirt
setblock ~14 ~125 ~122 dirt
setblock ~14 ~125 ~123 dirt
setblock ~14 ~125 ~124 dirt
setblock ~14 ~126 ~106 poppy
setblock ~14 ~126 ~111 poppy
setblock ~14 ~126 ~112 short_grass
setblock ~14 ~126 ~114 short_grass
setblock ~14 ~126 ~116 grass_block
setblock ~14 ~126 ~117 grass_block
setblock ~14 ~126 ~118 grass_block
setblock ~14 ~126 ~119 grass_block
setblock ~14 ~126 ~120 grass_block
setblock ~14 ~126 ~121 grass_block
setblock ~14 ~126 ~122 grass_block
setblock ~14 ~126 ~123 grass_block
setblock ~14 ~126 ~124 grass_block
setblock ~14 ~127 ~123 short_grass
setblock ~14 ~127 ~124 short_grass
setblock ~15 ~85 ~120 dirt
setblock ~15 ~86 ~120 dirt
setblock ~15 ~86 ~121 dirt
setblock ~15 ~87 ~119 dirt
setblock ~15 ~87 ~120 dirt
setblock ~15 ~87 ~121 dirt
setblock ~15 ~88 ~119 dirt
setblock ~15 ~88 ~120 dirt
setblock ~15 ~88 ~121 dirt
setblock ~15 ~89 ~118 dirt
setblock ~15 ~89 ~119 dirt
setblock ~15 ~89 ~120 dirt
setblock ~15 ~89 ~121 dirt
setblock ~15 ~89 ~122 dirt
setblock ~15 ~90 ~118 dirt
setblock ~15 ~90 ~119 dirt
setblock ~15 ~90 ~120 dirt
setblock ~15 ~90 ~121 dirt
setblock ~15 ~90 ~122 dirt
setblock ~15 ~91 ~117 dirt
setblock ~15 ~91 ~118 dirt
setblock ~15 ~91 ~119 dirt
setblock ~15 ~91 ~120 dirt
setblock ~15 ~91 ~121 dirt
setblock ~15 ~91 ~122 dirt
setblock ~15 ~92 ~116 dirt
setblock ~15 ~92 ~117 dirt
setblock ~15 ~92 ~118 dirt
setblock ~15 ~92 ~119 dirt
setblock ~15 ~92 ~120 dirt
setblock ~15 ~92 ~121 dirt
setblock ~15 ~92 ~122 dirt
setblock ~15 ~92 ~124 dirt
setblock ~15 ~92 ~125 dirt
setblock ~15 ~93 ~115 dirt
setblock ~15 ~93 ~116 dirt
setblock ~15 ~93 ~117 dirt
setblock ~15 ~93 ~118 dirt
setblock ~15 ~93 ~119 dirt
setblock ~15 ~93 ~120 dirt
setblock ~15 ~93 ~121 dirt
setblock ~15 ~93 ~122 dirt
setblock ~15 ~93 ~123 dirt
setblock ~15 ~93 ~124 dirt
setblock ~15 ~93 ~125 dirt
setblock ~15 ~93 ~126 dirt
setblock ~15 ~94 ~77 dirt
setblock ~15 ~94 ~78 dirt
setblock ~15 ~94 ~114 dirt
setblock ~15 ~94 ~115 dirt
setblock ~15 ~94 ~116 dirt
setblock ~15 ~94 ~117 dirt
setblock ~15 ~94 ~118 dirt
setblock ~15 ~94 ~119 dirt
setblock ~15 ~94 ~120 dirt
setblock ~15 ~94 ~121 dirt
setblock ~15 ~94 ~122 dirt
setblock ~15 ~94 ~123 dirt
setblock ~15 ~94 ~124 dirt
setblock ~15 ~94 ~125 dirt
setblock ~15 ~94 ~126 dirt
setblock ~15 ~95 ~77 dirt
setblock ~15 ~95 ~78 dirt
setblock ~15 ~95 ~79 dirt
setblock ~15 ~95 ~97 dirt
setblock ~15 ~95 ~99 dirt
setblock ~15 ~95 ~100 dirt
setblock ~15 ~95 ~113 dirt
setblock ~15 ~95 ~114 dirt
setblock ~15 ~95 ~115 dirt
setblock ~15 ~95 ~116 dirt
setblock ~15 ~95 ~117 dirt
setblock ~15 ~95 ~118 dirt
setblock ~15 ~95 ~119 dirt
setblock ~15 ~95 ~120 dirt
setblock ~15 ~95 ~121 dirt
setblock ~15 ~95 ~122 dirt
setblock ~15 ~95 ~123 dirt
setblock ~15 ~95 ~124 dirt
setblock ~15 ~95 ~125 dirt
setblock ~15 ~95 ~126 dirt
setblock ~15 ~96 ~72 dirt
setblock ~15 ~96 ~74 dirt
setblock ~15 ~96 ~75 dirt
setblock ~15 ~96 ~76 dirt
setblock ~15 ~96 ~77 dirt
setblock ~15 ~96 ~78 dirt
setblock ~15 ~96 ~79 dirt
setblock ~15 ~96 ~80 dirt
setblock ~15 ~96 ~97 dirt
setblock ~15 ~96 ~98 dirt
setblock ~15 ~96 ~99 dirt
setblock ~15 ~96 ~100 dirt
setblock ~15 ~96 ~101 dirt
setblock ~15 ~96 ~112 dirt
setblock ~15 ~96 ~113 dirt
setblock ~15 ~96 ~114 dirt
setblock ~15 ~96 ~115 dirt
setblock ~15 ~96 ~116 dirt
setblock ~15 ~96 ~117 dirt
setblock ~15 ~96 ~118 dirt
setblock ~15 ~96 ~119 dirt
setblock ~15 ~96 ~120 dirt
setblock ~15 ~96 ~121 dirt
setblock ~15 ~96 ~122 dirt
setblock ~15 ~96 ~123 dirt
setblock ~15 ~96 ~124 dirt
setblock ~15 ~96 ~125 dirt
setblock ~15 ~96 ~126 dirt
setblock ~15 ~97 ~71 dirt
setblock ~15 ~97 ~72 dirt
setblock ~15 ~97 ~73 dirt
setblock ~15 ~97 ~74 dirt
setblock ~15 ~97 ~75 dirt
setblock ~15 ~97 ~76 dirt
setblock ~15 ~97 ~77 dirt
setblock ~15 ~97 ~78 dirt
setblock ~15 ~97 ~79 dirt
setblock ~15 ~97 ~80 dirt
setblock ~15 ~97 ~82 dirt
setblock ~15 ~97 ~92 dirt
setblock ~15 ~97 ~96 dirt
setblock ~15 ~97 ~97 dirt
setblock ~15 ~97 ~98 dirt
setblock ~15 ~97 ~99 dirt
setblock ~15 ~97 ~100 dirt
setblock ~15 ~97 ~101 dirt
setblock ~15 ~97 ~102 dirt
setblock ~15 ~97 ~111 dirt
setblock ~15 ~97 ~112 dirt
setblock ~15 ~97 ~113 dirt
setblock ~15 ~97 ~114 dirt
setblock ~15 ~97 ~115 dirt
setblock ~15 ~97 ~116 dirt
setblock ~15 ~97 ~117 dirt
setblock ~15 ~97 ~118 dirt
setblock ~15 ~97 ~119 dirt
setblock ~15 ~97 ~120 dirt
setblock ~15 ~97 ~121 dirt
setblock ~15 ~97 ~122 dirt
setblock ~15 ~97 ~123 dirt
setblock ~15 ~97 ~124 dirt
setblock ~15 ~97 ~125 dirt
setblock ~15 ~97 ~126 dirt
setblock ~15 ~97 ~127 dirt
setblock ~15 ~98 ~70 dirt
setblock ~15 ~98 ~71 dirt
setblock ~15 ~98 ~72 dirt
setblock ~15 ~98 ~73 dirt
setblock ~15 ~98 ~74 dirt
setblock ~15 ~98 ~75 dirt
setblock ~15 ~98 ~76 dirt
setblock ~15 ~98 ~77 dirt
setblock ~15 ~98 ~78 dirt
setblock ~15 ~98 ~79 dirt
setblock ~15 ~98 ~80 dirt
setblock ~15 ~98 ~82 dirt
setblock ~15 ~98 ~91 dirt
setblock ~15 ~98 ~92 dirt
setblock ~15 ~98 ~96 dirt
setblock ~15 ~98 ~97 dirt
setblock ~15 ~98 ~98 dirt
setblock ~15 ~98 ~99 dirt
setblock ~15 ~98 ~100 dirt
setblock ~15 ~98 ~101 dirt
setblock ~15 ~98 ~102 dirt
setblock ~15 ~98 ~111 dirt
setblock ~15 ~98 ~112 dirt
setblock ~15 ~98 ~113 dirt
setblock ~15 ~98 ~114 dirt
setblock ~15 ~98 ~115 dirt
setblock ~15 ~98 ~116 dirt
setblock ~15 ~98 ~117 dirt
setblock ~15 ~98 ~118 dirt
setblock ~15 ~98 ~119 dirt
setblock ~15 ~98 ~120 dirt
setblock ~15 ~98 ~121 dirt
setblock ~15 ~98 ~122 dirt
setblock ~15 ~98 ~123 dirt
setblock ~15 ~98 ~124 dirt
setblock ~15 ~98 ~125 dirt
setblock ~15 ~98 ~126 dirt
setblock ~15 ~98 ~127 dirt
setblock ~15 ~98 ~128 dirt
setblock ~15 ~98 ~130 dirt
setblock ~15 ~99 ~69 dirt
setblock ~15 ~99 ~70 dirt
setblock ~15 ~99 ~71 dirt
setblock ~15 ~99 ~72 dirt
setblock ~15 ~99 ~73 dirt
setblock ~15 ~99 ~74 dirt
setblock ~15 ~99 ~75 dirt
setblock ~15 ~99 ~76 dirt
setblock ~15 ~99 ~77 dirt
setblock ~15 ~99 ~78 dirt
setblock ~15 ~99 ~79 dirt
setblock ~15 ~99 ~80 dirt
setblock ~15 ~99 ~81 dirt
setblock ~15 ~99 ~82 dirt
setblock ~15 ~99 ~83 dirt
setblock ~15 ~99 ~90 dirt
setblock ~15 ~99 ~91 dirt
setblock ~15 ~99 ~92 dirt
setblock ~15 ~99 ~93 dirt
setblock ~15 ~99 ~96 dirt
setblock ~15 ~99 ~97 dirt
setblock ~15 ~99 ~98 dirt
setblock ~15 ~99 ~99 dirt
setblock ~15 ~99 ~100 dirt
setblock ~15 ~99 ~101 dirt
setblock ~15 ~99 ~102 dirt
setblock ~15 ~99 ~103 dirt
setblock ~15 ~99 ~104 dirt
setblock ~15 ~99 ~111 dirt
setblock ~15 ~99 ~112 dirt
setblock ~15 ~99 ~113 dirt
setblock ~15 ~99 ~114 dirt
setblock ~15 ~99 ~115 dirt
setblock ~15 ~99 ~116 dirt
setblock ~15 ~99 ~117 dirt
setblock ~15 ~99 ~118 dirt
setblock ~15 ~99 ~119 dirt
setblock ~15 ~99 ~120 dirt
setblock ~15 ~99 ~121 dirt
setblock ~15 ~99 ~122 dirt
setblock ~15 ~99 ~123 dirt
setblock ~15 ~99 ~124 dirt
setblock ~15 ~99 ~125 dirt
setblock ~15 ~99 ~126 dirt
setblock ~15 ~99 ~127 dirt
setblock ~15 ~99 ~128 dirt
setblock ~15 ~99 ~129 dirt
setblock ~15 ~99 ~130 dirt
setblock ~15 ~99 ~131 dirt
setblock ~15 ~100 ~69 dirt
setblock ~15 ~100 ~70 dirt
setblock ~15 ~100 ~71 dirt
setblock ~15 ~100 ~72 dirt
setblock ~15 ~100 ~73 dirt
setblock ~15 ~100 ~74 dirt
setblock ~15 ~100 ~75 dirt
setblock ~15 ~100 ~76 dirt
setblock ~15 ~100 ~77 dirt
setblock ~15 ~100 ~78 dirt
setblock ~15 ~100 ~79 dirt
setblock ~15 ~100 ~80 dirt
setblock ~15 ~100 ~81 dirt
setblock ~15 ~100 ~82 dirt
setblock ~15 ~100 ~83 dirt
setblock ~15 ~100 ~84 dirt
setblock ~15 ~100 ~85 dirt
setblock ~15 ~100 ~89 dirt
setblock ~15 ~100 ~90 dirt
setblock ~15 ~100 ~91 dirt
setblock ~15 ~100 ~92 dirt
setblock ~15 ~100 ~93 dirt
setblock ~15 ~100 ~94 dirt
setblock ~15 ~100 ~95 dirt
setblock ~15 ~100 ~96 dirt
setblock ~15 ~100 ~97 dirt
setblock ~15 ~100 ~98 dirt
setblock ~15 ~100 ~99 dirt
setblock ~15 ~100 ~100 dirt
setblock ~15 ~100 ~101 dirt
setblock ~15 ~100 ~102 dirt
setblock ~15 ~100 ~103 dirt
setblock ~15 ~100 ~104 dirt
setblock ~15 ~100 ~110 dirt
setblock ~15 ~100 ~111 dirt
setblock ~15 ~100 ~112 dirt
setblock ~15 ~100 ~113 dirt
setblock ~15 ~100 ~114 dirt
setblock ~15 ~100 ~115 dirt
setblock ~15 ~100 ~116 dirt
setblock ~15 ~100 ~117 dirt
setblock ~15 ~100 ~118 dirt
setblock ~15 ~100 ~119 dirt
setblock ~15 ~100 ~120 dirt
setblock ~15 ~100 ~121 dirt
setblock ~15 ~100 ~122 dirt
setblock ~15 ~100 ~123 dirt
setblock ~15 ~100 ~124 dirt
setblock ~15 ~100 ~125 dirt
setblock ~15 ~100 ~126 dirt
setblock ~15 ~100 ~127 dirt
setblock ~15 ~100 ~128 dirt
setblock ~15 ~100 ~129 dirt
setblock ~15 ~100 ~130 dirt
setblock ~15 ~100 ~131 dirt
setblock ~15 ~100 ~132 dirt
setblock ~15 ~101 ~69 grass_block
setblock ~15 ~101 ~70 grass_block
setblock ~15 ~101 ~71 grass_block
setblock ~15 ~101 ~72 grass_block
setblock ~15 ~101 ~73 dirt
setblock ~15 ~101 ~74 dirt
setblock ~15 ~101 ~75 dirt
setblock ~15 ~101 ~76 dirt
setblock ~15 ~101 ~77 dirt
setblock ~15 ~101 ~78 dirt
setblock ~15 ~101 ~79 dirt
setblock ~15 ~101 ~80 dirt
setblock ~15 ~101 ~81 dirt
setblock ~15 ~101 ~82 dirt
setblock ~15 ~101 ~83 dirt
setblock ~15 ~101 ~84 dirt
setblock ~15 ~101 ~85 grass_block
setblock ~15 ~101 ~86 dirt
setblock ~15 ~101 ~87 dirt
setblock ~15 ~101 ~88 grass_block
setblock ~15 ~101 ~89 grass_block
setblock ~15 ~101 ~90 grass_block
setblock ~15 ~101 ~91 dirt
setblock ~15 ~101 ~92 dirt
setblock ~15 ~101 ~93 dirt
setblock ~15 ~101 ~94 dirt
setblock ~15 ~101 ~95 dirt
setblock ~15 ~101 ~96 dirt
setblock ~15 ~101 ~97 dirt
setblock ~15 ~101 ~98 dirt
setblock ~15 ~101 ~99 dirt
setblock ~15 ~101 ~100 dirt
setblock ~15 ~101 ~101 dirt
setblock ~15 ~101 ~102 dirt
setblock ~15 ~101 ~103 dirt
setblock ~15 ~101 ~104 dirt
setblock ~15 ~101 ~105 dirt
setblock ~15 ~101 ~109 dirt
setblock ~15 ~101 ~110 dirt
setblock ~15 ~101 ~111 dirt
setblock ~15 ~101 ~112 dirt
setblock ~15 ~101 ~113 dirt
setblock ~15 ~101 ~114 dirt
setblock ~15 ~101 ~115 dirt
setblock ~15 ~101 ~116 dirt
setblock ~15 ~101 ~117 dirt
setblock ~15 ~101 ~118 dirt
setblock ~15 ~101 ~119 dirt
setblock ~15 ~101 ~120 dirt
setblock ~15 ~101 ~121 dirt
setblock ~15 ~101 ~122 dirt
setblock ~15 ~101 ~123 dirt
setblock ~15 ~101 ~124 dirt
setblock ~15 ~101 ~125 dirt
setblock ~15 ~101 ~126 dirt
setblock ~15 ~101 ~127 dirt
setblock ~15 ~101 ~128 grass_block
setblock ~15 ~101 ~129 grass_block
setblock ~15 ~101 ~130 grass_block
setblock ~15 ~101 ~131 grass_block
setblock ~15 ~101 ~132 grass_block
setblock ~15 ~102 ~72 short_grass
setblock ~15 ~102 ~90 short_grass
setblock ~15 ~102 ~128 short_grass
setblock ~15 ~112 ~101 dirt
setblock ~15 ~112 ~119 dirt
setblock ~15 ~113 ~101 dirt
setblock ~15 ~113 ~102 dirt
setblock ~15 ~113 ~107 dirt
setblock ~15 ~113 ~119 dirt
setblock ~15 ~114 ~100 dirt
setblock ~15 ~114 ~101 dirt
setblock ~15 ~114 ~102 dirt
setblock ~15 ~114 ~103 dirt
setblock ~15 ~114 ~105 dirt
setblock ~15 ~114 ~107 dirt
setblock ~15 ~114 ~118 dirt
setblock ~15 ~114 ~119 dirt
setblock ~15 ~114 ~120 dirt
setblock ~15 ~114 ~121 dirt
setblock ~15 ~115 ~95 dirt
setblock ~15 ~115 ~99 dirt
setblock ~15 ~115 ~100 dirt
setblock ~15 ~115 ~101 dirt
setblock ~15 ~115 ~102 dirt
setblock ~15 ~115 ~103 dirt
setblock ~15 ~115 ~104 dirt
setblock ~15 ~115 ~105 dirt
setblock ~15 ~115 ~106 dirt
setblock ~15 ~115 ~107 dirt
setblock ~15 ~115 ~116 dirt
setblock ~15 ~115 ~117 dirt
setblock ~15 ~115 ~118 dirt
setblock ~15 ~115 ~119 dirt
setblock ~15 ~115 ~120 dirt
setblock ~15 ~115 ~121 dirt
setblock ~15 ~115 ~122 dirt
setblock ~15 ~115 ~124 dirt
setblock ~15 ~116 ~80 dirt
setblock ~15 ~116 ~95 dirt
setblock ~15 ~116 ~99 dirt
setblock ~15 ~116 ~100 dirt
setblock ~15 ~116 ~101 dirt
setblock ~15 ~116 ~102 dirt
setblock ~15 ~116 ~103 dirt
setblock ~15 ~116 ~104 dirt
setblock ~15 ~116 ~105 dirt
setblock ~15 ~116 ~106 dirt
setblock ~15 ~116 ~107 dirt
setblock ~15 ~116 ~108 dirt
setblock ~15 ~116 ~113 dirt
setblock ~15 ~116 ~115 dirt
setblock ~15 ~116 ~116 dirt
setblock ~15 ~116 ~117 dirt
setblock ~15 ~116 ~118 dirt
setblock ~15 ~116 ~119 dirt
setblock ~15 ~116 ~120 dirt
setblock ~15 ~116 ~121 dirt
setblock ~15 ~116 ~122 dirt
setblock ~15 ~116 ~123 dirt
setblock ~15 ~116 ~124 dirt
setblock ~15 ~117 ~75 dirt
setblock ~15 ~117 ~80 dirt
setblock ~15 ~117 ~81 dirt
setblock ~15 ~117 ~95 dirt
setblock ~15 ~117 ~96 dirt
setblock ~15 ~117 ~98 dirt
setblock ~15 ~117 ~99 dirt
setblock ~15 ~117 ~100 dirt
setblock ~15 ~117 ~101 dirt
setblock ~15 ~117 ~102 dirt
setblock ~15 ~117 ~103 dirt
setblock ~15 ~117 ~104 dirt
setblock ~15 ~117 ~105 dirt
setblock ~15 ~117 ~106 dirt
setblock ~15 ~117 ~107 dirt
setblock ~15 ~117 ~108 dirt
setblock ~15 ~117 ~112 dirt
setblock ~15 ~117 ~113 dirt
setblock ~15 ~117 ~114 dirt
setblock ~15 ~117 ~115 dirt
setblock ~15 ~117 ~116 dirt
setblock ~15 ~117 ~117 dirt
setblock ~15 ~117 ~118 dirt
setblock ~15 ~117 ~119 dirt
setblock ~15 ~117 ~120 dirt
setblock ~15 ~117 ~121 dirt
setblock ~15 ~117 ~122 dirt
setblock ~15 ~117 ~123 dirt
setblock ~15 ~117 ~124 dirt
setblock ~15 ~118 ~74 dirt
setblock ~15 ~118 ~75 dirt
setblock ~15 ~118 ~76 dirt
setblock ~15 ~118 ~77 dirt
setblock ~15 ~118 ~78 dirt
setblock ~15 ~118 ~80 dirt
setblock ~15 ~118 ~81 dirt
setblock ~15 ~118 ~93 dirt
setblock ~15 ~118 ~95 dirt
setblock ~15 ~118 ~96 dirt
setblock ~15 ~118 ~97 dirt
setblock ~15 ~118 ~98 dirt
setblock ~15 ~118 ~99 dirt
setblock ~15 ~118 ~100 dirt
setblock ~15 ~118 ~101 dirt
setblock ~15 ~118 ~102 dirt
setblock ~15 ~118 ~103 dirt
setblock ~15 ~118 ~104 dirt
setblock ~15 ~118 ~105 dirt
setblock ~15 ~118 ~106 dirt
setblock ~15 ~118 ~107 dirt
setblock ~15 ~118 ~108 dirt
setblock ~15 ~118 ~109 dirt
setblock ~15 ~118 ~111 dirt
setblock ~15 ~118 ~112 dirt
setblock ~15 ~118 ~113 dirt
setblock ~15 ~118 ~114 dirt
setblock ~15 ~118 ~115 dirt
setblock ~15 ~118 ~116 dirt
setblock ~15 ~118 ~117 dirt
setblock ~15 ~118 ~118 dirt
setblock ~15 ~118 ~119 dirt
setblock ~15 ~118 ~120 dirt
setblock ~15 ~118 ~121 dirt
setblock ~15 ~118 ~122 dirt
setblock ~15 ~118 ~123 dirt
setblock ~15 ~118 ~124 dirt
setblock ~15 ~118 ~125 dirt
setblock ~15 ~119 ~74 dirt
setblock ~15 ~119 ~75 dirt
setblock ~15 ~119 ~76 dirt
setblock ~15 ~119 ~77 dirt
setblock ~15 ~119 ~78 dirt
setblock ~15 ~119 ~79 dirt
setblock ~15 ~119 ~80 dirt
setblock ~15 ~119 ~81 dirt
setblock ~15 ~119 ~92 dirt
setblock ~15 ~119 ~93 dirt
setblock ~15 ~119 ~94 dirt
setblock ~15 ~119 ~95 dirt
setblock ~15 ~119 ~96 dirt
setblock ~15 ~119 ~97 dirt
