setblock ~84 ~124 ~189 dirt
setblock ~84 ~124 ~190 dirt
setblock ~84 ~124 ~191 dirt
setblock ~84 ~124 ~192 dirt
setblock ~84 ~124 ~193 dirt
setblock ~84 ~124 ~194 dirt
setblock ~84 ~124 ~195 dirt
setblock ~84 ~124 ~196 dirt
setblock ~84 ~124 ~197 grass_block
setblock ~84 ~124 ~198 grass_block
setblock ~84 ~125 ~1 short_grass
setblock ~84 ~125 ~5 grass_block
setblock ~84 ~125 ~6 grass_block
setblock ~84 ~125 ~7 grass_block
setblock ~84 ~125 ~8 grass_block
setblock ~84 ~125 ~9 dirt
setblock ~84 ~125 ~10 dirt
setblock ~84 ~125 ~11 dirt
setblock ~84 ~125 ~12 dirt
setblock ~84 ~125 ~13 dirt
setblock ~84 ~125 ~14 dirt
setblock ~84 ~125 ~15 dirt
setblock ~84 ~125 ~16 dirt
setblock ~84 ~125 ~17 dirt
setblock ~84 ~125 ~18 grass_block
setblock ~84 ~125 ~19 grass_block
setblock ~84 ~125 ~20 grass_block
setblock ~84 ~125 ~21 grass_block
setblock ~84 ~125 ~22 grass_block
setblock ~84 ~125 ~23 grass_block
setblock ~84 ~125 ~24 grass_block
setblock ~84 ~125 ~25 grass_block
setblock ~84 ~125 ~26 grass_block
setblock ~84 ~125 ~27 grass_block
setblock ~84 ~125 ~28 grass_block
setblock ~84 ~125 ~29 grass_block
setblock ~84 ~125 ~30 grass_block
setblock ~84 ~125 ~31 grass_block
setblock ~84 ~125 ~32 grass_block
setblock ~84 ~125 ~33 grass_block
setblock ~84 ~125 ~34 grass_block
setblock ~84 ~125 ~35 grass_block
setblock ~84 ~125 ~36 grass_block
setblock ~84 ~125 ~37 short_grass
setblock ~84 ~125 ~41 short_grass
setblock ~84 ~125 ~43 short_grass
setblock ~84 ~125 ~50 short_grass
setblock ~84 ~125 ~68 short_grass
setblock ~84 ~125 ~69 short_grass
setblock ~84 ~125 ~72 short_grass
setblock ~84 ~125 ~75 short_grass
setblock ~84 ~125 ~78 short_grass
setblock ~84 ~125 ~79 short_grass
setblock ~84 ~125 ~81 grass_block
setblock ~84 ~125 ~82 grass_block
setblock ~84 ~125 ~83 grass_block
setblock ~84 ~125 ~84 grass_block
setblock ~84 ~125 ~85 grass_block
setblock ~84 ~125 ~86 grass_block
setblock ~84 ~125 ~87 dirt
setblock ~84 ~125 ~88 dirt
setblock ~84 ~125 ~89 dirt
setblock ~84 ~125 ~90 dirt
setblock ~84 ~125 ~91 dirt
setblock ~84 ~125 ~92 dirt
setblock ~84 ~125 ~93 dirt
setblock ~84 ~125 ~94 dirt
setblock ~84 ~125 ~95 dirt
setblock ~84 ~125 ~96 dirt
setblock ~84 ~125 ~97 dirt
setblock ~84 ~125 ~98 dirt
setblock ~84 ~125 ~99 grass_block
setblock ~84 ~125 ~100 grass_block
setblock ~84 ~125 ~101 grass_block
setblock ~84 ~125 ~102 grass_block
setblock ~84 ~125 ~103 dirt
setblock ~84 ~125 ~104 dirt
setblock ~84 ~125 ~105 dirt
setblock ~84 ~125 ~106 dirt
setblock ~84 ~125 ~107 dirt
setblock ~84 ~125 ~108 dirt
setblock ~84 ~125 ~109 dirt
setblock ~84 ~125 ~110 dirt
setblock ~84 ~125 ~111 dirt
setblock ~84 ~125 ~112 dirt
setblock ~84 ~125 ~113 dirt
setblock ~84 ~125 ~114 grass_block
setblock ~84 ~125 ~115 grass_block
setblock ~84 ~125 ~116 grass_block
setblock ~84 ~125 ~117 grass_block
setblock ~84 ~125 ~118 grass_block
setblock ~84 ~125 ~119 grass_block
setblock ~84 ~125 ~122 poppy
setblock ~84 ~125 ~123 grass_block
setblock ~84 ~125 ~124 grass_block
setblock ~84 ~125 ~125 grass_block
setblock ~84 ~125 ~126 grass_block
setblock ~84 ~125 ~127 grass_block
setblock ~84 ~125 ~128 grass_block
setblock ~84 ~125 ~129 grass_block
setblock ~84 ~125 ~130 grass_block
setblock ~84 ~125 ~131 grass_block
setblock ~84 ~125 ~132 grass_block
setblock ~84 ~125 ~133 grass_block
setblock ~84 ~125 ~134 dirt
setblock ~84 ~125 ~135 dirt
setblock ~84 ~125 ~136 dirt
setblock ~84 ~125 ~137 dirt
setblock ~84 ~125 ~138 dirt
setblock ~84 ~125 ~139 dirt
setblock ~84 ~125 ~140 dirt
setblock ~84 ~125 ~141 dirt
setblock ~84 ~125 ~142 grass_block
setblock ~84 ~125 ~143 grass_block
setblock ~84 ~125 ~144 grass_block
setblock ~84 ~125 ~154 grass_block
setblock ~84 ~125 ~155 grass_block
setblock ~84 ~125 ~156 dirt
setblock ~84 ~125 ~157 dirt
setblock ~84 ~125 ~158 dirt
setblock ~84 ~125 ~159 dirt
setblock ~84 ~125 ~160 dirt
setblock ~84 ~125 ~161 dirt
setblock ~84 ~125 ~162 dirt
setblock ~84 ~125 ~163 dirt
setblock ~84 ~125 ~164 dirt
setblock ~84 ~125 ~165 dirt
setblock ~84 ~125 ~166 dirt
setblock ~84 ~125 ~167 dirt
setblock ~84 ~125 ~168 dirt
setblock ~84 ~125 ~169 dirt
setblock ~84 ~125 ~170 grass_block
setblock ~84 ~125 ~171 grass_block
setblock ~84 ~125 ~172 grass_block
setblock ~84 ~125 ~173 grass_block
setblock ~84 ~125 ~174 grass_block
setblock ~84 ~125 ~175 grass_block
setblock ~84 ~125 ~176 grass_block
setblock ~84 ~125 ~177 grass_block
setblock ~84 ~125 ~178 grass_block
setblock ~84 ~125 ~179 grass_block
setblock ~84 ~125 ~182 grass_block
setblock ~84 ~125 ~183 grass_block
setblock ~84 ~125 ~184 grass_block
setblock ~84 ~125 ~185 grass_block
setblock ~84 ~125 ~186 grass_block
setblock ~84 ~125 ~187 grass_block
setblock ~84 ~125 ~188 grass_block
setblock ~84 ~125 ~189 dirt
setblock ~84 ~125 ~190 dirt
setblock ~84 ~125 ~191 dirt
setblock ~84 ~125 ~192 grass_block
setblock ~84 ~125 ~193 grass_block
setblock ~84 ~125 ~194 grass_block
setblock ~84 ~125 ~195 grass_block
setblock ~84 ~125 ~196 grass_block
setblock ~84 ~126 ~7 short_grass
setblock ~84 ~126 ~9 grass_block
setblock ~84 ~126 ~10 grass_block
setblock ~84 ~126 ~11 grass_block
setblock ~84 ~126 ~12 grass_block
setblock ~84 ~126 ~13 grass_block
setblock ~84 ~126 ~14 grass_block
setblock ~84 ~126 ~15 grass_block
setblock ~84 ~126 ~16 grass_block
setblock ~84 ~126 ~17 grass_block
setblock ~84 ~126 ~18 short_grass
setblock ~84 ~126 ~23 short_grass
setblock ~84 ~126 ~26 short_grass
setblock ~84 ~126 ~28 short_grass
setblock ~84 ~126 ~31 short_grass
setblock ~84 ~126 ~36 short_grass
setblock ~84 ~126 ~82 fern
setblock ~84 ~126 ~84 short_grass
setblock ~84 ~126 ~87 grass_block
setblock ~84 ~126 ~88 grass_block
setblock ~84 ~126 ~89 grass_block
setblock ~84 ~126 ~90 grass_block
setblock ~84 ~126 ~91 grass_block
setblock ~84 ~126 ~92 grass_block
setblock ~84 ~126 ~93 grass_block
setblock ~84 ~126 ~94 grass_block
setblock ~84 ~126 ~95 grass_block
setblock ~84 ~126 ~96 grass_block
setblock ~84 ~126 ~97 grass_block
setblock ~84 ~126 ~98 grass_block
setblock ~84 ~126 ~99 fern
setblock ~84 ~126 ~103 grass_block
setblock ~84 ~126 ~104 grass_block
setblock ~84 ~126 ~105 grass_block
setblock ~84 ~126 ~106 grass_block
setblock ~84 ~126 ~107 grass_block
setblock ~84 ~126 ~108 grass_block
setblock ~84 ~126 ~109 grass_block
setblock ~84 ~126 ~110 grass_block
setblock ~84 ~126 ~111 grass_block
setblock ~84 ~126 ~112 grass_block
setblock ~84 ~126 ~113 grass_block
setblock ~84 ~126 ~115 short_grass
setblock ~84 ~126 ~124 short_grass
setblock ~84 ~126 ~134 grass_block
setblock ~84 ~126 ~135 grass_block
setblock ~84 ~126 ~136 grass_block
setblock ~84 ~126 ~137 grass_block
setblock ~84 ~126 ~138 grass_block
setblock ~84 ~126 ~139 grass_block
setblock ~84 ~126 ~140 grass_block
setblock ~84 ~126 ~141 grass_block
setblock ~84 ~126 ~154 short_grass
setblock ~84 ~126 ~156 grass_block
setblock ~84 ~126 ~157 grass_block
setblock ~84 ~126 ~158 dirt
setblock ~84 ~126 ~159 dirt
setblock ~84 ~126 ~160 dirt
setblock ~84 ~126 ~161 dirt
setblock ~84 ~126 ~162 dirt
setblock ~84 ~126 ~163 dirt
setblock ~84 ~126 ~164 dirt
setblock ~84 ~126 ~165 dirt
setblock ~84 ~126 ~166 dirt
setblock ~84 ~126 ~167 grass_block
setblock ~84 ~126 ~168 grass_block
setblock ~84 ~126 ~169 grass_block
setblock ~84 ~126 ~170 short_grass
setblock ~84 ~126 ~172 short_grass
setblock ~84 ~126 ~176 short_grass
setblock ~84 ~126 ~177 short_grass
setblock ~84 ~126 ~178 short_grass
setblock ~84 ~126 ~188 short_grass
setblock ~84 ~126 ~189 grass_block
setblock ~84 ~126 ~190 grass_block
setblock ~84 ~126 ~191 grass_block
setblock ~84 ~127 ~14 short_grass
setblock ~84 ~127 ~15 short_grass
setblock ~84 ~127 ~93 short_grass
setblock ~84 ~127 ~95 short_grass
setblock ~84 ~127 ~104 short_grass
setblock ~84 ~127 ~109 short_grass
setblock ~84 ~127 ~110 short_grass
setblock ~84 ~127 ~111 poppy
setblock ~84 ~127 ~113 fern
setblock ~84 ~127 ~141 short_grass
setblock ~84 ~127 ~158 grass_block
setblock ~84 ~127 ~159 dirt
setblock ~84 ~127 ~160 dirt
setblock ~84 ~127 ~161 dirt
setblock ~84 ~127 ~162 dirt
setblock ~84 ~127 ~163 grass_block
setblock ~84 ~127 ~164 grass_block
setblock ~84 ~127 ~165 grass_block
setblock ~84 ~127 ~166 grass_block
setblock ~84 ~127 ~169 fern
setblock ~84 ~127 ~189 short_grass
setblock ~84 ~128 ~159 grass_block
setblock ~84 ~128 ~160 grass_block
setblock ~84 ~128 ~161 grass_block
setblock ~84 ~128 ~162 grass_block
setblock ~84 ~128 ~163 short_grass
setblock ~84 ~128 ~164 short_grass
setblock ~84 ~128 ~166 short_grass
setblock ~84 ~129 ~161 short_grass
setblock ~85 ~122 ~0 dirt
setblock ~85 ~122 ~1 dirt
setblock ~85 ~122 ~2 dirt
setblock ~85 ~122 ~3 dirt
setblock ~85 ~122 ~4 dirt
setblock ~85 ~122 ~5 dirt
setblock ~85 ~122 ~6 dirt
setblock ~85 ~122 ~7 dirt
setblock ~85 ~122 ~8 dirt
setblock ~85 ~122 ~9 dirt
setblock ~85 ~122 ~10 dirt
setblock ~85 ~122 ~11 dirt
setblock ~85 ~122 ~12 dirt
setblock ~85 ~122 ~13 dirt
setblock ~85 ~122 ~14 dirt
setblock ~85 ~122 ~15 dirt
setblock ~85 ~122 ~16 dirt
setblock ~85 ~122 ~17 dirt
setblock ~85 ~122 ~18 dirt
setblock ~85 ~122 ~19 dirt
setblock ~85 ~122 ~20 dirt
setblock ~85 ~122 ~21 dirt
setblock ~85 ~122 ~22 dirt
setblock ~85 ~122 ~23 dirt
setblock ~85 ~122 ~24 dirt
setblock ~85 ~122 ~25 dirt
setblock ~85 ~122 ~26 dirt
setblock ~85 ~122 ~27 dirt
setblock ~85 ~122 ~28 dirt
setblock ~85 ~122 ~29 dirt
setblock ~85 ~122 ~30 dirt
setblock ~85 ~122 ~31 dirt
setblock ~85 ~122 ~32 dirt
setblock ~85 ~122 ~33 dirt
setblock ~85 ~122 ~34 dirt
setblock ~85 ~122 ~35 dirt
setblock ~85 ~122 ~36 dirt
setblock ~85 ~122 ~37 dirt
setblock ~85 ~122 ~38 dirt
setblock ~85 ~122 ~39 dirt
setblock ~85 ~122 ~40 dirt
setblock ~85 ~122 ~41 dirt
setblock ~85 ~122 ~42 dirt
setblock ~85 ~122 ~43 dirt
setblock ~85 ~122 ~44 dirt
setblock ~85 ~122 ~45 dirt
setblock ~85 ~122 ~46 dirt
setblock ~85 ~122 ~47 dirt
setblock ~85 ~122 ~48 dirt
setblock ~85 ~122 ~49 dirt
setblock ~85 ~122 ~50 dirt
setblock ~85 ~122 ~51 dirt
setblock ~85 ~122 ~52 dirt
setblock ~85 ~122 ~53 dirt
setblock ~85 ~122 ~54 dirt
setblock ~85 ~122 ~55 dirt
setblock ~85 ~122 ~56 dirt
setblock ~85 ~122 ~57 dirt
setblock ~85 ~122 ~58 dirt
setblock ~85 ~122 ~59 dirt
setblock ~85 ~122 ~60 dirt
setblock ~85 ~122 ~61 dirt
setblock ~85 ~122 ~62 dirt
setblock ~85 ~122 ~63 dirt
setblock ~85 ~122 ~64 dirt
setblock ~85 ~122 ~65 dirt
setblock ~85 ~122 ~66 dirt
setblock ~85 ~122 ~67 dirt
setblock ~85 ~122 ~68 dirt
setblock ~85 ~122 ~69 dirt
setblock ~85 ~122 ~70 dirt
setblock ~85 ~122 ~71 dirt
setblock ~85 ~122 ~72 dirt
setblock ~85 ~122 ~73 dirt
setblock ~85 ~122 ~74 dirt
setblock ~85 ~122 ~75 dirt
setblock ~85 ~122 ~76 dirt
setblock ~85 ~122 ~77 dirt
setblock ~85 ~122 ~78 dirt
setblock ~85 ~122 ~79 dirt
setblock ~85 ~122 ~80 dirt
setblock ~85 ~122 ~81 dirt
setblock ~85 ~122 ~82 dirt
setblock ~85 ~122 ~83 dirt
setblock ~85 ~122 ~84 dirt
setblock ~85 ~122 ~85 dirt
setblock ~85 ~122 ~86 dirt
setblock ~85 ~122 ~87 dirt
setblock ~85 ~122 ~88 dirt
setblock ~85 ~122 ~89 dirt
setblock ~85 ~122 ~90 dirt
setblock ~85 ~122 ~91 dirt
setblock ~85 ~122 ~92 dirt
setblock ~85 ~122 ~93 dirt
setblock ~85 ~122 ~94 dirt
setblock ~85 ~122 ~95 dirt
setblock ~85 ~122 ~96 dirt
setblock ~85 ~122 ~97 dirt
setblock ~85 ~122 ~98 dirt
setblock ~85 ~122 ~99 dirt
setblock ~85 ~122 ~100 dirt
setblock ~85 ~122 ~101 dirt
setblock ~85 ~122 ~102 dirt
setblock ~85 ~122 ~103 dirt
setblock ~85 ~122 ~104 dirt
setblock ~85 ~122 ~105 dirt
setblock ~85 ~122 ~106 dirt
setblock ~85 ~122 ~107 dirt
setblock ~85 ~122 ~108 dirt
setblock ~85 ~122 ~109 dirt
setblock ~85 ~122 ~110 dirt
setblock ~85 ~122 ~111 dirt
setblock ~85 ~122 ~112 dirt
setblock ~85 ~122 ~113 dirt
setblock ~85 ~122 ~114 dirt
setblock ~85 ~122 ~115 dirt
setblock ~85 ~122 ~116 dirt
setblock ~85 ~122 ~117 dirt
setblock ~85 ~122 ~118 dirt
setblock ~85 ~122 ~119 dirt
setblock ~85 ~122 ~120 dirt
setblock ~85 ~122 ~121 dirt
setblock ~85 ~122 ~122 dirt
setblock ~85 ~122 ~123 dirt
setblock ~85 ~122 ~124 dirt
setblock ~85 ~122 ~125 dirt
setblock ~85 ~122 ~126 dirt
setblock ~85 ~122 ~127 dirt
setblock ~85 ~122 ~128 dirt
setblock ~85 ~122 ~129 dirt
setblock ~85 ~122 ~130 dirt
setblock ~85 ~122 ~131 dirt
setblock ~85 ~122 ~132 dirt
setblock ~85 ~122 ~133 dirt
setblock ~85 ~122 ~134 dirt
setblock ~85 ~122 ~135 dirt
setblock ~85 ~122 ~136 dirt
setblock ~85 ~122 ~137 dirt
setblock ~85 ~122 ~138 dirt
setblock ~85 ~122 ~139 dirt
setblock ~85 ~122 ~140 dirt
setblock ~85 ~122 ~141 dirt
setblock ~85 ~122 ~142 dirt
setblock ~85 ~122 ~143 dirt
setblock ~85 ~122 ~144 dirt
setblock ~85 ~122 ~145 dirt
setblock ~85 ~122 ~146 dirt
setblock ~85 ~122 ~147 dirt
setblock ~85 ~122 ~148 dirt
setblock ~85 ~122 ~149 dirt
setblock ~85 ~122 ~150 dirt
setblock ~85 ~122 ~151 dirt
setblock ~85 ~122 ~152 dirt
setblock ~85 ~122 ~153 dirt
setblock ~85 ~122 ~154 dirt
setblock ~85 ~122 ~155 dirt
setblock ~85 ~122 ~156 dirt
setblock ~85 ~122 ~157 dirt
setblock ~85 ~122 ~158 dirt
setblock ~85 ~122 ~159 dirt
setblock ~85 ~122 ~160 dirt
setblock ~85 ~122 ~161 dirt
setblock ~85 ~122 ~162 dirt
setblock ~85 ~122 ~163 dirt
setblock ~85 ~122 ~164 dirt
setblock ~85 ~122 ~165 dirt
setblock ~85 ~122 ~166 dirt
setblock ~85 ~122 ~167 dirt
setblock ~85 ~122 ~168 dirt
setblock ~85 ~122 ~169 dirt
setblock ~85 ~122 ~170 dirt
setblock ~85 ~122 ~171 dirt
setblock ~85 ~122 ~172 dirt
setblock ~85 ~122 ~173 dirt
setblock ~85 ~122 ~174 dirt
setblock ~85 ~122 ~175 dirt
setblock ~85 ~122 ~176 dirt
setblock ~85 ~122 ~177 dirt
setblock ~85 ~122 ~178 dirt
setblock ~85 ~122 ~179 dirt
setblock ~85 ~122 ~180 dirt
setblock ~85 ~122 ~181 dirt
setblock ~85 ~122 ~182 dirt
setblock ~85 ~122 ~183 dirt
setblock ~85 ~122 ~184 dirt
setblock ~85 ~122 ~185 dirt
setblock ~85 ~122 ~186 dirt
setblock ~85 ~122 ~187 dirt
setblock ~85 ~122 ~188 dirt
setblock ~85 ~122 ~189 dirt
setblock ~85 ~122 ~190 dirt
setblock ~85 ~122 ~191 dirt
setblock ~85 ~122 ~192 dirt
setblock ~85 ~122 ~193 dirt
setblock ~85 ~122 ~194 dirt
setblock ~85 ~122 ~195 dirt
setblock ~85 ~122 ~196 dirt
setblock ~85 ~122 ~197 dirt
setblock ~85 ~122 ~198 dirt
setblock ~85 ~122 ~199 dirt
setblock ~85 ~123 ~0 grass_block
setblock ~85 ~123 ~1 dirt
setblock ~85 ~123 ~2 dirt
setblock ~85 ~123 ~3 dirt
setblock ~85 ~123 ~4 dirt
setblock ~85 ~123 ~5 dirt
setblock ~85 ~123 ~6 dirt
setblock ~85 ~123 ~7 dirt
setblock ~85 ~123 ~8 dirt
setblock ~85 ~123 ~9 dirt
setblock ~85 ~123 ~10 dirt
setblock ~85 ~123 ~11 dirt
setblock ~85 ~123 ~12 dirt
setblock ~85 ~123 ~13 dirt
setblock ~85 ~123 ~14 dirt
setblock ~85 ~123 ~15 dirt
setblock ~85 ~123 ~16 dirt
setblock ~85 ~123 ~17 dirt
setblock ~85 ~123 ~18 dirt
setblock ~85 ~123 ~19 dirt
setblock ~85 ~123 ~20 dirt
setblock ~85 ~123 ~21 dirt
setblock ~85 ~123 ~22 dirt
setblock ~85 ~123 ~23 dirt
setblock ~85 ~123 ~24 dirt
setblock ~85 ~123 ~25 dirt
setblock ~85 ~123 ~26 dirt
setblock ~85 ~123 ~27 dirt
setblock ~85 ~123 ~28 dirt
setblock ~85 ~123 ~29 dirt
setblock ~85 ~123 ~30 dirt
setblock ~85 ~123 ~31 dirt
setblock ~85 ~123 ~32 dirt
setblock ~85 ~123 ~33 dirt
setblock ~85 ~123 ~34 dirt
setblock ~85 ~123 ~35 dirt
setblock ~85 ~123 ~36 dirt
setblock ~85 ~123 ~37 dirt
setblock ~85 ~123 ~38 dirt
setblock ~85 ~123 ~39 dirt
setblock ~85 ~123 ~40 dirt
setblock ~85 ~123 ~41 dirt
setblock ~85 ~123 ~42 dirt
setblock ~85 ~123 ~43 dirt
setblock ~85 ~123 ~44 dirt
setblock ~85 ~123 ~45 dirt
setblock ~85 ~123 ~46 dirt
setblock ~85 ~123 ~47 dirt
setblock ~85 ~123 ~48 dirt
setblock ~85 ~123 ~49 dirt
setblock ~85 ~123 ~50 dirt
setblock ~85 ~123 ~51 dirt
setblock ~85 ~123 ~52 dirt
setblock ~85 ~123 ~53 dirt
setblock ~85 ~123 ~54 dirt
setblock ~85 ~123 ~55 dirt
setblock ~85 ~123 ~56 grass_block
setblock ~85 ~123 ~57 grass_block
setblock ~85 ~123 ~58 grass_block
setblock ~85 ~123 ~59 grass_block
setblock ~85 ~123 ~60 grass_block
setblock ~85 ~123 ~61 grass_block
setblock ~85 ~123 ~62 grass_block
setblock ~85 ~123 ~63 grass_block
setblock ~85 ~123 ~64 grass_block
setblock ~85 ~123 ~65 grass_block
setblock ~85 ~123 ~66 grass_block
setblock ~85 ~123 ~67 grass_block
setblock ~85 ~123 ~68 grass_block
setblock ~85 ~123 ~69 grass_block
setblock ~85 ~123 ~70 grass_block
setblock ~85 ~123 ~71 grass_block
setblock ~85 ~123 ~72 grass_block
setblock ~85 ~123 ~73 dirt
setblock ~85 ~123 ~74 dirt
setblock ~85 ~123 ~75 dirt
setblock ~85 ~123 ~76 dirt
setblock ~85 ~123 ~77 dirt
setblock ~85 ~123 ~78 dirt
setblock ~85 ~123 ~79 dirt
setblock ~85 ~123 ~80 dirt
setblock ~85 ~123 ~81 dirt
setblock ~85 ~123 ~82 dirt
setblock ~85 ~123 ~83 dirt
setblock ~85 ~123 ~84 dirt
setblock ~85 ~123 ~85 dirt
setblock ~85 ~123 ~86 dirt
setblock ~85 ~123 ~87 dirt
setblock ~85 ~123 ~88 dirt
setblock ~85 ~123 ~89 dirt
setblock ~85 ~123 ~90 dirt
setblock ~85 ~123 ~91 dirt
setblock ~85 ~123 ~92 dirt
setblock ~85 ~123 ~93 dirt
setblock ~85 ~123 ~94 dirt
setblock ~85 ~123 ~95 dirt
setblock ~85 ~123 ~96 dirt
setblock ~85 ~123 ~97 dirt
setblock ~85 ~123 ~98 dirt
setblock ~85 ~123 ~99 dirt
setblock ~85 ~123 ~100 dirt
setblock ~85 ~123 ~101 dirt
setblock ~85 ~123 ~102 dirt
setblock ~85 ~123 ~103 dirt
setblock ~85 ~123 ~104 dirt
setblock ~85 ~123 ~105 dirt
setblock ~85 ~123 ~106 dirt
setblock ~85 ~123 ~107 dirt
setblock ~85 ~123 ~108 dirt
setblock ~85 ~123 ~109 dirt
setblock ~85 ~123 ~110 dirt
setblock ~85 ~123 ~111 dirt
setblock ~85 ~123 ~112 dirt
setblock ~85 ~123 ~113 dirt
setblock ~85 ~123 ~114 dirt
setblock ~85 ~123 ~115 dirt
setblock ~85 ~123 ~116 dirt
setblock ~85 ~123 ~117 dirt
setblock ~85 ~123 ~118 dirt
setblock ~85 ~123 ~119 dirt
setblock ~85 ~123 ~120 dirt
setblock ~85 ~123 ~121 dirt
setblock ~85 ~123 ~122 dirt
setblock ~85 ~123 ~123 dirt
setblock ~85 ~123 ~124 dirt
setblock ~85 ~123 ~125 dirt
setblock ~85 ~123 ~126 dirt
setblock ~85 ~123 ~127 dirt
setblock ~85 ~123 ~128 dirt
setblock ~85 ~123 ~129 dirt
setblock ~85 ~123 ~130 dirt
setblock ~85 ~123 ~131 dirt
setblock ~85 ~123 ~132 dirt
setblock ~85 ~123 ~133 dirt
setblock ~85 ~123 ~134 dirt
setblock ~85 ~123 ~135 dirt
setblock ~85 ~123 ~136 dirt
setblock ~85 ~123 ~137 dirt
setblock ~85 ~123 ~138 dirt
setblock ~85 ~123 ~139 dirt
setblock ~85 ~123 ~140 dirt
setblock ~85 ~123 ~141 dirt
setblock ~85 ~123 ~142 dirt
setblock ~85 ~123 ~143 dirt
setblock ~85 ~123 ~144 dirt
setblock ~85 ~123 ~145 dirt
setblock ~85 ~123 ~146 dirt
setblock ~85 ~123 ~147 dirt
setblock ~85 ~123 ~148 grass_block
setblock ~85 ~123 ~149 grass_block
setblock ~85 ~123 ~150 grass_block
setblock ~85 ~123 ~151 grass_block
setblock ~85 ~123 ~152 dirt
setblock ~85 ~123 ~153 dirt
setblock ~85 ~123 ~154 dirt
setblock ~85 ~123 ~155 dirt
setblock ~85 ~123 ~156 dirt
setblock ~85 ~123 ~157 dirt
setblock ~85 ~123 ~158 dirt
setblock ~85 ~123 ~159 dirt
setblock ~85 ~123 ~160 dirt
setblock ~85 ~123 ~161 dirt
setblock ~85 ~123 ~162 dirt
setblock ~85 ~123 ~163 dirt
setblock ~85 ~123 ~164 dirt
setblock ~85 ~123 ~165 dirt
setblock ~85 ~123 ~166 dirt
setblock ~85 ~123 ~167 dirt
setblock ~85 ~123 ~168 dirt
setblock ~85 ~123 ~169 dirt
setblock ~85 ~123 ~170 dirt
setblock ~85 ~123 ~171 dirt
setblock ~85 ~123 ~172 dirt
setblock ~85 ~123 ~173 dirt
setblock ~85 ~123 ~174 dirt
setblock ~85 ~123 ~175 dirt
setblock ~85 ~123 ~176 dirt
setblock ~85 ~123 ~177 dirt
setblock ~85 ~123 ~178 dirt
setblock ~85 ~123 ~179 dirt
setblock ~85 ~123 ~180 dirt
setblock ~85 ~123 ~181 dirt
setblock ~85 ~123 ~182 dirt
setblock ~85 ~123 ~183 dirt
setblock ~85 ~123 ~184 dirt
setblock ~85 ~123 ~185 dirt
setblock ~85 ~123 ~186 dirt
setblock ~85 ~123 ~187 dirt
setblock ~85 ~123 ~188 dirt
setblock ~85 ~123 ~189 dirt
setblock ~85 ~123 ~190 dirt
setblock ~85 ~123 ~191 dirt
setblock ~85 ~123 ~192 dirt
setblock ~85 ~123 ~193 dirt
setblock ~85 ~123 ~194 dirt
setblock ~85 ~123 ~195 dirt
setblock ~85 ~123 ~196 dirt
setblock ~85 ~123 ~197 dirt
setblock ~85 ~123 ~198 dirt
setblock ~85 ~123 ~199 grass_block
setblock ~85 ~124 ~1 grass_block
setblock ~85 ~124 ~2 grass_block
setblock ~85 ~124 ~3 grass_block
setblock ~85 ~124 ~4 dirt
setblock ~85 ~124 ~5 dirt
setblock ~85 ~124 ~6 dirt
setblock ~85 ~124 ~7 dirt
setblock ~85 ~124 ~8 dirt
setblock ~85 ~124 ~9 dirt
setblock ~85 ~124 ~10 dirt
setblock ~85 ~124 ~11 dirt
setblock ~85 ~124 ~12 dirt
setblock ~85 ~124 ~13 dirt
setblock ~85 ~124 ~14 dirt
setblock ~85 ~124 ~15 dirt
setblock ~85 ~124 ~16 dirt
setblock ~85 ~124 ~17 dirt
setblock ~85 ~124 ~18 dirt
setblock ~85 ~124 ~19 dirt
setblock ~85 ~124 ~20 dirt
setblock ~85 ~124 ~21 dirt
setblock ~85 ~124 ~22 dirt
setblock ~85 ~124 ~23 dirt
setblock ~85 ~124 ~24 dirt
setblock ~85 ~124 ~25 dirt
setblock ~85 ~124 ~26 dirt
setblock ~85 ~124 ~27 dirt
setblock ~85 ~124 ~28 dirt
setblock ~85 ~124 ~29 dirt
setblock ~85 ~124 ~30 dirt
setblock ~85 ~124 ~31 dirt
setblock ~85 ~124 ~32 dirt
setblock ~85 ~124 ~33 dirt
setblock ~85 ~124 ~34 dirt
setblock ~85 ~124 ~35 dirt
setblock ~85 ~124 ~36 grass_block
setblock ~85 ~124 ~37 grass_block
setblock ~85 ~124 ~38 grass_block
setblock ~85 ~124 ~39 grass_block
setblock ~85 ~124 ~40 grass_block
setblock ~85 ~124 ~41 grass_block
setblock ~85 ~124 ~42 grass_block
setblock ~85 ~124 ~43 grass_block
setblock ~85 ~124 ~44 grass_block
setblock ~85 ~124 ~45 grass_block
setblock ~85 ~124 ~46 grass_block
setblock ~85 ~124 ~47 grass_block
setblock ~85 ~124 ~48 grass_block
setblock ~85 ~124 ~49 grass_block
setblock ~85 ~124 ~50 grass_block
setblock ~85 ~124 ~51 grass_block
setblock ~85 ~124 ~52 grass_block
setblock ~85 ~124 ~53 grass_block
setblock ~85 ~124 ~54 grass_block
setblock ~85 ~124 ~55 grass_block
setblock ~85 ~124 ~62 short_grass
setblock ~85 ~124 ~63 short_grass
setblock ~85 ~124 ~68 short_grass
setblock ~85 ~124 ~73 grass_block
setblock ~85 ~124 ~74 grass_block
setblock ~85 ~124 ~75 grass_block
setblock ~85 ~124 ~76 grass_block
setblock ~85 ~124 ~77 grass_block
setblock ~85 ~124 ~78 grass_block
setblock ~85 ~124 ~79 grass_block
setblock ~85 ~124 ~80 grass_block
setblock ~85 ~124 ~81 grass_block
setblock ~85 ~124 ~82 dirt
setblock ~85 ~124 ~83 dirt
setblock ~85 ~124 ~84 dirt
setblock ~85 ~124 ~85 dirt
setblock ~85 ~124 ~86 dirt
setblock ~85 ~124 ~87 dirt
setblock ~85 ~124 ~88 dirt
setblock ~85 ~124 ~89 dirt
setblock ~85 ~124 ~90 dirt
setblock ~85 ~124 ~91 dirt
setblock ~85 ~124 ~92 dirt
setblock ~85 ~124 ~93 dirt
setblock ~85 ~124 ~94 dirt
setblock ~85 ~124 ~95 dirt
setblock ~85 ~124 ~96 dirt
setblock ~85 ~124 ~97 dirt
setblock ~85 ~124 ~98 dirt
setblock ~85 ~124 ~99 dirt
setblock ~85 ~124 ~100 dirt
setblock ~85 ~124 ~101 dirt
setblock ~85 ~124 ~102 dirt
setblock ~85 ~124 ~103 dirt
setblock ~85 ~124 ~104 dirt
setblock ~85 ~124 ~105 dirt
setblock ~85 ~124 ~106 dirt
setblock ~85 ~124 ~107 dirt
setblock ~85 ~124 ~108 dirt
setblock ~85 ~124 ~109 dirt
setblock ~85 ~124 ~110 dirt
setblock ~85 ~124 ~111 dirt
setblock ~85 ~124 ~112 dirt
setblock ~85 ~124 ~113 dirt
setblock ~85 ~124 ~114 dirt
setblock ~85 ~124 ~115 dirt
setblock ~85 ~124 ~116 dirt
setblock ~85 ~124 ~117 dirt
setblock ~85 ~124 ~118 dirt
setblock ~85 ~124 ~119 dirt
setblock ~85 ~124 ~120 grass_block
setblock ~85 ~124 ~121 grass_block
setblock ~85 ~124 ~122 dirt
setblock ~85 ~124 ~123 dirt
setblock ~85 ~124 ~124 dirt
setblock ~85 ~124 ~125 dirt
setblock ~85 ~124 ~126 dirt
setblock ~85 ~124 ~127 dirt
setblock ~85 ~124 ~128 dirt
setblock ~85 ~124 ~129 dirt
setblock ~85 ~124 ~130 dirt
setblock ~85 ~124 ~131 dirt
setblock ~85 ~124 ~132 dirt
setblock ~85 ~124 ~133 dirt
setblock ~85 ~124 ~134 dirt
setblock ~85 ~124 ~135 dirt
setblock ~85 ~124 ~136 dirt
setblock ~85 ~124 ~137 dirt
setblock ~85 ~124 ~138 dirt
setblock ~85 ~124 ~139 dirt
setblock ~85 ~124 ~140 dirt
setblock ~85 ~124 ~141 dirt
setblock ~85 ~124 ~142 dirt
setblock ~85 ~124 ~143 dirt
setblock ~85 ~124 ~144 dirt
setblock ~85 ~124 ~145 grass_block
setblock ~85 ~124 ~146 grass_block
setblock ~85 ~124 ~147 grass_block
setblock ~85 ~124 ~152 grass_block
setblock ~85 ~124 ~153 grass_block
setblock ~85 ~124 ~154 dirt
setblock ~85 ~124 ~155 dirt
setblock ~85 ~124 ~156 dirt
setblock ~85 ~124 ~157 dirt
setblock ~85 ~124 ~158 dirt
setblock ~85 ~124 ~159 dirt
setblock ~85 ~124 ~160 dirt
setblock ~85 ~124 ~161 dirt
setblock ~85 ~124 ~162 dirt
setblock ~85 ~124 ~163 dirt
setblock ~85 ~124 ~164 dirt
setblock ~85 ~124 ~165 dirt
setblock ~85 ~124 ~166 dirt
setblock ~85 ~124 ~167 dirt
setblock ~85 ~124 ~168 dirt
setblock ~85 ~124 ~169 dirt
setblock ~85 ~124 ~170 dirt
setblock ~85 ~124 ~171 dirt
setblock ~85 ~124 ~172 dirt
setblock ~85 ~124 ~173 dirt
setblock ~85 ~124 ~174 dirt
setblock ~85 ~124 ~175 dirt
setblock ~85 ~124 ~176 dirt
setblock ~85 ~124 ~177 dirt
setblock ~85 ~124 ~178 dirt
setblock ~85 ~124 ~179 grass_block
setblock ~85 ~124 ~180 grass_block
setblock ~85 ~124 ~181 grass_block
setblock ~85 ~124 ~182 dirt
setblock ~85 ~124 ~183 dirt
setblock ~85 ~124 ~184 dirt
setblock ~85 ~124 ~185 dirt
setblock ~85 ~124 ~186 dirt
setblock ~85 ~124 ~187 dirt
setblock ~85 ~124 ~188 dirt
setblock ~85 ~124 ~189 dirt
setblock ~85 ~124 ~190 dirt
setblock ~85 ~124 ~191 dirt
setblock ~85 ~124 ~192 dirt
setblock ~85 ~124 ~193 dirt
setblock ~85 ~124 ~194 dirt
setblock ~85 ~124 ~195 dirt
setblock ~85 ~124 ~196 dirt
setblock ~85 ~124 ~197 grass_block
setblock ~85 ~124 ~198 grass_block
setblock ~85 ~125 ~2 short_grass
setblock ~85 ~125 ~4 grass_block
setblock ~85 ~125 ~5 grass_block
setblock ~85 ~125 ~6 grass_block
setblock ~85 ~125 ~7 grass_block
setblock ~85 ~125 ~8 dirt
setblock ~85 ~125 ~9 dirt
setblock ~85 ~125 ~10 dirt
setblock ~85 ~125 ~11 dirt
setblock ~85 ~125 ~12 dirt
setblock ~85 ~125 ~13 dirt
setblock ~85 ~125 ~14 dirt
setblock ~85 ~125 ~15 dirt
setblock ~85 ~125 ~16 dirt
setblock ~85 ~125 ~17 dirt
setblock ~85 ~125 ~18 dirt
setblock ~85 ~125 ~19 dirt
setblock ~85 ~125 ~20 grass_block
setblock ~85 ~125 ~21 grass_block
setblock ~85 ~125 ~22 grass_block
setblock ~85 ~125 ~23 grass_block
setblock ~85 ~125 ~24 grass_block
setblock ~85 ~125 ~25 grass_block
setblock ~85 ~125 ~26 grass_block
setblock ~85 ~125 ~27 grass_block
setblock ~85 ~125 ~28 grass_block
setblock ~85 ~125 ~29 grass_block
setblock ~85 ~125 ~30 grass_block
setblock ~85 ~125 ~31 grass_block
setblock ~85 ~125 ~32 grass_block
setblock ~85 ~125 ~33 grass_block
setblock ~85 ~125 ~34 grass_block
setblock ~85 ~125 ~35 grass_block
setblock ~85 ~125 ~37 short_grass
setblock ~85 ~125 ~39 fern
setblock ~85 ~125 ~40 short_grass
setblock ~85 ~125 ~42 short_grass
setblock ~85 ~125 ~45 fern
setblock ~85 ~125 ~50 short_grass
setblock ~85 ~125 ~53 short_grass
setblock ~85 ~125 ~55 short_grass
setblock ~85 ~125 ~78 short_grass
setblock ~85 ~125 ~82 grass_block
setblock ~85 ~125 ~83 grass_block
setblock ~85 ~125 ~84 grass_block
setblock ~85 ~125 ~85 grass_block
setblock ~85 ~125 ~86 grass_block
setblock ~85 ~125 ~87 grass_block
setblock ~85 ~125 ~88 dirt
setblock ~85 ~125 ~89 dirt
setblock ~85 ~125 ~90 dirt
setblock ~85 ~125 ~91 dirt
setblock ~85 ~125 ~92 dirt
setblock ~85 ~125 ~93 dirt
setblock ~85 ~125 ~94 dirt
setblock ~85 ~125 ~95 dirt
setblock ~85 ~125 ~96 dirt
setblock ~85 ~125 ~97 dirt
setblock ~85 ~125 ~98 grass_block
setblock ~85 ~125 ~99 grass_block
setblock ~85 ~125 ~100 grass_block
setblock ~85 ~125 ~101 grass_block
setblock ~85 ~125 ~102 grass_block
setblock ~85 ~125 ~103 grass_block
setblock ~85 ~125 ~104 grass_block
setblock ~85 ~125 ~105 grass_block
setblock ~85 ~125 ~106 dirt
setblock ~85 ~125 ~107 dirt
setblock ~85 ~125 ~108 dirt
setblock ~85 ~125 ~109 dirt
setblock ~85 ~125 ~110 dirt
setblock ~85 ~125 ~111 grass_block
setblock ~85 ~125 ~112 grass_block
setblock ~85 ~125 ~113 grass_block
setblock ~85 ~125 ~114 grass_block
setblock ~85 ~125 ~115 grass_block
setblock ~85 ~125 ~116 grass_block
setblock ~85 ~125 ~117 grass_block
setblock ~85 ~125 ~118 grass_block
setblock ~85 ~125 ~119 grass_block
setblock ~85 ~125 ~121 poppy
setblock ~85 ~125 ~122 grass_block
setblock ~85 ~125 ~123 grass_block
setblock ~85 ~125 ~124 grass_block
setblock ~85 ~125 ~125 grass_block
setblock ~85 ~125 ~126 grass_block
setblock ~85 ~125 ~127 grass_block
setblock ~85 ~125 ~128 grass_block
setblock ~85 ~125 ~129 grass_block
setblock ~85 ~125 ~130 grass_block
setblock ~85 ~125 ~131 dirt
setblock ~85 ~125 ~132 dirt
setblock ~85 ~125 ~133 dirt
setblock ~85 ~125 ~134 dirt
setblock ~85 ~125 ~135 dirt
setblock ~85 ~125 ~136 dirt
setblock ~85 ~125 ~137 dirt
setblock ~85 ~125 ~138 dirt
setblock ~85 ~125 ~139 dirt
setblock ~85 ~125 ~140 dirt
setblock ~85 ~125 ~141 dirt
setblock ~85 ~125 ~142 grass_block
setblock ~85 ~125 ~143 grass_block
setblock ~85 ~125 ~144 grass_block
setblock ~85 ~125 ~145 short_grass
setblock ~85 ~125 ~154 grass_block
setblock ~85 ~125 ~155 grass_block
setblock ~85 ~125 ~156 dirt
setblock ~85 ~125 ~157 dirt
setblock ~85 ~125 ~158 dirt
setblock ~85 ~125 ~159 dirt
setblock ~85 ~125 ~160 dirt
setblock ~85 ~125 ~161 dirt
setblock ~85 ~125 ~162 dirt
setblock ~85 ~125 ~163 dirt
setblock ~85 ~125 ~164 dirt
setblock ~85 ~125 ~165 dirt
setblock ~85 ~125 ~166 dirt
setblock ~85 ~125 ~167 dirt
setblock ~85 ~125 ~168 grass_block
setblock ~85 ~125 ~169 grass_block
setblock ~85 ~125 ~170 grass_block
setblock ~85 ~125 ~171 grass_block
setblock ~85 ~125 ~172 grass_block
setblock ~85 ~125 ~173 grass_block
setblock ~85 ~125 ~174 grass_block
setblock ~85 ~125 ~175 grass_block
setblock ~85 ~125 ~176 grass_block
setblock ~85 ~125 ~177 grass_block
setblock ~85 ~125 ~178 grass_block
setblock ~85 ~125 ~182 grass_block
setblock ~85 ~125 ~183 grass_block
setblock ~85 ~125 ~184 grass_block
setblock ~85 ~125 ~185 grass_block
setblock ~85 ~125 ~186 dirt
setblock ~85 ~125 ~187 dirt
setblock ~85 ~125 ~188 dirt
setblock ~85 ~125 ~189 dirt
setblock ~85 ~125 ~190 dirt
setblock ~85 ~125 ~191 dirt
setblock ~85 ~125 ~192 dirt
setblock ~85 ~125 ~193 dirt
setblock ~85 ~125 ~194 grass_block
setblock ~85 ~125 ~195 grass_block
setblock ~85 ~125 ~196 grass_block
setblock ~85 ~125 ~197 short_grass
setblock ~85 ~125 ~198 short_grass
setblock ~85 ~126 ~4 short_grass
setblock ~85 ~126 ~7 short_grass
setblock ~85 ~126 ~8 grass_block
setblock ~85 ~126 ~9 grass_block
setblock ~85 ~126 ~10 grass_block
setblock ~85 ~126 ~11 grass_block
setblock ~85 ~126 ~12 grass_block
setblock ~85 ~126 ~13 grass_block
setblock ~85 ~126 ~14 grass_block
setblock ~85 ~126 ~15 grass_block
setblock ~85 ~126 ~16 grass_block
setblock ~85 ~126 ~17 grass_block
setblock ~85 ~126 ~18 grass_block
setblock ~85 ~126 ~19 grass_block
setblock ~85 ~126 ~26 short_grass
setblock ~85 ~126 ~28 short_grass
setblock ~85 ~126 ~85 short_grass
setblock ~85 ~126 ~87 short_grass
setblock ~85 ~126 ~88 grass_block
setblock ~85 ~126 ~89 grass_block
setblock ~85 ~126 ~90 grass_block
setblock ~85 ~126 ~91 grass_block
setblock ~85 ~126 ~92 grass_block
setblock ~85 ~126 ~93 grass_block
setblock ~85 ~126 ~94 grass_block
setblock ~85 ~126 ~95 grass_block
setblock ~85 ~126 ~96 grass_block
setblock ~85 ~126 ~97 grass_block
setblock ~85 ~126 ~106 grass_block
setblock ~85 ~126 ~107 grass_block
setblock ~85 ~126 ~108 grass_block
setblock ~85 ~126 ~109 grass_block
setblock ~85 ~126 ~110 grass_block
setblock ~85 ~126 ~112 short_grass
setblock ~85 ~126 ~115 fern
setblock ~85 ~126 ~118 short_grass
setblock ~85 ~126 ~127 short_grass
setblock ~85 ~126 ~131 grass_block
setblock ~85 ~126 ~132 grass_block
setblock ~85 ~126 ~133 grass_block
setblock ~85 ~126 ~134 grass_block
setblock ~85 ~126 ~135 grass_block
setblock ~85 ~126 ~136 grass_block
setblock ~85 ~126 ~137 grass_block
setblock ~85 ~126 ~138 grass_block
setblock ~85 ~126 ~139 grass_block
setblock ~85 ~126 ~140 grass_block
setblock ~85 ~126 ~141 grass_block
setblock ~85 ~126 ~142 fern
setblock ~85 ~126 ~155 short_grass
setblock ~85 ~126 ~156 grass_block
setblock ~85 ~126 ~157 grass_block
setblock ~85 ~126 ~158 dirt
setblock ~85 ~126 ~159 dirt
setblock ~85 ~126 ~160 dirt
setblock ~85 ~126 ~161 dirt
setblock ~85 ~126 ~162 dirt
setblock ~85 ~126 ~163 dirt
setblock ~85 ~126 ~164 dirt
setblock ~85 ~126 ~165 grass_block
setblock ~85 ~126 ~166 grass_block
setblock ~85 ~126 ~167 grass_block
setblock ~85 ~126 ~169 short_grass
setblock ~85 ~126 ~170 short_grass
setblock ~85 ~126 ~172 short_grass
setblock ~85 ~126 ~186 grass_block
setblock ~85 ~126 ~187 grass_block
setblock ~85 ~126 ~188 grass_block
setblock ~85 ~126 ~189 grass_block
setblock ~85 ~126 ~190 grass_block
setblock ~85 ~126 ~191 grass_block
setblock ~85 ~126 ~192 grass_block
setblock ~85 ~126 ~193 grass_block
setblock ~85 ~126 ~195 short_grass
setblock ~85 ~126 ~196 poppy
setblock ~85 ~127 ~8 short_grass
setblock ~85 ~127 ~10 short_grass
setblock ~85 ~127 ~12 short_grass
setblock ~85 ~127 ~19 poppy
setblock ~85 ~127 ~88 poppy
setblock ~85 ~127 ~92 short_grass
setblock ~85 ~127 ~96 short_grass
setblock ~85 ~127 ~106 short_grass
setblock ~85 ~127 ~107 short_grass
setblock ~85 ~127 ~110 fern
setblock ~85 ~127 ~131 short_grass
setblock ~85 ~127 ~135 fern
setblock ~85 ~127 ~138 poppy
setblock ~85 ~127 ~140 short_grass
setblock ~85 ~127 ~158 grass_block
setblock ~85 ~127 ~159 grass_block
setblock ~85 ~127 ~160 dirt
setblock ~85 ~127 ~161 dirt
setblock ~85 ~127 ~162 grass_block
setblock ~85 ~127 ~163 grass_block
setblock ~85 ~127 ~164 grass_block
setblock ~85 ~127 ~187 short_grass
setblock ~85 ~127 ~190 short_grass
setblock ~85 ~128 ~160 grass_block
setblock ~85 ~128 ~161 grass_block
setblock ~85 ~128 ~164 short_grass
setblock ~85 ~129 ~160 short_grass
setblock ~86 ~122 ~0 dirt
setblock ~86 ~122 ~1 dirt
setblock ~86 ~122 ~2 dirt
setblock ~86 ~122 ~3 dirt
setblock ~86 ~122 ~4 dirt
setblock ~86 ~122 ~5 dirt
setblock ~86 ~122 ~6 dirt
setblock ~86 ~122 ~7 dirt
setblock ~86 ~122 ~8 dirt
setblock ~86 ~122 ~9 dirt
setblock ~86 ~122 ~10 dirt
setblock ~86 ~122 ~11 dirt
setblock ~86 ~122 ~12 dirt
setblock ~86 ~122 ~13 dirt
setblock ~86 ~122 ~14 dirt
setblock ~86 ~122 ~15 dirt
setblock ~86 ~122 ~16 dirt
setblock ~86 ~122 ~17 dirt
setblock ~86 ~122 ~18 dirt
setblock ~86 ~122 ~19 dirt
setblock ~86 ~122 ~20 dirt
setblock ~86 ~122 ~21 dirt
setblock ~86 ~122 ~22 dirt
setblock ~86 ~122 ~23 dirt
setblock ~86 ~122 ~24 dirt
setblock ~86 ~122 ~25 dirt
setblock ~86 ~122 ~26 dirt
setblock ~86 ~122 ~27 dirt
setblock ~86 ~122 ~28 dirt
setblock ~86 ~122 ~29 dirt
setblock ~86 ~122 ~30 dirt
setblock ~86 ~122 ~31 dirt
setblock ~86 ~122 ~32 dirt
setblock ~86 ~122 ~33 dirt
setblock ~86 ~122 ~34 dirt
setblock ~86 ~122 ~35 dirt
setblock ~86 ~122 ~36 dirt
setblock ~86 ~122 ~37 dirt
setblock ~86 ~122 ~38 dirt
setblock ~86 ~122 ~39 dirt
setblock ~86 ~122 ~40 dirt
setblock ~86 ~122 ~41 dirt
setblock ~86 ~122 ~42 dirt
setblock ~86 ~122 ~43 dirt
setblock ~86 ~122 ~44 dirt
setblock ~86 ~122 ~45 dirt
setblock ~86 ~122 ~46 dirt
setblock ~86 ~122 ~47 dirt
setblock ~86 ~122 ~48 dirt
setblock ~86 ~122 ~49 dirt
setblock ~86 ~122 ~50 dirt
setblock ~86 ~122 ~51 dirt
setblock ~86 ~122 ~52 dirt
setblock ~86 ~122 ~53 dirt
setblock ~86 ~122 ~54 dirt
setblock ~86 ~122 ~55 dirt
setblock ~86 ~122 ~56 dirt
setblock ~86 ~122 ~57 dirt
setblock ~86 ~122 ~58 dirt
setblock ~86 ~122 ~59 dirt
setblock ~86 ~122 ~60 dirt
setblock ~86 ~122 ~61 dirt
setblock ~86 ~122 ~62 dirt
setblock ~86 ~122 ~63 dirt
setblock ~86 ~122 ~64 dirt
setblock ~86 ~122 ~65 dirt
setblock ~86 ~122 ~66 dirt
setblock ~86 ~122 ~67 dirt
setblock ~86 ~122 ~68 dirt
setblock ~86 ~122 ~69 dirt
setblock ~86 ~122 ~70 dirt
setblock ~86 ~122 ~71 dirt
setblock ~86 ~122 ~72 dirt
setblock ~86 ~122 ~73 dirt
setblock ~86 ~122 ~74 dirt
setblock ~86 ~122 ~75 dirt
setblock ~86 ~122 ~76 dirt
setblock ~86 ~122 ~77 dirt
setblock ~86 ~122 ~78 dirt
setblock ~86 ~122 ~79 dirt
setblock ~86 ~122 ~80 dirt
setblock ~86 ~122 ~81 dirt
setblock ~86 ~122 ~82 dirt
setblock ~86 ~122 ~83 dirt
setblock ~86 ~122 ~84 dirt
setblock ~86 ~122 ~85 dirt
setblock ~86 ~122 ~86 dirt
setblock ~86 ~122 ~87 dirt
setblock ~86 ~122 ~88 dirt
setblock ~86 ~122 ~89 dirt
setblock ~86 ~122 ~90 dirt
setblock ~86 ~122 ~91 dirt
setblock ~86 ~122 ~92 dirt
setblock ~86 ~122 ~93 dirt
setblock ~86 ~122 ~94 dirt
setblock ~86 ~122 ~95 dirt
setblock ~86 ~122 ~96 dirt
setblock ~86 ~122 ~97 dirt
setblock ~86 ~122 ~98 dirt
setblock ~86 ~122 ~99 dirt
setblock ~86 ~122 ~100 dirt
setblock ~86 ~122 ~101 dirt
setblock ~86 ~122 ~102 dirt
setblock ~86 ~122 ~103 dirt
setblock ~86 ~122 ~104 dirt
setblock ~86 ~122 ~105 dirt
setblock ~86 ~122 ~106 dirt
setblock ~86 ~122 ~107 dirt
setblock ~86 ~122 ~108 dirt
setblock ~86 ~122 ~109 dirt
setblock ~86 ~122 ~110 dirt
setblock ~86 ~122 ~111 dirt
setblock ~86 ~122 ~112 dirt
setblock ~86 ~122 ~113 dirt
setblock ~86 ~122 ~114 dirt
setblock ~86 ~122 ~115 dirt
setblock ~86 ~122 ~116 dirt
setblock ~86 ~122 ~117 dirt
setblock ~86 ~122 ~118 dirt
setblock ~86 ~122 ~119 dirt
setblock ~86 ~122 ~120 dirt
setblock ~86 ~122 ~121 dirt
setblock ~86 ~122 ~122 dirt
setblock ~86 ~122 ~123 dirt
setblock ~86 ~122 ~124 dirt
setblock ~86 ~122 ~125 dirt
setblock ~86 ~122 ~126 dirt
setblock ~86 ~122 ~127 dirt
setblock ~86 ~122 ~128 dirt
setblock ~86 ~122 ~129 dirt
setblock ~86 ~122 ~130 dirt
setblock ~86 ~122 ~131 dirt
setblock ~86 ~122 ~132 dirt
setblock ~86 ~122 ~133 dirt
setblock ~86 ~122 ~134 dirt
setblock ~86 ~122 ~135 dirt
setblock ~86 ~122 ~136 dirt
setblock ~86 ~122 ~137 dirt
setblock ~86 ~122 ~138 dirt
setblock ~86 ~122 ~139 dirt
setblock ~86 ~122 ~140 dirt
setblock ~86 ~122 ~141 dirt
setblock ~86 ~122 ~142 dirt
setblock ~86 ~122 ~143 dirt
setblock ~86 ~122 ~144 dirt
setblock ~86 ~122 ~145 dirt
setblock ~86 ~122 ~146 dirt
setblock ~86 ~122 ~147 dirt
setblock ~86 ~122 ~148 dirt
setblock ~86 ~122 ~149 dirt
setblock ~86 ~122 ~150 dirt
setblock ~86 ~122 ~151 dirt
setblock ~86 ~122 ~152 dirt
setblock ~86 ~122 ~153 dirt
setblock ~86 ~122 ~154 dirt
setblock ~86 ~122 ~155 dirt
setblock ~86 ~122 ~156 dirt
setblock ~86 ~122 ~157 dirt
setblock ~86 ~122 ~158 dirt
setblock ~86 ~122 ~159 dirt
setblock ~86 ~122 ~160 dirt
setblock ~86 ~122 ~161 dirt
setblock ~86 ~122 ~162 dirt
setblock ~86 ~122 ~163 dirt
setblock ~86 ~122 ~164 dirt
setblock ~86 ~122 ~165 dirt
setblock ~86 ~122 ~166 dirt
setblock ~86 ~122 ~167 dirt
setblock ~86 ~122 ~168 dirt
setblock ~86 ~122 ~169 dirt
setblock ~86 ~122 ~170 dirt
setblock ~86 ~122 ~171 dirt
setblock ~86 ~122 ~172 dirt
setblock ~86 ~122 ~173 dirt
setblock ~86 ~122 ~174 dirt
setblock ~86 ~122 ~175 dirt
setblock ~86 ~122 ~176 dirt
setblock ~86 ~122 ~177 dirt
setblock ~86 ~122 ~178 dirt
setblock ~86 ~122 ~179 dirt
setblock ~86 ~122 ~180 dirt
setblock ~86 ~122 ~181 dirt
setblock ~86 ~122 ~182 dirt
setblock ~86 ~122 ~183 dirt
setblock ~86 ~122 ~184 dirt
setblock ~86 ~122 ~185 dirt
setblock ~86 ~122 ~186 dirt
setblock ~86 ~122 ~187 dirt
setblock ~86 ~122 ~188 dirt
setblock ~86 ~122 ~189 dirt
setblock ~86 ~122 ~190 dirt
setblock ~86 ~122 ~191 dirt
setblock ~86 ~122 ~192 dirt
setblock ~86 ~122 ~193 dirt
setblock ~86 ~122 ~194 dirt
setblock ~86 ~122 ~195 dirt
setblock ~86 ~122 ~196 dirt
setblock ~86 ~122 ~197 dirt
setblock ~86 ~122 ~198 dirt
setblock ~86 ~122 ~199 dirt
setblock ~86 ~123 ~0 grass_block
setblock ~86 ~123 ~1 dirt
setblock ~86 ~123 ~2 dirt
setblock ~86 ~123 ~3 dirt
setblock ~86 ~123 ~4 dirt
setblock ~86 ~123 ~5 dirt
setblock ~86 ~123 ~6 dirt
setblock ~86 ~123 ~7 dirt
setblock ~86 ~123 ~8 dirt
setblock ~86 ~123 ~9 dirt
setblock ~86 ~123 ~10 dirt
setblock ~86 ~123 ~11 dirt
setblock ~86 ~123 ~12 dirt
setblock ~86 ~123 ~13 dirt
setblock ~86 ~123 ~14 dirt
setblock ~86 ~123 ~15 dirt
setblock ~86 ~123 ~16 dirt
setblock ~86 ~123 ~17 dirt
setblock ~86 ~123 ~18 dirt
setblock ~86 ~123 ~19 dirt
setblock ~86 ~123 ~20 dirt
setblock ~86 ~123 ~21 dirt
setblock ~86 ~123 ~22 dirt
setblock ~86 ~123 ~23 dirt
setblock ~86 ~123 ~24 dirt
setblock ~86 ~123 ~25 dirt
setblock ~86 ~123 ~26 dirt
setblock ~86 ~123 ~27 dirt
setblock ~86 ~123 ~28 dirt
setblock ~86 ~123 ~29 dirt
setblock ~86 ~123 ~30 dirt
setblock ~86 ~123 ~31 dirt
setblock ~86 ~123 ~32 dirt
setblock ~86 ~123 ~33 dirt
setblock ~86 ~123 ~34 dirt
setblock ~86 ~123 ~35 dirt
setblock ~86 ~123 ~36 dirt
setblock ~86 ~123 ~37 dirt
setblock ~86 ~123 ~38 dirt
setblock ~86 ~123 ~39 dirt
setblock ~86 ~123 ~40 dirt
setblock ~86 ~123 ~41 dirt
setblock ~86 ~123 ~42 dirt
setblock ~86 ~123 ~43 dirt
setblock ~86 ~123 ~44 dirt
setblock ~86 ~123 ~45 dirt
setblock ~86 ~123 ~46 dirt
setblock ~86 ~123 ~47 dirt
setblock ~86 ~123 ~48 dirt
setblock ~86 ~123 ~49 dirt
setblock ~86 ~123 ~50 dirt
setblock ~86 ~123 ~51 dirt
setblock ~86 ~123 ~52 dirt
setblock ~86 ~123 ~53 dirt
setblock ~86 ~123 ~54 dirt
setblock ~86 ~123 ~55 dirt
setblock ~86 ~123 ~56 dirt
setblock ~86 ~123 ~57 grass_block
setblock ~86 ~123 ~58 grass_block
setblock ~86 ~123 ~59 grass_block
setblock ~86 ~123 ~60 grass_block
setblock ~86 ~123 ~61 grass_block
setblock ~86 ~123 ~62 grass_block
setblock ~86 ~123 ~63 grass_block
setblock ~86 ~123 ~64 grass_block
setblock ~86 ~123 ~65 grass_block
setblock ~86 ~123 ~66 grass_block
setblock ~86 ~123 ~67 grass_block
setblock ~86 ~123 ~68 grass_block
setblock ~86 ~123 ~69 grass_block
setblock ~86 ~123 ~70 grass_block
setblock ~86 ~123 ~71 grass_block
setblock ~86 ~123 ~72 grass_block
setblock ~86 ~123 ~73 grass_block
setblock ~86 ~123 ~74 grass_block
setblock ~86 ~123 ~75 dirt
setblock ~86 ~123 ~76 dirt
setblock ~86 ~123 ~77 dirt
setblock ~86 ~123 ~78 dirt
setblock ~86 ~123 ~79 dirt
setblock ~86 ~123 ~80 dirt
setblock ~86 ~123 ~81 dirt
setblock ~86 ~123 ~82 dirt
setblock ~86 ~123 ~83 dirt
setblock ~86 ~123 ~84 dirt
setblock ~86 ~123 ~85 dirt
setblock ~86 ~123 ~86 dirt
setblock ~86 ~123 ~87 dirt
setblock ~86 ~123 ~88 dirt
setblock ~86 ~123 ~89 dirt
setblock ~86 ~123 ~90 dirt
setblock ~86 ~123 ~91 dirt
setblock ~86 ~123 ~92 dirt
setblock ~86 ~123 ~93 dirt
setblock ~86 ~123 ~94 dirt
setblock ~86 ~123 ~95 dirt
setblock ~86 ~123 ~96 dirt
setblock ~86 ~123 ~97 dirt
setblock ~86 ~123 ~98 dirt
setblock ~86 ~123 ~99 dirt
setblock ~86 ~123 ~100 dirt
setblock ~86 ~123 ~101 dirt
setblock ~86 ~123 ~102 dirt
setblock ~86 ~123 ~103 dirt
setblock ~86 ~123 ~104 dirt
setblock ~86 ~123 ~105 dirt
setblock ~86 ~123 ~106 dirt
setblock ~86 ~123 ~107 dirt
setblock ~86 ~123 ~108 dirt
setblock ~86 ~123 ~109 dirt
setblock ~86 ~123 ~110 dirt
setblock ~86 ~123 ~111 dirt
setblock ~86 ~123 ~112 dirt
setblock ~86 ~123 ~113 dirt
setblock ~86 ~123 ~114 dirt
setblock ~86 ~123 ~115 dirt
setblock ~86 ~123 ~116 dirt
setblock ~86 ~123 ~117 dirt
setblock ~86 ~123 ~118 dirt
setblock ~86 ~123 ~119 dirt
setblock ~86 ~123 ~120 dirt
setblock ~86 ~123 ~121 dirt
setblock ~86 ~123 ~122 dirt
setblock ~86 ~123 ~123 dirt
setblock ~86 ~123 ~124 dirt
setblock ~86 ~123 ~125 dirt
setblock ~86 ~123 ~126 dirt
setblock ~86 ~123 ~127 dirt
setblock ~86 ~123 ~128 dirt
setblock ~86 ~123 ~129 dirt
setblock ~86 ~123 ~130 dirt
setblock ~86 ~123 ~131 dirt
setblock ~86 ~123 ~132 dirt
setblock ~86 ~123 ~133 dirt
setblock ~86 ~123 ~134 dirt
setblock ~86 ~123 ~135 dirt
setblock ~86 ~123 ~136 dirt
setblock ~86 ~123 ~137 dirt
setblock ~86 ~123 ~138 dirt
setblock ~86 ~123 ~139 dirt
setblock ~86 ~123 ~140 dirt
setblock ~86 ~123 ~141 dirt
setblock ~86 ~123 ~142 dirt
setblock ~86 ~123 ~143 dirt
setblock ~86 ~123 ~144 dirt
setblock ~86 ~123 ~145 dirt
setblock ~86 ~123 ~146 dirt
setblock ~86 ~123 ~147 dirt
setblock ~86 ~123 ~148 dirt
setblock ~86 ~123 ~149 grass_block
setblock ~86 ~123 ~150 grass_block
setblock ~86 ~123 ~151 grass_block
setblock ~86 ~123 ~152 dirt
setblock ~86 ~123 ~153 dirt
setblock ~86 ~123 ~154 dirt
setblock ~86 ~123 ~155 dirt
setblock ~86 ~123 ~156 dirt
setblock ~86 ~123 ~157 dirt
setblock ~86 ~123 ~158 dirt
setblock ~86 ~123 ~159 dirt
setblock ~86 ~123 ~160 dirt
setblock ~86 ~123 ~161 dirt
setblock ~86 ~123 ~162 dirt
setblock ~86 ~123 ~163 dirt
setblock ~86 ~123 ~164 dirt
setblock ~86 ~123 ~165 dirt
setblock ~86 ~123 ~166 dirt
setblock ~86 ~123 ~167 dirt
setblock ~86 ~123 ~168 dirt
setblock ~86 ~123 ~169 dirt
setblock ~86 ~123 ~170 dirt
setblock ~86 ~123 ~171 dirt
setblock ~86 ~123 ~172 dirt
setblock ~86 ~123 ~173 dirt
setblock ~86 ~123 ~174 dirt
setblock ~86 ~123 ~175 dirt
setblock ~86 ~123 ~176 dirt
setblock ~86 ~123 ~177 dirt
setblock ~86 ~123 ~178 dirt
setblock ~86 ~123 ~179 dirt
setblock ~86 ~123 ~180 dirt
setblock ~86 ~123 ~181 dirt
setblock ~86 ~123 ~182 dirt
setblock ~86 ~123 ~183 dirt
setblock ~86 ~123 ~184 dirt
setblock ~86 ~123 ~185 dirt
setblock ~86 ~123 ~186 dirt
setblock ~86 ~123 ~187 dirt
setblock ~86 ~123 ~188 dirt
setblock ~86 ~123 ~189 dirt
setblock ~86 ~123 ~190 dirt
setblock ~86 ~123 ~191 dirt
setblock ~86 ~123 ~192 dirt
setblock ~86 ~123 ~193 dirt
setblock ~86 ~123 ~194 dirt
setblock ~86 ~123 ~195 dirt
setblock ~86 ~123 ~196 dirt
setblock ~86 ~123 ~197 dirt
setblock ~86 ~123 ~198 dirt
setblock ~86 ~123 ~199 grass_block
setblock ~86 ~124 ~0 short_grass
setblock ~86 ~124 ~1 grass_block
setblock ~86 ~124 ~2 grass_block
setblock ~86 ~124 ~3 grass_block
setblock ~86 ~124 ~4 dirt
setblock ~86 ~124 ~5 dirt
setblock ~86 ~124 ~6 dirt
setblock ~86 ~124 ~7 dirt
setblock ~86 ~124 ~8 dirt
setblock ~86 ~124 ~9 dirt
setblock ~86 ~124 ~10 dirt
setblock ~86 ~124 ~11 dirt
setblock ~86 ~124 ~12 dirt
setblock ~86 ~124 ~13 dirt
setblock ~86 ~124 ~14 dirt
setblock ~86 ~124 ~15 dirt
setblock ~86 ~124 ~16 dirt
setblock ~86 ~124 ~17 dirt
setblock ~86 ~124 ~18 dirt
setblock ~86 ~124 ~19 dirt
setblock ~86 ~124 ~20 dirt
setblock ~86 ~124 ~21 dirt
setblock ~86 ~124 ~22 dirt
setblock ~86 ~124 ~23 dirt
setblock ~86 ~124 ~24 dirt
setblock ~86 ~124 ~25 dirt
setblock ~86 ~124 ~26 dirt
setblock ~86 ~124 ~27 dirt
setblock ~86 ~124 ~28 dirt
setblock ~86 ~124 ~29 dirt
setblock ~86 ~124 ~30 dirt
setblock ~86 ~124 ~31 dirt
setblock ~86 ~124 ~32 dirt
setblock ~86 ~124 ~33 dirt
setblock ~86 ~124 ~34 dirt
setblock ~86 ~124 ~35 grass_block
setblock ~86 ~124 ~36 grass_block
setblock ~86 ~124 ~37 grass_block
setblock ~86 ~124 ~38 grass_block
setblock ~86 ~124 ~39 grass_block
setblock ~86 ~124 ~40 grass_block
setblock ~86 ~124 ~41 grass_block
setblock ~86 ~124 ~42 grass_block
setblock ~86 ~124 ~43 grass_block
setblock ~86 ~124 ~44 grass_block
setblock ~86 ~124 ~45 grass_block
setblock ~86 ~124 ~46 grass_block
setblock ~86 ~124 ~47 grass_block
setblock ~86 ~124 ~48 grass_block
setblock ~86 ~124 ~49 grass_block
setblock ~86 ~124 ~50 grass_block
setblock ~86 ~124 ~51 grass_block
setblock ~86 ~124 ~52 grass_block
setblock ~86 ~124 ~53 grass_block
setblock ~86 ~124 ~54 grass_block
setblock ~86 ~124 ~55 grass_block
setblock ~86 ~124 ~56 grass_block
setblock ~86 ~124 ~59 short_grass
setblock ~86 ~124 ~62 short_grass
setblock ~86 ~124 ~63 short_grass
setblock ~86 ~124 ~64 poppy
setblock ~86 ~124 ~66 fern
setblock ~86 ~124 ~75 grass_block
setblock ~86 ~124 ~76 grass_block
setblock ~86 ~124 ~77 grass_block
setblock ~86 ~124 ~78 grass_block
setblock ~86 ~124 ~79 grass_block
setblock ~86 ~124 ~80 grass_block
setblock ~86 ~124 ~81 grass_block
setblock ~86 ~124 ~82 grass_block
setblock ~86 ~124 ~83 dirt
setblock ~86 ~124 ~84 dirt
setblock ~86 ~124 ~85 dirt
setblock ~86 ~124 ~86 dirt
setblock ~86 ~124 ~87 dirt
setblock ~86 ~124 ~88 dirt
setblock ~86 ~124 ~89 dirt
setblock ~86 ~124 ~90 dirt
setblock ~86 ~124 ~91 dirt
setblock ~86 ~124 ~92 dirt
setblock ~86 ~124 ~93 dirt
setblock ~86 ~124 ~94 dirt
setblock ~86 ~124 ~95 dirt
setblock ~86 ~124 ~96 dirt
setblock ~86 ~124 ~97 dirt
setblock ~86 ~124 ~98 dirt
setblock ~86 ~124 ~99 dirt
setblock ~86 ~124 ~100 dirt
setblock ~86 ~124 ~101 dirt
setblock ~86 ~124 ~102 dirt
setblock ~86 ~124 ~103 dirt
setblock ~86 ~124 ~104 dirt
setblock ~86 ~124 ~105 dirt
setblock ~86 ~124 ~106 dirt
setblock ~86 ~124 ~107 dirt
setblock ~86 ~124 ~108 dirt
setblock ~86 ~124 ~109 dirt
setblock ~86 ~124 ~110 dirt
setblock ~86 ~124 ~111 dirt
setblock ~86 ~124 ~112 dirt
setblock ~86 ~124 ~113 dirt
setblock ~86 ~124 ~114 dirt
setblock ~86 ~124 ~115 dirt
setblock ~86 ~124 ~116 dirt
setblock ~86 ~124 ~117 dirt
setblock ~86 ~124 ~118 dirt
setblock ~86 ~124 ~119 grass_block
setblock ~86 ~124 ~120 grass_block
setblock ~86 ~124 ~121 dirt
setblock ~86 ~124 ~122 dirt
setblock ~86 ~124 ~123 dirt
setblock ~86 ~124 ~124 dirt
setblock ~86 ~124 ~125 dirt
setblock ~86 ~124 ~126 dirt
setblock ~86 ~124 ~127 dirt
setblock ~86 ~124 ~128 dirt
setblock ~86 ~124 ~129 dirt
setblock ~86 ~124 ~130 dirt
setblock ~86 ~124 ~131 dirt
setblock ~86 ~124 ~132 dirt
setblock ~86 ~124 ~133 dirt
setblock ~86 ~124 ~134 dirt
setblock ~86 ~124 ~135 dirt
setblock ~86 ~124 ~136 dirt
setblock ~86 ~124 ~137 dirt
setblock ~86 ~124 ~138 dirt
setblock ~86 ~124 ~139 dirt
setblock ~86 ~124 ~140 dirt
setblock ~86 ~124 ~141 dirt
setblock ~86 ~124 ~142 dirt
setblock ~86 ~124 ~143 dirt
setblock ~86 ~124 ~144 dirt
setblock ~86 ~124 ~145 grass_block
setblock ~86 ~124 ~146 grass_block
setblock ~86 ~124 ~147 grass_block
setblock ~86 ~124 ~148 grass_block
setblock ~86 ~124 ~152 grass_block
setblock ~86 ~124 ~153 grass_block
setblock ~86 ~124 ~154 dirt
setblock ~86 ~124 ~155 dirt
setblock ~86 ~124 ~156 dirt
setblock ~86 ~124 ~157 dirt
setblock ~86 ~124 ~158 dirt
setblock ~86 ~124 ~159 dirt
setblock ~86 ~124 ~160 dirt
setblock ~86 ~124 ~161 dirt
setblock ~86 ~124 ~162 dirt
setblock ~86 ~124 ~163 dirt
setblock ~86 ~124 ~164 dirt
setblock ~86 ~124 ~165 dirt
setblock ~86 ~124 ~166 dirt
setblock ~86 ~124 ~167 dirt
setblock ~86 ~124 ~168 dirt
setblock ~86 ~124 ~169 dirt
setblock ~86 ~124 ~170 grass_block
setblock ~86 ~124 ~171 grass_block
setblock ~86 ~124 ~172 grass_block
setblock ~86 ~124 ~173 grass_block
setblock ~86 ~124 ~174 grass_block
setblock ~86 ~124 ~175 grass_block
setblock ~86 ~124 ~176 grass_block
setblock ~86 ~124 ~177 grass_block
setblock ~86 ~124 ~178 grass_block
setblock ~86 ~124 ~179 grass_block
setblock ~86 ~124 ~180 grass_block
setblock ~86 ~124 ~181 grass_block
setblock ~86 ~124 ~182 dirt
setblock ~86 ~124 ~183 dirt
setblock ~86 ~124 ~184 dirt
setblock ~86 ~124 ~185 dirt
setblock ~86 ~124 ~186 dirt
setblock ~86 ~124 ~187 dirt
setblock ~86 ~124 ~188 dirt
setblock ~86 ~124 ~189 dirt
setblock ~86 ~124 ~190 dirt
setblock ~86 ~124 ~191 dirt
setblock ~86 ~124 ~192 dirt
setblock ~86 ~124 ~193 dirt
setblock ~86 ~124 ~194 dirt
setblock ~86 ~124 ~195 dirt
setblock ~86 ~124 ~196 dirt
setblock ~86 ~124 ~197 grass_block
setblock ~86 ~124 ~198 grass_block
setblock ~86 ~124 ~199 short_grass
setblock ~86 ~125 ~2 poppy
setblock ~86 ~125 ~3 short_grass
setblock ~86 ~125 ~4 grass_block
setblock ~86 ~125 ~5 grass_block
setblock ~86 ~125 ~6 grass_block
setblock ~86 ~125 ~7 dirt
setblock ~86 ~125 ~8 dirt
setblock ~86 ~125 ~9 dirt
setblock ~86 ~125 ~10 dirt
setblock ~86 ~125 ~11 dirt
setblock ~86 ~125 ~12 dirt
setblock ~86 ~125 ~13 dirt
setblock ~86 ~125 ~14 dirt
setblock ~86 ~125 ~15 dirt
setblock ~86 ~125 ~16 dirt
setblock ~86 ~125 ~17 dirt
setblock ~86 ~125 ~18 dirt
setblock ~86 ~125 ~19 dirt
setblock ~86 ~125 ~20 dirt
setblock ~86 ~125 ~21 dirt
setblock ~86 ~125 ~22 dirt
setblock ~86 ~125 ~23 dirt
setblock ~86 ~125 ~24 dirt
setblock ~86 ~125 ~25 dirt
setblock ~86 ~125 ~26 dirt
setblock ~86 ~125 ~27 dirt
setblock ~86 ~125 ~28 dirt
setblock ~86 ~125 ~29 grass_block
setblock ~86 ~125 ~30 grass_block
setblock ~86 ~125 ~31 grass_block
setblock ~86 ~125 ~32 grass_block
setblock ~86 ~125 ~33 grass_block
setblock ~86 ~125 ~34 grass_block
setblock ~86 ~125 ~38 short_grass
setblock ~86 ~125 ~39 short_grass
setblock ~86 ~125 ~41 poppy
setblock ~86 ~125 ~42 short_grass
setblock ~86 ~125 ~43 short_grass
setblock ~86 ~125 ~44 short_grass
setblock ~86 ~125 ~49 fern
setblock ~86 ~125 ~55 poppy
setblock ~86 ~125 ~76 short_grass
setblock ~86 ~125 ~83 grass_block
setblock ~86 ~125 ~84 grass_block
setblock ~86 ~125 ~85 grass_block
setblock ~86 ~125 ~86 grass_block
setblock ~86 ~125 ~87 grass_block
setblock ~86 ~125 ~88 grass_block
setblock ~86 ~125 ~89 grass_block
setblock ~86 ~125 ~90 dirt
setblock ~86 ~125 ~91 grass_block
setblock ~86 ~125 ~92 grass_block
setblock ~86 ~125 ~93 grass_block
setblock ~86 ~125 ~94 grass_block
setblock ~86 ~125 ~95 grass_block
setblock ~86 ~125 ~96 grass_block
setblock ~86 ~125 ~97 grass_block
setblock ~86 ~125 ~98 grass_block
setblock ~86 ~125 ~99 grass_block
setblock ~86 ~125 ~100 grass_block
setblock ~86 ~125 ~101 grass_block
setblock ~86 ~125 ~102 grass_block
setblock ~86 ~125 ~103 grass_block
setblock ~86 ~125 ~104 grass_block
setblock ~86 ~125 ~105 grass_block
setblock ~86 ~125 ~106 grass_block
setblock ~86 ~125 ~107 grass_block
setblock ~86 ~125 ~108 grass_block
setblock ~86 ~125 ~109 grass_block
setblock ~86 ~125 ~110 grass_block
setblock ~86 ~125 ~111 grass_block
setblock ~86 ~125 ~112 grass_block
setblock ~86 ~125 ~113 grass_block
setblock ~86 ~125 ~114 grass_block
setblock ~86 ~125 ~115 grass_block
setblock ~86 ~125 ~116 grass_block
setblock ~86 ~125 ~117 grass_block
setblock ~86 ~125 ~118 grass_block
setblock ~86 ~125 ~121 grass_block
setblock ~86 ~125 ~122 grass_block
setblock ~86 ~125 ~123 grass_block
setblock ~86 ~125 ~124 grass_block
setblock ~86 ~125 ~125 grass_block
setblock ~86 ~125 ~126 grass_block
setblock ~86 ~125 ~127 grass_block
setblock ~86 ~125 ~128 dirt
setblock ~86 ~125 ~129 dirt
setblock ~86 ~125 ~130 dirt
setblock ~86 ~125 ~131 dirt
setblock ~86 ~125 ~132 dirt
setblock ~86 ~125 ~133 dirt
setblock ~86 ~125 ~134 dirt
setblock ~86 ~125 ~135 dirt
setblock ~86 ~125 ~136 dirt
setblock ~86 ~125 ~137 dirt
setblock ~86 ~125 ~138 dirt
setblock ~86 ~125 ~139 dirt
setblock ~86 ~125 ~140 dirt
setblock ~86 ~125 ~141 dirt
setblock ~86 ~125 ~142 grass_block
setblock ~86 ~125 ~143 grass_block
setblock ~86 ~125 ~144 grass_block
setblock ~86 ~125 ~145 short_grass
setblock ~86 ~125 ~148 short_grass
setblock ~86 ~125 ~154 grass_block
setblock ~86 ~125 ~155 grass_block
setblock ~86 ~125 ~156 dirt
setblock ~86 ~125 ~157 dirt
setblock ~86 ~125 ~158 dirt
setblock ~86 ~125 ~159 dirt
setblock ~86 ~125 ~160 dirt
setblock ~86 ~125 ~161 dirt
setblock ~86 ~125 ~162 dirt
setblock ~86 ~125 ~163 dirt
setblock ~86 ~125 ~164 dirt
setblock ~86 ~125 ~165 dirt
setblock ~86 ~125 ~166 dirt
setblock ~86 ~125 ~167 grass_block
setblock ~86 ~125 ~168 grass_block
setblock ~86 ~125 ~169 grass_block
setblock ~86 ~125 ~171 short_grass
setblock ~86 ~125 ~172 short_grass
setblock ~86 ~125 ~173 short_grass
setblock ~86 ~125 ~175 poppy
setblock ~86 ~125 ~179 short_grass
setblock ~86 ~125 ~182 grass_block
setblock ~86 ~125 ~183 grass_block
setblock ~86 ~125 ~184 grass_block
setblock ~86 ~125 ~185 dirt
setblock ~86 ~125 ~186 dirt
setblock ~86 ~125 ~187 dirt
setblock ~86 ~125 ~188 dirt
setblock ~86 ~125 ~189 dirt
setblock ~86 ~125 ~190 dirt
setblock ~86 ~125 ~191 dirt
setblock ~86 ~125 ~192 dirt
setblock ~86 ~125 ~193 dirt
setblock ~86 ~125 ~194 dirt
setblock ~86 ~125 ~195 grass_block
setblock ~86 ~125 ~196 grass_block
setblock ~86 ~125 ~197 fern
setblock ~86 ~126 ~5 short_grass
setblock ~86 ~126 ~7 grass_block
setblock ~86 ~126 ~8 grass_block
setblock ~86 ~126 ~9 grass_block
setblock ~86 ~126 ~10 dirt
setblock ~86 ~126 ~11 dirt
setblock ~86 ~126 ~12 grass_block
setblock ~86 ~126 ~13 grass_block
setblock ~86 ~126 ~14 grass_block
setblock ~86 ~126 ~15 grass_block
setblock ~86 ~126 ~16 grass_block
setblock ~86 ~126 ~17 grass_block
setblock ~86 ~126 ~18 grass_block
setblock ~86 ~126 ~19 grass_block
setblock ~86 ~126 ~20 grass_block
setblock ~86 ~126 ~21 grass_block
setblock ~86 ~126 ~22 grass_block
setblock ~86 ~126 ~23 grass_block
setblock ~86 ~126 ~24 grass_block
setblock ~86 ~126 ~25 grass_block
setblock ~86 ~126 ~26 grass_block
setblock ~86 ~126 ~27 grass_block
setblock ~86 ~126 ~28 grass_block
setblock ~86 ~126 ~29 short_grass
setblock ~86 ~126 ~32 short_grass
setblock ~86 ~126 ~33 fern
setblock ~86 ~126 ~83 short_grass
setblock ~86 ~126 ~84 short_grass
setblock ~86 ~126 ~90 grass_block
setblock ~86 ~126 ~92 short_grass
setblock ~86 ~126 ~94 short_grass
setblock ~86 ~126 ~95 short_grass
setblock ~86 ~126 ~108 short_grass
setblock ~86 ~126 ~109 short_grass
setblock ~86 ~126 ~110 fern
setblock ~86 ~126 ~118 poppy
setblock ~86 ~126 ~127 poppy
setblock ~86 ~126 ~128 grass_block
setblock ~86 ~126 ~129 grass_block
setblock ~86 ~126 ~130 grass_block
setblock ~86 ~126 ~131 grass_block
setblock ~86 ~126 ~132 grass_block
setblock ~86 ~126 ~133 grass_block
setblock ~86 ~126 ~134 grass_block
setblock ~86 ~126 ~135 grass_block
setblock ~86 ~126 ~136 grass_block
setblock ~86 ~126 ~137 grass_block
setblock ~86 ~126 ~138 grass_block
setblock ~86 ~126 ~139 grass_block
setblock ~86 ~126 ~140 grass_block
setblock ~86 ~126 ~141 grass_block
setblock ~86 ~126 ~156 grass_block
setblock ~86 ~126 ~157 grass_block
setblock ~86 ~126 ~158 dirt
setblock ~86 ~126 ~159 dirt
setblock ~86 ~126 ~160 dirt
setblock ~86 ~126 ~161 dirt
setblock ~86 ~126 ~162 dirt
setblock ~86 ~126 ~163 dirt
setblock ~86 ~126 ~164 dirt
setblock ~86 ~126 ~165 grass_block
setblock ~86 ~126 ~166 grass_block
setblock ~86 ~126 ~167 short_grass
setblock ~86 ~126 ~185 grass_block
setblock ~86 ~126 ~186 grass_block
setblock ~86 ~126 ~187 grass_block
setblock ~86 ~126 ~188 grass_block
setblock ~86 ~126 ~189 dirt
setblock ~86 ~126 ~190 dirt
setblock ~86 ~126 ~191 dirt
setblock ~86 ~126 ~192 grass_block
setblock ~86 ~126 ~193 grass_block
setblock ~86 ~126 ~194 grass_block
setblock ~86 ~126 ~195 short_grass
setblock ~86 ~127 ~8 short_grass
setblock ~86 ~127 ~10 grass_block
setblock ~86 ~127 ~11 grass_block
setblock ~86 ~127 ~15 short_grass
setblock ~86 ~127 ~20 short_grass
setblock ~86 ~127 ~21 fern
setblock ~86 ~127 ~22 short_grass
setblock ~86 ~127 ~23 short_grass
setblock ~86 ~127 ~24 short_grass
setblock ~86 ~127 ~25 short_grass
setblock ~86 ~127 ~130 short_grass
setblock ~86 ~127 ~156 fern
setblock ~86 ~127 ~157 fern
setblock ~86 ~127 ~158 grass_block
setblock ~86 ~127 ~159 grass_block
setblock ~86 ~127 ~160 dirt
setblock ~86 ~127 ~161 dirt
setblock ~86 ~127 ~162 grass_block
setblock ~86 ~127 ~163 grass_block
setblock ~86 ~127 ~164 grass_block
setblock ~86 ~127 ~165 short_grass
setblock ~86 ~127 ~186 short_grass
setblock ~86 ~127 ~189 grass_block
setblock ~86 ~127 ~190 grass_block
setblock ~86 ~127 ~191 grass_block
setblock ~86 ~127 ~193 short_grass
setblock ~86 ~128 ~10 short_grass
setblock ~86 ~128 ~158 short_grass
setblock ~86 ~128 ~159 poppy
setblock ~86 ~128 ~160 grass_block
setblock ~86 ~128 ~161 grass_block
setblock ~87 ~122 ~0 dirt
setblock ~87 ~122 ~1 dirt
setblock ~87 ~122 ~2 dirt
setblock ~87 ~122 ~3 dirt
setblock ~87 ~122 ~4 dirt
setblock ~87 ~122 ~5 dirt
setblock ~87 ~122 ~6 dirt
setblock ~87 ~122 ~7 dirt
setblock ~87 ~122 ~8 dirt
setblock ~87 ~122 ~9 dirt
setblock ~87 ~122 ~10 dirt
setblock ~87 ~122 ~11 dirt
setblock ~87 ~122 ~12 dirt
setblock ~87 ~122 ~13 dirt
setblock ~87 ~122 ~14 dirt
setblock ~87 ~122 ~15 dirt
setblock ~87 ~122 ~16 dirt
setblock ~87 ~122 ~17 dirt
setblock ~87 ~122 ~18 dirt
setblock ~87 ~122 ~19 dirt
setblock ~87 ~122 ~20 dirt
setblock ~87 ~122 ~21 dirt
setblock ~87 ~122 ~22 dirt
setblock ~87 ~122 ~23 dirt
setblock ~87 ~122 ~24 dirt
setblock ~87 ~122 ~25 dirt
setblock ~87 ~122 ~26 dirt
setblock ~87 ~122 ~27 dirt
setblock ~87 ~122 ~28 dirt
setblock ~87 ~122 ~29 dirt
setblock ~87 ~122 ~30 dirt
setblock ~87 ~122 ~31 dirt
setblock ~87 ~122 ~32 dirt
setblock ~87 ~122 ~33 dirt
setblock ~87 ~122 ~34 dirt
setblock ~87 ~122 ~35 dirt
setblock ~87 ~122 ~36 dirt
setblock ~87 ~122 ~37 dirt
setblock ~87 ~122 ~38 dirt
setblock ~87 ~122 ~39 dirt
setblock ~87 ~122 ~40 dirt
setblock ~87 ~122 ~41 dirt
setblock ~87 ~122 ~42 dirt
setblock ~87 ~122 ~43 dirt
setblock ~87 ~122 ~44 dirt
setblock ~87 ~122 ~45 dirt
setblock ~87 ~122 ~46 dirt
setblock ~87 ~122 ~47 dirt
setblock ~87 ~122 ~48 dirt
setblock ~87 ~122 ~49 dirt
setblock ~87 ~122 ~50 dirt
setblock ~87 ~122 ~51 dirt
setblock ~87 ~122 ~52 dirt
setblock ~87 ~122 ~53 dirt
setblock ~87 ~122 ~54 dirt
setblock ~87 ~122 ~55 dirt
setblock ~87 ~122 ~56 dirt
setblock ~87 ~122 ~57 dirt
setblock ~87 ~122 ~58 dirt
setblock ~87 ~122 ~59 dirt
setblock ~87 ~122 ~60 dirt
setblock ~87 ~122 ~61 dirt
setblock ~87 ~122 ~62 dirt
setblock ~87 ~122 ~63 dirt
setblock ~87 ~122 ~64 dirt
setblock ~87 ~122 ~65 dirt
setblock ~87 ~122 ~66 dirt
setblock ~87 ~122 ~67 dirt
setblock ~87 ~122 ~68 dirt
setblock ~87 ~122 ~69 dirt
setblock ~87 ~122 ~70 dirt
setblock ~87 ~122 ~71 dirt
setblock ~87 ~122 ~72 dirt
setblock ~87 ~122 ~73 dirt
setblock ~87 ~122 ~74 dirt
setblock ~87 ~122 ~75 dirt
setblock ~87 ~122 ~76 dirt
setblock ~87 ~122 ~77 dirt
setblock ~87 ~122 ~78 dirt
setblock ~87 ~122 ~79 dirt
setblock ~87 ~122 ~80 dirt
