setblock ~164 ~121 ~92 dirt
setblock ~164 ~121 ~93 dirt
setblock ~164 ~121 ~94 dirt
setblock ~164 ~121 ~95 dirt
setblock ~164 ~121 ~96 dirt
setblock ~164 ~121 ~97 dirt
setblock ~164 ~121 ~98 dirt
setblock ~164 ~121 ~99 dirt
setblock ~164 ~121 ~100 dirt
setblock ~164 ~121 ~101 dirt
setblock ~164 ~121 ~102 dirt
setblock ~164 ~121 ~103 dirt
setblock ~164 ~121 ~104 dirt
setblock ~164 ~121 ~105 dirt
setblock ~164 ~121 ~106 dirt
setblock ~164 ~121 ~107 dirt
setblock ~164 ~121 ~108 dirt
setblock ~164 ~121 ~109 dirt
setblock ~164 ~121 ~110 dirt
setblock ~164 ~121 ~111 dirt
setblock ~164 ~121 ~112 dirt
setblock ~164 ~121 ~121 dirt
setblock ~164 ~121 ~122 dirt
setblock ~164 ~121 ~123 dirt
setblock ~164 ~121 ~124 dirt
setblock ~164 ~121 ~125 dirt
setblock ~164 ~121 ~128 dirt
setblock ~164 ~121 ~129 dirt
setblock ~164 ~122 ~67 dirt
setblock ~164 ~122 ~68 dirt
setblock ~164 ~122 ~69 dirt
setblock ~164 ~122 ~70 dirt
setblock ~164 ~122 ~71 dirt
setblock ~164 ~122 ~72 dirt
setblock ~164 ~122 ~73 dirt
setblock ~164 ~122 ~74 dirt
setblock ~164 ~122 ~75 dirt
setblock ~164 ~122 ~76 dirt
setblock ~164 ~122 ~77 dirt
setblock ~164 ~122 ~78 dirt
setblock ~164 ~122 ~79 dirt
setblock ~164 ~122 ~80 dirt
setblock ~164 ~122 ~81 dirt
setblock ~164 ~122 ~82 dirt
setblock ~164 ~122 ~83 dirt
setblock ~164 ~122 ~84 dirt
setblock ~164 ~122 ~85 dirt
setblock ~164 ~122 ~86 dirt
setblock ~164 ~122 ~87 dirt
setblock ~164 ~122 ~90 dirt
setblock ~164 ~122 ~91 dirt
setblock ~164 ~122 ~92 dirt
setblock ~164 ~122 ~93 dirt
setblock ~164 ~122 ~94 dirt
setblock ~164 ~122 ~95 dirt
setblock ~164 ~122 ~96 dirt
setblock ~164 ~122 ~97 dirt
setblock ~164 ~122 ~98 dirt
setblock ~164 ~122 ~99 dirt
setblock ~164 ~122 ~100 dirt
setblock ~164 ~122 ~101 dirt
setblock ~164 ~122 ~102 dirt
setblock ~164 ~122 ~103 dirt
setblock ~164 ~122 ~104 dirt
setblock ~164 ~122 ~105 dirt
setblock ~164 ~122 ~106 dirt
setblock ~164 ~122 ~107 dirt
setblock ~164 ~122 ~108 dirt
setblock ~164 ~122 ~109 dirt
setblock ~164 ~122 ~110 dirt
setblock ~164 ~122 ~111 dirt
setblock ~164 ~122 ~112 dirt
setblock ~164 ~122 ~121 dirt
setblock ~164 ~122 ~122 dirt
setblock ~164 ~122 ~123 dirt
setblock ~164 ~122 ~124 dirt
setblock ~164 ~122 ~125 dirt
setblock ~164 ~122 ~128 dirt
setblock ~164 ~122 ~129 dirt
setblock ~164 ~123 ~67 dirt
setblock ~164 ~123 ~68 dirt
setblock ~164 ~123 ~69 dirt
setblock ~164 ~123 ~70 dirt
setblock ~164 ~123 ~71 dirt
setblock ~164 ~123 ~72 dirt
setblock ~164 ~123 ~73 dirt
setblock ~164 ~123 ~74 dirt
setblock ~164 ~123 ~75 dirt
setblock ~164 ~123 ~76 dirt
setblock ~164 ~123 ~77 dirt
setblock ~164 ~123 ~78 dirt
setblock ~164 ~123 ~79 dirt
setblock ~164 ~123 ~80 dirt
setblock ~164 ~123 ~81 dirt
setblock ~164 ~123 ~82 dirt
setblock ~164 ~123 ~83 dirt
setblock ~164 ~123 ~84 dirt
setblock ~164 ~123 ~85 dirt
setblock ~164 ~123 ~86 dirt
setblock ~164 ~123 ~87 dirt
setblock ~164 ~123 ~90 dirt
setblock ~164 ~123 ~91 dirt
setblock ~164 ~123 ~92 dirt
setblock ~164 ~123 ~93 dirt
setblock ~164 ~123 ~94 dirt
setblock ~164 ~123 ~95 dirt
setblock ~164 ~123 ~96 dirt
setblock ~164 ~123 ~97 dirt
setblock ~164 ~123 ~98 dirt
setblock ~164 ~123 ~99 dirt
setblock ~164 ~123 ~100 dirt
setblock ~164 ~123 ~101 dirt
setblock ~164 ~123 ~102 dirt
setblock ~164 ~123 ~103 dirt
setblock ~164 ~123 ~104 dirt
setblock ~164 ~123 ~105 dirt
setblock ~164 ~123 ~106 dirt
setblock ~164 ~123 ~107 dirt
setblock ~164 ~123 ~108 dirt
setblock ~164 ~123 ~109 dirt
setblock ~164 ~123 ~110 dirt
setblock ~164 ~123 ~111 dirt
setblock ~164 ~123 ~112 dirt
setblock ~164 ~123 ~121 dirt
setblock ~164 ~123 ~122 dirt
setblock ~164 ~123 ~123 dirt
setblock ~164 ~123 ~124 dirt
setblock ~164 ~123 ~125 dirt
setblock ~164 ~123 ~128 dirt
setblock ~164 ~123 ~129 dirt
setblock ~164 ~124 ~67 dirt
setblock ~164 ~124 ~68 dirt
setblock ~164 ~124 ~69 dirt
setblock ~164 ~124 ~70 dirt
setblock ~164 ~124 ~71 dirt
setblock ~164 ~124 ~72 dirt
setblock ~164 ~124 ~73 dirt
setblock ~164 ~124 ~74 dirt
setblock ~164 ~124 ~75 dirt
setblock ~164 ~124 ~76 dirt
setblock ~164 ~124 ~77 dirt
setblock ~164 ~124 ~78 grass_block
setblock ~164 ~124 ~79 grass_block
setblock ~164 ~124 ~80 grass_block
setblock ~164 ~124 ~81 grass_block
setblock ~164 ~124 ~82 dirt
setblock ~164 ~124 ~83 dirt
setblock ~164 ~124 ~84 dirt
setblock ~164 ~124 ~85 dirt
setblock ~164 ~124 ~86 dirt
setblock ~164 ~124 ~87 dirt
setblock ~164 ~124 ~90 dirt
setblock ~164 ~124 ~91 dirt
setblock ~164 ~124 ~92 dirt
setblock ~164 ~124 ~93 dirt
setblock ~164 ~124 ~94 dirt
setblock ~164 ~124 ~95 dirt
setblock ~164 ~124 ~96 dirt
setblock ~164 ~124 ~97 dirt
setblock ~164 ~124 ~98 dirt
setblock ~164 ~124 ~99 dirt
setblock ~164 ~124 ~100 dirt
setblock ~164 ~124 ~101 dirt
setblock ~164 ~124 ~102 dirt
setblock ~164 ~124 ~103 dirt
setblock ~164 ~124 ~104 dirt
setblock ~164 ~124 ~105 dirt
setblock ~164 ~124 ~106 dirt
setblock ~164 ~124 ~107 dirt
setblock ~164 ~124 ~108 dirt
setblock ~164 ~124 ~109 grass_block
setblock ~164 ~124 ~110 grass_block
setblock ~164 ~124 ~111 grass_block
setblock ~164 ~124 ~112 grass_block
setblock ~164 ~124 ~121 grass_block
setblock ~164 ~124 ~122 grass_block
setblock ~164 ~124 ~123 grass_block
setblock ~164 ~124 ~124 grass_block
setblock ~164 ~124 ~125 grass_block
setblock ~164 ~124 ~128 grass_block
setblock ~164 ~124 ~129 grass_block
setblock ~164 ~125 ~67 grass_block
setblock ~164 ~125 ~68 grass_block
setblock ~164 ~125 ~69 dirt
setblock ~164 ~125 ~70 dirt
setblock ~164 ~125 ~71 dirt
setblock ~164 ~125 ~72 grass_block
setblock ~164 ~125 ~73 grass_block
setblock ~164 ~125 ~74 grass_block
setblock ~164 ~125 ~75 grass_block
setblock ~164 ~125 ~76 grass_block
setblock ~164 ~125 ~77 grass_block
setblock ~164 ~125 ~80 short_grass
setblock ~164 ~125 ~82 grass_block
setblock ~164 ~125 ~83 grass_block
setblock ~164 ~125 ~84 grass_block
setblock ~164 ~125 ~85 grass_block
setblock ~164 ~125 ~86 grass_block
setblock ~164 ~125 ~87 grass_block
setblock ~164 ~125 ~90 grass_block
setblock ~164 ~125 ~91 grass_block
setblock ~164 ~125 ~92 grass_block
setblock ~164 ~125 ~93 grass_block
setblock ~164 ~125 ~94 grass_block
setblock ~164 ~125 ~95 grass_block
setblock ~164 ~125 ~96 grass_block
setblock ~164 ~125 ~97 grass_block
setblock ~164 ~125 ~98 grass_block
setblock ~164 ~125 ~99 grass_block
setblock ~164 ~125 ~100 grass_block
setblock ~164 ~125 ~101 grass_block
setblock ~164 ~125 ~102 grass_block
setblock ~164 ~125 ~103 grass_block
setblock ~164 ~125 ~104 grass_block
setblock ~164 ~125 ~105 grass_block
setblock ~164 ~125 ~106 grass_block
setblock ~164 ~125 ~107 grass_block
setblock ~164 ~125 ~108 grass_block
setblock ~164 ~125 ~112 short_grass
setblock ~164 ~126 ~68 poppy
setblock ~164 ~126 ~69 grass_block
setblock ~164 ~126 ~70 grass_block
setblock ~164 ~126 ~71 grass_block
setblock ~164 ~126 ~75 short_grass
setblock ~164 ~126 ~91 short_grass
setblock ~164 ~126 ~94 short_grass
setblock ~164 ~126 ~95 fern
setblock ~164 ~126 ~99 fern
setblock ~164 ~126 ~106 poppy
setblock ~164 ~134 ~74 oak_leaves[persistent=true]
setblock ~164 ~134 ~75 oak_leaves[persistent=true]
setblock ~164 ~135 ~74 oak_leaves[persistent=true]
setblock ~164 ~135 ~75 jungle_leaves[persistent=true]
setblock ~164 ~135 ~76 oak_wood
setblock ~164 ~135 ~77 oak_leaves[persistent=true]
setblock ~164 ~135 ~79 oak_leaves[persistent=true]
setblock ~164 ~135 ~81 oak_leaves[persistent=true]
setblock ~164 ~135 ~82 oak_leaves[persistent=true]
setblock ~164 ~136 ~75 oak_leaves[persistent=true]
setblock ~164 ~136 ~76 oak_leaves[persistent=true]
setblock ~164 ~136 ~77 oak_leaves[persistent=true]
setblock ~164 ~136 ~79 oak_leaves[persistent=true]
setblock ~164 ~136 ~80 oak_leaves[persistent=true]
setblock ~164 ~136 ~81 oak_leaves[persistent=true]
setblock ~164 ~136 ~82 oak_leaves[persistent=true]
setblock ~164 ~137 ~74 oak_leaves[persistent=true]
setblock ~164 ~137 ~75 oak_leaves[persistent=true]
setblock ~164 ~137 ~76 oak_leaves[persistent=true]
setblock ~164 ~137 ~77 oak_leaves[persistent=true]
setblock ~164 ~137 ~79 jungle_leaves[persistent=true]
setblock ~164 ~137 ~80 oak_wood
setblock ~164 ~137 ~81 oak_leaves[persistent=true]
setblock ~164 ~137 ~82 oak_leaves[persistent=true]
setblock ~164 ~138 ~74 oak_leaves[persistent=true]
setblock ~164 ~138 ~75 oak_leaves[persistent=true]
setblock ~164 ~138 ~76 oak_leaves[persistent=true]
setblock ~164 ~138 ~77 jungle_leaves[persistent=true]
setblock ~164 ~138 ~79 oak_leaves[persistent=true]
setblock ~164 ~138 ~80 jungle_leaves[persistent=true]
setblock ~164 ~138 ~81 oak_leaves[persistent=true]
setblock ~164 ~138 ~82 jungle_leaves[persistent=true]
setblock ~164 ~139 ~74 jungle_leaves[persistent=true]
setblock ~164 ~139 ~75 jungle_leaves[persistent=true]
setblock ~164 ~139 ~76 jungle_leaves[persistent=true]
setblock ~164 ~139 ~77 oak_leaves[persistent=true]
setblock ~165 ~109 ~78 dirt
setblock ~165 ~110 ~76 dirt
setblock ~165 ~110 ~77 dirt
setblock ~165 ~110 ~78 dirt
setblock ~165 ~111 ~75 dirt
setblock ~165 ~111 ~76 dirt
setblock ~165 ~111 ~77 dirt
setblock ~165 ~111 ~78 dirt
setblock ~165 ~111 ~79 dirt
setblock ~165 ~111 ~81 dirt
setblock ~165 ~112 ~73 dirt
setblock ~165 ~112 ~74 dirt
setblock ~165 ~112 ~75 dirt
setblock ~165 ~112 ~76 dirt
setblock ~165 ~112 ~77 dirt
setblock ~165 ~112 ~78 dirt
setblock ~165 ~112 ~79 dirt
setblock ~165 ~112 ~80 dirt
setblock ~165 ~112 ~81 dirt
setblock ~165 ~112 ~82 dirt
setblock ~165 ~113 ~72 dirt
setblock ~165 ~113 ~73 dirt
setblock ~165 ~113 ~74 dirt
setblock ~165 ~113 ~75 dirt
setblock ~165 ~113 ~76 dirt
setblock ~165 ~113 ~77 dirt
setblock ~165 ~113 ~78 dirt
setblock ~165 ~113 ~79 dirt
setblock ~165 ~113 ~80 dirt
setblock ~165 ~113 ~81 dirt
setblock ~165 ~113 ~82 dirt
setblock ~165 ~114 ~71 dirt
setblock ~165 ~114 ~72 dirt
setblock ~165 ~114 ~73 dirt
setblock ~165 ~114 ~74 dirt
setblock ~165 ~114 ~75 dirt
setblock ~165 ~114 ~76 dirt
setblock ~165 ~114 ~77 dirt
setblock ~165 ~114 ~78 dirt
setblock ~165 ~114 ~79 dirt
setblock ~165 ~114 ~80 dirt
setblock ~165 ~114 ~81 dirt
setblock ~165 ~114 ~82 dirt
setblock ~165 ~114 ~105 dirt
setblock ~165 ~114 ~106 dirt
setblock ~165 ~114 ~107 dirt
setblock ~165 ~115 ~71 dirt
setblock ~165 ~115 ~72 dirt
setblock ~165 ~115 ~73 dirt
setblock ~165 ~115 ~74 dirt
setblock ~165 ~115 ~75 dirt
setblock ~165 ~115 ~76 dirt
setblock ~165 ~115 ~77 dirt
setblock ~165 ~115 ~78 dirt
setblock ~165 ~115 ~79 dirt
setblock ~165 ~115 ~80 dirt
setblock ~165 ~115 ~81 dirt
setblock ~165 ~115 ~82 dirt
setblock ~165 ~115 ~83 dirt
setblock ~165 ~115 ~105 dirt
setblock ~165 ~115 ~106 dirt
setblock ~165 ~115 ~107 dirt
setblock ~165 ~115 ~108 dirt
setblock ~165 ~116 ~71 dirt
setblock ~165 ~116 ~72 dirt
setblock ~165 ~116 ~73 dirt
setblock ~165 ~116 ~74 dirt
setblock ~165 ~116 ~75 dirt
setblock ~165 ~116 ~76 dirt
setblock ~165 ~116 ~77 dirt
setblock ~165 ~116 ~78 dirt
setblock ~165 ~116 ~79 dirt
setblock ~165 ~116 ~80 dirt
setblock ~165 ~116 ~81 dirt
setblock ~165 ~116 ~82 dirt
setblock ~165 ~116 ~83 dirt
setblock ~165 ~116 ~84 dirt
setblock ~165 ~116 ~104 dirt
setblock ~165 ~116 ~105 dirt
setblock ~165 ~116 ~106 dirt
setblock ~165 ~116 ~107 dirt
setblock ~165 ~116 ~108 dirt
setblock ~165 ~117 ~70 dirt
setblock ~165 ~117 ~71 dirt
setblock ~165 ~117 ~72 dirt
setblock ~165 ~117 ~73 dirt
setblock ~165 ~117 ~74 dirt
setblock ~165 ~117 ~75 dirt
setblock ~165 ~117 ~76 dirt
setblock ~165 ~117 ~77 dirt
setblock ~165 ~117 ~78 dirt
setblock ~165 ~117 ~79 dirt
setblock ~165 ~117 ~80 dirt
setblock ~165 ~117 ~81 dirt
setblock ~165 ~117 ~82 dirt
setblock ~165 ~117 ~83 dirt
setblock ~165 ~117 ~84 dirt
setblock ~165 ~117 ~85 dirt
setblock ~165 ~117 ~94 dirt
setblock ~165 ~117 ~102 dirt
setblock ~165 ~117 ~104 dirt
setblock ~165 ~117 ~105 dirt
setblock ~165 ~117 ~106 dirt
setblock ~165 ~117 ~107 dirt
setblock ~165 ~117 ~108 dirt
setblock ~165 ~117 ~109 dirt
setblock ~165 ~118 ~69 dirt
setblock ~165 ~118 ~70 dirt
setblock ~165 ~118 ~71 dirt
setblock ~165 ~118 ~72 dirt
setblock ~165 ~118 ~73 dirt
setblock ~165 ~118 ~74 dirt
setblock ~165 ~118 ~75 dirt
setblock ~165 ~118 ~76 dirt
setblock ~165 ~118 ~77 dirt
setblock ~165 ~118 ~78 dirt
setblock ~165 ~118 ~79 dirt
setblock ~165 ~118 ~80 dirt
setblock ~165 ~118 ~81 dirt
setblock ~165 ~118 ~82 dirt
setblock ~165 ~118 ~83 dirt
setblock ~165 ~118 ~84 dirt
setblock ~165 ~118 ~85 dirt
setblock ~165 ~118 ~94 dirt
setblock ~165 ~118 ~95 dirt
setblock ~165 ~118 ~102 dirt
setblock ~165 ~118 ~103 dirt
setblock ~165 ~118 ~104 dirt
setblock ~165 ~118 ~105 dirt
setblock ~165 ~118 ~106 dirt
setblock ~165 ~118 ~107 dirt
setblock ~165 ~118 ~108 dirt
setblock ~165 ~118 ~109 dirt
setblock ~165 ~118 ~110 dirt
setblock ~165 ~119 ~68 dirt
setblock ~165 ~119 ~69 dirt
setblock ~165 ~119 ~70 dirt
setblock ~165 ~119 ~71 dirt
setblock ~165 ~119 ~72 dirt
setblock ~165 ~119 ~73 dirt
setblock ~165 ~119 ~74 dirt
setblock ~165 ~119 ~75 dirt
setblock ~165 ~119 ~76 dirt
setblock ~165 ~119 ~77 dirt
setblock ~165 ~119 ~78 dirt
setblock ~165 ~119 ~79 dirt
setblock ~165 ~119 ~80 dirt
setblock ~165 ~119 ~81 dirt
setblock ~165 ~119 ~82 dirt
setblock ~165 ~119 ~83 dirt
setblock ~165 ~119 ~84 dirt
setblock ~165 ~119 ~85 dirt
setblock ~165 ~119 ~86 dirt
setblock ~165 ~119 ~92 dirt
setblock ~165 ~119 ~93 dirt
setblock ~165 ~119 ~94 dirt
setblock ~165 ~119 ~95 dirt
setblock ~165 ~119 ~98 dirt
setblock ~165 ~119 ~102 dirt
setblock ~165 ~119 ~103 dirt
setblock ~165 ~119 ~104 dirt
setblock ~165 ~119 ~105 dirt
setblock ~165 ~119 ~106 dirt
setblock ~165 ~119 ~107 dirt
setblock ~165 ~119 ~108 dirt
setblock ~165 ~119 ~109 dirt
setblock ~165 ~119 ~110 dirt
setblock ~165 ~120 ~68 dirt
setblock ~165 ~120 ~69 dirt
setblock ~165 ~120 ~70 dirt
setblock ~165 ~120 ~71 dirt
setblock ~165 ~120 ~72 dirt
setblock ~165 ~120 ~73 dirt
setblock ~165 ~120 ~74 dirt
setblock ~165 ~120 ~75 dirt
setblock ~165 ~120 ~76 dirt
setblock ~165 ~120 ~77 dirt
setblock ~165 ~120 ~78 dirt
setblock ~165 ~120 ~79 dirt
setblock ~165 ~120 ~80 dirt
setblock ~165 ~120 ~81 dirt
setblock ~165 ~120 ~82 dirt
setblock ~165 ~120 ~83 dirt
setblock ~165 ~120 ~84 dirt
setblock ~165 ~120 ~85 dirt
setblock ~165 ~120 ~86 dirt
setblock ~165 ~120 ~91 dirt
setblock ~165 ~120 ~92 dirt
setblock ~165 ~120 ~93 dirt
setblock ~165 ~120 ~94 dirt
setblock ~165 ~120 ~95 dirt
setblock ~165 ~120 ~96 dirt
setblock ~165 ~120 ~97 dirt
setblock ~165 ~120 ~98 dirt
setblock ~165 ~120 ~101 dirt
setblock ~165 ~120 ~102 dirt
setblock ~165 ~120 ~103 dirt
setblock ~165 ~120 ~104 dirt
setblock ~165 ~120 ~105 dirt
setblock ~165 ~120 ~106 dirt
setblock ~165 ~120 ~107 dirt
setblock ~165 ~120 ~108 dirt
setblock ~165 ~120 ~109 dirt
setblock ~165 ~120 ~110 dirt
setblock ~165 ~120 ~111 dirt
setblock ~165 ~120 ~124 dirt
setblock ~165 ~121 ~67 dirt
setblock ~165 ~121 ~68 dirt
setblock ~165 ~121 ~69 dirt
setblock ~165 ~121 ~70 dirt
setblock ~165 ~121 ~71 dirt
setblock ~165 ~121 ~72 dirt
setblock ~165 ~121 ~73 dirt
setblock ~165 ~121 ~74 dirt
setblock ~165 ~121 ~75 dirt
setblock ~165 ~121 ~76 dirt
setblock ~165 ~121 ~77 dirt
setblock ~165 ~121 ~78 dirt
setblock ~165 ~121 ~79 dirt
setblock ~165 ~121 ~80 dirt
setblock ~165 ~121 ~81 dirt
setblock ~165 ~121 ~82 dirt
setblock ~165 ~121 ~83 dirt
setblock ~165 ~121 ~84 dirt
setblock ~165 ~121 ~85 dirt
setblock ~165 ~121 ~86 dirt
setblock ~165 ~121 ~91 dirt
setblock ~165 ~121 ~92 dirt
setblock ~165 ~121 ~93 dirt
setblock ~165 ~121 ~94 dirt
setblock ~165 ~121 ~95 dirt
setblock ~165 ~121 ~96 dirt
setblock ~165 ~121 ~97 dirt
setblock ~165 ~121 ~98 dirt
setblock ~165 ~121 ~99 dirt
setblock ~165 ~121 ~100 dirt
setblock ~165 ~121 ~101 dirt
setblock ~165 ~121 ~102 dirt
setblock ~165 ~121 ~103 dirt
setblock ~165 ~121 ~104 dirt
setblock ~165 ~121 ~105 dirt
setblock ~165 ~121 ~106 dirt
setblock ~165 ~121 ~107 dirt
setblock ~165 ~121 ~108 dirt
setblock ~165 ~121 ~109 dirt
setblock ~165 ~121 ~110 dirt
setblock ~165 ~121 ~111 dirt
setblock ~165 ~121 ~122 dirt
setblock ~165 ~121 ~123 dirt
setblock ~165 ~121 ~124 dirt
setblock ~165 ~122 ~67 dirt
setblock ~165 ~122 ~68 dirt
setblock ~165 ~122 ~69 dirt
setblock ~165 ~122 ~70 dirt
setblock ~165 ~122 ~71 dirt
setblock ~165 ~122 ~72 dirt
setblock ~165 ~122 ~73 dirt
setblock ~165 ~122 ~74 dirt
setblock ~165 ~122 ~75 dirt
setblock ~165 ~122 ~76 dirt
setblock ~165 ~122 ~77 dirt
setblock ~165 ~122 ~78 dirt
setblock ~165 ~122 ~79 dirt
setblock ~165 ~122 ~80 dirt
setblock ~165 ~122 ~81 dirt
setblock ~165 ~122 ~82 dirt
setblock ~165 ~122 ~83 dirt
setblock ~165 ~122 ~84 dirt
setblock ~165 ~122 ~85 dirt
setblock ~165 ~122 ~86 dirt
setblock ~165 ~122 ~91 dirt
setblock ~165 ~122 ~92 dirt
setblock ~165 ~122 ~93 dirt
setblock ~165 ~122 ~94 dirt
setblock ~165 ~122 ~95 dirt
setblock ~165 ~122 ~96 dirt
setblock ~165 ~122 ~97 dirt
setblock ~165 ~122 ~98 dirt
setblock ~165 ~122 ~99 dirt
setblock ~165 ~122 ~100 dirt
setblock ~165 ~122 ~101 dirt
setblock ~165 ~122 ~102 dirt
setblock ~165 ~122 ~103 dirt
setblock ~165 ~122 ~104 dirt
setblock ~165 ~122 ~105 dirt
setblock ~165 ~122 ~106 dirt
setblock ~165 ~122 ~107 dirt
setblock ~165 ~122 ~108 dirt
setblock ~165 ~122 ~109 dirt
setblock ~165 ~122 ~110 dirt
setblock ~165 ~122 ~111 dirt
setblock ~165 ~122 ~122 dirt
setblock ~165 ~122 ~123 dirt
setblock ~165 ~122 ~124 dirt
setblock ~165 ~123 ~67 dirt
setblock ~165 ~123 ~68 dirt
setblock ~165 ~123 ~69 dirt
setblock ~165 ~123 ~70 dirt
setblock ~165 ~123 ~71 dirt
setblock ~165 ~123 ~72 dirt
setblock ~165 ~123 ~73 dirt
setblock ~165 ~123 ~74 dirt
setblock ~165 ~123 ~75 dirt
setblock ~165 ~123 ~76 dirt
setblock ~165 ~123 ~77 dirt
setblock ~165 ~123 ~78 dirt
setblock ~165 ~123 ~79 dirt
setblock ~165 ~123 ~80 dirt
setblock ~165 ~123 ~81 dirt
setblock ~165 ~123 ~82 dirt
setblock ~165 ~123 ~83 dirt
setblock ~165 ~123 ~84 dirt
setblock ~165 ~123 ~85 dirt
setblock ~165 ~123 ~86 dirt
setblock ~165 ~123 ~91 dirt
setblock ~165 ~123 ~92 dirt
setblock ~165 ~123 ~93 dirt
setblock ~165 ~123 ~94 dirt
setblock ~165 ~123 ~95 dirt
setblock ~165 ~123 ~96 dirt
setblock ~165 ~123 ~97 dirt
setblock ~165 ~123 ~98 dirt
setblock ~165 ~123 ~99 dirt
setblock ~165 ~123 ~100 dirt
setblock ~165 ~123 ~101 dirt
setblock ~165 ~123 ~102 dirt
setblock ~165 ~123 ~103 dirt
setblock ~165 ~123 ~104 dirt
setblock ~165 ~123 ~105 dirt
setblock ~165 ~123 ~106 dirt
setblock ~165 ~123 ~107 dirt
setblock ~165 ~123 ~108 dirt
setblock ~165 ~123 ~109 dirt
setblock ~165 ~123 ~110 dirt
setblock ~165 ~123 ~111 dirt
setblock ~165 ~123 ~122 dirt
setblock ~165 ~123 ~123 dirt
setblock ~165 ~123 ~124 dirt
setblock ~165 ~124 ~67 dirt
setblock ~165 ~124 ~68 dirt
setblock ~165 ~124 ~69 dirt
setblock ~165 ~124 ~70 dirt
setblock ~165 ~124 ~71 dirt
setblock ~165 ~124 ~72 dirt
setblock ~165 ~124 ~73 dirt
setblock ~165 ~124 ~74 dirt
setblock ~165 ~124 ~75 dirt
setblock ~165 ~124 ~76 dirt
setblock ~165 ~124 ~77 dirt
setblock ~165 ~124 ~78 dirt
setblock ~165 ~124 ~79 dirt
setblock ~165 ~124 ~80 dirt
setblock ~165 ~124 ~81 dirt
setblock ~165 ~124 ~82 dirt
setblock ~165 ~124 ~83 dirt
setblock ~165 ~124 ~84 dirt
setblock ~165 ~124 ~85 dirt
setblock ~165 ~124 ~86 dirt
setblock ~165 ~124 ~91 dirt
setblock ~165 ~124 ~92 dirt
setblock ~165 ~124 ~93 dirt
setblock ~165 ~124 ~94 dirt
setblock ~165 ~124 ~95 dirt
setblock ~165 ~124 ~96 dirt
setblock ~165 ~124 ~97 dirt
setblock ~165 ~124 ~98 dirt
setblock ~165 ~124 ~99 dirt
setblock ~165 ~124 ~100 dirt
setblock ~165 ~124 ~101 dirt
setblock ~165 ~124 ~102 dirt
setblock ~165 ~124 ~103 dirt
setblock ~165 ~124 ~104 dirt
setblock ~165 ~124 ~105 dirt
setblock ~165 ~124 ~106 dirt
setblock ~165 ~124 ~107 dirt
setblock ~165 ~124 ~108 dirt
setblock ~165 ~124 ~109 grass_block
setblock ~165 ~124 ~110 grass_block
setblock ~165 ~124 ~111 grass_block
setblock ~165 ~124 ~122 grass_block
setblock ~165 ~124 ~123 grass_block
setblock ~165 ~124 ~124 grass_block
setblock ~165 ~125 ~67 dirt
setblock ~165 ~125 ~68 dirt
setblock ~165 ~125 ~69 dirt
setblock ~165 ~125 ~70 dirt
setblock ~165 ~125 ~71 dirt
setblock ~165 ~125 ~72 dirt
setblock ~165 ~125 ~73 dirt
setblock ~165 ~125 ~74 dirt
setblock ~165 ~125 ~75 dirt
setblock ~165 ~125 ~76 grass_block
setblock ~165 ~125 ~77 grass_block
setblock ~165 ~125 ~78 grass_block
setblock ~165 ~125 ~79 grass_block
setblock ~165 ~125 ~80 grass_block
setblock ~165 ~125 ~81 grass_block
setblock ~165 ~125 ~82 grass_block
setblock ~165 ~125 ~83 grass_block
setblock ~165 ~125 ~84 grass_block
setblock ~165 ~125 ~85 grass_block
setblock ~165 ~125 ~86 grass_block
setblock ~165 ~125 ~91 grass_block
setblock ~165 ~125 ~92 grass_block
setblock ~165 ~125 ~93 grass_block
setblock ~165 ~125 ~94 grass_block
setblock ~165 ~125 ~95 grass_block
setblock ~165 ~125 ~96 grass_block
setblock ~165 ~125 ~97 grass_block
setblock ~165 ~125 ~98 grass_block
setblock ~165 ~125 ~99 grass_block
setblock ~165 ~125 ~100 grass_block
setblock ~165 ~125 ~101 grass_block
setblock ~165 ~125 ~102 grass_block
setblock ~165 ~125 ~103 grass_block
setblock ~165 ~125 ~104 grass_block
setblock ~165 ~125 ~105 grass_block
setblock ~165 ~125 ~106 grass_block
setblock ~165 ~125 ~107 grass_block
setblock ~165 ~125 ~108 grass_block
setblock ~165 ~126 ~67 grass_block
setblock ~165 ~126 ~68 grass_block
setblock ~165 ~126 ~69 grass_block
setblock ~165 ~126 ~70 grass_block
setblock ~165 ~126 ~71 grass_block
setblock ~165 ~126 ~72 grass_block
setblock ~165 ~126 ~73 grass_block
setblock ~165 ~126 ~74 grass_block
setblock ~165 ~126 ~75 grass_block
setblock ~165 ~126 ~77 short_grass
setblock ~165 ~126 ~78 short_grass
setblock ~165 ~126 ~94 short_grass
setblock ~165 ~126 ~95 short_grass
setblock ~165 ~126 ~99 short_grass
setblock ~165 ~126 ~100 short_grass
setblock ~165 ~126 ~104 short_grass
setblock ~165 ~126 ~107 short_grass
setblock ~165 ~126 ~108 short_grass
setblock ~165 ~127 ~68 short_grass
setblock ~165 ~127 ~70 fern
setblock ~165 ~127 ~73 fern
setblock ~165 ~127 ~75 poppy
setblock ~165 ~134 ~74 oak_leaves[persistent=true]
setblock ~165 ~134 ~75 oak_leaves[persistent=true]
setblock ~165 ~134 ~77 oak_leaves[persistent=true]
setblock ~165 ~134 ~78 oak_leaves[persistent=true]
setblock ~165 ~135 ~74 oak_leaves[persistent=true]
setblock ~165 ~135 ~75 oak_leaves[persistent=true]
setblock ~165 ~135 ~76 oak_wood
setblock ~165 ~135 ~77 oak_leaves[persistent=true]
setblock ~165 ~135 ~78 oak_leaves[persistent=true]
setblock ~165 ~135 ~80 jungle_leaves[persistent=true]
setblock ~165 ~136 ~74 oak_leaves[persistent=true]
setblock ~165 ~136 ~75 oak_leaves[persistent=true]
setblock ~165 ~136 ~77 jungle_leaves[persistent=true]
setblock ~165 ~136 ~78 jungle_leaves[persistent=true]
setblock ~165 ~136 ~81 jungle_leaves[persistent=true]
setblock ~165 ~137 ~74 oak_leaves[persistent=true]
setblock ~165 ~137 ~75 oak_leaves[persistent=true]
setblock ~165 ~137 ~76 oak_leaves[persistent=true]
setblock ~165 ~137 ~77 oak_leaves[persistent=true]
setblock ~165 ~137 ~78 oak_leaves[persistent=true]
setblock ~165 ~137 ~79 jungle_leaves[persistent=true]
setblock ~165 ~137 ~80 oak_wood
setblock ~165 ~137 ~81 oak_leaves[persistent=true]
setblock ~165 ~138 ~74 jungle_leaves[persistent=true]
setblock ~165 ~138 ~75 oak_leaves[persistent=true]
setblock ~165 ~138 ~76 oak_wood
setblock ~165 ~138 ~77 jungle_leaves[persistent=true]
setblock ~165 ~138 ~78 oak_leaves[persistent=true]
setblock ~165 ~138 ~79 oak_leaves[persistent=true]
setblock ~165 ~138 ~80 oak_leaves[persistent=true]
setblock ~165 ~139 ~74 oak_leaves[persistent=true]
setblock ~165 ~139 ~75 oak_leaves[persistent=true]
setblock ~165 ~139 ~76 oak_leaves[persistent=true]
setblock ~165 ~139 ~77 oak_leaves[persistent=true]
setblock ~166 ~112 ~75 dirt
setblock ~166 ~112 ~79 dirt
setblock ~166 ~112 ~81 dirt
setblock ~166 ~113 ~73 dirt
setblock ~166 ~113 ~74 dirt
setblock ~166 ~113 ~75 dirt
setblock ~166 ~113 ~76 dirt
setblock ~166 ~113 ~78 dirt
setblock ~166 ~113 ~79 dirt
setblock ~166 ~113 ~81 dirt
setblock ~166 ~114 ~72 dirt
setblock ~166 ~114 ~73 dirt
setblock ~166 ~114 ~74 dirt
setblock ~166 ~114 ~75 dirt
setblock ~166 ~114 ~76 dirt
setblock ~166 ~114 ~77 dirt
setblock ~166 ~114 ~78 dirt
setblock ~166 ~114 ~79 dirt
setblock ~166 ~114 ~80 dirt
setblock ~166 ~114 ~81 dirt
setblock ~166 ~115 ~71 dirt
setblock ~166 ~115 ~72 dirt
setblock ~166 ~115 ~73 dirt
setblock ~166 ~115 ~74 dirt
setblock ~166 ~115 ~75 dirt
setblock ~166 ~115 ~76 dirt
setblock ~166 ~115 ~77 dirt
setblock ~166 ~115 ~78 dirt
setblock ~166 ~115 ~79 dirt
setblock ~166 ~115 ~80 dirt
setblock ~166 ~115 ~81 dirt
setblock ~166 ~115 ~82 dirt
setblock ~166 ~116 ~71 dirt
setblock ~166 ~116 ~72 dirt
setblock ~166 ~116 ~73 dirt
setblock ~166 ~116 ~74 dirt
setblock ~166 ~116 ~75 dirt
setblock ~166 ~116 ~76 dirt
setblock ~166 ~116 ~77 dirt
setblock ~166 ~116 ~78 dirt
setblock ~166 ~116 ~79 dirt
setblock ~166 ~116 ~80 dirt
setblock ~166 ~116 ~81 dirt
setblock ~166 ~116 ~82 dirt
setblock ~166 ~116 ~106 dirt
setblock ~166 ~117 ~71 dirt
setblock ~166 ~117 ~72 dirt
setblock ~166 ~117 ~73 dirt
setblock ~166 ~117 ~74 dirt
setblock ~166 ~117 ~75 dirt
setblock ~166 ~117 ~76 dirt
setblock ~166 ~117 ~77 dirt
setblock ~166 ~117 ~78 dirt
setblock ~166 ~117 ~79 dirt
setblock ~166 ~117 ~80 dirt
setblock ~166 ~117 ~81 dirt
setblock ~166 ~117 ~82 dirt
setblock ~166 ~117 ~83 dirt
setblock ~166 ~117 ~84 dirt
setblock ~166 ~117 ~105 dirt
setblock ~166 ~117 ~106 dirt
setblock ~166 ~117 ~108 dirt
setblock ~166 ~118 ~70 dirt
setblock ~166 ~118 ~71 dirt
setblock ~166 ~118 ~72 dirt
setblock ~166 ~118 ~73 dirt
setblock ~166 ~118 ~74 dirt
setblock ~166 ~118 ~75 dirt
setblock ~166 ~118 ~76 dirt
setblock ~166 ~118 ~77 dirt
setblock ~166 ~118 ~78 dirt
setblock ~166 ~118 ~79 dirt
setblock ~166 ~118 ~80 dirt
setblock ~166 ~118 ~81 dirt
setblock ~166 ~118 ~82 dirt
setblock ~166 ~118 ~83 dirt
setblock ~166 ~118 ~84 dirt
setblock ~166 ~118 ~85 dirt
setblock ~166 ~118 ~104 dirt
setblock ~166 ~118 ~105 dirt
setblock ~166 ~118 ~106 dirt
setblock ~166 ~118 ~107 dirt
setblock ~166 ~118 ~108 dirt
setblock ~166 ~118 ~109 dirt
setblock ~166 ~119 ~70 dirt
setblock ~166 ~119 ~71 dirt
setblock ~166 ~119 ~72 dirt
setblock ~166 ~119 ~73 dirt
setblock ~166 ~119 ~74 dirt
setblock ~166 ~119 ~75 dirt
setblock ~166 ~119 ~76 dirt
setblock ~166 ~119 ~77 dirt
setblock ~166 ~119 ~78 dirt
setblock ~166 ~119 ~79 dirt
setblock ~166 ~119 ~80 dirt
setblock ~166 ~119 ~81 dirt
setblock ~166 ~119 ~82 dirt
setblock ~166 ~119 ~83 dirt
setblock ~166 ~119 ~84 dirt
setblock ~166 ~119 ~85 dirt
setblock ~166 ~119 ~94 dirt
setblock ~166 ~119 ~103 dirt
setblock ~166 ~119 ~104 dirt
setblock ~166 ~119 ~105 dirt
setblock ~166 ~119 ~106 dirt
setblock ~166 ~119 ~107 dirt
setblock ~166 ~119 ~108 dirt
setblock ~166 ~119 ~109 dirt
setblock ~166 ~120 ~69 dirt
setblock ~166 ~120 ~70 dirt
setblock ~166 ~120 ~71 dirt
setblock ~166 ~120 ~72 dirt
setblock ~166 ~120 ~73 dirt
setblock ~166 ~120 ~74 dirt
setblock ~166 ~120 ~75 dirt
setblock ~166 ~120 ~76 dirt
setblock ~166 ~120 ~77 dirt
setblock ~166 ~120 ~78 dirt
setblock ~166 ~120 ~79 dirt
setblock ~166 ~120 ~80 dirt
setblock ~166 ~120 ~81 dirt
setblock ~166 ~120 ~82 dirt
setblock ~166 ~120 ~83 dirt
setblock ~166 ~120 ~84 dirt
setblock ~166 ~120 ~85 dirt
setblock ~166 ~120 ~92 dirt
setblock ~166 ~120 ~94 dirt
setblock ~166 ~120 ~95 dirt
setblock ~166 ~120 ~102 dirt
setblock ~166 ~120 ~103 dirt
setblock ~166 ~120 ~104 dirt
setblock ~166 ~120 ~105 dirt
setblock ~166 ~120 ~106 dirt
setblock ~166 ~120 ~107 dirt
setblock ~166 ~120 ~108 dirt
setblock ~166 ~120 ~109 dirt
setblock ~166 ~120 ~110 dirt
setblock ~166 ~121 ~68 dirt
setblock ~166 ~121 ~69 dirt
setblock ~166 ~121 ~70 dirt
setblock ~166 ~121 ~71 dirt
setblock ~166 ~121 ~72 dirt
setblock ~166 ~121 ~73 dirt
setblock ~166 ~121 ~74 dirt
setblock ~166 ~121 ~75 dirt
setblock ~166 ~121 ~76 dirt
setblock ~166 ~121 ~77 dirt
setblock ~166 ~121 ~78 dirt
setblock ~166 ~121 ~79 dirt
setblock ~166 ~121 ~80 dirt
setblock ~166 ~121 ~81 dirt
setblock ~166 ~121 ~82 dirt
setblock ~166 ~121 ~83 dirt
setblock ~166 ~121 ~84 dirt
setblock ~166 ~121 ~85 dirt
setblock ~166 ~121 ~92 dirt
setblock ~166 ~121 ~93 dirt
setblock ~166 ~121 ~94 dirt
setblock ~166 ~121 ~95 dirt
setblock ~166 ~121 ~97 dirt
setblock ~166 ~121 ~102 dirt
setblock ~166 ~121 ~103 dirt
setblock ~166 ~121 ~104 dirt
setblock ~166 ~121 ~105 dirt
setblock ~166 ~121 ~106 dirt
setblock ~166 ~121 ~107 dirt
setblock ~166 ~121 ~108 dirt
setblock ~166 ~121 ~109 dirt
setblock ~166 ~121 ~110 dirt
setblock ~166 ~122 ~68 dirt
setblock ~166 ~122 ~69 dirt
setblock ~166 ~122 ~70 dirt
setblock ~166 ~122 ~71 dirt
setblock ~166 ~122 ~72 dirt
setblock ~166 ~122 ~73 dirt
setblock ~166 ~122 ~74 dirt
setblock ~166 ~122 ~75 dirt
setblock ~166 ~122 ~76 dirt
setblock ~166 ~122 ~77 dirt
setblock ~166 ~122 ~78 dirt
setblock ~166 ~122 ~79 dirt
setblock ~166 ~122 ~80 dirt
setblock ~166 ~122 ~81 dirt
setblock ~166 ~122 ~82 dirt
setblock ~166 ~122 ~83 dirt
setblock ~166 ~122 ~84 dirt
setblock ~166 ~122 ~85 dirt
setblock ~166 ~122 ~92 dirt
setblock ~166 ~122 ~93 dirt
setblock ~166 ~122 ~94 dirt
setblock ~166 ~122 ~95 dirt
setblock ~166 ~122 ~97 dirt
setblock ~166 ~122 ~102 dirt
setblock ~166 ~122 ~103 dirt
setblock ~166 ~122 ~104 dirt
setblock ~166 ~122 ~105 dirt
setblock ~166 ~122 ~106 dirt
setblock ~166 ~122 ~107 dirt
setblock ~166 ~122 ~108 dirt
setblock ~166 ~122 ~109 dirt
setblock ~166 ~122 ~110 dirt
setblock ~166 ~123 ~68 dirt
setblock ~166 ~123 ~69 dirt
setblock ~166 ~123 ~70 dirt
setblock ~166 ~123 ~71 dirt
setblock ~166 ~123 ~72 dirt
setblock ~166 ~123 ~73 dirt
setblock ~166 ~123 ~74 dirt
setblock ~166 ~123 ~75 dirt
setblock ~166 ~123 ~76 dirt
setblock ~166 ~123 ~77 dirt
setblock ~166 ~123 ~78 dirt
setblock ~166 ~123 ~79 dirt
setblock ~166 ~123 ~80 dirt
setblock ~166 ~123 ~81 dirt
setblock ~166 ~123 ~82 dirt
setblock ~166 ~123 ~83 dirt
setblock ~166 ~123 ~84 dirt
setblock ~166 ~123 ~85 dirt
setblock ~166 ~123 ~92 dirt
setblock ~166 ~123 ~93 dirt
setblock ~166 ~123 ~94 dirt
setblock ~166 ~123 ~95 dirt
setblock ~166 ~123 ~97 dirt
setblock ~166 ~123 ~102 dirt
setblock ~166 ~123 ~103 dirt
setblock ~166 ~123 ~104 dirt
setblock ~166 ~123 ~105 dirt
setblock ~166 ~123 ~106 dirt
setblock ~166 ~123 ~107 dirt
setblock ~166 ~123 ~108 dirt
setblock ~166 ~123 ~109 dirt
setblock ~166 ~123 ~110 dirt
setblock ~166 ~124 ~68 dirt
setblock ~166 ~124 ~69 dirt
setblock ~166 ~124 ~70 dirt
setblock ~166 ~124 ~71 dirt
setblock ~166 ~124 ~72 dirt
setblock ~166 ~124 ~73 dirt
setblock ~166 ~124 ~74 dirt
setblock ~166 ~124 ~75 dirt
setblock ~166 ~124 ~76 dirt
setblock ~166 ~124 ~77 dirt
setblock ~166 ~124 ~78 dirt
setblock ~166 ~124 ~79 dirt
setblock ~166 ~124 ~80 dirt
setblock ~166 ~124 ~81 dirt
setblock ~166 ~124 ~82 dirt
setblock ~166 ~124 ~83 dirt
setblock ~166 ~124 ~84 dirt
setblock ~166 ~124 ~85 dirt
setblock ~166 ~124 ~92 dirt
setblock ~166 ~124 ~93 dirt
setblock ~166 ~124 ~94 dirt
setblock ~166 ~124 ~95 dirt
setblock ~166 ~124 ~97 dirt
setblock ~166 ~124 ~102 dirt
setblock ~166 ~124 ~103 dirt
setblock ~166 ~124 ~104 dirt
setblock ~166 ~124 ~105 dirt
setblock ~166 ~124 ~106 dirt
setblock ~166 ~124 ~107 dirt
setblock ~166 ~124 ~108 dirt
setblock ~166 ~124 ~109 dirt
setblock ~166 ~124 ~110 grass_block
setblock ~166 ~125 ~68 dirt
setblock ~166 ~125 ~69 dirt
setblock ~166 ~125 ~70 dirt
setblock ~166 ~125 ~71 dirt
setblock ~166 ~125 ~72 dirt
setblock ~166 ~125 ~73 dirt
setblock ~166 ~125 ~74 dirt
setblock ~166 ~125 ~75 dirt
setblock ~166 ~125 ~76 dirt
setblock ~166 ~125 ~77 dirt
setblock ~166 ~125 ~78 dirt
setblock ~166 ~125 ~79 grass_block
setblock ~166 ~125 ~80 grass_block
setblock ~166 ~125 ~81 grass_block
setblock ~166 ~125 ~82 grass_block
setblock ~166 ~125 ~83 grass_block
setblock ~166 ~125 ~84 grass_block
setblock ~166 ~125 ~85 grass_block
setblock ~166 ~125 ~92 grass_block
setblock ~166 ~125 ~93 grass_block
setblock ~166 ~125 ~94 grass_block
setblock ~166 ~125 ~95 grass_block
setblock ~166 ~125 ~97 grass_block
setblock ~166 ~125 ~102 grass_block
setblock ~166 ~125 ~103 grass_block
setblock ~166 ~125 ~104 grass_block
setblock ~166 ~125 ~105 grass_block
setblock ~166 ~125 ~106 grass_block
setblock ~166 ~125 ~107 grass_block
setblock ~166 ~125 ~108 grass_block
setblock ~166 ~125 ~109 grass_block
setblock ~166 ~126 ~68 dirt
setblock ~166 ~126 ~69 dirt
setblock ~166 ~126 ~70 dirt
setblock ~166 ~126 ~71 dirt
setblock ~166 ~126 ~72 dirt
setblock ~166 ~126 ~73 dirt
setblock ~166 ~126 ~74 grass_block
setblock ~166 ~126 ~75 grass_block
setblock ~166 ~126 ~76 grass_block
setblock ~166 ~126 ~77 grass_block
setblock ~166 ~126 ~78 grass_block
setblock ~166 ~126 ~83 short_grass
setblock ~166 ~126 ~85 poppy
setblock ~166 ~126 ~92 poppy
setblock ~166 ~126 ~93 short_grass
setblock ~166 ~126 ~97 short_grass
setblock ~166 ~126 ~104 short_grass
setblock ~166 ~126 ~105 fern
setblock ~166 ~126 ~109 short_grass
setblock ~166 ~127 ~68 grass_block
setblock ~166 ~127 ~69 grass_block
setblock ~166 ~127 ~70 grass_block
setblock ~166 ~127 ~71 grass_block
setblock ~166 ~127 ~72 grass_block
setblock ~166 ~127 ~73 grass_block
setblock ~166 ~127 ~76 short_grass
setblock ~166 ~127 ~77 short_grass
setblock ~166 ~134 ~74 oak_leaves[persistent=true]
setblock ~166 ~134 ~75 oak_leaves[persistent=true]
setblock ~166 ~134 ~77 jungle_leaves[persistent=true]
setblock ~166 ~134 ~78 jungle_leaves[persistent=true]
setblock ~166 ~135 ~74 oak_leaves[persistent=true]
setblock ~166 ~135 ~75 oak_leaves[persistent=true]
setblock ~166 ~135 ~76 oak_leaves[persistent=true]
setblock ~166 ~135 ~77 jungle_leaves[persistent=true]
setblock ~166 ~135 ~79 oak_leaves[persistent=true]
setblock ~166 ~135 ~80 oak_leaves[persistent=true]
setblock ~166 ~136 ~74 oak_leaves[persistent=true]
setblock ~166 ~136 ~75 oak_leaves[persistent=true]
setblock ~166 ~136 ~76 oak_wood
setblock ~166 ~136 ~77 oak_leaves[persistent=true]
setblock ~166 ~136 ~78 oak_leaves[persistent=true]
setblock ~166 ~136 ~80 oak_leaves[persistent=true]
setblock ~166 ~136 ~81 jungle_leaves[persistent=true]
setblock ~166 ~137 ~74 oak_leaves[persistent=true]
setblock ~166 ~137 ~75 jungle_leaves[persistent=true]
setblock ~166 ~137 ~76 oak_leaves[persistent=true]
setblock ~166 ~137 ~77 oak_leaves[persistent=true]
setblock ~166 ~137 ~78 jungle_leaves[persistent=true]
setblock ~166 ~137 ~79 oak_leaves[persistent=true]
setblock ~166 ~137 ~80 oak_wood
setblock ~166 ~137 ~81 oak_leaves[persistent=true]
setblock ~166 ~138 ~74 oak_leaves[persistent=true]
setblock ~166 ~138 ~75 oak_leaves[persistent=true]
setblock ~166 ~138 ~76 oak_wood
setblock ~166 ~138 ~77 oak_leaves[persistent=true]
setblock ~166 ~138 ~79 oak_leaves[persistent=true]
setblock ~166 ~138 ~81 oak_leaves[persistent=true]
setblock ~166 ~139 ~74 oak_leaves[persistent=true]
setblock ~166 ~139 ~75 oak_leaves[persistent=true]
setblock ~166 ~139 ~76 oak_leaves[persistent=true]
setblock ~166 ~139 ~77 oak_leaves[persistent=true]
setblock ~166 ~139 ~78 oak_leaves[persistent=true]
setblock ~166 ~139 ~79 oak_leaves[persistent=true]
setblock ~166 ~139 ~80 oak_leaves[persistent=true]
setblock ~166 ~140 ~75 oak_leaves[persistent=true]
setblock ~166 ~140 ~76 oak_leaves[persistent=true]
setblock ~166 ~140 ~77 oak_leaves[persistent=true]
setblock ~166 ~140 ~78 oak_leaves[persistent=true]
setblock ~166 ~140 ~79 oak_leaves[persistent=true]
setblock ~166 ~140 ~80 oak_leaves[persistent=true]
setblock ~167 ~113 ~75 dirt
setblock ~167 ~114 ~74 dirt
setblock ~167 ~114 ~75 dirt
setblock ~167 ~114 ~76 dirt
setblock ~167 ~115 ~72 dirt
setblock ~167 ~115 ~74 dirt
setblock ~167 ~115 ~75 dirt
setblock ~167 ~115 ~76 dirt
setblock ~167 ~115 ~77 dirt
setblock ~167 ~116 ~72 dirt
setblock ~167 ~116 ~73 dirt
setblock ~167 ~116 ~74 dirt
setblock ~167 ~116 ~75 dirt
setblock ~167 ~116 ~76 dirt
setblock ~167 ~116 ~77 dirt
setblock ~167 ~116 ~79 dirt
setblock ~167 ~116 ~80 dirt
setblock ~167 ~116 ~81 dirt
setblock ~167 ~117 ~72 dirt
setblock ~167 ~117 ~73 dirt
setblock ~167 ~117 ~74 dirt
setblock ~167 ~117 ~75 dirt
setblock ~167 ~117 ~76 dirt
setblock ~167 ~117 ~77 dirt
setblock ~167 ~117 ~78 dirt
setblock ~167 ~117 ~79 dirt
setblock ~167 ~117 ~80 dirt
setblock ~167 ~117 ~81 dirt
setblock ~167 ~117 ~82 dirt
setblock ~167 ~118 ~71 dirt
setblock ~167 ~118 ~72 dirt
setblock ~167 ~118 ~73 dirt
setblock ~167 ~118 ~74 dirt
setblock ~167 ~118 ~75 dirt
setblock ~167 ~118 ~76 dirt
setblock ~167 ~118 ~77 dirt
setblock ~167 ~118 ~78 dirt
setblock ~167 ~118 ~79 dirt
setblock ~167 ~118 ~80 dirt
setblock ~167 ~118 ~81 dirt
setblock ~167 ~118 ~82 dirt
setblock ~167 ~118 ~83 dirt
setblock ~167 ~118 ~84 dirt
setblock ~167 ~119 ~70 dirt
setblock ~167 ~119 ~71 dirt
setblock ~167 ~119 ~72 dirt
setblock ~167 ~119 ~73 dirt
setblock ~167 ~119 ~74 dirt
setblock ~167 ~119 ~75 dirt
setblock ~167 ~119 ~76 dirt
setblock ~167 ~119 ~77 dirt
setblock ~167 ~119 ~78 dirt
setblock ~167 ~119 ~79 dirt
setblock ~167 ~119 ~80 dirt
setblock ~167 ~119 ~81 dirt
setblock ~167 ~119 ~82 dirt
setblock ~167 ~119 ~83 dirt
setblock ~167 ~119 ~84 dirt
setblock ~167 ~119 ~105 dirt
setblock ~167 ~119 ~106 dirt
setblock ~167 ~119 ~107 dirt
setblock ~167 ~119 ~108 dirt
setblock ~167 ~120 ~69 dirt
setblock ~167 ~120 ~70 dirt
setblock ~167 ~120 ~71 dirt
setblock ~167 ~120 ~72 dirt
setblock ~167 ~120 ~73 dirt
setblock ~167 ~120 ~74 dirt
setblock ~167 ~120 ~75 dirt
setblock ~167 ~120 ~76 dirt
setblock ~167 ~120 ~77 dirt
setblock ~167 ~120 ~78 dirt
setblock ~167 ~120 ~79 dirt
setblock ~167 ~120 ~80 dirt
setblock ~167 ~120 ~81 dirt
setblock ~167 ~120 ~82 dirt
setblock ~167 ~120 ~83 dirt
setblock ~167 ~120 ~84 dirt
setblock ~167 ~120 ~104 dirt
setblock ~167 ~120 ~105 dirt
setblock ~167 ~120 ~106 dirt
setblock ~167 ~120 ~107 dirt
setblock ~167 ~120 ~108 dirt
setblock ~167 ~120 ~109 dirt
setblock ~167 ~121 ~69 dirt
setblock ~167 ~121 ~70 dirt
setblock ~167 ~121 ~71 dirt
setblock ~167 ~121 ~72 dirt
setblock ~167 ~121 ~73 dirt
setblock ~167 ~121 ~74 dirt
setblock ~167 ~121 ~75 dirt
setblock ~167 ~121 ~76 dirt
setblock ~167 ~121 ~77 dirt
setblock ~167 ~121 ~78 dirt
setblock ~167 ~121 ~79 dirt
setblock ~167 ~121 ~80 dirt
setblock ~167 ~121 ~81 dirt
setblock ~167 ~121 ~82 dirt
setblock ~167 ~121 ~83 dirt
setblock ~167 ~121 ~84 dirt
setblock ~167 ~121 ~94 dirt
setblock ~167 ~121 ~103 dirt
setblock ~167 ~121 ~104 dirt
setblock ~167 ~121 ~105 dirt
setblock ~167 ~121 ~106 dirt
setblock ~167 ~121 ~107 dirt
setblock ~167 ~121 ~108 dirt
setblock ~167 ~121 ~109 dirt
setblock ~167 ~122 ~69 dirt
setblock ~167 ~122 ~70 dirt
setblock ~167 ~122 ~71 dirt
setblock ~167 ~122 ~72 dirt
setblock ~167 ~122 ~73 dirt
setblock ~167 ~122 ~74 dirt
setblock ~167 ~122 ~75 dirt
setblock ~167 ~122 ~76 dirt
setblock ~167 ~122 ~77 dirt
setblock ~167 ~122 ~78 dirt
setblock ~167 ~122 ~79 dirt
setblock ~167 ~122 ~80 dirt
setblock ~167 ~122 ~81 dirt
setblock ~167 ~122 ~82 dirt
setblock ~167 ~122 ~83 dirt
setblock ~167 ~122 ~84 dirt
setblock ~167 ~122 ~94 dirt
setblock ~167 ~122 ~103 dirt
setblock ~167 ~122 ~104 dirt
setblock ~167 ~122 ~105 dirt
setblock ~167 ~122 ~106 dirt
setblock ~167 ~122 ~107 dirt
setblock ~167 ~122 ~108 dirt
setblock ~167 ~122 ~109 dirt
setblock ~167 ~123 ~69 dirt
setblock ~167 ~123 ~70 dirt
setblock ~167 ~123 ~71 dirt
setblock ~167 ~123 ~72 dirt
setblock ~167 ~123 ~73 dirt
setblock ~167 ~123 ~74 dirt
setblock ~167 ~123 ~75 dirt
setblock ~167 ~123 ~76 dirt
setblock ~167 ~123 ~77 dirt
setblock ~167 ~123 ~78 dirt
setblock ~167 ~123 ~79 dirt
setblock ~167 ~123 ~80 dirt
setblock ~167 ~123 ~81 dirt
setblock ~167 ~123 ~82 dirt
setblock ~167 ~123 ~83 dirt
setblock ~167 ~123 ~84 dirt
setblock ~167 ~123 ~94 dirt
setblock ~167 ~123 ~103 dirt
setblock ~167 ~123 ~104 dirt
setblock ~167 ~123 ~105 dirt
setblock ~167 ~123 ~106 dirt
setblock ~167 ~123 ~107 dirt
setblock ~167 ~123 ~108 dirt
setblock ~167 ~123 ~109 dirt
setblock ~167 ~124 ~69 dirt
setblock ~167 ~124 ~70 dirt
setblock ~167 ~124 ~71 dirt
setblock ~167 ~124 ~72 dirt
setblock ~167 ~124 ~73 dirt
setblock ~167 ~124 ~74 dirt
setblock ~167 ~124 ~75 dirt
setblock ~167 ~124 ~76 dirt
setblock ~167 ~124 ~77 dirt
setblock ~167 ~124 ~78 dirt
setblock ~167 ~124 ~79 dirt
setblock ~167 ~124 ~80 dirt
setblock ~167 ~124 ~81 dirt
setblock ~167 ~124 ~82 dirt
setblock ~167 ~124 ~83 dirt
setblock ~167 ~124 ~84 dirt
setblock ~167 ~124 ~94 dirt
setblock ~167 ~124 ~103 dirt
setblock ~167 ~124 ~104 dirt
setblock ~167 ~124 ~105 dirt
setblock ~167 ~124 ~106 dirt
setblock ~167 ~124 ~107 dirt
setblock ~167 ~124 ~108 dirt
setblock ~167 ~124 ~109 dirt
setblock ~167 ~125 ~69 dirt
setblock ~167 ~125 ~70 dirt
setblock ~167 ~125 ~71 dirt
setblock ~167 ~125 ~72 dirt
setblock ~167 ~125 ~73 dirt
setblock ~167 ~125 ~74 dirt
setblock ~167 ~125 ~75 dirt
setblock ~167 ~125 ~76 dirt
setblock ~167 ~125 ~77 dirt
setblock ~167 ~125 ~78 dirt
setblock ~167 ~125 ~79 dirt
setblock ~167 ~125 ~80 dirt
setblock ~167 ~125 ~81 dirt
setblock ~167 ~125 ~82 dirt
setblock ~167 ~125 ~83 dirt
setblock ~167 ~125 ~84 dirt
setblock ~167 ~125 ~94 grass_block
setblock ~167 ~125 ~103 grass_block
setblock ~167 ~125 ~104 grass_block
setblock ~167 ~125 ~105 grass_block
setblock ~167 ~125 ~106 grass_block
setblock ~167 ~125 ~107 grass_block
setblock ~167 ~125 ~108 grass_block
setblock ~167 ~125 ~109 grass_block
setblock ~167 ~126 ~69 dirt
setblock ~167 ~126 ~70 dirt
setblock ~167 ~126 ~71 dirt
setblock ~167 ~126 ~72 dirt
setblock ~167 ~126 ~73 dirt
setblock ~167 ~126 ~74 dirt
setblock ~167 ~126 ~75 dirt
setblock ~167 ~126 ~76 dirt
setblock ~167 ~126 ~77 grass_block
setblock ~167 ~126 ~78 grass_block
setblock ~167 ~126 ~79 grass_block
setblock ~167 ~126 ~80 grass_block
setblock ~167 ~126 ~81 grass_block
setblock ~167 ~126 ~82 grass_block
setblock ~167 ~126 ~83 grass_block
setblock ~167 ~126 ~84 grass_block
setblock ~167 ~126 ~104 short_grass
setblock ~167 ~126 ~105 poppy
setblock ~167 ~126 ~106 short_grass
setblock ~167 ~126 ~109 short_grass
setblock ~167 ~127 ~69 grass_block
setblock ~167 ~127 ~70 dirt
setblock ~167 ~127 ~71 dirt
setblock ~167 ~127 ~72 grass_block
setblock ~167 ~127 ~73 grass_block
setblock ~167 ~127 ~74 grass_block
setblock ~167 ~127 ~75 grass_block
setblock ~167 ~127 ~76 grass_block
setblock ~167 ~127 ~79 short_grass
setblock ~167 ~127 ~82 poppy
setblock ~167 ~127 ~84 short_grass
setblock ~167 ~128 ~70 grass_block
setblock ~167 ~128 ~71 grass_block
setblock ~167 ~128 ~74 poppy
setblock ~167 ~128 ~76 poppy
setblock ~167 ~134 ~74 oak_leaves[persistent=true]
setblock ~167 ~134 ~75 oak_leaves[persistent=true]
setblock ~167 ~134 ~76 oak_leaves[persistent=true]
setblock ~167 ~134 ~77 oak_leaves[persistent=true]
setblock ~167 ~134 ~78 jungle_leaves[persistent=true]
setblock ~167 ~135 ~74 oak_leaves[persistent=true]
setblock ~167 ~135 ~75 oak_leaves[persistent=true]
setblock ~167 ~135 ~76 jungle_leaves[persistent=true]
setblock ~167 ~135 ~78 oak_leaves[persistent=true]
setblock ~167 ~135 ~79 oak_leaves[persistent=true]
setblock ~167 ~135 ~80 oak_leaves[persistent=true]
setblock ~167 ~136 ~74 oak_leaves[persistent=true]
setblock ~167 ~136 ~76 oak_leaves[persistent=true]
setblock ~167 ~136 ~77 oak_wood
setblock ~167 ~136 ~78 jungle_leaves[persistent=true]
setblock ~167 ~136 ~79 oak_leaves[persistent=true]
setblock ~167 ~136 ~80 oak_leaves[persistent=true]
setblock ~167 ~136 ~81 oak_leaves[persistent=true]
setblock ~167 ~137 ~75 oak_leaves[persistent=true]
setblock ~167 ~137 ~76 oak_leaves[persistent=true]
setblock ~167 ~137 ~77 oak_leaves[persistent=true]
setblock ~167 ~137 ~78 oak_leaves[persistent=true]
setblock ~167 ~137 ~79 oak_wood
setblock ~167 ~137 ~80 jungle_leaves[persistent=true]
setblock ~167 ~137 ~81 oak_leaves[persistent=true]
setblock ~167 ~138 ~74 oak_leaves[persistent=true]
setblock ~167 ~138 ~75 oak_leaves[persistent=true]
setblock ~167 ~138 ~76 oak_wood
setblock ~167 ~138 ~77 oak_wood
setblock ~167 ~138 ~79 oak_leaves[persistent=true]
setblock ~167 ~138 ~80 jungle_leaves[persistent=true]
setblock ~167 ~138 ~81 jungle_leaves[persistent=true]
setblock ~167 ~139 ~74 jungle_leaves[persistent=true]
setblock ~167 ~139 ~75 oak_leaves[persistent=true]
setblock ~167 ~139 ~76 oak_leaves[persistent=true]
setblock ~167 ~139 ~77 oak_leaves[persistent=true]
setblock ~167 ~139 ~78 oak_leaves[persistent=true]
setblock ~167 ~139 ~79 oak_leaves[persistent=true]
setblock ~167 ~139 ~80 oak_leaves[persistent=true]
setblock ~167 ~140 ~74 oak_leaves[persistent=true]
setblock ~167 ~140 ~75 oak_leaves[persistent=true]
setblock ~167 ~140 ~76 oak_leaves[persistent=true]
setblock ~167 ~140 ~77 oak_leaves[persistent=true]
setblock ~167 ~140 ~79 oak_leaves[persistent=true]
setblock ~167 ~140 ~80 oak_leaves[persistent=true]
setblock ~167 ~141 ~74 oak_leaves[persistent=true]
setblock ~167 ~141 ~75 oak_leaves[persistent=true]
setblock ~167 ~141 ~76 oak_leaves[persistent=true]
setblock ~167 ~141 ~77 oak_leaves[persistent=true]
setblock ~167 ~141 ~78 oak_leaves[persistent=true]
setblock ~167 ~141 ~79 oak_leaves[persistent=true]
setblock ~167 ~142 ~74 oak_leaves[persistent=true]
setblock ~167 ~142 ~75 oak_leaves[persistent=true]
setblock ~167 ~142 ~76 jungle_leaves[persistent=true]
setblock ~167 ~142 ~77 oak_leaves[persistent=true]
setblock ~167 ~142 ~78 oak_leaves[persistent=true]
setblock ~167 ~142 ~79 oak_leaves[persistent=true]
setblock ~168 ~114 ~75 dirt
setblock ~168 ~115 ~74 dirt
setblock ~168 ~115 ~75 dirt
setblock ~168 ~115 ~76 dirt
setblock ~168 ~116 ~74 dirt
setblock ~168 ~116 ~75 dirt
setblock ~168 ~116 ~76 dirt
setblock ~168 ~116 ~77 dirt
setblock ~168 ~117 ~73 dirt
setblock ~168 ~117 ~74 dirt
setblock ~168 ~117 ~75 dirt
setblock ~168 ~117 ~76 dirt
setblock ~168 ~117 ~77 dirt
setblock ~168 ~117 ~78 dirt
setblock ~168 ~117 ~81 dirt
setblock ~168 ~118 ~72 dirt
setblock ~168 ~118 ~73 dirt
setblock ~168 ~118 ~74 dirt
setblock ~168 ~118 ~75 dirt
setblock ~168 ~118 ~76 dirt
setblock ~168 ~118 ~77 dirt
setblock ~168 ~118 ~78 dirt
setblock ~168 ~118 ~79 dirt
setblock ~168 ~118 ~81 dirt
setblock ~168 ~119 ~71 dirt
setblock ~168 ~119 ~72 dirt
setblock ~168 ~119 ~73 dirt
setblock ~168 ~119 ~74 dirt
setblock ~168 ~119 ~75 dirt
setblock ~168 ~119 ~76 dirt
setblock ~168 ~119 ~77 dirt
setblock ~168 ~119 ~78 dirt
setblock ~168 ~119 ~79 dirt
setblock ~168 ~119 ~80 dirt
setblock ~168 ~119 ~81 dirt
setblock ~168 ~119 ~82 dirt
setblock ~168 ~120 ~70 dirt
setblock ~168 ~120 ~71 dirt
setblock ~168 ~120 ~72 dirt
setblock ~168 ~120 ~73 dirt
setblock ~168 ~120 ~74 dirt
setblock ~168 ~120 ~75 dirt
setblock ~168 ~120 ~76 dirt
setblock ~168 ~120 ~77 dirt
setblock ~168 ~120 ~78 dirt
setblock ~168 ~120 ~79 dirt
setblock ~168 ~120 ~80 dirt
setblock ~168 ~120 ~81 dirt
setblock ~168 ~120 ~82 dirt
setblock ~168 ~120 ~83 dirt
setblock ~168 ~120 ~107 dirt
setblock ~168 ~120 ~108 dirt
setblock ~168 ~121 ~70 dirt
setblock ~168 ~121 ~71 dirt
setblock ~168 ~121 ~72 dirt
setblock ~168 ~121 ~73 dirt
setblock ~168 ~121 ~74 dirt
setblock ~168 ~121 ~75 dirt
setblock ~168 ~121 ~76 dirt
setblock ~168 ~121 ~77 dirt
setblock ~168 ~121 ~78 dirt
setblock ~168 ~121 ~79 dirt
setblock ~168 ~121 ~80 dirt
setblock ~168 ~121 ~81 dirt
setblock ~168 ~121 ~82 dirt
setblock ~168 ~121 ~83 dirt
setblock ~168 ~121 ~106 dirt
setblock ~168 ~121 ~107 dirt
setblock ~168 ~121 ~108 dirt
setblock ~168 ~122 ~70 dirt
setblock ~168 ~122 ~71 dirt
setblock ~168 ~122 ~72 dirt
setblock ~168 ~122 ~73 dirt
setblock ~168 ~122 ~74 dirt
setblock ~168 ~122 ~75 dirt
setblock ~168 ~122 ~76 dirt
setblock ~168 ~122 ~77 dirt
setblock ~168 ~122 ~78 dirt
setblock ~168 ~122 ~79 dirt
setblock ~168 ~122 ~80 dirt
setblock ~168 ~122 ~81 dirt
setblock ~168 ~122 ~82 dirt
setblock ~168 ~122 ~83 dirt
setblock ~168 ~122 ~106 dirt
setblock ~168 ~122 ~107 dirt
setblock ~168 ~122 ~108 dirt
setblock ~168 ~123 ~70 dirt
setblock ~168 ~123 ~71 dirt
setblock ~168 ~123 ~72 dirt
setblock ~168 ~123 ~73 dirt
setblock ~168 ~123 ~74 dirt
setblock ~168 ~123 ~75 dirt
setblock ~168 ~123 ~76 dirt
setblock ~168 ~123 ~77 dirt
setblock ~168 ~123 ~78 dirt
setblock ~168 ~123 ~79 dirt
setblock ~168 ~123 ~80 dirt
setblock ~168 ~123 ~81 dirt
setblock ~168 ~123 ~82 dirt
setblock ~168 ~123 ~83 dirt
setblock ~168 ~123 ~106 dirt
setblock ~168 ~123 ~107 dirt
setblock ~168 ~123 ~108 dirt
setblock ~168 ~124 ~70 dirt
setblock ~168 ~124 ~71 dirt
setblock ~168 ~124 ~72 dirt
setblock ~168 ~124 ~73 dirt
setblock ~168 ~124 ~74 dirt
setblock ~168 ~124 ~75 dirt
setblock ~168 ~124 ~76 dirt
setblock ~168 ~124 ~77 dirt
setblock ~168 ~124 ~78 dirt
setblock ~168 ~124 ~79 dirt
setblock ~168 ~124 ~80 dirt
setblock ~168 ~124 ~81 dirt
setblock ~168 ~124 ~82 dirt
setblock ~168 ~124 ~83 dirt
setblock ~168 ~124 ~106 dirt
setblock ~168 ~124 ~107 dirt
setblock ~168 ~124 ~108 dirt
setblock ~168 ~125 ~70 dirt
setblock ~168 ~125 ~71 dirt
setblock ~168 ~125 ~72 dirt
setblock ~168 ~125 ~73 dirt
setblock ~168 ~125 ~74 dirt
setblock ~168 ~125 ~75 dirt
setblock ~168 ~125 ~76 dirt
setblock ~168 ~125 ~77 dirt
setblock ~168 ~125 ~78 dirt
setblock ~168 ~125 ~79 dirt
setblock ~168 ~125 ~80 dirt
setblock ~168 ~125 ~81 dirt
setblock ~168 ~125 ~82 dirt
setblock ~168 ~125 ~83 dirt
setblock ~168 ~125 ~106 grass_block
setblock ~168 ~125 ~107 grass_block
setblock ~168 ~125 ~108 grass_block
setblock ~168 ~126 ~70 dirt
setblock ~168 ~126 ~71 dirt
setblock ~168 ~126 ~72 dirt
setblock ~168 ~126 ~73 dirt
setblock ~168 ~126 ~74 dirt
setblock ~168 ~126 ~75 dirt
setblock ~168 ~126 ~76 dirt
setblock ~168 ~126 ~77 dirt
setblock ~168 ~126 ~78 dirt
setblock ~168 ~126 ~79 dirt
setblock ~168 ~126 ~80 grass_block
setblock ~168 ~126 ~81 grass_block
setblock ~168 ~126 ~82 grass_block
setblock ~168 ~126 ~83 grass_block
setblock ~168 ~126 ~106 poppy
setblock ~168 ~126 ~108 short_grass
setblock ~168 ~127 ~70 dirt
setblock ~168 ~127 ~71 dirt
setblock ~168 ~127 ~72 dirt
setblock ~168 ~127 ~73 dirt
setblock ~168 ~127 ~74 dirt
setblock ~168 ~127 ~75 dirt
setblock ~168 ~127 ~76 grass_block
setblock ~168 ~127 ~77 grass_block
setblock ~168 ~127 ~78 grass_block
setblock ~168 ~127 ~79 grass_block
setblock ~168 ~128 ~70 dirt
setblock ~168 ~128 ~71 grass_block
setblock ~168 ~128 ~72 grass_block
setblock ~168 ~128 ~73 grass_block
setblock ~168 ~128 ~74 grass_block
setblock ~168 ~128 ~75 grass_block
setblock ~168 ~128 ~78 spruce_slab
setblock ~168 ~128 ~79 short_grass
setblock ~168 ~128 ~80 spruce_slab
setblock ~168 ~129 ~70 grass_block
setblock ~168 ~129 ~71 short_grass
setblock ~168 ~129 ~72 short_grass
setblock ~168 ~129 ~75 short_grass
setblock ~168 ~134 ~75 oak_leaves[persistent=true]
setblock ~168 ~134 ~76 oak_leaves[persistent=true]
setblock ~168 ~134 ~77 oak_leaves[persistent=true]
setblock ~168 ~135 ~71 oak_leaves[persistent=true]
setblock ~168 ~135 ~72 oak_leaves[persistent=true]
setblock ~168 ~135 ~73 oak_leaves[persistent=true]
setblock ~168 ~135 ~75 oak_leaves[persistent=true]
setblock ~168 ~135 ~76 oak_leaves[persistent=true]
setblock ~168 ~135 ~78 oak_leaves[persistent=true]
setblock ~168 ~135 ~79 oak_leaves[persistent=true]
setblock ~168 ~135 ~80 oak_leaves[persistent=true]
setblock ~168 ~136 ~70 oak_leaves[persistent=true]
setblock ~168 ~136 ~71 oak_leaves[persistent=true]
setblock ~168 ~136 ~72 oak_leaves[persistent=true]
setblock ~168 ~136 ~73 jungle_leaves[persistent=true]
setblock ~168 ~136 ~74 jungle_leaves[persistent=true]
setblock ~168 ~136 ~75 oak_leaves[persistent=true]
setblock ~168 ~136 ~76 oak_leaves[persistent=true]
setblock ~168 ~136 ~77 oak_leaves[persistent=true]
setblock ~168 ~136 ~78 oak_leaves[persistent=true]
setblock ~168 ~136 ~79 oak_leaves[persistent=true]
setblock ~168 ~136 ~80 oak_leaves[persistent=true]
setblock ~168 ~136 ~81 oak_leaves[persistent=true]
setblock ~168 ~137 ~71 oak_leaves[persistent=true]
setblock ~168 ~137 ~72 jungle_leaves[persistent=true]
setblock ~168 ~137 ~73 oak_leaves[persistent=true]
setblock ~168 ~137 ~74 oak_leaves[persistent=true]
setblock ~168 ~137 ~75 oak_leaves[persistent=true]
setblock ~168 ~137 ~76 jungle_leaves[persistent=true]
setblock ~168 ~137 ~77 oak_wood
setblock ~168 ~137 ~78 jungle_leaves[persistent=true]
setblock ~168 ~137 ~79 oak_wood
setblock ~168 ~137 ~80 jungle_leaves[persistent=true]
setblock ~168 ~137 ~81 jungle_leaves[persistent=true]
setblock ~168 ~137 ~82 oak_leaves[persistent=true]
setblock ~168 ~138 ~73 oak_leaves[persistent=true]
setblock ~168 ~138 ~74 oak_leaves[persistent=true]
setblock ~168 ~138 ~75 jungle_leaves[persistent=true]
setblock ~168 ~138 ~77 oak_wood
setblock ~168 ~138 ~78 jungle_leaves[persistent=true]
setblock ~168 ~138 ~79 oak_leaves[persistent=true]
setblock ~168 ~138 ~80 oak_leaves[persistent=true]
setblock ~168 ~138 ~81 oak_leaves[persistent=true]
setblock ~168 ~138 ~82 jungle_leaves[persistent=true]
setblock ~168 ~139 ~74 oak_leaves[persistent=true]
setblock ~168 ~139 ~75 jungle_leaves[persistent=true]
setblock ~168 ~139 ~76 oak_leaves[persistent=true]
setblock ~168 ~139 ~77 oak_leaves[persistent=true]
setblock ~168 ~139 ~79 jungle_leaves[persistent=true]
setblock ~168 ~139 ~80 oak_leaves[persistent=true]
setblock ~168 ~139 ~82 oak_leaves[persistent=true]
setblock ~168 ~140 ~74 oak_leaves[persistent=true]
setblock ~168 ~140 ~75 oak_leaves[persistent=true]
setblock ~168 ~140 ~77 jungle_leaves[persistent=true]
setblock ~168 ~140 ~78 oak_leaves[persistent=true]
setblock ~168 ~140 ~79 oak_leaves[persistent=true]
setblock ~168 ~140 ~80 jungle_leaves[persistent=true]
setblock ~168 ~140 ~81 oak_leaves[persistent=true]
setblock ~168 ~141 ~74 oak_leaves[persistent=true]
setblock ~168 ~141 ~75 jungle_leaves[persistent=true]
setblock ~168 ~141 ~77 oak_leaves[persistent=true]
setblock ~168 ~141 ~78 oak_leaves[persistent=true]
setblock ~168 ~141 ~79 oak_leaves[persistent=true]
setblock ~168 ~141 ~80 oak_leaves[persistent=true]
setblock ~168 ~141 ~81 oak_leaves[persistent=true]
setblock ~168 ~141 ~82 oak_leaves[persistent=true]
setblock ~168 ~142 ~75 oak_leaves[persistent=true]
setblock ~168 ~142 ~76 oak_leaves[persistent=true]
setblock ~168 ~142 ~77 oak_leaves[persistent=true]
setblock ~168 ~142 ~78 oak_leaves[persistent=true]
setblock ~168 ~142 ~79 oak_leaves[persistent=true]
setblock ~169 ~115 ~75 dirt
setblock ~169 ~116 ~75 dirt
setblock ~169 ~116 ~76 dirt
setblock ~169 ~117 ~74 dirt
setblock ~169 ~117 ~75 dirt
setblock ~169 ~117 ~76 dirt
setblock ~169 ~117 ~77 dirt
setblock ~169 ~118 ~74 dirt
setblock ~169 ~118 ~75 dirt
setblock ~169 ~118 ~76 dirt
setblock ~169 ~118 ~77 dirt
setblock ~169 ~118 ~78 dirt
setblock ~169 ~119 ~72 dirt
setblock ~169 ~119 ~74 dirt
setblock ~169 ~119 ~75 dirt
setblock ~169 ~119 ~76 dirt
setblock ~169 ~119 ~77 dirt
setblock ~169 ~119 ~78 dirt
setblock ~169 ~119 ~79 dirt
setblock ~169 ~119 ~81 dirt
setblock ~169 ~120 ~72 dirt
setblock ~169 ~120 ~73 dirt
setblock ~169 ~120 ~74 dirt
setblock ~169 ~120 ~75 dirt
setblock ~169 ~120 ~76 dirt
setblock ~169 ~120 ~77 dirt
setblock ~169 ~120 ~78 dirt
setblock ~169 ~120 ~79 dirt
setblock ~169 ~120 ~80 dirt
setblock ~169 ~120 ~81 dirt
setblock ~169 ~120 ~82 dirt
setblock ~169 ~121 ~71 dirt
setblock ~169 ~121 ~72 dirt
setblock ~169 ~121 ~73 dirt
setblock ~169 ~121 ~74 dirt
setblock ~169 ~121 ~75 dirt
setblock ~169 ~121 ~76 dirt
setblock ~169 ~121 ~77 dirt
setblock ~169 ~121 ~78 dirt
setblock ~169 ~121 ~79 dirt
setblock ~169 ~121 ~80 dirt
setblock ~169 ~121 ~81 dirt
setblock ~169 ~121 ~82 dirt
setblock ~169 ~121 ~83 dirt
setblock ~169 ~122 ~71 dirt
setblock ~169 ~122 ~72 dirt
setblock ~169 ~122 ~73 dirt
setblock ~169 ~122 ~74 dirt
setblock ~169 ~122 ~75 dirt
setblock ~169 ~122 ~76 dirt
setblock ~169 ~122 ~77 dirt
setblock ~169 ~122 ~78 dirt
setblock ~169 ~122 ~79 dirt
setblock ~169 ~122 ~80 dirt
setblock ~169 ~122 ~81 dirt
setblock ~169 ~122 ~82 dirt
setblock ~169 ~122 ~83 dirt
setblock ~169 ~123 ~71 dirt
setblock ~169 ~123 ~72 dirt
setblock ~169 ~123 ~73 dirt
setblock ~169 ~123 ~74 dirt
setblock ~169 ~123 ~75 dirt
setblock ~169 ~123 ~76 dirt
setblock ~169 ~123 ~77 dirt
setblock ~169 ~123 ~78 dirt
setblock ~169 ~123 ~79 dirt
setblock ~169 ~123 ~80 dirt
setblock ~169 ~123 ~81 dirt
setblock ~169 ~123 ~82 dirt
setblock ~169 ~123 ~83 dirt
setblock ~169 ~124 ~71 dirt
setblock ~169 ~124 ~72 dirt
setblock ~169 ~124 ~73 dirt
setblock ~169 ~124 ~74 dirt
setblock ~169 ~124 ~75 dirt
setblock ~169 ~124 ~76 dirt
setblock ~169 ~124 ~77 dirt
setblock ~169 ~124 ~78 dirt
setblock ~169 ~124 ~79 dirt
setblock ~169 ~124 ~80 dirt
setblock ~169 ~124 ~81 dirt
setblock ~169 ~124 ~82 dirt
setblock ~169 ~124 ~83 dirt
setblock ~169 ~125 ~71 dirt
setblock ~169 ~125 ~72 dirt
setblock ~169 ~125 ~73 dirt
setblock ~169 ~125 ~74 dirt
setblock ~169 ~125 ~75 dirt
setblock ~169 ~125 ~76 dirt
setblock ~169 ~125 ~77 dirt
setblock ~169 ~125 ~78 dirt
setblock ~169 ~125 ~79 dirt
setblock ~169 ~125 ~80 dirt
setblock ~169 ~125 ~81 dirt
setblock ~169 ~125 ~82 dirt
setblock ~169 ~125 ~83 dirt
setblock ~169 ~126 ~71 dirt
setblock ~169 ~126 ~72 dirt
setblock ~169 ~126 ~73 dirt
setblock ~169 ~126 ~74 dirt
setblock ~169 ~126 ~75 dirt
setblock ~169 ~126 ~76 dirt
setblock ~169 ~126 ~77 dirt
setblock ~169 ~126 ~78 dirt
setblock ~169 ~126 ~79 dirt
setblock ~169 ~126 ~80 dirt
setblock ~169 ~126 ~81 dirt
setblock ~169 ~126 ~82 dirt
setblock ~169 ~126 ~83 grass_block
setblock ~169 ~127 ~71 dirt
setblock ~169 ~127 ~72 dirt
setblock ~169 ~127 ~73 dirt
setblock ~169 ~127 ~74 dirt
setblock ~169 ~127 ~75 dirt
setblock ~169 ~127 ~76 dirt
setblock ~169 ~127 ~77 dirt
setblock ~169 ~127 ~78 dirt
setblock ~169 ~127 ~79 grass_block
setblock ~169 ~127 ~80 grass_block
setblock ~169 ~127 ~81 grass_block
setblock ~169 ~127 ~82 grass_block
setblock ~169 ~128 ~71 dirt
setblock ~169 ~128 ~72 dirt
setblock ~169 ~128 ~73 dirt
setblock ~169 ~128 ~74 dirt
setblock ~169 ~128 ~75 grass_block
setblock ~169 ~128 ~76 grass_block
setblock ~169 ~128 ~77 grass_block
setblock ~169 ~128 ~78 spruce_slab
setblock ~169 ~128 ~79 oak_log
setblock ~169 ~128 ~80 short_grass
setblock ~169 ~128 ~82 short_grass
setblock ~169 ~129 ~71 grass_block
setblock ~169 ~129 ~72 grass_block
setblock ~169 ~129 ~73 grass_block
setblock ~169 ~129 ~74 grass_block
setblock ~169 ~129 ~76 fern
setblock ~169 ~129 ~78 short_grass
setblock ~169 ~129 ~79 oak_log
setblock ~169 ~130 ~71 fern
setblock ~169 ~130 ~74 short_grass
setblock ~169 ~130 ~79 oak_log
setblock ~169 ~131 ~79 oak_log
setblock ~169 ~132 ~79 oak_log
setblock ~169 ~133 ~79 oak_log
setblock ~169 ~134 ~74 oak_leaves[persistent=true]
setblock ~169 ~134 ~75 oak_leaves[persistent=true]
setblock ~169 ~134 ~76 oak_leaves[persistent=true]
setblock ~169 ~134 ~77 oak_leaves[persistent=true]
setblock ~169 ~134 ~78 oak_leaves[persistent=true]
setblock ~169 ~134 ~79 spruce_slab[type=top]
setblock ~169 ~135 ~70 jungle_leaves[persistent=true]
setblock ~169 ~135 ~72 oak_leaves[persistent=true]
setblock ~169 ~135 ~73 jungle_leaves[persistent=true]
setblock ~169 ~135 ~74 oak_leaves[persistent=true]
setblock ~169 ~135 ~75 oak_leaves[persistent=true]
setblock ~169 ~135 ~76 jungle_leaves[persistent=true]
setblock ~169 ~135 ~77 jungle_leaves[persistent=true]
setblock ~169 ~135 ~78 oak_leaves[persistent=true]
setblock ~169 ~135 ~79 oak_log
setblock ~169 ~135 ~80 oak_leaves[persistent=true]
setblock ~169 ~136 ~70 oak_leaves[persistent=true]
setblock ~169 ~136 ~71 oak_wood
setblock ~169 ~136 ~72 oak_wood
setblock ~169 ~136 ~73 oak_wood
setblock ~169 ~136 ~74 oak_leaves[persistent=true]
setblock ~169 ~136 ~75 oak_leaves[persistent=true]
setblock ~169 ~136 ~76 jungle_leaves[persistent=true]
setblock ~169 ~136 ~77 jungle_leaves[persistent=true]
setblock ~169 ~136 ~78 oak_wood
setblock ~169 ~136 ~79 oak_leaves[persistent=true]
setblock ~169 ~136 ~80 oak_leaves[persistent=true]
setblock ~169 ~136 ~81 oak_leaves[persistent=true]
setblock ~169 ~136 ~82 oak_leaves[persistent=true]
setblock ~169 ~137 ~70 oak_leaves[persistent=true]
setblock ~169 ~137 ~72 oak_leaves[persistent=true]
setblock ~169 ~137 ~73 oak_leaves[persistent=true]
setblock ~169 ~137 ~74 oak_wood
setblock ~169 ~137 ~75 oak_wood
setblock ~169 ~137 ~76 oak_wood
setblock ~169 ~137 ~77 oak_wood
setblock ~169 ~137 ~78 oak_leaves[persistent=true]
setblock ~169 ~137 ~79 oak_wood
setblock ~169 ~137 ~80 oak_leaves[persistent=true]
setblock ~169 ~137 ~81 oak_leaves[persistent=true]
setblock ~169 ~137 ~82 jungle_leaves[persistent=true]
setblock ~169 ~138 ~73 oak_leaves[persistent=true]
setblock ~169 ~138 ~75 jungle_leaves[persistent=true]
setblock ~169 ~138 ~76 oak_leaves[persistent=true]
setblock ~169 ~138 ~77 jungle_leaves[persistent=true]
setblock ~169 ~138 ~78 oak_wood
setblock ~169 ~138 ~79 oak_leaves[persistent=true]
setblock ~169 ~138 ~80 jungle_leaves[persistent=true]
setblock ~169 ~138 ~82 jungle_leaves[persistent=true]
setblock ~169 ~139 ~74 oak_leaves[persistent=true]
setblock ~169 ~139 ~75 jungle_leaves[persistent=true]
setblock ~169 ~139 ~76 oak_leaves[persistent=true]
setblock ~169 ~139 ~77 oak_leaves[persistent=true]
setblock ~169 ~139 ~78 oak_log
setblock ~169 ~139 ~79 oak_leaves[persistent=true]
setblock ~169 ~139 ~80 oak_leaves[persistent=true]
setblock ~169 ~139 ~81 oak_leaves[persistent=true]
setblock ~169 ~139 ~82 jungle_leaves[persistent=true]
setblock ~169 ~140 ~74 oak_leaves[persistent=true]
setblock ~169 ~140 ~75 oak_leaves[persistent=true]
setblock ~169 ~140 ~76 jungle_leaves[persistent=true]
setblock ~169 ~140 ~77 oak_log
setblock ~169 ~140 ~78 jungle_leaves[persistent=true]
setblock ~169 ~140 ~79 jungle_leaves[persistent=true]
setblock ~169 ~140 ~80 oak_leaves[persistent=true]
setblock ~169 ~140 ~81 oak_leaves[persistent=true]
setblock ~169 ~140 ~82 jungle_leaves[persistent=true]
setblock ~169 ~141 ~74 oak_leaves[persistent=true]
setblock ~169 ~141 ~75 oak_leaves[persistent=true]
setblock ~169 ~141 ~76 oak_leaves[persistent=true]
setblock ~169 ~141 ~78 oak_leaves[persistent=true]
setblock ~169 ~141 ~79 oak_leaves[persistent=true]
setblock ~169 ~141 ~80 jungle_leaves[persistent=true]
setblock ~169 ~141 ~81 oak_leaves[persistent=true]
setblock ~169 ~141 ~82 jungle_leaves[persistent=true]
setblock ~169 ~142 ~75 oak_leaves[persistent=true]
setblock ~169 ~142 ~76 oak_leaves[persistent=true]
setblock ~169 ~142 ~77 oak_leaves[persistent=true]
setblock ~169 ~142 ~78 oak_leaves[persistent=true]
setblock ~169 ~142 ~79 oak_leaves[persistent=true]
setblock ~169 ~142 ~80 oak_leaves[persistent=true]
setblock ~170 ~117 ~75 dirt
setblock ~170 ~118 ~75 dirt
setblock ~170 ~118 ~76 dirt
setblock ~170 ~118 ~77 dirt
setblock ~170 ~119 ~75 dirt
setblock ~170 ~119 ~76 dirt
setblock ~170 ~119 ~77 dirt
setblock ~170 ~120 ~74 dirt
setblock ~170 ~120 ~75 dirt
setblock ~170 ~120 ~76 dirt
setblock ~170 ~120 ~77 dirt
setblock ~170 ~120 ~78 dirt
setblock ~170 ~121 ~72 dirt
setblock ~170 ~121 ~73 dirt
setblock ~170 ~121 ~74 dirt
setblock ~170 ~121 ~75 dirt
setblock ~170 ~121 ~76 dirt
setblock ~170 ~121 ~77 dirt
setblock ~170 ~121 ~78 dirt
setblock ~170 ~121 ~82 dirt
setblock ~170 ~122 ~72 dirt
setblock ~170 ~122 ~73 dirt
setblock ~170 ~122 ~74 dirt
setblock ~170 ~122 ~75 dirt
setblock ~170 ~122 ~76 dirt
setblock ~170 ~122 ~77 dirt
setblock ~170 ~122 ~78 dirt
setblock ~170 ~122 ~82 dirt
setblock ~170 ~123 ~72 dirt
setblock ~170 ~123 ~73 dirt
setblock ~170 ~123 ~74 dirt
setblock ~170 ~123 ~75 dirt
setblock ~170 ~123 ~76 dirt
setblock ~170 ~123 ~77 dirt
setblock ~170 ~123 ~78 dirt
setblock ~170 ~123 ~82 dirt
setblock ~170 ~124 ~72 dirt
setblock ~170 ~124 ~73 dirt
setblock ~170 ~124 ~74 dirt
setblock ~170 ~124 ~75 dirt
setblock ~170 ~124 ~76 dirt
setblock ~170 ~124 ~77 dirt
setblock ~170 ~124 ~78 dirt
setblock ~170 ~124 ~82 dirt
setblock ~170 ~125 ~72 dirt
setblock ~170 ~125 ~73 dirt
setblock ~170 ~125 ~74 dirt
setblock ~170 ~125 ~75 dirt
setblock ~170 ~125 ~76 dirt
setblock ~170 ~125 ~77 dirt
setblock ~170 ~125 ~78 dirt
setblock ~170 ~125 ~82 dirt
setblock ~170 ~126 ~72 dirt
setblock ~170 ~126 ~73 dirt
setblock ~170 ~126 ~74 dirt
setblock ~170 ~126 ~75 dirt
setblock ~170 ~126 ~76 dirt
setblock ~170 ~126 ~77 dirt
setblock ~170 ~126 ~78 dirt
setblock ~170 ~126 ~82 dirt
setblock ~170 ~127 ~72 dirt
setblock ~170 ~127 ~73 dirt
setblock ~170 ~127 ~74 dirt
setblock ~170 ~127 ~75 dirt
setblock ~170 ~127 ~76 dirt
setblock ~170 ~127 ~77 dirt
setblock ~170 ~127 ~78 dirt
setblock ~170 ~127 ~82 grass_block
setblock ~170 ~128 ~72 dirt
setblock ~170 ~128 ~73 dirt
setblock ~170 ~128 ~74 dirt
setblock ~170 ~128 ~75 dirt
setblock ~170 ~128 ~76 dirt
setblock ~170 ~128 ~77 dirt
setblock ~170 ~128 ~78 grass_block
setblock ~170 ~128 ~79 spruce_slab
setblock ~170 ~128 ~80 spruce_slab
setblock ~170 ~129 ~72 dirt
setblock ~170 ~129 ~73 dirt
setblock ~170 ~129 ~74 dirt
setblock ~170 ~129 ~75 grass_block
setblock ~170 ~129 ~76 grass_block
setblock ~170 ~129 ~77 grass_block
setblock ~170 ~130 ~72 grass_block
setblock ~170 ~130 ~73 grass_block
setblock ~170 ~130 ~74 grass_block
setblock ~170 ~132 ~71 oak_leaves[persistent=true]
setblock ~170 ~132 ~72 oak_leaves[persistent=true]
setblock ~170 ~132 ~73 oak_leaves[persistent=true]
setblock ~170 ~132 ~74 oak_leaves[persistent=true]
setblock ~170 ~133 ~71 oak_leaves[persistent=true]
setblock ~170 ~133 ~72 oak_leaves[persistent=true]
setblock ~170 ~133 ~73 oak_leaves[persistent=true]
setblock ~170 ~133 ~74 oak_leaves[persistent=true]
setblock ~170 ~134 ~71 oak_leaves[persistent=true]
setblock ~170 ~134 ~73 oak_leaves[persistent=true]
setblock ~170 ~134 ~75 jungle_leaves[persistent=true]
setblock ~170 ~134 ~76 oak_leaves[persistent=true]
setblock ~170 ~134 ~77 oak_leaves[persistent=true]
setblock ~170 ~134 ~78 oak_leaves[persistent=true]
setblock ~170 ~135 ~70 jungle_leaves[persistent=true]
setblock ~170 ~135 ~71 oak_leaves[persistent=true]
setblock ~170 ~135 ~72 oak_leaves[persistent=true]
setblock ~170 ~135 ~73 oak_leaves[persistent=true]
setblock ~170 ~135 ~75 jungle_leaves[persistent=true]
setblock ~170 ~135 ~76 oak_wood
setblock ~170 ~135 ~77 jungle_leaves[persistent=true]
setblock ~170 ~135 ~78 jungle_leaves[persistent=true]
setblock ~170 ~135 ~79 oak_leaves[persistent=true]
setblock ~170 ~135 ~80 oak_leaves[persistent=true]
setblock ~170 ~136 ~71 oak_leaves[persistent=true]
setblock ~170 ~136 ~72 oak_leaves[persistent=true]
setblock ~170 ~136 ~73 oak_leaves[persistent=true]
setblock ~170 ~136 ~74 jungle_leaves[persistent=true]
setblock ~170 ~136 ~75 oak_leaves[persistent=true]
setblock ~170 ~136 ~76 oak_leaves[persistent=true]
setblock ~170 ~136 ~77 oak_wood
setblock ~170 ~136 ~78 oak_wood
setblock ~170 ~136 ~79 oak_leaves[persistent=true]
setblock ~170 ~136 ~80 oak_leaves[persistent=true]
setblock ~170 ~136 ~81 oak_leaves[persistent=true]
setblock ~170 ~136 ~82 oak_leaves[persistent=true]
setblock ~170 ~137 ~70 jungle_leaves[persistent=true]
setblock ~170 ~137 ~72 oak_leaves[persistent=true]
