setblock ~31 ~125 ~103 short_grass
setblock ~31 ~125 ~104 grass_block
setblock ~31 ~125 ~105 grass_block
setblock ~31 ~125 ~106 dirt
setblock ~31 ~125 ~107 dirt
setblock ~31 ~125 ~108 dirt
setblock ~31 ~125 ~109 dirt
setblock ~31 ~125 ~110 dirt
setblock ~31 ~125 ~111 dirt
setblock ~31 ~125 ~112 dirt
setblock ~31 ~125 ~113 dirt
setblock ~31 ~125 ~114 grass_block
setblock ~31 ~125 ~115 grass_block
setblock ~31 ~126 ~72 dirt
setblock ~31 ~126 ~73 dirt
setblock ~31 ~126 ~74 dirt
setblock ~31 ~126 ~75 dirt
setblock ~31 ~126 ~76 dirt
setblock ~31 ~126 ~77 dirt
setblock ~31 ~126 ~78 dirt
setblock ~31 ~126 ~79 dirt
setblock ~31 ~126 ~80 dirt
setblock ~31 ~126 ~81 dirt
setblock ~31 ~126 ~82 dirt
setblock ~31 ~126 ~83 grass_block
setblock ~31 ~126 ~84 grass_block
setblock ~31 ~126 ~85 grass_block
setblock ~31 ~126 ~87 fern
setblock ~31 ~126 ~105 fern
setblock ~31 ~126 ~106 grass_block
setblock ~31 ~126 ~107 dirt
setblock ~31 ~126 ~108 dirt
setblock ~31 ~126 ~109 dirt
setblock ~31 ~126 ~110 dirt
setblock ~31 ~126 ~111 dirt
setblock ~31 ~126 ~112 dirt
setblock ~31 ~126 ~113 grass_block
setblock ~31 ~127 ~72 grass_block
setblock ~31 ~127 ~73 grass_block
setblock ~31 ~127 ~74 grass_block
setblock ~31 ~127 ~75 grass_block
setblock ~31 ~127 ~76 grass_block
setblock ~31 ~127 ~77 grass_block
setblock ~31 ~127 ~78 dirt
setblock ~31 ~127 ~79 dirt
setblock ~31 ~127 ~80 dirt
setblock ~31 ~127 ~81 grass_block
setblock ~31 ~127 ~82 grass_block
setblock ~31 ~127 ~85 short_grass
setblock ~31 ~127 ~106 short_grass
setblock ~31 ~127 ~107 grass_block
setblock ~31 ~127 ~108 dirt
setblock ~31 ~127 ~109 dirt
setblock ~31 ~127 ~110 dirt
setblock ~31 ~127 ~111 dirt
setblock ~31 ~127 ~112 grass_block
setblock ~31 ~128 ~76 short_grass
setblock ~31 ~128 ~78 grass_block
setblock ~31 ~128 ~79 grass_block
setblock ~31 ~128 ~80 grass_block
setblock ~31 ~128 ~108 grass_block
setblock ~31 ~128 ~109 dirt
setblock ~31 ~128 ~110 dirt
setblock ~31 ~128 ~111 grass_block
setblock ~31 ~129 ~79 short_grass
setblock ~31 ~129 ~80 short_grass
setblock ~31 ~129 ~108 short_grass
setblock ~31 ~129 ~109 grass_block
setblock ~31 ~129 ~110 grass_block
setblock ~32 ~108 ~105 dirt
setblock ~32 ~108 ~106 dirt
setblock ~32 ~108 ~112 dirt
setblock ~32 ~109 ~101 dirt
setblock ~32 ~109 ~102 dirt
setblock ~32 ~109 ~105 dirt
setblock ~32 ~109 ~106 dirt
setblock ~32 ~109 ~107 dirt
setblock ~32 ~109 ~110 dirt
setblock ~32 ~109 ~112 dirt
setblock ~32 ~110 ~100 dirt
setblock ~32 ~110 ~101 dirt
setblock ~32 ~110 ~102 dirt
setblock ~32 ~110 ~103 dirt
setblock ~32 ~110 ~104 dirt
setblock ~32 ~110 ~105 dirt
setblock ~32 ~110 ~106 dirt
setblock ~32 ~110 ~107 dirt
setblock ~32 ~110 ~109 dirt
setblock ~32 ~110 ~110 dirt
setblock ~32 ~110 ~111 dirt
setblock ~32 ~110 ~112 dirt
setblock ~32 ~110 ~113 dirt
setblock ~32 ~110 ~114 dirt
setblock ~32 ~111 ~100 dirt
setblock ~32 ~111 ~101 dirt
setblock ~32 ~111 ~102 dirt
setblock ~32 ~111 ~103 dirt
setblock ~32 ~111 ~104 dirt
setblock ~32 ~111 ~105 dirt
setblock ~32 ~111 ~106 dirt
setblock ~32 ~111 ~107 dirt
setblock ~32 ~111 ~108 dirt
setblock ~32 ~111 ~109 dirt
setblock ~32 ~111 ~110 dirt
setblock ~32 ~111 ~111 dirt
setblock ~32 ~111 ~112 dirt
setblock ~32 ~111 ~113 dirt
setblock ~32 ~111 ~114 dirt
setblock ~32 ~111 ~115 dirt
setblock ~32 ~112 ~77 dirt
setblock ~32 ~112 ~99 dirt
setblock ~32 ~112 ~100 dirt
setblock ~32 ~112 ~101 dirt
setblock ~32 ~112 ~102 dirt
setblock ~32 ~112 ~103 dirt
setblock ~32 ~112 ~104 dirt
setblock ~32 ~112 ~105 dirt
setblock ~32 ~112 ~106 dirt
setblock ~32 ~112 ~107 dirt
setblock ~32 ~112 ~108 dirt
setblock ~32 ~112 ~109 dirt
setblock ~32 ~112 ~110 dirt
setblock ~32 ~112 ~111 dirt
setblock ~32 ~112 ~112 dirt
setblock ~32 ~112 ~113 dirt
setblock ~32 ~112 ~114 dirt
setblock ~32 ~112 ~115 dirt
setblock ~32 ~112 ~116 dirt
setblock ~32 ~113 ~76 dirt
setblock ~32 ~113 ~77 dirt
setblock ~32 ~113 ~81 dirt
setblock ~32 ~113 ~95 dirt
setblock ~32 ~113 ~96 dirt
setblock ~32 ~113 ~99 dirt
setblock ~32 ~113 ~100 dirt
setblock ~32 ~113 ~101 dirt
setblock ~32 ~113 ~102 dirt
setblock ~32 ~113 ~103 dirt
setblock ~32 ~113 ~104 dirt
setblock ~32 ~113 ~105 dirt
setblock ~32 ~113 ~106 dirt
setblock ~32 ~113 ~107 dirt
setblock ~32 ~113 ~108 dirt
setblock ~32 ~113 ~109 dirt
setblock ~32 ~113 ~110 dirt
setblock ~32 ~113 ~111 dirt
setblock ~32 ~113 ~112 dirt
setblock ~32 ~113 ~113 dirt
setblock ~32 ~113 ~114 dirt
setblock ~32 ~113 ~115 dirt
setblock ~32 ~113 ~116 dirt
setblock ~32 ~113 ~117 dirt
setblock ~32 ~114 ~76 dirt
setblock ~32 ~114 ~77 dirt
setblock ~32 ~114 ~79 dirt
setblock ~32 ~114 ~81 dirt
setblock ~32 ~114 ~86 dirt
setblock ~32 ~114 ~92 dirt
setblock ~32 ~114 ~93 dirt
setblock ~32 ~114 ~94 dirt
setblock ~32 ~114 ~95 dirt
setblock ~32 ~114 ~96 dirt
setblock ~32 ~114 ~98 dirt
setblock ~32 ~114 ~99 dirt
setblock ~32 ~114 ~100 dirt
setblock ~32 ~114 ~101 dirt
setblock ~32 ~114 ~102 dirt
setblock ~32 ~114 ~103 dirt
setblock ~32 ~114 ~104 dirt
setblock ~32 ~114 ~105 dirt
setblock ~32 ~114 ~106 dirt
setblock ~32 ~114 ~107 dirt
setblock ~32 ~114 ~108 dirt
setblock ~32 ~114 ~109 dirt
setblock ~32 ~114 ~110 dirt
setblock ~32 ~114 ~111 dirt
setblock ~32 ~114 ~112 dirt
setblock ~32 ~114 ~113 dirt
setblock ~32 ~114 ~114 dirt
setblock ~32 ~114 ~115 dirt
setblock ~32 ~114 ~116 dirt
setblock ~32 ~114 ~117 dirt
setblock ~32 ~115 ~75 dirt
setblock ~32 ~115 ~76 dirt
setblock ~32 ~115 ~77 dirt
setblock ~32 ~115 ~78 dirt
setblock ~32 ~115 ~79 dirt
setblock ~32 ~115 ~80 dirt
setblock ~32 ~115 ~81 dirt
setblock ~32 ~115 ~82 dirt
setblock ~32 ~115 ~85 dirt
setblock ~32 ~115 ~86 dirt
setblock ~32 ~115 ~87 dirt
setblock ~32 ~115 ~91 dirt
setblock ~32 ~115 ~92 dirt
setblock ~32 ~115 ~93 dirt
setblock ~32 ~115 ~94 dirt
setblock ~32 ~115 ~95 dirt
setblock ~32 ~115 ~96 dirt
setblock ~32 ~115 ~97 dirt
setblock ~32 ~115 ~98 dirt
setblock ~32 ~115 ~99 dirt
setblock ~32 ~115 ~100 dirt
setblock ~32 ~115 ~101 dirt
setblock ~32 ~115 ~102 dirt
setblock ~32 ~115 ~103 dirt
setblock ~32 ~115 ~104 dirt
setblock ~32 ~115 ~105 dirt
setblock ~32 ~115 ~106 dirt
setblock ~32 ~115 ~107 dirt
setblock ~32 ~115 ~108 dirt
setblock ~32 ~115 ~109 dirt
setblock ~32 ~115 ~110 dirt
setblock ~32 ~115 ~111 dirt
setblock ~32 ~115 ~112 dirt
setblock ~32 ~115 ~113 dirt
setblock ~32 ~115 ~114 dirt
setblock ~32 ~115 ~115 dirt
setblock ~32 ~115 ~116 dirt
setblock ~32 ~115 ~117 dirt
setblock ~32 ~115 ~118 dirt
setblock ~32 ~116 ~74 dirt
setblock ~32 ~116 ~75 dirt
setblock ~32 ~116 ~76 dirt
setblock ~32 ~116 ~77 dirt
setblock ~32 ~116 ~78 dirt
setblock ~32 ~116 ~79 dirt
setblock ~32 ~116 ~80 dirt
setblock ~32 ~116 ~81 dirt
setblock ~32 ~116 ~82 dirt
setblock ~32 ~116 ~83 dirt
setblock ~32 ~116 ~84 dirt
setblock ~32 ~116 ~85 dirt
setblock ~32 ~116 ~86 dirt
setblock ~32 ~116 ~87 dirt
setblock ~32 ~116 ~90 dirt
setblock ~32 ~116 ~91 dirt
setblock ~32 ~116 ~92 dirt
setblock ~32 ~116 ~93 dirt
setblock ~32 ~116 ~94 dirt
setblock ~32 ~116 ~95 dirt
setblock ~32 ~116 ~96 dirt
setblock ~32 ~116 ~97 dirt
setblock ~32 ~116 ~98 dirt
setblock ~32 ~116 ~99 dirt
setblock ~32 ~116 ~100 dirt
setblock ~32 ~116 ~101 dirt
setblock ~32 ~116 ~102 dirt
setblock ~32 ~116 ~103 dirt
setblock ~32 ~116 ~104 dirt
setblock ~32 ~116 ~105 dirt
setblock ~32 ~116 ~106 dirt
setblock ~32 ~116 ~107 dirt
setblock ~32 ~116 ~108 dirt
setblock ~32 ~116 ~109 dirt
setblock ~32 ~116 ~110 dirt
setblock ~32 ~116 ~111 dirt
setblock ~32 ~116 ~112 dirt
setblock ~32 ~116 ~113 dirt
setblock ~32 ~116 ~114 dirt
setblock ~32 ~116 ~115 dirt
setblock ~32 ~116 ~116 dirt
setblock ~32 ~116 ~117 dirt
setblock ~32 ~116 ~118 dirt
setblock ~32 ~117 ~73 dirt
setblock ~32 ~117 ~74 dirt
setblock ~32 ~117 ~75 dirt
setblock ~32 ~117 ~76 dirt
setblock ~32 ~117 ~77 dirt
setblock ~32 ~117 ~78 dirt
setblock ~32 ~117 ~79 dirt
setblock ~32 ~117 ~80 dirt
setblock ~32 ~117 ~81 dirt
setblock ~32 ~117 ~82 dirt
setblock ~32 ~117 ~83 dirt
setblock ~32 ~117 ~84 dirt
setblock ~32 ~117 ~85 dirt
setblock ~32 ~117 ~86 dirt
setblock ~32 ~117 ~87 dirt
setblock ~32 ~117 ~88 dirt
setblock ~32 ~117 ~89 dirt
setblock ~32 ~117 ~90 dirt
setblock ~32 ~117 ~91 dirt
setblock ~32 ~117 ~92 dirt
setblock ~32 ~117 ~93 dirt
setblock ~32 ~117 ~94 dirt
setblock ~32 ~117 ~95 dirt
setblock ~32 ~117 ~96 dirt
setblock ~32 ~117 ~97 dirt
setblock ~32 ~117 ~98 dirt
setblock ~32 ~117 ~99 dirt
setblock ~32 ~117 ~100 dirt
setblock ~32 ~117 ~101 dirt
setblock ~32 ~117 ~102 dirt
setblock ~32 ~117 ~103 dirt
setblock ~32 ~117 ~104 dirt
setblock ~32 ~117 ~105 dirt
setblock ~32 ~117 ~106 dirt
setblock ~32 ~117 ~107 dirt
setblock ~32 ~117 ~108 dirt
setblock ~32 ~117 ~109 dirt
setblock ~32 ~117 ~110 dirt
setblock ~32 ~117 ~111 dirt
setblock ~32 ~117 ~112 dirt
setblock ~32 ~117 ~113 dirt
setblock ~32 ~117 ~114 dirt
setblock ~32 ~117 ~115 dirt
setblock ~32 ~117 ~116 dirt
setblock ~32 ~117 ~117 dirt
setblock ~32 ~117 ~118 dirt
setblock ~32 ~118 ~73 dirt
setblock ~32 ~118 ~74 dirt
setblock ~32 ~118 ~75 dirt
setblock ~32 ~118 ~76 dirt
setblock ~32 ~118 ~77 dirt
setblock ~32 ~118 ~78 dirt
setblock ~32 ~118 ~79 dirt
setblock ~32 ~118 ~80 dirt
setblock ~32 ~118 ~81 dirt
setblock ~32 ~118 ~82 dirt
setblock ~32 ~118 ~83 dirt
setblock ~32 ~118 ~84 dirt
setblock ~32 ~118 ~85 dirt
setblock ~32 ~118 ~86 dirt
setblock ~32 ~118 ~87 dirt
setblock ~32 ~118 ~88 dirt
setblock ~32 ~118 ~89 dirt
setblock ~32 ~118 ~90 dirt
setblock ~32 ~118 ~91 dirt
setblock ~32 ~118 ~92 dirt
setblock ~32 ~118 ~93 dirt
setblock ~32 ~118 ~94 dirt
setblock ~32 ~118 ~95 dirt
setblock ~32 ~118 ~96 dirt
setblock ~32 ~118 ~97 dirt
setblock ~32 ~118 ~98 dirt
setblock ~32 ~118 ~99 dirt
setblock ~32 ~118 ~100 dirt
setblock ~32 ~118 ~101 dirt
setblock ~32 ~118 ~102 dirt
setblock ~32 ~118 ~103 dirt
setblock ~32 ~118 ~104 dirt
setblock ~32 ~118 ~105 dirt
setblock ~32 ~118 ~106 dirt
setblock ~32 ~118 ~107 dirt
setblock ~32 ~118 ~108 dirt
setblock ~32 ~118 ~109 dirt
setblock ~32 ~118 ~110 dirt
setblock ~32 ~118 ~111 dirt
setblock ~32 ~118 ~112 dirt
setblock ~32 ~118 ~113 dirt
setblock ~32 ~118 ~114 dirt
setblock ~32 ~118 ~115 dirt
setblock ~32 ~118 ~116 dirt
setblock ~32 ~118 ~117 dirt
setblock ~32 ~118 ~118 dirt
setblock ~32 ~118 ~119 dirt
setblock ~32 ~119 ~72 dirt
setblock ~32 ~119 ~73 dirt
setblock ~32 ~119 ~74 dirt
setblock ~32 ~119 ~75 dirt
setblock ~32 ~119 ~76 dirt
setblock ~32 ~119 ~77 dirt
setblock ~32 ~119 ~78 dirt
setblock ~32 ~119 ~79 dirt
setblock ~32 ~119 ~80 dirt
setblock ~32 ~119 ~81 dirt
setblock ~32 ~119 ~82 dirt
setblock ~32 ~119 ~83 dirt
setblock ~32 ~119 ~84 dirt
setblock ~32 ~119 ~85 dirt
setblock ~32 ~119 ~86 dirt
setblock ~32 ~119 ~87 dirt
setblock ~32 ~119 ~88 dirt
setblock ~32 ~119 ~89 dirt
setblock ~32 ~119 ~90 dirt
setblock ~32 ~119 ~91 dirt
setblock ~32 ~119 ~92 dirt
setblock ~32 ~119 ~93 dirt
setblock ~32 ~119 ~94 dirt
setblock ~32 ~119 ~95 dirt
setblock ~32 ~119 ~96 dirt
setblock ~32 ~119 ~97 dirt
setblock ~32 ~119 ~98 dirt
setblock ~32 ~119 ~99 dirt
setblock ~32 ~119 ~100 dirt
setblock ~32 ~119 ~101 dirt
setblock ~32 ~119 ~102 dirt
setblock ~32 ~119 ~103 dirt
setblock ~32 ~119 ~104 dirt
setblock ~32 ~119 ~105 dirt
setblock ~32 ~119 ~106 dirt
setblock ~32 ~119 ~107 dirt
setblock ~32 ~119 ~108 dirt
setblock ~32 ~119 ~109 dirt
setblock ~32 ~119 ~110 dirt
setblock ~32 ~119 ~111 dirt
setblock ~32 ~119 ~112 dirt
setblock ~32 ~119 ~113 dirt
setblock ~32 ~119 ~114 dirt
setblock ~32 ~119 ~115 dirt
setblock ~32 ~119 ~116 dirt
setblock ~32 ~119 ~117 dirt
setblock ~32 ~119 ~118 dirt
setblock ~32 ~119 ~119 dirt
setblock ~32 ~120 ~71 dirt
setblock ~32 ~120 ~72 dirt
setblock ~32 ~120 ~73 dirt
setblock ~32 ~120 ~74 dirt
setblock ~32 ~120 ~75 dirt
setblock ~32 ~120 ~76 dirt
setblock ~32 ~120 ~77 dirt
setblock ~32 ~120 ~78 dirt
setblock ~32 ~120 ~79 dirt
setblock ~32 ~120 ~80 dirt
setblock ~32 ~120 ~81 dirt
setblock ~32 ~120 ~82 dirt
setblock ~32 ~120 ~83 dirt
setblock ~32 ~120 ~84 dirt
setblock ~32 ~120 ~85 dirt
setblock ~32 ~120 ~86 dirt
setblock ~32 ~120 ~87 dirt
setblock ~32 ~120 ~88 dirt
setblock ~32 ~120 ~89 dirt
setblock ~32 ~120 ~90 dirt
setblock ~32 ~120 ~91 dirt
setblock ~32 ~120 ~92 dirt
setblock ~32 ~120 ~93 dirt
setblock ~32 ~120 ~94 dirt
setblock ~32 ~120 ~95 dirt
setblock ~32 ~120 ~96 dirt
setblock ~32 ~120 ~97 dirt
setblock ~32 ~120 ~98 dirt
setblock ~32 ~120 ~99 dirt
setblock ~32 ~120 ~100 dirt
setblock ~32 ~120 ~101 dirt
setblock ~32 ~120 ~102 dirt
setblock ~32 ~120 ~103 dirt
setblock ~32 ~120 ~104 dirt
setblock ~32 ~120 ~105 dirt
setblock ~32 ~120 ~106 dirt
setblock ~32 ~120 ~107 dirt
setblock ~32 ~120 ~108 dirt
setblock ~32 ~120 ~109 dirt
setblock ~32 ~120 ~110 dirt
setblock ~32 ~120 ~111 dirt
setblock ~32 ~120 ~112 dirt
setblock ~32 ~120 ~113 dirt
setblock ~32 ~120 ~114 dirt
setblock ~32 ~120 ~115 dirt
setblock ~32 ~120 ~116 dirt
setblock ~32 ~120 ~117 dirt
setblock ~32 ~120 ~118 dirt
setblock ~32 ~120 ~119 dirt
setblock ~32 ~120 ~120 dirt
setblock ~32 ~121 ~71 dirt
setblock ~32 ~121 ~72 dirt
setblock ~32 ~121 ~73 dirt
setblock ~32 ~121 ~74 dirt
setblock ~32 ~121 ~75 dirt
setblock ~32 ~121 ~76 dirt
setblock ~32 ~121 ~77 dirt
setblock ~32 ~121 ~78 dirt
setblock ~32 ~121 ~79 dirt
setblock ~32 ~121 ~80 dirt
setblock ~32 ~121 ~81 dirt
setblock ~32 ~121 ~82 dirt
setblock ~32 ~121 ~83 dirt
setblock ~32 ~121 ~84 dirt
setblock ~32 ~121 ~85 dirt
setblock ~32 ~121 ~86 dirt
setblock ~32 ~121 ~87 dirt
setblock ~32 ~121 ~88 dirt
setblock ~32 ~121 ~89 dirt
setblock ~32 ~121 ~90 dirt
setblock ~32 ~121 ~91 dirt
setblock ~32 ~121 ~92 dirt
setblock ~32 ~121 ~93 dirt
setblock ~32 ~121 ~94 dirt
setblock ~32 ~121 ~95 dirt
setblock ~32 ~121 ~96 dirt
setblock ~32 ~121 ~97 dirt
setblock ~32 ~121 ~98 dirt
setblock ~32 ~121 ~99 dirt
setblock ~32 ~121 ~100 dirt
setblock ~32 ~121 ~101 dirt
setblock ~32 ~121 ~102 dirt
setblock ~32 ~121 ~103 dirt
setblock ~32 ~121 ~104 dirt
setblock ~32 ~121 ~105 dirt
setblock ~32 ~121 ~106 dirt
setblock ~32 ~121 ~107 dirt
setblock ~32 ~121 ~108 dirt
setblock ~32 ~121 ~109 dirt
setblock ~32 ~121 ~110 dirt
setblock ~32 ~121 ~111 dirt
setblock ~32 ~121 ~112 dirt
setblock ~32 ~121 ~113 dirt
setblock ~32 ~121 ~114 dirt
setblock ~32 ~121 ~115 dirt
setblock ~32 ~121 ~116 dirt
setblock ~32 ~121 ~117 dirt
setblock ~32 ~121 ~118 dirt
setblock ~32 ~121 ~119 dirt
setblock ~32 ~121 ~120 dirt
setblock ~32 ~122 ~71 dirt
setblock ~32 ~122 ~72 dirt
setblock ~32 ~122 ~73 dirt
setblock ~32 ~122 ~74 dirt
setblock ~32 ~122 ~75 dirt
setblock ~32 ~122 ~76 dirt
setblock ~32 ~122 ~77 dirt
setblock ~32 ~122 ~78 dirt
setblock ~32 ~122 ~79 dirt
setblock ~32 ~122 ~80 dirt
setblock ~32 ~122 ~81 dirt
setblock ~32 ~122 ~82 dirt
setblock ~32 ~122 ~83 dirt
setblock ~32 ~122 ~84 dirt
setblock ~32 ~122 ~85 dirt
setblock ~32 ~122 ~86 dirt
setblock ~32 ~122 ~87 dirt
setblock ~32 ~122 ~88 dirt
setblock ~32 ~122 ~89 dirt
setblock ~32 ~122 ~90 dirt
setblock ~32 ~122 ~91 dirt
setblock ~32 ~122 ~92 dirt
setblock ~32 ~122 ~93 dirt
setblock ~32 ~122 ~94 dirt
setblock ~32 ~122 ~95 dirt
setblock ~32 ~122 ~96 dirt
setblock ~32 ~122 ~97 dirt
setblock ~32 ~122 ~98 dirt
setblock ~32 ~122 ~99 dirt
setblock ~32 ~122 ~100 dirt
setblock ~32 ~122 ~101 dirt
setblock ~32 ~122 ~102 dirt
setblock ~32 ~122 ~103 dirt
setblock ~32 ~122 ~104 dirt
setblock ~32 ~122 ~105 dirt
setblock ~32 ~122 ~106 dirt
setblock ~32 ~122 ~107 dirt
setblock ~32 ~122 ~108 dirt
setblock ~32 ~122 ~109 dirt
setblock ~32 ~122 ~110 dirt
setblock ~32 ~122 ~111 dirt
setblock ~32 ~122 ~112 dirt
setblock ~32 ~122 ~113 dirt
setblock ~32 ~122 ~114 dirt
setblock ~32 ~122 ~115 dirt
setblock ~32 ~122 ~116 dirt
setblock ~32 ~122 ~117 dirt
setblock ~32 ~122 ~118 dirt
setblock ~32 ~122 ~119 dirt
setblock ~32 ~122 ~120 dirt
setblock ~32 ~123 ~71 dirt
setblock ~32 ~123 ~72 dirt
setblock ~32 ~123 ~73 dirt
setblock ~32 ~123 ~74 dirt
setblock ~32 ~123 ~75 dirt
setblock ~32 ~123 ~76 dirt
setblock ~32 ~123 ~77 dirt
setblock ~32 ~123 ~78 dirt
setblock ~32 ~123 ~79 dirt
setblock ~32 ~123 ~80 dirt
setblock ~32 ~123 ~81 dirt
setblock ~32 ~123 ~82 dirt
setblock ~32 ~123 ~83 dirt
setblock ~32 ~123 ~84 dirt
setblock ~32 ~123 ~85 dirt
setblock ~32 ~123 ~86 dirt
setblock ~32 ~123 ~87 dirt
setblock ~32 ~123 ~88 dirt
setblock ~32 ~123 ~89 dirt
setblock ~32 ~123 ~90 dirt
setblock ~32 ~123 ~91 dirt
setblock ~32 ~123 ~92 dirt
setblock ~32 ~123 ~93 dirt
setblock ~32 ~123 ~94 dirt
setblock ~32 ~123 ~95 dirt
setblock ~32 ~123 ~96 dirt
setblock ~32 ~123 ~97 dirt
setblock ~32 ~123 ~98 dirt
setblock ~32 ~123 ~99 dirt
setblock ~32 ~123 ~100 grass_block
setblock ~32 ~123 ~101 dirt
setblock ~32 ~123 ~102 dirt
setblock ~32 ~123 ~103 dirt
setblock ~32 ~123 ~104 dirt
setblock ~32 ~123 ~105 dirt
setblock ~32 ~123 ~106 dirt
setblock ~32 ~123 ~107 dirt
setblock ~32 ~123 ~108 dirt
setblock ~32 ~123 ~109 dirt
setblock ~32 ~123 ~110 dirt
setblock ~32 ~123 ~111 dirt
setblock ~32 ~123 ~112 dirt
setblock ~32 ~123 ~113 dirt
setblock ~32 ~123 ~114 dirt
setblock ~32 ~123 ~115 dirt
setblock ~32 ~123 ~116 dirt
setblock ~32 ~123 ~117 dirt
setblock ~32 ~123 ~118 grass_block
setblock ~32 ~123 ~119 grass_block
setblock ~32 ~123 ~120 grass_block
setblock ~32 ~124 ~71 dirt
setblock ~32 ~124 ~72 dirt
setblock ~32 ~124 ~73 dirt
setblock ~32 ~124 ~74 dirt
setblock ~32 ~124 ~75 dirt
setblock ~32 ~124 ~76 dirt
setblock ~32 ~124 ~77 dirt
setblock ~32 ~124 ~78 dirt
setblock ~32 ~124 ~79 dirt
setblock ~32 ~124 ~80 dirt
setblock ~32 ~124 ~81 dirt
setblock ~32 ~124 ~82 dirt
setblock ~32 ~124 ~83 dirt
setblock ~32 ~124 ~84 dirt
setblock ~32 ~124 ~85 dirt
setblock ~32 ~124 ~86 dirt
setblock ~32 ~124 ~87 dirt
setblock ~32 ~124 ~88 dirt
setblock ~32 ~124 ~89 dirt
setblock ~32 ~124 ~90 grass_block
setblock ~32 ~124 ~91 dirt
setblock ~32 ~124 ~92 dirt
setblock ~32 ~124 ~93 dirt
setblock ~32 ~124 ~94 dirt
setblock ~32 ~124 ~95 dirt
setblock ~32 ~124 ~96 dirt
setblock ~32 ~124 ~97 grass_block
setblock ~32 ~124 ~98 grass_block
setblock ~32 ~124 ~99 grass_block
setblock ~32 ~124 ~101 grass_block
setblock ~32 ~124 ~102 grass_block
setblock ~32 ~124 ~103 dirt
setblock ~32 ~124 ~104 dirt
setblock ~32 ~124 ~105 dirt
setblock ~32 ~124 ~106 dirt
setblock ~32 ~124 ~107 dirt
setblock ~32 ~124 ~108 dirt
setblock ~32 ~124 ~109 dirt
setblock ~32 ~124 ~110 dirt
setblock ~32 ~124 ~111 dirt
setblock ~32 ~124 ~112 dirt
setblock ~32 ~124 ~113 dirt
setblock ~32 ~124 ~114 dirt
setblock ~32 ~124 ~115 grass_block
setblock ~32 ~124 ~116 grass_block
setblock ~32 ~124 ~117 grass_block
setblock ~32 ~124 ~120 short_grass
setblock ~32 ~125 ~71 dirt
setblock ~32 ~125 ~72 dirt
setblock ~32 ~125 ~73 dirt
setblock ~32 ~125 ~74 dirt
setblock ~32 ~125 ~75 dirt
setblock ~32 ~125 ~76 dirt
setblock ~32 ~125 ~77 dirt
setblock ~32 ~125 ~78 dirt
setblock ~32 ~125 ~79 dirt
setblock ~32 ~125 ~80 dirt
setblock ~32 ~125 ~81 dirt
setblock ~32 ~125 ~82 dirt
setblock ~32 ~125 ~83 dirt
setblock ~32 ~125 ~84 dirt
setblock ~32 ~125 ~85 dirt
setblock ~32 ~125 ~86 grass_block
setblock ~32 ~125 ~87 grass_block
setblock ~32 ~125 ~88 grass_block
setblock ~32 ~125 ~89 grass_block
setblock ~32 ~125 ~90 short_grass
setblock ~32 ~125 ~91 grass_block
setblock ~32 ~125 ~92 grass_block
setblock ~32 ~125 ~93 grass_block
setblock ~32 ~125 ~94 grass_block
setblock ~32 ~125 ~95 grass_block
setblock ~32 ~125 ~96 grass_block
setblock ~32 ~125 ~97 short_grass
setblock ~32 ~125 ~99 poppy
setblock ~32 ~125 ~101 short_grass
setblock ~32 ~125 ~103 grass_block
setblock ~32 ~125 ~104 grass_block
setblock ~32 ~125 ~105 dirt
setblock ~32 ~125 ~106 dirt
setblock ~32 ~125 ~107 dirt
setblock ~32 ~125 ~108 dirt
setblock ~32 ~125 ~109 dirt
setblock ~32 ~125 ~110 dirt
setblock ~32 ~125 ~111 dirt
setblock ~32 ~125 ~112 dirt
setblock ~32 ~125 ~113 grass_block
setblock ~32 ~125 ~114 grass_block
setblock ~32 ~126 ~71 dirt
setblock ~32 ~126 ~72 dirt
setblock ~32 ~126 ~73 dirt
setblock ~32 ~126 ~74 dirt
setblock ~32 ~126 ~75 dirt
setblock ~32 ~126 ~76 dirt
setblock ~32 ~126 ~77 dirt
setblock ~32 ~126 ~78 dirt
setblock ~32 ~126 ~79 dirt
setblock ~32 ~126 ~80 dirt
setblock ~32 ~126 ~81 dirt
setblock ~32 ~126 ~82 dirt
setblock ~32 ~126 ~83 grass_block
setblock ~32 ~126 ~84 grass_block
setblock ~32 ~126 ~85 grass_block
setblock ~32 ~126 ~87 fern
setblock ~32 ~126 ~91 short_grass
setblock ~32 ~126 ~94 short_grass
setblock ~32 ~126 ~96 short_grass
setblock ~32 ~126 ~105 grass_block
setblock ~32 ~126 ~106 grass_block
setblock ~32 ~126 ~107 dirt
setblock ~32 ~126 ~108 dirt
setblock ~32 ~126 ~109 dirt
setblock ~32 ~126 ~110 dirt
setblock ~32 ~126 ~111 dirt
setblock ~32 ~126 ~112 grass_block
setblock ~32 ~126 ~114 short_grass
setblock ~32 ~127 ~71 grass_block
setblock ~32 ~127 ~72 grass_block
setblock ~32 ~127 ~73 grass_block
setblock ~32 ~127 ~74 grass_block
setblock ~32 ~127 ~75 grass_block
setblock ~32 ~127 ~76 grass_block
setblock ~32 ~127 ~77 grass_block
setblock ~32 ~127 ~78 grass_block
setblock ~32 ~127 ~79 grass_block
setblock ~32 ~127 ~80 grass_block
setblock ~32 ~127 ~81 grass_block
setblock ~32 ~127 ~82 grass_block
setblock ~32 ~127 ~83 short_grass
setblock ~32 ~127 ~105 short_grass
setblock ~32 ~127 ~107 grass_block
setblock ~32 ~127 ~108 grass_block
setblock ~32 ~127 ~109 dirt
setblock ~32 ~127 ~110 dirt
setblock ~32 ~127 ~111 grass_block
setblock ~32 ~127 ~112 short_grass
setblock ~32 ~128 ~75 short_grass
setblock ~32 ~128 ~76 short_grass
setblock ~32 ~128 ~78 poppy
setblock ~32 ~128 ~109 grass_block
setblock ~32 ~128 ~110 grass_block
setblock ~33 ~105 ~106 dirt
setblock ~33 ~106 ~105 dirt
setblock ~33 ~106 ~106 dirt
setblock ~33 ~106 ~112 dirt
setblock ~33 ~107 ~103 dirt
setblock ~33 ~107 ~105 dirt
setblock ~33 ~107 ~106 dirt
setblock ~33 ~107 ~108 dirt
setblock ~33 ~107 ~109 dirt
setblock ~33 ~107 ~110 dirt
setblock ~33 ~107 ~111 dirt
setblock ~33 ~107 ~112 dirt
setblock ~33 ~107 ~114 dirt
setblock ~33 ~108 ~100 dirt
setblock ~33 ~108 ~101 dirt
setblock ~33 ~108 ~102 dirt
setblock ~33 ~108 ~103 dirt
setblock ~33 ~108 ~104 dirt
setblock ~33 ~108 ~105 dirt
setblock ~33 ~108 ~106 dirt
setblock ~33 ~108 ~107 dirt
setblock ~33 ~108 ~108 dirt
setblock ~33 ~108 ~109 dirt
setblock ~33 ~108 ~110 dirt
setblock ~33 ~108 ~111 dirt
setblock ~33 ~108 ~112 dirt
setblock ~33 ~108 ~113 dirt
setblock ~33 ~108 ~114 dirt
setblock ~33 ~109 ~77 dirt
setblock ~33 ~109 ~99 dirt
setblock ~33 ~109 ~100 dirt
setblock ~33 ~109 ~101 dirt
setblock ~33 ~109 ~102 dirt
setblock ~33 ~109 ~103 dirt
setblock ~33 ~109 ~104 dirt
setblock ~33 ~109 ~105 dirt
setblock ~33 ~109 ~106 dirt
setblock ~33 ~109 ~107 dirt
setblock ~33 ~109 ~108 dirt
setblock ~33 ~109 ~109 dirt
setblock ~33 ~109 ~110 dirt
setblock ~33 ~109 ~111 dirt
setblock ~33 ~109 ~112 dirt
setblock ~33 ~109 ~113 dirt
setblock ~33 ~109 ~114 dirt
setblock ~33 ~109 ~116 dirt
setblock ~33 ~110 ~77 dirt
setblock ~33 ~110 ~94 dirt
setblock ~33 ~110 ~95 dirt
setblock ~33 ~110 ~99 dirt
setblock ~33 ~110 ~100 dirt
setblock ~33 ~110 ~101 dirt
setblock ~33 ~110 ~102 dirt
setblock ~33 ~110 ~103 dirt
setblock ~33 ~110 ~104 dirt
setblock ~33 ~110 ~105 dirt
setblock ~33 ~110 ~106 dirt
setblock ~33 ~110 ~107 dirt
setblock ~33 ~110 ~108 dirt
setblock ~33 ~110 ~109 dirt
setblock ~33 ~110 ~110 dirt
setblock ~33 ~110 ~111 dirt
setblock ~33 ~110 ~112 dirt
setblock ~33 ~110 ~113 dirt
setblock ~33 ~110 ~114 dirt
setblock ~33 ~110 ~115 dirt
setblock ~33 ~110 ~116 dirt
setblock ~33 ~111 ~77 dirt
setblock ~33 ~111 ~78 dirt
setblock ~33 ~111 ~82 dirt
setblock ~33 ~111 ~94 dirt
setblock ~33 ~111 ~95 dirt
setblock ~33 ~111 ~96 dirt
setblock ~33 ~111 ~98 dirt
setblock ~33 ~111 ~99 dirt
setblock ~33 ~111 ~100 dirt
setblock ~33 ~111 ~101 dirt
setblock ~33 ~111 ~102 dirt
setblock ~33 ~111 ~103 dirt
setblock ~33 ~111 ~104 dirt
setblock ~33 ~111 ~105 dirt
setblock ~33 ~111 ~106 dirt
setblock ~33 ~111 ~107 dirt
setblock ~33 ~111 ~108 dirt
setblock ~33 ~111 ~109 dirt
setblock ~33 ~111 ~110 dirt
setblock ~33 ~111 ~111 dirt
setblock ~33 ~111 ~112 dirt
setblock ~33 ~111 ~113 dirt
setblock ~33 ~111 ~114 dirt
setblock ~33 ~111 ~115 dirt
setblock ~33 ~111 ~116 dirt
setblock ~33 ~112 ~76 dirt
setblock ~33 ~112 ~77 dirt
setblock ~33 ~112 ~78 dirt
setblock ~33 ~112 ~80 dirt
setblock ~33 ~112 ~81 dirt
setblock ~33 ~112 ~82 dirt
setblock ~33 ~112 ~93 dirt
setblock ~33 ~112 ~94 dirt
setblock ~33 ~112 ~95 dirt
setblock ~33 ~112 ~96 dirt
setblock ~33 ~112 ~97 dirt
setblock ~33 ~112 ~98 dirt
setblock ~33 ~112 ~99 dirt
setblock ~33 ~112 ~100 dirt
setblock ~33 ~112 ~101 dirt
setblock ~33 ~112 ~102 dirt
setblock ~33 ~112 ~103 dirt
setblock ~33 ~112 ~104 dirt
setblock ~33 ~112 ~105 dirt
setblock ~33 ~112 ~106 dirt
setblock ~33 ~112 ~107 dirt
setblock ~33 ~112 ~108 dirt
setblock ~33 ~112 ~109 dirt
setblock ~33 ~112 ~110 dirt
setblock ~33 ~112 ~111 dirt
setblock ~33 ~112 ~112 dirt
setblock ~33 ~112 ~113 dirt
setblock ~33 ~112 ~114 dirt
setblock ~33 ~112 ~115 dirt
setblock ~33 ~112 ~116 dirt
setblock ~33 ~112 ~117 dirt
setblock ~33 ~113 ~75 dirt
setblock ~33 ~113 ~76 dirt
setblock ~33 ~113 ~77 dirt
setblock ~33 ~113 ~78 dirt
setblock ~33 ~113 ~79 dirt
setblock ~33 ~113 ~80 dirt
setblock ~33 ~113 ~81 dirt
setblock ~33 ~113 ~82 dirt
setblock ~33 ~113 ~84 dirt
setblock ~33 ~113 ~86 dirt
setblock ~33 ~113 ~89 dirt
setblock ~33 ~113 ~90 dirt
setblock ~33 ~113 ~91 dirt
setblock ~33 ~113 ~92 dirt
setblock ~33 ~113 ~93 dirt
setblock ~33 ~113 ~94 dirt
setblock ~33 ~113 ~95 dirt
setblock ~33 ~113 ~96 dirt
setblock ~33 ~113 ~97 dirt
setblock ~33 ~113 ~98 dirt
setblock ~33 ~113 ~99 dirt
setblock ~33 ~113 ~100 dirt
setblock ~33 ~113 ~101 dirt
setblock ~33 ~113 ~102 dirt
setblock ~33 ~113 ~103 dirt
setblock ~33 ~113 ~104 dirt
setblock ~33 ~113 ~105 dirt
setblock ~33 ~113 ~106 dirt
setblock ~33 ~113 ~107 dirt
setblock ~33 ~113 ~108 dirt
setblock ~33 ~113 ~109 dirt
setblock ~33 ~113 ~110 dirt
setblock ~33 ~113 ~111 dirt
setblock ~33 ~113 ~112 dirt
setblock ~33 ~113 ~113 dirt
setblock ~33 ~113 ~114 dirt
setblock ~33 ~113 ~115 dirt
setblock ~33 ~113 ~116 dirt
setblock ~33 ~113 ~117 dirt
setblock ~33 ~114 ~75 dirt
setblock ~33 ~114 ~76 dirt
setblock ~33 ~114 ~77 dirt
setblock ~33 ~114 ~78 dirt
setblock ~33 ~114 ~79 dirt
setblock ~33 ~114 ~80 dirt
setblock ~33 ~114 ~81 dirt
setblock ~33 ~114 ~82 dirt
setblock ~33 ~114 ~84 dirt
setblock ~33 ~114 ~85 dirt
setblock ~33 ~114 ~86 dirt
setblock ~33 ~114 ~87 dirt
setblock ~33 ~114 ~89 dirt
setblock ~33 ~114 ~90 dirt
setblock ~33 ~114 ~91 dirt
setblock ~33 ~114 ~92 dirt
setblock ~33 ~114 ~93 dirt
setblock ~33 ~114 ~94 dirt
setblock ~33 ~114 ~95 dirt
setblock ~33 ~114 ~96 dirt
setblock ~33 ~114 ~97 dirt
setblock ~33 ~114 ~98 dirt
setblock ~33 ~114 ~99 dirt
setblock ~33 ~114 ~100 dirt
setblock ~33 ~114 ~101 dirt
setblock ~33 ~114 ~102 dirt
setblock ~33 ~114 ~103 dirt
setblock ~33 ~114 ~104 dirt
setblock ~33 ~114 ~105 dirt
setblock ~33 ~114 ~106 dirt
setblock ~33 ~114 ~107 dirt
setblock ~33 ~114 ~108 dirt
setblock ~33 ~114 ~109 dirt
setblock ~33 ~114 ~110 dirt
setblock ~33 ~114 ~111 dirt
setblock ~33 ~114 ~112 dirt
setblock ~33 ~114 ~113 dirt
setblock ~33 ~114 ~114 dirt
setblock ~33 ~114 ~115 dirt
setblock ~33 ~114 ~116 dirt
setblock ~33 ~114 ~117 dirt
setblock ~33 ~115 ~74 dirt
setblock ~33 ~115 ~75 dirt
setblock ~33 ~115 ~76 dirt
setblock ~33 ~115 ~77 dirt
setblock ~33 ~115 ~78 dirt
setblock ~33 ~115 ~79 dirt
setblock ~33 ~115 ~80 dirt
setblock ~33 ~115 ~81 dirt
setblock ~33 ~115 ~82 dirt
setblock ~33 ~115 ~83 dirt
setblock ~33 ~115 ~84 dirt
setblock ~33 ~115 ~85 dirt
setblock ~33 ~115 ~86 dirt
setblock ~33 ~115 ~87 dirt
setblock ~33 ~115 ~88 dirt
setblock ~33 ~115 ~89 dirt
setblock ~33 ~115 ~90 dirt
setblock ~33 ~115 ~91 dirt
setblock ~33 ~115 ~92 dirt
setblock ~33 ~115 ~93 dirt
setblock ~33 ~115 ~94 dirt
setblock ~33 ~115 ~95 dirt
setblock ~33 ~115 ~96 dirt
setblock ~33 ~115 ~97 dirt
setblock ~33 ~115 ~98 dirt
setblock ~33 ~115 ~99 dirt
setblock ~33 ~115 ~100 dirt
setblock ~33 ~115 ~101 dirt
setblock ~33 ~115 ~102 dirt
setblock ~33 ~115 ~103 dirt
setblock ~33 ~115 ~104 dirt
setblock ~33 ~115 ~105 dirt
setblock ~33 ~115 ~106 dirt
setblock ~33 ~115 ~107 dirt
setblock ~33 ~115 ~108 dirt
setblock ~33 ~115 ~109 dirt
setblock ~33 ~115 ~110 dirt
setblock ~33 ~115 ~111 dirt
setblock ~33 ~115 ~112 dirt
setblock ~33 ~115 ~113 dirt
setblock ~33 ~115 ~114 dirt
setblock ~33 ~115 ~115 dirt
setblock ~33 ~115 ~116 dirt
setblock ~33 ~115 ~117 dirt
setblock ~33 ~115 ~118 dirt
setblock ~33 ~116 ~73 dirt
setblock ~33 ~116 ~74 dirt
setblock ~33 ~116 ~75 dirt
setblock ~33 ~116 ~76 dirt
setblock ~33 ~116 ~77 dirt
setblock ~33 ~116 ~78 dirt
setblock ~33 ~116 ~79 dirt
setblock ~33 ~116 ~80 dirt
setblock ~33 ~116 ~81 dirt
setblock ~33 ~116 ~82 dirt
setblock ~33 ~116 ~83 dirt
setblock ~33 ~116 ~84 dirt
setblock ~33 ~116 ~85 dirt
setblock ~33 ~116 ~86 dirt
setblock ~33 ~116 ~87 dirt
setblock ~33 ~116 ~88 dirt
setblock ~33 ~116 ~89 dirt
setblock ~33 ~116 ~90 dirt
setblock ~33 ~116 ~91 dirt
setblock ~33 ~116 ~92 dirt
setblock ~33 ~116 ~93 dirt
setblock ~33 ~116 ~94 dirt
setblock ~33 ~116 ~95 dirt
setblock ~33 ~116 ~96 dirt
setblock ~33 ~116 ~97 dirt
setblock ~33 ~116 ~98 dirt
setblock ~33 ~116 ~99 dirt
setblock ~33 ~116 ~100 dirt
setblock ~33 ~116 ~101 dirt
setblock ~33 ~116 ~102 dirt
setblock ~33 ~116 ~103 dirt
setblock ~33 ~116 ~104 dirt
setblock ~33 ~116 ~105 dirt
setblock ~33 ~116 ~106 dirt
setblock ~33 ~116 ~107 dirt
setblock ~33 ~116 ~108 dirt
setblock ~33 ~116 ~109 dirt
setblock ~33 ~116 ~110 dirt
setblock ~33 ~116 ~111 dirt
setblock ~33 ~116 ~112 dirt
setblock ~33 ~116 ~113 dirt
setblock ~33 ~116 ~114 dirt
setblock ~33 ~116 ~115 dirt
setblock ~33 ~116 ~116 dirt
setblock ~33 ~116 ~117 dirt
setblock ~33 ~116 ~118 dirt
setblock ~33 ~116 ~119 dirt
setblock ~33 ~117 ~73 dirt
setblock ~33 ~117 ~74 dirt
setblock ~33 ~117 ~75 dirt
setblock ~33 ~117 ~76 dirt
setblock ~33 ~117 ~77 dirt
setblock ~33 ~117 ~78 dirt
setblock ~33 ~117 ~79 dirt
setblock ~33 ~117 ~80 dirt
setblock ~33 ~117 ~81 dirt
setblock ~33 ~117 ~82 dirt
setblock ~33 ~117 ~83 dirt
setblock ~33 ~117 ~84 dirt
setblock ~33 ~117 ~85 dirt
setblock ~33 ~117 ~86 dirt
setblock ~33 ~117 ~87 dirt
setblock ~33 ~117 ~88 dirt
setblock ~33 ~117 ~89 dirt
setblock ~33 ~117 ~90 dirt
setblock ~33 ~117 ~91 dirt
setblock ~33 ~117 ~92 dirt
setblock ~33 ~117 ~93 dirt
setblock ~33 ~117 ~94 dirt
setblock ~33 ~117 ~95 dirt
setblock ~33 ~117 ~96 dirt
setblock ~33 ~117 ~97 dirt
setblock ~33 ~117 ~98 dirt
setblock ~33 ~117 ~99 dirt
setblock ~33 ~117 ~100 dirt
setblock ~33 ~117 ~101 dirt
setblock ~33 ~117 ~102 dirt
setblock ~33 ~117 ~103 dirt
setblock ~33 ~117 ~104 dirt
setblock ~33 ~117 ~105 dirt
setblock ~33 ~117 ~106 dirt
setblock ~33 ~117 ~107 dirt
setblock ~33 ~117 ~108 dirt
setblock ~33 ~117 ~109 dirt
setblock ~33 ~117 ~110 dirt
setblock ~33 ~117 ~111 dirt
setblock ~33 ~117 ~112 dirt
setblock ~33 ~117 ~113 dirt
setblock ~33 ~117 ~114 dirt
setblock ~33 ~117 ~115 dirt
setblock ~33 ~117 ~116 dirt
setblock ~33 ~117 ~117 dirt
setblock ~33 ~117 ~118 dirt
setblock ~33 ~117 ~119 dirt
setblock ~33 ~118 ~72 dirt
setblock ~33 ~118 ~73 dirt
setblock ~33 ~118 ~74 dirt
setblock ~33 ~118 ~75 dirt
setblock ~33 ~118 ~76 dirt
setblock ~33 ~118 ~77 dirt
setblock ~33 ~118 ~78 dirt
setblock ~33 ~118 ~79 dirt
setblock ~33 ~118 ~80 dirt
setblock ~33 ~118 ~81 dirt
setblock ~33 ~118 ~82 dirt
setblock ~33 ~118 ~83 dirt
setblock ~33 ~118 ~84 dirt
setblock ~33 ~118 ~85 dirt
setblock ~33 ~118 ~86 dirt
setblock ~33 ~118 ~87 dirt
setblock ~33 ~118 ~88 dirt
setblock ~33 ~118 ~89 dirt
setblock ~33 ~118 ~90 dirt
setblock ~33 ~118 ~91 dirt
setblock ~33 ~118 ~92 dirt
setblock ~33 ~118 ~93 dirt
setblock ~33 ~118 ~94 dirt
setblock ~33 ~118 ~95 dirt
setblock ~33 ~118 ~96 dirt
setblock ~33 ~118 ~97 dirt
setblock ~33 ~118 ~98 dirt
setblock ~33 ~118 ~99 dirt
setblock ~33 ~118 ~100 dirt
setblock ~33 ~118 ~101 dirt
setblock ~33 ~118 ~102 dirt
setblock ~33 ~118 ~103 dirt
setblock ~33 ~118 ~104 dirt
setblock ~33 ~118 ~105 dirt
setblock ~33 ~118 ~106 dirt
setblock ~33 ~118 ~107 dirt
setblock ~33 ~118 ~108 dirt
setblock ~33 ~118 ~109 dirt
setblock ~33 ~118 ~110 dirt
setblock ~33 ~118 ~111 dirt
setblock ~33 ~118 ~112 dirt
setblock ~33 ~118 ~113 dirt
setblock ~33 ~118 ~114 dirt
setblock ~33 ~118 ~115 dirt
setblock ~33 ~118 ~116 dirt
setblock ~33 ~118 ~117 dirt
setblock ~33 ~118 ~118 dirt
setblock ~33 ~118 ~119 dirt
setblock ~33 ~118 ~120 dirt
setblock ~33 ~119 ~71 dirt
setblock ~33 ~119 ~72 dirt
setblock ~33 ~119 ~73 dirt
setblock ~33 ~119 ~74 dirt
setblock ~33 ~119 ~75 dirt
setblock ~33 ~119 ~76 dirt
setblock ~33 ~119 ~77 dirt
setblock ~33 ~119 ~78 dirt
setblock ~33 ~119 ~79 dirt
setblock ~33 ~119 ~80 dirt
setblock ~33 ~119 ~81 dirt
setblock ~33 ~119 ~82 dirt
setblock ~33 ~119 ~83 dirt
setblock ~33 ~119 ~84 dirt
setblock ~33 ~119 ~85 dirt
setblock ~33 ~119 ~86 dirt
setblock ~33 ~119 ~87 dirt
setblock ~33 ~119 ~88 dirt
setblock ~33 ~119 ~89 dirt
setblock ~33 ~119 ~90 dirt
setblock ~33 ~119 ~91 dirt
setblock ~33 ~119 ~92 dirt
setblock ~33 ~119 ~93 dirt
setblock ~33 ~119 ~94 dirt
setblock ~33 ~119 ~95 dirt
setblock ~33 ~119 ~96 dirt
setblock ~33 ~119 ~97 dirt
setblock ~33 ~119 ~98 dirt
setblock ~33 ~119 ~99 dirt
setblock ~33 ~119 ~100 dirt
setblock ~33 ~119 ~101 dirt
setblock ~33 ~119 ~102 dirt
setblock ~33 ~119 ~103 dirt
setblock ~33 ~119 ~104 dirt
setblock ~33 ~119 ~105 dirt
setblock ~33 ~119 ~106 dirt
setblock ~33 ~119 ~107 dirt
setblock ~33 ~119 ~108 dirt
setblock ~33 ~119 ~109 dirt
setblock ~33 ~119 ~110 dirt
setblock ~33 ~119 ~111 dirt
setblock ~33 ~119 ~112 dirt
setblock ~33 ~119 ~113 dirt
setblock ~33 ~119 ~114 dirt
setblock ~33 ~119 ~115 dirt
setblock ~33 ~119 ~116 dirt
setblock ~33 ~119 ~117 dirt
setblock ~33 ~119 ~118 dirt
setblock ~33 ~119 ~119 dirt
setblock ~33 ~119 ~120 dirt
setblock ~33 ~120 ~70 dirt
setblock ~33 ~120 ~71 dirt
setblock ~33 ~120 ~72 dirt
setblock ~33 ~120 ~73 dirt
setblock ~33 ~120 ~74 dirt
setblock ~33 ~120 ~75 dirt
setblock ~33 ~120 ~76 dirt
setblock ~33 ~120 ~77 dirt
setblock ~33 ~120 ~78 dirt
setblock ~33 ~120 ~79 dirt
setblock ~33 ~120 ~80 dirt
setblock ~33 ~120 ~81 dirt
setblock ~33 ~120 ~82 dirt
setblock ~33 ~120 ~83 dirt
setblock ~33 ~120 ~84 dirt
setblock ~33 ~120 ~85 dirt
setblock ~33 ~120 ~86 dirt
setblock ~33 ~120 ~87 dirt
setblock ~33 ~120 ~88 dirt
setblock ~33 ~120 ~89 dirt
setblock ~33 ~120 ~90 dirt
setblock ~33 ~120 ~91 dirt
setblock ~33 ~120 ~92 dirt
setblock ~33 ~120 ~93 dirt
setblock ~33 ~120 ~94 dirt
setblock ~33 ~120 ~95 dirt
setblock ~33 ~120 ~96 dirt
setblock ~33 ~120 ~97 dirt
setblock ~33 ~120 ~98 dirt
setblock ~33 ~120 ~99 dirt
setblock ~33 ~120 ~100 dirt
setblock ~33 ~120 ~101 dirt
setblock ~33 ~120 ~102 dirt
setblock ~33 ~120 ~103 dirt
setblock ~33 ~120 ~104 dirt
setblock ~33 ~120 ~105 dirt
setblock ~33 ~120 ~106 dirt
setblock ~33 ~120 ~107 dirt
setblock ~33 ~120 ~108 dirt
setblock ~33 ~120 ~109 dirt
setblock ~33 ~120 ~110 dirt
setblock ~33 ~120 ~111 dirt
setblock ~33 ~120 ~112 dirt
setblock ~33 ~120 ~113 dirt
setblock ~33 ~120 ~114 dirt
setblock ~33 ~120 ~115 dirt
setblock ~33 ~120 ~116 dirt
setblock ~33 ~120 ~117 dirt
setblock ~33 ~120 ~118 dirt
setblock ~33 ~120 ~119 dirt
setblock ~33 ~120 ~120 dirt
setblock ~33 ~121 ~69 dirt
setblock ~33 ~121 ~70 dirt
setblock ~33 ~121 ~71 dirt
setblock ~33 ~121 ~72 dirt
setblock ~33 ~121 ~73 dirt
setblock ~33 ~121 ~74 dirt
setblock ~33 ~121 ~75 dirt
setblock ~33 ~121 ~76 dirt
setblock ~33 ~121 ~77 dirt
setblock ~33 ~121 ~78 dirt
setblock ~33 ~121 ~79 dirt
setblock ~33 ~121 ~80 dirt
setblock ~33 ~121 ~81 dirt
setblock ~33 ~121 ~82 dirt
setblock ~33 ~121 ~83 dirt
setblock ~33 ~121 ~84 dirt
setblock ~33 ~121 ~85 dirt
setblock ~33 ~121 ~86 dirt
setblock ~33 ~121 ~87 dirt
setblock ~33 ~121 ~88 dirt
setblock ~33 ~121 ~89 dirt
setblock ~33 ~121 ~90 dirt
setblock ~33 ~121 ~91 dirt
setblock ~33 ~121 ~92 dirt
setblock ~33 ~121 ~93 dirt
setblock ~33 ~121 ~94 dirt
setblock ~33 ~121 ~95 dirt
setblock ~33 ~121 ~96 dirt
setblock ~33 ~121 ~97 dirt
setblock ~33 ~121 ~98 dirt
setblock ~33 ~121 ~99 dirt
setblock ~33 ~121 ~100 dirt
setblock ~33 ~121 ~101 dirt
setblock ~33 ~121 ~102 dirt
setblock ~33 ~121 ~103 dirt
setblock ~33 ~121 ~104 dirt
setblock ~33 ~121 ~105 dirt
setblock ~33 ~121 ~106 dirt
setblock ~33 ~121 ~107 dirt
setblock ~33 ~121 ~108 dirt
setblock ~33 ~121 ~109 dirt
setblock ~33 ~121 ~110 dirt
setblock ~33 ~121 ~111 dirt
setblock ~33 ~121 ~112 dirt
setblock ~33 ~121 ~113 dirt
setblock ~33 ~121 ~114 dirt
setblock ~33 ~121 ~115 dirt
setblock ~33 ~121 ~116 dirt
setblock ~33 ~121 ~117 dirt
setblock ~33 ~121 ~118 dirt
setblock ~33 ~121 ~119 dirt
setblock ~33 ~121 ~120 dirt
setblock ~33 ~121 ~121 dirt
setblock ~33 ~122 ~69 dirt
setblock ~33 ~122 ~70 dirt
setblock ~33 ~122 ~71 dirt
setblock ~33 ~122 ~72 dirt
setblock ~33 ~122 ~73 dirt
setblock ~33 ~122 ~74 dirt
setblock ~33 ~122 ~75 dirt
setblock ~33 ~122 ~76 dirt
setblock ~33 ~122 ~77 dirt
setblock ~33 ~122 ~78 dirt
setblock ~33 ~122 ~79 dirt
setblock ~33 ~122 ~80 dirt
setblock ~33 ~122 ~81 dirt
setblock ~33 ~122 ~82 dirt
setblock ~33 ~122 ~83 dirt
setblock ~33 ~122 ~84 dirt
setblock ~33 ~122 ~85 dirt
setblock ~33 ~122 ~86 dirt
setblock ~33 ~122 ~87 dirt
setblock ~33 ~122 ~88 dirt
setblock ~33 ~122 ~89 dirt
setblock ~33 ~122 ~90 dirt
setblock ~33 ~122 ~91 dirt
setblock ~33 ~122 ~92 dirt
setblock ~33 ~122 ~93 dirt
setblock ~33 ~122 ~94 dirt
setblock ~33 ~122 ~95 dirt
setblock ~33 ~122 ~96 dirt
setblock ~33 ~122 ~97 dirt
setblock ~33 ~122 ~98 dirt
setblock ~33 ~122 ~99 dirt
setblock ~33 ~122 ~100 dirt
setblock ~33 ~122 ~101 dirt
setblock ~33 ~122 ~102 dirt
setblock ~33 ~122 ~103 dirt
setblock ~33 ~122 ~104 dirt
setblock ~33 ~122 ~105 dirt
setblock ~33 ~122 ~106 dirt
setblock ~33 ~122 ~107 dirt
setblock ~33 ~122 ~108 dirt
setblock ~33 ~122 ~109 dirt
setblock ~33 ~122 ~110 dirt
setblock ~33 ~122 ~111 dirt
setblock ~33 ~122 ~112 dirt
setblock ~33 ~122 ~113 dirt
setblock ~33 ~122 ~114 dirt
setblock ~33 ~122 ~115 dirt
setblock ~33 ~122 ~116 dirt
setblock ~33 ~122 ~117 dirt
setblock ~33 ~122 ~118 dirt
setblock ~33 ~122 ~119 dirt
setblock ~33 ~122 ~120 dirt
setblock ~33 ~122 ~121 dirt
setblock ~33 ~123 ~69 dirt
setblock ~33 ~123 ~70 dirt
setblock ~33 ~123 ~71 dirt
setblock ~33 ~123 ~72 dirt
setblock ~33 ~123 ~73 dirt
setblock ~33 ~123 ~74 dirt
setblock ~33 ~123 ~75 dirt
setblock ~33 ~123 ~76 dirt
setblock ~33 ~123 ~77 dirt
setblock ~33 ~123 ~78 dirt
setblock ~33 ~123 ~79 dirt
setblock ~33 ~123 ~80 dirt
setblock ~33 ~123 ~81 dirt
setblock ~33 ~123 ~82 dirt
setblock ~33 ~123 ~83 dirt
setblock ~33 ~123 ~84 dirt
setblock ~33 ~123 ~85 dirt
setblock ~33 ~123 ~86 dirt
setblock ~33 ~123 ~87 dirt
setblock ~33 ~123 ~88 dirt
setblock ~33 ~123 ~89 dirt
setblock ~33 ~123 ~90 dirt
setblock ~33 ~123 ~91 dirt
setblock ~33 ~123 ~92 dirt
setblock ~33 ~123 ~93 dirt
setblock ~33 ~123 ~94 dirt
setblock ~33 ~123 ~95 dirt
setblock ~33 ~123 ~96 dirt
setblock ~33 ~123 ~97 dirt
setblock ~33 ~123 ~98 dirt
setblock ~33 ~123 ~99 dirt
setblock ~33 ~123 ~100 dirt
setblock ~33 ~123 ~101 dirt
setblock ~33 ~123 ~102 dirt
setblock ~33 ~123 ~103 dirt
setblock ~33 ~123 ~104 dirt
setblock ~33 ~123 ~105 dirt
setblock ~33 ~123 ~106 dirt
setblock ~33 ~123 ~107 dirt
setblock ~33 ~123 ~108 dirt
setblock ~33 ~123 ~109 dirt
setblock ~33 ~123 ~110 dirt
setblock ~33 ~123 ~111 dirt
setblock ~33 ~123 ~112 dirt
setblock ~33 ~123 ~113 dirt
setblock ~33 ~123 ~114 dirt
setblock ~33 ~123 ~115 dirt
setblock ~33 ~123 ~116 dirt
setblock ~33 ~123 ~117 grass_block
setblock ~33 ~123 ~118 grass_block
setblock ~33 ~123 ~119 grass_block
setblock ~33 ~123 ~120 grass_block
setblock ~33 ~123 ~121 grass_block
setblock ~33 ~124 ~69 dirt
setblock ~33 ~124 ~70 dirt
setblock ~33 ~124 ~71 dirt
setblock ~33 ~124 ~72 dirt
setblock ~33 ~124 ~73 dirt
setblock ~33 ~124 ~74 dirt
setblock ~33 ~124 ~75 dirt
setblock ~33 ~124 ~76 dirt
setblock ~33 ~124 ~77 dirt
setblock ~33 ~124 ~78 dirt
setblock ~33 ~124 ~79 dirt
setblock ~33 ~124 ~80 dirt
setblock ~33 ~124 ~81 dirt
setblock ~33 ~124 ~82 dirt
setblock ~33 ~124 ~83 dirt
setblock ~33 ~124 ~84 dirt
setblock ~33 ~124 ~85 dirt
setblock ~33 ~124 ~86 dirt
setblock ~33 ~124 ~87 dirt
setblock ~33 ~124 ~88 dirt
setblock ~33 ~124 ~89 dirt
setblock ~33 ~124 ~90 dirt
setblock ~33 ~124 ~91 dirt
setblock ~33 ~124 ~92 dirt
setblock ~33 ~124 ~93 dirt
setblock ~33 ~124 ~94 dirt
setblock ~33 ~124 ~95 dirt
setblock ~33 ~124 ~96 dirt
setblock ~33 ~124 ~97 dirt
setblock ~33 ~124 ~98 dirt
setblock ~33 ~124 ~99 grass_block
setblock ~33 ~124 ~100 grass_block
setblock ~33 ~124 ~101 grass_block
setblock ~33 ~124 ~102 dirt
setblock ~33 ~124 ~103 dirt
setblock ~33 ~124 ~104 dirt
setblock ~33 ~124 ~105 dirt
setblock ~33 ~124 ~106 dirt
setblock ~33 ~124 ~107 dirt
setblock ~33 ~124 ~108 dirt
setblock ~33 ~124 ~109 dirt
setblock ~33 ~124 ~110 dirt
setblock ~33 ~124 ~111 dirt
setblock ~33 ~124 ~112 dirt
setblock ~33 ~124 ~113 dirt
setblock ~33 ~124 ~114 dirt
setblock ~33 ~124 ~115 grass_block
setblock ~33 ~124 ~116 grass_block
setblock ~33 ~124 ~118 poppy
setblock ~33 ~124 ~119 short_grass
setblock ~33 ~125 ~69 dirt
setblock ~33 ~125 ~70 dirt
setblock ~33 ~125 ~71 dirt
setblock ~33 ~125 ~72 dirt
setblock ~33 ~125 ~73 dirt
setblock ~33 ~125 ~74 dirt
setblock ~33 ~125 ~75 dirt
setblock ~33 ~125 ~76 dirt
setblock ~33 ~125 ~77 dirt
setblock ~33 ~125 ~78 dirt
setblock ~33 ~125 ~79 dirt
setblock ~33 ~125 ~80 dirt
setblock ~33 ~125 ~81 dirt
setblock ~33 ~125 ~82 dirt
setblock ~33 ~125 ~83 dirt
setblock ~33 ~125 ~84 dirt
setblock ~33 ~125 ~85 dirt
setblock ~33 ~125 ~86 dirt
setblock ~33 ~125 ~87 grass_block
setblock ~33 ~125 ~88 grass_block
setblock ~33 ~125 ~89 grass_block
setblock ~33 ~125 ~90 grass_block
setblock ~33 ~125 ~91 grass_block
setblock ~33 ~125 ~92 grass_block
setblock ~33 ~125 ~93 grass_block
setblock ~33 ~125 ~94 grass_block
setblock ~33 ~125 ~95 grass_block
setblock ~33 ~125 ~96 grass_block
setblock ~33 ~125 ~97 grass_block
setblock ~33 ~125 ~98 grass_block
setblock ~33 ~125 ~100 short_grass
setblock ~33 ~125 ~101 fern
setblock ~33 ~125 ~102 grass_block
setblock ~33 ~125 ~103 grass_block
setblock ~33 ~125 ~104 grass_block
setblock ~33 ~125 ~105 dirt
setblock ~33 ~125 ~106 dirt
setblock ~33 ~125 ~107 dirt
setblock ~33 ~125 ~108 dirt
setblock ~33 ~125 ~109 dirt
setblock ~33 ~125 ~110 dirt
setblock ~33 ~125 ~111 dirt
setblock ~33 ~125 ~112 dirt
setblock ~33 ~125 ~113 grass_block
setblock ~33 ~125 ~114 grass_block
setblock ~33 ~126 ~69 dirt
setblock ~33 ~126 ~70 dirt
setblock ~33 ~126 ~71 dirt
setblock ~33 ~126 ~72 dirt
setblock ~33 ~126 ~73 dirt
setblock ~33 ~126 ~74 dirt
setblock ~33 ~126 ~75 dirt
setblock ~33 ~126 ~76 dirt
setblock ~33 ~126 ~77 dirt
setblock ~33 ~126 ~78 dirt
setblock ~33 ~126 ~79 dirt
setblock ~33 ~126 ~80 dirt
setblock ~33 ~126 ~81 dirt
setblock ~33 ~126 ~82 dirt
setblock ~33 ~126 ~83 grass_block
setblock ~33 ~126 ~84 grass_block
setblock ~33 ~126 ~85 grass_block
setblock ~33 ~126 ~86 grass_block
setblock ~33 ~126 ~93 fern
setblock ~33 ~126 ~94 short_grass
setblock ~33 ~126 ~97 poppy
setblock ~33 ~126 ~105 grass_block
setblock ~33 ~126 ~106 grass_block
setblock ~33 ~126 ~107 grass_block
setblock ~33 ~126 ~108 dirt
setblock ~33 ~126 ~109 dirt
setblock ~33 ~126 ~110 dirt
setblock ~33 ~126 ~111 grass_block
setblock ~33 ~126 ~112 grass_block
setblock ~33 ~126 ~113 short_grass
setblock ~33 ~126 ~114 short_grass
setblock ~33 ~127 ~69 grass_block
setblock ~33 ~127 ~70 grass_block
setblock ~33 ~127 ~71 grass_block
setblock ~33 ~127 ~72 grass_block
setblock ~33 ~127 ~73 grass_block
setblock ~33 ~127 ~74 grass_block
setblock ~33 ~127 ~75 grass_block
setblock ~33 ~127 ~76 grass_block
setblock ~33 ~127 ~77 grass_block
setblock ~33 ~127 ~78 grass_block
setblock ~33 ~127 ~79 grass_block
setblock ~33 ~127 ~80 grass_block
setblock ~33 ~127 ~81 grass_block
setblock ~33 ~127 ~82 grass_block
setblock ~33 ~127 ~83 short_grass
setblock ~33 ~127 ~86 short_grass
setblock ~33 ~127 ~105 short_grass
setblock ~33 ~127 ~107 short_grass
setblock ~33 ~127 ~108 grass_block
setblock ~33 ~127 ~109 grass_block
setblock ~33 ~127 ~110 grass_block
setblock ~33 ~128 ~76 short_grass
setblock ~33 ~128 ~109 short_grass
setblock ~34 ~104 ~103 dirt
setblock ~34 ~104 ~106 dirt
setblock ~34 ~104 ~109 dirt
setblock ~34 ~105 ~101 dirt
setblock ~34 ~105 ~103 dirt
setblock ~34 ~105 ~104 dirt
setblock ~34 ~105 ~105 dirt
setblock ~34 ~105 ~106 dirt
setblock ~34 ~105 ~107 dirt
setblock ~34 ~105 ~108 dirt
setblock ~34 ~105 ~109 dirt
setblock ~34 ~105 ~110 dirt
setblock ~34 ~105 ~111 dirt
setblock ~34 ~105 ~112 dirt
setblock ~34 ~106 ~99 dirt
setblock ~34 ~106 ~100 dirt
setblock ~34 ~106 ~101 dirt
setblock ~34 ~106 ~102 dirt
setblock ~34 ~106 ~103 dirt
setblock ~34 ~106 ~104 dirt
setblock ~34 ~106 ~105 dirt
setblock ~34 ~106 ~106 dirt
setblock ~34 ~106 ~107 dirt
setblock ~34 ~106 ~108 dirt
setblock ~34 ~106 ~109 dirt
setblock ~34 ~106 ~110 dirt
setblock ~34 ~106 ~111 dirt
setblock ~34 ~106 ~112 dirt
setblock ~34 ~106 ~113 dirt
setblock ~34 ~106 ~114 dirt
setblock ~34 ~107 ~94 dirt
setblock ~34 ~107 ~96 dirt
setblock ~34 ~107 ~99 dirt
setblock ~34 ~107 ~100 dirt
setblock ~34 ~107 ~101 dirt
setblock ~34 ~107 ~102 dirt
setblock ~34 ~107 ~103 dirt
setblock ~34 ~107 ~104 dirt
setblock ~34 ~107 ~105 dirt
setblock ~34 ~107 ~106 dirt
setblock ~34 ~107 ~107 dirt
setblock ~34 ~107 ~108 dirt
setblock ~34 ~107 ~109 dirt
setblock ~34 ~107 ~110 dirt
setblock ~34 ~107 ~111 dirt
setblock ~34 ~107 ~112 dirt
setblock ~34 ~107 ~113 dirt
setblock ~34 ~107 ~114 dirt
setblock ~34 ~107 ~115 dirt
setblock ~34 ~108 ~77 dirt
setblock ~34 ~108 ~94 dirt
setblock ~34 ~108 ~96 dirt
setblock ~34 ~108 ~99 dirt
setblock ~34 ~108 ~100 dirt
setblock ~34 ~108 ~101 dirt
setblock ~34 ~108 ~102 dirt
setblock ~34 ~108 ~103 dirt
setblock ~34 ~108 ~104 dirt
setblock ~34 ~108 ~105 dirt
setblock ~34 ~108 ~106 dirt
setblock ~34 ~108 ~107 dirt
setblock ~34 ~108 ~108 dirt
setblock ~34 ~108 ~109 dirt
setblock ~34 ~108 ~110 dirt
setblock ~34 ~108 ~111 dirt
setblock ~34 ~108 ~112 dirt
setblock ~34 ~108 ~113 dirt
setblock ~34 ~108 ~114 dirt
setblock ~34 ~108 ~115 dirt
setblock ~34 ~108 ~116 dirt
setblock ~34 ~109 ~76 dirt
setblock ~34 ~109 ~77 dirt
setblock ~34 ~109 ~78 dirt
setblock ~34 ~109 ~79 dirt
setblock ~34 ~109 ~93 dirt
setblock ~34 ~109 ~94 dirt
setblock ~34 ~109 ~95 dirt
setblock ~34 ~109 ~96 dirt
setblock ~34 ~109 ~98 dirt
setblock ~34 ~109 ~99 dirt
setblock ~34 ~109 ~100 dirt
setblock ~34 ~109 ~101 dirt
setblock ~34 ~109 ~102 dirt
setblock ~34 ~109 ~103 dirt
setblock ~34 ~109 ~104 dirt
setblock ~34 ~109 ~105 dirt
setblock ~34 ~109 ~106 dirt
setblock ~34 ~109 ~107 dirt
setblock ~34 ~109 ~108 dirt
setblock ~34 ~109 ~109 dirt
setblock ~34 ~109 ~110 dirt
setblock ~34 ~109 ~111 dirt
setblock ~34 ~109 ~112 dirt
setblock ~34 ~109 ~113 dirt
setblock ~34 ~109 ~114 dirt
setblock ~34 ~109 ~115 dirt
setblock ~34 ~109 ~116 dirt
setblock ~34 ~109 ~117 dirt
setblock ~34 ~110 ~76 dirt
setblock ~34 ~110 ~77 dirt
setblock ~34 ~110 ~78 dirt
setblock ~34 ~110 ~79 dirt
setblock ~34 ~110 ~80 dirt
setblock ~34 ~110 ~81 dirt
setblock ~34 ~110 ~82 dirt
setblock ~34 ~110 ~86 dirt
setblock ~34 ~110 ~93 dirt
setblock ~34 ~110 ~94 dirt
setblock ~34 ~110 ~95 dirt
setblock ~34 ~110 ~96 dirt
setblock ~34 ~110 ~97 dirt
setblock ~34 ~110 ~98 dirt
setblock ~34 ~110 ~99 dirt
setblock ~34 ~110 ~100 dirt
setblock ~34 ~110 ~101 dirt
setblock ~34 ~110 ~102 dirt
setblock ~34 ~110 ~103 dirt
setblock ~34 ~110 ~104 dirt
setblock ~34 ~110 ~105 dirt
setblock ~34 ~110 ~106 dirt
setblock ~34 ~110 ~107 dirt
setblock ~34 ~110 ~108 dirt
setblock ~34 ~110 ~109 dirt
setblock ~34 ~110 ~110 dirt
setblock ~34 ~110 ~111 dirt
setblock ~34 ~110 ~112 dirt
setblock ~34 ~110 ~113 dirt
setblock ~34 ~110 ~114 dirt
setblock ~34 ~110 ~115 dirt
setblock ~34 ~110 ~116 dirt
setblock ~34 ~110 ~117 dirt
setblock ~34 ~111 ~76 dirt
setblock ~34 ~111 ~77 dirt
setblock ~34 ~111 ~78 dirt
setblock ~34 ~111 ~79 dirt
setblock ~34 ~111 ~80 dirt
setblock ~34 ~111 ~81 dirt
setblock ~34 ~111 ~82 dirt
setblock ~34 ~111 ~83 dirt
setblock ~34 ~111 ~84 dirt
setblock ~34 ~111 ~86 dirt
setblock ~34 ~111 ~87 dirt
setblock ~34 ~111 ~90 dirt
setblock ~34 ~111 ~92 dirt
setblock ~34 ~111 ~93 dirt
setblock ~34 ~111 ~94 dirt
setblock ~34 ~111 ~95 dirt
setblock ~34 ~111 ~96 dirt
setblock ~34 ~111 ~97 dirt
setblock ~34 ~111 ~98 dirt
setblock ~34 ~111 ~99 dirt
setblock ~34 ~111 ~100 dirt
setblock ~34 ~111 ~101 dirt
setblock ~34 ~111 ~102 dirt
setblock ~34 ~111 ~103 dirt
setblock ~34 ~111 ~104 dirt
setblock ~34 ~111 ~105 dirt
setblock ~34 ~111 ~106 dirt
setblock ~34 ~111 ~107 dirt
setblock ~34 ~111 ~108 dirt
setblock ~34 ~111 ~109 dirt
setblock ~34 ~111 ~110 dirt
setblock ~34 ~111 ~111 dirt
setblock ~34 ~111 ~112 dirt
setblock ~34 ~111 ~113 dirt
setblock ~34 ~111 ~114 dirt
setblock ~34 ~111 ~115 dirt
setblock ~34 ~111 ~116 dirt
setblock ~34 ~111 ~117 dirt
setblock ~34 ~112 ~75 dirt
setblock ~34 ~112 ~76 dirt
setblock ~34 ~112 ~77 dirt
setblock ~34 ~112 ~78 dirt
setblock ~34 ~112 ~79 dirt
setblock ~34 ~112 ~80 dirt
setblock ~34 ~112 ~81 dirt
setblock ~34 ~112 ~82 dirt
setblock ~34 ~112 ~83 dirt
setblock ~34 ~112 ~84 dirt
setblock ~34 ~112 ~85 dirt
setblock ~34 ~112 ~86 dirt
setblock ~34 ~112 ~87 dirt
setblock ~34 ~112 ~88 dirt
setblock ~34 ~112 ~89 dirt
setblock ~34 ~112 ~90 dirt
setblock ~34 ~112 ~91 dirt
setblock ~34 ~112 ~92 dirt
setblock ~34 ~112 ~93 dirt
setblock ~34 ~112 ~94 dirt
setblock ~34 ~112 ~95 dirt
setblock ~34 ~112 ~96 dirt
setblock ~34 ~112 ~97 dirt
setblock ~34 ~112 ~98 dirt
setblock ~34 ~112 ~99 dirt
setblock ~34 ~112 ~100 dirt
setblock ~34 ~112 ~101 dirt
setblock ~34 ~112 ~102 dirt
setblock ~34 ~112 ~103 dirt
setblock ~34 ~112 ~104 dirt
setblock ~34 ~112 ~105 dirt
setblock ~34 ~112 ~106 dirt
setblock ~34 ~112 ~107 dirt
setblock ~34 ~112 ~108 dirt
setblock ~34 ~112 ~109 dirt
setblock ~34 ~112 ~110 dirt
setblock ~34 ~112 ~111 dirt
setblock ~34 ~112 ~112 dirt
setblock ~34 ~112 ~113 dirt
setblock ~34 ~112 ~114 dirt
setblock ~34 ~112 ~115 dirt
setblock ~34 ~112 ~116 dirt
setblock ~34 ~112 ~117 dirt
setblock ~34 ~112 ~118 dirt
setblock ~34 ~113 ~74 dirt
setblock ~34 ~113 ~75 dirt
setblock ~34 ~113 ~76 dirt
setblock ~34 ~113 ~77 dirt
setblock ~34 ~113 ~78 dirt
setblock ~34 ~113 ~79 dirt
setblock ~34 ~113 ~80 dirt
setblock ~34 ~113 ~81 dirt
setblock ~34 ~113 ~82 dirt
setblock ~34 ~113 ~83 dirt
setblock ~34 ~113 ~84 dirt
setblock ~34 ~113 ~85 dirt
setblock ~34 ~113 ~86 dirt
setblock ~34 ~113 ~87 dirt
setblock ~34 ~113 ~88 dirt
setblock ~34 ~113 ~89 dirt
setblock ~34 ~113 ~90 dirt
setblock ~34 ~113 ~91 dirt
setblock ~34 ~113 ~92 dirt
setblock ~34 ~113 ~93 dirt
setblock ~34 ~113 ~94 dirt
setblock ~34 ~113 ~95 dirt
setblock ~34 ~113 ~96 dirt
setblock ~34 ~113 ~97 dirt
setblock ~34 ~113 ~98 dirt
setblock ~34 ~113 ~99 dirt
setblock ~34 ~113 ~100 dirt
setblock ~34 ~113 ~101 dirt
setblock ~34 ~113 ~102 dirt
setblock ~34 ~113 ~103 dirt
setblock ~34 ~113 ~104 dirt
setblock ~34 ~113 ~105 dirt
setblock ~34 ~113 ~106 dirt
setblock ~34 ~113 ~107 dirt
setblock ~34 ~113 ~108 dirt
setblock ~34 ~113 ~109 dirt
setblock ~34 ~113 ~110 dirt
setblock ~34 ~113 ~111 dirt
setblock ~34 ~113 ~112 dirt
setblock ~34 ~113 ~113 dirt
setblock ~34 ~113 ~114 dirt
setblock ~34 ~113 ~115 dirt
setblock ~34 ~113 ~116 dirt
setblock ~34 ~113 ~117 dirt
setblock ~34 ~113 ~118 dirt
setblock ~34 ~114 ~74 dirt
setblock ~34 ~114 ~75 dirt
setblock ~34 ~114 ~76 dirt
setblock ~34 ~114 ~77 dirt
setblock ~34 ~114 ~78 dirt
setblock ~34 ~114 ~79 dirt
setblock ~34 ~114 ~80 dirt
setblock ~34 ~114 ~81 dirt
setblock ~34 ~114 ~82 dirt
setblock ~34 ~114 ~83 dirt
setblock ~34 ~114 ~84 dirt
setblock ~34 ~114 ~85 dirt
setblock ~34 ~114 ~86 dirt
setblock ~34 ~114 ~87 dirt
setblock ~34 ~114 ~88 dirt
setblock ~34 ~114 ~89 dirt
setblock ~34 ~114 ~90 dirt
setblock ~34 ~114 ~91 dirt
setblock ~34 ~114 ~92 dirt
setblock ~34 ~114 ~93 dirt
setblock ~34 ~114 ~94 dirt
setblock ~34 ~114 ~95 dirt
setblock ~34 ~114 ~96 dirt
setblock ~34 ~114 ~97 dirt
setblock ~34 ~114 ~98 dirt
setblock ~34 ~114 ~99 dirt
setblock ~34 ~114 ~100 dirt
setblock ~34 ~114 ~101 dirt
setblock ~34 ~114 ~102 dirt
setblock ~34 ~114 ~103 dirt
setblock ~34 ~114 ~104 dirt
setblock ~34 ~114 ~105 dirt
setblock ~34 ~114 ~106 dirt
setblock ~34 ~114 ~107 dirt
setblock ~34 ~114 ~108 dirt
setblock ~34 ~114 ~109 dirt
setblock ~34 ~114 ~110 dirt
setblock ~34 ~114 ~111 dirt
setblock ~34 ~114 ~112 dirt
setblock ~34 ~114 ~113 dirt
setblock ~34 ~114 ~114 dirt
setblock ~34 ~114 ~115 dirt
setblock ~34 ~114 ~116 dirt
setblock ~34 ~114 ~117 dirt
setblock ~34 ~114 ~118 dirt
setblock ~34 ~114 ~119 dirt
setblock ~34 ~115 ~73 dirt
setblock ~34 ~115 ~74 dirt
setblock ~34 ~115 ~75 dirt
setblock ~34 ~115 ~76 dirt
setblock ~34 ~115 ~77 dirt
setblock ~34 ~115 ~78 dirt
setblock ~34 ~115 ~79 dirt
setblock ~34 ~115 ~80 dirt
setblock ~34 ~115 ~81 dirt
setblock ~34 ~115 ~82 dirt
setblock ~34 ~115 ~83 dirt
setblock ~34 ~115 ~84 dirt
setblock ~34 ~115 ~85 dirt
setblock ~34 ~115 ~86 dirt
setblock ~34 ~115 ~87 dirt
setblock ~34 ~115 ~88 dirt
setblock ~34 ~115 ~89 dirt
setblock ~34 ~115 ~90 dirt
setblock ~34 ~115 ~91 dirt
setblock ~34 ~115 ~92 dirt
setblock ~34 ~115 ~93 dirt
setblock ~34 ~115 ~94 dirt
setblock ~34 ~115 ~95 dirt
setblock ~34 ~115 ~96 dirt
setblock ~34 ~115 ~97 dirt
setblock ~34 ~115 ~98 dirt
setblock ~34 ~115 ~99 dirt
setblock ~34 ~115 ~100 dirt
setblock ~34 ~115 ~101 dirt
setblock ~34 ~115 ~102 dirt
setblock ~34 ~115 ~103 dirt
setblock ~34 ~115 ~104 dirt
setblock ~34 ~115 ~105 dirt
setblock ~34 ~115 ~106 dirt
setblock ~34 ~115 ~107 dirt
setblock ~34 ~115 ~108 dirt
setblock ~34 ~115 ~109 dirt
setblock ~34 ~115 ~110 dirt
setblock ~34 ~115 ~111 dirt
setblock ~34 ~115 ~112 dirt
setblock ~34 ~115 ~113 dirt
setblock ~34 ~115 ~114 dirt
setblock ~34 ~115 ~115 dirt
setblock ~34 ~115 ~116 dirt
setblock ~34 ~115 ~117 dirt
setblock ~34 ~115 ~118 dirt
setblock ~34 ~115 ~119 dirt
setblock ~34 ~116 ~72 dirt
setblock ~34 ~116 ~73 dirt
setblock ~34 ~116 ~74 dirt
setblock ~34 ~116 ~75 dirt
setblock ~34 ~116 ~76 dirt
setblock ~34 ~116 ~77 dirt
setblock ~34 ~116 ~78 dirt
setblock ~34 ~116 ~79 dirt
setblock ~34 ~116 ~80 dirt
setblock ~34 ~116 ~81 dirt
setblock ~34 ~116 ~82 dirt
setblock ~34 ~116 ~83 dirt
setblock ~34 ~116 ~84 dirt
setblock ~34 ~116 ~85 dirt
setblock ~34 ~116 ~86 dirt
setblock ~34 ~116 ~87 dirt
setblock ~34 ~116 ~88 dirt
setblock ~34 ~116 ~89 dirt
setblock ~34 ~116 ~90 dirt
setblock ~34 ~116 ~91 dirt
setblock ~34 ~116 ~92 dirt
setblock ~34 ~116 ~93 dirt
setblock ~34 ~116 ~94 dirt
setblock ~34 ~116 ~95 dirt
setblock ~34 ~116 ~96 dirt
setblock ~34 ~116 ~97 dirt
setblock ~34 ~116 ~98 dirt
setblock ~34 ~116 ~99 dirt
setblock ~34 ~116 ~100 dirt
setblock ~34 ~116 ~101 dirt
setblock ~34 ~116 ~102 dirt
setblock ~34 ~116 ~103 dirt
setblock ~34 ~116 ~104 dirt
setblock ~34 ~116 ~105 dirt
setblock ~34 ~116 ~106 dirt
setblock ~34 ~116 ~107 dirt
setblock ~34 ~116 ~108 dirt
setblock ~34 ~116 ~109 dirt
setblock ~34 ~116 ~110 dirt
setblock ~34 ~116 ~111 dirt
setblock ~34 ~116 ~112 dirt
setblock ~34 ~116 ~113 dirt
setblock ~34 ~116 ~114 dirt
setblock ~34 ~116 ~115 dirt
setblock ~34 ~116 ~116 dirt
setblock ~34 ~116 ~117 dirt
setblock ~34 ~116 ~118 dirt
setblock ~34 ~116 ~119 dirt
setblock ~34 ~117 ~71 dirt
setblock ~34 ~117 ~72 dirt
setblock ~34 ~117 ~73 dirt
setblock ~34 ~117 ~74 dirt
setblock ~34 ~117 ~75 dirt
setblock ~34 ~117 ~76 dirt
setblock ~34 ~117 ~77 dirt
setblock ~34 ~117 ~78 dirt
setblock ~34 ~117 ~79 dirt
setblock ~34 ~117 ~80 dirt
setblock ~34 ~117 ~81 dirt
setblock ~34 ~117 ~82 dirt
setblock ~34 ~117 ~83 dirt
setblock ~34 ~117 ~84 dirt
setblock ~34 ~117 ~85 dirt
setblock ~34 ~117 ~86 dirt
setblock ~34 ~117 ~87 dirt
setblock ~34 ~117 ~88 dirt
setblock ~34 ~117 ~89 dirt
setblock ~34 ~117 ~90 dirt
setblock ~34 ~117 ~91 dirt
setblock ~34 ~117 ~92 dirt
setblock ~34 ~117 ~93 dirt
setblock ~34 ~117 ~94 dirt
setblock ~34 ~117 ~95 dirt
setblock ~34 ~117 ~96 dirt
setblock ~34 ~117 ~97 dirt
setblock ~34 ~117 ~98 dirt
setblock ~34 ~117 ~99 dirt
setblock ~34 ~117 ~100 dirt
setblock ~34 ~117 ~101 dirt
setblock ~34 ~117 ~102 dirt
setblock ~34 ~117 ~103 dirt
setblock ~34 ~117 ~104 dirt
setblock ~34 ~117 ~105 dirt
setblock ~34 ~117 ~106 dirt
setblock ~34 ~117 ~107 dirt
setblock ~34 ~117 ~108 dirt
setblock ~34 ~117 ~109 dirt
setblock ~34 ~117 ~110 dirt
setblock ~34 ~117 ~111 dirt
setblock ~34 ~117 ~112 dirt
setblock ~34 ~117 ~113 dirt
setblock ~34 ~117 ~114 dirt
setblock ~34 ~117 ~115 dirt
setblock ~34 ~117 ~116 dirt
setblock ~34 ~117 ~117 dirt
setblock ~34 ~117 ~118 dirt
setblock ~34 ~117 ~119 dirt
setblock ~34 ~117 ~120 dirt
setblock ~34 ~118 ~70 dirt
setblock ~34 ~118 ~71 dirt
setblock ~34 ~118 ~72 dirt
setblock ~34 ~118 ~73 dirt
setblock ~34 ~118 ~74 dirt
setblock ~34 ~118 ~75 dirt
