setblock ~36 ~114 ~104 dirt
setblock ~36 ~114 ~105 dirt
setblock ~36 ~114 ~106 dirt
setblock ~36 ~114 ~107 dirt
setblock ~36 ~115 ~76 dirt
setblock ~36 ~115 ~77 dirt
setblock ~36 ~115 ~78 dirt
setblock ~36 ~115 ~79 dirt
setblock ~36 ~115 ~80 dirt
setblock ~36 ~115 ~81 dirt
setblock ~36 ~115 ~82 dirt
setblock ~36 ~115 ~83 dirt
setblock ~36 ~115 ~84 dirt
setblock ~36 ~115 ~85 dirt
setblock ~36 ~115 ~86 dirt
setblock ~36 ~115 ~87 dirt
setblock ~36 ~115 ~88 dirt
setblock ~36 ~115 ~89 dirt
setblock ~36 ~115 ~90 dirt
setblock ~36 ~115 ~91 dirt
setblock ~36 ~115 ~92 dirt
setblock ~36 ~115 ~93 dirt
setblock ~36 ~115 ~94 dirt
setblock ~36 ~115 ~95 dirt
setblock ~36 ~115 ~96 dirt
setblock ~36 ~115 ~97 dirt
setblock ~36 ~115 ~98 dirt
setblock ~36 ~115 ~99 dirt
setblock ~36 ~115 ~100 dirt
setblock ~36 ~115 ~101 dirt
setblock ~36 ~115 ~102 dirt
setblock ~36 ~115 ~103 dirt
setblock ~36 ~115 ~104 dirt
setblock ~36 ~115 ~105 dirt
setblock ~36 ~115 ~106 dirt
setblock ~36 ~115 ~107 dirt
setblock ~36 ~115 ~108 dirt
setblock ~36 ~116 ~75 dirt
setblock ~36 ~116 ~76 dirt
setblock ~36 ~116 ~77 dirt
setblock ~36 ~116 ~78 dirt
setblock ~36 ~116 ~79 dirt
setblock ~36 ~116 ~80 dirt
setblock ~36 ~116 ~81 dirt
setblock ~36 ~116 ~82 dirt
setblock ~36 ~116 ~83 dirt
setblock ~36 ~116 ~84 dirt
setblock ~36 ~116 ~85 dirt
setblock ~36 ~116 ~86 dirt
setblock ~36 ~116 ~87 dirt
setblock ~36 ~116 ~88 dirt
setblock ~36 ~116 ~89 dirt
setblock ~36 ~116 ~90 dirt
setblock ~36 ~116 ~91 dirt
setblock ~36 ~116 ~92 dirt
setblock ~36 ~116 ~93 dirt
setblock ~36 ~116 ~94 dirt
setblock ~36 ~116 ~95 dirt
setblock ~36 ~116 ~96 dirt
setblock ~36 ~116 ~97 dirt
setblock ~36 ~116 ~98 dirt
setblock ~36 ~116 ~99 dirt
setblock ~36 ~116 ~100 dirt
setblock ~36 ~116 ~101 dirt
setblock ~36 ~116 ~102 dirt
setblock ~36 ~116 ~103 dirt
setblock ~36 ~116 ~104 dirt
setblock ~36 ~116 ~105 dirt
setblock ~36 ~116 ~106 dirt
setblock ~36 ~116 ~107 dirt
setblock ~36 ~116 ~108 dirt
setblock ~36 ~117 ~75 dirt
setblock ~36 ~117 ~76 dirt
setblock ~36 ~117 ~77 dirt
setblock ~36 ~117 ~78 dirt
setblock ~36 ~117 ~79 dirt
setblock ~36 ~117 ~80 dirt
setblock ~36 ~117 ~81 dirt
setblock ~36 ~117 ~82 dirt
setblock ~36 ~117 ~83 dirt
setblock ~36 ~117 ~84 dirt
setblock ~36 ~117 ~85 dirt
setblock ~36 ~117 ~86 dirt
setblock ~36 ~117 ~87 dirt
setblock ~36 ~117 ~88 dirt
setblock ~36 ~117 ~89 dirt
setblock ~36 ~117 ~90 dirt
setblock ~36 ~117 ~91 dirt
setblock ~36 ~117 ~92 dirt
setblock ~36 ~117 ~93 dirt
setblock ~36 ~117 ~94 dirt
setblock ~36 ~117 ~95 dirt
setblock ~36 ~117 ~96 dirt
setblock ~36 ~117 ~97 dirt
setblock ~36 ~117 ~98 dirt
setblock ~36 ~117 ~99 dirt
setblock ~36 ~117 ~100 dirt
setblock ~36 ~117 ~101 dirt
setblock ~36 ~117 ~102 dirt
setblock ~36 ~117 ~103 dirt
setblock ~36 ~117 ~104 dirt
setblock ~36 ~117 ~105 dirt
setblock ~36 ~117 ~106 dirt
setblock ~36 ~117 ~107 dirt
setblock ~36 ~117 ~108 dirt
setblock ~36 ~117 ~109 dirt
setblock ~36 ~118 ~75 dirt
setblock ~36 ~118 ~76 dirt
setblock ~36 ~118 ~77 dirt
setblock ~36 ~118 ~78 dirt
setblock ~36 ~118 ~79 dirt
setblock ~36 ~118 ~80 dirt
setblock ~36 ~118 ~81 dirt
setblock ~36 ~118 ~82 dirt
setblock ~36 ~118 ~83 dirt
setblock ~36 ~118 ~84 dirt
setblock ~36 ~118 ~85 dirt
setblock ~36 ~118 ~86 dirt
setblock ~36 ~118 ~87 dirt
setblock ~36 ~118 ~88 dirt
setblock ~36 ~118 ~89 dirt
setblock ~36 ~118 ~90 dirt
setblock ~36 ~118 ~91 dirt
setblock ~36 ~118 ~92 dirt
setblock ~36 ~118 ~93 dirt
setblock ~36 ~118 ~94 dirt
setblock ~36 ~118 ~95 dirt
setblock ~36 ~118 ~96 dirt
setblock ~36 ~118 ~97 dirt
setblock ~36 ~118 ~98 dirt
setblock ~36 ~118 ~99 dirt
setblock ~36 ~118 ~100 dirt
setblock ~36 ~118 ~101 dirt
setblock ~36 ~118 ~102 dirt
setblock ~36 ~118 ~103 dirt
setblock ~36 ~118 ~104 dirt
setblock ~36 ~118 ~105 dirt
setblock ~36 ~118 ~106 dirt
setblock ~36 ~118 ~107 dirt
setblock ~36 ~118 ~108 dirt
setblock ~36 ~118 ~109 dirt
setblock ~36 ~119 ~74 dirt
setblock ~36 ~119 ~75 dirt
setblock ~36 ~119 ~76 dirt
setblock ~36 ~119 ~77 dirt
setblock ~36 ~119 ~78 dirt
setblock ~36 ~119 ~79 dirt
setblock ~36 ~119 ~80 dirt
setblock ~36 ~119 ~81 dirt
setblock ~36 ~119 ~82 dirt
setblock ~36 ~119 ~83 dirt
setblock ~36 ~119 ~84 dirt
setblock ~36 ~119 ~85 dirt
setblock ~36 ~119 ~86 dirt
setblock ~36 ~119 ~87 dirt
setblock ~36 ~119 ~88 dirt
setblock ~36 ~119 ~89 dirt
setblock ~36 ~119 ~90 dirt
setblock ~36 ~119 ~91 dirt
setblock ~36 ~119 ~92 dirt
setblock ~36 ~119 ~93 dirt
setblock ~36 ~119 ~94 dirt
setblock ~36 ~119 ~95 dirt
setblock ~36 ~119 ~96 dirt
setblock ~36 ~119 ~97 dirt
setblock ~36 ~119 ~98 dirt
setblock ~36 ~119 ~99 dirt
setblock ~36 ~119 ~100 dirt
setblock ~36 ~119 ~101 dirt
setblock ~36 ~119 ~102 dirt
setblock ~36 ~119 ~103 dirt
setblock ~36 ~119 ~104 dirt
setblock ~36 ~119 ~105 dirt
setblock ~36 ~119 ~106 dirt
setblock ~36 ~119 ~107 dirt
setblock ~36 ~119 ~108 dirt
setblock ~36 ~119 ~109 dirt
setblock ~36 ~120 ~73 dirt
setblock ~36 ~120 ~74 dirt
setblock ~36 ~120 ~75 dirt
setblock ~36 ~120 ~76 dirt
setblock ~36 ~120 ~77 dirt
setblock ~36 ~120 ~78 dirt
setblock ~36 ~120 ~79 dirt
setblock ~36 ~120 ~80 dirt
setblock ~36 ~120 ~81 dirt
setblock ~36 ~120 ~82 dirt
setblock ~36 ~120 ~83 dirt
setblock ~36 ~120 ~84 dirt
setblock ~36 ~120 ~85 dirt
setblock ~36 ~120 ~86 dirt
setblock ~36 ~120 ~87 dirt
setblock ~36 ~120 ~88 dirt
setblock ~36 ~120 ~89 dirt
setblock ~36 ~120 ~90 dirt
setblock ~36 ~120 ~91 dirt
setblock ~36 ~120 ~92 dirt
setblock ~36 ~120 ~93 dirt
setblock ~36 ~120 ~94 dirt
setblock ~36 ~120 ~95 dirt
setblock ~36 ~120 ~96 dirt
setblock ~36 ~120 ~97 dirt
setblock ~36 ~120 ~98 dirt
setblock ~36 ~120 ~99 dirt
setblock ~36 ~120 ~100 dirt
setblock ~36 ~120 ~101 dirt
setblock ~36 ~120 ~102 dirt
setblock ~36 ~120 ~103 dirt
setblock ~36 ~120 ~104 dirt
setblock ~36 ~120 ~105 dirt
setblock ~36 ~120 ~106 dirt
setblock ~36 ~120 ~107 dirt
setblock ~36 ~120 ~108 dirt
setblock ~36 ~120 ~109 dirt
setblock ~36 ~121 ~73 dirt
setblock ~36 ~121 ~74 dirt
setblock ~36 ~121 ~75 dirt
setblock ~36 ~121 ~76 dirt
setblock ~36 ~121 ~77 dirt
setblock ~36 ~121 ~78 dirt
setblock ~36 ~121 ~79 dirt
setblock ~36 ~121 ~80 dirt
setblock ~36 ~121 ~81 dirt
setblock ~36 ~121 ~82 dirt
setblock ~36 ~121 ~83 dirt
setblock ~36 ~121 ~84 dirt
setblock ~36 ~121 ~85 dirt
setblock ~36 ~121 ~86 dirt
setblock ~36 ~121 ~87 dirt
setblock ~36 ~121 ~88 dirt
setblock ~36 ~121 ~89 dirt
setblock ~36 ~121 ~90 dirt
setblock ~36 ~121 ~91 dirt
setblock ~36 ~121 ~92 dirt
setblock ~36 ~121 ~93 dirt
setblock ~36 ~121 ~94 dirt
setblock ~36 ~121 ~95 dirt
setblock ~36 ~121 ~96 dirt
setblock ~36 ~121 ~97 dirt
setblock ~36 ~121 ~98 dirt
setblock ~36 ~121 ~99 dirt
setblock ~36 ~121 ~100 dirt
setblock ~36 ~121 ~101 dirt
setblock ~36 ~121 ~102 dirt
setblock ~36 ~121 ~103 dirt
setblock ~36 ~121 ~104 dirt
setblock ~36 ~121 ~105 dirt
setblock ~36 ~121 ~106 dirt
setblock ~36 ~121 ~107 dirt
setblock ~36 ~121 ~108 dirt
setblock ~36 ~121 ~109 dirt
setblock ~36 ~121 ~110 dirt
setblock ~36 ~122 ~73 dirt
setblock ~36 ~122 ~74 dirt
setblock ~36 ~122 ~75 dirt
setblock ~36 ~122 ~76 dirt
setblock ~36 ~122 ~77 dirt
setblock ~36 ~122 ~78 dirt
setblock ~36 ~122 ~79 dirt
setblock ~36 ~122 ~80 dirt
setblock ~36 ~122 ~81 dirt
setblock ~36 ~122 ~82 dirt
setblock ~36 ~122 ~83 dirt
setblock ~36 ~122 ~84 dirt
setblock ~36 ~122 ~85 dirt
setblock ~36 ~122 ~86 dirt
setblock ~36 ~122 ~87 dirt
setblock ~36 ~122 ~88 dirt
setblock ~36 ~122 ~89 dirt
setblock ~36 ~122 ~90 dirt
setblock ~36 ~122 ~91 dirt
setblock ~36 ~122 ~92 dirt
setblock ~36 ~122 ~93 dirt
setblock ~36 ~122 ~94 dirt
setblock ~36 ~122 ~95 dirt
setblock ~36 ~122 ~96 dirt
setblock ~36 ~122 ~97 dirt
setblock ~36 ~122 ~98 dirt
setblock ~36 ~122 ~99 dirt
setblock ~36 ~122 ~100 dirt
setblock ~36 ~122 ~101 dirt
setblock ~36 ~122 ~102 dirt
setblock ~36 ~122 ~103 dirt
setblock ~36 ~122 ~104 dirt
setblock ~36 ~122 ~105 dirt
setblock ~36 ~122 ~106 dirt
setblock ~36 ~122 ~107 dirt
setblock ~36 ~122 ~108 dirt
setblock ~36 ~122 ~109 dirt
setblock ~36 ~122 ~110 dirt
setblock ~36 ~123 ~73 dirt
setblock ~36 ~123 ~74 dirt
setblock ~36 ~123 ~75 dirt
setblock ~36 ~123 ~76 dirt
setblock ~36 ~123 ~77 dirt
setblock ~36 ~123 ~78 dirt
setblock ~36 ~123 ~79 dirt
setblock ~36 ~123 ~80 dirt
setblock ~36 ~123 ~81 dirt
setblock ~36 ~123 ~82 dirt
setblock ~36 ~123 ~83 dirt
setblock ~36 ~123 ~84 dirt
setblock ~36 ~123 ~85 dirt
setblock ~36 ~123 ~86 dirt
setblock ~36 ~123 ~87 dirt
setblock ~36 ~123 ~88 dirt
setblock ~36 ~123 ~89 dirt
setblock ~36 ~123 ~90 dirt
setblock ~36 ~123 ~91 dirt
setblock ~36 ~123 ~92 dirt
setblock ~36 ~123 ~93 dirt
setblock ~36 ~123 ~94 dirt
setblock ~36 ~123 ~95 dirt
setblock ~36 ~123 ~96 dirt
setblock ~36 ~123 ~97 dirt
setblock ~36 ~123 ~98 dirt
setblock ~36 ~123 ~99 dirt
setblock ~36 ~123 ~100 dirt
setblock ~36 ~123 ~101 dirt
setblock ~36 ~123 ~102 dirt
setblock ~36 ~123 ~103 dirt
setblock ~36 ~123 ~104 dirt
setblock ~36 ~123 ~105 dirt
setblock ~36 ~123 ~106 dirt
setblock ~36 ~123 ~107 dirt
setblock ~36 ~123 ~108 dirt
setblock ~36 ~123 ~109 dirt
setblock ~36 ~123 ~110 dirt
setblock ~36 ~124 ~73 dirt
setblock ~36 ~124 ~74 dirt
setblock ~36 ~124 ~75 dirt
setblock ~36 ~124 ~76 dirt
setblock ~36 ~124 ~77 dirt
setblock ~36 ~124 ~78 dirt
setblock ~36 ~124 ~79 dirt
setblock ~36 ~124 ~80 dirt
setblock ~36 ~124 ~81 dirt
setblock ~36 ~124 ~82 dirt
setblock ~36 ~124 ~83 dirt
setblock ~36 ~124 ~84 dirt
setblock ~36 ~124 ~85 dirt
setblock ~36 ~124 ~86 dirt
setblock ~36 ~124 ~87 dirt
setblock ~36 ~124 ~88 dirt
setblock ~36 ~124 ~89 dirt
setblock ~36 ~124 ~90 dirt
setblock ~36 ~124 ~91 dirt
setblock ~36 ~124 ~92 dirt
setblock ~36 ~124 ~93 dirt
setblock ~36 ~124 ~94 dirt
setblock ~36 ~124 ~95 dirt
setblock ~36 ~124 ~96 dirt
setblock ~36 ~124 ~97 dirt
setblock ~36 ~124 ~98 dirt
setblock ~36 ~124 ~99 grass_block
setblock ~36 ~124 ~100 grass_block
setblock ~36 ~124 ~101 grass_block
setblock ~36 ~124 ~102 grass_block
setblock ~36 ~124 ~103 grass_block
setblock ~36 ~124 ~104 grass_block
setblock ~36 ~124 ~105 grass_block
setblock ~36 ~124 ~106 grass_block
setblock ~36 ~124 ~107 grass_block
setblock ~36 ~124 ~108 grass_block
setblock ~36 ~124 ~109 grass_block
setblock ~36 ~124 ~110 grass_block
setblock ~36 ~125 ~73 grass_block
setblock ~36 ~125 ~74 dirt
setblock ~36 ~125 ~75 dirt
setblock ~36 ~125 ~76 dirt
setblock ~36 ~125 ~77 dirt
setblock ~36 ~125 ~78 dirt
setblock ~36 ~125 ~79 dirt
setblock ~36 ~125 ~80 dirt
setblock ~36 ~125 ~81 dirt
setblock ~36 ~125 ~82 dirt
setblock ~36 ~125 ~83 dirt
setblock ~36 ~125 ~84 dirt
setblock ~36 ~125 ~85 dirt
setblock ~36 ~125 ~86 dirt
setblock ~36 ~125 ~87 dirt
setblock ~36 ~125 ~88 dirt
setblock ~36 ~125 ~89 dirt
setblock ~36 ~125 ~90 dirt
setblock ~36 ~125 ~91 dirt
setblock ~36 ~125 ~92 dirt
setblock ~36 ~125 ~93 dirt
setblock ~36 ~125 ~94 grass_block
setblock ~36 ~125 ~95 grass_block
setblock ~36 ~125 ~96 grass_block
setblock ~36 ~125 ~97 grass_block
setblock ~36 ~125 ~98 grass_block
setblock ~36 ~125 ~99 short_grass
setblock ~36 ~125 ~102 short_grass
setblock ~36 ~125 ~103 short_grass
setblock ~36 ~125 ~108 short_grass
setblock ~36 ~126 ~74 grass_block
setblock ~36 ~126 ~75 grass_block
setblock ~36 ~126 ~76 dirt
setblock ~36 ~126 ~77 dirt
setblock ~36 ~126 ~78 dirt
setblock ~36 ~126 ~79 dirt
setblock ~36 ~126 ~80 dirt
setblock ~36 ~126 ~81 dirt
setblock ~36 ~126 ~82 dirt
setblock ~36 ~126 ~83 dirt
setblock ~36 ~126 ~84 dirt
setblock ~36 ~126 ~85 dirt
setblock ~36 ~126 ~86 grass_block
setblock ~36 ~126 ~87 grass_block
setblock ~36 ~126 ~88 grass_block
setblock ~36 ~126 ~89 grass_block
setblock ~36 ~126 ~90 grass_block
setblock ~36 ~126 ~91 grass_block
setblock ~36 ~126 ~92 grass_block
setblock ~36 ~126 ~93 grass_block
setblock ~36 ~126 ~94 poppy
setblock ~36 ~127 ~75 poppy
setblock ~36 ~127 ~76 grass_block
setblock ~36 ~127 ~77 grass_block
setblock ~36 ~127 ~78 grass_block
setblock ~36 ~127 ~79 grass_block
setblock ~36 ~127 ~80 grass_block
setblock ~36 ~127 ~81 grass_block
setblock ~36 ~127 ~82 grass_block
setblock ~36 ~127 ~83 grass_block
setblock ~36 ~127 ~84 grass_block
setblock ~36 ~127 ~85 grass_block
setblock ~36 ~127 ~90 short_grass
setblock ~36 ~127 ~91 short_grass
setblock ~36 ~128 ~77 short_grass
setblock ~36 ~128 ~79 short_grass
setblock ~36 ~128 ~82 short_grass
setblock ~36 ~128 ~83 short_grass
setblock ~36 ~128 ~84 short_grass
setblock ~37 ~102 ~93 dirt
setblock ~37 ~103 ~92 dirt
setblock ~37 ~103 ~93 dirt
setblock ~37 ~103 ~102 dirt
setblock ~37 ~104 ~90 dirt
setblock ~37 ~104 ~91 dirt
setblock ~37 ~104 ~92 dirt
setblock ~37 ~104 ~93 dirt
setblock ~37 ~104 ~95 dirt
setblock ~37 ~104 ~102 dirt
setblock ~37 ~105 ~90 dirt
setblock ~37 ~105 ~91 dirt
setblock ~37 ~105 ~92 dirt
setblock ~37 ~105 ~93 dirt
setblock ~37 ~105 ~94 dirt
setblock ~37 ~105 ~95 dirt
setblock ~37 ~105 ~102 dirt
setblock ~37 ~105 ~103 dirt
setblock ~37 ~106 ~90 dirt
setblock ~37 ~106 ~91 dirt
setblock ~37 ~106 ~92 dirt
setblock ~37 ~106 ~93 dirt
setblock ~37 ~106 ~94 dirt
setblock ~37 ~106 ~95 dirt
setblock ~37 ~106 ~96 dirt
setblock ~37 ~106 ~101 dirt
setblock ~37 ~106 ~102 dirt
setblock ~37 ~106 ~103 dirt
setblock ~37 ~106 ~104 dirt
setblock ~37 ~107 ~89 dirt
setblock ~37 ~107 ~90 dirt
setblock ~37 ~107 ~91 dirt
setblock ~37 ~107 ~92 dirt
setblock ~37 ~107 ~93 dirt
setblock ~37 ~107 ~94 dirt
setblock ~37 ~107 ~95 dirt
setblock ~37 ~107 ~96 dirt
setblock ~37 ~107 ~97 dirt
setblock ~37 ~107 ~99 dirt
setblock ~37 ~107 ~100 dirt
setblock ~37 ~107 ~101 dirt
setblock ~37 ~107 ~102 dirt
setblock ~37 ~107 ~103 dirt
setblock ~37 ~107 ~104 dirt
setblock ~37 ~108 ~88 dirt
setblock ~37 ~108 ~89 dirt
setblock ~37 ~108 ~90 dirt
setblock ~37 ~108 ~91 dirt
setblock ~37 ~108 ~92 dirt
setblock ~37 ~108 ~93 dirt
setblock ~37 ~108 ~94 dirt
setblock ~37 ~108 ~95 dirt
setblock ~37 ~108 ~96 dirt
setblock ~37 ~108 ~97 dirt
setblock ~37 ~108 ~98 dirt
setblock ~37 ~108 ~99 dirt
setblock ~37 ~108 ~100 dirt
setblock ~37 ~108 ~101 dirt
setblock ~37 ~108 ~102 dirt
setblock ~37 ~108 ~103 dirt
setblock ~37 ~108 ~104 dirt
setblock ~37 ~109 ~86 dirt
setblock ~37 ~109 ~87 dirt
setblock ~37 ~109 ~88 dirt
setblock ~37 ~109 ~89 dirt
setblock ~37 ~109 ~90 dirt
setblock ~37 ~109 ~91 dirt
setblock ~37 ~109 ~92 dirt
setblock ~37 ~109 ~93 dirt
setblock ~37 ~109 ~94 dirt
setblock ~37 ~109 ~95 dirt
setblock ~37 ~109 ~96 dirt
setblock ~37 ~109 ~97 dirt
setblock ~37 ~109 ~98 dirt
setblock ~37 ~109 ~99 dirt
setblock ~37 ~109 ~100 dirt
setblock ~37 ~109 ~101 dirt
setblock ~37 ~109 ~102 dirt
setblock ~37 ~109 ~103 dirt
setblock ~37 ~109 ~104 dirt
setblock ~37 ~109 ~105 dirt
setblock ~37 ~110 ~79 dirt
setblock ~37 ~110 ~85 dirt
setblock ~37 ~110 ~86 dirt
setblock ~37 ~110 ~87 dirt
setblock ~37 ~110 ~88 dirt
setblock ~37 ~110 ~89 dirt
setblock ~37 ~110 ~90 dirt
setblock ~37 ~110 ~91 dirt
setblock ~37 ~110 ~92 dirt
setblock ~37 ~110 ~93 dirt
setblock ~37 ~110 ~94 dirt
setblock ~37 ~110 ~95 dirt
setblock ~37 ~110 ~96 dirt
setblock ~37 ~110 ~97 dirt
setblock ~37 ~110 ~98 dirt
setblock ~37 ~110 ~99 dirt
setblock ~37 ~110 ~100 dirt
setblock ~37 ~110 ~101 dirt
setblock ~37 ~110 ~102 dirt
setblock ~37 ~110 ~103 dirt
setblock ~37 ~110 ~104 dirt
setblock ~37 ~110 ~105 dirt
setblock ~37 ~111 ~77 dirt
setblock ~37 ~111 ~78 dirt
setblock ~37 ~111 ~79 dirt
setblock ~37 ~111 ~81 dirt
setblock ~37 ~111 ~82 dirt
setblock ~37 ~111 ~84 dirt
setblock ~37 ~111 ~85 dirt
setblock ~37 ~111 ~86 dirt
setblock ~37 ~111 ~87 dirt
setblock ~37 ~111 ~88 dirt
setblock ~37 ~111 ~89 dirt
setblock ~37 ~111 ~90 dirt
setblock ~37 ~111 ~91 dirt
setblock ~37 ~111 ~92 dirt
setblock ~37 ~111 ~93 dirt
setblock ~37 ~111 ~94 dirt
setblock ~37 ~111 ~95 dirt
setblock ~37 ~111 ~96 dirt
setblock ~37 ~111 ~97 dirt
setblock ~37 ~111 ~98 dirt
setblock ~37 ~111 ~99 dirt
setblock ~37 ~111 ~100 dirt
setblock ~37 ~111 ~101 dirt
setblock ~37 ~111 ~102 dirt
setblock ~37 ~111 ~103 dirt
setblock ~37 ~111 ~104 dirt
setblock ~37 ~111 ~105 dirt
setblock ~37 ~112 ~77 dirt
setblock ~37 ~112 ~78 dirt
setblock ~37 ~112 ~79 dirt
setblock ~37 ~112 ~81 dirt
setblock ~37 ~112 ~82 dirt
setblock ~37 ~112 ~83 dirt
setblock ~37 ~112 ~84 dirt
setblock ~37 ~112 ~85 dirt
setblock ~37 ~112 ~86 dirt
setblock ~37 ~112 ~87 dirt
setblock ~37 ~112 ~88 dirt
setblock ~37 ~112 ~89 dirt
setblock ~37 ~112 ~90 dirt
setblock ~37 ~112 ~91 dirt
setblock ~37 ~112 ~92 dirt
setblock ~37 ~112 ~93 dirt
setblock ~37 ~112 ~94 dirt
setblock ~37 ~112 ~95 dirt
setblock ~37 ~112 ~96 dirt
setblock ~37 ~112 ~97 dirt
setblock ~37 ~112 ~98 dirt
setblock ~37 ~112 ~99 dirt
setblock ~37 ~112 ~100 dirt
setblock ~37 ~112 ~101 dirt
setblock ~37 ~112 ~102 dirt
setblock ~37 ~112 ~103 dirt
setblock ~37 ~112 ~104 dirt
setblock ~37 ~112 ~105 dirt
setblock ~37 ~112 ~106 dirt
setblock ~37 ~113 ~76 dirt
setblock ~37 ~113 ~77 dirt
setblock ~37 ~113 ~78 dirt
setblock ~37 ~113 ~79 dirt
setblock ~37 ~113 ~80 dirt
setblock ~37 ~113 ~81 dirt
setblock ~37 ~113 ~82 dirt
setblock ~37 ~113 ~83 dirt
setblock ~37 ~113 ~84 dirt
setblock ~37 ~113 ~85 dirt
setblock ~37 ~113 ~86 dirt
setblock ~37 ~113 ~87 dirt
setblock ~37 ~113 ~88 dirt
setblock ~37 ~113 ~89 dirt
setblock ~37 ~113 ~90 dirt
setblock ~37 ~113 ~91 dirt
setblock ~37 ~113 ~92 dirt
setblock ~37 ~113 ~93 dirt
setblock ~37 ~113 ~94 dirt
setblock ~37 ~113 ~95 dirt
setblock ~37 ~113 ~96 dirt
setblock ~37 ~113 ~97 dirt
setblock ~37 ~113 ~98 dirt
setblock ~37 ~113 ~99 dirt
setblock ~37 ~113 ~100 dirt
setblock ~37 ~113 ~101 dirt
setblock ~37 ~113 ~102 dirt
setblock ~37 ~113 ~103 dirt
setblock ~37 ~113 ~104 dirt
setblock ~37 ~113 ~105 dirt
setblock ~37 ~113 ~106 dirt
setblock ~37 ~114 ~75 dirt
setblock ~37 ~114 ~76 dirt
setblock ~37 ~114 ~77 dirt
setblock ~37 ~114 ~78 dirt
setblock ~37 ~114 ~79 dirt
setblock ~37 ~114 ~80 dirt
setblock ~37 ~114 ~81 dirt
setblock ~37 ~114 ~82 dirt
setblock ~37 ~114 ~83 dirt
setblock ~37 ~114 ~84 dirt
setblock ~37 ~114 ~85 dirt
setblock ~37 ~114 ~86 dirt
setblock ~37 ~114 ~87 dirt
setblock ~37 ~114 ~88 dirt
setblock ~37 ~114 ~89 dirt
setblock ~37 ~114 ~90 dirt
setblock ~37 ~114 ~91 dirt
setblock ~37 ~114 ~92 dirt
setblock ~37 ~114 ~93 dirt
setblock ~37 ~114 ~94 dirt
setblock ~37 ~114 ~95 dirt
setblock ~37 ~114 ~96 dirt
setblock ~37 ~114 ~97 dirt
setblock ~37 ~114 ~98 dirt
setblock ~37 ~114 ~99 dirt
setblock ~37 ~114 ~100 dirt
setblock ~37 ~114 ~101 dirt
setblock ~37 ~114 ~102 dirt
setblock ~37 ~114 ~103 dirt
setblock ~37 ~114 ~104 dirt
setblock ~37 ~114 ~105 dirt
setblock ~37 ~114 ~106 dirt
setblock ~37 ~114 ~107 dirt
setblock ~37 ~115 ~75 dirt
setblock ~37 ~115 ~76 dirt
setblock ~37 ~115 ~77 dirt
setblock ~37 ~115 ~78 dirt
setblock ~37 ~115 ~79 dirt
setblock ~37 ~115 ~80 dirt
setblock ~37 ~115 ~81 dirt
setblock ~37 ~115 ~82 dirt
setblock ~37 ~115 ~83 dirt
setblock ~37 ~115 ~84 dirt
setblock ~37 ~115 ~85 dirt
setblock ~37 ~115 ~86 dirt
setblock ~37 ~115 ~87 dirt
setblock ~37 ~115 ~88 dirt
setblock ~37 ~115 ~89 dirt
setblock ~37 ~115 ~90 dirt
setblock ~37 ~115 ~91 dirt
setblock ~37 ~115 ~92 dirt
setblock ~37 ~115 ~93 dirt
setblock ~37 ~115 ~94 dirt
setblock ~37 ~115 ~95 dirt
setblock ~37 ~115 ~96 dirt
setblock ~37 ~115 ~97 dirt
setblock ~37 ~115 ~98 dirt
setblock ~37 ~115 ~99 dirt
setblock ~37 ~115 ~100 dirt
setblock ~37 ~115 ~101 dirt
setblock ~37 ~115 ~102 dirt
setblock ~37 ~115 ~103 dirt
setblock ~37 ~115 ~104 dirt
setblock ~37 ~115 ~105 dirt
setblock ~37 ~115 ~106 dirt
setblock ~37 ~115 ~107 dirt
setblock ~37 ~115 ~108 dirt
setblock ~37 ~116 ~74 dirt
setblock ~37 ~116 ~75 dirt
setblock ~37 ~116 ~76 dirt
setblock ~37 ~116 ~77 dirt
setblock ~37 ~116 ~78 dirt
setblock ~37 ~116 ~79 dirt
setblock ~37 ~116 ~80 dirt
setblock ~37 ~116 ~81 dirt
setblock ~37 ~116 ~82 dirt
setblock ~37 ~116 ~83 dirt
setblock ~37 ~116 ~84 dirt
setblock ~37 ~116 ~85 dirt
setblock ~37 ~116 ~86 dirt
setblock ~37 ~116 ~87 dirt
setblock ~37 ~116 ~88 dirt
setblock ~37 ~116 ~89 dirt
setblock ~37 ~116 ~90 dirt
setblock ~37 ~116 ~91 dirt
setblock ~37 ~116 ~92 dirt
setblock ~37 ~116 ~93 dirt
setblock ~37 ~116 ~94 dirt
setblock ~37 ~116 ~95 dirt
setblock ~37 ~116 ~96 dirt
setblock ~37 ~116 ~97 dirt
setblock ~37 ~116 ~98 dirt
setblock ~37 ~116 ~99 dirt
setblock ~37 ~116 ~100 dirt
setblock ~37 ~116 ~101 dirt
setblock ~37 ~116 ~102 dirt
setblock ~37 ~116 ~103 dirt
setblock ~37 ~116 ~104 dirt
setblock ~37 ~116 ~105 dirt
setblock ~37 ~116 ~106 dirt
setblock ~37 ~116 ~107 dirt
setblock ~37 ~116 ~108 dirt
setblock ~37 ~117 ~74 dirt
setblock ~37 ~117 ~75 dirt
setblock ~37 ~117 ~76 dirt
setblock ~37 ~117 ~77 dirt
setblock ~37 ~117 ~78 dirt
setblock ~37 ~117 ~79 dirt
setblock ~37 ~117 ~80 dirt
setblock ~37 ~117 ~81 dirt
setblock ~37 ~117 ~82 dirt
setblock ~37 ~117 ~83 dirt
setblock ~37 ~117 ~84 dirt
setblock ~37 ~117 ~85 dirt
setblock ~37 ~117 ~86 dirt
setblock ~37 ~117 ~87 dirt
setblock ~37 ~117 ~88 dirt
setblock ~37 ~117 ~89 dirt
setblock ~37 ~117 ~90 dirt
setblock ~37 ~117 ~91 dirt
setblock ~37 ~117 ~92 dirt
setblock ~37 ~117 ~93 dirt
setblock ~37 ~117 ~94 dirt
setblock ~37 ~117 ~95 dirt
setblock ~37 ~117 ~96 dirt
setblock ~37 ~117 ~97 dirt
setblock ~37 ~117 ~98 dirt
setblock ~37 ~117 ~99 dirt
setblock ~37 ~117 ~100 dirt
setblock ~37 ~117 ~101 dirt
setblock ~37 ~117 ~102 dirt
setblock ~37 ~117 ~103 dirt
setblock ~37 ~117 ~104 dirt
setblock ~37 ~117 ~105 dirt
setblock ~37 ~117 ~106 dirt
setblock ~37 ~117 ~107 dirt
setblock ~37 ~117 ~108 dirt
setblock ~37 ~118 ~74 dirt
setblock ~37 ~118 ~75 dirt
setblock ~37 ~118 ~76 dirt
setblock ~37 ~118 ~77 dirt
setblock ~37 ~118 ~78 dirt
setblock ~37 ~118 ~79 dirt
setblock ~37 ~118 ~80 dirt
setblock ~37 ~118 ~81 dirt
setblock ~37 ~118 ~82 dirt
setblock ~37 ~118 ~83 dirt
setblock ~37 ~118 ~84 dirt
setblock ~37 ~118 ~85 dirt
setblock ~37 ~118 ~86 dirt
setblock ~37 ~118 ~87 dirt
setblock ~37 ~118 ~88 dirt
setblock ~37 ~118 ~89 dirt
setblock ~37 ~118 ~90 dirt
setblock ~37 ~118 ~91 dirt
setblock ~37 ~118 ~92 dirt
setblock ~37 ~118 ~93 dirt
setblock ~37 ~118 ~94 dirt
setblock ~37 ~118 ~95 dirt
setblock ~37 ~118 ~96 dirt
setblock ~37 ~118 ~97 dirt
setblock ~37 ~118 ~98 dirt
setblock ~37 ~118 ~99 dirt
setblock ~37 ~118 ~100 dirt
setblock ~37 ~118 ~101 dirt
setblock ~37 ~118 ~102 dirt
setblock ~37 ~118 ~103 dirt
setblock ~37 ~118 ~104 dirt
setblock ~37 ~118 ~105 dirt
setblock ~37 ~118 ~106 dirt
setblock ~37 ~118 ~107 dirt
setblock ~37 ~118 ~108 dirt
setblock ~37 ~118 ~109 dirt
setblock ~37 ~119 ~74 dirt
setblock ~37 ~119 ~75 dirt
setblock ~37 ~119 ~76 dirt
setblock ~37 ~119 ~77 dirt
setblock ~37 ~119 ~78 dirt
setblock ~37 ~119 ~79 dirt
setblock ~37 ~119 ~80 dirt
setblock ~37 ~119 ~81 dirt
setblock ~37 ~119 ~82 dirt
setblock ~37 ~119 ~83 dirt
setblock ~37 ~119 ~84 dirt
setblock ~37 ~119 ~85 dirt
setblock ~37 ~119 ~86 dirt
setblock ~37 ~119 ~87 dirt
setblock ~37 ~119 ~88 dirt
setblock ~37 ~119 ~89 dirt
setblock ~37 ~119 ~90 dirt
setblock ~37 ~119 ~91 dirt
setblock ~37 ~119 ~92 dirt
setblock ~37 ~119 ~93 dirt
setblock ~37 ~119 ~94 dirt
setblock ~37 ~119 ~95 dirt
setblock ~37 ~119 ~96 dirt
setblock ~37 ~119 ~97 dirt
setblock ~37 ~119 ~98 dirt
setblock ~37 ~119 ~99 dirt
setblock ~37 ~119 ~100 dirt
setblock ~37 ~119 ~101 dirt
setblock ~37 ~119 ~102 dirt
setblock ~37 ~119 ~103 dirt
setblock ~37 ~119 ~104 dirt
setblock ~37 ~119 ~105 dirt
setblock ~37 ~119 ~106 dirt
setblock ~37 ~119 ~107 dirt
setblock ~37 ~119 ~108 dirt
setblock ~37 ~119 ~109 dirt
setblock ~37 ~119 ~110 dirt
setblock ~37 ~120 ~72 dirt
setblock ~37 ~120 ~73 dirt
setblock ~37 ~120 ~74 dirt
setblock ~37 ~120 ~75 dirt
setblock ~37 ~120 ~76 dirt
setblock ~37 ~120 ~77 dirt
setblock ~37 ~120 ~78 dirt
setblock ~37 ~120 ~79 dirt
setblock ~37 ~120 ~80 dirt
setblock ~37 ~120 ~81 dirt
setblock ~37 ~120 ~82 dirt
setblock ~37 ~120 ~83 dirt
setblock ~37 ~120 ~84 dirt
setblock ~37 ~120 ~85 dirt
setblock ~37 ~120 ~86 dirt
setblock ~37 ~120 ~87 dirt
setblock ~37 ~120 ~88 dirt
setblock ~37 ~120 ~89 dirt
setblock ~37 ~120 ~90 dirt
setblock ~37 ~120 ~91 dirt
setblock ~37 ~120 ~92 dirt
setblock ~37 ~120 ~93 dirt
setblock ~37 ~120 ~94 dirt
setblock ~37 ~120 ~95 dirt
setblock ~37 ~120 ~96 dirt
setblock ~37 ~120 ~97 dirt
setblock ~37 ~120 ~98 dirt
setblock ~37 ~120 ~99 dirt
setblock ~37 ~120 ~100 dirt
setblock ~37 ~120 ~101 dirt
setblock ~37 ~120 ~102 dirt
setblock ~37 ~120 ~103 dirt
setblock ~37 ~120 ~104 dirt
setblock ~37 ~120 ~105 dirt
setblock ~37 ~120 ~106 dirt
setblock ~37 ~120 ~107 dirt
setblock ~37 ~120 ~108 dirt
setblock ~37 ~120 ~109 dirt
setblock ~37 ~120 ~110 dirt
setblock ~37 ~121 ~72 dirt
setblock ~37 ~121 ~73 dirt
setblock ~37 ~121 ~74 dirt
setblock ~37 ~121 ~75 dirt
setblock ~37 ~121 ~76 dirt
setblock ~37 ~121 ~77 dirt
setblock ~37 ~121 ~78 dirt
setblock ~37 ~121 ~79 dirt
setblock ~37 ~121 ~80 dirt
setblock ~37 ~121 ~81 dirt
setblock ~37 ~121 ~82 dirt
setblock ~37 ~121 ~83 dirt
setblock ~37 ~121 ~84 dirt
setblock ~37 ~121 ~85 dirt
setblock ~37 ~121 ~86 dirt
setblock ~37 ~121 ~87 dirt
setblock ~37 ~121 ~88 dirt
setblock ~37 ~121 ~89 dirt
setblock ~37 ~121 ~90 dirt
setblock ~37 ~121 ~91 dirt
setblock ~37 ~121 ~92 dirt
setblock ~37 ~121 ~93 dirt
setblock ~37 ~121 ~94 dirt
setblock ~37 ~121 ~95 dirt
setblock ~37 ~121 ~96 dirt
setblock ~37 ~121 ~97 dirt
setblock ~37 ~121 ~98 dirt
setblock ~37 ~121 ~99 dirt
setblock ~37 ~121 ~100 dirt
setblock ~37 ~121 ~101 dirt
setblock ~37 ~121 ~102 dirt
setblock ~37 ~121 ~103 dirt
setblock ~37 ~121 ~104 dirt
setblock ~37 ~121 ~105 dirt
setblock ~37 ~121 ~106 dirt
setblock ~37 ~121 ~107 dirt
setblock ~37 ~121 ~108 dirt
setblock ~37 ~121 ~109 dirt
setblock ~37 ~121 ~110 dirt
setblock ~37 ~121 ~111 dirt
setblock ~37 ~122 ~72 dirt
setblock ~37 ~122 ~73 dirt
setblock ~37 ~122 ~74 dirt
setblock ~37 ~122 ~75 dirt
setblock ~37 ~122 ~76 dirt
setblock ~37 ~122 ~77 dirt
setblock ~37 ~122 ~78 dirt
setblock ~37 ~122 ~79 dirt
setblock ~37 ~122 ~80 dirt
setblock ~37 ~122 ~81 dirt
setblock ~37 ~122 ~82 dirt
setblock ~37 ~122 ~83 dirt
setblock ~37 ~122 ~84 dirt
setblock ~37 ~122 ~85 dirt
setblock ~37 ~122 ~86 dirt
setblock ~37 ~122 ~87 dirt
setblock ~37 ~122 ~88 dirt
setblock ~37 ~122 ~89 dirt
setblock ~37 ~122 ~90 dirt
setblock ~37 ~122 ~91 dirt
setblock ~37 ~122 ~92 dirt
setblock ~37 ~122 ~93 dirt
setblock ~37 ~122 ~94 dirt
setblock ~37 ~122 ~95 dirt
setblock ~37 ~122 ~96 dirt
setblock ~37 ~122 ~97 dirt
setblock ~37 ~122 ~98 dirt
setblock ~37 ~122 ~99 dirt
setblock ~37 ~122 ~100 dirt
setblock ~37 ~122 ~101 dirt
setblock ~37 ~122 ~102 dirt
setblock ~37 ~122 ~103 dirt
setblock ~37 ~122 ~104 dirt
setblock ~37 ~122 ~105 dirt
setblock ~37 ~122 ~106 dirt
setblock ~37 ~122 ~107 dirt
setblock ~37 ~122 ~108 dirt
setblock ~37 ~122 ~109 dirt
setblock ~37 ~122 ~110 dirt
setblock ~37 ~122 ~111 dirt
setblock ~37 ~123 ~72 dirt
setblock ~37 ~123 ~73 dirt
setblock ~37 ~123 ~74 dirt
setblock ~37 ~123 ~75 dirt
setblock ~37 ~123 ~76 dirt
setblock ~37 ~123 ~77 dirt
setblock ~37 ~123 ~78 dirt
setblock ~37 ~123 ~79 dirt
setblock ~37 ~123 ~80 dirt
setblock ~37 ~123 ~81 dirt
setblock ~37 ~123 ~82 dirt
setblock ~37 ~123 ~83 dirt
setblock ~37 ~123 ~84 dirt
setblock ~37 ~123 ~85 dirt
setblock ~37 ~123 ~86 dirt
setblock ~37 ~123 ~87 dirt
setblock ~37 ~123 ~88 dirt
setblock ~37 ~123 ~89 dirt
setblock ~37 ~123 ~90 dirt
setblock ~37 ~123 ~91 dirt
setblock ~37 ~123 ~92 dirt
setblock ~37 ~123 ~93 dirt
setblock ~37 ~123 ~94 dirt
setblock ~37 ~123 ~95 dirt
setblock ~37 ~123 ~96 dirt
setblock ~37 ~123 ~97 dirt
setblock ~37 ~123 ~98 dirt
setblock ~37 ~123 ~99 dirt
setblock ~37 ~123 ~100 dirt
setblock ~37 ~123 ~101 dirt
setblock ~37 ~123 ~102 dirt
setblock ~37 ~123 ~103 dirt
setblock ~37 ~123 ~104 dirt
setblock ~37 ~123 ~105 dirt
setblock ~37 ~123 ~106 dirt
setblock ~37 ~123 ~107 dirt
setblock ~37 ~123 ~108 dirt
setblock ~37 ~123 ~109 dirt
setblock ~37 ~123 ~110 dirt
setblock ~37 ~123 ~111 dirt
setblock ~37 ~124 ~72 dirt
setblock ~37 ~124 ~73 dirt
setblock ~37 ~124 ~74 dirt
setblock ~37 ~124 ~75 dirt
setblock ~37 ~124 ~76 dirt
setblock ~37 ~124 ~77 dirt
setblock ~37 ~124 ~78 dirt
setblock ~37 ~124 ~79 dirt
setblock ~37 ~124 ~80 dirt
setblock ~37 ~124 ~81 dirt
setblock ~37 ~124 ~82 dirt
setblock ~37 ~124 ~83 dirt
setblock ~37 ~124 ~84 dirt
setblock ~37 ~124 ~85 dirt
setblock ~37 ~124 ~86 dirt
setblock ~37 ~124 ~87 dirt
setblock ~37 ~124 ~88 dirt
setblock ~37 ~124 ~89 dirt
setblock ~37 ~124 ~90 dirt
setblock ~37 ~124 ~91 dirt
setblock ~37 ~124 ~92 dirt
setblock ~37 ~124 ~93 dirt
setblock ~37 ~124 ~94 dirt
setblock ~37 ~124 ~95 dirt
setblock ~37 ~124 ~96 dirt
setblock ~37 ~124 ~97 dirt
setblock ~37 ~124 ~98 dirt
setblock ~37 ~124 ~99 dirt
setblock ~37 ~124 ~100 dirt
setblock ~37 ~124 ~101 dirt
setblock ~37 ~124 ~102 dirt
setblock ~37 ~124 ~103 dirt
setblock ~37 ~124 ~104 dirt
setblock ~37 ~124 ~105 dirt
setblock ~37 ~124 ~106 dirt
setblock ~37 ~124 ~107 dirt
setblock ~37 ~124 ~108 dirt
setblock ~37 ~124 ~109 grass_block
setblock ~37 ~124 ~110 grass_block
setblock ~37 ~124 ~111 dirt
setblock ~37 ~125 ~72 grass_block
setblock ~37 ~125 ~73 grass_block
setblock ~37 ~125 ~74 dirt
setblock ~37 ~125 ~75 dirt
setblock ~37 ~125 ~76 dirt
setblock ~37 ~125 ~77 dirt
setblock ~37 ~125 ~78 dirt
setblock ~37 ~125 ~79 dirt
setblock ~37 ~125 ~80 dirt
setblock ~37 ~125 ~81 dirt
setblock ~37 ~125 ~82 dirt
setblock ~37 ~125 ~83 dirt
setblock ~37 ~125 ~84 dirt
setblock ~37 ~125 ~85 dirt
setblock ~37 ~125 ~86 dirt
setblock ~37 ~125 ~87 dirt
setblock ~37 ~125 ~88 dirt
setblock ~37 ~125 ~89 dirt
setblock ~37 ~125 ~90 dirt
setblock ~37 ~125 ~91 dirt
setblock ~37 ~125 ~92 dirt
setblock ~37 ~125 ~93 grass_block
setblock ~37 ~125 ~94 grass_block
setblock ~37 ~125 ~95 grass_block
setblock ~37 ~125 ~96 grass_block
setblock ~37 ~125 ~97 grass_block
setblock ~37 ~125 ~98 grass_block
setblock ~37 ~125 ~99 grass_block
setblock ~37 ~125 ~100 grass_block
setblock ~37 ~125 ~101 grass_block
setblock ~37 ~125 ~102 grass_block
setblock ~37 ~125 ~103 grass_block
setblock ~37 ~125 ~104 grass_block
setblock ~37 ~125 ~105 grass_block
setblock ~37 ~125 ~106 grass_block
setblock ~37 ~125 ~107 grass_block
setblock ~37 ~125 ~108 grass_block
setblock ~37 ~125 ~109 short_grass
setblock ~37 ~125 ~110 short_grass
setblock ~37 ~125 ~111 grass_block
setblock ~37 ~126 ~73 short_grass
setblock ~37 ~126 ~74 grass_block
setblock ~37 ~126 ~75 grass_block
setblock ~37 ~126 ~76 dirt
setblock ~37 ~126 ~77 dirt
setblock ~37 ~126 ~78 dirt
setblock ~37 ~126 ~79 dirt
setblock ~37 ~126 ~80 dirt
setblock ~37 ~126 ~81 dirt
setblock ~37 ~126 ~82 dirt
setblock ~37 ~126 ~83 dirt
setblock ~37 ~126 ~84 dirt
setblock ~37 ~126 ~85 dirt
setblock ~37 ~126 ~86 grass_block
setblock ~37 ~126 ~87 grass_block
setblock ~37 ~126 ~88 grass_block
setblock ~37 ~126 ~89 grass_block
setblock ~37 ~126 ~90 grass_block
setblock ~37 ~126 ~91 grass_block
setblock ~37 ~126 ~92 grass_block
setblock ~37 ~126 ~95 poppy
setblock ~37 ~126 ~98 short_grass
setblock ~37 ~126 ~100 short_grass
setblock ~37 ~126 ~101 short_grass
setblock ~37 ~126 ~104 short_grass
setblock ~37 ~127 ~74 short_grass
setblock ~37 ~127 ~76 grass_block
setblock ~37 ~127 ~77 grass_block
setblock ~37 ~127 ~78 grass_block
setblock ~37 ~127 ~79 dirt
setblock ~37 ~127 ~80 dirt
setblock ~37 ~127 ~81 dirt
setblock ~37 ~127 ~82 grass_block
setblock ~37 ~127 ~83 grass_block
setblock ~37 ~127 ~84 grass_block
setblock ~37 ~127 ~85 grass_block
setblock ~37 ~128 ~76 short_grass
setblock ~37 ~128 ~79 grass_block
setblock ~37 ~128 ~80 grass_block
setblock ~37 ~128 ~81 grass_block
setblock ~37 ~128 ~82 short_grass
setblock ~37 ~128 ~85 short_grass
setblock ~37 ~129 ~80 short_grass
setblock ~37 ~129 ~81 short_grass
setblock ~38 ~100 ~93 dirt
setblock ~38 ~101 ~93 dirt
setblock ~38 ~102 ~92 dirt
setblock ~38 ~102 ~93 dirt
setblock ~38 ~102 ~94 dirt
setblock ~38 ~102 ~95 dirt
setblock ~38 ~102 ~102 dirt
setblock ~38 ~103 ~90 dirt
setblock ~38 ~103 ~91 dirt
setblock ~38 ~103 ~92 dirt
setblock ~38 ~103 ~93 dirt
setblock ~38 ~103 ~94 dirt
setblock ~38 ~103 ~95 dirt
setblock ~38 ~103 ~96 dirt
setblock ~38 ~103 ~101 dirt
setblock ~38 ~103 ~102 dirt
setblock ~38 ~103 ~103 dirt
setblock ~38 ~104 ~89 dirt
setblock ~38 ~104 ~90 dirt
setblock ~38 ~104 ~91 dirt
setblock ~38 ~104 ~92 dirt
setblock ~38 ~104 ~93 dirt
setblock ~38 ~104 ~94 dirt
setblock ~38 ~104 ~95 dirt
setblock ~38 ~104 ~96 dirt
setblock ~38 ~104 ~98 dirt
setblock ~38 ~104 ~101 dirt
setblock ~38 ~104 ~102 dirt
setblock ~38 ~104 ~103 dirt
setblock ~38 ~105 ~88 dirt
setblock ~38 ~105 ~89 dirt
setblock ~38 ~105 ~90 dirt
setblock ~38 ~105 ~91 dirt
setblock ~38 ~105 ~92 dirt
setblock ~38 ~105 ~93 dirt
setblock ~38 ~105 ~94 dirt
setblock ~38 ~105 ~95 dirt
setblock ~38 ~105 ~96 dirt
setblock ~38 ~105 ~97 dirt
setblock ~38 ~105 ~98 dirt
setblock ~38 ~105 ~101 dirt
setblock ~38 ~105 ~102 dirt
setblock ~38 ~105 ~103 dirt
setblock ~38 ~105 ~104 dirt
setblock ~38 ~106 ~87 dirt
setblock ~38 ~106 ~88 dirt
setblock ~38 ~106 ~89 dirt
setblock ~38 ~106 ~90 dirt
setblock ~38 ~106 ~91 dirt
setblock ~38 ~106 ~92 dirt
setblock ~38 ~106 ~93 dirt
setblock ~38 ~106 ~94 dirt
setblock ~38 ~106 ~95 dirt
setblock ~38 ~106 ~96 dirt
setblock ~38 ~106 ~97 dirt
setblock ~38 ~106 ~98 dirt
setblock ~38 ~106 ~99 dirt
setblock ~38 ~106 ~100 dirt
setblock ~38 ~106 ~101 dirt
setblock ~38 ~106 ~102 dirt
setblock ~38 ~106 ~103 dirt
setblock ~38 ~106 ~104 dirt
setblock ~38 ~107 ~86 dirt
setblock ~38 ~107 ~87 dirt
setblock ~38 ~107 ~88 dirt
setblock ~38 ~107 ~89 dirt
setblock ~38 ~107 ~90 dirt
setblock ~38 ~107 ~91 dirt
setblock ~38 ~107 ~92 dirt
setblock ~38 ~107 ~93 dirt
setblock ~38 ~107 ~94 dirt
setblock ~38 ~107 ~95 dirt
setblock ~38 ~107 ~96 dirt
setblock ~38 ~107 ~97 dirt
setblock ~38 ~107 ~98 dirt
setblock ~38 ~107 ~99 dirt
setblock ~38 ~107 ~100 dirt
setblock ~38 ~107 ~101 dirt
setblock ~38 ~107 ~102 dirt
setblock ~38 ~107 ~103 dirt
setblock ~38 ~107 ~104 dirt
setblock ~38 ~107 ~105 dirt
setblock ~38 ~108 ~86 dirt
setblock ~38 ~108 ~87 dirt
setblock ~38 ~108 ~88 dirt
setblock ~38 ~108 ~89 dirt
setblock ~38 ~108 ~90 dirt
setblock ~38 ~108 ~91 dirt
setblock ~38 ~108 ~92 dirt
setblock ~38 ~108 ~93 dirt
setblock ~38 ~108 ~94 dirt
setblock ~38 ~108 ~95 dirt
setblock ~38 ~108 ~96 dirt
setblock ~38 ~108 ~97 dirt
setblock ~38 ~108 ~98 dirt
setblock ~38 ~108 ~99 dirt
setblock ~38 ~108 ~100 dirt
setblock ~38 ~108 ~101 dirt
setblock ~38 ~108 ~102 dirt
setblock ~38 ~108 ~103 dirt
setblock ~38 ~108 ~104 dirt
setblock ~38 ~108 ~105 dirt
setblock ~38 ~109 ~79 dirt
setblock ~38 ~109 ~80 dirt
setblock ~38 ~109 ~81 dirt
setblock ~38 ~109 ~85 dirt
setblock ~38 ~109 ~86 dirt
setblock ~38 ~109 ~87 dirt
setblock ~38 ~109 ~88 dirt
setblock ~38 ~109 ~89 dirt
setblock ~38 ~109 ~90 dirt
setblock ~38 ~109 ~91 dirt
setblock ~38 ~109 ~92 dirt
setblock ~38 ~109 ~93 dirt
setblock ~38 ~109 ~94 dirt
setblock ~38 ~109 ~95 dirt
setblock ~38 ~109 ~96 dirt
setblock ~38 ~109 ~97 dirt
setblock ~38 ~109 ~98 dirt
setblock ~38 ~109 ~99 dirt
setblock ~38 ~109 ~100 dirt
setblock ~38 ~109 ~101 dirt
setblock ~38 ~109 ~102 dirt
setblock ~38 ~109 ~103 dirt
setblock ~38 ~109 ~104 dirt
setblock ~38 ~109 ~105 dirt
setblock ~38 ~109 ~106 dirt
setblock ~38 ~110 ~77 dirt
setblock ~38 ~110 ~78 dirt
setblock ~38 ~110 ~79 dirt
setblock ~38 ~110 ~80 dirt
setblock ~38 ~110 ~81 dirt
setblock ~38 ~110 ~82 dirt
setblock ~38 ~110 ~84 dirt
setblock ~38 ~110 ~85 dirt
setblock ~38 ~110 ~86 dirt
setblock ~38 ~110 ~87 dirt
setblock ~38 ~110 ~88 dirt
setblock ~38 ~110 ~89 dirt
setblock ~38 ~110 ~90 dirt
setblock ~38 ~110 ~91 dirt
setblock ~38 ~110 ~92 dirt
setblock ~38 ~110 ~93 dirt
setblock ~38 ~110 ~94 dirt
setblock ~38 ~110 ~95 dirt
setblock ~38 ~110 ~96 dirt
setblock ~38 ~110 ~97 dirt
setblock ~38 ~110 ~98 dirt
setblock ~38 ~110 ~99 dirt
setblock ~38 ~110 ~100 dirt
setblock ~38 ~110 ~101 dirt
setblock ~38 ~110 ~102 dirt
setblock ~38 ~110 ~103 dirt
setblock ~38 ~110 ~104 dirt
setblock ~38 ~110 ~105 dirt
setblock ~38 ~110 ~106 dirt
setblock ~38 ~111 ~76 dirt
setblock ~38 ~111 ~77 dirt
setblock ~38 ~111 ~78 dirt
setblock ~38 ~111 ~79 dirt
setblock ~38 ~111 ~80 dirt
setblock ~38 ~111 ~81 dirt
setblock ~38 ~111 ~82 dirt
setblock ~38 ~111 ~83 dirt
setblock ~38 ~111 ~84 dirt
setblock ~38 ~111 ~85 dirt
setblock ~38 ~111 ~86 dirt
setblock ~38 ~111 ~87 dirt
setblock ~38 ~111 ~88 dirt
setblock ~38 ~111 ~89 dirt
setblock ~38 ~111 ~90 dirt
setblock ~38 ~111 ~91 dirt
setblock ~38 ~111 ~92 dirt
setblock ~38 ~111 ~93 dirt
setblock ~38 ~111 ~94 dirt
setblock ~38 ~111 ~95 dirt
setblock ~38 ~111 ~96 dirt
setblock ~38 ~111 ~97 dirt
setblock ~38 ~111 ~98 dirt
setblock ~38 ~111 ~99 dirt
setblock ~38 ~111 ~100 dirt
setblock ~38 ~111 ~101 dirt
setblock ~38 ~111 ~102 dirt
setblock ~38 ~111 ~103 dirt
setblock ~38 ~111 ~104 dirt
setblock ~38 ~111 ~105 dirt
setblock ~38 ~111 ~106 dirt
setblock ~38 ~112 ~76 dirt
setblock ~38 ~112 ~77 dirt
setblock ~38 ~112 ~78 dirt
setblock ~38 ~112 ~79 dirt
setblock ~38 ~112 ~80 dirt
setblock ~38 ~112 ~81 dirt
setblock ~38 ~112 ~82 dirt
setblock ~38 ~112 ~83 dirt
setblock ~38 ~112 ~84 dirt
setblock ~38 ~112 ~85 dirt
setblock ~38 ~112 ~86 dirt
setblock ~38 ~112 ~87 dirt
setblock ~38 ~112 ~88 dirt
setblock ~38 ~112 ~89 dirt
setblock ~38 ~112 ~90 dirt
setblock ~38 ~112 ~91 dirt
setblock ~38 ~112 ~92 dirt
setblock ~38 ~112 ~93 dirt
setblock ~38 ~112 ~94 dirt
setblock ~38 ~112 ~95 dirt
setblock ~38 ~112 ~96 dirt
setblock ~38 ~112 ~97 dirt
setblock ~38 ~112 ~98 dirt
setblock ~38 ~112 ~99 dirt
setblock ~38 ~112 ~100 dirt
setblock ~38 ~112 ~101 dirt
setblock ~38 ~112 ~102 dirt
setblock ~38 ~112 ~103 dirt
setblock ~38 ~112 ~104 dirt
setblock ~38 ~112 ~105 dirt
setblock ~38 ~112 ~106 dirt
setblock ~38 ~112 ~107 dirt
setblock ~38 ~113 ~75 dirt
setblock ~38 ~113 ~76 dirt
setblock ~38 ~113 ~77 dirt
setblock ~38 ~113 ~78 dirt
setblock ~38 ~113 ~79 dirt
setblock ~38 ~113 ~80 dirt
setblock ~38 ~113 ~81 dirt
setblock ~38 ~113 ~82 dirt
setblock ~38 ~113 ~83 dirt
setblock ~38 ~113 ~84 dirt
setblock ~38 ~113 ~85 dirt
setblock ~38 ~113 ~86 dirt
setblock ~38 ~113 ~87 dirt
setblock ~38 ~113 ~88 dirt
setblock ~38 ~113 ~89 dirt
setblock ~38 ~113 ~90 dirt
setblock ~38 ~113 ~91 dirt
setblock ~38 ~113 ~92 dirt
setblock ~38 ~113 ~93 dirt
setblock ~38 ~113 ~94 dirt
setblock ~38 ~113 ~95 dirt
setblock ~38 ~113 ~96 dirt
setblock ~38 ~113 ~97 dirt
setblock ~38 ~113 ~98 dirt
setblock ~38 ~113 ~99 dirt
setblock ~38 ~113 ~100 dirt
setblock ~38 ~113 ~101 dirt
setblock ~38 ~113 ~102 dirt
setblock ~38 ~113 ~103 dirt
setblock ~38 ~113 ~104 dirt
setblock ~38 ~113 ~105 dirt
setblock ~38 ~113 ~106 dirt
setblock ~38 ~113 ~107 dirt
setblock ~38 ~114 ~75 dirt
setblock ~38 ~114 ~76 dirt
setblock ~38 ~114 ~77 dirt
setblock ~38 ~114 ~78 dirt
setblock ~38 ~114 ~79 dirt
setblock ~38 ~114 ~80 dirt
setblock ~38 ~114 ~81 dirt
setblock ~38 ~114 ~82 dirt
setblock ~38 ~114 ~83 dirt
setblock ~38 ~114 ~84 dirt
setblock ~38 ~114 ~85 dirt
setblock ~38 ~114 ~86 dirt
setblock ~38 ~114 ~87 dirt
setblock ~38 ~114 ~88 dirt
setblock ~38 ~114 ~89 dirt
setblock ~38 ~114 ~90 dirt
setblock ~38 ~114 ~91 dirt
setblock ~38 ~114 ~92 dirt
setblock ~38 ~114 ~93 dirt
setblock ~38 ~114 ~94 dirt
setblock ~38 ~114 ~95 dirt
setblock ~38 ~114 ~96 dirt
setblock ~38 ~114 ~97 dirt
setblock ~38 ~114 ~98 dirt
setblock ~38 ~114 ~99 dirt
setblock ~38 ~114 ~100 dirt
setblock ~38 ~114 ~101 dirt
setblock ~38 ~114 ~102 dirt
setblock ~38 ~114 ~103 dirt
setblock ~38 ~114 ~104 dirt
setblock ~38 ~114 ~105 dirt
setblock ~38 ~114 ~106 dirt
setblock ~38 ~114 ~107 dirt
setblock ~38 ~114 ~108 dirt
setblock ~38 ~115 ~74 dirt
setblock ~38 ~115 ~75 dirt
setblock ~38 ~115 ~76 dirt
setblock ~38 ~115 ~77 dirt
setblock ~38 ~115 ~78 dirt
setblock ~38 ~115 ~79 dirt
setblock ~38 ~115 ~80 dirt
setblock ~38 ~115 ~81 dirt
setblock ~38 ~115 ~82 dirt
setblock ~38 ~115 ~83 dirt
setblock ~38 ~115 ~84 dirt
setblock ~38 ~115 ~85 dirt
setblock ~38 ~115 ~86 dirt
setblock ~38 ~115 ~87 dirt
setblock ~38 ~115 ~88 dirt
setblock ~38 ~115 ~89 dirt
setblock ~38 ~115 ~90 dirt
setblock ~38 ~115 ~91 dirt
setblock ~38 ~115 ~92 dirt
setblock ~38 ~115 ~93 dirt
setblock ~38 ~115 ~94 dirt
setblock ~38 ~115 ~95 dirt
setblock ~38 ~115 ~96 dirt
setblock ~38 ~115 ~97 dirt
setblock ~38 ~115 ~98 dirt
setblock ~38 ~115 ~99 dirt
setblock ~38 ~115 ~100 dirt
setblock ~38 ~115 ~101 dirt
setblock ~38 ~115 ~102 dirt
setblock ~38 ~115 ~103 dirt
setblock ~38 ~115 ~104 dirt
setblock ~38 ~115 ~105 dirt
setblock ~38 ~115 ~106 dirt
setblock ~38 ~115 ~107 dirt
setblock ~38 ~115 ~108 dirt
setblock ~38 ~115 ~109 dirt
setblock ~38 ~116 ~73 dirt
setblock ~38 ~116 ~74 dirt
setblock ~38 ~116 ~75 dirt
setblock ~38 ~116 ~76 dirt
setblock ~38 ~116 ~77 dirt
setblock ~38 ~116 ~78 dirt
setblock ~38 ~116 ~79 dirt
setblock ~38 ~116 ~80 dirt
setblock ~38 ~116 ~81 dirt
setblock ~38 ~116 ~82 dirt
setblock ~38 ~116 ~83 dirt
setblock ~38 ~116 ~84 dirt
setblock ~38 ~116 ~85 dirt
setblock ~38 ~116 ~86 dirt
setblock ~38 ~116 ~87 dirt
setblock ~38 ~116 ~88 dirt
setblock ~38 ~116 ~89 dirt
setblock ~38 ~116 ~90 dirt
setblock ~38 ~116 ~91 dirt
setblock ~38 ~116 ~92 dirt
setblock ~38 ~116 ~93 dirt
setblock ~38 ~116 ~94 dirt
setblock ~38 ~116 ~95 dirt
setblock ~38 ~116 ~96 dirt
setblock ~38 ~116 ~97 dirt
setblock ~38 ~116 ~98 dirt
setblock ~38 ~116 ~99 dirt
setblock ~38 ~116 ~100 dirt
setblock ~38 ~116 ~101 dirt
setblock ~38 ~116 ~102 dirt
setblock ~38 ~116 ~103 dirt
setblock ~38 ~116 ~104 dirt
setblock ~38 ~116 ~105 dirt
setblock ~38 ~116 ~106 dirt
setblock ~38 ~116 ~107 dirt
setblock ~38 ~116 ~108 dirt
setblock ~38 ~116 ~109 dirt
setblock ~38 ~117 ~73 dirt
setblock ~38 ~117 ~74 dirt
setblock ~38 ~117 ~75 dirt
setblock ~38 ~117 ~76 dirt
setblock ~38 ~117 ~77 dirt
setblock ~38 ~117 ~78 dirt
setblock ~38 ~117 ~79 dirt
setblock ~38 ~117 ~80 dirt
setblock ~38 ~117 ~81 dirt
setblock ~38 ~117 ~82 dirt
setblock ~38 ~117 ~83 dirt
setblock ~38 ~117 ~84 dirt
setblock ~38 ~117 ~85 dirt
setblock ~38 ~117 ~86 dirt
setblock ~38 ~117 ~87 dirt
setblock ~38 ~117 ~88 dirt
setblock ~38 ~117 ~89 dirt
setblock ~38 ~117 ~90 dirt
setblock ~38 ~117 ~91 dirt
setblock ~38 ~117 ~92 dirt
setblock ~38 ~117 ~93 dirt
setblock ~38 ~117 ~94 dirt
setblock ~38 ~117 ~95 dirt
setblock ~38 ~117 ~96 dirt
setblock ~38 ~117 ~97 dirt
setblock ~38 ~117 ~98 dirt
setblock ~38 ~117 ~99 dirt
setblock ~38 ~117 ~100 dirt
setblock ~38 ~117 ~101 dirt
setblock ~38 ~117 ~102 dirt
setblock ~38 ~117 ~103 dirt
setblock ~38 ~117 ~104 dirt
setblock ~38 ~117 ~105 dirt
setblock ~38 ~117 ~106 dirt
setblock ~38 ~117 ~107 dirt
setblock ~38 ~117 ~108 dirt
setblock ~38 ~117 ~109 dirt
setblock ~38 ~118 ~72 dirt
setblock ~38 ~118 ~73 dirt
setblock ~38 ~118 ~74 dirt
setblock ~38 ~118 ~75 dirt
setblock ~38 ~118 ~76 dirt
setblock ~38 ~118 ~77 dirt
setblock ~38 ~118 ~78 dirt
setblock ~38 ~118 ~79 dirt
setblock ~38 ~118 ~80 dirt
setblock ~38 ~118 ~81 dirt
setblock ~38 ~118 ~82 dirt
setblock ~38 ~118 ~83 dirt
setblock ~38 ~118 ~84 dirt
setblock ~38 ~118 ~85 dirt
setblock ~38 ~118 ~86 dirt
setblock ~38 ~118 ~87 dirt
setblock ~38 ~118 ~88 dirt
setblock ~38 ~118 ~89 dirt
setblock ~38 ~118 ~90 dirt
setblock ~38 ~118 ~91 dirt
setblock ~38 ~118 ~92 dirt
setblock ~38 ~118 ~93 dirt
setblock ~38 ~118 ~94 dirt
setblock ~38 ~118 ~95 dirt
setblock ~38 ~118 ~96 dirt
setblock ~38 ~118 ~97 dirt
setblock ~38 ~118 ~98 dirt
setblock ~38 ~118 ~99 dirt
setblock ~38 ~118 ~100 dirt
setblock ~38 ~118 ~101 dirt
setblock ~38 ~118 ~102 dirt
setblock ~38 ~118 ~103 dirt
setblock ~38 ~118 ~104 dirt
setblock ~38 ~118 ~105 dirt
setblock ~38 ~118 ~106 dirt
setblock ~38 ~118 ~107 dirt
setblock ~38 ~118 ~108 dirt
setblock ~38 ~118 ~109 dirt
setblock ~38 ~119 ~72 dirt
setblock ~38 ~119 ~73 dirt
setblock ~38 ~119 ~74 dirt
setblock ~38 ~119 ~75 dirt
setblock ~38 ~119 ~76 dirt
setblock ~38 ~119 ~77 dirt
setblock ~38 ~119 ~78 dirt
setblock ~38 ~119 ~79 dirt
setblock ~38 ~119 ~80 dirt
setblock ~38 ~119 ~81 dirt
setblock ~38 ~119 ~82 dirt
setblock ~38 ~119 ~83 dirt
setblock ~38 ~119 ~84 dirt
setblock ~38 ~119 ~85 dirt
setblock ~38 ~119 ~86 dirt
setblock ~38 ~119 ~87 dirt
setblock ~38 ~119 ~88 dirt
setblock ~38 ~119 ~89 dirt
setblock ~38 ~119 ~90 dirt
setblock ~38 ~119 ~91 dirt
setblock ~38 ~119 ~92 dirt
setblock ~38 ~119 ~93 dirt
setblock ~38 ~119 ~94 dirt
setblock ~38 ~119 ~95 dirt
setblock ~38 ~119 ~96 dirt
setblock ~38 ~119 ~97 dirt
setblock ~38 ~119 ~98 dirt
setblock ~38 ~119 ~99 dirt
setblock ~38 ~119 ~100 dirt
setblock ~38 ~119 ~101 dirt
setblock ~38 ~119 ~102 dirt
setblock ~38 ~119 ~103 dirt
setblock ~38 ~119 ~104 dirt
setblock ~38 ~119 ~105 dirt
setblock ~38 ~119 ~106 dirt
setblock ~38 ~119 ~107 dirt
setblock ~38 ~119 ~108 dirt
setblock ~38 ~119 ~109 dirt
setblock ~38 ~119 ~110 dirt
setblock ~38 ~120 ~71 dirt
setblock ~38 ~120 ~72 dirt
setblock ~38 ~120 ~73 dirt
setblock ~38 ~120 ~74 dirt
setblock ~38 ~120 ~75 dirt
setblock ~38 ~120 ~76 dirt
setblock ~38 ~120 ~77 dirt
setblock ~38 ~120 ~78 dirt
setblock ~38 ~120 ~79 dirt
setblock ~38 ~120 ~80 dirt
setblock ~38 ~120 ~81 dirt
setblock ~38 ~120 ~82 dirt
setblock ~38 ~120 ~83 dirt
setblock ~38 ~120 ~84 dirt
setblock ~38 ~120 ~85 dirt
setblock ~38 ~120 ~86 dirt
setblock ~38 ~120 ~87 dirt
setblock ~38 ~120 ~88 dirt
setblock ~38 ~120 ~89 dirt
setblock ~38 ~120 ~90 dirt
setblock ~38 ~120 ~91 dirt
setblock ~38 ~120 ~92 dirt
setblock ~38 ~120 ~93 dirt
setblock ~38 ~120 ~94 dirt
setblock ~38 ~120 ~95 dirt
setblock ~38 ~120 ~96 dirt
setblock ~38 ~120 ~97 dirt
setblock ~38 ~120 ~98 dirt
setblock ~38 ~120 ~99 dirt
setblock ~38 ~120 ~100 dirt
setblock ~38 ~120 ~101 dirt
setblock ~38 ~120 ~102 dirt
setblock ~38 ~120 ~103 dirt
setblock ~38 ~120 ~104 dirt
setblock ~38 ~120 ~105 dirt
setblock ~38 ~120 ~106 dirt
setblock ~38 ~120 ~107 dirt
setblock ~38 ~120 ~108 dirt
setblock ~38 ~120 ~109 dirt
setblock ~38 ~120 ~110 dirt
setblock ~38 ~121 ~71 dirt
setblock ~38 ~121 ~72 dirt
setblock ~38 ~121 ~73 dirt
setblock ~38 ~121 ~74 dirt
setblock ~38 ~121 ~75 dirt
setblock ~38 ~121 ~76 dirt
setblock ~38 ~121 ~77 dirt
setblock ~38 ~121 ~78 dirt
setblock ~38 ~121 ~79 dirt
setblock ~38 ~121 ~80 dirt
setblock ~38 ~121 ~81 dirt
setblock ~38 ~121 ~82 dirt
setblock ~38 ~121 ~83 dirt
setblock ~38 ~121 ~84 dirt
setblock ~38 ~121 ~85 dirt
setblock ~38 ~121 ~86 dirt
setblock ~38 ~121 ~87 dirt
setblock ~38 ~121 ~88 dirt
setblock ~38 ~121 ~89 dirt
setblock ~38 ~121 ~90 dirt
setblock ~38 ~121 ~91 dirt
setblock ~38 ~121 ~92 dirt
setblock ~38 ~121 ~93 dirt
setblock ~38 ~121 ~94 dirt
setblock ~38 ~121 ~95 dirt
setblock ~38 ~121 ~96 dirt
setblock ~38 ~121 ~97 dirt
setblock ~38 ~121 ~98 dirt
setblock ~38 ~121 ~99 dirt
setblock ~38 ~121 ~100 dirt
setblock ~38 ~121 ~101 dirt
setblock ~38 ~121 ~102 dirt
setblock ~38 ~121 ~103 dirt
setblock ~38 ~121 ~104 dirt
setblock ~38 ~121 ~105 dirt
setblock ~38 ~121 ~106 dirt
setblock ~38 ~121 ~107 dirt
setblock ~38 ~121 ~108 dirt
setblock ~38 ~121 ~109 dirt
setblock ~38 ~121 ~110 dirt
setblock ~38 ~121 ~111 dirt
setblock ~38 ~122 ~71 dirt
setblock ~38 ~122 ~72 dirt
setblock ~38 ~122 ~73 dirt
setblock ~38 ~122 ~74 dirt
setblock ~38 ~122 ~75 dirt
setblock ~38 ~122 ~76 dirt
setblock ~38 ~122 ~77 dirt
setblock ~38 ~122 ~78 dirt
setblock ~38 ~122 ~79 dirt
setblock ~38 ~122 ~80 dirt
setblock ~38 ~122 ~81 dirt
setblock ~38 ~122 ~82 dirt
setblock ~38 ~122 ~83 dirt
setblock ~38 ~122 ~84 dirt
setblock ~38 ~122 ~85 dirt
setblock ~38 ~122 ~86 dirt
setblock ~38 ~122 ~87 dirt
setblock ~38 ~122 ~88 dirt
setblock ~38 ~122 ~89 dirt
setblock ~38 ~122 ~90 dirt
setblock ~38 ~122 ~91 dirt
setblock ~38 ~122 ~92 dirt
setblock ~38 ~122 ~93 dirt
setblock ~38 ~122 ~94 dirt
setblock ~38 ~122 ~95 dirt
setblock ~38 ~122 ~96 dirt
setblock ~38 ~122 ~97 dirt
setblock ~38 ~122 ~98 dirt
setblock ~38 ~122 ~99 dirt
setblock ~38 ~122 ~100 dirt
setblock ~38 ~122 ~101 dirt
setblock ~38 ~122 ~102 dirt
setblock ~38 ~122 ~103 dirt
setblock ~38 ~122 ~104 dirt
setblock ~38 ~122 ~105 dirt
setblock ~38 ~122 ~106 dirt
setblock ~38 ~122 ~107 dirt
setblock ~38 ~122 ~108 dirt
setblock ~38 ~122 ~109 dirt
setblock ~38 ~122 ~110 dirt
setblock ~38 ~122 ~111 dirt
setblock ~38 ~123 ~71 dirt
setblock ~38 ~123 ~72 dirt
setblock ~38 ~123 ~73 dirt
setblock ~38 ~123 ~74 dirt
setblock ~38 ~123 ~75 dirt
setblock ~38 ~123 ~76 dirt
setblock ~38 ~123 ~77 dirt
setblock ~38 ~123 ~78 dirt
setblock ~38 ~123 ~79 dirt
setblock ~38 ~123 ~80 dirt
setblock ~38 ~123 ~81 dirt
setblock ~38 ~123 ~82 dirt
setblock ~38 ~123 ~83 dirt
setblock ~38 ~123 ~84 dirt
setblock ~38 ~123 ~85 dirt
setblock ~38 ~123 ~86 dirt
setblock ~38 ~123 ~87 dirt
setblock ~38 ~123 ~88 dirt
setblock ~38 ~123 ~89 dirt
setblock ~38 ~123 ~90 dirt
setblock ~38 ~123 ~91 dirt
setblock ~38 ~123 ~92 dirt
setblock ~38 ~123 ~93 dirt
setblock ~38 ~123 ~94 dirt
setblock ~38 ~123 ~95 dirt
setblock ~38 ~123 ~96 dirt
setblock ~38 ~123 ~97 dirt
setblock ~38 ~123 ~98 dirt
setblock ~38 ~123 ~99 dirt
setblock ~38 ~123 ~100 dirt
setblock ~38 ~123 ~101 dirt
setblock ~38 ~123 ~102 dirt
setblock ~38 ~123 ~103 dirt
setblock ~38 ~123 ~104 dirt
setblock ~38 ~123 ~105 dirt
setblock ~38 ~123 ~106 dirt
setblock ~38 ~123 ~107 dirt
setblock ~38 ~123 ~108 dirt
setblock ~38 ~123 ~109 dirt
setblock ~38 ~123 ~110 dirt
setblock ~38 ~123 ~111 dirt
setblock ~38 ~124 ~71 grass_block
setblock ~38 ~124 ~72 dirt
setblock ~38 ~124 ~73 dirt
setblock ~38 ~124 ~74 dirt
setblock ~38 ~124 ~75 dirt
setblock ~38 ~124 ~76 dirt
setblock ~38 ~124 ~77 dirt
setblock ~38 ~124 ~78 dirt
setblock ~38 ~124 ~79 dirt
setblock ~38 ~124 ~80 dirt
setblock ~38 ~124 ~81 dirt
setblock ~38 ~124 ~82 dirt
setblock ~38 ~124 ~83 dirt
setblock ~38 ~124 ~84 dirt
setblock ~38 ~124 ~85 dirt
setblock ~38 ~124 ~86 dirt
setblock ~38 ~124 ~87 dirt
setblock ~38 ~124 ~88 dirt
setblock ~38 ~124 ~89 dirt
setblock ~38 ~124 ~90 dirt
setblock ~38 ~124 ~91 dirt
setblock ~38 ~124 ~92 dirt
setblock ~38 ~124 ~93 dirt
setblock ~38 ~124 ~94 dirt
setblock ~38 ~124 ~95 dirt
setblock ~38 ~124 ~96 dirt
setblock ~38 ~124 ~97 dirt
setblock ~38 ~124 ~98 dirt
setblock ~38 ~124 ~99 dirt
setblock ~38 ~124 ~100 dirt
setblock ~38 ~124 ~101 dirt
setblock ~38 ~124 ~102 dirt
setblock ~38 ~124 ~103 dirt
setblock ~38 ~124 ~104 dirt
setblock ~38 ~124 ~105 dirt
setblock ~38 ~124 ~106 dirt
setblock ~38 ~124 ~107 dirt
setblock ~38 ~124 ~108 dirt
setblock ~38 ~124 ~109 dirt
setblock ~38 ~124 ~110 grass_block
setblock ~38 ~124 ~111 dirt
setblock ~38 ~125 ~72 grass_block
setblock ~38 ~125 ~73 grass_block
setblock ~38 ~125 ~74 dirt
setblock ~38 ~125 ~75 dirt
setblock ~38 ~125 ~76 dirt
setblock ~38 ~125 ~77 dirt
setblock ~38 ~125 ~78 dirt
setblock ~38 ~125 ~79 dirt
setblock ~38 ~125 ~80 dirt
setblock ~38 ~125 ~81 dirt
setblock ~38 ~125 ~82 dirt
setblock ~38 ~125 ~83 dirt
setblock ~38 ~125 ~84 dirt
setblock ~38 ~125 ~85 dirt
setblock ~38 ~125 ~86 dirt
setblock ~38 ~125 ~87 dirt
setblock ~38 ~125 ~88 dirt
setblock ~38 ~125 ~89 dirt
setblock ~38 ~125 ~90 grass_block
setblock ~38 ~125 ~91 grass_block
setblock ~38 ~125 ~92 grass_block
setblock ~38 ~125 ~93 grass_block
setblock ~38 ~125 ~94 grass_block
setblock ~38 ~125 ~95 grass_block
setblock ~38 ~125 ~96 grass_block
setblock ~38 ~125 ~97 grass_block
setblock ~38 ~125 ~98 grass_block
setblock ~38 ~125 ~99 grass_block
setblock ~38 ~125 ~100 grass_block
setblock ~38 ~125 ~101 grass_block
setblock ~38 ~125 ~102 grass_block
setblock ~38 ~125 ~103 grass_block
setblock ~38 ~125 ~104 grass_block
setblock ~38 ~125 ~105 grass_block
setblock ~38 ~125 ~106 grass_block
setblock ~38 ~125 ~107 grass_block
setblock ~38 ~125 ~108 grass_block
setblock ~38 ~125 ~109 grass_block
setblock ~38 ~125 ~111 grass_block
setblock ~38 ~126 ~72 short_grass
setblock ~38 ~126 ~74 grass_block
setblock ~38 ~126 ~75 grass_block
setblock ~38 ~126 ~76 dirt
setblock ~38 ~126 ~77 dirt
setblock ~38 ~126 ~78 dirt
setblock ~38 ~126 ~79 dirt
setblock ~38 ~126 ~80 dirt
setblock ~38 ~126 ~81 dirt
setblock ~38 ~126 ~82 dirt
setblock ~38 ~126 ~83 dirt
setblock ~38 ~126 ~84 dirt
setblock ~38 ~126 ~85 dirt
setblock ~38 ~126 ~86 grass_block
setblock ~38 ~126 ~87 grass_block
setblock ~38 ~126 ~88 grass_block
setblock ~38 ~126 ~89 grass_block
setblock ~38 ~126 ~91 short_grass
setblock ~38 ~127 ~76 grass_block
setblock ~38 ~127 ~77 grass_block
setblock ~38 ~127 ~78 dirt
setblock ~38 ~127 ~79 dirt
setblock ~38 ~127 ~80 dirt
setblock ~38 ~127 ~81 dirt
setblock ~38 ~127 ~82 dirt
setblock ~38 ~127 ~83 grass_block
setblock ~38 ~127 ~84 grass_block
setblock ~38 ~127 ~85 grass_block
setblock ~38 ~128 ~78 grass_block
setblock ~38 ~128 ~79 grass_block
setblock ~38 ~128 ~80 dirt
setblock ~38 ~128 ~81 grass_block
setblock ~38 ~128 ~82 grass_block
setblock ~38 ~128 ~84 poppy
setblock ~38 ~129 ~79 short_grass
setblock ~38 ~129 ~80 grass_block
setblock ~39 ~98 ~93 dirt
setblock ~39 ~99 ~93 dirt
setblock ~39 ~100 ~92 dirt
setblock ~39 ~100 ~93 dirt
setblock ~39 ~100 ~94 dirt
setblock ~39 ~100 ~103 dirt
setblock ~39 ~101 ~91 dirt
setblock ~39 ~101 ~92 dirt
setblock ~39 ~101 ~93 dirt
setblock ~39 ~101 ~94 dirt
setblock ~39 ~101 ~95 dirt
setblock ~39 ~101 ~102 dirt
setblock ~39 ~101 ~103 dirt
setblock ~39 ~102 ~90 dirt
setblock ~39 ~102 ~91 dirt
setblock ~39 ~102 ~92 dirt
setblock ~39 ~102 ~93 dirt
setblock ~39 ~102 ~94 dirt
setblock ~39 ~102 ~95 dirt
setblock ~39 ~102 ~96 dirt
setblock ~39 ~102 ~98 dirt
setblock ~39 ~102 ~101 dirt
setblock ~39 ~102 ~102 dirt
setblock ~39 ~102 ~103 dirt
setblock ~39 ~102 ~104 dirt
setblock ~39 ~103 ~89 dirt
setblock ~39 ~103 ~90 dirt
setblock ~39 ~103 ~91 dirt
setblock ~39 ~103 ~92 dirt
setblock ~39 ~103 ~93 dirt
setblock ~39 ~103 ~94 dirt
setblock ~39 ~103 ~95 dirt
setblock ~39 ~103 ~96 dirt
setblock ~39 ~103 ~97 dirt
setblock ~39 ~103 ~98 dirt
setblock ~39 ~103 ~101 dirt
setblock ~39 ~103 ~102 dirt
setblock ~39 ~103 ~103 dirt
setblock ~39 ~103 ~104 dirt
setblock ~39 ~104 ~88 dirt
setblock ~39 ~104 ~89 dirt
setblock ~39 ~104 ~90 dirt
setblock ~39 ~104 ~91 dirt
setblock ~39 ~104 ~92 dirt
setblock ~39 ~104 ~93 dirt
setblock ~39 ~104 ~94 dirt
setblock ~39 ~104 ~95 dirt
setblock ~39 ~104 ~96 dirt
setblock ~39 ~104 ~97 dirt
setblock ~39 ~104 ~98 dirt
setblock ~39 ~104 ~99 dirt
setblock ~39 ~104 ~101 dirt
setblock ~39 ~104 ~102 dirt
setblock ~39 ~104 ~103 dirt
setblock ~39 ~104 ~104 dirt
setblock ~39 ~105 ~87 dirt
setblock ~39 ~105 ~88 dirt
setblock ~39 ~105 ~89 dirt
setblock ~39 ~105 ~90 dirt
setblock ~39 ~105 ~91 dirt
setblock ~39 ~105 ~92 dirt
setblock ~39 ~105 ~93 dirt
setblock ~39 ~105 ~94 dirt
setblock ~39 ~105 ~95 dirt
setblock ~39 ~105 ~96 dirt
setblock ~39 ~105 ~97 dirt
setblock ~39 ~105 ~98 dirt
setblock ~39 ~105 ~99 dirt
setblock ~39 ~105 ~100 dirt
setblock ~39 ~105 ~101 dirt
setblock ~39 ~105 ~102 dirt
setblock ~39 ~105 ~103 dirt
setblock ~39 ~105 ~104 dirt
setblock ~39 ~105 ~105 dirt
setblock ~39 ~106 ~79 dirt
setblock ~39 ~106 ~80 dirt
setblock ~39 ~106 ~86 dirt
setblock ~39 ~106 ~87 dirt
setblock ~39 ~106 ~88 dirt
setblock ~39 ~106 ~89 dirt
setblock ~39 ~106 ~90 dirt
setblock ~39 ~106 ~91 dirt
setblock ~39 ~106 ~92 dirt
setblock ~39 ~106 ~93 dirt
setblock ~39 ~106 ~94 dirt
setblock ~39 ~106 ~95 dirt
setblock ~39 ~106 ~96 dirt
setblock ~39 ~106 ~97 dirt
setblock ~39 ~106 ~98 dirt
setblock ~39 ~106 ~99 dirt
setblock ~39 ~106 ~100 dirt
setblock ~39 ~106 ~101 dirt
setblock ~39 ~106 ~102 dirt
setblock ~39 ~106 ~103 dirt
setblock ~39 ~106 ~104 dirt
setblock ~39 ~106 ~105 dirt
setblock ~39 ~107 ~79 dirt
setblock ~39 ~107 ~80 dirt
setblock ~39 ~107 ~81 dirt
setblock ~39 ~107 ~85 dirt
setblock ~39 ~107 ~86 dirt
setblock ~39 ~107 ~87 dirt
setblock ~39 ~107 ~88 dirt
setblock ~39 ~107 ~89 dirt
setblock ~39 ~107 ~90 dirt
setblock ~39 ~107 ~91 dirt
setblock ~39 ~107 ~92 dirt
setblock ~39 ~107 ~93 dirt
setblock ~39 ~107 ~94 dirt
setblock ~39 ~107 ~95 dirt
setblock ~39 ~107 ~96 dirt
setblock ~39 ~107 ~97 dirt
setblock ~39 ~107 ~98 dirt
setblock ~39 ~107 ~99 dirt
setblock ~39 ~107 ~100 dirt
setblock ~39 ~107 ~101 dirt
setblock ~39 ~107 ~102 dirt
setblock ~39 ~107 ~103 dirt
setblock ~39 ~107 ~104 dirt
setblock ~39 ~107 ~105 dirt
setblock ~39 ~107 ~106 dirt
setblock ~39 ~108 ~79 dirt
setblock ~39 ~108 ~80 dirt
setblock ~39 ~108 ~81 dirt
setblock ~39 ~108 ~85 dirt
setblock ~39 ~108 ~86 dirt
setblock ~39 ~108 ~87 dirt
setblock ~39 ~108 ~88 dirt
setblock ~39 ~108 ~89 dirt
setblock ~39 ~108 ~90 dirt
setblock ~39 ~108 ~91 dirt
