setblock ~175 ~115 ~97 dirt
setblock ~175 ~115 ~98 dirt
setblock ~175 ~116 ~93 dirt
setblock ~175 ~116 ~94 dirt
setblock ~175 ~116 ~95 dirt
setblock ~175 ~116 ~96 dirt
setblock ~175 ~116 ~97 dirt
setblock ~175 ~116 ~98 dirt
setblock ~175 ~116 ~99 dirt
setblock ~175 ~117 ~92 dirt
setblock ~175 ~117 ~93 dirt
setblock ~175 ~117 ~94 dirt
setblock ~175 ~117 ~95 dirt
setblock ~175 ~117 ~96 dirt
setblock ~175 ~117 ~97 dirt
setblock ~175 ~117 ~98 dirt
setblock ~175 ~117 ~99 dirt
setblock ~175 ~117 ~100 dirt
setblock ~175 ~117 ~102 dirt
setblock ~175 ~118 ~92 dirt
setblock ~175 ~118 ~93 dirt
setblock ~175 ~118 ~94 dirt
setblock ~175 ~118 ~95 dirt
setblock ~175 ~118 ~96 dirt
setblock ~175 ~118 ~97 dirt
setblock ~175 ~118 ~98 dirt
setblock ~175 ~118 ~99 dirt
setblock ~175 ~118 ~100 dirt
setblock ~175 ~118 ~102 dirt
setblock ~175 ~119 ~91 dirt
setblock ~175 ~119 ~92 dirt
setblock ~175 ~119 ~93 dirt
setblock ~175 ~119 ~94 dirt
setblock ~175 ~119 ~95 dirt
setblock ~175 ~119 ~96 dirt
setblock ~175 ~119 ~97 dirt
setblock ~175 ~119 ~98 dirt
setblock ~175 ~119 ~99 dirt
setblock ~175 ~119 ~100 dirt
setblock ~175 ~119 ~101 dirt
setblock ~175 ~119 ~102 dirt
setblock ~175 ~120 ~90 dirt
setblock ~175 ~120 ~91 dirt
setblock ~175 ~120 ~92 dirt
setblock ~175 ~120 ~93 dirt
setblock ~175 ~120 ~94 dirt
setblock ~175 ~120 ~95 dirt
setblock ~175 ~120 ~96 dirt
setblock ~175 ~120 ~97 dirt
setblock ~175 ~120 ~98 dirt
setblock ~175 ~120 ~99 dirt
setblock ~175 ~120 ~100 dirt
setblock ~175 ~120 ~101 dirt
setblock ~175 ~120 ~102 dirt
setblock ~175 ~120 ~103 dirt
setblock ~175 ~120 ~105 dirt
setblock ~175 ~121 ~90 dirt
setblock ~175 ~121 ~91 dirt
setblock ~175 ~121 ~92 dirt
setblock ~175 ~121 ~93 dirt
setblock ~175 ~121 ~94 dirt
setblock ~175 ~121 ~95 dirt
setblock ~175 ~121 ~96 dirt
setblock ~175 ~121 ~97 dirt
setblock ~175 ~121 ~98 dirt
setblock ~175 ~121 ~99 dirt
setblock ~175 ~121 ~100 dirt
setblock ~175 ~121 ~101 dirt
setblock ~175 ~121 ~102 dirt
setblock ~175 ~121 ~103 dirt
setblock ~175 ~121 ~104 dirt
setblock ~175 ~121 ~105 dirt
setblock ~175 ~121 ~106 dirt
setblock ~175 ~122 ~90 dirt
setblock ~175 ~122 ~91 dirt
setblock ~175 ~122 ~92 dirt
setblock ~175 ~122 ~93 dirt
setblock ~175 ~122 ~94 dirt
setblock ~175 ~122 ~95 dirt
setblock ~175 ~122 ~96 dirt
setblock ~175 ~122 ~97 dirt
setblock ~175 ~122 ~98 dirt
setblock ~175 ~122 ~99 dirt
setblock ~175 ~122 ~100 dirt
setblock ~175 ~122 ~101 dirt
setblock ~175 ~122 ~102 dirt
setblock ~175 ~122 ~103 dirt
setblock ~175 ~122 ~104 dirt
setblock ~175 ~122 ~105 dirt
setblock ~175 ~122 ~106 dirt
setblock ~175 ~123 ~90 dirt
setblock ~175 ~123 ~91 dirt
setblock ~175 ~123 ~92 dirt
setblock ~175 ~123 ~93 dirt
setblock ~175 ~123 ~94 dirt
setblock ~175 ~123 ~95 dirt
setblock ~175 ~123 ~96 dirt
setblock ~175 ~123 ~97 dirt
setblock ~175 ~123 ~98 dirt
setblock ~175 ~123 ~99 dirt
setblock ~175 ~123 ~100 dirt
setblock ~175 ~123 ~101 dirt
setblock ~175 ~123 ~102 dirt
setblock ~175 ~123 ~103 dirt
setblock ~175 ~123 ~104 dirt
setblock ~175 ~123 ~105 dirt
setblock ~175 ~123 ~106 dirt
setblock ~175 ~124 ~90 grass_block
setblock ~175 ~124 ~91 grass_block
setblock ~175 ~124 ~92 grass_block
setblock ~175 ~124 ~93 grass_block
setblock ~175 ~124 ~94 grass_block
setblock ~175 ~124 ~95 grass_block
setblock ~175 ~124 ~96 grass_block
setblock ~175 ~124 ~97 grass_block
setblock ~175 ~124 ~98 grass_block
setblock ~175 ~124 ~99 grass_block
setblock ~175 ~124 ~100 grass_block
setblock ~175 ~124 ~101 grass_block
setblock ~175 ~124 ~102 grass_block
setblock ~175 ~124 ~103 grass_block
setblock ~175 ~124 ~104 grass_block
setblock ~175 ~124 ~105 grass_block
setblock ~175 ~124 ~106 grass_block
setblock ~175 ~125 ~95 short_grass
setblock ~175 ~125 ~97 short_grass
setblock ~175 ~125 ~100 short_grass
setblock ~175 ~125 ~102 fern
setblock ~175 ~125 ~103 fern
setblock ~175 ~131 ~105 oak_leaves[persistent=null]
setblock ~175 ~131 ~107 oak_leaves[persistent=null]
setblock ~175 ~131 ~108 oak_leaves[persistent=null]
setblock ~175 ~132 ~103 oak_leaves[persistent=null]
setblock ~175 ~132 ~104 jungle_leaves[persistent=null]
setblock ~175 ~132 ~105 oak_leaves[persistent=null]
setblock ~175 ~132 ~106 oak_leaves[persistent=null]
setblock ~175 ~132 ~107 oak_leaves[persistent=null]
setblock ~175 ~132 ~108 oak_leaves[persistent=null]
setblock ~175 ~132 ~113 oak_leaves[persistent=null]
setblock ~175 ~133 ~102 oak_leaves[persistent=null]
setblock ~175 ~133 ~103 jungle_leaves[persistent=null]
setblock ~175 ~133 ~107 oak_leaves[persistent=null]
setblock ~175 ~133 ~108 jungle_leaves[persistent=null]
setblock ~175 ~133 ~111 oak_leaves[persistent=null]
setblock ~175 ~133 ~114 oak_leaves[persistent=null]
setblock ~175 ~134 ~102 jungle_leaves[persistent=null]
setblock ~175 ~134 ~103 oak_leaves[persistent=null]
setblock ~175 ~134 ~104 oak_wood
setblock ~175 ~134 ~105 oak_leaves[persistent=null]
setblock ~175 ~134 ~108 oak_leaves[persistent=null]
setblock ~175 ~134 ~111 oak_leaves[persistent=null]
setblock ~175 ~134 ~112 oak_wood
setblock ~175 ~134 ~114 oak_leaves[persistent=null]
setblock ~175 ~135 ~102 oak_leaves[persistent=null]
setblock ~175 ~135 ~103 jungle_leaves[persistent=null]
setblock ~175 ~135 ~105 oak_leaves[persistent=null]
setblock ~175 ~135 ~106 oak_leaves[persistent=null]
setblock ~175 ~135 ~108 oak_leaves[persistent=null]
setblock ~175 ~135 ~109 oak_wood
setblock ~175 ~135 ~111 oak_leaves[persistent=null]
setblock ~175 ~135 ~112 oak_wood
setblock ~175 ~135 ~113 jungle_leaves[persistent=null]
setblock ~175 ~135 ~114 oak_leaves[persistent=null]
setblock ~175 ~136 ~102 oak_leaves[persistent=null]
setblock ~175 ~136 ~103 oak_leaves[persistent=null]
setblock ~175 ~136 ~104 oak_leaves[persistent=null]
setblock ~175 ~136 ~106 jungle_leaves[persistent=null]
setblock ~175 ~136 ~108 oak_wood
setblock ~175 ~136 ~110 jungle_leaves[persistent=null]
setblock ~175 ~136 ~111 oak_leaves[persistent=null]
setblock ~175 ~136 ~112 oak_leaves[persistent=null]
setblock ~175 ~137 ~107 jungle_leaves[persistent=null]
setblock ~175 ~137 ~108 oak_leaves[persistent=null]
setblock ~175 ~137 ~109 oak_leaves[persistent=null]
setblock ~175 ~137 ~112 oak_leaves[persistent=null]
setblock ~176 ~115 ~95 dirt
setblock ~176 ~116 ~95 dirt
setblock ~176 ~116 ~97 dirt
setblock ~176 ~116 ~98 dirt
setblock ~176 ~117 ~93 dirt
setblock ~176 ~117 ~94 dirt
setblock ~176 ~117 ~95 dirt
setblock ~176 ~117 ~96 dirt
setblock ~176 ~117 ~97 dirt
setblock ~176 ~117 ~98 dirt
setblock ~176 ~117 ~99 dirt
setblock ~176 ~118 ~93 dirt
setblock ~176 ~118 ~94 dirt
setblock ~176 ~118 ~95 dirt
setblock ~176 ~118 ~96 dirt
setblock ~176 ~118 ~97 dirt
setblock ~176 ~118 ~98 dirt
setblock ~176 ~118 ~99 dirt
setblock ~176 ~119 ~92 dirt
setblock ~176 ~119 ~93 dirt
setblock ~176 ~119 ~94 dirt
setblock ~176 ~119 ~95 dirt
setblock ~176 ~119 ~96 dirt
setblock ~176 ~119 ~97 dirt
setblock ~176 ~119 ~98 dirt
setblock ~176 ~119 ~99 dirt
setblock ~176 ~120 ~91 dirt
setblock ~176 ~120 ~92 dirt
setblock ~176 ~120 ~93 dirt
setblock ~176 ~120 ~94 dirt
setblock ~176 ~120 ~95 dirt
setblock ~176 ~120 ~96 dirt
setblock ~176 ~120 ~97 dirt
setblock ~176 ~120 ~98 dirt
setblock ~176 ~120 ~99 dirt
setblock ~176 ~120 ~100 dirt
setblock ~176 ~120 ~102 dirt
setblock ~176 ~121 ~91 dirt
setblock ~176 ~121 ~92 dirt
setblock ~176 ~121 ~93 dirt
setblock ~176 ~121 ~94 dirt
setblock ~176 ~121 ~95 dirt
setblock ~176 ~121 ~96 dirt
setblock ~176 ~121 ~97 dirt
setblock ~176 ~121 ~98 dirt
setblock ~176 ~121 ~99 dirt
setblock ~176 ~121 ~100 dirt
setblock ~176 ~121 ~101 dirt
setblock ~176 ~121 ~102 dirt
setblock ~176 ~121 ~105 dirt
setblock ~176 ~122 ~91 dirt
setblock ~176 ~122 ~92 dirt
setblock ~176 ~122 ~93 dirt
setblock ~176 ~122 ~94 dirt
setblock ~176 ~122 ~95 dirt
setblock ~176 ~122 ~96 dirt
setblock ~176 ~122 ~97 dirt
setblock ~176 ~122 ~98 dirt
setblock ~176 ~122 ~99 dirt
setblock ~176 ~122 ~100 dirt
setblock ~176 ~122 ~101 dirt
setblock ~176 ~122 ~102 dirt
setblock ~176 ~122 ~105 dirt
setblock ~176 ~123 ~91 dirt
setblock ~176 ~123 ~92 dirt
setblock ~176 ~123 ~93 dirt
setblock ~176 ~123 ~94 dirt
setblock ~176 ~123 ~95 dirt
setblock ~176 ~123 ~96 dirt
setblock ~176 ~123 ~97 dirt
setblock ~176 ~123 ~98 dirt
setblock ~176 ~123 ~99 dirt
setblock ~176 ~123 ~100 dirt
setblock ~176 ~123 ~101 dirt
setblock ~176 ~123 ~102 dirt
setblock ~176 ~123 ~105 dirt
setblock ~176 ~124 ~91 grass_block
setblock ~176 ~124 ~92 grass_block
setblock ~176 ~124 ~93 grass_block
setblock ~176 ~124 ~94 grass_block
setblock ~176 ~124 ~95 grass_block
setblock ~176 ~124 ~96 grass_block
setblock ~176 ~124 ~97 grass_block
setblock ~176 ~124 ~98 grass_block
setblock ~176 ~124 ~99 grass_block
setblock ~176 ~124 ~100 grass_block
setblock ~176 ~124 ~101 grass_block
setblock ~176 ~124 ~102 grass_block
setblock ~176 ~124 ~105 grass_block
setblock ~176 ~125 ~91 short_grass
setblock ~176 ~125 ~92 short_grass
setblock ~176 ~125 ~96 short_grass
setblock ~176 ~125 ~97 short_grass
setblock ~176 ~125 ~99 short_grass
setblock ~176 ~125 ~100 poppy
setblock ~176 ~125 ~105 short_grass
setblock ~176 ~131 ~106 jungle_leaves[persistent=null]
setblock ~176 ~131 ~108 oak_leaves[persistent=null]
setblock ~176 ~132 ~102 oak_leaves[persistent=null]
setblock ~176 ~132 ~103 oak_leaves[persistent=null]
setblock ~176 ~132 ~104 oak_leaves[persistent=null]
setblock ~176 ~132 ~106 oak_leaves[persistent=null]
setblock ~176 ~132 ~108 oak_leaves[persistent=null]
setblock ~176 ~132 ~111 oak_leaves[persistent=null]
setblock ~176 ~132 ~112 oak_leaves[persistent=null]
setblock ~176 ~132 ~113 oak_leaves[persistent=null]
setblock ~176 ~132 ~114 oak_leaves[persistent=null]
setblock ~176 ~132 ~115 oak_leaves[persistent=null]
setblock ~176 ~133 ~103 jungle_leaves[persistent=null]
setblock ~176 ~133 ~104 jungle_leaves[persistent=null]
setblock ~176 ~133 ~105 oak_leaves[persistent=null]
setblock ~176 ~133 ~107 jungle_leaves[persistent=null]
setblock ~176 ~133 ~109 oak_leaves[persistent=null]
setblock ~176 ~133 ~110 jungle_leaves[persistent=null]
setblock ~176 ~133 ~111 oak_leaves[persistent=null]
setblock ~176 ~133 ~112 jungle_leaves[persistent=null]
setblock ~176 ~133 ~113 oak_leaves[persistent=null]
setblock ~176 ~133 ~114 oak_leaves[persistent=null]
setblock ~176 ~133 ~115 oak_leaves[persistent=null]
setblock ~176 ~134 ~102 oak_leaves[persistent=null]
setblock ~176 ~134 ~103 jungle_leaves[persistent=null]
setblock ~176 ~134 ~105 jungle_leaves[persistent=null]
setblock ~176 ~134 ~106 oak_leaves[persistent=null]
setblock ~176 ~134 ~107 oak_leaves[persistent=null]
setblock ~176 ~134 ~108 oak_leaves[persistent=null]
setblock ~176 ~134 ~109 oak_leaves[persistent=null]
setblock ~176 ~134 ~110 oak_leaves[persistent=null]
setblock ~176 ~134 ~111 oak_leaves[persistent=null]
setblock ~176 ~134 ~112 jungle_leaves[persistent=null]
setblock ~176 ~134 ~113 oak_wood
setblock ~176 ~135 ~102 oak_leaves[persistent=null]
setblock ~176 ~135 ~103 oak_leaves[persistent=null]
setblock ~176 ~135 ~106 oak_leaves[persistent=null]
setblock ~176 ~135 ~108 jungle_leaves[persistent=null]
setblock ~176 ~135 ~109 oak_leaves[persistent=null]
setblock ~176 ~135 ~110 oak_leaves[persistent=null]
setblock ~176 ~135 ~112 oak_wood
setblock ~176 ~135 ~113 oak_leaves[persistent=null]
setblock ~176 ~135 ~115 oak_leaves[persistent=null]
setblock ~176 ~136 ~102 oak_leaves[persistent=null]
setblock ~176 ~136 ~103 jungle_leaves[persistent=null]
setblock ~176 ~136 ~104 oak_leaves[persistent=null]
setblock ~176 ~136 ~107 jungle_leaves[persistent=null]
setblock ~176 ~136 ~108 oak_wood
setblock ~176 ~136 ~109 oak_leaves[persistent=null]
setblock ~176 ~136 ~111 jungle_leaves[persistent=null]
setblock ~176 ~136 ~112 oak_leaves[persistent=null]
setblock ~176 ~136 ~114 oak_leaves[persistent=null]
setblock ~176 ~137 ~106 oak_leaves[persistent=null]
setblock ~176 ~137 ~108 oak_leaves[persistent=null]
setblock ~177 ~119 ~95 dirt
setblock ~177 ~119 ~96 dirt
setblock ~177 ~119 ~97 dirt
setblock ~177 ~120 ~93 dirt
setblock ~177 ~120 ~94 dirt
setblock ~177 ~120 ~95 dirt
setblock ~177 ~120 ~96 dirt
setblock ~177 ~120 ~97 dirt
setblock ~177 ~120 ~98 dirt
setblock ~177 ~120 ~99 dirt
setblock ~177 ~121 ~92 dirt
setblock ~177 ~121 ~93 dirt
setblock ~177 ~121 ~94 dirt
setblock ~177 ~121 ~95 dirt
setblock ~177 ~121 ~96 dirt
setblock ~177 ~121 ~97 dirt
setblock ~177 ~121 ~98 dirt
setblock ~177 ~121 ~99 dirt
setblock ~177 ~122 ~92 dirt
setblock ~177 ~122 ~93 dirt
setblock ~177 ~122 ~94 dirt
setblock ~177 ~122 ~95 dirt
setblock ~177 ~122 ~96 dirt
setblock ~177 ~122 ~97 dirt
setblock ~177 ~122 ~98 dirt
setblock ~177 ~122 ~99 dirt
setblock ~177 ~123 ~92 dirt
setblock ~177 ~123 ~93 dirt
setblock ~177 ~123 ~94 dirt
setblock ~177 ~123 ~95 dirt
setblock ~177 ~123 ~96 dirt
setblock ~177 ~123 ~97 dirt
setblock ~177 ~123 ~98 dirt
setblock ~177 ~123 ~99 dirt
setblock ~177 ~124 ~92 grass_block
setblock ~177 ~124 ~93 grass_block
setblock ~177 ~124 ~94 grass_block
setblock ~177 ~124 ~95 grass_block
setblock ~177 ~124 ~96 grass_block
setblock ~177 ~124 ~97 grass_block
setblock ~177 ~124 ~98 grass_block
setblock ~177 ~124 ~99 grass_block
setblock ~177 ~125 ~93 fern
setblock ~177 ~125 ~98 poppy
setblock ~177 ~132 ~112 oak_leaves[persistent=null]
setblock ~177 ~132 ~115 jungle_leaves[persistent=null]
setblock ~177 ~133 ~110 jungle_leaves[persistent=null]
setblock ~177 ~133 ~111 oak_leaves[persistent=null]
setblock ~177 ~133 ~112 oak_leaves[persistent=null]
setblock ~177 ~133 ~113 oak_leaves[persistent=null]
setblock ~177 ~133 ~115 oak_leaves[persistent=null]
setblock ~177 ~134 ~102 oak_leaves[persistent=null]
setblock ~177 ~134 ~104 oak_leaves[persistent=null]
setblock ~177 ~134 ~107 oak_leaves[persistent=null]
setblock ~177 ~134 ~108 oak_leaves[persistent=null]
setblock ~177 ~134 ~109 jungle_leaves[persistent=null]
setblock ~177 ~134 ~111 oak_leaves[persistent=null]
setblock ~177 ~134 ~114 oak_wood
setblock ~177 ~135 ~102 oak_leaves[persistent=null]
setblock ~177 ~135 ~104 oak_leaves[persistent=null]
setblock ~177 ~135 ~106 oak_leaves[persistent=null]
setblock ~177 ~135 ~107 oak_leaves[persistent=null]
setblock ~177 ~135 ~109 oak_leaves[persistent=null]
setblock ~177 ~135 ~111 jungle_leaves[persistent=null]
setblock ~177 ~135 ~113 oak_wood
setblock ~177 ~135 ~114 jungle_leaves[persistent=null]
setblock ~177 ~135 ~115 jungle_leaves[persistent=null]
setblock ~177 ~136 ~102 oak_leaves[persistent=null]
setblock ~177 ~136 ~103 oak_leaves[persistent=null]
setblock ~177 ~136 ~104 oak_leaves[persistent=null]
setblock ~177 ~136 ~106 oak_leaves[persistent=null]
setblock ~177 ~136 ~107 oak_leaves[persistent=null]
setblock ~177 ~136 ~108 oak_wood
setblock ~177 ~136 ~109 oak_leaves[persistent=null]
setblock ~177 ~136 ~110 jungle_leaves[persistent=null]
setblock ~177 ~136 ~111 oak_leaves[persistent=null]
setblock ~177 ~136 ~113 oak_leaves[persistent=null]
setblock ~177 ~136 ~115 oak_leaves[persistent=null]
setblock ~177 ~137 ~106 oak_leaves[persistent=null]
setblock ~177 ~137 ~107 oak_leaves[persistent=null]
setblock ~177 ~137 ~108 oak_leaves[persistent=null]
setblock ~177 ~137 ~109 oak_leaves[persistent=null]
setblock ~177 ~137 ~112 oak_leaves[persistent=null]
setblock ~177 ~137 ~113 oak_leaves[persistent=null]
setblock ~177 ~137 ~114 oak_leaves[persistent=null]
setblock ~177 ~138 ~106 oak_leaves[persistent=null]
setblock ~177 ~138 ~107 oak_leaves[persistent=null]
setblock ~177 ~138 ~108 oak_leaves[persistent=null]
setblock ~178 ~120 ~95 dirt
setblock ~178 ~120 ~96 dirt
setblock ~178 ~121 ~93 dirt
setblock ~178 ~121 ~94 dirt
setblock ~178 ~121 ~95 dirt
setblock ~178 ~121 ~96 dirt
setblock ~178 ~122 ~93 dirt
setblock ~178 ~122 ~94 dirt
setblock ~178 ~122 ~95 dirt
setblock ~178 ~122 ~96 dirt
setblock ~178 ~123 ~93 dirt
setblock ~178 ~123 ~94 dirt
setblock ~178 ~123 ~95 dirt
setblock ~178 ~123 ~96 dirt
setblock ~178 ~124 ~93 grass_block
setblock ~178 ~124 ~94 grass_block
setblock ~178 ~124 ~95 grass_block
setblock ~178 ~124 ~96 grass_block
setblock ~178 ~125 ~94 short_grass
setblock ~178 ~125 ~95 fern
setblock ~178 ~133 ~112 oak_leaves[persistent=null]
setblock ~178 ~133 ~114 oak_leaves[persistent=null]
setblock ~178 ~133 ~115 oak_leaves[persistent=null]
setblock ~178 ~134 ~107 oak_leaves[persistent=null]
setblock ~178 ~134 ~108 oak_leaves[persistent=null]
setblock ~178 ~134 ~112 oak_leaves[persistent=null]
setblock ~178 ~134 ~113 oak_leaves[persistent=null]
setblock ~178 ~134 ~114 oak_leaves[persistent=null]
setblock ~178 ~135 ~107 oak_leaves[persistent=null]
setblock ~178 ~135 ~108 oak_leaves[persistent=null]
setblock ~178 ~135 ~113 oak_leaves[persistent=null]
setblock ~178 ~135 ~115 oak_leaves[persistent=null]
setblock ~178 ~136 ~107 oak_wood
setblock ~178 ~136 ~109 oak_leaves[persistent=null]
setblock ~178 ~136 ~112 oak_leaves[persistent=null]
setblock ~178 ~136 ~113 oak_wood
setblock ~178 ~136 ~115 oak_leaves[persistent=null]
setblock ~178 ~137 ~106 oak_leaves[persistent=null]
setblock ~178 ~137 ~107 oak_wood
setblock ~178 ~137 ~108 oak_leaves[persistent=null]
setblock ~178 ~137 ~109 jungle_leaves[persistent=null]
setblock ~178 ~137 ~113 oak_leaves[persistent=null]
setblock ~178 ~137 ~114 oak_leaves[persistent=null]
setblock ~178 ~138 ~106 oak_leaves[persistent=null]
setblock ~178 ~138 ~107 oak_leaves[persistent=null]
setblock ~179 ~132 ~114 oak_leaves[persistent=null]
setblock ~179 ~133 ~112 oak_leaves[persistent=null]
setblock ~179 ~133 ~113 oak_leaves[persistent=null]
setblock ~179 ~133 ~114 oak_leaves[persistent=null]
setblock ~179 ~133 ~115 jungle_leaves[persistent=null]
setblock ~179 ~134 ~112 oak_leaves[persistent=null]
setblock ~179 ~134 ~113 oak_leaves[persistent=null]
setblock ~179 ~134 ~114 oak_leaves[persistent=null]
setblock ~179 ~134 ~115 oak_leaves[persistent=null]
setblock ~179 ~135 ~113 oak_leaves[persistent=null]
setblock ~179 ~135 ~114 oak_leaves[persistent=null]
setblock ~179 ~135 ~115 oak_leaves[persistent=null]
setblock ~179 ~136 ~106 jungle_leaves[persistent=null]
setblock ~179 ~136 ~107 oak_leaves[persistent=null]
setblock ~179 ~136 ~108 oak_leaves[persistent=null]
setblock ~179 ~136 ~112 jungle_leaves[persistent=null]
setblock ~179 ~136 ~113 oak_leaves[persistent=null]
setblock ~179 ~136 ~115 oak_leaves[persistent=null]
setblock ~179 ~137 ~107 oak_wood
setblock ~179 ~137 ~108 oak_leaves[persistent=null]
setblock ~179 ~137 ~114 oak_leaves[persistent=null]
setblock ~179 ~138 ~106 oak_leaves[persistent=null]
setblock ~179 ~138 ~107 oak_leaves[persistent=null]
setblock ~179 ~138 ~108 oak_leaves[persistent=null]
setblock ~180 ~136 ~106 oak_leaves[persistent=null]
setblock ~180 ~136 ~107 jungle_leaves[persistent=null]
setblock ~180 ~136 ~108 oak_leaves[persistent=null]
setblock ~180 ~137 ~107 oak_leaves[persistent=null]
setblock ~180 ~137 ~108 oak_leaves[persistent=null]
setblock ~180 ~138 ~106 oak_leaves[persistent=null]
setblock ~180 ~138 ~108 jungle_leaves[persistent=null]
setblock ~181 ~136 ~106 oak_leaves[persistent=null]
setblock ~181 ~136 ~107 oak_leaves[persistent=null]
setblock ~181 ~136 ~108 jungle_leaves[persistent=null]
setblock ~181 ~137 ~106 oak_leaves[persistent=null]
setblock ~181 ~137 ~107 oak_leaves[persistent=null]
setblock ~181 ~138 ~106 oak_leaves[persistent=null]
setblock ~181 ~138 ~108 oak_leaves[persistent=null]
setblock ~199 ~200 ~199 gold_block
