setblock ~0 ~1 ~0 gold_block
setblock ~6 ~120 ~106 dirt
setblock ~6 ~120 ~107 dirt
setblock ~6 ~121 ~105 dirt
setblock ~6 ~121 ~106 dirt
setblock ~6 ~121 ~107 dirt
setblock ~6 ~121 ~108 dirt
setblock ~6 ~122 ~105 dirt
setblock ~6 ~122 ~106 dirt
setblock ~6 ~122 ~107 dirt
setblock ~6 ~122 ~108 dirt
setblock ~6 ~123 ~105 dirt
setblock ~6 ~123 ~106 dirt
setblock ~6 ~123 ~107 dirt
setblock ~6 ~123 ~108 dirt
setblock ~6 ~124 ~105 grass_block
setblock ~6 ~124 ~106 grass_block
setblock ~6 ~124 ~107 dirt
setblock ~6 ~124 ~108 dirt
setblock ~6 ~125 ~106 short_grass
setblock ~6 ~125 ~107 grass_block
setblock ~6 ~125 ~108 grass_block
setblock ~7 ~118 ~106 dirt
setblock ~7 ~119 ~106 dirt
setblock ~7 ~119 ~107 dirt
setblock ~7 ~120 ~105 dirt
setblock ~7 ~120 ~106 dirt
setblock ~7 ~120 ~107 dirt
setblock ~7 ~120 ~108 dirt
setblock ~7 ~121 ~103 dirt
setblock ~7 ~121 ~104 dirt
setblock ~7 ~121 ~105 dirt
setblock ~7 ~121 ~106 dirt
setblock ~7 ~121 ~107 dirt
setblock ~7 ~121 ~108 dirt
setblock ~7 ~121 ~109 dirt
setblock ~7 ~122 ~103 dirt
setblock ~7 ~122 ~104 dirt
setblock ~7 ~122 ~105 dirt
setblock ~7 ~122 ~106 dirt
setblock ~7 ~122 ~107 dirt
setblock ~7 ~122 ~108 dirt
setblock ~7 ~122 ~109 dirt
setblock ~7 ~123 ~103 dirt
setblock ~7 ~123 ~104 dirt
setblock ~7 ~123 ~105 dirt
setblock ~7 ~123 ~106 dirt
setblock ~7 ~123 ~107 dirt
setblock ~7 ~123 ~108 dirt
setblock ~7 ~123 ~109 dirt
setblock ~7 ~124 ~103 grass_block
setblock ~7 ~124 ~104 grass_block
setblock ~7 ~124 ~105 grass_block
setblock ~7 ~124 ~106 grass_block
setblock ~7 ~124 ~107 grass_block
setblock ~7 ~124 ~108 dirt
setblock ~7 ~124 ~109 dirt
setblock ~7 ~125 ~104 short_grass
setblock ~7 ~125 ~105 short_grass
setblock ~7 ~125 ~108 grass_block
setblock ~7 ~125 ~109 grass_block
setblock ~8 ~117 ~106 dirt
setblock ~8 ~118 ~105 dirt
setblock ~8 ~118 ~106 dirt
setblock ~8 ~118 ~107 dirt
setblock ~8 ~118 ~108 dirt
setblock ~8 ~119 ~105 dirt
setblock ~8 ~119 ~106 dirt
setblock ~8 ~119 ~107 dirt
setblock ~8 ~119 ~108 dirt
setblock ~8 ~119 ~109 dirt
setblock ~8 ~120 ~103 dirt
setblock ~8 ~120 ~104 dirt
setblock ~8 ~120 ~105 dirt
setblock ~8 ~120 ~106 dirt
setblock ~8 ~120 ~107 dirt
setblock ~8 ~120 ~108 dirt
setblock ~8 ~120 ~109 dirt
setblock ~8 ~120 ~110 dirt
setblock ~8 ~120 ~111 dirt
setblock ~8 ~121 ~102 dirt
setblock ~8 ~121 ~103 dirt
setblock ~8 ~121 ~104 dirt
setblock ~8 ~121 ~105 dirt
setblock ~8 ~121 ~106 dirt
setblock ~8 ~121 ~107 dirt
setblock ~8 ~121 ~108 dirt
setblock ~8 ~121 ~109 dirt
setblock ~8 ~121 ~110 dirt
setblock ~8 ~121 ~111 dirt
setblock ~8 ~121 ~112 dirt
setblock ~8 ~121 ~113 dirt
setblock ~8 ~121 ~114 dirt
setblock ~8 ~122 ~102 dirt
setblock ~8 ~122 ~103 dirt
setblock ~8 ~122 ~104 dirt
setblock ~8 ~122 ~105 dirt
setblock ~8 ~122 ~106 dirt
setblock ~8 ~122 ~107 dirt
setblock ~8 ~122 ~108 dirt
setblock ~8 ~122 ~109 dirt
setblock ~8 ~122 ~110 dirt
setblock ~8 ~122 ~111 dirt
setblock ~8 ~122 ~112 dirt
setblock ~8 ~122 ~113 dirt
setblock ~8 ~122 ~114 dirt
setblock ~8 ~123 ~102 grass_block
setblock ~8 ~123 ~103 grass_block
setblock ~8 ~123 ~104 dirt
setblock ~8 ~123 ~105 dirt
setblock ~8 ~123 ~106 dirt
setblock ~8 ~123 ~107 dirt
setblock ~8 ~123 ~108 dirt
setblock ~8 ~123 ~109 dirt
setblock ~8 ~123 ~110 dirt
setblock ~8 ~123 ~111 dirt
setblock ~8 ~123 ~112 dirt
setblock ~8 ~123 ~113 dirt
setblock ~8 ~123 ~114 dirt
setblock ~8 ~124 ~104 grass_block
setblock ~8 ~124 ~105 grass_block
setblock ~8 ~124 ~106 grass_block
setblock ~8 ~124 ~107 grass_block
setblock ~8 ~124 ~108 grass_block
setblock ~8 ~124 ~109 grass_block
setblock ~8 ~124 ~110 dirt
setblock ~8 ~124 ~111 dirt
setblock ~8 ~124 ~112 dirt
setblock ~8 ~124 ~113 dirt
setblock ~8 ~124 ~114 dirt
setblock ~8 ~125 ~104 poppy
setblock ~8 ~125 ~110 grass_block
setblock ~8 ~125 ~111 grass_block
setblock ~8 ~125 ~112 grass_block
setblock ~8 ~125 ~113 grass_block
setblock ~8 ~125 ~114 grass_block
setblock ~9 ~116 ~106 dirt
setblock ~9 ~117 ~105 dirt
setblock ~9 ~117 ~106 dirt
setblock ~9 ~117 ~107 dirt
setblock ~9 ~117 ~108 dirt
setblock ~9 ~118 ~105 dirt
setblock ~9 ~118 ~106 dirt
setblock ~9 ~118 ~107 dirt
setblock ~9 ~118 ~108 dirt
setblock ~9 ~118 ~109 dirt
setblock ~9 ~118 ~111 dirt
setblock ~9 ~119 ~103 dirt
setblock ~9 ~119 ~104 dirt
setblock ~9 ~119 ~105 dirt
setblock ~9 ~119 ~106 dirt
setblock ~9 ~119 ~107 dirt
setblock ~9 ~119 ~108 dirt
setblock ~9 ~119 ~109 dirt
setblock ~9 ~119 ~110 dirt
setblock ~9 ~119 ~111 dirt
setblock ~9 ~119 ~113 dirt
setblock ~9 ~120 ~102 dirt
setblock ~9 ~120 ~103 dirt
setblock ~9 ~120 ~104 dirt
setblock ~9 ~120 ~105 dirt
setblock ~9 ~120 ~106 dirt
setblock ~9 ~120 ~107 dirt
setblock ~9 ~120 ~108 dirt
setblock ~9 ~120 ~109 dirt
setblock ~9 ~120 ~110 dirt
setblock ~9 ~120 ~111 dirt
setblock ~9 ~120 ~112 dirt
setblock ~9 ~120 ~113 dirt
setblock ~9 ~120 ~114 dirt
setblock ~9 ~121 ~101 dirt
setblock ~9 ~121 ~102 dirt
setblock ~9 ~121 ~103 dirt
setblock ~9 ~121 ~104 dirt
setblock ~9 ~121 ~105 dirt
setblock ~9 ~121 ~106 dirt
setblock ~9 ~121 ~107 dirt
setblock ~9 ~121 ~108 dirt
setblock ~9 ~121 ~109 dirt
setblock ~9 ~121 ~110 dirt
setblock ~9 ~121 ~111 dirt
setblock ~9 ~121 ~112 dirt
setblock ~9 ~121 ~113 dirt
setblock ~9 ~121 ~114 dirt
setblock ~9 ~121 ~115 dirt
setblock ~9 ~122 ~101 dirt
setblock ~9 ~122 ~102 dirt
setblock ~9 ~122 ~103 dirt
setblock ~9 ~122 ~104 dirt
setblock ~9 ~122 ~105 dirt
setblock ~9 ~122 ~106 dirt
setblock ~9 ~122 ~107 dirt
setblock ~9 ~122 ~108 dirt
setblock ~9 ~122 ~109 dirt
setblock ~9 ~122 ~110 dirt
setblock ~9 ~122 ~111 dirt
setblock ~9 ~122 ~112 dirt
setblock ~9 ~122 ~113 dirt
setblock ~9 ~122 ~114 dirt
setblock ~9 ~122 ~115 dirt
setblock ~9 ~123 ~101 grass_block
setblock ~9 ~123 ~102 grass_block
setblock ~9 ~123 ~103 grass_block
setblock ~9 ~123 ~104 grass_block
setblock ~9 ~123 ~105 dirt
setblock ~9 ~123 ~106 dirt
setblock ~9 ~123 ~107 dirt
setblock ~9 ~123 ~108 dirt
setblock ~9 ~123 ~109 dirt
setblock ~9 ~123 ~110 dirt
setblock ~9 ~123 ~111 dirt
setblock ~9 ~123 ~112 dirt
setblock ~9 ~123 ~113 dirt
setblock ~9 ~123 ~114 dirt
setblock ~9 ~123 ~115 dirt
setblock ~9 ~124 ~104 short_grass
setblock ~9 ~124 ~105 grass_block
setblock ~9 ~124 ~106 grass_block
setblock ~9 ~124 ~107 grass_block
setblock ~9 ~124 ~108 grass_block
setblock ~9 ~124 ~109 grass_block
setblock ~9 ~124 ~110 grass_block
setblock ~9 ~124 ~111 grass_block
setblock ~9 ~124 ~112 dirt
setblock ~9 ~124 ~113 dirt
setblock ~9 ~124 ~114 dirt
setblock ~9 ~124 ~115 dirt
setblock ~9 ~125 ~107 short_grass
setblock ~9 ~125 ~108 short_grass
setblock ~9 ~125 ~109 short_grass
setblock ~9 ~125 ~111 short_grass
setblock ~9 ~125 ~112 grass_block
setblock ~9 ~125 ~113 grass_block
setblock ~9 ~125 ~114 grass_block
setblock ~9 ~125 ~115 grass_block
setblock ~9 ~126 ~112 short_grass
setblock ~9 ~126 ~113 short_grass
setblock ~9 ~126 ~115 short_grass
setblock ~10 ~115 ~106 dirt
setblock ~10 ~116 ~105 dirt
setblock ~10 ~116 ~106 dirt
setblock ~10 ~116 ~107 dirt
setblock ~10 ~116 ~108 dirt
setblock ~10 ~117 ~104 dirt
setblock ~10 ~117 ~105 dirt
setblock ~10 ~117 ~106 dirt
setblock ~10 ~117 ~107 dirt
setblock ~10 ~117 ~108 dirt
setblock ~10 ~117 ~109 dirt
setblock ~10 ~117 ~111 dirt
setblock ~10 ~118 ~103 dirt
setblock ~10 ~118 ~104 dirt
setblock ~10 ~118 ~105 dirt
setblock ~10 ~118 ~106 dirt
setblock ~10 ~118 ~107 dirt
setblock ~10 ~118 ~108 dirt
setblock ~10 ~118 ~109 dirt
setblock ~10 ~118 ~110 dirt
setblock ~10 ~118 ~111 dirt
setblock ~10 ~118 ~112 dirt
setblock ~10 ~118 ~113 dirt
setblock ~10 ~119 ~102 dirt
setblock ~10 ~119 ~103 dirt
setblock ~10 ~119 ~104 dirt
setblock ~10 ~119 ~105 dirt
setblock ~10 ~119 ~106 dirt
setblock ~10 ~119 ~107 dirt
setblock ~10 ~119 ~108 dirt
setblock ~10 ~119 ~109 dirt
setblock ~10 ~119 ~110 dirt
setblock ~10 ~119 ~111 dirt
setblock ~10 ~119 ~112 dirt
setblock ~10 ~119 ~113 dirt
setblock ~10 ~119 ~114 dirt
setblock ~10 ~120 ~101 dirt
setblock ~10 ~120 ~102 dirt
setblock ~10 ~120 ~103 dirt
setblock ~10 ~120 ~104 dirt
setblock ~10 ~120 ~105 dirt
setblock ~10 ~120 ~106 dirt
setblock ~10 ~120 ~107 dirt
setblock ~10 ~120 ~108 dirt
setblock ~10 ~120 ~109 dirt
setblock ~10 ~120 ~110 dirt
setblock ~10 ~120 ~111 dirt
setblock ~10 ~120 ~112 dirt
setblock ~10 ~120 ~113 dirt
setblock ~10 ~120 ~114 dirt
setblock ~10 ~120 ~115 dirt
setblock ~10 ~121 ~100 dirt
setblock ~10 ~121 ~101 dirt
setblock ~10 ~121 ~102 dirt
setblock ~10 ~121 ~103 dirt
setblock ~10 ~121 ~104 dirt
setblock ~10 ~121 ~105 dirt
setblock ~10 ~121 ~106 dirt
setblock ~10 ~121 ~107 dirt
setblock ~10 ~121 ~108 dirt
setblock ~10 ~121 ~109 dirt
setblock ~10 ~121 ~110 dirt
setblock ~10 ~121 ~111 dirt
setblock ~10 ~121 ~112 dirt
setblock ~10 ~121 ~113 dirt
setblock ~10 ~121 ~114 dirt
setblock ~10 ~121 ~115 dirt
setblock ~10 ~121 ~116 dirt
setblock ~10 ~122 ~100 grass_block
setblock ~10 ~122 ~101 grass_block
setblock ~10 ~122 ~102 dirt
setblock ~10 ~122 ~103 dirt
setblock ~10 ~122 ~104 dirt
setblock ~10 ~122 ~105 dirt
setblock ~10 ~122 ~106 dirt
setblock ~10 ~122 ~107 dirt
setblock ~10 ~122 ~108 dirt
setblock ~10 ~122 ~109 dirt
setblock ~10 ~122 ~110 dirt
setblock ~10 ~122 ~111 dirt
setblock ~10 ~122 ~112 dirt
setblock ~10 ~122 ~113 dirt
setblock ~10 ~122 ~114 dirt
setblock ~10 ~122 ~115 dirt
setblock ~10 ~122 ~116 dirt
setblock ~10 ~123 ~102 grass_block
setblock ~10 ~123 ~103 grass_block
setblock ~10 ~123 ~104 grass_block
setblock ~10 ~123 ~105 grass_block
setblock ~10 ~123 ~106 dirt
setblock ~10 ~123 ~107 dirt
setblock ~10 ~123 ~108 dirt
setblock ~10 ~123 ~109 dirt
setblock ~10 ~123 ~110 dirt
setblock ~10 ~123 ~111 dirt
setblock ~10 ~123 ~112 dirt
setblock ~10 ~123 ~113 dirt
setblock ~10 ~123 ~114 dirt
setblock ~10 ~123 ~115 dirt
setblock ~10 ~123 ~116 dirt
setblock ~10 ~124 ~103 poppy
setblock ~10 ~124 ~106 grass_block
setblock ~10 ~124 ~107 grass_block
setblock ~10 ~124 ~108 grass_block
setblock ~10 ~124 ~109 grass_block
setblock ~10 ~124 ~110 grass_block
setblock ~10 ~124 ~111 grass_block
setblock ~10 ~124 ~112 grass_block
setblock ~10 ~124 ~113 grass_block
setblock ~10 ~124 ~114 dirt
setblock ~10 ~124 ~115 dirt
setblock ~10 ~124 ~116 dirt
setblock ~10 ~125 ~110 short_grass
setblock ~10 ~125 ~111 short_grass
setblock ~10 ~125 ~114 grass_block
setblock ~10 ~125 ~115 grass_block
setblock ~10 ~125 ~116 grass_block
setblock ~10 ~126 ~116 short_grass
setblock ~11 ~114 ~106 dirt
setblock ~11 ~114 ~108 dirt
setblock ~11 ~115 ~105 dirt
setblock ~11 ~115 ~106 dirt
setblock ~11 ~115 ~107 dirt
setblock ~11 ~115 ~108 dirt
setblock ~11 ~116 ~104 dirt
setblock ~11 ~116 ~105 dirt
setblock ~11 ~116 ~106 dirt
setblock ~11 ~116 ~107 dirt
setblock ~11 ~116 ~108 dirt
setblock ~11 ~116 ~109 dirt
setblock ~11 ~116 ~110 dirt
setblock ~11 ~116 ~111 dirt
setblock ~11 ~116 ~112 dirt
setblock ~11 ~117 ~103 dirt
setblock ~11 ~117 ~104 dirt
setblock ~11 ~117 ~105 dirt
setblock ~11 ~117 ~106 dirt
setblock ~11 ~117 ~107 dirt
setblock ~11 ~117 ~108 dirt
setblock ~11 ~117 ~109 dirt
setblock ~11 ~117 ~110 dirt
setblock ~11 ~117 ~111 dirt
setblock ~11 ~117 ~112 dirt
setblock ~11 ~117 ~113 dirt
setblock ~11 ~118 ~102 dirt
setblock ~11 ~118 ~103 dirt
setblock ~11 ~118 ~104 dirt
setblock ~11 ~118 ~105 dirt
setblock ~11 ~118 ~106 dirt
setblock ~11 ~118 ~107 dirt
setblock ~11 ~118 ~108 dirt
setblock ~11 ~118 ~109 dirt
setblock ~11 ~118 ~110 dirt
setblock ~11 ~118 ~111 dirt
setblock ~11 ~118 ~112 dirt
setblock ~11 ~118 ~113 dirt
setblock ~11 ~118 ~114 dirt
setblock ~11 ~119 ~101 dirt
setblock ~11 ~119 ~102 dirt
setblock ~11 ~119 ~103 dirt
setblock ~11 ~119 ~104 dirt
setblock ~11 ~119 ~105 dirt
setblock ~11 ~119 ~106 dirt
setblock ~11 ~119 ~107 dirt
setblock ~11 ~119 ~108 dirt
setblock ~11 ~119 ~109 dirt
setblock ~11 ~119 ~110 dirt
setblock ~11 ~119 ~111 dirt
setblock ~11 ~119 ~112 dirt
setblock ~11 ~119 ~113 dirt
setblock ~11 ~119 ~114 dirt
setblock ~11 ~119 ~115 dirt
setblock ~11 ~120 ~100 dirt
setblock ~11 ~120 ~101 dirt
setblock ~11 ~120 ~102 dirt
setblock ~11 ~120 ~103 dirt
setblock ~11 ~120 ~104 dirt
setblock ~11 ~120 ~105 dirt
setblock ~11 ~120 ~106 dirt
setblock ~11 ~120 ~107 dirt
setblock ~11 ~120 ~108 dirt
setblock ~11 ~120 ~109 dirt
setblock ~11 ~120 ~110 dirt
setblock ~11 ~120 ~111 dirt
setblock ~11 ~120 ~112 dirt
setblock ~11 ~120 ~113 dirt
setblock ~11 ~120 ~114 dirt
setblock ~11 ~120 ~115 dirt
setblock ~11 ~120 ~116 dirt
setblock ~11 ~121 ~99 dirt
setblock ~11 ~121 ~100 dirt
setblock ~11 ~121 ~101 dirt
setblock ~11 ~121 ~102 dirt
setblock ~11 ~121 ~103 dirt
setblock ~11 ~121 ~104 dirt
setblock ~11 ~121 ~105 dirt
setblock ~11 ~121 ~106 dirt
setblock ~11 ~121 ~107 dirt
setblock ~11 ~121 ~108 dirt
setblock ~11 ~121 ~109 dirt
setblock ~11 ~121 ~110 dirt
setblock ~11 ~121 ~111 dirt
setblock ~11 ~121 ~112 dirt
setblock ~11 ~121 ~113 dirt
setblock ~11 ~121 ~114 dirt
setblock ~11 ~121 ~115 dirt
setblock ~11 ~121 ~116 dirt
setblock ~11 ~121 ~117 dirt
setblock ~11 ~122 ~99 dirt
setblock ~11 ~122 ~100 grass_block
setblock ~11 ~122 ~101 dirt
setblock ~11 ~122 ~102 dirt
setblock ~11 ~122 ~103 dirt
setblock ~11 ~122 ~104 dirt
setblock ~11 ~122 ~105 dirt
setblock ~11 ~122 ~106 dirt
setblock ~11 ~122 ~107 dirt
setblock ~11 ~122 ~108 dirt
setblock ~11 ~122 ~109 dirt
setblock ~11 ~122 ~110 dirt
setblock ~11 ~122 ~111 dirt
setblock ~11 ~122 ~112 dirt
setblock ~11 ~122 ~113 dirt
setblock ~11 ~122 ~114 dirt
setblock ~11 ~122 ~115 dirt
setblock ~11 ~122 ~116 dirt
setblock ~11 ~122 ~117 dirt
setblock ~11 ~123 ~99 grass_block
setblock ~11 ~123 ~101 grass_block
setblock ~11 ~123 ~102 grass_block
setblock ~11 ~123 ~103 grass_block
setblock ~11 ~123 ~104 grass_block
setblock ~11 ~123 ~105 dirt
setblock ~11 ~123 ~106 dirt
setblock ~11 ~123 ~107 dirt
setblock ~11 ~123 ~108 dirt
setblock ~11 ~123 ~109 dirt
setblock ~11 ~123 ~110 dirt
setblock ~11 ~123 ~111 dirt
setblock ~11 ~123 ~112 dirt
setblock ~11 ~123 ~113 dirt
setblock ~11 ~123 ~114 dirt
setblock ~11 ~123 ~115 dirt
setblock ~11 ~123 ~116 dirt
setblock ~11 ~123 ~117 dirt
setblock ~11 ~124 ~105 grass_block
setblock ~11 ~124 ~106 grass_block
setblock ~11 ~124 ~107 grass_block
setblock ~11 ~124 ~108 grass_block
setblock ~11 ~124 ~109 grass_block
setblock ~11 ~124 ~110 dirt
setblock ~11 ~124 ~111 dirt
setblock ~11 ~124 ~112 dirt
setblock ~11 ~124 ~113 dirt
setblock ~11 ~124 ~114 dirt
setblock ~11 ~124 ~115 dirt
setblock ~11 ~124 ~116 dirt
setblock ~11 ~124 ~117 dirt
setblock ~11 ~125 ~109 short_grass
setblock ~11 ~125 ~110 grass_block
setblock ~11 ~125 ~111 grass_block
setblock ~11 ~125 ~112 grass_block
setblock ~11 ~125 ~113 grass_block
setblock ~11 ~125 ~114 grass_block
setblock ~11 ~125 ~115 grass_block
setblock ~11 ~125 ~116 grass_block
setblock ~11 ~125 ~117 grass_block
setblock ~11 ~126 ~116 short_grass
setblock ~11 ~126 ~117 short_grass
setblock ~12 ~113 ~106 dirt
setblock ~12 ~113 ~107 dirt
setblock ~12 ~113 ~108 dirt
setblock ~12 ~114 ~105 dirt
setblock ~12 ~114 ~106 dirt
setblock ~12 ~114 ~107 dirt
setblock ~12 ~114 ~108 dirt
setblock ~12 ~114 ~109 dirt
setblock ~12 ~114 ~110 dirt
setblock ~12 ~115 ~104 dirt
setblock ~12 ~115 ~105 dirt
setblock ~12 ~115 ~106 dirt
setblock ~12 ~115 ~107 dirt
setblock ~12 ~115 ~108 dirt
setblock ~12 ~115 ~109 dirt
setblock ~12 ~115 ~110 dirt
setblock ~12 ~115 ~111 dirt
setblock ~12 ~115 ~112 dirt
setblock ~12 ~116 ~103 dirt
setblock ~12 ~116 ~104 dirt
setblock ~12 ~116 ~105 dirt
setblock ~12 ~116 ~106 dirt
setblock ~12 ~116 ~107 dirt
setblock ~12 ~116 ~108 dirt
setblock ~12 ~116 ~109 dirt
setblock ~12 ~116 ~110 dirt
setblock ~12 ~116 ~111 dirt
setblock ~12 ~116 ~112 dirt
setblock ~12 ~116 ~113 dirt
setblock ~12 ~117 ~102 dirt
setblock ~12 ~117 ~103 dirt
setblock ~12 ~117 ~104 dirt
setblock ~12 ~117 ~105 dirt
setblock ~12 ~117 ~106 dirt
setblock ~12 ~117 ~107 dirt
setblock ~12 ~117 ~108 dirt
setblock ~12 ~117 ~109 dirt
setblock ~12 ~117 ~110 dirt
setblock ~12 ~117 ~111 dirt
setblock ~12 ~117 ~112 dirt
setblock ~12 ~117 ~113 dirt
setblock ~12 ~117 ~114 dirt
setblock ~12 ~118 ~101 dirt
setblock ~12 ~118 ~102 dirt
setblock ~12 ~118 ~103 dirt
setblock ~12 ~118 ~104 dirt
setblock ~12 ~118 ~105 dirt
setblock ~12 ~118 ~106 dirt
setblock ~12 ~118 ~107 dirt
setblock ~12 ~118 ~108 dirt
setblock ~12 ~118 ~109 dirt
setblock ~12 ~118 ~110 dirt
setblock ~12 ~118 ~111 dirt
setblock ~12 ~118 ~112 dirt
setblock ~12 ~118 ~113 dirt
setblock ~12 ~118 ~114 dirt
setblock ~12 ~118 ~115 dirt
setblock ~12 ~119 ~100 dirt
setblock ~12 ~119 ~101 dirt
setblock ~12 ~119 ~102 dirt
setblock ~12 ~119 ~103 dirt
setblock ~12 ~119 ~104 dirt
setblock ~12 ~119 ~105 dirt
setblock ~12 ~119 ~106 dirt
setblock ~12 ~119 ~107 dirt
setblock ~12 ~119 ~108 dirt
setblock ~12 ~119 ~109 dirt
setblock ~12 ~119 ~110 dirt
setblock ~12 ~119 ~111 dirt
setblock ~12 ~119 ~112 dirt
setblock ~12 ~119 ~113 dirt
setblock ~12 ~119 ~114 dirt
setblock ~12 ~119 ~115 dirt
setblock ~12 ~119 ~116 dirt
setblock ~12 ~120 ~99 dirt
setblock ~12 ~120 ~100 dirt
setblock ~12 ~120 ~101 dirt
setblock ~12 ~120 ~102 dirt
setblock ~12 ~120 ~103 dirt
setblock ~12 ~120 ~104 dirt
setblock ~12 ~120 ~105 dirt
setblock ~12 ~120 ~106 dirt
setblock ~12 ~120 ~107 dirt
setblock ~12 ~120 ~108 dirt
setblock ~12 ~120 ~109 dirt
setblock ~12 ~120 ~110 dirt
setblock ~12 ~120 ~111 dirt
setblock ~12 ~120 ~112 dirt
setblock ~12 ~120 ~113 dirt
setblock ~12 ~120 ~114 dirt
setblock ~12 ~120 ~115 dirt
setblock ~12 ~120 ~116 dirt
setblock ~12 ~120 ~117 dirt
setblock ~12 ~121 ~98 dirt
setblock ~12 ~121 ~99 dirt
setblock ~12 ~121 ~100 dirt
setblock ~12 ~121 ~101 dirt
setblock ~12 ~121 ~102 dirt
setblock ~12 ~121 ~103 dirt
setblock ~12 ~121 ~104 dirt
setblock ~12 ~121 ~105 dirt
setblock ~12 ~121 ~106 dirt
setblock ~12 ~121 ~107 dirt
setblock ~12 ~121 ~108 dirt
setblock ~12 ~121 ~109 dirt
setblock ~12 ~121 ~110 dirt
setblock ~12 ~121 ~111 dirt
setblock ~12 ~121 ~112 dirt
setblock ~12 ~121 ~113 dirt
setblock ~12 ~121 ~114 dirt
setblock ~12 ~121 ~115 dirt
setblock ~12 ~121 ~116 dirt
setblock ~12 ~121 ~117 dirt
setblock ~12 ~121 ~118 dirt
setblock ~12 ~122 ~98 dirt
setblock ~12 ~122 ~99 dirt
setblock ~12 ~122 ~100 dirt
setblock ~12 ~122 ~101 dirt
setblock ~12 ~122 ~102 dirt
setblock ~12 ~122 ~103 dirt
setblock ~12 ~122 ~104 dirt
setblock ~12 ~122 ~105 dirt
setblock ~12 ~122 ~106 dirt
setblock ~12 ~122 ~107 dirt
setblock ~12 ~122 ~108 dirt
setblock ~12 ~122 ~109 dirt
setblock ~12 ~122 ~110 dirt
setblock ~12 ~122 ~111 dirt
setblock ~12 ~122 ~112 dirt
setblock ~12 ~122 ~113 dirt
setblock ~12 ~122 ~114 dirt
setblock ~12 ~122 ~115 dirt
setblock ~12 ~122 ~116 dirt
setblock ~12 ~122 ~117 dirt
setblock ~12 ~122 ~118 dirt
setblock ~12 ~123 ~98 grass_block
setblock ~12 ~123 ~99 grass_block
setblock ~12 ~123 ~100 grass_block
setblock ~12 ~123 ~101 grass_block
setblock ~12 ~123 ~102 grass_block
setblock ~12 ~123 ~103 grass_block
setblock ~12 ~123 ~104 dirt
setblock ~12 ~123 ~105 dirt
setblock ~12 ~123 ~106 dirt
setblock ~12 ~123 ~107 dirt
setblock ~12 ~123 ~108 dirt
setblock ~12 ~123 ~109 dirt
setblock ~12 ~123 ~110 dirt
setblock ~12 ~123 ~111 dirt
setblock ~12 ~123 ~112 dirt
setblock ~12 ~123 ~113 dirt
setblock ~12 ~123 ~114 dirt
setblock ~12 ~123 ~115 dirt
setblock ~12 ~123 ~116 dirt
setblock ~12 ~123 ~117 dirt
setblock ~12 ~123 ~118 dirt
setblock ~12 ~124 ~104 grass_block
setblock ~12 ~124 ~105 grass_block
setblock ~12 ~124 ~106 grass_block
setblock ~12 ~124 ~107 grass_block
setblock ~12 ~124 ~108 dirt
setblock ~12 ~124 ~109 dirt
setblock ~12 ~124 ~110 dirt
setblock ~12 ~124 ~111 dirt
setblock ~12 ~124 ~112 dirt
setblock ~12 ~124 ~113 dirt
setblock ~12 ~124 ~114 dirt
setblock ~12 ~124 ~115 dirt
setblock ~12 ~124 ~116 dirt
setblock ~12 ~124 ~117 grass_block
setblock ~12 ~124 ~118 grass_block
setblock ~12 ~125 ~105 short_grass
setblock ~12 ~125 ~108 grass_block
setblock ~12 ~125 ~109 grass_block
setblock ~12 ~125 ~110 grass_block
setblock ~12 ~125 ~111 grass_block
setblock ~12 ~125 ~112 grass_block
setblock ~12 ~125 ~113 grass_block
setblock ~12 ~125 ~114 grass_block
setblock ~12 ~125 ~115 grass_block
setblock ~12 ~125 ~116 grass_block
setblock ~12 ~126 ~112 short_grass
setblock ~13 ~111 ~108 dirt
setblock ~13 ~112 ~106 dirt
setblock ~13 ~112 ~107 dirt
setblock ~13 ~112 ~108 dirt
setblock ~13 ~112 ~109 dirt
setblock ~13 ~112 ~110 dirt
setblock ~13 ~113 ~105 dirt
setblock ~13 ~113 ~106 dirt
setblock ~13 ~113 ~107 dirt
setblock ~13 ~113 ~108 dirt
setblock ~13 ~113 ~109 dirt
setblock ~13 ~113 ~110 dirt
setblock ~13 ~113 ~111 dirt
setblock ~13 ~114 ~104 dirt
setblock ~13 ~114 ~105 dirt
setblock ~13 ~114 ~106 dirt
setblock ~13 ~114 ~107 dirt
setblock ~13 ~114 ~108 dirt
setblock ~13 ~114 ~109 dirt
setblock ~13 ~114 ~110 dirt
setblock ~13 ~114 ~111 dirt
setblock ~13 ~114 ~112 dirt
setblock ~13 ~115 ~103 dirt
setblock ~13 ~115 ~104 dirt
setblock ~13 ~115 ~105 dirt
setblock ~13 ~115 ~106 dirt
setblock ~13 ~115 ~107 dirt
setblock ~13 ~115 ~108 dirt
setblock ~13 ~115 ~109 dirt
setblock ~13 ~115 ~110 dirt
setblock ~13 ~115 ~111 dirt
setblock ~13 ~115 ~112 dirt
setblock ~13 ~115 ~113 dirt
setblock ~13 ~116 ~102 dirt
setblock ~13 ~116 ~103 dirt
setblock ~13 ~116 ~104 dirt
setblock ~13 ~116 ~105 dirt
setblock ~13 ~116 ~106 dirt
setblock ~13 ~116 ~107 dirt
setblock ~13 ~116 ~108 dirt
setblock ~13 ~116 ~109 dirt
setblock ~13 ~116 ~110 dirt
setblock ~13 ~116 ~111 dirt
setblock ~13 ~116 ~112 dirt
setblock ~13 ~116 ~113 dirt
setblock ~13 ~116 ~114 dirt
setblock ~13 ~117 ~101 dirt
setblock ~13 ~117 ~102 dirt
setblock ~13 ~117 ~103 dirt
setblock ~13 ~117 ~104 dirt
setblock ~13 ~117 ~105 dirt
setblock ~13 ~117 ~106 dirt
setblock ~13 ~117 ~107 dirt
setblock ~13 ~117 ~108 dirt
setblock ~13 ~117 ~109 dirt
setblock ~13 ~117 ~110 dirt
setblock ~13 ~117 ~111 dirt
setblock ~13 ~117 ~112 dirt
setblock ~13 ~117 ~113 dirt
setblock ~13 ~117 ~114 dirt
setblock ~13 ~117 ~115 dirt
setblock ~13 ~118 ~100 dirt
setblock ~13 ~118 ~101 dirt
setblock ~13 ~118 ~102 dirt
setblock ~13 ~118 ~103 dirt
setblock ~13 ~118 ~104 dirt
setblock ~13 ~118 ~105 dirt
setblock ~13 ~118 ~106 dirt
setblock ~13 ~118 ~107 dirt
setblock ~13 ~118 ~108 dirt
setblock ~13 ~118 ~109 dirt
setblock ~13 ~118 ~110 dirt
setblock ~13 ~118 ~111 dirt
setblock ~13 ~118 ~112 dirt
setblock ~13 ~118 ~113 dirt
setblock ~13 ~118 ~114 dirt
setblock ~13 ~118 ~115 dirt
setblock ~13 ~118 ~116 dirt
setblock ~13 ~119 ~99 dirt
setblock ~13 ~119 ~100 dirt
setblock ~13 ~119 ~101 dirt
setblock ~13 ~119 ~102 dirt
setblock ~13 ~119 ~103 dirt
setblock ~13 ~119 ~104 dirt
setblock ~13 ~119 ~105 dirt
setblock ~13 ~119 ~106 dirt
setblock ~13 ~119 ~107 dirt
setblock ~13 ~119 ~108 dirt
setblock ~13 ~119 ~109 dirt
setblock ~13 ~119 ~110 dirt
setblock ~13 ~119 ~111 dirt
setblock ~13 ~119 ~112 dirt
setblock ~13 ~119 ~113 dirt
setblock ~13 ~119 ~114 dirt
setblock ~13 ~119 ~115 dirt
setblock ~13 ~119 ~116 dirt
setblock ~13 ~119 ~117 dirt
setblock ~13 ~120 ~98 dirt
setblock ~13 ~120 ~99 dirt
setblock ~13 ~120 ~100 dirt
setblock ~13 ~120 ~101 dirt
setblock ~13 ~120 ~102 dirt
setblock ~13 ~120 ~103 dirt
setblock ~13 ~120 ~104 dirt
setblock ~13 ~120 ~105 dirt
setblock ~13 ~120 ~106 dirt
setblock ~13 ~120 ~107 dirt
setblock ~13 ~120 ~108 dirt
setblock ~13 ~120 ~109 dirt
setblock ~13 ~120 ~110 dirt
setblock ~13 ~120 ~111 dirt
setblock ~13 ~120 ~112 dirt
setblock ~13 ~120 ~113 dirt
setblock ~13 ~120 ~114 dirt
setblock ~13 ~120 ~115 dirt
setblock ~13 ~120 ~116 dirt
setblock ~13 ~120 ~117 dirt
setblock ~13 ~120 ~118 dirt
setblock ~13 ~120 ~120 dirt
setblock ~13 ~121 ~96 dirt
setblock ~13 ~121 ~97 dirt
setblock ~13 ~121 ~98 dirt
setblock ~13 ~121 ~99 dirt
setblock ~13 ~121 ~100 dirt
setblock ~13 ~121 ~101 dirt
setblock ~13 ~121 ~102 dirt
setblock ~13 ~121 ~103 dirt
setblock ~13 ~121 ~104 dirt
setblock ~13 ~121 ~105 dirt
setblock ~13 ~121 ~106 dirt
setblock ~13 ~121 ~107 dirt
setblock ~13 ~121 ~108 dirt
setblock ~13 ~121 ~109 dirt
setblock ~13 ~121 ~110 dirt
setblock ~13 ~121 ~111 dirt
setblock ~13 ~121 ~112 dirt
setblock ~13 ~121 ~113 dirt
setblock ~13 ~121 ~114 dirt
setblock ~13 ~121 ~115 dirt
setblock ~13 ~121 ~116 dirt
setblock ~13 ~121 ~117 dirt
setblock ~13 ~121 ~118 dirt
setblock ~13 ~121 ~120 dirt
setblock ~13 ~122 ~96 dirt
setblock ~13 ~122 ~97 dirt
setblock ~13 ~122 ~98 dirt
setblock ~13 ~122 ~99 dirt
setblock ~13 ~122 ~100 dirt
setblock ~13 ~122 ~101 dirt
setblock ~13 ~122 ~102 dirt
setblock ~13 ~122 ~103 dirt
setblock ~13 ~122 ~104 dirt
setblock ~13 ~122 ~105 dirt
setblock ~13 ~122 ~106 dirt
setblock ~13 ~122 ~107 dirt
setblock ~13 ~122 ~108 dirt
setblock ~13 ~122 ~109 dirt
setblock ~13 ~122 ~110 dirt
setblock ~13 ~122 ~111 dirt
setblock ~13 ~122 ~112 dirt
setblock ~13 ~122 ~113 dirt
setblock ~13 ~122 ~114 dirt
setblock ~13 ~122 ~115 dirt
setblock ~13 ~122 ~116 dirt
setblock ~13 ~122 ~117 dirt
setblock ~13 ~122 ~118 dirt
setblock ~13 ~122 ~120 dirt
setblock ~13 ~123 ~96 dirt
setblock ~13 ~123 ~97 dirt
setblock ~13 ~123 ~98 grass_block
setblock ~13 ~123 ~99 grass_block
setblock ~13 ~123 ~100 grass_block
setblock ~13 ~123 ~101 grass_block
setblock ~13 ~123 ~102 grass_block
setblock ~13 ~123 ~103 dirt
setblock ~13 ~123 ~104 dirt
setblock ~13 ~123 ~105 dirt
setblock ~13 ~123 ~106 dirt
setblock ~13 ~123 ~107 dirt
setblock ~13 ~123 ~108 dirt
setblock ~13 ~123 ~109 dirt
setblock ~13 ~123 ~110 dirt
setblock ~13 ~123 ~111 dirt
setblock ~13 ~123 ~112 dirt
setblock ~13 ~123 ~113 dirt
setblock ~13 ~123 ~114 dirt
setblock ~13 ~123 ~115 dirt
setblock ~13 ~123 ~116 dirt
setblock ~13 ~123 ~117 dirt
setblock ~13 ~123 ~118 dirt
setblock ~13 ~123 ~120 dirt
setblock ~13 ~124 ~96 grass_block
setblock ~13 ~124 ~97 grass_block
setblock ~13 ~124 ~100 short_grass
setblock ~13 ~124 ~103 grass_block
setblock ~13 ~124 ~104 grass_block
setblock ~13 ~124 ~105 grass_block
setblock ~13 ~124 ~106 grass_block
setblock ~13 ~124 ~107 dirt
setblock ~13 ~124 ~108 dirt
setblock ~13 ~124 ~109 dirt
setblock ~13 ~124 ~110 dirt
setblock ~13 ~124 ~111 dirt
setblock ~13 ~124 ~112 dirt
setblock ~13 ~124 ~113 dirt
setblock ~13 ~124 ~114 dirt
setblock ~13 ~124 ~115 dirt
setblock ~13 ~124 ~116 grass_block
setblock ~13 ~124 ~117 grass_block
setblock ~13 ~124 ~118 grass_block
setblock ~13 ~124 ~120 grass_block
setblock ~13 ~125 ~96 short_grass
setblock ~13 ~125 ~103 poppy
setblock ~13 ~125 ~104 short_grass
setblock ~13 ~125 ~107 grass_block
setblock ~13 ~125 ~108 grass_block
setblock ~13 ~125 ~109 grass_block
setblock ~13 ~125 ~110 grass_block
setblock ~13 ~125 ~111 grass_block
setblock ~13 ~125 ~112 grass_block
setblock ~13 ~125 ~113 grass_block
setblock ~13 ~125 ~114 grass_block
setblock ~13 ~125 ~115 grass_block
setblock ~13 ~126 ~110 short_grass
setblock ~13 ~126 ~115 short_grass
setblock ~14 ~110 ~108 dirt
setblock ~14 ~110 ~109 dirt
setblock ~14 ~111 ~106 dirt
setblock ~14 ~111 ~107 dirt
setblock ~14 ~111 ~108 dirt
setblock ~14 ~111 ~109 dirt
setblock ~14 ~111 ~110 dirt
setblock ~14 ~112 ~105 dirt
setblock ~14 ~112 ~106 dirt
setblock ~14 ~112 ~107 dirt
setblock ~14 ~112 ~108 dirt
setblock ~14 ~112 ~109 dirt
setblock ~14 ~112 ~110 dirt
setblock ~14 ~112 ~111 dirt
setblock ~14 ~113 ~104 dirt
setblock ~14 ~113 ~105 dirt
setblock ~14 ~113 ~106 dirt
setblock ~14 ~113 ~107 dirt
setblock ~14 ~113 ~108 dirt
setblock ~14 ~113 ~109 dirt
setblock ~14 ~113 ~110 dirt
setblock ~14 ~113 ~111 dirt
setblock ~14 ~113 ~112 dirt
setblock ~14 ~114 ~102 dirt
setblock ~14 ~114 ~103 dirt
setblock ~14 ~114 ~104 dirt
setblock ~14 ~114 ~105 dirt
setblock ~14 ~114 ~106 dirt
setblock ~14 ~114 ~107 dirt
setblock ~14 ~114 ~108 dirt
setblock ~14 ~114 ~109 dirt
setblock ~14 ~114 ~110 dirt
setblock ~14 ~114 ~111 dirt
setblock ~14 ~114 ~112 dirt
setblock ~14 ~114 ~113 dirt
setblock ~14 ~115 ~101 dirt
setblock ~14 ~115 ~102 dirt
setblock ~14 ~115 ~103 dirt
setblock ~14 ~115 ~104 dirt
setblock ~14 ~115 ~105 dirt
setblock ~14 ~115 ~106 dirt
setblock ~14 ~115 ~107 dirt
setblock ~14 ~115 ~108 dirt
setblock ~14 ~115 ~109 dirt
setblock ~14 ~115 ~110 dirt
setblock ~14 ~115 ~111 dirt
setblock ~14 ~115 ~112 dirt
setblock ~14 ~115 ~113 dirt
setblock ~14 ~115 ~114 dirt
setblock ~14 ~116 ~101 dirt
setblock ~14 ~116 ~102 dirt
setblock ~14 ~116 ~103 dirt
setblock ~14 ~116 ~104 dirt
setblock ~14 ~116 ~105 dirt
setblock ~14 ~116 ~106 dirt
setblock ~14 ~116 ~107 dirt
setblock ~14 ~116 ~108 dirt
setblock ~14 ~116 ~109 dirt
setblock ~14 ~116 ~110 dirt
setblock ~14 ~116 ~111 dirt
setblock ~14 ~116 ~112 dirt
setblock ~14 ~116 ~113 dirt
setblock ~14 ~116 ~114 dirt
setblock ~14 ~116 ~115 dirt
setblock ~14 ~117 ~100 dirt
setblock ~14 ~117 ~101 dirt
setblock ~14 ~117 ~102 dirt
setblock ~14 ~117 ~103 dirt
setblock ~14 ~117 ~104 dirt
setblock ~14 ~117 ~105 dirt
setblock ~14 ~117 ~106 dirt
setblock ~14 ~117 ~107 dirt
setblock ~14 ~117 ~108 dirt
setblock ~14 ~117 ~109 dirt
setblock ~14 ~117 ~110 dirt
setblock ~14 ~117 ~111 dirt
setblock ~14 ~117 ~112 dirt
setblock ~14 ~117 ~113 dirt
setblock ~14 ~117 ~114 dirt
setblock ~14 ~117 ~115 dirt
setblock ~14 ~117 ~116 dirt
setblock ~14 ~118 ~99 dirt
setblock ~14 ~118 ~100 dirt
setblock ~14 ~118 ~101 dirt
setblock ~14 ~118 ~102 dirt
setblock ~14 ~118 ~103 dirt
setblock ~14 ~118 ~104 dirt
setblock ~14 ~118 ~105 dirt
setblock ~14 ~118 ~106 dirt
setblock ~14 ~118 ~107 dirt
setblock ~14 ~118 ~108 dirt
setblock ~14 ~118 ~109 dirt
setblock ~14 ~118 ~110 dirt
setblock ~14 ~118 ~111 dirt
setblock ~14 ~118 ~112 dirt
setblock ~14 ~118 ~113 dirt
setblock ~14 ~118 ~114 dirt
setblock ~14 ~118 ~115 dirt
setblock ~14 ~118 ~116 dirt
setblock ~14 ~118 ~117 dirt
setblock ~14 ~119 ~98 dirt
setblock ~14 ~119 ~99 dirt
setblock ~14 ~119 ~100 dirt
setblock ~14 ~119 ~101 dirt
setblock ~14 ~119 ~102 dirt
setblock ~14 ~119 ~103 dirt
setblock ~14 ~119 ~104 dirt
setblock ~14 ~119 ~105 dirt
setblock ~14 ~119 ~106 dirt
setblock ~14 ~119 ~107 dirt
setblock ~14 ~119 ~108 dirt
setblock ~14 ~119 ~109 dirt
setblock ~14 ~119 ~110 dirt
setblock ~14 ~119 ~111 dirt
setblock ~14 ~119 ~112 dirt
setblock ~14 ~119 ~113 dirt
setblock ~14 ~119 ~114 dirt
setblock ~14 ~119 ~115 dirt
setblock ~14 ~119 ~116 dirt
setblock ~14 ~119 ~117 dirt
setblock ~14 ~119 ~118 dirt
setblock ~14 ~120 ~96 dirt
setblock ~14 ~120 ~97 dirt
setblock ~14 ~120 ~98 dirt
setblock ~14 ~120 ~99 dirt
setblock ~14 ~120 ~100 dirt
setblock ~14 ~120 ~101 dirt
setblock ~14 ~120 ~102 dirt
setblock ~14 ~120 ~103 dirt
setblock ~14 ~120 ~104 dirt
setblock ~14 ~120 ~105 dirt
setblock ~14 ~120 ~106 dirt
setblock ~14 ~120 ~107 dirt
setblock ~14 ~120 ~108 dirt
setblock ~14 ~120 ~109 dirt
setblock ~14 ~120 ~110 dirt
setblock ~14 ~120 ~111 dirt
setblock ~14 ~120 ~112 dirt
setblock ~14 ~120 ~113 dirt
setblock ~14 ~120 ~114 dirt
setblock ~14 ~120 ~115 dirt
setblock ~14 ~120 ~116 dirt
setblock ~14 ~120 ~117 dirt
setblock ~14 ~120 ~118 dirt
setblock ~14 ~121 ~95 dirt
setblock ~14 ~121 ~96 dirt
setblock ~14 ~121 ~97 dirt
setblock ~14 ~121 ~98 dirt
setblock ~14 ~121 ~99 dirt
setblock ~14 ~121 ~100 dirt
setblock ~14 ~121 ~101 dirt
setblock ~14 ~121 ~102 dirt
setblock ~14 ~121 ~103 dirt
setblock ~14 ~121 ~104 dirt
setblock ~14 ~121 ~105 dirt
setblock ~14 ~121 ~106 dirt
setblock ~14 ~121 ~107 dirt
setblock ~14 ~121 ~108 dirt
setblock ~14 ~121 ~109 dirt
setblock ~14 ~121 ~110 dirt
setblock ~14 ~121 ~111 dirt
setblock ~14 ~121 ~112 dirt
setblock ~14 ~121 ~113 dirt
setblock ~14 ~121 ~114 dirt
setblock ~14 ~121 ~115 dirt
setblock ~14 ~121 ~116 dirt
setblock ~14 ~121 ~117 dirt
setblock ~14 ~121 ~118 dirt
setblock ~14 ~121 ~119 dirt
setblock ~14 ~122 ~95 dirt
setblock ~14 ~122 ~96 dirt
setblock ~14 ~122 ~97 dirt
setblock ~14 ~122 ~98 dirt
setblock ~14 ~122 ~99 dirt
setblock ~14 ~122 ~100 dirt
setblock ~14 ~122 ~101 dirt
setblock ~14 ~122 ~102 dirt
setblock ~14 ~122 ~103 dirt
setblock ~14 ~122 ~104 dirt
setblock ~14 ~122 ~105 dirt
setblock ~14 ~122 ~106 dirt
setblock ~14 ~122 ~107 dirt
setblock ~14 ~122 ~108 dirt
setblock ~14 ~122 ~109 dirt
setblock ~14 ~122 ~110 dirt
setblock ~14 ~122 ~111 dirt
setblock ~14 ~122 ~112 dirt
setblock ~14 ~122 ~113 dirt
setblock ~14 ~122 ~114 dirt
setblock ~14 ~122 ~115 dirt
setblock ~14 ~122 ~116 dirt
setblock ~14 ~122 ~117 dirt
setblock ~14 ~122 ~118 dirt
setblock ~14 ~122 ~119 dirt
setblock ~14 ~123 ~95 dirt
setblock ~14 ~123 ~96 dirt
setblock ~14 ~123 ~97 dirt
setblock ~14 ~123 ~98 dirt
setblock ~14 ~123 ~99 grass_block
setblock ~14 ~123 ~100 grass_block
setblock ~14 ~123 ~101 grass_block
setblock ~14 ~123 ~102 dirt
setblock ~14 ~123 ~103 dirt
setblock ~14 ~123 ~104 dirt
setblock ~14 ~123 ~105 dirt
setblock ~14 ~123 ~106 dirt
setblock ~14 ~123 ~107 dirt
setblock ~14 ~123 ~108 dirt
setblock ~14 ~123 ~109 dirt
setblock ~14 ~123 ~110 dirt
setblock ~14 ~123 ~111 dirt
setblock ~14 ~123 ~112 dirt
setblock ~14 ~123 ~113 dirt
setblock ~14 ~123 ~114 dirt
setblock ~14 ~123 ~115 dirt
setblock ~14 ~123 ~116 dirt
setblock ~14 ~123 ~117 dirt
setblock ~14 ~123 ~118 dirt
setblock ~14 ~123 ~119 dirt
setblock ~14 ~124 ~95 dirt
setblock ~14 ~124 ~96 grass_block
setblock ~14 ~124 ~97 grass_block
setblock ~14 ~124 ~98 grass_block
setblock ~14 ~124 ~100 short_grass
setblock ~14 ~124 ~101 short_grass
setblock ~14 ~124 ~102 grass_block
setblock ~14 ~124 ~103 grass_block
setblock ~14 ~124 ~104 grass_block
setblock ~14 ~124 ~105 grass_block
setblock ~14 ~124 ~106 dirt
setblock ~14 ~124 ~107 dirt
setblock ~14 ~124 ~108 dirt
setblock ~14 ~124 ~109 dirt
setblock ~14 ~124 ~110 dirt
setblock ~14 ~124 ~111 dirt
setblock ~14 ~124 ~112 dirt
setblock ~14 ~124 ~113 dirt
setblock ~14 ~124 ~114 dirt
setblock ~14 ~124 ~115 dirt
setblock ~14 ~124 ~116 grass_block
setblock ~14 ~124 ~117 grass_block
setblock ~14 ~124 ~118 grass_block
setblock ~14 ~124 ~119 grass_block
setblock ~14 ~125 ~95 grass_block
setblock ~14 ~125 ~106 grass_block
setblock ~14 ~125 ~107 grass_block
setblock ~14 ~125 ~108 grass_block
setblock ~14 ~125 ~109 grass_block
setblock ~14 ~125 ~110 dirt
setblock ~14 ~125 ~111 grass_block
setblock ~14 ~125 ~112 grass_block
setblock ~14 ~125 ~113 grass_block
setblock ~14 ~125 ~114 grass_block
setblock ~14 ~125 ~115 grass_block
setblock ~14 ~126 ~107 short_grass
setblock ~14 ~126 ~110 grass_block
setblock ~14 ~126 ~113 short_grass
setblock ~15 ~109 ~108 dirt
setblock ~15 ~109 ~109 dirt
setblock ~15 ~110 ~106 dirt
setblock ~15 ~110 ~107 dirt
setblock ~15 ~110 ~108 dirt
setblock ~15 ~110 ~109 dirt
setblock ~15 ~110 ~110 dirt
setblock ~15 ~111 ~105 dirt
setblock ~15 ~111 ~106 dirt
setblock ~15 ~111 ~107 dirt
setblock ~15 ~111 ~108 dirt
setblock ~15 ~111 ~109 dirt
setblock ~15 ~111 ~110 dirt
setblock ~15 ~111 ~111 dirt
setblock ~15 ~112 ~103 dirt
setblock ~15 ~112 ~104 dirt
setblock ~15 ~112 ~105 dirt
setblock ~15 ~112 ~106 dirt
setblock ~15 ~112 ~107 dirt
setblock ~15 ~112 ~108 dirt
setblock ~15 ~112 ~109 dirt
setblock ~15 ~112 ~110 dirt
setblock ~15 ~112 ~111 dirt
setblock ~15 ~112 ~112 dirt
setblock ~15 ~113 ~102 dirt
setblock ~15 ~113 ~103 dirt
setblock ~15 ~113 ~104 dirt
setblock ~15 ~113 ~105 dirt
setblock ~15 ~113 ~106 dirt
setblock ~15 ~113 ~107 dirt
setblock ~15 ~113 ~108 dirt
setblock ~15 ~113 ~109 dirt
setblock ~15 ~113 ~110 dirt
setblock ~15 ~113 ~111 dirt
setblock ~15 ~113 ~112 dirt
setblock ~15 ~113 ~113 dirt
setblock ~15 ~114 ~101 dirt
setblock ~15 ~114 ~102 dirt
setblock ~15 ~114 ~103 dirt
setblock ~15 ~114 ~104 dirt
setblock ~15 ~114 ~105 dirt
setblock ~15 ~114 ~106 dirt
setblock ~15 ~114 ~107 dirt
setblock ~15 ~114 ~108 dirt
setblock ~15 ~114 ~109 dirt
setblock ~15 ~114 ~110 dirt
setblock ~15 ~114 ~111 dirt
setblock ~15 ~114 ~112 dirt
setblock ~15 ~114 ~113 dirt
setblock ~15 ~114 ~114 dirt
setblock ~15 ~115 ~100 dirt
setblock ~15 ~115 ~101 dirt
setblock ~15 ~115 ~102 dirt
setblock ~15 ~115 ~103 dirt
setblock ~15 ~115 ~104 dirt
setblock ~15 ~115 ~105 dirt
setblock ~15 ~115 ~106 dirt
setblock ~15 ~115 ~107 dirt
setblock ~15 ~115 ~108 dirt
setblock ~15 ~115 ~109 dirt
setblock ~15 ~115 ~110 dirt
setblock ~15 ~115 ~111 dirt
setblock ~15 ~115 ~112 dirt
setblock ~15 ~115 ~113 dirt
setblock ~15 ~115 ~114 dirt
setblock ~15 ~115 ~115 dirt
setblock ~15 ~116 ~99 dirt
setblock ~15 ~116 ~100 dirt
setblock ~15 ~116 ~101 dirt
setblock ~15 ~116 ~102 dirt
setblock ~15 ~116 ~103 dirt
setblock ~15 ~116 ~104 dirt
setblock ~15 ~116 ~105 dirt
setblock ~15 ~116 ~106 dirt
setblock ~15 ~116 ~107 dirt
setblock ~15 ~116 ~108 dirt
setblock ~15 ~116 ~109 dirt
setblock ~15 ~116 ~110 dirt
setblock ~15 ~116 ~111 dirt
setblock ~15 ~116 ~112 dirt
setblock ~15 ~116 ~113 dirt
setblock ~15 ~116 ~114 dirt
setblock ~15 ~116 ~115 dirt
setblock ~15 ~116 ~116 dirt
setblock ~15 ~117 ~98 dirt
setblock ~15 ~117 ~99 dirt
setblock ~15 ~117 ~100 dirt
setblock ~15 ~117 ~101 dirt
setblock ~15 ~117 ~102 dirt
setblock ~15 ~117 ~103 dirt
setblock ~15 ~117 ~104 dirt
setblock ~15 ~117 ~105 dirt
setblock ~15 ~117 ~106 dirt
setblock ~15 ~117 ~107 dirt
setblock ~15 ~117 ~108 dirt
setblock ~15 ~117 ~109 dirt
setblock ~15 ~117 ~110 dirt
setblock ~15 ~117 ~111 dirt
setblock ~15 ~117 ~112 dirt
setblock ~15 ~117 ~113 dirt
setblock ~15 ~117 ~114 dirt
setblock ~15 ~117 ~115 dirt
setblock ~15 ~117 ~116 dirt
setblock ~15 ~117 ~117 dirt
setblock ~15 ~118 ~97 dirt
setblock ~15 ~118 ~98 dirt
setblock ~15 ~118 ~99 dirt
setblock ~15 ~118 ~100 dirt
setblock ~15 ~118 ~101 dirt
setblock ~15 ~118 ~102 dirt
setblock ~15 ~118 ~103 dirt
setblock ~15 ~118 ~104 dirt
setblock ~15 ~118 ~105 dirt
setblock ~15 ~118 ~106 dirt
setblock ~15 ~118 ~107 dirt
setblock ~15 ~118 ~108 dirt
setblock ~15 ~118 ~109 dirt
setblock ~15 ~118 ~110 dirt
setblock ~15 ~118 ~111 dirt
setblock ~15 ~118 ~112 dirt
setblock ~15 ~118 ~113 dirt
setblock ~15 ~118 ~114 dirt
setblock ~15 ~118 ~115 dirt
setblock ~15 ~118 ~116 dirt
setblock ~15 ~118 ~117 dirt
setblock ~15 ~118 ~118 dirt
setblock ~15 ~119 ~96 dirt
setblock ~15 ~119 ~97 dirt
setblock ~15 ~119 ~98 dirt
setblock ~15 ~119 ~99 dirt
setblock ~15 ~119 ~100 dirt
setblock ~15 ~119 ~101 dirt
setblock ~15 ~119 ~102 dirt
setblock ~15 ~119 ~103 dirt
setblock ~15 ~119 ~104 dirt
setblock ~15 ~119 ~105 dirt
setblock ~15 ~119 ~106 dirt
setblock ~15 ~119 ~107 dirt
setblock ~15 ~119 ~108 dirt
setblock ~15 ~119 ~109 dirt
setblock ~15 ~119 ~110 dirt
setblock ~15 ~119 ~111 dirt
setblock ~15 ~119 ~112 dirt
setblock ~15 ~119 ~113 dirt
setblock ~15 ~119 ~114 dirt
setblock ~15 ~119 ~115 dirt
setblock ~15 ~119 ~116 dirt
setblock ~15 ~119 ~117 dirt
setblock ~15 ~119 ~118 dirt
setblock ~15 ~120 ~95 dirt
setblock ~15 ~120 ~96 dirt
setblock ~15 ~120 ~97 dirt
setblock ~15 ~120 ~98 dirt
setblock ~15 ~120 ~99 dirt
setblock ~15 ~120 ~100 dirt
setblock ~15 ~120 ~101 dirt
setblock ~15 ~120 ~102 dirt
setblock ~15 ~120 ~103 dirt
setblock ~15 ~120 ~104 dirt
setblock ~15 ~120 ~105 dirt
setblock ~15 ~120 ~106 dirt
setblock ~15 ~120 ~107 dirt
setblock ~15 ~120 ~108 dirt
setblock ~15 ~120 ~109 dirt
setblock ~15 ~120 ~110 dirt
setblock ~15 ~120 ~111 dirt
setblock ~15 ~120 ~112 dirt
setblock ~15 ~120 ~113 dirt
setblock ~15 ~120 ~114 dirt
setblock ~15 ~120 ~115 dirt
setblock ~15 ~120 ~116 dirt
setblock ~15 ~120 ~117 dirt
setblock ~15 ~120 ~118 dirt
setblock ~15 ~120 ~119 dirt
setblock ~15 ~121 ~95 dirt
setblock ~15 ~121 ~96 dirt
setblock ~15 ~121 ~97 dirt
setblock ~15 ~121 ~98 dirt
setblock ~15 ~121 ~99 dirt
setblock ~15 ~121 ~100 dirt
setblock ~15 ~121 ~101 dirt
setblock ~15 ~121 ~102 dirt
setblock ~15 ~121 ~103 dirt
setblock ~15 ~121 ~104 dirt
setblock ~15 ~121 ~105 dirt
setblock ~15 ~121 ~106 dirt
setblock ~15 ~121 ~107 dirt
setblock ~15 ~121 ~108 dirt
setblock ~15 ~121 ~109 dirt
setblock ~15 ~121 ~110 dirt
setblock ~15 ~121 ~111 dirt
setblock ~15 ~121 ~112 dirt
setblock ~15 ~121 ~113 dirt
setblock ~15 ~121 ~114 dirt
setblock ~15 ~121 ~115 dirt
setblock ~15 ~121 ~116 dirt
setblock ~15 ~121 ~117 dirt
setblock ~15 ~121 ~118 dirt
setblock ~15 ~121 ~119 dirt
setblock ~15 ~121 ~120 dirt
setblock ~15 ~122 ~95 dirt
setblock ~15 ~122 ~96 dirt
setblock ~15 ~122 ~97 dirt
setblock ~15 ~122 ~98 dirt
setblock ~15 ~122 ~99 dirt
setblock ~15 ~122 ~100 dirt
setblock ~15 ~122 ~101 dirt
setblock ~15 ~122 ~102 dirt
setblock ~15 ~122 ~103 dirt
setblock ~15 ~122 ~104 dirt
setblock ~15 ~122 ~105 dirt
setblock ~15 ~122 ~106 dirt
setblock ~15 ~122 ~107 dirt
setblock ~15 ~122 ~108 dirt
setblock ~15 ~122 ~109 dirt
setblock ~15 ~122 ~110 dirt
setblock ~15 ~122 ~111 dirt
setblock ~15 ~122 ~112 dirt
setblock ~15 ~122 ~113 dirt
setblock ~15 ~122 ~114 dirt
setblock ~15 ~122 ~115 dirt
setblock ~15 ~122 ~116 dirt
setblock ~15 ~122 ~117 dirt
setblock ~15 ~122 ~118 dirt
setblock ~15 ~122 ~119 dirt
setblock ~15 ~122 ~120 dirt
setblock ~15 ~123 ~95 dirt
setblock ~15 ~123 ~96 dirt
setblock ~15 ~123 ~97 dirt
setblock ~15 ~123 ~98 dirt
setblock ~15 ~123 ~99 dirt
setblock ~15 ~123 ~100 grass_block
setblock ~15 ~123 ~101 dirt
setblock ~15 ~123 ~102 dirt
setblock ~15 ~123 ~103 dirt
setblock ~15 ~123 ~104 dirt
setblock ~15 ~123 ~105 dirt
setblock ~15 ~123 ~106 dirt
setblock ~15 ~123 ~107 dirt
setblock ~15 ~123 ~108 dirt
setblock ~15 ~123 ~109 dirt
setblock ~15 ~123 ~110 dirt
setblock ~15 ~123 ~111 dirt
setblock ~15 ~123 ~112 dirt
setblock ~15 ~123 ~113 dirt
setblock ~15 ~123 ~114 dirt
setblock ~15 ~123 ~115 dirt
setblock ~15 ~123 ~116 dirt
setblock ~15 ~123 ~117 dirt
setblock ~15 ~123 ~118 dirt
setblock ~15 ~123 ~119 dirt
setblock ~15 ~123 ~120 grass_block
setblock ~15 ~124 ~95 dirt
setblock ~15 ~124 ~96 grass_block
setblock ~15 ~124 ~97 grass_block
setblock ~15 ~124 ~98 grass_block
setblock ~15 ~124 ~99 grass_block
setblock ~15 ~124 ~100 short_grass
setblock ~15 ~124 ~101 grass_block
setblock ~15 ~124 ~102 grass_block
setblock ~15 ~124 ~103 grass_block
setblock ~15 ~124 ~104 grass_block
setblock ~15 ~124 ~105 dirt
setblock ~15 ~124 ~106 dirt
setblock ~15 ~124 ~107 dirt
setblock ~15 ~124 ~108 dirt
setblock ~15 ~124 ~109 dirt
setblock ~15 ~124 ~110 dirt
setblock ~15 ~124 ~111 dirt
setblock ~15 ~124 ~112 dirt
setblock ~15 ~124 ~113 dirt
setblock ~15 ~124 ~114 dirt
setblock ~15 ~124 ~115 dirt
setblock ~15 ~124 ~116 grass_block
setblock ~15 ~124 ~117 grass_block
setblock ~15 ~124 ~118 grass_block
setblock ~15 ~124 ~119 grass_block
setblock ~15 ~125 ~95 grass_block
setblock ~15 ~125 ~98 poppy
setblock ~15 ~125 ~99 short_grass
setblock ~15 ~125 ~101 short_grass
setblock ~15 ~125 ~102 short_grass
setblock ~15 ~125 ~103 short_grass
setblock ~15 ~125 ~105 grass_block
setblock ~15 ~125 ~106 grass_block
setblock ~15 ~125 ~107 grass_block
setblock ~15 ~125 ~108 grass_block
setblock ~15 ~125 ~109 dirt
setblock ~15 ~125 ~110 dirt
setblock ~15 ~125 ~111 dirt
setblock ~15 ~125 ~112 grass_block
setblock ~15 ~125 ~113 grass_block
setblock ~15 ~125 ~114 grass_block
setblock ~15 ~125 ~115 grass_block
setblock ~15 ~125 ~117 short_grass
setblock ~15 ~125 ~119 short_grass
setblock ~15 ~126 ~109 grass_block
setblock ~15 ~126 ~110 grass_block
setblock ~15 ~126 ~111 grass_block
setblock ~15 ~127 ~110 short_grass
setblock ~16 ~107 ~108 dirt
setblock ~16 ~108 ~107 dirt
setblock ~16 ~108 ~108 dirt
setblock ~16 ~108 ~109 dirt
setblock ~16 ~109 ~106 dirt
setblock ~16 ~109 ~107 dirt
setblock ~16 ~109 ~108 dirt
setblock ~16 ~109 ~109 dirt
setblock ~16 ~109 ~110 dirt
setblock ~16 ~110 ~105 dirt
setblock ~16 ~110 ~106 dirt
setblock ~16 ~110 ~107 dirt
setblock ~16 ~110 ~108 dirt
setblock ~16 ~110 ~109 dirt
setblock ~16 ~110 ~110 dirt
setblock ~16 ~110 ~111 dirt
setblock ~16 ~111 ~103 dirt
setblock ~16 ~111 ~104 dirt
setblock ~16 ~111 ~105 dirt
setblock ~16 ~111 ~106 dirt
setblock ~16 ~111 ~107 dirt
setblock ~16 ~111 ~108 dirt
setblock ~16 ~111 ~109 dirt
setblock ~16 ~111 ~110 dirt
setblock ~16 ~111 ~111 dirt
setblock ~16 ~111 ~112 dirt
setblock ~16 ~112 ~102 dirt
setblock ~16 ~112 ~103 dirt
setblock ~16 ~112 ~104 dirt
setblock ~16 ~112 ~105 dirt
setblock ~16 ~112 ~106 dirt
setblock ~16 ~112 ~107 dirt
setblock ~16 ~112 ~108 dirt
setblock ~16 ~112 ~109 dirt
setblock ~16 ~112 ~110 dirt
setblock ~16 ~112 ~111 dirt
setblock ~16 ~112 ~112 dirt
setblock ~16 ~112 ~113 dirt
setblock ~16 ~113 ~101 dirt
setblock ~16 ~113 ~102 dirt
setblock ~16 ~113 ~103 dirt
setblock ~16 ~113 ~104 dirt
setblock ~16 ~113 ~105 dirt
setblock ~16 ~113 ~106 dirt
setblock ~16 ~113 ~107 dirt
setblock ~16 ~113 ~108 dirt
setblock ~16 ~113 ~109 dirt
setblock ~16 ~113 ~110 dirt
setblock ~16 ~113 ~111 dirt
setblock ~16 ~113 ~112 dirt
setblock ~16 ~113 ~113 dirt
setblock ~16 ~113 ~114 dirt
setblock ~16 ~114 ~100 dirt
setblock ~16 ~114 ~101 dirt
setblock ~16 ~114 ~102 dirt
setblock ~16 ~114 ~103 dirt
setblock ~16 ~114 ~104 dirt
setblock ~16 ~114 ~105 dirt
setblock ~16 ~114 ~106 dirt
setblock ~16 ~114 ~107 dirt
setblock ~16 ~114 ~108 dirt
setblock ~16 ~114 ~109 dirt
setblock ~16 ~114 ~110 dirt
setblock ~16 ~114 ~111 dirt
setblock ~16 ~114 ~112 dirt
setblock ~16 ~114 ~113 dirt
setblock ~16 ~114 ~114 dirt
setblock ~16 ~114 ~115 dirt
setblock ~16 ~115 ~99 dirt
setblock ~16 ~115 ~100 dirt
setblock ~16 ~115 ~101 dirt
setblock ~16 ~115 ~102 dirt
setblock ~16 ~115 ~103 dirt
setblock ~16 ~115 ~104 dirt
setblock ~16 ~115 ~105 dirt
setblock ~16 ~115 ~106 dirt
setblock ~16 ~115 ~107 dirt
setblock ~16 ~115 ~108 dirt
setblock ~16 ~115 ~109 dirt
setblock ~16 ~115 ~110 dirt
setblock ~16 ~115 ~111 dirt
setblock ~16 ~115 ~112 dirt
setblock ~16 ~115 ~113 dirt
setblock ~16 ~115 ~114 dirt
setblock ~16 ~115 ~115 dirt
setblock ~16 ~116 ~98 dirt
setblock ~16 ~116 ~99 dirt
setblock ~16 ~116 ~100 dirt
setblock ~16 ~116 ~101 dirt
setblock ~16 ~116 ~102 dirt
setblock ~16 ~116 ~103 dirt
setblock ~16 ~116 ~104 dirt
setblock ~16 ~116 ~105 dirt
setblock ~16 ~116 ~106 dirt
setblock ~16 ~116 ~107 dirt
setblock ~16 ~116 ~108 dirt
setblock ~16 ~116 ~109 dirt
setblock ~16 ~116 ~110 dirt
setblock ~16 ~116 ~111 dirt
setblock ~16 ~116 ~112 dirt
setblock ~16 ~116 ~113 dirt
setblock ~16 ~116 ~114 dirt
setblock ~16 ~116 ~115 dirt
setblock ~16 ~116 ~116 dirt
setblock ~16 ~117 ~97 dirt
setblock ~16 ~117 ~98 dirt
setblock ~16 ~117 ~99 dirt
setblock ~16 ~117 ~100 dirt
setblock ~16 ~117 ~101 dirt
setblock ~16 ~117 ~102 dirt
setblock ~16 ~117 ~103 dirt
setblock ~16 ~117 ~104 dirt
setblock ~16 ~117 ~105 dirt
setblock ~16 ~117 ~106 dirt
setblock ~16 ~117 ~107 dirt
setblock ~16 ~117 ~108 dirt
setblock ~16 ~117 ~109 dirt
setblock ~16 ~117 ~110 dirt
setblock ~16 ~117 ~111 dirt
setblock ~16 ~117 ~112 dirt
setblock ~16 ~117 ~113 dirt
setblock ~16 ~117 ~114 dirt
setblock ~16 ~117 ~115 dirt
setblock ~16 ~117 ~116 dirt
setblock ~16 ~117 ~117 dirt
setblock ~16 ~118 ~96 dirt
setblock ~16 ~118 ~97 dirt
setblock ~16 ~118 ~98 dirt
setblock ~16 ~118 ~99 dirt
setblock ~16 ~118 ~100 dirt
setblock ~16 ~118 ~101 dirt
setblock ~16 ~118 ~102 dirt
setblock ~16 ~118 ~103 dirt
setblock ~16 ~118 ~104 dirt
setblock ~16 ~118 ~105 dirt
setblock ~16 ~118 ~106 dirt
setblock ~16 ~118 ~107 dirt
setblock ~16 ~118 ~108 dirt
setblock ~16 ~118 ~109 dirt
setblock ~16 ~118 ~110 dirt
setblock ~16 ~118 ~111 dirt
setblock ~16 ~118 ~112 dirt
setblock ~16 ~118 ~113 dirt
setblock ~16 ~118 ~114 dirt
setblock ~16 ~118 ~115 dirt
setblock ~16 ~118 ~116 dirt
setblock ~16 ~118 ~117 dirt
setblock ~16 ~118 ~118 dirt
setblock ~16 ~119 ~95 dirt
setblock ~16 ~119 ~96 dirt
setblock ~16 ~119 ~97 dirt
setblock ~16 ~119 ~98 dirt
setblock ~16 ~119 ~99 dirt
setblock ~16 ~119 ~100 dirt
setblock ~16 ~119 ~101 dirt
setblock ~16 ~119 ~102 dirt
setblock ~16 ~119 ~103 dirt
setblock ~16 ~119 ~104 dirt
setblock ~16 ~119 ~105 dirt
setblock ~16 ~119 ~106 dirt
setblock ~16 ~119 ~107 dirt
setblock ~16 ~119 ~108 dirt
setblock ~16 ~119 ~109 dirt
setblock ~16 ~119 ~110 dirt
setblock ~16 ~119 ~111 dirt
setblock ~16 ~119 ~112 dirt
setblock ~16 ~119 ~113 dirt
setblock ~16 ~119 ~114 dirt
setblock ~16 ~119 ~115 dirt
setblock ~16 ~119 ~116 dirt
setblock ~16 ~119 ~117 dirt
setblock ~16 ~119 ~118 dirt
setblock ~16 ~119 ~119 dirt
setblock ~16 ~120 ~95 dirt
setblock ~16 ~120 ~96 dirt
setblock ~16 ~120 ~97 dirt
setblock ~16 ~120 ~98 dirt
setblock ~16 ~120 ~99 dirt
setblock ~16 ~120 ~100 dirt
setblock ~16 ~120 ~101 dirt
setblock ~16 ~120 ~102 dirt
setblock ~16 ~120 ~103 dirt
setblock ~16 ~120 ~104 dirt
setblock ~16 ~120 ~105 dirt
setblock ~16 ~120 ~106 dirt
setblock ~16 ~120 ~107 dirt
setblock ~16 ~120 ~108 dirt
setblock ~16 ~120 ~109 dirt
setblock ~16 ~120 ~110 dirt
setblock ~16 ~120 ~111 dirt
setblock ~16 ~120 ~112 dirt
setblock ~16 ~120 ~113 dirt
setblock ~16 ~120 ~114 dirt
setblock ~16 ~120 ~115 dirt
setblock ~16 ~120 ~116 dirt
setblock ~16 ~120 ~117 dirt
setblock ~16 ~120 ~118 dirt
setblock ~16 ~120 ~119 dirt
setblock ~16 ~121 ~94 dirt
setblock ~16 ~121 ~95 dirt
setblock ~16 ~121 ~96 dirt
setblock ~16 ~121 ~97 dirt
setblock ~16 ~121 ~98 dirt
setblock ~16 ~121 ~99 dirt
setblock ~16 ~121 ~100 dirt
setblock ~16 ~121 ~101 dirt
setblock ~16 ~121 ~102 dirt
setblock ~16 ~121 ~103 dirt
setblock ~16 ~121 ~104 dirt
setblock ~16 ~121 ~105 dirt
setblock ~16 ~121 ~106 dirt
setblock ~16 ~121 ~107 dirt
setblock ~16 ~121 ~108 dirt
setblock ~16 ~121 ~109 dirt
setblock ~16 ~121 ~110 dirt
setblock ~16 ~121 ~111 dirt
setblock ~16 ~121 ~112 dirt
setblock ~16 ~121 ~113 dirt
setblock ~16 ~121 ~114 dirt
setblock ~16 ~121 ~115 dirt
setblock ~16 ~121 ~116 dirt
setblock ~16 ~121 ~117 dirt
setblock ~16 ~121 ~118 dirt
setblock ~16 ~121 ~119 dirt
setblock ~16 ~121 ~120 dirt
setblock ~16 ~122 ~94 dirt
setblock ~16 ~122 ~95 dirt
setblock ~16 ~122 ~96 dirt
setblock ~16 ~122 ~97 dirt
setblock ~16 ~122 ~98 dirt
setblock ~16 ~122 ~99 dirt
setblock ~16 ~122 ~100 dirt
setblock ~16 ~122 ~101 dirt
setblock ~16 ~122 ~102 dirt
setblock ~16 ~122 ~103 dirt
setblock ~16 ~122 ~104 dirt
setblock ~16 ~122 ~105 dirt
setblock ~16 ~122 ~106 dirt
setblock ~16 ~122 ~107 dirt
setblock ~16 ~122 ~108 dirt
setblock ~16 ~122 ~109 dirt
setblock ~16 ~122 ~110 dirt
setblock ~16 ~122 ~111 dirt
setblock ~16 ~122 ~112 dirt
setblock ~16 ~122 ~113 dirt
setblock ~16 ~122 ~114 dirt
setblock ~16 ~122 ~115 dirt
setblock ~16 ~122 ~116 dirt
setblock ~16 ~122 ~117 dirt
setblock ~16 ~122 ~118 dirt
setblock ~16 ~122 ~119 dirt
setblock ~16 ~122 ~120 dirt
setblock ~16 ~123 ~94 dirt
setblock ~16 ~123 ~95 dirt
setblock ~16 ~123 ~96 dirt
setblock ~16 ~123 ~97 dirt
setblock ~16 ~123 ~98 dirt
setblock ~16 ~123 ~99 dirt
setblock ~16 ~123 ~100 dirt
setblock ~16 ~123 ~101 dirt
setblock ~16 ~123 ~102 dirt
setblock ~16 ~123 ~103 dirt
setblock ~16 ~123 ~104 dirt
setblock ~16 ~123 ~105 dirt
setblock ~16 ~123 ~106 dirt
setblock ~16 ~123 ~107 dirt
setblock ~16 ~123 ~108 dirt
setblock ~16 ~123 ~109 dirt
setblock ~16 ~123 ~110 dirt
setblock ~16 ~123 ~111 dirt
setblock ~16 ~123 ~112 dirt
setblock ~16 ~123 ~113 dirt
setblock ~16 ~123 ~114 dirt
setblock ~16 ~123 ~115 dirt
setblock ~16 ~123 ~116 dirt
setblock ~16 ~123 ~117 dirt
setblock ~16 ~123 ~118 dirt
setblock ~16 ~123 ~119 grass_block
setblock ~16 ~123 ~120 grass_block
setblock ~16 ~124 ~94 dirt
setblock ~16 ~124 ~95 dirt
setblock ~16 ~124 ~96 dirt
setblock ~16 ~124 ~97 grass_block
setblock ~16 ~124 ~98 grass_block
setblock ~16 ~124 ~99 grass_block
setblock ~16 ~124 ~100 grass_block
setblock ~16 ~124 ~101 grass_block
setblock ~16 ~124 ~102 grass_block
setblock ~16 ~124 ~103 grass_block
setblock ~16 ~124 ~104 grass_block
setblock ~16 ~124 ~105 dirt
setblock ~16 ~124 ~106 dirt
setblock ~16 ~124 ~107 dirt
setblock ~16 ~124 ~108 dirt
setblock ~16 ~124 ~109 dirt
setblock ~16 ~124 ~110 dirt
setblock ~16 ~124 ~111 dirt
setblock ~16 ~124 ~112 dirt
setblock ~16 ~124 ~113 dirt
setblock ~16 ~124 ~114 dirt
setblock ~16 ~124 ~115 grass_block
setblock ~16 ~124 ~116 grass_block
setblock ~16 ~124 ~117 grass_block
setblock ~16 ~124 ~118 grass_block
setblock ~16 ~125 ~94 grass_block
setblock ~16 ~125 ~95 grass_block
setblock ~16 ~125 ~96 grass_block
setblock ~16 ~125 ~98 short_grass
setblock ~16 ~125 ~100 short_grass
setblock ~16 ~125 ~105 grass_block
setblock ~16 ~125 ~106 grass_block
setblock ~16 ~125 ~107 grass_block
setblock ~16 ~125 ~108 dirt
setblock ~16 ~125 ~109 dirt
setblock ~16 ~125 ~110 dirt
setblock ~16 ~125 ~111 dirt
setblock ~16 ~125 ~112 grass_block
setblock ~16 ~125 ~113 grass_block
setblock ~16 ~125 ~114 grass_block
setblock ~16 ~125 ~116 short_grass
setblock ~16 ~125 ~118 short_grass
setblock ~16 ~126 ~108 grass_block
setblock ~16 ~126 ~109 grass_block
setblock ~16 ~126 ~110 grass_block
setblock ~16 ~126 ~111 grass_block
setblock ~16 ~127 ~108 short_grass
setblock ~16 ~127 ~111 short_grass
setblock ~17 ~106 ~108 dirt
setblock ~17 ~106 ~109 dirt
setblock ~17 ~107 ~106 dirt
setblock ~17 ~107 ~107 dirt
setblock ~17 ~107 ~108 dirt
setblock ~17 ~107 ~109 dirt
setblock ~17 ~107 ~110 dirt
setblock ~17 ~108 ~106 dirt
setblock ~17 ~108 ~107 dirt
setblock ~17 ~108 ~108 dirt
setblock ~17 ~108 ~109 dirt
setblock ~17 ~108 ~110 dirt
setblock ~17 ~108 ~111 dirt
setblock ~17 ~109 ~105 dirt
setblock ~17 ~109 ~106 dirt
setblock ~17 ~109 ~107 dirt
setblock ~17 ~109 ~108 dirt
setblock ~17 ~109 ~109 dirt
setblock ~17 ~109 ~110 dirt
setblock ~17 ~109 ~111 dirt
setblock ~17 ~110 ~103 dirt
setblock ~17 ~110 ~104 dirt
setblock ~17 ~110 ~105 dirt
setblock ~17 ~110 ~106 dirt
setblock ~17 ~110 ~107 dirt
setblock ~17 ~110 ~108 dirt
setblock ~17 ~110 ~109 dirt
setblock ~17 ~110 ~110 dirt
setblock ~17 ~110 ~111 dirt
setblock ~17 ~110 ~112 dirt
setblock ~17 ~111 ~102 dirt
setblock ~17 ~111 ~103 dirt
setblock ~17 ~111 ~104 dirt
setblock ~17 ~111 ~105 dirt
setblock ~17 ~111 ~106 dirt
setblock ~17 ~111 ~107 dirt
setblock ~17 ~111 ~108 dirt
setblock ~17 ~111 ~109 dirt
setblock ~17 ~111 ~110 dirt
setblock ~17 ~111 ~111 dirt
setblock ~17 ~111 ~112 dirt
setblock ~17 ~111 ~113 dirt
setblock ~17 ~112 ~101 dirt
setblock ~17 ~112 ~102 dirt
setblock ~17 ~112 ~103 dirt
setblock ~17 ~112 ~104 dirt
setblock ~17 ~112 ~105 dirt
setblock ~17 ~112 ~106 dirt
setblock ~17 ~112 ~107 dirt
setblock ~17 ~112 ~108 dirt
setblock ~17 ~112 ~109 dirt
setblock ~17 ~112 ~110 dirt
setblock ~17 ~112 ~111 dirt
setblock ~17 ~112 ~112 dirt
setblock ~17 ~112 ~113 dirt
setblock ~17 ~112 ~114 dirt
setblock ~17 ~113 ~100 dirt
setblock ~17 ~113 ~101 dirt
setblock ~17 ~113 ~102 dirt
setblock ~17 ~113 ~103 dirt
setblock ~17 ~113 ~104 dirt
setblock ~17 ~113 ~105 dirt
setblock ~17 ~113 ~106 dirt
setblock ~17 ~113 ~107 dirt
setblock ~17 ~113 ~108 dirt
setblock ~17 ~113 ~109 dirt
setblock ~17 ~113 ~110 dirt
setblock ~17 ~113 ~111 dirt
setblock ~17 ~113 ~112 dirt
setblock ~17 ~113 ~113 dirt
setblock ~17 ~113 ~114 dirt
setblock ~17 ~113 ~115 dirt
setblock ~17 ~114 ~99 dirt
setblock ~17 ~114 ~100 dirt
setblock ~17 ~114 ~101 dirt
setblock ~17 ~114 ~102 dirt
setblock ~17 ~114 ~103 dirt
setblock ~17 ~114 ~104 dirt
setblock ~17 ~114 ~105 dirt
setblock ~17 ~114 ~106 dirt
setblock ~17 ~114 ~107 dirt
setblock ~17 ~114 ~108 dirt
setblock ~17 ~114 ~109 dirt
setblock ~17 ~114 ~110 dirt
setblock ~17 ~114 ~111 dirt
setblock ~17 ~114 ~112 dirt
setblock ~17 ~114 ~113 dirt
setblock ~17 ~114 ~114 dirt
setblock ~17 ~114 ~115 dirt
setblock ~17 ~114 ~116 dirt
setblock ~17 ~115 ~98 dirt
setblock ~17 ~115 ~99 dirt
setblock ~17 ~115 ~100 dirt
setblock ~17 ~115 ~101 dirt
setblock ~17 ~115 ~102 dirt
setblock ~17 ~115 ~103 dirt
setblock ~17 ~115 ~104 dirt
setblock ~17 ~115 ~105 dirt
setblock ~17 ~115 ~106 dirt
setblock ~17 ~115 ~107 dirt
setblock ~17 ~115 ~108 dirt
setblock ~17 ~115 ~109 dirt
setblock ~17 ~115 ~110 dirt
setblock ~17 ~115 ~111 dirt
setblock ~17 ~115 ~112 dirt
setblock ~17 ~115 ~113 dirt
setblock ~17 ~115 ~114 dirt
setblock ~17 ~115 ~115 dirt
setblock ~17 ~115 ~116 dirt
setblock ~17 ~116 ~97 dirt
setblock ~17 ~116 ~98 dirt
setblock ~17 ~116 ~99 dirt
setblock ~17 ~116 ~100 dirt
setblock ~17 ~116 ~101 dirt
setblock ~17 ~116 ~102 dirt
setblock ~17 ~116 ~103 dirt
setblock ~17 ~116 ~104 dirt
setblock ~17 ~116 ~105 dirt
setblock ~17 ~116 ~106 dirt
setblock ~17 ~116 ~107 dirt
setblock ~17 ~116 ~108 dirt
setblock ~17 ~116 ~109 dirt
setblock ~17 ~116 ~110 dirt
setblock ~17 ~116 ~111 dirt
setblock ~17 ~116 ~112 dirt
setblock ~17 ~116 ~113 dirt
setblock ~17 ~116 ~114 dirt
setblock ~17 ~116 ~115 dirt
setblock ~17 ~116 ~116 dirt
setblock ~17 ~116 ~117 dirt
setblock ~17 ~117 ~96 dirt
setblock ~17 ~117 ~97 dirt
setblock ~17 ~117 ~98 dirt
setblock ~17 ~117 ~99 dirt
setblock ~17 ~117 ~100 dirt
setblock ~17 ~117 ~101 dirt
setblock ~17 ~117 ~102 dirt
setblock ~17 ~117 ~103 dirt
setblock ~17 ~117 ~104 dirt
setblock ~17 ~117 ~105 dirt
setblock ~17 ~117 ~106 dirt
setblock ~17 ~117 ~107 dirt
setblock ~17 ~117 ~108 dirt
setblock ~17 ~117 ~109 dirt
setblock ~17 ~117 ~110 dirt
setblock ~17 ~117 ~111 dirt
setblock ~17 ~117 ~112 dirt
setblock ~17 ~117 ~113 dirt
setblock ~17 ~117 ~114 dirt
setblock ~17 ~117 ~115 dirt
setblock ~17 ~117 ~116 dirt
setblock ~17 ~117 ~117 dirt
setblock ~17 ~117 ~118 dirt
setblock ~17 ~118 ~95 dirt
setblock ~17 ~118 ~96 dirt
setblock ~17 ~118 ~97 dirt
setblock ~17 ~118 ~98 dirt
setblock ~17 ~118 ~99 dirt
setblock ~17 ~118 ~100 dirt
setblock ~17 ~118 ~101 dirt
setblock ~17 ~118 ~102 dirt
setblock ~17 ~118 ~103 dirt
setblock ~17 ~118 ~104 dirt
setblock ~17 ~118 ~105 dirt
setblock ~17 ~118 ~106 dirt
setblock ~17 ~118 ~107 dirt
setblock ~17 ~118 ~108 dirt
setblock ~17 ~118 ~109 dirt
setblock ~17 ~118 ~110 dirt
setblock ~17 ~118 ~111 dirt
setblock ~17 ~118 ~112 dirt
setblock ~17 ~118 ~113 dirt
setblock ~17 ~118 ~114 dirt
setblock ~17 ~118 ~115 dirt
setblock ~17 ~118 ~116 dirt
setblock ~17 ~118 ~117 dirt
setblock ~17 ~118 ~118 dirt
setblock ~17 ~118 ~119 dirt
setblock ~17 ~119 ~95 dirt
setblock ~17 ~119 ~96 dirt
setblock ~17 ~119 ~97 dirt
setblock ~17 ~119 ~98 dirt
setblock ~17 ~119 ~99 dirt
setblock ~17 ~119 ~100 dirt
setblock ~17 ~119 ~101 dirt
setblock ~17 ~119 ~102 dirt
setblock ~17 ~119 ~103 dirt
setblock ~17 ~119 ~104 dirt
setblock ~17 ~119 ~105 dirt
setblock ~17 ~119 ~106 dirt
setblock ~17 ~119 ~107 dirt
setblock ~17 ~119 ~108 dirt
setblock ~17 ~119 ~109 dirt
setblock ~17 ~119 ~110 dirt
setblock ~17 ~119 ~111 dirt
setblock ~17 ~119 ~112 dirt
setblock ~17 ~119 ~113 dirt
setblock ~17 ~119 ~114 dirt
setblock ~17 ~119 ~115 dirt
setblock ~17 ~119 ~116 dirt
setblock ~17 ~119 ~117 dirt
setblock ~17 ~119 ~118 dirt
setblock ~17 ~119 ~119 dirt
