setblock ~137 ~122 ~109 dirt
setblock ~137 ~122 ~110 dirt
setblock ~137 ~122 ~111 dirt
setblock ~137 ~122 ~112 dirt
setblock ~137 ~122 ~113 dirt
setblock ~137 ~122 ~114 dirt
setblock ~137 ~122 ~115 dirt
setblock ~137 ~122 ~116 dirt
setblock ~137 ~122 ~117 dirt
setblock ~137 ~122 ~118 dirt
setblock ~137 ~122 ~119 dirt
setblock ~137 ~122 ~120 dirt
setblock ~137 ~122 ~121 dirt
setblock ~137 ~123 ~77 dirt
setblock ~137 ~123 ~78 dirt
setblock ~137 ~123 ~79 dirt
setblock ~137 ~123 ~80 dirt
setblock ~137 ~123 ~81 dirt
setblock ~137 ~123 ~82 dirt
setblock ~137 ~123 ~83 dirt
setblock ~137 ~123 ~84 dirt
setblock ~137 ~123 ~85 dirt
setblock ~137 ~123 ~86 dirt
setblock ~137 ~123 ~87 dirt
setblock ~137 ~123 ~88 dirt
setblock ~137 ~123 ~89 dirt
setblock ~137 ~123 ~90 dirt
setblock ~137 ~123 ~91 dirt
setblock ~137 ~123 ~92 dirt
setblock ~137 ~123 ~93 dirt
setblock ~137 ~123 ~94 dirt
setblock ~137 ~123 ~95 dirt
setblock ~137 ~123 ~96 dirt
setblock ~137 ~123 ~97 dirt
setblock ~137 ~123 ~98 dirt
setblock ~137 ~123 ~99 dirt
setblock ~137 ~123 ~100 dirt
setblock ~137 ~123 ~101 dirt
setblock ~137 ~123 ~102 dirt
setblock ~137 ~123 ~103 dirt
setblock ~137 ~123 ~104 dirt
setblock ~137 ~123 ~105 dirt
setblock ~137 ~123 ~106 dirt
setblock ~137 ~123 ~107 dirt
setblock ~137 ~123 ~108 dirt
setblock ~137 ~123 ~109 dirt
setblock ~137 ~123 ~110 dirt
setblock ~137 ~123 ~111 dirt
setblock ~137 ~123 ~112 dirt
setblock ~137 ~123 ~113 dirt
setblock ~137 ~123 ~114 dirt
setblock ~137 ~123 ~115 dirt
setblock ~137 ~123 ~116 dirt
setblock ~137 ~123 ~117 dirt
setblock ~137 ~123 ~118 dirt
setblock ~137 ~123 ~119 dirt
setblock ~137 ~123 ~120 dirt
setblock ~137 ~123 ~121 dirt
setblock ~137 ~124 ~77 dirt
setblock ~137 ~124 ~78 dirt
setblock ~137 ~124 ~79 dirt
setblock ~137 ~124 ~80 dirt
setblock ~137 ~124 ~81 dirt
setblock ~137 ~124 ~82 dirt
setblock ~137 ~124 ~83 dirt
setblock ~137 ~124 ~84 dirt
setblock ~137 ~124 ~85 dirt
setblock ~137 ~124 ~86 dirt
setblock ~137 ~124 ~87 dirt
setblock ~137 ~124 ~88 dirt
setblock ~137 ~124 ~89 dirt
setblock ~137 ~124 ~90 dirt
setblock ~137 ~124 ~91 dirt
setblock ~137 ~124 ~92 dirt
setblock ~137 ~124 ~93 dirt
setblock ~137 ~124 ~94 dirt
setblock ~137 ~124 ~95 dirt
setblock ~137 ~124 ~96 dirt
setblock ~137 ~124 ~97 dirt
setblock ~137 ~124 ~98 dirt
setblock ~137 ~124 ~99 dirt
setblock ~137 ~124 ~100 dirt
setblock ~137 ~124 ~101 dirt
setblock ~137 ~124 ~102 dirt
setblock ~137 ~124 ~103 dirt
setblock ~137 ~124 ~104 dirt
setblock ~137 ~124 ~105 dirt
setblock ~137 ~124 ~106 dirt
setblock ~137 ~124 ~107 dirt
setblock ~137 ~124 ~108 dirt
setblock ~137 ~124 ~109 dirt
setblock ~137 ~124 ~110 dirt
setblock ~137 ~124 ~111 dirt
setblock ~137 ~124 ~112 dirt
setblock ~137 ~124 ~113 dirt
setblock ~137 ~124 ~114 dirt
setblock ~137 ~124 ~115 dirt
setblock ~137 ~124 ~116 dirt
setblock ~137 ~124 ~117 dirt
setblock ~137 ~124 ~118 dirt
setblock ~137 ~124 ~119 dirt
setblock ~137 ~124 ~120 dirt
setblock ~137 ~124 ~121 dirt
setblock ~137 ~125 ~77 grass_block
setblock ~137 ~125 ~78 dirt
setblock ~137 ~125 ~79 dirt
setblock ~137 ~125 ~80 dirt
setblock ~137 ~125 ~81 dirt
setblock ~137 ~125 ~82 dirt
setblock ~137 ~125 ~83 dirt
setblock ~137 ~125 ~84 dirt
setblock ~137 ~125 ~85 dirt
setblock ~137 ~125 ~86 dirt
setblock ~137 ~125 ~87 dirt
setblock ~137 ~125 ~88 dirt
setblock ~137 ~125 ~89 dirt
setblock ~137 ~125 ~90 dirt
setblock ~137 ~125 ~91 dirt
setblock ~137 ~125 ~92 dirt
setblock ~137 ~125 ~93 dirt
setblock ~137 ~125 ~94 dirt
setblock ~137 ~125 ~95 dirt
setblock ~137 ~125 ~96 dirt
setblock ~137 ~125 ~97 dirt
setblock ~137 ~125 ~98 grass_block
setblock ~137 ~125 ~99 grass_block
setblock ~137 ~125 ~100 grass_block
setblock ~137 ~125 ~101 grass_block
setblock ~137 ~125 ~102 dirt
setblock ~137 ~125 ~103 dirt
setblock ~137 ~125 ~104 dirt
setblock ~137 ~125 ~105 dirt
setblock ~137 ~125 ~106 dirt
setblock ~137 ~125 ~107 dirt
setblock ~137 ~125 ~108 dirt
setblock ~137 ~125 ~109 dirt
setblock ~137 ~125 ~110 dirt
setblock ~137 ~125 ~111 dirt
setblock ~137 ~125 ~112 dirt
setblock ~137 ~125 ~113 dirt
setblock ~137 ~125 ~114 dirt
setblock ~137 ~125 ~115 dirt
setblock ~137 ~125 ~116 dirt
setblock ~137 ~125 ~117 dirt
setblock ~137 ~125 ~118 dirt
setblock ~137 ~125 ~119 dirt
setblock ~137 ~125 ~120 dirt
setblock ~137 ~125 ~121 dirt
setblock ~137 ~126 ~78 grass_block
setblock ~137 ~126 ~79 grass_block
setblock ~137 ~126 ~80 grass_block
setblock ~137 ~126 ~81 grass_block
setblock ~137 ~126 ~82 grass_block
setblock ~137 ~126 ~83 grass_block
setblock ~137 ~126 ~84 grass_block
setblock ~137 ~126 ~85 dirt
setblock ~137 ~126 ~86 dirt
setblock ~137 ~126 ~87 dirt
setblock ~137 ~126 ~88 dirt
setblock ~137 ~126 ~89 dirt
setblock ~137 ~126 ~90 dirt
setblock ~137 ~126 ~91 dirt
setblock ~137 ~126 ~92 dirt
setblock ~137 ~126 ~93 grass_block
setblock ~137 ~126 ~94 grass_block
setblock ~137 ~126 ~95 grass_block
setblock ~137 ~126 ~96 grass_block
setblock ~137 ~126 ~97 grass_block
setblock ~137 ~126 ~98 fern
setblock ~137 ~126 ~99 short_grass
setblock ~137 ~126 ~102 grass_block
setblock ~137 ~126 ~103 grass_block
setblock ~137 ~126 ~104 grass_block
setblock ~137 ~126 ~105 dirt
setblock ~137 ~126 ~106 dirt
setblock ~137 ~126 ~107 dirt
setblock ~137 ~126 ~108 dirt
setblock ~137 ~126 ~109 dirt
setblock ~137 ~126 ~110 dirt
setblock ~137 ~126 ~111 dirt
setblock ~137 ~126 ~112 dirt
setblock ~137 ~126 ~113 dirt
setblock ~137 ~126 ~114 dirt
setblock ~137 ~126 ~115 dirt
setblock ~137 ~126 ~116 dirt
setblock ~137 ~126 ~117 grass_block
setblock ~137 ~126 ~118 grass_block
setblock ~137 ~126 ~119 grass_block
setblock ~137 ~126 ~120 grass_block
setblock ~137 ~126 ~121 grass_block
setblock ~137 ~127 ~82 short_grass
setblock ~137 ~127 ~85 grass_block
setblock ~137 ~127 ~86 grass_block
setblock ~137 ~127 ~87 grass_block
setblock ~137 ~127 ~88 grass_block
setblock ~137 ~127 ~89 grass_block
setblock ~137 ~127 ~90 grass_block
setblock ~137 ~127 ~91 grass_block
setblock ~137 ~127 ~92 grass_block
setblock ~137 ~127 ~95 short_grass
setblock ~137 ~127 ~96 fern
setblock ~137 ~127 ~103 short_grass
setblock ~137 ~127 ~105 grass_block
setblock ~137 ~127 ~106 grass_block
setblock ~137 ~127 ~107 grass_block
setblock ~137 ~127 ~108 grass_block
setblock ~137 ~127 ~109 dirt
setblock ~137 ~127 ~110 dirt
setblock ~137 ~127 ~111 dirt
setblock ~137 ~127 ~112 grass_block
setblock ~137 ~127 ~113 grass_block
setblock ~137 ~127 ~114 grass_block
setblock ~137 ~127 ~115 grass_block
setblock ~137 ~127 ~116 grass_block
setblock ~137 ~127 ~117 short_grass
setblock ~137 ~127 ~121 short_grass
setblock ~137 ~128 ~85 short_grass
setblock ~137 ~128 ~86 short_grass
setblock ~137 ~128 ~106 fern
setblock ~137 ~128 ~108 short_grass
setblock ~137 ~128 ~109 grass_block
setblock ~137 ~128 ~110 grass_block
setblock ~137 ~128 ~111 grass_block
setblock ~137 ~129 ~109 short_grass
setblock ~138 ~107 ~107 dirt
setblock ~138 ~108 ~98 dirt
setblock ~138 ~108 ~101 dirt
setblock ~138 ~108 ~102 dirt
setblock ~138 ~108 ~103 dirt
setblock ~138 ~108 ~107 dirt
setblock ~138 ~109 ~97 dirt
setblock ~138 ~109 ~98 dirt
setblock ~138 ~109 ~99 dirt
setblock ~138 ~109 ~100 dirt
setblock ~138 ~109 ~101 dirt
setblock ~138 ~109 ~102 dirt
setblock ~138 ~109 ~103 dirt
setblock ~138 ~109 ~106 dirt
setblock ~138 ~109 ~107 dirt
setblock ~138 ~110 ~96 dirt
setblock ~138 ~110 ~97 dirt
setblock ~138 ~110 ~98 dirt
setblock ~138 ~110 ~99 dirt
setblock ~138 ~110 ~100 dirt
setblock ~138 ~110 ~101 dirt
setblock ~138 ~110 ~102 dirt
setblock ~138 ~110 ~103 dirt
setblock ~138 ~110 ~104 dirt
setblock ~138 ~110 ~105 dirt
setblock ~138 ~110 ~106 dirt
setblock ~138 ~110 ~107 dirt
setblock ~138 ~110 ~108 dirt
setblock ~138 ~110 ~109 dirt
setblock ~138 ~111 ~94 dirt
setblock ~138 ~111 ~95 dirt
setblock ~138 ~111 ~96 dirt
setblock ~138 ~111 ~97 dirt
setblock ~138 ~111 ~98 dirt
setblock ~138 ~111 ~99 dirt
setblock ~138 ~111 ~100 dirt
setblock ~138 ~111 ~101 dirt
setblock ~138 ~111 ~102 dirt
setblock ~138 ~111 ~103 dirt
setblock ~138 ~111 ~104 dirt
setblock ~138 ~111 ~105 dirt
setblock ~138 ~111 ~106 dirt
setblock ~138 ~111 ~107 dirt
setblock ~138 ~111 ~108 dirt
setblock ~138 ~111 ~109 dirt
setblock ~138 ~111 ~110 dirt
setblock ~138 ~112 ~94 dirt
setblock ~138 ~112 ~95 dirt
setblock ~138 ~112 ~96 dirt
setblock ~138 ~112 ~97 dirt
setblock ~138 ~112 ~98 dirt
setblock ~138 ~112 ~99 dirt
setblock ~138 ~112 ~100 dirt
setblock ~138 ~112 ~101 dirt
setblock ~138 ~112 ~102 dirt
setblock ~138 ~112 ~103 dirt
setblock ~138 ~112 ~104 dirt
setblock ~138 ~112 ~105 dirt
setblock ~138 ~112 ~106 dirt
setblock ~138 ~112 ~107 dirt
setblock ~138 ~112 ~108 dirt
setblock ~138 ~112 ~109 dirt
setblock ~138 ~112 ~110 dirt
setblock ~138 ~112 ~111 dirt
setblock ~138 ~112 ~112 dirt
setblock ~138 ~113 ~93 dirt
setblock ~138 ~113 ~94 dirt
setblock ~138 ~113 ~95 dirt
setblock ~138 ~113 ~96 dirt
setblock ~138 ~113 ~97 dirt
setblock ~138 ~113 ~98 dirt
setblock ~138 ~113 ~99 dirt
setblock ~138 ~113 ~100 dirt
setblock ~138 ~113 ~101 dirt
setblock ~138 ~113 ~102 dirt
setblock ~138 ~113 ~103 dirt
setblock ~138 ~113 ~104 dirt
setblock ~138 ~113 ~105 dirt
setblock ~138 ~113 ~106 dirt
setblock ~138 ~113 ~107 dirt
setblock ~138 ~113 ~108 dirt
setblock ~138 ~113 ~109 dirt
setblock ~138 ~113 ~110 dirt
setblock ~138 ~113 ~111 dirt
setblock ~138 ~113 ~112 dirt
setblock ~138 ~114 ~92 dirt
setblock ~138 ~114 ~93 dirt
setblock ~138 ~114 ~94 dirt
setblock ~138 ~114 ~95 dirt
setblock ~138 ~114 ~96 dirt
setblock ~138 ~114 ~97 dirt
setblock ~138 ~114 ~98 dirt
setblock ~138 ~114 ~99 dirt
setblock ~138 ~114 ~100 dirt
setblock ~138 ~114 ~101 dirt
setblock ~138 ~114 ~102 dirt
setblock ~138 ~114 ~103 dirt
setblock ~138 ~114 ~104 dirt
setblock ~138 ~114 ~105 dirt
setblock ~138 ~114 ~106 dirt
setblock ~138 ~114 ~107 dirt
setblock ~138 ~114 ~108 dirt
setblock ~138 ~114 ~109 dirt
setblock ~138 ~114 ~110 dirt
setblock ~138 ~114 ~111 dirt
setblock ~138 ~114 ~112 dirt
setblock ~138 ~114 ~113 dirt
setblock ~138 ~114 ~114 dirt
setblock ~138 ~115 ~91 dirt
setblock ~138 ~115 ~92 dirt
setblock ~138 ~115 ~93 dirt
setblock ~138 ~115 ~94 dirt
setblock ~138 ~115 ~95 dirt
setblock ~138 ~115 ~96 dirt
setblock ~138 ~115 ~97 dirt
setblock ~138 ~115 ~98 dirt
setblock ~138 ~115 ~99 dirt
setblock ~138 ~115 ~100 dirt
setblock ~138 ~115 ~101 dirt
setblock ~138 ~115 ~102 dirt
setblock ~138 ~115 ~103 dirt
setblock ~138 ~115 ~104 dirt
setblock ~138 ~115 ~105 dirt
setblock ~138 ~115 ~106 dirt
setblock ~138 ~115 ~107 dirt
setblock ~138 ~115 ~108 dirt
setblock ~138 ~115 ~109 dirt
setblock ~138 ~115 ~110 dirt
setblock ~138 ~115 ~111 dirt
setblock ~138 ~115 ~112 dirt
setblock ~138 ~115 ~113 dirt
setblock ~138 ~115 ~114 dirt
setblock ~138 ~115 ~115 dirt
setblock ~138 ~116 ~90 dirt
setblock ~138 ~116 ~91 dirt
setblock ~138 ~116 ~92 dirt
setblock ~138 ~116 ~93 dirt
setblock ~138 ~116 ~94 dirt
setblock ~138 ~116 ~95 dirt
setblock ~138 ~116 ~96 dirt
setblock ~138 ~116 ~97 dirt
setblock ~138 ~116 ~98 dirt
setblock ~138 ~116 ~99 dirt
setblock ~138 ~116 ~100 dirt
setblock ~138 ~116 ~101 dirt
setblock ~138 ~116 ~102 dirt
setblock ~138 ~116 ~103 dirt
setblock ~138 ~116 ~104 dirt
setblock ~138 ~116 ~105 dirt
setblock ~138 ~116 ~106 dirt
setblock ~138 ~116 ~107 dirt
setblock ~138 ~116 ~108 dirt
setblock ~138 ~116 ~109 dirt
setblock ~138 ~116 ~110 dirt
setblock ~138 ~116 ~111 dirt
setblock ~138 ~116 ~112 dirt
setblock ~138 ~116 ~113 dirt
setblock ~138 ~116 ~114 dirt
setblock ~138 ~116 ~115 dirt
setblock ~138 ~116 ~116 dirt
setblock ~138 ~117 ~86 dirt
setblock ~138 ~117 ~90 dirt
setblock ~138 ~117 ~91 dirt
setblock ~138 ~117 ~92 dirt
setblock ~138 ~117 ~93 dirt
setblock ~138 ~117 ~94 dirt
setblock ~138 ~117 ~95 dirt
setblock ~138 ~117 ~96 dirt
setblock ~138 ~117 ~97 dirt
setblock ~138 ~117 ~98 dirt
setblock ~138 ~117 ~99 dirt
setblock ~138 ~117 ~100 dirt
setblock ~138 ~117 ~101 dirt
setblock ~138 ~117 ~102 dirt
setblock ~138 ~117 ~103 dirt
setblock ~138 ~117 ~104 dirt
setblock ~138 ~117 ~105 dirt
setblock ~138 ~117 ~106 dirt
setblock ~138 ~117 ~107 dirt
setblock ~138 ~117 ~108 dirt
setblock ~138 ~117 ~109 dirt
setblock ~138 ~117 ~110 dirt
setblock ~138 ~117 ~111 dirt
setblock ~138 ~117 ~112 dirt
setblock ~138 ~117 ~113 dirt
setblock ~138 ~117 ~114 dirt
setblock ~138 ~117 ~115 dirt
setblock ~138 ~117 ~116 dirt
setblock ~138 ~117 ~117 dirt
setblock ~138 ~118 ~85 dirt
setblock ~138 ~118 ~86 dirt
setblock ~138 ~118 ~88 dirt
setblock ~138 ~118 ~89 dirt
setblock ~138 ~118 ~90 dirt
setblock ~138 ~118 ~91 dirt
setblock ~138 ~118 ~92 dirt
setblock ~138 ~118 ~93 dirt
setblock ~138 ~118 ~94 dirt
setblock ~138 ~118 ~95 dirt
setblock ~138 ~118 ~96 dirt
setblock ~138 ~118 ~97 dirt
setblock ~138 ~118 ~98 dirt
setblock ~138 ~118 ~99 dirt
setblock ~138 ~118 ~100 dirt
setblock ~138 ~118 ~101 dirt
setblock ~138 ~118 ~102 dirt
setblock ~138 ~118 ~103 dirt
setblock ~138 ~118 ~104 dirt
setblock ~138 ~118 ~105 dirt
setblock ~138 ~118 ~106 dirt
setblock ~138 ~118 ~107 dirt
setblock ~138 ~118 ~108 dirt
setblock ~138 ~118 ~109 dirt
setblock ~138 ~118 ~110 dirt
setblock ~138 ~118 ~111 dirt
setblock ~138 ~118 ~112 dirt
setblock ~138 ~118 ~113 dirt
setblock ~138 ~118 ~114 dirt
setblock ~138 ~118 ~115 dirt
setblock ~138 ~118 ~116 dirt
setblock ~138 ~118 ~117 dirt
setblock ~138 ~119 ~84 dirt
setblock ~138 ~119 ~85 dirt
setblock ~138 ~119 ~86 dirt
setblock ~138 ~119 ~87 dirt
setblock ~138 ~119 ~88 dirt
setblock ~138 ~119 ~89 dirt
setblock ~138 ~119 ~90 dirt
setblock ~138 ~119 ~91 dirt
setblock ~138 ~119 ~92 dirt
setblock ~138 ~119 ~93 dirt
setblock ~138 ~119 ~94 dirt
setblock ~138 ~119 ~95 dirt
setblock ~138 ~119 ~96 dirt
setblock ~138 ~119 ~97 dirt
setblock ~138 ~119 ~98 dirt
setblock ~138 ~119 ~99 dirt
setblock ~138 ~119 ~100 dirt
setblock ~138 ~119 ~101 dirt
setblock ~138 ~119 ~102 dirt
setblock ~138 ~119 ~103 dirt
setblock ~138 ~119 ~104 dirt
setblock ~138 ~119 ~105 dirt
setblock ~138 ~119 ~106 dirt
setblock ~138 ~119 ~107 dirt
setblock ~138 ~119 ~108 dirt
setblock ~138 ~119 ~109 dirt
setblock ~138 ~119 ~110 dirt
setblock ~138 ~119 ~111 dirt
setblock ~138 ~119 ~112 dirt
setblock ~138 ~119 ~113 dirt
setblock ~138 ~119 ~114 dirt
setblock ~138 ~119 ~115 dirt
setblock ~138 ~119 ~116 dirt
setblock ~138 ~119 ~117 dirt
setblock ~138 ~119 ~118 dirt
setblock ~138 ~120 ~84 dirt
setblock ~138 ~120 ~85 dirt
setblock ~138 ~120 ~86 dirt
setblock ~138 ~120 ~87 dirt
setblock ~138 ~120 ~88 dirt
setblock ~138 ~120 ~89 dirt
setblock ~138 ~120 ~90 dirt
setblock ~138 ~120 ~91 dirt
setblock ~138 ~120 ~92 dirt
setblock ~138 ~120 ~93 dirt
setblock ~138 ~120 ~94 dirt
setblock ~138 ~120 ~95 dirt
setblock ~138 ~120 ~96 dirt
setblock ~138 ~120 ~97 dirt
setblock ~138 ~120 ~98 dirt
setblock ~138 ~120 ~99 dirt
setblock ~138 ~120 ~100 dirt
setblock ~138 ~120 ~101 dirt
setblock ~138 ~120 ~102 dirt
setblock ~138 ~120 ~103 dirt
setblock ~138 ~120 ~104 dirt
setblock ~138 ~120 ~105 dirt
setblock ~138 ~120 ~106 dirt
setblock ~138 ~120 ~107 dirt
setblock ~138 ~120 ~108 dirt
setblock ~138 ~120 ~109 dirt
setblock ~138 ~120 ~110 dirt
setblock ~138 ~120 ~111 dirt
setblock ~138 ~120 ~112 dirt
setblock ~138 ~120 ~113 dirt
setblock ~138 ~120 ~114 dirt
setblock ~138 ~120 ~115 dirt
setblock ~138 ~120 ~116 dirt
setblock ~138 ~120 ~117 dirt
setblock ~138 ~120 ~118 dirt
setblock ~138 ~120 ~119 dirt
setblock ~138 ~121 ~83 dirt
setblock ~138 ~121 ~84 dirt
setblock ~138 ~121 ~85 dirt
setblock ~138 ~121 ~86 dirt
setblock ~138 ~121 ~87 dirt
setblock ~138 ~121 ~88 dirt
setblock ~138 ~121 ~89 dirt
setblock ~138 ~121 ~90 dirt
setblock ~138 ~121 ~91 dirt
setblock ~138 ~121 ~92 dirt
setblock ~138 ~121 ~93 dirt
setblock ~138 ~121 ~94 dirt
setblock ~138 ~121 ~95 dirt
setblock ~138 ~121 ~96 dirt
setblock ~138 ~121 ~97 dirt
setblock ~138 ~121 ~98 dirt
setblock ~138 ~121 ~99 dirt
setblock ~138 ~121 ~100 dirt
setblock ~138 ~121 ~101 dirt
setblock ~138 ~121 ~102 dirt
setblock ~138 ~121 ~103 dirt
setblock ~138 ~121 ~104 dirt
setblock ~138 ~121 ~105 dirt
setblock ~138 ~121 ~106 dirt
setblock ~138 ~121 ~107 dirt
setblock ~138 ~121 ~108 dirt
setblock ~138 ~121 ~109 dirt
setblock ~138 ~121 ~110 dirt
setblock ~138 ~121 ~111 dirt
setblock ~138 ~121 ~112 dirt
setblock ~138 ~121 ~113 dirt
setblock ~138 ~121 ~114 dirt
setblock ~138 ~121 ~115 dirt
setblock ~138 ~121 ~116 dirt
setblock ~138 ~121 ~117 dirt
setblock ~138 ~121 ~118 dirt
setblock ~138 ~121 ~119 dirt
setblock ~138 ~121 ~120 dirt
setblock ~138 ~122 ~83 dirt
setblock ~138 ~122 ~84 dirt
setblock ~138 ~122 ~85 dirt
setblock ~138 ~122 ~86 dirt
setblock ~138 ~122 ~87 dirt
setblock ~138 ~122 ~88 dirt
setblock ~138 ~122 ~89 dirt
setblock ~138 ~122 ~90 dirt
setblock ~138 ~122 ~91 dirt
setblock ~138 ~122 ~92 dirt
setblock ~138 ~122 ~93 dirt
setblock ~138 ~122 ~94 dirt
setblock ~138 ~122 ~95 dirt
setblock ~138 ~122 ~96 dirt
setblock ~138 ~122 ~97 dirt
setblock ~138 ~122 ~98 dirt
setblock ~138 ~122 ~99 dirt
setblock ~138 ~122 ~100 dirt
setblock ~138 ~122 ~101 dirt
setblock ~138 ~122 ~102 dirt
setblock ~138 ~122 ~103 dirt
setblock ~138 ~122 ~104 dirt
setblock ~138 ~122 ~105 dirt
setblock ~138 ~122 ~106 dirt
setblock ~138 ~122 ~107 dirt
setblock ~138 ~122 ~108 dirt
setblock ~138 ~122 ~109 dirt
setblock ~138 ~122 ~110 dirt
setblock ~138 ~122 ~111 dirt
setblock ~138 ~122 ~112 dirt
setblock ~138 ~122 ~113 dirt
setblock ~138 ~122 ~114 dirt
setblock ~138 ~122 ~115 dirt
setblock ~138 ~122 ~116 dirt
setblock ~138 ~122 ~117 dirt
setblock ~138 ~122 ~118 dirt
setblock ~138 ~122 ~119 dirt
setblock ~138 ~122 ~120 dirt
setblock ~138 ~123 ~83 dirt
setblock ~138 ~123 ~84 dirt
setblock ~138 ~123 ~85 dirt
setblock ~138 ~123 ~86 dirt
setblock ~138 ~123 ~87 dirt
setblock ~138 ~123 ~88 dirt
setblock ~138 ~123 ~89 dirt
setblock ~138 ~123 ~90 dirt
setblock ~138 ~123 ~91 dirt
setblock ~138 ~123 ~92 dirt
setblock ~138 ~123 ~93 dirt
setblock ~138 ~123 ~94 dirt
setblock ~138 ~123 ~95 dirt
setblock ~138 ~123 ~96 dirt
setblock ~138 ~123 ~97 dirt
setblock ~138 ~123 ~98 dirt
setblock ~138 ~123 ~99 dirt
setblock ~138 ~123 ~100 dirt
setblock ~138 ~123 ~101 dirt
setblock ~138 ~123 ~102 dirt
setblock ~138 ~123 ~103 dirt
setblock ~138 ~123 ~104 dirt
setblock ~138 ~123 ~105 dirt
setblock ~138 ~123 ~106 dirt
setblock ~138 ~123 ~107 dirt
setblock ~138 ~123 ~108 dirt
setblock ~138 ~123 ~109 dirt
setblock ~138 ~123 ~110 dirt
setblock ~138 ~123 ~111 dirt
setblock ~138 ~123 ~112 dirt
setblock ~138 ~123 ~113 dirt
setblock ~138 ~123 ~114 dirt
setblock ~138 ~123 ~115 dirt
setblock ~138 ~123 ~116 dirt
setblock ~138 ~123 ~117 dirt
setblock ~138 ~123 ~118 dirt
setblock ~138 ~123 ~119 dirt
setblock ~138 ~123 ~120 dirt
setblock ~138 ~124 ~83 dirt
setblock ~138 ~124 ~84 dirt
setblock ~138 ~124 ~85 dirt
setblock ~138 ~124 ~86 dirt
setblock ~138 ~124 ~87 dirt
setblock ~138 ~124 ~88 dirt
setblock ~138 ~124 ~89 dirt
setblock ~138 ~124 ~90 dirt
setblock ~138 ~124 ~91 dirt
setblock ~138 ~124 ~92 dirt
setblock ~138 ~124 ~93 dirt
setblock ~138 ~124 ~94 dirt
setblock ~138 ~124 ~95 dirt
setblock ~138 ~124 ~96 dirt
setblock ~138 ~124 ~97 dirt
setblock ~138 ~124 ~98 dirt
setblock ~138 ~124 ~99 dirt
setblock ~138 ~124 ~100 dirt
setblock ~138 ~124 ~101 dirt
setblock ~138 ~124 ~102 dirt
setblock ~138 ~124 ~103 dirt
setblock ~138 ~124 ~104 dirt
setblock ~138 ~124 ~105 dirt
setblock ~138 ~124 ~106 dirt
setblock ~138 ~124 ~107 dirt
setblock ~138 ~124 ~108 dirt
setblock ~138 ~124 ~109 dirt
setblock ~138 ~124 ~110 dirt
setblock ~138 ~124 ~111 dirt
setblock ~138 ~124 ~112 dirt
setblock ~138 ~124 ~113 dirt
setblock ~138 ~124 ~114 dirt
setblock ~138 ~124 ~115 dirt
setblock ~138 ~124 ~116 dirt
setblock ~138 ~124 ~117 dirt
setblock ~138 ~124 ~118 dirt
setblock ~138 ~124 ~119 dirt
setblock ~138 ~124 ~120 dirt
setblock ~138 ~125 ~83 dirt
setblock ~138 ~125 ~84 dirt
setblock ~138 ~125 ~85 dirt
setblock ~138 ~125 ~86 dirt
setblock ~138 ~125 ~87 dirt
setblock ~138 ~125 ~88 dirt
setblock ~138 ~125 ~89 dirt
setblock ~138 ~125 ~90 dirt
setblock ~138 ~125 ~91 dirt
setblock ~138 ~125 ~92 dirt
setblock ~138 ~125 ~93 dirt
setblock ~138 ~125 ~94 dirt
setblock ~138 ~125 ~95 dirt
setblock ~138 ~125 ~96 dirt
setblock ~138 ~125 ~97 dirt
setblock ~138 ~125 ~98 grass_block
setblock ~138 ~125 ~99 grass_block
setblock ~138 ~125 ~100 grass_block
setblock ~138 ~125 ~101 grass_block
setblock ~138 ~125 ~102 dirt
setblock ~138 ~125 ~103 dirt
setblock ~138 ~125 ~104 dirt
setblock ~138 ~125 ~105 dirt
setblock ~138 ~125 ~106 dirt
setblock ~138 ~125 ~107 dirt
setblock ~138 ~125 ~108 dirt
setblock ~138 ~125 ~109 dirt
setblock ~138 ~125 ~110 dirt
setblock ~138 ~125 ~111 dirt
setblock ~138 ~125 ~112 dirt
setblock ~138 ~125 ~113 dirt
setblock ~138 ~125 ~114 dirt
setblock ~138 ~125 ~115 dirt
setblock ~138 ~125 ~116 dirt
setblock ~138 ~125 ~117 dirt
setblock ~138 ~125 ~118 dirt
setblock ~138 ~125 ~119 dirt
setblock ~138 ~125 ~120 dirt
setblock ~138 ~126 ~83 dirt
setblock ~138 ~126 ~84 dirt
setblock ~138 ~126 ~85 dirt
setblock ~138 ~126 ~86 dirt
setblock ~138 ~126 ~87 dirt
setblock ~138 ~126 ~88 dirt
setblock ~138 ~126 ~89 dirt
setblock ~138 ~126 ~90 dirt
setblock ~138 ~126 ~91 dirt
setblock ~138 ~126 ~92 dirt
setblock ~138 ~126 ~93 dirt
setblock ~138 ~126 ~94 grass_block
setblock ~138 ~126 ~95 grass_block
setblock ~138 ~126 ~96 grass_block
setblock ~138 ~126 ~97 grass_block
setblock ~138 ~126 ~102 grass_block
setblock ~138 ~126 ~103 grass_block
setblock ~138 ~126 ~104 grass_block
setblock ~138 ~126 ~105 dirt
setblock ~138 ~126 ~106 dirt
setblock ~138 ~126 ~107 dirt
setblock ~138 ~126 ~108 dirt
setblock ~138 ~126 ~109 dirt
setblock ~138 ~126 ~110 dirt
setblock ~138 ~126 ~111 dirt
setblock ~138 ~126 ~112 dirt
setblock ~138 ~126 ~113 dirt
setblock ~138 ~126 ~114 dirt
setblock ~138 ~126 ~115 dirt
setblock ~138 ~126 ~116 dirt
setblock ~138 ~126 ~117 grass_block
setblock ~138 ~126 ~118 grass_block
setblock ~138 ~126 ~119 grass_block
setblock ~138 ~126 ~120 grass_block
setblock ~138 ~127 ~83 grass_block
setblock ~138 ~127 ~84 grass_block
setblock ~138 ~127 ~85 grass_block
setblock ~138 ~127 ~86 grass_block
setblock ~138 ~127 ~87 grass_block
setblock ~138 ~127 ~88 grass_block
setblock ~138 ~127 ~89 grass_block
setblock ~138 ~127 ~90 grass_block
setblock ~138 ~127 ~91 grass_block
setblock ~138 ~127 ~92 grass_block
setblock ~138 ~127 ~93 grass_block
setblock ~138 ~127 ~95 short_grass
setblock ~138 ~127 ~104 poppy
setblock ~138 ~127 ~105 grass_block
setblock ~138 ~127 ~106 grass_block
setblock ~138 ~127 ~107 grass_block
setblock ~138 ~127 ~108 grass_block
setblock ~138 ~127 ~109 dirt
setblock ~138 ~127 ~110 dirt
setblock ~138 ~127 ~111 grass_block
setblock ~138 ~127 ~112 grass_block
setblock ~138 ~127 ~113 grass_block
setblock ~138 ~127 ~114 grass_block
setblock ~138 ~127 ~115 grass_block
setblock ~138 ~127 ~116 grass_block
setblock ~138 ~127 ~117 short_grass
setblock ~138 ~127 ~119 poppy
setblock ~138 ~128 ~87 short_grass
setblock ~138 ~128 ~88 fern
setblock ~138 ~128 ~108 short_grass
setblock ~138 ~128 ~109 grass_block
setblock ~138 ~128 ~110 grass_block
setblock ~138 ~128 ~112 poppy
setblock ~138 ~128 ~116 short_grass
setblock ~139 ~109 ~98 dirt
setblock ~139 ~110 ~97 dirt
setblock ~139 ~110 ~98 dirt
setblock ~139 ~110 ~100 dirt
setblock ~139 ~110 ~101 dirt
setblock ~139 ~110 ~106 dirt
setblock ~139 ~110 ~107 dirt
setblock ~139 ~111 ~96 dirt
setblock ~139 ~111 ~97 dirt
setblock ~139 ~111 ~98 dirt
setblock ~139 ~111 ~100 dirt
setblock ~139 ~111 ~101 dirt
setblock ~139 ~111 ~102 dirt
setblock ~139 ~111 ~103 dirt
setblock ~139 ~111 ~105 dirt
setblock ~139 ~111 ~106 dirt
setblock ~139 ~111 ~107 dirt
setblock ~139 ~111 ~109 dirt
setblock ~139 ~112 ~95 dirt
setblock ~139 ~112 ~96 dirt
setblock ~139 ~112 ~97 dirt
setblock ~139 ~112 ~98 dirt
setblock ~139 ~112 ~99 dirt
setblock ~139 ~112 ~100 dirt
setblock ~139 ~112 ~101 dirt
setblock ~139 ~112 ~102 dirt
setblock ~139 ~112 ~103 dirt
setblock ~139 ~112 ~104 dirt
setblock ~139 ~112 ~105 dirt
setblock ~139 ~112 ~106 dirt
setblock ~139 ~112 ~107 dirt
setblock ~139 ~112 ~108 dirt
setblock ~139 ~112 ~109 dirt
setblock ~139 ~112 ~110 dirt
setblock ~139 ~113 ~95 dirt
setblock ~139 ~113 ~96 dirt
setblock ~139 ~113 ~97 dirt
setblock ~139 ~113 ~98 dirt
setblock ~139 ~113 ~99 dirt
setblock ~139 ~113 ~100 dirt
setblock ~139 ~113 ~101 dirt
setblock ~139 ~113 ~102 dirt
setblock ~139 ~113 ~103 dirt
setblock ~139 ~113 ~104 dirt
setblock ~139 ~113 ~105 dirt
setblock ~139 ~113 ~106 dirt
setblock ~139 ~113 ~107 dirt
setblock ~139 ~113 ~108 dirt
setblock ~139 ~113 ~109 dirt
setblock ~139 ~113 ~110 dirt
setblock ~139 ~114 ~95 dirt
setblock ~139 ~114 ~96 dirt
setblock ~139 ~114 ~97 dirt
setblock ~139 ~114 ~98 dirt
setblock ~139 ~114 ~99 dirt
setblock ~139 ~114 ~100 dirt
setblock ~139 ~114 ~101 dirt
setblock ~139 ~114 ~102 dirt
setblock ~139 ~114 ~103 dirt
setblock ~139 ~114 ~104 dirt
setblock ~139 ~114 ~105 dirt
setblock ~139 ~114 ~106 dirt
setblock ~139 ~114 ~107 dirt
setblock ~139 ~114 ~108 dirt
setblock ~139 ~114 ~109 dirt
setblock ~139 ~114 ~110 dirt
setblock ~139 ~114 ~112 dirt
setblock ~139 ~115 ~92 dirt
setblock ~139 ~115 ~93 dirt
setblock ~139 ~115 ~94 dirt
setblock ~139 ~115 ~95 dirt
setblock ~139 ~115 ~96 dirt
setblock ~139 ~115 ~97 dirt
setblock ~139 ~115 ~98 dirt
setblock ~139 ~115 ~99 dirt
setblock ~139 ~115 ~100 dirt
setblock ~139 ~115 ~101 dirt
setblock ~139 ~115 ~102 dirt
setblock ~139 ~115 ~103 dirt
setblock ~139 ~115 ~104 dirt
setblock ~139 ~115 ~105 dirt
setblock ~139 ~115 ~106 dirt
setblock ~139 ~115 ~107 dirt
setblock ~139 ~115 ~108 dirt
setblock ~139 ~115 ~109 dirt
setblock ~139 ~115 ~110 dirt
setblock ~139 ~115 ~111 dirt
setblock ~139 ~115 ~112 dirt
setblock ~139 ~116 ~92 dirt
setblock ~139 ~116 ~93 dirt
setblock ~139 ~116 ~94 dirt
setblock ~139 ~116 ~95 dirt
setblock ~139 ~116 ~96 dirt
setblock ~139 ~116 ~97 dirt
setblock ~139 ~116 ~98 dirt
setblock ~139 ~116 ~99 dirt
setblock ~139 ~116 ~100 dirt
setblock ~139 ~116 ~101 dirt
setblock ~139 ~116 ~102 dirt
setblock ~139 ~116 ~103 dirt
setblock ~139 ~116 ~104 dirt
setblock ~139 ~116 ~105 dirt
setblock ~139 ~116 ~106 dirt
setblock ~139 ~116 ~107 dirt
setblock ~139 ~116 ~108 dirt
setblock ~139 ~116 ~109 dirt
setblock ~139 ~116 ~110 dirt
setblock ~139 ~116 ~111 dirt
setblock ~139 ~116 ~112 dirt
setblock ~139 ~116 ~114 dirt
setblock ~139 ~117 ~91 dirt
setblock ~139 ~117 ~92 dirt
setblock ~139 ~117 ~93 dirt
setblock ~139 ~117 ~94 dirt
setblock ~139 ~117 ~95 dirt
setblock ~139 ~117 ~96 dirt
setblock ~139 ~117 ~97 dirt
setblock ~139 ~117 ~98 dirt
setblock ~139 ~117 ~99 dirt
setblock ~139 ~117 ~100 dirt
setblock ~139 ~117 ~101 dirt
setblock ~139 ~117 ~102 dirt
setblock ~139 ~117 ~103 dirt
setblock ~139 ~117 ~104 dirt
setblock ~139 ~117 ~105 dirt
setblock ~139 ~117 ~106 dirt
setblock ~139 ~117 ~107 dirt
setblock ~139 ~117 ~108 dirt
setblock ~139 ~117 ~109 dirt
setblock ~139 ~117 ~110 dirt
setblock ~139 ~117 ~111 dirt
setblock ~139 ~117 ~112 dirt
setblock ~139 ~117 ~113 dirt
setblock ~139 ~117 ~114 dirt
setblock ~139 ~117 ~115 dirt
setblock ~139 ~117 ~116 dirt
setblock ~139 ~118 ~91 dirt
setblock ~139 ~118 ~92 dirt
setblock ~139 ~118 ~93 dirt
setblock ~139 ~118 ~94 dirt
setblock ~139 ~118 ~95 dirt
setblock ~139 ~118 ~96 dirt
setblock ~139 ~118 ~97 dirt
setblock ~139 ~118 ~98 dirt
setblock ~139 ~118 ~99 dirt
setblock ~139 ~118 ~100 dirt
setblock ~139 ~118 ~101 dirt
setblock ~139 ~118 ~102 dirt
setblock ~139 ~118 ~103 dirt
setblock ~139 ~118 ~104 dirt
setblock ~139 ~118 ~105 dirt
setblock ~139 ~118 ~106 dirt
setblock ~139 ~118 ~107 dirt
setblock ~139 ~118 ~108 dirt
setblock ~139 ~118 ~109 dirt
setblock ~139 ~118 ~110 dirt
setblock ~139 ~118 ~111 dirt
setblock ~139 ~118 ~112 dirt
setblock ~139 ~118 ~113 dirt
setblock ~139 ~118 ~114 dirt
setblock ~139 ~118 ~115 dirt
setblock ~139 ~118 ~116 dirt
setblock ~139 ~119 ~91 dirt
setblock ~139 ~119 ~92 dirt
setblock ~139 ~119 ~93 dirt
setblock ~139 ~119 ~94 dirt
setblock ~139 ~119 ~95 dirt
setblock ~139 ~119 ~96 dirt
setblock ~139 ~119 ~97 dirt
setblock ~139 ~119 ~98 dirt
setblock ~139 ~119 ~99 dirt
setblock ~139 ~119 ~100 dirt
setblock ~139 ~119 ~101 dirt
setblock ~139 ~119 ~102 dirt
setblock ~139 ~119 ~103 dirt
setblock ~139 ~119 ~104 dirt
setblock ~139 ~119 ~105 dirt
setblock ~139 ~119 ~106 dirt
setblock ~139 ~119 ~107 dirt
setblock ~139 ~119 ~108 dirt
setblock ~139 ~119 ~109 dirt
setblock ~139 ~119 ~110 dirt
setblock ~139 ~119 ~111 dirt
setblock ~139 ~119 ~112 dirt
setblock ~139 ~119 ~113 dirt
setblock ~139 ~119 ~114 dirt
setblock ~139 ~119 ~115 dirt
setblock ~139 ~119 ~116 dirt
setblock ~139 ~119 ~117 dirt
setblock ~139 ~120 ~86 dirt
setblock ~139 ~120 ~87 dirt
setblock ~139 ~120 ~90 dirt
setblock ~139 ~120 ~91 dirt
setblock ~139 ~120 ~92 dirt
setblock ~139 ~120 ~93 dirt
setblock ~139 ~120 ~94 dirt
setblock ~139 ~120 ~95 dirt
setblock ~139 ~120 ~96 dirt
setblock ~139 ~120 ~97 dirt
setblock ~139 ~120 ~98 dirt
setblock ~139 ~120 ~99 dirt
setblock ~139 ~120 ~100 dirt
setblock ~139 ~120 ~101 dirt
setblock ~139 ~120 ~102 dirt
setblock ~139 ~120 ~103 dirt
setblock ~139 ~120 ~104 dirt
setblock ~139 ~120 ~105 dirt
setblock ~139 ~120 ~106 dirt
setblock ~139 ~120 ~107 dirt
setblock ~139 ~120 ~108 dirt
setblock ~139 ~120 ~109 dirt
setblock ~139 ~120 ~110 dirt
setblock ~139 ~120 ~111 dirt
setblock ~139 ~120 ~112 dirt
setblock ~139 ~120 ~113 dirt
setblock ~139 ~120 ~114 dirt
setblock ~139 ~120 ~115 dirt
setblock ~139 ~120 ~116 dirt
setblock ~139 ~120 ~117 dirt
setblock ~139 ~121 ~85 dirt
setblock ~139 ~121 ~86 dirt
setblock ~139 ~121 ~87 dirt
setblock ~139 ~121 ~88 dirt
setblock ~139 ~121 ~89 dirt
setblock ~139 ~121 ~90 dirt
setblock ~139 ~121 ~91 dirt
setblock ~139 ~121 ~92 dirt
setblock ~139 ~121 ~93 dirt
setblock ~139 ~121 ~94 dirt
setblock ~139 ~121 ~95 dirt
setblock ~139 ~121 ~96 dirt
setblock ~139 ~121 ~97 dirt
setblock ~139 ~121 ~98 dirt
setblock ~139 ~121 ~99 dirt
setblock ~139 ~121 ~100 dirt
setblock ~139 ~121 ~101 dirt
setblock ~139 ~121 ~102 dirt
setblock ~139 ~121 ~103 dirt
setblock ~139 ~121 ~104 dirt
setblock ~139 ~121 ~105 dirt
setblock ~139 ~121 ~106 dirt
setblock ~139 ~121 ~107 dirt
setblock ~139 ~121 ~108 dirt
setblock ~139 ~121 ~109 dirt
setblock ~139 ~121 ~110 dirt
setblock ~139 ~121 ~111 dirt
setblock ~139 ~121 ~112 dirt
setblock ~139 ~121 ~113 dirt
setblock ~139 ~121 ~114 dirt
setblock ~139 ~121 ~115 dirt
setblock ~139 ~121 ~116 dirt
setblock ~139 ~121 ~117 dirt
setblock ~139 ~121 ~119 dirt
setblock ~139 ~122 ~85 dirt
setblock ~139 ~122 ~86 dirt
setblock ~139 ~122 ~87 dirt
setblock ~139 ~122 ~88 dirt
setblock ~139 ~122 ~89 dirt
setblock ~139 ~122 ~90 dirt
setblock ~139 ~122 ~91 dirt
setblock ~139 ~122 ~92 dirt
setblock ~139 ~122 ~93 dirt
setblock ~139 ~122 ~94 dirt
setblock ~139 ~122 ~95 dirt
setblock ~139 ~122 ~96 dirt
setblock ~139 ~122 ~97 dirt
setblock ~139 ~122 ~98 dirt
setblock ~139 ~122 ~99 dirt
setblock ~139 ~122 ~100 dirt
setblock ~139 ~122 ~101 dirt
setblock ~139 ~122 ~102 dirt
setblock ~139 ~122 ~103 dirt
setblock ~139 ~122 ~104 dirt
setblock ~139 ~122 ~105 dirt
setblock ~139 ~122 ~106 dirt
setblock ~139 ~122 ~107 dirt
setblock ~139 ~122 ~108 dirt
setblock ~139 ~122 ~109 dirt
setblock ~139 ~122 ~110 dirt
setblock ~139 ~122 ~111 dirt
setblock ~139 ~122 ~112 dirt
setblock ~139 ~122 ~113 dirt
setblock ~139 ~122 ~114 dirt
setblock ~139 ~122 ~115 dirt
setblock ~139 ~122 ~116 dirt
setblock ~139 ~122 ~117 dirt
setblock ~139 ~122 ~119 dirt
setblock ~139 ~123 ~85 dirt
setblock ~139 ~123 ~86 dirt
setblock ~139 ~123 ~87 dirt
setblock ~139 ~123 ~88 dirt
setblock ~139 ~123 ~89 dirt
setblock ~139 ~123 ~90 dirt
setblock ~139 ~123 ~91 dirt
setblock ~139 ~123 ~92 dirt
setblock ~139 ~123 ~93 dirt
setblock ~139 ~123 ~94 dirt
setblock ~139 ~123 ~95 dirt
setblock ~139 ~123 ~96 dirt
setblock ~139 ~123 ~97 dirt
setblock ~139 ~123 ~98 dirt
setblock ~139 ~123 ~99 dirt
setblock ~139 ~123 ~100 dirt
setblock ~139 ~123 ~101 dirt
setblock ~139 ~123 ~102 dirt
setblock ~139 ~123 ~103 dirt
setblock ~139 ~123 ~104 dirt
setblock ~139 ~123 ~105 dirt
setblock ~139 ~123 ~106 dirt
setblock ~139 ~123 ~107 dirt
setblock ~139 ~123 ~108 dirt
setblock ~139 ~123 ~109 dirt
setblock ~139 ~123 ~110 dirt
setblock ~139 ~123 ~111 dirt
setblock ~139 ~123 ~112 dirt
setblock ~139 ~123 ~113 dirt
setblock ~139 ~123 ~114 dirt
setblock ~139 ~123 ~115 dirt
setblock ~139 ~123 ~116 dirt
setblock ~139 ~123 ~117 dirt
setblock ~139 ~123 ~119 dirt
setblock ~139 ~124 ~85 dirt
setblock ~139 ~124 ~86 dirt
setblock ~139 ~124 ~87 dirt
setblock ~139 ~124 ~88 dirt
setblock ~139 ~124 ~89 dirt
setblock ~139 ~124 ~90 dirt
setblock ~139 ~124 ~91 dirt
setblock ~139 ~124 ~92 dirt
setblock ~139 ~124 ~93 dirt
setblock ~139 ~124 ~94 dirt
setblock ~139 ~124 ~95 dirt
setblock ~139 ~124 ~96 dirt
setblock ~139 ~124 ~97 dirt
setblock ~139 ~124 ~98 dirt
setblock ~139 ~124 ~99 dirt
setblock ~139 ~124 ~100 dirt
setblock ~139 ~124 ~101 dirt
setblock ~139 ~124 ~102 dirt
setblock ~139 ~124 ~103 dirt
setblock ~139 ~124 ~104 dirt
setblock ~139 ~124 ~105 dirt
setblock ~139 ~124 ~106 dirt
setblock ~139 ~124 ~107 dirt
setblock ~139 ~124 ~108 dirt
setblock ~139 ~124 ~109 dirt
setblock ~139 ~124 ~110 dirt
setblock ~139 ~124 ~111 dirt
setblock ~139 ~124 ~112 dirt
setblock ~139 ~124 ~113 dirt
setblock ~139 ~124 ~114 dirt
setblock ~139 ~124 ~115 dirt
setblock ~139 ~124 ~116 dirt
setblock ~139 ~124 ~117 dirt
setblock ~139 ~124 ~119 dirt
setblock ~139 ~125 ~85 dirt
setblock ~139 ~125 ~86 dirt
setblock ~139 ~125 ~87 dirt
setblock ~139 ~125 ~88 dirt
setblock ~139 ~125 ~89 dirt
setblock ~139 ~125 ~90 dirt
setblock ~139 ~125 ~91 dirt
setblock ~139 ~125 ~92 dirt
setblock ~139 ~125 ~93 dirt
setblock ~139 ~125 ~94 dirt
setblock ~139 ~125 ~95 dirt
setblock ~139 ~125 ~96 dirt
setblock ~139 ~125 ~97 dirt
setblock ~139 ~125 ~98 grass_block
setblock ~139 ~125 ~99 grass_block
setblock ~139 ~125 ~100 grass_block
setblock ~139 ~125 ~101 grass_block
setblock ~139 ~125 ~102 grass_block
setblock ~139 ~125 ~103 dirt
setblock ~139 ~125 ~104 dirt
setblock ~139 ~125 ~105 dirt
setblock ~139 ~125 ~106 dirt
setblock ~139 ~125 ~107 dirt
setblock ~139 ~125 ~108 dirt
setblock ~139 ~125 ~109 dirt
setblock ~139 ~125 ~110 dirt
setblock ~139 ~125 ~111 dirt
setblock ~139 ~125 ~112 dirt
setblock ~139 ~125 ~113 dirt
setblock ~139 ~125 ~114 dirt
setblock ~139 ~125 ~115 dirt
setblock ~139 ~125 ~116 dirt
setblock ~139 ~125 ~117 dirt
setblock ~139 ~125 ~119 dirt
setblock ~139 ~126 ~85 dirt
setblock ~139 ~126 ~86 dirt
setblock ~139 ~126 ~87 dirt
setblock ~139 ~126 ~88 dirt
setblock ~139 ~126 ~89 dirt
setblock ~139 ~126 ~90 dirt
setblock ~139 ~126 ~91 dirt
setblock ~139 ~126 ~92 dirt
setblock ~139 ~126 ~93 dirt
setblock ~139 ~126 ~94 dirt
setblock ~139 ~126 ~95 grass_block
setblock ~139 ~126 ~96 grass_block
setblock ~139 ~126 ~97 grass_block
setblock ~139 ~126 ~98 short_grass
setblock ~139 ~126 ~103 grass_block
setblock ~139 ~126 ~104 grass_block
setblock ~139 ~126 ~105 dirt
setblock ~139 ~126 ~106 dirt
setblock ~139 ~126 ~107 dirt
setblock ~139 ~126 ~108 dirt
setblock ~139 ~126 ~109 dirt
setblock ~139 ~126 ~110 dirt
setblock ~139 ~126 ~111 dirt
setblock ~139 ~126 ~112 dirt
setblock ~139 ~126 ~113 dirt
setblock ~139 ~126 ~114 dirt
setblock ~139 ~126 ~115 dirt
setblock ~139 ~126 ~116 dirt
setblock ~139 ~126 ~117 grass_block
setblock ~139 ~126 ~119 grass_block
setblock ~139 ~127 ~85 grass_block
setblock ~139 ~127 ~86 grass_block
setblock ~139 ~127 ~87 grass_block
setblock ~139 ~127 ~88 grass_block
setblock ~139 ~127 ~89 grass_block
setblock ~139 ~127 ~90 grass_block
setblock ~139 ~127 ~91 grass_block
setblock ~139 ~127 ~92 grass_block
setblock ~139 ~127 ~93 grass_block
setblock ~139 ~127 ~94 grass_block
setblock ~139 ~127 ~95 poppy
setblock ~139 ~127 ~97 short_grass
setblock ~139 ~127 ~105 grass_block
setblock ~139 ~127 ~106 grass_block
setblock ~139 ~127 ~107 grass_block
setblock ~139 ~127 ~108 grass_block
setblock ~139 ~127 ~109 grass_block
setblock ~139 ~127 ~110 dirt
setblock ~139 ~127 ~111 grass_block
setblock ~139 ~127 ~112 grass_block
setblock ~139 ~127 ~113 grass_block
setblock ~139 ~127 ~114 grass_block
setblock ~139 ~127 ~115 grass_block
setblock ~139 ~127 ~116 grass_block
setblock ~139 ~127 ~117 short_grass
setblock ~139 ~128 ~86 short_grass
setblock ~139 ~128 ~91 short_grass
setblock ~139 ~128 ~94 short_grass
setblock ~139 ~128 ~107 short_grass
setblock ~139 ~128 ~110 grass_block
setblock ~139 ~128 ~112 short_grass
setblock ~139 ~128 ~113 fern
setblock ~139 ~129 ~110 short_grass
setblock ~140 ~111 ~97 dirt
setblock ~140 ~111 ~101 dirt
setblock ~140 ~111 ~106 dirt
setblock ~140 ~112 ~96 dirt
setblock ~140 ~112 ~97 dirt
setblock ~140 ~112 ~98 dirt
setblock ~140 ~112 ~100 dirt
setblock ~140 ~112 ~101 dirt
setblock ~140 ~112 ~102 dirt
setblock ~140 ~112 ~106 dirt
setblock ~140 ~112 ~107 dirt
setblock ~140 ~113 ~95 dirt
setblock ~140 ~113 ~96 dirt
setblock ~140 ~113 ~97 dirt
setblock ~140 ~113 ~98 dirt
setblock ~140 ~113 ~99 dirt
setblock ~140 ~113 ~100 dirt
setblock ~140 ~113 ~101 dirt
setblock ~140 ~113 ~102 dirt
setblock ~140 ~113 ~104 dirt
setblock ~140 ~113 ~106 dirt
setblock ~140 ~113 ~107 dirt
setblock ~140 ~113 ~108 dirt
setblock ~140 ~114 ~95 dirt
setblock ~140 ~114 ~96 dirt
setblock ~140 ~114 ~97 dirt
setblock ~140 ~114 ~98 dirt
setblock ~140 ~114 ~99 dirt
setblock ~140 ~114 ~100 dirt
setblock ~140 ~114 ~101 dirt
setblock ~140 ~114 ~102 dirt
setblock ~140 ~114 ~103 dirt
setblock ~140 ~114 ~104 dirt
setblock ~140 ~114 ~105 dirt
setblock ~140 ~114 ~106 dirt
setblock ~140 ~114 ~107 dirt
setblock ~140 ~114 ~108 dirt
setblock ~140 ~114 ~109 dirt
setblock ~140 ~115 ~94 dirt
setblock ~140 ~115 ~95 dirt
setblock ~140 ~115 ~96 dirt
setblock ~140 ~115 ~97 dirt
setblock ~140 ~115 ~98 dirt
setblock ~140 ~115 ~99 dirt
setblock ~140 ~115 ~100 dirt
setblock ~140 ~115 ~101 dirt
setblock ~140 ~115 ~102 dirt
setblock ~140 ~115 ~103 dirt
setblock ~140 ~115 ~104 dirt
setblock ~140 ~115 ~105 dirt
setblock ~140 ~115 ~106 dirt
setblock ~140 ~115 ~107 dirt
setblock ~140 ~115 ~108 dirt
setblock ~140 ~115 ~109 dirt
setblock ~140 ~116 ~94 dirt
setblock ~140 ~116 ~95 dirt
setblock ~140 ~116 ~96 dirt
setblock ~140 ~116 ~97 dirt
setblock ~140 ~116 ~98 dirt
setblock ~140 ~116 ~99 dirt
setblock ~140 ~116 ~100 dirt
setblock ~140 ~116 ~101 dirt
setblock ~140 ~116 ~102 dirt
setblock ~140 ~116 ~103 dirt
setblock ~140 ~116 ~104 dirt
setblock ~140 ~116 ~105 dirt
setblock ~140 ~116 ~106 dirt
setblock ~140 ~116 ~107 dirt
setblock ~140 ~116 ~108 dirt
setblock ~140 ~116 ~109 dirt
setblock ~140 ~116 ~110 dirt
setblock ~140 ~117 ~94 dirt
setblock ~140 ~117 ~95 dirt
setblock ~140 ~117 ~96 dirt
setblock ~140 ~117 ~97 dirt
setblock ~140 ~117 ~98 dirt
setblock ~140 ~117 ~99 dirt
setblock ~140 ~117 ~100 dirt
setblock ~140 ~117 ~101 dirt
setblock ~140 ~117 ~102 dirt
setblock ~140 ~117 ~103 dirt
setblock ~140 ~117 ~104 dirt
setblock ~140 ~117 ~105 dirt
setblock ~140 ~117 ~106 dirt
setblock ~140 ~117 ~107 dirt
setblock ~140 ~117 ~108 dirt
setblock ~140 ~117 ~109 dirt
setblock ~140 ~117 ~110 dirt
setblock ~140 ~117 ~111 dirt
setblock ~140 ~117 ~112 dirt
setblock ~140 ~118 ~92 dirt
setblock ~140 ~118 ~93 dirt
setblock ~140 ~118 ~94 dirt
setblock ~140 ~118 ~95 dirt
setblock ~140 ~118 ~96 dirt
setblock ~140 ~118 ~97 dirt
setblock ~140 ~118 ~98 dirt
setblock ~140 ~118 ~99 dirt
setblock ~140 ~118 ~100 dirt
setblock ~140 ~118 ~101 dirt
setblock ~140 ~118 ~102 dirt
setblock ~140 ~118 ~103 dirt
setblock ~140 ~118 ~104 dirt
setblock ~140 ~118 ~105 dirt
setblock ~140 ~118 ~106 dirt
setblock ~140 ~118 ~107 dirt
setblock ~140 ~118 ~108 dirt
setblock ~140 ~118 ~109 dirt
setblock ~140 ~118 ~110 dirt
setblock ~140 ~118 ~111 dirt
setblock ~140 ~118 ~112 dirt
setblock ~140 ~119 ~92 dirt
setblock ~140 ~119 ~93 dirt
setblock ~140 ~119 ~94 dirt
setblock ~140 ~119 ~95 dirt
setblock ~140 ~119 ~96 dirt
setblock ~140 ~119 ~97 dirt
setblock ~140 ~119 ~98 dirt
setblock ~140 ~119 ~99 dirt
setblock ~140 ~119 ~100 dirt
setblock ~140 ~119 ~101 dirt
setblock ~140 ~119 ~102 dirt
setblock ~140 ~119 ~103 dirt
setblock ~140 ~119 ~104 dirt
setblock ~140 ~119 ~105 dirt
setblock ~140 ~119 ~106 dirt
setblock ~140 ~119 ~107 dirt
setblock ~140 ~119 ~108 dirt
setblock ~140 ~119 ~109 dirt
setblock ~140 ~119 ~110 dirt
setblock ~140 ~119 ~111 dirt
setblock ~140 ~119 ~112 dirt
setblock ~140 ~119 ~113 dirt
setblock ~140 ~119 ~114 dirt
setblock ~140 ~120 ~92 dirt
setblock ~140 ~120 ~93 dirt
setblock ~140 ~120 ~94 dirt
setblock ~140 ~120 ~95 dirt
setblock ~140 ~120 ~96 dirt
setblock ~140 ~120 ~97 dirt
setblock ~140 ~120 ~98 dirt
setblock ~140 ~120 ~99 dirt
setblock ~140 ~120 ~100 dirt
setblock ~140 ~120 ~101 dirt
setblock ~140 ~120 ~102 dirt
setblock ~140 ~120 ~103 dirt
setblock ~140 ~120 ~104 dirt
setblock ~140 ~120 ~105 dirt
setblock ~140 ~120 ~106 dirt
setblock ~140 ~120 ~107 dirt
setblock ~140 ~120 ~108 dirt
setblock ~140 ~120 ~109 dirt
setblock ~140 ~120 ~110 dirt
setblock ~140 ~120 ~111 dirt
setblock ~140 ~120 ~112 dirt
setblock ~140 ~120 ~113 dirt
setblock ~140 ~120 ~114 dirt
setblock ~140 ~120 ~116 dirt
setblock ~140 ~121 ~90 dirt
setblock ~140 ~121 ~91 dirt
setblock ~140 ~121 ~92 dirt
setblock ~140 ~121 ~93 dirt
setblock ~140 ~121 ~94 dirt
setblock ~140 ~121 ~95 dirt
setblock ~140 ~121 ~96 dirt
setblock ~140 ~121 ~97 dirt
setblock ~140 ~121 ~98 dirt
setblock ~140 ~121 ~99 dirt
setblock ~140 ~121 ~100 dirt
setblock ~140 ~121 ~101 dirt
setblock ~140 ~121 ~102 dirt
setblock ~140 ~121 ~103 dirt
setblock ~140 ~121 ~104 dirt
setblock ~140 ~121 ~105 dirt
setblock ~140 ~121 ~106 dirt
setblock ~140 ~121 ~107 dirt
setblock ~140 ~121 ~108 dirt
setblock ~140 ~121 ~109 dirt
setblock ~140 ~121 ~110 dirt
setblock ~140 ~121 ~111 dirt
setblock ~140 ~121 ~112 dirt
setblock ~140 ~121 ~113 dirt
setblock ~140 ~121 ~114 dirt
setblock ~140 ~121 ~115 dirt
setblock ~140 ~121 ~116 dirt
setblock ~140 ~121 ~117 dirt
setblock ~140 ~122 ~90 dirt
setblock ~140 ~122 ~91 dirt
setblock ~140 ~122 ~92 dirt
setblock ~140 ~122 ~93 dirt
setblock ~140 ~122 ~94 dirt
setblock ~140 ~122 ~95 dirt
setblock ~140 ~122 ~96 dirt
setblock ~140 ~122 ~97 dirt
setblock ~140 ~122 ~98 dirt
setblock ~140 ~122 ~99 dirt
setblock ~140 ~122 ~100 dirt
setblock ~140 ~122 ~101 dirt
setblock ~140 ~122 ~102 dirt
setblock ~140 ~122 ~103 dirt
setblock ~140 ~122 ~104 dirt
setblock ~140 ~122 ~105 dirt
setblock ~140 ~122 ~106 dirt
setblock ~140 ~122 ~107 dirt
setblock ~140 ~122 ~108 dirt
setblock ~140 ~122 ~109 dirt
setblock ~140 ~122 ~110 dirt
setblock ~140 ~122 ~111 dirt
setblock ~140 ~122 ~112 dirt
setblock ~140 ~122 ~113 dirt
setblock ~140 ~122 ~114 dirt
setblock ~140 ~122 ~115 dirt
setblock ~140 ~122 ~116 dirt
setblock ~140 ~122 ~117 dirt
setblock ~140 ~123 ~90 dirt
setblock ~140 ~123 ~91 dirt
setblock ~140 ~123 ~92 dirt
setblock ~140 ~123 ~93 dirt
setblock ~140 ~123 ~94 dirt
setblock ~140 ~123 ~95 dirt
setblock ~140 ~123 ~96 dirt
setblock ~140 ~123 ~97 dirt
setblock ~140 ~123 ~98 dirt
setblock ~140 ~123 ~99 dirt
setblock ~140 ~123 ~100 dirt
setblock ~140 ~123 ~101 dirt
setblock ~140 ~123 ~102 dirt
setblock ~140 ~123 ~103 dirt
setblock ~140 ~123 ~104 dirt
setblock ~140 ~123 ~105 dirt
setblock ~140 ~123 ~106 dirt
setblock ~140 ~123 ~107 dirt
setblock ~140 ~123 ~108 dirt
setblock ~140 ~123 ~109 dirt
setblock ~140 ~123 ~110 dirt
setblock ~140 ~123 ~111 dirt
setblock ~140 ~123 ~112 dirt
setblock ~140 ~123 ~113 dirt
setblock ~140 ~123 ~114 dirt
setblock ~140 ~123 ~115 dirt
setblock ~140 ~123 ~116 dirt
setblock ~140 ~123 ~117 dirt
setblock ~140 ~124 ~90 dirt
setblock ~140 ~124 ~91 dirt
setblock ~140 ~124 ~92 dirt
setblock ~140 ~124 ~93 dirt
setblock ~140 ~124 ~94 dirt
setblock ~140 ~124 ~95 dirt
setblock ~140 ~124 ~96 dirt
setblock ~140 ~124 ~97 dirt
setblock ~140 ~124 ~98 dirt
setblock ~140 ~124 ~99 dirt
setblock ~140 ~124 ~100 grass_block
setblock ~140 ~124 ~101 dirt
setblock ~140 ~124 ~102 dirt
setblock ~140 ~124 ~103 dirt
setblock ~140 ~124 ~104 dirt
setblock ~140 ~124 ~105 dirt
setblock ~140 ~124 ~106 dirt
setblock ~140 ~124 ~107 dirt
setblock ~140 ~124 ~108 dirt
setblock ~140 ~124 ~109 dirt
setblock ~140 ~124 ~110 dirt
setblock ~140 ~124 ~111 dirt
setblock ~140 ~124 ~112 dirt
setblock ~140 ~124 ~113 dirt
setblock ~140 ~124 ~114 dirt
setblock ~140 ~124 ~115 dirt
setblock ~140 ~124 ~116 dirt
setblock ~140 ~124 ~117 dirt
setblock ~140 ~125 ~90 dirt
setblock ~140 ~125 ~91 dirt
setblock ~140 ~125 ~92 dirt
setblock ~140 ~125 ~93 dirt
setblock ~140 ~125 ~94 dirt
setblock ~140 ~125 ~95 dirt
setblock ~140 ~125 ~96 dirt
setblock ~140 ~125 ~97 dirt
setblock ~140 ~125 ~98 grass_block
setblock ~140 ~125 ~99 grass_block
setblock ~140 ~125 ~101 grass_block
setblock ~140 ~125 ~102 grass_block
setblock ~140 ~125 ~103 dirt
setblock ~140 ~125 ~104 dirt
setblock ~140 ~125 ~105 dirt
setblock ~140 ~125 ~106 dirt
setblock ~140 ~125 ~107 dirt
setblock ~140 ~125 ~108 dirt
setblock ~140 ~125 ~109 dirt
setblock ~140 ~125 ~110 dirt
setblock ~140 ~125 ~111 dirt
setblock ~140 ~125 ~112 dirt
setblock ~140 ~125 ~113 dirt
setblock ~140 ~125 ~114 dirt
setblock ~140 ~125 ~115 dirt
setblock ~140 ~125 ~116 dirt
setblock ~140 ~125 ~117 dirt
setblock ~140 ~126 ~90 dirt
setblock ~140 ~126 ~91 dirt
setblock ~140 ~126 ~92 dirt
setblock ~140 ~126 ~93 dirt
setblock ~140 ~126 ~94 dirt
setblock ~140 ~126 ~95 grass_block
setblock ~140 ~126 ~96 grass_block
setblock ~140 ~126 ~97 grass_block
setblock ~140 ~126 ~98 short_grass
setblock ~140 ~126 ~101 short_grass
setblock ~140 ~126 ~103 grass_block
setblock ~140 ~126 ~104 grass_block
setblock ~140 ~126 ~105 dirt
setblock ~140 ~126 ~106 dirt
setblock ~140 ~126 ~107 dirt
setblock ~140 ~126 ~108 dirt
setblock ~140 ~126 ~109 dirt
setblock ~140 ~126 ~110 dirt
setblock ~140 ~126 ~111 dirt
setblock ~140 ~126 ~112 dirt
setblock ~140 ~126 ~113 dirt
setblock ~140 ~126 ~114 dirt
setblock ~140 ~126 ~115 dirt
setblock ~140 ~126 ~116 dirt
setblock ~140 ~126 ~117 grass_block
setblock ~140 ~127 ~90 grass_block
setblock ~140 ~127 ~91 grass_block
setblock ~140 ~127 ~92 grass_block
setblock ~140 ~127 ~93 grass_block
setblock ~140 ~127 ~94 grass_block
setblock ~140 ~127 ~105 grass_block
setblock ~140 ~127 ~106 grass_block
setblock ~140 ~127 ~107 grass_block
setblock ~140 ~127 ~108 grass_block
setblock ~140 ~127 ~109 grass_block
setblock ~140 ~127 ~110 dirt
setblock ~140 ~127 ~111 grass_block
setblock ~140 ~127 ~112 grass_block
setblock ~140 ~127 ~113 grass_block
setblock ~140 ~127 ~114 grass_block
setblock ~140 ~127 ~115 grass_block
setblock ~140 ~127 ~116 grass_block
setblock ~140 ~128 ~90 fern
setblock ~140 ~128 ~106 short_grass
setblock ~140 ~128 ~107 short_grass
setblock ~140 ~128 ~108 fern
setblock ~140 ~128 ~110 grass_block
setblock ~140 ~128 ~111 fern
setblock ~140 ~128 ~114 short_grass
setblock ~141 ~112 ~97 dirt
setblock ~141 ~112 ~101 dirt
setblock ~141 ~113 ~96 dirt
setblock ~141 ~113 ~97 dirt
setblock ~141 ~113 ~98 dirt
setblock ~141 ~113 ~100 dirt
setblock ~141 ~113 ~101 dirt
setblock ~141 ~114 ~96 dirt
setblock ~141 ~114 ~97 dirt
setblock ~141 ~114 ~98 dirt
setblock ~141 ~114 ~99 dirt
setblock ~141 ~114 ~100 dirt
setblock ~141 ~114 ~101 dirt
setblock ~141 ~114 ~102 dirt
setblock ~141 ~114 ~104 dirt
setblock ~141 ~114 ~107 dirt
setblock ~141 ~115 ~95 dirt
setblock ~141 ~115 ~96 dirt
setblock ~141 ~115 ~97 dirt
setblock ~141 ~115 ~98 dirt
setblock ~141 ~115 ~99 dirt
setblock ~141 ~115 ~100 dirt
setblock ~141 ~115 ~101 dirt
setblock ~141 ~115 ~102 dirt
setblock ~141 ~115 ~103 dirt
setblock ~141 ~115 ~104 dirt
setblock ~141 ~115 ~106 dirt
setblock ~141 ~115 ~107 dirt
setblock ~141 ~116 ~94 dirt
setblock ~141 ~116 ~95 dirt
setblock ~141 ~116 ~96 dirt
setblock ~141 ~116 ~97 dirt
setblock ~141 ~116 ~98 dirt
setblock ~141 ~116 ~99 dirt
setblock ~141 ~116 ~100 dirt
setblock ~141 ~116 ~101 dirt
setblock ~141 ~116 ~102 dirt
setblock ~141 ~116 ~103 dirt
setblock ~141 ~116 ~104 dirt
setblock ~141 ~116 ~105 dirt
setblock ~141 ~116 ~106 dirt
setblock ~141 ~116 ~107 dirt
setblock ~141 ~117 ~93 dirt
setblock ~141 ~117 ~94 dirt
setblock ~141 ~117 ~95 dirt
setblock ~141 ~117 ~96 dirt
setblock ~141 ~117 ~97 dirt
setblock ~141 ~117 ~98 dirt
setblock ~141 ~117 ~99 dirt
setblock ~141 ~117 ~100 dirt
setblock ~141 ~117 ~101 dirt
setblock ~141 ~117 ~102 dirt
setblock ~141 ~117 ~103 dirt
setblock ~141 ~117 ~104 dirt
setblock ~141 ~117 ~105 dirt
setblock ~141 ~117 ~106 dirt
setblock ~141 ~117 ~107 dirt
setblock ~141 ~117 ~108 dirt
setblock ~141 ~117 ~109 dirt
setblock ~141 ~118 ~93 dirt
setblock ~141 ~118 ~94 dirt
setblock ~141 ~118 ~95 dirt
setblock ~141 ~118 ~96 dirt
setblock ~141 ~118 ~97 dirt
setblock ~141 ~118 ~98 dirt
setblock ~141 ~118 ~99 dirt
setblock ~141 ~118 ~100 dirt
setblock ~141 ~118 ~101 dirt
setblock ~141 ~118 ~102 dirt
setblock ~141 ~118 ~103 dirt
setblock ~141 ~118 ~104 dirt
setblock ~141 ~118 ~105 dirt
setblock ~141 ~118 ~106 dirt
setblock ~141 ~118 ~107 dirt
setblock ~141 ~118 ~108 dirt
setblock ~141 ~118 ~109 dirt
setblock ~141 ~118 ~110 dirt
setblock ~141 ~118 ~111 dirt
setblock ~141 ~119 ~93 dirt
setblock ~141 ~119 ~94 dirt
setblock ~141 ~119 ~95 dirt
setblock ~141 ~119 ~96 dirt
setblock ~141 ~119 ~97 dirt
setblock ~141 ~119 ~98 dirt
setblock ~141 ~119 ~99 dirt
setblock ~141 ~119 ~100 dirt
setblock ~141 ~119 ~101 dirt
setblock ~141 ~119 ~102 dirt
setblock ~141 ~119 ~103 dirt
setblock ~141 ~119 ~104 dirt
setblock ~141 ~119 ~105 dirt
setblock ~141 ~119 ~106 dirt
setblock ~141 ~119 ~107 dirt
setblock ~141 ~119 ~108 dirt
setblock ~141 ~119 ~109 dirt
setblock ~141 ~119 ~110 dirt
setblock ~141 ~119 ~111 dirt
setblock ~141 ~119 ~112 dirt
setblock ~141 ~120 ~93 dirt
setblock ~141 ~120 ~94 dirt
setblock ~141 ~120 ~95 dirt
setblock ~141 ~120 ~96 dirt
setblock ~141 ~120 ~97 dirt
setblock ~141 ~120 ~98 dirt
setblock ~141 ~120 ~99 dirt
setblock ~141 ~120 ~100 dirt
setblock ~141 ~120 ~101 dirt
setblock ~141 ~120 ~102 dirt
setblock ~141 ~120 ~103 dirt
setblock ~141 ~120 ~104 dirt
setblock ~141 ~120 ~105 dirt
setblock ~141 ~120 ~106 dirt
setblock ~141 ~120 ~107 dirt
setblock ~141 ~120 ~108 dirt
setblock ~141 ~120 ~109 dirt
setblock ~141 ~120 ~110 dirt
setblock ~141 ~120 ~111 dirt
setblock ~141 ~120 ~112 dirt
setblock ~141 ~121 ~92 dirt
setblock ~141 ~121 ~93 dirt
setblock ~141 ~121 ~94 dirt
setblock ~141 ~121 ~95 dirt
setblock ~141 ~121 ~96 dirt
setblock ~141 ~121 ~97 dirt
setblock ~141 ~121 ~98 dirt
setblock ~141 ~121 ~99 dirt
setblock ~141 ~121 ~100 dirt
setblock ~141 ~121 ~101 dirt
setblock ~141 ~121 ~102 dirt
setblock ~141 ~121 ~103 dirt
setblock ~141 ~121 ~104 dirt
setblock ~141 ~121 ~105 dirt
setblock ~141 ~121 ~106 dirt
setblock ~141 ~121 ~107 dirt
setblock ~141 ~121 ~108 dirt
setblock ~141 ~121 ~109 dirt
setblock ~141 ~121 ~110 dirt
setblock ~141 ~121 ~111 dirt
setblock ~141 ~121 ~112 dirt
setblock ~141 ~121 ~113 dirt
setblock ~141 ~121 ~116 dirt
setblock ~141 ~122 ~92 dirt
setblock ~141 ~122 ~93 dirt
setblock ~141 ~122 ~94 dirt
setblock ~141 ~122 ~95 dirt
setblock ~141 ~122 ~96 dirt
setblock ~141 ~122 ~97 dirt
setblock ~141 ~122 ~98 dirt
setblock ~141 ~122 ~99 dirt
setblock ~141 ~122 ~100 dirt
setblock ~141 ~122 ~101 dirt
setblock ~141 ~122 ~102 dirt
setblock ~141 ~122 ~103 dirt
setblock ~141 ~122 ~104 dirt
setblock ~141 ~122 ~105 dirt
setblock ~141 ~122 ~106 dirt
setblock ~141 ~122 ~107 dirt
setblock ~141 ~122 ~108 dirt
setblock ~141 ~122 ~109 dirt
setblock ~141 ~122 ~110 dirt
setblock ~141 ~122 ~111 dirt
setblock ~141 ~122 ~112 dirt
setblock ~141 ~122 ~113 dirt
setblock ~141 ~122 ~116 dirt
setblock ~141 ~123 ~92 dirt
setblock ~141 ~123 ~93 dirt
setblock ~141 ~123 ~94 dirt
setblock ~141 ~123 ~95 dirt
setblock ~141 ~123 ~96 dirt
setblock ~141 ~123 ~97 dirt
setblock ~141 ~123 ~98 dirt
setblock ~141 ~123 ~99 dirt
setblock ~141 ~123 ~100 dirt
setblock ~141 ~123 ~101 dirt
setblock ~141 ~123 ~102 dirt
setblock ~141 ~123 ~103 dirt
setblock ~141 ~123 ~104 dirt
setblock ~141 ~123 ~105 dirt
setblock ~141 ~123 ~106 dirt
setblock ~141 ~123 ~107 dirt
setblock ~141 ~123 ~108 dirt
setblock ~141 ~123 ~109 dirt
setblock ~141 ~123 ~110 dirt
setblock ~141 ~123 ~111 dirt
setblock ~141 ~123 ~112 dirt
setblock ~141 ~123 ~113 dirt
setblock ~141 ~123 ~116 dirt
setblock ~141 ~124 ~92 dirt
setblock ~141 ~124 ~93 dirt
setblock ~141 ~124 ~94 dirt
setblock ~141 ~124 ~95 dirt
setblock ~141 ~124 ~96 dirt
setblock ~141 ~124 ~97 dirt
setblock ~141 ~124 ~98 dirt
setblock ~141 ~124 ~99 dirt
setblock ~141 ~124 ~100 dirt
setblock ~141 ~124 ~101 dirt
setblock ~141 ~124 ~102 dirt
setblock ~141 ~124 ~103 dirt
setblock ~141 ~124 ~104 dirt
setblock ~141 ~124 ~105 dirt
setblock ~141 ~124 ~106 dirt
setblock ~141 ~124 ~107 dirt
setblock ~141 ~124 ~108 dirt
setblock ~141 ~124 ~109 dirt
setblock ~141 ~124 ~110 dirt
setblock ~141 ~124 ~111 dirt
setblock ~141 ~124 ~112 dirt
setblock ~141 ~124 ~113 dirt
setblock ~141 ~124 ~116 dirt
setblock ~141 ~125 ~92 dirt
setblock ~141 ~125 ~93 dirt
setblock ~141 ~125 ~94 dirt
setblock ~141 ~125 ~95 dirt
setblock ~141 ~125 ~96 dirt
setblock ~141 ~125 ~97 dirt
setblock ~141 ~125 ~98 grass_block
setblock ~141 ~125 ~99 grass_block
setblock ~141 ~125 ~100 grass_block
setblock ~141 ~125 ~101 grass_block
setblock ~141 ~125 ~102 dirt
setblock ~141 ~125 ~103 dirt
setblock ~141 ~125 ~104 dirt
setblock ~141 ~125 ~105 dirt
setblock ~141 ~125 ~106 dirt
setblock ~141 ~125 ~107 dirt
setblock ~141 ~125 ~108 dirt
setblock ~141 ~125 ~109 dirt
setblock ~141 ~125 ~110 dirt
setblock ~141 ~125 ~111 dirt
setblock ~141 ~125 ~112 dirt
setblock ~141 ~125 ~113 dirt
setblock ~141 ~125 ~116 dirt
setblock ~141 ~126 ~92 dirt
setblock ~141 ~126 ~93 dirt
setblock ~141 ~126 ~94 grass_block
setblock ~141 ~126 ~95 grass_block
setblock ~141 ~126 ~96 grass_block
setblock ~141 ~126 ~97 grass_block
setblock ~141 ~126 ~99 fern
setblock ~141 ~126 ~102 grass_block
setblock ~141 ~126 ~103 grass_block
setblock ~141 ~126 ~104 grass_block
setblock ~141 ~126 ~105 dirt
setblock ~141 ~126 ~106 dirt
setblock ~141 ~126 ~107 dirt
setblock ~141 ~126 ~108 dirt
setblock ~141 ~126 ~109 dirt
setblock ~141 ~126 ~110 dirt
setblock ~141 ~126 ~111 dirt
setblock ~141 ~126 ~112 dirt
setblock ~141 ~126 ~113 dirt
setblock ~141 ~126 ~116 dirt
setblock ~141 ~127 ~92 grass_block
setblock ~141 ~127 ~93 grass_block
setblock ~141 ~127 ~95 short_grass
setblock ~141 ~127 ~102 short_grass
setblock ~141 ~127 ~105 grass_block
setblock ~141 ~127 ~106 grass_block
setblock ~141 ~127 ~107 grass_block
setblock ~141 ~127 ~108 grass_block
setblock ~141 ~127 ~109 dirt
setblock ~141 ~127 ~110 dirt
setblock ~141 ~127 ~111 grass_block
setblock ~141 ~127 ~112 grass_block
setblock ~141 ~127 ~113 grass_block
setblock ~141 ~127 ~116 grass_block
setblock ~141 ~128 ~108 short_grass
setblock ~141 ~128 ~109 grass_block
setblock ~141 ~128 ~110 grass_block
setblock ~141 ~128 ~111 short_grass
setblock ~141 ~128 ~116 short_grass
setblock ~142 ~114 ~98 dirt
setblock ~142 ~114 ~100 dirt
setblock ~142 ~114 ~101 dirt
setblock ~142 ~115 ~96 dirt
setblock ~142 ~115 ~98 dirt
setblock ~142 ~115 ~99 dirt
setblock ~142 ~115 ~100 dirt
setblock ~142 ~115 ~101 dirt
setblock ~142 ~116 ~95 dirt
setblock ~142 ~116 ~96 dirt
setblock ~142 ~116 ~97 dirt
setblock ~142 ~116 ~98 dirt
setblock ~142 ~116 ~99 dirt
setblock ~142 ~116 ~100 dirt
setblock ~142 ~116 ~101 dirt
setblock ~142 ~116 ~102 dirt
setblock ~142 ~116 ~106 dirt
setblock ~142 ~117 ~94 dirt
setblock ~142 ~117 ~95 dirt
setblock ~142 ~117 ~96 dirt
setblock ~142 ~117 ~97 dirt
setblock ~142 ~117 ~98 dirt
setblock ~142 ~117 ~99 dirt
setblock ~142 ~117 ~100 dirt
setblock ~142 ~117 ~101 dirt
setblock ~142 ~117 ~102 dirt
setblock ~142 ~117 ~103 dirt
setblock ~142 ~117 ~105 dirt
setblock ~142 ~117 ~106 dirt
setblock ~142 ~117 ~107 dirt
setblock ~142 ~118 ~94 dirt
setblock ~142 ~118 ~95 dirt
setblock ~142 ~118 ~96 dirt
setblock ~142 ~118 ~97 dirt
setblock ~142 ~118 ~98 dirt
setblock ~142 ~118 ~99 dirt
setblock ~142 ~118 ~100 dirt
setblock ~142 ~118 ~101 dirt
setblock ~142 ~118 ~102 dirt
setblock ~142 ~118 ~103 dirt
setblock ~142 ~118 ~104 dirt
setblock ~142 ~118 ~105 dirt
setblock ~142 ~118 ~106 dirt
setblock ~142 ~118 ~107 dirt
setblock ~142 ~118 ~108 dirt
setblock ~142 ~119 ~94 dirt
setblock ~142 ~119 ~95 dirt
setblock ~142 ~119 ~96 dirt
setblock ~142 ~119 ~97 dirt
setblock ~142 ~119 ~98 dirt
setblock ~142 ~119 ~99 dirt
setblock ~142 ~119 ~100 dirt
setblock ~142 ~119 ~101 dirt
setblock ~142 ~119 ~102 dirt
setblock ~142 ~119 ~103 dirt
setblock ~142 ~119 ~104 dirt
setblock ~142 ~119 ~105 dirt
setblock ~142 ~119 ~106 dirt
setblock ~142 ~119 ~107 dirt
setblock ~142 ~119 ~108 dirt
setblock ~142 ~120 ~93 dirt
setblock ~142 ~120 ~94 dirt
setblock ~142 ~120 ~95 dirt
setblock ~142 ~120 ~96 dirt
setblock ~142 ~120 ~97 dirt
setblock ~142 ~120 ~98 dirt
setblock ~142 ~120 ~99 dirt
setblock ~142 ~120 ~100 dirt
setblock ~142 ~120 ~101 dirt
setblock ~142 ~120 ~102 dirt
setblock ~142 ~120 ~103 dirt
setblock ~142 ~120 ~104 dirt
setblock ~142 ~120 ~105 dirt
setblock ~142 ~120 ~106 dirt
setblock ~142 ~120 ~107 dirt
setblock ~142 ~120 ~108 dirt
setblock ~142 ~120 ~109 dirt
setblock ~142 ~120 ~111 dirt
setblock ~142 ~121 ~93 dirt
setblock ~142 ~121 ~94 dirt
setblock ~142 ~121 ~95 dirt
setblock ~142 ~121 ~96 dirt
setblock ~142 ~121 ~97 dirt
setblock ~142 ~121 ~98 dirt
setblock ~142 ~121 ~99 dirt
setblock ~142 ~121 ~100 dirt
setblock ~142 ~121 ~101 dirt
setblock ~142 ~121 ~102 dirt
setblock ~142 ~121 ~103 dirt
setblock ~142 ~121 ~104 dirt
setblock ~142 ~121 ~105 dirt
setblock ~142 ~121 ~106 dirt
setblock ~142 ~121 ~107 dirt
setblock ~142 ~121 ~108 dirt
setblock ~142 ~121 ~109 dirt
setblock ~142 ~121 ~110 dirt
setblock ~142 ~121 ~111 dirt
setblock ~142 ~121 ~112 dirt
setblock ~142 ~122 ~93 dirt
setblock ~142 ~122 ~94 dirt
setblock ~142 ~122 ~95 dirt
setblock ~142 ~122 ~96 dirt
setblock ~142 ~122 ~97 dirt
setblock ~142 ~122 ~98 dirt
setblock ~142 ~122 ~99 dirt
setblock ~142 ~122 ~100 dirt
setblock ~142 ~122 ~101 dirt
setblock ~142 ~122 ~102 dirt
setblock ~142 ~122 ~103 dirt
setblock ~142 ~122 ~104 dirt
setblock ~142 ~122 ~105 dirt
setblock ~142 ~122 ~106 dirt
setblock ~142 ~122 ~107 dirt
setblock ~142 ~122 ~108 dirt
setblock ~142 ~122 ~109 dirt
setblock ~142 ~122 ~110 dirt
setblock ~142 ~122 ~111 dirt
setblock ~142 ~122 ~112 dirt
setblock ~142 ~123 ~93 dirt
setblock ~142 ~123 ~94 dirt
setblock ~142 ~123 ~95 dirt
setblock ~142 ~123 ~96 dirt
setblock ~142 ~123 ~97 dirt
setblock ~142 ~123 ~98 dirt
setblock ~142 ~123 ~99 dirt
setblock ~142 ~123 ~100 dirt
setblock ~142 ~123 ~101 dirt
setblock ~142 ~123 ~102 dirt
setblock ~142 ~123 ~103 dirt
setblock ~142 ~123 ~104 dirt
setblock ~142 ~123 ~105 dirt
setblock ~142 ~123 ~106 dirt
setblock ~142 ~123 ~107 dirt
setblock ~142 ~123 ~108 dirt
setblock ~142 ~123 ~109 dirt
setblock ~142 ~123 ~110 dirt
setblock ~142 ~123 ~111 dirt
setblock ~142 ~123 ~112 dirt
setblock ~142 ~124 ~93 dirt
setblock ~142 ~124 ~94 dirt
setblock ~142 ~124 ~95 dirt
setblock ~142 ~124 ~96 dirt
setblock ~142 ~124 ~97 dirt
setblock ~142 ~124 ~98 dirt
setblock ~142 ~124 ~99 dirt
setblock ~142 ~124 ~100 dirt
setblock ~142 ~124 ~101 dirt
setblock ~142 ~124 ~102 dirt
setblock ~142 ~124 ~103 dirt
setblock ~142 ~124 ~104 dirt
setblock ~142 ~124 ~105 dirt
setblock ~142 ~124 ~106 dirt
setblock ~142 ~124 ~107 dirt
setblock ~142 ~124 ~108 dirt
setblock ~142 ~124 ~109 dirt
setblock ~142 ~124 ~110 dirt
setblock ~142 ~124 ~111 dirt
