setblock ~0 ~1 ~0 gold_block
setblock ~31 ~120 ~90 dirt
setblock ~31 ~121 ~89 dirt
setblock ~31 ~121 ~90 dirt
setblock ~31 ~121 ~93 dirt
setblock ~31 ~121 ~94 dirt
setblock ~31 ~122 ~89 dirt
setblock ~31 ~122 ~90 dirt
setblock ~31 ~122 ~93 dirt
setblock ~31 ~122 ~94 dirt
setblock ~31 ~123 ~89 dirt
setblock ~31 ~123 ~90 dirt
setblock ~31 ~123 ~93 dirt
setblock ~31 ~123 ~94 dirt
setblock ~31 ~124 ~89 dirt
setblock ~31 ~124 ~90 dirt
setblock ~31 ~124 ~93 dirt
setblock ~31 ~124 ~94 dirt
setblock ~31 ~125 ~89 dirt
setblock ~31 ~125 ~90 dirt
setblock ~31 ~125 ~93 dirt
setblock ~31 ~125 ~94 dirt
setblock ~31 ~126 ~89 dirt
setblock ~31 ~126 ~90 dirt
setblock ~31 ~126 ~93 dirt
setblock ~31 ~126 ~94 dirt
setblock ~31 ~127 ~89 dirt
setblock ~31 ~127 ~90 dirt
setblock ~31 ~127 ~93 dirt
setblock ~31 ~127 ~94 grass_block
setblock ~31 ~128 ~89 dirt
setblock ~31 ~128 ~90 dirt
setblock ~31 ~128 ~93 grass_block
setblock ~31 ~129 ~89 grass_block
setblock ~31 ~129 ~90 dirt
setblock ~31 ~129 ~93 short_grass
setblock ~31 ~130 ~90 grass_block
setblock ~32 ~119 ~90 dirt
setblock ~32 ~119 ~91 dirt
setblock ~32 ~119 ~92 dirt
setblock ~32 ~119 ~94 dirt
setblock ~32 ~120 ~89 dirt
setblock ~32 ~120 ~90 dirt
setblock ~32 ~120 ~91 dirt
setblock ~32 ~120 ~92 dirt
setblock ~32 ~120 ~93 dirt
setblock ~32 ~120 ~94 dirt
setblock ~32 ~121 ~88 dirt
setblock ~32 ~121 ~89 dirt
setblock ~32 ~121 ~90 dirt
setblock ~32 ~121 ~91 dirt
setblock ~32 ~121 ~92 dirt
setblock ~32 ~121 ~93 dirt
setblock ~32 ~121 ~94 dirt
setblock ~32 ~121 ~95 dirt
setblock ~32 ~121 ~96 dirt
setblock ~32 ~121 ~100 dirt
setblock ~32 ~122 ~88 dirt
setblock ~32 ~122 ~89 dirt
setblock ~32 ~122 ~90 dirt
setblock ~32 ~122 ~91 dirt
setblock ~32 ~122 ~92 dirt
setblock ~32 ~122 ~93 dirt
setblock ~32 ~122 ~94 dirt
setblock ~32 ~122 ~95 dirt
setblock ~32 ~122 ~96 dirt
setblock ~32 ~122 ~100 dirt
setblock ~32 ~123 ~88 dirt
setblock ~32 ~123 ~89 dirt
setblock ~32 ~123 ~90 dirt
setblock ~32 ~123 ~91 dirt
setblock ~32 ~123 ~92 dirt
setblock ~32 ~123 ~93 dirt
setblock ~32 ~123 ~94 dirt
setblock ~32 ~123 ~95 dirt
setblock ~32 ~123 ~96 dirt
setblock ~32 ~123 ~100 grass_block
setblock ~32 ~124 ~88 dirt
setblock ~32 ~124 ~89 dirt
setblock ~32 ~124 ~90 dirt
setblock ~32 ~124 ~91 dirt
setblock ~32 ~124 ~92 dirt
setblock ~32 ~124 ~93 dirt
setblock ~32 ~124 ~94 dirt
setblock ~32 ~124 ~95 dirt
setblock ~32 ~124 ~96 dirt
setblock ~32 ~125 ~88 dirt
setblock ~32 ~125 ~89 dirt
setblock ~32 ~125 ~90 dirt
setblock ~32 ~125 ~91 dirt
setblock ~32 ~125 ~92 dirt
setblock ~32 ~125 ~93 dirt
setblock ~32 ~125 ~94 dirt
setblock ~32 ~125 ~95 dirt
setblock ~32 ~125 ~96 grass_block
setblock ~32 ~126 ~88 dirt
setblock ~32 ~126 ~89 dirt
setblock ~32 ~126 ~90 dirt
setblock ~32 ~126 ~91 dirt
setblock ~32 ~126 ~92 dirt
setblock ~32 ~126 ~93 dirt
setblock ~32 ~126 ~94 dirt
setblock ~32 ~126 ~95 grass_block
setblock ~32 ~127 ~88 dirt
setblock ~32 ~127 ~89 dirt
setblock ~32 ~127 ~90 dirt
setblock ~32 ~127 ~91 dirt
setblock ~32 ~127 ~92 dirt
setblock ~32 ~127 ~93 grass_block
setblock ~32 ~127 ~94 grass_block
setblock ~32 ~128 ~88 grass_block
setblock ~32 ~128 ~89 dirt
setblock ~32 ~128 ~90 dirt
setblock ~32 ~128 ~91 dirt
setblock ~32 ~128 ~92 grass_block
setblock ~32 ~129 ~89 grass_block
setblock ~32 ~129 ~90 grass_block
setblock ~32 ~129 ~91 grass_block
setblock ~33 ~115 ~92 dirt
setblock ~33 ~116 ~91 dirt
setblock ~33 ~116 ~92 dirt
setblock ~33 ~117 ~91 dirt
setblock ~33 ~117 ~92 dirt
setblock ~33 ~117 ~93 dirt
setblock ~33 ~117 ~94 dirt
setblock ~33 ~118 ~90 dirt
setblock ~33 ~118 ~91 dirt
setblock ~33 ~118 ~92 dirt
setblock ~33 ~118 ~93 dirt
setblock ~33 ~118 ~94 dirt
setblock ~33 ~119 ~89 dirt
setblock ~33 ~119 ~90 dirt
setblock ~33 ~119 ~91 dirt
setblock ~33 ~119 ~92 dirt
setblock ~33 ~119 ~93 dirt
setblock ~33 ~119 ~94 dirt
setblock ~33 ~119 ~95 dirt
setblock ~33 ~119 ~96 dirt
setblock ~33 ~119 ~100 dirt
setblock ~33 ~120 ~89 dirt
setblock ~33 ~120 ~90 dirt
setblock ~33 ~120 ~91 dirt
setblock ~33 ~120 ~92 dirt
setblock ~33 ~120 ~93 dirt
setblock ~33 ~120 ~94 dirt
setblock ~33 ~120 ~95 dirt
setblock ~33 ~120 ~96 dirt
setblock ~33 ~120 ~100 dirt
setblock ~33 ~121 ~88 dirt
setblock ~33 ~121 ~89 dirt
setblock ~33 ~121 ~90 dirt
setblock ~33 ~121 ~91 dirt
setblock ~33 ~121 ~92 dirt
setblock ~33 ~121 ~93 dirt
setblock ~33 ~121 ~94 dirt
setblock ~33 ~121 ~95 dirt
setblock ~33 ~121 ~96 dirt
setblock ~33 ~121 ~97 dirt
setblock ~33 ~121 ~99 dirt
setblock ~33 ~121 ~100 dirt
setblock ~33 ~121 ~101 dirt
setblock ~33 ~122 ~88 dirt
setblock ~33 ~122 ~89 dirt
setblock ~33 ~122 ~90 dirt
setblock ~33 ~122 ~91 dirt
setblock ~33 ~122 ~92 dirt
setblock ~33 ~122 ~93 dirt
setblock ~33 ~122 ~94 dirt
setblock ~33 ~122 ~95 dirt
setblock ~33 ~122 ~96 dirt
setblock ~33 ~122 ~97 dirt
setblock ~33 ~122 ~99 dirt
setblock ~33 ~122 ~100 dirt
setblock ~33 ~122 ~101 dirt
setblock ~33 ~123 ~88 dirt
setblock ~33 ~123 ~89 dirt
setblock ~33 ~123 ~90 dirt
setblock ~33 ~123 ~91 dirt
setblock ~33 ~123 ~92 dirt
setblock ~33 ~123 ~93 dirt
setblock ~33 ~123 ~94 dirt
setblock ~33 ~123 ~95 dirt
setblock ~33 ~123 ~96 dirt
setblock ~33 ~123 ~97 dirt
setblock ~33 ~123 ~99 grass_block
setblock ~33 ~123 ~100 grass_block
setblock ~33 ~123 ~101 grass_block
setblock ~33 ~124 ~88 dirt
setblock ~33 ~124 ~89 dirt
setblock ~33 ~124 ~90 dirt
setblock ~33 ~124 ~91 dirt
setblock ~33 ~124 ~92 dirt
setblock ~33 ~124 ~93 dirt
setblock ~33 ~124 ~94 dirt
setblock ~33 ~124 ~95 dirt
setblock ~33 ~124 ~96 dirt
setblock ~33 ~124 ~97 grass_block
setblock ~33 ~124 ~99 short_grass
setblock ~33 ~124 ~100 poppy
setblock ~33 ~125 ~88 dirt
setblock ~33 ~125 ~89 dirt
setblock ~33 ~125 ~90 dirt
setblock ~33 ~125 ~91 dirt
setblock ~33 ~125 ~92 dirt
setblock ~33 ~125 ~93 dirt
setblock ~33 ~125 ~94 dirt
setblock ~33 ~125 ~95 dirt
setblock ~33 ~125 ~96 grass_block
setblock ~33 ~125 ~97 short_grass
setblock ~33 ~126 ~88 dirt
setblock ~33 ~126 ~89 dirt
setblock ~33 ~126 ~90 dirt
setblock ~33 ~126 ~91 dirt
setblock ~33 ~126 ~92 dirt
setblock ~33 ~126 ~93 dirt
setblock ~33 ~126 ~94 grass_block
setblock ~33 ~126 ~95 grass_block
setblock ~33 ~127 ~88 dirt
setblock ~33 ~127 ~89 dirt
setblock ~33 ~127 ~90 dirt
setblock ~33 ~127 ~91 dirt
setblock ~33 ~127 ~92 grass_block
setblock ~33 ~127 ~93 grass_block
setblock ~33 ~127 ~94 short_grass
setblock ~33 ~128 ~88 grass_block
setblock ~33 ~128 ~89 grass_block
setblock ~33 ~128 ~90 grass_block
setblock ~33 ~128 ~91 grass_block
setblock ~33 ~128 ~92 short_grass
setblock ~33 ~128 ~93 short_grass
setblock ~34 ~114 ~92 dirt
setblock ~34 ~115 ~91 dirt
setblock ~34 ~115 ~92 dirt
setblock ~34 ~115 ~93 dirt
setblock ~34 ~116 ~90 dirt
setblock ~34 ~116 ~91 dirt
setblock ~34 ~116 ~92 dirt
setblock ~34 ~116 ~93 dirt
setblock ~34 ~116 ~94 dirt
setblock ~34 ~117 ~90 dirt
setblock ~34 ~117 ~91 dirt
setblock ~34 ~117 ~92 dirt
setblock ~34 ~117 ~93 dirt
setblock ~34 ~117 ~94 dirt
setblock ~34 ~117 ~95 dirt
setblock ~34 ~117 ~96 dirt
setblock ~34 ~118 ~89 dirt
setblock ~34 ~118 ~90 dirt
setblock ~34 ~118 ~91 dirt
setblock ~34 ~118 ~92 dirt
setblock ~34 ~118 ~93 dirt
setblock ~34 ~118 ~94 dirt
setblock ~34 ~118 ~95 dirt
setblock ~34 ~118 ~96 dirt
setblock ~34 ~118 ~100 dirt
setblock ~34 ~119 ~88 dirt
setblock ~34 ~119 ~89 dirt
setblock ~34 ~119 ~90 dirt
setblock ~34 ~119 ~91 dirt
setblock ~34 ~119 ~92 dirt
setblock ~34 ~119 ~93 dirt
setblock ~34 ~119 ~94 dirt
setblock ~34 ~119 ~95 dirt
setblock ~34 ~119 ~96 dirt
setblock ~34 ~119 ~97 dirt
setblock ~34 ~119 ~99 dirt
setblock ~34 ~119 ~100 dirt
setblock ~34 ~119 ~101 dirt
setblock ~34 ~119 ~103 dirt
setblock ~34 ~120 ~78 dirt
setblock ~34 ~120 ~88 dirt
setblock ~34 ~120 ~89 dirt
setblock ~34 ~120 ~90 dirt
setblock ~34 ~120 ~91 dirt
setblock ~34 ~120 ~92 dirt
setblock ~34 ~120 ~93 dirt
setblock ~34 ~120 ~94 dirt
setblock ~34 ~120 ~95 dirt
setblock ~34 ~120 ~96 dirt
setblock ~34 ~120 ~97 dirt
setblock ~34 ~120 ~99 dirt
setblock ~34 ~120 ~100 dirt
setblock ~34 ~120 ~101 dirt
setblock ~34 ~120 ~103 dirt
setblock ~34 ~120 ~104 dirt
setblock ~34 ~121 ~76 dirt
setblock ~34 ~121 ~78 dirt
setblock ~34 ~121 ~79 dirt
setblock ~34 ~121 ~87 dirt
setblock ~34 ~121 ~88 dirt
setblock ~34 ~121 ~89 dirt
setblock ~34 ~121 ~90 dirt
setblock ~34 ~121 ~91 dirt
setblock ~34 ~121 ~92 dirt
setblock ~34 ~121 ~93 dirt
setblock ~34 ~121 ~94 dirt
setblock ~34 ~121 ~95 dirt
setblock ~34 ~121 ~96 dirt
setblock ~34 ~121 ~97 dirt
setblock ~34 ~121 ~98 dirt
setblock ~34 ~121 ~99 dirt
setblock ~34 ~121 ~100 dirt
setblock ~34 ~121 ~101 dirt
setblock ~34 ~121 ~102 dirt
setblock ~34 ~121 ~103 dirt
setblock ~34 ~121 ~104 dirt
setblock ~34 ~121 ~121 dirt
setblock ~34 ~121 ~122 dirt
setblock ~34 ~121 ~123 dirt
setblock ~34 ~122 ~76 dirt
setblock ~34 ~122 ~78 dirt
setblock ~34 ~122 ~79 dirt
setblock ~34 ~122 ~87 dirt
setblock ~34 ~122 ~88 dirt
setblock ~34 ~122 ~89 dirt
setblock ~34 ~122 ~90 dirt
setblock ~34 ~122 ~91 dirt
setblock ~34 ~122 ~92 dirt
setblock ~34 ~122 ~93 dirt
setblock ~34 ~122 ~94 dirt
setblock ~34 ~122 ~95 dirt
setblock ~34 ~122 ~96 dirt
setblock ~34 ~122 ~97 dirt
setblock ~34 ~122 ~98 dirt
setblock ~34 ~122 ~99 dirt
setblock ~34 ~122 ~100 dirt
setblock ~34 ~122 ~101 dirt
setblock ~34 ~122 ~102 dirt
setblock ~34 ~122 ~103 dirt
setblock ~34 ~122 ~104 dirt
setblock ~34 ~122 ~121 dirt
setblock ~34 ~122 ~122 dirt
setblock ~34 ~122 ~123 dirt
setblock ~34 ~123 ~76 dirt
setblock ~34 ~123 ~78 dirt
setblock ~34 ~123 ~79 dirt
setblock ~34 ~123 ~87 dirt
setblock ~34 ~123 ~88 dirt
setblock ~34 ~123 ~89 dirt
setblock ~34 ~123 ~90 dirt
setblock ~34 ~123 ~91 dirt
setblock ~34 ~123 ~92 dirt
setblock ~34 ~123 ~93 dirt
setblock ~34 ~123 ~94 dirt
setblock ~34 ~123 ~95 dirt
setblock ~34 ~123 ~96 dirt
setblock ~34 ~123 ~97 dirt
setblock ~34 ~123 ~98 dirt
setblock ~34 ~123 ~99 grass_block
setblock ~34 ~123 ~100 grass_block
setblock ~34 ~123 ~101 grass_block
setblock ~34 ~123 ~102 grass_block
setblock ~34 ~123 ~103 dirt
setblock ~34 ~123 ~104 dirt
setblock ~34 ~123 ~121 dirt
setblock ~34 ~123 ~122 dirt
setblock ~34 ~123 ~123 dirt
setblock ~34 ~124 ~76 dirt
setblock ~34 ~124 ~78 dirt
setblock ~34 ~124 ~79 dirt
setblock ~34 ~124 ~87 dirt
setblock ~34 ~124 ~88 dirt
setblock ~34 ~124 ~89 dirt
setblock ~34 ~124 ~90 dirt
setblock ~34 ~124 ~91 dirt
setblock ~34 ~124 ~92 dirt
setblock ~34 ~124 ~93 dirt
setblock ~34 ~124 ~94 dirt
setblock ~34 ~124 ~95 dirt
setblock ~34 ~124 ~96 dirt
setblock ~34 ~124 ~97 grass_block
setblock ~34 ~124 ~98 grass_block
setblock ~34 ~124 ~103 grass_block
setblock ~34 ~124 ~104 grass_block
setblock ~34 ~124 ~121 grass_block
setblock ~34 ~124 ~122 grass_block
setblock ~34 ~124 ~123 dirt
setblock ~34 ~125 ~76 grass_block
setblock ~34 ~125 ~78 grass_block
setblock ~34 ~125 ~79 grass_block
setblock ~34 ~125 ~87 dirt
setblock ~34 ~125 ~88 dirt
setblock ~34 ~125 ~89 dirt
setblock ~34 ~125 ~90 dirt
setblock ~34 ~125 ~91 dirt
setblock ~34 ~125 ~92 dirt
setblock ~34 ~125 ~93 dirt
setblock ~34 ~125 ~94 dirt
setblock ~34 ~125 ~95 grass_block
setblock ~34 ~125 ~96 grass_block
setblock ~34 ~125 ~98 short_grass
setblock ~34 ~125 ~122 short_grass
setblock ~34 ~125 ~123 grass_block
setblock ~34 ~126 ~87 dirt
setblock ~34 ~126 ~88 dirt
setblock ~34 ~126 ~89 dirt
setblock ~34 ~126 ~90 dirt
setblock ~34 ~126 ~91 dirt
setblock ~34 ~126 ~92 dirt
setblock ~34 ~126 ~93 grass_block
setblock ~34 ~126 ~94 grass_block
setblock ~34 ~126 ~95 short_grass
setblock ~34 ~126 ~96 short_grass
setblock ~34 ~127 ~87 grass_block
setblock ~34 ~127 ~88 grass_block
setblock ~34 ~127 ~89 grass_block
setblock ~34 ~127 ~90 dirt
setblock ~34 ~127 ~91 grass_block
setblock ~34 ~127 ~92 grass_block
setblock ~34 ~127 ~94 short_grass
setblock ~34 ~128 ~90 grass_block
setblock ~35 ~113 ~92 dirt
setblock ~35 ~114 ~91 dirt
setblock ~35 ~114 ~92 dirt
setblock ~35 ~114 ~93 dirt
setblock ~35 ~115 ~90 dirt
setblock ~35 ~115 ~91 dirt
setblock ~35 ~115 ~92 dirt
setblock ~35 ~115 ~93 dirt
setblock ~35 ~115 ~94 dirt
setblock ~35 ~116 ~90 dirt
setblock ~35 ~116 ~91 dirt
setblock ~35 ~116 ~92 dirt
setblock ~35 ~116 ~93 dirt
setblock ~35 ~116 ~94 dirt
setblock ~35 ~116 ~95 dirt
setblock ~35 ~116 ~96 dirt
setblock ~35 ~117 ~90 dirt
setblock ~35 ~117 ~91 dirt
setblock ~35 ~117 ~92 dirt
setblock ~35 ~117 ~93 dirt
setblock ~35 ~117 ~94 dirt
setblock ~35 ~117 ~95 dirt
setblock ~35 ~117 ~96 dirt
setblock ~35 ~117 ~97 dirt
setblock ~35 ~117 ~100 dirt
setblock ~35 ~118 ~90 dirt
setblock ~35 ~118 ~91 dirt
setblock ~35 ~118 ~92 dirt
setblock ~35 ~118 ~93 dirt
setblock ~35 ~118 ~94 dirt
setblock ~35 ~118 ~95 dirt
setblock ~35 ~118 ~96 dirt
setblock ~35 ~118 ~97 dirt
setblock ~35 ~118 ~99 dirt
setblock ~35 ~118 ~100 dirt
setblock ~35 ~118 ~101 dirt
setblock ~35 ~118 ~102 dirt
setblock ~35 ~118 ~103 dirt
setblock ~35 ~119 ~76 dirt
setblock ~35 ~119 ~78 dirt
setblock ~35 ~119 ~89 dirt
setblock ~35 ~119 ~90 dirt
setblock ~35 ~119 ~91 dirt
setblock ~35 ~119 ~92 dirt
setblock ~35 ~119 ~93 dirt
setblock ~35 ~119 ~94 dirt
setblock ~35 ~119 ~95 dirt
setblock ~35 ~119 ~96 dirt
setblock ~35 ~119 ~97 dirt
setblock ~35 ~119 ~98 dirt
setblock ~35 ~119 ~99 dirt
setblock ~35 ~119 ~100 dirt
setblock ~35 ~119 ~101 dirt
setblock ~35 ~119 ~102 dirt
setblock ~35 ~119 ~103 dirt
setblock ~35 ~119 ~104 dirt
setblock ~35 ~119 ~105 dirt
setblock ~35 ~120 ~76 dirt
setblock ~35 ~120 ~77 dirt
setblock ~35 ~120 ~78 dirt
setblock ~35 ~120 ~79 dirt
setblock ~35 ~120 ~88 dirt
setblock ~35 ~120 ~89 dirt
setblock ~35 ~120 ~90 dirt
setblock ~35 ~120 ~91 dirt
setblock ~35 ~120 ~92 dirt
setblock ~35 ~120 ~93 dirt
setblock ~35 ~120 ~94 dirt
setblock ~35 ~120 ~95 dirt
setblock ~35 ~120 ~96 dirt
setblock ~35 ~120 ~97 dirt
setblock ~35 ~120 ~98 dirt
setblock ~35 ~120 ~99 dirt
setblock ~35 ~120 ~100 dirt
setblock ~35 ~120 ~101 dirt
setblock ~35 ~120 ~102 dirt
setblock ~35 ~120 ~103 dirt
setblock ~35 ~120 ~104 dirt
setblock ~35 ~120 ~105 dirt
setblock ~35 ~120 ~118 dirt
setblock ~35 ~120 ~121 dirt
setblock ~35 ~120 ~122 dirt
setblock ~35 ~120 ~123 dirt
setblock ~35 ~121 ~75 dirt
setblock ~35 ~121 ~76 dirt
setblock ~35 ~121 ~77 dirt
setblock ~35 ~121 ~78 dirt
setblock ~35 ~121 ~79 dirt
setblock ~35 ~121 ~80 dirt
setblock ~35 ~121 ~85 dirt
setblock ~35 ~121 ~86 dirt
setblock ~35 ~121 ~87 dirt
setblock ~35 ~121 ~88 dirt
setblock ~35 ~121 ~89 dirt
setblock ~35 ~121 ~90 dirt
setblock ~35 ~121 ~91 dirt
setblock ~35 ~121 ~92 dirt
setblock ~35 ~121 ~93 dirt
setblock ~35 ~121 ~94 dirt
setblock ~35 ~121 ~95 dirt
setblock ~35 ~121 ~96 dirt
setblock ~35 ~121 ~97 dirt
setblock ~35 ~121 ~98 dirt
setblock ~35 ~121 ~99 dirt
setblock ~35 ~121 ~100 dirt
setblock ~35 ~121 ~101 dirt
setblock ~35 ~121 ~102 dirt
setblock ~35 ~121 ~103 dirt
setblock ~35 ~121 ~104 dirt
setblock ~35 ~121 ~105 dirt
setblock ~35 ~121 ~106 dirt
setblock ~35 ~121 ~116 dirt
setblock ~35 ~121 ~117 dirt
setblock ~35 ~121 ~118 dirt
setblock ~35 ~121 ~120 dirt
setblock ~35 ~121 ~121 dirt
setblock ~35 ~121 ~122 dirt
setblock ~35 ~121 ~123 dirt
setblock ~35 ~121 ~124 dirt
setblock ~35 ~121 ~125 dirt
setblock ~35 ~122 ~75 dirt
setblock ~35 ~122 ~76 dirt
setblock ~35 ~122 ~77 dirt
setblock ~35 ~122 ~78 dirt
setblock ~35 ~122 ~79 dirt
setblock ~35 ~122 ~80 dirt
setblock ~35 ~122 ~85 dirt
setblock ~35 ~122 ~86 dirt
setblock ~35 ~122 ~87 dirt
setblock ~35 ~122 ~88 dirt
setblock ~35 ~122 ~89 dirt
setblock ~35 ~122 ~90 dirt
setblock ~35 ~122 ~91 dirt
setblock ~35 ~122 ~92 dirt
setblock ~35 ~122 ~93 dirt
setblock ~35 ~122 ~94 dirt
setblock ~35 ~122 ~95 dirt
setblock ~35 ~122 ~96 dirt
setblock ~35 ~122 ~97 dirt
setblock ~35 ~122 ~98 dirt
setblock ~35 ~122 ~99 dirt
setblock ~35 ~122 ~100 dirt
setblock ~35 ~122 ~101 dirt
setblock ~35 ~122 ~102 dirt
setblock ~35 ~122 ~103 dirt
setblock ~35 ~122 ~104 dirt
setblock ~35 ~122 ~105 dirt
setblock ~35 ~122 ~106 dirt
setblock ~35 ~122 ~116 dirt
setblock ~35 ~122 ~117 dirt
setblock ~35 ~122 ~118 dirt
setblock ~35 ~122 ~120 dirt
setblock ~35 ~122 ~121 dirt
setblock ~35 ~122 ~122 dirt
setblock ~35 ~122 ~123 dirt
setblock ~35 ~122 ~124 dirt
setblock ~35 ~122 ~125 dirt
setblock ~35 ~123 ~75 dirt
setblock ~35 ~123 ~76 dirt
setblock ~35 ~123 ~77 dirt
setblock ~35 ~123 ~78 dirt
setblock ~35 ~123 ~79 dirt
setblock ~35 ~123 ~80 dirt
setblock ~35 ~123 ~85 dirt
setblock ~35 ~123 ~86 dirt
setblock ~35 ~123 ~87 dirt
setblock ~35 ~123 ~88 dirt
setblock ~35 ~123 ~89 dirt
setblock ~35 ~123 ~90 dirt
setblock ~35 ~123 ~91 dirt
setblock ~35 ~123 ~92 dirt
setblock ~35 ~123 ~93 dirt
setblock ~35 ~123 ~94 dirt
setblock ~35 ~123 ~95 dirt
setblock ~35 ~123 ~96 dirt
setblock ~35 ~123 ~97 dirt
setblock ~35 ~123 ~98 dirt
setblock ~35 ~123 ~99 grass_block
setblock ~35 ~123 ~100 grass_block
setblock ~35 ~123 ~101 grass_block
setblock ~35 ~123 ~102 grass_block
setblock ~35 ~123 ~103 dirt
setblock ~35 ~123 ~104 dirt
setblock ~35 ~123 ~105 dirt
setblock ~35 ~123 ~106 dirt
setblock ~35 ~123 ~116 dirt
setblock ~35 ~123 ~117 dirt
setblock ~35 ~123 ~118 dirt
setblock ~35 ~123 ~120 dirt
setblock ~35 ~123 ~121 dirt
setblock ~35 ~123 ~122 dirt
setblock ~35 ~123 ~123 dirt
setblock ~35 ~123 ~124 dirt
setblock ~35 ~123 ~125 dirt
setblock ~35 ~124 ~75 dirt
setblock ~35 ~124 ~76 dirt
setblock ~35 ~124 ~77 dirt
setblock ~35 ~124 ~78 dirt
setblock ~35 ~124 ~79 dirt
setblock ~35 ~124 ~80 dirt
setblock ~35 ~124 ~85 dirt
setblock ~35 ~124 ~86 dirt
setblock ~35 ~124 ~87 dirt
setblock ~35 ~124 ~88 dirt
setblock ~35 ~124 ~89 dirt
setblock ~35 ~124 ~90 dirt
setblock ~35 ~124 ~91 dirt
setblock ~35 ~124 ~92 dirt
setblock ~35 ~124 ~93 dirt
setblock ~35 ~124 ~94 dirt
setblock ~35 ~124 ~95 dirt
setblock ~35 ~124 ~96 dirt
setblock ~35 ~124 ~97 grass_block
setblock ~35 ~124 ~98 grass_block
setblock ~35 ~124 ~99 short_grass
setblock ~35 ~124 ~102 short_grass
setblock ~35 ~124 ~103 grass_block
setblock ~35 ~124 ~104 grass_block
setblock ~35 ~124 ~105 grass_block
setblock ~35 ~124 ~106 grass_block
setblock ~35 ~124 ~116 grass_block
setblock ~35 ~124 ~117 dirt
setblock ~35 ~124 ~118 dirt
setblock ~35 ~124 ~120 dirt
setblock ~35 ~124 ~121 dirt
setblock ~35 ~124 ~122 dirt
setblock ~35 ~124 ~123 dirt
setblock ~35 ~124 ~124 dirt
setblock ~35 ~124 ~125 dirt
setblock ~35 ~125 ~75 grass_block
setblock ~35 ~125 ~76 grass_block
setblock ~35 ~125 ~77 grass_block
setblock ~35 ~125 ~78 grass_block
setblock ~35 ~125 ~79 grass_block
setblock ~35 ~125 ~80 grass_block
setblock ~35 ~125 ~85 dirt
setblock ~35 ~125 ~86 dirt
setblock ~35 ~125 ~87 dirt
setblock ~35 ~125 ~88 dirt
setblock ~35 ~125 ~89 dirt
setblock ~35 ~125 ~90 dirt
setblock ~35 ~125 ~91 dirt
setblock ~35 ~125 ~92 dirt
setblock ~35 ~125 ~93 dirt
setblock ~35 ~125 ~94 grass_block
setblock ~35 ~125 ~95 grass_block
setblock ~35 ~125 ~96 grass_block
setblock ~35 ~125 ~104 short_grass
setblock ~35 ~125 ~117 grass_block
setblock ~35 ~125 ~118 grass_block
setblock ~35 ~125 ~120 grass_block
setblock ~35 ~125 ~121 grass_block
setblock ~35 ~125 ~122 grass_block
setblock ~35 ~125 ~123 grass_block
setblock ~35 ~125 ~124 grass_block
setblock ~35 ~125 ~125 grass_block
setblock ~35 ~126 ~85 grass_block
setblock ~35 ~126 ~86 grass_block
setblock ~35 ~126 ~87 grass_block
setblock ~35 ~126 ~88 dirt
setblock ~35 ~126 ~89 dirt
setblock ~35 ~126 ~90 dirt
setblock ~35 ~126 ~91 grass_block
setblock ~35 ~126 ~92 grass_block
setblock ~35 ~126 ~93 grass_block
setblock ~35 ~126 ~96 short_grass
setblock ~35 ~126 ~123 poppy
setblock ~35 ~127 ~86 short_grass
setblock ~35 ~127 ~87 short_grass
setblock ~35 ~127 ~88 grass_block
setblock ~35 ~127 ~89 grass_block
setblock ~35 ~127 ~90 grass_block
setblock ~36 ~111 ~93 dirt
setblock ~36 ~112 ~92 dirt
setblock ~36 ~112 ~93 dirt
setblock ~36 ~112 ~94 dirt
setblock ~36 ~113 ~91 dirt
setblock ~36 ~113 ~92 dirt
setblock ~36 ~113 ~93 dirt
setblock ~36 ~113 ~94 dirt
setblock ~36 ~113 ~96 dirt
setblock ~36 ~114 ~91 dirt
setblock ~36 ~114 ~92 dirt
setblock ~36 ~114 ~93 dirt
setblock ~36 ~114 ~94 dirt
setblock ~36 ~114 ~95 dirt
setblock ~36 ~114 ~96 dirt
setblock ~36 ~115 ~91 dirt
setblock ~36 ~115 ~92 dirt
setblock ~36 ~115 ~93 dirt
setblock ~36 ~115 ~94 dirt
setblock ~36 ~115 ~95 dirt
setblock ~36 ~115 ~96 dirt
setblock ~36 ~116 ~90 dirt
setblock ~36 ~116 ~91 dirt
setblock ~36 ~116 ~92 dirt
setblock ~36 ~116 ~93 dirt
setblock ~36 ~116 ~94 dirt
setblock ~36 ~116 ~95 dirt
setblock ~36 ~116 ~96 dirt
setblock ~36 ~116 ~97 dirt
setblock ~36 ~116 ~98 dirt
setblock ~36 ~116 ~99 dirt
setblock ~36 ~116 ~100 dirt
setblock ~36 ~116 ~122 dirt
setblock ~36 ~117 ~77 dirt
setblock ~36 ~117 ~90 dirt
setblock ~36 ~117 ~91 dirt
setblock ~36 ~117 ~92 dirt
setblock ~36 ~117 ~93 dirt
setblock ~36 ~117 ~94 dirt
setblock ~36 ~117 ~95 dirt
setblock ~36 ~117 ~96 dirt
setblock ~36 ~117 ~97 dirt
setblock ~36 ~117 ~98 dirt
setblock ~36 ~117 ~99 dirt
setblock ~36 ~117 ~100 dirt
setblock ~36 ~117 ~101 dirt
setblock ~36 ~117 ~102 dirt
setblock ~36 ~117 ~103 dirt
setblock ~36 ~117 ~104 dirt
setblock ~36 ~117 ~118 dirt
setblock ~36 ~117 ~122 dirt
setblock ~36 ~118 ~76 dirt
setblock ~36 ~118 ~77 dirt
setblock ~36 ~118 ~78 dirt
setblock ~36 ~118 ~87 dirt
setblock ~36 ~118 ~89 dirt
setblock ~36 ~118 ~90 dirt
setblock ~36 ~118 ~91 dirt
setblock ~36 ~118 ~92 dirt
setblock ~36 ~118 ~93 dirt
setblock ~36 ~118 ~94 dirt
setblock ~36 ~118 ~95 dirt
setblock ~36 ~118 ~96 dirt
setblock ~36 ~118 ~97 dirt
setblock ~36 ~118 ~98 dirt
setblock ~36 ~118 ~99 dirt
setblock ~36 ~118 ~100 dirt
setblock ~36 ~118 ~101 dirt
setblock ~36 ~118 ~102 dirt
setblock ~36 ~118 ~103 dirt
setblock ~36 ~118 ~104 dirt
setblock ~36 ~118 ~105 dirt
setblock ~36 ~118 ~117 dirt
setblock ~36 ~118 ~118 dirt
setblock ~36 ~118 ~120 dirt
setblock ~36 ~118 ~121 dirt
setblock ~36 ~118 ~122 dirt
setblock ~36 ~119 ~75 dirt
setblock ~36 ~119 ~76 dirt
setblock ~36 ~119 ~77 dirt
setblock ~36 ~119 ~78 dirt
setblock ~36 ~119 ~79 dirt
setblock ~36 ~119 ~80 dirt
setblock ~36 ~119 ~85 dirt
setblock ~36 ~119 ~87 dirt
setblock ~36 ~119 ~88 dirt
setblock ~36 ~119 ~89 dirt
setblock ~36 ~119 ~90 dirt
setblock ~36 ~119 ~91 dirt
setblock ~36 ~119 ~92 dirt
setblock ~36 ~119 ~93 dirt
setblock ~36 ~119 ~94 dirt
setblock ~36 ~119 ~95 dirt
setblock ~36 ~119 ~96 dirt
setblock ~36 ~119 ~97 dirt
setblock ~36 ~119 ~98 dirt
setblock ~36 ~119 ~99 dirt
setblock ~36 ~119 ~100 dirt
setblock ~36 ~119 ~101 dirt
setblock ~36 ~119 ~102 dirt
setblock ~36 ~119 ~103 dirt
setblock ~36 ~119 ~104 dirt
setblock ~36 ~119 ~105 dirt
setblock ~36 ~119 ~106 dirt
setblock ~36 ~119 ~117 dirt
setblock ~36 ~119 ~118 dirt
setblock ~36 ~119 ~119 dirt
setblock ~36 ~119 ~120 dirt
setblock ~36 ~119 ~121 dirt
setblock ~36 ~119 ~122 dirt
setblock ~36 ~119 ~123 dirt
setblock ~36 ~119 ~125 dirt
setblock ~36 ~120 ~74 dirt
setblock ~36 ~120 ~75 dirt
setblock ~36 ~120 ~76 dirt
setblock ~36 ~120 ~77 dirt
setblock ~36 ~120 ~78 dirt
setblock ~36 ~120 ~79 dirt
setblock ~36 ~120 ~80 dirt
setblock ~36 ~120 ~82 dirt
setblock ~36 ~120 ~85 dirt
setblock ~36 ~120 ~86 dirt
setblock ~36 ~120 ~87 dirt
setblock ~36 ~120 ~88 dirt
setblock ~36 ~120 ~89 dirt
setblock ~36 ~120 ~90 dirt
setblock ~36 ~120 ~91 dirt
setblock ~36 ~120 ~92 dirt
setblock ~36 ~120 ~93 dirt
setblock ~36 ~120 ~94 dirt
setblock ~36 ~120 ~95 dirt
setblock ~36 ~120 ~96 dirt
setblock ~36 ~120 ~97 dirt
setblock ~36 ~120 ~98 dirt
setblock ~36 ~120 ~99 dirt
setblock ~36 ~120 ~100 dirt
setblock ~36 ~120 ~101 dirt
setblock ~36 ~120 ~102 dirt
setblock ~36 ~120 ~103 dirt
setblock ~36 ~120 ~104 dirt
setblock ~36 ~120 ~105 dirt
setblock ~36 ~120 ~106 dirt
setblock ~36 ~120 ~116 dirt
setblock ~36 ~120 ~117 dirt
setblock ~36 ~120 ~118 dirt
setblock ~36 ~120 ~119 dirt
setblock ~36 ~120 ~120 dirt
setblock ~36 ~120 ~121 dirt
setblock ~36 ~120 ~122 dirt
setblock ~36 ~120 ~123 dirt
setblock ~36 ~120 ~124 dirt
setblock ~36 ~120 ~125 dirt
setblock ~36 ~121 ~73 dirt
setblock ~36 ~121 ~74 dirt
setblock ~36 ~121 ~75 dirt
setblock ~36 ~121 ~76 dirt
setblock ~36 ~121 ~77 dirt
setblock ~36 ~121 ~78 dirt
setblock ~36 ~121 ~79 dirt
setblock ~36 ~121 ~80 dirt
setblock ~36 ~121 ~81 dirt
setblock ~36 ~121 ~82 dirt
setblock ~36 ~121 ~83 dirt
setblock ~36 ~121 ~84 dirt
setblock ~36 ~121 ~85 dirt
setblock ~36 ~121 ~86 dirt
setblock ~36 ~121 ~87 dirt
setblock ~36 ~121 ~88 dirt
setblock ~36 ~121 ~89 dirt
setblock ~36 ~121 ~90 dirt
setblock ~36 ~121 ~91 dirt
setblock ~36 ~121 ~92 dirt
setblock ~36 ~121 ~93 dirt
setblock ~36 ~121 ~94 dirt
setblock ~36 ~121 ~95 dirt
setblock ~36 ~121 ~96 dirt
setblock ~36 ~121 ~97 dirt
setblock ~36 ~121 ~98 dirt
setblock ~36 ~121 ~99 dirt
setblock ~36 ~121 ~100 dirt
setblock ~36 ~121 ~101 dirt
setblock ~36 ~121 ~102 dirt
setblock ~36 ~121 ~103 dirt
setblock ~36 ~121 ~104 dirt
setblock ~36 ~121 ~105 dirt
setblock ~36 ~121 ~106 dirt
setblock ~36 ~121 ~107 dirt
setblock ~36 ~121 ~112 dirt
setblock ~36 ~121 ~114 dirt
setblock ~36 ~121 ~115 dirt
setblock ~36 ~121 ~116 dirt
setblock ~36 ~121 ~117 dirt
setblock ~36 ~121 ~118 dirt
setblock ~36 ~121 ~119 dirt
setblock ~36 ~121 ~120 dirt
setblock ~36 ~121 ~121 dirt
setblock ~36 ~121 ~122 dirt
setblock ~36 ~121 ~123 dirt
setblock ~36 ~121 ~124 dirt
setblock ~36 ~121 ~125 dirt
setblock ~36 ~121 ~126 dirt
setblock ~36 ~122 ~73 dirt
setblock ~36 ~122 ~74 dirt
setblock ~36 ~122 ~75 dirt
setblock ~36 ~122 ~76 dirt
setblock ~36 ~122 ~77 dirt
setblock ~36 ~122 ~78 dirt
setblock ~36 ~122 ~79 dirt
setblock ~36 ~122 ~80 dirt
setblock ~36 ~122 ~81 dirt
setblock ~36 ~122 ~82 dirt
setblock ~36 ~122 ~83 dirt
setblock ~36 ~122 ~84 dirt
setblock ~36 ~122 ~85 dirt
setblock ~36 ~122 ~86 dirt
setblock ~36 ~122 ~87 dirt
setblock ~36 ~122 ~88 dirt
setblock ~36 ~122 ~89 dirt
setblock ~36 ~122 ~90 dirt
setblock ~36 ~122 ~91 dirt
setblock ~36 ~122 ~92 dirt
setblock ~36 ~122 ~93 dirt
setblock ~36 ~122 ~94 dirt
setblock ~36 ~122 ~95 dirt
setblock ~36 ~122 ~96 dirt
setblock ~36 ~122 ~97 dirt
setblock ~36 ~122 ~98 dirt
setblock ~36 ~122 ~99 dirt
setblock ~36 ~122 ~100 dirt
setblock ~36 ~122 ~101 dirt
setblock ~36 ~122 ~102 dirt
setblock ~36 ~122 ~103 dirt
setblock ~36 ~122 ~104 dirt
setblock ~36 ~122 ~105 dirt
setblock ~36 ~122 ~106 dirt
setblock ~36 ~122 ~107 dirt
setblock ~36 ~122 ~112 dirt
setblock ~36 ~122 ~114 dirt
setblock ~36 ~122 ~115 dirt
setblock ~36 ~122 ~116 dirt
setblock ~36 ~122 ~117 dirt
setblock ~36 ~122 ~118 dirt
setblock ~36 ~122 ~119 dirt
setblock ~36 ~122 ~120 dirt
setblock ~36 ~122 ~121 dirt
setblock ~36 ~122 ~122 dirt
setblock ~36 ~122 ~123 dirt
setblock ~36 ~122 ~124 dirt
setblock ~36 ~122 ~125 dirt
setblock ~36 ~122 ~126 dirt
setblock ~36 ~123 ~73 dirt
setblock ~36 ~123 ~74 dirt
setblock ~36 ~123 ~75 dirt
setblock ~36 ~123 ~76 dirt
setblock ~36 ~123 ~77 dirt
setblock ~36 ~123 ~78 dirt
setblock ~36 ~123 ~79 dirt
setblock ~36 ~123 ~80 dirt
setblock ~36 ~123 ~81 dirt
setblock ~36 ~123 ~82 dirt
setblock ~36 ~123 ~83 dirt
setblock ~36 ~123 ~84 dirt
setblock ~36 ~123 ~85 dirt
setblock ~36 ~123 ~86 dirt
setblock ~36 ~123 ~87 dirt
setblock ~36 ~123 ~88 dirt
setblock ~36 ~123 ~89 dirt
setblock ~36 ~123 ~90 dirt
setblock ~36 ~123 ~91 dirt
setblock ~36 ~123 ~92 dirt
setblock ~36 ~123 ~93 dirt
setblock ~36 ~123 ~94 dirt
setblock ~36 ~123 ~95 dirt
setblock ~36 ~123 ~96 dirt
setblock ~36 ~123 ~97 dirt
setblock ~36 ~123 ~98 dirt
setblock ~36 ~123 ~99 dirt
setblock ~36 ~123 ~100 grass_block
setblock ~36 ~123 ~101 grass_block
setblock ~36 ~123 ~102 grass_block
setblock ~36 ~123 ~103 dirt
setblock ~36 ~123 ~104 dirt
setblock ~36 ~123 ~105 dirt
setblock ~36 ~123 ~106 dirt
setblock ~36 ~123 ~107 dirt
setblock ~36 ~123 ~112 dirt
setblock ~36 ~123 ~114 dirt
setblock ~36 ~123 ~115 dirt
setblock ~36 ~123 ~116 dirt
setblock ~36 ~123 ~117 dirt
setblock ~36 ~123 ~118 dirt
setblock ~36 ~123 ~119 dirt
setblock ~36 ~123 ~120 dirt
setblock ~36 ~123 ~121 dirt
setblock ~36 ~123 ~122 dirt
setblock ~36 ~123 ~123 dirt
setblock ~36 ~123 ~124 dirt
setblock ~36 ~123 ~125 dirt
setblock ~36 ~123 ~126 dirt
setblock ~36 ~124 ~73 grass_block
setblock ~36 ~124 ~74 grass_block
setblock ~36 ~124 ~75 dirt
setblock ~36 ~124 ~76 dirt
setblock ~36 ~124 ~77 dirt
setblock ~36 ~124 ~78 dirt
setblock ~36 ~124 ~79 dirt
setblock ~36 ~124 ~80 dirt
setblock ~36 ~124 ~81 dirt
setblock ~36 ~124 ~82 dirt
setblock ~36 ~124 ~83 dirt
setblock ~36 ~124 ~84 dirt
setblock ~36 ~124 ~85 dirt
setblock ~36 ~124 ~86 dirt
setblock ~36 ~124 ~87 dirt
setblock ~36 ~124 ~88 dirt
setblock ~36 ~124 ~89 dirt
setblock ~36 ~124 ~90 dirt
setblock ~36 ~124 ~91 dirt
setblock ~36 ~124 ~92 dirt
setblock ~36 ~124 ~93 dirt
setblock ~36 ~124 ~94 dirt
setblock ~36 ~124 ~95 dirt
setblock ~36 ~124 ~96 grass_block
setblock ~36 ~124 ~97 grass_block
setblock ~36 ~124 ~98 grass_block
setblock ~36 ~124 ~99 grass_block
setblock ~36 ~124 ~101 short_grass
setblock ~36 ~124 ~102 short_grass
setblock ~36 ~124 ~103 grass_block
setblock ~36 ~124 ~104 grass_block
setblock ~36 ~124 ~105 grass_block
setblock ~36 ~124 ~106 grass_block
setblock ~36 ~124 ~107 grass_block
setblock ~36 ~124 ~112 grass_block
setblock ~36 ~124 ~114 dirt
setblock ~36 ~124 ~115 dirt
setblock ~36 ~124 ~116 dirt
setblock ~36 ~124 ~117 dirt
setblock ~36 ~124 ~118 dirt
setblock ~36 ~124 ~119 dirt
setblock ~36 ~124 ~120 dirt
setblock ~36 ~124 ~121 dirt
setblock ~36 ~124 ~122 dirt
setblock ~36 ~124 ~123 dirt
setblock ~36 ~124 ~124 dirt
setblock ~36 ~124 ~125 dirt
setblock ~36 ~124 ~126 dirt
setblock ~36 ~125 ~74 short_grass
setblock ~36 ~125 ~75 grass_block
setblock ~36 ~125 ~76 grass_block
setblock ~36 ~125 ~77 grass_block
setblock ~36 ~125 ~78 grass_block
setblock ~36 ~125 ~79 grass_block
setblock ~36 ~125 ~80 grass_block
setblock ~36 ~125 ~81 grass_block
setblock ~36 ~125 ~82 grass_block
setblock ~36 ~125 ~83 grass_block
setblock ~36 ~125 ~84 grass_block
setblock ~36 ~125 ~85 dirt
setblock ~36 ~125 ~86 dirt
setblock ~36 ~125 ~87 dirt
setblock ~36 ~125 ~88 dirt
setblock ~36 ~125 ~89 dirt
setblock ~36 ~125 ~90 dirt
setblock ~36 ~125 ~91 dirt
setblock ~36 ~125 ~92 dirt
setblock ~36 ~125 ~93 grass_block
setblock ~36 ~125 ~94 grass_block
setblock ~36 ~125 ~95 grass_block
setblock ~36 ~125 ~96 short_grass
setblock ~36 ~125 ~105 poppy
setblock ~36 ~125 ~106 fern
setblock ~36 ~125 ~107 short_grass
setblock ~36 ~125 ~112 short_grass
setblock ~36 ~125 ~114 grass_block
setblock ~36 ~125 ~115 grass_block
setblock ~36 ~125 ~116 grass_block
setblock ~36 ~125 ~117 grass_block
setblock ~36 ~125 ~118 grass_block
setblock ~36 ~125 ~119 grass_block
setblock ~36 ~125 ~120 grass_block
setblock ~36 ~125 ~121 grass_block
setblock ~36 ~125 ~122 grass_block
setblock ~36 ~125 ~123 grass_block
setblock ~36 ~125 ~124 grass_block
setblock ~36 ~125 ~125 grass_block
setblock ~36 ~125 ~126 grass_block
setblock ~36 ~126 ~75 short_grass
setblock ~36 ~126 ~76 short_grass
setblock ~36 ~126 ~77 short_grass
setblock ~36 ~126 ~84 poppy
setblock ~36 ~126 ~85 grass_block
setblock ~36 ~126 ~86 grass_block
setblock ~36 ~126 ~87 grass_block
setblock ~36 ~126 ~88 grass_block
setblock ~36 ~126 ~89 grass_block
setblock ~36 ~126 ~90 grass_block
setblock ~36 ~126 ~91 grass_block
setblock ~36 ~126 ~92 grass_block
setblock ~36 ~126 ~94 short_grass
setblock ~36 ~126 ~114 short_grass
setblock ~36 ~126 ~118 fern
setblock ~36 ~126 ~125 short_grass
setblock ~36 ~127 ~91 poppy
setblock ~37 ~110 ~93 dirt
setblock ~37 ~111 ~92 dirt
setblock ~37 ~111 ~93 dirt
setblock ~37 ~111 ~94 dirt
setblock ~37 ~112 ~91 dirt
setblock ~37 ~112 ~92 dirt
setblock ~37 ~112 ~93 dirt
setblock ~37 ~112 ~94 dirt
setblock ~37 ~112 ~95 dirt
setblock ~37 ~112 ~96 dirt
setblock ~37 ~112 ~100 dirt
setblock ~37 ~113 ~77 dirt
setblock ~37 ~113 ~91 dirt
setblock ~37 ~113 ~92 dirt
setblock ~37 ~113 ~93 dirt
setblock ~37 ~113 ~94 dirt
setblock ~37 ~113 ~95 dirt
setblock ~37 ~113 ~96 dirt
setblock ~37 ~113 ~97 dirt
setblock ~37 ~113 ~99 dirt
setblock ~37 ~113 ~100 dirt
setblock ~37 ~114 ~77 dirt
setblock ~37 ~114 ~90 dirt
setblock ~37 ~114 ~91 dirt
setblock ~37 ~114 ~92 dirt
setblock ~37 ~114 ~93 dirt
setblock ~37 ~114 ~94 dirt
setblock ~37 ~114 ~95 dirt
setblock ~37 ~114 ~96 dirt
setblock ~37 ~114 ~97 dirt
setblock ~37 ~114 ~99 dirt
setblock ~37 ~114 ~100 dirt
setblock ~37 ~114 ~101 dirt
setblock ~37 ~114 ~102 dirt
setblock ~37 ~115 ~77 dirt
setblock ~37 ~115 ~78 dirt
setblock ~37 ~115 ~90 dirt
setblock ~37 ~115 ~91 dirt
setblock ~37 ~115 ~92 dirt
setblock ~37 ~115 ~93 dirt
setblock ~37 ~115 ~94 dirt
setblock ~37 ~115 ~95 dirt
setblock ~37 ~115 ~96 dirt
setblock ~37 ~115 ~97 dirt
setblock ~37 ~115 ~98 dirt
setblock ~37 ~115 ~99 dirt
setblock ~37 ~115 ~100 dirt
setblock ~37 ~115 ~101 dirt
setblock ~37 ~115 ~102 dirt
setblock ~37 ~115 ~103 dirt
setblock ~37 ~115 ~119 dirt
setblock ~37 ~115 ~120 dirt
setblock ~37 ~115 ~122 dirt
setblock ~37 ~116 ~75 dirt
setblock ~37 ~116 ~77 dirt
setblock ~37 ~116 ~78 dirt
setblock ~37 ~116 ~79 dirt
setblock ~37 ~116 ~87 dirt
setblock ~37 ~116 ~88 dirt
setblock ~37 ~116 ~89 dirt
setblock ~37 ~116 ~90 dirt
setblock ~37 ~116 ~91 dirt
setblock ~37 ~116 ~92 dirt
setblock ~37 ~116 ~93 dirt
setblock ~37 ~116 ~94 dirt
setblock ~37 ~116 ~95 dirt
setblock ~37 ~116 ~96 dirt
setblock ~37 ~116 ~97 dirt
setblock ~37 ~116 ~98 dirt
setblock ~37 ~116 ~99 dirt
setblock ~37 ~116 ~100 dirt
setblock ~37 ~116 ~101 dirt
setblock ~37 ~116 ~102 dirt
setblock ~37 ~116 ~103 dirt
setblock ~37 ~116 ~104 dirt
setblock ~37 ~116 ~118 dirt
setblock ~37 ~116 ~119 dirt
setblock ~37 ~116 ~120 dirt
setblock ~37 ~116 ~121 dirt
setblock ~37 ~116 ~122 dirt
setblock ~37 ~116 ~123 dirt
setblock ~37 ~117 ~74 dirt
setblock ~37 ~117 ~75 dirt
setblock ~37 ~117 ~76 dirt
setblock ~37 ~117 ~77 dirt
setblock ~37 ~117 ~78 dirt
setblock ~37 ~117 ~79 dirt
setblock ~37 ~117 ~80 dirt
setblock ~37 ~117 ~85 dirt
setblock ~37 ~117 ~87 dirt
setblock ~37 ~117 ~88 dirt
setblock ~37 ~117 ~89 dirt
setblock ~37 ~117 ~90 dirt
setblock ~37 ~117 ~91 dirt
setblock ~37 ~117 ~92 dirt
setblock ~37 ~117 ~93 dirt
setblock ~37 ~117 ~94 dirt
setblock ~37 ~117 ~95 dirt
setblock ~37 ~117 ~96 dirt
setblock ~37 ~117 ~97 dirt
setblock ~37 ~117 ~98 dirt
setblock ~37 ~117 ~99 dirt
setblock ~37 ~117 ~100 dirt
setblock ~37 ~117 ~101 dirt
setblock ~37 ~117 ~102 dirt
setblock ~37 ~117 ~103 dirt
setblock ~37 ~117 ~104 dirt
setblock ~37 ~117 ~105 dirt
setblock ~37 ~117 ~116 dirt
setblock ~37 ~117 ~117 dirt
setblock ~37 ~117 ~118 dirt
setblock ~37 ~117 ~119 dirt
setblock ~37 ~117 ~120 dirt
setblock ~37 ~117 ~121 dirt
setblock ~37 ~117 ~122 dirt
setblock ~37 ~117 ~123 dirt
setblock ~37 ~117 ~124 dirt
setblock ~37 ~117 ~125 dirt
setblock ~37 ~118 ~74 dirt
setblock ~37 ~118 ~75 dirt
setblock ~37 ~118 ~76 dirt
setblock ~37 ~118 ~77 dirt
setblock ~37 ~118 ~78 dirt
setblock ~37 ~118 ~79 dirt
setblock ~37 ~118 ~80 dirt
setblock ~37 ~118 ~81 dirt
setblock ~37 ~118 ~82 dirt
setblock ~37 ~118 ~83 dirt
setblock ~37 ~118 ~84 dirt
setblock ~37 ~118 ~85 dirt
setblock ~37 ~118 ~86 dirt
setblock ~37 ~118 ~87 dirt
setblock ~37 ~118 ~88 dirt
setblock ~37 ~118 ~89 dirt
setblock ~37 ~118 ~90 dirt
setblock ~37 ~118 ~91 dirt
setblock ~37 ~118 ~92 dirt
setblock ~37 ~118 ~93 dirt
setblock ~37 ~118 ~94 dirt
setblock ~37 ~118 ~95 dirt
setblock ~37 ~118 ~96 dirt
setblock ~37 ~118 ~97 dirt
setblock ~37 ~118 ~98 dirt
setblock ~37 ~118 ~99 dirt
setblock ~37 ~118 ~100 dirt
setblock ~37 ~118 ~101 dirt
setblock ~37 ~118 ~102 dirt
setblock ~37 ~118 ~103 dirt
setblock ~37 ~118 ~104 dirt
setblock ~37 ~118 ~105 dirt
setblock ~37 ~118 ~106 dirt
setblock ~37 ~118 ~116 dirt
setblock ~37 ~118 ~117 dirt
setblock ~37 ~118 ~118 dirt
setblock ~37 ~118 ~119 dirt
setblock ~37 ~118 ~120 dirt
setblock ~37 ~118 ~121 dirt
setblock ~37 ~118 ~122 dirt
setblock ~37 ~118 ~123 dirt
setblock ~37 ~118 ~124 dirt
setblock ~37 ~118 ~125 dirt
setblock ~37 ~119 ~73 dirt
setblock ~37 ~119 ~74 dirt
setblock ~37 ~119 ~75 dirt
setblock ~37 ~119 ~76 dirt
setblock ~37 ~119 ~77 dirt
setblock ~37 ~119 ~78 dirt
setblock ~37 ~119 ~79 dirt
setblock ~37 ~119 ~80 dirt
setblock ~37 ~119 ~81 dirt
setblock ~37 ~119 ~82 dirt
setblock ~37 ~119 ~83 dirt
setblock ~37 ~119 ~84 dirt
setblock ~37 ~119 ~85 dirt
setblock ~37 ~119 ~86 dirt
setblock ~37 ~119 ~87 dirt
setblock ~37 ~119 ~88 dirt
setblock ~37 ~119 ~89 dirt
setblock ~37 ~119 ~90 dirt
setblock ~37 ~119 ~91 dirt
setblock ~37 ~119 ~92 dirt
setblock ~37 ~119 ~93 dirt
setblock ~37 ~119 ~94 dirt
setblock ~37 ~119 ~95 dirt
setblock ~37 ~119 ~96 dirt
setblock ~37 ~119 ~97 dirt
setblock ~37 ~119 ~98 dirt
setblock ~37 ~119 ~99 dirt
setblock ~37 ~119 ~100 dirt
setblock ~37 ~119 ~101 dirt
setblock ~37 ~119 ~102 dirt
setblock ~37 ~119 ~103 dirt
setblock ~37 ~119 ~104 dirt
setblock ~37 ~119 ~105 dirt
setblock ~37 ~119 ~106 dirt
setblock ~37 ~119 ~107 dirt
setblock ~37 ~119 ~113 dirt
setblock ~37 ~119 ~116 dirt
setblock ~37 ~119 ~117 dirt
setblock ~37 ~119 ~118 dirt
setblock ~37 ~119 ~119 dirt
setblock ~37 ~119 ~120 dirt
setblock ~37 ~119 ~121 dirt
setblock ~37 ~119 ~122 dirt
setblock ~37 ~119 ~123 dirt
setblock ~37 ~119 ~124 dirt
setblock ~37 ~119 ~125 dirt
setblock ~37 ~119 ~126 dirt
setblock ~37 ~120 ~71 dirt
setblock ~37 ~120 ~73 dirt
setblock ~37 ~120 ~74 dirt
setblock ~37 ~120 ~75 dirt
setblock ~37 ~120 ~76 dirt
setblock ~37 ~120 ~77 dirt
setblock ~37 ~120 ~78 dirt
setblock ~37 ~120 ~79 dirt
setblock ~37 ~120 ~80 dirt
setblock ~37 ~120 ~81 dirt
setblock ~37 ~120 ~82 dirt
setblock ~37 ~120 ~83 dirt
setblock ~37 ~120 ~84 dirt
setblock ~37 ~120 ~85 dirt
setblock ~37 ~120 ~86 dirt
setblock ~37 ~120 ~87 dirt
setblock ~37 ~120 ~88 dirt
setblock ~37 ~120 ~89 dirt
setblock ~37 ~120 ~90 dirt
setblock ~37 ~120 ~91 dirt
setblock ~37 ~120 ~92 dirt
setblock ~37 ~120 ~93 dirt
setblock ~37 ~120 ~94 dirt
setblock ~37 ~120 ~95 dirt
setblock ~37 ~120 ~96 dirt
setblock ~37 ~120 ~97 dirt
setblock ~37 ~120 ~98 dirt
setblock ~37 ~120 ~99 dirt
setblock ~37 ~120 ~100 dirt
setblock ~37 ~120 ~101 dirt
setblock ~37 ~120 ~102 dirt
setblock ~37 ~120 ~103 dirt
setblock ~37 ~120 ~104 dirt
setblock ~37 ~120 ~105 dirt
setblock ~37 ~120 ~106 dirt
setblock ~37 ~120 ~107 dirt
setblock ~37 ~120 ~112 dirt
setblock ~37 ~120 ~113 dirt
setblock ~37 ~120 ~114 dirt
setblock ~37 ~120 ~115 dirt
setblock ~37 ~120 ~116 dirt
setblock ~37 ~120 ~117 dirt
setblock ~37 ~120 ~118 dirt
setblock ~37 ~120 ~119 dirt
setblock ~37 ~120 ~120 dirt
setblock ~37 ~120 ~121 dirt
setblock ~37 ~120 ~122 dirt
setblock ~37 ~120 ~123 dirt
setblock ~37 ~120 ~124 dirt
setblock ~37 ~120 ~125 dirt
setblock ~37 ~120 ~126 dirt
setblock ~37 ~120 ~127 dirt
setblock ~37 ~121 ~71 dirt
setblock ~37 ~121 ~72 dirt
setblock ~37 ~121 ~73 dirt
setblock ~37 ~121 ~74 dirt
setblock ~37 ~121 ~75 dirt
setblock ~37 ~121 ~76 dirt
setblock ~37 ~121 ~77 dirt
setblock ~37 ~121 ~78 dirt
setblock ~37 ~121 ~79 dirt
setblock ~37 ~121 ~80 dirt
setblock ~37 ~121 ~81 dirt
setblock ~37 ~121 ~82 dirt
setblock ~37 ~121 ~83 dirt
setblock ~37 ~121 ~84 dirt
setblock ~37 ~121 ~85 dirt
setblock ~37 ~121 ~86 dirt
setblock ~37 ~121 ~87 dirt
setblock ~37 ~121 ~88 dirt
setblock ~37 ~121 ~89 dirt
setblock ~37 ~121 ~90 dirt
setblock ~37 ~121 ~91 dirt
setblock ~37 ~121 ~92 dirt
setblock ~37 ~121 ~93 dirt
setblock ~37 ~121 ~94 dirt
setblock ~37 ~121 ~95 dirt
setblock ~37 ~121 ~96 dirt
setblock ~37 ~121 ~97 dirt
setblock ~37 ~121 ~98 dirt
setblock ~37 ~121 ~99 dirt
setblock ~37 ~121 ~100 dirt
setblock ~37 ~121 ~101 dirt
setblock ~37 ~121 ~102 dirt
setblock ~37 ~121 ~103 dirt
setblock ~37 ~121 ~104 dirt
setblock ~37 ~121 ~105 dirt
setblock ~37 ~121 ~106 dirt
setblock ~37 ~121 ~107 dirt
setblock ~37 ~121 ~108 dirt
setblock ~37 ~121 ~111 dirt
setblock ~37 ~121 ~112 dirt
setblock ~37 ~121 ~113 dirt
setblock ~37 ~121 ~114 dirt
setblock ~37 ~121 ~115 dirt
setblock ~37 ~121 ~116 dirt
setblock ~37 ~121 ~117 dirt
setblock ~37 ~121 ~118 dirt
setblock ~37 ~121 ~119 dirt
setblock ~37 ~121 ~120 dirt
setblock ~37 ~121 ~121 dirt
setblock ~37 ~121 ~122 dirt
setblock ~37 ~121 ~123 dirt
setblock ~37 ~121 ~124 dirt
setblock ~37 ~121 ~125 dirt
setblock ~37 ~121 ~126 dirt
setblock ~37 ~121 ~127 dirt
setblock ~37 ~122 ~71 dirt
setblock ~37 ~122 ~72 dirt
setblock ~37 ~122 ~73 dirt
setblock ~37 ~122 ~74 dirt
setblock ~37 ~122 ~75 dirt
setblock ~37 ~122 ~76 dirt
setblock ~37 ~122 ~77 dirt
setblock ~37 ~122 ~78 dirt
setblock ~37 ~122 ~79 dirt
setblock ~37 ~122 ~80 dirt
setblock ~37 ~122 ~81 dirt
setblock ~37 ~122 ~82 dirt
setblock ~37 ~122 ~83 dirt
setblock ~37 ~122 ~84 dirt
setblock ~37 ~122 ~85 dirt
setblock ~37 ~122 ~86 dirt
setblock ~37 ~122 ~87 dirt
setblock ~37 ~122 ~88 dirt
setblock ~37 ~122 ~89 dirt
setblock ~37 ~122 ~90 dirt
setblock ~37 ~122 ~91 dirt
setblock ~37 ~122 ~92 dirt
setblock ~37 ~122 ~93 dirt
setblock ~37 ~122 ~94 dirt
setblock ~37 ~122 ~95 dirt
setblock ~37 ~122 ~96 dirt
setblock ~37 ~122 ~97 dirt
setblock ~37 ~122 ~98 dirt
setblock ~37 ~122 ~99 dirt
setblock ~37 ~122 ~100 dirt
setblock ~37 ~122 ~101 dirt
setblock ~37 ~122 ~102 dirt
setblock ~37 ~122 ~103 dirt
setblock ~37 ~122 ~104 dirt
setblock ~37 ~122 ~105 dirt
setblock ~37 ~122 ~106 dirt
setblock ~37 ~122 ~107 dirt
setblock ~37 ~122 ~108 dirt
setblock ~37 ~122 ~111 dirt
setblock ~37 ~122 ~112 dirt
setblock ~37 ~122 ~113 dirt
setblock ~37 ~122 ~114 dirt
setblock ~37 ~122 ~115 dirt
setblock ~37 ~122 ~116 dirt
setblock ~37 ~122 ~117 dirt
setblock ~37 ~122 ~118 dirt
setblock ~37 ~122 ~119 dirt
setblock ~37 ~122 ~120 dirt
setblock ~37 ~122 ~121 dirt
setblock ~37 ~122 ~122 dirt
setblock ~37 ~122 ~123 dirt
setblock ~37 ~122 ~124 dirt
setblock ~37 ~122 ~125 dirt
setblock ~37 ~122 ~126 dirt
setblock ~37 ~122 ~127 dirt
setblock ~37 ~123 ~71 dirt
setblock ~37 ~123 ~72 dirt
setblock ~37 ~123 ~73 dirt
setblock ~37 ~123 ~74 dirt
setblock ~37 ~123 ~75 dirt
setblock ~37 ~123 ~76 dirt
setblock ~37 ~123 ~77 dirt
setblock ~37 ~123 ~78 dirt
setblock ~37 ~123 ~79 dirt
setblock ~37 ~123 ~80 dirt
setblock ~37 ~123 ~81 dirt
setblock ~37 ~123 ~82 dirt
setblock ~37 ~123 ~83 dirt
setblock ~37 ~123 ~84 dirt
setblock ~37 ~123 ~85 dirt
setblock ~37 ~123 ~86 dirt
setblock ~37 ~123 ~87 dirt
setblock ~37 ~123 ~88 dirt
setblock ~37 ~123 ~89 dirt
setblock ~37 ~123 ~90 dirt
setblock ~37 ~123 ~91 dirt
setblock ~37 ~123 ~92 dirt
setblock ~37 ~123 ~93 dirt
setblock ~37 ~123 ~94 dirt
setblock ~37 ~123 ~95 dirt
setblock ~37 ~123 ~96 dirt
setblock ~37 ~123 ~97 dirt
setblock ~37 ~123 ~98 dirt
setblock ~37 ~123 ~99 dirt
setblock ~37 ~123 ~100 grass_block
setblock ~37 ~123 ~101 grass_block
setblock ~37 ~123 ~102 dirt
setblock ~37 ~123 ~103 dirt
setblock ~37 ~123 ~104 dirt
setblock ~37 ~123 ~105 dirt
setblock ~37 ~123 ~106 dirt
setblock ~37 ~123 ~107 dirt
setblock ~37 ~123 ~108 dirt
setblock ~37 ~123 ~111 dirt
setblock ~37 ~123 ~112 dirt
setblock ~37 ~123 ~113 dirt
setblock ~37 ~123 ~114 dirt
setblock ~37 ~123 ~115 dirt
setblock ~37 ~123 ~116 dirt
setblock ~37 ~123 ~117 dirt
setblock ~37 ~123 ~118 dirt
setblock ~37 ~123 ~119 dirt
setblock ~37 ~123 ~120 dirt
setblock ~37 ~123 ~121 dirt
setblock ~37 ~123 ~122 dirt
setblock ~37 ~123 ~123 dirt
setblock ~37 ~123 ~124 dirt
setblock ~37 ~123 ~125 dirt
setblock ~37 ~123 ~126 dirt
setblock ~37 ~123 ~127 dirt
setblock ~37 ~124 ~71 grass_block
setblock ~37 ~124 ~72 grass_block
setblock ~37 ~124 ~73 grass_block
setblock ~37 ~124 ~74 dirt
setblock ~37 ~124 ~75 dirt
setblock ~37 ~124 ~76 dirt
setblock ~37 ~124 ~77 dirt
setblock ~37 ~124 ~78 dirt
setblock ~37 ~124 ~79 dirt
setblock ~37 ~124 ~80 dirt
setblock ~37 ~124 ~81 dirt
setblock ~37 ~124 ~82 dirt
setblock ~37 ~124 ~83 dirt
setblock ~37 ~124 ~84 dirt
setblock ~37 ~124 ~85 dirt
setblock ~37 ~124 ~86 dirt
setblock ~37 ~124 ~87 dirt
setblock ~37 ~124 ~88 dirt
setblock ~37 ~124 ~89 dirt
setblock ~37 ~124 ~90 dirt
setblock ~37 ~124 ~91 dirt
setblock ~37 ~124 ~92 dirt
setblock ~37 ~124 ~93 dirt
setblock ~37 ~124 ~94 dirt
setblock ~37 ~124 ~95 grass_block
setblock ~37 ~124 ~96 grass_block
setblock ~37 ~124 ~97 grass_block
setblock ~37 ~124 ~98 grass_block
setblock ~37 ~124 ~99 grass_block
setblock ~37 ~124 ~101 short_grass
setblock ~37 ~124 ~102 grass_block
setblock ~37 ~124 ~103 grass_block
setblock ~37 ~124 ~104 grass_block
setblock ~37 ~124 ~105 grass_block
setblock ~37 ~124 ~106 grass_block
setblock ~37 ~124 ~107 grass_block
setblock ~37 ~124 ~108 grass_block
setblock ~37 ~124 ~111 grass_block
setblock ~37 ~124 ~112 grass_block
setblock ~37 ~124 ~113 dirt
setblock ~37 ~124 ~114 dirt
setblock ~37 ~124 ~115 dirt
setblock ~37 ~124 ~116 dirt
setblock ~37 ~124 ~117 dirt
setblock ~37 ~124 ~118 dirt
setblock ~37 ~124 ~119 dirt
setblock ~37 ~124 ~120 dirt
setblock ~37 ~124 ~121 dirt
setblock ~37 ~124 ~122 dirt
setblock ~37 ~124 ~123 dirt
setblock ~37 ~124 ~124 dirt
setblock ~37 ~124 ~125 dirt
setblock ~37 ~124 ~126 dirt
setblock ~37 ~124 ~127 dirt
setblock ~37 ~125 ~74 grass_block
setblock ~37 ~125 ~75 grass_block
setblock ~37 ~125 ~76 grass_block
setblock ~37 ~125 ~77 grass_block
setblock ~37 ~125 ~78 grass_block
setblock ~37 ~125 ~79 grass_block
setblock ~37 ~125 ~80 grass_block
setblock ~37 ~125 ~81 grass_block
setblock ~37 ~125 ~82 grass_block
setblock ~37 ~125 ~83 grass_block
setblock ~37 ~125 ~84 grass_block
setblock ~37 ~125 ~85 grass_block
setblock ~37 ~125 ~86 grass_block
setblock ~37 ~125 ~87 grass_block
setblock ~37 ~125 ~88 grass_block
setblock ~37 ~125 ~89 grass_block
setblock ~37 ~125 ~90 grass_block
setblock ~37 ~125 ~91 grass_block
setblock ~37 ~125 ~92 grass_block
setblock ~37 ~125 ~93 grass_block
setblock ~37 ~125 ~94 grass_block
setblock ~37 ~125 ~99 short_grass
setblock ~37 ~125 ~103 fern
setblock ~37 ~125 ~107 short_grass
setblock ~37 ~125 ~108 poppy
setblock ~37 ~125 ~111 short_grass
setblock ~37 ~125 ~113 grass_block
setblock ~37 ~125 ~114 grass_block
setblock ~37 ~125 ~115 grass_block
setblock ~37 ~125 ~116 grass_block
setblock ~37 ~125 ~117 grass_block
setblock ~37 ~125 ~118 dirt
setblock ~37 ~125 ~119 dirt
setblock ~37 ~125 ~120 dirt
setblock ~37 ~125 ~121 dirt
setblock ~37 ~125 ~122 dirt
setblock ~37 ~125 ~123 dirt
setblock ~37 ~125 ~124 dirt
setblock ~37 ~125 ~125 dirt
setblock ~37 ~125 ~126 grass_block
setblock ~37 ~125 ~127 grass_block
setblock ~37 ~126 ~74 fern
setblock ~37 ~126 ~75 short_grass
setblock ~37 ~126 ~77 fern
setblock ~37 ~126 ~82 fern
setblock ~37 ~126 ~86 short_grass
setblock ~37 ~126 ~90 poppy
setblock ~37 ~126 ~93 short_grass
setblock ~37 ~126 ~115 poppy
setblock ~37 ~126 ~118 grass_block
setblock ~37 ~126 ~119 grass_block
setblock ~37 ~126 ~120 grass_block
setblock ~37 ~126 ~121 grass_block
setblock ~37 ~126 ~122 grass_block
setblock ~37 ~126 ~123 grass_block
setblock ~37 ~126 ~124 grass_block
setblock ~37 ~126 ~125 grass_block
setblock ~37 ~126 ~126 short_grass
setblock ~37 ~127 ~118 short_grass
setblock ~37 ~127 ~119 short_grass
setblock ~37 ~127 ~121 short_grass
setblock ~37 ~127 ~124 short_grass
setblock ~38 ~108 ~94 dirt
setblock ~38 ~109 ~93 dirt
setblock ~38 ~109 ~94 dirt
setblock ~38 ~110 ~92 dirt
setblock ~38 ~110 ~93 dirt
setblock ~38 ~110 ~94 dirt
setblock ~38 ~110 ~95 dirt
setblock ~38 ~110 ~99 dirt
setblock ~38 ~110 ~100 dirt
setblock ~38 ~111 ~77 dirt
setblock ~38 ~111 ~91 dirt
setblock ~38 ~111 ~92 dirt
setblock ~38 ~111 ~93 dirt
setblock ~38 ~111 ~94 dirt
setblock ~38 ~111 ~95 dirt
setblock ~38 ~111 ~96 dirt
setblock ~38 ~111 ~97 dirt
setblock ~38 ~111 ~99 dirt
setblock ~38 ~111 ~100 dirt
setblock ~38 ~112 ~77 dirt
setblock ~38 ~112 ~78 dirt
setblock ~38 ~112 ~90 dirt
setblock ~38 ~112 ~91 dirt
setblock ~38 ~112 ~92 dirt
setblock ~38 ~112 ~93 dirt
setblock ~38 ~112 ~94 dirt
setblock ~38 ~112 ~95 dirt
setblock ~38 ~112 ~96 dirt
setblock ~38 ~112 ~97 dirt
setblock ~38 ~112 ~98 dirt
setblock ~38 ~112 ~99 dirt
setblock ~38 ~112 ~100 dirt
setblock ~38 ~112 ~101 dirt
setblock ~38 ~112 ~121 dirt
setblock ~38 ~112 ~122 dirt
setblock ~38 ~113 ~76 dirt
setblock ~38 ~113 ~77 dirt
setblock ~38 ~113 ~78 dirt
setblock ~38 ~113 ~79 dirt
setblock ~38 ~113 ~89 dirt
setblock ~38 ~113 ~90 dirt
setblock ~38 ~113 ~91 dirt
setblock ~38 ~113 ~92 dirt
setblock ~38 ~113 ~93 dirt
setblock ~38 ~113 ~94 dirt
setblock ~38 ~113 ~95 dirt
setblock ~38 ~113 ~96 dirt
setblock ~38 ~113 ~97 dirt
setblock ~38 ~113 ~98 dirt
setblock ~38 ~113 ~99 dirt
setblock ~38 ~113 ~100 dirt
setblock ~38 ~113 ~101 dirt
setblock ~38 ~113 ~102 dirt
setblock ~38 ~113 ~121 dirt
setblock ~38 ~113 ~122 dirt
setblock ~38 ~113 ~123 dirt
setblock ~38 ~114 ~76 dirt
setblock ~38 ~114 ~77 dirt
setblock ~38 ~114 ~78 dirt
setblock ~38 ~114 ~79 dirt
setblock ~38 ~114 ~87 dirt
setblock ~38 ~114 ~88 dirt
setblock ~38 ~114 ~89 dirt
setblock ~38 ~114 ~90 dirt
setblock ~38 ~114 ~91 dirt
setblock ~38 ~114 ~92 dirt
setblock ~38 ~114 ~93 dirt
setblock ~38 ~114 ~94 dirt
setblock ~38 ~114 ~95 dirt
setblock ~38 ~114 ~96 dirt
setblock ~38 ~114 ~97 dirt
setblock ~38 ~114 ~98 dirt
setblock ~38 ~114 ~99 dirt
setblock ~38 ~114 ~100 dirt
setblock ~38 ~114 ~101 dirt
setblock ~38 ~114 ~102 dirt
setblock ~38 ~114 ~103 dirt
setblock ~38 ~114 ~118 dirt
setblock ~38 ~114 ~119 dirt
setblock ~38 ~114 ~120 dirt
setblock ~38 ~114 ~121 dirt
setblock ~38 ~114 ~122 dirt
setblock ~38 ~114 ~123 dirt
setblock ~38 ~115 ~75 dirt
setblock ~38 ~115 ~76 dirt
setblock ~38 ~115 ~77 dirt
setblock ~38 ~115 ~78 dirt
setblock ~38 ~115 ~79 dirt
setblock ~38 ~115 ~80 dirt
setblock ~38 ~115 ~86 dirt
setblock ~38 ~115 ~87 dirt
setblock ~38 ~115 ~88 dirt
setblock ~38 ~115 ~89 dirt
setblock ~38 ~115 ~90 dirt
setblock ~38 ~115 ~91 dirt
setblock ~38 ~115 ~92 dirt
setblock ~38 ~115 ~93 dirt
setblock ~38 ~115 ~94 dirt
setblock ~38 ~115 ~95 dirt
setblock ~38 ~115 ~96 dirt
setblock ~38 ~115 ~97 dirt
setblock ~38 ~115 ~98 dirt
setblock ~38 ~115 ~99 dirt
setblock ~38 ~115 ~100 dirt
setblock ~38 ~115 ~101 dirt
setblock ~38 ~115 ~102 dirt
setblock ~38 ~115 ~103 dirt
setblock ~38 ~115 ~104 dirt
setblock ~38 ~115 ~117 dirt
setblock ~38 ~115 ~118 dirt
setblock ~38 ~115 ~119 dirt
setblock ~38 ~115 ~120 dirt
setblock ~38 ~115 ~121 dirt
setblock ~38 ~115 ~122 dirt
setblock ~38 ~115 ~123 dirt
setblock ~38 ~116 ~74 dirt
setblock ~38 ~116 ~75 dirt
setblock ~38 ~116 ~76 dirt
setblock ~38 ~116 ~77 dirt
setblock ~38 ~116 ~78 dirt
setblock ~38 ~116 ~79 dirt
setblock ~38 ~116 ~80 dirt
setblock ~38 ~116 ~81 dirt
setblock ~38 ~116 ~83 dirt
setblock ~38 ~116 ~85 dirt
setblock ~38 ~116 ~86 dirt
setblock ~38 ~116 ~87 dirt
setblock ~38 ~116 ~88 dirt
setblock ~38 ~116 ~89 dirt
setblock ~38 ~116 ~90 dirt
setblock ~38 ~116 ~91 dirt
setblock ~38 ~116 ~92 dirt
setblock ~38 ~116 ~93 dirt
setblock ~38 ~116 ~94 dirt
setblock ~38 ~116 ~95 dirt
setblock ~38 ~116 ~96 dirt
setblock ~38 ~116 ~97 dirt
setblock ~38 ~116 ~98 dirt
setblock ~38 ~116 ~99 dirt
setblock ~38 ~116 ~100 dirt
setblock ~38 ~116 ~101 dirt
setblock ~38 ~116 ~102 dirt
setblock ~38 ~116 ~103 dirt
setblock ~38 ~116 ~104 dirt
setblock ~38 ~116 ~105 dirt
setblock ~38 ~116 ~116 dirt
setblock ~38 ~116 ~117 dirt
setblock ~38 ~116 ~118 dirt
setblock ~38 ~116 ~119 dirt
setblock ~38 ~116 ~120 dirt
setblock ~38 ~116 ~121 dirt
setblock ~38 ~116 ~122 dirt
setblock ~38 ~116 ~123 dirt
setblock ~38 ~116 ~124 dirt
setblock ~38 ~116 ~125 dirt
setblock ~38 ~116 ~126 dirt
setblock ~38 ~117 ~73 dirt
setblock ~38 ~117 ~74 dirt
setblock ~38 ~117 ~75 dirt
setblock ~38 ~117 ~76 dirt
setblock ~38 ~117 ~77 dirt
setblock ~38 ~117 ~78 dirt
setblock ~38 ~117 ~79 dirt
setblock ~38 ~117 ~80 dirt
setblock ~38 ~117 ~81 dirt
setblock ~38 ~117 ~82 dirt
setblock ~38 ~117 ~83 dirt
setblock ~38 ~117 ~84 dirt
setblock ~38 ~117 ~85 dirt
setblock ~38 ~117 ~86 dirt
setblock ~38 ~117 ~87 dirt
setblock ~38 ~117 ~88 dirt
setblock ~38 ~117 ~89 dirt
setblock ~38 ~117 ~90 dirt
setblock ~38 ~117 ~91 dirt
setblock ~38 ~117 ~92 dirt
setblock ~38 ~117 ~93 dirt
setblock ~38 ~117 ~94 dirt
setblock ~38 ~117 ~95 dirt
setblock ~38 ~117 ~96 dirt
setblock ~38 ~117 ~97 dirt
setblock ~38 ~117 ~98 dirt
setblock ~38 ~117 ~99 dirt
setblock ~38 ~117 ~100 dirt
setblock ~38 ~117 ~101 dirt
setblock ~38 ~117 ~102 dirt
setblock ~38 ~117 ~103 dirt
setblock ~38 ~117 ~104 dirt
setblock ~38 ~117 ~105 dirt
setblock ~38 ~117 ~106 dirt
setblock ~38 ~117 ~115 dirt
setblock ~38 ~117 ~116 dirt
setblock ~38 ~117 ~117 dirt
setblock ~38 ~117 ~118 dirt
setblock ~38 ~117 ~119 dirt
setblock ~38 ~117 ~120 dirt
setblock ~38 ~117 ~121 dirt
setblock ~38 ~117 ~122 dirt
setblock ~38 ~117 ~123 dirt
setblock ~38 ~117 ~124 dirt
setblock ~38 ~117 ~125 dirt
setblock ~38 ~117 ~126 dirt
setblock ~38 ~118 ~71 dirt
setblock ~38 ~118 ~72 dirt
setblock ~38 ~118 ~73 dirt
setblock ~38 ~118 ~74 dirt
setblock ~38 ~118 ~75 dirt
setblock ~38 ~118 ~76 dirt
setblock ~38 ~118 ~77 dirt
setblock ~38 ~118 ~78 dirt
setblock ~38 ~118 ~79 dirt
setblock ~38 ~118 ~80 dirt
setblock ~38 ~118 ~81 dirt
setblock ~38 ~118 ~82 dirt
setblock ~38 ~118 ~83 dirt
setblock ~38 ~118 ~84 dirt
setblock ~38 ~118 ~85 dirt
setblock ~38 ~118 ~86 dirt
setblock ~38 ~118 ~87 dirt
setblock ~38 ~118 ~88 dirt
setblock ~38 ~118 ~89 dirt
setblock ~38 ~118 ~90 dirt
setblock ~38 ~118 ~91 dirt
setblock ~38 ~118 ~92 dirt
setblock ~38 ~118 ~93 dirt
setblock ~38 ~118 ~94 dirt
setblock ~38 ~118 ~95 dirt
setblock ~38 ~118 ~96 dirt
setblock ~38 ~118 ~97 dirt
setblock ~38 ~118 ~98 dirt
setblock ~38 ~118 ~99 dirt
setblock ~38 ~118 ~100 dirt
setblock ~38 ~118 ~101 dirt
setblock ~38 ~118 ~102 dirt
setblock ~38 ~118 ~103 dirt
setblock ~38 ~118 ~104 dirt
setblock ~38 ~118 ~105 dirt
setblock ~38 ~118 ~106 dirt
setblock ~38 ~118 ~107 dirt
setblock ~38 ~118 ~113 dirt
setblock ~38 ~118 ~115 dirt
setblock ~38 ~118 ~116 dirt
setblock ~38 ~118 ~117 dirt
setblock ~38 ~118 ~118 dirt
setblock ~38 ~118 ~119 dirt
setblock ~38 ~118 ~120 dirt
setblock ~38 ~118 ~121 dirt
setblock ~38 ~118 ~122 dirt
setblock ~38 ~118 ~123 dirt
setblock ~38 ~118 ~124 dirt
setblock ~38 ~118 ~125 dirt
setblock ~38 ~118 ~126 dirt
setblock ~38 ~119 ~71 dirt
setblock ~38 ~119 ~72 dirt
setblock ~38 ~119 ~73 dirt
setblock ~38 ~119 ~74 dirt
setblock ~38 ~119 ~75 dirt
setblock ~38 ~119 ~76 dirt
setblock ~38 ~119 ~77 dirt
setblock ~38 ~119 ~78 dirt
setblock ~38 ~119 ~79 dirt
setblock ~38 ~119 ~80 dirt
setblock ~38 ~119 ~81 dirt
setblock ~38 ~119 ~82 dirt
setblock ~38 ~119 ~83 dirt
setblock ~38 ~119 ~84 dirt
setblock ~38 ~119 ~85 dirt
setblock ~38 ~119 ~86 dirt
setblock ~38 ~119 ~87 dirt
setblock ~38 ~119 ~88 dirt
setblock ~38 ~119 ~89 dirt
setblock ~38 ~119 ~90 dirt
setblock ~38 ~119 ~91 dirt
setblock ~38 ~119 ~92 dirt
setblock ~38 ~119 ~93 dirt
setblock ~38 ~119 ~94 dirt
setblock ~38 ~119 ~95 dirt
setblock ~38 ~119 ~96 dirt
setblock ~38 ~119 ~97 dirt
setblock ~38 ~119 ~98 dirt
setblock ~38 ~119 ~99 dirt
setblock ~38 ~119 ~100 dirt
setblock ~38 ~119 ~101 dirt
setblock ~38 ~119 ~102 dirt
setblock ~38 ~119 ~103 dirt
setblock ~38 ~119 ~104 dirt
setblock ~38 ~119 ~105 dirt
setblock ~38 ~119 ~106 dirt
setblock ~38 ~119 ~107 dirt
setblock ~38 ~119 ~112 dirt
setblock ~38 ~119 ~113 dirt
setblock ~38 ~119 ~114 dirt
setblock ~38 ~119 ~115 dirt
setblock ~38 ~119 ~116 dirt
setblock ~38 ~119 ~117 dirt
setblock ~38 ~119 ~118 dirt
setblock ~38 ~119 ~119 dirt
setblock ~38 ~119 ~120 dirt
setblock ~38 ~119 ~121 dirt
setblock ~38 ~119 ~122 dirt
setblock ~38 ~119 ~123 dirt
setblock ~38 ~119 ~124 dirt
setblock ~38 ~119 ~125 dirt
setblock ~38 ~119 ~126 dirt
setblock ~38 ~119 ~127 dirt
setblock ~38 ~120 ~70 dirt
setblock ~38 ~120 ~71 dirt
setblock ~38 ~120 ~72 dirt
setblock ~38 ~120 ~73 dirt
setblock ~38 ~120 ~74 dirt
setblock ~38 ~120 ~75 dirt
setblock ~38 ~120 ~76 dirt
setblock ~38 ~120 ~77 dirt
setblock ~38 ~120 ~78 dirt
setblock ~38 ~120 ~79 dirt
setblock ~38 ~120 ~80 dirt
setblock ~38 ~120 ~81 dirt
setblock ~38 ~120 ~82 dirt
setblock ~38 ~120 ~83 dirt
setblock ~38 ~120 ~84 dirt
setblock ~38 ~120 ~85 dirt
setblock ~38 ~120 ~86 dirt
setblock ~38 ~120 ~87 dirt
setblock ~38 ~120 ~88 dirt
setblock ~38 ~120 ~89 dirt
setblock ~38 ~120 ~90 dirt
setblock ~38 ~120 ~91 dirt
setblock ~38 ~120 ~92 dirt
setblock ~38 ~120 ~93 dirt
setblock ~38 ~120 ~94 dirt
setblock ~38 ~120 ~95 dirt
setblock ~38 ~120 ~96 dirt
setblock ~38 ~120 ~97 dirt
setblock ~38 ~120 ~98 dirt
setblock ~38 ~120 ~99 dirt
setblock ~38 ~120 ~100 dirt
setblock ~38 ~120 ~101 dirt
setblock ~38 ~120 ~102 dirt
setblock ~38 ~120 ~103 dirt
setblock ~38 ~120 ~104 dirt
setblock ~38 ~120 ~105 dirt
setblock ~38 ~120 ~106 dirt
setblock ~38 ~120 ~107 dirt
setblock ~38 ~120 ~111 dirt
setblock ~38 ~120 ~112 dirt
setblock ~38 ~120 ~113 dirt
setblock ~38 ~120 ~114 dirt
setblock ~38 ~120 ~115 dirt
setblock ~38 ~120 ~116 dirt
setblock ~38 ~120 ~117 dirt
setblock ~38 ~120 ~118 dirt
setblock ~38 ~120 ~119 dirt
setblock ~38 ~120 ~120 dirt
setblock ~38 ~120 ~121 dirt
setblock ~38 ~120 ~122 dirt
setblock ~38 ~120 ~123 dirt
setblock ~38 ~120 ~124 dirt
setblock ~38 ~120 ~125 dirt
setblock ~38 ~120 ~126 dirt
setblock ~38 ~120 ~127 dirt
setblock ~38 ~120 ~128 dirt
setblock ~38 ~121 ~69 dirt
setblock ~38 ~121 ~70 dirt
setblock ~38 ~121 ~71 dirt
setblock ~38 ~121 ~72 dirt
setblock ~38 ~121 ~73 dirt
setblock ~38 ~121 ~74 dirt
setblock ~38 ~121 ~75 dirt
setblock ~38 ~121 ~76 dirt
setblock ~38 ~121 ~77 dirt
setblock ~38 ~121 ~78 dirt
setblock ~38 ~121 ~79 dirt
setblock ~38 ~121 ~80 dirt
