setblock ~0 ~1 ~0 gold_block
setblock ~25 ~121 ~97 dirt
setblock ~25 ~121 ~102 dirt
setblock ~25 ~121 ~114 dirt
setblock ~25 ~122 ~97 dirt
setblock ~25 ~122 ~102 dirt
setblock ~25 ~122 ~114 dirt
setblock ~25 ~123 ~97 dirt
setblock ~25 ~123 ~102 dirt
setblock ~25 ~123 ~114 dirt
setblock ~25 ~124 ~97 dirt
setblock ~25 ~124 ~102 dirt
setblock ~25 ~124 ~114 grass_block
setblock ~25 ~125 ~97 grass_block
setblock ~25 ~125 ~102 grass_block
setblock ~26 ~119 ~113 dirt
setblock ~26 ~119 ~115 dirt
setblock ~26 ~120 ~97 dirt
setblock ~26 ~120 ~102 dirt
setblock ~26 ~120 ~112 dirt
setblock ~26 ~120 ~113 dirt
setblock ~26 ~120 ~114 dirt
setblock ~26 ~120 ~115 dirt
setblock ~26 ~120 ~116 dirt
setblock ~26 ~121 ~96 dirt
setblock ~26 ~121 ~97 dirt
setblock ~26 ~121 ~98 dirt
setblock ~26 ~121 ~100 dirt
setblock ~26 ~121 ~101 dirt
setblock ~26 ~121 ~102 dirt
setblock ~26 ~121 ~103 dirt
setblock ~26 ~121 ~112 dirt
setblock ~26 ~121 ~113 dirt
setblock ~26 ~121 ~114 dirt
setblock ~26 ~121 ~115 dirt
setblock ~26 ~121 ~116 dirt
setblock ~26 ~121 ~117 dirt
setblock ~26 ~122 ~96 dirt
setblock ~26 ~122 ~97 dirt
setblock ~26 ~122 ~98 dirt
setblock ~26 ~122 ~100 dirt
setblock ~26 ~122 ~101 dirt
setblock ~26 ~122 ~102 dirt
setblock ~26 ~122 ~103 dirt
setblock ~26 ~122 ~112 dirt
setblock ~26 ~122 ~113 dirt
setblock ~26 ~122 ~114 dirt
setblock ~26 ~122 ~115 dirt
setblock ~26 ~122 ~116 dirt
setblock ~26 ~122 ~117 dirt
setblock ~26 ~123 ~96 dirt
setblock ~26 ~123 ~97 dirt
setblock ~26 ~123 ~98 dirt
setblock ~26 ~123 ~100 dirt
setblock ~26 ~123 ~101 dirt
setblock ~26 ~123 ~102 dirt
setblock ~26 ~123 ~103 dirt
setblock ~26 ~123 ~112 dirt
setblock ~26 ~123 ~113 dirt
setblock ~26 ~123 ~114 dirt
setblock ~26 ~123 ~115 dirt
setblock ~26 ~123 ~116 dirt
setblock ~26 ~123 ~117 dirt
setblock ~26 ~124 ~96 dirt
setblock ~26 ~124 ~97 dirt
setblock ~26 ~124 ~98 dirt
setblock ~26 ~124 ~100 dirt
setblock ~26 ~124 ~101 dirt
setblock ~26 ~124 ~102 dirt
setblock ~26 ~124 ~103 dirt
setblock ~26 ~124 ~112 dirt
setblock ~26 ~124 ~113 dirt
setblock ~26 ~124 ~114 grass_block
setblock ~26 ~124 ~115 grass_block
setblock ~26 ~124 ~116 grass_block
setblock ~26 ~124 ~117 grass_block
setblock ~26 ~125 ~96 grass_block
setblock ~26 ~125 ~97 grass_block
setblock ~26 ~125 ~98 grass_block
setblock ~26 ~125 ~100 grass_block
setblock ~26 ~125 ~101 grass_block
setblock ~26 ~125 ~102 grass_block
setblock ~26 ~125 ~103 grass_block
setblock ~26 ~125 ~112 grass_block
setblock ~26 ~125 ~113 grass_block
setblock ~26 ~126 ~100 short_grass
setblock ~26 ~126 ~101 fern
setblock ~27 ~118 ~97 dirt
setblock ~27 ~118 ~113 dirt
setblock ~27 ~118 ~115 dirt
setblock ~27 ~119 ~96 dirt
setblock ~27 ~119 ~97 dirt
setblock ~27 ~119 ~101 dirt
setblock ~27 ~119 ~102 dirt
setblock ~27 ~119 ~103 dirt
setblock ~27 ~119 ~112 dirt
setblock ~27 ~119 ~113 dirt
setblock ~27 ~119 ~114 dirt
setblock ~27 ~119 ~115 dirt
setblock ~27 ~119 ~116 dirt
setblock ~27 ~120 ~96 dirt
setblock ~27 ~120 ~97 dirt
setblock ~27 ~120 ~98 dirt
setblock ~27 ~120 ~100 dirt
setblock ~27 ~120 ~101 dirt
setblock ~27 ~120 ~102 dirt
setblock ~27 ~120 ~103 dirt
setblock ~27 ~120 ~104 dirt
setblock ~27 ~120 ~108 dirt
setblock ~27 ~120 ~111 dirt
setblock ~27 ~120 ~112 dirt
setblock ~27 ~120 ~113 dirt
setblock ~27 ~120 ~114 dirt
setblock ~27 ~120 ~115 dirt
setblock ~27 ~120 ~116 dirt
setblock ~27 ~120 ~117 dirt
setblock ~27 ~121 ~78 dirt
setblock ~27 ~121 ~95 dirt
setblock ~27 ~121 ~96 dirt
setblock ~27 ~121 ~97 dirt
setblock ~27 ~121 ~98 dirt
setblock ~27 ~121 ~99 dirt
setblock ~27 ~121 ~100 dirt
setblock ~27 ~121 ~101 dirt
setblock ~27 ~121 ~102 dirt
setblock ~27 ~121 ~103 dirt
setblock ~27 ~121 ~104 dirt
setblock ~27 ~121 ~106 dirt
setblock ~27 ~121 ~107 dirt
setblock ~27 ~121 ~108 dirt
setblock ~27 ~121 ~109 dirt
setblock ~27 ~121 ~110 dirt
setblock ~27 ~121 ~111 dirt
setblock ~27 ~121 ~112 dirt
setblock ~27 ~121 ~113 dirt
setblock ~27 ~121 ~114 dirt
setblock ~27 ~121 ~115 dirt
setblock ~27 ~121 ~116 dirt
setblock ~27 ~121 ~117 dirt
setblock ~27 ~121 ~118 dirt
setblock ~27 ~122 ~78 dirt
setblock ~27 ~122 ~95 dirt
setblock ~27 ~122 ~96 dirt
setblock ~27 ~122 ~97 dirt
setblock ~27 ~122 ~98 dirt
setblock ~27 ~122 ~99 dirt
setblock ~27 ~122 ~100 dirt
setblock ~27 ~122 ~101 dirt
setblock ~27 ~122 ~102 dirt
setblock ~27 ~122 ~103 dirt
setblock ~27 ~122 ~104 dirt
setblock ~27 ~122 ~106 dirt
setblock ~27 ~122 ~107 dirt
setblock ~27 ~122 ~108 dirt
setblock ~27 ~122 ~109 dirt
setblock ~27 ~122 ~110 dirt
setblock ~27 ~122 ~111 dirt
setblock ~27 ~122 ~112 dirt
setblock ~27 ~122 ~113 dirt
setblock ~27 ~122 ~114 dirt
setblock ~27 ~122 ~115 dirt
setblock ~27 ~122 ~116 dirt
setblock ~27 ~122 ~117 dirt
setblock ~27 ~122 ~118 dirt
setblock ~27 ~123 ~78 dirt
setblock ~27 ~123 ~95 dirt
setblock ~27 ~123 ~96 dirt
setblock ~27 ~123 ~97 dirt
setblock ~27 ~123 ~98 dirt
setblock ~27 ~123 ~99 dirt
setblock ~27 ~123 ~100 dirt
setblock ~27 ~123 ~101 dirt
setblock ~27 ~123 ~102 dirt
setblock ~27 ~123 ~103 dirt
setblock ~27 ~123 ~104 dirt
setblock ~27 ~123 ~106 dirt
setblock ~27 ~123 ~107 dirt
setblock ~27 ~123 ~108 dirt
setblock ~27 ~123 ~109 dirt
setblock ~27 ~123 ~110 dirt
setblock ~27 ~123 ~111 dirt
setblock ~27 ~123 ~112 dirt
setblock ~27 ~123 ~113 dirt
setblock ~27 ~123 ~114 dirt
setblock ~27 ~123 ~115 dirt
setblock ~27 ~123 ~116 dirt
setblock ~27 ~123 ~117 dirt
setblock ~27 ~123 ~118 grass_block
setblock ~27 ~124 ~78 dirt
setblock ~27 ~124 ~95 dirt
setblock ~27 ~124 ~96 dirt
setblock ~27 ~124 ~97 dirt
setblock ~27 ~124 ~98 dirt
setblock ~27 ~124 ~99 dirt
setblock ~27 ~124 ~100 grass_block
setblock ~27 ~124 ~101 grass_block
setblock ~27 ~124 ~102 dirt
setblock ~27 ~124 ~103 dirt
setblock ~27 ~124 ~104 dirt
setblock ~27 ~124 ~106 dirt
setblock ~27 ~124 ~107 dirt
setblock ~27 ~124 ~108 dirt
setblock ~27 ~124 ~109 dirt
setblock ~27 ~124 ~110 dirt
setblock ~27 ~124 ~111 dirt
setblock ~27 ~124 ~112 dirt
setblock ~27 ~124 ~113 dirt
setblock ~27 ~124 ~114 dirt
setblock ~27 ~124 ~115 grass_block
setblock ~27 ~124 ~116 grass_block
setblock ~27 ~124 ~117 grass_block
setblock ~27 ~125 ~78 dirt
setblock ~27 ~125 ~95 grass_block
setblock ~27 ~125 ~96 grass_block
setblock ~27 ~125 ~97 grass_block
setblock ~27 ~125 ~98 grass_block
setblock ~27 ~125 ~99 grass_block
setblock ~27 ~125 ~100 fern
setblock ~27 ~125 ~101 short_grass
setblock ~27 ~125 ~102 grass_block
setblock ~27 ~125 ~103 grass_block
setblock ~27 ~125 ~104 grass_block
setblock ~27 ~125 ~106 dirt
setblock ~27 ~125 ~107 dirt
setblock ~27 ~125 ~108 dirt
setblock ~27 ~125 ~109 dirt
setblock ~27 ~125 ~110 dirt
setblock ~27 ~125 ~111 dirt
setblock ~27 ~125 ~112 grass_block
setblock ~27 ~125 ~113 grass_block
setblock ~27 ~125 ~114 grass_block
setblock ~27 ~125 ~115 poppy
setblock ~27 ~125 ~117 short_grass
setblock ~27 ~126 ~78 dirt
setblock ~27 ~126 ~98 fern
setblock ~27 ~126 ~106 grass_block
setblock ~27 ~126 ~107 grass_block
setblock ~27 ~126 ~108 grass_block
setblock ~27 ~126 ~109 grass_block
setblock ~27 ~126 ~110 grass_block
setblock ~27 ~126 ~111 grass_block
setblock ~27 ~126 ~112 fern
setblock ~27 ~127 ~78 grass_block
setblock ~27 ~127 ~108 short_grass
setblock ~27 ~127 ~109 poppy
setblock ~28 ~116 ~101 dirt
setblock ~28 ~116 ~102 dirt
setblock ~28 ~116 ~114 dirt
setblock ~28 ~117 ~97 dirt
setblock ~28 ~117 ~100 dirt
setblock ~28 ~117 ~101 dirt
setblock ~28 ~117 ~102 dirt
setblock ~28 ~117 ~109 dirt
setblock ~28 ~117 ~110 dirt
setblock ~28 ~117 ~113 dirt
setblock ~28 ~117 ~114 dirt
setblock ~28 ~117 ~115 dirt
setblock ~28 ~118 ~96 dirt
setblock ~28 ~118 ~97 dirt
setblock ~28 ~118 ~98 dirt
setblock ~28 ~118 ~99 dirt
setblock ~28 ~118 ~100 dirt
setblock ~28 ~118 ~101 dirt
setblock ~28 ~118 ~102 dirt
setblock ~28 ~118 ~103 dirt
setblock ~28 ~118 ~105 dirt
setblock ~28 ~118 ~107 dirt
setblock ~28 ~118 ~109 dirt
setblock ~28 ~118 ~110 dirt
setblock ~28 ~118 ~111 dirt
setblock ~28 ~118 ~112 dirt
setblock ~28 ~118 ~113 dirt
setblock ~28 ~118 ~114 dirt
setblock ~28 ~118 ~115 dirt
setblock ~28 ~118 ~116 dirt
setblock ~28 ~118 ~117 dirt
setblock ~28 ~119 ~91 dirt
setblock ~28 ~119 ~95 dirt
setblock ~28 ~119 ~96 dirt
setblock ~28 ~119 ~97 dirt
setblock ~28 ~119 ~98 dirt
setblock ~28 ~119 ~99 dirt
setblock ~28 ~119 ~100 dirt
setblock ~28 ~119 ~101 dirt
setblock ~28 ~119 ~102 dirt
setblock ~28 ~119 ~103 dirt
setblock ~28 ~119 ~104 dirt
setblock ~28 ~119 ~105 dirt
setblock ~28 ~119 ~106 dirt
setblock ~28 ~119 ~107 dirt
setblock ~28 ~119 ~108 dirt
setblock ~28 ~119 ~109 dirt
setblock ~28 ~119 ~110 dirt
setblock ~28 ~119 ~111 dirt
setblock ~28 ~119 ~112 dirt
setblock ~28 ~119 ~113 dirt
setblock ~28 ~119 ~114 dirt
setblock ~28 ~119 ~115 dirt
setblock ~28 ~119 ~116 dirt
setblock ~28 ~119 ~117 dirt
setblock ~28 ~120 ~78 dirt
setblock ~28 ~120 ~85 dirt
setblock ~28 ~120 ~90 dirt
setblock ~28 ~120 ~91 dirt
setblock ~28 ~120 ~94 dirt
setblock ~28 ~120 ~95 dirt
setblock ~28 ~120 ~96 dirt
setblock ~28 ~120 ~97 dirt
setblock ~28 ~120 ~98 dirt
setblock ~28 ~120 ~99 dirt
setblock ~28 ~120 ~100 dirt
setblock ~28 ~120 ~101 dirt
setblock ~28 ~120 ~102 dirt
setblock ~28 ~120 ~103 dirt
setblock ~28 ~120 ~104 dirt
setblock ~28 ~120 ~105 dirt
setblock ~28 ~120 ~106 dirt
setblock ~28 ~120 ~107 dirt
setblock ~28 ~120 ~108 dirt
setblock ~28 ~120 ~109 dirt
setblock ~28 ~120 ~110 dirt
setblock ~28 ~120 ~111 dirt
setblock ~28 ~120 ~112 dirt
setblock ~28 ~120 ~113 dirt
setblock ~28 ~120 ~114 dirt
setblock ~28 ~120 ~115 dirt
setblock ~28 ~120 ~116 dirt
setblock ~28 ~120 ~117 dirt
setblock ~28 ~120 ~118 dirt
setblock ~28 ~121 ~74 dirt
setblock ~28 ~121 ~75 dirt
setblock ~28 ~121 ~76 dirt
setblock ~28 ~121 ~77 dirt
setblock ~28 ~121 ~78 dirt
setblock ~28 ~121 ~79 dirt
setblock ~28 ~121 ~81 dirt
setblock ~28 ~121 ~84 dirt
setblock ~28 ~121 ~85 dirt
setblock ~28 ~121 ~86 dirt
setblock ~28 ~121 ~90 dirt
setblock ~28 ~121 ~91 dirt
setblock ~28 ~121 ~92 dirt
setblock ~28 ~121 ~94 dirt
setblock ~28 ~121 ~95 dirt
setblock ~28 ~121 ~96 dirt
setblock ~28 ~121 ~97 dirt
setblock ~28 ~121 ~98 dirt
setblock ~28 ~121 ~99 dirt
setblock ~28 ~121 ~100 dirt
setblock ~28 ~121 ~101 dirt
setblock ~28 ~121 ~102 dirt
setblock ~28 ~121 ~103 dirt
setblock ~28 ~121 ~104 dirt
setblock ~28 ~121 ~105 dirt
setblock ~28 ~121 ~106 dirt
setblock ~28 ~121 ~107 dirt
setblock ~28 ~121 ~108 dirt
setblock ~28 ~121 ~109 dirt
setblock ~28 ~121 ~110 dirt
setblock ~28 ~121 ~111 dirt
setblock ~28 ~121 ~112 dirt
setblock ~28 ~121 ~113 dirt
setblock ~28 ~121 ~114 dirt
setblock ~28 ~121 ~115 dirt
setblock ~28 ~121 ~116 dirt
setblock ~28 ~121 ~117 dirt
setblock ~28 ~121 ~118 dirt
setblock ~28 ~122 ~74 dirt
setblock ~28 ~122 ~75 dirt
setblock ~28 ~122 ~76 dirt
setblock ~28 ~122 ~77 dirt
setblock ~28 ~122 ~78 dirt
setblock ~28 ~122 ~79 dirt
setblock ~28 ~122 ~81 dirt
setblock ~28 ~122 ~84 dirt
setblock ~28 ~122 ~85 dirt
setblock ~28 ~122 ~86 dirt
setblock ~28 ~122 ~90 dirt
setblock ~28 ~122 ~91 dirt
setblock ~28 ~122 ~92 dirt
setblock ~28 ~122 ~94 dirt
setblock ~28 ~122 ~95 dirt
setblock ~28 ~122 ~96 dirt
setblock ~28 ~122 ~97 dirt
setblock ~28 ~122 ~98 dirt
setblock ~28 ~122 ~99 dirt
setblock ~28 ~122 ~100 dirt
setblock ~28 ~122 ~101 dirt
setblock ~28 ~122 ~102 dirt
setblock ~28 ~122 ~103 dirt
setblock ~28 ~122 ~104 dirt
setblock ~28 ~122 ~105 dirt
setblock ~28 ~122 ~106 dirt
setblock ~28 ~122 ~107 dirt
setblock ~28 ~122 ~108 dirt
setblock ~28 ~122 ~109 dirt
setblock ~28 ~122 ~110 dirt
setblock ~28 ~122 ~111 dirt
setblock ~28 ~122 ~112 dirt
setblock ~28 ~122 ~113 dirt
setblock ~28 ~122 ~114 dirt
setblock ~28 ~122 ~115 dirt
setblock ~28 ~122 ~116 dirt
setblock ~28 ~122 ~117 dirt
setblock ~28 ~122 ~118 dirt
setblock ~28 ~123 ~74 dirt
setblock ~28 ~123 ~75 dirt
setblock ~28 ~123 ~76 dirt
setblock ~28 ~123 ~77 dirt
setblock ~28 ~123 ~78 dirt
setblock ~28 ~123 ~79 dirt
setblock ~28 ~123 ~81 dirt
setblock ~28 ~123 ~84 dirt
setblock ~28 ~123 ~85 dirt
setblock ~28 ~123 ~86 dirt
setblock ~28 ~123 ~90 dirt
setblock ~28 ~123 ~91 dirt
setblock ~28 ~123 ~92 dirt
setblock ~28 ~123 ~94 dirt
setblock ~28 ~123 ~95 dirt
setblock ~28 ~123 ~96 dirt
setblock ~28 ~123 ~97 dirt
setblock ~28 ~123 ~98 dirt
setblock ~28 ~123 ~99 dirt
setblock ~28 ~123 ~100 dirt
setblock ~28 ~123 ~101 dirt
setblock ~28 ~123 ~102 dirt
setblock ~28 ~123 ~103 dirt
setblock ~28 ~123 ~104 dirt
setblock ~28 ~123 ~105 dirt
setblock ~28 ~123 ~106 dirt
setblock ~28 ~123 ~107 dirt
setblock ~28 ~123 ~108 dirt
setblock ~28 ~123 ~109 dirt
setblock ~28 ~123 ~110 dirt
setblock ~28 ~123 ~111 dirt
setblock ~28 ~123 ~112 dirt
setblock ~28 ~123 ~113 dirt
setblock ~28 ~123 ~114 dirt
setblock ~28 ~123 ~115 dirt
setblock ~28 ~123 ~116 dirt
setblock ~28 ~123 ~117 dirt
setblock ~28 ~123 ~118 grass_block
setblock ~28 ~124 ~74 dirt
setblock ~28 ~124 ~75 dirt
setblock ~28 ~124 ~76 dirt
setblock ~28 ~124 ~77 dirt
setblock ~28 ~124 ~78 dirt
setblock ~28 ~124 ~79 dirt
setblock ~28 ~124 ~81 dirt
setblock ~28 ~124 ~84 dirt
setblock ~28 ~124 ~85 dirt
setblock ~28 ~124 ~86 dirt
setblock ~28 ~124 ~90 grass_block
setblock ~28 ~124 ~91 dirt
setblock ~28 ~124 ~92 dirt
setblock ~28 ~124 ~94 dirt
setblock ~28 ~124 ~95 dirt
setblock ~28 ~124 ~96 dirt
setblock ~28 ~124 ~97 dirt
setblock ~28 ~124 ~98 grass_block
setblock ~28 ~124 ~99 grass_block
setblock ~28 ~124 ~100 grass_block
setblock ~28 ~124 ~101 grass_block
setblock ~28 ~124 ~102 grass_block
setblock ~28 ~124 ~103 dirt
setblock ~28 ~124 ~104 dirt
setblock ~28 ~124 ~105 dirt
setblock ~28 ~124 ~106 dirt
setblock ~28 ~124 ~107 dirt
setblock ~28 ~124 ~108 dirt
setblock ~28 ~124 ~109 dirt
setblock ~28 ~124 ~110 dirt
setblock ~28 ~124 ~111 dirt
setblock ~28 ~124 ~112 dirt
setblock ~28 ~124 ~113 dirt
setblock ~28 ~124 ~114 dirt
setblock ~28 ~124 ~115 grass_block
setblock ~28 ~124 ~116 grass_block
setblock ~28 ~124 ~117 grass_block
setblock ~28 ~125 ~74 dirt
setblock ~28 ~125 ~75 dirt
setblock ~28 ~125 ~76 dirt
setblock ~28 ~125 ~77 dirt
setblock ~28 ~125 ~78 dirt
setblock ~28 ~125 ~79 dirt
setblock ~28 ~125 ~81 dirt
setblock ~28 ~125 ~84 dirt
setblock ~28 ~125 ~85 dirt
setblock ~28 ~125 ~86 grass_block
setblock ~28 ~125 ~91 grass_block
setblock ~28 ~125 ~92 grass_block
setblock ~28 ~125 ~94 grass_block
setblock ~28 ~125 ~95 grass_block
setblock ~28 ~125 ~96 grass_block
setblock ~28 ~125 ~97 grass_block
setblock ~28 ~125 ~98 fern
setblock ~28 ~125 ~100 fern
setblock ~28 ~125 ~103 grass_block
setblock ~28 ~125 ~104 grass_block
setblock ~28 ~125 ~105 grass_block
setblock ~28 ~125 ~106 dirt
setblock ~28 ~125 ~107 dirt
setblock ~28 ~125 ~108 dirt
setblock ~28 ~125 ~109 dirt
setblock ~28 ~125 ~110 dirt
setblock ~28 ~125 ~111 dirt
setblock ~28 ~125 ~112 dirt
setblock ~28 ~125 ~113 grass_block
setblock ~28 ~125 ~114 grass_block
setblock ~28 ~126 ~74 dirt
setblock ~28 ~126 ~75 dirt
setblock ~28 ~126 ~76 dirt
setblock ~28 ~126 ~77 dirt
setblock ~28 ~126 ~78 dirt
setblock ~28 ~126 ~79 dirt
setblock ~28 ~126 ~81 dirt
setblock ~28 ~126 ~84 grass_block
setblock ~28 ~126 ~85 grass_block
setblock ~28 ~126 ~97 short_grass
setblock ~28 ~126 ~103 short_grass
setblock ~28 ~126 ~105 short_grass
setblock ~28 ~126 ~106 grass_block
setblock ~28 ~126 ~107 grass_block
setblock ~28 ~126 ~108 dirt
setblock ~28 ~126 ~109 dirt
setblock ~28 ~126 ~110 dirt
setblock ~28 ~126 ~111 dirt
setblock ~28 ~126 ~112 grass_block
setblock ~28 ~127 ~74 grass_block
setblock ~28 ~127 ~75 grass_block
setblock ~28 ~127 ~76 grass_block
setblock ~28 ~127 ~77 grass_block
setblock ~28 ~127 ~78 grass_block
setblock ~28 ~127 ~79 grass_block
setblock ~28 ~127 ~81 grass_block
setblock ~28 ~127 ~108 grass_block
setblock ~28 ~127 ~109 grass_block
setblock ~28 ~127 ~110 dirt
setblock ~28 ~127 ~111 grass_block
setblock ~28 ~128 ~76 short_grass
setblock ~28 ~128 ~77 short_grass
setblock ~28 ~128 ~110 grass_block
setblock ~29 ~112 ~101 dirt
setblock ~29 ~113 ~101 dirt
setblock ~29 ~114 ~101 dirt
setblock ~29 ~114 ~102 dirt
setblock ~29 ~114 ~110 dirt
setblock ~29 ~115 ~100 dirt
setblock ~29 ~115 ~101 dirt
setblock ~29 ~115 ~102 dirt
setblock ~29 ~115 ~103 dirt
setblock ~29 ~115 ~108 dirt
setblock ~29 ~115 ~110 dirt
setblock ~29 ~115 ~111 dirt
setblock ~29 ~115 ~114 dirt
setblock ~29 ~116 ~97 dirt
setblock ~29 ~116 ~98 dirt
setblock ~29 ~116 ~100 dirt
setblock ~29 ~116 ~101 dirt
setblock ~29 ~116 ~102 dirt
setblock ~29 ~116 ~103 dirt
setblock ~29 ~116 ~107 dirt
setblock ~29 ~116 ~108 dirt
setblock ~29 ~116 ~109 dirt
setblock ~29 ~116 ~110 dirt
setblock ~29 ~116 ~111 dirt
setblock ~29 ~116 ~112 dirt
setblock ~29 ~116 ~113 dirt
setblock ~29 ~116 ~114 dirt
setblock ~29 ~116 ~115 dirt
setblock ~29 ~116 ~117 dirt
setblock ~29 ~117 ~96 dirt
setblock ~29 ~117 ~97 dirt
setblock ~29 ~117 ~98 dirt
setblock ~29 ~117 ~99 dirt
setblock ~29 ~117 ~100 dirt
setblock ~29 ~117 ~101 dirt
setblock ~29 ~117 ~102 dirt
setblock ~29 ~117 ~103 dirt
setblock ~29 ~117 ~105 dirt
setblock ~29 ~117 ~106 dirt
setblock ~29 ~117 ~107 dirt
setblock ~29 ~117 ~108 dirt
setblock ~29 ~117 ~109 dirt
setblock ~29 ~117 ~110 dirt
setblock ~29 ~117 ~111 dirt
setblock ~29 ~117 ~112 dirt
setblock ~29 ~117 ~113 dirt
setblock ~29 ~117 ~114 dirt
setblock ~29 ~117 ~115 dirt
setblock ~29 ~117 ~116 dirt
setblock ~29 ~117 ~117 dirt
setblock ~29 ~118 ~75 dirt
setblock ~29 ~118 ~76 dirt
setblock ~29 ~118 ~78 dirt
setblock ~29 ~118 ~91 dirt
setblock ~29 ~118 ~95 dirt
setblock ~29 ~118 ~96 dirt
setblock ~29 ~118 ~97 dirt
setblock ~29 ~118 ~98 dirt
setblock ~29 ~118 ~99 dirt
setblock ~29 ~118 ~100 dirt
setblock ~29 ~118 ~101 dirt
setblock ~29 ~118 ~102 dirt
setblock ~29 ~118 ~103 dirt
setblock ~29 ~118 ~104 dirt
setblock ~29 ~118 ~105 dirt
setblock ~29 ~118 ~106 dirt
setblock ~29 ~118 ~107 dirt
setblock ~29 ~118 ~108 dirt
setblock ~29 ~118 ~109 dirt
setblock ~29 ~118 ~110 dirt
setblock ~29 ~118 ~111 dirt
setblock ~29 ~118 ~112 dirt
setblock ~29 ~118 ~113 dirt
setblock ~29 ~118 ~114 dirt
setblock ~29 ~118 ~115 dirt
setblock ~29 ~118 ~116 dirt
setblock ~29 ~118 ~117 dirt
setblock ~29 ~118 ~118 dirt
setblock ~29 ~119 ~75 dirt
setblock ~29 ~119 ~76 dirt
setblock ~29 ~119 ~78 dirt
setblock ~29 ~119 ~85 dirt
setblock ~29 ~119 ~90 dirt
setblock ~29 ~119 ~91 dirt
setblock ~29 ~119 ~92 dirt
setblock ~29 ~119 ~94 dirt
setblock ~29 ~119 ~95 dirt
setblock ~29 ~119 ~96 dirt
setblock ~29 ~119 ~97 dirt
setblock ~29 ~119 ~98 dirt
setblock ~29 ~119 ~99 dirt
setblock ~29 ~119 ~100 dirt
setblock ~29 ~119 ~101 dirt
setblock ~29 ~119 ~102 dirt
setblock ~29 ~119 ~103 dirt
setblock ~29 ~119 ~104 dirt
setblock ~29 ~119 ~105 dirt
setblock ~29 ~119 ~106 dirt
setblock ~29 ~119 ~107 dirt
setblock ~29 ~119 ~108 dirt
setblock ~29 ~119 ~109 dirt
setblock ~29 ~119 ~110 dirt
setblock ~29 ~119 ~111 dirt
setblock ~29 ~119 ~112 dirt
setblock ~29 ~119 ~113 dirt
setblock ~29 ~119 ~114 dirt
setblock ~29 ~119 ~115 dirt
setblock ~29 ~119 ~116 dirt
setblock ~29 ~119 ~117 dirt
setblock ~29 ~119 ~118 dirt
setblock ~29 ~120 ~74 dirt
setblock ~29 ~120 ~75 dirt
setblock ~29 ~120 ~76 dirt
setblock ~29 ~120 ~77 dirt
setblock ~29 ~120 ~78 dirt
setblock ~29 ~120 ~79 dirt
setblock ~29 ~120 ~80 dirt
setblock ~29 ~120 ~81 dirt
setblock ~29 ~120 ~84 dirt
setblock ~29 ~120 ~85 dirt
setblock ~29 ~120 ~86 dirt
setblock ~29 ~120 ~89 dirt
setblock ~29 ~120 ~90 dirt
setblock ~29 ~120 ~91 dirt
setblock ~29 ~120 ~92 dirt
setblock ~29 ~120 ~93 dirt
setblock ~29 ~120 ~94 dirt
setblock ~29 ~120 ~95 dirt
setblock ~29 ~120 ~96 dirt
setblock ~29 ~120 ~97 dirt
setblock ~29 ~120 ~98 dirt
setblock ~29 ~120 ~99 dirt
setblock ~29 ~120 ~100 dirt
setblock ~29 ~120 ~101 dirt
setblock ~29 ~120 ~102 dirt
setblock ~29 ~120 ~103 dirt
setblock ~29 ~120 ~104 dirt
setblock ~29 ~120 ~105 dirt
setblock ~29 ~120 ~106 dirt
setblock ~29 ~120 ~107 dirt
setblock ~29 ~120 ~108 dirt
setblock ~29 ~120 ~109 dirt
setblock ~29 ~120 ~110 dirt
setblock ~29 ~120 ~111 dirt
setblock ~29 ~120 ~112 dirt
setblock ~29 ~120 ~113 dirt
setblock ~29 ~120 ~114 dirt
setblock ~29 ~120 ~115 dirt
setblock ~29 ~120 ~116 dirt
setblock ~29 ~120 ~117 dirt
setblock ~29 ~120 ~118 dirt
setblock ~29 ~120 ~119 dirt
setblock ~29 ~121 ~73 dirt
setblock ~29 ~121 ~74 dirt
setblock ~29 ~121 ~75 dirt
setblock ~29 ~121 ~76 dirt
setblock ~29 ~121 ~77 dirt
setblock ~29 ~121 ~78 dirt
setblock ~29 ~121 ~79 dirt
setblock ~29 ~121 ~80 dirt
setblock ~29 ~121 ~81 dirt
setblock ~29 ~121 ~82 dirt
setblock ~29 ~121 ~83 dirt
setblock ~29 ~121 ~84 dirt
setblock ~29 ~121 ~85 dirt
setblock ~29 ~121 ~86 dirt
setblock ~29 ~121 ~87 dirt
setblock ~29 ~121 ~89 dirt
setblock ~29 ~121 ~90 dirt
setblock ~29 ~121 ~91 dirt
setblock ~29 ~121 ~92 dirt
setblock ~29 ~121 ~93 dirt
setblock ~29 ~121 ~94 dirt
setblock ~29 ~121 ~95 dirt
setblock ~29 ~121 ~96 dirt
setblock ~29 ~121 ~97 dirt
setblock ~29 ~121 ~98 dirt
setblock ~29 ~121 ~99 dirt
setblock ~29 ~121 ~100 dirt
setblock ~29 ~121 ~101 dirt
setblock ~29 ~121 ~102 dirt
setblock ~29 ~121 ~103 dirt
setblock ~29 ~121 ~104 dirt
setblock ~29 ~121 ~105 dirt
setblock ~29 ~121 ~106 dirt
setblock ~29 ~121 ~107 dirt
setblock ~29 ~121 ~108 dirt
setblock ~29 ~121 ~109 dirt
setblock ~29 ~121 ~110 dirt
setblock ~29 ~121 ~111 dirt
setblock ~29 ~121 ~112 dirt
setblock ~29 ~121 ~113 dirt
setblock ~29 ~121 ~114 dirt
setblock ~29 ~121 ~115 dirt
setblock ~29 ~121 ~116 dirt
setblock ~29 ~121 ~117 dirt
setblock ~29 ~121 ~118 dirt
setblock ~29 ~121 ~119 dirt
setblock ~29 ~122 ~73 dirt
setblock ~29 ~122 ~74 dirt
setblock ~29 ~122 ~75 dirt
setblock ~29 ~122 ~76 dirt
setblock ~29 ~122 ~77 dirt
setblock ~29 ~122 ~78 dirt
setblock ~29 ~122 ~79 dirt
setblock ~29 ~122 ~80 dirt
setblock ~29 ~122 ~81 dirt
setblock ~29 ~122 ~82 dirt
setblock ~29 ~122 ~83 dirt
setblock ~29 ~122 ~84 dirt
setblock ~29 ~122 ~85 dirt
setblock ~29 ~122 ~86 dirt
setblock ~29 ~122 ~87 dirt
setblock ~29 ~122 ~89 dirt
setblock ~29 ~122 ~90 dirt
setblock ~29 ~122 ~91 dirt
setblock ~29 ~122 ~92 dirt
setblock ~29 ~122 ~93 dirt
setblock ~29 ~122 ~94 dirt
setblock ~29 ~122 ~95 dirt
setblock ~29 ~122 ~96 dirt
setblock ~29 ~122 ~97 dirt
setblock ~29 ~122 ~98 dirt
setblock ~29 ~122 ~99 dirt
setblock ~29 ~122 ~100 dirt
setblock ~29 ~122 ~101 dirt
setblock ~29 ~122 ~102 dirt
setblock ~29 ~122 ~103 dirt
setblock ~29 ~122 ~104 dirt
setblock ~29 ~122 ~105 dirt
setblock ~29 ~122 ~106 dirt
setblock ~29 ~122 ~107 dirt
setblock ~29 ~122 ~108 dirt
setblock ~29 ~122 ~109 dirt
setblock ~29 ~122 ~110 dirt
setblock ~29 ~122 ~111 dirt
setblock ~29 ~122 ~112 dirt
setblock ~29 ~122 ~113 dirt
setblock ~29 ~122 ~114 dirt
setblock ~29 ~122 ~115 dirt
setblock ~29 ~122 ~116 dirt
setblock ~29 ~122 ~117 dirt
setblock ~29 ~122 ~118 dirt
setblock ~29 ~122 ~119 dirt
setblock ~29 ~123 ~73 dirt
setblock ~29 ~123 ~74 dirt
setblock ~29 ~123 ~75 dirt
setblock ~29 ~123 ~76 dirt
setblock ~29 ~123 ~77 dirt
setblock ~29 ~123 ~78 dirt
setblock ~29 ~123 ~79 dirt
setblock ~29 ~123 ~80 dirt
setblock ~29 ~123 ~81 dirt
setblock ~29 ~123 ~82 dirt
setblock ~29 ~123 ~83 dirt
setblock ~29 ~123 ~84 dirt
setblock ~29 ~123 ~85 dirt
setblock ~29 ~123 ~86 dirt
setblock ~29 ~123 ~87 dirt
setblock ~29 ~123 ~89 dirt
setblock ~29 ~123 ~90 dirt
setblock ~29 ~123 ~91 dirt
setblock ~29 ~123 ~92 dirt
setblock ~29 ~123 ~93 dirt
setblock ~29 ~123 ~94 dirt
setblock ~29 ~123 ~95 dirt
setblock ~29 ~123 ~96 dirt
setblock ~29 ~123 ~97 dirt
setblock ~29 ~123 ~98 dirt
setblock ~29 ~123 ~99 grass_block
setblock ~29 ~123 ~100 grass_block
setblock ~29 ~123 ~101 grass_block
setblock ~29 ~123 ~102 dirt
setblock ~29 ~123 ~103 dirt
setblock ~29 ~123 ~104 dirt
setblock ~29 ~123 ~105 dirt
setblock ~29 ~123 ~106 dirt
setblock ~29 ~123 ~107 dirt
setblock ~29 ~123 ~108 dirt
setblock ~29 ~123 ~109 dirt
setblock ~29 ~123 ~110 dirt
setblock ~29 ~123 ~111 dirt
setblock ~29 ~123 ~112 dirt
setblock ~29 ~123 ~113 dirt
setblock ~29 ~123 ~114 dirt
setblock ~29 ~123 ~115 dirt
setblock ~29 ~123 ~116 dirt
setblock ~29 ~123 ~117 dirt
setblock ~29 ~123 ~118 grass_block
setblock ~29 ~123 ~119 grass_block
setblock ~29 ~124 ~73 dirt
setblock ~29 ~124 ~74 dirt
setblock ~29 ~124 ~75 dirt
setblock ~29 ~124 ~76 dirt
setblock ~29 ~124 ~77 dirt
setblock ~29 ~124 ~78 dirt
setblock ~29 ~124 ~79 dirt
setblock ~29 ~124 ~80 dirt
setblock ~29 ~124 ~81 dirt
setblock ~29 ~124 ~82 dirt
setblock ~29 ~124 ~83 dirt
setblock ~29 ~124 ~84 dirt
setblock ~29 ~124 ~85 dirt
setblock ~29 ~124 ~86 dirt
setblock ~29 ~124 ~87 dirt
setblock ~29 ~124 ~89 grass_block
setblock ~29 ~124 ~90 grass_block
setblock ~29 ~124 ~91 grass_block
setblock ~29 ~124 ~92 grass_block
setblock ~29 ~124 ~93 dirt
setblock ~29 ~124 ~94 dirt
setblock ~29 ~124 ~95 dirt
setblock ~29 ~124 ~96 grass_block
setblock ~29 ~124 ~97 grass_block
setblock ~29 ~124 ~98 grass_block
setblock ~29 ~124 ~102 grass_block
setblock ~29 ~124 ~103 grass_block
setblock ~29 ~124 ~104 dirt
setblock ~29 ~124 ~105 dirt
setblock ~29 ~124 ~106 dirt
setblock ~29 ~124 ~107 dirt
setblock ~29 ~124 ~108 dirt
setblock ~29 ~124 ~109 dirt
setblock ~29 ~124 ~110 dirt
setblock ~29 ~124 ~111 dirt
setblock ~29 ~124 ~112 dirt
setblock ~29 ~124 ~113 dirt
setblock ~29 ~124 ~114 dirt
setblock ~29 ~124 ~115 dirt
setblock ~29 ~124 ~116 grass_block
setblock ~29 ~124 ~117 grass_block
setblock ~29 ~125 ~73 dirt
setblock ~29 ~125 ~74 dirt
setblock ~29 ~125 ~75 dirt
setblock ~29 ~125 ~76 dirt
setblock ~29 ~125 ~77 dirt
setblock ~29 ~125 ~78 dirt
setblock ~29 ~125 ~79 dirt
setblock ~29 ~125 ~80 dirt
setblock ~29 ~125 ~81 dirt
setblock ~29 ~125 ~82 dirt
setblock ~29 ~125 ~83 dirt
setblock ~29 ~125 ~84 dirt
setblock ~29 ~125 ~85 grass_block
setblock ~29 ~125 ~86 grass_block
setblock ~29 ~125 ~87 grass_block
setblock ~29 ~125 ~91 short_grass
setblock ~29 ~125 ~93 grass_block
setblock ~29 ~125 ~94 grass_block
setblock ~29 ~125 ~95 grass_block
setblock ~29 ~125 ~96 fern
setblock ~29 ~125 ~104 grass_block
setblock ~29 ~125 ~105 grass_block
setblock ~29 ~125 ~106 dirt
setblock ~29 ~125 ~107 dirt
setblock ~29 ~125 ~108 dirt
setblock ~29 ~125 ~109 dirt
setblock ~29 ~125 ~110 dirt
setblock ~29 ~125 ~111 dirt
setblock ~29 ~125 ~112 dirt
setblock ~29 ~125 ~113 dirt
setblock ~29 ~125 ~114 grass_block
setblock ~29 ~125 ~115 grass_block
setblock ~29 ~125 ~116 short_grass
setblock ~29 ~126 ~73 dirt
setblock ~29 ~126 ~74 dirt
setblock ~29 ~126 ~75 dirt
setblock ~29 ~126 ~76 dirt
setblock ~29 ~126 ~77 dirt
setblock ~29 ~126 ~78 dirt
setblock ~29 ~126 ~79 dirt
setblock ~29 ~126 ~80 dirt
setblock ~29 ~126 ~81 dirt
setblock ~29 ~126 ~82 dirt
setblock ~29 ~126 ~83 grass_block
setblock ~29 ~126 ~84 grass_block
setblock ~29 ~126 ~94 fern
setblock ~29 ~126 ~105 fern
setblock ~29 ~126 ~106 grass_block
setblock ~29 ~126 ~107 dirt
setblock ~29 ~126 ~108 dirt
setblock ~29 ~126 ~109 dirt
setblock ~29 ~126 ~110 dirt
setblock ~29 ~126 ~111 dirt
setblock ~29 ~126 ~112 dirt
setblock ~29 ~126 ~113 grass_block
setblock ~29 ~127 ~73 grass_block
setblock ~29 ~127 ~74 grass_block
setblock ~29 ~127 ~75 grass_block
setblock ~29 ~127 ~76 grass_block
setblock ~29 ~127 ~77 grass_block
setblock ~29 ~127 ~78 grass_block
setblock ~29 ~127 ~79 dirt
setblock ~29 ~127 ~80 dirt
setblock ~29 ~127 ~81 grass_block
setblock ~29 ~127 ~82 grass_block
setblock ~29 ~127 ~106 fern
setblock ~29 ~127 ~107 grass_block
setblock ~29 ~127 ~108 grass_block
setblock ~29 ~127 ~109 dirt
setblock ~29 ~127 ~110 dirt
setblock ~29 ~127 ~111 dirt
setblock ~29 ~127 ~112 grass_block
setblock ~29 ~128 ~79 grass_block
setblock ~29 ~128 ~80 grass_block
setblock ~29 ~128 ~109 grass_block
setblock ~29 ~128 ~110 dirt
setblock ~29 ~128 ~111 grass_block
setblock ~29 ~129 ~80 short_grass
setblock ~29 ~129 ~110 grass_block
setblock ~29 ~129 ~111 short_grass
setblock ~29 ~130 ~110 short_grass
setblock ~30 ~111 ~101 dirt
setblock ~30 ~111 ~102 dirt
setblock ~30 ~111 ~110 dirt
setblock ~30 ~112 ~100 dirt
setblock ~30 ~112 ~101 dirt
setblock ~30 ~112 ~102 dirt
setblock ~30 ~112 ~103 dirt
setblock ~30 ~112 ~110 dirt
setblock ~30 ~112 ~113 dirt
setblock ~30 ~113 ~99 dirt
setblock ~30 ~113 ~100 dirt
setblock ~30 ~113 ~101 dirt
setblock ~30 ~113 ~102 dirt
setblock ~30 ~113 ~103 dirt
setblock ~30 ~113 ~107 dirt
setblock ~30 ~113 ~108 dirt
setblock ~30 ~113 ~109 dirt
setblock ~30 ~113 ~110 dirt
setblock ~30 ~113 ~111 dirt
setblock ~30 ~113 ~113 dirt
setblock ~30 ~114 ~98 dirt
setblock ~30 ~114 ~99 dirt
setblock ~30 ~114 ~100 dirt
setblock ~30 ~114 ~101 dirt
setblock ~30 ~114 ~102 dirt
setblock ~30 ~114 ~103 dirt
setblock ~30 ~114 ~105 dirt
setblock ~30 ~114 ~107 dirt
setblock ~30 ~114 ~108 dirt
setblock ~30 ~114 ~109 dirt
setblock ~30 ~114 ~110 dirt
setblock ~30 ~114 ~111 dirt
setblock ~30 ~114 ~112 dirt
setblock ~30 ~114 ~113 dirt
setblock ~30 ~114 ~114 dirt
setblock ~30 ~114 ~116 dirt
setblock ~30 ~115 ~97 dirt
setblock ~30 ~115 ~98 dirt
setblock ~30 ~115 ~99 dirt
setblock ~30 ~115 ~100 dirt
setblock ~30 ~115 ~101 dirt
setblock ~30 ~115 ~102 dirt
setblock ~30 ~115 ~103 dirt
setblock ~30 ~115 ~104 dirt
setblock ~30 ~115 ~105 dirt
setblock ~30 ~115 ~106 dirt
setblock ~30 ~115 ~107 dirt
setblock ~30 ~115 ~108 dirt
setblock ~30 ~115 ~109 dirt
setblock ~30 ~115 ~110 dirt
setblock ~30 ~115 ~111 dirt
setblock ~30 ~115 ~112 dirt
setblock ~30 ~115 ~113 dirt
setblock ~30 ~115 ~114 dirt
setblock ~30 ~115 ~115 dirt
setblock ~30 ~115 ~116 dirt
setblock ~30 ~115 ~117 dirt
setblock ~30 ~116 ~96 dirt
setblock ~30 ~116 ~97 dirt
setblock ~30 ~116 ~98 dirt
setblock ~30 ~116 ~99 dirt
setblock ~30 ~116 ~100 dirt
setblock ~30 ~116 ~101 dirt
setblock ~30 ~116 ~102 dirt
setblock ~30 ~116 ~103 dirt
setblock ~30 ~116 ~104 dirt
setblock ~30 ~116 ~105 dirt
setblock ~30 ~116 ~106 dirt
setblock ~30 ~116 ~107 dirt
setblock ~30 ~116 ~108 dirt
setblock ~30 ~116 ~109 dirt
setblock ~30 ~116 ~110 dirt
setblock ~30 ~116 ~111 dirt
setblock ~30 ~116 ~112 dirt
setblock ~30 ~116 ~113 dirt
setblock ~30 ~116 ~114 dirt
setblock ~30 ~116 ~115 dirt
setblock ~30 ~116 ~116 dirt
setblock ~30 ~116 ~117 dirt
setblock ~30 ~116 ~118 dirt
setblock ~30 ~117 ~75 dirt
setblock ~30 ~117 ~76 dirt
setblock ~30 ~117 ~78 dirt
setblock ~30 ~117 ~81 dirt
setblock ~30 ~117 ~85 dirt
setblock ~30 ~117 ~91 dirt
setblock ~30 ~117 ~94 dirt
setblock ~30 ~117 ~95 dirt
setblock ~30 ~117 ~96 dirt
setblock ~30 ~117 ~97 dirt
setblock ~30 ~117 ~98 dirt
setblock ~30 ~117 ~99 dirt
setblock ~30 ~117 ~100 dirt
setblock ~30 ~117 ~101 dirt
setblock ~30 ~117 ~102 dirt
setblock ~30 ~117 ~103 dirt
setblock ~30 ~117 ~104 dirt
setblock ~30 ~117 ~105 dirt
setblock ~30 ~117 ~106 dirt
setblock ~30 ~117 ~107 dirt
setblock ~30 ~117 ~108 dirt
setblock ~30 ~117 ~109 dirt
setblock ~30 ~117 ~110 dirt
setblock ~30 ~117 ~111 dirt
setblock ~30 ~117 ~112 dirt
setblock ~30 ~117 ~113 dirt
setblock ~30 ~117 ~114 dirt
setblock ~30 ~117 ~115 dirt
setblock ~30 ~117 ~116 dirt
setblock ~30 ~117 ~117 dirt
setblock ~30 ~117 ~118 dirt
setblock ~30 ~118 ~74 dirt
setblock ~30 ~118 ~75 dirt
setblock ~30 ~118 ~76 dirt
setblock ~30 ~118 ~77 dirt
setblock ~30 ~118 ~78 dirt
setblock ~30 ~118 ~79 dirt
setblock ~30 ~118 ~81 dirt
setblock ~30 ~118 ~85 dirt
setblock ~30 ~118 ~90 dirt
setblock ~30 ~118 ~91 dirt
setblock ~30 ~118 ~92 dirt
setblock ~30 ~118 ~94 dirt
setblock ~30 ~118 ~95 dirt
setblock ~30 ~118 ~96 dirt
setblock ~30 ~118 ~97 dirt
setblock ~30 ~118 ~98 dirt
setblock ~30 ~118 ~99 dirt
setblock ~30 ~118 ~100 dirt
setblock ~30 ~118 ~101 dirt
setblock ~30 ~118 ~102 dirt
setblock ~30 ~118 ~103 dirt
setblock ~30 ~118 ~104 dirt
setblock ~30 ~118 ~105 dirt
setblock ~30 ~118 ~106 dirt
setblock ~30 ~118 ~107 dirt
setblock ~30 ~118 ~108 dirt
setblock ~30 ~118 ~109 dirt
setblock ~30 ~118 ~110 dirt
setblock ~30 ~118 ~111 dirt
setblock ~30 ~118 ~112 dirt
setblock ~30 ~118 ~113 dirt
setblock ~30 ~118 ~114 dirt
setblock ~30 ~118 ~115 dirt
setblock ~30 ~118 ~116 dirt
setblock ~30 ~118 ~117 dirt
setblock ~30 ~118 ~118 dirt
setblock ~30 ~118 ~119 dirt
setblock ~30 ~119 ~74 dirt
setblock ~30 ~119 ~75 dirt
setblock ~30 ~119 ~76 dirt
setblock ~30 ~119 ~77 dirt
setblock ~30 ~119 ~78 dirt
setblock ~30 ~119 ~79 dirt
setblock ~30 ~119 ~80 dirt
setblock ~30 ~119 ~81 dirt
setblock ~30 ~119 ~84 dirt
setblock ~30 ~119 ~85 dirt
setblock ~30 ~119 ~86 dirt
setblock ~30 ~119 ~89 dirt
setblock ~30 ~119 ~90 dirt
setblock ~30 ~119 ~91 dirt
setblock ~30 ~119 ~92 dirt
setblock ~30 ~119 ~93 dirt
setblock ~30 ~119 ~94 dirt
setblock ~30 ~119 ~95 dirt
setblock ~30 ~119 ~96 dirt
setblock ~30 ~119 ~97 dirt
setblock ~30 ~119 ~98 dirt
setblock ~30 ~119 ~99 dirt
setblock ~30 ~119 ~100 dirt
setblock ~30 ~119 ~101 dirt
setblock ~30 ~119 ~102 dirt
setblock ~30 ~119 ~103 dirt
setblock ~30 ~119 ~104 dirt
setblock ~30 ~119 ~105 dirt
setblock ~30 ~119 ~106 dirt
setblock ~30 ~119 ~107 dirt
setblock ~30 ~119 ~108 dirt
setblock ~30 ~119 ~109 dirt
setblock ~30 ~119 ~110 dirt
setblock ~30 ~119 ~111 dirt
setblock ~30 ~119 ~112 dirt
setblock ~30 ~119 ~113 dirt
setblock ~30 ~119 ~114 dirt
setblock ~30 ~119 ~115 dirt
setblock ~30 ~119 ~116 dirt
setblock ~30 ~119 ~117 dirt
setblock ~30 ~119 ~118 dirt
setblock ~30 ~119 ~119 dirt
setblock ~30 ~120 ~73 dirt
setblock ~30 ~120 ~74 dirt
setblock ~30 ~120 ~75 dirt
setblock ~30 ~120 ~76 dirt
setblock ~30 ~120 ~77 dirt
setblock ~30 ~120 ~78 dirt
setblock ~30 ~120 ~79 dirt
setblock ~30 ~120 ~80 dirt
setblock ~30 ~120 ~81 dirt
setblock ~30 ~120 ~82 dirt
setblock ~30 ~120 ~83 dirt
setblock ~30 ~120 ~84 dirt
setblock ~30 ~120 ~85 dirt
setblock ~30 ~120 ~86 dirt
setblock ~30 ~120 ~87 dirt
setblock ~30 ~120 ~89 dirt
setblock ~30 ~120 ~90 dirt
setblock ~30 ~120 ~91 dirt
setblock ~30 ~120 ~92 dirt
setblock ~30 ~120 ~93 dirt
setblock ~30 ~120 ~94 dirt
setblock ~30 ~120 ~95 dirt
setblock ~30 ~120 ~96 dirt
setblock ~30 ~120 ~97 dirt
setblock ~30 ~120 ~98 dirt
setblock ~30 ~120 ~99 dirt
setblock ~30 ~120 ~100 dirt
setblock ~30 ~120 ~101 dirt
setblock ~30 ~120 ~102 dirt
setblock ~30 ~120 ~103 dirt
setblock ~30 ~120 ~104 dirt
setblock ~30 ~120 ~105 dirt
setblock ~30 ~120 ~106 dirt
setblock ~30 ~120 ~107 dirt
setblock ~30 ~120 ~108 dirt
setblock ~30 ~120 ~109 dirt
setblock ~30 ~120 ~110 dirt
setblock ~30 ~120 ~111 dirt
setblock ~30 ~120 ~112 dirt
setblock ~30 ~120 ~113 dirt
setblock ~30 ~120 ~114 dirt
setblock ~30 ~120 ~115 dirt
setblock ~30 ~120 ~116 dirt
setblock ~30 ~120 ~117 dirt
setblock ~30 ~120 ~118 dirt
setblock ~30 ~120 ~119 dirt
setblock ~30 ~120 ~120 dirt
setblock ~30 ~121 ~73 dirt
setblock ~30 ~121 ~74 dirt
setblock ~30 ~121 ~75 dirt
setblock ~30 ~121 ~76 dirt
setblock ~30 ~121 ~77 dirt
setblock ~30 ~121 ~78 dirt
setblock ~30 ~121 ~79 dirt
setblock ~30 ~121 ~80 dirt
setblock ~30 ~121 ~81 dirt
setblock ~30 ~121 ~82 dirt
setblock ~30 ~121 ~83 dirt
setblock ~30 ~121 ~84 dirt
setblock ~30 ~121 ~85 dirt
setblock ~30 ~121 ~86 dirt
setblock ~30 ~121 ~87 dirt
setblock ~30 ~121 ~88 dirt
setblock ~30 ~121 ~89 dirt
setblock ~30 ~121 ~90 dirt
setblock ~30 ~121 ~91 dirt
setblock ~30 ~121 ~92 dirt
setblock ~30 ~121 ~93 dirt
setblock ~30 ~121 ~94 dirt
setblock ~30 ~121 ~95 dirt
setblock ~30 ~121 ~96 dirt
setblock ~30 ~121 ~97 dirt
setblock ~30 ~121 ~98 dirt
setblock ~30 ~121 ~99 dirt
setblock ~30 ~121 ~100 dirt
setblock ~30 ~121 ~101 dirt
setblock ~30 ~121 ~102 dirt
setblock ~30 ~121 ~103 dirt
setblock ~30 ~121 ~104 dirt
setblock ~30 ~121 ~105 dirt
setblock ~30 ~121 ~106 dirt
setblock ~30 ~121 ~107 dirt
setblock ~30 ~121 ~108 dirt
setblock ~30 ~121 ~109 dirt
setblock ~30 ~121 ~110 dirt
setblock ~30 ~121 ~111 dirt
setblock ~30 ~121 ~112 dirt
setblock ~30 ~121 ~113 dirt
setblock ~30 ~121 ~114 dirt
setblock ~30 ~121 ~115 dirt
setblock ~30 ~121 ~116 dirt
setblock ~30 ~121 ~117 dirt
setblock ~30 ~121 ~118 dirt
setblock ~30 ~121 ~119 dirt
setblock ~30 ~121 ~120 dirt
setblock ~30 ~122 ~73 dirt
setblock ~30 ~122 ~74 dirt
setblock ~30 ~122 ~75 dirt
setblock ~30 ~122 ~76 dirt
setblock ~30 ~122 ~77 dirt
setblock ~30 ~122 ~78 dirt
setblock ~30 ~122 ~79 dirt
setblock ~30 ~122 ~80 dirt
setblock ~30 ~122 ~81 dirt
setblock ~30 ~122 ~82 dirt
setblock ~30 ~122 ~83 dirt
setblock ~30 ~122 ~84 dirt
setblock ~30 ~122 ~85 dirt
setblock ~30 ~122 ~86 dirt
setblock ~30 ~122 ~87 dirt
setblock ~30 ~122 ~88 dirt
setblock ~30 ~122 ~89 dirt
setblock ~30 ~122 ~90 dirt
setblock ~30 ~122 ~91 dirt
setblock ~30 ~122 ~92 dirt
setblock ~30 ~122 ~93 dirt
setblock ~30 ~122 ~94 dirt
setblock ~30 ~122 ~95 dirt
setblock ~30 ~122 ~96 dirt
setblock ~30 ~122 ~97 dirt
setblock ~30 ~122 ~98 dirt
setblock ~30 ~122 ~99 dirt
setblock ~30 ~122 ~100 grass_block
setblock ~30 ~122 ~101 dirt
setblock ~30 ~122 ~102 dirt
setblock ~30 ~122 ~103 dirt
setblock ~30 ~122 ~104 dirt
setblock ~30 ~122 ~105 dirt
setblock ~30 ~122 ~106 dirt
setblock ~30 ~122 ~107 dirt
setblock ~30 ~122 ~108 dirt
setblock ~30 ~122 ~109 dirt
setblock ~30 ~122 ~110 dirt
setblock ~30 ~122 ~111 dirt
setblock ~30 ~122 ~112 dirt
setblock ~30 ~122 ~113 dirt
setblock ~30 ~122 ~114 dirt
setblock ~30 ~122 ~115 dirt
setblock ~30 ~122 ~116 dirt
setblock ~30 ~122 ~117 dirt
setblock ~30 ~122 ~118 dirt
setblock ~30 ~122 ~119 dirt
setblock ~30 ~122 ~120 grass_block
setblock ~30 ~123 ~73 dirt
setblock ~30 ~123 ~74 dirt
setblock ~30 ~123 ~75 dirt
setblock ~30 ~123 ~76 dirt
setblock ~30 ~123 ~77 dirt
setblock ~30 ~123 ~78 dirt
setblock ~30 ~123 ~79 dirt
setblock ~30 ~123 ~80 dirt
setblock ~30 ~123 ~81 dirt
setblock ~30 ~123 ~82 dirt
setblock ~30 ~123 ~83 dirt
setblock ~30 ~123 ~84 dirt
setblock ~30 ~123 ~85 dirt
setblock ~30 ~123 ~86 dirt
setblock ~30 ~123 ~87 dirt
setblock ~30 ~123 ~88 dirt
setblock ~30 ~123 ~89 dirt
setblock ~30 ~123 ~90 grass_block
setblock ~30 ~123 ~91 dirt
setblock ~30 ~123 ~92 dirt
setblock ~30 ~123 ~93 dirt
setblock ~30 ~123 ~94 dirt
setblock ~30 ~123 ~95 dirt
setblock ~30 ~123 ~96 dirt
setblock ~30 ~123 ~97 dirt
setblock ~30 ~123 ~98 grass_block
setblock ~30 ~123 ~99 grass_block
setblock ~30 ~123 ~101 grass_block
setblock ~30 ~123 ~102 grass_block
setblock ~30 ~123 ~103 dirt
setblock ~30 ~123 ~104 dirt
setblock ~30 ~123 ~105 dirt
setblock ~30 ~123 ~106 dirt
setblock ~30 ~123 ~107 dirt
setblock ~30 ~123 ~108 dirt
setblock ~30 ~123 ~109 dirt
setblock ~30 ~123 ~110 dirt
setblock ~30 ~123 ~111 dirt
setblock ~30 ~123 ~112 dirt
setblock ~30 ~123 ~113 dirt
setblock ~30 ~123 ~114 dirt
setblock ~30 ~123 ~115 dirt
setblock ~30 ~123 ~116 dirt
setblock ~30 ~123 ~117 dirt
setblock ~30 ~123 ~118 grass_block
setblock ~30 ~123 ~119 grass_block
setblock ~30 ~123 ~120 short_grass
setblock ~30 ~124 ~73 dirt
setblock ~30 ~124 ~74 dirt
setblock ~30 ~124 ~75 dirt
setblock ~30 ~124 ~76 dirt
setblock ~30 ~124 ~77 dirt
setblock ~30 ~124 ~78 dirt
setblock ~30 ~124 ~79 dirt
setblock ~30 ~124 ~80 dirt
setblock ~30 ~124 ~81 dirt
setblock ~30 ~124 ~82 dirt
setblock ~30 ~124 ~83 dirt
setblock ~30 ~124 ~84 dirt
setblock ~30 ~124 ~85 dirt
setblock ~30 ~124 ~86 dirt
setblock ~30 ~124 ~87 dirt
setblock ~30 ~124 ~88 grass_block
setblock ~30 ~124 ~89 grass_block
setblock ~30 ~124 ~91 grass_block
setblock ~30 ~124 ~92 grass_block
setblock ~30 ~124 ~93 grass_block
setblock ~30 ~124 ~94 grass_block
setblock ~30 ~124 ~95 grass_block
setblock ~30 ~124 ~96 grass_block
setblock ~30 ~124 ~97 grass_block
setblock ~30 ~124 ~98 short_grass
setblock ~30 ~124 ~99 short_grass
setblock ~30 ~124 ~103 grass_block
setblock ~30 ~124 ~104 dirt
setblock ~30 ~124 ~105 dirt
setblock ~30 ~124 ~106 dirt
setblock ~30 ~124 ~107 dirt
setblock ~30 ~124 ~108 dirt
setblock ~30 ~124 ~109 dirt
setblock ~30 ~124 ~110 dirt
setblock ~30 ~124 ~111 dirt
setblock ~30 ~124 ~112 dirt
setblock ~30 ~124 ~113 dirt
setblock ~30 ~124 ~114 dirt
setblock ~30 ~124 ~115 dirt
setblock ~30 ~124 ~116 grass_block
setblock ~30 ~124 ~117 grass_block
setblock ~30 ~124 ~119 short_grass
setblock ~30 ~125 ~73 dirt
setblock ~30 ~125 ~74 dirt
setblock ~30 ~125 ~75 dirt
setblock ~30 ~125 ~76 dirt
setblock ~30 ~125 ~77 dirt
setblock ~30 ~125 ~78 dirt
setblock ~30 ~125 ~79 dirt
setblock ~30 ~125 ~80 dirt
setblock ~30 ~125 ~81 dirt
setblock ~30 ~125 ~82 dirt
setblock ~30 ~125 ~83 dirt
setblock ~30 ~125 ~84 dirt
setblock ~30 ~125 ~85 grass_block
setblock ~30 ~125 ~86 grass_block
setblock ~30 ~125 ~87 grass_block
setblock ~30 ~125 ~89 short_grass
setblock ~30 ~125 ~94 poppy
setblock ~30 ~125 ~95 fern
setblock ~30 ~125 ~97 short_grass
setblock ~30 ~125 ~104 grass_block
setblock ~30 ~125 ~105 grass_block
setblock ~30 ~125 ~106 dirt
setblock ~30 ~125 ~107 dirt
setblock ~30 ~125 ~108 dirt
setblock ~30 ~125 ~109 dirt
setblock ~30 ~125 ~110 dirt
setblock ~30 ~125 ~111 dirt
setblock ~30 ~125 ~112 dirt
setblock ~30 ~125 ~113 dirt
setblock ~30 ~125 ~114 dirt
setblock ~30 ~125 ~115 grass_block
setblock ~30 ~126 ~73 dirt
setblock ~30 ~126 ~74 dirt
setblock ~30 ~126 ~75 dirt
setblock ~30 ~126 ~76 dirt
setblock ~30 ~126 ~77 dirt
setblock ~30 ~126 ~78 dirt
setblock ~30 ~126 ~79 dirt
setblock ~30 ~126 ~80 dirt
setblock ~30 ~126 ~81 dirt
setblock ~30 ~126 ~82 dirt
setblock ~30 ~126 ~83 grass_block
setblock ~30 ~126 ~84 grass_block
setblock ~30 ~126 ~85 short_grass
setblock ~30 ~126 ~86 poppy
setblock ~30 ~126 ~105 fern
setblock ~30 ~126 ~106 grass_block
setblock ~30 ~126 ~107 dirt
setblock ~30 ~126 ~108 dirt
setblock ~30 ~126 ~109 dirt
setblock ~30 ~126 ~110 dirt
setblock ~30 ~126 ~111 dirt
setblock ~30 ~126 ~112 dirt
setblock ~30 ~126 ~113 grass_block
setblock ~30 ~126 ~114 grass_block
setblock ~30 ~126 ~115 poppy
setblock ~30 ~127 ~73 grass_block
setblock ~30 ~127 ~74 grass_block
setblock ~30 ~127 ~75 grass_block
setblock ~30 ~127 ~76 grass_block
setblock ~30 ~127 ~77 dirt
setblock ~30 ~127 ~78 dirt
setblock ~30 ~127 ~79 dirt
setblock ~30 ~127 ~80 dirt
setblock ~30 ~127 ~81 grass_block
setblock ~30 ~127 ~82 grass_block
setblock ~30 ~127 ~83 poppy
setblock ~30 ~127 ~107 grass_block
setblock ~30 ~127 ~108 dirt
setblock ~30 ~127 ~109 dirt
setblock ~30 ~127 ~110 dirt
setblock ~30 ~127 ~111 dirt
setblock ~30 ~127 ~112 dirt
setblock ~30 ~128 ~75 short_grass
setblock ~30 ~128 ~76 poppy
setblock ~30 ~128 ~77 grass_block
setblock ~30 ~128 ~78 grass_block
setblock ~30 ~128 ~79 grass_block
setblock ~30 ~128 ~80 grass_block
setblock ~30 ~128 ~81 fern
setblock ~30 ~128 ~107 fern
setblock ~30 ~128 ~108 grass_block
setblock ~30 ~128 ~109 dirt
setblock ~30 ~128 ~110 dirt
setblock ~30 ~128 ~111 dirt
setblock ~30 ~128 ~112 grass_block
setblock ~30 ~129 ~80 short_grass
setblock ~30 ~129 ~109 dirt
setblock ~30 ~129 ~110 dirt
setblock ~30 ~129 ~111 grass_block
setblock ~30 ~130 ~109 grass_block
setblock ~30 ~130 ~110 dirt
setblock ~30 ~131 ~109 short_grass
setblock ~30 ~131 ~110 grass_block
setblock ~31 ~110 ~101 dirt
setblock ~31 ~110 ~102 dirt
setblock ~31 ~110 ~110 dirt
setblock ~31 ~110 ~112 dirt
setblock ~31 ~111 ~100 dirt
setblock ~31 ~111 ~101 dirt
setblock ~31 ~111 ~102 dirt
setblock ~31 ~111 ~103 dirt
setblock ~31 ~111 ~105 dirt
setblock ~31 ~111 ~107 dirt
setblock ~31 ~111 ~109 dirt
setblock ~31 ~111 ~110 dirt
setblock ~31 ~111 ~111 dirt
setblock ~31 ~111 ~112 dirt
setblock ~31 ~111 ~113 dirt
setblock ~31 ~111 ~114 dirt
setblock ~31 ~112 ~99 dirt
setblock ~31 ~112 ~100 dirt
setblock ~31 ~112 ~101 dirt
setblock ~31 ~112 ~102 dirt
setblock ~31 ~112 ~103 dirt
setblock ~31 ~112 ~104 dirt
setblock ~31 ~112 ~105 dirt
setblock ~31 ~112 ~106 dirt
setblock ~31 ~112 ~107 dirt
setblock ~31 ~112 ~108 dirt
setblock ~31 ~112 ~109 dirt
setblock ~31 ~112 ~110 dirt
setblock ~31 ~112 ~111 dirt
setblock ~31 ~112 ~112 dirt
setblock ~31 ~112 ~113 dirt
setblock ~31 ~112 ~114 dirt
setblock ~31 ~113 ~98 dirt
setblock ~31 ~113 ~99 dirt
setblock ~31 ~113 ~100 dirt
setblock ~31 ~113 ~101 dirt
setblock ~31 ~113 ~102 dirt
setblock ~31 ~113 ~103 dirt
setblock ~31 ~113 ~104 dirt
setblock ~31 ~113 ~105 dirt
setblock ~31 ~113 ~106 dirt
setblock ~31 ~113 ~107 dirt
setblock ~31 ~113 ~108 dirt
setblock ~31 ~113 ~109 dirt
setblock ~31 ~113 ~110 dirt
setblock ~31 ~113 ~111 dirt
setblock ~31 ~113 ~112 dirt
setblock ~31 ~113 ~113 dirt
setblock ~31 ~113 ~114 dirt
setblock ~31 ~113 ~115 dirt
setblock ~31 ~113 ~116 dirt
setblock ~31 ~114 ~95 dirt
setblock ~31 ~114 ~97 dirt
setblock ~31 ~114 ~98 dirt
setblock ~31 ~114 ~99 dirt
setblock ~31 ~114 ~100 dirt
setblock ~31 ~114 ~101 dirt
setblock ~31 ~114 ~102 dirt
setblock ~31 ~114 ~103 dirt
setblock ~31 ~114 ~104 dirt
setblock ~31 ~114 ~105 dirt
setblock ~31 ~114 ~106 dirt
setblock ~31 ~114 ~107 dirt
setblock ~31 ~114 ~108 dirt
setblock ~31 ~114 ~109 dirt
setblock ~31 ~114 ~110 dirt
setblock ~31 ~114 ~111 dirt
setblock ~31 ~114 ~112 dirt
setblock ~31 ~114 ~113 dirt
setblock ~31 ~114 ~114 dirt
setblock ~31 ~114 ~115 dirt
setblock ~31 ~114 ~116 dirt
setblock ~31 ~114 ~117 dirt
setblock ~31 ~115 ~76 dirt
setblock ~31 ~115 ~79 dirt
setblock ~31 ~115 ~86 dirt
setblock ~31 ~115 ~95 dirt
setblock ~31 ~115 ~96 dirt
setblock ~31 ~115 ~97 dirt
setblock ~31 ~115 ~98 dirt
setblock ~31 ~115 ~99 dirt
setblock ~31 ~115 ~100 dirt
setblock ~31 ~115 ~101 dirt
setblock ~31 ~115 ~102 dirt
setblock ~31 ~115 ~103 dirt
setblock ~31 ~115 ~104 dirt
setblock ~31 ~115 ~105 dirt
setblock ~31 ~115 ~106 dirt
setblock ~31 ~115 ~107 dirt
setblock ~31 ~115 ~108 dirt
setblock ~31 ~115 ~109 dirt
setblock ~31 ~115 ~110 dirt
setblock ~31 ~115 ~111 dirt
setblock ~31 ~115 ~112 dirt
setblock ~31 ~115 ~113 dirt
setblock ~31 ~115 ~114 dirt
setblock ~31 ~115 ~115 dirt
setblock ~31 ~115 ~116 dirt
setblock ~31 ~115 ~117 dirt
setblock ~31 ~115 ~118 dirt
setblock ~31 ~116 ~75 dirt
setblock ~31 ~116 ~76 dirt
setblock ~31 ~116 ~77 dirt
setblock ~31 ~116 ~78 dirt
setblock ~31 ~116 ~79 dirt
setblock ~31 ~116 ~80 dirt
setblock ~31 ~116 ~81 dirt
setblock ~31 ~116 ~85 dirt
setblock ~31 ~116 ~86 dirt
setblock ~31 ~116 ~91 dirt
setblock ~31 ~116 ~92 dirt
setblock ~31 ~116 ~94 dirt
setblock ~31 ~116 ~95 dirt
setblock ~31 ~116 ~96 dirt
setblock ~31 ~116 ~97 dirt
setblock ~31 ~116 ~98 dirt
setblock ~31 ~116 ~99 dirt
setblock ~31 ~116 ~100 dirt
setblock ~31 ~116 ~101 dirt
setblock ~31 ~116 ~102 dirt
setblock ~31 ~116 ~103 dirt
setblock ~31 ~116 ~104 dirt
setblock ~31 ~116 ~105 dirt
setblock ~31 ~116 ~106 dirt
setblock ~31 ~116 ~107 dirt
setblock ~31 ~116 ~108 dirt
setblock ~31 ~116 ~109 dirt
setblock ~31 ~116 ~110 dirt
setblock ~31 ~116 ~111 dirt
setblock ~31 ~116 ~112 dirt
setblock ~31 ~116 ~113 dirt
setblock ~31 ~116 ~114 dirt
setblock ~31 ~116 ~115 dirt
setblock ~31 ~116 ~116 dirt
setblock ~31 ~116 ~117 dirt
setblock ~31 ~116 ~118 dirt
setblock ~31 ~117 ~74 dirt
setblock ~31 ~117 ~75 dirt
setblock ~31 ~117 ~76 dirt
setblock ~31 ~117 ~77 dirt
setblock ~31 ~117 ~78 dirt
setblock ~31 ~117 ~79 dirt
setblock ~31 ~117 ~80 dirt
setblock ~31 ~117 ~81 dirt
setblock ~31 ~117 ~82 dirt
setblock ~31 ~117 ~83 dirt
setblock ~31 ~117 ~84 dirt
setblock ~31 ~117 ~85 dirt
setblock ~31 ~117 ~86 dirt
setblock ~31 ~117 ~90 dirt
setblock ~31 ~117 ~91 dirt
setblock ~31 ~117 ~92 dirt
setblock ~31 ~117 ~93 dirt
setblock ~31 ~117 ~94 dirt
setblock ~31 ~117 ~95 dirt
setblock ~31 ~117 ~96 dirt
setblock ~31 ~117 ~97 dirt
setblock ~31 ~117 ~98 dirt
setblock ~31 ~117 ~99 dirt
setblock ~31 ~117 ~100 dirt
setblock ~31 ~117 ~101 dirt
setblock ~31 ~117 ~102 dirt
setblock ~31 ~117 ~103 dirt
setblock ~31 ~117 ~104 dirt
setblock ~31 ~117 ~105 dirt
setblock ~31 ~117 ~106 dirt
setblock ~31 ~117 ~107 dirt
setblock ~31 ~117 ~108 dirt
setblock ~31 ~117 ~109 dirt
setblock ~31 ~117 ~110 dirt
setblock ~31 ~117 ~111 dirt
setblock ~31 ~117 ~112 dirt
setblock ~31 ~117 ~113 dirt
setblock ~31 ~117 ~114 dirt
setblock ~31 ~117 ~115 dirt
setblock ~31 ~117 ~116 dirt
setblock ~31 ~117 ~117 dirt
setblock ~31 ~117 ~118 dirt
setblock ~31 ~118 ~74 dirt
setblock ~31 ~118 ~75 dirt
setblock ~31 ~118 ~76 dirt
setblock ~31 ~118 ~77 dirt
setblock ~31 ~118 ~78 dirt
setblock ~31 ~118 ~79 dirt
setblock ~31 ~118 ~80 dirt
setblock ~31 ~118 ~81 dirt
setblock ~31 ~118 ~82 dirt
setblock ~31 ~118 ~83 dirt
setblock ~31 ~118 ~84 dirt
setblock ~31 ~118 ~85 dirt
setblock ~31 ~118 ~86 dirt
setblock ~31 ~118 ~87 dirt
setblock ~31 ~118 ~90 dirt
setblock ~31 ~118 ~91 dirt
setblock ~31 ~118 ~92 dirt
setblock ~31 ~118 ~93 dirt
setblock ~31 ~118 ~94 dirt
setblock ~31 ~118 ~95 dirt
setblock ~31 ~118 ~96 dirt
setblock ~31 ~118 ~97 dirt
setblock ~31 ~118 ~98 dirt
setblock ~31 ~118 ~99 dirt
setblock ~31 ~118 ~100 dirt
setblock ~31 ~118 ~101 dirt
setblock ~31 ~118 ~102 dirt
setblock ~31 ~118 ~103 dirt
setblock ~31 ~118 ~104 dirt
setblock ~31 ~118 ~105 dirt
setblock ~31 ~118 ~106 dirt
setblock ~31 ~118 ~107 dirt
setblock ~31 ~118 ~108 dirt
setblock ~31 ~118 ~109 dirt
setblock ~31 ~118 ~110 dirt
setblock ~31 ~118 ~111 dirt
setblock ~31 ~118 ~112 dirt
setblock ~31 ~118 ~113 dirt
setblock ~31 ~118 ~114 dirt
setblock ~31 ~118 ~115 dirt
setblock ~31 ~118 ~116 dirt
setblock ~31 ~118 ~117 dirt
setblock ~31 ~118 ~118 dirt
setblock ~31 ~119 ~73 dirt
setblock ~31 ~119 ~74 dirt
setblock ~31 ~119 ~75 dirt
setblock ~31 ~119 ~76 dirt
setblock ~31 ~119 ~77 dirt
setblock ~31 ~119 ~78 dirt
setblock ~31 ~119 ~79 dirt
setblock ~31 ~119 ~80 dirt
setblock ~31 ~119 ~81 dirt
setblock ~31 ~119 ~82 dirt
setblock ~31 ~119 ~83 dirt
setblock ~31 ~119 ~84 dirt
setblock ~31 ~119 ~85 dirt
setblock ~31 ~119 ~86 dirt
setblock ~31 ~119 ~87 dirt
setblock ~31 ~119 ~89 dirt
setblock ~31 ~119 ~90 dirt
setblock ~31 ~119 ~91 dirt
setblock ~31 ~119 ~92 dirt
setblock ~31 ~119 ~93 dirt
setblock ~31 ~119 ~94 dirt
setblock ~31 ~119 ~95 dirt
setblock ~31 ~119 ~96 dirt
setblock ~31 ~119 ~97 dirt
setblock ~31 ~119 ~98 dirt
setblock ~31 ~119 ~99 dirt
setblock ~31 ~119 ~100 dirt
setblock ~31 ~119 ~101 dirt
setblock ~31 ~119 ~102 dirt
setblock ~31 ~119 ~103 dirt
setblock ~31 ~119 ~104 dirt
setblock ~31 ~119 ~105 dirt
setblock ~31 ~119 ~106 dirt
setblock ~31 ~119 ~107 dirt
setblock ~31 ~119 ~108 dirt
setblock ~31 ~119 ~109 dirt
setblock ~31 ~119 ~110 dirt
setblock ~31 ~119 ~111 dirt
setblock ~31 ~119 ~112 dirt
setblock ~31 ~119 ~113 dirt
setblock ~31 ~119 ~114 dirt
setblock ~31 ~119 ~115 dirt
setblock ~31 ~119 ~116 dirt
setblock ~31 ~119 ~117 dirt
setblock ~31 ~119 ~118 dirt
setblock ~31 ~119 ~119 dirt
setblock ~31 ~120 ~73 dirt
setblock ~31 ~120 ~74 dirt
setblock ~31 ~120 ~75 dirt
setblock ~31 ~120 ~76 dirt
setblock ~31 ~120 ~77 dirt
setblock ~31 ~120 ~78 dirt
setblock ~31 ~120 ~79 dirt
setblock ~31 ~120 ~80 dirt
setblock ~31 ~120 ~81 dirt
setblock ~31 ~120 ~82 dirt
setblock ~31 ~120 ~83 dirt
setblock ~31 ~120 ~84 dirt
setblock ~31 ~120 ~85 dirt
setblock ~31 ~120 ~86 dirt
setblock ~31 ~120 ~87 dirt
setblock ~31 ~120 ~88 dirt
setblock ~31 ~120 ~89 dirt
setblock ~31 ~120 ~90 dirt
setblock ~31 ~120 ~91 dirt
setblock ~31 ~120 ~92 dirt
setblock ~31 ~120 ~93 dirt
setblock ~31 ~120 ~94 dirt
setblock ~31 ~120 ~95 dirt
setblock ~31 ~120 ~96 dirt
setblock ~31 ~120 ~97 dirt
setblock ~31 ~120 ~98 dirt
setblock ~31 ~120 ~99 dirt
setblock ~31 ~120 ~100 dirt
setblock ~31 ~120 ~101 dirt
setblock ~31 ~120 ~102 dirt
setblock ~31 ~120 ~103 dirt
setblock ~31 ~120 ~104 dirt
setblock ~31 ~120 ~105 dirt
setblock ~31 ~120 ~106 dirt
setblock ~31 ~120 ~107 dirt
setblock ~31 ~120 ~108 dirt
setblock ~31 ~120 ~109 dirt
setblock ~31 ~120 ~110 dirt
setblock ~31 ~120 ~111 dirt
setblock ~31 ~120 ~112 dirt
setblock ~31 ~120 ~113 dirt
setblock ~31 ~120 ~114 dirt
setblock ~31 ~120 ~115 dirt
setblock ~31 ~120 ~116 dirt
setblock ~31 ~120 ~117 dirt
setblock ~31 ~120 ~118 dirt
setblock ~31 ~120 ~119 dirt
setblock ~31 ~121 ~72 dirt
setblock ~31 ~121 ~73 dirt
setblock ~31 ~121 ~74 dirt
setblock ~31 ~121 ~75 dirt
setblock ~31 ~121 ~76 dirt
setblock ~31 ~121 ~77 dirt
setblock ~31 ~121 ~78 dirt
setblock ~31 ~121 ~79 dirt
setblock ~31 ~121 ~80 dirt
setblock ~31 ~121 ~81 dirt
setblock ~31 ~121 ~82 dirt
setblock ~31 ~121 ~83 dirt
setblock ~31 ~121 ~84 dirt
setblock ~31 ~121 ~85 dirt
setblock ~31 ~121 ~86 dirt
setblock ~31 ~121 ~87 dirt
setblock ~31 ~121 ~88 dirt
setblock ~31 ~121 ~89 dirt
setblock ~31 ~121 ~90 dirt
setblock ~31 ~121 ~91 dirt
setblock ~31 ~121 ~92 dirt
setblock ~31 ~121 ~93 dirt
setblock ~31 ~121 ~94 dirt
setblock ~31 ~121 ~95 dirt
setblock ~31 ~121 ~96 dirt
setblock ~31 ~121 ~97 dirt
setblock ~31 ~121 ~98 dirt
setblock ~31 ~121 ~99 dirt
setblock ~31 ~121 ~100 dirt
setblock ~31 ~121 ~101 dirt
setblock ~31 ~121 ~102 dirt
setblock ~31 ~121 ~103 dirt
setblock ~31 ~121 ~104 dirt
setblock ~31 ~121 ~105 dirt
setblock ~31 ~121 ~106 dirt
setblock ~31 ~121 ~107 dirt
setblock ~31 ~121 ~108 dirt
setblock ~31 ~121 ~109 dirt
setblock ~31 ~121 ~110 dirt
setblock ~31 ~121 ~111 dirt
setblock ~31 ~121 ~112 dirt
setblock ~31 ~121 ~113 dirt
setblock ~31 ~121 ~114 dirt
setblock ~31 ~121 ~115 dirt
setblock ~31 ~121 ~116 dirt
setblock ~31 ~121 ~117 dirt
setblock ~31 ~121 ~118 dirt
setblock ~31 ~121 ~119 dirt
setblock ~31 ~121 ~120 dirt
setblock ~31 ~122 ~72 dirt
setblock ~31 ~122 ~73 dirt
setblock ~31 ~122 ~74 dirt
setblock ~31 ~122 ~75 dirt
setblock ~31 ~122 ~76 dirt
setblock ~31 ~122 ~77 dirt
setblock ~31 ~122 ~78 dirt
setblock ~31 ~122 ~79 dirt
setblock ~31 ~122 ~80 dirt
setblock ~31 ~122 ~81 dirt
setblock ~31 ~122 ~82 dirt
setblock ~31 ~122 ~83 dirt
setblock ~31 ~122 ~84 dirt
setblock ~31 ~122 ~85 dirt
setblock ~31 ~122 ~86 dirt
setblock ~31 ~122 ~87 dirt
setblock ~31 ~122 ~88 dirt
setblock ~31 ~122 ~89 dirt
setblock ~31 ~122 ~90 dirt
setblock ~31 ~122 ~91 dirt
setblock ~31 ~122 ~92 dirt
setblock ~31 ~122 ~93 dirt
setblock ~31 ~122 ~94 dirt
setblock ~31 ~122 ~95 dirt
setblock ~31 ~122 ~96 dirt
setblock ~31 ~122 ~97 dirt
setblock ~31 ~122 ~98 dirt
setblock ~31 ~122 ~99 dirt
setblock ~31 ~122 ~100 dirt
setblock ~31 ~122 ~101 dirt
setblock ~31 ~122 ~102 dirt
setblock ~31 ~122 ~103 dirt
setblock ~31 ~122 ~104 dirt
setblock ~31 ~122 ~105 dirt
setblock ~31 ~122 ~106 dirt
setblock ~31 ~122 ~107 dirt
setblock ~31 ~122 ~108 dirt
setblock ~31 ~122 ~109 dirt
setblock ~31 ~122 ~110 dirt
setblock ~31 ~122 ~111 dirt
setblock ~31 ~122 ~112 dirt
setblock ~31 ~122 ~113 dirt
setblock ~31 ~122 ~114 dirt
setblock ~31 ~122 ~115 dirt
setblock ~31 ~122 ~116 dirt
setblock ~31 ~122 ~117 dirt
setblock ~31 ~122 ~118 dirt
setblock ~31 ~122 ~119 dirt
setblock ~31 ~122 ~120 dirt
setblock ~31 ~123 ~72 dirt
setblock ~31 ~123 ~73 dirt
setblock ~31 ~123 ~74 dirt
setblock ~31 ~123 ~75 dirt
setblock ~31 ~123 ~76 dirt
setblock ~31 ~123 ~77 dirt
setblock ~31 ~123 ~78 dirt
setblock ~31 ~123 ~79 dirt
setblock ~31 ~123 ~80 dirt
setblock ~31 ~123 ~81 dirt
setblock ~31 ~123 ~82 dirt
setblock ~31 ~123 ~83 dirt
setblock ~31 ~123 ~84 dirt
setblock ~31 ~123 ~85 dirt
setblock ~31 ~123 ~86 dirt
setblock ~31 ~123 ~87 dirt
setblock ~31 ~123 ~88 dirt
setblock ~31 ~123 ~89 dirt
setblock ~31 ~123 ~90 dirt
setblock ~31 ~123 ~91 dirt
setblock ~31 ~123 ~92 dirt
setblock ~31 ~123 ~93 dirt
setblock ~31 ~123 ~94 dirt
setblock ~31 ~123 ~95 dirt
setblock ~31 ~123 ~96 dirt
setblock ~31 ~123 ~97 dirt
setblock ~31 ~123 ~98 dirt
setblock ~31 ~123 ~99 grass_block
setblock ~31 ~123 ~100 grass_block
setblock ~31 ~123 ~101 grass_block
setblock ~31 ~123 ~102 dirt
setblock ~31 ~123 ~103 dirt
setblock ~31 ~123 ~104 dirt
setblock ~31 ~123 ~105 dirt
setblock ~31 ~123 ~106 dirt
setblock ~31 ~123 ~107 dirt
setblock ~31 ~123 ~108 dirt
setblock ~31 ~123 ~109 dirt
setblock ~31 ~123 ~110 dirt
setblock ~31 ~123 ~111 dirt
setblock ~31 ~123 ~112 dirt
setblock ~31 ~123 ~113 dirt
setblock ~31 ~123 ~114 dirt
setblock ~31 ~123 ~115 dirt
setblock ~31 ~123 ~116 dirt
setblock ~31 ~123 ~117 dirt
setblock ~31 ~123 ~118 grass_block
setblock ~31 ~123 ~119 grass_block
setblock ~31 ~123 ~120 grass_block
setblock ~31 ~124 ~72 dirt
setblock ~31 ~124 ~73 dirt
setblock ~31 ~124 ~74 dirt
setblock ~31 ~124 ~75 dirt
setblock ~31 ~124 ~76 dirt
setblock ~31 ~124 ~77 dirt
setblock ~31 ~124 ~78 dirt
setblock ~31 ~124 ~79 dirt
setblock ~31 ~124 ~80 dirt
setblock ~31 ~124 ~81 dirt
setblock ~31 ~124 ~82 dirt
setblock ~31 ~124 ~83 dirt
setblock ~31 ~124 ~84 dirt
setblock ~31 ~124 ~85 dirt
setblock ~31 ~124 ~86 dirt
setblock ~31 ~124 ~87 dirt
setblock ~31 ~124 ~88 dirt
setblock ~31 ~124 ~89 grass_block
setblock ~31 ~124 ~90 grass_block
setblock ~31 ~124 ~91 grass_block
setblock ~31 ~124 ~92 grass_block
setblock ~31 ~124 ~93 dirt
setblock ~31 ~124 ~94 dirt
setblock ~31 ~124 ~95 dirt
setblock ~31 ~124 ~96 grass_block
setblock ~31 ~124 ~97 grass_block
setblock ~31 ~124 ~98 grass_block
setblock ~31 ~124 ~100 poppy
setblock ~31 ~124 ~102 grass_block
setblock ~31 ~124 ~103 grass_block
setblock ~31 ~124 ~104 dirt
setblock ~31 ~124 ~105 dirt
setblock ~31 ~124 ~106 dirt
setblock ~31 ~124 ~107 dirt
setblock ~31 ~124 ~108 dirt
setblock ~31 ~124 ~109 dirt
setblock ~31 ~124 ~110 dirt
setblock ~31 ~124 ~111 dirt
setblock ~31 ~124 ~112 dirt
setblock ~31 ~124 ~113 dirt
setblock ~31 ~124 ~114 dirt
setblock ~31 ~124 ~115 dirt
setblock ~31 ~124 ~116 grass_block
setblock ~31 ~124 ~117 grass_block
setblock ~31 ~124 ~118 short_grass
setblock ~31 ~125 ~72 dirt
setblock ~31 ~125 ~73 dirt
setblock ~31 ~125 ~74 dirt
setblock ~31 ~125 ~75 dirt
setblock ~31 ~125 ~76 dirt
setblock ~31 ~125 ~77 dirt
setblock ~31 ~125 ~78 dirt
setblock ~31 ~125 ~79 dirt
setblock ~31 ~125 ~80 dirt
setblock ~31 ~125 ~81 dirt
setblock ~31 ~125 ~82 dirt
setblock ~31 ~125 ~83 dirt
setblock ~31 ~125 ~84 dirt
setblock ~31 ~125 ~85 dirt
setblock ~31 ~125 ~86 grass_block
setblock ~31 ~125 ~87 grass_block
setblock ~31 ~125 ~88 grass_block
setblock ~31 ~125 ~89 short_grass
setblock ~31 ~125 ~91 short_grass
setblock ~31 ~125 ~92 poppy
setblock ~31 ~125 ~93 grass_block
setblock ~31 ~125 ~94 grass_block
setblock ~31 ~125 ~95 grass_block
setblock ~31 ~125 ~102 short_grass
