setblock ~162 ~121 ~96 dirt
setblock ~162 ~121 ~97 dirt
setblock ~162 ~121 ~98 dirt
setblock ~162 ~121 ~99 dirt
setblock ~162 ~121 ~100 dirt
setblock ~162 ~121 ~101 dirt
setblock ~162 ~121 ~102 dirt
setblock ~162 ~121 ~103 dirt
setblock ~162 ~121 ~104 dirt
setblock ~162 ~121 ~105 dirt
setblock ~162 ~121 ~106 dirt
setblock ~162 ~121 ~107 dirt
setblock ~162 ~121 ~108 dirt
setblock ~162 ~121 ~109 dirt
setblock ~162 ~121 ~110 dirt
setblock ~162 ~121 ~111 dirt
setblock ~162 ~121 ~112 dirt
setblock ~162 ~121 ~113 dirt
setblock ~162 ~121 ~114 dirt
setblock ~162 ~121 ~115 dirt
setblock ~162 ~121 ~116 dirt
setblock ~162 ~121 ~117 dirt
setblock ~162 ~121 ~118 dirt
setblock ~162 ~121 ~119 dirt
setblock ~162 ~121 ~120 dirt
setblock ~162 ~121 ~121 dirt
setblock ~162 ~121 ~122 dirt
setblock ~162 ~121 ~123 dirt
setblock ~162 ~121 ~124 dirt
setblock ~162 ~121 ~125 dirt
setblock ~162 ~121 ~126 dirt
setblock ~162 ~121 ~127 dirt
setblock ~162 ~121 ~128 dirt
setblock ~162 ~121 ~129 dirt
setblock ~162 ~121 ~130 dirt
setblock ~162 ~121 ~131 dirt
setblock ~162 ~121 ~132 dirt
setblock ~162 ~121 ~133 dirt
setblock ~162 ~121 ~134 dirt
setblock ~162 ~121 ~135 dirt
setblock ~162 ~122 ~66 dirt
setblock ~162 ~122 ~71 dirt
setblock ~162 ~122 ~72 dirt
setblock ~162 ~122 ~73 dirt
setblock ~162 ~122 ~74 dirt
setblock ~162 ~122 ~75 dirt
setblock ~162 ~122 ~76 dirt
setblock ~162 ~122 ~77 dirt
setblock ~162 ~122 ~78 dirt
setblock ~162 ~122 ~79 dirt
setblock ~162 ~122 ~80 dirt
setblock ~162 ~122 ~81 dirt
setblock ~162 ~122 ~82 dirt
setblock ~162 ~122 ~83 dirt
setblock ~162 ~122 ~84 dirt
setblock ~162 ~122 ~85 dirt
setblock ~162 ~122 ~86 dirt
setblock ~162 ~122 ~87 dirt
setblock ~162 ~122 ~88 dirt
setblock ~162 ~122 ~89 dirt
setblock ~162 ~122 ~90 dirt
setblock ~162 ~122 ~91 dirt
setblock ~162 ~122 ~92 dirt
setblock ~162 ~122 ~93 dirt
setblock ~162 ~122 ~94 dirt
setblock ~162 ~122 ~95 dirt
setblock ~162 ~122 ~96 dirt
setblock ~162 ~122 ~97 dirt
setblock ~162 ~122 ~98 dirt
setblock ~162 ~122 ~99 dirt
setblock ~162 ~122 ~100 dirt
setblock ~162 ~122 ~101 dirt
setblock ~162 ~122 ~102 dirt
setblock ~162 ~122 ~103 dirt
setblock ~162 ~122 ~104 dirt
setblock ~162 ~122 ~105 dirt
setblock ~162 ~122 ~106 dirt
setblock ~162 ~122 ~107 dirt
setblock ~162 ~122 ~108 dirt
setblock ~162 ~122 ~109 dirt
setblock ~162 ~122 ~110 dirt
setblock ~162 ~122 ~111 dirt
setblock ~162 ~122 ~112 dirt
setblock ~162 ~122 ~113 dirt
setblock ~162 ~122 ~114 dirt
setblock ~162 ~122 ~115 dirt
setblock ~162 ~122 ~116 dirt
setblock ~162 ~122 ~117 dirt
setblock ~162 ~122 ~118 dirt
setblock ~162 ~122 ~119 dirt
setblock ~162 ~122 ~120 dirt
setblock ~162 ~122 ~121 dirt
setblock ~162 ~122 ~122 dirt
setblock ~162 ~122 ~123 dirt
setblock ~162 ~122 ~124 dirt
setblock ~162 ~122 ~125 dirt
setblock ~162 ~122 ~126 dirt
setblock ~162 ~122 ~127 dirt
setblock ~162 ~122 ~128 dirt
setblock ~162 ~122 ~129 dirt
setblock ~162 ~122 ~130 dirt
setblock ~162 ~122 ~131 dirt
setblock ~162 ~122 ~132 dirt
setblock ~162 ~122 ~133 dirt
setblock ~162 ~122 ~134 dirt
setblock ~162 ~122 ~135 dirt
setblock ~162 ~123 ~66 dirt
setblock ~162 ~123 ~71 dirt
setblock ~162 ~123 ~72 dirt
setblock ~162 ~123 ~73 dirt
setblock ~162 ~123 ~74 dirt
setblock ~162 ~123 ~75 dirt
setblock ~162 ~123 ~76 dirt
setblock ~162 ~123 ~77 dirt
setblock ~162 ~123 ~78 dirt
setblock ~162 ~123 ~79 dirt
setblock ~162 ~123 ~80 dirt
setblock ~162 ~123 ~81 dirt
setblock ~162 ~123 ~82 dirt
setblock ~162 ~123 ~83 dirt
setblock ~162 ~123 ~84 dirt
setblock ~162 ~123 ~85 dirt
setblock ~162 ~123 ~86 dirt
setblock ~162 ~123 ~87 grass_block
setblock ~162 ~123 ~88 grass_block
setblock ~162 ~123 ~89 grass_block
setblock ~162 ~123 ~90 grass_block
setblock ~162 ~123 ~91 grass_block
setblock ~162 ~123 ~92 grass_block
setblock ~162 ~123 ~93 grass_block
setblock ~162 ~123 ~94 grass_block
setblock ~162 ~123 ~95 grass_block
setblock ~162 ~123 ~96 grass_block
setblock ~162 ~123 ~97 grass_block
setblock ~162 ~123 ~98 grass_block
setblock ~162 ~123 ~99 grass_block
setblock ~162 ~123 ~100 grass_block
setblock ~162 ~123 ~101 dirt
setblock ~162 ~123 ~102 dirt
setblock ~162 ~123 ~103 dirt
setblock ~162 ~123 ~104 dirt
setblock ~162 ~123 ~105 dirt
setblock ~162 ~123 ~106 dirt
setblock ~162 ~123 ~107 dirt
setblock ~162 ~123 ~108 dirt
setblock ~162 ~123 ~109 dirt
setblock ~162 ~123 ~110 dirt
setblock ~162 ~123 ~111 dirt
setblock ~162 ~123 ~112 dirt
setblock ~162 ~123 ~113 dirt
setblock ~162 ~123 ~114 dirt
setblock ~162 ~123 ~115 dirt
setblock ~162 ~123 ~116 dirt
setblock ~162 ~123 ~117 dirt
setblock ~162 ~123 ~118 dirt
setblock ~162 ~123 ~119 dirt
setblock ~162 ~123 ~120 dirt
setblock ~162 ~123 ~121 dirt
setblock ~162 ~123 ~122 dirt
setblock ~162 ~123 ~123 dirt
setblock ~162 ~123 ~124 dirt
setblock ~162 ~123 ~125 dirt
setblock ~162 ~123 ~126 dirt
setblock ~162 ~123 ~127 dirt
setblock ~162 ~123 ~128 dirt
setblock ~162 ~123 ~129 grass_block
setblock ~162 ~123 ~130 grass_block
setblock ~162 ~123 ~131 grass_block
setblock ~162 ~123 ~132 grass_block
setblock ~162 ~123 ~133 grass_block
setblock ~162 ~123 ~134 grass_block
setblock ~162 ~123 ~135 grass_block
setblock ~162 ~124 ~66 dirt
setblock ~162 ~124 ~71 dirt
setblock ~162 ~124 ~72 dirt
setblock ~162 ~124 ~73 dirt
setblock ~162 ~124 ~74 dirt
setblock ~162 ~124 ~75 dirt
setblock ~162 ~124 ~76 dirt
setblock ~162 ~124 ~77 dirt
setblock ~162 ~124 ~78 dirt
setblock ~162 ~124 ~79 dirt
setblock ~162 ~124 ~80 grass_block
setblock ~162 ~124 ~81 grass_block
setblock ~162 ~124 ~82 grass_block
setblock ~162 ~124 ~83 grass_block
setblock ~162 ~124 ~84 grass_block
setblock ~162 ~124 ~85 grass_block
setblock ~162 ~124 ~86 grass_block
setblock ~162 ~124 ~88 short_grass
setblock ~162 ~124 ~92 short_grass
setblock ~162 ~124 ~93 short_grass
setblock ~162 ~124 ~96 poppy
setblock ~162 ~124 ~97 short_grass
setblock ~162 ~124 ~99 short_grass
setblock ~162 ~124 ~101 grass_block
setblock ~162 ~124 ~102 grass_block
setblock ~162 ~124 ~103 dirt
setblock ~162 ~124 ~104 dirt
setblock ~162 ~124 ~105 dirt
setblock ~162 ~124 ~106 dirt
setblock ~162 ~124 ~107 dirt
setblock ~162 ~124 ~108 dirt
setblock ~162 ~124 ~109 dirt
setblock ~162 ~124 ~110 dirt
setblock ~162 ~124 ~111 dirt
setblock ~162 ~124 ~112 dirt
setblock ~162 ~124 ~113 dirt
setblock ~162 ~124 ~114 dirt
setblock ~162 ~124 ~115 dirt
setblock ~162 ~124 ~116 dirt
setblock ~162 ~124 ~117 dirt
setblock ~162 ~124 ~118 dirt
setblock ~162 ~124 ~119 grass_block
setblock ~162 ~124 ~120 grass_block
setblock ~162 ~124 ~121 grass_block
setblock ~162 ~124 ~122 grass_block
setblock ~162 ~124 ~123 grass_block
setblock ~162 ~124 ~124 grass_block
setblock ~162 ~124 ~125 grass_block
setblock ~162 ~124 ~126 grass_block
setblock ~162 ~124 ~127 grass_block
setblock ~162 ~124 ~128 grass_block
setblock ~162 ~124 ~129 short_grass
setblock ~162 ~125 ~66 dirt
setblock ~162 ~125 ~71 dirt
setblock ~162 ~125 ~72 dirt
setblock ~162 ~125 ~73 dirt
setblock ~162 ~125 ~74 dirt
setblock ~162 ~125 ~75 dirt
setblock ~162 ~125 ~76 dirt
setblock ~162 ~125 ~77 grass_block
setblock ~162 ~125 ~78 grass_block
setblock ~162 ~125 ~79 grass_block
setblock ~162 ~125 ~81 short_grass
setblock ~162 ~125 ~86 short_grass
setblock ~162 ~125 ~103 grass_block
setblock ~162 ~125 ~104 grass_block
setblock ~162 ~125 ~105 grass_block
setblock ~162 ~125 ~106 grass_block
setblock ~162 ~125 ~107 dirt
setblock ~162 ~125 ~108 dirt
setblock ~162 ~125 ~109 dirt
setblock ~162 ~125 ~110 dirt
setblock ~162 ~125 ~111 dirt
setblock ~162 ~125 ~112 dirt
setblock ~162 ~125 ~113 dirt
setblock ~162 ~125 ~114 dirt
setblock ~162 ~125 ~115 dirt
setblock ~162 ~125 ~116 grass_block
setblock ~162 ~125 ~117 grass_block
setblock ~162 ~125 ~118 grass_block
setblock ~162 ~125 ~120 short_grass
setblock ~162 ~125 ~121 short_grass
setblock ~162 ~126 ~66 dirt
setblock ~162 ~126 ~71 dirt
setblock ~162 ~126 ~72 dirt
setblock ~162 ~126 ~73 dirt
setblock ~162 ~126 ~74 dirt
setblock ~162 ~126 ~75 grass_block
setblock ~162 ~126 ~76 grass_block
setblock ~162 ~126 ~78 short_grass
setblock ~162 ~126 ~104 short_grass
setblock ~162 ~126 ~105 short_grass
setblock ~162 ~126 ~107 grass_block
setblock ~162 ~126 ~108 grass_block
setblock ~162 ~126 ~109 grass_block
setblock ~162 ~126 ~110 grass_block
setblock ~162 ~126 ~111 grass_block
setblock ~162 ~126 ~112 grass_block
setblock ~162 ~126 ~113 grass_block
setblock ~162 ~126 ~114 grass_block
setblock ~162 ~126 ~115 grass_block
setblock ~162 ~126 ~117 short_grass
setblock ~162 ~126 ~118 short_grass
setblock ~162 ~127 ~66 grass_block
setblock ~162 ~127 ~71 dirt
setblock ~162 ~127 ~72 dirt
setblock ~162 ~127 ~73 grass_block
setblock ~162 ~127 ~74 grass_block
setblock ~162 ~127 ~75 short_grass
setblock ~162 ~127 ~76 fern
setblock ~162 ~127 ~109 fern
setblock ~162 ~127 ~112 short_grass
setblock ~162 ~127 ~114 short_grass
setblock ~162 ~128 ~71 grass_block
setblock ~162 ~128 ~72 grass_block
setblock ~162 ~128 ~74 short_grass
setblock ~162 ~129 ~71 short_grass
setblock ~163 ~102 ~83 dirt
setblock ~163 ~103 ~82 dirt
setblock ~163 ~103 ~83 dirt
setblock ~163 ~103 ~84 dirt
setblock ~163 ~104 ~82 dirt
setblock ~163 ~104 ~83 dirt
setblock ~163 ~104 ~84 dirt
setblock ~163 ~104 ~85 dirt
setblock ~163 ~104 ~86 dirt
setblock ~163 ~105 ~80 dirt
setblock ~163 ~105 ~81 dirt
setblock ~163 ~105 ~82 dirt
setblock ~163 ~105 ~83 dirt
setblock ~163 ~105 ~84 dirt
setblock ~163 ~105 ~85 dirt
setblock ~163 ~105 ~86 dirt
setblock ~163 ~105 ~100 dirt
setblock ~163 ~106 ~79 dirt
setblock ~163 ~106 ~80 dirt
setblock ~163 ~106 ~81 dirt
setblock ~163 ~106 ~82 dirt
setblock ~163 ~106 ~83 dirt
setblock ~163 ~106 ~84 dirt
setblock ~163 ~106 ~85 dirt
setblock ~163 ~106 ~86 dirt
setblock ~163 ~106 ~87 dirt
setblock ~163 ~106 ~99 dirt
setblock ~163 ~106 ~100 dirt
setblock ~163 ~106 ~101 dirt
setblock ~163 ~106 ~104 dirt
setblock ~163 ~106 ~105 dirt
setblock ~163 ~107 ~78 dirt
setblock ~163 ~107 ~79 dirt
setblock ~163 ~107 ~80 dirt
setblock ~163 ~107 ~81 dirt
setblock ~163 ~107 ~82 dirt
setblock ~163 ~107 ~83 dirt
setblock ~163 ~107 ~84 dirt
setblock ~163 ~107 ~85 dirt
setblock ~163 ~107 ~86 dirt
setblock ~163 ~107 ~87 dirt
setblock ~163 ~107 ~88 dirt
setblock ~163 ~107 ~98 dirt
setblock ~163 ~107 ~99 dirt
setblock ~163 ~107 ~100 dirt
setblock ~163 ~107 ~101 dirt
setblock ~163 ~107 ~104 dirt
setblock ~163 ~107 ~105 dirt
setblock ~163 ~108 ~78 dirt
setblock ~163 ~108 ~79 dirt
setblock ~163 ~108 ~80 dirt
setblock ~163 ~108 ~81 dirt
setblock ~163 ~108 ~82 dirt
setblock ~163 ~108 ~83 dirt
setblock ~163 ~108 ~84 dirt
setblock ~163 ~108 ~85 dirt
setblock ~163 ~108 ~86 dirt
setblock ~163 ~108 ~87 dirt
setblock ~163 ~108 ~88 dirt
setblock ~163 ~108 ~89 dirt
setblock ~163 ~108 ~98 dirt
setblock ~163 ~108 ~99 dirt
setblock ~163 ~108 ~100 dirt
setblock ~163 ~108 ~101 dirt
setblock ~163 ~108 ~104 dirt
setblock ~163 ~108 ~105 dirt
setblock ~163 ~108 ~106 dirt
setblock ~163 ~109 ~78 dirt
setblock ~163 ~109 ~79 dirt
setblock ~163 ~109 ~80 dirt
setblock ~163 ~109 ~81 dirt
setblock ~163 ~109 ~82 dirt
setblock ~163 ~109 ~83 dirt
setblock ~163 ~109 ~84 dirt
setblock ~163 ~109 ~85 dirt
setblock ~163 ~109 ~86 dirt
setblock ~163 ~109 ~87 dirt
setblock ~163 ~109 ~88 dirt
setblock ~163 ~109 ~89 dirt
setblock ~163 ~109 ~90 dirt
setblock ~163 ~109 ~98 dirt
setblock ~163 ~109 ~99 dirt
setblock ~163 ~109 ~100 dirt
setblock ~163 ~109 ~101 dirt
setblock ~163 ~109 ~103 dirt
setblock ~163 ~109 ~104 dirt
setblock ~163 ~109 ~105 dirt
setblock ~163 ~109 ~106 dirt
setblock ~163 ~110 ~77 dirt
setblock ~163 ~110 ~78 dirt
setblock ~163 ~110 ~79 dirt
setblock ~163 ~110 ~80 dirt
setblock ~163 ~110 ~81 dirt
setblock ~163 ~110 ~82 dirt
setblock ~163 ~110 ~83 dirt
setblock ~163 ~110 ~84 dirt
setblock ~163 ~110 ~85 dirt
setblock ~163 ~110 ~86 dirt
setblock ~163 ~110 ~87 dirt
setblock ~163 ~110 ~88 dirt
setblock ~163 ~110 ~89 dirt
setblock ~163 ~110 ~90 dirt
setblock ~163 ~110 ~91 dirt
setblock ~163 ~110 ~97 dirt
setblock ~163 ~110 ~98 dirt
setblock ~163 ~110 ~99 dirt
setblock ~163 ~110 ~100 dirt
setblock ~163 ~110 ~101 dirt
setblock ~163 ~110 ~102 dirt
setblock ~163 ~110 ~103 dirt
setblock ~163 ~110 ~104 dirt
setblock ~163 ~110 ~105 dirt
setblock ~163 ~110 ~106 dirt
setblock ~163 ~110 ~107 dirt
setblock ~163 ~111 ~76 dirt
setblock ~163 ~111 ~77 dirt
setblock ~163 ~111 ~78 dirt
setblock ~163 ~111 ~79 dirt
setblock ~163 ~111 ~80 dirt
setblock ~163 ~111 ~81 dirt
setblock ~163 ~111 ~82 dirt
setblock ~163 ~111 ~83 dirt
setblock ~163 ~111 ~84 dirt
setblock ~163 ~111 ~85 dirt
setblock ~163 ~111 ~86 dirt
setblock ~163 ~111 ~87 dirt
setblock ~163 ~111 ~88 dirt
setblock ~163 ~111 ~89 dirt
setblock ~163 ~111 ~90 dirt
setblock ~163 ~111 ~91 dirt
setblock ~163 ~111 ~96 dirt
setblock ~163 ~111 ~97 dirt
setblock ~163 ~111 ~98 dirt
setblock ~163 ~111 ~99 dirt
setblock ~163 ~111 ~100 dirt
setblock ~163 ~111 ~101 dirt
setblock ~163 ~111 ~102 dirt
setblock ~163 ~111 ~103 dirt
setblock ~163 ~111 ~104 dirt
setblock ~163 ~111 ~105 dirt
setblock ~163 ~111 ~106 dirt
setblock ~163 ~111 ~107 dirt
setblock ~163 ~111 ~108 dirt
setblock ~163 ~111 ~123 dirt
setblock ~163 ~112 ~76 dirt
setblock ~163 ~112 ~77 dirt
setblock ~163 ~112 ~78 dirt
setblock ~163 ~112 ~79 dirt
setblock ~163 ~112 ~80 dirt
setblock ~163 ~112 ~81 dirt
setblock ~163 ~112 ~82 dirt
setblock ~163 ~112 ~83 dirt
setblock ~163 ~112 ~84 dirt
setblock ~163 ~112 ~85 dirt
setblock ~163 ~112 ~86 dirt
setblock ~163 ~112 ~87 dirt
setblock ~163 ~112 ~88 dirt
setblock ~163 ~112 ~89 dirt
setblock ~163 ~112 ~90 dirt
setblock ~163 ~112 ~91 dirt
setblock ~163 ~112 ~92 dirt
setblock ~163 ~112 ~96 dirt
setblock ~163 ~112 ~97 dirt
setblock ~163 ~112 ~98 dirt
setblock ~163 ~112 ~99 dirt
setblock ~163 ~112 ~100 dirt
setblock ~163 ~112 ~101 dirt
setblock ~163 ~112 ~102 dirt
setblock ~163 ~112 ~103 dirt
setblock ~163 ~112 ~104 dirt
setblock ~163 ~112 ~105 dirt
setblock ~163 ~112 ~106 dirt
setblock ~163 ~112 ~107 dirt
setblock ~163 ~112 ~108 dirt
setblock ~163 ~112 ~122 dirt
setblock ~163 ~112 ~123 dirt
setblock ~163 ~112 ~124 dirt
setblock ~163 ~113 ~76 dirt
setblock ~163 ~113 ~77 dirt
setblock ~163 ~113 ~78 dirt
setblock ~163 ~113 ~79 dirt
setblock ~163 ~113 ~80 dirt
setblock ~163 ~113 ~81 dirt
setblock ~163 ~113 ~82 dirt
setblock ~163 ~113 ~83 dirt
setblock ~163 ~113 ~84 dirt
setblock ~163 ~113 ~85 dirt
setblock ~163 ~113 ~86 dirt
setblock ~163 ~113 ~87 dirt
setblock ~163 ~113 ~88 dirt
setblock ~163 ~113 ~89 dirt
setblock ~163 ~113 ~90 dirt
setblock ~163 ~113 ~91 dirt
setblock ~163 ~113 ~92 dirt
setblock ~163 ~113 ~95 dirt
setblock ~163 ~113 ~96 dirt
setblock ~163 ~113 ~97 dirt
setblock ~163 ~113 ~98 dirt
setblock ~163 ~113 ~99 dirt
setblock ~163 ~113 ~100 dirt
setblock ~163 ~113 ~101 dirt
setblock ~163 ~113 ~102 dirt
setblock ~163 ~113 ~103 dirt
setblock ~163 ~113 ~104 dirt
setblock ~163 ~113 ~105 dirt
setblock ~163 ~113 ~106 dirt
setblock ~163 ~113 ~107 dirt
setblock ~163 ~113 ~108 dirt
setblock ~163 ~113 ~109 dirt
setblock ~163 ~113 ~121 dirt
setblock ~163 ~113 ~122 dirt
setblock ~163 ~113 ~123 dirt
setblock ~163 ~113 ~124 dirt
setblock ~163 ~113 ~125 dirt
setblock ~163 ~113 ~128 dirt
setblock ~163 ~114 ~76 dirt
setblock ~163 ~114 ~77 dirt
setblock ~163 ~114 ~78 dirt
setblock ~163 ~114 ~79 dirt
setblock ~163 ~114 ~80 dirt
setblock ~163 ~114 ~81 dirt
setblock ~163 ~114 ~82 dirt
setblock ~163 ~114 ~83 dirt
setblock ~163 ~114 ~84 dirt
setblock ~163 ~114 ~85 dirt
setblock ~163 ~114 ~86 dirt
setblock ~163 ~114 ~87 dirt
setblock ~163 ~114 ~88 dirt
setblock ~163 ~114 ~89 dirt
setblock ~163 ~114 ~90 dirt
setblock ~163 ~114 ~91 dirt
setblock ~163 ~114 ~92 dirt
setblock ~163 ~114 ~95 dirt
setblock ~163 ~114 ~96 dirt
setblock ~163 ~114 ~97 dirt
setblock ~163 ~114 ~98 dirt
setblock ~163 ~114 ~99 dirt
setblock ~163 ~114 ~100 dirt
setblock ~163 ~114 ~101 dirt
setblock ~163 ~114 ~102 dirt
setblock ~163 ~114 ~103 dirt
setblock ~163 ~114 ~104 dirt
setblock ~163 ~114 ~105 dirt
setblock ~163 ~114 ~106 dirt
setblock ~163 ~114 ~107 dirt
setblock ~163 ~114 ~108 dirt
setblock ~163 ~114 ~109 dirt
setblock ~163 ~114 ~110 dirt
setblock ~163 ~114 ~121 dirt
setblock ~163 ~114 ~122 dirt
setblock ~163 ~114 ~123 dirt
setblock ~163 ~114 ~124 dirt
setblock ~163 ~114 ~125 dirt
setblock ~163 ~114 ~126 dirt
setblock ~163 ~114 ~127 dirt
setblock ~163 ~114 ~128 dirt
setblock ~163 ~114 ~129 dirt
setblock ~163 ~115 ~75 dirt
setblock ~163 ~115 ~76 dirt
setblock ~163 ~115 ~77 dirt
setblock ~163 ~115 ~78 dirt
setblock ~163 ~115 ~79 dirt
setblock ~163 ~115 ~80 dirt
setblock ~163 ~115 ~81 dirt
setblock ~163 ~115 ~82 dirt
setblock ~163 ~115 ~83 dirt
setblock ~163 ~115 ~84 dirt
setblock ~163 ~115 ~85 dirt
setblock ~163 ~115 ~86 dirt
setblock ~163 ~115 ~87 dirt
setblock ~163 ~115 ~88 dirt
setblock ~163 ~115 ~89 dirt
setblock ~163 ~115 ~90 dirt
setblock ~163 ~115 ~91 dirt
setblock ~163 ~115 ~92 dirt
setblock ~163 ~115 ~93 dirt
setblock ~163 ~115 ~94 dirt
setblock ~163 ~115 ~95 dirt
setblock ~163 ~115 ~96 dirt
setblock ~163 ~115 ~97 dirt
setblock ~163 ~115 ~98 dirt
setblock ~163 ~115 ~99 dirt
setblock ~163 ~115 ~100 dirt
setblock ~163 ~115 ~101 dirt
setblock ~163 ~115 ~102 dirt
setblock ~163 ~115 ~103 dirt
setblock ~163 ~115 ~104 dirt
setblock ~163 ~115 ~105 dirt
setblock ~163 ~115 ~106 dirt
setblock ~163 ~115 ~107 dirt
setblock ~163 ~115 ~108 dirt
setblock ~163 ~115 ~109 dirt
setblock ~163 ~115 ~110 dirt
setblock ~163 ~115 ~117 dirt
setblock ~163 ~115 ~118 dirt
setblock ~163 ~115 ~120 dirt
setblock ~163 ~115 ~121 dirt
setblock ~163 ~115 ~122 dirt
setblock ~163 ~115 ~123 dirt
setblock ~163 ~115 ~124 dirt
setblock ~163 ~115 ~125 dirt
setblock ~163 ~115 ~126 dirt
setblock ~163 ~115 ~127 dirt
setblock ~163 ~115 ~128 dirt
setblock ~163 ~115 ~129 dirt
setblock ~163 ~115 ~130 dirt
setblock ~163 ~116 ~74 dirt
setblock ~163 ~116 ~75 dirt
setblock ~163 ~116 ~76 dirt
setblock ~163 ~116 ~77 dirt
setblock ~163 ~116 ~78 dirt
setblock ~163 ~116 ~79 dirt
setblock ~163 ~116 ~80 dirt
setblock ~163 ~116 ~81 dirt
setblock ~163 ~116 ~82 dirt
setblock ~163 ~116 ~83 dirt
setblock ~163 ~116 ~84 dirt
setblock ~163 ~116 ~85 dirt
setblock ~163 ~116 ~86 dirt
setblock ~163 ~116 ~87 dirt
setblock ~163 ~116 ~88 dirt
setblock ~163 ~116 ~89 dirt
setblock ~163 ~116 ~90 dirt
setblock ~163 ~116 ~91 dirt
setblock ~163 ~116 ~92 dirt
setblock ~163 ~116 ~93 dirt
setblock ~163 ~116 ~94 dirt
setblock ~163 ~116 ~95 dirt
setblock ~163 ~116 ~96 dirt
setblock ~163 ~116 ~97 dirt
setblock ~163 ~116 ~98 dirt
setblock ~163 ~116 ~99 dirt
setblock ~163 ~116 ~100 dirt
setblock ~163 ~116 ~101 dirt
setblock ~163 ~116 ~102 dirt
setblock ~163 ~116 ~103 dirt
setblock ~163 ~116 ~104 dirt
setblock ~163 ~116 ~105 dirt
setblock ~163 ~116 ~106 dirt
setblock ~163 ~116 ~107 dirt
setblock ~163 ~116 ~108 dirt
setblock ~163 ~116 ~109 dirt
setblock ~163 ~116 ~110 dirt
setblock ~163 ~116 ~111 dirt
setblock ~163 ~116 ~116 dirt
setblock ~163 ~116 ~117 dirt
setblock ~163 ~116 ~118 dirt
setblock ~163 ~116 ~120 dirt
setblock ~163 ~116 ~121 dirt
setblock ~163 ~116 ~122 dirt
setblock ~163 ~116 ~123 dirt
setblock ~163 ~116 ~124 dirt
setblock ~163 ~116 ~125 dirt
setblock ~163 ~116 ~126 dirt
setblock ~163 ~116 ~127 dirt
setblock ~163 ~116 ~128 dirt
setblock ~163 ~116 ~129 dirt
setblock ~163 ~116 ~130 dirt
setblock ~163 ~116 ~131 dirt
setblock ~163 ~117 ~73 dirt
setblock ~163 ~117 ~74 dirt
setblock ~163 ~117 ~75 dirt
setblock ~163 ~117 ~76 dirt
setblock ~163 ~117 ~77 dirt
setblock ~163 ~117 ~78 dirt
setblock ~163 ~117 ~79 dirt
setblock ~163 ~117 ~80 dirt
setblock ~163 ~117 ~81 dirt
setblock ~163 ~117 ~82 dirt
setblock ~163 ~117 ~83 dirt
setblock ~163 ~117 ~84 dirt
setblock ~163 ~117 ~85 dirt
setblock ~163 ~117 ~86 dirt
setblock ~163 ~117 ~87 dirt
setblock ~163 ~117 ~88 dirt
setblock ~163 ~117 ~89 dirt
setblock ~163 ~117 ~90 dirt
setblock ~163 ~117 ~91 dirt
setblock ~163 ~117 ~92 dirt
setblock ~163 ~117 ~93 dirt
setblock ~163 ~117 ~94 dirt
setblock ~163 ~117 ~95 dirt
setblock ~163 ~117 ~96 dirt
setblock ~163 ~117 ~97 dirt
setblock ~163 ~117 ~98 dirt
setblock ~163 ~117 ~99 dirt
setblock ~163 ~117 ~100 dirt
setblock ~163 ~117 ~101 dirt
setblock ~163 ~117 ~102 dirt
setblock ~163 ~117 ~103 dirt
setblock ~163 ~117 ~104 dirt
setblock ~163 ~117 ~105 dirt
setblock ~163 ~117 ~106 dirt
setblock ~163 ~117 ~107 dirt
setblock ~163 ~117 ~108 dirt
setblock ~163 ~117 ~109 dirt
setblock ~163 ~117 ~110 dirt
setblock ~163 ~117 ~111 dirt
setblock ~163 ~117 ~112 dirt
setblock ~163 ~117 ~116 dirt
setblock ~163 ~117 ~117 dirt
setblock ~163 ~117 ~118 dirt
setblock ~163 ~117 ~119 dirt
setblock ~163 ~117 ~120 dirt
setblock ~163 ~117 ~121 dirt
setblock ~163 ~117 ~122 dirt
setblock ~163 ~117 ~123 dirt
setblock ~163 ~117 ~124 dirt
setblock ~163 ~117 ~125 dirt
setblock ~163 ~117 ~126 dirt
setblock ~163 ~117 ~127 dirt
setblock ~163 ~117 ~128 dirt
setblock ~163 ~117 ~129 dirt
setblock ~163 ~117 ~130 dirt
setblock ~163 ~117 ~131 dirt
setblock ~163 ~118 ~73 dirt
setblock ~163 ~118 ~74 dirt
setblock ~163 ~118 ~75 dirt
setblock ~163 ~118 ~76 dirt
setblock ~163 ~118 ~77 dirt
setblock ~163 ~118 ~78 dirt
setblock ~163 ~118 ~79 dirt
setblock ~163 ~118 ~80 dirt
setblock ~163 ~118 ~81 dirt
setblock ~163 ~118 ~82 dirt
setblock ~163 ~118 ~83 dirt
setblock ~163 ~118 ~84 dirt
setblock ~163 ~118 ~85 dirt
setblock ~163 ~118 ~86 dirt
setblock ~163 ~118 ~87 dirt
setblock ~163 ~118 ~88 dirt
setblock ~163 ~118 ~89 dirt
setblock ~163 ~118 ~90 dirt
setblock ~163 ~118 ~91 dirt
setblock ~163 ~118 ~92 dirt
setblock ~163 ~118 ~93 dirt
setblock ~163 ~118 ~94 dirt
setblock ~163 ~118 ~95 dirt
setblock ~163 ~118 ~96 dirt
setblock ~163 ~118 ~97 dirt
setblock ~163 ~118 ~98 dirt
setblock ~163 ~118 ~99 dirt
setblock ~163 ~118 ~100 dirt
setblock ~163 ~118 ~101 dirt
setblock ~163 ~118 ~102 dirt
setblock ~163 ~118 ~103 dirt
setblock ~163 ~118 ~104 dirt
setblock ~163 ~118 ~105 dirt
setblock ~163 ~118 ~106 dirt
setblock ~163 ~118 ~107 dirt
setblock ~163 ~118 ~108 dirt
setblock ~163 ~118 ~109 dirt
setblock ~163 ~118 ~110 dirt
setblock ~163 ~118 ~111 dirt
setblock ~163 ~118 ~112 dirt
setblock ~163 ~118 ~113 dirt
setblock ~163 ~118 ~115 dirt
setblock ~163 ~118 ~116 dirt
setblock ~163 ~118 ~117 dirt
setblock ~163 ~118 ~118 dirt
setblock ~163 ~118 ~119 dirt
setblock ~163 ~118 ~120 dirt
setblock ~163 ~118 ~121 dirt
setblock ~163 ~118 ~122 dirt
setblock ~163 ~118 ~123 dirt
setblock ~163 ~118 ~124 dirt
setblock ~163 ~118 ~125 dirt
setblock ~163 ~118 ~126 dirt
setblock ~163 ~118 ~127 dirt
setblock ~163 ~118 ~128 dirt
setblock ~163 ~118 ~129 dirt
setblock ~163 ~118 ~130 dirt
setblock ~163 ~118 ~131 dirt
setblock ~163 ~119 ~73 dirt
setblock ~163 ~119 ~74 dirt
setblock ~163 ~119 ~75 dirt
setblock ~163 ~119 ~76 dirt
setblock ~163 ~119 ~77 dirt
setblock ~163 ~119 ~78 dirt
setblock ~163 ~119 ~79 dirt
setblock ~163 ~119 ~80 dirt
setblock ~163 ~119 ~81 dirt
setblock ~163 ~119 ~82 dirt
setblock ~163 ~119 ~83 dirt
setblock ~163 ~119 ~84 dirt
setblock ~163 ~119 ~85 dirt
setblock ~163 ~119 ~86 dirt
setblock ~163 ~119 ~87 dirt
setblock ~163 ~119 ~88 dirt
setblock ~163 ~119 ~89 dirt
setblock ~163 ~119 ~90 dirt
setblock ~163 ~119 ~91 dirt
setblock ~163 ~119 ~92 dirt
setblock ~163 ~119 ~93 dirt
setblock ~163 ~119 ~94 dirt
setblock ~163 ~119 ~95 dirt
setblock ~163 ~119 ~96 dirt
setblock ~163 ~119 ~97 dirt
setblock ~163 ~119 ~98 dirt
setblock ~163 ~119 ~99 dirt
setblock ~163 ~119 ~100 dirt
setblock ~163 ~119 ~101 dirt
setblock ~163 ~119 ~102 dirt
setblock ~163 ~119 ~103 dirt
setblock ~163 ~119 ~104 dirt
setblock ~163 ~119 ~105 dirt
setblock ~163 ~119 ~106 dirt
setblock ~163 ~119 ~107 dirt
setblock ~163 ~119 ~108 dirt
setblock ~163 ~119 ~109 dirt
setblock ~163 ~119 ~110 dirt
setblock ~163 ~119 ~111 dirt
setblock ~163 ~119 ~112 dirt
setblock ~163 ~119 ~113 dirt
setblock ~163 ~119 ~114 dirt
setblock ~163 ~119 ~115 dirt
setblock ~163 ~119 ~116 dirt
setblock ~163 ~119 ~117 dirt
setblock ~163 ~119 ~118 dirt
setblock ~163 ~119 ~119 dirt
setblock ~163 ~119 ~120 dirt
setblock ~163 ~119 ~121 dirt
setblock ~163 ~119 ~122 dirt
setblock ~163 ~119 ~123 dirt
setblock ~163 ~119 ~124 dirt
setblock ~163 ~119 ~125 dirt
setblock ~163 ~119 ~126 dirt
setblock ~163 ~119 ~127 dirt
setblock ~163 ~119 ~128 dirt
setblock ~163 ~119 ~129 dirt
setblock ~163 ~119 ~130 dirt
setblock ~163 ~119 ~131 dirt
setblock ~163 ~119 ~132 dirt
setblock ~163 ~120 ~72 dirt
setblock ~163 ~120 ~73 dirt
setblock ~163 ~120 ~74 dirt
setblock ~163 ~120 ~75 dirt
setblock ~163 ~120 ~76 dirt
setblock ~163 ~120 ~77 dirt
setblock ~163 ~120 ~78 dirt
setblock ~163 ~120 ~79 dirt
setblock ~163 ~120 ~80 dirt
setblock ~163 ~120 ~81 dirt
setblock ~163 ~120 ~82 dirt
setblock ~163 ~120 ~83 dirt
setblock ~163 ~120 ~84 dirt
setblock ~163 ~120 ~85 dirt
setblock ~163 ~120 ~86 dirt
setblock ~163 ~120 ~87 dirt
setblock ~163 ~120 ~88 dirt
setblock ~163 ~120 ~89 dirt
setblock ~163 ~120 ~90 dirt
setblock ~163 ~120 ~91 dirt
setblock ~163 ~120 ~92 dirt
setblock ~163 ~120 ~93 dirt
setblock ~163 ~120 ~94 dirt
setblock ~163 ~120 ~95 dirt
setblock ~163 ~120 ~96 dirt
setblock ~163 ~120 ~97 dirt
setblock ~163 ~120 ~98 dirt
setblock ~163 ~120 ~99 dirt
setblock ~163 ~120 ~100 dirt
setblock ~163 ~120 ~101 dirt
setblock ~163 ~120 ~102 dirt
setblock ~163 ~120 ~103 dirt
setblock ~163 ~120 ~104 dirt
setblock ~163 ~120 ~105 dirt
setblock ~163 ~120 ~106 dirt
setblock ~163 ~120 ~107 dirt
setblock ~163 ~120 ~108 dirt
setblock ~163 ~120 ~109 dirt
setblock ~163 ~120 ~110 dirt
setblock ~163 ~120 ~111 dirt
setblock ~163 ~120 ~112 dirt
setblock ~163 ~120 ~113 dirt
setblock ~163 ~120 ~114 dirt
setblock ~163 ~120 ~115 dirt
setblock ~163 ~120 ~116 dirt
setblock ~163 ~120 ~117 dirt
setblock ~163 ~120 ~118 dirt
setblock ~163 ~120 ~119 dirt
setblock ~163 ~120 ~120 dirt
setblock ~163 ~120 ~121 dirt
setblock ~163 ~120 ~122 dirt
setblock ~163 ~120 ~123 dirt
setblock ~163 ~120 ~124 dirt
setblock ~163 ~120 ~125 dirt
setblock ~163 ~120 ~126 dirt
setblock ~163 ~120 ~127 dirt
setblock ~163 ~120 ~128 dirt
setblock ~163 ~120 ~129 dirt
setblock ~163 ~120 ~130 dirt
setblock ~163 ~120 ~131 dirt
setblock ~163 ~120 ~132 dirt
setblock ~163 ~120 ~133 dirt
setblock ~163 ~121 ~71 dirt
setblock ~163 ~121 ~72 dirt
setblock ~163 ~121 ~73 dirt
setblock ~163 ~121 ~74 dirt
setblock ~163 ~121 ~75 dirt
setblock ~163 ~121 ~76 dirt
setblock ~163 ~121 ~77 dirt
setblock ~163 ~121 ~78 dirt
setblock ~163 ~121 ~79 dirt
setblock ~163 ~121 ~80 dirt
setblock ~163 ~121 ~81 dirt
setblock ~163 ~121 ~82 dirt
setblock ~163 ~121 ~83 dirt
setblock ~163 ~121 ~84 dirt
setblock ~163 ~121 ~85 dirt
setblock ~163 ~121 ~86 dirt
setblock ~163 ~121 ~87 dirt
setblock ~163 ~121 ~88 dirt
setblock ~163 ~121 ~89 dirt
setblock ~163 ~121 ~90 dirt
setblock ~163 ~121 ~91 dirt
setblock ~163 ~121 ~92 dirt
setblock ~163 ~121 ~93 dirt
setblock ~163 ~121 ~94 dirt
setblock ~163 ~121 ~95 dirt
setblock ~163 ~121 ~96 dirt
setblock ~163 ~121 ~97 dirt
setblock ~163 ~121 ~98 dirt
setblock ~163 ~121 ~99 dirt
setblock ~163 ~121 ~100 dirt
setblock ~163 ~121 ~101 dirt
setblock ~163 ~121 ~102 dirt
setblock ~163 ~121 ~103 dirt
setblock ~163 ~121 ~104 dirt
setblock ~163 ~121 ~105 dirt
setblock ~163 ~121 ~106 dirt
setblock ~163 ~121 ~107 dirt
setblock ~163 ~121 ~108 dirt
setblock ~163 ~121 ~109 dirt
setblock ~163 ~121 ~110 dirt
setblock ~163 ~121 ~111 dirt
setblock ~163 ~121 ~112 dirt
setblock ~163 ~121 ~113 dirt
setblock ~163 ~121 ~114 dirt
setblock ~163 ~121 ~115 dirt
setblock ~163 ~121 ~116 dirt
setblock ~163 ~121 ~117 dirt
setblock ~163 ~121 ~118 dirt
setblock ~163 ~121 ~119 dirt
setblock ~163 ~121 ~120 dirt
setblock ~163 ~121 ~121 dirt
setblock ~163 ~121 ~122 dirt
setblock ~163 ~121 ~123 dirt
setblock ~163 ~121 ~124 dirt
setblock ~163 ~121 ~125 dirt
setblock ~163 ~121 ~126 dirt
setblock ~163 ~121 ~127 dirt
setblock ~163 ~121 ~128 dirt
setblock ~163 ~121 ~129 dirt
setblock ~163 ~121 ~130 dirt
setblock ~163 ~121 ~131 dirt
setblock ~163 ~121 ~132 dirt
setblock ~163 ~121 ~133 dirt
setblock ~163 ~121 ~134 dirt
setblock ~163 ~122 ~71 dirt
setblock ~163 ~122 ~72 dirt
setblock ~163 ~122 ~73 dirt
setblock ~163 ~122 ~74 dirt
setblock ~163 ~122 ~75 dirt
setblock ~163 ~122 ~76 dirt
setblock ~163 ~122 ~77 dirt
setblock ~163 ~122 ~78 dirt
setblock ~163 ~122 ~79 dirt
setblock ~163 ~122 ~80 dirt
setblock ~163 ~122 ~81 dirt
setblock ~163 ~122 ~82 dirt
setblock ~163 ~122 ~83 dirt
setblock ~163 ~122 ~84 dirt
setblock ~163 ~122 ~85 dirt
setblock ~163 ~122 ~86 dirt
setblock ~163 ~122 ~87 dirt
setblock ~163 ~122 ~88 dirt
setblock ~163 ~122 ~89 dirt
setblock ~163 ~122 ~90 dirt
setblock ~163 ~122 ~91 dirt
setblock ~163 ~122 ~92 dirt
setblock ~163 ~122 ~93 dirt
setblock ~163 ~122 ~94 dirt
setblock ~163 ~122 ~95 dirt
setblock ~163 ~122 ~96 dirt
setblock ~163 ~122 ~97 dirt
setblock ~163 ~122 ~98 dirt
setblock ~163 ~122 ~99 dirt
setblock ~163 ~122 ~100 dirt
setblock ~163 ~122 ~101 dirt
setblock ~163 ~122 ~102 dirt
setblock ~163 ~122 ~103 dirt
setblock ~163 ~122 ~104 dirt
setblock ~163 ~122 ~105 dirt
setblock ~163 ~122 ~106 dirt
setblock ~163 ~122 ~107 dirt
setblock ~163 ~122 ~108 dirt
setblock ~163 ~122 ~109 dirt
setblock ~163 ~122 ~110 dirt
setblock ~163 ~122 ~111 dirt
setblock ~163 ~122 ~112 dirt
setblock ~163 ~122 ~113 dirt
setblock ~163 ~122 ~114 dirt
setblock ~163 ~122 ~115 dirt
setblock ~163 ~122 ~116 dirt
setblock ~163 ~122 ~117 dirt
setblock ~163 ~122 ~118 dirt
setblock ~163 ~122 ~119 dirt
setblock ~163 ~122 ~120 dirt
setblock ~163 ~122 ~121 dirt
setblock ~163 ~122 ~122 dirt
setblock ~163 ~122 ~123 dirt
setblock ~163 ~122 ~124 dirt
setblock ~163 ~122 ~125 dirt
setblock ~163 ~122 ~126 dirt
setblock ~163 ~122 ~127 dirt
setblock ~163 ~122 ~128 dirt
setblock ~163 ~122 ~129 dirt
setblock ~163 ~122 ~130 dirt
setblock ~163 ~122 ~131 dirt
setblock ~163 ~122 ~132 dirt
setblock ~163 ~122 ~133 dirt
setblock ~163 ~122 ~134 dirt
setblock ~163 ~123 ~71 dirt
setblock ~163 ~123 ~72 dirt
setblock ~163 ~123 ~73 dirt
setblock ~163 ~123 ~74 dirt
setblock ~163 ~123 ~75 dirt
setblock ~163 ~123 ~76 dirt
setblock ~163 ~123 ~77 dirt
setblock ~163 ~123 ~78 dirt
setblock ~163 ~123 ~79 dirt
setblock ~163 ~123 ~80 dirt
setblock ~163 ~123 ~81 dirt
setblock ~163 ~123 ~82 dirt
setblock ~163 ~123 ~83 dirt
setblock ~163 ~123 ~84 dirt
setblock ~163 ~123 ~85 dirt
setblock ~163 ~123 ~86 dirt
setblock ~163 ~123 ~87 grass_block
setblock ~163 ~123 ~88 grass_block
setblock ~163 ~123 ~89 grass_block
setblock ~163 ~123 ~90 grass_block
setblock ~163 ~123 ~91 grass_block
setblock ~163 ~123 ~92 grass_block
setblock ~163 ~123 ~93 grass_block
setblock ~163 ~123 ~94 grass_block
setblock ~163 ~123 ~95 grass_block
setblock ~163 ~123 ~96 grass_block
setblock ~163 ~123 ~97 grass_block
setblock ~163 ~123 ~98 grass_block
setblock ~163 ~123 ~99 grass_block
setblock ~163 ~123 ~100 grass_block
setblock ~163 ~123 ~101 dirt
setblock ~163 ~123 ~102 dirt
setblock ~163 ~123 ~103 dirt
setblock ~163 ~123 ~104 dirt
setblock ~163 ~123 ~105 dirt
setblock ~163 ~123 ~106 dirt
setblock ~163 ~123 ~107 dirt
setblock ~163 ~123 ~108 dirt
setblock ~163 ~123 ~109 dirt
setblock ~163 ~123 ~110 dirt
setblock ~163 ~123 ~111 dirt
setblock ~163 ~123 ~112 dirt
setblock ~163 ~123 ~113 dirt
setblock ~163 ~123 ~114 dirt
setblock ~163 ~123 ~115 dirt
setblock ~163 ~123 ~116 dirt
setblock ~163 ~123 ~117 dirt
setblock ~163 ~123 ~118 dirt
setblock ~163 ~123 ~119 dirt
setblock ~163 ~123 ~120 dirt
setblock ~163 ~123 ~121 dirt
setblock ~163 ~123 ~122 dirt
setblock ~163 ~123 ~123 dirt
setblock ~163 ~123 ~124 dirt
setblock ~163 ~123 ~125 dirt
setblock ~163 ~123 ~126 dirt
setblock ~163 ~123 ~127 dirt
setblock ~163 ~123 ~128 dirt
setblock ~163 ~123 ~129 grass_block
setblock ~163 ~123 ~130 grass_block
setblock ~163 ~123 ~131 grass_block
setblock ~163 ~123 ~132 grass_block
setblock ~163 ~123 ~133 grass_block
setblock ~163 ~123 ~134 grass_block
setblock ~163 ~124 ~71 dirt
setblock ~163 ~124 ~72 dirt
setblock ~163 ~124 ~73 dirt
setblock ~163 ~124 ~74 dirt
setblock ~163 ~124 ~75 dirt
setblock ~163 ~124 ~76 dirt
setblock ~163 ~124 ~77 dirt
setblock ~163 ~124 ~78 dirt
setblock ~163 ~124 ~79 grass_block
setblock ~163 ~124 ~80 grass_block
setblock ~163 ~124 ~81 grass_block
setblock ~163 ~124 ~82 grass_block
setblock ~163 ~124 ~83 grass_block
setblock ~163 ~124 ~84 grass_block
setblock ~163 ~124 ~85 grass_block
setblock ~163 ~124 ~86 grass_block
setblock ~163 ~124 ~90 short_grass
setblock ~163 ~124 ~98 short_grass
setblock ~163 ~124 ~99 short_grass
setblock ~163 ~124 ~101 grass_block
setblock ~163 ~124 ~102 grass_block
setblock ~163 ~124 ~103 dirt
setblock ~163 ~124 ~104 dirt
setblock ~163 ~124 ~105 dirt
setblock ~163 ~124 ~106 dirt
setblock ~163 ~124 ~107 dirt
setblock ~163 ~124 ~108 dirt
setblock ~163 ~124 ~109 dirt
setblock ~163 ~124 ~110 dirt
setblock ~163 ~124 ~111 dirt
setblock ~163 ~124 ~112 dirt
setblock ~163 ~124 ~113 dirt
setblock ~163 ~124 ~114 dirt
setblock ~163 ~124 ~115 dirt
setblock ~163 ~124 ~116 dirt
setblock ~163 ~124 ~117 dirt
setblock ~163 ~124 ~118 dirt
setblock ~163 ~124 ~119 dirt
setblock ~163 ~124 ~120 grass_block
setblock ~163 ~124 ~121 grass_block
setblock ~163 ~124 ~122 grass_block
setblock ~163 ~124 ~123 grass_block
setblock ~163 ~124 ~124 grass_block
setblock ~163 ~124 ~125 grass_block
setblock ~163 ~124 ~126 grass_block
setblock ~163 ~124 ~127 grass_block
setblock ~163 ~124 ~128 grass_block
setblock ~163 ~124 ~132 short_grass
setblock ~163 ~125 ~71 dirt
setblock ~163 ~125 ~72 dirt
setblock ~163 ~125 ~73 dirt
setblock ~163 ~125 ~74 dirt
setblock ~163 ~125 ~75 dirt
setblock ~163 ~125 ~76 grass_block
setblock ~163 ~125 ~77 grass_block
setblock ~163 ~125 ~78 grass_block
setblock ~163 ~125 ~81 short_grass
setblock ~163 ~125 ~82 short_grass
setblock ~163 ~125 ~86 poppy
setblock ~163 ~125 ~103 grass_block
setblock ~163 ~125 ~104 grass_block
setblock ~163 ~125 ~105 grass_block
setblock ~163 ~125 ~106 grass_block
setblock ~163 ~125 ~107 grass_block
setblock ~163 ~125 ~108 grass_block
setblock ~163 ~125 ~109 dirt
setblock ~163 ~125 ~110 dirt
setblock ~163 ~125 ~111 dirt
setblock ~163 ~125 ~112 dirt
setblock ~163 ~125 ~113 dirt
setblock ~163 ~125 ~114 dirt
setblock ~163 ~125 ~115 grass_block
setblock ~163 ~125 ~116 grass_block
setblock ~163 ~125 ~117 grass_block
setblock ~163 ~125 ~118 grass_block
setblock ~163 ~125 ~119 grass_block
setblock ~163 ~125 ~123 short_grass
setblock ~163 ~125 ~124 short_grass
setblock ~163 ~125 ~127 short_grass
setblock ~163 ~126 ~71 dirt
setblock ~163 ~126 ~72 dirt
setblock ~163 ~126 ~73 dirt
setblock ~163 ~126 ~74 grass_block
setblock ~163 ~126 ~75 grass_block
setblock ~163 ~126 ~108 short_grass
setblock ~163 ~126 ~109 grass_block
setblock ~163 ~126 ~110 grass_block
setblock ~163 ~126 ~111 grass_block
setblock ~163 ~126 ~112 grass_block
setblock ~163 ~126 ~113 grass_block
setblock ~163 ~126 ~114 grass_block
setblock ~163 ~126 ~116 fern
setblock ~163 ~126 ~117 short_grass
setblock ~163 ~126 ~118 poppy
setblock ~163 ~127 ~71 dirt
setblock ~163 ~127 ~72 grass_block
setblock ~163 ~127 ~73 grass_block
setblock ~163 ~127 ~109 short_grass
setblock ~163 ~127 ~110 short_grass
setblock ~163 ~127 ~111 short_grass
setblock ~163 ~127 ~113 poppy
setblock ~163 ~128 ~71 grass_block
setblock ~164 ~103 ~83 dirt
setblock ~164 ~104 ~83 dirt
setblock ~164 ~104 ~84 dirt
setblock ~164 ~105 ~83 dirt
setblock ~164 ~105 ~84 dirt
setblock ~164 ~105 ~85 dirt
setblock ~164 ~106 ~81 dirt
setblock ~164 ~106 ~82 dirt
setblock ~164 ~106 ~83 dirt
setblock ~164 ~106 ~84 dirt
setblock ~164 ~106 ~85 dirt
setblock ~164 ~107 ~79 dirt
setblock ~164 ~107 ~80 dirt
setblock ~164 ~107 ~81 dirt
setblock ~164 ~107 ~82 dirt
setblock ~164 ~107 ~83 dirt
setblock ~164 ~107 ~84 dirt
setblock ~164 ~107 ~85 dirt
setblock ~164 ~107 ~86 dirt
setblock ~164 ~107 ~99 dirt
setblock ~164 ~107 ~100 dirt
setblock ~164 ~108 ~78 dirt
setblock ~164 ~108 ~79 dirt
setblock ~164 ~108 ~80 dirt
setblock ~164 ~108 ~81 dirt
setblock ~164 ~108 ~82 dirt
setblock ~164 ~108 ~83 dirt
setblock ~164 ~108 ~84 dirt
setblock ~164 ~108 ~85 dirt
setblock ~164 ~108 ~86 dirt
setblock ~164 ~108 ~87 dirt
setblock ~164 ~108 ~88 dirt
setblock ~164 ~108 ~98 dirt
setblock ~164 ~108 ~99 dirt
setblock ~164 ~108 ~100 dirt
setblock ~164 ~108 ~105 dirt
setblock ~164 ~109 ~78 dirt
setblock ~164 ~109 ~79 dirt
setblock ~164 ~109 ~80 dirt
setblock ~164 ~109 ~81 dirt
setblock ~164 ~109 ~82 dirt
setblock ~164 ~109 ~83 dirt
setblock ~164 ~109 ~84 dirt
setblock ~164 ~109 ~85 dirt
setblock ~164 ~109 ~86 dirt
setblock ~164 ~109 ~87 dirt
setblock ~164 ~109 ~88 dirt
setblock ~164 ~109 ~89 dirt
setblock ~164 ~109 ~98 dirt
setblock ~164 ~109 ~99 dirt
setblock ~164 ~109 ~100 dirt
setblock ~164 ~109 ~105 dirt
setblock ~164 ~110 ~77 dirt
setblock ~164 ~110 ~78 dirt
setblock ~164 ~110 ~79 dirt
setblock ~164 ~110 ~80 dirt
setblock ~164 ~110 ~81 dirt
setblock ~164 ~110 ~82 dirt
setblock ~164 ~110 ~83 dirt
setblock ~164 ~110 ~84 dirt
setblock ~164 ~110 ~85 dirt
setblock ~164 ~110 ~86 dirt
setblock ~164 ~110 ~87 dirt
setblock ~164 ~110 ~88 dirt
setblock ~164 ~110 ~89 dirt
setblock ~164 ~110 ~90 dirt
setblock ~164 ~110 ~98 dirt
setblock ~164 ~110 ~99 dirt
setblock ~164 ~110 ~100 dirt
setblock ~164 ~110 ~101 dirt
setblock ~164 ~110 ~103 dirt
setblock ~164 ~110 ~104 dirt
setblock ~164 ~110 ~105 dirt
setblock ~164 ~111 ~76 dirt
setblock ~164 ~111 ~77 dirt
setblock ~164 ~111 ~78 dirt
setblock ~164 ~111 ~79 dirt
setblock ~164 ~111 ~80 dirt
setblock ~164 ~111 ~81 dirt
setblock ~164 ~111 ~82 dirt
setblock ~164 ~111 ~83 dirt
setblock ~164 ~111 ~84 dirt
setblock ~164 ~111 ~85 dirt
setblock ~164 ~111 ~86 dirt
setblock ~164 ~111 ~87 dirt
setblock ~164 ~111 ~88 dirt
setblock ~164 ~111 ~89 dirt
setblock ~164 ~111 ~90 dirt
setblock ~164 ~111 ~91 dirt
setblock ~164 ~111 ~97 dirt
setblock ~164 ~111 ~98 dirt
setblock ~164 ~111 ~99 dirt
setblock ~164 ~111 ~100 dirt
setblock ~164 ~111 ~101 dirt
setblock ~164 ~111 ~102 dirt
setblock ~164 ~111 ~103 dirt
setblock ~164 ~111 ~104 dirt
setblock ~164 ~111 ~105 dirt
setblock ~164 ~111 ~107 dirt
setblock ~164 ~112 ~76 dirt
setblock ~164 ~112 ~77 dirt
setblock ~164 ~112 ~78 dirt
setblock ~164 ~112 ~79 dirt
setblock ~164 ~112 ~80 dirt
setblock ~164 ~112 ~81 dirt
setblock ~164 ~112 ~82 dirt
setblock ~164 ~112 ~83 dirt
setblock ~164 ~112 ~84 dirt
setblock ~164 ~112 ~85 dirt
setblock ~164 ~112 ~86 dirt
setblock ~164 ~112 ~87 dirt
setblock ~164 ~112 ~88 dirt
setblock ~164 ~112 ~89 dirt
setblock ~164 ~112 ~90 dirt
setblock ~164 ~112 ~91 dirt
setblock ~164 ~112 ~92 dirt
setblock ~164 ~112 ~96 dirt
setblock ~164 ~112 ~97 dirt
setblock ~164 ~112 ~98 dirt
setblock ~164 ~112 ~99 dirt
setblock ~164 ~112 ~100 dirt
setblock ~164 ~112 ~101 dirt
setblock ~164 ~112 ~102 dirt
setblock ~164 ~112 ~103 dirt
setblock ~164 ~112 ~104 dirt
setblock ~164 ~112 ~105 dirt
setblock ~164 ~112 ~106 dirt
setblock ~164 ~112 ~107 dirt
setblock ~164 ~112 ~123 dirt
setblock ~164 ~113 ~76 dirt
setblock ~164 ~113 ~77 dirt
setblock ~164 ~113 ~78 dirt
setblock ~164 ~113 ~79 dirt
setblock ~164 ~113 ~80 dirt
setblock ~164 ~113 ~81 dirt
setblock ~164 ~113 ~82 dirt
setblock ~164 ~113 ~83 dirt
setblock ~164 ~113 ~84 dirt
setblock ~164 ~113 ~85 dirt
setblock ~164 ~113 ~86 dirt
setblock ~164 ~113 ~87 dirt
setblock ~164 ~113 ~88 dirt
setblock ~164 ~113 ~89 dirt
setblock ~164 ~113 ~90 dirt
setblock ~164 ~113 ~91 dirt
setblock ~164 ~113 ~92 dirt
setblock ~164 ~113 ~95 dirt
setblock ~164 ~113 ~96 dirt
setblock ~164 ~113 ~97 dirt
setblock ~164 ~113 ~98 dirt
setblock ~164 ~113 ~99 dirt
setblock ~164 ~113 ~100 dirt
setblock ~164 ~113 ~101 dirt
setblock ~164 ~113 ~102 dirt
setblock ~164 ~113 ~103 dirt
setblock ~164 ~113 ~104 dirt
setblock ~164 ~113 ~105 dirt
setblock ~164 ~113 ~106 dirt
setblock ~164 ~113 ~107 dirt
setblock ~164 ~113 ~108 dirt
setblock ~164 ~113 ~122 dirt
setblock ~164 ~113 ~123 dirt
setblock ~164 ~113 ~124 dirt
setblock ~164 ~114 ~75 dirt
setblock ~164 ~114 ~76 dirt
setblock ~164 ~114 ~77 dirt
setblock ~164 ~114 ~78 dirt
setblock ~164 ~114 ~79 dirt
setblock ~164 ~114 ~80 dirt
setblock ~164 ~114 ~81 dirt
setblock ~164 ~114 ~82 dirt
setblock ~164 ~114 ~83 dirt
setblock ~164 ~114 ~84 dirt
setblock ~164 ~114 ~85 dirt
setblock ~164 ~114 ~86 dirt
setblock ~164 ~114 ~87 dirt
setblock ~164 ~114 ~88 dirt
setblock ~164 ~114 ~89 dirt
setblock ~164 ~114 ~90 dirt
setblock ~164 ~114 ~91 dirt
setblock ~164 ~114 ~92 dirt
setblock ~164 ~114 ~93 dirt
setblock ~164 ~114 ~94 dirt
setblock ~164 ~114 ~95 dirt
setblock ~164 ~114 ~96 dirt
setblock ~164 ~114 ~97 dirt
setblock ~164 ~114 ~98 dirt
setblock ~164 ~114 ~99 dirt
setblock ~164 ~114 ~100 dirt
setblock ~164 ~114 ~101 dirt
setblock ~164 ~114 ~102 dirt
setblock ~164 ~114 ~103 dirt
setblock ~164 ~114 ~104 dirt
setblock ~164 ~114 ~105 dirt
setblock ~164 ~114 ~106 dirt
setblock ~164 ~114 ~107 dirt
setblock ~164 ~114 ~108 dirt
setblock ~164 ~114 ~121 dirt
setblock ~164 ~114 ~122 dirt
setblock ~164 ~114 ~123 dirt
setblock ~164 ~114 ~124 dirt
setblock ~164 ~114 ~128 dirt
setblock ~164 ~115 ~74 dirt
setblock ~164 ~115 ~75 dirt
setblock ~164 ~115 ~76 dirt
setblock ~164 ~115 ~77 dirt
setblock ~164 ~115 ~78 dirt
setblock ~164 ~115 ~79 dirt
setblock ~164 ~115 ~80 dirt
setblock ~164 ~115 ~81 dirt
setblock ~164 ~115 ~82 dirt
setblock ~164 ~115 ~83 dirt
setblock ~164 ~115 ~84 dirt
setblock ~164 ~115 ~85 dirt
setblock ~164 ~115 ~86 dirt
setblock ~164 ~115 ~87 dirt
setblock ~164 ~115 ~88 dirt
setblock ~164 ~115 ~89 dirt
setblock ~164 ~115 ~90 dirt
setblock ~164 ~115 ~91 dirt
setblock ~164 ~115 ~92 dirt
setblock ~164 ~115 ~93 dirt
setblock ~164 ~115 ~94 dirt
setblock ~164 ~115 ~95 dirt
setblock ~164 ~115 ~96 dirt
setblock ~164 ~115 ~97 dirt
setblock ~164 ~115 ~98 dirt
setblock ~164 ~115 ~99 dirt
setblock ~164 ~115 ~100 dirt
setblock ~164 ~115 ~101 dirt
setblock ~164 ~115 ~102 dirt
setblock ~164 ~115 ~103 dirt
setblock ~164 ~115 ~104 dirt
setblock ~164 ~115 ~105 dirt
setblock ~164 ~115 ~106 dirt
setblock ~164 ~115 ~107 dirt
setblock ~164 ~115 ~108 dirt
setblock ~164 ~115 ~121 dirt
setblock ~164 ~115 ~122 dirt
setblock ~164 ~115 ~123 dirt
setblock ~164 ~115 ~124 dirt
setblock ~164 ~115 ~127 dirt
setblock ~164 ~115 ~128 dirt
setblock ~164 ~115 ~129 dirt
setblock ~164 ~116 ~74 dirt
setblock ~164 ~116 ~75 dirt
setblock ~164 ~116 ~76 dirt
setblock ~164 ~116 ~77 dirt
setblock ~164 ~116 ~78 dirt
setblock ~164 ~116 ~79 dirt
setblock ~164 ~116 ~80 dirt
setblock ~164 ~116 ~81 dirt
setblock ~164 ~116 ~82 dirt
setblock ~164 ~116 ~83 dirt
setblock ~164 ~116 ~84 dirt
setblock ~164 ~116 ~85 dirt
setblock ~164 ~116 ~86 dirt
setblock ~164 ~116 ~87 dirt
setblock ~164 ~116 ~88 dirt
setblock ~164 ~116 ~89 dirt
setblock ~164 ~116 ~90 dirt
setblock ~164 ~116 ~91 dirt
setblock ~164 ~116 ~92 dirt
setblock ~164 ~116 ~93 dirt
setblock ~164 ~116 ~94 dirt
setblock ~164 ~116 ~95 dirt
setblock ~164 ~116 ~96 dirt
setblock ~164 ~116 ~97 dirt
setblock ~164 ~116 ~98 dirt
setblock ~164 ~116 ~99 dirt
setblock ~164 ~116 ~100 dirt
setblock ~164 ~116 ~101 dirt
setblock ~164 ~116 ~102 dirt
setblock ~164 ~116 ~103 dirt
setblock ~164 ~116 ~104 dirt
setblock ~164 ~116 ~105 dirt
setblock ~164 ~116 ~106 dirt
setblock ~164 ~116 ~107 dirt
setblock ~164 ~116 ~108 dirt
setblock ~164 ~116 ~110 dirt
setblock ~164 ~116 ~117 dirt
setblock ~164 ~116 ~121 dirt
setblock ~164 ~116 ~122 dirt
setblock ~164 ~116 ~123 dirt
setblock ~164 ~116 ~124 dirt
setblock ~164 ~116 ~127 dirt
setblock ~164 ~116 ~128 dirt
setblock ~164 ~116 ~129 dirt
setblock ~164 ~116 ~130 dirt
setblock ~164 ~117 ~74 dirt
setblock ~164 ~117 ~75 dirt
setblock ~164 ~117 ~76 dirt
setblock ~164 ~117 ~77 dirt
setblock ~164 ~117 ~78 dirt
setblock ~164 ~117 ~79 dirt
setblock ~164 ~117 ~80 dirt
setblock ~164 ~117 ~81 dirt
setblock ~164 ~117 ~82 dirt
setblock ~164 ~117 ~83 dirt
setblock ~164 ~117 ~84 dirt
setblock ~164 ~117 ~85 dirt
setblock ~164 ~117 ~86 dirt
setblock ~164 ~117 ~87 dirt
setblock ~164 ~117 ~88 dirt
setblock ~164 ~117 ~89 dirt
setblock ~164 ~117 ~90 dirt
setblock ~164 ~117 ~91 dirt
setblock ~164 ~117 ~92 dirt
setblock ~164 ~117 ~93 dirt
setblock ~164 ~117 ~94 dirt
setblock ~164 ~117 ~95 dirt
setblock ~164 ~117 ~96 dirt
setblock ~164 ~117 ~97 dirt
setblock ~164 ~117 ~98 dirt
setblock ~164 ~117 ~99 dirt
setblock ~164 ~117 ~100 dirt
setblock ~164 ~117 ~101 dirt
setblock ~164 ~117 ~102 dirt
setblock ~164 ~117 ~103 dirt
setblock ~164 ~117 ~104 dirt
setblock ~164 ~117 ~105 dirt
setblock ~164 ~117 ~106 dirt
setblock ~164 ~117 ~107 dirt
setblock ~164 ~117 ~108 dirt
setblock ~164 ~117 ~109 dirt
setblock ~164 ~117 ~110 dirt
setblock ~164 ~117 ~117 dirt
setblock ~164 ~117 ~120 dirt
setblock ~164 ~117 ~121 dirt
setblock ~164 ~117 ~122 dirt
setblock ~164 ~117 ~123 dirt
setblock ~164 ~117 ~124 dirt
setblock ~164 ~117 ~125 dirt
setblock ~164 ~117 ~126 dirt
setblock ~164 ~117 ~127 dirt
setblock ~164 ~117 ~128 dirt
setblock ~164 ~117 ~129 dirt
setblock ~164 ~117 ~130 dirt
setblock ~164 ~118 ~73 dirt
setblock ~164 ~118 ~74 dirt
setblock ~164 ~118 ~75 dirt
setblock ~164 ~118 ~76 dirt
setblock ~164 ~118 ~77 dirt
setblock ~164 ~118 ~78 dirt
setblock ~164 ~118 ~79 dirt
setblock ~164 ~118 ~80 dirt
setblock ~164 ~118 ~81 dirt
setblock ~164 ~118 ~82 dirt
setblock ~164 ~118 ~83 dirt
setblock ~164 ~118 ~84 dirt
setblock ~164 ~118 ~85 dirt
setblock ~164 ~118 ~86 dirt
setblock ~164 ~118 ~87 dirt
setblock ~164 ~118 ~88 dirt
setblock ~164 ~118 ~89 dirt
setblock ~164 ~118 ~90 dirt
setblock ~164 ~118 ~91 dirt
setblock ~164 ~118 ~92 dirt
setblock ~164 ~118 ~93 dirt
setblock ~164 ~118 ~94 dirt
setblock ~164 ~118 ~95 dirt
setblock ~164 ~118 ~96 dirt
setblock ~164 ~118 ~97 dirt
setblock ~164 ~118 ~98 dirt
setblock ~164 ~118 ~99 dirt
setblock ~164 ~118 ~100 dirt
setblock ~164 ~118 ~101 dirt
setblock ~164 ~118 ~102 dirt
setblock ~164 ~118 ~103 dirt
setblock ~164 ~118 ~104 dirt
setblock ~164 ~118 ~105 dirt
setblock ~164 ~118 ~106 dirt
setblock ~164 ~118 ~107 dirt
setblock ~164 ~118 ~108 dirt
setblock ~164 ~118 ~109 dirt
setblock ~164 ~118 ~110 dirt
setblock ~164 ~118 ~111 dirt
setblock ~164 ~118 ~116 dirt
setblock ~164 ~118 ~117 dirt
setblock ~164 ~118 ~118 dirt
setblock ~164 ~118 ~120 dirt
setblock ~164 ~118 ~121 dirt
setblock ~164 ~118 ~122 dirt
setblock ~164 ~118 ~123 dirt
setblock ~164 ~118 ~124 dirt
setblock ~164 ~118 ~125 dirt
setblock ~164 ~118 ~126 dirt
setblock ~164 ~118 ~127 dirt
setblock ~164 ~118 ~128 dirt
setblock ~164 ~118 ~129 dirt
setblock ~164 ~118 ~130 dirt
setblock ~164 ~119 ~73 dirt
setblock ~164 ~119 ~74 dirt
setblock ~164 ~119 ~75 dirt
setblock ~164 ~119 ~76 dirt
setblock ~164 ~119 ~77 dirt
setblock ~164 ~119 ~78 dirt
setblock ~164 ~119 ~79 dirt
setblock ~164 ~119 ~80 dirt
setblock ~164 ~119 ~81 dirt
setblock ~164 ~119 ~82 dirt
setblock ~164 ~119 ~83 dirt
setblock ~164 ~119 ~84 dirt
setblock ~164 ~119 ~85 dirt
setblock ~164 ~119 ~86 dirt
setblock ~164 ~119 ~87 dirt
setblock ~164 ~119 ~88 dirt
setblock ~164 ~119 ~89 dirt
setblock ~164 ~119 ~90 dirt
setblock ~164 ~119 ~91 dirt
setblock ~164 ~119 ~92 dirt
setblock ~164 ~119 ~93 dirt
setblock ~164 ~119 ~94 dirt
setblock ~164 ~119 ~95 dirt
setblock ~164 ~119 ~96 dirt
setblock ~164 ~119 ~97 dirt
setblock ~164 ~119 ~98 dirt
setblock ~164 ~119 ~99 dirt
setblock ~164 ~119 ~100 dirt
setblock ~164 ~119 ~101 dirt
setblock ~164 ~119 ~102 dirt
setblock ~164 ~119 ~103 dirt
setblock ~164 ~119 ~104 dirt
setblock ~164 ~119 ~105 dirt
setblock ~164 ~119 ~106 dirt
setblock ~164 ~119 ~107 dirt
setblock ~164 ~119 ~108 dirt
setblock ~164 ~119 ~109 dirt
setblock ~164 ~119 ~110 dirt
setblock ~164 ~119 ~111 dirt
setblock ~164 ~119 ~112 dirt
setblock ~164 ~119 ~113 dirt
setblock ~164 ~119 ~116 dirt
setblock ~164 ~119 ~117 dirt
setblock ~164 ~119 ~118 dirt
setblock ~164 ~119 ~119 dirt
setblock ~164 ~119 ~120 dirt
setblock ~164 ~119 ~121 dirt
setblock ~164 ~119 ~122 dirt
setblock ~164 ~119 ~123 dirt
setblock ~164 ~119 ~124 dirt
setblock ~164 ~119 ~125 dirt
setblock ~164 ~119 ~126 dirt
setblock ~164 ~119 ~127 dirt
setblock ~164 ~119 ~128 dirt
setblock ~164 ~119 ~129 dirt
setblock ~164 ~119 ~130 dirt
setblock ~164 ~120 ~72 dirt
setblock ~164 ~120 ~73 dirt
setblock ~164 ~120 ~74 dirt
setblock ~164 ~120 ~75 dirt
setblock ~164 ~120 ~76 dirt
setblock ~164 ~120 ~77 dirt
setblock ~164 ~120 ~78 dirt
setblock ~164 ~120 ~79 dirt
setblock ~164 ~120 ~80 dirt
setblock ~164 ~120 ~81 dirt
setblock ~164 ~120 ~82 dirt
setblock ~164 ~120 ~83 dirt
setblock ~164 ~120 ~84 dirt
setblock ~164 ~120 ~85 dirt
setblock ~164 ~120 ~86 dirt
setblock ~164 ~120 ~87 dirt
setblock ~164 ~120 ~88 dirt
setblock ~164 ~120 ~89 dirt
setblock ~164 ~120 ~90 dirt
setblock ~164 ~120 ~91 dirt
setblock ~164 ~120 ~92 dirt
setblock ~164 ~120 ~93 dirt
setblock ~164 ~120 ~94 dirt
setblock ~164 ~120 ~95 dirt
setblock ~164 ~120 ~96 dirt
setblock ~164 ~120 ~97 dirt
setblock ~164 ~120 ~98 dirt
setblock ~164 ~120 ~99 dirt
setblock ~164 ~120 ~100 dirt
setblock ~164 ~120 ~101 dirt
setblock ~164 ~120 ~102 dirt
setblock ~164 ~120 ~103 dirt
setblock ~164 ~120 ~104 dirt
setblock ~164 ~120 ~105 dirt
setblock ~164 ~120 ~106 dirt
setblock ~164 ~120 ~107 dirt
setblock ~164 ~120 ~108 dirt
setblock ~164 ~120 ~109 dirt
setblock ~164 ~120 ~110 dirt
setblock ~164 ~120 ~111 dirt
setblock ~164 ~120 ~112 dirt
setblock ~164 ~120 ~113 dirt
setblock ~164 ~120 ~115 dirt
setblock ~164 ~120 ~116 dirt
setblock ~164 ~120 ~117 dirt
setblock ~164 ~120 ~118 dirt
setblock ~164 ~120 ~119 dirt
setblock ~164 ~120 ~120 dirt
setblock ~164 ~120 ~121 dirt
setblock ~164 ~120 ~122 dirt
setblock ~164 ~120 ~123 dirt
setblock ~164 ~120 ~124 dirt
setblock ~164 ~120 ~125 dirt
setblock ~164 ~120 ~126 dirt
setblock ~164 ~120 ~127 dirt
setblock ~164 ~120 ~128 dirt
setblock ~164 ~120 ~129 dirt
setblock ~164 ~120 ~130 dirt
setblock ~164 ~120 ~131 dirt
setblock ~164 ~120 ~132 dirt
setblock ~164 ~121 ~72 dirt
setblock ~164 ~121 ~73 dirt
setblock ~164 ~121 ~74 dirt
setblock ~164 ~121 ~75 dirt
setblock ~164 ~121 ~76 dirt
setblock ~164 ~121 ~77 dirt
setblock ~164 ~121 ~78 dirt
setblock ~164 ~121 ~79 dirt
setblock ~164 ~121 ~80 dirt
setblock ~164 ~121 ~81 dirt
setblock ~164 ~121 ~82 dirt
setblock ~164 ~121 ~83 dirt
setblock ~164 ~121 ~84 dirt
setblock ~164 ~121 ~85 dirt
setblock ~164 ~121 ~86 dirt
setblock ~164 ~121 ~87 dirt
setblock ~164 ~121 ~88 dirt
setblock ~164 ~121 ~89 dirt
setblock ~164 ~121 ~90 dirt
setblock ~164 ~121 ~91 dirt
setblock ~164 ~121 ~92 dirt
setblock ~164 ~121 ~93 dirt
setblock ~164 ~121 ~94 dirt
setblock ~164 ~121 ~95 dirt
setblock ~164 ~121 ~96 dirt
setblock ~164 ~121 ~97 dirt
setblock ~164 ~121 ~98 dirt
setblock ~164 ~121 ~99 dirt
setblock ~164 ~121 ~100 dirt
setblock ~164 ~121 ~101 dirt
setblock ~164 ~121 ~102 dirt
setblock ~164 ~121 ~103 dirt
setblock ~164 ~121 ~104 dirt
setblock ~164 ~121 ~105 dirt
setblock ~164 ~121 ~106 dirt
setblock ~164 ~121 ~107 dirt
setblock ~164 ~121 ~108 dirt
setblock ~164 ~121 ~109 dirt
setblock ~164 ~121 ~110 dirt
setblock ~164 ~121 ~111 dirt
setblock ~164 ~121 ~112 dirt
setblock ~164 ~121 ~113 dirt
setblock ~164 ~121 ~114 dirt
setblock ~164 ~121 ~115 dirt
setblock ~164 ~121 ~116 dirt
setblock ~164 ~121 ~117 dirt
setblock ~164 ~121 ~118 dirt
setblock ~164 ~121 ~119 dirt
setblock ~164 ~121 ~120 dirt
setblock ~164 ~121 ~121 dirt
setblock ~164 ~121 ~122 dirt
setblock ~164 ~121 ~123 dirt
setblock ~164 ~121 ~124 dirt
setblock ~164 ~121 ~125 dirt
setblock ~164 ~121 ~126 dirt
setblock ~164 ~121 ~127 dirt
setblock ~164 ~121 ~128 dirt
setblock ~164 ~121 ~129 dirt
setblock ~164 ~121 ~130 dirt
setblock ~164 ~121 ~131 dirt
setblock ~164 ~121 ~132 dirt
setblock ~164 ~122 ~72 dirt
setblock ~164 ~122 ~73 dirt
setblock ~164 ~122 ~74 dirt
setblock ~164 ~122 ~75 dirt
setblock ~164 ~122 ~76 dirt
setblock ~164 ~122 ~77 dirt
setblock ~164 ~122 ~78 dirt
setblock ~164 ~122 ~79 dirt
setblock ~164 ~122 ~80 dirt
setblock ~164 ~122 ~81 dirt
setblock ~164 ~122 ~82 dirt
setblock ~164 ~122 ~83 dirt
setblock ~164 ~122 ~84 dirt
setblock ~164 ~122 ~85 dirt
setblock ~164 ~122 ~86 dirt
setblock ~164 ~122 ~87 dirt
setblock ~164 ~122 ~88 dirt
setblock ~164 ~122 ~89 dirt
setblock ~164 ~122 ~90 dirt
setblock ~164 ~122 ~91 dirt
setblock ~164 ~122 ~92 dirt
setblock ~164 ~122 ~93 dirt
setblock ~164 ~122 ~94 dirt
setblock ~164 ~122 ~95 dirt
setblock ~164 ~122 ~96 dirt
setblock ~164 ~122 ~97 dirt
setblock ~164 ~122 ~98 dirt
setblock ~164 ~122 ~99 dirt
setblock ~164 ~122 ~100 dirt
setblock ~164 ~122 ~101 dirt
setblock ~164 ~122 ~102 dirt
setblock ~164 ~122 ~103 dirt
setblock ~164 ~122 ~104 dirt
setblock ~164 ~122 ~105 dirt
setblock ~164 ~122 ~106 dirt
setblock ~164 ~122 ~107 dirt
setblock ~164 ~122 ~108 dirt
setblock ~164 ~122 ~109 dirt
setblock ~164 ~122 ~110 dirt
setblock ~164 ~122 ~111 dirt
setblock ~164 ~122 ~112 dirt
setblock ~164 ~122 ~113 dirt
setblock ~164 ~122 ~114 dirt
setblock ~164 ~122 ~115 dirt
setblock ~164 ~122 ~116 dirt
setblock ~164 ~122 ~117 dirt
setblock ~164 ~122 ~118 dirt
setblock ~164 ~122 ~119 dirt
setblock ~164 ~122 ~120 dirt
setblock ~164 ~122 ~121 dirt
setblock ~164 ~122 ~122 dirt
setblock ~164 ~122 ~123 dirt
setblock ~164 ~122 ~124 dirt
setblock ~164 ~122 ~125 dirt
setblock ~164 ~122 ~126 dirt
setblock ~164 ~122 ~127 dirt
setblock ~164 ~122 ~128 dirt
setblock ~164 ~122 ~129 dirt
setblock ~164 ~122 ~130 dirt
setblock ~164 ~122 ~131 dirt
setblock ~164 ~122 ~132 dirt
setblock ~164 ~123 ~72 dirt
setblock ~164 ~123 ~73 dirt
setblock ~164 ~123 ~74 dirt
setblock ~164 ~123 ~75 dirt
setblock ~164 ~123 ~76 dirt
setblock ~164 ~123 ~77 dirt
setblock ~164 ~123 ~78 dirt
setblock ~164 ~123 ~79 dirt
setblock ~164 ~123 ~80 dirt
setblock ~164 ~123 ~81 dirt
setblock ~164 ~123 ~82 dirt
setblock ~164 ~123 ~83 dirt
setblock ~164 ~123 ~84 dirt
setblock ~164 ~123 ~85 dirt
setblock ~164 ~123 ~86 dirt
setblock ~164 ~123 ~87 grass_block
setblock ~164 ~123 ~88 grass_block
setblock ~164 ~123 ~89 grass_block
setblock ~164 ~123 ~90 grass_block
setblock ~164 ~123 ~91 grass_block
setblock ~164 ~123 ~92 grass_block
setblock ~164 ~123 ~93 grass_block
setblock ~164 ~123 ~94 grass_block
setblock ~164 ~123 ~95 grass_block
setblock ~164 ~123 ~96 grass_block
setblock ~164 ~123 ~97 grass_block
setblock ~164 ~123 ~98 grass_block
setblock ~164 ~123 ~99 grass_block
setblock ~164 ~123 ~100 dirt
setblock ~164 ~123 ~101 dirt
setblock ~164 ~123 ~102 dirt
setblock ~164 ~123 ~103 dirt
setblock ~164 ~123 ~104 dirt
setblock ~164 ~123 ~105 dirt
setblock ~164 ~123 ~106 dirt
setblock ~164 ~123 ~107 dirt
setblock ~164 ~123 ~108 dirt
setblock ~164 ~123 ~109 dirt
setblock ~164 ~123 ~110 dirt
setblock ~164 ~123 ~111 dirt
setblock ~164 ~123 ~112 dirt
setblock ~164 ~123 ~113 dirt
setblock ~164 ~123 ~114 dirt
setblock ~164 ~123 ~115 dirt
setblock ~164 ~123 ~116 dirt
setblock ~164 ~123 ~117 dirt
setblock ~164 ~123 ~118 dirt
setblock ~164 ~123 ~119 dirt
setblock ~164 ~123 ~120 dirt
setblock ~164 ~123 ~121 dirt
setblock ~164 ~123 ~122 dirt
setblock ~164 ~123 ~123 dirt
setblock ~164 ~123 ~124 dirt
setblock ~164 ~123 ~125 dirt
setblock ~164 ~123 ~126 dirt
setblock ~164 ~123 ~127 dirt
setblock ~164 ~123 ~128 grass_block
setblock ~164 ~123 ~129 grass_block
setblock ~164 ~123 ~130 grass_block
setblock ~164 ~123 ~131 grass_block
setblock ~164 ~123 ~132 grass_block
setblock ~164 ~124 ~72 dirt
setblock ~164 ~124 ~73 dirt
setblock ~164 ~124 ~74 dirt
setblock ~164 ~124 ~75 dirt
setblock ~164 ~124 ~76 dirt
setblock ~164 ~124 ~77 dirt
setblock ~164 ~124 ~78 grass_block
setblock ~164 ~124 ~79 grass_block
setblock ~164 ~124 ~80 grass_block
setblock ~164 ~124 ~81 grass_block
setblock ~164 ~124 ~82 grass_block
setblock ~164 ~124 ~83 grass_block
setblock ~164 ~124 ~84 grass_block
setblock ~164 ~124 ~85 grass_block
setblock ~164 ~124 ~86 grass_block
setblock ~164 ~124 ~88 fern
setblock ~164 ~124 ~89 short_grass
setblock ~164 ~124 ~91 short_grass
setblock ~164 ~124 ~97 short_grass
setblock ~164 ~124 ~100 grass_block
setblock ~164 ~124 ~101 grass_block
setblock ~164 ~124 ~102 grass_block
setblock ~164 ~124 ~103 grass_block
setblock ~164 ~124 ~104 dirt
setblock ~164 ~124 ~105 dirt
setblock ~164 ~124 ~106 dirt
setblock ~164 ~124 ~107 dirt
setblock ~164 ~124 ~108 dirt
setblock ~164 ~124 ~109 dirt
setblock ~164 ~124 ~110 dirt
setblock ~164 ~124 ~111 dirt
setblock ~164 ~124 ~112 dirt
setblock ~164 ~124 ~113 dirt
setblock ~164 ~124 ~114 dirt
setblock ~164 ~124 ~115 dirt
setblock ~164 ~124 ~116 dirt
setblock ~164 ~124 ~117 dirt
setblock ~164 ~124 ~118 dirt
setblock ~164 ~124 ~119 dirt
setblock ~164 ~124 ~120 dirt
setblock ~164 ~124 ~121 dirt
setblock ~164 ~124 ~122 grass_block
setblock ~164 ~124 ~123 grass_block
setblock ~164 ~124 ~124 grass_block
setblock ~164 ~124 ~125 grass_block
setblock ~164 ~124 ~126 grass_block
setblock ~164 ~124 ~127 grass_block
setblock ~164 ~124 ~129 short_grass
setblock ~164 ~124 ~130 short_grass
setblock ~164 ~124 ~132 fern
setblock ~164 ~125 ~72 dirt
setblock ~164 ~125 ~73 dirt
setblock ~164 ~125 ~74 dirt
setblock ~164 ~125 ~75 dirt
setblock ~164 ~125 ~76 grass_block
setblock ~164 ~125 ~77 grass_block
setblock ~164 ~125 ~82 short_grass
setblock ~164 ~125 ~84 short_grass
setblock ~164 ~125 ~86 poppy
setblock ~164 ~125 ~103 short_grass
setblock ~164 ~125 ~104 grass_block
setblock ~164 ~125 ~105 grass_block
setblock ~164 ~125 ~106 grass_block
setblock ~164 ~125 ~107 grass_block
setblock ~164 ~125 ~108 grass_block
setblock ~164 ~125 ~109 grass_block
setblock ~164 ~125 ~110 grass_block
setblock ~164 ~125 ~111 grass_block
setblock ~164 ~125 ~112 grass_block
setblock ~164 ~125 ~113 grass_block
setblock ~164 ~125 ~114 grass_block
setblock ~164 ~125 ~115 grass_block
setblock ~164 ~125 ~116 grass_block
setblock ~164 ~125 ~117 grass_block
setblock ~164 ~125 ~118 grass_block
setblock ~164 ~125 ~119 grass_block
setblock ~164 ~125 ~120 grass_block
setblock ~164 ~125 ~121 grass_block
setblock ~164 ~125 ~122 fern
setblock ~164 ~125 ~123 short_grass
setblock ~164 ~125 ~125 short_grass
setblock ~164 ~126 ~72 dirt
setblock ~164 ~126 ~73 grass_block
setblock ~164 ~126 ~74 grass_block
setblock ~164 ~126 ~75 grass_block
setblock ~164 ~126 ~104 poppy
setblock ~164 ~126 ~107 short_grass
setblock ~164 ~126 ~113 short_grass
setblock ~164 ~126 ~114 short_grass
setblock ~164 ~126 ~117 short_grass
setblock ~164 ~126 ~118 short_grass
setblock ~164 ~126 ~121 short_grass
setblock ~164 ~127 ~72 grass_block
setblock ~165 ~105 ~84 dirt
setblock ~165 ~106 ~83 dirt
setblock ~165 ~106 ~84 dirt
setblock ~165 ~107 ~82 dirt
setblock ~165 ~107 ~83 dirt
setblock ~165 ~107 ~84 dirt
setblock ~165 ~107 ~85 dirt
setblock ~165 ~108 ~79 dirt
setblock ~165 ~108 ~82 dirt
setblock ~165 ~108 ~83 dirt
setblock ~165 ~108 ~84 dirt
setblock ~165 ~108 ~85 dirt
setblock ~165 ~108 ~99 dirt
setblock ~165 ~109 ~79 dirt
setblock ~165 ~109 ~80 dirt
setblock ~165 ~109 ~81 dirt
setblock ~165 ~109 ~82 dirt
setblock ~165 ~109 ~83 dirt
setblock ~165 ~109 ~84 dirt
setblock ~165 ~109 ~85 dirt
setblock ~165 ~109 ~87 dirt
setblock ~165 ~109 ~99 dirt
setblock ~165 ~110 ~78 dirt
setblock ~165 ~110 ~79 dirt
setblock ~165 ~110 ~80 dirt
setblock ~165 ~110 ~81 dirt
setblock ~165 ~110 ~82 dirt
setblock ~165 ~110 ~83 dirt
setblock ~165 ~110 ~84 dirt
setblock ~165 ~110 ~85 dirt
setblock ~165 ~110 ~86 dirt
setblock ~165 ~110 ~87 dirt
setblock ~165 ~110 ~88 dirt
setblock ~165 ~110 ~89 dirt
setblock ~165 ~110 ~99 dirt
setblock ~165 ~111 ~77 dirt
setblock ~165 ~111 ~78 dirt
setblock ~165 ~111 ~79 dirt
setblock ~165 ~111 ~80 dirt
setblock ~165 ~111 ~81 dirt
