setblock ~0 ~1 ~0 gold_block
setblock ~30 ~121 ~100 dirt
setblock ~30 ~122 ~100 dirt
setblock ~30 ~123 ~100 dirt
setblock ~30 ~124 ~100 dirt
setblock ~30 ~125 ~100 grass_block
setblock ~31 ~119 ~98 dirt
setblock ~31 ~119 ~100 dirt
setblock ~31 ~120 ~91 dirt
setblock ~31 ~120 ~93 dirt
setblock ~31 ~120 ~94 dirt
setblock ~31 ~120 ~98 dirt
setblock ~31 ~120 ~100 dirt
setblock ~31 ~120 ~101 dirt
setblock ~31 ~121 ~91 dirt
setblock ~31 ~121 ~93 dirt
setblock ~31 ~121 ~94 dirt
setblock ~31 ~121 ~95 dirt
setblock ~31 ~121 ~98 dirt
setblock ~31 ~121 ~99 dirt
setblock ~31 ~121 ~100 dirt
setblock ~31 ~121 ~101 dirt
setblock ~31 ~122 ~91 dirt
setblock ~31 ~122 ~93 dirt
setblock ~31 ~122 ~94 dirt
setblock ~31 ~122 ~95 dirt
setblock ~31 ~122 ~98 dirt
setblock ~31 ~122 ~99 dirt
setblock ~31 ~122 ~100 dirt
setblock ~31 ~122 ~101 dirt
setblock ~31 ~123 ~91 grass_block
setblock ~31 ~123 ~93 dirt
setblock ~31 ~123 ~94 dirt
setblock ~31 ~123 ~95 dirt
setblock ~31 ~123 ~98 dirt
setblock ~31 ~123 ~99 dirt
setblock ~31 ~123 ~100 dirt
setblock ~31 ~123 ~101 dirt
setblock ~31 ~124 ~91 short_grass
setblock ~31 ~124 ~93 grass_block
setblock ~31 ~124 ~94 grass_block
setblock ~31 ~124 ~95 grass_block
setblock ~31 ~124 ~98 dirt
setblock ~31 ~124 ~99 dirt
setblock ~31 ~124 ~100 dirt
setblock ~31 ~124 ~101 dirt
setblock ~31 ~125 ~93 short_grass
setblock ~31 ~125 ~95 short_grass
setblock ~31 ~125 ~98 grass_block
setblock ~31 ~125 ~99 grass_block
setblock ~31 ~125 ~100 grass_block
setblock ~31 ~125 ~101 grass_block
setblock ~32 ~117 ~98 dirt
setblock ~32 ~117 ~99 dirt
setblock ~32 ~118 ~93 dirt
setblock ~32 ~118 ~94 dirt
setblock ~32 ~118 ~98 dirt
setblock ~32 ~118 ~99 dirt
setblock ~32 ~118 ~100 dirt
setblock ~32 ~119 ~91 dirt
setblock ~32 ~119 ~93 dirt
setblock ~32 ~119 ~94 dirt
setblock ~32 ~119 ~95 dirt
setblock ~32 ~119 ~97 dirt
setblock ~32 ~119 ~98 dirt
setblock ~32 ~119 ~99 dirt
setblock ~32 ~119 ~100 dirt
setblock ~32 ~119 ~101 dirt
setblock ~32 ~120 ~90 dirt
setblock ~32 ~120 ~91 dirt
setblock ~32 ~120 ~92 dirt
setblock ~32 ~120 ~93 dirt
setblock ~32 ~120 ~94 dirt
setblock ~32 ~120 ~95 dirt
setblock ~32 ~120 ~97 dirt
setblock ~32 ~120 ~98 dirt
setblock ~32 ~120 ~99 dirt
setblock ~32 ~120 ~100 dirt
setblock ~32 ~120 ~101 dirt
setblock ~32 ~120 ~102 dirt
setblock ~32 ~121 ~90 dirt
setblock ~32 ~121 ~91 dirt
setblock ~32 ~121 ~92 dirt
setblock ~32 ~121 ~93 dirt
setblock ~32 ~121 ~94 dirt
setblock ~32 ~121 ~95 dirt
setblock ~32 ~121 ~96 dirt
setblock ~32 ~121 ~97 dirt
setblock ~32 ~121 ~98 dirt
setblock ~32 ~121 ~99 dirt
setblock ~32 ~121 ~100 dirt
setblock ~32 ~121 ~101 dirt
setblock ~32 ~121 ~102 dirt
setblock ~32 ~122 ~90 dirt
setblock ~32 ~122 ~91 dirt
setblock ~32 ~122 ~92 dirt
setblock ~32 ~122 ~93 dirt
setblock ~32 ~122 ~94 dirt
setblock ~32 ~122 ~95 dirt
setblock ~32 ~122 ~96 dirt
setblock ~32 ~122 ~97 dirt
setblock ~32 ~122 ~98 dirt
setblock ~32 ~122 ~99 dirt
setblock ~32 ~122 ~100 dirt
setblock ~32 ~122 ~101 dirt
setblock ~32 ~122 ~102 dirt
setblock ~32 ~123 ~90 grass_block
setblock ~32 ~123 ~91 dirt
setblock ~32 ~123 ~92 dirt
setblock ~32 ~123 ~93 dirt
setblock ~32 ~123 ~94 dirt
setblock ~32 ~123 ~95 dirt
setblock ~32 ~123 ~96 dirt
setblock ~32 ~123 ~97 dirt
setblock ~32 ~123 ~98 dirt
setblock ~32 ~123 ~99 dirt
setblock ~32 ~123 ~100 dirt
setblock ~32 ~123 ~101 dirt
setblock ~32 ~123 ~102 dirt
setblock ~32 ~124 ~91 grass_block
setblock ~32 ~124 ~92 grass_block
setblock ~32 ~124 ~93 grass_block
setblock ~32 ~124 ~94 grass_block
setblock ~32 ~124 ~95 dirt
setblock ~32 ~124 ~96 dirt
setblock ~32 ~124 ~97 dirt
setblock ~32 ~124 ~98 dirt
setblock ~32 ~124 ~99 dirt
setblock ~32 ~124 ~100 dirt
setblock ~32 ~124 ~101 dirt
setblock ~32 ~124 ~102 dirt
setblock ~32 ~125 ~92 short_grass
setblock ~32 ~125 ~94 short_grass
setblock ~32 ~125 ~95 grass_block
setblock ~32 ~125 ~96 grass_block
setblock ~32 ~125 ~97 grass_block
setblock ~32 ~125 ~98 grass_block
setblock ~32 ~125 ~99 grass_block
setblock ~32 ~125 ~100 grass_block
setblock ~32 ~125 ~101 grass_block
setblock ~32 ~125 ~102 grass_block
setblock ~33 ~113 ~99 dirt
setblock ~33 ~114 ~99 dirt
setblock ~33 ~115 ~94 dirt
setblock ~33 ~115 ~99 dirt
setblock ~33 ~116 ~93 dirt
setblock ~33 ~116 ~94 dirt
setblock ~33 ~116 ~98 dirt
setblock ~33 ~116 ~99 dirt
setblock ~33 ~116 ~100 dirt
setblock ~33 ~117 ~92 dirt
setblock ~33 ~117 ~93 dirt
setblock ~33 ~117 ~94 dirt
setblock ~33 ~117 ~97 dirt
setblock ~33 ~117 ~98 dirt
setblock ~33 ~117 ~99 dirt
setblock ~33 ~117 ~100 dirt
setblock ~33 ~117 ~101 dirt
setblock ~33 ~118 ~91 dirt
setblock ~33 ~118 ~92 dirt
setblock ~33 ~118 ~93 dirt
setblock ~33 ~118 ~94 dirt
setblock ~33 ~118 ~95 dirt
setblock ~33 ~118 ~96 dirt
setblock ~33 ~118 ~97 dirt
setblock ~33 ~118 ~98 dirt
setblock ~33 ~118 ~99 dirt
setblock ~33 ~118 ~100 dirt
setblock ~33 ~118 ~101 dirt
setblock ~33 ~119 ~90 dirt
setblock ~33 ~119 ~91 dirt
setblock ~33 ~119 ~92 dirt
setblock ~33 ~119 ~93 dirt
setblock ~33 ~119 ~94 dirt
setblock ~33 ~119 ~95 dirt
setblock ~33 ~119 ~96 dirt
setblock ~33 ~119 ~97 dirt
setblock ~33 ~119 ~98 dirt
setblock ~33 ~119 ~99 dirt
setblock ~33 ~119 ~100 dirt
setblock ~33 ~119 ~101 dirt
setblock ~33 ~120 ~90 dirt
setblock ~33 ~120 ~91 dirt
setblock ~33 ~120 ~92 dirt
setblock ~33 ~120 ~93 dirt
setblock ~33 ~120 ~94 dirt
setblock ~33 ~120 ~95 dirt
setblock ~33 ~120 ~96 dirt
setblock ~33 ~120 ~97 dirt
setblock ~33 ~120 ~98 dirt
setblock ~33 ~120 ~99 dirt
setblock ~33 ~120 ~100 dirt
setblock ~33 ~120 ~101 dirt
setblock ~33 ~120 ~102 dirt
setblock ~33 ~120 ~106 dirt
setblock ~33 ~121 ~90 dirt
setblock ~33 ~121 ~91 dirt
setblock ~33 ~121 ~92 dirt
setblock ~33 ~121 ~93 dirt
setblock ~33 ~121 ~94 dirt
setblock ~33 ~121 ~95 dirt
setblock ~33 ~121 ~96 dirt
setblock ~33 ~121 ~97 dirt
setblock ~33 ~121 ~98 dirt
setblock ~33 ~121 ~99 dirt
setblock ~33 ~121 ~100 dirt
setblock ~33 ~121 ~101 dirt
setblock ~33 ~121 ~102 dirt
setblock ~33 ~121 ~103 dirt
setblock ~33 ~121 ~106 dirt
setblock ~33 ~122 ~90 dirt
setblock ~33 ~122 ~91 dirt
setblock ~33 ~122 ~92 dirt
setblock ~33 ~122 ~93 dirt
setblock ~33 ~122 ~94 dirt
setblock ~33 ~122 ~95 dirt
setblock ~33 ~122 ~96 dirt
setblock ~33 ~122 ~97 dirt
setblock ~33 ~122 ~98 dirt
setblock ~33 ~122 ~99 dirt
setblock ~33 ~122 ~100 dirt
setblock ~33 ~122 ~101 dirt
setblock ~33 ~122 ~102 dirt
setblock ~33 ~122 ~103 dirt
setblock ~33 ~122 ~106 dirt
setblock ~33 ~123 ~90 dirt
setblock ~33 ~123 ~91 dirt
setblock ~33 ~123 ~92 dirt
setblock ~33 ~123 ~93 dirt
setblock ~33 ~123 ~94 dirt
setblock ~33 ~123 ~95 dirt
setblock ~33 ~123 ~96 dirt
setblock ~33 ~123 ~97 dirt
setblock ~33 ~123 ~98 dirt
setblock ~33 ~123 ~99 dirt
setblock ~33 ~123 ~100 dirt
setblock ~33 ~123 ~101 dirt
setblock ~33 ~123 ~102 dirt
setblock ~33 ~123 ~103 dirt
setblock ~33 ~123 ~106 dirt
setblock ~33 ~124 ~90 grass_block
setblock ~33 ~124 ~91 grass_block
setblock ~33 ~124 ~92 grass_block
setblock ~33 ~124 ~93 dirt
setblock ~33 ~124 ~94 dirt
setblock ~33 ~124 ~95 dirt
setblock ~33 ~124 ~96 dirt
setblock ~33 ~124 ~97 dirt
setblock ~33 ~124 ~98 dirt
setblock ~33 ~124 ~99 dirt
setblock ~33 ~124 ~100 dirt
setblock ~33 ~124 ~101 dirt
setblock ~33 ~124 ~102 dirt
setblock ~33 ~124 ~103 dirt
setblock ~33 ~124 ~106 dirt
setblock ~33 ~125 ~91 short_grass
setblock ~33 ~125 ~93 grass_block
setblock ~33 ~125 ~94 grass_block
setblock ~33 ~125 ~95 grass_block
setblock ~33 ~125 ~96 grass_block
setblock ~33 ~125 ~97 grass_block
setblock ~33 ~125 ~98 grass_block
setblock ~33 ~125 ~99 grass_block
setblock ~33 ~125 ~100 grass_block
setblock ~33 ~125 ~101 grass_block
setblock ~33 ~125 ~102 grass_block
setblock ~33 ~125 ~103 grass_block
setblock ~33 ~125 ~106 grass_block
setblock ~33 ~126 ~94 short_grass
setblock ~33 ~126 ~96 short_grass
setblock ~33 ~126 ~101 short_grass
setblock ~34 ~112 ~99 dirt
setblock ~34 ~113 ~98 dirt
setblock ~34 ~113 ~99 dirt
setblock ~34 ~113 ~100 dirt
setblock ~34 ~114 ~94 dirt
setblock ~34 ~114 ~98 dirt
setblock ~34 ~114 ~99 dirt
setblock ~34 ~114 ~100 dirt
setblock ~34 ~115 ~93 dirt
setblock ~34 ~115 ~94 dirt
setblock ~34 ~115 ~95 dirt
setblock ~34 ~115 ~97 dirt
setblock ~34 ~115 ~98 dirt
setblock ~34 ~115 ~99 dirt
setblock ~34 ~115 ~100 dirt
setblock ~34 ~116 ~92 dirt
setblock ~34 ~116 ~93 dirt
setblock ~34 ~116 ~94 dirt
setblock ~34 ~116 ~95 dirt
setblock ~34 ~116 ~97 dirt
setblock ~34 ~116 ~98 dirt
setblock ~34 ~116 ~99 dirt
setblock ~34 ~116 ~100 dirt
setblock ~34 ~116 ~101 dirt
setblock ~34 ~117 ~91 dirt
setblock ~34 ~117 ~92 dirt
setblock ~34 ~117 ~93 dirt
setblock ~34 ~117 ~94 dirt
setblock ~34 ~117 ~95 dirt
setblock ~34 ~117 ~96 dirt
setblock ~34 ~117 ~97 dirt
setblock ~34 ~117 ~98 dirt
setblock ~34 ~117 ~99 dirt
setblock ~34 ~117 ~100 dirt
setblock ~34 ~117 ~101 dirt
setblock ~34 ~117 ~102 dirt
setblock ~34 ~118 ~90 dirt
setblock ~34 ~118 ~91 dirt
setblock ~34 ~118 ~92 dirt
setblock ~34 ~118 ~93 dirt
setblock ~34 ~118 ~94 dirt
setblock ~34 ~118 ~95 dirt
setblock ~34 ~118 ~96 dirt
setblock ~34 ~118 ~97 dirt
setblock ~34 ~118 ~98 dirt
setblock ~34 ~118 ~99 dirt
setblock ~34 ~118 ~100 dirt
setblock ~34 ~118 ~101 dirt
setblock ~34 ~118 ~102 dirt
setblock ~34 ~119 ~89 dirt
setblock ~34 ~119 ~90 dirt
setblock ~34 ~119 ~91 dirt
setblock ~34 ~119 ~92 dirt
setblock ~34 ~119 ~93 dirt
setblock ~34 ~119 ~94 dirt
setblock ~34 ~119 ~95 dirt
setblock ~34 ~119 ~96 dirt
setblock ~34 ~119 ~97 dirt
setblock ~34 ~119 ~98 dirt
setblock ~34 ~119 ~99 dirt
setblock ~34 ~119 ~100 dirt
setblock ~34 ~119 ~101 dirt
setblock ~34 ~119 ~102 dirt
setblock ~34 ~119 ~104 dirt
setblock ~34 ~119 ~105 dirt
setblock ~34 ~119 ~106 dirt
setblock ~34 ~120 ~89 dirt
setblock ~34 ~120 ~90 dirt
setblock ~34 ~120 ~91 dirt
setblock ~34 ~120 ~92 dirt
setblock ~34 ~120 ~93 dirt
setblock ~34 ~120 ~94 dirt
setblock ~34 ~120 ~95 dirt
setblock ~34 ~120 ~96 dirt
setblock ~34 ~120 ~97 dirt
setblock ~34 ~120 ~98 dirt
setblock ~34 ~120 ~99 dirt
setblock ~34 ~120 ~100 dirt
setblock ~34 ~120 ~101 dirt
setblock ~34 ~120 ~102 dirt
setblock ~34 ~120 ~103 dirt
setblock ~34 ~120 ~104 dirt
setblock ~34 ~120 ~105 dirt
setblock ~34 ~120 ~106 dirt
setblock ~34 ~120 ~107 dirt
setblock ~34 ~121 ~89 dirt
setblock ~34 ~121 ~90 dirt
setblock ~34 ~121 ~91 dirt
setblock ~34 ~121 ~92 dirt
setblock ~34 ~121 ~93 dirt
setblock ~34 ~121 ~94 dirt
setblock ~34 ~121 ~95 dirt
setblock ~34 ~121 ~96 dirt
setblock ~34 ~121 ~97 dirt
setblock ~34 ~121 ~98 dirt
setblock ~34 ~121 ~99 dirt
setblock ~34 ~121 ~100 dirt
setblock ~34 ~121 ~101 dirt
setblock ~34 ~121 ~102 dirt
setblock ~34 ~121 ~103 dirt
setblock ~34 ~121 ~104 dirt
setblock ~34 ~121 ~105 dirt
setblock ~34 ~121 ~106 dirt
setblock ~34 ~121 ~107 dirt
setblock ~34 ~121 ~108 dirt
setblock ~34 ~122 ~89 dirt
setblock ~34 ~122 ~90 dirt
setblock ~34 ~122 ~91 dirt
setblock ~34 ~122 ~92 dirt
setblock ~34 ~122 ~93 dirt
setblock ~34 ~122 ~94 dirt
setblock ~34 ~122 ~95 dirt
setblock ~34 ~122 ~96 dirt
setblock ~34 ~122 ~97 dirt
setblock ~34 ~122 ~98 dirt
setblock ~34 ~122 ~99 dirt
setblock ~34 ~122 ~100 dirt
setblock ~34 ~122 ~101 dirt
setblock ~34 ~122 ~102 dirt
setblock ~34 ~122 ~103 dirt
setblock ~34 ~122 ~104 dirt
setblock ~34 ~122 ~105 dirt
setblock ~34 ~122 ~106 dirt
setblock ~34 ~122 ~107 dirt
setblock ~34 ~122 ~108 dirt
setblock ~34 ~123 ~89 dirt
setblock ~34 ~123 ~90 dirt
setblock ~34 ~123 ~91 dirt
setblock ~34 ~123 ~92 dirt
setblock ~34 ~123 ~93 dirt
setblock ~34 ~123 ~94 dirt
setblock ~34 ~123 ~95 dirt
setblock ~34 ~123 ~96 dirt
setblock ~34 ~123 ~97 dirt
setblock ~34 ~123 ~98 dirt
setblock ~34 ~123 ~99 dirt
setblock ~34 ~123 ~100 dirt
setblock ~34 ~123 ~101 dirt
setblock ~34 ~123 ~102 dirt
setblock ~34 ~123 ~103 dirt
setblock ~34 ~123 ~104 dirt
setblock ~34 ~123 ~105 dirt
setblock ~34 ~123 ~106 dirt
setblock ~34 ~123 ~107 dirt
setblock ~34 ~123 ~108 dirt
setblock ~34 ~124 ~89 dirt
setblock ~34 ~124 ~90 dirt
setblock ~34 ~124 ~91 dirt
setblock ~34 ~124 ~92 dirt
setblock ~34 ~124 ~93 dirt
setblock ~34 ~124 ~94 dirt
setblock ~34 ~124 ~95 dirt
setblock ~34 ~124 ~96 dirt
setblock ~34 ~124 ~97 dirt
setblock ~34 ~124 ~98 dirt
setblock ~34 ~124 ~99 dirt
setblock ~34 ~124 ~100 dirt
setblock ~34 ~124 ~101 dirt
setblock ~34 ~124 ~102 dirt
setblock ~34 ~124 ~103 dirt
setblock ~34 ~124 ~104 dirt
setblock ~34 ~124 ~105 dirt
setblock ~34 ~124 ~106 dirt
setblock ~34 ~124 ~107 dirt
setblock ~34 ~124 ~108 dirt
setblock ~34 ~125 ~89 grass_block
setblock ~34 ~125 ~90 grass_block
setblock ~34 ~125 ~91 grass_block
setblock ~34 ~125 ~92 grass_block
setblock ~34 ~125 ~93 grass_block
setblock ~34 ~125 ~94 grass_block
setblock ~34 ~125 ~95 grass_block
setblock ~34 ~125 ~96 grass_block
setblock ~34 ~125 ~97 grass_block
setblock ~34 ~125 ~98 grass_block
setblock ~34 ~125 ~99 grass_block
setblock ~34 ~125 ~100 grass_block
setblock ~34 ~125 ~101 grass_block
setblock ~34 ~125 ~102 grass_block
setblock ~34 ~125 ~103 grass_block
setblock ~34 ~125 ~104 grass_block
setblock ~34 ~125 ~105 grass_block
setblock ~34 ~125 ~106 grass_block
setblock ~34 ~125 ~107 grass_block
setblock ~34 ~125 ~108 grass_block
setblock ~34 ~126 ~95 short_grass
setblock ~34 ~126 ~100 short_grass
setblock ~35 ~111 ~98 dirt
setblock ~35 ~111 ~99 dirt
setblock ~35 ~112 ~98 dirt
setblock ~35 ~112 ~99 dirt
setblock ~35 ~112 ~100 dirt
setblock ~35 ~113 ~94 dirt
setblock ~35 ~113 ~97 dirt
setblock ~35 ~113 ~98 dirt
setblock ~35 ~113 ~99 dirt
setblock ~35 ~113 ~100 dirt
setblock ~35 ~113 ~101 dirt
setblock ~35 ~114 ~93 dirt
setblock ~35 ~114 ~94 dirt
setblock ~35 ~114 ~95 dirt
setblock ~35 ~114 ~96 dirt
setblock ~35 ~114 ~97 dirt
setblock ~35 ~114 ~98 dirt
setblock ~35 ~114 ~99 dirt
setblock ~35 ~114 ~100 dirt
setblock ~35 ~114 ~101 dirt
setblock ~35 ~115 ~92 dirt
setblock ~35 ~115 ~93 dirt
setblock ~35 ~115 ~94 dirt
setblock ~35 ~115 ~95 dirt
setblock ~35 ~115 ~96 dirt
setblock ~35 ~115 ~97 dirt
setblock ~35 ~115 ~98 dirt
setblock ~35 ~115 ~99 dirt
setblock ~35 ~115 ~100 dirt
setblock ~35 ~115 ~101 dirt
setblock ~35 ~116 ~91 dirt
setblock ~35 ~116 ~92 dirt
setblock ~35 ~116 ~93 dirt
setblock ~35 ~116 ~94 dirt
setblock ~35 ~116 ~95 dirt
setblock ~35 ~116 ~96 dirt
setblock ~35 ~116 ~97 dirt
setblock ~35 ~116 ~98 dirt
setblock ~35 ~116 ~99 dirt
setblock ~35 ~116 ~100 dirt
setblock ~35 ~116 ~101 dirt
setblock ~35 ~116 ~102 dirt
setblock ~35 ~116 ~104 dirt
setblock ~35 ~117 ~90 dirt
setblock ~35 ~117 ~91 dirt
setblock ~35 ~117 ~92 dirt
setblock ~35 ~117 ~93 dirt
setblock ~35 ~117 ~94 dirt
setblock ~35 ~117 ~95 dirt
setblock ~35 ~117 ~96 dirt
setblock ~35 ~117 ~97 dirt
setblock ~35 ~117 ~98 dirt
setblock ~35 ~117 ~99 dirt
setblock ~35 ~117 ~100 dirt
setblock ~35 ~117 ~101 dirt
setblock ~35 ~117 ~102 dirt
setblock ~35 ~117 ~104 dirt
setblock ~35 ~117 ~105 dirt
setblock ~35 ~118 ~90 dirt
setblock ~35 ~118 ~91 dirt
setblock ~35 ~118 ~92 dirt
setblock ~35 ~118 ~93 dirt
setblock ~35 ~118 ~94 dirt
setblock ~35 ~118 ~95 dirt
setblock ~35 ~118 ~96 dirt
setblock ~35 ~118 ~97 dirt
setblock ~35 ~118 ~98 dirt
setblock ~35 ~118 ~99 dirt
setblock ~35 ~118 ~100 dirt
setblock ~35 ~118 ~101 dirt
setblock ~35 ~118 ~102 dirt
setblock ~35 ~118 ~103 dirt
setblock ~35 ~118 ~104 dirt
setblock ~35 ~118 ~105 dirt
setblock ~35 ~118 ~106 dirt
setblock ~35 ~119 ~90 dirt
setblock ~35 ~119 ~91 dirt
setblock ~35 ~119 ~92 dirt
setblock ~35 ~119 ~93 dirt
setblock ~35 ~119 ~94 dirt
setblock ~35 ~119 ~95 dirt
setblock ~35 ~119 ~96 dirt
setblock ~35 ~119 ~97 dirt
setblock ~35 ~119 ~98 dirt
setblock ~35 ~119 ~99 dirt
setblock ~35 ~119 ~100 dirt
setblock ~35 ~119 ~101 dirt
setblock ~35 ~119 ~102 dirt
setblock ~35 ~119 ~103 dirt
setblock ~35 ~119 ~104 dirt
setblock ~35 ~119 ~105 dirt
setblock ~35 ~119 ~106 dirt
setblock ~35 ~119 ~107 dirt
setblock ~35 ~119 ~108 dirt
setblock ~35 ~120 ~89 dirt
setblock ~35 ~120 ~90 dirt
setblock ~35 ~120 ~91 dirt
setblock ~35 ~120 ~92 dirt
setblock ~35 ~120 ~93 dirt
setblock ~35 ~120 ~94 dirt
setblock ~35 ~120 ~95 dirt
setblock ~35 ~120 ~96 dirt
setblock ~35 ~120 ~97 dirt
setblock ~35 ~120 ~98 dirt
setblock ~35 ~120 ~99 dirt
setblock ~35 ~120 ~100 dirt
setblock ~35 ~120 ~101 dirt
setblock ~35 ~120 ~102 dirt
setblock ~35 ~120 ~103 dirt
setblock ~35 ~120 ~104 dirt
setblock ~35 ~120 ~105 dirt
setblock ~35 ~120 ~106 dirt
setblock ~35 ~120 ~107 dirt
setblock ~35 ~120 ~108 dirt
setblock ~35 ~121 ~88 dirt
setblock ~35 ~121 ~89 dirt
setblock ~35 ~121 ~90 dirt
setblock ~35 ~121 ~91 dirt
setblock ~35 ~121 ~92 dirt
setblock ~35 ~121 ~93 dirt
setblock ~35 ~121 ~94 dirt
setblock ~35 ~121 ~95 dirt
setblock ~35 ~121 ~96 dirt
setblock ~35 ~121 ~97 dirt
setblock ~35 ~121 ~98 dirt
setblock ~35 ~121 ~99 dirt
setblock ~35 ~121 ~100 dirt
setblock ~35 ~121 ~101 dirt
setblock ~35 ~121 ~102 dirt
setblock ~35 ~121 ~103 dirt
setblock ~35 ~121 ~104 dirt
setblock ~35 ~121 ~105 dirt
setblock ~35 ~121 ~106 dirt
setblock ~35 ~121 ~107 dirt
setblock ~35 ~121 ~108 dirt
setblock ~35 ~121 ~109 dirt
setblock ~35 ~121 ~110 dirt
setblock ~35 ~121 ~123 dirt
setblock ~35 ~121 ~125 dirt
setblock ~35 ~121 ~130 dirt
setblock ~35 ~122 ~88 dirt
setblock ~35 ~122 ~89 dirt
setblock ~35 ~122 ~90 dirt
setblock ~35 ~122 ~91 dirt
setblock ~35 ~122 ~92 dirt
setblock ~35 ~122 ~93 dirt
setblock ~35 ~122 ~94 dirt
setblock ~35 ~122 ~95 dirt
setblock ~35 ~122 ~96 dirt
setblock ~35 ~122 ~97 dirt
setblock ~35 ~122 ~98 dirt
setblock ~35 ~122 ~99 dirt
setblock ~35 ~122 ~100 dirt
setblock ~35 ~122 ~101 dirt
setblock ~35 ~122 ~102 dirt
setblock ~35 ~122 ~103 dirt
setblock ~35 ~122 ~104 dirt
setblock ~35 ~122 ~105 dirt
setblock ~35 ~122 ~106 dirt
setblock ~35 ~122 ~107 dirt
setblock ~35 ~122 ~108 dirt
setblock ~35 ~122 ~109 dirt
setblock ~35 ~122 ~110 dirt
setblock ~35 ~122 ~123 dirt
setblock ~35 ~122 ~125 dirt
setblock ~35 ~122 ~130 dirt
setblock ~35 ~123 ~88 dirt
setblock ~35 ~123 ~89 dirt
setblock ~35 ~123 ~90 dirt
setblock ~35 ~123 ~91 dirt
setblock ~35 ~123 ~92 dirt
setblock ~35 ~123 ~93 dirt
setblock ~35 ~123 ~94 dirt
setblock ~35 ~123 ~95 dirt
setblock ~35 ~123 ~96 dirt
setblock ~35 ~123 ~97 dirt
setblock ~35 ~123 ~98 dirt
setblock ~35 ~123 ~99 dirt
setblock ~35 ~123 ~100 dirt
setblock ~35 ~123 ~101 dirt
setblock ~35 ~123 ~102 dirt
setblock ~35 ~123 ~103 dirt
setblock ~35 ~123 ~104 dirt
setblock ~35 ~123 ~105 dirt
setblock ~35 ~123 ~106 dirt
setblock ~35 ~123 ~107 dirt
setblock ~35 ~123 ~108 dirt
setblock ~35 ~123 ~109 dirt
setblock ~35 ~123 ~110 dirt
setblock ~35 ~123 ~123 dirt
setblock ~35 ~123 ~125 dirt
setblock ~35 ~123 ~130 dirt
setblock ~35 ~124 ~88 dirt
setblock ~35 ~124 ~89 dirt
setblock ~35 ~124 ~90 dirt
setblock ~35 ~124 ~91 dirt
setblock ~35 ~124 ~92 dirt
setblock ~35 ~124 ~93 dirt
setblock ~35 ~124 ~94 dirt
setblock ~35 ~124 ~95 dirt
setblock ~35 ~124 ~96 dirt
setblock ~35 ~124 ~97 dirt
setblock ~35 ~124 ~98 dirt
setblock ~35 ~124 ~99 dirt
setblock ~35 ~124 ~100 dirt
setblock ~35 ~124 ~101 dirt
setblock ~35 ~124 ~102 dirt
setblock ~35 ~124 ~103 dirt
setblock ~35 ~124 ~104 dirt
setblock ~35 ~124 ~105 dirt
setblock ~35 ~124 ~106 dirt
setblock ~35 ~124 ~107 dirt
setblock ~35 ~124 ~108 dirt
setblock ~35 ~124 ~109 dirt
setblock ~35 ~124 ~110 dirt
setblock ~35 ~124 ~123 grass_block
setblock ~35 ~124 ~125 grass_block
setblock ~35 ~124 ~130 dirt
setblock ~35 ~125 ~88 dirt
setblock ~35 ~125 ~89 dirt
setblock ~35 ~125 ~90 dirt
setblock ~35 ~125 ~91 dirt
setblock ~35 ~125 ~92 dirt
setblock ~35 ~125 ~93 dirt
setblock ~35 ~125 ~94 dirt
setblock ~35 ~125 ~95 grass_block
setblock ~35 ~125 ~96 grass_block
setblock ~35 ~125 ~97 grass_block
setblock ~35 ~125 ~98 grass_block
setblock ~35 ~125 ~99 grass_block
setblock ~35 ~125 ~100 grass_block
setblock ~35 ~125 ~101 grass_block
setblock ~35 ~125 ~102 grass_block
setblock ~35 ~125 ~103 grass_block
setblock ~35 ~125 ~104 grass_block
setblock ~35 ~125 ~105 grass_block
setblock ~35 ~125 ~106 grass_block
setblock ~35 ~125 ~107 grass_block
setblock ~35 ~125 ~108 grass_block
setblock ~35 ~125 ~109 grass_block
setblock ~35 ~125 ~110 grass_block
setblock ~35 ~125 ~130 dirt
setblock ~35 ~126 ~88 grass_block
setblock ~35 ~126 ~89 grass_block
setblock ~35 ~126 ~90 grass_block
setblock ~35 ~126 ~91 grass_block
setblock ~35 ~126 ~92 grass_block
setblock ~35 ~126 ~93 grass_block
setblock ~35 ~126 ~94 grass_block
setblock ~35 ~126 ~97 short_grass
setblock ~35 ~126 ~99 poppy
setblock ~35 ~126 ~101 short_grass
setblock ~35 ~126 ~110 short_grass
setblock ~35 ~126 ~130 grass_block
setblock ~35 ~127 ~92 short_grass
setblock ~35 ~127 ~93 short_grass
setblock ~36 ~109 ~98 dirt
setblock ~36 ~110 ~97 dirt
setblock ~36 ~110 ~98 dirt
setblock ~36 ~110 ~99 dirt
setblock ~36 ~111 ~97 dirt
setblock ~36 ~111 ~98 dirt
setblock ~36 ~111 ~99 dirt
setblock ~36 ~111 ~100 dirt
setblock ~36 ~112 ~94 dirt
setblock ~36 ~112 ~95 dirt
setblock ~36 ~112 ~96 dirt
setblock ~36 ~112 ~97 dirt
setblock ~36 ~112 ~98 dirt
setblock ~36 ~112 ~99 dirt
setblock ~36 ~112 ~100 dirt
setblock ~36 ~112 ~101 dirt
setblock ~36 ~113 ~93 dirt
setblock ~36 ~113 ~94 dirt
setblock ~36 ~113 ~95 dirt
setblock ~36 ~113 ~96 dirt
setblock ~36 ~113 ~97 dirt
setblock ~36 ~113 ~98 dirt
setblock ~36 ~113 ~99 dirt
setblock ~36 ~113 ~100 dirt
setblock ~36 ~113 ~101 dirt
setblock ~36 ~113 ~102 dirt
setblock ~36 ~113 ~104 dirt
setblock ~36 ~114 ~92 dirt
setblock ~36 ~114 ~93 dirt
setblock ~36 ~114 ~94 dirt
setblock ~36 ~114 ~95 dirt
setblock ~36 ~114 ~96 dirt
setblock ~36 ~114 ~97 dirt
setblock ~36 ~114 ~98 dirt
setblock ~36 ~114 ~99 dirt
setblock ~36 ~114 ~100 dirt
setblock ~36 ~114 ~101 dirt
setblock ~36 ~114 ~102 dirt
setblock ~36 ~114 ~103 dirt
setblock ~36 ~114 ~104 dirt
setblock ~36 ~115 ~92 dirt
setblock ~36 ~115 ~93 dirt
setblock ~36 ~115 ~94 dirt
setblock ~36 ~115 ~95 dirt
setblock ~36 ~115 ~96 dirt
setblock ~36 ~115 ~97 dirt
setblock ~36 ~115 ~98 dirt
setblock ~36 ~115 ~99 dirt
setblock ~36 ~115 ~100 dirt
setblock ~36 ~115 ~101 dirt
setblock ~36 ~115 ~102 dirt
setblock ~36 ~115 ~103 dirt
setblock ~36 ~115 ~104 dirt
setblock ~36 ~115 ~105 dirt
setblock ~36 ~116 ~92 dirt
setblock ~36 ~116 ~93 dirt
setblock ~36 ~116 ~94 dirt
setblock ~36 ~116 ~95 dirt
setblock ~36 ~116 ~96 dirt
setblock ~36 ~116 ~97 dirt
setblock ~36 ~116 ~98 dirt
setblock ~36 ~116 ~99 dirt
setblock ~36 ~116 ~100 dirt
setblock ~36 ~116 ~101 dirt
setblock ~36 ~116 ~102 dirt
setblock ~36 ~116 ~103 dirt
setblock ~36 ~116 ~104 dirt
setblock ~36 ~116 ~105 dirt
setblock ~36 ~116 ~106 dirt
setblock ~36 ~117 ~91 dirt
setblock ~36 ~117 ~92 dirt
setblock ~36 ~117 ~93 dirt
setblock ~36 ~117 ~94 dirt
setblock ~36 ~117 ~95 dirt
setblock ~36 ~117 ~96 dirt
setblock ~36 ~117 ~97 dirt
setblock ~36 ~117 ~98 dirt
setblock ~36 ~117 ~99 dirt
setblock ~36 ~117 ~100 dirt
setblock ~36 ~117 ~101 dirt
setblock ~36 ~117 ~102 dirt
setblock ~36 ~117 ~103 dirt
setblock ~36 ~117 ~104 dirt
setblock ~36 ~117 ~105 dirt
setblock ~36 ~117 ~106 dirt
setblock ~36 ~117 ~107 dirt
setblock ~36 ~117 ~108 dirt
setblock ~36 ~118 ~90 dirt
setblock ~36 ~118 ~91 dirt
setblock ~36 ~118 ~92 dirt
setblock ~36 ~118 ~93 dirt
setblock ~36 ~118 ~94 dirt
setblock ~36 ~118 ~95 dirt
setblock ~36 ~118 ~96 dirt
setblock ~36 ~118 ~97 dirt
setblock ~36 ~118 ~98 dirt
setblock ~36 ~118 ~99 dirt
setblock ~36 ~118 ~100 dirt
setblock ~36 ~118 ~101 dirt
setblock ~36 ~118 ~102 dirt
setblock ~36 ~118 ~103 dirt
setblock ~36 ~118 ~104 dirt
setblock ~36 ~118 ~105 dirt
setblock ~36 ~118 ~106 dirt
setblock ~36 ~118 ~107 dirt
setblock ~36 ~118 ~108 dirt
setblock ~36 ~118 ~109 dirt
setblock ~36 ~119 ~89 dirt
setblock ~36 ~119 ~90 dirt
setblock ~36 ~119 ~91 dirt
setblock ~36 ~119 ~92 dirt
setblock ~36 ~119 ~93 dirt
setblock ~36 ~119 ~94 dirt
setblock ~36 ~119 ~95 dirt
setblock ~36 ~119 ~96 dirt
setblock ~36 ~119 ~97 dirt
setblock ~36 ~119 ~98 dirt
setblock ~36 ~119 ~99 dirt
setblock ~36 ~119 ~100 dirt
setblock ~36 ~119 ~101 dirt
setblock ~36 ~119 ~102 dirt
setblock ~36 ~119 ~103 dirt
setblock ~36 ~119 ~104 dirt
setblock ~36 ~119 ~105 dirt
setblock ~36 ~119 ~106 dirt
setblock ~36 ~119 ~107 dirt
setblock ~36 ~119 ~108 dirt
setblock ~36 ~119 ~109 dirt
setblock ~36 ~119 ~110 dirt
setblock ~36 ~119 ~124 dirt
setblock ~36 ~119 ~125 dirt
setblock ~36 ~119 ~129 dirt
setblock ~36 ~120 ~88 dirt
setblock ~36 ~120 ~89 dirt
setblock ~36 ~120 ~90 dirt
setblock ~36 ~120 ~91 dirt
setblock ~36 ~120 ~92 dirt
setblock ~36 ~120 ~93 dirt
setblock ~36 ~120 ~94 dirt
setblock ~36 ~120 ~95 dirt
setblock ~36 ~120 ~96 dirt
setblock ~36 ~120 ~97 dirt
setblock ~36 ~120 ~98 dirt
setblock ~36 ~120 ~99 dirt
setblock ~36 ~120 ~100 dirt
setblock ~36 ~120 ~101 dirt
setblock ~36 ~120 ~102 dirt
setblock ~36 ~120 ~103 dirt
setblock ~36 ~120 ~104 dirt
setblock ~36 ~120 ~105 dirt
setblock ~36 ~120 ~106 dirt
setblock ~36 ~120 ~107 dirt
setblock ~36 ~120 ~108 dirt
setblock ~36 ~120 ~109 dirt
setblock ~36 ~120 ~110 dirt
setblock ~36 ~120 ~123 dirt
setblock ~36 ~120 ~124 dirt
setblock ~36 ~120 ~125 dirt
setblock ~36 ~120 ~126 dirt
setblock ~36 ~120 ~128 dirt
setblock ~36 ~120 ~129 dirt
setblock ~36 ~120 ~130 dirt
setblock ~36 ~121 ~72 dirt
setblock ~36 ~121 ~88 dirt
setblock ~36 ~121 ~89 dirt
setblock ~36 ~121 ~90 dirt
setblock ~36 ~121 ~91 dirt
setblock ~36 ~121 ~92 dirt
setblock ~36 ~121 ~93 dirt
setblock ~36 ~121 ~94 dirt
setblock ~36 ~121 ~95 dirt
setblock ~36 ~121 ~96 dirt
setblock ~36 ~121 ~97 dirt
setblock ~36 ~121 ~98 dirt
setblock ~36 ~121 ~99 dirt
setblock ~36 ~121 ~100 dirt
setblock ~36 ~121 ~101 dirt
setblock ~36 ~121 ~102 dirt
setblock ~36 ~121 ~103 dirt
setblock ~36 ~121 ~104 dirt
setblock ~36 ~121 ~105 dirt
setblock ~36 ~121 ~106 dirt
setblock ~36 ~121 ~107 dirt
setblock ~36 ~121 ~108 dirt
setblock ~36 ~121 ~109 dirt
setblock ~36 ~121 ~110 dirt
setblock ~36 ~121 ~111 dirt
setblock ~36 ~121 ~122 dirt
setblock ~36 ~121 ~123 dirt
setblock ~36 ~121 ~124 dirt
setblock ~36 ~121 ~125 dirt
setblock ~36 ~121 ~126 dirt
setblock ~36 ~121 ~127 dirt
setblock ~36 ~121 ~128 dirt
setblock ~36 ~121 ~129 dirt
setblock ~36 ~121 ~130 dirt
setblock ~36 ~121 ~131 dirt
setblock ~36 ~121 ~134 dirt
setblock ~36 ~122 ~72 dirt
setblock ~36 ~122 ~88 dirt
setblock ~36 ~122 ~89 dirt
setblock ~36 ~122 ~90 dirt
setblock ~36 ~122 ~91 dirt
setblock ~36 ~122 ~92 dirt
setblock ~36 ~122 ~93 dirt
setblock ~36 ~122 ~94 dirt
setblock ~36 ~122 ~95 dirt
setblock ~36 ~122 ~96 dirt
setblock ~36 ~122 ~97 dirt
setblock ~36 ~122 ~98 dirt
setblock ~36 ~122 ~99 dirt
setblock ~36 ~122 ~100 dirt
setblock ~36 ~122 ~101 dirt
setblock ~36 ~122 ~102 dirt
setblock ~36 ~122 ~103 dirt
setblock ~36 ~122 ~104 dirt
setblock ~36 ~122 ~105 dirt
setblock ~36 ~122 ~106 dirt
setblock ~36 ~122 ~107 dirt
setblock ~36 ~122 ~108 dirt
setblock ~36 ~122 ~109 dirt
setblock ~36 ~122 ~110 dirt
setblock ~36 ~122 ~111 dirt
setblock ~36 ~122 ~122 dirt
setblock ~36 ~122 ~123 dirt
setblock ~36 ~122 ~124 dirt
setblock ~36 ~122 ~125 dirt
setblock ~36 ~122 ~126 dirt
setblock ~36 ~122 ~127 dirt
setblock ~36 ~122 ~128 dirt
setblock ~36 ~122 ~129 dirt
setblock ~36 ~122 ~130 dirt
setblock ~36 ~122 ~131 dirt
setblock ~36 ~122 ~134 dirt
setblock ~36 ~123 ~72 dirt
setblock ~36 ~123 ~88 dirt
setblock ~36 ~123 ~89 dirt
setblock ~36 ~123 ~90 dirt
setblock ~36 ~123 ~91 dirt
setblock ~36 ~123 ~92 dirt
setblock ~36 ~123 ~93 dirt
setblock ~36 ~123 ~94 dirt
setblock ~36 ~123 ~95 dirt
setblock ~36 ~123 ~96 dirt
setblock ~36 ~123 ~97 dirt
setblock ~36 ~123 ~98 dirt
setblock ~36 ~123 ~99 dirt
setblock ~36 ~123 ~100 dirt
setblock ~36 ~123 ~101 dirt
setblock ~36 ~123 ~102 dirt
setblock ~36 ~123 ~103 dirt
setblock ~36 ~123 ~104 dirt
setblock ~36 ~123 ~105 dirt
setblock ~36 ~123 ~106 dirt
setblock ~36 ~123 ~107 dirt
setblock ~36 ~123 ~108 dirt
setblock ~36 ~123 ~109 dirt
setblock ~36 ~123 ~110 dirt
setblock ~36 ~123 ~111 dirt
setblock ~36 ~123 ~122 grass_block
setblock ~36 ~123 ~123 grass_block
setblock ~36 ~123 ~124 dirt
setblock ~36 ~123 ~125 dirt
setblock ~36 ~123 ~126 dirt
setblock ~36 ~123 ~127 dirt
setblock ~36 ~123 ~128 dirt
setblock ~36 ~123 ~129 dirt
setblock ~36 ~123 ~130 dirt
setblock ~36 ~123 ~131 dirt
setblock ~36 ~123 ~134 dirt
setblock ~36 ~124 ~72 dirt
setblock ~36 ~124 ~88 dirt
setblock ~36 ~124 ~89 dirt
setblock ~36 ~124 ~90 dirt
setblock ~36 ~124 ~91 dirt
setblock ~36 ~124 ~92 dirt
setblock ~36 ~124 ~93 dirt
setblock ~36 ~124 ~94 dirt
setblock ~36 ~124 ~95 dirt
setblock ~36 ~124 ~96 dirt
setblock ~36 ~124 ~97 dirt
setblock ~36 ~124 ~98 dirt
setblock ~36 ~124 ~99 dirt
setblock ~36 ~124 ~100 dirt
setblock ~36 ~124 ~101 dirt
setblock ~36 ~124 ~102 dirt
setblock ~36 ~124 ~103 dirt
setblock ~36 ~124 ~104 dirt
setblock ~36 ~124 ~105 dirt
setblock ~36 ~124 ~106 dirt
setblock ~36 ~124 ~107 dirt
setblock ~36 ~124 ~108 dirt
setblock ~36 ~124 ~109 dirt
setblock ~36 ~124 ~110 grass_block
setblock ~36 ~124 ~111 grass_block
setblock ~36 ~124 ~124 grass_block
setblock ~36 ~124 ~125 grass_block
setblock ~36 ~124 ~126 grass_block
setblock ~36 ~124 ~127 dirt
setblock ~36 ~124 ~128 dirt
setblock ~36 ~124 ~129 dirt
setblock ~36 ~124 ~130 dirt
setblock ~36 ~124 ~131 dirt
setblock ~36 ~124 ~134 dirt
setblock ~36 ~125 ~72 dirt
setblock ~36 ~125 ~88 dirt
setblock ~36 ~125 ~89 dirt
setblock ~36 ~125 ~90 dirt
setblock ~36 ~125 ~91 dirt
setblock ~36 ~125 ~92 dirt
setblock ~36 ~125 ~93 dirt
setblock ~36 ~125 ~94 dirt
setblock ~36 ~125 ~95 dirt
setblock ~36 ~125 ~96 dirt
setblock ~36 ~125 ~97 dirt
setblock ~36 ~125 ~98 dirt
setblock ~36 ~125 ~99 grass_block
setblock ~36 ~125 ~100 grass_block
setblock ~36 ~125 ~101 grass_block
setblock ~36 ~125 ~102 grass_block
setblock ~36 ~125 ~103 grass_block
setblock ~36 ~125 ~104 grass_block
setblock ~36 ~125 ~105 grass_block
setblock ~36 ~125 ~106 grass_block
setblock ~36 ~125 ~107 grass_block
setblock ~36 ~125 ~108 grass_block
setblock ~36 ~125 ~109 grass_block
setblock ~36 ~125 ~110 poppy
setblock ~36 ~125 ~124 short_grass
setblock ~36 ~125 ~127 grass_block
setblock ~36 ~125 ~128 grass_block
setblock ~36 ~125 ~129 grass_block
setblock ~36 ~125 ~130 dirt
setblock ~36 ~125 ~131 dirt
setblock ~36 ~125 ~134 dirt
setblock ~36 ~126 ~72 dirt
setblock ~36 ~126 ~88 dirt
setblock ~36 ~126 ~89 grass_block
setblock ~36 ~126 ~90 grass_block
setblock ~36 ~126 ~91 grass_block
setblock ~36 ~126 ~92 grass_block
setblock ~36 ~126 ~93 grass_block
setblock ~36 ~126 ~94 grass_block
setblock ~36 ~126 ~95 grass_block
setblock ~36 ~126 ~96 grass_block
setblock ~36 ~126 ~97 grass_block
setblock ~36 ~126 ~98 grass_block
setblock ~36 ~126 ~100 short_grass
setblock ~36 ~126 ~103 short_grass
setblock ~36 ~126 ~105 short_grass
setblock ~36 ~126 ~106 short_grass
setblock ~36 ~126 ~128 short_grass
setblock ~36 ~126 ~129 short_grass
setblock ~36 ~126 ~130 grass_block
setblock ~36 ~126 ~131 grass_block
setblock ~36 ~126 ~134 grass_block
setblock ~36 ~127 ~72 grass_block
setblock ~36 ~127 ~88 grass_block
setblock ~36 ~127 ~91 short_grass
setblock ~36 ~127 ~95 short_grass
setblock ~36 ~127 ~130 short_grass
setblock ~36 ~127 ~134 short_grass
setblock ~37 ~108 ~98 dirt
setblock ~37 ~108 ~99 dirt
setblock ~37 ~109 ~96 dirt
setblock ~37 ~109 ~97 dirt
setblock ~37 ~109 ~98 dirt
setblock ~37 ~109 ~99 dirt
setblock ~37 ~110 ~95 dirt
setblock ~37 ~110 ~96 dirt
setblock ~37 ~110 ~97 dirt
setblock ~37 ~110 ~98 dirt
setblock ~37 ~110 ~99 dirt
setblock ~37 ~110 ~100 dirt
setblock ~37 ~111 ~94 dirt
setblock ~37 ~111 ~95 dirt
setblock ~37 ~111 ~96 dirt
setblock ~37 ~111 ~97 dirt
setblock ~37 ~111 ~98 dirt
setblock ~37 ~111 ~99 dirt
setblock ~37 ~111 ~100 dirt
setblock ~37 ~111 ~101 dirt
setblock ~37 ~111 ~105 dirt
setblock ~37 ~112 ~93 dirt
setblock ~37 ~112 ~94 dirt
setblock ~37 ~112 ~95 dirt
setblock ~37 ~112 ~96 dirt
setblock ~37 ~112 ~97 dirt
setblock ~37 ~112 ~98 dirt
setblock ~37 ~112 ~99 dirt
setblock ~37 ~112 ~100 dirt
setblock ~37 ~112 ~101 dirt
setblock ~37 ~112 ~102 dirt
setblock ~37 ~112 ~104 dirt
setblock ~37 ~112 ~105 dirt
setblock ~37 ~113 ~92 dirt
setblock ~37 ~113 ~93 dirt
setblock ~37 ~113 ~94 dirt
setblock ~37 ~113 ~95 dirt
setblock ~37 ~113 ~96 dirt
setblock ~37 ~113 ~97 dirt
setblock ~37 ~113 ~98 dirt
setblock ~37 ~113 ~99 dirt
setblock ~37 ~113 ~100 dirt
setblock ~37 ~113 ~101 dirt
setblock ~37 ~113 ~102 dirt
setblock ~37 ~113 ~103 dirt
setblock ~37 ~113 ~104 dirt
setblock ~37 ~113 ~105 dirt
setblock ~37 ~113 ~106 dirt
setblock ~37 ~114 ~92 dirt
setblock ~37 ~114 ~93 dirt
setblock ~37 ~114 ~94 dirt
setblock ~37 ~114 ~95 dirt
setblock ~37 ~114 ~96 dirt
setblock ~37 ~114 ~97 dirt
setblock ~37 ~114 ~98 dirt
setblock ~37 ~114 ~99 dirt
setblock ~37 ~114 ~100 dirt
setblock ~37 ~114 ~101 dirt
setblock ~37 ~114 ~102 dirt
setblock ~37 ~114 ~103 dirt
setblock ~37 ~114 ~104 dirt
setblock ~37 ~114 ~105 dirt
setblock ~37 ~114 ~106 dirt
setblock ~37 ~114 ~107 dirt
setblock ~37 ~115 ~92 dirt
setblock ~37 ~115 ~93 dirt
setblock ~37 ~115 ~94 dirt
setblock ~37 ~115 ~95 dirt
setblock ~37 ~115 ~96 dirt
setblock ~37 ~115 ~97 dirt
setblock ~37 ~115 ~98 dirt
setblock ~37 ~115 ~99 dirt
setblock ~37 ~115 ~100 dirt
setblock ~37 ~115 ~101 dirt
setblock ~37 ~115 ~102 dirt
setblock ~37 ~115 ~103 dirt
setblock ~37 ~115 ~104 dirt
setblock ~37 ~115 ~105 dirt
setblock ~37 ~115 ~106 dirt
setblock ~37 ~115 ~107 dirt
setblock ~37 ~115 ~108 dirt
setblock ~37 ~116 ~91 dirt
setblock ~37 ~116 ~92 dirt
setblock ~37 ~116 ~93 dirt
setblock ~37 ~116 ~94 dirt
setblock ~37 ~116 ~95 dirt
setblock ~37 ~116 ~96 dirt
setblock ~37 ~116 ~97 dirt
setblock ~37 ~116 ~98 dirt
setblock ~37 ~116 ~99 dirt
setblock ~37 ~116 ~100 dirt
setblock ~37 ~116 ~101 dirt
setblock ~37 ~116 ~102 dirt
setblock ~37 ~116 ~103 dirt
setblock ~37 ~116 ~104 dirt
setblock ~37 ~116 ~105 dirt
setblock ~37 ~116 ~106 dirt
setblock ~37 ~116 ~107 dirt
setblock ~37 ~116 ~108 dirt
setblock ~37 ~117 ~89 dirt
setblock ~37 ~117 ~90 dirt
setblock ~37 ~117 ~91 dirt
setblock ~37 ~117 ~92 dirt
setblock ~37 ~117 ~93 dirt
setblock ~37 ~117 ~94 dirt
setblock ~37 ~117 ~95 dirt
setblock ~37 ~117 ~96 dirt
setblock ~37 ~117 ~97 dirt
setblock ~37 ~117 ~98 dirt
setblock ~37 ~117 ~99 dirt
setblock ~37 ~117 ~100 dirt
setblock ~37 ~117 ~101 dirt
setblock ~37 ~117 ~102 dirt
setblock ~37 ~117 ~103 dirt
setblock ~37 ~117 ~104 dirt
setblock ~37 ~117 ~105 dirt
setblock ~37 ~117 ~106 dirt
setblock ~37 ~117 ~107 dirt
setblock ~37 ~117 ~108 dirt
setblock ~37 ~117 ~109 dirt
setblock ~37 ~117 ~124 dirt
setblock ~37 ~117 ~126 dirt
setblock ~37 ~118 ~88 dirt
setblock ~37 ~118 ~89 dirt
setblock ~37 ~118 ~90 dirt
setblock ~37 ~118 ~91 dirt
setblock ~37 ~118 ~92 dirt
setblock ~37 ~118 ~93 dirt
setblock ~37 ~118 ~94 dirt
setblock ~37 ~118 ~95 dirt
setblock ~37 ~118 ~96 dirt
setblock ~37 ~118 ~97 dirt
setblock ~37 ~118 ~98 dirt
setblock ~37 ~118 ~99 dirt
setblock ~37 ~118 ~100 dirt
setblock ~37 ~118 ~101 dirt
setblock ~37 ~118 ~102 dirt
setblock ~37 ~118 ~103 dirt
setblock ~37 ~118 ~104 dirt
setblock ~37 ~118 ~105 dirt
setblock ~37 ~118 ~106 dirt
setblock ~37 ~118 ~107 dirt
setblock ~37 ~118 ~108 dirt
setblock ~37 ~118 ~109 dirt
setblock ~37 ~118 ~110 dirt
setblock ~37 ~118 ~123 dirt
setblock ~37 ~118 ~124 dirt
setblock ~37 ~118 ~125 dirt
setblock ~37 ~118 ~126 dirt
setblock ~37 ~118 ~129 dirt
setblock ~37 ~118 ~133 dirt
setblock ~37 ~119 ~74 dirt
setblock ~37 ~119 ~88 dirt
setblock ~37 ~119 ~89 dirt
setblock ~37 ~119 ~90 dirt
setblock ~37 ~119 ~91 dirt
setblock ~37 ~119 ~92 dirt
setblock ~37 ~119 ~93 dirt
setblock ~37 ~119 ~94 dirt
setblock ~37 ~119 ~95 dirt
setblock ~37 ~119 ~96 dirt
setblock ~37 ~119 ~97 dirt
setblock ~37 ~119 ~98 dirt
setblock ~37 ~119 ~99 dirt
setblock ~37 ~119 ~100 dirt
setblock ~37 ~119 ~101 dirt
setblock ~37 ~119 ~102 dirt
setblock ~37 ~119 ~103 dirt
setblock ~37 ~119 ~104 dirt
setblock ~37 ~119 ~105 dirt
setblock ~37 ~119 ~106 dirt
setblock ~37 ~119 ~107 dirt
setblock ~37 ~119 ~108 dirt
setblock ~37 ~119 ~109 dirt
setblock ~37 ~119 ~110 dirt
setblock ~37 ~119 ~111 dirt
setblock ~37 ~119 ~123 dirt
setblock ~37 ~119 ~124 dirt
setblock ~37 ~119 ~125 dirt
setblock ~37 ~119 ~126 dirt
setblock ~37 ~119 ~128 dirt
setblock ~37 ~119 ~129 dirt
setblock ~37 ~119 ~130 dirt
setblock ~37 ~119 ~133 dirt
setblock ~37 ~120 ~71 dirt
setblock ~37 ~120 ~72 dirt
setblock ~37 ~120 ~74 dirt
setblock ~37 ~120 ~75 dirt
setblock ~37 ~120 ~87 dirt
setblock ~37 ~120 ~88 dirt
setblock ~37 ~120 ~89 dirt
setblock ~37 ~120 ~90 dirt
setblock ~37 ~120 ~91 dirt
setblock ~37 ~120 ~92 dirt
setblock ~37 ~120 ~93 dirt
setblock ~37 ~120 ~94 dirt
setblock ~37 ~120 ~95 dirt
setblock ~37 ~120 ~96 dirt
setblock ~37 ~120 ~97 dirt
setblock ~37 ~120 ~98 dirt
setblock ~37 ~120 ~99 dirt
setblock ~37 ~120 ~100 dirt
setblock ~37 ~120 ~101 dirt
setblock ~37 ~120 ~102 dirt
setblock ~37 ~120 ~103 dirt
setblock ~37 ~120 ~104 dirt
setblock ~37 ~120 ~105 dirt
setblock ~37 ~120 ~106 dirt
setblock ~37 ~120 ~107 dirt
setblock ~37 ~120 ~108 dirt
setblock ~37 ~120 ~109 dirt
setblock ~37 ~120 ~110 dirt
setblock ~37 ~120 ~111 dirt
setblock ~37 ~120 ~122 dirt
setblock ~37 ~120 ~123 dirt
setblock ~37 ~120 ~124 dirt
setblock ~37 ~120 ~125 dirt
setblock ~37 ~120 ~126 dirt
setblock ~37 ~120 ~127 dirt
setblock ~37 ~120 ~128 dirt
setblock ~37 ~120 ~129 dirt
setblock ~37 ~120 ~130 dirt
setblock ~37 ~120 ~131 dirt
setblock ~37 ~120 ~132 dirt
setblock ~37 ~120 ~133 dirt
setblock ~37 ~120 ~134 dirt
setblock ~37 ~121 ~70 dirt
setblock ~37 ~121 ~71 dirt
setblock ~37 ~121 ~72 dirt
setblock ~37 ~121 ~73 dirt
setblock ~37 ~121 ~74 dirt
setblock ~37 ~121 ~75 dirt
setblock ~37 ~121 ~76 dirt
setblock ~37 ~121 ~87 dirt
setblock ~37 ~121 ~88 dirt
setblock ~37 ~121 ~89 dirt
setblock ~37 ~121 ~90 dirt
setblock ~37 ~121 ~91 dirt
setblock ~37 ~121 ~92 dirt
setblock ~37 ~121 ~93 dirt
setblock ~37 ~121 ~94 dirt
setblock ~37 ~121 ~95 dirt
setblock ~37 ~121 ~96 dirt
setblock ~37 ~121 ~97 dirt
setblock ~37 ~121 ~98 dirt
setblock ~37 ~121 ~99 dirt
setblock ~37 ~121 ~100 dirt
setblock ~37 ~121 ~101 dirt
setblock ~37 ~121 ~102 dirt
setblock ~37 ~121 ~103 dirt
setblock ~37 ~121 ~104 dirt
setblock ~37 ~121 ~105 dirt
setblock ~37 ~121 ~106 dirt
setblock ~37 ~121 ~107 dirt
setblock ~37 ~121 ~108 dirt
setblock ~37 ~121 ~109 dirt
setblock ~37 ~121 ~110 dirt
setblock ~37 ~121 ~111 dirt
setblock ~37 ~121 ~120 dirt
setblock ~37 ~121 ~121 dirt
setblock ~37 ~121 ~122 dirt
setblock ~37 ~121 ~123 dirt
setblock ~37 ~121 ~124 dirt
setblock ~37 ~121 ~125 dirt
setblock ~37 ~121 ~126 dirt
setblock ~37 ~121 ~127 dirt
setblock ~37 ~121 ~128 dirt
setblock ~37 ~121 ~129 dirt
setblock ~37 ~121 ~130 dirt
setblock ~37 ~121 ~131 dirt
setblock ~37 ~121 ~132 dirt
setblock ~37 ~121 ~133 dirt
setblock ~37 ~121 ~134 dirt
setblock ~37 ~121 ~135 dirt
setblock ~37 ~122 ~70 dirt
setblock ~37 ~122 ~71 dirt
setblock ~37 ~122 ~72 dirt
setblock ~37 ~122 ~73 dirt
setblock ~37 ~122 ~74 dirt
setblock ~37 ~122 ~75 dirt
setblock ~37 ~122 ~76 dirt
setblock ~37 ~122 ~87 dirt
setblock ~37 ~122 ~88 dirt
setblock ~37 ~122 ~89 dirt
setblock ~37 ~122 ~90 dirt
setblock ~37 ~122 ~91 dirt
setblock ~37 ~122 ~92 dirt
setblock ~37 ~122 ~93 dirt
setblock ~37 ~122 ~94 dirt
setblock ~37 ~122 ~95 dirt
setblock ~37 ~122 ~96 dirt
setblock ~37 ~122 ~97 dirt
setblock ~37 ~122 ~98 dirt
setblock ~37 ~122 ~99 dirt
setblock ~37 ~122 ~100 dirt
setblock ~37 ~122 ~101 dirt
setblock ~37 ~122 ~102 dirt
setblock ~37 ~122 ~103 dirt
setblock ~37 ~122 ~104 dirt
setblock ~37 ~122 ~105 dirt
setblock ~37 ~122 ~106 dirt
setblock ~37 ~122 ~107 dirt
setblock ~37 ~122 ~108 dirt
setblock ~37 ~122 ~109 dirt
setblock ~37 ~122 ~110 dirt
setblock ~37 ~122 ~111 dirt
setblock ~37 ~122 ~120 grass_block
setblock ~37 ~122 ~121 dirt
setblock ~37 ~122 ~122 dirt
setblock ~37 ~122 ~123 dirt
setblock ~37 ~122 ~124 dirt
setblock ~37 ~122 ~125 dirt
setblock ~37 ~122 ~126 dirt
setblock ~37 ~122 ~127 dirt
setblock ~37 ~122 ~128 dirt
setblock ~37 ~122 ~129 dirt
setblock ~37 ~122 ~130 dirt
setblock ~37 ~122 ~131 dirt
setblock ~37 ~122 ~132 dirt
setblock ~37 ~122 ~133 dirt
setblock ~37 ~122 ~134 dirt
setblock ~37 ~122 ~135 dirt
setblock ~37 ~123 ~70 dirt
setblock ~37 ~123 ~71 dirt
setblock ~37 ~123 ~72 dirt
setblock ~37 ~123 ~73 dirt
setblock ~37 ~123 ~74 dirt
setblock ~37 ~123 ~75 dirt
setblock ~37 ~123 ~76 dirt
setblock ~37 ~123 ~87 dirt
setblock ~37 ~123 ~88 dirt
setblock ~37 ~123 ~89 dirt
setblock ~37 ~123 ~90 dirt
setblock ~37 ~123 ~91 dirt
setblock ~37 ~123 ~92 dirt
setblock ~37 ~123 ~93 dirt
setblock ~37 ~123 ~94 dirt
setblock ~37 ~123 ~95 dirt
setblock ~37 ~123 ~96 dirt
setblock ~37 ~123 ~97 dirt
setblock ~37 ~123 ~98 dirt
setblock ~37 ~123 ~99 dirt
setblock ~37 ~123 ~100 dirt
setblock ~37 ~123 ~101 dirt
setblock ~37 ~123 ~102 dirt
setblock ~37 ~123 ~103 dirt
setblock ~37 ~123 ~104 dirt
setblock ~37 ~123 ~105 dirt
setblock ~37 ~123 ~106 dirt
setblock ~37 ~123 ~107 dirt
setblock ~37 ~123 ~108 dirt
setblock ~37 ~123 ~109 dirt
setblock ~37 ~123 ~110 dirt
setblock ~37 ~123 ~111 dirt
setblock ~37 ~123 ~121 grass_block
setblock ~37 ~123 ~122 grass_block
setblock ~37 ~123 ~123 grass_block
setblock ~37 ~123 ~124 grass_block
setblock ~37 ~123 ~125 grass_block
setblock ~37 ~123 ~126 dirt
setblock ~37 ~123 ~127 dirt
setblock ~37 ~123 ~128 dirt
setblock ~37 ~123 ~129 dirt
setblock ~37 ~123 ~130 dirt
setblock ~37 ~123 ~131 dirt
setblock ~37 ~123 ~132 dirt
setblock ~37 ~123 ~133 dirt
setblock ~37 ~123 ~134 dirt
setblock ~37 ~123 ~135 dirt
setblock ~37 ~124 ~70 dirt
setblock ~37 ~124 ~71 dirt
setblock ~37 ~124 ~72 dirt
setblock ~37 ~124 ~73 dirt
setblock ~37 ~124 ~74 dirt
setblock ~37 ~124 ~75 dirt
setblock ~37 ~124 ~76 dirt
setblock ~37 ~124 ~87 dirt
setblock ~37 ~124 ~88 dirt
setblock ~37 ~124 ~89 dirt
setblock ~37 ~124 ~90 dirt
setblock ~37 ~124 ~91 dirt
setblock ~37 ~124 ~92 dirt
setblock ~37 ~124 ~93 dirt
setblock ~37 ~124 ~94 dirt
setblock ~37 ~124 ~95 dirt
setblock ~37 ~124 ~96 dirt
setblock ~37 ~124 ~97 dirt
setblock ~37 ~124 ~98 dirt
setblock ~37 ~124 ~99 dirt
setblock ~37 ~124 ~100 dirt
setblock ~37 ~124 ~101 dirt
setblock ~37 ~124 ~102 dirt
setblock ~37 ~124 ~103 dirt
setblock ~37 ~124 ~104 dirt
setblock ~37 ~124 ~105 dirt
setblock ~37 ~124 ~106 dirt
setblock ~37 ~124 ~107 dirt
setblock ~37 ~124 ~108 dirt
setblock ~37 ~124 ~109 grass_block
setblock ~37 ~124 ~110 grass_block
setblock ~37 ~124 ~111 grass_block
setblock ~37 ~124 ~121 short_grass
setblock ~37 ~124 ~125 fern
setblock ~37 ~124 ~126 grass_block
setblock ~37 ~124 ~127 grass_block
setblock ~37 ~124 ~128 grass_block
setblock ~37 ~124 ~129 dirt
setblock ~37 ~124 ~130 dirt
setblock ~37 ~124 ~131 dirt
setblock ~37 ~124 ~132 dirt
setblock ~37 ~124 ~133 dirt
setblock ~37 ~124 ~134 dirt
setblock ~37 ~124 ~135 dirt
setblock ~37 ~125 ~70 dirt
setblock ~37 ~125 ~71 dirt
setblock ~37 ~125 ~72 dirt
setblock ~37 ~125 ~73 dirt
setblock ~37 ~125 ~74 dirt
setblock ~37 ~125 ~75 dirt
setblock ~37 ~125 ~76 dirt
setblock ~37 ~125 ~87 dirt
setblock ~37 ~125 ~88 dirt
setblock ~37 ~125 ~89 dirt
setblock ~37 ~125 ~90 dirt
setblock ~37 ~125 ~91 dirt
setblock ~37 ~125 ~92 dirt
setblock ~37 ~125 ~93 dirt
setblock ~37 ~125 ~94 dirt
setblock ~37 ~125 ~95 dirt
setblock ~37 ~125 ~96 dirt
setblock ~37 ~125 ~97 dirt
setblock ~37 ~125 ~98 dirt
setblock ~37 ~125 ~99 dirt
setblock ~37 ~125 ~100 grass_block
setblock ~37 ~125 ~101 grass_block
setblock ~37 ~125 ~102 grass_block
setblock ~37 ~125 ~103 grass_block
setblock ~37 ~125 ~104 grass_block
setblock ~37 ~125 ~105 grass_block
setblock ~37 ~125 ~106 grass_block
setblock ~37 ~125 ~107 grass_block
setblock ~37 ~125 ~108 grass_block
setblock ~37 ~125 ~129 grass_block
setblock ~37 ~125 ~130 grass_block
setblock ~37 ~125 ~131 grass_block
setblock ~37 ~125 ~132 dirt
setblock ~37 ~125 ~133 dirt
setblock ~37 ~125 ~134 dirt
setblock ~37 ~125 ~135 dirt
setblock ~37 ~126 ~70 grass_block
setblock ~37 ~126 ~71 grass_block
setblock ~37 ~126 ~72 grass_block
setblock ~37 ~126 ~73 grass_block
setblock ~37 ~126 ~74 dirt
setblock ~37 ~126 ~75 dirt
setblock ~37 ~126 ~76 dirt
setblock ~37 ~126 ~87 dirt
setblock ~37 ~126 ~88 dirt
setblock ~37 ~126 ~89 dirt
setblock ~37 ~126 ~90 dirt
setblock ~37 ~126 ~91 dirt
setblock ~37 ~126 ~92 dirt
setblock ~37 ~126 ~93 dirt
setblock ~37 ~126 ~94 grass_block
setblock ~37 ~126 ~95 grass_block
setblock ~37 ~126 ~96 grass_block
setblock ~37 ~126 ~97 grass_block
setblock ~37 ~126 ~98 grass_block
setblock ~37 ~126 ~99 grass_block
setblock ~37 ~126 ~100 short_grass
setblock ~37 ~126 ~103 fern
setblock ~37 ~126 ~104 short_grass
setblock ~37 ~126 ~106 fern
setblock ~37 ~126 ~108 short_grass
setblock ~37 ~126 ~129 short_grass
setblock ~37 ~126 ~131 short_grass
setblock ~37 ~126 ~132 grass_block
setblock ~37 ~126 ~133 grass_block
setblock ~37 ~126 ~134 grass_block
setblock ~37 ~126 ~135 grass_block
setblock ~37 ~127 ~74 grass_block
setblock ~37 ~127 ~75 grass_block
setblock ~37 ~127 ~76 grass_block
setblock ~37 ~127 ~87 grass_block
setblock ~37 ~127 ~88 grass_block
setblock ~37 ~127 ~89 grass_block
setblock ~37 ~127 ~90 grass_block
setblock ~37 ~127 ~91 grass_block
setblock ~37 ~127 ~92 grass_block
setblock ~37 ~127 ~93 grass_block
setblock ~37 ~127 ~96 fern
setblock ~37 ~127 ~135 fern
setblock ~37 ~128 ~74 poppy
setblock ~37 ~128 ~76 short_grass
setblock ~37 ~128 ~90 short_grass
setblock ~38 ~107 ~97 dirt
setblock ~38 ~107 ~98 dirt
setblock ~38 ~107 ~99 dirt
setblock ~38 ~108 ~96 dirt
setblock ~38 ~108 ~97 dirt
setblock ~38 ~108 ~98 dirt
setblock ~38 ~108 ~99 dirt
setblock ~38 ~108 ~100 dirt
setblock ~38 ~109 ~94 dirt
setblock ~38 ~109 ~95 dirt
setblock ~38 ~109 ~96 dirt
setblock ~38 ~109 ~97 dirt
setblock ~38 ~109 ~98 dirt
setblock ~38 ~109 ~99 dirt
setblock ~38 ~109 ~100 dirt
setblock ~38 ~109 ~102 dirt
setblock ~38 ~110 ~94 dirt
setblock ~38 ~110 ~95 dirt
setblock ~38 ~110 ~96 dirt
setblock ~38 ~110 ~97 dirt
setblock ~38 ~110 ~98 dirt
setblock ~38 ~110 ~99 dirt
setblock ~38 ~110 ~100 dirt
setblock ~38 ~110 ~101 dirt
setblock ~38 ~110 ~102 dirt
setblock ~38 ~110 ~104 dirt
setblock ~38 ~110 ~105 dirt
setblock ~38 ~111 ~93 dirt
setblock ~38 ~111 ~94 dirt
setblock ~38 ~111 ~95 dirt
setblock ~38 ~111 ~96 dirt
setblock ~38 ~111 ~97 dirt
setblock ~38 ~111 ~98 dirt
setblock ~38 ~111 ~99 dirt
setblock ~38 ~111 ~100 dirt
setblock ~38 ~111 ~101 dirt
setblock ~38 ~111 ~102 dirt
setblock ~38 ~111 ~104 dirt
setblock ~38 ~111 ~105 dirt
setblock ~38 ~111 ~106 dirt
setblock ~38 ~112 ~92 dirt
setblock ~38 ~112 ~93 dirt
setblock ~38 ~112 ~94 dirt
setblock ~38 ~112 ~95 dirt
setblock ~38 ~112 ~96 dirt
setblock ~38 ~112 ~97 dirt
setblock ~38 ~112 ~98 dirt
setblock ~38 ~112 ~99 dirt
setblock ~38 ~112 ~100 dirt
setblock ~38 ~112 ~101 dirt
setblock ~38 ~112 ~102 dirt
setblock ~38 ~112 ~103 dirt
setblock ~38 ~112 ~104 dirt
setblock ~38 ~112 ~105 dirt
setblock ~38 ~112 ~106 dirt
setblock ~38 ~113 ~92 dirt
setblock ~38 ~113 ~93 dirt
setblock ~38 ~113 ~94 dirt
setblock ~38 ~113 ~95 dirt
setblock ~38 ~113 ~96 dirt
setblock ~38 ~113 ~97 dirt
setblock ~38 ~113 ~98 dirt
setblock ~38 ~113 ~99 dirt
setblock ~38 ~113 ~100 dirt
setblock ~38 ~113 ~101 dirt
setblock ~38 ~113 ~102 dirt
setblock ~38 ~113 ~103 dirt
setblock ~38 ~113 ~104 dirt
setblock ~38 ~113 ~105 dirt
setblock ~38 ~113 ~106 dirt
setblock ~38 ~113 ~107 dirt
setblock ~38 ~114 ~91 dirt
setblock ~38 ~114 ~92 dirt
setblock ~38 ~114 ~93 dirt
setblock ~38 ~114 ~94 dirt
setblock ~38 ~114 ~95 dirt
setblock ~38 ~114 ~96 dirt
setblock ~38 ~114 ~97 dirt
setblock ~38 ~114 ~98 dirt
setblock ~38 ~114 ~99 dirt
setblock ~38 ~114 ~100 dirt
setblock ~38 ~114 ~101 dirt
setblock ~38 ~114 ~102 dirt
setblock ~38 ~114 ~103 dirt
setblock ~38 ~114 ~104 dirt
setblock ~38 ~114 ~105 dirt
setblock ~38 ~114 ~106 dirt
setblock ~38 ~114 ~107 dirt
setblock ~38 ~114 ~108 dirt
setblock ~38 ~115 ~91 dirt
setblock ~38 ~115 ~92 dirt
setblock ~38 ~115 ~93 dirt
setblock ~38 ~115 ~94 dirt
setblock ~38 ~115 ~95 dirt
setblock ~38 ~115 ~96 dirt
setblock ~38 ~115 ~97 dirt
setblock ~38 ~115 ~98 dirt
setblock ~38 ~115 ~99 dirt
setblock ~38 ~115 ~100 dirt
setblock ~38 ~115 ~101 dirt
setblock ~38 ~115 ~102 dirt
setblock ~38 ~115 ~103 dirt
setblock ~38 ~115 ~104 dirt
setblock ~38 ~115 ~105 dirt
setblock ~38 ~115 ~106 dirt
setblock ~38 ~115 ~107 dirt
setblock ~38 ~115 ~108 dirt
setblock ~38 ~115 ~109 dirt
setblock ~38 ~116 ~89 dirt
setblock ~38 ~116 ~90 dirt
setblock ~38 ~116 ~91 dirt
setblock ~38 ~116 ~92 dirt
setblock ~38 ~116 ~93 dirt
setblock ~38 ~116 ~94 dirt
setblock ~38 ~116 ~95 dirt
setblock ~38 ~116 ~96 dirt
setblock ~38 ~116 ~97 dirt
setblock ~38 ~116 ~98 dirt
setblock ~38 ~116 ~99 dirt
setblock ~38 ~116 ~100 dirt
setblock ~38 ~116 ~101 dirt
setblock ~38 ~116 ~102 dirt
setblock ~38 ~116 ~103 dirt
setblock ~38 ~116 ~104 dirt
setblock ~38 ~116 ~105 dirt
setblock ~38 ~116 ~106 dirt
setblock ~38 ~116 ~107 dirt
setblock ~38 ~116 ~108 dirt
setblock ~38 ~116 ~109 dirt
setblock ~38 ~116 ~124 dirt
setblock ~38 ~116 ~126 dirt
setblock ~38 ~117 ~88 dirt
setblock ~38 ~117 ~89 dirt
setblock ~38 ~117 ~90 dirt
setblock ~38 ~117 ~91 dirt
setblock ~38 ~117 ~92 dirt
setblock ~38 ~117 ~93 dirt
setblock ~38 ~117 ~94 dirt
setblock ~38 ~117 ~95 dirt
setblock ~38 ~117 ~96 dirt
setblock ~38 ~117 ~97 dirt
setblock ~38 ~117 ~98 dirt
setblock ~38 ~117 ~99 dirt
setblock ~38 ~117 ~100 dirt
setblock ~38 ~117 ~101 dirt
setblock ~38 ~117 ~102 dirt
setblock ~38 ~117 ~103 dirt
setblock ~38 ~117 ~104 dirt
setblock ~38 ~117 ~105 dirt
setblock ~38 ~117 ~106 dirt
setblock ~38 ~117 ~107 dirt
setblock ~38 ~117 ~108 dirt
setblock ~38 ~117 ~109 dirt
setblock ~38 ~117 ~110 dirt
setblock ~38 ~117 ~123 dirt
setblock ~38 ~117 ~124 dirt
setblock ~38 ~117 ~125 dirt
setblock ~38 ~117 ~126 dirt
setblock ~38 ~117 ~127 dirt
setblock ~38 ~117 ~128 dirt
setblock ~38 ~117 ~129 dirt
setblock ~38 ~117 ~133 dirt
setblock ~38 ~118 ~72 dirt
setblock ~38 ~118 ~73 dirt
setblock ~38 ~118 ~74 dirt
setblock ~38 ~118 ~87 dirt
setblock ~38 ~118 ~88 dirt
setblock ~38 ~118 ~89 dirt
setblock ~38 ~118 ~90 dirt
setblock ~38 ~118 ~91 dirt
setblock ~38 ~118 ~92 dirt
setblock ~38 ~118 ~93 dirt
setblock ~38 ~118 ~94 dirt
setblock ~38 ~118 ~95 dirt
setblock ~38 ~118 ~96 dirt
setblock ~38 ~118 ~97 dirt
setblock ~38 ~118 ~98 dirt
setblock ~38 ~118 ~99 dirt
setblock ~38 ~118 ~100 dirt
setblock ~38 ~118 ~101 dirt
setblock ~38 ~118 ~102 dirt
setblock ~38 ~118 ~103 dirt
setblock ~38 ~118 ~104 dirt
setblock ~38 ~118 ~105 dirt
setblock ~38 ~118 ~106 dirt
setblock ~38 ~118 ~107 dirt
setblock ~38 ~118 ~108 dirt
setblock ~38 ~118 ~109 dirt
setblock ~38 ~118 ~110 dirt
setblock ~38 ~118 ~120 dirt
setblock ~38 ~118 ~122 dirt
setblock ~38 ~118 ~123 dirt
setblock ~38 ~118 ~124 dirt
setblock ~38 ~118 ~125 dirt
setblock ~38 ~118 ~126 dirt
setblock ~38 ~118 ~127 dirt
setblock ~38 ~118 ~128 dirt
setblock ~38 ~118 ~129 dirt
setblock ~38 ~118 ~130 dirt
setblock ~38 ~118 ~131 dirt
setblock ~38 ~118 ~132 dirt
setblock ~38 ~118 ~133 dirt
setblock ~38 ~118 ~134 dirt
setblock ~38 ~119 ~71 dirt
setblock ~38 ~119 ~72 dirt
setblock ~38 ~119 ~73 dirt
setblock ~38 ~119 ~74 dirt
setblock ~38 ~119 ~75 dirt
setblock ~38 ~119 ~87 dirt
setblock ~38 ~119 ~88 dirt
setblock ~38 ~119 ~89 dirt
setblock ~38 ~119 ~90 dirt
setblock ~38 ~119 ~91 dirt
setblock ~38 ~119 ~92 dirt
setblock ~38 ~119 ~93 dirt
setblock ~38 ~119 ~94 dirt
setblock ~38 ~119 ~95 dirt
setblock ~38 ~119 ~96 dirt
setblock ~38 ~119 ~97 dirt
setblock ~38 ~119 ~98 dirt
setblock ~38 ~119 ~99 dirt
setblock ~38 ~119 ~100 dirt
setblock ~38 ~119 ~101 dirt
setblock ~38 ~119 ~102 dirt
setblock ~38 ~119 ~103 dirt
setblock ~38 ~119 ~104 dirt
setblock ~38 ~119 ~105 dirt
setblock ~38 ~119 ~106 dirt
setblock ~38 ~119 ~107 dirt
setblock ~38 ~119 ~108 dirt
setblock ~38 ~119 ~109 dirt
setblock ~38 ~119 ~110 dirt
setblock ~38 ~119 ~120 dirt
setblock ~38 ~119 ~122 dirt
setblock ~38 ~119 ~123 dirt
setblock ~38 ~119 ~124 dirt
setblock ~38 ~119 ~125 dirt
setblock ~38 ~119 ~126 dirt
setblock ~38 ~119 ~127 dirt
setblock ~38 ~119 ~128 dirt
setblock ~38 ~119 ~129 dirt
setblock ~38 ~119 ~130 dirt
setblock ~38 ~119 ~131 dirt
setblock ~38 ~119 ~132 dirt
setblock ~38 ~119 ~133 dirt
setblock ~38 ~119 ~134 dirt
setblock ~38 ~120 ~70 dirt
setblock ~38 ~120 ~71 dirt
setblock ~38 ~120 ~72 dirt
setblock ~38 ~120 ~73 dirt
setblock ~38 ~120 ~74 dirt
setblock ~38 ~120 ~75 dirt
setblock ~38 ~120 ~76 dirt
setblock ~38 ~120 ~86 dirt
setblock ~38 ~120 ~87 dirt
setblock ~38 ~120 ~88 dirt
setblock ~38 ~120 ~89 dirt
setblock ~38 ~120 ~90 dirt
setblock ~38 ~120 ~91 dirt
setblock ~38 ~120 ~92 dirt
setblock ~38 ~120 ~93 dirt
setblock ~38 ~120 ~94 dirt
setblock ~38 ~120 ~95 dirt
setblock ~38 ~120 ~96 dirt
setblock ~38 ~120 ~97 dirt
setblock ~38 ~120 ~98 dirt
setblock ~38 ~120 ~99 dirt
setblock ~38 ~120 ~100 dirt
setblock ~38 ~120 ~101 dirt
setblock ~38 ~120 ~102 dirt
setblock ~38 ~120 ~103 dirt
setblock ~38 ~120 ~104 dirt
setblock ~38 ~120 ~105 dirt
setblock ~38 ~120 ~106 dirt
setblock ~38 ~120 ~107 dirt
setblock ~38 ~120 ~108 dirt
setblock ~38 ~120 ~109 dirt
setblock ~38 ~120 ~110 dirt
setblock ~38 ~120 ~119 dirt
setblock ~38 ~120 ~120 dirt
setblock ~38 ~120 ~121 dirt
setblock ~38 ~120 ~122 dirt
setblock ~38 ~120 ~123 dirt
setblock ~38 ~120 ~124 dirt
setblock ~38 ~120 ~125 dirt
setblock ~38 ~120 ~126 dirt
setblock ~38 ~120 ~127 dirt
setblock ~38 ~120 ~128 dirt
setblock ~38 ~120 ~129 dirt
setblock ~38 ~120 ~130 dirt
setblock ~38 ~120 ~131 dirt
setblock ~38 ~120 ~132 dirt
setblock ~38 ~120 ~133 dirt
setblock ~38 ~120 ~134 dirt
setblock ~38 ~120 ~135 dirt
setblock ~38 ~121 ~64 dirt
setblock ~38 ~121 ~68 dirt
setblock ~38 ~121 ~69 dirt
setblock ~38 ~121 ~70 dirt
setblock ~38 ~121 ~71 dirt
setblock ~38 ~121 ~72 dirt
setblock ~38 ~121 ~73 dirt
setblock ~38 ~121 ~74 dirt
setblock ~38 ~121 ~75 dirt
setblock ~38 ~121 ~76 dirt
setblock ~38 ~121 ~77 dirt
setblock ~38 ~121 ~86 dirt
setblock ~38 ~121 ~87 dirt
setblock ~38 ~121 ~88 dirt
setblock ~38 ~121 ~89 dirt
setblock ~38 ~121 ~90 dirt
setblock ~38 ~121 ~91 dirt
setblock ~38 ~121 ~92 dirt
setblock ~38 ~121 ~93 dirt
setblock ~38 ~121 ~94 dirt
setblock ~38 ~121 ~95 dirt
setblock ~38 ~121 ~96 dirt
setblock ~38 ~121 ~97 dirt
setblock ~38 ~121 ~98 dirt
setblock ~38 ~121 ~99 dirt
setblock ~38 ~121 ~100 dirt
setblock ~38 ~121 ~101 dirt
setblock ~38 ~121 ~102 dirt
setblock ~38 ~121 ~103 dirt
setblock ~38 ~121 ~104 dirt
setblock ~38 ~121 ~105 dirt
setblock ~38 ~121 ~106 dirt
setblock ~38 ~121 ~107 dirt
setblock ~38 ~121 ~108 dirt
setblock ~38 ~121 ~109 dirt
setblock ~38 ~121 ~110 dirt
setblock ~38 ~121 ~111 dirt
setblock ~38 ~121 ~119 dirt
setblock ~38 ~121 ~120 dirt
setblock ~38 ~121 ~121 dirt
setblock ~38 ~121 ~122 dirt
setblock ~38 ~121 ~123 dirt
setblock ~38 ~121 ~124 dirt
setblock ~38 ~121 ~125 dirt
setblock ~38 ~121 ~126 dirt
setblock ~38 ~121 ~127 dirt
setblock ~38 ~121 ~128 dirt
setblock ~38 ~121 ~129 dirt
setblock ~38 ~121 ~130 dirt
setblock ~38 ~121 ~131 dirt
setblock ~38 ~121 ~132 dirt
setblock ~38 ~121 ~133 dirt
setblock ~38 ~121 ~134 dirt
setblock ~38 ~121 ~135 dirt
setblock ~38 ~122 ~64 dirt
setblock ~38 ~122 ~68 dirt
setblock ~38 ~122 ~69 dirt
setblock ~38 ~122 ~70 dirt
setblock ~38 ~122 ~71 dirt
setblock ~38 ~122 ~72 dirt
setblock ~38 ~122 ~73 dirt
setblock ~38 ~122 ~74 dirt
setblock ~38 ~122 ~75 dirt
setblock ~38 ~122 ~76 dirt
setblock ~38 ~122 ~77 dirt
setblock ~38 ~122 ~86 dirt
setblock ~38 ~122 ~87 dirt
setblock ~38 ~122 ~88 dirt
setblock ~38 ~122 ~89 dirt
setblock ~38 ~122 ~90 dirt
setblock ~38 ~122 ~91 dirt
setblock ~38 ~122 ~92 dirt
setblock ~38 ~122 ~93 dirt
setblock ~38 ~122 ~94 dirt
setblock ~38 ~122 ~95 dirt
setblock ~38 ~122 ~96 dirt
setblock ~38 ~122 ~97 dirt
setblock ~38 ~122 ~98 dirt
setblock ~38 ~122 ~99 dirt
setblock ~38 ~122 ~100 dirt
setblock ~38 ~122 ~101 dirt
setblock ~38 ~122 ~102 dirt
setblock ~38 ~122 ~103 dirt
setblock ~38 ~122 ~104 dirt
setblock ~38 ~122 ~105 dirt
setblock ~38 ~122 ~106 dirt
setblock ~38 ~122 ~107 dirt
setblock ~38 ~122 ~108 dirt
setblock ~38 ~122 ~109 dirt
setblock ~38 ~122 ~110 dirt
setblock ~38 ~122 ~111 dirt
setblock ~38 ~122 ~119 grass_block
setblock ~38 ~122 ~120 grass_block
setblock ~38 ~122 ~121 grass_block
setblock ~38 ~122 ~122 grass_block
setblock ~38 ~122 ~123 dirt
setblock ~38 ~122 ~124 dirt
setblock ~38 ~122 ~125 dirt
setblock ~38 ~122 ~126 dirt
setblock ~38 ~122 ~127 dirt
setblock ~38 ~122 ~128 dirt
setblock ~38 ~122 ~129 dirt
setblock ~38 ~122 ~130 dirt
setblock ~38 ~122 ~131 dirt
setblock ~38 ~122 ~132 dirt
setblock ~38 ~122 ~133 dirt
setblock ~38 ~122 ~134 dirt
setblock ~38 ~122 ~135 dirt
setblock ~38 ~123 ~64 dirt
setblock ~38 ~123 ~68 dirt
setblock ~38 ~123 ~69 dirt
setblock ~38 ~123 ~70 dirt
setblock ~38 ~123 ~71 dirt
setblock ~38 ~123 ~72 dirt
setblock ~38 ~123 ~73 dirt
setblock ~38 ~123 ~74 dirt
setblock ~38 ~123 ~75 dirt
setblock ~38 ~123 ~76 dirt
setblock ~38 ~123 ~77 dirt
setblock ~38 ~123 ~86 dirt
setblock ~38 ~123 ~87 dirt
setblock ~38 ~123 ~88 dirt
setblock ~38 ~123 ~89 dirt
setblock ~38 ~123 ~90 dirt
setblock ~38 ~123 ~91 dirt
setblock ~38 ~123 ~92 dirt
setblock ~38 ~123 ~93 dirt
setblock ~38 ~123 ~94 dirt
setblock ~38 ~123 ~95 dirt
setblock ~38 ~123 ~96 dirt
setblock ~38 ~123 ~97 dirt
setblock ~38 ~123 ~98 dirt
setblock ~38 ~123 ~99 dirt
setblock ~38 ~123 ~100 dirt
setblock ~38 ~123 ~101 dirt
