setblock ~161 ~123 ~80 grass_block
setblock ~161 ~123 ~81 grass_block
setblock ~161 ~123 ~82 grass_block
setblock ~161 ~123 ~83 dirt
setblock ~161 ~123 ~84 dirt
setblock ~161 ~123 ~85 dirt
setblock ~161 ~123 ~86 dirt
setblock ~161 ~123 ~87 dirt
setblock ~161 ~123 ~89 dirt
setblock ~161 ~123 ~90 dirt
setblock ~161 ~123 ~91 dirt
setblock ~161 ~123 ~92 dirt
setblock ~161 ~123 ~93 dirt
setblock ~161 ~123 ~94 dirt
setblock ~161 ~123 ~95 dirt
setblock ~161 ~123 ~96 dirt
setblock ~161 ~123 ~97 dirt
setblock ~161 ~123 ~98 dirt
setblock ~161 ~123 ~99 dirt
setblock ~161 ~123 ~100 dirt
setblock ~161 ~123 ~101 dirt
setblock ~161 ~123 ~102 dirt
setblock ~161 ~123 ~103 dirt
setblock ~161 ~123 ~104 dirt
setblock ~161 ~123 ~105 dirt
setblock ~161 ~123 ~106 dirt
setblock ~161 ~123 ~107 dirt
setblock ~161 ~123 ~108 dirt
setblock ~161 ~123 ~109 dirt
setblock ~161 ~123 ~110 dirt
setblock ~161 ~123 ~111 dirt
setblock ~161 ~123 ~112 dirt
setblock ~161 ~123 ~113 dirt
setblock ~161 ~123 ~114 dirt
setblock ~161 ~123 ~115 dirt
setblock ~161 ~123 ~116 dirt
setblock ~161 ~123 ~117 grass_block
setblock ~161 ~123 ~118 grass_block
setblock ~161 ~123 ~119 grass_block
setblock ~161 ~123 ~120 grass_block
setblock ~161 ~123 ~121 grass_block
setblock ~161 ~123 ~122 grass_block
setblock ~161 ~123 ~123 grass_block
setblock ~161 ~123 ~124 grass_block
setblock ~161 ~123 ~125 grass_block
setblock ~161 ~123 ~126 dirt
setblock ~161 ~123 ~127 dirt
setblock ~161 ~123 ~128 dirt
setblock ~161 ~123 ~129 dirt
setblock ~161 ~123 ~130 dirt
setblock ~161 ~123 ~131 dirt
setblock ~161 ~123 ~132 dirt
setblock ~161 ~123 ~133 dirt
setblock ~161 ~123 ~134 dirt
setblock ~161 ~124 ~65 grass_block
setblock ~161 ~124 ~66 grass_block
setblock ~161 ~124 ~67 grass_block
setblock ~161 ~124 ~68 grass_block
setblock ~161 ~124 ~69 grass_block
setblock ~161 ~124 ~70 grass_block
setblock ~161 ~124 ~71 grass_block
setblock ~161 ~124 ~72 grass_block
setblock ~161 ~124 ~73 grass_block
setblock ~161 ~124 ~74 grass_block
setblock ~161 ~124 ~75 grass_block
setblock ~161 ~124 ~76 short_grass
setblock ~161 ~124 ~80 short_grass
setblock ~161 ~124 ~82 fern
setblock ~161 ~124 ~83 grass_block
setblock ~161 ~124 ~84 grass_block
setblock ~161 ~124 ~85 grass_block
setblock ~161 ~124 ~86 grass_block
setblock ~161 ~124 ~87 dirt
setblock ~161 ~124 ~89 dirt
setblock ~161 ~124 ~90 dirt
setblock ~161 ~124 ~91 dirt
setblock ~161 ~124 ~92 dirt
setblock ~161 ~124 ~93 dirt
setblock ~161 ~124 ~94 dirt
setblock ~161 ~124 ~95 dirt
setblock ~161 ~124 ~96 dirt
setblock ~161 ~124 ~97 dirt
setblock ~161 ~124 ~98 dirt
setblock ~161 ~124 ~99 dirt
setblock ~161 ~124 ~100 dirt
setblock ~161 ~124 ~101 dirt
setblock ~161 ~124 ~102 dirt
setblock ~161 ~124 ~103 dirt
setblock ~161 ~124 ~104 dirt
setblock ~161 ~124 ~105 dirt
setblock ~161 ~124 ~106 dirt
setblock ~161 ~124 ~107 dirt
setblock ~161 ~124 ~108 grass_block
setblock ~161 ~124 ~109 grass_block
setblock ~161 ~124 ~110 grass_block
setblock ~161 ~124 ~111 grass_block
setblock ~161 ~124 ~112 grass_block
setblock ~161 ~124 ~113 grass_block
setblock ~161 ~124 ~114 grass_block
setblock ~161 ~124 ~115 grass_block
setblock ~161 ~124 ~116 grass_block
setblock ~161 ~124 ~119 fern
setblock ~161 ~124 ~126 grass_block
setblock ~161 ~124 ~127 grass_block
setblock ~161 ~124 ~128 grass_block
setblock ~161 ~124 ~129 grass_block
setblock ~161 ~124 ~130 grass_block
setblock ~161 ~124 ~131 grass_block
setblock ~161 ~124 ~132 grass_block
setblock ~161 ~124 ~133 grass_block
setblock ~161 ~124 ~134 grass_block
setblock ~161 ~125 ~65 short_grass
setblock ~161 ~125 ~70 short_grass
setblock ~161 ~125 ~71 short_grass
setblock ~161 ~125 ~72 short_grass
setblock ~161 ~125 ~73 short_grass
setblock ~161 ~125 ~75 short_grass
setblock ~161 ~125 ~85 fern
setblock ~161 ~125 ~87 grass_block
setblock ~161 ~125 ~89 grass_block
setblock ~161 ~125 ~90 grass_block
setblock ~161 ~125 ~91 grass_block
setblock ~161 ~125 ~92 grass_block
setblock ~161 ~125 ~93 grass_block
setblock ~161 ~125 ~94 grass_block
setblock ~161 ~125 ~95 grass_block
setblock ~161 ~125 ~96 grass_block
setblock ~161 ~125 ~97 grass_block
setblock ~161 ~125 ~98 grass_block
setblock ~161 ~125 ~99 grass_block
setblock ~161 ~125 ~100 grass_block
setblock ~161 ~125 ~101 grass_block
setblock ~161 ~125 ~102 grass_block
setblock ~161 ~125 ~103 grass_block
setblock ~161 ~125 ~104 grass_block
setblock ~161 ~125 ~105 grass_block
setblock ~161 ~125 ~106 grass_block
setblock ~161 ~125 ~107 grass_block
setblock ~161 ~125 ~110 poppy
setblock ~161 ~125 ~112 short_grass
setblock ~161 ~125 ~114 short_grass
setblock ~161 ~125 ~116 fern
setblock ~161 ~125 ~131 fern
setblock ~161 ~125 ~133 short_grass
setblock ~161 ~126 ~87 poppy
setblock ~161 ~126 ~92 short_grass
setblock ~161 ~126 ~97 short_grass
setblock ~161 ~126 ~100 fern
setblock ~161 ~126 ~101 fern
setblock ~161 ~126 ~102 fern
setblock ~161 ~126 ~105 fern
setblock ~161 ~126 ~106 fern
setblock ~161 ~126 ~107 poppy
setblock ~161 ~132 ~74 oak_leaves[persistent=true]
setblock ~161 ~133 ~74 oak_leaves[persistent=true]
setblock ~161 ~133 ~75 oak_leaves[persistent=true]
setblock ~161 ~133 ~76 oak_leaves[persistent=true]
setblock ~161 ~134 ~75 oak_leaves[persistent=true]
setblock ~161 ~135 ~74 oak_leaves[persistent=true]
setblock ~161 ~135 ~75 oak_leaves[persistent=true]
setblock ~161 ~135 ~76 oak_leaves[persistent=true]
setblock ~161 ~135 ~79 oak_leaves[persistent=true]
setblock ~161 ~135 ~80 oak_leaves[persistent=true]
setblock ~161 ~135 ~81 oak_leaves[persistent=true]
setblock ~161 ~135 ~82 oak_leaves[persistent=true]
setblock ~161 ~136 ~79 oak_leaves[persistent=true]
setblock ~161 ~136 ~80 oak_leaves[persistent=true]
setblock ~161 ~136 ~81 oak_leaves[persistent=true]
setblock ~161 ~136 ~82 oak_leaves[persistent=true]
setblock ~161 ~137 ~79 oak_leaves[persistent=true]
setblock ~161 ~137 ~80 oak_leaves[persistent=true]
setblock ~161 ~137 ~81 oak_leaves[persistent=true]
setblock ~161 ~137 ~82 jungle_leaves[persistent=true]
setblock ~161 ~138 ~79 jungle_leaves[persistent=true]
setblock ~161 ~138 ~81 oak_leaves[persistent=true]
setblock ~161 ~138 ~82 jungle_leaves[persistent=true]
setblock ~162 ~104 ~77 dirt
setblock ~162 ~104 ~79 dirt
setblock ~162 ~105 ~74 dirt
setblock ~162 ~105 ~76 dirt
setblock ~162 ~105 ~77 dirt
setblock ~162 ~105 ~78 dirt
setblock ~162 ~105 ~79 dirt
setblock ~162 ~106 ~74 dirt
setblock ~162 ~106 ~75 dirt
setblock ~162 ~106 ~76 dirt
setblock ~162 ~106 ~77 dirt
setblock ~162 ~106 ~78 dirt
setblock ~162 ~106 ~79 dirt
setblock ~162 ~106 ~80 dirt
setblock ~162 ~107 ~73 dirt
setblock ~162 ~107 ~74 dirt
setblock ~162 ~107 ~75 dirt
setblock ~162 ~107 ~76 dirt
setblock ~162 ~107 ~77 dirt
setblock ~162 ~107 ~78 dirt
setblock ~162 ~107 ~79 dirt
setblock ~162 ~107 ~80 dirt
setblock ~162 ~107 ~81 dirt
setblock ~162 ~108 ~72 dirt
setblock ~162 ~108 ~73 dirt
setblock ~162 ~108 ~74 dirt
setblock ~162 ~108 ~75 dirt
setblock ~162 ~108 ~76 dirt
setblock ~162 ~108 ~77 dirt
setblock ~162 ~108 ~78 dirt
setblock ~162 ~108 ~79 dirt
setblock ~162 ~108 ~80 dirt
setblock ~162 ~108 ~81 dirt
setblock ~162 ~108 ~104 dirt
setblock ~162 ~108 ~106 dirt
setblock ~162 ~108 ~107 dirt
setblock ~162 ~109 ~72 dirt
setblock ~162 ~109 ~73 dirt
setblock ~162 ~109 ~74 dirt
setblock ~162 ~109 ~75 dirt
setblock ~162 ~109 ~76 dirt
setblock ~162 ~109 ~77 dirt
setblock ~162 ~109 ~78 dirt
setblock ~162 ~109 ~79 dirt
setblock ~162 ~109 ~80 dirt
setblock ~162 ~109 ~81 dirt
setblock ~162 ~109 ~82 dirt
setblock ~162 ~109 ~104 dirt
setblock ~162 ~109 ~106 dirt
setblock ~162 ~109 ~107 dirt
setblock ~162 ~109 ~108 dirt
setblock ~162 ~110 ~71 dirt
setblock ~162 ~110 ~72 dirt
setblock ~162 ~110 ~73 dirt
setblock ~162 ~110 ~74 dirt
setblock ~162 ~110 ~75 dirt
setblock ~162 ~110 ~76 dirt
setblock ~162 ~110 ~77 dirt
setblock ~162 ~110 ~78 dirt
setblock ~162 ~110 ~79 dirt
setblock ~162 ~110 ~80 dirt
setblock ~162 ~110 ~81 dirt
setblock ~162 ~110 ~82 dirt
setblock ~162 ~110 ~104 dirt
setblock ~162 ~110 ~106 dirt
setblock ~162 ~110 ~107 dirt
setblock ~162 ~110 ~108 dirt
setblock ~162 ~111 ~71 dirt
setblock ~162 ~111 ~72 dirt
setblock ~162 ~111 ~73 dirt
setblock ~162 ~111 ~74 dirt
setblock ~162 ~111 ~75 dirt
setblock ~162 ~111 ~76 dirt
setblock ~162 ~111 ~77 dirt
setblock ~162 ~111 ~78 dirt
setblock ~162 ~111 ~79 dirt
setblock ~162 ~111 ~80 dirt
setblock ~162 ~111 ~81 dirt
setblock ~162 ~111 ~82 dirt
setblock ~162 ~111 ~83 dirt
setblock ~162 ~111 ~101 dirt
setblock ~162 ~111 ~103 dirt
setblock ~162 ~111 ~104 dirt
setblock ~162 ~111 ~105 dirt
setblock ~162 ~111 ~106 dirt
setblock ~162 ~111 ~107 dirt
setblock ~162 ~111 ~108 dirt
setblock ~162 ~111 ~109 dirt
setblock ~162 ~112 ~70 dirt
setblock ~162 ~112 ~71 dirt
setblock ~162 ~112 ~72 dirt
setblock ~162 ~112 ~73 dirt
setblock ~162 ~112 ~74 dirt
setblock ~162 ~112 ~75 dirt
setblock ~162 ~112 ~76 dirt
setblock ~162 ~112 ~77 dirt
setblock ~162 ~112 ~78 dirt
setblock ~162 ~112 ~79 dirt
setblock ~162 ~112 ~80 dirt
setblock ~162 ~112 ~81 dirt
setblock ~162 ~112 ~82 dirt
setblock ~162 ~112 ~83 dirt
setblock ~162 ~112 ~95 dirt
setblock ~162 ~112 ~100 dirt
setblock ~162 ~112 ~101 dirt
setblock ~162 ~112 ~102 dirt
setblock ~162 ~112 ~103 dirt
setblock ~162 ~112 ~104 dirt
setblock ~162 ~112 ~105 dirt
setblock ~162 ~112 ~106 dirt
setblock ~162 ~112 ~107 dirt
setblock ~162 ~112 ~108 dirt
setblock ~162 ~112 ~109 dirt
setblock ~162 ~113 ~69 dirt
setblock ~162 ~113 ~70 dirt
setblock ~162 ~113 ~71 dirt
setblock ~162 ~113 ~72 dirt
setblock ~162 ~113 ~73 dirt
setblock ~162 ~113 ~74 dirt
setblock ~162 ~113 ~75 dirt
setblock ~162 ~113 ~76 dirt
setblock ~162 ~113 ~77 dirt
setblock ~162 ~113 ~78 dirt
setblock ~162 ~113 ~79 dirt
setblock ~162 ~113 ~80 dirt
setblock ~162 ~113 ~81 dirt
setblock ~162 ~113 ~82 dirt
setblock ~162 ~113 ~83 dirt
setblock ~162 ~113 ~84 dirt
setblock ~162 ~113 ~94 dirt
setblock ~162 ~113 ~95 dirt
setblock ~162 ~113 ~96 dirt
setblock ~162 ~113 ~100 dirt
setblock ~162 ~113 ~101 dirt
setblock ~162 ~113 ~102 dirt
setblock ~162 ~113 ~103 dirt
setblock ~162 ~113 ~104 dirt
setblock ~162 ~113 ~105 dirt
setblock ~162 ~113 ~106 dirt
setblock ~162 ~113 ~107 dirt
setblock ~162 ~113 ~108 dirt
setblock ~162 ~113 ~109 dirt
setblock ~162 ~113 ~110 dirt
setblock ~162 ~114 ~68 dirt
setblock ~162 ~114 ~69 dirt
setblock ~162 ~114 ~70 dirt
setblock ~162 ~114 ~71 dirt
setblock ~162 ~114 ~72 dirt
setblock ~162 ~114 ~73 dirt
setblock ~162 ~114 ~74 dirt
setblock ~162 ~114 ~75 dirt
setblock ~162 ~114 ~76 dirt
setblock ~162 ~114 ~77 dirt
setblock ~162 ~114 ~78 dirt
setblock ~162 ~114 ~79 dirt
setblock ~162 ~114 ~80 dirt
setblock ~162 ~114 ~81 dirt
setblock ~162 ~114 ~82 dirt
setblock ~162 ~114 ~83 dirt
setblock ~162 ~114 ~84 dirt
setblock ~162 ~114 ~93 dirt
setblock ~162 ~114 ~94 dirt
setblock ~162 ~114 ~95 dirt
setblock ~162 ~114 ~96 dirt
setblock ~162 ~114 ~97 dirt
setblock ~162 ~114 ~98 dirt
setblock ~162 ~114 ~100 dirt
setblock ~162 ~114 ~101 dirt
setblock ~162 ~114 ~102 dirt
setblock ~162 ~114 ~103 dirt
setblock ~162 ~114 ~104 dirt
setblock ~162 ~114 ~105 dirt
setblock ~162 ~114 ~106 dirt
setblock ~162 ~114 ~107 dirt
setblock ~162 ~114 ~108 dirt
setblock ~162 ~114 ~109 dirt
setblock ~162 ~114 ~110 dirt
setblock ~162 ~115 ~68 dirt
setblock ~162 ~115 ~69 dirt
setblock ~162 ~115 ~70 dirt
setblock ~162 ~115 ~71 dirt
setblock ~162 ~115 ~72 dirt
setblock ~162 ~115 ~73 dirt
setblock ~162 ~115 ~74 dirt
setblock ~162 ~115 ~75 dirt
setblock ~162 ~115 ~76 dirt
setblock ~162 ~115 ~77 dirt
setblock ~162 ~115 ~78 dirt
setblock ~162 ~115 ~79 dirt
setblock ~162 ~115 ~80 dirt
setblock ~162 ~115 ~81 dirt
setblock ~162 ~115 ~82 dirt
setblock ~162 ~115 ~83 dirt
setblock ~162 ~115 ~84 dirt
setblock ~162 ~115 ~93 dirt
setblock ~162 ~115 ~94 dirt
setblock ~162 ~115 ~95 dirt
setblock ~162 ~115 ~96 dirt
setblock ~162 ~115 ~97 dirt
setblock ~162 ~115 ~98 dirt
setblock ~162 ~115 ~99 dirt
setblock ~162 ~115 ~100 dirt
setblock ~162 ~115 ~101 dirt
setblock ~162 ~115 ~102 dirt
setblock ~162 ~115 ~103 dirt
setblock ~162 ~115 ~104 dirt
setblock ~162 ~115 ~105 dirt
setblock ~162 ~115 ~106 dirt
setblock ~162 ~115 ~107 dirt
setblock ~162 ~115 ~108 dirt
setblock ~162 ~115 ~109 dirt
setblock ~162 ~115 ~110 dirt
setblock ~162 ~115 ~111 dirt
setblock ~162 ~115 ~125 dirt
setblock ~162 ~116 ~68 dirt
setblock ~162 ~116 ~69 dirt
setblock ~162 ~116 ~70 dirt
setblock ~162 ~116 ~71 dirt
setblock ~162 ~116 ~72 dirt
setblock ~162 ~116 ~73 dirt
setblock ~162 ~116 ~74 dirt
setblock ~162 ~116 ~75 dirt
setblock ~162 ~116 ~76 dirt
setblock ~162 ~116 ~77 dirt
setblock ~162 ~116 ~78 dirt
setblock ~162 ~116 ~79 dirt
setblock ~162 ~116 ~80 dirt
setblock ~162 ~116 ~81 dirt
setblock ~162 ~116 ~82 dirt
setblock ~162 ~116 ~83 dirt
setblock ~162 ~116 ~84 dirt
setblock ~162 ~116 ~92 dirt
setblock ~162 ~116 ~93 dirt
setblock ~162 ~116 ~94 dirt
setblock ~162 ~116 ~95 dirt
setblock ~162 ~116 ~96 dirt
setblock ~162 ~116 ~97 dirt
setblock ~162 ~116 ~98 dirt
setblock ~162 ~116 ~99 dirt
setblock ~162 ~116 ~100 dirt
setblock ~162 ~116 ~101 dirt
setblock ~162 ~116 ~102 dirt
setblock ~162 ~116 ~103 dirt
setblock ~162 ~116 ~104 dirt
setblock ~162 ~116 ~105 dirt
setblock ~162 ~116 ~106 dirt
setblock ~162 ~116 ~107 dirt
setblock ~162 ~116 ~108 dirt
setblock ~162 ~116 ~109 dirt
setblock ~162 ~116 ~110 dirt
setblock ~162 ~116 ~111 dirt
setblock ~162 ~116 ~122 dirt
setblock ~162 ~116 ~124 dirt
setblock ~162 ~116 ~125 dirt
setblock ~162 ~116 ~126 dirt
setblock ~162 ~117 ~67 dirt
setblock ~162 ~117 ~68 dirt
setblock ~162 ~117 ~69 dirt
setblock ~162 ~117 ~70 dirt
setblock ~162 ~117 ~71 dirt
setblock ~162 ~117 ~72 dirt
setblock ~162 ~117 ~73 dirt
setblock ~162 ~117 ~74 dirt
setblock ~162 ~117 ~75 dirt
setblock ~162 ~117 ~76 dirt
setblock ~162 ~117 ~77 dirt
setblock ~162 ~117 ~78 dirt
setblock ~162 ~117 ~79 dirt
setblock ~162 ~117 ~80 dirt
setblock ~162 ~117 ~81 dirt
setblock ~162 ~117 ~82 dirt
setblock ~162 ~117 ~83 dirt
setblock ~162 ~117 ~84 dirt
setblock ~162 ~117 ~85 dirt
setblock ~162 ~117 ~91 dirt
setblock ~162 ~117 ~92 dirt
setblock ~162 ~117 ~93 dirt
setblock ~162 ~117 ~94 dirt
setblock ~162 ~117 ~95 dirt
setblock ~162 ~117 ~96 dirt
setblock ~162 ~117 ~97 dirt
setblock ~162 ~117 ~98 dirt
setblock ~162 ~117 ~99 dirt
setblock ~162 ~117 ~100 dirt
setblock ~162 ~117 ~101 dirt
setblock ~162 ~117 ~102 dirt
setblock ~162 ~117 ~103 dirt
setblock ~162 ~117 ~104 dirt
setblock ~162 ~117 ~105 dirt
setblock ~162 ~117 ~106 dirt
setblock ~162 ~117 ~107 dirt
setblock ~162 ~117 ~108 dirt
setblock ~162 ~117 ~109 dirt
setblock ~162 ~117 ~110 dirt
setblock ~162 ~117 ~111 dirt
setblock ~162 ~117 ~112 dirt
setblock ~162 ~117 ~122 dirt
setblock ~162 ~117 ~123 dirt
setblock ~162 ~117 ~124 dirt
setblock ~162 ~117 ~125 dirt
setblock ~162 ~117 ~126 dirt
setblock ~162 ~117 ~128 dirt
setblock ~162 ~118 ~67 dirt
setblock ~162 ~118 ~68 dirt
setblock ~162 ~118 ~69 dirt
setblock ~162 ~118 ~70 dirt
setblock ~162 ~118 ~71 dirt
setblock ~162 ~118 ~72 dirt
setblock ~162 ~118 ~73 dirt
setblock ~162 ~118 ~74 dirt
setblock ~162 ~118 ~75 dirt
setblock ~162 ~118 ~76 dirt
setblock ~162 ~118 ~77 dirt
setblock ~162 ~118 ~78 dirt
setblock ~162 ~118 ~79 dirt
setblock ~162 ~118 ~80 dirt
setblock ~162 ~118 ~81 dirt
setblock ~162 ~118 ~82 dirt
setblock ~162 ~118 ~83 dirt
setblock ~162 ~118 ~84 dirt
setblock ~162 ~118 ~85 dirt
setblock ~162 ~118 ~86 dirt
setblock ~162 ~118 ~91 dirt
setblock ~162 ~118 ~92 dirt
setblock ~162 ~118 ~93 dirt
setblock ~162 ~118 ~94 dirt
setblock ~162 ~118 ~95 dirt
setblock ~162 ~118 ~96 dirt
setblock ~162 ~118 ~97 dirt
setblock ~162 ~118 ~98 dirt
setblock ~162 ~118 ~99 dirt
setblock ~162 ~118 ~100 dirt
setblock ~162 ~118 ~101 dirt
setblock ~162 ~118 ~102 dirt
setblock ~162 ~118 ~103 dirt
setblock ~162 ~118 ~104 dirt
setblock ~162 ~118 ~105 dirt
setblock ~162 ~118 ~106 dirt
setblock ~162 ~118 ~107 dirt
setblock ~162 ~118 ~108 dirt
setblock ~162 ~118 ~109 dirt
setblock ~162 ~118 ~110 dirt
setblock ~162 ~118 ~111 dirt
setblock ~162 ~118 ~112 dirt
setblock ~162 ~118 ~113 dirt
setblock ~162 ~118 ~119 dirt
setblock ~162 ~118 ~122 dirt
setblock ~162 ~118 ~123 dirt
setblock ~162 ~118 ~124 dirt
setblock ~162 ~118 ~125 dirt
setblock ~162 ~118 ~126 dirt
setblock ~162 ~118 ~127 dirt
setblock ~162 ~118 ~128 dirt
setblock ~162 ~119 ~66 dirt
setblock ~162 ~119 ~67 dirt
setblock ~162 ~119 ~68 dirt
setblock ~162 ~119 ~69 dirt
setblock ~162 ~119 ~70 dirt
setblock ~162 ~119 ~71 dirt
setblock ~162 ~119 ~72 dirt
setblock ~162 ~119 ~73 dirt
setblock ~162 ~119 ~74 dirt
setblock ~162 ~119 ~75 dirt
setblock ~162 ~119 ~76 dirt
setblock ~162 ~119 ~77 dirt
setblock ~162 ~119 ~78 dirt
setblock ~162 ~119 ~79 dirt
setblock ~162 ~119 ~80 dirt
setblock ~162 ~119 ~81 dirt
setblock ~162 ~119 ~82 dirt
setblock ~162 ~119 ~83 dirt
setblock ~162 ~119 ~84 dirt
setblock ~162 ~119 ~85 dirt
setblock ~162 ~119 ~86 dirt
setblock ~162 ~119 ~87 dirt
setblock ~162 ~119 ~90 dirt
setblock ~162 ~119 ~91 dirt
setblock ~162 ~119 ~92 dirt
setblock ~162 ~119 ~93 dirt
setblock ~162 ~119 ~94 dirt
setblock ~162 ~119 ~95 dirt
setblock ~162 ~119 ~96 dirt
setblock ~162 ~119 ~97 dirt
setblock ~162 ~119 ~98 dirt
setblock ~162 ~119 ~99 dirt
setblock ~162 ~119 ~100 dirt
setblock ~162 ~119 ~101 dirt
setblock ~162 ~119 ~102 dirt
setblock ~162 ~119 ~103 dirt
setblock ~162 ~119 ~104 dirt
setblock ~162 ~119 ~105 dirt
setblock ~162 ~119 ~106 dirt
setblock ~162 ~119 ~107 dirt
setblock ~162 ~119 ~108 dirt
setblock ~162 ~119 ~109 dirt
setblock ~162 ~119 ~110 dirt
setblock ~162 ~119 ~111 dirt
setblock ~162 ~119 ~112 dirt
setblock ~162 ~119 ~113 dirt
setblock ~162 ~119 ~115 dirt
setblock ~162 ~119 ~118 dirt
setblock ~162 ~119 ~119 dirt
setblock ~162 ~119 ~120 dirt
setblock ~162 ~119 ~121 dirt
setblock ~162 ~119 ~122 dirt
setblock ~162 ~119 ~123 dirt
setblock ~162 ~119 ~124 dirt
setblock ~162 ~119 ~125 dirt
setblock ~162 ~119 ~126 dirt
setblock ~162 ~119 ~127 dirt
setblock ~162 ~119 ~128 dirt
setblock ~162 ~119 ~129 dirt
setblock ~162 ~119 ~132 dirt
setblock ~162 ~120 ~66 dirt
setblock ~162 ~120 ~67 dirt
setblock ~162 ~120 ~68 dirt
setblock ~162 ~120 ~69 dirt
setblock ~162 ~120 ~70 dirt
setblock ~162 ~120 ~71 dirt
setblock ~162 ~120 ~72 dirt
setblock ~162 ~120 ~73 dirt
setblock ~162 ~120 ~74 dirt
setblock ~162 ~120 ~75 dirt
setblock ~162 ~120 ~76 dirt
setblock ~162 ~120 ~77 dirt
setblock ~162 ~120 ~78 dirt
setblock ~162 ~120 ~79 dirt
setblock ~162 ~120 ~80 dirt
setblock ~162 ~120 ~81 dirt
setblock ~162 ~120 ~82 dirt
setblock ~162 ~120 ~83 dirt
setblock ~162 ~120 ~84 dirt
setblock ~162 ~120 ~85 dirt
setblock ~162 ~120 ~86 dirt
setblock ~162 ~120 ~87 dirt
setblock ~162 ~120 ~88 dirt
setblock ~162 ~120 ~90 dirt
setblock ~162 ~120 ~91 dirt
setblock ~162 ~120 ~92 dirt
setblock ~162 ~120 ~93 dirt
setblock ~162 ~120 ~94 dirt
setblock ~162 ~120 ~95 dirt
setblock ~162 ~120 ~96 dirt
setblock ~162 ~120 ~97 dirt
setblock ~162 ~120 ~98 dirt
setblock ~162 ~120 ~99 dirt
setblock ~162 ~120 ~100 dirt
setblock ~162 ~120 ~101 dirt
setblock ~162 ~120 ~102 dirt
setblock ~162 ~120 ~103 dirt
setblock ~162 ~120 ~104 dirt
setblock ~162 ~120 ~105 dirt
setblock ~162 ~120 ~106 dirt
setblock ~162 ~120 ~107 dirt
setblock ~162 ~120 ~108 dirt
setblock ~162 ~120 ~109 dirt
setblock ~162 ~120 ~110 dirt
setblock ~162 ~120 ~111 dirt
setblock ~162 ~120 ~112 dirt
setblock ~162 ~120 ~113 dirt
setblock ~162 ~120 ~115 dirt
setblock ~162 ~120 ~116 dirt
setblock ~162 ~120 ~117 dirt
setblock ~162 ~120 ~118 dirt
setblock ~162 ~120 ~119 dirt
setblock ~162 ~120 ~120 dirt
setblock ~162 ~120 ~121 dirt
setblock ~162 ~120 ~122 dirt
setblock ~162 ~120 ~123 dirt
setblock ~162 ~120 ~124 dirt
setblock ~162 ~120 ~125 dirt
setblock ~162 ~120 ~126 dirt
setblock ~162 ~120 ~127 dirt
setblock ~162 ~120 ~128 dirt
setblock ~162 ~120 ~129 dirt
setblock ~162 ~120 ~130 dirt
setblock ~162 ~120 ~132 dirt
setblock ~162 ~120 ~133 dirt
setblock ~162 ~121 ~65 dirt
setblock ~162 ~121 ~66 dirt
setblock ~162 ~121 ~67 dirt
setblock ~162 ~121 ~68 dirt
setblock ~162 ~121 ~69 dirt
setblock ~162 ~121 ~70 dirt
setblock ~162 ~121 ~71 dirt
setblock ~162 ~121 ~72 dirt
setblock ~162 ~121 ~73 dirt
setblock ~162 ~121 ~74 dirt
setblock ~162 ~121 ~75 dirt
setblock ~162 ~121 ~76 dirt
setblock ~162 ~121 ~77 dirt
setblock ~162 ~121 ~78 dirt
setblock ~162 ~121 ~79 dirt
setblock ~162 ~121 ~80 dirt
setblock ~162 ~121 ~81 dirt
setblock ~162 ~121 ~82 dirt
setblock ~162 ~121 ~83 dirt
setblock ~162 ~121 ~84 dirt
setblock ~162 ~121 ~85 dirt
setblock ~162 ~121 ~86 dirt
setblock ~162 ~121 ~87 dirt
setblock ~162 ~121 ~88 dirt
setblock ~162 ~121 ~89 dirt
setblock ~162 ~121 ~90 dirt
setblock ~162 ~121 ~91 dirt
setblock ~162 ~121 ~92 dirt
setblock ~162 ~121 ~93 dirt
setblock ~162 ~121 ~94 dirt
setblock ~162 ~121 ~95 dirt
setblock ~162 ~121 ~96 dirt
setblock ~162 ~121 ~97 dirt
setblock ~162 ~121 ~98 dirt
setblock ~162 ~121 ~99 dirt
setblock ~162 ~121 ~100 dirt
setblock ~162 ~121 ~101 dirt
setblock ~162 ~121 ~102 dirt
setblock ~162 ~121 ~103 dirt
setblock ~162 ~121 ~104 dirt
setblock ~162 ~121 ~105 dirt
setblock ~162 ~121 ~106 dirt
setblock ~162 ~121 ~107 dirt
setblock ~162 ~121 ~108 dirt
setblock ~162 ~121 ~109 dirt
setblock ~162 ~121 ~110 dirt
setblock ~162 ~121 ~111 dirt
setblock ~162 ~121 ~112 dirt
setblock ~162 ~121 ~113 dirt
setblock ~162 ~121 ~114 dirt
setblock ~162 ~121 ~115 dirt
setblock ~162 ~121 ~116 dirt
setblock ~162 ~121 ~117 dirt
setblock ~162 ~121 ~118 dirt
setblock ~162 ~121 ~119 dirt
setblock ~162 ~121 ~120 dirt
setblock ~162 ~121 ~121 dirt
setblock ~162 ~121 ~122 dirt
setblock ~162 ~121 ~123 dirt
setblock ~162 ~121 ~124 dirt
setblock ~162 ~121 ~125 dirt
setblock ~162 ~121 ~126 dirt
setblock ~162 ~121 ~127 dirt
setblock ~162 ~121 ~128 dirt
setblock ~162 ~121 ~129 dirt
setblock ~162 ~121 ~130 dirt
setblock ~162 ~121 ~131 dirt
setblock ~162 ~121 ~132 dirt
setblock ~162 ~121 ~133 dirt
setblock ~162 ~122 ~65 dirt
setblock ~162 ~122 ~66 dirt
setblock ~162 ~122 ~67 dirt
setblock ~162 ~122 ~68 dirt
setblock ~162 ~122 ~69 dirt
setblock ~162 ~122 ~70 dirt
setblock ~162 ~122 ~71 dirt
setblock ~162 ~122 ~72 dirt
setblock ~162 ~122 ~73 dirt
setblock ~162 ~122 ~74 dirt
setblock ~162 ~122 ~75 dirt
setblock ~162 ~122 ~76 dirt
setblock ~162 ~122 ~77 dirt
setblock ~162 ~122 ~78 dirt
setblock ~162 ~122 ~79 dirt
setblock ~162 ~122 ~80 dirt
setblock ~162 ~122 ~81 dirt
setblock ~162 ~122 ~82 dirt
setblock ~162 ~122 ~83 dirt
setblock ~162 ~122 ~84 dirt
setblock ~162 ~122 ~85 dirt
setblock ~162 ~122 ~86 dirt
setblock ~162 ~122 ~87 dirt
setblock ~162 ~122 ~88 dirt
setblock ~162 ~122 ~89 dirt
setblock ~162 ~122 ~90 dirt
setblock ~162 ~122 ~91 dirt
setblock ~162 ~122 ~92 dirt
setblock ~162 ~122 ~93 dirt
setblock ~162 ~122 ~94 dirt
setblock ~162 ~122 ~95 dirt
setblock ~162 ~122 ~96 dirt
setblock ~162 ~122 ~97 dirt
setblock ~162 ~122 ~98 dirt
setblock ~162 ~122 ~99 dirt
setblock ~162 ~122 ~100 dirt
setblock ~162 ~122 ~101 dirt
setblock ~162 ~122 ~102 dirt
setblock ~162 ~122 ~103 dirt
setblock ~162 ~122 ~104 dirt
setblock ~162 ~122 ~105 dirt
setblock ~162 ~122 ~106 dirt
setblock ~162 ~122 ~107 dirt
setblock ~162 ~122 ~108 dirt
setblock ~162 ~122 ~109 dirt
setblock ~162 ~122 ~110 dirt
setblock ~162 ~122 ~111 dirt
setblock ~162 ~122 ~112 dirt
setblock ~162 ~122 ~113 dirt
setblock ~162 ~122 ~114 dirt
setblock ~162 ~122 ~115 dirt
setblock ~162 ~122 ~116 dirt
setblock ~162 ~122 ~117 dirt
setblock ~162 ~122 ~118 dirt
setblock ~162 ~122 ~119 dirt
setblock ~162 ~122 ~120 dirt
setblock ~162 ~122 ~121 dirt
setblock ~162 ~122 ~122 dirt
setblock ~162 ~122 ~123 dirt
setblock ~162 ~122 ~124 dirt
setblock ~162 ~122 ~125 dirt
setblock ~162 ~122 ~126 dirt
setblock ~162 ~122 ~127 dirt
setblock ~162 ~122 ~128 dirt
setblock ~162 ~122 ~129 dirt
setblock ~162 ~122 ~130 dirt
setblock ~162 ~122 ~131 dirt
setblock ~162 ~122 ~132 dirt
setblock ~162 ~122 ~133 dirt
setblock ~162 ~123 ~65 dirt
setblock ~162 ~123 ~66 dirt
setblock ~162 ~123 ~67 dirt
setblock ~162 ~123 ~68 dirt
setblock ~162 ~123 ~69 dirt
setblock ~162 ~123 ~70 dirt
setblock ~162 ~123 ~71 dirt
setblock ~162 ~123 ~72 dirt
setblock ~162 ~123 ~73 dirt
setblock ~162 ~123 ~74 dirt
setblock ~162 ~123 ~75 dirt
setblock ~162 ~123 ~76 dirt
setblock ~162 ~123 ~77 dirt
setblock ~162 ~123 ~78 grass_block
setblock ~162 ~123 ~79 grass_block
setblock ~162 ~123 ~80 grass_block
setblock ~162 ~123 ~81 grass_block
setblock ~162 ~123 ~82 dirt
setblock ~162 ~123 ~83 dirt
setblock ~162 ~123 ~84 dirt
setblock ~162 ~123 ~85 dirt
setblock ~162 ~123 ~86 dirt
setblock ~162 ~123 ~87 dirt
setblock ~162 ~123 ~88 dirt
setblock ~162 ~123 ~89 dirt
setblock ~162 ~123 ~90 dirt
setblock ~162 ~123 ~91 dirt
setblock ~162 ~123 ~92 dirt
setblock ~162 ~123 ~93 dirt
setblock ~162 ~123 ~94 dirt
setblock ~162 ~123 ~95 dirt
setblock ~162 ~123 ~96 dirt
setblock ~162 ~123 ~97 dirt
setblock ~162 ~123 ~98 dirt
setblock ~162 ~123 ~99 dirt
setblock ~162 ~123 ~100 dirt
setblock ~162 ~123 ~101 dirt
setblock ~162 ~123 ~102 dirt
setblock ~162 ~123 ~103 dirt
setblock ~162 ~123 ~104 dirt
setblock ~162 ~123 ~105 dirt
setblock ~162 ~123 ~106 dirt
setblock ~162 ~123 ~107 dirt
setblock ~162 ~123 ~108 dirt
setblock ~162 ~123 ~109 dirt
setblock ~162 ~123 ~110 dirt
setblock ~162 ~123 ~111 dirt
setblock ~162 ~123 ~112 dirt
setblock ~162 ~123 ~113 dirt
setblock ~162 ~123 ~114 dirt
setblock ~162 ~123 ~115 dirt
setblock ~162 ~123 ~116 dirt
setblock ~162 ~123 ~117 dirt
setblock ~162 ~123 ~118 dirt
setblock ~162 ~123 ~119 grass_block
setblock ~162 ~123 ~120 grass_block
setblock ~162 ~123 ~121 grass_block
setblock ~162 ~123 ~122 grass_block
setblock ~162 ~123 ~123 dirt
setblock ~162 ~123 ~124 dirt
setblock ~162 ~123 ~125 dirt
setblock ~162 ~123 ~126 dirt
setblock ~162 ~123 ~127 dirt
setblock ~162 ~123 ~128 dirt
setblock ~162 ~123 ~129 dirt
setblock ~162 ~123 ~130 dirt
setblock ~162 ~123 ~131 dirt
setblock ~162 ~123 ~132 dirt
setblock ~162 ~123 ~133 dirt
setblock ~162 ~124 ~65 grass_block
setblock ~162 ~124 ~66 grass_block
setblock ~162 ~124 ~67 grass_block
setblock ~162 ~124 ~68 grass_block
setblock ~162 ~124 ~69 dirt
setblock ~162 ~124 ~70 dirt
setblock ~162 ~124 ~71 grass_block
setblock ~162 ~124 ~72 grass_block
setblock ~162 ~124 ~73 grass_block
setblock ~162 ~124 ~74 grass_block
setblock ~162 ~124 ~75 grass_block
setblock ~162 ~124 ~76 grass_block
setblock ~162 ~124 ~77 grass_block
setblock ~162 ~124 ~80 poppy
setblock ~162 ~124 ~82 grass_block
setblock ~162 ~124 ~83 grass_block
setblock ~162 ~124 ~84 grass_block
setblock ~162 ~124 ~85 grass_block
setblock ~162 ~124 ~86 dirt
setblock ~162 ~124 ~87 dirt
setblock ~162 ~124 ~88 dirt
setblock ~162 ~124 ~89 dirt
setblock ~162 ~124 ~90 dirt
setblock ~162 ~124 ~91 dirt
setblock ~162 ~124 ~92 dirt
setblock ~162 ~124 ~93 dirt
setblock ~162 ~124 ~94 dirt
setblock ~162 ~124 ~95 dirt
setblock ~162 ~124 ~96 dirt
setblock ~162 ~124 ~97 dirt
setblock ~162 ~124 ~98 dirt
setblock ~162 ~124 ~99 dirt
setblock ~162 ~124 ~100 dirt
setblock ~162 ~124 ~101 dirt
setblock ~162 ~124 ~102 dirt
setblock ~162 ~124 ~103 dirt
setblock ~162 ~124 ~104 dirt
setblock ~162 ~124 ~105 dirt
setblock ~162 ~124 ~106 dirt
setblock ~162 ~124 ~107 dirt
setblock ~162 ~124 ~108 grass_block
setblock ~162 ~124 ~109 grass_block
setblock ~162 ~124 ~110 grass_block
setblock ~162 ~124 ~111 grass_block
setblock ~162 ~124 ~112 grass_block
setblock ~162 ~124 ~113 grass_block
setblock ~162 ~124 ~114 grass_block
setblock ~162 ~124 ~115 grass_block
setblock ~162 ~124 ~116 grass_block
setblock ~162 ~124 ~117 grass_block
setblock ~162 ~124 ~118 grass_block
setblock ~162 ~124 ~123 grass_block
setblock ~162 ~124 ~124 grass_block
setblock ~162 ~124 ~125 grass_block
setblock ~162 ~124 ~126 grass_block
setblock ~162 ~124 ~127 grass_block
setblock ~162 ~124 ~128 grass_block
setblock ~162 ~124 ~129 grass_block
setblock ~162 ~124 ~130 grass_block
setblock ~162 ~124 ~131 grass_block
setblock ~162 ~124 ~132 grass_block
setblock ~162 ~124 ~133 grass_block
setblock ~162 ~125 ~69 grass_block
setblock ~162 ~125 ~70 grass_block
setblock ~162 ~125 ~71 short_grass
setblock ~162 ~125 ~73 short_grass
setblock ~162 ~125 ~74 short_grass
setblock ~162 ~125 ~83 fern
setblock ~162 ~125 ~85 short_grass
setblock ~162 ~125 ~86 grass_block
setblock ~162 ~125 ~87 grass_block
setblock ~162 ~125 ~88 grass_block
setblock ~162 ~125 ~89 grass_block
setblock ~162 ~125 ~90 grass_block
setblock ~162 ~125 ~91 grass_block
setblock ~162 ~125 ~92 grass_block
setblock ~162 ~125 ~93 grass_block
setblock ~162 ~125 ~94 grass_block
setblock ~162 ~125 ~95 grass_block
setblock ~162 ~125 ~96 grass_block
setblock ~162 ~125 ~97 grass_block
setblock ~162 ~125 ~98 grass_block
setblock ~162 ~125 ~99 grass_block
setblock ~162 ~125 ~100 grass_block
setblock ~162 ~125 ~101 grass_block
setblock ~162 ~125 ~102 grass_block
setblock ~162 ~125 ~103 grass_block
setblock ~162 ~125 ~104 grass_block
setblock ~162 ~125 ~105 grass_block
setblock ~162 ~125 ~106 grass_block
setblock ~162 ~125 ~107 grass_block
setblock ~162 ~125 ~110 fern
setblock ~162 ~125 ~113 short_grass
setblock ~162 ~125 ~117 short_grass
setblock ~162 ~125 ~128 poppy
setblock ~162 ~125 ~129 poppy
setblock ~162 ~125 ~130 short_grass
setblock ~162 ~125 ~131 short_grass
setblock ~162 ~126 ~70 poppy
setblock ~162 ~126 ~86 short_grass
setblock ~162 ~126 ~87 short_grass
setblock ~162 ~126 ~92 short_grass
setblock ~162 ~126 ~94 poppy
setblock ~162 ~126 ~101 short_grass
setblock ~162 ~126 ~103 short_grass
setblock ~162 ~126 ~104 poppy
setblock ~162 ~126 ~106 short_grass
setblock ~162 ~132 ~74 oak_leaves[persistent=true]
setblock ~162 ~132 ~75 oak_leaves[persistent=true]
setblock ~162 ~132 ~76 oak_leaves[persistent=true]
setblock ~162 ~133 ~74 jungle_leaves[persistent=true]
setblock ~162 ~133 ~75 oak_leaves[persistent=true]
setblock ~162 ~133 ~76 jungle_leaves[persistent=true]
setblock ~162 ~134 ~75 oak_wood
setblock ~162 ~134 ~76 oak_leaves[persistent=true]
setblock ~162 ~135 ~74 jungle_leaves[persistent=true]
setblock ~162 ~135 ~75 jungle_leaves[persistent=true]
setblock ~162 ~135 ~79 oak_leaves[persistent=true]
setblock ~162 ~135 ~80 oak_leaves[persistent=true]
setblock ~162 ~135 ~81 jungle_leaves[persistent=true]
setblock ~162 ~135 ~82 oak_leaves[persistent=true]
setblock ~162 ~136 ~79 oak_leaves[persistent=true]
setblock ~162 ~136 ~80 oak_leaves[persistent=true]
setblock ~162 ~136 ~81 jungle_leaves[persistent=true]
setblock ~162 ~136 ~82 oak_leaves[persistent=true]
setblock ~162 ~137 ~79 oak_leaves[persistent=true]
setblock ~162 ~137 ~80 oak_leaves[persistent=true]
setblock ~162 ~137 ~81 oak_leaves[persistent=true]
setblock ~162 ~137 ~82 oak_leaves[persistent=true]
setblock ~162 ~138 ~79 oak_leaves[persistent=true]
setblock ~162 ~138 ~80 jungle_leaves[persistent=true]
setblock ~162 ~138 ~81 oak_leaves[persistent=true]
setblock ~162 ~138 ~82 oak_leaves[persistent=true]
setblock ~163 ~105 ~77 dirt
setblock ~163 ~106 ~76 dirt
setblock ~163 ~106 ~77 dirt
setblock ~163 ~106 ~78 dirt
setblock ~163 ~107 ~74 dirt
setblock ~163 ~107 ~75 dirt
setblock ~163 ~107 ~76 dirt
setblock ~163 ~107 ~77 dirt
setblock ~163 ~107 ~78 dirt
setblock ~163 ~107 ~79 dirt
setblock ~163 ~107 ~80 dirt
setblock ~163 ~108 ~73 dirt
setblock ~163 ~108 ~74 dirt
setblock ~163 ~108 ~75 dirt
setblock ~163 ~108 ~76 dirt
setblock ~163 ~108 ~77 dirt
setblock ~163 ~108 ~78 dirt
setblock ~163 ~108 ~79 dirt
setblock ~163 ~108 ~80 dirt
setblock ~163 ~108 ~81 dirt
setblock ~163 ~109 ~73 dirt
setblock ~163 ~109 ~74 dirt
setblock ~163 ~109 ~75 dirt
setblock ~163 ~109 ~76 dirt
setblock ~163 ~109 ~77 dirt
setblock ~163 ~109 ~78 dirt
setblock ~163 ~109 ~79 dirt
setblock ~163 ~109 ~80 dirt
setblock ~163 ~109 ~81 dirt
setblock ~163 ~109 ~82 dirt
setblock ~163 ~110 ~72 dirt
setblock ~163 ~110 ~73 dirt
setblock ~163 ~110 ~74 dirt
setblock ~163 ~110 ~75 dirt
setblock ~163 ~110 ~76 dirt
setblock ~163 ~110 ~77 dirt
setblock ~163 ~110 ~78 dirt
setblock ~163 ~110 ~79 dirt
setblock ~163 ~110 ~80 dirt
setblock ~163 ~110 ~81 dirt
setblock ~163 ~110 ~82 dirt
setblock ~163 ~110 ~107 dirt
setblock ~163 ~111 ~71 dirt
setblock ~163 ~111 ~72 dirt
setblock ~163 ~111 ~73 dirt
setblock ~163 ~111 ~74 dirt
setblock ~163 ~111 ~75 dirt
setblock ~163 ~111 ~76 dirt
setblock ~163 ~111 ~77 dirt
setblock ~163 ~111 ~78 dirt
setblock ~163 ~111 ~79 dirt
setblock ~163 ~111 ~80 dirt
setblock ~163 ~111 ~81 dirt
setblock ~163 ~111 ~82 dirt
setblock ~163 ~111 ~83 dirt
setblock ~163 ~111 ~106 dirt
setblock ~163 ~111 ~107 dirt
setblock ~163 ~111 ~108 dirt
setblock ~163 ~112 ~71 dirt
setblock ~163 ~112 ~72 dirt
setblock ~163 ~112 ~73 dirt
setblock ~163 ~112 ~74 dirt
setblock ~163 ~112 ~75 dirt
setblock ~163 ~112 ~76 dirt
setblock ~163 ~112 ~77 dirt
setblock ~163 ~112 ~78 dirt
setblock ~163 ~112 ~79 dirt
setblock ~163 ~112 ~80 dirt
setblock ~163 ~112 ~81 dirt
setblock ~163 ~112 ~82 dirt
setblock ~163 ~112 ~83 dirt
setblock ~163 ~112 ~104 dirt
setblock ~163 ~112 ~105 dirt
setblock ~163 ~112 ~106 dirt
setblock ~163 ~112 ~107 dirt
setblock ~163 ~112 ~108 dirt
setblock ~163 ~113 ~70 dirt
setblock ~163 ~113 ~71 dirt
setblock ~163 ~113 ~72 dirt
setblock ~163 ~113 ~73 dirt
setblock ~163 ~113 ~74 dirt
setblock ~163 ~113 ~75 dirt
setblock ~163 ~113 ~76 dirt
setblock ~163 ~113 ~77 dirt
setblock ~163 ~113 ~78 dirt
setblock ~163 ~113 ~79 dirt
setblock ~163 ~113 ~80 dirt
setblock ~163 ~113 ~81 dirt
setblock ~163 ~113 ~82 dirt
setblock ~163 ~113 ~83 dirt
setblock ~163 ~113 ~84 dirt
setblock ~163 ~113 ~103 dirt
setblock ~163 ~113 ~104 dirt
setblock ~163 ~113 ~105 dirt
setblock ~163 ~113 ~106 dirt
setblock ~163 ~113 ~107 dirt
setblock ~163 ~113 ~108 dirt
setblock ~163 ~113 ~109 dirt
setblock ~163 ~114 ~69 dirt
setblock ~163 ~114 ~70 dirt
setblock ~163 ~114 ~71 dirt
setblock ~163 ~114 ~72 dirt
setblock ~163 ~114 ~73 dirt
setblock ~163 ~114 ~74 dirt
setblock ~163 ~114 ~75 dirt
setblock ~163 ~114 ~76 dirt
setblock ~163 ~114 ~77 dirt
setblock ~163 ~114 ~78 dirt
setblock ~163 ~114 ~79 dirt
setblock ~163 ~114 ~80 dirt
setblock ~163 ~114 ~81 dirt
setblock ~163 ~114 ~82 dirt
setblock ~163 ~114 ~83 dirt
setblock ~163 ~114 ~84 dirt
setblock ~163 ~114 ~94 dirt
setblock ~163 ~114 ~96 dirt
setblock ~163 ~114 ~102 dirt
setblock ~163 ~114 ~103 dirt
setblock ~163 ~114 ~104 dirt
setblock ~163 ~114 ~105 dirt
setblock ~163 ~114 ~106 dirt
setblock ~163 ~114 ~107 dirt
setblock ~163 ~114 ~108 dirt
setblock ~163 ~114 ~109 dirt
setblock ~163 ~115 ~69 dirt
setblock ~163 ~115 ~70 dirt
setblock ~163 ~115 ~71 dirt
setblock ~163 ~115 ~72 dirt
setblock ~163 ~115 ~73 dirt
setblock ~163 ~115 ~74 dirt
setblock ~163 ~115 ~75 dirt
setblock ~163 ~115 ~76 dirt
setblock ~163 ~115 ~77 dirt
setblock ~163 ~115 ~78 dirt
setblock ~163 ~115 ~79 dirt
setblock ~163 ~115 ~80 dirt
setblock ~163 ~115 ~81 dirt
setblock ~163 ~115 ~82 dirt
setblock ~163 ~115 ~83 dirt
setblock ~163 ~115 ~84 dirt
setblock ~163 ~115 ~85 dirt
setblock ~163 ~115 ~94 dirt
setblock ~163 ~115 ~95 dirt
setblock ~163 ~115 ~96 dirt
setblock ~163 ~115 ~100 dirt
setblock ~163 ~115 ~101 dirt
setblock ~163 ~115 ~102 dirt
setblock ~163 ~115 ~103 dirt
setblock ~163 ~115 ~104 dirt
setblock ~163 ~115 ~105 dirt
setblock ~163 ~115 ~106 dirt
setblock ~163 ~115 ~107 dirt
setblock ~163 ~115 ~108 dirt
setblock ~163 ~115 ~109 dirt
setblock ~163 ~115 ~110 dirt
setblock ~163 ~116 ~69 dirt
setblock ~163 ~116 ~70 dirt
setblock ~163 ~116 ~71 dirt
setblock ~163 ~116 ~72 dirt
setblock ~163 ~116 ~73 dirt
setblock ~163 ~116 ~74 dirt
setblock ~163 ~116 ~75 dirt
setblock ~163 ~116 ~76 dirt
setblock ~163 ~116 ~77 dirt
setblock ~163 ~116 ~78 dirt
setblock ~163 ~116 ~79 dirt
setblock ~163 ~116 ~80 dirt
setblock ~163 ~116 ~81 dirt
setblock ~163 ~116 ~82 dirt
setblock ~163 ~116 ~83 dirt
setblock ~163 ~116 ~84 dirt
setblock ~163 ~116 ~85 dirt
setblock ~163 ~116 ~93 dirt
setblock ~163 ~116 ~94 dirt
setblock ~163 ~116 ~95 dirt
setblock ~163 ~116 ~96 dirt
setblock ~163 ~116 ~98 dirt
setblock ~163 ~116 ~99 dirt
setblock ~163 ~116 ~100 dirt
setblock ~163 ~116 ~101 dirt
setblock ~163 ~116 ~102 dirt
setblock ~163 ~116 ~103 dirt
setblock ~163 ~116 ~104 dirt
setblock ~163 ~116 ~105 dirt
setblock ~163 ~116 ~106 dirt
setblock ~163 ~116 ~107 dirt
setblock ~163 ~116 ~108 dirt
setblock ~163 ~116 ~109 dirt
setblock ~163 ~116 ~110 dirt
setblock ~163 ~116 ~111 dirt
setblock ~163 ~117 ~68 dirt
setblock ~163 ~117 ~69 dirt
setblock ~163 ~117 ~70 dirt
setblock ~163 ~117 ~71 dirt
setblock ~163 ~117 ~72 dirt
setblock ~163 ~117 ~73 dirt
setblock ~163 ~117 ~74 dirt
setblock ~163 ~117 ~75 dirt
setblock ~163 ~117 ~76 dirt
setblock ~163 ~117 ~77 dirt
setblock ~163 ~117 ~78 dirt
setblock ~163 ~117 ~79 dirt
setblock ~163 ~117 ~80 dirt
setblock ~163 ~117 ~81 dirt
setblock ~163 ~117 ~82 dirt
setblock ~163 ~117 ~83 dirt
setblock ~163 ~117 ~84 dirt
setblock ~163 ~117 ~85 dirt
setblock ~163 ~117 ~86 dirt
setblock ~163 ~117 ~92 dirt
setblock ~163 ~117 ~93 dirt
setblock ~163 ~117 ~94 dirt
setblock ~163 ~117 ~95 dirt
setblock ~163 ~117 ~96 dirt
setblock ~163 ~117 ~97 dirt
setblock ~163 ~117 ~98 dirt
setblock ~163 ~117 ~99 dirt
setblock ~163 ~117 ~100 dirt
setblock ~163 ~117 ~101 dirt
setblock ~163 ~117 ~102 dirt
setblock ~163 ~117 ~103 dirt
setblock ~163 ~117 ~104 dirt
setblock ~163 ~117 ~105 dirt
setblock ~163 ~117 ~106 dirt
setblock ~163 ~117 ~107 dirt
setblock ~163 ~117 ~108 dirt
setblock ~163 ~117 ~109 dirt
setblock ~163 ~117 ~110 dirt
setblock ~163 ~117 ~111 dirt
setblock ~163 ~117 ~125 dirt
setblock ~163 ~118 ~67 dirt
setblock ~163 ~118 ~68 dirt
setblock ~163 ~118 ~69 dirt
setblock ~163 ~118 ~70 dirt
setblock ~163 ~118 ~71 dirt
setblock ~163 ~118 ~72 dirt
setblock ~163 ~118 ~73 dirt
setblock ~163 ~118 ~74 dirt
setblock ~163 ~118 ~75 dirt
setblock ~163 ~118 ~76 dirt
setblock ~163 ~118 ~77 dirt
setblock ~163 ~118 ~78 dirt
setblock ~163 ~118 ~79 dirt
setblock ~163 ~118 ~80 dirt
setblock ~163 ~118 ~81 dirt
setblock ~163 ~118 ~82 dirt
setblock ~163 ~118 ~83 dirt
setblock ~163 ~118 ~84 dirt
setblock ~163 ~118 ~85 dirt
setblock ~163 ~118 ~86 dirt
setblock ~163 ~118 ~87 dirt
setblock ~163 ~118 ~91 dirt
setblock ~163 ~118 ~92 dirt
setblock ~163 ~118 ~93 dirt
setblock ~163 ~118 ~94 dirt
setblock ~163 ~118 ~95 dirt
setblock ~163 ~118 ~96 dirt
setblock ~163 ~118 ~97 dirt
setblock ~163 ~118 ~98 dirt
setblock ~163 ~118 ~99 dirt
setblock ~163 ~118 ~100 dirt
setblock ~163 ~118 ~101 dirt
setblock ~163 ~118 ~102 dirt
setblock ~163 ~118 ~103 dirt
setblock ~163 ~118 ~104 dirt
setblock ~163 ~118 ~105 dirt
setblock ~163 ~118 ~106 dirt
setblock ~163 ~118 ~107 dirt
setblock ~163 ~118 ~108 dirt
setblock ~163 ~118 ~109 dirt
setblock ~163 ~118 ~110 dirt
setblock ~163 ~118 ~111 dirt
setblock ~163 ~118 ~112 dirt
setblock ~163 ~118 ~124 dirt
setblock ~163 ~118 ~125 dirt
setblock ~163 ~119 ~66 dirt
setblock ~163 ~119 ~67 dirt
setblock ~163 ~119 ~68 dirt
setblock ~163 ~119 ~69 dirt
setblock ~163 ~119 ~70 dirt
setblock ~163 ~119 ~71 dirt
setblock ~163 ~119 ~72 dirt
setblock ~163 ~119 ~73 dirt
setblock ~163 ~119 ~74 dirt
setblock ~163 ~119 ~75 dirt
setblock ~163 ~119 ~76 dirt
setblock ~163 ~119 ~77 dirt
setblock ~163 ~119 ~78 dirt
setblock ~163 ~119 ~79 dirt
setblock ~163 ~119 ~80 dirt
setblock ~163 ~119 ~81 dirt
setblock ~163 ~119 ~82 dirt
setblock ~163 ~119 ~83 dirt
setblock ~163 ~119 ~84 dirt
setblock ~163 ~119 ~85 dirt
setblock ~163 ~119 ~86 dirt
setblock ~163 ~119 ~87 dirt
setblock ~163 ~119 ~91 dirt
setblock ~163 ~119 ~92 dirt
setblock ~163 ~119 ~93 dirt
setblock ~163 ~119 ~94 dirt
setblock ~163 ~119 ~95 dirt
setblock ~163 ~119 ~96 dirt
setblock ~163 ~119 ~97 dirt
setblock ~163 ~119 ~98 dirt
setblock ~163 ~119 ~99 dirt
setblock ~163 ~119 ~100 dirt
setblock ~163 ~119 ~101 dirt
setblock ~163 ~119 ~102 dirt
setblock ~163 ~119 ~103 dirt
setblock ~163 ~119 ~104 dirt
setblock ~163 ~119 ~105 dirt
setblock ~163 ~119 ~106 dirt
setblock ~163 ~119 ~107 dirt
setblock ~163 ~119 ~108 dirt
setblock ~163 ~119 ~109 dirt
setblock ~163 ~119 ~110 dirt
setblock ~163 ~119 ~111 dirt
setblock ~163 ~119 ~112 dirt
setblock ~163 ~119 ~119 dirt
setblock ~163 ~119 ~122 dirt
setblock ~163 ~119 ~123 dirt
setblock ~163 ~119 ~124 dirt
setblock ~163 ~119 ~125 dirt
setblock ~163 ~119 ~126 dirt
setblock ~163 ~120 ~66 dirt
setblock ~163 ~120 ~67 dirt
setblock ~163 ~120 ~68 dirt
setblock ~163 ~120 ~69 dirt
setblock ~163 ~120 ~70 dirt
setblock ~163 ~120 ~71 dirt
setblock ~163 ~120 ~72 dirt
setblock ~163 ~120 ~73 dirt
setblock ~163 ~120 ~74 dirt
setblock ~163 ~120 ~75 dirt
setblock ~163 ~120 ~76 dirt
setblock ~163 ~120 ~77 dirt
setblock ~163 ~120 ~78 dirt
setblock ~163 ~120 ~79 dirt
setblock ~163 ~120 ~80 dirt
setblock ~163 ~120 ~81 dirt
setblock ~163 ~120 ~82 dirt
setblock ~163 ~120 ~83 dirt
setblock ~163 ~120 ~84 dirt
setblock ~163 ~120 ~85 dirt
setblock ~163 ~120 ~86 dirt
setblock ~163 ~120 ~87 dirt
setblock ~163 ~120 ~90 dirt
setblock ~163 ~120 ~91 dirt
setblock ~163 ~120 ~92 dirt
setblock ~163 ~120 ~93 dirt
setblock ~163 ~120 ~94 dirt
setblock ~163 ~120 ~95 dirt
setblock ~163 ~120 ~96 dirt
setblock ~163 ~120 ~97 dirt
setblock ~163 ~120 ~98 dirt
setblock ~163 ~120 ~99 dirt
setblock ~163 ~120 ~100 dirt
setblock ~163 ~120 ~101 dirt
setblock ~163 ~120 ~102 dirt
setblock ~163 ~120 ~103 dirt
setblock ~163 ~120 ~104 dirt
setblock ~163 ~120 ~105 dirt
setblock ~163 ~120 ~106 dirt
setblock ~163 ~120 ~107 dirt
setblock ~163 ~120 ~108 dirt
setblock ~163 ~120 ~109 dirt
setblock ~163 ~120 ~110 dirt
setblock ~163 ~120 ~111 dirt
setblock ~163 ~120 ~112 dirt
setblock ~163 ~120 ~119 dirt
setblock ~163 ~120 ~121 dirt
setblock ~163 ~120 ~122 dirt
setblock ~163 ~120 ~123 dirt
setblock ~163 ~120 ~124 dirt
setblock ~163 ~120 ~125 dirt
setblock ~163 ~120 ~126 dirt
setblock ~163 ~120 ~128 dirt
setblock ~163 ~120 ~129 dirt
setblock ~163 ~121 ~66 dirt
setblock ~163 ~121 ~67 dirt
setblock ~163 ~121 ~68 dirt
setblock ~163 ~121 ~69 dirt
setblock ~163 ~121 ~70 dirt
setblock ~163 ~121 ~71 dirt
setblock ~163 ~121 ~72 dirt
setblock ~163 ~121 ~73 dirt
setblock ~163 ~121 ~74 dirt
setblock ~163 ~121 ~75 dirt
setblock ~163 ~121 ~76 dirt
setblock ~163 ~121 ~77 dirt
setblock ~163 ~121 ~78 dirt
setblock ~163 ~121 ~79 dirt
setblock ~163 ~121 ~80 dirt
setblock ~163 ~121 ~81 dirt
setblock ~163 ~121 ~82 dirt
setblock ~163 ~121 ~83 dirt
setblock ~163 ~121 ~84 dirt
setblock ~163 ~121 ~85 dirt
setblock ~163 ~121 ~86 dirt
setblock ~163 ~121 ~87 dirt
setblock ~163 ~121 ~90 dirt
setblock ~163 ~121 ~91 dirt
setblock ~163 ~121 ~92 dirt
setblock ~163 ~121 ~93 dirt
setblock ~163 ~121 ~94 dirt
setblock ~163 ~121 ~95 dirt
setblock ~163 ~121 ~96 dirt
setblock ~163 ~121 ~97 dirt
setblock ~163 ~121 ~98 dirt
setblock ~163 ~121 ~99 dirt
setblock ~163 ~121 ~100 dirt
setblock ~163 ~121 ~101 dirt
setblock ~163 ~121 ~102 dirt
setblock ~163 ~121 ~103 dirt
setblock ~163 ~121 ~104 dirt
setblock ~163 ~121 ~105 dirt
setblock ~163 ~121 ~106 dirt
setblock ~163 ~121 ~107 dirt
setblock ~163 ~121 ~108 dirt
setblock ~163 ~121 ~109 dirt
setblock ~163 ~121 ~110 dirt
setblock ~163 ~121 ~111 dirt
setblock ~163 ~121 ~112 dirt
setblock ~163 ~121 ~113 dirt
setblock ~163 ~121 ~119 dirt
setblock ~163 ~121 ~120 dirt
setblock ~163 ~121 ~121 dirt
setblock ~163 ~121 ~122 dirt
setblock ~163 ~121 ~123 dirt
setblock ~163 ~121 ~124 dirt
setblock ~163 ~121 ~125 dirt
setblock ~163 ~121 ~126 dirt
setblock ~163 ~121 ~127 dirt
setblock ~163 ~121 ~128 dirt
setblock ~163 ~121 ~129 dirt
setblock ~163 ~121 ~130 dirt
setblock ~163 ~122 ~66 dirt
setblock ~163 ~122 ~67 dirt
setblock ~163 ~122 ~68 dirt
setblock ~163 ~122 ~69 dirt
setblock ~163 ~122 ~70 dirt
setblock ~163 ~122 ~71 dirt
setblock ~163 ~122 ~72 dirt
setblock ~163 ~122 ~73 dirt
setblock ~163 ~122 ~74 dirt
setblock ~163 ~122 ~75 dirt
setblock ~163 ~122 ~76 dirt
setblock ~163 ~122 ~77 dirt
setblock ~163 ~122 ~78 dirt
setblock ~163 ~122 ~79 dirt
setblock ~163 ~122 ~80 dirt
setblock ~163 ~122 ~81 dirt
setblock ~163 ~122 ~82 dirt
setblock ~163 ~122 ~83 dirt
setblock ~163 ~122 ~84 dirt
setblock ~163 ~122 ~85 dirt
setblock ~163 ~122 ~86 dirt
setblock ~163 ~122 ~87 dirt
setblock ~163 ~122 ~90 dirt
setblock ~163 ~122 ~91 dirt
setblock ~163 ~122 ~92 dirt
setblock ~163 ~122 ~93 dirt
setblock ~163 ~122 ~94 dirt
setblock ~163 ~122 ~95 dirt
setblock ~163 ~122 ~96 dirt
setblock ~163 ~122 ~97 dirt
setblock ~163 ~122 ~98 dirt
setblock ~163 ~122 ~99 dirt
setblock ~163 ~122 ~100 dirt
setblock ~163 ~122 ~101 dirt
setblock ~163 ~122 ~102 dirt
setblock ~163 ~122 ~103 dirt
setblock ~163 ~122 ~104 dirt
setblock ~163 ~122 ~105 dirt
setblock ~163 ~122 ~106 dirt
setblock ~163 ~122 ~107 dirt
setblock ~163 ~122 ~108 dirt
setblock ~163 ~122 ~109 dirt
setblock ~163 ~122 ~110 dirt
setblock ~163 ~122 ~111 dirt
setblock ~163 ~122 ~112 dirt
setblock ~163 ~122 ~113 dirt
setblock ~163 ~122 ~119 dirt
setblock ~163 ~122 ~120 dirt
setblock ~163 ~122 ~121 dirt
setblock ~163 ~122 ~122 dirt
setblock ~163 ~122 ~123 dirt
setblock ~163 ~122 ~124 dirt
setblock ~163 ~122 ~125 dirt
setblock ~163 ~122 ~126 dirt
setblock ~163 ~122 ~127 dirt
setblock ~163 ~122 ~128 dirt
setblock ~163 ~122 ~129 dirt
setblock ~163 ~122 ~130 dirt
setblock ~163 ~123 ~66 dirt
setblock ~163 ~123 ~67 dirt
setblock ~163 ~123 ~68 dirt
setblock ~163 ~123 ~69 dirt
setblock ~163 ~123 ~70 dirt
setblock ~163 ~123 ~71 dirt
setblock ~163 ~123 ~72 dirt
setblock ~163 ~123 ~73 dirt
setblock ~163 ~123 ~74 dirt
setblock ~163 ~123 ~75 dirt
setblock ~163 ~123 ~76 dirt
setblock ~163 ~123 ~77 dirt
setblock ~163 ~123 ~78 dirt
setblock ~163 ~123 ~79 dirt
setblock ~163 ~123 ~80 dirt
setblock ~163 ~123 ~81 dirt
setblock ~163 ~123 ~82 dirt
setblock ~163 ~123 ~83 dirt
setblock ~163 ~123 ~84 dirt
setblock ~163 ~123 ~85 dirt
setblock ~163 ~123 ~86 dirt
setblock ~163 ~123 ~87 dirt
setblock ~163 ~123 ~90 dirt
setblock ~163 ~123 ~91 dirt
setblock ~163 ~123 ~92 dirt
setblock ~163 ~123 ~93 dirt
setblock ~163 ~123 ~94 dirt
setblock ~163 ~123 ~95 dirt
setblock ~163 ~123 ~96 dirt
setblock ~163 ~123 ~97 dirt
setblock ~163 ~123 ~98 dirt
setblock ~163 ~123 ~99 dirt
setblock ~163 ~123 ~100 dirt
setblock ~163 ~123 ~101 dirt
setblock ~163 ~123 ~102 dirt
setblock ~163 ~123 ~103 dirt
setblock ~163 ~123 ~104 dirt
setblock ~163 ~123 ~105 dirt
setblock ~163 ~123 ~106 dirt
setblock ~163 ~123 ~107 dirt
setblock ~163 ~123 ~108 dirt
setblock ~163 ~123 ~109 dirt
setblock ~163 ~123 ~110 dirt
setblock ~163 ~123 ~111 dirt
setblock ~163 ~123 ~112 dirt
setblock ~163 ~123 ~113 dirt
setblock ~163 ~123 ~119 dirt
setblock ~163 ~123 ~120 dirt
setblock ~163 ~123 ~121 dirt
setblock ~163 ~123 ~122 dirt
setblock ~163 ~123 ~123 dirt
setblock ~163 ~123 ~124 dirt
setblock ~163 ~123 ~125 dirt
setblock ~163 ~123 ~126 dirt
setblock ~163 ~123 ~127 dirt
setblock ~163 ~123 ~128 dirt
setblock ~163 ~123 ~129 dirt
setblock ~163 ~123 ~130 dirt
setblock ~163 ~124 ~66 dirt
setblock ~163 ~124 ~67 dirt
setblock ~163 ~124 ~68 dirt
setblock ~163 ~124 ~69 dirt
setblock ~163 ~124 ~70 dirt
setblock ~163 ~124 ~71 dirt
setblock ~163 ~124 ~72 dirt
setblock ~163 ~124 ~73 dirt
setblock ~163 ~124 ~74 dirt
setblock ~163 ~124 ~75 grass_block
setblock ~163 ~124 ~76 grass_block
setblock ~163 ~124 ~77 grass_block
setblock ~163 ~124 ~78 grass_block
setblock ~163 ~124 ~79 grass_block
setblock ~163 ~124 ~80 grass_block
setblock ~163 ~124 ~81 grass_block
setblock ~163 ~124 ~82 grass_block
setblock ~163 ~124 ~83 grass_block
setblock ~163 ~124 ~84 dirt
setblock ~163 ~124 ~85 dirt
setblock ~163 ~124 ~86 dirt
setblock ~163 ~124 ~87 dirt
setblock ~163 ~124 ~90 dirt
setblock ~163 ~124 ~91 dirt
setblock ~163 ~124 ~92 dirt
setblock ~163 ~124 ~93 dirt
setblock ~163 ~124 ~94 dirt
setblock ~163 ~124 ~95 dirt
setblock ~163 ~124 ~96 dirt
setblock ~163 ~124 ~97 dirt
setblock ~163 ~124 ~98 dirt
setblock ~163 ~124 ~99 dirt
setblock ~163 ~124 ~100 dirt
setblock ~163 ~124 ~101 dirt
setblock ~163 ~124 ~102 dirt
setblock ~163 ~124 ~103 dirt
setblock ~163 ~124 ~104 dirt
setblock ~163 ~124 ~105 dirt
setblock ~163 ~124 ~106 dirt
setblock ~163 ~124 ~107 dirt
setblock ~163 ~124 ~108 dirt
setblock ~163 ~124 ~109 grass_block
setblock ~163 ~124 ~110 grass_block
setblock ~163 ~124 ~111 grass_block
setblock ~163 ~124 ~112 grass_block
setblock ~163 ~124 ~113 grass_block
setblock ~163 ~124 ~119 grass_block
setblock ~163 ~124 ~120 grass_block
setblock ~163 ~124 ~121 grass_block
setblock ~163 ~124 ~122 grass_block
setblock ~163 ~124 ~123 grass_block
setblock ~163 ~124 ~124 grass_block
setblock ~163 ~124 ~125 grass_block
setblock ~163 ~124 ~126 grass_block
setblock ~163 ~124 ~127 grass_block
setblock ~163 ~124 ~128 grass_block
setblock ~163 ~124 ~129 grass_block
setblock ~163 ~124 ~130 grass_block
setblock ~163 ~125 ~66 grass_block
setblock ~163 ~125 ~67 grass_block
setblock ~163 ~125 ~68 grass_block
setblock ~163 ~125 ~69 grass_block
setblock ~163 ~125 ~70 grass_block
setblock ~163 ~125 ~71 grass_block
setblock ~163 ~125 ~72 grass_block
setblock ~163 ~125 ~73 grass_block
setblock ~163 ~125 ~74 grass_block
setblock ~163 ~125 ~79 short_grass
setblock ~163 ~125 ~80 short_grass
setblock ~163 ~125 ~81 short_grass
setblock ~163 ~125 ~84 grass_block
setblock ~163 ~125 ~85 grass_block
setblock ~163 ~125 ~86 grass_block
setblock ~163 ~125 ~87 grass_block
setblock ~163 ~125 ~90 grass_block
setblock ~163 ~125 ~91 grass_block
setblock ~163 ~125 ~92 grass_block
setblock ~163 ~125 ~93 grass_block
setblock ~163 ~125 ~94 grass_block
setblock ~163 ~125 ~95 grass_block
setblock ~163 ~125 ~96 grass_block
setblock ~163 ~125 ~97 grass_block
setblock ~163 ~125 ~98 grass_block
setblock ~163 ~125 ~99 grass_block
setblock ~163 ~125 ~100 grass_block
setblock ~163 ~125 ~101 grass_block
setblock ~163 ~125 ~102 grass_block
setblock ~163 ~125 ~103 grass_block
setblock ~163 ~125 ~104 grass_block
setblock ~163 ~125 ~105 grass_block
setblock ~163 ~125 ~106 grass_block
setblock ~163 ~125 ~107 grass_block
setblock ~163 ~125 ~108 grass_block
setblock ~163 ~125 ~111 fern
setblock ~163 ~125 ~121 short_grass
setblock ~163 ~125 ~124 poppy
setblock ~163 ~125 ~125 short_grass
setblock ~163 ~125 ~126 short_grass
setblock ~163 ~125 ~130 short_grass
setblock ~163 ~126 ~67 fern
setblock ~163 ~126 ~70 short_grass
setblock ~163 ~126 ~72 short_grass
setblock ~163 ~126 ~90 fern
setblock ~163 ~126 ~93 fern
setblock ~163 ~126 ~94 fern
setblock ~163 ~126 ~95 short_grass
setblock ~163 ~126 ~96 poppy
setblock ~163 ~126 ~97 poppy
setblock ~163 ~133 ~74 oak_leaves[persistent=true]
setblock ~163 ~133 ~75 oak_leaves[persistent=true]
setblock ~163 ~133 ~76 oak_leaves[persistent=true]
setblock ~163 ~134 ~75 oak_wood
setblock ~163 ~134 ~76 jungle_leaves[persistent=true]
setblock ~163 ~135 ~75 oak_leaves[persistent=true]
setblock ~163 ~135 ~76 oak_leaves[persistent=true]
setblock ~163 ~135 ~79 jungle_leaves[persistent=true]
setblock ~163 ~135 ~80 oak_leaves[persistent=true]
setblock ~163 ~135 ~81 oak_leaves[persistent=true]
setblock ~163 ~135 ~82 oak_leaves[persistent=true]
setblock ~163 ~136 ~74 jungle_leaves[persistent=true]
setblock ~163 ~136 ~75 oak_leaves[persistent=true]
setblock ~163 ~136 ~77 oak_leaves[persistent=true]
setblock ~163 ~136 ~79 oak_leaves[persistent=true]
setblock ~163 ~136 ~81 jungle_leaves[persistent=true]
setblock ~163 ~136 ~82 oak_leaves[persistent=true]
setblock ~163 ~137 ~74 oak_leaves[persistent=true]
setblock ~163 ~137 ~75 oak_leaves[persistent=true]
setblock ~163 ~137 ~76 oak_leaves[persistent=true]
setblock ~163 ~137 ~77 oak_leaves[persistent=true]
setblock ~163 ~137 ~79 jungle_leaves[persistent=true]
setblock ~163 ~137 ~80 oak_leaves[persistent=true]
setblock ~163 ~137 ~81 oak_leaves[persistent=true]
setblock ~163 ~137 ~82 oak_leaves[persistent=true]
setblock ~163 ~138 ~74 oak_leaves[persistent=true]
setblock ~163 ~138 ~75 oak_leaves[persistent=true]
setblock ~163 ~138 ~76 oak_leaves[persistent=true]
setblock ~163 ~138 ~77 oak_leaves[persistent=true]
setblock ~163 ~138 ~79 oak_leaves[persistent=true]
setblock ~163 ~138 ~80 oak_leaves[persistent=true]
setblock ~163 ~138 ~81 oak_leaves[persistent=true]
setblock ~163 ~139 ~74 oak_leaves[persistent=true]
setblock ~163 ~139 ~75 oak_leaves[persistent=true]
setblock ~163 ~139 ~76 oak_leaves[persistent=true]
setblock ~163 ~139 ~77 oak_leaves[persistent=true]
setblock ~164 ~106 ~77 dirt
setblock ~164 ~107 ~76 dirt
setblock ~164 ~107 ~77 dirt
setblock ~164 ~108 ~76 dirt
setblock ~164 ~108 ~77 dirt
setblock ~164 ~108 ~78 dirt
setblock ~164 ~108 ~80 dirt
setblock ~164 ~109 ~74 dirt
setblock ~164 ~109 ~75 dirt
setblock ~164 ~109 ~76 dirt
setblock ~164 ~109 ~77 dirt
setblock ~164 ~109 ~78 dirt
setblock ~164 ~109 ~79 dirt
setblock ~164 ~109 ~80 dirt
setblock ~164 ~109 ~81 dirt
setblock ~164 ~110 ~73 dirt
setblock ~164 ~110 ~74 dirt
setblock ~164 ~110 ~75 dirt
setblock ~164 ~110 ~76 dirt
setblock ~164 ~110 ~77 dirt
setblock ~164 ~110 ~78 dirt
setblock ~164 ~110 ~79 dirt
setblock ~164 ~110 ~80 dirt
setblock ~164 ~110 ~81 dirt
setblock ~164 ~111 ~72 dirt
setblock ~164 ~111 ~73 dirt
setblock ~164 ~111 ~74 dirt
setblock ~164 ~111 ~75 dirt
setblock ~164 ~111 ~76 dirt
setblock ~164 ~111 ~77 dirt
setblock ~164 ~111 ~78 dirt
setblock ~164 ~111 ~79 dirt
setblock ~164 ~111 ~80 dirt
setblock ~164 ~111 ~81 dirt
setblock ~164 ~111 ~82 dirt
setblock ~164 ~112 ~72 dirt
setblock ~164 ~112 ~73 dirt
setblock ~164 ~112 ~74 dirt
setblock ~164 ~112 ~75 dirt
setblock ~164 ~112 ~76 dirt
setblock ~164 ~112 ~77 dirt
setblock ~164 ~112 ~78 dirt
setblock ~164 ~112 ~79 dirt
setblock ~164 ~112 ~80 dirt
setblock ~164 ~112 ~81 dirt
setblock ~164 ~112 ~82 dirt
setblock ~164 ~112 ~106 dirt
setblock ~164 ~112 ~107 dirt
setblock ~164 ~113 ~71 dirt
setblock ~164 ~113 ~72 dirt
setblock ~164 ~113 ~73 dirt
setblock ~164 ~113 ~74 dirt
setblock ~164 ~113 ~75 dirt
setblock ~164 ~113 ~76 dirt
setblock ~164 ~113 ~77 dirt
setblock ~164 ~113 ~78 dirt
setblock ~164 ~113 ~79 dirt
setblock ~164 ~113 ~80 dirt
setblock ~164 ~113 ~81 dirt
setblock ~164 ~113 ~82 dirt
setblock ~164 ~113 ~83 dirt
setblock ~164 ~113 ~105 dirt
setblock ~164 ~113 ~106 dirt
setblock ~164 ~113 ~107 dirt
setblock ~164 ~114 ~71 dirt
setblock ~164 ~114 ~72 dirt
setblock ~164 ~114 ~73 dirt
setblock ~164 ~114 ~74 dirt
setblock ~164 ~114 ~75 dirt
setblock ~164 ~114 ~76 dirt
setblock ~164 ~114 ~77 dirt
setblock ~164 ~114 ~78 dirt
setblock ~164 ~114 ~79 dirt
setblock ~164 ~114 ~80 dirt
setblock ~164 ~114 ~81 dirt
setblock ~164 ~114 ~82 dirt
setblock ~164 ~114 ~83 dirt
setblock ~164 ~114 ~103 dirt
setblock ~164 ~114 ~104 dirt
setblock ~164 ~114 ~105 dirt
setblock ~164 ~114 ~106 dirt
setblock ~164 ~114 ~107 dirt
setblock ~164 ~114 ~108 dirt
setblock ~164 ~115 ~71 dirt
setblock ~164 ~115 ~72 dirt
setblock ~164 ~115 ~73 dirt
setblock ~164 ~115 ~74 dirt
setblock ~164 ~115 ~75 dirt
setblock ~164 ~115 ~76 dirt
setblock ~164 ~115 ~77 dirt
setblock ~164 ~115 ~78 dirt
setblock ~164 ~115 ~79 dirt
setblock ~164 ~115 ~80 dirt
setblock ~164 ~115 ~81 dirt
setblock ~164 ~115 ~82 dirt
setblock ~164 ~115 ~83 dirt
setblock ~164 ~115 ~84 dirt
setblock ~164 ~115 ~102 dirt
setblock ~164 ~115 ~103 dirt
setblock ~164 ~115 ~104 dirt
setblock ~164 ~115 ~105 dirt
setblock ~164 ~115 ~106 dirt
setblock ~164 ~115 ~107 dirt
setblock ~164 ~115 ~108 dirt
setblock ~164 ~115 ~109 dirt
setblock ~164 ~116 ~70 dirt
setblock ~164 ~116 ~71 dirt
setblock ~164 ~116 ~72 dirt
setblock ~164 ~116 ~73 dirt
setblock ~164 ~116 ~74 dirt
setblock ~164 ~116 ~75 dirt
setblock ~164 ~116 ~76 dirt
setblock ~164 ~116 ~77 dirt
setblock ~164 ~116 ~78 dirt
setblock ~164 ~116 ~79 dirt
setblock ~164 ~116 ~80 dirt
setblock ~164 ~116 ~81 dirt
setblock ~164 ~116 ~82 dirt
setblock ~164 ~116 ~83 dirt
setblock ~164 ~116 ~84 dirt
setblock ~164 ~116 ~85 dirt
setblock ~164 ~116 ~94 dirt
setblock ~164 ~116 ~102 dirt
setblock ~164 ~116 ~103 dirt
setblock ~164 ~116 ~104 dirt
setblock ~164 ~116 ~105 dirt
setblock ~164 ~116 ~106 dirt
setblock ~164 ~116 ~107 dirt
setblock ~164 ~116 ~108 dirt
setblock ~164 ~116 ~109 dirt
setblock ~164 ~116 ~110 dirt
setblock ~164 ~117 ~69 dirt
setblock ~164 ~117 ~70 dirt
setblock ~164 ~117 ~71 dirt
setblock ~164 ~117 ~72 dirt
setblock ~164 ~117 ~73 dirt
setblock ~164 ~117 ~74 dirt
setblock ~164 ~117 ~75 dirt
setblock ~164 ~117 ~76 dirt
setblock ~164 ~117 ~77 dirt
setblock ~164 ~117 ~78 dirt
setblock ~164 ~117 ~79 dirt
setblock ~164 ~117 ~80 dirt
setblock ~164 ~117 ~81 dirt
setblock ~164 ~117 ~82 dirt
setblock ~164 ~117 ~83 dirt
setblock ~164 ~117 ~84 dirt
setblock ~164 ~117 ~85 dirt
setblock ~164 ~117 ~86 dirt
setblock ~164 ~117 ~93 dirt
setblock ~164 ~117 ~94 dirt
setblock ~164 ~117 ~95 dirt
setblock ~164 ~117 ~98 dirt
setblock ~164 ~117 ~101 dirt
setblock ~164 ~117 ~102 dirt
setblock ~164 ~117 ~103 dirt
setblock ~164 ~117 ~104 dirt
setblock ~164 ~117 ~105 dirt
setblock ~164 ~117 ~106 dirt
setblock ~164 ~117 ~107 dirt
setblock ~164 ~117 ~108 dirt
setblock ~164 ~117 ~109 dirt
setblock ~164 ~117 ~110 dirt
setblock ~164 ~118 ~68 dirt
setblock ~164 ~118 ~69 dirt
setblock ~164 ~118 ~70 dirt
setblock ~164 ~118 ~71 dirt
setblock ~164 ~118 ~72 dirt
setblock ~164 ~118 ~73 dirt
setblock ~164 ~118 ~74 dirt
setblock ~164 ~118 ~75 dirt
setblock ~164 ~118 ~76 dirt
setblock ~164 ~118 ~77 dirt
setblock ~164 ~118 ~78 dirt
setblock ~164 ~118 ~79 dirt
setblock ~164 ~118 ~80 dirt
setblock ~164 ~118 ~81 dirt
setblock ~164 ~118 ~82 dirt
setblock ~164 ~118 ~83 dirt
setblock ~164 ~118 ~84 dirt
setblock ~164 ~118 ~85 dirt
setblock ~164 ~118 ~86 dirt
setblock ~164 ~118 ~92 dirt
setblock ~164 ~118 ~93 dirt
setblock ~164 ~118 ~94 dirt
setblock ~164 ~118 ~95 dirt
setblock ~164 ~118 ~96 dirt
setblock ~164 ~118 ~98 dirt
setblock ~164 ~118 ~100 dirt
setblock ~164 ~118 ~101 dirt
setblock ~164 ~118 ~102 dirt
setblock ~164 ~118 ~103 dirt
setblock ~164 ~118 ~104 dirt
setblock ~164 ~118 ~105 dirt
setblock ~164 ~118 ~106 dirt
setblock ~164 ~118 ~107 dirt
setblock ~164 ~118 ~108 dirt
setblock ~164 ~118 ~109 dirt
setblock ~164 ~118 ~110 dirt
setblock ~164 ~118 ~111 dirt
setblock ~164 ~119 ~67 dirt
setblock ~164 ~119 ~68 dirt
setblock ~164 ~119 ~69 dirt
setblock ~164 ~119 ~70 dirt
setblock ~164 ~119 ~71 dirt
setblock ~164 ~119 ~72 dirt
setblock ~164 ~119 ~73 dirt
setblock ~164 ~119 ~74 dirt
setblock ~164 ~119 ~75 dirt
setblock ~164 ~119 ~76 dirt
setblock ~164 ~119 ~77 dirt
setblock ~164 ~119 ~78 dirt
setblock ~164 ~119 ~79 dirt
setblock ~164 ~119 ~80 dirt
setblock ~164 ~119 ~81 dirt
setblock ~164 ~119 ~82 dirt
setblock ~164 ~119 ~83 dirt
setblock ~164 ~119 ~84 dirt
setblock ~164 ~119 ~85 dirt
setblock ~164 ~119 ~86 dirt
setblock ~164 ~119 ~91 dirt
setblock ~164 ~119 ~92 dirt
setblock ~164 ~119 ~93 dirt
setblock ~164 ~119 ~94 dirt
setblock ~164 ~119 ~95 dirt
setblock ~164 ~119 ~96 dirt
setblock ~164 ~119 ~97 dirt
setblock ~164 ~119 ~98 dirt
setblock ~164 ~119 ~99 dirt
setblock ~164 ~119 ~100 dirt
setblock ~164 ~119 ~101 dirt
setblock ~164 ~119 ~102 dirt
setblock ~164 ~119 ~103 dirt
setblock ~164 ~119 ~104 dirt
setblock ~164 ~119 ~105 dirt
setblock ~164 ~119 ~106 dirt
setblock ~164 ~119 ~107 dirt
setblock ~164 ~119 ~108 dirt
setblock ~164 ~119 ~109 dirt
setblock ~164 ~119 ~110 dirt
setblock ~164 ~119 ~111 dirt
setblock ~164 ~119 ~124 dirt
setblock ~164 ~120 ~67 dirt
setblock ~164 ~120 ~68 dirt
setblock ~164 ~120 ~69 dirt
setblock ~164 ~120 ~70 dirt
setblock ~164 ~120 ~71 dirt
setblock ~164 ~120 ~72 dirt
setblock ~164 ~120 ~73 dirt
setblock ~164 ~120 ~74 dirt
setblock ~164 ~120 ~75 dirt
setblock ~164 ~120 ~76 dirt
setblock ~164 ~120 ~77 dirt
setblock ~164 ~120 ~78 dirt
setblock ~164 ~120 ~79 dirt
setblock ~164 ~120 ~80 dirt
setblock ~164 ~120 ~81 dirt
setblock ~164 ~120 ~82 dirt
setblock ~164 ~120 ~83 dirt
setblock ~164 ~120 ~84 dirt
setblock ~164 ~120 ~85 dirt
setblock ~164 ~120 ~86 dirt
setblock ~164 ~120 ~91 dirt
setblock ~164 ~120 ~92 dirt
setblock ~164 ~120 ~93 dirt
setblock ~164 ~120 ~94 dirt
setblock ~164 ~120 ~95 dirt
setblock ~164 ~120 ~96 dirt
setblock ~164 ~120 ~97 dirt
setblock ~164 ~120 ~98 dirt
setblock ~164 ~120 ~99 dirt
setblock ~164 ~120 ~100 dirt
setblock ~164 ~120 ~101 dirt
setblock ~164 ~120 ~102 dirt
setblock ~164 ~120 ~103 dirt
setblock ~164 ~120 ~104 dirt
setblock ~164 ~120 ~105 dirt
setblock ~164 ~120 ~106 dirt
setblock ~164 ~120 ~107 dirt
setblock ~164 ~120 ~108 dirt
setblock ~164 ~120 ~109 dirt
setblock ~164 ~120 ~110 dirt
setblock ~164 ~120 ~111 dirt
setblock ~164 ~120 ~122 dirt
setblock ~164 ~120 ~123 dirt
setblock ~164 ~120 ~124 dirt
setblock ~164 ~120 ~125 dirt
setblock ~164 ~121 ~67 dirt
setblock ~164 ~121 ~68 dirt
setblock ~164 ~121 ~69 dirt
setblock ~164 ~121 ~70 dirt
setblock ~164 ~121 ~71 dirt
setblock ~164 ~121 ~72 dirt
setblock ~164 ~121 ~73 dirt
setblock ~164 ~121 ~74 dirt
setblock ~164 ~121 ~75 dirt
setblock ~164 ~121 ~76 dirt
setblock ~164 ~121 ~77 dirt
setblock ~164 ~121 ~78 dirt
setblock ~164 ~121 ~79 dirt
setblock ~164 ~121 ~80 dirt
setblock ~164 ~121 ~81 dirt
setblock ~164 ~121 ~82 dirt
setblock ~164 ~121 ~83 dirt
setblock ~164 ~121 ~84 dirt
setblock ~164 ~121 ~85 dirt
setblock ~164 ~121 ~86 dirt
setblock ~164 ~121 ~87 dirt
setblock ~164 ~121 ~90 dirt
setblock ~164 ~121 ~91 dirt
