setblock ~165 ~116 ~98 dirt
setblock ~165 ~116 ~99 dirt
setblock ~165 ~116 ~100 dirt
setblock ~165 ~116 ~101 dirt
setblock ~165 ~116 ~102 dirt
setblock ~165 ~116 ~104 dirt
setblock ~165 ~116 ~105 dirt
setblock ~165 ~116 ~106 dirt
setblock ~165 ~116 ~107 dirt
setblock ~165 ~116 ~108 dirt
setblock ~165 ~116 ~109 dirt
setblock ~165 ~116 ~110 dirt
setblock ~165 ~116 ~111 dirt
setblock ~165 ~116 ~112 dirt
setblock ~165 ~116 ~113 dirt
setblock ~165 ~116 ~114 dirt
setblock ~165 ~116 ~115 dirt
setblock ~165 ~117 ~88 dirt
setblock ~165 ~117 ~89 dirt
setblock ~165 ~117 ~90 dirt
setblock ~165 ~117 ~91 dirt
setblock ~165 ~117 ~92 dirt
setblock ~165 ~117 ~93 dirt
setblock ~165 ~117 ~94 dirt
setblock ~165 ~117 ~95 dirt
setblock ~165 ~117 ~96 dirt
setblock ~165 ~117 ~97 dirt
setblock ~165 ~117 ~98 dirt
setblock ~165 ~117 ~99 dirt
setblock ~165 ~117 ~100 dirt
setblock ~165 ~117 ~101 dirt
setblock ~165 ~117 ~102 dirt
setblock ~165 ~117 ~103 dirt
setblock ~165 ~117 ~104 dirt
setblock ~165 ~117 ~105 dirt
setblock ~165 ~117 ~106 dirt
setblock ~165 ~117 ~107 dirt
setblock ~165 ~117 ~108 dirt
setblock ~165 ~117 ~109 dirt
setblock ~165 ~117 ~110 dirt
setblock ~165 ~117 ~111 dirt
setblock ~165 ~117 ~112 dirt
setblock ~165 ~117 ~113 dirt
setblock ~165 ~117 ~114 dirt
setblock ~165 ~117 ~115 dirt
setblock ~165 ~117 ~116 dirt
setblock ~165 ~118 ~87 dirt
setblock ~165 ~118 ~88 dirt
setblock ~165 ~118 ~89 dirt
setblock ~165 ~118 ~90 dirt
setblock ~165 ~118 ~91 dirt
setblock ~165 ~118 ~92 dirt
setblock ~165 ~118 ~93 dirt
setblock ~165 ~118 ~94 dirt
setblock ~165 ~118 ~95 dirt
setblock ~165 ~118 ~96 dirt
setblock ~165 ~118 ~97 dirt
setblock ~165 ~118 ~98 dirt
setblock ~165 ~118 ~99 dirt
setblock ~165 ~118 ~100 dirt
setblock ~165 ~118 ~101 dirt
setblock ~165 ~118 ~102 dirt
setblock ~165 ~118 ~103 dirt
setblock ~165 ~118 ~104 dirt
setblock ~165 ~118 ~105 dirt
setblock ~165 ~118 ~106 dirt
setblock ~165 ~118 ~107 dirt
setblock ~165 ~118 ~108 dirt
setblock ~165 ~118 ~109 dirt
setblock ~165 ~118 ~110 dirt
setblock ~165 ~118 ~111 dirt
setblock ~165 ~118 ~112 dirt
setblock ~165 ~118 ~113 dirt
setblock ~165 ~118 ~114 dirt
setblock ~165 ~118 ~115 dirt
setblock ~165 ~118 ~116 dirt
setblock ~165 ~118 ~117 dirt
setblock ~165 ~119 ~87 dirt
setblock ~165 ~119 ~88 dirt
setblock ~165 ~119 ~89 dirt
setblock ~165 ~119 ~90 dirt
setblock ~165 ~119 ~91 dirt
setblock ~165 ~119 ~92 dirt
setblock ~165 ~119 ~93 dirt
setblock ~165 ~119 ~94 dirt
setblock ~165 ~119 ~95 dirt
setblock ~165 ~119 ~96 dirt
setblock ~165 ~119 ~97 dirt
setblock ~165 ~119 ~98 dirt
setblock ~165 ~119 ~99 dirt
setblock ~165 ~119 ~100 dirt
setblock ~165 ~119 ~101 dirt
setblock ~165 ~119 ~102 dirt
setblock ~165 ~119 ~103 dirt
setblock ~165 ~119 ~104 dirt
setblock ~165 ~119 ~105 dirt
setblock ~165 ~119 ~106 dirt
setblock ~165 ~119 ~107 dirt
setblock ~165 ~119 ~108 dirt
setblock ~165 ~119 ~109 dirt
setblock ~165 ~119 ~110 dirt
setblock ~165 ~119 ~111 dirt
setblock ~165 ~119 ~112 dirt
setblock ~165 ~119 ~113 dirt
setblock ~165 ~119 ~114 dirt
setblock ~165 ~119 ~115 dirt
setblock ~165 ~119 ~116 dirt
setblock ~165 ~119 ~117 dirt
setblock ~165 ~119 ~118 dirt
setblock ~165 ~120 ~87 dirt
setblock ~165 ~120 ~88 dirt
setblock ~165 ~120 ~89 dirt
setblock ~165 ~120 ~90 dirt
setblock ~165 ~120 ~91 dirt
setblock ~165 ~120 ~92 dirt
setblock ~165 ~120 ~93 dirt
setblock ~165 ~120 ~94 dirt
setblock ~165 ~120 ~95 dirt
setblock ~165 ~120 ~96 dirt
setblock ~165 ~120 ~97 dirt
setblock ~165 ~120 ~98 dirt
setblock ~165 ~120 ~99 dirt
setblock ~165 ~120 ~100 dirt
setblock ~165 ~120 ~101 dirt
setblock ~165 ~120 ~102 dirt
setblock ~165 ~120 ~103 dirt
setblock ~165 ~120 ~104 dirt
setblock ~165 ~120 ~105 dirt
setblock ~165 ~120 ~106 dirt
setblock ~165 ~120 ~107 dirt
setblock ~165 ~120 ~108 dirt
setblock ~165 ~120 ~109 dirt
setblock ~165 ~120 ~110 dirt
setblock ~165 ~120 ~111 dirt
setblock ~165 ~120 ~112 dirt
setblock ~165 ~120 ~113 dirt
setblock ~165 ~120 ~114 dirt
setblock ~165 ~120 ~115 dirt
setblock ~165 ~120 ~116 dirt
setblock ~165 ~120 ~117 dirt
setblock ~165 ~120 ~118 dirt
setblock ~165 ~120 ~119 dirt
setblock ~165 ~121 ~87 dirt
setblock ~165 ~121 ~88 dirt
setblock ~165 ~121 ~89 dirt
setblock ~165 ~121 ~90 dirt
setblock ~165 ~121 ~91 dirt
setblock ~165 ~121 ~92 dirt
setblock ~165 ~121 ~93 dirt
setblock ~165 ~121 ~94 dirt
setblock ~165 ~121 ~95 dirt
setblock ~165 ~121 ~96 dirt
setblock ~165 ~121 ~97 dirt
setblock ~165 ~121 ~98 dirt
setblock ~165 ~121 ~99 dirt
setblock ~165 ~121 ~100 dirt
setblock ~165 ~121 ~101 dirt
setblock ~165 ~121 ~102 dirt
setblock ~165 ~121 ~103 dirt
setblock ~165 ~121 ~104 dirt
setblock ~165 ~121 ~105 dirt
setblock ~165 ~121 ~106 dirt
setblock ~165 ~121 ~107 dirt
setblock ~165 ~121 ~108 dirt
setblock ~165 ~121 ~109 dirt
setblock ~165 ~121 ~110 dirt
setblock ~165 ~121 ~111 dirt
setblock ~165 ~121 ~112 dirt
setblock ~165 ~121 ~113 dirt
setblock ~165 ~121 ~114 dirt
setblock ~165 ~121 ~115 dirt
setblock ~165 ~121 ~116 dirt
setblock ~165 ~121 ~117 dirt
setblock ~165 ~121 ~118 dirt
setblock ~165 ~121 ~119 dirt
setblock ~165 ~121 ~120 dirt
setblock ~165 ~122 ~87 dirt
setblock ~165 ~122 ~88 dirt
setblock ~165 ~122 ~89 dirt
setblock ~165 ~122 ~90 dirt
setblock ~165 ~122 ~91 dirt
setblock ~165 ~122 ~92 dirt
setblock ~165 ~122 ~93 dirt
setblock ~165 ~122 ~94 dirt
setblock ~165 ~122 ~95 dirt
setblock ~165 ~122 ~96 dirt
setblock ~165 ~122 ~97 dirt
setblock ~165 ~122 ~98 dirt
setblock ~165 ~122 ~99 dirt
setblock ~165 ~122 ~100 dirt
setblock ~165 ~122 ~101 dirt
setblock ~165 ~122 ~102 dirt
setblock ~165 ~122 ~103 dirt
setblock ~165 ~122 ~104 dirt
setblock ~165 ~122 ~105 dirt
setblock ~165 ~122 ~106 dirt
setblock ~165 ~122 ~107 dirt
setblock ~165 ~122 ~108 dirt
setblock ~165 ~122 ~109 dirt
setblock ~165 ~122 ~110 dirt
setblock ~165 ~122 ~111 dirt
setblock ~165 ~122 ~112 dirt
setblock ~165 ~122 ~113 dirt
setblock ~165 ~122 ~114 dirt
setblock ~165 ~122 ~115 dirt
setblock ~165 ~122 ~116 dirt
setblock ~165 ~122 ~117 dirt
setblock ~165 ~122 ~118 dirt
setblock ~165 ~122 ~119 dirt
setblock ~165 ~122 ~120 dirt
setblock ~165 ~123 ~87 dirt
setblock ~165 ~123 ~88 dirt
setblock ~165 ~123 ~89 dirt
setblock ~165 ~123 ~90 dirt
setblock ~165 ~123 ~91 dirt
setblock ~165 ~123 ~92 dirt
setblock ~165 ~123 ~93 dirt
setblock ~165 ~123 ~94 dirt
setblock ~165 ~123 ~95 dirt
setblock ~165 ~123 ~96 dirt
setblock ~165 ~123 ~97 dirt
setblock ~165 ~123 ~98 dirt
setblock ~165 ~123 ~99 dirt
setblock ~165 ~123 ~100 dirt
setblock ~165 ~123 ~101 dirt
setblock ~165 ~123 ~102 dirt
setblock ~165 ~123 ~103 dirt
setblock ~165 ~123 ~104 dirt
setblock ~165 ~123 ~105 dirt
setblock ~165 ~123 ~106 dirt
setblock ~165 ~123 ~107 dirt
setblock ~165 ~123 ~108 dirt
setblock ~165 ~123 ~109 dirt
setblock ~165 ~123 ~110 dirt
setblock ~165 ~123 ~111 dirt
setblock ~165 ~123 ~112 dirt
setblock ~165 ~123 ~113 dirt
setblock ~165 ~123 ~114 dirt
setblock ~165 ~123 ~115 dirt
setblock ~165 ~123 ~116 dirt
setblock ~165 ~123 ~117 dirt
setblock ~165 ~123 ~118 dirt
setblock ~165 ~123 ~119 dirt
setblock ~165 ~123 ~120 dirt
setblock ~165 ~124 ~87 grass_block
setblock ~165 ~124 ~88 grass_block
setblock ~165 ~124 ~89 grass_block
setblock ~165 ~124 ~90 grass_block
setblock ~165 ~124 ~91 grass_block
setblock ~165 ~124 ~92 grass_block
setblock ~165 ~124 ~93 grass_block
setblock ~165 ~124 ~94 grass_block
setblock ~165 ~124 ~95 grass_block
setblock ~165 ~124 ~96 dirt
setblock ~165 ~124 ~97 dirt
setblock ~165 ~124 ~98 dirt
setblock ~165 ~124 ~99 dirt
setblock ~165 ~124 ~100 dirt
setblock ~165 ~124 ~101 dirt
setblock ~165 ~124 ~102 dirt
setblock ~165 ~124 ~103 dirt
setblock ~165 ~124 ~104 dirt
setblock ~165 ~124 ~105 dirt
setblock ~165 ~124 ~106 grass_block
setblock ~165 ~124 ~107 grass_block
setblock ~165 ~124 ~108 grass_block
setblock ~165 ~124 ~109 grass_block
setblock ~165 ~124 ~110 grass_block
setblock ~165 ~124 ~111 grass_block
setblock ~165 ~124 ~112 dirt
setblock ~165 ~124 ~113 dirt
setblock ~165 ~124 ~114 dirt
setblock ~165 ~124 ~115 dirt
setblock ~165 ~124 ~116 dirt
setblock ~165 ~124 ~117 dirt
setblock ~165 ~124 ~118 dirt
setblock ~165 ~124 ~119 dirt
setblock ~165 ~124 ~120 dirt
setblock ~165 ~125 ~89 short_grass
setblock ~165 ~125 ~90 short_grass
setblock ~165 ~125 ~91 short_grass
setblock ~165 ~125 ~96 grass_block
setblock ~165 ~125 ~97 grass_block
setblock ~165 ~125 ~98 grass_block
setblock ~165 ~125 ~99 grass_block
setblock ~165 ~125 ~100 dirt
setblock ~165 ~125 ~101 dirt
setblock ~165 ~125 ~102 grass_block
setblock ~165 ~125 ~103 grass_block
setblock ~165 ~125 ~104 grass_block
setblock ~165 ~125 ~105 grass_block
setblock ~165 ~125 ~112 grass_block
setblock ~165 ~125 ~113 grass_block
setblock ~165 ~125 ~114 grass_block
setblock ~165 ~125 ~115 dirt
setblock ~165 ~125 ~116 dirt
setblock ~165 ~125 ~117 dirt
setblock ~165 ~125 ~118 dirt
setblock ~165 ~125 ~119 dirt
setblock ~165 ~125 ~120 dirt
setblock ~165 ~126 ~98 short_grass
setblock ~165 ~126 ~100 grass_block
setblock ~165 ~126 ~101 grass_block
setblock ~165 ~126 ~103 short_grass
setblock ~165 ~126 ~104 fern
setblock ~165 ~126 ~114 short_grass
setblock ~165 ~126 ~115 grass_block
setblock ~165 ~126 ~116 grass_block
setblock ~165 ~126 ~117 grass_block
setblock ~165 ~126 ~118 grass_block
setblock ~165 ~126 ~119 dirt
setblock ~165 ~126 ~120 dirt
setblock ~165 ~127 ~100 short_grass
setblock ~165 ~127 ~101 poppy
setblock ~165 ~127 ~119 grass_block
setblock ~165 ~127 ~120 grass_block
setblock ~165 ~128 ~120 fern
setblock ~166 ~109 ~97 dirt
setblock ~166 ~110 ~95 dirt
setblock ~166 ~110 ~97 dirt
setblock ~166 ~111 ~94 dirt
setblock ~166 ~111 ~95 dirt
setblock ~166 ~111 ~97 dirt
setblock ~166 ~111 ~98 dirt
setblock ~166 ~112 ~92 dirt
setblock ~166 ~112 ~94 dirt
setblock ~166 ~112 ~95 dirt
setblock ~166 ~112 ~96 dirt
setblock ~166 ~112 ~97 dirt
setblock ~166 ~112 ~98 dirt
setblock ~166 ~112 ~99 dirt
setblock ~166 ~113 ~92 dirt
setblock ~166 ~113 ~94 dirt
setblock ~166 ~113 ~95 dirt
setblock ~166 ~113 ~96 dirt
setblock ~166 ~113 ~97 dirt
setblock ~166 ~113 ~98 dirt
setblock ~166 ~113 ~99 dirt
setblock ~166 ~114 ~92 dirt
setblock ~166 ~114 ~93 dirt
setblock ~166 ~114 ~94 dirt
setblock ~166 ~114 ~95 dirt
setblock ~166 ~114 ~96 dirt
setblock ~166 ~114 ~97 dirt
setblock ~166 ~114 ~98 dirt
setblock ~166 ~114 ~99 dirt
setblock ~166 ~114 ~100 dirt
setblock ~166 ~114 ~108 dirt
setblock ~166 ~114 ~109 dirt
setblock ~166 ~115 ~91 dirt
setblock ~166 ~115 ~92 dirt
setblock ~166 ~115 ~93 dirt
setblock ~166 ~115 ~94 dirt
setblock ~166 ~115 ~95 dirt
setblock ~166 ~115 ~96 dirt
setblock ~166 ~115 ~97 dirt
setblock ~166 ~115 ~98 dirt
setblock ~166 ~115 ~99 dirt
setblock ~166 ~115 ~100 dirt
setblock ~166 ~115 ~101 dirt
setblock ~166 ~115 ~108 dirt
setblock ~166 ~115 ~109 dirt
setblock ~166 ~115 ~110 dirt
setblock ~166 ~115 ~111 dirt
setblock ~166 ~116 ~91 dirt
setblock ~166 ~116 ~92 dirt
setblock ~166 ~116 ~93 dirt
setblock ~166 ~116 ~94 dirt
setblock ~166 ~116 ~95 dirt
setblock ~166 ~116 ~96 dirt
setblock ~166 ~116 ~97 dirt
setblock ~166 ~116 ~98 dirt
setblock ~166 ~116 ~99 dirt
setblock ~166 ~116 ~100 dirt
setblock ~166 ~116 ~101 dirt
setblock ~166 ~116 ~102 dirt
setblock ~166 ~116 ~107 dirt
setblock ~166 ~116 ~108 dirt
setblock ~166 ~116 ~109 dirt
setblock ~166 ~116 ~110 dirt
setblock ~166 ~116 ~111 dirt
setblock ~166 ~116 ~112 dirt
setblock ~166 ~116 ~114 dirt
setblock ~166 ~117 ~90 dirt
setblock ~166 ~117 ~91 dirt
setblock ~166 ~117 ~92 dirt
setblock ~166 ~117 ~93 dirt
setblock ~166 ~117 ~94 dirt
setblock ~166 ~117 ~95 dirt
setblock ~166 ~117 ~96 dirt
setblock ~166 ~117 ~97 dirt
setblock ~166 ~117 ~98 dirt
setblock ~166 ~117 ~99 dirt
setblock ~166 ~117 ~100 dirt
setblock ~166 ~117 ~101 dirt
setblock ~166 ~117 ~102 dirt
setblock ~166 ~117 ~106 dirt
setblock ~166 ~117 ~107 dirt
setblock ~166 ~117 ~108 dirt
setblock ~166 ~117 ~109 dirt
setblock ~166 ~117 ~110 dirt
setblock ~166 ~117 ~111 dirt
setblock ~166 ~117 ~112 dirt
setblock ~166 ~117 ~113 dirt
setblock ~166 ~117 ~114 dirt
setblock ~166 ~117 ~115 dirt
setblock ~166 ~118 ~88 dirt
setblock ~166 ~118 ~89 dirt
setblock ~166 ~118 ~90 dirt
setblock ~166 ~118 ~91 dirt
setblock ~166 ~118 ~92 dirt
setblock ~166 ~118 ~93 dirt
setblock ~166 ~118 ~94 dirt
setblock ~166 ~118 ~95 dirt
setblock ~166 ~118 ~96 dirt
setblock ~166 ~118 ~97 dirt
setblock ~166 ~118 ~98 dirt
setblock ~166 ~118 ~99 dirt
setblock ~166 ~118 ~100 dirt
setblock ~166 ~118 ~101 dirt
setblock ~166 ~118 ~102 dirt
setblock ~166 ~118 ~103 dirt
setblock ~166 ~118 ~104 dirt
setblock ~166 ~118 ~105 dirt
setblock ~166 ~118 ~106 dirt
setblock ~166 ~118 ~107 dirt
setblock ~166 ~118 ~108 dirt
setblock ~166 ~118 ~109 dirt
setblock ~166 ~118 ~110 dirt
setblock ~166 ~118 ~111 dirt
setblock ~166 ~118 ~112 dirt
setblock ~166 ~118 ~113 dirt
setblock ~166 ~118 ~114 dirt
setblock ~166 ~118 ~115 dirt
setblock ~166 ~118 ~116 dirt
setblock ~166 ~119 ~88 dirt
setblock ~166 ~119 ~89 dirt
setblock ~166 ~119 ~90 dirt
setblock ~166 ~119 ~91 dirt
setblock ~166 ~119 ~92 dirt
setblock ~166 ~119 ~93 dirt
setblock ~166 ~119 ~94 dirt
setblock ~166 ~119 ~95 dirt
setblock ~166 ~119 ~96 dirt
setblock ~166 ~119 ~97 dirt
setblock ~166 ~119 ~98 dirt
setblock ~166 ~119 ~99 dirt
setblock ~166 ~119 ~100 dirt
setblock ~166 ~119 ~101 dirt
setblock ~166 ~119 ~102 dirt
setblock ~166 ~119 ~103 dirt
setblock ~166 ~119 ~104 dirt
setblock ~166 ~119 ~105 dirt
setblock ~166 ~119 ~106 dirt
setblock ~166 ~119 ~107 dirt
setblock ~166 ~119 ~108 dirt
setblock ~166 ~119 ~109 dirt
setblock ~166 ~119 ~110 dirt
setblock ~166 ~119 ~111 dirt
setblock ~166 ~119 ~112 dirt
setblock ~166 ~119 ~113 dirt
setblock ~166 ~119 ~114 dirt
setblock ~166 ~119 ~115 dirt
setblock ~166 ~119 ~116 dirt
setblock ~166 ~119 ~117 dirt
setblock ~166 ~120 ~87 dirt
setblock ~166 ~120 ~88 dirt
setblock ~166 ~120 ~89 dirt
setblock ~166 ~120 ~90 dirt
setblock ~166 ~120 ~91 dirt
setblock ~166 ~120 ~92 dirt
setblock ~166 ~120 ~93 dirt
setblock ~166 ~120 ~94 dirt
setblock ~166 ~120 ~95 dirt
setblock ~166 ~120 ~96 dirt
setblock ~166 ~120 ~97 dirt
setblock ~166 ~120 ~98 dirt
setblock ~166 ~120 ~99 dirt
setblock ~166 ~120 ~100 dirt
setblock ~166 ~120 ~101 dirt
setblock ~166 ~120 ~102 dirt
setblock ~166 ~120 ~103 dirt
setblock ~166 ~120 ~104 dirt
setblock ~166 ~120 ~105 dirt
setblock ~166 ~120 ~106 dirt
setblock ~166 ~120 ~107 dirt
setblock ~166 ~120 ~108 dirt
setblock ~166 ~120 ~109 dirt
setblock ~166 ~120 ~110 dirt
setblock ~166 ~120 ~111 dirt
setblock ~166 ~120 ~112 dirt
setblock ~166 ~120 ~113 dirt
setblock ~166 ~120 ~114 dirt
setblock ~166 ~120 ~115 dirt
setblock ~166 ~120 ~116 dirt
setblock ~166 ~120 ~117 dirt
setblock ~166 ~120 ~118 dirt
setblock ~166 ~121 ~87 dirt
setblock ~166 ~121 ~88 dirt
setblock ~166 ~121 ~89 dirt
setblock ~166 ~121 ~90 dirt
setblock ~166 ~121 ~91 dirt
setblock ~166 ~121 ~92 dirt
setblock ~166 ~121 ~93 dirt
setblock ~166 ~121 ~94 dirt
setblock ~166 ~121 ~95 dirt
setblock ~166 ~121 ~96 dirt
setblock ~166 ~121 ~97 dirt
setblock ~166 ~121 ~98 dirt
setblock ~166 ~121 ~99 dirt
setblock ~166 ~121 ~100 dirt
setblock ~166 ~121 ~101 dirt
setblock ~166 ~121 ~102 dirt
setblock ~166 ~121 ~103 dirt
setblock ~166 ~121 ~104 dirt
setblock ~166 ~121 ~105 dirt
setblock ~166 ~121 ~106 dirt
setblock ~166 ~121 ~107 dirt
setblock ~166 ~121 ~108 dirt
setblock ~166 ~121 ~109 dirt
setblock ~166 ~121 ~110 dirt
setblock ~166 ~121 ~111 dirt
setblock ~166 ~121 ~112 dirt
setblock ~166 ~121 ~113 dirt
setblock ~166 ~121 ~114 dirt
setblock ~166 ~121 ~115 dirt
setblock ~166 ~121 ~116 dirt
setblock ~166 ~121 ~117 dirt
setblock ~166 ~121 ~118 dirt
setblock ~166 ~121 ~119 dirt
setblock ~166 ~122 ~87 dirt
setblock ~166 ~122 ~88 dirt
setblock ~166 ~122 ~89 dirt
setblock ~166 ~122 ~90 dirt
setblock ~166 ~122 ~91 dirt
setblock ~166 ~122 ~92 dirt
setblock ~166 ~122 ~93 dirt
setblock ~166 ~122 ~94 dirt
setblock ~166 ~122 ~95 dirt
setblock ~166 ~122 ~96 dirt
setblock ~166 ~122 ~97 dirt
setblock ~166 ~122 ~98 dirt
setblock ~166 ~122 ~99 dirt
setblock ~166 ~122 ~100 dirt
setblock ~166 ~122 ~101 dirt
setblock ~166 ~122 ~102 dirt
setblock ~166 ~122 ~103 dirt
setblock ~166 ~122 ~104 dirt
setblock ~166 ~122 ~105 dirt
setblock ~166 ~122 ~106 dirt
setblock ~166 ~122 ~107 dirt
setblock ~166 ~122 ~108 dirt
setblock ~166 ~122 ~109 dirt
setblock ~166 ~122 ~110 dirt
setblock ~166 ~122 ~111 dirt
setblock ~166 ~122 ~112 dirt
setblock ~166 ~122 ~113 dirt
setblock ~166 ~122 ~114 dirt
setblock ~166 ~122 ~115 dirt
setblock ~166 ~122 ~116 dirt
setblock ~166 ~122 ~117 dirt
setblock ~166 ~122 ~118 dirt
setblock ~166 ~122 ~119 dirt
setblock ~166 ~123 ~87 dirt
setblock ~166 ~123 ~88 dirt
setblock ~166 ~123 ~89 grass_block
setblock ~166 ~123 ~90 grass_block
setblock ~166 ~123 ~91 grass_block
setblock ~166 ~123 ~92 grass_block
setblock ~166 ~123 ~93 dirt
setblock ~166 ~123 ~94 dirt
setblock ~166 ~123 ~95 dirt
setblock ~166 ~123 ~96 dirt
setblock ~166 ~123 ~97 dirt
setblock ~166 ~123 ~98 dirt
setblock ~166 ~123 ~99 dirt
setblock ~166 ~123 ~100 dirt
setblock ~166 ~123 ~101 dirt
setblock ~166 ~123 ~102 dirt
setblock ~166 ~123 ~103 dirt
setblock ~166 ~123 ~104 dirt
setblock ~166 ~123 ~105 dirt
setblock ~166 ~123 ~106 dirt
setblock ~166 ~123 ~107 dirt
setblock ~166 ~123 ~108 dirt
setblock ~166 ~123 ~109 dirt
setblock ~166 ~123 ~110 dirt
setblock ~166 ~123 ~111 dirt
setblock ~166 ~123 ~112 dirt
setblock ~166 ~123 ~113 dirt
setblock ~166 ~123 ~114 dirt
setblock ~166 ~123 ~115 dirt
setblock ~166 ~123 ~116 dirt
setblock ~166 ~123 ~117 dirt
setblock ~166 ~123 ~118 dirt
setblock ~166 ~123 ~119 dirt
setblock ~166 ~124 ~87 grass_block
setblock ~166 ~124 ~88 grass_block
setblock ~166 ~124 ~90 short_grass
setblock ~166 ~124 ~92 poppy
setblock ~166 ~124 ~93 grass_block
setblock ~166 ~124 ~94 grass_block
setblock ~166 ~124 ~95 grass_block
setblock ~166 ~124 ~96 dirt
setblock ~166 ~124 ~97 dirt
setblock ~166 ~124 ~98 dirt
setblock ~166 ~124 ~99 dirt
setblock ~166 ~124 ~100 dirt
setblock ~166 ~124 ~101 dirt
setblock ~166 ~124 ~102 dirt
setblock ~166 ~124 ~103 dirt
setblock ~166 ~124 ~104 dirt
setblock ~166 ~124 ~105 dirt
setblock ~166 ~124 ~106 dirt
setblock ~166 ~124 ~107 grass_block
setblock ~166 ~124 ~108 grass_block
setblock ~166 ~124 ~109 grass_block
setblock ~166 ~124 ~110 grass_block
setblock ~166 ~124 ~111 grass_block
setblock ~166 ~124 ~112 dirt
setblock ~166 ~124 ~113 dirt
setblock ~166 ~124 ~114 dirt
setblock ~166 ~124 ~115 dirt
setblock ~166 ~124 ~116 dirt
setblock ~166 ~124 ~117 dirt
setblock ~166 ~124 ~118 dirt
setblock ~166 ~124 ~119 dirt
setblock ~166 ~125 ~93 poppy
setblock ~166 ~125 ~96 grass_block
setblock ~166 ~125 ~97 grass_block
setblock ~166 ~125 ~98 grass_block
setblock ~166 ~125 ~99 dirt
setblock ~166 ~125 ~100 dirt
setblock ~166 ~125 ~101 dirt
setblock ~166 ~125 ~102 dirt
setblock ~166 ~125 ~103 grass_block
setblock ~166 ~125 ~104 grass_block
setblock ~166 ~125 ~105 grass_block
setblock ~166 ~125 ~106 grass_block
setblock ~166 ~125 ~109 short_grass
setblock ~166 ~125 ~112 grass_block
setblock ~166 ~125 ~113 grass_block
setblock ~166 ~125 ~114 grass_block
setblock ~166 ~125 ~115 grass_block
setblock ~166 ~125 ~116 dirt
setblock ~166 ~125 ~117 dirt
setblock ~166 ~125 ~118 dirt
setblock ~166 ~125 ~119 dirt
setblock ~166 ~126 ~99 grass_block
setblock ~166 ~126 ~100 dirt
setblock ~166 ~126 ~101 grass_block
setblock ~166 ~126 ~102 grass_block
setblock ~166 ~126 ~112 short_grass
setblock ~166 ~126 ~116 grass_block
setblock ~166 ~126 ~117 grass_block
setblock ~166 ~126 ~118 grass_block
setblock ~166 ~126 ~119 grass_block
setblock ~166 ~127 ~100 grass_block
setblock ~166 ~127 ~101 short_grass
setblock ~166 ~127 ~119 short_grass
setblock ~166 ~128 ~100 short_grass
setblock ~167 ~113 ~95 dirt
setblock ~167 ~113 ~97 dirt
setblock ~167 ~113 ~98 dirt
setblock ~167 ~114 ~94 dirt
setblock ~167 ~114 ~95 dirt
setblock ~167 ~114 ~96 dirt
setblock ~167 ~114 ~97 dirt
setblock ~167 ~114 ~98 dirt
setblock ~167 ~115 ~93 dirt
setblock ~167 ~115 ~94 dirt
setblock ~167 ~115 ~95 dirt
setblock ~167 ~115 ~96 dirt
setblock ~167 ~115 ~97 dirt
setblock ~167 ~115 ~98 dirt
setblock ~167 ~115 ~99 dirt
setblock ~167 ~115 ~109 dirt
setblock ~167 ~116 ~92 dirt
setblock ~167 ~116 ~93 dirt
setblock ~167 ~116 ~94 dirt
setblock ~167 ~116 ~95 dirt
setblock ~167 ~116 ~96 dirt
setblock ~167 ~116 ~97 dirt
setblock ~167 ~116 ~98 dirt
setblock ~167 ~116 ~99 dirt
setblock ~167 ~116 ~101 dirt
setblock ~167 ~116 ~108 dirt
setblock ~167 ~116 ~109 dirt
setblock ~167 ~117 ~91 dirt
setblock ~167 ~117 ~92 dirt
setblock ~167 ~117 ~93 dirt
setblock ~167 ~117 ~94 dirt
setblock ~167 ~117 ~95 dirt
setblock ~167 ~117 ~96 dirt
setblock ~167 ~117 ~97 dirt
setblock ~167 ~117 ~98 dirt
setblock ~167 ~117 ~99 dirt
setblock ~167 ~117 ~100 dirt
setblock ~167 ~117 ~101 dirt
setblock ~167 ~117 ~107 dirt
setblock ~167 ~117 ~108 dirt
setblock ~167 ~117 ~109 dirt
setblock ~167 ~117 ~111 dirt
setblock ~167 ~118 ~90 dirt
setblock ~167 ~118 ~91 dirt
setblock ~167 ~118 ~92 dirt
setblock ~167 ~118 ~93 dirt
setblock ~167 ~118 ~94 dirt
setblock ~167 ~118 ~95 dirt
setblock ~167 ~118 ~96 dirt
setblock ~167 ~118 ~97 dirt
setblock ~167 ~118 ~98 dirt
setblock ~167 ~118 ~99 dirt
setblock ~167 ~118 ~100 dirt
setblock ~167 ~118 ~101 dirt
setblock ~167 ~118 ~102 dirt
setblock ~167 ~118 ~106 dirt
setblock ~167 ~118 ~107 dirt
setblock ~167 ~118 ~108 dirt
setblock ~167 ~118 ~109 dirt
setblock ~167 ~118 ~110 dirt
setblock ~167 ~118 ~111 dirt
setblock ~167 ~118 ~112 dirt
setblock ~167 ~118 ~113 dirt
setblock ~167 ~119 ~89 dirt
setblock ~167 ~119 ~90 dirt
setblock ~167 ~119 ~91 dirt
setblock ~167 ~119 ~92 dirt
setblock ~167 ~119 ~93 dirt
setblock ~167 ~119 ~94 dirt
setblock ~167 ~119 ~95 dirt
setblock ~167 ~119 ~96 dirt
setblock ~167 ~119 ~97 dirt
setblock ~167 ~119 ~98 dirt
setblock ~167 ~119 ~99 dirt
setblock ~167 ~119 ~100 dirt
setblock ~167 ~119 ~101 dirt
setblock ~167 ~119 ~102 dirt
setblock ~167 ~119 ~106 dirt
setblock ~167 ~119 ~107 dirt
setblock ~167 ~119 ~108 dirt
setblock ~167 ~119 ~109 dirt
setblock ~167 ~119 ~110 dirt
setblock ~167 ~119 ~111 dirt
setblock ~167 ~119 ~112 dirt
setblock ~167 ~119 ~113 dirt
setblock ~167 ~119 ~114 dirt
setblock ~167 ~120 ~88 dirt
setblock ~167 ~120 ~89 dirt
setblock ~167 ~120 ~90 dirt
setblock ~167 ~120 ~91 dirt
setblock ~167 ~120 ~92 dirt
setblock ~167 ~120 ~93 dirt
setblock ~167 ~120 ~94 dirt
setblock ~167 ~120 ~95 dirt
setblock ~167 ~120 ~96 dirt
setblock ~167 ~120 ~97 dirt
setblock ~167 ~120 ~98 dirt
setblock ~167 ~120 ~99 dirt
setblock ~167 ~120 ~100 dirt
setblock ~167 ~120 ~101 dirt
setblock ~167 ~120 ~102 dirt
setblock ~167 ~120 ~104 dirt
setblock ~167 ~120 ~105 dirt
setblock ~167 ~120 ~106 dirt
setblock ~167 ~120 ~107 dirt
setblock ~167 ~120 ~108 dirt
setblock ~167 ~120 ~109 dirt
setblock ~167 ~120 ~110 dirt
setblock ~167 ~120 ~111 dirt
setblock ~167 ~120 ~112 dirt
setblock ~167 ~120 ~113 dirt
setblock ~167 ~120 ~114 dirt
setblock ~167 ~121 ~87 dirt
setblock ~167 ~121 ~88 dirt
setblock ~167 ~121 ~89 dirt
setblock ~167 ~121 ~90 dirt
setblock ~167 ~121 ~91 dirt
setblock ~167 ~121 ~92 dirt
setblock ~167 ~121 ~93 dirt
setblock ~167 ~121 ~94 dirt
setblock ~167 ~121 ~95 dirt
setblock ~167 ~121 ~96 dirt
setblock ~167 ~121 ~97 dirt
setblock ~167 ~121 ~98 dirt
setblock ~167 ~121 ~99 dirt
setblock ~167 ~121 ~100 dirt
setblock ~167 ~121 ~101 dirt
setblock ~167 ~121 ~102 dirt
setblock ~167 ~121 ~103 dirt
setblock ~167 ~121 ~104 dirt
setblock ~167 ~121 ~105 dirt
setblock ~167 ~121 ~106 dirt
setblock ~167 ~121 ~107 dirt
setblock ~167 ~121 ~108 dirt
setblock ~167 ~121 ~109 dirt
setblock ~167 ~121 ~110 dirt
setblock ~167 ~121 ~111 dirt
setblock ~167 ~121 ~112 dirt
setblock ~167 ~121 ~113 dirt
setblock ~167 ~121 ~114 dirt
setblock ~167 ~121 ~115 dirt
setblock ~167 ~121 ~116 dirt
setblock ~167 ~121 ~117 dirt
setblock ~167 ~121 ~118 dirt
setblock ~167 ~122 ~87 dirt
setblock ~167 ~122 ~88 dirt
setblock ~167 ~122 ~89 dirt
setblock ~167 ~122 ~90 dirt
setblock ~167 ~122 ~91 dirt
setblock ~167 ~122 ~92 dirt
setblock ~167 ~122 ~93 dirt
setblock ~167 ~122 ~94 dirt
setblock ~167 ~122 ~95 dirt
setblock ~167 ~122 ~96 dirt
setblock ~167 ~122 ~97 dirt
setblock ~167 ~122 ~98 dirt
setblock ~167 ~122 ~99 dirt
setblock ~167 ~122 ~100 dirt
setblock ~167 ~122 ~101 dirt
setblock ~167 ~122 ~102 dirt
setblock ~167 ~122 ~103 dirt
setblock ~167 ~122 ~104 dirt
setblock ~167 ~122 ~105 dirt
setblock ~167 ~122 ~106 dirt
setblock ~167 ~122 ~107 dirt
setblock ~167 ~122 ~108 dirt
setblock ~167 ~122 ~109 dirt
setblock ~167 ~122 ~110 dirt
setblock ~167 ~122 ~111 dirt
setblock ~167 ~122 ~112 dirt
setblock ~167 ~122 ~113 dirt
setblock ~167 ~122 ~114 dirt
setblock ~167 ~122 ~115 dirt
setblock ~167 ~122 ~116 dirt
setblock ~167 ~122 ~117 dirt
setblock ~167 ~122 ~118 dirt
setblock ~167 ~123 ~87 dirt
setblock ~167 ~123 ~88 grass_block
setblock ~167 ~123 ~89 grass_block
setblock ~167 ~123 ~90 grass_block
setblock ~167 ~123 ~91 grass_block
setblock ~167 ~123 ~92 grass_block
setblock ~167 ~123 ~93 grass_block
setblock ~167 ~123 ~94 dirt
setblock ~167 ~123 ~95 dirt
setblock ~167 ~123 ~96 dirt
setblock ~167 ~123 ~97 dirt
setblock ~167 ~123 ~98 dirt
setblock ~167 ~123 ~99 dirt
setblock ~167 ~123 ~100 dirt
setblock ~167 ~123 ~101 dirt
setblock ~167 ~123 ~102 dirt
setblock ~167 ~123 ~103 dirt
setblock ~167 ~123 ~104 dirt
setblock ~167 ~123 ~105 dirt
setblock ~167 ~123 ~106 dirt
setblock ~167 ~123 ~107 dirt
setblock ~167 ~123 ~108 dirt
setblock ~167 ~123 ~109 dirt
setblock ~167 ~123 ~110 dirt
setblock ~167 ~123 ~111 dirt
setblock ~167 ~123 ~112 dirt
setblock ~167 ~123 ~113 dirt
setblock ~167 ~123 ~114 dirt
setblock ~167 ~123 ~115 dirt
setblock ~167 ~123 ~116 dirt
setblock ~167 ~123 ~117 dirt
setblock ~167 ~123 ~118 dirt
setblock ~167 ~124 ~87 grass_block
setblock ~167 ~124 ~89 short_grass
setblock ~167 ~124 ~91 short_grass
setblock ~167 ~124 ~94 grass_block
setblock ~167 ~124 ~95 grass_block
setblock ~167 ~124 ~96 grass_block
setblock ~167 ~124 ~97 dirt
setblock ~167 ~124 ~98 dirt
setblock ~167 ~124 ~99 dirt
setblock ~167 ~124 ~100 dirt
setblock ~167 ~124 ~101 dirt
setblock ~167 ~124 ~102 dirt
setblock ~167 ~124 ~103 dirt
setblock ~167 ~124 ~104 dirt
setblock ~167 ~124 ~105 dirt
setblock ~167 ~124 ~106 dirt
setblock ~167 ~124 ~107 dirt
setblock ~167 ~124 ~108 grass_block
setblock ~167 ~124 ~109 grass_block
setblock ~167 ~124 ~110 grass_block
setblock ~167 ~124 ~111 grass_block
setblock ~167 ~124 ~112 dirt
setblock ~167 ~124 ~113 dirt
setblock ~167 ~124 ~114 dirt
setblock ~167 ~124 ~115 dirt
setblock ~167 ~124 ~116 dirt
setblock ~167 ~124 ~117 dirt
setblock ~167 ~124 ~118 dirt
setblock ~167 ~125 ~95 fern
setblock ~167 ~125 ~97 grass_block
setblock ~167 ~125 ~98 dirt
setblock ~167 ~125 ~99 dirt
setblock ~167 ~125 ~100 dirt
setblock ~167 ~125 ~101 dirt
setblock ~167 ~125 ~102 dirt
setblock ~167 ~125 ~103 dirt
setblock ~167 ~125 ~104 dirt
setblock ~167 ~125 ~105 grass_block
setblock ~167 ~125 ~106 grass_block
setblock ~167 ~125 ~107 grass_block
setblock ~167 ~125 ~110 short_grass
setblock ~167 ~125 ~112 grass_block
setblock ~167 ~125 ~113 grass_block
setblock ~167 ~125 ~114 grass_block
setblock ~167 ~125 ~115 grass_block
setblock ~167 ~125 ~116 dirt
setblock ~167 ~125 ~117 dirt
setblock ~167 ~125 ~118 dirt
setblock ~167 ~126 ~98 grass_block
setblock ~167 ~126 ~99 dirt
setblock ~167 ~126 ~100 dirt
setblock ~167 ~126 ~101 dirt
setblock ~167 ~126 ~102 grass_block
setblock ~167 ~126 ~103 grass_block
setblock ~167 ~126 ~104 grass_block
setblock ~167 ~126 ~106 short_grass
setblock ~167 ~126 ~107 short_grass
setblock ~167 ~126 ~114 fern
setblock ~167 ~126 ~115 short_grass
setblock ~167 ~126 ~116 grass_block
setblock ~167 ~126 ~117 grass_block
setblock ~167 ~126 ~118 grass_block
setblock ~167 ~127 ~99 grass_block
setblock ~167 ~127 ~100 dirt
setblock ~167 ~127 ~101 grass_block
setblock ~167 ~127 ~104 poppy
setblock ~167 ~127 ~116 poppy
setblock ~167 ~127 ~117 short_grass
setblock ~167 ~128 ~100 grass_block
setblock ~167 ~129 ~100 short_grass
setblock ~168 ~115 ~94 dirt
setblock ~168 ~115 ~95 dirt
setblock ~168 ~116 ~93 dirt
setblock ~168 ~116 ~94 dirt
setblock ~168 ~116 ~95 dirt
setblock ~168 ~116 ~96 dirt
setblock ~168 ~116 ~97 dirt
setblock ~168 ~117 ~93 dirt
setblock ~168 ~117 ~94 dirt
setblock ~168 ~117 ~95 dirt
setblock ~168 ~117 ~96 dirt
setblock ~168 ~117 ~97 dirt
setblock ~168 ~117 ~98 dirt
setblock ~168 ~117 ~99 dirt
setblock ~168 ~118 ~91 dirt
setblock ~168 ~118 ~92 dirt
setblock ~168 ~118 ~93 dirt
setblock ~168 ~118 ~94 dirt
setblock ~168 ~118 ~95 dirt
setblock ~168 ~118 ~96 dirt
setblock ~168 ~118 ~97 dirt
setblock ~168 ~118 ~98 dirt
setblock ~168 ~118 ~99 dirt
setblock ~168 ~118 ~100 dirt
setblock ~168 ~118 ~101 dirt
setblock ~168 ~118 ~108 dirt
setblock ~168 ~118 ~111 dirt
setblock ~168 ~119 ~90 dirt
setblock ~168 ~119 ~91 dirt
setblock ~168 ~119 ~92 dirt
setblock ~168 ~119 ~93 dirt
setblock ~168 ~119 ~94 dirt
setblock ~168 ~119 ~95 dirt
setblock ~168 ~119 ~96 dirt
setblock ~168 ~119 ~97 dirt
setblock ~168 ~119 ~98 dirt
setblock ~168 ~119 ~99 dirt
setblock ~168 ~119 ~100 dirt
setblock ~168 ~119 ~101 dirt
setblock ~168 ~119 ~107 dirt
setblock ~168 ~119 ~108 dirt
setblock ~168 ~119 ~109 dirt
setblock ~168 ~119 ~110 dirt
setblock ~168 ~119 ~111 dirt
setblock ~168 ~119 ~112 dirt
setblock ~168 ~120 ~90 dirt
setblock ~168 ~120 ~91 dirt
setblock ~168 ~120 ~92 dirt
setblock ~168 ~120 ~93 dirt
setblock ~168 ~120 ~94 dirt
setblock ~168 ~120 ~95 dirt
setblock ~168 ~120 ~96 dirt
setblock ~168 ~120 ~97 dirt
setblock ~168 ~120 ~98 dirt
setblock ~168 ~120 ~99 dirt
setblock ~168 ~120 ~100 dirt
setblock ~168 ~120 ~101 dirt
setblock ~168 ~120 ~106 dirt
setblock ~168 ~120 ~107 dirt
setblock ~168 ~120 ~108 dirt
setblock ~168 ~120 ~109 dirt
setblock ~168 ~120 ~110 dirt
setblock ~168 ~120 ~111 dirt
setblock ~168 ~120 ~112 dirt
setblock ~168 ~120 ~113 dirt
setblock ~168 ~121 ~88 dirt
setblock ~168 ~121 ~89 dirt
setblock ~168 ~121 ~90 dirt
setblock ~168 ~121 ~91 dirt
setblock ~168 ~121 ~92 dirt
setblock ~168 ~121 ~93 dirt
setblock ~168 ~121 ~94 dirt
setblock ~168 ~121 ~95 dirt
setblock ~168 ~121 ~96 dirt
setblock ~168 ~121 ~97 dirt
setblock ~168 ~121 ~98 dirt
setblock ~168 ~121 ~99 dirt
setblock ~168 ~121 ~100 dirt
setblock ~168 ~121 ~101 dirt
setblock ~168 ~121 ~102 dirt
setblock ~168 ~121 ~105 dirt
setblock ~168 ~121 ~106 dirt
setblock ~168 ~121 ~107 dirt
setblock ~168 ~121 ~108 dirt
setblock ~168 ~121 ~109 dirt
setblock ~168 ~121 ~110 dirt
setblock ~168 ~121 ~111 dirt
setblock ~168 ~121 ~112 dirt
setblock ~168 ~121 ~113 dirt
setblock ~168 ~121 ~114 dirt
setblock ~168 ~122 ~88 dirt
setblock ~168 ~122 ~89 dirt
setblock ~168 ~122 ~90 grass_block
setblock ~168 ~122 ~91 grass_block
setblock ~168 ~122 ~92 dirt
setblock ~168 ~122 ~93 dirt
setblock ~168 ~122 ~94 dirt
setblock ~168 ~122 ~95 dirt
setblock ~168 ~122 ~96 dirt
setblock ~168 ~122 ~97 dirt
setblock ~168 ~122 ~98 dirt
setblock ~168 ~122 ~99 dirt
setblock ~168 ~122 ~100 dirt
setblock ~168 ~122 ~101 dirt
setblock ~168 ~122 ~102 dirt
setblock ~168 ~122 ~105 dirt
setblock ~168 ~122 ~106 dirt
setblock ~168 ~122 ~107 dirt
setblock ~168 ~122 ~108 dirt
setblock ~168 ~122 ~109 dirt
setblock ~168 ~122 ~110 dirt
setblock ~168 ~122 ~111 dirt
setblock ~168 ~122 ~112 dirt
setblock ~168 ~122 ~113 dirt
setblock ~168 ~122 ~114 dirt
setblock ~168 ~123 ~88 grass_block
setblock ~168 ~123 ~89 grass_block
setblock ~168 ~123 ~92 grass_block
setblock ~168 ~123 ~93 grass_block
setblock ~168 ~123 ~94 grass_block
setblock ~168 ~123 ~95 dirt
setblock ~168 ~123 ~96 dirt
setblock ~168 ~123 ~97 dirt
setblock ~168 ~123 ~98 dirt
setblock ~168 ~123 ~99 dirt
setblock ~168 ~123 ~100 dirt
setblock ~168 ~123 ~101 dirt
setblock ~168 ~123 ~102 dirt
setblock ~168 ~123 ~105 dirt
setblock ~168 ~123 ~106 dirt
setblock ~168 ~123 ~107 dirt
setblock ~168 ~123 ~108 dirt
setblock ~168 ~123 ~109 dirt
setblock ~168 ~123 ~110 dirt
setblock ~168 ~123 ~111 dirt
setblock ~168 ~123 ~112 dirt
setblock ~168 ~123 ~113 dirt
setblock ~168 ~123 ~114 dirt
setblock ~168 ~124 ~92 short_grass
setblock ~168 ~124 ~95 grass_block
setblock ~168 ~124 ~96 grass_block
setblock ~168 ~124 ~97 dirt
setblock ~168 ~124 ~98 dirt
setblock ~168 ~124 ~99 dirt
setblock ~168 ~124 ~100 dirt
setblock ~168 ~124 ~101 dirt
setblock ~168 ~124 ~102 dirt
setblock ~168 ~124 ~105 dirt
setblock ~168 ~124 ~106 dirt
setblock ~168 ~124 ~107 dirt
setblock ~168 ~124 ~108 grass_block
setblock ~168 ~124 ~109 grass_block
setblock ~168 ~124 ~110 grass_block
setblock ~168 ~124 ~111 grass_block
setblock ~168 ~124 ~112 grass_block
setblock ~168 ~124 ~113 dirt
setblock ~168 ~124 ~114 dirt
setblock ~168 ~125 ~95 short_grass
setblock ~168 ~125 ~96 short_grass
setblock ~168 ~125 ~97 grass_block
setblock ~168 ~125 ~98 dirt
setblock ~168 ~125 ~99 dirt
setblock ~168 ~125 ~100 dirt
setblock ~168 ~125 ~101 dirt
setblock ~168 ~125 ~102 dirt
setblock ~168 ~125 ~105 grass_block
setblock ~168 ~125 ~106 grass_block
setblock ~168 ~125 ~107 grass_block
setblock ~168 ~125 ~112 fern
setblock ~168 ~125 ~113 grass_block
setblock ~168 ~125 ~114 grass_block
setblock ~168 ~126 ~98 grass_block
setblock ~168 ~126 ~99 dirt
setblock ~168 ~126 ~100 dirt
setblock ~168 ~126 ~101 dirt
setblock ~168 ~126 ~102 dirt
setblock ~168 ~126 ~105 short_grass
setblock ~168 ~126 ~107 short_grass
setblock ~168 ~126 ~113 short_grass
setblock ~168 ~127 ~99 grass_block
setblock ~168 ~127 ~100 dirt
setblock ~168 ~127 ~101 dirt
setblock ~168 ~127 ~102 grass_block
setblock ~168 ~128 ~100 dirt
setblock ~168 ~128 ~101 grass_block
setblock ~168 ~128 ~102 short_grass
setblock ~168 ~129 ~100 dirt
setblock ~168 ~129 ~101 short_grass
setblock ~168 ~130 ~100 grass_block
setblock ~168 ~131 ~100 short_grass
setblock ~169 ~116 ~94 dirt
setblock ~169 ~116 ~95 dirt
setblock ~169 ~117 ~94 dirt
setblock ~169 ~117 ~95 dirt
setblock ~169 ~117 ~96 dirt
setblock ~169 ~117 ~97 dirt
setblock ~169 ~118 ~93 dirt
setblock ~169 ~118 ~94 dirt
setblock ~169 ~118 ~95 dirt
setblock ~169 ~118 ~96 dirt
setblock ~169 ~118 ~97 dirt
setblock ~169 ~118 ~99 dirt
setblock ~169 ~119 ~92 dirt
setblock ~169 ~119 ~93 dirt
setblock ~169 ~119 ~94 dirt
setblock ~169 ~119 ~95 dirt
setblock ~169 ~119 ~96 dirt
setblock ~169 ~119 ~97 dirt
setblock ~169 ~119 ~98 dirt
setblock ~169 ~119 ~99 dirt
setblock ~169 ~119 ~111 dirt
setblock ~169 ~120 ~91 dirt
setblock ~169 ~120 ~92 dirt
setblock ~169 ~120 ~93 dirt
setblock ~169 ~120 ~94 dirt
setblock ~169 ~120 ~95 dirt
setblock ~169 ~120 ~96 dirt
setblock ~169 ~120 ~97 dirt
setblock ~169 ~120 ~98 dirt
setblock ~169 ~120 ~99 dirt
setblock ~169 ~120 ~108 dirt
setblock ~169 ~120 ~111 dirt
setblock ~169 ~120 ~112 dirt
setblock ~169 ~121 ~90 dirt
setblock ~169 ~121 ~91 dirt
setblock ~169 ~121 ~92 dirt
setblock ~169 ~121 ~93 dirt
setblock ~169 ~121 ~94 dirt
setblock ~169 ~121 ~95 dirt
setblock ~169 ~121 ~96 dirt
setblock ~169 ~121 ~97 dirt
setblock ~169 ~121 ~98 dirt
setblock ~169 ~121 ~99 dirt
setblock ~169 ~121 ~100 dirt
setblock ~169 ~121 ~101 dirt
setblock ~169 ~121 ~107 dirt
setblock ~169 ~121 ~108 dirt
setblock ~169 ~121 ~109 dirt
setblock ~169 ~121 ~110 dirt
setblock ~169 ~121 ~111 dirt
setblock ~169 ~121 ~112 dirt
setblock ~169 ~122 ~90 grass_block
setblock ~169 ~122 ~91 grass_block
setblock ~169 ~122 ~92 grass_block
setblock ~169 ~122 ~93 dirt
setblock ~169 ~122 ~94 dirt
setblock ~169 ~122 ~95 dirt
setblock ~169 ~122 ~96 dirt
setblock ~169 ~122 ~97 dirt
setblock ~169 ~122 ~98 dirt
setblock ~169 ~122 ~99 dirt
setblock ~169 ~122 ~100 dirt
setblock ~169 ~122 ~101 dirt
setblock ~169 ~122 ~107 dirt
setblock ~169 ~122 ~108 dirt
setblock ~169 ~122 ~109 dirt
setblock ~169 ~122 ~110 dirt
setblock ~169 ~122 ~111 dirt
setblock ~169 ~122 ~112 dirt
setblock ~169 ~123 ~93 grass_block
setblock ~169 ~123 ~94 grass_block
setblock ~169 ~123 ~95 dirt
setblock ~169 ~123 ~96 dirt
setblock ~169 ~123 ~97 dirt
setblock ~169 ~123 ~98 dirt
setblock ~169 ~123 ~99 dirt
setblock ~169 ~123 ~100 dirt
setblock ~169 ~123 ~101 dirt
setblock ~169 ~123 ~107 dirt
setblock ~169 ~123 ~108 dirt
setblock ~169 ~123 ~109 dirt
setblock ~169 ~123 ~110 dirt
setblock ~169 ~123 ~111 dirt
setblock ~169 ~123 ~112 dirt
setblock ~169 ~124 ~93 short_grass
setblock ~169 ~124 ~95 grass_block
setblock ~169 ~124 ~96 grass_block
setblock ~169 ~124 ~97 dirt
setblock ~169 ~124 ~98 dirt
setblock ~169 ~124 ~99 dirt
setblock ~169 ~124 ~100 dirt
setblock ~169 ~124 ~101 dirt
setblock ~169 ~124 ~107 dirt
setblock ~169 ~124 ~108 grass_block
setblock ~169 ~124 ~109 grass_block
setblock ~169 ~124 ~110 grass_block
setblock ~169 ~124 ~111 grass_block
setblock ~169 ~124 ~112 grass_block
setblock ~169 ~125 ~97 grass_block
setblock ~169 ~125 ~98 dirt
setblock ~169 ~125 ~99 dirt
setblock ~169 ~125 ~100 dirt
setblock ~169 ~125 ~101 dirt
setblock ~169 ~125 ~107 grass_block
setblock ~169 ~125 ~112 short_grass
setblock ~169 ~126 ~98 grass_block
setblock ~169 ~126 ~99 dirt
setblock ~169 ~126 ~100 dirt
setblock ~169 ~126 ~101 dirt
setblock ~169 ~127 ~99 dirt
setblock ~169 ~127 ~100 dirt
setblock ~169 ~127 ~101 dirt
setblock ~169 ~128 ~99 dirt
setblock ~169 ~128 ~100 dirt
setblock ~169 ~128 ~101 dirt
setblock ~169 ~129 ~99 grass_block
setblock ~169 ~129 ~100 dirt
setblock ~169 ~129 ~101 dirt
setblock ~169 ~130 ~99 poppy
setblock ~169 ~130 ~100 dirt
setblock ~169 ~130 ~101 grass_block
setblock ~169 ~131 ~100 grass_block
setblock ~169 ~131 ~101 fern
setblock ~169 ~132 ~100 fern
setblock ~170 ~118 ~94 dirt
setblock ~170 ~118 ~96 dirt
setblock ~170 ~119 ~93 dirt
setblock ~170 ~119 ~94 dirt
setblock ~170 ~119 ~96 dirt
setblock ~170 ~119 ~97 dirt
setblock ~170 ~120 ~92 dirt
setblock ~170 ~120 ~93 dirt
setblock ~170 ~120 ~94 dirt
setblock ~170 ~120 ~95 dirt
setblock ~170 ~120 ~96 dirt
setblock ~170 ~120 ~97 dirt
setblock ~170 ~120 ~98 dirt
setblock ~170 ~121 ~91 dirt
setblock ~170 ~121 ~92 dirt
setblock ~170 ~121 ~93 dirt
setblock ~170 ~121 ~94 dirt
setblock ~170 ~121 ~95 dirt
setblock ~170 ~121 ~96 dirt
setblock ~170 ~121 ~97 dirt
setblock ~170 ~121 ~98 dirt
setblock ~170 ~121 ~99 dirt
setblock ~170 ~121 ~108 dirt
setblock ~170 ~121 ~111 dirt
setblock ~170 ~122 ~91 grass_block
setblock ~170 ~122 ~92 grass_block
setblock ~170 ~122 ~93 grass_block
setblock ~170 ~122 ~94 dirt
setblock ~170 ~122 ~95 dirt
setblock ~170 ~122 ~96 dirt
setblock ~170 ~122 ~97 dirt
setblock ~170 ~122 ~98 dirt
setblock ~170 ~122 ~99 dirt
setblock ~170 ~122 ~108 dirt
setblock ~170 ~122 ~111 dirt
setblock ~170 ~123 ~93 short_grass
setblock ~170 ~123 ~94 grass_block
setblock ~170 ~123 ~95 grass_block
setblock ~170 ~123 ~96 dirt
setblock ~170 ~123 ~97 dirt
setblock ~170 ~123 ~98 dirt
setblock ~170 ~123 ~99 dirt
setblock ~170 ~123 ~108 dirt
setblock ~170 ~123 ~111 dirt
setblock ~170 ~124 ~96 grass_block
setblock ~170 ~124 ~97 dirt
setblock ~170 ~124 ~98 dirt
setblock ~170 ~124 ~99 dirt
setblock ~170 ~124 ~108 dirt
setblock ~170 ~124 ~111 grass_block
setblock ~170 ~125 ~97 grass_block
setblock ~170 ~125 ~98 dirt
setblock ~170 ~125 ~99 dirt
setblock ~170 ~125 ~108 grass_block
setblock ~170 ~126 ~97 short_grass
setblock ~170 ~126 ~98 dirt
setblock ~170 ~126 ~99 dirt
setblock ~170 ~127 ~98 grass_block
setblock ~170 ~127 ~99 dirt
setblock ~170 ~128 ~99 dirt
setblock ~170 ~129 ~99 dirt
setblock ~170 ~130 ~99 grass_block
setblock ~171 ~120 ~93 dirt
setblock ~171 ~120 ~94 dirt
setblock ~171 ~120 ~97 dirt
setblock ~171 ~121 ~92 dirt
setblock ~171 ~121 ~93 dirt
setblock ~171 ~121 ~94 dirt
setblock ~171 ~121 ~96 dirt
setblock ~171 ~121 ~97 dirt
setblock ~171 ~121 ~98 dirt
setblock ~171 ~122 ~92 grass_block
setblock ~171 ~122 ~93 dirt
setblock ~171 ~122 ~94 dirt
setblock ~171 ~122 ~96 dirt
setblock ~171 ~122 ~97 dirt
setblock ~171 ~122 ~98 dirt
setblock ~171 ~123 ~93 grass_block
setblock ~171 ~123 ~94 grass_block
setblock ~171 ~123 ~96 dirt
setblock ~171 ~123 ~97 dirt
setblock ~171 ~123 ~98 dirt
setblock ~171 ~124 ~93 fern
setblock ~171 ~124 ~94 short_grass
setblock ~171 ~124 ~96 grass_block
setblock ~171 ~124 ~97 dirt
setblock ~171 ~124 ~98 dirt
setblock ~171 ~125 ~97 grass_block
setblock ~171 ~125 ~98 dirt
setblock ~171 ~126 ~98 dirt
setblock ~171 ~127 ~98 grass_block
setblock ~171 ~128 ~98 short_grass
setblock ~172 ~121 ~93 dirt
setblock ~172 ~121 ~97 dirt
setblock ~172 ~122 ~93 dirt
setblock ~172 ~122 ~97 dirt
setblock ~172 ~123 ~93 grass_block
setblock ~172 ~123 ~97 dirt
setblock ~172 ~124 ~97 dirt
setblock ~172 ~125 ~97 dirt
setblock ~172 ~126 ~97 grass_block
setblock ~172 ~127 ~97 short_grass
setblock ~199 ~200 ~199 gold_block
