setblock ~38 ~123 ~102 dirt
setblock ~38 ~123 ~103 dirt
setblock ~38 ~123 ~104 dirt
setblock ~38 ~123 ~105 dirt
setblock ~38 ~123 ~106 dirt
setblock ~38 ~123 ~107 dirt
setblock ~38 ~123 ~108 dirt
setblock ~38 ~123 ~109 dirt
setblock ~38 ~123 ~110 dirt
setblock ~38 ~123 ~111 dirt
setblock ~38 ~123 ~119 short_grass
setblock ~38 ~123 ~123 grass_block
setblock ~38 ~123 ~124 grass_block
setblock ~38 ~123 ~125 grass_block
setblock ~38 ~123 ~126 grass_block
setblock ~38 ~123 ~127 dirt
setblock ~38 ~123 ~128 dirt
setblock ~38 ~123 ~129 dirt
setblock ~38 ~123 ~130 dirt
setblock ~38 ~123 ~131 dirt
setblock ~38 ~123 ~132 dirt
setblock ~38 ~123 ~133 dirt
setblock ~38 ~123 ~134 dirt
setblock ~38 ~123 ~135 dirt
setblock ~38 ~124 ~64 grass_block
setblock ~38 ~124 ~68 dirt
setblock ~38 ~124 ~69 dirt
setblock ~38 ~124 ~70 dirt
setblock ~38 ~124 ~71 dirt
setblock ~38 ~124 ~72 dirt
setblock ~38 ~124 ~73 dirt
setblock ~38 ~124 ~74 dirt
setblock ~38 ~124 ~75 dirt
setblock ~38 ~124 ~76 dirt
setblock ~38 ~124 ~77 dirt
setblock ~38 ~124 ~86 dirt
setblock ~38 ~124 ~87 dirt
setblock ~38 ~124 ~88 dirt
setblock ~38 ~124 ~89 dirt
setblock ~38 ~124 ~90 dirt
setblock ~38 ~124 ~91 dirt
setblock ~38 ~124 ~92 dirt
setblock ~38 ~124 ~93 dirt
setblock ~38 ~124 ~94 dirt
setblock ~38 ~124 ~95 dirt
setblock ~38 ~124 ~96 dirt
setblock ~38 ~124 ~97 dirt
setblock ~38 ~124 ~98 dirt
setblock ~38 ~124 ~99 dirt
setblock ~38 ~124 ~100 dirt
setblock ~38 ~124 ~101 dirt
setblock ~38 ~124 ~102 dirt
setblock ~38 ~124 ~103 dirt
setblock ~38 ~124 ~104 dirt
setblock ~38 ~124 ~105 dirt
setblock ~38 ~124 ~106 dirt
setblock ~38 ~124 ~107 dirt
setblock ~38 ~124 ~108 grass_block
setblock ~38 ~124 ~109 grass_block
setblock ~38 ~124 ~110 grass_block
setblock ~38 ~124 ~111 grass_block
setblock ~38 ~124 ~123 short_grass
setblock ~38 ~124 ~126 short_grass
setblock ~38 ~124 ~127 grass_block
setblock ~38 ~124 ~128 grass_block
setblock ~38 ~124 ~129 grass_block
setblock ~38 ~124 ~130 dirt
setblock ~38 ~124 ~131 dirt
setblock ~38 ~124 ~132 dirt
setblock ~38 ~124 ~133 dirt
setblock ~38 ~124 ~134 dirt
setblock ~38 ~124 ~135 dirt
setblock ~38 ~125 ~68 grass_block
setblock ~38 ~125 ~69 grass_block
setblock ~38 ~125 ~70 dirt
setblock ~38 ~125 ~71 dirt
setblock ~38 ~125 ~72 dirt
setblock ~38 ~125 ~73 dirt
setblock ~38 ~125 ~74 dirt
setblock ~38 ~125 ~75 dirt
setblock ~38 ~125 ~76 dirt
setblock ~38 ~125 ~77 dirt
setblock ~38 ~125 ~86 dirt
setblock ~38 ~125 ~87 dirt
setblock ~38 ~125 ~88 dirt
setblock ~38 ~125 ~89 dirt
setblock ~38 ~125 ~90 dirt
setblock ~38 ~125 ~91 dirt
setblock ~38 ~125 ~92 dirt
setblock ~38 ~125 ~93 dirt
setblock ~38 ~125 ~94 dirt
setblock ~38 ~125 ~95 dirt
setblock ~38 ~125 ~96 dirt
setblock ~38 ~125 ~97 dirt
setblock ~38 ~125 ~98 dirt
setblock ~38 ~125 ~99 dirt
setblock ~38 ~125 ~100 grass_block
setblock ~38 ~125 ~101 grass_block
setblock ~38 ~125 ~102 grass_block
setblock ~38 ~125 ~103 grass_block
setblock ~38 ~125 ~104 grass_block
setblock ~38 ~125 ~105 grass_block
setblock ~38 ~125 ~106 grass_block
setblock ~38 ~125 ~107 grass_block
setblock ~38 ~125 ~111 poppy
setblock ~38 ~125 ~130 grass_block
setblock ~38 ~125 ~131 grass_block
setblock ~38 ~125 ~132 grass_block
setblock ~38 ~125 ~133 grass_block
setblock ~38 ~125 ~134 dirt
setblock ~38 ~125 ~135 dirt
setblock ~38 ~126 ~68 short_grass
setblock ~38 ~126 ~70 grass_block
setblock ~38 ~126 ~71 grass_block
setblock ~38 ~126 ~72 grass_block
setblock ~38 ~126 ~73 grass_block
setblock ~38 ~126 ~74 grass_block
setblock ~38 ~126 ~75 grass_block
setblock ~38 ~126 ~76 dirt
setblock ~38 ~126 ~77 dirt
setblock ~38 ~126 ~86 dirt
setblock ~38 ~126 ~87 dirt
setblock ~38 ~126 ~88 dirt
setblock ~38 ~126 ~89 dirt
setblock ~38 ~126 ~90 dirt
setblock ~38 ~126 ~91 dirt
setblock ~38 ~126 ~92 dirt
setblock ~38 ~126 ~93 dirt
setblock ~38 ~126 ~94 dirt
setblock ~38 ~126 ~95 dirt
setblock ~38 ~126 ~96 grass_block
setblock ~38 ~126 ~97 grass_block
setblock ~38 ~126 ~98 grass_block
setblock ~38 ~126 ~99 grass_block
setblock ~38 ~126 ~104 short_grass
setblock ~38 ~126 ~106 short_grass
setblock ~38 ~126 ~107 short_grass
setblock ~38 ~126 ~130 short_grass
setblock ~38 ~126 ~134 grass_block
setblock ~38 ~126 ~135 grass_block
setblock ~38 ~127 ~72 short_grass
setblock ~38 ~127 ~73 short_grass
setblock ~38 ~127 ~76 grass_block
setblock ~38 ~127 ~77 grass_block
setblock ~38 ~127 ~86 grass_block
setblock ~38 ~127 ~87 dirt
setblock ~38 ~127 ~88 dirt
setblock ~38 ~127 ~89 dirt
setblock ~38 ~127 ~90 dirt
setblock ~38 ~127 ~91 grass_block
setblock ~38 ~127 ~92 grass_block
setblock ~38 ~127 ~93 grass_block
setblock ~38 ~127 ~94 grass_block
setblock ~38 ~127 ~95 grass_block
setblock ~38 ~127 ~97 short_grass
setblock ~38 ~127 ~98 short_grass
setblock ~38 ~127 ~99 short_grass
setblock ~38 ~127 ~134 short_grass
setblock ~38 ~128 ~87 grass_block
setblock ~38 ~128 ~88 grass_block
setblock ~38 ~128 ~89 grass_block
setblock ~38 ~128 ~90 grass_block
setblock ~38 ~128 ~92 short_grass
setblock ~38 ~129 ~89 short_grass
setblock ~39 ~104 ~98 dirt
setblock ~39 ~105 ~97 dirt
setblock ~39 ~105 ~98 dirt
setblock ~39 ~106 ~96 dirt
setblock ~39 ~106 ~97 dirt
setblock ~39 ~106 ~98 dirt
setblock ~39 ~106 ~99 dirt
setblock ~39 ~106 ~100 dirt
setblock ~39 ~107 ~96 dirt
setblock ~39 ~107 ~97 dirt
setblock ~39 ~107 ~98 dirt
setblock ~39 ~107 ~99 dirt
setblock ~39 ~107 ~100 dirt
setblock ~39 ~107 ~102 dirt
setblock ~39 ~108 ~94 dirt
setblock ~39 ~108 ~95 dirt
setblock ~39 ~108 ~96 dirt
setblock ~39 ~108 ~97 dirt
setblock ~39 ~108 ~98 dirt
setblock ~39 ~108 ~99 dirt
setblock ~39 ~108 ~100 dirt
setblock ~39 ~108 ~101 dirt
setblock ~39 ~108 ~102 dirt
setblock ~39 ~108 ~104 dirt
setblock ~39 ~109 ~93 dirt
setblock ~39 ~109 ~94 dirt
setblock ~39 ~109 ~95 dirt
setblock ~39 ~109 ~96 dirt
setblock ~39 ~109 ~97 dirt
setblock ~39 ~109 ~98 dirt
setblock ~39 ~109 ~99 dirt
setblock ~39 ~109 ~100 dirt
setblock ~39 ~109 ~101 dirt
setblock ~39 ~109 ~102 dirt
setblock ~39 ~109 ~103 dirt
setblock ~39 ~109 ~104 dirt
setblock ~39 ~109 ~105 dirt
setblock ~39 ~110 ~93 dirt
setblock ~39 ~110 ~94 dirt
setblock ~39 ~110 ~95 dirt
setblock ~39 ~110 ~96 dirt
setblock ~39 ~110 ~97 dirt
setblock ~39 ~110 ~98 dirt
setblock ~39 ~110 ~99 dirt
setblock ~39 ~110 ~100 dirt
setblock ~39 ~110 ~101 dirt
setblock ~39 ~110 ~102 dirt
setblock ~39 ~110 ~103 dirt
setblock ~39 ~110 ~104 dirt
setblock ~39 ~110 ~105 dirt
setblock ~39 ~110 ~106 dirt
setblock ~39 ~111 ~92 dirt
setblock ~39 ~111 ~93 dirt
setblock ~39 ~111 ~94 dirt
setblock ~39 ~111 ~95 dirt
setblock ~39 ~111 ~96 dirt
setblock ~39 ~111 ~97 dirt
setblock ~39 ~111 ~98 dirt
setblock ~39 ~111 ~99 dirt
setblock ~39 ~111 ~100 dirt
setblock ~39 ~111 ~101 dirt
setblock ~39 ~111 ~102 dirt
setblock ~39 ~111 ~103 dirt
setblock ~39 ~111 ~104 dirt
setblock ~39 ~111 ~105 dirt
setblock ~39 ~111 ~106 dirt
setblock ~39 ~111 ~107 dirt
setblock ~39 ~112 ~91 dirt
setblock ~39 ~112 ~92 dirt
setblock ~39 ~112 ~93 dirt
setblock ~39 ~112 ~94 dirt
setblock ~39 ~112 ~95 dirt
setblock ~39 ~112 ~96 dirt
setblock ~39 ~112 ~97 dirt
setblock ~39 ~112 ~98 dirt
setblock ~39 ~112 ~99 dirt
setblock ~39 ~112 ~100 dirt
setblock ~39 ~112 ~101 dirt
setblock ~39 ~112 ~102 dirt
setblock ~39 ~112 ~103 dirt
setblock ~39 ~112 ~104 dirt
setblock ~39 ~112 ~105 dirt
setblock ~39 ~112 ~106 dirt
setblock ~39 ~112 ~107 dirt
setblock ~39 ~113 ~91 dirt
setblock ~39 ~113 ~92 dirt
setblock ~39 ~113 ~93 dirt
setblock ~39 ~113 ~94 dirt
setblock ~39 ~113 ~95 dirt
setblock ~39 ~113 ~96 dirt
setblock ~39 ~113 ~97 dirt
setblock ~39 ~113 ~98 dirt
setblock ~39 ~113 ~99 dirt
setblock ~39 ~113 ~100 dirt
setblock ~39 ~113 ~101 dirt
setblock ~39 ~113 ~102 dirt
setblock ~39 ~113 ~103 dirt
setblock ~39 ~113 ~104 dirt
setblock ~39 ~113 ~105 dirt
setblock ~39 ~113 ~106 dirt
setblock ~39 ~113 ~107 dirt
setblock ~39 ~113 ~128 dirt
setblock ~39 ~114 ~90 dirt
setblock ~39 ~114 ~91 dirt
setblock ~39 ~114 ~92 dirt
setblock ~39 ~114 ~93 dirt
setblock ~39 ~114 ~94 dirt
setblock ~39 ~114 ~95 dirt
setblock ~39 ~114 ~96 dirt
setblock ~39 ~114 ~97 dirt
setblock ~39 ~114 ~98 dirt
setblock ~39 ~114 ~99 dirt
setblock ~39 ~114 ~100 dirt
setblock ~39 ~114 ~101 dirt
setblock ~39 ~114 ~102 dirt
setblock ~39 ~114 ~103 dirt
setblock ~39 ~114 ~104 dirt
setblock ~39 ~114 ~105 dirt
setblock ~39 ~114 ~106 dirt
setblock ~39 ~114 ~107 dirt
setblock ~39 ~114 ~108 dirt
setblock ~39 ~114 ~126 dirt
setblock ~39 ~114 ~128 dirt
setblock ~39 ~114 ~129 dirt
setblock ~39 ~115 ~89 dirt
setblock ~39 ~115 ~90 dirt
setblock ~39 ~115 ~91 dirt
setblock ~39 ~115 ~92 dirt
setblock ~39 ~115 ~93 dirt
setblock ~39 ~115 ~94 dirt
setblock ~39 ~115 ~95 dirt
setblock ~39 ~115 ~96 dirt
setblock ~39 ~115 ~97 dirt
setblock ~39 ~115 ~98 dirt
setblock ~39 ~115 ~99 dirt
setblock ~39 ~115 ~100 dirt
setblock ~39 ~115 ~101 dirt
setblock ~39 ~115 ~102 dirt
setblock ~39 ~115 ~103 dirt
setblock ~39 ~115 ~104 dirt
setblock ~39 ~115 ~105 dirt
setblock ~39 ~115 ~106 dirt
setblock ~39 ~115 ~107 dirt
setblock ~39 ~115 ~108 dirt
setblock ~39 ~115 ~124 dirt
setblock ~39 ~115 ~126 dirt
setblock ~39 ~115 ~128 dirt
setblock ~39 ~115 ~129 dirt
setblock ~39 ~115 ~130 dirt
setblock ~39 ~116 ~88 dirt
setblock ~39 ~116 ~89 dirt
setblock ~39 ~116 ~90 dirt
setblock ~39 ~116 ~91 dirt
setblock ~39 ~116 ~92 dirt
setblock ~39 ~116 ~93 dirt
setblock ~39 ~116 ~94 dirt
setblock ~39 ~116 ~95 dirt
setblock ~39 ~116 ~96 dirt
setblock ~39 ~116 ~97 dirt
setblock ~39 ~116 ~98 dirt
setblock ~39 ~116 ~99 dirt
setblock ~39 ~116 ~100 dirt
setblock ~39 ~116 ~101 dirt
setblock ~39 ~116 ~102 dirt
setblock ~39 ~116 ~103 dirt
setblock ~39 ~116 ~104 dirt
setblock ~39 ~116 ~105 dirt
setblock ~39 ~116 ~106 dirt
setblock ~39 ~116 ~107 dirt
setblock ~39 ~116 ~108 dirt
setblock ~39 ~116 ~109 dirt
setblock ~39 ~116 ~123 dirt
setblock ~39 ~116 ~124 dirt
setblock ~39 ~116 ~125 dirt
setblock ~39 ~116 ~126 dirt
setblock ~39 ~116 ~127 dirt
setblock ~39 ~116 ~128 dirt
setblock ~39 ~116 ~129 dirt
setblock ~39 ~116 ~130 dirt
setblock ~39 ~116 ~131 dirt
setblock ~39 ~116 ~132 dirt
setblock ~39 ~116 ~133 dirt
setblock ~39 ~117 ~71 dirt
setblock ~39 ~117 ~72 dirt
setblock ~39 ~117 ~73 dirt
setblock ~39 ~117 ~74 dirt
setblock ~39 ~117 ~75 dirt
setblock ~39 ~117 ~87 dirt
setblock ~39 ~117 ~88 dirt
setblock ~39 ~117 ~89 dirt
setblock ~39 ~117 ~90 dirt
setblock ~39 ~117 ~91 dirt
setblock ~39 ~117 ~92 dirt
setblock ~39 ~117 ~93 dirt
setblock ~39 ~117 ~94 dirt
setblock ~39 ~117 ~95 dirt
setblock ~39 ~117 ~96 dirt
setblock ~39 ~117 ~97 dirt
setblock ~39 ~117 ~98 dirt
setblock ~39 ~117 ~99 dirt
setblock ~39 ~117 ~100 dirt
setblock ~39 ~117 ~101 dirt
setblock ~39 ~117 ~102 dirt
setblock ~39 ~117 ~103 dirt
setblock ~39 ~117 ~104 dirt
setblock ~39 ~117 ~105 dirt
setblock ~39 ~117 ~106 dirt
setblock ~39 ~117 ~107 dirt
setblock ~39 ~117 ~108 dirt
setblock ~39 ~117 ~109 dirt
setblock ~39 ~117 ~120 dirt
setblock ~39 ~117 ~121 dirt
setblock ~39 ~117 ~122 dirt
setblock ~39 ~117 ~123 dirt
setblock ~39 ~117 ~124 dirt
setblock ~39 ~117 ~125 dirt
setblock ~39 ~117 ~126 dirt
setblock ~39 ~117 ~127 dirt
setblock ~39 ~117 ~128 dirt
setblock ~39 ~117 ~129 dirt
setblock ~39 ~117 ~130 dirt
setblock ~39 ~117 ~131 dirt
setblock ~39 ~117 ~132 dirt
setblock ~39 ~117 ~133 dirt
setblock ~39 ~117 ~134 dirt
setblock ~39 ~118 ~69 dirt
setblock ~39 ~118 ~70 dirt
setblock ~39 ~118 ~71 dirt
setblock ~39 ~118 ~72 dirt
setblock ~39 ~118 ~73 dirt
setblock ~39 ~118 ~74 dirt
setblock ~39 ~118 ~75 dirt
setblock ~39 ~118 ~87 dirt
setblock ~39 ~118 ~88 dirt
setblock ~39 ~118 ~89 dirt
setblock ~39 ~118 ~90 dirt
setblock ~39 ~118 ~91 dirt
setblock ~39 ~118 ~92 dirt
setblock ~39 ~118 ~93 dirt
setblock ~39 ~118 ~94 dirt
setblock ~39 ~118 ~95 dirt
setblock ~39 ~118 ~96 dirt
setblock ~39 ~118 ~97 dirt
setblock ~39 ~118 ~98 dirt
setblock ~39 ~118 ~99 dirt
setblock ~39 ~118 ~100 dirt
setblock ~39 ~118 ~101 dirt
setblock ~39 ~118 ~102 dirt
setblock ~39 ~118 ~103 dirt
setblock ~39 ~118 ~104 dirt
setblock ~39 ~118 ~105 dirt
setblock ~39 ~118 ~106 dirt
setblock ~39 ~118 ~107 dirt
setblock ~39 ~118 ~108 dirt
setblock ~39 ~118 ~109 dirt
setblock ~39 ~118 ~119 dirt
setblock ~39 ~118 ~120 dirt
setblock ~39 ~118 ~121 dirt
setblock ~39 ~118 ~122 dirt
setblock ~39 ~118 ~123 dirt
setblock ~39 ~118 ~124 dirt
setblock ~39 ~118 ~125 dirt
setblock ~39 ~118 ~126 dirt
setblock ~39 ~118 ~127 dirt
setblock ~39 ~118 ~128 dirt
setblock ~39 ~118 ~129 dirt
setblock ~39 ~118 ~130 dirt
setblock ~39 ~118 ~131 dirt
setblock ~39 ~118 ~132 dirt
setblock ~39 ~118 ~133 dirt
setblock ~39 ~118 ~134 dirt
setblock ~39 ~119 ~69 dirt
setblock ~39 ~119 ~70 dirt
setblock ~39 ~119 ~71 dirt
setblock ~39 ~119 ~72 dirt
setblock ~39 ~119 ~73 dirt
setblock ~39 ~119 ~74 dirt
setblock ~39 ~119 ~75 dirt
setblock ~39 ~119 ~76 dirt
setblock ~39 ~119 ~86 dirt
setblock ~39 ~119 ~87 dirt
setblock ~39 ~119 ~88 dirt
setblock ~39 ~119 ~89 dirt
setblock ~39 ~119 ~90 dirt
setblock ~39 ~119 ~91 dirt
setblock ~39 ~119 ~92 dirt
setblock ~39 ~119 ~93 dirt
setblock ~39 ~119 ~94 dirt
setblock ~39 ~119 ~95 dirt
setblock ~39 ~119 ~96 dirt
setblock ~39 ~119 ~97 dirt
setblock ~39 ~119 ~98 dirt
setblock ~39 ~119 ~99 dirt
setblock ~39 ~119 ~100 dirt
setblock ~39 ~119 ~101 dirt
setblock ~39 ~119 ~102 dirt
setblock ~39 ~119 ~103 dirt
setblock ~39 ~119 ~104 dirt
setblock ~39 ~119 ~105 dirt
setblock ~39 ~119 ~106 dirt
setblock ~39 ~119 ~107 dirt
setblock ~39 ~119 ~108 dirt
setblock ~39 ~119 ~109 dirt
setblock ~39 ~119 ~110 dirt
setblock ~39 ~119 ~119 dirt
setblock ~39 ~119 ~120 dirt
setblock ~39 ~119 ~121 dirt
setblock ~39 ~119 ~122 dirt
setblock ~39 ~119 ~123 dirt
setblock ~39 ~119 ~124 dirt
setblock ~39 ~119 ~125 dirt
setblock ~39 ~119 ~126 dirt
setblock ~39 ~119 ~127 dirt
setblock ~39 ~119 ~128 dirt
setblock ~39 ~119 ~129 dirt
setblock ~39 ~119 ~130 dirt
setblock ~39 ~119 ~131 dirt
setblock ~39 ~119 ~132 dirt
setblock ~39 ~119 ~133 dirt
setblock ~39 ~119 ~134 dirt
setblock ~39 ~120 ~64 dirt
setblock ~39 ~120 ~67 dirt
setblock ~39 ~120 ~68 dirt
setblock ~39 ~120 ~69 dirt
setblock ~39 ~120 ~70 dirt
setblock ~39 ~120 ~71 dirt
setblock ~39 ~120 ~72 dirt
setblock ~39 ~120 ~73 dirt
setblock ~39 ~120 ~74 dirt
setblock ~39 ~120 ~75 dirt
setblock ~39 ~120 ~76 dirt
setblock ~39 ~120 ~77 dirt
setblock ~39 ~120 ~80 dirt
setblock ~39 ~120 ~85 dirt
setblock ~39 ~120 ~86 dirt
setblock ~39 ~120 ~87 dirt
setblock ~39 ~120 ~88 dirt
setblock ~39 ~120 ~89 dirt
setblock ~39 ~120 ~90 dirt
setblock ~39 ~120 ~91 dirt
setblock ~39 ~120 ~92 dirt
setblock ~39 ~120 ~93 dirt
setblock ~39 ~120 ~94 dirt
setblock ~39 ~120 ~95 dirt
setblock ~39 ~120 ~96 dirt
setblock ~39 ~120 ~97 dirt
setblock ~39 ~120 ~98 dirt
setblock ~39 ~120 ~99 dirt
setblock ~39 ~120 ~100 dirt
setblock ~39 ~120 ~101 dirt
setblock ~39 ~120 ~102 dirt
setblock ~39 ~120 ~103 dirt
setblock ~39 ~120 ~104 dirt
setblock ~39 ~120 ~105 dirt
setblock ~39 ~120 ~106 dirt
setblock ~39 ~120 ~107 dirt
setblock ~39 ~120 ~108 dirt
setblock ~39 ~120 ~109 dirt
setblock ~39 ~120 ~110 dirt
setblock ~39 ~120 ~111 dirt
setblock ~39 ~120 ~118 dirt
setblock ~39 ~120 ~119 dirt
setblock ~39 ~120 ~120 dirt
setblock ~39 ~120 ~121 dirt
setblock ~39 ~120 ~122 dirt
setblock ~39 ~120 ~123 dirt
setblock ~39 ~120 ~124 dirt
setblock ~39 ~120 ~125 dirt
setblock ~39 ~120 ~126 dirt
setblock ~39 ~120 ~127 dirt
setblock ~39 ~120 ~128 dirt
setblock ~39 ~120 ~129 dirt
setblock ~39 ~120 ~130 dirt
setblock ~39 ~120 ~131 dirt
setblock ~39 ~120 ~132 dirt
setblock ~39 ~120 ~133 dirt
setblock ~39 ~120 ~134 dirt
setblock ~39 ~120 ~135 dirt
setblock ~39 ~120 ~136 dirt
setblock ~39 ~121 ~63 dirt
setblock ~39 ~121 ~64 dirt
setblock ~39 ~121 ~65 dirt
setblock ~39 ~121 ~67 dirt
setblock ~39 ~121 ~68 dirt
setblock ~39 ~121 ~69 dirt
setblock ~39 ~121 ~70 dirt
setblock ~39 ~121 ~71 dirt
setblock ~39 ~121 ~72 dirt
setblock ~39 ~121 ~73 dirt
setblock ~39 ~121 ~74 dirt
setblock ~39 ~121 ~75 dirt
setblock ~39 ~121 ~76 dirt
setblock ~39 ~121 ~77 dirt
setblock ~39 ~121 ~80 dirt
setblock ~39 ~121 ~81 dirt
setblock ~39 ~121 ~82 dirt
setblock ~39 ~121 ~84 dirt
setblock ~39 ~121 ~85 dirt
setblock ~39 ~121 ~86 dirt
setblock ~39 ~121 ~87 dirt
setblock ~39 ~121 ~88 dirt
setblock ~39 ~121 ~89 dirt
setblock ~39 ~121 ~90 dirt
setblock ~39 ~121 ~91 dirt
setblock ~39 ~121 ~92 dirt
setblock ~39 ~121 ~93 dirt
setblock ~39 ~121 ~94 dirt
setblock ~39 ~121 ~95 dirt
setblock ~39 ~121 ~96 dirt
setblock ~39 ~121 ~97 dirt
setblock ~39 ~121 ~98 dirt
setblock ~39 ~121 ~99 dirt
setblock ~39 ~121 ~100 dirt
setblock ~39 ~121 ~101 dirt
setblock ~39 ~121 ~102 dirt
setblock ~39 ~121 ~103 dirt
setblock ~39 ~121 ~104 dirt
setblock ~39 ~121 ~105 dirt
setblock ~39 ~121 ~106 dirt
setblock ~39 ~121 ~107 dirt
setblock ~39 ~121 ~108 dirt
setblock ~39 ~121 ~109 dirt
setblock ~39 ~121 ~110 dirt
setblock ~39 ~121 ~111 dirt
setblock ~39 ~121 ~112 dirt
setblock ~39 ~121 ~116 dirt
setblock ~39 ~121 ~117 dirt
setblock ~39 ~121 ~118 dirt
setblock ~39 ~121 ~119 dirt
setblock ~39 ~121 ~120 dirt
setblock ~39 ~121 ~121 dirt
setblock ~39 ~121 ~122 dirt
setblock ~39 ~121 ~123 dirt
setblock ~39 ~121 ~124 dirt
setblock ~39 ~121 ~125 dirt
setblock ~39 ~121 ~126 dirt
setblock ~39 ~121 ~127 dirt
setblock ~39 ~121 ~128 dirt
setblock ~39 ~121 ~129 dirt
setblock ~39 ~121 ~130 dirt
setblock ~39 ~121 ~131 dirt
setblock ~39 ~121 ~132 dirt
setblock ~39 ~121 ~133 dirt
setblock ~39 ~121 ~134 dirt
setblock ~39 ~121 ~135 dirt
setblock ~39 ~121 ~136 dirt
setblock ~39 ~122 ~63 dirt
setblock ~39 ~122 ~64 dirt
setblock ~39 ~122 ~65 dirt
setblock ~39 ~122 ~67 dirt
setblock ~39 ~122 ~68 dirt
setblock ~39 ~122 ~69 dirt
setblock ~39 ~122 ~70 dirt
setblock ~39 ~122 ~71 dirt
setblock ~39 ~122 ~72 dirt
setblock ~39 ~122 ~73 dirt
setblock ~39 ~122 ~74 dirt
setblock ~39 ~122 ~75 dirt
setblock ~39 ~122 ~76 dirt
setblock ~39 ~122 ~77 dirt
setblock ~39 ~122 ~80 dirt
setblock ~39 ~122 ~81 dirt
setblock ~39 ~122 ~82 dirt
setblock ~39 ~122 ~84 dirt
setblock ~39 ~122 ~85 dirt
setblock ~39 ~122 ~86 dirt
setblock ~39 ~122 ~87 dirt
setblock ~39 ~122 ~88 dirt
setblock ~39 ~122 ~89 dirt
setblock ~39 ~122 ~90 dirt
setblock ~39 ~122 ~91 dirt
setblock ~39 ~122 ~92 dirt
setblock ~39 ~122 ~93 dirt
setblock ~39 ~122 ~94 dirt
setblock ~39 ~122 ~95 dirt
setblock ~39 ~122 ~96 dirt
setblock ~39 ~122 ~97 dirt
setblock ~39 ~122 ~98 dirt
setblock ~39 ~122 ~99 dirt
setblock ~39 ~122 ~100 dirt
setblock ~39 ~122 ~101 dirt
setblock ~39 ~122 ~102 dirt
setblock ~39 ~122 ~103 dirt
setblock ~39 ~122 ~104 dirt
setblock ~39 ~122 ~105 dirt
setblock ~39 ~122 ~106 dirt
setblock ~39 ~122 ~107 dirt
setblock ~39 ~122 ~108 dirt
setblock ~39 ~122 ~109 dirt
setblock ~39 ~122 ~110 dirt
setblock ~39 ~122 ~111 dirt
setblock ~39 ~122 ~112 dirt
setblock ~39 ~122 ~116 dirt
setblock ~39 ~122 ~117 dirt
setblock ~39 ~122 ~118 grass_block
setblock ~39 ~122 ~119 grass_block
setblock ~39 ~122 ~120 grass_block
setblock ~39 ~122 ~121 grass_block
setblock ~39 ~122 ~122 grass_block
setblock ~39 ~122 ~123 grass_block
setblock ~39 ~122 ~124 dirt
setblock ~39 ~122 ~125 dirt
setblock ~39 ~122 ~126 dirt
setblock ~39 ~122 ~127 dirt
setblock ~39 ~122 ~128 dirt
setblock ~39 ~122 ~129 dirt
setblock ~39 ~122 ~130 dirt
setblock ~39 ~122 ~131 dirt
setblock ~39 ~122 ~132 dirt
setblock ~39 ~122 ~133 dirt
setblock ~39 ~122 ~134 dirt
setblock ~39 ~122 ~135 dirt
setblock ~39 ~122 ~136 dirt
setblock ~39 ~123 ~63 grass_block
setblock ~39 ~123 ~64 dirt
setblock ~39 ~123 ~65 dirt
setblock ~39 ~123 ~67 dirt
setblock ~39 ~123 ~68 dirt
setblock ~39 ~123 ~69 dirt
setblock ~39 ~123 ~70 dirt
setblock ~39 ~123 ~71 dirt
setblock ~39 ~123 ~72 dirt
setblock ~39 ~123 ~73 dirt
setblock ~39 ~123 ~74 dirt
setblock ~39 ~123 ~75 dirt
setblock ~39 ~123 ~76 dirt
setblock ~39 ~123 ~77 dirt
setblock ~39 ~123 ~80 dirt
setblock ~39 ~123 ~81 dirt
setblock ~39 ~123 ~82 dirt
setblock ~39 ~123 ~84 dirt
setblock ~39 ~123 ~85 dirt
setblock ~39 ~123 ~86 dirt
setblock ~39 ~123 ~87 dirt
setblock ~39 ~123 ~88 dirt
setblock ~39 ~123 ~89 dirt
setblock ~39 ~123 ~90 dirt
setblock ~39 ~123 ~91 dirt
setblock ~39 ~123 ~92 dirt
setblock ~39 ~123 ~93 dirt
setblock ~39 ~123 ~94 dirt
setblock ~39 ~123 ~95 dirt
setblock ~39 ~123 ~96 dirt
setblock ~39 ~123 ~97 dirt
setblock ~39 ~123 ~98 dirt
setblock ~39 ~123 ~99 dirt
setblock ~39 ~123 ~100 dirt
setblock ~39 ~123 ~101 dirt
setblock ~39 ~123 ~102 dirt
setblock ~39 ~123 ~103 dirt
setblock ~39 ~123 ~104 dirt
setblock ~39 ~123 ~105 dirt
setblock ~39 ~123 ~106 dirt
setblock ~39 ~123 ~107 dirt
setblock ~39 ~123 ~108 dirt
setblock ~39 ~123 ~109 dirt
setblock ~39 ~123 ~110 dirt
setblock ~39 ~123 ~111 grass_block
setblock ~39 ~123 ~112 grass_block
setblock ~39 ~123 ~116 grass_block
setblock ~39 ~123 ~117 grass_block
setblock ~39 ~123 ~118 short_grass
setblock ~39 ~123 ~124 grass_block
setblock ~39 ~123 ~125 grass_block
setblock ~39 ~123 ~126 grass_block
setblock ~39 ~123 ~127 grass_block
setblock ~39 ~123 ~128 dirt
setblock ~39 ~123 ~129 dirt
setblock ~39 ~123 ~130 dirt
setblock ~39 ~123 ~131 dirt
setblock ~39 ~123 ~132 dirt
setblock ~39 ~123 ~133 dirt
setblock ~39 ~123 ~134 dirt
setblock ~39 ~123 ~135 dirt
setblock ~39 ~123 ~136 dirt
setblock ~39 ~124 ~64 grass_block
setblock ~39 ~124 ~65 grass_block
setblock ~39 ~124 ~67 dirt
setblock ~39 ~124 ~68 dirt
setblock ~39 ~124 ~69 dirt
setblock ~39 ~124 ~70 dirt
setblock ~39 ~124 ~71 dirt
setblock ~39 ~124 ~72 dirt
setblock ~39 ~124 ~73 dirt
setblock ~39 ~124 ~74 dirt
setblock ~39 ~124 ~75 dirt
setblock ~39 ~124 ~76 dirt
setblock ~39 ~124 ~77 dirt
setblock ~39 ~124 ~80 dirt
setblock ~39 ~124 ~81 dirt
setblock ~39 ~124 ~82 dirt
setblock ~39 ~124 ~84 dirt
setblock ~39 ~124 ~85 dirt
setblock ~39 ~124 ~86 dirt
setblock ~39 ~124 ~87 dirt
setblock ~39 ~124 ~88 dirt
setblock ~39 ~124 ~89 dirt
setblock ~39 ~124 ~90 dirt
setblock ~39 ~124 ~91 dirt
setblock ~39 ~124 ~92 dirt
setblock ~39 ~124 ~93 dirt
setblock ~39 ~124 ~94 dirt
setblock ~39 ~124 ~95 dirt
setblock ~39 ~124 ~96 dirt
setblock ~39 ~124 ~97 dirt
setblock ~39 ~124 ~98 dirt
setblock ~39 ~124 ~99 dirt
setblock ~39 ~124 ~100 dirt
setblock ~39 ~124 ~101 dirt
setblock ~39 ~124 ~102 dirt
setblock ~39 ~124 ~103 dirt
setblock ~39 ~124 ~104 dirt
setblock ~39 ~124 ~105 dirt
setblock ~39 ~124 ~106 dirt
setblock ~39 ~124 ~107 grass_block
setblock ~39 ~124 ~108 grass_block
setblock ~39 ~124 ~109 grass_block
setblock ~39 ~124 ~110 grass_block
setblock ~39 ~124 ~111 short_grass
setblock ~39 ~124 ~112 short_grass
setblock ~39 ~124 ~116 short_grass
setblock ~39 ~124 ~117 short_grass
setblock ~39 ~124 ~127 short_grass
setblock ~39 ~124 ~128 grass_block
setblock ~39 ~124 ~129 grass_block
setblock ~39 ~124 ~130 grass_block
setblock ~39 ~124 ~131 dirt
setblock ~39 ~124 ~132 dirt
setblock ~39 ~124 ~133 dirt
setblock ~39 ~124 ~134 dirt
setblock ~39 ~124 ~135 dirt
setblock ~39 ~124 ~136 dirt
setblock ~39 ~125 ~67 grass_block
setblock ~39 ~125 ~68 grass_block
setblock ~39 ~125 ~69 grass_block
setblock ~39 ~125 ~70 grass_block
setblock ~39 ~125 ~71 dirt
setblock ~39 ~125 ~72 dirt
setblock ~39 ~125 ~73 dirt
setblock ~39 ~125 ~74 dirt
setblock ~39 ~125 ~75 dirt
setblock ~39 ~125 ~76 dirt
setblock ~39 ~125 ~77 dirt
setblock ~39 ~125 ~80 dirt
setblock ~39 ~125 ~81 dirt
setblock ~39 ~125 ~82 dirt
setblock ~39 ~125 ~84 dirt
setblock ~39 ~125 ~85 dirt
setblock ~39 ~125 ~86 dirt
setblock ~39 ~125 ~87 dirt
setblock ~39 ~125 ~88 dirt
setblock ~39 ~125 ~89 dirt
setblock ~39 ~125 ~90 dirt
setblock ~39 ~125 ~91 dirt
setblock ~39 ~125 ~92 dirt
setblock ~39 ~125 ~93 dirt
setblock ~39 ~125 ~94 dirt
setblock ~39 ~125 ~95 dirt
setblock ~39 ~125 ~96 dirt
setblock ~39 ~125 ~97 dirt
setblock ~39 ~125 ~98 dirt
setblock ~39 ~125 ~99 dirt
setblock ~39 ~125 ~100 grass_block
setblock ~39 ~125 ~101 grass_block
setblock ~39 ~125 ~102 grass_block
setblock ~39 ~125 ~103 grass_block
setblock ~39 ~125 ~104 grass_block
setblock ~39 ~125 ~105 grass_block
setblock ~39 ~125 ~106 grass_block
setblock ~39 ~125 ~108 short_grass
setblock ~39 ~125 ~110 short_grass
setblock ~39 ~125 ~128 fern
setblock ~39 ~125 ~129 short_grass
setblock ~39 ~125 ~131 grass_block
setblock ~39 ~125 ~132 grass_block
setblock ~39 ~125 ~133 grass_block
setblock ~39 ~125 ~134 grass_block
setblock ~39 ~125 ~135 grass_block
setblock ~39 ~125 ~136 grass_block
setblock ~39 ~126 ~71 grass_block
setblock ~39 ~126 ~72 grass_block
setblock ~39 ~126 ~73 grass_block
setblock ~39 ~126 ~74 grass_block
setblock ~39 ~126 ~75 grass_block
setblock ~39 ~126 ~76 grass_block
setblock ~39 ~126 ~77 grass_block
setblock ~39 ~126 ~80 dirt
setblock ~39 ~126 ~81 dirt
setblock ~39 ~126 ~82 dirt
setblock ~39 ~126 ~84 dirt
setblock ~39 ~126 ~85 dirt
setblock ~39 ~126 ~86 dirt
setblock ~39 ~126 ~87 dirt
setblock ~39 ~126 ~88 dirt
setblock ~39 ~126 ~89 dirt
setblock ~39 ~126 ~90 dirt
setblock ~39 ~126 ~91 dirt
setblock ~39 ~126 ~92 dirt
setblock ~39 ~126 ~93 dirt
setblock ~39 ~126 ~94 dirt
setblock ~39 ~126 ~95 dirt
setblock ~39 ~126 ~96 dirt
setblock ~39 ~126 ~97 grass_block
setblock ~39 ~126 ~98 grass_block
setblock ~39 ~126 ~99 grass_block
setblock ~39 ~126 ~104 short_grass
setblock ~39 ~126 ~105 short_grass
setblock ~39 ~126 ~106 poppy
setblock ~39 ~126 ~134 short_grass
setblock ~39 ~126 ~135 short_grass
setblock ~39 ~127 ~75 short_grass
setblock ~39 ~127 ~80 grass_block
setblock ~39 ~127 ~81 grass_block
setblock ~39 ~127 ~82 grass_block
setblock ~39 ~127 ~84 grass_block
setblock ~39 ~127 ~85 dirt
setblock ~39 ~127 ~86 dirt
setblock ~39 ~127 ~87 dirt
setblock ~39 ~127 ~88 dirt
setblock ~39 ~127 ~89 dirt
setblock ~39 ~127 ~90 dirt
setblock ~39 ~127 ~91 dirt
setblock ~39 ~127 ~92 dirt
setblock ~39 ~127 ~93 dirt
setblock ~39 ~127 ~94 grass_block
setblock ~39 ~127 ~95 grass_block
setblock ~39 ~127 ~96 grass_block
setblock ~39 ~127 ~97 short_grass
setblock ~39 ~127 ~98 short_grass
setblock ~39 ~127 ~99 short_grass
setblock ~39 ~128 ~80 short_grass
setblock ~39 ~128 ~84 fern
setblock ~39 ~128 ~85 grass_block
setblock ~39 ~128 ~86 grass_block
setblock ~39 ~128 ~87 grass_block
setblock ~39 ~128 ~88 grass_block
setblock ~39 ~128 ~89 grass_block
setblock ~39 ~128 ~90 grass_block
setblock ~39 ~128 ~91 grass_block
setblock ~39 ~128 ~92 grass_block
setblock ~39 ~128 ~93 grass_block
setblock ~39 ~128 ~95 short_grass
setblock ~39 ~129 ~90 short_grass
setblock ~39 ~129 ~93 short_grass
setblock ~40 ~103 ~98 dirt
setblock ~40 ~103 ~100 dirt
setblock ~40 ~104 ~97 dirt
setblock ~40 ~104 ~98 dirt
setblock ~40 ~104 ~99 dirt
setblock ~40 ~104 ~100 dirt
setblock ~40 ~104 ~101 dirt
setblock ~40 ~105 ~96 dirt
setblock ~40 ~105 ~97 dirt
setblock ~40 ~105 ~98 dirt
setblock ~40 ~105 ~99 dirt
setblock ~40 ~105 ~100 dirt
setblock ~40 ~105 ~101 dirt
setblock ~40 ~105 ~102 dirt
setblock ~40 ~106 ~94 dirt
setblock ~40 ~106 ~95 dirt
setblock ~40 ~106 ~96 dirt
setblock ~40 ~106 ~97 dirt
setblock ~40 ~106 ~98 dirt
setblock ~40 ~106 ~99 dirt
setblock ~40 ~106 ~100 dirt
setblock ~40 ~106 ~101 dirt
setblock ~40 ~106 ~102 dirt
setblock ~40 ~106 ~103 dirt
setblock ~40 ~107 ~94 dirt
setblock ~40 ~107 ~95 dirt
setblock ~40 ~107 ~96 dirt
setblock ~40 ~107 ~97 dirt
setblock ~40 ~107 ~98 dirt
setblock ~40 ~107 ~99 dirt
setblock ~40 ~107 ~100 dirt
setblock ~40 ~107 ~101 dirt
setblock ~40 ~107 ~102 dirt
setblock ~40 ~107 ~103 dirt
setblock ~40 ~107 ~104 dirt
setblock ~40 ~108 ~92 dirt
setblock ~40 ~108 ~93 dirt
setblock ~40 ~108 ~94 dirt
setblock ~40 ~108 ~95 dirt
setblock ~40 ~108 ~96 dirt
setblock ~40 ~108 ~97 dirt
setblock ~40 ~108 ~98 dirt
setblock ~40 ~108 ~99 dirt
setblock ~40 ~108 ~100 dirt
setblock ~40 ~108 ~101 dirt
setblock ~40 ~108 ~102 dirt
setblock ~40 ~108 ~103 dirt
setblock ~40 ~108 ~104 dirt
setblock ~40 ~108 ~105 dirt
setblock ~40 ~109 ~92 dirt
setblock ~40 ~109 ~93 dirt
setblock ~40 ~109 ~94 dirt
setblock ~40 ~109 ~95 dirt
setblock ~40 ~109 ~96 dirt
setblock ~40 ~109 ~97 dirt
setblock ~40 ~109 ~98 dirt
setblock ~40 ~109 ~99 dirt
setblock ~40 ~109 ~100 dirt
setblock ~40 ~109 ~101 dirt
setblock ~40 ~109 ~102 dirt
setblock ~40 ~109 ~103 dirt
setblock ~40 ~109 ~104 dirt
setblock ~40 ~109 ~105 dirt
setblock ~40 ~109 ~106 dirt
setblock ~40 ~110 ~91 dirt
setblock ~40 ~110 ~92 dirt
setblock ~40 ~110 ~93 dirt
setblock ~40 ~110 ~94 dirt
setblock ~40 ~110 ~95 dirt
setblock ~40 ~110 ~96 dirt
setblock ~40 ~110 ~97 dirt
setblock ~40 ~110 ~98 dirt
setblock ~40 ~110 ~99 dirt
setblock ~40 ~110 ~100 dirt
setblock ~40 ~110 ~101 dirt
setblock ~40 ~110 ~102 dirt
setblock ~40 ~110 ~103 dirt
setblock ~40 ~110 ~104 dirt
setblock ~40 ~110 ~105 dirt
setblock ~40 ~110 ~106 dirt
setblock ~40 ~110 ~107 dirt
setblock ~40 ~110 ~129 dirt
setblock ~40 ~111 ~90 dirt
setblock ~40 ~111 ~91 dirt
setblock ~40 ~111 ~92 dirt
setblock ~40 ~111 ~93 dirt
setblock ~40 ~111 ~94 dirt
setblock ~40 ~111 ~95 dirt
setblock ~40 ~111 ~96 dirt
setblock ~40 ~111 ~97 dirt
setblock ~40 ~111 ~98 dirt
setblock ~40 ~111 ~99 dirt
setblock ~40 ~111 ~100 dirt
setblock ~40 ~111 ~101 dirt
setblock ~40 ~111 ~102 dirt
setblock ~40 ~111 ~103 dirt
setblock ~40 ~111 ~104 dirt
setblock ~40 ~111 ~105 dirt
setblock ~40 ~111 ~106 dirt
setblock ~40 ~111 ~107 dirt
setblock ~40 ~111 ~129 dirt
setblock ~40 ~112 ~89 dirt
setblock ~40 ~112 ~90 dirt
setblock ~40 ~112 ~91 dirt
setblock ~40 ~112 ~92 dirt
setblock ~40 ~112 ~93 dirt
setblock ~40 ~112 ~94 dirt
setblock ~40 ~112 ~95 dirt
setblock ~40 ~112 ~96 dirt
setblock ~40 ~112 ~97 dirt
setblock ~40 ~112 ~98 dirt
setblock ~40 ~112 ~99 dirt
setblock ~40 ~112 ~100 dirt
setblock ~40 ~112 ~101 dirt
setblock ~40 ~112 ~102 dirt
setblock ~40 ~112 ~103 dirt
setblock ~40 ~112 ~104 dirt
setblock ~40 ~112 ~105 dirt
setblock ~40 ~112 ~106 dirt
setblock ~40 ~112 ~107 dirt
setblock ~40 ~112 ~128 dirt
setblock ~40 ~112 ~129 dirt
setblock ~40 ~112 ~132 dirt
setblock ~40 ~113 ~74 dirt
setblock ~40 ~113 ~89 dirt
setblock ~40 ~113 ~90 dirt
setblock ~40 ~113 ~91 dirt
setblock ~40 ~113 ~92 dirt
setblock ~40 ~113 ~93 dirt
setblock ~40 ~113 ~94 dirt
setblock ~40 ~113 ~95 dirt
setblock ~40 ~113 ~96 dirt
setblock ~40 ~113 ~97 dirt
setblock ~40 ~113 ~98 dirt
setblock ~40 ~113 ~99 dirt
setblock ~40 ~113 ~100 dirt
setblock ~40 ~113 ~101 dirt
setblock ~40 ~113 ~102 dirt
setblock ~40 ~113 ~103 dirt
setblock ~40 ~113 ~104 dirt
setblock ~40 ~113 ~105 dirt
setblock ~40 ~113 ~106 dirt
setblock ~40 ~113 ~107 dirt
setblock ~40 ~113 ~108 dirt
setblock ~40 ~113 ~126 dirt
setblock ~40 ~113 ~127 dirt
setblock ~40 ~113 ~128 dirt
setblock ~40 ~113 ~129 dirt
setblock ~40 ~113 ~130 dirt
setblock ~40 ~113 ~132 dirt
setblock ~40 ~114 ~73 dirt
setblock ~40 ~114 ~74 dirt
setblock ~40 ~114 ~88 dirt
setblock ~40 ~114 ~89 dirt
setblock ~40 ~114 ~90 dirt
setblock ~40 ~114 ~91 dirt
setblock ~40 ~114 ~92 dirt
setblock ~40 ~114 ~93 dirt
setblock ~40 ~114 ~94 dirt
setblock ~40 ~114 ~95 dirt
setblock ~40 ~114 ~96 dirt
setblock ~40 ~114 ~97 dirt
setblock ~40 ~114 ~98 dirt
setblock ~40 ~114 ~99 dirt
setblock ~40 ~114 ~100 dirt
setblock ~40 ~114 ~101 dirt
setblock ~40 ~114 ~102 dirt
setblock ~40 ~114 ~103 dirt
setblock ~40 ~114 ~104 dirt
setblock ~40 ~114 ~105 dirt
setblock ~40 ~114 ~106 dirt
setblock ~40 ~114 ~107 dirt
setblock ~40 ~114 ~108 dirt
setblock ~40 ~114 ~109 dirt
setblock ~40 ~114 ~124 dirt
setblock ~40 ~114 ~125 dirt
setblock ~40 ~114 ~126 dirt
setblock ~40 ~114 ~127 dirt
setblock ~40 ~114 ~128 dirt
setblock ~40 ~114 ~129 dirt
setblock ~40 ~114 ~130 dirt
setblock ~40 ~114 ~131 dirt
setblock ~40 ~114 ~132 dirt
setblock ~40 ~115 ~71 dirt
setblock ~40 ~115 ~72 dirt
setblock ~40 ~115 ~73 dirt
setblock ~40 ~115 ~74 dirt
setblock ~40 ~115 ~75 dirt
setblock ~40 ~115 ~87 dirt
setblock ~40 ~115 ~88 dirt
setblock ~40 ~115 ~89 dirt
setblock ~40 ~115 ~90 dirt
setblock ~40 ~115 ~91 dirt
setblock ~40 ~115 ~92 dirt
setblock ~40 ~115 ~93 dirt
setblock ~40 ~115 ~94 dirt
setblock ~40 ~115 ~95 dirt
setblock ~40 ~115 ~96 dirt
setblock ~40 ~115 ~97 dirt
setblock ~40 ~115 ~98 dirt
setblock ~40 ~115 ~99 dirt
setblock ~40 ~115 ~100 dirt
setblock ~40 ~115 ~101 dirt
setblock ~40 ~115 ~102 dirt
setblock ~40 ~115 ~103 dirt
setblock ~40 ~115 ~104 dirt
setblock ~40 ~115 ~105 dirt
setblock ~40 ~115 ~106 dirt
setblock ~40 ~115 ~107 dirt
setblock ~40 ~115 ~108 dirt
setblock ~40 ~115 ~109 dirt
setblock ~40 ~115 ~120 dirt
setblock ~40 ~115 ~121 dirt
setblock ~40 ~115 ~123 dirt
setblock ~40 ~115 ~124 dirt
setblock ~40 ~115 ~125 dirt
setblock ~40 ~115 ~126 dirt
setblock ~40 ~115 ~127 dirt
setblock ~40 ~115 ~128 dirt
setblock ~40 ~115 ~129 dirt
setblock ~40 ~115 ~130 dirt
setblock ~40 ~115 ~131 dirt
setblock ~40 ~115 ~132 dirt
setblock ~40 ~115 ~133 dirt
setblock ~40 ~116 ~69 dirt
setblock ~40 ~116 ~70 dirt
setblock ~40 ~116 ~71 dirt
setblock ~40 ~116 ~72 dirt
setblock ~40 ~116 ~73 dirt
setblock ~40 ~116 ~74 dirt
setblock ~40 ~116 ~75 dirt
setblock ~40 ~116 ~87 dirt
setblock ~40 ~116 ~88 dirt
setblock ~40 ~116 ~89 dirt
setblock ~40 ~116 ~90 dirt
setblock ~40 ~116 ~91 dirt
setblock ~40 ~116 ~92 dirt
setblock ~40 ~116 ~93 dirt
setblock ~40 ~116 ~94 dirt
setblock ~40 ~116 ~95 dirt
setblock ~40 ~116 ~96 dirt
setblock ~40 ~116 ~97 dirt
setblock ~40 ~116 ~98 dirt
setblock ~40 ~116 ~99 dirt
setblock ~40 ~116 ~100 dirt
setblock ~40 ~116 ~101 dirt
setblock ~40 ~116 ~102 dirt
setblock ~40 ~116 ~103 dirt
setblock ~40 ~116 ~104 dirt
setblock ~40 ~116 ~105 dirt
setblock ~40 ~116 ~106 dirt
setblock ~40 ~116 ~107 dirt
setblock ~40 ~116 ~108 dirt
setblock ~40 ~116 ~109 dirt
setblock ~40 ~116 ~110 dirt
setblock ~40 ~116 ~120 dirt
setblock ~40 ~116 ~121 dirt
setblock ~40 ~116 ~122 dirt
setblock ~40 ~116 ~123 dirt
setblock ~40 ~116 ~124 dirt
setblock ~40 ~116 ~125 dirt
setblock ~40 ~116 ~126 dirt
setblock ~40 ~116 ~127 dirt
setblock ~40 ~116 ~128 dirt
setblock ~40 ~116 ~129 dirt
setblock ~40 ~116 ~130 dirt
setblock ~40 ~116 ~131 dirt
setblock ~40 ~116 ~132 dirt
setblock ~40 ~116 ~133 dirt
setblock ~40 ~116 ~134 dirt
setblock ~40 ~117 ~69 dirt
setblock ~40 ~117 ~70 dirt
setblock ~40 ~117 ~71 dirt
setblock ~40 ~117 ~72 dirt
setblock ~40 ~117 ~73 dirt
setblock ~40 ~117 ~74 dirt
setblock ~40 ~117 ~75 dirt
setblock ~40 ~117 ~76 dirt
setblock ~40 ~117 ~87 dirt
setblock ~40 ~117 ~88 dirt
setblock ~40 ~117 ~89 dirt
setblock ~40 ~117 ~90 dirt
setblock ~40 ~117 ~91 dirt
setblock ~40 ~117 ~92 dirt
setblock ~40 ~117 ~93 dirt
setblock ~40 ~117 ~94 dirt
setblock ~40 ~117 ~95 dirt
setblock ~40 ~117 ~96 dirt
setblock ~40 ~117 ~97 dirt
setblock ~40 ~117 ~98 dirt
setblock ~40 ~117 ~99 dirt
setblock ~40 ~117 ~100 dirt
setblock ~40 ~117 ~101 dirt
setblock ~40 ~117 ~102 dirt
setblock ~40 ~117 ~103 dirt
setblock ~40 ~117 ~104 dirt
setblock ~40 ~117 ~105 dirt
setblock ~40 ~117 ~106 dirt
setblock ~40 ~117 ~107 dirt
setblock ~40 ~117 ~108 dirt
setblock ~40 ~117 ~109 dirt
setblock ~40 ~117 ~110 dirt
setblock ~40 ~117 ~117 dirt
setblock ~40 ~117 ~119 dirt
setblock ~40 ~117 ~120 dirt
setblock ~40 ~117 ~121 dirt
setblock ~40 ~117 ~122 dirt
setblock ~40 ~117 ~123 dirt
setblock ~40 ~117 ~124 dirt
setblock ~40 ~117 ~125 dirt
setblock ~40 ~117 ~126 dirt
setblock ~40 ~117 ~127 dirt
setblock ~40 ~117 ~128 dirt
setblock ~40 ~117 ~129 dirt
setblock ~40 ~117 ~130 dirt
setblock ~40 ~117 ~131 dirt
setblock ~40 ~117 ~132 dirt
setblock ~40 ~117 ~133 dirt
setblock ~40 ~117 ~134 dirt
setblock ~40 ~117 ~135 dirt
setblock ~40 ~118 ~65 dirt
setblock ~40 ~118 ~68 dirt
setblock ~40 ~118 ~69 dirt
setblock ~40 ~118 ~70 dirt
setblock ~40 ~118 ~71 dirt
setblock ~40 ~118 ~72 dirt
setblock ~40 ~118 ~73 dirt
setblock ~40 ~118 ~74 dirt
setblock ~40 ~118 ~75 dirt
setblock ~40 ~118 ~76 dirt
setblock ~40 ~118 ~79 dirt
setblock ~40 ~118 ~86 dirt
setblock ~40 ~118 ~87 dirt
setblock ~40 ~118 ~88 dirt
setblock ~40 ~118 ~89 dirt
setblock ~40 ~118 ~90 dirt
setblock ~40 ~118 ~91 dirt
setblock ~40 ~118 ~92 dirt
setblock ~40 ~118 ~93 dirt
setblock ~40 ~118 ~94 dirt
setblock ~40 ~118 ~95 dirt
setblock ~40 ~118 ~96 dirt
setblock ~40 ~118 ~97 dirt
setblock ~40 ~118 ~98 dirt
setblock ~40 ~118 ~99 dirt
setblock ~40 ~118 ~100 dirt
setblock ~40 ~118 ~101 dirt
setblock ~40 ~118 ~102 dirt
setblock ~40 ~118 ~103 dirt
setblock ~40 ~118 ~104 dirt
setblock ~40 ~118 ~105 dirt
setblock ~40 ~118 ~106 dirt
setblock ~40 ~118 ~107 dirt
setblock ~40 ~118 ~108 dirt
setblock ~40 ~118 ~109 dirt
setblock ~40 ~118 ~110 dirt
setblock ~40 ~118 ~116 dirt
setblock ~40 ~118 ~117 dirt
setblock ~40 ~118 ~118 dirt
setblock ~40 ~118 ~119 dirt
setblock ~40 ~118 ~120 dirt
setblock ~40 ~118 ~121 dirt
setblock ~40 ~118 ~122 dirt
setblock ~40 ~118 ~123 dirt
setblock ~40 ~118 ~124 dirt
setblock ~40 ~118 ~125 dirt
setblock ~40 ~118 ~126 dirt
setblock ~40 ~118 ~127 dirt
setblock ~40 ~118 ~128 dirt
setblock ~40 ~118 ~129 dirt
setblock ~40 ~118 ~130 dirt
setblock ~40 ~118 ~131 dirt
setblock ~40 ~118 ~132 dirt
setblock ~40 ~118 ~133 dirt
setblock ~40 ~118 ~134 dirt
setblock ~40 ~118 ~135 dirt
setblock ~40 ~119 ~63 dirt
setblock ~40 ~119 ~64 dirt
setblock ~40 ~119 ~65 dirt
setblock ~40 ~119 ~66 dirt
setblock ~40 ~119 ~67 dirt
setblock ~40 ~119 ~68 dirt
setblock ~40 ~119 ~69 dirt
setblock ~40 ~119 ~70 dirt
setblock ~40 ~119 ~71 dirt
setblock ~40 ~119 ~72 dirt
setblock ~40 ~119 ~73 dirt
setblock ~40 ~119 ~74 dirt
setblock ~40 ~119 ~75 dirt
setblock ~40 ~119 ~76 dirt
setblock ~40 ~119 ~77 dirt
setblock ~40 ~119 ~78 dirt
setblock ~40 ~119 ~79 dirt
setblock ~40 ~119 ~80 dirt
setblock ~40 ~119 ~81 dirt
setblock ~40 ~119 ~85 dirt
setblock ~40 ~119 ~86 dirt
setblock ~40 ~119 ~87 dirt
setblock ~40 ~119 ~88 dirt
setblock ~40 ~119 ~89 dirt
setblock ~40 ~119 ~90 dirt
setblock ~40 ~119 ~91 dirt
setblock ~40 ~119 ~92 dirt
setblock ~40 ~119 ~93 dirt
setblock ~40 ~119 ~94 dirt
setblock ~40 ~119 ~95 dirt
setblock ~40 ~119 ~96 dirt
setblock ~40 ~119 ~97 dirt
setblock ~40 ~119 ~98 dirt
setblock ~40 ~119 ~99 dirt
setblock ~40 ~119 ~100 dirt
setblock ~40 ~119 ~101 dirt
setblock ~40 ~119 ~102 dirt
setblock ~40 ~119 ~103 dirt
setblock ~40 ~119 ~104 dirt
setblock ~40 ~119 ~105 dirt
setblock ~40 ~119 ~106 dirt
setblock ~40 ~119 ~107 dirt
setblock ~40 ~119 ~108 dirt
setblock ~40 ~119 ~109 dirt
setblock ~40 ~119 ~110 dirt
setblock ~40 ~119 ~111 dirt
setblock ~40 ~119 ~116 dirt
setblock ~40 ~119 ~117 dirt
setblock ~40 ~119 ~118 dirt
setblock ~40 ~119 ~119 dirt
setblock ~40 ~119 ~120 dirt
setblock ~40 ~119 ~121 dirt
setblock ~40 ~119 ~122 dirt
setblock ~40 ~119 ~123 dirt
setblock ~40 ~119 ~124 dirt
setblock ~40 ~119 ~125 dirt
setblock ~40 ~119 ~126 dirt
setblock ~40 ~119 ~127 dirt
setblock ~40 ~119 ~128 dirt
setblock ~40 ~119 ~129 dirt
setblock ~40 ~119 ~130 dirt
setblock ~40 ~119 ~131 dirt
setblock ~40 ~119 ~132 dirt
setblock ~40 ~119 ~133 dirt
setblock ~40 ~119 ~134 dirt
setblock ~40 ~119 ~135 dirt
setblock ~40 ~119 ~136 dirt
setblock ~40 ~120 ~63 dirt
setblock ~40 ~120 ~64 dirt
setblock ~40 ~120 ~65 dirt
setblock ~40 ~120 ~66 dirt
setblock ~40 ~120 ~67 dirt
setblock ~40 ~120 ~68 dirt
setblock ~40 ~120 ~69 dirt
setblock ~40 ~120 ~70 dirt
setblock ~40 ~120 ~71 dirt
setblock ~40 ~120 ~72 dirt
setblock ~40 ~120 ~73 dirt
setblock ~40 ~120 ~74 dirt
setblock ~40 ~120 ~75 dirt
setblock ~40 ~120 ~76 dirt
setblock ~40 ~120 ~77 dirt
setblock ~40 ~120 ~78 dirt
setblock ~40 ~120 ~79 dirt
setblock ~40 ~120 ~80 dirt
setblock ~40 ~120 ~81 dirt
setblock ~40 ~120 ~82 dirt
setblock ~40 ~120 ~83 dirt
setblock ~40 ~120 ~84 dirt
setblock ~40 ~120 ~85 dirt
setblock ~40 ~120 ~86 dirt
setblock ~40 ~120 ~87 dirt
setblock ~40 ~120 ~88 dirt
setblock ~40 ~120 ~89 dirt
setblock ~40 ~120 ~90 dirt
setblock ~40 ~120 ~91 dirt
setblock ~40 ~120 ~92 dirt
setblock ~40 ~120 ~93 dirt
setblock ~40 ~120 ~94 dirt
setblock ~40 ~120 ~95 dirt
setblock ~40 ~120 ~96 dirt
setblock ~40 ~120 ~97 dirt
setblock ~40 ~120 ~98 dirt
setblock ~40 ~120 ~99 dirt
setblock ~40 ~120 ~100 dirt
setblock ~40 ~120 ~101 dirt
setblock ~40 ~120 ~102 dirt
setblock ~40 ~120 ~103 dirt
setblock ~40 ~120 ~104 dirt
setblock ~40 ~120 ~105 dirt
setblock ~40 ~120 ~106 dirt
setblock ~40 ~120 ~107 dirt
setblock ~40 ~120 ~108 dirt
setblock ~40 ~120 ~109 dirt
setblock ~40 ~120 ~110 dirt
setblock ~40 ~120 ~111 dirt
setblock ~40 ~120 ~115 dirt
setblock ~40 ~120 ~116 dirt
setblock ~40 ~120 ~117 dirt
setblock ~40 ~120 ~118 dirt
setblock ~40 ~120 ~119 dirt
setblock ~40 ~120 ~120 dirt
setblock ~40 ~120 ~121 dirt
setblock ~40 ~120 ~122 dirt
setblock ~40 ~120 ~123 dirt
setblock ~40 ~120 ~124 dirt
setblock ~40 ~120 ~125 dirt
setblock ~40 ~120 ~126 dirt
setblock ~40 ~120 ~127 dirt
setblock ~40 ~120 ~128 dirt
setblock ~40 ~120 ~129 dirt
setblock ~40 ~120 ~130 dirt
setblock ~40 ~120 ~131 dirt
setblock ~40 ~120 ~132 dirt
setblock ~40 ~120 ~133 dirt
setblock ~40 ~120 ~134 dirt
setblock ~40 ~120 ~135 dirt
setblock ~40 ~120 ~136 dirt
setblock ~40 ~120 ~137 dirt
setblock ~40 ~121 ~62 dirt
setblock ~40 ~121 ~63 dirt
setblock ~40 ~121 ~64 dirt
setblock ~40 ~121 ~65 dirt
setblock ~40 ~121 ~66 dirt
setblock ~40 ~121 ~67 dirt
setblock ~40 ~121 ~68 dirt
setblock ~40 ~121 ~69 dirt
setblock ~40 ~121 ~70 dirt
setblock ~40 ~121 ~71 dirt
setblock ~40 ~121 ~72 dirt
setblock ~40 ~121 ~73 dirt
setblock ~40 ~121 ~74 dirt
setblock ~40 ~121 ~75 dirt
setblock ~40 ~121 ~76 dirt
setblock ~40 ~121 ~77 dirt
setblock ~40 ~121 ~78 dirt
setblock ~40 ~121 ~79 dirt
setblock ~40 ~121 ~80 dirt
setblock ~40 ~121 ~81 dirt
setblock ~40 ~121 ~82 dirt
setblock ~40 ~121 ~83 dirt
setblock ~40 ~121 ~84 dirt
setblock ~40 ~121 ~85 dirt
setblock ~40 ~121 ~86 dirt
setblock ~40 ~121 ~87 dirt
setblock ~40 ~121 ~88 dirt
setblock ~40 ~121 ~89 dirt
setblock ~40 ~121 ~90 dirt
setblock ~40 ~121 ~91 dirt
setblock ~40 ~121 ~92 dirt
setblock ~40 ~121 ~93 dirt
setblock ~40 ~121 ~94 dirt
setblock ~40 ~121 ~95 dirt
setblock ~40 ~121 ~96 dirt
setblock ~40 ~121 ~97 dirt
setblock ~40 ~121 ~98 dirt
setblock ~40 ~121 ~99 dirt
setblock ~40 ~121 ~100 dirt
setblock ~40 ~121 ~101 dirt
setblock ~40 ~121 ~102 dirt
setblock ~40 ~121 ~103 dirt
setblock ~40 ~121 ~104 dirt
setblock ~40 ~121 ~105 dirt
setblock ~40 ~121 ~106 dirt
setblock ~40 ~121 ~107 dirt
setblock ~40 ~121 ~108 dirt
setblock ~40 ~121 ~109 dirt
setblock ~40 ~121 ~110 dirt
setblock ~40 ~121 ~111 dirt
setblock ~40 ~121 ~112 dirt
setblock ~40 ~121 ~113 dirt
setblock ~40 ~121 ~114 dirt
setblock ~40 ~121 ~115 dirt
setblock ~40 ~121 ~116 dirt
setblock ~40 ~121 ~117 dirt
setblock ~40 ~121 ~118 dirt
setblock ~40 ~121 ~119 dirt
setblock ~40 ~121 ~120 dirt
setblock ~40 ~121 ~121 dirt
setblock ~40 ~121 ~122 dirt
setblock ~40 ~121 ~123 dirt
setblock ~40 ~121 ~124 dirt
setblock ~40 ~121 ~125 dirt
setblock ~40 ~121 ~126 dirt
setblock ~40 ~121 ~127 dirt
setblock ~40 ~121 ~128 dirt
setblock ~40 ~121 ~129 dirt
setblock ~40 ~121 ~130 dirt
setblock ~40 ~121 ~131 dirt
setblock ~40 ~121 ~132 dirt
setblock ~40 ~121 ~133 dirt
setblock ~40 ~121 ~134 dirt
setblock ~40 ~121 ~135 dirt
setblock ~40 ~121 ~136 dirt
setblock ~40 ~121 ~137 dirt
setblock ~40 ~122 ~62 dirt
setblock ~40 ~122 ~63 dirt
setblock ~40 ~122 ~64 dirt
setblock ~40 ~122 ~65 dirt
setblock ~40 ~122 ~66 dirt
setblock ~40 ~122 ~67 dirt
setblock ~40 ~122 ~68 dirt
setblock ~40 ~122 ~69 dirt
setblock ~40 ~122 ~70 dirt
setblock ~40 ~122 ~71 dirt
setblock ~40 ~122 ~72 dirt
setblock ~40 ~122 ~73 dirt
setblock ~40 ~122 ~74 dirt
setblock ~40 ~122 ~75 dirt
setblock ~40 ~122 ~76 dirt
setblock ~40 ~122 ~77 dirt
setblock ~40 ~122 ~78 dirt
setblock ~40 ~122 ~79 dirt
setblock ~40 ~122 ~80 dirt
setblock ~40 ~122 ~81 dirt
setblock ~40 ~122 ~82 dirt
setblock ~40 ~122 ~83 dirt
setblock ~40 ~122 ~84 dirt
setblock ~40 ~122 ~85 dirt
setblock ~40 ~122 ~86 dirt
setblock ~40 ~122 ~87 dirt
setblock ~40 ~122 ~88 dirt
setblock ~40 ~122 ~89 dirt
setblock ~40 ~122 ~90 dirt
setblock ~40 ~122 ~91 dirt
setblock ~40 ~122 ~92 dirt
setblock ~40 ~122 ~93 dirt
setblock ~40 ~122 ~94 dirt
setblock ~40 ~122 ~95 dirt
setblock ~40 ~122 ~96 dirt
setblock ~40 ~122 ~97 dirt
setblock ~40 ~122 ~98 dirt
setblock ~40 ~122 ~99 dirt
setblock ~40 ~122 ~100 dirt
setblock ~40 ~122 ~101 dirt
setblock ~40 ~122 ~102 dirt
setblock ~40 ~122 ~103 dirt
setblock ~40 ~122 ~104 dirt
setblock ~40 ~122 ~105 dirt
setblock ~40 ~122 ~106 dirt
setblock ~40 ~122 ~107 dirt
setblock ~40 ~122 ~108 dirt
setblock ~40 ~122 ~109 dirt
setblock ~40 ~122 ~110 dirt
setblock ~40 ~122 ~111 dirt
setblock ~40 ~122 ~112 dirt
setblock ~40 ~122 ~113 dirt
setblock ~40 ~122 ~114 dirt
setblock ~40 ~122 ~115 dirt
setblock ~40 ~122 ~116 dirt
setblock ~40 ~122 ~117 grass_block
setblock ~40 ~122 ~118 grass_block
setblock ~40 ~122 ~119 grass_block
setblock ~40 ~122 ~120 grass_block
setblock ~40 ~122 ~121 grass_block
setblock ~40 ~122 ~122 grass_block
setblock ~40 ~122 ~123 grass_block
setblock ~40 ~122 ~124 grass_block
setblock ~40 ~122 ~125 grass_block
setblock ~40 ~122 ~126 dirt
setblock ~40 ~122 ~127 dirt
setblock ~40 ~122 ~128 dirt
setblock ~40 ~122 ~129 dirt
setblock ~40 ~122 ~130 dirt
setblock ~40 ~122 ~131 dirt
setblock ~40 ~122 ~132 dirt
setblock ~40 ~122 ~133 dirt
setblock ~40 ~122 ~134 dirt
setblock ~40 ~122 ~135 dirt
setblock ~40 ~122 ~136 dirt
setblock ~40 ~122 ~137 dirt
setblock ~40 ~123 ~62 grass_block
setblock ~40 ~123 ~63 grass_block
setblock ~40 ~123 ~64 grass_block
setblock ~40 ~123 ~65 dirt
setblock ~40 ~123 ~66 dirt
setblock ~40 ~123 ~67 dirt
setblock ~40 ~123 ~68 dirt
setblock ~40 ~123 ~69 dirt
setblock ~40 ~123 ~70 dirt
setblock ~40 ~123 ~71 dirt
setblock ~40 ~123 ~72 dirt
setblock ~40 ~123 ~73 dirt
setblock ~40 ~123 ~74 dirt
setblock ~40 ~123 ~75 dirt
setblock ~40 ~123 ~76 dirt
setblock ~40 ~123 ~77 dirt
setblock ~40 ~123 ~78 dirt
setblock ~40 ~123 ~79 dirt
setblock ~40 ~123 ~80 dirt
setblock ~40 ~123 ~81 dirt
setblock ~40 ~123 ~82 dirt
setblock ~40 ~123 ~83 dirt
setblock ~40 ~123 ~84 dirt
setblock ~40 ~123 ~85 dirt
setblock ~40 ~123 ~86 dirt
setblock ~40 ~123 ~87 dirt
setblock ~40 ~123 ~88 dirt
setblock ~40 ~123 ~89 dirt
setblock ~40 ~123 ~90 dirt
setblock ~40 ~123 ~91 dirt
setblock ~40 ~123 ~92 dirt
setblock ~40 ~123 ~93 dirt
setblock ~40 ~123 ~94 dirt
setblock ~40 ~123 ~95 dirt
setblock ~40 ~123 ~96 dirt
setblock ~40 ~123 ~97 dirt
setblock ~40 ~123 ~98 dirt
setblock ~40 ~123 ~99 dirt
setblock ~40 ~123 ~100 dirt
setblock ~40 ~123 ~101 dirt
setblock ~40 ~123 ~102 dirt
setblock ~40 ~123 ~103 dirt
setblock ~40 ~123 ~104 dirt
setblock ~40 ~123 ~105 dirt
setblock ~40 ~123 ~106 dirt
setblock ~40 ~123 ~107 dirt
setblock ~40 ~123 ~108 dirt
setblock ~40 ~123 ~109 dirt
setblock ~40 ~123 ~110 grass_block
setblock ~40 ~123 ~111 grass_block
setblock ~40 ~123 ~112 grass_block
setblock ~40 ~123 ~113 grass_block
setblock ~40 ~123 ~114 grass_block
setblock ~40 ~123 ~115 grass_block
setblock ~40 ~123 ~116 grass_block
setblock ~40 ~123 ~120 short_grass
setblock ~40 ~123 ~126 grass_block
setblock ~40 ~123 ~127 grass_block
setblock ~40 ~123 ~128 grass_block
setblock ~40 ~123 ~129 grass_block
setblock ~40 ~123 ~130 dirt
setblock ~40 ~123 ~131 dirt
setblock ~40 ~123 ~132 dirt
setblock ~40 ~123 ~133 dirt
setblock ~40 ~123 ~134 dirt
setblock ~40 ~123 ~135 dirt
setblock ~40 ~123 ~136 dirt
setblock ~40 ~123 ~137 dirt
setblock ~40 ~124 ~65 grass_block
setblock ~40 ~124 ~66 grass_block
setblock ~40 ~124 ~67 grass_block
setblock ~40 ~124 ~68 dirt
setblock ~40 ~124 ~69 dirt
setblock ~40 ~124 ~70 dirt
setblock ~40 ~124 ~71 dirt
setblock ~40 ~124 ~72 dirt
setblock ~40 ~124 ~73 dirt
setblock ~40 ~124 ~74 dirt
setblock ~40 ~124 ~75 dirt
setblock ~40 ~124 ~76 dirt
setblock ~40 ~124 ~77 dirt
setblock ~40 ~124 ~78 dirt
setblock ~40 ~124 ~79 dirt
setblock ~40 ~124 ~80 dirt
setblock ~40 ~124 ~81 dirt
setblock ~40 ~124 ~82 dirt
setblock ~40 ~124 ~83 dirt
setblock ~40 ~124 ~84 dirt
setblock ~40 ~124 ~85 dirt
setblock ~40 ~124 ~86 dirt
setblock ~40 ~124 ~87 dirt
setblock ~40 ~124 ~88 dirt
setblock ~40 ~124 ~89 dirt
setblock ~40 ~124 ~90 dirt
setblock ~40 ~124 ~91 dirt
setblock ~40 ~124 ~92 dirt
setblock ~40 ~124 ~93 dirt
setblock ~40 ~124 ~94 dirt
setblock ~40 ~124 ~95 dirt
setblock ~40 ~124 ~96 dirt
setblock ~40 ~124 ~97 dirt
setblock ~40 ~124 ~98 dirt
setblock ~40 ~124 ~99 dirt
setblock ~40 ~124 ~100 dirt
setblock ~40 ~124 ~101 dirt
setblock ~40 ~124 ~102 dirt
setblock ~40 ~124 ~103 dirt
setblock ~40 ~124 ~104 dirt
setblock ~40 ~124 ~105 dirt
setblock ~40 ~124 ~106 grass_block
setblock ~40 ~124 ~107 grass_block
setblock ~40 ~124 ~108 grass_block
setblock ~40 ~124 ~109 grass_block
setblock ~40 ~124 ~113 short_grass
setblock ~40 ~124 ~129 short_grass
setblock ~40 ~124 ~130 grass_block
setblock ~40 ~124 ~131 grass_block
setblock ~40 ~124 ~132 dirt
setblock ~40 ~124 ~133 dirt
setblock ~40 ~124 ~134 dirt
setblock ~40 ~124 ~135 dirt
setblock ~40 ~124 ~136 dirt
setblock ~40 ~124 ~137 dirt
setblock ~40 ~125 ~68 grass_block
setblock ~40 ~125 ~69 grass_block
setblock ~40 ~125 ~70 grass_block
setblock ~40 ~125 ~71 grass_block
setblock ~40 ~125 ~72 grass_block
setblock ~40 ~125 ~73 dirt
setblock ~40 ~125 ~74 dirt
setblock ~40 ~125 ~75 dirt
setblock ~40 ~125 ~76 dirt
setblock ~40 ~125 ~77 dirt
setblock ~40 ~125 ~78 dirt
setblock ~40 ~125 ~79 dirt
setblock ~40 ~125 ~80 dirt
setblock ~40 ~125 ~81 dirt
setblock ~40 ~125 ~82 dirt
setblock ~40 ~125 ~83 dirt
setblock ~40 ~125 ~84 dirt
setblock ~40 ~125 ~85 dirt
setblock ~40 ~125 ~86 dirt
setblock ~40 ~125 ~87 dirt
setblock ~40 ~125 ~88 dirt
setblock ~40 ~125 ~89 dirt
setblock ~40 ~125 ~90 dirt
setblock ~40 ~125 ~91 dirt
setblock ~40 ~125 ~92 dirt
setblock ~40 ~125 ~93 dirt
setblock ~40 ~125 ~94 dirt
setblock ~40 ~125 ~95 dirt
setblock ~40 ~125 ~96 dirt
setblock ~40 ~125 ~97 dirt
setblock ~40 ~125 ~98 dirt
setblock ~40 ~125 ~99 grass_block
setblock ~40 ~125 ~100 grass_block
setblock ~40 ~125 ~101 grass_block
setblock ~40 ~125 ~102 grass_block
setblock ~40 ~125 ~103 grass_block
setblock ~40 ~125 ~104 grass_block
setblock ~40 ~125 ~105 grass_block
setblock ~40 ~125 ~109 short_grass
setblock ~40 ~125 ~132 grass_block
setblock ~40 ~125 ~133 grass_block
setblock ~40 ~125 ~134 grass_block
setblock ~40 ~125 ~135 grass_block
setblock ~40 ~125 ~136 grass_block
setblock ~40 ~125 ~137 grass_block
setblock ~40 ~126 ~72 short_grass
setblock ~40 ~126 ~73 grass_block
setblock ~40 ~126 ~74 grass_block
setblock ~40 ~126 ~75 grass_block
setblock ~40 ~126 ~76 grass_block
setblock ~40 ~126 ~77 grass_block
setblock ~40 ~126 ~78 grass_block
setblock ~40 ~126 ~79 grass_block
setblock ~40 ~126 ~80 grass_block
setblock ~40 ~126 ~81 dirt
setblock ~40 ~126 ~82 dirt
setblock ~40 ~126 ~83 dirt
setblock ~40 ~126 ~84 dirt
setblock ~40 ~126 ~85 dirt
setblock ~40 ~126 ~86 dirt
setblock ~40 ~126 ~87 dirt
setblock ~40 ~126 ~88 dirt
setblock ~40 ~126 ~89 dirt
setblock ~40 ~126 ~90 dirt
setblock ~40 ~126 ~91 dirt
setblock ~40 ~126 ~92 dirt
setblock ~40 ~126 ~93 dirt
setblock ~40 ~126 ~94 dirt
setblock ~40 ~126 ~95 dirt
setblock ~40 ~126 ~96 dirt
setblock ~40 ~126 ~97 dirt
setblock ~40 ~126 ~98 grass_block
setblock ~40 ~126 ~99 fern
setblock ~40 ~126 ~103 short_grass
setblock ~40 ~126 ~104 short_grass
setblock ~40 ~126 ~135 short_grass
setblock ~40 ~126 ~137 poppy
setblock ~40 ~127 ~73 short_grass
setblock ~40 ~127 ~77 short_grass
setblock ~40 ~127 ~81 grass_block
setblock ~40 ~127 ~82 grass_block
setblock ~40 ~127 ~83 grass_block
setblock ~40 ~127 ~84 grass_block
setblock ~40 ~127 ~85 dirt
setblock ~40 ~127 ~86 dirt
setblock ~40 ~127 ~87 dirt
setblock ~40 ~127 ~88 dirt
setblock ~40 ~127 ~89 dirt
setblock ~40 ~127 ~90 dirt
setblock ~40 ~127 ~91 dirt
setblock ~40 ~127 ~92 dirt
setblock ~40 ~127 ~93 dirt
setblock ~40 ~127 ~94 dirt
setblock ~40 ~127 ~95 grass_block
setblock ~40 ~127 ~96 grass_block
setblock ~40 ~127 ~97 grass_block
setblock ~40 ~128 ~83 short_grass
setblock ~40 ~128 ~85 grass_block
setblock ~40 ~128 ~86 grass_block
setblock ~40 ~128 ~87 grass_block
setblock ~40 ~128 ~88 grass_block
setblock ~40 ~128 ~89 dirt
setblock ~40 ~128 ~90 dirt
setblock ~40 ~128 ~91 dirt
setblock ~40 ~128 ~92 grass_block
setblock ~40 ~128 ~93 grass_block
setblock ~40 ~128 ~94 grass_block
setblock ~40 ~129 ~85 short_grass
setblock ~40 ~129 ~89 grass_block
setblock ~40 ~129 ~90 grass_block
setblock ~40 ~129 ~91 grass_block
setblock ~40 ~130 ~89 short_grass
setblock ~40 ~130 ~90 short_grass
setblock ~41 ~101 ~99 dirt
setblock ~41 ~101 ~100 dirt
setblock ~41 ~102 ~97 dirt
setblock ~41 ~102 ~98 dirt
setblock ~41 ~102 ~99 dirt
setblock ~41 ~102 ~100 dirt
setblock ~41 ~102 ~101 dirt
setblock ~41 ~103 ~96 dirt
setblock ~41 ~103 ~97 dirt
setblock ~41 ~103 ~98 dirt
setblock ~41 ~103 ~99 dirt
setblock ~41 ~103 ~100 dirt
setblock ~41 ~103 ~101 dirt
setblock ~41 ~103 ~102 dirt
setblock ~41 ~104 ~96 dirt
setblock ~41 ~104 ~97 dirt
setblock ~41 ~104 ~98 dirt
setblock ~41 ~104 ~99 dirt
setblock ~41 ~104 ~100 dirt
setblock ~41 ~104 ~101 dirt
setblock ~41 ~104 ~102 dirt
setblock ~41 ~104 ~104 dirt
setblock ~41 ~105 ~94 dirt
setblock ~41 ~105 ~95 dirt
setblock ~41 ~105 ~96 dirt
setblock ~41 ~105 ~97 dirt
setblock ~41 ~105 ~98 dirt
setblock ~41 ~105 ~99 dirt
setblock ~41 ~105 ~100 dirt
setblock ~41 ~105 ~101 dirt
setblock ~41 ~105 ~102 dirt
setblock ~41 ~105 ~103 dirt
setblock ~41 ~105 ~104 dirt
setblock ~41 ~106 ~92 dirt
setblock ~41 ~106 ~93 dirt
setblock ~41 ~106 ~94 dirt
setblock ~41 ~106 ~95 dirt
setblock ~41 ~106 ~96 dirt
setblock ~41 ~106 ~97 dirt
setblock ~41 ~106 ~98 dirt
setblock ~41 ~106 ~99 dirt
setblock ~41 ~106 ~100 dirt
setblock ~41 ~106 ~101 dirt
setblock ~41 ~106 ~102 dirt
setblock ~41 ~106 ~103 dirt
setblock ~41 ~106 ~104 dirt
setblock ~41 ~106 ~105 dirt
setblock ~41 ~107 ~91 dirt
setblock ~41 ~107 ~92 dirt
setblock ~41 ~107 ~93 dirt
setblock ~41 ~107 ~94 dirt
setblock ~41 ~107 ~95 dirt
setblock ~41 ~107 ~96 dirt
setblock ~41 ~107 ~97 dirt
setblock ~41 ~107 ~98 dirt
setblock ~41 ~107 ~99 dirt
setblock ~41 ~107 ~100 dirt
setblock ~41 ~107 ~101 dirt
setblock ~41 ~107 ~102 dirt
setblock ~41 ~107 ~103 dirt
setblock ~41 ~107 ~104 dirt
setblock ~41 ~107 ~105 dirt
setblock ~41 ~107 ~106 dirt
setblock ~41 ~108 ~91 dirt
setblock ~41 ~108 ~92 dirt
setblock ~41 ~108 ~93 dirt
setblock ~41 ~108 ~94 dirt
setblock ~41 ~108 ~95 dirt
setblock ~41 ~108 ~96 dirt
setblock ~41 ~108 ~97 dirt
setblock ~41 ~108 ~98 dirt
setblock ~41 ~108 ~99 dirt
setblock ~41 ~108 ~100 dirt
setblock ~41 ~108 ~101 dirt
setblock ~41 ~108 ~102 dirt
setblock ~41 ~108 ~103 dirt
setblock ~41 ~108 ~104 dirt
setblock ~41 ~108 ~105 dirt
setblock ~41 ~108 ~106 dirt
setblock ~41 ~109 ~90 dirt
setblock ~41 ~109 ~91 dirt
setblock ~41 ~109 ~92 dirt
setblock ~41 ~109 ~93 dirt
setblock ~41 ~109 ~94 dirt
setblock ~41 ~109 ~95 dirt
setblock ~41 ~109 ~96 dirt
setblock ~41 ~109 ~97 dirt
setblock ~41 ~109 ~98 dirt
setblock ~41 ~109 ~99 dirt
setblock ~41 ~109 ~100 dirt
setblock ~41 ~109 ~101 dirt
setblock ~41 ~109 ~102 dirt
setblock ~41 ~109 ~103 dirt
setblock ~41 ~109 ~104 dirt
setblock ~41 ~109 ~105 dirt
setblock ~41 ~109 ~106 dirt
setblock ~41 ~109 ~107 dirt
setblock ~41 ~109 ~129 dirt
setblock ~41 ~110 ~90 dirt
setblock ~41 ~110 ~91 dirt
setblock ~41 ~110 ~92 dirt
setblock ~41 ~110 ~93 dirt
setblock ~41 ~110 ~94 dirt
setblock ~41 ~110 ~95 dirt
setblock ~41 ~110 ~96 dirt
setblock ~41 ~110 ~97 dirt
setblock ~41 ~110 ~98 dirt
setblock ~41 ~110 ~99 dirt
setblock ~41 ~110 ~100 dirt
setblock ~41 ~110 ~101 dirt
setblock ~41 ~110 ~102 dirt
setblock ~41 ~110 ~103 dirt
setblock ~41 ~110 ~104 dirt
setblock ~41 ~110 ~105 dirt
setblock ~41 ~110 ~106 dirt
setblock ~41 ~110 ~107 dirt
setblock ~41 ~110 ~108 dirt
setblock ~41 ~110 ~125 dirt
setblock ~41 ~110 ~128 dirt
setblock ~41 ~110 ~129 dirt
setblock ~41 ~110 ~130 dirt
setblock ~41 ~111 ~89 dirt
setblock ~41 ~111 ~90 dirt
setblock ~41 ~111 ~91 dirt
setblock ~41 ~111 ~92 dirt
setblock ~41 ~111 ~93 dirt
setblock ~41 ~111 ~94 dirt
setblock ~41 ~111 ~95 dirt
setblock ~41 ~111 ~96 dirt
setblock ~41 ~111 ~97 dirt
setblock ~41 ~111 ~98 dirt
setblock ~41 ~111 ~99 dirt
setblock ~41 ~111 ~100 dirt
setblock ~41 ~111 ~101 dirt
setblock ~41 ~111 ~102 dirt
setblock ~41 ~111 ~103 dirt
setblock ~41 ~111 ~104 dirt
setblock ~41 ~111 ~105 dirt
setblock ~41 ~111 ~106 dirt
setblock ~41 ~111 ~107 dirt
setblock ~41 ~111 ~108 dirt
setblock ~41 ~111 ~121 dirt
setblock ~41 ~111 ~125 dirt
setblock ~41 ~111 ~126 dirt
setblock ~41 ~111 ~128 dirt
setblock ~41 ~111 ~129 dirt
setblock ~41 ~111 ~130 dirt
setblock ~41 ~111 ~132 dirt
setblock ~41 ~112 ~73 dirt
setblock ~41 ~112 ~74 dirt
setblock ~41 ~112 ~88 dirt
setblock ~41 ~112 ~89 dirt
setblock ~41 ~112 ~90 dirt
setblock ~41 ~112 ~91 dirt
setblock ~41 ~112 ~92 dirt
setblock ~41 ~112 ~93 dirt
setblock ~41 ~112 ~94 dirt
setblock ~41 ~112 ~95 dirt
setblock ~41 ~112 ~96 dirt
setblock ~41 ~112 ~97 dirt
setblock ~41 ~112 ~98 dirt
setblock ~41 ~112 ~99 dirt
setblock ~41 ~112 ~100 dirt
setblock ~41 ~112 ~101 dirt
setblock ~41 ~112 ~102 dirt
setblock ~41 ~112 ~103 dirt
setblock ~41 ~112 ~104 dirt
setblock ~41 ~112 ~105 dirt
setblock ~41 ~112 ~106 dirt
setblock ~41 ~112 ~107 dirt
setblock ~41 ~112 ~108 dirt
setblock ~41 ~112 ~121 dirt
setblock ~41 ~112 ~124 dirt
setblock ~41 ~112 ~125 dirt
setblock ~41 ~112 ~126 dirt
setblock ~41 ~112 ~127 dirt
setblock ~41 ~112 ~128 dirt
setblock ~41 ~112 ~129 dirt
setblock ~41 ~112 ~130 dirt
setblock ~41 ~112 ~131 dirt
setblock ~41 ~112 ~132 dirt
setblock ~41 ~112 ~133 dirt
setblock ~41 ~113 ~73 dirt
setblock ~41 ~113 ~74 dirt
setblock ~41 ~113 ~75 dirt
setblock ~41 ~113 ~76 dirt
setblock ~41 ~113 ~88 dirt
setblock ~41 ~113 ~89 dirt
setblock ~41 ~113 ~90 dirt
setblock ~41 ~113 ~91 dirt
