setblock ~0 ~1 ~0 gold_block
setblock ~56 ~120 ~99 dirt
setblock ~56 ~120 ~102 dirt
setblock ~56 ~121 ~86 dirt
setblock ~56 ~121 ~91 dirt
setblock ~56 ~121 ~99 dirt
setblock ~56 ~121 ~100 dirt
setblock ~56 ~121 ~102 dirt
setblock ~56 ~122 ~86 dirt
setblock ~56 ~122 ~91 dirt
setblock ~56 ~122 ~99 dirt
setblock ~56 ~122 ~100 dirt
setblock ~56 ~122 ~102 dirt
setblock ~56 ~123 ~86 dirt
setblock ~56 ~123 ~91 dirt
setblock ~56 ~123 ~99 dirt
setblock ~56 ~123 ~100 dirt
setblock ~56 ~123 ~102 dirt
setblock ~56 ~124 ~86 grass_block
setblock ~56 ~124 ~91 grass_block
setblock ~56 ~124 ~99 dirt
setblock ~56 ~124 ~100 dirt
setblock ~56 ~124 ~102 dirt
setblock ~56 ~125 ~99 dirt
setblock ~56 ~125 ~100 dirt
setblock ~56 ~125 ~102 dirt
setblock ~56 ~126 ~99 grass_block
setblock ~56 ~126 ~100 grass_block
setblock ~56 ~126 ~102 grass_block
setblock ~56 ~127 ~99 fern
setblock ~56 ~127 ~100 short_grass
setblock ~57 ~118 ~100 dirt
setblock ~57 ~118 ~102 dirt
setblock ~57 ~119 ~86 dirt
setblock ~57 ~119 ~99 dirt
setblock ~57 ~119 ~100 dirt
setblock ~57 ~119 ~101 dirt
setblock ~57 ~119 ~102 dirt
setblock ~57 ~119 ~103 dirt
setblock ~57 ~120 ~86 dirt
setblock ~57 ~120 ~91 dirt
setblock ~57 ~120 ~98 dirt
setblock ~57 ~120 ~99 dirt
setblock ~57 ~120 ~100 dirt
setblock ~57 ~120 ~101 dirt
setblock ~57 ~120 ~102 dirt
setblock ~57 ~120 ~103 dirt
setblock ~57 ~120 ~104 dirt
setblock ~57 ~120 ~107 dirt
setblock ~57 ~121 ~85 dirt
setblock ~57 ~121 ~86 dirt
setblock ~57 ~121 ~87 dirt
setblock ~57 ~121 ~90 dirt
setblock ~57 ~121 ~91 dirt
setblock ~57 ~121 ~92 dirt
setblock ~57 ~121 ~96 dirt
setblock ~57 ~121 ~97 dirt
setblock ~57 ~121 ~98 dirt
setblock ~57 ~121 ~99 dirt
setblock ~57 ~121 ~100 dirt
setblock ~57 ~121 ~101 dirt
setblock ~57 ~121 ~102 dirt
setblock ~57 ~121 ~103 dirt
setblock ~57 ~121 ~104 dirt
setblock ~57 ~121 ~105 dirt
setblock ~57 ~121 ~107 dirt
setblock ~57 ~121 ~108 dirt
setblock ~57 ~121 ~109 dirt
setblock ~57 ~122 ~85 dirt
setblock ~57 ~122 ~86 dirt
setblock ~57 ~122 ~87 dirt
setblock ~57 ~122 ~90 dirt
setblock ~57 ~122 ~91 dirt
setblock ~57 ~122 ~92 dirt
setblock ~57 ~122 ~96 dirt
setblock ~57 ~122 ~97 dirt
setblock ~57 ~122 ~98 dirt
setblock ~57 ~122 ~99 dirt
setblock ~57 ~122 ~100 dirt
setblock ~57 ~122 ~101 dirt
setblock ~57 ~122 ~102 dirt
setblock ~57 ~122 ~103 dirt
setblock ~57 ~122 ~104 dirt
setblock ~57 ~122 ~105 dirt
setblock ~57 ~122 ~107 dirt
setblock ~57 ~122 ~108 dirt
setblock ~57 ~122 ~109 dirt
setblock ~57 ~123 ~85 dirt
setblock ~57 ~123 ~86 dirt
setblock ~57 ~123 ~87 dirt
setblock ~57 ~123 ~90 dirt
setblock ~57 ~123 ~91 dirt
setblock ~57 ~123 ~92 dirt
setblock ~57 ~123 ~96 dirt
setblock ~57 ~123 ~97 dirt
setblock ~57 ~123 ~98 dirt
setblock ~57 ~123 ~99 dirt
setblock ~57 ~123 ~100 dirt
setblock ~57 ~123 ~101 dirt
setblock ~57 ~123 ~102 dirt
setblock ~57 ~123 ~103 dirt
setblock ~57 ~123 ~104 dirt
setblock ~57 ~123 ~105 dirt
setblock ~57 ~123 ~107 dirt
setblock ~57 ~123 ~108 dirt
setblock ~57 ~123 ~109 dirt
setblock ~57 ~124 ~85 grass_block
setblock ~57 ~124 ~86 grass_block
setblock ~57 ~124 ~87 grass_block
setblock ~57 ~124 ~90 grass_block
setblock ~57 ~124 ~91 grass_block
setblock ~57 ~124 ~92 grass_block
setblock ~57 ~124 ~96 dirt
setblock ~57 ~124 ~97 dirt
setblock ~57 ~124 ~98 dirt
setblock ~57 ~124 ~99 dirt
setblock ~57 ~124 ~100 dirt
setblock ~57 ~124 ~101 dirt
setblock ~57 ~124 ~102 dirt
setblock ~57 ~124 ~103 dirt
setblock ~57 ~124 ~104 dirt
setblock ~57 ~124 ~105 dirt
setblock ~57 ~124 ~107 dirt
setblock ~57 ~124 ~108 dirt
setblock ~57 ~124 ~109 dirt
setblock ~57 ~125 ~91 short_grass
setblock ~57 ~125 ~96 grass_block
setblock ~57 ~125 ~97 grass_block
setblock ~57 ~125 ~98 grass_block
setblock ~57 ~125 ~99 dirt
setblock ~57 ~125 ~100 dirt
setblock ~57 ~125 ~101 dirt
setblock ~57 ~125 ~102 dirt
setblock ~57 ~125 ~103 dirt
setblock ~57 ~125 ~104 dirt
setblock ~57 ~125 ~105 dirt
setblock ~57 ~125 ~107 dirt
setblock ~57 ~125 ~108 dirt
setblock ~57 ~125 ~109 dirt
setblock ~57 ~126 ~96 short_grass
setblock ~57 ~126 ~98 short_grass
setblock ~57 ~126 ~99 grass_block
setblock ~57 ~126 ~100 grass_block
setblock ~57 ~126 ~101 dirt
setblock ~57 ~126 ~102 dirt
setblock ~57 ~126 ~103 dirt
setblock ~57 ~126 ~104 dirt
setblock ~57 ~126 ~105 dirt
setblock ~57 ~126 ~107 dirt
setblock ~57 ~126 ~108 dirt
setblock ~57 ~126 ~109 dirt
setblock ~57 ~127 ~99 poppy
setblock ~57 ~127 ~101 grass_block
setblock ~57 ~127 ~102 grass_block
setblock ~57 ~127 ~103 grass_block
setblock ~57 ~127 ~104 grass_block
setblock ~57 ~127 ~105 dirt
setblock ~57 ~127 ~107 dirt
setblock ~57 ~127 ~108 dirt
setblock ~57 ~127 ~109 dirt
setblock ~57 ~128 ~101 short_grass
setblock ~57 ~128 ~105 grass_block
setblock ~57 ~128 ~107 grass_block
setblock ~57 ~128 ~108 grass_block
setblock ~57 ~128 ~109 grass_block
setblock ~58 ~117 ~99 dirt
setblock ~58 ~117 ~100 dirt
setblock ~58 ~117 ~101 dirt
setblock ~58 ~117 ~102 dirt
setblock ~58 ~117 ~103 dirt
setblock ~58 ~118 ~86 dirt
setblock ~58 ~118 ~98 dirt
setblock ~58 ~118 ~99 dirt
setblock ~58 ~118 ~100 dirt
setblock ~58 ~118 ~101 dirt
setblock ~58 ~118 ~102 dirt
setblock ~58 ~118 ~103 dirt
setblock ~58 ~118 ~104 dirt
setblock ~58 ~118 ~105 dirt
setblock ~58 ~118 ~107 dirt
setblock ~58 ~118 ~109 dirt
setblock ~58 ~119 ~85 dirt
setblock ~58 ~119 ~86 dirt
setblock ~58 ~119 ~87 dirt
setblock ~58 ~119 ~90 dirt
setblock ~58 ~119 ~91 dirt
setblock ~58 ~119 ~97 dirt
setblock ~58 ~119 ~98 dirt
setblock ~58 ~119 ~99 dirt
setblock ~58 ~119 ~100 dirt
setblock ~58 ~119 ~101 dirt
setblock ~58 ~119 ~102 dirt
setblock ~58 ~119 ~103 dirt
setblock ~58 ~119 ~104 dirt
setblock ~58 ~119 ~105 dirt
setblock ~58 ~119 ~107 dirt
setblock ~58 ~119 ~108 dirt
setblock ~58 ~119 ~109 dirt
setblock ~58 ~119 ~111 dirt
setblock ~58 ~120 ~85 dirt
setblock ~58 ~120 ~86 dirt
setblock ~58 ~120 ~87 dirt
setblock ~58 ~120 ~89 dirt
setblock ~58 ~120 ~90 dirt
setblock ~58 ~120 ~91 dirt
setblock ~58 ~120 ~92 dirt
setblock ~58 ~120 ~95 dirt
setblock ~58 ~120 ~96 dirt
setblock ~58 ~120 ~97 dirt
setblock ~58 ~120 ~98 dirt
setblock ~58 ~120 ~99 dirt
setblock ~58 ~120 ~100 dirt
setblock ~58 ~120 ~101 dirt
setblock ~58 ~120 ~102 dirt
setblock ~58 ~120 ~103 dirt
setblock ~58 ~120 ~104 dirt
setblock ~58 ~120 ~105 dirt
setblock ~58 ~120 ~106 dirt
setblock ~58 ~120 ~107 dirt
setblock ~58 ~120 ~108 dirt
setblock ~58 ~120 ~109 dirt
setblock ~58 ~120 ~110 dirt
setblock ~58 ~120 ~111 dirt
setblock ~58 ~121 ~84 dirt
setblock ~58 ~121 ~85 dirt
setblock ~58 ~121 ~86 dirt
setblock ~58 ~121 ~87 dirt
setblock ~58 ~121 ~88 dirt
setblock ~58 ~121 ~89 dirt
setblock ~58 ~121 ~90 dirt
setblock ~58 ~121 ~91 dirt
setblock ~58 ~121 ~92 dirt
setblock ~58 ~121 ~93 dirt
setblock ~58 ~121 ~94 dirt
setblock ~58 ~121 ~95 dirt
setblock ~58 ~121 ~96 dirt
setblock ~58 ~121 ~97 dirt
setblock ~58 ~121 ~98 dirt
setblock ~58 ~121 ~99 dirt
setblock ~58 ~121 ~100 dirt
setblock ~58 ~121 ~101 dirt
setblock ~58 ~121 ~102 dirt
setblock ~58 ~121 ~103 dirt
setblock ~58 ~121 ~104 dirt
setblock ~58 ~121 ~105 dirt
setblock ~58 ~121 ~106 dirt
setblock ~58 ~121 ~107 dirt
setblock ~58 ~121 ~108 dirt
setblock ~58 ~121 ~109 dirt
setblock ~58 ~121 ~110 dirt
setblock ~58 ~121 ~111 dirt
setblock ~58 ~122 ~84 dirt
setblock ~58 ~122 ~85 dirt
setblock ~58 ~122 ~86 dirt
setblock ~58 ~122 ~87 dirt
setblock ~58 ~122 ~88 dirt
setblock ~58 ~122 ~89 dirt
setblock ~58 ~122 ~90 dirt
setblock ~58 ~122 ~91 dirt
setblock ~58 ~122 ~92 dirt
setblock ~58 ~122 ~93 dirt
setblock ~58 ~122 ~94 dirt
setblock ~58 ~122 ~95 dirt
setblock ~58 ~122 ~96 dirt
setblock ~58 ~122 ~97 dirt
setblock ~58 ~122 ~98 dirt
setblock ~58 ~122 ~99 dirt
setblock ~58 ~122 ~100 dirt
setblock ~58 ~122 ~101 dirt
setblock ~58 ~122 ~102 dirt
setblock ~58 ~122 ~103 dirt
setblock ~58 ~122 ~104 dirt
setblock ~58 ~122 ~105 dirt
setblock ~58 ~122 ~106 dirt
setblock ~58 ~122 ~107 dirt
setblock ~58 ~122 ~108 dirt
setblock ~58 ~122 ~109 dirt
setblock ~58 ~122 ~110 dirt
setblock ~58 ~122 ~111 dirt
setblock ~58 ~123 ~84 grass_block
setblock ~58 ~123 ~85 grass_block
setblock ~58 ~123 ~86 grass_block
setblock ~58 ~123 ~87 grass_block
setblock ~58 ~123 ~88 dirt
setblock ~58 ~123 ~89 dirt
setblock ~58 ~123 ~90 dirt
setblock ~58 ~123 ~91 dirt
setblock ~58 ~123 ~92 dirt
setblock ~58 ~123 ~93 dirt
setblock ~58 ~123 ~94 dirt
setblock ~58 ~123 ~95 dirt
setblock ~58 ~123 ~96 dirt
setblock ~58 ~123 ~97 dirt
setblock ~58 ~123 ~98 dirt
setblock ~58 ~123 ~99 dirt
setblock ~58 ~123 ~100 dirt
setblock ~58 ~123 ~101 dirt
setblock ~58 ~123 ~102 dirt
setblock ~58 ~123 ~103 dirt
setblock ~58 ~123 ~104 dirt
setblock ~58 ~123 ~105 dirt
setblock ~58 ~123 ~106 dirt
setblock ~58 ~123 ~107 dirt
setblock ~58 ~123 ~108 dirt
setblock ~58 ~123 ~109 dirt
setblock ~58 ~123 ~110 dirt
setblock ~58 ~123 ~111 dirt
setblock ~58 ~124 ~86 short_grass
setblock ~58 ~124 ~88 grass_block
setblock ~58 ~124 ~89 grass_block
setblock ~58 ~124 ~90 grass_block
setblock ~58 ~124 ~91 grass_block
setblock ~58 ~124 ~92 grass_block
setblock ~58 ~124 ~93 grass_block
setblock ~58 ~124 ~94 grass_block
setblock ~58 ~124 ~95 dirt
setblock ~58 ~124 ~96 dirt
setblock ~58 ~124 ~97 dirt
setblock ~58 ~124 ~98 dirt
setblock ~58 ~124 ~99 dirt
setblock ~58 ~124 ~100 dirt
setblock ~58 ~124 ~101 dirt
setblock ~58 ~124 ~102 dirt
setblock ~58 ~124 ~103 dirt
setblock ~58 ~124 ~104 dirt
setblock ~58 ~124 ~105 dirt
setblock ~58 ~124 ~106 dirt
setblock ~58 ~124 ~107 dirt
setblock ~58 ~124 ~108 dirt
setblock ~58 ~124 ~109 dirt
setblock ~58 ~124 ~110 dirt
setblock ~58 ~124 ~111 dirt
setblock ~58 ~125 ~89 short_grass
setblock ~58 ~125 ~95 grass_block
setblock ~58 ~125 ~96 grass_block
setblock ~58 ~125 ~97 grass_block
setblock ~58 ~125 ~98 grass_block
setblock ~58 ~125 ~99 dirt
setblock ~58 ~125 ~100 dirt
setblock ~58 ~125 ~101 dirt
setblock ~58 ~125 ~102 dirt
setblock ~58 ~125 ~103 dirt
setblock ~58 ~125 ~104 dirt
setblock ~58 ~125 ~105 dirt
setblock ~58 ~125 ~106 dirt
setblock ~58 ~125 ~107 dirt
setblock ~58 ~125 ~108 dirt
setblock ~58 ~125 ~109 dirt
setblock ~58 ~125 ~110 dirt
setblock ~58 ~125 ~111 dirt
setblock ~58 ~126 ~95 short_grass
setblock ~58 ~126 ~97 short_grass
setblock ~58 ~126 ~99 grass_block
setblock ~58 ~126 ~100 dirt
setblock ~58 ~126 ~101 dirt
setblock ~58 ~126 ~102 dirt
setblock ~58 ~126 ~103 dirt
setblock ~58 ~126 ~104 dirt
setblock ~58 ~126 ~105 dirt
setblock ~58 ~126 ~106 dirt
setblock ~58 ~126 ~107 dirt
setblock ~58 ~126 ~108 dirt
setblock ~58 ~126 ~109 dirt
setblock ~58 ~126 ~110 dirt
setblock ~58 ~126 ~111 dirt
setblock ~58 ~127 ~100 grass_block
setblock ~58 ~127 ~101 grass_block
setblock ~58 ~127 ~102 grass_block
setblock ~58 ~127 ~103 dirt
setblock ~58 ~127 ~104 dirt
setblock ~58 ~127 ~105 dirt
setblock ~58 ~127 ~106 dirt
setblock ~58 ~127 ~107 dirt
setblock ~58 ~127 ~108 dirt
setblock ~58 ~127 ~109 dirt
setblock ~58 ~127 ~110 dirt
setblock ~58 ~127 ~111 dirt
setblock ~58 ~128 ~102 poppy
setblock ~58 ~128 ~103 grass_block
setblock ~58 ~128 ~104 grass_block
setblock ~58 ~128 ~105 grass_block
setblock ~58 ~128 ~106 grass_block
setblock ~58 ~128 ~107 dirt
setblock ~58 ~128 ~108 dirt
setblock ~58 ~128 ~109 dirt
setblock ~58 ~128 ~110 dirt
setblock ~58 ~128 ~111 dirt
setblock ~58 ~129 ~107 grass_block
setblock ~58 ~129 ~108 grass_block
setblock ~58 ~129 ~109 grass_block
setblock ~58 ~129 ~110 grass_block
setblock ~58 ~129 ~111 grass_block
setblock ~58 ~130 ~111 short_grass
setblock ~59 ~113 ~102 dirt
setblock ~59 ~114 ~102 dirt
setblock ~59 ~114 ~103 dirt
setblock ~59 ~115 ~99 dirt
setblock ~59 ~115 ~101 dirt
setblock ~59 ~115 ~102 dirt
setblock ~59 ~115 ~103 dirt
setblock ~59 ~116 ~90 dirt
setblock ~59 ~116 ~91 dirt
setblock ~59 ~116 ~98 dirt
setblock ~59 ~116 ~99 dirt
setblock ~59 ~116 ~100 dirt
setblock ~59 ~116 ~101 dirt
setblock ~59 ~116 ~102 dirt
setblock ~59 ~116 ~103 dirt
setblock ~59 ~116 ~104 dirt
setblock ~59 ~116 ~107 dirt
setblock ~59 ~117 ~86 dirt
setblock ~59 ~117 ~89 dirt
setblock ~59 ~117 ~90 dirt
setblock ~59 ~117 ~91 dirt
setblock ~59 ~117 ~96 dirt
setblock ~59 ~117 ~97 dirt
setblock ~59 ~117 ~98 dirt
setblock ~59 ~117 ~99 dirt
setblock ~59 ~117 ~100 dirt
setblock ~59 ~117 ~101 dirt
setblock ~59 ~117 ~102 dirt
setblock ~59 ~117 ~103 dirt
setblock ~59 ~117 ~104 dirt
setblock ~59 ~117 ~105 dirt
setblock ~59 ~117 ~107 dirt
setblock ~59 ~117 ~109 dirt
setblock ~59 ~118 ~85 dirt
setblock ~59 ~118 ~86 dirt
setblock ~59 ~118 ~87 dirt
setblock ~59 ~118 ~89 dirt
setblock ~59 ~118 ~90 dirt
setblock ~59 ~118 ~91 dirt
setblock ~59 ~118 ~95 dirt
setblock ~59 ~118 ~96 dirt
setblock ~59 ~118 ~97 dirt
setblock ~59 ~118 ~98 dirt
setblock ~59 ~118 ~99 dirt
setblock ~59 ~118 ~100 dirt
setblock ~59 ~118 ~101 dirt
setblock ~59 ~118 ~102 dirt
setblock ~59 ~118 ~103 dirt
setblock ~59 ~118 ~104 dirt
setblock ~59 ~118 ~105 dirt
setblock ~59 ~118 ~106 dirt
setblock ~59 ~118 ~107 dirt
setblock ~59 ~118 ~108 dirt
setblock ~59 ~118 ~109 dirt
setblock ~59 ~118 ~110 dirt
setblock ~59 ~118 ~111 dirt
setblock ~59 ~119 ~84 dirt
setblock ~59 ~119 ~85 dirt
setblock ~59 ~119 ~86 dirt
setblock ~59 ~119 ~87 dirt
setblock ~59 ~119 ~89 dirt
setblock ~59 ~119 ~90 dirt
setblock ~59 ~119 ~91 dirt
setblock ~59 ~119 ~92 dirt
setblock ~59 ~119 ~93 dirt
setblock ~59 ~119 ~94 dirt
setblock ~59 ~119 ~95 dirt
setblock ~59 ~119 ~96 dirt
setblock ~59 ~119 ~97 dirt
setblock ~59 ~119 ~98 dirt
setblock ~59 ~119 ~99 dirt
setblock ~59 ~119 ~100 dirt
setblock ~59 ~119 ~101 dirt
setblock ~59 ~119 ~102 dirt
setblock ~59 ~119 ~103 dirt
setblock ~59 ~119 ~104 dirt
setblock ~59 ~119 ~105 dirt
setblock ~59 ~119 ~106 dirt
setblock ~59 ~119 ~107 dirt
setblock ~59 ~119 ~108 dirt
setblock ~59 ~119 ~109 dirt
setblock ~59 ~119 ~110 dirt
setblock ~59 ~119 ~111 dirt
setblock ~59 ~119 ~112 dirt
setblock ~59 ~120 ~84 dirt
setblock ~59 ~120 ~85 dirt
setblock ~59 ~120 ~86 dirt
setblock ~59 ~120 ~87 dirt
setblock ~59 ~120 ~88 dirt
setblock ~59 ~120 ~89 dirt
setblock ~59 ~120 ~90 dirt
setblock ~59 ~120 ~91 dirt
setblock ~59 ~120 ~92 dirt
setblock ~59 ~120 ~93 dirt
setblock ~59 ~120 ~94 dirt
setblock ~59 ~120 ~95 dirt
setblock ~59 ~120 ~96 dirt
setblock ~59 ~120 ~97 dirt
setblock ~59 ~120 ~98 dirt
setblock ~59 ~120 ~99 dirt
setblock ~59 ~120 ~100 dirt
setblock ~59 ~120 ~101 dirt
setblock ~59 ~120 ~102 dirt
setblock ~59 ~120 ~103 dirt
setblock ~59 ~120 ~104 dirt
setblock ~59 ~120 ~105 dirt
setblock ~59 ~120 ~106 dirt
setblock ~59 ~120 ~107 dirt
setblock ~59 ~120 ~108 dirt
setblock ~59 ~120 ~109 dirt
setblock ~59 ~120 ~110 dirt
setblock ~59 ~120 ~111 dirt
setblock ~59 ~120 ~112 dirt
setblock ~59 ~121 ~84 dirt
setblock ~59 ~121 ~85 dirt
setblock ~59 ~121 ~86 dirt
setblock ~59 ~121 ~87 dirt
setblock ~59 ~121 ~88 dirt
setblock ~59 ~121 ~89 dirt
setblock ~59 ~121 ~90 dirt
setblock ~59 ~121 ~91 dirt
setblock ~59 ~121 ~92 dirt
setblock ~59 ~121 ~93 dirt
setblock ~59 ~121 ~94 dirt
setblock ~59 ~121 ~95 dirt
setblock ~59 ~121 ~96 dirt
setblock ~59 ~121 ~97 dirt
setblock ~59 ~121 ~98 dirt
setblock ~59 ~121 ~99 dirt
setblock ~59 ~121 ~100 dirt
setblock ~59 ~121 ~101 dirt
setblock ~59 ~121 ~102 dirt
setblock ~59 ~121 ~103 dirt
setblock ~59 ~121 ~104 dirt
setblock ~59 ~121 ~105 dirt
setblock ~59 ~121 ~106 dirt
setblock ~59 ~121 ~107 dirt
setblock ~59 ~121 ~108 dirt
setblock ~59 ~121 ~109 dirt
setblock ~59 ~121 ~110 dirt
setblock ~59 ~121 ~111 dirt
setblock ~59 ~121 ~112 dirt
setblock ~59 ~121 ~113 dirt
setblock ~59 ~122 ~84 dirt
setblock ~59 ~122 ~85 dirt
setblock ~59 ~122 ~86 dirt
setblock ~59 ~122 ~87 dirt
setblock ~59 ~122 ~88 dirt
setblock ~59 ~122 ~89 dirt
setblock ~59 ~122 ~90 dirt
setblock ~59 ~122 ~91 dirt
setblock ~59 ~122 ~92 dirt
setblock ~59 ~122 ~93 dirt
setblock ~59 ~122 ~94 dirt
setblock ~59 ~122 ~95 dirt
setblock ~59 ~122 ~96 dirt
setblock ~59 ~122 ~97 dirt
setblock ~59 ~122 ~98 dirt
setblock ~59 ~122 ~99 dirt
setblock ~59 ~122 ~100 dirt
setblock ~59 ~122 ~101 dirt
setblock ~59 ~122 ~102 dirt
setblock ~59 ~122 ~103 dirt
setblock ~59 ~122 ~104 dirt
setblock ~59 ~122 ~105 dirt
setblock ~59 ~122 ~106 dirt
setblock ~59 ~122 ~107 dirt
setblock ~59 ~122 ~108 dirt
setblock ~59 ~122 ~109 dirt
setblock ~59 ~122 ~110 dirt
setblock ~59 ~122 ~111 dirt
setblock ~59 ~122 ~112 dirt
setblock ~59 ~122 ~113 dirt
setblock ~59 ~123 ~84 grass_block
setblock ~59 ~123 ~85 grass_block
setblock ~59 ~123 ~86 grass_block
setblock ~59 ~123 ~87 grass_block
setblock ~59 ~123 ~88 grass_block
setblock ~59 ~123 ~89 grass_block
setblock ~59 ~123 ~90 grass_block
setblock ~59 ~123 ~91 grass_block
setblock ~59 ~123 ~92 dirt
setblock ~59 ~123 ~93 dirt
setblock ~59 ~123 ~94 dirt
setblock ~59 ~123 ~95 dirt
setblock ~59 ~123 ~96 dirt
setblock ~59 ~123 ~97 dirt
setblock ~59 ~123 ~98 dirt
setblock ~59 ~123 ~99 dirt
setblock ~59 ~123 ~100 dirt
setblock ~59 ~123 ~101 dirt
setblock ~59 ~123 ~102 dirt
setblock ~59 ~123 ~103 dirt
setblock ~59 ~123 ~104 dirt
setblock ~59 ~123 ~105 dirt
setblock ~59 ~123 ~106 dirt
setblock ~59 ~123 ~107 dirt
setblock ~59 ~123 ~108 dirt
setblock ~59 ~123 ~109 dirt
setblock ~59 ~123 ~110 dirt
setblock ~59 ~123 ~111 dirt
setblock ~59 ~123 ~112 dirt
setblock ~59 ~123 ~113 dirt
setblock ~59 ~124 ~84 short_grass
setblock ~59 ~124 ~87 poppy
setblock ~59 ~124 ~88 short_grass
setblock ~59 ~124 ~90 short_grass
setblock ~59 ~124 ~92 grass_block
setblock ~59 ~124 ~93 grass_block
setblock ~59 ~124 ~94 grass_block
setblock ~59 ~124 ~95 grass_block
setblock ~59 ~124 ~96 dirt
setblock ~59 ~124 ~97 dirt
setblock ~59 ~124 ~98 dirt
setblock ~59 ~124 ~99 dirt
setblock ~59 ~124 ~100 dirt
setblock ~59 ~124 ~101 dirt
setblock ~59 ~124 ~102 dirt
setblock ~59 ~124 ~103 dirt
setblock ~59 ~124 ~104 dirt
setblock ~59 ~124 ~105 dirt
setblock ~59 ~124 ~106 dirt
setblock ~59 ~124 ~107 dirt
setblock ~59 ~124 ~108 dirt
setblock ~59 ~124 ~109 dirt
setblock ~59 ~124 ~110 dirt
setblock ~59 ~124 ~111 dirt
setblock ~59 ~124 ~112 dirt
setblock ~59 ~124 ~113 dirt
setblock ~59 ~125 ~92 short_grass
setblock ~59 ~125 ~96 grass_block
setblock ~59 ~125 ~97 grass_block
setblock ~59 ~125 ~98 dirt
setblock ~59 ~125 ~99 dirt
setblock ~59 ~125 ~100 dirt
setblock ~59 ~125 ~101 dirt
setblock ~59 ~125 ~102 dirt
setblock ~59 ~125 ~103 dirt
setblock ~59 ~125 ~104 dirt
setblock ~59 ~125 ~105 dirt
setblock ~59 ~125 ~106 dirt
setblock ~59 ~125 ~107 dirt
setblock ~59 ~125 ~108 dirt
setblock ~59 ~125 ~109 dirt
setblock ~59 ~125 ~110 dirt
setblock ~59 ~125 ~111 dirt
setblock ~59 ~125 ~112 dirt
setblock ~59 ~125 ~113 dirt
setblock ~59 ~126 ~98 grass_block
setblock ~59 ~126 ~99 grass_block
setblock ~59 ~126 ~100 dirt
setblock ~59 ~126 ~101 dirt
setblock ~59 ~126 ~102 dirt
setblock ~59 ~126 ~103 dirt
setblock ~59 ~126 ~104 dirt
setblock ~59 ~126 ~105 dirt
setblock ~59 ~126 ~106 dirt
setblock ~59 ~126 ~107 dirt
setblock ~59 ~126 ~108 dirt
setblock ~59 ~126 ~109 dirt
setblock ~59 ~126 ~110 dirt
setblock ~59 ~126 ~111 dirt
setblock ~59 ~126 ~112 dirt
setblock ~59 ~126 ~113 dirt
setblock ~59 ~127 ~98 short_grass
setblock ~59 ~127 ~100 dirt
setblock ~59 ~127 ~101 dirt
setblock ~59 ~127 ~102 dirt
setblock ~59 ~127 ~103 dirt
setblock ~59 ~127 ~104 dirt
setblock ~59 ~127 ~105 dirt
setblock ~59 ~127 ~106 dirt
setblock ~59 ~127 ~107 dirt
setblock ~59 ~127 ~108 dirt
setblock ~59 ~127 ~109 dirt
setblock ~59 ~127 ~110 dirt
setblock ~59 ~127 ~111 dirt
setblock ~59 ~127 ~112 dirt
setblock ~59 ~127 ~113 dirt
setblock ~59 ~128 ~100 grass_block
setblock ~59 ~128 ~101 grass_block
setblock ~59 ~128 ~102 grass_block
setblock ~59 ~128 ~103 dirt
setblock ~59 ~128 ~104 dirt
setblock ~59 ~128 ~105 dirt
setblock ~59 ~128 ~106 dirt
setblock ~59 ~128 ~107 dirt
setblock ~59 ~128 ~108 dirt
setblock ~59 ~128 ~109 dirt
setblock ~59 ~128 ~110 dirt
setblock ~59 ~128 ~111 dirt
setblock ~59 ~128 ~112 dirt
setblock ~59 ~128 ~113 dirt
setblock ~59 ~129 ~101 short_grass
setblock ~59 ~129 ~102 short_grass
setblock ~59 ~129 ~103 grass_block
setblock ~59 ~129 ~104 grass_block
setblock ~59 ~129 ~105 grass_block
setblock ~59 ~129 ~106 grass_block
setblock ~59 ~129 ~107 grass_block
setblock ~59 ~129 ~108 grass_block
setblock ~59 ~129 ~109 grass_block
setblock ~59 ~129 ~110 dirt
setblock ~59 ~129 ~111 grass_block
setblock ~59 ~129 ~112 grass_block
setblock ~59 ~129 ~113 grass_block
setblock ~59 ~130 ~104 short_grass
setblock ~59 ~130 ~106 short_grass
setblock ~59 ~130 ~107 short_grass
setblock ~59 ~130 ~110 grass_block
setblock ~59 ~130 ~111 fern
setblock ~59 ~130 ~113 short_grass
setblock ~60 ~111 ~101 dirt
setblock ~60 ~111 ~102 dirt
setblock ~60 ~112 ~101 dirt
setblock ~60 ~112 ~102 dirt
setblock ~60 ~113 ~98 dirt
setblock ~60 ~113 ~101 dirt
setblock ~60 ~113 ~102 dirt
setblock ~60 ~113 ~103 dirt
setblock ~60 ~114 ~97 dirt
setblock ~60 ~114 ~98 dirt
setblock ~60 ~114 ~99 dirt
setblock ~60 ~114 ~100 dirt
setblock ~60 ~114 ~101 dirt
setblock ~60 ~114 ~102 dirt
setblock ~60 ~114 ~103 dirt
setblock ~60 ~114 ~104 dirt
setblock ~60 ~114 ~107 dirt
setblock ~60 ~114 ~109 dirt
setblock ~60 ~115 ~90 dirt
setblock ~60 ~115 ~91 dirt
setblock ~60 ~115 ~97 dirt
setblock ~60 ~115 ~98 dirt
setblock ~60 ~115 ~99 dirt
setblock ~60 ~115 ~100 dirt
setblock ~60 ~115 ~101 dirt
setblock ~60 ~115 ~102 dirt
setblock ~60 ~115 ~103 dirt
setblock ~60 ~115 ~104 dirt
setblock ~60 ~115 ~107 dirt
setblock ~60 ~115 ~108 dirt
setblock ~60 ~115 ~109 dirt
setblock ~60 ~116 ~86 dirt
setblock ~60 ~116 ~87 dirt
setblock ~60 ~116 ~89 dirt
setblock ~60 ~116 ~90 dirt
setblock ~60 ~116 ~91 dirt
setblock ~60 ~116 ~92 dirt
setblock ~60 ~116 ~93 dirt
setblock ~60 ~116 ~96 dirt
setblock ~60 ~116 ~97 dirt
setblock ~60 ~116 ~98 dirt
setblock ~60 ~116 ~99 dirt
setblock ~60 ~116 ~100 dirt
setblock ~60 ~116 ~101 dirt
setblock ~60 ~116 ~102 dirt
setblock ~60 ~116 ~103 dirt
setblock ~60 ~116 ~104 dirt
setblock ~60 ~116 ~105 dirt
setblock ~60 ~116 ~106 dirt
setblock ~60 ~116 ~107 dirt
setblock ~60 ~116 ~108 dirt
setblock ~60 ~116 ~109 dirt
setblock ~60 ~116 ~110 dirt
setblock ~60 ~116 ~111 dirt
setblock ~60 ~117 ~85 dirt
setblock ~60 ~117 ~86 dirt
setblock ~60 ~117 ~87 dirt
setblock ~60 ~117 ~88 dirt
setblock ~60 ~117 ~89 dirt
setblock ~60 ~117 ~90 dirt
setblock ~60 ~117 ~91 dirt
setblock ~60 ~117 ~92 dirt
setblock ~60 ~117 ~93 dirt
setblock ~60 ~117 ~94 dirt
setblock ~60 ~117 ~95 dirt
setblock ~60 ~117 ~96 dirt
setblock ~60 ~117 ~97 dirt
setblock ~60 ~117 ~98 dirt
setblock ~60 ~117 ~99 dirt
setblock ~60 ~117 ~100 dirt
setblock ~60 ~117 ~101 dirt
setblock ~60 ~117 ~102 dirt
setblock ~60 ~117 ~103 dirt
setblock ~60 ~117 ~104 dirt
setblock ~60 ~117 ~105 dirt
setblock ~60 ~117 ~106 dirt
setblock ~60 ~117 ~107 dirt
setblock ~60 ~117 ~108 dirt
setblock ~60 ~117 ~109 dirt
setblock ~60 ~117 ~110 dirt
setblock ~60 ~117 ~111 dirt
setblock ~60 ~117 ~112 dirt
setblock ~60 ~118 ~84 dirt
setblock ~60 ~118 ~85 dirt
setblock ~60 ~118 ~86 dirt
setblock ~60 ~118 ~87 dirt
setblock ~60 ~118 ~88 dirt
setblock ~60 ~118 ~89 dirt
setblock ~60 ~118 ~90 dirt
setblock ~60 ~118 ~91 dirt
setblock ~60 ~118 ~92 dirt
setblock ~60 ~118 ~93 dirt
setblock ~60 ~118 ~94 dirt
setblock ~60 ~118 ~95 dirt
setblock ~60 ~118 ~96 dirt
setblock ~60 ~118 ~97 dirt
setblock ~60 ~118 ~98 dirt
setblock ~60 ~118 ~99 dirt
setblock ~60 ~118 ~100 dirt
setblock ~60 ~118 ~101 dirt
setblock ~60 ~118 ~102 dirt
setblock ~60 ~118 ~103 dirt
setblock ~60 ~118 ~104 dirt
setblock ~60 ~118 ~105 dirt
setblock ~60 ~118 ~106 dirt
setblock ~60 ~118 ~107 dirt
setblock ~60 ~118 ~108 dirt
setblock ~60 ~118 ~109 dirt
setblock ~60 ~118 ~110 dirt
setblock ~60 ~118 ~111 dirt
setblock ~60 ~118 ~112 dirt
setblock ~60 ~119 ~83 dirt
setblock ~60 ~119 ~84 dirt
setblock ~60 ~119 ~85 dirt
setblock ~60 ~119 ~86 dirt
setblock ~60 ~119 ~87 dirt
setblock ~60 ~119 ~88 dirt
setblock ~60 ~119 ~89 dirt
setblock ~60 ~119 ~90 dirt
setblock ~60 ~119 ~91 dirt
setblock ~60 ~119 ~92 dirt
setblock ~60 ~119 ~93 dirt
setblock ~60 ~119 ~94 dirt
setblock ~60 ~119 ~95 dirt
setblock ~60 ~119 ~96 dirt
setblock ~60 ~119 ~97 dirt
setblock ~60 ~119 ~98 dirt
setblock ~60 ~119 ~99 dirt
setblock ~60 ~119 ~100 dirt
setblock ~60 ~119 ~101 dirt
setblock ~60 ~119 ~102 dirt
setblock ~60 ~119 ~103 dirt
setblock ~60 ~119 ~104 dirt
setblock ~60 ~119 ~105 dirt
setblock ~60 ~119 ~106 dirt
setblock ~60 ~119 ~107 dirt
setblock ~60 ~119 ~108 dirt
setblock ~60 ~119 ~109 dirt
setblock ~60 ~119 ~110 dirt
setblock ~60 ~119 ~111 dirt
setblock ~60 ~119 ~112 dirt
setblock ~60 ~120 ~80 dirt
setblock ~60 ~120 ~83 dirt
setblock ~60 ~120 ~84 dirt
setblock ~60 ~120 ~85 dirt
setblock ~60 ~120 ~86 dirt
setblock ~60 ~120 ~87 dirt
setblock ~60 ~120 ~88 dirt
setblock ~60 ~120 ~89 dirt
setblock ~60 ~120 ~90 dirt
setblock ~60 ~120 ~91 dirt
setblock ~60 ~120 ~92 dirt
setblock ~60 ~120 ~93 dirt
setblock ~60 ~120 ~94 dirt
setblock ~60 ~120 ~95 dirt
setblock ~60 ~120 ~96 dirt
setblock ~60 ~120 ~97 dirt
setblock ~60 ~120 ~98 dirt
setblock ~60 ~120 ~99 dirt
setblock ~60 ~120 ~100 dirt
setblock ~60 ~120 ~101 dirt
setblock ~60 ~120 ~102 dirt
setblock ~60 ~120 ~103 dirt
setblock ~60 ~120 ~104 dirt
setblock ~60 ~120 ~105 dirt
setblock ~60 ~120 ~106 dirt
setblock ~60 ~120 ~107 dirt
setblock ~60 ~120 ~108 dirt
setblock ~60 ~120 ~109 dirt
setblock ~60 ~120 ~110 dirt
setblock ~60 ~120 ~111 dirt
setblock ~60 ~120 ~112 dirt
setblock ~60 ~120 ~113 dirt
setblock ~60 ~120 ~114 dirt
setblock ~60 ~121 ~80 dirt
setblock ~60 ~121 ~83 dirt
setblock ~60 ~121 ~84 dirt
setblock ~60 ~121 ~85 dirt
setblock ~60 ~121 ~86 dirt
setblock ~60 ~121 ~87 dirt
setblock ~60 ~121 ~88 dirt
setblock ~60 ~121 ~89 dirt
setblock ~60 ~121 ~90 dirt
setblock ~60 ~121 ~91 dirt
setblock ~60 ~121 ~92 dirt
setblock ~60 ~121 ~93 dirt
setblock ~60 ~121 ~94 dirt
setblock ~60 ~121 ~95 dirt
setblock ~60 ~121 ~96 dirt
setblock ~60 ~121 ~97 dirt
setblock ~60 ~121 ~98 dirt
setblock ~60 ~121 ~99 dirt
setblock ~60 ~121 ~100 dirt
setblock ~60 ~121 ~101 dirt
setblock ~60 ~121 ~102 dirt
setblock ~60 ~121 ~103 dirt
setblock ~60 ~121 ~104 dirt
setblock ~60 ~121 ~105 dirt
setblock ~60 ~121 ~106 dirt
setblock ~60 ~121 ~107 dirt
setblock ~60 ~121 ~108 dirt
setblock ~60 ~121 ~109 dirt
setblock ~60 ~121 ~110 dirt
setblock ~60 ~121 ~111 dirt
setblock ~60 ~121 ~112 dirt
setblock ~60 ~121 ~113 dirt
setblock ~60 ~121 ~114 dirt
setblock ~60 ~121 ~115 dirt
setblock ~60 ~122 ~80 grass_block
setblock ~60 ~122 ~83 dirt
setblock ~60 ~122 ~84 dirt
setblock ~60 ~122 ~85 dirt
setblock ~60 ~122 ~86 dirt
setblock ~60 ~122 ~87 dirt
setblock ~60 ~122 ~88 dirt
setblock ~60 ~122 ~89 dirt
setblock ~60 ~122 ~90 dirt
setblock ~60 ~122 ~91 dirt
setblock ~60 ~122 ~92 dirt
setblock ~60 ~122 ~93 dirt
setblock ~60 ~122 ~94 dirt
setblock ~60 ~122 ~95 dirt
setblock ~60 ~122 ~96 dirt
setblock ~60 ~122 ~97 dirt
setblock ~60 ~122 ~98 dirt
setblock ~60 ~122 ~99 dirt
setblock ~60 ~122 ~100 dirt
setblock ~60 ~122 ~101 dirt
setblock ~60 ~122 ~102 dirt
setblock ~60 ~122 ~103 dirt
setblock ~60 ~122 ~104 dirt
setblock ~60 ~122 ~105 dirt
setblock ~60 ~122 ~106 dirt
setblock ~60 ~122 ~107 dirt
setblock ~60 ~122 ~108 dirt
setblock ~60 ~122 ~109 dirt
setblock ~60 ~122 ~110 dirt
setblock ~60 ~122 ~111 dirt
setblock ~60 ~122 ~112 dirt
setblock ~60 ~122 ~113 dirt
setblock ~60 ~122 ~114 dirt
setblock ~60 ~122 ~115 dirt
setblock ~60 ~123 ~83 grass_block
setblock ~60 ~123 ~84 grass_block
setblock ~60 ~123 ~85 grass_block
setblock ~60 ~123 ~86 grass_block
setblock ~60 ~123 ~87 grass_block
setblock ~60 ~123 ~88 grass_block
setblock ~60 ~123 ~89 grass_block
setblock ~60 ~123 ~90 grass_block
setblock ~60 ~123 ~91 grass_block
setblock ~60 ~123 ~92 grass_block
setblock ~60 ~123 ~93 grass_block
setblock ~60 ~123 ~94 dirt
setblock ~60 ~123 ~95 dirt
setblock ~60 ~123 ~96 dirt
setblock ~60 ~123 ~97 dirt
setblock ~60 ~123 ~98 dirt
setblock ~60 ~123 ~99 dirt
setblock ~60 ~123 ~100 dirt
setblock ~60 ~123 ~101 dirt
setblock ~60 ~123 ~102 dirt
setblock ~60 ~123 ~103 dirt
setblock ~60 ~123 ~104 dirt
setblock ~60 ~123 ~105 dirt
setblock ~60 ~123 ~106 dirt
setblock ~60 ~123 ~107 dirt
setblock ~60 ~123 ~108 dirt
setblock ~60 ~123 ~109 dirt
setblock ~60 ~123 ~110 dirt
setblock ~60 ~123 ~111 dirt
setblock ~60 ~123 ~112 dirt
setblock ~60 ~123 ~113 dirt
setblock ~60 ~123 ~114 dirt
setblock ~60 ~123 ~115 dirt
setblock ~60 ~124 ~83 short_grass
setblock ~60 ~124 ~85 short_grass
setblock ~60 ~124 ~92 short_grass
setblock ~60 ~124 ~94 grass_block
setblock ~60 ~124 ~95 grass_block
setblock ~60 ~124 ~96 grass_block
setblock ~60 ~124 ~97 dirt
setblock ~60 ~124 ~98 dirt
setblock ~60 ~124 ~99 dirt
setblock ~60 ~124 ~100 dirt
setblock ~60 ~124 ~101 dirt
setblock ~60 ~124 ~102 dirt
setblock ~60 ~124 ~103 dirt
setblock ~60 ~124 ~104 dirt
setblock ~60 ~124 ~105 dirt
setblock ~60 ~124 ~106 dirt
setblock ~60 ~124 ~107 dirt
setblock ~60 ~124 ~108 dirt
setblock ~60 ~124 ~109 dirt
setblock ~60 ~124 ~110 dirt
setblock ~60 ~124 ~111 dirt
setblock ~60 ~124 ~112 dirt
setblock ~60 ~124 ~113 dirt
setblock ~60 ~124 ~114 dirt
setblock ~60 ~124 ~115 dirt
setblock ~60 ~125 ~97 grass_block
setblock ~60 ~125 ~98 dirt
setblock ~60 ~125 ~99 dirt
setblock ~60 ~125 ~100 dirt
setblock ~60 ~125 ~101 dirt
setblock ~60 ~125 ~102 dirt
setblock ~60 ~125 ~103 dirt
setblock ~60 ~125 ~104 dirt
setblock ~60 ~125 ~105 dirt
setblock ~60 ~125 ~106 dirt
setblock ~60 ~125 ~107 dirt
setblock ~60 ~125 ~108 dirt
setblock ~60 ~125 ~109 dirt
setblock ~60 ~125 ~110 dirt
setblock ~60 ~125 ~111 dirt
setblock ~60 ~125 ~112 dirt
setblock ~60 ~125 ~113 dirt
setblock ~60 ~125 ~114 dirt
setblock ~60 ~125 ~115 dirt
setblock ~60 ~126 ~98 grass_block
setblock ~60 ~126 ~99 dirt
setblock ~60 ~126 ~100 dirt
setblock ~60 ~126 ~101 dirt
setblock ~60 ~126 ~102 dirt
setblock ~60 ~126 ~103 dirt
setblock ~60 ~126 ~104 dirt
setblock ~60 ~126 ~105 dirt
setblock ~60 ~126 ~106 dirt
setblock ~60 ~126 ~107 dirt
setblock ~60 ~126 ~108 dirt
setblock ~60 ~126 ~109 dirt
setblock ~60 ~126 ~110 dirt
setblock ~60 ~126 ~111 dirt
setblock ~60 ~126 ~112 dirt
setblock ~60 ~126 ~113 dirt
setblock ~60 ~126 ~114 dirt
setblock ~60 ~126 ~115 dirt
setblock ~60 ~127 ~98 fern
setblock ~60 ~127 ~99 grass_block
setblock ~60 ~127 ~100 dirt
setblock ~60 ~127 ~101 dirt
setblock ~60 ~127 ~102 dirt
setblock ~60 ~127 ~103 dirt
setblock ~60 ~127 ~104 dirt
setblock ~60 ~127 ~105 dirt
setblock ~60 ~127 ~106 dirt
setblock ~60 ~127 ~107 dirt
setblock ~60 ~127 ~108 dirt
setblock ~60 ~127 ~109 dirt
setblock ~60 ~127 ~110 dirt
setblock ~60 ~127 ~111 dirt
setblock ~60 ~127 ~112 dirt
setblock ~60 ~127 ~113 dirt
setblock ~60 ~127 ~114 dirt
setblock ~60 ~127 ~115 dirt
setblock ~60 ~128 ~100 dirt
setblock ~60 ~128 ~101 dirt
setblock ~60 ~128 ~102 dirt
setblock ~60 ~128 ~103 dirt
setblock ~60 ~128 ~104 dirt
setblock ~60 ~128 ~105 dirt
setblock ~60 ~128 ~106 dirt
setblock ~60 ~128 ~107 dirt
setblock ~60 ~128 ~108 dirt
setblock ~60 ~128 ~109 dirt
setblock ~60 ~128 ~110 dirt
setblock ~60 ~128 ~111 dirt
setblock ~60 ~128 ~112 dirt
setblock ~60 ~128 ~113 dirt
setblock ~60 ~128 ~114 dirt
setblock ~60 ~128 ~115 dirt
setblock ~60 ~129 ~100 dirt
setblock ~60 ~129 ~101 dirt
setblock ~60 ~129 ~102 dirt
setblock ~60 ~129 ~103 dirt
setblock ~60 ~129 ~104 dirt
setblock ~60 ~129 ~105 dirt
setblock ~60 ~129 ~106 dirt
setblock ~60 ~129 ~107 dirt
setblock ~60 ~129 ~108 dirt
setblock ~60 ~129 ~109 dirt
setblock ~60 ~129 ~110 dirt
setblock ~60 ~129 ~111 dirt
setblock ~60 ~129 ~112 dirt
setblock ~60 ~129 ~113 grass_block
setblock ~60 ~129 ~114 grass_block
setblock ~60 ~129 ~115 grass_block
setblock ~60 ~130 ~100 grass_block
setblock ~60 ~130 ~101 grass_block
setblock ~60 ~130 ~102 grass_block
setblock ~60 ~130 ~103 grass_block
setblock ~60 ~130 ~104 grass_block
setblock ~60 ~130 ~105 grass_block
setblock ~60 ~130 ~106 grass_block
setblock ~60 ~130 ~107 grass_block
setblock ~60 ~130 ~108 grass_block
setblock ~60 ~130 ~109 grass_block
setblock ~60 ~130 ~110 grass_block
setblock ~60 ~130 ~111 grass_block
setblock ~60 ~130 ~112 grass_block
setblock ~60 ~131 ~100 short_grass
setblock ~60 ~131 ~104 fern
setblock ~60 ~131 ~107 poppy
setblock ~60 ~131 ~108 short_grass
setblock ~60 ~131 ~110 poppy
setblock ~61 ~107 ~101 dirt
setblock ~61 ~108 ~101 dirt
setblock ~61 ~109 ~101 dirt
setblock ~61 ~109 ~102 dirt
setblock ~61 ~110 ~101 dirt
setblock ~61 ~110 ~102 dirt
setblock ~61 ~111 ~98 dirt
setblock ~61 ~111 ~99 dirt
setblock ~61 ~111 ~100 dirt
setblock ~61 ~111 ~101 dirt
setblock ~61 ~111 ~102 dirt
setblock ~61 ~111 ~103 dirt
setblock ~61 ~111 ~108 dirt
setblock ~61 ~112 ~87 dirt
setblock ~61 ~112 ~90 dirt
setblock ~61 ~112 ~91 dirt
setblock ~61 ~112 ~97 dirt
setblock ~61 ~112 ~98 dirt
setblock ~61 ~112 ~99 dirt
setblock ~61 ~112 ~100 dirt
setblock ~61 ~112 ~101 dirt
setblock ~61 ~112 ~102 dirt
setblock ~61 ~112 ~103 dirt
setblock ~61 ~112 ~108 dirt
setblock ~61 ~112 ~109 dirt
setblock ~61 ~113 ~87 dirt
setblock ~61 ~113 ~90 dirt
setblock ~61 ~113 ~91 dirt
setblock ~61 ~113 ~97 dirt
setblock ~61 ~113 ~98 dirt
setblock ~61 ~113 ~99 dirt
setblock ~61 ~113 ~100 dirt
setblock ~61 ~113 ~101 dirt
setblock ~61 ~113 ~102 dirt
setblock ~61 ~113 ~103 dirt
setblock ~61 ~113 ~104 dirt
setblock ~61 ~113 ~107 dirt
setblock ~61 ~113 ~108 dirt
setblock ~61 ~113 ~109 dirt
setblock ~61 ~114 ~86 dirt
setblock ~61 ~114 ~87 dirt
setblock ~61 ~114 ~90 dirt
setblock ~61 ~114 ~91 dirt
setblock ~61 ~114 ~95 dirt
setblock ~61 ~114 ~96 dirt
setblock ~61 ~114 ~97 dirt
setblock ~61 ~114 ~98 dirt
setblock ~61 ~114 ~99 dirt
setblock ~61 ~114 ~100 dirt
setblock ~61 ~114 ~101 dirt
setblock ~61 ~114 ~102 dirt
setblock ~61 ~114 ~103 dirt
setblock ~61 ~114 ~104 dirt
setblock ~61 ~114 ~106 dirt
setblock ~61 ~114 ~107 dirt
setblock ~61 ~114 ~108 dirt
setblock ~61 ~114 ~109 dirt
setblock ~61 ~114 ~110 dirt
setblock ~61 ~115 ~85 dirt
setblock ~61 ~115 ~86 dirt
setblock ~61 ~115 ~87 dirt
setblock ~61 ~115 ~88 dirt
setblock ~61 ~115 ~89 dirt
setblock ~61 ~115 ~90 dirt
setblock ~61 ~115 ~91 dirt
setblock ~61 ~115 ~92 dirt
setblock ~61 ~115 ~93 dirt
setblock ~61 ~115 ~95 dirt
setblock ~61 ~115 ~96 dirt
setblock ~61 ~115 ~97 dirt
setblock ~61 ~115 ~98 dirt
setblock ~61 ~115 ~99 dirt
setblock ~61 ~115 ~100 dirt
setblock ~61 ~115 ~101 dirt
setblock ~61 ~115 ~102 dirt
setblock ~61 ~115 ~103 dirt
setblock ~61 ~115 ~104 dirt
setblock ~61 ~115 ~105 dirt
setblock ~61 ~115 ~106 dirt
setblock ~61 ~115 ~107 dirt
setblock ~61 ~115 ~108 dirt
setblock ~61 ~115 ~109 dirt
setblock ~61 ~115 ~110 dirt
setblock ~61 ~115 ~111 dirt
setblock ~61 ~116 ~85 dirt
setblock ~61 ~116 ~86 dirt
setblock ~61 ~116 ~87 dirt
setblock ~61 ~116 ~88 dirt
setblock ~61 ~116 ~89 dirt
setblock ~61 ~116 ~90 dirt
setblock ~61 ~116 ~91 dirt
setblock ~61 ~116 ~92 dirt
setblock ~61 ~116 ~93 dirt
setblock ~61 ~116 ~94 dirt
setblock ~61 ~116 ~95 dirt
setblock ~61 ~116 ~96 dirt
setblock ~61 ~116 ~97 dirt
setblock ~61 ~116 ~98 dirt
setblock ~61 ~116 ~99 dirt
setblock ~61 ~116 ~100 dirt
setblock ~61 ~116 ~101 dirt
setblock ~61 ~116 ~102 dirt
setblock ~61 ~116 ~103 dirt
setblock ~61 ~116 ~104 dirt
setblock ~61 ~116 ~105 dirt
setblock ~61 ~116 ~106 dirt
setblock ~61 ~116 ~107 dirt
setblock ~61 ~116 ~108 dirt
setblock ~61 ~116 ~109 dirt
setblock ~61 ~116 ~110 dirt
setblock ~61 ~116 ~111 dirt
setblock ~61 ~116 ~112 dirt
setblock ~61 ~117 ~84 dirt
setblock ~61 ~117 ~85 dirt
setblock ~61 ~117 ~86 dirt
setblock ~61 ~117 ~87 dirt
setblock ~61 ~117 ~88 dirt
setblock ~61 ~117 ~89 dirt
setblock ~61 ~117 ~90 dirt
setblock ~61 ~117 ~91 dirt
setblock ~61 ~117 ~92 dirt
setblock ~61 ~117 ~93 dirt
setblock ~61 ~117 ~94 dirt
setblock ~61 ~117 ~95 dirt
setblock ~61 ~117 ~96 dirt
setblock ~61 ~117 ~97 dirt
setblock ~61 ~117 ~98 dirt
setblock ~61 ~117 ~99 dirt
setblock ~61 ~117 ~100 dirt
setblock ~61 ~117 ~101 dirt
setblock ~61 ~117 ~102 dirt
setblock ~61 ~117 ~103 dirt
setblock ~61 ~117 ~104 dirt
setblock ~61 ~117 ~105 dirt
setblock ~61 ~117 ~106 dirt
setblock ~61 ~117 ~107 dirt
setblock ~61 ~117 ~108 dirt
setblock ~61 ~117 ~109 dirt
setblock ~61 ~117 ~110 dirt
setblock ~61 ~117 ~111 dirt
setblock ~61 ~117 ~112 dirt
setblock ~61 ~117 ~113 dirt
setblock ~61 ~118 ~80 dirt
setblock ~61 ~118 ~81 dirt
setblock ~61 ~118 ~82 dirt
setblock ~61 ~118 ~83 dirt
setblock ~61 ~118 ~84 dirt
setblock ~61 ~118 ~85 dirt
setblock ~61 ~118 ~86 dirt
setblock ~61 ~118 ~87 dirt
setblock ~61 ~118 ~88 dirt
setblock ~61 ~118 ~89 dirt
setblock ~61 ~118 ~90 dirt
setblock ~61 ~118 ~91 dirt
setblock ~61 ~118 ~92 dirt
setblock ~61 ~118 ~93 dirt
setblock ~61 ~118 ~94 dirt
setblock ~61 ~118 ~95 dirt
setblock ~61 ~118 ~96 dirt
setblock ~61 ~118 ~97 dirt
setblock ~61 ~118 ~98 dirt
setblock ~61 ~118 ~99 dirt
setblock ~61 ~118 ~100 dirt
setblock ~61 ~118 ~101 dirt
setblock ~61 ~118 ~102 dirt
setblock ~61 ~118 ~103 dirt
setblock ~61 ~118 ~104 dirt
setblock ~61 ~118 ~105 dirt
setblock ~61 ~118 ~106 dirt
setblock ~61 ~118 ~107 dirt
setblock ~61 ~118 ~108 dirt
setblock ~61 ~118 ~109 dirt
setblock ~61 ~118 ~110 dirt
setblock ~61 ~118 ~111 dirt
setblock ~61 ~118 ~112 dirt
setblock ~61 ~118 ~113 dirt
setblock ~61 ~118 ~114 dirt
setblock ~61 ~119 ~79 dirt
setblock ~61 ~119 ~80 dirt
setblock ~61 ~119 ~81 dirt
setblock ~61 ~119 ~82 dirt
setblock ~61 ~119 ~83 dirt
setblock ~61 ~119 ~84 dirt
setblock ~61 ~119 ~85 dirt
setblock ~61 ~119 ~86 dirt
setblock ~61 ~119 ~87 dirt
setblock ~61 ~119 ~88 dirt
setblock ~61 ~119 ~89 dirt
setblock ~61 ~119 ~90 dirt
setblock ~61 ~119 ~91 dirt
setblock ~61 ~119 ~92 dirt
setblock ~61 ~119 ~93 dirt
setblock ~61 ~119 ~94 dirt
setblock ~61 ~119 ~95 dirt
setblock ~61 ~119 ~96 dirt
setblock ~61 ~119 ~97 dirt
setblock ~61 ~119 ~98 dirt
setblock ~61 ~119 ~99 dirt
setblock ~61 ~119 ~100 dirt
setblock ~61 ~119 ~101 dirt
setblock ~61 ~119 ~102 dirt
setblock ~61 ~119 ~103 dirt
setblock ~61 ~119 ~104 dirt
setblock ~61 ~119 ~105 dirt
setblock ~61 ~119 ~106 dirt
setblock ~61 ~119 ~107 dirt
setblock ~61 ~119 ~108 dirt
setblock ~61 ~119 ~109 dirt
setblock ~61 ~119 ~110 dirt
setblock ~61 ~119 ~111 dirt
setblock ~61 ~119 ~112 dirt
setblock ~61 ~119 ~113 dirt
setblock ~61 ~119 ~114 dirt
setblock ~61 ~120 ~79 dirt
setblock ~61 ~120 ~80 dirt
setblock ~61 ~120 ~81 dirt
setblock ~61 ~120 ~82 dirt
setblock ~61 ~120 ~83 dirt
setblock ~61 ~120 ~84 dirt
setblock ~61 ~120 ~85 dirt
setblock ~61 ~120 ~86 dirt
setblock ~61 ~120 ~87 dirt
setblock ~61 ~120 ~88 dirt
setblock ~61 ~120 ~89 dirt
setblock ~61 ~120 ~90 dirt
setblock ~61 ~120 ~91 dirt
setblock ~61 ~120 ~92 dirt
setblock ~61 ~120 ~93 dirt
setblock ~61 ~120 ~94 dirt
setblock ~61 ~120 ~95 dirt
setblock ~61 ~120 ~96 dirt
setblock ~61 ~120 ~97 dirt
setblock ~61 ~120 ~98 dirt
setblock ~61 ~120 ~99 dirt
setblock ~61 ~120 ~100 dirt
setblock ~61 ~120 ~101 dirt
setblock ~61 ~120 ~102 dirt
setblock ~61 ~120 ~103 dirt
setblock ~61 ~120 ~104 dirt
setblock ~61 ~120 ~105 dirt
setblock ~61 ~120 ~106 dirt
setblock ~61 ~120 ~107 dirt
setblock ~61 ~120 ~108 dirt
setblock ~61 ~120 ~109 dirt
setblock ~61 ~120 ~110 dirt
setblock ~61 ~120 ~111 dirt
setblock ~61 ~120 ~112 dirt
setblock ~61 ~120 ~113 dirt
setblock ~61 ~120 ~114 dirt
setblock ~61 ~120 ~115 dirt
setblock ~61 ~121 ~78 dirt
setblock ~61 ~121 ~79 dirt
setblock ~61 ~121 ~80 dirt
setblock ~61 ~121 ~81 dirt
setblock ~61 ~121 ~82 dirt
setblock ~61 ~121 ~83 dirt
setblock ~61 ~121 ~84 dirt
setblock ~61 ~121 ~85 dirt
setblock ~61 ~121 ~86 dirt
setblock ~61 ~121 ~87 dirt
setblock ~61 ~121 ~88 dirt
setblock ~61 ~121 ~89 dirt
setblock ~61 ~121 ~90 dirt
setblock ~61 ~121 ~91 dirt
setblock ~61 ~121 ~92 dirt
setblock ~61 ~121 ~93 dirt
setblock ~61 ~121 ~94 dirt
setblock ~61 ~121 ~95 dirt
setblock ~61 ~121 ~96 dirt
setblock ~61 ~121 ~97 dirt
setblock ~61 ~121 ~98 dirt
setblock ~61 ~121 ~99 dirt
setblock ~61 ~121 ~100 dirt
setblock ~61 ~121 ~101 dirt
setblock ~61 ~121 ~102 dirt
setblock ~61 ~121 ~103 dirt
setblock ~61 ~121 ~104 dirt
setblock ~61 ~121 ~105 dirt
setblock ~61 ~121 ~106 dirt
setblock ~61 ~121 ~107 dirt
setblock ~61 ~121 ~108 dirt
setblock ~61 ~121 ~109 dirt
setblock ~61 ~121 ~110 dirt
setblock ~61 ~121 ~111 dirt
setblock ~61 ~121 ~112 dirt
setblock ~61 ~121 ~113 dirt
setblock ~61 ~121 ~114 dirt
setblock ~61 ~121 ~115 dirt
setblock ~61 ~121 ~116 dirt
setblock ~61 ~122 ~78 dirt
setblock ~61 ~122 ~79 dirt
setblock ~61 ~122 ~80 dirt
setblock ~61 ~122 ~81 dirt
setblock ~61 ~122 ~82 dirt
setblock ~61 ~122 ~83 dirt
setblock ~61 ~122 ~84 dirt
setblock ~61 ~122 ~85 dirt
setblock ~61 ~122 ~86 dirt
setblock ~61 ~122 ~87 dirt
setblock ~61 ~122 ~88 dirt
setblock ~61 ~122 ~89 dirt
setblock ~61 ~122 ~90 dirt
setblock ~61 ~122 ~91 dirt
setblock ~61 ~122 ~92 dirt
setblock ~61 ~122 ~93 dirt
setblock ~61 ~122 ~94 dirt
setblock ~61 ~122 ~95 dirt
setblock ~61 ~122 ~96 dirt
setblock ~61 ~122 ~97 dirt
setblock ~61 ~122 ~98 dirt
setblock ~61 ~122 ~99 dirt
setblock ~61 ~122 ~100 dirt
setblock ~61 ~122 ~101 dirt
setblock ~61 ~122 ~102 dirt
setblock ~61 ~122 ~103 dirt
setblock ~61 ~122 ~104 dirt
setblock ~61 ~122 ~105 dirt
setblock ~61 ~122 ~106 dirt
setblock ~61 ~122 ~107 dirt
setblock ~61 ~122 ~108 dirt
setblock ~61 ~122 ~109 dirt
setblock ~61 ~122 ~110 dirt
setblock ~61 ~122 ~111 dirt
setblock ~61 ~122 ~112 dirt
setblock ~61 ~122 ~113 dirt
setblock ~61 ~122 ~114 dirt
setblock ~61 ~122 ~115 dirt
setblock ~61 ~122 ~116 dirt
setblock ~61 ~123 ~78 grass_block
setblock ~61 ~123 ~79 grass_block
setblock ~61 ~123 ~80 grass_block
setblock ~61 ~123 ~81 grass_block
setblock ~61 ~123 ~82 grass_block
setblock ~61 ~123 ~83 grass_block
setblock ~61 ~123 ~84 grass_block
setblock ~61 ~123 ~85 grass_block
setblock ~61 ~123 ~86 grass_block
setblock ~61 ~123 ~87 grass_block
setblock ~61 ~123 ~88 grass_block
setblock ~61 ~123 ~89 grass_block
setblock ~61 ~123 ~90 grass_block
setblock ~61 ~123 ~91 dirt
setblock ~61 ~123 ~92 dirt
setblock ~61 ~123 ~93 dirt
setblock ~61 ~123 ~94 dirt
setblock ~61 ~123 ~95 dirt
setblock ~61 ~123 ~96 dirt
setblock ~61 ~123 ~97 dirt
setblock ~61 ~123 ~98 dirt
setblock ~61 ~123 ~99 dirt
setblock ~61 ~123 ~100 dirt
setblock ~61 ~123 ~101 dirt
setblock ~61 ~123 ~102 dirt
setblock ~61 ~123 ~103 dirt
setblock ~61 ~123 ~104 dirt
setblock ~61 ~123 ~105 dirt
setblock ~61 ~123 ~106 dirt
setblock ~61 ~123 ~107 dirt
setblock ~61 ~123 ~108 dirt
setblock ~61 ~123 ~109 dirt
setblock ~61 ~123 ~110 dirt
setblock ~61 ~123 ~111 dirt
setblock ~61 ~123 ~112 dirt
setblock ~61 ~123 ~113 dirt
setblock ~61 ~123 ~114 dirt
setblock ~61 ~123 ~115 dirt
setblock ~61 ~123 ~116 dirt
setblock ~61 ~124 ~81 short_grass
setblock ~61 ~124 ~82 fern
setblock ~61 ~124 ~90 short_grass
setblock ~61 ~124 ~91 grass_block
setblock ~61 ~124 ~92 grass_block
setblock ~61 ~124 ~93 grass_block
setblock ~61 ~124 ~94 grass_block
setblock ~61 ~124 ~95 grass_block
setblock ~61 ~124 ~96 dirt
setblock ~61 ~124 ~97 dirt
setblock ~61 ~124 ~98 dirt
setblock ~61 ~124 ~99 dirt
setblock ~61 ~124 ~100 dirt
setblock ~61 ~124 ~101 dirt
setblock ~61 ~124 ~102 dirt
setblock ~61 ~124 ~103 dirt
setblock ~61 ~124 ~104 dirt
setblock ~61 ~124 ~105 dirt
setblock ~61 ~124 ~106 dirt
setblock ~61 ~124 ~107 dirt
setblock ~61 ~124 ~108 dirt
setblock ~61 ~124 ~109 dirt
setblock ~61 ~124 ~110 dirt
setblock ~61 ~124 ~111 dirt
setblock ~61 ~124 ~112 dirt
setblock ~61 ~124 ~113 dirt
setblock ~61 ~124 ~114 dirt
setblock ~61 ~124 ~115 dirt
setblock ~61 ~124 ~116 dirt
setblock ~61 ~125 ~96 grass_block
setblock ~61 ~125 ~97 grass_block
setblock ~61 ~125 ~98 dirt
setblock ~61 ~125 ~99 dirt
setblock ~61 ~125 ~100 dirt
setblock ~61 ~125 ~101 dirt
setblock ~61 ~125 ~102 dirt
setblock ~61 ~125 ~103 dirt
setblock ~61 ~125 ~104 dirt
setblock ~61 ~125 ~105 dirt
setblock ~61 ~125 ~106 dirt
setblock ~61 ~125 ~107 dirt
setblock ~61 ~125 ~108 dirt
setblock ~61 ~125 ~109 dirt
setblock ~61 ~125 ~110 dirt
setblock ~61 ~125 ~111 dirt
setblock ~61 ~125 ~112 dirt
setblock ~61 ~125 ~113 dirt
setblock ~61 ~125 ~114 dirt
setblock ~61 ~125 ~115 dirt
setblock ~61 ~125 ~116 dirt
setblock ~61 ~126 ~98 grass_block
setblock ~61 ~126 ~99 dirt
setblock ~61 ~126 ~100 dirt
setblock ~61 ~126 ~101 dirt
setblock ~61 ~126 ~102 dirt
setblock ~61 ~126 ~103 dirt
setblock ~61 ~126 ~104 dirt
setblock ~61 ~126 ~105 dirt
setblock ~61 ~126 ~106 dirt
setblock ~61 ~126 ~107 dirt
setblock ~61 ~126 ~108 dirt
setblock ~61 ~126 ~109 dirt
setblock ~61 ~126 ~110 dirt
setblock ~61 ~126 ~111 dirt
setblock ~61 ~126 ~112 dirt
setblock ~61 ~126 ~113 dirt
setblock ~61 ~126 ~114 dirt
setblock ~61 ~126 ~115 dirt
setblock ~61 ~126 ~116 dirt
setblock ~61 ~127 ~99 grass_block
setblock ~61 ~127 ~100 dirt
setblock ~61 ~127 ~101 dirt
setblock ~61 ~127 ~102 dirt
setblock ~61 ~127 ~103 dirt
setblock ~61 ~127 ~104 dirt
setblock ~61 ~127 ~105 dirt
setblock ~61 ~127 ~106 dirt
setblock ~61 ~127 ~107 dirt
setblock ~61 ~127 ~108 dirt
setblock ~61 ~127 ~109 dirt
setblock ~61 ~127 ~110 dirt
setblock ~61 ~127 ~111 dirt
setblock ~61 ~127 ~112 dirt
setblock ~61 ~127 ~113 dirt
setblock ~61 ~127 ~114 dirt
setblock ~61 ~127 ~115 dirt
setblock ~61 ~127 ~116 dirt
setblock ~61 ~128 ~100 dirt
setblock ~61 ~128 ~101 dirt
setblock ~61 ~128 ~102 dirt
setblock ~61 ~128 ~103 dirt
setblock ~61 ~128 ~104 dirt
setblock ~61 ~128 ~105 dirt
setblock ~61 ~128 ~106 dirt
setblock ~61 ~128 ~107 dirt
setblock ~61 ~128 ~108 dirt
setblock ~61 ~128 ~109 dirt
setblock ~61 ~128 ~110 dirt
setblock ~61 ~128 ~111 dirt
setblock ~61 ~128 ~112 dirt
setblock ~61 ~128 ~113 grass_block
setblock ~61 ~128 ~114 grass_block
setblock ~61 ~128 ~115 grass_block
setblock ~61 ~128 ~116 grass_block
setblock ~61 ~129 ~100 dirt
setblock ~61 ~129 ~101 dirt
setblock ~61 ~129 ~102 grass_block
setblock ~61 ~129 ~103 grass_block
setblock ~61 ~129 ~104 grass_block
setblock ~61 ~129 ~105 grass_block
setblock ~61 ~129 ~106 grass_block
setblock ~61 ~129 ~107 grass_block
setblock ~61 ~129 ~108 grass_block
setblock ~61 ~129 ~109 grass_block
setblock ~61 ~129 ~110 grass_block
setblock ~61 ~129 ~111 grass_block
setblock ~61 ~129 ~112 grass_block
setblock ~61 ~129 ~113 short_grass
setblock ~61 ~129 ~116 fern
setblock ~61 ~130 ~100 grass_block
setblock ~61 ~130 ~101 grass_block
setblock ~61 ~130 ~106 short_grass
setblock ~61 ~130 ~110 short_grass
setblock ~61 ~130 ~111 short_grass
setblock ~61 ~131 ~101 fern
setblock ~62 ~105 ~101 dirt
setblock ~62 ~106 ~101 dirt
setblock ~62 ~107 ~100 dirt
setblock ~62 ~107 ~101 dirt
setblock ~62 ~107 ~102 dirt
setblock ~62 ~108 ~100 dirt
setblock ~62 ~108 ~101 dirt
setblock ~62 ~108 ~102 dirt
setblock ~62 ~109 ~100 dirt
setblock ~62 ~109 ~101 dirt
setblock ~62 ~109 ~102 dirt
setblock ~62 ~109 ~103 dirt
setblock ~62 ~109 ~108 dirt
setblock ~62 ~110 ~87 dirt
setblock ~62 ~110 ~96 dirt
setblock ~62 ~110 ~97 dirt
setblock ~62 ~110 ~98 dirt
setblock ~62 ~110 ~99 dirt
setblock ~62 ~110 ~100 dirt
setblock ~62 ~110 ~101 dirt
setblock ~62 ~110 ~102 dirt
setblock ~62 ~110 ~103 dirt
setblock ~62 ~110 ~108 dirt
setblock ~62 ~111 ~86 dirt
setblock ~62 ~111 ~87 dirt
setblock ~62 ~111 ~90 dirt
setblock ~62 ~111 ~91 dirt
setblock ~62 ~111 ~92 dirt
setblock ~62 ~111 ~96 dirt
setblock ~62 ~111 ~97 dirt
setblock ~62 ~111 ~98 dirt
setblock ~62 ~111 ~99 dirt
setblock ~62 ~111 ~100 dirt
setblock ~62 ~111 ~101 dirt
setblock ~62 ~111 ~102 dirt
setblock ~62 ~111 ~103 dirt
setblock ~62 ~111 ~104 dirt
setblock ~62 ~111 ~107 dirt
setblock ~62 ~111 ~108 dirt
setblock ~62 ~111 ~109 dirt
setblock ~62 ~112 ~86 dirt
setblock ~62 ~112 ~87 dirt
setblock ~62 ~112 ~88 dirt
setblock ~62 ~112 ~89 dirt
setblock ~62 ~112 ~90 dirt
setblock ~62 ~112 ~91 dirt
setblock ~62 ~112 ~92 dirt
setblock ~62 ~112 ~94 dirt
setblock ~62 ~112 ~95 dirt
setblock ~62 ~112 ~96 dirt
setblock ~62 ~112 ~97 dirt
setblock ~62 ~112 ~98 dirt
setblock ~62 ~112 ~99 dirt
setblock ~62 ~112 ~100 dirt
setblock ~62 ~112 ~101 dirt
setblock ~62 ~112 ~102 dirt
setblock ~62 ~112 ~103 dirt
setblock ~62 ~112 ~104 dirt
setblock ~62 ~112 ~107 dirt
setblock ~62 ~112 ~108 dirt
setblock ~62 ~112 ~109 dirt
setblock ~62 ~112 ~110 dirt
setblock ~62 ~113 ~85 dirt
setblock ~62 ~113 ~86 dirt
setblock ~62 ~113 ~87 dirt
setblock ~62 ~113 ~88 dirt
setblock ~62 ~113 ~89 dirt
setblock ~62 ~113 ~90 dirt
setblock ~62 ~113 ~91 dirt
setblock ~62 ~113 ~92 dirt
setblock ~62 ~113 ~94 dirt
setblock ~62 ~113 ~95 dirt
setblock ~62 ~113 ~96 dirt
setblock ~62 ~113 ~97 dirt
setblock ~62 ~113 ~98 dirt
setblock ~62 ~113 ~99 dirt
setblock ~62 ~113 ~100 dirt
setblock ~62 ~113 ~101 dirt
setblock ~62 ~113 ~102 dirt
setblock ~62 ~113 ~103 dirt
setblock ~62 ~113 ~104 dirt
setblock ~62 ~113 ~106 dirt
setblock ~62 ~113 ~107 dirt
setblock ~62 ~113 ~108 dirt
setblock ~62 ~113 ~109 dirt
setblock ~62 ~113 ~110 dirt
setblock ~62 ~114 ~85 dirt
setblock ~62 ~114 ~86 dirt
setblock ~62 ~114 ~87 dirt
setblock ~62 ~114 ~88 dirt
setblock ~62 ~114 ~89 dirt
setblock ~62 ~114 ~90 dirt
setblock ~62 ~114 ~91 dirt
setblock ~62 ~114 ~92 dirt
setblock ~62 ~114 ~93 dirt
setblock ~62 ~114 ~94 dirt
setblock ~62 ~114 ~95 dirt
setblock ~62 ~114 ~96 dirt
setblock ~62 ~114 ~97 dirt
setblock ~62 ~114 ~98 dirt
setblock ~62 ~114 ~99 dirt
setblock ~62 ~114 ~100 dirt
setblock ~62 ~114 ~101 dirt
setblock ~62 ~114 ~102 dirt
setblock ~62 ~114 ~103 dirt
setblock ~62 ~114 ~104 dirt
setblock ~62 ~114 ~105 dirt
setblock ~62 ~114 ~106 dirt
setblock ~62 ~114 ~107 dirt
setblock ~62 ~114 ~108 dirt
setblock ~62 ~114 ~109 dirt
setblock ~62 ~114 ~110 dirt
setblock ~62 ~114 ~111 dirt
setblock ~62 ~115 ~84 dirt
setblock ~62 ~115 ~85 dirt
setblock ~62 ~115 ~86 dirt
setblock ~62 ~115 ~87 dirt
setblock ~62 ~115 ~88 dirt
setblock ~62 ~115 ~89 dirt
setblock ~62 ~115 ~90 dirt
setblock ~62 ~115 ~91 dirt
setblock ~62 ~115 ~92 dirt
setblock ~62 ~115 ~93 dirt
setblock ~62 ~115 ~94 dirt
setblock ~62 ~115 ~95 dirt
setblock ~62 ~115 ~96 dirt
setblock ~62 ~115 ~97 dirt
setblock ~62 ~115 ~98 dirt
setblock ~62 ~115 ~99 dirt
setblock ~62 ~115 ~100 dirt
setblock ~62 ~115 ~101 dirt
setblock ~62 ~115 ~102 dirt
setblock ~62 ~115 ~103 dirt
setblock ~62 ~115 ~104 dirt
setblock ~62 ~115 ~105 dirt
setblock ~62 ~115 ~106 dirt
setblock ~62 ~115 ~107 dirt
setblock ~62 ~115 ~108 dirt
setblock ~62 ~115 ~109 dirt
setblock ~62 ~115 ~110 dirt
setblock ~62 ~115 ~111 dirt
setblock ~62 ~115 ~112 dirt
setblock ~62 ~115 ~113 dirt
setblock ~62 ~116 ~81 dirt
setblock ~62 ~116 ~82 dirt
setblock ~62 ~116 ~83 dirt
setblock ~62 ~116 ~84 dirt
setblock ~62 ~116 ~85 dirt
setblock ~62 ~116 ~86 dirt
setblock ~62 ~116 ~87 dirt
setblock ~62 ~116 ~88 dirt
setblock ~62 ~116 ~89 dirt
setblock ~62 ~116 ~90 dirt
setblock ~62 ~116 ~91 dirt
setblock ~62 ~116 ~92 dirt
setblock ~62 ~116 ~93 dirt
setblock ~62 ~116 ~94 dirt
setblock ~62 ~116 ~95 dirt
setblock ~62 ~116 ~96 dirt
setblock ~62 ~116 ~97 dirt
setblock ~62 ~116 ~98 dirt
setblock ~62 ~116 ~99 dirt
setblock ~62 ~116 ~100 dirt
setblock ~62 ~116 ~101 dirt
setblock ~62 ~116 ~102 dirt
setblock ~62 ~116 ~103 dirt
setblock ~62 ~116 ~104 dirt
setblock ~62 ~116 ~105 dirt
setblock ~62 ~116 ~106 dirt
setblock ~62 ~116 ~107 dirt
setblock ~62 ~116 ~108 dirt
setblock ~62 ~116 ~109 dirt
setblock ~62 ~116 ~110 dirt
setblock ~62 ~116 ~111 dirt
setblock ~62 ~116 ~112 dirt
setblock ~62 ~116 ~113 dirt
setblock ~62 ~117 ~80 dirt
setblock ~62 ~117 ~81 dirt
setblock ~62 ~117 ~82 dirt
setblock ~62 ~117 ~83 dirt
setblock ~62 ~117 ~84 dirt
setblock ~62 ~117 ~85 dirt
setblock ~62 ~117 ~86 dirt
setblock ~62 ~117 ~87 dirt
setblock ~62 ~117 ~88 dirt
setblock ~62 ~117 ~89 dirt
setblock ~62 ~117 ~90 dirt
setblock ~62 ~117 ~91 dirt
setblock ~62 ~117 ~92 dirt
setblock ~62 ~117 ~93 dirt
setblock ~62 ~117 ~94 dirt
setblock ~62 ~117 ~95 dirt
setblock ~62 ~117 ~96 dirt
setblock ~62 ~117 ~97 dirt
setblock ~62 ~117 ~98 dirt
setblock ~62 ~117 ~99 dirt
setblock ~62 ~117 ~100 dirt
setblock ~62 ~117 ~101 dirt
setblock ~62 ~117 ~102 dirt
setblock ~62 ~117 ~103 dirt
setblock ~62 ~117 ~104 dirt
setblock ~62 ~117 ~105 dirt
setblock ~62 ~117 ~106 dirt
setblock ~62 ~117 ~107 dirt
setblock ~62 ~117 ~108 dirt
setblock ~62 ~117 ~109 dirt
setblock ~62 ~117 ~110 dirt
setblock ~62 ~117 ~111 dirt
setblock ~62 ~117 ~112 dirt
setblock ~62 ~117 ~113 dirt
setblock ~62 ~117 ~114 dirt
setblock ~62 ~118 ~79 dirt
setblock ~62 ~118 ~80 dirt
setblock ~62 ~118 ~81 dirt
setblock ~62 ~118 ~82 dirt
setblock ~62 ~118 ~83 dirt
setblock ~62 ~118 ~84 dirt
setblock ~62 ~118 ~85 dirt
setblock ~62 ~118 ~86 dirt
setblock ~62 ~118 ~87 dirt
setblock ~62 ~118 ~88 dirt
setblock ~62 ~118 ~89 dirt
setblock ~62 ~118 ~90 dirt
setblock ~62 ~118 ~91 dirt
setblock ~62 ~118 ~92 dirt
setblock ~62 ~118 ~93 dirt
setblock ~62 ~118 ~94 dirt
setblock ~62 ~118 ~95 dirt
setblock ~62 ~118 ~96 dirt
setblock ~62 ~118 ~97 dirt
setblock ~62 ~118 ~98 dirt
setblock ~62 ~118 ~99 dirt
setblock ~62 ~118 ~100 dirt
setblock ~62 ~118 ~101 dirt
setblock ~62 ~118 ~102 dirt
setblock ~62 ~118 ~103 dirt
setblock ~62 ~118 ~104 dirt
setblock ~62 ~118 ~105 dirt
setblock ~62 ~118 ~106 dirt
setblock ~62 ~118 ~107 dirt
setblock ~62 ~118 ~108 dirt
setblock ~62 ~118 ~109 dirt
setblock ~62 ~118 ~110 dirt
setblock ~62 ~118 ~111 dirt
setblock ~62 ~118 ~112 dirt
setblock ~62 ~118 ~113 dirt
setblock ~62 ~118 ~114 dirt
setblock ~62 ~118 ~115 dirt
setblock ~62 ~119 ~78 dirt
setblock ~62 ~119 ~79 dirt
setblock ~62 ~119 ~80 dirt
setblock ~62 ~119 ~81 dirt
setblock ~62 ~119 ~82 dirt
setblock ~62 ~119 ~83 dirt
setblock ~62 ~119 ~84 dirt
setblock ~62 ~119 ~85 dirt
setblock ~62 ~119 ~86 dirt
setblock ~62 ~119 ~87 dirt
setblock ~62 ~119 ~88 dirt
setblock ~62 ~119 ~89 dirt
setblock ~62 ~119 ~90 dirt
setblock ~62 ~119 ~91 dirt
setblock ~62 ~119 ~92 dirt
setblock ~62 ~119 ~93 dirt
setblock ~62 ~119 ~94 dirt
setblock ~62 ~119 ~95 dirt
setblock ~62 ~119 ~96 dirt
setblock ~62 ~119 ~97 dirt
setblock ~62 ~119 ~98 dirt
setblock ~62 ~119 ~99 dirt
setblock ~62 ~119 ~100 dirt
setblock ~62 ~119 ~101 dirt
setblock ~62 ~119 ~102 dirt
setblock ~62 ~119 ~103 dirt
setblock ~62 ~119 ~104 dirt
setblock ~62 ~119 ~105 dirt
setblock ~62 ~119 ~106 dirt
setblock ~62 ~119 ~107 dirt
setblock ~62 ~119 ~108 dirt
setblock ~62 ~119 ~109 dirt
setblock ~62 ~119 ~110 dirt
setblock ~62 ~119 ~111 dirt
setblock ~62 ~119 ~112 dirt
setblock ~62 ~119 ~113 dirt
setblock ~62 ~119 ~114 dirt
setblock ~62 ~119 ~115 dirt
setblock ~62 ~119 ~116 dirt
setblock ~62 ~120 ~77 dirt
setblock ~62 ~120 ~78 dirt
setblock ~62 ~120 ~79 dirt
setblock ~62 ~120 ~80 dirt
setblock ~62 ~120 ~81 dirt
setblock ~62 ~120 ~82 dirt
setblock ~62 ~120 ~83 dirt
setblock ~62 ~120 ~84 dirt
setblock ~62 ~120 ~85 dirt
setblock ~62 ~120 ~86 dirt
setblock ~62 ~120 ~87 dirt
setblock ~62 ~120 ~88 dirt
setblock ~62 ~120 ~89 dirt
setblock ~62 ~120 ~90 dirt
setblock ~62 ~120 ~91 dirt
setblock ~62 ~120 ~92 dirt
setblock ~62 ~120 ~93 dirt
setblock ~62 ~120 ~94 dirt
setblock ~62 ~120 ~95 dirt
setblock ~62 ~120 ~96 dirt
setblock ~62 ~120 ~97 dirt
setblock ~62 ~120 ~98 dirt
setblock ~62 ~120 ~99 dirt
setblock ~62 ~120 ~100 dirt
setblock ~62 ~120 ~101 dirt
setblock ~62 ~120 ~102 dirt
setblock ~62 ~120 ~103 dirt
setblock ~62 ~120 ~104 dirt
setblock ~62 ~120 ~105 dirt
setblock ~62 ~120 ~106 dirt
setblock ~62 ~120 ~107 dirt
setblock ~62 ~120 ~108 dirt
setblock ~62 ~120 ~109 dirt
setblock ~62 ~120 ~110 dirt
setblock ~62 ~120 ~111 dirt
setblock ~62 ~120 ~112 dirt
setblock ~62 ~120 ~113 dirt
setblock ~62 ~120 ~114 dirt
setblock ~62 ~120 ~115 dirt
setblock ~62 ~120 ~116 dirt
setblock ~62 ~120 ~118 dirt
setblock ~62 ~121 ~77 dirt
setblock ~62 ~121 ~78 dirt
setblock ~62 ~121 ~79 dirt
setblock ~62 ~121 ~80 dirt
setblock ~62 ~121 ~81 dirt
setblock ~62 ~121 ~82 dirt
setblock ~62 ~121 ~83 dirt
setblock ~62 ~121 ~84 dirt
setblock ~62 ~121 ~85 dirt
setblock ~62 ~121 ~86 dirt
setblock ~62 ~121 ~87 dirt
setblock ~62 ~121 ~88 dirt
setblock ~62 ~121 ~89 dirt
setblock ~62 ~121 ~90 dirt
setblock ~62 ~121 ~91 dirt
setblock ~62 ~121 ~92 dirt
setblock ~62 ~121 ~93 dirt
setblock ~62 ~121 ~94 dirt
setblock ~62 ~121 ~95 dirt
setblock ~62 ~121 ~96 dirt
setblock ~62 ~121 ~97 dirt
setblock ~62 ~121 ~98 dirt
setblock ~62 ~121 ~99 dirt
setblock ~62 ~121 ~100 dirt
setblock ~62 ~121 ~101 dirt
setblock ~62 ~121 ~102 dirt
setblock ~62 ~121 ~103 dirt
setblock ~62 ~121 ~104 dirt
setblock ~62 ~121 ~105 dirt
setblock ~62 ~121 ~106 dirt
setblock ~62 ~121 ~107 dirt
setblock ~62 ~121 ~108 dirt
setblock ~62 ~121 ~109 dirt
setblock ~62 ~121 ~110 dirt
setblock ~62 ~121 ~111 dirt
setblock ~62 ~121 ~112 dirt
setblock ~62 ~121 ~113 dirt
setblock ~62 ~121 ~114 dirt
setblock ~62 ~121 ~115 dirt
setblock ~62 ~121 ~116 dirt
setblock ~62 ~121 ~117 dirt
setblock ~62 ~121 ~118 dirt
setblock ~62 ~121 ~119 dirt
setblock ~62 ~122 ~77 dirt
setblock ~62 ~122 ~78 dirt
setblock ~62 ~122 ~79 dirt
setblock ~62 ~122 ~80 dirt
setblock ~62 ~122 ~81 dirt
setblock ~62 ~122 ~82 dirt
setblock ~62 ~122 ~83 dirt
setblock ~62 ~122 ~84 dirt
setblock ~62 ~122 ~85 dirt
setblock ~62 ~122 ~86 dirt
setblock ~62 ~122 ~87 dirt
setblock ~62 ~122 ~88 dirt
setblock ~62 ~122 ~89 dirt
setblock ~62 ~122 ~90 dirt
setblock ~62 ~122 ~91 dirt
setblock ~62 ~122 ~92 dirt
setblock ~62 ~122 ~93 dirt
setblock ~62 ~122 ~94 dirt
setblock ~62 ~122 ~95 dirt
setblock ~62 ~122 ~96 dirt
setblock ~62 ~122 ~97 dirt
setblock ~62 ~122 ~98 dirt
setblock ~62 ~122 ~99 dirt
setblock ~62 ~122 ~100 dirt
setblock ~62 ~122 ~101 dirt
setblock ~62 ~122 ~102 dirt
setblock ~62 ~122 ~103 dirt
setblock ~62 ~122 ~104 dirt
