setblock ~155 ~125 ~176 short_grass
setblock ~155 ~125 ~179 short_grass
setblock ~155 ~125 ~180 grass_block
setblock ~155 ~125 ~181 grass_block
setblock ~155 ~125 ~182 grass_block
setblock ~155 ~125 ~183 grass_block
setblock ~155 ~125 ~184 grass_block
setblock ~155 ~125 ~185 grass_block
setblock ~155 ~125 ~186 grass_block
setblock ~155 ~125 ~187 grass_block
setblock ~155 ~125 ~188 grass_block
setblock ~155 ~125 ~189 grass_block
setblock ~155 ~125 ~190 dirt
setblock ~155 ~125 ~191 dirt
setblock ~155 ~125 ~192 dirt
setblock ~155 ~125 ~193 dirt
setblock ~155 ~125 ~194 dirt
setblock ~155 ~125 ~195 dirt
setblock ~155 ~125 ~196 dirt
setblock ~155 ~125 ~197 dirt
setblock ~155 ~125 ~198 dirt
setblock ~155 ~125 ~199 dirt
setblock ~155 ~126 ~35 short_grass
setblock ~155 ~126 ~38 grass_block
setblock ~155 ~126 ~39 grass_block
setblock ~155 ~126 ~40 grass_block
setblock ~155 ~126 ~41 grass_block
setblock ~155 ~126 ~42 grass_block
setblock ~155 ~126 ~43 grass_block
setblock ~155 ~126 ~44 dirt
setblock ~155 ~126 ~45 dirt
setblock ~155 ~126 ~46 dirt
setblock ~155 ~126 ~47 dirt
setblock ~155 ~126 ~48 dirt
setblock ~155 ~126 ~49 dirt
setblock ~155 ~126 ~50 dirt
setblock ~155 ~126 ~51 dirt
setblock ~155 ~126 ~52 grass_block
setblock ~155 ~126 ~53 grass_block
setblock ~155 ~126 ~54 grass_block
setblock ~155 ~126 ~55 short_grass
setblock ~155 ~126 ~75 grass_block
setblock ~155 ~126 ~76 grass_block
setblock ~155 ~126 ~77 grass_block
setblock ~155 ~126 ~78 dirt
setblock ~155 ~126 ~79 dirt
setblock ~155 ~126 ~80 dirt
setblock ~155 ~126 ~81 dirt
setblock ~155 ~126 ~82 dirt
setblock ~155 ~126 ~83 dirt
setblock ~155 ~126 ~84 grass_block
setblock ~155 ~126 ~85 grass_block
setblock ~155 ~126 ~86 grass_block
setblock ~155 ~126 ~87 short_grass
setblock ~155 ~126 ~88 short_grass
setblock ~155 ~126 ~89 short_grass
setblock ~155 ~126 ~94 grass_block
setblock ~155 ~126 ~95 grass_block
setblock ~155 ~126 ~96 grass_block
setblock ~155 ~126 ~97 grass_block
setblock ~155 ~126 ~98 grass_block
setblock ~155 ~126 ~99 dirt
setblock ~155 ~126 ~100 dirt
setblock ~155 ~126 ~101 dirt
setblock ~155 ~126 ~102 grass_block
setblock ~155 ~126 ~103 grass_block
setblock ~155 ~126 ~106 short_grass
setblock ~155 ~126 ~150 poppy
setblock ~155 ~126 ~158 short_grass
setblock ~155 ~126 ~183 short_grass
setblock ~155 ~126 ~187 short_grass
setblock ~155 ~126 ~190 grass_block
setblock ~155 ~126 ~191 grass_block
setblock ~155 ~126 ~192 grass_block
setblock ~155 ~126 ~193 grass_block
setblock ~155 ~126 ~194 grass_block
setblock ~155 ~126 ~195 grass_block
setblock ~155 ~126 ~196 grass_block
setblock ~155 ~126 ~197 grass_block
setblock ~155 ~126 ~198 grass_block
setblock ~155 ~126 ~199 grass_block
setblock ~155 ~127 ~41 short_grass
setblock ~155 ~127 ~43 short_grass
setblock ~155 ~127 ~44 grass_block
setblock ~155 ~127 ~45 grass_block
setblock ~155 ~127 ~46 grass_block
setblock ~155 ~127 ~47 grass_block
setblock ~155 ~127 ~48 grass_block
setblock ~155 ~127 ~49 grass_block
setblock ~155 ~127 ~50 grass_block
setblock ~155 ~127 ~51 grass_block
setblock ~155 ~127 ~78 grass_block
setblock ~155 ~127 ~79 dirt
setblock ~155 ~127 ~80 dirt
setblock ~155 ~127 ~81 dirt
setblock ~155 ~127 ~82 grass_block
setblock ~155 ~127 ~83 grass_block
setblock ~155 ~127 ~94 short_grass
setblock ~155 ~127 ~96 fern
setblock ~155 ~127 ~97 short_grass
setblock ~155 ~127 ~99 grass_block
setblock ~155 ~127 ~100 grass_block
setblock ~155 ~127 ~101 grass_block
setblock ~155 ~127 ~191 fern
setblock ~155 ~127 ~192 poppy
setblock ~155 ~127 ~193 short_grass
setblock ~155 ~127 ~194 short_grass
setblock ~155 ~127 ~198 short_grass
setblock ~155 ~128 ~44 short_grass
setblock ~155 ~128 ~51 short_grass
setblock ~155 ~128 ~78 fern
setblock ~155 ~128 ~79 grass_block
setblock ~155 ~128 ~80 grass_block
setblock ~155 ~128 ~81 grass_block
setblock ~155 ~128 ~101 short_grass
setblock ~156 ~122 ~0 dirt
setblock ~156 ~122 ~1 dirt
setblock ~156 ~122 ~2 dirt
setblock ~156 ~122 ~3 dirt
setblock ~156 ~122 ~4 dirt
setblock ~156 ~122 ~5 dirt
setblock ~156 ~122 ~6 dirt
setblock ~156 ~122 ~7 dirt
setblock ~156 ~122 ~8 dirt
setblock ~156 ~122 ~9 dirt
setblock ~156 ~122 ~10 dirt
setblock ~156 ~122 ~11 dirt
setblock ~156 ~122 ~12 dirt
setblock ~156 ~122 ~13 dirt
setblock ~156 ~122 ~14 dirt
setblock ~156 ~122 ~15 dirt
setblock ~156 ~122 ~16 dirt
setblock ~156 ~122 ~17 dirt
setblock ~156 ~122 ~18 dirt
setblock ~156 ~122 ~19 dirt
setblock ~156 ~122 ~20 dirt
setblock ~156 ~122 ~21 dirt
setblock ~156 ~122 ~22 dirt
setblock ~156 ~122 ~23 dirt
setblock ~156 ~122 ~24 dirt
setblock ~156 ~122 ~25 dirt
setblock ~156 ~122 ~26 dirt
setblock ~156 ~122 ~27 grass_block
setblock ~156 ~122 ~28 grass_block
setblock ~156 ~122 ~29 grass_block
setblock ~156 ~122 ~30 grass_block
setblock ~156 ~122 ~31 dirt
setblock ~156 ~122 ~32 dirt
setblock ~156 ~122 ~33 dirt
setblock ~156 ~122 ~34 dirt
setblock ~156 ~122 ~35 dirt
setblock ~156 ~122 ~36 dirt
setblock ~156 ~122 ~37 dirt
setblock ~156 ~122 ~38 dirt
setblock ~156 ~122 ~39 dirt
setblock ~156 ~122 ~40 dirt
setblock ~156 ~122 ~41 dirt
setblock ~156 ~122 ~42 dirt
setblock ~156 ~122 ~43 dirt
setblock ~156 ~122 ~44 dirt
setblock ~156 ~122 ~45 dirt
setblock ~156 ~122 ~46 dirt
setblock ~156 ~122 ~47 dirt
setblock ~156 ~122 ~48 dirt
setblock ~156 ~122 ~49 dirt
setblock ~156 ~122 ~50 dirt
setblock ~156 ~122 ~51 dirt
setblock ~156 ~122 ~52 dirt
setblock ~156 ~122 ~53 dirt
setblock ~156 ~122 ~54 dirt
setblock ~156 ~122 ~55 dirt
setblock ~156 ~122 ~56 dirt
setblock ~156 ~122 ~57 dirt
setblock ~156 ~122 ~58 dirt
setblock ~156 ~122 ~59 dirt
setblock ~156 ~122 ~60 dirt
setblock ~156 ~122 ~61 dirt
setblock ~156 ~122 ~62 dirt
setblock ~156 ~122 ~63 dirt
setblock ~156 ~122 ~64 dirt
setblock ~156 ~122 ~65 dirt
setblock ~156 ~122 ~66 dirt
setblock ~156 ~122 ~67 dirt
setblock ~156 ~122 ~68 dirt
setblock ~156 ~122 ~69 dirt
setblock ~156 ~122 ~70 dirt
setblock ~156 ~122 ~71 dirt
setblock ~156 ~122 ~72 dirt
setblock ~156 ~122 ~73 dirt
setblock ~156 ~122 ~74 dirt
setblock ~156 ~122 ~75 dirt
setblock ~156 ~122 ~76 dirt
setblock ~156 ~122 ~77 dirt
setblock ~156 ~122 ~78 dirt
setblock ~156 ~122 ~79 dirt
setblock ~156 ~122 ~80 dirt
setblock ~156 ~122 ~81 dirt
setblock ~156 ~122 ~82 dirt
setblock ~156 ~122 ~83 dirt
setblock ~156 ~122 ~84 dirt
setblock ~156 ~122 ~85 dirt
setblock ~156 ~122 ~86 dirt
setblock ~156 ~122 ~87 dirt
setblock ~156 ~122 ~88 dirt
setblock ~156 ~122 ~89 dirt
setblock ~156 ~122 ~90 dirt
setblock ~156 ~122 ~91 dirt
setblock ~156 ~122 ~92 dirt
setblock ~156 ~122 ~93 dirt
setblock ~156 ~122 ~94 dirt
setblock ~156 ~122 ~95 dirt
setblock ~156 ~122 ~96 dirt
setblock ~156 ~122 ~97 dirt
setblock ~156 ~122 ~98 dirt
setblock ~156 ~122 ~99 dirt
setblock ~156 ~122 ~100 dirt
setblock ~156 ~122 ~101 dirt
setblock ~156 ~122 ~102 dirt
setblock ~156 ~122 ~103 dirt
setblock ~156 ~122 ~104 dirt
setblock ~156 ~122 ~105 dirt
setblock ~156 ~122 ~106 dirt
setblock ~156 ~122 ~107 dirt
setblock ~156 ~122 ~108 dirt
setblock ~156 ~122 ~109 dirt
setblock ~156 ~122 ~110 dirt
setblock ~156 ~122 ~111 dirt
setblock ~156 ~122 ~112 dirt
setblock ~156 ~122 ~113 dirt
setblock ~156 ~122 ~114 dirt
setblock ~156 ~122 ~115 dirt
setblock ~156 ~122 ~116 dirt
setblock ~156 ~122 ~117 dirt
setblock ~156 ~122 ~118 dirt
setblock ~156 ~122 ~119 dirt
setblock ~156 ~122 ~120 dirt
setblock ~156 ~122 ~121 dirt
setblock ~156 ~122 ~122 dirt
setblock ~156 ~122 ~123 dirt
setblock ~156 ~122 ~124 dirt
setblock ~156 ~122 ~125 dirt
setblock ~156 ~122 ~126 dirt
setblock ~156 ~122 ~127 dirt
setblock ~156 ~122 ~128 dirt
setblock ~156 ~122 ~129 dirt
setblock ~156 ~122 ~130 dirt
setblock ~156 ~122 ~131 dirt
setblock ~156 ~122 ~132 dirt
setblock ~156 ~122 ~133 dirt
setblock ~156 ~122 ~134 dirt
setblock ~156 ~122 ~135 dirt
setblock ~156 ~122 ~136 dirt
setblock ~156 ~122 ~137 dirt
setblock ~156 ~122 ~138 grass_block
setblock ~156 ~122 ~139 grass_block
setblock ~156 ~122 ~140 grass_block
setblock ~156 ~122 ~141 dirt
setblock ~156 ~122 ~142 dirt
setblock ~156 ~122 ~143 dirt
setblock ~156 ~122 ~144 dirt
setblock ~156 ~122 ~145 dirt
setblock ~156 ~122 ~146 dirt
setblock ~156 ~122 ~147 dirt
setblock ~156 ~122 ~148 dirt
setblock ~156 ~122 ~149 dirt
setblock ~156 ~122 ~150 dirt
setblock ~156 ~122 ~151 dirt
setblock ~156 ~122 ~152 dirt
setblock ~156 ~122 ~153 dirt
setblock ~156 ~122 ~154 dirt
setblock ~156 ~122 ~155 dirt
setblock ~156 ~122 ~156 dirt
setblock ~156 ~122 ~157 dirt
setblock ~156 ~122 ~158 dirt
setblock ~156 ~122 ~159 dirt
setblock ~156 ~122 ~160 dirt
setblock ~156 ~122 ~161 dirt
setblock ~156 ~122 ~162 dirt
setblock ~156 ~122 ~163 dirt
setblock ~156 ~122 ~164 dirt
setblock ~156 ~122 ~165 dirt
setblock ~156 ~122 ~166 dirt
setblock ~156 ~122 ~167 dirt
setblock ~156 ~122 ~168 dirt
setblock ~156 ~122 ~169 dirt
setblock ~156 ~122 ~170 dirt
setblock ~156 ~122 ~171 dirt
setblock ~156 ~122 ~172 dirt
setblock ~156 ~122 ~173 dirt
setblock ~156 ~122 ~174 dirt
setblock ~156 ~122 ~175 dirt
setblock ~156 ~122 ~176 dirt
setblock ~156 ~122 ~177 dirt
setblock ~156 ~122 ~178 dirt
setblock ~156 ~122 ~179 dirt
setblock ~156 ~122 ~180 dirt
setblock ~156 ~122 ~181 dirt
setblock ~156 ~122 ~182 dirt
setblock ~156 ~122 ~183 dirt
setblock ~156 ~122 ~184 dirt
setblock ~156 ~122 ~185 dirt
setblock ~156 ~122 ~186 dirt
setblock ~156 ~122 ~187 dirt
setblock ~156 ~122 ~188 dirt
setblock ~156 ~122 ~189 dirt
setblock ~156 ~122 ~190 dirt
setblock ~156 ~122 ~191 dirt
setblock ~156 ~122 ~192 dirt
setblock ~156 ~122 ~193 dirt
setblock ~156 ~122 ~194 dirt
setblock ~156 ~122 ~195 dirt
setblock ~156 ~122 ~196 dirt
setblock ~156 ~122 ~197 dirt
setblock ~156 ~122 ~198 dirt
setblock ~156 ~122 ~199 dirt
setblock ~156 ~123 ~0 dirt
setblock ~156 ~123 ~1 dirt
setblock ~156 ~123 ~2 dirt
setblock ~156 ~123 ~3 dirt
setblock ~156 ~123 ~4 dirt
setblock ~156 ~123 ~5 dirt
setblock ~156 ~123 ~6 dirt
setblock ~156 ~123 ~7 dirt
setblock ~156 ~123 ~8 dirt
setblock ~156 ~123 ~9 dirt
setblock ~156 ~123 ~10 dirt
setblock ~156 ~123 ~11 dirt
setblock ~156 ~123 ~12 dirt
setblock ~156 ~123 ~13 dirt
setblock ~156 ~123 ~14 dirt
setblock ~156 ~123 ~15 grass_block
setblock ~156 ~123 ~16 grass_block
setblock ~156 ~123 ~17 grass_block
setblock ~156 ~123 ~18 grass_block
setblock ~156 ~123 ~19 grass_block
setblock ~156 ~123 ~20 grass_block
setblock ~156 ~123 ~21 grass_block
setblock ~156 ~123 ~22 grass_block
setblock ~156 ~123 ~23 grass_block
setblock ~156 ~123 ~24 grass_block
setblock ~156 ~123 ~25 grass_block
setblock ~156 ~123 ~26 grass_block
setblock ~156 ~123 ~28 short_grass
setblock ~156 ~123 ~31 grass_block
setblock ~156 ~123 ~32 grass_block
setblock ~156 ~123 ~33 dirt
setblock ~156 ~123 ~34 dirt
setblock ~156 ~123 ~35 dirt
setblock ~156 ~123 ~36 dirt
setblock ~156 ~123 ~37 dirt
setblock ~156 ~123 ~38 dirt
setblock ~156 ~123 ~39 dirt
setblock ~156 ~123 ~40 dirt
setblock ~156 ~123 ~41 dirt
setblock ~156 ~123 ~42 dirt
setblock ~156 ~123 ~43 dirt
setblock ~156 ~123 ~44 dirt
setblock ~156 ~123 ~45 dirt
setblock ~156 ~123 ~46 dirt
setblock ~156 ~123 ~47 dirt
setblock ~156 ~123 ~48 dirt
setblock ~156 ~123 ~49 dirt
setblock ~156 ~123 ~50 dirt
setblock ~156 ~123 ~51 dirt
setblock ~156 ~123 ~52 dirt
setblock ~156 ~123 ~53 dirt
setblock ~156 ~123 ~54 dirt
setblock ~156 ~123 ~55 dirt
setblock ~156 ~123 ~56 dirt
setblock ~156 ~123 ~57 dirt
setblock ~156 ~123 ~58 dirt
setblock ~156 ~123 ~59 dirt
setblock ~156 ~123 ~60 dirt
setblock ~156 ~123 ~61 dirt
setblock ~156 ~123 ~62 dirt
setblock ~156 ~123 ~63 dirt
setblock ~156 ~123 ~64 dirt
setblock ~156 ~123 ~65 dirt
setblock ~156 ~123 ~66 dirt
setblock ~156 ~123 ~67 dirt
setblock ~156 ~123 ~68 dirt
setblock ~156 ~123 ~69 dirt
setblock ~156 ~123 ~70 dirt
setblock ~156 ~123 ~71 dirt
setblock ~156 ~123 ~72 dirt
setblock ~156 ~123 ~73 dirt
setblock ~156 ~123 ~74 dirt
setblock ~156 ~123 ~75 dirt
setblock ~156 ~123 ~76 dirt
setblock ~156 ~123 ~77 dirt
setblock ~156 ~123 ~78 dirt
setblock ~156 ~123 ~79 dirt
setblock ~156 ~123 ~80 dirt
setblock ~156 ~123 ~81 dirt
setblock ~156 ~123 ~82 dirt
setblock ~156 ~123 ~83 dirt
setblock ~156 ~123 ~84 dirt
setblock ~156 ~123 ~85 dirt
setblock ~156 ~123 ~86 dirt
setblock ~156 ~123 ~87 dirt
setblock ~156 ~123 ~88 dirt
setblock ~156 ~123 ~89 dirt
setblock ~156 ~123 ~90 dirt
setblock ~156 ~123 ~91 dirt
setblock ~156 ~123 ~92 dirt
setblock ~156 ~123 ~93 dirt
setblock ~156 ~123 ~94 dirt
setblock ~156 ~123 ~95 dirt
setblock ~156 ~123 ~96 dirt
setblock ~156 ~123 ~97 dirt
setblock ~156 ~123 ~98 dirt
setblock ~156 ~123 ~99 dirt
setblock ~156 ~123 ~100 dirt
setblock ~156 ~123 ~101 dirt
setblock ~156 ~123 ~102 dirt
setblock ~156 ~123 ~103 dirt
setblock ~156 ~123 ~104 dirt
setblock ~156 ~123 ~105 dirt
setblock ~156 ~123 ~106 dirt
setblock ~156 ~123 ~107 dirt
setblock ~156 ~123 ~108 dirt
setblock ~156 ~123 ~109 grass_block
setblock ~156 ~123 ~110 grass_block
setblock ~156 ~123 ~111 grass_block
setblock ~156 ~123 ~112 grass_block
setblock ~156 ~123 ~113 grass_block
setblock ~156 ~123 ~114 grass_block
setblock ~156 ~123 ~115 grass_block
setblock ~156 ~123 ~116 grass_block
setblock ~156 ~123 ~117 grass_block
setblock ~156 ~123 ~118 grass_block
setblock ~156 ~123 ~119 grass_block
setblock ~156 ~123 ~120 grass_block
setblock ~156 ~123 ~121 grass_block
setblock ~156 ~123 ~122 grass_block
setblock ~156 ~123 ~123 grass_block
setblock ~156 ~123 ~124 grass_block
setblock ~156 ~123 ~125 grass_block
setblock ~156 ~123 ~126 grass_block
setblock ~156 ~123 ~127 grass_block
setblock ~156 ~123 ~128 grass_block
setblock ~156 ~123 ~129 grass_block
setblock ~156 ~123 ~130 grass_block
setblock ~156 ~123 ~131 grass_block
setblock ~156 ~123 ~132 grass_block
setblock ~156 ~123 ~133 grass_block
setblock ~156 ~123 ~134 grass_block
setblock ~156 ~123 ~135 grass_block
setblock ~156 ~123 ~136 grass_block
setblock ~156 ~123 ~137 grass_block
setblock ~156 ~123 ~138 short_grass
setblock ~156 ~123 ~140 fern
setblock ~156 ~123 ~141 grass_block
setblock ~156 ~123 ~142 grass_block
setblock ~156 ~123 ~143 grass_block
setblock ~156 ~123 ~144 dirt
setblock ~156 ~123 ~145 dirt
setblock ~156 ~123 ~146 dirt
setblock ~156 ~123 ~147 dirt
setblock ~156 ~123 ~148 dirt
setblock ~156 ~123 ~149 dirt
setblock ~156 ~123 ~150 dirt
setblock ~156 ~123 ~151 dirt
setblock ~156 ~123 ~152 dirt
setblock ~156 ~123 ~153 dirt
setblock ~156 ~123 ~154 dirt
setblock ~156 ~123 ~155 dirt
setblock ~156 ~123 ~156 dirt
setblock ~156 ~123 ~157 dirt
setblock ~156 ~123 ~158 dirt
setblock ~156 ~123 ~159 dirt
setblock ~156 ~123 ~160 dirt
setblock ~156 ~123 ~161 dirt
setblock ~156 ~123 ~162 dirt
setblock ~156 ~123 ~163 dirt
setblock ~156 ~123 ~164 dirt
setblock ~156 ~123 ~165 dirt
setblock ~156 ~123 ~166 dirt
setblock ~156 ~123 ~167 dirt
setblock ~156 ~123 ~168 dirt
setblock ~156 ~123 ~169 dirt
setblock ~156 ~123 ~170 dirt
setblock ~156 ~123 ~171 dirt
setblock ~156 ~123 ~172 dirt
setblock ~156 ~123 ~173 dirt
setblock ~156 ~123 ~174 dirt
setblock ~156 ~123 ~175 dirt
setblock ~156 ~123 ~176 dirt
setblock ~156 ~123 ~177 dirt
setblock ~156 ~123 ~178 dirt
setblock ~156 ~123 ~179 dirt
setblock ~156 ~123 ~180 dirt
setblock ~156 ~123 ~181 dirt
setblock ~156 ~123 ~182 dirt
setblock ~156 ~123 ~183 dirt
setblock ~156 ~123 ~184 dirt
setblock ~156 ~123 ~185 dirt
setblock ~156 ~123 ~186 dirt
setblock ~156 ~123 ~187 dirt
setblock ~156 ~123 ~188 dirt
setblock ~156 ~123 ~189 dirt
setblock ~156 ~123 ~190 dirt
setblock ~156 ~123 ~191 dirt
setblock ~156 ~123 ~192 dirt
setblock ~156 ~123 ~193 dirt
setblock ~156 ~123 ~194 dirt
setblock ~156 ~123 ~195 dirt
setblock ~156 ~123 ~196 dirt
setblock ~156 ~123 ~197 dirt
setblock ~156 ~123 ~198 dirt
setblock ~156 ~123 ~199 dirt
setblock ~156 ~124 ~0 grass_block
setblock ~156 ~124 ~1 grass_block
setblock ~156 ~124 ~2 grass_block
setblock ~156 ~124 ~3 grass_block
setblock ~156 ~124 ~4 grass_block
setblock ~156 ~124 ~5 grass_block
setblock ~156 ~124 ~6 grass_block
setblock ~156 ~124 ~7 grass_block
setblock ~156 ~124 ~8 grass_block
setblock ~156 ~124 ~9 grass_block
setblock ~156 ~124 ~10 dirt
setblock ~156 ~124 ~11 grass_block
setblock ~156 ~124 ~12 grass_block
setblock ~156 ~124 ~13 grass_block
setblock ~156 ~124 ~14 grass_block
setblock ~156 ~124 ~16 short_grass
setblock ~156 ~124 ~17 fern
setblock ~156 ~124 ~25 fern
setblock ~156 ~124 ~31 short_grass
setblock ~156 ~124 ~33 grass_block
setblock ~156 ~124 ~34 grass_block
setblock ~156 ~124 ~35 dirt
setblock ~156 ~124 ~36 dirt
setblock ~156 ~124 ~37 dirt
setblock ~156 ~124 ~38 dirt
setblock ~156 ~124 ~39 dirt
setblock ~156 ~124 ~40 dirt
setblock ~156 ~124 ~41 dirt
setblock ~156 ~124 ~42 dirt
setblock ~156 ~124 ~43 dirt
setblock ~156 ~124 ~44 dirt
setblock ~156 ~124 ~45 dirt
setblock ~156 ~124 ~46 dirt
setblock ~156 ~124 ~47 dirt
setblock ~156 ~124 ~48 dirt
setblock ~156 ~124 ~49 dirt
setblock ~156 ~124 ~50 dirt
setblock ~156 ~124 ~51 dirt
setblock ~156 ~124 ~52 dirt
setblock ~156 ~124 ~53 dirt
setblock ~156 ~124 ~54 dirt
setblock ~156 ~124 ~55 dirt
setblock ~156 ~124 ~56 dirt
setblock ~156 ~124 ~57 grass_block
setblock ~156 ~124 ~58 grass_block
setblock ~156 ~124 ~59 grass_block
setblock ~156 ~124 ~60 grass_block
setblock ~156 ~124 ~61 grass_block
setblock ~156 ~124 ~62 grass_block
setblock ~156 ~124 ~63 grass_block
setblock ~156 ~124 ~64 grass_block
setblock ~156 ~124 ~65 grass_block
setblock ~156 ~124 ~66 grass_block
setblock ~156 ~124 ~67 grass_block
setblock ~156 ~124 ~68 grass_block
setblock ~156 ~124 ~69 grass_block
setblock ~156 ~124 ~70 grass_block
setblock ~156 ~124 ~71 grass_block
setblock ~156 ~124 ~72 dirt
setblock ~156 ~124 ~73 dirt
setblock ~156 ~124 ~74 dirt
setblock ~156 ~124 ~75 dirt
setblock ~156 ~124 ~76 dirt
setblock ~156 ~124 ~77 dirt
setblock ~156 ~124 ~78 dirt
setblock ~156 ~124 ~79 dirt
setblock ~156 ~124 ~80 dirt
setblock ~156 ~124 ~81 dirt
setblock ~156 ~124 ~82 dirt
setblock ~156 ~124 ~83 dirt
setblock ~156 ~124 ~84 dirt
setblock ~156 ~124 ~85 dirt
setblock ~156 ~124 ~86 dirt
setblock ~156 ~124 ~87 dirt
setblock ~156 ~124 ~88 dirt
setblock ~156 ~124 ~89 dirt
setblock ~156 ~124 ~90 dirt
setblock ~156 ~124 ~91 dirt
setblock ~156 ~124 ~92 dirt
setblock ~156 ~124 ~93 dirt
setblock ~156 ~124 ~94 dirt
setblock ~156 ~124 ~95 dirt
setblock ~156 ~124 ~96 dirt
setblock ~156 ~124 ~97 dirt
setblock ~156 ~124 ~98 dirt
setblock ~156 ~124 ~99 dirt
setblock ~156 ~124 ~100 dirt
setblock ~156 ~124 ~101 dirt
setblock ~156 ~124 ~102 dirt
setblock ~156 ~124 ~103 dirt
setblock ~156 ~124 ~104 dirt
setblock ~156 ~124 ~105 dirt
setblock ~156 ~124 ~106 dirt
setblock ~156 ~124 ~107 grass_block
setblock ~156 ~124 ~108 grass_block
setblock ~156 ~124 ~113 short_grass
setblock ~156 ~124 ~118 short_grass
setblock ~156 ~124 ~119 fern
setblock ~156 ~124 ~123 short_grass
setblock ~156 ~124 ~128 poppy
setblock ~156 ~124 ~130 short_grass
setblock ~156 ~124 ~132 short_grass
setblock ~156 ~124 ~133 short_grass
setblock ~156 ~124 ~135 short_grass
setblock ~156 ~124 ~143 short_grass
setblock ~156 ~124 ~144 grass_block
setblock ~156 ~124 ~145 grass_block
setblock ~156 ~124 ~146 grass_block
setblock ~156 ~124 ~147 dirt
setblock ~156 ~124 ~148 dirt
setblock ~156 ~124 ~149 dirt
setblock ~156 ~124 ~150 dirt
setblock ~156 ~124 ~151 dirt
setblock ~156 ~124 ~152 dirt
setblock ~156 ~124 ~153 dirt
setblock ~156 ~124 ~154 dirt
setblock ~156 ~124 ~155 dirt
setblock ~156 ~124 ~156 dirt
setblock ~156 ~124 ~157 dirt
setblock ~156 ~124 ~158 dirt
setblock ~156 ~124 ~159 dirt
setblock ~156 ~124 ~160 dirt
setblock ~156 ~124 ~161 dirt
setblock ~156 ~124 ~162 dirt
setblock ~156 ~124 ~163 dirt
setblock ~156 ~124 ~164 dirt
setblock ~156 ~124 ~165 dirt
setblock ~156 ~124 ~166 dirt
setblock ~156 ~124 ~167 grass_block
setblock ~156 ~124 ~168 grass_block
setblock ~156 ~124 ~169 grass_block
setblock ~156 ~124 ~170 grass_block
setblock ~156 ~124 ~171 grass_block
setblock ~156 ~124 ~172 grass_block
setblock ~156 ~124 ~173 grass_block
setblock ~156 ~124 ~174 grass_block
setblock ~156 ~124 ~175 grass_block
setblock ~156 ~124 ~176 grass_block
setblock ~156 ~124 ~177 grass_block
setblock ~156 ~124 ~178 grass_block
setblock ~156 ~124 ~179 grass_block
setblock ~156 ~124 ~180 grass_block
setblock ~156 ~124 ~181 grass_block
setblock ~156 ~124 ~182 dirt
setblock ~156 ~124 ~183 dirt
setblock ~156 ~124 ~184 dirt
setblock ~156 ~124 ~185 dirt
setblock ~156 ~124 ~186 dirt
setblock ~156 ~124 ~187 dirt
setblock ~156 ~124 ~188 dirt
setblock ~156 ~124 ~189 dirt
setblock ~156 ~124 ~190 dirt
setblock ~156 ~124 ~191 dirt
setblock ~156 ~124 ~192 dirt
setblock ~156 ~124 ~193 dirt
setblock ~156 ~124 ~194 dirt
setblock ~156 ~124 ~195 dirt
setblock ~156 ~124 ~196 dirt
setblock ~156 ~124 ~197 dirt
setblock ~156 ~124 ~198 dirt
setblock ~156 ~124 ~199 dirt
setblock ~156 ~125 ~0 fern
setblock ~156 ~125 ~5 short_grass
setblock ~156 ~125 ~7 short_grass
setblock ~156 ~125 ~8 short_grass
setblock ~156 ~125 ~9 short_grass
setblock ~156 ~125 ~10 grass_block
setblock ~156 ~125 ~14 short_grass
setblock ~156 ~125 ~34 short_grass
setblock ~156 ~125 ~35 grass_block
setblock ~156 ~125 ~36 grass_block
setblock ~156 ~125 ~37 grass_block
setblock ~156 ~125 ~38 dirt
setblock ~156 ~125 ~39 dirt
setblock ~156 ~125 ~40 dirt
setblock ~156 ~125 ~41 dirt
setblock ~156 ~125 ~42 dirt
setblock ~156 ~125 ~43 dirt
setblock ~156 ~125 ~44 dirt
setblock ~156 ~125 ~45 dirt
setblock ~156 ~125 ~46 dirt
setblock ~156 ~125 ~47 dirt
setblock ~156 ~125 ~48 dirt
setblock ~156 ~125 ~49 dirt
setblock ~156 ~125 ~50 dirt
setblock ~156 ~125 ~51 dirt
setblock ~156 ~125 ~52 dirt
setblock ~156 ~125 ~53 dirt
setblock ~156 ~125 ~54 grass_block
setblock ~156 ~125 ~55 grass_block
setblock ~156 ~125 ~56 grass_block
setblock ~156 ~125 ~57 short_grass
setblock ~156 ~125 ~58 short_grass
setblock ~156 ~125 ~60 short_grass
setblock ~156 ~125 ~62 short_grass
setblock ~156 ~125 ~64 short_grass
setblock ~156 ~125 ~69 short_grass
setblock ~156 ~125 ~72 grass_block
setblock ~156 ~125 ~73 grass_block
setblock ~156 ~125 ~74 grass_block
setblock ~156 ~125 ~75 dirt
setblock ~156 ~125 ~76 dirt
setblock ~156 ~125 ~77 dirt
setblock ~156 ~125 ~78 dirt
setblock ~156 ~125 ~79 dirt
setblock ~156 ~125 ~80 dirt
setblock ~156 ~125 ~81 dirt
setblock ~156 ~125 ~82 dirt
setblock ~156 ~125 ~83 dirt
setblock ~156 ~125 ~84 dirt
setblock ~156 ~125 ~85 dirt
setblock ~156 ~125 ~86 dirt
setblock ~156 ~125 ~87 dirt
setblock ~156 ~125 ~88 dirt
setblock ~156 ~125 ~89 grass_block
setblock ~156 ~125 ~90 grass_block
setblock ~156 ~125 ~91 grass_block
setblock ~156 ~125 ~92 grass_block
setblock ~156 ~125 ~93 dirt
setblock ~156 ~125 ~94 dirt
setblock ~156 ~125 ~95 dirt
setblock ~156 ~125 ~96 dirt
setblock ~156 ~125 ~97 dirt
setblock ~156 ~125 ~98 dirt
setblock ~156 ~125 ~99 dirt
setblock ~156 ~125 ~100 dirt
setblock ~156 ~125 ~101 dirt
setblock ~156 ~125 ~102 dirt
setblock ~156 ~125 ~103 dirt
setblock ~156 ~125 ~104 grass_block
setblock ~156 ~125 ~105 grass_block
setblock ~156 ~125 ~106 grass_block
setblock ~156 ~125 ~147 grass_block
setblock ~156 ~125 ~148 grass_block
setblock ~156 ~125 ~149 grass_block
setblock ~156 ~125 ~150 grass_block
setblock ~156 ~125 ~151 grass_block
setblock ~156 ~125 ~152 grass_block
setblock ~156 ~125 ~153 grass_block
setblock ~156 ~125 ~154 grass_block
setblock ~156 ~125 ~155 grass_block
setblock ~156 ~125 ~156 grass_block
setblock ~156 ~125 ~157 dirt
setblock ~156 ~125 ~158 dirt
setblock ~156 ~125 ~159 dirt
setblock ~156 ~125 ~160 dirt
setblock ~156 ~125 ~161 dirt
setblock ~156 ~125 ~162 grass_block
setblock ~156 ~125 ~163 grass_block
setblock ~156 ~125 ~164 grass_block
setblock ~156 ~125 ~165 grass_block
setblock ~156 ~125 ~166 grass_block
setblock ~156 ~125 ~173 short_grass
setblock ~156 ~125 ~174 short_grass
setblock ~156 ~125 ~175 short_grass
setblock ~156 ~125 ~179 short_grass
setblock ~156 ~125 ~182 grass_block
setblock ~156 ~125 ~183 grass_block
setblock ~156 ~125 ~184 grass_block
setblock ~156 ~125 ~185 grass_block
setblock ~156 ~125 ~186 grass_block
setblock ~156 ~125 ~187 grass_block
setblock ~156 ~125 ~188 dirt
setblock ~156 ~125 ~189 dirt
setblock ~156 ~125 ~190 dirt
setblock ~156 ~125 ~191 dirt
setblock ~156 ~125 ~192 dirt
setblock ~156 ~125 ~193 dirt
setblock ~156 ~125 ~194 dirt
setblock ~156 ~125 ~195 dirt
setblock ~156 ~125 ~196 dirt
setblock ~156 ~125 ~197 dirt
setblock ~156 ~125 ~198 dirt
setblock ~156 ~125 ~199 dirt
setblock ~156 ~126 ~10 short_grass
setblock ~156 ~126 ~35 short_grass
setblock ~156 ~126 ~37 short_grass
setblock ~156 ~126 ~38 grass_block
setblock ~156 ~126 ~39 grass_block
setblock ~156 ~126 ~40 grass_block
setblock ~156 ~126 ~41 grass_block
setblock ~156 ~126 ~42 dirt
setblock ~156 ~126 ~43 dirt
setblock ~156 ~126 ~44 dirt
setblock ~156 ~126 ~45 dirt
setblock ~156 ~126 ~46 dirt
setblock ~156 ~126 ~47 dirt
setblock ~156 ~126 ~48 dirt
setblock ~156 ~126 ~49 dirt
setblock ~156 ~126 ~50 dirt
setblock ~156 ~126 ~51 dirt
setblock ~156 ~126 ~52 grass_block
setblock ~156 ~126 ~53 grass_block
setblock ~156 ~126 ~54 short_grass
setblock ~156 ~126 ~72 short_grass
setblock ~156 ~126 ~75 grass_block
setblock ~156 ~126 ~76 grass_block
setblock ~156 ~126 ~77 grass_block
setblock ~156 ~126 ~78 dirt
setblock ~156 ~126 ~79 dirt
setblock ~156 ~126 ~80 dirt
setblock ~156 ~126 ~81 dirt
setblock ~156 ~126 ~82 dirt
setblock ~156 ~126 ~83 dirt
setblock ~156 ~126 ~84 dirt
setblock ~156 ~126 ~85 grass_block
setblock ~156 ~126 ~86 grass_block
setblock ~156 ~126 ~87 grass_block
setblock ~156 ~126 ~88 grass_block
setblock ~156 ~126 ~89 short_grass
setblock ~156 ~126 ~90 poppy
setblock ~156 ~126 ~91 short_grass
setblock ~156 ~126 ~93 grass_block
setblock ~156 ~126 ~94 grass_block
setblock ~156 ~126 ~95 grass_block
setblock ~156 ~126 ~96 grass_block
setblock ~156 ~126 ~97 grass_block
setblock ~156 ~126 ~98 grass_block
setblock ~156 ~126 ~99 grass_block
setblock ~156 ~126 ~100 grass_block
setblock ~156 ~126 ~101 grass_block
setblock ~156 ~126 ~102 grass_block
setblock ~156 ~126 ~103 grass_block
setblock ~156 ~126 ~149 short_grass
setblock ~156 ~126 ~152 poppy
setblock ~156 ~126 ~155 short_grass
setblock ~156 ~126 ~156 short_grass
setblock ~156 ~126 ~157 grass_block
setblock ~156 ~126 ~158 grass_block
setblock ~156 ~126 ~159 grass_block
setblock ~156 ~126 ~160 grass_block
setblock ~156 ~126 ~161 grass_block
setblock ~156 ~126 ~188 grass_block
setblock ~156 ~126 ~189 grass_block
setblock ~156 ~126 ~190 grass_block
setblock ~156 ~126 ~191 grass_block
setblock ~156 ~126 ~192 grass_block
setblock ~156 ~126 ~193 grass_block
setblock ~156 ~126 ~194 grass_block
setblock ~156 ~126 ~195 grass_block
setblock ~156 ~126 ~196 grass_block
setblock ~156 ~126 ~197 grass_block
setblock ~156 ~126 ~198 grass_block
setblock ~156 ~126 ~199 grass_block
setblock ~156 ~127 ~39 short_grass
setblock ~156 ~127 ~42 grass_block
setblock ~156 ~127 ~43 grass_block
setblock ~156 ~127 ~44 grass_block
setblock ~156 ~127 ~45 grass_block
setblock ~156 ~127 ~46 grass_block
setblock ~156 ~127 ~47 grass_block
setblock ~156 ~127 ~48 grass_block
setblock ~156 ~127 ~49 grass_block
setblock ~156 ~127 ~50 grass_block
setblock ~156 ~127 ~51 grass_block
setblock ~156 ~127 ~78 grass_block
setblock ~156 ~127 ~79 dirt
setblock ~156 ~127 ~80 dirt
setblock ~156 ~127 ~81 dirt
setblock ~156 ~127 ~82 grass_block
setblock ~156 ~127 ~83 grass_block
setblock ~156 ~127 ~84 grass_block
setblock ~156 ~127 ~87 short_grass
setblock ~156 ~127 ~94 poppy
setblock ~156 ~127 ~157 short_grass
setblock ~156 ~127 ~159 short_grass
setblock ~156 ~127 ~189 poppy
setblock ~156 ~127 ~193 fern
setblock ~156 ~128 ~47 short_grass
setblock ~156 ~128 ~48 fern
setblock ~156 ~128 ~79 grass_block
setblock ~156 ~128 ~80 grass_block
setblock ~156 ~128 ~81 grass_block
setblock ~156 ~129 ~81 short_grass
setblock ~157 ~122 ~0 dirt
setblock ~157 ~122 ~1 dirt
setblock ~157 ~122 ~2 dirt
setblock ~157 ~122 ~3 dirt
setblock ~157 ~122 ~4 dirt
setblock ~157 ~122 ~5 dirt
setblock ~157 ~122 ~6 dirt
setblock ~157 ~122 ~7 dirt
setblock ~157 ~122 ~8 dirt
setblock ~157 ~122 ~9 dirt
setblock ~157 ~122 ~10 dirt
setblock ~157 ~122 ~11 dirt
setblock ~157 ~122 ~12 dirt
setblock ~157 ~122 ~13 dirt
setblock ~157 ~122 ~14 dirt
setblock ~157 ~122 ~15 dirt
setblock ~157 ~122 ~16 dirt
setblock ~157 ~122 ~17 dirt
setblock ~157 ~122 ~18 dirt
setblock ~157 ~122 ~19 dirt
setblock ~157 ~122 ~20 dirt
setblock ~157 ~122 ~21 dirt
setblock ~157 ~122 ~22 dirt
setblock ~157 ~122 ~23 dirt
setblock ~157 ~122 ~24 grass_block
setblock ~157 ~122 ~25 grass_block
setblock ~157 ~122 ~26 grass_block
setblock ~157 ~122 ~27 grass_block
setblock ~157 ~122 ~28 grass_block
setblock ~157 ~122 ~29 grass_block
setblock ~157 ~122 ~30 grass_block
setblock ~157 ~122 ~31 dirt
setblock ~157 ~122 ~32 dirt
setblock ~157 ~122 ~33 dirt
setblock ~157 ~122 ~34 dirt
setblock ~157 ~122 ~35 dirt
setblock ~157 ~122 ~36 dirt
setblock ~157 ~122 ~37 dirt
setblock ~157 ~122 ~38 dirt
setblock ~157 ~122 ~39 dirt
setblock ~157 ~122 ~40 dirt
setblock ~157 ~122 ~41 dirt
setblock ~157 ~122 ~42 dirt
setblock ~157 ~122 ~43 dirt
setblock ~157 ~122 ~44 dirt
setblock ~157 ~122 ~45 dirt
setblock ~157 ~122 ~46 dirt
setblock ~157 ~122 ~47 dirt
setblock ~157 ~122 ~48 dirt
setblock ~157 ~122 ~49 dirt
setblock ~157 ~122 ~50 dirt
setblock ~157 ~122 ~51 dirt
setblock ~157 ~122 ~52 dirt
setblock ~157 ~122 ~53 dirt
setblock ~157 ~122 ~54 dirt
setblock ~157 ~122 ~55 dirt
setblock ~157 ~122 ~56 dirt
setblock ~157 ~122 ~57 dirt
setblock ~157 ~122 ~58 dirt
setblock ~157 ~122 ~59 dirt
setblock ~157 ~122 ~60 dirt
setblock ~157 ~122 ~61 dirt
setblock ~157 ~122 ~62 dirt
setblock ~157 ~122 ~63 dirt
setblock ~157 ~122 ~64 dirt
setblock ~157 ~122 ~65 dirt
setblock ~157 ~122 ~66 dirt
setblock ~157 ~122 ~67 dirt
setblock ~157 ~122 ~68 dirt
setblock ~157 ~122 ~69 dirt
setblock ~157 ~122 ~70 dirt
setblock ~157 ~122 ~71 dirt
setblock ~157 ~122 ~72 dirt
setblock ~157 ~122 ~73 dirt
setblock ~157 ~122 ~74 dirt
setblock ~157 ~122 ~75 dirt
setblock ~157 ~122 ~76 dirt
setblock ~157 ~122 ~77 dirt
setblock ~157 ~122 ~78 dirt
setblock ~157 ~122 ~79 dirt
setblock ~157 ~122 ~80 dirt
setblock ~157 ~122 ~81 dirt
setblock ~157 ~122 ~82 dirt
setblock ~157 ~122 ~83 dirt
setblock ~157 ~122 ~84 dirt
setblock ~157 ~122 ~85 dirt
setblock ~157 ~122 ~86 dirt
setblock ~157 ~122 ~87 dirt
setblock ~157 ~122 ~88 dirt
setblock ~157 ~122 ~89 dirt
setblock ~157 ~122 ~90 dirt
setblock ~157 ~122 ~91 dirt
setblock ~157 ~122 ~92 dirt
setblock ~157 ~122 ~93 dirt
setblock ~157 ~122 ~94 dirt
setblock ~157 ~122 ~95 dirt
setblock ~157 ~122 ~96 dirt
setblock ~157 ~122 ~97 dirt
setblock ~157 ~122 ~98 dirt
setblock ~157 ~122 ~99 dirt
setblock ~157 ~122 ~100 dirt
setblock ~157 ~122 ~101 dirt
setblock ~157 ~122 ~102 dirt
setblock ~157 ~122 ~103 dirt
setblock ~157 ~122 ~104 dirt
setblock ~157 ~122 ~105 dirt
setblock ~157 ~122 ~106 dirt
setblock ~157 ~122 ~107 dirt
setblock ~157 ~122 ~108 dirt
setblock ~157 ~122 ~109 dirt
setblock ~157 ~122 ~110 dirt
setblock ~157 ~122 ~111 dirt
setblock ~157 ~122 ~112 dirt
setblock ~157 ~122 ~113 dirt
setblock ~157 ~122 ~114 dirt
setblock ~157 ~122 ~115 dirt
setblock ~157 ~122 ~116 dirt
setblock ~157 ~122 ~117 dirt
setblock ~157 ~122 ~118 dirt
setblock ~157 ~122 ~119 dirt
setblock ~157 ~122 ~120 dirt
setblock ~157 ~122 ~121 dirt
setblock ~157 ~122 ~122 dirt
setblock ~157 ~122 ~123 dirt
setblock ~157 ~122 ~124 dirt
setblock ~157 ~122 ~125 dirt
setblock ~157 ~122 ~126 dirt
setblock ~157 ~122 ~127 dirt
setblock ~157 ~122 ~128 dirt
setblock ~157 ~122 ~129 dirt
setblock ~157 ~122 ~130 dirt
setblock ~157 ~122 ~131 dirt
setblock ~157 ~122 ~132 dirt
setblock ~157 ~122 ~133 dirt
setblock ~157 ~122 ~134 dirt
setblock ~157 ~122 ~135 dirt
setblock ~157 ~122 ~136 dirt
setblock ~157 ~122 ~137 dirt
setblock ~157 ~122 ~138 grass_block
setblock ~157 ~122 ~139 grass_block
setblock ~157 ~122 ~140 grass_block
setblock ~157 ~122 ~141 dirt
setblock ~157 ~122 ~142 dirt
setblock ~157 ~122 ~143 dirt
setblock ~157 ~122 ~144 dirt
setblock ~157 ~122 ~145 dirt
setblock ~157 ~122 ~146 dirt
setblock ~157 ~122 ~147 dirt
setblock ~157 ~122 ~148 dirt
setblock ~157 ~122 ~149 dirt
setblock ~157 ~122 ~150 dirt
setblock ~157 ~122 ~151 dirt
setblock ~157 ~122 ~152 dirt
setblock ~157 ~122 ~153 dirt
setblock ~157 ~122 ~154 dirt
setblock ~157 ~122 ~155 dirt
setblock ~157 ~122 ~156 dirt
setblock ~157 ~122 ~157 dirt
setblock ~157 ~122 ~158 dirt
setblock ~157 ~122 ~159 dirt
setblock ~157 ~122 ~160 dirt
setblock ~157 ~122 ~161 dirt
setblock ~157 ~122 ~162 dirt
setblock ~157 ~122 ~163 dirt
setblock ~157 ~122 ~164 dirt
setblock ~157 ~122 ~165 dirt
setblock ~157 ~122 ~166 dirt
setblock ~157 ~122 ~167 dirt
setblock ~157 ~122 ~168 dirt
setblock ~157 ~122 ~169 dirt
setblock ~157 ~122 ~170 dirt
setblock ~157 ~122 ~171 dirt
setblock ~157 ~122 ~172 dirt
setblock ~157 ~122 ~173 dirt
setblock ~157 ~122 ~174 dirt
setblock ~157 ~122 ~175 dirt
setblock ~157 ~122 ~176 dirt
setblock ~157 ~122 ~177 dirt
setblock ~157 ~122 ~178 dirt
setblock ~157 ~122 ~179 dirt
setblock ~157 ~122 ~180 dirt
setblock ~157 ~122 ~181 dirt
setblock ~157 ~122 ~182 dirt
setblock ~157 ~122 ~183 dirt
setblock ~157 ~122 ~184 dirt
setblock ~157 ~122 ~185 dirt
setblock ~157 ~122 ~186 dirt
setblock ~157 ~122 ~187 dirt
setblock ~157 ~122 ~188 dirt
setblock ~157 ~122 ~189 dirt
setblock ~157 ~122 ~190 dirt
setblock ~157 ~122 ~191 dirt
setblock ~157 ~122 ~192 dirt
setblock ~157 ~122 ~193 dirt
setblock ~157 ~122 ~194 dirt
setblock ~157 ~122 ~195 dirt
setblock ~157 ~122 ~196 dirt
setblock ~157 ~122 ~197 dirt
setblock ~157 ~122 ~198 dirt
setblock ~157 ~122 ~199 dirt
setblock ~157 ~123 ~0 dirt
setblock ~157 ~123 ~1 dirt
setblock ~157 ~123 ~2 dirt
setblock ~157 ~123 ~3 dirt
setblock ~157 ~123 ~4 dirt
setblock ~157 ~123 ~5 dirt
setblock ~157 ~123 ~6 dirt
setblock ~157 ~123 ~7 dirt
setblock ~157 ~123 ~8 dirt
setblock ~157 ~123 ~9 dirt
setblock ~157 ~123 ~10 dirt
setblock ~157 ~123 ~11 dirt
setblock ~157 ~123 ~12 dirt
setblock ~157 ~123 ~13 dirt
setblock ~157 ~123 ~14 dirt
setblock ~157 ~123 ~15 grass_block
setblock ~157 ~123 ~16 grass_block
setblock ~157 ~123 ~17 grass_block
setblock ~157 ~123 ~18 grass_block
setblock ~157 ~123 ~19 grass_block
setblock ~157 ~123 ~20 grass_block
setblock ~157 ~123 ~21 grass_block
setblock ~157 ~123 ~22 grass_block
setblock ~157 ~123 ~23 grass_block
setblock ~157 ~123 ~31 grass_block
setblock ~157 ~123 ~32 grass_block
setblock ~157 ~123 ~33 dirt
setblock ~157 ~123 ~34 dirt
setblock ~157 ~123 ~35 dirt
setblock ~157 ~123 ~36 dirt
setblock ~157 ~123 ~37 dirt
setblock ~157 ~123 ~38 dirt
setblock ~157 ~123 ~39 dirt
setblock ~157 ~123 ~40 dirt
setblock ~157 ~123 ~41 dirt
setblock ~157 ~123 ~42 dirt
setblock ~157 ~123 ~43 dirt
setblock ~157 ~123 ~44 dirt
setblock ~157 ~123 ~45 dirt
setblock ~157 ~123 ~46 dirt
setblock ~157 ~123 ~47 dirt
setblock ~157 ~123 ~48 dirt
setblock ~157 ~123 ~49 dirt
setblock ~157 ~123 ~50 dirt
setblock ~157 ~123 ~51 dirt
setblock ~157 ~123 ~52 dirt
setblock ~157 ~123 ~53 dirt
setblock ~157 ~123 ~54 dirt
setblock ~157 ~123 ~55 dirt
setblock ~157 ~123 ~56 dirt
setblock ~157 ~123 ~57 dirt
setblock ~157 ~123 ~58 dirt
setblock ~157 ~123 ~59 dirt
setblock ~157 ~123 ~60 dirt
setblock ~157 ~123 ~61 dirt
setblock ~157 ~123 ~62 dirt
setblock ~157 ~123 ~63 dirt
setblock ~157 ~123 ~64 dirt
setblock ~157 ~123 ~65 dirt
setblock ~157 ~123 ~66 dirt
setblock ~157 ~123 ~67 dirt
setblock ~157 ~123 ~68 dirt
setblock ~157 ~123 ~69 dirt
setblock ~157 ~123 ~70 dirt
setblock ~157 ~123 ~71 dirt
setblock ~157 ~123 ~72 dirt
setblock ~157 ~123 ~73 dirt
setblock ~157 ~123 ~74 dirt
setblock ~157 ~123 ~75 dirt
setblock ~157 ~123 ~76 dirt
setblock ~157 ~123 ~77 dirt
setblock ~157 ~123 ~78 dirt
setblock ~157 ~123 ~79 dirt
setblock ~157 ~123 ~80 dirt
setblock ~157 ~123 ~81 dirt
setblock ~157 ~123 ~82 dirt
setblock ~157 ~123 ~83 dirt
setblock ~157 ~123 ~84 dirt
setblock ~157 ~123 ~85 dirt
setblock ~157 ~123 ~86 dirt
setblock ~157 ~123 ~87 dirt
setblock ~157 ~123 ~88 dirt
setblock ~157 ~123 ~89 dirt
setblock ~157 ~123 ~90 dirt
setblock ~157 ~123 ~91 dirt
setblock ~157 ~123 ~92 dirt
setblock ~157 ~123 ~93 dirt
setblock ~157 ~123 ~94 dirt
setblock ~157 ~123 ~95 dirt
setblock ~157 ~123 ~96 dirt
setblock ~157 ~123 ~97 dirt
setblock ~157 ~123 ~98 dirt
setblock ~157 ~123 ~99 dirt
setblock ~157 ~123 ~100 dirt
setblock ~157 ~123 ~101 dirt
setblock ~157 ~123 ~102 dirt
setblock ~157 ~123 ~103 dirt
setblock ~157 ~123 ~104 dirt
setblock ~157 ~123 ~105 dirt
setblock ~157 ~123 ~106 dirt
setblock ~157 ~123 ~107 dirt
setblock ~157 ~123 ~108 dirt
setblock ~157 ~123 ~109 grass_block
setblock ~157 ~123 ~110 grass_block
setblock ~157 ~123 ~111 grass_block
setblock ~157 ~123 ~112 grass_block
setblock ~157 ~123 ~113 grass_block
setblock ~157 ~123 ~114 grass_block
setblock ~157 ~123 ~115 grass_block
setblock ~157 ~123 ~116 grass_block
setblock ~157 ~123 ~117 grass_block
setblock ~157 ~123 ~118 grass_block
setblock ~157 ~123 ~119 grass_block
setblock ~157 ~123 ~120 grass_block
setblock ~157 ~123 ~121 grass_block
setblock ~157 ~123 ~122 grass_block
setblock ~157 ~123 ~123 grass_block
setblock ~157 ~123 ~124 grass_block
setblock ~157 ~123 ~125 grass_block
setblock ~157 ~123 ~126 grass_block
setblock ~157 ~123 ~127 grass_block
setblock ~157 ~123 ~128 grass_block
setblock ~157 ~123 ~129 grass_block
setblock ~157 ~123 ~130 grass_block
setblock ~157 ~123 ~131 grass_block
setblock ~157 ~123 ~132 grass_block
setblock ~157 ~123 ~133 grass_block
setblock ~157 ~123 ~134 grass_block
setblock ~157 ~123 ~135 grass_block
setblock ~157 ~123 ~136 grass_block
setblock ~157 ~123 ~137 grass_block
setblock ~157 ~123 ~138 short_grass
setblock ~157 ~123 ~139 fern
setblock ~157 ~123 ~140 short_grass
setblock ~157 ~123 ~141 grass_block
setblock ~157 ~123 ~142 grass_block
setblock ~157 ~123 ~143 grass_block
setblock ~157 ~123 ~144 dirt
setblock ~157 ~123 ~145 dirt
setblock ~157 ~123 ~146 dirt
setblock ~157 ~123 ~147 dirt
setblock ~157 ~123 ~148 dirt
setblock ~157 ~123 ~149 dirt
setblock ~157 ~123 ~150 dirt
setblock ~157 ~123 ~151 dirt
setblock ~157 ~123 ~152 dirt
setblock ~157 ~123 ~153 dirt
setblock ~157 ~123 ~154 dirt
setblock ~157 ~123 ~155 dirt
setblock ~157 ~123 ~156 dirt
setblock ~157 ~123 ~157 dirt
setblock ~157 ~123 ~158 dirt
setblock ~157 ~123 ~159 dirt
setblock ~157 ~123 ~160 dirt
setblock ~157 ~123 ~161 dirt
setblock ~157 ~123 ~162 dirt
setblock ~157 ~123 ~163 dirt
setblock ~157 ~123 ~164 dirt
setblock ~157 ~123 ~165 dirt
setblock ~157 ~123 ~166 dirt
setblock ~157 ~123 ~167 dirt
setblock ~157 ~123 ~168 dirt
setblock ~157 ~123 ~169 dirt
setblock ~157 ~123 ~170 dirt
setblock ~157 ~123 ~171 dirt
setblock ~157 ~123 ~172 dirt
setblock ~157 ~123 ~173 dirt
setblock ~157 ~123 ~174 dirt
setblock ~157 ~123 ~175 dirt
setblock ~157 ~123 ~176 dirt
setblock ~157 ~123 ~177 dirt
setblock ~157 ~123 ~178 dirt
setblock ~157 ~123 ~179 dirt
setblock ~157 ~123 ~180 dirt
setblock ~157 ~123 ~181 dirt
setblock ~157 ~123 ~182 dirt
setblock ~157 ~123 ~183 dirt
setblock ~157 ~123 ~184 dirt
setblock ~157 ~123 ~185 dirt
setblock ~157 ~123 ~186 dirt
setblock ~157 ~123 ~187 dirt
setblock ~157 ~123 ~188 dirt
setblock ~157 ~123 ~189 dirt
setblock ~157 ~123 ~190 dirt
setblock ~157 ~123 ~191 dirt
setblock ~157 ~123 ~192 dirt
setblock ~157 ~123 ~193 dirt
setblock ~157 ~123 ~194 dirt
setblock ~157 ~123 ~195 dirt
setblock ~157 ~123 ~196 dirt
setblock ~157 ~123 ~197 dirt
setblock ~157 ~123 ~198 dirt
setblock ~157 ~123 ~199 dirt
setblock ~157 ~124 ~0 grass_block
setblock ~157 ~124 ~1 grass_block
setblock ~157 ~124 ~2 grass_block
setblock ~157 ~124 ~3 grass_block
setblock ~157 ~124 ~4 grass_block
setblock ~157 ~124 ~5 grass_block
setblock ~157 ~124 ~6 grass_block
setblock ~157 ~124 ~7 dirt
setblock ~157 ~124 ~8 dirt
setblock ~157 ~124 ~9 dirt
setblock ~157 ~124 ~10 dirt
setblock ~157 ~124 ~11 dirt
setblock ~157 ~124 ~12 grass_block
setblock ~157 ~124 ~13 grass_block
setblock ~157 ~124 ~14 grass_block
setblock ~157 ~124 ~15 fern
setblock ~157 ~124 ~17 short_grass
setblock ~157 ~124 ~22 short_grass
setblock ~157 ~124 ~23 poppy
setblock ~157 ~124 ~31 poppy
setblock ~157 ~124 ~33 grass_block
setblock ~157 ~124 ~34 grass_block
setblock ~157 ~124 ~35 dirt
setblock ~157 ~124 ~36 dirt
setblock ~157 ~124 ~37 dirt
setblock ~157 ~124 ~38 dirt
setblock ~157 ~124 ~39 dirt
setblock ~157 ~124 ~40 dirt
setblock ~157 ~124 ~41 dirt
setblock ~157 ~124 ~42 dirt
setblock ~157 ~124 ~43 dirt
setblock ~157 ~124 ~44 dirt
setblock ~157 ~124 ~45 dirt
setblock ~157 ~124 ~46 dirt
setblock ~157 ~124 ~47 dirt
setblock ~157 ~124 ~48 dirt
setblock ~157 ~124 ~49 dirt
setblock ~157 ~124 ~50 dirt
setblock ~157 ~124 ~51 dirt
setblock ~157 ~124 ~52 dirt
setblock ~157 ~124 ~53 dirt
setblock ~157 ~124 ~54 dirt
setblock ~157 ~124 ~55 dirt
setblock ~157 ~124 ~56 grass_block
setblock ~157 ~124 ~57 grass_block
setblock ~157 ~124 ~58 grass_block
setblock ~157 ~124 ~59 grass_block
setblock ~157 ~124 ~60 grass_block
setblock ~157 ~124 ~61 grass_block
setblock ~157 ~124 ~62 grass_block
setblock ~157 ~124 ~63 grass_block
setblock ~157 ~124 ~64 grass_block
setblock ~157 ~124 ~65 grass_block
setblock ~157 ~124 ~66 grass_block
setblock ~157 ~124 ~67 grass_block
setblock ~157 ~124 ~68 grass_block
setblock ~157 ~124 ~69 grass_block
setblock ~157 ~124 ~70 grass_block
setblock ~157 ~124 ~71 dirt
setblock ~157 ~124 ~72 dirt
setblock ~157 ~124 ~73 dirt
setblock ~157 ~124 ~74 dirt
setblock ~157 ~124 ~75 dirt
setblock ~157 ~124 ~76 dirt
setblock ~157 ~124 ~77 dirt
setblock ~157 ~124 ~78 dirt
setblock ~157 ~124 ~79 dirt
setblock ~157 ~124 ~80 dirt
setblock ~157 ~124 ~81 dirt
setblock ~157 ~124 ~82 dirt
setblock ~157 ~124 ~83 dirt
setblock ~157 ~124 ~84 dirt
setblock ~157 ~124 ~85 dirt
setblock ~157 ~124 ~86 dirt
setblock ~157 ~124 ~87 dirt
setblock ~157 ~124 ~88 dirt
setblock ~157 ~124 ~89 dirt
setblock ~157 ~124 ~90 dirt
setblock ~157 ~124 ~91 dirt
setblock ~157 ~124 ~92 dirt
setblock ~157 ~124 ~93 dirt
setblock ~157 ~124 ~94 dirt
setblock ~157 ~124 ~95 dirt
setblock ~157 ~124 ~96 dirt
setblock ~157 ~124 ~97 dirt
setblock ~157 ~124 ~98 dirt
setblock ~157 ~124 ~99 dirt
setblock ~157 ~124 ~100 dirt
setblock ~157 ~124 ~101 dirt
setblock ~157 ~124 ~102 dirt
setblock ~157 ~124 ~103 dirt
setblock ~157 ~124 ~104 dirt
setblock ~157 ~124 ~105 dirt
setblock ~157 ~124 ~106 grass_block
setblock ~157 ~124 ~107 grass_block
setblock ~157 ~124 ~108 grass_block
setblock ~157 ~124 ~110 short_grass
setblock ~157 ~124 ~111 short_grass
setblock ~157 ~124 ~113 short_grass
setblock ~157 ~124 ~115 poppy
setblock ~157 ~124 ~116 short_grass
setblock ~157 ~124 ~120 fern
setblock ~157 ~124 ~121 short_grass
setblock ~157 ~124 ~128 short_grass
setblock ~157 ~124 ~132 short_grass
setblock ~157 ~124 ~135 short_grass
setblock ~157 ~124 ~142 short_grass
setblock ~157 ~124 ~144 grass_block
setblock ~157 ~124 ~145 grass_block
setblock ~157 ~124 ~146 grass_block
setblock ~157 ~124 ~147 grass_block
setblock ~157 ~124 ~148 dirt
setblock ~157 ~124 ~149 dirt
setblock ~157 ~124 ~150 dirt
setblock ~157 ~124 ~151 dirt
setblock ~157 ~124 ~152 dirt
setblock ~157 ~124 ~153 dirt
setblock ~157 ~124 ~154 dirt
setblock ~157 ~124 ~155 dirt
setblock ~157 ~124 ~156 dirt
setblock ~157 ~124 ~157 dirt
setblock ~157 ~124 ~158 dirt
setblock ~157 ~124 ~159 dirt
setblock ~157 ~124 ~160 dirt
setblock ~157 ~124 ~161 dirt
setblock ~157 ~124 ~162 dirt
setblock ~157 ~124 ~163 dirt
setblock ~157 ~124 ~164 dirt
setblock ~157 ~124 ~165 dirt
setblock ~157 ~124 ~166 dirt
setblock ~157 ~124 ~167 dirt
setblock ~157 ~124 ~168 dirt
setblock ~157 ~124 ~169 dirt
setblock ~157 ~124 ~170 dirt
setblock ~157 ~124 ~171 dirt
setblock ~157 ~124 ~172 grass_block
setblock ~157 ~124 ~173 grass_block
setblock ~157 ~124 ~174 grass_block
setblock ~157 ~124 ~175 grass_block
setblock ~157 ~124 ~176 grass_block
setblock ~157 ~124 ~177 grass_block
setblock ~157 ~124 ~178 grass_block
setblock ~157 ~124 ~179 grass_block
setblock ~157 ~124 ~180 grass_block
setblock ~157 ~124 ~181 grass_block
setblock ~157 ~124 ~182 grass_block
setblock ~157 ~124 ~183 dirt
setblock ~157 ~124 ~184 dirt
setblock ~157 ~124 ~185 dirt
setblock ~157 ~124 ~186 dirt
setblock ~157 ~124 ~187 dirt
setblock ~157 ~124 ~188 dirt
setblock ~157 ~124 ~189 dirt
setblock ~157 ~124 ~190 dirt
setblock ~157 ~124 ~191 dirt
setblock ~157 ~124 ~192 dirt
setblock ~157 ~124 ~193 dirt
setblock ~157 ~124 ~194 dirt
setblock ~157 ~124 ~195 dirt
setblock ~157 ~124 ~196 dirt
setblock ~157 ~124 ~197 dirt
setblock ~157 ~124 ~198 dirt
setblock ~157 ~124 ~199 dirt
setblock ~157 ~125 ~2 short_grass
setblock ~157 ~125 ~3 short_grass
setblock ~157 ~125 ~7 grass_block
setblock ~157 ~125 ~8 grass_block
setblock ~157 ~125 ~9 grass_block
setblock ~157 ~125 ~10 grass_block
setblock ~157 ~125 ~11 grass_block
setblock ~157 ~125 ~35 grass_block
setblock ~157 ~125 ~36 grass_block
setblock ~157 ~125 ~37 dirt
setblock ~157 ~125 ~38 dirt
setblock ~157 ~125 ~39 dirt
setblock ~157 ~125 ~40 dirt
setblock ~157 ~125 ~41 dirt
setblock ~157 ~125 ~42 dirt
setblock ~157 ~125 ~43 dirt
setblock ~157 ~125 ~44 dirt
setblock ~157 ~125 ~45 dirt
setblock ~157 ~125 ~46 dirt
setblock ~157 ~125 ~47 dirt
setblock ~157 ~125 ~48 dirt
setblock ~157 ~125 ~49 dirt
setblock ~157 ~125 ~50 dirt
setblock ~157 ~125 ~51 dirt
setblock ~157 ~125 ~52 dirt
setblock ~157 ~125 ~53 grass_block
setblock ~157 ~125 ~54 grass_block
setblock ~157 ~125 ~55 grass_block
setblock ~157 ~125 ~56 fern
setblock ~157 ~125 ~61 poppy
setblock ~157 ~125 ~63 short_grass
setblock ~157 ~125 ~64 short_grass
setblock ~157 ~125 ~66 short_grass
setblock ~157 ~125 ~69 short_grass
setblock ~157 ~125 ~71 grass_block
setblock ~157 ~125 ~72 grass_block
setblock ~157 ~125 ~73 grass_block
setblock ~157 ~125 ~74 grass_block
setblock ~157 ~125 ~75 dirt
setblock ~157 ~125 ~76 dirt
setblock ~157 ~125 ~77 dirt
setblock ~157 ~125 ~78 dirt
setblock ~157 ~125 ~79 dirt
setblock ~157 ~125 ~80 dirt
setblock ~157 ~125 ~81 dirt
setblock ~157 ~125 ~82 dirt
setblock ~157 ~125 ~83 dirt
setblock ~157 ~125 ~84 dirt
setblock ~157 ~125 ~85 dirt
setblock ~157 ~125 ~86 dirt
setblock ~157 ~125 ~87 dirt
setblock ~157 ~125 ~88 dirt
setblock ~157 ~125 ~89 dirt
setblock ~157 ~125 ~90 dirt
setblock ~157 ~125 ~91 dirt
setblock ~157 ~125 ~92 dirt
setblock ~157 ~125 ~93 dirt
setblock ~157 ~125 ~94 dirt
setblock ~157 ~125 ~95 dirt
setblock ~157 ~125 ~96 dirt
setblock ~157 ~125 ~97 dirt
setblock ~157 ~125 ~98 dirt
setblock ~157 ~125 ~99 dirt
setblock ~157 ~125 ~100 dirt
setblock ~157 ~125 ~101 dirt
setblock ~157 ~125 ~102 dirt
setblock ~157 ~125 ~103 grass_block
setblock ~157 ~125 ~104 grass_block
setblock ~157 ~125 ~105 grass_block
setblock ~157 ~125 ~107 short_grass
setblock ~157 ~125 ~146 short_grass
setblock ~157 ~125 ~148 grass_block
setblock ~157 ~125 ~149 grass_block
setblock ~157 ~125 ~150 grass_block
setblock ~157 ~125 ~151 grass_block
setblock ~157 ~125 ~152 grass_block
setblock ~157 ~125 ~153 grass_block
setblock ~157 ~125 ~154 grass_block
setblock ~157 ~125 ~155 grass_block
setblock ~157 ~125 ~156 dirt
setblock ~157 ~125 ~157 dirt
setblock ~157 ~125 ~158 dirt
setblock ~157 ~125 ~159 dirt
setblock ~157 ~125 ~160 dirt
setblock ~157 ~125 ~161 dirt
setblock ~157 ~125 ~162 dirt
setblock ~157 ~125 ~163 dirt
setblock ~157 ~125 ~164 dirt
setblock ~157 ~125 ~165 grass_block
setblock ~157 ~125 ~166 grass_block
setblock ~157 ~125 ~167 grass_block
setblock ~157 ~125 ~168 grass_block
setblock ~157 ~125 ~169 grass_block
setblock ~157 ~125 ~170 grass_block
setblock ~157 ~125 ~171 grass_block
setblock ~157 ~125 ~172 short_grass
setblock ~157 ~125 ~173 short_grass
setblock ~157 ~125 ~181 short_grass
setblock ~157 ~125 ~182 short_grass
setblock ~157 ~125 ~183 grass_block
setblock ~157 ~125 ~184 grass_block
setblock ~157 ~125 ~185 grass_block
setblock ~157 ~125 ~186 grass_block
setblock ~157 ~125 ~187 grass_block
setblock ~157 ~125 ~188 dirt
setblock ~157 ~125 ~189 dirt
setblock ~157 ~125 ~190 dirt
setblock ~157 ~125 ~191 dirt
setblock ~157 ~125 ~192 dirt
setblock ~157 ~125 ~193 dirt
setblock ~157 ~125 ~194 dirt
setblock ~157 ~125 ~195 dirt
setblock ~157 ~125 ~196 dirt
setblock ~157 ~125 ~197 dirt
setblock ~157 ~125 ~198 dirt
setblock ~157 ~125 ~199 dirt
setblock ~157 ~126 ~7 short_grass
setblock ~157 ~126 ~9 short_grass
setblock ~157 ~126 ~37 grass_block
setblock ~157 ~126 ~38 grass_block
setblock ~157 ~126 ~39 grass_block
setblock ~157 ~126 ~40 dirt
setblock ~157 ~126 ~41 dirt
setblock ~157 ~126 ~42 dirt
setblock ~157 ~126 ~43 dirt
setblock ~157 ~126 ~44 dirt
setblock ~157 ~126 ~45 dirt
setblock ~157 ~126 ~46 dirt
setblock ~157 ~126 ~47 dirt
setblock ~157 ~126 ~48 dirt
setblock ~157 ~126 ~49 dirt
setblock ~157 ~126 ~50 grass_block
setblock ~157 ~126 ~51 grass_block
setblock ~157 ~126 ~52 grass_block
setblock ~157 ~126 ~54 short_grass
setblock ~157 ~126 ~73 short_grass
setblock ~157 ~126 ~74 short_grass
setblock ~157 ~126 ~75 grass_block
setblock ~157 ~126 ~76 grass_block
setblock ~157 ~126 ~77 dirt
setblock ~157 ~126 ~78 dirt
setblock ~157 ~126 ~79 dirt
setblock ~157 ~126 ~80 dirt
setblock ~157 ~126 ~81 dirt
setblock ~157 ~126 ~82 dirt
setblock ~157 ~126 ~83 dirt
setblock ~157 ~126 ~84 dirt
setblock ~157 ~126 ~85 dirt
setblock ~157 ~126 ~86 grass_block
setblock ~157 ~126 ~87 grass_block
setblock ~157 ~126 ~88 grass_block
setblock ~157 ~126 ~89 grass_block
setblock ~157 ~126 ~90 grass_block
setblock ~157 ~126 ~91 grass_block
setblock ~157 ~126 ~92 grass_block
setblock ~157 ~126 ~93 grass_block
setblock ~157 ~126 ~94 grass_block
setblock ~157 ~126 ~95 grass_block
setblock ~157 ~126 ~96 grass_block
setblock ~157 ~126 ~97 grass_block
setblock ~157 ~126 ~98 grass_block
setblock ~157 ~126 ~99 grass_block
setblock ~157 ~126 ~100 grass_block
setblock ~157 ~126 ~101 grass_block
setblock ~157 ~126 ~102 grass_block
setblock ~157 ~126 ~103 short_grass
setblock ~157 ~126 ~104 short_grass
setblock ~157 ~126 ~150 poppy
setblock ~157 ~126 ~155 short_grass
setblock ~157 ~126 ~156 grass_block
setblock ~157 ~126 ~157 grass_block
setblock ~157 ~126 ~158 grass_block
setblock ~157 ~126 ~159 grass_block
setblock ~157 ~126 ~160 grass_block
setblock ~157 ~126 ~161 grass_block
setblock ~157 ~126 ~162 grass_block
setblock ~157 ~126 ~163 grass_block
setblock ~157 ~126 ~164 grass_block
setblock ~157 ~126 ~165 short_grass
setblock ~157 ~126 ~166 short_grass
setblock ~157 ~126 ~169 short_grass
setblock ~157 ~126 ~171 short_grass
setblock ~157 ~126 ~184 short_grass
setblock ~157 ~126 ~185 short_grass
setblock ~157 ~126 ~188 grass_block
setblock ~157 ~126 ~189 grass_block
setblock ~157 ~126 ~190 grass_block
setblock ~157 ~126 ~191 grass_block
setblock ~157 ~126 ~192 grass_block
setblock ~157 ~126 ~193 grass_block
setblock ~157 ~126 ~194 grass_block
setblock ~157 ~126 ~195 grass_block
setblock ~157 ~126 ~196 grass_block
setblock ~157 ~126 ~197 dirt
setblock ~157 ~126 ~198 dirt
setblock ~157 ~126 ~199 dirt
setblock ~157 ~127 ~38 poppy
setblock ~157 ~127 ~39 fern
setblock ~157 ~127 ~40 grass_block
setblock ~157 ~127 ~41 grass_block
setblock ~157 ~127 ~42 grass_block
setblock ~157 ~127 ~43 grass_block
setblock ~157 ~127 ~44 grass_block
setblock ~157 ~127 ~45 grass_block
setblock ~157 ~127 ~46 grass_block
setblock ~157 ~127 ~47 grass_block
setblock ~157 ~127 ~48 grass_block
setblock ~157 ~127 ~49 grass_block
setblock ~157 ~127 ~51 fern
setblock ~157 ~127 ~52 short_grass
setblock ~157 ~127 ~77 grass_block
setblock ~157 ~127 ~78 grass_block
setblock ~157 ~127 ~79 dirt
setblock ~157 ~127 ~80 dirt
setblock ~157 ~127 ~81 dirt
setblock ~157 ~127 ~82 grass_block
setblock ~157 ~127 ~83 grass_block
setblock ~157 ~127 ~84 grass_block
setblock ~157 ~127 ~85 grass_block
setblock ~157 ~127 ~88 short_grass
setblock ~157 ~127 ~91 short_grass
setblock ~157 ~127 ~95 short_grass
setblock ~157 ~127 ~96 poppy
setblock ~157 ~127 ~102 short_grass
setblock ~157 ~127 ~156 poppy
setblock ~157 ~127 ~158 short_grass
setblock ~157 ~127 ~163 short_grass
setblock ~157 ~127 ~164 short_grass
setblock ~157 ~127 ~193 short_grass
setblock ~157 ~127 ~194 short_grass
setblock ~157 ~127 ~195 short_grass
setblock ~157 ~127 ~197 grass_block
setblock ~157 ~127 ~198 grass_block
setblock ~157 ~127 ~199 grass_block
setblock ~157 ~128 ~40 short_grass
setblock ~157 ~128 ~41 short_grass
setblock ~157 ~128 ~45 short_grass
setblock ~157 ~128 ~79 grass_block
setblock ~157 ~128 ~80 grass_block
setblock ~157 ~128 ~81 grass_block
setblock ~157 ~128 ~82 short_grass
setblock ~157 ~129 ~80 short_grass
setblock ~158 ~122 ~0 dirt
setblock ~158 ~122 ~1 dirt
setblock ~158 ~122 ~2 dirt
setblock ~158 ~122 ~3 dirt
setblock ~158 ~122 ~4 dirt
setblock ~158 ~122 ~5 dirt
setblock ~158 ~122 ~6 dirt
setblock ~158 ~122 ~7 dirt
setblock ~158 ~122 ~8 dirt
setblock ~158 ~122 ~9 dirt
setblock ~158 ~122 ~10 dirt
setblock ~158 ~122 ~11 dirt
setblock ~158 ~122 ~12 dirt
setblock ~158 ~122 ~13 dirt
setblock ~158 ~122 ~14 dirt
setblock ~158 ~122 ~15 dirt
setblock ~158 ~122 ~16 dirt
setblock ~158 ~122 ~17 dirt
setblock ~158 ~122 ~18 dirt
setblock ~158 ~122 ~19 dirt
setblock ~158 ~122 ~20 grass_block
setblock ~158 ~122 ~21 grass_block
setblock ~158 ~122 ~22 grass_block
setblock ~158 ~122 ~23 grass_block
setblock ~158 ~122 ~24 grass_block
setblock ~158 ~122 ~25 grass_block
setblock ~158 ~122 ~26 grass_block
setblock ~158 ~122 ~27 grass_block
setblock ~158 ~122 ~28 grass_block
setblock ~158 ~122 ~29 grass_block
setblock ~158 ~122 ~30 grass_block
setblock ~158 ~122 ~31 dirt
setblock ~158 ~122 ~32 dirt
setblock ~158 ~122 ~33 dirt
setblock ~158 ~122 ~34 dirt
setblock ~158 ~122 ~35 dirt
setblock ~158 ~122 ~36 dirt
setblock ~158 ~122 ~37 dirt
setblock ~158 ~122 ~38 dirt
setblock ~158 ~122 ~39 dirt
setblock ~158 ~122 ~40 dirt
setblock ~158 ~122 ~41 dirt
setblock ~158 ~122 ~42 dirt
setblock ~158 ~122 ~43 dirt
setblock ~158 ~122 ~44 dirt
setblock ~158 ~122 ~45 dirt
setblock ~158 ~122 ~46 dirt
setblock ~158 ~122 ~47 dirt
setblock ~158 ~122 ~48 dirt
setblock ~158 ~122 ~49 dirt
setblock ~158 ~122 ~50 dirt
setblock ~158 ~122 ~51 dirt
setblock ~158 ~122 ~52 dirt
setblock ~158 ~122 ~53 dirt
setblock ~158 ~122 ~54 dirt
setblock ~158 ~122 ~55 dirt
setblock ~158 ~122 ~56 dirt
setblock ~158 ~122 ~57 dirt
setblock ~158 ~122 ~58 dirt
setblock ~158 ~122 ~59 dirt
setblock ~158 ~122 ~60 dirt
setblock ~158 ~122 ~61 dirt
setblock ~158 ~122 ~62 dirt
setblock ~158 ~122 ~63 dirt
setblock ~158 ~122 ~64 dirt
setblock ~158 ~122 ~65 dirt
setblock ~158 ~122 ~66 dirt
setblock ~158 ~122 ~67 dirt
setblock ~158 ~122 ~68 dirt
setblock ~158 ~122 ~69 dirt
setblock ~158 ~122 ~70 dirt
setblock ~158 ~122 ~71 dirt
setblock ~158 ~122 ~72 dirt
setblock ~158 ~122 ~73 dirt
setblock ~158 ~122 ~74 dirt
setblock ~158 ~122 ~75 dirt
setblock ~158 ~122 ~76 dirt
setblock ~158 ~122 ~77 dirt
setblock ~158 ~122 ~78 dirt
setblock ~158 ~122 ~79 dirt
setblock ~158 ~122 ~80 dirt
setblock ~158 ~122 ~81 dirt
setblock ~158 ~122 ~82 dirt
setblock ~158 ~122 ~83 dirt
setblock ~158 ~122 ~84 dirt
setblock ~158 ~122 ~85 dirt
setblock ~158 ~122 ~86 dirt
setblock ~158 ~122 ~87 dirt
setblock ~158 ~122 ~88 dirt
setblock ~158 ~122 ~89 dirt
setblock ~158 ~122 ~90 dirt
setblock ~158 ~122 ~91 dirt
setblock ~158 ~122 ~92 dirt
setblock ~158 ~122 ~93 dirt
setblock ~158 ~122 ~94 dirt
setblock ~158 ~122 ~95 dirt
setblock ~158 ~122 ~96 dirt
setblock ~158 ~122 ~97 dirt
setblock ~158 ~122 ~98 dirt
setblock ~158 ~122 ~99 dirt
setblock ~158 ~122 ~100 dirt
setblock ~158 ~122 ~101 dirt
setblock ~158 ~122 ~102 dirt
setblock ~158 ~122 ~103 dirt
setblock ~158 ~122 ~104 dirt
setblock ~158 ~122 ~105 dirt
setblock ~158 ~122 ~106 dirt
setblock ~158 ~122 ~107 dirt
setblock ~158 ~122 ~108 dirt
setblock ~158 ~122 ~109 dirt
setblock ~158 ~122 ~110 dirt
setblock ~158 ~122 ~111 dirt
setblock ~158 ~122 ~112 dirt
setblock ~158 ~122 ~113 dirt
setblock ~158 ~122 ~114 dirt
setblock ~158 ~122 ~115 dirt
setblock ~158 ~122 ~116 dirt
setblock ~158 ~122 ~117 dirt
setblock ~158 ~122 ~118 dirt
setblock ~158 ~122 ~119 dirt
setblock ~158 ~122 ~120 dirt
setblock ~158 ~122 ~121 dirt
setblock ~158 ~122 ~122 dirt
setblock ~158 ~122 ~123 dirt
setblock ~158 ~122 ~124 dirt
setblock ~158 ~122 ~125 dirt
setblock ~158 ~122 ~126 dirt
setblock ~158 ~122 ~127 dirt
setblock ~158 ~122 ~128 dirt
setblock ~158 ~122 ~129 dirt
setblock ~158 ~122 ~130 dirt
setblock ~158 ~122 ~131 dirt
setblock ~158 ~122 ~132 dirt
setblock ~158 ~122 ~133 dirt
setblock ~158 ~122 ~134 dirt
setblock ~158 ~122 ~135 dirt
setblock ~158 ~122 ~136 dirt
setblock ~158 ~122 ~137 dirt
setblock ~158 ~122 ~138 grass_block
setblock ~158 ~122 ~139 grass_block
setblock ~158 ~122 ~140 grass_block
setblock ~158 ~122 ~141 dirt
setblock ~158 ~122 ~142 dirt
setblock ~158 ~122 ~143 dirt
setblock ~158 ~122 ~144 dirt
setblock ~158 ~122 ~145 dirt
setblock ~158 ~122 ~146 dirt
setblock ~158 ~122 ~147 dirt
setblock ~158 ~122 ~148 dirt
setblock ~158 ~122 ~149 dirt
setblock ~158 ~122 ~150 dirt
setblock ~158 ~122 ~151 dirt
setblock ~158 ~122 ~152 dirt
setblock ~158 ~122 ~153 dirt
setblock ~158 ~122 ~154 dirt
setblock ~158 ~122 ~155 dirt
setblock ~158 ~122 ~156 dirt
setblock ~158 ~122 ~157 dirt
setblock ~158 ~122 ~158 dirt
setblock ~158 ~122 ~159 dirt
setblock ~158 ~122 ~160 dirt
setblock ~158 ~122 ~161 dirt
setblock ~158 ~122 ~162 dirt
setblock ~158 ~122 ~163 dirt
setblock ~158 ~122 ~164 dirt
setblock ~158 ~122 ~165 dirt
setblock ~158 ~122 ~166 dirt
setblock ~158 ~122 ~167 dirt
setblock ~158 ~122 ~168 dirt
setblock ~158 ~122 ~169 dirt
setblock ~158 ~122 ~170 dirt
setblock ~158 ~122 ~171 dirt
setblock ~158 ~122 ~172 dirt
setblock ~158 ~122 ~173 dirt
setblock ~158 ~122 ~174 dirt
setblock ~158 ~122 ~175 dirt
setblock ~158 ~122 ~176 dirt
setblock ~158 ~122 ~177 dirt
setblock ~158 ~122 ~178 dirt
setblock ~158 ~122 ~179 dirt
setblock ~158 ~122 ~180 dirt
setblock ~158 ~122 ~181 dirt
setblock ~158 ~122 ~182 dirt
setblock ~158 ~122 ~183 dirt
setblock ~158 ~122 ~184 dirt
setblock ~158 ~122 ~185 dirt
setblock ~158 ~122 ~186 dirt
setblock ~158 ~122 ~187 dirt
setblock ~158 ~122 ~188 dirt
setblock ~158 ~122 ~189 dirt
setblock ~158 ~122 ~190 dirt
setblock ~158 ~122 ~191 dirt
setblock ~158 ~122 ~192 dirt
setblock ~158 ~122 ~193 dirt
setblock ~158 ~122 ~194 dirt
setblock ~158 ~122 ~195 dirt
setblock ~158 ~122 ~196 dirt
setblock ~158 ~122 ~197 dirt
setblock ~158 ~122 ~198 dirt
setblock ~158 ~122 ~199 dirt
setblock ~158 ~123 ~0 dirt
setblock ~158 ~123 ~1 dirt
setblock ~158 ~123 ~2 dirt
setblock ~158 ~123 ~3 dirt
setblock ~158 ~123 ~4 dirt
setblock ~158 ~123 ~5 dirt
setblock ~158 ~123 ~6 dirt
setblock ~158 ~123 ~7 dirt
setblock ~158 ~123 ~8 dirt
setblock ~158 ~123 ~9 dirt
setblock ~158 ~123 ~10 dirt
setblock ~158 ~123 ~11 dirt
setblock ~158 ~123 ~12 dirt
setblock ~158 ~123 ~13 dirt
setblock ~158 ~123 ~14 dirt
setblock ~158 ~123 ~15 grass_block
setblock ~158 ~123 ~16 grass_block
setblock ~158 ~123 ~17 grass_block
setblock ~158 ~123 ~18 grass_block
setblock ~158 ~123 ~19 grass_block
setblock ~158 ~123 ~21 short_grass
setblock ~158 ~123 ~22 short_grass
setblock ~158 ~123 ~23 short_grass
setblock ~158 ~123 ~29 short_grass
setblock ~158 ~123 ~31 grass_block
setblock ~158 ~123 ~32 grass_block
setblock ~158 ~123 ~33 dirt
setblock ~158 ~123 ~34 dirt
setblock ~158 ~123 ~35 dirt
setblock ~158 ~123 ~36 dirt
setblock ~158 ~123 ~37 dirt
setblock ~158 ~123 ~38 dirt
setblock ~158 ~123 ~39 dirt
setblock ~158 ~123 ~40 dirt
setblock ~158 ~123 ~41 dirt
setblock ~158 ~123 ~42 dirt
setblock ~158 ~123 ~43 dirt
setblock ~158 ~123 ~44 dirt
setblock ~158 ~123 ~45 dirt
setblock ~158 ~123 ~46 dirt
setblock ~158 ~123 ~47 dirt
setblock ~158 ~123 ~48 dirt
setblock ~158 ~123 ~49 dirt
setblock ~158 ~123 ~50 dirt
setblock ~158 ~123 ~51 dirt
setblock ~158 ~123 ~52 dirt
setblock ~158 ~123 ~53 dirt
setblock ~158 ~123 ~54 dirt
setblock ~158 ~123 ~55 dirt
setblock ~158 ~123 ~56 dirt
setblock ~158 ~123 ~57 dirt
setblock ~158 ~123 ~58 dirt
setblock ~158 ~123 ~59 dirt
setblock ~158 ~123 ~60 grass_block
setblock ~158 ~123 ~61 dirt
setblock ~158 ~123 ~62 dirt
setblock ~158 ~123 ~63 dirt
setblock ~158 ~123 ~64 dirt
setblock ~158 ~123 ~65 dirt
setblock ~158 ~123 ~66 dirt
setblock ~158 ~123 ~67 dirt
setblock ~158 ~123 ~68 dirt
setblock ~158 ~123 ~69 dirt
setblock ~158 ~123 ~70 dirt
setblock ~158 ~123 ~71 dirt
setblock ~158 ~123 ~72 dirt
setblock ~158 ~123 ~73 dirt
setblock ~158 ~123 ~74 dirt
setblock ~158 ~123 ~75 dirt
setblock ~158 ~123 ~76 dirt
setblock ~158 ~123 ~77 dirt
setblock ~158 ~123 ~78 dirt
setblock ~158 ~123 ~79 dirt
setblock ~158 ~123 ~80 dirt
setblock ~158 ~123 ~81 dirt
setblock ~158 ~123 ~82 dirt
setblock ~158 ~123 ~83 dirt
setblock ~158 ~123 ~84 dirt
setblock ~158 ~123 ~85 dirt
setblock ~158 ~123 ~86 dirt
setblock ~158 ~123 ~87 dirt
setblock ~158 ~123 ~88 dirt
setblock ~158 ~123 ~89 dirt
setblock ~158 ~123 ~90 dirt
setblock ~158 ~123 ~91 dirt
setblock ~158 ~123 ~92 dirt
setblock ~158 ~123 ~93 dirt
setblock ~158 ~123 ~94 dirt
setblock ~158 ~123 ~95 dirt
setblock ~158 ~123 ~96 dirt
setblock ~158 ~123 ~97 dirt
setblock ~158 ~123 ~98 dirt
setblock ~158 ~123 ~99 dirt
setblock ~158 ~123 ~100 dirt
setblock ~158 ~123 ~101 dirt
setblock ~158 ~123 ~102 dirt
setblock ~158 ~123 ~103 dirt
setblock ~158 ~123 ~104 dirt
setblock ~158 ~123 ~105 dirt
setblock ~158 ~123 ~106 dirt
setblock ~158 ~123 ~107 dirt
setblock ~158 ~123 ~108 dirt
setblock ~158 ~123 ~109 grass_block
setblock ~158 ~123 ~110 grass_block
setblock ~158 ~123 ~111 grass_block
setblock ~158 ~123 ~112 grass_block
setblock ~158 ~123 ~113 grass_block
setblock ~158 ~123 ~114 grass_block
setblock ~158 ~123 ~115 grass_block
setblock ~158 ~123 ~116 grass_block
setblock ~158 ~123 ~117 grass_block
setblock ~158 ~123 ~118 grass_block
setblock ~158 ~123 ~119 grass_block
setblock ~158 ~123 ~120 grass_block
setblock ~158 ~123 ~121 grass_block
setblock ~158 ~123 ~122 grass_block
setblock ~158 ~123 ~123 grass_block
setblock ~158 ~123 ~124 grass_block
