setblock ~169 ~116 ~90 dirt
setblock ~169 ~116 ~91 dirt
setblock ~169 ~117 ~72 dirt
setblock ~169 ~117 ~73 dirt
setblock ~169 ~117 ~74 dirt
setblock ~169 ~117 ~75 dirt
setblock ~169 ~117 ~76 dirt
setblock ~169 ~117 ~77 dirt
setblock ~169 ~117 ~78 dirt
setblock ~169 ~117 ~79 dirt
setblock ~169 ~117 ~80 dirt
setblock ~169 ~117 ~81 dirt
setblock ~169 ~117 ~82 dirt
setblock ~169 ~117 ~83 dirt
setblock ~169 ~117 ~84 dirt
setblock ~169 ~117 ~85 dirt
setblock ~169 ~117 ~86 dirt
setblock ~169 ~117 ~87 dirt
setblock ~169 ~117 ~88 dirt
setblock ~169 ~117 ~89 dirt
setblock ~169 ~117 ~90 dirt
setblock ~169 ~117 ~91 dirt
setblock ~169 ~118 ~72 dirt
setblock ~169 ~118 ~73 dirt
setblock ~169 ~118 ~74 dirt
setblock ~169 ~118 ~75 dirt
setblock ~169 ~118 ~76 dirt
setblock ~169 ~118 ~77 dirt
setblock ~169 ~118 ~78 dirt
setblock ~169 ~118 ~79 dirt
setblock ~169 ~118 ~80 dirt
setblock ~169 ~118 ~81 dirt
setblock ~169 ~118 ~82 dirt
setblock ~169 ~118 ~83 dirt
setblock ~169 ~118 ~84 dirt
setblock ~169 ~118 ~85 dirt
setblock ~169 ~118 ~86 dirt
setblock ~169 ~118 ~87 dirt
setblock ~169 ~118 ~88 dirt
setblock ~169 ~118 ~89 dirt
setblock ~169 ~118 ~90 dirt
setblock ~169 ~118 ~91 dirt
setblock ~169 ~118 ~92 dirt
setblock ~169 ~118 ~100 dirt
setblock ~169 ~118 ~101 dirt
setblock ~169 ~119 ~71 dirt
setblock ~169 ~119 ~72 dirt
setblock ~169 ~119 ~73 dirt
setblock ~169 ~119 ~74 dirt
setblock ~169 ~119 ~75 dirt
setblock ~169 ~119 ~76 dirt
setblock ~169 ~119 ~77 dirt
setblock ~169 ~119 ~78 dirt
setblock ~169 ~119 ~79 dirt
setblock ~169 ~119 ~80 dirt
setblock ~169 ~119 ~81 dirt
setblock ~169 ~119 ~82 dirt
setblock ~169 ~119 ~83 dirt
setblock ~169 ~119 ~84 dirt
setblock ~169 ~119 ~85 dirt
setblock ~169 ~119 ~86 dirt
setblock ~169 ~119 ~87 dirt
setblock ~169 ~119 ~88 dirt
setblock ~169 ~119 ~89 dirt
setblock ~169 ~119 ~90 dirt
setblock ~169 ~119 ~91 dirt
setblock ~169 ~119 ~92 dirt
setblock ~169 ~119 ~93 dirt
setblock ~169 ~119 ~94 dirt
setblock ~169 ~119 ~96 dirt
setblock ~169 ~119 ~97 dirt
setblock ~169 ~119 ~99 dirt
setblock ~169 ~119 ~100 dirt
setblock ~169 ~119 ~101 dirt
setblock ~169 ~119 ~102 dirt
setblock ~169 ~120 ~70 dirt
setblock ~169 ~120 ~71 dirt
setblock ~169 ~120 ~72 dirt
setblock ~169 ~120 ~73 dirt
setblock ~169 ~120 ~74 dirt
setblock ~169 ~120 ~75 dirt
setblock ~169 ~120 ~76 dirt
setblock ~169 ~120 ~77 dirt
setblock ~169 ~120 ~78 dirt
setblock ~169 ~120 ~79 dirt
setblock ~169 ~120 ~80 dirt
setblock ~169 ~120 ~81 dirt
setblock ~169 ~120 ~82 dirt
setblock ~169 ~120 ~83 dirt
setblock ~169 ~120 ~84 dirt
setblock ~169 ~120 ~85 dirt
setblock ~169 ~120 ~86 dirt
setblock ~169 ~120 ~87 dirt
setblock ~169 ~120 ~88 dirt
setblock ~169 ~120 ~89 dirt
setblock ~169 ~120 ~90 dirt
setblock ~169 ~120 ~91 dirt
setblock ~169 ~120 ~92 dirt
setblock ~169 ~120 ~93 dirt
setblock ~169 ~120 ~94 dirt
setblock ~169 ~120 ~95 dirt
setblock ~169 ~120 ~96 dirt
setblock ~169 ~120 ~97 dirt
setblock ~169 ~120 ~98 dirt
setblock ~169 ~120 ~99 dirt
setblock ~169 ~120 ~100 dirt
setblock ~169 ~120 ~101 dirt
setblock ~169 ~120 ~102 dirt
setblock ~169 ~120 ~103 dirt
setblock ~169 ~120 ~106 dirt
setblock ~169 ~120 ~107 dirt
setblock ~169 ~121 ~69 dirt
setblock ~169 ~121 ~70 dirt
setblock ~169 ~121 ~71 dirt
setblock ~169 ~121 ~72 dirt
setblock ~169 ~121 ~73 dirt
setblock ~169 ~121 ~74 dirt
setblock ~169 ~121 ~75 dirt
setblock ~169 ~121 ~76 dirt
setblock ~169 ~121 ~77 dirt
setblock ~169 ~121 ~78 dirt
setblock ~169 ~121 ~79 dirt
setblock ~169 ~121 ~80 dirt
setblock ~169 ~121 ~81 dirt
setblock ~169 ~121 ~82 dirt
setblock ~169 ~121 ~83 dirt
setblock ~169 ~121 ~84 dirt
setblock ~169 ~121 ~85 dirt
setblock ~169 ~121 ~86 dirt
setblock ~169 ~121 ~87 dirt
setblock ~169 ~121 ~88 dirt
setblock ~169 ~121 ~89 dirt
setblock ~169 ~121 ~90 dirt
setblock ~169 ~121 ~91 dirt
setblock ~169 ~121 ~92 dirt
setblock ~169 ~121 ~93 dirt
setblock ~169 ~121 ~94 dirt
setblock ~169 ~121 ~95 dirt
setblock ~169 ~121 ~96 dirt
setblock ~169 ~121 ~97 dirt
setblock ~169 ~121 ~98 dirt
setblock ~169 ~121 ~99 dirt
setblock ~169 ~121 ~100 dirt
setblock ~169 ~121 ~101 dirt
setblock ~169 ~121 ~102 dirt
setblock ~169 ~121 ~103 dirt
setblock ~169 ~121 ~104 dirt
setblock ~169 ~121 ~105 dirt
setblock ~169 ~121 ~106 dirt
setblock ~169 ~121 ~107 dirt
setblock ~169 ~121 ~108 dirt
setblock ~169 ~122 ~69 dirt
setblock ~169 ~122 ~70 grass_block
setblock ~169 ~122 ~71 dirt
setblock ~169 ~122 ~72 dirt
setblock ~169 ~122 ~73 dirt
setblock ~169 ~122 ~74 dirt
setblock ~169 ~122 ~75 dirt
setblock ~169 ~122 ~76 dirt
setblock ~169 ~122 ~77 dirt
setblock ~169 ~122 ~78 dirt
setblock ~169 ~122 ~79 dirt
setblock ~169 ~122 ~80 dirt
setblock ~169 ~122 ~81 dirt
setblock ~169 ~122 ~82 dirt
setblock ~169 ~122 ~83 dirt
setblock ~169 ~122 ~84 dirt
setblock ~169 ~122 ~85 dirt
setblock ~169 ~122 ~86 dirt
setblock ~169 ~122 ~87 dirt
setblock ~169 ~122 ~88 dirt
setblock ~169 ~122 ~89 dirt
setblock ~169 ~122 ~90 dirt
setblock ~169 ~122 ~91 dirt
setblock ~169 ~122 ~92 dirt
setblock ~169 ~122 ~93 dirt
setblock ~169 ~122 ~94 dirt
setblock ~169 ~122 ~95 dirt
setblock ~169 ~122 ~96 dirt
setblock ~169 ~122 ~97 dirt
setblock ~169 ~122 ~98 dirt
setblock ~169 ~122 ~99 dirt
setblock ~169 ~122 ~100 grass_block
setblock ~169 ~122 ~101 dirt
setblock ~169 ~122 ~102 dirt
setblock ~169 ~122 ~103 dirt
setblock ~169 ~122 ~104 dirt
setblock ~169 ~122 ~105 dirt
setblock ~169 ~122 ~106 dirt
setblock ~169 ~122 ~107 grass_block
setblock ~169 ~122 ~108 grass_block
setblock ~169 ~123 ~69 grass_block
setblock ~169 ~123 ~71 grass_block
setblock ~169 ~123 ~72 grass_block
setblock ~169 ~123 ~73 grass_block
setblock ~169 ~123 ~74 dirt
setblock ~169 ~123 ~75 dirt
setblock ~169 ~123 ~76 dirt
setblock ~169 ~123 ~77 dirt
setblock ~169 ~123 ~78 dirt
setblock ~169 ~123 ~79 dirt
setblock ~169 ~123 ~80 dirt
setblock ~169 ~123 ~81 dirt
setblock ~169 ~123 ~82 dirt
setblock ~169 ~123 ~83 dirt
setblock ~169 ~123 ~84 dirt
setblock ~169 ~123 ~85 dirt
setblock ~169 ~123 ~86 dirt
setblock ~169 ~123 ~87 dirt
setblock ~169 ~123 ~88 dirt
setblock ~169 ~123 ~89 dirt
setblock ~169 ~123 ~90 dirt
setblock ~169 ~123 ~91 dirt
setblock ~169 ~123 ~92 dirt
setblock ~169 ~123 ~93 dirt
setblock ~169 ~123 ~94 dirt
setblock ~169 ~123 ~95 dirt
setblock ~169 ~123 ~96 dirt
setblock ~169 ~123 ~97 dirt
setblock ~169 ~123 ~98 grass_block
setblock ~169 ~123 ~99 grass_block
setblock ~169 ~123 ~101 grass_block
setblock ~169 ~123 ~102 grass_block
setblock ~169 ~123 ~103 grass_block
setblock ~169 ~123 ~104 grass_block
setblock ~169 ~123 ~105 grass_block
setblock ~169 ~123 ~106 grass_block
setblock ~169 ~123 ~108 short_grass
setblock ~169 ~124 ~71 short_grass
setblock ~169 ~124 ~74 grass_block
setblock ~169 ~124 ~75 grass_block
setblock ~169 ~124 ~76 grass_block
setblock ~169 ~124 ~77 dirt
setblock ~169 ~124 ~78 dirt
setblock ~169 ~124 ~79 dirt
setblock ~169 ~124 ~80 dirt
setblock ~169 ~124 ~81 dirt
setblock ~169 ~124 ~82 dirt
setblock ~169 ~124 ~83 dirt
setblock ~169 ~124 ~84 dirt
setblock ~169 ~124 ~85 dirt
setblock ~169 ~124 ~86 dirt
setblock ~169 ~124 ~87 dirt
setblock ~169 ~124 ~88 dirt
setblock ~169 ~124 ~89 dirt
setblock ~169 ~124 ~90 dirt
setblock ~169 ~124 ~91 dirt
setblock ~169 ~124 ~92 dirt
setblock ~169 ~124 ~93 dirt
setblock ~169 ~124 ~94 dirt
setblock ~169 ~124 ~95 dirt
setblock ~169 ~124 ~96 grass_block
setblock ~169 ~124 ~97 grass_block
setblock ~169 ~124 ~103 poppy
setblock ~169 ~124 ~106 short_grass
setblock ~169 ~125 ~77 grass_block
setblock ~169 ~125 ~78 grass_block
setblock ~169 ~125 ~79 grass_block
setblock ~169 ~125 ~80 dirt
setblock ~169 ~125 ~81 dirt
setblock ~169 ~125 ~82 dirt
setblock ~169 ~125 ~83 dirt
setblock ~169 ~125 ~84 dirt
setblock ~169 ~125 ~85 dirt
setblock ~169 ~125 ~86 dirt
setblock ~169 ~125 ~87 dirt
setblock ~169 ~125 ~88 dirt
setblock ~169 ~125 ~89 dirt
setblock ~169 ~125 ~90 dirt
setblock ~169 ~125 ~91 dirt
setblock ~169 ~125 ~92 dirt
setblock ~169 ~125 ~93 grass_block
setblock ~169 ~125 ~94 grass_block
setblock ~169 ~125 ~95 grass_block
setblock ~169 ~126 ~77 short_grass
setblock ~169 ~126 ~80 grass_block
setblock ~169 ~126 ~81 grass_block
setblock ~169 ~126 ~82 grass_block
setblock ~169 ~126 ~83 grass_block
setblock ~169 ~126 ~84 grass_block
setblock ~169 ~126 ~85 grass_block
setblock ~169 ~126 ~86 grass_block
setblock ~169 ~126 ~87 grass_block
setblock ~169 ~126 ~88 grass_block
setblock ~169 ~126 ~89 grass_block
setblock ~169 ~126 ~90 grass_block
setblock ~169 ~126 ~91 grass_block
setblock ~169 ~126 ~92 grass_block
setblock ~169 ~127 ~80 poppy
setblock ~169 ~127 ~82 short_grass
setblock ~169 ~127 ~91 short_grass
setblock ~170 ~109 ~82 dirt
setblock ~170 ~109 ~85 dirt
setblock ~170 ~110 ~81 dirt
setblock ~170 ~110 ~82 dirt
setblock ~170 ~110 ~85 dirt
setblock ~170 ~110 ~86 dirt
setblock ~170 ~111 ~81 dirt
setblock ~170 ~111 ~82 dirt
setblock ~170 ~111 ~84 dirt
setblock ~170 ~111 ~85 dirt
setblock ~170 ~111 ~86 dirt
setblock ~170 ~111 ~87 dirt
setblock ~170 ~112 ~80 dirt
setblock ~170 ~112 ~81 dirt
setblock ~170 ~112 ~82 dirt
setblock ~170 ~112 ~83 dirt
setblock ~170 ~112 ~84 dirt
setblock ~170 ~112 ~85 dirt
setblock ~170 ~112 ~86 dirt
setblock ~170 ~112 ~87 dirt
setblock ~170 ~112 ~88 dirt
setblock ~170 ~113 ~80 dirt
setblock ~170 ~113 ~81 dirt
setblock ~170 ~113 ~82 dirt
setblock ~170 ~113 ~83 dirt
setblock ~170 ~113 ~84 dirt
setblock ~170 ~113 ~85 dirt
setblock ~170 ~113 ~86 dirt
setblock ~170 ~113 ~87 dirt
setblock ~170 ~113 ~88 dirt
setblock ~170 ~113 ~89 dirt
setblock ~170 ~114 ~79 dirt
setblock ~170 ~114 ~80 dirt
setblock ~170 ~114 ~81 dirt
setblock ~170 ~114 ~82 dirt
setblock ~170 ~114 ~83 dirt
setblock ~170 ~114 ~84 dirt
setblock ~170 ~114 ~85 dirt
setblock ~170 ~114 ~86 dirt
setblock ~170 ~114 ~87 dirt
setblock ~170 ~114 ~88 dirt
setblock ~170 ~114 ~89 dirt
setblock ~170 ~114 ~90 dirt
setblock ~170 ~115 ~76 dirt
setblock ~170 ~115 ~77 dirt
setblock ~170 ~115 ~78 dirt
setblock ~170 ~115 ~79 dirt
setblock ~170 ~115 ~80 dirt
setblock ~170 ~115 ~81 dirt
setblock ~170 ~115 ~82 dirt
setblock ~170 ~115 ~83 dirt
setblock ~170 ~115 ~84 dirt
setblock ~170 ~115 ~85 dirt
setblock ~170 ~115 ~86 dirt
setblock ~170 ~115 ~87 dirt
setblock ~170 ~115 ~88 dirt
setblock ~170 ~115 ~89 dirt
setblock ~170 ~115 ~90 dirt
setblock ~170 ~116 ~74 dirt
setblock ~170 ~116 ~76 dirt
setblock ~170 ~116 ~77 dirt
setblock ~170 ~116 ~78 dirt
setblock ~170 ~116 ~79 dirt
setblock ~170 ~116 ~80 dirt
setblock ~170 ~116 ~81 dirt
setblock ~170 ~116 ~82 dirt
setblock ~170 ~116 ~83 dirt
setblock ~170 ~116 ~84 dirt
setblock ~170 ~116 ~85 dirt
setblock ~170 ~116 ~86 dirt
setblock ~170 ~116 ~87 dirt
setblock ~170 ~116 ~88 dirt
setblock ~170 ~116 ~89 dirt
setblock ~170 ~116 ~90 dirt
setblock ~170 ~116 ~91 dirt
setblock ~170 ~117 ~73 dirt
setblock ~170 ~117 ~74 dirt
setblock ~170 ~117 ~76 dirt
setblock ~170 ~117 ~77 dirt
setblock ~170 ~117 ~78 dirt
setblock ~170 ~117 ~79 dirt
setblock ~170 ~117 ~80 dirt
setblock ~170 ~117 ~81 dirt
setblock ~170 ~117 ~82 dirt
setblock ~170 ~117 ~83 dirt
setblock ~170 ~117 ~84 dirt
setblock ~170 ~117 ~85 dirt
setblock ~170 ~117 ~86 dirt
setblock ~170 ~117 ~87 dirt
setblock ~170 ~117 ~88 dirt
setblock ~170 ~117 ~89 dirt
setblock ~170 ~117 ~90 dirt
setblock ~170 ~117 ~91 dirt
setblock ~170 ~118 ~73 dirt
setblock ~170 ~118 ~74 dirt
setblock ~170 ~118 ~75 dirt
setblock ~170 ~118 ~76 dirt
setblock ~170 ~118 ~77 dirt
setblock ~170 ~118 ~78 dirt
setblock ~170 ~118 ~79 dirt
setblock ~170 ~118 ~80 dirt
setblock ~170 ~118 ~81 dirt
setblock ~170 ~118 ~82 dirt
setblock ~170 ~118 ~83 dirt
setblock ~170 ~118 ~84 dirt
setblock ~170 ~118 ~85 dirt
setblock ~170 ~118 ~86 dirt
setblock ~170 ~118 ~87 dirt
setblock ~170 ~118 ~88 dirt
setblock ~170 ~118 ~89 dirt
setblock ~170 ~118 ~90 dirt
setblock ~170 ~118 ~91 dirt
setblock ~170 ~119 ~72 dirt
setblock ~170 ~119 ~73 dirt
setblock ~170 ~119 ~74 dirt
setblock ~170 ~119 ~75 dirt
setblock ~170 ~119 ~76 dirt
setblock ~170 ~119 ~77 dirt
setblock ~170 ~119 ~78 dirt
setblock ~170 ~119 ~79 dirt
setblock ~170 ~119 ~80 dirt
setblock ~170 ~119 ~81 dirt
setblock ~170 ~119 ~82 dirt
setblock ~170 ~119 ~83 dirt
setblock ~170 ~119 ~84 dirt
setblock ~170 ~119 ~85 dirt
setblock ~170 ~119 ~86 dirt
setblock ~170 ~119 ~87 dirt
setblock ~170 ~119 ~88 dirt
setblock ~170 ~119 ~89 dirt
setblock ~170 ~119 ~90 dirt
setblock ~170 ~119 ~91 dirt
setblock ~170 ~119 ~92 dirt
setblock ~170 ~120 ~72 dirt
setblock ~170 ~120 ~73 dirt
setblock ~170 ~120 ~74 dirt
setblock ~170 ~120 ~75 dirt
setblock ~170 ~120 ~76 dirt
setblock ~170 ~120 ~77 dirt
setblock ~170 ~120 ~78 dirt
setblock ~170 ~120 ~79 dirt
setblock ~170 ~120 ~80 dirt
setblock ~170 ~120 ~81 dirt
setblock ~170 ~120 ~82 dirt
setblock ~170 ~120 ~83 dirt
setblock ~170 ~120 ~84 dirt
setblock ~170 ~120 ~85 dirt
setblock ~170 ~120 ~86 dirt
setblock ~170 ~120 ~87 dirt
setblock ~170 ~120 ~88 dirt
setblock ~170 ~120 ~89 dirt
setblock ~170 ~120 ~90 dirt
setblock ~170 ~120 ~91 dirt
setblock ~170 ~120 ~92 dirt
setblock ~170 ~120 ~94 dirt
setblock ~170 ~120 ~97 dirt
setblock ~170 ~121 ~71 dirt
setblock ~170 ~121 ~72 dirt
setblock ~170 ~121 ~73 dirt
setblock ~170 ~121 ~74 dirt
setblock ~170 ~121 ~75 dirt
setblock ~170 ~121 ~76 dirt
setblock ~170 ~121 ~77 dirt
setblock ~170 ~121 ~78 dirt
setblock ~170 ~121 ~79 dirt
setblock ~170 ~121 ~80 dirt
setblock ~170 ~121 ~81 dirt
setblock ~170 ~121 ~82 dirt
setblock ~170 ~121 ~83 dirt
setblock ~170 ~121 ~84 dirt
setblock ~170 ~121 ~85 dirt
setblock ~170 ~121 ~86 dirt
setblock ~170 ~121 ~87 dirt
setblock ~170 ~121 ~88 dirt
setblock ~170 ~121 ~89 dirt
setblock ~170 ~121 ~90 dirt
setblock ~170 ~121 ~91 dirt
setblock ~170 ~121 ~92 dirt
setblock ~170 ~121 ~93 dirt
setblock ~170 ~121 ~94 dirt
setblock ~170 ~121 ~95 dirt
setblock ~170 ~121 ~96 dirt
setblock ~170 ~121 ~97 dirt
setblock ~170 ~121 ~99 dirt
setblock ~170 ~121 ~101 dirt
setblock ~170 ~121 ~102 dirt
setblock ~170 ~121 ~103 dirt
setblock ~170 ~122 ~71 dirt
setblock ~170 ~122 ~72 dirt
setblock ~170 ~122 ~73 dirt
setblock ~170 ~122 ~74 dirt
setblock ~170 ~122 ~75 dirt
setblock ~170 ~122 ~76 dirt
setblock ~170 ~122 ~77 dirt
setblock ~170 ~122 ~78 dirt
setblock ~170 ~122 ~79 dirt
setblock ~170 ~122 ~80 dirt
setblock ~170 ~122 ~81 dirt
setblock ~170 ~122 ~82 dirt
setblock ~170 ~122 ~83 dirt
setblock ~170 ~122 ~84 dirt
setblock ~170 ~122 ~85 dirt
setblock ~170 ~122 ~86 dirt
setblock ~170 ~122 ~87 dirt
setblock ~170 ~122 ~88 dirt
setblock ~170 ~122 ~89 dirt
setblock ~170 ~122 ~90 dirt
setblock ~170 ~122 ~91 dirt
setblock ~170 ~122 ~92 dirt
setblock ~170 ~122 ~93 dirt
setblock ~170 ~122 ~94 dirt
setblock ~170 ~122 ~95 dirt
setblock ~170 ~122 ~96 dirt
setblock ~170 ~122 ~97 dirt
setblock ~170 ~122 ~99 grass_block
setblock ~170 ~122 ~101 grass_block
setblock ~170 ~122 ~102 grass_block
setblock ~170 ~122 ~103 grass_block
setblock ~170 ~123 ~71 grass_block
setblock ~170 ~123 ~72 grass_block
setblock ~170 ~123 ~73 grass_block
setblock ~170 ~123 ~74 dirt
setblock ~170 ~123 ~75 dirt
setblock ~170 ~123 ~76 dirt
setblock ~170 ~123 ~77 dirt
setblock ~170 ~123 ~78 dirt
setblock ~170 ~123 ~79 dirt
setblock ~170 ~123 ~80 dirt
setblock ~170 ~123 ~81 dirt
setblock ~170 ~123 ~82 dirt
setblock ~170 ~123 ~83 dirt
setblock ~170 ~123 ~84 dirt
setblock ~170 ~123 ~85 dirt
setblock ~170 ~123 ~86 dirt
setblock ~170 ~123 ~87 dirt
setblock ~170 ~123 ~88 dirt
setblock ~170 ~123 ~89 dirt
setblock ~170 ~123 ~90 dirt
setblock ~170 ~123 ~91 dirt
setblock ~170 ~123 ~92 dirt
setblock ~170 ~123 ~93 dirt
setblock ~170 ~123 ~94 dirt
setblock ~170 ~123 ~95 dirt
setblock ~170 ~123 ~96 dirt
setblock ~170 ~123 ~97 dirt
setblock ~170 ~124 ~71 short_grass
setblock ~170 ~124 ~74 grass_block
setblock ~170 ~124 ~75 grass_block
setblock ~170 ~124 ~76 grass_block
setblock ~170 ~124 ~77 grass_block
setblock ~170 ~124 ~78 dirt
setblock ~170 ~124 ~79 dirt
setblock ~170 ~124 ~80 dirt
setblock ~170 ~124 ~81 dirt
setblock ~170 ~124 ~82 dirt
setblock ~170 ~124 ~83 dirt
setblock ~170 ~124 ~84 dirt
setblock ~170 ~124 ~85 dirt
setblock ~170 ~124 ~86 dirt
setblock ~170 ~124 ~87 dirt
setblock ~170 ~124 ~88 dirt
setblock ~170 ~124 ~89 dirt
setblock ~170 ~124 ~90 dirt
setblock ~170 ~124 ~91 dirt
setblock ~170 ~124 ~92 dirt
setblock ~170 ~124 ~93 dirt
setblock ~170 ~124 ~94 dirt
setblock ~170 ~124 ~95 grass_block
setblock ~170 ~124 ~96 grass_block
setblock ~170 ~124 ~97 grass_block
setblock ~170 ~125 ~76 short_grass
setblock ~170 ~125 ~78 grass_block
setblock ~170 ~125 ~79 grass_block
setblock ~170 ~125 ~80 grass_block
setblock ~170 ~125 ~81 grass_block
setblock ~170 ~125 ~82 dirt
setblock ~170 ~125 ~83 dirt
setblock ~170 ~125 ~84 dirt
setblock ~170 ~125 ~85 dirt
setblock ~170 ~125 ~86 dirt
setblock ~170 ~125 ~87 dirt
setblock ~170 ~125 ~88 dirt
setblock ~170 ~125 ~89 dirt
setblock ~170 ~125 ~90 dirt
setblock ~170 ~125 ~91 dirt
setblock ~170 ~125 ~92 dirt
setblock ~170 ~125 ~93 grass_block
setblock ~170 ~125 ~94 grass_block
setblock ~170 ~125 ~97 short_grass
setblock ~170 ~126 ~80 short_grass
setblock ~170 ~126 ~82 grass_block
setblock ~170 ~126 ~83 grass_block
setblock ~170 ~126 ~84 grass_block
setblock ~170 ~126 ~85 grass_block
setblock ~170 ~126 ~86 grass_block
setblock ~170 ~126 ~87 grass_block
setblock ~170 ~126 ~88 grass_block
setblock ~170 ~126 ~89 grass_block
setblock ~170 ~126 ~90 grass_block
setblock ~170 ~126 ~91 grass_block
setblock ~170 ~126 ~92 grass_block
setblock ~170 ~126 ~93 short_grass
setblock ~170 ~126 ~94 short_grass
setblock ~170 ~127 ~84 short_grass
setblock ~170 ~127 ~86 short_grass
setblock ~170 ~127 ~89 short_grass
setblock ~170 ~127 ~90 short_grass
setblock ~171 ~112 ~81 dirt
setblock ~171 ~112 ~85 dirt
setblock ~171 ~112 ~86 dirt
setblock ~171 ~113 ~81 dirt
setblock ~171 ~113 ~82 dirt
setblock ~171 ~113 ~84 dirt
setblock ~171 ~113 ~85 dirt
setblock ~171 ~113 ~86 dirt
setblock ~171 ~113 ~87 dirt
setblock ~171 ~114 ~80 dirt
setblock ~171 ~114 ~81 dirt
setblock ~171 ~114 ~82 dirt
setblock ~171 ~114 ~83 dirt
setblock ~171 ~114 ~84 dirt
setblock ~171 ~114 ~85 dirt
setblock ~171 ~114 ~86 dirt
setblock ~171 ~114 ~87 dirt
setblock ~171 ~114 ~88 dirt
setblock ~171 ~114 ~89 dirt
setblock ~171 ~115 ~80 dirt
setblock ~171 ~115 ~81 dirt
setblock ~171 ~115 ~82 dirt
setblock ~171 ~115 ~83 dirt
setblock ~171 ~115 ~84 dirt
setblock ~171 ~115 ~85 dirt
setblock ~171 ~115 ~86 dirt
setblock ~171 ~115 ~87 dirt
setblock ~171 ~115 ~88 dirt
setblock ~171 ~115 ~89 dirt
setblock ~171 ~116 ~78 dirt
setblock ~171 ~116 ~79 dirt
setblock ~171 ~116 ~80 dirt
setblock ~171 ~116 ~81 dirt
setblock ~171 ~116 ~82 dirt
setblock ~171 ~116 ~83 dirt
setblock ~171 ~116 ~84 dirt
setblock ~171 ~116 ~85 dirt
setblock ~171 ~116 ~86 dirt
setblock ~171 ~116 ~87 dirt
setblock ~171 ~116 ~88 dirt
setblock ~171 ~116 ~89 dirt
setblock ~171 ~116 ~90 dirt
setblock ~171 ~117 ~77 dirt
setblock ~171 ~117 ~78 dirt
setblock ~171 ~117 ~79 dirt
setblock ~171 ~117 ~80 dirt
setblock ~171 ~117 ~81 dirt
setblock ~171 ~117 ~82 dirt
setblock ~171 ~117 ~83 dirt
setblock ~171 ~117 ~84 dirt
setblock ~171 ~117 ~85 dirt
setblock ~171 ~117 ~86 dirt
setblock ~171 ~117 ~87 dirt
setblock ~171 ~117 ~88 dirt
setblock ~171 ~117 ~89 dirt
setblock ~171 ~117 ~90 dirt
setblock ~171 ~117 ~91 dirt
setblock ~171 ~118 ~74 dirt
setblock ~171 ~118 ~77 dirt
setblock ~171 ~118 ~78 dirt
setblock ~171 ~118 ~79 dirt
setblock ~171 ~118 ~80 dirt
setblock ~171 ~118 ~81 dirt
setblock ~171 ~118 ~82 dirt
setblock ~171 ~118 ~83 dirt
setblock ~171 ~118 ~84 dirt
setblock ~171 ~118 ~85 dirt
setblock ~171 ~118 ~86 dirt
setblock ~171 ~118 ~87 dirt
setblock ~171 ~118 ~88 dirt
setblock ~171 ~118 ~89 dirt
setblock ~171 ~118 ~90 dirt
setblock ~171 ~118 ~91 dirt
setblock ~171 ~119 ~73 dirt
setblock ~171 ~119 ~74 dirt
setblock ~171 ~119 ~75 dirt
setblock ~171 ~119 ~76 dirt
setblock ~171 ~119 ~77 dirt
setblock ~171 ~119 ~78 dirt
setblock ~171 ~119 ~79 dirt
setblock ~171 ~119 ~80 dirt
setblock ~171 ~119 ~81 dirt
setblock ~171 ~119 ~82 dirt
setblock ~171 ~119 ~83 dirt
setblock ~171 ~119 ~84 dirt
setblock ~171 ~119 ~85 dirt
setblock ~171 ~119 ~86 dirt
setblock ~171 ~119 ~87 dirt
setblock ~171 ~119 ~88 dirt
setblock ~171 ~119 ~89 dirt
setblock ~171 ~119 ~90 dirt
setblock ~171 ~119 ~91 dirt
setblock ~171 ~120 ~72 dirt
setblock ~171 ~120 ~73 dirt
setblock ~171 ~120 ~74 dirt
setblock ~171 ~120 ~75 dirt
setblock ~171 ~120 ~76 dirt
setblock ~171 ~120 ~77 dirt
setblock ~171 ~120 ~78 dirt
setblock ~171 ~120 ~79 dirt
setblock ~171 ~120 ~80 dirt
setblock ~171 ~120 ~81 dirt
setblock ~171 ~120 ~82 dirt
setblock ~171 ~120 ~83 dirt
setblock ~171 ~120 ~84 dirt
setblock ~171 ~120 ~85 dirt
setblock ~171 ~120 ~86 dirt
setblock ~171 ~120 ~87 dirt
setblock ~171 ~120 ~88 dirt
setblock ~171 ~120 ~89 dirt
setblock ~171 ~120 ~90 dirt
setblock ~171 ~120 ~91 dirt
setblock ~171 ~121 ~71 dirt
setblock ~171 ~121 ~72 dirt
setblock ~171 ~121 ~73 dirt
setblock ~171 ~121 ~74 dirt
setblock ~171 ~121 ~75 dirt
setblock ~171 ~121 ~76 dirt
setblock ~171 ~121 ~77 dirt
setblock ~171 ~121 ~78 dirt
setblock ~171 ~121 ~79 dirt
setblock ~171 ~121 ~80 dirt
setblock ~171 ~121 ~81 dirt
setblock ~171 ~121 ~82 dirt
setblock ~171 ~121 ~83 dirt
setblock ~171 ~121 ~84 dirt
setblock ~171 ~121 ~85 dirt
setblock ~171 ~121 ~86 dirt
setblock ~171 ~121 ~87 dirt
setblock ~171 ~121 ~88 dirt
setblock ~171 ~121 ~89 dirt
setblock ~171 ~121 ~90 dirt
setblock ~171 ~121 ~91 dirt
setblock ~171 ~121 ~92 dirt
setblock ~171 ~121 ~94 dirt
setblock ~171 ~122 ~71 dirt
setblock ~171 ~122 ~72 dirt
setblock ~171 ~122 ~73 dirt
setblock ~171 ~122 ~74 dirt
setblock ~171 ~122 ~75 dirt
setblock ~171 ~122 ~76 dirt
setblock ~171 ~122 ~77 dirt
setblock ~171 ~122 ~78 dirt
setblock ~171 ~122 ~79 dirt
setblock ~171 ~122 ~80 dirt
setblock ~171 ~122 ~81 dirt
setblock ~171 ~122 ~82 dirt
setblock ~171 ~122 ~83 dirt
setblock ~171 ~122 ~84 dirt
setblock ~171 ~122 ~85 dirt
setblock ~171 ~122 ~86 dirt
setblock ~171 ~122 ~87 dirt
setblock ~171 ~122 ~88 dirt
setblock ~171 ~122 ~89 dirt
setblock ~171 ~122 ~90 dirt
setblock ~171 ~122 ~91 dirt
setblock ~171 ~122 ~92 dirt
setblock ~171 ~122 ~94 dirt
setblock ~171 ~123 ~71 grass_block
setblock ~171 ~123 ~72 grass_block
setblock ~171 ~123 ~73 dirt
setblock ~171 ~123 ~74 dirt
setblock ~171 ~123 ~75 dirt
setblock ~171 ~123 ~76 dirt
setblock ~171 ~123 ~77 dirt
setblock ~171 ~123 ~78 dirt
setblock ~171 ~123 ~79 dirt
setblock ~171 ~123 ~80 dirt
setblock ~171 ~123 ~81 dirt
setblock ~171 ~123 ~82 dirt
setblock ~171 ~123 ~83 dirt
setblock ~171 ~123 ~84 dirt
setblock ~171 ~123 ~85 dirt
setblock ~171 ~123 ~86 dirt
setblock ~171 ~123 ~87 dirt
setblock ~171 ~123 ~88 dirt
setblock ~171 ~123 ~89 dirt
setblock ~171 ~123 ~90 dirt
setblock ~171 ~123 ~91 dirt
setblock ~171 ~123 ~92 dirt
setblock ~171 ~123 ~94 dirt
setblock ~171 ~124 ~71 fern
setblock ~171 ~124 ~73 grass_block
setblock ~171 ~124 ~74 grass_block
setblock ~171 ~124 ~75 grass_block
setblock ~171 ~124 ~76 grass_block
setblock ~171 ~124 ~77 dirt
setblock ~171 ~124 ~78 dirt
setblock ~171 ~124 ~79 dirt
setblock ~171 ~124 ~80 dirt
setblock ~171 ~124 ~81 dirt
setblock ~171 ~124 ~82 dirt
setblock ~171 ~124 ~83 dirt
setblock ~171 ~124 ~84 dirt
setblock ~171 ~124 ~85 dirt
setblock ~171 ~124 ~86 dirt
setblock ~171 ~124 ~87 dirt
setblock ~171 ~124 ~88 dirt
setblock ~171 ~124 ~89 dirt
setblock ~171 ~124 ~90 dirt
setblock ~171 ~124 ~91 dirt
setblock ~171 ~124 ~92 dirt
setblock ~171 ~124 ~94 dirt
setblock ~171 ~125 ~76 short_grass
setblock ~171 ~125 ~77 grass_block
setblock ~171 ~125 ~78 grass_block
setblock ~171 ~125 ~79 grass_block
setblock ~171 ~125 ~80 grass_block
setblock ~171 ~125 ~81 grass_block
setblock ~171 ~125 ~82 grass_block
setblock ~171 ~125 ~83 grass_block
setblock ~171 ~125 ~84 grass_block
setblock ~171 ~125 ~85 dirt
setblock ~171 ~125 ~86 dirt
setblock ~171 ~125 ~87 dirt
setblock ~171 ~125 ~88 dirt
setblock ~171 ~125 ~89 dirt
setblock ~171 ~125 ~90 dirt
setblock ~171 ~125 ~91 dirt
setblock ~171 ~125 ~92 grass_block
setblock ~171 ~125 ~94 grass_block
setblock ~171 ~126 ~80 short_grass
setblock ~171 ~126 ~83 fern
setblock ~171 ~126 ~85 grass_block
setblock ~171 ~126 ~86 grass_block
setblock ~171 ~126 ~87 grass_block
setblock ~171 ~126 ~88 grass_block
setblock ~171 ~126 ~89 grass_block
setblock ~171 ~126 ~90 grass_block
setblock ~171 ~126 ~91 grass_block
setblock ~171 ~127 ~88 short_grass
setblock ~172 ~115 ~82 dirt
setblock ~172 ~115 ~84 dirt
setblock ~172 ~115 ~85 dirt
setblock ~172 ~116 ~80 dirt
setblock ~172 ~116 ~81 dirt
setblock ~172 ~116 ~82 dirt
setblock ~172 ~116 ~84 dirt
setblock ~172 ~116 ~85 dirt
setblock ~172 ~116 ~86 dirt
setblock ~172 ~116 ~87 dirt
setblock ~172 ~117 ~79 dirt
setblock ~172 ~117 ~80 dirt
setblock ~172 ~117 ~81 dirt
setblock ~172 ~117 ~82 dirt
setblock ~172 ~117 ~83 dirt
setblock ~172 ~117 ~84 dirt
setblock ~172 ~117 ~85 dirt
setblock ~172 ~117 ~86 dirt
setblock ~172 ~117 ~87 dirt
setblock ~172 ~117 ~88 dirt
setblock ~172 ~117 ~90 dirt
setblock ~172 ~118 ~79 dirt
setblock ~172 ~118 ~80 dirt
setblock ~172 ~118 ~81 dirt
setblock ~172 ~118 ~82 dirt
setblock ~172 ~118 ~83 dirt
setblock ~172 ~118 ~84 dirt
setblock ~172 ~118 ~85 dirt
setblock ~172 ~118 ~86 dirt
setblock ~172 ~118 ~87 dirt
setblock ~172 ~118 ~88 dirt
setblock ~172 ~118 ~89 dirt
setblock ~172 ~118 ~90 dirt
setblock ~172 ~119 ~77 dirt
setblock ~172 ~119 ~78 dirt
setblock ~172 ~119 ~79 dirt
setblock ~172 ~119 ~80 dirt
setblock ~172 ~119 ~81 dirt
setblock ~172 ~119 ~82 dirt
setblock ~172 ~119 ~83 dirt
setblock ~172 ~119 ~84 dirt
setblock ~172 ~119 ~85 dirt
setblock ~172 ~119 ~86 dirt
setblock ~172 ~119 ~87 dirt
setblock ~172 ~119 ~88 dirt
setblock ~172 ~119 ~89 dirt
setblock ~172 ~119 ~90 dirt
setblock ~172 ~120 ~73 dirt
setblock ~172 ~120 ~75 dirt
setblock ~172 ~120 ~77 dirt
setblock ~172 ~120 ~78 dirt
setblock ~172 ~120 ~79 dirt
setblock ~172 ~120 ~80 dirt
setblock ~172 ~120 ~81 dirt
setblock ~172 ~120 ~82 dirt
setblock ~172 ~120 ~83 dirt
setblock ~172 ~120 ~84 dirt
setblock ~172 ~120 ~85 dirt
setblock ~172 ~120 ~86 dirt
setblock ~172 ~120 ~87 dirt
setblock ~172 ~120 ~88 dirt
setblock ~172 ~120 ~89 dirt
setblock ~172 ~120 ~90 dirt
setblock ~172 ~120 ~91 dirt
setblock ~172 ~121 ~72 dirt
setblock ~172 ~121 ~73 dirt
setblock ~172 ~121 ~74 dirt
setblock ~172 ~121 ~75 dirt
setblock ~172 ~121 ~76 dirt
setblock ~172 ~121 ~77 dirt
setblock ~172 ~121 ~78 dirt
setblock ~172 ~121 ~79 dirt
setblock ~172 ~121 ~80 dirt
setblock ~172 ~121 ~81 dirt
setblock ~172 ~121 ~82 dirt
setblock ~172 ~121 ~83 dirt
setblock ~172 ~121 ~84 dirt
setblock ~172 ~121 ~85 dirt
setblock ~172 ~121 ~86 dirt
setblock ~172 ~121 ~87 dirt
setblock ~172 ~121 ~88 dirt
setblock ~172 ~121 ~89 dirt
setblock ~172 ~121 ~90 dirt
setblock ~172 ~121 ~91 dirt
setblock ~172 ~122 ~72 dirt
setblock ~172 ~122 ~73 dirt
setblock ~172 ~122 ~74 dirt
setblock ~172 ~122 ~75 dirt
setblock ~172 ~122 ~76 dirt
setblock ~172 ~122 ~77 dirt
setblock ~172 ~122 ~78 dirt
setblock ~172 ~122 ~79 dirt
setblock ~172 ~122 ~80 dirt
setblock ~172 ~122 ~81 dirt
setblock ~172 ~122 ~82 dirt
setblock ~172 ~122 ~83 dirt
setblock ~172 ~122 ~84 dirt
setblock ~172 ~122 ~85 dirt
setblock ~172 ~122 ~86 dirt
setblock ~172 ~122 ~87 dirt
setblock ~172 ~122 ~88 dirt
setblock ~172 ~122 ~89 dirt
setblock ~172 ~122 ~90 dirt
setblock ~172 ~122 ~91 dirt
setblock ~172 ~123 ~72 dirt
setblock ~172 ~123 ~73 dirt
setblock ~172 ~123 ~74 dirt
setblock ~172 ~123 ~75 dirt
setblock ~172 ~123 ~76 dirt
setblock ~172 ~123 ~77 dirt
setblock ~172 ~123 ~78 dirt
setblock ~172 ~123 ~79 dirt
setblock ~172 ~123 ~80 dirt
setblock ~172 ~123 ~81 dirt
setblock ~172 ~123 ~82 dirt
setblock ~172 ~123 ~83 dirt
setblock ~172 ~123 ~84 dirt
setblock ~172 ~123 ~85 dirt
setblock ~172 ~123 ~86 dirt
setblock ~172 ~123 ~87 dirt
setblock ~172 ~123 ~88 dirt
setblock ~172 ~123 ~89 dirt
setblock ~172 ~123 ~90 dirt
setblock ~172 ~123 ~91 dirt
setblock ~172 ~124 ~72 grass_block
setblock ~172 ~124 ~73 grass_block
setblock ~172 ~124 ~74 grass_block
setblock ~172 ~124 ~75 grass_block
setblock ~172 ~124 ~76 grass_block
setblock ~172 ~124 ~77 dirt
setblock ~172 ~124 ~78 dirt
setblock ~172 ~124 ~79 dirt
setblock ~172 ~124 ~80 dirt
setblock ~172 ~124 ~81 dirt
setblock ~172 ~124 ~82 dirt
setblock ~172 ~124 ~83 dirt
setblock ~172 ~124 ~84 dirt
setblock ~172 ~124 ~85 dirt
setblock ~172 ~124 ~86 dirt
setblock ~172 ~124 ~87 dirt
setblock ~172 ~124 ~88 dirt
setblock ~172 ~124 ~89 dirt
setblock ~172 ~124 ~90 dirt
setblock ~172 ~124 ~91 dirt
setblock ~172 ~125 ~73 short_grass
setblock ~172 ~125 ~77 grass_block
setblock ~172 ~125 ~78 grass_block
setblock ~172 ~125 ~79 grass_block
setblock ~172 ~125 ~80 grass_block
setblock ~172 ~125 ~81 grass_block
setblock ~172 ~125 ~82 grass_block
setblock ~172 ~125 ~83 grass_block
setblock ~172 ~125 ~84 grass_block
setblock ~172 ~125 ~85 grass_block
setblock ~172 ~125 ~86 grass_block
setblock ~172 ~125 ~87 grass_block
setblock ~172 ~125 ~88 grass_block
setblock ~172 ~125 ~89 grass_block
setblock ~172 ~125 ~90 dirt
setblock ~172 ~125 ~91 grass_block
setblock ~172 ~126 ~80 short_grass
setblock ~172 ~126 ~84 short_grass
setblock ~172 ~126 ~86 fern
setblock ~172 ~126 ~90 grass_block
setblock ~173 ~117 ~81 dirt
setblock ~173 ~117 ~84 dirt
setblock ~173 ~118 ~81 dirt
setblock ~173 ~118 ~83 dirt
setblock ~173 ~118 ~84 dirt
setblock ~173 ~118 ~85 dirt
setblock ~173 ~118 ~86 dirt
setblock ~173 ~118 ~87 dirt
setblock ~173 ~119 ~79 dirt
setblock ~173 ~119 ~80 dirt
setblock ~173 ~119 ~81 dirt
setblock ~173 ~119 ~82 dirt
setblock ~173 ~119 ~83 dirt
setblock ~173 ~119 ~84 dirt
setblock ~173 ~119 ~85 dirt
setblock ~173 ~119 ~86 dirt
setblock ~173 ~119 ~87 dirt
setblock ~173 ~119 ~88 dirt
setblock ~173 ~119 ~89 dirt
setblock ~173 ~120 ~78 dirt
setblock ~173 ~120 ~79 dirt
setblock ~173 ~120 ~80 dirt
setblock ~173 ~120 ~81 dirt
setblock ~173 ~120 ~82 dirt
setblock ~173 ~120 ~83 dirt
setblock ~173 ~120 ~84 dirt
setblock ~173 ~120 ~85 dirt
setblock ~173 ~120 ~86 dirt
setblock ~173 ~120 ~87 dirt
setblock ~173 ~120 ~88 dirt
setblock ~173 ~120 ~89 dirt
setblock ~173 ~120 ~90 dirt
setblock ~173 ~121 ~77 dirt
setblock ~173 ~121 ~78 dirt
setblock ~173 ~121 ~79 dirt
setblock ~173 ~121 ~80 dirt
setblock ~173 ~121 ~81 dirt
setblock ~173 ~121 ~82 dirt
setblock ~173 ~121 ~83 dirt
setblock ~173 ~121 ~84 dirt
setblock ~173 ~121 ~85 dirt
setblock ~173 ~121 ~86 dirt
setblock ~173 ~121 ~87 dirt
setblock ~173 ~121 ~88 dirt
setblock ~173 ~121 ~89 dirt
setblock ~173 ~121 ~90 dirt
setblock ~173 ~122 ~77 dirt
setblock ~173 ~122 ~78 dirt
setblock ~173 ~122 ~79 dirt
setblock ~173 ~122 ~80 dirt
setblock ~173 ~122 ~81 dirt
setblock ~173 ~122 ~82 dirt
setblock ~173 ~122 ~83 dirt
setblock ~173 ~122 ~84 dirt
setblock ~173 ~122 ~85 dirt
setblock ~173 ~122 ~86 dirt
setblock ~173 ~122 ~87 dirt
setblock ~173 ~122 ~88 dirt
setblock ~173 ~122 ~89 dirt
setblock ~173 ~122 ~90 dirt
setblock ~173 ~123 ~77 dirt
setblock ~173 ~123 ~78 dirt
setblock ~173 ~123 ~79 dirt
setblock ~173 ~123 ~80 dirt
setblock ~173 ~123 ~81 dirt
setblock ~173 ~123 ~82 dirt
setblock ~173 ~123 ~83 dirt
setblock ~173 ~123 ~84 dirt
setblock ~173 ~123 ~85 dirt
setblock ~173 ~123 ~86 dirt
setblock ~173 ~123 ~87 dirt
setblock ~173 ~123 ~88 dirt
setblock ~173 ~123 ~89 dirt
setblock ~173 ~123 ~90 dirt
setblock ~173 ~124 ~77 dirt
setblock ~173 ~124 ~78 dirt
setblock ~173 ~124 ~79 dirt
setblock ~173 ~124 ~80 dirt
setblock ~173 ~124 ~81 dirt
setblock ~173 ~124 ~82 dirt
setblock ~173 ~124 ~83 dirt
setblock ~173 ~124 ~84 dirt
setblock ~173 ~124 ~85 dirt
setblock ~173 ~124 ~86 dirt
setblock ~173 ~124 ~87 dirt
setblock ~173 ~124 ~88 dirt
setblock ~173 ~124 ~89 dirt
setblock ~173 ~124 ~90 dirt
setblock ~173 ~125 ~77 grass_block
setblock ~173 ~125 ~78 grass_block
setblock ~173 ~125 ~79 grass_block
setblock ~173 ~125 ~80 grass_block
setblock ~173 ~125 ~81 grass_block
setblock ~173 ~125 ~82 grass_block
setblock ~173 ~125 ~83 grass_block
setblock ~173 ~125 ~84 grass_block
setblock ~173 ~125 ~85 grass_block
setblock ~173 ~125 ~86 grass_block
setblock ~173 ~125 ~87 grass_block
setblock ~173 ~125 ~88 grass_block
setblock ~173 ~125 ~89 grass_block
setblock ~173 ~125 ~90 grass_block
setblock ~173 ~126 ~77 fern
setblock ~173 ~126 ~81 short_grass
setblock ~173 ~126 ~83 fern
setblock ~173 ~126 ~88 poppy
setblock ~174 ~119 ~83 dirt
setblock ~174 ~119 ~84 dirt
setblock ~174 ~119 ~86 dirt
setblock ~174 ~119 ~87 dirt
setblock ~174 ~120 ~80 dirt
setblock ~174 ~120 ~82 dirt
setblock ~174 ~120 ~83 dirt
setblock ~174 ~120 ~84 dirt
setblock ~174 ~120 ~85 dirt
setblock ~174 ~120 ~86 dirt
setblock ~174 ~120 ~87 dirt
setblock ~174 ~120 ~88 dirt
setblock ~174 ~121 ~79 dirt
setblock ~174 ~121 ~80 dirt
setblock ~174 ~121 ~81 dirt
setblock ~174 ~121 ~82 dirt
setblock ~174 ~121 ~83 dirt
setblock ~174 ~121 ~84 dirt
setblock ~174 ~121 ~85 dirt
setblock ~174 ~121 ~86 dirt
setblock ~174 ~121 ~87 dirt
setblock ~174 ~121 ~88 dirt
setblock ~174 ~121 ~89 dirt
setblock ~174 ~122 ~79 dirt
setblock ~174 ~122 ~80 dirt
setblock ~174 ~122 ~81 dirt
setblock ~174 ~122 ~82 dirt
setblock ~174 ~122 ~83 dirt
setblock ~174 ~122 ~84 dirt
setblock ~174 ~122 ~85 dirt
setblock ~174 ~122 ~86 dirt
setblock ~174 ~122 ~87 dirt
setblock ~174 ~122 ~88 dirt
setblock ~174 ~122 ~89 dirt
setblock ~174 ~123 ~79 dirt
setblock ~174 ~123 ~80 dirt
setblock ~174 ~123 ~81 dirt
setblock ~174 ~123 ~82 dirt
setblock ~174 ~123 ~83 dirt
setblock ~174 ~123 ~84 dirt
setblock ~174 ~123 ~85 dirt
setblock ~174 ~123 ~86 dirt
setblock ~174 ~123 ~87 dirt
setblock ~174 ~123 ~88 dirt
setblock ~174 ~123 ~89 dirt
setblock ~174 ~124 ~79 dirt
setblock ~174 ~124 ~80 dirt
setblock ~174 ~124 ~81 dirt
setblock ~174 ~124 ~82 dirt
setblock ~174 ~124 ~83 dirt
setblock ~174 ~124 ~84 dirt
setblock ~174 ~124 ~85 dirt
setblock ~174 ~124 ~86 dirt
setblock ~174 ~124 ~87 dirt
setblock ~174 ~124 ~88 dirt
setblock ~174 ~124 ~89 dirt
setblock ~174 ~125 ~79 grass_block
setblock ~174 ~125 ~80 grass_block
setblock ~174 ~125 ~81 grass_block
setblock ~174 ~125 ~82 grass_block
setblock ~174 ~125 ~83 grass_block
setblock ~174 ~125 ~84 grass_block
setblock ~174 ~125 ~85 grass_block
setblock ~174 ~125 ~86 grass_block
setblock ~174 ~125 ~87 grass_block
setblock ~174 ~125 ~88 grass_block
setblock ~174 ~125 ~89 grass_block
setblock ~174 ~126 ~79 short_grass
setblock ~174 ~126 ~82 short_grass
setblock ~175 ~120 ~87 dirt
setblock ~175 ~121 ~84 dirt
setblock ~175 ~121 ~86 dirt
setblock ~175 ~121 ~87 dirt
setblock ~175 ~121 ~88 dirt
setblock ~175 ~122 ~84 dirt
setblock ~175 ~122 ~86 dirt
setblock ~175 ~122 ~87 dirt
setblock ~175 ~122 ~88 dirt
setblock ~175 ~123 ~84 dirt
setblock ~175 ~123 ~86 dirt
setblock ~175 ~123 ~87 dirt
setblock ~175 ~123 ~88 dirt
setblock ~175 ~124 ~84 grass_block
setblock ~175 ~124 ~86 grass_block
setblock ~175 ~124 ~87 grass_block
setblock ~175 ~124 ~88 grass_block
setblock ~199 ~200 ~199 gold_block
