setblock ~35 ~120 ~62 dirt
setblock ~35 ~120 ~63 dirt
setblock ~35 ~120 ~64 dirt
setblock ~35 ~120 ~65 dirt
setblock ~35 ~120 ~66 dirt
setblock ~35 ~120 ~67 dirt
setblock ~35 ~120 ~68 dirt
setblock ~35 ~120 ~69 dirt
setblock ~35 ~120 ~70 dirt
setblock ~35 ~120 ~71 dirt
setblock ~35 ~120 ~72 dirt
setblock ~35 ~120 ~73 dirt
setblock ~35 ~120 ~74 dirt
setblock ~35 ~120 ~75 dirt
setblock ~35 ~120 ~76 dirt
setblock ~35 ~120 ~77 dirt
setblock ~35 ~120 ~78 dirt
setblock ~35 ~120 ~79 dirt
setblock ~35 ~120 ~80 dirt
setblock ~35 ~120 ~81 dirt
setblock ~35 ~120 ~82 dirt
setblock ~35 ~120 ~83 dirt
setblock ~35 ~120 ~84 dirt
setblock ~35 ~120 ~85 dirt
setblock ~35 ~120 ~96 dirt
setblock ~35 ~120 ~97 dirt
setblock ~35 ~120 ~98 dirt
setblock ~35 ~120 ~99 dirt
setblock ~35 ~120 ~100 dirt
setblock ~35 ~120 ~101 dirt
setblock ~35 ~120 ~102 dirt
setblock ~35 ~120 ~103 dirt
setblock ~35 ~120 ~104 dirt
setblock ~35 ~120 ~119 dirt
setblock ~35 ~120 ~120 dirt
setblock ~35 ~120 ~121 dirt
setblock ~35 ~120 ~122 dirt
setblock ~35 ~120 ~123 dirt
setblock ~35 ~120 ~124 dirt
setblock ~35 ~120 ~125 dirt
setblock ~35 ~121 ~59 dirt
setblock ~35 ~121 ~60 dirt
setblock ~35 ~121 ~61 dirt
setblock ~35 ~121 ~62 dirt
setblock ~35 ~121 ~63 dirt
setblock ~35 ~121 ~64 dirt
setblock ~35 ~121 ~65 dirt
setblock ~35 ~121 ~66 dirt
setblock ~35 ~121 ~67 dirt
setblock ~35 ~121 ~68 dirt
setblock ~35 ~121 ~69 dirt
setblock ~35 ~121 ~70 dirt
setblock ~35 ~121 ~71 dirt
setblock ~35 ~121 ~72 dirt
setblock ~35 ~121 ~73 dirt
setblock ~35 ~121 ~74 dirt
setblock ~35 ~121 ~75 dirt
setblock ~35 ~121 ~76 dirt
setblock ~35 ~121 ~77 dirt
setblock ~35 ~121 ~78 dirt
setblock ~35 ~121 ~79 dirt
setblock ~35 ~121 ~80 dirt
setblock ~35 ~121 ~81 dirt
setblock ~35 ~121 ~82 dirt
setblock ~35 ~121 ~83 dirt
setblock ~35 ~121 ~84 dirt
setblock ~35 ~121 ~85 dirt
setblock ~35 ~121 ~86 dirt
setblock ~35 ~121 ~88 dirt
setblock ~35 ~121 ~94 dirt
setblock ~35 ~121 ~95 dirt
setblock ~35 ~121 ~96 dirt
setblock ~35 ~121 ~97 dirt
setblock ~35 ~121 ~98 dirt
setblock ~35 ~121 ~99 dirt
setblock ~35 ~121 ~100 dirt
setblock ~35 ~121 ~101 dirt
setblock ~35 ~121 ~102 dirt
setblock ~35 ~121 ~103 dirt
setblock ~35 ~121 ~104 dirt
setblock ~35 ~121 ~105 dirt
setblock ~35 ~121 ~119 dirt
setblock ~35 ~121 ~120 dirt
setblock ~35 ~121 ~121 dirt
setblock ~35 ~121 ~122 dirt
setblock ~35 ~121 ~123 dirt
setblock ~35 ~121 ~124 dirt
setblock ~35 ~121 ~125 dirt
setblock ~35 ~122 ~59 dirt
setblock ~35 ~122 ~60 grass_block
setblock ~35 ~122 ~61 dirt
setblock ~35 ~122 ~62 dirt
setblock ~35 ~122 ~63 dirt
setblock ~35 ~122 ~64 dirt
setblock ~35 ~122 ~65 dirt
setblock ~35 ~122 ~66 dirt
setblock ~35 ~122 ~67 dirt
setblock ~35 ~122 ~68 dirt
setblock ~35 ~122 ~69 dirt
setblock ~35 ~122 ~70 dirt
setblock ~35 ~122 ~71 dirt
setblock ~35 ~122 ~72 dirt
setblock ~35 ~122 ~73 dirt
setblock ~35 ~122 ~74 dirt
setblock ~35 ~122 ~75 dirt
setblock ~35 ~122 ~76 dirt
setblock ~35 ~122 ~77 dirt
setblock ~35 ~122 ~78 dirt
setblock ~35 ~122 ~79 dirt
setblock ~35 ~122 ~80 dirt
setblock ~35 ~122 ~81 dirt
setblock ~35 ~122 ~82 dirt
setblock ~35 ~122 ~83 dirt
setblock ~35 ~122 ~84 dirt
setblock ~35 ~122 ~85 dirt
setblock ~35 ~122 ~86 dirt
setblock ~35 ~122 ~88 dirt
setblock ~35 ~122 ~94 dirt
setblock ~35 ~122 ~95 dirt
setblock ~35 ~122 ~96 dirt
setblock ~35 ~122 ~97 dirt
setblock ~35 ~122 ~98 dirt
setblock ~35 ~122 ~99 dirt
setblock ~35 ~122 ~100 dirt
setblock ~35 ~122 ~101 dirt
setblock ~35 ~122 ~102 dirt
setblock ~35 ~122 ~103 dirt
setblock ~35 ~122 ~104 dirt
setblock ~35 ~122 ~105 dirt
setblock ~35 ~122 ~119 dirt
setblock ~35 ~122 ~120 dirt
setblock ~35 ~122 ~121 dirt
setblock ~35 ~122 ~122 dirt
setblock ~35 ~122 ~123 dirt
setblock ~35 ~122 ~124 dirt
setblock ~35 ~122 ~125 dirt
setblock ~35 ~123 ~59 grass_block
setblock ~35 ~123 ~60 short_grass
setblock ~35 ~123 ~61 grass_block
setblock ~35 ~123 ~62 grass_block
setblock ~35 ~123 ~63 dirt
setblock ~35 ~123 ~64 dirt
setblock ~35 ~123 ~65 dirt
setblock ~35 ~123 ~66 dirt
setblock ~35 ~123 ~67 dirt
setblock ~35 ~123 ~68 dirt
setblock ~35 ~123 ~69 dirt
setblock ~35 ~123 ~70 dirt
setblock ~35 ~123 ~71 dirt
setblock ~35 ~123 ~72 dirt
setblock ~35 ~123 ~73 dirt
setblock ~35 ~123 ~74 dirt
setblock ~35 ~123 ~75 dirt
setblock ~35 ~123 ~76 dirt
setblock ~35 ~123 ~77 dirt
setblock ~35 ~123 ~78 dirt
setblock ~35 ~123 ~79 dirt
setblock ~35 ~123 ~80 dirt
setblock ~35 ~123 ~81 dirt
setblock ~35 ~123 ~82 dirt
setblock ~35 ~123 ~83 dirt
setblock ~35 ~123 ~84 dirt
setblock ~35 ~123 ~85 dirt
setblock ~35 ~123 ~86 dirt
setblock ~35 ~123 ~88 dirt
setblock ~35 ~123 ~94 dirt
setblock ~35 ~123 ~95 dirt
setblock ~35 ~123 ~96 dirt
setblock ~35 ~123 ~97 dirt
setblock ~35 ~123 ~98 dirt
setblock ~35 ~123 ~99 dirt
setblock ~35 ~123 ~100 dirt
setblock ~35 ~123 ~101 dirt
setblock ~35 ~123 ~102 dirt
setblock ~35 ~123 ~103 dirt
setblock ~35 ~123 ~104 dirt
setblock ~35 ~123 ~105 dirt
setblock ~35 ~123 ~119 dirt
setblock ~35 ~123 ~120 dirt
setblock ~35 ~123 ~121 dirt
setblock ~35 ~123 ~122 dirt
setblock ~35 ~123 ~123 dirt
setblock ~35 ~123 ~124 dirt
setblock ~35 ~123 ~125 dirt
setblock ~35 ~124 ~63 grass_block
setblock ~35 ~124 ~64 grass_block
setblock ~35 ~124 ~65 grass_block
setblock ~35 ~124 ~66 dirt
setblock ~35 ~124 ~67 dirt
setblock ~35 ~124 ~68 dirt
setblock ~35 ~124 ~69 dirt
setblock ~35 ~124 ~70 dirt
setblock ~35 ~124 ~71 dirt
setblock ~35 ~124 ~72 dirt
setblock ~35 ~124 ~73 dirt
setblock ~35 ~124 ~74 dirt
setblock ~35 ~124 ~75 dirt
setblock ~35 ~124 ~76 dirt
setblock ~35 ~124 ~77 dirt
setblock ~35 ~124 ~78 dirt
setblock ~35 ~124 ~79 dirt
setblock ~35 ~124 ~80 dirt
setblock ~35 ~124 ~81 dirt
setblock ~35 ~124 ~82 dirt
setblock ~35 ~124 ~83 dirt
setblock ~35 ~124 ~84 dirt
setblock ~35 ~124 ~85 dirt
setblock ~35 ~124 ~86 dirt
setblock ~35 ~124 ~88 dirt
setblock ~35 ~124 ~94 grass_block
setblock ~35 ~124 ~95 grass_block
setblock ~35 ~124 ~96 grass_block
setblock ~35 ~124 ~97 grass_block
setblock ~35 ~124 ~98 grass_block
setblock ~35 ~124 ~99 grass_block
setblock ~35 ~124 ~100 grass_block
setblock ~35 ~124 ~101 dirt
setblock ~35 ~124 ~102 dirt
setblock ~35 ~124 ~103 dirt
setblock ~35 ~124 ~104 dirt
setblock ~35 ~124 ~105 dirt
setblock ~35 ~124 ~119 grass_block
setblock ~35 ~124 ~120 grass_block
setblock ~35 ~124 ~121 grass_block
setblock ~35 ~124 ~122 grass_block
setblock ~35 ~124 ~123 grass_block
setblock ~35 ~124 ~124 grass_block
setblock ~35 ~124 ~125 grass_block
setblock ~35 ~125 ~63 short_grass
setblock ~35 ~125 ~66 grass_block
setblock ~35 ~125 ~67 grass_block
setblock ~35 ~125 ~68 dirt
setblock ~35 ~125 ~69 dirt
setblock ~35 ~125 ~70 dirt
setblock ~35 ~125 ~71 dirt
setblock ~35 ~125 ~72 dirt
setblock ~35 ~125 ~73 dirt
setblock ~35 ~125 ~74 dirt
setblock ~35 ~125 ~75 dirt
setblock ~35 ~125 ~76 dirt
setblock ~35 ~125 ~77 dirt
setblock ~35 ~125 ~78 dirt
setblock ~35 ~125 ~79 dirt
setblock ~35 ~125 ~80 dirt
setblock ~35 ~125 ~81 dirt
setblock ~35 ~125 ~82 grass_block
setblock ~35 ~125 ~83 grass_block
setblock ~35 ~125 ~84 grass_block
setblock ~35 ~125 ~85 grass_block
setblock ~35 ~125 ~86 grass_block
setblock ~35 ~125 ~88 grass_block
setblock ~35 ~125 ~95 short_grass
setblock ~35 ~125 ~97 short_grass
setblock ~35 ~125 ~99 fern
setblock ~35 ~125 ~100 fern
setblock ~35 ~125 ~101 grass_block
setblock ~35 ~125 ~102 grass_block
setblock ~35 ~125 ~103 grass_block
setblock ~35 ~125 ~104 grass_block
setblock ~35 ~125 ~105 dirt
setblock ~35 ~125 ~119 short_grass
setblock ~35 ~125 ~123 fern
setblock ~35 ~125 ~124 short_grass
setblock ~35 ~126 ~68 grass_block
setblock ~35 ~126 ~69 grass_block
setblock ~35 ~126 ~70 dirt
setblock ~35 ~126 ~71 dirt
setblock ~35 ~126 ~72 grass_block
setblock ~35 ~126 ~73 grass_block
setblock ~35 ~126 ~74 grass_block
setblock ~35 ~126 ~75 grass_block
setblock ~35 ~126 ~76 grass_block
setblock ~35 ~126 ~77 grass_block
setblock ~35 ~126 ~78 grass_block
setblock ~35 ~126 ~79 grass_block
setblock ~35 ~126 ~80 grass_block
setblock ~35 ~126 ~81 grass_block
setblock ~35 ~126 ~84 short_grass
setblock ~35 ~126 ~88 short_grass
setblock ~35 ~126 ~101 short_grass
setblock ~35 ~126 ~102 fern
setblock ~35 ~126 ~104 fern
setblock ~35 ~126 ~105 grass_block
setblock ~35 ~127 ~70 grass_block
setblock ~35 ~127 ~71 grass_block
setblock ~35 ~127 ~80 short_grass
setblock ~35 ~127 ~81 short_grass
setblock ~35 ~128 ~71 fern
setblock ~35 ~129 ~66 jungle_leaves[persistent=null]
setblock ~35 ~129 ~67 oak_leaves[persistent=null]
setblock ~35 ~129 ~68 oak_leaves[persistent=null]
setblock ~35 ~130 ~66 oak_leaves[persistent=null]
setblock ~35 ~130 ~67 jungle_leaves[persistent=null]
setblock ~35 ~130 ~68 oak_leaves[persistent=null]
setblock ~35 ~131 ~65 oak_leaves[persistent=null]
setblock ~35 ~131 ~66 oak_leaves[persistent=null]
setblock ~35 ~131 ~67 oak_leaves[persistent=null]
setblock ~35 ~131 ~68 oak_leaves[persistent=null]
setblock ~35 ~131 ~69 oak_leaves[persistent=null]
setblock ~35 ~131 ~70 oak_leaves[persistent=null]
setblock ~35 ~132 ~67 oak_leaves[persistent=null]
setblock ~35 ~132 ~68 jungle_leaves[persistent=null]
setblock ~35 ~132 ~69 oak_leaves[persistent=null]
setblock ~35 ~132 ~70 jungle_leaves[persistent=null]
setblock ~35 ~132 ~73 oak_leaves[persistent=null]
setblock ~35 ~132 ~75 oak_leaves[persistent=null]
setblock ~35 ~132 ~76 oak_leaves[persistent=null]
setblock ~35 ~133 ~64 oak_leaves[persistent=null]
setblock ~35 ~133 ~65 oak_leaves[persistent=null]
setblock ~35 ~133 ~66 oak_leaves[persistent=null]
setblock ~35 ~133 ~67 oak_leaves[persistent=null]
setblock ~35 ~133 ~69 oak_leaves[persistent=null]
setblock ~35 ~133 ~70 oak_leaves[persistent=null]
setblock ~35 ~133 ~74 oak_leaves[persistent=null]
setblock ~35 ~133 ~75 oak_leaves[persistent=null]
setblock ~35 ~133 ~76 oak_leaves[persistent=null]
setblock ~35 ~134 ~64 jungle_leaves[persistent=null]
setblock ~35 ~134 ~65 oak_leaves[persistent=null]
setblock ~35 ~134 ~66 oak_leaves[persistent=null]
setblock ~35 ~134 ~68 oak_leaves[persistent=null]
setblock ~35 ~134 ~70 jungle_leaves[persistent=null]
setblock ~35 ~134 ~73 oak_leaves[persistent=null]
setblock ~35 ~134 ~75 oak_wood
setblock ~35 ~135 ~64 oak_leaves[persistent=null]
setblock ~35 ~135 ~65 oak_leaves[persistent=null]
setblock ~35 ~135 ~66 oak_wood
setblock ~35 ~135 ~67 jungle_leaves[persistent=null]
setblock ~35 ~135 ~74 oak_leaves[persistent=null]
setblock ~35 ~135 ~75 jungle_leaves[persistent=null]
setblock ~35 ~135 ~76 oak_leaves[persistent=null]
setblock ~35 ~136 ~64 oak_leaves[persistent=null]
setblock ~35 ~136 ~65 oak_leaves[persistent=null]
setblock ~35 ~136 ~66 oak_leaves[persistent=null]
setblock ~35 ~136 ~67 oak_leaves[persistent=null]
setblock ~35 ~138 ~76 oak_leaves[persistent=null]
setblock ~35 ~139 ~70 oak_leaves[persistent=null]
setblock ~35 ~139 ~71 oak_leaves[persistent=null]
setblock ~35 ~139 ~73 oak_leaves[persistent=null]
setblock ~35 ~139 ~74 oak_leaves[persistent=null]
setblock ~35 ~139 ~75 oak_leaves[persistent=null]
setblock ~35 ~139 ~77 oak_leaves[persistent=null]
setblock ~35 ~140 ~68 oak_leaves[persistent=null]
setblock ~35 ~140 ~70 oak_leaves[persistent=null]
setblock ~35 ~140 ~72 oak_leaves[persistent=null]
setblock ~35 ~140 ~73 jungle_leaves[persistent=null]
setblock ~35 ~140 ~74 jungle_leaves[persistent=null]
setblock ~35 ~140 ~75 oak_leaves[persistent=null]
setblock ~35 ~140 ~76 oak_leaves[persistent=null]
setblock ~35 ~140 ~77 jungle_leaves[persistent=null]
setblock ~35 ~141 ~69 oak_leaves[persistent=null]
setblock ~35 ~141 ~70 oak_leaves[persistent=null]
setblock ~35 ~141 ~71 oak_wood
setblock ~35 ~141 ~72 oak_leaves[persistent=null]
setblock ~35 ~141 ~73 oak_leaves[persistent=null]
setblock ~35 ~141 ~74 oak_leaves[persistent=null]
setblock ~35 ~141 ~75 jungle_leaves[persistent=null]
setblock ~35 ~141 ~76 oak_leaves[persistent=null]
setblock ~35 ~142 ~68 oak_leaves[persistent=null]
setblock ~35 ~142 ~69 oak_leaves[persistent=null]
setblock ~35 ~142 ~70 jungle_leaves[persistent=null]
setblock ~35 ~142 ~71 oak_leaves[persistent=null]
setblock ~35 ~142 ~72 oak_leaves[persistent=null]
setblock ~35 ~142 ~74 oak_leaves[persistent=null]
setblock ~35 ~142 ~75 jungle_leaves[persistent=null]
setblock ~35 ~142 ~76 oak_leaves[persistent=null]
setblock ~35 ~142 ~77 jungle_leaves[persistent=null]
setblock ~35 ~143 ~68 oak_leaves[persistent=null]
setblock ~35 ~143 ~69 jungle_leaves[persistent=null]
setblock ~35 ~143 ~70 oak_leaves[persistent=null]
setblock ~35 ~143 ~71 oak_leaves[persistent=null]
setblock ~36 ~106 ~72 dirt
setblock ~36 ~107 ~72 dirt
setblock ~36 ~107 ~77 dirt
setblock ~36 ~108 ~72 dirt
setblock ~36 ~108 ~74 dirt
setblock ~36 ~108 ~75 dirt
setblock ~36 ~108 ~76 dirt
setblock ~36 ~108 ~77 dirt
setblock ~36 ~109 ~68 dirt
setblock ~36 ~109 ~70 dirt
setblock ~36 ~109 ~71 dirt
setblock ~36 ~109 ~72 dirt
setblock ~36 ~109 ~73 dirt
setblock ~36 ~109 ~74 dirt
setblock ~36 ~109 ~75 dirt
setblock ~36 ~109 ~76 dirt
setblock ~36 ~109 ~77 dirt
setblock ~36 ~109 ~78 dirt
setblock ~36 ~110 ~67 dirt
setblock ~36 ~110 ~68 dirt
setblock ~36 ~110 ~69 dirt
setblock ~36 ~110 ~70 dirt
setblock ~36 ~110 ~71 dirt
setblock ~36 ~110 ~72 dirt
setblock ~36 ~110 ~73 dirt
setblock ~36 ~110 ~74 dirt
setblock ~36 ~110 ~75 dirt
setblock ~36 ~110 ~76 dirt
setblock ~36 ~110 ~77 dirt
setblock ~36 ~110 ~78 dirt
setblock ~36 ~110 ~79 dirt
setblock ~36 ~111 ~66 dirt
setblock ~36 ~111 ~67 dirt
setblock ~36 ~111 ~68 dirt
setblock ~36 ~111 ~69 dirt
setblock ~36 ~111 ~70 dirt
setblock ~36 ~111 ~71 dirt
setblock ~36 ~111 ~72 dirt
setblock ~36 ~111 ~73 dirt
setblock ~36 ~111 ~74 dirt
setblock ~36 ~111 ~75 dirt
setblock ~36 ~111 ~76 dirt
setblock ~36 ~111 ~77 dirt
setblock ~36 ~111 ~78 dirt
setblock ~36 ~111 ~79 dirt
setblock ~36 ~111 ~80 dirt
setblock ~36 ~112 ~66 dirt
setblock ~36 ~112 ~67 dirt
setblock ~36 ~112 ~68 dirt
setblock ~36 ~112 ~69 dirt
setblock ~36 ~112 ~70 dirt
setblock ~36 ~112 ~71 dirt
setblock ~36 ~112 ~72 dirt
setblock ~36 ~112 ~73 dirt
setblock ~36 ~112 ~74 dirt
setblock ~36 ~112 ~75 dirt
setblock ~36 ~112 ~76 dirt
setblock ~36 ~112 ~77 dirt
setblock ~36 ~112 ~78 dirt
setblock ~36 ~112 ~79 dirt
setblock ~36 ~112 ~80 dirt
setblock ~36 ~113 ~65 dirt
setblock ~36 ~113 ~66 dirt
setblock ~36 ~113 ~67 dirt
setblock ~36 ~113 ~68 dirt
setblock ~36 ~113 ~69 dirt
setblock ~36 ~113 ~70 dirt
setblock ~36 ~113 ~71 dirt
setblock ~36 ~113 ~72 dirt
setblock ~36 ~113 ~73 dirt
setblock ~36 ~113 ~74 dirt
setblock ~36 ~113 ~75 dirt
setblock ~36 ~113 ~76 dirt
setblock ~36 ~113 ~77 dirt
setblock ~36 ~113 ~78 dirt
setblock ~36 ~113 ~79 dirt
setblock ~36 ~113 ~80 dirt
setblock ~36 ~113 ~81 dirt
setblock ~36 ~113 ~98 dirt
setblock ~36 ~113 ~101 dirt
setblock ~36 ~114 ~63 dirt
setblock ~36 ~114 ~65 dirt
setblock ~36 ~114 ~66 dirt
setblock ~36 ~114 ~67 dirt
setblock ~36 ~114 ~68 dirt
setblock ~36 ~114 ~69 dirt
setblock ~36 ~114 ~70 dirt
setblock ~36 ~114 ~71 dirt
setblock ~36 ~114 ~72 dirt
setblock ~36 ~114 ~73 dirt
setblock ~36 ~114 ~74 dirt
setblock ~36 ~114 ~75 dirt
setblock ~36 ~114 ~76 dirt
setblock ~36 ~114 ~77 dirt
setblock ~36 ~114 ~78 dirt
setblock ~36 ~114 ~79 dirt
setblock ~36 ~114 ~80 dirt
setblock ~36 ~114 ~81 dirt
setblock ~36 ~114 ~97 dirt
setblock ~36 ~114 ~98 dirt
setblock ~36 ~114 ~99 dirt
setblock ~36 ~114 ~101 dirt
setblock ~36 ~115 ~62 dirt
setblock ~36 ~115 ~63 dirt
setblock ~36 ~115 ~64 dirt
setblock ~36 ~115 ~65 dirt
setblock ~36 ~115 ~66 dirt
setblock ~36 ~115 ~67 dirt
setblock ~36 ~115 ~68 dirt
setblock ~36 ~115 ~69 dirt
setblock ~36 ~115 ~70 dirt
setblock ~36 ~115 ~71 dirt
setblock ~36 ~115 ~72 dirt
setblock ~36 ~115 ~73 dirt
setblock ~36 ~115 ~74 dirt
setblock ~36 ~115 ~75 dirt
setblock ~36 ~115 ~76 dirt
setblock ~36 ~115 ~77 dirt
setblock ~36 ~115 ~78 dirt
setblock ~36 ~115 ~79 dirt
setblock ~36 ~115 ~80 dirt
setblock ~36 ~115 ~81 dirt
setblock ~36 ~115 ~82 dirt
setblock ~36 ~115 ~96 dirt
setblock ~36 ~115 ~97 dirt
setblock ~36 ~115 ~98 dirt
setblock ~36 ~115 ~99 dirt
setblock ~36 ~115 ~100 dirt
setblock ~36 ~115 ~101 dirt
setblock ~36 ~115 ~102 dirt
setblock ~36 ~115 ~123 dirt
setblock ~36 ~115 ~124 dirt
setblock ~36 ~116 ~61 dirt
setblock ~36 ~116 ~62 dirt
setblock ~36 ~116 ~63 dirt
setblock ~36 ~116 ~64 dirt
setblock ~36 ~116 ~65 dirt
setblock ~36 ~116 ~66 dirt
setblock ~36 ~116 ~67 dirt
setblock ~36 ~116 ~68 dirt
setblock ~36 ~116 ~69 dirt
setblock ~36 ~116 ~70 dirt
setblock ~36 ~116 ~71 dirt
setblock ~36 ~116 ~72 dirt
setblock ~36 ~116 ~73 dirt
setblock ~36 ~116 ~74 dirt
setblock ~36 ~116 ~75 dirt
setblock ~36 ~116 ~76 dirt
setblock ~36 ~116 ~77 dirt
setblock ~36 ~116 ~78 dirt
setblock ~36 ~116 ~79 dirt
setblock ~36 ~116 ~80 dirt
setblock ~36 ~116 ~81 dirt
setblock ~36 ~116 ~82 dirt
setblock ~36 ~116 ~96 dirt
setblock ~36 ~116 ~97 dirt
setblock ~36 ~116 ~98 dirt
setblock ~36 ~116 ~99 dirt
setblock ~36 ~116 ~100 dirt
setblock ~36 ~116 ~101 dirt
setblock ~36 ~116 ~102 dirt
setblock ~36 ~116 ~103 dirt
setblock ~36 ~116 ~121 dirt
setblock ~36 ~116 ~123 dirt
setblock ~36 ~116 ~124 dirt
setblock ~36 ~117 ~60 dirt
setblock ~36 ~117 ~61 dirt
setblock ~36 ~117 ~62 dirt
setblock ~36 ~117 ~63 dirt
setblock ~36 ~117 ~64 dirt
setblock ~36 ~117 ~65 dirt
setblock ~36 ~117 ~66 dirt
setblock ~36 ~117 ~67 dirt
setblock ~36 ~117 ~68 dirt
setblock ~36 ~117 ~69 dirt
setblock ~36 ~117 ~70 dirt
setblock ~36 ~117 ~71 dirt
setblock ~36 ~117 ~72 dirt
setblock ~36 ~117 ~73 dirt
setblock ~36 ~117 ~74 dirt
setblock ~36 ~117 ~75 dirt
setblock ~36 ~117 ~76 dirt
setblock ~36 ~117 ~77 dirt
setblock ~36 ~117 ~78 dirt
setblock ~36 ~117 ~79 dirt
setblock ~36 ~117 ~80 dirt
setblock ~36 ~117 ~81 dirt
setblock ~36 ~117 ~82 dirt
setblock ~36 ~117 ~83 dirt
setblock ~36 ~117 ~95 dirt
setblock ~36 ~117 ~96 dirt
setblock ~36 ~117 ~97 dirt
setblock ~36 ~117 ~98 dirt
setblock ~36 ~117 ~99 dirt
setblock ~36 ~117 ~100 dirt
setblock ~36 ~117 ~101 dirt
setblock ~36 ~117 ~102 dirt
setblock ~36 ~117 ~103 dirt
setblock ~36 ~117 ~104 dirt
setblock ~36 ~117 ~120 dirt
setblock ~36 ~117 ~121 dirt
setblock ~36 ~117 ~123 dirt
setblock ~36 ~117 ~124 dirt
setblock ~36 ~117 ~125 dirt
setblock ~36 ~118 ~60 dirt
setblock ~36 ~118 ~61 dirt
setblock ~36 ~118 ~62 dirt
setblock ~36 ~118 ~63 dirt
setblock ~36 ~118 ~64 dirt
setblock ~36 ~118 ~65 dirt
setblock ~36 ~118 ~66 dirt
setblock ~36 ~118 ~67 dirt
setblock ~36 ~118 ~68 dirt
setblock ~36 ~118 ~69 dirt
setblock ~36 ~118 ~70 dirt
setblock ~36 ~118 ~71 dirt
setblock ~36 ~118 ~72 dirt
setblock ~36 ~118 ~73 dirt
setblock ~36 ~118 ~74 dirt
setblock ~36 ~118 ~75 dirt
setblock ~36 ~118 ~76 dirt
setblock ~36 ~118 ~77 dirt
setblock ~36 ~118 ~78 dirt
setblock ~36 ~118 ~79 dirt
setblock ~36 ~118 ~80 dirt
setblock ~36 ~118 ~81 dirt
setblock ~36 ~118 ~82 dirt
setblock ~36 ~118 ~83 dirt
setblock ~36 ~118 ~84 dirt
setblock ~36 ~118 ~94 dirt
setblock ~36 ~118 ~95 dirt
setblock ~36 ~118 ~96 dirt
setblock ~36 ~118 ~97 dirt
setblock ~36 ~118 ~98 dirt
setblock ~36 ~118 ~99 dirt
setblock ~36 ~118 ~100 dirt
setblock ~36 ~118 ~101 dirt
setblock ~36 ~118 ~102 dirt
setblock ~36 ~118 ~103 dirt
setblock ~36 ~118 ~104 dirt
setblock ~36 ~118 ~120 dirt
setblock ~36 ~118 ~121 dirt
setblock ~36 ~118 ~122 dirt
setblock ~36 ~118 ~123 dirt
setblock ~36 ~118 ~124 dirt
setblock ~36 ~118 ~125 dirt
setblock ~36 ~119 ~59 dirt
setblock ~36 ~119 ~60 dirt
setblock ~36 ~119 ~61 dirt
setblock ~36 ~119 ~62 dirt
setblock ~36 ~119 ~63 dirt
setblock ~36 ~119 ~64 dirt
setblock ~36 ~119 ~65 dirt
setblock ~36 ~119 ~66 dirt
setblock ~36 ~119 ~67 dirt
setblock ~36 ~119 ~68 dirt
setblock ~36 ~119 ~69 dirt
setblock ~36 ~119 ~70 dirt
setblock ~36 ~119 ~71 dirt
setblock ~36 ~119 ~72 dirt
setblock ~36 ~119 ~73 dirt
setblock ~36 ~119 ~74 dirt
setblock ~36 ~119 ~75 dirt
setblock ~36 ~119 ~76 dirt
setblock ~36 ~119 ~77 dirt
setblock ~36 ~119 ~78 dirt
setblock ~36 ~119 ~79 dirt
setblock ~36 ~119 ~80 dirt
setblock ~36 ~119 ~81 dirt
setblock ~36 ~119 ~82 dirt
setblock ~36 ~119 ~83 dirt
setblock ~36 ~119 ~84 dirt
setblock ~36 ~119 ~85 dirt
setblock ~36 ~119 ~93 dirt
setblock ~36 ~119 ~94 dirt
setblock ~36 ~119 ~95 dirt
setblock ~36 ~119 ~96 dirt
setblock ~36 ~119 ~97 dirt
setblock ~36 ~119 ~98 dirt
setblock ~36 ~119 ~99 dirt
setblock ~36 ~119 ~100 dirt
setblock ~36 ~119 ~101 dirt
setblock ~36 ~119 ~102 dirt
setblock ~36 ~119 ~103 dirt
setblock ~36 ~119 ~104 dirt
setblock ~36 ~119 ~105 dirt
setblock ~36 ~119 ~118 dirt
setblock ~36 ~119 ~119 dirt
setblock ~36 ~119 ~120 dirt
setblock ~36 ~119 ~121 dirt
setblock ~36 ~119 ~122 dirt
setblock ~36 ~119 ~123 dirt
setblock ~36 ~119 ~124 dirt
setblock ~36 ~119 ~125 dirt
setblock ~36 ~120 ~59 dirt
setblock ~36 ~120 ~60 dirt
setblock ~36 ~120 ~61 dirt
setblock ~36 ~120 ~62 dirt
setblock ~36 ~120 ~63 dirt
setblock ~36 ~120 ~64 dirt
setblock ~36 ~120 ~65 dirt
setblock ~36 ~120 ~66 dirt
setblock ~36 ~120 ~67 dirt
setblock ~36 ~120 ~68 dirt
setblock ~36 ~120 ~69 dirt
setblock ~36 ~120 ~70 dirt
setblock ~36 ~120 ~71 dirt
setblock ~36 ~120 ~72 dirt
setblock ~36 ~120 ~73 dirt
setblock ~36 ~120 ~74 dirt
setblock ~36 ~120 ~75 dirt
setblock ~36 ~120 ~76 dirt
setblock ~36 ~120 ~77 dirt
setblock ~36 ~120 ~78 dirt
setblock ~36 ~120 ~79 dirt
setblock ~36 ~120 ~80 dirt
setblock ~36 ~120 ~81 dirt
setblock ~36 ~120 ~82 dirt
setblock ~36 ~120 ~83 dirt
setblock ~36 ~120 ~84 dirt
setblock ~36 ~120 ~85 dirt
setblock ~36 ~120 ~86 dirt
setblock ~36 ~120 ~88 dirt
setblock ~36 ~120 ~93 dirt
setblock ~36 ~120 ~94 dirt
setblock ~36 ~120 ~95 dirt
setblock ~36 ~120 ~96 dirt
setblock ~36 ~120 ~97 dirt
setblock ~36 ~120 ~98 dirt
setblock ~36 ~120 ~99 dirt
setblock ~36 ~120 ~100 dirt
setblock ~36 ~120 ~101 dirt
setblock ~36 ~120 ~102 dirt
setblock ~36 ~120 ~103 dirt
setblock ~36 ~120 ~104 dirt
setblock ~36 ~120 ~105 dirt
setblock ~36 ~120 ~118 dirt
setblock ~36 ~120 ~119 dirt
setblock ~36 ~120 ~120 dirt
setblock ~36 ~120 ~121 dirt
setblock ~36 ~120 ~122 dirt
setblock ~36 ~120 ~123 dirt
setblock ~36 ~120 ~124 dirt
setblock ~36 ~120 ~125 dirt
setblock ~36 ~120 ~126 dirt
setblock ~36 ~121 ~59 dirt
setblock ~36 ~121 ~60 dirt
setblock ~36 ~121 ~61 dirt
setblock ~36 ~121 ~62 dirt
setblock ~36 ~121 ~63 dirt
setblock ~36 ~121 ~64 dirt
setblock ~36 ~121 ~65 dirt
setblock ~36 ~121 ~66 dirt
setblock ~36 ~121 ~67 dirt
setblock ~36 ~121 ~68 dirt
setblock ~36 ~121 ~69 dirt
setblock ~36 ~121 ~70 dirt
setblock ~36 ~121 ~71 dirt
setblock ~36 ~121 ~72 dirt
setblock ~36 ~121 ~73 dirt
setblock ~36 ~121 ~74 dirt
setblock ~36 ~121 ~75 dirt
setblock ~36 ~121 ~76 dirt
setblock ~36 ~121 ~77 dirt
setblock ~36 ~121 ~78 dirt
setblock ~36 ~121 ~79 dirt
setblock ~36 ~121 ~80 dirt
setblock ~36 ~121 ~81 dirt
setblock ~36 ~121 ~82 dirt
setblock ~36 ~121 ~83 dirt
setblock ~36 ~121 ~84 dirt
setblock ~36 ~121 ~85 dirt
setblock ~36 ~121 ~86 dirt
setblock ~36 ~121 ~87 dirt
setblock ~36 ~121 ~88 dirt
setblock ~36 ~121 ~89 dirt
setblock ~36 ~121 ~92 dirt
setblock ~36 ~121 ~93 dirt
setblock ~36 ~121 ~94 dirt
setblock ~36 ~121 ~95 dirt
setblock ~36 ~121 ~96 dirt
setblock ~36 ~121 ~97 dirt
setblock ~36 ~121 ~98 dirt
setblock ~36 ~121 ~99 dirt
setblock ~36 ~121 ~100 dirt
setblock ~36 ~121 ~101 dirt
setblock ~36 ~121 ~102 dirt
setblock ~36 ~121 ~103 dirt
setblock ~36 ~121 ~104 dirt
setblock ~36 ~121 ~105 dirt
setblock ~36 ~121 ~106 dirt
setblock ~36 ~121 ~116 dirt
setblock ~36 ~121 ~117 dirt
setblock ~36 ~121 ~118 dirt
setblock ~36 ~121 ~119 dirt
setblock ~36 ~121 ~120 dirt
setblock ~36 ~121 ~121 dirt
setblock ~36 ~121 ~122 dirt
setblock ~36 ~121 ~123 dirt
setblock ~36 ~121 ~124 dirt
setblock ~36 ~121 ~125 dirt
setblock ~36 ~121 ~126 dirt
setblock ~36 ~121 ~127 dirt
setblock ~36 ~122 ~59 dirt
setblock ~36 ~122 ~60 grass_block
setblock ~36 ~122 ~61 dirt
setblock ~36 ~122 ~62 dirt
setblock ~36 ~122 ~63 dirt
setblock ~36 ~122 ~64 dirt
setblock ~36 ~122 ~65 dirt
setblock ~36 ~122 ~66 dirt
setblock ~36 ~122 ~67 dirt
setblock ~36 ~122 ~68 dirt
setblock ~36 ~122 ~69 dirt
setblock ~36 ~122 ~70 dirt
setblock ~36 ~122 ~71 dirt
setblock ~36 ~122 ~72 dirt
setblock ~36 ~122 ~73 dirt
setblock ~36 ~122 ~74 dirt
setblock ~36 ~122 ~75 dirt
setblock ~36 ~122 ~76 dirt
setblock ~36 ~122 ~77 dirt
setblock ~36 ~122 ~78 dirt
setblock ~36 ~122 ~79 dirt
setblock ~36 ~122 ~80 dirt
setblock ~36 ~122 ~81 dirt
setblock ~36 ~122 ~82 dirt
setblock ~36 ~122 ~83 dirt
setblock ~36 ~122 ~84 dirt
setblock ~36 ~122 ~85 dirt
setblock ~36 ~122 ~86 dirt
setblock ~36 ~122 ~87 dirt
setblock ~36 ~122 ~88 dirt
setblock ~36 ~122 ~89 dirt
setblock ~36 ~122 ~92 dirt
setblock ~36 ~122 ~93 dirt
setblock ~36 ~122 ~94 dirt
setblock ~36 ~122 ~95 dirt
setblock ~36 ~122 ~96 dirt
setblock ~36 ~122 ~97 dirt
setblock ~36 ~122 ~98 dirt
setblock ~36 ~122 ~99 dirt
setblock ~36 ~122 ~100 dirt
setblock ~36 ~122 ~101 dirt
setblock ~36 ~122 ~102 dirt
setblock ~36 ~122 ~103 dirt
setblock ~36 ~122 ~104 dirt
setblock ~36 ~122 ~105 dirt
setblock ~36 ~122 ~106 dirt
setblock ~36 ~122 ~116 dirt
setblock ~36 ~122 ~117 dirt
setblock ~36 ~122 ~118 dirt
setblock ~36 ~122 ~119 dirt
setblock ~36 ~122 ~120 dirt
setblock ~36 ~122 ~121 dirt
setblock ~36 ~122 ~122 dirt
setblock ~36 ~122 ~123 dirt
setblock ~36 ~122 ~124 dirt
setblock ~36 ~122 ~125 dirt
setblock ~36 ~122 ~126 dirt
setblock ~36 ~122 ~127 dirt
setblock ~36 ~123 ~59 grass_block
setblock ~36 ~123 ~61 grass_block
setblock ~36 ~123 ~62 grass_block
setblock ~36 ~123 ~63 grass_block
setblock ~36 ~123 ~64 dirt
setblock ~36 ~123 ~65 dirt
setblock ~36 ~123 ~66 dirt
setblock ~36 ~123 ~67 dirt
setblock ~36 ~123 ~68 dirt
setblock ~36 ~123 ~69 dirt
setblock ~36 ~123 ~70 dirt
setblock ~36 ~123 ~71 dirt
setblock ~36 ~123 ~72 dirt
setblock ~36 ~123 ~73 dirt
setblock ~36 ~123 ~74 dirt
setblock ~36 ~123 ~75 dirt
setblock ~36 ~123 ~76 dirt
setblock ~36 ~123 ~77 dirt
setblock ~36 ~123 ~78 dirt
setblock ~36 ~123 ~79 dirt
setblock ~36 ~123 ~80 dirt
setblock ~36 ~123 ~81 dirt
setblock ~36 ~123 ~82 dirt
setblock ~36 ~123 ~83 dirt
setblock ~36 ~123 ~84 dirt
setblock ~36 ~123 ~85 dirt
setblock ~36 ~123 ~86 dirt
setblock ~36 ~123 ~87 dirt
setblock ~36 ~123 ~88 dirt
setblock ~36 ~123 ~89 dirt
setblock ~36 ~123 ~92 dirt
setblock ~36 ~123 ~93 dirt
setblock ~36 ~123 ~94 dirt
setblock ~36 ~123 ~95 dirt
setblock ~36 ~123 ~96 dirt
setblock ~36 ~123 ~97 dirt
setblock ~36 ~123 ~98 dirt
setblock ~36 ~123 ~99 dirt
setblock ~36 ~123 ~100 dirt
setblock ~36 ~123 ~101 dirt
setblock ~36 ~123 ~102 dirt
setblock ~36 ~123 ~103 dirt
setblock ~36 ~123 ~104 dirt
setblock ~36 ~123 ~105 dirt
setblock ~36 ~123 ~106 dirt
setblock ~36 ~123 ~116 dirt
setblock ~36 ~123 ~117 dirt
setblock ~36 ~123 ~118 dirt
setblock ~36 ~123 ~119 dirt
setblock ~36 ~123 ~120 dirt
setblock ~36 ~123 ~121 dirt
setblock ~36 ~123 ~122 dirt
setblock ~36 ~123 ~123 dirt
setblock ~36 ~123 ~124 dirt
setblock ~36 ~123 ~125 dirt
setblock ~36 ~123 ~126 dirt
setblock ~36 ~123 ~127 dirt
setblock ~36 ~124 ~61 short_grass
setblock ~36 ~124 ~63 short_grass
setblock ~36 ~124 ~64 grass_block
setblock ~36 ~124 ~65 grass_block
setblock ~36 ~124 ~66 dirt
setblock ~36 ~124 ~67 dirt
setblock ~36 ~124 ~68 dirt
setblock ~36 ~124 ~69 dirt
setblock ~36 ~124 ~70 dirt
setblock ~36 ~124 ~71 dirt
setblock ~36 ~124 ~72 dirt
setblock ~36 ~124 ~73 dirt
setblock ~36 ~124 ~74 dirt
setblock ~36 ~124 ~75 dirt
setblock ~36 ~124 ~76 dirt
setblock ~36 ~124 ~77 dirt
setblock ~36 ~124 ~78 dirt
setblock ~36 ~124 ~79 dirt
setblock ~36 ~124 ~80 dirt
setblock ~36 ~124 ~81 dirt
setblock ~36 ~124 ~82 dirt
setblock ~36 ~124 ~83 dirt
setblock ~36 ~124 ~84 dirt
setblock ~36 ~124 ~85 dirt
setblock ~36 ~124 ~86 dirt
setblock ~36 ~124 ~87 dirt
setblock ~36 ~124 ~88 dirt
setblock ~36 ~124 ~89 dirt
setblock ~36 ~124 ~92 dirt
setblock ~36 ~124 ~93 dirt
setblock ~36 ~124 ~94 dirt
setblock ~36 ~124 ~95 dirt
setblock ~36 ~124 ~96 dirt
setblock ~36 ~124 ~97 dirt
setblock ~36 ~124 ~98 dirt
setblock ~36 ~124 ~99 dirt
setblock ~36 ~124 ~100 dirt
setblock ~36 ~124 ~101 dirt
setblock ~36 ~124 ~102 dirt
setblock ~36 ~124 ~103 dirt
setblock ~36 ~124 ~104 dirt
setblock ~36 ~124 ~105 dirt
setblock ~36 ~124 ~106 dirt
setblock ~36 ~124 ~116 dirt
setblock ~36 ~124 ~117 dirt
setblock ~36 ~124 ~118 dirt
setblock ~36 ~124 ~119 dirt
setblock ~36 ~124 ~120 dirt
setblock ~36 ~124 ~121 dirt
setblock ~36 ~124 ~122 dirt
setblock ~36 ~124 ~123 grass_block
setblock ~36 ~124 ~124 grass_block
setblock ~36 ~124 ~125 grass_block
setblock ~36 ~124 ~126 grass_block
setblock ~36 ~124 ~127 grass_block
setblock ~36 ~125 ~65 short_grass
setblock ~36 ~125 ~66 grass_block
setblock ~36 ~125 ~67 grass_block
setblock ~36 ~125 ~68 grass_block
setblock ~36 ~125 ~69 dirt
setblock ~36 ~125 ~70 dirt
setblock ~36 ~125 ~71 dirt
setblock ~36 ~125 ~72 dirt
setblock ~36 ~125 ~73 dirt
setblock ~36 ~125 ~74 dirt
setblock ~36 ~125 ~75 dirt
setblock ~36 ~125 ~76 dirt
setblock ~36 ~125 ~77 dirt
setblock ~36 ~125 ~78 dirt
setblock ~36 ~125 ~79 dirt
setblock ~36 ~125 ~80 dirt
setblock ~36 ~125 ~81 dirt
setblock ~36 ~125 ~82 dirt
setblock ~36 ~125 ~83 dirt
setblock ~36 ~125 ~84 grass_block
setblock ~36 ~125 ~85 grass_block
setblock ~36 ~125 ~86 grass_block
setblock ~36 ~125 ~87 grass_block
setblock ~36 ~125 ~88 grass_block
setblock ~36 ~125 ~89 grass_block
setblock ~36 ~125 ~92 grass_block
setblock ~36 ~125 ~93 grass_block
setblock ~36 ~125 ~94 grass_block
setblock ~36 ~125 ~95 grass_block
setblock ~36 ~125 ~96 grass_block
setblock ~36 ~125 ~97 grass_block
setblock ~36 ~125 ~98 grass_block
setblock ~36 ~125 ~99 grass_block
setblock ~36 ~125 ~100 grass_block
setblock ~36 ~125 ~101 grass_block
setblock ~36 ~125 ~102 grass_block
setblock ~36 ~125 ~103 grass_block
setblock ~36 ~125 ~104 dirt
setblock ~36 ~125 ~105 dirt
setblock ~36 ~125 ~106 dirt
setblock ~36 ~125 ~116 dirt
setblock ~36 ~125 ~117 grass_block
setblock ~36 ~125 ~118 grass_block
setblock ~36 ~125 ~119 grass_block
setblock ~36 ~125 ~120 grass_block
setblock ~36 ~125 ~121 grass_block
setblock ~36 ~125 ~122 grass_block
setblock ~36 ~125 ~124 short_grass
setblock ~36 ~125 ~126 short_grass
setblock ~36 ~125 ~127 short_grass
setblock ~36 ~126 ~67 short_grass
setblock ~36 ~126 ~68 short_grass
setblock ~36 ~126 ~69 grass_block
setblock ~36 ~126 ~70 grass_block
setblock ~36 ~126 ~71 grass_block
setblock ~36 ~126 ~72 grass_block
setblock ~36 ~126 ~73 grass_block
setblock ~36 ~126 ~74 grass_block
setblock ~36 ~126 ~75 grass_block
setblock ~36 ~126 ~76 grass_block
setblock ~36 ~126 ~77 grass_block
setblock ~36 ~126 ~78 grass_block
setblock ~36 ~126 ~79 grass_block
setblock ~36 ~126 ~80 grass_block
setblock ~36 ~126 ~81 grass_block
setblock ~36 ~126 ~82 grass_block
setblock ~36 ~126 ~83 grass_block
setblock ~36 ~126 ~85 short_grass
setblock ~36 ~126 ~87 poppy
setblock ~36 ~126 ~104 grass_block
setblock ~36 ~126 ~105 grass_block
setblock ~36 ~126 ~106 grass_block
setblock ~36 ~126 ~116 grass_block
setblock ~36 ~126 ~119 poppy
setblock ~36 ~126 ~120 short_grass
setblock ~36 ~127 ~70 short_grass
setblock ~36 ~127 ~71 poppy
setblock ~36 ~127 ~75 short_grass
setblock ~36 ~127 ~77 short_grass
setblock ~36 ~127 ~79 short_grass
setblock ~36 ~127 ~80 poppy
setblock ~36 ~127 ~81 short_grass
setblock ~36 ~127 ~83 short_grass
setblock ~36 ~129 ~64 oak_leaves[persistent=null]
setblock ~36 ~129 ~65 oak_leaves[persistent=null]
setblock ~36 ~129 ~66 jungle_leaves[persistent=null]
setblock ~36 ~129 ~67 jungle_leaves[persistent=null]
setblock ~36 ~130 ~64 oak_leaves[persistent=null]
setblock ~36 ~130 ~65 oak_leaves[persistent=null]
setblock ~36 ~130 ~68 oak_leaves[persistent=null]
setblock ~36 ~131 ~63 jungle_leaves[persistent=null]
setblock ~36 ~131 ~65 oak_leaves[persistent=null]
setblock ~36 ~131 ~66 oak_leaves[persistent=null]
setblock ~36 ~131 ~67 oak_leaves[persistent=null]
setblock ~36 ~131 ~68 oak_leaves[persistent=null]
setblock ~36 ~131 ~70 oak_leaves[persistent=null]
setblock ~36 ~132 ~63 oak_leaves[persistent=null]
setblock ~36 ~132 ~64 jungle_leaves[persistent=null]
setblock ~36 ~132 ~65 oak_leaves[persistent=null]
setblock ~36 ~132 ~68 oak_leaves[persistent=null]
setblock ~36 ~132 ~70 jungle_leaves[persistent=null]
setblock ~36 ~132 ~74 oak_leaves[persistent=null]
setblock ~36 ~132 ~76 jungle_leaves[persistent=null]
setblock ~36 ~132 ~77 oak_leaves[persistent=null]
setblock ~36 ~133 ~64 oak_leaves[persistent=null]
setblock ~36 ~133 ~65 oak_leaves[persistent=null]
setblock ~36 ~133 ~66 oak_leaves[persistent=null]
setblock ~36 ~133 ~67 jungle_leaves[persistent=null]
setblock ~36 ~133 ~68 oak_wood
setblock ~36 ~133 ~69 oak_wood
setblock ~36 ~133 ~70 oak_leaves[persistent=null]
setblock ~36 ~133 ~73 oak_leaves[persistent=null]
setblock ~36 ~133 ~74 jungle_leaves[persistent=null]
setblock ~36 ~133 ~75 oak_leaves[persistent=null]
setblock ~36 ~133 ~76 oak_leaves[persistent=null]
setblock ~36 ~133 ~77 oak_leaves[persistent=null]
setblock ~36 ~134 ~63 oak_leaves[persistent=null]
setblock ~36 ~134 ~64 oak_leaves[persistent=null]
setblock ~36 ~134 ~66 oak_leaves[persistent=null]
setblock ~36 ~134 ~67 oak_leaves[persistent=null]
setblock ~36 ~134 ~70 oak_leaves[persistent=null]
setblock ~36 ~134 ~73 oak_leaves[persistent=null]
setblock ~36 ~134 ~74 oak_leaves[persistent=null]
setblock ~36 ~134 ~75 oak_wood
setblock ~36 ~134 ~76 oak_leaves[persistent=null]
setblock ~36 ~135 ~63 jungle_leaves[persistent=null]
setblock ~36 ~135 ~66 oak_wood
setblock ~36 ~135 ~68 oak_leaves[persistent=null]
setblock ~36 ~135 ~69 oak_leaves[persistent=null]
setblock ~36 ~135 ~74 oak_leaves[persistent=null]
setblock ~36 ~135 ~76 oak_leaves[persistent=null]
setblock ~36 ~135 ~77 oak_leaves[persistent=null]
setblock ~36 ~136 ~63 oak_leaves[persistent=null]
setblock ~36 ~136 ~64 oak_leaves[persistent=null]
setblock ~36 ~136 ~65 oak_leaves[persistent=null]
setblock ~36 ~136 ~66 oak_leaves[persistent=null]
setblock ~36 ~136 ~67 oak_leaves[persistent=null]
setblock ~36 ~139 ~69 oak_leaves[persistent=null]
setblock ~36 ~140 ~68 oak_leaves[persistent=null]
setblock ~36 ~140 ~69 oak_leaves[persistent=null]
setblock ~36 ~140 ~70 oak_leaves[persistent=null]
setblock ~36 ~140 ~71 oak_leaves[persistent=null]
setblock ~36 ~140 ~72 oak_leaves[persistent=null]
setblock ~36 ~141 ~69 oak_leaves[persistent=null]
setblock ~36 ~141 ~70 oak_leaves[persistent=null]
setblock ~36 ~141 ~71 oak_wood
setblock ~36 ~141 ~72 oak_leaves[persistent=null]
setblock ~36 ~142 ~68 jungle_leaves[persistent=null]
setblock ~36 ~142 ~69 oak_leaves[persistent=null]
setblock ~36 ~142 ~70 oak_leaves[persistent=null]
setblock ~36 ~142 ~72 jungle_leaves[persistent=null]
setblock ~36 ~143 ~68 oak_leaves[persistent=null]
setblock ~36 ~143 ~70 oak_leaves[persistent=null]
setblock ~37 ~105 ~72 dirt
setblock ~37 ~105 ~76 dirt
setblock ~37 ~106 ~71 dirt
setblock ~37 ~106 ~72 dirt
setblock ~37 ~106 ~73 dirt
setblock ~37 ~106 ~74 dirt
setblock ~37 ~106 ~75 dirt
setblock ~37 ~106 ~76 dirt
setblock ~37 ~106 ~77 dirt
setblock ~37 ~107 ~69 dirt
setblock ~37 ~107 ~70 dirt
setblock ~37 ~107 ~71 dirt
setblock ~37 ~107 ~72 dirt
setblock ~37 ~107 ~73 dirt
setblock ~37 ~107 ~74 dirt
setblock ~37 ~107 ~75 dirt
setblock ~37 ~107 ~76 dirt
setblock ~37 ~107 ~77 dirt
setblock ~37 ~107 ~78 dirt
setblock ~37 ~108 ~68 dirt
setblock ~37 ~108 ~69 dirt
setblock ~37 ~108 ~70 dirt
setblock ~37 ~108 ~71 dirt
setblock ~37 ~108 ~72 dirt
setblock ~37 ~108 ~73 dirt
setblock ~37 ~108 ~74 dirt
setblock ~37 ~108 ~75 dirt
setblock ~37 ~108 ~76 dirt
setblock ~37 ~108 ~77 dirt
setblock ~37 ~108 ~78 dirt
setblock ~37 ~109 ~67 dirt
setblock ~37 ~109 ~68 dirt
setblock ~37 ~109 ~69 dirt
setblock ~37 ~109 ~70 dirt
setblock ~37 ~109 ~71 dirt
setblock ~37 ~109 ~72 dirt
setblock ~37 ~109 ~73 dirt
setblock ~37 ~109 ~74 dirt
setblock ~37 ~109 ~75 dirt
setblock ~37 ~109 ~76 dirt
setblock ~37 ~109 ~77 dirt
setblock ~37 ~109 ~78 dirt
setblock ~37 ~109 ~79 dirt
setblock ~37 ~110 ~66 dirt
setblock ~37 ~110 ~67 dirt
setblock ~37 ~110 ~68 dirt
setblock ~37 ~110 ~69 dirt
setblock ~37 ~110 ~70 dirt
setblock ~37 ~110 ~71 dirt
setblock ~37 ~110 ~72 dirt
setblock ~37 ~110 ~73 dirt
setblock ~37 ~110 ~74 dirt
setblock ~37 ~110 ~75 dirt
setblock ~37 ~110 ~76 dirt
setblock ~37 ~110 ~77 dirt
setblock ~37 ~110 ~78 dirt
setblock ~37 ~110 ~79 dirt
setblock ~37 ~110 ~80 dirt
setblock ~37 ~110 ~99 dirt
setblock ~37 ~111 ~65 dirt
setblock ~37 ~111 ~66 dirt
setblock ~37 ~111 ~67 dirt
setblock ~37 ~111 ~68 dirt
setblock ~37 ~111 ~69 dirt
setblock ~37 ~111 ~70 dirt
setblock ~37 ~111 ~71 dirt
setblock ~37 ~111 ~72 dirt
setblock ~37 ~111 ~73 dirt
setblock ~37 ~111 ~74 dirt
setblock ~37 ~111 ~75 dirt
setblock ~37 ~111 ~76 dirt
setblock ~37 ~111 ~77 dirt
setblock ~37 ~111 ~78 dirt
setblock ~37 ~111 ~79 dirt
setblock ~37 ~111 ~80 dirt
setblock ~37 ~111 ~81 dirt
setblock ~37 ~111 ~98 dirt
setblock ~37 ~111 ~99 dirt
setblock ~37 ~111 ~100 dirt
setblock ~37 ~112 ~65 dirt
setblock ~37 ~112 ~66 dirt
setblock ~37 ~112 ~67 dirt
setblock ~37 ~112 ~68 dirt
setblock ~37 ~112 ~69 dirt
setblock ~37 ~112 ~70 dirt
setblock ~37 ~112 ~71 dirt
setblock ~37 ~112 ~72 dirt
setblock ~37 ~112 ~73 dirt
setblock ~37 ~112 ~74 dirt
setblock ~37 ~112 ~75 dirt
setblock ~37 ~112 ~76 dirt
setblock ~37 ~112 ~77 dirt
setblock ~37 ~112 ~78 dirt
setblock ~37 ~112 ~79 dirt
setblock ~37 ~112 ~80 dirt
setblock ~37 ~112 ~81 dirt
setblock ~37 ~112 ~98 dirt
setblock ~37 ~112 ~99 dirt
setblock ~37 ~112 ~100 dirt
setblock ~37 ~112 ~101 dirt
setblock ~37 ~112 ~123 dirt
setblock ~37 ~113 ~63 dirt
setblock ~37 ~113 ~64 dirt
setblock ~37 ~113 ~65 dirt
setblock ~37 ~113 ~66 dirt
setblock ~37 ~113 ~67 dirt
setblock ~37 ~113 ~68 dirt
setblock ~37 ~113 ~69 dirt
setblock ~37 ~113 ~70 dirt
setblock ~37 ~113 ~71 dirt
setblock ~37 ~113 ~72 dirt
setblock ~37 ~113 ~73 dirt
setblock ~37 ~113 ~74 dirt
setblock ~37 ~113 ~75 dirt
setblock ~37 ~113 ~76 dirt
setblock ~37 ~113 ~77 dirt
setblock ~37 ~113 ~78 dirt
setblock ~37 ~113 ~79 dirt
setblock ~37 ~113 ~80 dirt
setblock ~37 ~113 ~81 dirt
setblock ~37 ~113 ~97 dirt
setblock ~37 ~113 ~98 dirt
setblock ~37 ~113 ~99 dirt
setblock ~37 ~113 ~100 dirt
setblock ~37 ~113 ~101 dirt
setblock ~37 ~113 ~102 dirt
setblock ~37 ~113 ~123 dirt
setblock ~37 ~114 ~62 dirt
setblock ~37 ~114 ~63 dirt
setblock ~37 ~114 ~64 dirt
setblock ~37 ~114 ~65 dirt
setblock ~37 ~114 ~66 dirt
setblock ~37 ~114 ~67 dirt
setblock ~37 ~114 ~68 dirt
setblock ~37 ~114 ~69 dirt
setblock ~37 ~114 ~70 dirt
setblock ~37 ~114 ~71 dirt
setblock ~37 ~114 ~72 dirt
setblock ~37 ~114 ~73 dirt
setblock ~37 ~114 ~74 dirt
setblock ~37 ~114 ~75 dirt
setblock ~37 ~114 ~76 dirt
setblock ~37 ~114 ~77 dirt
setblock ~37 ~114 ~78 dirt
setblock ~37 ~114 ~79 dirt
setblock ~37 ~114 ~80 dirt
setblock ~37 ~114 ~81 dirt
setblock ~37 ~114 ~82 dirt
setblock ~37 ~114 ~95 dirt
setblock ~37 ~114 ~96 dirt
setblock ~37 ~114 ~97 dirt
setblock ~37 ~114 ~98 dirt
setblock ~37 ~114 ~99 dirt
setblock ~37 ~114 ~100 dirt
setblock ~37 ~114 ~101 dirt
setblock ~37 ~114 ~102 dirt
setblock ~37 ~114 ~122 dirt
setblock ~37 ~114 ~123 dirt
setblock ~37 ~114 ~124 dirt
setblock ~37 ~115 ~61 dirt
setblock ~37 ~115 ~62 dirt
setblock ~37 ~115 ~63 dirt
setblock ~37 ~115 ~64 dirt
setblock ~37 ~115 ~65 dirt
setblock ~37 ~115 ~66 dirt
setblock ~37 ~115 ~67 dirt
setblock ~37 ~115 ~68 dirt
setblock ~37 ~115 ~69 dirt
setblock ~37 ~115 ~70 dirt
setblock ~37 ~115 ~71 dirt
setblock ~37 ~115 ~72 dirt
setblock ~37 ~115 ~73 dirt
setblock ~37 ~115 ~74 dirt
setblock ~37 ~115 ~75 dirt
setblock ~37 ~115 ~76 dirt
setblock ~37 ~115 ~77 dirt
setblock ~37 ~115 ~78 dirt
setblock ~37 ~115 ~79 dirt
setblock ~37 ~115 ~80 dirt
setblock ~37 ~115 ~81 dirt
setblock ~37 ~115 ~82 dirt
setblock ~37 ~115 ~95 dirt
setblock ~37 ~115 ~96 dirt
setblock ~37 ~115 ~97 dirt
setblock ~37 ~115 ~98 dirt
setblock ~37 ~115 ~99 dirt
setblock ~37 ~115 ~100 dirt
setblock ~37 ~115 ~101 dirt
setblock ~37 ~115 ~102 dirt
setblock ~37 ~115 ~103 dirt
setblock ~37 ~115 ~121 dirt
setblock ~37 ~115 ~122 dirt
setblock ~37 ~115 ~123 dirt
setblock ~37 ~115 ~124 dirt
setblock ~37 ~115 ~125 dirt
setblock ~37 ~116 ~60 dirt
setblock ~37 ~116 ~61 dirt
setblock ~37 ~116 ~62 dirt
setblock ~37 ~116 ~63 dirt
setblock ~37 ~116 ~64 dirt
setblock ~37 ~116 ~65 dirt
setblock ~37 ~116 ~66 dirt
setblock ~37 ~116 ~67 dirt
setblock ~37 ~116 ~68 dirt
setblock ~37 ~116 ~69 dirt
setblock ~37 ~116 ~70 dirt
setblock ~37 ~116 ~71 dirt
setblock ~37 ~116 ~72 dirt
setblock ~37 ~116 ~73 dirt
setblock ~37 ~116 ~74 dirt
setblock ~37 ~116 ~75 dirt
setblock ~37 ~116 ~76 dirt
setblock ~37 ~116 ~77 dirt
setblock ~37 ~116 ~78 dirt
setblock ~37 ~116 ~79 dirt
setblock ~37 ~116 ~80 dirt
setblock ~37 ~116 ~81 dirt
setblock ~37 ~116 ~82 dirt
setblock ~37 ~116 ~83 dirt
setblock ~37 ~116 ~95 dirt
setblock ~37 ~116 ~96 dirt
setblock ~37 ~116 ~97 dirt
setblock ~37 ~116 ~98 dirt
setblock ~37 ~116 ~99 dirt
setblock ~37 ~116 ~100 dirt
setblock ~37 ~116 ~101 dirt
setblock ~37 ~116 ~102 dirt
setblock ~37 ~116 ~103 dirt
setblock ~37 ~116 ~104 dirt
setblock ~37 ~116 ~119 dirt
setblock ~37 ~116 ~120 dirt
setblock ~37 ~116 ~121 dirt
setblock ~37 ~116 ~122 dirt
setblock ~37 ~116 ~123 dirt
setblock ~37 ~116 ~124 dirt
setblock ~37 ~116 ~125 dirt
setblock ~37 ~117 ~60 dirt
setblock ~37 ~117 ~61 dirt
setblock ~37 ~117 ~62 dirt
setblock ~37 ~117 ~63 dirt
setblock ~37 ~117 ~64 dirt
setblock ~37 ~117 ~65 dirt
setblock ~37 ~117 ~66 dirt
setblock ~37 ~117 ~67 dirt
setblock ~37 ~117 ~68 dirt
setblock ~37 ~117 ~69 dirt
setblock ~37 ~117 ~70 dirt
setblock ~37 ~117 ~71 dirt
setblock ~37 ~117 ~72 dirt
setblock ~37 ~117 ~73 dirt
setblock ~37 ~117 ~74 dirt
setblock ~37 ~117 ~75 dirt
setblock ~37 ~117 ~76 dirt
setblock ~37 ~117 ~77 dirt
setblock ~37 ~117 ~78 dirt
setblock ~37 ~117 ~79 dirt
setblock ~37 ~117 ~80 dirt
setblock ~37 ~117 ~81 dirt
setblock ~37 ~117 ~82 dirt
setblock ~37 ~117 ~83 dirt
setblock ~37 ~117 ~84 dirt
setblock ~37 ~117 ~93 dirt
setblock ~37 ~117 ~94 dirt
setblock ~37 ~117 ~95 dirt
setblock ~37 ~117 ~96 dirt
setblock ~37 ~117 ~97 dirt
setblock ~37 ~117 ~98 dirt
setblock ~37 ~117 ~99 dirt
setblock ~37 ~117 ~100 dirt
setblock ~37 ~117 ~101 dirt
setblock ~37 ~117 ~102 dirt
setblock ~37 ~117 ~103 dirt
setblock ~37 ~117 ~104 dirt
setblock ~37 ~117 ~105 dirt
setblock ~37 ~117 ~118 dirt
setblock ~37 ~117 ~119 dirt
setblock ~37 ~117 ~120 dirt
setblock ~37 ~117 ~121 dirt
setblock ~37 ~117 ~122 dirt
setblock ~37 ~117 ~123 dirt
setblock ~37 ~117 ~124 dirt
setblock ~37 ~117 ~125 dirt
setblock ~37 ~118 ~59 dirt
setblock ~37 ~118 ~60 dirt
setblock ~37 ~118 ~61 dirt
setblock ~37 ~118 ~62 dirt
setblock ~37 ~118 ~63 dirt
setblock ~37 ~118 ~64 dirt
setblock ~37 ~118 ~65 dirt
setblock ~37 ~118 ~66 dirt
setblock ~37 ~118 ~67 dirt
setblock ~37 ~118 ~68 dirt
setblock ~37 ~118 ~69 dirt
setblock ~37 ~118 ~70 dirt
setblock ~37 ~118 ~71 dirt
setblock ~37 ~118 ~72 dirt
setblock ~37 ~118 ~73 dirt
setblock ~37 ~118 ~74 dirt
setblock ~37 ~118 ~75 dirt
setblock ~37 ~118 ~76 dirt
setblock ~37 ~118 ~77 dirt
setblock ~37 ~118 ~78 dirt
setblock ~37 ~118 ~79 dirt
setblock ~37 ~118 ~80 dirt
setblock ~37 ~118 ~81 dirt
setblock ~37 ~118 ~82 dirt
setblock ~37 ~118 ~83 dirt
setblock ~37 ~118 ~84 dirt
setblock ~37 ~118 ~85 dirt
setblock ~37 ~118 ~93 dirt
setblock ~37 ~118 ~94 dirt
setblock ~37 ~118 ~95 dirt
setblock ~37 ~118 ~96 dirt
setblock ~37 ~118 ~97 dirt
setblock ~37 ~118 ~98 dirt
setblock ~37 ~118 ~99 dirt
setblock ~37 ~118 ~100 dirt
setblock ~37 ~118 ~101 dirt
setblock ~37 ~118 ~102 dirt
setblock ~37 ~118 ~103 dirt
setblock ~37 ~118 ~104 dirt
setblock ~37 ~118 ~105 dirt
setblock ~37 ~118 ~118 dirt
setblock ~37 ~118 ~119 dirt
setblock ~37 ~118 ~120 dirt
setblock ~37 ~118 ~121 dirt
setblock ~37 ~118 ~122 dirt
setblock ~37 ~118 ~123 dirt
setblock ~37 ~118 ~124 dirt
setblock ~37 ~118 ~125 dirt
setblock ~37 ~118 ~126 dirt
setblock ~37 ~119 ~59 dirt
setblock ~37 ~119 ~60 dirt
setblock ~37 ~119 ~61 dirt
setblock ~37 ~119 ~62 dirt
setblock ~37 ~119 ~63 dirt
setblock ~37 ~119 ~64 dirt
setblock ~37 ~119 ~65 dirt
setblock ~37 ~119 ~66 dirt
setblock ~37 ~119 ~67 dirt
setblock ~37 ~119 ~68 dirt
setblock ~37 ~119 ~69 dirt
setblock ~37 ~119 ~70 dirt
setblock ~37 ~119 ~71 dirt
setblock ~37 ~119 ~72 dirt
setblock ~37 ~119 ~73 dirt
setblock ~37 ~119 ~74 dirt
setblock ~37 ~119 ~75 dirt
setblock ~37 ~119 ~76 dirt
setblock ~37 ~119 ~77 dirt
setblock ~37 ~119 ~78 dirt
setblock ~37 ~119 ~79 dirt
setblock ~37 ~119 ~80 dirt
setblock ~37 ~119 ~81 dirt
setblock ~37 ~119 ~82 dirt
setblock ~37 ~119 ~83 dirt
setblock ~37 ~119 ~84 dirt
setblock ~37 ~119 ~85 dirt
setblock ~37 ~119 ~86 dirt
setblock ~37 ~119 ~88 dirt
setblock ~37 ~119 ~92 dirt
setblock ~37 ~119 ~93 dirt
setblock ~37 ~119 ~94 dirt
setblock ~37 ~119 ~95 dirt
setblock ~37 ~119 ~96 dirt
setblock ~37 ~119 ~97 dirt
setblock ~37 ~119 ~98 dirt
setblock ~37 ~119 ~99 dirt
setblock ~37 ~119 ~100 dirt
setblock ~37 ~119 ~101 dirt
setblock ~37 ~119 ~102 dirt
setblock ~37 ~119 ~103 dirt
setblock ~37 ~119 ~104 dirt
setblock ~37 ~119 ~105 dirt
setblock ~37 ~119 ~106 dirt
setblock ~37 ~119 ~117 dirt
setblock ~37 ~119 ~118 dirt
setblock ~37 ~119 ~119 dirt
setblock ~37 ~119 ~120 dirt
setblock ~37 ~119 ~121 dirt
setblock ~37 ~119 ~122 dirt
setblock ~37 ~119 ~123 dirt
setblock ~37 ~119 ~124 dirt
setblock ~37 ~119 ~125 dirt
setblock ~37 ~119 ~126 dirt
setblock ~37 ~119 ~127 dirt
setblock ~37 ~120 ~59 dirt
setblock ~37 ~120 ~60 dirt
setblock ~37 ~120 ~61 dirt
setblock ~37 ~120 ~62 dirt
setblock ~37 ~120 ~63 dirt
setblock ~37 ~120 ~64 dirt
setblock ~37 ~120 ~65 dirt
setblock ~37 ~120 ~66 dirt
setblock ~37 ~120 ~67 dirt
setblock ~37 ~120 ~68 dirt
setblock ~37 ~120 ~69 dirt
setblock ~37 ~120 ~70 dirt
setblock ~37 ~120 ~71 dirt
setblock ~37 ~120 ~72 dirt
setblock ~37 ~120 ~73 dirt
setblock ~37 ~120 ~74 dirt
setblock ~37 ~120 ~75 dirt
setblock ~37 ~120 ~76 dirt
setblock ~37 ~120 ~77 dirt
setblock ~37 ~120 ~78 dirt
setblock ~37 ~120 ~79 dirt
setblock ~37 ~120 ~80 dirt
setblock ~37 ~120 ~81 dirt
setblock ~37 ~120 ~82 dirt
setblock ~37 ~120 ~83 dirt
setblock ~37 ~120 ~84 dirt
setblock ~37 ~120 ~85 dirt
setblock ~37 ~120 ~86 dirt
setblock ~37 ~120 ~87 dirt
setblock ~37 ~120 ~88 dirt
setblock ~37 ~120 ~89 dirt
setblock ~37 ~120 ~90 dirt
setblock ~37 ~120 ~92 dirt
setblock ~37 ~120 ~93 dirt
setblock ~37 ~120 ~94 dirt
setblock ~37 ~120 ~95 dirt
setblock ~37 ~120 ~96 dirt
setblock ~37 ~120 ~97 dirt
setblock ~37 ~120 ~98 dirt
setblock ~37 ~120 ~99 dirt
setblock ~37 ~120 ~100 dirt
setblock ~37 ~120 ~101 dirt
setblock ~37 ~120 ~102 dirt
setblock ~37 ~120 ~103 dirt
setblock ~37 ~120 ~104 dirt
setblock ~37 ~120 ~105 dirt
setblock ~37 ~120 ~106 dirt
setblock ~37 ~120 ~115 dirt
setblock ~37 ~120 ~116 dirt
setblock ~37 ~120 ~117 dirt
setblock ~37 ~120 ~118 dirt
setblock ~37 ~120 ~119 dirt
setblock ~37 ~120 ~120 dirt
setblock ~37 ~120 ~121 dirt
setblock ~37 ~120 ~122 dirt
setblock ~37 ~120 ~123 dirt
setblock ~37 ~120 ~124 dirt
setblock ~37 ~120 ~125 dirt
setblock ~37 ~120 ~126 dirt
setblock ~37 ~120 ~127 dirt
setblock ~37 ~121 ~58 dirt
setblock ~37 ~121 ~59 dirt
setblock ~37 ~121 ~60 dirt
setblock ~37 ~121 ~61 dirt
setblock ~37 ~121 ~62 dirt
setblock ~37 ~121 ~63 dirt
setblock ~37 ~121 ~64 dirt
setblock ~37 ~121 ~65 dirt
setblock ~37 ~121 ~66 dirt
setblock ~37 ~121 ~67 dirt
setblock ~37 ~121 ~68 dirt
setblock ~37 ~121 ~69 dirt
setblock ~37 ~121 ~70 dirt
setblock ~37 ~121 ~71 dirt
setblock ~37 ~121 ~72 dirt
setblock ~37 ~121 ~73 dirt
setblock ~37 ~121 ~74 dirt
setblock ~37 ~121 ~75 dirt
setblock ~37 ~121 ~76 dirt
setblock ~37 ~121 ~77 dirt
setblock ~37 ~121 ~78 dirt
setblock ~37 ~121 ~79 dirt
setblock ~37 ~121 ~80 dirt
setblock ~37 ~121 ~81 dirt
setblock ~37 ~121 ~82 dirt
setblock ~37 ~121 ~83 dirt
setblock ~37 ~121 ~84 dirt
setblock ~37 ~121 ~85 dirt
setblock ~37 ~121 ~86 dirt
setblock ~37 ~121 ~87 dirt
setblock ~37 ~121 ~88 dirt
setblock ~37 ~121 ~89 dirt
setblock ~37 ~121 ~90 dirt
setblock ~37 ~121 ~91 dirt
setblock ~37 ~121 ~92 dirt
setblock ~37 ~121 ~93 dirt
setblock ~37 ~121 ~94 dirt
setblock ~37 ~121 ~95 dirt
setblock ~37 ~121 ~96 dirt
setblock ~37 ~121 ~97 dirt
setblock ~37 ~121 ~98 dirt
setblock ~37 ~121 ~99 dirt
setblock ~37 ~121 ~100 dirt
setblock ~37 ~121 ~101 dirt
setblock ~37 ~121 ~102 dirt
setblock ~37 ~121 ~103 dirt
setblock ~37 ~121 ~104 dirt
setblock ~37 ~121 ~105 dirt
setblock ~37 ~121 ~106 dirt
setblock ~37 ~121 ~114 dirt
setblock ~37 ~121 ~115 dirt
setblock ~37 ~121 ~116 dirt
setblock ~37 ~121 ~117 dirt
setblock ~37 ~121 ~118 dirt
setblock ~37 ~121 ~119 dirt
setblock ~37 ~121 ~120 dirt
setblock ~37 ~121 ~121 dirt
setblock ~37 ~121 ~122 dirt
setblock ~37 ~121 ~123 dirt
setblock ~37 ~121 ~124 dirt
setblock ~37 ~121 ~125 dirt
setblock ~37 ~121 ~126 dirt
setblock ~37 ~121 ~127 dirt
setblock ~37 ~121 ~128 dirt
setblock ~37 ~122 ~58 dirt
setblock ~37 ~122 ~59 dirt
setblock ~37 ~122 ~60 grass_block
setblock ~37 ~122 ~61 dirt
setblock ~37 ~122 ~62 dirt
setblock ~37 ~122 ~63 dirt
setblock ~37 ~122 ~64 dirt
setblock ~37 ~122 ~65 dirt
setblock ~37 ~122 ~66 dirt
setblock ~37 ~122 ~67 dirt
setblock ~37 ~122 ~68 dirt
setblock ~37 ~122 ~69 dirt
setblock ~37 ~122 ~70 dirt
setblock ~37 ~122 ~71 dirt
setblock ~37 ~122 ~72 dirt
setblock ~37 ~122 ~73 dirt
setblock ~37 ~122 ~74 dirt
setblock ~37 ~122 ~75 dirt
setblock ~37 ~122 ~76 dirt
setblock ~37 ~122 ~77 dirt
setblock ~37 ~122 ~78 dirt
setblock ~37 ~122 ~79 dirt
setblock ~37 ~122 ~80 dirt
setblock ~37 ~122 ~81 dirt
setblock ~37 ~122 ~82 dirt
setblock ~37 ~122 ~83 dirt
setblock ~37 ~122 ~84 dirt
setblock ~37 ~122 ~85 dirt
setblock ~37 ~122 ~86 dirt
setblock ~37 ~122 ~87 dirt
setblock ~37 ~122 ~88 dirt
setblock ~37 ~122 ~89 dirt
setblock ~37 ~122 ~90 dirt
setblock ~37 ~122 ~91 dirt
setblock ~37 ~122 ~92 dirt
setblock ~37 ~122 ~93 dirt
setblock ~37 ~122 ~94 dirt
setblock ~37 ~122 ~95 dirt
setblock ~37 ~122 ~96 dirt
setblock ~37 ~122 ~97 dirt
setblock ~37 ~122 ~98 dirt
setblock ~37 ~122 ~99 dirt
setblock ~37 ~122 ~100 dirt
setblock ~37 ~122 ~101 dirt
setblock ~37 ~122 ~102 dirt
setblock ~37 ~122 ~103 dirt
setblock ~37 ~122 ~104 dirt
setblock ~37 ~122 ~105 dirt
setblock ~37 ~122 ~106 dirt
setblock ~37 ~122 ~114 dirt
setblock ~37 ~122 ~115 dirt
setblock ~37 ~122 ~116 dirt
setblock ~37 ~122 ~117 dirt
setblock ~37 ~122 ~118 dirt
setblock ~37 ~122 ~119 dirt
setblock ~37 ~122 ~120 dirt
setblock ~37 ~122 ~121 dirt
setblock ~37 ~122 ~122 dirt
setblock ~37 ~122 ~123 dirt
setblock ~37 ~122 ~124 dirt
setblock ~37 ~122 ~125 dirt
setblock ~37 ~122 ~126 dirt
setblock ~37 ~122 ~127 dirt
setblock ~37 ~122 ~128 dirt
setblock ~37 ~123 ~58 grass_block
setblock ~37 ~123 ~59 grass_block
setblock ~37 ~123 ~60 fern
setblock ~37 ~123 ~61 grass_block
setblock ~37 ~123 ~62 grass_block
setblock ~37 ~123 ~63 grass_block
setblock ~37 ~123 ~64 dirt
setblock ~37 ~123 ~65 dirt
setblock ~37 ~123 ~66 dirt
setblock ~37 ~123 ~67 dirt
setblock ~37 ~123 ~68 dirt
setblock ~37 ~123 ~69 dirt
setblock ~37 ~123 ~70 dirt
setblock ~37 ~123 ~71 dirt
setblock ~37 ~123 ~72 dirt
setblock ~37 ~123 ~73 dirt
setblock ~37 ~123 ~74 dirt
setblock ~37 ~123 ~75 dirt
setblock ~37 ~123 ~76 dirt
setblock ~37 ~123 ~77 dirt
setblock ~37 ~123 ~78 dirt
setblock ~37 ~123 ~79 dirt
setblock ~37 ~123 ~80 dirt
setblock ~37 ~123 ~81 dirt
setblock ~37 ~123 ~82 dirt
setblock ~37 ~123 ~83 dirt
setblock ~37 ~123 ~84 dirt
setblock ~37 ~123 ~85 dirt
setblock ~37 ~123 ~86 dirt
setblock ~37 ~123 ~87 dirt
setblock ~37 ~123 ~88 dirt
setblock ~37 ~123 ~89 dirt
setblock ~37 ~123 ~90 dirt
setblock ~37 ~123 ~91 dirt
setblock ~37 ~123 ~92 dirt
setblock ~37 ~123 ~93 dirt
setblock ~37 ~123 ~94 dirt
setblock ~37 ~123 ~95 dirt
setblock ~37 ~123 ~96 dirt
setblock ~37 ~123 ~97 dirt
setblock ~37 ~123 ~98 dirt
setblock ~37 ~123 ~99 dirt
setblock ~37 ~123 ~100 dirt
setblock ~37 ~123 ~101 dirt
setblock ~37 ~123 ~102 dirt
setblock ~37 ~123 ~103 dirt
setblock ~37 ~123 ~104 dirt
setblock ~37 ~123 ~105 dirt
setblock ~37 ~123 ~106 dirt
setblock ~37 ~123 ~114 dirt
setblock ~37 ~123 ~115 dirt
setblock ~37 ~123 ~116 dirt
setblock ~37 ~123 ~117 dirt
setblock ~37 ~123 ~118 dirt
setblock ~37 ~123 ~119 dirt
setblock ~37 ~123 ~120 dirt
setblock ~37 ~123 ~121 dirt
setblock ~37 ~123 ~122 dirt
setblock ~37 ~123 ~123 dirt
setblock ~37 ~123 ~124 dirt
setblock ~37 ~123 ~125 dirt
setblock ~37 ~123 ~126 dirt
setblock ~37 ~123 ~127 dirt
setblock ~37 ~123 ~128 dirt
setblock ~37 ~124 ~58 fern
setblock ~37 ~124 ~64 grass_block
setblock ~37 ~124 ~65 grass_block
setblock ~37 ~124 ~66 grass_block
setblock ~37 ~124 ~67 dirt
setblock ~37 ~124 ~68 dirt
setblock ~37 ~124 ~69 dirt
setblock ~37 ~124 ~70 dirt
setblock ~37 ~124 ~71 dirt
setblock ~37 ~124 ~72 dirt
setblock ~37 ~124 ~73 dirt
setblock ~37 ~124 ~74 dirt
setblock ~37 ~124 ~75 dirt
setblock ~37 ~124 ~76 dirt
setblock ~37 ~124 ~77 dirt
setblock ~37 ~124 ~78 dirt
setblock ~37 ~124 ~79 dirt
setblock ~37 ~124 ~80 dirt
setblock ~37 ~124 ~81 dirt
setblock ~37 ~124 ~82 dirt
setblock ~37 ~124 ~83 dirt
setblock ~37 ~124 ~84 dirt
setblock ~37 ~124 ~85 dirt
setblock ~37 ~124 ~86 dirt
setblock ~37 ~124 ~87 dirt
setblock ~37 ~124 ~88 dirt
setblock ~37 ~124 ~89 dirt
setblock ~37 ~124 ~90 dirt
setblock ~37 ~124 ~91 dirt
setblock ~37 ~124 ~92 dirt
setblock ~37 ~124 ~93 dirt
setblock ~37 ~124 ~94 dirt
setblock ~37 ~124 ~95 dirt
setblock ~37 ~124 ~96 dirt
setblock ~37 ~124 ~97 dirt
setblock ~37 ~124 ~98 dirt
setblock ~37 ~124 ~99 dirt
setblock ~37 ~124 ~100 dirt
setblock ~37 ~124 ~101 dirt
setblock ~37 ~124 ~102 dirt
setblock ~37 ~124 ~103 dirt
setblock ~37 ~124 ~104 dirt
setblock ~37 ~124 ~105 dirt
setblock ~37 ~124 ~106 dirt
setblock ~37 ~124 ~114 dirt
setblock ~37 ~124 ~115 dirt
setblock ~37 ~124 ~116 dirt
setblock ~37 ~124 ~117 dirt
setblock ~37 ~124 ~118 dirt
setblock ~37 ~124 ~119 dirt
setblock ~37 ~124 ~120 dirt
setblock ~37 ~124 ~121 dirt
setblock ~37 ~124 ~122 dirt
setblock ~37 ~124 ~123 dirt
setblock ~37 ~124 ~124 dirt
setblock ~37 ~124 ~125 dirt
setblock ~37 ~124 ~126 dirt
setblock ~37 ~124 ~127 grass_block
setblock ~37 ~124 ~128 grass_block
setblock ~37 ~125 ~65 short_grass
setblock ~37 ~125 ~67 grass_block
setblock ~37 ~125 ~68 grass_block
setblock ~37 ~125 ~69 grass_block
setblock ~37 ~125 ~70 dirt
setblock ~37 ~125 ~71 dirt
setblock ~37 ~125 ~72 dirt
setblock ~37 ~125 ~73 dirt
setblock ~37 ~125 ~74 dirt
setblock ~37 ~125 ~75 dirt
setblock ~37 ~125 ~76 dirt
setblock ~37 ~125 ~77 dirt
setblock ~37 ~125 ~78 dirt
setblock ~37 ~125 ~79 dirt
setblock ~37 ~125 ~80 dirt
setblock ~37 ~125 ~81 dirt
setblock ~37 ~125 ~82 dirt
setblock ~37 ~125 ~83 dirt
setblock ~37 ~125 ~84 dirt
setblock ~37 ~125 ~85 dirt
setblock ~37 ~125 ~86 dirt
setblock ~37 ~125 ~87 grass_block
setblock ~37 ~125 ~88 grass_block
setblock ~37 ~125 ~89 grass_block
setblock ~37 ~125 ~90 grass_block
setblock ~37 ~125 ~91 grass_block
setblock ~37 ~125 ~92 grass_block
setblock ~37 ~125 ~93 grass_block
setblock ~37 ~125 ~94 grass_block
setblock ~37 ~125 ~95 grass_block
setblock ~37 ~125 ~96 grass_block
setblock ~37 ~125 ~97 grass_block
setblock ~37 ~125 ~98 grass_block
setblock ~37 ~125 ~99 grass_block
setblock ~37 ~125 ~100 grass_block
setblock ~37 ~125 ~101 grass_block
setblock ~37 ~125 ~102 grass_block
setblock ~37 ~125 ~103 grass_block
setblock ~37 ~125 ~104 dirt
setblock ~37 ~125 ~105 dirt
setblock ~37 ~125 ~106 dirt
setblock ~37 ~125 ~114 dirt
setblock ~37 ~125 ~115 dirt
setblock ~37 ~125 ~116 dirt
setblock ~37 ~125 ~117 dirt
setblock ~37 ~125 ~118 dirt
setblock ~37 ~125 ~119 dirt
setblock ~37 ~125 ~120 dirt
setblock ~37 ~125 ~121 grass_block
setblock ~37 ~125 ~122 grass_block
setblock ~37 ~125 ~123 grass_block
setblock ~37 ~125 ~124 grass_block
setblock ~37 ~125 ~125 grass_block
setblock ~37 ~125 ~126 grass_block
setblock ~37 ~125 ~127 poppy
setblock ~37 ~125 ~128 poppy
setblock ~37 ~126 ~67 poppy
setblock ~37 ~126 ~70 grass_block
setblock ~37 ~126 ~71 grass_block
setblock ~37 ~126 ~72 grass_block
setblock ~37 ~126 ~73 grass_block
setblock ~37 ~126 ~74 grass_block
setblock ~37 ~126 ~75 grass_block
setblock ~37 ~126 ~76 grass_block
setblock ~37 ~126 ~77 grass_block
setblock ~37 ~126 ~78 grass_block
setblock ~37 ~126 ~79 grass_block
setblock ~37 ~126 ~80 grass_block
setblock ~37 ~126 ~81 grass_block
setblock ~37 ~126 ~82 grass_block
setblock ~37 ~126 ~83 grass_block
setblock ~37 ~126 ~84 grass_block
setblock ~37 ~126 ~85 grass_block
setblock ~37 ~126 ~86 grass_block
setblock ~37 ~126 ~89 short_grass
setblock ~37 ~126 ~90 short_grass
setblock ~37 ~126 ~92 short_grass
setblock ~37 ~126 ~93 short_grass
setblock ~37 ~126 ~97 fern
setblock ~37 ~126 ~98 short_grass
setblock ~37 ~126 ~100 short_grass
setblock ~37 ~126 ~102 fern
setblock ~37 ~126 ~104 grass_block
setblock ~37 ~126 ~105 grass_block
setblock ~37 ~126 ~106 grass_block
setblock ~37 ~126 ~114 grass_block
setblock ~37 ~126 ~115 grass_block
setblock ~37 ~126 ~116 grass_block
setblock ~37 ~126 ~117 grass_block
setblock ~37 ~126 ~118 grass_block
setblock ~37 ~126 ~119 grass_block
setblock ~37 ~126 ~120 grass_block
setblock ~37 ~126 ~126 poppy
setblock ~37 ~127 ~75 poppy
setblock ~37 ~127 ~78 short_grass
setblock ~37 ~127 ~81 short_grass
setblock ~37 ~127 ~84 poppy
setblock ~37 ~127 ~104 fern
setblock ~37 ~127 ~105 fern
setblock ~37 ~127 ~116 short_grass
setblock ~37 ~127 ~118 short_grass
setblock ~37 ~129 ~62 oak_leaves[persistent=null]
setblock ~37 ~129 ~63 oak_leaves[persistent=null]
setblock ~37 ~129 ~64 jungle_leaves[persistent=null]
setblock ~37 ~129 ~66 oak_leaves[persistent=null]
setblock ~37 ~129 ~68 oak_leaves[persistent=null]
setblock ~37 ~130 ~62 oak_leaves[persistent=null]
setblock ~37 ~130 ~63 jungle_leaves[persistent=null]
setblock ~37 ~130 ~64 oak_leaves[persistent=null]
setblock ~37 ~130 ~66 oak_leaves[persistent=null]
setblock ~37 ~130 ~67 oak_leaves[persistent=null]
setblock ~37 ~130 ~68 oak_leaves[persistent=null]
setblock ~37 ~131 ~63 oak_leaves[persistent=null]
setblock ~37 ~131 ~64 jungle_leaves[persistent=null]
setblock ~37 ~131 ~65 oak_leaves[persistent=null]
setblock ~37 ~131 ~66 jungle_leaves[persistent=null]
setblock ~37 ~131 ~67 oak_wood
setblock ~37 ~131 ~68 oak_leaves[persistent=null]
setblock ~37 ~131 ~70 oak_leaves[persistent=null]
setblock ~37 ~132 ~62 oak_leaves[persistent=null]
setblock ~37 ~132 ~63 jungle_leaves[persistent=null]
setblock ~37 ~132 ~64 jungle_leaves[persistent=null]
setblock ~37 ~132 ~68 oak_leaves[persistent=null]
setblock ~37 ~132 ~69 oak_leaves[persistent=null]
setblock ~37 ~132 ~70 oak_leaves[persistent=null]
setblock ~37 ~132 ~74 oak_leaves[persistent=null]
setblock ~37 ~132 ~75 oak_leaves[persistent=null]
setblock ~37 ~132 ~76 oak_leaves[persistent=null]
setblock ~37 ~132 ~77 oak_leaves[persistent=null]
setblock ~37 ~133 ~63 jungle_leaves[persistent=null]
setblock ~37 ~133 ~64 oak_leaves[persistent=null]
setblock ~37 ~133 ~66 oak_wood
setblock ~37 ~133 ~67 oak_wood
setblock ~37 ~133 ~69 oak_leaves[persistent=null]
setblock ~37 ~133 ~70 oak_leaves[persistent=null]
setblock ~37 ~133 ~74 oak_leaves[persistent=null]
setblock ~37 ~133 ~76 oak_leaves[persistent=null]
setblock ~37 ~133 ~77 oak_leaves[persistent=null]
setblock ~37 ~134 ~63 jungle_leaves[persistent=null]
setblock ~37 ~134 ~64 oak_leaves[persistent=null]
setblock ~37 ~134 ~65 oak_leaves[persistent=null]
setblock ~37 ~134 ~66 oak_leaves[persistent=null]
setblock ~37 ~134 ~67 oak_leaves[persistent=null]
setblock ~37 ~134 ~69 oak_leaves[persistent=null]
setblock ~37 ~134 ~70 jungle_leaves[persistent=null]
setblock ~37 ~134 ~73 oak_leaves[persistent=null]
setblock ~37 ~134 ~75 oak_wood
setblock ~37 ~134 ~77 oak_leaves[persistent=null]
setblock ~37 ~135 ~63 jungle_leaves[persistent=null]
setblock ~37 ~135 ~64 oak_leaves[persistent=null]
setblock ~37 ~135 ~66 oak_wood
setblock ~37 ~135 ~67 oak_leaves[persistent=null]
setblock ~37 ~135 ~68 oak_leaves[persistent=null]
setblock ~37 ~135 ~70 oak_leaves[persistent=null]
setblock ~37 ~135 ~73 jungle_leaves[persistent=null]
setblock ~37 ~135 ~75 oak_leaves[persistent=null]
setblock ~37 ~135 ~77 oak_leaves[persistent=null]
setblock ~37 ~136 ~64 oak_leaves[persistent=null]
setblock ~37 ~136 ~65 oak_leaves[persistent=null]
setblock ~37 ~136 ~67 jungle_leaves[persistent=null]
setblock ~37 ~136 ~95 oak_leaves[persistent=null]
setblock ~37 ~136 ~96 oak_leaves[persistent=null]
setblock ~37 ~136 ~97 oak_leaves[persistent=null]
setblock ~37 ~137 ~64 oak_leaves[persistent=null]
setblock ~37 ~137 ~66 oak_leaves[persistent=null]
setblock ~37 ~137 ~67 oak_leaves[persistent=null]
setblock ~37 ~137 ~68 oak_leaves[persistent=null]
setblock ~37 ~137 ~95 oak_leaves[persistent=null]
setblock ~37 ~137 ~96 oak_leaves[persistent=null]
setblock ~37 ~137 ~97 jungle_leaves[persistent=null]
setblock ~37 ~138 ~64 oak_leaves[persistent=null]
setblock ~37 ~138 ~65 oak_leaves[persistent=null]
setblock ~37 ~138 ~66 jungle_leaves[persistent=null]
setblock ~37 ~138 ~67 oak_leaves[persistent=null]
setblock ~37 ~138 ~68 oak_leaves[persistent=null]
setblock ~37 ~138 ~96 oak_leaves[persistent=null]
setblock ~37 ~138 ~97 oak_leaves[persistent=null]
setblock ~37 ~139 ~96 oak_leaves[persistent=null]
setblock ~37 ~139 ~97 oak_leaves[persistent=null]
setblock ~37 ~139 ~98 oak_leaves[persistent=null]
setblock ~37 ~140 ~68 oak_leaves[persistent=null]
setblock ~37 ~140 ~69 oak_leaves[persistent=null]
setblock ~37 ~141 ~68 oak_leaves[persistent=null]
setblock ~37 ~141 ~69 oak_leaves[persistent=null]
setblock ~37 ~141 ~70 oak_leaves[persistent=null]
setblock ~37 ~142 ~68 oak_leaves[persistent=null]
setblock ~37 ~142 ~69 oak_leaves[persistent=null]
setblock ~37 ~142 ~70 oak_wood
setblock ~37 ~142 ~71 oak_leaves[persistent=null]
setblock ~37 ~143 ~68 jungle_leaves[persistent=null]
setblock ~37 ~143 ~69 oak_leaves[persistent=null]
setblock ~37 ~143 ~70 oak_leaves[persistent=null]
setblock ~38 ~103 ~75 dirt
setblock ~38 ~103 ~76 dirt
setblock ~38 ~104 ~72 dirt
setblock ~38 ~104 ~75 dirt
setblock ~38 ~104 ~76 dirt
setblock ~38 ~104 ~77 dirt
setblock ~38 ~104 ~78 dirt
setblock ~38 ~105 ~70 dirt
setblock ~38 ~105 ~71 dirt
setblock ~38 ~105 ~72 dirt
setblock ~38 ~105 ~73 dirt
setblock ~38 ~105 ~74 dirt
setblock ~38 ~105 ~75 dirt
setblock ~38 ~105 ~76 dirt
setblock ~38 ~105 ~77 dirt
setblock ~38 ~105 ~78 dirt
