setblock ~168 ~126 ~75 short_grass
setblock ~168 ~126 ~83 short_grass
setblock ~168 ~126 ~84 short_grass
setblock ~168 ~126 ~94 fern
setblock ~168 ~126 ~96 grass_block
setblock ~168 ~126 ~97 grass_block
setblock ~168 ~126 ~98 grass_block
setblock ~168 ~126 ~99 grass_block
setblock ~168 ~126 ~100 grass_block
setblock ~168 ~126 ~101 grass_block
setblock ~168 ~126 ~102 grass_block
setblock ~168 ~126 ~103 grass_block
setblock ~168 ~126 ~104 grass_block
setblock ~168 ~126 ~105 grass_block
setblock ~168 ~126 ~106 grass_block
setblock ~168 ~126 ~108 fern
setblock ~168 ~126 ~109 short_grass
setblock ~168 ~126 ~113 short_grass
setblock ~168 ~126 ~115 poppy
setblock ~168 ~126 ~119 poppy
setblock ~168 ~126 ~124 grass_block
setblock ~168 ~126 ~125 grass_block
setblock ~168 ~126 ~126 grass_block
setblock ~168 ~126 ~127 grass_block
setblock ~168 ~126 ~128 grass_block
setblock ~168 ~126 ~129 grass_block
setblock ~168 ~126 ~130 dirt
setblock ~168 ~126 ~131 dirt
setblock ~168 ~127 ~98 short_grass
setblock ~168 ~127 ~101 short_grass
setblock ~168 ~127 ~124 fern
setblock ~168 ~127 ~125 short_grass
setblock ~168 ~127 ~130 grass_block
setblock ~168 ~127 ~131 grass_block
setblock ~169 ~113 ~80 dirt
setblock ~169 ~113 ~99 dirt
setblock ~169 ~113 ~101 dirt
setblock ~169 ~114 ~79 dirt
setblock ~169 ~114 ~80 dirt
setblock ~169 ~114 ~81 dirt
setblock ~169 ~114 ~98 dirt
setblock ~169 ~114 ~99 dirt
setblock ~169 ~114 ~100 dirt
setblock ~169 ~114 ~101 dirt
setblock ~169 ~114 ~102 dirt
setblock ~169 ~114 ~103 dirt
setblock ~169 ~115 ~77 dirt
setblock ~169 ~115 ~78 dirt
setblock ~169 ~115 ~79 dirt
setblock ~169 ~115 ~80 dirt
setblock ~169 ~115 ~81 dirt
setblock ~169 ~115 ~82 dirt
setblock ~169 ~115 ~97 dirt
setblock ~169 ~115 ~98 dirt
setblock ~169 ~115 ~99 dirt
setblock ~169 ~115 ~100 dirt
setblock ~169 ~115 ~101 dirt
setblock ~169 ~115 ~102 dirt
setblock ~169 ~115 ~103 dirt
setblock ~169 ~115 ~104 dirt
setblock ~169 ~115 ~105 dirt
setblock ~169 ~116 ~77 dirt
setblock ~169 ~116 ~78 dirt
setblock ~169 ~116 ~79 dirt
setblock ~169 ~116 ~80 dirt
setblock ~169 ~116 ~81 dirt
setblock ~169 ~116 ~82 dirt
setblock ~169 ~116 ~83 dirt
setblock ~169 ~116 ~86 dirt
setblock ~169 ~116 ~87 dirt
setblock ~169 ~116 ~97 dirt
setblock ~169 ~116 ~98 dirt
setblock ~169 ~116 ~99 dirt
setblock ~169 ~116 ~100 dirt
setblock ~169 ~116 ~101 dirt
setblock ~169 ~116 ~102 dirt
setblock ~169 ~116 ~103 dirt
setblock ~169 ~116 ~104 dirt
setblock ~169 ~116 ~105 dirt
setblock ~169 ~116 ~106 dirt
setblock ~169 ~116 ~107 dirt
setblock ~169 ~116 ~108 dirt
setblock ~169 ~117 ~76 dirt
setblock ~169 ~117 ~77 dirt
setblock ~169 ~117 ~78 dirt
setblock ~169 ~117 ~79 dirt
setblock ~169 ~117 ~80 dirt
setblock ~169 ~117 ~81 dirt
setblock ~169 ~117 ~82 dirt
setblock ~169 ~117 ~83 dirt
setblock ~169 ~117 ~84 dirt
setblock ~169 ~117 ~86 dirt
setblock ~169 ~117 ~87 dirt
setblock ~169 ~117 ~88 dirt
setblock ~169 ~117 ~97 dirt
setblock ~169 ~117 ~98 dirt
setblock ~169 ~117 ~99 dirt
setblock ~169 ~117 ~100 dirt
setblock ~169 ~117 ~101 dirt
setblock ~169 ~117 ~102 dirt
setblock ~169 ~117 ~103 dirt
setblock ~169 ~117 ~104 dirt
setblock ~169 ~117 ~105 dirt
setblock ~169 ~117 ~106 dirt
setblock ~169 ~117 ~107 dirt
setblock ~169 ~117 ~108 dirt
setblock ~169 ~118 ~76 dirt
setblock ~169 ~118 ~77 dirt
setblock ~169 ~118 ~78 dirt
setblock ~169 ~118 ~79 dirt
setblock ~169 ~118 ~80 dirt
setblock ~169 ~118 ~81 dirt
setblock ~169 ~118 ~82 dirt
setblock ~169 ~118 ~83 dirt
setblock ~169 ~118 ~84 dirt
setblock ~169 ~118 ~85 dirt
setblock ~169 ~118 ~86 dirt
setblock ~169 ~118 ~87 dirt
setblock ~169 ~118 ~88 dirt
setblock ~169 ~118 ~89 dirt
setblock ~169 ~118 ~96 dirt
setblock ~169 ~118 ~97 dirt
setblock ~169 ~118 ~98 dirt
setblock ~169 ~118 ~99 dirt
setblock ~169 ~118 ~100 dirt
setblock ~169 ~118 ~101 dirt
setblock ~169 ~118 ~102 dirt
setblock ~169 ~118 ~103 dirt
setblock ~169 ~118 ~104 dirt
setblock ~169 ~118 ~105 dirt
setblock ~169 ~118 ~106 dirt
setblock ~169 ~118 ~107 dirt
setblock ~169 ~118 ~108 dirt
setblock ~169 ~119 ~76 dirt
setblock ~169 ~119 ~77 dirt
setblock ~169 ~119 ~78 dirt
setblock ~169 ~119 ~79 dirt
setblock ~169 ~119 ~80 dirt
setblock ~169 ~119 ~81 dirt
setblock ~169 ~119 ~82 dirt
setblock ~169 ~119 ~83 dirt
setblock ~169 ~119 ~84 dirt
setblock ~169 ~119 ~85 dirt
setblock ~169 ~119 ~86 dirt
setblock ~169 ~119 ~87 dirt
setblock ~169 ~119 ~88 dirt
setblock ~169 ~119 ~89 dirt
setblock ~169 ~119 ~90 dirt
setblock ~169 ~119 ~91 dirt
setblock ~169 ~119 ~95 dirt
setblock ~169 ~119 ~96 dirt
setblock ~169 ~119 ~97 dirt
setblock ~169 ~119 ~98 dirt
setblock ~169 ~119 ~99 dirt
setblock ~169 ~119 ~100 dirt
setblock ~169 ~119 ~101 dirt
setblock ~169 ~119 ~102 dirt
setblock ~169 ~119 ~103 dirt
setblock ~169 ~119 ~104 dirt
setblock ~169 ~119 ~105 dirt
setblock ~169 ~119 ~106 dirt
setblock ~169 ~119 ~107 dirt
setblock ~169 ~119 ~108 dirt
setblock ~169 ~119 ~109 dirt
setblock ~169 ~119 ~110 dirt
setblock ~169 ~119 ~114 dirt
setblock ~169 ~119 ~128 dirt
setblock ~169 ~120 ~76 dirt
setblock ~169 ~120 ~77 dirt
setblock ~169 ~120 ~78 dirt
setblock ~169 ~120 ~79 dirt
setblock ~169 ~120 ~80 dirt
setblock ~169 ~120 ~81 dirt
setblock ~169 ~120 ~82 dirt
setblock ~169 ~120 ~83 dirt
setblock ~169 ~120 ~84 dirt
setblock ~169 ~120 ~85 dirt
setblock ~169 ~120 ~86 dirt
setblock ~169 ~120 ~87 dirt
setblock ~169 ~120 ~88 dirt
setblock ~169 ~120 ~89 dirt
setblock ~169 ~120 ~90 dirt
setblock ~169 ~120 ~91 dirt
setblock ~169 ~120 ~92 dirt
setblock ~169 ~120 ~94 dirt
setblock ~169 ~120 ~95 dirt
setblock ~169 ~120 ~96 dirt
setblock ~169 ~120 ~97 dirt
setblock ~169 ~120 ~98 dirt
setblock ~169 ~120 ~99 dirt
setblock ~169 ~120 ~100 dirt
setblock ~169 ~120 ~101 dirt
setblock ~169 ~120 ~102 dirt
setblock ~169 ~120 ~103 dirt
setblock ~169 ~120 ~104 dirt
setblock ~169 ~120 ~105 dirt
setblock ~169 ~120 ~106 dirt
setblock ~169 ~120 ~107 dirt
setblock ~169 ~120 ~108 dirt
setblock ~169 ~120 ~109 dirt
setblock ~169 ~120 ~110 dirt
setblock ~169 ~120 ~111 dirt
setblock ~169 ~120 ~112 dirt
setblock ~169 ~120 ~113 dirt
setblock ~169 ~120 ~114 dirt
setblock ~169 ~120 ~118 dirt
setblock ~169 ~120 ~125 dirt
setblock ~169 ~120 ~128 dirt
setblock ~169 ~120 ~129 dirt
setblock ~169 ~121 ~75 dirt
setblock ~169 ~121 ~76 dirt
setblock ~169 ~121 ~77 dirt
setblock ~169 ~121 ~78 dirt
setblock ~169 ~121 ~79 dirt
setblock ~169 ~121 ~80 dirt
setblock ~169 ~121 ~81 dirt
setblock ~169 ~121 ~82 dirt
setblock ~169 ~121 ~83 dirt
setblock ~169 ~121 ~84 dirt
setblock ~169 ~121 ~85 dirt
setblock ~169 ~121 ~86 dirt
setblock ~169 ~121 ~87 dirt
setblock ~169 ~121 ~88 dirt
setblock ~169 ~121 ~89 dirt
setblock ~169 ~121 ~90 dirt
setblock ~169 ~121 ~91 dirt
setblock ~169 ~121 ~92 dirt
setblock ~169 ~121 ~93 dirt
setblock ~169 ~121 ~94 dirt
setblock ~169 ~121 ~95 dirt
setblock ~169 ~121 ~96 dirt
setblock ~169 ~121 ~97 dirt
setblock ~169 ~121 ~98 dirt
setblock ~169 ~121 ~99 dirt
setblock ~169 ~121 ~100 dirt
setblock ~169 ~121 ~101 dirt
setblock ~169 ~121 ~102 dirt
setblock ~169 ~121 ~103 dirt
setblock ~169 ~121 ~104 dirt
setblock ~169 ~121 ~105 dirt
setblock ~169 ~121 ~106 dirt
setblock ~169 ~121 ~107 dirt
setblock ~169 ~121 ~108 dirt
setblock ~169 ~121 ~109 dirt
setblock ~169 ~121 ~110 dirt
setblock ~169 ~121 ~111 dirt
setblock ~169 ~121 ~112 dirt
setblock ~169 ~121 ~113 dirt
setblock ~169 ~121 ~114 dirt
setblock ~169 ~121 ~115 dirt
setblock ~169 ~121 ~116 dirt
setblock ~169 ~121 ~117 dirt
setblock ~169 ~121 ~118 dirt
setblock ~169 ~121 ~119 dirt
setblock ~169 ~121 ~124 dirt
setblock ~169 ~121 ~125 dirt
setblock ~169 ~121 ~126 dirt
setblock ~169 ~121 ~127 dirt
setblock ~169 ~121 ~128 dirt
setblock ~169 ~121 ~129 dirt
setblock ~169 ~121 ~130 dirt
setblock ~169 ~122 ~75 dirt
setblock ~169 ~122 ~76 dirt
setblock ~169 ~122 ~77 dirt
setblock ~169 ~122 ~78 dirt
setblock ~169 ~122 ~79 dirt
setblock ~169 ~122 ~80 dirt
setblock ~169 ~122 ~81 dirt
setblock ~169 ~122 ~82 dirt
setblock ~169 ~122 ~83 dirt
setblock ~169 ~122 ~84 dirt
setblock ~169 ~122 ~85 dirt
setblock ~169 ~122 ~86 dirt
setblock ~169 ~122 ~87 dirt
setblock ~169 ~122 ~88 dirt
setblock ~169 ~122 ~89 dirt
setblock ~169 ~122 ~90 dirt
setblock ~169 ~122 ~91 dirt
setblock ~169 ~122 ~92 dirt
setblock ~169 ~122 ~93 dirt
setblock ~169 ~122 ~94 dirt
setblock ~169 ~122 ~95 dirt
setblock ~169 ~122 ~96 dirt
setblock ~169 ~122 ~97 dirt
setblock ~169 ~122 ~98 dirt
setblock ~169 ~122 ~99 dirt
setblock ~169 ~122 ~100 dirt
setblock ~169 ~122 ~101 dirt
setblock ~169 ~122 ~102 dirt
setblock ~169 ~122 ~103 dirt
setblock ~169 ~122 ~104 dirt
setblock ~169 ~122 ~105 dirt
setblock ~169 ~122 ~106 dirt
setblock ~169 ~122 ~107 dirt
setblock ~169 ~122 ~108 dirt
setblock ~169 ~122 ~109 dirt
setblock ~169 ~122 ~110 dirt
setblock ~169 ~122 ~111 dirt
setblock ~169 ~122 ~112 dirt
setblock ~169 ~122 ~113 dirt
setblock ~169 ~122 ~114 dirt
setblock ~169 ~122 ~115 dirt
setblock ~169 ~122 ~116 dirt
setblock ~169 ~122 ~117 dirt
setblock ~169 ~122 ~118 dirt
setblock ~169 ~122 ~119 dirt
setblock ~169 ~122 ~124 dirt
setblock ~169 ~122 ~125 dirt
setblock ~169 ~122 ~126 dirt
setblock ~169 ~122 ~127 dirt
setblock ~169 ~122 ~128 dirt
setblock ~169 ~122 ~129 dirt
setblock ~169 ~122 ~130 dirt
setblock ~169 ~123 ~75 dirt
setblock ~169 ~123 ~76 dirt
setblock ~169 ~123 ~77 dirt
setblock ~169 ~123 ~78 dirt
setblock ~169 ~123 ~79 dirt
setblock ~169 ~123 ~80 dirt
setblock ~169 ~123 ~81 dirt
setblock ~169 ~123 ~82 dirt
setblock ~169 ~123 ~83 dirt
setblock ~169 ~123 ~84 dirt
setblock ~169 ~123 ~85 dirt
setblock ~169 ~123 ~86 dirt
setblock ~169 ~123 ~87 dirt
setblock ~169 ~123 ~88 dirt
setblock ~169 ~123 ~89 dirt
setblock ~169 ~123 ~90 dirt
setblock ~169 ~123 ~91 dirt
setblock ~169 ~123 ~92 dirt
setblock ~169 ~123 ~93 dirt
setblock ~169 ~123 ~94 dirt
setblock ~169 ~123 ~95 dirt
setblock ~169 ~123 ~96 dirt
setblock ~169 ~123 ~97 dirt
setblock ~169 ~123 ~98 dirt
setblock ~169 ~123 ~99 dirt
setblock ~169 ~123 ~100 dirt
setblock ~169 ~123 ~101 dirt
setblock ~169 ~123 ~102 dirt
setblock ~169 ~123 ~103 dirt
setblock ~169 ~123 ~104 dirt
setblock ~169 ~123 ~105 dirt
setblock ~169 ~123 ~106 dirt
setblock ~169 ~123 ~107 dirt
setblock ~169 ~123 ~108 dirt
setblock ~169 ~123 ~109 dirt
setblock ~169 ~123 ~110 dirt
setblock ~169 ~123 ~111 dirt
setblock ~169 ~123 ~112 dirt
setblock ~169 ~123 ~113 dirt
setblock ~169 ~123 ~114 dirt
setblock ~169 ~123 ~115 dirt
setblock ~169 ~123 ~116 dirt
setblock ~169 ~123 ~117 dirt
setblock ~169 ~123 ~118 dirt
setblock ~169 ~123 ~119 dirt
setblock ~169 ~123 ~124 dirt
setblock ~169 ~123 ~125 dirt
setblock ~169 ~123 ~126 dirt
setblock ~169 ~123 ~127 dirt
setblock ~169 ~123 ~128 dirt
setblock ~169 ~123 ~129 dirt
setblock ~169 ~123 ~130 dirt
setblock ~169 ~124 ~75 dirt
setblock ~169 ~124 ~76 dirt
setblock ~169 ~124 ~77 dirt
setblock ~169 ~124 ~78 grass_block
setblock ~169 ~124 ~79 grass_block
setblock ~169 ~124 ~80 grass_block
setblock ~169 ~124 ~81 grass_block
setblock ~169 ~124 ~82 dirt
setblock ~169 ~124 ~83 dirt
setblock ~169 ~124 ~84 dirt
setblock ~169 ~124 ~85 dirt
setblock ~169 ~124 ~86 dirt
setblock ~169 ~124 ~87 dirt
setblock ~169 ~124 ~88 dirt
setblock ~169 ~124 ~89 grass_block
setblock ~169 ~124 ~90 grass_block
setblock ~169 ~124 ~91 grass_block
setblock ~169 ~124 ~92 dirt
setblock ~169 ~124 ~93 dirt
setblock ~169 ~124 ~94 dirt
setblock ~169 ~124 ~95 dirt
setblock ~169 ~124 ~96 dirt
setblock ~169 ~124 ~97 dirt
setblock ~169 ~124 ~98 dirt
setblock ~169 ~124 ~99 dirt
setblock ~169 ~124 ~100 dirt
setblock ~169 ~124 ~101 dirt
setblock ~169 ~124 ~102 dirt
setblock ~169 ~124 ~103 dirt
setblock ~169 ~124 ~104 dirt
setblock ~169 ~124 ~105 dirt
setblock ~169 ~124 ~106 dirt
setblock ~169 ~124 ~107 dirt
setblock ~169 ~124 ~108 dirt
setblock ~169 ~124 ~109 grass_block
setblock ~169 ~124 ~110 grass_block
setblock ~169 ~124 ~111 grass_block
setblock ~169 ~124 ~112 grass_block
setblock ~169 ~124 ~113 grass_block
setblock ~169 ~124 ~114 grass_block
setblock ~169 ~124 ~115 grass_block
setblock ~169 ~124 ~116 grass_block
setblock ~169 ~124 ~117 grass_block
setblock ~169 ~124 ~118 grass_block
setblock ~169 ~124 ~119 grass_block
setblock ~169 ~124 ~124 dirt
setblock ~169 ~124 ~125 dirt
setblock ~169 ~124 ~126 dirt
setblock ~169 ~124 ~127 dirt
setblock ~169 ~124 ~128 dirt
setblock ~169 ~124 ~129 dirt
setblock ~169 ~124 ~130 dirt
setblock ~169 ~125 ~75 grass_block
setblock ~169 ~125 ~76 grass_block
setblock ~169 ~125 ~77 grass_block
setblock ~169 ~125 ~78 short_grass
setblock ~169 ~125 ~79 short_grass
setblock ~169 ~125 ~80 short_grass
setblock ~169 ~125 ~82 grass_block
setblock ~169 ~125 ~83 grass_block
setblock ~169 ~125 ~84 grass_block
setblock ~169 ~125 ~85 grass_block
setblock ~169 ~125 ~86 grass_block
setblock ~169 ~125 ~87 grass_block
setblock ~169 ~125 ~88 grass_block
setblock ~169 ~125 ~92 grass_block
setblock ~169 ~125 ~93 grass_block
setblock ~169 ~125 ~94 grass_block
setblock ~169 ~125 ~95 grass_block
setblock ~169 ~125 ~96 dirt
setblock ~169 ~125 ~97 dirt
setblock ~169 ~125 ~98 dirt
setblock ~169 ~125 ~99 dirt
setblock ~169 ~125 ~100 dirt
setblock ~169 ~125 ~101 dirt
setblock ~169 ~125 ~102 dirt
setblock ~169 ~125 ~103 dirt
setblock ~169 ~125 ~104 dirt
setblock ~169 ~125 ~105 dirt
setblock ~169 ~125 ~106 grass_block
setblock ~169 ~125 ~107 grass_block
setblock ~169 ~125 ~108 grass_block
setblock ~169 ~125 ~109 short_grass
setblock ~169 ~125 ~115 poppy
setblock ~169 ~125 ~116 poppy
setblock ~169 ~125 ~119 short_grass
setblock ~169 ~125 ~124 dirt
setblock ~169 ~125 ~125 dirt
setblock ~169 ~125 ~126 dirt
setblock ~169 ~125 ~127 dirt
setblock ~169 ~125 ~128 dirt
setblock ~169 ~125 ~129 dirt
setblock ~169 ~125 ~130 dirt
setblock ~169 ~126 ~75 short_grass
setblock ~169 ~126 ~83 fern
setblock ~169 ~126 ~93 fern
setblock ~169 ~126 ~96 grass_block
setblock ~169 ~126 ~97 grass_block
setblock ~169 ~126 ~98 grass_block
setblock ~169 ~126 ~99 grass_block
setblock ~169 ~126 ~100 dirt
setblock ~169 ~126 ~101 dirt
setblock ~169 ~126 ~102 grass_block
setblock ~169 ~126 ~103 grass_block
setblock ~169 ~126 ~104 grass_block
setblock ~169 ~126 ~105 grass_block
setblock ~169 ~126 ~108 short_grass
setblock ~169 ~126 ~124 grass_block
setblock ~169 ~126 ~125 grass_block
setblock ~169 ~126 ~126 grass_block
setblock ~169 ~126 ~127 grass_block
setblock ~169 ~126 ~128 grass_block
setblock ~169 ~126 ~129 grass_block
setblock ~169 ~126 ~130 grass_block
setblock ~169 ~127 ~98 short_grass
setblock ~169 ~127 ~99 short_grass
setblock ~169 ~127 ~100 grass_block
setblock ~169 ~127 ~101 grass_block
setblock ~169 ~127 ~103 short_grass
setblock ~169 ~127 ~104 fern
setblock ~169 ~127 ~105 short_grass
setblock ~169 ~128 ~100 short_grass
setblock ~170 ~114 ~99 dirt
setblock ~170 ~115 ~98 dirt
setblock ~170 ~115 ~99 dirt
setblock ~170 ~115 ~100 dirt
setblock ~170 ~115 ~101 dirt
setblock ~170 ~115 ~103 dirt
setblock ~170 ~116 ~78 dirt
setblock ~170 ~116 ~79 dirt
setblock ~170 ~116 ~80 dirt
setblock ~170 ~116 ~82 dirt
setblock ~170 ~116 ~98 dirt
setblock ~170 ~116 ~99 dirt
setblock ~170 ~116 ~100 dirt
setblock ~170 ~116 ~101 dirt
setblock ~170 ~116 ~102 dirt
setblock ~170 ~116 ~103 dirt
setblock ~170 ~117 ~78 dirt
setblock ~170 ~117 ~79 dirt
setblock ~170 ~117 ~80 dirt
setblock ~170 ~117 ~81 dirt
setblock ~170 ~117 ~82 dirt
setblock ~170 ~117 ~83 dirt
setblock ~170 ~117 ~98 dirt
setblock ~170 ~117 ~99 dirt
setblock ~170 ~117 ~100 dirt
setblock ~170 ~117 ~101 dirt
setblock ~170 ~117 ~102 dirt
setblock ~170 ~117 ~103 dirt
setblock ~170 ~118 ~77 dirt
setblock ~170 ~118 ~78 dirt
setblock ~170 ~118 ~79 dirt
setblock ~170 ~118 ~80 dirt
setblock ~170 ~118 ~81 dirt
setblock ~170 ~118 ~82 dirt
setblock ~170 ~118 ~83 dirt
setblock ~170 ~118 ~84 dirt
setblock ~170 ~118 ~97 dirt
setblock ~170 ~118 ~98 dirt
setblock ~170 ~118 ~99 dirt
setblock ~170 ~118 ~100 dirt
setblock ~170 ~118 ~101 dirt
setblock ~170 ~118 ~102 dirt
setblock ~170 ~118 ~103 dirt
setblock ~170 ~118 ~104 dirt
setblock ~170 ~118 ~105 dirt
setblock ~170 ~118 ~106 dirt
setblock ~170 ~119 ~77 dirt
setblock ~170 ~119 ~78 dirt
setblock ~170 ~119 ~79 dirt
setblock ~170 ~119 ~80 dirt
setblock ~170 ~119 ~81 dirt
setblock ~170 ~119 ~82 dirt
setblock ~170 ~119 ~83 dirt
setblock ~170 ~119 ~84 dirt
setblock ~170 ~119 ~85 dirt
setblock ~170 ~119 ~86 dirt
setblock ~170 ~119 ~96 dirt
setblock ~170 ~119 ~97 dirt
setblock ~170 ~119 ~98 dirt
setblock ~170 ~119 ~99 dirt
setblock ~170 ~119 ~100 dirt
setblock ~170 ~119 ~101 dirt
setblock ~170 ~119 ~102 dirt
setblock ~170 ~119 ~103 dirt
setblock ~170 ~119 ~104 dirt
setblock ~170 ~119 ~105 dirt
setblock ~170 ~119 ~106 dirt
setblock ~170 ~119 ~107 dirt
setblock ~170 ~120 ~76 dirt
setblock ~170 ~120 ~77 dirt
setblock ~170 ~120 ~78 dirt
setblock ~170 ~120 ~79 dirt
setblock ~170 ~120 ~80 dirt
setblock ~170 ~120 ~81 dirt
setblock ~170 ~120 ~82 dirt
setblock ~170 ~120 ~83 dirt
setblock ~170 ~120 ~84 dirt
setblock ~170 ~120 ~85 dirt
setblock ~170 ~120 ~86 dirt
setblock ~170 ~120 ~87 dirt
setblock ~170 ~120 ~90 dirt
setblock ~170 ~120 ~95 dirt
setblock ~170 ~120 ~96 dirt
setblock ~170 ~120 ~97 dirt
setblock ~170 ~120 ~98 dirt
setblock ~170 ~120 ~99 dirt
setblock ~170 ~120 ~100 dirt
setblock ~170 ~120 ~101 dirt
setblock ~170 ~120 ~102 dirt
setblock ~170 ~120 ~103 dirt
setblock ~170 ~120 ~104 dirt
setblock ~170 ~120 ~105 dirt
setblock ~170 ~120 ~106 dirt
setblock ~170 ~120 ~107 dirt
setblock ~170 ~120 ~108 dirt
setblock ~170 ~120 ~109 dirt
setblock ~170 ~120 ~110 dirt
setblock ~170 ~121 ~75 dirt
setblock ~170 ~121 ~76 dirt
setblock ~170 ~121 ~77 dirt
setblock ~170 ~121 ~78 dirt
setblock ~170 ~121 ~79 dirt
setblock ~170 ~121 ~80 dirt
setblock ~170 ~121 ~81 dirt
setblock ~170 ~121 ~82 dirt
setblock ~170 ~121 ~83 dirt
setblock ~170 ~121 ~84 dirt
setblock ~170 ~121 ~85 dirt
setblock ~170 ~121 ~86 dirt
setblock ~170 ~121 ~87 dirt
setblock ~170 ~121 ~88 dirt
setblock ~170 ~121 ~90 dirt
setblock ~170 ~121 ~91 dirt
setblock ~170 ~121 ~95 dirt
setblock ~170 ~121 ~96 dirt
setblock ~170 ~121 ~97 dirt
setblock ~170 ~121 ~98 dirt
setblock ~170 ~121 ~99 dirt
setblock ~170 ~121 ~100 dirt
setblock ~170 ~121 ~101 dirt
setblock ~170 ~121 ~102 dirt
setblock ~170 ~121 ~103 dirt
setblock ~170 ~121 ~104 dirt
setblock ~170 ~121 ~105 dirt
setblock ~170 ~121 ~106 dirt
setblock ~170 ~121 ~107 dirt
setblock ~170 ~121 ~108 dirt
setblock ~170 ~121 ~109 dirt
setblock ~170 ~121 ~110 dirt
setblock ~170 ~121 ~111 dirt
setblock ~170 ~121 ~113 dirt
setblock ~170 ~121 ~118 dirt
setblock ~170 ~121 ~125 dirt
setblock ~170 ~122 ~75 dirt
setblock ~170 ~122 ~76 dirt
setblock ~170 ~122 ~77 dirt
setblock ~170 ~122 ~78 dirt
setblock ~170 ~122 ~79 dirt
setblock ~170 ~122 ~80 dirt
setblock ~170 ~122 ~81 dirt
setblock ~170 ~122 ~82 dirt
setblock ~170 ~122 ~83 dirt
setblock ~170 ~122 ~84 dirt
setblock ~170 ~122 ~85 dirt
setblock ~170 ~122 ~86 dirt
setblock ~170 ~122 ~87 dirt
setblock ~170 ~122 ~88 dirt
setblock ~170 ~122 ~90 dirt
setblock ~170 ~122 ~91 dirt
setblock ~170 ~122 ~95 dirt
setblock ~170 ~122 ~96 dirt
setblock ~170 ~122 ~97 dirt
setblock ~170 ~122 ~98 dirt
setblock ~170 ~122 ~99 dirt
setblock ~170 ~122 ~100 dirt
setblock ~170 ~122 ~101 dirt
setblock ~170 ~122 ~102 dirt
setblock ~170 ~122 ~103 dirt
setblock ~170 ~122 ~104 dirt
setblock ~170 ~122 ~105 dirt
setblock ~170 ~122 ~106 dirt
setblock ~170 ~122 ~107 dirt
setblock ~170 ~122 ~108 dirt
setblock ~170 ~122 ~109 dirt
setblock ~170 ~122 ~110 dirt
setblock ~170 ~122 ~111 dirt
setblock ~170 ~122 ~113 dirt
setblock ~170 ~122 ~118 dirt
setblock ~170 ~122 ~125 dirt
setblock ~170 ~123 ~75 dirt
setblock ~170 ~123 ~76 dirt
setblock ~170 ~123 ~77 dirt
setblock ~170 ~123 ~78 dirt
setblock ~170 ~123 ~79 dirt
setblock ~170 ~123 ~80 dirt
setblock ~170 ~123 ~81 dirt
setblock ~170 ~123 ~82 dirt
setblock ~170 ~123 ~83 dirt
setblock ~170 ~123 ~84 dirt
setblock ~170 ~123 ~85 dirt
setblock ~170 ~123 ~86 dirt
setblock ~170 ~123 ~87 dirt
setblock ~170 ~123 ~88 dirt
setblock ~170 ~123 ~90 dirt
setblock ~170 ~123 ~91 dirt
setblock ~170 ~123 ~95 dirt
setblock ~170 ~123 ~96 dirt
setblock ~170 ~123 ~97 dirt
setblock ~170 ~123 ~98 dirt
setblock ~170 ~123 ~99 dirt
setblock ~170 ~123 ~100 dirt
setblock ~170 ~123 ~101 dirt
setblock ~170 ~123 ~102 dirt
setblock ~170 ~123 ~103 dirt
setblock ~170 ~123 ~104 dirt
setblock ~170 ~123 ~105 dirt
setblock ~170 ~123 ~106 dirt
setblock ~170 ~123 ~107 dirt
setblock ~170 ~123 ~108 dirt
setblock ~170 ~123 ~109 dirt
setblock ~170 ~123 ~110 grass_block
setblock ~170 ~123 ~111 dirt
setblock ~170 ~123 ~113 dirt
setblock ~170 ~123 ~118 dirt
setblock ~170 ~123 ~125 dirt
setblock ~170 ~124 ~75 dirt
setblock ~170 ~124 ~76 dirt
setblock ~170 ~124 ~77 dirt
setblock ~170 ~124 ~78 grass_block
setblock ~170 ~124 ~79 grass_block
setblock ~170 ~124 ~80 grass_block
setblock ~170 ~124 ~81 grass_block
setblock ~170 ~124 ~82 dirt
setblock ~170 ~124 ~83 dirt
setblock ~170 ~124 ~84 dirt
setblock ~170 ~124 ~85 dirt
setblock ~170 ~124 ~86 dirt
setblock ~170 ~124 ~87 dirt
setblock ~170 ~124 ~88 grass_block
setblock ~170 ~124 ~90 grass_block
setblock ~170 ~124 ~91 grass_block
setblock ~170 ~124 ~95 dirt
setblock ~170 ~124 ~96 dirt
setblock ~170 ~124 ~97 dirt
setblock ~170 ~124 ~98 dirt
setblock ~170 ~124 ~99 dirt
setblock ~170 ~124 ~100 dirt
setblock ~170 ~124 ~101 dirt
setblock ~170 ~124 ~102 dirt
setblock ~170 ~124 ~103 dirt
setblock ~170 ~124 ~104 dirt
setblock ~170 ~124 ~105 dirt
setblock ~170 ~124 ~106 dirt
setblock ~170 ~124 ~107 dirt
setblock ~170 ~124 ~108 grass_block
setblock ~170 ~124 ~109 grass_block
setblock ~170 ~124 ~111 grass_block
setblock ~170 ~124 ~113 grass_block
setblock ~170 ~124 ~118 grass_block
setblock ~170 ~124 ~125 dirt
setblock ~170 ~125 ~75 grass_block
setblock ~170 ~125 ~76 grass_block
setblock ~170 ~125 ~77 grass_block
setblock ~170 ~125 ~79 short_grass
setblock ~170 ~125 ~82 grass_block
setblock ~170 ~125 ~83 grass_block
setblock ~170 ~125 ~84 grass_block
setblock ~170 ~125 ~85 grass_block
setblock ~170 ~125 ~86 grass_block
setblock ~170 ~125 ~87 grass_block
setblock ~170 ~125 ~95 grass_block
setblock ~170 ~125 ~96 grass_block
setblock ~170 ~125 ~97 dirt
setblock ~170 ~125 ~98 dirt
setblock ~170 ~125 ~99 dirt
setblock ~170 ~125 ~100 dirt
setblock ~170 ~125 ~101 dirt
setblock ~170 ~125 ~102 dirt
setblock ~170 ~125 ~103 dirt
setblock ~170 ~125 ~104 dirt
setblock ~170 ~125 ~105 dirt
setblock ~170 ~125 ~106 grass_block
setblock ~170 ~125 ~107 grass_block
setblock ~170 ~125 ~108 short_grass
setblock ~170 ~125 ~111 poppy
setblock ~170 ~125 ~125 dirt
setblock ~170 ~126 ~75 short_grass
setblock ~170 ~126 ~82 short_grass
setblock ~170 ~126 ~83 fern
setblock ~170 ~126 ~84 short_grass
setblock ~170 ~126 ~87 fern
setblock ~170 ~126 ~95 fern
setblock ~170 ~126 ~97 grass_block
setblock ~170 ~126 ~98 grass_block
setblock ~170 ~126 ~99 dirt
setblock ~170 ~126 ~100 dirt
setblock ~170 ~126 ~101 dirt
setblock ~170 ~126 ~102 dirt
setblock ~170 ~126 ~103 grass_block
setblock ~170 ~126 ~104 grass_block
setblock ~170 ~126 ~105 grass_block
setblock ~170 ~126 ~125 grass_block
setblock ~170 ~127 ~99 grass_block
setblock ~170 ~127 ~100 grass_block
setblock ~170 ~127 ~101 grass_block
setblock ~170 ~127 ~102 grass_block
setblock ~170 ~127 ~125 poppy
setblock ~170 ~128 ~99 short_grass
setblock ~171 ~116 ~99 dirt
setblock ~171 ~116 ~101 dirt
setblock ~171 ~117 ~99 dirt
setblock ~171 ~117 ~100 dirt
setblock ~171 ~117 ~101 dirt
setblock ~171 ~118 ~79 dirt
setblock ~171 ~118 ~82 dirt
setblock ~171 ~118 ~83 dirt
setblock ~171 ~118 ~99 dirt
setblock ~171 ~118 ~100 dirt
setblock ~171 ~118 ~101 dirt
setblock ~171 ~118 ~102 dirt
setblock ~171 ~118 ~103 dirt
setblock ~171 ~119 ~79 dirt
setblock ~171 ~119 ~81 dirt
setblock ~171 ~119 ~82 dirt
setblock ~171 ~119 ~83 dirt
setblock ~171 ~119 ~84 dirt
setblock ~171 ~119 ~98 dirt
setblock ~171 ~119 ~99 dirt
setblock ~171 ~119 ~100 dirt
setblock ~171 ~119 ~101 dirt
setblock ~171 ~119 ~102 dirt
setblock ~171 ~119 ~103 dirt
setblock ~171 ~120 ~77 dirt
setblock ~171 ~120 ~78 dirt
setblock ~171 ~120 ~79 dirt
setblock ~171 ~120 ~80 dirt
setblock ~171 ~120 ~81 dirt
setblock ~171 ~120 ~82 dirt
setblock ~171 ~120 ~83 dirt
setblock ~171 ~120 ~84 dirt
setblock ~171 ~120 ~86 dirt
setblock ~171 ~120 ~96 dirt
setblock ~171 ~120 ~97 dirt
setblock ~171 ~120 ~98 dirt
setblock ~171 ~120 ~99 dirt
setblock ~171 ~120 ~100 dirt
setblock ~171 ~120 ~101 dirt
setblock ~171 ~120 ~102 dirt
setblock ~171 ~120 ~103 dirt
setblock ~171 ~121 ~76 dirt
setblock ~171 ~121 ~77 dirt
setblock ~171 ~121 ~78 dirt
setblock ~171 ~121 ~79 dirt
setblock ~171 ~121 ~80 dirt
setblock ~171 ~121 ~81 dirt
setblock ~171 ~121 ~82 dirt
setblock ~171 ~121 ~83 dirt
setblock ~171 ~121 ~84 dirt
setblock ~171 ~121 ~85 dirt
setblock ~171 ~121 ~86 dirt
setblock ~171 ~121 ~87 dirt
setblock ~171 ~121 ~96 dirt
setblock ~171 ~121 ~97 dirt
setblock ~171 ~121 ~98 dirt
setblock ~171 ~121 ~99 dirt
setblock ~171 ~121 ~100 dirt
setblock ~171 ~121 ~101 dirt
setblock ~171 ~121 ~102 dirt
setblock ~171 ~121 ~103 dirt
setblock ~171 ~121 ~104 dirt
setblock ~171 ~121 ~105 dirt
setblock ~171 ~121 ~107 dirt
setblock ~171 ~121 ~110 dirt
setblock ~171 ~122 ~76 dirt
setblock ~171 ~122 ~77 dirt
setblock ~171 ~122 ~78 dirt
setblock ~171 ~122 ~79 dirt
setblock ~171 ~122 ~80 dirt
setblock ~171 ~122 ~81 dirt
setblock ~171 ~122 ~82 dirt
setblock ~171 ~122 ~83 dirt
setblock ~171 ~122 ~84 dirt
setblock ~171 ~122 ~85 dirt
setblock ~171 ~122 ~86 dirt
setblock ~171 ~122 ~87 dirt
setblock ~171 ~122 ~96 dirt
setblock ~171 ~122 ~97 dirt
setblock ~171 ~122 ~98 dirt
setblock ~171 ~122 ~99 dirt
setblock ~171 ~122 ~100 dirt
setblock ~171 ~122 ~101 dirt
setblock ~171 ~122 ~102 dirt
setblock ~171 ~122 ~103 dirt
setblock ~171 ~122 ~104 dirt
setblock ~171 ~122 ~105 dirt
setblock ~171 ~122 ~107 dirt
setblock ~171 ~122 ~110 dirt
setblock ~171 ~123 ~76 dirt
setblock ~171 ~123 ~77 dirt
setblock ~171 ~123 ~78 dirt
setblock ~171 ~123 ~79 dirt
setblock ~171 ~123 ~80 dirt
setblock ~171 ~123 ~81 dirt
setblock ~171 ~123 ~82 dirt
setblock ~171 ~123 ~83 dirt
setblock ~171 ~123 ~84 dirt
setblock ~171 ~123 ~85 dirt
setblock ~171 ~123 ~86 dirt
setblock ~171 ~123 ~87 dirt
setblock ~171 ~123 ~96 dirt
setblock ~171 ~123 ~97 dirt
setblock ~171 ~123 ~98 dirt
setblock ~171 ~123 ~99 dirt
setblock ~171 ~123 ~100 dirt
setblock ~171 ~123 ~101 dirt
setblock ~171 ~123 ~102 dirt
setblock ~171 ~123 ~103 dirt
setblock ~171 ~123 ~104 dirt
setblock ~171 ~123 ~105 dirt
setblock ~171 ~123 ~107 dirt
setblock ~171 ~123 ~110 dirt
setblock ~171 ~124 ~76 dirt
setblock ~171 ~124 ~77 dirt
setblock ~171 ~124 ~78 grass_block
setblock ~171 ~124 ~79 grass_block
setblock ~171 ~124 ~80 grass_block
setblock ~171 ~124 ~81 grass_block
setblock ~171 ~124 ~82 dirt
setblock ~171 ~124 ~83 dirt
setblock ~171 ~124 ~84 dirt
setblock ~171 ~124 ~85 dirt
setblock ~171 ~124 ~86 dirt
setblock ~171 ~124 ~87 dirt
setblock ~171 ~124 ~96 dirt
setblock ~171 ~124 ~97 dirt
setblock ~171 ~124 ~98 dirt
setblock ~171 ~124 ~99 dirt
setblock ~171 ~124 ~100 dirt
setblock ~171 ~124 ~101 dirt
setblock ~171 ~124 ~102 dirt
setblock ~171 ~124 ~103 dirt
setblock ~171 ~124 ~104 dirt
setblock ~171 ~124 ~105 dirt
setblock ~171 ~124 ~107 dirt
setblock ~171 ~124 ~110 grass_block
setblock ~171 ~125 ~76 grass_block
setblock ~171 ~125 ~77 grass_block
setblock ~171 ~125 ~79 short_grass
setblock ~171 ~125 ~80 short_grass
setblock ~171 ~125 ~81 short_grass
setblock ~171 ~125 ~82 grass_block
setblock ~171 ~125 ~83 grass_block
setblock ~171 ~125 ~84 grass_block
setblock ~171 ~125 ~85 grass_block
setblock ~171 ~125 ~86 grass_block
setblock ~171 ~125 ~87 grass_block
setblock ~171 ~125 ~96 grass_block
setblock ~171 ~125 ~97 dirt
setblock ~171 ~125 ~98 dirt
setblock ~171 ~125 ~99 dirt
setblock ~171 ~125 ~100 dirt
setblock ~171 ~125 ~101 dirt
setblock ~171 ~125 ~102 dirt
setblock ~171 ~125 ~103 dirt
setblock ~171 ~125 ~104 dirt
setblock ~171 ~125 ~105 dirt
setblock ~171 ~125 ~107 grass_block
setblock ~171 ~126 ~82 short_grass
setblock ~171 ~126 ~84 short_grass
setblock ~171 ~126 ~87 short_grass
setblock ~171 ~126 ~97 grass_block
setblock ~171 ~126 ~98 grass_block
setblock ~171 ~126 ~99 dirt
setblock ~171 ~126 ~100 dirt
setblock ~171 ~126 ~101 dirt
setblock ~171 ~126 ~102 dirt
setblock ~171 ~126 ~103 grass_block
setblock ~171 ~126 ~104 grass_block
setblock ~171 ~126 ~105 grass_block
setblock ~171 ~126 ~107 short_grass
setblock ~171 ~127 ~97 short_grass
setblock ~171 ~127 ~99 grass_block
setblock ~171 ~127 ~100 grass_block
setblock ~171 ~127 ~101 grass_block
setblock ~171 ~127 ~102 grass_block
setblock ~171 ~128 ~99 poppy
setblock ~172 ~119 ~101 dirt
setblock ~172 ~119 ~102 dirt
setblock ~172 ~120 ~79 dirt
setblock ~172 ~120 ~81 dirt
setblock ~172 ~120 ~82 dirt
setblock ~172 ~120 ~98 dirt
setblock ~172 ~120 ~99 dirt
setblock ~172 ~120 ~100 dirt
setblock ~172 ~120 ~101 dirt
setblock ~172 ~120 ~102 dirt
setblock ~172 ~121 ~78 dirt
setblock ~172 ~121 ~79 dirt
setblock ~172 ~121 ~80 dirt
setblock ~172 ~121 ~81 dirt
setblock ~172 ~121 ~82 dirt
setblock ~172 ~121 ~83 dirt
setblock ~172 ~121 ~86 dirt
setblock ~172 ~121 ~97 dirt
setblock ~172 ~121 ~98 dirt
setblock ~172 ~121 ~99 dirt
setblock ~172 ~121 ~100 dirt
setblock ~172 ~121 ~101 dirt
setblock ~172 ~121 ~102 dirt
setblock ~172 ~122 ~78 dirt
setblock ~172 ~122 ~79 dirt
setblock ~172 ~122 ~80 dirt
setblock ~172 ~122 ~81 dirt
setblock ~172 ~122 ~82 dirt
setblock ~172 ~122 ~83 dirt
setblock ~172 ~122 ~86 dirt
setblock ~172 ~122 ~97 dirt
setblock ~172 ~122 ~98 dirt
setblock ~172 ~122 ~99 dirt
setblock ~172 ~122 ~100 dirt
setblock ~172 ~122 ~101 dirt
setblock ~172 ~122 ~102 dirt
setblock ~172 ~123 ~78 dirt
setblock ~172 ~123 ~79 dirt
setblock ~172 ~123 ~80 dirt
setblock ~172 ~123 ~81 dirt
setblock ~172 ~123 ~82 dirt
setblock ~172 ~123 ~83 dirt
setblock ~172 ~123 ~86 dirt
setblock ~172 ~123 ~97 dirt
setblock ~172 ~123 ~98 dirt
setblock ~172 ~123 ~99 dirt
setblock ~172 ~123 ~100 dirt
setblock ~172 ~123 ~101 dirt
setblock ~172 ~123 ~102 dirt
setblock ~172 ~124 ~78 grass_block
setblock ~172 ~124 ~79 grass_block
setblock ~172 ~124 ~80 grass_block
setblock ~172 ~124 ~81 grass_block
setblock ~172 ~124 ~82 dirt
setblock ~172 ~124 ~83 dirt
setblock ~172 ~124 ~86 dirt
setblock ~172 ~124 ~97 dirt
setblock ~172 ~124 ~98 dirt
setblock ~172 ~124 ~99 dirt
setblock ~172 ~124 ~100 dirt
setblock ~172 ~124 ~101 dirt
setblock ~172 ~124 ~102 dirt
setblock ~172 ~125 ~80 short_grass
setblock ~172 ~125 ~82 grass_block
setblock ~172 ~125 ~83 grass_block
setblock ~172 ~125 ~86 grass_block
setblock ~172 ~125 ~97 dirt
setblock ~172 ~125 ~98 dirt
setblock ~172 ~125 ~99 dirt
setblock ~172 ~125 ~100 dirt
setblock ~172 ~125 ~101 dirt
setblock ~172 ~125 ~102 dirt
setblock ~172 ~126 ~82 fern
setblock ~172 ~126 ~97 grass_block
setblock ~172 ~126 ~98 grass_block
setblock ~172 ~126 ~99 dirt
setblock ~172 ~126 ~100 dirt
setblock ~172 ~126 ~101 dirt
setblock ~172 ~126 ~102 dirt
setblock ~172 ~127 ~97 short_grass
setblock ~172 ~127 ~99 grass_block
setblock ~172 ~127 ~100 grass_block
setblock ~172 ~127 ~101 grass_block
setblock ~172 ~127 ~102 grass_block
setblock ~172 ~128 ~99 short_grass
setblock ~173 ~120 ~101 dirt
setblock ~173 ~121 ~79 dirt
setblock ~173 ~121 ~98 dirt
setblock ~173 ~121 ~101 dirt
setblock ~173 ~122 ~79 dirt
setblock ~173 ~122 ~98 dirt
setblock ~173 ~122 ~101 dirt
setblock ~173 ~123 ~79 dirt
setblock ~173 ~123 ~98 dirt
setblock ~173 ~123 ~101 dirt
setblock ~173 ~124 ~79 grass_block
setblock ~173 ~124 ~98 dirt
setblock ~173 ~124 ~101 dirt
setblock ~173 ~125 ~98 dirt
setblock ~173 ~125 ~101 dirt
setblock ~173 ~126 ~98 grass_block
setblock ~173 ~126 ~101 dirt
setblock ~173 ~127 ~101 grass_block
setblock ~199 ~200 ~199 gold_block
