setblock ~169 ~118 ~110 dirt
setblock ~169 ~119 ~82 dirt
setblock ~169 ~119 ~83 dirt
setblock ~169 ~119 ~84 dirt
setblock ~169 ~119 ~85 dirt
setblock ~169 ~119 ~86 dirt
setblock ~169 ~119 ~87 dirt
setblock ~169 ~119 ~88 dirt
setblock ~169 ~119 ~89 dirt
setblock ~169 ~119 ~90 dirt
setblock ~169 ~119 ~91 dirt
setblock ~169 ~119 ~92 dirt
setblock ~169 ~119 ~93 dirt
setblock ~169 ~119 ~94 dirt
setblock ~169 ~119 ~95 dirt
setblock ~169 ~119 ~96 dirt
setblock ~169 ~119 ~97 dirt
setblock ~169 ~119 ~98 dirt
setblock ~169 ~119 ~99 dirt
setblock ~169 ~119 ~100 dirt
setblock ~169 ~119 ~101 dirt
setblock ~169 ~119 ~102 dirt
setblock ~169 ~119 ~103 dirt
setblock ~169 ~119 ~104 dirt
setblock ~169 ~119 ~105 dirt
setblock ~169 ~119 ~106 dirt
setblock ~169 ~119 ~107 dirt
setblock ~169 ~119 ~108 dirt
setblock ~169 ~119 ~109 dirt
setblock ~169 ~119 ~110 dirt
setblock ~169 ~119 ~117 dirt
setblock ~169 ~119 ~122 dirt
setblock ~169 ~120 ~81 dirt
setblock ~169 ~120 ~82 dirt
setblock ~169 ~120 ~83 dirt
setblock ~169 ~120 ~84 dirt
setblock ~169 ~120 ~85 dirt
setblock ~169 ~120 ~86 dirt
setblock ~169 ~120 ~87 dirt
setblock ~169 ~120 ~88 dirt
setblock ~169 ~120 ~89 dirt
setblock ~169 ~120 ~90 dirt
setblock ~169 ~120 ~91 dirt
setblock ~169 ~120 ~92 dirt
setblock ~169 ~120 ~93 dirt
setblock ~169 ~120 ~94 dirt
setblock ~169 ~120 ~95 dirt
setblock ~169 ~120 ~96 dirt
setblock ~169 ~120 ~97 dirt
setblock ~169 ~120 ~98 dirt
setblock ~169 ~120 ~99 dirt
setblock ~169 ~120 ~100 dirt
setblock ~169 ~120 ~101 dirt
setblock ~169 ~120 ~102 dirt
setblock ~169 ~120 ~103 dirt
setblock ~169 ~120 ~104 dirt
setblock ~169 ~120 ~105 dirt
setblock ~169 ~120 ~106 dirt
setblock ~169 ~120 ~107 dirt
setblock ~169 ~120 ~108 dirt
setblock ~169 ~120 ~109 dirt
setblock ~169 ~120 ~110 dirt
setblock ~169 ~120 ~111 dirt
setblock ~169 ~120 ~117 dirt
setblock ~169 ~120 ~121 dirt
setblock ~169 ~120 ~122 dirt
setblock ~169 ~120 ~123 dirt
setblock ~169 ~120 ~126 dirt
setblock ~169 ~121 ~81 dirt
setblock ~169 ~121 ~82 dirt
setblock ~169 ~121 ~83 dirt
setblock ~169 ~121 ~84 dirt
setblock ~169 ~121 ~85 dirt
setblock ~169 ~121 ~86 dirt
setblock ~169 ~121 ~87 dirt
setblock ~169 ~121 ~88 dirt
setblock ~169 ~121 ~89 dirt
setblock ~169 ~121 ~90 dirt
setblock ~169 ~121 ~91 dirt
setblock ~169 ~121 ~92 dirt
setblock ~169 ~121 ~93 dirt
setblock ~169 ~121 ~94 dirt
setblock ~169 ~121 ~95 dirt
setblock ~169 ~121 ~96 dirt
setblock ~169 ~121 ~97 dirt
setblock ~169 ~121 ~98 dirt
setblock ~169 ~121 ~99 dirt
setblock ~169 ~121 ~100 dirt
setblock ~169 ~121 ~101 dirt
setblock ~169 ~121 ~102 dirt
setblock ~169 ~121 ~103 dirt
setblock ~169 ~121 ~104 dirt
setblock ~169 ~121 ~105 dirt
setblock ~169 ~121 ~106 dirt
setblock ~169 ~121 ~107 dirt
setblock ~169 ~121 ~108 dirt
setblock ~169 ~121 ~109 dirt
setblock ~169 ~121 ~110 dirt
setblock ~169 ~121 ~111 dirt
setblock ~169 ~121 ~112 dirt
setblock ~169 ~121 ~114 dirt
setblock ~169 ~121 ~116 dirt
setblock ~169 ~121 ~117 dirt
setblock ~169 ~121 ~118 dirt
setblock ~169 ~121 ~120 dirt
setblock ~169 ~121 ~121 dirt
setblock ~169 ~121 ~122 dirt
setblock ~169 ~121 ~123 dirt
setblock ~169 ~121 ~124 dirt
setblock ~169 ~121 ~126 dirt
setblock ~169 ~122 ~81 dirt
setblock ~169 ~122 ~82 dirt
setblock ~169 ~122 ~83 dirt
setblock ~169 ~122 ~84 dirt
setblock ~169 ~122 ~85 dirt
setblock ~169 ~122 ~86 dirt
setblock ~169 ~122 ~87 dirt
setblock ~169 ~122 ~88 dirt
setblock ~169 ~122 ~89 dirt
setblock ~169 ~122 ~90 dirt
setblock ~169 ~122 ~91 dirt
setblock ~169 ~122 ~92 dirt
setblock ~169 ~122 ~93 dirt
setblock ~169 ~122 ~94 dirt
setblock ~169 ~122 ~95 dirt
setblock ~169 ~122 ~96 dirt
setblock ~169 ~122 ~97 dirt
setblock ~169 ~122 ~98 dirt
setblock ~169 ~122 ~99 dirt
setblock ~169 ~122 ~100 dirt
setblock ~169 ~122 ~101 dirt
setblock ~169 ~122 ~102 dirt
setblock ~169 ~122 ~103 dirt
setblock ~169 ~122 ~104 dirt
setblock ~169 ~122 ~105 dirt
setblock ~169 ~122 ~106 dirt
setblock ~169 ~122 ~107 dirt
setblock ~169 ~122 ~108 dirt
setblock ~169 ~122 ~109 dirt
setblock ~169 ~122 ~110 dirt
setblock ~169 ~122 ~111 dirt
setblock ~169 ~122 ~112 dirt
setblock ~169 ~122 ~114 dirt
setblock ~169 ~122 ~116 dirt
setblock ~169 ~122 ~117 dirt
setblock ~169 ~122 ~118 dirt
setblock ~169 ~122 ~120 dirt
setblock ~169 ~122 ~121 dirt
setblock ~169 ~122 ~122 dirt
setblock ~169 ~122 ~123 dirt
setblock ~169 ~122 ~124 dirt
setblock ~169 ~122 ~126 dirt
setblock ~169 ~123 ~81 dirt
setblock ~169 ~123 ~82 dirt
setblock ~169 ~123 ~83 dirt
setblock ~169 ~123 ~84 dirt
setblock ~169 ~123 ~85 dirt
setblock ~169 ~123 ~86 dirt
setblock ~169 ~123 ~87 dirt
setblock ~169 ~123 ~88 dirt
setblock ~169 ~123 ~89 dirt
setblock ~169 ~123 ~90 dirt
setblock ~169 ~123 ~91 dirt
setblock ~169 ~123 ~92 dirt
setblock ~169 ~123 ~93 dirt
setblock ~169 ~123 ~94 dirt
setblock ~169 ~123 ~95 dirt
setblock ~169 ~123 ~96 dirt
setblock ~169 ~123 ~97 dirt
setblock ~169 ~123 ~98 dirt
setblock ~169 ~123 ~99 dirt
setblock ~169 ~123 ~100 dirt
setblock ~169 ~123 ~101 dirt
setblock ~169 ~123 ~102 dirt
setblock ~169 ~123 ~103 dirt
setblock ~169 ~123 ~104 dirt
setblock ~169 ~123 ~105 dirt
setblock ~169 ~123 ~106 dirt
setblock ~169 ~123 ~107 dirt
setblock ~169 ~123 ~108 grass_block
setblock ~169 ~123 ~109 grass_block
setblock ~169 ~123 ~110 grass_block
setblock ~169 ~123 ~111 grass_block
setblock ~169 ~123 ~112 grass_block
setblock ~169 ~123 ~114 grass_block
setblock ~169 ~123 ~116 grass_block
setblock ~169 ~123 ~117 grass_block
setblock ~169 ~123 ~118 grass_block
setblock ~169 ~123 ~120 grass_block
setblock ~169 ~123 ~121 grass_block
setblock ~169 ~123 ~122 grass_block
setblock ~169 ~123 ~123 grass_block
setblock ~169 ~123 ~124 grass_block
setblock ~169 ~123 ~126 grass_block
setblock ~169 ~124 ~81 grass_block
setblock ~169 ~124 ~82 grass_block
setblock ~169 ~124 ~83 grass_block
setblock ~169 ~124 ~84 grass_block
setblock ~169 ~124 ~85 grass_block
setblock ~169 ~124 ~86 grass_block
setblock ~169 ~124 ~87 grass_block
setblock ~169 ~124 ~88 grass_block
setblock ~169 ~124 ~89 grass_block
setblock ~169 ~124 ~90 grass_block
setblock ~169 ~124 ~91 grass_block
setblock ~169 ~124 ~92 grass_block
setblock ~169 ~124 ~93 grass_block
setblock ~169 ~124 ~94 grass_block
setblock ~169 ~124 ~95 grass_block
setblock ~169 ~124 ~96 grass_block
setblock ~169 ~124 ~97 grass_block
setblock ~169 ~124 ~98 grass_block
setblock ~169 ~124 ~99 grass_block
setblock ~169 ~124 ~100 grass_block
setblock ~169 ~124 ~101 grass_block
setblock ~169 ~124 ~102 grass_block
setblock ~169 ~124 ~103 grass_block
setblock ~169 ~124 ~104 grass_block
setblock ~169 ~124 ~105 grass_block
setblock ~169 ~124 ~106 grass_block
setblock ~169 ~124 ~107 grass_block
setblock ~169 ~124 ~108 fern
setblock ~169 ~124 ~109 spruce_slab
setblock ~169 ~124 ~117 short_grass
setblock ~169 ~124 ~118 short_grass
setblock ~169 ~124 ~123 short_grass
setblock ~169 ~125 ~84 poppy
setblock ~169 ~125 ~87 short_grass
setblock ~169 ~125 ~91 short_grass
setblock ~169 ~125 ~104 short_grass
setblock ~169 ~125 ~107 short_grass
setblock ~169 ~127 ~110 oak_leaves[persistent=null]
setblock ~169 ~128 ~108 oak_leaves[persistent=null]
setblock ~169 ~128 ~109 oak_leaves[persistent=null]
setblock ~169 ~128 ~110 jungle_leaves[persistent=null]
setblock ~169 ~129 ~108 oak_leaves[persistent=null]
setblock ~169 ~129 ~109 oak_leaves[persistent=null]
setblock ~169 ~129 ~110 spruce_slab[type=null]
setblock ~169 ~130 ~107 oak_leaves[persistent=null]
setblock ~169 ~130 ~108 oak_leaves[persistent=null]
setblock ~169 ~130 ~110 oak_log
setblock ~169 ~130 ~111 oak_leaves[persistent=null]
setblock ~169 ~130 ~112 oak_leaves[persistent=null]
setblock ~169 ~130 ~113 oak_leaves[persistent=null]
setblock ~169 ~130 ~114 oak_leaves[persistent=null]
setblock ~169 ~130 ~115 oak_leaves[persistent=null]
setblock ~169 ~131 ~107 oak_leaves[persistent=null]
setblock ~169 ~131 ~108 oak_leaves[persistent=null]
setblock ~169 ~131 ~111 oak_leaves[persistent=null]
setblock ~169 ~131 ~112 oak_leaves[persistent=null]
setblock ~169 ~131 ~113 oak_leaves[persistent=null]
setblock ~169 ~131 ~114 oak_leaves[persistent=null]
setblock ~169 ~132 ~107 oak_leaves[persistent=null]
setblock ~169 ~132 ~108 oak_leaves[persistent=null]
setblock ~169 ~132 ~110 oak_leaves[persistent=null]
setblock ~169 ~132 ~111 oak_leaves[persistent=null]
setblock ~169 ~132 ~112 oak_leaves[persistent=null]
setblock ~169 ~132 ~113 oak_leaves[persistent=null]
setblock ~169 ~133 ~106 jungle_leaves[persistent=null]
setblock ~169 ~133 ~107 oak_leaves[persistent=null]
setblock ~169 ~133 ~108 oak_wood
setblock ~169 ~133 ~109 oak_wood
setblock ~169 ~133 ~110 oak_wood
setblock ~169 ~133 ~111 oak_leaves[persistent=null]
setblock ~169 ~133 ~114 oak_leaves[persistent=null]
setblock ~169 ~133 ~115 jungle_leaves[persistent=null]
setblock ~169 ~134 ~107 oak_leaves[persistent=null]
setblock ~169 ~134 ~108 oak_wood
setblock ~169 ~134 ~109 oak_leaves[persistent=null]
setblock ~169 ~134 ~110 oak_leaves[persistent=null]
setblock ~169 ~134 ~111 oak_wood
setblock ~169 ~135 ~106 jungle_leaves[persistent=null]
setblock ~169 ~135 ~108 oak_wood
setblock ~169 ~135 ~110 oak_leaves[persistent=null]
setblock ~169 ~135 ~111 oak_leaves[persistent=null]
setblock ~169 ~135 ~112 oak_leaves[persistent=null]
setblock ~169 ~135 ~113 oak_leaves[persistent=null]
setblock ~169 ~136 ~106 oak_leaves[persistent=null]
setblock ~169 ~136 ~107 jungle_leaves[persistent=null]
setblock ~169 ~136 ~108 oak_log
setblock ~169 ~136 ~112 oak_log
setblock ~169 ~136 ~113 oak_leaves[persistent=null]
setblock ~169 ~137 ~106 oak_leaves[persistent=null]
setblock ~169 ~137 ~108 oak_leaves[persistent=null]
setblock ~169 ~137 ~110 oak_leaves[persistent=null]
setblock ~169 ~137 ~111 oak_leaves[persistent=null]
setblock ~169 ~137 ~112 oak_leaves[persistent=null]
setblock ~169 ~137 ~113 oak_leaves[persistent=null]
setblock ~169 ~138 ~107 oak_leaves[persistent=null]
setblock ~169 ~138 ~109 oak_leaves[persistent=null]
setblock ~169 ~138 ~111 oak_leaves[persistent=null]
setblock ~170 ~103 ~97 dirt
setblock ~170 ~104 ~96 dirt
setblock ~170 ~104 ~97 dirt
setblock ~170 ~105 ~95 dirt
setblock ~170 ~105 ~96 dirt
setblock ~170 ~105 ~97 dirt
setblock ~170 ~105 ~98 dirt
setblock ~170 ~106 ~95 dirt
setblock ~170 ~106 ~96 dirt
setblock ~170 ~106 ~97 dirt
setblock ~170 ~106 ~98 dirt
setblock ~170 ~106 ~99 dirt
setblock ~170 ~107 ~94 dirt
setblock ~170 ~107 ~95 dirt
setblock ~170 ~107 ~96 dirt
setblock ~170 ~107 ~97 dirt
setblock ~170 ~107 ~98 dirt
setblock ~170 ~107 ~99 dirt
setblock ~170 ~108 ~94 dirt
setblock ~170 ~108 ~95 dirt
setblock ~170 ~108 ~96 dirt
setblock ~170 ~108 ~97 dirt
setblock ~170 ~108 ~98 dirt
setblock ~170 ~108 ~99 dirt
setblock ~170 ~108 ~102 dirt
setblock ~170 ~108 ~103 dirt
setblock ~170 ~109 ~93 dirt
setblock ~170 ~109 ~94 dirt
setblock ~170 ~109 ~95 dirt
setblock ~170 ~109 ~96 dirt
setblock ~170 ~109 ~97 dirt
setblock ~170 ~109 ~98 dirt
setblock ~170 ~109 ~99 dirt
setblock ~170 ~109 ~100 dirt
setblock ~170 ~109 ~101 dirt
setblock ~170 ~109 ~102 dirt
setblock ~170 ~109 ~103 dirt
setblock ~170 ~110 ~92 dirt
setblock ~170 ~110 ~93 dirt
setblock ~170 ~110 ~94 dirt
setblock ~170 ~110 ~95 dirt
setblock ~170 ~110 ~96 dirt
setblock ~170 ~110 ~97 dirt
setblock ~170 ~110 ~98 dirt
setblock ~170 ~110 ~99 dirt
setblock ~170 ~110 ~100 dirt
setblock ~170 ~110 ~101 dirt
setblock ~170 ~110 ~102 dirt
setblock ~170 ~110 ~103 dirt
setblock ~170 ~110 ~104 dirt
setblock ~170 ~111 ~90 dirt
setblock ~170 ~111 ~92 dirt
setblock ~170 ~111 ~93 dirt
setblock ~170 ~111 ~94 dirt
setblock ~170 ~111 ~95 dirt
setblock ~170 ~111 ~96 dirt
setblock ~170 ~111 ~97 dirt
setblock ~170 ~111 ~98 dirt
setblock ~170 ~111 ~99 dirt
setblock ~170 ~111 ~100 dirt
setblock ~170 ~111 ~101 dirt
setblock ~170 ~111 ~102 dirt
setblock ~170 ~111 ~103 dirt
setblock ~170 ~111 ~104 dirt
setblock ~170 ~112 ~89 dirt
setblock ~170 ~112 ~90 dirt
setblock ~170 ~112 ~91 dirt
setblock ~170 ~112 ~92 dirt
setblock ~170 ~112 ~93 dirt
setblock ~170 ~112 ~94 dirt
setblock ~170 ~112 ~95 dirt
setblock ~170 ~112 ~96 dirt
setblock ~170 ~112 ~97 dirt
setblock ~170 ~112 ~98 dirt
setblock ~170 ~112 ~99 dirt
setblock ~170 ~112 ~100 dirt
setblock ~170 ~112 ~101 dirt
setblock ~170 ~112 ~102 dirt
setblock ~170 ~112 ~103 dirt
setblock ~170 ~112 ~104 dirt
setblock ~170 ~112 ~105 dirt
setblock ~170 ~113 ~89 dirt
setblock ~170 ~113 ~90 dirt
setblock ~170 ~113 ~91 dirt
setblock ~170 ~113 ~92 dirt
setblock ~170 ~113 ~93 dirt
setblock ~170 ~113 ~94 dirt
setblock ~170 ~113 ~95 dirt
setblock ~170 ~113 ~96 dirt
setblock ~170 ~113 ~97 dirt
setblock ~170 ~113 ~98 dirt
setblock ~170 ~113 ~99 dirt
setblock ~170 ~113 ~100 dirt
setblock ~170 ~113 ~101 dirt
setblock ~170 ~113 ~102 dirt
setblock ~170 ~113 ~103 dirt
setblock ~170 ~113 ~104 dirt
setblock ~170 ~113 ~105 dirt
setblock ~170 ~113 ~106 dirt
setblock ~170 ~114 ~88 dirt
setblock ~170 ~114 ~89 dirt
setblock ~170 ~114 ~90 dirt
setblock ~170 ~114 ~91 dirt
setblock ~170 ~114 ~92 dirt
setblock ~170 ~114 ~93 dirt
setblock ~170 ~114 ~94 dirt
setblock ~170 ~114 ~95 dirt
setblock ~170 ~114 ~96 dirt
setblock ~170 ~114 ~97 dirt
setblock ~170 ~114 ~98 dirt
setblock ~170 ~114 ~99 dirt
setblock ~170 ~114 ~100 dirt
setblock ~170 ~114 ~101 dirt
setblock ~170 ~114 ~102 dirt
setblock ~170 ~114 ~103 dirt
setblock ~170 ~114 ~104 dirt
setblock ~170 ~114 ~105 dirt
setblock ~170 ~114 ~106 dirt
setblock ~170 ~114 ~107 dirt
setblock ~170 ~115 ~86 dirt
setblock ~170 ~115 ~88 dirt
setblock ~170 ~115 ~89 dirt
setblock ~170 ~115 ~90 dirt
setblock ~170 ~115 ~91 dirt
setblock ~170 ~115 ~92 dirt
setblock ~170 ~115 ~93 dirt
setblock ~170 ~115 ~94 dirt
setblock ~170 ~115 ~95 dirt
setblock ~170 ~115 ~96 dirt
setblock ~170 ~115 ~97 dirt
setblock ~170 ~115 ~98 dirt
setblock ~170 ~115 ~99 dirt
setblock ~170 ~115 ~100 dirt
setblock ~170 ~115 ~101 dirt
setblock ~170 ~115 ~102 dirt
setblock ~170 ~115 ~103 dirt
setblock ~170 ~115 ~104 dirt
setblock ~170 ~115 ~105 dirt
setblock ~170 ~115 ~106 dirt
setblock ~170 ~115 ~107 dirt
setblock ~170 ~116 ~86 dirt
setblock ~170 ~116 ~87 dirt
setblock ~170 ~116 ~88 dirt
setblock ~170 ~116 ~89 dirt
setblock ~170 ~116 ~90 dirt
setblock ~170 ~116 ~91 dirt
setblock ~170 ~116 ~92 dirt
setblock ~170 ~116 ~93 dirt
setblock ~170 ~116 ~94 dirt
setblock ~170 ~116 ~95 dirt
setblock ~170 ~116 ~96 dirt
setblock ~170 ~116 ~97 dirt
setblock ~170 ~116 ~98 dirt
setblock ~170 ~116 ~99 dirt
setblock ~170 ~116 ~100 dirt
setblock ~170 ~116 ~101 dirt
setblock ~170 ~116 ~102 dirt
setblock ~170 ~116 ~103 dirt
setblock ~170 ~116 ~104 dirt
setblock ~170 ~116 ~105 dirt
setblock ~170 ~116 ~106 dirt
setblock ~170 ~116 ~107 dirt
setblock ~170 ~117 ~85 dirt
setblock ~170 ~117 ~86 dirt
setblock ~170 ~117 ~87 dirt
setblock ~170 ~117 ~88 dirt
setblock ~170 ~117 ~89 dirt
setblock ~170 ~117 ~90 dirt
setblock ~170 ~117 ~91 dirt
setblock ~170 ~117 ~92 dirt
setblock ~170 ~117 ~93 dirt
setblock ~170 ~117 ~94 dirt
setblock ~170 ~117 ~95 dirt
setblock ~170 ~117 ~96 dirt
setblock ~170 ~117 ~97 dirt
setblock ~170 ~117 ~98 dirt
setblock ~170 ~117 ~99 dirt
setblock ~170 ~117 ~100 dirt
setblock ~170 ~117 ~101 dirt
setblock ~170 ~117 ~102 dirt
setblock ~170 ~117 ~103 dirt
setblock ~170 ~117 ~104 dirt
setblock ~170 ~117 ~105 dirt
setblock ~170 ~117 ~106 dirt
setblock ~170 ~117 ~107 dirt
setblock ~170 ~118 ~83 dirt
setblock ~170 ~118 ~85 dirt
setblock ~170 ~118 ~86 dirt
setblock ~170 ~118 ~87 dirt
setblock ~170 ~118 ~88 dirt
setblock ~170 ~118 ~89 dirt
setblock ~170 ~118 ~90 dirt
setblock ~170 ~118 ~91 dirt
setblock ~170 ~118 ~92 dirt
setblock ~170 ~118 ~93 dirt
setblock ~170 ~118 ~94 dirt
setblock ~170 ~118 ~95 dirt
setblock ~170 ~118 ~96 dirt
setblock ~170 ~118 ~97 dirt
setblock ~170 ~118 ~98 dirt
setblock ~170 ~118 ~99 dirt
setblock ~170 ~118 ~100 dirt
setblock ~170 ~118 ~101 dirt
setblock ~170 ~118 ~102 dirt
setblock ~170 ~118 ~103 dirt
setblock ~170 ~118 ~104 dirt
setblock ~170 ~118 ~105 dirt
setblock ~170 ~118 ~106 dirt
setblock ~170 ~118 ~107 dirt
setblock ~170 ~118 ~108 dirt
setblock ~170 ~119 ~82 dirt
setblock ~170 ~119 ~83 dirt
setblock ~170 ~119 ~84 dirt
setblock ~170 ~119 ~85 dirt
setblock ~170 ~119 ~86 dirt
setblock ~170 ~119 ~87 dirt
setblock ~170 ~119 ~88 dirt
setblock ~170 ~119 ~89 dirt
setblock ~170 ~119 ~90 dirt
setblock ~170 ~119 ~91 dirt
setblock ~170 ~119 ~92 dirt
setblock ~170 ~119 ~93 dirt
setblock ~170 ~119 ~94 dirt
setblock ~170 ~119 ~95 dirt
setblock ~170 ~119 ~96 dirt
setblock ~170 ~119 ~97 dirt
setblock ~170 ~119 ~98 dirt
setblock ~170 ~119 ~99 dirt
setblock ~170 ~119 ~100 dirt
setblock ~170 ~119 ~101 dirt
setblock ~170 ~119 ~102 dirt
setblock ~170 ~119 ~103 dirt
setblock ~170 ~119 ~104 dirt
setblock ~170 ~119 ~105 dirt
setblock ~170 ~119 ~106 dirt
setblock ~170 ~119 ~107 dirt
setblock ~170 ~119 ~108 dirt
setblock ~170 ~119 ~109 dirt
setblock ~170 ~120 ~82 dirt
setblock ~170 ~120 ~83 dirt
setblock ~170 ~120 ~84 dirt
setblock ~170 ~120 ~85 dirt
setblock ~170 ~120 ~86 dirt
setblock ~170 ~120 ~87 dirt
setblock ~170 ~120 ~88 dirt
setblock ~170 ~120 ~89 dirt
setblock ~170 ~120 ~90 dirt
setblock ~170 ~120 ~91 dirt
setblock ~170 ~120 ~92 dirt
setblock ~170 ~120 ~93 dirt
setblock ~170 ~120 ~94 dirt
setblock ~170 ~120 ~95 dirt
setblock ~170 ~120 ~96 dirt
setblock ~170 ~120 ~97 dirt
setblock ~170 ~120 ~98 dirt
setblock ~170 ~120 ~99 dirt
setblock ~170 ~120 ~100 dirt
setblock ~170 ~120 ~101 dirt
setblock ~170 ~120 ~102 dirt
setblock ~170 ~120 ~103 dirt
setblock ~170 ~120 ~104 dirt
setblock ~170 ~120 ~105 dirt
setblock ~170 ~120 ~106 dirt
setblock ~170 ~120 ~107 dirt
setblock ~170 ~120 ~108 dirt
setblock ~170 ~120 ~109 dirt
setblock ~170 ~120 ~110 dirt
setblock ~170 ~120 ~122 dirt
setblock ~170 ~121 ~81 dirt
setblock ~170 ~121 ~82 dirt
setblock ~170 ~121 ~83 dirt
setblock ~170 ~121 ~84 dirt
setblock ~170 ~121 ~85 dirt
setblock ~170 ~121 ~86 dirt
setblock ~170 ~121 ~87 dirt
setblock ~170 ~121 ~88 dirt
setblock ~170 ~121 ~89 dirt
setblock ~170 ~121 ~90 dirt
setblock ~170 ~121 ~91 dirt
setblock ~170 ~121 ~92 dirt
setblock ~170 ~121 ~93 dirt
setblock ~170 ~121 ~94 dirt
setblock ~170 ~121 ~95 dirt
setblock ~170 ~121 ~96 dirt
setblock ~170 ~121 ~97 dirt
setblock ~170 ~121 ~98 dirt
setblock ~170 ~121 ~99 dirt
setblock ~170 ~121 ~100 dirt
setblock ~170 ~121 ~101 dirt
setblock ~170 ~121 ~102 dirt
setblock ~170 ~121 ~103 dirt
setblock ~170 ~121 ~104 dirt
setblock ~170 ~121 ~105 dirt
setblock ~170 ~121 ~106 dirt
setblock ~170 ~121 ~107 dirt
setblock ~170 ~121 ~108 dirt
setblock ~170 ~121 ~109 dirt
setblock ~170 ~121 ~110 dirt
setblock ~170 ~121 ~111 dirt
setblock ~170 ~121 ~121 dirt
setblock ~170 ~121 ~122 dirt
setblock ~170 ~121 ~123 dirt
setblock ~170 ~122 ~81 dirt
setblock ~170 ~122 ~82 dirt
setblock ~170 ~122 ~83 dirt
setblock ~170 ~122 ~84 dirt
setblock ~170 ~122 ~85 dirt
setblock ~170 ~122 ~86 dirt
setblock ~170 ~122 ~87 dirt
setblock ~170 ~122 ~88 dirt
setblock ~170 ~122 ~89 dirt
setblock ~170 ~122 ~90 dirt
setblock ~170 ~122 ~91 dirt
setblock ~170 ~122 ~92 dirt
setblock ~170 ~122 ~93 dirt
setblock ~170 ~122 ~94 dirt
setblock ~170 ~122 ~95 dirt
setblock ~170 ~122 ~96 dirt
setblock ~170 ~122 ~97 dirt
setblock ~170 ~122 ~98 dirt
setblock ~170 ~122 ~99 dirt
setblock ~170 ~122 ~100 dirt
setblock ~170 ~122 ~101 dirt
setblock ~170 ~122 ~102 dirt
setblock ~170 ~122 ~103 dirt
setblock ~170 ~122 ~104 dirt
setblock ~170 ~122 ~105 dirt
setblock ~170 ~122 ~106 dirt
setblock ~170 ~122 ~107 dirt
setblock ~170 ~122 ~108 dirt
setblock ~170 ~122 ~109 dirt
setblock ~170 ~122 ~110 dirt
setblock ~170 ~122 ~111 dirt
setblock ~170 ~122 ~121 dirt
setblock ~170 ~122 ~122 dirt
setblock ~170 ~122 ~123 dirt
setblock ~170 ~123 ~81 dirt
setblock ~170 ~123 ~82 dirt
setblock ~170 ~123 ~83 dirt
setblock ~170 ~123 ~84 dirt
setblock ~170 ~123 ~85 dirt
setblock ~170 ~123 ~86 dirt
setblock ~170 ~123 ~87 dirt
setblock ~170 ~123 ~88 dirt
setblock ~170 ~123 ~89 dirt
setblock ~170 ~123 ~90 dirt
setblock ~170 ~123 ~91 dirt
setblock ~170 ~123 ~92 dirt
setblock ~170 ~123 ~93 dirt
setblock ~170 ~123 ~94 dirt
setblock ~170 ~123 ~95 dirt
setblock ~170 ~123 ~96 dirt
setblock ~170 ~123 ~97 dirt
setblock ~170 ~123 ~98 dirt
setblock ~170 ~123 ~99 dirt
setblock ~170 ~123 ~100 dirt
setblock ~170 ~123 ~101 dirt
setblock ~170 ~123 ~102 dirt
setblock ~170 ~123 ~103 dirt
setblock ~170 ~123 ~104 dirt
setblock ~170 ~123 ~105 dirt
setblock ~170 ~123 ~106 grass_block
setblock ~170 ~123 ~107 grass_block
setblock ~170 ~123 ~108 grass_block
setblock ~170 ~123 ~109 grass_block
setblock ~170 ~123 ~110 grass_block
setblock ~170 ~123 ~111 grass_block
setblock ~170 ~123 ~121 grass_block
setblock ~170 ~123 ~122 grass_block
setblock ~170 ~123 ~123 grass_block
setblock ~170 ~124 ~81 grass_block
setblock ~170 ~124 ~82 grass_block
setblock ~170 ~124 ~83 grass_block
setblock ~170 ~124 ~84 grass_block
setblock ~170 ~124 ~85 grass_block
setblock ~170 ~124 ~86 grass_block
setblock ~170 ~124 ~87 grass_block
setblock ~170 ~124 ~88 grass_block
setblock ~170 ~124 ~89 grass_block
setblock ~170 ~124 ~90 grass_block
setblock ~170 ~124 ~91 grass_block
setblock ~170 ~124 ~92 grass_block
setblock ~170 ~124 ~93 grass_block
setblock ~170 ~124 ~94 grass_block
setblock ~170 ~124 ~95 grass_block
setblock ~170 ~124 ~96 grass_block
setblock ~170 ~124 ~97 grass_block
setblock ~170 ~124 ~98 grass_block
setblock ~170 ~124 ~99 grass_block
setblock ~170 ~124 ~100 grass_block
setblock ~170 ~124 ~101 grass_block
setblock ~170 ~124 ~102 grass_block
setblock ~170 ~124 ~103 grass_block
setblock ~170 ~124 ~104 grass_block
setblock ~170 ~124 ~105 grass_block
setblock ~170 ~124 ~108 spruce_slab
setblock ~170 ~124 ~109 oak_log
setblock ~170 ~124 ~110 poppy
setblock ~170 ~124 ~111 short_grass
setblock ~170 ~125 ~84 poppy
setblock ~170 ~125 ~85 short_grass
setblock ~170 ~125 ~90 poppy
setblock ~170 ~125 ~93 fern
setblock ~170 ~125 ~95 short_grass
setblock ~170 ~125 ~99 poppy
setblock ~170 ~125 ~109 oak_log
setblock ~170 ~126 ~109 oak_log
setblock ~170 ~127 ~109 oak_log
setblock ~170 ~128 ~109 oak_log
setblock ~170 ~128 ~110 spruce_slab[type=null]
setblock ~170 ~129 ~109 spruce_fence
setblock ~170 ~129 ~110 oak_log
setblock ~170 ~129 ~115 jungle_leaves[persistent=null]
setblock ~170 ~129 ~116 oak_leaves[persistent=null]
setblock ~170 ~130 ~107 oak_leaves[persistent=null]
setblock ~170 ~130 ~108 jungle_leaves[persistent=null]
setblock ~170 ~130 ~109 oak_leaves[persistent=null]
setblock ~170 ~130 ~110 oak_leaves[persistent=null]
setblock ~170 ~130 ~111 oak_leaves[persistent=null]
setblock ~170 ~130 ~112 oak_leaves[persistent=null]
setblock ~170 ~130 ~113 oak_leaves[persistent=null]
setblock ~170 ~130 ~115 oak_leaves[persistent=null]
setblock ~170 ~130 ~116 oak_leaves[persistent=null]
setblock ~170 ~131 ~107 jungle_leaves[persistent=null]
setblock ~170 ~131 ~109 oak_log
setblock ~170 ~131 ~110 oak_wood
setblock ~170 ~131 ~111 jungle_leaves[persistent=null]
setblock ~170 ~131 ~113 oak_leaves[persistent=null]
setblock ~170 ~131 ~114 jungle_leaves[persistent=null]
setblock ~170 ~131 ~115 oak_wood
setblock ~170 ~131 ~116 jungle_leaves[persistent=null]
setblock ~170 ~132 ~110 oak_wood
setblock ~170 ~132 ~111 oak_leaves[persistent=null]
setblock ~170 ~132 ~112 jungle_leaves[persistent=null]
setblock ~170 ~132 ~113 oak_wood
setblock ~170 ~132 ~114 oak_wood
setblock ~170 ~132 ~116 oak_leaves[persistent=null]
setblock ~170 ~133 ~106 oak_leaves[persistent=null]
setblock ~170 ~133 ~107 oak_leaves[persistent=null]
setblock ~170 ~133 ~108 oak_leaves[persistent=null]
setblock ~170 ~133 ~110 oak_wood
setblock ~170 ~133 ~111 oak_wood
setblock ~170 ~133 ~112 oak_wood
setblock ~170 ~133 ~114 jungle_leaves[persistent=null]
setblock ~170 ~134 ~108 oak_leaves[persistent=null]
setblock ~170 ~134 ~109 oak_wood
setblock ~170 ~134 ~110 oak_wood
setblock ~170 ~134 ~111 oak_log
setblock ~170 ~134 ~112 oak_leaves[persistent=null]
setblock ~170 ~135 ~105 oak_leaves[persistent=null]
setblock ~170 ~135 ~106 jungle_leaves[persistent=null]
setblock ~170 ~135 ~107 oak_leaves[persistent=null]
setblock ~170 ~135 ~108 oak_leaves[persistent=null]
setblock ~170 ~135 ~109 oak_leaves[persistent=null]
setblock ~170 ~135 ~110 oak_leaves[persistent=null]
setblock ~170 ~135 ~111 oak_log
setblock ~170 ~135 ~112 oak_leaves[persistent=null]
setblock ~170 ~135 ~113 oak_leaves[persistent=null]
setblock ~170 ~136 ~105 oak_leaves[persistent=null]
setblock ~170 ~136 ~107 oak_leaves[persistent=null]
setblock ~170 ~136 ~108 oak_leaves[persistent=null]
setblock ~170 ~136 ~109 oak_log
setblock ~170 ~136 ~112 oak_leaves[persistent=null]
setblock ~170 ~136 ~113 jungle_leaves[persistent=null]
setblock ~170 ~137 ~106 jungle_leaves[persistent=null]
setblock ~170 ~137 ~107 jungle_leaves[persistent=null]
setblock ~170 ~137 ~109 oak_leaves[persistent=null]
setblock ~170 ~137 ~110 oak_leaves[persistent=null]
setblock ~170 ~138 ~107 oak_leaves[persistent=null]
setblock ~170 ~138 ~109 oak_leaves[persistent=null]
setblock ~170 ~138 ~110 oak_leaves[persistent=null]
setblock ~170 ~138 ~111 oak_leaves[persistent=null]
setblock ~171 ~106 ~96 dirt
setblock ~171 ~106 ~97 dirt
setblock ~171 ~106 ~98 dirt
setblock ~171 ~107 ~95 dirt
setblock ~171 ~107 ~96 dirt
setblock ~171 ~107 ~97 dirt
setblock ~171 ~107 ~98 dirt
setblock ~171 ~108 ~94 dirt
setblock ~171 ~108 ~95 dirt
setblock ~171 ~108 ~96 dirt
setblock ~171 ~108 ~97 dirt
setblock ~171 ~108 ~98 dirt
setblock ~171 ~108 ~99 dirt
setblock ~171 ~109 ~94 dirt
setblock ~171 ~109 ~95 dirt
setblock ~171 ~109 ~96 dirt
setblock ~171 ~109 ~97 dirt
setblock ~171 ~109 ~98 dirt
setblock ~171 ~109 ~99 dirt
setblock ~171 ~109 ~102 dirt
setblock ~171 ~110 ~93 dirt
setblock ~171 ~110 ~94 dirt
setblock ~171 ~110 ~95 dirt
setblock ~171 ~110 ~96 dirt
setblock ~171 ~110 ~97 dirt
setblock ~171 ~110 ~98 dirt
setblock ~171 ~110 ~99 dirt
setblock ~171 ~110 ~102 dirt
setblock ~171 ~110 ~103 dirt
setblock ~171 ~111 ~93 dirt
setblock ~171 ~111 ~94 dirt
setblock ~171 ~111 ~95 dirt
setblock ~171 ~111 ~96 dirt
setblock ~171 ~111 ~97 dirt
setblock ~171 ~111 ~98 dirt
setblock ~171 ~111 ~99 dirt
setblock ~171 ~111 ~100 dirt
setblock ~171 ~111 ~102 dirt
setblock ~171 ~111 ~103 dirt
setblock ~171 ~112 ~92 dirt
setblock ~171 ~112 ~93 dirt
setblock ~171 ~112 ~94 dirt
setblock ~171 ~112 ~95 dirt
setblock ~171 ~112 ~96 dirt
setblock ~171 ~112 ~97 dirt
setblock ~171 ~112 ~98 dirt
setblock ~171 ~112 ~99 dirt
setblock ~171 ~112 ~100 dirt
setblock ~171 ~112 ~102 dirt
setblock ~171 ~112 ~103 dirt
setblock ~171 ~112 ~104 dirt
setblock ~171 ~113 ~92 dirt
setblock ~171 ~113 ~93 dirt
setblock ~171 ~113 ~94 dirt
setblock ~171 ~113 ~95 dirt
setblock ~171 ~113 ~96 dirt
setblock ~171 ~113 ~97 dirt
setblock ~171 ~113 ~98 dirt
setblock ~171 ~113 ~99 dirt
setblock ~171 ~113 ~100 dirt
setblock ~171 ~113 ~101 dirt
setblock ~171 ~113 ~102 dirt
setblock ~171 ~113 ~103 dirt
setblock ~171 ~113 ~104 dirt
setblock ~171 ~114 ~90 dirt
setblock ~171 ~114 ~91 dirt
setblock ~171 ~114 ~92 dirt
setblock ~171 ~114 ~93 dirt
setblock ~171 ~114 ~94 dirt
setblock ~171 ~114 ~95 dirt
setblock ~171 ~114 ~96 dirt
setblock ~171 ~114 ~97 dirt
setblock ~171 ~114 ~98 dirt
setblock ~171 ~114 ~99 dirt
setblock ~171 ~114 ~100 dirt
setblock ~171 ~114 ~101 dirt
setblock ~171 ~114 ~102 dirt
setblock ~171 ~114 ~103 dirt
setblock ~171 ~114 ~104 dirt
setblock ~171 ~114 ~106 dirt
setblock ~171 ~115 ~90 dirt
setblock ~171 ~115 ~91 dirt
setblock ~171 ~115 ~92 dirt
setblock ~171 ~115 ~93 dirt
setblock ~171 ~115 ~94 dirt
setblock ~171 ~115 ~95 dirt
setblock ~171 ~115 ~96 dirt
setblock ~171 ~115 ~97 dirt
setblock ~171 ~115 ~98 dirt
setblock ~171 ~115 ~99 dirt
setblock ~171 ~115 ~100 dirt
setblock ~171 ~115 ~101 dirt
setblock ~171 ~115 ~102 dirt
setblock ~171 ~115 ~103 dirt
setblock ~171 ~115 ~104 dirt
setblock ~171 ~115 ~105 dirt
setblock ~171 ~115 ~106 dirt
setblock ~171 ~116 ~88 dirt
setblock ~171 ~116 ~89 dirt
setblock ~171 ~116 ~90 dirt
setblock ~171 ~116 ~91 dirt
setblock ~171 ~116 ~92 dirt
setblock ~171 ~116 ~93 dirt
setblock ~171 ~116 ~94 dirt
setblock ~171 ~116 ~95 dirt
setblock ~171 ~116 ~96 dirt
setblock ~171 ~116 ~97 dirt
setblock ~171 ~116 ~98 dirt
setblock ~171 ~116 ~99 dirt
setblock ~171 ~116 ~100 dirt
setblock ~171 ~116 ~101 dirt
setblock ~171 ~116 ~102 dirt
setblock ~171 ~116 ~103 dirt
setblock ~171 ~116 ~104 dirt
setblock ~171 ~116 ~105 dirt
setblock ~171 ~116 ~106 dirt
setblock ~171 ~116 ~107 dirt
setblock ~171 ~117 ~86 dirt
setblock ~171 ~117 ~87 dirt
setblock ~171 ~117 ~88 dirt
setblock ~171 ~117 ~89 dirt
setblock ~171 ~117 ~90 dirt
setblock ~171 ~117 ~91 dirt
setblock ~171 ~117 ~92 dirt
setblock ~171 ~117 ~93 dirt
setblock ~171 ~117 ~94 dirt
setblock ~171 ~117 ~95 dirt
setblock ~171 ~117 ~96 dirt
setblock ~171 ~117 ~97 dirt
setblock ~171 ~117 ~98 dirt
setblock ~171 ~117 ~99 dirt
setblock ~171 ~117 ~100 dirt
setblock ~171 ~117 ~101 dirt
setblock ~171 ~117 ~102 dirt
setblock ~171 ~117 ~103 dirt
setblock ~171 ~117 ~104 dirt
setblock ~171 ~117 ~105 dirt
setblock ~171 ~117 ~106 dirt
setblock ~171 ~117 ~107 dirt
setblock ~171 ~118 ~86 dirt
setblock ~171 ~118 ~87 dirt
setblock ~171 ~118 ~88 dirt
setblock ~171 ~118 ~89 dirt
setblock ~171 ~118 ~90 dirt
setblock ~171 ~118 ~91 dirt
setblock ~171 ~118 ~92 dirt
setblock ~171 ~118 ~93 dirt
setblock ~171 ~118 ~94 dirt
setblock ~171 ~118 ~95 dirt
setblock ~171 ~118 ~96 dirt
setblock ~171 ~118 ~97 dirt
setblock ~171 ~118 ~98 dirt
setblock ~171 ~118 ~99 dirt
setblock ~171 ~118 ~100 dirt
setblock ~171 ~118 ~101 dirt
setblock ~171 ~118 ~102 dirt
setblock ~171 ~118 ~103 dirt
setblock ~171 ~118 ~104 dirt
setblock ~171 ~118 ~105 dirt
setblock ~171 ~118 ~106 dirt
setblock ~171 ~118 ~107 dirt
setblock ~171 ~119 ~83 dirt
setblock ~171 ~119 ~86 dirt
setblock ~171 ~119 ~87 dirt
setblock ~171 ~119 ~88 dirt
setblock ~171 ~119 ~89 dirt
setblock ~171 ~119 ~90 dirt
setblock ~171 ~119 ~91 dirt
setblock ~171 ~119 ~92 dirt
setblock ~171 ~119 ~93 dirt
setblock ~171 ~119 ~94 dirt
setblock ~171 ~119 ~95 dirt
setblock ~171 ~119 ~96 dirt
setblock ~171 ~119 ~97 dirt
setblock ~171 ~119 ~98 dirt
setblock ~171 ~119 ~99 dirt
setblock ~171 ~119 ~100 dirt
setblock ~171 ~119 ~101 dirt
setblock ~171 ~119 ~102 dirt
setblock ~171 ~119 ~103 dirt
setblock ~171 ~119 ~104 dirt
setblock ~171 ~119 ~105 dirt
setblock ~171 ~119 ~106 dirt
setblock ~171 ~119 ~107 dirt
setblock ~171 ~119 ~108 dirt
setblock ~171 ~120 ~83 dirt
setblock ~171 ~120 ~84 dirt
setblock ~171 ~120 ~85 dirt
setblock ~171 ~120 ~86 dirt
setblock ~171 ~120 ~87 dirt
setblock ~171 ~120 ~88 dirt
setblock ~171 ~120 ~89 dirt
setblock ~171 ~120 ~90 dirt
setblock ~171 ~120 ~91 dirt
setblock ~171 ~120 ~92 dirt
setblock ~171 ~120 ~93 dirt
setblock ~171 ~120 ~94 dirt
setblock ~171 ~120 ~95 dirt
setblock ~171 ~120 ~96 dirt
setblock ~171 ~120 ~97 dirt
setblock ~171 ~120 ~98 dirt
setblock ~171 ~120 ~99 dirt
setblock ~171 ~120 ~100 dirt
setblock ~171 ~120 ~101 dirt
setblock ~171 ~120 ~102 dirt
setblock ~171 ~120 ~103 dirt
setblock ~171 ~120 ~104 dirt
setblock ~171 ~120 ~105 dirt
setblock ~171 ~120 ~106 dirt
setblock ~171 ~120 ~107 dirt
setblock ~171 ~120 ~108 dirt
setblock ~171 ~120 ~109 dirt
setblock ~171 ~121 ~82 dirt
setblock ~171 ~121 ~83 dirt
setblock ~171 ~121 ~84 dirt
setblock ~171 ~121 ~85 dirt
setblock ~171 ~121 ~86 dirt
setblock ~171 ~121 ~87 dirt
setblock ~171 ~121 ~88 dirt
setblock ~171 ~121 ~89 dirt
setblock ~171 ~121 ~90 dirt
setblock ~171 ~121 ~91 dirt
setblock ~171 ~121 ~92 dirt
setblock ~171 ~121 ~93 dirt
setblock ~171 ~121 ~94 dirt
setblock ~171 ~121 ~95 dirt
setblock ~171 ~121 ~96 dirt
setblock ~171 ~121 ~97 dirt
setblock ~171 ~121 ~98 dirt
setblock ~171 ~121 ~99 dirt
setblock ~171 ~121 ~100 dirt
setblock ~171 ~121 ~101 dirt
setblock ~171 ~121 ~102 dirt
setblock ~171 ~121 ~103 dirt
setblock ~171 ~121 ~104 dirt
setblock ~171 ~121 ~105 dirt
setblock ~171 ~121 ~106 dirt
setblock ~171 ~121 ~107 dirt
setblock ~171 ~121 ~108 dirt
setblock ~171 ~121 ~109 dirt
setblock ~171 ~121 ~110 dirt
setblock ~171 ~121 ~122 dirt
setblock ~171 ~122 ~82 dirt
setblock ~171 ~122 ~83 dirt
setblock ~171 ~122 ~84 dirt
setblock ~171 ~122 ~85 dirt
setblock ~171 ~122 ~86 dirt
setblock ~171 ~122 ~87 dirt
setblock ~171 ~122 ~88 dirt
setblock ~171 ~122 ~89 dirt
setblock ~171 ~122 ~90 dirt
setblock ~171 ~122 ~91 dirt
setblock ~171 ~122 ~92 dirt
setblock ~171 ~122 ~93 dirt
setblock ~171 ~122 ~94 dirt
setblock ~171 ~122 ~95 dirt
setblock ~171 ~122 ~96 dirt
setblock ~171 ~122 ~97 dirt
setblock ~171 ~122 ~98 dirt
setblock ~171 ~122 ~99 dirt
setblock ~171 ~122 ~100 dirt
setblock ~171 ~122 ~101 dirt
setblock ~171 ~122 ~102 dirt
setblock ~171 ~122 ~103 dirt
setblock ~171 ~122 ~104 dirt
setblock ~171 ~122 ~105 dirt
setblock ~171 ~122 ~106 dirt
setblock ~171 ~122 ~107 dirt
setblock ~171 ~122 ~108 dirt
setblock ~171 ~122 ~109 dirt
setblock ~171 ~122 ~110 dirt
setblock ~171 ~122 ~122 dirt
setblock ~171 ~123 ~82 dirt
setblock ~171 ~123 ~83 dirt
setblock ~171 ~123 ~84 dirt
setblock ~171 ~123 ~85 dirt
setblock ~171 ~123 ~86 dirt
setblock ~171 ~123 ~87 dirt
setblock ~171 ~123 ~88 dirt
setblock ~171 ~123 ~89 dirt
setblock ~171 ~123 ~90 dirt
setblock ~171 ~123 ~91 dirt
setblock ~171 ~123 ~92 dirt
setblock ~171 ~123 ~93 dirt
setblock ~171 ~123 ~94 dirt
setblock ~171 ~123 ~95 dirt
setblock ~171 ~123 ~96 dirt
setblock ~171 ~123 ~97 dirt
setblock ~171 ~123 ~98 dirt
setblock ~171 ~123 ~99 dirt
setblock ~171 ~123 ~100 dirt
setblock ~171 ~123 ~101 dirt
setblock ~171 ~123 ~102 dirt
setblock ~171 ~123 ~103 dirt
setblock ~171 ~123 ~104 dirt
setblock ~171 ~123 ~105 dirt
setblock ~171 ~123 ~106 dirt
setblock ~171 ~123 ~107 dirt
setblock ~171 ~123 ~108 grass_block
setblock ~171 ~123 ~109 grass_block
setblock ~171 ~123 ~110 grass_block
setblock ~171 ~123 ~122 grass_block
setblock ~171 ~124 ~82 grass_block
setblock ~171 ~124 ~83 grass_block
setblock ~171 ~124 ~84 grass_block
setblock ~171 ~124 ~85 grass_block
setblock ~171 ~124 ~86 grass_block
setblock ~171 ~124 ~87 grass_block
setblock ~171 ~124 ~88 grass_block
setblock ~171 ~124 ~89 grass_block
setblock ~171 ~124 ~90 grass_block
setblock ~171 ~124 ~91 grass_block
setblock ~171 ~124 ~92 grass_block
setblock ~171 ~124 ~93 grass_block
setblock ~171 ~124 ~94 grass_block
setblock ~171 ~124 ~95 grass_block
setblock ~171 ~124 ~96 grass_block
setblock ~171 ~124 ~97 grass_block
setblock ~171 ~124 ~98 grass_block
setblock ~171 ~124 ~99 grass_block
setblock ~171 ~124 ~100 grass_block
setblock ~171 ~124 ~101 grass_block
setblock ~171 ~124 ~102 grass_block
setblock ~171 ~124 ~103 grass_block
setblock ~171 ~124 ~104 grass_block
setblock ~171 ~124 ~105 grass_block
setblock ~171 ~124 ~106 grass_block
setblock ~171 ~124 ~107 grass_block
setblock ~171 ~124 ~108 short_grass
setblock ~171 ~125 ~82 short_grass
setblock ~171 ~125 ~85 short_grass
setblock ~171 ~125 ~90 short_grass
setblock ~171 ~125 ~97 fern
setblock ~171 ~125 ~103 fern
setblock ~171 ~125 ~104 short_grass
setblock ~171 ~129 ~115 oak_leaves[persistent=null]
setblock ~171 ~129 ~116 oak_leaves[persistent=null]
setblock ~171 ~130 ~107 jungle_leaves[persistent=null]
setblock ~171 ~130 ~108 oak_leaves[persistent=null]
setblock ~171 ~130 ~110 oak_leaves[persistent=null]
setblock ~171 ~130 ~111 oak_leaves[persistent=null]
setblock ~171 ~130 ~112 oak_leaves[persistent=null]
setblock ~171 ~130 ~113 oak_leaves[persistent=null]
setblock ~171 ~130 ~114 jungle_leaves[persistent=null]
setblock ~171 ~130 ~115 oak_leaves[persistent=null]
setblock ~171 ~130 ~116 oak_leaves[persistent=null]
setblock ~171 ~131 ~110 oak_leaves[persistent=null]
setblock ~171 ~131 ~112 oak_leaves[persistent=null]
setblock ~171 ~131 ~113 oak_leaves[persistent=null]
setblock ~171 ~131 ~114 jungle_leaves[persistent=null]
setblock ~171 ~131 ~115 oak_wood
setblock ~171 ~131 ~116 oak_leaves[persistent=null]
setblock ~171 ~132 ~105 oak_leaves[persistent=null]
setblock ~171 ~132 ~107 oak_leaves[persistent=null]
setblock ~171 ~132 ~108 oak_leaves[persistent=null]
setblock ~171 ~132 ~109 oak_leaves[persistent=null]
setblock ~171 ~132 ~110 oak_log
setblock ~171 ~132 ~112 oak_leaves[persistent=null]
setblock ~171 ~132 ~115 oak_leaves[persistent=null]
setblock ~171 ~133 ~106 oak_leaves[persistent=null]
setblock ~171 ~133 ~107 oak_leaves[persistent=null]
setblock ~171 ~133 ~109 oak_wood
setblock ~171 ~133 ~110 oak_wood
setblock ~171 ~133 ~111 oak_leaves[persistent=null]
setblock ~171 ~133 ~112 jungle_leaves[persistent=null]
setblock ~171 ~133 ~113 oak_leaves[persistent=null]
setblock ~171 ~133 ~114 oak_leaves[persistent=null]
setblock ~171 ~134 ~104 oak_leaves[persistent=null]
setblock ~171 ~134 ~105 jungle_leaves[persistent=null]
setblock ~171 ~134 ~107 oak_leaves[persistent=null]
setblock ~171 ~134 ~108 jungle_leaves[persistent=null]
setblock ~171 ~134 ~109 oak_wood
setblock ~171 ~134 ~110 oak_leaves[persistent=null]
setblock ~171 ~135 ~105 oak_leaves[persistent=null]
setblock ~171 ~135 ~107 oak_wood
setblock ~171 ~135 ~108 oak_wood
setblock ~171 ~135 ~110 oak_wood
setblock ~171 ~135 ~111 oak_leaves[persistent=null]
setblock ~171 ~135 ~112 oak_leaves[persistent=null]
setblock ~171 ~136 ~105 oak_leaves[persistent=null]
setblock ~171 ~136 ~106 oak_leaves[persistent=null]
setblock ~171 ~136 ~107 oak_wood
setblock ~171 ~136 ~108 oak_leaves[persistent=null]
setblock ~171 ~136 ~109 oak_log
setblock ~171 ~136 ~110 oak_leaves[persistent=null]
setblock ~171 ~136 ~111 oak_log
setblock ~171 ~136 ~113 jungle_leaves[persistent=null]
setblock ~171 ~137 ~106 jungle_leaves[persistent=null]
setblock ~171 ~137 ~107 jungle_leaves[persistent=null]
setblock ~171 ~137 ~108 oak_leaves[persistent=null]
setblock ~171 ~137 ~109 oak_leaves[persistent=null]
setblock ~171 ~137 ~110 oak_leaves[persistent=null]
setblock ~171 ~137 ~112 oak_leaves[persistent=null]
setblock ~171 ~137 ~113 oak_leaves[persistent=null]
setblock ~171 ~138 ~107 oak_leaves[persistent=null]
setblock ~171 ~138 ~109 oak_leaves[persistent=null]
setblock ~171 ~138 ~110 oak_leaves[persistent=null]
setblock ~172 ~107 ~97 dirt
setblock ~172 ~108 ~95 dirt
setblock ~172 ~108 ~96 dirt
setblock ~172 ~108 ~97 dirt
setblock ~172 ~108 ~98 dirt
setblock ~172 ~109 ~95 dirt
setblock ~172 ~109 ~96 dirt
setblock ~172 ~109 ~97 dirt
setblock ~172 ~109 ~98 dirt
setblock ~172 ~110 ~94 dirt
setblock ~172 ~110 ~95 dirt
setblock ~172 ~110 ~96 dirt
setblock ~172 ~110 ~97 dirt
setblock ~172 ~110 ~98 dirt
setblock ~172 ~110 ~99 dirt
setblock ~172 ~111 ~94 dirt
setblock ~172 ~111 ~95 dirt
setblock ~172 ~111 ~96 dirt
setblock ~172 ~111 ~97 dirt
setblock ~172 ~111 ~98 dirt
setblock ~172 ~111 ~99 dirt
setblock ~172 ~112 ~93 dirt
setblock ~172 ~112 ~94 dirt
setblock ~172 ~112 ~95 dirt
setblock ~172 ~112 ~96 dirt
setblock ~172 ~112 ~97 dirt
setblock ~172 ~112 ~98 dirt
setblock ~172 ~112 ~99 dirt
setblock ~172 ~112 ~103 dirt
setblock ~172 ~113 ~93 dirt
setblock ~172 ~113 ~94 dirt
setblock ~172 ~113 ~95 dirt
setblock ~172 ~113 ~96 dirt
setblock ~172 ~113 ~97 dirt
setblock ~172 ~113 ~98 dirt
setblock ~172 ~113 ~99 dirt
setblock ~172 ~113 ~100 dirt
setblock ~172 ~113 ~102 dirt
setblock ~172 ~113 ~103 dirt
setblock ~172 ~114 ~92 dirt
setblock ~172 ~114 ~93 dirt
setblock ~172 ~114 ~94 dirt
setblock ~172 ~114 ~95 dirt
setblock ~172 ~114 ~96 dirt
setblock ~172 ~114 ~97 dirt
setblock ~172 ~114 ~98 dirt
setblock ~172 ~114 ~99 dirt
setblock ~172 ~114 ~100 dirt
setblock ~172 ~114 ~101 dirt
setblock ~172 ~114 ~102 dirt
setblock ~172 ~114 ~103 dirt
setblock ~172 ~115 ~91 dirt
setblock ~172 ~115 ~92 dirt
setblock ~172 ~115 ~93 dirt
setblock ~172 ~115 ~94 dirt
setblock ~172 ~115 ~95 dirt
setblock ~172 ~115 ~96 dirt
setblock ~172 ~115 ~97 dirt
setblock ~172 ~115 ~98 dirt
setblock ~172 ~115 ~99 dirt
setblock ~172 ~115 ~100 dirt
setblock ~172 ~115 ~101 dirt
setblock ~172 ~115 ~102 dirt
setblock ~172 ~115 ~103 dirt
setblock ~172 ~115 ~104 dirt
setblock ~172 ~116 ~90 dirt
setblock ~172 ~116 ~91 dirt
setblock ~172 ~116 ~92 dirt
setblock ~172 ~116 ~93 dirt
setblock ~172 ~116 ~94 dirt
setblock ~172 ~116 ~95 dirt
setblock ~172 ~116 ~96 dirt
setblock ~172 ~116 ~97 dirt
setblock ~172 ~116 ~98 dirt
setblock ~172 ~116 ~99 dirt
setblock ~172 ~116 ~100 dirt
setblock ~172 ~116 ~101 dirt
setblock ~172 ~116 ~102 dirt
setblock ~172 ~116 ~103 dirt
setblock ~172 ~116 ~104 dirt
setblock ~172 ~116 ~105 dirt
setblock ~172 ~116 ~106 dirt
setblock ~172 ~117 ~90 dirt
setblock ~172 ~117 ~91 dirt
setblock ~172 ~117 ~92 dirt
setblock ~172 ~117 ~93 dirt
setblock ~172 ~117 ~94 dirt
setblock ~172 ~117 ~95 dirt
setblock ~172 ~117 ~96 dirt
setblock ~172 ~117 ~97 dirt
setblock ~172 ~117 ~98 dirt
setblock ~172 ~117 ~99 dirt
setblock ~172 ~117 ~100 dirt
setblock ~172 ~117 ~101 dirt
setblock ~172 ~117 ~102 dirt
setblock ~172 ~117 ~103 dirt
setblock ~172 ~117 ~104 dirt
setblock ~172 ~117 ~105 dirt
setblock ~172 ~117 ~106 dirt
setblock ~172 ~118 ~89 dirt
setblock ~172 ~118 ~90 dirt
setblock ~172 ~118 ~91 dirt
setblock ~172 ~118 ~92 dirt
setblock ~172 ~118 ~93 dirt
setblock ~172 ~118 ~94 dirt
setblock ~172 ~118 ~95 dirt
setblock ~172 ~118 ~96 dirt
setblock ~172 ~118 ~97 dirt
setblock ~172 ~118 ~98 dirt
setblock ~172 ~118 ~99 dirt
setblock ~172 ~118 ~100 dirt
setblock ~172 ~118 ~101 dirt
setblock ~172 ~118 ~102 dirt
setblock ~172 ~118 ~103 dirt
setblock ~172 ~118 ~104 dirt
setblock ~172 ~118 ~105 dirt
setblock ~172 ~118 ~106 dirt
setblock ~172 ~118 ~107 dirt
setblock ~172 ~119 ~89 dirt
setblock ~172 ~119 ~90 dirt
setblock ~172 ~119 ~91 dirt
setblock ~172 ~119 ~92 dirt
setblock ~172 ~119 ~93 dirt
setblock ~172 ~119 ~94 dirt
setblock ~172 ~119 ~95 dirt
setblock ~172 ~119 ~96 dirt
setblock ~172 ~119 ~97 dirt
setblock ~172 ~119 ~98 dirt
setblock ~172 ~119 ~99 dirt
setblock ~172 ~119 ~100 dirt
setblock ~172 ~119 ~101 dirt
setblock ~172 ~119 ~102 dirt
setblock ~172 ~119 ~103 dirt
setblock ~172 ~119 ~104 dirt
setblock ~172 ~119 ~105 dirt
setblock ~172 ~119 ~106 dirt
setblock ~172 ~119 ~107 dirt
setblock ~172 ~120 ~86 dirt
setblock ~172 ~120 ~87 dirt
setblock ~172 ~120 ~88 dirt
setblock ~172 ~120 ~89 dirt
setblock ~172 ~120 ~90 dirt
setblock ~172 ~120 ~91 dirt
setblock ~172 ~120 ~92 dirt
setblock ~172 ~120 ~93 dirt
setblock ~172 ~120 ~94 dirt
setblock ~172 ~120 ~95 dirt
setblock ~172 ~120 ~96 dirt
setblock ~172 ~120 ~97 dirt
setblock ~172 ~120 ~98 dirt
setblock ~172 ~120 ~99 dirt
setblock ~172 ~120 ~100 dirt
setblock ~172 ~120 ~101 dirt
setblock ~172 ~120 ~102 dirt
setblock ~172 ~120 ~103 dirt
setblock ~172 ~120 ~104 dirt
setblock ~172 ~120 ~105 dirt
setblock ~172 ~120 ~106 dirt
setblock ~172 ~120 ~107 dirt
setblock ~172 ~120 ~108 dirt
setblock ~172 ~121 ~83 dirt
setblock ~172 ~121 ~86 dirt
setblock ~172 ~121 ~87 dirt
setblock ~172 ~121 ~88 dirt
setblock ~172 ~121 ~89 dirt
setblock ~172 ~121 ~90 dirt
setblock ~172 ~121 ~91 dirt
setblock ~172 ~121 ~92 dirt
setblock ~172 ~121 ~93 dirt
setblock ~172 ~121 ~94 dirt
setblock ~172 ~121 ~95 dirt
setblock ~172 ~121 ~96 dirt
setblock ~172 ~121 ~97 dirt
setblock ~172 ~121 ~98 dirt
setblock ~172 ~121 ~99 dirt
setblock ~172 ~121 ~100 dirt
setblock ~172 ~121 ~101 dirt
setblock ~172 ~121 ~102 dirt
setblock ~172 ~121 ~103 dirt
setblock ~172 ~121 ~104 dirt
setblock ~172 ~121 ~105 dirt
setblock ~172 ~121 ~106 dirt
setblock ~172 ~121 ~107 dirt
setblock ~172 ~121 ~108 dirt
setblock ~172 ~121 ~109 dirt
setblock ~172 ~122 ~83 dirt
setblock ~172 ~122 ~86 dirt
setblock ~172 ~122 ~87 dirt
setblock ~172 ~122 ~88 dirt
setblock ~172 ~122 ~89 dirt
setblock ~172 ~122 ~90 dirt
setblock ~172 ~122 ~91 dirt
setblock ~172 ~122 ~92 dirt
setblock ~172 ~122 ~93 dirt
setblock ~172 ~122 ~94 dirt
setblock ~172 ~122 ~95 dirt
setblock ~172 ~122 ~96 dirt
setblock ~172 ~122 ~97 dirt
setblock ~172 ~122 ~98 dirt
setblock ~172 ~122 ~99 dirt
setblock ~172 ~122 ~100 dirt
setblock ~172 ~122 ~101 dirt
setblock ~172 ~122 ~102 dirt
setblock ~172 ~122 ~103 dirt
setblock ~172 ~122 ~104 dirt
setblock ~172 ~122 ~105 dirt
setblock ~172 ~122 ~106 dirt
setblock ~172 ~122 ~107 dirt
setblock ~172 ~122 ~108 dirt
setblock ~172 ~122 ~109 dirt
setblock ~172 ~123 ~83 dirt
setblock ~172 ~123 ~86 dirt
setblock ~172 ~123 ~87 dirt
setblock ~172 ~123 ~88 dirt
setblock ~172 ~123 ~89 dirt
setblock ~172 ~123 ~90 dirt
setblock ~172 ~123 ~91 dirt
setblock ~172 ~123 ~92 dirt
setblock ~172 ~123 ~93 dirt
setblock ~172 ~123 ~94 dirt
setblock ~172 ~123 ~95 dirt
setblock ~172 ~123 ~96 dirt
setblock ~172 ~123 ~97 dirt
setblock ~172 ~123 ~98 dirt
setblock ~172 ~123 ~99 dirt
setblock ~172 ~123 ~100 dirt
setblock ~172 ~123 ~101 dirt
setblock ~172 ~123 ~102 dirt
setblock ~172 ~123 ~103 dirt
setblock ~172 ~123 ~104 dirt
setblock ~172 ~123 ~105 dirt
setblock ~172 ~123 ~106 dirt
setblock ~172 ~123 ~107 dirt
setblock ~172 ~123 ~108 dirt
setblock ~172 ~123 ~109 dirt
setblock ~172 ~124 ~83 grass_block
setblock ~172 ~124 ~86 grass_block
setblock ~172 ~124 ~87 grass_block
setblock ~172 ~124 ~88 grass_block
setblock ~172 ~124 ~89 grass_block
setblock ~172 ~124 ~90 grass_block
setblock ~172 ~124 ~91 grass_block
setblock ~172 ~124 ~92 grass_block
setblock ~172 ~124 ~93 grass_block
setblock ~172 ~124 ~94 grass_block
setblock ~172 ~124 ~95 grass_block
setblock ~172 ~124 ~96 grass_block
setblock ~172 ~124 ~97 grass_block
setblock ~172 ~124 ~98 grass_block
setblock ~172 ~124 ~99 grass_block
setblock ~172 ~124 ~100 grass_block
setblock ~172 ~124 ~101 grass_block
setblock ~172 ~124 ~102 grass_block
setblock ~172 ~124 ~103 grass_block
setblock ~172 ~124 ~104 grass_block
setblock ~172 ~124 ~105 grass_block
setblock ~172 ~124 ~106 grass_block
setblock ~172 ~124 ~107 grass_block
setblock ~172 ~124 ~108 grass_block
setblock ~172 ~124 ~109 grass_block
setblock ~172 ~125 ~88 fern
setblock ~172 ~125 ~89 short_grass
setblock ~172 ~125 ~100 fern
setblock ~172 ~125 ~101 short_grass
setblock ~172 ~125 ~102 short_grass
setblock ~172 ~125 ~103 short_grass
setblock ~172 ~125 ~104 poppy
setblock ~172 ~125 ~107 short_grass
setblock ~172 ~130 ~109 jungle_leaves[persistent=null]
setblock ~172 ~130 ~111 oak_leaves[persistent=null]
setblock ~172 ~130 ~112 oak_leaves[persistent=null]
setblock ~172 ~130 ~114 oak_leaves[persistent=null]
setblock ~172 ~131 ~105 oak_leaves[persistent=null]
setblock ~172 ~131 ~106 oak_leaves[persistent=null]
setblock ~172 ~131 ~108 oak_leaves[persistent=null]
setblock ~172 ~131 ~109 oak_leaves[persistent=null]
setblock ~172 ~131 ~110 oak_leaves[persistent=null]
setblock ~172 ~131 ~111 oak_leaves[persistent=null]
setblock ~172 ~131 ~113 oak_leaves[persistent=null]
setblock ~172 ~131 ~115 oak_leaves[persistent=null]
setblock ~172 ~131 ~116 jungle_leaves[persistent=null]
setblock ~172 ~132 ~103 oak_leaves[persistent=null]
setblock ~172 ~132 ~104 oak_leaves[persistent=null]
setblock ~172 ~132 ~106 oak_leaves[persistent=null]
setblock ~172 ~132 ~107 oak_leaves[persistent=null]
setblock ~172 ~132 ~108 oak_leaves[persistent=null]
setblock ~172 ~132 ~109 oak_leaves[persistent=null]
setblock ~172 ~132 ~110 oak_leaves[persistent=null]
setblock ~172 ~132 ~111 jungle_leaves[persistent=null]
setblock ~172 ~132 ~113 oak_leaves[persistent=null]
setblock ~172 ~132 ~114 jungle_leaves[persistent=null]
setblock ~172 ~132 ~115 oak_leaves[persistent=null]
setblock ~172 ~132 ~116 oak_leaves[persistent=null]
setblock ~172 ~133 ~103 oak_leaves[persistent=null]
setblock ~172 ~133 ~104 oak_leaves[persistent=null]
setblock ~172 ~133 ~106 jungle_leaves[persistent=null]
setblock ~172 ~133 ~108 oak_wood
setblock ~172 ~133 ~109 oak_wood
setblock ~172 ~133 ~110 oak_leaves[persistent=null]
setblock ~172 ~133 ~111 oak_log
setblock ~172 ~133 ~112 jungle_leaves[persistent=null]
setblock ~172 ~133 ~113 oak_leaves[persistent=null]
setblock ~172 ~134 ~103 jungle_leaves[persistent=null]
setblock ~172 ~134 ~104 oak_leaves[persistent=null]
setblock ~172 ~134 ~105 oak_leaves[persistent=null]
setblock ~172 ~134 ~108 oak_leaves[persistent=null]
setblock ~172 ~134 ~110 oak_wood
setblock ~172 ~134 ~111 oak_leaves[persistent=null]
setblock ~172 ~134 ~112 oak_leaves[persistent=null]
setblock ~172 ~134 ~113 jungle_leaves[persistent=null]
setblock ~172 ~135 ~104 jungle_leaves[persistent=null]
setblock ~172 ~135 ~105 oak_leaves[persistent=null]
setblock ~172 ~135 ~107 oak_leaves[persistent=null]
setblock ~172 ~135 ~108 jungle_leaves[persistent=null]
setblock ~172 ~135 ~109 oak_leaves[persistent=null]
setblock ~172 ~135 ~110 oak_wood
setblock ~172 ~135 ~111 oak_leaves[persistent=null]
setblock ~172 ~135 ~112 oak_leaves[persistent=null]
setblock ~172 ~136 ~106 oak_leaves[persistent=null]
setblock ~172 ~136 ~107 oak_leaves[persistent=null]
setblock ~172 ~136 ~108 oak_leaves[persistent=null]
setblock ~172 ~136 ~109 oak_leaves[persistent=null]
setblock ~172 ~136 ~110 oak_log
setblock ~172 ~136 ~111 oak_leaves[persistent=null]
setblock ~172 ~136 ~112 oak_log
setblock ~172 ~136 ~113 jungle_leaves[persistent=null]
setblock ~172 ~137 ~106 jungle_leaves[persistent=null]
setblock ~172 ~137 ~108 oak_leaves[persistent=null]
setblock ~172 ~137 ~109 oak_leaves[persistent=null]
setblock ~172 ~137 ~112 oak_leaves[persistent=null]
setblock ~172 ~137 ~113 oak_leaves[persistent=null]
setblock ~172 ~138 ~110 oak_leaves[persistent=null]
setblock ~172 ~138 ~111 oak_leaves[persistent=null]
setblock ~173 ~109 ~96 dirt
setblock ~173 ~109 ~97 dirt
setblock ~173 ~110 ~95 dirt
setblock ~173 ~110 ~96 dirt
setblock ~173 ~110 ~97 dirt
setblock ~173 ~110 ~98 dirt
setblock ~173 ~111 ~94 dirt
setblock ~173 ~111 ~95 dirt
setblock ~173 ~111 ~96 dirt
setblock ~173 ~111 ~97 dirt
setblock ~173 ~111 ~98 dirt
setblock ~173 ~111 ~99 dirt
setblock ~173 ~112 ~94 dirt
setblock ~173 ~112 ~95 dirt
setblock ~173 ~112 ~96 dirt
setblock ~173 ~112 ~97 dirt
setblock ~173 ~112 ~98 dirt
setblock ~173 ~112 ~99 dirt
setblock ~173 ~113 ~94 dirt
setblock ~173 ~113 ~95 dirt
setblock ~173 ~113 ~96 dirt
setblock ~173 ~113 ~97 dirt
setblock ~173 ~113 ~98 dirt
setblock ~173 ~113 ~99 dirt
setblock ~173 ~114 ~94 dirt
setblock ~173 ~114 ~95 dirt
setblock ~173 ~114 ~96 dirt
setblock ~173 ~114 ~97 dirt
setblock ~173 ~114 ~98 dirt
setblock ~173 ~114 ~99 dirt
setblock ~173 ~114 ~100 dirt
setblock ~173 ~114 ~102 dirt
setblock ~173 ~115 ~93 dirt
setblock ~173 ~115 ~94 dirt
setblock ~173 ~115 ~95 dirt
setblock ~173 ~115 ~96 dirt
setblock ~173 ~115 ~97 dirt
setblock ~173 ~115 ~98 dirt
setblock ~173 ~115 ~99 dirt
setblock ~173 ~115 ~100 dirt
setblock ~173 ~115 ~102 dirt
setblock ~173 ~115 ~103 dirt
setblock ~173 ~116 ~91 dirt
setblock ~173 ~116 ~92 dirt
setblock ~173 ~116 ~93 dirt
setblock ~173 ~116 ~94 dirt
setblock ~173 ~116 ~95 dirt
setblock ~173 ~116 ~96 dirt
setblock ~173 ~116 ~97 dirt
setblock ~173 ~116 ~98 dirt
setblock ~173 ~116 ~99 dirt
setblock ~173 ~116 ~100 dirt
setblock ~173 ~116 ~101 dirt
setblock ~173 ~116 ~102 dirt
setblock ~173 ~116 ~103 dirt
setblock ~173 ~116 ~104 dirt
setblock ~173 ~117 ~90 dirt
setblock ~173 ~117 ~91 dirt
setblock ~173 ~117 ~92 dirt
setblock ~173 ~117 ~93 dirt
setblock ~173 ~117 ~94 dirt
setblock ~173 ~117 ~95 dirt
setblock ~173 ~117 ~96 dirt
setblock ~173 ~117 ~97 dirt
setblock ~173 ~117 ~98 dirt
setblock ~173 ~117 ~99 dirt
setblock ~173 ~117 ~100 dirt
setblock ~173 ~117 ~101 dirt
setblock ~173 ~117 ~102 dirt
setblock ~173 ~117 ~103 dirt
setblock ~173 ~117 ~104 dirt
setblock ~173 ~117 ~105 dirt
setblock ~173 ~118 ~90 dirt
setblock ~173 ~118 ~91 dirt
setblock ~173 ~118 ~92 dirt
setblock ~173 ~118 ~93 dirt
setblock ~173 ~118 ~94 dirt
setblock ~173 ~118 ~95 dirt
setblock ~173 ~118 ~96 dirt
setblock ~173 ~118 ~97 dirt
setblock ~173 ~118 ~98 dirt
setblock ~173 ~118 ~99 dirt
setblock ~173 ~118 ~100 dirt
setblock ~173 ~118 ~101 dirt
setblock ~173 ~118 ~102 dirt
setblock ~173 ~118 ~103 dirt
setblock ~173 ~118 ~104 dirt
setblock ~173 ~118 ~105 dirt
setblock ~173 ~118 ~106 dirt
setblock ~173 ~119 ~90 dirt
setblock ~173 ~119 ~91 dirt
setblock ~173 ~119 ~92 dirt
setblock ~173 ~119 ~93 dirt
setblock ~173 ~119 ~94 dirt
setblock ~173 ~119 ~95 dirt
setblock ~173 ~119 ~96 dirt
setblock ~173 ~119 ~97 dirt
setblock ~173 ~119 ~98 dirt
setblock ~173 ~119 ~99 dirt
setblock ~173 ~119 ~100 dirt
setblock ~173 ~119 ~101 dirt
setblock ~173 ~119 ~102 dirt
setblock ~173 ~119 ~103 dirt
setblock ~173 ~119 ~104 dirt
setblock ~173 ~119 ~105 dirt
setblock ~173 ~119 ~106 dirt
setblock ~173 ~120 ~89 dirt
setblock ~173 ~120 ~90 dirt
setblock ~173 ~120 ~91 dirt
setblock ~173 ~120 ~92 dirt
setblock ~173 ~120 ~93 dirt
setblock ~173 ~120 ~94 dirt
setblock ~173 ~120 ~95 dirt
setblock ~173 ~120 ~96 dirt
setblock ~173 ~120 ~97 dirt
setblock ~173 ~120 ~98 dirt
setblock ~173 ~120 ~99 dirt
setblock ~173 ~120 ~100 dirt
setblock ~173 ~120 ~101 dirt
setblock ~173 ~120 ~102 dirt
setblock ~173 ~120 ~103 dirt
setblock ~173 ~120 ~104 dirt
setblock ~173 ~120 ~105 dirt
setblock ~173 ~120 ~106 dirt
setblock ~173 ~120 ~107 dirt
setblock ~173 ~121 ~88 dirt
setblock ~173 ~121 ~89 dirt
setblock ~173 ~121 ~90 dirt
setblock ~173 ~121 ~91 dirt
setblock ~173 ~121 ~92 dirt
setblock ~173 ~121 ~93 dirt
setblock ~173 ~121 ~94 dirt
setblock ~173 ~121 ~95 dirt
setblock ~173 ~121 ~96 dirt
setblock ~173 ~121 ~97 dirt
setblock ~173 ~121 ~98 dirt
setblock ~173 ~121 ~99 dirt
setblock ~173 ~121 ~100 dirt
setblock ~173 ~121 ~101 dirt
setblock ~173 ~121 ~102 dirt
setblock ~173 ~121 ~103 dirt
setblock ~173 ~121 ~104 dirt
setblock ~173 ~121 ~105 dirt
setblock ~173 ~121 ~106 dirt
setblock ~173 ~121 ~107 dirt
setblock ~173 ~122 ~88 dirt
setblock ~173 ~122 ~89 dirt
setblock ~173 ~122 ~90 dirt
setblock ~173 ~122 ~91 dirt
setblock ~173 ~122 ~92 dirt
setblock ~173 ~122 ~93 dirt
setblock ~173 ~122 ~94 dirt
setblock ~173 ~122 ~95 dirt
setblock ~173 ~122 ~96 dirt
setblock ~173 ~122 ~97 dirt
setblock ~173 ~122 ~98 dirt
setblock ~173 ~122 ~99 dirt
setblock ~173 ~122 ~100 dirt
setblock ~173 ~122 ~101 dirt
setblock ~173 ~122 ~102 dirt
setblock ~173 ~122 ~103 dirt
setblock ~173 ~122 ~104 dirt
setblock ~173 ~122 ~105 dirt
setblock ~173 ~122 ~106 dirt
setblock ~173 ~122 ~107 dirt
setblock ~173 ~123 ~88 dirt
setblock ~173 ~123 ~89 dirt
setblock ~173 ~123 ~90 dirt
setblock ~173 ~123 ~91 dirt
setblock ~173 ~123 ~92 dirt
setblock ~173 ~123 ~93 dirt
setblock ~173 ~123 ~94 dirt
setblock ~173 ~123 ~95 dirt
setblock ~173 ~123 ~96 dirt
setblock ~173 ~123 ~97 dirt
setblock ~173 ~123 ~98 dirt
setblock ~173 ~123 ~99 dirt
setblock ~173 ~123 ~100 dirt
setblock ~173 ~123 ~101 dirt
setblock ~173 ~123 ~102 dirt
setblock ~173 ~123 ~103 dirt
setblock ~173 ~123 ~104 dirt
setblock ~173 ~123 ~105 dirt
setblock ~173 ~123 ~106 dirt
setblock ~173 ~123 ~107 dirt
setblock ~173 ~124 ~88 grass_block
setblock ~173 ~124 ~89 grass_block
setblock ~173 ~124 ~90 grass_block
setblock ~173 ~124 ~91 grass_block
setblock ~173 ~124 ~92 grass_block
setblock ~173 ~124 ~93 grass_block
setblock ~173 ~124 ~94 grass_block
setblock ~173 ~124 ~95 grass_block
setblock ~173 ~124 ~96 grass_block
setblock ~173 ~124 ~97 grass_block
setblock ~173 ~124 ~98 grass_block
setblock ~173 ~124 ~99 grass_block
setblock ~173 ~124 ~100 grass_block
setblock ~173 ~124 ~101 grass_block
setblock ~173 ~124 ~102 grass_block
setblock ~173 ~124 ~103 grass_block
setblock ~173 ~124 ~104 grass_block
setblock ~173 ~124 ~105 grass_block
setblock ~173 ~124 ~106 grass_block
setblock ~173 ~124 ~107 grass_block
setblock ~173 ~125 ~88 poppy
setblock ~173 ~125 ~91 short_grass
setblock ~173 ~130 ~108 oak_leaves[persistent=null]
setblock ~173 ~130 ~110 oak_leaves[persistent=null]
setblock ~173 ~130 ~111 oak_leaves[persistent=null]
setblock ~173 ~130 ~112 oak_leaves[persistent=null]
setblock ~173 ~130 ~113 oak_leaves[persistent=null]
setblock ~173 ~131 ~105 oak_leaves[persistent=null]
setblock ~173 ~131 ~106 oak_leaves[persistent=null]
setblock ~173 ~131 ~107 oak_leaves[persistent=null]
setblock ~173 ~131 ~108 oak_leaves[persistent=null]
setblock ~173 ~131 ~111 oak_leaves[persistent=null]
setblock ~173 ~131 ~112 oak_leaves[persistent=null]
setblock ~173 ~131 ~113 jungle_leaves[persistent=null]
setblock ~173 ~132 ~102 oak_leaves[persistent=null]
setblock ~173 ~132 ~103 oak_leaves[persistent=null]
setblock ~173 ~132 ~104 jungle_leaves[persistent=null]
setblock ~173 ~132 ~105 oak_leaves[persistent=null]
setblock ~173 ~132 ~106 oak_leaves[persistent=null]
setblock ~173 ~132 ~107 oak_leaves[persistent=null]
setblock ~173 ~132 ~108 oak_leaves[persistent=null]
setblock ~173 ~132 ~109 jungle_leaves[persistent=null]
setblock ~173 ~132 ~110 jungle_leaves[persistent=null]
setblock ~173 ~132 ~111 oak_leaves[persistent=null]
setblock ~173 ~132 ~113 jungle_leaves[persistent=null]
setblock ~173 ~133 ~102 oak_leaves[persistent=null]
setblock ~173 ~133 ~103 oak_leaves[persistent=null]
setblock ~173 ~133 ~104 oak_leaves[persistent=null]
setblock ~173 ~133 ~107 oak_wood
setblock ~173 ~133 ~108 oak_wood
setblock ~173 ~133 ~109 oak_leaves[persistent=null]
setblock ~173 ~133 ~110 oak_leaves[persistent=null]
setblock ~173 ~133 ~112 oak_leaves[persistent=null]
setblock ~173 ~134 ~105 oak_leaves[persistent=null]
setblock ~173 ~134 ~106 oak_wood
setblock ~173 ~134 ~107 oak_leaves[persistent=null]
setblock ~173 ~134 ~108 oak_leaves[persistent=null]
setblock ~173 ~134 ~109 oak_leaves[persistent=null]
setblock ~173 ~134 ~110 jungle_leaves[persistent=null]
setblock ~173 ~134 ~111 oak_wood
setblock ~173 ~134 ~112 oak_leaves[persistent=null]
setblock ~173 ~134 ~113 oak_leaves[persistent=null]
setblock ~173 ~135 ~103 oak_leaves[persistent=null]
setblock ~173 ~135 ~105 jungle_leaves[persistent=null]
setblock ~173 ~135 ~107 oak_leaves[persistent=null]
setblock ~173 ~135 ~108 oak_leaves[persistent=null]
setblock ~173 ~135 ~109 oak_wood
setblock ~173 ~135 ~110 oak_wood
setblock ~173 ~135 ~111 oak_log
setblock ~173 ~136 ~108 oak_leaves[persistent=null]
setblock ~173 ~136 ~109 jungle_leaves[persistent=null]
setblock ~173 ~136 ~110 oak_log
setblock ~173 ~136 ~111 oak_leaves[persistent=null]
setblock ~173 ~136 ~112 oak_log
setblock ~173 ~136 ~113 oak_leaves[persistent=null]
setblock ~173 ~137 ~107 oak_leaves[persistent=null]
setblock ~173 ~137 ~109 oak_leaves[persistent=null]
setblock ~173 ~137 ~110 oak_leaves[persistent=null]
setblock ~173 ~137 ~111 oak_leaves[persistent=null]
setblock ~173 ~137 ~113 oak_leaves[persistent=null]
setblock ~174 ~111 ~95 dirt
setblock ~174 ~111 ~98 dirt
setblock ~174 ~112 ~95 dirt
setblock ~174 ~112 ~97 dirt
setblock ~174 ~112 ~98 dirt
setblock ~174 ~112 ~99 dirt
setblock ~174 ~113 ~94 dirt
setblock ~174 ~113 ~95 dirt
setblock ~174 ~113 ~96 dirt
setblock ~174 ~113 ~97 dirt
setblock ~174 ~113 ~98 dirt
setblock ~174 ~113 ~99 dirt
setblock ~174 ~114 ~94 dirt
setblock ~174 ~114 ~95 dirt
setblock ~174 ~114 ~96 dirt
setblock ~174 ~114 ~97 dirt
setblock ~174 ~114 ~98 dirt
setblock ~174 ~114 ~99 dirt
setblock ~174 ~115 ~93 dirt
setblock ~174 ~115 ~94 dirt
setblock ~174 ~115 ~95 dirt
setblock ~174 ~115 ~96 dirt
setblock ~174 ~115 ~97 dirt
setblock ~174 ~115 ~98 dirt
setblock ~174 ~115 ~99 dirt
setblock ~174 ~116 ~92 dirt
setblock ~174 ~116 ~93 dirt
setblock ~174 ~116 ~94 dirt
setblock ~174 ~116 ~95 dirt
setblock ~174 ~116 ~96 dirt
setblock ~174 ~116 ~97 dirt
setblock ~174 ~116 ~98 dirt
setblock ~174 ~116 ~99 dirt
setblock ~174 ~116 ~100 dirt
setblock ~174 ~116 ~102 dirt
setblock ~174 ~117 ~91 dirt
setblock ~174 ~117 ~92 dirt
setblock ~174 ~117 ~93 dirt
setblock ~174 ~117 ~94 dirt
setblock ~174 ~117 ~95 dirt
setblock ~174 ~117 ~96 dirt
setblock ~174 ~117 ~97 dirt
setblock ~174 ~117 ~98 dirt
setblock ~174 ~117 ~99 dirt
setblock ~174 ~117 ~100 dirt
setblock ~174 ~117 ~101 dirt
setblock ~174 ~117 ~102 dirt
setblock ~174 ~117 ~103 dirt
setblock ~174 ~118 ~91 dirt
setblock ~174 ~118 ~92 dirt
setblock ~174 ~118 ~93 dirt
setblock ~174 ~118 ~94 dirt
setblock ~174 ~118 ~95 dirt
setblock ~174 ~118 ~96 dirt
setblock ~174 ~118 ~97 dirt
setblock ~174 ~118 ~98 dirt
setblock ~174 ~118 ~99 dirt
setblock ~174 ~118 ~100 dirt
setblock ~174 ~118 ~101 dirt
setblock ~174 ~118 ~102 dirt
setblock ~174 ~118 ~103 dirt
setblock ~174 ~118 ~104 dirt
setblock ~174 ~118 ~105 dirt
setblock ~174 ~119 ~90 dirt
setblock ~174 ~119 ~91 dirt
setblock ~174 ~119 ~92 dirt
setblock ~174 ~119 ~93 dirt
setblock ~174 ~119 ~94 dirt
setblock ~174 ~119 ~95 dirt
setblock ~174 ~119 ~96 dirt
setblock ~174 ~119 ~97 dirt
setblock ~174 ~119 ~98 dirt
setblock ~174 ~119 ~99 dirt
setblock ~174 ~119 ~100 dirt
setblock ~174 ~119 ~101 dirt
setblock ~174 ~119 ~102 dirt
setblock ~174 ~119 ~103 dirt
setblock ~174 ~119 ~104 dirt
setblock ~174 ~119 ~105 dirt
setblock ~174 ~120 ~90 dirt
setblock ~174 ~120 ~91 dirt
setblock ~174 ~120 ~92 dirt
setblock ~174 ~120 ~93 dirt
setblock ~174 ~120 ~94 dirt
setblock ~174 ~120 ~95 dirt
setblock ~174 ~120 ~96 dirt
setblock ~174 ~120 ~97 dirt
setblock ~174 ~120 ~98 dirt
setblock ~174 ~120 ~99 dirt
setblock ~174 ~120 ~100 dirt
setblock ~174 ~120 ~101 dirt
setblock ~174 ~120 ~102 dirt
setblock ~174 ~120 ~103 dirt
setblock ~174 ~120 ~104 dirt
setblock ~174 ~120 ~105 dirt
setblock ~174 ~120 ~106 dirt
setblock ~174 ~121 ~89 dirt
setblock ~174 ~121 ~90 dirt
setblock ~174 ~121 ~91 dirt
setblock ~174 ~121 ~92 dirt
setblock ~174 ~121 ~93 dirt
setblock ~174 ~121 ~94 dirt
setblock ~174 ~121 ~95 dirt
setblock ~174 ~121 ~96 dirt
setblock ~174 ~121 ~97 dirt
setblock ~174 ~121 ~98 dirt
setblock ~174 ~121 ~99 dirt
setblock ~174 ~121 ~100 dirt
setblock ~174 ~121 ~101 dirt
setblock ~174 ~121 ~102 dirt
setblock ~174 ~121 ~103 dirt
setblock ~174 ~121 ~104 dirt
setblock ~174 ~121 ~105 dirt
setblock ~174 ~121 ~106 dirt
setblock ~174 ~121 ~107 dirt
setblock ~174 ~122 ~89 dirt
setblock ~174 ~122 ~90 dirt
setblock ~174 ~122 ~91 dirt
setblock ~174 ~122 ~92 dirt
setblock ~174 ~122 ~93 dirt
setblock ~174 ~122 ~94 dirt
setblock ~174 ~122 ~95 dirt
setblock ~174 ~122 ~96 dirt
setblock ~174 ~122 ~97 dirt
setblock ~174 ~122 ~98 dirt
setblock ~174 ~122 ~99 dirt
setblock ~174 ~122 ~100 dirt
setblock ~174 ~122 ~101 dirt
setblock ~174 ~122 ~102 dirt
setblock ~174 ~122 ~103 dirt
setblock ~174 ~122 ~104 dirt
setblock ~174 ~122 ~105 dirt
setblock ~174 ~122 ~106 dirt
setblock ~174 ~122 ~107 dirt
setblock ~174 ~123 ~89 dirt
setblock ~174 ~123 ~90 dirt
setblock ~174 ~123 ~91 dirt
setblock ~174 ~123 ~92 dirt
setblock ~174 ~123 ~93 dirt
setblock ~174 ~123 ~94 dirt
setblock ~174 ~123 ~95 dirt
setblock ~174 ~123 ~96 dirt
setblock ~174 ~123 ~97 dirt
setblock ~174 ~123 ~98 dirt
setblock ~174 ~123 ~99 dirt
setblock ~174 ~123 ~100 dirt
setblock ~174 ~123 ~101 dirt
setblock ~174 ~123 ~102 dirt
setblock ~174 ~123 ~103 dirt
setblock ~174 ~123 ~104 dirt
setblock ~174 ~123 ~105 dirt
setblock ~174 ~123 ~106 dirt
setblock ~174 ~123 ~107 dirt
setblock ~174 ~124 ~89 grass_block
setblock ~174 ~124 ~90 grass_block
setblock ~174 ~124 ~91 grass_block
setblock ~174 ~124 ~92 grass_block
setblock ~174 ~124 ~93 grass_block
setblock ~174 ~124 ~94 grass_block
setblock ~174 ~124 ~95 grass_block
setblock ~174 ~124 ~96 grass_block
setblock ~174 ~124 ~97 grass_block
setblock ~174 ~124 ~98 grass_block
setblock ~174 ~124 ~99 grass_block
setblock ~174 ~124 ~100 grass_block
setblock ~174 ~124 ~101 grass_block
setblock ~174 ~124 ~102 grass_block
setblock ~174 ~124 ~103 grass_block
setblock ~174 ~124 ~104 grass_block
setblock ~174 ~124 ~105 grass_block
setblock ~174 ~124 ~106 grass_block
setblock ~174 ~124 ~107 grass_block
setblock ~174 ~125 ~102 poppy
setblock ~174 ~130 ~108 oak_leaves[persistent=null]
setblock ~174 ~130 ~109 oak_leaves[persistent=null]
setblock ~174 ~130 ~110 oak_leaves[persistent=null]
setblock ~174 ~130 ~113 jungle_leaves[persistent=null]
setblock ~174 ~131 ~105 oak_leaves[persistent=null]
setblock ~174 ~131 ~107 jungle_leaves[persistent=null]
setblock ~174 ~131 ~108 oak_leaves[persistent=null]
setblock ~174 ~131 ~109 oak_leaves[persistent=null]
setblock ~174 ~131 ~110 jungle_leaves[persistent=null]
setblock ~174 ~131 ~111 oak_leaves[persistent=null]
setblock ~174 ~131 ~112 oak_leaves[persistent=null]
setblock ~174 ~131 ~113 oak_leaves[persistent=null]
setblock ~174 ~132 ~102 oak_leaves[persistent=null]
setblock ~174 ~132 ~103 jungle_leaves[persistent=null]
setblock ~174 ~132 ~104 oak_leaves[persistent=null]
setblock ~174 ~132 ~105 oak_leaves[persistent=null]
setblock ~174 ~132 ~106 oak_leaves[persistent=null]
setblock ~174 ~132 ~107 oak_leaves[persistent=null]
setblock ~174 ~132 ~108 jungle_leaves[persistent=null]
setblock ~174 ~132 ~111 oak_leaves[persistent=null]
setblock ~174 ~132 ~112 oak_leaves[persistent=null]
setblock ~174 ~132 ~113 oak_leaves[persistent=null]
setblock ~174 ~133 ~103 oak_leaves[persistent=null]
setblock ~174 ~133 ~104 oak_leaves[persistent=null]
setblock ~174 ~133 ~105 oak_leaves[persistent=null]
setblock ~174 ~133 ~106 oak_leaves[persistent=null]
setblock ~174 ~133 ~107 oak_wood
setblock ~174 ~133 ~108 oak_wood
setblock ~174 ~133 ~111 oak_leaves[persistent=null]
setblock ~174 ~133 ~112 oak_leaves[persistent=null]
setblock ~174 ~133 ~113 jungle_leaves[persistent=null]
setblock ~174 ~134 ~102 oak_leaves[persistent=null]
setblock ~174 ~134 ~105 oak_wood
setblock ~174 ~134 ~106 oak_leaves[persistent=null]
setblock ~174 ~134 ~107 oak_leaves[persistent=null]
setblock ~174 ~134 ~111 oak_wood
setblock ~174 ~134 ~112 oak_wood
setblock ~174 ~134 ~113 oak_leaves[persistent=null]
setblock ~174 ~135 ~102 oak_leaves[persistent=null]
setblock ~174 ~135 ~103 oak_leaves[persistent=null]
setblock ~174 ~135 ~104 oak_leaves[persistent=null]
setblock ~174 ~135 ~105 oak_leaves[persistent=null]
setblock ~174 ~135 ~106 oak_leaves[persistent=null]
setblock ~174 ~135 ~107 oak_leaves[persistent=null]
setblock ~174 ~135 ~108 oak_leaves[persistent=null]
setblock ~174 ~135 ~109 oak_wood
setblock ~174 ~135 ~111 oak_wood
setblock ~174 ~135 ~112 oak_leaves[persistent=null]
setblock ~174 ~135 ~113 oak_leaves[persistent=null]
setblock ~174 ~136 ~107 oak_leaves[persistent=null]
setblock ~174 ~136 ~108 oak_leaves[persistent=null]
setblock ~174 ~136 ~109 oak_leaves[persistent=null]
setblock ~174 ~136 ~110 oak_leaves[persistent=null]
setblock ~174 ~136 ~111 oak_leaves[persistent=null]
setblock ~174 ~136 ~112 oak_leaves[persistent=null]
setblock ~174 ~136 ~113 oak_leaves[persistent=null]
setblock ~174 ~137 ~107 oak_leaves[persistent=null]
setblock ~174 ~137 ~110 oak_leaves[persistent=null]
setblock ~174 ~137 ~112 oak_leaves[persistent=null]
setblock ~174 ~137 ~113 oak_leaves[persistent=null]
setblock ~175 ~112 ~98 dirt
setblock ~175 ~113 ~95 dirt
setblock ~175 ~113 ~98 dirt
setblock ~175 ~114 ~95 dirt
setblock ~175 ~114 ~96 dirt
setblock ~175 ~114 ~97 dirt
setblock ~175 ~114 ~98 dirt
setblock ~175 ~115 ~94 dirt
setblock ~175 ~115 ~95 dirt
setblock ~175 ~115 ~96 dirt
