setblock ~166 ~121 ~95 dirt
setblock ~166 ~121 ~96 dirt
setblock ~166 ~121 ~97 dirt
setblock ~166 ~121 ~98 dirt
setblock ~166 ~121 ~99 dirt
setblock ~166 ~121 ~100 dirt
setblock ~166 ~121 ~101 dirt
setblock ~166 ~121 ~102 dirt
setblock ~166 ~121 ~103 dirt
setblock ~166 ~121 ~104 dirt
setblock ~166 ~121 ~105 dirt
setblock ~166 ~121 ~106 dirt
setblock ~166 ~121 ~107 dirt
setblock ~166 ~121 ~108 dirt
setblock ~166 ~121 ~109 dirt
setblock ~166 ~121 ~110 dirt
setblock ~166 ~121 ~111 dirt
setblock ~166 ~121 ~120 dirt
setblock ~166 ~121 ~121 dirt
setblock ~166 ~121 ~122 dirt
setblock ~166 ~121 ~131 dirt
setblock ~166 ~121 ~132 dirt
setblock ~166 ~121 ~133 dirt
setblock ~166 ~121 ~134 dirt
setblock ~166 ~122 ~65 dirt
setblock ~166 ~122 ~66 dirt
setblock ~166 ~122 ~67 dirt
setblock ~166 ~122 ~68 dirt
setblock ~166 ~122 ~69 dirt
setblock ~166 ~122 ~70 dirt
setblock ~166 ~122 ~71 dirt
setblock ~166 ~122 ~72 dirt
setblock ~166 ~122 ~73 dirt
setblock ~166 ~122 ~74 dirt
setblock ~166 ~122 ~75 dirt
setblock ~166 ~122 ~76 dirt
setblock ~166 ~122 ~77 dirt
setblock ~166 ~122 ~78 dirt
setblock ~166 ~122 ~79 dirt
setblock ~166 ~122 ~80 dirt
setblock ~166 ~122 ~81 dirt
setblock ~166 ~122 ~82 dirt
setblock ~166 ~122 ~83 dirt
setblock ~166 ~122 ~84 dirt
setblock ~166 ~122 ~85 dirt
setblock ~166 ~122 ~86 dirt
setblock ~166 ~122 ~87 dirt
setblock ~166 ~122 ~88 dirt
setblock ~166 ~122 ~89 dirt
setblock ~166 ~122 ~90 dirt
setblock ~166 ~122 ~91 dirt
setblock ~166 ~122 ~92 dirt
setblock ~166 ~122 ~93 dirt
setblock ~166 ~122 ~94 dirt
setblock ~166 ~122 ~95 dirt
setblock ~166 ~122 ~96 dirt
setblock ~166 ~122 ~97 dirt
setblock ~166 ~122 ~98 dirt
setblock ~166 ~122 ~99 dirt
setblock ~166 ~122 ~100 dirt
setblock ~166 ~122 ~101 dirt
setblock ~166 ~122 ~102 dirt
setblock ~166 ~122 ~103 dirt
setblock ~166 ~122 ~104 dirt
setblock ~166 ~122 ~105 dirt
setblock ~166 ~122 ~106 dirt
setblock ~166 ~122 ~107 dirt
setblock ~166 ~122 ~108 dirt
setblock ~166 ~122 ~109 dirt
setblock ~166 ~122 ~110 dirt
setblock ~166 ~122 ~111 dirt
setblock ~166 ~122 ~120 dirt
setblock ~166 ~122 ~121 dirt
setblock ~166 ~122 ~122 dirt
setblock ~166 ~122 ~131 dirt
setblock ~166 ~122 ~132 dirt
setblock ~166 ~122 ~133 dirt
setblock ~166 ~122 ~134 dirt
setblock ~166 ~123 ~65 dirt
setblock ~166 ~123 ~66 dirt
setblock ~166 ~123 ~67 dirt
setblock ~166 ~123 ~68 dirt
setblock ~166 ~123 ~69 dirt
setblock ~166 ~123 ~70 dirt
setblock ~166 ~123 ~71 dirt
setblock ~166 ~123 ~72 dirt
setblock ~166 ~123 ~73 dirt
setblock ~166 ~123 ~74 dirt
setblock ~166 ~123 ~75 dirt
setblock ~166 ~123 ~76 dirt
setblock ~166 ~123 ~77 dirt
setblock ~166 ~123 ~78 dirt
setblock ~166 ~123 ~79 dirt
setblock ~166 ~123 ~80 dirt
setblock ~166 ~123 ~81 dirt
setblock ~166 ~123 ~82 dirt
setblock ~166 ~123 ~83 dirt
setblock ~166 ~123 ~84 dirt
setblock ~166 ~123 ~85 dirt
setblock ~166 ~123 ~86 dirt
setblock ~166 ~123 ~87 dirt
setblock ~166 ~123 ~88 dirt
setblock ~166 ~123 ~89 dirt
setblock ~166 ~123 ~90 dirt
setblock ~166 ~123 ~91 dirt
setblock ~166 ~123 ~92 dirt
setblock ~166 ~123 ~93 dirt
setblock ~166 ~123 ~94 dirt
setblock ~166 ~123 ~95 dirt
setblock ~166 ~123 ~96 dirt
setblock ~166 ~123 ~97 dirt
setblock ~166 ~123 ~98 dirt
setblock ~166 ~123 ~99 dirt
setblock ~166 ~123 ~100 dirt
setblock ~166 ~123 ~101 dirt
setblock ~166 ~123 ~102 dirt
setblock ~166 ~123 ~103 dirt
setblock ~166 ~123 ~104 dirt
setblock ~166 ~123 ~105 dirt
setblock ~166 ~123 ~106 dirt
setblock ~166 ~123 ~107 dirt
setblock ~166 ~123 ~108 dirt
setblock ~166 ~123 ~109 dirt
setblock ~166 ~123 ~110 dirt
setblock ~166 ~123 ~111 dirt
setblock ~166 ~123 ~120 dirt
setblock ~166 ~123 ~121 dirt
setblock ~166 ~123 ~122 dirt
setblock ~166 ~123 ~131 dirt
setblock ~166 ~123 ~132 dirt
setblock ~166 ~123 ~133 dirt
setblock ~166 ~123 ~134 dirt
setblock ~166 ~124 ~65 grass_block
setblock ~166 ~124 ~66 dirt
setblock ~166 ~124 ~67 dirt
setblock ~166 ~124 ~68 dirt
setblock ~166 ~124 ~69 dirt
setblock ~166 ~124 ~70 dirt
setblock ~166 ~124 ~71 dirt
setblock ~166 ~124 ~72 dirt
setblock ~166 ~124 ~73 dirt
setblock ~166 ~124 ~74 dirt
setblock ~166 ~124 ~75 dirt
setblock ~166 ~124 ~76 dirt
setblock ~166 ~124 ~77 dirt
setblock ~166 ~124 ~78 dirt
setblock ~166 ~124 ~79 dirt
setblock ~166 ~124 ~80 dirt
setblock ~166 ~124 ~81 dirt
setblock ~166 ~124 ~82 dirt
setblock ~166 ~124 ~83 dirt
setblock ~166 ~124 ~84 dirt
setblock ~166 ~124 ~85 dirt
setblock ~166 ~124 ~86 dirt
setblock ~166 ~124 ~87 dirt
setblock ~166 ~124 ~88 dirt
setblock ~166 ~124 ~89 dirt
setblock ~166 ~124 ~90 dirt
setblock ~166 ~124 ~91 dirt
setblock ~166 ~124 ~92 dirt
setblock ~166 ~124 ~93 dirt
setblock ~166 ~124 ~94 dirt
setblock ~166 ~124 ~95 dirt
setblock ~166 ~124 ~96 dirt
setblock ~166 ~124 ~97 dirt
setblock ~166 ~124 ~98 dirt
setblock ~166 ~124 ~99 dirt
setblock ~166 ~124 ~100 dirt
setblock ~166 ~124 ~101 dirt
setblock ~166 ~124 ~102 dirt
setblock ~166 ~124 ~103 dirt
setblock ~166 ~124 ~104 dirt
setblock ~166 ~124 ~105 dirt
setblock ~166 ~124 ~106 dirt
setblock ~166 ~124 ~107 dirt
setblock ~166 ~124 ~108 grass_block
setblock ~166 ~124 ~109 grass_block
setblock ~166 ~124 ~110 grass_block
setblock ~166 ~124 ~111 dirt
setblock ~166 ~124 ~120 dirt
setblock ~166 ~124 ~121 dirt
setblock ~166 ~124 ~122 dirt
setblock ~166 ~124 ~131 dirt
setblock ~166 ~124 ~132 dirt
setblock ~166 ~124 ~133 dirt
setblock ~166 ~124 ~134 dirt
setblock ~166 ~125 ~66 grass_block
setblock ~166 ~125 ~67 grass_block
setblock ~166 ~125 ~68 grass_block
setblock ~166 ~125 ~69 grass_block
setblock ~166 ~125 ~70 dirt
setblock ~166 ~125 ~71 dirt
setblock ~166 ~125 ~72 dirt
setblock ~166 ~125 ~73 dirt
setblock ~166 ~125 ~74 dirt
setblock ~166 ~125 ~75 dirt
setblock ~166 ~125 ~76 dirt
setblock ~166 ~125 ~77 dirt
setblock ~166 ~125 ~78 dirt
setblock ~166 ~125 ~79 dirt
setblock ~166 ~125 ~80 dirt
setblock ~166 ~125 ~81 dirt
setblock ~166 ~125 ~82 dirt
setblock ~166 ~125 ~83 dirt
setblock ~166 ~125 ~84 dirt
setblock ~166 ~125 ~85 dirt
setblock ~166 ~125 ~86 dirt
setblock ~166 ~125 ~87 dirt
setblock ~166 ~125 ~88 dirt
setblock ~166 ~125 ~89 dirt
setblock ~166 ~125 ~90 grass_block
setblock ~166 ~125 ~91 grass_block
setblock ~166 ~125 ~92 grass_block
setblock ~166 ~125 ~93 grass_block
setblock ~166 ~125 ~94 grass_block
setblock ~166 ~125 ~95 grass_block
setblock ~166 ~125 ~96 grass_block
setblock ~166 ~125 ~97 grass_block
setblock ~166 ~125 ~98 grass_block
setblock ~166 ~125 ~99 grass_block
setblock ~166 ~125 ~100 grass_block
setblock ~166 ~125 ~101 grass_block
setblock ~166 ~125 ~102 grass_block
setblock ~166 ~125 ~103 grass_block
setblock ~166 ~125 ~104 grass_block
setblock ~166 ~125 ~105 grass_block
setblock ~166 ~125 ~106 grass_block
setblock ~166 ~125 ~107 grass_block
setblock ~166 ~125 ~111 grass_block
setblock ~166 ~125 ~120 dirt
setblock ~166 ~125 ~121 dirt
setblock ~166 ~125 ~122 dirt
setblock ~166 ~125 ~131 dirt
setblock ~166 ~125 ~132 dirt
setblock ~166 ~125 ~133 dirt
setblock ~166 ~125 ~134 dirt
setblock ~166 ~126 ~66 short_grass
setblock ~166 ~126 ~67 short_grass
setblock ~166 ~126 ~70 grass_block
setblock ~166 ~126 ~71 grass_block
setblock ~166 ~126 ~72 grass_block
setblock ~166 ~126 ~73 dirt
setblock ~166 ~126 ~74 dirt
setblock ~166 ~126 ~75 dirt
setblock ~166 ~126 ~76 dirt
setblock ~166 ~126 ~77 dirt
setblock ~166 ~126 ~78 dirt
setblock ~166 ~126 ~79 dirt
setblock ~166 ~126 ~80 dirt
setblock ~166 ~126 ~81 dirt
setblock ~166 ~126 ~82 dirt
setblock ~166 ~126 ~83 dirt
setblock ~166 ~126 ~84 dirt
setblock ~166 ~126 ~85 dirt
setblock ~166 ~126 ~86 dirt
setblock ~166 ~126 ~87 grass_block
setblock ~166 ~126 ~88 grass_block
setblock ~166 ~126 ~89 grass_block
setblock ~166 ~126 ~94 short_grass
setblock ~166 ~126 ~96 short_grass
setblock ~166 ~126 ~97 short_grass
setblock ~166 ~126 ~98 fern
setblock ~166 ~126 ~99 short_grass
setblock ~166 ~126 ~100 poppy
setblock ~166 ~126 ~102 short_grass
setblock ~166 ~126 ~106 poppy
setblock ~166 ~126 ~111 short_grass
setblock ~166 ~126 ~120 dirt
setblock ~166 ~126 ~121 dirt
setblock ~166 ~126 ~122 dirt
setblock ~166 ~126 ~131 dirt
setblock ~166 ~126 ~132 dirt
setblock ~166 ~126 ~133 dirt
setblock ~166 ~126 ~134 dirt
setblock ~166 ~127 ~72 poppy
setblock ~166 ~127 ~73 grass_block
setblock ~166 ~127 ~74 grass_block
setblock ~166 ~127 ~75 grass_block
setblock ~166 ~127 ~76 dirt
setblock ~166 ~127 ~77 dirt
setblock ~166 ~127 ~78 dirt
setblock ~166 ~127 ~79 dirt
setblock ~166 ~127 ~80 dirt
setblock ~166 ~127 ~81 dirt
setblock ~166 ~127 ~82 dirt
setblock ~166 ~127 ~83 dirt
setblock ~166 ~127 ~84 grass_block
setblock ~166 ~127 ~85 grass_block
setblock ~166 ~127 ~86 grass_block
setblock ~166 ~127 ~89 short_grass
setblock ~166 ~127 ~120 grass_block
setblock ~166 ~127 ~121 grass_block
setblock ~166 ~127 ~122 grass_block
setblock ~166 ~127 ~131 grass_block
setblock ~166 ~127 ~132 grass_block
setblock ~166 ~127 ~133 grass_block
setblock ~166 ~127 ~134 grass_block
setblock ~166 ~128 ~73 short_grass
setblock ~166 ~128 ~75 short_grass
setblock ~166 ~128 ~76 grass_block
setblock ~166 ~128 ~77 grass_block
setblock ~166 ~128 ~78 grass_block
setblock ~166 ~128 ~79 dirt
setblock ~166 ~128 ~80 dirt
setblock ~166 ~128 ~81 dirt
setblock ~166 ~128 ~82 grass_block
setblock ~166 ~128 ~83 grass_block
setblock ~166 ~128 ~120 fern
setblock ~166 ~128 ~121 short_grass
setblock ~166 ~128 ~132 short_grass
setblock ~166 ~128 ~133 poppy
setblock ~166 ~128 ~134 short_grass
setblock ~166 ~129 ~76 poppy
setblock ~166 ~129 ~78 short_grass
setblock ~166 ~129 ~79 grass_block
setblock ~166 ~129 ~80 grass_block
setblock ~166 ~129 ~81 grass_block
setblock ~166 ~132 ~77 oak_leaves[persistent=true]
setblock ~166 ~133 ~77 oak_leaves[persistent=true]
setblock ~166 ~133 ~78 oak_leaves[persistent=true]
setblock ~166 ~135 ~117 oak_leaves[persistent=true]
setblock ~166 ~135 ~118 jungle_leaves[persistent=true]
setblock ~166 ~136 ~117 oak_leaves[persistent=true]
setblock ~166 ~136 ~118 oak_leaves[persistent=true]
setblock ~166 ~136 ~119 oak_leaves[persistent=true]
setblock ~166 ~137 ~69 oak_leaves[persistent=true]
setblock ~166 ~137 ~118 oak_leaves[persistent=true]
setblock ~166 ~137 ~119 jungle_leaves[persistent=true]
setblock ~166 ~138 ~68 oak_leaves[persistent=true]
setblock ~166 ~138 ~70 oak_leaves[persistent=true]
setblock ~166 ~138 ~121 oak_leaves[persistent=true]
setblock ~166 ~138 ~122 oak_leaves[persistent=true]
setblock ~166 ~139 ~68 oak_leaves[persistent=true]
setblock ~166 ~139 ~69 oak_leaves[persistent=true]
setblock ~166 ~139 ~70 oak_leaves[persistent=true]
setblock ~166 ~139 ~120 jungle_leaves[persistent=true]
setblock ~166 ~139 ~121 oak_leaves[persistent=true]
setblock ~166 ~140 ~120 oak_leaves[persistent=true]
setblock ~166 ~140 ~122 oak_leaves[persistent=true]
setblock ~167 ~105 ~81 dirt
setblock ~167 ~106 ~81 dirt
setblock ~167 ~107 ~80 dirt
setblock ~167 ~107 ~81 dirt
setblock ~167 ~107 ~82 dirt
setblock ~167 ~107 ~83 dirt
setblock ~167 ~108 ~79 dirt
setblock ~167 ~108 ~80 dirt
setblock ~167 ~108 ~81 dirt
setblock ~167 ~108 ~82 dirt
setblock ~167 ~108 ~83 dirt
setblock ~167 ~109 ~78 dirt
setblock ~167 ~109 ~79 dirt
setblock ~167 ~109 ~80 dirt
setblock ~167 ~109 ~81 dirt
setblock ~167 ~109 ~82 dirt
setblock ~167 ~109 ~83 dirt
setblock ~167 ~110 ~77 dirt
setblock ~167 ~110 ~78 dirt
setblock ~167 ~110 ~79 dirt
setblock ~167 ~110 ~80 dirt
setblock ~167 ~110 ~81 dirt
setblock ~167 ~110 ~82 dirt
setblock ~167 ~110 ~83 dirt
setblock ~167 ~110 ~84 dirt
setblock ~167 ~111 ~77 dirt
setblock ~167 ~111 ~78 dirt
setblock ~167 ~111 ~79 dirt
setblock ~167 ~111 ~80 dirt
setblock ~167 ~111 ~81 dirt
setblock ~167 ~111 ~82 dirt
setblock ~167 ~111 ~83 dirt
setblock ~167 ~111 ~84 dirt
setblock ~167 ~111 ~87 dirt
setblock ~167 ~112 ~74 dirt
setblock ~167 ~112 ~77 dirt
setblock ~167 ~112 ~78 dirt
setblock ~167 ~112 ~79 dirt
setblock ~167 ~112 ~80 dirt
setblock ~167 ~112 ~81 dirt
setblock ~167 ~112 ~82 dirt
setblock ~167 ~112 ~83 dirt
setblock ~167 ~112 ~84 dirt
setblock ~167 ~112 ~86 dirt
setblock ~167 ~112 ~87 dirt
setblock ~167 ~112 ~88 dirt
setblock ~167 ~113 ~71 dirt
setblock ~167 ~113 ~73 dirt
setblock ~167 ~113 ~74 dirt
setblock ~167 ~113 ~75 dirt
setblock ~167 ~113 ~76 dirt
setblock ~167 ~113 ~77 dirt
setblock ~167 ~113 ~78 dirt
setblock ~167 ~113 ~79 dirt
setblock ~167 ~113 ~80 dirt
setblock ~167 ~113 ~81 dirt
setblock ~167 ~113 ~82 dirt
setblock ~167 ~113 ~83 dirt
setblock ~167 ~113 ~84 dirt
setblock ~167 ~113 ~85 dirt
setblock ~167 ~113 ~86 dirt
setblock ~167 ~113 ~87 dirt
setblock ~167 ~113 ~88 dirt
setblock ~167 ~114 ~71 dirt
setblock ~167 ~114 ~72 dirt
setblock ~167 ~114 ~73 dirt
setblock ~167 ~114 ~74 dirt
setblock ~167 ~114 ~75 dirt
setblock ~167 ~114 ~76 dirt
setblock ~167 ~114 ~77 dirt
setblock ~167 ~114 ~78 dirt
setblock ~167 ~114 ~79 dirt
setblock ~167 ~114 ~80 dirt
setblock ~167 ~114 ~81 dirt
setblock ~167 ~114 ~82 dirt
setblock ~167 ~114 ~83 dirt
setblock ~167 ~114 ~84 dirt
setblock ~167 ~114 ~85 dirt
setblock ~167 ~114 ~86 dirt
setblock ~167 ~114 ~87 dirt
setblock ~167 ~114 ~88 dirt
setblock ~167 ~114 ~91 dirt
setblock ~167 ~115 ~71 dirt
setblock ~167 ~115 ~72 dirt
setblock ~167 ~115 ~73 dirt
setblock ~167 ~115 ~74 dirt
setblock ~167 ~115 ~75 dirt
setblock ~167 ~115 ~76 dirt
setblock ~167 ~115 ~77 dirt
setblock ~167 ~115 ~78 dirt
setblock ~167 ~115 ~79 dirt
setblock ~167 ~115 ~80 dirt
setblock ~167 ~115 ~81 dirt
setblock ~167 ~115 ~82 dirt
setblock ~167 ~115 ~83 dirt
setblock ~167 ~115 ~84 dirt
setblock ~167 ~115 ~85 dirt
setblock ~167 ~115 ~86 dirt
setblock ~167 ~115 ~87 dirt
setblock ~167 ~115 ~88 dirt
setblock ~167 ~115 ~90 dirt
setblock ~167 ~115 ~91 dirt
setblock ~167 ~115 ~100 dirt
setblock ~167 ~115 ~101 dirt
setblock ~167 ~115 ~106 dirt
setblock ~167 ~116 ~70 dirt
setblock ~167 ~116 ~71 dirt
setblock ~167 ~116 ~72 dirt
setblock ~167 ~116 ~73 dirt
setblock ~167 ~116 ~74 dirt
setblock ~167 ~116 ~75 dirt
setblock ~167 ~116 ~76 dirt
setblock ~167 ~116 ~77 dirt
setblock ~167 ~116 ~78 dirt
setblock ~167 ~116 ~79 dirt
setblock ~167 ~116 ~80 dirt
setblock ~167 ~116 ~81 dirt
setblock ~167 ~116 ~82 dirt
setblock ~167 ~116 ~83 dirt
setblock ~167 ~116 ~84 dirt
setblock ~167 ~116 ~85 dirt
setblock ~167 ~116 ~86 dirt
setblock ~167 ~116 ~87 dirt
setblock ~167 ~116 ~88 dirt
setblock ~167 ~116 ~89 dirt
setblock ~167 ~116 ~90 dirt
setblock ~167 ~116 ~91 dirt
setblock ~167 ~116 ~99 dirt
setblock ~167 ~116 ~100 dirt
setblock ~167 ~116 ~101 dirt
setblock ~167 ~116 ~102 dirt
setblock ~167 ~116 ~105 dirt
setblock ~167 ~116 ~106 dirt
setblock ~167 ~116 ~107 dirt
setblock ~167 ~117 ~70 dirt
setblock ~167 ~117 ~71 dirt
setblock ~167 ~117 ~72 dirt
setblock ~167 ~117 ~73 dirt
setblock ~167 ~117 ~74 dirt
setblock ~167 ~117 ~75 dirt
setblock ~167 ~117 ~76 dirt
setblock ~167 ~117 ~77 dirt
setblock ~167 ~117 ~78 dirt
setblock ~167 ~117 ~79 dirt
setblock ~167 ~117 ~80 dirt
setblock ~167 ~117 ~81 dirt
setblock ~167 ~117 ~82 dirt
setblock ~167 ~117 ~83 dirt
setblock ~167 ~117 ~84 dirt
setblock ~167 ~117 ~85 dirt
setblock ~167 ~117 ~86 dirt
setblock ~167 ~117 ~87 dirt
setblock ~167 ~117 ~88 dirt
setblock ~167 ~117 ~89 dirt
setblock ~167 ~117 ~90 dirt
setblock ~167 ~117 ~91 dirt
setblock ~167 ~117 ~92 dirt
setblock ~167 ~117 ~93 dirt
setblock ~167 ~117 ~94 dirt
setblock ~167 ~117 ~97 dirt
setblock ~167 ~117 ~99 dirt
setblock ~167 ~117 ~100 dirt
setblock ~167 ~117 ~101 dirt
setblock ~167 ~117 ~102 dirt
setblock ~167 ~117 ~103 dirt
setblock ~167 ~117 ~105 dirt
setblock ~167 ~117 ~106 dirt
setblock ~167 ~117 ~107 dirt
setblock ~167 ~117 ~108 dirt
setblock ~167 ~118 ~70 dirt
setblock ~167 ~118 ~71 dirt
setblock ~167 ~118 ~72 dirt
setblock ~167 ~118 ~73 dirt
setblock ~167 ~118 ~74 dirt
setblock ~167 ~118 ~75 dirt
setblock ~167 ~118 ~76 dirt
setblock ~167 ~118 ~77 dirt
setblock ~167 ~118 ~78 dirt
setblock ~167 ~118 ~79 dirt
setblock ~167 ~118 ~80 dirt
setblock ~167 ~118 ~81 dirt
setblock ~167 ~118 ~82 dirt
setblock ~167 ~118 ~83 dirt
setblock ~167 ~118 ~84 dirt
setblock ~167 ~118 ~85 dirt
setblock ~167 ~118 ~86 dirt
setblock ~167 ~118 ~87 dirt
setblock ~167 ~118 ~88 dirt
setblock ~167 ~118 ~89 dirt
setblock ~167 ~118 ~90 dirt
setblock ~167 ~118 ~91 dirt
setblock ~167 ~118 ~92 dirt
setblock ~167 ~118 ~93 dirt
setblock ~167 ~118 ~94 dirt
setblock ~167 ~118 ~97 dirt
setblock ~167 ~118 ~98 dirt
setblock ~167 ~118 ~99 dirt
setblock ~167 ~118 ~100 dirt
setblock ~167 ~118 ~101 dirt
setblock ~167 ~118 ~102 dirt
setblock ~167 ~118 ~103 dirt
setblock ~167 ~118 ~104 dirt
setblock ~167 ~118 ~105 dirt
setblock ~167 ~118 ~106 dirt
setblock ~167 ~118 ~107 dirt
setblock ~167 ~118 ~108 dirt
setblock ~167 ~119 ~69 dirt
setblock ~167 ~119 ~70 dirt
setblock ~167 ~119 ~71 dirt
setblock ~167 ~119 ~72 dirt
setblock ~167 ~119 ~73 dirt
setblock ~167 ~119 ~74 dirt
setblock ~167 ~119 ~75 dirt
setblock ~167 ~119 ~76 dirt
setblock ~167 ~119 ~77 dirt
setblock ~167 ~119 ~78 dirt
setblock ~167 ~119 ~79 dirt
setblock ~167 ~119 ~80 dirt
setblock ~167 ~119 ~81 dirt
setblock ~167 ~119 ~82 dirt
setblock ~167 ~119 ~83 dirt
setblock ~167 ~119 ~84 dirt
setblock ~167 ~119 ~85 dirt
setblock ~167 ~119 ~86 dirt
setblock ~167 ~119 ~87 dirt
setblock ~167 ~119 ~88 dirt
setblock ~167 ~119 ~89 dirt
setblock ~167 ~119 ~90 dirt
setblock ~167 ~119 ~91 dirt
setblock ~167 ~119 ~92 dirt
setblock ~167 ~119 ~93 dirt
setblock ~167 ~119 ~94 dirt
setblock ~167 ~119 ~95 dirt
setblock ~167 ~119 ~97 dirt
setblock ~167 ~119 ~98 dirt
setblock ~167 ~119 ~99 dirt
setblock ~167 ~119 ~100 dirt
setblock ~167 ~119 ~101 dirt
setblock ~167 ~119 ~102 dirt
setblock ~167 ~119 ~103 dirt
setblock ~167 ~119 ~104 dirt
setblock ~167 ~119 ~105 dirt
setblock ~167 ~119 ~106 dirt
setblock ~167 ~119 ~107 dirt
setblock ~167 ~119 ~108 dirt
setblock ~167 ~119 ~109 dirt
setblock ~167 ~120 ~67 dirt
setblock ~167 ~120 ~68 dirt
setblock ~167 ~120 ~69 dirt
setblock ~167 ~120 ~70 dirt
setblock ~167 ~120 ~71 dirt
setblock ~167 ~120 ~72 dirt
setblock ~167 ~120 ~73 dirt
setblock ~167 ~120 ~74 dirt
setblock ~167 ~120 ~75 dirt
setblock ~167 ~120 ~76 dirt
setblock ~167 ~120 ~77 dirt
setblock ~167 ~120 ~78 dirt
setblock ~167 ~120 ~79 dirt
setblock ~167 ~120 ~80 dirt
setblock ~167 ~120 ~81 dirt
setblock ~167 ~120 ~82 dirt
setblock ~167 ~120 ~83 dirt
setblock ~167 ~120 ~84 dirt
setblock ~167 ~120 ~85 dirt
setblock ~167 ~120 ~86 dirt
setblock ~167 ~120 ~87 dirt
setblock ~167 ~120 ~88 dirt
setblock ~167 ~120 ~89 dirt
setblock ~167 ~120 ~90 dirt
setblock ~167 ~120 ~91 dirt
setblock ~167 ~120 ~92 dirt
setblock ~167 ~120 ~93 dirt
setblock ~167 ~120 ~94 dirt
setblock ~167 ~120 ~95 dirt
setblock ~167 ~120 ~96 dirt
setblock ~167 ~120 ~97 dirt
setblock ~167 ~120 ~98 dirt
setblock ~167 ~120 ~99 dirt
setblock ~167 ~120 ~100 dirt
setblock ~167 ~120 ~101 dirt
setblock ~167 ~120 ~102 dirt
setblock ~167 ~120 ~103 dirt
setblock ~167 ~120 ~104 dirt
setblock ~167 ~120 ~105 dirt
setblock ~167 ~120 ~106 dirt
setblock ~167 ~120 ~107 dirt
setblock ~167 ~120 ~108 dirt
setblock ~167 ~120 ~109 dirt
setblock ~167 ~120 ~110 dirt
setblock ~167 ~121 ~66 dirt
setblock ~167 ~121 ~67 dirt
setblock ~167 ~121 ~68 dirt
setblock ~167 ~121 ~69 dirt
setblock ~167 ~121 ~70 dirt
setblock ~167 ~121 ~71 dirt
setblock ~167 ~121 ~72 dirt
setblock ~167 ~121 ~73 dirt
setblock ~167 ~121 ~74 dirt
setblock ~167 ~121 ~75 dirt
setblock ~167 ~121 ~76 dirt
setblock ~167 ~121 ~77 dirt
setblock ~167 ~121 ~78 dirt
setblock ~167 ~121 ~79 dirt
setblock ~167 ~121 ~80 dirt
setblock ~167 ~121 ~81 dirt
setblock ~167 ~121 ~82 dirt
setblock ~167 ~121 ~83 dirt
setblock ~167 ~121 ~84 dirt
setblock ~167 ~121 ~85 dirt
setblock ~167 ~121 ~86 dirt
setblock ~167 ~121 ~87 dirt
setblock ~167 ~121 ~88 dirt
setblock ~167 ~121 ~89 dirt
setblock ~167 ~121 ~90 dirt
setblock ~167 ~121 ~91 dirt
setblock ~167 ~121 ~92 dirt
setblock ~167 ~121 ~93 dirt
setblock ~167 ~121 ~94 dirt
setblock ~167 ~121 ~95 dirt
setblock ~167 ~121 ~96 dirt
setblock ~167 ~121 ~97 dirt
setblock ~167 ~121 ~98 dirt
setblock ~167 ~121 ~99 dirt
setblock ~167 ~121 ~100 dirt
setblock ~167 ~121 ~101 dirt
setblock ~167 ~121 ~102 dirt
setblock ~167 ~121 ~103 dirt
setblock ~167 ~121 ~104 dirt
setblock ~167 ~121 ~105 dirt
setblock ~167 ~121 ~106 dirt
setblock ~167 ~121 ~107 dirt
setblock ~167 ~121 ~108 dirt
setblock ~167 ~121 ~109 dirt
setblock ~167 ~121 ~110 dirt
setblock ~167 ~121 ~121 dirt
setblock ~167 ~121 ~133 dirt
setblock ~167 ~122 ~66 dirt
setblock ~167 ~122 ~67 dirt
setblock ~167 ~122 ~68 dirt
setblock ~167 ~122 ~69 dirt
setblock ~167 ~122 ~70 dirt
setblock ~167 ~122 ~71 dirt
setblock ~167 ~122 ~72 dirt
setblock ~167 ~122 ~73 dirt
setblock ~167 ~122 ~74 dirt
setblock ~167 ~122 ~75 dirt
setblock ~167 ~122 ~76 dirt
setblock ~167 ~122 ~77 dirt
setblock ~167 ~122 ~78 dirt
setblock ~167 ~122 ~79 dirt
setblock ~167 ~122 ~80 dirt
setblock ~167 ~122 ~81 dirt
setblock ~167 ~122 ~82 dirt
setblock ~167 ~122 ~83 dirt
setblock ~167 ~122 ~84 dirt
setblock ~167 ~122 ~85 dirt
setblock ~167 ~122 ~86 dirt
setblock ~167 ~122 ~87 dirt
setblock ~167 ~122 ~88 dirt
setblock ~167 ~122 ~89 dirt
setblock ~167 ~122 ~90 dirt
setblock ~167 ~122 ~91 dirt
setblock ~167 ~122 ~92 dirt
setblock ~167 ~122 ~93 dirt
setblock ~167 ~122 ~94 dirt
setblock ~167 ~122 ~95 dirt
setblock ~167 ~122 ~96 dirt
setblock ~167 ~122 ~97 dirt
setblock ~167 ~122 ~98 dirt
setblock ~167 ~122 ~99 dirt
setblock ~167 ~122 ~100 dirt
setblock ~167 ~122 ~101 dirt
setblock ~167 ~122 ~102 dirt
setblock ~167 ~122 ~103 dirt
setblock ~167 ~122 ~104 dirt
setblock ~167 ~122 ~105 dirt
setblock ~167 ~122 ~106 dirt
setblock ~167 ~122 ~107 dirt
setblock ~167 ~122 ~108 dirt
setblock ~167 ~122 ~109 dirt
setblock ~167 ~122 ~110 dirt
setblock ~167 ~122 ~121 dirt
setblock ~167 ~122 ~133 dirt
setblock ~167 ~123 ~66 dirt
setblock ~167 ~123 ~67 dirt
setblock ~167 ~123 ~68 dirt
setblock ~167 ~123 ~69 dirt
setblock ~167 ~123 ~70 dirt
setblock ~167 ~123 ~71 dirt
setblock ~167 ~123 ~72 dirt
setblock ~167 ~123 ~73 dirt
setblock ~167 ~123 ~74 dirt
setblock ~167 ~123 ~75 dirt
setblock ~167 ~123 ~76 dirt
setblock ~167 ~123 ~77 dirt
setblock ~167 ~123 ~78 dirt
setblock ~167 ~123 ~79 dirt
setblock ~167 ~123 ~80 dirt
setblock ~167 ~123 ~81 dirt
setblock ~167 ~123 ~82 dirt
setblock ~167 ~123 ~83 dirt
setblock ~167 ~123 ~84 dirt
setblock ~167 ~123 ~85 dirt
setblock ~167 ~123 ~86 dirt
setblock ~167 ~123 ~87 dirt
setblock ~167 ~123 ~88 dirt
setblock ~167 ~123 ~89 dirt
setblock ~167 ~123 ~90 dirt
setblock ~167 ~123 ~91 dirt
setblock ~167 ~123 ~92 dirt
setblock ~167 ~123 ~93 dirt
setblock ~167 ~123 ~94 dirt
setblock ~167 ~123 ~95 dirt
setblock ~167 ~123 ~96 dirt
setblock ~167 ~123 ~97 dirt
setblock ~167 ~123 ~98 dirt
setblock ~167 ~123 ~99 dirt
setblock ~167 ~123 ~100 dirt
setblock ~167 ~123 ~101 dirt
setblock ~167 ~123 ~102 dirt
setblock ~167 ~123 ~103 dirt
setblock ~167 ~123 ~104 dirt
setblock ~167 ~123 ~105 dirt
setblock ~167 ~123 ~106 dirt
setblock ~167 ~123 ~107 dirt
setblock ~167 ~123 ~108 dirt
setblock ~167 ~123 ~109 dirt
setblock ~167 ~123 ~110 dirt
setblock ~167 ~123 ~121 dirt
setblock ~167 ~123 ~133 dirt
setblock ~167 ~124 ~66 dirt
setblock ~167 ~124 ~67 dirt
setblock ~167 ~124 ~68 dirt
setblock ~167 ~124 ~69 dirt
setblock ~167 ~124 ~70 dirt
setblock ~167 ~124 ~71 dirt
setblock ~167 ~124 ~72 dirt
setblock ~167 ~124 ~73 dirt
setblock ~167 ~124 ~74 dirt
setblock ~167 ~124 ~75 dirt
setblock ~167 ~124 ~76 dirt
setblock ~167 ~124 ~77 dirt
setblock ~167 ~124 ~78 dirt
setblock ~167 ~124 ~79 dirt
setblock ~167 ~124 ~80 dirt
setblock ~167 ~124 ~81 dirt
setblock ~167 ~124 ~82 dirt
setblock ~167 ~124 ~83 dirt
setblock ~167 ~124 ~84 dirt
setblock ~167 ~124 ~85 dirt
setblock ~167 ~124 ~86 dirt
setblock ~167 ~124 ~87 dirt
setblock ~167 ~124 ~88 dirt
setblock ~167 ~124 ~89 dirt
setblock ~167 ~124 ~90 dirt
setblock ~167 ~124 ~91 dirt
setblock ~167 ~124 ~92 dirt
setblock ~167 ~124 ~93 dirt
setblock ~167 ~124 ~94 dirt
setblock ~167 ~124 ~95 dirt
setblock ~167 ~124 ~96 dirt
setblock ~167 ~124 ~97 dirt
setblock ~167 ~124 ~98 dirt
setblock ~167 ~124 ~99 dirt
setblock ~167 ~124 ~100 dirt
setblock ~167 ~124 ~101 dirt
setblock ~167 ~124 ~102 dirt
setblock ~167 ~124 ~103 dirt
setblock ~167 ~124 ~104 dirt
setblock ~167 ~124 ~105 dirt
setblock ~167 ~124 ~106 dirt
setblock ~167 ~124 ~107 dirt
setblock ~167 ~124 ~108 dirt
setblock ~167 ~124 ~109 grass_block
setblock ~167 ~124 ~110 grass_block
setblock ~167 ~124 ~121 dirt
setblock ~167 ~124 ~133 dirt
setblock ~167 ~125 ~66 grass_block
setblock ~167 ~125 ~67 grass_block
setblock ~167 ~125 ~68 grass_block
setblock ~167 ~125 ~69 grass_block
setblock ~167 ~125 ~70 grass_block
setblock ~167 ~125 ~71 dirt
setblock ~167 ~125 ~72 dirt
setblock ~167 ~125 ~73 dirt
setblock ~167 ~125 ~74 dirt
setblock ~167 ~125 ~75 dirt
setblock ~167 ~125 ~76 dirt
setblock ~167 ~125 ~77 dirt
setblock ~167 ~125 ~78 dirt
setblock ~167 ~125 ~79 dirt
setblock ~167 ~125 ~80 dirt
setblock ~167 ~125 ~81 dirt
setblock ~167 ~125 ~82 dirt
setblock ~167 ~125 ~83 dirt
setblock ~167 ~125 ~84 dirt
setblock ~167 ~125 ~85 dirt
setblock ~167 ~125 ~86 dirt
setblock ~167 ~125 ~87 dirt
setblock ~167 ~125 ~88 dirt
setblock ~167 ~125 ~89 grass_block
setblock ~167 ~125 ~90 grass_block
setblock ~167 ~125 ~91 grass_block
setblock ~167 ~125 ~92 grass_block
setblock ~167 ~125 ~93 grass_block
setblock ~167 ~125 ~94 grass_block
setblock ~167 ~125 ~95 grass_block
setblock ~167 ~125 ~96 grass_block
setblock ~167 ~125 ~97 grass_block
setblock ~167 ~125 ~98 dirt
setblock ~167 ~125 ~99 dirt
setblock ~167 ~125 ~100 dirt
setblock ~167 ~125 ~101 dirt
setblock ~167 ~125 ~102 grass_block
setblock ~167 ~125 ~103 grass_block
setblock ~167 ~125 ~104 grass_block
setblock ~167 ~125 ~105 grass_block
setblock ~167 ~125 ~106 grass_block
setblock ~167 ~125 ~107 grass_block
setblock ~167 ~125 ~108 grass_block
setblock ~167 ~125 ~121 dirt
setblock ~167 ~125 ~133 dirt
setblock ~167 ~126 ~66 poppy
setblock ~167 ~126 ~69 short_grass
setblock ~167 ~126 ~71 grass_block
setblock ~167 ~126 ~72 grass_block
setblock ~167 ~126 ~73 dirt
setblock ~167 ~126 ~74 dirt
setblock ~167 ~126 ~75 dirt
setblock ~167 ~126 ~76 dirt
setblock ~167 ~126 ~77 dirt
setblock ~167 ~126 ~78 dirt
setblock ~167 ~126 ~79 dirt
setblock ~167 ~126 ~80 dirt
setblock ~167 ~126 ~81 dirt
setblock ~167 ~126 ~82 dirt
setblock ~167 ~126 ~83 dirt
setblock ~167 ~126 ~84 dirt
setblock ~167 ~126 ~85 dirt
setblock ~167 ~126 ~86 dirt
setblock ~167 ~126 ~87 grass_block
setblock ~167 ~126 ~88 grass_block
setblock ~167 ~126 ~89 short_grass
setblock ~167 ~126 ~93 poppy
setblock ~167 ~126 ~98 grass_block
setblock ~167 ~126 ~99 grass_block
setblock ~167 ~126 ~100 grass_block
setblock ~167 ~126 ~101 grass_block
setblock ~167 ~126 ~103 poppy
setblock ~167 ~126 ~105 short_grass
setblock ~167 ~126 ~121 dirt
setblock ~167 ~126 ~133 dirt
setblock ~167 ~127 ~73 grass_block
setblock ~167 ~127 ~74 grass_block
setblock ~167 ~127 ~75 dirt
setblock ~167 ~127 ~76 dirt
setblock ~167 ~127 ~77 dirt
setblock ~167 ~127 ~78 dirt
setblock ~167 ~127 ~79 dirt
setblock ~167 ~127 ~80 dirt
setblock ~167 ~127 ~81 dirt
setblock ~167 ~127 ~82 dirt
setblock ~167 ~127 ~83 dirt
setblock ~167 ~127 ~84 dirt
setblock ~167 ~127 ~85 grass_block
setblock ~167 ~127 ~86 grass_block
setblock ~167 ~127 ~98 poppy
setblock ~167 ~127 ~101 short_grass
setblock ~167 ~127 ~121 grass_block
setblock ~167 ~127 ~133 grass_block
setblock ~167 ~128 ~75 grass_block
setblock ~167 ~128 ~76 grass_block
setblock ~167 ~128 ~77 grass_block
setblock ~167 ~128 ~78 dirt
setblock ~167 ~128 ~79 dirt
setblock ~167 ~128 ~80 dirt
setblock ~167 ~128 ~81 dirt
setblock ~167 ~128 ~82 dirt
setblock ~167 ~128 ~83 grass_block
setblock ~167 ~128 ~84 grass_block
setblock ~167 ~128 ~133 short_grass
setblock ~167 ~129 ~77 fern
setblock ~167 ~129 ~78 grass_block
setblock ~167 ~129 ~79 grass_block
setblock ~167 ~129 ~80 dirt
setblock ~167 ~129 ~81 grass_block
setblock ~167 ~129 ~82 grass_block
setblock ~167 ~129 ~83 poppy
setblock ~167 ~130 ~80 grass_block
setblock ~167 ~131 ~80 short_grass
setblock ~167 ~137 ~68 oak_leaves[persistent=true]
setblock ~167 ~137 ~69 oak_leaves[persistent=true]
setblock ~167 ~137 ~70 jungle_leaves[persistent=true]
setblock ~167 ~138 ~68 jungle_leaves[persistent=true]
setblock ~167 ~138 ~69 oak_leaves[persistent=true]
setblock ~167 ~138 ~120 oak_leaves[persistent=true]
setblock ~167 ~138 ~121 jungle_leaves[persistent=true]
setblock ~167 ~138 ~122 oak_leaves[persistent=true]
setblock ~167 ~139 ~68 oak_leaves[persistent=true]
setblock ~167 ~139 ~70 oak_leaves[persistent=true]
setblock ~167 ~139 ~120 oak_leaves[persistent=true]
setblock ~167 ~139 ~121 oak_leaves[persistent=true]
setblock ~167 ~139 ~122 oak_leaves[persistent=true]
setblock ~167 ~140 ~121 jungle_leaves[persistent=true]
setblock ~167 ~140 ~122 oak_leaves[persistent=true]
setblock ~168 ~107 ~81 dirt
setblock ~168 ~108 ~81 dirt
setblock ~168 ~109 ~79 dirt
setblock ~168 ~109 ~80 dirt
setblock ~168 ~109 ~81 dirt
setblock ~168 ~109 ~82 dirt
setblock ~168 ~110 ~78 dirt
setblock ~168 ~110 ~79 dirt
setblock ~168 ~110 ~80 dirt
setblock ~168 ~110 ~81 dirt
setblock ~168 ~110 ~82 dirt
setblock ~168 ~110 ~83 dirt
setblock ~168 ~111 ~78 dirt
setblock ~168 ~111 ~79 dirt
setblock ~168 ~111 ~80 dirt
setblock ~168 ~111 ~81 dirt
setblock ~168 ~111 ~82 dirt
setblock ~168 ~111 ~83 dirt
setblock ~168 ~112 ~78 dirt
setblock ~168 ~112 ~79 dirt
setblock ~168 ~112 ~80 dirt
setblock ~168 ~112 ~81 dirt
setblock ~168 ~112 ~82 dirt
setblock ~168 ~112 ~83 dirt
setblock ~168 ~112 ~84 dirt
setblock ~168 ~113 ~74 dirt
setblock ~168 ~113 ~77 dirt
setblock ~168 ~113 ~78 dirt
setblock ~168 ~113 ~79 dirt
setblock ~168 ~113 ~80 dirt
setblock ~168 ~113 ~81 dirt
setblock ~168 ~113 ~82 dirt
setblock ~168 ~113 ~83 dirt
setblock ~168 ~113 ~84 dirt
setblock ~168 ~113 ~85 dirt
setblock ~168 ~113 ~86 dirt
setblock ~168 ~114 ~74 dirt
setblock ~168 ~114 ~75 dirt
setblock ~168 ~114 ~76 dirt
setblock ~168 ~114 ~77 dirt
setblock ~168 ~114 ~78 dirt
setblock ~168 ~114 ~79 dirt
setblock ~168 ~114 ~80 dirt
setblock ~168 ~114 ~81 dirt
setblock ~168 ~114 ~82 dirt
setblock ~168 ~114 ~83 dirt
setblock ~168 ~114 ~84 dirt
setblock ~168 ~114 ~85 dirt
setblock ~168 ~114 ~86 dirt
setblock ~168 ~114 ~87 dirt
setblock ~168 ~115 ~73 dirt
setblock ~168 ~115 ~74 dirt
setblock ~168 ~115 ~75 dirt
setblock ~168 ~115 ~76 dirt
setblock ~168 ~115 ~77 dirt
setblock ~168 ~115 ~78 dirt
setblock ~168 ~115 ~79 dirt
setblock ~168 ~115 ~80 dirt
setblock ~168 ~115 ~81 dirt
setblock ~168 ~115 ~82 dirt
setblock ~168 ~115 ~83 dirt
setblock ~168 ~115 ~84 dirt
setblock ~168 ~115 ~85 dirt
setblock ~168 ~115 ~86 dirt
setblock ~168 ~115 ~87 dirt
setblock ~168 ~116 ~71 dirt
setblock ~168 ~116 ~73 dirt
setblock ~168 ~116 ~74 dirt
setblock ~168 ~116 ~75 dirt
setblock ~168 ~116 ~76 dirt
setblock ~168 ~116 ~77 dirt
setblock ~168 ~116 ~78 dirt
setblock ~168 ~116 ~79 dirt
setblock ~168 ~116 ~80 dirt
setblock ~168 ~116 ~81 dirt
setblock ~168 ~116 ~82 dirt
setblock ~168 ~116 ~83 dirt
setblock ~168 ~116 ~84 dirt
setblock ~168 ~116 ~85 dirt
setblock ~168 ~116 ~86 dirt
setblock ~168 ~116 ~87 dirt
setblock ~168 ~116 ~88 dirt
setblock ~168 ~116 ~100 dirt
setblock ~168 ~116 ~101 dirt
setblock ~168 ~116 ~106 dirt
setblock ~168 ~117 ~71 dirt
setblock ~168 ~117 ~73 dirt
setblock ~168 ~117 ~74 dirt
setblock ~168 ~117 ~75 dirt
setblock ~168 ~117 ~76 dirt
setblock ~168 ~117 ~77 dirt
setblock ~168 ~117 ~78 dirt
setblock ~168 ~117 ~79 dirt
setblock ~168 ~117 ~80 dirt
setblock ~168 ~117 ~81 dirt
setblock ~168 ~117 ~82 dirt
setblock ~168 ~117 ~83 dirt
setblock ~168 ~117 ~84 dirt
setblock ~168 ~117 ~85 dirt
setblock ~168 ~117 ~86 dirt
setblock ~168 ~117 ~87 dirt
setblock ~168 ~117 ~88 dirt
setblock ~168 ~117 ~89 dirt
setblock ~168 ~117 ~90 dirt
setblock ~168 ~117 ~91 dirt
setblock ~168 ~117 ~100 dirt
setblock ~168 ~117 ~101 dirt
setblock ~168 ~117 ~106 dirt
setblock ~168 ~117 ~107 dirt
setblock ~168 ~118 ~71 dirt
setblock ~168 ~118 ~72 dirt
setblock ~168 ~118 ~73 dirt
setblock ~168 ~118 ~74 dirt
setblock ~168 ~118 ~75 dirt
setblock ~168 ~118 ~76 dirt
setblock ~168 ~118 ~77 dirt
setblock ~168 ~118 ~78 dirt
setblock ~168 ~118 ~79 dirt
setblock ~168 ~118 ~80 dirt
setblock ~168 ~118 ~81 dirt
setblock ~168 ~118 ~82 dirt
setblock ~168 ~118 ~83 dirt
setblock ~168 ~118 ~84 dirt
setblock ~168 ~118 ~85 dirt
setblock ~168 ~118 ~86 dirt
setblock ~168 ~118 ~87 dirt
setblock ~168 ~118 ~88 dirt
setblock ~168 ~118 ~89 dirt
setblock ~168 ~118 ~90 dirt
setblock ~168 ~118 ~91 dirt
setblock ~168 ~118 ~93 dirt
setblock ~168 ~118 ~99 dirt
setblock ~168 ~118 ~100 dirt
setblock ~168 ~118 ~101 dirt
setblock ~168 ~118 ~102 dirt
setblock ~168 ~118 ~106 dirt
setblock ~168 ~118 ~107 dirt
setblock ~168 ~119 ~70 dirt
setblock ~168 ~119 ~71 dirt
setblock ~168 ~119 ~72 dirt
setblock ~168 ~119 ~73 dirt
setblock ~168 ~119 ~74 dirt
setblock ~168 ~119 ~75 dirt
setblock ~168 ~119 ~76 dirt
setblock ~168 ~119 ~77 dirt
setblock ~168 ~119 ~78 dirt
setblock ~168 ~119 ~79 dirt
setblock ~168 ~119 ~80 dirt
setblock ~168 ~119 ~81 dirt
setblock ~168 ~119 ~82 dirt
setblock ~168 ~119 ~83 dirt
setblock ~168 ~119 ~84 dirt
setblock ~168 ~119 ~85 dirt
setblock ~168 ~119 ~86 dirt
setblock ~168 ~119 ~87 dirt
setblock ~168 ~119 ~88 dirt
setblock ~168 ~119 ~89 dirt
setblock ~168 ~119 ~90 dirt
setblock ~168 ~119 ~91 dirt
setblock ~168 ~119 ~92 dirt
setblock ~168 ~119 ~93 dirt
setblock ~168 ~119 ~94 dirt
setblock ~168 ~119 ~99 dirt
setblock ~168 ~119 ~100 dirt
setblock ~168 ~119 ~101 dirt
setblock ~168 ~119 ~102 dirt
setblock ~168 ~119 ~105 dirt
setblock ~168 ~119 ~106 dirt
setblock ~168 ~119 ~107 dirt
setblock ~168 ~119 ~108 dirt
setblock ~168 ~120 ~70 dirt
setblock ~168 ~120 ~71 dirt
setblock ~168 ~120 ~72 dirt
setblock ~168 ~120 ~73 dirt
setblock ~168 ~120 ~74 dirt
setblock ~168 ~120 ~75 dirt
setblock ~168 ~120 ~76 dirt
setblock ~168 ~120 ~77 dirt
setblock ~168 ~120 ~78 dirt
setblock ~168 ~120 ~79 dirt
setblock ~168 ~120 ~80 dirt
setblock ~168 ~120 ~81 dirt
setblock ~168 ~120 ~82 dirt
setblock ~168 ~120 ~83 dirt
setblock ~168 ~120 ~84 dirt
setblock ~168 ~120 ~85 dirt
setblock ~168 ~120 ~86 dirt
setblock ~168 ~120 ~87 dirt
setblock ~168 ~120 ~88 dirt
setblock ~168 ~120 ~89 dirt
setblock ~168 ~120 ~90 dirt
setblock ~168 ~120 ~91 dirt
setblock ~168 ~120 ~92 dirt
setblock ~168 ~120 ~93 dirt
setblock ~168 ~120 ~94 dirt
setblock ~168 ~120 ~95 dirt
setblock ~168 ~120 ~98 dirt
setblock ~168 ~120 ~99 dirt
setblock ~168 ~120 ~100 dirt
setblock ~168 ~120 ~101 dirt
setblock ~168 ~120 ~102 dirt
setblock ~168 ~120 ~103 dirt
setblock ~168 ~120 ~104 dirt
setblock ~168 ~120 ~105 dirt
setblock ~168 ~120 ~106 dirt
setblock ~168 ~120 ~107 dirt
setblock ~168 ~120 ~108 dirt
setblock ~168 ~120 ~109 dirt
setblock ~168 ~121 ~67 dirt
setblock ~168 ~121 ~69 dirt
setblock ~168 ~121 ~70 dirt
setblock ~168 ~121 ~71 dirt
setblock ~168 ~121 ~72 dirt
setblock ~168 ~121 ~73 dirt
setblock ~168 ~121 ~74 dirt
setblock ~168 ~121 ~75 dirt
setblock ~168 ~121 ~76 dirt
setblock ~168 ~121 ~77 dirt
setblock ~168 ~121 ~78 dirt
setblock ~168 ~121 ~79 dirt
setblock ~168 ~121 ~80 dirt
setblock ~168 ~121 ~81 dirt
setblock ~168 ~121 ~82 dirt
setblock ~168 ~121 ~83 dirt
setblock ~168 ~121 ~84 dirt
setblock ~168 ~121 ~85 dirt
setblock ~168 ~121 ~86 dirt
setblock ~168 ~121 ~87 dirt
setblock ~168 ~121 ~88 dirt
setblock ~168 ~121 ~89 dirt
setblock ~168 ~121 ~90 dirt
setblock ~168 ~121 ~91 dirt
setblock ~168 ~121 ~92 dirt
setblock ~168 ~121 ~93 dirt
setblock ~168 ~121 ~94 dirt
setblock ~168 ~121 ~95 dirt
setblock ~168 ~121 ~96 dirt
setblock ~168 ~121 ~97 dirt
setblock ~168 ~121 ~98 dirt
setblock ~168 ~121 ~99 dirt
setblock ~168 ~121 ~100 dirt
setblock ~168 ~121 ~101 dirt
setblock ~168 ~121 ~102 dirt
setblock ~168 ~121 ~103 dirt
setblock ~168 ~121 ~104 dirt
setblock ~168 ~121 ~105 dirt
setblock ~168 ~121 ~106 dirt
setblock ~168 ~121 ~107 dirt
setblock ~168 ~121 ~108 dirt
setblock ~168 ~121 ~109 dirt
setblock ~168 ~122 ~67 dirt
setblock ~168 ~122 ~69 dirt
setblock ~168 ~122 ~70 dirt
setblock ~168 ~122 ~71 dirt
setblock ~168 ~122 ~72 dirt
setblock ~168 ~122 ~73 dirt
setblock ~168 ~122 ~74 dirt
setblock ~168 ~122 ~75 dirt
setblock ~168 ~122 ~76 dirt
setblock ~168 ~122 ~77 dirt
setblock ~168 ~122 ~78 dirt
setblock ~168 ~122 ~79 dirt
setblock ~168 ~122 ~80 dirt
setblock ~168 ~122 ~81 dirt
setblock ~168 ~122 ~82 dirt
setblock ~168 ~122 ~83 dirt
setblock ~168 ~122 ~84 dirt
setblock ~168 ~122 ~85 dirt
setblock ~168 ~122 ~86 dirt
setblock ~168 ~122 ~87 dirt
setblock ~168 ~122 ~88 dirt
setblock ~168 ~122 ~89 dirt
setblock ~168 ~122 ~90 dirt
setblock ~168 ~122 ~91 dirt
setblock ~168 ~122 ~92 dirt
setblock ~168 ~122 ~93 dirt
setblock ~168 ~122 ~94 dirt
setblock ~168 ~122 ~95 dirt
setblock ~168 ~122 ~96 dirt
setblock ~168 ~122 ~97 dirt
setblock ~168 ~122 ~98 dirt
setblock ~168 ~122 ~99 dirt
setblock ~168 ~122 ~100 dirt
setblock ~168 ~122 ~101 dirt
setblock ~168 ~122 ~102 dirt
setblock ~168 ~122 ~103 dirt
setblock ~168 ~122 ~104 dirt
setblock ~168 ~122 ~105 dirt
setblock ~168 ~122 ~106 dirt
setblock ~168 ~122 ~107 dirt
setblock ~168 ~122 ~108 dirt
setblock ~168 ~122 ~109 dirt
setblock ~168 ~123 ~67 dirt
setblock ~168 ~123 ~69 dirt
setblock ~168 ~123 ~70 dirt
setblock ~168 ~123 ~71 dirt
setblock ~168 ~123 ~72 dirt
setblock ~168 ~123 ~73 dirt
setblock ~168 ~123 ~74 dirt
setblock ~168 ~123 ~75 dirt
setblock ~168 ~123 ~76 dirt
setblock ~168 ~123 ~77 dirt
setblock ~168 ~123 ~78 dirt
setblock ~168 ~123 ~79 dirt
setblock ~168 ~123 ~80 dirt
setblock ~168 ~123 ~81 dirt
setblock ~168 ~123 ~82 dirt
setblock ~168 ~123 ~83 dirt
setblock ~168 ~123 ~84 dirt
setblock ~168 ~123 ~85 dirt
setblock ~168 ~123 ~86 dirt
setblock ~168 ~123 ~87 dirt
setblock ~168 ~123 ~88 dirt
setblock ~168 ~123 ~89 dirt
setblock ~168 ~123 ~90 dirt
setblock ~168 ~123 ~91 dirt
setblock ~168 ~123 ~92 dirt
setblock ~168 ~123 ~93 dirt
setblock ~168 ~123 ~94 dirt
setblock ~168 ~123 ~95 dirt
setblock ~168 ~123 ~96 dirt
setblock ~168 ~123 ~97 dirt
setblock ~168 ~123 ~98 dirt
setblock ~168 ~123 ~99 dirt
setblock ~168 ~123 ~100 dirt
setblock ~168 ~123 ~101 dirt
setblock ~168 ~123 ~102 dirt
setblock ~168 ~123 ~103 dirt
setblock ~168 ~123 ~104 dirt
setblock ~168 ~123 ~105 dirt
setblock ~168 ~123 ~106 dirt
setblock ~168 ~123 ~107 dirt
setblock ~168 ~123 ~108 dirt
setblock ~168 ~123 ~109 dirt
setblock ~168 ~124 ~67 grass_block
setblock ~168 ~124 ~69 dirt
setblock ~168 ~124 ~70 dirt
setblock ~168 ~124 ~71 dirt
setblock ~168 ~124 ~72 dirt
setblock ~168 ~124 ~73 dirt
setblock ~168 ~124 ~74 dirt
setblock ~168 ~124 ~75 dirt
setblock ~168 ~124 ~76 dirt
setblock ~168 ~124 ~77 dirt
setblock ~168 ~124 ~78 dirt
setblock ~168 ~124 ~79 dirt
setblock ~168 ~124 ~80 dirt
setblock ~168 ~124 ~81 dirt
setblock ~168 ~124 ~82 dirt
setblock ~168 ~124 ~83 dirt
setblock ~168 ~124 ~84 dirt
setblock ~168 ~124 ~85 dirt
setblock ~168 ~124 ~86 dirt
setblock ~168 ~124 ~87 dirt
setblock ~168 ~124 ~88 dirt
setblock ~168 ~124 ~89 dirt
setblock ~168 ~124 ~90 dirt
setblock ~168 ~124 ~91 dirt
setblock ~168 ~124 ~92 dirt
setblock ~168 ~124 ~93 dirt
setblock ~168 ~124 ~94 dirt
setblock ~168 ~124 ~95 dirt
setblock ~168 ~124 ~96 dirt
setblock ~168 ~124 ~97 dirt
setblock ~168 ~124 ~98 dirt
setblock ~168 ~124 ~99 dirt
setblock ~168 ~124 ~100 dirt
setblock ~168 ~124 ~101 dirt
setblock ~168 ~124 ~102 dirt
setblock ~168 ~124 ~103 dirt
setblock ~168 ~124 ~104 dirt
setblock ~168 ~124 ~105 dirt
setblock ~168 ~124 ~106 dirt
setblock ~168 ~124 ~107 dirt
setblock ~168 ~124 ~108 dirt
setblock ~168 ~124 ~109 grass_block
setblock ~168 ~125 ~69 grass_block
setblock ~168 ~125 ~70 grass_block
setblock ~168 ~125 ~71 grass_block
setblock ~168 ~125 ~72 dirt
setblock ~168 ~125 ~73 dirt
setblock ~168 ~125 ~74 dirt
setblock ~168 ~125 ~75 dirt
setblock ~168 ~125 ~76 dirt
setblock ~168 ~125 ~77 dirt
setblock ~168 ~125 ~78 dirt
setblock ~168 ~125 ~79 dirt
setblock ~168 ~125 ~80 dirt
setblock ~168 ~125 ~81 dirt
setblock ~168 ~125 ~82 dirt
setblock ~168 ~125 ~83 dirt
setblock ~168 ~125 ~84 dirt
setblock ~168 ~125 ~85 dirt
setblock ~168 ~125 ~86 dirt
setblock ~168 ~125 ~87 dirt
setblock ~168 ~125 ~88 dirt
setblock ~168 ~125 ~89 grass_block
setblock ~168 ~125 ~90 grass_block
setblock ~168 ~125 ~91 grass_block
setblock ~168 ~125 ~92 grass_block
setblock ~168 ~125 ~93 grass_block
setblock ~168 ~125 ~94 grass_block
setblock ~168 ~125 ~95 dirt
setblock ~168 ~125 ~96 dirt
setblock ~168 ~125 ~97 dirt
setblock ~168 ~125 ~98 dirt
setblock ~168 ~125 ~99 dirt
setblock ~168 ~125 ~100 dirt
setblock ~168 ~125 ~101 dirt
setblock ~168 ~125 ~102 dirt
setblock ~168 ~125 ~103 dirt
setblock ~168 ~125 ~104 dirt
setblock ~168 ~125 ~105 grass_block
setblock ~168 ~125 ~106 grass_block
setblock ~168 ~125 ~107 grass_block
setblock ~168 ~125 ~108 grass_block
setblock ~168 ~125 ~109 short_grass
setblock ~168 ~126 ~72 grass_block
setblock ~168 ~126 ~73 dirt
setblock ~168 ~126 ~74 dirt
setblock ~168 ~126 ~75 dirt
setblock ~168 ~126 ~76 dirt
setblock ~168 ~126 ~77 dirt
setblock ~168 ~126 ~78 dirt
setblock ~168 ~126 ~79 dirt
setblock ~168 ~126 ~80 dirt
setblock ~168 ~126 ~81 dirt
setblock ~168 ~126 ~82 dirt
setblock ~168 ~126 ~83 dirt
setblock ~168 ~126 ~84 dirt
setblock ~168 ~126 ~85 dirt
setblock ~168 ~126 ~86 dirt
setblock ~168 ~126 ~87 grass_block
setblock ~168 ~126 ~88 grass_block
setblock ~168 ~126 ~91 short_grass
setblock ~168 ~126 ~95 grass_block
setblock ~168 ~126 ~96 grass_block
setblock ~168 ~126 ~97 grass_block
setblock ~168 ~126 ~98 grass_block
setblock ~168 ~126 ~99 grass_block
setblock ~168 ~126 ~100 grass_block
setblock ~168 ~126 ~101 grass_block
setblock ~168 ~126 ~102 grass_block
setblock ~168 ~126 ~103 grass_block
setblock ~168 ~126 ~104 grass_block
setblock ~168 ~127 ~72 fern
setblock ~168 ~127 ~73 grass_block
setblock ~168 ~127 ~74 grass_block
setblock ~168 ~127 ~75 dirt
setblock ~168 ~127 ~76 dirt
setblock ~168 ~127 ~77 dirt
setblock ~168 ~127 ~78 dirt
setblock ~168 ~127 ~79 dirt
setblock ~168 ~127 ~80 dirt
setblock ~168 ~127 ~81 dirt
setblock ~168 ~127 ~82 dirt
setblock ~168 ~127 ~83 dirt
setblock ~168 ~127 ~84 dirt
setblock ~168 ~127 ~85 grass_block
setblock ~168 ~127 ~86 grass_block
setblock ~168 ~127 ~87 poppy
setblock ~168 ~127 ~95 fern
setblock ~168 ~127 ~99 short_grass
setblock ~168 ~128 ~74 fern
setblock ~168 ~128 ~75 grass_block
setblock ~168 ~128 ~76 grass_block
setblock ~168 ~128 ~77 dirt
setblock ~168 ~128 ~78 dirt
setblock ~168 ~128 ~79 dirt
setblock ~168 ~128 ~80 dirt
setblock ~168 ~128 ~81 dirt
setblock ~168 ~128 ~82 dirt
setblock ~168 ~128 ~83 grass_block
setblock ~168 ~128 ~84 grass_block
setblock ~168 ~129 ~75 short_grass
setblock ~168 ~129 ~77 grass_block
setblock ~168 ~129 ~78 dirt
setblock ~168 ~129 ~79 dirt
setblock ~168 ~129 ~80 dirt
setblock ~168 ~129 ~81 dirt
setblock ~168 ~129 ~82 grass_block
setblock ~168 ~130 ~77 fern
setblock ~168 ~130 ~78 grass_block
setblock ~168 ~130 ~79 grass_block
setblock ~168 ~130 ~80 dirt
setblock ~168 ~130 ~81 grass_block
setblock ~168 ~130 ~82 short_grass
setblock ~168 ~131 ~80 grass_block
setblock ~168 ~131 ~81 short_grass
setblock ~168 ~132 ~80 fern
setblock ~169 ~109 ~81 dirt
setblock ~169 ~110 ~79 dirt
setblock ~169 ~110 ~80 dirt
setblock ~169 ~110 ~81 dirt
setblock ~169 ~110 ~82 dirt
setblock ~169 ~111 ~79 dirt
setblock ~169 ~111 ~80 dirt
setblock ~169 ~111 ~81 dirt
setblock ~169 ~111 ~82 dirt
setblock ~169 ~112 ~79 dirt
setblock ~169 ~112 ~80 dirt
setblock ~169 ~112 ~81 dirt
setblock ~169 ~112 ~82 dirt
setblock ~169 ~112 ~83 dirt
setblock ~169 ~113 ~78 dirt
setblock ~169 ~113 ~79 dirt
setblock ~169 ~113 ~80 dirt
setblock ~169 ~113 ~81 dirt
setblock ~169 ~113 ~82 dirt
setblock ~169 ~113 ~83 dirt
setblock ~169 ~113 ~84 dirt
setblock ~169 ~114 ~77 dirt
setblock ~169 ~114 ~78 dirt
setblock ~169 ~114 ~79 dirt
setblock ~169 ~114 ~80 dirt
setblock ~169 ~114 ~81 dirt
setblock ~169 ~114 ~82 dirt
setblock ~169 ~114 ~83 dirt
setblock ~169 ~114 ~84 dirt
setblock ~169 ~114 ~85 dirt
setblock ~169 ~114 ~86 dirt
setblock ~169 ~115 ~74 dirt
setblock ~169 ~115 ~77 dirt
setblock ~169 ~115 ~78 dirt
setblock ~169 ~115 ~79 dirt
setblock ~169 ~115 ~80 dirt
setblock ~169 ~115 ~81 dirt
setblock ~169 ~115 ~82 dirt
setblock ~169 ~115 ~83 dirt
setblock ~169 ~115 ~84 dirt
setblock ~169 ~115 ~85 dirt
setblock ~169 ~115 ~86 dirt
setblock ~169 ~115 ~87 dirt
setblock ~169 ~116 ~74 dirt
setblock ~169 ~116 ~75 dirt
setblock ~169 ~116 ~76 dirt
setblock ~169 ~116 ~77 dirt
setblock ~169 ~116 ~78 dirt
setblock ~169 ~116 ~79 dirt
setblock ~169 ~116 ~80 dirt
setblock ~169 ~116 ~81 dirt
setblock ~169 ~116 ~82 dirt
setblock ~169 ~116 ~83 dirt
setblock ~169 ~116 ~84 dirt
setblock ~169 ~116 ~85 dirt
setblock ~169 ~116 ~86 dirt
setblock ~169 ~116 ~87 dirt
setblock ~169 ~117 ~74 dirt
setblock ~169 ~117 ~75 dirt
setblock ~169 ~117 ~76 dirt
setblock ~169 ~117 ~77 dirt
setblock ~169 ~117 ~78 dirt
setblock ~169 ~117 ~79 dirt
setblock ~169 ~117 ~80 dirt
setblock ~169 ~117 ~81 dirt
setblock ~169 ~117 ~82 dirt
setblock ~169 ~117 ~83 dirt
setblock ~169 ~117 ~84 dirt
setblock ~169 ~117 ~85 dirt
setblock ~169 ~117 ~86 dirt
setblock ~169 ~117 ~87 dirt
setblock ~169 ~117 ~88 dirt
setblock ~169 ~118 ~73 dirt
setblock ~169 ~118 ~74 dirt
setblock ~169 ~118 ~75 dirt
setblock ~169 ~118 ~76 dirt
setblock ~169 ~118 ~77 dirt
setblock ~169 ~118 ~78 dirt
setblock ~169 ~118 ~79 dirt
setblock ~169 ~118 ~80 dirt
setblock ~169 ~118 ~81 dirt
setblock ~169 ~118 ~82 dirt
setblock ~169 ~118 ~83 dirt
setblock ~169 ~118 ~84 dirt
setblock ~169 ~118 ~85 dirt
setblock ~169 ~118 ~86 dirt
setblock ~169 ~118 ~87 dirt
setblock ~169 ~118 ~88 dirt
setblock ~169 ~118 ~89 dirt
setblock ~169 ~119 ~72 dirt
setblock ~169 ~119 ~73 dirt
setblock ~169 ~119 ~74 dirt
setblock ~169 ~119 ~75 dirt
setblock ~169 ~119 ~76 dirt
setblock ~169 ~119 ~77 dirt
setblock ~169 ~119 ~78 dirt
setblock ~169 ~119 ~79 dirt
setblock ~169 ~119 ~80 dirt
setblock ~169 ~119 ~81 dirt
setblock ~169 ~119 ~82 dirt
setblock ~169 ~119 ~83 dirt
setblock ~169 ~119 ~84 dirt
setblock ~169 ~119 ~85 dirt
setblock ~169 ~119 ~86 dirt
setblock ~169 ~119 ~87 dirt
setblock ~169 ~119 ~88 dirt
setblock ~169 ~119 ~89 dirt
setblock ~169 ~119 ~91 dirt
setblock ~169 ~119 ~100 dirt
setblock ~169 ~119 ~107 dirt
setblock ~169 ~120 ~71 dirt
setblock ~169 ~120 ~72 dirt
setblock ~169 ~120 ~73 dirt
setblock ~169 ~120 ~74 dirt
setblock ~169 ~120 ~75 dirt
setblock ~169 ~120 ~76 dirt
setblock ~169 ~120 ~77 dirt
setblock ~169 ~120 ~78 dirt
setblock ~169 ~120 ~79 dirt
setblock ~169 ~120 ~80 dirt
setblock ~169 ~120 ~81 dirt
setblock ~169 ~120 ~82 dirt
setblock ~169 ~120 ~83 dirt
setblock ~169 ~120 ~84 dirt
setblock ~169 ~120 ~85 dirt
setblock ~169 ~120 ~86 dirt
setblock ~169 ~120 ~87 dirt
setblock ~169 ~120 ~88 dirt
setblock ~169 ~120 ~89 dirt
setblock ~169 ~120 ~90 dirt
setblock ~169 ~120 ~91 dirt
setblock ~169 ~120 ~92 dirt
setblock ~169 ~120 ~99 dirt
setblock ~169 ~120 ~100 dirt
setblock ~169 ~120 ~101 dirt
setblock ~169 ~120 ~102 dirt
setblock ~169 ~120 ~105 dirt
setblock ~169 ~120 ~106 dirt
setblock ~169 ~120 ~107 dirt
setblock ~169 ~120 ~108 dirt
setblock ~169 ~121 ~71 dirt
setblock ~169 ~121 ~72 dirt
setblock ~169 ~121 ~73 dirt
setblock ~169 ~121 ~74 dirt
setblock ~169 ~121 ~75 dirt
setblock ~169 ~121 ~76 dirt
setblock ~169 ~121 ~77 dirt
setblock ~169 ~121 ~78 dirt
setblock ~169 ~121 ~79 dirt
setblock ~169 ~121 ~80 dirt
setblock ~169 ~121 ~81 dirt
setblock ~169 ~121 ~82 dirt
setblock ~169 ~121 ~83 dirt
setblock ~169 ~121 ~84 dirt
setblock ~169 ~121 ~85 dirt
setblock ~169 ~121 ~86 dirt
setblock ~169 ~121 ~87 dirt
setblock ~169 ~121 ~88 dirt
setblock ~169 ~121 ~89 dirt
setblock ~169 ~121 ~90 dirt
setblock ~169 ~121 ~91 dirt
setblock ~169 ~121 ~92 dirt
setblock ~169 ~121 ~93 dirt
setblock ~169 ~121 ~94 dirt
setblock ~169 ~121 ~99 dirt
setblock ~169 ~121 ~100 dirt
setblock ~169 ~121 ~101 dirt
setblock ~169 ~121 ~102 dirt
setblock ~169 ~121 ~103 dirt
setblock ~169 ~121 ~105 dirt
setblock ~169 ~121 ~106 dirt
setblock ~169 ~121 ~107 dirt
setblock ~169 ~121 ~108 dirt
setblock ~169 ~121 ~109 dirt
setblock ~169 ~122 ~71 dirt
setblock ~169 ~122 ~72 dirt
setblock ~169 ~122 ~73 dirt
setblock ~169 ~122 ~74 dirt
setblock ~169 ~122 ~75 dirt
setblock ~169 ~122 ~76 dirt
setblock ~169 ~122 ~77 dirt
setblock ~169 ~122 ~78 dirt
setblock ~169 ~122 ~79 dirt
setblock ~169 ~122 ~80 dirt
setblock ~169 ~122 ~81 dirt
setblock ~169 ~122 ~82 dirt
setblock ~169 ~122 ~83 dirt
setblock ~169 ~122 ~84 dirt
setblock ~169 ~122 ~85 dirt
setblock ~169 ~122 ~86 dirt
setblock ~169 ~122 ~87 dirt
setblock ~169 ~122 ~88 dirt
setblock ~169 ~122 ~89 dirt
setblock ~169 ~122 ~90 dirt
setblock ~169 ~122 ~91 dirt
setblock ~169 ~122 ~92 dirt
setblock ~169 ~122 ~93 dirt
setblock ~169 ~122 ~94 dirt
setblock ~169 ~122 ~99 dirt
setblock ~169 ~122 ~100 dirt
setblock ~169 ~122 ~101 dirt
setblock ~169 ~122 ~102 dirt
setblock ~169 ~122 ~103 dirt
setblock ~169 ~122 ~105 dirt
setblock ~169 ~122 ~106 dirt
setblock ~169 ~122 ~107 dirt
setblock ~169 ~122 ~108 dirt
setblock ~169 ~122 ~109 dirt
setblock ~169 ~123 ~71 dirt
setblock ~169 ~123 ~72 dirt
setblock ~169 ~123 ~73 dirt
setblock ~169 ~123 ~74 dirt
setblock ~169 ~123 ~75 dirt
setblock ~169 ~123 ~76 dirt
setblock ~169 ~123 ~77 dirt
setblock ~169 ~123 ~78 dirt
setblock ~169 ~123 ~79 dirt
setblock ~169 ~123 ~80 dirt
setblock ~169 ~123 ~81 dirt
setblock ~169 ~123 ~82 dirt
setblock ~169 ~123 ~83 dirt
setblock ~169 ~123 ~84 dirt
setblock ~169 ~123 ~85 dirt
setblock ~169 ~123 ~86 dirt
setblock ~169 ~123 ~87 dirt
setblock ~169 ~123 ~88 dirt
setblock ~169 ~123 ~89 dirt
setblock ~169 ~123 ~90 dirt
setblock ~169 ~123 ~91 dirt
setblock ~169 ~123 ~92 dirt
setblock ~169 ~123 ~93 dirt
setblock ~169 ~123 ~94 dirt
setblock ~169 ~123 ~99 dirt
setblock ~169 ~123 ~100 dirt
setblock ~169 ~123 ~101 dirt
setblock ~169 ~123 ~102 dirt
setblock ~169 ~123 ~103 dirt
setblock ~169 ~123 ~105 dirt
setblock ~169 ~123 ~106 dirt
setblock ~169 ~123 ~107 dirt
setblock ~169 ~123 ~108 dirt
setblock ~169 ~123 ~109 dirt
setblock ~169 ~124 ~71 dirt
setblock ~169 ~124 ~72 dirt
setblock ~169 ~124 ~73 dirt
setblock ~169 ~124 ~74 dirt
setblock ~169 ~124 ~75 dirt
setblock ~169 ~124 ~76 dirt
setblock ~169 ~124 ~77 dirt
setblock ~169 ~124 ~78 dirt
setblock ~169 ~124 ~79 dirt
setblock ~169 ~124 ~80 dirt
setblock ~169 ~124 ~81 dirt
setblock ~169 ~124 ~82 dirt
setblock ~169 ~124 ~83 dirt
setblock ~169 ~124 ~84 dirt
setblock ~169 ~124 ~85 dirt
setblock ~169 ~124 ~86 dirt
setblock ~169 ~124 ~87 dirt
setblock ~169 ~124 ~88 dirt
setblock ~169 ~124 ~89 dirt
setblock ~169 ~124 ~90 dirt
setblock ~169 ~124 ~91 dirt
setblock ~169 ~124 ~92 dirt
setblock ~169 ~124 ~93 dirt
setblock ~169 ~124 ~94 dirt
setblock ~169 ~124 ~99 dirt
setblock ~169 ~124 ~100 dirt
setblock ~169 ~124 ~101 dirt
setblock ~169 ~124 ~102 dirt
setblock ~169 ~124 ~103 dirt
setblock ~169 ~124 ~105 dirt
setblock ~169 ~124 ~106 dirt
setblock ~169 ~124 ~107 dirt
setblock ~169 ~124 ~108 dirt
setblock ~169 ~124 ~109 dirt
setblock ~169 ~125 ~71 grass_block
setblock ~169 ~125 ~72 dirt
setblock ~169 ~125 ~73 dirt
setblock ~169 ~125 ~74 dirt
setblock ~169 ~125 ~75 dirt
setblock ~169 ~125 ~76 dirt
setblock ~169 ~125 ~77 dirt
setblock ~169 ~125 ~78 dirt
setblock ~169 ~125 ~79 dirt
setblock ~169 ~125 ~80 dirt
setblock ~169 ~125 ~81 dirt
setblock ~169 ~125 ~82 dirt
setblock ~169 ~125 ~83 dirt
setblock ~169 ~125 ~84 dirt
setblock ~169 ~125 ~85 dirt
setblock ~169 ~125 ~86 dirt
setblock ~169 ~125 ~87 dirt
setblock ~169 ~125 ~88 dirt
setblock ~169 ~125 ~89 grass_block
setblock ~169 ~125 ~90 grass_block
setblock ~169 ~125 ~91 grass_block
setblock ~169 ~125 ~92 grass_block
setblock ~169 ~125 ~93 grass_block
setblock ~169 ~125 ~94 dirt
setblock ~169 ~125 ~99 dirt
setblock ~169 ~125 ~100 dirt
setblock ~169 ~125 ~101 dirt
setblock ~169 ~125 ~102 dirt
setblock ~169 ~125 ~103 dirt
setblock ~169 ~125 ~105 dirt
setblock ~169 ~125 ~106 grass_block
setblock ~169 ~125 ~107 grass_block
setblock ~169 ~125 ~108 grass_block
setblock ~169 ~125 ~109 grass_block
setblock ~169 ~126 ~71 short_grass
setblock ~169 ~126 ~72 grass_block
setblock ~169 ~126 ~73 grass_block
setblock ~169 ~126 ~74 dirt
setblock ~169 ~126 ~75 dirt
setblock ~169 ~126 ~76 dirt
setblock ~169 ~126 ~77 dirt
setblock ~169 ~126 ~78 dirt
setblock ~169 ~126 ~79 dirt
setblock ~169 ~126 ~80 dirt
setblock ~169 ~126 ~81 dirt
setblock ~169 ~126 ~82 dirt
setblock ~169 ~126 ~83 dirt
setblock ~169 ~126 ~84 dirt
setblock ~169 ~126 ~85 dirt
setblock ~169 ~126 ~86 dirt
setblock ~169 ~126 ~87 grass_block
setblock ~169 ~126 ~88 grass_block
setblock ~169 ~126 ~90 short_grass
setblock ~169 ~126 ~93 poppy
setblock ~169 ~126 ~94 grass_block
setblock ~169 ~126 ~99 dirt
setblock ~169 ~126 ~100 dirt
setblock ~169 ~126 ~101 dirt
setblock ~169 ~126 ~102 grass_block
setblock ~169 ~126 ~103 grass_block
setblock ~169 ~126 ~105 grass_block
setblock ~169 ~126 ~106 fern
setblock ~169 ~127 ~73 short_grass
setblock ~169 ~127 ~74 grass_block
setblock ~169 ~127 ~75 dirt
setblock ~169 ~127 ~76 dirt
setblock ~169 ~127 ~77 dirt
setblock ~169 ~127 ~78 dirt
setblock ~169 ~127 ~79 dirt
setblock ~169 ~127 ~80 dirt
setblock ~169 ~127 ~81 dirt
setblock ~169 ~127 ~82 dirt
setblock ~169 ~127 ~83 dirt
setblock ~169 ~127 ~84 dirt
setblock ~169 ~127 ~85 grass_block
setblock ~169 ~127 ~86 grass_block
setblock ~169 ~127 ~87 short_grass
setblock ~169 ~127 ~94 poppy
setblock ~169 ~127 ~99 grass_block
setblock ~169 ~127 ~100 grass_block
setblock ~169 ~127 ~101 grass_block
setblock ~169 ~127 ~105 poppy
setblock ~169 ~128 ~75 grass_block
setblock ~169 ~128 ~76 dirt
setblock ~169 ~128 ~77 dirt
setblock ~169 ~128 ~78 dirt
setblock ~169 ~128 ~79 dirt
setblock ~169 ~128 ~80 dirt
setblock ~169 ~128 ~81 dirt
setblock ~169 ~128 ~82 dirt
setblock ~169 ~128 ~83 dirt
setblock ~169 ~128 ~84 grass_block
setblock ~169 ~128 ~99 short_grass
setblock ~169 ~128 ~101 short_grass
setblock ~169 ~129 ~76 grass_block
setblock ~169 ~129 ~77 grass_block
setblock ~169 ~129 ~78 dirt
setblock ~169 ~129 ~79 dirt
setblock ~169 ~129 ~80 dirt
setblock ~169 ~129 ~81 dirt
setblock ~169 ~129 ~82 dirt
setblock ~169 ~129 ~83 grass_block
setblock ~169 ~129 ~84 short_grass
setblock ~169 ~130 ~76 poppy
setblock ~169 ~130 ~77 fern
setblock ~169 ~130 ~78 grass_block
setblock ~169 ~130 ~79 dirt
setblock ~169 ~130 ~80 dirt
setblock ~169 ~130 ~81 dirt
setblock ~169 ~130 ~82 grass_block
setblock ~169 ~131 ~79 grass_block
setblock ~169 ~131 ~80 grass_block
setblock ~169 ~131 ~81 grass_block
setblock ~170 ~113 ~81 dirt
setblock ~170 ~114 ~78 dirt
setblock ~170 ~114 ~79 dirt
setblock ~170 ~114 ~80 dirt
setblock ~170 ~114 ~81 dirt
setblock ~170 ~114 ~82 dirt
setblock ~170 ~114 ~83 dirt
setblock ~170 ~114 ~84 dirt
setblock ~170 ~115 ~78 dirt
setblock ~170 ~115 ~79 dirt
setblock ~170 ~115 ~80 dirt
setblock ~170 ~115 ~81 dirt
setblock ~170 ~115 ~82 dirt
setblock ~170 ~115 ~83 dirt
setblock ~170 ~115 ~84 dirt
setblock ~170 ~115 ~85 dirt
setblock ~170 ~115 ~86 dirt
setblock ~170 ~116 ~77 dirt
setblock ~170 ~116 ~78 dirt
setblock ~170 ~116 ~79 dirt
setblock ~170 ~116 ~80 dirt
setblock ~170 ~116 ~81 dirt
setblock ~170 ~116 ~82 dirt
setblock ~170 ~116 ~83 dirt
setblock ~170 ~116 ~84 dirt
setblock ~170 ~116 ~85 dirt
setblock ~170 ~116 ~86 dirt
setblock ~170 ~116 ~87 dirt
setblock ~170 ~117 ~75 dirt
setblock ~170 ~117 ~76 dirt
setblock ~170 ~117 ~77 dirt
setblock ~170 ~117 ~78 dirt
setblock ~170 ~117 ~79 dirt
setblock ~170 ~117 ~80 dirt
setblock ~170 ~117 ~81 dirt
setblock ~170 ~117 ~82 dirt
setblock ~170 ~117 ~83 dirt
setblock ~170 ~117 ~84 dirt
setblock ~170 ~117 ~85 dirt
setblock ~170 ~117 ~86 dirt
setblock ~170 ~117 ~87 dirt
setblock ~170 ~118 ~74 dirt
setblock ~170 ~118 ~75 dirt
setblock ~170 ~118 ~76 dirt
setblock ~170 ~118 ~77 dirt
setblock ~170 ~118 ~78 dirt
setblock ~170 ~118 ~79 dirt
setblock ~170 ~118 ~80 dirt
setblock ~170 ~118 ~81 dirt
setblock ~170 ~118 ~82 dirt
setblock ~170 ~118 ~83 dirt
setblock ~170 ~118 ~84 dirt
setblock ~170 ~118 ~85 dirt
setblock ~170 ~118 ~86 dirt
setblock ~170 ~118 ~87 dirt
setblock ~170 ~119 ~73 dirt
setblock ~170 ~119 ~74 dirt
setblock ~170 ~119 ~75 dirt
setblock ~170 ~119 ~76 dirt
setblock ~170 ~119 ~77 dirt
setblock ~170 ~119 ~78 dirt
setblock ~170 ~119 ~79 dirt
setblock ~170 ~119 ~80 dirt
setblock ~170 ~119 ~81 dirt
setblock ~170 ~119 ~82 dirt
setblock ~170 ~119 ~83 dirt
setblock ~170 ~119 ~84 dirt
setblock ~170 ~119 ~85 dirt
setblock ~170 ~119 ~86 dirt
setblock ~170 ~119 ~87 dirt
setblock ~170 ~119 ~88 dirt
setblock ~170 ~120 ~73 dirt
setblock ~170 ~120 ~74 dirt
setblock ~170 ~120 ~75 dirt
setblock ~170 ~120 ~76 dirt
setblock ~170 ~120 ~77 dirt
setblock ~170 ~120 ~78 dirt
setblock ~170 ~120 ~79 dirt
setblock ~170 ~120 ~80 dirt
setblock ~170 ~120 ~81 dirt
setblock ~170 ~120 ~82 dirt
setblock ~170 ~120 ~83 dirt
setblock ~170 ~120 ~84 dirt
setblock ~170 ~120 ~85 dirt
setblock ~170 ~120 ~86 dirt
setblock ~170 ~120 ~87 dirt
setblock ~170 ~120 ~88 dirt
setblock ~170 ~120 ~91 dirt
setblock ~170 ~120 ~100 dirt
setblock ~170 ~121 ~72 dirt
setblock ~170 ~121 ~73 dirt
setblock ~170 ~121 ~74 dirt
setblock ~170 ~121 ~75 dirt
setblock ~170 ~121 ~76 dirt
setblock ~170 ~121 ~77 dirt
setblock ~170 ~121 ~78 dirt
setblock ~170 ~121 ~79 dirt
setblock ~170 ~121 ~80 dirt
setblock ~170 ~121 ~81 dirt
setblock ~170 ~121 ~82 dirt
setblock ~170 ~121 ~83 dirt
setblock ~170 ~121 ~84 dirt
setblock ~170 ~121 ~85 dirt
setblock ~170 ~121 ~86 dirt
setblock ~170 ~121 ~87 dirt
setblock ~170 ~121 ~88 dirt
setblock ~170 ~121 ~89 dirt
setblock ~170 ~121 ~90 dirt
setblock ~170 ~121 ~91 dirt
setblock ~170 ~121 ~92 dirt
setblock ~170 ~121 ~99 dirt
setblock ~170 ~121 ~100 dirt
setblock ~170 ~121 ~101 dirt
setblock ~170 ~121 ~106 dirt
setblock ~170 ~121 ~108 dirt
setblock ~170 ~122 ~72 dirt
setblock ~170 ~122 ~73 dirt
setblock ~170 ~122 ~74 dirt
setblock ~170 ~122 ~75 dirt
setblock ~170 ~122 ~76 dirt
setblock ~170 ~122 ~77 dirt
setblock ~170 ~122 ~78 dirt
setblock ~170 ~122 ~79 dirt
setblock ~170 ~122 ~80 dirt
setblock ~170 ~122 ~81 dirt
setblock ~170 ~122 ~82 dirt
setblock ~170 ~122 ~83 dirt
setblock ~170 ~122 ~84 dirt
setblock ~170 ~122 ~85 dirt
setblock ~170 ~122 ~86 dirt
setblock ~170 ~122 ~87 dirt
setblock ~170 ~122 ~88 dirt
setblock ~170 ~122 ~89 dirt
setblock ~170 ~122 ~90 dirt
setblock ~170 ~122 ~91 dirt
setblock ~170 ~122 ~92 dirt
setblock ~170 ~122 ~99 dirt
setblock ~170 ~122 ~100 dirt
setblock ~170 ~122 ~101 dirt
setblock ~170 ~122 ~106 dirt
setblock ~170 ~122 ~108 dirt
setblock ~170 ~123 ~72 dirt
setblock ~170 ~123 ~73 dirt
setblock ~170 ~123 ~74 dirt
setblock ~170 ~123 ~75 dirt
setblock ~170 ~123 ~76 dirt
setblock ~170 ~123 ~77 dirt
setblock ~170 ~123 ~78 dirt
setblock ~170 ~123 ~79 dirt
setblock ~170 ~123 ~80 dirt
setblock ~170 ~123 ~81 dirt
setblock ~170 ~123 ~82 dirt
setblock ~170 ~123 ~83 dirt
setblock ~170 ~123 ~84 dirt
setblock ~170 ~123 ~85 dirt
setblock ~170 ~123 ~86 dirt
setblock ~170 ~123 ~87 dirt
setblock ~170 ~123 ~88 dirt
setblock ~170 ~123 ~89 dirt
setblock ~170 ~123 ~90 dirt
setblock ~170 ~123 ~91 dirt
setblock ~170 ~123 ~92 dirt
setblock ~170 ~123 ~99 dirt
setblock ~170 ~123 ~100 dirt
setblock ~170 ~123 ~101 dirt
setblock ~170 ~123 ~106 dirt
setblock ~170 ~123 ~108 dirt
setblock ~170 ~124 ~72 dirt
setblock ~170 ~124 ~73 dirt
setblock ~170 ~124 ~74 dirt
setblock ~170 ~124 ~75 dirt
setblock ~170 ~124 ~76 dirt
setblock ~170 ~124 ~77 dirt
setblock ~170 ~124 ~78 dirt
setblock ~170 ~124 ~79 dirt
setblock ~170 ~124 ~80 dirt
setblock ~170 ~124 ~81 dirt
