setblock ~0 ~1 ~0 gold_block
setblock ~26 ~165 ~129 oak_leaves[persistent=true]
setblock ~26 ~165 ~131 oak_leaves[persistent=true]
setblock ~26 ~165 ~132 oak_leaves[persistent=true]
setblock ~26 ~166 ~124 jungle_leaves[persistent=true]
setblock ~26 ~166 ~125 oak_leaves[persistent=true]
setblock ~26 ~166 ~126 oak_leaves[persistent=true]
setblock ~26 ~166 ~127 jungle_leaves[persistent=true]
setblock ~26 ~166 ~128 jungle_leaves[persistent=true]
setblock ~26 ~166 ~130 jungle_leaves[persistent=true]
setblock ~26 ~166 ~131 oak_leaves[persistent=true]
setblock ~26 ~166 ~132 jungle_leaves[persistent=true]
setblock ~26 ~167 ~124 oak_leaves[persistent=true]
setblock ~26 ~167 ~125 oak_leaves[persistent=true]
setblock ~26 ~167 ~126 oak_leaves[persistent=true]
setblock ~26 ~167 ~127 oak_leaves[persistent=true]
setblock ~26 ~167 ~128 oak_leaves[persistent=true]
setblock ~26 ~167 ~129 oak_leaves[persistent=true]
setblock ~26 ~167 ~130 oak_leaves[persistent=true]
setblock ~26 ~167 ~131 oak_leaves[persistent=true]
setblock ~26 ~167 ~132 jungle_leaves[persistent=true]
setblock ~26 ~168 ~124 oak_leaves[persistent=true]
setblock ~26 ~168 ~125 jungle_leaves[persistent=true]
setblock ~26 ~168 ~126 oak_leaves[persistent=true]
setblock ~26 ~168 ~127 oak_leaves[persistent=true]
setblock ~26 ~168 ~128 oak_leaves[persistent=true]
setblock ~26 ~168 ~129 oak_leaves[persistent=true]
setblock ~26 ~168 ~130 jungle_leaves[persistent=true]
setblock ~26 ~168 ~131 oak_leaves[persistent=true]
setblock ~26 ~169 ~124 oak_leaves[persistent=true]
setblock ~26 ~169 ~125 oak_leaves[persistent=true]
setblock ~26 ~169 ~126 oak_leaves[persistent=true]
setblock ~26 ~169 ~127 oak_leaves[persistent=true]
setblock ~26 ~169 ~128 oak_leaves[persistent=true]
setblock ~26 ~169 ~129 oak_leaves[persistent=true]
setblock ~27 ~162 ~118 oak_leaves[persistent=true]
setblock ~27 ~162 ~119 oak_leaves[persistent=true]
setblock ~27 ~162 ~120 jungle_leaves[persistent=true]
setblock ~27 ~162 ~121 oak_leaves[persistent=true]
setblock ~27 ~162 ~130 jungle_leaves[persistent=true]
setblock ~27 ~162 ~131 oak_leaves[persistent=true]
setblock ~27 ~162 ~132 jungle_leaves[persistent=true]
setblock ~27 ~163 ~118 oak_leaves[persistent=true]
setblock ~27 ~163 ~119 oak_leaves[persistent=true]
setblock ~27 ~163 ~120 oak_leaves[persistent=true]
setblock ~27 ~163 ~121 jungle_leaves[persistent=true]
setblock ~27 ~163 ~130 oak_leaves[persistent=true]
setblock ~27 ~163 ~131 jungle_leaves[persistent=true]
setblock ~27 ~164 ~118 oak_leaves[persistent=true]
setblock ~27 ~164 ~119 oak_leaves[persistent=true]
setblock ~27 ~164 ~120 oak_leaves[persistent=true]
setblock ~27 ~164 ~121 oak_leaves[persistent=true]
setblock ~27 ~164 ~130 oak_leaves[persistent=true]
setblock ~27 ~164 ~131 oak_leaves[persistent=true]
setblock ~27 ~164 ~132 jungle_leaves[persistent=true]
setblock ~27 ~165 ~118 oak_leaves[persistent=true]
setblock ~27 ~165 ~119 oak_leaves[persistent=true]
setblock ~27 ~165 ~120 jungle_leaves[persistent=true]
setblock ~27 ~165 ~121 oak_leaves[persistent=true]
setblock ~27 ~165 ~123 oak_leaves[persistent=true]
setblock ~27 ~165 ~125 jungle_leaves[persistent=true]
setblock ~27 ~165 ~126 jungle_leaves[persistent=true]
setblock ~27 ~165 ~127 oak_leaves[persistent=true]
setblock ~27 ~165 ~128 jungle_leaves[persistent=true]
setblock ~27 ~165 ~129 jungle_leaves[persistent=true]
setblock ~27 ~165 ~130 oak_leaves[persistent=true]
setblock ~27 ~165 ~131 oak_leaves[persistent=true]
setblock ~27 ~165 ~132 oak_leaves[persistent=true]
setblock ~27 ~165 ~133 oak_leaves[persistent=true]
setblock ~27 ~166 ~123 oak_leaves[persistent=true]
setblock ~27 ~166 ~124 oak_leaves[persistent=true]
setblock ~27 ~166 ~125 oak_leaves[persistent=true]
setblock ~27 ~166 ~126 oak_leaves[persistent=true]
setblock ~27 ~166 ~127 oak_leaves[persistent=true]
setblock ~27 ~166 ~128 oak_leaves[persistent=true]
setblock ~27 ~166 ~129 oak_leaves[persistent=true]
setblock ~27 ~166 ~130 oak_leaves[persistent=true]
setblock ~27 ~166 ~131 jungle_leaves[persistent=true]
setblock ~27 ~166 ~132 oak_leaves[persistent=true]
setblock ~27 ~167 ~122 oak_leaves[persistent=true]
setblock ~27 ~167 ~123 oak_leaves[persistent=true]
setblock ~27 ~167 ~124 oak_leaves[persistent=true]
setblock ~27 ~167 ~125 oak_leaves[persistent=true]
setblock ~27 ~167 ~126 oak_leaves[persistent=true]
setblock ~27 ~167 ~127 oak_leaves[persistent=true]
setblock ~27 ~167 ~128 oak_leaves[persistent=true]
setblock ~27 ~167 ~129 oak_leaves[persistent=true]
setblock ~27 ~167 ~131 oak_leaves[persistent=true]
setblock ~27 ~167 ~132 oak_leaves[persistent=true]
setblock ~27 ~167 ~133 oak_leaves[persistent=true]
setblock ~27 ~168 ~122 oak_leaves[persistent=true]
setblock ~27 ~168 ~123 oak_leaves[persistent=true]
setblock ~27 ~168 ~124 oak_leaves[persistent=true]
setblock ~27 ~168 ~125 oak_leaves[persistent=true]
setblock ~27 ~168 ~126 oak_leaves[persistent=true]
setblock ~27 ~168 ~127 jungle_leaves[persistent=true]
setblock ~27 ~168 ~128 oak_leaves[persistent=true]
setblock ~27 ~168 ~129 oak_leaves[persistent=true]
setblock ~27 ~168 ~130 oak_leaves[persistent=true]
setblock ~27 ~168 ~132 jungle_leaves[persistent=true]
setblock ~27 ~168 ~133 oak_leaves[persistent=true]
setblock ~27 ~169 ~122 oak_leaves[persistent=true]
setblock ~27 ~169 ~123 oak_leaves[persistent=true]
setblock ~27 ~169 ~124 oak_leaves[persistent=true]
setblock ~27 ~169 ~125 jungle_leaves[persistent=true]
setblock ~27 ~169 ~126 oak_leaves[persistent=true]
setblock ~27 ~169 ~127 oak_leaves[persistent=true]
setblock ~27 ~169 ~128 jungle_leaves[persistent=true]
setblock ~27 ~169 ~129 oak_leaves[persistent=true]
setblock ~27 ~170 ~122 oak_leaves[persistent=true]
setblock ~27 ~170 ~123 oak_leaves[persistent=true]
setblock ~27 ~170 ~124 oak_leaves[persistent=true]
setblock ~27 ~170 ~125 oak_leaves[persistent=true]
setblock ~28 ~158 ~133 jungle_leaves[persistent=true]
setblock ~28 ~159 ~124 oak_leaves[persistent=true]
setblock ~28 ~159 ~125 oak_leaves[persistent=true]
setblock ~28 ~159 ~126 jungle_leaves[persistent=true]
setblock ~28 ~159 ~127 oak_leaves[persistent=true]
setblock ~28 ~159 ~132 oak_leaves[persistent=true]
setblock ~28 ~159 ~134 oak_leaves[persistent=true]
setblock ~28 ~160 ~124 oak_leaves[persistent=true]
setblock ~28 ~160 ~125 oak_leaves[persistent=true]
setblock ~28 ~160 ~127 oak_leaves[persistent=true]
setblock ~28 ~160 ~132 oak_leaves[persistent=true]
setblock ~28 ~160 ~133 jungle_leaves[persistent=true]
setblock ~28 ~160 ~134 oak_leaves[persistent=true]
setblock ~28 ~161 ~124 jungle_leaves[persistent=true]
setblock ~28 ~161 ~125 jungle_leaves[persistent=true]
setblock ~28 ~161 ~126 oak_leaves[persistent=true]
setblock ~28 ~161 ~127 oak_leaves[persistent=true]
setblock ~28 ~161 ~133 oak_leaves[persistent=true]
setblock ~28 ~161 ~134 oak_leaves[persistent=true]
setblock ~28 ~161 ~135 jungle_leaves[persistent=true]
setblock ~28 ~162 ~118 oak_leaves[persistent=true]
setblock ~28 ~162 ~119 jungle_leaves[persistent=true]
setblock ~28 ~162 ~120 oak_leaves[persistent=true]
setblock ~28 ~162 ~121 oak_leaves[persistent=true]
setblock ~28 ~162 ~122 oak_leaves[persistent=true]
setblock ~28 ~162 ~123 oak_leaves[persistent=true]
setblock ~28 ~162 ~124 oak_leaves[persistent=true]
setblock ~28 ~162 ~125 oak_leaves[persistent=true]
setblock ~28 ~162 ~126 oak_leaves[persistent=true]
setblock ~28 ~162 ~127 oak_leaves[persistent=true]
setblock ~28 ~162 ~128 oak_leaves[persistent=true]
setblock ~28 ~162 ~130 oak_leaves[persistent=true]
setblock ~28 ~162 ~131 oak_leaves[persistent=true]
setblock ~28 ~162 ~132 oak_leaves[persistent=true]
setblock ~28 ~162 ~133 oak_leaves[persistent=true]
setblock ~28 ~162 ~134 jungle_leaves[persistent=true]
setblock ~28 ~162 ~135 oak_leaves[persistent=true]
setblock ~28 ~163 ~118 jungle_leaves[persistent=true]
setblock ~28 ~163 ~119 jungle_leaves[persistent=true]
setblock ~28 ~163 ~120 jungle_leaves[persistent=true]
setblock ~28 ~163 ~121 oak_leaves[persistent=true]
setblock ~28 ~163 ~123 oak_leaves[persistent=true]
setblock ~28 ~163 ~124 oak_leaves[persistent=true]
setblock ~28 ~163 ~128 oak_leaves[persistent=true]
setblock ~28 ~163 ~129 jungle_leaves[persistent=true]
setblock ~28 ~163 ~130 oak_leaves[persistent=true]
setblock ~28 ~163 ~131 oak_leaves[persistent=true]
setblock ~28 ~163 ~133 jungle_leaves[persistent=true]
setblock ~28 ~163 ~134 oak_leaves[persistent=true]
setblock ~28 ~163 ~135 oak_leaves[persistent=true]
setblock ~28 ~164 ~118 oak_leaves[persistent=true]
setblock ~28 ~164 ~119 oak_leaves[persistent=true]
setblock ~28 ~164 ~120 oak_leaves[persistent=true]
setblock ~28 ~164 ~121 oak_leaves[persistent=true]
setblock ~28 ~164 ~122 oak_leaves[persistent=true]
setblock ~28 ~164 ~123 oak_leaves[persistent=true]
setblock ~28 ~164 ~124 oak_leaves[persistent=true]
setblock ~28 ~164 ~126 jungle_leaves[persistent=true]
setblock ~28 ~164 ~128 oak_leaves[persistent=true]
setblock ~28 ~164 ~129 oak_leaves[persistent=true]
setblock ~28 ~164 ~130 oak_leaves[persistent=true]
setblock ~28 ~164 ~131 oak_leaves[persistent=true]
setblock ~28 ~164 ~132 oak_leaves[persistent=true]
setblock ~28 ~164 ~133 oak_leaves[persistent=true]
setblock ~28 ~164 ~134 oak_leaves[persistent=true]
setblock ~28 ~164 ~135 oak_leaves[persistent=true]
setblock ~28 ~165 ~118 oak_leaves[persistent=true]
setblock ~28 ~165 ~119 jungle_leaves[persistent=true]
setblock ~28 ~165 ~120 oak_leaves[persistent=true]
setblock ~28 ~165 ~121 oak_leaves[persistent=true]
setblock ~28 ~165 ~122 jungle_leaves[persistent=true]
setblock ~28 ~165 ~124 oak_leaves[persistent=true]
setblock ~28 ~165 ~125 oak_leaves[persistent=true]
setblock ~28 ~165 ~126 jungle_leaves[persistent=true]
setblock ~28 ~165 ~127 oak_leaves[persistent=true]
setblock ~28 ~165 ~128 oak_leaves[persistent=true]
setblock ~28 ~165 ~129 oak_leaves[persistent=true]
setblock ~28 ~165 ~130 oak_leaves[persistent=true]
setblock ~28 ~165 ~131 oak_leaves[persistent=true]
setblock ~28 ~165 ~133 oak_leaves[persistent=true]
setblock ~28 ~166 ~119 jungle_leaves[persistent=true]
setblock ~28 ~166 ~120 oak_leaves[persistent=true]
setblock ~28 ~166 ~121 jungle_leaves[persistent=true]
setblock ~28 ~166 ~122 jungle_leaves[persistent=true]
setblock ~28 ~166 ~123 oak_leaves[persistent=true]
setblock ~28 ~166 ~124 jungle_leaves[persistent=true]
setblock ~28 ~166 ~125 oak_leaves[persistent=true]
setblock ~28 ~166 ~126 oak_wood
setblock ~28 ~166 ~127 jungle_leaves[persistent=true]
setblock ~28 ~166 ~128 oak_leaves[persistent=true]
setblock ~28 ~166 ~129 oak_leaves[persistent=true]
setblock ~28 ~166 ~130 oak_leaves[persistent=true]
setblock ~28 ~166 ~131 oak_leaves[persistent=true]
setblock ~28 ~166 ~132 oak_leaves[persistent=true]
setblock ~28 ~166 ~133 oak_leaves[persistent=true]
setblock ~28 ~167 ~116 oak_leaves[persistent=true]
setblock ~28 ~167 ~117 oak_leaves[persistent=true]
setblock ~28 ~167 ~118 oak_leaves[persistent=true]
setblock ~28 ~167 ~119 oak_leaves[persistent=true]
setblock ~28 ~167 ~120 oak_leaves[persistent=true]
setblock ~28 ~167 ~121 oak_leaves[persistent=true]
setblock ~28 ~167 ~122 jungle_leaves[persistent=true]
setblock ~28 ~167 ~123 oak_leaves[persistent=true]
setblock ~28 ~167 ~124 oak_leaves[persistent=true]
setblock ~28 ~167 ~125 jungle_leaves[persistent=true]
setblock ~28 ~167 ~127 oak_leaves[persistent=true]
setblock ~28 ~167 ~128 oak_leaves[persistent=true]
setblock ~28 ~167 ~129 oak_leaves[persistent=true]
setblock ~28 ~167 ~130 oak_leaves[persistent=true]
setblock ~28 ~167 ~131 oak_leaves[persistent=true]
setblock ~28 ~167 ~132 oak_leaves[persistent=true]
setblock ~28 ~167 ~133 oak_leaves[persistent=true]
setblock ~28 ~168 ~116 oak_leaves[persistent=true]
setblock ~28 ~168 ~118 oak_leaves[persistent=true]
setblock ~28 ~168 ~119 jungle_leaves[persistent=true]
setblock ~28 ~168 ~120 oak_leaves[persistent=true]
setblock ~28 ~168 ~121 oak_leaves[persistent=true]
setblock ~28 ~168 ~122 oak_leaves[persistent=true]
setblock ~28 ~168 ~123 oak_leaves[persistent=true]
setblock ~28 ~168 ~124 jungle_leaves[persistent=true]
setblock ~28 ~168 ~125 jungle_leaves[persistent=true]
setblock ~28 ~168 ~126 jungle_leaves[persistent=true]
setblock ~28 ~168 ~127 oak_leaves[persistent=true]
setblock ~28 ~168 ~128 oak_leaves[persistent=true]
setblock ~28 ~168 ~129 oak_leaves[persistent=true]
setblock ~28 ~168 ~130 jungle_leaves[persistent=true]
setblock ~28 ~168 ~131 oak_leaves[persistent=true]
setblock ~28 ~168 ~132 oak_leaves[persistent=true]
setblock ~28 ~168 ~133 oak_leaves[persistent=true]
setblock ~28 ~169 ~118 jungle_leaves[persistent=true]
setblock ~28 ~169 ~119 oak_leaves[persistent=true]
setblock ~28 ~169 ~120 oak_leaves[persistent=true]
setblock ~28 ~169 ~121 jungle_leaves[persistent=true]
setblock ~28 ~169 ~122 jungle_leaves[persistent=true]
setblock ~28 ~169 ~125 oak_leaves[persistent=true]
setblock ~28 ~169 ~126 oak_leaves[persistent=true]
setblock ~28 ~169 ~127 oak_leaves[persistent=true]
setblock ~28 ~169 ~128 oak_leaves[persistent=true]
setblock ~28 ~169 ~129 oak_leaves[persistent=true]
setblock ~28 ~170 ~118 oak_leaves[persistent=true]
setblock ~28 ~170 ~119 oak_leaves[persistent=true]
setblock ~28 ~170 ~120 oak_leaves[persistent=true]
setblock ~28 ~170 ~121 oak_leaves[persistent=true]
setblock ~28 ~170 ~122 oak_leaves[persistent=true]
setblock ~28 ~170 ~123 oak_leaves[persistent=true]
setblock ~28 ~170 ~124 oak_leaves[persistent=true]
setblock ~28 ~170 ~125 jungle_leaves[persistent=true]
setblock ~28 ~170 ~126 jungle_leaves[persistent=true]
setblock ~28 ~170 ~127 oak_leaves[persistent=true]
setblock ~28 ~170 ~129 oak_leaves[persistent=true]
setblock ~28 ~171 ~118 oak_leaves[persistent=true]
setblock ~28 ~171 ~119 oak_leaves[persistent=true]
setblock ~28 ~171 ~120 oak_leaves[persistent=true]
setblock ~28 ~171 ~124 oak_leaves[persistent=true]
setblock ~28 ~171 ~125 oak_leaves[persistent=true]
setblock ~28 ~171 ~128 oak_leaves[persistent=true]
setblock ~28 ~171 ~129 oak_leaves[persistent=true]
setblock ~29 ~120 ~97 dirt
setblock ~29 ~121 ~81 dirt
setblock ~29 ~121 ~97 dirt
setblock ~29 ~121 ~99 dirt
setblock ~29 ~122 ~81 dirt
setblock ~29 ~122 ~97 dirt
setblock ~29 ~122 ~99 dirt
setblock ~29 ~123 ~81 dirt
setblock ~29 ~123 ~97 dirt
setblock ~29 ~123 ~99 dirt
setblock ~29 ~124 ~81 grass_block
setblock ~29 ~124 ~97 grass_block
setblock ~29 ~124 ~99 grass_block
setblock ~29 ~125 ~99 short_grass
setblock ~29 ~157 ~117 oak_leaves[persistent=true]
setblock ~29 ~157 ~118 oak_leaves[persistent=true]
setblock ~29 ~157 ~119 oak_leaves[persistent=true]
setblock ~29 ~157 ~120 oak_leaves[persistent=true]
setblock ~29 ~158 ~117 oak_leaves[persistent=true]
setblock ~29 ~158 ~119 oak_leaves[persistent=true]
setblock ~29 ~158 ~126 oak_leaves[persistent=true]
setblock ~29 ~158 ~127 jungle_leaves[persistent=true]
setblock ~29 ~158 ~128 jungle_leaves[persistent=true]
setblock ~29 ~158 ~131 oak_leaves[persistent=true]
setblock ~29 ~158 ~132 jungle_leaves[persistent=true]
setblock ~29 ~158 ~133 oak_leaves[persistent=true]
setblock ~29 ~158 ~134 oak_leaves[persistent=true]
setblock ~29 ~159 ~77 oak_leaves[persistent=true]
setblock ~29 ~159 ~78 oak_leaves[persistent=true]
setblock ~29 ~159 ~79 oak_leaves[persistent=true]
setblock ~29 ~159 ~80 jungle_leaves[persistent=true]
setblock ~29 ~159 ~117 jungle_leaves[persistent=true]
setblock ~29 ~159 ~118 oak_leaves[persistent=true]
setblock ~29 ~159 ~119 oak_leaves[persistent=true]
setblock ~29 ~159 ~120 oak_leaves[persistent=true]
setblock ~29 ~159 ~121 oak_leaves[persistent=true]
setblock ~29 ~159 ~122 oak_leaves[persistent=true]
setblock ~29 ~159 ~124 oak_leaves[persistent=true]
setblock ~29 ~159 ~125 oak_leaves[persistent=true]
setblock ~29 ~159 ~126 oak_leaves[persistent=true]
setblock ~29 ~159 ~127 jungle_leaves[persistent=true]
setblock ~29 ~159 ~128 jungle_leaves[persistent=true]
setblock ~29 ~159 ~132 oak_leaves[persistent=true]
setblock ~29 ~159 ~133 oak_leaves[persistent=true]
setblock ~29 ~159 ~134 oak_leaves[persistent=true]
setblock ~29 ~160 ~77 oak_leaves[persistent=true]
setblock ~29 ~160 ~78 oak_leaves[persistent=true]
setblock ~29 ~160 ~79 oak_leaves[persistent=true]
setblock ~29 ~160 ~80 oak_leaves[persistent=true]
setblock ~29 ~160 ~117 jungle_leaves[persistent=true]
setblock ~29 ~160 ~118 oak_leaves[persistent=true]
setblock ~29 ~160 ~119 oak_leaves[persistent=true]
setblock ~29 ~160 ~120 oak_leaves[persistent=true]
setblock ~29 ~160 ~121 oak_leaves[persistent=true]
setblock ~29 ~160 ~122 oak_leaves[persistent=true]
setblock ~29 ~160 ~123 oak_leaves[persistent=true]
setblock ~29 ~160 ~126 oak_leaves[persistent=true]
setblock ~29 ~160 ~127 oak_leaves[persistent=true]
setblock ~29 ~160 ~128 oak_leaves[persistent=true]
setblock ~29 ~160 ~132 oak_leaves[persistent=true]
setblock ~29 ~160 ~133 jungle_leaves[persistent=true]
setblock ~29 ~160 ~134 jungle_leaves[persistent=true]
setblock ~29 ~161 ~78 oak_leaves[persistent=true]
setblock ~29 ~161 ~79 oak_leaves[persistent=true]
setblock ~29 ~161 ~80 oak_leaves[persistent=true]
setblock ~29 ~161 ~119 oak_leaves[persistent=true]
setblock ~29 ~161 ~120 oak_leaves[persistent=true]
setblock ~29 ~161 ~121 oak_leaves[persistent=true]
setblock ~29 ~161 ~122 oak_leaves[persistent=true]
setblock ~29 ~161 ~123 jungle_leaves[persistent=true]
setblock ~29 ~161 ~125 oak_leaves[persistent=true]
setblock ~29 ~161 ~126 oak_leaves[persistent=true]
setblock ~29 ~161 ~127 oak_leaves[persistent=true]
setblock ~29 ~161 ~128 oak_leaves[persistent=true]
setblock ~29 ~161 ~130 jungle_leaves[persistent=true]
setblock ~29 ~161 ~131 oak_leaves[persistent=true]
setblock ~29 ~161 ~132 oak_leaves[persistent=true]
setblock ~29 ~161 ~133 jungle_leaves[persistent=true]
setblock ~29 ~161 ~134 oak_leaves[persistent=true]
setblock ~29 ~161 ~135 oak_leaves[persistent=true]
setblock ~29 ~162 ~77 oak_leaves[persistent=true]
setblock ~29 ~162 ~78 jungle_leaves[persistent=true]
setblock ~29 ~162 ~79 oak_leaves[persistent=true]
setblock ~29 ~162 ~80 oak_leaves[persistent=true]
setblock ~29 ~162 ~113 oak_leaves[persistent=true]
setblock ~29 ~162 ~114 oak_leaves[persistent=true]
setblock ~29 ~162 ~115 oak_leaves[persistent=true]
setblock ~29 ~162 ~118 oak_leaves[persistent=true]
setblock ~29 ~162 ~119 oak_leaves[persistent=true]
setblock ~29 ~162 ~120 oak_leaves[persistent=true]
setblock ~29 ~162 ~121 oak_leaves[persistent=true]
setblock ~29 ~162 ~122 oak_leaves[persistent=true]
setblock ~29 ~162 ~123 oak_leaves[persistent=true]
setblock ~29 ~162 ~124 oak_leaves[persistent=true]
setblock ~29 ~162 ~125 oak_leaves[persistent=true]
setblock ~29 ~162 ~126 oak_leaves[persistent=true]
setblock ~29 ~162 ~127 oak_leaves[persistent=true]
setblock ~29 ~162 ~129 oak_leaves[persistent=true]
setblock ~29 ~162 ~130 oak_leaves[persistent=true]
setblock ~29 ~162 ~131 oak_leaves[persistent=true]
setblock ~29 ~162 ~132 oak_leaves[persistent=true]
setblock ~29 ~162 ~133 oak_leaves[persistent=true]
setblock ~29 ~162 ~134 oak_leaves[persistent=true]
setblock ~29 ~162 ~135 oak_leaves[persistent=true]
setblock ~29 ~163 ~112 oak_leaves[persistent=true]
setblock ~29 ~163 ~113 oak_leaves[persistent=true]
setblock ~29 ~163 ~114 oak_leaves[persistent=true]
setblock ~29 ~163 ~115 oak_leaves[persistent=true]
setblock ~29 ~163 ~118 oak_leaves[persistent=true]
setblock ~29 ~163 ~119 oak_leaves[persistent=true]
setblock ~29 ~163 ~120 oak_leaves[persistent=true]
setblock ~29 ~163 ~121 oak_leaves[persistent=true]
setblock ~29 ~163 ~122 jungle_leaves[persistent=true]
setblock ~29 ~163 ~123 oak_leaves[persistent=true]
setblock ~29 ~163 ~124 jungle_leaves[persistent=true]
setblock ~29 ~163 ~125 oak_leaves[persistent=true]
setblock ~29 ~163 ~126 oak_leaves[persistent=true]
setblock ~29 ~163 ~127 jungle_leaves[persistent=true]
setblock ~29 ~163 ~128 oak_leaves[persistent=true]
setblock ~29 ~163 ~129 oak_leaves[persistent=true]
setblock ~29 ~163 ~130 jungle_leaves[persistent=true]
setblock ~29 ~163 ~131 oak_wood
setblock ~29 ~163 ~132 oak_leaves[persistent=true]
setblock ~29 ~163 ~133 oak_leaves[persistent=true]
setblock ~29 ~163 ~134 jungle_leaves[persistent=true]
setblock ~29 ~163 ~135 oak_leaves[persistent=true]
setblock ~29 ~164 ~112 oak_leaves[persistent=true]
setblock ~29 ~164 ~113 oak_leaves[persistent=true]
setblock ~29 ~164 ~114 oak_leaves[persistent=true]
setblock ~29 ~164 ~115 oak_leaves[persistent=true]
setblock ~29 ~164 ~118 oak_leaves[persistent=true]
setblock ~29 ~164 ~120 oak_leaves[persistent=true]
setblock ~29 ~164 ~121 oak_leaves[persistent=true]
setblock ~29 ~164 ~122 oak_leaves[persistent=true]
setblock ~29 ~164 ~123 oak_leaves[persistent=true]
setblock ~29 ~164 ~124 oak_leaves[persistent=true]
setblock ~29 ~164 ~125 jungle_leaves[persistent=true]
setblock ~29 ~164 ~127 oak_leaves[persistent=true]
setblock ~29 ~164 ~128 oak_leaves[persistent=true]
setblock ~29 ~164 ~129 oak_leaves[persistent=true]
setblock ~29 ~164 ~130 oak_leaves[persistent=true]
setblock ~29 ~164 ~131 oak_leaves[persistent=true]
setblock ~29 ~164 ~132 oak_leaves[persistent=true]
setblock ~29 ~164 ~133 oak_leaves[persistent=true]
setblock ~29 ~164 ~134 oak_leaves[persistent=true]
setblock ~29 ~164 ~135 oak_leaves[persistent=true]
setblock ~29 ~165 ~112 oak_leaves[persistent=true]
setblock ~29 ~165 ~115 oak_leaves[persistent=true]
setblock ~29 ~165 ~117 oak_leaves[persistent=true]
setblock ~29 ~165 ~118 oak_leaves[persistent=true]
setblock ~29 ~165 ~119 jungle_leaves[persistent=true]
setblock ~29 ~165 ~120 oak_leaves[persistent=true]
setblock ~29 ~165 ~121 oak_leaves[persistent=true]
setblock ~29 ~165 ~122 oak_leaves[persistent=true]
setblock ~29 ~165 ~123 oak_leaves[persistent=true]
setblock ~29 ~165 ~124 oak_leaves[persistent=true]
setblock ~29 ~165 ~125 jungle_leaves[persistent=true]
setblock ~29 ~165 ~127 oak_leaves[persistent=true]
setblock ~29 ~165 ~128 oak_leaves[persistent=true]
setblock ~29 ~165 ~129 oak_leaves[persistent=true]
setblock ~29 ~165 ~130 oak_leaves[persistent=true]
setblock ~29 ~165 ~131 oak_leaves[persistent=true]
setblock ~29 ~165 ~132 oak_leaves[persistent=true]
setblock ~29 ~165 ~133 oak_leaves[persistent=true]
setblock ~29 ~166 ~113 oak_leaves[persistent=true]
setblock ~29 ~166 ~114 oak_leaves[persistent=true]
setblock ~29 ~166 ~115 jungle_leaves[persistent=true]
setblock ~29 ~166 ~116 jungle_leaves[persistent=true]
setblock ~29 ~166 ~117 jungle_leaves[persistent=true]
setblock ~29 ~166 ~118 jungle_leaves[persistent=true]
setblock ~29 ~166 ~119 oak_leaves[persistent=true]
setblock ~29 ~166 ~120 oak_leaves[persistent=true]
setblock ~29 ~166 ~121 oak_leaves[persistent=true]
setblock ~29 ~166 ~122 oak_wood
setblock ~29 ~166 ~123 oak_leaves[persistent=true]
setblock ~29 ~166 ~124 oak_leaves[persistent=true]
setblock ~29 ~166 ~125 oak_leaves[persistent=true]
setblock ~29 ~166 ~126 jungle_leaves[persistent=true]
setblock ~29 ~166 ~127 oak_leaves[persistent=true]
setblock ~29 ~166 ~128 jungle_leaves[persistent=true]
setblock ~29 ~166 ~129 oak_leaves[persistent=true]
setblock ~29 ~166 ~130 oak_leaves[persistent=true]
setblock ~29 ~166 ~131 jungle_leaves[persistent=true]
setblock ~29 ~166 ~132 oak_leaves[persistent=true]
setblock ~29 ~166 ~133 oak_leaves[persistent=true]
setblock ~29 ~167 ~113 oak_leaves[persistent=true]
setblock ~29 ~167 ~114 jungle_leaves[persistent=true]
setblock ~29 ~167 ~115 oak_leaves[persistent=true]
setblock ~29 ~167 ~116 oak_leaves[persistent=true]
setblock ~29 ~167 ~117 oak_leaves[persistent=true]
setblock ~29 ~167 ~118 jungle_leaves[persistent=true]
setblock ~29 ~167 ~120 jungle_leaves[persistent=true]
setblock ~29 ~167 ~121 oak_leaves[persistent=true]
setblock ~29 ~167 ~123 jungle_leaves[persistent=true]
setblock ~29 ~167 ~124 oak_leaves[persistent=true]
setblock ~29 ~167 ~125 oak_wood
setblock ~29 ~167 ~126 oak_wood
setblock ~29 ~167 ~127 jungle_leaves[persistent=true]
setblock ~29 ~167 ~128 oak_leaves[persistent=true]
setblock ~29 ~167 ~130 oak_wood
setblock ~29 ~167 ~131 oak_leaves[persistent=true]
setblock ~29 ~167 ~132 oak_leaves[persistent=true]
setblock ~29 ~167 ~133 oak_leaves[persistent=true]
setblock ~29 ~168 ~113 jungle_leaves[persistent=true]
setblock ~29 ~168 ~114 oak_leaves[persistent=true]
setblock ~29 ~168 ~115 jungle_leaves[persistent=true]
setblock ~29 ~168 ~116 jungle_leaves[persistent=true]
setblock ~29 ~168 ~117 oak_leaves[persistent=true]
setblock ~29 ~168 ~119 jungle_leaves[persistent=true]
setblock ~29 ~168 ~120 oak_leaves[persistent=true]
setblock ~29 ~168 ~121 oak_leaves[persistent=true]
setblock ~29 ~168 ~122 oak_leaves[persistent=true]
setblock ~29 ~168 ~123 oak_leaves[persistent=true]
setblock ~29 ~168 ~124 oak_leaves[persistent=true]
setblock ~29 ~168 ~125 oak_leaves[persistent=true]
setblock ~29 ~168 ~126 oak_leaves[persistent=true]
setblock ~29 ~168 ~127 oak_wood
setblock ~29 ~168 ~128 oak_wood
setblock ~29 ~168 ~129 jungle_leaves[persistent=true]
setblock ~29 ~168 ~130 jungle_leaves[persistent=true]
setblock ~29 ~168 ~132 oak_leaves[persistent=true]
setblock ~29 ~168 ~133 oak_leaves[persistent=true]
setblock ~29 ~169 ~113 oak_leaves[persistent=true]
setblock ~29 ~169 ~114 oak_leaves[persistent=true]
setblock ~29 ~169 ~115 oak_leaves[persistent=true]
setblock ~29 ~169 ~116 jungle_leaves[persistent=true]
setblock ~29 ~169 ~117 oak_leaves[persistent=true]
setblock ~29 ~169 ~118 oak_leaves[persistent=true]
setblock ~29 ~169 ~119 oak_leaves[persistent=true]
setblock ~29 ~169 ~121 jungle_leaves[persistent=true]
setblock ~29 ~169 ~122 oak_leaves[persistent=true]
setblock ~29 ~169 ~123 oak_leaves[persistent=true]
setblock ~29 ~169 ~124 oak_leaves[persistent=true]
setblock ~29 ~169 ~125 oak_leaves[persistent=true]
setblock ~29 ~169 ~126 oak_leaves[persistent=true]
setblock ~29 ~169 ~127 oak_leaves[persistent=true]
setblock ~29 ~169 ~129 jungle_leaves[persistent=true]
setblock ~29 ~170 ~117 oak_leaves[persistent=true]
setblock ~29 ~170 ~119 oak_leaves[persistent=true]
setblock ~29 ~170 ~120 oak_leaves[persistent=true]
setblock ~29 ~170 ~121 oak_leaves[persistent=true]
setblock ~29 ~170 ~122 oak_leaves[persistent=true]
setblock ~29 ~170 ~123 oak_leaves[persistent=true]
setblock ~29 ~170 ~124 oak_leaves[persistent=true]
setblock ~29 ~170 ~125 oak_leaves[persistent=true]
setblock ~29 ~170 ~126 oak_leaves[persistent=true]
setblock ~29 ~170 ~127 jungle_leaves[persistent=true]
setblock ~29 ~170 ~128 oak_leaves[persistent=true]
setblock ~29 ~170 ~129 jungle_leaves[persistent=true]
setblock ~29 ~171 ~118 oak_leaves[persistent=true]
setblock ~29 ~171 ~120 jungle_leaves[persistent=true]
setblock ~29 ~171 ~121 oak_leaves[persistent=true]
setblock ~29 ~171 ~122 oak_leaves[persistent=true]
setblock ~29 ~171 ~123 oak_leaves[persistent=true]
setblock ~29 ~171 ~124 jungle_leaves[persistent=true]
setblock ~29 ~171 ~125 oak_leaves[persistent=true]
setblock ~29 ~171 ~126 oak_leaves[persistent=true]
setblock ~29 ~171 ~127 oak_leaves[persistent=true]
setblock ~29 ~171 ~128 oak_leaves[persistent=true]
setblock ~29 ~171 ~129 oak_leaves[persistent=true]
setblock ~30 ~118 ~98 dirt
setblock ~30 ~118 ~99 dirt
setblock ~30 ~119 ~97 dirt
setblock ~30 ~119 ~98 dirt
setblock ~30 ~119 ~99 dirt
setblock ~30 ~120 ~81 dirt
setblock ~30 ~120 ~96 dirt
setblock ~30 ~120 ~97 dirt
setblock ~30 ~120 ~98 dirt
setblock ~30 ~120 ~99 dirt
setblock ~30 ~121 ~75 dirt
setblock ~30 ~121 ~80 dirt
setblock ~30 ~121 ~81 dirt
setblock ~30 ~121 ~82 dirt
setblock ~30 ~121 ~96 dirt
setblock ~30 ~121 ~97 dirt
setblock ~30 ~121 ~98 dirt
setblock ~30 ~121 ~99 dirt
setblock ~30 ~121 ~100 dirt
setblock ~30 ~122 ~75 dirt
setblock ~30 ~122 ~80 dirt
setblock ~30 ~122 ~81 dirt
setblock ~30 ~122 ~82 dirt
setblock ~30 ~122 ~96 dirt
setblock ~30 ~122 ~97 dirt
setblock ~30 ~122 ~98 dirt
setblock ~30 ~122 ~99 dirt
setblock ~30 ~122 ~100 dirt
setblock ~30 ~123 ~75 dirt
setblock ~30 ~123 ~80 grass_block
setblock ~30 ~123 ~81 grass_block
setblock ~30 ~123 ~82 dirt
setblock ~30 ~123 ~96 dirt
setblock ~30 ~123 ~97 dirt
setblock ~30 ~123 ~98 dirt
setblock ~30 ~123 ~99 dirt
setblock ~30 ~123 ~100 dirt
setblock ~30 ~124 ~75 dirt
setblock ~30 ~124 ~80 fern
setblock ~30 ~124 ~82 grass_block
setblock ~30 ~124 ~96 dirt
setblock ~30 ~124 ~97 grass_block
setblock ~30 ~124 ~98 grass_block
setblock ~30 ~124 ~99 grass_block
setblock ~30 ~124 ~100 grass_block
setblock ~30 ~125 ~75 grass_block
setblock ~30 ~125 ~96 grass_block
setblock ~30 ~125 ~97 fern
setblock ~30 ~153 ~118 oak_leaves[persistent=true]
setblock ~30 ~153 ~119 oak_leaves[persistent=true]
setblock ~30 ~153 ~120 oak_leaves[persistent=true]
setblock ~30 ~153 ~121 jungle_leaves[persistent=true]
setblock ~30 ~154 ~118 jungle_leaves[persistent=true]
setblock ~30 ~154 ~119 oak_leaves[persistent=true]
setblock ~30 ~154 ~120 oak_leaves[persistent=true]
setblock ~30 ~154 ~121 jungle_leaves[persistent=true]
setblock ~30 ~155 ~118 oak_leaves[persistent=true]
setblock ~30 ~155 ~119 jungle_leaves[persistent=true]
setblock ~30 ~155 ~120 jungle_leaves[persistent=true]
setblock ~30 ~155 ~121 oak_leaves[persistent=true]
setblock ~30 ~156 ~118 oak_leaves[persistent=true]
setblock ~30 ~156 ~119 oak_leaves[persistent=true]
setblock ~30 ~156 ~120 oak_leaves[persistent=true]
setblock ~30 ~156 ~121 oak_leaves[persistent=true]
setblock ~30 ~156 ~127 jungle_leaves[persistent=true]
setblock ~30 ~156 ~129 oak_leaves[persistent=true]
setblock ~30 ~156 ~130 oak_leaves[persistent=true]
setblock ~30 ~157 ~117 oak_leaves[persistent=true]
setblock ~30 ~157 ~118 jungle_leaves[persistent=true]
setblock ~30 ~157 ~119 oak_leaves[persistent=true]
setblock ~30 ~157 ~120 oak_leaves[persistent=true]
setblock ~30 ~157 ~122 oak_leaves[persistent=true]
setblock ~30 ~157 ~127 oak_leaves[persistent=true]
setblock ~30 ~157 ~128 jungle_leaves[persistent=true]
setblock ~30 ~157 ~129 oak_leaves[persistent=true]
setblock ~30 ~157 ~130 oak_leaves[persistent=true]
setblock ~30 ~158 ~117 oak_leaves[persistent=true]
setblock ~30 ~158 ~118 oak_leaves[persistent=true]
setblock ~30 ~158 ~119 oak_leaves[persistent=true]
setblock ~30 ~158 ~121 oak_leaves[persistent=true]
setblock ~30 ~158 ~122 oak_leaves[persistent=true]
setblock ~30 ~158 ~123 jungle_leaves[persistent=true]
setblock ~30 ~158 ~124 oak_leaves[persistent=true]
setblock ~30 ~158 ~125 oak_leaves[persistent=true]
setblock ~30 ~158 ~126 oak_leaves[persistent=true]
setblock ~30 ~158 ~127 oak_leaves[persistent=true]
setblock ~30 ~158 ~128 oak_leaves[persistent=true]
setblock ~30 ~158 ~129 oak_leaves[persistent=true]
setblock ~30 ~158 ~130 oak_leaves[persistent=true]
setblock ~30 ~158 ~131 oak_leaves[persistent=true]
setblock ~30 ~158 ~132 oak_leaves[persistent=true]
setblock ~30 ~158 ~133 oak_leaves[persistent=true]
setblock ~30 ~159 ~77 oak_leaves[persistent=true]
setblock ~30 ~159 ~78 jungle_leaves[persistent=true]
setblock ~30 ~159 ~79 oak_leaves[persistent=true]
setblock ~30 ~159 ~114 oak_leaves[persistent=true]
setblock ~30 ~159 ~115 jungle_leaves[persistent=true]
setblock ~30 ~159 ~116 oak_leaves[persistent=true]
setblock ~30 ~159 ~117 oak_leaves[persistent=true]
setblock ~30 ~159 ~118 oak_leaves[persistent=true]
setblock ~30 ~159 ~119 oak_leaves[persistent=true]
setblock ~30 ~159 ~120 oak_leaves[persistent=true]
setblock ~30 ~159 ~121 oak_leaves[persistent=true]
setblock ~30 ~159 ~122 oak_leaves[persistent=true]
setblock ~30 ~159 ~123 oak_leaves[persistent=true]
setblock ~30 ~159 ~124 jungle_leaves[persistent=true]
setblock ~30 ~159 ~125 jungle_leaves[persistent=true]
setblock ~30 ~159 ~129 oak_leaves[persistent=true]
setblock ~30 ~159 ~131 oak_leaves[persistent=true]
setblock ~30 ~159 ~132 oak_wood
setblock ~30 ~159 ~133 oak_leaves[persistent=true]
setblock ~30 ~159 ~134 oak_leaves[persistent=true]
setblock ~30 ~160 ~77 jungle_leaves[persistent=true]
setblock ~30 ~160 ~78 oak_leaves[persistent=true]
setblock ~30 ~160 ~79 oak_leaves[persistent=true]
setblock ~30 ~160 ~80 oak_leaves[persistent=true]
setblock ~30 ~160 ~114 oak_leaves[persistent=true]
setblock ~30 ~160 ~115 oak_leaves[persistent=true]
setblock ~30 ~160 ~116 jungle_leaves[persistent=true]
setblock ~30 ~160 ~117 oak_leaves[persistent=true]
setblock ~30 ~160 ~118 jungle_leaves[persistent=true]
setblock ~30 ~160 ~119 oak_leaves[persistent=true]
setblock ~30 ~160 ~120 oak_leaves[persistent=true]
setblock ~30 ~160 ~121 jungle_leaves[persistent=true]
setblock ~30 ~160 ~122 oak_leaves[persistent=true]
setblock ~30 ~160 ~123 oak_leaves[persistent=true]
setblock ~30 ~160 ~125 oak_leaves[persistent=true]
setblock ~30 ~160 ~126 oak_leaves[persistent=true]
setblock ~30 ~160 ~127 oak_leaves[persistent=true]
setblock ~30 ~160 ~128 jungle_leaves[persistent=true]
setblock ~30 ~160 ~129 oak_leaves[persistent=true]
setblock ~30 ~160 ~130 oak_leaves[persistent=true]
setblock ~30 ~160 ~131 oak_leaves[persistent=true]
setblock ~30 ~160 ~132 oak_leaves[persistent=true]
setblock ~30 ~160 ~133 jungle_leaves[persistent=true]
setblock ~30 ~160 ~134 oak_leaves[persistent=true]
setblock ~30 ~161 ~77 oak_leaves[persistent=true]
setblock ~30 ~161 ~78 jungle_leaves[persistent=true]
setblock ~30 ~161 ~79 jungle_leaves[persistent=true]
setblock ~30 ~161 ~114 jungle_leaves[persistent=true]
setblock ~30 ~161 ~115 oak_leaves[persistent=true]
setblock ~30 ~161 ~119 oak_leaves[persistent=true]
setblock ~30 ~161 ~120 oak_leaves[persistent=true]
setblock ~30 ~161 ~121 oak_leaves[persistent=true]
setblock ~30 ~161 ~122 oak_leaves[persistent=true]
setblock ~30 ~161 ~123 oak_leaves[persistent=true]
setblock ~30 ~161 ~124 jungle_leaves[persistent=true]
setblock ~30 ~161 ~125 oak_leaves[persistent=true]
setblock ~30 ~161 ~126 oak_leaves[persistent=true]
setblock ~30 ~161 ~127 oak_leaves[persistent=true]
setblock ~30 ~161 ~129 oak_leaves[persistent=true]
setblock ~30 ~161 ~130 oak_leaves[persistent=true]
setblock ~30 ~161 ~131 oak_leaves[persistent=true]
setblock ~30 ~161 ~132 oak_leaves[persistent=true]
setblock ~30 ~161 ~133 oak_leaves[persistent=true]
setblock ~30 ~161 ~134 oak_leaves[persistent=true]
setblock ~30 ~161 ~135 oak_leaves[persistent=true]
setblock ~30 ~162 ~77 oak_leaves[persistent=true]
setblock ~30 ~162 ~78 oak_leaves[persistent=true]
setblock ~30 ~162 ~79 oak_leaves[persistent=true]
setblock ~30 ~162 ~80 oak_leaves[persistent=true]
setblock ~30 ~162 ~112 oak_leaves[persistent=true]
setblock ~30 ~162 ~113 oak_leaves[persistent=true]
setblock ~30 ~162 ~114 jungle_leaves[persistent=true]
setblock ~30 ~162 ~115 oak_leaves[persistent=true]
setblock ~30 ~162 ~117 oak_leaves[persistent=true]
setblock ~30 ~162 ~118 oak_leaves[persistent=true]
setblock ~30 ~162 ~119 oak_leaves[persistent=true]
setblock ~30 ~162 ~120 oak_leaves[persistent=true]
setblock ~30 ~162 ~121 oak_leaves[persistent=true]
setblock ~30 ~162 ~122 oak_leaves[persistent=true]
setblock ~30 ~162 ~123 oak_leaves[persistent=true]
setblock ~30 ~162 ~124 oak_leaves[persistent=true]
setblock ~30 ~162 ~125 oak_wood
setblock ~30 ~162 ~127 jungle_leaves[persistent=true]
setblock ~30 ~162 ~128 jungle_leaves[persistent=true]
setblock ~30 ~162 ~129 jungle_leaves[persistent=true]
setblock ~30 ~162 ~130 jungle_leaves[persistent=true]
setblock ~30 ~162 ~131 oak_leaves[persistent=true]
setblock ~30 ~162 ~132 oak_leaves[persistent=true]
setblock ~30 ~162 ~133 jungle_leaves[persistent=true]
setblock ~30 ~162 ~134 oak_leaves[persistent=true]
setblock ~30 ~162 ~135 jungle_leaves[persistent=true]
setblock ~30 ~163 ~112 oak_leaves[persistent=true]
setblock ~30 ~163 ~113 oak_leaves[persistent=true]
setblock ~30 ~163 ~114 oak_leaves[persistent=true]
setblock ~30 ~163 ~115 jungle_leaves[persistent=true]
setblock ~30 ~163 ~116 oak_leaves[persistent=true]
setblock ~30 ~163 ~117 oak_leaves[persistent=true]
setblock ~30 ~163 ~118 oak_leaves[persistent=true]
setblock ~30 ~163 ~119 oak_leaves[persistent=true]
setblock ~30 ~163 ~121 oak_leaves[persistent=true]
setblock ~30 ~163 ~122 oak_leaves[persistent=true]
setblock ~30 ~163 ~123 oak_leaves[persistent=true]
setblock ~30 ~163 ~124 oak_leaves[persistent=true]
setblock ~30 ~163 ~125 jungle_leaves[persistent=true]
setblock ~30 ~163 ~126 oak_leaves[persistent=true]
setblock ~30 ~163 ~128 oak_leaves[persistent=true]
setblock ~30 ~163 ~129 oak_leaves[persistent=true]
setblock ~30 ~163 ~130 oak_leaves[persistent=true]
setblock ~30 ~163 ~131 oak_leaves[persistent=true]
setblock ~30 ~163 ~132 jungle_leaves[persistent=true]
setblock ~30 ~163 ~133 oak_leaves[persistent=true]
setblock ~30 ~163 ~134 oak_wood
setblock ~30 ~163 ~135 oak_leaves[persistent=true]
setblock ~30 ~164 ~112 oak_leaves[persistent=true]
setblock ~30 ~164 ~113 oak_leaves[persistent=true]
setblock ~30 ~164 ~114 oak_leaves[persistent=true]
setblock ~30 ~164 ~115 oak_leaves[persistent=true]
setblock ~30 ~164 ~116 jungle_leaves[persistent=true]
setblock ~30 ~164 ~117 oak_leaves[persistent=true]
setblock ~30 ~164 ~118 oak_leaves[persistent=true]
setblock ~30 ~164 ~119 oak_leaves[persistent=true]
setblock ~30 ~164 ~120 oak_leaves[persistent=true]
setblock ~30 ~164 ~121 oak_leaves[persistent=true]
setblock ~30 ~164 ~122 oak_leaves[persistent=true]
setblock ~30 ~164 ~123 oak_wood
setblock ~30 ~164 ~126 oak_leaves[persistent=true]
setblock ~30 ~164 ~127 oak_leaves[persistent=true]
setblock ~30 ~164 ~128 jungle_leaves[persistent=true]
setblock ~30 ~164 ~129 jungle_leaves[persistent=true]
setblock ~30 ~164 ~130 oak_wood
setblock ~30 ~164 ~131 oak_leaves[persistent=true]
setblock ~30 ~164 ~132 jungle_leaves[persistent=true]
setblock ~30 ~164 ~133 oak_leaves[persistent=true]
setblock ~30 ~164 ~134 jungle_leaves[persistent=true]
setblock ~30 ~164 ~135 oak_leaves[persistent=true]
setblock ~30 ~165 ~113 oak_leaves[persistent=true]
setblock ~30 ~165 ~114 oak_leaves[persistent=true]
setblock ~30 ~165 ~116 oak_leaves[persistent=true]
setblock ~30 ~165 ~117 oak_leaves[persistent=true]
setblock ~30 ~165 ~118 oak_leaves[persistent=true]
setblock ~30 ~165 ~119 oak_leaves[persistent=true]
setblock ~30 ~165 ~120 oak_wood
setblock ~30 ~165 ~121 oak_wood
setblock ~30 ~165 ~122 oak_leaves[persistent=true]
setblock ~30 ~165 ~123 oak_leaves[persistent=true]
setblock ~30 ~165 ~124 oak_leaves[persistent=true]
setblock ~30 ~165 ~125 oak_leaves[persistent=true]
setblock ~30 ~165 ~126 oak_leaves[persistent=true]
setblock ~30 ~165 ~127 oak_leaves[persistent=true]
setblock ~30 ~165 ~128 oak_leaves[persistent=true]
setblock ~30 ~165 ~129 jungle_leaves[persistent=true]
setblock ~30 ~165 ~130 jungle_leaves[persistent=true]
setblock ~30 ~165 ~131 oak_leaves[persistent=true]
setblock ~30 ~165 ~132 oak_leaves[persistent=true]
setblock ~30 ~166 ~113 oak_leaves[persistent=true]
setblock ~30 ~166 ~114 oak_leaves[persistent=true]
setblock ~30 ~166 ~115 oak_leaves[persistent=true]
setblock ~30 ~166 ~116 oak_leaves[persistent=true]
setblock ~30 ~166 ~117 oak_leaves[persistent=true]
setblock ~30 ~166 ~118 oak_leaves[persistent=true]
setblock ~30 ~166 ~119 oak_leaves[persistent=true]
setblock ~30 ~166 ~120 oak_leaves[persistent=true]
setblock ~30 ~166 ~121 oak_leaves[persistent=true]
setblock ~30 ~166 ~122 oak_wood
setblock ~30 ~166 ~123 oak_leaves[persistent=true]
setblock ~30 ~166 ~124 oak_leaves[persistent=true]
setblock ~30 ~166 ~125 jungle_leaves[persistent=true]
setblock ~30 ~166 ~126 oak_leaves[persistent=true]
setblock ~30 ~166 ~127 oak_leaves[persistent=true]
setblock ~30 ~166 ~128 oak_leaves[persistent=true]
setblock ~30 ~166 ~130 oak_wood
setblock ~30 ~166 ~131 oak_leaves[persistent=true]
setblock ~30 ~166 ~132 oak_leaves[persistent=true]
setblock ~30 ~166 ~133 jungle_leaves[persistent=true]
setblock ~30 ~167 ~113 oak_leaves[persistent=true]
setblock ~30 ~167 ~117 jungle_leaves[persistent=true]
setblock ~30 ~167 ~118 oak_leaves[persistent=true]
setblock ~30 ~167 ~119 oak_leaves[persistent=true]
setblock ~30 ~167 ~121 oak_leaves[persistent=true]
setblock ~30 ~167 ~122 oak_leaves[persistent=true]
setblock ~30 ~167 ~123 oak_wood
setblock ~30 ~167 ~124 oak_wood
setblock ~30 ~167 ~125 oak_leaves[persistent=true]
setblock ~30 ~167 ~126 oak_leaves[persistent=true]
setblock ~30 ~167 ~127 oak_wood
setblock ~30 ~167 ~128 jungle_leaves[persistent=true]
setblock ~30 ~167 ~129 oak_wood
setblock ~30 ~167 ~130 oak_leaves[persistent=true]
setblock ~30 ~167 ~131 oak_wood
setblock ~30 ~167 ~132 oak_leaves[persistent=true]
setblock ~30 ~167 ~133 jungle_leaves[persistent=true]
setblock ~30 ~168 ~113 jungle_leaves[persistent=true]
setblock ~30 ~168 ~114 oak_leaves[persistent=true]
setblock ~30 ~168 ~115 oak_leaves[persistent=true]
setblock ~30 ~168 ~117 oak_leaves[persistent=true]
setblock ~30 ~168 ~118 oak_wood
setblock ~30 ~168 ~119 jungle_leaves[persistent=true]
setblock ~30 ~168 ~120 oak_leaves[persistent=true]
setblock ~30 ~168 ~121 oak_wood
setblock ~30 ~168 ~122 oak_leaves[persistent=true]
setblock ~30 ~168 ~123 oak_wood
setblock ~30 ~168 ~124 oak_wood
setblock ~30 ~168 ~125 oak_wood
setblock ~30 ~168 ~126 jungle_leaves[persistent=true]
setblock ~30 ~168 ~127 oak_leaves[persistent=true]
setblock ~30 ~168 ~128 oak_leaves[persistent=true]
setblock ~30 ~168 ~129 oak_leaves[persistent=true]
setblock ~30 ~168 ~130 oak_leaves[persistent=true]
setblock ~30 ~168 ~131 oak_leaves[persistent=true]
setblock ~30 ~168 ~132 oak_leaves[persistent=true]
setblock ~30 ~168 ~133 oak_leaves[persistent=true]
setblock ~30 ~169 ~113 oak_leaves[persistent=true]
setblock ~30 ~169 ~115 oak_leaves[persistent=true]
setblock ~30 ~169 ~116 oak_leaves[persistent=true]
setblock ~30 ~169 ~117 oak_leaves[persistent=true]
setblock ~30 ~169 ~118 oak_leaves[persistent=true]
setblock ~30 ~169 ~119 oak_leaves[persistent=true]
setblock ~30 ~169 ~120 jungle_leaves[persistent=true]
setblock ~30 ~169 ~121 oak_leaves[persistent=true]
setblock ~30 ~169 ~122 jungle_leaves[persistent=true]
setblock ~30 ~169 ~123 oak_leaves[persistent=true]
setblock ~30 ~169 ~124 oak_leaves[persistent=true]
setblock ~30 ~169 ~125 oak_leaves[persistent=true]
setblock ~30 ~169 ~126 oak_leaves[persistent=true]
setblock ~30 ~169 ~127 oak_leaves[persistent=true]
setblock ~30 ~169 ~128 oak_leaves[persistent=true]
setblock ~30 ~169 ~129 oak_leaves[persistent=true]
setblock ~30 ~170 ~117 oak_leaves[persistent=true]
setblock ~30 ~170 ~118 oak_leaves[persistent=true]
setblock ~30 ~170 ~119 oak_leaves[persistent=true]
setblock ~30 ~170 ~121 jungle_leaves[persistent=true]
setblock ~30 ~170 ~122 oak_log
setblock ~30 ~170 ~123 oak_leaves[persistent=true]
setblock ~30 ~170 ~124 oak_leaves[persistent=true]
setblock ~30 ~170 ~125 oak_leaves[persistent=true]
setblock ~30 ~170 ~126 jungle_leaves[persistent=true]
setblock ~30 ~170 ~127 jungle_leaves[persistent=true]
setblock ~30 ~170 ~128 jungle_leaves[persistent=true]
setblock ~30 ~170 ~129 oak_leaves[persistent=true]
setblock ~30 ~171 ~118 oak_leaves[persistent=true]
setblock ~30 ~171 ~119 oak_leaves[persistent=true]
setblock ~30 ~171 ~120 oak_leaves[persistent=true]
setblock ~30 ~171 ~121 jungle_leaves[persistent=true]
setblock ~30 ~171 ~122 oak_leaves[persistent=true]
setblock ~30 ~171 ~123 jungle_leaves[persistent=true]
setblock ~30 ~171 ~124 oak_leaves[persistent=true]
setblock ~30 ~171 ~125 jungle_leaves[persistent=true]
setblock ~30 ~171 ~126 oak_leaves[persistent=true]
setblock ~30 ~171 ~127 jungle_leaves[persistent=true]
setblock ~30 ~171 ~128 oak_leaves[persistent=true]
setblock ~30 ~171 ~129 oak_leaves[persistent=true]
setblock ~30 ~172 ~122 jungle_leaves[persistent=true]
setblock ~30 ~172 ~123 oak_leaves[persistent=true]
setblock ~30 ~172 ~124 oak_leaves[persistent=true]
setblock ~30 ~172 ~125 oak_leaves[persistent=true]
setblock ~30 ~172 ~126 jungle_leaves[persistent=true]
setblock ~30 ~172 ~127 oak_leaves[persistent=true]
setblock ~31 ~115 ~99 dirt
setblock ~31 ~116 ~98 dirt
setblock ~31 ~116 ~99 dirt
setblock ~31 ~117 ~98 dirt
setblock ~31 ~117 ~99 dirt
setblock ~31 ~118 ~96 dirt
setblock ~31 ~118 ~97 dirt
setblock ~31 ~118 ~98 dirt
setblock ~31 ~118 ~99 dirt
setblock ~31 ~118 ~100 dirt
setblock ~31 ~119 ~81 dirt
setblock ~31 ~119 ~93 dirt
setblock ~31 ~119 ~95 dirt
setblock ~31 ~119 ~96 dirt
setblock ~31 ~119 ~97 dirt
setblock ~31 ~119 ~98 dirt
setblock ~31 ~119 ~99 dirt
setblock ~31 ~119 ~100 dirt
setblock ~31 ~120 ~75 dirt
setblock ~31 ~120 ~76 dirt
setblock ~31 ~120 ~77 dirt
setblock ~31 ~120 ~78 dirt
setblock ~31 ~120 ~80 dirt
setblock ~31 ~120 ~81 dirt
setblock ~31 ~120 ~82 dirt
setblock ~31 ~120 ~93 dirt
setblock ~31 ~120 ~94 dirt
setblock ~31 ~120 ~95 dirt
setblock ~31 ~120 ~96 dirt
setblock ~31 ~120 ~97 dirt
setblock ~31 ~120 ~98 dirt
setblock ~31 ~120 ~99 dirt
setblock ~31 ~120 ~100 dirt
setblock ~31 ~120 ~101 dirt
setblock ~31 ~121 ~74 dirt
setblock ~31 ~121 ~75 dirt
setblock ~31 ~121 ~76 dirt
setblock ~31 ~121 ~77 dirt
setblock ~31 ~121 ~78 dirt
setblock ~31 ~121 ~80 dirt
setblock ~31 ~121 ~81 dirt
setblock ~31 ~121 ~82 dirt
setblock ~31 ~121 ~83 dirt
setblock ~31 ~121 ~92 dirt
setblock ~31 ~121 ~93 dirt
setblock ~31 ~121 ~94 dirt
setblock ~31 ~121 ~95 dirt
setblock ~31 ~121 ~96 dirt
setblock ~31 ~121 ~97 dirt
setblock ~31 ~121 ~98 dirt
setblock ~31 ~121 ~99 dirt
setblock ~31 ~121 ~100 dirt
setblock ~31 ~121 ~101 dirt
setblock ~31 ~122 ~74 dirt
setblock ~31 ~122 ~75 dirt
setblock ~31 ~122 ~76 dirt
setblock ~31 ~122 ~77 dirt
setblock ~31 ~122 ~78 dirt
setblock ~31 ~122 ~80 dirt
setblock ~31 ~122 ~81 dirt
setblock ~31 ~122 ~82 dirt
setblock ~31 ~122 ~83 dirt
setblock ~31 ~122 ~92 dirt
setblock ~31 ~122 ~93 dirt
setblock ~31 ~122 ~94 dirt
setblock ~31 ~122 ~95 dirt
setblock ~31 ~122 ~96 dirt
setblock ~31 ~122 ~97 dirt
setblock ~31 ~122 ~98 dirt
setblock ~31 ~122 ~99 dirt
setblock ~31 ~122 ~100 dirt
setblock ~31 ~122 ~101 dirt
setblock ~31 ~123 ~74 dirt
setblock ~31 ~123 ~75 dirt
setblock ~31 ~123 ~76 dirt
setblock ~31 ~123 ~77 dirt
setblock ~31 ~123 ~78 dirt
setblock ~31 ~123 ~80 grass_block
setblock ~31 ~123 ~81 grass_block
setblock ~31 ~123 ~82 dirt
setblock ~31 ~123 ~83 dirt
setblock ~31 ~123 ~92 dirt
setblock ~31 ~123 ~93 dirt
setblock ~31 ~123 ~94 dirt
setblock ~31 ~123 ~95 dirt
setblock ~31 ~123 ~96 dirt
setblock ~31 ~123 ~97 dirt
setblock ~31 ~123 ~98 dirt
setblock ~31 ~123 ~99 dirt
setblock ~31 ~123 ~100 dirt
setblock ~31 ~123 ~101 dirt
setblock ~31 ~124 ~74 dirt
setblock ~31 ~124 ~75 dirt
setblock ~31 ~124 ~76 grass_block
setblock ~31 ~124 ~77 grass_block
setblock ~31 ~124 ~78 grass_block
setblock ~31 ~124 ~82 grass_block
setblock ~31 ~124 ~83 grass_block
setblock ~31 ~124 ~92 dirt
setblock ~31 ~124 ~93 dirt
setblock ~31 ~124 ~94 dirt
setblock ~31 ~124 ~95 dirt
setblock ~31 ~124 ~96 grass_block
setblock ~31 ~124 ~97 grass_block
setblock ~31 ~124 ~98 grass_block
setblock ~31 ~124 ~99 grass_block
setblock ~31 ~124 ~100 grass_block
setblock ~31 ~124 ~101 grass_block
setblock ~31 ~125 ~74 grass_block
setblock ~31 ~125 ~75 grass_block
setblock ~31 ~125 ~82 short_grass
setblock ~31 ~125 ~92 grass_block
setblock ~31 ~125 ~93 grass_block
setblock ~31 ~125 ~94 grass_block
setblock ~31 ~125 ~95 grass_block
setblock ~31 ~125 ~99 short_grass
setblock ~31 ~126 ~74 short_grass
setblock ~31 ~126 ~75 short_grass
setblock ~31 ~126 ~93 short_grass
setblock ~31 ~126 ~94 poppy
setblock ~31 ~147 ~117 oak_leaves[persistent=true]
setblock ~31 ~147 ~118 oak_leaves[persistent=true]
setblock ~31 ~147 ~119 oak_leaves[persistent=true]
setblock ~31 ~147 ~120 oak_leaves[persistent=true]
setblock ~31 ~148 ~117 oak_leaves[persistent=true]
setblock ~31 ~148 ~118 jungle_leaves[persistent=true]
setblock ~31 ~148 ~124 oak_leaves[persistent=true]
setblock ~31 ~148 ~125 oak_leaves[persistent=true]
setblock ~31 ~149 ~117 oak_leaves[persistent=true]
setblock ~31 ~149 ~118 oak_leaves[persistent=true]
setblock ~31 ~149 ~119 jungle_leaves[persistent=true]
setblock ~31 ~149 ~120 oak_leaves[persistent=true]
setblock ~31 ~149 ~121 oak_leaves[persistent=true]
setblock ~31 ~149 ~124 jungle_leaves[persistent=true]
setblock ~31 ~149 ~125 jungle_leaves[persistent=true]
setblock ~31 ~150 ~117 oak_leaves[persistent=true]
setblock ~31 ~150 ~118 oak_leaves[persistent=true]
setblock ~31 ~150 ~119 oak_leaves[persistent=true]
setblock ~31 ~150 ~120 oak_leaves[persistent=true]
setblock ~31 ~150 ~121 oak_leaves[persistent=true]
setblock ~31 ~150 ~124 jungle_leaves[persistent=true]
setblock ~31 ~150 ~125 oak_leaves[persistent=true]
setblock ~31 ~150 ~126 oak_leaves[persistent=true]
setblock ~31 ~150 ~127 oak_leaves[persistent=true]
setblock ~31 ~150 ~129 jungle_leaves[persistent=true]
setblock ~31 ~151 ~118 oak_leaves[persistent=true]
setblock ~31 ~151 ~119 oak_leaves[persistent=true]
setblock ~31 ~151 ~120 oak_leaves[persistent=true]
setblock ~31 ~151 ~121 oak_leaves[persistent=true]
setblock ~31 ~151 ~124 oak_leaves[persistent=true]
setblock ~31 ~151 ~125 oak_leaves[persistent=true]
setblock ~31 ~151 ~126 jungle_leaves[persistent=true]
setblock ~31 ~151 ~127 jungle_leaves[persistent=true]
setblock ~31 ~151 ~128 oak_leaves[persistent=true]
setblock ~31 ~151 ~129 oak_leaves[persistent=true]
setblock ~31 ~152 ~118 oak_leaves[persistent=true]
setblock ~31 ~152 ~119 oak_leaves[persistent=true]
setblock ~31 ~152 ~120 oak_leaves[persistent=true]
setblock ~31 ~152 ~121 jungle_leaves[persistent=true]
setblock ~31 ~152 ~124 oak_leaves[persistent=true]
setblock ~31 ~152 ~125 oak_leaves[persistent=true]
setblock ~31 ~152 ~126 oak_leaves[persistent=true]
setblock ~31 ~152 ~127 oak_leaves[persistent=true]
setblock ~31 ~152 ~128 oak_leaves[persistent=true]
setblock ~31 ~152 ~129 oak_leaves[persistent=true]
setblock ~31 ~153 ~119 oak_leaves[persistent=true]
setblock ~31 ~153 ~120 jungle_leaves[persistent=true]
setblock ~31 ~153 ~122 oak_leaves[persistent=true]
setblock ~31 ~153 ~123 jungle_leaves[persistent=true]
setblock ~31 ~153 ~126 oak_leaves[persistent=true]
setblock ~31 ~153 ~127 oak_leaves[persistent=true]
setblock ~31 ~153 ~128 oak_leaves[persistent=true]
setblock ~31 ~153 ~129 oak_leaves[persistent=true]
setblock ~31 ~154 ~118 oak_leaves[persistent=true]
setblock ~31 ~154 ~119 oak_leaves[persistent=true]
setblock ~31 ~154 ~120 oak_leaves[persistent=true]
setblock ~31 ~154 ~121 jungle_leaves[persistent=true]
setblock ~31 ~154 ~122 oak_leaves[persistent=true]
setblock ~31 ~154 ~123 jungle_leaves[persistent=true]
setblock ~31 ~154 ~124 oak_leaves[persistent=true]
setblock ~31 ~154 ~125 oak_leaves[persistent=true]
setblock ~31 ~154 ~126 oak_leaves[persistent=true]
setblock ~31 ~154 ~127 oak_leaves[persistent=true]
setblock ~31 ~154 ~128 oak_leaves[persistent=true]
setblock ~31 ~154 ~129 oak_leaves[persistent=true]
setblock ~31 ~155 ~118 oak_leaves[persistent=true]
setblock ~31 ~155 ~119 oak_leaves[persistent=true]
setblock ~31 ~155 ~120 oak_leaves[persistent=true]
setblock ~31 ~155 ~121 jungle_leaves[persistent=true]
setblock ~31 ~155 ~122 oak_leaves[persistent=true]
setblock ~31 ~155 ~123 jungle_leaves[persistent=true]
setblock ~31 ~155 ~124 jungle_leaves[persistent=true]
setblock ~31 ~155 ~125 oak_leaves[persistent=true]
setblock ~31 ~155 ~126 oak_leaves[persistent=true]
setblock ~31 ~155 ~128 jungle_leaves[persistent=true]
setblock ~31 ~155 ~129 jungle_leaves[persistent=true]
setblock ~31 ~156 ~118 oak_leaves[persistent=true]
setblock ~31 ~156 ~119 oak_leaves[persistent=true]
setblock ~31 ~156 ~120 oak_leaves[persistent=true]
setblock ~31 ~156 ~121 oak_leaves[persistent=true]
setblock ~31 ~156 ~122 oak_leaves[persistent=true]
setblock ~31 ~156 ~123 oak_leaves[persistent=true]
setblock ~31 ~156 ~125 oak_leaves[persistent=true]
setblock ~31 ~156 ~126 jungle_leaves[persistent=true]
setblock ~31 ~156 ~127 oak_leaves[persistent=true]
setblock ~31 ~156 ~128 oak_leaves[persistent=true]
setblock ~31 ~156 ~129 oak_leaves[persistent=true]
setblock ~31 ~156 ~130 oak_leaves[persistent=true]
setblock ~31 ~157 ~117 jungle_leaves[persistent=true]
setblock ~31 ~157 ~118 oak_leaves[persistent=true]
setblock ~31 ~157 ~119 oak_leaves[persistent=true]
setblock ~31 ~157 ~120 oak_leaves[persistent=true]
setblock ~31 ~157 ~121 oak_leaves[persistent=true]
setblock ~31 ~157 ~122 jungle_leaves[persistent=true]
setblock ~31 ~157 ~124 oak_leaves[persistent=true]
setblock ~31 ~157 ~125 oak_leaves[persistent=true]
setblock ~31 ~157 ~126 oak_leaves[persistent=true]
setblock ~31 ~157 ~127 oak_leaves[persistent=true]
setblock ~31 ~157 ~128 jungle_leaves[persistent=true]
setblock ~31 ~157 ~129 oak_leaves[persistent=true]
setblock ~31 ~157 ~130 oak_leaves[persistent=true]
setblock ~31 ~157 ~131 oak_leaves[persistent=true]
setblock ~31 ~158 ~117 oak_leaves[persistent=true]
setblock ~31 ~158 ~118 oak_leaves[persistent=true]
setblock ~31 ~158 ~121 jungle_leaves[persistent=true]
setblock ~31 ~158 ~122 oak_leaves[persistent=true]
setblock ~31 ~158 ~123 jungle_leaves[persistent=true]
setblock ~31 ~158 ~124 jungle_leaves[persistent=true]
setblock ~31 ~158 ~125 oak_leaves[persistent=true]
setblock ~31 ~158 ~126 oak_leaves[persistent=true]
setblock ~31 ~158 ~127 oak_leaves[persistent=true]
setblock ~31 ~158 ~129 oak_leaves[persistent=true]
setblock ~31 ~158 ~130 oak_leaves[persistent=true]
setblock ~31 ~158 ~131 oak_leaves[persistent=true]
setblock ~31 ~158 ~132 oak_leaves[persistent=true]
setblock ~31 ~158 ~133 oak_leaves[persistent=true]
setblock ~31 ~158 ~134 jungle_leaves[persistent=true]
setblock ~31 ~159 ~77 oak_leaves[persistent=true]
setblock ~31 ~159 ~78 oak_leaves[persistent=true]
setblock ~31 ~159 ~79 oak_leaves[persistent=true]
setblock ~31 ~159 ~80 jungle_leaves[persistent=true]
setblock ~31 ~159 ~114 oak_leaves[persistent=true]
setblock ~31 ~159 ~115 oak_leaves[persistent=true]
setblock ~31 ~159 ~116 oak_leaves[persistent=true]
setblock ~31 ~159 ~117 oak_leaves[persistent=true]
setblock ~31 ~159 ~118 oak_leaves[persistent=true]
setblock ~31 ~159 ~119 oak_leaves[persistent=true]
setblock ~31 ~159 ~120 oak_leaves[persistent=true]
setblock ~31 ~159 ~121 oak_leaves[persistent=true]
setblock ~31 ~159 ~122 oak_leaves[persistent=true]
setblock ~31 ~159 ~123 oak_leaves[persistent=true]
setblock ~31 ~159 ~124 oak_leaves[persistent=true]
setblock ~31 ~159 ~126 oak_leaves[persistent=true]
setblock ~31 ~159 ~127 oak_wood
setblock ~31 ~159 ~128 oak_leaves[persistent=true]
setblock ~31 ~159 ~129 jungle_leaves[persistent=true]
setblock ~31 ~159 ~131 oak_wood
setblock ~31 ~159 ~132 oak_leaves[persistent=true]
setblock ~31 ~159 ~133 oak_leaves[persistent=true]
setblock ~31 ~159 ~134 oak_leaves[persistent=true]
setblock ~31 ~160 ~77 jungle_leaves[persistent=true]
setblock ~31 ~160 ~78 jungle_leaves[persistent=true]
setblock ~31 ~160 ~79 oak_leaves[persistent=true]
setblock ~31 ~160 ~80 oak_leaves[persistent=true]
setblock ~31 ~160 ~114 oak_leaves[persistent=true]
setblock ~31 ~160 ~117 oak_leaves[persistent=true]
setblock ~31 ~160 ~118 jungle_leaves[persistent=true]
setblock ~31 ~160 ~119 oak_leaves[persistent=true]
setblock ~31 ~160 ~120 oak_leaves[persistent=true]
setblock ~31 ~160 ~121 oak_leaves[persistent=true]
setblock ~31 ~160 ~122 oak_leaves[persistent=true]
setblock ~31 ~160 ~123 oak_leaves[persistent=true]
setblock ~31 ~160 ~124 oak_leaves[persistent=true]
setblock ~31 ~160 ~125 oak_leaves[persistent=true]
setblock ~31 ~160 ~126 oak_leaves[persistent=true]
setblock ~31 ~160 ~127 oak_leaves[persistent=true]
setblock ~31 ~160 ~128 oak_leaves[persistent=true]
setblock ~31 ~160 ~129 oak_leaves[persistent=true]
setblock ~31 ~160 ~130 oak_leaves[persistent=true]
setblock ~31 ~160 ~131 oak_leaves[persistent=true]
setblock ~31 ~160 ~133 jungle_leaves[persistent=true]
setblock ~31 ~160 ~134 jungle_leaves[persistent=true]
setblock ~31 ~161 ~77 jungle_leaves[persistent=true]
setblock ~31 ~161 ~78 oak_leaves[persistent=true]
setblock ~31 ~161 ~79 oak_leaves[persistent=true]
setblock ~31 ~161 ~80 jungle_leaves[persistent=true]
setblock ~31 ~161 ~114 oak_leaves[persistent=true]
setblock ~31 ~161 ~115 oak_leaves[persistent=true]
setblock ~31 ~161 ~116 jungle_leaves[persistent=true]
setblock ~31 ~161 ~117 oak_leaves[persistent=true]
setblock ~31 ~161 ~118 oak_leaves[persistent=true]
setblock ~31 ~161 ~119 oak_leaves[persistent=true]
setblock ~31 ~161 ~120 oak_leaves[persistent=true]
setblock ~31 ~161 ~121 oak_leaves[persistent=true]
setblock ~31 ~161 ~122 oak_leaves[persistent=true]
setblock ~31 ~161 ~123 oak_leaves[persistent=true]
setblock ~31 ~161 ~124 jungle_leaves[persistent=true]
setblock ~31 ~161 ~125 oak_leaves[persistent=true]
setblock ~31 ~161 ~126 oak_leaves[persistent=true]
setblock ~31 ~161 ~127 oak_leaves[persistent=true]
setblock ~31 ~161 ~129 oak_leaves[persistent=true]
setblock ~31 ~161 ~130 oak_leaves[persistent=true]
setblock ~31 ~161 ~131 jungle_leaves[persistent=true]
setblock ~31 ~161 ~132 oak_leaves[persistent=true]
setblock ~31 ~161 ~134 oak_leaves[persistent=true]
setblock ~31 ~161 ~135 oak_leaves[persistent=true]
setblock ~31 ~162 ~77 oak_leaves[persistent=true]
setblock ~31 ~162 ~78 oak_leaves[persistent=true]
setblock ~31 ~162 ~79 oak_leaves[persistent=true]
setblock ~31 ~162 ~80 oak_leaves[persistent=true]
setblock ~31 ~162 ~112 oak_leaves[persistent=true]
setblock ~31 ~162 ~114 oak_leaves[persistent=true]
setblock ~31 ~162 ~115 oak_leaves[persistent=true]
setblock ~31 ~162 ~116 oak_leaves[persistent=true]
setblock ~31 ~162 ~117 oak_leaves[persistent=true]
setblock ~31 ~162 ~118 oak_leaves[persistent=true]
setblock ~31 ~162 ~119 jungle_leaves[persistent=true]
setblock ~31 ~162 ~120 oak_leaves[persistent=true]
setblock ~31 ~162 ~121 oak_leaves[persistent=true]
setblock ~31 ~162 ~123 oak_leaves[persistent=true]
setblock ~31 ~162 ~124 oak_wood
setblock ~31 ~162 ~125 oak_wood
setblock ~31 ~162 ~126 oak_leaves[persistent=true]
setblock ~31 ~162 ~127 jungle_leaves[persistent=true]
setblock ~31 ~162 ~129 oak_leaves[persistent=true]
setblock ~31 ~162 ~130 oak_leaves[persistent=true]
setblock ~31 ~162 ~131 oak_leaves[persistent=true]
setblock ~31 ~162 ~132 oak_leaves[persistent=true]
setblock ~31 ~162 ~133 jungle_leaves[persistent=true]
setblock ~31 ~162 ~134 oak_leaves[persistent=true]
setblock ~31 ~162 ~135 oak_leaves[persistent=true]
setblock ~31 ~163 ~112 oak_leaves[persistent=true]
setblock ~31 ~163 ~113 jungle_leaves[persistent=true]
setblock ~31 ~163 ~114 oak_leaves[persistent=true]
setblock ~31 ~163 ~116 oak_leaves[persistent=true]
setblock ~31 ~163 ~117 oak_leaves[persistent=true]
setblock ~31 ~163 ~119 oak_leaves[persistent=true]
setblock ~31 ~163 ~120 oak_wood
setblock ~31 ~163 ~121 oak_leaves[persistent=true]
setblock ~31 ~163 ~122 oak_leaves[persistent=true]
setblock ~31 ~163 ~123 oak_leaves[persistent=true]
setblock ~31 ~163 ~124 oak_leaves[persistent=true]
setblock ~31 ~163 ~126 oak_leaves[persistent=true]
setblock ~31 ~163 ~128 oak_leaves[persistent=true]
setblock ~31 ~163 ~129 oak_leaves[persistent=true]
setblock ~31 ~163 ~130 jungle_leaves[persistent=true]
setblock ~31 ~163 ~131 oak_leaves[persistent=true]
setblock ~31 ~163 ~133 oak_wood
setblock ~31 ~163 ~134 oak_leaves[persistent=true]
setblock ~31 ~163 ~135 oak_leaves[persistent=true]
setblock ~31 ~164 ~112 jungle_leaves[persistent=true]
setblock ~31 ~164 ~113 oak_leaves[persistent=true]
setblock ~31 ~164 ~114 oak_leaves[persistent=true]
setblock ~31 ~164 ~115 jungle_leaves[persistent=true]
setblock ~31 ~164 ~116 oak_leaves[persistent=true]
setblock ~31 ~164 ~117 oak_leaves[persistent=true]
setblock ~31 ~164 ~118 oak_leaves[persistent=true]
setblock ~31 ~164 ~119 jungle_leaves[persistent=true]
setblock ~31 ~164 ~120 jungle_leaves[persistent=true]
setblock ~31 ~164 ~121 oak_leaves[persistent=true]
setblock ~31 ~164 ~122 oak_leaves[persistent=true]
setblock ~31 ~164 ~123 oak_leaves[persistent=true]
setblock ~31 ~164 ~124 oak_leaves[persistent=true]
setblock ~31 ~164 ~125 oak_wood
setblock ~31 ~164 ~126 oak_wood
setblock ~31 ~164 ~127 oak_leaves[persistent=true]
setblock ~31 ~164 ~128 oak_leaves[persistent=true]
setblock ~31 ~164 ~129 oak_wood
setblock ~31 ~164 ~130 oak_leaves[persistent=true]
setblock ~31 ~164 ~131 oak_leaves[persistent=true]
setblock ~31 ~164 ~132 oak_leaves[persistent=true]
setblock ~31 ~164 ~134 oak_leaves[persistent=true]
setblock ~31 ~164 ~135 oak_leaves[persistent=true]
setblock ~31 ~165 ~112 oak_leaves[persistent=true]
setblock ~31 ~165 ~113 oak_leaves[persistent=true]
setblock ~31 ~165 ~114 oak_leaves[persistent=true]
setblock ~31 ~165 ~115 oak_wood
setblock ~31 ~165 ~116 oak_leaves[persistent=true]
setblock ~31 ~165 ~117 jungle_leaves[persistent=true]
setblock ~31 ~165 ~118 jungle_leaves[persistent=true]
setblock ~31 ~165 ~119 oak_leaves[persistent=true]
setblock ~31 ~165 ~120 oak_leaves[persistent=true]
setblock ~31 ~165 ~122 oak_wood
setblock ~31 ~165 ~123 oak_wood
setblock ~31 ~165 ~124 oak_wood
setblock ~31 ~165 ~125 oak_wood
setblock ~31 ~165 ~126 oak_leaves[persistent=true]
setblock ~31 ~165 ~127 oak_leaves[persistent=true]
setblock ~31 ~165 ~128 oak_leaves[persistent=true]
setblock ~31 ~165 ~129 oak_wood
setblock ~31 ~165 ~130 oak_leaves[persistent=true]
setblock ~31 ~165 ~131 oak_leaves[persistent=true]
setblock ~31 ~165 ~132 oak_leaves[persistent=true]
setblock ~31 ~165 ~133 oak_leaves[persistent=true]
setblock ~31 ~165 ~134 oak_leaves[persistent=true]
setblock ~31 ~166 ~113 oak_leaves[persistent=true]
setblock ~31 ~166 ~114 jungle_leaves[persistent=true]
setblock ~31 ~166 ~115 oak_leaves[persistent=true]
setblock ~31 ~166 ~116 oak_leaves[persistent=true]
setblock ~31 ~166 ~117 oak_leaves[persistent=true]
setblock ~31 ~166 ~118 oak_leaves[persistent=true]
setblock ~31 ~166 ~119 oak_leaves[persistent=true]
setblock ~31 ~166 ~120 oak_leaves[persistent=true]
setblock ~31 ~166 ~121 oak_wood
setblock ~31 ~166 ~122 oak_wood
setblock ~31 ~166 ~123 oak_wood
setblock ~31 ~166 ~124 oak_leaves[persistent=true]
setblock ~31 ~166 ~125 oak_wood
setblock ~31 ~166 ~126 oak_wood
setblock ~31 ~166 ~127 oak_leaves[persistent=true]
setblock ~31 ~166 ~128 oak_leaves[persistent=true]
setblock ~31 ~166 ~129 oak_wood
setblock ~31 ~166 ~130 oak_wood
setblock ~31 ~166 ~131 oak_leaves[persistent=true]
setblock ~31 ~166 ~132 oak_leaves[persistent=true]
setblock ~31 ~166 ~133 oak_leaves[persistent=true]
setblock ~31 ~166 ~134 oak_leaves[persistent=true]
setblock ~31 ~166 ~135 oak_leaves[persistent=true]
setblock ~31 ~167 ~113 oak_leaves[persistent=true]
setblock ~31 ~167 ~114 oak_leaves[persistent=true]
setblock ~31 ~167 ~115 oak_leaves[persistent=true]
setblock ~31 ~167 ~116 oak_leaves[persistent=true]
setblock ~31 ~167 ~117 oak_leaves[persistent=true]
setblock ~31 ~167 ~118 oak_leaves[persistent=true]
setblock ~31 ~167 ~119 oak_leaves[persistent=true]
setblock ~31 ~167 ~120 oak_leaves[persistent=true]
setblock ~31 ~167 ~121 oak_wood
setblock ~31 ~167 ~122 oak_wood
setblock ~31 ~167 ~123 oak_wood
setblock ~31 ~167 ~124 oak_leaves[persistent=true]
setblock ~31 ~167 ~125 oak_leaves[persistent=true]
setblock ~31 ~167 ~126 oak_leaves[persistent=true]
setblock ~31 ~167 ~127 oak_wood
setblock ~31 ~167 ~128 oak_wood
setblock ~31 ~167 ~129 oak_leaves[persistent=true]
setblock ~31 ~167 ~130 oak_leaves[persistent=true]
setblock ~31 ~167 ~131 oak_wood
setblock ~31 ~167 ~132 oak_leaves[persistent=true]
setblock ~31 ~167 ~133 oak_leaves[persistent=true]
setblock ~31 ~167 ~134 oak_leaves[persistent=true]
setblock ~31 ~167 ~135 oak_leaves[persistent=true]
setblock ~31 ~168 ~113 oak_leaves[persistent=true]
setblock ~31 ~168 ~114 oak_leaves[persistent=true]
setblock ~31 ~168 ~115 oak_leaves[persistent=true]
setblock ~31 ~168 ~116 oak_leaves[persistent=true]
setblock ~31 ~168 ~117 oak_leaves[persistent=true]
setblock ~31 ~168 ~118 oak_leaves[persistent=true]
setblock ~31 ~168 ~119 oak_wood
setblock ~31 ~168 ~120 oak_wood
setblock ~31 ~168 ~121 oak_wood
setblock ~31 ~168 ~122 oak_leaves[persistent=true]
setblock ~31 ~168 ~123 oak_wood
setblock ~31 ~168 ~124 oak_leaves[persistent=true]
setblock ~31 ~168 ~125 oak_leaves[persistent=true]
setblock ~31 ~168 ~126 jungle_leaves[persistent=true]
setblock ~31 ~168 ~127 jungle_leaves[persistent=true]
setblock ~31 ~168 ~128 oak_leaves[persistent=true]
setblock ~31 ~168 ~129 oak_leaves[persistent=true]
setblock ~31 ~168 ~130 oak_leaves[persistent=true]
setblock ~31 ~168 ~131 oak_leaves[persistent=true]
setblock ~31 ~168 ~132 oak_leaves[persistent=true]
setblock ~31 ~168 ~133 oak_leaves[persistent=true]
setblock ~31 ~168 ~134 oak_leaves[persistent=true]
setblock ~31 ~168 ~135 oak_leaves[persistent=true]
setblock ~31 ~169 ~113 oak_leaves[persistent=true]
setblock ~31 ~169 ~114 oak_leaves[persistent=true]
setblock ~31 ~169 ~115 jungle_leaves[persistent=true]
setblock ~31 ~169 ~116 oak_leaves[persistent=true]
setblock ~31 ~169 ~117 oak_leaves[persistent=true]
setblock ~31 ~169 ~118 oak_leaves[persistent=true]
setblock ~31 ~169 ~119 oak_wood
setblock ~31 ~169 ~120 oak_leaves[persistent=true]
setblock ~31 ~169 ~121 oak_leaves[persistent=true]
setblock ~31 ~169 ~123 oak_log
setblock ~31 ~169 ~124 oak_wood
setblock ~31 ~169 ~125 oak_wood
setblock ~31 ~169 ~126 oak_wood
setblock ~31 ~169 ~127 jungle_leaves[persistent=true]
setblock ~31 ~169 ~128 oak_wood
setblock ~31 ~169 ~129 oak_leaves[persistent=true]
setblock ~31 ~169 ~130 jungle_leaves[persistent=true]
setblock ~31 ~169 ~131 oak_leaves[persistent=true]
setblock ~31 ~169 ~132 oak_leaves[persistent=true]
setblock ~31 ~169 ~133 oak_leaves[persistent=true]
setblock ~31 ~169 ~134 oak_leaves[persistent=true]
setblock ~31 ~169 ~135 oak_leaves[persistent=true]
setblock ~31 ~170 ~116 oak_leaves[persistent=true]
setblock ~31 ~170 ~117 oak_leaves[persistent=true]
setblock ~31 ~170 ~118 oak_leaves[persistent=true]
setblock ~31 ~170 ~119 oak_leaves[persistent=true]
setblock ~31 ~170 ~120 jungle_leaves[persistent=true]
setblock ~31 ~170 ~121 oak_wood
setblock ~31 ~170 ~122 oak_leaves[persistent=true]
setblock ~31 ~170 ~123 oak_log
setblock ~31 ~170 ~124 oak_log
setblock ~31 ~170 ~125 jungle_leaves[persistent=true]
setblock ~31 ~170 ~126 oak_leaves[persistent=true]
setblock ~31 ~170 ~127 oak_wood
setblock ~31 ~170 ~128 oak_leaves[persistent=true]
setblock ~31 ~170 ~129 oak_leaves[persistent=true]
setblock ~31 ~170 ~130 jungle_leaves[persistent=true]
setblock ~31 ~170 ~131 oak_leaves[persistent=true]
setblock ~31 ~170 ~133 oak_leaves[persistent=true]
setblock ~31 ~171 ~116 jungle_leaves[persistent=true]
setblock ~31 ~171 ~117 oak_leaves[persistent=true]
setblock ~31 ~171 ~118 oak_leaves[persistent=true]
setblock ~31 ~171 ~119 oak_leaves[persistent=true]
setblock ~31 ~171 ~121 oak_leaves[persistent=true]
setblock ~31 ~171 ~122 oak_leaves[persistent=true]
setblock ~31 ~171 ~123 oak_leaves[persistent=true]
setblock ~31 ~171 ~124 oak_leaves[persistent=true]
setblock ~31 ~171 ~125 oak_leaves[persistent=true]
setblock ~31 ~171 ~126 oak_leaves[persistent=true]
setblock ~31 ~171 ~127 oak_leaves[persistent=true]
setblock ~31 ~171 ~128 jungle_leaves[persistent=true]
setblock ~31 ~171 ~129 oak_leaves[persistent=true]
setblock ~31 ~171 ~130 oak_leaves[persistent=true]
setblock ~31 ~171 ~131 oak_leaves[persistent=true]
setblock ~31 ~171 ~132 oak_leaves[persistent=true]
setblock ~31 ~171 ~133 jungle_leaves[persistent=true]
setblock ~31 ~171 ~134 jungle_leaves[persistent=true]
setblock ~31 ~172 ~118 oak_leaves[persistent=true]
setblock ~31 ~172 ~119 oak_leaves[persistent=true]
setblock ~31 ~172 ~120 oak_leaves[persistent=true]
setblock ~31 ~172 ~121 oak_leaves[persistent=true]
setblock ~31 ~172 ~122 oak_leaves[persistent=true]
setblock ~31 ~172 ~123 oak_leaves[persistent=true]
setblock ~31 ~172 ~124 jungle_leaves[persistent=true]
setblock ~31 ~172 ~125 oak_leaves[persistent=true]
setblock ~31 ~172 ~126 oak_leaves[persistent=true]
setblock ~31 ~172 ~127 jungle_leaves[persistent=true]
setblock ~31 ~172 ~130 jungle_leaves[persistent=true]
setblock ~31 ~172 ~131 oak_leaves[persistent=true]
setblock ~31 ~172 ~132 oak_leaves[persistent=true]
setblock ~31 ~172 ~133 oak_leaves[persistent=true]
setblock ~31 ~172 ~134 oak_leaves[persistent=true]
setblock ~32 ~114 ~99 dirt
setblock ~32 ~115 ~98 dirt
setblock ~32 ~115 ~99 dirt
setblock ~32 ~115 ~100 dirt
setblock ~32 ~116 ~78 dirt
setblock ~32 ~116 ~96 dirt
setblock ~32 ~116 ~97 dirt
setblock ~32 ~116 ~98 dirt
setblock ~32 ~116 ~99 dirt
setblock ~32 ~116 ~100 dirt
setblock ~32 ~117 ~78 dirt
setblock ~32 ~117 ~96 dirt
setblock ~32 ~117 ~97 dirt
setblock ~32 ~117 ~98 dirt
setblock ~32 ~117 ~99 dirt
setblock ~32 ~117 ~100 dirt
setblock ~32 ~118 ~76 dirt
setblock ~32 ~118 ~77 dirt
setblock ~32 ~118 ~78 dirt
setblock ~32 ~118 ~79 dirt
setblock ~32 ~118 ~81 dirt
setblock ~32 ~118 ~92 dirt
setblock ~32 ~118 ~93 dirt
setblock ~32 ~118 ~95 dirt
setblock ~32 ~118 ~96 dirt
setblock ~32 ~118 ~97 dirt
setblock ~32 ~118 ~98 dirt
setblock ~32 ~118 ~99 dirt
setblock ~32 ~118 ~100 dirt
setblock ~32 ~118 ~101 dirt
setblock ~32 ~119 ~75 dirt
setblock ~32 ~119 ~76 dirt
setblock ~32 ~119 ~77 dirt
setblock ~32 ~119 ~78 dirt
setblock ~32 ~119 ~79 dirt
setblock ~32 ~119 ~80 dirt
setblock ~32 ~119 ~81 dirt
setblock ~32 ~119 ~82 dirt
setblock ~32 ~119 ~92 dirt
setblock ~32 ~119 ~93 dirt
setblock ~32 ~119 ~94 dirt
setblock ~32 ~119 ~95 dirt
setblock ~32 ~119 ~96 dirt
setblock ~32 ~119 ~97 dirt
setblock ~32 ~119 ~98 dirt
setblock ~32 ~119 ~99 dirt
setblock ~32 ~119 ~100 dirt
setblock ~32 ~119 ~101 dirt
setblock ~32 ~120 ~74 dirt
setblock ~32 ~120 ~75 dirt
setblock ~32 ~120 ~76 dirt
setblock ~32 ~120 ~77 dirt
setblock ~32 ~120 ~78 dirt
setblock ~32 ~120 ~79 dirt
setblock ~32 ~120 ~80 dirt
setblock ~32 ~120 ~81 dirt
setblock ~32 ~120 ~82 dirt
setblock ~32 ~120 ~83 dirt
setblock ~32 ~120 ~92 dirt
setblock ~32 ~120 ~93 dirt
setblock ~32 ~120 ~94 dirt
setblock ~32 ~120 ~95 dirt
setblock ~32 ~120 ~96 dirt
setblock ~32 ~120 ~97 dirt
setblock ~32 ~120 ~98 dirt
setblock ~32 ~120 ~99 dirt
setblock ~32 ~120 ~100 dirt
setblock ~32 ~120 ~101 dirt
setblock ~32 ~120 ~102 dirt
setblock ~32 ~120 ~103 dirt
setblock ~32 ~121 ~74 dirt
setblock ~32 ~121 ~75 dirt
setblock ~32 ~121 ~76 dirt
setblock ~32 ~121 ~77 dirt
setblock ~32 ~121 ~78 dirt
setblock ~32 ~121 ~79 dirt
setblock ~32 ~121 ~80 dirt
setblock ~32 ~121 ~81 dirt
setblock ~32 ~121 ~82 dirt
setblock ~32 ~121 ~83 dirt
setblock ~32 ~121 ~84 dirt
setblock ~32 ~121 ~88 dirt
setblock ~32 ~121 ~90 dirt
setblock ~32 ~121 ~91 dirt
setblock ~32 ~121 ~92 dirt
setblock ~32 ~121 ~93 dirt
setblock ~32 ~121 ~94 dirt
setblock ~32 ~121 ~95 dirt
setblock ~32 ~121 ~96 dirt
setblock ~32 ~121 ~97 dirt
setblock ~32 ~121 ~98 dirt
setblock ~32 ~121 ~99 dirt
setblock ~32 ~121 ~100 dirt
setblock ~32 ~121 ~101 dirt
setblock ~32 ~121 ~102 dirt
setblock ~32 ~121 ~103 dirt
setblock ~32 ~121 ~104 dirt
setblock ~32 ~122 ~74 dirt
setblock ~32 ~122 ~75 dirt
setblock ~32 ~122 ~76 dirt
setblock ~32 ~122 ~77 dirt
setblock ~32 ~122 ~78 dirt
setblock ~32 ~122 ~79 dirt
setblock ~32 ~122 ~80 dirt
setblock ~32 ~122 ~81 dirt
setblock ~32 ~122 ~82 dirt
setblock ~32 ~122 ~83 dirt
setblock ~32 ~122 ~84 dirt
setblock ~32 ~122 ~88 dirt
setblock ~32 ~122 ~90 dirt
setblock ~32 ~122 ~91 dirt
setblock ~32 ~122 ~92 dirt
setblock ~32 ~122 ~93 dirt
setblock ~32 ~122 ~94 dirt
setblock ~32 ~122 ~95 dirt
setblock ~32 ~122 ~96 dirt
setblock ~32 ~122 ~97 dirt
setblock ~32 ~122 ~98 dirt
setblock ~32 ~122 ~99 dirt
setblock ~32 ~122 ~100 dirt
setblock ~32 ~122 ~101 dirt
setblock ~32 ~122 ~102 dirt
setblock ~32 ~122 ~103 dirt
setblock ~32 ~122 ~104 dirt
setblock ~32 ~123 ~74 dirt
setblock ~32 ~123 ~75 dirt
setblock ~32 ~123 ~76 dirt
setblock ~32 ~123 ~77 dirt
setblock ~32 ~123 ~78 dirt
setblock ~32 ~123 ~79 grass_block
setblock ~32 ~123 ~80 grass_block
setblock ~32 ~123 ~81 grass_block
setblock ~32 ~123 ~82 dirt
setblock ~32 ~123 ~83 dirt
setblock ~32 ~123 ~84 dirt
setblock ~32 ~123 ~88 dirt
setblock ~32 ~123 ~90 dirt
setblock ~32 ~123 ~91 dirt
setblock ~32 ~123 ~92 dirt
setblock ~32 ~123 ~93 dirt
setblock ~32 ~123 ~94 dirt
setblock ~32 ~123 ~95 dirt
setblock ~32 ~123 ~96 dirt
setblock ~32 ~123 ~97 dirt
setblock ~32 ~123 ~98 dirt
setblock ~32 ~123 ~99 dirt
setblock ~32 ~123 ~100 dirt
setblock ~32 ~123 ~101 dirt
setblock ~32 ~123 ~102 dirt
setblock ~32 ~123 ~103 dirt
setblock ~32 ~123 ~104 dirt
setblock ~32 ~124 ~74 dirt
setblock ~32 ~124 ~75 dirt
setblock ~32 ~124 ~76 grass_block
setblock ~32 ~124 ~77 grass_block
setblock ~32 ~124 ~78 grass_block
setblock ~32 ~124 ~79 short_grass
setblock ~32 ~124 ~82 grass_block
setblock ~32 ~124 ~83 grass_block
setblock ~32 ~124 ~84 grass_block
setblock ~32 ~124 ~88 dirt
setblock ~32 ~124 ~90 dirt
setblock ~32 ~124 ~91 dirt
setblock ~32 ~124 ~92 dirt
setblock ~32 ~124 ~93 dirt
setblock ~32 ~124 ~94 dirt
setblock ~32 ~124 ~95 grass_block
setblock ~32 ~124 ~96 grass_block
setblock ~32 ~124 ~97 grass_block
setblock ~32 ~124 ~98 grass_block
setblock ~32 ~124 ~99 grass_block
setblock ~32 ~124 ~100 grass_block
setblock ~32 ~124 ~101 grass_block
setblock ~32 ~124 ~102 grass_block
setblock ~32 ~124 ~103 dirt
setblock ~32 ~124 ~104 dirt
setblock ~32 ~125 ~74 grass_block
setblock ~32 ~125 ~75 grass_block
setblock ~32 ~125 ~78 short_grass
setblock ~32 ~125 ~82 short_grass
setblock ~32 ~125 ~84 short_grass
setblock ~32 ~125 ~88 grass_block
setblock ~32 ~125 ~90 grass_block
setblock ~32 ~125 ~91 grass_block
setblock ~32 ~125 ~92 grass_block
setblock ~32 ~125 ~93 grass_block
setblock ~32 ~125 ~94 grass_block
setblock ~32 ~125 ~98 short_grass
setblock ~32 ~125 ~103 grass_block
setblock ~32 ~125 ~104 grass_block
setblock ~32 ~126 ~88 short_grass
setblock ~32 ~126 ~92 short_grass
setblock ~32 ~126 ~104 short_grass
setblock ~32 ~147 ~117 oak_leaves[persistent=true]
setblock ~32 ~147 ~118 oak_leaves[persistent=true]
setblock ~32 ~147 ~119 oak_leaves[persistent=true]
setblock ~32 ~147 ~120 oak_leaves[persistent=true]
setblock ~32 ~147 ~121 oak_leaves[persistent=true]
setblock ~32 ~147 ~122 oak_leaves[persistent=true]
setblock ~32 ~147 ~123 jungle_leaves[persistent=true]
setblock ~32 ~147 ~124 oak_leaves[persistent=true]
setblock ~32 ~147 ~125 oak_leaves[persistent=true]
setblock ~32 ~148 ~117 jungle_leaves[persistent=true]
setblock ~32 ~148 ~118 oak_leaves[persistent=true]
setblock ~32 ~148 ~119 oak_leaves[persistent=true]
setblock ~32 ~148 ~120 oak_leaves[persistent=true]
setblock ~32 ~148 ~121 oak_leaves[persistent=true]
setblock ~32 ~148 ~122 oak_leaves[persistent=true]
setblock ~32 ~148 ~123 oak_leaves[persistent=true]
setblock ~32 ~148 ~124 oak_leaves[persistent=true]
setblock ~32 ~148 ~125 oak_leaves[persistent=true]
setblock ~32 ~148 ~126 oak_leaves[persistent=true]
setblock ~32 ~149 ~116 oak_leaves[persistent=true]
setblock ~32 ~149 ~117 oak_leaves[persistent=true]
setblock ~32 ~149 ~118 oak_leaves[persistent=true]
setblock ~32 ~149 ~119 oak_leaves[persistent=true]
setblock ~32 ~149 ~120 oak_leaves[persistent=true]
setblock ~32 ~149 ~121 jungle_leaves[persistent=true]
setblock ~32 ~149 ~122 oak_leaves[persistent=true]
setblock ~32 ~149 ~123 jungle_leaves[persistent=true]
setblock ~32 ~149 ~124 jungle_leaves[persistent=true]
setblock ~32 ~149 ~125 jungle_leaves[persistent=true]
setblock ~32 ~149 ~126 oak_leaves[persistent=true]
setblock ~32 ~149 ~127 oak_leaves[persistent=true]
setblock ~32 ~150 ~116 oak_leaves[persistent=true]
setblock ~32 ~150 ~117 oak_leaves[persistent=true]
setblock ~32 ~150 ~118 jungle_leaves[persistent=true]
setblock ~32 ~150 ~122 oak_leaves[persistent=true]
setblock ~32 ~150 ~123 oak_leaves[persistent=true]
setblock ~32 ~150 ~125 oak_leaves[persistent=true]
setblock ~32 ~150 ~127 oak_leaves[persistent=true]
setblock ~32 ~150 ~128 oak_leaves[persistent=true]
setblock ~32 ~150 ~129 oak_leaves[persistent=true]
setblock ~32 ~151 ~116 oak_leaves[persistent=true]
setblock ~32 ~151 ~117 oak_leaves[persistent=true]
setblock ~32 ~151 ~118 jungle_leaves[persistent=true]
setblock ~32 ~151 ~119 oak_leaves[persistent=true]
setblock ~32 ~151 ~120 oak_leaves[persistent=true]
setblock ~32 ~151 ~121 oak_leaves[persistent=true]
setblock ~32 ~151 ~122 oak_leaves[persistent=true]
setblock ~32 ~151 ~124 oak_leaves[persistent=true]
setblock ~32 ~151 ~125 oak_leaves[persistent=true]
setblock ~32 ~151 ~126 oak_leaves[persistent=true]
setblock ~32 ~151 ~127 oak_leaves[persistent=true]
setblock ~32 ~151 ~128 oak_leaves[persistent=true]
setblock ~32 ~151 ~130 oak_leaves[persistent=true]
setblock ~32 ~151 ~131 oak_leaves[persistent=true]
setblock ~32 ~151 ~132 oak_leaves[persistent=true]
setblock ~32 ~152 ~116 oak_leaves[persistent=true]
setblock ~32 ~152 ~117 oak_leaves[persistent=true]
setblock ~32 ~152 ~118 oak_leaves[persistent=true]
setblock ~32 ~152 ~120 oak_leaves[persistent=true]
setblock ~32 ~152 ~121 oak_leaves[persistent=true]
setblock ~32 ~152 ~122 oak_leaves[persistent=true]
setblock ~32 ~152 ~123 jungle_leaves[persistent=true]
setblock ~32 ~152 ~124 oak_leaves[persistent=true]
setblock ~32 ~152 ~125 oak_leaves[persistent=true]
setblock ~32 ~152 ~126 jungle_leaves[persistent=true]
setblock ~32 ~152 ~127 jungle_leaves[persistent=true]
setblock ~32 ~152 ~128 oak_leaves[persistent=true]
setblock ~32 ~152 ~129 oak_leaves[persistent=true]
setblock ~32 ~152 ~130 oak_leaves[persistent=true]
setblock ~32 ~152 ~131 oak_leaves[persistent=true]
setblock ~32 ~152 ~132 oak_leaves[persistent=true]
setblock ~32 ~153 ~118 oak_leaves[persistent=true]
setblock ~32 ~153 ~119 oak_leaves[persistent=true]
setblock ~32 ~153 ~120 jungle_leaves[persistent=true]
setblock ~32 ~153 ~121 oak_leaves[persistent=true]
setblock ~32 ~153 ~122 jungle_leaves[persistent=true]
setblock ~32 ~153 ~123 oak_leaves[persistent=true]
setblock ~32 ~153 ~124 oak_leaves[persistent=true]
setblock ~32 ~153 ~125 jungle_leaves[persistent=true]
setblock ~32 ~153 ~126 oak_leaves[persistent=true]
setblock ~32 ~153 ~127 jungle_leaves[persistent=true]
setblock ~32 ~153 ~128 oak_leaves[persistent=true]
setblock ~32 ~153 ~129 jungle_leaves[persistent=true]
setblock ~32 ~153 ~130 oak_leaves[persistent=true]
setblock ~32 ~153 ~131 oak_leaves[persistent=true]
setblock ~32 ~153 ~132 oak_leaves[persistent=true]
setblock ~32 ~154 ~118 jungle_leaves[persistent=true]
setblock ~32 ~154 ~119 jungle_leaves[persistent=true]
setblock ~32 ~154 ~120 oak_leaves[persistent=true]
setblock ~32 ~154 ~121 oak_leaves[persistent=true]
setblock ~32 ~154 ~123 jungle_leaves[persistent=true]
setblock ~32 ~154 ~124 jungle_leaves[persistent=true]
setblock ~32 ~154 ~125 jungle_leaves[persistent=true]
setblock ~32 ~154 ~126 oak_leaves[persistent=true]
setblock ~32 ~154 ~127 jungle_leaves[persistent=true]
setblock ~32 ~154 ~128 jungle_leaves[persistent=true]
setblock ~32 ~154 ~129 oak_leaves[persistent=true]
setblock ~32 ~155 ~118 jungle_leaves[persistent=true]
setblock ~32 ~155 ~119 jungle_leaves[persistent=true]
setblock ~32 ~155 ~120 jungle_leaves[persistent=true]
setblock ~32 ~155 ~121 oak_wood
setblock ~32 ~155 ~122 oak_leaves[persistent=true]
setblock ~32 ~155 ~123 oak_leaves[persistent=true]
setblock ~32 ~155 ~124 oak_leaves[persistent=true]
setblock ~32 ~155 ~125 oak_leaves[persistent=true]
setblock ~32 ~155 ~126 oak_leaves[persistent=true]
setblock ~32 ~155 ~128 oak_leaves[persistent=true]
setblock ~32 ~155 ~129 oak_leaves[persistent=true]
setblock ~32 ~156 ~118 oak_leaves[persistent=true]
setblock ~32 ~156 ~119 jungle_leaves[persistent=true]
setblock ~32 ~156 ~120 oak_leaves[persistent=true]
setblock ~32 ~156 ~121 oak_leaves[persistent=true]
setblock ~32 ~156 ~122 oak_leaves[persistent=true]
setblock ~32 ~156 ~123 oak_leaves[persistent=true]
setblock ~32 ~156 ~124 jungle_leaves[persistent=true]
setblock ~32 ~156 ~125 oak_leaves[persistent=true]
setblock ~32 ~156 ~126 oak_leaves[persistent=true]
setblock ~32 ~156 ~127 oak_leaves[persistent=true]
setblock ~32 ~156 ~128 oak_leaves[persistent=true]
setblock ~32 ~156 ~129 oak_leaves[persistent=true]
setblock ~32 ~156 ~130 oak_leaves[persistent=true]
setblock ~32 ~156 ~131 oak_leaves[persistent=true]
setblock ~32 ~157 ~116 oak_leaves[persistent=true]
setblock ~32 ~157 ~117 oak_leaves[persistent=true]
setblock ~32 ~157 ~118 oak_leaves[persistent=true]
setblock ~32 ~157 ~119 oak_leaves[persistent=true]
setblock ~32 ~157 ~120 oak_leaves[persistent=true]
setblock ~32 ~157 ~121 oak_leaves[persistent=true]
setblock ~32 ~157 ~122 jungle_leaves[persistent=true]
setblock ~32 ~157 ~123 oak_leaves[persistent=true]
setblock ~32 ~157 ~124 oak_leaves[persistent=true]
setblock ~32 ~157 ~125 oak_leaves[persistent=true]
setblock ~32 ~157 ~126 oak_leaves[persistent=true]
setblock ~32 ~157 ~127 jungle_leaves[persistent=true]
setblock ~32 ~157 ~129 jungle_leaves[persistent=true]
setblock ~32 ~157 ~130 oak_leaves[persistent=true]
setblock ~32 ~157 ~131 oak_leaves[persistent=true]
setblock ~32 ~158 ~78 oak_leaves[persistent=true]
setblock ~32 ~158 ~79 oak_leaves[persistent=true]
setblock ~32 ~158 ~81 oak_leaves[persistent=true]
setblock ~32 ~158 ~116 jungle_leaves[persistent=true]
setblock ~32 ~158 ~118 oak_leaves[persistent=true]
setblock ~32 ~158 ~119 oak_leaves[persistent=true]
setblock ~32 ~158 ~120 jungle_leaves[persistent=true]
setblock ~32 ~158 ~121 jungle_leaves[persistent=true]
setblock ~32 ~158 ~122 oak_leaves[persistent=true]
setblock ~32 ~158 ~123 oak_leaves[persistent=true]
setblock ~32 ~158 ~124 jungle_leaves[persistent=true]
setblock ~32 ~158 ~125 oak_leaves[persistent=true]
setblock ~32 ~158 ~126 oak_leaves[persistent=true]
setblock ~32 ~158 ~127 oak_leaves[persistent=true]
setblock ~32 ~158 ~128 jungle_leaves[persistent=true]
setblock ~32 ~158 ~129 oak_wood
setblock ~32 ~158 ~130 oak_leaves[persistent=true]
setblock ~32 ~158 ~132 oak_leaves[persistent=true]
setblock ~32 ~158 ~133 jungle_leaves[persistent=true]
setblock ~32 ~158 ~134 oak_leaves[persistent=true]
setblock ~32 ~159 ~77 oak_leaves[persistent=true]
setblock ~32 ~159 ~79 oak_leaves[persistent=true]
setblock ~32 ~159 ~80 oak_leaves[persistent=true]
setblock ~32 ~159 ~81 oak_leaves[persistent=true]
setblock ~32 ~159 ~110 oak_leaves[persistent=true]
setblock ~32 ~159 ~111 oak_leaves[persistent=true]
setblock ~32 ~159 ~112 oak_leaves[persistent=true]
setblock ~32 ~159 ~113 jungle_leaves[persistent=true]
setblock ~32 ~159 ~116 oak_leaves[persistent=true]
setblock ~32 ~159 ~118 oak_leaves[persistent=true]
setblock ~32 ~159 ~119 oak_leaves[persistent=true]
setblock ~32 ~159 ~120 oak_wood
setblock ~32 ~159 ~121 oak_leaves[persistent=true]
setblock ~32 ~159 ~122 oak_leaves[persistent=true]
setblock ~32 ~159 ~123 jungle_leaves[persistent=true]
setblock ~32 ~159 ~124 oak_leaves[persistent=true]
setblock ~32 ~159 ~125 oak_wood
setblock ~32 ~159 ~126 jungle_leaves[persistent=true]
setblock ~32 ~159 ~127 oak_leaves[persistent=true]
setblock ~32 ~159 ~128 jungle_leaves[persistent=true]
setblock ~32 ~159 ~129 oak_wood
setblock ~32 ~159 ~130 oak_wood
setblock ~32 ~159 ~131 oak_leaves[persistent=true]
setblock ~32 ~159 ~132 oak_leaves[persistent=true]
setblock ~32 ~159 ~133 jungle_leaves[persistent=true]
setblock ~32 ~159 ~134 oak_leaves[persistent=true]
setblock ~32 ~160 ~77 oak_leaves[persistent=true]
setblock ~32 ~160 ~78 jungle_leaves[persistent=true]
setblock ~32 ~160 ~79 jungle_leaves[persistent=true]
setblock ~32 ~160 ~80 jungle_leaves[persistent=true]
setblock ~32 ~160 ~81 jungle_leaves[persistent=true]
setblock ~32 ~160 ~110 jungle_leaves[persistent=true]
setblock ~32 ~160 ~112 oak_leaves[persistent=true]
setblock ~32 ~160 ~113 oak_leaves[persistent=true]
setblock ~32 ~160 ~114 oak_leaves[persistent=true]
setblock ~32 ~160 ~115 oak_leaves[persistent=true]
setblock ~32 ~160 ~116 oak_leaves[persistent=true]
setblock ~32 ~160 ~117 oak_leaves[persistent=true]
setblock ~32 ~160 ~118 oak_leaves[persistent=true]
setblock ~32 ~160 ~119 oak_leaves[persistent=true]
setblock ~32 ~160 ~121 oak_leaves[persistent=true]
setblock ~32 ~160 ~122 oak_wood
setblock ~32 ~160 ~123 oak_leaves[persistent=true]
setblock ~32 ~160 ~124 oak_leaves[persistent=true]
setblock ~32 ~160 ~125 jungle_leaves[persistent=true]
setblock ~32 ~160 ~126 oak_wood
setblock ~32 ~160 ~127 oak_leaves[persistent=true]
setblock ~32 ~160 ~128 oak_leaves[persistent=true]
setblock ~32 ~160 ~129 oak_leaves[persistent=true]
setblock ~32 ~160 ~130 oak_leaves[persistent=true]
setblock ~32 ~160 ~131 oak_leaves[persistent=true]
setblock ~32 ~160 ~132 oak_leaves[persistent=true]
setblock ~32 ~160 ~133 oak_wood
setblock ~32 ~160 ~134 oak_leaves[persistent=true]
setblock ~32 ~161 ~79 oak_wood
setblock ~32 ~161 ~80 oak_leaves[persistent=true]
setblock ~32 ~161 ~81 oak_leaves[persistent=true]
setblock ~32 ~161 ~82 jungle_leaves[persistent=true]
setblock ~32 ~161 ~110 oak_leaves[persistent=true]
setblock ~32 ~161 ~112 oak_leaves[persistent=true]
setblock ~32 ~161 ~114 jungle_leaves[persistent=true]
setblock ~32 ~161 ~115 oak_leaves[persistent=true]
setblock ~32 ~161 ~116 oak_leaves[persistent=true]
setblock ~32 ~161 ~117 oak_leaves[persistent=true]
setblock ~32 ~161 ~118 oak_leaves[persistent=true]
setblock ~32 ~161 ~119 oak_leaves[persistent=true]
setblock ~32 ~161 ~120 jungle_leaves[persistent=true]
setblock ~32 ~161 ~121 oak_wood
setblock ~32 ~161 ~122 oak_wood
setblock ~32 ~161 ~123 oak_leaves[persistent=true]
setblock ~32 ~161 ~125 oak_wood
setblock ~32 ~161 ~126 jungle_leaves[persistent=true]
setblock ~32 ~161 ~127 oak_leaves[persistent=true]
setblock ~32 ~161 ~128 oak_leaves[persistent=true]
setblock ~32 ~161 ~129 oak_leaves[persistent=true]
setblock ~32 ~161 ~130 oak_wood
setblock ~32 ~161 ~131 oak_leaves[persistent=true]
setblock ~32 ~161 ~132 oak_leaves[persistent=true]
setblock ~32 ~161 ~133 oak_leaves[persistent=true]
setblock ~32 ~161 ~134 oak_leaves[persistent=true]
setblock ~32 ~162 ~78 oak_leaves[persistent=true]
setblock ~32 ~162 ~79 oak_leaves[persistent=true]
setblock ~32 ~162 ~80 oak_leaves[persistent=true]
setblock ~32 ~162 ~81 oak_leaves[persistent=true]
setblock ~32 ~162 ~82 oak_leaves[persistent=true]
setblock ~32 ~162 ~110 oak_leaves[persistent=true]
setblock ~32 ~162 ~111 oak_leaves[persistent=true]
setblock ~32 ~162 ~112 jungle_leaves[persistent=true]
setblock ~32 ~162 ~113 oak_leaves[persistent=true]
setblock ~32 ~162 ~114 oak_leaves[persistent=true]
setblock ~32 ~162 ~115 oak_leaves[persistent=true]
setblock ~32 ~162 ~116 oak_leaves[persistent=true]
setblock ~32 ~162 ~117 jungle_leaves[persistent=true]
setblock ~32 ~162 ~119 jungle_leaves[persistent=true]
setblock ~32 ~162 ~120 oak_leaves[persistent=true]
setblock ~32 ~162 ~121 oak_leaves[persistent=true]
setblock ~32 ~162 ~122 oak_leaves[persistent=true]
setblock ~32 ~162 ~123 oak_leaves[persistent=true]
setblock ~32 ~162 ~124 oak_wood
setblock ~32 ~162 ~125 oak_leaves[persistent=true]
setblock ~32 ~162 ~126 oak_leaves[persistent=true]
setblock ~32 ~162 ~127 oak_leaves[persistent=true]
setblock ~32 ~162 ~128 oak_leaves[persistent=true]
setblock ~32 ~162 ~129 oak_leaves[persistent=true]
setblock ~32 ~162 ~130 oak_leaves[persistent=true]
setblock ~32 ~162 ~131 oak_leaves[persistent=true]
setblock ~32 ~162 ~132 oak_leaves[persistent=true]
setblock ~32 ~162 ~134 oak_leaves[persistent=true]
setblock ~32 ~163 ~72 oak_leaves[persistent=true]
setblock ~32 ~163 ~73 oak_leaves[persistent=true]
setblock ~32 ~163 ~74 oak_leaves[persistent=true]
setblock ~32 ~163 ~75 oak_leaves[persistent=true]
setblock ~32 ~163 ~77 oak_leaves[persistent=true]
setblock ~32 ~163 ~78 oak_leaves[persistent=true]
setblock ~32 ~163 ~79 oak_leaves[persistent=true]
setblock ~32 ~163 ~80 jungle_leaves[persistent=true]
setblock ~32 ~163 ~112 oak_leaves[persistent=true]
setblock ~32 ~163 ~113 oak_leaves[persistent=true]
setblock ~32 ~163 ~114 oak_leaves[persistent=true]
setblock ~32 ~163 ~115 oak_leaves[persistent=true]
setblock ~32 ~163 ~116 oak_leaves[persistent=true]
setblock ~32 ~163 ~117 oak_leaves[persistent=true]
setblock ~32 ~163 ~118 oak_leaves[persistent=true]
setblock ~32 ~163 ~119 oak_leaves[persistent=true]
setblock ~32 ~163 ~120 oak_leaves[persistent=true]
setblock ~32 ~163 ~121 oak_wood
setblock ~32 ~163 ~122 oak_wood
setblock ~32 ~163 ~123 oak_wood
setblock ~32 ~163 ~124 oak_leaves[persistent=true]
setblock ~32 ~163 ~125 oak_wood
setblock ~32 ~163 ~126 oak_leaves[persistent=true]
setblock ~32 ~163 ~127 oak_wood
setblock ~32 ~163 ~128 oak_wood
setblock ~32 ~163 ~129 oak_leaves[persistent=true]
setblock ~32 ~163 ~131 jungle_leaves[persistent=true]
setblock ~32 ~163 ~132 oak_wood
setblock ~32 ~163 ~133 oak_leaves[persistent=true]
setblock ~32 ~164 ~72 oak_leaves[persistent=true]
setblock ~32 ~164 ~73 oak_leaves[persistent=true]
setblock ~32 ~164 ~74 jungle_leaves[persistent=true]
setblock ~32 ~164 ~112 jungle_leaves[persistent=true]
setblock ~32 ~164 ~113 oak_leaves[persistent=true]
setblock ~32 ~164 ~114 oak_leaves[persistent=true]
setblock ~32 ~164 ~115 oak_leaves[persistent=true]
setblock ~32 ~164 ~116 oak_leaves[persistent=true]
setblock ~32 ~164 ~117 oak_leaves[persistent=true]
setblock ~32 ~164 ~118 oak_leaves[persistent=true]
setblock ~32 ~164 ~119 oak_leaves[persistent=true]
setblock ~32 ~164 ~120 oak_wood
setblock ~32 ~164 ~121 oak_leaves[persistent=true]
setblock ~32 ~164 ~122 oak_leaves[persistent=true]
setblock ~32 ~164 ~123 oak_wood
setblock ~32 ~164 ~125 oak_wood
setblock ~32 ~164 ~126 oak_wood
setblock ~32 ~164 ~128 jungle_leaves[persistent=true]
setblock ~32 ~164 ~129 oak_wood
setblock ~32 ~164 ~130 oak_leaves[persistent=true]
setblock ~32 ~164 ~131 jungle_leaves[persistent=true]
setblock ~32 ~164 ~132 oak_leaves[persistent=true]
setblock ~32 ~164 ~133 oak_leaves[persistent=true]
setblock ~32 ~164 ~134 oak_leaves[persistent=true]
setblock ~32 ~165 ~72 oak_leaves[persistent=true]
setblock ~32 ~165 ~73 jungle_leaves[persistent=true]
setblock ~32 ~165 ~74 oak_leaves[persistent=true]
setblock ~32 ~165 ~75 oak_leaves[persistent=true]
setblock ~32 ~165 ~112 jungle_leaves[persistent=true]
setblock ~32 ~165 ~113 oak_leaves[persistent=true]
setblock ~32 ~165 ~114 oak_leaves[persistent=true]
setblock ~32 ~165 ~115 oak_wood
setblock ~32 ~165 ~116 oak_wood
setblock ~32 ~165 ~117 jungle_leaves[persistent=true]
setblock ~32 ~165 ~118 oak_wood
setblock ~32 ~165 ~119 jungle_leaves[persistent=true]
setblock ~32 ~165 ~121 oak_wood
setblock ~32 ~165 ~122 oak_wood
setblock ~32 ~165 ~123 oak_leaves[persistent=true]
setblock ~32 ~165 ~124 oak_wood
setblock ~32 ~165 ~125 oak_wood
setblock ~32 ~165 ~127 oak_leaves[persistent=true]
setblock ~32 ~165 ~128 oak_leaves[persistent=true]
setblock ~32 ~165 ~129 oak_wood
setblock ~32 ~165 ~130 oak_leaves[persistent=true]
setblock ~32 ~165 ~131 oak_wood
setblock ~32 ~165 ~132 oak_leaves[persistent=true]
setblock ~32 ~165 ~133 oak_leaves[persistent=true]
setblock ~32 ~165 ~134 oak_leaves[persistent=true]
setblock ~32 ~166 ~73 oak_leaves[persistent=true]
setblock ~32 ~166 ~74 oak_leaves[persistent=true]
setblock ~32 ~166 ~75 oak_leaves[persistent=true]
setblock ~32 ~166 ~113 oak_leaves[persistent=true]
setblock ~32 ~166 ~114 oak_leaves[persistent=true]
setblock ~32 ~166 ~115 oak_leaves[persistent=true]
setblock ~32 ~166 ~116 oak_leaves[persistent=true]
setblock ~32 ~166 ~117 oak_wood
setblock ~32 ~166 ~118 oak_leaves[persistent=true]
setblock ~32 ~166 ~119 oak_leaves[persistent=true]
setblock ~32 ~166 ~120 oak_leaves[persistent=true]
setblock ~32 ~166 ~121 oak_leaves[persistent=true]
setblock ~32 ~166 ~122 oak_wood
setblock ~32 ~166 ~123 oak_wood
setblock ~32 ~166 ~124 oak_wood
setblock ~32 ~166 ~125 oak_wood
setblock ~32 ~166 ~126 oak_wood
setblock ~32 ~166 ~127 oak_wood
setblock ~32 ~166 ~128 jungle_leaves[persistent=true]
setblock ~32 ~166 ~129 oak_wood
setblock ~32 ~166 ~130 oak_leaves[persistent=true]
setblock ~32 ~166 ~131 oak_leaves[persistent=true]
setblock ~32 ~166 ~132 oak_leaves[persistent=true]
setblock ~32 ~166 ~133 oak_leaves[persistent=true]
setblock ~32 ~166 ~134 oak_leaves[persistent=true]
setblock ~32 ~166 ~135 oak_leaves[persistent=true]
setblock ~32 ~167 ~113 oak_leaves[persistent=true]
setblock ~32 ~167 ~115 oak_leaves[persistent=true]
setblock ~32 ~167 ~116 oak_leaves[persistent=true]
setblock ~32 ~167 ~117 oak_leaves[persistent=true]
setblock ~32 ~167 ~118 oak_wood
setblock ~32 ~167 ~119 jungle_leaves[persistent=true]
setblock ~32 ~167 ~120 oak_wood
setblock ~32 ~167 ~121 oak_leaves[persistent=true]
setblock ~32 ~167 ~122 oak_wood
setblock ~32 ~167 ~123 oak_wood
setblock ~32 ~167 ~124 oak_wood
setblock ~32 ~167 ~126 oak_wood
setblock ~32 ~167 ~127 oak_leaves[persistent=true]
setblock ~32 ~167 ~128 oak_leaves[persistent=true]
setblock ~32 ~167 ~129 oak_leaves[persistent=true]
setblock ~32 ~167 ~130 oak_wood
setblock ~32 ~167 ~131 oak_leaves[persistent=true]
setblock ~32 ~167 ~132 oak_leaves[persistent=true]
setblock ~32 ~167 ~135 oak_leaves[persistent=true]
setblock ~32 ~168 ~113 jungle_leaves[persistent=true]
setblock ~32 ~168 ~114 jungle_leaves[persistent=true]
setblock ~32 ~168 ~115 oak_leaves[persistent=true]
setblock ~32 ~168 ~116 oak_wood
setblock ~32 ~168 ~117 oak_leaves[persistent=true]
