setblock ~168 ~123 ~127 dirt
setblock ~168 ~123 ~128 dirt
setblock ~168 ~123 ~129 dirt
setblock ~168 ~123 ~130 dirt
setblock ~168 ~123 ~131 dirt
setblock ~168 ~123 ~132 dirt
setblock ~168 ~123 ~133 dirt
setblock ~168 ~123 ~134 dirt
setblock ~168 ~124 ~70 dirt
setblock ~168 ~124 ~71 dirt
setblock ~168 ~124 ~72 dirt
setblock ~168 ~124 ~73 dirt
setblock ~168 ~124 ~74 dirt
setblock ~168 ~124 ~75 dirt
setblock ~168 ~124 ~76 dirt
setblock ~168 ~124 ~77 dirt
setblock ~168 ~124 ~78 dirt
setblock ~168 ~124 ~79 grass_block
setblock ~168 ~124 ~80 grass_block
setblock ~168 ~124 ~81 grass_block
setblock ~168 ~124 ~82 dirt
setblock ~168 ~124 ~83 dirt
setblock ~168 ~124 ~84 dirt
setblock ~168 ~124 ~85 dirt
setblock ~168 ~124 ~87 dirt
setblock ~168 ~124 ~88 dirt
setblock ~168 ~124 ~89 dirt
setblock ~168 ~124 ~90 dirt
setblock ~168 ~124 ~91 dirt
setblock ~168 ~124 ~92 dirt
setblock ~168 ~124 ~93 dirt
setblock ~168 ~124 ~94 dirt
setblock ~168 ~124 ~95 dirt
setblock ~168 ~124 ~96 dirt
setblock ~168 ~124 ~97 dirt
setblock ~168 ~124 ~98 dirt
setblock ~168 ~124 ~99 dirt
setblock ~168 ~124 ~100 dirt
setblock ~168 ~124 ~101 dirt
setblock ~168 ~124 ~102 dirt
setblock ~168 ~124 ~103 dirt
setblock ~168 ~124 ~104 dirt
setblock ~168 ~124 ~105 dirt
setblock ~168 ~124 ~106 grass_block
setblock ~168 ~124 ~107 grass_block
setblock ~168 ~124 ~108 grass_block
setblock ~168 ~124 ~119 short_grass
setblock ~168 ~124 ~120 short_grass
setblock ~168 ~124 ~122 grass_block
setblock ~168 ~124 ~123 grass_block
setblock ~168 ~124 ~124 grass_block
setblock ~168 ~124 ~125 grass_block
setblock ~168 ~124 ~126 dirt
setblock ~168 ~124 ~127 dirt
setblock ~168 ~124 ~128 dirt
setblock ~168 ~124 ~129 dirt
setblock ~168 ~124 ~130 dirt
setblock ~168 ~124 ~131 dirt
setblock ~168 ~124 ~132 dirt
setblock ~168 ~124 ~133 dirt
setblock ~168 ~124 ~134 dirt
setblock ~168 ~125 ~70 dirt
setblock ~168 ~125 ~71 grass_block
setblock ~168 ~125 ~72 grass_block
setblock ~168 ~125 ~73 grass_block
setblock ~168 ~125 ~74 grass_block
setblock ~168 ~125 ~75 grass_block
setblock ~168 ~125 ~76 grass_block
setblock ~168 ~125 ~77 grass_block
setblock ~168 ~125 ~78 grass_block
setblock ~168 ~125 ~79 short_grass
setblock ~168 ~125 ~81 poppy
setblock ~168 ~125 ~82 grass_block
setblock ~168 ~125 ~83 grass_block
setblock ~168 ~125 ~84 grass_block
setblock ~168 ~125 ~85 grass_block
setblock ~168 ~125 ~87 dirt
setblock ~168 ~125 ~88 dirt
setblock ~168 ~125 ~89 dirt
setblock ~168 ~125 ~90 dirt
setblock ~168 ~125 ~91 dirt
setblock ~168 ~125 ~92 dirt
setblock ~168 ~125 ~93 dirt
setblock ~168 ~125 ~94 dirt
setblock ~168 ~125 ~95 dirt
setblock ~168 ~125 ~96 dirt
setblock ~168 ~125 ~97 dirt
setblock ~168 ~125 ~98 dirt
setblock ~168 ~125 ~99 dirt
setblock ~168 ~125 ~100 dirt
setblock ~168 ~125 ~101 dirt
setblock ~168 ~125 ~102 grass_block
setblock ~168 ~125 ~103 grass_block
setblock ~168 ~125 ~104 grass_block
setblock ~168 ~125 ~105 grass_block
setblock ~168 ~125 ~123 short_grass
setblock ~168 ~125 ~126 grass_block
setblock ~168 ~125 ~127 grass_block
setblock ~168 ~125 ~128 dirt
setblock ~168 ~125 ~129 dirt
setblock ~168 ~125 ~130 dirt
setblock ~168 ~125 ~131 dirt
setblock ~168 ~125 ~132 dirt
setblock ~168 ~125 ~133 grass_block
setblock ~168 ~125 ~134 grass_block
setblock ~168 ~126 ~70 grass_block
setblock ~168 ~126 ~71 poppy
setblock ~168 ~126 ~73 short_grass
setblock ~168 ~126 ~74 short_grass
setblock ~168 ~126 ~75 short_grass
setblock ~168 ~126 ~76 short_grass
setblock ~168 ~126 ~77 short_grass
setblock ~168 ~126 ~83 short_grass
setblock ~168 ~126 ~84 poppy
setblock ~168 ~126 ~87 grass_block
setblock ~168 ~126 ~88 dirt
setblock ~168 ~126 ~89 dirt
setblock ~168 ~126 ~90 dirt
setblock ~168 ~126 ~91 dirt
setblock ~168 ~126 ~92 dirt
setblock ~168 ~126 ~93 dirt
setblock ~168 ~126 ~94 dirt
setblock ~168 ~126 ~95 dirt
setblock ~168 ~126 ~96 grass_block
setblock ~168 ~126 ~97 grass_block
setblock ~168 ~126 ~98 grass_block
setblock ~168 ~126 ~99 grass_block
setblock ~168 ~126 ~100 grass_block
setblock ~168 ~126 ~101 grass_block
setblock ~168 ~126 ~102 short_grass
setblock ~168 ~126 ~128 grass_block
setblock ~168 ~126 ~129 grass_block
setblock ~168 ~126 ~130 dirt
setblock ~168 ~126 ~131 grass_block
setblock ~168 ~126 ~132 grass_block
setblock ~168 ~126 ~134 poppy
setblock ~168 ~127 ~70 short_grass
setblock ~168 ~127 ~87 short_grass
setblock ~168 ~127 ~88 grass_block
setblock ~168 ~127 ~89 dirt
setblock ~168 ~127 ~90 dirt
setblock ~168 ~127 ~91 dirt
setblock ~168 ~127 ~92 dirt
setblock ~168 ~127 ~93 grass_block
setblock ~168 ~127 ~94 grass_block
setblock ~168 ~127 ~95 grass_block
setblock ~168 ~127 ~130 grass_block
setblock ~168 ~127 ~132 short_grass
setblock ~168 ~128 ~89 grass_block
setblock ~168 ~128 ~90 dirt
setblock ~168 ~128 ~91 grass_block
setblock ~168 ~128 ~92 grass_block
setblock ~168 ~128 ~95 short_grass
setblock ~168 ~129 ~89 poppy
setblock ~168 ~129 ~90 grass_block
setblock ~168 ~129 ~91 poppy
setblock ~168 ~129 ~92 poppy
setblock ~168 ~130 ~90 short_grass
setblock ~169 ~103 ~101 dirt
setblock ~169 ~104 ~100 dirt
setblock ~169 ~104 ~101 dirt
setblock ~169 ~105 ~99 dirt
setblock ~169 ~105 ~100 dirt
setblock ~169 ~105 ~101 dirt
setblock ~169 ~105 ~103 dirt
setblock ~169 ~106 ~98 dirt
setblock ~169 ~106 ~99 dirt
setblock ~169 ~106 ~100 dirt
setblock ~169 ~106 ~101 dirt
setblock ~169 ~106 ~102 dirt
setblock ~169 ~106 ~103 dirt
setblock ~169 ~107 ~98 dirt
setblock ~169 ~107 ~99 dirt
setblock ~169 ~107 ~100 dirt
setblock ~169 ~107 ~101 dirt
setblock ~169 ~107 ~102 dirt
setblock ~169 ~107 ~103 dirt
setblock ~169 ~107 ~104 dirt
setblock ~169 ~108 ~97 dirt
setblock ~169 ~108 ~98 dirt
setblock ~169 ~108 ~99 dirt
setblock ~169 ~108 ~100 dirt
setblock ~169 ~108 ~101 dirt
setblock ~169 ~108 ~102 dirt
setblock ~169 ~108 ~103 dirt
setblock ~169 ~108 ~104 dirt
setblock ~169 ~108 ~119 dirt
setblock ~169 ~109 ~96 dirt
setblock ~169 ~109 ~97 dirt
setblock ~169 ~109 ~98 dirt
setblock ~169 ~109 ~99 dirt
setblock ~169 ~109 ~100 dirt
setblock ~169 ~109 ~101 dirt
setblock ~169 ~109 ~102 dirt
setblock ~169 ~109 ~103 dirt
setblock ~169 ~109 ~104 dirt
setblock ~169 ~109 ~119 dirt
setblock ~169 ~109 ~120 dirt
setblock ~169 ~110 ~96 dirt
setblock ~169 ~110 ~97 dirt
setblock ~169 ~110 ~98 dirt
setblock ~169 ~110 ~99 dirt
setblock ~169 ~110 ~100 dirt
setblock ~169 ~110 ~101 dirt
setblock ~169 ~110 ~102 dirt
setblock ~169 ~110 ~103 dirt
setblock ~169 ~110 ~104 dirt
setblock ~169 ~110 ~105 dirt
setblock ~169 ~110 ~119 dirt
setblock ~169 ~110 ~120 dirt
setblock ~169 ~110 ~121 dirt
setblock ~169 ~111 ~96 dirt
setblock ~169 ~111 ~97 dirt
setblock ~169 ~111 ~98 dirt
setblock ~169 ~111 ~99 dirt
setblock ~169 ~111 ~100 dirt
setblock ~169 ~111 ~101 dirt
setblock ~169 ~111 ~102 dirt
setblock ~169 ~111 ~103 dirt
setblock ~169 ~111 ~104 dirt
setblock ~169 ~111 ~105 dirt
setblock ~169 ~111 ~106 dirt
setblock ~169 ~111 ~108 dirt
setblock ~169 ~111 ~118 dirt
setblock ~169 ~111 ~119 dirt
setblock ~169 ~111 ~120 dirt
setblock ~169 ~111 ~121 dirt
setblock ~169 ~112 ~96 dirt
setblock ~169 ~112 ~97 dirt
setblock ~169 ~112 ~98 dirt
setblock ~169 ~112 ~99 dirt
setblock ~169 ~112 ~100 dirt
setblock ~169 ~112 ~101 dirt
setblock ~169 ~112 ~102 dirt
setblock ~169 ~112 ~103 dirt
setblock ~169 ~112 ~104 dirt
setblock ~169 ~112 ~105 dirt
setblock ~169 ~112 ~106 dirt
setblock ~169 ~112 ~107 dirt
setblock ~169 ~112 ~108 dirt
setblock ~169 ~112 ~116 dirt
setblock ~169 ~112 ~117 dirt
setblock ~169 ~112 ~118 dirt
setblock ~169 ~112 ~119 dirt
setblock ~169 ~112 ~120 dirt
setblock ~169 ~112 ~121 dirt
setblock ~169 ~112 ~122 dirt
setblock ~169 ~113 ~95 dirt
setblock ~169 ~113 ~96 dirt
setblock ~169 ~113 ~97 dirt
setblock ~169 ~113 ~98 dirt
setblock ~169 ~113 ~99 dirt
setblock ~169 ~113 ~100 dirt
setblock ~169 ~113 ~101 dirt
setblock ~169 ~113 ~102 dirt
setblock ~169 ~113 ~103 dirt
setblock ~169 ~113 ~104 dirt
setblock ~169 ~113 ~105 dirt
setblock ~169 ~113 ~106 dirt
setblock ~169 ~113 ~107 dirt
setblock ~169 ~113 ~108 dirt
setblock ~169 ~113 ~109 dirt
setblock ~169 ~113 ~110 dirt
setblock ~169 ~113 ~112 dirt
setblock ~169 ~113 ~114 dirt
setblock ~169 ~113 ~115 dirt
setblock ~169 ~113 ~116 dirt
setblock ~169 ~113 ~117 dirt
setblock ~169 ~113 ~118 dirt
setblock ~169 ~113 ~119 dirt
setblock ~169 ~113 ~120 dirt
setblock ~169 ~113 ~121 dirt
setblock ~169 ~113 ~122 dirt
setblock ~169 ~113 ~123 dirt
setblock ~169 ~114 ~95 dirt
setblock ~169 ~114 ~96 dirt
setblock ~169 ~114 ~97 dirt
setblock ~169 ~114 ~98 dirt
setblock ~169 ~114 ~99 dirt
setblock ~169 ~114 ~100 dirt
setblock ~169 ~114 ~101 dirt
setblock ~169 ~114 ~102 dirt
setblock ~169 ~114 ~103 dirt
setblock ~169 ~114 ~104 dirt
setblock ~169 ~114 ~105 dirt
setblock ~169 ~114 ~106 dirt
setblock ~169 ~114 ~107 dirt
setblock ~169 ~114 ~108 dirt
setblock ~169 ~114 ~109 dirt
setblock ~169 ~114 ~110 dirt
setblock ~169 ~114 ~111 dirt
setblock ~169 ~114 ~112 dirt
setblock ~169 ~114 ~113 dirt
setblock ~169 ~114 ~114 dirt
setblock ~169 ~114 ~115 dirt
setblock ~169 ~114 ~116 dirt
setblock ~169 ~114 ~117 dirt
setblock ~169 ~114 ~118 dirt
setblock ~169 ~114 ~119 dirt
setblock ~169 ~114 ~120 dirt
setblock ~169 ~114 ~121 dirt
setblock ~169 ~114 ~122 dirt
setblock ~169 ~114 ~123 dirt
setblock ~169 ~114 ~124 dirt
setblock ~169 ~114 ~127 dirt
setblock ~169 ~115 ~94 dirt
setblock ~169 ~115 ~95 dirt
setblock ~169 ~115 ~96 dirt
setblock ~169 ~115 ~97 dirt
setblock ~169 ~115 ~98 dirt
setblock ~169 ~115 ~99 dirt
setblock ~169 ~115 ~100 dirt
setblock ~169 ~115 ~101 dirt
setblock ~169 ~115 ~102 dirt
setblock ~169 ~115 ~103 dirt
setblock ~169 ~115 ~104 dirt
setblock ~169 ~115 ~105 dirt
setblock ~169 ~115 ~106 dirt
setblock ~169 ~115 ~107 dirt
setblock ~169 ~115 ~108 dirt
setblock ~169 ~115 ~109 dirt
setblock ~169 ~115 ~110 dirt
setblock ~169 ~115 ~111 dirt
setblock ~169 ~115 ~112 dirt
setblock ~169 ~115 ~113 dirt
setblock ~169 ~115 ~114 dirt
setblock ~169 ~115 ~115 dirt
setblock ~169 ~115 ~116 dirt
setblock ~169 ~115 ~117 dirt
setblock ~169 ~115 ~118 dirt
setblock ~169 ~115 ~119 dirt
setblock ~169 ~115 ~120 dirt
setblock ~169 ~115 ~121 dirt
setblock ~169 ~115 ~122 dirt
setblock ~169 ~115 ~123 dirt
setblock ~169 ~115 ~124 dirt
setblock ~169 ~115 ~127 dirt
setblock ~169 ~115 ~128 dirt
setblock ~169 ~116 ~93 dirt
setblock ~169 ~116 ~94 dirt
setblock ~169 ~116 ~95 dirt
setblock ~169 ~116 ~96 dirt
setblock ~169 ~116 ~97 dirt
setblock ~169 ~116 ~98 dirt
setblock ~169 ~116 ~99 dirt
setblock ~169 ~116 ~100 dirt
setblock ~169 ~116 ~101 dirt
setblock ~169 ~116 ~102 dirt
setblock ~169 ~116 ~103 dirt
setblock ~169 ~116 ~104 dirt
setblock ~169 ~116 ~105 dirt
setblock ~169 ~116 ~106 dirt
setblock ~169 ~116 ~107 dirt
setblock ~169 ~116 ~108 dirt
setblock ~169 ~116 ~109 dirt
setblock ~169 ~116 ~110 dirt
setblock ~169 ~116 ~111 dirt
setblock ~169 ~116 ~112 dirt
setblock ~169 ~116 ~113 dirt
setblock ~169 ~116 ~114 dirt
setblock ~169 ~116 ~115 dirt
setblock ~169 ~116 ~116 dirt
setblock ~169 ~116 ~117 dirt
setblock ~169 ~116 ~118 dirt
setblock ~169 ~116 ~119 dirt
setblock ~169 ~116 ~120 dirt
setblock ~169 ~116 ~121 dirt
setblock ~169 ~116 ~122 dirt
setblock ~169 ~116 ~123 dirt
setblock ~169 ~116 ~124 dirt
setblock ~169 ~116 ~125 dirt
setblock ~169 ~116 ~127 dirt
setblock ~169 ~116 ~128 dirt
setblock ~169 ~116 ~129 dirt
setblock ~169 ~117 ~79 dirt
setblock ~169 ~117 ~93 dirt
setblock ~169 ~117 ~94 dirt
setblock ~169 ~117 ~95 dirt
setblock ~169 ~117 ~96 dirt
setblock ~169 ~117 ~97 dirt
setblock ~169 ~117 ~98 dirt
setblock ~169 ~117 ~99 dirt
setblock ~169 ~117 ~100 dirt
setblock ~169 ~117 ~101 dirt
setblock ~169 ~117 ~102 dirt
setblock ~169 ~117 ~103 dirt
setblock ~169 ~117 ~104 dirt
setblock ~169 ~117 ~105 dirt
setblock ~169 ~117 ~106 dirt
setblock ~169 ~117 ~107 dirt
setblock ~169 ~117 ~108 dirt
setblock ~169 ~117 ~109 dirt
setblock ~169 ~117 ~110 dirt
setblock ~169 ~117 ~111 dirt
setblock ~169 ~117 ~112 dirt
setblock ~169 ~117 ~113 dirt
setblock ~169 ~117 ~114 dirt
setblock ~169 ~117 ~115 dirt
setblock ~169 ~117 ~116 dirt
setblock ~169 ~117 ~117 dirt
setblock ~169 ~117 ~118 dirt
setblock ~169 ~117 ~119 dirt
setblock ~169 ~117 ~120 dirt
setblock ~169 ~117 ~121 dirt
setblock ~169 ~117 ~122 dirt
setblock ~169 ~117 ~123 dirt
setblock ~169 ~117 ~124 dirt
setblock ~169 ~117 ~125 dirt
setblock ~169 ~117 ~126 dirt
setblock ~169 ~117 ~127 dirt
setblock ~169 ~117 ~128 dirt
setblock ~169 ~117 ~129 dirt
setblock ~169 ~118 ~79 dirt
setblock ~169 ~118 ~81 dirt
setblock ~169 ~118 ~92 dirt
setblock ~169 ~118 ~93 dirt
setblock ~169 ~118 ~94 dirt
setblock ~169 ~118 ~95 dirt
setblock ~169 ~118 ~96 dirt
setblock ~169 ~118 ~97 dirt
setblock ~169 ~118 ~98 dirt
setblock ~169 ~118 ~99 dirt
setblock ~169 ~118 ~100 dirt
setblock ~169 ~118 ~101 dirt
setblock ~169 ~118 ~102 dirt
setblock ~169 ~118 ~103 dirt
setblock ~169 ~118 ~104 dirt
setblock ~169 ~118 ~105 dirt
setblock ~169 ~118 ~106 dirt
setblock ~169 ~118 ~107 dirt
setblock ~169 ~118 ~108 dirt
setblock ~169 ~118 ~109 dirt
setblock ~169 ~118 ~110 dirt
setblock ~169 ~118 ~111 dirt
setblock ~169 ~118 ~112 dirt
setblock ~169 ~118 ~113 dirt
setblock ~169 ~118 ~114 dirt
setblock ~169 ~118 ~115 dirt
setblock ~169 ~118 ~116 dirt
setblock ~169 ~118 ~117 dirt
setblock ~169 ~118 ~118 dirt
setblock ~169 ~118 ~119 dirt
setblock ~169 ~118 ~120 dirt
setblock ~169 ~118 ~121 dirt
setblock ~169 ~118 ~122 dirt
setblock ~169 ~118 ~123 dirt
setblock ~169 ~118 ~124 dirt
setblock ~169 ~118 ~125 dirt
setblock ~169 ~118 ~126 dirt
setblock ~169 ~118 ~127 dirt
setblock ~169 ~118 ~128 dirt
setblock ~169 ~118 ~129 dirt
setblock ~169 ~119 ~78 dirt
setblock ~169 ~119 ~79 dirt
setblock ~169 ~119 ~80 dirt
setblock ~169 ~119 ~81 dirt
setblock ~169 ~119 ~90 dirt
setblock ~169 ~119 ~91 dirt
setblock ~169 ~119 ~92 dirt
setblock ~169 ~119 ~93 dirt
setblock ~169 ~119 ~94 dirt
setblock ~169 ~119 ~95 dirt
setblock ~169 ~119 ~96 dirt
setblock ~169 ~119 ~97 dirt
setblock ~169 ~119 ~98 dirt
setblock ~169 ~119 ~99 dirt
setblock ~169 ~119 ~100 dirt
setblock ~169 ~119 ~101 dirt
setblock ~169 ~119 ~102 dirt
setblock ~169 ~119 ~103 dirt
setblock ~169 ~119 ~104 dirt
setblock ~169 ~119 ~105 dirt
setblock ~169 ~119 ~106 dirt
setblock ~169 ~119 ~107 dirt
setblock ~169 ~119 ~108 dirt
setblock ~169 ~119 ~109 dirt
setblock ~169 ~119 ~110 dirt
setblock ~169 ~119 ~111 dirt
setblock ~169 ~119 ~112 dirt
setblock ~169 ~119 ~113 dirt
setblock ~169 ~119 ~114 dirt
setblock ~169 ~119 ~115 dirt
setblock ~169 ~119 ~116 dirt
setblock ~169 ~119 ~117 dirt
setblock ~169 ~119 ~118 dirt
setblock ~169 ~119 ~119 dirt
setblock ~169 ~119 ~120 dirt
setblock ~169 ~119 ~121 dirt
setblock ~169 ~119 ~122 dirt
setblock ~169 ~119 ~123 dirt
setblock ~169 ~119 ~124 dirt
setblock ~169 ~119 ~125 dirt
setblock ~169 ~119 ~126 dirt
setblock ~169 ~119 ~127 dirt
setblock ~169 ~119 ~128 dirt
setblock ~169 ~119 ~129 dirt
setblock ~169 ~119 ~130 dirt
setblock ~169 ~119 ~131 dirt
setblock ~169 ~120 ~72 dirt
setblock ~169 ~120 ~75 dirt
setblock ~169 ~120 ~76 dirt
setblock ~169 ~120 ~77 dirt
setblock ~169 ~120 ~78 dirt
setblock ~169 ~120 ~79 dirt
setblock ~169 ~120 ~80 dirt
setblock ~169 ~120 ~81 dirt
setblock ~169 ~120 ~82 dirt
setblock ~169 ~120 ~89 dirt
setblock ~169 ~120 ~90 dirt
setblock ~169 ~120 ~91 dirt
setblock ~169 ~120 ~92 dirt
setblock ~169 ~120 ~93 dirt
setblock ~169 ~120 ~94 dirt
setblock ~169 ~120 ~95 dirt
setblock ~169 ~120 ~96 dirt
setblock ~169 ~120 ~97 dirt
setblock ~169 ~120 ~98 dirt
setblock ~169 ~120 ~99 dirt
setblock ~169 ~120 ~100 dirt
setblock ~169 ~120 ~101 dirt
setblock ~169 ~120 ~102 dirt
setblock ~169 ~120 ~103 dirt
setblock ~169 ~120 ~104 dirt
setblock ~169 ~120 ~105 dirt
setblock ~169 ~120 ~106 dirt
setblock ~169 ~120 ~107 dirt
setblock ~169 ~120 ~108 dirt
setblock ~169 ~120 ~109 dirt
setblock ~169 ~120 ~110 dirt
setblock ~169 ~120 ~111 dirt
setblock ~169 ~120 ~112 dirt
setblock ~169 ~120 ~113 dirt
setblock ~169 ~120 ~114 dirt
setblock ~169 ~120 ~115 dirt
setblock ~169 ~120 ~116 dirt
setblock ~169 ~120 ~117 dirt
setblock ~169 ~120 ~118 dirt
setblock ~169 ~120 ~119 dirt
setblock ~169 ~120 ~120 dirt
setblock ~169 ~120 ~121 dirt
setblock ~169 ~120 ~122 dirt
setblock ~169 ~120 ~123 dirt
setblock ~169 ~120 ~124 dirt
setblock ~169 ~120 ~125 dirt
setblock ~169 ~120 ~126 dirt
setblock ~169 ~120 ~127 dirt
setblock ~169 ~120 ~128 dirt
setblock ~169 ~120 ~129 dirt
setblock ~169 ~120 ~130 dirt
setblock ~169 ~120 ~131 dirt
setblock ~169 ~120 ~132 dirt
setblock ~169 ~121 ~71 dirt
setblock ~169 ~121 ~72 dirt
setblock ~169 ~121 ~74 dirt
setblock ~169 ~121 ~75 dirt
setblock ~169 ~121 ~76 dirt
setblock ~169 ~121 ~77 dirt
setblock ~169 ~121 ~78 dirt
setblock ~169 ~121 ~79 dirt
setblock ~169 ~121 ~80 dirt
setblock ~169 ~121 ~81 dirt
setblock ~169 ~121 ~82 dirt
setblock ~169 ~121 ~83 dirt
setblock ~169 ~121 ~88 dirt
setblock ~169 ~121 ~89 dirt
setblock ~169 ~121 ~90 dirt
setblock ~169 ~121 ~91 dirt
setblock ~169 ~121 ~92 dirt
setblock ~169 ~121 ~93 dirt
setblock ~169 ~121 ~94 dirt
setblock ~169 ~121 ~95 dirt
setblock ~169 ~121 ~96 dirt
setblock ~169 ~121 ~97 dirt
setblock ~169 ~121 ~98 dirt
setblock ~169 ~121 ~99 dirt
setblock ~169 ~121 ~100 dirt
setblock ~169 ~121 ~101 dirt
setblock ~169 ~121 ~102 dirt
setblock ~169 ~121 ~103 dirt
setblock ~169 ~121 ~104 dirt
setblock ~169 ~121 ~105 dirt
setblock ~169 ~121 ~106 dirt
setblock ~169 ~121 ~107 dirt
setblock ~169 ~121 ~108 dirt
setblock ~169 ~121 ~109 dirt
setblock ~169 ~121 ~110 dirt
setblock ~169 ~121 ~111 dirt
setblock ~169 ~121 ~112 dirt
setblock ~169 ~121 ~113 dirt
setblock ~169 ~121 ~114 dirt
setblock ~169 ~121 ~115 dirt
setblock ~169 ~121 ~116 dirt
setblock ~169 ~121 ~117 dirt
setblock ~169 ~121 ~118 dirt
setblock ~169 ~121 ~119 dirt
setblock ~169 ~121 ~120 dirt
setblock ~169 ~121 ~121 dirt
setblock ~169 ~121 ~122 dirt
setblock ~169 ~121 ~123 dirt
setblock ~169 ~121 ~124 dirt
setblock ~169 ~121 ~125 dirt
setblock ~169 ~121 ~126 dirt
setblock ~169 ~121 ~127 dirt
setblock ~169 ~121 ~128 dirt
setblock ~169 ~121 ~129 dirt
setblock ~169 ~121 ~130 dirt
setblock ~169 ~121 ~131 dirt
setblock ~169 ~121 ~132 dirt
setblock ~169 ~121 ~133 dirt
setblock ~169 ~122 ~71 dirt
setblock ~169 ~122 ~72 dirt
setblock ~169 ~122 ~74 dirt
setblock ~169 ~122 ~75 dirt
setblock ~169 ~122 ~76 dirt
setblock ~169 ~122 ~77 dirt
setblock ~169 ~122 ~78 dirt
setblock ~169 ~122 ~79 dirt
setblock ~169 ~122 ~80 dirt
setblock ~169 ~122 ~81 dirt
setblock ~169 ~122 ~82 dirt
setblock ~169 ~122 ~83 dirt
setblock ~169 ~122 ~88 dirt
setblock ~169 ~122 ~89 dirt
setblock ~169 ~122 ~90 dirt
setblock ~169 ~122 ~91 dirt
setblock ~169 ~122 ~92 dirt
setblock ~169 ~122 ~93 dirt
setblock ~169 ~122 ~94 dirt
setblock ~169 ~122 ~95 dirt
setblock ~169 ~122 ~96 dirt
setblock ~169 ~122 ~97 dirt
setblock ~169 ~122 ~98 dirt
setblock ~169 ~122 ~99 dirt
setblock ~169 ~122 ~100 dirt
setblock ~169 ~122 ~101 dirt
setblock ~169 ~122 ~102 dirt
setblock ~169 ~122 ~103 dirt
setblock ~169 ~122 ~104 dirt
setblock ~169 ~122 ~105 dirt
setblock ~169 ~122 ~106 dirt
setblock ~169 ~122 ~107 dirt
setblock ~169 ~122 ~108 dirt
setblock ~169 ~122 ~109 dirt
setblock ~169 ~122 ~110 dirt
setblock ~169 ~122 ~111 dirt
setblock ~169 ~122 ~112 dirt
setblock ~169 ~122 ~113 dirt
setblock ~169 ~122 ~114 dirt
setblock ~169 ~122 ~115 dirt
setblock ~169 ~122 ~116 dirt
setblock ~169 ~122 ~117 dirt
setblock ~169 ~122 ~118 dirt
setblock ~169 ~122 ~119 dirt
setblock ~169 ~122 ~120 dirt
setblock ~169 ~122 ~121 dirt
setblock ~169 ~122 ~122 dirt
setblock ~169 ~122 ~123 dirt
setblock ~169 ~122 ~124 dirt
setblock ~169 ~122 ~125 dirt
setblock ~169 ~122 ~126 dirt
setblock ~169 ~122 ~127 dirt
setblock ~169 ~122 ~128 dirt
setblock ~169 ~122 ~129 dirt
setblock ~169 ~122 ~130 dirt
setblock ~169 ~122 ~131 dirt
setblock ~169 ~122 ~132 dirt
setblock ~169 ~122 ~133 dirt
setblock ~169 ~123 ~71 dirt
setblock ~169 ~123 ~72 dirt
setblock ~169 ~123 ~74 dirt
setblock ~169 ~123 ~75 dirt
setblock ~169 ~123 ~76 dirt
setblock ~169 ~123 ~77 dirt
setblock ~169 ~123 ~78 dirt
setblock ~169 ~123 ~79 dirt
setblock ~169 ~123 ~80 dirt
setblock ~169 ~123 ~81 dirt
setblock ~169 ~123 ~82 dirt
setblock ~169 ~123 ~83 dirt
setblock ~169 ~123 ~88 dirt
setblock ~169 ~123 ~89 dirt
setblock ~169 ~123 ~90 dirt
setblock ~169 ~123 ~91 dirt
setblock ~169 ~123 ~92 dirt
setblock ~169 ~123 ~93 dirt
setblock ~169 ~123 ~94 dirt
setblock ~169 ~123 ~95 dirt
setblock ~169 ~123 ~96 dirt
setblock ~169 ~123 ~97 dirt
setblock ~169 ~123 ~98 dirt
setblock ~169 ~123 ~99 dirt
setblock ~169 ~123 ~100 dirt
setblock ~169 ~123 ~101 dirt
setblock ~169 ~123 ~102 dirt
setblock ~169 ~123 ~103 dirt
setblock ~169 ~123 ~104 dirt
setblock ~169 ~123 ~105 dirt
setblock ~169 ~123 ~106 dirt
setblock ~169 ~123 ~107 dirt
setblock ~169 ~123 ~108 dirt
setblock ~169 ~123 ~109 grass_block
setblock ~169 ~123 ~110 grass_block
setblock ~169 ~123 ~111 grass_block
setblock ~169 ~123 ~112 grass_block
setblock ~169 ~123 ~113 grass_block
setblock ~169 ~123 ~114 grass_block
setblock ~169 ~123 ~115 grass_block
setblock ~169 ~123 ~116 grass_block
setblock ~169 ~123 ~117 grass_block
setblock ~169 ~123 ~118 grass_block
setblock ~169 ~123 ~119 grass_block
setblock ~169 ~123 ~120 grass_block
setblock ~169 ~123 ~121 grass_block
setblock ~169 ~123 ~122 dirt
setblock ~169 ~123 ~123 dirt
setblock ~169 ~123 ~124 dirt
setblock ~169 ~123 ~125 dirt
setblock ~169 ~123 ~126 dirt
setblock ~169 ~123 ~127 dirt
setblock ~169 ~123 ~128 dirt
setblock ~169 ~123 ~129 dirt
setblock ~169 ~123 ~130 dirt
setblock ~169 ~123 ~131 dirt
setblock ~169 ~123 ~132 dirt
setblock ~169 ~123 ~133 dirt
setblock ~169 ~124 ~71 dirt
setblock ~169 ~124 ~72 dirt
setblock ~169 ~124 ~74 dirt
setblock ~169 ~124 ~75 dirt
setblock ~169 ~124 ~76 dirt
setblock ~169 ~124 ~77 dirt
setblock ~169 ~124 ~78 dirt
setblock ~169 ~124 ~79 grass_block
setblock ~169 ~124 ~80 grass_block
setblock ~169 ~124 ~81 grass_block
setblock ~169 ~124 ~82 dirt
setblock ~169 ~124 ~83 dirt
setblock ~169 ~124 ~88 dirt
setblock ~169 ~124 ~89 dirt
setblock ~169 ~124 ~90 dirt
setblock ~169 ~124 ~91 dirt
setblock ~169 ~124 ~92 dirt
setblock ~169 ~124 ~93 dirt
setblock ~169 ~124 ~94 dirt
setblock ~169 ~124 ~95 dirt
setblock ~169 ~124 ~96 dirt
setblock ~169 ~124 ~97 dirt
setblock ~169 ~124 ~98 dirt
setblock ~169 ~124 ~99 dirt
setblock ~169 ~124 ~100 dirt
setblock ~169 ~124 ~101 dirt
setblock ~169 ~124 ~102 dirt
setblock ~169 ~124 ~103 dirt
setblock ~169 ~124 ~104 dirt
setblock ~169 ~124 ~105 dirt
setblock ~169 ~124 ~106 grass_block
setblock ~169 ~124 ~107 grass_block
setblock ~169 ~124 ~108 grass_block
setblock ~169 ~124 ~110 fern
setblock ~169 ~124 ~111 short_grass
setblock ~169 ~124 ~112 short_grass
setblock ~169 ~124 ~113 short_grass
setblock ~169 ~124 ~114 short_grass
setblock ~169 ~124 ~116 poppy
setblock ~169 ~124 ~118 short_grass
setblock ~169 ~124 ~120 fern
setblock ~169 ~124 ~121 fern
setblock ~169 ~124 ~122 grass_block
setblock ~169 ~124 ~123 grass_block
setblock ~169 ~124 ~124 grass_block
setblock ~169 ~124 ~125 dirt
setblock ~169 ~124 ~126 dirt
setblock ~169 ~124 ~127 dirt
setblock ~169 ~124 ~128 dirt
setblock ~169 ~124 ~129 dirt
setblock ~169 ~124 ~130 dirt
setblock ~169 ~124 ~131 dirt
setblock ~169 ~124 ~132 dirt
setblock ~169 ~124 ~133 dirt
setblock ~169 ~125 ~71 dirt
setblock ~169 ~125 ~72 dirt
setblock ~169 ~125 ~74 grass_block
setblock ~169 ~125 ~75 grass_block
setblock ~169 ~125 ~76 grass_block
setblock ~169 ~125 ~77 grass_block
setblock ~169 ~125 ~78 grass_block
setblock ~169 ~125 ~79 fern
setblock ~169 ~125 ~82 grass_block
setblock ~169 ~125 ~83 grass_block
setblock ~169 ~125 ~88 dirt
setblock ~169 ~125 ~89 dirt
setblock ~169 ~125 ~90 dirt
setblock ~169 ~125 ~91 dirt
setblock ~169 ~125 ~92 dirt
setblock ~169 ~125 ~93 dirt
setblock ~169 ~125 ~94 dirt
setblock ~169 ~125 ~95 dirt
setblock ~169 ~125 ~96 dirt
setblock ~169 ~125 ~97 dirt
setblock ~169 ~125 ~98 dirt
setblock ~169 ~125 ~99 dirt
setblock ~169 ~125 ~100 dirt
setblock ~169 ~125 ~101 dirt
setblock ~169 ~125 ~102 grass_block
setblock ~169 ~125 ~103 grass_block
setblock ~169 ~125 ~104 grass_block
setblock ~169 ~125 ~105 grass_block
setblock ~169 ~125 ~125 grass_block
setblock ~169 ~125 ~126 grass_block
setblock ~169 ~125 ~127 grass_block
setblock ~169 ~125 ~128 dirt
setblock ~169 ~125 ~129 dirt
setblock ~169 ~125 ~130 dirt
setblock ~169 ~125 ~131 dirt
setblock ~169 ~125 ~132 dirt
setblock ~169 ~125 ~133 grass_block
setblock ~169 ~126 ~71 grass_block
setblock ~169 ~126 ~72 grass_block
setblock ~169 ~126 ~82 short_grass
setblock ~169 ~126 ~88 dirt
setblock ~169 ~126 ~89 dirt
setblock ~169 ~126 ~90 dirt
setblock ~169 ~126 ~91 dirt
setblock ~169 ~126 ~92 dirt
setblock ~169 ~126 ~93 dirt
setblock ~169 ~126 ~94 dirt
setblock ~169 ~126 ~95 dirt
setblock ~169 ~126 ~96 dirt
setblock ~169 ~126 ~97 grass_block
setblock ~169 ~126 ~98 grass_block
setblock ~169 ~126 ~99 grass_block
setblock ~169 ~126 ~100 grass_block
setblock ~169 ~126 ~101 grass_block
setblock ~169 ~126 ~125 fern
setblock ~169 ~126 ~128 grass_block
setblock ~169 ~126 ~129 dirt
setblock ~169 ~126 ~130 dirt
setblock ~169 ~126 ~131 dirt
setblock ~169 ~126 ~132 grass_block
setblock ~169 ~127 ~88 grass_block
setblock ~169 ~127 ~89 dirt
setblock ~169 ~127 ~90 dirt
setblock ~169 ~127 ~91 dirt
setblock ~169 ~127 ~92 dirt
setblock ~169 ~127 ~93 grass_block
setblock ~169 ~127 ~94 grass_block
setblock ~169 ~127 ~95 grass_block
setblock ~169 ~127 ~96 grass_block
setblock ~169 ~127 ~129 grass_block
setblock ~169 ~127 ~130 grass_block
setblock ~169 ~127 ~131 grass_block
setblock ~169 ~128 ~89 grass_block
setblock ~169 ~128 ~90 dirt
setblock ~169 ~128 ~91 dirt
setblock ~169 ~128 ~92 grass_block
setblock ~169 ~128 ~93 fern
setblock ~169 ~128 ~94 short_grass
setblock ~169 ~128 ~129 short_grass
setblock ~169 ~128 ~131 short_grass
setblock ~169 ~129 ~89 short_grass
setblock ~169 ~129 ~90 dirt
setblock ~169 ~129 ~91 grass_block
setblock ~169 ~130 ~90 grass_block
setblock ~170 ~105 ~100 dirt
setblock ~170 ~106 ~99 dirt
setblock ~170 ~106 ~100 dirt
setblock ~170 ~107 ~99 dirt
setblock ~170 ~107 ~100 dirt
setblock ~170 ~107 ~101 dirt
setblock ~170 ~107 ~102 dirt
setblock ~170 ~107 ~103 dirt
setblock ~170 ~108 ~98 dirt
setblock ~170 ~108 ~99 dirt
setblock ~170 ~108 ~100 dirt
setblock ~170 ~108 ~101 dirt
setblock ~170 ~108 ~102 dirt
setblock ~170 ~108 ~103 dirt
setblock ~170 ~108 ~104 dirt
setblock ~170 ~109 ~97 dirt
setblock ~170 ~109 ~98 dirt
setblock ~170 ~109 ~99 dirt
setblock ~170 ~109 ~100 dirt
setblock ~170 ~109 ~101 dirt
setblock ~170 ~109 ~102 dirt
setblock ~170 ~109 ~103 dirt
setblock ~170 ~109 ~104 dirt
setblock ~170 ~109 ~105 dirt
setblock ~170 ~110 ~97 dirt
setblock ~170 ~110 ~98 dirt
setblock ~170 ~110 ~99 dirt
setblock ~170 ~110 ~100 dirt
setblock ~170 ~110 ~101 dirt
setblock ~170 ~110 ~102 dirt
setblock ~170 ~110 ~103 dirt
setblock ~170 ~110 ~104 dirt
setblock ~170 ~110 ~105 dirt
setblock ~170 ~110 ~120 dirt
setblock ~170 ~111 ~96 dirt
setblock ~170 ~111 ~97 dirt
setblock ~170 ~111 ~98 dirt
setblock ~170 ~111 ~99 dirt
setblock ~170 ~111 ~100 dirt
setblock ~170 ~111 ~101 dirt
setblock ~170 ~111 ~102 dirt
setblock ~170 ~111 ~103 dirt
setblock ~170 ~111 ~104 dirt
setblock ~170 ~111 ~105 dirt
setblock ~170 ~111 ~120 dirt
setblock ~170 ~112 ~95 dirt
setblock ~170 ~112 ~96 dirt
setblock ~170 ~112 ~97 dirt
setblock ~170 ~112 ~98 dirt
setblock ~170 ~112 ~99 dirt
setblock ~170 ~112 ~100 dirt
setblock ~170 ~112 ~101 dirt
setblock ~170 ~112 ~102 dirt
setblock ~170 ~112 ~103 dirt
setblock ~170 ~112 ~104 dirt
setblock ~170 ~112 ~105 dirt
setblock ~170 ~112 ~106 dirt
setblock ~170 ~112 ~119 dirt
setblock ~170 ~112 ~120 dirt
setblock ~170 ~112 ~121 dirt
setblock ~170 ~113 ~95 dirt
setblock ~170 ~113 ~96 dirt
setblock ~170 ~113 ~97 dirt
setblock ~170 ~113 ~98 dirt
setblock ~170 ~113 ~99 dirt
setblock ~170 ~113 ~100 dirt
setblock ~170 ~113 ~101 dirt
setblock ~170 ~113 ~102 dirt
setblock ~170 ~113 ~103 dirt
setblock ~170 ~113 ~104 dirt
setblock ~170 ~113 ~105 dirt
setblock ~170 ~113 ~106 dirt
setblock ~170 ~113 ~107 dirt
setblock ~170 ~113 ~108 dirt
setblock ~170 ~113 ~116 dirt
setblock ~170 ~113 ~118 dirt
setblock ~170 ~113 ~119 dirt
setblock ~170 ~113 ~120 dirt
setblock ~170 ~113 ~121 dirt
setblock ~170 ~114 ~94 dirt
setblock ~170 ~114 ~95 dirt
setblock ~170 ~114 ~96 dirt
setblock ~170 ~114 ~97 dirt
setblock ~170 ~114 ~98 dirt
setblock ~170 ~114 ~99 dirt
setblock ~170 ~114 ~100 dirt
setblock ~170 ~114 ~101 dirt
setblock ~170 ~114 ~102 dirt
setblock ~170 ~114 ~103 dirt
setblock ~170 ~114 ~104 dirt
setblock ~170 ~114 ~105 dirt
setblock ~170 ~114 ~106 dirt
setblock ~170 ~114 ~107 dirt
setblock ~170 ~114 ~108 dirt
setblock ~170 ~114 ~109 dirt
setblock ~170 ~114 ~116 dirt
setblock ~170 ~114 ~118 dirt
setblock ~170 ~114 ~119 dirt
setblock ~170 ~114 ~120 dirt
setblock ~170 ~114 ~121 dirt
setblock ~170 ~114 ~122 dirt
setblock ~170 ~115 ~94 dirt
setblock ~170 ~115 ~95 dirt
setblock ~170 ~115 ~96 dirt
setblock ~170 ~115 ~97 dirt
setblock ~170 ~115 ~98 dirt
setblock ~170 ~115 ~99 dirt
setblock ~170 ~115 ~100 dirt
setblock ~170 ~115 ~101 dirt
setblock ~170 ~115 ~102 dirt
setblock ~170 ~115 ~103 dirt
setblock ~170 ~115 ~104 dirt
setblock ~170 ~115 ~105 dirt
setblock ~170 ~115 ~106 dirt
setblock ~170 ~115 ~107 dirt
setblock ~170 ~115 ~108 dirt
setblock ~170 ~115 ~109 dirt
setblock ~170 ~115 ~110 dirt
setblock ~170 ~115 ~111 dirt
setblock ~170 ~115 ~113 dirt
setblock ~170 ~115 ~115 dirt
setblock ~170 ~115 ~116 dirt
setblock ~170 ~115 ~117 dirt
setblock ~170 ~115 ~118 dirt
setblock ~170 ~115 ~119 dirt
setblock ~170 ~115 ~120 dirt
setblock ~170 ~115 ~121 dirt
setblock ~170 ~115 ~122 dirt
setblock ~170 ~116 ~94 dirt
setblock ~170 ~116 ~95 dirt
setblock ~170 ~116 ~96 dirt
setblock ~170 ~116 ~97 dirt
setblock ~170 ~116 ~98 dirt
setblock ~170 ~116 ~99 dirt
setblock ~170 ~116 ~100 dirt
setblock ~170 ~116 ~101 dirt
setblock ~170 ~116 ~102 dirt
setblock ~170 ~116 ~103 dirt
setblock ~170 ~116 ~104 dirt
setblock ~170 ~116 ~105 dirt
setblock ~170 ~116 ~106 dirt
setblock ~170 ~116 ~107 dirt
setblock ~170 ~116 ~108 dirt
setblock ~170 ~116 ~109 dirt
setblock ~170 ~116 ~110 dirt
setblock ~170 ~116 ~111 dirt
setblock ~170 ~116 ~112 dirt
setblock ~170 ~116 ~113 dirt
setblock ~170 ~116 ~114 dirt
setblock ~170 ~116 ~115 dirt
setblock ~170 ~116 ~116 dirt
setblock ~170 ~116 ~117 dirt
setblock ~170 ~116 ~118 dirt
setblock ~170 ~116 ~119 dirt
setblock ~170 ~116 ~120 dirt
setblock ~170 ~116 ~121 dirt
setblock ~170 ~116 ~122 dirt
setblock ~170 ~116 ~123 dirt
setblock ~170 ~116 ~128 dirt
setblock ~170 ~117 ~94 dirt
setblock ~170 ~117 ~95 dirt
setblock ~170 ~117 ~96 dirt
setblock ~170 ~117 ~97 dirt
setblock ~170 ~117 ~98 dirt
setblock ~170 ~117 ~99 dirt
setblock ~170 ~117 ~100 dirt
setblock ~170 ~117 ~101 dirt
setblock ~170 ~117 ~102 dirt
setblock ~170 ~117 ~103 dirt
setblock ~170 ~117 ~104 dirt
setblock ~170 ~117 ~105 dirt
setblock ~170 ~117 ~106 dirt
setblock ~170 ~117 ~107 dirt
setblock ~170 ~117 ~108 dirt
setblock ~170 ~117 ~109 dirt
setblock ~170 ~117 ~110 dirt
setblock ~170 ~117 ~111 dirt
setblock ~170 ~117 ~112 dirt
setblock ~170 ~117 ~113 dirt
setblock ~170 ~117 ~114 dirt
setblock ~170 ~117 ~115 dirt
setblock ~170 ~117 ~116 dirt
setblock ~170 ~117 ~117 dirt
setblock ~170 ~117 ~118 dirt
setblock ~170 ~117 ~119 dirt
setblock ~170 ~117 ~120 dirt
setblock ~170 ~117 ~121 dirt
setblock ~170 ~117 ~122 dirt
setblock ~170 ~117 ~123 dirt
setblock ~170 ~117 ~124 dirt
setblock ~170 ~117 ~127 dirt
setblock ~170 ~117 ~128 dirt
setblock ~170 ~118 ~93 dirt
setblock ~170 ~118 ~94 dirt
setblock ~170 ~118 ~95 dirt
setblock ~170 ~118 ~96 dirt
setblock ~170 ~118 ~97 dirt
setblock ~170 ~118 ~98 dirt
setblock ~170 ~118 ~99 dirt
setblock ~170 ~118 ~100 dirt
setblock ~170 ~118 ~101 dirt
setblock ~170 ~118 ~102 dirt
setblock ~170 ~118 ~103 dirt
setblock ~170 ~118 ~104 dirt
setblock ~170 ~118 ~105 dirt
setblock ~170 ~118 ~106 dirt
setblock ~170 ~118 ~107 dirt
setblock ~170 ~118 ~108 dirt
setblock ~170 ~118 ~109 dirt
setblock ~170 ~118 ~110 dirt
setblock ~170 ~118 ~111 dirt
setblock ~170 ~118 ~112 dirt
setblock ~170 ~118 ~113 dirt
setblock ~170 ~118 ~114 dirt
setblock ~170 ~118 ~115 dirt
setblock ~170 ~118 ~116 dirt
setblock ~170 ~118 ~117 dirt
setblock ~170 ~118 ~118 dirt
setblock ~170 ~118 ~119 dirt
setblock ~170 ~118 ~120 dirt
setblock ~170 ~118 ~121 dirt
setblock ~170 ~118 ~122 dirt
setblock ~170 ~118 ~123 dirt
setblock ~170 ~118 ~124 dirt
setblock ~170 ~118 ~125 dirt
setblock ~170 ~118 ~126 dirt
setblock ~170 ~118 ~127 dirt
setblock ~170 ~118 ~128 dirt
setblock ~170 ~119 ~79 dirt
setblock ~170 ~119 ~92 dirt
setblock ~170 ~119 ~93 dirt
setblock ~170 ~119 ~94 dirt
setblock ~170 ~119 ~95 dirt
setblock ~170 ~119 ~96 dirt
setblock ~170 ~119 ~97 dirt
setblock ~170 ~119 ~98 dirt
setblock ~170 ~119 ~99 dirt
setblock ~170 ~119 ~100 dirt
setblock ~170 ~119 ~101 dirt
setblock ~170 ~119 ~102 dirt
setblock ~170 ~119 ~103 dirt
setblock ~170 ~119 ~104 dirt
setblock ~170 ~119 ~105 dirt
setblock ~170 ~119 ~106 dirt
setblock ~170 ~119 ~107 dirt
setblock ~170 ~119 ~108 dirt
setblock ~170 ~119 ~109 dirt
setblock ~170 ~119 ~110 dirt
setblock ~170 ~119 ~111 dirt
setblock ~170 ~119 ~112 dirt
setblock ~170 ~119 ~113 dirt
setblock ~170 ~119 ~114 dirt
setblock ~170 ~119 ~115 dirt
setblock ~170 ~119 ~116 dirt
setblock ~170 ~119 ~117 dirt
setblock ~170 ~119 ~118 dirt
setblock ~170 ~119 ~119 dirt
setblock ~170 ~119 ~120 dirt
setblock ~170 ~119 ~121 dirt
setblock ~170 ~119 ~122 dirt
setblock ~170 ~119 ~123 dirt
setblock ~170 ~119 ~124 dirt
setblock ~170 ~119 ~125 dirt
setblock ~170 ~119 ~126 dirt
setblock ~170 ~119 ~127 dirt
setblock ~170 ~119 ~128 dirt
setblock ~170 ~119 ~129 dirt
setblock ~170 ~120 ~79 dirt
setblock ~170 ~120 ~80 dirt
setblock ~170 ~120 ~81 dirt
setblock ~170 ~120 ~91 dirt
setblock ~170 ~120 ~92 dirt
setblock ~170 ~120 ~93 dirt
setblock ~170 ~120 ~94 dirt
setblock ~170 ~120 ~95 dirt
setblock ~170 ~120 ~96 dirt
setblock ~170 ~120 ~97 dirt
setblock ~170 ~120 ~98 dirt
setblock ~170 ~120 ~99 dirt
setblock ~170 ~120 ~100 dirt
setblock ~170 ~120 ~101 dirt
setblock ~170 ~120 ~102 dirt
setblock ~170 ~120 ~103 dirt
setblock ~170 ~120 ~104 dirt
setblock ~170 ~120 ~105 dirt
setblock ~170 ~120 ~106 dirt
setblock ~170 ~120 ~107 dirt
setblock ~170 ~120 ~108 dirt
setblock ~170 ~120 ~109 dirt
setblock ~170 ~120 ~110 dirt
setblock ~170 ~120 ~111 dirt
setblock ~170 ~120 ~112 dirt
setblock ~170 ~120 ~113 dirt
setblock ~170 ~120 ~114 dirt
setblock ~170 ~120 ~115 dirt
setblock ~170 ~120 ~116 dirt
setblock ~170 ~120 ~117 dirt
setblock ~170 ~120 ~118 dirt
setblock ~170 ~120 ~119 dirt
setblock ~170 ~120 ~120 dirt
setblock ~170 ~120 ~121 dirt
setblock ~170 ~120 ~122 dirt
setblock ~170 ~120 ~123 dirt
setblock ~170 ~120 ~124 dirt
setblock ~170 ~120 ~125 dirt
setblock ~170 ~120 ~126 dirt
setblock ~170 ~120 ~127 dirt
setblock ~170 ~120 ~128 dirt
setblock ~170 ~120 ~129 dirt
setblock ~170 ~120 ~130 dirt
setblock ~170 ~121 ~76 dirt
setblock ~170 ~121 ~78 dirt
setblock ~170 ~121 ~79 dirt
setblock ~170 ~121 ~80 dirt
setblock ~170 ~121 ~81 dirt
setblock ~170 ~121 ~82 dirt
setblock ~170 ~121 ~90 dirt
setblock ~170 ~121 ~91 dirt
setblock ~170 ~121 ~92 dirt
setblock ~170 ~121 ~93 dirt
setblock ~170 ~121 ~94 dirt
setblock ~170 ~121 ~95 dirt
setblock ~170 ~121 ~96 dirt
setblock ~170 ~121 ~97 dirt
setblock ~170 ~121 ~98 dirt
setblock ~170 ~121 ~99 dirt
setblock ~170 ~121 ~100 dirt
setblock ~170 ~121 ~101 dirt
setblock ~170 ~121 ~102 dirt
setblock ~170 ~121 ~103 dirt
setblock ~170 ~121 ~104 dirt
setblock ~170 ~121 ~105 dirt
setblock ~170 ~121 ~106 dirt
setblock ~170 ~121 ~107 dirt
setblock ~170 ~121 ~108 dirt
setblock ~170 ~121 ~109 dirt
setblock ~170 ~121 ~110 dirt
setblock ~170 ~121 ~111 dirt
setblock ~170 ~121 ~112 dirt
setblock ~170 ~121 ~113 dirt
setblock ~170 ~121 ~114 dirt
setblock ~170 ~121 ~115 dirt
setblock ~170 ~121 ~116 dirt
setblock ~170 ~121 ~117 dirt
setblock ~170 ~121 ~118 dirt
setblock ~170 ~121 ~119 dirt
setblock ~170 ~121 ~120 dirt
setblock ~170 ~121 ~121 dirt
setblock ~170 ~121 ~122 dirt
setblock ~170 ~121 ~123 dirt
setblock ~170 ~121 ~124 dirt
setblock ~170 ~121 ~125 dirt
setblock ~170 ~121 ~126 dirt
setblock ~170 ~121 ~127 dirt
setblock ~170 ~121 ~128 dirt
setblock ~170 ~121 ~129 dirt
setblock ~170 ~121 ~130 dirt
setblock ~170 ~122 ~76 dirt
setblock ~170 ~122 ~78 dirt
setblock ~170 ~122 ~79 dirt
setblock ~170 ~122 ~80 dirt
setblock ~170 ~122 ~81 dirt
setblock ~170 ~122 ~82 dirt
setblock ~170 ~122 ~90 dirt
setblock ~170 ~122 ~91 dirt
setblock ~170 ~122 ~92 dirt
setblock ~170 ~122 ~93 dirt
setblock ~170 ~122 ~94 dirt
setblock ~170 ~122 ~95 dirt
setblock ~170 ~122 ~96 dirt
setblock ~170 ~122 ~97 dirt
setblock ~170 ~122 ~98 dirt
setblock ~170 ~122 ~99 dirt
setblock ~170 ~122 ~100 dirt
setblock ~170 ~122 ~101 dirt
setblock ~170 ~122 ~102 dirt
setblock ~170 ~122 ~103 dirt
setblock ~170 ~122 ~104 dirt
setblock ~170 ~122 ~105 dirt
setblock ~170 ~122 ~106 dirt
setblock ~170 ~122 ~107 dirt
setblock ~170 ~122 ~108 dirt
setblock ~170 ~122 ~109 dirt
setblock ~170 ~122 ~110 dirt
setblock ~170 ~122 ~111 dirt
setblock ~170 ~122 ~112 dirt
setblock ~170 ~122 ~113 dirt
setblock ~170 ~122 ~114 dirt
setblock ~170 ~122 ~115 dirt
setblock ~170 ~122 ~116 dirt
setblock ~170 ~122 ~117 dirt
setblock ~170 ~122 ~118 dirt
setblock ~170 ~122 ~119 dirt
setblock ~170 ~122 ~120 dirt
setblock ~170 ~122 ~121 dirt
setblock ~170 ~122 ~122 dirt
setblock ~170 ~122 ~123 dirt
setblock ~170 ~122 ~124 dirt
setblock ~170 ~122 ~125 dirt
setblock ~170 ~122 ~126 dirt
setblock ~170 ~122 ~127 dirt
setblock ~170 ~122 ~128 dirt
setblock ~170 ~122 ~129 dirt
setblock ~170 ~122 ~130 dirt
setblock ~170 ~123 ~76 dirt
setblock ~170 ~123 ~78 dirt
setblock ~170 ~123 ~79 dirt
setblock ~170 ~123 ~80 dirt
setblock ~170 ~123 ~81 dirt
setblock ~170 ~123 ~82 dirt
setblock ~170 ~123 ~90 dirt
setblock ~170 ~123 ~91 dirt
setblock ~170 ~123 ~92 dirt
setblock ~170 ~123 ~93 dirt
setblock ~170 ~123 ~94 dirt
setblock ~170 ~123 ~95 dirt
setblock ~170 ~123 ~96 dirt
setblock ~170 ~123 ~97 dirt
setblock ~170 ~123 ~98 dirt
setblock ~170 ~123 ~99 dirt
setblock ~170 ~123 ~100 dirt
setblock ~170 ~123 ~101 dirt
setblock ~170 ~123 ~102 dirt
setblock ~170 ~123 ~103 dirt
setblock ~170 ~123 ~104 dirt
setblock ~170 ~123 ~105 dirt
setblock ~170 ~123 ~106 dirt
setblock ~170 ~123 ~107 dirt
setblock ~170 ~123 ~108 grass_block
setblock ~170 ~123 ~109 grass_block
setblock ~170 ~123 ~110 grass_block
setblock ~170 ~123 ~111 grass_block
setblock ~170 ~123 ~112 grass_block
setblock ~170 ~123 ~113 grass_block
setblock ~170 ~123 ~114 grass_block
setblock ~170 ~123 ~115 grass_block
setblock ~170 ~123 ~116 grass_block
setblock ~170 ~123 ~117 grass_block
setblock ~170 ~123 ~118 grass_block
setblock ~170 ~123 ~119 grass_block
setblock ~170 ~123 ~120 grass_block
setblock ~170 ~123 ~121 grass_block
setblock ~170 ~123 ~122 dirt
setblock ~170 ~123 ~123 dirt
setblock ~170 ~123 ~124 dirt
setblock ~170 ~123 ~125 dirt
setblock ~170 ~123 ~126 dirt
setblock ~170 ~123 ~127 dirt
setblock ~170 ~123 ~128 dirt
setblock ~170 ~123 ~129 dirt
setblock ~170 ~123 ~130 dirt
setblock ~170 ~124 ~76 dirt
setblock ~170 ~124 ~78 dirt
setblock ~170 ~124 ~79 dirt
setblock ~170 ~124 ~80 grass_block
setblock ~170 ~124 ~81 dirt
setblock ~170 ~124 ~82 dirt
setblock ~170 ~124 ~90 dirt
setblock ~170 ~124 ~91 dirt
setblock ~170 ~124 ~92 dirt
setblock ~170 ~124 ~93 dirt
setblock ~170 ~124 ~94 dirt
setblock ~170 ~124 ~95 dirt
setblock ~170 ~124 ~96 dirt
setblock ~170 ~124 ~97 dirt
setblock ~170 ~124 ~98 dirt
setblock ~170 ~124 ~99 dirt
setblock ~170 ~124 ~100 dirt
setblock ~170 ~124 ~101 dirt
setblock ~170 ~124 ~102 dirt
setblock ~170 ~124 ~103 dirt
setblock ~170 ~124 ~104 dirt
setblock ~170 ~124 ~105 grass_block
setblock ~170 ~124 ~106 grass_block
setblock ~170 ~124 ~107 grass_block
setblock ~170 ~124 ~109 poppy
setblock ~170 ~124 ~112 short_grass
setblock ~170 ~124 ~117 short_grass
setblock ~170 ~124 ~122 grass_block
setblock ~170 ~124 ~123 grass_block
setblock ~170 ~124 ~124 grass_block
setblock ~170 ~124 ~125 dirt
setblock ~170 ~124 ~126 dirt
setblock ~170 ~124 ~127 dirt
setblock ~170 ~124 ~128 dirt
setblock ~170 ~124 ~129 dirt
setblock ~170 ~124 ~130 dirt
setblock ~170 ~125 ~76 grass_block
setblock ~170 ~125 ~78 grass_block
setblock ~170 ~125 ~79 grass_block
setblock ~170 ~125 ~81 grass_block
setblock ~170 ~125 ~82 grass_block
setblock ~170 ~125 ~90 dirt
setblock ~170 ~125 ~91 dirt
setblock ~170 ~125 ~92 dirt
setblock ~170 ~125 ~93 dirt
setblock ~170 ~125 ~94 dirt
setblock ~170 ~125 ~95 dirt
setblock ~170 ~125 ~96 dirt
setblock ~170 ~125 ~97 dirt
setblock ~170 ~125 ~98 dirt
setblock ~170 ~125 ~99 dirt
setblock ~170 ~125 ~100 dirt
setblock ~170 ~125 ~101 dirt
setblock ~170 ~125 ~102 grass_block
setblock ~170 ~125 ~103 grass_block
setblock ~170 ~125 ~104 grass_block
setblock ~170 ~125 ~123 fern
setblock ~170 ~125 ~124 short_grass
setblock ~170 ~125 ~125 grass_block
setblock ~170 ~125 ~126 grass_block
setblock ~170 ~125 ~127 dirt
setblock ~170 ~125 ~128 dirt
setblock ~170 ~125 ~129 dirt
setblock ~170 ~125 ~130 dirt
setblock ~170 ~126 ~79 poppy
setblock ~170 ~126 ~90 dirt
setblock ~170 ~126 ~91 dirt
setblock ~170 ~126 ~92 dirt
setblock ~170 ~126 ~93 dirt
setblock ~170 ~126 ~94 dirt
setblock ~170 ~126 ~95 dirt
setblock ~170 ~126 ~96 dirt
setblock ~170 ~126 ~97 grass_block
setblock ~170 ~126 ~98 grass_block
setblock ~170 ~126 ~99 grass_block
setblock ~170 ~126 ~100 grass_block
setblock ~170 ~126 ~101 grass_block
setblock ~170 ~126 ~104 short_grass
setblock ~170 ~126 ~125 poppy
setblock ~170 ~126 ~127 grass_block
setblock ~170 ~126 ~128 grass_block
setblock ~170 ~126 ~129 dirt
setblock ~170 ~126 ~130 dirt
setblock ~170 ~127 ~90 dirt
setblock ~170 ~127 ~91 dirt
setblock ~170 ~127 ~92 dirt
setblock ~170 ~127 ~93 dirt
setblock ~170 ~127 ~94 grass_block
setblock ~170 ~127 ~95 grass_block
setblock ~170 ~127 ~96 grass_block
setblock ~170 ~127 ~98 short_grass
setblock ~170 ~127 ~99 short_grass
setblock ~170 ~127 ~128 short_grass
setblock ~170 ~127 ~129 grass_block
setblock ~170 ~127 ~130 dirt
setblock ~170 ~128 ~90 dirt
setblock ~170 ~128 ~91 dirt
setblock ~170 ~128 ~92 grass_block
setblock ~170 ~128 ~93 grass_block
setblock ~170 ~128 ~130 grass_block
setblock ~170 ~129 ~90 dirt
setblock ~170 ~129 ~91 grass_block
setblock ~170 ~129 ~92 short_grass
setblock ~170 ~130 ~90 grass_block
setblock ~171 ~108 ~102 dirt
setblock ~171 ~108 ~103 dirt
setblock ~171 ~109 ~99 dirt
setblock ~171 ~109 ~100 dirt
setblock ~171 ~109 ~101 dirt
setblock ~171 ~109 ~102 dirt
setblock ~171 ~109 ~103 dirt
setblock ~171 ~109 ~104 dirt
setblock ~171 ~110 ~99 dirt
setblock ~171 ~110 ~100 dirt
setblock ~171 ~110 ~101 dirt
setblock ~171 ~110 ~102 dirt
setblock ~171 ~110 ~103 dirt
setblock ~171 ~110 ~104 dirt
setblock ~171 ~111 ~97 dirt
setblock ~171 ~111 ~98 dirt
setblock ~171 ~111 ~99 dirt
setblock ~171 ~111 ~100 dirt
setblock ~171 ~111 ~101 dirt
setblock ~171 ~111 ~102 dirt
setblock ~171 ~111 ~103 dirt
setblock ~171 ~111 ~104 dirt
setblock ~171 ~112 ~96 dirt
setblock ~171 ~112 ~97 dirt
setblock ~171 ~112 ~98 dirt
setblock ~171 ~112 ~99 dirt
setblock ~171 ~112 ~100 dirt
setblock ~171 ~112 ~101 dirt
setblock ~171 ~112 ~102 dirt
setblock ~171 ~112 ~103 dirt
setblock ~171 ~112 ~104 dirt
setblock ~171 ~112 ~105 dirt
setblock ~171 ~113 ~96 dirt
setblock ~171 ~113 ~97 dirt
setblock ~171 ~113 ~98 dirt
setblock ~171 ~113 ~99 dirt
setblock ~171 ~113 ~100 dirt
setblock ~171 ~113 ~101 dirt
setblock ~171 ~113 ~102 dirt
setblock ~171 ~113 ~103 dirt
setblock ~171 ~113 ~104 dirt
setblock ~171 ~113 ~105 dirt
setblock ~171 ~113 ~106 dirt
setblock ~171 ~114 ~95 dirt
setblock ~171 ~114 ~96 dirt
setblock ~171 ~114 ~97 dirt
setblock ~171 ~114 ~98 dirt
setblock ~171 ~114 ~99 dirt
setblock ~171 ~114 ~100 dirt
setblock ~171 ~114 ~101 dirt
setblock ~171 ~114 ~102 dirt
setblock ~171 ~114 ~103 dirt
setblock ~171 ~114 ~104 dirt
setblock ~171 ~114 ~105 dirt
setblock ~171 ~114 ~106 dirt
setblock ~171 ~114 ~108 dirt
setblock ~171 ~114 ~120 dirt
setblock ~171 ~114 ~121 dirt
setblock ~171 ~115 ~94 dirt
setblock ~171 ~115 ~95 dirt
setblock ~171 ~115 ~96 dirt
setblock ~171 ~115 ~97 dirt
setblock ~171 ~115 ~98 dirt
setblock ~171 ~115 ~99 dirt
setblock ~171 ~115 ~100 dirt
setblock ~171 ~115 ~101 dirt
setblock ~171 ~115 ~102 dirt
setblock ~171 ~115 ~103 dirt
setblock ~171 ~115 ~104 dirt
setblock ~171 ~115 ~105 dirt
setblock ~171 ~115 ~106 dirt
setblock ~171 ~115 ~107 dirt
setblock ~171 ~115 ~108 dirt
setblock ~171 ~115 ~109 dirt
setblock ~171 ~115 ~118 dirt
setblock ~171 ~115 ~119 dirt
setblock ~171 ~115 ~120 dirt
setblock ~171 ~115 ~121 dirt
setblock ~171 ~116 ~94 dirt
setblock ~171 ~116 ~95 dirt
setblock ~171 ~116 ~96 dirt
setblock ~171 ~116 ~97 dirt
setblock ~171 ~116 ~98 dirt
setblock ~171 ~116 ~99 dirt
setblock ~171 ~116 ~100 dirt
setblock ~171 ~116 ~101 dirt
setblock ~171 ~116 ~102 dirt
setblock ~171 ~116 ~103 dirt
setblock ~171 ~116 ~104 dirt
setblock ~171 ~116 ~105 dirt
setblock ~171 ~116 ~106 dirt
setblock ~171 ~116 ~107 dirt
setblock ~171 ~116 ~108 dirt
setblock ~171 ~116 ~109 dirt
setblock ~171 ~116 ~111 dirt
setblock ~171 ~116 ~116 dirt
setblock ~171 ~116 ~117 dirt
setblock ~171 ~116 ~118 dirt
setblock ~171 ~116 ~119 dirt
setblock ~171 ~116 ~120 dirt
setblock ~171 ~116 ~121 dirt
setblock ~171 ~116 ~122 dirt
setblock ~171 ~117 ~94 dirt
setblock ~171 ~117 ~95 dirt
setblock ~171 ~117 ~96 dirt
setblock ~171 ~117 ~97 dirt
setblock ~171 ~117 ~98 dirt
setblock ~171 ~117 ~99 dirt
setblock ~171 ~117 ~100 dirt
setblock ~171 ~117 ~101 dirt
setblock ~171 ~117 ~102 dirt
setblock ~171 ~117 ~103 dirt
setblock ~171 ~117 ~104 dirt
setblock ~171 ~117 ~105 dirt
setblock ~171 ~117 ~106 dirt
setblock ~171 ~117 ~107 dirt
setblock ~171 ~117 ~108 dirt
setblock ~171 ~117 ~109 dirt
setblock ~171 ~117 ~110 dirt
setblock ~171 ~117 ~111 dirt
setblock ~171 ~117 ~112 dirt
setblock ~171 ~117 ~114 dirt
setblock ~171 ~117 ~116 dirt
setblock ~171 ~117 ~117 dirt
setblock ~171 ~117 ~118 dirt
setblock ~171 ~117 ~119 dirt
setblock ~171 ~117 ~120 dirt
setblock ~171 ~117 ~121 dirt
setblock ~171 ~117 ~122 dirt
setblock ~171 ~118 ~93 dirt
setblock ~171 ~118 ~94 dirt
setblock ~171 ~118 ~95 dirt
setblock ~171 ~118 ~96 dirt
setblock ~171 ~118 ~97 dirt
setblock ~171 ~118 ~98 dirt
setblock ~171 ~118 ~99 dirt
setblock ~171 ~118 ~100 dirt
setblock ~171 ~118 ~101 dirt
setblock ~171 ~118 ~102 dirt
setblock ~171 ~118 ~103 dirt
setblock ~171 ~118 ~104 dirt
setblock ~171 ~118 ~105 dirt
setblock ~171 ~118 ~106 dirt
setblock ~171 ~118 ~107 dirt
setblock ~171 ~118 ~108 dirt
setblock ~171 ~118 ~109 dirt
setblock ~171 ~118 ~110 dirt
setblock ~171 ~118 ~111 dirt
setblock ~171 ~118 ~112 dirt
setblock ~171 ~118 ~114 dirt
setblock ~171 ~118 ~115 dirt
setblock ~171 ~118 ~116 dirt
setblock ~171 ~118 ~117 dirt
setblock ~171 ~118 ~118 dirt
setblock ~171 ~118 ~119 dirt
setblock ~171 ~118 ~120 dirt
setblock ~171 ~118 ~121 dirt
setblock ~171 ~118 ~122 dirt
setblock ~171 ~118 ~123 dirt
setblock ~171 ~118 ~124 dirt
setblock ~171 ~118 ~127 dirt
setblock ~171 ~119 ~92 dirt
setblock ~171 ~119 ~93 dirt
setblock ~171 ~119 ~94 dirt
setblock ~171 ~119 ~95 dirt
setblock ~171 ~119 ~96 dirt
setblock ~171 ~119 ~97 dirt
setblock ~171 ~119 ~98 dirt
setblock ~171 ~119 ~99 dirt
setblock ~171 ~119 ~100 dirt
setblock ~171 ~119 ~101 dirt
setblock ~171 ~119 ~102 dirt
setblock ~171 ~119 ~103 dirt
setblock ~171 ~119 ~104 dirt
setblock ~171 ~119 ~105 dirt
setblock ~171 ~119 ~106 dirt
setblock ~171 ~119 ~107 dirt
setblock ~171 ~119 ~108 dirt
setblock ~171 ~119 ~109 dirt
setblock ~171 ~119 ~110 dirt
setblock ~171 ~119 ~111 dirt
setblock ~171 ~119 ~112 dirt
setblock ~171 ~119 ~113 dirt
setblock ~171 ~119 ~114 dirt
setblock ~171 ~119 ~115 dirt
setblock ~171 ~119 ~116 dirt
setblock ~171 ~119 ~117 dirt
setblock ~171 ~119 ~118 dirt
setblock ~171 ~119 ~119 dirt
setblock ~171 ~119 ~120 dirt
setblock ~171 ~119 ~121 dirt
setblock ~171 ~119 ~122 dirt
setblock ~171 ~119 ~123 dirt
setblock ~171 ~119 ~124 dirt
setblock ~171 ~119 ~125 dirt
setblock ~171 ~119 ~126 dirt
setblock ~171 ~119 ~127 dirt
setblock ~171 ~119 ~128 dirt
setblock ~171 ~120 ~92 dirt
setblock ~171 ~120 ~93 dirt
setblock ~171 ~120 ~94 dirt
setblock ~171 ~120 ~95 dirt
setblock ~171 ~120 ~96 dirt
setblock ~171 ~120 ~97 dirt
setblock ~171 ~120 ~98 dirt
setblock ~171 ~120 ~99 dirt
setblock ~171 ~120 ~100 dirt
setblock ~171 ~120 ~101 dirt
setblock ~171 ~120 ~102 dirt
setblock ~171 ~120 ~103 dirt
setblock ~171 ~120 ~104 dirt
setblock ~171 ~120 ~105 dirt
setblock ~171 ~120 ~106 dirt
setblock ~171 ~120 ~107 dirt
setblock ~171 ~120 ~108 dirt
setblock ~171 ~120 ~109 dirt
setblock ~171 ~120 ~110 dirt
setblock ~171 ~120 ~111 dirt
setblock ~171 ~120 ~112 dirt
setblock ~171 ~120 ~113 dirt
setblock ~171 ~120 ~114 dirt
setblock ~171 ~120 ~115 dirt
setblock ~171 ~120 ~116 dirt
setblock ~171 ~120 ~117 dirt
setblock ~171 ~120 ~118 dirt
setblock ~171 ~120 ~119 dirt
setblock ~171 ~120 ~120 dirt
setblock ~171 ~120 ~121 dirt
setblock ~171 ~120 ~122 dirt
setblock ~171 ~120 ~123 dirt
setblock ~171 ~120 ~124 dirt
setblock ~171 ~120 ~125 dirt
setblock ~171 ~120 ~126 dirt
setblock ~171 ~120 ~127 dirt
setblock ~171 ~120 ~128 dirt
setblock ~171 ~120 ~129 dirt
setblock ~171 ~121 ~92 dirt
setblock ~171 ~121 ~93 dirt
setblock ~171 ~121 ~94 dirt
setblock ~171 ~121 ~95 dirt
setblock ~171 ~121 ~96 dirt
setblock ~171 ~121 ~97 dirt
setblock ~171 ~121 ~98 dirt
setblock ~171 ~121 ~99 dirt
setblock ~171 ~121 ~100 dirt
setblock ~171 ~121 ~101 dirt
setblock ~171 ~121 ~102 dirt
setblock ~171 ~121 ~103 dirt
setblock ~171 ~121 ~104 dirt
setblock ~171 ~121 ~105 dirt
setblock ~171 ~121 ~106 dirt
setblock ~171 ~121 ~107 dirt
setblock ~171 ~121 ~108 dirt
setblock ~171 ~121 ~109 dirt
setblock ~171 ~121 ~110 dirt
setblock ~171 ~121 ~111 dirt
setblock ~171 ~121 ~112 dirt
setblock ~171 ~121 ~113 dirt
setblock ~171 ~121 ~114 dirt
setblock ~171 ~121 ~115 dirt
setblock ~171 ~121 ~116 dirt
setblock ~171 ~121 ~117 dirt
setblock ~171 ~121 ~118 dirt
setblock ~171 ~121 ~119 dirt
setblock ~171 ~121 ~120 dirt
setblock ~171 ~121 ~121 dirt
setblock ~171 ~121 ~122 dirt
setblock ~171 ~121 ~123 dirt
setblock ~171 ~121 ~124 dirt
setblock ~171 ~121 ~125 dirt
setblock ~171 ~121 ~126 dirt
setblock ~171 ~121 ~127 dirt
setblock ~171 ~121 ~128 dirt
setblock ~171 ~121 ~129 dirt
setblock ~171 ~122 ~92 dirt
setblock ~171 ~122 ~93 dirt
setblock ~171 ~122 ~94 dirt
setblock ~171 ~122 ~95 dirt
setblock ~171 ~122 ~96 dirt
setblock ~171 ~122 ~97 dirt
setblock ~171 ~122 ~98 dirt
setblock ~171 ~122 ~99 dirt
setblock ~171 ~122 ~100 dirt
setblock ~171 ~122 ~101 dirt
setblock ~171 ~122 ~102 dirt
setblock ~171 ~122 ~103 dirt
setblock ~171 ~122 ~104 dirt
setblock ~171 ~122 ~105 dirt
setblock ~171 ~122 ~106 dirt
setblock ~171 ~122 ~107 dirt
setblock ~171 ~122 ~108 dirt
setblock ~171 ~122 ~109 dirt
setblock ~171 ~122 ~110 dirt
setblock ~171 ~122 ~111 dirt
setblock ~171 ~122 ~112 dirt
setblock ~171 ~122 ~113 dirt
setblock ~171 ~122 ~114 dirt
setblock ~171 ~122 ~115 dirt
setblock ~171 ~122 ~116 dirt
setblock ~171 ~122 ~117 dirt
setblock ~171 ~122 ~118 dirt
setblock ~171 ~122 ~119 dirt
setblock ~171 ~122 ~120 dirt
setblock ~171 ~122 ~121 dirt
setblock ~171 ~122 ~122 dirt
setblock ~171 ~122 ~123 dirt
setblock ~171 ~122 ~124 dirt
setblock ~171 ~122 ~125 dirt
setblock ~171 ~122 ~126 dirt
setblock ~171 ~122 ~127 dirt
setblock ~171 ~122 ~128 dirt
setblock ~171 ~122 ~129 dirt
setblock ~171 ~123 ~92 dirt
setblock ~171 ~123 ~93 dirt
setblock ~171 ~123 ~94 dirt
setblock ~171 ~123 ~95 dirt
setblock ~171 ~123 ~96 dirt
setblock ~171 ~123 ~97 dirt
setblock ~171 ~123 ~98 dirt
setblock ~171 ~123 ~99 dirt
setblock ~171 ~123 ~100 dirt
setblock ~171 ~123 ~101 dirt
setblock ~171 ~123 ~102 dirt
setblock ~171 ~123 ~103 dirt
setblock ~171 ~123 ~104 dirt
setblock ~171 ~123 ~105 dirt
setblock ~171 ~123 ~106 dirt
setblock ~171 ~123 ~107 dirt
setblock ~171 ~123 ~108 grass_block
setblock ~171 ~123 ~109 grass_block
setblock ~171 ~123 ~110 grass_block
setblock ~171 ~123 ~111 grass_block
setblock ~171 ~123 ~112 grass_block
setblock ~171 ~123 ~113 grass_block
setblock ~171 ~123 ~114 grass_block
setblock ~171 ~123 ~115 grass_block
setblock ~171 ~123 ~116 grass_block
setblock ~171 ~123 ~117 grass_block
setblock ~171 ~123 ~118 grass_block
setblock ~171 ~123 ~119 grass_block
setblock ~171 ~123 ~120 grass_block
setblock ~171 ~123 ~121 dirt
setblock ~171 ~123 ~122 dirt
setblock ~171 ~123 ~123 dirt
setblock ~171 ~123 ~124 dirt
setblock ~171 ~123 ~125 dirt
setblock ~171 ~123 ~126 dirt
setblock ~171 ~123 ~127 dirt
setblock ~171 ~123 ~128 dirt
setblock ~171 ~123 ~129 dirt
setblock ~171 ~124 ~92 dirt
setblock ~171 ~124 ~93 dirt
setblock ~171 ~124 ~94 dirt
setblock ~171 ~124 ~95 dirt
setblock ~171 ~124 ~96 dirt
setblock ~171 ~124 ~97 dirt
setblock ~171 ~124 ~98 dirt
setblock ~171 ~124 ~99 dirt
setblock ~171 ~124 ~100 dirt
setblock ~171 ~124 ~101 dirt
setblock ~171 ~124 ~102 dirt
setblock ~171 ~124 ~103 dirt
setblock ~171 ~124 ~104 dirt
setblock ~171 ~124 ~105 grass_block
setblock ~171 ~124 ~106 grass_block
setblock ~171 ~124 ~107 grass_block
setblock ~171 ~124 ~108 short_grass
setblock ~171 ~124 ~109 short_grass
setblock ~171 ~124 ~114 short_grass
setblock ~171 ~124 ~116 short_grass
setblock ~171 ~124 ~117 short_grass
setblock ~171 ~124 ~121 grass_block
setblock ~171 ~124 ~122 grass_block
setblock ~171 ~124 ~123 grass_block
setblock ~171 ~124 ~124 dirt
setblock ~171 ~124 ~125 dirt
setblock ~171 ~124 ~126 dirt
setblock ~171 ~124 ~127 dirt
setblock ~171 ~124 ~128 dirt
setblock ~171 ~124 ~129 dirt
setblock ~171 ~125 ~92 dirt
setblock ~171 ~125 ~93 dirt
setblock ~171 ~125 ~94 dirt
setblock ~171 ~125 ~95 dirt
setblock ~171 ~125 ~96 dirt
setblock ~171 ~125 ~97 dirt
setblock ~171 ~125 ~98 dirt
setblock ~171 ~125 ~99 dirt
setblock ~171 ~125 ~100 dirt
setblock ~171 ~125 ~101 dirt
setblock ~171 ~125 ~102 grass_block
setblock ~171 ~125 ~103 grass_block
setblock ~171 ~125 ~104 grass_block
setblock ~171 ~125 ~106 short_grass
setblock ~171 ~125 ~121 short_grass
setblock ~171 ~125 ~124 grass_block
setblock ~171 ~125 ~125 grass_block
setblock ~171 ~125 ~126 grass_block
setblock ~171 ~125 ~127 dirt
setblock ~171 ~125 ~128 dirt
setblock ~171 ~125 ~129 dirt
setblock ~171 ~126 ~92 dirt
setblock ~171 ~126 ~93 dirt
setblock ~171 ~126 ~94 dirt
setblock ~171 ~126 ~95 dirt
setblock ~171 ~126 ~96 grass_block
setblock ~171 ~126 ~97 grass_block
setblock ~171 ~126 ~98 grass_block
setblock ~171 ~126 ~99 grass_block
setblock ~171 ~126 ~100 grass_block
setblock ~171 ~126 ~101 grass_block
setblock ~171 ~126 ~102 short_grass
setblock ~171 ~126 ~104 poppy
setblock ~171 ~126 ~127 grass_block
setblock ~171 ~126 ~128 dirt
setblock ~171 ~126 ~129 dirt
setblock ~171 ~127 ~92 dirt
setblock ~171 ~127 ~93 grass_block
setblock ~171 ~127 ~94 grass_block
setblock ~171 ~127 ~95 grass_block
setblock ~171 ~127 ~96 short_grass
setblock ~171 ~127 ~100 fern
setblock ~171 ~127 ~128 grass_block
setblock ~171 ~127 ~129 grass_block
setblock ~171 ~128 ~92 grass_block
setblock ~171 ~128 ~93 fern
setblock ~172 ~109 ~102 dirt
setblock ~172 ~110 ~100 dirt
setblock ~172 ~110 ~101 dirt
setblock ~172 ~110 ~102 dirt
setblock ~172 ~110 ~103 dirt
setblock ~172 ~111 ~100 dirt
setblock ~172 ~111 ~101 dirt
setblock ~172 ~111 ~102 dirt
setblock ~172 ~111 ~103 dirt
setblock ~172 ~112 ~98 dirt
setblock ~172 ~112 ~100 dirt
setblock ~172 ~112 ~101 dirt
setblock ~172 ~112 ~102 dirt
setblock ~172 ~112 ~103 dirt
setblock ~172 ~112 ~104 dirt
setblock ~172 ~113 ~97 dirt
setblock ~172 ~113 ~98 dirt
setblock ~172 ~113 ~99 dirt
setblock ~172 ~113 ~100 dirt
setblock ~172 ~113 ~101 dirt
setblock ~172 ~113 ~102 dirt
setblock ~172 ~113 ~103 dirt
setblock ~172 ~113 ~104 dirt
setblock ~172 ~113 ~105 dirt
setblock ~172 ~114 ~96 dirt
setblock ~172 ~114 ~97 dirt
setblock ~172 ~114 ~98 dirt
setblock ~172 ~114 ~99 dirt
setblock ~172 ~114 ~100 dirt
setblock ~172 ~114 ~101 dirt
setblock ~172 ~114 ~102 dirt
setblock ~172 ~114 ~103 dirt
setblock ~172 ~114 ~104 dirt
setblock ~172 ~114 ~105 dirt
setblock ~172 ~115 ~95 dirt
setblock ~172 ~115 ~96 dirt
setblock ~172 ~115 ~97 dirt
setblock ~172 ~115 ~98 dirt
setblock ~172 ~115 ~99 dirt
setblock ~172 ~115 ~100 dirt
setblock ~172 ~115 ~101 dirt
setblock ~172 ~115 ~102 dirt
setblock ~172 ~115 ~103 dirt
setblock ~172 ~115 ~104 dirt
setblock ~172 ~115 ~105 dirt
setblock ~172 ~116 ~95 dirt
setblock ~172 ~116 ~96 dirt
setblock ~172 ~116 ~97 dirt
setblock ~172 ~116 ~98 dirt
setblock ~172 ~116 ~99 dirt
setblock ~172 ~116 ~100 dirt
setblock ~172 ~116 ~101 dirt
setblock ~172 ~116 ~102 dirt
setblock ~172 ~116 ~103 dirt
setblock ~172 ~116 ~104 dirt
setblock ~172 ~116 ~105 dirt
setblock ~172 ~116 ~106 dirt
setblock ~172 ~116 ~118 dirt
setblock ~172 ~116 ~120 dirt
setblock ~172 ~116 ~121 dirt
setblock ~172 ~117 ~94 dirt
setblock ~172 ~117 ~95 dirt
setblock ~172 ~117 ~96 dirt
setblock ~172 ~117 ~97 dirt
setblock ~172 ~117 ~98 dirt
setblock ~172 ~117 ~99 dirt
setblock ~172 ~117 ~100 dirt
setblock ~172 ~117 ~101 dirt
setblock ~172 ~117 ~102 dirt
setblock ~172 ~117 ~103 dirt
setblock ~172 ~117 ~104 dirt
setblock ~172 ~117 ~105 dirt
setblock ~172 ~117 ~106 dirt
setblock ~172 ~117 ~108 dirt
setblock ~172 ~117 ~118 dirt
setblock ~172 ~117 ~120 dirt
setblock ~172 ~117 ~121 dirt
setblock ~172 ~117 ~122 dirt
setblock ~172 ~118 ~94 dirt
setblock ~172 ~118 ~95 dirt
setblock ~172 ~118 ~96 dirt
setblock ~172 ~118 ~97 dirt
setblock ~172 ~118 ~98 dirt
setblock ~172 ~118 ~99 dirt
setblock ~172 ~118 ~100 dirt
setblock ~172 ~118 ~101 dirt
setblock ~172 ~118 ~102 dirt
setblock ~172 ~118 ~103 dirt
setblock ~172 ~118 ~104 dirt
setblock ~172 ~118 ~105 dirt
setblock ~172 ~118 ~106 dirt
setblock ~172 ~118 ~107 dirt
setblock ~172 ~118 ~108 dirt
setblock ~172 ~118 ~109 dirt
setblock ~172 ~118 ~117 dirt
setblock ~172 ~118 ~118 dirt
setblock ~172 ~118 ~119 dirt
setblock ~172 ~118 ~120 dirt
setblock ~172 ~118 ~121 dirt
setblock ~172 ~118 ~122 dirt
setblock ~172 ~118 ~123 dirt
setblock ~172 ~119 ~93 dirt
setblock ~172 ~119 ~94 dirt
setblock ~172 ~119 ~95 dirt
setblock ~172 ~119 ~96 dirt
setblock ~172 ~119 ~97 dirt
setblock ~172 ~119 ~98 dirt
setblock ~172 ~119 ~99 dirt
setblock ~172 ~119 ~100 dirt
setblock ~172 ~119 ~101 dirt
setblock ~172 ~119 ~102 dirt
setblock ~172 ~119 ~103 dirt
setblock ~172 ~119 ~104 dirt
setblock ~172 ~119 ~105 dirt
setblock ~172 ~119 ~106 dirt
setblock ~172 ~119 ~107 dirt
setblock ~172 ~119 ~108 dirt
setblock ~172 ~119 ~109 dirt
setblock ~172 ~119 ~110 dirt
setblock ~172 ~119 ~111 dirt
setblock ~172 ~119 ~112 dirt
setblock ~172 ~119 ~114 dirt
setblock ~172 ~119 ~116 dirt
setblock ~172 ~119 ~117 dirt
setblock ~172 ~119 ~118 dirt
setblock ~172 ~119 ~119 dirt
setblock ~172 ~119 ~120 dirt
setblock ~172 ~119 ~121 dirt
setblock ~172 ~119 ~122 dirt
setblock ~172 ~119 ~123 dirt
setblock ~172 ~119 ~124 dirt
setblock ~172 ~119 ~127 dirt
setblock ~172 ~120 ~93 dirt
setblock ~172 ~120 ~94 dirt
setblock ~172 ~120 ~95 dirt
setblock ~172 ~120 ~96 dirt
setblock ~172 ~120 ~97 dirt
setblock ~172 ~120 ~98 dirt
setblock ~172 ~120 ~99 dirt
setblock ~172 ~120 ~100 dirt
setblock ~172 ~120 ~101 dirt
setblock ~172 ~120 ~102 dirt
setblock ~172 ~120 ~103 dirt
setblock ~172 ~120 ~104 dirt
setblock ~172 ~120 ~105 dirt
setblock ~172 ~120 ~106 dirt
setblock ~172 ~120 ~107 dirt
setblock ~172 ~120 ~108 dirt
setblock ~172 ~120 ~109 dirt
setblock ~172 ~120 ~110 dirt
setblock ~172 ~120 ~111 dirt
setblock ~172 ~120 ~112 dirt
setblock ~172 ~120 ~113 dirt
setblock ~172 ~120 ~114 dirt
setblock ~172 ~120 ~115 dirt
setblock ~172 ~120 ~116 dirt
setblock ~172 ~120 ~117 dirt
