setblock ~162 ~116 ~90 dirt
setblock ~162 ~116 ~91 dirt
setblock ~162 ~116 ~92 dirt
setblock ~162 ~116 ~93 dirt
setblock ~162 ~116 ~94 dirt
setblock ~162 ~116 ~95 dirt
setblock ~162 ~116 ~96 dirt
setblock ~162 ~116 ~97 dirt
setblock ~162 ~116 ~98 dirt
setblock ~162 ~116 ~99 dirt
setblock ~162 ~116 ~100 dirt
setblock ~162 ~116 ~101 dirt
setblock ~162 ~116 ~102 dirt
setblock ~162 ~116 ~103 dirt
setblock ~162 ~116 ~104 dirt
setblock ~162 ~116 ~105 dirt
setblock ~162 ~116 ~106 dirt
setblock ~162 ~116 ~107 dirt
setblock ~162 ~116 ~108 dirt
setblock ~162 ~116 ~109 dirt
setblock ~162 ~116 ~110 dirt
setblock ~162 ~116 ~111 dirt
setblock ~162 ~116 ~112 dirt
setblock ~162 ~116 ~113 dirt
setblock ~162 ~116 ~114 dirt
setblock ~162 ~116 ~115 dirt
setblock ~162 ~116 ~116 dirt
setblock ~162 ~116 ~117 dirt
setblock ~162 ~116 ~118 dirt
setblock ~162 ~116 ~119 dirt
setblock ~162 ~116 ~120 dirt
setblock ~162 ~116 ~121 dirt
setblock ~162 ~116 ~122 dirt
setblock ~162 ~116 ~123 dirt
setblock ~162 ~116 ~124 dirt
setblock ~162 ~116 ~125 dirt
setblock ~162 ~116 ~126 dirt
setblock ~162 ~116 ~127 dirt
setblock ~162 ~116 ~128 dirt
setblock ~162 ~116 ~129 dirt
setblock ~162 ~117 ~76 dirt
setblock ~162 ~117 ~80 dirt
setblock ~162 ~117 ~81 dirt
setblock ~162 ~117 ~82 dirt
setblock ~162 ~117 ~83 dirt
setblock ~162 ~117 ~84 dirt
setblock ~162 ~117 ~85 dirt
setblock ~162 ~117 ~86 dirt
setblock ~162 ~117 ~87 dirt
setblock ~162 ~117 ~88 dirt
setblock ~162 ~117 ~89 dirt
setblock ~162 ~117 ~90 dirt
setblock ~162 ~117 ~91 dirt
setblock ~162 ~117 ~92 dirt
setblock ~162 ~117 ~93 dirt
setblock ~162 ~117 ~94 dirt
setblock ~162 ~117 ~95 dirt
setblock ~162 ~117 ~96 dirt
setblock ~162 ~117 ~97 dirt
setblock ~162 ~117 ~98 dirt
setblock ~162 ~117 ~99 dirt
setblock ~162 ~117 ~100 dirt
setblock ~162 ~117 ~101 dirt
setblock ~162 ~117 ~102 dirt
setblock ~162 ~117 ~103 dirt
setblock ~162 ~117 ~104 dirt
setblock ~162 ~117 ~105 dirt
setblock ~162 ~117 ~106 dirt
setblock ~162 ~117 ~107 dirt
setblock ~162 ~117 ~108 dirt
setblock ~162 ~117 ~109 dirt
setblock ~162 ~117 ~110 dirt
setblock ~162 ~117 ~111 dirt
setblock ~162 ~117 ~112 dirt
setblock ~162 ~117 ~113 dirt
setblock ~162 ~117 ~114 dirt
setblock ~162 ~117 ~115 dirt
setblock ~162 ~117 ~116 dirt
setblock ~162 ~117 ~117 dirt
setblock ~162 ~117 ~118 dirt
setblock ~162 ~117 ~119 dirt
setblock ~162 ~117 ~120 dirt
setblock ~162 ~117 ~121 dirt
setblock ~162 ~117 ~122 dirt
setblock ~162 ~117 ~123 dirt
setblock ~162 ~117 ~124 dirt
setblock ~162 ~117 ~125 dirt
setblock ~162 ~117 ~126 dirt
setblock ~162 ~117 ~127 dirt
setblock ~162 ~117 ~128 dirt
setblock ~162 ~117 ~129 dirt
setblock ~162 ~117 ~130 dirt
setblock ~162 ~118 ~76 dirt
setblock ~162 ~118 ~79 dirt
setblock ~162 ~118 ~80 dirt
setblock ~162 ~118 ~81 dirt
setblock ~162 ~118 ~82 dirt
setblock ~162 ~118 ~83 dirt
setblock ~162 ~118 ~84 dirt
setblock ~162 ~118 ~85 dirt
setblock ~162 ~118 ~86 dirt
setblock ~162 ~118 ~87 dirt
setblock ~162 ~118 ~88 dirt
setblock ~162 ~118 ~89 dirt
setblock ~162 ~118 ~90 dirt
setblock ~162 ~118 ~91 dirt
setblock ~162 ~118 ~92 dirt
setblock ~162 ~118 ~93 dirt
setblock ~162 ~118 ~94 dirt
setblock ~162 ~118 ~95 dirt
setblock ~162 ~118 ~96 dirt
setblock ~162 ~118 ~97 dirt
setblock ~162 ~118 ~98 dirt
setblock ~162 ~118 ~99 dirt
setblock ~162 ~118 ~100 dirt
setblock ~162 ~118 ~101 dirt
setblock ~162 ~118 ~102 dirt
setblock ~162 ~118 ~103 dirt
setblock ~162 ~118 ~104 dirt
setblock ~162 ~118 ~105 dirt
setblock ~162 ~118 ~106 dirt
setblock ~162 ~118 ~107 dirt
setblock ~162 ~118 ~108 dirt
setblock ~162 ~118 ~109 dirt
setblock ~162 ~118 ~110 dirt
setblock ~162 ~118 ~111 dirt
setblock ~162 ~118 ~112 dirt
setblock ~162 ~118 ~113 dirt
setblock ~162 ~118 ~114 dirt
setblock ~162 ~118 ~115 dirt
setblock ~162 ~118 ~116 dirt
setblock ~162 ~118 ~117 dirt
setblock ~162 ~118 ~118 dirt
setblock ~162 ~118 ~119 dirt
setblock ~162 ~118 ~120 dirt
setblock ~162 ~118 ~121 dirt
setblock ~162 ~118 ~122 dirt
setblock ~162 ~118 ~123 dirt
setblock ~162 ~118 ~124 dirt
setblock ~162 ~118 ~125 dirt
setblock ~162 ~118 ~126 dirt
setblock ~162 ~118 ~127 dirt
setblock ~162 ~118 ~128 dirt
setblock ~162 ~118 ~129 dirt
setblock ~162 ~118 ~130 dirt
setblock ~162 ~119 ~72 dirt
setblock ~162 ~119 ~75 dirt
setblock ~162 ~119 ~76 dirt
setblock ~162 ~119 ~78 dirt
setblock ~162 ~119 ~79 dirt
setblock ~162 ~119 ~80 dirt
setblock ~162 ~119 ~81 dirt
setblock ~162 ~119 ~82 dirt
setblock ~162 ~119 ~83 dirt
setblock ~162 ~119 ~84 dirt
setblock ~162 ~119 ~85 dirt
setblock ~162 ~119 ~86 dirt
setblock ~162 ~119 ~87 dirt
setblock ~162 ~119 ~88 dirt
setblock ~162 ~119 ~89 dirt
setblock ~162 ~119 ~90 dirt
setblock ~162 ~119 ~91 dirt
setblock ~162 ~119 ~92 dirt
setblock ~162 ~119 ~93 dirt
setblock ~162 ~119 ~94 dirt
setblock ~162 ~119 ~95 dirt
setblock ~162 ~119 ~96 dirt
setblock ~162 ~119 ~97 dirt
setblock ~162 ~119 ~98 dirt
setblock ~162 ~119 ~99 dirt
setblock ~162 ~119 ~100 dirt
setblock ~162 ~119 ~101 dirt
setblock ~162 ~119 ~102 dirt
setblock ~162 ~119 ~103 dirt
setblock ~162 ~119 ~104 dirt
setblock ~162 ~119 ~105 dirt
setblock ~162 ~119 ~106 dirt
setblock ~162 ~119 ~107 dirt
setblock ~162 ~119 ~108 dirt
setblock ~162 ~119 ~109 dirt
setblock ~162 ~119 ~110 dirt
setblock ~162 ~119 ~111 dirt
setblock ~162 ~119 ~112 dirt
setblock ~162 ~119 ~113 dirt
setblock ~162 ~119 ~114 dirt
setblock ~162 ~119 ~115 dirt
setblock ~162 ~119 ~116 dirt
setblock ~162 ~119 ~117 dirt
setblock ~162 ~119 ~118 dirt
setblock ~162 ~119 ~119 dirt
setblock ~162 ~119 ~120 dirt
setblock ~162 ~119 ~121 dirt
setblock ~162 ~119 ~122 dirt
setblock ~162 ~119 ~123 dirt
setblock ~162 ~119 ~124 dirt
setblock ~162 ~119 ~125 dirt
setblock ~162 ~119 ~126 dirt
setblock ~162 ~119 ~127 dirt
setblock ~162 ~119 ~128 dirt
setblock ~162 ~119 ~129 dirt
setblock ~162 ~119 ~130 dirt
setblock ~162 ~119 ~131 dirt
setblock ~162 ~120 ~71 dirt
setblock ~162 ~120 ~72 dirt
setblock ~162 ~120 ~73 dirt
setblock ~162 ~120 ~74 dirt
setblock ~162 ~120 ~75 dirt
setblock ~162 ~120 ~76 dirt
setblock ~162 ~120 ~77 dirt
setblock ~162 ~120 ~78 dirt
setblock ~162 ~120 ~79 dirt
setblock ~162 ~120 ~80 dirt
setblock ~162 ~120 ~81 dirt
setblock ~162 ~120 ~82 dirt
setblock ~162 ~120 ~83 dirt
setblock ~162 ~120 ~84 dirt
setblock ~162 ~120 ~85 dirt
setblock ~162 ~120 ~86 dirt
setblock ~162 ~120 ~87 dirt
setblock ~162 ~120 ~88 dirt
setblock ~162 ~120 ~89 dirt
setblock ~162 ~120 ~90 dirt
setblock ~162 ~120 ~91 dirt
setblock ~162 ~120 ~92 dirt
setblock ~162 ~120 ~93 dirt
setblock ~162 ~120 ~94 dirt
setblock ~162 ~120 ~95 dirt
setblock ~162 ~120 ~96 dirt
setblock ~162 ~120 ~97 dirt
setblock ~162 ~120 ~98 dirt
setblock ~162 ~120 ~99 dirt
setblock ~162 ~120 ~100 dirt
setblock ~162 ~120 ~101 dirt
setblock ~162 ~120 ~102 dirt
setblock ~162 ~120 ~103 dirt
setblock ~162 ~120 ~104 dirt
setblock ~162 ~120 ~105 dirt
setblock ~162 ~120 ~106 dirt
setblock ~162 ~120 ~107 dirt
setblock ~162 ~120 ~108 dirt
setblock ~162 ~120 ~109 dirt
setblock ~162 ~120 ~110 dirt
setblock ~162 ~120 ~111 dirt
setblock ~162 ~120 ~112 dirt
setblock ~162 ~120 ~113 dirt
setblock ~162 ~120 ~114 dirt
setblock ~162 ~120 ~115 dirt
setblock ~162 ~120 ~116 dirt
setblock ~162 ~120 ~117 dirt
setblock ~162 ~120 ~118 dirt
setblock ~162 ~120 ~119 dirt
setblock ~162 ~120 ~120 dirt
setblock ~162 ~120 ~121 dirt
setblock ~162 ~120 ~122 dirt
setblock ~162 ~120 ~123 dirt
setblock ~162 ~120 ~124 dirt
setblock ~162 ~120 ~125 dirt
setblock ~162 ~120 ~126 dirt
setblock ~162 ~120 ~127 dirt
setblock ~162 ~120 ~128 dirt
setblock ~162 ~120 ~129 dirt
setblock ~162 ~120 ~130 dirt
setblock ~162 ~120 ~131 dirt
setblock ~162 ~120 ~132 dirt
setblock ~162 ~120 ~135 dirt
setblock ~162 ~120 ~136 dirt
setblock ~162 ~121 ~71 dirt
setblock ~162 ~121 ~72 dirt
setblock ~162 ~121 ~73 dirt
setblock ~162 ~121 ~74 dirt
setblock ~162 ~121 ~75 dirt
setblock ~162 ~121 ~76 dirt
setblock ~162 ~121 ~77 dirt
setblock ~162 ~121 ~78 dirt
setblock ~162 ~121 ~79 dirt
setblock ~162 ~121 ~80 dirt
setblock ~162 ~121 ~81 dirt
setblock ~162 ~121 ~82 dirt
setblock ~162 ~121 ~83 dirt
setblock ~162 ~121 ~84 dirt
setblock ~162 ~121 ~85 dirt
setblock ~162 ~121 ~86 dirt
setblock ~162 ~121 ~87 dirt
setblock ~162 ~121 ~88 dirt
setblock ~162 ~121 ~89 dirt
setblock ~162 ~121 ~90 dirt
setblock ~162 ~121 ~91 dirt
setblock ~162 ~121 ~92 dirt
setblock ~162 ~121 ~93 dirt
setblock ~162 ~121 ~94 dirt
setblock ~162 ~121 ~95 dirt
setblock ~162 ~121 ~96 dirt
setblock ~162 ~121 ~97 dirt
setblock ~162 ~121 ~98 dirt
setblock ~162 ~121 ~99 dirt
setblock ~162 ~121 ~100 dirt
setblock ~162 ~121 ~101 dirt
setblock ~162 ~121 ~102 dirt
setblock ~162 ~121 ~103 dirt
setblock ~162 ~121 ~104 dirt
setblock ~162 ~121 ~105 dirt
setblock ~162 ~121 ~106 dirt
setblock ~162 ~121 ~107 dirt
setblock ~162 ~121 ~108 dirt
setblock ~162 ~121 ~109 dirt
setblock ~162 ~121 ~110 dirt
setblock ~162 ~121 ~111 dirt
setblock ~162 ~121 ~112 dirt
setblock ~162 ~121 ~113 dirt
setblock ~162 ~121 ~114 dirt
setblock ~162 ~121 ~115 dirt
setblock ~162 ~121 ~116 dirt
setblock ~162 ~121 ~117 dirt
setblock ~162 ~121 ~118 dirt
setblock ~162 ~121 ~119 dirt
setblock ~162 ~121 ~120 dirt
setblock ~162 ~121 ~121 dirt
setblock ~162 ~121 ~122 dirt
setblock ~162 ~121 ~123 dirt
setblock ~162 ~121 ~124 dirt
setblock ~162 ~121 ~125 dirt
setblock ~162 ~121 ~126 dirt
setblock ~162 ~121 ~127 dirt
setblock ~162 ~121 ~128 dirt
setblock ~162 ~121 ~129 dirt
setblock ~162 ~121 ~130 dirt
setblock ~162 ~121 ~131 dirt
setblock ~162 ~121 ~132 dirt
setblock ~162 ~121 ~134 dirt
setblock ~162 ~121 ~135 dirt
setblock ~162 ~121 ~136 dirt
setblock ~162 ~121 ~137 dirt
setblock ~162 ~122 ~71 dirt
setblock ~162 ~122 ~72 dirt
setblock ~162 ~122 ~73 dirt
setblock ~162 ~122 ~74 dirt
setblock ~162 ~122 ~75 dirt
setblock ~162 ~122 ~76 grass_block
setblock ~162 ~122 ~77 grass_block
setblock ~162 ~122 ~78 grass_block
setblock ~162 ~122 ~79 grass_block
setblock ~162 ~122 ~80 grass_block
setblock ~162 ~122 ~81 grass_block
setblock ~162 ~122 ~82 grass_block
setblock ~162 ~122 ~83 dirt
setblock ~162 ~122 ~84 dirt
setblock ~162 ~122 ~85 dirt
setblock ~162 ~122 ~86 dirt
setblock ~162 ~122 ~87 dirt
setblock ~162 ~122 ~88 dirt
setblock ~162 ~122 ~89 dirt
setblock ~162 ~122 ~90 dirt
setblock ~162 ~122 ~91 dirt
setblock ~162 ~122 ~92 dirt
setblock ~162 ~122 ~93 dirt
setblock ~162 ~122 ~94 dirt
setblock ~162 ~122 ~95 dirt
setblock ~162 ~122 ~96 dirt
setblock ~162 ~122 ~97 dirt
setblock ~162 ~122 ~98 dirt
setblock ~162 ~122 ~99 dirt
setblock ~162 ~122 ~100 dirt
setblock ~162 ~122 ~101 dirt
setblock ~162 ~122 ~102 dirt
setblock ~162 ~122 ~103 dirt
setblock ~162 ~122 ~104 dirt
setblock ~162 ~122 ~105 dirt
setblock ~162 ~122 ~106 dirt
setblock ~162 ~122 ~107 dirt
setblock ~162 ~122 ~108 dirt
setblock ~162 ~122 ~109 dirt
setblock ~162 ~122 ~110 dirt
setblock ~162 ~122 ~111 dirt
setblock ~162 ~122 ~112 dirt
setblock ~162 ~122 ~113 dirt
setblock ~162 ~122 ~114 dirt
setblock ~162 ~122 ~115 dirt
setblock ~162 ~122 ~116 dirt
setblock ~162 ~122 ~117 dirt
setblock ~162 ~122 ~118 dirt
setblock ~162 ~122 ~119 dirt
setblock ~162 ~122 ~120 dirt
setblock ~162 ~122 ~121 dirt
setblock ~162 ~122 ~122 dirt
setblock ~162 ~122 ~123 dirt
setblock ~162 ~122 ~124 dirt
setblock ~162 ~122 ~125 dirt
setblock ~162 ~122 ~126 dirt
setblock ~162 ~122 ~127 dirt
setblock ~162 ~122 ~128 dirt
setblock ~162 ~122 ~129 dirt
setblock ~162 ~122 ~130 dirt
setblock ~162 ~122 ~131 dirt
setblock ~162 ~122 ~132 dirt
setblock ~162 ~122 ~134 dirt
setblock ~162 ~122 ~135 dirt
setblock ~162 ~122 ~136 dirt
setblock ~162 ~122 ~137 dirt
setblock ~162 ~123 ~71 grass_block
setblock ~162 ~123 ~72 grass_block
setblock ~162 ~123 ~73 grass_block
setblock ~162 ~123 ~74 grass_block
setblock ~162 ~123 ~75 grass_block
setblock ~162 ~123 ~83 grass_block
setblock ~162 ~123 ~84 grass_block
setblock ~162 ~123 ~85 grass_block
setblock ~162 ~123 ~86 grass_block
setblock ~162 ~123 ~87 dirt
setblock ~162 ~123 ~88 dirt
setblock ~162 ~123 ~89 dirt
setblock ~162 ~123 ~90 dirt
setblock ~162 ~123 ~91 dirt
setblock ~162 ~123 ~92 dirt
setblock ~162 ~123 ~93 dirt
setblock ~162 ~123 ~94 dirt
setblock ~162 ~123 ~95 dirt
setblock ~162 ~123 ~96 dirt
setblock ~162 ~123 ~97 dirt
setblock ~162 ~123 ~98 dirt
setblock ~162 ~123 ~99 dirt
setblock ~162 ~123 ~100 dirt
setblock ~162 ~123 ~101 dirt
setblock ~162 ~123 ~102 dirt
setblock ~162 ~123 ~103 dirt
setblock ~162 ~123 ~104 dirt
setblock ~162 ~123 ~105 dirt
setblock ~162 ~123 ~106 dirt
setblock ~162 ~123 ~107 dirt
setblock ~162 ~123 ~108 dirt
setblock ~162 ~123 ~109 dirt
setblock ~162 ~123 ~110 grass_block
setblock ~162 ~123 ~111 dirt
setblock ~162 ~123 ~112 dirt
setblock ~162 ~123 ~113 dirt
setblock ~162 ~123 ~114 dirt
setblock ~162 ~123 ~115 dirt
setblock ~162 ~123 ~116 dirt
setblock ~162 ~123 ~117 dirt
setblock ~162 ~123 ~118 dirt
setblock ~162 ~123 ~119 dirt
setblock ~162 ~123 ~120 dirt
setblock ~162 ~123 ~121 dirt
setblock ~162 ~123 ~122 dirt
setblock ~162 ~123 ~123 dirt
setblock ~162 ~123 ~124 dirt
setblock ~162 ~123 ~125 dirt
setblock ~162 ~123 ~126 dirt
setblock ~162 ~123 ~127 dirt
setblock ~162 ~123 ~128 grass_block
setblock ~162 ~123 ~129 grass_block
setblock ~162 ~123 ~130 grass_block
setblock ~162 ~123 ~131 grass_block
setblock ~162 ~123 ~132 grass_block
setblock ~162 ~123 ~134 dirt
setblock ~162 ~123 ~135 dirt
setblock ~162 ~123 ~136 dirt
setblock ~162 ~123 ~137 dirt
setblock ~162 ~124 ~73 short_grass
setblock ~162 ~124 ~74 short_grass
setblock ~162 ~124 ~87 grass_block
setblock ~162 ~124 ~88 grass_block
setblock ~162 ~124 ~89 grass_block
setblock ~162 ~124 ~90 grass_block
setblock ~162 ~124 ~91 dirt
setblock ~162 ~124 ~92 dirt
setblock ~162 ~124 ~93 dirt
setblock ~162 ~124 ~94 dirt
setblock ~162 ~124 ~95 dirt
setblock ~162 ~124 ~96 dirt
setblock ~162 ~124 ~97 dirt
setblock ~162 ~124 ~98 dirt
setblock ~162 ~124 ~99 dirt
setblock ~162 ~124 ~100 dirt
setblock ~162 ~124 ~101 dirt
setblock ~162 ~124 ~102 dirt
setblock ~162 ~124 ~103 dirt
setblock ~162 ~124 ~104 dirt
setblock ~162 ~124 ~105 dirt
setblock ~162 ~124 ~106 dirt
setblock ~162 ~124 ~107 grass_block
setblock ~162 ~124 ~108 grass_block
setblock ~162 ~124 ~109 grass_block
setblock ~162 ~124 ~110 short_grass
setblock ~162 ~124 ~111 grass_block
setblock ~162 ~124 ~112 grass_block
setblock ~162 ~124 ~113 grass_block
setblock ~162 ~124 ~114 dirt
setblock ~162 ~124 ~115 dirt
setblock ~162 ~124 ~116 dirt
setblock ~162 ~124 ~117 dirt
setblock ~162 ~124 ~118 dirt
setblock ~162 ~124 ~119 dirt
setblock ~162 ~124 ~120 dirt
setblock ~162 ~124 ~121 dirt
setblock ~162 ~124 ~122 dirt
setblock ~162 ~124 ~123 dirt
setblock ~162 ~124 ~124 dirt
setblock ~162 ~124 ~125 grass_block
setblock ~162 ~124 ~126 grass_block
setblock ~162 ~124 ~127 grass_block
setblock ~162 ~124 ~129 short_grass
setblock ~162 ~124 ~131 poppy
setblock ~162 ~124 ~134 grass_block
setblock ~162 ~124 ~135 grass_block
setblock ~162 ~124 ~136 grass_block
setblock ~162 ~124 ~137 dirt
setblock ~162 ~125 ~88 poppy
setblock ~162 ~125 ~89 short_grass
setblock ~162 ~125 ~91 grass_block
setblock ~162 ~125 ~92 grass_block
setblock ~162 ~125 ~93 grass_block
setblock ~162 ~125 ~94 grass_block
setblock ~162 ~125 ~95 dirt
setblock ~162 ~125 ~96 dirt
setblock ~162 ~125 ~97 dirt
setblock ~162 ~125 ~98 dirt
setblock ~162 ~125 ~99 dirt
setblock ~162 ~125 ~100 dirt
setblock ~162 ~125 ~101 dirt
setblock ~162 ~125 ~102 dirt
setblock ~162 ~125 ~103 dirt
setblock ~162 ~125 ~104 grass_block
setblock ~162 ~125 ~105 grass_block
setblock ~162 ~125 ~106 grass_block
setblock ~162 ~125 ~112 short_grass
setblock ~162 ~125 ~113 short_grass
setblock ~162 ~125 ~114 grass_block
setblock ~162 ~125 ~115 grass_block
setblock ~162 ~125 ~116 grass_block
setblock ~162 ~125 ~117 dirt
setblock ~162 ~125 ~118 dirt
setblock ~162 ~125 ~119 dirt
setblock ~162 ~125 ~120 dirt
setblock ~162 ~125 ~121 dirt
setblock ~162 ~125 ~122 dirt
setblock ~162 ~125 ~123 grass_block
setblock ~162 ~125 ~124 grass_block
setblock ~162 ~125 ~127 short_grass
setblock ~162 ~125 ~134 short_grass
setblock ~162 ~125 ~137 grass_block
setblock ~162 ~126 ~91 fern
setblock ~162 ~126 ~92 short_grass
setblock ~162 ~126 ~95 grass_block
setblock ~162 ~126 ~96 grass_block
setblock ~162 ~126 ~97 grass_block
setblock ~162 ~126 ~98 dirt
setblock ~162 ~126 ~99 dirt
setblock ~162 ~126 ~100 dirt
setblock ~162 ~126 ~101 dirt
setblock ~162 ~126 ~102 grass_block
setblock ~162 ~126 ~103 grass_block
setblock ~162 ~126 ~115 poppy
setblock ~162 ~126 ~116 short_grass
setblock ~162 ~126 ~117 grass_block
setblock ~162 ~126 ~118 grass_block
setblock ~162 ~126 ~119 grass_block
setblock ~162 ~126 ~120 dirt
setblock ~162 ~126 ~121 grass_block
setblock ~162 ~126 ~122 grass_block
setblock ~162 ~126 ~123 short_grass
setblock ~162 ~127 ~95 short_grass
setblock ~162 ~127 ~96 poppy
setblock ~162 ~127 ~98 grass_block
setblock ~162 ~127 ~99 grass_block
setblock ~162 ~127 ~100 grass_block
setblock ~162 ~127 ~101 grass_block
setblock ~162 ~127 ~117 short_grass
setblock ~162 ~127 ~120 grass_block
setblock ~162 ~127 ~122 poppy
setblock ~162 ~128 ~99 short_grass
setblock ~163 ~104 ~119 dirt
setblock ~163 ~105 ~119 dirt
setblock ~163 ~105 ~120 dirt
setblock ~163 ~106 ~117 dirt
setblock ~163 ~106 ~119 dirt
setblock ~163 ~106 ~120 dirt
setblock ~163 ~106 ~121 dirt
setblock ~163 ~107 ~94 dirt
setblock ~163 ~107 ~95 dirt
setblock ~163 ~107 ~98 dirt
setblock ~163 ~107 ~102 dirt
setblock ~163 ~107 ~104 dirt
setblock ~163 ~107 ~117 dirt
setblock ~163 ~107 ~118 dirt
setblock ~163 ~107 ~119 dirt
setblock ~163 ~107 ~120 dirt
setblock ~163 ~107 ~121 dirt
setblock ~163 ~107 ~122 dirt
setblock ~163 ~108 ~93 dirt
setblock ~163 ~108 ~94 dirt
setblock ~163 ~108 ~95 dirt
setblock ~163 ~108 ~97 dirt
setblock ~163 ~108 ~98 dirt
setblock ~163 ~108 ~99 dirt
setblock ~163 ~108 ~102 dirt
setblock ~163 ~108 ~104 dirt
setblock ~163 ~108 ~116 dirt
setblock ~163 ~108 ~117 dirt
setblock ~163 ~108 ~118 dirt
setblock ~163 ~108 ~119 dirt
setblock ~163 ~108 ~120 dirt
setblock ~163 ~108 ~121 dirt
setblock ~163 ~108 ~122 dirt
setblock ~163 ~108 ~123 dirt
setblock ~163 ~109 ~92 dirt
setblock ~163 ~109 ~93 dirt
setblock ~163 ~109 ~94 dirt
setblock ~163 ~109 ~95 dirt
setblock ~163 ~109 ~96 dirt
setblock ~163 ~109 ~97 dirt
setblock ~163 ~109 ~98 dirt
setblock ~163 ~109 ~99 dirt
setblock ~163 ~109 ~101 dirt
setblock ~163 ~109 ~102 dirt
setblock ~163 ~109 ~103 dirt
setblock ~163 ~109 ~104 dirt
setblock ~163 ~109 ~105 dirt
setblock ~163 ~109 ~115 dirt
setblock ~163 ~109 ~116 dirt
setblock ~163 ~109 ~117 dirt
setblock ~163 ~109 ~118 dirt
setblock ~163 ~109 ~119 dirt
setblock ~163 ~109 ~120 dirt
setblock ~163 ~109 ~121 dirt
setblock ~163 ~109 ~122 dirt
setblock ~163 ~109 ~123 dirt
setblock ~163 ~110 ~92 dirt
setblock ~163 ~110 ~93 dirt
setblock ~163 ~110 ~94 dirt
setblock ~163 ~110 ~95 dirt
setblock ~163 ~110 ~96 dirt
setblock ~163 ~110 ~97 dirt
setblock ~163 ~110 ~98 dirt
setblock ~163 ~110 ~99 dirt
setblock ~163 ~110 ~100 dirt
setblock ~163 ~110 ~101 dirt
setblock ~163 ~110 ~102 dirt
setblock ~163 ~110 ~103 dirt
setblock ~163 ~110 ~104 dirt
setblock ~163 ~110 ~105 dirt
setblock ~163 ~110 ~106 dirt
setblock ~163 ~110 ~115 dirt
setblock ~163 ~110 ~116 dirt
setblock ~163 ~110 ~117 dirt
setblock ~163 ~110 ~118 dirt
setblock ~163 ~110 ~119 dirt
setblock ~163 ~110 ~120 dirt
setblock ~163 ~110 ~121 dirt
setblock ~163 ~110 ~122 dirt
setblock ~163 ~110 ~123 dirt
setblock ~163 ~110 ~124 dirt
setblock ~163 ~111 ~91 dirt
setblock ~163 ~111 ~92 dirt
setblock ~163 ~111 ~93 dirt
setblock ~163 ~111 ~94 dirt
setblock ~163 ~111 ~95 dirt
setblock ~163 ~111 ~96 dirt
setblock ~163 ~111 ~97 dirt
setblock ~163 ~111 ~98 dirt
setblock ~163 ~111 ~99 dirt
setblock ~163 ~111 ~100 dirt
setblock ~163 ~111 ~101 dirt
setblock ~163 ~111 ~102 dirt
setblock ~163 ~111 ~103 dirt
setblock ~163 ~111 ~104 dirt
setblock ~163 ~111 ~105 dirt
setblock ~163 ~111 ~106 dirt
setblock ~163 ~111 ~107 dirt
setblock ~163 ~111 ~114 dirt
setblock ~163 ~111 ~115 dirt
setblock ~163 ~111 ~116 dirt
setblock ~163 ~111 ~117 dirt
setblock ~163 ~111 ~118 dirt
setblock ~163 ~111 ~119 dirt
setblock ~163 ~111 ~120 dirt
setblock ~163 ~111 ~121 dirt
setblock ~163 ~111 ~122 dirt
setblock ~163 ~111 ~123 dirt
setblock ~163 ~111 ~124 dirt
setblock ~163 ~112 ~90 dirt
setblock ~163 ~112 ~91 dirt
setblock ~163 ~112 ~92 dirt
setblock ~163 ~112 ~93 dirt
setblock ~163 ~112 ~94 dirt
setblock ~163 ~112 ~95 dirt
setblock ~163 ~112 ~96 dirt
setblock ~163 ~112 ~97 dirt
setblock ~163 ~112 ~98 dirt
setblock ~163 ~112 ~99 dirt
setblock ~163 ~112 ~100 dirt
setblock ~163 ~112 ~101 dirt
setblock ~163 ~112 ~102 dirt
setblock ~163 ~112 ~103 dirt
setblock ~163 ~112 ~104 dirt
setblock ~163 ~112 ~105 dirt
setblock ~163 ~112 ~106 dirt
setblock ~163 ~112 ~107 dirt
setblock ~163 ~112 ~114 dirt
setblock ~163 ~112 ~115 dirt
setblock ~163 ~112 ~116 dirt
setblock ~163 ~112 ~117 dirt
setblock ~163 ~112 ~118 dirt
setblock ~163 ~112 ~119 dirt
setblock ~163 ~112 ~120 dirt
setblock ~163 ~112 ~121 dirt
setblock ~163 ~112 ~122 dirt
setblock ~163 ~112 ~123 dirt
setblock ~163 ~112 ~124 dirt
setblock ~163 ~113 ~89 dirt
setblock ~163 ~113 ~90 dirt
setblock ~163 ~113 ~91 dirt
setblock ~163 ~113 ~92 dirt
setblock ~163 ~113 ~93 dirt
setblock ~163 ~113 ~94 dirt
setblock ~163 ~113 ~95 dirt
setblock ~163 ~113 ~96 dirt
setblock ~163 ~113 ~97 dirt
setblock ~163 ~113 ~98 dirt
setblock ~163 ~113 ~99 dirt
setblock ~163 ~113 ~100 dirt
setblock ~163 ~113 ~101 dirt
setblock ~163 ~113 ~102 dirt
setblock ~163 ~113 ~103 dirt
setblock ~163 ~113 ~104 dirt
setblock ~163 ~113 ~105 dirt
setblock ~163 ~113 ~106 dirt
setblock ~163 ~113 ~107 dirt
setblock ~163 ~113 ~108 dirt
setblock ~163 ~113 ~113 dirt
setblock ~163 ~113 ~114 dirt
setblock ~163 ~113 ~115 dirt
setblock ~163 ~113 ~116 dirt
setblock ~163 ~113 ~117 dirt
setblock ~163 ~113 ~118 dirt
setblock ~163 ~113 ~119 dirt
setblock ~163 ~113 ~120 dirt
setblock ~163 ~113 ~121 dirt
setblock ~163 ~113 ~122 dirt
setblock ~163 ~113 ~123 dirt
setblock ~163 ~113 ~124 dirt
setblock ~163 ~113 ~125 dirt
setblock ~163 ~114 ~88 dirt
setblock ~163 ~114 ~89 dirt
setblock ~163 ~114 ~90 dirt
setblock ~163 ~114 ~91 dirt
setblock ~163 ~114 ~92 dirt
setblock ~163 ~114 ~93 dirt
setblock ~163 ~114 ~94 dirt
setblock ~163 ~114 ~95 dirt
setblock ~163 ~114 ~96 dirt
setblock ~163 ~114 ~97 dirt
setblock ~163 ~114 ~98 dirt
setblock ~163 ~114 ~99 dirt
setblock ~163 ~114 ~100 dirt
setblock ~163 ~114 ~101 dirt
setblock ~163 ~114 ~102 dirt
setblock ~163 ~114 ~103 dirt
setblock ~163 ~114 ~104 dirt
setblock ~163 ~114 ~105 dirt
setblock ~163 ~114 ~106 dirt
setblock ~163 ~114 ~107 dirt
setblock ~163 ~114 ~108 dirt
setblock ~163 ~114 ~113 dirt
setblock ~163 ~114 ~114 dirt
setblock ~163 ~114 ~115 dirt
setblock ~163 ~114 ~116 dirt
setblock ~163 ~114 ~117 dirt
setblock ~163 ~114 ~118 dirt
setblock ~163 ~114 ~119 dirt
setblock ~163 ~114 ~120 dirt
setblock ~163 ~114 ~121 dirt
setblock ~163 ~114 ~122 dirt
setblock ~163 ~114 ~123 dirt
setblock ~163 ~114 ~124 dirt
setblock ~163 ~114 ~125 dirt
setblock ~163 ~114 ~126 dirt
setblock ~163 ~115 ~88 dirt
setblock ~163 ~115 ~89 dirt
setblock ~163 ~115 ~90 dirt
setblock ~163 ~115 ~91 dirt
setblock ~163 ~115 ~92 dirt
setblock ~163 ~115 ~93 dirt
setblock ~163 ~115 ~94 dirt
setblock ~163 ~115 ~95 dirt
setblock ~163 ~115 ~96 dirt
setblock ~163 ~115 ~97 dirt
setblock ~163 ~115 ~98 dirt
setblock ~163 ~115 ~99 dirt
setblock ~163 ~115 ~100 dirt
setblock ~163 ~115 ~101 dirt
setblock ~163 ~115 ~102 dirt
setblock ~163 ~115 ~103 dirt
setblock ~163 ~115 ~104 dirt
setblock ~163 ~115 ~105 dirt
setblock ~163 ~115 ~106 dirt
setblock ~163 ~115 ~107 dirt
setblock ~163 ~115 ~108 dirt
setblock ~163 ~115 ~109 dirt
setblock ~163 ~115 ~112 dirt
setblock ~163 ~115 ~113 dirt
setblock ~163 ~115 ~114 dirt
setblock ~163 ~115 ~115 dirt
setblock ~163 ~115 ~116 dirt
setblock ~163 ~115 ~117 dirt
setblock ~163 ~115 ~118 dirt
setblock ~163 ~115 ~119 dirt
setblock ~163 ~115 ~120 dirt
setblock ~163 ~115 ~121 dirt
setblock ~163 ~115 ~122 dirt
setblock ~163 ~115 ~123 dirt
setblock ~163 ~115 ~124 dirt
setblock ~163 ~115 ~125 dirt
setblock ~163 ~115 ~126 dirt
setblock ~163 ~115 ~127 dirt
setblock ~163 ~116 ~81 dirt
setblock ~163 ~116 ~82 dirt
setblock ~163 ~116 ~87 dirt
setblock ~163 ~116 ~88 dirt
setblock ~163 ~116 ~89 dirt
setblock ~163 ~116 ~90 dirt
setblock ~163 ~116 ~91 dirt
setblock ~163 ~116 ~92 dirt
setblock ~163 ~116 ~93 dirt
setblock ~163 ~116 ~94 dirt
setblock ~163 ~116 ~95 dirt
setblock ~163 ~116 ~96 dirt
setblock ~163 ~116 ~97 dirt
setblock ~163 ~116 ~98 dirt
setblock ~163 ~116 ~99 dirt
setblock ~163 ~116 ~100 dirt
setblock ~163 ~116 ~101 dirt
setblock ~163 ~116 ~102 dirt
setblock ~163 ~116 ~103 dirt
setblock ~163 ~116 ~104 dirt
setblock ~163 ~116 ~105 dirt
setblock ~163 ~116 ~106 dirt
setblock ~163 ~116 ~107 dirt
setblock ~163 ~116 ~108 dirt
setblock ~163 ~116 ~109 dirt
setblock ~163 ~116 ~110 dirt
setblock ~163 ~116 ~112 dirt
setblock ~163 ~116 ~113 dirt
setblock ~163 ~116 ~114 dirt
setblock ~163 ~116 ~115 dirt
setblock ~163 ~116 ~116 dirt
setblock ~163 ~116 ~117 dirt
setblock ~163 ~116 ~118 dirt
setblock ~163 ~116 ~119 dirt
setblock ~163 ~116 ~120 dirt
setblock ~163 ~116 ~121 dirt
setblock ~163 ~116 ~122 dirt
setblock ~163 ~116 ~123 dirt
setblock ~163 ~116 ~124 dirt
setblock ~163 ~116 ~125 dirt
setblock ~163 ~116 ~126 dirt
setblock ~163 ~116 ~127 dirt
setblock ~163 ~116 ~128 dirt
setblock ~163 ~117 ~80 dirt
setblock ~163 ~117 ~81 dirt
setblock ~163 ~117 ~82 dirt
setblock ~163 ~117 ~86 dirt
setblock ~163 ~117 ~87 dirt
setblock ~163 ~117 ~88 dirt
setblock ~163 ~117 ~89 dirt
setblock ~163 ~117 ~90 dirt
setblock ~163 ~117 ~91 dirt
setblock ~163 ~117 ~92 dirt
setblock ~163 ~117 ~93 dirt
setblock ~163 ~117 ~94 dirt
setblock ~163 ~117 ~95 dirt
setblock ~163 ~117 ~96 dirt
setblock ~163 ~117 ~97 dirt
setblock ~163 ~117 ~98 dirt
setblock ~163 ~117 ~99 dirt
setblock ~163 ~117 ~100 dirt
setblock ~163 ~117 ~101 dirt
setblock ~163 ~117 ~102 dirt
setblock ~163 ~117 ~103 dirt
setblock ~163 ~117 ~104 dirt
setblock ~163 ~117 ~105 dirt
setblock ~163 ~117 ~106 dirt
setblock ~163 ~117 ~107 dirt
setblock ~163 ~117 ~108 dirt
setblock ~163 ~117 ~109 dirt
setblock ~163 ~117 ~110 dirt
setblock ~163 ~117 ~111 dirt
setblock ~163 ~117 ~112 dirt
setblock ~163 ~117 ~113 dirt
setblock ~163 ~117 ~114 dirt
setblock ~163 ~117 ~115 dirt
setblock ~163 ~117 ~116 dirt
setblock ~163 ~117 ~117 dirt
setblock ~163 ~117 ~118 dirt
setblock ~163 ~117 ~119 dirt
setblock ~163 ~117 ~120 dirt
setblock ~163 ~117 ~121 dirt
setblock ~163 ~117 ~122 dirt
setblock ~163 ~117 ~123 dirt
setblock ~163 ~117 ~124 dirt
setblock ~163 ~117 ~125 dirt
setblock ~163 ~117 ~126 dirt
setblock ~163 ~117 ~127 dirt
setblock ~163 ~117 ~128 dirt
setblock ~163 ~117 ~129 dirt
setblock ~163 ~118 ~80 dirt
setblock ~163 ~118 ~81 dirt
setblock ~163 ~118 ~82 dirt
setblock ~163 ~118 ~83 dirt
setblock ~163 ~118 ~86 dirt
setblock ~163 ~118 ~87 dirt
setblock ~163 ~118 ~88 dirt
setblock ~163 ~118 ~89 dirt
setblock ~163 ~118 ~90 dirt
setblock ~163 ~118 ~91 dirt
setblock ~163 ~118 ~92 dirt
setblock ~163 ~118 ~93 dirt
setblock ~163 ~118 ~94 dirt
setblock ~163 ~118 ~95 dirt
setblock ~163 ~118 ~96 dirt
setblock ~163 ~118 ~97 dirt
setblock ~163 ~118 ~98 dirt
setblock ~163 ~118 ~99 dirt
setblock ~163 ~118 ~100 dirt
setblock ~163 ~118 ~101 dirt
setblock ~163 ~118 ~102 dirt
setblock ~163 ~118 ~103 dirt
setblock ~163 ~118 ~104 dirt
setblock ~163 ~118 ~105 dirt
setblock ~163 ~118 ~106 dirt
setblock ~163 ~118 ~107 dirt
setblock ~163 ~118 ~108 dirt
setblock ~163 ~118 ~109 dirt
setblock ~163 ~118 ~110 dirt
setblock ~163 ~118 ~111 dirt
setblock ~163 ~118 ~112 dirt
setblock ~163 ~118 ~113 dirt
setblock ~163 ~118 ~114 dirt
setblock ~163 ~118 ~115 dirt
setblock ~163 ~118 ~116 dirt
setblock ~163 ~118 ~117 dirt
setblock ~163 ~118 ~118 dirt
setblock ~163 ~118 ~119 dirt
setblock ~163 ~118 ~120 dirt
setblock ~163 ~118 ~121 dirt
setblock ~163 ~118 ~122 dirt
setblock ~163 ~118 ~123 dirt
setblock ~163 ~118 ~124 dirt
setblock ~163 ~118 ~125 dirt
setblock ~163 ~118 ~126 dirt
setblock ~163 ~118 ~127 dirt
setblock ~163 ~118 ~128 dirt
setblock ~163 ~118 ~129 dirt
setblock ~163 ~119 ~80 dirt
setblock ~163 ~119 ~81 dirt
setblock ~163 ~119 ~82 dirt
setblock ~163 ~119 ~83 dirt
setblock ~163 ~119 ~84 dirt
setblock ~163 ~119 ~85 dirt
setblock ~163 ~119 ~86 dirt
setblock ~163 ~119 ~87 dirt
setblock ~163 ~119 ~88 dirt
setblock ~163 ~119 ~89 dirt
setblock ~163 ~119 ~90 dirt
setblock ~163 ~119 ~91 dirt
setblock ~163 ~119 ~92 dirt
setblock ~163 ~119 ~93 dirt
setblock ~163 ~119 ~94 dirt
setblock ~163 ~119 ~95 dirt
setblock ~163 ~119 ~96 dirt
setblock ~163 ~119 ~97 dirt
setblock ~163 ~119 ~98 dirt
setblock ~163 ~119 ~99 dirt
setblock ~163 ~119 ~100 dirt
setblock ~163 ~119 ~101 dirt
setblock ~163 ~119 ~102 dirt
setblock ~163 ~119 ~103 dirt
setblock ~163 ~119 ~104 dirt
setblock ~163 ~119 ~105 dirt
setblock ~163 ~119 ~106 dirt
setblock ~163 ~119 ~107 dirt
setblock ~163 ~119 ~108 dirt
setblock ~163 ~119 ~109 dirt
setblock ~163 ~119 ~110 dirt
setblock ~163 ~119 ~111 dirt
setblock ~163 ~119 ~112 dirt
setblock ~163 ~119 ~113 dirt
setblock ~163 ~119 ~114 dirt
setblock ~163 ~119 ~115 dirt
setblock ~163 ~119 ~116 dirt
setblock ~163 ~119 ~117 dirt
setblock ~163 ~119 ~118 dirt
setblock ~163 ~119 ~119 dirt
setblock ~163 ~119 ~120 dirt
setblock ~163 ~119 ~121 dirt
setblock ~163 ~119 ~122 dirt
setblock ~163 ~119 ~123 dirt
setblock ~163 ~119 ~124 dirt
setblock ~163 ~119 ~125 dirt
setblock ~163 ~119 ~126 dirt
setblock ~163 ~119 ~127 dirt
setblock ~163 ~119 ~128 dirt
setblock ~163 ~119 ~129 dirt
setblock ~163 ~119 ~130 dirt
setblock ~163 ~120 ~72 dirt
setblock ~163 ~120 ~75 dirt
setblock ~163 ~120 ~79 dirt
setblock ~163 ~120 ~80 dirt
setblock ~163 ~120 ~81 dirt
setblock ~163 ~120 ~82 dirt
setblock ~163 ~120 ~83 dirt
setblock ~163 ~120 ~84 dirt
setblock ~163 ~120 ~85 dirt
setblock ~163 ~120 ~86 dirt
setblock ~163 ~120 ~87 dirt
setblock ~163 ~120 ~88 dirt
setblock ~163 ~120 ~89 dirt
setblock ~163 ~120 ~90 dirt
setblock ~163 ~120 ~91 dirt
setblock ~163 ~120 ~92 dirt
setblock ~163 ~120 ~93 dirt
setblock ~163 ~120 ~94 dirt
setblock ~163 ~120 ~95 dirt
setblock ~163 ~120 ~96 dirt
setblock ~163 ~120 ~97 dirt
setblock ~163 ~120 ~98 dirt
setblock ~163 ~120 ~99 dirt
setblock ~163 ~120 ~100 dirt
setblock ~163 ~120 ~101 dirt
setblock ~163 ~120 ~102 dirt
setblock ~163 ~120 ~103 dirt
setblock ~163 ~120 ~104 dirt
setblock ~163 ~120 ~105 dirt
setblock ~163 ~120 ~106 dirt
setblock ~163 ~120 ~107 dirt
setblock ~163 ~120 ~108 dirt
setblock ~163 ~120 ~109 dirt
setblock ~163 ~120 ~110 dirt
setblock ~163 ~120 ~111 dirt
setblock ~163 ~120 ~112 dirt
setblock ~163 ~120 ~113 dirt
setblock ~163 ~120 ~114 dirt
setblock ~163 ~120 ~115 dirt
setblock ~163 ~120 ~116 dirt
setblock ~163 ~120 ~117 dirt
setblock ~163 ~120 ~118 dirt
setblock ~163 ~120 ~119 dirt
setblock ~163 ~120 ~120 dirt
setblock ~163 ~120 ~121 dirt
setblock ~163 ~120 ~122 dirt
setblock ~163 ~120 ~123 dirt
setblock ~163 ~120 ~124 dirt
setblock ~163 ~120 ~125 dirt
setblock ~163 ~120 ~126 dirt
setblock ~163 ~120 ~127 dirt
setblock ~163 ~120 ~128 dirt
setblock ~163 ~120 ~129 dirt
setblock ~163 ~120 ~130 dirt
setblock ~163 ~120 ~131 dirt
setblock ~163 ~121 ~72 dirt
setblock ~163 ~121 ~75 dirt
setblock ~163 ~121 ~76 dirt
setblock ~163 ~121 ~79 dirt
setblock ~163 ~121 ~80 dirt
setblock ~163 ~121 ~81 dirt
setblock ~163 ~121 ~82 dirt
setblock ~163 ~121 ~83 dirt
setblock ~163 ~121 ~84 dirt
setblock ~163 ~121 ~85 dirt
setblock ~163 ~121 ~86 dirt
setblock ~163 ~121 ~87 dirt
setblock ~163 ~121 ~88 dirt
setblock ~163 ~121 ~89 dirt
setblock ~163 ~121 ~90 dirt
setblock ~163 ~121 ~91 dirt
setblock ~163 ~121 ~92 dirt
setblock ~163 ~121 ~93 dirt
setblock ~163 ~121 ~94 dirt
setblock ~163 ~121 ~95 dirt
setblock ~163 ~121 ~96 dirt
setblock ~163 ~121 ~97 dirt
setblock ~163 ~121 ~98 dirt
setblock ~163 ~121 ~99 dirt
setblock ~163 ~121 ~100 dirt
setblock ~163 ~121 ~101 dirt
setblock ~163 ~121 ~102 dirt
setblock ~163 ~121 ~103 dirt
setblock ~163 ~121 ~104 dirt
setblock ~163 ~121 ~105 dirt
setblock ~163 ~121 ~106 dirt
setblock ~163 ~121 ~107 dirt
setblock ~163 ~121 ~108 dirt
setblock ~163 ~121 ~109 dirt
setblock ~163 ~121 ~110 dirt
setblock ~163 ~121 ~111 dirt
setblock ~163 ~121 ~112 dirt
setblock ~163 ~121 ~113 dirt
setblock ~163 ~121 ~114 dirt
setblock ~163 ~121 ~115 dirt
setblock ~163 ~121 ~116 dirt
setblock ~163 ~121 ~117 dirt
setblock ~163 ~121 ~118 dirt
setblock ~163 ~121 ~119 dirt
setblock ~163 ~121 ~120 dirt
setblock ~163 ~121 ~121 dirt
setblock ~163 ~121 ~122 dirt
setblock ~163 ~121 ~123 dirt
setblock ~163 ~121 ~124 dirt
setblock ~163 ~121 ~125 dirt
setblock ~163 ~121 ~126 dirt
setblock ~163 ~121 ~127 dirt
setblock ~163 ~121 ~128 dirt
setblock ~163 ~121 ~129 dirt
setblock ~163 ~121 ~130 dirt
setblock ~163 ~121 ~131 dirt
setblock ~163 ~122 ~72 dirt
setblock ~163 ~122 ~75 dirt
setblock ~163 ~122 ~76 dirt
setblock ~163 ~122 ~79 grass_block
setblock ~163 ~122 ~80 grass_block
setblock ~163 ~122 ~81 grass_block
setblock ~163 ~122 ~82 dirt
setblock ~163 ~122 ~83 dirt
setblock ~163 ~122 ~84 dirt
setblock ~163 ~122 ~85 dirt
setblock ~163 ~122 ~86 dirt
setblock ~163 ~122 ~87 dirt
setblock ~163 ~122 ~88 dirt
setblock ~163 ~122 ~89 dirt
setblock ~163 ~122 ~90 dirt
setblock ~163 ~122 ~91 dirt
setblock ~163 ~122 ~92 dirt
setblock ~163 ~122 ~93 dirt
setblock ~163 ~122 ~94 dirt
setblock ~163 ~122 ~95 dirt
setblock ~163 ~122 ~96 dirt
setblock ~163 ~122 ~97 dirt
setblock ~163 ~122 ~98 dirt
setblock ~163 ~122 ~99 dirt
setblock ~163 ~122 ~100 dirt
setblock ~163 ~122 ~101 dirt
setblock ~163 ~122 ~102 dirt
setblock ~163 ~122 ~103 dirt
setblock ~163 ~122 ~104 dirt
setblock ~163 ~122 ~105 dirt
setblock ~163 ~122 ~106 dirt
setblock ~163 ~122 ~107 dirt
setblock ~163 ~122 ~108 dirt
setblock ~163 ~122 ~109 dirt
setblock ~163 ~122 ~110 dirt
setblock ~163 ~122 ~111 dirt
setblock ~163 ~122 ~112 dirt
setblock ~163 ~122 ~113 dirt
setblock ~163 ~122 ~114 dirt
setblock ~163 ~122 ~115 dirt
setblock ~163 ~122 ~116 dirt
setblock ~163 ~122 ~117 dirt
setblock ~163 ~122 ~118 dirt
setblock ~163 ~122 ~119 dirt
setblock ~163 ~122 ~120 dirt
setblock ~163 ~122 ~121 dirt
setblock ~163 ~122 ~122 dirt
setblock ~163 ~122 ~123 dirt
setblock ~163 ~122 ~124 dirt
setblock ~163 ~122 ~125 dirt
setblock ~163 ~122 ~126 dirt
setblock ~163 ~122 ~127 dirt
setblock ~163 ~122 ~128 dirt
setblock ~163 ~122 ~129 dirt
setblock ~163 ~122 ~130 dirt
setblock ~163 ~122 ~131 dirt
setblock ~163 ~123 ~72 grass_block
setblock ~163 ~123 ~75 grass_block
setblock ~163 ~123 ~76 grass_block
setblock ~163 ~123 ~82 grass_block
setblock ~163 ~123 ~83 grass_block
setblock ~163 ~123 ~84 grass_block
setblock ~163 ~123 ~85 grass_block
setblock ~163 ~123 ~86 dirt
setblock ~163 ~123 ~87 dirt
setblock ~163 ~123 ~88 dirt
setblock ~163 ~123 ~89 dirt
setblock ~163 ~123 ~90 dirt
setblock ~163 ~123 ~91 dirt
setblock ~163 ~123 ~92 dirt
setblock ~163 ~123 ~93 dirt
setblock ~163 ~123 ~94 dirt
setblock ~163 ~123 ~95 dirt
setblock ~163 ~123 ~96 dirt
setblock ~163 ~123 ~97 dirt
setblock ~163 ~123 ~98 dirt
setblock ~163 ~123 ~99 dirt
setblock ~163 ~123 ~100 dirt
setblock ~163 ~123 ~101 dirt
setblock ~163 ~123 ~102 dirt
setblock ~163 ~123 ~103 dirt
setblock ~163 ~123 ~104 dirt
setblock ~163 ~123 ~105 dirt
setblock ~163 ~123 ~106 dirt
setblock ~163 ~123 ~107 dirt
setblock ~163 ~123 ~108 dirt
setblock ~163 ~123 ~109 dirt
setblock ~163 ~123 ~110 grass_block
setblock ~163 ~123 ~111 dirt
setblock ~163 ~123 ~112 dirt
setblock ~163 ~123 ~113 dirt
setblock ~163 ~123 ~114 dirt
setblock ~163 ~123 ~115 dirt
setblock ~163 ~123 ~116 dirt
setblock ~163 ~123 ~117 dirt
setblock ~163 ~123 ~118 dirt
setblock ~163 ~123 ~119 dirt
setblock ~163 ~123 ~120 dirt
setblock ~163 ~123 ~121 dirt
setblock ~163 ~123 ~122 dirt
setblock ~163 ~123 ~123 dirt
setblock ~163 ~123 ~124 dirt
setblock ~163 ~123 ~125 dirt
setblock ~163 ~123 ~126 dirt
setblock ~163 ~123 ~127 dirt
setblock ~163 ~123 ~128 grass_block
setblock ~163 ~123 ~129 grass_block
setblock ~163 ~123 ~130 grass_block
setblock ~163 ~123 ~131 grass_block
setblock ~163 ~124 ~75 short_grass
setblock ~163 ~124 ~84 short_grass
setblock ~163 ~124 ~86 grass_block
setblock ~163 ~124 ~87 grass_block
setblock ~163 ~124 ~88 grass_block
setblock ~163 ~124 ~89 dirt
setblock ~163 ~124 ~90 dirt
setblock ~163 ~124 ~91 dirt
setblock ~163 ~124 ~92 dirt
setblock ~163 ~124 ~93 dirt
setblock ~163 ~124 ~94 dirt
setblock ~163 ~124 ~95 dirt
setblock ~163 ~124 ~96 dirt
setblock ~163 ~124 ~97 dirt
setblock ~163 ~124 ~98 dirt
setblock ~163 ~124 ~99 dirt
setblock ~163 ~124 ~100 dirt
setblock ~163 ~124 ~101 dirt
setblock ~163 ~124 ~102 dirt
setblock ~163 ~124 ~103 dirt
setblock ~163 ~124 ~104 dirt
setblock ~163 ~124 ~105 dirt
setblock ~163 ~124 ~106 grass_block
setblock ~163 ~124 ~107 grass_block
setblock ~163 ~124 ~108 grass_block
setblock ~163 ~124 ~109 grass_block
setblock ~163 ~124 ~111 grass_block
setblock ~163 ~124 ~112 grass_block
setblock ~163 ~124 ~113 grass_block
setblock ~163 ~124 ~114 grass_block
setblock ~163 ~124 ~115 dirt
setblock ~163 ~124 ~116 dirt
setblock ~163 ~124 ~117 dirt
setblock ~163 ~124 ~118 dirt
setblock ~163 ~124 ~119 dirt
setblock ~163 ~124 ~120 dirt
setblock ~163 ~124 ~121 dirt
setblock ~163 ~124 ~122 dirt
setblock ~163 ~124 ~123 dirt
setblock ~163 ~124 ~124 dirt
setblock ~163 ~124 ~125 grass_block
setblock ~163 ~124 ~126 grass_block
setblock ~163 ~124 ~127 grass_block
setblock ~163 ~124 ~129 short_grass
setblock ~163 ~124 ~130 short_grass
setblock ~163 ~125 ~87 short_grass
setblock ~163 ~125 ~88 poppy
setblock ~163 ~125 ~89 grass_block
setblock ~163 ~125 ~90 grass_block
setblock ~163 ~125 ~91 grass_block
setblock ~163 ~125 ~92 grass_block
setblock ~163 ~125 ~93 grass_block
setblock ~163 ~125 ~94 dirt
setblock ~163 ~125 ~95 dirt
setblock ~163 ~125 ~96 dirt
setblock ~163 ~125 ~97 dirt
setblock ~163 ~125 ~98 dirt
setblock ~163 ~125 ~99 dirt
setblock ~163 ~125 ~100 dirt
setblock ~163 ~125 ~101 dirt
setblock ~163 ~125 ~102 dirt
setblock ~163 ~125 ~103 grass_block
setblock ~163 ~125 ~104 grass_block
setblock ~163 ~125 ~105 grass_block
setblock ~163 ~125 ~106 short_grass
setblock ~163 ~125 ~113 short_grass
setblock ~163 ~125 ~115 grass_block
setblock ~163 ~125 ~116 grass_block
setblock ~163 ~125 ~117 grass_block
setblock ~163 ~125 ~118 grass_block
setblock ~163 ~125 ~119 dirt
setblock ~163 ~125 ~120 dirt
setblock ~163 ~125 ~121 dirt
setblock ~163 ~125 ~122 grass_block
setblock ~163 ~125 ~123 grass_block
setblock ~163 ~125 ~124 grass_block
setblock ~163 ~125 ~125 short_grass
setblock ~163 ~126 ~89 fern
setblock ~163 ~126 ~90 short_grass
setblock ~163 ~126 ~92 short_grass
setblock ~163 ~126 ~94 grass_block
setblock ~163 ~126 ~95 grass_block
setblock ~163 ~126 ~96 grass_block
setblock ~163 ~126 ~97 grass_block
setblock ~163 ~126 ~98 grass_block
setblock ~163 ~126 ~99 grass_block
setblock ~163 ~126 ~100 grass_block
setblock ~163 ~126 ~101 grass_block
setblock ~163 ~126 ~102 grass_block
setblock ~163 ~126 ~103 poppy
setblock ~163 ~126 ~104 short_grass
setblock ~163 ~126 ~118 fern
setblock ~163 ~126 ~119 grass_block
setblock ~163 ~126 ~120 grass_block
setblock ~163 ~126 ~121 grass_block
setblock ~163 ~126 ~122 short_grass
setblock ~163 ~127 ~101 short_grass
setblock ~163 ~127 ~102 fern
setblock ~164 ~107 ~119 dirt
setblock ~164 ~107 ~120 dirt
setblock ~164 ~108 ~117 dirt
setblock ~164 ~108 ~118 dirt
setblock ~164 ~108 ~119 dirt
setblock ~164 ~108 ~120 dirt
setblock ~164 ~108 ~121 dirt
setblock ~164 ~108 ~122 dirt
setblock ~164 ~109 ~93 dirt
setblock ~164 ~109 ~95 dirt
setblock ~164 ~109 ~98 dirt
setblock ~164 ~109 ~102 dirt
setblock ~164 ~109 ~104 dirt
setblock ~164 ~109 ~116 dirt
setblock ~164 ~109 ~117 dirt
setblock ~164 ~109 ~118 dirt
setblock ~164 ~109 ~119 dirt
setblock ~164 ~109 ~120 dirt
setblock ~164 ~109 ~121 dirt
setblock ~164 ~109 ~122 dirt
setblock ~164 ~109 ~123 dirt
setblock ~164 ~110 ~93 dirt
setblock ~164 ~110 ~94 dirt
setblock ~164 ~110 ~95 dirt
setblock ~164 ~110 ~96 dirt
setblock ~164 ~110 ~97 dirt
setblock ~164 ~110 ~98 dirt
setblock ~164 ~110 ~99 dirt
setblock ~164 ~110 ~101 dirt
setblock ~164 ~110 ~102 dirt
setblock ~164 ~110 ~104 dirt
setblock ~164 ~110 ~116 dirt
setblock ~164 ~110 ~117 dirt
setblock ~164 ~110 ~118 dirt
setblock ~164 ~110 ~119 dirt
setblock ~164 ~110 ~120 dirt
setblock ~164 ~110 ~121 dirt
setblock ~164 ~110 ~122 dirt
setblock ~164 ~110 ~123 dirt
setblock ~164 ~111 ~92 dirt
setblock ~164 ~111 ~93 dirt
setblock ~164 ~111 ~94 dirt
setblock ~164 ~111 ~95 dirt
setblock ~164 ~111 ~96 dirt
setblock ~164 ~111 ~97 dirt
setblock ~164 ~111 ~98 dirt
setblock ~164 ~111 ~99 dirt
setblock ~164 ~111 ~100 dirt
setblock ~164 ~111 ~101 dirt
setblock ~164 ~111 ~102 dirt
setblock ~164 ~111 ~103 dirt
setblock ~164 ~111 ~104 dirt
setblock ~164 ~111 ~115 dirt
setblock ~164 ~111 ~116 dirt
setblock ~164 ~111 ~117 dirt
setblock ~164 ~111 ~118 dirt
setblock ~164 ~111 ~119 dirt
setblock ~164 ~111 ~120 dirt
setblock ~164 ~111 ~121 dirt
setblock ~164 ~111 ~122 dirt
setblock ~164 ~111 ~123 dirt
setblock ~164 ~112 ~91 dirt
setblock ~164 ~112 ~92 dirt
setblock ~164 ~112 ~93 dirt
setblock ~164 ~112 ~94 dirt
setblock ~164 ~112 ~95 dirt
setblock ~164 ~112 ~96 dirt
setblock ~164 ~112 ~97 dirt
setblock ~164 ~112 ~98 dirt
setblock ~164 ~112 ~99 dirt
setblock ~164 ~112 ~100 dirt
setblock ~164 ~112 ~101 dirt
setblock ~164 ~112 ~102 dirt
setblock ~164 ~112 ~103 dirt
setblock ~164 ~112 ~104 dirt
setblock ~164 ~112 ~105 dirt
setblock ~164 ~112 ~106 dirt
setblock ~164 ~112 ~114 dirt
setblock ~164 ~112 ~115 dirt
setblock ~164 ~112 ~116 dirt
setblock ~164 ~112 ~117 dirt
setblock ~164 ~112 ~118 dirt
setblock ~164 ~112 ~119 dirt
setblock ~164 ~112 ~120 dirt
setblock ~164 ~112 ~121 dirt
setblock ~164 ~112 ~122 dirt
setblock ~164 ~112 ~123 dirt
setblock ~164 ~113 ~90 dirt
setblock ~164 ~113 ~91 dirt
setblock ~164 ~113 ~92 dirt
setblock ~164 ~113 ~93 dirt
setblock ~164 ~113 ~94 dirt
setblock ~164 ~113 ~95 dirt
setblock ~164 ~113 ~96 dirt
setblock ~164 ~113 ~97 dirt
setblock ~164 ~113 ~98 dirt
setblock ~164 ~113 ~99 dirt
setblock ~164 ~113 ~100 dirt
setblock ~164 ~113 ~101 dirt
setblock ~164 ~113 ~102 dirt
setblock ~164 ~113 ~103 dirt
setblock ~164 ~113 ~104 dirt
setblock ~164 ~113 ~105 dirt
setblock ~164 ~113 ~106 dirt
setblock ~164 ~113 ~107 dirt
setblock ~164 ~113 ~114 dirt
setblock ~164 ~113 ~115 dirt
setblock ~164 ~113 ~116 dirt
setblock ~164 ~113 ~117 dirt
setblock ~164 ~113 ~118 dirt
setblock ~164 ~113 ~119 dirt
setblock ~164 ~113 ~120 dirt
setblock ~164 ~113 ~121 dirt
setblock ~164 ~113 ~122 dirt
setblock ~164 ~113 ~123 dirt
setblock ~164 ~113 ~124 dirt
setblock ~164 ~114 ~89 dirt
setblock ~164 ~114 ~90 dirt
setblock ~164 ~114 ~91 dirt
setblock ~164 ~114 ~92 dirt
setblock ~164 ~114 ~93 dirt
setblock ~164 ~114 ~94 dirt
setblock ~164 ~114 ~95 dirt
setblock ~164 ~114 ~96 dirt
setblock ~164 ~114 ~97 dirt
setblock ~164 ~114 ~98 dirt
setblock ~164 ~114 ~99 dirt
setblock ~164 ~114 ~100 dirt
setblock ~164 ~114 ~101 dirt
setblock ~164 ~114 ~102 dirt
setblock ~164 ~114 ~103 dirt
setblock ~164 ~114 ~104 dirt
setblock ~164 ~114 ~105 dirt
setblock ~164 ~114 ~106 dirt
setblock ~164 ~114 ~107 dirt
setblock ~164 ~114 ~113 dirt
setblock ~164 ~114 ~114 dirt
setblock ~164 ~114 ~115 dirt
setblock ~164 ~114 ~116 dirt
setblock ~164 ~114 ~117 dirt
setblock ~164 ~114 ~118 dirt
setblock ~164 ~114 ~119 dirt
setblock ~164 ~114 ~120 dirt
setblock ~164 ~114 ~121 dirt
setblock ~164 ~114 ~122 dirt
setblock ~164 ~114 ~123 dirt
setblock ~164 ~114 ~124 dirt
setblock ~164 ~114 ~125 dirt
setblock ~164 ~115 ~88 dirt
setblock ~164 ~115 ~89 dirt
setblock ~164 ~115 ~90 dirt
setblock ~164 ~115 ~91 dirt
setblock ~164 ~115 ~92 dirt
setblock ~164 ~115 ~93 dirt
setblock ~164 ~115 ~94 dirt
setblock ~164 ~115 ~95 dirt
setblock ~164 ~115 ~96 dirt
setblock ~164 ~115 ~97 dirt
setblock ~164 ~115 ~98 dirt
setblock ~164 ~115 ~99 dirt
setblock ~164 ~115 ~100 dirt
setblock ~164 ~115 ~101 dirt
setblock ~164 ~115 ~102 dirt
setblock ~164 ~115 ~103 dirt
setblock ~164 ~115 ~104 dirt
setblock ~164 ~115 ~105 dirt
setblock ~164 ~115 ~106 dirt
setblock ~164 ~115 ~107 dirt
setblock ~164 ~115 ~108 dirt
setblock ~164 ~115 ~113 dirt
setblock ~164 ~115 ~114 dirt
setblock ~164 ~115 ~115 dirt
setblock ~164 ~115 ~116 dirt
setblock ~164 ~115 ~117 dirt
setblock ~164 ~115 ~118 dirt
setblock ~164 ~115 ~119 dirt
setblock ~164 ~115 ~120 dirt
setblock ~164 ~115 ~121 dirt
setblock ~164 ~115 ~122 dirt
setblock ~164 ~115 ~123 dirt
setblock ~164 ~115 ~124 dirt
setblock ~164 ~115 ~125 dirt
setblock ~164 ~115 ~126 dirt
setblock ~164 ~116 ~87 dirt
setblock ~164 ~116 ~88 dirt
setblock ~164 ~116 ~89 dirt
setblock ~164 ~116 ~90 dirt
setblock ~164 ~116 ~91 dirt
setblock ~164 ~116 ~92 dirt
setblock ~164 ~116 ~93 dirt
setblock ~164 ~116 ~94 dirt
setblock ~164 ~116 ~95 dirt
setblock ~164 ~116 ~96 dirt
setblock ~164 ~116 ~97 dirt
setblock ~164 ~116 ~98 dirt
setblock ~164 ~116 ~99 dirt
setblock ~164 ~116 ~100 dirt
setblock ~164 ~116 ~101 dirt
setblock ~164 ~116 ~102 dirt
setblock ~164 ~116 ~103 dirt
setblock ~164 ~116 ~104 dirt
setblock ~164 ~116 ~105 dirt
setblock ~164 ~116 ~106 dirt
setblock ~164 ~116 ~107 dirt
setblock ~164 ~116 ~108 dirt
setblock ~164 ~116 ~112 dirt
setblock ~164 ~116 ~113 dirt
setblock ~164 ~116 ~114 dirt
setblock ~164 ~116 ~115 dirt
setblock ~164 ~116 ~116 dirt
setblock ~164 ~116 ~117 dirt
setblock ~164 ~116 ~118 dirt
setblock ~164 ~116 ~119 dirt
setblock ~164 ~116 ~120 dirt
setblock ~164 ~116 ~121 dirt
setblock ~164 ~116 ~122 dirt
setblock ~164 ~116 ~123 dirt
setblock ~164 ~116 ~124 dirt
setblock ~164 ~116 ~125 dirt
setblock ~164 ~116 ~126 dirt
setblock ~164 ~116 ~127 dirt
setblock ~164 ~117 ~81 dirt
setblock ~164 ~117 ~87 dirt
setblock ~164 ~117 ~88 dirt
setblock ~164 ~117 ~89 dirt
setblock ~164 ~117 ~90 dirt
setblock ~164 ~117 ~91 dirt
setblock ~164 ~117 ~92 dirt
setblock ~164 ~117 ~93 dirt
setblock ~164 ~117 ~94 dirt
setblock ~164 ~117 ~95 dirt
setblock ~164 ~117 ~96 dirt
setblock ~164 ~117 ~97 dirt
setblock ~164 ~117 ~98 dirt
setblock ~164 ~117 ~99 dirt
setblock ~164 ~117 ~100 dirt
setblock ~164 ~117 ~101 dirt
setblock ~164 ~117 ~102 dirt
setblock ~164 ~117 ~103 dirt
setblock ~164 ~117 ~104 dirt
setblock ~164 ~117 ~105 dirt
setblock ~164 ~117 ~106 dirt
setblock ~164 ~117 ~107 dirt
setblock ~164 ~117 ~108 dirt
setblock ~164 ~117 ~109 dirt
setblock ~164 ~117 ~112 dirt
setblock ~164 ~117 ~113 dirt
setblock ~164 ~117 ~114 dirt
setblock ~164 ~117 ~115 dirt
setblock ~164 ~117 ~116 dirt
setblock ~164 ~117 ~117 dirt
setblock ~164 ~117 ~118 dirt
setblock ~164 ~117 ~119 dirt
setblock ~164 ~117 ~120 dirt
setblock ~164 ~117 ~121 dirt
setblock ~164 ~117 ~122 dirt
setblock ~164 ~117 ~123 dirt
setblock ~164 ~117 ~124 dirt
setblock ~164 ~117 ~125 dirt
setblock ~164 ~117 ~126 dirt
setblock ~164 ~117 ~127 dirt
setblock ~164 ~118 ~81 dirt
setblock ~164 ~118 ~87 dirt
setblock ~164 ~118 ~88 dirt
setblock ~164 ~118 ~89 dirt
setblock ~164 ~118 ~90 dirt
setblock ~164 ~118 ~91 dirt
setblock ~164 ~118 ~92 dirt
setblock ~164 ~118 ~93 dirt
setblock ~164 ~118 ~94 dirt
setblock ~164 ~118 ~95 dirt
setblock ~164 ~118 ~96 dirt
setblock ~164 ~118 ~97 dirt
setblock ~164 ~118 ~98 dirt
setblock ~164 ~118 ~99 dirt
setblock ~164 ~118 ~100 dirt
setblock ~164 ~118 ~101 dirt
setblock ~164 ~118 ~102 dirt
setblock ~164 ~118 ~103 dirt
setblock ~164 ~118 ~104 dirt
setblock ~164 ~118 ~105 dirt
setblock ~164 ~118 ~106 dirt
setblock ~164 ~118 ~107 dirt
setblock ~164 ~118 ~108 dirt
setblock ~164 ~118 ~109 dirt
setblock ~164 ~118 ~110 dirt
setblock ~164 ~118 ~111 dirt
setblock ~164 ~118 ~112 dirt
setblock ~164 ~118 ~113 dirt
setblock ~164 ~118 ~114 dirt
setblock ~164 ~118 ~115 dirt
setblock ~164 ~118 ~116 dirt
setblock ~164 ~118 ~117 dirt
setblock ~164 ~118 ~118 dirt
setblock ~164 ~118 ~119 dirt
setblock ~164 ~118 ~120 dirt
setblock ~164 ~118 ~121 dirt
setblock ~164 ~118 ~122 dirt
setblock ~164 ~118 ~123 dirt
setblock ~164 ~118 ~124 dirt
setblock ~164 ~118 ~125 dirt
setblock ~164 ~118 ~126 dirt
setblock ~164 ~118 ~127 dirt
setblock ~164 ~118 ~128 dirt
setblock ~164 ~119 ~81 dirt
setblock ~164 ~119 ~87 dirt
setblock ~164 ~119 ~88 dirt
setblock ~164 ~119 ~89 dirt
setblock ~164 ~119 ~90 dirt
setblock ~164 ~119 ~91 dirt
setblock ~164 ~119 ~92 dirt
setblock ~164 ~119 ~93 dirt
setblock ~164 ~119 ~94 dirt
setblock ~164 ~119 ~95 dirt
setblock ~164 ~119 ~96 dirt
setblock ~164 ~119 ~97 dirt
setblock ~164 ~119 ~98 dirt
setblock ~164 ~119 ~99 dirt
setblock ~164 ~119 ~100 dirt
setblock ~164 ~119 ~101 dirt
setblock ~164 ~119 ~102 dirt
setblock ~164 ~119 ~103 dirt
setblock ~164 ~119 ~104 dirt
setblock ~164 ~119 ~105 dirt
setblock ~164 ~119 ~106 dirt
setblock ~164 ~119 ~107 dirt
setblock ~164 ~119 ~108 dirt
setblock ~164 ~119 ~109 dirt
setblock ~164 ~119 ~110 dirt
setblock ~164 ~119 ~111 dirt
setblock ~164 ~119 ~112 dirt
setblock ~164 ~119 ~113 dirt
setblock ~164 ~119 ~114 dirt
setblock ~164 ~119 ~115 dirt
setblock ~164 ~119 ~116 dirt
setblock ~164 ~119 ~117 dirt
setblock ~164 ~119 ~118 dirt
setblock ~164 ~119 ~119 dirt
setblock ~164 ~119 ~120 dirt
setblock ~164 ~119 ~121 dirt
setblock ~164 ~119 ~122 dirt
setblock ~164 ~119 ~123 dirt
setblock ~164 ~119 ~124 dirt
setblock ~164 ~119 ~125 dirt
setblock ~164 ~119 ~126 dirt
setblock ~164 ~119 ~127 dirt
setblock ~164 ~119 ~128 dirt
setblock ~164 ~120 ~80 dirt
setblock ~164 ~120 ~81 dirt
setblock ~164 ~120 ~82 dirt
setblock ~164 ~120 ~84 dirt
setblock ~164 ~120 ~86 dirt
setblock ~164 ~120 ~87 dirt
setblock ~164 ~120 ~88 dirt
setblock ~164 ~120 ~89 dirt
setblock ~164 ~120 ~90 dirt
setblock ~164 ~120 ~91 dirt
setblock ~164 ~120 ~92 dirt
setblock ~164 ~120 ~93 dirt
setblock ~164 ~120 ~94 dirt
setblock ~164 ~120 ~95 dirt
setblock ~164 ~120 ~96 dirt
setblock ~164 ~120 ~97 dirt
setblock ~164 ~120 ~98 dirt
setblock ~164 ~120 ~99 dirt
setblock ~164 ~120 ~100 dirt
setblock ~164 ~120 ~101 dirt
setblock ~164 ~120 ~102 dirt
setblock ~164 ~120 ~103 dirt
setblock ~164 ~120 ~104 dirt
setblock ~164 ~120 ~105 dirt
setblock ~164 ~120 ~106 dirt
setblock ~164 ~120 ~107 dirt
setblock ~164 ~120 ~108 dirt
setblock ~164 ~120 ~109 dirt
setblock ~164 ~120 ~110 dirt
setblock ~164 ~120 ~111 dirt
setblock ~164 ~120 ~112 dirt
setblock ~164 ~120 ~113 dirt
setblock ~164 ~120 ~114 dirt
setblock ~164 ~120 ~115 dirt
setblock ~164 ~120 ~116 dirt
setblock ~164 ~120 ~117 dirt
setblock ~164 ~120 ~118 dirt
setblock ~164 ~120 ~119 dirt
setblock ~164 ~120 ~120 dirt
setblock ~164 ~120 ~121 dirt
setblock ~164 ~120 ~122 dirt
setblock ~164 ~120 ~123 dirt
setblock ~164 ~120 ~124 dirt
setblock ~164 ~120 ~125 dirt
setblock ~164 ~120 ~126 dirt
setblock ~164 ~120 ~127 dirt
setblock ~164 ~120 ~128 dirt
setblock ~164 ~120 ~129 dirt
setblock ~164 ~121 ~80 dirt
setblock ~164 ~121 ~81 dirt
setblock ~164 ~121 ~82 dirt
setblock ~164 ~121 ~83 dirt
setblock ~164 ~121 ~84 dirt
setblock ~164 ~121 ~85 dirt
setblock ~164 ~121 ~86 dirt
setblock ~164 ~121 ~87 dirt
setblock ~164 ~121 ~88 dirt
setblock ~164 ~121 ~89 dirt
setblock ~164 ~121 ~90 dirt
setblock ~164 ~121 ~91 dirt
setblock ~164 ~121 ~92 dirt
setblock ~164 ~121 ~93 dirt
setblock ~164 ~121 ~94 dirt
setblock ~164 ~121 ~95 dirt
setblock ~164 ~121 ~96 dirt
setblock ~164 ~121 ~97 dirt
setblock ~164 ~121 ~98 dirt
setblock ~164 ~121 ~99 dirt
setblock ~164 ~121 ~100 dirt
setblock ~164 ~121 ~101 dirt
setblock ~164 ~121 ~102 dirt
setblock ~164 ~121 ~103 dirt
setblock ~164 ~121 ~104 dirt
setblock ~164 ~121 ~105 dirt
setblock ~164 ~121 ~106 dirt
setblock ~164 ~121 ~107 dirt
setblock ~164 ~121 ~108 dirt
setblock ~164 ~121 ~109 dirt
setblock ~164 ~121 ~110 dirt
setblock ~164 ~121 ~111 dirt
setblock ~164 ~121 ~112 dirt
setblock ~164 ~121 ~113 dirt
setblock ~164 ~121 ~114 dirt
setblock ~164 ~121 ~115 dirt
setblock ~164 ~121 ~116 dirt
setblock ~164 ~121 ~117 dirt
setblock ~164 ~121 ~118 dirt
setblock ~164 ~121 ~119 dirt
setblock ~164 ~121 ~120 dirt
setblock ~164 ~121 ~121 dirt
setblock ~164 ~121 ~122 dirt
setblock ~164 ~121 ~123 dirt
setblock ~164 ~121 ~124 dirt
setblock ~164 ~121 ~125 dirt
setblock ~164 ~121 ~126 dirt
setblock ~164 ~121 ~127 dirt
setblock ~164 ~121 ~128 dirt
setblock ~164 ~121 ~129 dirt
setblock ~164 ~121 ~130 dirt
setblock ~164 ~122 ~80 grass_block
setblock ~164 ~122 ~81 grass_block
setblock ~164 ~122 ~82 dirt
setblock ~164 ~122 ~83 dirt
setblock ~164 ~122 ~84 dirt
setblock ~164 ~122 ~85 dirt
setblock ~164 ~122 ~86 dirt
setblock ~164 ~122 ~87 dirt
setblock ~164 ~122 ~88 dirt
setblock ~164 ~122 ~89 dirt
setblock ~164 ~122 ~90 dirt
setblock ~164 ~122 ~91 dirt
setblock ~164 ~122 ~92 dirt
setblock ~164 ~122 ~93 dirt
setblock ~164 ~122 ~94 dirt
setblock ~164 ~122 ~95 dirt
setblock ~164 ~122 ~96 dirt
setblock ~164 ~122 ~97 dirt
setblock ~164 ~122 ~98 dirt
setblock ~164 ~122 ~99 dirt
setblock ~164 ~122 ~100 dirt
setblock ~164 ~122 ~101 dirt
setblock ~164 ~122 ~102 dirt
setblock ~164 ~122 ~103 dirt
setblock ~164 ~122 ~104 dirt
setblock ~164 ~122 ~105 dirt
setblock ~164 ~122 ~106 dirt
setblock ~164 ~122 ~107 dirt
setblock ~164 ~122 ~108 dirt
setblock ~164 ~122 ~109 dirt
setblock ~164 ~122 ~110 dirt
setblock ~164 ~122 ~111 dirt
setblock ~164 ~122 ~112 dirt
setblock ~164 ~122 ~113 dirt
setblock ~164 ~122 ~114 dirt
setblock ~164 ~122 ~115 dirt
setblock ~164 ~122 ~116 dirt
setblock ~164 ~122 ~117 dirt
setblock ~164 ~122 ~118 dirt
setblock ~164 ~122 ~119 dirt
setblock ~164 ~122 ~120 dirt
setblock ~164 ~122 ~121 dirt
setblock ~164 ~122 ~122 dirt
setblock ~164 ~122 ~123 dirt
setblock ~164 ~122 ~124 dirt
setblock ~164 ~122 ~125 dirt
setblock ~164 ~122 ~126 dirt
setblock ~164 ~122 ~127 dirt
setblock ~164 ~122 ~128 dirt
setblock ~164 ~122 ~129 dirt
setblock ~164 ~122 ~130 dirt
setblock ~164 ~123 ~81 fern
setblock ~164 ~123 ~82 grass_block
setblock ~164 ~123 ~83 grass_block
setblock ~164 ~123 ~84 grass_block
setblock ~164 ~123 ~85 dirt
setblock ~164 ~123 ~86 dirt
setblock ~164 ~123 ~87 dirt
setblock ~164 ~123 ~88 dirt
setblock ~164 ~123 ~89 dirt
setblock ~164 ~123 ~90 dirt
setblock ~164 ~123 ~91 dirt
setblock ~164 ~123 ~92 dirt
setblock ~164 ~123 ~93 dirt
setblock ~164 ~123 ~94 dirt
setblock ~164 ~123 ~95 dirt
setblock ~164 ~123 ~96 dirt
setblock ~164 ~123 ~97 dirt
setblock ~164 ~123 ~98 dirt
setblock ~164 ~123 ~99 dirt
setblock ~164 ~123 ~100 dirt
setblock ~164 ~123 ~101 dirt
setblock ~164 ~123 ~102 dirt
setblock ~164 ~123 ~103 dirt
setblock ~164 ~123 ~104 dirt
setblock ~164 ~123 ~105 dirt
setblock ~164 ~123 ~106 dirt
setblock ~164 ~123 ~107 dirt
setblock ~164 ~123 ~108 dirt
setblock ~164 ~123 ~109 grass_block
setblock ~164 ~123 ~110 grass_block
setblock ~164 ~123 ~111 grass_block
setblock ~164 ~123 ~112 dirt
setblock ~164 ~123 ~113 dirt
setblock ~164 ~123 ~114 dirt
setblock ~164 ~123 ~115 dirt
setblock ~164 ~123 ~116 dirt
setblock ~164 ~123 ~117 dirt
setblock ~164 ~123 ~118 dirt
setblock ~164 ~123 ~119 dirt
setblock ~164 ~123 ~120 dirt
setblock ~164 ~123 ~121 dirt
setblock ~164 ~123 ~122 dirt
setblock ~164 ~123 ~123 dirt
setblock ~164 ~123 ~124 dirt
setblock ~164 ~123 ~125 dirt
setblock ~164 ~123 ~126 dirt
setblock ~164 ~123 ~127 grass_block
setblock ~164 ~123 ~128 grass_block
setblock ~164 ~123 ~129 grass_block
setblock ~164 ~123 ~130 grass_block
setblock ~164 ~124 ~82 short_grass
setblock ~164 ~124 ~85 grass_block
setblock ~164 ~124 ~86 grass_block
setblock ~164 ~124 ~87 dirt
setblock ~164 ~124 ~88 dirt
setblock ~164 ~124 ~89 dirt
setblock ~164 ~124 ~90 dirt
setblock ~164 ~124 ~91 dirt
setblock ~164 ~124 ~92 dirt
setblock ~164 ~124 ~93 dirt
setblock ~164 ~124 ~94 dirt
setblock ~164 ~124 ~95 dirt
setblock ~164 ~124 ~96 dirt
setblock ~164 ~124 ~97 dirt
setblock ~164 ~124 ~98 dirt
setblock ~164 ~124 ~99 dirt
setblock ~164 ~124 ~100 dirt
setblock ~164 ~124 ~101 dirt
setblock ~164 ~124 ~102 dirt
setblock ~164 ~124 ~103 dirt
setblock ~164 ~124 ~104 dirt
setblock ~164 ~124 ~105 grass_block
setblock ~164 ~124 ~106 grass_block
setblock ~164 ~124 ~107 grass_block
setblock ~164 ~124 ~108 grass_block
setblock ~164 ~124 ~109 short_grass
setblock ~164 ~124 ~112 grass_block
setblock ~164 ~124 ~113 grass_block
setblock ~164 ~124 ~114 grass_block
setblock ~164 ~124 ~115 grass_block
setblock ~164 ~124 ~116 grass_block
setblock ~164 ~124 ~117 dirt
setblock ~164 ~124 ~118 dirt
setblock ~164 ~124 ~119 dirt
setblock ~164 ~124 ~120 dirt
setblock ~164 ~124 ~121 dirt
setblock ~164 ~124 ~122 dirt
setblock ~164 ~124 ~123 grass_block
setblock ~164 ~124 ~124 grass_block
setblock ~164 ~124 ~125 grass_block
setblock ~164 ~124 ~126 grass_block
setblock ~164 ~124 ~129 fern
setblock ~164 ~124 ~130 short_grass
setblock ~164 ~125 ~87 grass_block
setblock ~164 ~125 ~88 grass_block
setblock ~164 ~125 ~89 grass_block
setblock ~164 ~125 ~90 dirt
setblock ~164 ~125 ~91 dirt
setblock ~164 ~125 ~92 dirt
setblock ~164 ~125 ~93 dirt
setblock ~164 ~125 ~94 dirt
setblock ~164 ~125 ~95 dirt
setblock ~164 ~125 ~96 dirt
setblock ~164 ~125 ~97 dirt
setblock ~164 ~125 ~98 dirt
setblock ~164 ~125 ~99 dirt
setblock ~164 ~125 ~100 dirt
setblock ~164 ~125 ~101 grass_block
setblock ~164 ~125 ~102 grass_block
setblock ~164 ~125 ~103 grass_block
setblock ~164 ~125 ~104 grass_block
setblock ~164 ~125 ~106 short_grass
setblock ~164 ~125 ~117 grass_block
setblock ~164 ~125 ~118 grass_block
setblock ~164 ~125 ~119 grass_block
setblock ~164 ~125 ~120 grass_block
setblock ~164 ~125 ~121 grass_block
setblock ~164 ~125 ~122 grass_block
setblock ~164 ~125 ~123 short_grass
setblock ~164 ~125 ~124 short_grass
setblock ~164 ~126 ~90 grass_block
setblock ~164 ~126 ~91 grass_block
setblock ~164 ~126 ~92 grass_block
setblock ~164 ~126 ~93 grass_block
setblock ~164 ~126 ~94 grass_block
setblock ~164 ~126 ~95 grass_block
setblock ~164 ~126 ~96 grass_block
setblock ~164 ~126 ~97 grass_block
setblock ~164 ~126 ~98 grass_block
setblock ~164 ~126 ~99 grass_block
setblock ~164 ~126 ~100 grass_block
setblock ~164 ~126 ~101 short_grass
setblock ~164 ~126 ~103 short_grass
setblock ~164 ~126 ~118 short_grass
setblock ~164 ~126 ~119 poppy
setblock ~164 ~126 ~121 short_grass
setblock ~164 ~126 ~122 short_grass
setblock ~164 ~127 ~91 fern
setblock ~164 ~127 ~96 poppy
setblock ~164 ~127 ~97 short_grass
setblock ~164 ~127 ~98 short_grass
setblock ~165 ~108 ~120 dirt
setblock ~165 ~109 ~120 dirt
setblock ~165 ~109 ~122 dirt
setblock ~165 ~110 ~95 dirt
setblock ~165 ~110 ~98 dirt
setblock ~165 ~110 ~119 dirt
setblock ~165 ~110 ~120 dirt
setblock ~165 ~110 ~121 dirt
setblock ~165 ~110 ~122 dirt
setblock ~165 ~110 ~123 dirt
setblock ~165 ~111 ~93 dirt
setblock ~165 ~111 ~94 dirt
setblock ~165 ~111 ~95 dirt
setblock ~165 ~111 ~96 dirt
setblock ~165 ~111 ~97 dirt
setblock ~165 ~111 ~98 dirt
setblock ~165 ~111 ~99 dirt
setblock ~165 ~111 ~116 dirt
setblock ~165 ~111 ~117 dirt
setblock ~165 ~111 ~119 dirt
setblock ~165 ~111 ~120 dirt
setblock ~165 ~111 ~121 dirt
setblock ~165 ~111 ~122 dirt
setblock ~165 ~111 ~123 dirt
setblock ~165 ~112 ~92 dirt
setblock ~165 ~112 ~93 dirt
setblock ~165 ~112 ~94 dirt
setblock ~165 ~112 ~95 dirt
setblock ~165 ~112 ~96 dirt
setblock ~165 ~112 ~97 dirt
setblock ~165 ~112 ~98 dirt
setblock ~165 ~112 ~99 dirt
setblock ~165 ~112 ~100 dirt
setblock ~165 ~112 ~102 dirt
setblock ~165 ~112 ~104 dirt
setblock ~165 ~112 ~115 dirt
setblock ~165 ~112 ~116 dirt
setblock ~165 ~112 ~117 dirt
setblock ~165 ~112 ~118 dirt
setblock ~165 ~112 ~119 dirt
setblock ~165 ~112 ~120 dirt
setblock ~165 ~112 ~121 dirt
