setblock ~62 ~122 ~105 dirt
setblock ~62 ~122 ~106 dirt
setblock ~62 ~122 ~107 dirt
setblock ~62 ~122 ~108 dirt
setblock ~62 ~122 ~109 dirt
setblock ~62 ~122 ~110 dirt
setblock ~62 ~122 ~111 dirt
setblock ~62 ~122 ~112 dirt
setblock ~62 ~122 ~113 dirt
setblock ~62 ~122 ~114 dirt
setblock ~62 ~122 ~115 dirt
setblock ~62 ~122 ~116 dirt
setblock ~62 ~122 ~117 dirt
setblock ~62 ~122 ~118 dirt
setblock ~62 ~122 ~119 dirt
setblock ~62 ~123 ~77 grass_block
setblock ~62 ~123 ~78 grass_block
setblock ~62 ~123 ~79 grass_block
setblock ~62 ~123 ~80 grass_block
setblock ~62 ~123 ~81 grass_block
setblock ~62 ~123 ~82 grass_block
setblock ~62 ~123 ~83 grass_block
setblock ~62 ~123 ~84 grass_block
setblock ~62 ~123 ~85 grass_block
setblock ~62 ~123 ~86 grass_block
setblock ~62 ~123 ~87 grass_block
setblock ~62 ~123 ~88 dirt
setblock ~62 ~123 ~89 dirt
setblock ~62 ~123 ~90 dirt
setblock ~62 ~123 ~91 dirt
setblock ~62 ~123 ~92 dirt
setblock ~62 ~123 ~93 dirt
setblock ~62 ~123 ~94 dirt
setblock ~62 ~123 ~95 dirt
setblock ~62 ~123 ~96 dirt
setblock ~62 ~123 ~97 dirt
setblock ~62 ~123 ~98 dirt
setblock ~62 ~123 ~99 dirt
setblock ~62 ~123 ~100 dirt
setblock ~62 ~123 ~101 dirt
setblock ~62 ~123 ~102 dirt
setblock ~62 ~123 ~103 dirt
setblock ~62 ~123 ~104 dirt
setblock ~62 ~123 ~105 dirt
setblock ~62 ~123 ~106 dirt
setblock ~62 ~123 ~107 dirt
setblock ~62 ~123 ~108 dirt
setblock ~62 ~123 ~109 dirt
setblock ~62 ~123 ~110 dirt
setblock ~62 ~123 ~111 dirt
setblock ~62 ~123 ~112 dirt
setblock ~62 ~123 ~113 dirt
setblock ~62 ~123 ~114 dirt
setblock ~62 ~123 ~115 dirt
setblock ~62 ~123 ~116 dirt
setblock ~62 ~123 ~117 dirt
setblock ~62 ~123 ~118 dirt
setblock ~62 ~123 ~119 dirt
setblock ~62 ~124 ~79 fern
setblock ~62 ~124 ~84 short_grass
setblock ~62 ~124 ~87 short_grass
setblock ~62 ~124 ~88 grass_block
setblock ~62 ~124 ~89 grass_block
setblock ~62 ~124 ~90 grass_block
setblock ~62 ~124 ~91 grass_block
setblock ~62 ~124 ~92 grass_block
setblock ~62 ~124 ~93 grass_block
setblock ~62 ~124 ~94 dirt
setblock ~62 ~124 ~95 dirt
setblock ~62 ~124 ~96 dirt
setblock ~62 ~124 ~97 dirt
setblock ~62 ~124 ~98 dirt
setblock ~62 ~124 ~99 dirt
setblock ~62 ~124 ~100 dirt
setblock ~62 ~124 ~101 dirt
setblock ~62 ~124 ~102 dirt
setblock ~62 ~124 ~103 dirt
setblock ~62 ~124 ~104 dirt
setblock ~62 ~124 ~105 dirt
setblock ~62 ~124 ~106 dirt
setblock ~62 ~124 ~107 dirt
setblock ~62 ~124 ~108 dirt
setblock ~62 ~124 ~109 dirt
setblock ~62 ~124 ~110 dirt
setblock ~62 ~124 ~111 dirt
setblock ~62 ~124 ~112 dirt
setblock ~62 ~124 ~113 dirt
setblock ~62 ~124 ~114 dirt
setblock ~62 ~124 ~115 dirt
setblock ~62 ~124 ~116 dirt
setblock ~62 ~124 ~117 dirt
setblock ~62 ~124 ~118 dirt
setblock ~62 ~124 ~119 dirt
setblock ~62 ~125 ~94 grass_block
setblock ~62 ~125 ~95 grass_block
setblock ~62 ~125 ~96 grass_block
setblock ~62 ~125 ~97 dirt
setblock ~62 ~125 ~98 dirt
setblock ~62 ~125 ~99 dirt
setblock ~62 ~125 ~100 dirt
setblock ~62 ~125 ~101 dirt
setblock ~62 ~125 ~102 dirt
setblock ~62 ~125 ~103 dirt
setblock ~62 ~125 ~104 dirt
setblock ~62 ~125 ~105 dirt
setblock ~62 ~125 ~106 dirt
setblock ~62 ~125 ~107 dirt
setblock ~62 ~125 ~108 dirt
setblock ~62 ~125 ~109 dirt
setblock ~62 ~125 ~110 dirt
setblock ~62 ~125 ~111 dirt
setblock ~62 ~125 ~112 dirt
setblock ~62 ~125 ~113 dirt
setblock ~62 ~125 ~114 dirt
setblock ~62 ~125 ~115 dirt
setblock ~62 ~125 ~116 dirt
setblock ~62 ~125 ~117 dirt
setblock ~62 ~125 ~118 dirt
setblock ~62 ~125 ~119 dirt
setblock ~62 ~126 ~97 grass_block
setblock ~62 ~126 ~98 grass_block
setblock ~62 ~126 ~99 dirt
setblock ~62 ~126 ~100 dirt
setblock ~62 ~126 ~101 dirt
setblock ~62 ~126 ~102 dirt
setblock ~62 ~126 ~103 dirt
setblock ~62 ~126 ~104 dirt
setblock ~62 ~126 ~105 dirt
setblock ~62 ~126 ~106 dirt
setblock ~62 ~126 ~107 dirt
setblock ~62 ~126 ~108 dirt
setblock ~62 ~126 ~109 dirt
setblock ~62 ~126 ~110 dirt
setblock ~62 ~126 ~111 dirt
setblock ~62 ~126 ~112 dirt
setblock ~62 ~126 ~113 dirt
setblock ~62 ~126 ~114 dirt
setblock ~62 ~126 ~115 dirt
setblock ~62 ~126 ~116 dirt
setblock ~62 ~126 ~117 dirt
setblock ~62 ~126 ~118 grass_block
setblock ~62 ~126 ~119 grass_block
setblock ~62 ~127 ~99 grass_block
setblock ~62 ~127 ~100 dirt
setblock ~62 ~127 ~101 dirt
setblock ~62 ~127 ~102 dirt
setblock ~62 ~127 ~103 dirt
setblock ~62 ~127 ~104 dirt
setblock ~62 ~127 ~105 dirt
setblock ~62 ~127 ~106 dirt
setblock ~62 ~127 ~107 dirt
setblock ~62 ~127 ~108 dirt
setblock ~62 ~127 ~109 dirt
setblock ~62 ~127 ~110 dirt
setblock ~62 ~127 ~111 dirt
setblock ~62 ~127 ~112 dirt
setblock ~62 ~127 ~113 dirt
setblock ~62 ~127 ~114 grass_block
setblock ~62 ~127 ~115 grass_block
setblock ~62 ~127 ~116 grass_block
setblock ~62 ~127 ~117 grass_block
setblock ~62 ~128 ~100 dirt
setblock ~62 ~128 ~101 dirt
setblock ~62 ~128 ~102 dirt
setblock ~62 ~128 ~103 dirt
setblock ~62 ~128 ~104 dirt
setblock ~62 ~128 ~105 grass_block
setblock ~62 ~128 ~106 grass_block
setblock ~62 ~128 ~107 grass_block
setblock ~62 ~128 ~108 grass_block
setblock ~62 ~128 ~109 grass_block
setblock ~62 ~128 ~110 grass_block
setblock ~62 ~128 ~111 grass_block
setblock ~62 ~128 ~112 grass_block
setblock ~62 ~128 ~113 grass_block
setblock ~62 ~128 ~116 short_grass
setblock ~62 ~129 ~100 grass_block
setblock ~62 ~129 ~101 grass_block
setblock ~62 ~129 ~102 grass_block
setblock ~62 ~129 ~103 grass_block
setblock ~62 ~129 ~104 grass_block
setblock ~62 ~129 ~105 short_grass
setblock ~62 ~129 ~109 short_grass
setblock ~62 ~130 ~101 short_grass
setblock ~63 ~104 ~101 dirt
setblock ~63 ~105 ~100 dirt
setblock ~63 ~105 ~101 dirt
setblock ~63 ~105 ~102 dirt
setblock ~63 ~106 ~100 dirt
setblock ~63 ~106 ~101 dirt
setblock ~63 ~106 ~102 dirt
setblock ~63 ~107 ~100 dirt
setblock ~63 ~107 ~101 dirt
setblock ~63 ~107 ~102 dirt
setblock ~63 ~107 ~108 dirt
setblock ~63 ~108 ~90 dirt
setblock ~63 ~108 ~96 dirt
setblock ~63 ~108 ~99 dirt
setblock ~63 ~108 ~100 dirt
setblock ~63 ~108 ~101 dirt
setblock ~63 ~108 ~102 dirt
setblock ~63 ~108 ~103 dirt
setblock ~63 ~108 ~107 dirt
setblock ~63 ~108 ~108 dirt
setblock ~63 ~108 ~109 dirt
setblock ~63 ~109 ~87 dirt
setblock ~63 ~109 ~89 dirt
setblock ~63 ~109 ~90 dirt
setblock ~63 ~109 ~91 dirt
setblock ~63 ~109 ~94 dirt
setblock ~63 ~109 ~96 dirt
setblock ~63 ~109 ~97 dirt
setblock ~63 ~109 ~98 dirt
setblock ~63 ~109 ~99 dirt
setblock ~63 ~109 ~100 dirt
setblock ~63 ~109 ~101 dirt
setblock ~63 ~109 ~102 dirt
setblock ~63 ~109 ~103 dirt
setblock ~63 ~109 ~106 dirt
setblock ~63 ~109 ~107 dirt
setblock ~63 ~109 ~108 dirt
setblock ~63 ~109 ~109 dirt
setblock ~63 ~110 ~86 dirt
setblock ~63 ~110 ~87 dirt
setblock ~63 ~110 ~88 dirt
setblock ~63 ~110 ~89 dirt
setblock ~63 ~110 ~90 dirt
setblock ~63 ~110 ~91 dirt
setblock ~63 ~110 ~92 dirt
setblock ~63 ~110 ~93 dirt
setblock ~63 ~110 ~94 dirt
setblock ~63 ~110 ~95 dirt
setblock ~63 ~110 ~96 dirt
setblock ~63 ~110 ~97 dirt
setblock ~63 ~110 ~98 dirt
setblock ~63 ~110 ~99 dirt
setblock ~63 ~110 ~100 dirt
setblock ~63 ~110 ~101 dirt
setblock ~63 ~110 ~102 dirt
setblock ~63 ~110 ~103 dirt
setblock ~63 ~110 ~104 dirt
setblock ~63 ~110 ~106 dirt
setblock ~63 ~110 ~107 dirt
setblock ~63 ~110 ~108 dirt
setblock ~63 ~110 ~109 dirt
setblock ~63 ~111 ~85 dirt
setblock ~63 ~111 ~86 dirt
setblock ~63 ~111 ~87 dirt
setblock ~63 ~111 ~88 dirt
setblock ~63 ~111 ~89 dirt
setblock ~63 ~111 ~90 dirt
setblock ~63 ~111 ~91 dirt
setblock ~63 ~111 ~92 dirt
setblock ~63 ~111 ~93 dirt
setblock ~63 ~111 ~94 dirt
setblock ~63 ~111 ~95 dirt
setblock ~63 ~111 ~96 dirt
setblock ~63 ~111 ~97 dirt
setblock ~63 ~111 ~98 dirt
setblock ~63 ~111 ~99 dirt
setblock ~63 ~111 ~100 dirt
setblock ~63 ~111 ~101 dirt
setblock ~63 ~111 ~102 dirt
setblock ~63 ~111 ~103 dirt
setblock ~63 ~111 ~104 dirt
setblock ~63 ~111 ~106 dirt
setblock ~63 ~111 ~107 dirt
setblock ~63 ~111 ~108 dirt
setblock ~63 ~111 ~109 dirt
setblock ~63 ~111 ~110 dirt
setblock ~63 ~112 ~82 dirt
setblock ~63 ~112 ~83 dirt
setblock ~63 ~112 ~85 dirt
setblock ~63 ~112 ~86 dirt
setblock ~63 ~112 ~87 dirt
setblock ~63 ~112 ~88 dirt
setblock ~63 ~112 ~89 dirt
setblock ~63 ~112 ~90 dirt
setblock ~63 ~112 ~91 dirt
setblock ~63 ~112 ~92 dirt
setblock ~63 ~112 ~93 dirt
setblock ~63 ~112 ~94 dirt
setblock ~63 ~112 ~95 dirt
setblock ~63 ~112 ~96 dirt
setblock ~63 ~112 ~97 dirt
setblock ~63 ~112 ~98 dirt
setblock ~63 ~112 ~99 dirt
setblock ~63 ~112 ~100 dirt
setblock ~63 ~112 ~101 dirt
setblock ~63 ~112 ~102 dirt
setblock ~63 ~112 ~103 dirt
setblock ~63 ~112 ~104 dirt
setblock ~63 ~112 ~105 dirt
setblock ~63 ~112 ~106 dirt
setblock ~63 ~112 ~107 dirt
setblock ~63 ~112 ~108 dirt
setblock ~63 ~112 ~109 dirt
setblock ~63 ~112 ~110 dirt
setblock ~63 ~112 ~111 dirt
setblock ~63 ~113 ~82 dirt
setblock ~63 ~113 ~83 dirt
setblock ~63 ~113 ~84 dirt
setblock ~63 ~113 ~85 dirt
setblock ~63 ~113 ~86 dirt
setblock ~63 ~113 ~87 dirt
setblock ~63 ~113 ~88 dirt
setblock ~63 ~113 ~89 dirt
setblock ~63 ~113 ~90 dirt
setblock ~63 ~113 ~91 dirt
setblock ~63 ~113 ~92 dirt
setblock ~63 ~113 ~93 dirt
setblock ~63 ~113 ~94 dirt
setblock ~63 ~113 ~95 dirt
setblock ~63 ~113 ~96 dirt
setblock ~63 ~113 ~97 dirt
setblock ~63 ~113 ~98 dirt
setblock ~63 ~113 ~99 dirt
setblock ~63 ~113 ~100 dirt
setblock ~63 ~113 ~101 dirt
setblock ~63 ~113 ~102 dirt
setblock ~63 ~113 ~103 dirt
setblock ~63 ~113 ~104 dirt
setblock ~63 ~113 ~105 dirt
setblock ~63 ~113 ~106 dirt
setblock ~63 ~113 ~107 dirt
setblock ~63 ~113 ~108 dirt
setblock ~63 ~113 ~109 dirt
setblock ~63 ~113 ~110 dirt
setblock ~63 ~113 ~111 dirt
setblock ~63 ~113 ~112 dirt
setblock ~63 ~114 ~80 dirt
setblock ~63 ~114 ~81 dirt
setblock ~63 ~114 ~82 dirt
setblock ~63 ~114 ~83 dirt
setblock ~63 ~114 ~84 dirt
setblock ~63 ~114 ~85 dirt
setblock ~63 ~114 ~86 dirt
setblock ~63 ~114 ~87 dirt
setblock ~63 ~114 ~88 dirt
setblock ~63 ~114 ~89 dirt
setblock ~63 ~114 ~90 dirt
setblock ~63 ~114 ~91 dirt
setblock ~63 ~114 ~92 dirt
setblock ~63 ~114 ~93 dirt
setblock ~63 ~114 ~94 dirt
setblock ~63 ~114 ~95 dirt
setblock ~63 ~114 ~96 dirt
setblock ~63 ~114 ~97 dirt
setblock ~63 ~114 ~98 dirt
setblock ~63 ~114 ~99 dirt
setblock ~63 ~114 ~100 dirt
setblock ~63 ~114 ~101 dirt
setblock ~63 ~114 ~102 dirt
setblock ~63 ~114 ~103 dirt
setblock ~63 ~114 ~104 dirt
setblock ~63 ~114 ~105 dirt
setblock ~63 ~114 ~106 dirt
setblock ~63 ~114 ~107 dirt
setblock ~63 ~114 ~108 dirt
setblock ~63 ~114 ~109 dirt
setblock ~63 ~114 ~110 dirt
setblock ~63 ~114 ~111 dirt
setblock ~63 ~114 ~112 dirt
setblock ~63 ~114 ~113 dirt
setblock ~63 ~114 ~114 dirt
setblock ~63 ~115 ~80 dirt
setblock ~63 ~115 ~81 dirt
setblock ~63 ~115 ~82 dirt
setblock ~63 ~115 ~83 dirt
setblock ~63 ~115 ~84 dirt
setblock ~63 ~115 ~85 dirt
setblock ~63 ~115 ~86 dirt
setblock ~63 ~115 ~87 dirt
setblock ~63 ~115 ~88 dirt
setblock ~63 ~115 ~89 dirt
setblock ~63 ~115 ~90 dirt
setblock ~63 ~115 ~91 dirt
setblock ~63 ~115 ~92 dirt
setblock ~63 ~115 ~93 dirt
setblock ~63 ~115 ~94 dirt
setblock ~63 ~115 ~95 dirt
setblock ~63 ~115 ~96 dirt
setblock ~63 ~115 ~97 dirt
setblock ~63 ~115 ~98 dirt
setblock ~63 ~115 ~99 dirt
setblock ~63 ~115 ~100 dirt
setblock ~63 ~115 ~101 dirt
setblock ~63 ~115 ~102 dirt
setblock ~63 ~115 ~103 dirt
setblock ~63 ~115 ~104 dirt
setblock ~63 ~115 ~105 dirt
setblock ~63 ~115 ~106 dirt
setblock ~63 ~115 ~107 dirt
setblock ~63 ~115 ~108 dirt
setblock ~63 ~115 ~109 dirt
setblock ~63 ~115 ~110 dirt
setblock ~63 ~115 ~111 dirt
setblock ~63 ~115 ~112 dirt
setblock ~63 ~115 ~113 dirt
setblock ~63 ~115 ~114 dirt
setblock ~63 ~115 ~115 dirt
setblock ~63 ~116 ~79 dirt
setblock ~63 ~116 ~80 dirt
setblock ~63 ~116 ~81 dirt
setblock ~63 ~116 ~82 dirt
setblock ~63 ~116 ~83 dirt
setblock ~63 ~116 ~84 dirt
setblock ~63 ~116 ~85 dirt
setblock ~63 ~116 ~86 dirt
setblock ~63 ~116 ~87 dirt
setblock ~63 ~116 ~88 dirt
setblock ~63 ~116 ~89 dirt
setblock ~63 ~116 ~90 dirt
setblock ~63 ~116 ~91 dirt
setblock ~63 ~116 ~92 dirt
setblock ~63 ~116 ~93 dirt
setblock ~63 ~116 ~94 dirt
setblock ~63 ~116 ~95 dirt
setblock ~63 ~116 ~96 dirt
setblock ~63 ~116 ~97 dirt
setblock ~63 ~116 ~98 dirt
setblock ~63 ~116 ~99 dirt
setblock ~63 ~116 ~100 dirt
setblock ~63 ~116 ~101 dirt
setblock ~63 ~116 ~102 dirt
setblock ~63 ~116 ~103 dirt
setblock ~63 ~116 ~104 dirt
setblock ~63 ~116 ~105 dirt
setblock ~63 ~116 ~106 dirt
setblock ~63 ~116 ~107 dirt
setblock ~63 ~116 ~108 dirt
setblock ~63 ~116 ~109 dirt
setblock ~63 ~116 ~110 dirt
setblock ~63 ~116 ~111 dirt
setblock ~63 ~116 ~112 dirt
setblock ~63 ~116 ~113 dirt
setblock ~63 ~116 ~114 dirt
setblock ~63 ~116 ~115 dirt
setblock ~63 ~117 ~79 dirt
setblock ~63 ~117 ~80 dirt
setblock ~63 ~117 ~81 dirt
setblock ~63 ~117 ~82 dirt
setblock ~63 ~117 ~83 dirt
setblock ~63 ~117 ~84 dirt
setblock ~63 ~117 ~85 dirt
setblock ~63 ~117 ~86 dirt
setblock ~63 ~117 ~87 dirt
setblock ~63 ~117 ~88 dirt
setblock ~63 ~117 ~89 dirt
setblock ~63 ~117 ~90 dirt
setblock ~63 ~117 ~91 dirt
setblock ~63 ~117 ~92 dirt
setblock ~63 ~117 ~93 dirt
setblock ~63 ~117 ~94 dirt
setblock ~63 ~117 ~95 dirt
setblock ~63 ~117 ~96 dirt
setblock ~63 ~117 ~97 dirt
setblock ~63 ~117 ~98 dirt
setblock ~63 ~117 ~99 dirt
setblock ~63 ~117 ~100 dirt
setblock ~63 ~117 ~101 dirt
setblock ~63 ~117 ~102 dirt
setblock ~63 ~117 ~103 dirt
setblock ~63 ~117 ~104 dirt
setblock ~63 ~117 ~105 dirt
setblock ~63 ~117 ~106 dirt
setblock ~63 ~117 ~107 dirt
setblock ~63 ~117 ~108 dirt
setblock ~63 ~117 ~109 dirt
setblock ~63 ~117 ~110 dirt
setblock ~63 ~117 ~111 dirt
setblock ~63 ~117 ~112 dirt
setblock ~63 ~117 ~113 dirt
setblock ~63 ~117 ~114 dirt
setblock ~63 ~117 ~115 dirt
setblock ~63 ~117 ~116 dirt
setblock ~63 ~117 ~117 dirt
setblock ~63 ~118 ~78 dirt
setblock ~63 ~118 ~79 dirt
setblock ~63 ~118 ~80 dirt
setblock ~63 ~118 ~81 dirt
setblock ~63 ~118 ~82 dirt
setblock ~63 ~118 ~83 dirt
setblock ~63 ~118 ~84 dirt
setblock ~63 ~118 ~85 dirt
setblock ~63 ~118 ~86 dirt
setblock ~63 ~118 ~87 dirt
setblock ~63 ~118 ~88 dirt
setblock ~63 ~118 ~89 dirt
setblock ~63 ~118 ~90 dirt
setblock ~63 ~118 ~91 dirt
setblock ~63 ~118 ~92 dirt
setblock ~63 ~118 ~93 dirt
setblock ~63 ~118 ~94 dirt
setblock ~63 ~118 ~95 dirt
setblock ~63 ~118 ~96 dirt
setblock ~63 ~118 ~97 dirt
setblock ~63 ~118 ~98 dirt
setblock ~63 ~118 ~99 dirt
setblock ~63 ~118 ~100 dirt
setblock ~63 ~118 ~101 dirt
setblock ~63 ~118 ~102 dirt
setblock ~63 ~118 ~103 dirt
setblock ~63 ~118 ~104 dirt
setblock ~63 ~118 ~105 dirt
setblock ~63 ~118 ~106 dirt
setblock ~63 ~118 ~107 dirt
setblock ~63 ~118 ~108 dirt
setblock ~63 ~118 ~109 dirt
setblock ~63 ~118 ~110 dirt
setblock ~63 ~118 ~111 dirt
setblock ~63 ~118 ~112 dirt
setblock ~63 ~118 ~113 dirt
setblock ~63 ~118 ~114 dirt
setblock ~63 ~118 ~115 dirt
setblock ~63 ~118 ~116 dirt
setblock ~63 ~118 ~117 dirt
setblock ~63 ~118 ~118 dirt
setblock ~63 ~119 ~77 dirt
setblock ~63 ~119 ~78 dirt
setblock ~63 ~119 ~79 dirt
setblock ~63 ~119 ~80 dirt
setblock ~63 ~119 ~81 dirt
setblock ~63 ~119 ~82 dirt
setblock ~63 ~119 ~83 dirt
setblock ~63 ~119 ~84 dirt
setblock ~63 ~119 ~85 dirt
setblock ~63 ~119 ~86 dirt
setblock ~63 ~119 ~87 dirt
setblock ~63 ~119 ~88 dirt
setblock ~63 ~119 ~89 dirt
setblock ~63 ~119 ~90 dirt
setblock ~63 ~119 ~91 dirt
setblock ~63 ~119 ~92 dirt
setblock ~63 ~119 ~93 dirt
setblock ~63 ~119 ~94 dirt
setblock ~63 ~119 ~95 dirt
setblock ~63 ~119 ~96 dirt
setblock ~63 ~119 ~97 dirt
setblock ~63 ~119 ~98 dirt
setblock ~63 ~119 ~99 dirt
setblock ~63 ~119 ~100 dirt
setblock ~63 ~119 ~101 dirt
setblock ~63 ~119 ~102 dirt
setblock ~63 ~119 ~103 dirt
setblock ~63 ~119 ~104 dirt
setblock ~63 ~119 ~105 dirt
setblock ~63 ~119 ~106 dirt
setblock ~63 ~119 ~107 dirt
setblock ~63 ~119 ~108 dirt
setblock ~63 ~119 ~109 dirt
setblock ~63 ~119 ~110 dirt
setblock ~63 ~119 ~111 dirt
setblock ~63 ~119 ~112 dirt
setblock ~63 ~119 ~113 dirt
setblock ~63 ~119 ~114 dirt
setblock ~63 ~119 ~115 dirt
setblock ~63 ~119 ~116 dirt
setblock ~63 ~119 ~117 dirt
setblock ~63 ~119 ~118 dirt
setblock ~63 ~120 ~76 dirt
setblock ~63 ~120 ~77 dirt
setblock ~63 ~120 ~78 dirt
setblock ~63 ~120 ~79 dirt
setblock ~63 ~120 ~80 dirt
setblock ~63 ~120 ~81 dirt
setblock ~63 ~120 ~82 dirt
setblock ~63 ~120 ~83 dirt
setblock ~63 ~120 ~84 dirt
setblock ~63 ~120 ~85 dirt
setblock ~63 ~120 ~86 dirt
setblock ~63 ~120 ~87 dirt
setblock ~63 ~120 ~88 dirt
setblock ~63 ~120 ~89 dirt
setblock ~63 ~120 ~90 dirt
setblock ~63 ~120 ~91 dirt
setblock ~63 ~120 ~92 dirt
setblock ~63 ~120 ~93 dirt
setblock ~63 ~120 ~94 dirt
setblock ~63 ~120 ~95 dirt
setblock ~63 ~120 ~96 dirt
setblock ~63 ~120 ~97 dirt
setblock ~63 ~120 ~98 dirt
setblock ~63 ~120 ~99 dirt
setblock ~63 ~120 ~100 dirt
setblock ~63 ~120 ~101 dirt
setblock ~63 ~120 ~102 dirt
setblock ~63 ~120 ~103 dirt
setblock ~63 ~120 ~104 dirt
setblock ~63 ~120 ~105 dirt
setblock ~63 ~120 ~106 dirt
setblock ~63 ~120 ~107 dirt
setblock ~63 ~120 ~108 dirt
setblock ~63 ~120 ~109 dirt
setblock ~63 ~120 ~110 dirt
setblock ~63 ~120 ~111 dirt
setblock ~63 ~120 ~112 dirt
setblock ~63 ~120 ~113 dirt
setblock ~63 ~120 ~114 dirt
setblock ~63 ~120 ~115 dirt
setblock ~63 ~120 ~116 dirt
setblock ~63 ~120 ~117 dirt
setblock ~63 ~120 ~118 dirt
setblock ~63 ~120 ~119 dirt
setblock ~63 ~120 ~120 dirt
setblock ~63 ~121 ~76 dirt
setblock ~63 ~121 ~77 dirt
setblock ~63 ~121 ~78 dirt
setblock ~63 ~121 ~79 dirt
setblock ~63 ~121 ~80 dirt
setblock ~63 ~121 ~81 dirt
setblock ~63 ~121 ~82 dirt
setblock ~63 ~121 ~83 dirt
setblock ~63 ~121 ~84 dirt
setblock ~63 ~121 ~85 dirt
setblock ~63 ~121 ~86 dirt
setblock ~63 ~121 ~87 dirt
setblock ~63 ~121 ~88 dirt
setblock ~63 ~121 ~89 dirt
setblock ~63 ~121 ~90 dirt
setblock ~63 ~121 ~91 dirt
setblock ~63 ~121 ~92 dirt
setblock ~63 ~121 ~93 dirt
setblock ~63 ~121 ~94 dirt
setblock ~63 ~121 ~95 dirt
setblock ~63 ~121 ~96 dirt
setblock ~63 ~121 ~97 dirt
setblock ~63 ~121 ~98 dirt
setblock ~63 ~121 ~99 dirt
setblock ~63 ~121 ~100 dirt
setblock ~63 ~121 ~101 dirt
setblock ~63 ~121 ~102 dirt
setblock ~63 ~121 ~103 dirt
setblock ~63 ~121 ~104 dirt
setblock ~63 ~121 ~105 dirt
setblock ~63 ~121 ~106 dirt
setblock ~63 ~121 ~107 dirt
setblock ~63 ~121 ~108 dirt
setblock ~63 ~121 ~109 dirt
setblock ~63 ~121 ~110 dirt
setblock ~63 ~121 ~111 dirt
setblock ~63 ~121 ~112 dirt
setblock ~63 ~121 ~113 dirt
setblock ~63 ~121 ~114 dirt
setblock ~63 ~121 ~115 dirt
setblock ~63 ~121 ~116 dirt
setblock ~63 ~121 ~117 dirt
setblock ~63 ~121 ~118 dirt
setblock ~63 ~121 ~119 dirt
setblock ~63 ~121 ~120 dirt
setblock ~63 ~122 ~76 dirt
setblock ~63 ~122 ~77 dirt
setblock ~63 ~122 ~78 dirt
setblock ~63 ~122 ~79 dirt
setblock ~63 ~122 ~80 dirt
setblock ~63 ~122 ~81 dirt
setblock ~63 ~122 ~82 dirt
setblock ~63 ~122 ~83 dirt
setblock ~63 ~122 ~84 dirt
setblock ~63 ~122 ~85 dirt
setblock ~63 ~122 ~86 dirt
setblock ~63 ~122 ~87 dirt
setblock ~63 ~122 ~88 dirt
setblock ~63 ~122 ~89 dirt
setblock ~63 ~122 ~90 dirt
setblock ~63 ~122 ~91 dirt
setblock ~63 ~122 ~92 dirt
setblock ~63 ~122 ~93 dirt
setblock ~63 ~122 ~94 dirt
setblock ~63 ~122 ~95 dirt
setblock ~63 ~122 ~96 dirt
setblock ~63 ~122 ~97 dirt
setblock ~63 ~122 ~98 dirt
setblock ~63 ~122 ~99 dirt
setblock ~63 ~122 ~100 dirt
setblock ~63 ~122 ~101 dirt
setblock ~63 ~122 ~102 dirt
setblock ~63 ~122 ~103 dirt
setblock ~63 ~122 ~104 dirt
setblock ~63 ~122 ~105 dirt
setblock ~63 ~122 ~106 dirt
setblock ~63 ~122 ~107 dirt
setblock ~63 ~122 ~108 dirt
setblock ~63 ~122 ~109 dirt
setblock ~63 ~122 ~110 dirt
setblock ~63 ~122 ~111 dirt
setblock ~63 ~122 ~112 dirt
setblock ~63 ~122 ~113 dirt
setblock ~63 ~122 ~114 dirt
setblock ~63 ~122 ~115 dirt
setblock ~63 ~122 ~116 dirt
setblock ~63 ~122 ~117 dirt
setblock ~63 ~122 ~118 dirt
setblock ~63 ~122 ~119 dirt
setblock ~63 ~122 ~120 dirt
setblock ~63 ~123 ~76 dirt
setblock ~63 ~123 ~77 grass_block
setblock ~63 ~123 ~78 grass_block
setblock ~63 ~123 ~79 grass_block
setblock ~63 ~123 ~80 grass_block
setblock ~63 ~123 ~81 grass_block
setblock ~63 ~123 ~82 grass_block
setblock ~63 ~123 ~83 grass_block
setblock ~63 ~123 ~84 grass_block
setblock ~63 ~123 ~85 grass_block
setblock ~63 ~123 ~86 dirt
setblock ~63 ~123 ~87 dirt
setblock ~63 ~123 ~88 dirt
setblock ~63 ~123 ~89 dirt
setblock ~63 ~123 ~90 dirt
setblock ~63 ~123 ~91 dirt
setblock ~63 ~123 ~92 dirt
setblock ~63 ~123 ~93 dirt
setblock ~63 ~123 ~94 dirt
setblock ~63 ~123 ~95 dirt
setblock ~63 ~123 ~96 dirt
setblock ~63 ~123 ~97 dirt
setblock ~63 ~123 ~98 dirt
setblock ~63 ~123 ~99 dirt
setblock ~63 ~123 ~100 dirt
setblock ~63 ~123 ~101 dirt
setblock ~63 ~123 ~102 dirt
setblock ~63 ~123 ~103 dirt
setblock ~63 ~123 ~104 dirt
setblock ~63 ~123 ~105 dirt
setblock ~63 ~123 ~106 dirt
setblock ~63 ~123 ~107 dirt
setblock ~63 ~123 ~108 dirt
setblock ~63 ~123 ~109 dirt
setblock ~63 ~123 ~110 dirt
setblock ~63 ~123 ~111 dirt
setblock ~63 ~123 ~112 dirt
setblock ~63 ~123 ~113 dirt
setblock ~63 ~123 ~114 dirt
setblock ~63 ~123 ~115 dirt
setblock ~63 ~123 ~116 dirt
setblock ~63 ~123 ~117 dirt
setblock ~63 ~123 ~118 dirt
setblock ~63 ~123 ~119 dirt
setblock ~63 ~123 ~120 dirt
setblock ~63 ~124 ~76 grass_block
setblock ~63 ~124 ~80 fern
setblock ~63 ~124 ~82 short_grass
setblock ~63 ~124 ~83 short_grass
setblock ~63 ~124 ~85 short_grass
setblock ~63 ~124 ~86 grass_block
setblock ~63 ~124 ~87 grass_block
setblock ~63 ~124 ~88 grass_block
setblock ~63 ~124 ~89 grass_block
setblock ~63 ~124 ~90 grass_block
setblock ~63 ~124 ~91 grass_block
setblock ~63 ~124 ~92 grass_block
setblock ~63 ~124 ~93 dirt
setblock ~63 ~124 ~94 dirt
setblock ~63 ~124 ~95 dirt
setblock ~63 ~124 ~96 dirt
setblock ~63 ~124 ~97 dirt
setblock ~63 ~124 ~98 dirt
setblock ~63 ~124 ~99 dirt
setblock ~63 ~124 ~100 dirt
setblock ~63 ~124 ~101 dirt
setblock ~63 ~124 ~102 dirt
setblock ~63 ~124 ~103 dirt
setblock ~63 ~124 ~104 dirt
setblock ~63 ~124 ~105 dirt
setblock ~63 ~124 ~106 dirt
setblock ~63 ~124 ~107 dirt
setblock ~63 ~124 ~108 dirt
setblock ~63 ~124 ~109 dirt
setblock ~63 ~124 ~110 dirt
setblock ~63 ~124 ~111 dirt
setblock ~63 ~124 ~112 dirt
setblock ~63 ~124 ~113 dirt
setblock ~63 ~124 ~114 dirt
setblock ~63 ~124 ~115 dirt
setblock ~63 ~124 ~116 dirt
setblock ~63 ~124 ~117 dirt
setblock ~63 ~124 ~118 dirt
setblock ~63 ~124 ~119 dirt
setblock ~63 ~124 ~120 dirt
setblock ~63 ~125 ~89 poppy
setblock ~63 ~125 ~90 short_grass
setblock ~63 ~125 ~92 short_grass
setblock ~63 ~125 ~93 grass_block
setblock ~63 ~125 ~94 grass_block
setblock ~63 ~125 ~95 grass_block
setblock ~63 ~125 ~96 grass_block
setblock ~63 ~125 ~97 dirt
setblock ~63 ~125 ~98 dirt
setblock ~63 ~125 ~99 dirt
setblock ~63 ~125 ~100 dirt
setblock ~63 ~125 ~101 dirt
setblock ~63 ~125 ~102 dirt
setblock ~63 ~125 ~103 dirt
setblock ~63 ~125 ~104 dirt
setblock ~63 ~125 ~105 dirt
setblock ~63 ~125 ~106 dirt
setblock ~63 ~125 ~107 dirt
setblock ~63 ~125 ~108 dirt
setblock ~63 ~125 ~109 dirt
setblock ~63 ~125 ~110 dirt
setblock ~63 ~125 ~111 dirt
setblock ~63 ~125 ~112 dirt
setblock ~63 ~125 ~113 dirt
setblock ~63 ~125 ~114 dirt
setblock ~63 ~125 ~115 dirt
setblock ~63 ~125 ~116 dirt
setblock ~63 ~125 ~117 dirt
setblock ~63 ~125 ~118 dirt
setblock ~63 ~125 ~119 dirt
setblock ~63 ~125 ~120 grass_block
setblock ~63 ~126 ~93 short_grass
setblock ~63 ~126 ~97 grass_block
setblock ~63 ~126 ~98 dirt
setblock ~63 ~126 ~99 dirt
setblock ~63 ~126 ~100 dirt
setblock ~63 ~126 ~101 dirt
setblock ~63 ~126 ~102 dirt
setblock ~63 ~126 ~103 dirt
setblock ~63 ~126 ~104 dirt
setblock ~63 ~126 ~105 dirt
setblock ~63 ~126 ~106 dirt
setblock ~63 ~126 ~107 dirt
setblock ~63 ~126 ~108 dirt
setblock ~63 ~126 ~109 dirt
setblock ~63 ~126 ~110 dirt
setblock ~63 ~126 ~111 dirt
setblock ~63 ~126 ~112 dirt
setblock ~63 ~126 ~113 dirt
setblock ~63 ~126 ~114 grass_block
setblock ~63 ~126 ~115 grass_block
setblock ~63 ~126 ~116 grass_block
setblock ~63 ~126 ~117 grass_block
setblock ~63 ~126 ~118 grass_block
setblock ~63 ~126 ~119 grass_block
setblock ~63 ~127 ~98 grass_block
setblock ~63 ~127 ~99 dirt
setblock ~63 ~127 ~100 dirt
setblock ~63 ~127 ~101 dirt
setblock ~63 ~127 ~102 dirt
setblock ~63 ~127 ~103 dirt
setblock ~63 ~127 ~104 dirt
setblock ~63 ~127 ~105 dirt
setblock ~63 ~127 ~106 dirt
setblock ~63 ~127 ~107 dirt
setblock ~63 ~127 ~108 grass_block
setblock ~63 ~127 ~109 grass_block
setblock ~63 ~127 ~110 grass_block
setblock ~63 ~127 ~111 grass_block
setblock ~63 ~127 ~112 grass_block
setblock ~63 ~127 ~113 grass_block
setblock ~63 ~127 ~117 short_grass
setblock ~63 ~128 ~99 grass_block
setblock ~63 ~128 ~100 dirt
setblock ~63 ~128 ~101 dirt
setblock ~63 ~128 ~102 grass_block
setblock ~63 ~128 ~103 grass_block
setblock ~63 ~128 ~104 grass_block
setblock ~63 ~128 ~105 grass_block
setblock ~63 ~128 ~106 grass_block
setblock ~63 ~128 ~107 grass_block
setblock ~63 ~128 ~108 fern
setblock ~63 ~128 ~111 short_grass
setblock ~63 ~128 ~112 short_grass
setblock ~63 ~129 ~100 grass_block
setblock ~63 ~129 ~101 grass_block
setblock ~64 ~102 ~102 dirt
setblock ~64 ~103 ~101 dirt
setblock ~64 ~103 ~102 dirt
setblock ~64 ~104 ~100 dirt
setblock ~64 ~104 ~101 dirt
setblock ~64 ~104 ~102 dirt
setblock ~64 ~105 ~89 dirt
setblock ~64 ~105 ~99 dirt
setblock ~64 ~105 ~100 dirt
setblock ~64 ~105 ~101 dirt
setblock ~64 ~105 ~102 dirt
setblock ~64 ~106 ~89 dirt
setblock ~64 ~106 ~99 dirt
setblock ~64 ~106 ~100 dirt
setblock ~64 ~106 ~101 dirt
setblock ~64 ~106 ~102 dirt
setblock ~64 ~106 ~103 dirt
setblock ~64 ~106 ~104 dirt
setblock ~64 ~106 ~108 dirt
setblock ~64 ~107 ~85 dirt
setblock ~64 ~107 ~86 dirt
setblock ~64 ~107 ~88 dirt
setblock ~64 ~107 ~89 dirt
setblock ~64 ~107 ~90 dirt
setblock ~64 ~107 ~96 dirt
setblock ~64 ~107 ~99 dirt
setblock ~64 ~107 ~100 dirt
setblock ~64 ~107 ~101 dirt
setblock ~64 ~107 ~102 dirt
setblock ~64 ~107 ~103 dirt
setblock ~64 ~107 ~104 dirt
setblock ~64 ~107 ~107 dirt
setblock ~64 ~107 ~108 dirt
setblock ~64 ~107 ~109 dirt
setblock ~64 ~108 ~85 dirt
setblock ~64 ~108 ~86 dirt
setblock ~64 ~108 ~87 dirt
setblock ~64 ~108 ~88 dirt
setblock ~64 ~108 ~89 dirt
setblock ~64 ~108 ~90 dirt
setblock ~64 ~108 ~91 dirt
setblock ~64 ~108 ~94 dirt
setblock ~64 ~108 ~95 dirt
setblock ~64 ~108 ~96 dirt
setblock ~64 ~108 ~97 dirt
setblock ~64 ~108 ~98 dirt
setblock ~64 ~108 ~99 dirt
setblock ~64 ~108 ~100 dirt
setblock ~64 ~108 ~101 dirt
setblock ~64 ~108 ~102 dirt
setblock ~64 ~108 ~103 dirt
setblock ~64 ~108 ~104 dirt
setblock ~64 ~108 ~105 dirt
setblock ~64 ~108 ~106 dirt
setblock ~64 ~108 ~107 dirt
setblock ~64 ~108 ~108 dirt
setblock ~64 ~108 ~109 dirt
setblock ~64 ~108 ~110 dirt
setblock ~64 ~109 ~83 dirt
setblock ~64 ~109 ~85 dirt
setblock ~64 ~109 ~86 dirt
setblock ~64 ~109 ~87 dirt
setblock ~64 ~109 ~88 dirt
setblock ~64 ~109 ~89 dirt
setblock ~64 ~109 ~90 dirt
setblock ~64 ~109 ~91 dirt
setblock ~64 ~109 ~92 dirt
setblock ~64 ~109 ~93 dirt
setblock ~64 ~109 ~94 dirt
setblock ~64 ~109 ~95 dirt
setblock ~64 ~109 ~96 dirt
setblock ~64 ~109 ~97 dirt
setblock ~64 ~109 ~98 dirt
setblock ~64 ~109 ~99 dirt
setblock ~64 ~109 ~100 dirt
setblock ~64 ~109 ~101 dirt
setblock ~64 ~109 ~102 dirt
setblock ~64 ~109 ~103 dirt
setblock ~64 ~109 ~104 dirt
setblock ~64 ~109 ~105 dirt
setblock ~64 ~109 ~106 dirt
setblock ~64 ~109 ~107 dirt
setblock ~64 ~109 ~108 dirt
setblock ~64 ~109 ~109 dirt
setblock ~64 ~109 ~110 dirt
setblock ~64 ~110 ~83 dirt
setblock ~64 ~110 ~84 dirt
setblock ~64 ~110 ~85 dirt
setblock ~64 ~110 ~86 dirt
setblock ~64 ~110 ~87 dirt
setblock ~64 ~110 ~88 dirt
setblock ~64 ~110 ~89 dirt
setblock ~64 ~110 ~90 dirt
setblock ~64 ~110 ~91 dirt
setblock ~64 ~110 ~92 dirt
setblock ~64 ~110 ~93 dirt
setblock ~64 ~110 ~94 dirt
setblock ~64 ~110 ~95 dirt
setblock ~64 ~110 ~96 dirt
setblock ~64 ~110 ~97 dirt
setblock ~64 ~110 ~98 dirt
setblock ~64 ~110 ~99 dirt
setblock ~64 ~110 ~100 dirt
setblock ~64 ~110 ~101 dirt
setblock ~64 ~110 ~102 dirt
setblock ~64 ~110 ~103 dirt
setblock ~64 ~110 ~104 dirt
setblock ~64 ~110 ~105 dirt
setblock ~64 ~110 ~106 dirt
setblock ~64 ~110 ~107 dirt
setblock ~64 ~110 ~108 dirt
setblock ~64 ~110 ~109 dirt
setblock ~64 ~110 ~110 dirt
setblock ~64 ~111 ~82 dirt
setblock ~64 ~111 ~83 dirt
setblock ~64 ~111 ~84 dirt
setblock ~64 ~111 ~85 dirt
setblock ~64 ~111 ~86 dirt
setblock ~64 ~111 ~87 dirt
setblock ~64 ~111 ~88 dirt
setblock ~64 ~111 ~89 dirt
setblock ~64 ~111 ~90 dirt
setblock ~64 ~111 ~91 dirt
setblock ~64 ~111 ~92 dirt
setblock ~64 ~111 ~93 dirt
setblock ~64 ~111 ~94 dirt
setblock ~64 ~111 ~95 dirt
setblock ~64 ~111 ~96 dirt
setblock ~64 ~111 ~97 dirt
setblock ~64 ~111 ~98 dirt
setblock ~64 ~111 ~99 dirt
setblock ~64 ~111 ~100 dirt
setblock ~64 ~111 ~101 dirt
setblock ~64 ~111 ~102 dirt
setblock ~64 ~111 ~103 dirt
setblock ~64 ~111 ~104 dirt
setblock ~64 ~111 ~105 dirt
setblock ~64 ~111 ~106 dirt
setblock ~64 ~111 ~107 dirt
setblock ~64 ~111 ~108 dirt
setblock ~64 ~111 ~109 dirt
setblock ~64 ~111 ~110 dirt
setblock ~64 ~111 ~111 dirt
setblock ~64 ~112 ~81 dirt
setblock ~64 ~112 ~82 dirt
setblock ~64 ~112 ~83 dirt
setblock ~64 ~112 ~84 dirt
setblock ~64 ~112 ~85 dirt
setblock ~64 ~112 ~86 dirt
setblock ~64 ~112 ~87 dirt
setblock ~64 ~112 ~88 dirt
setblock ~64 ~112 ~89 dirt
setblock ~64 ~112 ~90 dirt
setblock ~64 ~112 ~91 dirt
setblock ~64 ~112 ~92 dirt
setblock ~64 ~112 ~93 dirt
setblock ~64 ~112 ~94 dirt
setblock ~64 ~112 ~95 dirt
setblock ~64 ~112 ~96 dirt
setblock ~64 ~112 ~97 dirt
setblock ~64 ~112 ~98 dirt
setblock ~64 ~112 ~99 dirt
setblock ~64 ~112 ~100 dirt
setblock ~64 ~112 ~101 dirt
setblock ~64 ~112 ~102 dirt
setblock ~64 ~112 ~103 dirt
setblock ~64 ~112 ~104 dirt
setblock ~64 ~112 ~105 dirt
setblock ~64 ~112 ~106 dirt
setblock ~64 ~112 ~107 dirt
setblock ~64 ~112 ~108 dirt
setblock ~64 ~112 ~109 dirt
setblock ~64 ~112 ~110 dirt
setblock ~64 ~112 ~111 dirt
setblock ~64 ~112 ~112 dirt
setblock ~64 ~112 ~113 dirt
setblock ~64 ~113 ~80 dirt
setblock ~64 ~113 ~81 dirt
setblock ~64 ~113 ~82 dirt
setblock ~64 ~113 ~83 dirt
setblock ~64 ~113 ~84 dirt
setblock ~64 ~113 ~85 dirt
setblock ~64 ~113 ~86 dirt
setblock ~64 ~113 ~87 dirt
setblock ~64 ~113 ~88 dirt
setblock ~64 ~113 ~89 dirt
setblock ~64 ~113 ~90 dirt
setblock ~64 ~113 ~91 dirt
setblock ~64 ~113 ~92 dirt
setblock ~64 ~113 ~93 dirt
setblock ~64 ~113 ~94 dirt
setblock ~64 ~113 ~95 dirt
setblock ~64 ~113 ~96 dirt
setblock ~64 ~113 ~97 dirt
setblock ~64 ~113 ~98 dirt
setblock ~64 ~113 ~99 dirt
setblock ~64 ~113 ~100 dirt
setblock ~64 ~113 ~101 dirt
setblock ~64 ~113 ~102 dirt
setblock ~64 ~113 ~103 dirt
setblock ~64 ~113 ~104 dirt
setblock ~64 ~113 ~105 dirt
setblock ~64 ~113 ~106 dirt
setblock ~64 ~113 ~107 dirt
setblock ~64 ~113 ~108 dirt
setblock ~64 ~113 ~109 dirt
setblock ~64 ~113 ~110 dirt
setblock ~64 ~113 ~111 dirt
setblock ~64 ~113 ~112 dirt
setblock ~64 ~113 ~113 dirt
setblock ~64 ~113 ~114 dirt
setblock ~64 ~114 ~79 dirt
setblock ~64 ~114 ~80 dirt
setblock ~64 ~114 ~81 dirt
setblock ~64 ~114 ~82 dirt
setblock ~64 ~114 ~83 dirt
setblock ~64 ~114 ~84 dirt
setblock ~64 ~114 ~85 dirt
setblock ~64 ~114 ~86 dirt
setblock ~64 ~114 ~87 dirt
setblock ~64 ~114 ~88 dirt
setblock ~64 ~114 ~89 dirt
setblock ~64 ~114 ~90 dirt
setblock ~64 ~114 ~91 dirt
setblock ~64 ~114 ~92 dirt
setblock ~64 ~114 ~93 dirt
setblock ~64 ~114 ~94 dirt
setblock ~64 ~114 ~95 dirt
setblock ~64 ~114 ~96 dirt
setblock ~64 ~114 ~97 dirt
setblock ~64 ~114 ~98 dirt
setblock ~64 ~114 ~99 dirt
setblock ~64 ~114 ~100 dirt
setblock ~64 ~114 ~101 dirt
setblock ~64 ~114 ~102 dirt
setblock ~64 ~114 ~103 dirt
setblock ~64 ~114 ~104 dirt
setblock ~64 ~114 ~105 dirt
setblock ~64 ~114 ~106 dirt
setblock ~64 ~114 ~107 dirt
setblock ~64 ~114 ~108 dirt
setblock ~64 ~114 ~109 dirt
setblock ~64 ~114 ~110 dirt
setblock ~64 ~114 ~111 dirt
setblock ~64 ~114 ~112 dirt
setblock ~64 ~114 ~113 dirt
setblock ~64 ~114 ~114 dirt
setblock ~64 ~114 ~115 dirt
setblock ~64 ~114 ~116 dirt
setblock ~64 ~115 ~79 dirt
setblock ~64 ~115 ~80 dirt
setblock ~64 ~115 ~81 dirt
setblock ~64 ~115 ~82 dirt
setblock ~64 ~115 ~83 dirt
setblock ~64 ~115 ~84 dirt
setblock ~64 ~115 ~85 dirt
setblock ~64 ~115 ~86 dirt
setblock ~64 ~115 ~87 dirt
setblock ~64 ~115 ~88 dirt
setblock ~64 ~115 ~89 dirt
setblock ~64 ~115 ~90 dirt
setblock ~64 ~115 ~91 dirt
setblock ~64 ~115 ~92 dirt
setblock ~64 ~115 ~93 dirt
setblock ~64 ~115 ~94 dirt
setblock ~64 ~115 ~95 dirt
setblock ~64 ~115 ~96 dirt
setblock ~64 ~115 ~97 dirt
setblock ~64 ~115 ~98 dirt
setblock ~64 ~115 ~99 dirt
setblock ~64 ~115 ~100 dirt
setblock ~64 ~115 ~101 dirt
setblock ~64 ~115 ~102 dirt
setblock ~64 ~115 ~103 dirt
setblock ~64 ~115 ~104 dirt
setblock ~64 ~115 ~105 dirt
setblock ~64 ~115 ~106 dirt
setblock ~64 ~115 ~107 dirt
setblock ~64 ~115 ~108 dirt
setblock ~64 ~115 ~109 dirt
setblock ~64 ~115 ~110 dirt
setblock ~64 ~115 ~111 dirt
setblock ~64 ~115 ~112 dirt
setblock ~64 ~115 ~113 dirt
setblock ~64 ~115 ~114 dirt
setblock ~64 ~115 ~115 dirt
setblock ~64 ~115 ~116 dirt
setblock ~64 ~115 ~117 dirt
setblock ~64 ~116 ~78 dirt
setblock ~64 ~116 ~79 dirt
setblock ~64 ~116 ~80 dirt
setblock ~64 ~116 ~81 dirt
setblock ~64 ~116 ~82 dirt
setblock ~64 ~116 ~83 dirt
setblock ~64 ~116 ~84 dirt
setblock ~64 ~116 ~85 dirt
setblock ~64 ~116 ~86 dirt
setblock ~64 ~116 ~87 dirt
setblock ~64 ~116 ~88 dirt
setblock ~64 ~116 ~89 dirt
setblock ~64 ~116 ~90 dirt
setblock ~64 ~116 ~91 dirt
setblock ~64 ~116 ~92 dirt
setblock ~64 ~116 ~93 dirt
setblock ~64 ~116 ~94 dirt
setblock ~64 ~116 ~95 dirt
setblock ~64 ~116 ~96 dirt
setblock ~64 ~116 ~97 dirt
setblock ~64 ~116 ~98 dirt
setblock ~64 ~116 ~99 dirt
setblock ~64 ~116 ~100 dirt
setblock ~64 ~116 ~101 dirt
setblock ~64 ~116 ~102 dirt
setblock ~64 ~116 ~103 dirt
setblock ~64 ~116 ~104 dirt
setblock ~64 ~116 ~105 dirt
setblock ~64 ~116 ~106 dirt
setblock ~64 ~116 ~107 dirt
setblock ~64 ~116 ~108 dirt
setblock ~64 ~116 ~109 dirt
setblock ~64 ~116 ~110 dirt
setblock ~64 ~116 ~111 dirt
setblock ~64 ~116 ~112 dirt
setblock ~64 ~116 ~113 dirt
setblock ~64 ~116 ~114 dirt
setblock ~64 ~116 ~115 dirt
setblock ~64 ~116 ~116 dirt
setblock ~64 ~116 ~117 dirt
setblock ~64 ~117 ~78 dirt
setblock ~64 ~117 ~79 dirt
setblock ~64 ~117 ~80 dirt
setblock ~64 ~117 ~81 dirt
setblock ~64 ~117 ~82 dirt
setblock ~64 ~117 ~83 dirt
setblock ~64 ~117 ~84 dirt
setblock ~64 ~117 ~85 dirt
setblock ~64 ~117 ~86 dirt
setblock ~64 ~117 ~87 dirt
setblock ~64 ~117 ~88 dirt
setblock ~64 ~117 ~89 dirt
setblock ~64 ~117 ~90 dirt
setblock ~64 ~117 ~91 dirt
setblock ~64 ~117 ~92 dirt
setblock ~64 ~117 ~93 dirt
setblock ~64 ~117 ~94 dirt
setblock ~64 ~117 ~95 dirt
setblock ~64 ~117 ~96 dirt
setblock ~64 ~117 ~97 dirt
setblock ~64 ~117 ~98 dirt
setblock ~64 ~117 ~99 dirt
setblock ~64 ~117 ~100 dirt
setblock ~64 ~117 ~101 dirt
setblock ~64 ~117 ~102 dirt
setblock ~64 ~117 ~103 dirt
setblock ~64 ~117 ~104 dirt
setblock ~64 ~117 ~105 dirt
setblock ~64 ~117 ~106 dirt
setblock ~64 ~117 ~107 dirt
setblock ~64 ~117 ~108 dirt
setblock ~64 ~117 ~109 dirt
setblock ~64 ~117 ~110 dirt
setblock ~64 ~117 ~111 dirt
setblock ~64 ~117 ~112 dirt
setblock ~64 ~117 ~113 dirt
setblock ~64 ~117 ~114 dirt
setblock ~64 ~117 ~115 dirt
setblock ~64 ~117 ~116 dirt
setblock ~64 ~117 ~117 dirt
setblock ~64 ~117 ~118 dirt
setblock ~64 ~118 ~77 dirt
setblock ~64 ~118 ~78 dirt
setblock ~64 ~118 ~79 dirt
setblock ~64 ~118 ~80 dirt
setblock ~64 ~118 ~81 dirt
setblock ~64 ~118 ~82 dirt
setblock ~64 ~118 ~83 dirt
setblock ~64 ~118 ~84 dirt
setblock ~64 ~118 ~85 dirt
setblock ~64 ~118 ~86 dirt
setblock ~64 ~118 ~87 dirt
setblock ~64 ~118 ~88 dirt
setblock ~64 ~118 ~89 dirt
setblock ~64 ~118 ~90 dirt
setblock ~64 ~118 ~91 dirt
setblock ~64 ~118 ~92 dirt
setblock ~64 ~118 ~93 dirt
setblock ~64 ~118 ~94 dirt
setblock ~64 ~118 ~95 dirt
setblock ~64 ~118 ~96 dirt
setblock ~64 ~118 ~97 dirt
setblock ~64 ~118 ~98 dirt
setblock ~64 ~118 ~99 dirt
setblock ~64 ~118 ~100 dirt
setblock ~64 ~118 ~101 dirt
setblock ~64 ~118 ~102 dirt
setblock ~64 ~118 ~103 dirt
setblock ~64 ~118 ~104 dirt
setblock ~64 ~118 ~105 dirt
setblock ~64 ~118 ~106 dirt
setblock ~64 ~118 ~107 dirt
setblock ~64 ~118 ~108 dirt
setblock ~64 ~118 ~109 dirt
setblock ~64 ~118 ~110 dirt
setblock ~64 ~118 ~111 dirt
setblock ~64 ~118 ~112 dirt
setblock ~64 ~118 ~113 dirt
setblock ~64 ~118 ~114 dirt
setblock ~64 ~118 ~115 dirt
setblock ~64 ~118 ~116 dirt
setblock ~64 ~118 ~117 dirt
setblock ~64 ~118 ~118 dirt
setblock ~64 ~118 ~119 dirt
setblock ~64 ~119 ~77 dirt
setblock ~64 ~119 ~78 dirt
setblock ~64 ~119 ~79 dirt
setblock ~64 ~119 ~80 dirt
setblock ~64 ~119 ~81 dirt
setblock ~64 ~119 ~82 dirt
setblock ~64 ~119 ~83 dirt
setblock ~64 ~119 ~84 dirt
setblock ~64 ~119 ~85 dirt
setblock ~64 ~119 ~86 dirt
setblock ~64 ~119 ~87 dirt
setblock ~64 ~119 ~88 dirt
setblock ~64 ~119 ~89 dirt
setblock ~64 ~119 ~90 dirt
setblock ~64 ~119 ~91 dirt
setblock ~64 ~119 ~92 dirt
setblock ~64 ~119 ~93 dirt
setblock ~64 ~119 ~94 dirt
setblock ~64 ~119 ~95 dirt
setblock ~64 ~119 ~96 dirt
setblock ~64 ~119 ~97 dirt
setblock ~64 ~119 ~98 dirt
setblock ~64 ~119 ~99 dirt
setblock ~64 ~119 ~100 dirt
setblock ~64 ~119 ~101 dirt
setblock ~64 ~119 ~102 dirt
setblock ~64 ~119 ~103 dirt
setblock ~64 ~119 ~104 dirt
setblock ~64 ~119 ~105 dirt
setblock ~64 ~119 ~106 dirt
setblock ~64 ~119 ~107 dirt
setblock ~64 ~119 ~108 dirt
setblock ~64 ~119 ~109 dirt
setblock ~64 ~119 ~110 dirt
setblock ~64 ~119 ~111 dirt
setblock ~64 ~119 ~112 dirt
setblock ~64 ~119 ~113 dirt
setblock ~64 ~119 ~114 dirt
setblock ~64 ~119 ~115 dirt
setblock ~64 ~119 ~116 dirt
setblock ~64 ~119 ~117 dirt
setblock ~64 ~119 ~118 dirt
setblock ~64 ~119 ~119 dirt
setblock ~64 ~119 ~120 dirt
setblock ~64 ~120 ~77 dirt
setblock ~64 ~120 ~78 dirt
setblock ~64 ~120 ~79 dirt
setblock ~64 ~120 ~80 dirt
setblock ~64 ~120 ~81 dirt
setblock ~64 ~120 ~82 dirt
setblock ~64 ~120 ~83 dirt
setblock ~64 ~120 ~84 dirt
setblock ~64 ~120 ~85 dirt
setblock ~64 ~120 ~86 dirt
setblock ~64 ~120 ~87 dirt
setblock ~64 ~120 ~88 dirt
setblock ~64 ~120 ~89 dirt
setblock ~64 ~120 ~90 dirt
setblock ~64 ~120 ~91 dirt
setblock ~64 ~120 ~92 dirt
setblock ~64 ~120 ~93 dirt
setblock ~64 ~120 ~94 dirt
setblock ~64 ~120 ~95 dirt
setblock ~64 ~120 ~96 dirt
setblock ~64 ~120 ~97 dirt
setblock ~64 ~120 ~98 dirt
setblock ~64 ~120 ~99 dirt
setblock ~64 ~120 ~100 dirt
setblock ~64 ~120 ~101 dirt
setblock ~64 ~120 ~102 dirt
setblock ~64 ~120 ~103 dirt
setblock ~64 ~120 ~104 dirt
setblock ~64 ~120 ~105 dirt
setblock ~64 ~120 ~106 dirt
setblock ~64 ~120 ~107 dirt
setblock ~64 ~120 ~108 dirt
setblock ~64 ~120 ~109 dirt
setblock ~64 ~120 ~110 dirt
setblock ~64 ~120 ~111 dirt
setblock ~64 ~120 ~112 dirt
setblock ~64 ~120 ~113 dirt
setblock ~64 ~120 ~114 dirt
setblock ~64 ~120 ~115 dirt
setblock ~64 ~120 ~116 dirt
setblock ~64 ~120 ~117 dirt
setblock ~64 ~120 ~118 dirt
setblock ~64 ~120 ~119 dirt
setblock ~64 ~120 ~120 dirt
setblock ~64 ~120 ~121 dirt
setblock ~64 ~121 ~76 dirt
setblock ~64 ~121 ~77 dirt
setblock ~64 ~121 ~78 dirt
setblock ~64 ~121 ~79 dirt
setblock ~64 ~121 ~80 dirt
setblock ~64 ~121 ~81 dirt
setblock ~64 ~121 ~82 dirt
setblock ~64 ~121 ~83 dirt
setblock ~64 ~121 ~84 dirt
setblock ~64 ~121 ~85 dirt
setblock ~64 ~121 ~86 dirt
setblock ~64 ~121 ~87 dirt
setblock ~64 ~121 ~88 dirt
setblock ~64 ~121 ~89 dirt
setblock ~64 ~121 ~90 dirt
setblock ~64 ~121 ~91 dirt
setblock ~64 ~121 ~92 dirt
setblock ~64 ~121 ~93 dirt
setblock ~64 ~121 ~94 dirt
setblock ~64 ~121 ~95 dirt
setblock ~64 ~121 ~96 dirt
setblock ~64 ~121 ~97 dirt
setblock ~64 ~121 ~98 dirt
setblock ~64 ~121 ~99 dirt
setblock ~64 ~121 ~100 dirt
setblock ~64 ~121 ~101 dirt
setblock ~64 ~121 ~102 dirt
setblock ~64 ~121 ~103 dirt
setblock ~64 ~121 ~104 dirt
setblock ~64 ~121 ~105 dirt
setblock ~64 ~121 ~106 dirt
setblock ~64 ~121 ~107 dirt
setblock ~64 ~121 ~108 dirt
setblock ~64 ~121 ~109 dirt
setblock ~64 ~121 ~110 dirt
setblock ~64 ~121 ~111 dirt
setblock ~64 ~121 ~112 dirt
setblock ~64 ~121 ~113 dirt
setblock ~64 ~121 ~114 dirt
setblock ~64 ~121 ~115 dirt
setblock ~64 ~121 ~116 dirt
setblock ~64 ~121 ~117 dirt
setblock ~64 ~121 ~118 dirt
setblock ~64 ~121 ~119 dirt
setblock ~64 ~121 ~120 dirt
setblock ~64 ~121 ~121 dirt
setblock ~64 ~122 ~76 dirt
setblock ~64 ~122 ~77 dirt
setblock ~64 ~122 ~78 dirt
setblock ~64 ~122 ~79 dirt
setblock ~64 ~122 ~80 dirt
setblock ~64 ~122 ~81 dirt
setblock ~64 ~122 ~82 dirt
setblock ~64 ~122 ~83 dirt
setblock ~64 ~122 ~84 dirt
setblock ~64 ~122 ~85 dirt
setblock ~64 ~122 ~86 dirt
setblock ~64 ~122 ~87 dirt
setblock ~64 ~122 ~88 dirt
setblock ~64 ~122 ~89 dirt
setblock ~64 ~122 ~90 dirt
setblock ~64 ~122 ~91 dirt
setblock ~64 ~122 ~92 dirt
setblock ~64 ~122 ~93 dirt
setblock ~64 ~122 ~94 dirt
setblock ~64 ~122 ~95 dirt
setblock ~64 ~122 ~96 dirt
setblock ~64 ~122 ~97 dirt
setblock ~64 ~122 ~98 dirt
setblock ~64 ~122 ~99 dirt
setblock ~64 ~122 ~100 dirt
setblock ~64 ~122 ~101 dirt
setblock ~64 ~122 ~102 dirt
setblock ~64 ~122 ~103 dirt
setblock ~64 ~122 ~104 dirt
setblock ~64 ~122 ~105 dirt
setblock ~64 ~122 ~106 dirt
setblock ~64 ~122 ~107 dirt
setblock ~64 ~122 ~108 dirt
setblock ~64 ~122 ~109 dirt
setblock ~64 ~122 ~110 dirt
setblock ~64 ~122 ~111 dirt
setblock ~64 ~122 ~112 dirt
setblock ~64 ~122 ~113 dirt
setblock ~64 ~122 ~114 dirt
setblock ~64 ~122 ~115 dirt
setblock ~64 ~122 ~116 dirt
setblock ~64 ~122 ~117 dirt
setblock ~64 ~122 ~118 dirt
setblock ~64 ~122 ~119 dirt
setblock ~64 ~122 ~120 dirt
setblock ~64 ~122 ~121 dirt
setblock ~64 ~123 ~76 dirt
setblock ~64 ~123 ~77 grass_block
setblock ~64 ~123 ~78 grass_block
setblock ~64 ~123 ~79 grass_block
setblock ~64 ~123 ~80 grass_block
setblock ~64 ~123 ~81 grass_block
setblock ~64 ~123 ~82 grass_block
setblock ~64 ~123 ~83 grass_block
setblock ~64 ~123 ~84 grass_block
setblock ~64 ~123 ~85 dirt
setblock ~64 ~123 ~86 dirt
setblock ~64 ~123 ~87 dirt
setblock ~64 ~123 ~88 dirt
setblock ~64 ~123 ~89 dirt
setblock ~64 ~123 ~90 dirt
setblock ~64 ~123 ~91 dirt
setblock ~64 ~123 ~92 dirt
setblock ~64 ~123 ~93 dirt
setblock ~64 ~123 ~94 dirt
setblock ~64 ~123 ~95 dirt
setblock ~64 ~123 ~96 dirt
setblock ~64 ~123 ~97 dirt
setblock ~64 ~123 ~98 dirt
setblock ~64 ~123 ~99 dirt
setblock ~64 ~123 ~100 dirt
setblock ~64 ~123 ~101 dirt
setblock ~64 ~123 ~102 dirt
setblock ~64 ~123 ~103 dirt
setblock ~64 ~123 ~104 dirt
setblock ~64 ~123 ~105 dirt
setblock ~64 ~123 ~106 dirt
setblock ~64 ~123 ~107 dirt
setblock ~64 ~123 ~108 dirt
setblock ~64 ~123 ~109 dirt
setblock ~64 ~123 ~110 dirt
setblock ~64 ~123 ~111 dirt
setblock ~64 ~123 ~112 dirt
setblock ~64 ~123 ~113 dirt
setblock ~64 ~123 ~114 dirt
setblock ~64 ~123 ~115 dirt
setblock ~64 ~123 ~116 dirt
setblock ~64 ~123 ~117 dirt
setblock ~64 ~123 ~118 dirt
setblock ~64 ~123 ~119 dirt
setblock ~64 ~123 ~120 dirt
setblock ~64 ~123 ~121 dirt
setblock ~64 ~124 ~76 grass_block
setblock ~64 ~124 ~78 short_grass
setblock ~64 ~124 ~81 short_grass
setblock ~64 ~124 ~85 grass_block
setblock ~64 ~124 ~86 grass_block
setblock ~64 ~124 ~87 grass_block
setblock ~64 ~124 ~88 grass_block
setblock ~64 ~124 ~89 grass_block
setblock ~64 ~124 ~90 grass_block
setblock ~64 ~124 ~91 dirt
setblock ~64 ~124 ~92 dirt
setblock ~64 ~124 ~93 dirt
setblock ~64 ~124 ~94 dirt
setblock ~64 ~124 ~95 dirt
setblock ~64 ~124 ~96 dirt
setblock ~64 ~124 ~97 dirt
setblock ~64 ~124 ~98 dirt
setblock ~64 ~124 ~99 dirt
setblock ~64 ~124 ~100 dirt
setblock ~64 ~124 ~101 dirt
setblock ~64 ~124 ~102 dirt
setblock ~64 ~124 ~103 dirt
setblock ~64 ~124 ~104 dirt
setblock ~64 ~124 ~105 dirt
setblock ~64 ~124 ~106 dirt
setblock ~64 ~124 ~107 dirt
setblock ~64 ~124 ~108 dirt
setblock ~64 ~124 ~109 dirt
setblock ~64 ~124 ~110 dirt
setblock ~64 ~124 ~111 dirt
setblock ~64 ~124 ~112 dirt
setblock ~64 ~124 ~113 dirt
setblock ~64 ~124 ~114 dirt
setblock ~64 ~124 ~115 dirt
setblock ~64 ~124 ~116 dirt
setblock ~64 ~124 ~117 dirt
setblock ~64 ~124 ~118 dirt
setblock ~64 ~124 ~119 dirt
setblock ~64 ~124 ~120 dirt
setblock ~64 ~124 ~121 dirt
setblock ~64 ~125 ~87 short_grass
setblock ~64 ~125 ~89 fern
setblock ~64 ~125 ~91 grass_block
setblock ~64 ~125 ~92 grass_block
setblock ~64 ~125 ~93 grass_block
setblock ~64 ~125 ~94 grass_block
setblock ~64 ~125 ~95 grass_block
setblock ~64 ~125 ~96 dirt
setblock ~64 ~125 ~97 dirt
setblock ~64 ~125 ~98 dirt
setblock ~64 ~125 ~99 dirt
setblock ~64 ~125 ~100 dirt
setblock ~64 ~125 ~101 dirt
setblock ~64 ~125 ~102 dirt
setblock ~64 ~125 ~103 dirt
setblock ~64 ~125 ~104 dirt
setblock ~64 ~125 ~105 dirt
setblock ~64 ~125 ~106 dirt
setblock ~64 ~125 ~107 dirt
setblock ~64 ~125 ~108 dirt
setblock ~64 ~125 ~109 dirt
setblock ~64 ~125 ~110 dirt
setblock ~64 ~125 ~111 dirt
setblock ~64 ~125 ~112 dirt
setblock ~64 ~125 ~113 dirt
setblock ~64 ~125 ~114 dirt
setblock ~64 ~125 ~115 dirt
setblock ~64 ~125 ~116 grass_block
setblock ~64 ~125 ~117 grass_block
setblock ~64 ~125 ~118 grass_block
setblock ~64 ~125 ~119 grass_block
setblock ~64 ~125 ~120 grass_block
setblock ~64 ~125 ~121 grass_block
setblock ~64 ~126 ~91 short_grass
setblock ~64 ~126 ~93 short_grass
setblock ~64 ~126 ~95 short_grass
setblock ~64 ~126 ~96 grass_block
setblock ~64 ~126 ~97 grass_block
setblock ~64 ~126 ~98 dirt
setblock ~64 ~126 ~99 dirt
setblock ~64 ~126 ~100 dirt
setblock ~64 ~126 ~101 dirt
setblock ~64 ~126 ~102 dirt
setblock ~64 ~126 ~103 dirt
setblock ~64 ~126 ~104 dirt
setblock ~64 ~126 ~105 dirt
setblock ~64 ~126 ~106 dirt
setblock ~64 ~126 ~107 dirt
setblock ~64 ~126 ~108 dirt
setblock ~64 ~126 ~109 dirt
setblock ~64 ~126 ~110 grass_block
setblock ~64 ~126 ~111 grass_block
setblock ~64 ~126 ~112 grass_block
setblock ~64 ~126 ~113 grass_block
setblock ~64 ~126 ~114 grass_block
setblock ~64 ~126 ~115 grass_block
setblock ~64 ~126 ~117 fern
setblock ~64 ~127 ~96 short_grass
setblock ~64 ~127 ~98 grass_block
setblock ~64 ~127 ~99 dirt
setblock ~64 ~127 ~100 dirt
setblock ~64 ~127 ~101 dirt
setblock ~64 ~127 ~102 dirt
setblock ~64 ~127 ~103 dirt
setblock ~64 ~127 ~104 grass_block
setblock ~64 ~127 ~105 grass_block
setblock ~64 ~127 ~106 grass_block
setblock ~64 ~127 ~107 grass_block
setblock ~64 ~127 ~108 grass_block
setblock ~64 ~127 ~109 grass_block
setblock ~64 ~127 ~110 poppy
setblock ~64 ~128 ~99 grass_block
setblock ~64 ~128 ~100 dirt
setblock ~64 ~128 ~101 grass_block
setblock ~64 ~128 ~102 grass_block
setblock ~64 ~128 ~103 grass_block
setblock ~64 ~128 ~107 short_grass
setblock ~64 ~128 ~109 short_grass
setblock ~64 ~129 ~100 grass_block
setblock ~64 ~129 ~101 short_grass
setblock ~64 ~129 ~103 short_grass
setblock ~65 ~101 ~102 dirt
setblock ~65 ~102 ~89 dirt
setblock ~65 ~102 ~101 dirt
setblock ~65 ~102 ~102 dirt
setblock ~65 ~102 ~103 dirt
setblock ~65 ~103 ~89 dirt
setblock ~65 ~103 ~99 dirt
setblock ~65 ~103 ~100 dirt
setblock ~65 ~103 ~101 dirt
setblock ~65 ~103 ~102 dirt
setblock ~65 ~103 ~103 dirt
setblock ~65 ~104 ~88 dirt
setblock ~65 ~104 ~89 dirt
setblock ~65 ~104 ~96 dirt
setblock ~65 ~104 ~99 dirt
setblock ~65 ~104 ~100 dirt
setblock ~65 ~104 ~101 dirt
setblock ~65 ~104 ~102 dirt
setblock ~65 ~104 ~103 dirt
setblock ~65 ~104 ~104 dirt
setblock ~65 ~105 ~85 dirt
setblock ~65 ~105 ~88 dirt
setblock ~65 ~105 ~89 dirt
setblock ~65 ~105 ~90 dirt
setblock ~65 ~105 ~91 dirt
setblock ~65 ~105 ~96 dirt
setblock ~65 ~105 ~97 dirt
setblock ~65 ~105 ~98 dirt
setblock ~65 ~105 ~99 dirt
setblock ~65 ~105 ~100 dirt
setblock ~65 ~105 ~101 dirt
setblock ~65 ~105 ~102 dirt
setblock ~65 ~105 ~103 dirt
setblock ~65 ~105 ~104 dirt
setblock ~65 ~105 ~105 dirt
setblock ~65 ~105 ~106 dirt
setblock ~65 ~105 ~107 dirt
setblock ~65 ~105 ~108 dirt
setblock ~65 ~106 ~85 dirt
setblock ~65 ~106 ~86 dirt
setblock ~65 ~106 ~88 dirt
setblock ~65 ~106 ~89 dirt
setblock ~65 ~106 ~90 dirt
setblock ~65 ~106 ~91 dirt
setblock ~65 ~106 ~92 dirt
setblock ~65 ~106 ~94 dirt
setblock ~65 ~106 ~95 dirt
setblock ~65 ~106 ~96 dirt
setblock ~65 ~106 ~97 dirt
setblock ~65 ~106 ~98 dirt
setblock ~65 ~106 ~99 dirt
setblock ~65 ~106 ~100 dirt
setblock ~65 ~106 ~101 dirt
setblock ~65 ~106 ~102 dirt
setblock ~65 ~106 ~103 dirt
setblock ~65 ~106 ~104 dirt
setblock ~65 ~106 ~105 dirt
setblock ~65 ~106 ~106 dirt
setblock ~65 ~106 ~107 dirt
setblock ~65 ~106 ~108 dirt
setblock ~65 ~106 ~109 dirt
setblock ~65 ~107 ~84 dirt
setblock ~65 ~107 ~85 dirt
setblock ~65 ~107 ~86 dirt
setblock ~65 ~107 ~87 dirt
setblock ~65 ~107 ~88 dirt
setblock ~65 ~107 ~89 dirt
setblock ~65 ~107 ~90 dirt
setblock ~65 ~107 ~91 dirt
setblock ~65 ~107 ~92 dirt
setblock ~65 ~107 ~94 dirt
setblock ~65 ~107 ~95 dirt
setblock ~65 ~107 ~96 dirt
setblock ~65 ~107 ~97 dirt
setblock ~65 ~107 ~98 dirt
setblock ~65 ~107 ~99 dirt
setblock ~65 ~107 ~100 dirt
setblock ~65 ~107 ~101 dirt
setblock ~65 ~107 ~102 dirt
setblock ~65 ~107 ~103 dirt
setblock ~65 ~107 ~104 dirt
setblock ~65 ~107 ~105 dirt
setblock ~65 ~107 ~106 dirt
setblock ~65 ~107 ~107 dirt
setblock ~65 ~107 ~108 dirt
setblock ~65 ~107 ~109 dirt
setblock ~65 ~107 ~110 dirt
setblock ~65 ~108 ~83 dirt
setblock ~65 ~108 ~84 dirt
setblock ~65 ~108 ~85 dirt
setblock ~65 ~108 ~86 dirt
setblock ~65 ~108 ~87 dirt
setblock ~65 ~108 ~88 dirt
setblock ~65 ~108 ~89 dirt
setblock ~65 ~108 ~90 dirt
setblock ~65 ~108 ~91 dirt
setblock ~65 ~108 ~92 dirt
setblock ~65 ~108 ~93 dirt
setblock ~65 ~108 ~94 dirt
setblock ~65 ~108 ~95 dirt
setblock ~65 ~108 ~96 dirt
setblock ~65 ~108 ~97 dirt
setblock ~65 ~108 ~98 dirt
setblock ~65 ~108 ~99 dirt
setblock ~65 ~108 ~100 dirt
setblock ~65 ~108 ~101 dirt
setblock ~65 ~108 ~102 dirt
setblock ~65 ~108 ~103 dirt
setblock ~65 ~108 ~104 dirt
setblock ~65 ~108 ~105 dirt
setblock ~65 ~108 ~106 dirt
setblock ~65 ~108 ~107 dirt
setblock ~65 ~108 ~108 dirt
setblock ~65 ~108 ~109 dirt
setblock ~65 ~108 ~110 dirt
setblock ~65 ~109 ~82 dirt
setblock ~65 ~109 ~83 dirt
setblock ~65 ~109 ~84 dirt
setblock ~65 ~109 ~85 dirt
setblock ~65 ~109 ~86 dirt
setblock ~65 ~109 ~87 dirt
setblock ~65 ~109 ~88 dirt
setblock ~65 ~109 ~89 dirt
setblock ~65 ~109 ~90 dirt
setblock ~65 ~109 ~91 dirt
setblock ~65 ~109 ~92 dirt
setblock ~65 ~109 ~93 dirt
setblock ~65 ~109 ~94 dirt
setblock ~65 ~109 ~95 dirt
setblock ~65 ~109 ~96 dirt
setblock ~65 ~109 ~97 dirt
setblock ~65 ~109 ~98 dirt
setblock ~65 ~109 ~99 dirt
setblock ~65 ~109 ~100 dirt
setblock ~65 ~109 ~101 dirt
setblock ~65 ~109 ~102 dirt
setblock ~65 ~109 ~103 dirt
setblock ~65 ~109 ~104 dirt
setblock ~65 ~109 ~105 dirt
setblock ~65 ~109 ~106 dirt
setblock ~65 ~109 ~107 dirt
setblock ~65 ~109 ~108 dirt
setblock ~65 ~109 ~109 dirt
setblock ~65 ~109 ~110 dirt
setblock ~65 ~109 ~111 dirt
setblock ~65 ~110 ~82 dirt
setblock ~65 ~110 ~83 dirt
setblock ~65 ~110 ~84 dirt
setblock ~65 ~110 ~85 dirt
setblock ~65 ~110 ~86 dirt
setblock ~65 ~110 ~87 dirt
setblock ~65 ~110 ~88 dirt
setblock ~65 ~110 ~89 dirt
setblock ~65 ~110 ~90 dirt
setblock ~65 ~110 ~91 dirt
setblock ~65 ~110 ~92 dirt
setblock ~65 ~110 ~93 dirt
setblock ~65 ~110 ~94 dirt
setblock ~65 ~110 ~95 dirt
setblock ~65 ~110 ~96 dirt
setblock ~65 ~110 ~97 dirt
setblock ~65 ~110 ~98 dirt
setblock ~65 ~110 ~99 dirt
setblock ~65 ~110 ~100 dirt
setblock ~65 ~110 ~101 dirt
setblock ~65 ~110 ~102 dirt
setblock ~65 ~110 ~103 dirt
setblock ~65 ~110 ~104 dirt
setblock ~65 ~110 ~105 dirt
setblock ~65 ~110 ~106 dirt
setblock ~65 ~110 ~107 dirt
setblock ~65 ~110 ~108 dirt
setblock ~65 ~110 ~109 dirt
setblock ~65 ~110 ~110 dirt
setblock ~65 ~110 ~111 dirt
setblock ~65 ~110 ~114 dirt
setblock ~65 ~111 ~81 dirt
setblock ~65 ~111 ~82 dirt
setblock ~65 ~111 ~83 dirt
setblock ~65 ~111 ~84 dirt
setblock ~65 ~111 ~85 dirt
setblock ~65 ~111 ~86 dirt
setblock ~65 ~111 ~87 dirt
setblock ~65 ~111 ~88 dirt
setblock ~65 ~111 ~89 dirt
setblock ~65 ~111 ~90 dirt
setblock ~65 ~111 ~91 dirt
setblock ~65 ~111 ~92 dirt
setblock ~65 ~111 ~93 dirt
setblock ~65 ~111 ~94 dirt
setblock ~65 ~111 ~95 dirt
setblock ~65 ~111 ~96 dirt
setblock ~65 ~111 ~97 dirt
setblock ~65 ~111 ~98 dirt
setblock ~65 ~111 ~99 dirt
setblock ~65 ~111 ~100 dirt
setblock ~65 ~111 ~101 dirt
setblock ~65 ~111 ~102 dirt
setblock ~65 ~111 ~103 dirt
setblock ~65 ~111 ~104 dirt
setblock ~65 ~111 ~105 dirt
setblock ~65 ~111 ~106 dirt
setblock ~65 ~111 ~107 dirt
setblock ~65 ~111 ~108 dirt
setblock ~65 ~111 ~109 dirt
setblock ~65 ~111 ~110 dirt
setblock ~65 ~111 ~111 dirt
setblock ~65 ~111 ~112 dirt
setblock ~65 ~111 ~113 dirt
setblock ~65 ~111 ~114 dirt
setblock ~65 ~112 ~80 dirt
setblock ~65 ~112 ~81 dirt
setblock ~65 ~112 ~82 dirt
setblock ~65 ~112 ~83 dirt
setblock ~65 ~112 ~84 dirt
setblock ~65 ~112 ~85 dirt
setblock ~65 ~112 ~86 dirt
setblock ~65 ~112 ~87 dirt
setblock ~65 ~112 ~88 dirt
setblock ~65 ~112 ~89 dirt
setblock ~65 ~112 ~90 dirt
setblock ~65 ~112 ~91 dirt
setblock ~65 ~112 ~92 dirt
setblock ~65 ~112 ~93 dirt
setblock ~65 ~112 ~94 dirt
setblock ~65 ~112 ~95 dirt
setblock ~65 ~112 ~96 dirt
setblock ~65 ~112 ~97 dirt
setblock ~65 ~112 ~98 dirt
setblock ~65 ~112 ~99 dirt
setblock ~65 ~112 ~100 dirt
setblock ~65 ~112 ~101 dirt
setblock ~65 ~112 ~102 dirt
setblock ~65 ~112 ~103 dirt
setblock ~65 ~112 ~104 dirt
setblock ~65 ~112 ~105 dirt
setblock ~65 ~112 ~106 dirt
setblock ~65 ~112 ~107 dirt
setblock ~65 ~112 ~108 dirt
setblock ~65 ~112 ~109 dirt
setblock ~65 ~112 ~110 dirt
setblock ~65 ~112 ~111 dirt
setblock ~65 ~112 ~112 dirt
setblock ~65 ~112 ~113 dirt
setblock ~65 ~112 ~114 dirt
setblock ~65 ~112 ~115 dirt
setblock ~65 ~113 ~79 dirt
setblock ~65 ~113 ~80 dirt
setblock ~65 ~113 ~81 dirt
setblock ~65 ~113 ~82 dirt
setblock ~65 ~113 ~83 dirt
setblock ~65 ~113 ~84 dirt
setblock ~65 ~113 ~85 dirt
setblock ~65 ~113 ~86 dirt
setblock ~65 ~113 ~87 dirt
setblock ~65 ~113 ~88 dirt
setblock ~65 ~113 ~89 dirt
setblock ~65 ~113 ~90 dirt
setblock ~65 ~113 ~91 dirt
setblock ~65 ~113 ~92 dirt
setblock ~65 ~113 ~93 dirt
setblock ~65 ~113 ~94 dirt
setblock ~65 ~113 ~95 dirt
setblock ~65 ~113 ~96 dirt
setblock ~65 ~113 ~97 dirt
setblock ~65 ~113 ~98 dirt
setblock ~65 ~113 ~99 dirt
setblock ~65 ~113 ~100 dirt
setblock ~65 ~113 ~101 dirt
setblock ~65 ~113 ~102 dirt
setblock ~65 ~113 ~103 dirt
setblock ~65 ~113 ~104 dirt
setblock ~65 ~113 ~105 dirt
setblock ~65 ~113 ~106 dirt
setblock ~65 ~113 ~107 dirt
setblock ~65 ~113 ~108 dirt
setblock ~65 ~113 ~109 dirt
setblock ~65 ~113 ~110 dirt
setblock ~65 ~113 ~111 dirt
setblock ~65 ~113 ~112 dirt
setblock ~65 ~113 ~113 dirt
setblock ~65 ~113 ~114 dirt
setblock ~65 ~113 ~115 dirt
setblock ~65 ~113 ~116 dirt
setblock ~65 ~114 ~79 dirt
setblock ~65 ~114 ~80 dirt
setblock ~65 ~114 ~81 dirt
setblock ~65 ~114 ~82 dirt
setblock ~65 ~114 ~83 dirt
setblock ~65 ~114 ~84 dirt
setblock ~65 ~114 ~85 dirt
setblock ~65 ~114 ~86 dirt
setblock ~65 ~114 ~87 dirt
setblock ~65 ~114 ~88 dirt
setblock ~65 ~114 ~89 dirt
setblock ~65 ~114 ~90 dirt
setblock ~65 ~114 ~91 dirt
setblock ~65 ~114 ~92 dirt
setblock ~65 ~114 ~93 dirt
setblock ~65 ~114 ~94 dirt
setblock ~65 ~114 ~95 dirt
setblock ~65 ~114 ~96 dirt
setblock ~65 ~114 ~97 dirt
setblock ~65 ~114 ~98 dirt
setblock ~65 ~114 ~99 dirt
setblock ~65 ~114 ~100 dirt
setblock ~65 ~114 ~101 dirt
setblock ~65 ~114 ~102 dirt
setblock ~65 ~114 ~103 dirt
setblock ~65 ~114 ~104 dirt
setblock ~65 ~114 ~105 dirt
setblock ~65 ~114 ~106 dirt
setblock ~65 ~114 ~107 dirt
setblock ~65 ~114 ~108 dirt
setblock ~65 ~114 ~109 dirt
setblock ~65 ~114 ~110 dirt
setblock ~65 ~114 ~111 dirt
setblock ~65 ~114 ~112 dirt
setblock ~65 ~114 ~113 dirt
setblock ~65 ~114 ~114 dirt
setblock ~65 ~114 ~115 dirt
setblock ~65 ~114 ~116 dirt
setblock ~65 ~114 ~117 dirt
setblock ~65 ~115 ~78 dirt
setblock ~65 ~115 ~79 dirt
setblock ~65 ~115 ~80 dirt
setblock ~65 ~115 ~81 dirt
setblock ~65 ~115 ~82 dirt
setblock ~65 ~115 ~83 dirt
setblock ~65 ~115 ~84 dirt
setblock ~65 ~115 ~85 dirt
setblock ~65 ~115 ~86 dirt
setblock ~65 ~115 ~87 dirt
setblock ~65 ~115 ~88 dirt
setblock ~65 ~115 ~89 dirt
setblock ~65 ~115 ~90 dirt
setblock ~65 ~115 ~91 dirt
setblock ~65 ~115 ~92 dirt
setblock ~65 ~115 ~93 dirt
setblock ~65 ~115 ~94 dirt
setblock ~65 ~115 ~95 dirt
setblock ~65 ~115 ~96 dirt
setblock ~65 ~115 ~97 dirt
setblock ~65 ~115 ~98 dirt
setblock ~65 ~115 ~99 dirt
setblock ~65 ~115 ~100 dirt
setblock ~65 ~115 ~101 dirt
setblock ~65 ~115 ~102 dirt
setblock ~65 ~115 ~103 dirt
setblock ~65 ~115 ~104 dirt
setblock ~65 ~115 ~105 dirt
setblock ~65 ~115 ~106 dirt
setblock ~65 ~115 ~107 dirt
setblock ~65 ~115 ~108 dirt
setblock ~65 ~115 ~109 dirt
setblock ~65 ~115 ~110 dirt
setblock ~65 ~115 ~111 dirt
setblock ~65 ~115 ~112 dirt
setblock ~65 ~115 ~113 dirt
setblock ~65 ~115 ~114 dirt
setblock ~65 ~115 ~115 dirt
setblock ~65 ~115 ~116 dirt
setblock ~65 ~115 ~117 dirt
setblock ~65 ~115 ~118 dirt
setblock ~65 ~116 ~78 dirt
setblock ~65 ~116 ~79 dirt
setblock ~65 ~116 ~80 dirt
setblock ~65 ~116 ~81 dirt
setblock ~65 ~116 ~82 dirt
setblock ~65 ~116 ~83 dirt
setblock ~65 ~116 ~84 dirt
setblock ~65 ~116 ~85 dirt
setblock ~65 ~116 ~86 dirt
setblock ~65 ~116 ~87 dirt
setblock ~65 ~116 ~88 dirt
