setblock ~177 ~132 ~105 oak_wood
setblock ~177 ~132 ~106 oak_leaves[persistent=true]
setblock ~177 ~132 ~109 oak_leaves[persistent=true]
setblock ~177 ~132 ~110 jungle_leaves[persistent=true]
setblock ~177 ~132 ~111 oak_leaves[persistent=true]
setblock ~177 ~132 ~112 oak_leaves[persistent=true]
setblock ~177 ~133 ~70 oak_leaves[persistent=true]
setblock ~177 ~133 ~71 oak_leaves[persistent=true]
setblock ~177 ~133 ~72 oak_leaves[persistent=true]
setblock ~177 ~133 ~73 oak_leaves[persistent=true]
setblock ~177 ~133 ~74 oak_leaves[persistent=true]
setblock ~177 ~133 ~75 jungle_leaves[persistent=true]
setblock ~177 ~133 ~76 oak_leaves[persistent=true]
setblock ~177 ~133 ~77 jungle_leaves[persistent=true]
setblock ~177 ~133 ~78 oak_leaves[persistent=true]
setblock ~177 ~133 ~79 oak_leaves[persistent=true]
setblock ~177 ~133 ~80 oak_wood
setblock ~177 ~133 ~81 oak_leaves[persistent=true]
setblock ~177 ~133 ~82 oak_wood
setblock ~177 ~133 ~83 oak_leaves[persistent=true]
setblock ~177 ~133 ~84 oak_wood
setblock ~177 ~133 ~85 oak_wood
setblock ~177 ~133 ~87 jungle_leaves[persistent=true]
setblock ~177 ~133 ~88 oak_wood
setblock ~177 ~133 ~89 jungle_leaves[persistent=true]
setblock ~177 ~133 ~90 oak_leaves[persistent=true]
setblock ~177 ~133 ~91 oak_leaves[persistent=true]
setblock ~177 ~133 ~92 oak_leaves[persistent=true]
setblock ~177 ~133 ~93 oak_leaves[persistent=true]
setblock ~177 ~133 ~94 jungle_leaves[persistent=true]
setblock ~177 ~133 ~95 oak_leaves[persistent=true]
setblock ~177 ~133 ~96 jungle_leaves[persistent=true]
setblock ~177 ~133 ~97 oak_leaves[persistent=true]
setblock ~177 ~133 ~98 jungle_leaves[persistent=true]
setblock ~177 ~133 ~100 jungle_leaves[persistent=true]
setblock ~177 ~133 ~101 jungle_leaves[persistent=true]
setblock ~177 ~133 ~103 oak_leaves[persistent=true]
setblock ~177 ~133 ~104 oak_leaves[persistent=true]
setblock ~177 ~133 ~105 oak_leaves[persistent=true]
setblock ~177 ~133 ~106 oak_leaves[persistent=true]
setblock ~177 ~133 ~109 oak_leaves[persistent=true]
setblock ~177 ~133 ~110 oak_leaves[persistent=true]
setblock ~177 ~133 ~111 jungle_leaves[persistent=true]
setblock ~177 ~133 ~112 oak_leaves[persistent=true]
setblock ~177 ~134 ~73 oak_leaves[persistent=true]
setblock ~177 ~134 ~74 oak_leaves[persistent=true]
setblock ~177 ~134 ~75 oak_leaves[persistent=true]
setblock ~177 ~134 ~76 jungle_leaves[persistent=true]
setblock ~177 ~134 ~77 jungle_leaves[persistent=true]
setblock ~177 ~134 ~78 oak_leaves[persistent=true]
setblock ~177 ~134 ~79 oak_wood
setblock ~177 ~134 ~81 oak_leaves[persistent=true]
setblock ~177 ~134 ~82 oak_leaves[persistent=true]
setblock ~177 ~134 ~83 oak_wood
setblock ~177 ~134 ~86 oak_leaves[persistent=true]
setblock ~177 ~134 ~88 oak_leaves[persistent=true]
setblock ~177 ~134 ~89 jungle_leaves[persistent=true]
setblock ~177 ~134 ~90 oak_leaves[persistent=true]
setblock ~177 ~134 ~91 jungle_leaves[persistent=true]
setblock ~177 ~134 ~92 oak_leaves[persistent=true]
setblock ~177 ~134 ~93 oak_leaves[persistent=true]
setblock ~177 ~134 ~94 oak_leaves[persistent=true]
setblock ~177 ~134 ~95 oak_leaves[persistent=true]
setblock ~177 ~134 ~96 oak_leaves[persistent=true]
setblock ~177 ~134 ~97 oak_leaves[persistent=true]
setblock ~177 ~134 ~99 oak_leaves[persistent=true]
setblock ~177 ~134 ~100 oak_leaves[persistent=true]
setblock ~177 ~134 ~101 oak_leaves[persistent=true]
setblock ~177 ~134 ~102 jungle_leaves[persistent=true]
setblock ~177 ~134 ~103 oak_leaves[persistent=true]
setblock ~177 ~134 ~105 oak_leaves[persistent=true]
setblock ~177 ~134 ~106 jungle_leaves[persistent=true]
setblock ~177 ~134 ~107 oak_leaves[persistent=true]
setblock ~177 ~134 ~108 oak_leaves[persistent=true]
setblock ~177 ~134 ~109 oak_leaves[persistent=true]
setblock ~177 ~134 ~110 oak_leaves[persistent=true]
setblock ~177 ~134 ~111 oak_leaves[persistent=true]
setblock ~177 ~134 ~112 oak_leaves[persistent=true]
setblock ~177 ~134 ~113 oak_leaves[persistent=true]
setblock ~177 ~135 ~74 oak_leaves[persistent=true]
setblock ~177 ~135 ~75 oak_leaves[persistent=true]
setblock ~177 ~135 ~76 oak_leaves[persistent=true]
setblock ~177 ~135 ~77 oak_wood
setblock ~177 ~135 ~78 oak_wood
setblock ~177 ~135 ~79 oak_wood
setblock ~177 ~135 ~80 oak_wood
setblock ~177 ~135 ~81 oak_wood
setblock ~177 ~135 ~82 oak_wood
setblock ~177 ~135 ~83 oak_wood
setblock ~177 ~135 ~84 oak_wood
setblock ~177 ~135 ~85 oak_leaves[persistent=true]
setblock ~177 ~135 ~86 oak_wood
setblock ~177 ~135 ~88 oak_leaves[persistent=true]
setblock ~177 ~135 ~89 oak_leaves[persistent=true]
setblock ~177 ~135 ~90 oak_leaves[persistent=true]
setblock ~177 ~135 ~91 oak_leaves[persistent=true]
setblock ~177 ~135 ~92 oak_leaves[persistent=true]
setblock ~177 ~135 ~93 jungle_leaves[persistent=true]
setblock ~177 ~135 ~94 jungle_leaves[persistent=true]
setblock ~177 ~135 ~95 oak_leaves[persistent=true]
setblock ~177 ~135 ~96 oak_leaves[persistent=true]
setblock ~177 ~135 ~97 oak_leaves[persistent=true]
setblock ~177 ~135 ~98 oak_leaves[persistent=true]
setblock ~177 ~135 ~99 jungle_leaves[persistent=true]
setblock ~177 ~135 ~101 oak_leaves[persistent=true]
setblock ~177 ~135 ~102 oak_leaves[persistent=true]
setblock ~177 ~135 ~103 oak_leaves[persistent=true]
setblock ~177 ~135 ~105 oak_leaves[persistent=true]
setblock ~177 ~135 ~106 oak_leaves[persistent=true]
setblock ~177 ~135 ~107 oak_leaves[persistent=true]
setblock ~177 ~135 ~108 oak_leaves[persistent=true]
setblock ~177 ~135 ~110 oak_leaves[persistent=true]
setblock ~177 ~135 ~111 oak_leaves[persistent=true]
setblock ~177 ~135 ~112 oak_leaves[persistent=true]
setblock ~177 ~135 ~113 oak_leaves[persistent=true]
setblock ~177 ~135 ~115 oak_leaves[persistent=true]
setblock ~177 ~135 ~116 oak_leaves[persistent=true]
setblock ~177 ~136 ~72 oak_leaves[persistent=true]
setblock ~177 ~136 ~73 oak_leaves[persistent=true]
setblock ~177 ~136 ~74 jungle_leaves[persistent=true]
setblock ~177 ~136 ~75 jungle_leaves[persistent=true]
setblock ~177 ~136 ~76 oak_leaves[persistent=true]
setblock ~177 ~136 ~77 oak_leaves[persistent=true]
setblock ~177 ~136 ~79 oak_leaves[persistent=true]
setblock ~177 ~136 ~80 oak_wood
setblock ~177 ~136 ~81 oak_wood
setblock ~177 ~136 ~82 oak_leaves[persistent=true]
setblock ~177 ~136 ~83 oak_leaves[persistent=true]
setblock ~177 ~136 ~84 oak_leaves[persistent=true]
setblock ~177 ~136 ~85 oak_leaves[persistent=true]
setblock ~177 ~136 ~86 jungle_leaves[persistent=true]
setblock ~177 ~136 ~87 oak_leaves[persistent=true]
setblock ~177 ~136 ~88 oak_leaves[persistent=true]
setblock ~177 ~136 ~89 oak_leaves[persistent=true]
setblock ~177 ~136 ~90 oak_leaves[persistent=true]
setblock ~177 ~136 ~91 oak_leaves[persistent=true]
setblock ~177 ~136 ~92 oak_leaves[persistent=true]
setblock ~177 ~136 ~93 jungle_leaves[persistent=true]
setblock ~177 ~136 ~94 oak_leaves[persistent=true]
setblock ~177 ~136 ~97 jungle_leaves[persistent=true]
setblock ~177 ~136 ~98 jungle_leaves[persistent=true]
setblock ~177 ~136 ~99 oak_leaves[persistent=true]
setblock ~177 ~136 ~100 oak_leaves[persistent=true]
setblock ~177 ~136 ~101 oak_wood
setblock ~177 ~136 ~102 oak_leaves[persistent=true]
setblock ~177 ~136 ~103 jungle_leaves[persistent=true]
setblock ~177 ~136 ~104 oak_leaves[persistent=true]
setblock ~177 ~136 ~105 oak_leaves[persistent=true]
setblock ~177 ~136 ~106 oak_leaves[persistent=true]
setblock ~177 ~136 ~107 oak_leaves[persistent=true]
setblock ~177 ~136 ~108 oak_leaves[persistent=true]
setblock ~177 ~136 ~110 oak_leaves[persistent=true]
setblock ~177 ~136 ~111 oak_leaves[persistent=true]
setblock ~177 ~136 ~112 oak_leaves[persistent=true]
setblock ~177 ~136 ~113 oak_leaves[persistent=true]
setblock ~177 ~136 ~114 jungle_leaves[persistent=true]
setblock ~177 ~136 ~115 oak_leaves[persistent=true]
setblock ~177 ~136 ~116 oak_leaves[persistent=true]
setblock ~177 ~137 ~72 jungle_leaves[persistent=true]
setblock ~177 ~137 ~73 oak_leaves[persistent=true]
setblock ~177 ~137 ~74 jungle_leaves[persistent=true]
setblock ~177 ~137 ~75 oak_leaves[persistent=true]
setblock ~177 ~137 ~76 oak_wood
setblock ~177 ~137 ~77 oak_wood
setblock ~177 ~137 ~78 oak_leaves[persistent=true]
setblock ~177 ~137 ~79 oak_wood
setblock ~177 ~137 ~80 oak_leaves[persistent=true]
setblock ~177 ~137 ~81 jungle_leaves[persistent=true]
setblock ~177 ~137 ~82 oak_leaves[persistent=true]
setblock ~177 ~137 ~84 oak_leaves[persistent=true]
setblock ~177 ~137 ~85 oak_leaves[persistent=true]
setblock ~177 ~137 ~86 oak_leaves[persistent=true]
setblock ~177 ~137 ~87 oak_leaves[persistent=true]
setblock ~177 ~137 ~88 oak_leaves[persistent=true]
setblock ~177 ~137 ~89 oak_leaves[persistent=true]
setblock ~177 ~137 ~90 oak_leaves[persistent=true]
setblock ~177 ~137 ~91 jungle_leaves[persistent=true]
setblock ~177 ~137 ~92 oak_leaves[persistent=true]
setblock ~177 ~137 ~93 oak_leaves[persistent=true]
setblock ~177 ~137 ~94 oak_leaves[persistent=true]
setblock ~177 ~137 ~97 oak_leaves[persistent=true]
setblock ~177 ~137 ~98 oak_leaves[persistent=true]
setblock ~177 ~137 ~99 oak_leaves[persistent=true]
setblock ~177 ~137 ~100 oak_leaves[persistent=true]
setblock ~177 ~137 ~101 jungle_leaves[persistent=true]
setblock ~177 ~137 ~102 oak_leaves[persistent=true]
setblock ~177 ~137 ~103 oak_leaves[persistent=true]
setblock ~177 ~137 ~104 jungle_leaves[persistent=true]
setblock ~177 ~137 ~105 oak_leaves[persistent=true]
setblock ~177 ~137 ~106 jungle_leaves[persistent=true]
setblock ~177 ~137 ~107 jungle_leaves[persistent=true]
setblock ~177 ~137 ~114 oak_leaves[persistent=true]
setblock ~177 ~137 ~115 jungle_leaves[persistent=true]
setblock ~177 ~137 ~116 oak_leaves[persistent=true]
setblock ~177 ~137 ~117 oak_leaves[persistent=true]
setblock ~177 ~138 ~72 oak_leaves[persistent=true]
setblock ~177 ~138 ~73 oak_leaves[persistent=true]
setblock ~177 ~138 ~74 oak_leaves[persistent=true]
setblock ~177 ~138 ~75 jungle_leaves[persistent=true]
setblock ~177 ~138 ~76 oak_leaves[persistent=true]
setblock ~177 ~138 ~77 jungle_leaves[persistent=true]
setblock ~177 ~138 ~78 oak_wood
setblock ~177 ~138 ~79 oak_leaves[persistent=true]
setblock ~177 ~138 ~80 oak_wood
setblock ~177 ~138 ~81 jungle_leaves[persistent=true]
setblock ~177 ~138 ~82 oak_wood
setblock ~177 ~138 ~83 oak_wood
setblock ~177 ~138 ~84 oak_leaves[persistent=true]
setblock ~177 ~138 ~85 oak_leaves[persistent=true]
setblock ~177 ~138 ~86 oak_leaves[persistent=true]
setblock ~177 ~138 ~87 jungle_leaves[persistent=true]
setblock ~177 ~138 ~88 oak_leaves[persistent=true]
setblock ~177 ~138 ~89 jungle_leaves[persistent=true]
setblock ~177 ~138 ~90 oak_leaves[persistent=true]
setblock ~177 ~138 ~91 oak_leaves[persistent=true]
setblock ~177 ~138 ~92 oak_leaves[persistent=true]
setblock ~177 ~138 ~93 jungle_leaves[persistent=true]
setblock ~177 ~138 ~94 oak_leaves[persistent=true]
setblock ~177 ~138 ~97 oak_leaves[persistent=true]
setblock ~177 ~138 ~98 oak_leaves[persistent=true]
setblock ~177 ~138 ~99 oak_leaves[persistent=true]
setblock ~177 ~138 ~100 oak_leaves[persistent=true]
setblock ~177 ~138 ~103 oak_leaves[persistent=true]
setblock ~177 ~138 ~104 jungle_leaves[persistent=true]
setblock ~177 ~138 ~105 jungle_leaves[persistent=true]
setblock ~177 ~138 ~106 jungle_leaves[persistent=true]
setblock ~177 ~138 ~113 oak_leaves[persistent=true]
setblock ~177 ~138 ~114 oak_leaves[persistent=true]
setblock ~177 ~138 ~115 oak_leaves[persistent=true]
setblock ~177 ~138 ~116 jungle_leaves[persistent=true]
setblock ~177 ~138 ~117 oak_leaves[persistent=true]
setblock ~177 ~139 ~72 oak_leaves[persistent=true]
setblock ~177 ~139 ~73 oak_leaves[persistent=true]
setblock ~177 ~139 ~74 oak_leaves[persistent=true]
setblock ~177 ~139 ~75 oak_leaves[persistent=true]
setblock ~177 ~139 ~76 oak_leaves[persistent=true]
setblock ~177 ~139 ~77 jungle_leaves[persistent=true]
setblock ~177 ~139 ~78 oak_leaves[persistent=true]
setblock ~177 ~139 ~79 oak_leaves[persistent=true]
setblock ~177 ~139 ~80 oak_leaves[persistent=true]
setblock ~177 ~139 ~81 jungle_leaves[persistent=true]
setblock ~177 ~139 ~83 oak_leaves[persistent=true]
setblock ~177 ~139 ~84 oak_leaves[persistent=true]
setblock ~177 ~139 ~85 oak_leaves[persistent=true]
setblock ~177 ~139 ~102 oak_leaves[persistent=true]
setblock ~177 ~139 ~103 oak_leaves[persistent=true]
setblock ~177 ~139 ~104 oak_leaves[persistent=true]
setblock ~177 ~139 ~105 oak_leaves[persistent=true]
setblock ~177 ~139 ~115 oak_leaves[persistent=true]
setblock ~177 ~139 ~116 oak_leaves[persistent=true]
setblock ~177 ~139 ~117 jungle_leaves[persistent=true]
setblock ~177 ~140 ~75 jungle_leaves[persistent=true]
setblock ~177 ~140 ~76 oak_leaves[persistent=true]
setblock ~177 ~140 ~77 oak_leaves[persistent=true]
setblock ~178 ~127 ~81 oak_leaves[persistent=true]
setblock ~178 ~127 ~82 oak_leaves[persistent=true]
setblock ~178 ~127 ~83 oak_leaves[persistent=true]
setblock ~178 ~127 ~99 oak_leaves[persistent=true]
setblock ~178 ~127 ~100 oak_leaves[persistent=true]
setblock ~178 ~128 ~81 oak_leaves[persistent=true]
setblock ~178 ~128 ~82 oak_wood
setblock ~178 ~128 ~83 oak_leaves[persistent=true]
setblock ~178 ~128 ~99 oak_leaves[persistent=true]
setblock ~178 ~128 ~100 jungle_leaves[persistent=true]
setblock ~178 ~128 ~101 oak_leaves[persistent=true]
setblock ~178 ~128 ~104 oak_leaves[persistent=true]
setblock ~178 ~128 ~105 oak_leaves[persistent=true]
setblock ~178 ~128 ~106 oak_leaves[persistent=true]
setblock ~178 ~128 ~107 oak_leaves[persistent=true]
setblock ~178 ~129 ~81 jungle_leaves[persistent=true]
setblock ~178 ~129 ~82 jungle_leaves[persistent=true]
setblock ~178 ~129 ~83 oak_leaves[persistent=true]
setblock ~178 ~129 ~85 jungle_leaves[persistent=true]
setblock ~178 ~129 ~86 jungle_leaves[persistent=true]
setblock ~178 ~129 ~87 oak_leaves[persistent=true]
setblock ~178 ~129 ~91 oak_leaves[persistent=true]
setblock ~178 ~129 ~92 oak_leaves[persistent=true]
setblock ~178 ~129 ~93 oak_leaves[persistent=true]
setblock ~178 ~129 ~94 oak_leaves[persistent=true]
setblock ~178 ~129 ~99 oak_leaves[persistent=true]
setblock ~178 ~129 ~100 oak_wood
setblock ~178 ~129 ~101 jungle_leaves[persistent=true]
setblock ~178 ~129 ~102 jungle_leaves[persistent=true]
setblock ~178 ~129 ~103 oak_leaves[persistent=true]
setblock ~178 ~129 ~104 oak_leaves[persistent=true]
setblock ~178 ~129 ~105 oak_leaves[persistent=true]
setblock ~178 ~129 ~106 jungle_leaves[persistent=true]
setblock ~178 ~129 ~107 oak_leaves[persistent=true]
setblock ~178 ~130 ~76 oak_leaves[persistent=true]
setblock ~178 ~130 ~77 oak_leaves[persistent=true]
setblock ~178 ~130 ~78 oak_leaves[persistent=true]
setblock ~178 ~130 ~79 oak_leaves[persistent=true]
setblock ~178 ~130 ~81 oak_leaves[persistent=true]
setblock ~178 ~130 ~82 oak_leaves[persistent=true]
setblock ~178 ~130 ~83 jungle_leaves[persistent=true]
setblock ~178 ~130 ~85 jungle_leaves[persistent=true]
setblock ~178 ~130 ~86 oak_wood
setblock ~178 ~130 ~87 oak_leaves[persistent=true]
setblock ~178 ~130 ~91 jungle_leaves[persistent=true]
setblock ~178 ~130 ~92 jungle_leaves[persistent=true]
setblock ~178 ~130 ~93 oak_leaves[persistent=true]
setblock ~178 ~130 ~94 oak_leaves[persistent=true]
setblock ~178 ~130 ~99 oak_leaves[persistent=true]
setblock ~178 ~130 ~100 oak_leaves[persistent=true]
setblock ~178 ~130 ~101 oak_leaves[persistent=true]
setblock ~178 ~130 ~102 oak_leaves[persistent=true]
setblock ~178 ~130 ~103 oak_leaves[persistent=true]
setblock ~178 ~130 ~104 oak_leaves[persistent=true]
setblock ~178 ~130 ~105 oak_leaves[persistent=true]
setblock ~178 ~130 ~106 oak_leaves[persistent=true]
setblock ~178 ~130 ~107 jungle_leaves[persistent=true]
setblock ~178 ~131 ~76 jungle_leaves[persistent=true]
setblock ~178 ~131 ~77 oak_leaves[persistent=true]
setblock ~178 ~131 ~78 oak_leaves[persistent=true]
setblock ~178 ~131 ~79 oak_leaves[persistent=true]
setblock ~178 ~131 ~80 oak_leaves[persistent=true]
setblock ~178 ~131 ~81 oak_leaves[persistent=true]
setblock ~178 ~131 ~82 oak_leaves[persistent=true]
setblock ~178 ~131 ~84 oak_leaves[persistent=true]
setblock ~178 ~131 ~85 oak_leaves[persistent=true]
setblock ~178 ~131 ~86 jungle_leaves[persistent=true]
setblock ~178 ~131 ~87 jungle_leaves[persistent=true]
setblock ~178 ~131 ~88 jungle_leaves[persistent=true]
setblock ~178 ~131 ~89 jungle_leaves[persistent=true]
setblock ~178 ~131 ~90 oak_leaves[persistent=true]
setblock ~178 ~131 ~91 oak_leaves[persistent=true]
setblock ~178 ~131 ~92 jungle_leaves[persistent=true]
setblock ~178 ~131 ~93 oak_leaves[persistent=true]
setblock ~178 ~131 ~94 oak_leaves[persistent=true]
setblock ~178 ~131 ~99 oak_leaves[persistent=true]
setblock ~178 ~131 ~101 oak_wood
setblock ~178 ~131 ~102 oak_leaves[persistent=true]
setblock ~178 ~131 ~103 oak_leaves[persistent=true]
setblock ~178 ~131 ~105 oak_wood
setblock ~178 ~131 ~106 oak_leaves[persistent=true]
setblock ~178 ~131 ~107 oak_leaves[persistent=true]
setblock ~178 ~131 ~109 oak_leaves[persistent=true]
setblock ~178 ~131 ~110 oak_leaves[persistent=true]
setblock ~178 ~131 ~111 oak_leaves[persistent=true]
setblock ~178 ~131 ~112 oak_leaves[persistent=true]
setblock ~178 ~132 ~76 oak_leaves[persistent=true]
setblock ~178 ~132 ~77 oak_leaves[persistent=true]
setblock ~178 ~132 ~78 oak_wood
setblock ~178 ~132 ~80 jungle_leaves[persistent=true]
setblock ~178 ~132 ~81 oak_leaves[persistent=true]
setblock ~178 ~132 ~82 oak_leaves[persistent=true]
setblock ~178 ~132 ~83 oak_leaves[persistent=true]
setblock ~178 ~132 ~84 oak_leaves[persistent=true]
setblock ~178 ~132 ~85 oak_leaves[persistent=true]
setblock ~178 ~132 ~86 oak_leaves[persistent=true]
setblock ~178 ~132 ~87 oak_leaves[persistent=true]
setblock ~178 ~132 ~88 oak_wood
setblock ~178 ~132 ~89 oak_leaves[persistent=true]
setblock ~178 ~132 ~90 oak_leaves[persistent=true]
setblock ~178 ~132 ~91 oak_leaves[persistent=true]
setblock ~178 ~132 ~92 oak_leaves[persistent=true]
setblock ~178 ~132 ~93 oak_leaves[persistent=true]
setblock ~178 ~132 ~94 oak_leaves[persistent=true]
setblock ~178 ~132 ~99 oak_leaves[persistent=true]
setblock ~178 ~132 ~101 oak_leaves[persistent=true]
setblock ~178 ~132 ~103 oak_leaves[persistent=true]
setblock ~178 ~132 ~104 oak_leaves[persistent=true]
setblock ~178 ~132 ~105 oak_leaves[persistent=true]
setblock ~178 ~132 ~106 oak_leaves[persistent=true]
setblock ~178 ~132 ~109 oak_leaves[persistent=true]
setblock ~178 ~132 ~110 oak_leaves[persistent=true]
setblock ~178 ~132 ~111 oak_leaves[persistent=true]
setblock ~178 ~132 ~112 oak_leaves[persistent=true]
setblock ~178 ~133 ~75 oak_leaves[persistent=true]
setblock ~178 ~133 ~76 oak_leaves[persistent=true]
setblock ~178 ~133 ~78 oak_leaves[persistent=true]
setblock ~178 ~133 ~79 oak_leaves[persistent=true]
setblock ~178 ~133 ~80 oak_leaves[persistent=true]
setblock ~178 ~133 ~81 jungle_leaves[persistent=true]
setblock ~178 ~133 ~82 oak_wood
setblock ~178 ~133 ~83 oak_wood
setblock ~178 ~133 ~84 oak_wood
setblock ~178 ~133 ~85 oak_wood
setblock ~178 ~133 ~86 oak_leaves[persistent=true]
setblock ~178 ~133 ~87 oak_leaves[persistent=true]
setblock ~178 ~133 ~88 oak_wood
setblock ~178 ~133 ~89 jungle_leaves[persistent=true]
setblock ~178 ~133 ~90 oak_leaves[persistent=true]
setblock ~178 ~133 ~103 jungle_leaves[persistent=true]
setblock ~178 ~133 ~104 oak_leaves[persistent=true]
setblock ~178 ~133 ~105 oak_leaves[persistent=true]
setblock ~178 ~133 ~106 oak_leaves[persistent=true]
setblock ~178 ~133 ~110 jungle_leaves[persistent=true]
setblock ~178 ~133 ~111 oak_leaves[persistent=true]
setblock ~178 ~133 ~112 oak_leaves[persistent=true]
setblock ~178 ~134 ~75 oak_leaves[persistent=true]
setblock ~178 ~134 ~77 jungle_leaves[persistent=true]
setblock ~178 ~134 ~78 oak_leaves[persistent=true]
setblock ~178 ~134 ~79 oak_wood
setblock ~178 ~134 ~80 oak_leaves[persistent=true]
setblock ~178 ~134 ~81 jungle_leaves[persistent=true]
setblock ~178 ~134 ~82 oak_leaves[persistent=true]
setblock ~178 ~134 ~83 oak_leaves[persistent=true]
setblock ~178 ~134 ~84 oak_leaves[persistent=true]
setblock ~178 ~134 ~85 jungle_leaves[persistent=true]
setblock ~178 ~134 ~86 oak_leaves[persistent=true]
setblock ~178 ~134 ~88 oak_leaves[persistent=true]
setblock ~178 ~134 ~89 oak_leaves[persistent=true]
setblock ~178 ~134 ~105 oak_leaves[persistent=true]
setblock ~178 ~134 ~107 oak_leaves[persistent=true]
setblock ~178 ~134 ~108 oak_leaves[persistent=true]
setblock ~178 ~134 ~109 jungle_leaves[persistent=true]
setblock ~178 ~134 ~110 jungle_leaves[persistent=true]
setblock ~178 ~134 ~111 oak_leaves[persistent=true]
setblock ~178 ~134 ~112 oak_leaves[persistent=true]
setblock ~178 ~135 ~73 jungle_leaves[persistent=true]
setblock ~178 ~135 ~74 oak_leaves[persistent=true]
setblock ~178 ~135 ~75 oak_leaves[persistent=true]
setblock ~178 ~135 ~76 oak_leaves[persistent=true]
setblock ~178 ~135 ~77 oak_leaves[persistent=true]
setblock ~178 ~135 ~78 oak_leaves[persistent=true]
setblock ~178 ~135 ~79 oak_wood
setblock ~178 ~135 ~81 oak_leaves[persistent=true]
setblock ~178 ~135 ~82 oak_wood
setblock ~178 ~135 ~83 oak_wood
setblock ~178 ~135 ~84 jungle_leaves[persistent=true]
setblock ~178 ~135 ~85 oak_wood
setblock ~178 ~135 ~86 oak_leaves[persistent=true]
setblock ~178 ~135 ~87 jungle_leaves[persistent=true]
setblock ~178 ~135 ~88 jungle_leaves[persistent=true]
setblock ~178 ~135 ~89 oak_leaves[persistent=true]
setblock ~178 ~135 ~98 oak_leaves[persistent=true]
setblock ~178 ~135 ~99 oak_leaves[persistent=true]
setblock ~178 ~135 ~100 oak_leaves[persistent=true]
setblock ~178 ~135 ~102 jungle_leaves[persistent=true]
setblock ~178 ~135 ~105 oak_leaves[persistent=true]
setblock ~178 ~135 ~106 oak_leaves[persistent=true]
setblock ~178 ~135 ~107 oak_leaves[persistent=true]
setblock ~178 ~135 ~108 oak_leaves[persistent=true]
setblock ~178 ~136 ~73 oak_leaves[persistent=true]
setblock ~178 ~136 ~74 oak_leaves[persistent=true]
setblock ~178 ~136 ~76 jungle_leaves[persistent=true]
setblock ~178 ~136 ~77 oak_leaves[persistent=true]
setblock ~178 ~136 ~78 oak_leaves[persistent=true]
setblock ~178 ~136 ~79 oak_leaves[persistent=true]
setblock ~178 ~136 ~80 oak_wood
setblock ~178 ~136 ~81 oak_leaves[persistent=true]
setblock ~178 ~136 ~82 oak_leaves[persistent=true]
setblock ~178 ~136 ~83 oak_leaves[persistent=true]
setblock ~178 ~136 ~85 oak_wood
setblock ~178 ~136 ~86 oak_leaves[persistent=true]
setblock ~178 ~136 ~87 oak_wood
setblock ~178 ~136 ~88 oak_leaves[persistent=true]
setblock ~178 ~136 ~98 oak_leaves[persistent=true]
setblock ~178 ~136 ~99 oak_leaves[persistent=true]
setblock ~178 ~136 ~100 oak_wood
setblock ~178 ~136 ~102 oak_leaves[persistent=true]
setblock ~178 ~136 ~103 oak_leaves[persistent=true]
setblock ~178 ~136 ~104 oak_leaves[persistent=true]
setblock ~178 ~136 ~105 jungle_leaves[persistent=true]
setblock ~178 ~136 ~106 jungle_leaves[persistent=true]
setblock ~178 ~136 ~107 oak_leaves[persistent=true]
setblock ~178 ~136 ~108 oak_leaves[persistent=true]
setblock ~178 ~137 ~74 oak_leaves[persistent=true]
setblock ~178 ~137 ~75 jungle_leaves[persistent=true]
setblock ~178 ~137 ~76 oak_wood
setblock ~178 ~137 ~78 oak_wood
setblock ~178 ~137 ~79 oak_leaves[persistent=true]
setblock ~178 ~137 ~80 oak_leaves[persistent=true]
setblock ~178 ~137 ~81 jungle_leaves[persistent=true]
setblock ~178 ~137 ~82 jungle_leaves[persistent=true]
setblock ~178 ~137 ~83 oak_leaves[persistent=true]
setblock ~178 ~137 ~84 jungle_leaves[persistent=true]
setblock ~178 ~137 ~85 oak_leaves[persistent=true]
setblock ~178 ~137 ~86 jungle_leaves[persistent=true]
setblock ~178 ~137 ~87 oak_leaves[persistent=true]
setblock ~178 ~137 ~88 oak_leaves[persistent=true]
setblock ~178 ~137 ~89 jungle_leaves[persistent=true]
setblock ~178 ~137 ~98 jungle_leaves[persistent=true]
setblock ~178 ~137 ~99 oak_leaves[persistent=true]
setblock ~178 ~137 ~100 oak_leaves[persistent=true]
setblock ~178 ~137 ~101 oak_leaves[persistent=true]
setblock ~178 ~137 ~102 jungle_leaves[persistent=true]
setblock ~178 ~137 ~103 jungle_leaves[persistent=true]
setblock ~178 ~137 ~104 oak_leaves[persistent=true]
setblock ~178 ~137 ~105 oak_leaves[persistent=true]
setblock ~178 ~137 ~106 oak_leaves[persistent=true]
setblock ~178 ~137 ~107 oak_leaves[persistent=true]
setblock ~178 ~137 ~108 oak_leaves[persistent=true]
setblock ~178 ~138 ~73 oak_leaves[persistent=true]
setblock ~178 ~138 ~74 oak_leaves[persistent=true]
setblock ~178 ~138 ~75 oak_leaves[persistent=true]
setblock ~178 ~138 ~76 oak_leaves[persistent=true]
setblock ~178 ~138 ~77 oak_leaves[persistent=true]
setblock ~178 ~138 ~78 oak_leaves[persistent=true]
setblock ~178 ~138 ~80 oak_leaves[persistent=true]
setblock ~178 ~138 ~81 jungle_leaves[persistent=true]
setblock ~178 ~138 ~82 oak_leaves[persistent=true]
setblock ~178 ~138 ~83 jungle_leaves[persistent=true]
setblock ~178 ~138 ~84 oak_leaves[persistent=true]
setblock ~178 ~138 ~85 oak_leaves[persistent=true]
setblock ~178 ~138 ~102 oak_leaves[persistent=true]
setblock ~178 ~138 ~103 oak_leaves[persistent=true]
setblock ~178 ~138 ~104 jungle_leaves[persistent=true]
setblock ~178 ~138 ~105 oak_leaves[persistent=true]
setblock ~178 ~139 ~74 oak_leaves[persistent=true]
setblock ~178 ~139 ~75 oak_leaves[persistent=true]
setblock ~178 ~139 ~76 oak_leaves[persistent=true]
setblock ~178 ~139 ~77 oak_wood
setblock ~178 ~139 ~78 oak_leaves[persistent=true]
setblock ~178 ~139 ~79 jungle_leaves[persistent=true]
setblock ~178 ~139 ~80 oak_leaves[persistent=true]
setblock ~178 ~139 ~81 oak_leaves[persistent=true]
setblock ~178 ~139 ~82 jungle_leaves[persistent=true]
setblock ~178 ~139 ~83 jungle_leaves[persistent=true]
setblock ~178 ~139 ~84 oak_leaves[persistent=true]
setblock ~178 ~139 ~85 oak_leaves[persistent=true]
setblock ~178 ~139 ~102 oak_leaves[persistent=true]
setblock ~178 ~139 ~103 oak_leaves[persistent=true]
setblock ~178 ~139 ~104 jungle_leaves[persistent=true]
setblock ~178 ~139 ~105 jungle_leaves[persistent=true]
setblock ~178 ~140 ~74 oak_leaves[persistent=true]
setblock ~178 ~140 ~75 oak_leaves[persistent=true]
setblock ~178 ~140 ~76 oak_leaves[persistent=true]
setblock ~178 ~140 ~77 jungle_leaves[persistent=true]
setblock ~178 ~140 ~78 oak_leaves[persistent=true]
setblock ~179 ~127 ~81 jungle_leaves[persistent=true]
setblock ~179 ~127 ~82 oak_leaves[persistent=true]
setblock ~179 ~127 ~83 jungle_leaves[persistent=true]
setblock ~179 ~127 ~99 jungle_leaves[persistent=true]
setblock ~179 ~127 ~100 oak_leaves[persistent=true]
setblock ~179 ~128 ~81 oak_leaves[persistent=true]
setblock ~179 ~128 ~82 oak_wood
setblock ~179 ~128 ~83 oak_leaves[persistent=true]
setblock ~179 ~128 ~99 oak_leaves[persistent=true]
setblock ~179 ~128 ~100 oak_leaves[persistent=true]
setblock ~179 ~128 ~101 oak_leaves[persistent=true]
setblock ~179 ~128 ~106 oak_leaves[persistent=true]
setblock ~179 ~128 ~107 oak_leaves[persistent=true]
setblock ~179 ~129 ~81 oak_leaves[persistent=true]
setblock ~179 ~129 ~82 oak_leaves[persistent=true]
setblock ~179 ~129 ~83 oak_leaves[persistent=true]
setblock ~179 ~129 ~85 oak_leaves[persistent=true]
setblock ~179 ~129 ~86 oak_leaves[persistent=true]
setblock ~179 ~129 ~87 oak_leaves[persistent=true]
setblock ~179 ~129 ~99 oak_leaves[persistent=true]
setblock ~179 ~129 ~100 oak_leaves[persistent=true]
setblock ~179 ~129 ~102 oak_leaves[persistent=true]
setblock ~179 ~129 ~103 oak_leaves[persistent=true]
setblock ~179 ~129 ~105 oak_leaves[persistent=true]
setblock ~179 ~129 ~107 oak_leaves[persistent=true]
setblock ~179 ~130 ~76 oak_leaves[persistent=true]
setblock ~179 ~130 ~77 jungle_leaves[persistent=true]
setblock ~179 ~130 ~78 oak_leaves[persistent=true]
setblock ~179 ~130 ~83 oak_leaves[persistent=true]
setblock ~179 ~130 ~85 oak_leaves[persistent=true]
setblock ~179 ~130 ~87 oak_leaves[persistent=true]
setblock ~179 ~130 ~99 jungle_leaves[persistent=true]
setblock ~179 ~130 ~100 oak_leaves[persistent=true]
setblock ~179 ~130 ~101 oak_wood
setblock ~179 ~130 ~102 oak_leaves[persistent=true]
setblock ~179 ~130 ~103 oak_leaves[persistent=true]
setblock ~179 ~130 ~104 oak_leaves[persistent=true]
setblock ~179 ~130 ~105 oak_leaves[persistent=true]
setblock ~179 ~130 ~106 jungle_leaves[persistent=true]
setblock ~179 ~130 ~107 oak_leaves[persistent=true]
setblock ~179 ~131 ~76 oak_leaves[persistent=true]
setblock ~179 ~131 ~79 oak_leaves[persistent=true]
setblock ~179 ~131 ~80 oak_leaves[persistent=true]
setblock ~179 ~131 ~81 oak_leaves[persistent=true]
setblock ~179 ~131 ~82 oak_leaves[persistent=true]
setblock ~179 ~131 ~83 oak_leaves[persistent=true]
setblock ~179 ~131 ~84 oak_leaves[persistent=true]
setblock ~179 ~131 ~85 oak_leaves[persistent=true]
setblock ~179 ~131 ~86 oak_leaves[persistent=true]
setblock ~179 ~131 ~87 oak_leaves[persistent=true]
setblock ~179 ~131 ~88 jungle_leaves[persistent=true]
setblock ~179 ~131 ~89 oak_leaves[persistent=true]
setblock ~179 ~131 ~99 jungle_leaves[persistent=true]
setblock ~179 ~131 ~100 oak_leaves[persistent=true]
setblock ~179 ~131 ~101 oak_leaves[persistent=true]
setblock ~179 ~131 ~102 oak_leaves[persistent=true]
setblock ~179 ~131 ~103 oak_leaves[persistent=true]
setblock ~179 ~131 ~104 oak_leaves[persistent=true]
setblock ~179 ~131 ~105 oak_wood
setblock ~179 ~131 ~106 oak_leaves[persistent=true]
setblock ~179 ~131 ~107 oak_leaves[persistent=true]
setblock ~179 ~132 ~76 oak_leaves[persistent=true]
setblock ~179 ~132 ~77 jungle_leaves[persistent=true]
setblock ~179 ~132 ~78 jungle_leaves[persistent=true]
setblock ~179 ~132 ~79 oak_leaves[persistent=true]
setblock ~179 ~132 ~80 oak_leaves[persistent=true]
setblock ~179 ~132 ~81 oak_leaves[persistent=true]
setblock ~179 ~132 ~82 jungle_leaves[persistent=true]
setblock ~179 ~132 ~83 oak_leaves[persistent=true]
setblock ~179 ~132 ~84 oak_leaves[persistent=true]
setblock ~179 ~132 ~85 oak_wood
setblock ~179 ~132 ~86 oak_leaves[persistent=true]
setblock ~179 ~132 ~87 oak_leaves[persistent=true]
setblock ~179 ~132 ~88 oak_leaves[persistent=true]
setblock ~179 ~132 ~89 jungle_leaves[persistent=true]
setblock ~179 ~132 ~99 oak_leaves[persistent=true]
setblock ~179 ~132 ~100 oak_leaves[persistent=true]
setblock ~179 ~132 ~101 jungle_leaves[persistent=true]
setblock ~179 ~132 ~102 oak_leaves[persistent=true]
setblock ~179 ~132 ~103 oak_leaves[persistent=true]
setblock ~179 ~132 ~104 oak_leaves[persistent=true]
setblock ~179 ~132 ~105 oak_leaves[persistent=true]
setblock ~179 ~132 ~106 oak_leaves[persistent=true]
setblock ~179 ~132 ~107 oak_leaves[persistent=true]
setblock ~179 ~133 ~75 oak_leaves[persistent=true]
setblock ~179 ~133 ~76 jungle_leaves[persistent=true]
setblock ~179 ~133 ~77 oak_leaves[persistent=true]
setblock ~179 ~133 ~78 oak_leaves[persistent=true]
setblock ~179 ~133 ~79 oak_leaves[persistent=true]
setblock ~179 ~133 ~81 oak_wood
setblock ~179 ~133 ~82 oak_wood
setblock ~179 ~133 ~84 oak_wood
setblock ~179 ~133 ~85 oak_wood
setblock ~179 ~133 ~88 oak_wood
setblock ~179 ~133 ~89 oak_leaves[persistent=true]
setblock ~179 ~134 ~75 jungle_leaves[persistent=true]
setblock ~179 ~134 ~76 oak_leaves[persistent=true]
setblock ~179 ~134 ~77 jungle_leaves[persistent=true]
setblock ~179 ~134 ~78 oak_wood
setblock ~179 ~134 ~79 jungle_leaves[persistent=true]
setblock ~179 ~134 ~80 jungle_leaves[persistent=true]
setblock ~179 ~134 ~81 oak_leaves[persistent=true]
setblock ~179 ~134 ~82 oak_leaves[persistent=true]
setblock ~179 ~134 ~83 oak_leaves[persistent=true]
setblock ~179 ~134 ~84 oak_leaves[persistent=true]
setblock ~179 ~134 ~85 jungle_leaves[persistent=true]
setblock ~179 ~134 ~86 oak_wood
setblock ~179 ~134 ~87 oak_leaves[persistent=true]
setblock ~179 ~134 ~88 oak_leaves[persistent=true]
setblock ~179 ~134 ~89 jungle_leaves[persistent=true]
setblock ~179 ~135 ~73 oak_leaves[persistent=true]
setblock ~179 ~135 ~74 oak_leaves[persistent=true]
setblock ~179 ~135 ~75 oak_leaves[persistent=true]
setblock ~179 ~135 ~76 oak_leaves[persistent=true]
setblock ~179 ~135 ~77 jungle_leaves[persistent=true]
setblock ~179 ~135 ~78 oak_wood
setblock ~179 ~135 ~79 oak_leaves[persistent=true]
setblock ~179 ~135 ~80 oak_leaves[persistent=true]
setblock ~179 ~135 ~81 oak_leaves[persistent=true]
setblock ~179 ~135 ~82 jungle_leaves[persistent=true]
setblock ~179 ~135 ~83 oak_wood
setblock ~179 ~135 ~84 oak_wood
setblock ~179 ~135 ~85 oak_leaves[persistent=true]
setblock ~179 ~135 ~86 oak_wood
setblock ~179 ~135 ~87 oak_leaves[persistent=true]
setblock ~179 ~135 ~88 oak_leaves[persistent=true]
setblock ~179 ~135 ~89 jungle_leaves[persistent=true]
setblock ~179 ~135 ~98 oak_leaves[persistent=true]
setblock ~179 ~135 ~99 oak_leaves[persistent=true]
setblock ~179 ~135 ~100 oak_leaves[persistent=true]
setblock ~179 ~136 ~73 jungle_leaves[persistent=true]
setblock ~179 ~136 ~74 jungle_leaves[persistent=true]
setblock ~179 ~136 ~75 oak_leaves[persistent=true]
setblock ~179 ~136 ~77 oak_leaves[persistent=true]
setblock ~179 ~136 ~78 oak_leaves[persistent=true]
setblock ~179 ~136 ~79 oak_wood
setblock ~179 ~136 ~81 oak_leaves[persistent=true]
setblock ~179 ~136 ~82 jungle_leaves[persistent=true]
setblock ~179 ~136 ~83 oak_wood
setblock ~179 ~136 ~84 oak_leaves[persistent=true]
setblock ~179 ~136 ~85 oak_wood
setblock ~179 ~136 ~86 oak_leaves[persistent=true]
setblock ~179 ~136 ~88 oak_leaves[persistent=true]
setblock ~179 ~136 ~89 oak_leaves[persistent=true]
setblock ~179 ~136 ~98 oak_leaves[persistent=true]
setblock ~179 ~136 ~99 jungle_leaves[persistent=true]
setblock ~179 ~136 ~100 jungle_leaves[persistent=true]
setblock ~179 ~137 ~73 oak_leaves[persistent=true]
setblock ~179 ~137 ~75 oak_leaves[persistent=true]
setblock ~179 ~137 ~76 jungle_leaves[persistent=true]
setblock ~179 ~137 ~77 oak_wood
setblock ~179 ~137 ~78 oak_leaves[persistent=true]
setblock ~179 ~137 ~80 oak_leaves[persistent=true]
setblock ~179 ~137 ~81 oak_leaves[persistent=true]
setblock ~179 ~137 ~83 oak_leaves[persistent=true]
setblock ~179 ~137 ~84 jungle_leaves[persistent=true]
setblock ~179 ~137 ~85 jungle_leaves[persistent=true]
setblock ~179 ~137 ~86 oak_leaves[persistent=true]
setblock ~179 ~137 ~87 jungle_leaves[persistent=true]
setblock ~179 ~137 ~88 oak_leaves[persistent=true]
setblock ~179 ~137 ~89 oak_leaves[persistent=true]
setblock ~179 ~137 ~98 oak_leaves[persistent=true]
setblock ~179 ~137 ~99 oak_leaves[persistent=true]
setblock ~179 ~137 ~100 oak_leaves[persistent=true]
setblock ~179 ~138 ~73 oak_leaves[persistent=true]
setblock ~179 ~138 ~74 oak_leaves[persistent=true]
setblock ~179 ~138 ~75 oak_leaves[persistent=true]
setblock ~179 ~138 ~76 oak_leaves[persistent=true]
setblock ~179 ~138 ~77 jungle_leaves[persistent=true]
setblock ~179 ~138 ~78 oak_leaves[persistent=true]
setblock ~179 ~138 ~79 oak_leaves[persistent=true]
setblock ~179 ~138 ~80 oak_leaves[persistent=true]
setblock ~179 ~138 ~81 oak_leaves[persistent=true]
setblock ~179 ~138 ~82 oak_leaves[persistent=true]
setblock ~179 ~138 ~83 oak_leaves[persistent=true]
setblock ~179 ~138 ~84 oak_leaves[persistent=true]
setblock ~179 ~138 ~85 jungle_leaves[persistent=true]
setblock ~179 ~139 ~74 oak_leaves[persistent=true]
setblock ~179 ~139 ~75 jungle_leaves[persistent=true]
setblock ~179 ~139 ~76 oak_wood
setblock ~179 ~139 ~77 jungle_leaves[persistent=true]
setblock ~179 ~139 ~78 jungle_leaves[persistent=true]
setblock ~179 ~139 ~79 oak_leaves[persistent=true]
setblock ~179 ~139 ~80 oak_leaves[persistent=true]
setblock ~179 ~139 ~81 oak_leaves[persistent=true]
setblock ~179 ~139 ~82 oak_leaves[persistent=true]
setblock ~179 ~139 ~83 jungle_leaves[persistent=true]
setblock ~179 ~140 ~74 oak_leaves[persistent=true]
setblock ~179 ~140 ~76 oak_leaves[persistent=true]
setblock ~179 ~140 ~77 oak_leaves[persistent=true]
setblock ~179 ~140 ~78 oak_leaves[persistent=true]
setblock ~180 ~127 ~81 jungle_leaves[persistent=true]
setblock ~180 ~127 ~82 oak_leaves[persistent=true]
setblock ~180 ~127 ~83 oak_leaves[persistent=true]
setblock ~180 ~127 ~99 oak_leaves[persistent=true]
setblock ~180 ~127 ~100 jungle_leaves[persistent=true]
setblock ~180 ~127 ~101 oak_leaves[persistent=true]
setblock ~180 ~128 ~81 oak_leaves[persistent=true]
setblock ~180 ~128 ~82 oak_leaves[persistent=true]
setblock ~180 ~128 ~83 oak_leaves[persistent=true]
setblock ~180 ~128 ~99 jungle_leaves[persistent=true]
setblock ~180 ~128 ~100 oak_leaves[persistent=true]
setblock ~180 ~128 ~101 oak_leaves[persistent=true]
setblock ~180 ~128 ~104 jungle_leaves[persistent=true]
setblock ~180 ~128 ~105 jungle_leaves[persistent=true]
setblock ~180 ~128 ~107 oak_leaves[persistent=true]
setblock ~180 ~129 ~81 oak_leaves[persistent=true]
setblock ~180 ~129 ~82 jungle_leaves[persistent=true]
setblock ~180 ~129 ~99 oak_leaves[persistent=true]
setblock ~180 ~129 ~100 oak_leaves[persistent=true]
setblock ~180 ~129 ~101 oak_leaves[persistent=true]
setblock ~180 ~129 ~102 oak_leaves[persistent=true]
setblock ~180 ~129 ~103 jungle_leaves[persistent=true]
setblock ~180 ~129 ~104 oak_leaves[persistent=true]
setblock ~180 ~129 ~105 oak_leaves[persistent=true]
setblock ~180 ~129 ~106 jungle_leaves[persistent=true]
setblock ~180 ~129 ~107 jungle_leaves[persistent=true]
setblock ~180 ~130 ~83 oak_leaves[persistent=true]
setblock ~180 ~130 ~84 oak_leaves[persistent=true]
setblock ~180 ~130 ~85 jungle_leaves[persistent=true]
setblock ~180 ~130 ~86 oak_leaves[persistent=true]
setblock ~180 ~130 ~100 oak_leaves[persistent=true]
setblock ~180 ~130 ~101 jungle_leaves[persistent=true]
setblock ~180 ~130 ~102 oak_leaves[persistent=true]
setblock ~180 ~130 ~103 oak_leaves[persistent=true]
setblock ~180 ~130 ~104 oak_leaves[persistent=true]
setblock ~180 ~130 ~105 jungle_leaves[persistent=true]
setblock ~180 ~130 ~106 oak_leaves[persistent=true]
setblock ~180 ~130 ~107 oak_leaves[persistent=true]
setblock ~180 ~131 ~80 jungle_leaves[persistent=true]
setblock ~180 ~131 ~81 jungle_leaves[persistent=true]
setblock ~180 ~131 ~83 oak_leaves[persistent=true]
setblock ~180 ~131 ~84 oak_leaves[persistent=true]
setblock ~180 ~131 ~85 oak_leaves[persistent=true]
setblock ~180 ~131 ~86 oak_leaves[persistent=true]
setblock ~180 ~131 ~87 oak_leaves[persistent=true]
setblock ~180 ~131 ~89 oak_leaves[persistent=true]
setblock ~180 ~131 ~100 oak_leaves[persistent=true]
setblock ~180 ~131 ~101 oak_leaves[persistent=true]
setblock ~180 ~131 ~102 oak_leaves[persistent=true]
setblock ~180 ~131 ~103 oak_leaves[persistent=true]
setblock ~180 ~131 ~104 oak_leaves[persistent=true]
setblock ~180 ~131 ~105 jungle_leaves[persistent=true]
setblock ~180 ~131 ~106 oak_wood
setblock ~180 ~131 ~107 jungle_leaves[persistent=true]
setblock ~180 ~132 ~76 oak_leaves[persistent=true]
setblock ~180 ~132 ~77 oak_leaves[persistent=true]
setblock ~180 ~132 ~78 oak_leaves[persistent=true]
setblock ~180 ~132 ~79 jungle_leaves[persistent=true]
setblock ~180 ~132 ~80 oak_leaves[persistent=true]
setblock ~180 ~132 ~81 oak_leaves[persistent=true]
setblock ~180 ~132 ~82 oak_leaves[persistent=true]
setblock ~180 ~132 ~83 oak_leaves[persistent=true]
setblock ~180 ~132 ~84 oak_leaves[persistent=true]
setblock ~180 ~132 ~85 jungle_leaves[persistent=true]
setblock ~180 ~132 ~86 oak_leaves[persistent=true]
setblock ~180 ~132 ~87 oak_leaves[persistent=true]
setblock ~180 ~132 ~88 oak_leaves[persistent=true]
setblock ~180 ~132 ~89 oak_leaves[persistent=true]
setblock ~180 ~132 ~103 oak_leaves[persistent=true]
setblock ~180 ~132 ~104 oak_leaves[persistent=true]
setblock ~180 ~132 ~105 oak_leaves[persistent=true]
setblock ~180 ~132 ~106 oak_leaves[persistent=true]
setblock ~180 ~132 ~107 oak_leaves[persistent=true]
setblock ~180 ~133 ~76 oak_leaves[persistent=true]
setblock ~180 ~133 ~77 oak_leaves[persistent=true]
setblock ~180 ~133 ~78 oak_leaves[persistent=true]
setblock ~180 ~133 ~79 oak_leaves[persistent=true]
setblock ~180 ~133 ~80 oak_leaves[persistent=true]
setblock ~180 ~133 ~81 jungle_leaves[persistent=true]
setblock ~180 ~133 ~82 oak_wood
setblock ~180 ~133 ~83 oak_leaves[persistent=true]
setblock ~180 ~133 ~84 oak_leaves[persistent=true]
setblock ~180 ~133 ~85 jungle_leaves[persistent=true]
setblock ~180 ~133 ~86 jungle_leaves[persistent=true]
setblock ~180 ~133 ~87 jungle_leaves[persistent=true]
setblock ~180 ~133 ~88 jungle_leaves[persistent=true]
setblock ~180 ~133 ~89 oak_leaves[persistent=true]
setblock ~180 ~134 ~77 oak_leaves[persistent=true]
setblock ~180 ~134 ~78 oak_leaves[persistent=true]
setblock ~180 ~134 ~79 oak_leaves[persistent=true]
setblock ~180 ~134 ~80 oak_leaves[persistent=true]
setblock ~180 ~134 ~81 oak_leaves[persistent=true]
setblock ~180 ~134 ~82 oak_leaves[persistent=true]
setblock ~180 ~134 ~83 oak_leaves[persistent=true]
setblock ~180 ~134 ~84 oak_leaves[persistent=true]
setblock ~180 ~134 ~85 oak_leaves[persistent=true]
setblock ~180 ~134 ~86 jungle_leaves[persistent=true]
setblock ~180 ~134 ~87 oak_leaves[persistent=true]
setblock ~180 ~134 ~88 oak_leaves[persistent=true]
setblock ~180 ~134 ~89 oak_leaves[persistent=true]
setblock ~180 ~135 ~73 oak_leaves[persistent=true]
setblock ~180 ~135 ~74 oak_leaves[persistent=true]
setblock ~180 ~135 ~75 oak_leaves[persistent=true]
setblock ~180 ~135 ~76 jungle_leaves[persistent=true]
setblock ~180 ~135 ~77 oak_leaves[persistent=true]
setblock ~180 ~135 ~78 jungle_leaves[persistent=true]
setblock ~180 ~135 ~79 jungle_leaves[persistent=true]
setblock ~180 ~135 ~80 jungle_leaves[persistent=true]
setblock ~180 ~135 ~82 jungle_leaves[persistent=true]
setblock ~180 ~135 ~83 oak_leaves[persistent=true]
setblock ~180 ~135 ~84 oak_leaves[persistent=true]
setblock ~180 ~135 ~85 oak_leaves[persistent=true]
setblock ~180 ~135 ~86 oak_leaves[persistent=true]
setblock ~180 ~135 ~87 oak_wood
setblock ~180 ~135 ~88 oak_leaves[persistent=true]
setblock ~180 ~135 ~89 oak_leaves[persistent=true]
setblock ~180 ~135 ~98 oak_leaves[persistent=true]
setblock ~180 ~135 ~99 jungle_leaves[persistent=true]
setblock ~180 ~135 ~100 oak_leaves[persistent=true]
setblock ~180 ~136 ~73 oak_leaves[persistent=true]
setblock ~180 ~136 ~74 oak_leaves[persistent=true]
setblock ~180 ~136 ~76 oak_leaves[persistent=true]
setblock ~180 ~136 ~77 oak_leaves[persistent=true]
setblock ~180 ~136 ~78 oak_leaves[persistent=true]
setblock ~180 ~136 ~79 jungle_leaves[persistent=true]
setblock ~180 ~136 ~80 oak_leaves[persistent=true]
setblock ~180 ~136 ~81 jungle_leaves[persistent=true]
setblock ~180 ~136 ~82 oak_leaves[persistent=true]
setblock ~180 ~136 ~83 oak_leaves[persistent=true]
setblock ~180 ~136 ~84 jungle_leaves[persistent=true]
setblock ~180 ~136 ~85 oak_leaves[persistent=true]
setblock ~180 ~136 ~86 jungle_leaves[persistent=true]
setblock ~180 ~136 ~87 oak_leaves[persistent=true]
setblock ~180 ~136 ~88 oak_leaves[persistent=true]
setblock ~180 ~136 ~89 oak_leaves[persistent=true]
setblock ~180 ~136 ~98 oak_leaves[persistent=true]
setblock ~180 ~136 ~99 oak_leaves[persistent=true]
setblock ~180 ~137 ~74 oak_leaves[persistent=true]
setblock ~180 ~137 ~75 oak_leaves[persistent=true]
setblock ~180 ~137 ~76 oak_leaves[persistent=true]
setblock ~180 ~137 ~77 oak_leaves[persistent=true]
setblock ~180 ~137 ~78 oak_leaves[persistent=true]
setblock ~180 ~137 ~79 oak_leaves[persistent=true]
setblock ~180 ~137 ~80 oak_leaves[persistent=true]
setblock ~180 ~137 ~81 jungle_leaves[persistent=true]
setblock ~180 ~137 ~82 oak_leaves[persistent=true]
setblock ~180 ~137 ~83 oak_leaves[persistent=true]
setblock ~180 ~137 ~84 oak_wood
setblock ~180 ~137 ~85 oak_leaves[persistent=true]
setblock ~180 ~137 ~86 oak_leaves[persistent=true]
setblock ~180 ~137 ~99 jungle_leaves[persistent=true]
setblock ~180 ~138 ~73 jungle_leaves[persistent=true]
setblock ~180 ~138 ~74 oak_leaves[persistent=true]
setblock ~180 ~138 ~75 oak_leaves[persistent=true]
setblock ~180 ~138 ~76 oak_wood
setblock ~180 ~138 ~77 oak_leaves[persistent=true]
setblock ~180 ~138 ~78 oak_leaves[persistent=true]
setblock ~180 ~138 ~79 oak_leaves[persistent=true]
setblock ~180 ~138 ~81 oak_leaves[persistent=true]
setblock ~180 ~138 ~82 jungle_leaves[persistent=true]
setblock ~180 ~138 ~83 jungle_leaves[persistent=true]
setblock ~180 ~138 ~84 oak_leaves[persistent=true]
setblock ~180 ~138 ~85 oak_leaves[persistent=true]
setblock ~180 ~139 ~74 oak_leaves[persistent=true]
setblock ~180 ~139 ~75 oak_leaves[persistent=true]
setblock ~180 ~139 ~76 oak_leaves[persistent=true]
setblock ~180 ~139 ~77 oak_leaves[persistent=true]
setblock ~180 ~140 ~74 oak_leaves[persistent=true]
setblock ~180 ~140 ~75 oak_leaves[persistent=true]
setblock ~180 ~140 ~76 oak_leaves[persistent=true]
setblock ~181 ~127 ~81 oak_leaves[persistent=true]
setblock ~181 ~127 ~82 oak_leaves[persistent=true]
setblock ~181 ~128 ~81 oak_leaves[persistent=true]
setblock ~181 ~128 ~82 oak_leaves[persistent=true]
setblock ~181 ~128 ~83 oak_leaves[persistent=true]
setblock ~181 ~128 ~104 oak_leaves[persistent=true]
setblock ~181 ~128 ~105 oak_leaves[persistent=true]
setblock ~181 ~128 ~106 oak_leaves[persistent=true]
setblock ~181 ~128 ~107 jungle_leaves[persistent=true]
setblock ~181 ~129 ~81 oak_leaves[persistent=true]
setblock ~181 ~129 ~82 oak_leaves[persistent=true]
setblock ~181 ~129 ~83 oak_leaves[persistent=true]
setblock ~181 ~129 ~100 oak_leaves[persistent=true]
setblock ~181 ~129 ~101 oak_leaves[persistent=true]
setblock ~181 ~129 ~102 oak_leaves[persistent=true]
setblock ~181 ~129 ~104 oak_leaves[persistent=true]
setblock ~181 ~129 ~105 oak_leaves[persistent=true]
setblock ~181 ~129 ~106 oak_leaves[persistent=true]
setblock ~181 ~129 ~107 jungle_leaves[persistent=true]
setblock ~181 ~130 ~100 jungle_leaves[persistent=true]
setblock ~181 ~130 ~101 oak_leaves[persistent=true]
setblock ~181 ~130 ~102 oak_leaves[persistent=true]
setblock ~181 ~130 ~104 jungle_leaves[persistent=true]
setblock ~181 ~130 ~105 oak_leaves[persistent=true]
setblock ~181 ~130 ~106 oak_leaves[persistent=true]
setblock ~181 ~130 ~107 oak_leaves[persistent=true]
setblock ~181 ~131 ~100 jungle_leaves[persistent=true]
setblock ~181 ~131 ~101 oak_leaves[persistent=true]
setblock ~181 ~131 ~102 oak_leaves[persistent=true]
setblock ~181 ~131 ~106 oak_leaves[persistent=true]
setblock ~181 ~131 ~107 jungle_leaves[persistent=true]
setblock ~181 ~132 ~78 oak_leaves[persistent=true]
setblock ~181 ~132 ~80 oak_leaves[persistent=true]
setblock ~181 ~132 ~81 oak_leaves[persistent=true]
setblock ~181 ~132 ~82 oak_leaves[persistent=true]
setblock ~181 ~132 ~83 oak_leaves[persistent=true]
setblock ~181 ~132 ~84 oak_leaves[persistent=true]
setblock ~181 ~132 ~85 oak_leaves[persistent=true]
setblock ~181 ~132 ~86 jungle_leaves[persistent=true]
setblock ~181 ~132 ~87 oak_leaves[persistent=true]
setblock ~181 ~132 ~105 oak_leaves[persistent=true]
setblock ~181 ~132 ~106 oak_leaves[persistent=true]
setblock ~181 ~132 ~107 oak_leaves[persistent=true]
setblock ~181 ~133 ~77 oak_leaves[persistent=true]
setblock ~181 ~133 ~78 oak_leaves[persistent=true]
setblock ~181 ~133 ~79 oak_leaves[persistent=true]
setblock ~181 ~133 ~80 oak_leaves[persistent=true]
setblock ~181 ~133 ~81 oak_leaves[persistent=true]
setblock ~181 ~133 ~82 oak_leaves[persistent=true]
setblock ~181 ~133 ~83 jungle_leaves[persistent=true]
setblock ~181 ~133 ~84 oak_leaves[persistent=true]
setblock ~181 ~133 ~85 oak_leaves[persistent=true]
setblock ~181 ~133 ~86 jungle_leaves[persistent=true]
setblock ~181 ~133 ~87 oak_leaves[persistent=true]
setblock ~181 ~133 ~88 jungle_leaves[persistent=true]
setblock ~181 ~134 ~76 jungle_leaves[persistent=true]
setblock ~181 ~134 ~77 oak_leaves[persistent=true]
setblock ~181 ~134 ~78 oak_leaves[persistent=true]
setblock ~181 ~134 ~79 oak_leaves[persistent=true]
setblock ~181 ~134 ~80 oak_leaves[persistent=true]
setblock ~181 ~134 ~81 jungle_leaves[persistent=true]
setblock ~181 ~134 ~82 oak_leaves[persistent=true]
setblock ~181 ~134 ~83 oak_leaves[persistent=true]
setblock ~181 ~134 ~84 oak_leaves[persistent=true]
setblock ~181 ~134 ~85 oak_leaves[persistent=true]
setblock ~181 ~134 ~86 oak_leaves[persistent=true]
setblock ~181 ~134 ~88 oak_leaves[persistent=true]
setblock ~181 ~134 ~89 oak_leaves[persistent=true]
setblock ~181 ~135 ~76 jungle_leaves[persistent=true]
setblock ~181 ~135 ~77 oak_leaves[persistent=true]
setblock ~181 ~135 ~78 oak_leaves[persistent=true]
setblock ~181 ~135 ~79 oak_leaves[persistent=true]
setblock ~181 ~135 ~80 oak_leaves[persistent=true]
setblock ~181 ~135 ~81 jungle_leaves[persistent=true]
setblock ~181 ~135 ~82 oak_leaves[persistent=true]
setblock ~181 ~135 ~83 jungle_leaves[persistent=true]
setblock ~181 ~135 ~84 oak_leaves[persistent=true]
setblock ~181 ~135 ~86 oak_leaves[persistent=true]
setblock ~181 ~135 ~87 oak_leaves[persistent=true]
setblock ~181 ~135 ~88 oak_leaves[persistent=true]
setblock ~181 ~135 ~89 oak_leaves[persistent=true]
setblock ~181 ~136 ~77 jungle_leaves[persistent=true]
setblock ~181 ~136 ~78 oak_leaves[persistent=true]
setblock ~181 ~136 ~79 jungle_leaves[persistent=true]
setblock ~181 ~136 ~81 oak_leaves[persistent=true]
setblock ~181 ~136 ~82 oak_leaves[persistent=true]
setblock ~181 ~136 ~83 oak_leaves[persistent=true]
setblock ~181 ~136 ~85 jungle_leaves[persistent=true]
setblock ~181 ~136 ~86 oak_leaves[persistent=true]
setblock ~181 ~136 ~87 oak_leaves[persistent=true]
setblock ~181 ~136 ~89 oak_leaves[persistent=true]
setblock ~181 ~137 ~74 oak_leaves[persistent=true]
setblock ~181 ~137 ~75 jungle_leaves[persistent=true]
setblock ~181 ~137 ~76 oak_leaves[persistent=true]
setblock ~181 ~137 ~77 oak_leaves[persistent=true]
setblock ~181 ~137 ~79 oak_leaves[persistent=true]
setblock ~181 ~137 ~81 oak_leaves[persistent=true]
setblock ~181 ~137 ~82 oak_leaves[persistent=true]
setblock ~181 ~137 ~83 oak_leaves[persistent=true]
setblock ~181 ~137 ~84 oak_wood
setblock ~181 ~137 ~85 oak_leaves[persistent=true]
setblock ~181 ~138 ~74 oak_leaves[persistent=true]
setblock ~181 ~138 ~75 oak_leaves[persistent=true]
setblock ~181 ~138 ~76 oak_leaves[persistent=true]
setblock ~181 ~138 ~77 oak_leaves[persistent=true]
setblock ~181 ~138 ~78 oak_leaves[persistent=true]
setblock ~181 ~138 ~79 jungle_leaves[persistent=true]
setblock ~181 ~138 ~82 oak_leaves[persistent=true]
setblock ~181 ~138 ~83 oak_leaves[persistent=true]
setblock ~181 ~138 ~84 oak_leaves[persistent=true]
setblock ~181 ~138 ~85 jungle_leaves[persistent=true]
setblock ~181 ~139 ~74 oak_leaves[persistent=true]
setblock ~181 ~139 ~75 oak_leaves[persistent=true]
setblock ~181 ~139 ~76 oak_leaves[persistent=true]
setblock ~181 ~139 ~77 oak_leaves[persistent=true]
setblock ~182 ~132 ~80 oak_leaves[persistent=true]
setblock ~182 ~132 ~81 oak_leaves[persistent=true]
setblock ~182 ~132 ~83 oak_leaves[persistent=true]
setblock ~182 ~133 ~80 oak_leaves[persistent=true]
setblock ~182 ~133 ~81 oak_leaves[persistent=true]
setblock ~182 ~133 ~82 jungle_leaves[persistent=true]
setblock ~182 ~133 ~83 oak_leaves[persistent=true]
setblock ~182 ~134 ~80 oak_leaves[persistent=true]
setblock ~182 ~134 ~81 oak_leaves[persistent=true]
setblock ~182 ~134 ~82 oak_leaves[persistent=true]
setblock ~182 ~134 ~83 oak_leaves[persistent=true]
setblock ~182 ~135 ~80 oak_leaves[persistent=true]
setblock ~182 ~135 ~81 oak_leaves[persistent=true]
setblock ~182 ~135 ~82 oak_leaves[persistent=true]
setblock ~182 ~135 ~83 oak_leaves[persistent=true]
setblock ~182 ~135 ~84 oak_leaves[persistent=true]
setblock ~182 ~136 ~81 oak_leaves[persistent=true]
setblock ~182 ~136 ~82 oak_leaves[persistent=true]
setblock ~182 ~136 ~83 oak_leaves[persistent=true]
setblock ~182 ~136 ~84 jungle_leaves[persistent=true]
setblock ~182 ~136 ~85 oak_leaves[persistent=true]
setblock ~182 ~137 ~74 oak_leaves[persistent=true]
setblock ~182 ~137 ~75 oak_leaves[persistent=true]
setblock ~182 ~137 ~76 oak_leaves[persistent=true]
setblock ~182 ~137 ~81 oak_leaves[persistent=true]
setblock ~182 ~137 ~82 jungle_leaves[persistent=true]
setblock ~182 ~137 ~83 oak_leaves[persistent=true]
setblock ~182 ~137 ~84 oak_leaves[persistent=true]
setblock ~182 ~137 ~85 oak_leaves[persistent=true]
setblock ~182 ~138 ~75 oak_leaves[persistent=true]
setblock ~182 ~138 ~76 oak_leaves[persistent=true]
setblock ~182 ~138 ~81 oak_leaves[persistent=true]
setblock ~182 ~138 ~82 oak_leaves[persistent=true]
setblock ~182 ~138 ~83 oak_leaves[persistent=true]
setblock ~182 ~138 ~85 oak_leaves[persistent=true]
setblock ~182 ~139 ~74 oak_leaves[persistent=true]
setblock ~182 ~139 ~75 jungle_leaves[persistent=true]
setblock ~182 ~139 ~76 oak_leaves[persistent=true]
setblock ~183 ~135 ~81 oak_leaves[persistent=true]
setblock ~183 ~135 ~82 oak_leaves[persistent=true]
setblock ~183 ~135 ~83 oak_leaves[persistent=true]
setblock ~183 ~135 ~84 oak_leaves[persistent=true]
setblock ~183 ~136 ~82 jungle_leaves[persistent=true]
setblock ~183 ~136 ~83 jungle_leaves[persistent=true]
setblock ~183 ~136 ~84 oak_leaves[persistent=true]
setblock ~183 ~137 ~81 oak_leaves[persistent=true]
setblock ~183 ~137 ~82 oak_leaves[persistent=true]
setblock ~183 ~137 ~83 oak_leaves[persistent=true]
setblock ~183 ~137 ~84 jungle_leaves[persistent=true]
setblock ~183 ~138 ~81 oak_leaves[persistent=true]
setblock ~183 ~138 ~82 oak_leaves[persistent=true]
setblock ~183 ~138 ~83 oak_leaves[persistent=true]
setblock ~183 ~138 ~84 oak_leaves[persistent=true]
setblock ~199 ~200 ~199 gold_block
