setblock ~34 ~120 ~121 dirt
setblock ~34 ~120 ~122 dirt
setblock ~34 ~120 ~123 dirt
setblock ~34 ~120 ~124 dirt
setblock ~34 ~120 ~125 dirt
setblock ~34 ~120 ~126 dirt
setblock ~34 ~120 ~127 dirt
setblock ~34 ~121 ~74 dirt
setblock ~34 ~121 ~75 dirt
setblock ~34 ~121 ~76 dirt
setblock ~34 ~121 ~77 dirt
setblock ~34 ~121 ~78 dirt
setblock ~34 ~121 ~79 dirt
setblock ~34 ~121 ~80 dirt
setblock ~34 ~121 ~81 dirt
setblock ~34 ~121 ~82 dirt
setblock ~34 ~121 ~83 dirt
setblock ~34 ~121 ~84 dirt
setblock ~34 ~121 ~85 dirt
setblock ~34 ~121 ~86 dirt
setblock ~34 ~121 ~87 dirt
setblock ~34 ~121 ~88 dirt
setblock ~34 ~121 ~89 dirt
setblock ~34 ~121 ~90 dirt
setblock ~34 ~121 ~91 dirt
setblock ~34 ~121 ~92 dirt
setblock ~34 ~121 ~93 dirt
setblock ~34 ~121 ~94 dirt
setblock ~34 ~121 ~95 dirt
setblock ~34 ~121 ~96 dirt
setblock ~34 ~121 ~97 dirt
setblock ~34 ~121 ~98 dirt
setblock ~34 ~121 ~99 dirt
setblock ~34 ~121 ~100 dirt
setblock ~34 ~121 ~101 dirt
setblock ~34 ~121 ~102 dirt
setblock ~34 ~121 ~103 dirt
setblock ~34 ~121 ~104 dirt
setblock ~34 ~121 ~105 dirt
setblock ~34 ~121 ~106 dirt
setblock ~34 ~121 ~107 dirt
setblock ~34 ~121 ~108 dirt
setblock ~34 ~121 ~109 dirt
setblock ~34 ~121 ~110 dirt
setblock ~34 ~121 ~111 dirt
setblock ~34 ~121 ~112 dirt
setblock ~34 ~121 ~113 dirt
setblock ~34 ~121 ~114 dirt
setblock ~34 ~121 ~115 dirt
setblock ~34 ~121 ~116 dirt
setblock ~34 ~121 ~117 dirt
setblock ~34 ~121 ~118 dirt
setblock ~34 ~121 ~119 dirt
setblock ~34 ~121 ~120 dirt
setblock ~34 ~121 ~121 dirt
setblock ~34 ~121 ~122 dirt
setblock ~34 ~121 ~123 dirt
setblock ~34 ~121 ~124 dirt
setblock ~34 ~121 ~125 dirt
setblock ~34 ~121 ~126 dirt
setblock ~34 ~121 ~127 dirt
setblock ~34 ~121 ~128 dirt
setblock ~34 ~122 ~74 dirt
setblock ~34 ~122 ~75 dirt
setblock ~34 ~122 ~76 dirt
setblock ~34 ~122 ~77 dirt
setblock ~34 ~122 ~78 dirt
setblock ~34 ~122 ~79 dirt
setblock ~34 ~122 ~80 dirt
setblock ~34 ~122 ~81 dirt
setblock ~34 ~122 ~82 dirt
setblock ~34 ~122 ~83 dirt
setblock ~34 ~122 ~84 dirt
setblock ~34 ~122 ~85 dirt
setblock ~34 ~122 ~86 dirt
setblock ~34 ~122 ~87 dirt
setblock ~34 ~122 ~88 dirt
setblock ~34 ~122 ~89 dirt
setblock ~34 ~122 ~90 dirt
setblock ~34 ~122 ~91 dirt
setblock ~34 ~122 ~92 dirt
setblock ~34 ~122 ~93 dirt
setblock ~34 ~122 ~94 dirt
setblock ~34 ~122 ~95 dirt
setblock ~34 ~122 ~96 dirt
setblock ~34 ~122 ~97 dirt
setblock ~34 ~122 ~98 dirt
setblock ~34 ~122 ~99 dirt
setblock ~34 ~122 ~100 dirt
setblock ~34 ~122 ~101 dirt
setblock ~34 ~122 ~102 dirt
setblock ~34 ~122 ~103 dirt
setblock ~34 ~122 ~104 dirt
setblock ~34 ~122 ~105 dirt
setblock ~34 ~122 ~106 dirt
setblock ~34 ~122 ~107 dirt
setblock ~34 ~122 ~108 dirt
setblock ~34 ~122 ~109 dirt
setblock ~34 ~122 ~110 dirt
setblock ~34 ~122 ~111 dirt
setblock ~34 ~122 ~112 dirt
setblock ~34 ~122 ~113 dirt
setblock ~34 ~122 ~114 dirt
setblock ~34 ~122 ~115 dirt
setblock ~34 ~122 ~116 dirt
setblock ~34 ~122 ~117 dirt
setblock ~34 ~122 ~118 dirt
setblock ~34 ~122 ~119 dirt
setblock ~34 ~122 ~120 dirt
setblock ~34 ~122 ~121 dirt
setblock ~34 ~122 ~122 dirt
setblock ~34 ~122 ~123 dirt
setblock ~34 ~122 ~124 dirt
setblock ~34 ~122 ~125 dirt
setblock ~34 ~122 ~126 dirt
setblock ~34 ~122 ~127 dirt
setblock ~34 ~122 ~128 dirt
setblock ~34 ~123 ~74 dirt
setblock ~34 ~123 ~75 dirt
setblock ~34 ~123 ~76 dirt
setblock ~34 ~123 ~77 dirt
setblock ~34 ~123 ~78 dirt
setblock ~34 ~123 ~79 dirt
setblock ~34 ~123 ~80 dirt
setblock ~34 ~123 ~81 dirt
setblock ~34 ~123 ~82 dirt
setblock ~34 ~123 ~83 dirt
setblock ~34 ~123 ~84 dirt
setblock ~34 ~123 ~85 dirt
setblock ~34 ~123 ~86 dirt
setblock ~34 ~123 ~87 dirt
setblock ~34 ~123 ~88 dirt
setblock ~34 ~123 ~89 dirt
setblock ~34 ~123 ~90 dirt
setblock ~34 ~123 ~91 dirt
setblock ~34 ~123 ~92 dirt
setblock ~34 ~123 ~93 grass_block
setblock ~34 ~123 ~94 grass_block
setblock ~34 ~123 ~95 grass_block
setblock ~34 ~123 ~96 grass_block
setblock ~34 ~123 ~97 grass_block
setblock ~34 ~123 ~98 grass_block
setblock ~34 ~123 ~99 grass_block
setblock ~34 ~123 ~100 grass_block
setblock ~34 ~123 ~101 grass_block
setblock ~34 ~123 ~102 dirt
setblock ~34 ~123 ~103 dirt
setblock ~34 ~123 ~104 dirt
setblock ~34 ~123 ~105 dirt
setblock ~34 ~123 ~106 dirt
setblock ~34 ~123 ~107 dirt
setblock ~34 ~123 ~108 dirt
setblock ~34 ~123 ~109 dirt
setblock ~34 ~123 ~110 dirt
setblock ~34 ~123 ~111 dirt
setblock ~34 ~123 ~112 dirt
setblock ~34 ~123 ~113 dirt
setblock ~34 ~123 ~114 dirt
setblock ~34 ~123 ~115 dirt
setblock ~34 ~123 ~116 dirt
setblock ~34 ~123 ~117 dirt
setblock ~34 ~123 ~118 dirt
setblock ~34 ~123 ~119 dirt
setblock ~34 ~123 ~120 dirt
setblock ~34 ~123 ~121 dirt
setblock ~34 ~123 ~122 dirt
setblock ~34 ~123 ~123 dirt
setblock ~34 ~123 ~124 dirt
setblock ~34 ~123 ~125 dirt
setblock ~34 ~123 ~126 dirt
setblock ~34 ~123 ~127 dirt
setblock ~34 ~123 ~128 dirt
setblock ~34 ~124 ~74 dirt
setblock ~34 ~124 ~75 dirt
setblock ~34 ~124 ~76 dirt
setblock ~34 ~124 ~77 dirt
setblock ~34 ~124 ~78 dirt
setblock ~34 ~124 ~79 dirt
setblock ~34 ~124 ~80 dirt
setblock ~34 ~124 ~81 dirt
setblock ~34 ~124 ~82 dirt
setblock ~34 ~124 ~83 dirt
setblock ~34 ~124 ~84 dirt
setblock ~34 ~124 ~85 dirt
setblock ~34 ~124 ~86 grass_block
setblock ~34 ~124 ~87 grass_block
setblock ~34 ~124 ~88 grass_block
setblock ~34 ~124 ~89 grass_block
setblock ~34 ~124 ~90 grass_block
setblock ~34 ~124 ~91 grass_block
setblock ~34 ~124 ~92 grass_block
setblock ~34 ~124 ~94 short_grass
setblock ~34 ~124 ~95 short_grass
setblock ~34 ~124 ~96 short_grass
setblock ~34 ~124 ~99 short_grass
setblock ~34 ~124 ~102 grass_block
setblock ~34 ~124 ~103 grass_block
setblock ~34 ~124 ~104 grass_block
setblock ~34 ~124 ~105 grass_block
setblock ~34 ~124 ~106 dirt
setblock ~34 ~124 ~107 dirt
setblock ~34 ~124 ~108 dirt
setblock ~34 ~124 ~109 dirt
setblock ~34 ~124 ~110 dirt
setblock ~34 ~124 ~111 dirt
setblock ~34 ~124 ~112 dirt
setblock ~34 ~124 ~113 dirt
setblock ~34 ~124 ~114 dirt
setblock ~34 ~124 ~115 dirt
setblock ~34 ~124 ~116 dirt
setblock ~34 ~124 ~117 dirt
setblock ~34 ~124 ~118 dirt
setblock ~34 ~124 ~119 dirt
setblock ~34 ~124 ~120 dirt
setblock ~34 ~124 ~121 dirt
setblock ~34 ~124 ~122 dirt
setblock ~34 ~124 ~123 dirt
setblock ~34 ~124 ~124 dirt
setblock ~34 ~124 ~125 dirt
setblock ~34 ~124 ~126 dirt
setblock ~34 ~124 ~127 dirt
setblock ~34 ~124 ~128 dirt
setblock ~34 ~125 ~74 grass_block
setblock ~34 ~125 ~75 grass_block
setblock ~34 ~125 ~76 grass_block
setblock ~34 ~125 ~77 dirt
setblock ~34 ~125 ~78 dirt
setblock ~34 ~125 ~79 dirt
setblock ~34 ~125 ~80 dirt
setblock ~34 ~125 ~81 dirt
setblock ~34 ~125 ~82 dirt
setblock ~34 ~125 ~83 grass_block
setblock ~34 ~125 ~84 grass_block
setblock ~34 ~125 ~85 grass_block
setblock ~34 ~125 ~89 short_grass
setblock ~34 ~125 ~90 short_grass
setblock ~34 ~125 ~103 short_grass
setblock ~34 ~125 ~106 grass_block
setblock ~34 ~125 ~107 grass_block
setblock ~34 ~125 ~108 grass_block
setblock ~34 ~125 ~109 dirt
setblock ~34 ~125 ~110 dirt
setblock ~34 ~125 ~111 dirt
setblock ~34 ~125 ~112 dirt
setblock ~34 ~125 ~113 dirt
setblock ~34 ~125 ~114 grass_block
setblock ~34 ~125 ~115 grass_block
setblock ~34 ~125 ~116 grass_block
setblock ~34 ~125 ~117 grass_block
setblock ~34 ~125 ~118 grass_block
setblock ~34 ~125 ~119 grass_block
setblock ~34 ~125 ~120 grass_block
setblock ~34 ~125 ~121 grass_block
setblock ~34 ~125 ~122 grass_block
setblock ~34 ~125 ~123 grass_block
setblock ~34 ~125 ~124 grass_block
setblock ~34 ~125 ~125 grass_block
setblock ~34 ~125 ~126 grass_block
setblock ~34 ~125 ~127 grass_block
setblock ~34 ~125 ~128 grass_block
setblock ~34 ~126 ~75 short_grass
setblock ~34 ~126 ~76 fern
setblock ~34 ~126 ~77 grass_block
setblock ~34 ~126 ~78 grass_block
setblock ~34 ~126 ~79 grass_block
setblock ~34 ~126 ~80 grass_block
setblock ~34 ~126 ~81 grass_block
setblock ~34 ~126 ~82 grass_block
setblock ~34 ~126 ~83 short_grass
setblock ~34 ~126 ~84 short_grass
setblock ~34 ~126 ~85 short_grass
setblock ~34 ~126 ~109 grass_block
setblock ~34 ~126 ~110 grass_block
setblock ~34 ~126 ~111 grass_block
setblock ~34 ~126 ~112 grass_block
setblock ~34 ~126 ~113 grass_block
setblock ~34 ~126 ~115 short_grass
setblock ~34 ~126 ~119 poppy
setblock ~34 ~126 ~121 short_grass
setblock ~34 ~126 ~124 short_grass
setblock ~34 ~126 ~126 short_grass
setblock ~34 ~126 ~127 short_grass
setblock ~34 ~126 ~128 short_grass
setblock ~34 ~127 ~80 short_grass
setblock ~34 ~127 ~81 fern
setblock ~34 ~127 ~110 short_grass
setblock ~34 ~127 ~111 short_grass
setblock ~35 ~101 ~100 dirt
setblock ~35 ~102 ~100 dirt
setblock ~35 ~103 ~100 dirt
setblock ~35 ~103 ~101 dirt
setblock ~35 ~104 ~99 dirt
setblock ~35 ~104 ~100 dirt
setblock ~35 ~104 ~101 dirt
setblock ~35 ~104 ~102 dirt
setblock ~35 ~105 ~98 dirt
setblock ~35 ~105 ~99 dirt
setblock ~35 ~105 ~100 dirt
setblock ~35 ~105 ~101 dirt
setblock ~35 ~105 ~102 dirt
setblock ~35 ~106 ~97 dirt
setblock ~35 ~106 ~98 dirt
setblock ~35 ~106 ~99 dirt
setblock ~35 ~106 ~100 dirt
setblock ~35 ~106 ~101 dirt
setblock ~35 ~106 ~102 dirt
setblock ~35 ~106 ~103 dirt
setblock ~35 ~107 ~96 dirt
setblock ~35 ~107 ~97 dirt
setblock ~35 ~107 ~98 dirt
setblock ~35 ~107 ~99 dirt
setblock ~35 ~107 ~100 dirt
setblock ~35 ~107 ~101 dirt
setblock ~35 ~107 ~102 dirt
setblock ~35 ~107 ~103 dirt
setblock ~35 ~108 ~96 dirt
setblock ~35 ~108 ~97 dirt
setblock ~35 ~108 ~98 dirt
setblock ~35 ~108 ~99 dirt
setblock ~35 ~108 ~100 dirt
setblock ~35 ~108 ~101 dirt
setblock ~35 ~108 ~102 dirt
setblock ~35 ~108 ~103 dirt
setblock ~35 ~108 ~104 dirt
setblock ~35 ~108 ~105 dirt
setblock ~35 ~108 ~106 dirt
setblock ~35 ~109 ~94 dirt
setblock ~35 ~109 ~95 dirt
setblock ~35 ~109 ~96 dirt
setblock ~35 ~109 ~97 dirt
setblock ~35 ~109 ~98 dirt
setblock ~35 ~109 ~99 dirt
setblock ~35 ~109 ~100 dirt
setblock ~35 ~109 ~101 dirt
setblock ~35 ~109 ~102 dirt
setblock ~35 ~109 ~103 dirt
setblock ~35 ~109 ~104 dirt
setblock ~35 ~109 ~105 dirt
setblock ~35 ~109 ~106 dirt
setblock ~35 ~109 ~107 dirt
setblock ~35 ~110 ~89 dirt
setblock ~35 ~110 ~94 dirt
setblock ~35 ~110 ~95 dirt
setblock ~35 ~110 ~96 dirt
setblock ~35 ~110 ~97 dirt
setblock ~35 ~110 ~98 dirt
setblock ~35 ~110 ~99 dirt
setblock ~35 ~110 ~100 dirt
setblock ~35 ~110 ~101 dirt
setblock ~35 ~110 ~102 dirt
setblock ~35 ~110 ~103 dirt
setblock ~35 ~110 ~104 dirt
setblock ~35 ~110 ~105 dirt
setblock ~35 ~110 ~106 dirt
setblock ~35 ~110 ~107 dirt
setblock ~35 ~110 ~108 dirt
setblock ~35 ~111 ~87 dirt
setblock ~35 ~111 ~88 dirt
setblock ~35 ~111 ~89 dirt
setblock ~35 ~111 ~93 dirt
setblock ~35 ~111 ~94 dirt
setblock ~35 ~111 ~95 dirt
setblock ~35 ~111 ~96 dirt
setblock ~35 ~111 ~97 dirt
setblock ~35 ~111 ~98 dirt
setblock ~35 ~111 ~99 dirt
setblock ~35 ~111 ~100 dirt
setblock ~35 ~111 ~101 dirt
setblock ~35 ~111 ~102 dirt
setblock ~35 ~111 ~103 dirt
setblock ~35 ~111 ~104 dirt
setblock ~35 ~111 ~105 dirt
setblock ~35 ~111 ~106 dirt
setblock ~35 ~111 ~107 dirt
setblock ~35 ~111 ~108 dirt
setblock ~35 ~111 ~117 dirt
setblock ~35 ~112 ~86 dirt
setblock ~35 ~112 ~87 dirt
setblock ~35 ~112 ~88 dirt
setblock ~35 ~112 ~89 dirt
setblock ~35 ~112 ~90 dirt
setblock ~35 ~112 ~93 dirt
setblock ~35 ~112 ~94 dirt
setblock ~35 ~112 ~95 dirt
setblock ~35 ~112 ~96 dirt
setblock ~35 ~112 ~97 dirt
setblock ~35 ~112 ~98 dirt
setblock ~35 ~112 ~99 dirt
setblock ~35 ~112 ~100 dirt
setblock ~35 ~112 ~101 dirt
setblock ~35 ~112 ~102 dirt
setblock ~35 ~112 ~103 dirt
setblock ~35 ~112 ~104 dirt
setblock ~35 ~112 ~105 dirt
setblock ~35 ~112 ~106 dirt
setblock ~35 ~112 ~107 dirt
setblock ~35 ~112 ~108 dirt
setblock ~35 ~112 ~115 dirt
setblock ~35 ~112 ~116 dirt
setblock ~35 ~112 ~117 dirt
setblock ~35 ~112 ~118 dirt
setblock ~35 ~113 ~84 dirt
setblock ~35 ~113 ~86 dirt
setblock ~35 ~113 ~87 dirt
setblock ~35 ~113 ~88 dirt
setblock ~35 ~113 ~89 dirt
setblock ~35 ~113 ~90 dirt
setblock ~35 ~113 ~91 dirt
setblock ~35 ~113 ~92 dirt
setblock ~35 ~113 ~93 dirt
setblock ~35 ~113 ~94 dirt
setblock ~35 ~113 ~95 dirt
setblock ~35 ~113 ~96 dirt
setblock ~35 ~113 ~97 dirt
setblock ~35 ~113 ~98 dirt
setblock ~35 ~113 ~99 dirt
setblock ~35 ~113 ~100 dirt
setblock ~35 ~113 ~101 dirt
setblock ~35 ~113 ~102 dirt
setblock ~35 ~113 ~103 dirt
setblock ~35 ~113 ~104 dirt
setblock ~35 ~113 ~105 dirt
setblock ~35 ~113 ~106 dirt
setblock ~35 ~113 ~107 dirt
setblock ~35 ~113 ~108 dirt
setblock ~35 ~113 ~109 dirt
setblock ~35 ~113 ~110 dirt
setblock ~35 ~113 ~115 dirt
setblock ~35 ~113 ~116 dirt
setblock ~35 ~113 ~117 dirt
setblock ~35 ~113 ~118 dirt
setblock ~35 ~113 ~119 dirt
setblock ~35 ~114 ~83 dirt
setblock ~35 ~114 ~84 dirt
setblock ~35 ~114 ~86 dirt
setblock ~35 ~114 ~87 dirt
setblock ~35 ~114 ~88 dirt
setblock ~35 ~114 ~89 dirt
setblock ~35 ~114 ~90 dirt
setblock ~35 ~114 ~91 dirt
setblock ~35 ~114 ~92 dirt
setblock ~35 ~114 ~93 dirt
setblock ~35 ~114 ~94 dirt
setblock ~35 ~114 ~95 dirt
setblock ~35 ~114 ~96 dirt
setblock ~35 ~114 ~97 dirt
setblock ~35 ~114 ~98 dirt
setblock ~35 ~114 ~99 dirt
setblock ~35 ~114 ~100 dirt
setblock ~35 ~114 ~101 dirt
setblock ~35 ~114 ~102 dirt
setblock ~35 ~114 ~103 dirt
setblock ~35 ~114 ~104 dirt
setblock ~35 ~114 ~105 dirt
setblock ~35 ~114 ~106 dirt
setblock ~35 ~114 ~107 dirt
setblock ~35 ~114 ~108 dirt
setblock ~35 ~114 ~109 dirt
setblock ~35 ~114 ~110 dirt
setblock ~35 ~114 ~111 dirt
setblock ~35 ~114 ~114 dirt
setblock ~35 ~114 ~115 dirt
setblock ~35 ~114 ~116 dirt
setblock ~35 ~114 ~117 dirt
setblock ~35 ~114 ~118 dirt
setblock ~35 ~114 ~119 dirt
setblock ~35 ~114 ~122 dirt
setblock ~35 ~115 ~78 dirt
setblock ~35 ~115 ~79 dirt
setblock ~35 ~115 ~83 dirt
setblock ~35 ~115 ~84 dirt
setblock ~35 ~115 ~85 dirt
setblock ~35 ~115 ~86 dirt
setblock ~35 ~115 ~87 dirt
setblock ~35 ~115 ~88 dirt
setblock ~35 ~115 ~89 dirt
setblock ~35 ~115 ~90 dirt
setblock ~35 ~115 ~91 dirt
setblock ~35 ~115 ~92 dirt
setblock ~35 ~115 ~93 dirt
setblock ~35 ~115 ~94 dirt
setblock ~35 ~115 ~95 dirt
setblock ~35 ~115 ~96 dirt
setblock ~35 ~115 ~97 dirt
setblock ~35 ~115 ~98 dirt
setblock ~35 ~115 ~99 dirt
setblock ~35 ~115 ~100 dirt
setblock ~35 ~115 ~101 dirt
setblock ~35 ~115 ~102 dirt
setblock ~35 ~115 ~103 dirt
setblock ~35 ~115 ~104 dirt
setblock ~35 ~115 ~105 dirt
setblock ~35 ~115 ~106 dirt
setblock ~35 ~115 ~107 dirt
setblock ~35 ~115 ~108 dirt
setblock ~35 ~115 ~109 dirt
setblock ~35 ~115 ~110 dirt
setblock ~35 ~115 ~111 dirt
setblock ~35 ~115 ~112 dirt
setblock ~35 ~115 ~113 dirt
setblock ~35 ~115 ~114 dirt
setblock ~35 ~115 ~115 dirt
setblock ~35 ~115 ~116 dirt
setblock ~35 ~115 ~117 dirt
setblock ~35 ~115 ~118 dirt
setblock ~35 ~115 ~119 dirt
setblock ~35 ~115 ~120 dirt
setblock ~35 ~115 ~122 dirt
setblock ~35 ~116 ~77 dirt
setblock ~35 ~116 ~78 dirt
setblock ~35 ~116 ~79 dirt
setblock ~35 ~116 ~80 dirt
setblock ~35 ~116 ~81 dirt
setblock ~35 ~116 ~82 dirt
setblock ~35 ~116 ~83 dirt
setblock ~35 ~116 ~84 dirt
setblock ~35 ~116 ~85 dirt
setblock ~35 ~116 ~86 dirt
setblock ~35 ~116 ~87 dirt
setblock ~35 ~116 ~88 dirt
setblock ~35 ~116 ~89 dirt
setblock ~35 ~116 ~90 dirt
setblock ~35 ~116 ~91 dirt
setblock ~35 ~116 ~92 dirt
setblock ~35 ~116 ~93 dirt
setblock ~35 ~116 ~94 dirt
setblock ~35 ~116 ~95 dirt
setblock ~35 ~116 ~96 dirt
setblock ~35 ~116 ~97 dirt
setblock ~35 ~116 ~98 dirt
setblock ~35 ~116 ~99 dirt
setblock ~35 ~116 ~100 dirt
setblock ~35 ~116 ~101 dirt
setblock ~35 ~116 ~102 dirt
setblock ~35 ~116 ~103 dirt
setblock ~35 ~116 ~104 dirt
setblock ~35 ~116 ~105 dirt
setblock ~35 ~116 ~106 dirt
setblock ~35 ~116 ~107 dirt
setblock ~35 ~116 ~108 dirt
setblock ~35 ~116 ~109 dirt
setblock ~35 ~116 ~110 dirt
setblock ~35 ~116 ~111 dirt
setblock ~35 ~116 ~112 dirt
setblock ~35 ~116 ~113 dirt
setblock ~35 ~116 ~114 dirt
setblock ~35 ~116 ~115 dirt
setblock ~35 ~116 ~116 dirt
setblock ~35 ~116 ~117 dirt
setblock ~35 ~116 ~118 dirt
setblock ~35 ~116 ~119 dirt
setblock ~35 ~116 ~120 dirt
setblock ~35 ~116 ~121 dirt
setblock ~35 ~116 ~122 dirt
setblock ~35 ~116 ~123 dirt
setblock ~35 ~116 ~124 dirt
setblock ~35 ~117 ~77 dirt
setblock ~35 ~117 ~78 dirt
setblock ~35 ~117 ~79 dirt
setblock ~35 ~117 ~80 dirt
setblock ~35 ~117 ~81 dirt
setblock ~35 ~117 ~82 dirt
setblock ~35 ~117 ~83 dirt
setblock ~35 ~117 ~84 dirt
setblock ~35 ~117 ~85 dirt
setblock ~35 ~117 ~86 dirt
setblock ~35 ~117 ~87 dirt
setblock ~35 ~117 ~88 dirt
setblock ~35 ~117 ~89 dirt
setblock ~35 ~117 ~90 dirt
setblock ~35 ~117 ~91 dirt
setblock ~35 ~117 ~92 dirt
setblock ~35 ~117 ~93 dirt
setblock ~35 ~117 ~94 dirt
setblock ~35 ~117 ~95 dirt
setblock ~35 ~117 ~96 dirt
setblock ~35 ~117 ~97 dirt
setblock ~35 ~117 ~98 dirt
setblock ~35 ~117 ~99 dirt
setblock ~35 ~117 ~100 dirt
setblock ~35 ~117 ~101 dirt
setblock ~35 ~117 ~102 dirt
setblock ~35 ~117 ~103 dirt
setblock ~35 ~117 ~104 dirt
setblock ~35 ~117 ~105 dirt
setblock ~35 ~117 ~106 dirt
setblock ~35 ~117 ~107 dirt
setblock ~35 ~117 ~108 dirt
setblock ~35 ~117 ~109 dirt
setblock ~35 ~117 ~110 dirt
setblock ~35 ~117 ~111 dirt
setblock ~35 ~117 ~112 dirt
setblock ~35 ~117 ~113 dirt
setblock ~35 ~117 ~114 dirt
setblock ~35 ~117 ~115 dirt
setblock ~35 ~117 ~116 dirt
setblock ~35 ~117 ~117 dirt
setblock ~35 ~117 ~118 dirt
setblock ~35 ~117 ~119 dirt
setblock ~35 ~117 ~120 dirt
setblock ~35 ~117 ~121 dirt
setblock ~35 ~117 ~122 dirt
setblock ~35 ~117 ~123 dirt
setblock ~35 ~117 ~124 dirt
setblock ~35 ~117 ~125 dirt
setblock ~35 ~117 ~126 dirt
setblock ~35 ~118 ~77 dirt
setblock ~35 ~118 ~78 dirt
setblock ~35 ~118 ~79 dirt
setblock ~35 ~118 ~80 dirt
setblock ~35 ~118 ~81 dirt
setblock ~35 ~118 ~82 dirt
setblock ~35 ~118 ~83 dirt
setblock ~35 ~118 ~84 dirt
setblock ~35 ~118 ~85 dirt
setblock ~35 ~118 ~86 dirt
setblock ~35 ~118 ~87 dirt
setblock ~35 ~118 ~88 dirt
setblock ~35 ~118 ~89 dirt
setblock ~35 ~118 ~90 dirt
setblock ~35 ~118 ~91 dirt
setblock ~35 ~118 ~92 dirt
setblock ~35 ~118 ~93 dirt
setblock ~35 ~118 ~94 dirt
setblock ~35 ~118 ~95 dirt
setblock ~35 ~118 ~96 dirt
setblock ~35 ~118 ~97 dirt
setblock ~35 ~118 ~98 dirt
setblock ~35 ~118 ~99 dirt
setblock ~35 ~118 ~100 dirt
setblock ~35 ~118 ~101 dirt
setblock ~35 ~118 ~102 dirt
setblock ~35 ~118 ~103 dirt
setblock ~35 ~118 ~104 dirt
setblock ~35 ~118 ~105 dirt
setblock ~35 ~118 ~106 dirt
setblock ~35 ~118 ~107 dirt
setblock ~35 ~118 ~108 dirt
setblock ~35 ~118 ~109 dirt
setblock ~35 ~118 ~110 dirt
setblock ~35 ~118 ~111 dirt
setblock ~35 ~118 ~112 dirt
setblock ~35 ~118 ~113 dirt
setblock ~35 ~118 ~114 dirt
setblock ~35 ~118 ~115 dirt
setblock ~35 ~118 ~116 dirt
setblock ~35 ~118 ~117 dirt
setblock ~35 ~118 ~118 dirt
setblock ~35 ~118 ~119 dirt
setblock ~35 ~118 ~120 dirt
setblock ~35 ~118 ~121 dirt
setblock ~35 ~118 ~122 dirt
setblock ~35 ~118 ~123 dirt
setblock ~35 ~118 ~124 dirt
setblock ~35 ~118 ~125 dirt
setblock ~35 ~118 ~126 dirt
setblock ~35 ~118 ~127 dirt
setblock ~35 ~119 ~75 dirt
setblock ~35 ~119 ~76 dirt
setblock ~35 ~119 ~77 dirt
setblock ~35 ~119 ~78 dirt
setblock ~35 ~119 ~79 dirt
setblock ~35 ~119 ~80 dirt
setblock ~35 ~119 ~81 dirt
setblock ~35 ~119 ~82 dirt
setblock ~35 ~119 ~83 dirt
setblock ~35 ~119 ~84 dirt
setblock ~35 ~119 ~85 dirt
setblock ~35 ~119 ~86 dirt
setblock ~35 ~119 ~87 dirt
setblock ~35 ~119 ~88 dirt
setblock ~35 ~119 ~89 dirt
setblock ~35 ~119 ~90 dirt
setblock ~35 ~119 ~91 dirt
setblock ~35 ~119 ~92 dirt
setblock ~35 ~119 ~93 dirt
setblock ~35 ~119 ~94 dirt
setblock ~35 ~119 ~95 dirt
setblock ~35 ~119 ~96 dirt
setblock ~35 ~119 ~97 dirt
setblock ~35 ~119 ~98 dirt
setblock ~35 ~119 ~99 dirt
setblock ~35 ~119 ~100 dirt
setblock ~35 ~119 ~101 dirt
setblock ~35 ~119 ~102 dirt
setblock ~35 ~119 ~103 dirt
setblock ~35 ~119 ~104 dirt
setblock ~35 ~119 ~105 dirt
setblock ~35 ~119 ~106 dirt
setblock ~35 ~119 ~107 dirt
setblock ~35 ~119 ~108 dirt
setblock ~35 ~119 ~109 dirt
setblock ~35 ~119 ~110 dirt
setblock ~35 ~119 ~111 dirt
setblock ~35 ~119 ~112 dirt
setblock ~35 ~119 ~113 dirt
setblock ~35 ~119 ~114 dirt
setblock ~35 ~119 ~115 dirt
setblock ~35 ~119 ~116 dirt
setblock ~35 ~119 ~117 dirt
setblock ~35 ~119 ~118 dirt
setblock ~35 ~119 ~119 dirt
setblock ~35 ~119 ~120 dirt
setblock ~35 ~119 ~121 dirt
setblock ~35 ~119 ~122 dirt
setblock ~35 ~119 ~123 dirt
setblock ~35 ~119 ~124 dirt
setblock ~35 ~119 ~125 dirt
setblock ~35 ~119 ~126 dirt
setblock ~35 ~119 ~127 dirt
setblock ~35 ~119 ~128 dirt
setblock ~35 ~119 ~129 dirt
setblock ~35 ~119 ~130 dirt
setblock ~35 ~120 ~74 dirt
setblock ~35 ~120 ~75 dirt
setblock ~35 ~120 ~76 dirt
setblock ~35 ~120 ~77 dirt
setblock ~35 ~120 ~78 dirt
setblock ~35 ~120 ~79 dirt
setblock ~35 ~120 ~80 dirt
setblock ~35 ~120 ~81 dirt
setblock ~35 ~120 ~82 dirt
setblock ~35 ~120 ~83 dirt
setblock ~35 ~120 ~84 dirt
setblock ~35 ~120 ~85 dirt
setblock ~35 ~120 ~86 dirt
setblock ~35 ~120 ~87 dirt
setblock ~35 ~120 ~88 dirt
setblock ~35 ~120 ~89 dirt
setblock ~35 ~120 ~90 dirt
setblock ~35 ~120 ~91 dirt
setblock ~35 ~120 ~92 dirt
setblock ~35 ~120 ~93 dirt
setblock ~35 ~120 ~94 dirt
setblock ~35 ~120 ~95 dirt
setblock ~35 ~120 ~96 dirt
setblock ~35 ~120 ~97 dirt
setblock ~35 ~120 ~98 dirt
setblock ~35 ~120 ~99 dirt
setblock ~35 ~120 ~100 dirt
setblock ~35 ~120 ~101 dirt
setblock ~35 ~120 ~102 dirt
setblock ~35 ~120 ~103 dirt
setblock ~35 ~120 ~104 dirt
setblock ~35 ~120 ~105 dirt
setblock ~35 ~120 ~106 dirt
setblock ~35 ~120 ~107 dirt
setblock ~35 ~120 ~108 dirt
setblock ~35 ~120 ~109 dirt
setblock ~35 ~120 ~110 dirt
setblock ~35 ~120 ~111 dirt
setblock ~35 ~120 ~112 dirt
setblock ~35 ~120 ~113 dirt
setblock ~35 ~120 ~114 dirt
setblock ~35 ~120 ~115 dirt
setblock ~35 ~120 ~116 dirt
setblock ~35 ~120 ~117 dirt
setblock ~35 ~120 ~118 dirt
setblock ~35 ~120 ~119 dirt
setblock ~35 ~120 ~120 dirt
setblock ~35 ~120 ~121 dirt
setblock ~35 ~120 ~122 dirt
setblock ~35 ~120 ~123 dirt
setblock ~35 ~120 ~124 dirt
setblock ~35 ~120 ~125 dirt
setblock ~35 ~120 ~126 dirt
setblock ~35 ~120 ~127 dirt
setblock ~35 ~120 ~128 dirt
setblock ~35 ~120 ~129 dirt
setblock ~35 ~120 ~130 dirt
setblock ~35 ~121 ~74 dirt
setblock ~35 ~121 ~75 dirt
setblock ~35 ~121 ~76 dirt
setblock ~35 ~121 ~77 dirt
setblock ~35 ~121 ~78 dirt
setblock ~35 ~121 ~79 dirt
setblock ~35 ~121 ~80 dirt
setblock ~35 ~121 ~81 dirt
setblock ~35 ~121 ~82 dirt
setblock ~35 ~121 ~83 dirt
setblock ~35 ~121 ~84 dirt
setblock ~35 ~121 ~85 dirt
setblock ~35 ~121 ~86 dirt
setblock ~35 ~121 ~87 dirt
setblock ~35 ~121 ~88 dirt
setblock ~35 ~121 ~89 dirt
setblock ~35 ~121 ~90 dirt
setblock ~35 ~121 ~91 dirt
setblock ~35 ~121 ~92 dirt
setblock ~35 ~121 ~93 dirt
setblock ~35 ~121 ~94 dirt
setblock ~35 ~121 ~95 dirt
setblock ~35 ~121 ~96 dirt
setblock ~35 ~121 ~97 dirt
setblock ~35 ~121 ~98 dirt
setblock ~35 ~121 ~99 dirt
setblock ~35 ~121 ~100 dirt
setblock ~35 ~121 ~101 dirt
setblock ~35 ~121 ~102 dirt
setblock ~35 ~121 ~103 dirt
setblock ~35 ~121 ~104 dirt
setblock ~35 ~121 ~105 dirt
setblock ~35 ~121 ~106 dirt
setblock ~35 ~121 ~107 dirt
setblock ~35 ~121 ~108 dirt
setblock ~35 ~121 ~109 dirt
setblock ~35 ~121 ~110 dirt
setblock ~35 ~121 ~111 dirt
setblock ~35 ~121 ~112 dirt
setblock ~35 ~121 ~113 dirt
setblock ~35 ~121 ~114 dirt
setblock ~35 ~121 ~115 dirt
setblock ~35 ~121 ~116 dirt
setblock ~35 ~121 ~117 dirt
setblock ~35 ~121 ~118 dirt
setblock ~35 ~121 ~119 dirt
setblock ~35 ~121 ~120 dirt
setblock ~35 ~121 ~121 dirt
setblock ~35 ~121 ~122 dirt
setblock ~35 ~121 ~123 dirt
setblock ~35 ~121 ~124 dirt
setblock ~35 ~121 ~125 dirt
setblock ~35 ~121 ~126 dirt
setblock ~35 ~121 ~127 dirt
setblock ~35 ~121 ~128 dirt
setblock ~35 ~121 ~129 dirt
setblock ~35 ~121 ~130 dirt
setblock ~35 ~121 ~131 dirt
setblock ~35 ~121 ~132 dirt
setblock ~35 ~122 ~74 dirt
setblock ~35 ~122 ~75 dirt
setblock ~35 ~122 ~76 dirt
setblock ~35 ~122 ~77 dirt
setblock ~35 ~122 ~78 dirt
setblock ~35 ~122 ~79 dirt
setblock ~35 ~122 ~80 dirt
setblock ~35 ~122 ~81 dirt
setblock ~35 ~122 ~82 dirt
setblock ~35 ~122 ~83 dirt
setblock ~35 ~122 ~84 dirt
setblock ~35 ~122 ~85 dirt
setblock ~35 ~122 ~86 dirt
setblock ~35 ~122 ~87 dirt
setblock ~35 ~122 ~88 dirt
setblock ~35 ~122 ~89 dirt
setblock ~35 ~122 ~90 dirt
setblock ~35 ~122 ~91 dirt
setblock ~35 ~122 ~92 dirt
setblock ~35 ~122 ~93 dirt
setblock ~35 ~122 ~94 dirt
setblock ~35 ~122 ~95 dirt
setblock ~35 ~122 ~96 dirt
setblock ~35 ~122 ~97 dirt
setblock ~35 ~122 ~98 dirt
setblock ~35 ~122 ~99 dirt
setblock ~35 ~122 ~100 dirt
setblock ~35 ~122 ~101 dirt
setblock ~35 ~122 ~102 dirt
setblock ~35 ~122 ~103 dirt
setblock ~35 ~122 ~104 dirt
setblock ~35 ~122 ~105 dirt
setblock ~35 ~122 ~106 dirt
setblock ~35 ~122 ~107 dirt
setblock ~35 ~122 ~108 dirt
setblock ~35 ~122 ~109 dirt
setblock ~35 ~122 ~110 dirt
setblock ~35 ~122 ~111 dirt
setblock ~35 ~122 ~112 dirt
setblock ~35 ~122 ~113 dirt
setblock ~35 ~122 ~114 dirt
setblock ~35 ~122 ~115 dirt
setblock ~35 ~122 ~116 dirt
setblock ~35 ~122 ~117 dirt
setblock ~35 ~122 ~118 dirt
setblock ~35 ~122 ~119 dirt
setblock ~35 ~122 ~120 dirt
setblock ~35 ~122 ~121 dirt
setblock ~35 ~122 ~122 dirt
setblock ~35 ~122 ~123 dirt
setblock ~35 ~122 ~124 dirt
setblock ~35 ~122 ~125 dirt
setblock ~35 ~122 ~126 dirt
setblock ~35 ~122 ~127 dirt
setblock ~35 ~122 ~128 dirt
setblock ~35 ~122 ~129 dirt
setblock ~35 ~122 ~130 dirt
setblock ~35 ~122 ~131 dirt
setblock ~35 ~122 ~132 dirt
setblock ~35 ~123 ~74 dirt
setblock ~35 ~123 ~75 dirt
setblock ~35 ~123 ~76 dirt
setblock ~35 ~123 ~77 dirt
setblock ~35 ~123 ~78 dirt
setblock ~35 ~123 ~79 dirt
setblock ~35 ~123 ~80 dirt
setblock ~35 ~123 ~81 dirt
setblock ~35 ~123 ~82 dirt
setblock ~35 ~123 ~83 dirt
setblock ~35 ~123 ~84 dirt
setblock ~35 ~123 ~85 dirt
setblock ~35 ~123 ~86 dirt
setblock ~35 ~123 ~87 dirt
setblock ~35 ~123 ~88 dirt
setblock ~35 ~123 ~89 dirt
setblock ~35 ~123 ~90 dirt
setblock ~35 ~123 ~91 dirt
setblock ~35 ~123 ~92 dirt
setblock ~35 ~123 ~93 dirt
setblock ~35 ~123 ~94 grass_block
setblock ~35 ~123 ~95 grass_block
setblock ~35 ~123 ~96 grass_block
setblock ~35 ~123 ~97 grass_block
setblock ~35 ~123 ~98 grass_block
setblock ~35 ~123 ~99 grass_block
setblock ~35 ~123 ~100 grass_block
setblock ~35 ~123 ~101 grass_block
setblock ~35 ~123 ~102 dirt
setblock ~35 ~123 ~103 dirt
setblock ~35 ~123 ~104 dirt
setblock ~35 ~123 ~105 dirt
setblock ~35 ~123 ~106 dirt
setblock ~35 ~123 ~107 dirt
setblock ~35 ~123 ~108 dirt
setblock ~35 ~123 ~109 dirt
setblock ~35 ~123 ~110 dirt
setblock ~35 ~123 ~111 dirt
setblock ~35 ~123 ~112 dirt
setblock ~35 ~123 ~113 dirt
setblock ~35 ~123 ~114 dirt
setblock ~35 ~123 ~115 dirt
setblock ~35 ~123 ~116 dirt
setblock ~35 ~123 ~117 dirt
setblock ~35 ~123 ~118 dirt
setblock ~35 ~123 ~119 dirt
setblock ~35 ~123 ~120 dirt
setblock ~35 ~123 ~121 dirt
setblock ~35 ~123 ~122 dirt
setblock ~35 ~123 ~123 dirt
setblock ~35 ~123 ~124 dirt
setblock ~35 ~123 ~125 dirt
setblock ~35 ~123 ~126 dirt
setblock ~35 ~123 ~127 dirt
setblock ~35 ~123 ~128 dirt
setblock ~35 ~123 ~129 dirt
setblock ~35 ~123 ~130 dirt
setblock ~35 ~123 ~131 dirt
setblock ~35 ~123 ~132 dirt
setblock ~35 ~124 ~74 dirt
setblock ~35 ~124 ~75 dirt
setblock ~35 ~124 ~76 dirt
setblock ~35 ~124 ~77 dirt
setblock ~35 ~124 ~78 dirt
setblock ~35 ~124 ~79 dirt
setblock ~35 ~124 ~80 dirt
setblock ~35 ~124 ~81 dirt
setblock ~35 ~124 ~82 dirt
setblock ~35 ~124 ~83 dirt
setblock ~35 ~124 ~84 dirt
setblock ~35 ~124 ~85 dirt
setblock ~35 ~124 ~86 dirt
setblock ~35 ~124 ~87 grass_block
setblock ~35 ~124 ~88 grass_block
setblock ~35 ~124 ~89 grass_block
setblock ~35 ~124 ~90 grass_block
setblock ~35 ~124 ~91 grass_block
setblock ~35 ~124 ~92 grass_block
setblock ~35 ~124 ~93 grass_block
setblock ~35 ~124 ~96 poppy
setblock ~35 ~124 ~99 short_grass
setblock ~35 ~124 ~100 short_grass
setblock ~35 ~124 ~101 fern
setblock ~35 ~124 ~102 grass_block
setblock ~35 ~124 ~103 grass_block
setblock ~35 ~124 ~104 grass_block
setblock ~35 ~124 ~105 grass_block
setblock ~35 ~124 ~106 grass_block
setblock ~35 ~124 ~107 dirt
setblock ~35 ~124 ~108 dirt
setblock ~35 ~124 ~109 dirt
setblock ~35 ~124 ~110 dirt
setblock ~35 ~124 ~111 dirt
setblock ~35 ~124 ~112 dirt
setblock ~35 ~124 ~113 dirt
setblock ~35 ~124 ~114 dirt
setblock ~35 ~124 ~115 dirt
setblock ~35 ~124 ~116 dirt
setblock ~35 ~124 ~117 dirt
setblock ~35 ~124 ~118 dirt
setblock ~35 ~124 ~119 dirt
setblock ~35 ~124 ~120 grass_block
setblock ~35 ~124 ~121 grass_block
setblock ~35 ~124 ~122 grass_block
setblock ~35 ~124 ~123 grass_block
setblock ~35 ~124 ~124 grass_block
setblock ~35 ~124 ~125 grass_block
setblock ~35 ~124 ~126 grass_block
setblock ~35 ~124 ~127 grass_block
setblock ~35 ~124 ~128 grass_block
setblock ~35 ~124 ~129 grass_block
setblock ~35 ~124 ~130 grass_block
setblock ~35 ~124 ~131 grass_block
setblock ~35 ~124 ~132 grass_block
setblock ~35 ~125 ~74 grass_block
setblock ~35 ~125 ~75 grass_block
setblock ~35 ~125 ~76 dirt
setblock ~35 ~125 ~77 dirt
setblock ~35 ~125 ~78 dirt
setblock ~35 ~125 ~79 dirt
setblock ~35 ~125 ~80 dirt
setblock ~35 ~125 ~81 dirt
setblock ~35 ~125 ~82 dirt
setblock ~35 ~125 ~83 grass_block
setblock ~35 ~125 ~84 grass_block
setblock ~35 ~125 ~85 grass_block
setblock ~35 ~125 ~86 grass_block
setblock ~35 ~125 ~88 fern
setblock ~35 ~125 ~89 poppy
setblock ~35 ~125 ~102 short_grass
setblock ~35 ~125 ~107 grass_block
setblock ~35 ~125 ~108 grass_block
setblock ~35 ~125 ~109 grass_block
setblock ~35 ~125 ~110 dirt
setblock ~35 ~125 ~111 dirt
setblock ~35 ~125 ~112 grass_block
setblock ~35 ~125 ~113 grass_block
setblock ~35 ~125 ~114 grass_block
setblock ~35 ~125 ~115 grass_block
setblock ~35 ~125 ~116 grass_block
setblock ~35 ~125 ~117 grass_block
setblock ~35 ~125 ~118 grass_block
setblock ~35 ~125 ~119 grass_block
setblock ~35 ~125 ~124 short_grass
setblock ~35 ~125 ~125 short_grass
setblock ~35 ~125 ~130 short_grass
setblock ~35 ~126 ~74 short_grass
setblock ~35 ~126 ~76 grass_block
setblock ~35 ~126 ~77 grass_block
setblock ~35 ~126 ~78 grass_block
setblock ~35 ~126 ~79 grass_block
setblock ~35 ~126 ~80 grass_block
setblock ~35 ~126 ~81 grass_block
setblock ~35 ~126 ~82 grass_block
setblock ~35 ~126 ~83 short_grass
setblock ~35 ~126 ~85 short_grass
setblock ~35 ~126 ~110 grass_block
setblock ~35 ~126 ~111 grass_block
setblock ~35 ~126 ~115 short_grass
setblock ~35 ~126 ~116 short_grass
setblock ~35 ~127 ~79 fern
setblock ~35 ~127 ~110 short_grass
setblock ~35 ~137 ~101 jungle_leaves[persistent=true]
setblock ~35 ~137 ~102 oak_leaves[persistent=true]
setblock ~35 ~137 ~104 oak_leaves[persistent=true]
setblock ~35 ~138 ~101 jungle_leaves[persistent=true]
setblock ~35 ~138 ~103 jungle_leaves[persistent=true]
setblock ~35 ~138 ~104 jungle_leaves[persistent=true]
setblock ~35 ~139 ~101 jungle_leaves[persistent=true]
setblock ~35 ~139 ~102 oak_leaves[persistent=true]
setblock ~35 ~139 ~103 oak_leaves[persistent=true]
setblock ~35 ~139 ~104 oak_leaves[persistent=true]
setblock ~35 ~140 ~101 oak_leaves[persistent=true]
setblock ~35 ~140 ~103 jungle_leaves[persistent=true]
setblock ~35 ~140 ~104 oak_leaves[persistent=true]
setblock ~36 ~100 ~100 dirt
setblock ~36 ~101 ~99 dirt
setblock ~36 ~101 ~100 dirt
setblock ~36 ~101 ~101 dirt
setblock ~36 ~102 ~98 dirt
setblock ~36 ~102 ~99 dirt
setblock ~36 ~102 ~100 dirt
setblock ~36 ~102 ~101 dirt
setblock ~36 ~103 ~98 dirt
setblock ~36 ~103 ~99 dirt
setblock ~36 ~103 ~100 dirt
setblock ~36 ~103 ~101 dirt
setblock ~36 ~103 ~102 dirt
setblock ~36 ~104 ~98 dirt
setblock ~36 ~104 ~99 dirt
setblock ~36 ~104 ~100 dirt
setblock ~36 ~104 ~101 dirt
setblock ~36 ~104 ~102 dirt
setblock ~36 ~104 ~103 dirt
setblock ~36 ~105 ~97 dirt
setblock ~36 ~105 ~98 dirt
setblock ~36 ~105 ~99 dirt
setblock ~36 ~105 ~100 dirt
setblock ~36 ~105 ~101 dirt
setblock ~36 ~105 ~102 dirt
setblock ~36 ~105 ~103 dirt
setblock ~36 ~105 ~105 dirt
setblock ~36 ~106 ~96 dirt
setblock ~36 ~106 ~97 dirt
setblock ~36 ~106 ~98 dirt
setblock ~36 ~106 ~99 dirt
setblock ~36 ~106 ~100 dirt
setblock ~36 ~106 ~101 dirt
setblock ~36 ~106 ~102 dirt
setblock ~36 ~106 ~103 dirt
setblock ~36 ~106 ~105 dirt
setblock ~36 ~107 ~95 dirt
setblock ~36 ~107 ~96 dirt
setblock ~36 ~107 ~97 dirt
setblock ~36 ~107 ~98 dirt
setblock ~36 ~107 ~99 dirt
setblock ~36 ~107 ~100 dirt
setblock ~36 ~107 ~101 dirt
setblock ~36 ~107 ~102 dirt
setblock ~36 ~107 ~103 dirt
setblock ~36 ~107 ~104 dirt
setblock ~36 ~107 ~105 dirt
setblock ~36 ~107 ~106 dirt
setblock ~36 ~108 ~94 dirt
setblock ~36 ~108 ~95 dirt
setblock ~36 ~108 ~96 dirt
setblock ~36 ~108 ~97 dirt
setblock ~36 ~108 ~98 dirt
setblock ~36 ~108 ~99 dirt
setblock ~36 ~108 ~100 dirt
setblock ~36 ~108 ~101 dirt
setblock ~36 ~108 ~102 dirt
setblock ~36 ~108 ~103 dirt
setblock ~36 ~108 ~104 dirt
setblock ~36 ~108 ~105 dirt
setblock ~36 ~108 ~106 dirt
setblock ~36 ~108 ~107 dirt
setblock ~36 ~109 ~89 dirt
setblock ~36 ~109 ~93 dirt
setblock ~36 ~109 ~94 dirt
setblock ~36 ~109 ~95 dirt
setblock ~36 ~109 ~96 dirt
setblock ~36 ~109 ~97 dirt
setblock ~36 ~109 ~98 dirt
setblock ~36 ~109 ~99 dirt
setblock ~36 ~109 ~100 dirt
setblock ~36 ~109 ~101 dirt
setblock ~36 ~109 ~102 dirt
setblock ~36 ~109 ~103 dirt
setblock ~36 ~109 ~104 dirt
setblock ~36 ~109 ~105 dirt
setblock ~36 ~109 ~106 dirt
setblock ~36 ~109 ~107 dirt
setblock ~36 ~109 ~108 dirt
setblock ~36 ~110 ~86 dirt
setblock ~36 ~110 ~87 dirt
setblock ~36 ~110 ~88 dirt
setblock ~36 ~110 ~89 dirt
setblock ~36 ~110 ~90 dirt
setblock ~36 ~110 ~91 dirt
setblock ~36 ~110 ~92 dirt
setblock ~36 ~110 ~93 dirt
setblock ~36 ~110 ~94 dirt
setblock ~36 ~110 ~95 dirt
setblock ~36 ~110 ~96 dirt
setblock ~36 ~110 ~97 dirt
setblock ~36 ~110 ~98 dirt
setblock ~36 ~110 ~99 dirt
setblock ~36 ~110 ~100 dirt
setblock ~36 ~110 ~101 dirt
setblock ~36 ~110 ~102 dirt
setblock ~36 ~110 ~103 dirt
setblock ~36 ~110 ~104 dirt
setblock ~36 ~110 ~105 dirt
setblock ~36 ~110 ~106 dirt
setblock ~36 ~110 ~107 dirt
setblock ~36 ~110 ~108 dirt
setblock ~36 ~110 ~115 dirt
setblock ~36 ~110 ~117 dirt
setblock ~36 ~111 ~83 dirt
setblock ~36 ~111 ~86 dirt
setblock ~36 ~111 ~87 dirt
setblock ~36 ~111 ~88 dirt
setblock ~36 ~111 ~89 dirt
setblock ~36 ~111 ~90 dirt
setblock ~36 ~111 ~91 dirt
setblock ~36 ~111 ~92 dirt
setblock ~36 ~111 ~93 dirt
setblock ~36 ~111 ~94 dirt
setblock ~36 ~111 ~95 dirt
setblock ~36 ~111 ~96 dirt
setblock ~36 ~111 ~97 dirt
setblock ~36 ~111 ~98 dirt
setblock ~36 ~111 ~99 dirt
setblock ~36 ~111 ~100 dirt
setblock ~36 ~111 ~101 dirt
setblock ~36 ~111 ~102 dirt
setblock ~36 ~111 ~103 dirt
setblock ~36 ~111 ~104 dirt
setblock ~36 ~111 ~105 dirt
setblock ~36 ~111 ~106 dirt
setblock ~36 ~111 ~107 dirt
setblock ~36 ~111 ~108 dirt
setblock ~36 ~111 ~110 dirt
setblock ~36 ~111 ~114 dirt
setblock ~36 ~111 ~115 dirt
setblock ~36 ~111 ~116 dirt
setblock ~36 ~111 ~117 dirt
setblock ~36 ~111 ~118 dirt
setblock ~36 ~112 ~82 dirt
setblock ~36 ~112 ~83 dirt
setblock ~36 ~112 ~84 dirt
setblock ~36 ~112 ~85 dirt
setblock ~36 ~112 ~86 dirt
setblock ~36 ~112 ~87 dirt
setblock ~36 ~112 ~88 dirt
setblock ~36 ~112 ~89 dirt
setblock ~36 ~112 ~90 dirt
setblock ~36 ~112 ~91 dirt
setblock ~36 ~112 ~92 dirt
setblock ~36 ~112 ~93 dirt
setblock ~36 ~112 ~94 dirt
setblock ~36 ~112 ~95 dirt
setblock ~36 ~112 ~96 dirt
setblock ~36 ~112 ~97 dirt
setblock ~36 ~112 ~98 dirt
setblock ~36 ~112 ~99 dirt
setblock ~36 ~112 ~100 dirt
setblock ~36 ~112 ~101 dirt
setblock ~36 ~112 ~102 dirt
setblock ~36 ~112 ~103 dirt
setblock ~36 ~112 ~104 dirt
setblock ~36 ~112 ~105 dirt
setblock ~36 ~112 ~106 dirt
setblock ~36 ~112 ~107 dirt
setblock ~36 ~112 ~108 dirt
setblock ~36 ~112 ~109 dirt
setblock ~36 ~112 ~110 dirt
setblock ~36 ~112 ~113 dirt
setblock ~36 ~112 ~114 dirt
setblock ~36 ~112 ~115 dirt
setblock ~36 ~112 ~116 dirt
setblock ~36 ~112 ~117 dirt
setblock ~36 ~112 ~118 dirt
setblock ~36 ~112 ~119 dirt
setblock ~36 ~112 ~122 dirt
setblock ~36 ~113 ~82 dirt
setblock ~36 ~113 ~83 dirt
setblock ~36 ~113 ~84 dirt
setblock ~36 ~113 ~85 dirt
setblock ~36 ~113 ~86 dirt
setblock ~36 ~113 ~87 dirt
setblock ~36 ~113 ~88 dirt
setblock ~36 ~113 ~89 dirt
setblock ~36 ~113 ~90 dirt
setblock ~36 ~113 ~91 dirt
setblock ~36 ~113 ~92 dirt
setblock ~36 ~113 ~93 dirt
setblock ~36 ~113 ~94 dirt
setblock ~36 ~113 ~95 dirt
setblock ~36 ~113 ~96 dirt
setblock ~36 ~113 ~97 dirt
setblock ~36 ~113 ~98 dirt
setblock ~36 ~113 ~99 dirt
setblock ~36 ~113 ~100 dirt
setblock ~36 ~113 ~101 dirt
setblock ~36 ~113 ~102 dirt
setblock ~36 ~113 ~103 dirt
setblock ~36 ~113 ~104 dirt
setblock ~36 ~113 ~105 dirt
setblock ~36 ~113 ~106 dirt
setblock ~36 ~113 ~107 dirt
setblock ~36 ~113 ~108 dirt
setblock ~36 ~113 ~109 dirt
setblock ~36 ~113 ~110 dirt
setblock ~36 ~113 ~111 dirt
setblock ~36 ~113 ~112 dirt
setblock ~36 ~113 ~113 dirt
setblock ~36 ~113 ~114 dirt
setblock ~36 ~113 ~115 dirt
setblock ~36 ~113 ~116 dirt
setblock ~36 ~113 ~117 dirt
setblock ~36 ~113 ~118 dirt
setblock ~36 ~113 ~119 dirt
setblock ~36 ~113 ~120 dirt
setblock ~36 ~113 ~122 dirt
setblock ~36 ~114 ~78 dirt
setblock ~36 ~114 ~79 dirt
setblock ~36 ~114 ~80 dirt
setblock ~36 ~114 ~82 dirt
setblock ~36 ~114 ~83 dirt
setblock ~36 ~114 ~84 dirt
setblock ~36 ~114 ~85 dirt
setblock ~36 ~114 ~86 dirt
setblock ~36 ~114 ~87 dirt
setblock ~36 ~114 ~88 dirt
setblock ~36 ~114 ~89 dirt
setblock ~36 ~114 ~90 dirt
setblock ~36 ~114 ~91 dirt
setblock ~36 ~114 ~92 dirt
setblock ~36 ~114 ~93 dirt
setblock ~36 ~114 ~94 dirt
setblock ~36 ~114 ~95 dirt
setblock ~36 ~114 ~96 dirt
setblock ~36 ~114 ~97 dirt
setblock ~36 ~114 ~98 dirt
setblock ~36 ~114 ~99 dirt
setblock ~36 ~114 ~100 dirt
setblock ~36 ~114 ~101 dirt
setblock ~36 ~114 ~102 dirt
setblock ~36 ~114 ~103 dirt
setblock ~36 ~114 ~104 dirt
setblock ~36 ~114 ~105 dirt
setblock ~36 ~114 ~106 dirt
setblock ~36 ~114 ~107 dirt
setblock ~36 ~114 ~108 dirt
setblock ~36 ~114 ~109 dirt
setblock ~36 ~114 ~110 dirt
setblock ~36 ~114 ~111 dirt
setblock ~36 ~114 ~112 dirt
setblock ~36 ~114 ~113 dirt
setblock ~36 ~114 ~114 dirt
setblock ~36 ~114 ~115 dirt
setblock ~36 ~114 ~116 dirt
setblock ~36 ~114 ~117 dirt
setblock ~36 ~114 ~118 dirt
setblock ~36 ~114 ~119 dirt
setblock ~36 ~114 ~120 dirt
setblock ~36 ~114 ~121 dirt
setblock ~36 ~114 ~122 dirt
setblock ~36 ~114 ~123 dirt
setblock ~36 ~115 ~77 dirt
setblock ~36 ~115 ~78 dirt
setblock ~36 ~115 ~79 dirt
setblock ~36 ~115 ~80 dirt
setblock ~36 ~115 ~81 dirt
setblock ~36 ~115 ~82 dirt
setblock ~36 ~115 ~83 dirt
setblock ~36 ~115 ~84 dirt
setblock ~36 ~115 ~85 dirt
setblock ~36 ~115 ~86 dirt
setblock ~36 ~115 ~87 dirt
setblock ~36 ~115 ~88 dirt
setblock ~36 ~115 ~89 dirt
setblock ~36 ~115 ~90 dirt
setblock ~36 ~115 ~91 dirt
setblock ~36 ~115 ~92 dirt
setblock ~36 ~115 ~93 dirt
setblock ~36 ~115 ~94 dirt
setblock ~36 ~115 ~95 dirt
setblock ~36 ~115 ~96 dirt
setblock ~36 ~115 ~97 dirt
setblock ~36 ~115 ~98 dirt
setblock ~36 ~115 ~99 dirt
setblock ~36 ~115 ~100 dirt
setblock ~36 ~115 ~101 dirt
setblock ~36 ~115 ~102 dirt
setblock ~36 ~115 ~103 dirt
setblock ~36 ~115 ~104 dirt
setblock ~36 ~115 ~105 dirt
setblock ~36 ~115 ~106 dirt
setblock ~36 ~115 ~107 dirt
setblock ~36 ~115 ~108 dirt
setblock ~36 ~115 ~109 dirt
setblock ~36 ~115 ~110 dirt
setblock ~36 ~115 ~111 dirt
setblock ~36 ~115 ~112 dirt
setblock ~36 ~115 ~113 dirt
setblock ~36 ~115 ~114 dirt
setblock ~36 ~115 ~115 dirt
setblock ~36 ~115 ~116 dirt
setblock ~36 ~115 ~117 dirt
setblock ~36 ~115 ~118 dirt
setblock ~36 ~115 ~119 dirt
setblock ~36 ~115 ~120 dirt
setblock ~36 ~115 ~121 dirt
setblock ~36 ~115 ~122 dirt
setblock ~36 ~115 ~123 dirt
setblock ~36 ~115 ~124 dirt
setblock ~36 ~115 ~127 dirt
setblock ~36 ~116 ~76 dirt
setblock ~36 ~116 ~77 dirt
setblock ~36 ~116 ~78 dirt
setblock ~36 ~116 ~79 dirt
setblock ~36 ~116 ~80 dirt
setblock ~36 ~116 ~81 dirt
setblock ~36 ~116 ~82 dirt
setblock ~36 ~116 ~83 dirt
setblock ~36 ~116 ~84 dirt
setblock ~36 ~116 ~85 dirt
setblock ~36 ~116 ~86 dirt
setblock ~36 ~116 ~87 dirt
setblock ~36 ~116 ~88 dirt
setblock ~36 ~116 ~89 dirt
setblock ~36 ~116 ~90 dirt
setblock ~36 ~116 ~91 dirt
setblock ~36 ~116 ~92 dirt
setblock ~36 ~116 ~93 dirt
setblock ~36 ~116 ~94 dirt
setblock ~36 ~116 ~95 dirt
setblock ~36 ~116 ~96 dirt
setblock ~36 ~116 ~97 dirt
setblock ~36 ~116 ~98 dirt
setblock ~36 ~116 ~99 dirt
setblock ~36 ~116 ~100 dirt
setblock ~36 ~116 ~101 dirt
setblock ~36 ~116 ~102 dirt
setblock ~36 ~116 ~103 dirt
setblock ~36 ~116 ~104 dirt
setblock ~36 ~116 ~105 dirt
setblock ~36 ~116 ~106 dirt
setblock ~36 ~116 ~107 dirt
setblock ~36 ~116 ~108 dirt
setblock ~36 ~116 ~109 dirt
setblock ~36 ~116 ~110 dirt
setblock ~36 ~116 ~111 dirt
setblock ~36 ~116 ~112 dirt
setblock ~36 ~116 ~113 dirt
setblock ~36 ~116 ~114 dirt
setblock ~36 ~116 ~115 dirt
setblock ~36 ~116 ~116 dirt
setblock ~36 ~116 ~117 dirt
setblock ~36 ~116 ~118 dirt
setblock ~36 ~116 ~119 dirt
setblock ~36 ~116 ~120 dirt
setblock ~36 ~116 ~121 dirt
setblock ~36 ~116 ~122 dirt
setblock ~36 ~116 ~123 dirt
setblock ~36 ~116 ~124 dirt
setblock ~36 ~116 ~125 dirt
setblock ~36 ~116 ~126 dirt
setblock ~36 ~116 ~127 dirt
setblock ~36 ~116 ~128 dirt
setblock ~36 ~117 ~76 dirt
setblock ~36 ~117 ~77 dirt
setblock ~36 ~117 ~78 dirt
setblock ~36 ~117 ~79 dirt
setblock ~36 ~117 ~80 dirt
setblock ~36 ~117 ~81 dirt
setblock ~36 ~117 ~82 dirt
setblock ~36 ~117 ~83 dirt
setblock ~36 ~117 ~84 dirt
setblock ~36 ~117 ~85 dirt
setblock ~36 ~117 ~86 dirt
setblock ~36 ~117 ~87 dirt
setblock ~36 ~117 ~88 dirt
setblock ~36 ~117 ~89 dirt
setblock ~36 ~117 ~90 dirt
setblock ~36 ~117 ~91 dirt
setblock ~36 ~117 ~92 dirt
setblock ~36 ~117 ~93 dirt
setblock ~36 ~117 ~94 dirt
setblock ~36 ~117 ~95 dirt
setblock ~36 ~117 ~96 dirt
setblock ~36 ~117 ~97 dirt
setblock ~36 ~117 ~98 dirt
setblock ~36 ~117 ~99 dirt
setblock ~36 ~117 ~100 dirt
setblock ~36 ~117 ~101 dirt
setblock ~36 ~117 ~102 dirt
setblock ~36 ~117 ~103 dirt
setblock ~36 ~117 ~104 dirt
setblock ~36 ~117 ~105 dirt
setblock ~36 ~117 ~106 dirt
setblock ~36 ~117 ~107 dirt
setblock ~36 ~117 ~108 dirt
setblock ~36 ~117 ~109 dirt
setblock ~36 ~117 ~110 dirt
setblock ~36 ~117 ~111 dirt
setblock ~36 ~117 ~112 dirt
setblock ~36 ~117 ~113 dirt
setblock ~36 ~117 ~114 dirt
setblock ~36 ~117 ~115 dirt
setblock ~36 ~117 ~116 dirt
setblock ~36 ~117 ~117 dirt
setblock ~36 ~117 ~118 dirt
setblock ~36 ~117 ~119 dirt
setblock ~36 ~117 ~120 dirt
setblock ~36 ~117 ~121 dirt
setblock ~36 ~117 ~122 dirt
setblock ~36 ~117 ~123 dirt
setblock ~36 ~117 ~124 dirt
setblock ~36 ~117 ~125 dirt
setblock ~36 ~117 ~126 dirt
setblock ~36 ~117 ~127 dirt
setblock ~36 ~117 ~128 dirt
setblock ~36 ~117 ~129 dirt
setblock ~36 ~117 ~130 dirt
setblock ~36 ~117 ~131 dirt
setblock ~36 ~118 ~75 dirt
setblock ~36 ~118 ~76 dirt
setblock ~36 ~118 ~77 dirt
setblock ~36 ~118 ~78 dirt
setblock ~36 ~118 ~79 dirt
setblock ~36 ~118 ~80 dirt
setblock ~36 ~118 ~81 dirt
setblock ~36 ~118 ~82 dirt
setblock ~36 ~118 ~83 dirt
setblock ~36 ~118 ~84 dirt
setblock ~36 ~118 ~85 dirt
setblock ~36 ~118 ~86 dirt
setblock ~36 ~118 ~87 dirt
setblock ~36 ~118 ~88 dirt
setblock ~36 ~118 ~89 dirt
setblock ~36 ~118 ~90 dirt
setblock ~36 ~118 ~91 dirt
setblock ~36 ~118 ~92 dirt
setblock ~36 ~118 ~93 dirt
setblock ~36 ~118 ~94 dirt
setblock ~36 ~118 ~95 dirt
setblock ~36 ~118 ~96 dirt
setblock ~36 ~118 ~97 dirt
setblock ~36 ~118 ~98 dirt
setblock ~36 ~118 ~99 dirt
setblock ~36 ~118 ~100 dirt
setblock ~36 ~118 ~101 dirt
setblock ~36 ~118 ~102 dirt
setblock ~36 ~118 ~103 dirt
setblock ~36 ~118 ~104 dirt
setblock ~36 ~118 ~105 dirt
setblock ~36 ~118 ~106 dirt
setblock ~36 ~118 ~107 dirt
setblock ~36 ~118 ~108 dirt
setblock ~36 ~118 ~109 dirt
setblock ~36 ~118 ~110 dirt
setblock ~36 ~118 ~111 dirt
setblock ~36 ~118 ~112 dirt
setblock ~36 ~118 ~113 dirt
setblock ~36 ~118 ~114 dirt
setblock ~36 ~118 ~115 dirt
setblock ~36 ~118 ~116 dirt
setblock ~36 ~118 ~117 dirt
setblock ~36 ~118 ~118 dirt
setblock ~36 ~118 ~119 dirt
setblock ~36 ~118 ~120 dirt
setblock ~36 ~118 ~121 dirt
setblock ~36 ~118 ~122 dirt
setblock ~36 ~118 ~123 dirt
setblock ~36 ~118 ~124 dirt
setblock ~36 ~118 ~125 dirt
setblock ~36 ~118 ~126 dirt
setblock ~36 ~118 ~127 dirt
setblock ~36 ~118 ~128 dirt
setblock ~36 ~118 ~129 dirt
setblock ~36 ~118 ~130 dirt
setblock ~36 ~118 ~131 dirt
setblock ~36 ~119 ~74 dirt
setblock ~36 ~119 ~75 dirt
setblock ~36 ~119 ~76 dirt
setblock ~36 ~119 ~77 dirt
setblock ~36 ~119 ~78 dirt
setblock ~36 ~119 ~79 dirt
setblock ~36 ~119 ~80 dirt
setblock ~36 ~119 ~81 dirt
setblock ~36 ~119 ~82 dirt
setblock ~36 ~119 ~83 dirt
setblock ~36 ~119 ~84 dirt
setblock ~36 ~119 ~85 dirt
setblock ~36 ~119 ~86 dirt
setblock ~36 ~119 ~87 dirt
setblock ~36 ~119 ~88 dirt
setblock ~36 ~119 ~89 dirt
setblock ~36 ~119 ~90 dirt
setblock ~36 ~119 ~91 dirt
setblock ~36 ~119 ~92 dirt
setblock ~36 ~119 ~93 dirt
setblock ~36 ~119 ~94 dirt
setblock ~36 ~119 ~95 dirt
setblock ~36 ~119 ~96 dirt
setblock ~36 ~119 ~97 dirt
setblock ~36 ~119 ~98 dirt
setblock ~36 ~119 ~99 dirt
setblock ~36 ~119 ~100 dirt
setblock ~36 ~119 ~101 dirt
setblock ~36 ~119 ~102 dirt
setblock ~36 ~119 ~103 dirt
setblock ~36 ~119 ~104 dirt
setblock ~36 ~119 ~105 dirt
setblock ~36 ~119 ~106 dirt
setblock ~36 ~119 ~107 dirt
setblock ~36 ~119 ~108 dirt
setblock ~36 ~119 ~109 dirt
setblock ~36 ~119 ~110 dirt
setblock ~36 ~119 ~111 dirt
setblock ~36 ~119 ~112 dirt
setblock ~36 ~119 ~113 dirt
setblock ~36 ~119 ~114 dirt
setblock ~36 ~119 ~115 dirt
setblock ~36 ~119 ~116 dirt
setblock ~36 ~119 ~117 dirt
setblock ~36 ~119 ~118 dirt
setblock ~36 ~119 ~119 dirt
setblock ~36 ~119 ~120 dirt
setblock ~36 ~119 ~121 dirt
setblock ~36 ~119 ~122 dirt
setblock ~36 ~119 ~123 dirt
setblock ~36 ~119 ~124 dirt
setblock ~36 ~119 ~125 dirt
setblock ~36 ~119 ~126 dirt
setblock ~36 ~119 ~127 dirt
setblock ~36 ~119 ~128 dirt
setblock ~36 ~119 ~129 dirt
setblock ~36 ~119 ~130 dirt
setblock ~36 ~119 ~131 dirt
setblock ~36 ~120 ~73 dirt
setblock ~36 ~120 ~74 dirt
setblock ~36 ~120 ~75 dirt
setblock ~36 ~120 ~76 dirt
setblock ~36 ~120 ~77 dirt
setblock ~36 ~120 ~78 dirt
setblock ~36 ~120 ~79 dirt
setblock ~36 ~120 ~80 dirt
setblock ~36 ~120 ~81 dirt
setblock ~36 ~120 ~82 dirt
setblock ~36 ~120 ~83 dirt
setblock ~36 ~120 ~84 dirt
setblock ~36 ~120 ~85 dirt
setblock ~36 ~120 ~86 dirt
setblock ~36 ~120 ~87 dirt
setblock ~36 ~120 ~88 dirt
setblock ~36 ~120 ~89 dirt
setblock ~36 ~120 ~90 dirt
setblock ~36 ~120 ~91 dirt
setblock ~36 ~120 ~92 dirt
setblock ~36 ~120 ~93 dirt
setblock ~36 ~120 ~94 dirt
setblock ~36 ~120 ~95 dirt
setblock ~36 ~120 ~96 dirt
setblock ~36 ~120 ~97 dirt
setblock ~36 ~120 ~98 dirt
setblock ~36 ~120 ~99 dirt
setblock ~36 ~120 ~100 dirt
setblock ~36 ~120 ~101 dirt
setblock ~36 ~120 ~102 dirt
setblock ~36 ~120 ~103 dirt
setblock ~36 ~120 ~104 dirt
setblock ~36 ~120 ~105 dirt
setblock ~36 ~120 ~106 dirt
setblock ~36 ~120 ~107 dirt
setblock ~36 ~120 ~108 dirt
setblock ~36 ~120 ~109 dirt
setblock ~36 ~120 ~110 dirt
setblock ~36 ~120 ~111 dirt
setblock ~36 ~120 ~112 dirt
setblock ~36 ~120 ~113 dirt
setblock ~36 ~120 ~114 dirt
setblock ~36 ~120 ~115 dirt
setblock ~36 ~120 ~116 dirt
setblock ~36 ~120 ~117 dirt
setblock ~36 ~120 ~118 dirt
setblock ~36 ~120 ~119 dirt
setblock ~36 ~120 ~120 dirt
setblock ~36 ~120 ~121 dirt
setblock ~36 ~120 ~122 dirt
setblock ~36 ~120 ~123 dirt
setblock ~36 ~120 ~124 dirt
setblock ~36 ~120 ~125 dirt
setblock ~36 ~120 ~126 dirt
setblock ~36 ~120 ~127 dirt
setblock ~36 ~120 ~128 dirt
setblock ~36 ~120 ~129 dirt
setblock ~36 ~120 ~130 dirt
setblock ~36 ~120 ~131 dirt
setblock ~36 ~120 ~132 dirt
setblock ~36 ~121 ~72 dirt
setblock ~36 ~121 ~73 dirt
setblock ~36 ~121 ~74 dirt
setblock ~36 ~121 ~75 dirt
setblock ~36 ~121 ~76 dirt
setblock ~36 ~121 ~77 dirt
setblock ~36 ~121 ~78 dirt
setblock ~36 ~121 ~79 dirt
setblock ~36 ~121 ~80 dirt
setblock ~36 ~121 ~81 dirt
setblock ~36 ~121 ~82 dirt
setblock ~36 ~121 ~83 dirt
setblock ~36 ~121 ~84 dirt
setblock ~36 ~121 ~85 dirt
setblock ~36 ~121 ~86 dirt
setblock ~36 ~121 ~87 dirt
setblock ~36 ~121 ~88 dirt
setblock ~36 ~121 ~89 dirt
setblock ~36 ~121 ~90 dirt
setblock ~36 ~121 ~91 dirt
setblock ~36 ~121 ~92 dirt
setblock ~36 ~121 ~93 dirt
setblock ~36 ~121 ~94 dirt
setblock ~36 ~121 ~95 dirt
setblock ~36 ~121 ~96 dirt
setblock ~36 ~121 ~97 dirt
setblock ~36 ~121 ~98 dirt
setblock ~36 ~121 ~99 dirt
setblock ~36 ~121 ~100 dirt
setblock ~36 ~121 ~101 dirt
setblock ~36 ~121 ~102 dirt
setblock ~36 ~121 ~103 dirt
setblock ~36 ~121 ~104 dirt
setblock ~36 ~121 ~105 dirt
setblock ~36 ~121 ~106 dirt
setblock ~36 ~121 ~107 dirt
setblock ~36 ~121 ~108 dirt
setblock ~36 ~121 ~109 dirt
setblock ~36 ~121 ~110 dirt
setblock ~36 ~121 ~111 dirt
setblock ~36 ~121 ~112 dirt
setblock ~36 ~121 ~113 dirt
setblock ~36 ~121 ~114 dirt
setblock ~36 ~121 ~115 dirt
setblock ~36 ~121 ~116 dirt
setblock ~36 ~121 ~117 dirt
setblock ~36 ~121 ~118 dirt
setblock ~36 ~121 ~119 dirt
setblock ~36 ~121 ~120 dirt
setblock ~36 ~121 ~121 dirt
setblock ~36 ~121 ~122 dirt
setblock ~36 ~121 ~123 dirt
setblock ~36 ~121 ~124 dirt
setblock ~36 ~121 ~125 dirt
setblock ~36 ~121 ~126 dirt
setblock ~36 ~121 ~127 dirt
setblock ~36 ~121 ~128 dirt
setblock ~36 ~121 ~129 dirt
setblock ~36 ~121 ~130 dirt
setblock ~36 ~121 ~131 dirt
setblock ~36 ~121 ~132 dirt
setblock ~36 ~121 ~133 dirt
setblock ~36 ~122 ~72 dirt
setblock ~36 ~122 ~73 dirt
setblock ~36 ~122 ~74 dirt
setblock ~36 ~122 ~75 dirt
setblock ~36 ~122 ~76 dirt
setblock ~36 ~122 ~77 dirt
setblock ~36 ~122 ~78 dirt
setblock ~36 ~122 ~79 dirt
setblock ~36 ~122 ~80 dirt
setblock ~36 ~122 ~81 dirt
setblock ~36 ~122 ~82 dirt
setblock ~36 ~122 ~83 dirt
setblock ~36 ~122 ~84 dirt
setblock ~36 ~122 ~85 dirt
setblock ~36 ~122 ~86 dirt
setblock ~36 ~122 ~87 dirt
setblock ~36 ~122 ~88 dirt
setblock ~36 ~122 ~89 dirt
setblock ~36 ~122 ~90 dirt
setblock ~36 ~122 ~91 dirt
setblock ~36 ~122 ~92 dirt
setblock ~36 ~122 ~93 dirt
setblock ~36 ~122 ~94 dirt
setblock ~36 ~122 ~95 dirt
setblock ~36 ~122 ~96 dirt
setblock ~36 ~122 ~97 dirt
setblock ~36 ~122 ~98 dirt
setblock ~36 ~122 ~99 dirt
setblock ~36 ~122 ~100 dirt
setblock ~36 ~122 ~101 dirt
setblock ~36 ~122 ~102 dirt
setblock ~36 ~122 ~103 dirt
setblock ~36 ~122 ~104 dirt
setblock ~36 ~122 ~105 dirt
setblock ~36 ~122 ~106 dirt
setblock ~36 ~122 ~107 dirt
setblock ~36 ~122 ~108 dirt
setblock ~36 ~122 ~109 dirt
setblock ~36 ~122 ~110 dirt
setblock ~36 ~122 ~111 dirt
setblock ~36 ~122 ~112 dirt
setblock ~36 ~122 ~113 dirt
setblock ~36 ~122 ~114 dirt
setblock ~36 ~122 ~115 dirt
setblock ~36 ~122 ~116 dirt
setblock ~36 ~122 ~117 dirt
setblock ~36 ~122 ~118 dirt
setblock ~36 ~122 ~119 dirt
setblock ~36 ~122 ~120 dirt
setblock ~36 ~122 ~121 dirt
setblock ~36 ~122 ~122 dirt
setblock ~36 ~122 ~123 dirt
setblock ~36 ~122 ~124 dirt
setblock ~36 ~122 ~125 dirt
setblock ~36 ~122 ~126 dirt
setblock ~36 ~122 ~127 dirt
setblock ~36 ~122 ~128 dirt
setblock ~36 ~122 ~129 dirt
setblock ~36 ~122 ~130 dirt
setblock ~36 ~122 ~131 dirt
setblock ~36 ~122 ~132 dirt
setblock ~36 ~122 ~133 dirt
setblock ~36 ~123 ~72 dirt
setblock ~36 ~123 ~73 dirt
setblock ~36 ~123 ~74 dirt
setblock ~36 ~123 ~75 dirt
setblock ~36 ~123 ~76 dirt
setblock ~36 ~123 ~77 dirt
setblock ~36 ~123 ~78 dirt
setblock ~36 ~123 ~79 dirt
setblock ~36 ~123 ~80 dirt
setblock ~36 ~123 ~81 dirt
setblock ~36 ~123 ~82 dirt
setblock ~36 ~123 ~83 dirt
setblock ~36 ~123 ~84 dirt
setblock ~36 ~123 ~85 dirt
setblock ~36 ~123 ~86 dirt
setblock ~36 ~123 ~87 dirt
setblock ~36 ~123 ~88 dirt
setblock ~36 ~123 ~89 dirt
setblock ~36 ~123 ~90 dirt
setblock ~36 ~123 ~91 dirt
setblock ~36 ~123 ~92 dirt
setblock ~36 ~123 ~93 dirt
setblock ~36 ~123 ~94 grass_block
setblock ~36 ~123 ~95 grass_block
setblock ~36 ~123 ~96 grass_block
setblock ~36 ~123 ~97 grass_block
setblock ~36 ~123 ~98 grass_block
setblock ~36 ~123 ~99 grass_block
setblock ~36 ~123 ~100 grass_block
setblock ~36 ~123 ~101 grass_block
setblock ~36 ~123 ~102 grass_block
setblock ~36 ~123 ~103 dirt
setblock ~36 ~123 ~104 dirt
setblock ~36 ~123 ~105 dirt
setblock ~36 ~123 ~106 dirt
setblock ~36 ~123 ~107 dirt
setblock ~36 ~123 ~108 dirt
setblock ~36 ~123 ~109 dirt
setblock ~36 ~123 ~110 dirt
setblock ~36 ~123 ~111 dirt
setblock ~36 ~123 ~112 dirt
setblock ~36 ~123 ~113 dirt
setblock ~36 ~123 ~114 dirt
setblock ~36 ~123 ~115 dirt
setblock ~36 ~123 ~116 dirt
setblock ~36 ~123 ~117 dirt
setblock ~36 ~123 ~118 dirt
setblock ~36 ~123 ~119 dirt
setblock ~36 ~123 ~120 dirt
setblock ~36 ~123 ~121 dirt
setblock ~36 ~123 ~122 dirt
setblock ~36 ~123 ~123 dirt
setblock ~36 ~123 ~124 dirt
setblock ~36 ~123 ~125 dirt
setblock ~36 ~123 ~126 dirt
setblock ~36 ~123 ~127 dirt
setblock ~36 ~123 ~128 dirt
setblock ~36 ~123 ~129 dirt
setblock ~36 ~123 ~130 dirt
setblock ~36 ~123 ~131 dirt
setblock ~36 ~123 ~132 dirt
setblock ~36 ~123 ~133 dirt
setblock ~36 ~124 ~72 dirt
setblock ~36 ~124 ~73 dirt
setblock ~36 ~124 ~74 dirt
setblock ~36 ~124 ~75 dirt
setblock ~36 ~124 ~76 dirt
setblock ~36 ~124 ~77 dirt
setblock ~36 ~124 ~78 dirt
setblock ~36 ~124 ~79 dirt
setblock ~36 ~124 ~80 dirt
setblock ~36 ~124 ~81 dirt
setblock ~36 ~124 ~82 dirt
setblock ~36 ~124 ~83 dirt
setblock ~36 ~124 ~84 dirt
setblock ~36 ~124 ~85 dirt
setblock ~36 ~124 ~86 dirt
setblock ~36 ~124 ~87 grass_block
setblock ~36 ~124 ~88 grass_block
setblock ~36 ~124 ~89 grass_block
setblock ~36 ~124 ~90 grass_block
setblock ~36 ~124 ~91 grass_block
setblock ~36 ~124 ~92 grass_block
setblock ~36 ~124 ~93 grass_block
setblock ~36 ~124 ~97 fern
setblock ~36 ~124 ~98 short_grass
setblock ~36 ~124 ~99 short_grass
setblock ~36 ~124 ~103 grass_block
setblock ~36 ~124 ~104 grass_block
setblock ~36 ~124 ~105 grass_block
setblock ~36 ~124 ~106 grass_block
setblock ~36 ~124 ~107 grass_block
setblock ~36 ~124 ~108 dirt
setblock ~36 ~124 ~109 dirt
setblock ~36 ~124 ~110 dirt
setblock ~36 ~124 ~111 dirt
setblock ~36 ~124 ~112 dirt
setblock ~36 ~124 ~113 dirt
setblock ~36 ~124 ~114 dirt
setblock ~36 ~124 ~115 dirt
setblock ~36 ~124 ~116 dirt
setblock ~36 ~124 ~117 dirt
setblock ~36 ~124 ~118 grass_block
setblock ~36 ~124 ~119 grass_block
setblock ~36 ~124 ~120 grass_block
setblock ~36 ~124 ~121 grass_block
setblock ~36 ~124 ~122 grass_block
setblock ~36 ~124 ~123 grass_block
setblock ~36 ~124 ~124 grass_block
setblock ~36 ~124 ~125 grass_block
setblock ~36 ~124 ~126 grass_block
setblock ~36 ~124 ~127 grass_block
setblock ~36 ~124 ~128 grass_block
setblock ~36 ~124 ~129 grass_block
setblock ~36 ~124 ~130 grass_block
setblock ~36 ~124 ~131 grass_block
setblock ~36 ~124 ~132 grass_block
setblock ~36 ~124 ~133 grass_block
setblock ~36 ~125 ~72 grass_block
setblock ~36 ~125 ~73 grass_block
setblock ~36 ~125 ~74 grass_block
setblock ~36 ~125 ~75 dirt
setblock ~36 ~125 ~76 dirt
setblock ~36 ~125 ~77 dirt
setblock ~36 ~125 ~78 dirt
setblock ~36 ~125 ~79 dirt
setblock ~36 ~125 ~80 dirt
setblock ~36 ~125 ~81 dirt
setblock ~36 ~125 ~82 dirt
setblock ~36 ~125 ~83 grass_block
setblock ~36 ~125 ~84 grass_block
setblock ~36 ~125 ~85 grass_block
setblock ~36 ~125 ~86 grass_block
setblock ~36 ~125 ~89 short_grass
setblock ~36 ~125 ~107 poppy
setblock ~36 ~125 ~108 grass_block
setblock ~36 ~125 ~109 grass_block
setblock ~36 ~125 ~110 grass_block
setblock ~36 ~125 ~111 grass_block
setblock ~36 ~125 ~112 grass_block
setblock ~36 ~125 ~113 grass_block
setblock ~36 ~125 ~114 grass_block
setblock ~36 ~125 ~115 grass_block
setblock ~36 ~125 ~116 grass_block
setblock ~36 ~125 ~117 grass_block
setblock ~36 ~125 ~118 short_grass
setblock ~36 ~125 ~120 poppy
setblock ~36 ~125 ~122 poppy
setblock ~36 ~125 ~127 fern
setblock ~36 ~125 ~128 poppy
setblock ~36 ~125 ~129 short_grass
setblock ~36 ~126 ~74 short_grass
setblock ~36 ~126 ~75 grass_block
setblock ~36 ~126 ~76 grass_block
setblock ~36 ~126 ~77 grass_block
setblock ~36 ~126 ~78 grass_block
setblock ~36 ~126 ~79 grass_block
setblock ~36 ~126 ~80 grass_block
setblock ~36 ~126 ~81 grass_block
setblock ~36 ~126 ~82 grass_block
setblock ~36 ~126 ~83 poppy
setblock ~36 ~126 ~113 short_grass
setblock ~36 ~126 ~116 fern
setblock ~36 ~127 ~81 fern
setblock ~36 ~137 ~100 jungle_leaves[persistent=true]
setblock ~36 ~137 ~101 oak_leaves[persistent=true]
setblock ~36 ~137 ~102 jungle_leaves[persistent=true]
setblock ~36 ~137 ~104 oak_leaves[persistent=true]
setblock ~36 ~138 ~100 oak_leaves[persistent=true]
setblock ~36 ~138 ~101 oak_leaves[persistent=true]
setblock ~36 ~138 ~102 oak_leaves[persistent=true]
setblock ~36 ~138 ~103 jungle_leaves[persistent=true]
setblock ~36 ~138 ~104 jungle_leaves[persistent=true]
setblock ~36 ~139 ~100 oak_leaves[persistent=true]
setblock ~36 ~139 ~101 oak_leaves[persistent=true]
setblock ~36 ~139 ~102 oak_leaves[persistent=true]
setblock ~36 ~139 ~103 oak_leaves[persistent=true]
setblock ~36 ~140 ~100 oak_leaves[persistent=true]
setblock ~36 ~140 ~101 oak_leaves[persistent=true]
setblock ~36 ~140 ~102 oak_leaves[persistent=true]
setblock ~36 ~140 ~104 oak_leaves[persistent=true]
setblock ~37 ~98 ~100 dirt
setblock ~37 ~98 ~101 dirt
setblock ~37 ~99 ~100 dirt
setblock ~37 ~99 ~101 dirt
setblock ~37 ~99 ~102 dirt
setblock ~37 ~100 ~99 dirt
setblock ~37 ~100 ~100 dirt
setblock ~37 ~100 ~101 dirt
setblock ~37 ~100 ~102 dirt
setblock ~37 ~101 ~98 dirt
setblock ~37 ~101 ~99 dirt
setblock ~37 ~101 ~100 dirt
setblock ~37 ~101 ~101 dirt
setblock ~37 ~101 ~102 dirt
setblock ~37 ~102 ~97 dirt
setblock ~37 ~102 ~98 dirt
setblock ~37 ~102 ~99 dirt
setblock ~37 ~102 ~100 dirt
setblock ~37 ~102 ~101 dirt
setblock ~37 ~102 ~102 dirt
setblock ~37 ~103 ~97 dirt
setblock ~37 ~103 ~98 dirt
setblock ~37 ~103 ~99 dirt
setblock ~37 ~103 ~100 dirt
setblock ~37 ~103 ~101 dirt
setblock ~37 ~103 ~102 dirt
setblock ~37 ~103 ~103 dirt
setblock ~37 ~104 ~97 dirt
setblock ~37 ~104 ~98 dirt
setblock ~37 ~104 ~99 dirt
setblock ~37 ~104 ~100 dirt
setblock ~37 ~104 ~101 dirt
setblock ~37 ~104 ~102 dirt
setblock ~37 ~104 ~103 dirt
setblock ~37 ~104 ~104 dirt
setblock ~37 ~104 ~105 dirt
setblock ~37 ~105 ~89 dirt
setblock ~37 ~105 ~95 dirt
setblock ~37 ~105 ~96 dirt
setblock ~37 ~105 ~97 dirt
setblock ~37 ~105 ~98 dirt
setblock ~37 ~105 ~99 dirt
setblock ~37 ~105 ~100 dirt
setblock ~37 ~105 ~101 dirt
