setblock ~165 ~119 ~125 dirt
setblock ~165 ~119 ~126 dirt
setblock ~165 ~119 ~127 dirt
setblock ~165 ~119 ~128 dirt
setblock ~165 ~119 ~129 dirt
setblock ~165 ~119 ~130 dirt
setblock ~165 ~119 ~160 dirt
setblock ~165 ~120 ~69 dirt
setblock ~165 ~120 ~70 dirt
setblock ~165 ~120 ~71 dirt
setblock ~165 ~120 ~72 dirt
setblock ~165 ~120 ~73 dirt
setblock ~165 ~120 ~74 dirt
setblock ~165 ~120 ~75 dirt
setblock ~165 ~120 ~76 dirt
setblock ~165 ~120 ~77 dirt
setblock ~165 ~120 ~78 dirt
setblock ~165 ~120 ~79 dirt
setblock ~165 ~120 ~80 dirt
setblock ~165 ~120 ~81 dirt
setblock ~165 ~120 ~82 dirt
setblock ~165 ~120 ~83 dirt
setblock ~165 ~120 ~84 dirt
setblock ~165 ~120 ~85 dirt
setblock ~165 ~120 ~86 dirt
setblock ~165 ~120 ~87 dirt
setblock ~165 ~120 ~88 dirt
setblock ~165 ~120 ~89 dirt
setblock ~165 ~120 ~90 dirt
setblock ~165 ~120 ~91 dirt
setblock ~165 ~120 ~92 dirt
setblock ~165 ~120 ~93 dirt
setblock ~165 ~120 ~94 dirt
setblock ~165 ~120 ~95 dirt
setblock ~165 ~120 ~96 dirt
setblock ~165 ~120 ~97 dirt
setblock ~165 ~120 ~98 dirt
setblock ~165 ~120 ~99 dirt
setblock ~165 ~120 ~100 dirt
setblock ~165 ~120 ~101 dirt
setblock ~165 ~120 ~102 dirt
setblock ~165 ~120 ~103 dirt
setblock ~165 ~120 ~104 dirt
setblock ~165 ~120 ~105 dirt
setblock ~165 ~120 ~106 dirt
setblock ~165 ~120 ~107 dirt
setblock ~165 ~120 ~108 dirt
setblock ~165 ~120 ~109 dirt
setblock ~165 ~120 ~110 dirt
setblock ~165 ~120 ~111 dirt
setblock ~165 ~120 ~112 dirt
setblock ~165 ~120 ~113 dirt
setblock ~165 ~120 ~114 dirt
setblock ~165 ~120 ~115 dirt
setblock ~165 ~120 ~116 dirt
setblock ~165 ~120 ~117 dirt
setblock ~165 ~120 ~118 dirt
setblock ~165 ~120 ~119 dirt
setblock ~165 ~120 ~120 dirt
setblock ~165 ~120 ~121 dirt
setblock ~165 ~120 ~124 dirt
setblock ~165 ~120 ~125 dirt
setblock ~165 ~120 ~126 dirt
setblock ~165 ~120 ~127 dirt
setblock ~165 ~120 ~128 dirt
setblock ~165 ~120 ~129 dirt
setblock ~165 ~120 ~130 dirt
setblock ~165 ~120 ~160 dirt
setblock ~165 ~121 ~69 dirt
setblock ~165 ~121 ~70 dirt
setblock ~165 ~121 ~71 dirt
setblock ~165 ~121 ~72 dirt
setblock ~165 ~121 ~73 dirt
setblock ~165 ~121 ~74 dirt
setblock ~165 ~121 ~75 dirt
setblock ~165 ~121 ~76 dirt
setblock ~165 ~121 ~77 dirt
setblock ~165 ~121 ~78 dirt
setblock ~165 ~121 ~79 dirt
setblock ~165 ~121 ~80 dirt
setblock ~165 ~121 ~81 dirt
setblock ~165 ~121 ~82 dirt
setblock ~165 ~121 ~83 dirt
setblock ~165 ~121 ~84 dirt
setblock ~165 ~121 ~85 dirt
setblock ~165 ~121 ~86 dirt
setblock ~165 ~121 ~87 dirt
setblock ~165 ~121 ~88 dirt
setblock ~165 ~121 ~89 dirt
setblock ~165 ~121 ~90 dirt
setblock ~165 ~121 ~91 dirt
setblock ~165 ~121 ~92 dirt
setblock ~165 ~121 ~93 dirt
setblock ~165 ~121 ~94 dirt
setblock ~165 ~121 ~95 dirt
setblock ~165 ~121 ~96 dirt
setblock ~165 ~121 ~97 dirt
setblock ~165 ~121 ~98 dirt
setblock ~165 ~121 ~99 dirt
setblock ~165 ~121 ~100 dirt
setblock ~165 ~121 ~101 dirt
setblock ~165 ~121 ~102 dirt
setblock ~165 ~121 ~103 dirt
setblock ~165 ~121 ~104 dirt
setblock ~165 ~121 ~105 dirt
setblock ~165 ~121 ~106 dirt
setblock ~165 ~121 ~107 dirt
setblock ~165 ~121 ~108 dirt
setblock ~165 ~121 ~109 dirt
setblock ~165 ~121 ~110 dirt
setblock ~165 ~121 ~111 dirt
setblock ~165 ~121 ~112 dirt
setblock ~165 ~121 ~113 dirt
setblock ~165 ~121 ~114 dirt
setblock ~165 ~121 ~115 dirt
setblock ~165 ~121 ~116 dirt
setblock ~165 ~121 ~117 dirt
setblock ~165 ~121 ~118 dirt
setblock ~165 ~121 ~119 dirt
setblock ~165 ~121 ~120 dirt
setblock ~165 ~121 ~121 dirt
setblock ~165 ~121 ~122 dirt
setblock ~165 ~121 ~123 dirt
setblock ~165 ~121 ~124 dirt
setblock ~165 ~121 ~125 dirt
setblock ~165 ~121 ~126 dirt
setblock ~165 ~121 ~127 dirt
setblock ~165 ~121 ~128 dirt
setblock ~165 ~121 ~129 dirt
setblock ~165 ~121 ~130 dirt
setblock ~165 ~121 ~131 dirt
setblock ~165 ~121 ~160 dirt
setblock ~165 ~122 ~69 dirt
setblock ~165 ~122 ~70 dirt
setblock ~165 ~122 ~71 dirt
setblock ~165 ~122 ~72 dirt
setblock ~165 ~122 ~73 dirt
setblock ~165 ~122 ~74 dirt
setblock ~165 ~122 ~75 dirt
setblock ~165 ~122 ~76 dirt
setblock ~165 ~122 ~77 dirt
setblock ~165 ~122 ~78 dirt
setblock ~165 ~122 ~79 dirt
setblock ~165 ~122 ~80 dirt
setblock ~165 ~122 ~81 dirt
setblock ~165 ~122 ~82 dirt
setblock ~165 ~122 ~83 dirt
setblock ~165 ~122 ~84 dirt
setblock ~165 ~122 ~85 dirt
setblock ~165 ~122 ~86 dirt
setblock ~165 ~122 ~87 dirt
setblock ~165 ~122 ~88 dirt
setblock ~165 ~122 ~89 dirt
setblock ~165 ~122 ~90 dirt
setblock ~165 ~122 ~91 dirt
setblock ~165 ~122 ~92 dirt
setblock ~165 ~122 ~93 dirt
setblock ~165 ~122 ~94 dirt
setblock ~165 ~122 ~95 dirt
setblock ~165 ~122 ~96 dirt
setblock ~165 ~122 ~97 dirt
setblock ~165 ~122 ~98 dirt
setblock ~165 ~122 ~99 dirt
setblock ~165 ~122 ~100 dirt
setblock ~165 ~122 ~101 dirt
setblock ~165 ~122 ~102 dirt
setblock ~165 ~122 ~103 dirt
setblock ~165 ~122 ~104 dirt
setblock ~165 ~122 ~105 dirt
setblock ~165 ~122 ~106 dirt
setblock ~165 ~122 ~107 dirt
setblock ~165 ~122 ~108 dirt
setblock ~165 ~122 ~109 dirt
setblock ~165 ~122 ~110 dirt
setblock ~165 ~122 ~111 dirt
setblock ~165 ~122 ~112 dirt
setblock ~165 ~122 ~113 dirt
setblock ~165 ~122 ~114 dirt
setblock ~165 ~122 ~115 dirt
setblock ~165 ~122 ~116 dirt
setblock ~165 ~122 ~117 dirt
setblock ~165 ~122 ~118 dirt
setblock ~165 ~122 ~119 dirt
setblock ~165 ~122 ~120 dirt
setblock ~165 ~122 ~121 dirt
setblock ~165 ~122 ~122 dirt
setblock ~165 ~122 ~123 dirt
setblock ~165 ~122 ~124 dirt
setblock ~165 ~122 ~125 dirt
setblock ~165 ~122 ~126 dirt
setblock ~165 ~122 ~127 dirt
setblock ~165 ~122 ~128 dirt
setblock ~165 ~122 ~129 dirt
setblock ~165 ~122 ~130 dirt
setblock ~165 ~122 ~131 dirt
setblock ~165 ~122 ~160 dirt
setblock ~165 ~123 ~69 dirt
setblock ~165 ~123 ~70 dirt
setblock ~165 ~123 ~71 dirt
setblock ~165 ~123 ~72 dirt
setblock ~165 ~123 ~73 dirt
setblock ~165 ~123 ~74 dirt
setblock ~165 ~123 ~75 dirt
setblock ~165 ~123 ~76 dirt
setblock ~165 ~123 ~77 dirt
setblock ~165 ~123 ~78 dirt
setblock ~165 ~123 ~79 dirt
setblock ~165 ~123 ~80 dirt
setblock ~165 ~123 ~81 dirt
setblock ~165 ~123 ~82 dirt
setblock ~165 ~123 ~83 dirt
setblock ~165 ~123 ~84 dirt
setblock ~165 ~123 ~85 dirt
setblock ~165 ~123 ~86 dirt
setblock ~165 ~123 ~87 dirt
setblock ~165 ~123 ~88 dirt
setblock ~165 ~123 ~89 dirt
setblock ~165 ~123 ~90 dirt
setblock ~165 ~123 ~91 dirt
setblock ~165 ~123 ~92 dirt
setblock ~165 ~123 ~93 dirt
setblock ~165 ~123 ~94 dirt
setblock ~165 ~123 ~95 dirt
setblock ~165 ~123 ~96 dirt
setblock ~165 ~123 ~97 dirt
setblock ~165 ~123 ~98 dirt
setblock ~165 ~123 ~99 dirt
setblock ~165 ~123 ~100 dirt
setblock ~165 ~123 ~101 dirt
setblock ~165 ~123 ~102 dirt
setblock ~165 ~123 ~103 dirt
setblock ~165 ~123 ~104 dirt
setblock ~165 ~123 ~105 dirt
setblock ~165 ~123 ~106 dirt
setblock ~165 ~123 ~107 dirt
setblock ~165 ~123 ~108 dirt
setblock ~165 ~123 ~109 dirt
setblock ~165 ~123 ~110 dirt
setblock ~165 ~123 ~111 dirt
setblock ~165 ~123 ~112 dirt
setblock ~165 ~123 ~113 dirt
setblock ~165 ~123 ~114 dirt
setblock ~165 ~123 ~115 dirt
setblock ~165 ~123 ~116 dirt
setblock ~165 ~123 ~117 dirt
setblock ~165 ~123 ~118 dirt
setblock ~165 ~123 ~119 dirt
setblock ~165 ~123 ~120 grass_block
setblock ~165 ~123 ~121 dirt
setblock ~165 ~123 ~122 dirt
setblock ~165 ~123 ~123 dirt
setblock ~165 ~123 ~124 dirt
setblock ~165 ~123 ~125 dirt
setblock ~165 ~123 ~126 dirt
setblock ~165 ~123 ~127 dirt
setblock ~165 ~123 ~128 dirt
setblock ~165 ~123 ~129 dirt
setblock ~165 ~123 ~130 dirt
setblock ~165 ~123 ~131 dirt
setblock ~165 ~123 ~160 dirt
setblock ~165 ~124 ~69 grass_block
setblock ~165 ~124 ~70 grass_block
setblock ~165 ~124 ~71 grass_block
setblock ~165 ~124 ~72 dirt
setblock ~165 ~124 ~73 dirt
setblock ~165 ~124 ~74 dirt
setblock ~165 ~124 ~75 dirt
setblock ~165 ~124 ~76 dirt
setblock ~165 ~124 ~77 dirt
setblock ~165 ~124 ~78 dirt
setblock ~165 ~124 ~79 dirt
setblock ~165 ~124 ~80 dirt
setblock ~165 ~124 ~81 dirt
setblock ~165 ~124 ~82 dirt
setblock ~165 ~124 ~83 dirt
setblock ~165 ~124 ~84 dirt
setblock ~165 ~124 ~85 dirt
setblock ~165 ~124 ~86 dirt
setblock ~165 ~124 ~87 dirt
setblock ~165 ~124 ~88 dirt
setblock ~165 ~124 ~89 dirt
setblock ~165 ~124 ~90 dirt
setblock ~165 ~124 ~91 dirt
setblock ~165 ~124 ~92 dirt
setblock ~165 ~124 ~93 dirt
setblock ~165 ~124 ~94 dirt
setblock ~165 ~124 ~95 dirt
setblock ~165 ~124 ~96 dirt
setblock ~165 ~124 ~97 dirt
setblock ~165 ~124 ~98 dirt
setblock ~165 ~124 ~99 dirt
setblock ~165 ~124 ~100 dirt
setblock ~165 ~124 ~101 dirt
setblock ~165 ~124 ~102 dirt
setblock ~165 ~124 ~103 dirt
setblock ~165 ~124 ~104 dirt
setblock ~165 ~124 ~105 dirt
setblock ~165 ~124 ~106 dirt
setblock ~165 ~124 ~107 dirt
setblock ~165 ~124 ~108 dirt
setblock ~165 ~124 ~109 dirt
setblock ~165 ~124 ~110 dirt
setblock ~165 ~124 ~111 dirt
setblock ~165 ~124 ~112 dirt
setblock ~165 ~124 ~113 dirt
setblock ~165 ~124 ~114 dirt
setblock ~165 ~124 ~115 dirt
setblock ~165 ~124 ~116 dirt
setblock ~165 ~124 ~117 grass_block
setblock ~165 ~124 ~118 grass_block
setblock ~165 ~124 ~119 grass_block
setblock ~165 ~124 ~121 grass_block
setblock ~165 ~124 ~122 grass_block
setblock ~165 ~124 ~123 grass_block
setblock ~165 ~124 ~124 dirt
setblock ~165 ~124 ~125 dirt
setblock ~165 ~124 ~126 dirt
setblock ~165 ~124 ~127 dirt
setblock ~165 ~124 ~128 dirt
setblock ~165 ~124 ~129 dirt
setblock ~165 ~124 ~130 dirt
setblock ~165 ~124 ~131 dirt
setblock ~165 ~124 ~160 grass_block
setblock ~165 ~125 ~71 fern
setblock ~165 ~125 ~72 grass_block
setblock ~165 ~125 ~73 grass_block
setblock ~165 ~125 ~74 grass_block
setblock ~165 ~125 ~75 grass_block
setblock ~165 ~125 ~76 grass_block
setblock ~165 ~125 ~77 dirt
setblock ~165 ~125 ~78 dirt
setblock ~165 ~125 ~79 dirt
setblock ~165 ~125 ~80 dirt
setblock ~165 ~125 ~81 dirt
setblock ~165 ~125 ~82 dirt
setblock ~165 ~125 ~83 dirt
setblock ~165 ~125 ~84 dirt
setblock ~165 ~125 ~85 dirt
setblock ~165 ~125 ~86 dirt
setblock ~165 ~125 ~87 dirt
setblock ~165 ~125 ~88 dirt
setblock ~165 ~125 ~89 dirt
setblock ~165 ~125 ~90 grass_block
setblock ~165 ~125 ~91 grass_block
setblock ~165 ~125 ~92 grass_block
setblock ~165 ~125 ~93 grass_block
setblock ~165 ~125 ~94 grass_block
setblock ~165 ~125 ~95 grass_block
setblock ~165 ~125 ~96 grass_block
setblock ~165 ~125 ~97 grass_block
setblock ~165 ~125 ~98 grass_block
setblock ~165 ~125 ~99 grass_block
setblock ~165 ~125 ~100 grass_block
setblock ~165 ~125 ~101 dirt
setblock ~165 ~125 ~102 dirt
setblock ~165 ~125 ~103 dirt
setblock ~165 ~125 ~104 dirt
setblock ~165 ~125 ~105 dirt
setblock ~165 ~125 ~106 dirt
setblock ~165 ~125 ~107 dirt
setblock ~165 ~125 ~108 dirt
setblock ~165 ~125 ~109 dirt
setblock ~165 ~125 ~110 dirt
setblock ~165 ~125 ~111 dirt
setblock ~165 ~125 ~112 dirt
setblock ~165 ~125 ~113 dirt
setblock ~165 ~125 ~114 dirt
setblock ~165 ~125 ~115 grass_block
setblock ~165 ~125 ~116 grass_block
setblock ~165 ~125 ~119 short_grass
setblock ~165 ~125 ~121 short_grass
setblock ~165 ~125 ~124 grass_block
setblock ~165 ~125 ~125 grass_block
setblock ~165 ~125 ~126 grass_block
setblock ~165 ~125 ~127 dirt
setblock ~165 ~125 ~128 dirt
setblock ~165 ~125 ~129 dirt
setblock ~165 ~125 ~130 dirt
setblock ~165 ~125 ~131 dirt
setblock ~165 ~126 ~73 short_grass
setblock ~165 ~126 ~76 short_grass
setblock ~165 ~126 ~77 grass_block
setblock ~165 ~126 ~78 grass_block
setblock ~165 ~126 ~79 grass_block
setblock ~165 ~126 ~80 grass_block
setblock ~165 ~126 ~81 grass_block
setblock ~165 ~126 ~82 grass_block
setblock ~165 ~126 ~83 grass_block
setblock ~165 ~126 ~84 grass_block
setblock ~165 ~126 ~85 grass_block
setblock ~165 ~126 ~86 grass_block
setblock ~165 ~126 ~87 grass_block
setblock ~165 ~126 ~88 grass_block
setblock ~165 ~126 ~89 grass_block
setblock ~165 ~126 ~92 poppy
setblock ~165 ~126 ~94 short_grass
setblock ~165 ~126 ~99 short_grass
setblock ~165 ~126 ~100 short_grass
setblock ~165 ~126 ~101 grass_block
setblock ~165 ~126 ~102 grass_block
setblock ~165 ~126 ~103 grass_block
setblock ~165 ~126 ~104 grass_block
setblock ~165 ~126 ~105 grass_block
setblock ~165 ~126 ~106 dirt
setblock ~165 ~126 ~107 dirt
setblock ~165 ~126 ~108 dirt
setblock ~165 ~126 ~109 dirt
setblock ~165 ~126 ~110 dirt
setblock ~165 ~126 ~111 dirt
setblock ~165 ~126 ~112 grass_block
setblock ~165 ~126 ~113 grass_block
setblock ~165 ~126 ~114 grass_block
setblock ~165 ~126 ~124 short_grass
setblock ~165 ~126 ~126 short_grass
setblock ~165 ~126 ~127 grass_block
setblock ~165 ~126 ~128 grass_block
setblock ~165 ~126 ~129 grass_block
setblock ~165 ~126 ~130 grass_block
setblock ~165 ~126 ~131 grass_block
setblock ~165 ~127 ~77 short_grass
setblock ~165 ~127 ~78 short_grass
setblock ~165 ~127 ~79 fern
setblock ~165 ~127 ~82 short_grass
setblock ~165 ~127 ~103 short_grass
setblock ~165 ~127 ~106 grass_block
setblock ~165 ~127 ~107 grass_block
setblock ~165 ~127 ~108 grass_block
setblock ~165 ~127 ~109 grass_block
setblock ~165 ~127 ~110 grass_block
setblock ~165 ~127 ~111 grass_block
setblock ~165 ~127 ~112 short_grass
setblock ~165 ~127 ~128 short_grass
setblock ~165 ~128 ~106 short_grass
setblock ~165 ~128 ~108 short_grass
setblock ~165 ~128 ~110 fern
setblock ~166 ~102 ~93 dirt
setblock ~166 ~102 ~96 dirt
setblock ~166 ~103 ~93 dirt
setblock ~166 ~103 ~94 dirt
setblock ~166 ~103 ~95 dirt
setblock ~166 ~103 ~96 dirt
setblock ~166 ~103 ~97 dirt
setblock ~166 ~104 ~92 dirt
setblock ~166 ~104 ~93 dirt
setblock ~166 ~104 ~94 dirt
setblock ~166 ~104 ~95 dirt
setblock ~166 ~104 ~96 dirt
setblock ~166 ~104 ~97 dirt
setblock ~166 ~105 ~89 dirt
setblock ~166 ~105 ~90 dirt
setblock ~166 ~105 ~92 dirt
setblock ~166 ~105 ~93 dirt
setblock ~166 ~105 ~94 dirt
setblock ~166 ~105 ~95 dirt
setblock ~166 ~105 ~96 dirt
setblock ~166 ~105 ~97 dirt
setblock ~166 ~105 ~98 dirt
setblock ~166 ~106 ~88 dirt
setblock ~166 ~106 ~89 dirt
setblock ~166 ~106 ~90 dirt
setblock ~166 ~106 ~91 dirt
setblock ~166 ~106 ~92 dirt
setblock ~166 ~106 ~93 dirt
setblock ~166 ~106 ~94 dirt
setblock ~166 ~106 ~95 dirt
setblock ~166 ~106 ~96 dirt
setblock ~166 ~106 ~97 dirt
setblock ~166 ~106 ~98 dirt
setblock ~166 ~106 ~99 dirt
setblock ~166 ~107 ~87 dirt
setblock ~166 ~107 ~88 dirt
setblock ~166 ~107 ~89 dirt
setblock ~166 ~107 ~90 dirt
setblock ~166 ~107 ~91 dirt
setblock ~166 ~107 ~92 dirt
setblock ~166 ~107 ~93 dirt
setblock ~166 ~107 ~94 dirt
setblock ~166 ~107 ~95 dirt
setblock ~166 ~107 ~96 dirt
setblock ~166 ~107 ~97 dirt
setblock ~166 ~107 ~98 dirt
setblock ~166 ~107 ~99 dirt
setblock ~166 ~108 ~87 dirt
setblock ~166 ~108 ~88 dirt
setblock ~166 ~108 ~89 dirt
setblock ~166 ~108 ~90 dirt
setblock ~166 ~108 ~91 dirt
setblock ~166 ~108 ~92 dirt
setblock ~166 ~108 ~93 dirt
setblock ~166 ~108 ~94 dirt
setblock ~166 ~108 ~95 dirt
setblock ~166 ~108 ~96 dirt
setblock ~166 ~108 ~97 dirt
setblock ~166 ~108 ~98 dirt
setblock ~166 ~108 ~99 dirt
setblock ~166 ~108 ~112 dirt
setblock ~166 ~109 ~87 dirt
setblock ~166 ~109 ~88 dirt
setblock ~166 ~109 ~89 dirt
setblock ~166 ~109 ~90 dirt
setblock ~166 ~109 ~91 dirt
setblock ~166 ~109 ~92 dirt
setblock ~166 ~109 ~93 dirt
setblock ~166 ~109 ~94 dirt
setblock ~166 ~109 ~95 dirt
setblock ~166 ~109 ~96 dirt
setblock ~166 ~109 ~97 dirt
setblock ~166 ~109 ~98 dirt
setblock ~166 ~109 ~99 dirt
setblock ~166 ~109 ~100 dirt
setblock ~166 ~109 ~112 dirt
setblock ~166 ~110 ~86 dirt
setblock ~166 ~110 ~87 dirt
setblock ~166 ~110 ~88 dirt
setblock ~166 ~110 ~89 dirt
setblock ~166 ~110 ~90 dirt
setblock ~166 ~110 ~91 dirt
setblock ~166 ~110 ~92 dirt
setblock ~166 ~110 ~93 dirt
setblock ~166 ~110 ~94 dirt
setblock ~166 ~110 ~95 dirt
setblock ~166 ~110 ~96 dirt
setblock ~166 ~110 ~97 dirt
setblock ~166 ~110 ~98 dirt
setblock ~166 ~110 ~99 dirt
setblock ~166 ~110 ~100 dirt
setblock ~166 ~110 ~101 dirt
setblock ~166 ~110 ~111 dirt
setblock ~166 ~110 ~112 dirt
setblock ~166 ~111 ~86 dirt
setblock ~166 ~111 ~87 dirt
setblock ~166 ~111 ~88 dirt
setblock ~166 ~111 ~89 dirt
setblock ~166 ~111 ~90 dirt
setblock ~166 ~111 ~91 dirt
setblock ~166 ~111 ~92 dirt
setblock ~166 ~111 ~93 dirt
setblock ~166 ~111 ~94 dirt
setblock ~166 ~111 ~95 dirt
setblock ~166 ~111 ~96 dirt
setblock ~166 ~111 ~97 dirt
setblock ~166 ~111 ~98 dirt
setblock ~166 ~111 ~99 dirt
setblock ~166 ~111 ~100 dirt
setblock ~166 ~111 ~101 dirt
setblock ~166 ~111 ~110 dirt
setblock ~166 ~111 ~111 dirt
setblock ~166 ~111 ~112 dirt
setblock ~166 ~111 ~113 dirt
setblock ~166 ~112 ~85 dirt
setblock ~166 ~112 ~86 dirt
setblock ~166 ~112 ~87 dirt
setblock ~166 ~112 ~88 dirt
setblock ~166 ~112 ~89 dirt
setblock ~166 ~112 ~90 dirt
setblock ~166 ~112 ~91 dirt
setblock ~166 ~112 ~92 dirt
setblock ~166 ~112 ~93 dirt
setblock ~166 ~112 ~94 dirt
setblock ~166 ~112 ~95 dirt
setblock ~166 ~112 ~96 dirt
setblock ~166 ~112 ~97 dirt
setblock ~166 ~112 ~98 dirt
setblock ~166 ~112 ~99 dirt
setblock ~166 ~112 ~100 dirt
setblock ~166 ~112 ~101 dirt
setblock ~166 ~112 ~109 dirt
setblock ~166 ~112 ~110 dirt
setblock ~166 ~112 ~111 dirt
setblock ~166 ~112 ~112 dirt
setblock ~166 ~112 ~113 dirt
setblock ~166 ~113 ~81 dirt
setblock ~166 ~113 ~85 dirt
setblock ~166 ~113 ~86 dirt
setblock ~166 ~113 ~87 dirt
setblock ~166 ~113 ~88 dirt
setblock ~166 ~113 ~89 dirt
setblock ~166 ~113 ~90 dirt
setblock ~166 ~113 ~91 dirt
setblock ~166 ~113 ~92 dirt
setblock ~166 ~113 ~93 dirt
setblock ~166 ~113 ~94 dirt
setblock ~166 ~113 ~95 dirt
setblock ~166 ~113 ~96 dirt
setblock ~166 ~113 ~97 dirt
setblock ~166 ~113 ~98 dirt
setblock ~166 ~113 ~99 dirt
setblock ~166 ~113 ~100 dirt
setblock ~166 ~113 ~101 dirt
setblock ~166 ~113 ~102 dirt
setblock ~166 ~113 ~108 dirt
setblock ~166 ~113 ~109 dirt
setblock ~166 ~113 ~110 dirt
setblock ~166 ~113 ~111 dirt
setblock ~166 ~113 ~112 dirt
setblock ~166 ~113 ~113 dirt
setblock ~166 ~113 ~114 dirt
setblock ~166 ~114 ~73 dirt
setblock ~166 ~114 ~74 dirt
setblock ~166 ~114 ~81 dirt
setblock ~166 ~114 ~82 dirt
setblock ~166 ~114 ~83 dirt
setblock ~166 ~114 ~85 dirt
setblock ~166 ~114 ~86 dirt
setblock ~166 ~114 ~87 dirt
setblock ~166 ~114 ~88 dirt
setblock ~166 ~114 ~89 dirt
setblock ~166 ~114 ~90 dirt
setblock ~166 ~114 ~91 dirt
setblock ~166 ~114 ~92 dirt
setblock ~166 ~114 ~93 dirt
setblock ~166 ~114 ~94 dirt
setblock ~166 ~114 ~95 dirt
setblock ~166 ~114 ~96 dirt
setblock ~166 ~114 ~97 dirt
setblock ~166 ~114 ~98 dirt
setblock ~166 ~114 ~99 dirt
setblock ~166 ~114 ~100 dirt
setblock ~166 ~114 ~101 dirt
setblock ~166 ~114 ~102 dirt
setblock ~166 ~114 ~103 dirt
setblock ~166 ~114 ~108 dirt
setblock ~166 ~114 ~109 dirt
setblock ~166 ~114 ~110 dirt
setblock ~166 ~114 ~111 dirt
setblock ~166 ~114 ~112 dirt
setblock ~166 ~114 ~113 dirt
setblock ~166 ~114 ~114 dirt
setblock ~166 ~114 ~115 dirt
setblock ~166 ~115 ~73 dirt
setblock ~166 ~115 ~74 dirt
setblock ~166 ~115 ~80 dirt
setblock ~166 ~115 ~81 dirt
setblock ~166 ~115 ~82 dirt
setblock ~166 ~115 ~83 dirt
setblock ~166 ~115 ~84 dirt
setblock ~166 ~115 ~85 dirt
setblock ~166 ~115 ~86 dirt
setblock ~166 ~115 ~87 dirt
setblock ~166 ~115 ~88 dirt
setblock ~166 ~115 ~89 dirt
setblock ~166 ~115 ~90 dirt
setblock ~166 ~115 ~91 dirt
setblock ~166 ~115 ~92 dirt
setblock ~166 ~115 ~93 dirt
setblock ~166 ~115 ~94 dirt
setblock ~166 ~115 ~95 dirt
setblock ~166 ~115 ~96 dirt
setblock ~166 ~115 ~97 dirt
setblock ~166 ~115 ~98 dirt
setblock ~166 ~115 ~99 dirt
setblock ~166 ~115 ~100 dirt
setblock ~166 ~115 ~101 dirt
setblock ~166 ~115 ~102 dirt
setblock ~166 ~115 ~103 dirt
setblock ~166 ~115 ~108 dirt
setblock ~166 ~115 ~109 dirt
setblock ~166 ~115 ~110 dirt
setblock ~166 ~115 ~111 dirt
setblock ~166 ~115 ~112 dirt
setblock ~166 ~115 ~113 dirt
setblock ~166 ~115 ~114 dirt
setblock ~166 ~115 ~115 dirt
setblock ~166 ~116 ~72 dirt
setblock ~166 ~116 ~73 dirt
setblock ~166 ~116 ~74 dirt
setblock ~166 ~116 ~79 dirt
setblock ~166 ~116 ~80 dirt
setblock ~166 ~116 ~81 dirt
setblock ~166 ~116 ~82 dirt
setblock ~166 ~116 ~83 dirt
setblock ~166 ~116 ~84 dirt
setblock ~166 ~116 ~85 dirt
setblock ~166 ~116 ~86 dirt
setblock ~166 ~116 ~87 dirt
setblock ~166 ~116 ~88 dirt
setblock ~166 ~116 ~89 dirt
setblock ~166 ~116 ~90 dirt
setblock ~166 ~116 ~91 dirt
setblock ~166 ~116 ~92 dirt
setblock ~166 ~116 ~93 dirt
setblock ~166 ~116 ~94 dirt
setblock ~166 ~116 ~95 dirt
setblock ~166 ~116 ~96 dirt
setblock ~166 ~116 ~97 dirt
setblock ~166 ~116 ~98 dirt
setblock ~166 ~116 ~99 dirt
setblock ~166 ~116 ~100 dirt
setblock ~166 ~116 ~101 dirt
setblock ~166 ~116 ~102 dirt
setblock ~166 ~116 ~103 dirt
setblock ~166 ~116 ~104 dirt
setblock ~166 ~116 ~107 dirt
setblock ~166 ~116 ~108 dirt
setblock ~166 ~116 ~109 dirt
setblock ~166 ~116 ~110 dirt
setblock ~166 ~116 ~111 dirt
setblock ~166 ~116 ~112 dirt
setblock ~166 ~116 ~113 dirt
setblock ~166 ~116 ~114 dirt
setblock ~166 ~116 ~115 dirt
setblock ~166 ~116 ~116 dirt
setblock ~166 ~116 ~127 dirt
setblock ~166 ~117 ~71 dirt
setblock ~166 ~117 ~72 dirt
setblock ~166 ~117 ~73 dirt
setblock ~166 ~117 ~74 dirt
setblock ~166 ~117 ~75 dirt
setblock ~166 ~117 ~78 dirt
setblock ~166 ~117 ~79 dirt
setblock ~166 ~117 ~80 dirt
setblock ~166 ~117 ~81 dirt
setblock ~166 ~117 ~82 dirt
setblock ~166 ~117 ~83 dirt
setblock ~166 ~117 ~84 dirt
setblock ~166 ~117 ~85 dirt
setblock ~166 ~117 ~86 dirt
setblock ~166 ~117 ~87 dirt
setblock ~166 ~117 ~88 dirt
setblock ~166 ~117 ~89 dirt
setblock ~166 ~117 ~90 dirt
setblock ~166 ~117 ~91 dirt
setblock ~166 ~117 ~92 dirt
setblock ~166 ~117 ~93 dirt
setblock ~166 ~117 ~94 dirt
setblock ~166 ~117 ~95 dirt
setblock ~166 ~117 ~96 dirt
setblock ~166 ~117 ~97 dirt
setblock ~166 ~117 ~98 dirt
setblock ~166 ~117 ~99 dirt
setblock ~166 ~117 ~100 dirt
setblock ~166 ~117 ~101 dirt
setblock ~166 ~117 ~102 dirt
setblock ~166 ~117 ~103 dirt
setblock ~166 ~117 ~104 dirt
setblock ~166 ~117 ~105 dirt
setblock ~166 ~117 ~107 dirt
setblock ~166 ~117 ~108 dirt
setblock ~166 ~117 ~109 dirt
setblock ~166 ~117 ~110 dirt
setblock ~166 ~117 ~111 dirt
setblock ~166 ~117 ~112 dirt
setblock ~166 ~117 ~113 dirt
setblock ~166 ~117 ~114 dirt
setblock ~166 ~117 ~115 dirt
setblock ~166 ~117 ~116 dirt
setblock ~166 ~117 ~127 dirt
setblock ~166 ~118 ~71 dirt
setblock ~166 ~118 ~72 dirt
setblock ~166 ~118 ~73 dirt
setblock ~166 ~118 ~74 dirt
setblock ~166 ~118 ~75 dirt
setblock ~166 ~118 ~76 dirt
setblock ~166 ~118 ~78 dirt
setblock ~166 ~118 ~79 dirt
setblock ~166 ~118 ~80 dirt
setblock ~166 ~118 ~81 dirt
setblock ~166 ~118 ~82 dirt
setblock ~166 ~118 ~83 dirt
setblock ~166 ~118 ~84 dirt
setblock ~166 ~118 ~85 dirt
setblock ~166 ~118 ~86 dirt
setblock ~166 ~118 ~87 dirt
setblock ~166 ~118 ~88 dirt
setblock ~166 ~118 ~89 dirt
setblock ~166 ~118 ~90 dirt
setblock ~166 ~118 ~91 dirt
setblock ~166 ~118 ~92 dirt
setblock ~166 ~118 ~93 dirt
setblock ~166 ~118 ~94 dirt
setblock ~166 ~118 ~95 dirt
setblock ~166 ~118 ~96 dirt
setblock ~166 ~118 ~97 dirt
setblock ~166 ~118 ~98 dirt
setblock ~166 ~118 ~99 dirt
setblock ~166 ~118 ~100 dirt
setblock ~166 ~118 ~101 dirt
setblock ~166 ~118 ~102 dirt
setblock ~166 ~118 ~103 dirt
setblock ~166 ~118 ~104 dirt
setblock ~166 ~118 ~105 dirt
setblock ~166 ~118 ~106 dirt
setblock ~166 ~118 ~107 dirt
setblock ~166 ~118 ~108 dirt
setblock ~166 ~118 ~109 dirt
setblock ~166 ~118 ~110 dirt
setblock ~166 ~118 ~111 dirt
setblock ~166 ~118 ~112 dirt
setblock ~166 ~118 ~113 dirt
setblock ~166 ~118 ~114 dirt
setblock ~166 ~118 ~115 dirt
setblock ~166 ~118 ~116 dirt
setblock ~166 ~118 ~117 dirt
setblock ~166 ~118 ~126 dirt
setblock ~166 ~118 ~127 dirt
setblock ~166 ~118 ~128 dirt
setblock ~166 ~118 ~160 dirt
setblock ~166 ~119 ~70 dirt
setblock ~166 ~119 ~71 dirt
setblock ~166 ~119 ~72 dirt
setblock ~166 ~119 ~73 dirt
setblock ~166 ~119 ~74 dirt
setblock ~166 ~119 ~75 dirt
setblock ~166 ~119 ~76 dirt
setblock ~166 ~119 ~78 dirt
setblock ~166 ~119 ~79 dirt
setblock ~166 ~119 ~80 dirt
setblock ~166 ~119 ~81 dirt
setblock ~166 ~119 ~82 dirt
setblock ~166 ~119 ~83 dirt
setblock ~166 ~119 ~84 dirt
setblock ~166 ~119 ~85 dirt
setblock ~166 ~119 ~86 dirt
setblock ~166 ~119 ~87 dirt
setblock ~166 ~119 ~88 dirt
setblock ~166 ~119 ~89 dirt
setblock ~166 ~119 ~90 dirt
setblock ~166 ~119 ~91 dirt
setblock ~166 ~119 ~92 dirt
setblock ~166 ~119 ~93 dirt
setblock ~166 ~119 ~94 dirt
setblock ~166 ~119 ~95 dirt
setblock ~166 ~119 ~96 dirt
setblock ~166 ~119 ~97 dirt
setblock ~166 ~119 ~98 dirt
setblock ~166 ~119 ~99 dirt
setblock ~166 ~119 ~100 dirt
setblock ~166 ~119 ~101 dirt
setblock ~166 ~119 ~102 dirt
setblock ~166 ~119 ~103 dirt
setblock ~166 ~119 ~104 dirt
setblock ~166 ~119 ~105 dirt
setblock ~166 ~119 ~106 dirt
setblock ~166 ~119 ~107 dirt
setblock ~166 ~119 ~108 dirt
setblock ~166 ~119 ~109 dirt
setblock ~166 ~119 ~110 dirt
setblock ~166 ~119 ~111 dirt
setblock ~166 ~119 ~112 dirt
setblock ~166 ~119 ~113 dirt
setblock ~166 ~119 ~114 dirt
setblock ~166 ~119 ~115 dirt
setblock ~166 ~119 ~116 dirt
setblock ~166 ~119 ~117 dirt
setblock ~166 ~119 ~118 dirt
setblock ~166 ~119 ~119 dirt
setblock ~166 ~119 ~126 dirt
setblock ~166 ~119 ~127 dirt
setblock ~166 ~119 ~128 dirt
setblock ~166 ~119 ~159 dirt
setblock ~166 ~119 ~160 dirt
setblock ~166 ~119 ~161 dirt
setblock ~166 ~120 ~70 dirt
setblock ~166 ~120 ~71 dirt
setblock ~166 ~120 ~72 dirt
setblock ~166 ~120 ~73 dirt
setblock ~166 ~120 ~74 dirt
setblock ~166 ~120 ~75 dirt
setblock ~166 ~120 ~76 dirt
setblock ~166 ~120 ~77 dirt
setblock ~166 ~120 ~78 dirt
setblock ~166 ~120 ~79 dirt
setblock ~166 ~120 ~80 dirt
setblock ~166 ~120 ~81 dirt
setblock ~166 ~120 ~82 dirt
setblock ~166 ~120 ~83 dirt
setblock ~166 ~120 ~84 dirt
setblock ~166 ~120 ~85 dirt
setblock ~166 ~120 ~86 dirt
setblock ~166 ~120 ~87 dirt
setblock ~166 ~120 ~88 dirt
setblock ~166 ~120 ~89 dirt
setblock ~166 ~120 ~90 dirt
setblock ~166 ~120 ~91 dirt
setblock ~166 ~120 ~92 dirt
setblock ~166 ~120 ~93 dirt
setblock ~166 ~120 ~94 dirt
setblock ~166 ~120 ~95 dirt
setblock ~166 ~120 ~96 dirt
setblock ~166 ~120 ~97 dirt
setblock ~166 ~120 ~98 dirt
setblock ~166 ~120 ~99 dirt
setblock ~166 ~120 ~100 dirt
setblock ~166 ~120 ~101 dirt
setblock ~166 ~120 ~102 dirt
setblock ~166 ~120 ~103 dirt
setblock ~166 ~120 ~104 dirt
setblock ~166 ~120 ~105 dirt
setblock ~166 ~120 ~106 dirt
setblock ~166 ~120 ~107 dirt
setblock ~166 ~120 ~108 dirt
setblock ~166 ~120 ~109 dirt
setblock ~166 ~120 ~110 dirt
setblock ~166 ~120 ~111 dirt
setblock ~166 ~120 ~112 dirt
setblock ~166 ~120 ~113 dirt
setblock ~166 ~120 ~114 dirt
setblock ~166 ~120 ~115 dirt
setblock ~166 ~120 ~116 dirt
setblock ~166 ~120 ~117 dirt
setblock ~166 ~120 ~118 dirt
setblock ~166 ~120 ~119 dirt
setblock ~166 ~120 ~120 dirt
setblock ~166 ~120 ~125 dirt
setblock ~166 ~120 ~126 dirt
setblock ~166 ~120 ~127 dirt
setblock ~166 ~120 ~128 dirt
setblock ~166 ~120 ~159 dirt
setblock ~166 ~120 ~160 dirt
setblock ~166 ~120 ~161 dirt
setblock ~166 ~121 ~70 dirt
setblock ~166 ~121 ~71 dirt
setblock ~166 ~121 ~72 dirt
setblock ~166 ~121 ~73 dirt
setblock ~166 ~121 ~74 dirt
setblock ~166 ~121 ~75 dirt
setblock ~166 ~121 ~76 dirt
setblock ~166 ~121 ~77 dirt
setblock ~166 ~121 ~78 dirt
setblock ~166 ~121 ~79 dirt
setblock ~166 ~121 ~80 dirt
setblock ~166 ~121 ~81 dirt
setblock ~166 ~121 ~82 dirt
setblock ~166 ~121 ~83 dirt
setblock ~166 ~121 ~84 dirt
setblock ~166 ~121 ~85 dirt
setblock ~166 ~121 ~86 dirt
setblock ~166 ~121 ~87 dirt
setblock ~166 ~121 ~88 dirt
setblock ~166 ~121 ~89 dirt
setblock ~166 ~121 ~90 dirt
setblock ~166 ~121 ~91 dirt
setblock ~166 ~121 ~92 dirt
setblock ~166 ~121 ~93 dirt
setblock ~166 ~121 ~94 dirt
setblock ~166 ~121 ~95 dirt
setblock ~166 ~121 ~96 dirt
setblock ~166 ~121 ~97 dirt
setblock ~166 ~121 ~98 dirt
setblock ~166 ~121 ~99 dirt
setblock ~166 ~121 ~100 dirt
setblock ~166 ~121 ~101 dirt
setblock ~166 ~121 ~102 dirt
setblock ~166 ~121 ~103 dirt
setblock ~166 ~121 ~104 dirt
setblock ~166 ~121 ~105 dirt
setblock ~166 ~121 ~106 dirt
setblock ~166 ~121 ~107 dirt
setblock ~166 ~121 ~108 dirt
setblock ~166 ~121 ~109 dirt
setblock ~166 ~121 ~110 dirt
setblock ~166 ~121 ~111 dirt
setblock ~166 ~121 ~112 dirt
setblock ~166 ~121 ~113 dirt
setblock ~166 ~121 ~114 dirt
setblock ~166 ~121 ~115 dirt
setblock ~166 ~121 ~116 dirt
setblock ~166 ~121 ~117 dirt
setblock ~166 ~121 ~118 dirt
setblock ~166 ~121 ~119 dirt
setblock ~166 ~121 ~120 dirt
setblock ~166 ~121 ~124 dirt
setblock ~166 ~121 ~125 dirt
setblock ~166 ~121 ~126 dirt
setblock ~166 ~121 ~127 dirt
setblock ~166 ~121 ~128 dirt
setblock ~166 ~121 ~130 dirt
setblock ~166 ~121 ~159 dirt
setblock ~166 ~121 ~160 dirt
setblock ~166 ~121 ~161 dirt
setblock ~166 ~122 ~70 dirt
setblock ~166 ~122 ~71 dirt
setblock ~166 ~122 ~72 dirt
setblock ~166 ~122 ~73 dirt
setblock ~166 ~122 ~74 dirt
setblock ~166 ~122 ~75 dirt
setblock ~166 ~122 ~76 dirt
setblock ~166 ~122 ~77 dirt
setblock ~166 ~122 ~78 dirt
setblock ~166 ~122 ~79 dirt
setblock ~166 ~122 ~80 dirt
setblock ~166 ~122 ~81 dirt
setblock ~166 ~122 ~82 dirt
setblock ~166 ~122 ~83 dirt
setblock ~166 ~122 ~84 dirt
setblock ~166 ~122 ~85 dirt
setblock ~166 ~122 ~86 dirt
setblock ~166 ~122 ~87 dirt
setblock ~166 ~122 ~88 dirt
setblock ~166 ~122 ~89 dirt
setblock ~166 ~122 ~90 dirt
setblock ~166 ~122 ~91 dirt
setblock ~166 ~122 ~92 dirt
setblock ~166 ~122 ~93 dirt
setblock ~166 ~122 ~94 dirt
setblock ~166 ~122 ~95 dirt
setblock ~166 ~122 ~96 dirt
setblock ~166 ~122 ~97 dirt
setblock ~166 ~122 ~98 dirt
setblock ~166 ~122 ~99 dirt
setblock ~166 ~122 ~100 dirt
setblock ~166 ~122 ~101 dirt
setblock ~166 ~122 ~102 dirt
setblock ~166 ~122 ~103 dirt
setblock ~166 ~122 ~104 dirt
setblock ~166 ~122 ~105 dirt
setblock ~166 ~122 ~106 dirt
setblock ~166 ~122 ~107 dirt
setblock ~166 ~122 ~108 dirt
setblock ~166 ~122 ~109 dirt
setblock ~166 ~122 ~110 dirt
setblock ~166 ~122 ~111 dirt
setblock ~166 ~122 ~112 dirt
setblock ~166 ~122 ~113 dirt
setblock ~166 ~122 ~114 dirt
setblock ~166 ~122 ~115 dirt
setblock ~166 ~122 ~116 dirt
setblock ~166 ~122 ~117 dirt
setblock ~166 ~122 ~118 dirt
setblock ~166 ~122 ~119 dirt
setblock ~166 ~122 ~120 dirt
setblock ~166 ~122 ~124 dirt
setblock ~166 ~122 ~125 dirt
setblock ~166 ~122 ~126 dirt
setblock ~166 ~122 ~127 dirt
setblock ~166 ~122 ~128 dirt
setblock ~166 ~122 ~130 dirt
setblock ~166 ~122 ~159 dirt
setblock ~166 ~122 ~160 dirt
setblock ~166 ~122 ~161 dirt
setblock ~166 ~123 ~70 dirt
setblock ~166 ~123 ~71 dirt
setblock ~166 ~123 ~72 dirt
setblock ~166 ~123 ~73 dirt
setblock ~166 ~123 ~74 dirt
setblock ~166 ~123 ~75 dirt
setblock ~166 ~123 ~76 dirt
setblock ~166 ~123 ~77 dirt
setblock ~166 ~123 ~78 dirt
setblock ~166 ~123 ~79 dirt
setblock ~166 ~123 ~80 dirt
setblock ~166 ~123 ~81 dirt
setblock ~166 ~123 ~82 dirt
setblock ~166 ~123 ~83 dirt
setblock ~166 ~123 ~84 dirt
setblock ~166 ~123 ~85 dirt
setblock ~166 ~123 ~86 dirt
setblock ~166 ~123 ~87 dirt
setblock ~166 ~123 ~88 dirt
setblock ~166 ~123 ~89 dirt
setblock ~166 ~123 ~90 dirt
setblock ~166 ~123 ~91 dirt
setblock ~166 ~123 ~92 dirt
setblock ~166 ~123 ~93 dirt
setblock ~166 ~123 ~94 dirt
setblock ~166 ~123 ~95 dirt
setblock ~166 ~123 ~96 dirt
setblock ~166 ~123 ~97 dirt
setblock ~166 ~123 ~98 dirt
setblock ~166 ~123 ~99 dirt
setblock ~166 ~123 ~100 dirt
setblock ~166 ~123 ~101 dirt
setblock ~166 ~123 ~102 dirt
setblock ~166 ~123 ~103 dirt
setblock ~166 ~123 ~104 dirt
setblock ~166 ~123 ~105 dirt
setblock ~166 ~123 ~106 dirt
setblock ~166 ~123 ~107 dirt
setblock ~166 ~123 ~108 dirt
setblock ~166 ~123 ~109 dirt
setblock ~166 ~123 ~110 dirt
setblock ~166 ~123 ~111 dirt
setblock ~166 ~123 ~112 dirt
setblock ~166 ~123 ~113 dirt
setblock ~166 ~123 ~114 dirt
setblock ~166 ~123 ~115 dirt
setblock ~166 ~123 ~116 dirt
setblock ~166 ~123 ~117 dirt
setblock ~166 ~123 ~118 dirt
setblock ~166 ~123 ~119 dirt
setblock ~166 ~123 ~120 grass_block
setblock ~166 ~123 ~124 dirt
setblock ~166 ~123 ~125 dirt
setblock ~166 ~123 ~126 dirt
setblock ~166 ~123 ~127 dirt
setblock ~166 ~123 ~128 dirt
setblock ~166 ~123 ~130 dirt
setblock ~166 ~123 ~159 dirt
setblock ~166 ~123 ~160 dirt
setblock ~166 ~123 ~161 dirt
setblock ~166 ~124 ~70 grass_block
setblock ~166 ~124 ~71 grass_block
setblock ~166 ~124 ~72 dirt
setblock ~166 ~124 ~73 dirt
setblock ~166 ~124 ~74 dirt
setblock ~166 ~124 ~75 dirt
setblock ~166 ~124 ~76 dirt
setblock ~166 ~124 ~77 dirt
setblock ~166 ~124 ~78 dirt
setblock ~166 ~124 ~79 dirt
setblock ~166 ~124 ~80 dirt
setblock ~166 ~124 ~81 dirt
setblock ~166 ~124 ~82 dirt
setblock ~166 ~124 ~83 dirt
setblock ~166 ~124 ~84 dirt
setblock ~166 ~124 ~85 dirt
setblock ~166 ~124 ~86 dirt
setblock ~166 ~124 ~87 dirt
setblock ~166 ~124 ~88 dirt
setblock ~166 ~124 ~89 dirt
setblock ~166 ~124 ~90 dirt
setblock ~166 ~124 ~91 dirt
setblock ~166 ~124 ~92 dirt
setblock ~166 ~124 ~93 dirt
setblock ~166 ~124 ~94 dirt
setblock ~166 ~124 ~95 dirt
setblock ~166 ~124 ~96 dirt
setblock ~166 ~124 ~97 dirt
setblock ~166 ~124 ~98 dirt
setblock ~166 ~124 ~99 dirt
setblock ~166 ~124 ~100 dirt
setblock ~166 ~124 ~101 dirt
setblock ~166 ~124 ~102 dirt
setblock ~166 ~124 ~103 dirt
setblock ~166 ~124 ~104 dirt
setblock ~166 ~124 ~105 dirt
setblock ~166 ~124 ~106 dirt
setblock ~166 ~124 ~107 dirt
setblock ~166 ~124 ~108 dirt
setblock ~166 ~124 ~109 dirt
setblock ~166 ~124 ~110 dirt
setblock ~166 ~124 ~111 dirt
setblock ~166 ~124 ~112 dirt
setblock ~166 ~124 ~113 dirt
setblock ~166 ~124 ~114 dirt
setblock ~166 ~124 ~115 dirt
setblock ~166 ~124 ~116 dirt
setblock ~166 ~124 ~117 grass_block
setblock ~166 ~124 ~118 grass_block
setblock ~166 ~124 ~119 grass_block
setblock ~166 ~124 ~120 short_grass
setblock ~166 ~124 ~124 grass_block
setblock ~166 ~124 ~125 dirt
setblock ~166 ~124 ~126 dirt
setblock ~166 ~124 ~127 dirt
setblock ~166 ~124 ~128 dirt
setblock ~166 ~124 ~130 dirt
setblock ~166 ~124 ~159 grass_block
setblock ~166 ~124 ~160 grass_block
setblock ~166 ~124 ~161 grass_block
setblock ~166 ~125 ~72 grass_block
setblock ~166 ~125 ~73 grass_block
setblock ~166 ~125 ~74 grass_block
setblock ~166 ~125 ~75 grass_block
setblock ~166 ~125 ~76 grass_block
setblock ~166 ~125 ~77 dirt
setblock ~166 ~125 ~78 dirt
setblock ~166 ~125 ~79 dirt
setblock ~166 ~125 ~80 dirt
setblock ~166 ~125 ~81 dirt
setblock ~166 ~125 ~82 dirt
setblock ~166 ~125 ~83 dirt
setblock ~166 ~125 ~84 dirt
setblock ~166 ~125 ~85 dirt
setblock ~166 ~125 ~86 dirt
setblock ~166 ~125 ~87 dirt
setblock ~166 ~125 ~88 dirt
setblock ~166 ~125 ~89 dirt
setblock ~166 ~125 ~90 grass_block
setblock ~166 ~125 ~91 grass_block
setblock ~166 ~125 ~92 grass_block
setblock ~166 ~125 ~93 grass_block
setblock ~166 ~125 ~94 grass_block
setblock ~166 ~125 ~95 grass_block
setblock ~166 ~125 ~96 grass_block
setblock ~166 ~125 ~97 grass_block
setblock ~166 ~125 ~98 grass_block
setblock ~166 ~125 ~99 grass_block
setblock ~166 ~125 ~100 grass_block
setblock ~166 ~125 ~101 dirt
setblock ~166 ~125 ~102 dirt
setblock ~166 ~125 ~103 dirt
setblock ~166 ~125 ~104 dirt
setblock ~166 ~125 ~105 dirt
setblock ~166 ~125 ~106 dirt
setblock ~166 ~125 ~107 dirt
setblock ~166 ~125 ~108 dirt
setblock ~166 ~125 ~109 dirt
setblock ~166 ~125 ~110 dirt
setblock ~166 ~125 ~111 dirt
setblock ~166 ~125 ~112 dirt
setblock ~166 ~125 ~113 dirt
setblock ~166 ~125 ~114 dirt
setblock ~166 ~125 ~115 grass_block
setblock ~166 ~125 ~116 grass_block
setblock ~166 ~125 ~117 short_grass
setblock ~166 ~125 ~118 fern
setblock ~166 ~125 ~125 grass_block
setblock ~166 ~125 ~126 grass_block
setblock ~166 ~125 ~127 grass_block
setblock ~166 ~125 ~128 dirt
setblock ~166 ~125 ~130 dirt
setblock ~166 ~125 ~159 short_grass
setblock ~166 ~125 ~161 short_grass
setblock ~166 ~126 ~77 grass_block
setblock ~166 ~126 ~78 grass_block
setblock ~166 ~126 ~79 grass_block
setblock ~166 ~126 ~80 grass_block
setblock ~166 ~126 ~81 grass_block
setblock ~166 ~126 ~82 grass_block
setblock ~166 ~126 ~83 grass_block
setblock ~166 ~126 ~84 grass_block
setblock ~166 ~126 ~85 grass_block
setblock ~166 ~126 ~86 grass_block
setblock ~166 ~126 ~87 grass_block
setblock ~166 ~126 ~88 grass_block
setblock ~166 ~126 ~89 grass_block
setblock ~166 ~126 ~100 short_grass
setblock ~166 ~126 ~101 grass_block
setblock ~166 ~126 ~102 grass_block
setblock ~166 ~126 ~103 grass_block
setblock ~166 ~126 ~104 grass_block
setblock ~166 ~126 ~105 grass_block
setblock ~166 ~126 ~106 dirt
setblock ~166 ~126 ~107 dirt
setblock ~166 ~126 ~108 dirt
setblock ~166 ~126 ~109 dirt
setblock ~166 ~126 ~110 dirt
setblock ~166 ~126 ~111 dirt
setblock ~166 ~126 ~112 grass_block
setblock ~166 ~126 ~113 grass_block
setblock ~166 ~126 ~114 grass_block
setblock ~166 ~126 ~115 poppy
setblock ~166 ~126 ~128 grass_block
setblock ~166 ~126 ~130 grass_block
setblock ~166 ~127 ~77 poppy
setblock ~166 ~127 ~79 short_grass
setblock ~166 ~127 ~83 short_grass
setblock ~166 ~127 ~103 short_grass
setblock ~166 ~127 ~105 short_grass
setblock ~166 ~127 ~106 grass_block
setblock ~166 ~127 ~107 grass_block
setblock ~166 ~127 ~108 grass_block
setblock ~166 ~127 ~109 grass_block
setblock ~166 ~127 ~110 grass_block
setblock ~166 ~127 ~111 grass_block
setblock ~166 ~128 ~111 short_grass
setblock ~167 ~104 ~96 dirt
setblock ~167 ~105 ~96 dirt
setblock ~167 ~105 ~97 dirt
setblock ~167 ~106 ~90 dirt
setblock ~167 ~106 ~92 dirt
setblock ~167 ~106 ~93 dirt
setblock ~167 ~106 ~94 dirt
setblock ~167 ~106 ~96 dirt
setblock ~167 ~106 ~97 dirt
setblock ~167 ~106 ~98 dirt
setblock ~167 ~107 ~88 dirt
setblock ~167 ~107 ~89 dirt
setblock ~167 ~107 ~90 dirt
setblock ~167 ~107 ~91 dirt
setblock ~167 ~107 ~92 dirt
setblock ~167 ~107 ~93 dirt
setblock ~167 ~107 ~94 dirt
setblock ~167 ~107 ~95 dirt
setblock ~167 ~107 ~96 dirt
setblock ~167 ~107 ~97 dirt
setblock ~167 ~107 ~98 dirt
setblock ~167 ~107 ~99 dirt
setblock ~167 ~108 ~88 dirt
setblock ~167 ~108 ~89 dirt
setblock ~167 ~108 ~90 dirt
setblock ~167 ~108 ~91 dirt
setblock ~167 ~108 ~92 dirt
setblock ~167 ~108 ~93 dirt
setblock ~167 ~108 ~94 dirt
setblock ~167 ~108 ~95 dirt
setblock ~167 ~108 ~96 dirt
setblock ~167 ~108 ~97 dirt
setblock ~167 ~108 ~98 dirt
setblock ~167 ~108 ~99 dirt
setblock ~167 ~109 ~87 dirt
setblock ~167 ~109 ~88 dirt
setblock ~167 ~109 ~89 dirt
setblock ~167 ~109 ~90 dirt
setblock ~167 ~109 ~91 dirt
setblock ~167 ~109 ~92 dirt
setblock ~167 ~109 ~93 dirt
setblock ~167 ~109 ~94 dirt
setblock ~167 ~109 ~95 dirt
setblock ~167 ~109 ~96 dirt
setblock ~167 ~109 ~97 dirt
setblock ~167 ~109 ~98 dirt
setblock ~167 ~109 ~99 dirt
setblock ~167 ~110 ~87 dirt
setblock ~167 ~110 ~88 dirt
setblock ~167 ~110 ~89 dirt
setblock ~167 ~110 ~90 dirt
setblock ~167 ~110 ~91 dirt
setblock ~167 ~110 ~92 dirt
setblock ~167 ~110 ~93 dirt
setblock ~167 ~110 ~94 dirt
setblock ~167 ~110 ~95 dirt
setblock ~167 ~110 ~96 dirt
setblock ~167 ~110 ~97 dirt
setblock ~167 ~110 ~98 dirt
setblock ~167 ~110 ~99 dirt
setblock ~167 ~110 ~100 dirt
setblock ~167 ~111 ~86 dirt
setblock ~167 ~111 ~87 dirt
setblock ~167 ~111 ~88 dirt
setblock ~167 ~111 ~89 dirt
setblock ~167 ~111 ~90 dirt
setblock ~167 ~111 ~91 dirt
setblock ~167 ~111 ~92 dirt
setblock ~167 ~111 ~93 dirt
setblock ~167 ~111 ~94 dirt
setblock ~167 ~111 ~95 dirt
setblock ~167 ~111 ~96 dirt
setblock ~167 ~111 ~97 dirt
setblock ~167 ~111 ~98 dirt
setblock ~167 ~111 ~99 dirt
setblock ~167 ~111 ~100 dirt
setblock ~167 ~112 ~86 dirt
setblock ~167 ~112 ~87 dirt
setblock ~167 ~112 ~88 dirt
setblock ~167 ~112 ~89 dirt
setblock ~167 ~112 ~90 dirt
setblock ~167 ~112 ~91 dirt
setblock ~167 ~112 ~92 dirt
setblock ~167 ~112 ~93 dirt
setblock ~167 ~112 ~94 dirt
setblock ~167 ~112 ~95 dirt
setblock ~167 ~112 ~96 dirt
setblock ~167 ~112 ~97 dirt
setblock ~167 ~112 ~98 dirt
setblock ~167 ~112 ~99 dirt
setblock ~167 ~112 ~100 dirt
setblock ~167 ~112 ~101 dirt
setblock ~167 ~112 ~112 dirt
setblock ~167 ~113 ~86 dirt
setblock ~167 ~113 ~87 dirt
setblock ~167 ~113 ~88 dirt
setblock ~167 ~113 ~89 dirt
setblock ~167 ~113 ~90 dirt
setblock ~167 ~113 ~91 dirt
setblock ~167 ~113 ~92 dirt
setblock ~167 ~113 ~93 dirt
setblock ~167 ~113 ~94 dirt
setblock ~167 ~113 ~95 dirt
setblock ~167 ~113 ~96 dirt
setblock ~167 ~113 ~97 dirt
setblock ~167 ~113 ~98 dirt
setblock ~167 ~113 ~99 dirt
setblock ~167 ~113 ~100 dirt
setblock ~167 ~113 ~101 dirt
setblock ~167 ~113 ~111 dirt
setblock ~167 ~113 ~112 dirt
setblock ~167 ~114 ~86 dirt
setblock ~167 ~114 ~87 dirt
setblock ~167 ~114 ~88 dirt
setblock ~167 ~114 ~89 dirt
setblock ~167 ~114 ~90 dirt
setblock ~167 ~114 ~91 dirt
setblock ~167 ~114 ~92 dirt
setblock ~167 ~114 ~93 dirt
setblock ~167 ~114 ~94 dirt
setblock ~167 ~114 ~95 dirt
setblock ~167 ~114 ~96 dirt
setblock ~167 ~114 ~97 dirt
setblock ~167 ~114 ~98 dirt
setblock ~167 ~114 ~99 dirt
setblock ~167 ~114 ~100 dirt
setblock ~167 ~114 ~101 dirt
setblock ~167 ~114 ~102 dirt
setblock ~167 ~114 ~110 dirt
setblock ~167 ~114 ~111 dirt
setblock ~167 ~114 ~112 dirt
setblock ~167 ~114 ~113 dirt
setblock ~167 ~115 ~81 dirt
setblock ~167 ~115 ~82 dirt
setblock ~167 ~115 ~85 dirt
setblock ~167 ~115 ~86 dirt
setblock ~167 ~115 ~87 dirt
setblock ~167 ~115 ~88 dirt
setblock ~167 ~115 ~89 dirt
setblock ~167 ~115 ~90 dirt
setblock ~167 ~115 ~91 dirt
setblock ~167 ~115 ~92 dirt
setblock ~167 ~115 ~93 dirt
setblock ~167 ~115 ~94 dirt
setblock ~167 ~115 ~95 dirt
setblock ~167 ~115 ~96 dirt
setblock ~167 ~115 ~97 dirt
setblock ~167 ~115 ~98 dirt
setblock ~167 ~115 ~99 dirt
setblock ~167 ~115 ~100 dirt
setblock ~167 ~115 ~101 dirt
setblock ~167 ~115 ~102 dirt
setblock ~167 ~115 ~103 dirt
setblock ~167 ~115 ~109 dirt
setblock ~167 ~115 ~110 dirt
setblock ~167 ~115 ~111 dirt
setblock ~167 ~115 ~112 dirt
setblock ~167 ~115 ~113 dirt
setblock ~167 ~115 ~114 dirt
setblock ~167 ~116 ~73 dirt
setblock ~167 ~116 ~80 dirt
setblock ~167 ~116 ~81 dirt
setblock ~167 ~116 ~82 dirt
setblock ~167 ~116 ~83 dirt
setblock ~167 ~116 ~85 dirt
setblock ~167 ~116 ~86 dirt
setblock ~167 ~116 ~87 dirt
setblock ~167 ~116 ~88 dirt
setblock ~167 ~116 ~89 dirt
setblock ~167 ~116 ~90 dirt
setblock ~167 ~116 ~91 dirt
setblock ~167 ~116 ~92 dirt
setblock ~167 ~116 ~93 dirt
setblock ~167 ~116 ~94 dirt
setblock ~167 ~116 ~95 dirt
setblock ~167 ~116 ~96 dirt
setblock ~167 ~116 ~97 dirt
setblock ~167 ~116 ~98 dirt
setblock ~167 ~116 ~99 dirt
setblock ~167 ~116 ~100 dirt
setblock ~167 ~116 ~101 dirt
setblock ~167 ~116 ~102 dirt
setblock ~167 ~116 ~103 dirt
setblock ~167 ~116 ~108 dirt
setblock ~167 ~116 ~109 dirt
setblock ~167 ~116 ~110 dirt
setblock ~167 ~116 ~111 dirt
setblock ~167 ~116 ~112 dirt
setblock ~167 ~116 ~113 dirt
setblock ~167 ~116 ~114 dirt
setblock ~167 ~116 ~115 dirt
setblock ~167 ~117 ~72 dirt
setblock ~167 ~117 ~73 dirt
setblock ~167 ~117 ~74 dirt
setblock ~167 ~117 ~79 dirt
setblock ~167 ~117 ~80 dirt
setblock ~167 ~117 ~81 dirt
setblock ~167 ~117 ~82 dirt
setblock ~167 ~117 ~83 dirt
setblock ~167 ~117 ~84 dirt
setblock ~167 ~117 ~85 dirt
setblock ~167 ~117 ~86 dirt
setblock ~167 ~117 ~87 dirt
setblock ~167 ~117 ~88 dirt
setblock ~167 ~117 ~89 dirt
setblock ~167 ~117 ~90 dirt
setblock ~167 ~117 ~91 dirt
setblock ~167 ~117 ~92 dirt
setblock ~167 ~117 ~93 dirt
setblock ~167 ~117 ~94 dirt
setblock ~167 ~117 ~95 dirt
setblock ~167 ~117 ~96 dirt
setblock ~167 ~117 ~97 dirt
setblock ~167 ~117 ~98 dirt
setblock ~167 ~117 ~99 dirt
setblock ~167 ~117 ~100 dirt
setblock ~167 ~117 ~101 dirt
setblock ~167 ~117 ~102 dirt
setblock ~167 ~117 ~103 dirt
setblock ~167 ~117 ~104 dirt
setblock ~167 ~117 ~108 dirt
setblock ~167 ~117 ~109 dirt
setblock ~167 ~117 ~110 dirt
setblock ~167 ~117 ~111 dirt
setblock ~167 ~117 ~112 dirt
setblock ~167 ~117 ~113 dirt
setblock ~167 ~117 ~114 dirt
setblock ~167 ~117 ~115 dirt
setblock ~167 ~117 ~116 dirt
setblock ~167 ~118 ~72 dirt
setblock ~167 ~118 ~73 dirt
setblock ~167 ~118 ~74 dirt
setblock ~167 ~118 ~79 dirt
setblock ~167 ~118 ~80 dirt
setblock ~167 ~118 ~81 dirt
setblock ~167 ~118 ~82 dirt
setblock ~167 ~118 ~83 dirt
setblock ~167 ~118 ~84 dirt
setblock ~167 ~118 ~85 dirt
setblock ~167 ~118 ~86 dirt
setblock ~167 ~118 ~87 dirt
setblock ~167 ~118 ~88 dirt
setblock ~167 ~118 ~89 dirt
setblock ~167 ~118 ~90 dirt
setblock ~167 ~118 ~91 dirt
setblock ~167 ~118 ~92 dirt
setblock ~167 ~118 ~93 dirt
setblock ~167 ~118 ~94 dirt
setblock ~167 ~118 ~95 dirt
setblock ~167 ~118 ~96 dirt
setblock ~167 ~118 ~97 dirt
setblock ~167 ~118 ~98 dirt
setblock ~167 ~118 ~99 dirt
setblock ~167 ~118 ~100 dirt
setblock ~167 ~118 ~101 dirt
setblock ~167 ~118 ~102 dirt
setblock ~167 ~118 ~103 dirt
setblock ~167 ~118 ~104 dirt
setblock ~167 ~118 ~107 dirt
setblock ~167 ~118 ~108 dirt
setblock ~167 ~118 ~109 dirt
setblock ~167 ~118 ~110 dirt
setblock ~167 ~118 ~111 dirt
setblock ~167 ~118 ~112 dirt
setblock ~167 ~118 ~113 dirt
setblock ~167 ~118 ~114 dirt
setblock ~167 ~118 ~115 dirt
setblock ~167 ~118 ~116 dirt
setblock ~167 ~118 ~127 dirt
setblock ~167 ~119 ~71 dirt
setblock ~167 ~119 ~72 dirt
setblock ~167 ~119 ~73 dirt
setblock ~167 ~119 ~74 dirt
setblock ~167 ~119 ~75 dirt
setblock ~167 ~119 ~78 dirt
setblock ~167 ~119 ~79 dirt
setblock ~167 ~119 ~80 dirt
setblock ~167 ~119 ~81 dirt
setblock ~167 ~119 ~82 dirt
setblock ~167 ~119 ~83 dirt
setblock ~167 ~119 ~84 dirt
setblock ~167 ~119 ~85 dirt
setblock ~167 ~119 ~86 dirt
setblock ~167 ~119 ~87 dirt
setblock ~167 ~119 ~88 dirt
setblock ~167 ~119 ~89 dirt
setblock ~167 ~119 ~90 dirt
setblock ~167 ~119 ~91 dirt
setblock ~167 ~119 ~92 dirt
setblock ~167 ~119 ~93 dirt
setblock ~167 ~119 ~94 dirt
setblock ~167 ~119 ~95 dirt
setblock ~167 ~119 ~96 dirt
setblock ~167 ~119 ~97 dirt
setblock ~167 ~119 ~98 dirt
setblock ~167 ~119 ~99 dirt
setblock ~167 ~119 ~100 dirt
setblock ~167 ~119 ~101 dirt
setblock ~167 ~119 ~102 dirt
setblock ~167 ~119 ~103 dirt
setblock ~167 ~119 ~104 dirt
setblock ~167 ~119 ~106 dirt
setblock ~167 ~119 ~107 dirt
setblock ~167 ~119 ~108 dirt
setblock ~167 ~119 ~109 dirt
setblock ~167 ~119 ~110 dirt
setblock ~167 ~119 ~111 dirt
setblock ~167 ~119 ~112 dirt
setblock ~167 ~119 ~113 dirt
setblock ~167 ~119 ~114 dirt
setblock ~167 ~119 ~115 dirt
setblock ~167 ~119 ~116 dirt
setblock ~167 ~119 ~127 dirt
setblock ~167 ~119 ~160 dirt
setblock ~167 ~120 ~67 dirt
setblock ~167 ~120 ~71 dirt
setblock ~167 ~120 ~72 dirt
setblock ~167 ~120 ~73 dirt
setblock ~167 ~120 ~74 dirt
setblock ~167 ~120 ~75 dirt
setblock ~167 ~120 ~76 dirt
setblock ~167 ~120 ~78 dirt
setblock ~167 ~120 ~79 dirt
setblock ~167 ~120 ~80 dirt
setblock ~167 ~120 ~81 dirt
setblock ~167 ~120 ~82 dirt
setblock ~167 ~120 ~83 dirt
setblock ~167 ~120 ~84 dirt
setblock ~167 ~120 ~85 dirt
setblock ~167 ~120 ~86 dirt
setblock ~167 ~120 ~87 dirt
setblock ~167 ~120 ~88 dirt
setblock ~167 ~120 ~89 dirt
setblock ~167 ~120 ~90 dirt
setblock ~167 ~120 ~91 dirt
setblock ~167 ~120 ~92 dirt
setblock ~167 ~120 ~93 dirt
setblock ~167 ~120 ~94 dirt
setblock ~167 ~120 ~95 dirt
setblock ~167 ~120 ~96 dirt
setblock ~167 ~120 ~97 dirt
setblock ~167 ~120 ~98 dirt
setblock ~167 ~120 ~99 dirt
setblock ~167 ~120 ~100 dirt
setblock ~167 ~120 ~101 dirt
setblock ~167 ~120 ~102 dirt
setblock ~167 ~120 ~103 dirt
setblock ~167 ~120 ~104 dirt
setblock ~167 ~120 ~105 dirt
setblock ~167 ~120 ~106 dirt
setblock ~167 ~120 ~107 dirt
setblock ~167 ~120 ~108 dirt
setblock ~167 ~120 ~109 dirt
setblock ~167 ~120 ~110 dirt
setblock ~167 ~120 ~111 dirt
setblock ~167 ~120 ~112 dirt
setblock ~167 ~120 ~113 dirt
setblock ~167 ~120 ~114 dirt
setblock ~167 ~120 ~115 dirt
setblock ~167 ~120 ~116 dirt
setblock ~167 ~120 ~117 dirt
setblock ~167 ~120 ~119 dirt
setblock ~167 ~120 ~127 dirt
setblock ~167 ~120 ~159 dirt
setblock ~167 ~120 ~160 dirt
setblock ~167 ~120 ~161 dirt
setblock ~167 ~121 ~67 dirt
setblock ~167 ~121 ~70 dirt
setblock ~167 ~121 ~71 dirt
setblock ~167 ~121 ~72 dirt
setblock ~167 ~121 ~73 dirt
setblock ~167 ~121 ~74 dirt
setblock ~167 ~121 ~75 dirt
setblock ~167 ~121 ~76 dirt
setblock ~167 ~121 ~78 dirt
setblock ~167 ~121 ~79 dirt
setblock ~167 ~121 ~80 dirt
setblock ~167 ~121 ~81 dirt
setblock ~167 ~121 ~82 dirt
setblock ~167 ~121 ~83 dirt
setblock ~167 ~121 ~84 dirt
setblock ~167 ~121 ~85 dirt
setblock ~167 ~121 ~86 dirt
setblock ~167 ~121 ~87 dirt
setblock ~167 ~121 ~88 dirt
setblock ~167 ~121 ~89 dirt
setblock ~167 ~121 ~90 dirt
setblock ~167 ~121 ~91 dirt
setblock ~167 ~121 ~92 dirt
setblock ~167 ~121 ~93 dirt
setblock ~167 ~121 ~94 dirt
setblock ~167 ~121 ~95 dirt
setblock ~167 ~121 ~96 dirt
setblock ~167 ~121 ~97 dirt
setblock ~167 ~121 ~98 dirt
setblock ~167 ~121 ~99 dirt
setblock ~167 ~121 ~100 dirt
setblock ~167 ~121 ~101 dirt
setblock ~167 ~121 ~102 dirt
setblock ~167 ~121 ~103 dirt
setblock ~167 ~121 ~104 dirt
setblock ~167 ~121 ~105 dirt
setblock ~167 ~121 ~106 dirt
setblock ~167 ~121 ~107 dirt
setblock ~167 ~121 ~108 dirt
setblock ~167 ~121 ~109 dirt
setblock ~167 ~121 ~110 dirt
setblock ~167 ~121 ~111 dirt
setblock ~167 ~121 ~112 dirt
setblock ~167 ~121 ~113 dirt
setblock ~167 ~121 ~114 dirt
setblock ~167 ~121 ~115 dirt
setblock ~167 ~121 ~116 dirt
setblock ~167 ~121 ~117 dirt
setblock ~167 ~121 ~118 dirt
setblock ~167 ~121 ~119 dirt
setblock ~167 ~121 ~127 dirt
setblock ~167 ~121 ~159 dirt
setblock ~167 ~121 ~160 dirt
setblock ~167 ~121 ~161 dirt
setblock ~167 ~122 ~67 dirt
setblock ~167 ~122 ~70 dirt
setblock ~167 ~122 ~71 dirt
setblock ~167 ~122 ~72 dirt
setblock ~167 ~122 ~73 dirt
setblock ~167 ~122 ~74 dirt
setblock ~167 ~122 ~75 dirt
setblock ~167 ~122 ~76 dirt
setblock ~167 ~122 ~78 dirt
setblock ~167 ~122 ~79 dirt
setblock ~167 ~122 ~80 dirt
setblock ~167 ~122 ~81 dirt
setblock ~167 ~122 ~82 dirt
setblock ~167 ~122 ~83 dirt
setblock ~167 ~122 ~84 dirt
setblock ~167 ~122 ~85 dirt
setblock ~167 ~122 ~86 dirt
setblock ~167 ~122 ~87 dirt
setblock ~167 ~122 ~88 dirt
setblock ~167 ~122 ~89 dirt
setblock ~167 ~122 ~90 dirt
setblock ~167 ~122 ~91 dirt
setblock ~167 ~122 ~92 dirt
setblock ~167 ~122 ~93 dirt
setblock ~167 ~122 ~94 dirt
setblock ~167 ~122 ~95 dirt
setblock ~167 ~122 ~96 dirt
setblock ~167 ~122 ~97 dirt
setblock ~167 ~122 ~98 dirt
setblock ~167 ~122 ~99 dirt
setblock ~167 ~122 ~100 dirt
setblock ~167 ~122 ~101 dirt
setblock ~167 ~122 ~102 dirt
setblock ~167 ~122 ~103 dirt
setblock ~167 ~122 ~104 dirt
setblock ~167 ~122 ~105 dirt
setblock ~167 ~122 ~106 dirt
setblock ~167 ~122 ~107 dirt
setblock ~167 ~122 ~108 dirt
setblock ~167 ~122 ~109 dirt
setblock ~167 ~122 ~110 dirt
setblock ~167 ~122 ~111 dirt
setblock ~167 ~122 ~112 dirt
setblock ~167 ~122 ~113 dirt
setblock ~167 ~122 ~114 dirt
setblock ~167 ~122 ~115 dirt
setblock ~167 ~122 ~116 dirt
setblock ~167 ~122 ~117 dirt
setblock ~167 ~122 ~118 dirt
setblock ~167 ~122 ~119 dirt
setblock ~167 ~122 ~127 dirt
setblock ~167 ~122 ~159 dirt
setblock ~167 ~122 ~160 dirt
setblock ~167 ~122 ~161 dirt
setblock ~167 ~123 ~67 dirt
setblock ~167 ~123 ~70 dirt
setblock ~167 ~123 ~71 dirt
setblock ~167 ~123 ~72 dirt
setblock ~167 ~123 ~73 dirt
setblock ~167 ~123 ~74 dirt
setblock ~167 ~123 ~75 dirt
setblock ~167 ~123 ~76 dirt
setblock ~167 ~123 ~78 dirt
setblock ~167 ~123 ~79 dirt
setblock ~167 ~123 ~80 dirt
setblock ~167 ~123 ~81 dirt
setblock ~167 ~123 ~82 dirt
setblock ~167 ~123 ~83 dirt
setblock ~167 ~123 ~84 dirt
setblock ~167 ~123 ~85 dirt
setblock ~167 ~123 ~86 dirt
setblock ~167 ~123 ~87 dirt
setblock ~167 ~123 ~88 dirt
setblock ~167 ~123 ~89 dirt
setblock ~167 ~123 ~90 dirt
setblock ~167 ~123 ~91 dirt
setblock ~167 ~123 ~92 dirt
setblock ~167 ~123 ~93 dirt
setblock ~167 ~123 ~94 dirt
setblock ~167 ~123 ~95 dirt
setblock ~167 ~123 ~96 dirt
setblock ~167 ~123 ~97 dirt
setblock ~167 ~123 ~98 dirt
setblock ~167 ~123 ~99 dirt
setblock ~167 ~123 ~100 dirt
setblock ~167 ~123 ~101 dirt
setblock ~167 ~123 ~102 dirt
setblock ~167 ~123 ~103 dirt
setblock ~167 ~123 ~104 dirt
setblock ~167 ~123 ~105 dirt
setblock ~167 ~123 ~106 dirt
setblock ~167 ~123 ~107 dirt
setblock ~167 ~123 ~108 dirt
setblock ~167 ~123 ~109 dirt
setblock ~167 ~123 ~110 dirt
setblock ~167 ~123 ~111 dirt
setblock ~167 ~123 ~112 dirt
setblock ~167 ~123 ~113 dirt
setblock ~167 ~123 ~114 dirt
setblock ~167 ~123 ~115 dirt
setblock ~167 ~123 ~116 dirt
setblock ~167 ~123 ~117 dirt
setblock ~167 ~123 ~118 dirt
setblock ~167 ~123 ~119 grass_block
setblock ~167 ~123 ~127 dirt
setblock ~167 ~123 ~159 dirt
setblock ~167 ~123 ~160 dirt
setblock ~167 ~123 ~161 dirt
setblock ~167 ~124 ~67 dirt
setblock ~167 ~124 ~70 grass_block
setblock ~167 ~124 ~71 dirt
setblock ~167 ~124 ~72 dirt
setblock ~167 ~124 ~73 dirt
setblock ~167 ~124 ~74 dirt
setblock ~167 ~124 ~75 dirt
setblock ~167 ~124 ~76 dirt
setblock ~167 ~124 ~78 dirt
setblock ~167 ~124 ~79 dirt
setblock ~167 ~124 ~80 dirt
setblock ~167 ~124 ~81 dirt
setblock ~167 ~124 ~82 dirt
setblock ~167 ~124 ~83 dirt
setblock ~167 ~124 ~84 dirt
setblock ~167 ~124 ~85 dirt
setblock ~167 ~124 ~86 dirt
setblock ~167 ~124 ~87 dirt
setblock ~167 ~124 ~88 dirt
setblock ~167 ~124 ~89 dirt
setblock ~167 ~124 ~90 dirt
setblock ~167 ~124 ~91 dirt
setblock ~167 ~124 ~92 dirt
setblock ~167 ~124 ~93 dirt
setblock ~167 ~124 ~94 dirt
setblock ~167 ~124 ~95 dirt
setblock ~167 ~124 ~96 dirt
setblock ~167 ~124 ~97 dirt
setblock ~167 ~124 ~98 dirt
setblock ~167 ~124 ~99 dirt
setblock ~167 ~124 ~100 dirt
setblock ~167 ~124 ~101 dirt
setblock ~167 ~124 ~102 dirt
setblock ~167 ~124 ~103 dirt
setblock ~167 ~124 ~104 dirt
setblock ~167 ~124 ~105 dirt
setblock ~167 ~124 ~106 dirt
setblock ~167 ~124 ~107 dirt
setblock ~167 ~124 ~108 dirt
setblock ~167 ~124 ~109 dirt
setblock ~167 ~124 ~110 dirt
setblock ~167 ~124 ~111 dirt
setblock ~167 ~124 ~112 dirt
setblock ~167 ~124 ~113 dirt
setblock ~167 ~124 ~114 dirt
setblock ~167 ~124 ~115 dirt
setblock ~167 ~124 ~116 dirt
setblock ~167 ~124 ~117 grass_block
setblock ~167 ~124 ~118 grass_block
setblock ~167 ~124 ~119 fern
setblock ~167 ~124 ~127 dirt
setblock ~167 ~124 ~159 grass_block
setblock ~167 ~124 ~160 grass_block
setblock ~167 ~124 ~161 grass_block
setblock ~167 ~125 ~67 grass_block
setblock ~167 ~125 ~71 grass_block
setblock ~167 ~125 ~72 grass_block
setblock ~167 ~125 ~73 grass_block
setblock ~167 ~125 ~74 grass_block
setblock ~167 ~125 ~75 grass_block
setblock ~167 ~125 ~76 grass_block
setblock ~167 ~125 ~78 dirt
setblock ~167 ~125 ~79 dirt
setblock ~167 ~125 ~80 dirt
setblock ~167 ~125 ~81 dirt
setblock ~167 ~125 ~82 dirt
setblock ~167 ~125 ~83 dirt
setblock ~167 ~125 ~84 dirt
setblock ~167 ~125 ~85 dirt
setblock ~167 ~125 ~86 dirt
setblock ~167 ~125 ~87 dirt
setblock ~167 ~125 ~88 dirt
setblock ~167 ~125 ~89 dirt
setblock ~167 ~125 ~90 grass_block
setblock ~167 ~125 ~91 grass_block
setblock ~167 ~125 ~92 grass_block
setblock ~167 ~125 ~93 grass_block
setblock ~167 ~125 ~94 grass_block
setblock ~167 ~125 ~95 grass_block
setblock ~167 ~125 ~96 grass_block
setblock ~167 ~125 ~97 grass_block
setblock ~167 ~125 ~98 grass_block
setblock ~167 ~125 ~99 grass_block
setblock ~167 ~125 ~100 grass_block
setblock ~167 ~125 ~101 dirt
setblock ~167 ~125 ~102 dirt
setblock ~167 ~125 ~103 dirt
setblock ~167 ~125 ~104 dirt
setblock ~167 ~125 ~105 dirt
setblock ~167 ~125 ~106 dirt
setblock ~167 ~125 ~107 dirt
setblock ~167 ~125 ~108 dirt
setblock ~167 ~125 ~109 dirt
setblock ~167 ~125 ~110 dirt
setblock ~167 ~125 ~111 dirt
setblock ~167 ~125 ~112 dirt
setblock ~167 ~125 ~113 dirt
setblock ~167 ~125 ~114 grass_block
setblock ~167 ~125 ~115 grass_block
setblock ~167 ~125 ~116 grass_block
setblock ~167 ~125 ~117 short_grass
setblock ~167 ~125 ~127 grass_block
setblock ~167 ~126 ~74 short_grass
setblock ~167 ~126 ~75 short_grass
setblock ~167 ~126 ~78 grass_block
setblock ~167 ~126 ~79 grass_block
setblock ~167 ~126 ~80 grass_block
setblock ~167 ~126 ~81 grass_block
setblock ~167 ~126 ~82 grass_block
setblock ~167 ~126 ~83 grass_block
setblock ~167 ~126 ~84 grass_block
setblock ~167 ~126 ~85 grass_block
setblock ~167 ~126 ~86 grass_block
setblock ~167 ~126 ~87 grass_block
setblock ~167 ~126 ~88 grass_block
setblock ~167 ~126 ~89 grass_block
setblock ~167 ~126 ~91 poppy
setblock ~167 ~126 ~92 short_grass
setblock ~167 ~126 ~96 short_grass
setblock ~167 ~126 ~98 short_grass
setblock ~167 ~126 ~99 short_grass
setblock ~167 ~126 ~101 grass_block
setblock ~167 ~126 ~102 grass_block
setblock ~167 ~126 ~103 grass_block
setblock ~167 ~126 ~104 grass_block
setblock ~167 ~126 ~105 grass_block
setblock ~167 ~126 ~106 dirt
setblock ~167 ~126 ~107 dirt
setblock ~167 ~126 ~108 dirt
setblock ~167 ~126 ~109 dirt
setblock ~167 ~126 ~110 dirt
setblock ~167 ~126 ~111 dirt
setblock ~167 ~126 ~112 grass_block
setblock ~167 ~126 ~113 grass_block
setblock ~167 ~126 ~114 short_grass
setblock ~167 ~126 ~127 poppy
setblock ~167 ~127 ~78 poppy
setblock ~167 ~127 ~85 short_grass
setblock ~167 ~127 ~86 poppy
setblock ~167 ~127 ~104 short_grass
setblock ~167 ~127 ~106 grass_block
setblock ~167 ~127 ~107 grass_block
setblock ~167 ~127 ~108 grass_block
setblock ~167 ~127 ~109 grass_block
setblock ~167 ~127 ~110 grass_block
setblock ~167 ~127 ~111 grass_block
setblock ~167 ~128 ~106 short_grass
setblock ~168 ~106 ~97 dirt
setblock ~168 ~107 ~90 dirt
setblock ~168 ~107 ~96 dirt
setblock ~168 ~107 ~97 dirt
setblock ~168 ~107 ~98 dirt
setblock ~168 ~108 ~89 dirt
setblock ~168 ~108 ~90 dirt
setblock ~168 ~108 ~91 dirt
setblock ~168 ~108 ~93 dirt
setblock ~168 ~108 ~94 dirt
setblock ~168 ~108 ~95 dirt
setblock ~168 ~108 ~96 dirt
setblock ~168 ~108 ~97 dirt
setblock ~168 ~108 ~98 dirt
setblock ~168 ~109 ~88 dirt
setblock ~168 ~109 ~89 dirt
setblock ~168 ~109 ~90 dirt
setblock ~168 ~109 ~91 dirt
setblock ~168 ~109 ~92 dirt
setblock ~168 ~109 ~93 dirt
setblock ~168 ~109 ~94 dirt
setblock ~168 ~109 ~95 dirt
setblock ~168 ~109 ~96 dirt
setblock ~168 ~109 ~97 dirt
setblock ~168 ~109 ~98 dirt
setblock ~168 ~109 ~99 dirt
setblock ~168 ~110 ~88 dirt
setblock ~168 ~110 ~89 dirt
setblock ~168 ~110 ~90 dirt
setblock ~168 ~110 ~91 dirt
setblock ~168 ~110 ~92 dirt
setblock ~168 ~110 ~93 dirt
setblock ~168 ~110 ~94 dirt
setblock ~168 ~110 ~95 dirt
setblock ~168 ~110 ~96 dirt
setblock ~168 ~110 ~97 dirt
setblock ~168 ~110 ~98 dirt
setblock ~168 ~110 ~99 dirt
setblock ~168 ~110 ~100 dirt
setblock ~168 ~111 ~87 dirt
setblock ~168 ~111 ~88 dirt
setblock ~168 ~111 ~89 dirt
setblock ~168 ~111 ~90 dirt
setblock ~168 ~111 ~91 dirt
setblock ~168 ~111 ~92 dirt
setblock ~168 ~111 ~93 dirt
setblock ~168 ~111 ~94 dirt
setblock ~168 ~111 ~95 dirt
setblock ~168 ~111 ~96 dirt
setblock ~168 ~111 ~97 dirt
setblock ~168 ~111 ~98 dirt
setblock ~168 ~111 ~99 dirt
setblock ~168 ~111 ~100 dirt
setblock ~168 ~111 ~101 dirt
setblock ~168 ~112 ~86 dirt
setblock ~168 ~112 ~87 dirt
setblock ~168 ~112 ~88 dirt
setblock ~168 ~112 ~89 dirt
setblock ~168 ~112 ~90 dirt
setblock ~168 ~112 ~91 dirt
setblock ~168 ~112 ~92 dirt
setblock ~168 ~112 ~93 dirt
setblock ~168 ~112 ~94 dirt
setblock ~168 ~112 ~95 dirt
setblock ~168 ~112 ~96 dirt
setblock ~168 ~112 ~97 dirt
setblock ~168 ~112 ~98 dirt
setblock ~168 ~112 ~99 dirt
setblock ~168 ~112 ~100 dirt
setblock ~168 ~112 ~101 dirt
setblock ~168 ~113 ~86 dirt
setblock ~168 ~113 ~87 dirt
setblock ~168 ~113 ~88 dirt
setblock ~168 ~113 ~89 dirt
setblock ~168 ~113 ~90 dirt
setblock ~168 ~113 ~91 dirt
setblock ~168 ~113 ~92 dirt
setblock ~168 ~113 ~93 dirt
setblock ~168 ~113 ~94 dirt
