setblock ~26 ~125 ~65 dirt
setblock ~26 ~125 ~96 grass_block
setblock ~26 ~125 ~97 grass_block
setblock ~26 ~125 ~104 dirt
setblock ~26 ~125 ~105 dirt
setblock ~26 ~125 ~106 dirt
setblock ~26 ~125 ~107 dirt
setblock ~26 ~125 ~108 dirt
setblock ~26 ~125 ~109 dirt
setblock ~26 ~125 ~110 grass_block
setblock ~26 ~125 ~149 grass_block
setblock ~26 ~125 ~150 dirt
setblock ~26 ~125 ~151 grass_block
setblock ~26 ~125 ~152 grass_block
setblock ~26 ~125 ~153 grass_block
setblock ~26 ~125 ~154 grass_block
setblock ~26 ~125 ~155 grass_block
setblock ~26 ~125 ~156 grass_block
setblock ~26 ~126 ~63 grass_block
setblock ~26 ~126 ~64 grass_block
setblock ~26 ~126 ~65 grass_block
setblock ~26 ~126 ~104 grass_block
setblock ~26 ~126 ~105 grass_block
setblock ~26 ~126 ~106 grass_block
setblock ~26 ~126 ~107 grass_block
setblock ~26 ~126 ~108 grass_block
setblock ~26 ~126 ~109 grass_block
setblock ~26 ~126 ~149 short_grass
setblock ~26 ~126 ~150 grass_block
setblock ~26 ~126 ~152 poppy
setblock ~26 ~126 ~156 fern
setblock ~26 ~127 ~65 short_grass
setblock ~26 ~127 ~105 short_grass
setblock ~26 ~127 ~106 poppy
setblock ~26 ~127 ~107 short_grass
setblock ~26 ~127 ~108 short_grass
setblock ~26 ~127 ~150 short_grass
setblock ~27 ~112 ~152 dirt
setblock ~27 ~113 ~152 dirt
setblock ~27 ~114 ~151 dirt
setblock ~27 ~114 ~152 dirt
setblock ~27 ~114 ~153 dirt
setblock ~27 ~115 ~150 dirt
setblock ~27 ~115 ~151 dirt
setblock ~27 ~115 ~152 dirt
setblock ~27 ~115 ~153 dirt
setblock ~27 ~115 ~154 dirt
setblock ~27 ~116 ~150 dirt
setblock ~27 ~116 ~151 dirt
setblock ~27 ~116 ~152 dirt
setblock ~27 ~116 ~153 dirt
setblock ~27 ~116 ~154 dirt
setblock ~27 ~117 ~64 dirt
setblock ~27 ~117 ~108 dirt
setblock ~27 ~117 ~150 dirt
setblock ~27 ~117 ~151 dirt
setblock ~27 ~117 ~152 dirt
setblock ~27 ~117 ~153 dirt
setblock ~27 ~117 ~154 dirt
setblock ~27 ~118 ~63 dirt
setblock ~27 ~118 ~64 dirt
setblock ~27 ~118 ~65 dirt
setblock ~27 ~118 ~107 dirt
setblock ~27 ~118 ~108 dirt
setblock ~27 ~118 ~109 dirt
setblock ~27 ~118 ~149 dirt
setblock ~27 ~118 ~150 dirt
setblock ~27 ~118 ~151 dirt
setblock ~27 ~118 ~152 dirt
setblock ~27 ~118 ~153 dirt
setblock ~27 ~118 ~154 dirt
setblock ~27 ~118 ~155 dirt
setblock ~27 ~119 ~62 dirt
setblock ~27 ~119 ~63 dirt
setblock ~27 ~119 ~64 dirt
setblock ~27 ~119 ~65 dirt
setblock ~27 ~119 ~66 dirt
setblock ~27 ~119 ~105 dirt
setblock ~27 ~119 ~107 dirt
setblock ~27 ~119 ~108 dirt
setblock ~27 ~119 ~109 dirt
setblock ~27 ~119 ~110 dirt
setblock ~27 ~119 ~111 dirt
setblock ~27 ~119 ~149 dirt
setblock ~27 ~119 ~150 dirt
setblock ~27 ~119 ~151 dirt
setblock ~27 ~119 ~152 dirt
setblock ~27 ~119 ~153 dirt
setblock ~27 ~119 ~154 dirt
setblock ~27 ~119 ~155 dirt
setblock ~27 ~120 ~60 dirt
setblock ~27 ~120 ~62 dirt
setblock ~27 ~120 ~63 dirt
setblock ~27 ~120 ~64 dirt
setblock ~27 ~120 ~65 dirt
setblock ~27 ~120 ~66 dirt
setblock ~27 ~120 ~96 dirt
setblock ~27 ~120 ~104 dirt
setblock ~27 ~120 ~105 dirt
setblock ~27 ~120 ~106 dirt
setblock ~27 ~120 ~107 dirt
setblock ~27 ~120 ~108 dirt
setblock ~27 ~120 ~109 dirt
setblock ~27 ~120 ~110 dirt
setblock ~27 ~120 ~111 dirt
setblock ~27 ~120 ~149 dirt
setblock ~27 ~120 ~150 dirt
setblock ~27 ~120 ~151 dirt
setblock ~27 ~120 ~152 dirt
setblock ~27 ~120 ~153 dirt
setblock ~27 ~120 ~154 dirt
setblock ~27 ~120 ~155 dirt
setblock ~27 ~120 ~156 dirt
setblock ~27 ~121 ~59 dirt
setblock ~27 ~121 ~60 dirt
setblock ~27 ~121 ~62 dirt
setblock ~27 ~121 ~63 dirt
setblock ~27 ~121 ~64 dirt
setblock ~27 ~121 ~65 dirt
setblock ~27 ~121 ~66 dirt
setblock ~27 ~121 ~96 dirt
setblock ~27 ~121 ~103 dirt
setblock ~27 ~121 ~104 dirt
setblock ~27 ~121 ~105 dirt
setblock ~27 ~121 ~106 dirt
setblock ~27 ~121 ~107 dirt
setblock ~27 ~121 ~108 dirt
setblock ~27 ~121 ~109 dirt
setblock ~27 ~121 ~110 dirt
setblock ~27 ~121 ~111 dirt
setblock ~27 ~121 ~112 dirt
setblock ~27 ~121 ~139 dirt
setblock ~27 ~121 ~148 dirt
setblock ~27 ~121 ~149 dirt
setblock ~27 ~121 ~150 dirt
setblock ~27 ~121 ~151 dirt
setblock ~27 ~121 ~152 dirt
setblock ~27 ~121 ~153 dirt
setblock ~27 ~121 ~154 dirt
setblock ~27 ~121 ~155 dirt
setblock ~27 ~121 ~156 dirt
setblock ~27 ~121 ~157 dirt
setblock ~27 ~122 ~59 dirt
setblock ~27 ~122 ~60 dirt
setblock ~27 ~122 ~62 dirt
setblock ~27 ~122 ~63 dirt
setblock ~27 ~122 ~64 dirt
setblock ~27 ~122 ~65 dirt
setblock ~27 ~122 ~66 dirt
setblock ~27 ~122 ~96 dirt
setblock ~27 ~122 ~103 dirt
setblock ~27 ~122 ~104 dirt
setblock ~27 ~122 ~105 dirt
setblock ~27 ~122 ~106 dirt
setblock ~27 ~122 ~107 dirt
setblock ~27 ~122 ~108 dirt
setblock ~27 ~122 ~109 dirt
setblock ~27 ~122 ~110 dirt
setblock ~27 ~122 ~111 dirt
setblock ~27 ~122 ~112 dirt
setblock ~27 ~122 ~139 dirt
setblock ~27 ~122 ~148 dirt
setblock ~27 ~122 ~149 dirt
setblock ~27 ~122 ~150 dirt
setblock ~27 ~122 ~151 dirt
setblock ~27 ~122 ~152 dirt
setblock ~27 ~122 ~153 dirt
setblock ~27 ~122 ~154 dirt
setblock ~27 ~122 ~155 dirt
setblock ~27 ~122 ~156 dirt
setblock ~27 ~122 ~157 dirt
setblock ~27 ~123 ~59 dirt
setblock ~27 ~123 ~60 dirt
setblock ~27 ~123 ~62 dirt
setblock ~27 ~123 ~63 dirt
setblock ~27 ~123 ~64 dirt
setblock ~27 ~123 ~65 dirt
setblock ~27 ~123 ~66 dirt
setblock ~27 ~123 ~96 dirt
setblock ~27 ~123 ~103 dirt
setblock ~27 ~123 ~104 dirt
setblock ~27 ~123 ~105 dirt
setblock ~27 ~123 ~106 dirt
setblock ~27 ~123 ~107 dirt
setblock ~27 ~123 ~108 dirt
setblock ~27 ~123 ~109 dirt
setblock ~27 ~123 ~110 dirt
setblock ~27 ~123 ~111 dirt
setblock ~27 ~123 ~112 dirt
setblock ~27 ~123 ~139 dirt
setblock ~27 ~123 ~148 dirt
setblock ~27 ~123 ~149 dirt
setblock ~27 ~123 ~150 dirt
setblock ~27 ~123 ~151 dirt
setblock ~27 ~123 ~152 dirt
setblock ~27 ~123 ~153 dirt
setblock ~27 ~123 ~154 dirt
setblock ~27 ~123 ~155 dirt
setblock ~27 ~123 ~156 dirt
setblock ~27 ~123 ~157 dirt
setblock ~27 ~124 ~59 dirt
setblock ~27 ~124 ~60 dirt
setblock ~27 ~124 ~62 dirt
setblock ~27 ~124 ~63 dirt
setblock ~27 ~124 ~64 dirt
setblock ~27 ~124 ~65 dirt
setblock ~27 ~124 ~66 dirt
setblock ~27 ~124 ~96 dirt
setblock ~27 ~124 ~103 dirt
setblock ~27 ~124 ~104 dirt
setblock ~27 ~124 ~105 dirt
setblock ~27 ~124 ~106 dirt
setblock ~27 ~124 ~107 dirt
setblock ~27 ~124 ~108 dirt
setblock ~27 ~124 ~109 dirt
setblock ~27 ~124 ~110 dirt
setblock ~27 ~124 ~111 dirt
setblock ~27 ~124 ~112 dirt
setblock ~27 ~124 ~139 grass_block
setblock ~27 ~124 ~148 dirt
setblock ~27 ~124 ~149 dirt
setblock ~27 ~124 ~150 dirt
setblock ~27 ~124 ~151 dirt
setblock ~27 ~124 ~152 dirt
setblock ~27 ~124 ~153 dirt
setblock ~27 ~124 ~154 dirt
setblock ~27 ~124 ~155 dirt
setblock ~27 ~124 ~156 dirt
setblock ~27 ~124 ~157 dirt
setblock ~27 ~125 ~59 dirt
setblock ~27 ~125 ~60 dirt
setblock ~27 ~125 ~62 dirt
setblock ~27 ~125 ~63 dirt
setblock ~27 ~125 ~64 dirt
setblock ~27 ~125 ~65 dirt
setblock ~27 ~125 ~66 dirt
setblock ~27 ~125 ~96 grass_block
setblock ~27 ~125 ~103 dirt
setblock ~27 ~125 ~104 dirt
setblock ~27 ~125 ~105 dirt
setblock ~27 ~125 ~106 dirt
setblock ~27 ~125 ~107 dirt
setblock ~27 ~125 ~108 dirt
setblock ~27 ~125 ~109 dirt
setblock ~27 ~125 ~110 dirt
setblock ~27 ~125 ~111 dirt
setblock ~27 ~125 ~112 dirt
setblock ~27 ~125 ~139 short_grass
setblock ~27 ~125 ~148 grass_block
setblock ~27 ~125 ~149 dirt
setblock ~27 ~125 ~150 dirt
setblock ~27 ~125 ~151 dirt
setblock ~27 ~125 ~152 grass_block
setblock ~27 ~125 ~153 grass_block
setblock ~27 ~125 ~154 grass_block
setblock ~27 ~125 ~155 grass_block
setblock ~27 ~125 ~156 grass_block
setblock ~27 ~125 ~157 grass_block
setblock ~27 ~126 ~59 grass_block
setblock ~27 ~126 ~60 grass_block
setblock ~27 ~126 ~62 grass_block
setblock ~27 ~126 ~63 grass_block
setblock ~27 ~126 ~64 grass_block
setblock ~27 ~126 ~65 dirt
setblock ~27 ~126 ~66 dirt
setblock ~27 ~126 ~103 grass_block
setblock ~27 ~126 ~104 grass_block
setblock ~27 ~126 ~105 grass_block
setblock ~27 ~126 ~106 grass_block
setblock ~27 ~126 ~107 grass_block
setblock ~27 ~126 ~108 grass_block
setblock ~27 ~126 ~109 grass_block
setblock ~27 ~126 ~110 grass_block
setblock ~27 ~126 ~111 grass_block
setblock ~27 ~126 ~112 grass_block
setblock ~27 ~126 ~149 grass_block
setblock ~27 ~126 ~150 grass_block
setblock ~27 ~126 ~151 grass_block
setblock ~27 ~126 ~153 poppy
setblock ~27 ~126 ~155 short_grass
setblock ~27 ~126 ~157 poppy
setblock ~27 ~127 ~64 poppy
setblock ~27 ~127 ~65 grass_block
setblock ~27 ~127 ~66 grass_block
setblock ~27 ~127 ~110 short_grass
setblock ~27 ~127 ~111 short_grass
setblock ~28 ~114 ~108 dirt
setblock ~28 ~114 ~152 dirt
setblock ~28 ~115 ~64 dirt
setblock ~28 ~115 ~108 dirt
setblock ~28 ~115 ~109 dirt
setblock ~28 ~115 ~151 dirt
setblock ~28 ~115 ~152 dirt
setblock ~28 ~115 ~153 dirt
setblock ~28 ~116 ~64 dirt
setblock ~28 ~116 ~107 dirt
setblock ~28 ~116 ~108 dirt
setblock ~28 ~116 ~109 dirt
setblock ~28 ~116 ~110 dirt
setblock ~28 ~116 ~151 dirt
setblock ~28 ~116 ~152 dirt
setblock ~28 ~116 ~153 dirt
setblock ~28 ~116 ~154 dirt
setblock ~28 ~117 ~63 dirt
setblock ~28 ~117 ~64 dirt
setblock ~28 ~117 ~65 dirt
setblock ~28 ~117 ~107 dirt
setblock ~28 ~117 ~108 dirt
setblock ~28 ~117 ~109 dirt
setblock ~28 ~117 ~110 dirt
setblock ~28 ~117 ~111 dirt
setblock ~28 ~117 ~151 dirt
setblock ~28 ~117 ~152 dirt
setblock ~28 ~117 ~153 dirt
setblock ~28 ~117 ~154 dirt
setblock ~28 ~118 ~59 dirt
setblock ~28 ~118 ~60 dirt
setblock ~28 ~118 ~63 dirt
setblock ~28 ~118 ~64 dirt
setblock ~28 ~118 ~65 dirt
setblock ~28 ~118 ~66 dirt
setblock ~28 ~118 ~104 dirt
setblock ~28 ~118 ~105 dirt
setblock ~28 ~118 ~106 dirt
setblock ~28 ~118 ~107 dirt
setblock ~28 ~118 ~108 dirt
setblock ~28 ~118 ~109 dirt
setblock ~28 ~118 ~110 dirt
setblock ~28 ~118 ~111 dirt
setblock ~28 ~118 ~150 dirt
setblock ~28 ~118 ~151 dirt
setblock ~28 ~118 ~152 dirt
setblock ~28 ~118 ~153 dirt
setblock ~28 ~118 ~154 dirt
setblock ~28 ~119 ~59 dirt
setblock ~28 ~119 ~60 dirt
setblock ~28 ~119 ~62 dirt
setblock ~28 ~119 ~63 dirt
setblock ~28 ~119 ~64 dirt
setblock ~28 ~119 ~65 dirt
setblock ~28 ~119 ~66 dirt
setblock ~28 ~119 ~104 dirt
setblock ~28 ~119 ~105 dirt
setblock ~28 ~119 ~106 dirt
setblock ~28 ~119 ~107 dirt
setblock ~28 ~119 ~108 dirt
setblock ~28 ~119 ~109 dirt
setblock ~28 ~119 ~110 dirt
setblock ~28 ~119 ~111 dirt
setblock ~28 ~119 ~112 dirt
setblock ~28 ~119 ~149 dirt
setblock ~28 ~119 ~150 dirt
setblock ~28 ~119 ~151 dirt
setblock ~28 ~119 ~152 dirt
setblock ~28 ~119 ~153 dirt
setblock ~28 ~119 ~154 dirt
setblock ~28 ~120 ~58 dirt
setblock ~28 ~120 ~59 dirt
setblock ~28 ~120 ~60 dirt
setblock ~28 ~120 ~61 dirt
setblock ~28 ~120 ~62 dirt
setblock ~28 ~120 ~63 dirt
setblock ~28 ~120 ~64 dirt
setblock ~28 ~120 ~65 dirt
setblock ~28 ~120 ~66 dirt
setblock ~28 ~120 ~104 dirt
setblock ~28 ~120 ~105 dirt
setblock ~28 ~120 ~106 dirt
setblock ~28 ~120 ~107 dirt
setblock ~28 ~120 ~108 dirt
setblock ~28 ~120 ~109 dirt
setblock ~28 ~120 ~110 dirt
setblock ~28 ~120 ~111 dirt
setblock ~28 ~120 ~112 dirt
setblock ~28 ~120 ~123 dirt
setblock ~28 ~120 ~138 dirt
setblock ~28 ~120 ~139 dirt
setblock ~28 ~120 ~149 dirt
setblock ~28 ~120 ~150 dirt
setblock ~28 ~120 ~151 dirt
setblock ~28 ~120 ~152 dirt
setblock ~28 ~120 ~153 dirt
setblock ~28 ~120 ~154 dirt
setblock ~28 ~120 ~155 dirt
setblock ~28 ~121 ~57 dirt
setblock ~28 ~121 ~58 dirt
setblock ~28 ~121 ~59 dirt
setblock ~28 ~121 ~60 dirt
setblock ~28 ~121 ~61 dirt
setblock ~28 ~121 ~62 dirt
setblock ~28 ~121 ~63 dirt
setblock ~28 ~121 ~64 dirt
setblock ~28 ~121 ~65 dirt
setblock ~28 ~121 ~66 dirt
setblock ~28 ~121 ~67 dirt
setblock ~28 ~121 ~104 dirt
setblock ~28 ~121 ~105 dirt
setblock ~28 ~121 ~106 dirt
setblock ~28 ~121 ~107 dirt
setblock ~28 ~121 ~108 dirt
setblock ~28 ~121 ~109 dirt
setblock ~28 ~121 ~110 dirt
setblock ~28 ~121 ~111 dirt
setblock ~28 ~121 ~112 dirt
setblock ~28 ~121 ~113 dirt
setblock ~28 ~121 ~123 dirt
setblock ~28 ~121 ~124 dirt
setblock ~28 ~121 ~125 dirt
setblock ~28 ~121 ~130 dirt
setblock ~28 ~121 ~138 dirt
setblock ~28 ~121 ~139 dirt
setblock ~28 ~121 ~140 dirt
setblock ~28 ~121 ~141 dirt
setblock ~28 ~121 ~149 dirt
setblock ~28 ~121 ~150 dirt
setblock ~28 ~121 ~151 dirt
setblock ~28 ~121 ~152 dirt
setblock ~28 ~121 ~153 dirt
setblock ~28 ~121 ~154 dirt
setblock ~28 ~121 ~155 dirt
setblock ~28 ~121 ~156 dirt
setblock ~28 ~122 ~57 dirt
setblock ~28 ~122 ~58 dirt
setblock ~28 ~122 ~59 dirt
setblock ~28 ~122 ~60 dirt
setblock ~28 ~122 ~61 dirt
setblock ~28 ~122 ~62 dirt
setblock ~28 ~122 ~63 dirt
setblock ~28 ~122 ~64 dirt
setblock ~28 ~122 ~65 dirt
setblock ~28 ~122 ~66 dirt
setblock ~28 ~122 ~67 dirt
setblock ~28 ~122 ~104 dirt
setblock ~28 ~122 ~105 dirt
setblock ~28 ~122 ~106 dirt
setblock ~28 ~122 ~107 dirt
setblock ~28 ~122 ~108 dirt
setblock ~28 ~122 ~109 dirt
setblock ~28 ~122 ~110 dirt
setblock ~28 ~122 ~111 dirt
setblock ~28 ~122 ~112 dirt
setblock ~28 ~122 ~113 dirt
setblock ~28 ~122 ~123 dirt
setblock ~28 ~122 ~124 dirt
setblock ~28 ~122 ~125 dirt
setblock ~28 ~122 ~130 dirt
setblock ~28 ~122 ~138 dirt
setblock ~28 ~122 ~139 dirt
setblock ~28 ~122 ~140 dirt
setblock ~28 ~122 ~141 dirt
setblock ~28 ~122 ~149 dirt
setblock ~28 ~122 ~150 dirt
setblock ~28 ~122 ~151 dirt
setblock ~28 ~122 ~152 dirt
setblock ~28 ~122 ~153 dirt
setblock ~28 ~122 ~154 dirt
setblock ~28 ~122 ~155 dirt
setblock ~28 ~122 ~156 dirt
setblock ~28 ~123 ~57 dirt
setblock ~28 ~123 ~58 dirt
setblock ~28 ~123 ~59 dirt
setblock ~28 ~123 ~60 dirt
setblock ~28 ~123 ~61 dirt
setblock ~28 ~123 ~62 dirt
setblock ~28 ~123 ~63 dirt
setblock ~28 ~123 ~64 dirt
setblock ~28 ~123 ~65 dirt
setblock ~28 ~123 ~66 dirt
setblock ~28 ~123 ~67 dirt
setblock ~28 ~123 ~104 dirt
setblock ~28 ~123 ~105 dirt
setblock ~28 ~123 ~106 dirt
setblock ~28 ~123 ~107 dirt
setblock ~28 ~123 ~108 dirt
setblock ~28 ~123 ~109 dirt
setblock ~28 ~123 ~110 dirt
setblock ~28 ~123 ~111 dirt
setblock ~28 ~123 ~112 dirt
setblock ~28 ~123 ~113 dirt
setblock ~28 ~123 ~123 dirt
setblock ~28 ~123 ~124 dirt
setblock ~28 ~123 ~125 dirt
setblock ~28 ~123 ~130 dirt
setblock ~28 ~123 ~138 dirt
setblock ~28 ~123 ~139 dirt
setblock ~28 ~123 ~140 dirt
setblock ~28 ~123 ~141 dirt
setblock ~28 ~123 ~149 dirt
setblock ~28 ~123 ~150 dirt
setblock ~28 ~123 ~151 dirt
setblock ~28 ~123 ~152 dirt
setblock ~28 ~123 ~153 dirt
setblock ~28 ~123 ~154 dirt
setblock ~28 ~123 ~155 dirt
setblock ~28 ~123 ~156 dirt
setblock ~28 ~124 ~57 dirt
setblock ~28 ~124 ~58 dirt
setblock ~28 ~124 ~59 dirt
setblock ~28 ~124 ~60 dirt
setblock ~28 ~124 ~61 dirt
setblock ~28 ~124 ~62 dirt
setblock ~28 ~124 ~63 dirt
setblock ~28 ~124 ~64 dirt
setblock ~28 ~124 ~65 dirt
setblock ~28 ~124 ~66 dirt
setblock ~28 ~124 ~67 dirt
setblock ~28 ~124 ~104 dirt
setblock ~28 ~124 ~105 dirt
setblock ~28 ~124 ~106 dirt
setblock ~28 ~124 ~107 dirt
setblock ~28 ~124 ~108 dirt
setblock ~28 ~124 ~109 dirt
setblock ~28 ~124 ~110 dirt
setblock ~28 ~124 ~111 dirt
setblock ~28 ~124 ~112 dirt
setblock ~28 ~124 ~113 dirt
setblock ~28 ~124 ~123 dirt
setblock ~28 ~124 ~124 dirt
setblock ~28 ~124 ~125 dirt
setblock ~28 ~124 ~130 dirt
setblock ~28 ~124 ~138 dirt
setblock ~28 ~124 ~139 dirt
setblock ~28 ~124 ~140 dirt
setblock ~28 ~124 ~141 dirt
setblock ~28 ~124 ~149 dirt
setblock ~28 ~124 ~150 dirt
setblock ~28 ~124 ~151 dirt
setblock ~28 ~124 ~152 dirt
setblock ~28 ~124 ~153 dirt
setblock ~28 ~124 ~154 dirt
setblock ~28 ~124 ~155 dirt
setblock ~28 ~124 ~156 grass_block
setblock ~28 ~125 ~57 dirt
setblock ~28 ~125 ~58 dirt
setblock ~28 ~125 ~59 dirt
setblock ~28 ~125 ~60 dirt
setblock ~28 ~125 ~61 dirt
setblock ~28 ~125 ~62 dirt
setblock ~28 ~125 ~63 dirt
setblock ~28 ~125 ~64 dirt
setblock ~28 ~125 ~65 dirt
setblock ~28 ~125 ~66 dirt
setblock ~28 ~125 ~67 dirt
setblock ~28 ~125 ~104 dirt
setblock ~28 ~125 ~105 dirt
setblock ~28 ~125 ~106 dirt
setblock ~28 ~125 ~107 dirt
setblock ~28 ~125 ~108 dirt
setblock ~28 ~125 ~109 dirt
setblock ~28 ~125 ~110 dirt
setblock ~28 ~125 ~111 dirt
setblock ~28 ~125 ~112 dirt
setblock ~28 ~125 ~113 dirt
setblock ~28 ~125 ~123 dirt
setblock ~28 ~125 ~124 dirt
setblock ~28 ~125 ~125 grass_block
setblock ~28 ~125 ~130 grass_block
setblock ~28 ~125 ~138 grass_block
setblock ~28 ~125 ~139 grass_block
setblock ~28 ~125 ~140 grass_block
setblock ~28 ~125 ~141 grass_block
setblock ~28 ~125 ~149 dirt
setblock ~28 ~125 ~150 dirt
setblock ~28 ~125 ~151 dirt
setblock ~28 ~125 ~152 grass_block
setblock ~28 ~125 ~153 grass_block
setblock ~28 ~125 ~154 grass_block
setblock ~28 ~125 ~155 grass_block
setblock ~28 ~126 ~57 grass_block
setblock ~28 ~126 ~58 grass_block
setblock ~28 ~126 ~59 grass_block
setblock ~28 ~126 ~60 grass_block
setblock ~28 ~126 ~61 grass_block
setblock ~28 ~126 ~62 grass_block
setblock ~28 ~126 ~63 dirt
setblock ~28 ~126 ~64 dirt
setblock ~28 ~126 ~65 dirt
setblock ~28 ~126 ~66 dirt
setblock ~28 ~126 ~67 dirt
setblock ~28 ~126 ~104 grass_block
setblock ~28 ~126 ~105 grass_block
setblock ~28 ~126 ~106 grass_block
setblock ~28 ~126 ~107 grass_block
setblock ~28 ~126 ~108 grass_block
setblock ~28 ~126 ~109 grass_block
setblock ~28 ~126 ~110 grass_block
setblock ~28 ~126 ~111 grass_block
setblock ~28 ~126 ~112 grass_block
setblock ~28 ~126 ~113 grass_block
setblock ~28 ~126 ~123 grass_block
setblock ~28 ~126 ~124 grass_block
setblock ~28 ~126 ~138 short_grass
setblock ~28 ~126 ~139 short_grass
setblock ~28 ~126 ~140 fern
setblock ~28 ~126 ~149 grass_block
setblock ~28 ~126 ~150 grass_block
setblock ~28 ~126 ~151 grass_block
setblock ~28 ~126 ~153 poppy
setblock ~28 ~127 ~57 fern
setblock ~28 ~127 ~60 fern
setblock ~28 ~127 ~63 grass_block
setblock ~28 ~127 ~64 grass_block
setblock ~28 ~127 ~65 grass_block
setblock ~28 ~127 ~66 grass_block
setblock ~28 ~127 ~67 grass_block
setblock ~28 ~128 ~65 short_grass
setblock ~29 ~113 ~64 dirt
setblock ~29 ~113 ~108 dirt
setblock ~29 ~114 ~64 dirt
setblock ~29 ~114 ~107 dirt
setblock ~29 ~114 ~108 dirt
setblock ~29 ~114 ~109 dirt
setblock ~29 ~114 ~110 dirt
setblock ~29 ~115 ~60 dirt
setblock ~29 ~115 ~63 dirt
setblock ~29 ~115 ~64 dirt
setblock ~29 ~115 ~65 dirt
setblock ~29 ~115 ~106 dirt
setblock ~29 ~115 ~107 dirt
setblock ~29 ~115 ~108 dirt
setblock ~29 ~115 ~109 dirt
setblock ~29 ~115 ~110 dirt
setblock ~29 ~116 ~60 dirt
setblock ~29 ~116 ~63 dirt
setblock ~29 ~116 ~64 dirt
setblock ~29 ~116 ~65 dirt
setblock ~29 ~116 ~105 dirt
setblock ~29 ~116 ~106 dirt
setblock ~29 ~116 ~107 dirt
setblock ~29 ~116 ~108 dirt
setblock ~29 ~116 ~109 dirt
setblock ~29 ~116 ~110 dirt
setblock ~29 ~116 ~111 dirt
setblock ~29 ~116 ~153 dirt
setblock ~29 ~117 ~59 dirt
setblock ~29 ~117 ~60 dirt
setblock ~29 ~117 ~62 dirt
setblock ~29 ~117 ~63 dirt
setblock ~29 ~117 ~64 dirt
setblock ~29 ~117 ~65 dirt
setblock ~29 ~117 ~66 dirt
setblock ~29 ~117 ~104 dirt
setblock ~29 ~117 ~105 dirt
setblock ~29 ~117 ~106 dirt
setblock ~29 ~117 ~107 dirt
setblock ~29 ~117 ~108 dirt
setblock ~29 ~117 ~109 dirt
setblock ~29 ~117 ~110 dirt
setblock ~29 ~117 ~111 dirt
setblock ~29 ~117 ~112 dirt
setblock ~29 ~117 ~123 dirt
setblock ~29 ~117 ~153 dirt
setblock ~29 ~118 ~58 dirt
setblock ~29 ~118 ~59 dirt
setblock ~29 ~118 ~60 dirt
setblock ~29 ~118 ~61 dirt
setblock ~29 ~118 ~62 dirt
setblock ~29 ~118 ~63 dirt
setblock ~29 ~118 ~64 dirt
setblock ~29 ~118 ~65 dirt
setblock ~29 ~118 ~66 dirt
setblock ~29 ~118 ~67 dirt
setblock ~29 ~118 ~103 dirt
setblock ~29 ~118 ~104 dirt
setblock ~29 ~118 ~105 dirt
setblock ~29 ~118 ~106 dirt
setblock ~29 ~118 ~107 dirt
setblock ~29 ~118 ~108 dirt
setblock ~29 ~118 ~109 dirt
setblock ~29 ~118 ~110 dirt
setblock ~29 ~118 ~111 dirt
setblock ~29 ~118 ~112 dirt
setblock ~29 ~118 ~123 dirt
setblock ~29 ~118 ~128 dirt
setblock ~29 ~118 ~129 dirt
setblock ~29 ~118 ~139 dirt
setblock ~29 ~118 ~151 dirt
setblock ~29 ~118 ~152 dirt
setblock ~29 ~118 ~153 dirt
setblock ~29 ~119 ~58 dirt
setblock ~29 ~119 ~59 dirt
setblock ~29 ~119 ~60 dirt
setblock ~29 ~119 ~61 dirt
setblock ~29 ~119 ~62 dirt
setblock ~29 ~119 ~63 dirt
setblock ~29 ~119 ~64 dirt
setblock ~29 ~119 ~65 dirt
setblock ~29 ~119 ~66 dirt
setblock ~29 ~119 ~67 dirt
setblock ~29 ~119 ~103 dirt
setblock ~29 ~119 ~104 dirt
setblock ~29 ~119 ~105 dirt
setblock ~29 ~119 ~106 dirt
setblock ~29 ~119 ~107 dirt
setblock ~29 ~119 ~108 dirt
setblock ~29 ~119 ~109 dirt
setblock ~29 ~119 ~110 dirt
setblock ~29 ~119 ~111 dirt
setblock ~29 ~119 ~112 dirt
setblock ~29 ~119 ~122 dirt
setblock ~29 ~119 ~123 dirt
setblock ~29 ~119 ~125 dirt
setblock ~29 ~119 ~128 dirt
setblock ~29 ~119 ~129 dirt
setblock ~29 ~119 ~130 dirt
setblock ~29 ~119 ~138 dirt
setblock ~29 ~119 ~139 dirt
setblock ~29 ~119 ~140 dirt
setblock ~29 ~119 ~150 dirt
setblock ~29 ~119 ~151 dirt
setblock ~29 ~119 ~152 dirt
setblock ~29 ~119 ~153 dirt
setblock ~29 ~119 ~154 dirt
setblock ~29 ~120 ~57 dirt
setblock ~29 ~120 ~58 dirt
setblock ~29 ~120 ~59 dirt
setblock ~29 ~120 ~60 dirt
setblock ~29 ~120 ~61 dirt
setblock ~29 ~120 ~62 dirt
setblock ~29 ~120 ~63 dirt
setblock ~29 ~120 ~64 dirt
setblock ~29 ~120 ~65 dirt
setblock ~29 ~120 ~66 dirt
setblock ~29 ~120 ~67 dirt
setblock ~29 ~120 ~103 dirt
setblock ~29 ~120 ~104 dirt
setblock ~29 ~120 ~105 dirt
setblock ~29 ~120 ~106 dirt
setblock ~29 ~120 ~107 dirt
setblock ~29 ~120 ~108 dirt
setblock ~29 ~120 ~109 dirt
setblock ~29 ~120 ~110 dirt
setblock ~29 ~120 ~111 dirt
setblock ~29 ~120 ~112 dirt
setblock ~29 ~120 ~122 dirt
setblock ~29 ~120 ~123 dirt
setblock ~29 ~120 ~124 dirt
setblock ~29 ~120 ~125 dirt
setblock ~29 ~120 ~127 dirt
setblock ~29 ~120 ~128 dirt
setblock ~29 ~120 ~129 dirt
setblock ~29 ~120 ~130 dirt
setblock ~29 ~120 ~137 dirt
setblock ~29 ~120 ~138 dirt
setblock ~29 ~120 ~139 dirt
setblock ~29 ~120 ~140 dirt
setblock ~29 ~120 ~141 dirt
setblock ~29 ~120 ~150 dirt
setblock ~29 ~120 ~151 dirt
setblock ~29 ~120 ~152 dirt
setblock ~29 ~120 ~153 dirt
setblock ~29 ~120 ~154 dirt
setblock ~29 ~121 ~56 dirt
setblock ~29 ~121 ~57 dirt
setblock ~29 ~121 ~58 dirt
setblock ~29 ~121 ~59 dirt
setblock ~29 ~121 ~60 dirt
setblock ~29 ~121 ~61 dirt
setblock ~29 ~121 ~62 dirt
setblock ~29 ~121 ~63 dirt
setblock ~29 ~121 ~64 dirt
setblock ~29 ~121 ~65 dirt
setblock ~29 ~121 ~66 dirt
setblock ~29 ~121 ~67 dirt
setblock ~29 ~121 ~68 dirt
setblock ~29 ~121 ~103 dirt
setblock ~29 ~121 ~104 dirt
setblock ~29 ~121 ~105 dirt
setblock ~29 ~121 ~106 dirt
setblock ~29 ~121 ~107 dirt
setblock ~29 ~121 ~108 dirt
setblock ~29 ~121 ~109 dirt
setblock ~29 ~121 ~110 dirt
setblock ~29 ~121 ~111 dirt
setblock ~29 ~121 ~112 dirt
setblock ~29 ~121 ~113 dirt
setblock ~29 ~121 ~121 dirt
setblock ~29 ~121 ~122 dirt
setblock ~29 ~121 ~123 dirt
setblock ~29 ~121 ~124 dirt
setblock ~29 ~121 ~125 dirt
setblock ~29 ~121 ~126 dirt
setblock ~29 ~121 ~127 dirt
setblock ~29 ~121 ~128 dirt
setblock ~29 ~121 ~129 dirt
setblock ~29 ~121 ~130 dirt
setblock ~29 ~121 ~131 dirt
setblock ~29 ~121 ~136 dirt
setblock ~29 ~121 ~137 dirt
setblock ~29 ~121 ~138 dirt
setblock ~29 ~121 ~139 dirt
setblock ~29 ~121 ~140 dirt
setblock ~29 ~121 ~141 dirt
setblock ~29 ~121 ~142 dirt
setblock ~29 ~121 ~150 dirt
setblock ~29 ~121 ~151 dirt
setblock ~29 ~121 ~152 dirt
setblock ~29 ~121 ~153 dirt
setblock ~29 ~121 ~154 dirt
setblock ~29 ~121 ~155 dirt
setblock ~29 ~122 ~56 dirt
setblock ~29 ~122 ~57 dirt
setblock ~29 ~122 ~58 dirt
setblock ~29 ~122 ~59 dirt
setblock ~29 ~122 ~60 dirt
setblock ~29 ~122 ~61 dirt
setblock ~29 ~122 ~62 dirt
setblock ~29 ~122 ~63 dirt
setblock ~29 ~122 ~64 dirt
setblock ~29 ~122 ~65 dirt
setblock ~29 ~122 ~66 dirt
setblock ~29 ~122 ~67 dirt
setblock ~29 ~122 ~68 dirt
setblock ~29 ~122 ~103 dirt
setblock ~29 ~122 ~104 dirt
setblock ~29 ~122 ~105 dirt
setblock ~29 ~122 ~106 dirt
setblock ~29 ~122 ~107 dirt
setblock ~29 ~122 ~108 dirt
setblock ~29 ~122 ~109 dirt
setblock ~29 ~122 ~110 dirt
setblock ~29 ~122 ~111 dirt
setblock ~29 ~122 ~112 dirt
setblock ~29 ~122 ~113 dirt
setblock ~29 ~122 ~121 dirt
setblock ~29 ~122 ~122 dirt
setblock ~29 ~122 ~123 dirt
setblock ~29 ~122 ~124 dirt
setblock ~29 ~122 ~125 dirt
setblock ~29 ~122 ~126 dirt
setblock ~29 ~122 ~127 dirt
setblock ~29 ~122 ~128 dirt
setblock ~29 ~122 ~129 dirt
setblock ~29 ~122 ~130 dirt
setblock ~29 ~122 ~131 dirt
setblock ~29 ~122 ~136 dirt
setblock ~29 ~122 ~137 dirt
setblock ~29 ~122 ~138 dirt
setblock ~29 ~122 ~139 dirt
setblock ~29 ~122 ~140 dirt
setblock ~29 ~122 ~141 dirt
setblock ~29 ~122 ~142 dirt
setblock ~29 ~122 ~150 dirt
setblock ~29 ~122 ~151 dirt
setblock ~29 ~122 ~152 dirt
setblock ~29 ~122 ~153 dirt
setblock ~29 ~122 ~154 dirt
setblock ~29 ~122 ~155 dirt
setblock ~29 ~123 ~56 dirt
setblock ~29 ~123 ~57 dirt
setblock ~29 ~123 ~58 dirt
setblock ~29 ~123 ~59 dirt
setblock ~29 ~123 ~60 dirt
setblock ~29 ~123 ~61 dirt
setblock ~29 ~123 ~62 dirt
setblock ~29 ~123 ~63 dirt
setblock ~29 ~123 ~64 dirt
setblock ~29 ~123 ~65 dirt
setblock ~29 ~123 ~66 dirt
setblock ~29 ~123 ~67 dirt
setblock ~29 ~123 ~68 dirt
setblock ~29 ~123 ~103 dirt
setblock ~29 ~123 ~104 dirt
setblock ~29 ~123 ~105 dirt
setblock ~29 ~123 ~106 dirt
setblock ~29 ~123 ~107 dirt
setblock ~29 ~123 ~108 dirt
setblock ~29 ~123 ~109 dirt
setblock ~29 ~123 ~110 dirt
setblock ~29 ~123 ~111 dirt
setblock ~29 ~123 ~112 dirt
setblock ~29 ~123 ~113 dirt
setblock ~29 ~123 ~121 dirt
setblock ~29 ~123 ~122 dirt
setblock ~29 ~123 ~123 dirt
setblock ~29 ~123 ~124 dirt
setblock ~29 ~123 ~125 dirt
setblock ~29 ~123 ~126 dirt
setblock ~29 ~123 ~127 dirt
setblock ~29 ~123 ~128 dirt
setblock ~29 ~123 ~129 dirt
setblock ~29 ~123 ~130 dirt
setblock ~29 ~123 ~131 dirt
setblock ~29 ~123 ~136 dirt
setblock ~29 ~123 ~137 dirt
setblock ~29 ~123 ~138 dirt
setblock ~29 ~123 ~139 dirt
setblock ~29 ~123 ~140 dirt
setblock ~29 ~123 ~141 dirt
setblock ~29 ~123 ~142 dirt
setblock ~29 ~123 ~150 dirt
setblock ~29 ~123 ~151 dirt
setblock ~29 ~123 ~152 dirt
setblock ~29 ~123 ~153 dirt
setblock ~29 ~123 ~154 dirt
setblock ~29 ~123 ~155 dirt
setblock ~29 ~124 ~56 dirt
setblock ~29 ~124 ~57 dirt
setblock ~29 ~124 ~58 dirt
setblock ~29 ~124 ~59 dirt
setblock ~29 ~124 ~60 dirt
setblock ~29 ~124 ~61 dirt
setblock ~29 ~124 ~62 dirt
setblock ~29 ~124 ~63 dirt
setblock ~29 ~124 ~64 dirt
setblock ~29 ~124 ~65 dirt
setblock ~29 ~124 ~66 dirt
setblock ~29 ~124 ~67 dirt
setblock ~29 ~124 ~68 dirt
setblock ~29 ~124 ~103 dirt
setblock ~29 ~124 ~104 dirt
setblock ~29 ~124 ~105 dirt
setblock ~29 ~124 ~106 dirt
setblock ~29 ~124 ~107 dirt
setblock ~29 ~124 ~108 dirt
setblock ~29 ~124 ~109 dirt
setblock ~29 ~124 ~110 dirt
setblock ~29 ~124 ~111 dirt
setblock ~29 ~124 ~112 dirt
setblock ~29 ~124 ~113 dirt
setblock ~29 ~124 ~121 dirt
setblock ~29 ~124 ~122 dirt
setblock ~29 ~124 ~123 dirt
setblock ~29 ~124 ~124 dirt
setblock ~29 ~124 ~125 dirt
setblock ~29 ~124 ~126 dirt
setblock ~29 ~124 ~127 dirt
setblock ~29 ~124 ~128 dirt
setblock ~29 ~124 ~129 dirt
setblock ~29 ~124 ~130 dirt
setblock ~29 ~124 ~131 dirt
setblock ~29 ~124 ~136 dirt
setblock ~29 ~124 ~137 dirt
setblock ~29 ~124 ~138 dirt
setblock ~29 ~124 ~139 dirt
setblock ~29 ~124 ~140 dirt
setblock ~29 ~124 ~141 dirt
setblock ~29 ~124 ~142 dirt
setblock ~29 ~124 ~150 dirt
setblock ~29 ~124 ~151 dirt
setblock ~29 ~124 ~152 dirt
setblock ~29 ~124 ~153 dirt
setblock ~29 ~124 ~154 dirt
setblock ~29 ~124 ~155 grass_block
setblock ~29 ~125 ~56 dirt
setblock ~29 ~125 ~57 dirt
setblock ~29 ~125 ~58 dirt
setblock ~29 ~125 ~59 dirt
setblock ~29 ~125 ~60 dirt
setblock ~29 ~125 ~61 dirt
setblock ~29 ~125 ~62 dirt
setblock ~29 ~125 ~63 dirt
setblock ~29 ~125 ~64 dirt
setblock ~29 ~125 ~65 dirt
setblock ~29 ~125 ~66 dirt
setblock ~29 ~125 ~67 dirt
setblock ~29 ~125 ~68 dirt
setblock ~29 ~125 ~103 dirt
setblock ~29 ~125 ~104 dirt
setblock ~29 ~125 ~105 dirt
setblock ~29 ~125 ~106 dirt
setblock ~29 ~125 ~107 dirt
setblock ~29 ~125 ~108 dirt
setblock ~29 ~125 ~109 dirt
setblock ~29 ~125 ~110 dirt
setblock ~29 ~125 ~111 dirt
setblock ~29 ~125 ~112 dirt
setblock ~29 ~125 ~113 dirt
setblock ~29 ~125 ~121 dirt
setblock ~29 ~125 ~122 dirt
setblock ~29 ~125 ~123 dirt
setblock ~29 ~125 ~124 dirt
setblock ~29 ~125 ~125 dirt
setblock ~29 ~125 ~126 dirt
setblock ~29 ~125 ~127 dirt
setblock ~29 ~125 ~128 dirt
setblock ~29 ~125 ~129 dirt
setblock ~29 ~125 ~130 dirt
setblock ~29 ~125 ~131 dirt
setblock ~29 ~125 ~136 dirt
setblock ~29 ~125 ~137 dirt
setblock ~29 ~125 ~138 dirt
setblock ~29 ~125 ~139 dirt
setblock ~29 ~125 ~140 dirt
setblock ~29 ~125 ~141 dirt
setblock ~29 ~125 ~142 dirt
setblock ~29 ~125 ~150 dirt
setblock ~29 ~125 ~151 dirt
setblock ~29 ~125 ~152 grass_block
setblock ~29 ~125 ~153 grass_block
setblock ~29 ~125 ~154 grass_block
setblock ~29 ~125 ~155 fern
setblock ~29 ~126 ~56 grass_block
setblock ~29 ~126 ~57 grass_block
setblock ~29 ~126 ~58 grass_block
setblock ~29 ~126 ~59 grass_block
setblock ~29 ~126 ~60 dirt
setblock ~29 ~126 ~61 dirt
setblock ~29 ~126 ~62 dirt
setblock ~29 ~126 ~63 dirt
setblock ~29 ~126 ~64 dirt
setblock ~29 ~126 ~65 dirt
setblock ~29 ~126 ~66 dirt
setblock ~29 ~126 ~67 dirt
setblock ~29 ~126 ~68 dirt
setblock ~29 ~126 ~103 grass_block
setblock ~29 ~126 ~104 grass_block
setblock ~29 ~126 ~105 grass_block
setblock ~29 ~126 ~106 grass_block
setblock ~29 ~126 ~107 grass_block
setblock ~29 ~126 ~108 grass_block
setblock ~29 ~126 ~109 dirt
setblock ~29 ~126 ~110 dirt
setblock ~29 ~126 ~111 dirt
setblock ~29 ~126 ~112 dirt
setblock ~29 ~126 ~113 dirt
setblock ~29 ~126 ~121 grass_block
setblock ~29 ~126 ~122 grass_block
setblock ~29 ~126 ~123 grass_block
setblock ~29 ~126 ~124 grass_block
setblock ~29 ~126 ~125 grass_block
setblock ~29 ~126 ~126 grass_block
setblock ~29 ~126 ~127 grass_block
setblock ~29 ~126 ~128 grass_block
setblock ~29 ~126 ~129 grass_block
setblock ~29 ~126 ~130 grass_block
setblock ~29 ~126 ~131 grass_block
setblock ~29 ~126 ~136 grass_block
setblock ~29 ~126 ~137 grass_block
setblock ~29 ~126 ~138 grass_block
setblock ~29 ~126 ~139 grass_block
setblock ~29 ~126 ~140 grass_block
setblock ~29 ~126 ~141 grass_block
setblock ~29 ~126 ~142 grass_block
setblock ~29 ~126 ~150 grass_block
setblock ~29 ~126 ~151 grass_block
setblock ~29 ~127 ~60 grass_block
setblock ~29 ~127 ~61 grass_block
setblock ~29 ~127 ~62 grass_block
setblock ~29 ~127 ~63 grass_block
setblock ~29 ~127 ~64 grass_block
setblock ~29 ~127 ~65 grass_block
setblock ~29 ~127 ~66 grass_block
setblock ~29 ~127 ~67 grass_block
setblock ~29 ~127 ~68 grass_block
setblock ~29 ~127 ~103 short_grass
setblock ~29 ~127 ~106 short_grass
setblock ~29 ~127 ~107 short_grass
setblock ~29 ~127 ~109 grass_block
setblock ~29 ~127 ~110 grass_block
setblock ~29 ~127 ~111 grass_block
setblock ~29 ~127 ~112 grass_block
setblock ~29 ~127 ~113 grass_block
setblock ~29 ~127 ~127 short_grass
setblock ~29 ~127 ~131 short_grass
setblock ~29 ~127 ~137 short_grass
setblock ~29 ~127 ~138 short_grass
setblock ~29 ~127 ~150 short_grass
setblock ~29 ~127 ~151 short_grass
setblock ~29 ~128 ~60 short_grass
setblock ~29 ~128 ~61 short_grass
setblock ~29 ~128 ~63 poppy
setblock ~29 ~128 ~64 short_grass
setblock ~29 ~128 ~111 fern
setblock ~30 ~110 ~108 dirt
setblock ~30 ~111 ~107 dirt
setblock ~30 ~111 ~108 dirt
setblock ~30 ~112 ~106 dirt
setblock ~30 ~112 ~107 dirt
setblock ~30 ~112 ~108 dirt
setblock ~30 ~112 ~109 dirt
setblock ~30 ~113 ~106 dirt
setblock ~30 ~113 ~107 dirt
setblock ~30 ~113 ~108 dirt
setblock ~30 ~113 ~109 dirt
setblock ~30 ~113 ~110 dirt
setblock ~30 ~114 ~60 dirt
setblock ~30 ~114 ~106 dirt
setblock ~30 ~114 ~107 dirt
setblock ~30 ~114 ~108 dirt
setblock ~30 ~114 ~109 dirt
setblock ~30 ~114 ~110 dirt
setblock ~30 ~114 ~111 dirt
setblock ~30 ~115 ~59 dirt
setblock ~30 ~115 ~60 dirt
setblock ~30 ~115 ~61 dirt
setblock ~30 ~115 ~64 dirt
setblock ~30 ~115 ~105 dirt
setblock ~30 ~115 ~106 dirt
setblock ~30 ~115 ~107 dirt
setblock ~30 ~115 ~108 dirt
setblock ~30 ~115 ~109 dirt
setblock ~30 ~115 ~110 dirt
setblock ~30 ~115 ~111 dirt
setblock ~30 ~115 ~123 dirt
setblock ~30 ~115 ~128 dirt
setblock ~30 ~116 ~59 dirt
setblock ~30 ~116 ~60 dirt
setblock ~30 ~116 ~61 dirt
setblock ~30 ~116 ~62 dirt
setblock ~30 ~116 ~64 dirt
setblock ~30 ~116 ~104 dirt
setblock ~30 ~116 ~105 dirt
setblock ~30 ~116 ~106 dirt
setblock ~30 ~116 ~107 dirt
setblock ~30 ~116 ~108 dirt
setblock ~30 ~116 ~109 dirt
setblock ~30 ~116 ~110 dirt
setblock ~30 ~116 ~111 dirt
setblock ~30 ~116 ~123 dirt
setblock ~30 ~116 ~128 dirt
setblock ~30 ~116 ~129 dirt
setblock ~30 ~116 ~140 dirt
setblock ~30 ~117 ~58 dirt
setblock ~30 ~117 ~59 dirt
setblock ~30 ~117 ~60 dirt
setblock ~30 ~117 ~61 dirt
setblock ~30 ~117 ~62 dirt
setblock ~30 ~117 ~63 dirt
setblock ~30 ~117 ~64 dirt
setblock ~30 ~117 ~65 dirt
setblock ~30 ~117 ~103 dirt
setblock ~30 ~117 ~104 dirt
setblock ~30 ~117 ~105 dirt
setblock ~30 ~117 ~106 dirt
setblock ~30 ~117 ~107 dirt
setblock ~30 ~117 ~108 dirt
setblock ~30 ~117 ~109 dirt
setblock ~30 ~117 ~110 dirt
setblock ~30 ~117 ~111 dirt
setblock ~30 ~117 ~122 dirt
setblock ~30 ~117 ~123 dirt
setblock ~30 ~117 ~124 dirt
setblock ~30 ~117 ~128 dirt
setblock ~30 ~117 ~129 dirt
setblock ~30 ~117 ~130 dirt
setblock ~30 ~117 ~139 dirt
setblock ~30 ~117 ~140 dirt
setblock ~30 ~118 ~58 dirt
setblock ~30 ~118 ~59 dirt
setblock ~30 ~118 ~60 dirt
setblock ~30 ~118 ~61 dirt
setblock ~30 ~118 ~62 dirt
setblock ~30 ~118 ~63 dirt
setblock ~30 ~118 ~64 dirt
setblock ~30 ~118 ~65 dirt
setblock ~30 ~118 ~66 dirt
setblock ~30 ~118 ~103 dirt
setblock ~30 ~118 ~104 dirt
setblock ~30 ~118 ~105 dirt
setblock ~30 ~118 ~106 dirt
setblock ~30 ~118 ~107 dirt
setblock ~30 ~118 ~108 dirt
setblock ~30 ~118 ~109 dirt
setblock ~30 ~118 ~110 dirt
setblock ~30 ~118 ~111 dirt
setblock ~30 ~118 ~112 dirt
setblock ~30 ~118 ~122 dirt
setblock ~30 ~118 ~123 dirt
setblock ~30 ~118 ~124 dirt
setblock ~30 ~118 ~125 dirt
setblock ~30 ~118 ~127 dirt
setblock ~30 ~118 ~128 dirt
setblock ~30 ~118 ~129 dirt
setblock ~30 ~118 ~130 dirt
setblock ~30 ~118 ~138 dirt
setblock ~30 ~118 ~139 dirt
setblock ~30 ~118 ~140 dirt
setblock ~30 ~119 ~58 dirt
setblock ~30 ~119 ~59 dirt
setblock ~30 ~119 ~60 dirt
setblock ~30 ~119 ~61 dirt
setblock ~30 ~119 ~62 dirt
setblock ~30 ~119 ~63 dirt
setblock ~30 ~119 ~64 dirt
setblock ~30 ~119 ~65 dirt
setblock ~30 ~119 ~66 dirt
setblock ~30 ~119 ~67 dirt
setblock ~30 ~119 ~102 dirt
setblock ~30 ~119 ~103 dirt
setblock ~30 ~119 ~104 dirt
setblock ~30 ~119 ~105 dirt
setblock ~30 ~119 ~106 dirt
setblock ~30 ~119 ~107 dirt
setblock ~30 ~119 ~108 dirt
setblock ~30 ~119 ~109 dirt
setblock ~30 ~119 ~110 dirt
setblock ~30 ~119 ~111 dirt
setblock ~30 ~119 ~112 dirt
setblock ~30 ~119 ~113 dirt
setblock ~30 ~119 ~121 dirt
setblock ~30 ~119 ~122 dirt
setblock ~30 ~119 ~123 dirt
setblock ~30 ~119 ~124 dirt
setblock ~30 ~119 ~125 dirt
setblock ~30 ~119 ~126 dirt
setblock ~30 ~119 ~127 dirt
setblock ~30 ~119 ~128 dirt
setblock ~30 ~119 ~129 dirt
setblock ~30 ~119 ~130 dirt
setblock ~30 ~119 ~131 dirt
setblock ~30 ~119 ~137 dirt
setblock ~30 ~119 ~138 dirt
setblock ~30 ~119 ~139 dirt
setblock ~30 ~119 ~140 dirt
setblock ~30 ~119 ~141 dirt
setblock ~30 ~119 ~153 dirt
setblock ~30 ~120 ~57 dirt
setblock ~30 ~120 ~58 dirt
setblock ~30 ~120 ~59 dirt
setblock ~30 ~120 ~60 dirt
setblock ~30 ~120 ~61 dirt
setblock ~30 ~120 ~62 dirt
setblock ~30 ~120 ~63 dirt
setblock ~30 ~120 ~64 dirt
setblock ~30 ~120 ~65 dirt
setblock ~30 ~120 ~66 dirt
setblock ~30 ~120 ~67 dirt
setblock ~30 ~120 ~68 dirt
setblock ~30 ~120 ~70 dirt
setblock ~30 ~120 ~102 dirt
setblock ~30 ~120 ~103 dirt
setblock ~30 ~120 ~104 dirt
setblock ~30 ~120 ~105 dirt
setblock ~30 ~120 ~106 dirt
setblock ~30 ~120 ~107 dirt
setblock ~30 ~120 ~108 dirt
setblock ~30 ~120 ~109 dirt
setblock ~30 ~120 ~110 dirt
setblock ~30 ~120 ~111 dirt
setblock ~30 ~120 ~112 dirt
setblock ~30 ~120 ~113 dirt
setblock ~30 ~120 ~121 dirt
setblock ~30 ~120 ~122 dirt
setblock ~30 ~120 ~123 dirt
setblock ~30 ~120 ~124 dirt
setblock ~30 ~120 ~125 dirt
setblock ~30 ~120 ~126 dirt
setblock ~30 ~120 ~127 dirt
setblock ~30 ~120 ~128 dirt
setblock ~30 ~120 ~129 dirt
setblock ~30 ~120 ~130 dirt
setblock ~30 ~120 ~131 dirt
setblock ~30 ~120 ~136 dirt
setblock ~30 ~120 ~137 dirt
setblock ~30 ~120 ~138 dirt
setblock ~30 ~120 ~139 dirt
setblock ~30 ~120 ~140 dirt
setblock ~30 ~120 ~141 dirt
setblock ~30 ~120 ~142 dirt
setblock ~30 ~120 ~152 dirt
setblock ~30 ~120 ~153 dirt
setblock ~30 ~120 ~154 dirt
setblock ~30 ~121 ~57 dirt
setblock ~30 ~121 ~58 dirt
setblock ~30 ~121 ~59 dirt
setblock ~30 ~121 ~60 dirt
setblock ~30 ~121 ~61 dirt
setblock ~30 ~121 ~62 dirt
setblock ~30 ~121 ~63 dirt
setblock ~30 ~121 ~64 dirt
setblock ~30 ~121 ~65 dirt
setblock ~30 ~121 ~66 dirt
setblock ~30 ~121 ~67 dirt
setblock ~30 ~121 ~68 dirt
setblock ~30 ~121 ~69 dirt
setblock ~30 ~121 ~70 dirt
setblock ~30 ~121 ~72 dirt
setblock ~30 ~121 ~102 dirt
setblock ~30 ~121 ~103 dirt
setblock ~30 ~121 ~104 dirt
setblock ~30 ~121 ~105 dirt
setblock ~30 ~121 ~106 dirt
setblock ~30 ~121 ~107 dirt
setblock ~30 ~121 ~108 dirt
setblock ~30 ~121 ~109 dirt
setblock ~30 ~121 ~110 dirt
setblock ~30 ~121 ~111 dirt
setblock ~30 ~121 ~112 dirt
setblock ~30 ~121 ~113 dirt
setblock ~30 ~121 ~114 dirt
setblock ~30 ~121 ~120 dirt
setblock ~30 ~121 ~121 dirt
setblock ~30 ~121 ~122 dirt
setblock ~30 ~121 ~123 dirt
setblock ~30 ~121 ~124 dirt
setblock ~30 ~121 ~125 dirt
setblock ~30 ~121 ~126 dirt
setblock ~30 ~121 ~127 dirt
setblock ~30 ~121 ~128 dirt
setblock ~30 ~121 ~129 dirt
setblock ~30 ~121 ~130 dirt
setblock ~30 ~121 ~131 dirt
setblock ~30 ~121 ~132 dirt
setblock ~30 ~121 ~135 dirt
setblock ~30 ~121 ~136 dirt
setblock ~30 ~121 ~137 dirt
setblock ~30 ~121 ~138 dirt
setblock ~30 ~121 ~139 dirt
setblock ~30 ~121 ~140 dirt
setblock ~30 ~121 ~141 dirt
setblock ~30 ~121 ~142 dirt
setblock ~30 ~121 ~151 dirt
setblock ~30 ~121 ~152 dirt
setblock ~30 ~121 ~153 dirt
setblock ~30 ~121 ~154 dirt
setblock ~30 ~122 ~57 dirt
setblock ~30 ~122 ~58 dirt
setblock ~30 ~122 ~59 dirt
setblock ~30 ~122 ~60 dirt
setblock ~30 ~122 ~61 dirt
setblock ~30 ~122 ~62 dirt
setblock ~30 ~122 ~63 dirt
setblock ~30 ~122 ~64 dirt
setblock ~30 ~122 ~65 dirt
setblock ~30 ~122 ~66 dirt
setblock ~30 ~122 ~67 dirt
setblock ~30 ~122 ~68 dirt
setblock ~30 ~122 ~69 dirt
setblock ~30 ~122 ~70 dirt
setblock ~30 ~122 ~72 dirt
setblock ~30 ~122 ~102 dirt
setblock ~30 ~122 ~103 dirt
setblock ~30 ~122 ~104 dirt
setblock ~30 ~122 ~105 dirt
setblock ~30 ~122 ~106 dirt
setblock ~30 ~122 ~107 dirt
setblock ~30 ~122 ~108 dirt
setblock ~30 ~122 ~109 dirt
setblock ~30 ~122 ~110 dirt
setblock ~30 ~122 ~111 dirt
setblock ~30 ~122 ~112 dirt
setblock ~30 ~122 ~113 dirt
setblock ~30 ~122 ~114 dirt
setblock ~30 ~122 ~120 dirt
setblock ~30 ~122 ~121 dirt
setblock ~30 ~122 ~122 dirt
setblock ~30 ~122 ~123 dirt
setblock ~30 ~122 ~124 dirt
setblock ~30 ~122 ~125 dirt
setblock ~30 ~122 ~126 dirt
setblock ~30 ~122 ~127 dirt
setblock ~30 ~122 ~128 dirt
setblock ~30 ~122 ~129 dirt
setblock ~30 ~122 ~130 dirt
setblock ~30 ~122 ~131 dirt
setblock ~30 ~122 ~132 dirt
setblock ~30 ~122 ~135 dirt
setblock ~30 ~122 ~136 dirt
setblock ~30 ~122 ~137 dirt
setblock ~30 ~122 ~138 dirt
setblock ~30 ~122 ~139 dirt
setblock ~30 ~122 ~140 dirt
setblock ~30 ~122 ~141 dirt
setblock ~30 ~122 ~142 dirt
setblock ~30 ~122 ~151 dirt
setblock ~30 ~122 ~152 dirt
setblock ~30 ~122 ~153 dirt
setblock ~30 ~122 ~154 dirt
setblock ~30 ~123 ~57 dirt
setblock ~30 ~123 ~58 dirt
setblock ~30 ~123 ~59 dirt
setblock ~30 ~123 ~60 dirt
setblock ~30 ~123 ~61 dirt
setblock ~30 ~123 ~62 dirt
setblock ~30 ~123 ~63 dirt
setblock ~30 ~123 ~64 dirt
setblock ~30 ~123 ~65 dirt
setblock ~30 ~123 ~66 dirt
setblock ~30 ~123 ~67 dirt
setblock ~30 ~123 ~68 dirt
setblock ~30 ~123 ~69 dirt
setblock ~30 ~123 ~70 dirt
setblock ~30 ~123 ~72 dirt
setblock ~30 ~123 ~102 dirt
setblock ~30 ~123 ~103 dirt
setblock ~30 ~123 ~104 dirt
setblock ~30 ~123 ~105 dirt
setblock ~30 ~123 ~106 dirt
setblock ~30 ~123 ~107 dirt
setblock ~30 ~123 ~108 dirt
setblock ~30 ~123 ~109 dirt
setblock ~30 ~123 ~110 dirt
setblock ~30 ~123 ~111 dirt
setblock ~30 ~123 ~112 dirt
setblock ~30 ~123 ~113 dirt
setblock ~30 ~123 ~114 dirt
setblock ~30 ~123 ~120 dirt
setblock ~30 ~123 ~121 dirt
setblock ~30 ~123 ~122 dirt
setblock ~30 ~123 ~123 dirt
setblock ~30 ~123 ~124 dirt
setblock ~30 ~123 ~125 dirt
setblock ~30 ~123 ~126 dirt
setblock ~30 ~123 ~127 dirt
setblock ~30 ~123 ~128 dirt
setblock ~30 ~123 ~129 dirt
setblock ~30 ~123 ~130 dirt
setblock ~30 ~123 ~131 dirt
setblock ~30 ~123 ~132 dirt
setblock ~30 ~123 ~135 dirt
setblock ~30 ~123 ~136 dirt
setblock ~30 ~123 ~137 dirt
setblock ~30 ~123 ~138 dirt
setblock ~30 ~123 ~139 dirt
setblock ~30 ~123 ~140 dirt
setblock ~30 ~123 ~141 dirt
setblock ~30 ~123 ~142 dirt
setblock ~30 ~123 ~151 dirt
setblock ~30 ~123 ~152 dirt
setblock ~30 ~123 ~153 dirt
setblock ~30 ~123 ~154 dirt
setblock ~30 ~124 ~57 dirt
setblock ~30 ~124 ~58 dirt
setblock ~30 ~124 ~59 dirt
setblock ~30 ~124 ~60 dirt
setblock ~30 ~124 ~61 dirt
setblock ~30 ~124 ~62 dirt
setblock ~30 ~124 ~63 dirt
setblock ~30 ~124 ~64 dirt
setblock ~30 ~124 ~65 dirt
setblock ~30 ~124 ~66 dirt
setblock ~30 ~124 ~67 dirt
setblock ~30 ~124 ~68 dirt
setblock ~30 ~124 ~69 dirt
setblock ~30 ~124 ~70 dirt
setblock ~30 ~124 ~72 dirt
setblock ~30 ~124 ~102 dirt
setblock ~30 ~124 ~103 dirt
setblock ~30 ~124 ~104 dirt
setblock ~30 ~124 ~105 dirt
setblock ~30 ~124 ~106 dirt
setblock ~30 ~124 ~107 dirt
setblock ~30 ~124 ~108 dirt
setblock ~30 ~124 ~109 dirt
setblock ~30 ~124 ~110 dirt
setblock ~30 ~124 ~111 dirt
setblock ~30 ~124 ~112 dirt
setblock ~30 ~124 ~113 dirt
setblock ~30 ~124 ~114 dirt
setblock ~30 ~124 ~120 dirt
setblock ~30 ~124 ~121 dirt
setblock ~30 ~124 ~122 dirt
setblock ~30 ~124 ~123 dirt
setblock ~30 ~124 ~124 dirt
setblock ~30 ~124 ~125 dirt
setblock ~30 ~124 ~126 dirt
setblock ~30 ~124 ~127 dirt
setblock ~30 ~124 ~128 dirt
setblock ~30 ~124 ~129 dirt
setblock ~30 ~124 ~130 dirt
setblock ~30 ~124 ~131 dirt
setblock ~30 ~124 ~132 dirt
setblock ~30 ~124 ~135 dirt
setblock ~30 ~124 ~136 dirt
setblock ~30 ~124 ~137 dirt
setblock ~30 ~124 ~138 dirt
setblock ~30 ~124 ~139 dirt
setblock ~30 ~124 ~140 dirt
setblock ~30 ~124 ~141 dirt
setblock ~30 ~124 ~142 dirt
setblock ~30 ~124 ~151 dirt
setblock ~30 ~124 ~152 dirt
setblock ~30 ~124 ~153 dirt
setblock ~30 ~124 ~154 grass_block
setblock ~30 ~125 ~57 dirt
setblock ~30 ~125 ~58 dirt
setblock ~30 ~125 ~59 dirt
setblock ~30 ~125 ~60 dirt
setblock ~30 ~125 ~61 dirt
setblock ~30 ~125 ~62 dirt
setblock ~30 ~125 ~63 dirt
setblock ~30 ~125 ~64 dirt
setblock ~30 ~125 ~65 dirt
setblock ~30 ~125 ~66 dirt
setblock ~30 ~125 ~67 dirt
setblock ~30 ~125 ~68 dirt
setblock ~30 ~125 ~69 dirt
setblock ~30 ~125 ~70 dirt
setblock ~30 ~125 ~72 dirt
setblock ~30 ~125 ~102 dirt
setblock ~30 ~125 ~103 dirt
setblock ~30 ~125 ~104 dirt
setblock ~30 ~125 ~105 dirt
setblock ~30 ~125 ~106 dirt
setblock ~30 ~125 ~107 dirt
setblock ~30 ~125 ~108 dirt
setblock ~30 ~125 ~109 dirt
setblock ~30 ~125 ~110 dirt
setblock ~30 ~125 ~111 dirt
setblock ~30 ~125 ~112 dirt
setblock ~30 ~125 ~113 dirt
setblock ~30 ~125 ~114 dirt
setblock ~30 ~125 ~120 grass_block
setblock ~30 ~125 ~121 grass_block
setblock ~30 ~125 ~122 grass_block
setblock ~30 ~125 ~123 dirt
setblock ~30 ~125 ~124 dirt
setblock ~30 ~125 ~125 dirt
setblock ~30 ~125 ~126 dirt
setblock ~30 ~125 ~127 dirt
setblock ~30 ~125 ~128 dirt
setblock ~30 ~125 ~129 dirt
setblock ~30 ~125 ~130 dirt
setblock ~30 ~125 ~131 dirt
setblock ~30 ~125 ~132 dirt
setblock ~30 ~125 ~135 dirt
setblock ~30 ~125 ~136 dirt
setblock ~30 ~125 ~137 dirt
setblock ~30 ~125 ~138 dirt
setblock ~30 ~125 ~139 dirt
setblock ~30 ~125 ~140 dirt
setblock ~30 ~125 ~141 dirt
setblock ~30 ~125 ~142 dirt
setblock ~30 ~125 ~151 dirt
setblock ~30 ~125 ~152 grass_block
setblock ~30 ~125 ~153 grass_block
setblock ~30 ~126 ~57 grass_block
setblock ~30 ~126 ~58 grass_block
setblock ~30 ~126 ~59 dirt
setblock ~30 ~126 ~60 dirt
setblock ~30 ~126 ~61 dirt
setblock ~30 ~126 ~62 dirt
setblock ~30 ~126 ~63 dirt
setblock ~30 ~126 ~64 dirt
setblock ~30 ~126 ~65 dirt
setblock ~30 ~126 ~66 dirt
setblock ~30 ~126 ~67 dirt
setblock ~30 ~126 ~68 dirt
setblock ~30 ~126 ~69 dirt
setblock ~30 ~126 ~70 dirt
setblock ~30 ~126 ~72 dirt
setblock ~30 ~126 ~102 grass_block
setblock ~30 ~126 ~103 grass_block
setblock ~30 ~126 ~104 grass_block
setblock ~30 ~126 ~105 grass_block
setblock ~30 ~126 ~106 grass_block
setblock ~30 ~126 ~107 dirt
setblock ~30 ~126 ~108 dirt
setblock ~30 ~126 ~109 dirt
setblock ~30 ~126 ~110 dirt
setblock ~30 ~126 ~111 dirt
setblock ~30 ~126 ~112 dirt
setblock ~30 ~126 ~113 dirt
setblock ~30 ~126 ~114 dirt
setblock ~30 ~126 ~120 short_grass
setblock ~30 ~126 ~122 fern
setblock ~30 ~126 ~123 grass_block
setblock ~30 ~126 ~124 grass_block
setblock ~30 ~126 ~125 grass_block
setblock ~30 ~126 ~126 grass_block
setblock ~30 ~126 ~127 grass_block
setblock ~30 ~126 ~128 grass_block
setblock ~30 ~126 ~129 grass_block
setblock ~30 ~126 ~130 grass_block
setblock ~30 ~126 ~131 grass_block
setblock ~30 ~126 ~132 grass_block
setblock ~30 ~126 ~135 dirt
setblock ~30 ~126 ~136 dirt
setblock ~30 ~126 ~137 dirt
setblock ~30 ~126 ~138 dirt
setblock ~30 ~126 ~139 dirt
setblock ~30 ~126 ~140 grass_block
setblock ~30 ~126 ~141 grass_block
setblock ~30 ~126 ~142 grass_block
setblock ~30 ~126 ~151 grass_block
setblock ~30 ~126 ~153 short_grass
setblock ~30 ~127 ~57 short_grass
setblock ~30 ~127 ~58 short_grass
setblock ~30 ~127 ~59 grass_block
setblock ~30 ~127 ~60 grass_block
setblock ~30 ~127 ~61 grass_block
setblock ~30 ~127 ~62 grass_block
setblock ~30 ~127 ~63 grass_block
setblock ~30 ~127 ~64 grass_block
setblock ~30 ~127 ~65 grass_block
setblock ~30 ~127 ~66 grass_block
setblock ~30 ~127 ~67 grass_block
setblock ~30 ~127 ~68 grass_block
setblock ~30 ~127 ~69 grass_block
setblock ~30 ~127 ~70 grass_block
setblock ~30 ~127 ~72 grass_block
setblock ~30 ~127 ~103 short_grass
setblock ~30 ~127 ~105 fern
setblock ~30 ~127 ~107 grass_block
setblock ~30 ~127 ~108 grass_block
setblock ~30 ~127 ~109 grass_block
setblock ~30 ~127 ~110 dirt
setblock ~30 ~127 ~111 dirt
setblock ~30 ~127 ~112 dirt
setblock ~30 ~127 ~113 grass_block
setblock ~30 ~127 ~114 grass_block
setblock ~30 ~127 ~123 short_grass
setblock ~30 ~127 ~126 short_grass
setblock ~30 ~127 ~129 short_grass
setblock ~30 ~127 ~130 poppy
setblock ~30 ~127 ~131 short_grass
setblock ~30 ~127 ~135 grass_block
setblock ~30 ~127 ~136 grass_block
setblock ~30 ~127 ~137 grass_block
setblock ~30 ~127 ~138 grass_block
setblock ~30 ~127 ~139 grass_block
setblock ~30 ~127 ~151 short_grass
setblock ~30 ~128 ~59 short_grass
setblock ~30 ~128 ~66 short_grass
setblock ~30 ~128 ~72 short_grass
setblock ~30 ~128 ~107 short_grass
setblock ~30 ~128 ~110 grass_block
setblock ~30 ~128 ~111 grass_block
setblock ~30 ~128 ~112 grass_block
setblock ~30 ~128 ~113 short_grass
setblock ~30 ~128 ~138 short_grass
setblock ~30 ~129 ~110 short_grass
setblock ~30 ~129 ~112 short_grass
setblock ~31 ~106 ~108 dirt
setblock ~31 ~107 ~108 dirt
setblock ~31 ~108 ~108 dirt
setblock ~31 ~109 ~108 dirt
setblock ~31 ~110 ~107 dirt
setblock ~31 ~110 ~108 dirt
setblock ~31 ~110 ~109 dirt
setblock ~31 ~111 ~106 dirt
setblock ~31 ~111 ~107 dirt
setblock ~31 ~111 ~108 dirt
setblock ~31 ~111 ~109 dirt
setblock ~31 ~112 ~105 dirt
setblock ~31 ~112 ~106 dirt
setblock ~31 ~112 ~107 dirt
setblock ~31 ~112 ~108 dirt
setblock ~31 ~112 ~109 dirt
setblock ~31 ~112 ~110 dirt
setblock ~31 ~113 ~60 dirt
setblock ~31 ~113 ~105 dirt
setblock ~31 ~113 ~106 dirt
setblock ~31 ~113 ~107 dirt
setblock ~31 ~113 ~108 dirt
setblock ~31 ~113 ~109 dirt
setblock ~31 ~113 ~110 dirt
setblock ~31 ~113 ~111 dirt
setblock ~31 ~114 ~59 dirt
setblock ~31 ~114 ~60 dirt
setblock ~31 ~114 ~61 dirt
setblock ~31 ~114 ~105 dirt
setblock ~31 ~114 ~106 dirt
setblock ~31 ~114 ~107 dirt
setblock ~31 ~114 ~108 dirt
setblock ~31 ~114 ~109 dirt
setblock ~31 ~114 ~110 dirt
setblock ~31 ~114 ~111 dirt
setblock ~31 ~114 ~123 dirt
setblock ~31 ~114 ~128 dirt
setblock ~31 ~115 ~59 dirt
setblock ~31 ~115 ~60 dirt
setblock ~31 ~115 ~61 dirt
setblock ~31 ~115 ~62 dirt
setblock ~31 ~115 ~104 dirt
setblock ~31 ~115 ~105 dirt
setblock ~31 ~115 ~106 dirt
setblock ~31 ~115 ~107 dirt
setblock ~31 ~115 ~108 dirt
setblock ~31 ~115 ~109 dirt
setblock ~31 ~115 ~110 dirt
setblock ~31 ~115 ~111 dirt
setblock ~31 ~115 ~122 dirt
setblock ~31 ~115 ~123 dirt
setblock ~31 ~115 ~124 dirt
setblock ~31 ~115 ~127 dirt
setblock ~31 ~115 ~128 dirt
setblock ~31 ~115 ~129 dirt
setblock ~31 ~115 ~140 dirt
setblock ~31 ~116 ~59 dirt
setblock ~31 ~116 ~60 dirt
setblock ~31 ~116 ~61 dirt
setblock ~31 ~116 ~62 dirt
setblock ~31 ~116 ~63 dirt
setblock ~31 ~116 ~104 dirt
setblock ~31 ~116 ~105 dirt
setblock ~31 ~116 ~106 dirt
setblock ~31 ~116 ~107 dirt
setblock ~31 ~116 ~108 dirt
setblock ~31 ~116 ~109 dirt
setblock ~31 ~116 ~110 dirt
setblock ~31 ~116 ~111 dirt
setblock ~31 ~116 ~112 dirt
setblock ~31 ~116 ~122 dirt
setblock ~31 ~116 ~123 dirt
setblock ~31 ~116 ~124 dirt
setblock ~31 ~116 ~125 dirt
setblock ~31 ~116 ~127 dirt
setblock ~31 ~116 ~128 dirt
setblock ~31 ~116 ~129 dirt
setblock ~31 ~116 ~130 dirt
setblock ~31 ~116 ~139 dirt
setblock ~31 ~116 ~140 dirt
setblock ~31 ~116 ~141 dirt
setblock ~31 ~117 ~58 dirt
setblock ~31 ~117 ~59 dirt
setblock ~31 ~117 ~60 dirt
setblock ~31 ~117 ~61 dirt
setblock ~31 ~117 ~62 dirt
setblock ~31 ~117 ~63 dirt
setblock ~31 ~117 ~64 dirt
setblock ~31 ~117 ~103 dirt
setblock ~31 ~117 ~104 dirt
setblock ~31 ~117 ~105 dirt
setblock ~31 ~117 ~106 dirt
setblock ~31 ~117 ~107 dirt
setblock ~31 ~117 ~108 dirt
setblock ~31 ~117 ~109 dirt
setblock ~31 ~117 ~110 dirt
setblock ~31 ~117 ~111 dirt
setblock ~31 ~117 ~112 dirt
setblock ~31 ~117 ~121 dirt
setblock ~31 ~117 ~122 dirt
setblock ~31 ~117 ~123 dirt
setblock ~31 ~117 ~124 dirt
setblock ~31 ~117 ~125 dirt
setblock ~31 ~117 ~127 dirt
setblock ~31 ~117 ~128 dirt
setblock ~31 ~117 ~129 dirt
setblock ~31 ~117 ~130 dirt
setblock ~31 ~117 ~131 dirt
setblock ~31 ~117 ~138 dirt
setblock ~31 ~117 ~139 dirt
setblock ~31 ~117 ~140 dirt
setblock ~31 ~117 ~141 dirt
setblock ~31 ~118 ~58 dirt
setblock ~31 ~118 ~59 dirt
setblock ~31 ~118 ~60 dirt
setblock ~31 ~118 ~61 dirt
setblock ~31 ~118 ~62 dirt
setblock ~31 ~118 ~63 dirt
setblock ~31 ~118 ~64 dirt
setblock ~31 ~118 ~65 dirt
setblock ~31 ~118 ~70 dirt
setblock ~31 ~118 ~103 dirt
setblock ~31 ~118 ~104 dirt
setblock ~31 ~118 ~105 dirt
setblock ~31 ~118 ~106 dirt
setblock ~31 ~118 ~107 dirt
setblock ~31 ~118 ~108 dirt
setblock ~31 ~118 ~109 dirt
setblock ~31 ~118 ~110 dirt
setblock ~31 ~118 ~111 dirt
setblock ~31 ~118 ~112 dirt
setblock ~31 ~118 ~113 dirt
setblock ~31 ~118 ~121 dirt
setblock ~31 ~118 ~122 dirt
setblock ~31 ~118 ~123 dirt
setblock ~31 ~118 ~124 dirt
setblock ~31 ~118 ~125 dirt
setblock ~31 ~118 ~126 dirt
setblock ~31 ~118 ~127 dirt
setblock ~31 ~118 ~128 dirt
setblock ~31 ~118 ~129 dirt
setblock ~31 ~118 ~130 dirt
setblock ~31 ~118 ~131 dirt
setblock ~31 ~118 ~137 dirt
setblock ~31 ~118 ~138 dirt
setblock ~31 ~118 ~139 dirt
setblock ~31 ~118 ~140 dirt
setblock ~31 ~118 ~141 dirt
setblock ~31 ~119 ~57 dirt
setblock ~31 ~119 ~58 dirt
setblock ~31 ~119 ~59 dirt
setblock ~31 ~119 ~60 dirt
setblock ~31 ~119 ~61 dirt
setblock ~31 ~119 ~62 dirt
setblock ~31 ~119 ~63 dirt
setblock ~31 ~119 ~64 dirt
setblock ~31 ~119 ~65 dirt
setblock ~31 ~119 ~66 dirt
setblock ~31 ~119 ~70 dirt
setblock ~31 ~119 ~72 dirt
setblock ~31 ~119 ~73 dirt
setblock ~31 ~119 ~103 dirt
setblock ~31 ~119 ~104 dirt
setblock ~31 ~119 ~105 dirt
setblock ~31 ~119 ~106 dirt
setblock ~31 ~119 ~107 dirt
setblock ~31 ~119 ~108 dirt
setblock ~31 ~119 ~109 dirt
setblock ~31 ~119 ~110 dirt
setblock ~31 ~119 ~111 dirt
setblock ~31 ~119 ~112 dirt
setblock ~31 ~119 ~113 dirt
setblock ~31 ~119 ~119 dirt
setblock ~31 ~119 ~120 dirt
setblock ~31 ~119 ~121 dirt
setblock ~31 ~119 ~122 dirt
setblock ~31 ~119 ~123 dirt
setblock ~31 ~119 ~124 dirt
setblock ~31 ~119 ~125 dirt
setblock ~31 ~119 ~126 dirt
setblock ~31 ~119 ~127 dirt
setblock ~31 ~119 ~128 dirt
setblock ~31 ~119 ~129 dirt
setblock ~31 ~119 ~130 dirt
setblock ~31 ~119 ~131 dirt
setblock ~31 ~119 ~136 dirt
setblock ~31 ~119 ~137 dirt
setblock ~31 ~119 ~138 dirt
setblock ~31 ~119 ~139 dirt
setblock ~31 ~119 ~140 dirt
setblock ~31 ~119 ~141 dirt
setblock ~31 ~119 ~142 dirt
setblock ~31 ~120 ~57 dirt
setblock ~31 ~120 ~58 dirt
setblock ~31 ~120 ~59 dirt
setblock ~31 ~120 ~60 dirt
setblock ~31 ~120 ~61 dirt
setblock ~31 ~120 ~62 dirt
setblock ~31 ~120 ~63 dirt
setblock ~31 ~120 ~64 dirt
setblock ~31 ~120 ~65 dirt
setblock ~31 ~120 ~66 dirt
setblock ~31 ~120 ~67 dirt
setblock ~31 ~120 ~69 dirt
setblock ~31 ~120 ~70 dirt
setblock ~31 ~120 ~71 dirt
setblock ~31 ~120 ~72 dirt
setblock ~31 ~120 ~73 dirt
setblock ~31 ~120 ~74 dirt
setblock ~31 ~120 ~75 dirt
setblock ~31 ~120 ~77 dirt
setblock ~31 ~120 ~102 dirt
setblock ~31 ~120 ~103 dirt
setblock ~31 ~120 ~104 dirt
setblock ~31 ~120 ~105 dirt
setblock ~31 ~120 ~106 dirt
setblock ~31 ~120 ~107 dirt
setblock ~31 ~120 ~108 dirt
setblock ~31 ~120 ~109 dirt
setblock ~31 ~120 ~110 dirt
setblock ~31 ~120 ~111 dirt
setblock ~31 ~120 ~112 dirt
setblock ~31 ~120 ~113 dirt
setblock ~31 ~120 ~117 dirt
setblock ~31 ~120 ~119 dirt
setblock ~31 ~120 ~120 dirt
setblock ~31 ~120 ~121 dirt
setblock ~31 ~120 ~122 dirt
setblock ~31 ~120 ~123 dirt
setblock ~31 ~120 ~124 dirt
setblock ~31 ~120 ~125 dirt
setblock ~31 ~120 ~126 dirt
setblock ~31 ~120 ~127 dirt
setblock ~31 ~120 ~128 dirt
setblock ~31 ~120 ~129 dirt
setblock ~31 ~120 ~130 dirt
setblock ~31 ~120 ~131 dirt
setblock ~31 ~120 ~132 dirt
setblock ~31 ~120 ~136 dirt
setblock ~31 ~120 ~137 dirt
setblock ~31 ~120 ~138 dirt
setblock ~31 ~120 ~139 dirt
setblock ~31 ~120 ~140 dirt
setblock ~31 ~120 ~141 dirt
setblock ~31 ~120 ~142 dirt
setblock ~31 ~120 ~153 dirt
setblock ~31 ~121 ~57 dirt
setblock ~31 ~121 ~58 dirt
setblock ~31 ~121 ~59 dirt
setblock ~31 ~121 ~60 dirt
setblock ~31 ~121 ~61 dirt
setblock ~31 ~121 ~62 dirt
setblock ~31 ~121 ~63 dirt
setblock ~31 ~121 ~64 dirt
setblock ~31 ~121 ~65 dirt
setblock ~31 ~121 ~66 dirt
setblock ~31 ~121 ~67 dirt
setblock ~31 ~121 ~68 dirt
setblock ~31 ~121 ~69 dirt
setblock ~31 ~121 ~70 dirt
setblock ~31 ~121 ~71 dirt
setblock ~31 ~121 ~72 dirt
setblock ~31 ~121 ~73 dirt
setblock ~31 ~121 ~74 dirt
setblock ~31 ~121 ~75 dirt
setblock ~31 ~121 ~76 dirt
setblock ~31 ~121 ~77 dirt
setblock ~31 ~121 ~102 dirt
setblock ~31 ~121 ~103 dirt
setblock ~31 ~121 ~104 dirt
setblock ~31 ~121 ~105 dirt
setblock ~31 ~121 ~106 dirt
setblock ~31 ~121 ~107 dirt
setblock ~31 ~121 ~108 dirt
setblock ~31 ~121 ~109 dirt
setblock ~31 ~121 ~110 dirt
setblock ~31 ~121 ~111 dirt
setblock ~31 ~121 ~112 dirt
setblock ~31 ~121 ~113 dirt
setblock ~31 ~121 ~114 dirt
setblock ~31 ~121 ~116 dirt
setblock ~31 ~121 ~117 dirt
setblock ~31 ~121 ~118 dirt
setblock ~31 ~121 ~119 dirt
setblock ~31 ~121 ~120 dirt
setblock ~31 ~121 ~121 dirt
setblock ~31 ~121 ~122 dirt
setblock ~31 ~121 ~123 dirt
setblock ~31 ~121 ~124 dirt
setblock ~31 ~121 ~125 dirt
setblock ~31 ~121 ~126 dirt
setblock ~31 ~121 ~127 dirt
setblock ~31 ~121 ~128 dirt
setblock ~31 ~121 ~129 dirt
setblock ~31 ~121 ~130 dirt
setblock ~31 ~121 ~131 dirt
setblock ~31 ~121 ~132 dirt
setblock ~31 ~121 ~133 dirt
setblock ~31 ~121 ~136 dirt
setblock ~31 ~121 ~137 dirt
setblock ~31 ~121 ~138 dirt
setblock ~31 ~121 ~139 dirt
setblock ~31 ~121 ~140 dirt
setblock ~31 ~121 ~141 dirt
setblock ~31 ~121 ~142 dirt
setblock ~31 ~121 ~152 dirt
setblock ~31 ~121 ~153 dirt
setblock ~31 ~122 ~57 dirt
setblock ~31 ~122 ~58 dirt
setblock ~31 ~122 ~59 dirt
setblock ~31 ~122 ~60 dirt
setblock ~31 ~122 ~61 dirt
setblock ~31 ~122 ~62 dirt
setblock ~31 ~122 ~63 dirt
setblock ~31 ~122 ~64 dirt
setblock ~31 ~122 ~65 dirt
setblock ~31 ~122 ~66 dirt
setblock ~31 ~122 ~67 dirt
setblock ~31 ~122 ~68 dirt
setblock ~31 ~122 ~69 dirt
setblock ~31 ~122 ~70 dirt
setblock ~31 ~122 ~71 dirt
setblock ~31 ~122 ~72 dirt
setblock ~31 ~122 ~73 dirt
setblock ~31 ~122 ~74 dirt
setblock ~31 ~122 ~75 dirt
setblock ~31 ~122 ~76 dirt
setblock ~31 ~122 ~77 dirt
setblock ~31 ~122 ~102 dirt
setblock ~31 ~122 ~103 dirt
setblock ~31 ~122 ~104 dirt
setblock ~31 ~122 ~105 dirt
setblock ~31 ~122 ~106 dirt
setblock ~31 ~122 ~107 dirt
setblock ~31 ~122 ~108 dirt
setblock ~31 ~122 ~109 dirt
setblock ~31 ~122 ~110 dirt
setblock ~31 ~122 ~111 dirt
setblock ~31 ~122 ~112 dirt
setblock ~31 ~122 ~113 dirt
setblock ~31 ~122 ~114 dirt
setblock ~31 ~122 ~116 dirt
setblock ~31 ~122 ~117 dirt
setblock ~31 ~122 ~118 dirt
setblock ~31 ~122 ~119 dirt
setblock ~31 ~122 ~120 dirt
setblock ~31 ~122 ~121 dirt
setblock ~31 ~122 ~122 dirt
setblock ~31 ~122 ~123 dirt
setblock ~31 ~122 ~124 dirt
setblock ~31 ~122 ~125 dirt
setblock ~31 ~122 ~126 dirt
setblock ~31 ~122 ~127 dirt
setblock ~31 ~122 ~128 dirt
setblock ~31 ~122 ~129 dirt
setblock ~31 ~122 ~130 dirt
setblock ~31 ~122 ~131 dirt
setblock ~31 ~122 ~132 dirt
setblock ~31 ~122 ~133 dirt
setblock ~31 ~122 ~136 dirt
setblock ~31 ~122 ~137 dirt
setblock ~31 ~122 ~138 dirt
setblock ~31 ~122 ~139 dirt
setblock ~31 ~122 ~140 dirt
setblock ~31 ~122 ~141 dirt
setblock ~31 ~122 ~142 dirt
setblock ~31 ~122 ~152 dirt
setblock ~31 ~122 ~153 dirt
setblock ~31 ~123 ~57 dirt
setblock ~31 ~123 ~58 dirt
setblock ~31 ~123 ~59 dirt
setblock ~31 ~123 ~60 dirt
setblock ~31 ~123 ~61 dirt
setblock ~31 ~123 ~62 dirt
setblock ~31 ~123 ~63 dirt
setblock ~31 ~123 ~64 dirt
setblock ~31 ~123 ~65 dirt
setblock ~31 ~123 ~66 dirt
setblock ~31 ~123 ~67 dirt
setblock ~31 ~123 ~68 dirt
setblock ~31 ~123 ~69 dirt
setblock ~31 ~123 ~70 dirt
setblock ~31 ~123 ~71 dirt
setblock ~31 ~123 ~72 dirt
setblock ~31 ~123 ~73 dirt
setblock ~31 ~123 ~74 dirt
setblock ~31 ~123 ~75 dirt
