setblock ~0 ~1 ~0 gold_block
setblock ~24 ~121 ~83 dirt
setblock ~24 ~121 ~88 dirt
setblock ~24 ~122 ~83 dirt
setblock ~24 ~122 ~88 dirt
setblock ~24 ~123 ~83 dirt
setblock ~24 ~123 ~88 dirt
setblock ~24 ~124 ~83 grass_block
setblock ~24 ~124 ~88 dirt
setblock ~24 ~125 ~88 grass_block
setblock ~25 ~117 ~83 dirt
setblock ~25 ~118 ~83 dirt
setblock ~25 ~119 ~81 dirt
setblock ~25 ~119 ~83 dirt
setblock ~25 ~119 ~84 dirt
setblock ~25 ~120 ~81 dirt
setblock ~25 ~120 ~82 dirt
setblock ~25 ~120 ~83 dirt
setblock ~25 ~120 ~84 dirt
setblock ~25 ~120 ~85 dirt
setblock ~25 ~120 ~88 dirt
setblock ~25 ~121 ~80 dirt
setblock ~25 ~121 ~81 dirt
setblock ~25 ~121 ~82 dirt
setblock ~25 ~121 ~83 dirt
setblock ~25 ~121 ~84 dirt
setblock ~25 ~121 ~85 dirt
setblock ~25 ~121 ~87 dirt
setblock ~25 ~121 ~88 dirt
setblock ~25 ~121 ~89 dirt
setblock ~25 ~122 ~80 dirt
setblock ~25 ~122 ~81 dirt
setblock ~25 ~122 ~82 dirt
setblock ~25 ~122 ~83 dirt
setblock ~25 ~122 ~84 dirt
setblock ~25 ~122 ~85 dirt
setblock ~25 ~122 ~87 dirt
setblock ~25 ~122 ~88 dirt
setblock ~25 ~122 ~89 dirt
setblock ~25 ~123 ~80 dirt
setblock ~25 ~123 ~81 dirt
setblock ~25 ~123 ~82 dirt
setblock ~25 ~123 ~83 dirt
setblock ~25 ~123 ~84 dirt
setblock ~25 ~123 ~85 dirt
setblock ~25 ~123 ~87 dirt
setblock ~25 ~123 ~88 dirt
setblock ~25 ~123 ~89 dirt
setblock ~25 ~124 ~80 grass_block
setblock ~25 ~124 ~81 grass_block
setblock ~25 ~124 ~82 dirt
setblock ~25 ~124 ~83 dirt
setblock ~25 ~124 ~84 dirt
setblock ~25 ~124 ~85 dirt
setblock ~25 ~124 ~87 dirt
setblock ~25 ~124 ~88 dirt
setblock ~25 ~124 ~89 dirt
setblock ~25 ~125 ~80 short_grass
setblock ~25 ~125 ~82 grass_block
setblock ~25 ~125 ~83 grass_block
setblock ~25 ~125 ~84 grass_block
setblock ~25 ~125 ~85 grass_block
setblock ~25 ~125 ~87 grass_block
setblock ~25 ~125 ~88 grass_block
setblock ~25 ~125 ~89 grass_block
setblock ~25 ~126 ~82 short_grass
setblock ~25 ~126 ~89 short_grass
setblock ~26 ~116 ~83 dirt
setblock ~26 ~117 ~82 dirt
setblock ~26 ~117 ~83 dirt
setblock ~26 ~117 ~84 dirt
setblock ~26 ~118 ~80 dirt
setblock ~26 ~118 ~81 dirt
setblock ~26 ~118 ~82 dirt
setblock ~26 ~118 ~83 dirt
setblock ~26 ~118 ~84 dirt
setblock ~26 ~118 ~87 dirt
setblock ~26 ~119 ~80 dirt
setblock ~26 ~119 ~81 dirt
setblock ~26 ~119 ~82 dirt
setblock ~26 ~119 ~83 dirt
setblock ~26 ~119 ~84 dirt
setblock ~26 ~119 ~85 dirt
setblock ~26 ~119 ~87 dirt
setblock ~26 ~119 ~88 dirt
setblock ~26 ~120 ~79 dirt
setblock ~26 ~120 ~80 dirt
setblock ~26 ~120 ~81 dirt
setblock ~26 ~120 ~82 dirt
setblock ~26 ~120 ~83 dirt
setblock ~26 ~120 ~84 dirt
setblock ~26 ~120 ~85 dirt
setblock ~26 ~120 ~86 dirt
setblock ~26 ~120 ~87 dirt
setblock ~26 ~120 ~88 dirt
setblock ~26 ~120 ~89 dirt
setblock ~26 ~121 ~79 dirt
setblock ~26 ~121 ~80 dirt
setblock ~26 ~121 ~81 dirt
setblock ~26 ~121 ~82 dirt
setblock ~26 ~121 ~83 dirt
setblock ~26 ~121 ~84 dirt
setblock ~26 ~121 ~85 dirt
setblock ~26 ~121 ~86 dirt
setblock ~26 ~121 ~87 dirt
setblock ~26 ~121 ~88 dirt
setblock ~26 ~121 ~89 dirt
setblock ~26 ~121 ~90 dirt
setblock ~26 ~122 ~79 dirt
setblock ~26 ~122 ~80 dirt
setblock ~26 ~122 ~81 dirt
setblock ~26 ~122 ~82 dirt
setblock ~26 ~122 ~83 dirt
setblock ~26 ~122 ~84 dirt
setblock ~26 ~122 ~85 dirt
setblock ~26 ~122 ~86 dirt
setblock ~26 ~122 ~87 dirt
setblock ~26 ~122 ~88 dirt
setblock ~26 ~122 ~89 dirt
setblock ~26 ~122 ~90 dirt
setblock ~26 ~123 ~79 dirt
setblock ~26 ~123 ~80 dirt
setblock ~26 ~123 ~81 dirt
setblock ~26 ~123 ~82 dirt
setblock ~26 ~123 ~83 dirt
setblock ~26 ~123 ~84 dirt
setblock ~26 ~123 ~85 dirt
setblock ~26 ~123 ~86 dirt
setblock ~26 ~123 ~87 dirt
setblock ~26 ~123 ~88 dirt
setblock ~26 ~123 ~89 dirt
setblock ~26 ~123 ~90 dirt
setblock ~26 ~124 ~79 grass_block
setblock ~26 ~124 ~80 grass_block
setblock ~26 ~124 ~81 dirt
setblock ~26 ~124 ~82 dirt
setblock ~26 ~124 ~83 dirt
setblock ~26 ~124 ~84 dirt
setblock ~26 ~124 ~85 dirt
setblock ~26 ~124 ~86 dirt
setblock ~26 ~124 ~87 dirt
setblock ~26 ~124 ~88 dirt
setblock ~26 ~124 ~89 dirt
setblock ~26 ~124 ~90 dirt
setblock ~26 ~125 ~80 short_grass
setblock ~26 ~125 ~81 grass_block
setblock ~26 ~125 ~82 grass_block
setblock ~26 ~125 ~83 grass_block
setblock ~26 ~125 ~84 grass_block
setblock ~26 ~125 ~85 grass_block
setblock ~26 ~125 ~86 grass_block
setblock ~26 ~125 ~87 grass_block
setblock ~26 ~125 ~88 dirt
setblock ~26 ~125 ~89 dirt
setblock ~26 ~125 ~90 dirt
setblock ~26 ~126 ~87 short_grass
setblock ~26 ~126 ~88 grass_block
setblock ~26 ~126 ~89 grass_block
setblock ~26 ~126 ~90 grass_block
setblock ~26 ~127 ~88 fern
setblock ~26 ~127 ~89 poppy
setblock ~27 ~113 ~82 dirt
setblock ~27 ~114 ~81 dirt
setblock ~27 ~114 ~82 dirt
setblock ~27 ~114 ~83 dirt
setblock ~27 ~115 ~80 dirt
setblock ~27 ~115 ~81 dirt
setblock ~27 ~115 ~82 dirt
setblock ~27 ~115 ~83 dirt
setblock ~27 ~116 ~80 dirt
setblock ~27 ~116 ~81 dirt
setblock ~27 ~116 ~82 dirt
setblock ~27 ~116 ~83 dirt
setblock ~27 ~116 ~84 dirt
setblock ~27 ~116 ~85 dirt
setblock ~27 ~117 ~80 dirt
setblock ~27 ~117 ~81 dirt
setblock ~27 ~117 ~82 dirt
setblock ~27 ~117 ~83 dirt
setblock ~27 ~117 ~84 dirt
setblock ~27 ~117 ~85 dirt
setblock ~27 ~117 ~87 dirt
setblock ~27 ~118 ~79 dirt
setblock ~27 ~118 ~80 dirt
setblock ~27 ~118 ~81 dirt
setblock ~27 ~118 ~82 dirt
setblock ~27 ~118 ~83 dirt
setblock ~27 ~118 ~84 dirt
setblock ~27 ~118 ~85 dirt
setblock ~27 ~118 ~86 dirt
setblock ~27 ~118 ~87 dirt
setblock ~27 ~118 ~88 dirt
setblock ~27 ~119 ~78 dirt
setblock ~27 ~119 ~79 dirt
setblock ~27 ~119 ~80 dirt
setblock ~27 ~119 ~81 dirt
setblock ~27 ~119 ~82 dirt
setblock ~27 ~119 ~83 dirt
setblock ~27 ~119 ~84 dirt
setblock ~27 ~119 ~85 dirt
setblock ~27 ~119 ~86 dirt
setblock ~27 ~119 ~87 dirt
setblock ~27 ~119 ~88 dirt
setblock ~27 ~119 ~89 dirt
setblock ~27 ~120 ~78 dirt
setblock ~27 ~120 ~79 dirt
setblock ~27 ~120 ~80 dirt
setblock ~27 ~120 ~81 dirt
setblock ~27 ~120 ~82 dirt
setblock ~27 ~120 ~83 dirt
setblock ~27 ~120 ~84 dirt
setblock ~27 ~120 ~85 dirt
setblock ~27 ~120 ~86 dirt
setblock ~27 ~120 ~87 dirt
setblock ~27 ~120 ~88 dirt
setblock ~27 ~120 ~89 dirt
setblock ~27 ~121 ~77 dirt
setblock ~27 ~121 ~78 dirt
setblock ~27 ~121 ~79 dirt
setblock ~27 ~121 ~80 dirt
setblock ~27 ~121 ~81 dirt
setblock ~27 ~121 ~82 dirt
setblock ~27 ~121 ~83 dirt
setblock ~27 ~121 ~84 dirt
setblock ~27 ~121 ~85 dirt
setblock ~27 ~121 ~86 dirt
setblock ~27 ~121 ~87 dirt
setblock ~27 ~121 ~88 dirt
setblock ~27 ~121 ~89 dirt
setblock ~27 ~121 ~90 dirt
setblock ~27 ~121 ~91 dirt
setblock ~27 ~121 ~103 dirt
setblock ~27 ~122 ~77 dirt
setblock ~27 ~122 ~78 dirt
setblock ~27 ~122 ~79 dirt
setblock ~27 ~122 ~80 dirt
setblock ~27 ~122 ~81 dirt
setblock ~27 ~122 ~82 dirt
setblock ~27 ~122 ~83 dirt
setblock ~27 ~122 ~84 dirt
setblock ~27 ~122 ~85 dirt
setblock ~27 ~122 ~86 dirt
setblock ~27 ~122 ~87 dirt
setblock ~27 ~122 ~88 dirt
setblock ~27 ~122 ~89 dirt
setblock ~27 ~122 ~90 dirt
setblock ~27 ~122 ~91 dirt
setblock ~27 ~122 ~103 dirt
setblock ~27 ~123 ~77 dirt
setblock ~27 ~123 ~78 dirt
setblock ~27 ~123 ~79 dirt
setblock ~27 ~123 ~80 dirt
setblock ~27 ~123 ~81 dirt
setblock ~27 ~123 ~82 dirt
setblock ~27 ~123 ~83 dirt
setblock ~27 ~123 ~84 dirt
setblock ~27 ~123 ~85 dirt
setblock ~27 ~123 ~86 dirt
setblock ~27 ~123 ~87 dirt
setblock ~27 ~123 ~88 dirt
setblock ~27 ~123 ~89 dirt
setblock ~27 ~123 ~90 dirt
setblock ~27 ~123 ~91 dirt
setblock ~27 ~123 ~103 dirt
setblock ~27 ~124 ~77 dirt
setblock ~27 ~124 ~78 dirt
setblock ~27 ~124 ~79 dirt
setblock ~27 ~124 ~80 dirt
setblock ~27 ~124 ~81 dirt
setblock ~27 ~124 ~82 dirt
setblock ~27 ~124 ~83 dirt
setblock ~27 ~124 ~84 dirt
setblock ~27 ~124 ~85 dirt
setblock ~27 ~124 ~86 dirt
setblock ~27 ~124 ~87 dirt
setblock ~27 ~124 ~88 dirt
setblock ~27 ~124 ~89 dirt
setblock ~27 ~124 ~90 dirt
setblock ~27 ~124 ~91 dirt
setblock ~27 ~124 ~103 grass_block
setblock ~27 ~125 ~77 grass_block
setblock ~27 ~125 ~78 grass_block
setblock ~27 ~125 ~79 grass_block
setblock ~27 ~125 ~80 grass_block
setblock ~27 ~125 ~81 grass_block
setblock ~27 ~125 ~82 grass_block
setblock ~27 ~125 ~83 grass_block
setblock ~27 ~125 ~84 grass_block
setblock ~27 ~125 ~85 dirt
setblock ~27 ~125 ~86 dirt
setblock ~27 ~125 ~87 dirt
setblock ~27 ~125 ~88 dirt
setblock ~27 ~125 ~89 dirt
setblock ~27 ~125 ~90 dirt
setblock ~27 ~125 ~91 dirt
setblock ~27 ~125 ~103 fern
setblock ~27 ~126 ~77 short_grass
setblock ~27 ~126 ~80 short_grass
setblock ~27 ~126 ~81 short_grass
setblock ~27 ~126 ~85 grass_block
setblock ~27 ~126 ~86 grass_block
setblock ~27 ~126 ~87 grass_block
setblock ~27 ~126 ~88 grass_block
setblock ~27 ~126 ~89 grass_block
setblock ~27 ~126 ~90 grass_block
setblock ~27 ~126 ~91 grass_block
setblock ~27 ~127 ~91 poppy
setblock ~28 ~112 ~82 dirt
setblock ~28 ~113 ~81 dirt
setblock ~28 ~113 ~82 dirt
setblock ~28 ~113 ~83 dirt
setblock ~28 ~113 ~85 dirt
setblock ~28 ~114 ~80 dirt
setblock ~28 ~114 ~81 dirt
setblock ~28 ~114 ~82 dirt
setblock ~28 ~114 ~83 dirt
setblock ~28 ~114 ~84 dirt
setblock ~28 ~114 ~85 dirt
setblock ~28 ~115 ~79 dirt
setblock ~28 ~115 ~80 dirt
setblock ~28 ~115 ~81 dirt
setblock ~28 ~115 ~82 dirt
setblock ~28 ~115 ~83 dirt
setblock ~28 ~115 ~84 dirt
setblock ~28 ~115 ~85 dirt
setblock ~28 ~115 ~86 dirt
setblock ~28 ~116 ~79 dirt
setblock ~28 ~116 ~80 dirt
setblock ~28 ~116 ~81 dirt
setblock ~28 ~116 ~82 dirt
setblock ~28 ~116 ~83 dirt
setblock ~28 ~116 ~84 dirt
setblock ~28 ~116 ~85 dirt
setblock ~28 ~116 ~86 dirt
setblock ~28 ~116 ~87 dirt
setblock ~28 ~117 ~79 dirt
setblock ~28 ~117 ~80 dirt
setblock ~28 ~117 ~81 dirt
setblock ~28 ~117 ~82 dirt
setblock ~28 ~117 ~83 dirt
setblock ~28 ~117 ~84 dirt
setblock ~28 ~117 ~85 dirt
setblock ~28 ~117 ~86 dirt
setblock ~28 ~117 ~87 dirt
setblock ~28 ~117 ~88 dirt
setblock ~28 ~118 ~78 dirt
setblock ~28 ~118 ~79 dirt
setblock ~28 ~118 ~80 dirt
setblock ~28 ~118 ~81 dirt
setblock ~28 ~118 ~82 dirt
setblock ~28 ~118 ~83 dirt
setblock ~28 ~118 ~84 dirt
setblock ~28 ~118 ~85 dirt
setblock ~28 ~118 ~86 dirt
setblock ~28 ~118 ~87 dirt
setblock ~28 ~118 ~88 dirt
setblock ~28 ~118 ~89 dirt
setblock ~28 ~119 ~77 dirt
setblock ~28 ~119 ~78 dirt
setblock ~28 ~119 ~79 dirt
setblock ~28 ~119 ~80 dirt
setblock ~28 ~119 ~81 dirt
setblock ~28 ~119 ~82 dirt
setblock ~28 ~119 ~83 dirt
setblock ~28 ~119 ~84 dirt
setblock ~28 ~119 ~85 dirt
setblock ~28 ~119 ~86 dirt
setblock ~28 ~119 ~87 dirt
setblock ~28 ~119 ~88 dirt
setblock ~28 ~119 ~89 dirt
setblock ~28 ~119 ~90 dirt
setblock ~28 ~119 ~103 dirt
setblock ~28 ~119 ~104 dirt
setblock ~28 ~120 ~68 dirt
setblock ~28 ~120 ~73 dirt
setblock ~28 ~120 ~74 dirt
setblock ~28 ~120 ~77 dirt
setblock ~28 ~120 ~78 dirt
setblock ~28 ~120 ~79 dirt
setblock ~28 ~120 ~80 dirt
setblock ~28 ~120 ~81 dirt
setblock ~28 ~120 ~82 dirt
setblock ~28 ~120 ~83 dirt
setblock ~28 ~120 ~84 dirt
setblock ~28 ~120 ~85 dirt
setblock ~28 ~120 ~86 dirt
setblock ~28 ~120 ~87 dirt
setblock ~28 ~120 ~88 dirt
setblock ~28 ~120 ~89 dirt
setblock ~28 ~120 ~90 dirt
setblock ~28 ~120 ~91 dirt
setblock ~28 ~120 ~92 dirt
setblock ~28 ~120 ~100 dirt
setblock ~28 ~120 ~102 dirt
setblock ~28 ~120 ~103 dirt
setblock ~28 ~120 ~104 dirt
setblock ~28 ~120 ~105 dirt
setblock ~28 ~121 ~67 dirt
setblock ~28 ~121 ~68 dirt
setblock ~28 ~121 ~72 dirt
setblock ~28 ~121 ~73 dirt
setblock ~28 ~121 ~74 dirt
setblock ~28 ~121 ~75 dirt
setblock ~28 ~121 ~76 dirt
setblock ~28 ~121 ~77 dirt
setblock ~28 ~121 ~78 dirt
setblock ~28 ~121 ~79 dirt
setblock ~28 ~121 ~80 dirt
setblock ~28 ~121 ~81 dirt
setblock ~28 ~121 ~82 dirt
setblock ~28 ~121 ~83 dirt
setblock ~28 ~121 ~84 dirt
setblock ~28 ~121 ~85 dirt
setblock ~28 ~121 ~86 dirt
setblock ~28 ~121 ~87 dirt
setblock ~28 ~121 ~88 dirt
setblock ~28 ~121 ~89 dirt
setblock ~28 ~121 ~90 dirt
setblock ~28 ~121 ~91 dirt
setblock ~28 ~121 ~92 dirt
setblock ~28 ~121 ~93 dirt
setblock ~28 ~121 ~99 dirt
setblock ~28 ~121 ~100 dirt
setblock ~28 ~121 ~101 dirt
setblock ~28 ~121 ~102 dirt
setblock ~28 ~121 ~103 dirt
setblock ~28 ~121 ~104 dirt
setblock ~28 ~121 ~105 dirt
setblock ~28 ~121 ~106 dirt
setblock ~28 ~122 ~67 dirt
setblock ~28 ~122 ~68 dirt
setblock ~28 ~122 ~72 dirt
setblock ~28 ~122 ~73 dirt
setblock ~28 ~122 ~74 dirt
setblock ~28 ~122 ~75 dirt
setblock ~28 ~122 ~76 dirt
setblock ~28 ~122 ~77 dirt
setblock ~28 ~122 ~78 dirt
setblock ~28 ~122 ~79 dirt
setblock ~28 ~122 ~80 dirt
setblock ~28 ~122 ~81 dirt
setblock ~28 ~122 ~82 dirt
setblock ~28 ~122 ~83 dirt
setblock ~28 ~122 ~84 dirt
setblock ~28 ~122 ~85 dirt
setblock ~28 ~122 ~86 dirt
setblock ~28 ~122 ~87 dirt
setblock ~28 ~122 ~88 dirt
setblock ~28 ~122 ~89 dirt
setblock ~28 ~122 ~90 dirt
setblock ~28 ~122 ~91 dirt
setblock ~28 ~122 ~92 dirt
setblock ~28 ~122 ~93 dirt
setblock ~28 ~122 ~99 dirt
setblock ~28 ~122 ~100 dirt
setblock ~28 ~122 ~101 dirt
setblock ~28 ~122 ~102 dirt
setblock ~28 ~122 ~103 dirt
setblock ~28 ~122 ~104 dirt
setblock ~28 ~122 ~105 dirt
setblock ~28 ~122 ~106 dirt
setblock ~28 ~123 ~67 dirt
setblock ~28 ~123 ~68 dirt
setblock ~28 ~123 ~72 dirt
setblock ~28 ~123 ~73 dirt
setblock ~28 ~123 ~74 dirt
setblock ~28 ~123 ~75 dirt
setblock ~28 ~123 ~76 dirt
setblock ~28 ~123 ~77 dirt
setblock ~28 ~123 ~78 dirt
setblock ~28 ~123 ~79 dirt
setblock ~28 ~123 ~80 dirt
setblock ~28 ~123 ~81 dirt
setblock ~28 ~123 ~82 dirt
setblock ~28 ~123 ~83 dirt
setblock ~28 ~123 ~84 dirt
setblock ~28 ~123 ~85 dirt
setblock ~28 ~123 ~86 dirt
setblock ~28 ~123 ~87 dirt
setblock ~28 ~123 ~88 dirt
setblock ~28 ~123 ~89 dirt
setblock ~28 ~123 ~90 dirt
setblock ~28 ~123 ~91 dirt
setblock ~28 ~123 ~92 dirt
setblock ~28 ~123 ~93 dirt
setblock ~28 ~123 ~99 dirt
setblock ~28 ~123 ~100 dirt
setblock ~28 ~123 ~101 dirt
setblock ~28 ~123 ~102 dirt
setblock ~28 ~123 ~103 dirt
setblock ~28 ~123 ~104 dirt
setblock ~28 ~123 ~105 dirt
setblock ~28 ~123 ~106 dirt
setblock ~28 ~124 ~67 grass_block
setblock ~28 ~124 ~68 grass_block
setblock ~28 ~124 ~72 grass_block
setblock ~28 ~124 ~73 grass_block
setblock ~28 ~124 ~74 grass_block
setblock ~28 ~124 ~75 grass_block
setblock ~28 ~124 ~76 grass_block
setblock ~28 ~124 ~77 grass_block
setblock ~28 ~124 ~78 dirt
setblock ~28 ~124 ~79 dirt
setblock ~28 ~124 ~80 dirt
setblock ~28 ~124 ~81 dirt
setblock ~28 ~124 ~82 dirt
setblock ~28 ~124 ~83 dirt
setblock ~28 ~124 ~84 dirt
setblock ~28 ~124 ~85 dirt
setblock ~28 ~124 ~86 dirt
setblock ~28 ~124 ~87 dirt
setblock ~28 ~124 ~88 dirt
setblock ~28 ~124 ~89 dirt
setblock ~28 ~124 ~90 dirt
setblock ~28 ~124 ~91 dirt
setblock ~28 ~124 ~92 dirt
setblock ~28 ~124 ~93 dirt
setblock ~28 ~124 ~99 grass_block
setblock ~28 ~124 ~100 grass_block
setblock ~28 ~124 ~101 grass_block
setblock ~28 ~124 ~102 grass_block
setblock ~28 ~124 ~103 grass_block
setblock ~28 ~124 ~104 grass_block
setblock ~28 ~124 ~105 grass_block
setblock ~28 ~124 ~106 grass_block
setblock ~28 ~125 ~73 short_grass
setblock ~28 ~125 ~75 poppy
setblock ~28 ~125 ~78 grass_block
setblock ~28 ~125 ~79 grass_block
setblock ~28 ~125 ~80 grass_block
setblock ~28 ~125 ~81 grass_block
setblock ~28 ~125 ~82 grass_block
setblock ~28 ~125 ~83 grass_block
setblock ~28 ~125 ~84 dirt
setblock ~28 ~125 ~85 dirt
setblock ~28 ~125 ~86 dirt
setblock ~28 ~125 ~87 dirt
setblock ~28 ~125 ~88 dirt
setblock ~28 ~125 ~89 dirt
setblock ~28 ~125 ~90 dirt
setblock ~28 ~125 ~91 dirt
setblock ~28 ~125 ~92 dirt
setblock ~28 ~125 ~93 dirt
setblock ~28 ~126 ~79 poppy
setblock ~28 ~126 ~84 grass_block
setblock ~28 ~126 ~85 grass_block
setblock ~28 ~126 ~86 grass_block
setblock ~28 ~126 ~87 grass_block
setblock ~28 ~126 ~88 grass_block
setblock ~28 ~126 ~89 grass_block
setblock ~28 ~126 ~90 grass_block
setblock ~28 ~126 ~91 grass_block
setblock ~28 ~126 ~92 grass_block
setblock ~28 ~126 ~93 grass_block
setblock ~28 ~127 ~84 poppy
setblock ~28 ~127 ~88 poppy
setblock ~29 ~111 ~82 dirt
setblock ~29 ~112 ~81 dirt
setblock ~29 ~112 ~82 dirt
setblock ~29 ~112 ~83 dirt
setblock ~29 ~112 ~85 dirt
setblock ~29 ~113 ~81 dirt
setblock ~29 ~113 ~82 dirt
setblock ~29 ~113 ~83 dirt
setblock ~29 ~113 ~84 dirt
setblock ~29 ~113 ~85 dirt
setblock ~29 ~113 ~86 dirt
setblock ~29 ~114 ~81 dirt
setblock ~29 ~114 ~82 dirt
setblock ~29 ~114 ~83 dirt
setblock ~29 ~114 ~84 dirt
setblock ~29 ~114 ~85 dirt
setblock ~29 ~114 ~86 dirt
setblock ~29 ~115 ~80 dirt
setblock ~29 ~115 ~81 dirt
setblock ~29 ~115 ~82 dirt
setblock ~29 ~115 ~83 dirt
setblock ~29 ~115 ~84 dirt
setblock ~29 ~115 ~85 dirt
setblock ~29 ~115 ~86 dirt
setblock ~29 ~115 ~87 dirt
setblock ~29 ~115 ~104 dirt
setblock ~29 ~116 ~79 dirt
setblock ~29 ~116 ~80 dirt
setblock ~29 ~116 ~81 dirt
setblock ~29 ~116 ~82 dirt
setblock ~29 ~116 ~83 dirt
setblock ~29 ~116 ~84 dirt
setblock ~29 ~116 ~85 dirt
setblock ~29 ~116 ~86 dirt
setblock ~29 ~116 ~87 dirt
setblock ~29 ~116 ~88 dirt
setblock ~29 ~116 ~104 dirt
setblock ~29 ~117 ~74 dirt
setblock ~29 ~117 ~78 dirt
setblock ~29 ~117 ~79 dirt
setblock ~29 ~117 ~80 dirt
setblock ~29 ~117 ~81 dirt
setblock ~29 ~117 ~82 dirt
setblock ~29 ~117 ~83 dirt
setblock ~29 ~117 ~84 dirt
setblock ~29 ~117 ~85 dirt
setblock ~29 ~117 ~86 dirt
setblock ~29 ~117 ~87 dirt
setblock ~29 ~117 ~88 dirt
setblock ~29 ~117 ~89 dirt
setblock ~29 ~117 ~99 dirt
setblock ~29 ~117 ~103 dirt
setblock ~29 ~117 ~104 dirt
setblock ~29 ~117 ~105 dirt
setblock ~29 ~118 ~74 dirt
setblock ~29 ~118 ~78 dirt
setblock ~29 ~118 ~79 dirt
setblock ~29 ~118 ~80 dirt
setblock ~29 ~118 ~81 dirt
setblock ~29 ~118 ~82 dirt
setblock ~29 ~118 ~83 dirt
setblock ~29 ~118 ~84 dirt
setblock ~29 ~118 ~85 dirt
setblock ~29 ~118 ~86 dirt
setblock ~29 ~118 ~87 dirt
setblock ~29 ~118 ~88 dirt
setblock ~29 ~118 ~89 dirt
setblock ~29 ~118 ~90 dirt
setblock ~29 ~118 ~91 dirt
setblock ~29 ~118 ~99 dirt
setblock ~29 ~118 ~100 dirt
setblock ~29 ~118 ~103 dirt
setblock ~29 ~118 ~104 dirt
setblock ~29 ~118 ~105 dirt
setblock ~29 ~119 ~68 dirt
setblock ~29 ~119 ~71 dirt
setblock ~29 ~119 ~73 dirt
setblock ~29 ~119 ~74 dirt
setblock ~29 ~119 ~75 dirt
setblock ~29 ~119 ~77 dirt
setblock ~29 ~119 ~78 dirt
setblock ~29 ~119 ~79 dirt
setblock ~29 ~119 ~80 dirt
setblock ~29 ~119 ~81 dirt
setblock ~29 ~119 ~82 dirt
setblock ~29 ~119 ~83 dirt
setblock ~29 ~119 ~84 dirt
setblock ~29 ~119 ~85 dirt
setblock ~29 ~119 ~86 dirt
setblock ~29 ~119 ~87 dirt
setblock ~29 ~119 ~88 dirt
setblock ~29 ~119 ~89 dirt
setblock ~29 ~119 ~90 dirt
setblock ~29 ~119 ~91 dirt
setblock ~29 ~119 ~92 dirt
setblock ~29 ~119 ~99 dirt
setblock ~29 ~119 ~100 dirt
setblock ~29 ~119 ~102 dirt
setblock ~29 ~119 ~103 dirt
setblock ~29 ~119 ~104 dirt
setblock ~29 ~119 ~105 dirt
setblock ~29 ~119 ~106 dirt
setblock ~29 ~120 ~67 dirt
setblock ~29 ~120 ~68 dirt
setblock ~29 ~120 ~69 dirt
setblock ~29 ~120 ~70 dirt
setblock ~29 ~120 ~71 dirt
setblock ~29 ~120 ~72 dirt
setblock ~29 ~120 ~73 dirt
setblock ~29 ~120 ~74 dirt
setblock ~29 ~120 ~75 dirt
setblock ~29 ~120 ~76 dirt
setblock ~29 ~120 ~77 dirt
setblock ~29 ~120 ~78 dirt
setblock ~29 ~120 ~79 dirt
setblock ~29 ~120 ~80 dirt
setblock ~29 ~120 ~81 dirt
setblock ~29 ~120 ~82 dirt
setblock ~29 ~120 ~83 dirt
setblock ~29 ~120 ~84 dirt
setblock ~29 ~120 ~85 dirt
setblock ~29 ~120 ~86 dirt
setblock ~29 ~120 ~87 dirt
setblock ~29 ~120 ~88 dirt
setblock ~29 ~120 ~89 dirt
setblock ~29 ~120 ~90 dirt
setblock ~29 ~120 ~91 dirt
setblock ~29 ~120 ~92 dirt
setblock ~29 ~120 ~93 dirt
setblock ~29 ~120 ~96 dirt
setblock ~29 ~120 ~97 dirt
setblock ~29 ~120 ~99 dirt
setblock ~29 ~120 ~100 dirt
setblock ~29 ~120 ~101 dirt
setblock ~29 ~120 ~102 dirt
setblock ~29 ~120 ~103 dirt
setblock ~29 ~120 ~104 dirt
setblock ~29 ~120 ~105 dirt
setblock ~29 ~120 ~106 dirt
setblock ~29 ~120 ~107 dirt
setblock ~29 ~121 ~66 dirt
setblock ~29 ~121 ~67 dirt
setblock ~29 ~121 ~68 dirt
setblock ~29 ~121 ~69 dirt
setblock ~29 ~121 ~70 dirt
setblock ~29 ~121 ~71 dirt
setblock ~29 ~121 ~72 dirt
setblock ~29 ~121 ~73 dirt
setblock ~29 ~121 ~74 dirt
setblock ~29 ~121 ~75 dirt
setblock ~29 ~121 ~76 dirt
setblock ~29 ~121 ~77 dirt
setblock ~29 ~121 ~78 dirt
setblock ~29 ~121 ~79 dirt
setblock ~29 ~121 ~80 dirt
setblock ~29 ~121 ~81 dirt
setblock ~29 ~121 ~82 dirt
setblock ~29 ~121 ~83 dirt
setblock ~29 ~121 ~84 dirt
setblock ~29 ~121 ~85 dirt
setblock ~29 ~121 ~86 dirt
setblock ~29 ~121 ~87 dirt
setblock ~29 ~121 ~88 dirt
setblock ~29 ~121 ~89 dirt
setblock ~29 ~121 ~90 dirt
setblock ~29 ~121 ~91 dirt
setblock ~29 ~121 ~92 dirt
setblock ~29 ~121 ~93 dirt
setblock ~29 ~121 ~94 dirt
setblock ~29 ~121 ~95 dirt
setblock ~29 ~121 ~96 dirt
setblock ~29 ~121 ~97 dirt
setblock ~29 ~121 ~98 dirt
setblock ~29 ~121 ~99 dirt
setblock ~29 ~121 ~100 dirt
setblock ~29 ~121 ~101 dirt
setblock ~29 ~121 ~102 dirt
setblock ~29 ~121 ~103 dirt
setblock ~29 ~121 ~104 dirt
setblock ~29 ~121 ~105 dirt
setblock ~29 ~121 ~106 dirt
setblock ~29 ~121 ~107 dirt
setblock ~29 ~121 ~108 dirt
setblock ~29 ~122 ~66 dirt
setblock ~29 ~122 ~67 dirt
setblock ~29 ~122 ~68 dirt
setblock ~29 ~122 ~69 dirt
setblock ~29 ~122 ~70 dirt
setblock ~29 ~122 ~71 dirt
setblock ~29 ~122 ~72 dirt
setblock ~29 ~122 ~73 dirt
setblock ~29 ~122 ~74 dirt
setblock ~29 ~122 ~75 dirt
setblock ~29 ~122 ~76 dirt
setblock ~29 ~122 ~77 dirt
setblock ~29 ~122 ~78 dirt
setblock ~29 ~122 ~79 dirt
setblock ~29 ~122 ~80 dirt
setblock ~29 ~122 ~81 dirt
setblock ~29 ~122 ~82 dirt
setblock ~29 ~122 ~83 dirt
setblock ~29 ~122 ~84 dirt
setblock ~29 ~122 ~85 dirt
setblock ~29 ~122 ~86 dirt
setblock ~29 ~122 ~87 dirt
setblock ~29 ~122 ~88 dirt
setblock ~29 ~122 ~89 dirt
setblock ~29 ~122 ~90 dirt
setblock ~29 ~122 ~91 dirt
setblock ~29 ~122 ~92 dirt
setblock ~29 ~122 ~93 dirt
setblock ~29 ~122 ~94 dirt
setblock ~29 ~122 ~95 dirt
setblock ~29 ~122 ~96 dirt
setblock ~29 ~122 ~97 dirt
setblock ~29 ~122 ~98 dirt
setblock ~29 ~122 ~99 dirt
setblock ~29 ~122 ~100 dirt
setblock ~29 ~122 ~101 dirt
setblock ~29 ~122 ~102 dirt
setblock ~29 ~122 ~103 dirt
setblock ~29 ~122 ~104 dirt
setblock ~29 ~122 ~105 dirt
setblock ~29 ~122 ~106 dirt
setblock ~29 ~122 ~107 dirt
setblock ~29 ~122 ~108 dirt
setblock ~29 ~123 ~66 dirt
setblock ~29 ~123 ~67 dirt
setblock ~29 ~123 ~68 dirt
setblock ~29 ~123 ~69 dirt
setblock ~29 ~123 ~70 dirt
setblock ~29 ~123 ~71 dirt
setblock ~29 ~123 ~72 dirt
setblock ~29 ~123 ~73 dirt
setblock ~29 ~123 ~74 dirt
setblock ~29 ~123 ~75 dirt
setblock ~29 ~123 ~76 dirt
setblock ~29 ~123 ~77 dirt
setblock ~29 ~123 ~78 dirt
setblock ~29 ~123 ~79 dirt
setblock ~29 ~123 ~80 dirt
setblock ~29 ~123 ~81 dirt
setblock ~29 ~123 ~82 dirt
setblock ~29 ~123 ~83 dirt
setblock ~29 ~123 ~84 dirt
setblock ~29 ~123 ~85 dirt
setblock ~29 ~123 ~86 dirt
setblock ~29 ~123 ~87 dirt
setblock ~29 ~123 ~88 dirt
setblock ~29 ~123 ~89 dirt
setblock ~29 ~123 ~90 dirt
setblock ~29 ~123 ~91 dirt
setblock ~29 ~123 ~92 dirt
setblock ~29 ~123 ~93 dirt
setblock ~29 ~123 ~94 dirt
setblock ~29 ~123 ~95 dirt
setblock ~29 ~123 ~96 dirt
setblock ~29 ~123 ~97 dirt
setblock ~29 ~123 ~98 dirt
setblock ~29 ~123 ~99 dirt
setblock ~29 ~123 ~100 grass_block
setblock ~29 ~123 ~101 grass_block
setblock ~29 ~123 ~102 dirt
setblock ~29 ~123 ~103 dirt
setblock ~29 ~123 ~104 dirt
setblock ~29 ~123 ~105 dirt
setblock ~29 ~123 ~106 dirt
setblock ~29 ~123 ~107 dirt
setblock ~29 ~123 ~108 dirt
setblock ~29 ~124 ~66 grass_block
setblock ~29 ~124 ~67 grass_block
setblock ~29 ~124 ~68 grass_block
setblock ~29 ~124 ~69 grass_block
setblock ~29 ~124 ~70 grass_block
setblock ~29 ~124 ~71 grass_block
setblock ~29 ~124 ~72 grass_block
setblock ~29 ~124 ~73 grass_block
setblock ~29 ~124 ~74 grass_block
setblock ~29 ~124 ~75 grass_block
setblock ~29 ~124 ~76 grass_block
setblock ~29 ~124 ~77 grass_block
setblock ~29 ~124 ~78 dirt
setblock ~29 ~124 ~79 dirt
setblock ~29 ~124 ~80 dirt
setblock ~29 ~124 ~81 dirt
setblock ~29 ~124 ~82 dirt
setblock ~29 ~124 ~83 dirt
setblock ~29 ~124 ~84 dirt
setblock ~29 ~124 ~85 dirt
setblock ~29 ~124 ~86 dirt
setblock ~29 ~124 ~87 dirt
setblock ~29 ~124 ~88 dirt
setblock ~29 ~124 ~89 dirt
setblock ~29 ~124 ~90 dirt
setblock ~29 ~124 ~91 dirt
setblock ~29 ~124 ~92 dirt
setblock ~29 ~124 ~93 dirt
setblock ~29 ~124 ~94 dirt
setblock ~29 ~124 ~95 dirt
setblock ~29 ~124 ~96 dirt
setblock ~29 ~124 ~97 grass_block
setblock ~29 ~124 ~98 grass_block
setblock ~29 ~124 ~99 grass_block
setblock ~29 ~124 ~102 grass_block
setblock ~29 ~124 ~103 grass_block
setblock ~29 ~124 ~104 grass_block
setblock ~29 ~124 ~105 grass_block
setblock ~29 ~124 ~106 grass_block
setblock ~29 ~124 ~107 grass_block
setblock ~29 ~124 ~108 grass_block
setblock ~29 ~125 ~68 short_grass
setblock ~29 ~125 ~71 fern
setblock ~29 ~125 ~72 short_grass
setblock ~29 ~125 ~75 short_grass
setblock ~29 ~125 ~78 grass_block
setblock ~29 ~125 ~79 grass_block
setblock ~29 ~125 ~80 grass_block
setblock ~29 ~125 ~81 grass_block
setblock ~29 ~125 ~82 dirt
setblock ~29 ~125 ~83 dirt
setblock ~29 ~125 ~84 dirt
setblock ~29 ~125 ~85 dirt
setblock ~29 ~125 ~86 dirt
setblock ~29 ~125 ~87 dirt
setblock ~29 ~125 ~88 dirt
setblock ~29 ~125 ~89 dirt
setblock ~29 ~125 ~90 dirt
setblock ~29 ~125 ~91 dirt
setblock ~29 ~125 ~92 dirt
setblock ~29 ~125 ~93 dirt
setblock ~29 ~125 ~94 grass_block
setblock ~29 ~125 ~95 grass_block
setblock ~29 ~125 ~96 grass_block
setblock ~29 ~125 ~99 short_grass
setblock ~29 ~125 ~102 short_grass
setblock ~29 ~125 ~104 fern
setblock ~29 ~125 ~105 fern
setblock ~29 ~125 ~107 short_grass
setblock ~29 ~125 ~108 poppy
setblock ~29 ~126 ~78 fern
setblock ~29 ~126 ~79 short_grass
setblock ~29 ~126 ~82 grass_block
setblock ~29 ~126 ~83 grass_block
setblock ~29 ~126 ~84 grass_block
setblock ~29 ~126 ~85 grass_block
setblock ~29 ~126 ~86 grass_block
setblock ~29 ~126 ~87 grass_block
setblock ~29 ~126 ~88 dirt
setblock ~29 ~126 ~89 dirt
setblock ~29 ~126 ~90 dirt
setblock ~29 ~126 ~91 grass_block
setblock ~29 ~126 ~92 grass_block
setblock ~29 ~126 ~93 grass_block
setblock ~29 ~126 ~95 short_grass
setblock ~29 ~127 ~88 grass_block
setblock ~29 ~127 ~89 grass_block
setblock ~29 ~127 ~90 grass_block
setblock ~29 ~127 ~93 short_grass
setblock ~30 ~110 ~82 dirt
setblock ~30 ~110 ~85 dirt
setblock ~30 ~111 ~81 dirt
setblock ~30 ~111 ~82 dirt
setblock ~30 ~111 ~83 dirt
setblock ~30 ~111 ~85 dirt
setblock ~30 ~112 ~81 dirt
setblock ~30 ~112 ~82 dirt
setblock ~30 ~112 ~83 dirt
setblock ~30 ~112 ~84 dirt
setblock ~30 ~112 ~85 dirt
setblock ~30 ~112 ~86 dirt
setblock ~30 ~113 ~80 dirt
setblock ~30 ~113 ~81 dirt
setblock ~30 ~113 ~82 dirt
setblock ~30 ~113 ~83 dirt
setblock ~30 ~113 ~84 dirt
setblock ~30 ~113 ~85 dirt
setblock ~30 ~113 ~86 dirt
setblock ~30 ~113 ~87 dirt
setblock ~30 ~113 ~88 dirt
setblock ~30 ~113 ~104 dirt
setblock ~30 ~114 ~80 dirt
setblock ~30 ~114 ~81 dirt
setblock ~30 ~114 ~82 dirt
setblock ~30 ~114 ~83 dirt
setblock ~30 ~114 ~84 dirt
setblock ~30 ~114 ~85 dirt
setblock ~30 ~114 ~86 dirt
setblock ~30 ~114 ~87 dirt
setblock ~30 ~114 ~88 dirt
setblock ~30 ~114 ~103 dirt
setblock ~30 ~114 ~104 dirt
setblock ~30 ~114 ~105 dirt
setblock ~30 ~115 ~79 dirt
setblock ~30 ~115 ~80 dirt
setblock ~30 ~115 ~81 dirt
setblock ~30 ~115 ~82 dirt
setblock ~30 ~115 ~83 dirt
setblock ~30 ~115 ~84 dirt
setblock ~30 ~115 ~85 dirt
setblock ~30 ~115 ~86 dirt
setblock ~30 ~115 ~87 dirt
setblock ~30 ~115 ~88 dirt
setblock ~30 ~115 ~90 dirt
setblock ~30 ~115 ~91 dirt
setblock ~30 ~115 ~99 dirt
setblock ~30 ~115 ~100 dirt
setblock ~30 ~115 ~103 dirt
setblock ~30 ~115 ~104 dirt
setblock ~30 ~115 ~105 dirt
setblock ~30 ~116 ~68 dirt
setblock ~30 ~116 ~74 dirt
setblock ~30 ~116 ~78 dirt
setblock ~30 ~116 ~79 dirt
setblock ~30 ~116 ~80 dirt
setblock ~30 ~116 ~81 dirt
setblock ~30 ~116 ~82 dirt
setblock ~30 ~116 ~83 dirt
setblock ~30 ~116 ~84 dirt
setblock ~30 ~116 ~85 dirt
setblock ~30 ~116 ~86 dirt
setblock ~30 ~116 ~87 dirt
setblock ~30 ~116 ~88 dirt
setblock ~30 ~116 ~89 dirt
setblock ~30 ~116 ~90 dirt
setblock ~30 ~116 ~91 dirt
setblock ~30 ~116 ~92 dirt
setblock ~30 ~116 ~97 dirt
setblock ~30 ~116 ~99 dirt
setblock ~30 ~116 ~100 dirt
setblock ~30 ~116 ~101 dirt
setblock ~30 ~116 ~102 dirt
setblock ~30 ~116 ~103 dirt
setblock ~30 ~116 ~104 dirt
setblock ~30 ~116 ~105 dirt
setblock ~30 ~117 ~67 dirt
setblock ~30 ~117 ~68 dirt
setblock ~30 ~117 ~73 dirt
setblock ~30 ~117 ~74 dirt
setblock ~30 ~117 ~75 dirt
setblock ~30 ~117 ~77 dirt
setblock ~30 ~117 ~78 dirt
setblock ~30 ~117 ~79 dirt
setblock ~30 ~117 ~80 dirt
setblock ~30 ~117 ~81 dirt
setblock ~30 ~117 ~82 dirt
setblock ~30 ~117 ~83 dirt
setblock ~30 ~117 ~84 dirt
setblock ~30 ~117 ~85 dirt
setblock ~30 ~117 ~86 dirt
setblock ~30 ~117 ~87 dirt
setblock ~30 ~117 ~88 dirt
setblock ~30 ~117 ~89 dirt
setblock ~30 ~117 ~90 dirt
setblock ~30 ~117 ~91 dirt
setblock ~30 ~117 ~92 dirt
setblock ~30 ~117 ~93 dirt
setblock ~30 ~117 ~97 dirt
setblock ~30 ~117 ~98 dirt
setblock ~30 ~117 ~99 dirt
setblock ~30 ~117 ~100 dirt
setblock ~30 ~117 ~101 dirt
setblock ~30 ~117 ~102 dirt
setblock ~30 ~117 ~103 dirt
setblock ~30 ~117 ~104 dirt
setblock ~30 ~117 ~105 dirt
setblock ~30 ~117 ~106 dirt
setblock ~30 ~118 ~67 dirt
setblock ~30 ~118 ~68 dirt
setblock ~30 ~118 ~71 dirt
setblock ~30 ~118 ~72 dirt
setblock ~30 ~118 ~73 dirt
setblock ~30 ~118 ~74 dirt
setblock ~30 ~118 ~75 dirt
setblock ~30 ~118 ~77 dirt
setblock ~30 ~118 ~78 dirt
setblock ~30 ~118 ~79 dirt
setblock ~30 ~118 ~80 dirt
setblock ~30 ~118 ~81 dirt
setblock ~30 ~118 ~82 dirt
setblock ~30 ~118 ~83 dirt
setblock ~30 ~118 ~84 dirt
setblock ~30 ~118 ~85 dirt
setblock ~30 ~118 ~86 dirt
setblock ~30 ~118 ~87 dirt
setblock ~30 ~118 ~88 dirt
setblock ~30 ~118 ~89 dirt
setblock ~30 ~118 ~90 dirt
setblock ~30 ~118 ~91 dirt
setblock ~30 ~118 ~92 dirt
setblock ~30 ~118 ~93 dirt
setblock ~30 ~118 ~97 dirt
setblock ~30 ~118 ~98 dirt
setblock ~30 ~118 ~99 dirt
setblock ~30 ~118 ~100 dirt
setblock ~30 ~118 ~101 dirt
setblock ~30 ~118 ~102 dirt
setblock ~30 ~118 ~103 dirt
setblock ~30 ~118 ~104 dirt
setblock ~30 ~118 ~105 dirt
setblock ~30 ~118 ~106 dirt
setblock ~30 ~118 ~107 dirt
setblock ~30 ~119 ~67 dirt
setblock ~30 ~119 ~68 dirt
setblock ~30 ~119 ~69 dirt
setblock ~30 ~119 ~70 dirt
setblock ~30 ~119 ~71 dirt
setblock ~30 ~119 ~72 dirt
setblock ~30 ~119 ~73 dirt
setblock ~30 ~119 ~74 dirt
setblock ~30 ~119 ~75 dirt
setblock ~30 ~119 ~76 dirt
setblock ~30 ~119 ~77 dirt
setblock ~30 ~119 ~78 dirt
setblock ~30 ~119 ~79 dirt
setblock ~30 ~119 ~80 dirt
setblock ~30 ~119 ~81 dirt
setblock ~30 ~119 ~82 dirt
setblock ~30 ~119 ~83 dirt
setblock ~30 ~119 ~84 dirt
setblock ~30 ~119 ~85 dirt
setblock ~30 ~119 ~86 dirt
setblock ~30 ~119 ~87 dirt
setblock ~30 ~119 ~88 dirt
setblock ~30 ~119 ~89 dirt
setblock ~30 ~119 ~90 dirt
setblock ~30 ~119 ~91 dirt
setblock ~30 ~119 ~92 dirt
setblock ~30 ~119 ~93 dirt
setblock ~30 ~119 ~94 dirt
setblock ~30 ~119 ~96 dirt
setblock ~30 ~119 ~97 dirt
setblock ~30 ~119 ~98 dirt
setblock ~30 ~119 ~99 dirt
setblock ~30 ~119 ~100 dirt
setblock ~30 ~119 ~101 dirt
setblock ~30 ~119 ~102 dirt
setblock ~30 ~119 ~103 dirt
setblock ~30 ~119 ~104 dirt
setblock ~30 ~119 ~105 dirt
setblock ~30 ~119 ~106 dirt
setblock ~30 ~119 ~107 dirt
setblock ~30 ~119 ~108 dirt
setblock ~30 ~120 ~66 dirt
setblock ~30 ~120 ~67 dirt
setblock ~30 ~120 ~68 dirt
setblock ~30 ~120 ~69 dirt
setblock ~30 ~120 ~70 dirt
setblock ~30 ~120 ~71 dirt
setblock ~30 ~120 ~72 dirt
setblock ~30 ~120 ~73 dirt
setblock ~30 ~120 ~74 dirt
setblock ~30 ~120 ~75 dirt
setblock ~30 ~120 ~76 dirt
setblock ~30 ~120 ~77 dirt
setblock ~30 ~120 ~78 dirt
setblock ~30 ~120 ~79 dirt
setblock ~30 ~120 ~80 dirt
setblock ~30 ~120 ~81 dirt
setblock ~30 ~120 ~82 dirt
setblock ~30 ~120 ~83 dirt
setblock ~30 ~120 ~84 dirt
setblock ~30 ~120 ~85 dirt
setblock ~30 ~120 ~86 dirt
setblock ~30 ~120 ~87 dirt
setblock ~30 ~120 ~88 dirt
setblock ~30 ~120 ~89 dirt
setblock ~30 ~120 ~90 dirt
setblock ~30 ~120 ~91 dirt
setblock ~30 ~120 ~92 dirt
setblock ~30 ~120 ~93 dirt
setblock ~30 ~120 ~94 dirt
setblock ~30 ~120 ~95 dirt
setblock ~30 ~120 ~96 dirt
setblock ~30 ~120 ~97 dirt
setblock ~30 ~120 ~98 dirt
setblock ~30 ~120 ~99 dirt
setblock ~30 ~120 ~100 dirt
setblock ~30 ~120 ~101 dirt
setblock ~30 ~120 ~102 dirt
setblock ~30 ~120 ~103 dirt
setblock ~30 ~120 ~104 dirt
setblock ~30 ~120 ~105 dirt
setblock ~30 ~120 ~106 dirt
setblock ~30 ~120 ~107 dirt
setblock ~30 ~120 ~108 dirt
setblock ~30 ~121 ~65 dirt
setblock ~30 ~121 ~66 dirt
setblock ~30 ~121 ~67 dirt
setblock ~30 ~121 ~68 dirt
setblock ~30 ~121 ~69 dirt
setblock ~30 ~121 ~70 dirt
setblock ~30 ~121 ~71 dirt
setblock ~30 ~121 ~72 dirt
setblock ~30 ~121 ~73 dirt
setblock ~30 ~121 ~74 dirt
setblock ~30 ~121 ~75 dirt
setblock ~30 ~121 ~76 dirt
setblock ~30 ~121 ~77 dirt
setblock ~30 ~121 ~78 dirt
setblock ~30 ~121 ~79 dirt
setblock ~30 ~121 ~80 dirt
setblock ~30 ~121 ~81 dirt
setblock ~30 ~121 ~82 dirt
setblock ~30 ~121 ~83 dirt
setblock ~30 ~121 ~84 dirt
setblock ~30 ~121 ~85 dirt
setblock ~30 ~121 ~86 dirt
setblock ~30 ~121 ~87 dirt
setblock ~30 ~121 ~88 dirt
setblock ~30 ~121 ~89 dirt
setblock ~30 ~121 ~90 dirt
setblock ~30 ~121 ~91 dirt
setblock ~30 ~121 ~92 dirt
setblock ~30 ~121 ~93 dirt
setblock ~30 ~121 ~94 dirt
setblock ~30 ~121 ~95 dirt
setblock ~30 ~121 ~96 dirt
setblock ~30 ~121 ~97 dirt
setblock ~30 ~121 ~98 dirt
setblock ~30 ~121 ~99 dirt
setblock ~30 ~121 ~100 dirt
setblock ~30 ~121 ~101 dirt
setblock ~30 ~121 ~102 dirt
setblock ~30 ~121 ~103 dirt
setblock ~30 ~121 ~104 dirt
setblock ~30 ~121 ~105 dirt
setblock ~30 ~121 ~106 dirt
setblock ~30 ~121 ~107 dirt
setblock ~30 ~121 ~108 dirt
setblock ~30 ~121 ~109 dirt
setblock ~30 ~121 ~111 dirt
setblock ~30 ~122 ~65 dirt
setblock ~30 ~122 ~66 dirt
setblock ~30 ~122 ~67 dirt
setblock ~30 ~122 ~68 dirt
setblock ~30 ~122 ~69 dirt
setblock ~30 ~122 ~70 dirt
setblock ~30 ~122 ~71 dirt
setblock ~30 ~122 ~72 dirt
setblock ~30 ~122 ~73 dirt
setblock ~30 ~122 ~74 dirt
setblock ~30 ~122 ~75 dirt
setblock ~30 ~122 ~76 dirt
setblock ~30 ~122 ~77 dirt
setblock ~30 ~122 ~78 dirt
setblock ~30 ~122 ~79 dirt
setblock ~30 ~122 ~80 dirt
setblock ~30 ~122 ~81 dirt
setblock ~30 ~122 ~82 dirt
setblock ~30 ~122 ~83 dirt
setblock ~30 ~122 ~84 dirt
setblock ~30 ~122 ~85 dirt
setblock ~30 ~122 ~86 dirt
setblock ~30 ~122 ~87 dirt
setblock ~30 ~122 ~88 dirt
setblock ~30 ~122 ~89 dirt
setblock ~30 ~122 ~90 dirt
setblock ~30 ~122 ~91 dirt
setblock ~30 ~122 ~92 dirt
setblock ~30 ~122 ~93 dirt
setblock ~30 ~122 ~94 dirt
setblock ~30 ~122 ~95 dirt
setblock ~30 ~122 ~96 dirt
setblock ~30 ~122 ~97 dirt
setblock ~30 ~122 ~98 dirt
setblock ~30 ~122 ~99 dirt
setblock ~30 ~122 ~100 dirt
setblock ~30 ~122 ~101 dirt
setblock ~30 ~122 ~102 dirt
setblock ~30 ~122 ~103 dirt
setblock ~30 ~122 ~104 dirt
setblock ~30 ~122 ~105 dirt
setblock ~30 ~122 ~106 dirt
setblock ~30 ~122 ~107 dirt
setblock ~30 ~122 ~108 dirt
setblock ~30 ~122 ~109 dirt
setblock ~30 ~122 ~111 dirt
setblock ~30 ~123 ~65 dirt
setblock ~30 ~123 ~66 dirt
setblock ~30 ~123 ~67 dirt
setblock ~30 ~123 ~68 dirt
setblock ~30 ~123 ~69 dirt
setblock ~30 ~123 ~70 dirt
setblock ~30 ~123 ~71 dirt
setblock ~30 ~123 ~72 dirt
setblock ~30 ~123 ~73 dirt
setblock ~30 ~123 ~74 dirt
setblock ~30 ~123 ~75 dirt
setblock ~30 ~123 ~76 dirt
setblock ~30 ~123 ~77 dirt
setblock ~30 ~123 ~78 dirt
setblock ~30 ~123 ~79 dirt
setblock ~30 ~123 ~80 dirt
setblock ~30 ~123 ~81 dirt
setblock ~30 ~123 ~82 dirt
setblock ~30 ~123 ~83 dirt
setblock ~30 ~123 ~84 dirt
setblock ~30 ~123 ~85 dirt
setblock ~30 ~123 ~86 dirt
setblock ~30 ~123 ~87 dirt
setblock ~30 ~123 ~88 dirt
setblock ~30 ~123 ~89 dirt
setblock ~30 ~123 ~90 dirt
setblock ~30 ~123 ~91 dirt
setblock ~30 ~123 ~92 dirt
setblock ~30 ~123 ~93 dirt
setblock ~30 ~123 ~94 dirt
setblock ~30 ~123 ~95 dirt
setblock ~30 ~123 ~96 dirt
setblock ~30 ~123 ~97 dirt
setblock ~30 ~123 ~98 dirt
setblock ~30 ~123 ~99 dirt
setblock ~30 ~123 ~100 grass_block
setblock ~30 ~123 ~101 grass_block
setblock ~30 ~123 ~102 grass_block
setblock ~30 ~123 ~103 grass_block
setblock ~30 ~123 ~104 grass_block
setblock ~30 ~123 ~105 grass_block
setblock ~30 ~123 ~106 dirt
setblock ~30 ~123 ~107 dirt
setblock ~30 ~123 ~108 dirt
setblock ~30 ~123 ~109 dirt
setblock ~30 ~123 ~111 dirt
setblock ~30 ~124 ~65 grass_block
setblock ~30 ~124 ~66 grass_block
setblock ~30 ~124 ~67 grass_block
setblock ~30 ~124 ~68 grass_block
setblock ~30 ~124 ~69 grass_block
setblock ~30 ~124 ~70 grass_block
setblock ~30 ~124 ~71 grass_block
setblock ~30 ~124 ~72 grass_block
setblock ~30 ~124 ~73 grass_block
setblock ~30 ~124 ~74 grass_block
setblock ~30 ~124 ~75 grass_block
setblock ~30 ~124 ~76 grass_block
setblock ~30 ~124 ~77 grass_block
setblock ~30 ~124 ~78 dirt
setblock ~30 ~124 ~79 dirt
setblock ~30 ~124 ~80 dirt
setblock ~30 ~124 ~81 dirt
setblock ~30 ~124 ~82 dirt
setblock ~30 ~124 ~83 dirt
setblock ~30 ~124 ~84 dirt
setblock ~30 ~124 ~85 dirt
setblock ~30 ~124 ~86 dirt
setblock ~30 ~124 ~87 dirt
setblock ~30 ~124 ~88 dirt
setblock ~30 ~124 ~89 dirt
setblock ~30 ~124 ~90 dirt
setblock ~30 ~124 ~91 dirt
setblock ~30 ~124 ~92 dirt
setblock ~30 ~124 ~93 dirt
setblock ~30 ~124 ~94 dirt
setblock ~30 ~124 ~95 dirt
setblock ~30 ~124 ~96 dirt
setblock ~30 ~124 ~97 grass_block
setblock ~30 ~124 ~98 grass_block
setblock ~30 ~124 ~99 grass_block
setblock ~30 ~124 ~101 short_grass
setblock ~30 ~124 ~106 grass_block
setblock ~30 ~124 ~107 grass_block
setblock ~30 ~124 ~108 grass_block
setblock ~30 ~124 ~109 grass_block
setblock ~30 ~124 ~111 grass_block
setblock ~30 ~125 ~66 poppy
setblock ~30 ~125 ~71 short_grass
setblock ~30 ~125 ~77 short_grass
setblock ~30 ~125 ~78 grass_block
setblock ~30 ~125 ~79 grass_block
setblock ~30 ~125 ~80 grass_block
setblock ~30 ~125 ~81 grass_block
setblock ~30 ~125 ~82 dirt
setblock ~30 ~125 ~83 dirt
setblock ~30 ~125 ~84 dirt
setblock ~30 ~125 ~85 dirt
setblock ~30 ~125 ~86 dirt
setblock ~30 ~125 ~87 dirt
setblock ~30 ~125 ~88 dirt
setblock ~30 ~125 ~89 dirt
setblock ~30 ~125 ~90 dirt
setblock ~30 ~125 ~91 dirt
setblock ~30 ~125 ~92 dirt
setblock ~30 ~125 ~93 dirt
setblock ~30 ~125 ~94 grass_block
setblock ~30 ~125 ~95 grass_block
setblock ~30 ~125 ~96 grass_block
setblock ~30 ~125 ~98 fern
setblock ~30 ~125 ~107 poppy
setblock ~30 ~125 ~108 fern
setblock ~30 ~125 ~111 fern
setblock ~30 ~126 ~79 short_grass
setblock ~30 ~126 ~81 fern
setblock ~30 ~126 ~82 grass_block
setblock ~30 ~126 ~83 grass_block
setblock ~30 ~126 ~84 grass_block
setblock ~30 ~126 ~85 grass_block
setblock ~30 ~126 ~86 dirt
setblock ~30 ~126 ~87 dirt
setblock ~30 ~126 ~88 dirt
setblock ~30 ~126 ~89 dirt
setblock ~30 ~126 ~90 dirt
setblock ~30 ~126 ~91 dirt
setblock ~30 ~126 ~92 grass_block
setblock ~30 ~126 ~93 grass_block
setblock ~30 ~126 ~94 poppy
setblock ~30 ~126 ~95 fern
setblock ~30 ~127 ~82 fern
setblock ~30 ~127 ~83 short_grass
setblock ~30 ~127 ~86 grass_block
setblock ~30 ~127 ~87 grass_block
setblock ~30 ~127 ~88 grass_block
setblock ~30 ~127 ~89 grass_block
setblock ~30 ~127 ~90 grass_block
setblock ~30 ~127 ~91 grass_block
setblock ~30 ~128 ~64 oak_leaves[persistent=true]
setblock ~30 ~128 ~65 jungle_leaves[persistent=true]
setblock ~30 ~128 ~66 oak_leaves[persistent=true]
setblock ~30 ~128 ~67 oak_leaves[persistent=true]
setblock ~30 ~128 ~91 poppy
setblock ~30 ~129 ~64 oak_leaves[persistent=true]
setblock ~30 ~129 ~65 oak_leaves[persistent=true]
setblock ~30 ~129 ~66 oak_leaves[persistent=true]
setblock ~30 ~130 ~64 oak_leaves[persistent=true]
setblock ~30 ~130 ~67 jungle_leaves[persistent=true]
setblock ~30 ~131 ~64 oak_leaves[persistent=true]
setblock ~30 ~131 ~65 oak_leaves[persistent=true]
setblock ~30 ~131 ~66 jungle_leaves[persistent=true]
setblock ~30 ~131 ~67 oak_leaves[persistent=true]
setblock ~31 ~108 ~85 dirt
setblock ~31 ~109 ~82 dirt
setblock ~31 ~109 ~83 dirt
setblock ~31 ~109 ~85 dirt
setblock ~31 ~110 ~81 dirt
setblock ~31 ~110 ~82 dirt
setblock ~31 ~110 ~83 dirt
setblock ~31 ~110 ~84 dirt
setblock ~31 ~110 ~85 dirt
setblock ~31 ~110 ~86 dirt
setblock ~31 ~111 ~81 dirt
setblock ~31 ~111 ~82 dirt
setblock ~31 ~111 ~83 dirt
setblock ~31 ~111 ~84 dirt
setblock ~31 ~111 ~85 dirt
setblock ~31 ~111 ~86 dirt
setblock ~31 ~112 ~81 dirt
setblock ~31 ~112 ~82 dirt
setblock ~31 ~112 ~83 dirt
setblock ~31 ~112 ~84 dirt
setblock ~31 ~112 ~85 dirt
setblock ~31 ~112 ~86 dirt
setblock ~31 ~112 ~87 dirt
setblock ~31 ~112 ~88 dirt
setblock ~31 ~112 ~101 dirt
setblock ~31 ~112 ~103 dirt
setblock ~31 ~112 ~104 dirt
setblock ~31 ~113 ~80 dirt
setblock ~31 ~113 ~81 dirt
setblock ~31 ~113 ~82 dirt
setblock ~31 ~113 ~83 dirt
setblock ~31 ~113 ~84 dirt
setblock ~31 ~113 ~85 dirt
setblock ~31 ~113 ~86 dirt
setblock ~31 ~113 ~87 dirt
setblock ~31 ~113 ~88 dirt
setblock ~31 ~113 ~89 dirt
setblock ~31 ~113 ~100 dirt
setblock ~31 ~113 ~101 dirt
setblock ~31 ~113 ~102 dirt
setblock ~31 ~113 ~103 dirt
setblock ~31 ~113 ~104 dirt
setblock ~31 ~113 ~105 dirt
setblock ~31 ~114 ~74 dirt
setblock ~31 ~114 ~77 dirt
setblock ~31 ~114 ~79 dirt
setblock ~31 ~114 ~80 dirt
setblock ~31 ~114 ~81 dirt
setblock ~31 ~114 ~82 dirt
setblock ~31 ~114 ~83 dirt
setblock ~31 ~114 ~84 dirt
setblock ~31 ~114 ~85 dirt
setblock ~31 ~114 ~86 dirt
setblock ~31 ~114 ~87 dirt
setblock ~31 ~114 ~88 dirt
setblock ~31 ~114 ~89 dirt
setblock ~31 ~114 ~90 dirt
setblock ~31 ~114 ~91 dirt
setblock ~31 ~114 ~99 dirt
setblock ~31 ~114 ~100 dirt
setblock ~31 ~114 ~101 dirt
setblock ~31 ~114 ~102 dirt
setblock ~31 ~114 ~103 dirt
setblock ~31 ~114 ~104 dirt
setblock ~31 ~114 ~105 dirt
setblock ~31 ~114 ~106 dirt
setblock ~31 ~115 ~67 dirt
setblock ~31 ~115 ~68 dirt
setblock ~31 ~115 ~71 dirt
setblock ~31 ~115 ~73 dirt
setblock ~31 ~115 ~74 dirt
setblock ~31 ~115 ~77 dirt
setblock ~31 ~115 ~78 dirt
setblock ~31 ~115 ~79 dirt
setblock ~31 ~115 ~80 dirt
setblock ~31 ~115 ~81 dirt
setblock ~31 ~115 ~82 dirt
setblock ~31 ~115 ~83 dirt
setblock ~31 ~115 ~84 dirt
setblock ~31 ~115 ~85 dirt
setblock ~31 ~115 ~86 dirt
setblock ~31 ~115 ~87 dirt
setblock ~31 ~115 ~88 dirt
setblock ~31 ~115 ~89 dirt
setblock ~31 ~115 ~90 dirt
setblock ~31 ~115 ~91 dirt
setblock ~31 ~115 ~92 dirt
setblock ~31 ~115 ~97 dirt
setblock ~31 ~115 ~98 dirt
setblock ~31 ~115 ~99 dirt
setblock ~31 ~115 ~100 dirt
setblock ~31 ~115 ~101 dirt
setblock ~31 ~115 ~102 dirt
setblock ~31 ~115 ~103 dirt
setblock ~31 ~115 ~104 dirt
setblock ~31 ~115 ~105 dirt
setblock ~31 ~115 ~106 dirt
setblock ~31 ~116 ~67 dirt
setblock ~31 ~116 ~68 dirt
setblock ~31 ~116 ~69 dirt
setblock ~31 ~116 ~71 dirt
setblock ~31 ~116 ~73 dirt
setblock ~31 ~116 ~74 dirt
setblock ~31 ~116 ~75 dirt
setblock ~31 ~116 ~76 dirt
setblock ~31 ~116 ~77 dirt
setblock ~31 ~116 ~78 dirt
setblock ~31 ~116 ~79 dirt
setblock ~31 ~116 ~80 dirt
setblock ~31 ~116 ~81 dirt
setblock ~31 ~116 ~82 dirt
setblock ~31 ~116 ~83 dirt
setblock ~31 ~116 ~84 dirt
setblock ~31 ~116 ~85 dirt
setblock ~31 ~116 ~86 dirt
setblock ~31 ~116 ~87 dirt
setblock ~31 ~116 ~88 dirt
setblock ~31 ~116 ~89 dirt
setblock ~31 ~116 ~90 dirt
setblock ~31 ~116 ~91 dirt
setblock ~31 ~116 ~92 dirt
setblock ~31 ~116 ~93 dirt
setblock ~31 ~116 ~96 dirt
setblock ~31 ~116 ~97 dirt
setblock ~31 ~116 ~98 dirt
setblock ~31 ~116 ~99 dirt
setblock ~31 ~116 ~100 dirt
setblock ~31 ~116 ~101 dirt
setblock ~31 ~116 ~102 dirt
setblock ~31 ~116 ~103 dirt
setblock ~31 ~116 ~104 dirt
setblock ~31 ~116 ~105 dirt
setblock ~31 ~116 ~106 dirt
setblock ~31 ~117 ~66 dirt
setblock ~31 ~117 ~67 dirt
setblock ~31 ~117 ~68 dirt
setblock ~31 ~117 ~69 dirt
setblock ~31 ~117 ~70 dirt
setblock ~31 ~117 ~71 dirt
setblock ~31 ~117 ~72 dirt
setblock ~31 ~117 ~73 dirt
setblock ~31 ~117 ~74 dirt
setblock ~31 ~117 ~75 dirt
setblock ~31 ~117 ~76 dirt
setblock ~31 ~117 ~77 dirt
setblock ~31 ~117 ~78 dirt
setblock ~31 ~117 ~79 dirt
setblock ~31 ~117 ~80 dirt
setblock ~31 ~117 ~81 dirt
setblock ~31 ~117 ~82 dirt
setblock ~31 ~117 ~83 dirt
setblock ~31 ~117 ~84 dirt
setblock ~31 ~117 ~85 dirt
setblock ~31 ~117 ~86 dirt
setblock ~31 ~117 ~87 dirt
setblock ~31 ~117 ~88 dirt
setblock ~31 ~117 ~89 dirt
setblock ~31 ~117 ~90 dirt
setblock ~31 ~117 ~91 dirt
setblock ~31 ~117 ~92 dirt
setblock ~31 ~117 ~93 dirt
setblock ~31 ~117 ~94 dirt
setblock ~31 ~117 ~96 dirt
setblock ~31 ~117 ~97 dirt
setblock ~31 ~117 ~98 dirt
setblock ~31 ~117 ~99 dirt
setblock ~31 ~117 ~100 dirt
setblock ~31 ~117 ~101 dirt
setblock ~31 ~117 ~102 dirt
setblock ~31 ~117 ~103 dirt
setblock ~31 ~117 ~104 dirt
setblock ~31 ~117 ~105 dirt
setblock ~31 ~117 ~106 dirt
setblock ~31 ~117 ~107 dirt
setblock ~31 ~117 ~108 dirt
setblock ~31 ~118 ~66 dirt
setblock ~31 ~118 ~67 dirt
setblock ~31 ~118 ~68 dirt
setblock ~31 ~118 ~69 dirt
setblock ~31 ~118 ~70 dirt
setblock ~31 ~118 ~71 dirt
setblock ~31 ~118 ~72 dirt
setblock ~31 ~118 ~73 dirt
setblock ~31 ~118 ~74 dirt
setblock ~31 ~118 ~75 dirt
setblock ~31 ~118 ~76 dirt
setblock ~31 ~118 ~77 dirt
setblock ~31 ~118 ~78 dirt
setblock ~31 ~118 ~79 dirt
setblock ~31 ~118 ~80 dirt
setblock ~31 ~118 ~81 dirt
setblock ~31 ~118 ~82 dirt
setblock ~31 ~118 ~83 dirt
setblock ~31 ~118 ~84 dirt
setblock ~31 ~118 ~85 dirt
setblock ~31 ~118 ~86 dirt
setblock ~31 ~118 ~87 dirt
setblock ~31 ~118 ~88 dirt
setblock ~31 ~118 ~89 dirt
setblock ~31 ~118 ~90 dirt
setblock ~31 ~118 ~91 dirt
setblock ~31 ~118 ~92 dirt
setblock ~31 ~118 ~93 dirt
setblock ~31 ~118 ~94 dirt
setblock ~31 ~118 ~95 dirt
setblock ~31 ~118 ~96 dirt
setblock ~31 ~118 ~97 dirt
setblock ~31 ~118 ~98 dirt
setblock ~31 ~118 ~99 dirt
setblock ~31 ~118 ~100 dirt
setblock ~31 ~118 ~101 dirt
setblock ~31 ~118 ~102 dirt
setblock ~31 ~118 ~103 dirt
setblock ~31 ~118 ~104 dirt
setblock ~31 ~118 ~105 dirt
setblock ~31 ~118 ~106 dirt
setblock ~31 ~118 ~107 dirt
setblock ~31 ~118 ~108 dirt
setblock ~31 ~118 ~109 dirt
setblock ~31 ~119 ~65 dirt
setblock ~31 ~119 ~66 dirt
setblock ~31 ~119 ~67 dirt
setblock ~31 ~119 ~68 dirt
setblock ~31 ~119 ~69 dirt
setblock ~31 ~119 ~70 dirt
setblock ~31 ~119 ~71 dirt
setblock ~31 ~119 ~72 dirt
setblock ~31 ~119 ~73 dirt
setblock ~31 ~119 ~74 dirt
setblock ~31 ~119 ~75 dirt
setblock ~31 ~119 ~76 dirt
setblock ~31 ~119 ~77 dirt
setblock ~31 ~119 ~78 dirt
setblock ~31 ~119 ~79 dirt
setblock ~31 ~119 ~80 dirt
setblock ~31 ~119 ~81 dirt
setblock ~31 ~119 ~82 dirt
setblock ~31 ~119 ~83 dirt
setblock ~31 ~119 ~84 dirt
setblock ~31 ~119 ~85 dirt
setblock ~31 ~119 ~86 dirt
setblock ~31 ~119 ~87 dirt
setblock ~31 ~119 ~88 dirt
setblock ~31 ~119 ~89 dirt
setblock ~31 ~119 ~90 dirt
setblock ~31 ~119 ~91 dirt
setblock ~31 ~119 ~92 dirt
setblock ~31 ~119 ~93 dirt
setblock ~31 ~119 ~94 dirt
setblock ~31 ~119 ~95 dirt
setblock ~31 ~119 ~96 dirt
setblock ~31 ~119 ~97 dirt
setblock ~31 ~119 ~98 dirt
setblock ~31 ~119 ~99 dirt
setblock ~31 ~119 ~100 dirt
setblock ~31 ~119 ~101 dirt
setblock ~31 ~119 ~102 dirt
setblock ~31 ~119 ~103 dirt
setblock ~31 ~119 ~104 dirt
setblock ~31 ~119 ~105 dirt
setblock ~31 ~119 ~106 dirt
setblock ~31 ~119 ~107 dirt
setblock ~31 ~119 ~108 dirt
setblock ~31 ~119 ~109 dirt
setblock ~31 ~119 ~111 dirt
setblock ~31 ~120 ~64 dirt
setblock ~31 ~120 ~65 dirt
setblock ~31 ~120 ~66 dirt
setblock ~31 ~120 ~67 dirt
setblock ~31 ~120 ~68 dirt
setblock ~31 ~120 ~69 dirt
setblock ~31 ~120 ~70 dirt
setblock ~31 ~120 ~71 dirt
setblock ~31 ~120 ~72 dirt
setblock ~31 ~120 ~73 dirt
setblock ~31 ~120 ~74 dirt
setblock ~31 ~120 ~75 dirt
setblock ~31 ~120 ~76 dirt
setblock ~31 ~120 ~77 dirt
setblock ~31 ~120 ~78 dirt
setblock ~31 ~120 ~79 dirt
setblock ~31 ~120 ~80 dirt
setblock ~31 ~120 ~81 dirt
setblock ~31 ~120 ~82 dirt
setblock ~31 ~120 ~83 dirt
setblock ~31 ~120 ~84 dirt
setblock ~31 ~120 ~85 dirt
setblock ~31 ~120 ~86 dirt
setblock ~31 ~120 ~87 dirt
setblock ~31 ~120 ~88 dirt
setblock ~31 ~120 ~89 dirt
setblock ~31 ~120 ~90 dirt
setblock ~31 ~120 ~91 dirt
setblock ~31 ~120 ~92 dirt
setblock ~31 ~120 ~93 dirt
setblock ~31 ~120 ~94 dirt
setblock ~31 ~120 ~95 dirt
setblock ~31 ~120 ~96 dirt
setblock ~31 ~120 ~97 dirt
setblock ~31 ~120 ~98 dirt
setblock ~31 ~120 ~99 dirt
setblock ~31 ~120 ~100 dirt
setblock ~31 ~120 ~101 dirt
setblock ~31 ~120 ~102 dirt
setblock ~31 ~120 ~103 dirt
setblock ~31 ~120 ~104 dirt
setblock ~31 ~120 ~105 dirt
setblock ~31 ~120 ~106 dirt
setblock ~31 ~120 ~107 dirt
setblock ~31 ~120 ~108 dirt
setblock ~31 ~120 ~109 dirt
setblock ~31 ~120 ~110 dirt
setblock ~31 ~120 ~111 dirt
setblock ~31 ~121 ~64 dirt
setblock ~31 ~121 ~65 dirt
setblock ~31 ~121 ~66 dirt
setblock ~31 ~121 ~67 dirt
setblock ~31 ~121 ~68 dirt
setblock ~31 ~121 ~69 dirt
setblock ~31 ~121 ~70 dirt
setblock ~31 ~121 ~71 dirt
setblock ~31 ~121 ~72 dirt
setblock ~31 ~121 ~73 dirt
setblock ~31 ~121 ~74 dirt
setblock ~31 ~121 ~75 dirt
setblock ~31 ~121 ~76 dirt
setblock ~31 ~121 ~77 dirt
setblock ~31 ~121 ~78 dirt
setblock ~31 ~121 ~79 dirt
setblock ~31 ~121 ~80 dirt
setblock ~31 ~121 ~81 dirt
setblock ~31 ~121 ~82 dirt
setblock ~31 ~121 ~83 dirt
setblock ~31 ~121 ~84 dirt
setblock ~31 ~121 ~85 dirt
setblock ~31 ~121 ~86 dirt
setblock ~31 ~121 ~87 dirt
setblock ~31 ~121 ~88 dirt
setblock ~31 ~121 ~89 dirt
setblock ~31 ~121 ~90 dirt
setblock ~31 ~121 ~91 dirt
setblock ~31 ~121 ~92 dirt
setblock ~31 ~121 ~93 dirt
setblock ~31 ~121 ~94 dirt
setblock ~31 ~121 ~95 dirt
setblock ~31 ~121 ~96 dirt
setblock ~31 ~121 ~97 dirt
setblock ~31 ~121 ~98 dirt
setblock ~31 ~121 ~99 dirt
setblock ~31 ~121 ~100 dirt
setblock ~31 ~121 ~101 dirt
setblock ~31 ~121 ~102 dirt
setblock ~31 ~121 ~103 dirt
setblock ~31 ~121 ~104 dirt
setblock ~31 ~121 ~105 dirt
setblock ~31 ~121 ~106 dirt
setblock ~31 ~121 ~107 dirt
setblock ~31 ~121 ~108 dirt
setblock ~31 ~121 ~109 dirt
setblock ~31 ~121 ~110 dirt
setblock ~31 ~121 ~111 dirt
setblock ~31 ~121 ~112 dirt
setblock ~31 ~121 ~113 dirt
setblock ~31 ~122 ~64 dirt
setblock ~31 ~122 ~65 dirt
setblock ~31 ~122 ~66 dirt
setblock ~31 ~122 ~67 dirt
setblock ~31 ~122 ~68 dirt
setblock ~31 ~122 ~69 dirt
setblock ~31 ~122 ~70 dirt
setblock ~31 ~122 ~71 dirt
setblock ~31 ~122 ~72 dirt
setblock ~31 ~122 ~73 dirt
setblock ~31 ~122 ~74 dirt
setblock ~31 ~122 ~75 dirt
setblock ~31 ~122 ~76 dirt
setblock ~31 ~122 ~77 dirt
setblock ~31 ~122 ~78 dirt
setblock ~31 ~122 ~79 dirt
setblock ~31 ~122 ~80 dirt
setblock ~31 ~122 ~81 dirt
setblock ~31 ~122 ~82 dirt
setblock ~31 ~122 ~83 dirt
setblock ~31 ~122 ~84 dirt
setblock ~31 ~122 ~85 dirt
setblock ~31 ~122 ~86 dirt
setblock ~31 ~122 ~87 dirt
setblock ~31 ~122 ~88 dirt
setblock ~31 ~122 ~89 dirt
setblock ~31 ~122 ~90 dirt
setblock ~31 ~122 ~91 dirt
setblock ~31 ~122 ~92 dirt
setblock ~31 ~122 ~93 dirt
setblock ~31 ~122 ~94 dirt
setblock ~31 ~122 ~95 dirt
setblock ~31 ~122 ~96 dirt
setblock ~31 ~122 ~97 dirt
setblock ~31 ~122 ~98 dirt
setblock ~31 ~122 ~99 dirt
setblock ~31 ~122 ~100 dirt
setblock ~31 ~122 ~101 dirt
setblock ~31 ~122 ~102 dirt
setblock ~31 ~122 ~103 dirt
setblock ~31 ~122 ~104 dirt
setblock ~31 ~122 ~105 dirt
setblock ~31 ~122 ~106 dirt
setblock ~31 ~122 ~107 dirt
setblock ~31 ~122 ~108 dirt
setblock ~31 ~122 ~109 dirt
setblock ~31 ~122 ~110 dirt
setblock ~31 ~122 ~111 dirt
setblock ~31 ~122 ~112 dirt
setblock ~31 ~122 ~113 dirt
setblock ~31 ~123 ~64 dirt
setblock ~31 ~123 ~65 dirt
setblock ~31 ~123 ~66 dirt
setblock ~31 ~123 ~67 dirt
setblock ~31 ~123 ~68 dirt
setblock ~31 ~123 ~69 dirt
setblock ~31 ~123 ~70 grass_block
setblock ~31 ~123 ~71 dirt
setblock ~31 ~123 ~72 dirt
setblock ~31 ~123 ~73 dirt
setblock ~31 ~123 ~74 dirt
setblock ~31 ~123 ~75 dirt
setblock ~31 ~123 ~76 dirt
setblock ~31 ~123 ~77 dirt
setblock ~31 ~123 ~78 dirt
setblock ~31 ~123 ~79 dirt
setblock ~31 ~123 ~80 dirt
setblock ~31 ~123 ~81 dirt
setblock ~31 ~123 ~82 dirt
setblock ~31 ~123 ~83 dirt
setblock ~31 ~123 ~84 dirt
setblock ~31 ~123 ~85 dirt
setblock ~31 ~123 ~86 dirt
setblock ~31 ~123 ~87 dirt
setblock ~31 ~123 ~88 dirt
setblock ~31 ~123 ~89 dirt
setblock ~31 ~123 ~90 dirt
setblock ~31 ~123 ~91 dirt
setblock ~31 ~123 ~92 dirt
setblock ~31 ~123 ~93 dirt
setblock ~31 ~123 ~94 dirt
setblock ~31 ~123 ~95 dirt
setblock ~31 ~123 ~96 dirt
setblock ~31 ~123 ~97 dirt
setblock ~31 ~123 ~98 dirt
setblock ~31 ~123 ~99 dirt
setblock ~31 ~123 ~100 grass_block
setblock ~31 ~123 ~101 grass_block
setblock ~31 ~123 ~102 grass_block
setblock ~31 ~123 ~103 grass_block
setblock ~31 ~123 ~104 dirt
setblock ~31 ~123 ~105 dirt
setblock ~31 ~123 ~106 dirt
setblock ~31 ~123 ~107 dirt
setblock ~31 ~123 ~108 dirt
setblock ~31 ~123 ~109 dirt
setblock ~31 ~123 ~110 dirt
setblock ~31 ~123 ~111 dirt
setblock ~31 ~123 ~112 dirt
setblock ~31 ~123 ~113 dirt
setblock ~31 ~124 ~64 dirt
setblock ~31 ~124 ~65 grass_block
setblock ~31 ~124 ~66 grass_block
setblock ~31 ~124 ~67 grass_block
setblock ~31 ~124 ~68 grass_block
setblock ~31 ~124 ~69 grass_block
setblock ~31 ~124 ~70 short_grass
setblock ~31 ~124 ~71 grass_block
setblock ~31 ~124 ~72 grass_block
setblock ~31 ~124 ~73 grass_block
setblock ~31 ~124 ~74 grass_block
setblock ~31 ~124 ~75 grass_block
setblock ~31 ~124 ~76 grass_block
setblock ~31 ~124 ~77 dirt
setblock ~31 ~124 ~78 dirt
setblock ~31 ~124 ~79 dirt
setblock ~31 ~124 ~80 dirt
setblock ~31 ~124 ~81 dirt
setblock ~31 ~124 ~82 dirt
setblock ~31 ~124 ~83 dirt
setblock ~31 ~124 ~84 dirt
setblock ~31 ~124 ~85 dirt
setblock ~31 ~124 ~86 dirt
setblock ~31 ~124 ~87 dirt
setblock ~31 ~124 ~88 dirt
setblock ~31 ~124 ~89 dirt
setblock ~31 ~124 ~90 dirt
setblock ~31 ~124 ~91 dirt
setblock ~31 ~124 ~92 dirt
setblock ~31 ~124 ~93 dirt
setblock ~31 ~124 ~94 dirt
setblock ~31 ~124 ~95 dirt
setblock ~31 ~124 ~96 dirt
setblock ~31 ~124 ~97 grass_block
setblock ~31 ~124 ~98 grass_block
setblock ~31 ~124 ~99 grass_block
setblock ~31 ~124 ~104 grass_block
setblock ~31 ~124 ~105 grass_block
setblock ~31 ~124 ~106 grass_block
setblock ~31 ~124 ~107 grass_block
setblock ~31 ~124 ~108 grass_block
setblock ~31 ~124 ~109 grass_block
setblock ~31 ~124 ~110 grass_block
setblock ~31 ~124 ~111 grass_block
setblock ~31 ~124 ~112 grass_block
setblock ~31 ~124 ~113 grass_block
setblock ~31 ~125 ~64 grass_block
setblock ~31 ~125 ~67 short_grass
setblock ~31 ~125 ~68 short_grass
setblock ~31 ~125 ~73 poppy
setblock ~31 ~125 ~75 fern
setblock ~31 ~125 ~77 grass_block
setblock ~31 ~125 ~78 grass_block
setblock ~31 ~125 ~79 grass_block
setblock ~31 ~125 ~80 grass_block
setblock ~31 ~125 ~81 grass_block
setblock ~31 ~125 ~82 dirt
setblock ~31 ~125 ~83 dirt
setblock ~31 ~125 ~84 dirt
setblock ~31 ~125 ~85 dirt
setblock ~31 ~125 ~86 dirt
setblock ~31 ~125 ~87 dirt
setblock ~31 ~125 ~88 dirt
setblock ~31 ~125 ~89 dirt
setblock ~31 ~125 ~90 dirt
setblock ~31 ~125 ~91 dirt
setblock ~31 ~125 ~92 dirt
setblock ~31 ~125 ~93 dirt
setblock ~31 ~125 ~94 grass_block
setblock ~31 ~125 ~95 grass_block
setblock ~31 ~125 ~96 grass_block
setblock ~31 ~125 ~97 fern
setblock ~31 ~125 ~98 short_grass
setblock ~31 ~125 ~109 fern
setblock ~31 ~125 ~110 short_grass
setblock ~31 ~125 ~111 short_grass
setblock ~31 ~125 ~113 short_grass
setblock ~31 ~126 ~79 poppy
setblock ~31 ~126 ~81 short_grass
setblock ~31 ~126 ~82 grass_block
setblock ~31 ~126 ~83 grass_block
setblock ~31 ~126 ~84 grass_block
setblock ~31 ~126 ~85 grass_block
setblock ~31 ~126 ~86 grass_block
setblock ~31 ~126 ~87 dirt
setblock ~31 ~126 ~88 dirt
setblock ~31 ~126 ~89 dirt
setblock ~31 ~126 ~90 dirt
setblock ~31 ~126 ~91 dirt
setblock ~31 ~126 ~92 grass_block
setblock ~31 ~126 ~93 grass_block
setblock ~31 ~127 ~82 short_grass
setblock ~31 ~127 ~87 grass_block
setblock ~31 ~127 ~88 grass_block
setblock ~31 ~127 ~89 grass_block
setblock ~31 ~127 ~90 grass_block
setblock ~31 ~127 ~91 grass_block
setblock ~31 ~127 ~92 fern
setblock ~31 ~128 ~64 jungle_leaves[persistent=true]
setblock ~31 ~128 ~66 oak_leaves[persistent=true]
setblock ~31 ~128 ~67 oak_leaves[persistent=true]
setblock ~31 ~128 ~91 fern
setblock ~31 ~129 ~65 oak_leaves[persistent=true]
setblock ~31 ~129 ~66 oak_leaves[persistent=true]
setblock ~31 ~129 ~67 jungle_leaves[persistent=true]
setblock ~31 ~130 ~64 oak_leaves[persistent=true]
setblock ~31 ~130 ~65 oak_leaves[persistent=true]
setblock ~31 ~130 ~67 oak_leaves[persistent=true]
setblock ~31 ~130 ~74 oak_leaves[persistent=true]
setblock ~31 ~130 ~75 oak_leaves[persistent=true]
setblock ~31 ~130 ~76 oak_leaves[persistent=true]
setblock ~31 ~131 ~64 jungle_leaves[persistent=true]
setblock ~31 ~131 ~65 oak_leaves[persistent=true]
setblock ~31 ~131 ~66 jungle_leaves[persistent=true]
setblock ~31 ~131 ~67 oak_leaves[persistent=true]
setblock ~31 ~131 ~74 oak_leaves[persistent=true]
setblock ~31 ~131 ~75 oak_leaves[persistent=true]
setblock ~31 ~131 ~76 oak_leaves[persistent=true]
setblock ~31 ~132 ~74 oak_leaves[persistent=true]
setblock ~31 ~132 ~75 jungle_leaves[persistent=true]
setblock ~31 ~133 ~59 oak_leaves[persistent=true]
setblock ~31 ~133 ~60 oak_leaves[persistent=true]
setblock ~31 ~133 ~61 jungle_leaves[persistent=true]
setblock ~31 ~134 ~59 oak_leaves[persistent=true]
setblock ~31 ~134 ~60 oak_leaves[persistent=true]
setblock ~31 ~134 ~61 oak_leaves[persistent=true]
setblock ~31 ~134 ~62 jungle_leaves[persistent=true]
setblock ~31 ~134 ~63 jungle_leaves[persistent=true]
setblock ~31 ~135 ~59 jungle_leaves[persistent=true]
setblock ~31 ~135 ~60 oak_leaves[persistent=true]
setblock ~31 ~135 ~62 oak_leaves[persistent=true]
setblock ~31 ~135 ~63 jungle_leaves[persistent=true]
setblock ~31 ~136 ~60 oak_leaves[persistent=true]
setblock ~31 ~136 ~61 jungle_leaves[persistent=true]
setblock ~31 ~136 ~62 oak_leaves[persistent=true]
setblock ~31 ~137 ~60 oak_leaves[persistent=true]
setblock ~31 ~137 ~61 oak_leaves[persistent=true]
setblock ~31 ~137 ~62 jungle_leaves[persistent=true]
setblock ~31 ~137 ~63 oak_leaves[persistent=true]
setblock ~32 ~107 ~83 dirt
setblock ~32 ~107 ~84 dirt
setblock ~32 ~107 ~85 dirt
setblock ~32 ~108 ~82 dirt
setblock ~32 ~108 ~83 dirt
setblock ~32 ~108 ~84 dirt
setblock ~32 ~108 ~85 dirt
setblock ~32 ~108 ~86 dirt
setblock ~32 ~109 ~81 dirt
setblock ~32 ~109 ~82 dirt
setblock ~32 ~109 ~83 dirt
setblock ~32 ~109 ~84 dirt
setblock ~32 ~109 ~85 dirt
setblock ~32 ~109 ~86 dirt
setblock ~32 ~109 ~105 dirt
