setblock ~170 ~125 ~96 short_grass
setblock ~170 ~125 ~97 grass_block
setblock ~170 ~125 ~98 grass_block
setblock ~170 ~125 ~99 grass_block
setblock ~170 ~125 ~100 dirt
setblock ~170 ~125 ~101 dirt
setblock ~170 ~125 ~102 dirt
setblock ~170 ~125 ~103 dirt
setblock ~170 ~125 ~104 dirt
setblock ~170 ~125 ~105 dirt
setblock ~170 ~125 ~106 dirt
setblock ~170 ~125 ~107 dirt
setblock ~170 ~125 ~108 dirt
setblock ~170 ~125 ~109 dirt
setblock ~170 ~125 ~110 dirt
setblock ~170 ~125 ~111 dirt
setblock ~170 ~125 ~112 dirt
setblock ~170 ~126 ~74 short_grass
setblock ~170 ~126 ~76 poppy
setblock ~170 ~126 ~78 short_grass
setblock ~170 ~126 ~100 grass_block
setblock ~170 ~126 ~101 grass_block
setblock ~170 ~126 ~102 grass_block
setblock ~170 ~126 ~103 grass_block
setblock ~170 ~126 ~104 grass_block
setblock ~170 ~126 ~105 dirt
setblock ~170 ~126 ~106 dirt
setblock ~170 ~126 ~107 dirt
setblock ~170 ~126 ~108 dirt
setblock ~170 ~126 ~109 dirt
setblock ~170 ~126 ~110 dirt
setblock ~170 ~126 ~111 grass_block
setblock ~170 ~126 ~112 grass_block
setblock ~170 ~127 ~100 poppy
setblock ~170 ~127 ~104 short_grass
setblock ~170 ~127 ~105 grass_block
setblock ~170 ~127 ~106 grass_block
setblock ~170 ~127 ~107 grass_block
setblock ~170 ~127 ~108 grass_block
setblock ~170 ~127 ~109 grass_block
setblock ~170 ~127 ~110 grass_block
setblock ~170 ~128 ~106 short_grass
setblock ~170 ~128 ~109 fern
setblock ~171 ~107 ~96 dirt
setblock ~171 ~108 ~96 dirt
setblock ~171 ~108 ~97 dirt
setblock ~171 ~109 ~95 dirt
setblock ~171 ~109 ~96 dirt
setblock ~171 ~109 ~97 dirt
setblock ~171 ~109 ~98 dirt
setblock ~171 ~110 ~95 dirt
setblock ~171 ~110 ~96 dirt
setblock ~171 ~110 ~97 dirt
setblock ~171 ~110 ~98 dirt
setblock ~171 ~110 ~99 dirt
setblock ~171 ~111 ~94 dirt
setblock ~171 ~111 ~95 dirt
setblock ~171 ~111 ~96 dirt
setblock ~171 ~111 ~97 dirt
setblock ~171 ~111 ~98 dirt
setblock ~171 ~111 ~99 dirt
setblock ~171 ~111 ~100 dirt
setblock ~171 ~112 ~94 dirt
setblock ~171 ~112 ~95 dirt
setblock ~171 ~112 ~96 dirt
setblock ~171 ~112 ~97 dirt
setblock ~171 ~112 ~98 dirt
setblock ~171 ~112 ~99 dirt
setblock ~171 ~112 ~100 dirt
setblock ~171 ~112 ~102 dirt
setblock ~171 ~113 ~91 dirt
setblock ~171 ~113 ~93 dirt
setblock ~171 ~113 ~94 dirt
setblock ~171 ~113 ~95 dirt
setblock ~171 ~113 ~96 dirt
setblock ~171 ~113 ~97 dirt
setblock ~171 ~113 ~98 dirt
setblock ~171 ~113 ~99 dirt
setblock ~171 ~113 ~100 dirt
setblock ~171 ~113 ~101 dirt
setblock ~171 ~113 ~102 dirt
setblock ~171 ~113 ~103 dirt
setblock ~171 ~114 ~90 dirt
setblock ~171 ~114 ~91 dirt
setblock ~171 ~114 ~92 dirt
setblock ~171 ~114 ~93 dirt
setblock ~171 ~114 ~94 dirt
setblock ~171 ~114 ~95 dirt
setblock ~171 ~114 ~96 dirt
setblock ~171 ~114 ~97 dirt
setblock ~171 ~114 ~98 dirt
setblock ~171 ~114 ~99 dirt
setblock ~171 ~114 ~100 dirt
setblock ~171 ~114 ~101 dirt
setblock ~171 ~114 ~102 dirt
setblock ~171 ~114 ~103 dirt
setblock ~171 ~114 ~104 dirt
setblock ~171 ~115 ~90 dirt
setblock ~171 ~115 ~91 dirt
setblock ~171 ~115 ~92 dirt
setblock ~171 ~115 ~93 dirt
setblock ~171 ~115 ~94 dirt
setblock ~171 ~115 ~95 dirt
setblock ~171 ~115 ~96 dirt
setblock ~171 ~115 ~97 dirt
setblock ~171 ~115 ~98 dirt
setblock ~171 ~115 ~99 dirt
setblock ~171 ~115 ~100 dirt
setblock ~171 ~115 ~101 dirt
setblock ~171 ~115 ~102 dirt
setblock ~171 ~115 ~103 dirt
setblock ~171 ~115 ~104 dirt
setblock ~171 ~115 ~105 dirt
setblock ~171 ~116 ~89 dirt
setblock ~171 ~116 ~90 dirt
setblock ~171 ~116 ~91 dirt
setblock ~171 ~116 ~92 dirt
setblock ~171 ~116 ~93 dirt
setblock ~171 ~116 ~94 dirt
setblock ~171 ~116 ~95 dirt
setblock ~171 ~116 ~96 dirt
setblock ~171 ~116 ~97 dirt
setblock ~171 ~116 ~98 dirt
setblock ~171 ~116 ~99 dirt
setblock ~171 ~116 ~100 dirt
setblock ~171 ~116 ~101 dirt
setblock ~171 ~116 ~102 dirt
setblock ~171 ~116 ~103 dirt
setblock ~171 ~116 ~104 dirt
setblock ~171 ~116 ~105 dirt
setblock ~171 ~116 ~106 dirt
setblock ~171 ~117 ~89 dirt
setblock ~171 ~117 ~90 dirt
setblock ~171 ~117 ~91 dirt
setblock ~171 ~117 ~92 dirt
setblock ~171 ~117 ~93 dirt
setblock ~171 ~117 ~94 dirt
setblock ~171 ~117 ~95 dirt
setblock ~171 ~117 ~96 dirt
setblock ~171 ~117 ~97 dirt
setblock ~171 ~117 ~98 dirt
setblock ~171 ~117 ~99 dirt
setblock ~171 ~117 ~100 dirt
setblock ~171 ~117 ~101 dirt
setblock ~171 ~117 ~102 dirt
setblock ~171 ~117 ~103 dirt
setblock ~171 ~117 ~104 dirt
setblock ~171 ~117 ~105 dirt
setblock ~171 ~117 ~106 dirt
setblock ~171 ~118 ~88 dirt
setblock ~171 ~118 ~89 dirt
setblock ~171 ~118 ~90 dirt
setblock ~171 ~118 ~91 dirt
setblock ~171 ~118 ~92 dirt
setblock ~171 ~118 ~93 dirt
setblock ~171 ~118 ~94 dirt
setblock ~171 ~118 ~95 dirt
setblock ~171 ~118 ~96 dirt
setblock ~171 ~118 ~97 dirt
setblock ~171 ~118 ~98 dirt
setblock ~171 ~118 ~99 dirt
setblock ~171 ~118 ~100 dirt
setblock ~171 ~118 ~101 dirt
setblock ~171 ~118 ~102 dirt
setblock ~171 ~118 ~103 dirt
setblock ~171 ~118 ~104 dirt
setblock ~171 ~118 ~105 dirt
setblock ~171 ~118 ~106 dirt
setblock ~171 ~118 ~107 dirt
setblock ~171 ~119 ~88 dirt
setblock ~171 ~119 ~89 dirt
setblock ~171 ~119 ~90 dirt
setblock ~171 ~119 ~91 dirt
setblock ~171 ~119 ~92 dirt
setblock ~171 ~119 ~93 dirt
setblock ~171 ~119 ~94 dirt
setblock ~171 ~119 ~95 dirt
setblock ~171 ~119 ~96 dirt
setblock ~171 ~119 ~97 dirt
setblock ~171 ~119 ~98 dirt
setblock ~171 ~119 ~99 dirt
setblock ~171 ~119 ~100 dirt
setblock ~171 ~119 ~101 dirt
setblock ~171 ~119 ~102 dirt
setblock ~171 ~119 ~103 dirt
setblock ~171 ~119 ~104 dirt
setblock ~171 ~119 ~105 dirt
setblock ~171 ~119 ~106 dirt
setblock ~171 ~119 ~107 dirt
setblock ~171 ~120 ~82 dirt
setblock ~171 ~120 ~83 dirt
setblock ~171 ~120 ~84 dirt
setblock ~171 ~120 ~86 dirt
setblock ~171 ~120 ~87 dirt
setblock ~171 ~120 ~88 dirt
setblock ~171 ~120 ~89 dirt
setblock ~171 ~120 ~90 dirt
setblock ~171 ~120 ~91 dirt
setblock ~171 ~120 ~92 dirt
setblock ~171 ~120 ~93 dirt
setblock ~171 ~120 ~94 dirt
setblock ~171 ~120 ~95 dirt
setblock ~171 ~120 ~96 dirt
setblock ~171 ~120 ~97 dirt
setblock ~171 ~120 ~98 dirt
setblock ~171 ~120 ~99 dirt
setblock ~171 ~120 ~100 dirt
setblock ~171 ~120 ~101 dirt
setblock ~171 ~120 ~102 dirt
setblock ~171 ~120 ~103 dirt
setblock ~171 ~120 ~104 dirt
setblock ~171 ~120 ~105 dirt
setblock ~171 ~120 ~106 dirt
setblock ~171 ~120 ~107 dirt
setblock ~171 ~120 ~109 dirt
setblock ~171 ~120 ~110 dirt
setblock ~171 ~121 ~80 dirt
setblock ~171 ~121 ~81 dirt
setblock ~171 ~121 ~82 dirt
setblock ~171 ~121 ~83 dirt
setblock ~171 ~121 ~84 dirt
setblock ~171 ~121 ~86 dirt
setblock ~171 ~121 ~87 dirt
setblock ~171 ~121 ~88 dirt
setblock ~171 ~121 ~89 dirt
setblock ~171 ~121 ~90 dirt
setblock ~171 ~121 ~91 dirt
setblock ~171 ~121 ~92 dirt
setblock ~171 ~121 ~93 dirt
setblock ~171 ~121 ~94 dirt
setblock ~171 ~121 ~95 dirt
setblock ~171 ~121 ~96 dirt
setblock ~171 ~121 ~97 dirt
setblock ~171 ~121 ~98 dirt
setblock ~171 ~121 ~99 dirt
setblock ~171 ~121 ~100 dirt
setblock ~171 ~121 ~101 dirt
setblock ~171 ~121 ~102 dirt
setblock ~171 ~121 ~103 dirt
setblock ~171 ~121 ~104 dirt
setblock ~171 ~121 ~105 dirt
setblock ~171 ~121 ~106 dirt
setblock ~171 ~121 ~107 dirt
setblock ~171 ~121 ~108 dirt
setblock ~171 ~121 ~109 dirt
setblock ~171 ~121 ~110 dirt
setblock ~171 ~121 ~111 dirt
setblock ~171 ~122 ~80 dirt
setblock ~171 ~122 ~81 dirt
setblock ~171 ~122 ~82 dirt
setblock ~171 ~122 ~83 dirt
setblock ~171 ~122 ~84 dirt
setblock ~171 ~122 ~86 dirt
setblock ~171 ~122 ~87 dirt
setblock ~171 ~122 ~88 dirt
setblock ~171 ~122 ~89 grass_block
setblock ~171 ~122 ~90 grass_block
setblock ~171 ~122 ~91 grass_block
setblock ~171 ~122 ~92 dirt
setblock ~171 ~122 ~93 dirt
setblock ~171 ~122 ~94 dirt
setblock ~171 ~122 ~95 dirt
setblock ~171 ~122 ~96 dirt
setblock ~171 ~122 ~97 dirt
setblock ~171 ~122 ~98 dirt
setblock ~171 ~122 ~99 dirt
setblock ~171 ~122 ~100 dirt
setblock ~171 ~122 ~101 dirt
setblock ~171 ~122 ~102 dirt
setblock ~171 ~122 ~103 dirt
setblock ~171 ~122 ~104 dirt
setblock ~171 ~122 ~105 dirt
setblock ~171 ~122 ~106 dirt
setblock ~171 ~122 ~107 dirt
setblock ~171 ~122 ~108 dirt
setblock ~171 ~122 ~109 dirt
setblock ~171 ~122 ~110 dirt
setblock ~171 ~122 ~111 dirt
setblock ~171 ~123 ~80 dirt
setblock ~171 ~123 ~81 dirt
setblock ~171 ~123 ~82 dirt
setblock ~171 ~123 ~83 dirt
setblock ~171 ~123 ~84 dirt
setblock ~171 ~123 ~86 grass_block
setblock ~171 ~123 ~87 grass_block
setblock ~171 ~123 ~88 grass_block
setblock ~171 ~123 ~89 fern
setblock ~171 ~123 ~92 grass_block
setblock ~171 ~123 ~93 grass_block
setblock ~171 ~123 ~94 grass_block
setblock ~171 ~123 ~95 dirt
setblock ~171 ~123 ~96 dirt
setblock ~171 ~123 ~97 dirt
setblock ~171 ~123 ~98 dirt
setblock ~171 ~123 ~99 dirt
setblock ~171 ~123 ~100 dirt
setblock ~171 ~123 ~101 dirt
setblock ~171 ~123 ~102 dirt
setblock ~171 ~123 ~103 dirt
setblock ~171 ~123 ~104 dirt
setblock ~171 ~123 ~105 dirt
setblock ~171 ~123 ~106 dirt
setblock ~171 ~123 ~107 dirt
setblock ~171 ~123 ~108 dirt
setblock ~171 ~123 ~109 dirt
setblock ~171 ~123 ~110 dirt
setblock ~171 ~123 ~111 dirt
setblock ~171 ~124 ~80 dirt
setblock ~171 ~124 ~81 dirt
setblock ~171 ~124 ~82 grass_block
setblock ~171 ~124 ~83 grass_block
setblock ~171 ~124 ~84 grass_block
setblock ~171 ~124 ~92 short_grass
setblock ~171 ~124 ~93 short_grass
setblock ~171 ~124 ~95 grass_block
setblock ~171 ~124 ~96 grass_block
setblock ~171 ~124 ~97 dirt
setblock ~171 ~124 ~98 dirt
setblock ~171 ~124 ~99 dirt
setblock ~171 ~124 ~100 dirt
setblock ~171 ~124 ~101 dirt
setblock ~171 ~124 ~102 dirt
setblock ~171 ~124 ~103 dirt
setblock ~171 ~124 ~104 dirt
setblock ~171 ~124 ~105 dirt
setblock ~171 ~124 ~106 dirt
setblock ~171 ~124 ~107 dirt
setblock ~171 ~124 ~108 dirt
setblock ~171 ~124 ~109 dirt
setblock ~171 ~124 ~110 dirt
setblock ~171 ~124 ~111 dirt
setblock ~171 ~125 ~80 grass_block
setblock ~171 ~125 ~81 grass_block
setblock ~171 ~125 ~82 short_grass
setblock ~171 ~125 ~84 poppy
setblock ~171 ~125 ~96 short_grass
setblock ~171 ~125 ~97 grass_block
setblock ~171 ~125 ~98 grass_block
setblock ~171 ~125 ~99 grass_block
setblock ~171 ~125 ~100 dirt
setblock ~171 ~125 ~101 dirt
setblock ~171 ~125 ~102 dirt
setblock ~171 ~125 ~103 dirt
setblock ~171 ~125 ~104 dirt
setblock ~171 ~125 ~105 dirt
setblock ~171 ~125 ~106 dirt
setblock ~171 ~125 ~107 dirt
setblock ~171 ~125 ~108 dirt
setblock ~171 ~125 ~109 dirt
setblock ~171 ~125 ~110 dirt
setblock ~171 ~125 ~111 dirt
setblock ~171 ~126 ~80 short_grass
setblock ~171 ~126 ~97 fern
setblock ~171 ~126 ~99 short_grass
setblock ~171 ~126 ~100 grass_block
setblock ~171 ~126 ~101 grass_block
setblock ~171 ~126 ~102 grass_block
setblock ~171 ~126 ~103 grass_block
setblock ~171 ~126 ~104 grass_block
setblock ~171 ~126 ~105 dirt
setblock ~171 ~126 ~106 dirt
setblock ~171 ~126 ~107 dirt
setblock ~171 ~126 ~108 dirt
setblock ~171 ~126 ~109 dirt
setblock ~171 ~126 ~110 dirt
setblock ~171 ~126 ~111 grass_block
setblock ~171 ~127 ~100 short_grass
setblock ~171 ~127 ~101 short_grass
setblock ~171 ~127 ~105 grass_block
setblock ~171 ~127 ~106 grass_block
setblock ~171 ~127 ~107 grass_block
setblock ~171 ~127 ~108 grass_block
setblock ~171 ~127 ~109 grass_block
setblock ~171 ~127 ~110 grass_block
setblock ~171 ~127 ~111 poppy
setblock ~171 ~128 ~108 short_grass
setblock ~171 ~128 ~110 fern
setblock ~172 ~109 ~97 dirt
setblock ~172 ~110 ~97 dirt
setblock ~172 ~110 ~98 dirt
setblock ~172 ~111 ~95 dirt
setblock ~172 ~111 ~96 dirt
setblock ~172 ~111 ~97 dirt
setblock ~172 ~111 ~98 dirt
setblock ~172 ~111 ~99 dirt
setblock ~172 ~112 ~95 dirt
setblock ~172 ~112 ~96 dirt
setblock ~172 ~112 ~97 dirt
setblock ~172 ~112 ~98 dirt
setblock ~172 ~112 ~99 dirt
setblock ~172 ~112 ~100 dirt
setblock ~172 ~113 ~94 dirt
setblock ~172 ~113 ~95 dirt
setblock ~172 ~113 ~96 dirt
setblock ~172 ~113 ~97 dirt
setblock ~172 ~113 ~98 dirt
setblock ~172 ~113 ~99 dirt
setblock ~172 ~113 ~100 dirt
setblock ~172 ~114 ~91 dirt
setblock ~172 ~114 ~94 dirt
setblock ~172 ~114 ~95 dirt
setblock ~172 ~114 ~96 dirt
setblock ~172 ~114 ~97 dirt
setblock ~172 ~114 ~98 dirt
setblock ~172 ~114 ~99 dirt
setblock ~172 ~114 ~100 dirt
setblock ~172 ~114 ~103 dirt
setblock ~172 ~115 ~91 dirt
setblock ~172 ~115 ~93 dirt
setblock ~172 ~115 ~94 dirt
setblock ~172 ~115 ~95 dirt
setblock ~172 ~115 ~96 dirt
setblock ~172 ~115 ~97 dirt
setblock ~172 ~115 ~98 dirt
setblock ~172 ~115 ~99 dirt
setblock ~172 ~115 ~100 dirt
setblock ~172 ~115 ~101 dirt
setblock ~172 ~115 ~103 dirt
setblock ~172 ~115 ~104 dirt
setblock ~172 ~116 ~90 dirt
setblock ~172 ~116 ~91 dirt
setblock ~172 ~116 ~93 dirt
setblock ~172 ~116 ~94 dirt
setblock ~172 ~116 ~95 dirt
setblock ~172 ~116 ~96 dirt
setblock ~172 ~116 ~97 dirt
setblock ~172 ~116 ~98 dirt
setblock ~172 ~116 ~99 dirt
setblock ~172 ~116 ~100 dirt
setblock ~172 ~116 ~101 dirt
setblock ~172 ~116 ~102 dirt
setblock ~172 ~116 ~103 dirt
setblock ~172 ~116 ~104 dirt
setblock ~172 ~116 ~105 dirt
setblock ~172 ~117 ~90 dirt
setblock ~172 ~117 ~91 dirt
setblock ~172 ~117 ~93 dirt
setblock ~172 ~117 ~94 dirt
setblock ~172 ~117 ~95 dirt
setblock ~172 ~117 ~96 dirt
setblock ~172 ~117 ~97 dirt
setblock ~172 ~117 ~98 dirt
setblock ~172 ~117 ~99 dirt
setblock ~172 ~117 ~100 dirt
setblock ~172 ~117 ~101 dirt
setblock ~172 ~117 ~102 dirt
setblock ~172 ~117 ~103 dirt
setblock ~172 ~117 ~104 dirt
setblock ~172 ~117 ~105 dirt
setblock ~172 ~118 ~89 dirt
setblock ~172 ~118 ~90 dirt
setblock ~172 ~118 ~91 dirt
setblock ~172 ~118 ~92 dirt
setblock ~172 ~118 ~93 dirt
setblock ~172 ~118 ~94 dirt
setblock ~172 ~118 ~95 dirt
setblock ~172 ~118 ~96 dirt
setblock ~172 ~118 ~97 dirt
setblock ~172 ~118 ~98 dirt
setblock ~172 ~118 ~99 dirt
setblock ~172 ~118 ~100 dirt
setblock ~172 ~118 ~101 dirt
setblock ~172 ~118 ~102 dirt
setblock ~172 ~118 ~103 dirt
setblock ~172 ~118 ~104 dirt
setblock ~172 ~118 ~105 dirt
setblock ~172 ~118 ~106 dirt
setblock ~172 ~119 ~89 dirt
setblock ~172 ~119 ~90 dirt
setblock ~172 ~119 ~91 dirt
setblock ~172 ~119 ~92 dirt
setblock ~172 ~119 ~93 dirt
setblock ~172 ~119 ~94 dirt
setblock ~172 ~119 ~95 dirt
setblock ~172 ~119 ~96 dirt
setblock ~172 ~119 ~97 dirt
setblock ~172 ~119 ~98 dirt
setblock ~172 ~119 ~99 dirt
setblock ~172 ~119 ~100 dirt
setblock ~172 ~119 ~101 dirt
setblock ~172 ~119 ~102 dirt
setblock ~172 ~119 ~103 dirt
setblock ~172 ~119 ~104 dirt
setblock ~172 ~119 ~105 dirt
setblock ~172 ~119 ~106 dirt
setblock ~172 ~119 ~107 dirt
setblock ~172 ~120 ~88 dirt
setblock ~172 ~120 ~89 dirt
setblock ~172 ~120 ~90 dirt
setblock ~172 ~120 ~91 dirt
setblock ~172 ~120 ~92 dirt
setblock ~172 ~120 ~93 dirt
setblock ~172 ~120 ~94 dirt
setblock ~172 ~120 ~95 dirt
setblock ~172 ~120 ~96 dirt
setblock ~172 ~120 ~97 dirt
setblock ~172 ~120 ~98 dirt
setblock ~172 ~120 ~99 dirt
setblock ~172 ~120 ~100 dirt
setblock ~172 ~120 ~101 dirt
setblock ~172 ~120 ~102 dirt
setblock ~172 ~120 ~103 dirt
setblock ~172 ~120 ~104 dirt
setblock ~172 ~120 ~105 dirt
setblock ~172 ~120 ~106 dirt
setblock ~172 ~120 ~107 dirt
setblock ~172 ~121 ~82 dirt
setblock ~172 ~121 ~83 dirt
setblock ~172 ~121 ~87 dirt
setblock ~172 ~121 ~88 dirt
setblock ~172 ~121 ~89 dirt
setblock ~172 ~121 ~90 dirt
setblock ~172 ~121 ~91 dirt
setblock ~172 ~121 ~92 dirt
setblock ~172 ~121 ~93 dirt
setblock ~172 ~121 ~94 dirt
setblock ~172 ~121 ~95 dirt
setblock ~172 ~121 ~96 dirt
setblock ~172 ~121 ~97 dirt
setblock ~172 ~121 ~98 dirt
setblock ~172 ~121 ~99 dirt
setblock ~172 ~121 ~100 dirt
setblock ~172 ~121 ~101 dirt
setblock ~172 ~121 ~102 dirt
setblock ~172 ~121 ~103 dirt
setblock ~172 ~121 ~104 dirt
setblock ~172 ~121 ~105 dirt
setblock ~172 ~121 ~106 dirt
setblock ~172 ~121 ~107 dirt
setblock ~172 ~121 ~108 dirt
setblock ~172 ~122 ~82 dirt
setblock ~172 ~122 ~83 dirt
setblock ~172 ~122 ~87 dirt
setblock ~172 ~122 ~88 dirt
setblock ~172 ~122 ~89 grass_block
setblock ~172 ~122 ~90 grass_block
setblock ~172 ~122 ~91 grass_block
setblock ~172 ~122 ~92 dirt
setblock ~172 ~122 ~93 dirt
setblock ~172 ~122 ~94 dirt
setblock ~172 ~122 ~95 dirt
setblock ~172 ~122 ~96 dirt
setblock ~172 ~122 ~97 dirt
setblock ~172 ~122 ~98 dirt
setblock ~172 ~122 ~99 dirt
setblock ~172 ~122 ~100 dirt
setblock ~172 ~122 ~101 dirt
setblock ~172 ~122 ~102 dirt
setblock ~172 ~122 ~103 dirt
setblock ~172 ~122 ~104 dirt
setblock ~172 ~122 ~105 dirt
setblock ~172 ~122 ~106 dirt
setblock ~172 ~122 ~107 dirt
setblock ~172 ~122 ~108 dirt
setblock ~172 ~123 ~82 dirt
setblock ~172 ~123 ~83 dirt
setblock ~172 ~123 ~87 grass_block
setblock ~172 ~123 ~88 grass_block
setblock ~172 ~123 ~89 short_grass
setblock ~172 ~123 ~91 poppy
setblock ~172 ~123 ~92 grass_block
setblock ~172 ~123 ~93 grass_block
setblock ~172 ~123 ~94 dirt
setblock ~172 ~123 ~95 dirt
setblock ~172 ~123 ~96 dirt
setblock ~172 ~123 ~97 dirt
setblock ~172 ~123 ~98 dirt
setblock ~172 ~123 ~99 dirt
setblock ~172 ~123 ~100 dirt
setblock ~172 ~123 ~101 dirt
setblock ~172 ~123 ~102 dirt
setblock ~172 ~123 ~103 dirt
setblock ~172 ~123 ~104 dirt
setblock ~172 ~123 ~105 dirt
setblock ~172 ~123 ~106 dirt
setblock ~172 ~123 ~107 dirt
setblock ~172 ~123 ~108 dirt
setblock ~172 ~124 ~82 grass_block
setblock ~172 ~124 ~83 grass_block
setblock ~172 ~124 ~87 short_grass
setblock ~172 ~124 ~94 grass_block
setblock ~172 ~124 ~95 grass_block
setblock ~172 ~124 ~96 grass_block
setblock ~172 ~124 ~97 dirt
setblock ~172 ~124 ~98 dirt
setblock ~172 ~124 ~99 dirt
setblock ~172 ~124 ~100 dirt
setblock ~172 ~124 ~101 dirt
setblock ~172 ~124 ~102 dirt
setblock ~172 ~124 ~103 dirt
setblock ~172 ~124 ~104 dirt
setblock ~172 ~124 ~105 dirt
setblock ~172 ~124 ~106 dirt
setblock ~172 ~124 ~107 dirt
setblock ~172 ~124 ~108 dirt
setblock ~172 ~125 ~82 short_grass
setblock ~172 ~125 ~83 short_grass
setblock ~172 ~125 ~95 short_grass
setblock ~172 ~125 ~96 short_grass
setblock ~172 ~125 ~97 grass_block
setblock ~172 ~125 ~98 grass_block
setblock ~172 ~125 ~99 grass_block
setblock ~172 ~125 ~100 dirt
setblock ~172 ~125 ~101 dirt
setblock ~172 ~125 ~102 dirt
setblock ~172 ~125 ~103 dirt
setblock ~172 ~125 ~104 dirt
setblock ~172 ~125 ~105 dirt
setblock ~172 ~125 ~106 dirt
setblock ~172 ~125 ~107 dirt
setblock ~172 ~125 ~108 dirt
setblock ~172 ~126 ~100 grass_block
setblock ~172 ~126 ~101 grass_block
setblock ~172 ~126 ~102 grass_block
setblock ~172 ~126 ~103 grass_block
setblock ~172 ~126 ~104 grass_block
setblock ~172 ~126 ~105 grass_block
setblock ~172 ~126 ~106 dirt
setblock ~172 ~126 ~107 dirt
setblock ~172 ~126 ~108 dirt
setblock ~172 ~127 ~106 grass_block
setblock ~172 ~127 ~107 grass_block
setblock ~172 ~127 ~108 grass_block
setblock ~172 ~128 ~107 short_grass
setblock ~173 ~112 ~97 dirt
setblock ~173 ~112 ~99 dirt
setblock ~173 ~113 ~95 dirt
setblock ~173 ~113 ~96 dirt
setblock ~173 ~113 ~97 dirt
setblock ~173 ~113 ~98 dirt
setblock ~173 ~113 ~99 dirt
setblock ~173 ~114 ~94 dirt
setblock ~173 ~114 ~95 dirt
setblock ~173 ~114 ~96 dirt
setblock ~173 ~114 ~97 dirt
setblock ~173 ~114 ~98 dirt
setblock ~173 ~114 ~99 dirt
setblock ~173 ~115 ~94 dirt
setblock ~173 ~115 ~95 dirt
setblock ~173 ~115 ~96 dirt
setblock ~173 ~115 ~97 dirt
setblock ~173 ~115 ~98 dirt
setblock ~173 ~115 ~99 dirt
setblock ~173 ~116 ~93 dirt
setblock ~173 ~116 ~94 dirt
setblock ~173 ~116 ~95 dirt
setblock ~173 ~116 ~96 dirt
setblock ~173 ~116 ~97 dirt
setblock ~173 ~116 ~98 dirt
setblock ~173 ~116 ~99 dirt
setblock ~173 ~116 ~100 dirt
setblock ~173 ~116 ~101 dirt
setblock ~173 ~116 ~104 dirt
setblock ~173 ~117 ~93 dirt
setblock ~173 ~117 ~94 dirt
setblock ~173 ~117 ~95 dirt
setblock ~173 ~117 ~96 dirt
setblock ~173 ~117 ~97 dirt
setblock ~173 ~117 ~98 dirt
setblock ~173 ~117 ~99 dirt
setblock ~173 ~117 ~100 dirt
setblock ~173 ~117 ~101 dirt
setblock ~173 ~117 ~102 dirt
setblock ~173 ~117 ~104 dirt
setblock ~173 ~118 ~91 dirt
setblock ~173 ~118 ~92 dirt
setblock ~173 ~118 ~93 dirt
setblock ~173 ~118 ~94 dirt
setblock ~173 ~118 ~95 dirt
setblock ~173 ~118 ~96 dirt
setblock ~173 ~118 ~97 dirt
setblock ~173 ~118 ~98 dirt
setblock ~173 ~118 ~99 dirt
setblock ~173 ~118 ~100 dirt
setblock ~173 ~118 ~101 dirt
setblock ~173 ~118 ~102 dirt
setblock ~173 ~118 ~103 dirt
setblock ~173 ~118 ~104 dirt
setblock ~173 ~118 ~105 dirt
setblock ~173 ~119 ~90 dirt
setblock ~173 ~119 ~91 dirt
setblock ~173 ~119 ~92 dirt
setblock ~173 ~119 ~93 dirt
setblock ~173 ~119 ~94 dirt
setblock ~173 ~119 ~95 dirt
setblock ~173 ~119 ~96 dirt
setblock ~173 ~119 ~97 dirt
setblock ~173 ~119 ~98 dirt
setblock ~173 ~119 ~99 dirt
setblock ~173 ~119 ~100 dirt
setblock ~173 ~119 ~101 dirt
setblock ~173 ~119 ~102 dirt
setblock ~173 ~119 ~103 dirt
setblock ~173 ~119 ~104 dirt
setblock ~173 ~119 ~105 dirt
setblock ~173 ~119 ~106 dirt
setblock ~173 ~120 ~89 dirt
setblock ~173 ~120 ~90 dirt
setblock ~173 ~120 ~91 dirt
setblock ~173 ~120 ~92 dirt
setblock ~173 ~120 ~93 dirt
setblock ~173 ~120 ~94 dirt
setblock ~173 ~120 ~95 dirt
setblock ~173 ~120 ~96 dirt
setblock ~173 ~120 ~97 dirt
setblock ~173 ~120 ~98 dirt
setblock ~173 ~120 ~99 dirt
setblock ~173 ~120 ~100 dirt
setblock ~173 ~120 ~101 dirt
setblock ~173 ~120 ~102 dirt
setblock ~173 ~120 ~103 dirt
setblock ~173 ~120 ~104 dirt
setblock ~173 ~120 ~105 dirt
setblock ~173 ~120 ~106 dirt
setblock ~173 ~120 ~107 dirt
setblock ~173 ~121 ~88 dirt
setblock ~173 ~121 ~89 dirt
setblock ~173 ~121 ~90 dirt
setblock ~173 ~121 ~91 dirt
setblock ~173 ~121 ~92 dirt
setblock ~173 ~121 ~93 dirt
setblock ~173 ~121 ~94 dirt
setblock ~173 ~121 ~95 dirt
setblock ~173 ~121 ~96 dirt
setblock ~173 ~121 ~97 dirt
setblock ~173 ~121 ~98 dirt
setblock ~173 ~121 ~99 dirt
setblock ~173 ~121 ~100 dirt
setblock ~173 ~121 ~101 dirt
setblock ~173 ~121 ~102 dirt
setblock ~173 ~121 ~103 dirt
setblock ~173 ~121 ~104 dirt
setblock ~173 ~121 ~105 dirt
setblock ~173 ~121 ~106 dirt
setblock ~173 ~121 ~107 dirt
setblock ~173 ~122 ~88 dirt
setblock ~173 ~122 ~89 grass_block
setblock ~173 ~122 ~90 grass_block
setblock ~173 ~122 ~91 dirt
setblock ~173 ~122 ~92 dirt
setblock ~173 ~122 ~93 dirt
setblock ~173 ~122 ~94 dirt
setblock ~173 ~122 ~95 dirt
setblock ~173 ~122 ~96 dirt
setblock ~173 ~122 ~97 dirt
setblock ~173 ~122 ~98 dirt
setblock ~173 ~122 ~99 dirt
setblock ~173 ~122 ~100 dirt
setblock ~173 ~122 ~101 dirt
setblock ~173 ~122 ~102 dirt
setblock ~173 ~122 ~103 dirt
setblock ~173 ~122 ~104 dirt
setblock ~173 ~122 ~105 dirt
setblock ~173 ~122 ~106 dirt
setblock ~173 ~122 ~107 dirt
setblock ~173 ~123 ~88 grass_block
setblock ~173 ~123 ~90 poppy
setblock ~173 ~123 ~91 grass_block
setblock ~173 ~123 ~92 grass_block
setblock ~173 ~123 ~93 grass_block
setblock ~173 ~123 ~94 dirt
setblock ~173 ~123 ~95 dirt
setblock ~173 ~123 ~96 dirt
setblock ~173 ~123 ~97 dirt
setblock ~173 ~123 ~98 dirt
setblock ~173 ~123 ~99 dirt
setblock ~173 ~123 ~100 dirt
setblock ~173 ~123 ~101 dirt
setblock ~173 ~123 ~102 dirt
setblock ~173 ~123 ~103 dirt
setblock ~173 ~123 ~104 dirt
setblock ~173 ~123 ~105 dirt
setblock ~173 ~123 ~106 dirt
setblock ~173 ~123 ~107 dirt
setblock ~173 ~124 ~88 short_grass
setblock ~173 ~124 ~91 poppy
setblock ~173 ~124 ~94 grass_block
setblock ~173 ~124 ~95 grass_block
setblock ~173 ~124 ~96 grass_block
setblock ~173 ~124 ~97 dirt
setblock ~173 ~124 ~98 dirt
setblock ~173 ~124 ~99 dirt
setblock ~173 ~124 ~100 dirt
setblock ~173 ~124 ~101 dirt
setblock ~173 ~124 ~102 dirt
setblock ~173 ~124 ~103 dirt
setblock ~173 ~124 ~104 dirt
setblock ~173 ~124 ~105 dirt
setblock ~173 ~124 ~106 dirt
setblock ~173 ~124 ~107 dirt
setblock ~173 ~125 ~94 fern
setblock ~173 ~125 ~95 fern
setblock ~173 ~125 ~97 grass_block
setblock ~173 ~125 ~98 grass_block
setblock ~173 ~125 ~99 grass_block
setblock ~173 ~125 ~100 dirt
setblock ~173 ~125 ~101 dirt
setblock ~173 ~125 ~102 dirt
setblock ~173 ~125 ~103 dirt
setblock ~173 ~125 ~104 dirt
setblock ~173 ~125 ~105 dirt
setblock ~173 ~125 ~106 dirt
setblock ~173 ~125 ~107 dirt
setblock ~173 ~126 ~100 grass_block
setblock ~173 ~126 ~101 grass_block
setblock ~173 ~126 ~102 grass_block
setblock ~173 ~126 ~103 grass_block
setblock ~173 ~126 ~104 grass_block
setblock ~173 ~126 ~105 grass_block
setblock ~173 ~126 ~106 dirt
setblock ~173 ~126 ~107 dirt
setblock ~173 ~127 ~100 fern
setblock ~173 ~127 ~102 fern
setblock ~173 ~127 ~103 short_grass
setblock ~173 ~127 ~105 short_grass
setblock ~173 ~127 ~106 grass_block
setblock ~173 ~127 ~107 grass_block
setblock ~174 ~113 ~97 dirt
setblock ~174 ~114 ~95 dirt
setblock ~174 ~114 ~96 dirt
setblock ~174 ~114 ~97 dirt
setblock ~174 ~115 ~95 dirt
setblock ~174 ~115 ~96 dirt
setblock ~174 ~115 ~97 dirt
setblock ~174 ~115 ~98 dirt
setblock ~174 ~116 ~94 dirt
setblock ~174 ~116 ~95 dirt
setblock ~174 ~116 ~96 dirt
setblock ~174 ~116 ~97 dirt
setblock ~174 ~116 ~98 dirt
setblock ~174 ~116 ~99 dirt
setblock ~174 ~117 ~94 dirt
setblock ~174 ~117 ~95 dirt
setblock ~174 ~117 ~96 dirt
setblock ~174 ~117 ~97 dirt
setblock ~174 ~117 ~98 dirt
setblock ~174 ~117 ~99 dirt
setblock ~174 ~117 ~100 dirt
setblock ~174 ~118 ~93 dirt
setblock ~174 ~118 ~94 dirt
setblock ~174 ~118 ~95 dirt
setblock ~174 ~118 ~96 dirt
setblock ~174 ~118 ~97 dirt
setblock ~174 ~118 ~98 dirt
setblock ~174 ~118 ~99 dirt
setblock ~174 ~118 ~100 dirt
setblock ~174 ~119 ~93 dirt
setblock ~174 ~119 ~94 dirt
setblock ~174 ~119 ~95 dirt
setblock ~174 ~119 ~96 dirt
setblock ~174 ~119 ~97 dirt
setblock ~174 ~119 ~98 dirt
setblock ~174 ~119 ~99 dirt
setblock ~174 ~119 ~100 dirt
setblock ~174 ~119 ~101 dirt
setblock ~174 ~119 ~103 dirt
setblock ~174 ~120 ~92 dirt
setblock ~174 ~120 ~93 dirt
setblock ~174 ~120 ~94 dirt
setblock ~174 ~120 ~95 dirt
setblock ~174 ~120 ~96 dirt
setblock ~174 ~120 ~97 dirt
setblock ~174 ~120 ~98 dirt
setblock ~174 ~120 ~99 dirt
setblock ~174 ~120 ~100 dirt
setblock ~174 ~120 ~101 dirt
setblock ~174 ~120 ~102 dirt
setblock ~174 ~120 ~103 dirt
setblock ~174 ~120 ~104 dirt
setblock ~174 ~120 ~106 dirt
setblock ~174 ~121 ~89 dirt
setblock ~174 ~121 ~91 dirt
setblock ~174 ~121 ~92 dirt
setblock ~174 ~121 ~93 dirt
setblock ~174 ~121 ~94 dirt
setblock ~174 ~121 ~95 dirt
setblock ~174 ~121 ~96 dirt
setblock ~174 ~121 ~97 dirt
setblock ~174 ~121 ~98 dirt
setblock ~174 ~121 ~99 dirt
setblock ~174 ~121 ~100 dirt
setblock ~174 ~121 ~101 dirt
setblock ~174 ~121 ~102 dirt
setblock ~174 ~121 ~103 dirt
setblock ~174 ~121 ~104 dirt
setblock ~174 ~121 ~105 dirt
setblock ~174 ~121 ~106 dirt
setblock ~174 ~122 ~89 grass_block
setblock ~174 ~122 ~91 dirt
setblock ~174 ~122 ~92 dirt
setblock ~174 ~122 ~93 dirt
setblock ~174 ~122 ~94 dirt
setblock ~174 ~122 ~95 dirt
setblock ~174 ~122 ~96 dirt
setblock ~174 ~122 ~97 dirt
setblock ~174 ~122 ~98 dirt
setblock ~174 ~122 ~99 dirt
setblock ~174 ~122 ~100 dirt
setblock ~174 ~122 ~101 dirt
setblock ~174 ~122 ~102 dirt
setblock ~174 ~122 ~103 dirt
setblock ~174 ~122 ~104 dirt
setblock ~174 ~122 ~105 dirt
setblock ~174 ~122 ~106 dirt
setblock ~174 ~123 ~91 grass_block
setblock ~174 ~123 ~92 grass_block
setblock ~174 ~123 ~93 grass_block
setblock ~174 ~123 ~94 dirt
setblock ~174 ~123 ~95 dirt
setblock ~174 ~123 ~96 dirt
setblock ~174 ~123 ~97 dirt
setblock ~174 ~123 ~98 dirt
setblock ~174 ~123 ~99 dirt
setblock ~174 ~123 ~100 dirt
setblock ~174 ~123 ~101 dirt
setblock ~174 ~123 ~102 dirt
setblock ~174 ~123 ~103 dirt
setblock ~174 ~123 ~104 dirt
setblock ~174 ~123 ~105 dirt
setblock ~174 ~123 ~106 dirt
setblock ~174 ~124 ~91 short_grass
setblock ~174 ~124 ~92 short_grass
setblock ~174 ~124 ~94 grass_block
setblock ~174 ~124 ~95 grass_block
setblock ~174 ~124 ~96 grass_block
setblock ~174 ~124 ~97 dirt
setblock ~174 ~124 ~98 dirt
setblock ~174 ~124 ~99 dirt
setblock ~174 ~124 ~100 dirt
setblock ~174 ~124 ~101 dirt
setblock ~174 ~124 ~102 dirt
setblock ~174 ~124 ~103 dirt
setblock ~174 ~124 ~104 dirt
setblock ~174 ~124 ~105 dirt
setblock ~174 ~124 ~106 dirt
setblock ~174 ~125 ~97 grass_block
setblock ~174 ~125 ~98 grass_block
setblock ~174 ~125 ~99 grass_block
setblock ~174 ~125 ~100 dirt
setblock ~174 ~125 ~101 dirt
setblock ~174 ~125 ~102 dirt
setblock ~174 ~125 ~103 dirt
setblock ~174 ~125 ~104 dirt
setblock ~174 ~125 ~105 dirt
setblock ~174 ~125 ~106 dirt
setblock ~174 ~126 ~97 short_grass
setblock ~174 ~126 ~98 short_grass
setblock ~174 ~126 ~100 grass_block
setblock ~174 ~126 ~101 grass_block
setblock ~174 ~126 ~102 grass_block
setblock ~174 ~126 ~103 grass_block
setblock ~174 ~126 ~104 grass_block
setblock ~174 ~126 ~105 grass_block
setblock ~174 ~126 ~106 grass_block
setblock ~174 ~127 ~100 poppy
setblock ~174 ~127 ~102 short_grass
setblock ~175 ~116 ~98 dirt
setblock ~175 ~117 ~96 dirt
setblock ~175 ~117 ~97 dirt
setblock ~175 ~117 ~98 dirt
setblock ~175 ~117 ~99 dirt
setblock ~175 ~118 ~94 dirt
setblock ~175 ~118 ~95 dirt
setblock ~175 ~118 ~96 dirt
setblock ~175 ~118 ~97 dirt
setblock ~175 ~118 ~98 dirt
setblock ~175 ~118 ~99 dirt
setblock ~175 ~119 ~94 dirt
setblock ~175 ~119 ~95 dirt
setblock ~175 ~119 ~96 dirt
setblock ~175 ~119 ~97 dirt
setblock ~175 ~119 ~98 dirt
setblock ~175 ~119 ~99 dirt
setblock ~175 ~120 ~93 dirt
setblock ~175 ~120 ~94 dirt
setblock ~175 ~120 ~95 dirt
setblock ~175 ~120 ~96 dirt
setblock ~175 ~120 ~97 dirt
setblock ~175 ~120 ~98 dirt
setblock ~175 ~120 ~99 dirt
setblock ~175 ~120 ~100 dirt
setblock ~175 ~120 ~103 dirt
setblock ~175 ~121 ~92 dirt
setblock ~175 ~121 ~93 dirt
setblock ~175 ~121 ~94 dirt
setblock ~175 ~121 ~95 dirt
setblock ~175 ~121 ~96 dirt
setblock ~175 ~121 ~97 dirt
setblock ~175 ~121 ~98 dirt
setblock ~175 ~121 ~99 dirt
setblock ~175 ~121 ~100 dirt
setblock ~175 ~121 ~101 dirt
setblock ~175 ~121 ~103 dirt
setblock ~175 ~122 ~92 dirt
setblock ~175 ~122 ~93 dirt
setblock ~175 ~122 ~94 dirt
setblock ~175 ~122 ~95 dirt
setblock ~175 ~122 ~96 dirt
setblock ~175 ~122 ~97 dirt
setblock ~175 ~122 ~98 dirt
setblock ~175 ~122 ~99 dirt
setblock ~175 ~122 ~100 dirt
setblock ~175 ~122 ~101 dirt
setblock ~175 ~122 ~103 dirt
setblock ~175 ~123 ~92 grass_block
setblock ~175 ~123 ~93 grass_block
setblock ~175 ~123 ~94 dirt
setblock ~175 ~123 ~95 dirt
setblock ~175 ~123 ~96 dirt
setblock ~175 ~123 ~97 dirt
setblock ~175 ~123 ~98 dirt
setblock ~175 ~123 ~99 dirt
setblock ~175 ~123 ~100 dirt
setblock ~175 ~123 ~101 dirt
setblock ~175 ~123 ~103 dirt
setblock ~175 ~124 ~92 short_grass
setblock ~175 ~124 ~94 grass_block
setblock ~175 ~124 ~95 grass_block
setblock ~175 ~124 ~96 grass_block
setblock ~175 ~124 ~97 dirt
setblock ~175 ~124 ~98 dirt
setblock ~175 ~124 ~99 dirt
setblock ~175 ~124 ~100 dirt
setblock ~175 ~124 ~101 dirt
setblock ~175 ~124 ~103 dirt
setblock ~175 ~125 ~94 short_grass
setblock ~175 ~125 ~97 grass_block
setblock ~175 ~125 ~98 grass_block
setblock ~175 ~125 ~99 grass_block
setblock ~175 ~125 ~100 dirt
setblock ~175 ~125 ~101 dirt
setblock ~175 ~125 ~103 dirt
setblock ~175 ~126 ~98 poppy
setblock ~175 ~126 ~100 grass_block
setblock ~175 ~126 ~101 grass_block
setblock ~175 ~126 ~103 grass_block
setblock ~176 ~119 ~96 dirt
setblock ~176 ~120 ~94 dirt
setblock ~176 ~120 ~96 dirt
setblock ~176 ~120 ~98 dirt
setblock ~176 ~120 ~99 dirt
setblock ~176 ~121 ~93 dirt
setblock ~176 ~121 ~94 dirt
setblock ~176 ~121 ~95 dirt
setblock ~176 ~121 ~96 dirt
setblock ~176 ~121 ~97 dirt
setblock ~176 ~121 ~98 dirt
setblock ~176 ~121 ~99 dirt
setblock ~176 ~121 ~100 dirt
setblock ~176 ~122 ~93 dirt
setblock ~176 ~122 ~94 dirt
setblock ~176 ~122 ~95 dirt
setblock ~176 ~122 ~96 dirt
setblock ~176 ~122 ~97 dirt
setblock ~176 ~122 ~98 dirt
setblock ~176 ~122 ~99 dirt
setblock ~176 ~122 ~100 dirt
setblock ~176 ~123 ~93 grass_block
setblock ~176 ~123 ~94 dirt
setblock ~176 ~123 ~95 dirt
setblock ~176 ~123 ~96 dirt
setblock ~176 ~123 ~97 dirt
setblock ~176 ~123 ~98 dirt
setblock ~176 ~123 ~99 dirt
setblock ~176 ~123 ~100 dirt
setblock ~176 ~124 ~94 grass_block
setblock ~176 ~124 ~95 grass_block
setblock ~176 ~124 ~96 grass_block
setblock ~176 ~124 ~97 dirt
setblock ~176 ~124 ~98 dirt
setblock ~176 ~124 ~99 dirt
setblock ~176 ~124 ~100 dirt
setblock ~176 ~125 ~94 fern
setblock ~176 ~125 ~96 poppy
setblock ~176 ~125 ~97 grass_block
setblock ~176 ~125 ~98 grass_block
setblock ~176 ~125 ~99 grass_block
setblock ~176 ~125 ~100 grass_block
setblock ~176 ~126 ~98 short_grass
setblock ~177 ~121 ~96 dirt
setblock ~177 ~122 ~96 dirt
setblock ~177 ~123 ~96 dirt
setblock ~177 ~124 ~96 dirt
setblock ~177 ~125 ~96 grass_block
setblock ~199 ~200 ~199 gold_block
