setblock ~0 ~1 ~0 gold_block
setblock ~20 ~119 ~88 dirt
setblock ~20 ~119 ~89 dirt
setblock ~20 ~120 ~87 dirt
setblock ~20 ~120 ~88 dirt
setblock ~20 ~120 ~89 dirt
setblock ~20 ~121 ~87 dirt
setblock ~20 ~121 ~88 dirt
setblock ~20 ~121 ~89 dirt
setblock ~20 ~121 ~90 dirt
setblock ~20 ~122 ~87 dirt
setblock ~20 ~122 ~88 dirt
setblock ~20 ~122 ~89 dirt
setblock ~20 ~122 ~90 dirt
setblock ~20 ~123 ~87 dirt
setblock ~20 ~123 ~88 dirt
setblock ~20 ~123 ~89 dirt
setblock ~20 ~123 ~90 dirt
setblock ~20 ~124 ~87 dirt
setblock ~20 ~124 ~88 dirt
setblock ~20 ~124 ~89 dirt
setblock ~20 ~124 ~90 dirt
setblock ~20 ~125 ~87 grass_block
setblock ~20 ~125 ~88 grass_block
setblock ~20 ~125 ~89 dirt
setblock ~20 ~125 ~90 dirt
setblock ~20 ~126 ~89 grass_block
setblock ~20 ~126 ~90 grass_block
setblock ~21 ~118 ~88 dirt
setblock ~21 ~118 ~89 dirt
setblock ~21 ~119 ~87 dirt
setblock ~21 ~119 ~88 dirt
setblock ~21 ~119 ~89 dirt
setblock ~21 ~119 ~90 dirt
setblock ~21 ~120 ~86 dirt
setblock ~21 ~120 ~87 dirt
setblock ~21 ~120 ~88 dirt
setblock ~21 ~120 ~89 dirt
setblock ~21 ~120 ~90 dirt
setblock ~21 ~121 ~86 dirt
setblock ~21 ~121 ~87 dirt
setblock ~21 ~121 ~88 dirt
setblock ~21 ~121 ~89 dirt
setblock ~21 ~121 ~90 dirt
setblock ~21 ~121 ~91 dirt
setblock ~21 ~122 ~86 dirt
setblock ~21 ~122 ~87 dirt
setblock ~21 ~122 ~88 dirt
setblock ~21 ~122 ~89 dirt
setblock ~21 ~122 ~90 dirt
setblock ~21 ~122 ~91 dirt
setblock ~21 ~123 ~86 dirt
setblock ~21 ~123 ~87 dirt
setblock ~21 ~123 ~88 dirt
setblock ~21 ~123 ~89 dirt
setblock ~21 ~123 ~90 dirt
setblock ~21 ~123 ~91 dirt
setblock ~21 ~124 ~86 grass_block
setblock ~21 ~124 ~87 dirt
setblock ~21 ~124 ~88 dirt
setblock ~21 ~124 ~89 dirt
setblock ~21 ~124 ~90 dirt
setblock ~21 ~124 ~91 dirt
setblock ~21 ~125 ~87 grass_block
setblock ~21 ~125 ~88 grass_block
setblock ~21 ~125 ~89 dirt
setblock ~21 ~125 ~90 dirt
setblock ~21 ~125 ~91 dirt
setblock ~21 ~126 ~87 short_grass
setblock ~21 ~126 ~89 grass_block
setblock ~21 ~126 ~90 grass_block
setblock ~21 ~126 ~91 grass_block
setblock ~21 ~127 ~90 short_grass
setblock ~21 ~133 ~96 oak_leaves[persistent=true]
setblock ~21 ~133 ~97 oak_leaves[persistent=true]
setblock ~21 ~133 ~98 jungle_leaves[persistent=true]
setblock ~21 ~134 ~96 oak_leaves[persistent=true]
setblock ~21 ~134 ~97 jungle_leaves[persistent=true]
setblock ~21 ~134 ~99 oak_leaves[persistent=true]
setblock ~21 ~135 ~96 oak_leaves[persistent=true]
setblock ~21 ~135 ~97 oak_leaves[persistent=true]
setblock ~21 ~135 ~98 jungle_leaves[persistent=true]
setblock ~21 ~135 ~99 jungle_leaves[persistent=true]
setblock ~21 ~136 ~96 oak_leaves[persistent=true]
setblock ~21 ~136 ~97 oak_leaves[persistent=true]
setblock ~21 ~136 ~98 jungle_leaves[persistent=true]
setblock ~21 ~136 ~99 oak_leaves[persistent=true]
setblock ~22 ~115 ~89 dirt
setblock ~22 ~116 ~89 dirt
setblock ~22 ~117 ~86 dirt
setblock ~22 ~117 ~88 dirt
setblock ~22 ~117 ~89 dirt
setblock ~22 ~118 ~86 dirt
setblock ~22 ~118 ~87 dirt
setblock ~22 ~118 ~88 dirt
setblock ~22 ~118 ~89 dirt
setblock ~22 ~118 ~90 dirt
setblock ~22 ~119 ~86 dirt
setblock ~22 ~119 ~87 dirt
setblock ~22 ~119 ~88 dirt
setblock ~22 ~119 ~89 dirt
setblock ~22 ~119 ~90 dirt
setblock ~22 ~119 ~91 dirt
setblock ~22 ~120 ~85 dirt
setblock ~22 ~120 ~86 dirt
setblock ~22 ~120 ~87 dirt
setblock ~22 ~120 ~88 dirt
setblock ~22 ~120 ~89 dirt
setblock ~22 ~120 ~90 dirt
setblock ~22 ~120 ~91 dirt
setblock ~22 ~121 ~84 dirt
setblock ~22 ~121 ~85 dirt
setblock ~22 ~121 ~86 dirt
setblock ~22 ~121 ~87 dirt
setblock ~22 ~121 ~88 dirt
setblock ~22 ~121 ~89 dirt
setblock ~22 ~121 ~90 dirt
setblock ~22 ~121 ~91 dirt
setblock ~22 ~121 ~92 dirt
setblock ~22 ~122 ~84 dirt
setblock ~22 ~122 ~85 dirt
setblock ~22 ~122 ~86 dirt
setblock ~22 ~122 ~87 dirt
setblock ~22 ~122 ~88 dirt
setblock ~22 ~122 ~89 dirt
setblock ~22 ~122 ~90 dirt
setblock ~22 ~122 ~91 dirt
setblock ~22 ~122 ~92 dirt
setblock ~22 ~123 ~84 dirt
setblock ~22 ~123 ~85 dirt
setblock ~22 ~123 ~86 dirt
setblock ~22 ~123 ~87 dirt
setblock ~22 ~123 ~88 dirt
setblock ~22 ~123 ~89 dirt
setblock ~22 ~123 ~90 dirt
setblock ~22 ~123 ~91 dirt
setblock ~22 ~123 ~92 dirt
setblock ~22 ~124 ~84 grass_block
setblock ~22 ~124 ~85 grass_block
setblock ~22 ~124 ~86 grass_block
setblock ~22 ~124 ~87 dirt
setblock ~22 ~124 ~88 dirt
setblock ~22 ~124 ~89 dirt
setblock ~22 ~124 ~90 dirt
setblock ~22 ~124 ~91 dirt
setblock ~22 ~124 ~92 dirt
setblock ~22 ~125 ~87 grass_block
setblock ~22 ~125 ~88 grass_block
setblock ~22 ~125 ~89 grass_block
setblock ~22 ~125 ~90 dirt
setblock ~22 ~125 ~91 dirt
setblock ~22 ~125 ~92 dirt
setblock ~22 ~126 ~90 grass_block
setblock ~22 ~126 ~91 grass_block
setblock ~22 ~126 ~92 grass_block
setblock ~22 ~127 ~92 short_grass
setblock ~22 ~133 ~96 oak_leaves[persistent=true]
setblock ~22 ~133 ~97 oak_leaves[persistent=true]
setblock ~22 ~133 ~98 oak_leaves[persistent=true]
setblock ~22 ~133 ~99 oak_leaves[persistent=true]
setblock ~22 ~134 ~96 oak_leaves[persistent=true]
setblock ~22 ~134 ~97 oak_leaves[persistent=true]
setblock ~22 ~134 ~98 oak_leaves[persistent=true]
setblock ~22 ~134 ~99 jungle_leaves[persistent=true]
setblock ~22 ~135 ~98 oak_leaves[persistent=true]
setblock ~22 ~136 ~96 oak_leaves[persistent=true]
setblock ~22 ~136 ~98 oak_leaves[persistent=true]
setblock ~23 ~114 ~86 dirt
setblock ~23 ~114 ~89 dirt
setblock ~23 ~115 ~86 dirt
setblock ~23 ~115 ~87 dirt
setblock ~23 ~115 ~88 dirt
setblock ~23 ~115 ~89 dirt
setblock ~23 ~115 ~90 dirt
setblock ~23 ~116 ~86 dirt
setblock ~23 ~116 ~87 dirt
setblock ~23 ~116 ~88 dirt
setblock ~23 ~116 ~89 dirt
setblock ~23 ~116 ~90 dirt
setblock ~23 ~117 ~85 dirt
setblock ~23 ~117 ~86 dirt
setblock ~23 ~117 ~87 dirt
setblock ~23 ~117 ~88 dirt
setblock ~23 ~117 ~89 dirt
setblock ~23 ~117 ~90 dirt
setblock ~23 ~118 ~84 dirt
setblock ~23 ~118 ~85 dirt
setblock ~23 ~118 ~86 dirt
setblock ~23 ~118 ~87 dirt
setblock ~23 ~118 ~88 dirt
setblock ~23 ~118 ~89 dirt
setblock ~23 ~118 ~90 dirt
setblock ~23 ~118 ~91 dirt
setblock ~23 ~119 ~84 dirt
setblock ~23 ~119 ~85 dirt
setblock ~23 ~119 ~86 dirt
setblock ~23 ~119 ~87 dirt
setblock ~23 ~119 ~88 dirt
setblock ~23 ~119 ~89 dirt
setblock ~23 ~119 ~90 dirt
setblock ~23 ~119 ~91 dirt
setblock ~23 ~120 ~83 dirt
setblock ~23 ~120 ~84 dirt
setblock ~23 ~120 ~85 dirt
setblock ~23 ~120 ~86 dirt
setblock ~23 ~120 ~87 dirt
setblock ~23 ~120 ~88 dirt
setblock ~23 ~120 ~89 dirt
setblock ~23 ~120 ~90 dirt
setblock ~23 ~120 ~91 dirt
setblock ~23 ~120 ~92 dirt
setblock ~23 ~120 ~95 dirt
setblock ~23 ~121 ~83 dirt
setblock ~23 ~121 ~84 dirt
setblock ~23 ~121 ~85 dirt
setblock ~23 ~121 ~86 dirt
setblock ~23 ~121 ~87 dirt
setblock ~23 ~121 ~88 dirt
setblock ~23 ~121 ~89 dirt
setblock ~23 ~121 ~90 dirt
setblock ~23 ~121 ~91 dirt
setblock ~23 ~121 ~92 dirt
setblock ~23 ~121 ~93 dirt
setblock ~23 ~121 ~95 dirt
setblock ~23 ~122 ~83 dirt
setblock ~23 ~122 ~84 dirt
setblock ~23 ~122 ~85 dirt
setblock ~23 ~122 ~86 dirt
setblock ~23 ~122 ~87 dirt
setblock ~23 ~122 ~88 dirt
setblock ~23 ~122 ~89 dirt
setblock ~23 ~122 ~90 dirt
setblock ~23 ~122 ~91 dirt
setblock ~23 ~122 ~92 dirt
setblock ~23 ~122 ~93 dirt
setblock ~23 ~122 ~95 dirt
setblock ~23 ~123 ~83 dirt
setblock ~23 ~123 ~84 dirt
setblock ~23 ~123 ~85 dirt
setblock ~23 ~123 ~86 dirt
setblock ~23 ~123 ~87 dirt
setblock ~23 ~123 ~88 dirt
setblock ~23 ~123 ~89 dirt
setblock ~23 ~123 ~90 dirt
setblock ~23 ~123 ~91 dirt
setblock ~23 ~123 ~92 dirt
setblock ~23 ~123 ~93 dirt
setblock ~23 ~123 ~95 dirt
setblock ~23 ~124 ~83 grass_block
setblock ~23 ~124 ~84 grass_block
setblock ~23 ~124 ~85 grass_block
setblock ~23 ~124 ~86 grass_block
setblock ~23 ~124 ~87 dirt
setblock ~23 ~124 ~88 dirt
setblock ~23 ~124 ~89 dirt
setblock ~23 ~124 ~90 dirt
setblock ~23 ~124 ~91 dirt
setblock ~23 ~124 ~92 dirt
setblock ~23 ~124 ~93 dirt
setblock ~23 ~124 ~95 dirt
setblock ~23 ~125 ~83 short_grass
setblock ~23 ~125 ~85 short_grass
setblock ~23 ~125 ~87 grass_block
setblock ~23 ~125 ~88 grass_block
setblock ~23 ~125 ~89 grass_block
setblock ~23 ~125 ~90 grass_block
setblock ~23 ~125 ~91 grass_block
setblock ~23 ~125 ~92 dirt
setblock ~23 ~125 ~93 dirt
setblock ~23 ~125 ~95 dirt
setblock ~23 ~126 ~92 grass_block
setblock ~23 ~126 ~93 grass_block
setblock ~23 ~126 ~95 grass_block
setblock ~23 ~127 ~81 oak_leaves[persistent=true]
setblock ~23 ~127 ~82 jungle_leaves[persistent=true]
setblock ~23 ~127 ~83 oak_leaves[persistent=true]
setblock ~23 ~127 ~84 oak_leaves[persistent=true]
setblock ~23 ~127 ~92 short_grass
setblock ~23 ~128 ~81 oak_leaves[persistent=true]
setblock ~23 ~128 ~82 oak_leaves[persistent=true]
setblock ~23 ~128 ~83 oak_leaves[persistent=true]
setblock ~23 ~128 ~84 oak_leaves[persistent=true]
setblock ~23 ~129 ~81 oak_leaves[persistent=true]
setblock ~23 ~129 ~82 oak_leaves[persistent=true]
setblock ~23 ~129 ~83 oak_leaves[persistent=true]
setblock ~23 ~129 ~84 oak_leaves[persistent=true]
setblock ~23 ~130 ~84 oak_leaves[persistent=true]
setblock ~23 ~131 ~95 oak_leaves[persistent=true]
setblock ~23 ~131 ~96 jungle_leaves[persistent=true]
setblock ~23 ~131 ~97 oak_leaves[persistent=true]
setblock ~23 ~131 ~98 oak_leaves[persistent=true]
setblock ~23 ~132 ~95 oak_leaves[persistent=true]
setblock ~23 ~132 ~96 oak_leaves[persistent=true]
setblock ~23 ~132 ~97 oak_leaves[persistent=true]
setblock ~23 ~133 ~96 jungle_leaves[persistent=true]
setblock ~23 ~133 ~97 oak_leaves[persistent=true]
setblock ~23 ~133 ~99 oak_leaves[persistent=true]
setblock ~23 ~134 ~97 oak_leaves[persistent=true]
setblock ~23 ~134 ~98 oak_leaves[persistent=true]
setblock ~23 ~134 ~99 oak_leaves[persistent=true]
setblock ~23 ~135 ~91 oak_leaves[persistent=true]
setblock ~23 ~135 ~92 oak_leaves[persistent=true]
setblock ~23 ~135 ~96 jungle_leaves[persistent=true]
setblock ~23 ~135 ~97 jungle_leaves[persistent=true]
setblock ~23 ~135 ~98 jungle_leaves[persistent=true]
setblock ~23 ~135 ~99 oak_leaves[persistent=true]
setblock ~23 ~136 ~91 jungle_leaves[persistent=true]
setblock ~23 ~136 ~92 oak_leaves[persistent=true]
setblock ~23 ~136 ~96 oak_leaves[persistent=true]
setblock ~23 ~136 ~97 oak_leaves[persistent=true]
setblock ~23 ~136 ~99 oak_leaves[persistent=true]
setblock ~24 ~112 ~87 dirt
setblock ~24 ~112 ~88 dirt
setblock ~24 ~113 ~86 dirt
setblock ~24 ~113 ~87 dirt
setblock ~24 ~113 ~88 dirt
setblock ~24 ~113 ~89 dirt
setblock ~24 ~114 ~85 dirt
setblock ~24 ~114 ~86 dirt
setblock ~24 ~114 ~87 dirt
setblock ~24 ~114 ~88 dirt
setblock ~24 ~114 ~89 dirt
setblock ~24 ~114 ~90 dirt
setblock ~24 ~115 ~85 dirt
setblock ~24 ~115 ~86 dirt
setblock ~24 ~115 ~87 dirt
setblock ~24 ~115 ~88 dirt
setblock ~24 ~115 ~89 dirt
setblock ~24 ~115 ~90 dirt
setblock ~24 ~116 ~85 dirt
setblock ~24 ~116 ~86 dirt
setblock ~24 ~116 ~87 dirt
setblock ~24 ~116 ~88 dirt
setblock ~24 ~116 ~89 dirt
setblock ~24 ~116 ~90 dirt
setblock ~24 ~116 ~91 dirt
setblock ~24 ~117 ~84 dirt
setblock ~24 ~117 ~85 dirt
setblock ~24 ~117 ~86 dirt
setblock ~24 ~117 ~87 dirt
setblock ~24 ~117 ~88 dirt
setblock ~24 ~117 ~89 dirt
setblock ~24 ~117 ~90 dirt
setblock ~24 ~117 ~91 dirt
setblock ~24 ~118 ~83 dirt
setblock ~24 ~118 ~84 dirt
setblock ~24 ~118 ~85 dirt
setblock ~24 ~118 ~86 dirt
setblock ~24 ~118 ~87 dirt
setblock ~24 ~118 ~88 dirt
setblock ~24 ~118 ~89 dirt
setblock ~24 ~118 ~90 dirt
setblock ~24 ~118 ~91 dirt
setblock ~24 ~119 ~83 dirt
setblock ~24 ~119 ~84 dirt
setblock ~24 ~119 ~85 dirt
setblock ~24 ~119 ~86 dirt
setblock ~24 ~119 ~87 dirt
setblock ~24 ~119 ~88 dirt
setblock ~24 ~119 ~89 dirt
setblock ~24 ~119 ~90 dirt
setblock ~24 ~119 ~91 dirt
setblock ~24 ~119 ~92 dirt
setblock ~24 ~119 ~95 dirt
setblock ~24 ~120 ~82 dirt
setblock ~24 ~120 ~83 dirt
setblock ~24 ~120 ~84 dirt
setblock ~24 ~120 ~85 dirt
setblock ~24 ~120 ~86 dirt
setblock ~24 ~120 ~87 dirt
setblock ~24 ~120 ~88 dirt
setblock ~24 ~120 ~89 dirt
setblock ~24 ~120 ~90 dirt
setblock ~24 ~120 ~91 dirt
setblock ~24 ~120 ~92 dirt
setblock ~24 ~120 ~93 dirt
setblock ~24 ~120 ~94 dirt
setblock ~24 ~120 ~95 dirt
setblock ~24 ~120 ~96 dirt
setblock ~24 ~121 ~82 dirt
setblock ~24 ~121 ~83 dirt
setblock ~24 ~121 ~84 dirt
setblock ~24 ~121 ~85 dirt
setblock ~24 ~121 ~86 dirt
setblock ~24 ~121 ~87 dirt
setblock ~24 ~121 ~88 dirt
setblock ~24 ~121 ~89 dirt
setblock ~24 ~121 ~90 dirt
setblock ~24 ~121 ~91 dirt
setblock ~24 ~121 ~92 dirt
setblock ~24 ~121 ~93 dirt
setblock ~24 ~121 ~94 dirt
setblock ~24 ~121 ~95 dirt
setblock ~24 ~121 ~96 dirt
setblock ~24 ~121 ~113 dirt
setblock ~24 ~122 ~82 dirt
setblock ~24 ~122 ~83 dirt
setblock ~24 ~122 ~84 dirt
setblock ~24 ~122 ~85 dirt
setblock ~24 ~122 ~86 dirt
setblock ~24 ~122 ~87 dirt
setblock ~24 ~122 ~88 dirt
setblock ~24 ~122 ~89 dirt
setblock ~24 ~122 ~90 dirt
setblock ~24 ~122 ~91 dirt
setblock ~24 ~122 ~92 dirt
setblock ~24 ~122 ~93 dirt
setblock ~24 ~122 ~94 dirt
setblock ~24 ~122 ~95 dirt
setblock ~24 ~122 ~96 dirt
setblock ~24 ~122 ~113 dirt
setblock ~24 ~123 ~82 grass_block
setblock ~24 ~123 ~83 dirt
setblock ~24 ~123 ~84 dirt
setblock ~24 ~123 ~85 dirt
setblock ~24 ~123 ~86 dirt
setblock ~24 ~123 ~87 dirt
setblock ~24 ~123 ~88 dirt
setblock ~24 ~123 ~89 dirt
setblock ~24 ~123 ~90 dirt
setblock ~24 ~123 ~91 dirt
setblock ~24 ~123 ~92 dirt
setblock ~24 ~123 ~93 dirt
setblock ~24 ~123 ~94 dirt
setblock ~24 ~123 ~95 dirt
setblock ~24 ~123 ~96 dirt
setblock ~24 ~123 ~113 dirt
setblock ~24 ~124 ~83 grass_block
setblock ~24 ~124 ~84 grass_block
setblock ~24 ~124 ~85 grass_block
setblock ~24 ~124 ~86 grass_block
setblock ~24 ~124 ~87 grass_block
setblock ~24 ~124 ~88 dirt
setblock ~24 ~124 ~89 dirt
setblock ~24 ~124 ~90 dirt
setblock ~24 ~124 ~91 dirt
setblock ~24 ~124 ~92 dirt
setblock ~24 ~124 ~93 dirt
setblock ~24 ~124 ~94 dirt
setblock ~24 ~124 ~95 dirt
setblock ~24 ~124 ~96 dirt
setblock ~24 ~124 ~113 dirt
setblock ~24 ~125 ~87 short_grass
setblock ~24 ~125 ~88 grass_block
setblock ~24 ~125 ~89 grass_block
setblock ~24 ~125 ~90 grass_block
setblock ~24 ~125 ~91 grass_block
setblock ~24 ~125 ~92 grass_block
setblock ~24 ~125 ~93 dirt
setblock ~24 ~125 ~94 dirt
setblock ~24 ~125 ~95 dirt
setblock ~24 ~125 ~96 dirt
setblock ~24 ~125 ~113 grass_block
setblock ~24 ~126 ~88 short_grass
setblock ~24 ~126 ~89 short_grass
setblock ~24 ~126 ~92 short_grass
setblock ~24 ~126 ~93 grass_block
setblock ~24 ~126 ~94 grass_block
setblock ~24 ~126 ~95 grass_block
setblock ~24 ~126 ~96 grass_block
setblock ~24 ~127 ~81 oak_leaves[persistent=true]
setblock ~24 ~127 ~82 oak_leaves[persistent=true]
setblock ~24 ~127 ~83 oak_leaves[persistent=true]
setblock ~24 ~128 ~81 oak_leaves[persistent=true]
setblock ~24 ~128 ~82 oak_leaves[persistent=true]
setblock ~24 ~128 ~83 oak_leaves[persistent=true]
setblock ~24 ~128 ~84 oak_leaves[persistent=true]
setblock ~24 ~129 ~83 oak_leaves[persistent=true]
setblock ~24 ~129 ~85 oak_leaves[persistent=true]
setblock ~24 ~129 ~101 oak_leaves[persistent=true]
setblock ~24 ~129 ~103 oak_leaves[persistent=true]
setblock ~24 ~130 ~84 jungle_leaves[persistent=true]
setblock ~24 ~130 ~85 oak_leaves[persistent=true]
setblock ~24 ~130 ~100 oak_leaves[persistent=true]
setblock ~24 ~130 ~101 oak_leaves[persistent=true]
setblock ~24 ~130 ~102 oak_leaves[persistent=true]
setblock ~24 ~130 ~103 oak_leaves[persistent=true]
setblock ~24 ~131 ~84 oak_leaves[persistent=true]
setblock ~24 ~131 ~85 oak_leaves[persistent=true]
setblock ~24 ~131 ~95 jungle_leaves[persistent=true]
setblock ~24 ~131 ~96 jungle_leaves[persistent=true]
setblock ~24 ~131 ~97 oak_leaves[persistent=true]
setblock ~24 ~131 ~98 oak_leaves[persistent=true]
setblock ~24 ~131 ~100 oak_leaves[persistent=true]
setblock ~24 ~131 ~101 oak_leaves[persistent=true]
setblock ~24 ~132 ~95 oak_leaves[persistent=true]
setblock ~24 ~132 ~96 oak_leaves[persistent=true]
setblock ~24 ~132 ~97 oak_leaves[persistent=true]
setblock ~24 ~132 ~101 jungle_leaves[persistent=true]
setblock ~24 ~132 ~102 jungle_leaves[persistent=true]
setblock ~24 ~132 ~103 oak_leaves[persistent=true]
setblock ~24 ~133 ~89 oak_leaves[persistent=true]
setblock ~24 ~133 ~95 oak_leaves[persistent=true]
setblock ~24 ~133 ~96 oak_leaves[persistent=true]
setblock ~24 ~133 ~97 oak_leaves[persistent=true]
setblock ~24 ~133 ~98 oak_leaves[persistent=true]
setblock ~24 ~133 ~99 oak_leaves[persistent=true]
setblock ~24 ~134 ~89 oak_leaves[persistent=true]
setblock ~24 ~134 ~90 oak_leaves[persistent=true]
setblock ~24 ~134 ~91 jungle_leaves[persistent=true]
setblock ~24 ~134 ~92 oak_leaves[persistent=true]
setblock ~24 ~134 ~95 jungle_leaves[persistent=true]
setblock ~24 ~134 ~96 oak_leaves[persistent=true]
setblock ~24 ~134 ~97 oak_leaves[persistent=true]
setblock ~24 ~134 ~98 oak_leaves[persistent=true]
setblock ~24 ~134 ~99 oak_leaves[persistent=true]
setblock ~24 ~134 ~100 jungle_leaves[persistent=true]
setblock ~24 ~135 ~89 oak_leaves[persistent=true]
setblock ~24 ~135 ~90 oak_leaves[persistent=true]
setblock ~24 ~135 ~92 oak_leaves[persistent=true]
setblock ~24 ~135 ~96 oak_leaves[persistent=true]
setblock ~24 ~135 ~98 oak_wood
setblock ~24 ~135 ~99 oak_leaves[persistent=true]
setblock ~24 ~135 ~100 oak_leaves[persistent=true]
setblock ~24 ~136 ~90 oak_leaves[persistent=true]
setblock ~24 ~136 ~91 oak_leaves[persistent=true]
setblock ~24 ~136 ~96 oak_leaves[persistent=true]
setblock ~24 ~136 ~97 oak_leaves[persistent=true]
setblock ~24 ~136 ~98 oak_leaves[persistent=true]
setblock ~24 ~136 ~99 oak_leaves[persistent=true]
setblock ~24 ~136 ~100 oak_leaves[persistent=true]
setblock ~25 ~110 ~88 dirt
setblock ~25 ~110 ~89 dirt
setblock ~25 ~111 ~87 dirt
setblock ~25 ~111 ~88 dirt
setblock ~25 ~111 ~89 dirt
setblock ~25 ~112 ~86 dirt
setblock ~25 ~112 ~87 dirt
setblock ~25 ~112 ~88 dirt
setblock ~25 ~112 ~89 dirt
setblock ~25 ~113 ~85 dirt
setblock ~25 ~113 ~86 dirt
setblock ~25 ~113 ~87 dirt
setblock ~25 ~113 ~88 dirt
setblock ~25 ~113 ~89 dirt
setblock ~25 ~113 ~90 dirt
setblock ~25 ~114 ~85 dirt
setblock ~25 ~114 ~86 dirt
setblock ~25 ~114 ~87 dirt
setblock ~25 ~114 ~88 dirt
setblock ~25 ~114 ~89 dirt
setblock ~25 ~114 ~90 dirt
setblock ~25 ~115 ~84 dirt
setblock ~25 ~115 ~85 dirt
setblock ~25 ~115 ~86 dirt
setblock ~25 ~115 ~87 dirt
setblock ~25 ~115 ~88 dirt
setblock ~25 ~115 ~89 dirt
setblock ~25 ~115 ~90 dirt
setblock ~25 ~115 ~91 dirt
setblock ~25 ~116 ~84 dirt
setblock ~25 ~116 ~85 dirt
setblock ~25 ~116 ~86 dirt
setblock ~25 ~116 ~87 dirt
setblock ~25 ~116 ~88 dirt
setblock ~25 ~116 ~89 dirt
setblock ~25 ~116 ~90 dirt
setblock ~25 ~116 ~91 dirt
setblock ~25 ~116 ~92 dirt
setblock ~25 ~117 ~83 dirt
setblock ~25 ~117 ~84 dirt
setblock ~25 ~117 ~85 dirt
setblock ~25 ~117 ~86 dirt
setblock ~25 ~117 ~87 dirt
setblock ~25 ~117 ~88 dirt
setblock ~25 ~117 ~89 dirt
setblock ~25 ~117 ~90 dirt
setblock ~25 ~117 ~91 dirt
setblock ~25 ~117 ~92 dirt
setblock ~25 ~118 ~83 dirt
setblock ~25 ~118 ~84 dirt
setblock ~25 ~118 ~85 dirt
setblock ~25 ~118 ~86 dirt
setblock ~25 ~118 ~87 dirt
setblock ~25 ~118 ~88 dirt
setblock ~25 ~118 ~89 dirt
setblock ~25 ~118 ~90 dirt
setblock ~25 ~118 ~91 dirt
setblock ~25 ~118 ~92 dirt
setblock ~25 ~118 ~95 dirt
setblock ~25 ~118 ~98 dirt
setblock ~25 ~119 ~82 dirt
setblock ~25 ~119 ~83 dirt
setblock ~25 ~119 ~84 dirt
setblock ~25 ~119 ~85 dirt
setblock ~25 ~119 ~86 dirt
setblock ~25 ~119 ~87 dirt
setblock ~25 ~119 ~88 dirt
setblock ~25 ~119 ~89 dirt
setblock ~25 ~119 ~90 dirt
setblock ~25 ~119 ~91 dirt
setblock ~25 ~119 ~92 dirt
setblock ~25 ~119 ~93 dirt
setblock ~25 ~119 ~94 dirt
setblock ~25 ~119 ~95 dirt
setblock ~25 ~119 ~96 dirt
setblock ~25 ~119 ~98 dirt
setblock ~25 ~120 ~82 dirt
setblock ~25 ~120 ~83 dirt
setblock ~25 ~120 ~84 dirt
setblock ~25 ~120 ~85 dirt
setblock ~25 ~120 ~86 dirt
setblock ~25 ~120 ~87 dirt
setblock ~25 ~120 ~88 dirt
setblock ~25 ~120 ~89 dirt
setblock ~25 ~120 ~90 dirt
setblock ~25 ~120 ~91 dirt
setblock ~25 ~120 ~92 dirt
setblock ~25 ~120 ~93 dirt
setblock ~25 ~120 ~94 dirt
setblock ~25 ~120 ~95 dirt
setblock ~25 ~120 ~96 dirt
setblock ~25 ~120 ~97 dirt
setblock ~25 ~120 ~98 dirt
setblock ~25 ~120 ~99 dirt
setblock ~25 ~120 ~113 dirt
setblock ~25 ~120 ~116 dirt
setblock ~25 ~121 ~81 dirt
setblock ~25 ~121 ~82 dirt
setblock ~25 ~121 ~83 dirt
setblock ~25 ~121 ~84 dirt
setblock ~25 ~121 ~85 dirt
setblock ~25 ~121 ~86 dirt
setblock ~25 ~121 ~87 dirt
setblock ~25 ~121 ~88 dirt
setblock ~25 ~121 ~89 dirt
setblock ~25 ~121 ~90 dirt
setblock ~25 ~121 ~91 dirt
setblock ~25 ~121 ~92 dirt
setblock ~25 ~121 ~93 dirt
setblock ~25 ~121 ~94 dirt
setblock ~25 ~121 ~95 dirt
setblock ~25 ~121 ~96 dirt
setblock ~25 ~121 ~97 dirt
setblock ~25 ~121 ~98 dirt
setblock ~25 ~121 ~99 dirt
setblock ~25 ~121 ~100 dirt
setblock ~25 ~121 ~112 dirt
setblock ~25 ~121 ~113 dirt
setblock ~25 ~121 ~114 dirt
setblock ~25 ~121 ~116 dirt
setblock ~25 ~121 ~119 dirt
setblock ~25 ~122 ~81 dirt
setblock ~25 ~122 ~82 dirt
setblock ~25 ~122 ~83 dirt
setblock ~25 ~122 ~84 dirt
setblock ~25 ~122 ~85 dirt
setblock ~25 ~122 ~86 dirt
setblock ~25 ~122 ~87 dirt
setblock ~25 ~122 ~88 dirt
setblock ~25 ~122 ~89 dirt
setblock ~25 ~122 ~90 dirt
setblock ~25 ~122 ~91 dirt
setblock ~25 ~122 ~92 dirt
setblock ~25 ~122 ~93 dirt
setblock ~25 ~122 ~94 dirt
setblock ~25 ~122 ~95 dirt
setblock ~25 ~122 ~96 dirt
setblock ~25 ~122 ~97 dirt
setblock ~25 ~122 ~98 dirt
setblock ~25 ~122 ~99 dirt
setblock ~25 ~122 ~100 dirt
setblock ~25 ~122 ~112 dirt
setblock ~25 ~122 ~113 dirt
setblock ~25 ~122 ~114 dirt
setblock ~25 ~122 ~116 dirt
setblock ~25 ~122 ~119 dirt
setblock ~25 ~123 ~81 dirt
setblock ~25 ~123 ~82 dirt
setblock ~25 ~123 ~83 dirt
setblock ~25 ~123 ~84 dirt
setblock ~25 ~123 ~85 dirt
setblock ~25 ~123 ~86 dirt
setblock ~25 ~123 ~87 dirt
setblock ~25 ~123 ~88 dirt
setblock ~25 ~123 ~89 dirt
setblock ~25 ~123 ~90 dirt
setblock ~25 ~123 ~91 dirt
setblock ~25 ~123 ~92 dirt
setblock ~25 ~123 ~93 dirt
setblock ~25 ~123 ~94 dirt
setblock ~25 ~123 ~95 dirt
setblock ~25 ~123 ~96 dirt
setblock ~25 ~123 ~97 dirt
setblock ~25 ~123 ~98 dirt
setblock ~25 ~123 ~99 dirt
setblock ~25 ~123 ~100 dirt
setblock ~25 ~123 ~112 dirt
setblock ~25 ~123 ~113 dirt
setblock ~25 ~123 ~114 dirt
setblock ~25 ~123 ~116 dirt
setblock ~25 ~123 ~119 dirt
setblock ~25 ~124 ~81 grass_block
setblock ~25 ~124 ~82 grass_block
setblock ~25 ~124 ~83 grass_block
setblock ~25 ~124 ~84 grass_block
setblock ~25 ~124 ~85 grass_block
setblock ~25 ~124 ~86 grass_block
setblock ~25 ~124 ~87 grass_block
setblock ~25 ~124 ~88 grass_block
setblock ~25 ~124 ~89 grass_block
setblock ~25 ~124 ~90 grass_block
setblock ~25 ~124 ~91 dirt
setblock ~25 ~124 ~92 dirt
setblock ~25 ~124 ~93 dirt
setblock ~25 ~124 ~94 dirt
setblock ~25 ~124 ~95 dirt
setblock ~25 ~124 ~96 dirt
setblock ~25 ~124 ~97 dirt
setblock ~25 ~124 ~98 dirt
setblock ~25 ~124 ~99 dirt
setblock ~25 ~124 ~100 dirt
setblock ~25 ~124 ~112 dirt
setblock ~25 ~124 ~113 dirt
setblock ~25 ~124 ~114 dirt
setblock ~25 ~124 ~116 dirt
setblock ~25 ~124 ~119 dirt
setblock ~25 ~125 ~81 short_grass
setblock ~25 ~125 ~82 short_grass
setblock ~25 ~125 ~86 short_grass
setblock ~25 ~125 ~91 grass_block
setblock ~25 ~125 ~92 grass_block
setblock ~25 ~125 ~93 grass_block
setblock ~25 ~125 ~94 dirt
setblock ~25 ~125 ~95 dirt
setblock ~25 ~125 ~96 dirt
setblock ~25 ~125 ~97 dirt
setblock ~25 ~125 ~98 dirt
setblock ~25 ~125 ~99 dirt
setblock ~25 ~125 ~100 dirt
setblock ~25 ~125 ~112 grass_block
setblock ~25 ~125 ~113 grass_block
setblock ~25 ~125 ~114 grass_block
setblock ~25 ~125 ~116 dirt
setblock ~25 ~125 ~119 dirt
setblock ~25 ~126 ~94 grass_block
setblock ~25 ~126 ~95 grass_block
setblock ~25 ~126 ~96 grass_block
setblock ~25 ~126 ~97 dirt
setblock ~25 ~126 ~98 dirt
setblock ~25 ~126 ~99 dirt
setblock ~25 ~126 ~100 dirt
setblock ~25 ~126 ~116 grass_block
setblock ~25 ~126 ~119 grass_block
setblock ~25 ~127 ~81 oak_leaves[persistent=true]
setblock ~25 ~127 ~84 oak_leaves[persistent=true]
setblock ~25 ~127 ~94 short_grass
setblock ~25 ~127 ~97 grass_block
setblock ~25 ~127 ~98 grass_block
setblock ~25 ~127 ~99 grass_block
setblock ~25 ~127 ~100 dirt
setblock ~25 ~127 ~116 poppy
setblock ~25 ~128 ~82 oak_leaves[persistent=true]
setblock ~25 ~128 ~85 oak_leaves[persistent=true]
setblock ~25 ~128 ~100 grass_block
setblock ~25 ~129 ~83 oak_leaves[persistent=true]
setblock ~25 ~129 ~85 oak_leaves[persistent=true]
setblock ~25 ~129 ~100 oak_leaves[persistent=true]
setblock ~25 ~129 ~101 oak_leaves[persistent=true]
setblock ~25 ~129 ~103 jungle_leaves[persistent=true]
setblock ~25 ~130 ~81 oak_leaves[persistent=true]
setblock ~25 ~130 ~82 jungle_leaves[persistent=true]
setblock ~25 ~130 ~83 oak_leaves[persistent=true]
setblock ~25 ~130 ~84 oak_leaves[persistent=true]
setblock ~25 ~130 ~85 jungle_leaves[persistent=true]
setblock ~25 ~130 ~95 oak_leaves[persistent=true]
setblock ~25 ~130 ~96 oak_leaves[persistent=true]
setblock ~25 ~130 ~97 oak_leaves[persistent=true]
setblock ~25 ~130 ~99 oak_leaves[persistent=true]
setblock ~25 ~130 ~101 oak_leaves[persistent=true]
setblock ~25 ~130 ~103 jungle_leaves[persistent=true]
setblock ~25 ~130 ~104 oak_leaves[persistent=true]
setblock ~25 ~131 ~81 oak_leaves[persistent=true]
setblock ~25 ~131 ~82 oak_leaves[persistent=true]
setblock ~25 ~131 ~83 oak_leaves[persistent=true]
setblock ~25 ~131 ~84 oak_leaves[persistent=true]
setblock ~25 ~131 ~95 oak_leaves[persistent=true]
setblock ~25 ~131 ~96 oak_leaves[persistent=true]
setblock ~25 ~131 ~97 oak_leaves[persistent=true]
setblock ~25 ~131 ~98 oak_leaves[persistent=true]
setblock ~25 ~131 ~100 jungle_leaves[persistent=true]
setblock ~25 ~131 ~101 jungle_leaves[persistent=true]
setblock ~25 ~131 ~102 oak_leaves[persistent=true]
setblock ~25 ~131 ~103 oak_leaves[persistent=true]
setblock ~25 ~131 ~104 oak_leaves[persistent=true]
setblock ~25 ~132 ~88 oak_leaves[persistent=true]
setblock ~25 ~132 ~90 oak_leaves[persistent=true]
setblock ~25 ~132 ~91 oak_leaves[persistent=true]
setblock ~25 ~132 ~94 oak_leaves[persistent=true]
setblock ~25 ~132 ~97 oak_leaves[persistent=true]
setblock ~25 ~132 ~98 oak_leaves[persistent=true]
setblock ~25 ~132 ~101 oak_leaves[persistent=true]
setblock ~25 ~132 ~102 oak_leaves[persistent=true]
setblock ~25 ~132 ~103 oak_leaves[persistent=true]
setblock ~25 ~133 ~89 oak_leaves[persistent=true]
setblock ~25 ~133 ~90 jungle_leaves[persistent=true]
setblock ~25 ~133 ~91 oak_leaves[persistent=true]
setblock ~25 ~133 ~92 oak_leaves[persistent=true]
setblock ~25 ~133 ~94 oak_leaves[persistent=true]
setblock ~25 ~133 ~97 oak_wood
setblock ~25 ~133 ~98 oak_leaves[persistent=true]
setblock ~25 ~133 ~99 oak_leaves[persistent=true]
setblock ~25 ~133 ~100 oak_leaves[persistent=true]
setblock ~25 ~133 ~101 oak_leaves[persistent=true]
setblock ~25 ~133 ~103 jungle_leaves[persistent=true]
setblock ~25 ~133 ~104 oak_leaves[persistent=true]
setblock ~25 ~134 ~88 oak_leaves[persistent=true]
setblock ~25 ~134 ~89 oak_leaves[persistent=true]
setblock ~25 ~134 ~91 oak_leaves[persistent=true]
setblock ~25 ~134 ~92 oak_leaves[persistent=true]
setblock ~25 ~134 ~95 oak_leaves[persistent=true]
setblock ~25 ~134 ~96 oak_leaves[persistent=true]
setblock ~25 ~134 ~97 oak_leaves[persistent=true]
setblock ~25 ~134 ~98 oak_leaves[persistent=true]
setblock ~25 ~134 ~99 jungle_leaves[persistent=true]
setblock ~25 ~134 ~100 oak_leaves[persistent=true]
setblock ~25 ~134 ~101 jungle_leaves[persistent=true]
setblock ~25 ~135 ~88 oak_leaves[persistent=true]
setblock ~25 ~135 ~90 oak_leaves[persistent=true]
setblock ~25 ~135 ~91 oak_leaves[persistent=true]
setblock ~25 ~135 ~92 oak_wood
setblock ~25 ~135 ~97 oak_leaves[persistent=true]
setblock ~25 ~135 ~98 oak_leaves[persistent=true]
setblock ~25 ~135 ~99 oak_wood
setblock ~25 ~135 ~100 oak_leaves[persistent=true]
setblock ~25 ~136 ~90 oak_leaves[persistent=true]
setblock ~25 ~136 ~91 jungle_leaves[persistent=true]
setblock ~25 ~136 ~92 oak_leaves[persistent=true]
setblock ~25 ~136 ~97 oak_leaves[persistent=true]
setblock ~25 ~136 ~98 jungle_leaves[persistent=true]
setblock ~25 ~136 ~99 oak_leaves[persistent=true]
setblock ~25 ~136 ~100 oak_leaves[persistent=true]
setblock ~25 ~136 ~101 oak_leaves[persistent=true]
setblock ~25 ~137 ~98 oak_leaves[persistent=true]
setblock ~25 ~138 ~99 jungle_leaves[persistent=true]
setblock ~25 ~138 ~100 oak_leaves[persistent=true]
setblock ~26 ~107 ~87 dirt
setblock ~26 ~108 ~87 dirt
setblock ~26 ~108 ~88 dirt
setblock ~26 ~109 ~87 dirt
setblock ~26 ~109 ~88 dirt
setblock ~26 ~109 ~89 dirt
setblock ~26 ~110 ~87 dirt
setblock ~26 ~110 ~88 dirt
setblock ~26 ~110 ~89 dirt
setblock ~26 ~110 ~90 dirt
setblock ~26 ~111 ~86 dirt
setblock ~26 ~111 ~87 dirt
setblock ~26 ~111 ~88 dirt
setblock ~26 ~111 ~89 dirt
setblock ~26 ~111 ~90 dirt
setblock ~26 ~112 ~85 dirt
setblock ~26 ~112 ~86 dirt
setblock ~26 ~112 ~87 dirt
setblock ~26 ~112 ~88 dirt
setblock ~26 ~112 ~89 dirt
setblock ~26 ~112 ~90 dirt
setblock ~26 ~113 ~85 dirt
setblock ~26 ~113 ~86 dirt
setblock ~26 ~113 ~87 dirt
setblock ~26 ~113 ~88 dirt
setblock ~26 ~113 ~89 dirt
setblock ~26 ~113 ~90 dirt
setblock ~26 ~113 ~91 dirt
setblock ~26 ~114 ~84 dirt
setblock ~26 ~114 ~85 dirt
setblock ~26 ~114 ~86 dirt
setblock ~26 ~114 ~87 dirt
setblock ~26 ~114 ~88 dirt
setblock ~26 ~114 ~89 dirt
setblock ~26 ~114 ~90 dirt
setblock ~26 ~114 ~91 dirt
setblock ~26 ~115 ~84 dirt
setblock ~26 ~115 ~85 dirt
setblock ~26 ~115 ~86 dirt
setblock ~26 ~115 ~87 dirt
setblock ~26 ~115 ~88 dirt
setblock ~26 ~115 ~89 dirt
setblock ~26 ~115 ~90 dirt
setblock ~26 ~115 ~91 dirt
setblock ~26 ~115 ~92 dirt
setblock ~26 ~116 ~83 dirt
setblock ~26 ~116 ~84 dirt
setblock ~26 ~116 ~85 dirt
setblock ~26 ~116 ~86 dirt
setblock ~26 ~116 ~87 dirt
setblock ~26 ~116 ~88 dirt
setblock ~26 ~116 ~89 dirt
setblock ~26 ~116 ~90 dirt
setblock ~26 ~116 ~91 dirt
setblock ~26 ~116 ~92 dirt
setblock ~26 ~116 ~93 dirt
setblock ~26 ~116 ~95 dirt
setblock ~26 ~117 ~82 dirt
setblock ~26 ~117 ~83 dirt
setblock ~26 ~117 ~84 dirt
setblock ~26 ~117 ~85 dirt
setblock ~26 ~117 ~86 dirt
setblock ~26 ~117 ~87 dirt
setblock ~26 ~117 ~88 dirt
setblock ~26 ~117 ~89 dirt
setblock ~26 ~117 ~90 dirt
setblock ~26 ~117 ~91 dirt
setblock ~26 ~117 ~92 dirt
setblock ~26 ~117 ~93 dirt
setblock ~26 ~117 ~94 dirt
setblock ~26 ~117 ~95 dirt
setblock ~26 ~117 ~96 dirt
setblock ~26 ~117 ~98 dirt
setblock ~26 ~118 ~82 dirt
setblock ~26 ~118 ~83 dirt
setblock ~26 ~118 ~84 dirt
setblock ~26 ~118 ~85 dirt
setblock ~26 ~118 ~86 dirt
setblock ~26 ~118 ~87 dirt
setblock ~26 ~118 ~88 dirt
setblock ~26 ~118 ~89 dirt
setblock ~26 ~118 ~90 dirt
setblock ~26 ~118 ~91 dirt
setblock ~26 ~118 ~92 dirt
setblock ~26 ~118 ~93 dirt
setblock ~26 ~118 ~94 dirt
setblock ~26 ~118 ~95 dirt
setblock ~26 ~118 ~96 dirt
setblock ~26 ~118 ~97 dirt
setblock ~26 ~118 ~98 dirt
setblock ~26 ~118 ~99 dirt
setblock ~26 ~118 ~116 dirt
setblock ~26 ~118 ~119 dirt
setblock ~26 ~119 ~81 dirt
setblock ~26 ~119 ~82 dirt
setblock ~26 ~119 ~83 dirt
setblock ~26 ~119 ~84 dirt
setblock ~26 ~119 ~85 dirt
setblock ~26 ~119 ~86 dirt
setblock ~26 ~119 ~87 dirt
setblock ~26 ~119 ~88 dirt
setblock ~26 ~119 ~89 dirt
setblock ~26 ~119 ~90 dirt
setblock ~26 ~119 ~91 dirt
setblock ~26 ~119 ~92 dirt
setblock ~26 ~119 ~93 dirt
setblock ~26 ~119 ~94 dirt
setblock ~26 ~119 ~95 dirt
setblock ~26 ~119 ~96 dirt
setblock ~26 ~119 ~97 dirt
setblock ~26 ~119 ~98 dirt
setblock ~26 ~119 ~99 dirt
setblock ~26 ~119 ~113 dirt
setblock ~26 ~119 ~115 dirt
setblock ~26 ~119 ~116 dirt
setblock ~26 ~119 ~119 dirt
setblock ~26 ~119 ~120 dirt
setblock ~26 ~120 ~81 dirt
setblock ~26 ~120 ~82 dirt
setblock ~26 ~120 ~83 dirt
setblock ~26 ~120 ~84 dirt
setblock ~26 ~120 ~85 dirt
setblock ~26 ~120 ~86 dirt
setblock ~26 ~120 ~87 dirt
setblock ~26 ~120 ~88 dirt
setblock ~26 ~120 ~89 dirt
setblock ~26 ~120 ~90 dirt
setblock ~26 ~120 ~91 dirt
setblock ~26 ~120 ~92 dirt
setblock ~26 ~120 ~93 dirt
setblock ~26 ~120 ~94 dirt
setblock ~26 ~120 ~95 dirt
setblock ~26 ~120 ~96 dirt
setblock ~26 ~120 ~97 dirt
setblock ~26 ~120 ~98 dirt
setblock ~26 ~120 ~99 dirt
setblock ~26 ~120 ~100 dirt
setblock ~26 ~120 ~112 dirt
setblock ~26 ~120 ~113 dirt
setblock ~26 ~120 ~114 dirt
setblock ~26 ~120 ~115 dirt
setblock ~26 ~120 ~116 dirt
setblock ~26 ~120 ~117 dirt
setblock ~26 ~120 ~118 dirt
setblock ~26 ~120 ~119 dirt
setblock ~26 ~120 ~120 dirt
setblock ~26 ~120 ~121 dirt
setblock ~26 ~121 ~80 dirt
setblock ~26 ~121 ~81 dirt
setblock ~26 ~121 ~82 dirt
setblock ~26 ~121 ~83 dirt
setblock ~26 ~121 ~84 dirt
setblock ~26 ~121 ~85 dirt
setblock ~26 ~121 ~86 dirt
setblock ~26 ~121 ~87 dirt
setblock ~26 ~121 ~88 dirt
setblock ~26 ~121 ~89 dirt
setblock ~26 ~121 ~90 dirt
setblock ~26 ~121 ~91 dirt
setblock ~26 ~121 ~92 dirt
setblock ~26 ~121 ~93 dirt
setblock ~26 ~121 ~94 dirt
setblock ~26 ~121 ~95 dirt
setblock ~26 ~121 ~96 dirt
setblock ~26 ~121 ~97 dirt
setblock ~26 ~121 ~98 dirt
setblock ~26 ~121 ~99 dirt
setblock ~26 ~121 ~100 dirt
setblock ~26 ~121 ~101 dirt
setblock ~26 ~121 ~102 dirt
setblock ~26 ~121 ~111 dirt
setblock ~26 ~121 ~112 dirt
setblock ~26 ~121 ~113 dirt
setblock ~26 ~121 ~114 dirt
setblock ~26 ~121 ~115 dirt
setblock ~26 ~121 ~116 dirt
setblock ~26 ~121 ~117 dirt
setblock ~26 ~121 ~118 dirt
setblock ~26 ~121 ~119 dirt
setblock ~26 ~121 ~120 dirt
setblock ~26 ~121 ~121 dirt
setblock ~26 ~121 ~122 dirt
setblock ~26 ~122 ~80 dirt
setblock ~26 ~122 ~81 dirt
setblock ~26 ~122 ~82 dirt
setblock ~26 ~122 ~83 dirt
setblock ~26 ~122 ~84 dirt
setblock ~26 ~122 ~85 dirt
setblock ~26 ~122 ~86 dirt
setblock ~26 ~122 ~87 dirt
setblock ~26 ~122 ~88 dirt
setblock ~26 ~122 ~89 dirt
setblock ~26 ~122 ~90 dirt
setblock ~26 ~122 ~91 dirt
setblock ~26 ~122 ~92 dirt
setblock ~26 ~122 ~93 dirt
setblock ~26 ~122 ~94 dirt
setblock ~26 ~122 ~95 dirt
setblock ~26 ~122 ~96 dirt
setblock ~26 ~122 ~97 dirt
setblock ~26 ~122 ~98 dirt
setblock ~26 ~122 ~99 dirt
setblock ~26 ~122 ~100 dirt
setblock ~26 ~122 ~101 dirt
setblock ~26 ~122 ~102 dirt
setblock ~26 ~122 ~111 dirt
setblock ~26 ~122 ~112 dirt
setblock ~26 ~122 ~113 dirt
setblock ~26 ~122 ~114 dirt
setblock ~26 ~122 ~115 dirt
setblock ~26 ~122 ~116 dirt
setblock ~26 ~122 ~117 dirt
setblock ~26 ~122 ~118 dirt
setblock ~26 ~122 ~119 dirt
setblock ~26 ~122 ~120 dirt
setblock ~26 ~122 ~121 dirt
setblock ~26 ~122 ~122 dirt
setblock ~26 ~123 ~80 dirt
setblock ~26 ~123 ~81 dirt
setblock ~26 ~123 ~82 dirt
setblock ~26 ~123 ~83 dirt
setblock ~26 ~123 ~84 dirt
setblock ~26 ~123 ~85 dirt
setblock ~26 ~123 ~86 dirt
setblock ~26 ~123 ~87 dirt
setblock ~26 ~123 ~88 dirt
setblock ~26 ~123 ~89 dirt
setblock ~26 ~123 ~90 dirt
setblock ~26 ~123 ~91 dirt
setblock ~26 ~123 ~92 dirt
setblock ~26 ~123 ~93 dirt
setblock ~26 ~123 ~94 dirt
setblock ~26 ~123 ~95 dirt
setblock ~26 ~123 ~96 dirt
setblock ~26 ~123 ~97 dirt
setblock ~26 ~123 ~98 dirt
setblock ~26 ~123 ~99 dirt
setblock ~26 ~123 ~100 dirt
setblock ~26 ~123 ~101 dirt
setblock ~26 ~123 ~102 dirt
setblock ~26 ~123 ~111 dirt
setblock ~26 ~123 ~112 dirt
setblock ~26 ~123 ~113 dirt
setblock ~26 ~123 ~114 dirt
setblock ~26 ~123 ~115 dirt
setblock ~26 ~123 ~116 dirt
setblock ~26 ~123 ~117 dirt
setblock ~26 ~123 ~118 dirt
setblock ~26 ~123 ~119 dirt
setblock ~26 ~123 ~120 dirt
setblock ~26 ~123 ~121 dirt
setblock ~26 ~123 ~122 dirt
setblock ~26 ~124 ~80 grass_block
setblock ~26 ~124 ~81 grass_block
setblock ~26 ~124 ~82 grass_block
setblock ~26 ~124 ~83 grass_block
setblock ~26 ~124 ~84 grass_block
setblock ~26 ~124 ~85 grass_block
setblock ~26 ~124 ~86 grass_block
setblock ~26 ~124 ~87 grass_block
setblock ~26 ~124 ~88 grass_block
setblock ~26 ~124 ~89 grass_block
setblock ~26 ~124 ~90 grass_block
setblock ~26 ~124 ~91 grass_block
setblock ~26 ~124 ~92 dirt
setblock ~26 ~124 ~93 dirt
setblock ~26 ~124 ~94 dirt
setblock ~26 ~124 ~95 dirt
setblock ~26 ~124 ~96 dirt
setblock ~26 ~124 ~97 dirt
setblock ~26 ~124 ~98 dirt
setblock ~26 ~124 ~99 dirt
setblock ~26 ~124 ~100 dirt
setblock ~26 ~124 ~101 dirt
setblock ~26 ~124 ~102 dirt
setblock ~26 ~124 ~111 dirt
setblock ~26 ~124 ~112 dirt
setblock ~26 ~124 ~113 dirt
setblock ~26 ~124 ~114 dirt
setblock ~26 ~124 ~115 dirt
setblock ~26 ~124 ~116 dirt
setblock ~26 ~124 ~117 dirt
setblock ~26 ~124 ~118 dirt
setblock ~26 ~124 ~119 dirt
setblock ~26 ~124 ~120 dirt
setblock ~26 ~124 ~121 dirt
setblock ~26 ~124 ~122 dirt
setblock ~26 ~125 ~81 short_grass
setblock ~26 ~125 ~86 short_grass
setblock ~26 ~125 ~87 short_grass
setblock ~26 ~125 ~92 grass_block
setblock ~26 ~125 ~93 grass_block
setblock ~26 ~125 ~94 grass_block
setblock ~26 ~125 ~95 dirt
setblock ~26 ~125 ~96 dirt
setblock ~26 ~125 ~97 dirt
setblock ~26 ~125 ~98 dirt
setblock ~26 ~125 ~99 dirt
setblock ~26 ~125 ~100 dirt
setblock ~26 ~125 ~101 dirt
setblock ~26 ~125 ~102 dirt
setblock ~26 ~125 ~111 grass_block
setblock ~26 ~125 ~112 grass_block
setblock ~26 ~125 ~113 grass_block
setblock ~26 ~125 ~114 grass_block
setblock ~26 ~125 ~115 grass_block
setblock ~26 ~125 ~116 dirt
setblock ~26 ~125 ~117 dirt
setblock ~26 ~125 ~118 dirt
setblock ~26 ~125 ~119 dirt
setblock ~26 ~125 ~120 dirt
setblock ~26 ~125 ~121 dirt
setblock ~26 ~125 ~122 dirt
setblock ~26 ~126 ~92 short_grass
setblock ~26 ~126 ~93 fern
setblock ~26 ~126 ~95 grass_block
setblock ~26 ~126 ~96 grass_block
setblock ~26 ~126 ~97 grass_block
setblock ~26 ~126 ~98 dirt
setblock ~26 ~126 ~99 dirt
setblock ~26 ~126 ~100 dirt
setblock ~26 ~126 ~101 dirt
setblock ~26 ~126 ~102 dirt
setblock ~26 ~126 ~112 poppy
setblock ~26 ~126 ~114 short_grass
setblock ~26 ~126 ~116 grass_block
setblock ~26 ~126 ~117 grass_block
setblock ~26 ~126 ~118 grass_block
setblock ~26 ~126 ~119 dirt
setblock ~26 ~126 ~120 dirt
setblock ~26 ~126 ~121 dirt
setblock ~26 ~126 ~122 dirt
setblock ~26 ~127 ~81 oak_leaves[persistent=true]
setblock ~26 ~127 ~82 oak_leaves[persistent=true]
setblock ~26 ~127 ~83 oak_leaves[persistent=true]
setblock ~26 ~127 ~84 jungle_leaves[persistent=true]
setblock ~26 ~127 ~98 grass_block
setblock ~26 ~127 ~99 grass_block
setblock ~26 ~127 ~100 dirt
setblock ~26 ~127 ~101 grass_block
setblock ~26 ~127 ~102 grass_block
setblock ~26 ~127 ~117 short_grass
setblock ~26 ~127 ~119 grass_block
setblock ~26 ~127 ~120 grass_block
setblock ~26 ~127 ~121 grass_block
setblock ~26 ~127 ~122 grass_block
setblock ~26 ~128 ~81 oak_leaves[persistent=true]
setblock ~26 ~128 ~82 oak_leaves[persistent=true]
setblock ~26 ~128 ~83 oak_leaves[persistent=true]
setblock ~26 ~128 ~85 oak_leaves[persistent=true]
setblock ~26 ~128 ~98 fern
setblock ~26 ~128 ~101 jungle_leaves[persistent=true]
setblock ~26 ~128 ~102 oak_leaves[persistent=true]
setblock ~26 ~128 ~103 oak_leaves[persistent=true]
setblock ~26 ~128 ~122 short_grass
setblock ~26 ~129 ~81 jungle_leaves[persistent=true]
setblock ~26 ~129 ~82 oak_leaves[persistent=true]
setblock ~26 ~129 ~83 oak_leaves[persistent=true]
setblock ~26 ~129 ~84 oak_leaves[persistent=true]
setblock ~26 ~129 ~100 oak_leaves[persistent=true]
setblock ~26 ~129 ~102 oak_leaves[persistent=true]
setblock ~26 ~129 ~103 oak_leaves[persistent=true]
setblock ~26 ~130 ~81 oak_leaves[persistent=true]
setblock ~26 ~130 ~82 oak_leaves[persistent=true]
setblock ~26 ~130 ~83 oak_wood
setblock ~26 ~130 ~84 oak_wood
setblock ~26 ~130 ~92 jungle_leaves[persistent=true]
setblock ~26 ~130 ~94 jungle_leaves[persistent=true]
setblock ~26 ~130 ~96 oak_leaves[persistent=true]
setblock ~26 ~130 ~97 oak_leaves[persistent=true]
setblock ~26 ~130 ~99 oak_leaves[persistent=true]
setblock ~26 ~130 ~100 oak_leaves[persistent=true]
setblock ~26 ~130 ~101 jungle_leaves[persistent=true]
setblock ~26 ~130 ~102 oak_leaves[persistent=true]
setblock ~26 ~131 ~82 oak_leaves[persistent=true]
setblock ~26 ~131 ~83 oak_leaves[persistent=true]
setblock ~26 ~131 ~85 oak_leaves[persistent=true]
setblock ~26 ~131 ~91 jungle_leaves[persistent=true]
setblock ~26 ~131 ~92 oak_leaves[persistent=true]
setblock ~26 ~131 ~95 oak_leaves[persistent=true]
setblock ~26 ~131 ~96 oak_leaves[persistent=true]
setblock ~26 ~131 ~97 oak_leaves[persistent=true]
setblock ~26 ~131 ~98 jungle_leaves[persistent=true]
setblock ~26 ~131 ~99 oak_leaves[persistent=true]
setblock ~26 ~131 ~100 oak_leaves[persistent=true]
setblock ~26 ~131 ~102 oak_wood
setblock ~26 ~131 ~103 oak_leaves[persistent=true]
setblock ~26 ~132 ~89 oak_leaves[persistent=true]
setblock ~26 ~132 ~90 oak_leaves[persistent=true]
setblock ~26 ~132 ~91 oak_leaves[persistent=true]
setblock ~26 ~132 ~93 jungle_leaves[persistent=true]
setblock ~26 ~132 ~94 oak_leaves[persistent=true]
setblock ~26 ~132 ~95 oak_leaves[persistent=true]
setblock ~26 ~132 ~96 oak_leaves[persistent=true]
setblock ~26 ~132 ~98 oak_wood
setblock ~26 ~132 ~99 oak_wood
setblock ~26 ~132 ~100 oak_leaves[persistent=true]
setblock ~26 ~132 ~101 oak_leaves[persistent=true]
setblock ~26 ~132 ~102 oak_leaves[persistent=true]
setblock ~26 ~132 ~103 jungle_leaves[persistent=true]
setblock ~26 ~132 ~104 oak_leaves[persistent=true]
setblock ~26 ~133 ~88 oak_leaves[persistent=true]
setblock ~26 ~133 ~89 oak_leaves[persistent=true]
setblock ~26 ~133 ~90 oak_leaves[persistent=true]
setblock ~26 ~133 ~91 oak_leaves[persistent=true]
setblock ~26 ~133 ~92 oak_leaves[persistent=true]
setblock ~26 ~133 ~93 oak_leaves[persistent=true]
setblock ~26 ~133 ~94 oak_leaves[persistent=true]
setblock ~26 ~133 ~95 oak_leaves[persistent=true]
setblock ~26 ~133 ~96 oak_leaves[persistent=true]
setblock ~26 ~133 ~97 oak_leaves[persistent=true]
setblock ~26 ~133 ~98 oak_wood
setblock ~26 ~133 ~100 oak_leaves[persistent=true]
setblock ~26 ~133 ~101 oak_leaves[persistent=true]
setblock ~26 ~133 ~102 oak_leaves[persistent=true]
setblock ~26 ~133 ~103 jungle_leaves[persistent=true]
setblock ~26 ~133 ~104 oak_leaves[persistent=true]
setblock ~26 ~134 ~89 oak_leaves[persistent=true]
setblock ~26 ~134 ~93 jungle_leaves[persistent=true]
setblock ~26 ~134 ~94 oak_leaves[persistent=true]
setblock ~26 ~134 ~97 oak_leaves[persistent=true]
setblock ~26 ~134 ~99 oak_leaves[persistent=true]
setblock ~26 ~134 ~100 oak_wood
setblock ~26 ~135 ~88 oak_leaves[persistent=true]
setblock ~26 ~135 ~90 jungle_leaves[persistent=true]
setblock ~26 ~135 ~91 oak_wood
setblock ~26 ~135 ~93 oak_leaves[persistent=true]
setblock ~26 ~135 ~95 oak_leaves[persistent=true]
setblock ~26 ~135 ~98 oak_leaves[persistent=true]
setblock ~26 ~135 ~99 oak_leaves[persistent=true]
setblock ~26 ~135 ~100 oak_wood
setblock ~26 ~136 ~89 jungle_leaves[persistent=true]
setblock ~26 ~136 ~92 oak_leaves[persistent=true]
setblock ~26 ~136 ~93 oak_leaves[persistent=true]
setblock ~26 ~136 ~94 oak_leaves[persistent=true]
setblock ~26 ~136 ~95 oak_leaves[persistent=true]
setblock ~26 ~136 ~96 oak_leaves[persistent=true]
setblock ~26 ~136 ~97 jungle_leaves[persistent=true]
setblock ~26 ~136 ~98 jungle_leaves[persistent=true]
setblock ~26 ~136 ~99 oak_leaves[persistent=true]
setblock ~26 ~136 ~102 oak_leaves[persistent=true]
setblock ~26 ~137 ~93 oak_leaves[persistent=true]
setblock ~26 ~137 ~94 jungle_leaves[persistent=true]
setblock ~26 ~137 ~96 oak_leaves[persistent=true]
setblock ~26 ~137 ~97 oak_leaves[persistent=true]
setblock ~26 ~137 ~98 oak_leaves[persistent=true]
setblock ~26 ~137 ~99 oak_leaves[persistent=true]
setblock ~26 ~137 ~101 oak_leaves[persistent=true]
setblock ~26 ~137 ~102 oak_leaves[persistent=true]
setblock ~26 ~138 ~93 oak_leaves[persistent=true]
setblock ~26 ~138 ~95 oak_leaves[persistent=true]
setblock ~26 ~138 ~96 jungle_leaves[persistent=true]
setblock ~26 ~138 ~97 oak_leaves[persistent=true]
setblock ~26 ~138 ~98 oak_leaves[persistent=true]
setblock ~26 ~138 ~99 jungle_leaves[persistent=true]
setblock ~26 ~138 ~100 oak_leaves[persistent=true]
setblock ~26 ~139 ~93 oak_leaves[persistent=true]
setblock ~26 ~139 ~95 jungle_leaves[persistent=true]
setblock ~26 ~139 ~96 jungle_leaves[persistent=true]
setblock ~26 ~139 ~97 oak_leaves[persistent=true]
setblock ~27 ~106 ~87 dirt
setblock ~27 ~107 ~86 dirt
setblock ~27 ~107 ~87 dirt
setblock ~27 ~107 ~88 dirt
setblock ~27 ~108 ~86 dirt
setblock ~27 ~108 ~87 dirt
setblock ~27 ~108 ~88 dirt
setblock ~27 ~108 ~89 dirt
setblock ~27 ~109 ~86 dirt
setblock ~27 ~109 ~87 dirt
setblock ~27 ~109 ~88 dirt
setblock ~27 ~109 ~89 dirt
setblock ~27 ~109 ~90 dirt
setblock ~27 ~110 ~86 dirt
setblock ~27 ~110 ~87 dirt
setblock ~27 ~110 ~88 dirt
setblock ~27 ~110 ~89 dirt
setblock ~27 ~110 ~90 dirt
setblock ~27 ~111 ~85 dirt
setblock ~27 ~111 ~86 dirt
setblock ~27 ~111 ~87 dirt
setblock ~27 ~111 ~88 dirt
setblock ~27 ~111 ~89 dirt
setblock ~27 ~111 ~90 dirt
setblock ~27 ~111 ~91 dirt
setblock ~27 ~112 ~84 dirt
setblock ~27 ~112 ~85 dirt
setblock ~27 ~112 ~86 dirt
setblock ~27 ~112 ~87 dirt
setblock ~27 ~112 ~88 dirt
setblock ~27 ~112 ~89 dirt
setblock ~27 ~112 ~90 dirt
setblock ~27 ~112 ~91 dirt
setblock ~27 ~113 ~84 dirt
setblock ~27 ~113 ~85 dirt
setblock ~27 ~113 ~86 dirt
setblock ~27 ~113 ~87 dirt
setblock ~27 ~113 ~88 dirt
setblock ~27 ~113 ~89 dirt
setblock ~27 ~113 ~90 dirt
setblock ~27 ~113 ~91 dirt
setblock ~27 ~113 ~92 dirt
setblock ~27 ~114 ~83 dirt
setblock ~27 ~114 ~84 dirt
setblock ~27 ~114 ~85 dirt
setblock ~27 ~114 ~86 dirt
setblock ~27 ~114 ~87 dirt
setblock ~27 ~114 ~88 dirt
setblock ~27 ~114 ~89 dirt
setblock ~27 ~114 ~90 dirt
setblock ~27 ~114 ~91 dirt
setblock ~27 ~114 ~92 dirt
setblock ~27 ~114 ~93 dirt
setblock ~27 ~114 ~97 dirt
setblock ~27 ~115 ~83 dirt
setblock ~27 ~115 ~84 dirt
setblock ~27 ~115 ~85 dirt
setblock ~27 ~115 ~86 dirt
setblock ~27 ~115 ~87 dirt
setblock ~27 ~115 ~88 dirt
setblock ~27 ~115 ~89 dirt
setblock ~27 ~115 ~90 dirt
setblock ~27 ~115 ~91 dirt
setblock ~27 ~115 ~92 dirt
setblock ~27 ~115 ~93 dirt
setblock ~27 ~115 ~95 dirt
setblock ~27 ~115 ~97 dirt
setblock ~27 ~116 ~82 dirt
setblock ~27 ~116 ~83 dirt
setblock ~27 ~116 ~84 dirt
setblock ~27 ~116 ~85 dirt
setblock ~27 ~116 ~86 dirt
setblock ~27 ~116 ~87 dirt
setblock ~27 ~116 ~88 dirt
setblock ~27 ~116 ~89 dirt
setblock ~27 ~116 ~90 dirt
setblock ~27 ~116 ~91 dirt
setblock ~27 ~116 ~92 dirt
setblock ~27 ~116 ~93 dirt
setblock ~27 ~116 ~94 dirt
setblock ~27 ~116 ~95 dirt
setblock ~27 ~116 ~96 dirt
setblock ~27 ~116 ~97 dirt
setblock ~27 ~116 ~98 dirt
setblock ~27 ~116 ~117 dirt
setblock ~27 ~116 ~119 dirt
setblock ~27 ~117 ~82 dirt
setblock ~27 ~117 ~83 dirt
setblock ~27 ~117 ~84 dirt
setblock ~27 ~117 ~85 dirt
setblock ~27 ~117 ~86 dirt
setblock ~27 ~117 ~87 dirt
setblock ~27 ~117 ~88 dirt
setblock ~27 ~117 ~89 dirt
setblock ~27 ~117 ~90 dirt
setblock ~27 ~117 ~91 dirt
setblock ~27 ~117 ~92 dirt
setblock ~27 ~117 ~93 dirt
setblock ~27 ~117 ~94 dirt
setblock ~27 ~117 ~95 dirt
setblock ~27 ~117 ~96 dirt
setblock ~27 ~117 ~97 dirt
setblock ~27 ~117 ~98 dirt
setblock ~27 ~117 ~99 dirt
setblock ~27 ~117 ~111 dirt
setblock ~27 ~117 ~116 dirt
setblock ~27 ~117 ~117 dirt
setblock ~27 ~117 ~118 dirt
setblock ~27 ~117 ~119 dirt
setblock ~27 ~117 ~120 dirt
setblock ~27 ~118 ~80 dirt
setblock ~27 ~118 ~81 dirt
setblock ~27 ~118 ~82 dirt
setblock ~27 ~118 ~83 dirt
setblock ~27 ~118 ~84 dirt
setblock ~27 ~118 ~85 dirt
setblock ~27 ~118 ~86 dirt
setblock ~27 ~118 ~87 dirt
setblock ~27 ~118 ~88 dirt
setblock ~27 ~118 ~89 dirt
setblock ~27 ~118 ~90 dirt
setblock ~27 ~118 ~91 dirt
setblock ~27 ~118 ~92 dirt
setblock ~27 ~118 ~93 dirt
setblock ~27 ~118 ~94 dirt
setblock ~27 ~118 ~95 dirt
setblock ~27 ~118 ~96 dirt
setblock ~27 ~118 ~97 dirt
setblock ~27 ~118 ~98 dirt
setblock ~27 ~118 ~99 dirt
setblock ~27 ~118 ~100 dirt
setblock ~27 ~118 ~111 dirt
setblock ~27 ~118 ~113 dirt
setblock ~27 ~118 ~115 dirt
setblock ~27 ~118 ~116 dirt
setblock ~27 ~118 ~117 dirt
setblock ~27 ~118 ~118 dirt
setblock ~27 ~118 ~119 dirt
setblock ~27 ~118 ~120 dirt
setblock ~27 ~119 ~79 dirt
setblock ~27 ~119 ~80 dirt
setblock ~27 ~119 ~81 dirt
setblock ~27 ~119 ~82 dirt
setblock ~27 ~119 ~83 dirt
setblock ~27 ~119 ~84 dirt
setblock ~27 ~119 ~85 dirt
setblock ~27 ~119 ~86 dirt
setblock ~27 ~119 ~87 dirt
setblock ~27 ~119 ~88 dirt
setblock ~27 ~119 ~89 dirt
setblock ~27 ~119 ~90 dirt
setblock ~27 ~119 ~91 dirt
setblock ~27 ~119 ~92 dirt
setblock ~27 ~119 ~93 dirt
setblock ~27 ~119 ~94 dirt
setblock ~27 ~119 ~95 dirt
setblock ~27 ~119 ~96 dirt
setblock ~27 ~119 ~97 dirt
setblock ~27 ~119 ~98 dirt
setblock ~27 ~119 ~99 dirt
setblock ~27 ~119 ~100 dirt
setblock ~27 ~119 ~110 dirt
setblock ~27 ~119 ~111 dirt
setblock ~27 ~119 ~112 dirt
setblock ~27 ~119 ~113 dirt
setblock ~27 ~119 ~114 dirt
setblock ~27 ~119 ~115 dirt
setblock ~27 ~119 ~116 dirt
setblock ~27 ~119 ~117 dirt
setblock ~27 ~119 ~118 dirt
setblock ~27 ~119 ~119 dirt
setblock ~27 ~119 ~120 dirt
setblock ~27 ~119 ~121 dirt
setblock ~27 ~120 ~78 dirt
setblock ~27 ~120 ~79 dirt
setblock ~27 ~120 ~80 dirt
setblock ~27 ~120 ~81 dirt
setblock ~27 ~120 ~82 dirt
setblock ~27 ~120 ~83 dirt
setblock ~27 ~120 ~84 dirt
setblock ~27 ~120 ~85 dirt
setblock ~27 ~120 ~86 dirt
setblock ~27 ~120 ~87 dirt
setblock ~27 ~120 ~88 dirt
setblock ~27 ~120 ~89 dirt
setblock ~27 ~120 ~90 dirt
setblock ~27 ~120 ~91 dirt
setblock ~27 ~120 ~92 dirt
setblock ~27 ~120 ~93 dirt
setblock ~27 ~120 ~94 dirt
setblock ~27 ~120 ~95 dirt
setblock ~27 ~120 ~96 dirt
setblock ~27 ~120 ~97 dirt
setblock ~27 ~120 ~98 dirt
setblock ~27 ~120 ~99 dirt
setblock ~27 ~120 ~100 dirt
setblock ~27 ~120 ~101 dirt
setblock ~27 ~120 ~102 dirt
setblock ~27 ~120 ~109 dirt
setblock ~27 ~120 ~110 dirt
setblock ~27 ~120 ~111 dirt
setblock ~27 ~120 ~112 dirt
setblock ~27 ~120 ~113 dirt
setblock ~27 ~120 ~114 dirt
setblock ~27 ~120 ~115 dirt
setblock ~27 ~120 ~116 dirt
setblock ~27 ~120 ~117 dirt
setblock ~27 ~120 ~118 dirt
setblock ~27 ~120 ~119 dirt
setblock ~27 ~120 ~120 dirt
setblock ~27 ~120 ~121 dirt
setblock ~27 ~120 ~122 dirt
setblock ~27 ~121 ~78 dirt
setblock ~27 ~121 ~79 dirt
setblock ~27 ~121 ~80 dirt
setblock ~27 ~121 ~81 dirt
setblock ~27 ~121 ~82 dirt
setblock ~27 ~121 ~83 dirt
setblock ~27 ~121 ~84 dirt
setblock ~27 ~121 ~85 dirt
setblock ~27 ~121 ~86 dirt
setblock ~27 ~121 ~87 dirt
setblock ~27 ~121 ~88 dirt
setblock ~27 ~121 ~89 dirt
setblock ~27 ~121 ~90 dirt
setblock ~27 ~121 ~91 dirt
setblock ~27 ~121 ~92 dirt
setblock ~27 ~121 ~93 dirt
setblock ~27 ~121 ~94 dirt
setblock ~27 ~121 ~95 dirt
setblock ~27 ~121 ~96 dirt
setblock ~27 ~121 ~97 dirt
setblock ~27 ~121 ~98 dirt
setblock ~27 ~121 ~99 dirt
setblock ~27 ~121 ~100 dirt
setblock ~27 ~121 ~101 dirt
setblock ~27 ~121 ~102 dirt
setblock ~27 ~121 ~103 dirt
setblock ~27 ~121 ~109 dirt
setblock ~27 ~121 ~110 dirt
setblock ~27 ~121 ~111 dirt
setblock ~27 ~121 ~112 dirt
setblock ~27 ~121 ~113 dirt
setblock ~27 ~121 ~114 dirt
setblock ~27 ~121 ~115 dirt
setblock ~27 ~121 ~116 dirt
setblock ~27 ~121 ~117 dirt
setblock ~27 ~121 ~118 dirt
setblock ~27 ~121 ~119 dirt
setblock ~27 ~121 ~120 dirt
setblock ~27 ~121 ~121 dirt
setblock ~27 ~121 ~122 dirt
setblock ~27 ~121 ~123 dirt
setblock ~27 ~122 ~78 dirt
setblock ~27 ~122 ~79 dirt
setblock ~27 ~122 ~80 dirt
setblock ~27 ~122 ~81 dirt
setblock ~27 ~122 ~82 dirt
setblock ~27 ~122 ~83 dirt
setblock ~27 ~122 ~84 dirt
setblock ~27 ~122 ~85 dirt
setblock ~27 ~122 ~86 dirt
setblock ~27 ~122 ~87 dirt
setblock ~27 ~122 ~88 dirt
setblock ~27 ~122 ~89 dirt
setblock ~27 ~122 ~90 dirt
setblock ~27 ~122 ~91 dirt
setblock ~27 ~122 ~92 dirt
setblock ~27 ~122 ~93 dirt
setblock ~27 ~122 ~94 dirt
setblock ~27 ~122 ~95 dirt
setblock ~27 ~122 ~96 dirt
setblock ~27 ~122 ~97 dirt
setblock ~27 ~122 ~98 dirt
setblock ~27 ~122 ~99 dirt
setblock ~27 ~122 ~100 dirt
setblock ~27 ~122 ~101 dirt
setblock ~27 ~122 ~102 dirt
setblock ~27 ~122 ~103 dirt
setblock ~27 ~122 ~109 dirt
setblock ~27 ~122 ~110 dirt
setblock ~27 ~122 ~111 dirt
setblock ~27 ~122 ~112 dirt
setblock ~27 ~122 ~113 dirt
setblock ~27 ~122 ~114 dirt
setblock ~27 ~122 ~115 dirt
setblock ~27 ~122 ~116 dirt
setblock ~27 ~122 ~117 dirt
setblock ~27 ~122 ~118 dirt
setblock ~27 ~122 ~119 dirt
setblock ~27 ~122 ~120 dirt
setblock ~27 ~122 ~121 dirt
setblock ~27 ~122 ~122 dirt
setblock ~27 ~122 ~123 dirt
setblock ~27 ~123 ~78 dirt
setblock ~27 ~123 ~79 dirt
setblock ~27 ~123 ~80 dirt
setblock ~27 ~123 ~81 dirt
setblock ~27 ~123 ~82 dirt
setblock ~27 ~123 ~83 dirt
setblock ~27 ~123 ~84 dirt
setblock ~27 ~123 ~85 dirt
setblock ~27 ~123 ~86 dirt
setblock ~27 ~123 ~87 dirt
setblock ~27 ~123 ~88 dirt
setblock ~27 ~123 ~89 grass_block
setblock ~27 ~123 ~90 grass_block
setblock ~27 ~123 ~91 dirt
setblock ~27 ~123 ~92 dirt
setblock ~27 ~123 ~93 dirt
setblock ~27 ~123 ~94 dirt
setblock ~27 ~123 ~95 dirt
setblock ~27 ~123 ~96 dirt
setblock ~27 ~123 ~97 dirt
setblock ~27 ~123 ~98 dirt
setblock ~27 ~123 ~99 dirt
setblock ~27 ~123 ~100 dirt
setblock ~27 ~123 ~101 dirt
setblock ~27 ~123 ~102 dirt
setblock ~27 ~123 ~103 dirt
setblock ~27 ~123 ~109 dirt
setblock ~27 ~123 ~110 dirt
setblock ~27 ~123 ~111 dirt
setblock ~27 ~123 ~112 dirt
setblock ~27 ~123 ~113 dirt
setblock ~27 ~123 ~114 dirt
setblock ~27 ~123 ~115 dirt
setblock ~27 ~123 ~116 dirt
setblock ~27 ~123 ~117 dirt
setblock ~27 ~123 ~118 dirt
setblock ~27 ~123 ~119 dirt
setblock ~27 ~123 ~120 dirt
setblock ~27 ~123 ~121 dirt
setblock ~27 ~123 ~122 dirt
setblock ~27 ~123 ~123 dirt
setblock ~27 ~124 ~78 grass_block
setblock ~27 ~124 ~79 grass_block
setblock ~27 ~124 ~80 grass_block
setblock ~27 ~124 ~81 grass_block
setblock ~27 ~124 ~82 grass_block
setblock ~27 ~124 ~83 grass_block
setblock ~27 ~124 ~84 grass_block
setblock ~27 ~124 ~85 grass_block
setblock ~27 ~124 ~86 grass_block
setblock ~27 ~124 ~87 grass_block
setblock ~27 ~124 ~88 grass_block
setblock ~27 ~124 ~91 grass_block
setblock ~27 ~124 ~92 grass_block
setblock ~27 ~124 ~93 grass_block
setblock ~27 ~124 ~94 dirt
setblock ~27 ~124 ~95 dirt
setblock ~27 ~124 ~96 dirt
setblock ~27 ~124 ~97 dirt
setblock ~27 ~124 ~98 dirt
setblock ~27 ~124 ~99 dirt
setblock ~27 ~124 ~100 dirt
setblock ~27 ~124 ~101 dirt
setblock ~27 ~124 ~102 dirt
setblock ~27 ~124 ~103 dirt
setblock ~27 ~124 ~109 dirt
setblock ~27 ~124 ~110 grass_block
setblock ~27 ~124 ~111 grass_block
setblock ~27 ~124 ~112 dirt
setblock ~27 ~124 ~113 dirt
setblock ~27 ~124 ~114 dirt
setblock ~27 ~124 ~115 dirt
setblock ~27 ~124 ~116 dirt
setblock ~27 ~124 ~117 dirt
setblock ~27 ~124 ~118 dirt
setblock ~27 ~124 ~119 dirt
setblock ~27 ~124 ~120 dirt
setblock ~27 ~124 ~121 dirt
setblock ~27 ~124 ~122 dirt
setblock ~27 ~124 ~123 dirt
setblock ~27 ~125 ~81 short_grass
setblock ~27 ~125 ~83 fern
setblock ~27 ~125 ~86 poppy
setblock ~27 ~125 ~87 short_grass
setblock ~27 ~125 ~91 poppy
setblock ~27 ~125 ~94 grass_block
setblock ~27 ~125 ~95 grass_block
setblock ~27 ~125 ~96 dirt
setblock ~27 ~125 ~97 dirt
setblock ~27 ~125 ~98 dirt
setblock ~27 ~125 ~99 dirt
setblock ~27 ~125 ~100 dirt
setblock ~27 ~125 ~101 dirt
setblock ~27 ~125 ~102 dirt
setblock ~27 ~125 ~103 dirt
setblock ~27 ~125 ~109 grass_block
setblock ~27 ~125 ~112 grass_block
setblock ~27 ~125 ~113 grass_block
setblock ~27 ~125 ~114 grass_block
setblock ~27 ~125 ~115 grass_block
setblock ~27 ~125 ~116 grass_block
setblock ~27 ~125 ~117 dirt
setblock ~27 ~125 ~118 dirt
setblock ~27 ~125 ~119 dirt
setblock ~27 ~125 ~120 dirt
setblock ~27 ~125 ~121 dirt
setblock ~27 ~125 ~122 dirt
setblock ~27 ~125 ~123 dirt
setblock ~27 ~126 ~94 short_grass
setblock ~27 ~126 ~96 grass_block
setblock ~27 ~126 ~97 grass_block
setblock ~27 ~126 ~98 dirt
setblock ~27 ~126 ~99 dirt
setblock ~27 ~126 ~100 dirt
setblock ~27 ~126 ~101 dirt
setblock ~27 ~126 ~102 dirt
setblock ~27 ~126 ~103 grass_block
setblock ~27 ~126 ~109 short_grass
setblock ~27 ~126 ~117 grass_block
setblock ~27 ~126 ~118 grass_block
setblock ~27 ~126 ~119 dirt
setblock ~27 ~126 ~120 dirt
setblock ~27 ~126 ~121 dirt
setblock ~27 ~126 ~122 dirt
setblock ~27 ~126 ~123 dirt
setblock ~27 ~127 ~98 grass_block
setblock ~27 ~127 ~99 grass_block
setblock ~27 ~127 ~100 grass_block
setblock ~27 ~127 ~101 grass_block
setblock ~27 ~127 ~102 grass_block
setblock ~27 ~127 ~119 grass_block
setblock ~27 ~127 ~120 grass_block
setblock ~27 ~127 ~121 grass_block
setblock ~27 ~127 ~122 grass_block
setblock ~27 ~127 ~123 grass_block
setblock ~27 ~128 ~81 jungle_leaves[persistent=true]
setblock ~27 ~128 ~82 jungle_leaves[persistent=true]
setblock ~27 ~128 ~83 jungle_leaves[persistent=true]
setblock ~27 ~128 ~84 oak_leaves[persistent=true]
setblock ~27 ~128 ~85 oak_leaves[persistent=true]
setblock ~27 ~128 ~100 jungle_leaves[persistent=true]
setblock ~27 ~128 ~101 oak_leaves[persistent=true]
setblock ~27 ~128 ~102 oak_leaves[persistent=true]
setblock ~27 ~128 ~103 oak_leaves[persistent=true]
setblock ~27 ~128 ~104 oak_leaves[persistent=true]
setblock ~27 ~129 ~81 oak_leaves[persistent=true]
setblock ~27 ~129 ~82 oak_leaves[persistent=true]
setblock ~27 ~129 ~83 oak_leaves[persistent=true]
setblock ~27 ~129 ~85 oak_leaves[persistent=true]
setblock ~27 ~129 ~86 oak_leaves[persistent=true]
setblock ~27 ~129 ~100 jungle_leaves[persistent=true]
setblock ~27 ~129 ~101 oak_leaves[persistent=true]
setblock ~27 ~129 ~102 oak_leaves[persistent=true]
setblock ~27 ~129 ~103 oak_leaves[persistent=true]
setblock ~27 ~130 ~82 oak_leaves[persistent=true]
setblock ~27 ~130 ~83 oak_leaves[persistent=true]
setblock ~27 ~130 ~84 oak_wood
setblock ~27 ~130 ~85 oak_leaves[persistent=true]
setblock ~27 ~130 ~86 oak_leaves[persistent=true]
setblock ~27 ~130 ~92 oak_leaves[persistent=true]
setblock ~27 ~130 ~94 oak_leaves[persistent=true]
setblock ~27 ~130 ~95 oak_leaves[persistent=true]
setblock ~27 ~130 ~96 jungle_leaves[persistent=true]
setblock ~27 ~130 ~97 oak_leaves[persistent=true]
setblock ~27 ~130 ~100 oak_leaves[persistent=true]
setblock ~27 ~130 ~101 oak_leaves[persistent=true]
setblock ~27 ~130 ~102 jungle_leaves[persistent=true]
setblock ~27 ~130 ~103 jungle_leaves[persistent=true]
setblock ~27 ~130 ~104 oak_leaves[persistent=true]
setblock ~27 ~131 ~81 oak_leaves[persistent=true]
setblock ~27 ~131 ~82 oak_leaves[persistent=true]
setblock ~27 ~131 ~83 jungle_leaves[persistent=true]
setblock ~27 ~131 ~84 oak_leaves[persistent=true]
setblock ~27 ~131 ~85 jungle_leaves[persistent=true]
setblock ~27 ~131 ~91 oak_leaves[persistent=true]
setblock ~27 ~131 ~97 oak_leaves[persistent=true]
setblock ~27 ~131 ~98 oak_leaves[persistent=true]
setblock ~27 ~131 ~99 oak_leaves[persistent=true]
setblock ~27 ~131 ~100 jungle_leaves[persistent=true]
setblock ~27 ~131 ~101 oak_leaves[persistent=true]
setblock ~27 ~131 ~103 oak_wood
setblock ~27 ~131 ~105 oak_leaves[persistent=true]
setblock ~27 ~132 ~82 oak_leaves[persistent=true]
setblock ~27 ~132 ~84 oak_leaves[persistent=true]
setblock ~27 ~132 ~86 oak_leaves[persistent=true]
setblock ~27 ~132 ~88 jungle_leaves[persistent=true]
setblock ~27 ~132 ~90 oak_leaves[persistent=true]
setblock ~27 ~132 ~92 oak_leaves[persistent=true]
setblock ~27 ~132 ~93 jungle_leaves[persistent=true]
setblock ~27 ~132 ~95 jungle_leaves[persistent=true]
setblock ~27 ~132 ~96 oak_wood
setblock ~27 ~132 ~97 oak_wood
setblock ~27 ~132 ~98 oak_wood
setblock ~27 ~132 ~99 jungle_leaves[persistent=true]
setblock ~27 ~132 ~100 oak_leaves[persistent=true]
setblock ~27 ~132 ~101 oak_leaves[persistent=true]
setblock ~27 ~132 ~103 oak_wood
setblock ~27 ~132 ~104 oak_leaves[persistent=true]
setblock ~27 ~132 ~105 jungle_leaves[persistent=true]
setblock ~27 ~133 ~88 oak_leaves[persistent=true]
setblock ~27 ~133 ~89 oak_leaves[persistent=true]
setblock ~27 ~133 ~90 oak_leaves[persistent=true]
setblock ~27 ~133 ~91 oak_leaves[persistent=true]
setblock ~27 ~133 ~93 oak_leaves[persistent=true]
setblock ~27 ~133 ~95 oak_leaves[persistent=true]
setblock ~27 ~133 ~96 oak_leaves[persistent=true]
setblock ~27 ~133 ~97 oak_leaves[persistent=true]
setblock ~27 ~133 ~98 oak_leaves[persistent=true]
setblock ~27 ~133 ~99 oak_wood
setblock ~27 ~133 ~100 jungle_leaves[persistent=true]
setblock ~27 ~133 ~101 jungle_leaves[persistent=true]
setblock ~27 ~133 ~102 oak_leaves[persistent=true]
setblock ~27 ~133 ~103 oak_leaves[persistent=true]
setblock ~27 ~133 ~104 oak_leaves[persistent=true]
setblock ~27 ~133 ~105 oak_leaves[persistent=true]
setblock ~27 ~134 ~88 oak_leaves[persistent=true]
setblock ~27 ~134 ~89 oak_leaves[persistent=true]
setblock ~27 ~134 ~90 oak_wood
setblock ~27 ~134 ~91 jungle_leaves[persistent=true]
setblock ~27 ~134 ~92 oak_leaves[persistent=true]
setblock ~27 ~134 ~93 oak_leaves[persistent=true]
setblock ~27 ~134 ~94 jungle_leaves[persistent=true]
setblock ~27 ~134 ~95 oak_leaves[persistent=true]
setblock ~27 ~134 ~97 oak_leaves[persistent=true]
setblock ~27 ~134 ~98 oak_leaves[persistent=true]
setblock ~27 ~134 ~100 oak_leaves[persistent=true]
setblock ~27 ~134 ~101 oak_wood
setblock ~27 ~134 ~102 oak_leaves[persistent=true]
setblock ~27 ~134 ~105 oak_leaves[persistent=true]
setblock ~27 ~135 ~89 oak_leaves[persistent=true]
setblock ~27 ~135 ~91 oak_leaves[persistent=true]
setblock ~27 ~135 ~92 jungle_leaves[persistent=true]
setblock ~27 ~135 ~94 jungle_leaves[persistent=true]
setblock ~27 ~135 ~97 oak_leaves[persistent=true]
setblock ~27 ~135 ~100 oak_leaves[persistent=true]
setblock ~27 ~135 ~101 oak_leaves[persistent=true]
setblock ~27 ~135 ~102 oak_leaves[persistent=true]
setblock ~27 ~135 ~103 oak_leaves[persistent=true]
setblock ~27 ~135 ~111 oak_leaves[persistent=true]
setblock ~27 ~135 ~112 oak_leaves[persistent=true]
setblock ~27 ~135 ~113 jungle_leaves[persistent=true]
setblock ~27 ~136 ~88 oak_leaves[persistent=true]
setblock ~27 ~136 ~90 oak_leaves[persistent=true]
setblock ~27 ~136 ~91 oak_leaves[persistent=true]
setblock ~27 ~136 ~94 oak_leaves[persistent=true]
setblock ~27 ~136 ~95 oak_leaves[persistent=true]
setblock ~27 ~136 ~96 jungle_leaves[persistent=true]
setblock ~27 ~136 ~97 oak_leaves[persistent=true]
setblock ~27 ~136 ~99 jungle_leaves[persistent=true]
setblock ~27 ~136 ~100 oak_leaves[persistent=true]
setblock ~27 ~136 ~101 oak_leaves[persistent=true]
setblock ~27 ~136 ~103 jungle_leaves[persistent=true]
setblock ~27 ~136 ~111 oak_leaves[persistent=true]
setblock ~27 ~136 ~112 oak_leaves[persistent=true]
setblock ~27 ~136 ~113 oak_leaves[persistent=true]
setblock ~27 ~137 ~88 oak_leaves[persistent=true]
setblock ~27 ~137 ~94 oak_leaves[persistent=true]
setblock ~27 ~137 ~99 oak_wood
setblock ~27 ~137 ~100 oak_leaves[persistent=true]
setblock ~27 ~137 ~111 oak_leaves[persistent=true]
setblock ~27 ~137 ~112 oak_leaves[persistent=true]
setblock ~27 ~137 ~113 oak_leaves[persistent=true]
setblock ~27 ~138 ~88 jungle_leaves[persistent=true]
setblock ~27 ~138 ~89 oak_leaves[persistent=true]
setblock ~27 ~138 ~90 oak_leaves[persistent=true]
setblock ~27 ~138 ~92 oak_leaves[persistent=true]
setblock ~27 ~138 ~93 oak_leaves[persistent=true]
setblock ~27 ~138 ~95 oak_leaves[persistent=true]
setblock ~27 ~138 ~96 oak_leaves[persistent=true]
setblock ~27 ~138 ~97 oak_leaves[persistent=true]
setblock ~27 ~138 ~98 jungle_leaves[persistent=true]
setblock ~27 ~138 ~99 oak_leaves[persistent=true]
setblock ~27 ~138 ~100 jungle_leaves[persistent=true]
setblock ~27 ~138 ~111 oak_leaves[persistent=true]
setblock ~27 ~138 ~112 oak_leaves[persistent=true]
setblock ~27 ~138 ~113 oak_leaves[persistent=true]
setblock ~27 ~139 ~91 oak_leaves[persistent=true]
setblock ~27 ~139 ~93 jungle_leaves[persistent=true]
setblock ~27 ~139 ~95 oak_leaves[persistent=true]
setblock ~27 ~139 ~96 oak_leaves[persistent=true]
setblock ~27 ~139 ~97 oak_leaves[persistent=true]
setblock ~28 ~105 ~87 dirt
setblock ~28 ~106 ~86 dirt
setblock ~28 ~106 ~87 dirt
setblock ~28 ~106 ~88 dirt
setblock ~28 ~107 ~86 dirt
setblock ~28 ~107 ~87 dirt
setblock ~28 ~107 ~88 dirt
setblock ~28 ~108 ~86 dirt
setblock ~28 ~108 ~87 dirt
setblock ~28 ~108 ~88 dirt
setblock ~28 ~109 ~86 dirt
setblock ~28 ~109 ~87 dirt
setblock ~28 ~109 ~88 dirt
setblock ~28 ~109 ~89 dirt
setblock ~28 ~110 ~85 dirt
setblock ~28 ~110 ~86 dirt
setblock ~28 ~110 ~87 dirt
setblock ~28 ~110 ~88 dirt
setblock ~28 ~110 ~89 dirt
setblock ~28 ~110 ~90 dirt
setblock ~28 ~110 ~91 dirt
setblock ~28 ~111 ~84 dirt
setblock ~28 ~111 ~85 dirt
setblock ~28 ~111 ~86 dirt
setblock ~28 ~111 ~87 dirt
setblock ~28 ~111 ~88 dirt
setblock ~28 ~111 ~89 dirt
setblock ~28 ~111 ~90 dirt
setblock ~28 ~111 ~91 dirt
setblock ~28 ~111 ~92 dirt
setblock ~28 ~111 ~93 dirt
setblock ~28 ~112 ~83 dirt
setblock ~28 ~112 ~84 dirt
setblock ~28 ~112 ~85 dirt
setblock ~28 ~112 ~86 dirt
setblock ~28 ~112 ~87 dirt
setblock ~28 ~112 ~88 dirt
setblock ~28 ~112 ~89 dirt
setblock ~28 ~112 ~90 dirt
setblock ~28 ~112 ~91 dirt
setblock ~28 ~112 ~92 dirt
setblock ~28 ~112 ~93 dirt
setblock ~28 ~112 ~94 dirt
setblock ~28 ~112 ~97 dirt
setblock ~28 ~113 ~83 dirt
setblock ~28 ~113 ~84 dirt
setblock ~28 ~113 ~85 dirt
setblock ~28 ~113 ~86 dirt
setblock ~28 ~113 ~87 dirt
setblock ~28 ~113 ~88 dirt
setblock ~28 ~113 ~89 dirt
setblock ~28 ~113 ~90 dirt
setblock ~28 ~113 ~91 dirt
setblock ~28 ~113 ~92 dirt
setblock ~28 ~113 ~93 dirt
setblock ~28 ~113 ~94 dirt
setblock ~28 ~113 ~97 dirt
setblock ~28 ~114 ~83 dirt
setblock ~28 ~114 ~84 dirt
setblock ~28 ~114 ~85 dirt
setblock ~28 ~114 ~86 dirt
setblock ~28 ~114 ~87 dirt
setblock ~28 ~114 ~88 dirt
setblock ~28 ~114 ~89 dirt
setblock ~28 ~114 ~90 dirt
setblock ~28 ~114 ~91 dirt
setblock ~28 ~114 ~92 dirt
setblock ~28 ~114 ~93 dirt
setblock ~28 ~114 ~94 dirt
setblock ~28 ~114 ~95 dirt
setblock ~28 ~114 ~96 dirt
setblock ~28 ~114 ~97 dirt
setblock ~28 ~114 ~98 dirt
setblock ~28 ~114 ~118 dirt
setblock ~28 ~115 ~81 dirt
setblock ~28 ~115 ~82 dirt
setblock ~28 ~115 ~83 dirt
setblock ~28 ~115 ~84 dirt
setblock ~28 ~115 ~85 dirt
setblock ~28 ~115 ~86 dirt
setblock ~28 ~115 ~87 dirt
setblock ~28 ~115 ~88 dirt
setblock ~28 ~115 ~89 dirt
setblock ~28 ~115 ~90 dirt
setblock ~28 ~115 ~91 dirt
setblock ~28 ~115 ~92 dirt
setblock ~28 ~115 ~93 dirt
setblock ~28 ~115 ~94 dirt
setblock ~28 ~115 ~95 dirt
setblock ~28 ~115 ~96 dirt
setblock ~28 ~115 ~97 dirt
setblock ~28 ~115 ~98 dirt
setblock ~28 ~115 ~99 dirt
setblock ~28 ~115 ~117 dirt
setblock ~28 ~115 ~118 dirt
setblock ~28 ~115 ~119 dirt
setblock ~28 ~116 ~80 dirt
setblock ~28 ~116 ~81 dirt
setblock ~28 ~116 ~82 dirt
setblock ~28 ~116 ~83 dirt
setblock ~28 ~116 ~84 dirt
setblock ~28 ~116 ~85 dirt
setblock ~28 ~116 ~86 dirt
setblock ~28 ~116 ~87 dirt
setblock ~28 ~116 ~88 dirt
setblock ~28 ~116 ~89 dirt
setblock ~28 ~116 ~90 dirt
setblock ~28 ~116 ~91 dirt
setblock ~28 ~116 ~92 dirt
setblock ~28 ~116 ~93 dirt
setblock ~28 ~116 ~94 dirt
setblock ~28 ~116 ~95 dirt
setblock ~28 ~116 ~96 dirt
setblock ~28 ~116 ~97 dirt
setblock ~28 ~116 ~98 dirt
setblock ~28 ~116 ~99 dirt
setblock ~28 ~116 ~100 dirt
setblock ~28 ~116 ~111 dirt
setblock ~28 ~116 ~113 dirt
setblock ~28 ~116 ~115 dirt
setblock ~28 ~116 ~116 dirt
setblock ~28 ~116 ~117 dirt
setblock ~28 ~116 ~118 dirt
setblock ~28 ~116 ~119 dirt
setblock ~28 ~116 ~120 dirt
setblock ~28 ~117 ~79 dirt
setblock ~28 ~117 ~80 dirt
setblock ~28 ~117 ~81 dirt
setblock ~28 ~117 ~82 dirt
setblock ~28 ~117 ~83 dirt
