setblock ~0 ~1 ~0 gold_block
setblock ~27 ~120 ~98 dirt
setblock ~27 ~120 ~100 dirt
setblock ~27 ~121 ~96 dirt
setblock ~27 ~121 ~98 dirt
setblock ~27 ~121 ~99 dirt
setblock ~27 ~121 ~100 dirt
setblock ~27 ~121 ~104 dirt
setblock ~27 ~122 ~96 dirt
setblock ~27 ~122 ~98 dirt
setblock ~27 ~122 ~99 dirt
setblock ~27 ~122 ~100 dirt
setblock ~27 ~122 ~104 dirt
setblock ~27 ~123 ~96 dirt
setblock ~27 ~123 ~98 dirt
setblock ~27 ~123 ~99 dirt
setblock ~27 ~123 ~100 dirt
setblock ~27 ~123 ~104 dirt
setblock ~27 ~124 ~96 grass_block
setblock ~27 ~124 ~98 grass_block
setblock ~27 ~124 ~99 grass_block
setblock ~27 ~124 ~100 grass_block
setblock ~27 ~124 ~104 dirt
setblock ~27 ~125 ~100 fern
setblock ~27 ~125 ~104 grass_block
setblock ~27 ~126 ~104 short_grass
setblock ~28 ~118 ~100 dirt
setblock ~28 ~119 ~96 dirt
setblock ~28 ~119 ~98 dirt
setblock ~28 ~119 ~99 dirt
setblock ~28 ~119 ~100 dirt
setblock ~28 ~119 ~104 dirt
setblock ~28 ~120 ~96 dirt
setblock ~28 ~120 ~97 dirt
setblock ~28 ~120 ~98 dirt
setblock ~28 ~120 ~99 dirt
setblock ~28 ~120 ~100 dirt
setblock ~28 ~120 ~101 dirt
setblock ~28 ~120 ~102 dirt
setblock ~28 ~120 ~104 dirt
setblock ~28 ~121 ~95 dirt
setblock ~28 ~121 ~96 dirt
setblock ~28 ~121 ~97 dirt
setblock ~28 ~121 ~98 dirt
setblock ~28 ~121 ~99 dirt
setblock ~28 ~121 ~100 dirt
setblock ~28 ~121 ~101 dirt
setblock ~28 ~121 ~102 dirt
setblock ~28 ~121 ~103 dirt
setblock ~28 ~121 ~104 dirt
setblock ~28 ~121 ~105 dirt
setblock ~28 ~122 ~95 dirt
setblock ~28 ~122 ~96 dirt
setblock ~28 ~122 ~97 dirt
setblock ~28 ~122 ~98 dirt
setblock ~28 ~122 ~99 dirt
setblock ~28 ~122 ~100 dirt
setblock ~28 ~122 ~101 dirt
setblock ~28 ~122 ~102 dirt
setblock ~28 ~122 ~103 dirt
setblock ~28 ~122 ~104 dirt
setblock ~28 ~122 ~105 dirt
setblock ~28 ~123 ~95 dirt
setblock ~28 ~123 ~96 dirt
setblock ~28 ~123 ~97 dirt
setblock ~28 ~123 ~98 dirt
setblock ~28 ~123 ~99 dirt
setblock ~28 ~123 ~100 dirt
setblock ~28 ~123 ~101 dirt
setblock ~28 ~123 ~102 dirt
setblock ~28 ~123 ~103 dirt
setblock ~28 ~123 ~104 dirt
setblock ~28 ~123 ~105 dirt
setblock ~28 ~124 ~95 grass_block
setblock ~28 ~124 ~96 grass_block
setblock ~28 ~124 ~97 grass_block
setblock ~28 ~124 ~98 grass_block
setblock ~28 ~124 ~99 grass_block
setblock ~28 ~124 ~100 grass_block
setblock ~28 ~124 ~101 grass_block
setblock ~28 ~124 ~102 grass_block
setblock ~28 ~124 ~103 dirt
setblock ~28 ~124 ~104 dirt
setblock ~28 ~124 ~105 dirt
setblock ~28 ~125 ~99 short_grass
setblock ~28 ~125 ~100 poppy
setblock ~28 ~125 ~102 short_grass
setblock ~28 ~125 ~103 grass_block
setblock ~28 ~125 ~104 grass_block
setblock ~28 ~125 ~105 dirt
setblock ~28 ~126 ~103 poppy
setblock ~28 ~126 ~105 grass_block
setblock ~29 ~116 ~96 dirt
setblock ~29 ~116 ~97 dirt
setblock ~29 ~116 ~98 dirt
setblock ~29 ~116 ~100 dirt
setblock ~29 ~117 ~96 dirt
setblock ~29 ~117 ~97 dirt
setblock ~29 ~117 ~98 dirt
setblock ~29 ~117 ~99 dirt
setblock ~29 ~117 ~100 dirt
setblock ~29 ~118 ~96 dirt
setblock ~29 ~118 ~97 dirt
setblock ~29 ~118 ~98 dirt
setblock ~29 ~118 ~99 dirt
setblock ~29 ~118 ~100 dirt
setblock ~29 ~118 ~101 dirt
setblock ~29 ~118 ~104 dirt
setblock ~29 ~118 ~105 dirt
setblock ~29 ~119 ~95 dirt
setblock ~29 ~119 ~96 dirt
setblock ~29 ~119 ~97 dirt
setblock ~29 ~119 ~98 dirt
setblock ~29 ~119 ~99 dirt
setblock ~29 ~119 ~100 dirt
setblock ~29 ~119 ~101 dirt
setblock ~29 ~119 ~102 dirt
setblock ~29 ~119 ~103 dirt
setblock ~29 ~119 ~104 dirt
setblock ~29 ~119 ~105 dirt
setblock ~29 ~120 ~95 dirt
setblock ~29 ~120 ~96 dirt
setblock ~29 ~120 ~97 dirt
setblock ~29 ~120 ~98 dirt
setblock ~29 ~120 ~99 dirt
setblock ~29 ~120 ~100 dirt
setblock ~29 ~120 ~101 dirt
setblock ~29 ~120 ~102 dirt
setblock ~29 ~120 ~103 dirt
setblock ~29 ~120 ~104 dirt
setblock ~29 ~120 ~105 dirt
setblock ~29 ~120 ~106 dirt
setblock ~29 ~120 ~107 dirt
setblock ~29 ~120 ~108 dirt
setblock ~29 ~121 ~95 dirt
setblock ~29 ~121 ~96 dirt
setblock ~29 ~121 ~97 dirt
setblock ~29 ~121 ~98 dirt
setblock ~29 ~121 ~99 dirt
setblock ~29 ~121 ~100 dirt
setblock ~29 ~121 ~101 dirt
setblock ~29 ~121 ~102 dirt
setblock ~29 ~121 ~103 dirt
setblock ~29 ~121 ~104 dirt
setblock ~29 ~121 ~105 dirt
setblock ~29 ~121 ~106 dirt
setblock ~29 ~121 ~107 dirt
setblock ~29 ~121 ~108 dirt
setblock ~29 ~121 ~116 dirt
setblock ~29 ~122 ~95 dirt
setblock ~29 ~122 ~96 dirt
setblock ~29 ~122 ~97 dirt
setblock ~29 ~122 ~98 dirt
setblock ~29 ~122 ~99 dirt
setblock ~29 ~122 ~100 dirt
setblock ~29 ~122 ~101 dirt
setblock ~29 ~122 ~102 dirt
setblock ~29 ~122 ~103 dirt
setblock ~29 ~122 ~104 dirt
setblock ~29 ~122 ~105 dirt
setblock ~29 ~122 ~106 dirt
setblock ~29 ~122 ~107 dirt
setblock ~29 ~122 ~108 dirt
setblock ~29 ~122 ~116 dirt
setblock ~29 ~123 ~95 dirt
setblock ~29 ~123 ~96 dirt
setblock ~29 ~123 ~97 dirt
setblock ~29 ~123 ~98 dirt
setblock ~29 ~123 ~99 dirt
setblock ~29 ~123 ~100 dirt
setblock ~29 ~123 ~101 dirt
setblock ~29 ~123 ~102 dirt
setblock ~29 ~123 ~103 dirt
setblock ~29 ~123 ~104 dirt
setblock ~29 ~123 ~105 dirt
setblock ~29 ~123 ~106 dirt
setblock ~29 ~123 ~107 dirt
setblock ~29 ~123 ~108 dirt
setblock ~29 ~123 ~116 dirt
setblock ~29 ~124 ~95 grass_block
setblock ~29 ~124 ~96 grass_block
setblock ~29 ~124 ~97 grass_block
setblock ~29 ~124 ~98 grass_block
setblock ~29 ~124 ~99 grass_block
setblock ~29 ~124 ~100 grass_block
setblock ~29 ~124 ~101 grass_block
setblock ~29 ~124 ~102 grass_block
setblock ~29 ~124 ~103 dirt
setblock ~29 ~124 ~104 dirt
setblock ~29 ~124 ~105 dirt
setblock ~29 ~124 ~106 dirt
setblock ~29 ~124 ~107 dirt
setblock ~29 ~124 ~108 dirt
setblock ~29 ~124 ~116 dirt
setblock ~29 ~125 ~99 short_grass
setblock ~29 ~125 ~102 fern
setblock ~29 ~125 ~103 grass_block
setblock ~29 ~125 ~104 grass_block
setblock ~29 ~125 ~105 dirt
setblock ~29 ~125 ~106 dirt
setblock ~29 ~125 ~107 dirt
setblock ~29 ~125 ~108 dirt
setblock ~29 ~125 ~116 dirt
setblock ~29 ~126 ~105 grass_block
setblock ~29 ~126 ~106 grass_block
setblock ~29 ~126 ~107 dirt
setblock ~29 ~126 ~108 dirt
setblock ~29 ~126 ~116 dirt
setblock ~29 ~127 ~105 poppy
setblock ~29 ~127 ~107 grass_block
setblock ~29 ~127 ~108 dirt
setblock ~29 ~127 ~116 grass_block
setblock ~29 ~128 ~108 grass_block
setblock ~29 ~129 ~108 poppy
setblock ~30 ~114 ~96 dirt
setblock ~30 ~115 ~96 dirt
setblock ~30 ~115 ~97 dirt
setblock ~30 ~115 ~98 dirt
setblock ~30 ~115 ~99 dirt
setblock ~30 ~115 ~100 dirt
setblock ~30 ~116 ~95 dirt
setblock ~30 ~116 ~96 dirt
setblock ~30 ~116 ~97 dirt
setblock ~30 ~116 ~98 dirt
setblock ~30 ~116 ~99 dirt
setblock ~30 ~116 ~100 dirt
setblock ~30 ~116 ~101 dirt
setblock ~30 ~116 ~102 dirt
setblock ~30 ~117 ~95 dirt
setblock ~30 ~117 ~96 dirt
setblock ~30 ~117 ~97 dirt
setblock ~30 ~117 ~98 dirt
setblock ~30 ~117 ~99 dirt
setblock ~30 ~117 ~100 dirt
setblock ~30 ~117 ~101 dirt
setblock ~30 ~117 ~102 dirt
setblock ~30 ~117 ~104 dirt
setblock ~30 ~117 ~105 dirt
setblock ~30 ~118 ~95 dirt
setblock ~30 ~118 ~96 dirt
setblock ~30 ~118 ~97 dirt
setblock ~30 ~118 ~98 dirt
setblock ~30 ~118 ~99 dirt
setblock ~30 ~118 ~100 dirt
setblock ~30 ~118 ~101 dirt
setblock ~30 ~118 ~102 dirt
setblock ~30 ~118 ~103 dirt
setblock ~30 ~118 ~104 dirt
setblock ~30 ~118 ~105 dirt
setblock ~30 ~118 ~106 dirt
setblock ~30 ~119 ~87 dirt
setblock ~30 ~119 ~94 dirt
setblock ~30 ~119 ~95 dirt
setblock ~30 ~119 ~96 dirt
setblock ~30 ~119 ~97 dirt
setblock ~30 ~119 ~98 dirt
setblock ~30 ~119 ~99 dirt
setblock ~30 ~119 ~100 dirt
setblock ~30 ~119 ~101 dirt
setblock ~30 ~119 ~102 dirt
setblock ~30 ~119 ~103 dirt
setblock ~30 ~119 ~104 dirt
setblock ~30 ~119 ~105 dirt
setblock ~30 ~119 ~106 dirt
setblock ~30 ~119 ~107 dirt
setblock ~30 ~119 ~108 dirt
setblock ~30 ~120 ~87 dirt
setblock ~30 ~120 ~88 dirt
setblock ~30 ~120 ~94 dirt
setblock ~30 ~120 ~95 dirt
setblock ~30 ~120 ~96 dirt
setblock ~30 ~120 ~97 dirt
setblock ~30 ~120 ~98 dirt
setblock ~30 ~120 ~99 dirt
setblock ~30 ~120 ~100 dirt
setblock ~30 ~120 ~101 dirt
setblock ~30 ~120 ~102 dirt
setblock ~30 ~120 ~103 dirt
setblock ~30 ~120 ~104 dirt
setblock ~30 ~120 ~105 dirt
setblock ~30 ~120 ~106 dirt
setblock ~30 ~120 ~107 dirt
setblock ~30 ~120 ~108 dirt
setblock ~30 ~120 ~109 dirt
setblock ~30 ~120 ~116 dirt
setblock ~30 ~121 ~85 dirt
setblock ~30 ~121 ~86 dirt
setblock ~30 ~121 ~87 dirt
setblock ~30 ~121 ~88 dirt
setblock ~30 ~121 ~91 dirt
setblock ~30 ~121 ~93 dirt
setblock ~30 ~121 ~94 dirt
setblock ~30 ~121 ~95 dirt
setblock ~30 ~121 ~96 dirt
setblock ~30 ~121 ~97 dirt
setblock ~30 ~121 ~98 dirt
setblock ~30 ~121 ~99 dirt
setblock ~30 ~121 ~100 dirt
setblock ~30 ~121 ~101 dirt
setblock ~30 ~121 ~102 dirt
setblock ~30 ~121 ~103 dirt
setblock ~30 ~121 ~104 dirt
setblock ~30 ~121 ~105 dirt
setblock ~30 ~121 ~106 dirt
setblock ~30 ~121 ~107 dirt
setblock ~30 ~121 ~108 dirt
setblock ~30 ~121 ~109 dirt
setblock ~30 ~121 ~115 dirt
setblock ~30 ~121 ~116 dirt
setblock ~30 ~121 ~117 dirt
setblock ~30 ~121 ~118 dirt
setblock ~30 ~122 ~85 dirt
setblock ~30 ~122 ~86 dirt
setblock ~30 ~122 ~87 dirt
setblock ~30 ~122 ~88 dirt
setblock ~30 ~122 ~91 dirt
setblock ~30 ~122 ~93 dirt
setblock ~30 ~122 ~94 dirt
setblock ~30 ~122 ~95 dirt
setblock ~30 ~122 ~96 dirt
setblock ~30 ~122 ~97 dirt
setblock ~30 ~122 ~98 dirt
setblock ~30 ~122 ~99 dirt
setblock ~30 ~122 ~100 dirt
setblock ~30 ~122 ~101 dirt
setblock ~30 ~122 ~102 dirt
setblock ~30 ~122 ~103 dirt
setblock ~30 ~122 ~104 dirt
setblock ~30 ~122 ~105 dirt
setblock ~30 ~122 ~106 dirt
setblock ~30 ~122 ~107 dirt
setblock ~30 ~122 ~108 dirt
setblock ~30 ~122 ~109 dirt
setblock ~30 ~122 ~115 dirt
setblock ~30 ~122 ~116 dirt
setblock ~30 ~122 ~117 dirt
setblock ~30 ~122 ~118 dirt
setblock ~30 ~123 ~85 dirt
setblock ~30 ~123 ~86 dirt
setblock ~30 ~123 ~87 dirt
setblock ~30 ~123 ~88 dirt
setblock ~30 ~123 ~91 grass_block
setblock ~30 ~123 ~93 grass_block
setblock ~30 ~123 ~94 grass_block
setblock ~30 ~123 ~95 grass_block
setblock ~30 ~123 ~96 dirt
setblock ~30 ~123 ~97 dirt
setblock ~30 ~123 ~98 dirt
setblock ~30 ~123 ~99 dirt
setblock ~30 ~123 ~100 dirt
setblock ~30 ~123 ~101 dirt
setblock ~30 ~123 ~102 dirt
setblock ~30 ~123 ~103 dirt
setblock ~30 ~123 ~104 dirt
setblock ~30 ~123 ~105 dirt
setblock ~30 ~123 ~106 dirt
setblock ~30 ~123 ~107 dirt
setblock ~30 ~123 ~108 dirt
setblock ~30 ~123 ~109 dirt
setblock ~30 ~123 ~115 dirt
setblock ~30 ~123 ~116 dirt
setblock ~30 ~123 ~117 dirt
setblock ~30 ~123 ~118 dirt
setblock ~30 ~124 ~85 grass_block
setblock ~30 ~124 ~86 grass_block
setblock ~30 ~124 ~87 grass_block
setblock ~30 ~124 ~88 grass_block
setblock ~30 ~124 ~96 grass_block
setblock ~30 ~124 ~97 grass_block
setblock ~30 ~124 ~98 grass_block
setblock ~30 ~124 ~99 grass_block
setblock ~30 ~124 ~100 grass_block
setblock ~30 ~124 ~101 grass_block
setblock ~30 ~124 ~102 grass_block
setblock ~30 ~124 ~103 dirt
setblock ~30 ~124 ~104 dirt
setblock ~30 ~124 ~105 dirt
setblock ~30 ~124 ~106 dirt
setblock ~30 ~124 ~107 dirt
setblock ~30 ~124 ~108 dirt
setblock ~30 ~124 ~109 dirt
setblock ~30 ~124 ~115 dirt
setblock ~30 ~124 ~116 dirt
setblock ~30 ~124 ~117 dirt
setblock ~30 ~124 ~118 dirt
setblock ~30 ~125 ~85 poppy
setblock ~30 ~125 ~87 short_grass
setblock ~30 ~125 ~88 poppy
setblock ~30 ~125 ~97 short_grass
setblock ~30 ~125 ~98 fern
setblock ~30 ~125 ~100 short_grass
setblock ~30 ~125 ~103 grass_block
setblock ~30 ~125 ~104 grass_block
setblock ~30 ~125 ~105 dirt
setblock ~30 ~125 ~106 dirt
setblock ~30 ~125 ~107 dirt
setblock ~30 ~125 ~108 dirt
setblock ~30 ~125 ~109 dirt
setblock ~30 ~125 ~115 dirt
setblock ~30 ~125 ~116 dirt
setblock ~30 ~125 ~117 dirt
setblock ~30 ~125 ~118 dirt
setblock ~30 ~126 ~103 poppy
setblock ~30 ~126 ~104 short_grass
setblock ~30 ~126 ~105 grass_block
setblock ~30 ~126 ~106 grass_block
setblock ~30 ~126 ~107 dirt
setblock ~30 ~126 ~108 dirt
setblock ~30 ~126 ~109 dirt
setblock ~30 ~126 ~115 dirt
setblock ~30 ~126 ~116 dirt
setblock ~30 ~126 ~117 grass_block
setblock ~30 ~126 ~118 grass_block
setblock ~30 ~127 ~106 short_grass
setblock ~30 ~127 ~107 grass_block
setblock ~30 ~127 ~108 dirt
setblock ~30 ~127 ~109 dirt
setblock ~30 ~127 ~115 grass_block
setblock ~30 ~127 ~116 grass_block
setblock ~30 ~128 ~108 grass_block
setblock ~30 ~128 ~109 dirt
setblock ~30 ~129 ~109 dirt
setblock ~30 ~130 ~109 dirt
setblock ~30 ~131 ~109 grass_block
setblock ~31 ~112 ~96 dirt
setblock ~31 ~113 ~96 dirt
setblock ~31 ~113 ~97 dirt
setblock ~31 ~113 ~100 dirt
setblock ~31 ~113 ~101 dirt
setblock ~31 ~114 ~95 dirt
setblock ~31 ~114 ~96 dirt
setblock ~31 ~114 ~97 dirt
setblock ~31 ~114 ~98 dirt
setblock ~31 ~114 ~99 dirt
setblock ~31 ~114 ~100 dirt
setblock ~31 ~114 ~101 dirt
setblock ~31 ~115 ~95 dirt
setblock ~31 ~115 ~96 dirt
setblock ~31 ~115 ~97 dirt
setblock ~31 ~115 ~98 dirt
setblock ~31 ~115 ~99 dirt
setblock ~31 ~115 ~100 dirt
setblock ~31 ~115 ~101 dirt
setblock ~31 ~115 ~102 dirt
setblock ~31 ~116 ~95 dirt
setblock ~31 ~116 ~96 dirt
setblock ~31 ~116 ~97 dirt
setblock ~31 ~116 ~98 dirt
setblock ~31 ~116 ~99 dirt
setblock ~31 ~116 ~100 dirt
setblock ~31 ~116 ~101 dirt
setblock ~31 ~116 ~102 dirt
setblock ~31 ~116 ~103 dirt
setblock ~31 ~116 ~104 dirt
setblock ~31 ~116 ~105 dirt
setblock ~31 ~117 ~87 dirt
setblock ~31 ~117 ~94 dirt
setblock ~31 ~117 ~95 dirt
setblock ~31 ~117 ~96 dirt
setblock ~31 ~117 ~97 dirt
setblock ~31 ~117 ~98 dirt
setblock ~31 ~117 ~99 dirt
setblock ~31 ~117 ~100 dirt
setblock ~31 ~117 ~101 dirt
setblock ~31 ~117 ~102 dirt
setblock ~31 ~117 ~103 dirt
setblock ~31 ~117 ~104 dirt
setblock ~31 ~117 ~105 dirt
setblock ~31 ~117 ~106 dirt
setblock ~31 ~117 ~107 dirt
setblock ~31 ~117 ~108 dirt
setblock ~31 ~118 ~87 dirt
setblock ~31 ~118 ~88 dirt
setblock ~31 ~118 ~94 dirt
setblock ~31 ~118 ~95 dirt
setblock ~31 ~118 ~96 dirt
setblock ~31 ~118 ~97 dirt
setblock ~31 ~118 ~98 dirt
setblock ~31 ~118 ~99 dirt
setblock ~31 ~118 ~100 dirt
setblock ~31 ~118 ~101 dirt
setblock ~31 ~118 ~102 dirt
setblock ~31 ~118 ~103 dirt
setblock ~31 ~118 ~104 dirt
setblock ~31 ~118 ~105 dirt
setblock ~31 ~118 ~106 dirt
setblock ~31 ~118 ~107 dirt
setblock ~31 ~118 ~108 dirt
setblock ~31 ~119 ~86 dirt
setblock ~31 ~119 ~87 dirt
setblock ~31 ~119 ~88 dirt
setblock ~31 ~119 ~89 dirt
setblock ~31 ~119 ~93 dirt
setblock ~31 ~119 ~94 dirt
setblock ~31 ~119 ~95 dirt
setblock ~31 ~119 ~96 dirt
setblock ~31 ~119 ~97 dirt
setblock ~31 ~119 ~98 dirt
setblock ~31 ~119 ~99 dirt
setblock ~31 ~119 ~100 dirt
setblock ~31 ~119 ~101 dirt
setblock ~31 ~119 ~102 dirt
setblock ~31 ~119 ~103 dirt
setblock ~31 ~119 ~104 dirt
setblock ~31 ~119 ~105 dirt
setblock ~31 ~119 ~106 dirt
setblock ~31 ~119 ~107 dirt
setblock ~31 ~119 ~108 dirt
setblock ~31 ~119 ~109 dirt
setblock ~31 ~119 ~116 dirt
setblock ~31 ~119 ~117 dirt
setblock ~31 ~120 ~85 dirt
setblock ~31 ~120 ~86 dirt
setblock ~31 ~120 ~87 dirt
setblock ~31 ~120 ~88 dirt
setblock ~31 ~120 ~89 dirt
setblock ~31 ~120 ~91 dirt
setblock ~31 ~120 ~93 dirt
setblock ~31 ~120 ~94 dirt
setblock ~31 ~120 ~95 dirt
setblock ~31 ~120 ~96 dirt
setblock ~31 ~120 ~97 dirt
setblock ~31 ~120 ~98 dirt
setblock ~31 ~120 ~99 dirt
setblock ~31 ~120 ~100 dirt
setblock ~31 ~120 ~101 dirt
setblock ~31 ~120 ~102 dirt
setblock ~31 ~120 ~103 dirt
setblock ~31 ~120 ~104 dirt
setblock ~31 ~120 ~105 dirt
setblock ~31 ~120 ~106 dirt
setblock ~31 ~120 ~107 dirt
setblock ~31 ~120 ~108 dirt
setblock ~31 ~120 ~109 dirt
setblock ~31 ~120 ~110 dirt
setblock ~31 ~120 ~112 dirt
setblock ~31 ~120 ~115 dirt
setblock ~31 ~120 ~116 dirt
setblock ~31 ~120 ~117 dirt
setblock ~31 ~120 ~118 dirt
setblock ~31 ~121 ~84 dirt
setblock ~31 ~121 ~85 dirt
setblock ~31 ~121 ~86 dirt
setblock ~31 ~121 ~87 dirt
setblock ~31 ~121 ~88 dirt
setblock ~31 ~121 ~89 dirt
setblock ~31 ~121 ~90 dirt
setblock ~31 ~121 ~91 dirt
setblock ~31 ~121 ~92 dirt
setblock ~31 ~121 ~93 dirt
setblock ~31 ~121 ~94 dirt
setblock ~31 ~121 ~95 dirt
setblock ~31 ~121 ~96 dirt
setblock ~31 ~121 ~97 dirt
setblock ~31 ~121 ~98 dirt
setblock ~31 ~121 ~99 dirt
setblock ~31 ~121 ~100 dirt
setblock ~31 ~121 ~101 dirt
setblock ~31 ~121 ~102 dirt
setblock ~31 ~121 ~103 dirt
setblock ~31 ~121 ~104 dirt
setblock ~31 ~121 ~105 dirt
setblock ~31 ~121 ~106 dirt
setblock ~31 ~121 ~107 dirt
setblock ~31 ~121 ~108 dirt
setblock ~31 ~121 ~109 dirt
setblock ~31 ~121 ~110 dirt
setblock ~31 ~121 ~112 dirt
setblock ~31 ~121 ~115 dirt
setblock ~31 ~121 ~116 dirt
setblock ~31 ~121 ~117 dirt
setblock ~31 ~121 ~118 dirt
setblock ~31 ~121 ~119 dirt
setblock ~31 ~122 ~84 dirt
setblock ~31 ~122 ~85 dirt
setblock ~31 ~122 ~86 dirt
setblock ~31 ~122 ~87 dirt
setblock ~31 ~122 ~88 dirt
setblock ~31 ~122 ~89 dirt
setblock ~31 ~122 ~90 dirt
setblock ~31 ~122 ~91 dirt
setblock ~31 ~122 ~92 dirt
setblock ~31 ~122 ~93 dirt
setblock ~31 ~122 ~94 dirt
setblock ~31 ~122 ~95 dirt
setblock ~31 ~122 ~96 dirt
setblock ~31 ~122 ~97 dirt
setblock ~31 ~122 ~98 dirt
setblock ~31 ~122 ~99 dirt
setblock ~31 ~122 ~100 dirt
setblock ~31 ~122 ~101 dirt
setblock ~31 ~122 ~102 dirt
setblock ~31 ~122 ~103 dirt
setblock ~31 ~122 ~104 dirt
setblock ~31 ~122 ~105 dirt
setblock ~31 ~122 ~106 dirt
setblock ~31 ~122 ~107 dirt
setblock ~31 ~122 ~108 dirt
setblock ~31 ~122 ~109 dirt
setblock ~31 ~122 ~110 dirt
setblock ~31 ~122 ~112 dirt
setblock ~31 ~122 ~115 dirt
setblock ~31 ~122 ~116 dirt
setblock ~31 ~122 ~117 dirt
setblock ~31 ~122 ~118 dirt
setblock ~31 ~122 ~119 dirt
setblock ~31 ~123 ~84 dirt
setblock ~31 ~123 ~85 dirt
setblock ~31 ~123 ~86 dirt
setblock ~31 ~123 ~87 dirt
setblock ~31 ~123 ~88 dirt
setblock ~31 ~123 ~89 grass_block
setblock ~31 ~123 ~90 grass_block
setblock ~31 ~123 ~91 grass_block
setblock ~31 ~123 ~92 grass_block
setblock ~31 ~123 ~93 grass_block
setblock ~31 ~123 ~94 grass_block
setblock ~31 ~123 ~95 grass_block
setblock ~31 ~123 ~96 dirt
setblock ~31 ~123 ~97 dirt
setblock ~31 ~123 ~98 dirt
setblock ~31 ~123 ~99 dirt
setblock ~31 ~123 ~100 dirt
setblock ~31 ~123 ~101 dirt
setblock ~31 ~123 ~102 dirt
setblock ~31 ~123 ~103 dirt
setblock ~31 ~123 ~104 dirt
setblock ~31 ~123 ~105 dirt
setblock ~31 ~123 ~106 dirt
setblock ~31 ~123 ~107 dirt
setblock ~31 ~123 ~108 dirt
setblock ~31 ~123 ~109 dirt
setblock ~31 ~123 ~110 dirt
setblock ~31 ~123 ~112 dirt
setblock ~31 ~123 ~115 dirt
setblock ~31 ~123 ~116 dirt
setblock ~31 ~123 ~117 dirt
setblock ~31 ~123 ~118 dirt
setblock ~31 ~123 ~119 dirt
setblock ~31 ~124 ~84 dirt
setblock ~31 ~124 ~85 grass_block
setblock ~31 ~124 ~86 grass_block
setblock ~31 ~124 ~87 grass_block
setblock ~31 ~124 ~88 grass_block
setblock ~31 ~124 ~96 grass_block
setblock ~31 ~124 ~97 grass_block
setblock ~31 ~124 ~98 grass_block
setblock ~31 ~124 ~99 grass_block
setblock ~31 ~124 ~100 grass_block
setblock ~31 ~124 ~101 grass_block
setblock ~31 ~124 ~102 grass_block
setblock ~31 ~124 ~103 dirt
setblock ~31 ~124 ~104 dirt
setblock ~31 ~124 ~105 dirt
setblock ~31 ~124 ~106 dirt
setblock ~31 ~124 ~107 dirt
setblock ~31 ~124 ~108 dirt
setblock ~31 ~124 ~109 dirt
setblock ~31 ~124 ~110 dirt
setblock ~31 ~124 ~112 dirt
setblock ~31 ~124 ~115 dirt
setblock ~31 ~124 ~116 dirt
setblock ~31 ~124 ~117 dirt
setblock ~31 ~124 ~118 dirt
setblock ~31 ~124 ~119 dirt
setblock ~31 ~125 ~84 grass_block
setblock ~31 ~125 ~101 short_grass
setblock ~31 ~125 ~103 grass_block
setblock ~31 ~125 ~104 grass_block
setblock ~31 ~125 ~105 grass_block
setblock ~31 ~125 ~106 dirt
setblock ~31 ~125 ~107 dirt
setblock ~31 ~125 ~108 dirt
setblock ~31 ~125 ~109 dirt
setblock ~31 ~125 ~110 dirt
setblock ~31 ~125 ~112 dirt
setblock ~31 ~125 ~115 dirt
setblock ~31 ~125 ~116 dirt
setblock ~31 ~125 ~117 dirt
setblock ~31 ~125 ~118 grass_block
setblock ~31 ~125 ~119 grass_block
setblock ~31 ~126 ~103 short_grass
setblock ~31 ~126 ~105 short_grass
setblock ~31 ~126 ~106 grass_block
setblock ~31 ~126 ~107 dirt
setblock ~31 ~126 ~108 dirt
setblock ~31 ~126 ~109 dirt
setblock ~31 ~126 ~110 dirt
setblock ~31 ~126 ~112 dirt
setblock ~31 ~126 ~115 grass_block
setblock ~31 ~126 ~116 grass_block
setblock ~31 ~126 ~117 grass_block
setblock ~31 ~127 ~106 poppy
setblock ~31 ~127 ~107 grass_block
setblock ~31 ~127 ~108 grass_block
setblock ~31 ~127 ~109 dirt
setblock ~31 ~127 ~110 dirt
setblock ~31 ~127 ~112 dirt
setblock ~31 ~127 ~116 fern
setblock ~31 ~128 ~107 short_grass
setblock ~31 ~128 ~108 short_grass
setblock ~31 ~128 ~109 dirt
setblock ~31 ~128 ~110 dirt
setblock ~31 ~128 ~112 grass_block
setblock ~31 ~129 ~109 grass_block
setblock ~31 ~129 ~110 dirt
setblock ~31 ~130 ~109 spruce_slab
setblock ~31 ~130 ~110 dirt
setblock ~31 ~130 ~111 spruce_slab
setblock ~31 ~131 ~110 grass_block
setblock ~32 ~110 ~98 dirt
setblock ~32 ~110 ~101 dirt
setblock ~32 ~111 ~96 dirt
setblock ~32 ~111 ~98 dirt
setblock ~32 ~111 ~101 dirt
setblock ~32 ~112 ~95 dirt
setblock ~32 ~112 ~96 dirt
setblock ~32 ~112 ~97 dirt
setblock ~32 ~112 ~98 dirt
setblock ~32 ~112 ~99 dirt
setblock ~32 ~112 ~100 dirt
setblock ~32 ~112 ~101 dirt
setblock ~32 ~112 ~102 dirt
setblock ~32 ~113 ~95 dirt
setblock ~32 ~113 ~96 dirt
setblock ~32 ~113 ~97 dirt
setblock ~32 ~113 ~98 dirt
setblock ~32 ~113 ~99 dirt
setblock ~32 ~113 ~100 dirt
setblock ~32 ~113 ~101 dirt
setblock ~32 ~113 ~102 dirt
setblock ~32 ~113 ~103 dirt
setblock ~32 ~114 ~95 dirt
setblock ~32 ~114 ~96 dirt
setblock ~32 ~114 ~97 dirt
setblock ~32 ~114 ~98 dirt
setblock ~32 ~114 ~99 dirt
setblock ~32 ~114 ~100 dirt
setblock ~32 ~114 ~101 dirt
setblock ~32 ~114 ~102 dirt
setblock ~32 ~114 ~103 dirt
setblock ~32 ~114 ~106 dirt
setblock ~32 ~115 ~95 dirt
setblock ~32 ~115 ~96 dirt
setblock ~32 ~115 ~97 dirt
setblock ~32 ~115 ~98 dirt
setblock ~32 ~115 ~99 dirt
setblock ~32 ~115 ~100 dirt
setblock ~32 ~115 ~101 dirt
setblock ~32 ~115 ~102 dirt
setblock ~32 ~115 ~103 dirt
setblock ~32 ~115 ~104 dirt
setblock ~32 ~115 ~105 dirt
setblock ~32 ~115 ~106 dirt
setblock ~32 ~115 ~107 dirt
setblock ~32 ~115 ~108 dirt
setblock ~32 ~116 ~87 dirt
setblock ~32 ~116 ~94 dirt
setblock ~32 ~116 ~95 dirt
setblock ~32 ~116 ~96 dirt
setblock ~32 ~116 ~97 dirt
setblock ~32 ~116 ~98 dirt
setblock ~32 ~116 ~99 dirt
setblock ~32 ~116 ~100 dirt
setblock ~32 ~116 ~101 dirt
setblock ~32 ~116 ~102 dirt
setblock ~32 ~116 ~103 dirt
setblock ~32 ~116 ~104 dirt
setblock ~32 ~116 ~105 dirt
setblock ~32 ~116 ~106 dirt
setblock ~32 ~116 ~107 dirt
setblock ~32 ~116 ~108 dirt
setblock ~32 ~116 ~116 dirt
setblock ~32 ~117 ~86 dirt
setblock ~32 ~117 ~87 dirt
setblock ~32 ~117 ~88 dirt
setblock ~32 ~117 ~89 dirt
setblock ~32 ~117 ~93 dirt
setblock ~32 ~117 ~94 dirt
setblock ~32 ~117 ~95 dirt
setblock ~32 ~117 ~96 dirt
setblock ~32 ~117 ~97 dirt
setblock ~32 ~117 ~98 dirt
setblock ~32 ~117 ~99 dirt
setblock ~32 ~117 ~100 dirt
setblock ~32 ~117 ~101 dirt
setblock ~32 ~117 ~102 dirt
setblock ~32 ~117 ~103 dirt
setblock ~32 ~117 ~104 dirt
setblock ~32 ~117 ~105 dirt
setblock ~32 ~117 ~106 dirt
setblock ~32 ~117 ~107 dirt
setblock ~32 ~117 ~108 dirt
setblock ~32 ~117 ~109 dirt
setblock ~32 ~117 ~115 dirt
setblock ~32 ~117 ~116 dirt
setblock ~32 ~117 ~117 dirt
setblock ~32 ~118 ~85 dirt
setblock ~32 ~118 ~86 dirt
setblock ~32 ~118 ~87 dirt
setblock ~32 ~118 ~88 dirt
setblock ~32 ~118 ~89 dirt
setblock ~32 ~118 ~92 dirt
setblock ~32 ~118 ~93 dirt
setblock ~32 ~118 ~94 dirt
setblock ~32 ~118 ~95 dirt
setblock ~32 ~118 ~96 dirt
setblock ~32 ~118 ~97 dirt
setblock ~32 ~118 ~98 dirt
setblock ~32 ~118 ~99 dirt
setblock ~32 ~118 ~100 dirt
setblock ~32 ~118 ~101 dirt
setblock ~32 ~118 ~102 dirt
setblock ~32 ~118 ~103 dirt
setblock ~32 ~118 ~104 dirt
setblock ~32 ~118 ~105 dirt
setblock ~32 ~118 ~106 dirt
setblock ~32 ~118 ~107 dirt
setblock ~32 ~118 ~108 dirt
setblock ~32 ~118 ~109 dirt
setblock ~32 ~118 ~110 dirt
setblock ~32 ~118 ~115 dirt
setblock ~32 ~118 ~116 dirt
setblock ~32 ~118 ~117 dirt
setblock ~32 ~119 ~84 dirt
setblock ~32 ~119 ~85 dirt
setblock ~32 ~119 ~86 dirt
setblock ~32 ~119 ~87 dirt
setblock ~32 ~119 ~88 dirt
setblock ~32 ~119 ~89 dirt
setblock ~32 ~119 ~90 dirt
setblock ~32 ~119 ~91 dirt
setblock ~32 ~119 ~92 dirt
setblock ~32 ~119 ~93 dirt
setblock ~32 ~119 ~94 dirt
setblock ~32 ~119 ~95 dirt
setblock ~32 ~119 ~96 dirt
setblock ~32 ~119 ~97 dirt
setblock ~32 ~119 ~98 dirt
setblock ~32 ~119 ~99 dirt
setblock ~32 ~119 ~100 dirt
setblock ~32 ~119 ~101 dirt
setblock ~32 ~119 ~102 dirt
setblock ~32 ~119 ~103 dirt
setblock ~32 ~119 ~104 dirt
setblock ~32 ~119 ~105 dirt
setblock ~32 ~119 ~106 dirt
setblock ~32 ~119 ~107 dirt
setblock ~32 ~119 ~108 dirt
setblock ~32 ~119 ~109 dirt
setblock ~32 ~119 ~110 dirt
setblock ~32 ~119 ~111 dirt
setblock ~32 ~119 ~112 dirt
setblock ~32 ~119 ~115 dirt
setblock ~32 ~119 ~116 dirt
setblock ~32 ~119 ~117 dirt
setblock ~32 ~119 ~118 dirt
setblock ~32 ~120 ~81 dirt
setblock ~32 ~120 ~84 dirt
setblock ~32 ~120 ~85 dirt
setblock ~32 ~120 ~86 dirt
setblock ~32 ~120 ~87 dirt
setblock ~32 ~120 ~88 dirt
setblock ~32 ~120 ~89 dirt
setblock ~32 ~120 ~90 dirt
setblock ~32 ~120 ~91 dirt
setblock ~32 ~120 ~92 dirt
setblock ~32 ~120 ~93 dirt
setblock ~32 ~120 ~94 dirt
setblock ~32 ~120 ~95 dirt
setblock ~32 ~120 ~96 dirt
setblock ~32 ~120 ~97 dirt
setblock ~32 ~120 ~98 dirt
setblock ~32 ~120 ~99 dirt
setblock ~32 ~120 ~100 dirt
setblock ~32 ~120 ~101 dirt
setblock ~32 ~120 ~102 dirt
setblock ~32 ~120 ~103 dirt
setblock ~32 ~120 ~104 dirt
setblock ~32 ~120 ~105 dirt
setblock ~32 ~120 ~106 dirt
setblock ~32 ~120 ~107 dirt
setblock ~32 ~120 ~108 dirt
setblock ~32 ~120 ~109 dirt
setblock ~32 ~120 ~110 dirt
setblock ~32 ~120 ~111 dirt
setblock ~32 ~120 ~112 dirt
setblock ~32 ~120 ~113 dirt
setblock ~32 ~120 ~114 dirt
setblock ~32 ~120 ~115 dirt
setblock ~32 ~120 ~116 dirt
setblock ~32 ~120 ~117 dirt
setblock ~32 ~120 ~118 dirt
setblock ~32 ~120 ~119 dirt
setblock ~32 ~121 ~81 dirt
setblock ~32 ~121 ~83 dirt
setblock ~32 ~121 ~84 dirt
setblock ~32 ~121 ~85 dirt
setblock ~32 ~121 ~86 dirt
setblock ~32 ~121 ~87 dirt
setblock ~32 ~121 ~88 dirt
setblock ~32 ~121 ~89 dirt
setblock ~32 ~121 ~90 dirt
setblock ~32 ~121 ~91 dirt
setblock ~32 ~121 ~92 dirt
setblock ~32 ~121 ~93 dirt
setblock ~32 ~121 ~94 dirt
setblock ~32 ~121 ~95 dirt
setblock ~32 ~121 ~96 dirt
setblock ~32 ~121 ~97 dirt
setblock ~32 ~121 ~98 dirt
setblock ~32 ~121 ~99 dirt
setblock ~32 ~121 ~100 dirt
setblock ~32 ~121 ~101 dirt
setblock ~32 ~121 ~102 dirt
setblock ~32 ~121 ~103 dirt
setblock ~32 ~121 ~104 dirt
setblock ~32 ~121 ~105 dirt
setblock ~32 ~121 ~106 dirt
setblock ~32 ~121 ~107 dirt
setblock ~32 ~121 ~108 dirt
setblock ~32 ~121 ~109 dirt
setblock ~32 ~121 ~110 dirt
setblock ~32 ~121 ~111 dirt
setblock ~32 ~121 ~112 dirt
setblock ~32 ~121 ~113 dirt
setblock ~32 ~121 ~114 dirt
setblock ~32 ~121 ~115 dirt
setblock ~32 ~121 ~116 dirt
setblock ~32 ~121 ~117 dirt
setblock ~32 ~121 ~118 dirt
setblock ~32 ~121 ~119 dirt
setblock ~32 ~121 ~120 dirt
setblock ~32 ~121 ~124 dirt
setblock ~32 ~122 ~81 dirt
setblock ~32 ~122 ~83 dirt
setblock ~32 ~122 ~84 dirt
setblock ~32 ~122 ~85 dirt
setblock ~32 ~122 ~86 dirt
setblock ~32 ~122 ~87 dirt
setblock ~32 ~122 ~88 dirt
setblock ~32 ~122 ~89 dirt
setblock ~32 ~122 ~90 dirt
setblock ~32 ~122 ~91 dirt
setblock ~32 ~122 ~92 dirt
setblock ~32 ~122 ~93 dirt
setblock ~32 ~122 ~94 dirt
setblock ~32 ~122 ~95 dirt
setblock ~32 ~122 ~96 dirt
setblock ~32 ~122 ~97 dirt
setblock ~32 ~122 ~98 dirt
setblock ~32 ~122 ~99 dirt
setblock ~32 ~122 ~100 dirt
setblock ~32 ~122 ~101 dirt
setblock ~32 ~122 ~102 dirt
setblock ~32 ~122 ~103 dirt
setblock ~32 ~122 ~104 dirt
setblock ~32 ~122 ~105 dirt
setblock ~32 ~122 ~106 dirt
setblock ~32 ~122 ~107 dirt
setblock ~32 ~122 ~108 dirt
setblock ~32 ~122 ~109 dirt
setblock ~32 ~122 ~110 dirt
setblock ~32 ~122 ~111 dirt
setblock ~32 ~122 ~112 dirt
setblock ~32 ~122 ~113 dirt
setblock ~32 ~122 ~114 dirt
setblock ~32 ~122 ~115 dirt
setblock ~32 ~122 ~116 dirt
setblock ~32 ~122 ~117 dirt
setblock ~32 ~122 ~118 dirt
setblock ~32 ~122 ~119 dirt
setblock ~32 ~122 ~120 dirt
setblock ~32 ~122 ~124 dirt
setblock ~32 ~123 ~81 dirt
setblock ~32 ~123 ~83 dirt
setblock ~32 ~123 ~84 dirt
setblock ~32 ~123 ~85 dirt
setblock ~32 ~123 ~86 dirt
setblock ~32 ~123 ~87 dirt
setblock ~32 ~123 ~88 dirt
setblock ~32 ~123 ~89 dirt
setblock ~32 ~123 ~90 grass_block
setblock ~32 ~123 ~91 grass_block
setblock ~32 ~123 ~92 grass_block
setblock ~32 ~123 ~93 grass_block
setblock ~32 ~123 ~94 grass_block
setblock ~32 ~123 ~95 grass_block
setblock ~32 ~123 ~96 grass_block
setblock ~32 ~123 ~97 grass_block
setblock ~32 ~123 ~98 grass_block
setblock ~32 ~123 ~99 dirt
setblock ~32 ~123 ~100 dirt
setblock ~32 ~123 ~101 dirt
setblock ~32 ~123 ~102 dirt
setblock ~32 ~123 ~103 dirt
setblock ~32 ~123 ~104 dirt
setblock ~32 ~123 ~105 dirt
setblock ~32 ~123 ~106 dirt
setblock ~32 ~123 ~107 dirt
setblock ~32 ~123 ~108 dirt
setblock ~32 ~123 ~109 dirt
setblock ~32 ~123 ~110 dirt
setblock ~32 ~123 ~111 dirt
setblock ~32 ~123 ~112 dirt
setblock ~32 ~123 ~113 dirt
setblock ~32 ~123 ~114 dirt
setblock ~32 ~123 ~115 dirt
setblock ~32 ~123 ~116 dirt
setblock ~32 ~123 ~117 dirt
setblock ~32 ~123 ~118 dirt
setblock ~32 ~123 ~119 dirt
setblock ~32 ~123 ~120 dirt
setblock ~32 ~123 ~124 dirt
setblock ~32 ~124 ~81 dirt
setblock ~32 ~124 ~83 dirt
setblock ~32 ~124 ~84 dirt
setblock ~32 ~124 ~85 grass_block
setblock ~32 ~124 ~86 grass_block
setblock ~32 ~124 ~87 grass_block
setblock ~32 ~124 ~88 grass_block
setblock ~32 ~124 ~89 grass_block
setblock ~32 ~124 ~91 short_grass
setblock ~32 ~124 ~95 fern
setblock ~32 ~124 ~96 short_grass
setblock ~32 ~124 ~99 grass_block
setblock ~32 ~124 ~100 grass_block
setblock ~32 ~124 ~101 grass_block
setblock ~32 ~124 ~102 grass_block
setblock ~32 ~124 ~103 grass_block
setblock ~32 ~124 ~104 dirt
setblock ~32 ~124 ~105 dirt
setblock ~32 ~124 ~106 dirt
setblock ~32 ~124 ~107 dirt
setblock ~32 ~124 ~108 dirt
setblock ~32 ~124 ~109 dirt
setblock ~32 ~124 ~110 dirt
setblock ~32 ~124 ~111 dirt
setblock ~32 ~124 ~112 dirt
setblock ~32 ~124 ~113 dirt
setblock ~32 ~124 ~114 dirt
setblock ~32 ~124 ~115 dirt
setblock ~32 ~124 ~116 dirt
setblock ~32 ~124 ~117 dirt
setblock ~32 ~124 ~118 dirt
setblock ~32 ~124 ~119 dirt
setblock ~32 ~124 ~120 dirt
setblock ~32 ~124 ~124 dirt
setblock ~32 ~125 ~81 grass_block
setblock ~32 ~125 ~83 grass_block
setblock ~32 ~125 ~84 grass_block
setblock ~32 ~125 ~87 short_grass
setblock ~32 ~125 ~100 short_grass
setblock ~32 ~125 ~102 short_grass
setblock ~32 ~125 ~104 grass_block
setblock ~32 ~125 ~105 grass_block
setblock ~32 ~125 ~106 grass_block
setblock ~32 ~125 ~107 dirt
setblock ~32 ~125 ~108 dirt
setblock ~32 ~125 ~109 dirt
setblock ~32 ~125 ~110 dirt
setblock ~32 ~125 ~111 dirt
setblock ~32 ~125 ~112 dirt
setblock ~32 ~125 ~113 dirt
setblock ~32 ~125 ~114 dirt
setblock ~32 ~125 ~115 dirt
setblock ~32 ~125 ~116 dirt
setblock ~32 ~125 ~117 grass_block
setblock ~32 ~125 ~118 grass_block
setblock ~32 ~125 ~119 grass_block
setblock ~32 ~125 ~120 grass_block
setblock ~32 ~125 ~124 grass_block
setblock ~32 ~126 ~83 fern
setblock ~32 ~126 ~105 short_grass
setblock ~32 ~126 ~107 grass_block
setblock ~32 ~126 ~108 dirt
setblock ~32 ~126 ~109 dirt
setblock ~32 ~126 ~110 dirt
setblock ~32 ~126 ~111 dirt
setblock ~32 ~126 ~112 dirt
setblock ~32 ~126 ~113 dirt
setblock ~32 ~126 ~114 grass_block
setblock ~32 ~126 ~115 grass_block
setblock ~32 ~126 ~116 grass_block
setblock ~32 ~126 ~119 short_grass
setblock ~32 ~127 ~108 grass_block
setblock ~32 ~127 ~109 grass_block
setblock ~32 ~127 ~110 dirt
setblock ~32 ~127 ~111 dirt
setblock ~32 ~127 ~112 grass_block
setblock ~32 ~127 ~113 grass_block
setblock ~32 ~127 ~115 short_grass
setblock ~32 ~127 ~116 fern
setblock ~32 ~128 ~110 dirt
setblock ~32 ~128 ~111 grass_block
setblock ~32 ~128 ~113 oak_log
setblock ~32 ~128 ~114 spruce_slab
setblock ~32 ~129 ~110 grass_block
setblock ~32 ~129 ~113 oak_log
setblock ~32 ~130 ~110 oak_log
setblock ~32 ~130 ~113 oak_log
setblock ~32 ~131 ~110 oak_log
setblock ~32 ~131 ~113 oak_log
setblock ~32 ~132 ~110 oak_log
setblock ~32 ~132 ~113 oak_log
setblock ~32 ~133 ~110 oak_log
setblock ~32 ~133 ~113 oak_log
setblock ~32 ~134 ~110 oak_log
setblock ~32 ~134 ~113 oak_log
setblock ~32 ~135 ~110 oak_log
setblock ~33 ~108 ~99 dirt
setblock ~33 ~108 ~100 dirt
setblock ~33 ~108 ~101 dirt
setblock ~33 ~109 ~98 dirt
setblock ~33 ~109 ~99 dirt
setblock ~33 ~109 ~100 dirt
setblock ~33 ~109 ~101 dirt
setblock ~33 ~109 ~102 dirt
setblock ~33 ~110 ~96 dirt
setblock ~33 ~110 ~97 dirt
setblock ~33 ~110 ~98 dirt
setblock ~33 ~110 ~99 dirt
setblock ~33 ~110 ~100 dirt
setblock ~33 ~110 ~101 dirt
setblock ~33 ~110 ~102 dirt
setblock ~33 ~111 ~95 dirt
setblock ~33 ~111 ~96 dirt
setblock ~33 ~111 ~97 dirt
setblock ~33 ~111 ~98 dirt
setblock ~33 ~111 ~99 dirt
setblock ~33 ~111 ~100 dirt
setblock ~33 ~111 ~101 dirt
setblock ~33 ~111 ~102 dirt
setblock ~33 ~111 ~106 dirt
setblock ~33 ~112 ~95 dirt
setblock ~33 ~112 ~96 dirt
setblock ~33 ~112 ~97 dirt
setblock ~33 ~112 ~98 dirt
setblock ~33 ~112 ~99 dirt
setblock ~33 ~112 ~100 dirt
setblock ~33 ~112 ~101 dirt
setblock ~33 ~112 ~102 dirt
setblock ~33 ~112 ~103 dirt
setblock ~33 ~112 ~104 dirt
setblock ~33 ~112 ~106 dirt
setblock ~33 ~112 ~107 dirt
setblock ~33 ~113 ~95 dirt
setblock ~33 ~113 ~96 dirt
setblock ~33 ~113 ~97 dirt
setblock ~33 ~113 ~98 dirt
setblock ~33 ~113 ~99 dirt
setblock ~33 ~113 ~100 dirt
setblock ~33 ~113 ~101 dirt
setblock ~33 ~113 ~102 dirt
setblock ~33 ~113 ~103 dirt
setblock ~33 ~113 ~104 dirt
setblock ~33 ~113 ~105 dirt
setblock ~33 ~113 ~106 dirt
setblock ~33 ~113 ~107 dirt
setblock ~33 ~114 ~87 dirt
setblock ~33 ~114 ~94 dirt
setblock ~33 ~114 ~95 dirt
setblock ~33 ~114 ~96 dirt
setblock ~33 ~114 ~97 dirt
setblock ~33 ~114 ~98 dirt
setblock ~33 ~114 ~99 dirt
setblock ~33 ~114 ~100 dirt
setblock ~33 ~114 ~101 dirt
setblock ~33 ~114 ~102 dirt
setblock ~33 ~114 ~103 dirt
setblock ~33 ~114 ~104 dirt
setblock ~33 ~114 ~105 dirt
setblock ~33 ~114 ~106 dirt
setblock ~33 ~114 ~107 dirt
setblock ~33 ~114 ~108 dirt
setblock ~33 ~114 ~116 dirt
setblock ~33 ~115 ~87 dirt
setblock ~33 ~115 ~89 dirt
setblock ~33 ~115 ~93 dirt
setblock ~33 ~115 ~94 dirt
setblock ~33 ~115 ~95 dirt
setblock ~33 ~115 ~96 dirt
setblock ~33 ~115 ~97 dirt
setblock ~33 ~115 ~98 dirt
setblock ~33 ~115 ~99 dirt
setblock ~33 ~115 ~100 dirt
setblock ~33 ~115 ~101 dirt
setblock ~33 ~115 ~102 dirt
setblock ~33 ~115 ~103 dirt
setblock ~33 ~115 ~104 dirt
setblock ~33 ~115 ~105 dirt
setblock ~33 ~115 ~106 dirt
setblock ~33 ~115 ~107 dirt
setblock ~33 ~115 ~108 dirt
setblock ~33 ~115 ~109 dirt
setblock ~33 ~115 ~116 dirt
setblock ~33 ~116 ~86 dirt
setblock ~33 ~116 ~87 dirt
setblock ~33 ~116 ~88 dirt
setblock ~33 ~116 ~89 dirt
setblock ~33 ~116 ~92 dirt
setblock ~33 ~116 ~93 dirt
setblock ~33 ~116 ~94 dirt
setblock ~33 ~116 ~95 dirt
setblock ~33 ~116 ~96 dirt
setblock ~33 ~116 ~97 dirt
setblock ~33 ~116 ~98 dirt
setblock ~33 ~116 ~99 dirt
setblock ~33 ~116 ~100 dirt
setblock ~33 ~116 ~101 dirt
setblock ~33 ~116 ~102 dirt
setblock ~33 ~116 ~103 dirt
setblock ~33 ~116 ~104 dirt
setblock ~33 ~116 ~105 dirt
setblock ~33 ~116 ~106 dirt
setblock ~33 ~116 ~107 dirt
setblock ~33 ~116 ~108 dirt
setblock ~33 ~116 ~109 dirt
setblock ~33 ~116 ~115 dirt
setblock ~33 ~116 ~116 dirt
setblock ~33 ~116 ~117 dirt
setblock ~33 ~117 ~85 dirt
setblock ~33 ~117 ~86 dirt
setblock ~33 ~117 ~87 dirt
setblock ~33 ~117 ~88 dirt
setblock ~33 ~117 ~89 dirt
setblock ~33 ~117 ~90 dirt
setblock ~33 ~117 ~92 dirt
setblock ~33 ~117 ~93 dirt
setblock ~33 ~117 ~94 dirt
setblock ~33 ~117 ~95 dirt
setblock ~33 ~117 ~96 dirt
setblock ~33 ~117 ~97 dirt
setblock ~33 ~117 ~98 dirt
setblock ~33 ~117 ~99 dirt
setblock ~33 ~117 ~100 dirt
setblock ~33 ~117 ~101 dirt
setblock ~33 ~117 ~102 dirt
setblock ~33 ~117 ~103 dirt
setblock ~33 ~117 ~104 dirt
setblock ~33 ~117 ~105 dirt
setblock ~33 ~117 ~106 dirt
setblock ~33 ~117 ~107 dirt
setblock ~33 ~117 ~108 dirt
setblock ~33 ~117 ~109 dirt
setblock ~33 ~117 ~110 dirt
setblock ~33 ~117 ~114 dirt
setblock ~33 ~117 ~115 dirt
setblock ~33 ~117 ~116 dirt
setblock ~33 ~117 ~117 dirt
setblock ~33 ~117 ~118 dirt
setblock ~33 ~118 ~82 dirt
setblock ~33 ~118 ~83 dirt
setblock ~33 ~118 ~84 dirt
setblock ~33 ~118 ~85 dirt
setblock ~33 ~118 ~86 dirt
setblock ~33 ~118 ~87 dirt
setblock ~33 ~118 ~88 dirt
setblock ~33 ~118 ~89 dirt
setblock ~33 ~118 ~90 dirt
setblock ~33 ~118 ~91 dirt
setblock ~33 ~118 ~92 dirt
setblock ~33 ~118 ~93 dirt
setblock ~33 ~118 ~94 dirt
setblock ~33 ~118 ~95 dirt
setblock ~33 ~118 ~96 dirt
setblock ~33 ~118 ~97 dirt
setblock ~33 ~118 ~98 dirt
setblock ~33 ~118 ~99 dirt
setblock ~33 ~118 ~100 dirt
setblock ~33 ~118 ~101 dirt
setblock ~33 ~118 ~102 dirt
setblock ~33 ~118 ~103 dirt
setblock ~33 ~118 ~104 dirt
setblock ~33 ~118 ~105 dirt
setblock ~33 ~118 ~106 dirt
setblock ~33 ~118 ~107 dirt
setblock ~33 ~118 ~108 dirt
setblock ~33 ~118 ~109 dirt
setblock ~33 ~118 ~110 dirt
setblock ~33 ~118 ~111 dirt
setblock ~33 ~118 ~112 dirt
setblock ~33 ~118 ~114 dirt
setblock ~33 ~118 ~115 dirt
setblock ~33 ~118 ~116 dirt
setblock ~33 ~118 ~117 dirt
setblock ~33 ~118 ~118 dirt
setblock ~33 ~118 ~119 dirt
setblock ~33 ~118 ~123 dirt
setblock ~33 ~119 ~80 dirt
setblock ~33 ~119 ~81 dirt
setblock ~33 ~119 ~82 dirt
setblock ~33 ~119 ~83 dirt
setblock ~33 ~119 ~84 dirt
setblock ~33 ~119 ~85 dirt
setblock ~33 ~119 ~86 dirt
setblock ~33 ~119 ~87 dirt
setblock ~33 ~119 ~88 dirt
setblock ~33 ~119 ~89 dirt
setblock ~33 ~119 ~90 dirt
setblock ~33 ~119 ~91 dirt
setblock ~33 ~119 ~92 dirt
setblock ~33 ~119 ~93 dirt
setblock ~33 ~119 ~94 dirt
setblock ~33 ~119 ~95 dirt
setblock ~33 ~119 ~96 dirt
setblock ~33 ~119 ~97 dirt
setblock ~33 ~119 ~98 dirt
setblock ~33 ~119 ~99 dirt
setblock ~33 ~119 ~100 dirt
setblock ~33 ~119 ~101 dirt
setblock ~33 ~119 ~102 dirt
setblock ~33 ~119 ~103 dirt
setblock ~33 ~119 ~104 dirt
setblock ~33 ~119 ~105 dirt
setblock ~33 ~119 ~106 dirt
setblock ~33 ~119 ~107 dirt
setblock ~33 ~119 ~108 dirt
setblock ~33 ~119 ~109 dirt
setblock ~33 ~119 ~110 dirt
setblock ~33 ~119 ~111 dirt
setblock ~33 ~119 ~112 dirt
setblock ~33 ~119 ~113 dirt
setblock ~33 ~119 ~114 dirt
setblock ~33 ~119 ~115 dirt
setblock ~33 ~119 ~116 dirt
setblock ~33 ~119 ~117 dirt
setblock ~33 ~119 ~118 dirt
setblock ~33 ~119 ~119 dirt
setblock ~33 ~119 ~123 dirt
setblock ~33 ~120 ~78 dirt
setblock ~33 ~120 ~79 dirt
setblock ~33 ~120 ~80 dirt
setblock ~33 ~120 ~81 dirt
setblock ~33 ~120 ~82 dirt
setblock ~33 ~120 ~83 dirt
setblock ~33 ~120 ~84 dirt
setblock ~33 ~120 ~85 dirt
setblock ~33 ~120 ~86 dirt
setblock ~33 ~120 ~87 dirt
setblock ~33 ~120 ~88 dirt
setblock ~33 ~120 ~89 dirt
setblock ~33 ~120 ~90 dirt
setblock ~33 ~120 ~91 dirt
setblock ~33 ~120 ~92 dirt
setblock ~33 ~120 ~93 dirt
setblock ~33 ~120 ~94 dirt
setblock ~33 ~120 ~95 dirt
setblock ~33 ~120 ~96 dirt
setblock ~33 ~120 ~97 dirt
setblock ~33 ~120 ~98 dirt
setblock ~33 ~120 ~99 dirt
setblock ~33 ~120 ~100 dirt
setblock ~33 ~120 ~101 dirt
setblock ~33 ~120 ~102 dirt
setblock ~33 ~120 ~103 dirt
setblock ~33 ~120 ~104 dirt
setblock ~33 ~120 ~105 dirt
setblock ~33 ~120 ~106 dirt
setblock ~33 ~120 ~107 dirt
setblock ~33 ~120 ~108 dirt
setblock ~33 ~120 ~109 dirt
setblock ~33 ~120 ~110 dirt
setblock ~33 ~120 ~111 dirt
setblock ~33 ~120 ~112 dirt
setblock ~33 ~120 ~113 dirt
setblock ~33 ~120 ~114 dirt
setblock ~33 ~120 ~115 dirt
setblock ~33 ~120 ~116 dirt
setblock ~33 ~120 ~117 dirt
setblock ~33 ~120 ~118 dirt
setblock ~33 ~120 ~119 dirt
setblock ~33 ~120 ~120 dirt
setblock ~33 ~120 ~121 dirt
setblock ~33 ~120 ~122 dirt
setblock ~33 ~120 ~123 dirt
setblock ~33 ~120 ~124 dirt
setblock ~33 ~121 ~75 dirt
setblock ~33 ~121 ~77 dirt
setblock ~33 ~121 ~78 dirt
setblock ~33 ~121 ~79 dirt
setblock ~33 ~121 ~80 dirt
setblock ~33 ~121 ~81 dirt
setblock ~33 ~121 ~82 dirt
setblock ~33 ~121 ~83 dirt
setblock ~33 ~121 ~84 dirt
setblock ~33 ~121 ~85 dirt
setblock ~33 ~121 ~86 dirt
setblock ~33 ~121 ~87 dirt
setblock ~33 ~121 ~88 dirt
setblock ~33 ~121 ~89 dirt
setblock ~33 ~121 ~90 dirt
setblock ~33 ~121 ~91 dirt
setblock ~33 ~121 ~92 dirt
setblock ~33 ~121 ~93 dirt
setblock ~33 ~121 ~94 dirt
setblock ~33 ~121 ~95 dirt
setblock ~33 ~121 ~96 dirt
setblock ~33 ~121 ~97 dirt
setblock ~33 ~121 ~98 dirt
setblock ~33 ~121 ~99 dirt
setblock ~33 ~121 ~100 dirt
setblock ~33 ~121 ~101 dirt
setblock ~33 ~121 ~102 dirt
setblock ~33 ~121 ~103 dirt
setblock ~33 ~121 ~104 dirt
setblock ~33 ~121 ~105 dirt
setblock ~33 ~121 ~106 dirt
setblock ~33 ~121 ~107 dirt
setblock ~33 ~121 ~108 dirt
setblock ~33 ~121 ~109 dirt
setblock ~33 ~121 ~110 dirt
setblock ~33 ~121 ~111 dirt
setblock ~33 ~121 ~112 dirt
setblock ~33 ~121 ~113 dirt
setblock ~33 ~121 ~114 dirt
setblock ~33 ~121 ~115 dirt
setblock ~33 ~121 ~116 dirt
setblock ~33 ~121 ~117 dirt
setblock ~33 ~121 ~118 dirt
setblock ~33 ~121 ~119 dirt
setblock ~33 ~121 ~120 dirt
setblock ~33 ~121 ~121 dirt
setblock ~33 ~121 ~122 dirt
setblock ~33 ~121 ~123 dirt
setblock ~33 ~121 ~124 dirt
setblock ~33 ~121 ~125 dirt
setblock ~33 ~121 ~126 dirt
setblock ~33 ~122 ~75 dirt
setblock ~33 ~122 ~77 dirt
setblock ~33 ~122 ~78 dirt
setblock ~33 ~122 ~79 dirt
setblock ~33 ~122 ~80 dirt
setblock ~33 ~122 ~81 dirt
setblock ~33 ~122 ~82 dirt
setblock ~33 ~122 ~83 dirt
setblock ~33 ~122 ~84 dirt
setblock ~33 ~122 ~85 dirt
setblock ~33 ~122 ~86 dirt
setblock ~33 ~122 ~87 dirt
setblock ~33 ~122 ~88 dirt
setblock ~33 ~122 ~89 dirt
setblock ~33 ~122 ~90 dirt
setblock ~33 ~122 ~91 dirt
setblock ~33 ~122 ~92 dirt
setblock ~33 ~122 ~93 dirt
setblock ~33 ~122 ~94 dirt
setblock ~33 ~122 ~95 dirt
setblock ~33 ~122 ~96 dirt
setblock ~33 ~122 ~97 dirt
setblock ~33 ~122 ~98 dirt
setblock ~33 ~122 ~99 dirt
setblock ~33 ~122 ~100 dirt
setblock ~33 ~122 ~101 dirt
setblock ~33 ~122 ~102 dirt
setblock ~33 ~122 ~103 dirt
setblock ~33 ~122 ~104 dirt
setblock ~33 ~122 ~105 dirt
setblock ~33 ~122 ~106 dirt
setblock ~33 ~122 ~107 dirt
setblock ~33 ~122 ~108 dirt
setblock ~33 ~122 ~109 dirt
setblock ~33 ~122 ~110 dirt
setblock ~33 ~122 ~111 dirt
setblock ~33 ~122 ~112 dirt
setblock ~33 ~122 ~113 dirt
setblock ~33 ~122 ~114 dirt
setblock ~33 ~122 ~115 dirt
setblock ~33 ~122 ~116 dirt
setblock ~33 ~122 ~117 dirt
setblock ~33 ~122 ~118 dirt
setblock ~33 ~122 ~119 dirt
setblock ~33 ~122 ~120 dirt
setblock ~33 ~122 ~121 dirt
setblock ~33 ~122 ~122 dirt
setblock ~33 ~122 ~123 dirt
setblock ~33 ~122 ~124 dirt
setblock ~33 ~122 ~125 dirt
setblock ~33 ~122 ~126 dirt
setblock ~33 ~123 ~75 dirt
setblock ~33 ~123 ~77 dirt
setblock ~33 ~123 ~78 dirt
setblock ~33 ~123 ~79 dirt
setblock ~33 ~123 ~80 dirt
setblock ~33 ~123 ~81 dirt
setblock ~33 ~123 ~82 dirt
setblock ~33 ~123 ~83 dirt
setblock ~33 ~123 ~84 dirt
setblock ~33 ~123 ~85 dirt
setblock ~33 ~123 ~86 dirt
setblock ~33 ~123 ~87 dirt
setblock ~33 ~123 ~88 dirt
setblock ~33 ~123 ~89 dirt
setblock ~33 ~123 ~90 grass_block
setblock ~33 ~123 ~91 grass_block
setblock ~33 ~123 ~92 grass_block
setblock ~33 ~123 ~93 grass_block
setblock ~33 ~123 ~94 grass_block
setblock ~33 ~123 ~95 grass_block
setblock ~33 ~123 ~96 grass_block
setblock ~33 ~123 ~97 grass_block
setblock ~33 ~123 ~98 grass_block
setblock ~33 ~123 ~99 grass_block
setblock ~33 ~123 ~100 grass_block
setblock ~33 ~123 ~101 dirt
setblock ~33 ~123 ~102 dirt
setblock ~33 ~123 ~103 dirt
setblock ~33 ~123 ~104 dirt
setblock ~33 ~123 ~105 dirt
setblock ~33 ~123 ~106 dirt
setblock ~33 ~123 ~107 dirt
setblock ~33 ~123 ~108 dirt
setblock ~33 ~123 ~109 dirt
setblock ~33 ~123 ~110 dirt
setblock ~33 ~123 ~111 dirt
setblock ~33 ~123 ~112 dirt
setblock ~33 ~123 ~113 dirt
setblock ~33 ~123 ~114 dirt
setblock ~33 ~123 ~115 dirt
setblock ~33 ~123 ~116 dirt
setblock ~33 ~123 ~117 dirt
setblock ~33 ~123 ~118 dirt
setblock ~33 ~123 ~119 dirt
setblock ~33 ~123 ~120 dirt
setblock ~33 ~123 ~121 dirt
setblock ~33 ~123 ~122 dirt
setblock ~33 ~123 ~123 dirt
setblock ~33 ~123 ~124 dirt
setblock ~33 ~123 ~125 dirt
setblock ~33 ~123 ~126 dirt
setblock ~33 ~124 ~75 dirt
setblock ~33 ~124 ~77 dirt
setblock ~33 ~124 ~78 dirt
setblock ~33 ~124 ~79 dirt
setblock ~33 ~124 ~80 dirt
setblock ~33 ~124 ~81 dirt
setblock ~33 ~124 ~82 dirt
setblock ~33 ~124 ~83 dirt
setblock ~33 ~124 ~84 dirt
setblock ~33 ~124 ~85 dirt
setblock ~33 ~124 ~86 grass_block
setblock ~33 ~124 ~87 grass_block
setblock ~33 ~124 ~88 grass_block
setblock ~33 ~124 ~89 grass_block
setblock ~33 ~124 ~91 poppy
setblock ~33 ~124 ~97 poppy
setblock ~33 ~124 ~101 grass_block
setblock ~33 ~124 ~102 grass_block
setblock ~33 ~124 ~103 grass_block
setblock ~33 ~124 ~104 grass_block
setblock ~33 ~124 ~105 dirt
setblock ~33 ~124 ~106 dirt
setblock ~33 ~124 ~107 dirt
setblock ~33 ~124 ~108 dirt
setblock ~33 ~124 ~109 dirt
setblock ~33 ~124 ~110 dirt
setblock ~33 ~124 ~111 dirt
setblock ~33 ~124 ~112 dirt
setblock ~33 ~124 ~113 dirt
setblock ~33 ~124 ~114 dirt
setblock ~33 ~124 ~115 dirt
setblock ~33 ~124 ~116 dirt
setblock ~33 ~124 ~117 dirt
setblock ~33 ~124 ~118 dirt
setblock ~33 ~124 ~119 dirt
setblock ~33 ~124 ~120 dirt
setblock ~33 ~124 ~121 dirt
setblock ~33 ~124 ~122 dirt
setblock ~33 ~124 ~123 dirt
setblock ~33 ~124 ~124 dirt
setblock ~33 ~124 ~125 dirt
setblock ~33 ~124 ~126 dirt
setblock ~33 ~125 ~75 grass_block
setblock ~33 ~125 ~77 grass_block
setblock ~33 ~125 ~78 dirt
setblock ~33 ~125 ~79 dirt
setblock ~33 ~125 ~80 dirt
setblock ~33 ~125 ~81 dirt
setblock ~33 ~125 ~82 grass_block
setblock ~33 ~125 ~83 grass_block
setblock ~33 ~125 ~84 grass_block
setblock ~33 ~125 ~85 grass_block
setblock ~33 ~125 ~101 short_grass
setblock ~33 ~125 ~102 short_grass
setblock ~33 ~125 ~104 short_grass
setblock ~33 ~125 ~105 grass_block
setblock ~33 ~125 ~106 grass_block
setblock ~33 ~125 ~107 grass_block
setblock ~33 ~125 ~108 dirt
setblock ~33 ~125 ~109 dirt
setblock ~33 ~125 ~110 dirt
setblock ~33 ~125 ~111 dirt
setblock ~33 ~125 ~112 dirt
setblock ~33 ~125 ~113 dirt
setblock ~33 ~125 ~114 dirt
setblock ~33 ~125 ~115 dirt
setblock ~33 ~125 ~116 grass_block
setblock ~33 ~125 ~117 grass_block
setblock ~33 ~125 ~118 grass_block
setblock ~33 ~125 ~119 grass_block
setblock ~33 ~125 ~120 grass_block
setblock ~33 ~125 ~121 grass_block
setblock ~33 ~125 ~122 grass_block
setblock ~33 ~125 ~123 grass_block
setblock ~33 ~125 ~124 grass_block
setblock ~33 ~125 ~125 grass_block
setblock ~33 ~125 ~126 grass_block
setblock ~33 ~126 ~78 grass_block
setblock ~33 ~126 ~79 grass_block
setblock ~33 ~126 ~80 grass_block
setblock ~33 ~126 ~81 grass_block
setblock ~33 ~126 ~83 short_grass
setblock ~33 ~126 ~108 grass_block
setblock ~33 ~126 ~109 dirt
setblock ~33 ~126 ~110 dirt
setblock ~33 ~126 ~111 dirt
setblock ~33 ~126 ~112 grass_block
setblock ~33 ~126 ~113 grass_block
setblock ~33 ~126 ~114 grass_block
setblock ~33 ~126 ~115 grass_block
setblock ~33 ~126 ~120 short_grass
setblock ~33 ~126 ~122 fern
setblock ~33 ~126 ~124 short_grass
setblock ~33 ~127 ~78 short_grass
setblock ~33 ~127 ~80 short_grass
setblock ~33 ~127 ~81 short_grass
setblock ~33 ~127 ~109 grass_block
setblock ~33 ~127 ~110 grass_block
setblock ~33 ~127 ~111 grass_block
setblock ~33 ~127 ~112 fern
setblock ~33 ~128 ~110 short_grass
setblock ~33 ~128 ~111 short_grass
setblock ~33 ~128 ~114 spruce_slab
setblock ~33 ~130 ~110 spruce_slab
setblock ~34 ~104 ~100 dirt
setblock ~34 ~104 ~101 dirt
setblock ~34 ~105 ~100 dirt
setblock ~34 ~105 ~101 dirt
setblock ~34 ~106 ~99 dirt
setblock ~34 ~106 ~100 dirt
setblock ~34 ~106 ~101 dirt
setblock ~34 ~106 ~102 dirt
setblock ~34 ~107 ~98 dirt
setblock ~34 ~107 ~99 dirt
setblock ~34 ~107 ~100 dirt
setblock ~34 ~107 ~101 dirt
setblock ~34 ~107 ~102 dirt
setblock ~34 ~108 ~97 dirt
setblock ~34 ~108 ~98 dirt
setblock ~34 ~108 ~99 dirt
setblock ~34 ~108 ~100 dirt
setblock ~34 ~108 ~101 dirt
setblock ~34 ~108 ~102 dirt
setblock ~34 ~109 ~96 dirt
setblock ~34 ~109 ~97 dirt
setblock ~34 ~109 ~98 dirt
setblock ~34 ~109 ~99 dirt
setblock ~34 ~109 ~100 dirt
setblock ~34 ~109 ~101 dirt
setblock ~34 ~109 ~102 dirt
setblock ~34 ~109 ~103 dirt
setblock ~34 ~110 ~95 dirt
setblock ~34 ~110 ~96 dirt
setblock ~34 ~110 ~97 dirt
setblock ~34 ~110 ~98 dirt
setblock ~34 ~110 ~99 dirt
setblock ~34 ~110 ~100 dirt
setblock ~34 ~110 ~101 dirt
setblock ~34 ~110 ~102 dirt
setblock ~34 ~110 ~103 dirt
setblock ~34 ~110 ~106 dirt
setblock ~34 ~110 ~107 dirt
setblock ~34 ~111 ~94 dirt
setblock ~34 ~111 ~95 dirt
setblock ~34 ~111 ~96 dirt
setblock ~34 ~111 ~97 dirt
setblock ~34 ~111 ~98 dirt
setblock ~34 ~111 ~99 dirt
setblock ~34 ~111 ~100 dirt
setblock ~34 ~111 ~101 dirt
setblock ~34 ~111 ~102 dirt
setblock ~34 ~111 ~103 dirt
setblock ~34 ~111 ~104 dirt
setblock ~34 ~111 ~105 dirt
setblock ~34 ~111 ~106 dirt
setblock ~34 ~111 ~107 dirt
setblock ~34 ~112 ~87 dirt
setblock ~34 ~112 ~88 dirt
setblock ~34 ~112 ~94 dirt
setblock ~34 ~112 ~95 dirt
setblock ~34 ~112 ~96 dirt
setblock ~34 ~112 ~97 dirt
setblock ~34 ~112 ~98 dirt
setblock ~34 ~112 ~99 dirt
setblock ~34 ~112 ~100 dirt
setblock ~34 ~112 ~101 dirt
setblock ~34 ~112 ~102 dirt
setblock ~34 ~112 ~103 dirt
setblock ~34 ~112 ~104 dirt
setblock ~34 ~112 ~105 dirt
setblock ~34 ~112 ~106 dirt
setblock ~34 ~112 ~107 dirt
setblock ~34 ~112 ~108 dirt
setblock ~34 ~112 ~117 dirt
setblock ~34 ~113 ~87 dirt
setblock ~34 ~113 ~88 dirt
setblock ~34 ~113 ~94 dirt
setblock ~34 ~113 ~95 dirt
setblock ~34 ~113 ~96 dirt
setblock ~34 ~113 ~97 dirt
setblock ~34 ~113 ~98 dirt
setblock ~34 ~113 ~99 dirt
setblock ~34 ~113 ~100 dirt
setblock ~34 ~113 ~101 dirt
setblock ~34 ~113 ~102 dirt
setblock ~34 ~113 ~103 dirt
setblock ~34 ~113 ~104 dirt
setblock ~34 ~113 ~105 dirt
setblock ~34 ~113 ~106 dirt
setblock ~34 ~113 ~107 dirt
setblock ~34 ~113 ~108 dirt
setblock ~34 ~113 ~116 dirt
setblock ~34 ~113 ~117 dirt
setblock ~34 ~113 ~118 dirt
setblock ~34 ~114 ~86 dirt
setblock ~34 ~114 ~87 dirt
setblock ~34 ~114 ~88 dirt
setblock ~34 ~114 ~89 dirt
setblock ~34 ~114 ~93 dirt
setblock ~34 ~114 ~94 dirt
setblock ~34 ~114 ~95 dirt
setblock ~34 ~114 ~96 dirt
setblock ~34 ~114 ~97 dirt
setblock ~34 ~114 ~98 dirt
setblock ~34 ~114 ~99 dirt
setblock ~34 ~114 ~100 dirt
setblock ~34 ~114 ~101 dirt
setblock ~34 ~114 ~102 dirt
setblock ~34 ~114 ~103 dirt
setblock ~34 ~114 ~104 dirt
setblock ~34 ~114 ~105 dirt
setblock ~34 ~114 ~106 dirt
setblock ~34 ~114 ~107 dirt
setblock ~34 ~114 ~108 dirt
setblock ~34 ~114 ~109 dirt
setblock ~34 ~114 ~115 dirt
setblock ~34 ~114 ~116 dirt
setblock ~34 ~114 ~117 dirt
setblock ~34 ~114 ~118 dirt
setblock ~34 ~115 ~84 dirt
setblock ~34 ~115 ~86 dirt
setblock ~34 ~115 ~87 dirt
setblock ~34 ~115 ~88 dirt
setblock ~34 ~115 ~89 dirt
setblock ~34 ~115 ~90 dirt
setblock ~34 ~115 ~91 dirt
setblock ~34 ~115 ~92 dirt
setblock ~34 ~115 ~93 dirt
setblock ~34 ~115 ~94 dirt
setblock ~34 ~115 ~95 dirt
setblock ~34 ~115 ~96 dirt
setblock ~34 ~115 ~97 dirt
setblock ~34 ~115 ~98 dirt
setblock ~34 ~115 ~99 dirt
setblock ~34 ~115 ~100 dirt
setblock ~34 ~115 ~101 dirt
setblock ~34 ~115 ~102 dirt
setblock ~34 ~115 ~103 dirt
setblock ~34 ~115 ~104 dirt
setblock ~34 ~115 ~105 dirt
setblock ~34 ~115 ~106 dirt
setblock ~34 ~115 ~107 dirt
setblock ~34 ~115 ~108 dirt
setblock ~34 ~115 ~109 dirt
setblock ~34 ~115 ~111 dirt
setblock ~34 ~115 ~115 dirt
setblock ~34 ~115 ~116 dirt
setblock ~34 ~115 ~117 dirt
setblock ~34 ~115 ~118 dirt
setblock ~34 ~116 ~78 dirt
setblock ~34 ~116 ~79 dirt
setblock ~34 ~116 ~83 dirt
setblock ~34 ~116 ~84 dirt
setblock ~34 ~116 ~85 dirt
setblock ~34 ~116 ~86 dirt
setblock ~34 ~116 ~87 dirt
setblock ~34 ~116 ~88 dirt
setblock ~34 ~116 ~89 dirt
setblock ~34 ~116 ~90 dirt
setblock ~34 ~116 ~91 dirt
setblock ~34 ~116 ~92 dirt
setblock ~34 ~116 ~93 dirt
setblock ~34 ~116 ~94 dirt
setblock ~34 ~116 ~95 dirt
setblock ~34 ~116 ~96 dirt
setblock ~34 ~116 ~97 dirt
setblock ~34 ~116 ~98 dirt
setblock ~34 ~116 ~99 dirt
setblock ~34 ~116 ~100 dirt
setblock ~34 ~116 ~101 dirt
setblock ~34 ~116 ~102 dirt
setblock ~34 ~116 ~103 dirt
setblock ~34 ~116 ~104 dirt
setblock ~34 ~116 ~105 dirt
setblock ~34 ~116 ~106 dirt
setblock ~34 ~116 ~107 dirt
setblock ~34 ~116 ~108 dirt
setblock ~34 ~116 ~109 dirt
setblock ~34 ~116 ~110 dirt
setblock ~34 ~116 ~111 dirt
setblock ~34 ~116 ~114 dirt
setblock ~34 ~116 ~115 dirt
setblock ~34 ~116 ~116 dirt
setblock ~34 ~116 ~117 dirt
setblock ~34 ~116 ~118 dirt
setblock ~34 ~116 ~122 dirt
setblock ~34 ~117 ~78 dirt
setblock ~34 ~117 ~79 dirt
setblock ~34 ~117 ~80 dirt
setblock ~34 ~117 ~82 dirt
setblock ~34 ~117 ~83 dirt
setblock ~34 ~117 ~84 dirt
setblock ~34 ~117 ~85 dirt
setblock ~34 ~117 ~86 dirt
setblock ~34 ~117 ~87 dirt
setblock ~34 ~117 ~88 dirt
setblock ~34 ~117 ~89 dirt
setblock ~34 ~117 ~90 dirt
setblock ~34 ~117 ~91 dirt
setblock ~34 ~117 ~92 dirt
setblock ~34 ~117 ~93 dirt
setblock ~34 ~117 ~94 dirt
setblock ~34 ~117 ~95 dirt
setblock ~34 ~117 ~96 dirt
setblock ~34 ~117 ~97 dirt
setblock ~34 ~117 ~98 dirt
setblock ~34 ~117 ~99 dirt
setblock ~34 ~117 ~100 dirt
setblock ~34 ~117 ~101 dirt
setblock ~34 ~117 ~102 dirt
setblock ~34 ~117 ~103 dirt
setblock ~34 ~117 ~104 dirt
setblock ~34 ~117 ~105 dirt
setblock ~34 ~117 ~106 dirt
setblock ~34 ~117 ~107 dirt
setblock ~34 ~117 ~108 dirt
setblock ~34 ~117 ~109 dirt
setblock ~34 ~117 ~110 dirt
setblock ~34 ~117 ~111 dirt
setblock ~34 ~117 ~112 dirt
setblock ~34 ~117 ~114 dirt
setblock ~34 ~117 ~115 dirt
setblock ~34 ~117 ~116 dirt
setblock ~34 ~117 ~117 dirt
setblock ~34 ~117 ~118 dirt
setblock ~34 ~117 ~119 dirt
setblock ~34 ~117 ~120 dirt
setblock ~34 ~117 ~122 dirt
setblock ~34 ~117 ~123 dirt
setblock ~34 ~117 ~124 dirt
setblock ~34 ~118 ~78 dirt
setblock ~34 ~118 ~79 dirt
setblock ~34 ~118 ~80 dirt
setblock ~34 ~118 ~81 dirt
setblock ~34 ~118 ~82 dirt
setblock ~34 ~118 ~83 dirt
setblock ~34 ~118 ~84 dirt
setblock ~34 ~118 ~85 dirt
setblock ~34 ~118 ~86 dirt
setblock ~34 ~118 ~87 dirt
setblock ~34 ~118 ~88 dirt
setblock ~34 ~118 ~89 dirt
setblock ~34 ~118 ~90 dirt
setblock ~34 ~118 ~91 dirt
setblock ~34 ~118 ~92 dirt
setblock ~34 ~118 ~93 dirt
setblock ~34 ~118 ~94 dirt
setblock ~34 ~118 ~95 dirt
setblock ~34 ~118 ~96 dirt
setblock ~34 ~118 ~97 dirt
setblock ~34 ~118 ~98 dirt
setblock ~34 ~118 ~99 dirt
setblock ~34 ~118 ~100 dirt
setblock ~34 ~118 ~101 dirt
setblock ~34 ~118 ~102 dirt
setblock ~34 ~118 ~103 dirt
setblock ~34 ~118 ~104 dirt
setblock ~34 ~118 ~105 dirt
setblock ~34 ~118 ~106 dirt
setblock ~34 ~118 ~107 dirt
setblock ~34 ~118 ~108 dirt
setblock ~34 ~118 ~109 dirt
setblock ~34 ~118 ~110 dirt
setblock ~34 ~118 ~111 dirt
setblock ~34 ~118 ~112 dirt
setblock ~34 ~118 ~113 dirt
setblock ~34 ~118 ~114 dirt
setblock ~34 ~118 ~115 dirt
setblock ~34 ~118 ~116 dirt
setblock ~34 ~118 ~117 dirt
setblock ~34 ~118 ~118 dirt
setblock ~34 ~118 ~119 dirt
setblock ~34 ~118 ~120 dirt
setblock ~34 ~118 ~121 dirt
setblock ~34 ~118 ~122 dirt
setblock ~34 ~118 ~123 dirt
setblock ~34 ~118 ~124 dirt
setblock ~34 ~119 ~77 dirt
setblock ~34 ~119 ~78 dirt
setblock ~34 ~119 ~79 dirt
setblock ~34 ~119 ~80 dirt
setblock ~34 ~119 ~81 dirt
setblock ~34 ~119 ~82 dirt
setblock ~34 ~119 ~83 dirt
setblock ~34 ~119 ~84 dirt
setblock ~34 ~119 ~85 dirt
setblock ~34 ~119 ~86 dirt
setblock ~34 ~119 ~87 dirt
setblock ~34 ~119 ~88 dirt
setblock ~34 ~119 ~89 dirt
setblock ~34 ~119 ~90 dirt
setblock ~34 ~119 ~91 dirt
setblock ~34 ~119 ~92 dirt
setblock ~34 ~119 ~93 dirt
setblock ~34 ~119 ~94 dirt
setblock ~34 ~119 ~95 dirt
setblock ~34 ~119 ~96 dirt
setblock ~34 ~119 ~97 dirt
setblock ~34 ~119 ~98 dirt
setblock ~34 ~119 ~99 dirt
setblock ~34 ~119 ~100 dirt
setblock ~34 ~119 ~101 dirt
setblock ~34 ~119 ~102 dirt
setblock ~34 ~119 ~103 dirt
setblock ~34 ~119 ~104 dirt
setblock ~34 ~119 ~105 dirt
setblock ~34 ~119 ~106 dirt
setblock ~34 ~119 ~107 dirt
setblock ~34 ~119 ~108 dirt
setblock ~34 ~119 ~109 dirt
setblock ~34 ~119 ~110 dirt
setblock ~34 ~119 ~111 dirt
setblock ~34 ~119 ~112 dirt
setblock ~34 ~119 ~113 dirt
setblock ~34 ~119 ~114 dirt
setblock ~34 ~119 ~115 dirt
setblock ~34 ~119 ~116 dirt
setblock ~34 ~119 ~117 dirt
setblock ~34 ~119 ~118 dirt
setblock ~34 ~119 ~119 dirt
setblock ~34 ~119 ~120 dirt
setblock ~34 ~119 ~121 dirt
setblock ~34 ~119 ~122 dirt
setblock ~34 ~119 ~123 dirt
setblock ~34 ~119 ~124 dirt
setblock ~34 ~119 ~125 dirt
setblock ~34 ~120 ~75 dirt
setblock ~34 ~120 ~77 dirt
setblock ~34 ~120 ~78 dirt
setblock ~34 ~120 ~79 dirt
setblock ~34 ~120 ~80 dirt
setblock ~34 ~120 ~81 dirt
setblock ~34 ~120 ~82 dirt
setblock ~34 ~120 ~83 dirt
setblock ~34 ~120 ~84 dirt
setblock ~34 ~120 ~85 dirt
setblock ~34 ~120 ~86 dirt
setblock ~34 ~120 ~87 dirt
setblock ~34 ~120 ~88 dirt
setblock ~34 ~120 ~89 dirt
setblock ~34 ~120 ~90 dirt
setblock ~34 ~120 ~91 dirt
setblock ~34 ~120 ~92 dirt
setblock ~34 ~120 ~93 dirt
setblock ~34 ~120 ~94 dirt
setblock ~34 ~120 ~95 dirt
setblock ~34 ~120 ~96 dirt
setblock ~34 ~120 ~97 dirt
setblock ~34 ~120 ~98 dirt
setblock ~34 ~120 ~99 dirt
setblock ~34 ~120 ~100 dirt
setblock ~34 ~120 ~101 dirt
setblock ~34 ~120 ~102 dirt
setblock ~34 ~120 ~103 dirt
setblock ~34 ~120 ~104 dirt
setblock ~34 ~120 ~105 dirt
setblock ~34 ~120 ~106 dirt
setblock ~34 ~120 ~107 dirt
setblock ~34 ~120 ~108 dirt
setblock ~34 ~120 ~109 dirt
setblock ~34 ~120 ~110 dirt
setblock ~34 ~120 ~111 dirt
setblock ~34 ~120 ~112 dirt
setblock ~34 ~120 ~113 dirt
setblock ~34 ~120 ~114 dirt
setblock ~34 ~120 ~115 dirt
setblock ~34 ~120 ~116 dirt
setblock ~34 ~120 ~117 dirt
setblock ~34 ~120 ~118 dirt
setblock ~34 ~120 ~119 dirt
setblock ~34 ~120 ~120 dirt
