setblock ~0 ~1 ~0 gold_block
setblock ~6 ~121 ~80 dirt
setblock ~6 ~122 ~80 dirt
setblock ~6 ~123 ~80 dirt
setblock ~6 ~124 ~80 dirt
setblock ~6 ~125 ~80 dirt
setblock ~6 ~126 ~80 dirt
setblock ~6 ~127 ~80 grass_block
setblock ~7 ~120 ~80 dirt
setblock ~7 ~121 ~79 dirt
setblock ~7 ~121 ~80 dirt
setblock ~7 ~121 ~81 dirt
setblock ~7 ~121 ~115 dirt
setblock ~7 ~121 ~116 dirt
setblock ~7 ~121 ~120 dirt
setblock ~7 ~122 ~79 dirt
setblock ~7 ~122 ~80 dirt
setblock ~7 ~122 ~81 dirt
setblock ~7 ~122 ~115 dirt
setblock ~7 ~122 ~116 dirt
setblock ~7 ~122 ~120 dirt
setblock ~7 ~123 ~79 dirt
setblock ~7 ~123 ~80 dirt
setblock ~7 ~123 ~81 dirt
setblock ~7 ~123 ~115 dirt
setblock ~7 ~123 ~116 dirt
setblock ~7 ~123 ~120 dirt
setblock ~7 ~124 ~79 dirt
setblock ~7 ~124 ~80 dirt
setblock ~7 ~124 ~81 dirt
setblock ~7 ~124 ~115 dirt
setblock ~7 ~124 ~116 dirt
setblock ~7 ~124 ~120 dirt
setblock ~7 ~125 ~79 dirt
setblock ~7 ~125 ~80 dirt
setblock ~7 ~125 ~81 dirt
setblock ~7 ~125 ~115 dirt
setblock ~7 ~125 ~116 dirt
setblock ~7 ~125 ~120 grass_block
setblock ~7 ~126 ~79 dirt
setblock ~7 ~126 ~80 dirt
setblock ~7 ~126 ~81 grass_block
setblock ~7 ~126 ~115 grass_block
setblock ~7 ~126 ~116 grass_block
setblock ~7 ~127 ~79 grass_block
setblock ~7 ~127 ~80 grass_block
setblock ~7 ~127 ~115 short_grass
setblock ~7 ~128 ~80 poppy
setblock ~8 ~119 ~80 dirt
setblock ~8 ~119 ~115 dirt
setblock ~8 ~119 ~116 dirt
setblock ~8 ~120 ~79 dirt
setblock ~8 ~120 ~80 dirt
setblock ~8 ~120 ~81 dirt
setblock ~8 ~120 ~111 dirt
setblock ~8 ~120 ~114 dirt
setblock ~8 ~120 ~115 dirt
setblock ~8 ~120 ~116 dirt
setblock ~8 ~120 ~117 dirt
setblock ~8 ~120 ~120 dirt
setblock ~8 ~121 ~79 dirt
setblock ~8 ~121 ~80 dirt
setblock ~8 ~121 ~81 dirt
setblock ~8 ~121 ~82 dirt
setblock ~8 ~121 ~110 dirt
setblock ~8 ~121 ~111 dirt
setblock ~8 ~121 ~112 dirt
setblock ~8 ~121 ~114 dirt
setblock ~8 ~121 ~115 dirt
setblock ~8 ~121 ~116 dirt
setblock ~8 ~121 ~117 dirt
setblock ~8 ~121 ~119 dirt
setblock ~8 ~121 ~120 dirt
setblock ~8 ~121 ~121 dirt
setblock ~8 ~121 ~122 dirt
setblock ~8 ~122 ~79 dirt
setblock ~8 ~122 ~80 dirt
setblock ~8 ~122 ~81 dirt
setblock ~8 ~122 ~82 dirt
setblock ~8 ~122 ~110 dirt
setblock ~8 ~122 ~111 dirt
setblock ~8 ~122 ~112 dirt
setblock ~8 ~122 ~114 dirt
setblock ~8 ~122 ~115 dirt
setblock ~8 ~122 ~116 dirt
setblock ~8 ~122 ~117 dirt
setblock ~8 ~122 ~119 dirt
setblock ~8 ~122 ~120 dirt
setblock ~8 ~122 ~121 dirt
setblock ~8 ~122 ~122 dirt
setblock ~8 ~123 ~79 dirt
setblock ~8 ~123 ~80 dirt
setblock ~8 ~123 ~81 dirt
setblock ~8 ~123 ~82 dirt
setblock ~8 ~123 ~110 dirt
setblock ~8 ~123 ~111 dirt
setblock ~8 ~123 ~112 dirt
setblock ~8 ~123 ~114 dirt
setblock ~8 ~123 ~115 dirt
setblock ~8 ~123 ~116 dirt
setblock ~8 ~123 ~117 dirt
setblock ~8 ~123 ~119 dirt
setblock ~8 ~123 ~120 dirt
setblock ~8 ~123 ~121 dirt
setblock ~8 ~123 ~122 dirt
setblock ~8 ~124 ~79 dirt
setblock ~8 ~124 ~80 dirt
setblock ~8 ~124 ~81 dirt
setblock ~8 ~124 ~82 dirt
setblock ~8 ~124 ~110 dirt
setblock ~8 ~124 ~111 dirt
setblock ~8 ~124 ~112 dirt
setblock ~8 ~124 ~114 dirt
setblock ~8 ~124 ~115 dirt
setblock ~8 ~124 ~116 dirt
setblock ~8 ~124 ~117 dirt
setblock ~8 ~124 ~119 dirt
setblock ~8 ~124 ~120 dirt
setblock ~8 ~124 ~121 dirt
setblock ~8 ~124 ~122 dirt
setblock ~8 ~125 ~79 dirt
setblock ~8 ~125 ~80 dirt
setblock ~8 ~125 ~81 dirt
setblock ~8 ~125 ~82 dirt
setblock ~8 ~125 ~110 grass_block
setblock ~8 ~125 ~111 grass_block
setblock ~8 ~125 ~112 grass_block
setblock ~8 ~125 ~114 grass_block
setblock ~8 ~125 ~115 grass_block
setblock ~8 ~125 ~116 grass_block
setblock ~8 ~125 ~117 grass_block
setblock ~8 ~125 ~119 grass_block
setblock ~8 ~125 ~120 grass_block
setblock ~8 ~125 ~121 grass_block
setblock ~8 ~125 ~122 grass_block
setblock ~8 ~126 ~79 grass_block
setblock ~8 ~126 ~80 dirt
setblock ~8 ~126 ~81 grass_block
setblock ~8 ~126 ~82 grass_block
setblock ~8 ~126 ~111 fern
setblock ~8 ~126 ~114 fern
setblock ~8 ~126 ~115 short_grass
setblock ~8 ~127 ~80 grass_block
setblock ~8 ~127 ~82 short_grass
setblock ~9 ~116 ~111 dirt
setblock ~9 ~116 ~115 dirt
setblock ~9 ~117 ~80 dirt
setblock ~9 ~117 ~111 dirt
setblock ~9 ~117 ~115 dirt
setblock ~9 ~117 ~116 dirt
setblock ~9 ~117 ~117 dirt
setblock ~9 ~117 ~120 dirt
setblock ~9 ~117 ~121 dirt
setblock ~9 ~118 ~80 dirt
setblock ~9 ~118 ~81 dirt
setblock ~9 ~118 ~110 dirt
setblock ~9 ~118 ~111 dirt
setblock ~9 ~118 ~115 dirt
setblock ~9 ~118 ~116 dirt
setblock ~9 ~118 ~117 dirt
setblock ~9 ~118 ~118 dirt
setblock ~9 ~118 ~120 dirt
setblock ~9 ~118 ~121 dirt
setblock ~9 ~118 ~122 dirt
setblock ~9 ~119 ~79 dirt
setblock ~9 ~119 ~80 dirt
setblock ~9 ~119 ~81 dirt
setblock ~9 ~119 ~110 dirt
setblock ~9 ~119 ~111 dirt
setblock ~9 ~119 ~113 dirt
setblock ~9 ~119 ~114 dirt
setblock ~9 ~119 ~115 dirt
setblock ~9 ~119 ~116 dirt
setblock ~9 ~119 ~117 dirt
setblock ~9 ~119 ~118 dirt
setblock ~9 ~119 ~119 dirt
setblock ~9 ~119 ~120 dirt
setblock ~9 ~119 ~121 dirt
setblock ~9 ~119 ~122 dirt
setblock ~9 ~120 ~79 dirt
setblock ~9 ~120 ~80 dirt
setblock ~9 ~120 ~81 dirt
setblock ~9 ~120 ~82 dirt
setblock ~9 ~120 ~110 dirt
setblock ~9 ~120 ~111 dirt
setblock ~9 ~120 ~112 dirt
setblock ~9 ~120 ~113 dirt
setblock ~9 ~120 ~114 dirt
setblock ~9 ~120 ~115 dirt
setblock ~9 ~120 ~116 dirt
setblock ~9 ~120 ~117 dirt
setblock ~9 ~120 ~118 dirt
setblock ~9 ~120 ~119 dirt
setblock ~9 ~120 ~120 dirt
setblock ~9 ~120 ~121 dirt
setblock ~9 ~120 ~122 dirt
setblock ~9 ~121 ~79 dirt
setblock ~9 ~121 ~80 dirt
setblock ~9 ~121 ~81 dirt
setblock ~9 ~121 ~82 dirt
setblock ~9 ~121 ~83 dirt
setblock ~9 ~121 ~109 dirt
setblock ~9 ~121 ~110 dirt
setblock ~9 ~121 ~111 dirt
setblock ~9 ~121 ~112 dirt
setblock ~9 ~121 ~113 dirt
setblock ~9 ~121 ~114 dirt
setblock ~9 ~121 ~115 dirt
setblock ~9 ~121 ~116 dirt
setblock ~9 ~121 ~117 dirt
setblock ~9 ~121 ~118 dirt
setblock ~9 ~121 ~119 dirt
setblock ~9 ~121 ~120 dirt
setblock ~9 ~121 ~121 dirt
setblock ~9 ~121 ~122 dirt
setblock ~9 ~121 ~123 dirt
setblock ~9 ~122 ~79 dirt
setblock ~9 ~122 ~80 dirt
setblock ~9 ~122 ~81 dirt
setblock ~9 ~122 ~82 dirt
setblock ~9 ~122 ~83 dirt
setblock ~9 ~122 ~109 dirt
setblock ~9 ~122 ~110 dirt
setblock ~9 ~122 ~111 dirt
setblock ~9 ~122 ~112 dirt
setblock ~9 ~122 ~113 dirt
setblock ~9 ~122 ~114 dirt
setblock ~9 ~122 ~115 dirt
setblock ~9 ~122 ~116 dirt
setblock ~9 ~122 ~117 dirt
setblock ~9 ~122 ~118 dirt
setblock ~9 ~122 ~119 dirt
setblock ~9 ~122 ~120 dirt
setblock ~9 ~122 ~121 dirt
setblock ~9 ~122 ~122 dirt
setblock ~9 ~122 ~123 dirt
setblock ~9 ~123 ~79 dirt
setblock ~9 ~123 ~80 dirt
setblock ~9 ~123 ~81 dirt
setblock ~9 ~123 ~82 dirt
setblock ~9 ~123 ~83 dirt
setblock ~9 ~123 ~109 dirt
setblock ~9 ~123 ~110 dirt
setblock ~9 ~123 ~111 dirt
setblock ~9 ~123 ~112 dirt
setblock ~9 ~123 ~113 dirt
setblock ~9 ~123 ~114 dirt
setblock ~9 ~123 ~115 dirt
setblock ~9 ~123 ~116 dirt
setblock ~9 ~123 ~117 dirt
setblock ~9 ~123 ~118 dirt
setblock ~9 ~123 ~119 dirt
setblock ~9 ~123 ~120 dirt
setblock ~9 ~123 ~121 dirt
setblock ~9 ~123 ~122 dirt
setblock ~9 ~123 ~123 dirt
setblock ~9 ~124 ~79 dirt
setblock ~9 ~124 ~80 dirt
setblock ~9 ~124 ~81 dirt
setblock ~9 ~124 ~82 dirt
setblock ~9 ~124 ~83 dirt
setblock ~9 ~124 ~109 dirt
setblock ~9 ~124 ~110 dirt
setblock ~9 ~124 ~111 dirt
setblock ~9 ~124 ~112 dirt
setblock ~9 ~124 ~113 dirt
setblock ~9 ~124 ~114 dirt
setblock ~9 ~124 ~115 dirt
setblock ~9 ~124 ~116 dirt
setblock ~9 ~124 ~117 dirt
setblock ~9 ~124 ~118 dirt
setblock ~9 ~124 ~119 dirt
setblock ~9 ~124 ~120 dirt
setblock ~9 ~124 ~121 dirt
setblock ~9 ~124 ~122 dirt
setblock ~9 ~124 ~123 dirt
setblock ~9 ~125 ~79 dirt
setblock ~9 ~125 ~80 dirt
setblock ~9 ~125 ~81 dirt
setblock ~9 ~125 ~82 dirt
setblock ~9 ~125 ~83 grass_block
setblock ~9 ~125 ~109 grass_block
setblock ~9 ~125 ~110 grass_block
setblock ~9 ~125 ~111 grass_block
setblock ~9 ~125 ~112 grass_block
setblock ~9 ~125 ~113 grass_block
setblock ~9 ~125 ~114 grass_block
setblock ~9 ~125 ~115 grass_block
setblock ~9 ~125 ~116 grass_block
setblock ~9 ~125 ~117 grass_block
setblock ~9 ~125 ~118 grass_block
setblock ~9 ~125 ~119 grass_block
setblock ~9 ~125 ~120 grass_block
setblock ~9 ~125 ~121 grass_block
setblock ~9 ~125 ~122 grass_block
setblock ~9 ~125 ~123 grass_block
setblock ~9 ~126 ~79 grass_block
setblock ~9 ~126 ~80 grass_block
setblock ~9 ~126 ~81 grass_block
setblock ~9 ~126 ~82 grass_block
setblock ~9 ~126 ~111 short_grass
setblock ~9 ~126 ~113 short_grass
setblock ~9 ~126 ~116 short_grass
setblock ~10 ~113 ~111 dirt
setblock ~10 ~113 ~117 dirt
setblock ~10 ~114 ~111 dirt
setblock ~10 ~114 ~116 dirt
setblock ~10 ~114 ~117 dirt
setblock ~10 ~115 ~111 dirt
setblock ~10 ~115 ~115 dirt
setblock ~10 ~115 ~116 dirt
setblock ~10 ~115 ~117 dirt
setblock ~10 ~116 ~80 dirt
setblock ~10 ~116 ~110 dirt
setblock ~10 ~116 ~111 dirt
setblock ~10 ~116 ~112 dirt
setblock ~10 ~116 ~114 dirt
setblock ~10 ~116 ~115 dirt
setblock ~10 ~116 ~116 dirt
setblock ~10 ~116 ~117 dirt
setblock ~10 ~116 ~118 dirt
setblock ~10 ~116 ~119 dirt
setblock ~10 ~116 ~120 dirt
setblock ~10 ~116 ~121 dirt
setblock ~10 ~117 ~79 dirt
setblock ~10 ~117 ~80 dirt
setblock ~10 ~117 ~81 dirt
setblock ~10 ~117 ~110 dirt
setblock ~10 ~117 ~111 dirt
setblock ~10 ~117 ~112 dirt
setblock ~10 ~117 ~113 dirt
setblock ~10 ~117 ~114 dirt
setblock ~10 ~117 ~115 dirt
setblock ~10 ~117 ~116 dirt
setblock ~10 ~117 ~117 dirt
setblock ~10 ~117 ~118 dirt
setblock ~10 ~117 ~119 dirt
setblock ~10 ~117 ~120 dirt
setblock ~10 ~117 ~121 dirt
setblock ~10 ~117 ~122 dirt
setblock ~10 ~118 ~79 dirt
setblock ~10 ~118 ~80 dirt
setblock ~10 ~118 ~81 dirt
setblock ~10 ~118 ~82 dirt
setblock ~10 ~118 ~109 dirt
setblock ~10 ~118 ~110 dirt
setblock ~10 ~118 ~111 dirt
setblock ~10 ~118 ~112 dirt
setblock ~10 ~118 ~113 dirt
setblock ~10 ~118 ~114 dirt
setblock ~10 ~118 ~115 dirt
setblock ~10 ~118 ~116 dirt
setblock ~10 ~118 ~117 dirt
setblock ~10 ~118 ~118 dirt
setblock ~10 ~118 ~119 dirt
setblock ~10 ~118 ~120 dirt
setblock ~10 ~118 ~121 dirt
setblock ~10 ~118 ~122 dirt
setblock ~10 ~118 ~123 dirt
setblock ~10 ~119 ~79 dirt
setblock ~10 ~119 ~80 dirt
setblock ~10 ~119 ~81 dirt
setblock ~10 ~119 ~82 dirt
setblock ~10 ~119 ~109 dirt
setblock ~10 ~119 ~110 dirt
setblock ~10 ~119 ~111 dirt
setblock ~10 ~119 ~112 dirt
setblock ~10 ~119 ~113 dirt
setblock ~10 ~119 ~114 dirt
setblock ~10 ~119 ~115 dirt
setblock ~10 ~119 ~116 dirt
setblock ~10 ~119 ~117 dirt
setblock ~10 ~119 ~118 dirt
setblock ~10 ~119 ~119 dirt
setblock ~10 ~119 ~120 dirt
setblock ~10 ~119 ~121 dirt
setblock ~10 ~119 ~122 dirt
setblock ~10 ~119 ~123 dirt
setblock ~10 ~120 ~78 dirt
setblock ~10 ~120 ~79 dirt
setblock ~10 ~120 ~80 dirt
setblock ~10 ~120 ~81 dirt
setblock ~10 ~120 ~82 dirt
setblock ~10 ~120 ~108 dirt
setblock ~10 ~120 ~109 dirt
setblock ~10 ~120 ~110 dirt
setblock ~10 ~120 ~111 dirt
setblock ~10 ~120 ~112 dirt
setblock ~10 ~120 ~113 dirt
setblock ~10 ~120 ~114 dirt
setblock ~10 ~120 ~115 dirt
setblock ~10 ~120 ~116 dirt
setblock ~10 ~120 ~117 dirt
setblock ~10 ~120 ~118 dirt
setblock ~10 ~120 ~119 dirt
setblock ~10 ~120 ~120 dirt
setblock ~10 ~120 ~121 dirt
setblock ~10 ~120 ~122 dirt
setblock ~10 ~120 ~123 dirt
setblock ~10 ~120 ~125 dirt
setblock ~10 ~120 ~127 dirt
setblock ~10 ~121 ~78 dirt
setblock ~10 ~121 ~79 dirt
setblock ~10 ~121 ~80 dirt
setblock ~10 ~121 ~81 dirt
setblock ~10 ~121 ~82 dirt
setblock ~10 ~121 ~83 dirt
setblock ~10 ~121 ~107 dirt
setblock ~10 ~121 ~108 dirt
setblock ~10 ~121 ~109 dirt
setblock ~10 ~121 ~110 dirt
setblock ~10 ~121 ~111 dirt
setblock ~10 ~121 ~112 dirt
setblock ~10 ~121 ~113 dirt
setblock ~10 ~121 ~114 dirt
setblock ~10 ~121 ~115 dirt
setblock ~10 ~121 ~116 dirt
setblock ~10 ~121 ~117 dirt
setblock ~10 ~121 ~118 dirt
setblock ~10 ~121 ~119 dirt
setblock ~10 ~121 ~120 dirt
setblock ~10 ~121 ~121 dirt
setblock ~10 ~121 ~122 dirt
setblock ~10 ~121 ~123 dirt
setblock ~10 ~121 ~124 dirt
setblock ~10 ~121 ~125 dirt
setblock ~10 ~121 ~126 dirt
setblock ~10 ~121 ~127 dirt
setblock ~10 ~122 ~78 dirt
setblock ~10 ~122 ~79 dirt
setblock ~10 ~122 ~80 dirt
setblock ~10 ~122 ~81 dirt
setblock ~10 ~122 ~82 dirt
setblock ~10 ~122 ~83 dirt
setblock ~10 ~122 ~107 dirt
setblock ~10 ~122 ~108 dirt
setblock ~10 ~122 ~109 dirt
setblock ~10 ~122 ~110 dirt
setblock ~10 ~122 ~111 dirt
setblock ~10 ~122 ~112 dirt
setblock ~10 ~122 ~113 dirt
setblock ~10 ~122 ~114 dirt
setblock ~10 ~122 ~115 dirt
setblock ~10 ~122 ~116 dirt
setblock ~10 ~122 ~117 dirt
setblock ~10 ~122 ~118 dirt
setblock ~10 ~122 ~119 dirt
setblock ~10 ~122 ~120 dirt
setblock ~10 ~122 ~121 dirt
setblock ~10 ~122 ~122 dirt
setblock ~10 ~122 ~123 dirt
setblock ~10 ~122 ~124 dirt
setblock ~10 ~122 ~125 dirt
setblock ~10 ~122 ~126 dirt
setblock ~10 ~122 ~127 dirt
setblock ~10 ~123 ~78 dirt
setblock ~10 ~123 ~79 dirt
setblock ~10 ~123 ~80 dirt
setblock ~10 ~123 ~81 dirt
setblock ~10 ~123 ~82 dirt
setblock ~10 ~123 ~83 dirt
setblock ~10 ~123 ~107 dirt
setblock ~10 ~123 ~108 dirt
setblock ~10 ~123 ~109 dirt
setblock ~10 ~123 ~110 dirt
setblock ~10 ~123 ~111 dirt
setblock ~10 ~123 ~112 dirt
setblock ~10 ~123 ~113 dirt
setblock ~10 ~123 ~114 dirt
setblock ~10 ~123 ~115 dirt
setblock ~10 ~123 ~116 dirt
setblock ~10 ~123 ~117 dirt
setblock ~10 ~123 ~118 dirt
setblock ~10 ~123 ~119 dirt
setblock ~10 ~123 ~120 dirt
setblock ~10 ~123 ~121 dirt
setblock ~10 ~123 ~122 dirt
setblock ~10 ~123 ~123 dirt
setblock ~10 ~123 ~124 dirt
setblock ~10 ~123 ~125 dirt
setblock ~10 ~123 ~126 dirt
setblock ~10 ~123 ~127 dirt
setblock ~10 ~124 ~78 dirt
setblock ~10 ~124 ~79 dirt
setblock ~10 ~124 ~80 dirt
setblock ~10 ~124 ~81 dirt
setblock ~10 ~124 ~82 dirt
setblock ~10 ~124 ~83 dirt
setblock ~10 ~124 ~107 dirt
setblock ~10 ~124 ~108 dirt
setblock ~10 ~124 ~109 dirt
setblock ~10 ~124 ~110 grass_block
setblock ~10 ~124 ~111 dirt
setblock ~10 ~124 ~112 dirt
setblock ~10 ~124 ~113 dirt
setblock ~10 ~124 ~114 dirt
setblock ~10 ~124 ~115 dirt
setblock ~10 ~124 ~116 dirt
setblock ~10 ~124 ~117 dirt
setblock ~10 ~124 ~118 dirt
setblock ~10 ~124 ~119 dirt
setblock ~10 ~124 ~120 dirt
setblock ~10 ~124 ~121 dirt
setblock ~10 ~124 ~122 dirt
setblock ~10 ~124 ~123 dirt
setblock ~10 ~124 ~124 dirt
setblock ~10 ~124 ~125 dirt
setblock ~10 ~124 ~126 dirt
setblock ~10 ~124 ~127 dirt
setblock ~10 ~125 ~78 dirt
setblock ~10 ~125 ~79 dirt
setblock ~10 ~125 ~80 dirt
setblock ~10 ~125 ~81 dirt
setblock ~10 ~125 ~82 dirt
setblock ~10 ~125 ~83 grass_block
setblock ~10 ~125 ~107 grass_block
setblock ~10 ~125 ~108 grass_block
setblock ~10 ~125 ~109 grass_block
setblock ~10 ~125 ~111 grass_block
setblock ~10 ~125 ~112 grass_block
setblock ~10 ~125 ~113 grass_block
setblock ~10 ~125 ~114 grass_block
setblock ~10 ~125 ~115 grass_block
setblock ~10 ~125 ~116 grass_block
setblock ~10 ~125 ~117 grass_block
setblock ~10 ~125 ~118 grass_block
setblock ~10 ~125 ~119 grass_block
setblock ~10 ~125 ~120 grass_block
setblock ~10 ~125 ~121 grass_block
setblock ~10 ~125 ~122 grass_block
setblock ~10 ~125 ~123 grass_block
setblock ~10 ~125 ~124 grass_block
setblock ~10 ~125 ~125 grass_block
setblock ~10 ~125 ~126 grass_block
setblock ~10 ~125 ~127 grass_block
setblock ~10 ~126 ~78 grass_block
setblock ~10 ~126 ~79 grass_block
setblock ~10 ~126 ~80 grass_block
setblock ~10 ~126 ~81 grass_block
setblock ~10 ~126 ~82 grass_block
setblock ~10 ~126 ~107 short_grass
setblock ~10 ~126 ~114 poppy
setblock ~10 ~126 ~115 short_grass
setblock ~10 ~126 ~117 short_grass
setblock ~10 ~126 ~119 short_grass
setblock ~10 ~126 ~124 short_grass
setblock ~10 ~126 ~125 short_grass
setblock ~10 ~126 ~126 short_grass
setblock ~10 ~127 ~80 short_grass
setblock ~10 ~127 ~81 short_grass
setblock ~11 ~111 ~117 dirt
setblock ~11 ~112 ~111 dirt
setblock ~11 ~112 ~112 dirt
setblock ~11 ~112 ~117 dirt
setblock ~11 ~112 ~118 dirt
setblock ~11 ~113 ~80 dirt
setblock ~11 ~113 ~110 dirt
setblock ~11 ~113 ~111 dirt
setblock ~11 ~113 ~112 dirt
setblock ~11 ~113 ~114 dirt
setblock ~11 ~113 ~115 dirt
setblock ~11 ~113 ~116 dirt
setblock ~11 ~113 ~117 dirt
setblock ~11 ~113 ~118 dirt
setblock ~11 ~113 ~119 dirt
setblock ~11 ~114 ~80 dirt
setblock ~11 ~114 ~110 dirt
setblock ~11 ~114 ~111 dirt
setblock ~11 ~114 ~112 dirt
setblock ~11 ~114 ~114 dirt
setblock ~11 ~114 ~115 dirt
setblock ~11 ~114 ~116 dirt
setblock ~11 ~114 ~117 dirt
setblock ~11 ~114 ~118 dirt
setblock ~11 ~114 ~119 dirt
setblock ~11 ~114 ~120 dirt
setblock ~11 ~114 ~121 dirt
setblock ~11 ~115 ~80 dirt
setblock ~11 ~115 ~110 dirt
setblock ~11 ~115 ~111 dirt
setblock ~11 ~115 ~112 dirt
setblock ~11 ~115 ~113 dirt
setblock ~11 ~115 ~114 dirt
setblock ~11 ~115 ~115 dirt
setblock ~11 ~115 ~116 dirt
setblock ~11 ~115 ~117 dirt
setblock ~11 ~115 ~118 dirt
setblock ~11 ~115 ~119 dirt
setblock ~11 ~115 ~120 dirt
setblock ~11 ~115 ~121 dirt
setblock ~11 ~116 ~79 dirt
setblock ~11 ~116 ~80 dirt
setblock ~11 ~116 ~81 dirt
setblock ~11 ~116 ~109 dirt
setblock ~11 ~116 ~110 dirt
setblock ~11 ~116 ~111 dirt
setblock ~11 ~116 ~112 dirt
setblock ~11 ~116 ~113 dirt
setblock ~11 ~116 ~114 dirt
setblock ~11 ~116 ~115 dirt
setblock ~11 ~116 ~116 dirt
setblock ~11 ~116 ~117 dirt
setblock ~11 ~116 ~118 dirt
setblock ~11 ~116 ~119 dirt
setblock ~11 ~116 ~120 dirt
setblock ~11 ~116 ~121 dirt
setblock ~11 ~116 ~122 dirt
setblock ~11 ~117 ~79 dirt
setblock ~11 ~117 ~80 dirt
setblock ~11 ~117 ~81 dirt
setblock ~11 ~117 ~82 dirt
setblock ~11 ~117 ~108 dirt
setblock ~11 ~117 ~109 dirt
setblock ~11 ~117 ~110 dirt
setblock ~11 ~117 ~111 dirt
setblock ~11 ~117 ~112 dirt
setblock ~11 ~117 ~113 dirt
setblock ~11 ~117 ~114 dirt
setblock ~11 ~117 ~115 dirt
setblock ~11 ~117 ~116 dirt
setblock ~11 ~117 ~117 dirt
setblock ~11 ~117 ~118 dirt
setblock ~11 ~117 ~119 dirt
setblock ~11 ~117 ~120 dirt
setblock ~11 ~117 ~121 dirt
setblock ~11 ~117 ~122 dirt
setblock ~11 ~117 ~123 dirt
setblock ~11 ~118 ~79 dirt
setblock ~11 ~118 ~80 dirt
setblock ~11 ~118 ~81 dirt
setblock ~11 ~118 ~82 dirt
setblock ~11 ~118 ~108 dirt
setblock ~11 ~118 ~109 dirt
setblock ~11 ~118 ~110 dirt
setblock ~11 ~118 ~111 dirt
setblock ~11 ~118 ~112 dirt
setblock ~11 ~118 ~113 dirt
setblock ~11 ~118 ~114 dirt
setblock ~11 ~118 ~115 dirt
setblock ~11 ~118 ~116 dirt
setblock ~11 ~118 ~117 dirt
setblock ~11 ~118 ~118 dirt
setblock ~11 ~118 ~119 dirt
setblock ~11 ~118 ~120 dirt
setblock ~11 ~118 ~121 dirt
setblock ~11 ~118 ~122 dirt
setblock ~11 ~118 ~123 dirt
setblock ~11 ~118 ~125 dirt
setblock ~11 ~119 ~78 dirt
setblock ~11 ~119 ~79 dirt
setblock ~11 ~119 ~80 dirt
setblock ~11 ~119 ~81 dirt
setblock ~11 ~119 ~82 dirt
setblock ~11 ~119 ~107 dirt
setblock ~11 ~119 ~108 dirt
setblock ~11 ~119 ~109 dirt
setblock ~11 ~119 ~110 dirt
setblock ~11 ~119 ~111 dirt
setblock ~11 ~119 ~112 dirt
setblock ~11 ~119 ~113 dirt
setblock ~11 ~119 ~114 dirt
setblock ~11 ~119 ~115 dirt
setblock ~11 ~119 ~116 dirt
setblock ~11 ~119 ~117 dirt
setblock ~11 ~119 ~118 dirt
setblock ~11 ~119 ~119 dirt
setblock ~11 ~119 ~120 dirt
setblock ~11 ~119 ~121 dirt
setblock ~11 ~119 ~122 dirt
setblock ~11 ~119 ~123 dirt
setblock ~11 ~119 ~124 dirt
setblock ~11 ~119 ~125 dirt
setblock ~11 ~119 ~127 dirt
setblock ~11 ~119 ~129 dirt
setblock ~11 ~120 ~77 dirt
setblock ~11 ~120 ~78 dirt
setblock ~11 ~120 ~79 dirt
setblock ~11 ~120 ~80 dirt
setblock ~11 ~120 ~81 dirt
setblock ~11 ~120 ~82 dirt
setblock ~11 ~120 ~107 dirt
setblock ~11 ~120 ~108 dirt
setblock ~11 ~120 ~109 dirt
setblock ~11 ~120 ~110 dirt
setblock ~11 ~120 ~111 dirt
setblock ~11 ~120 ~112 dirt
setblock ~11 ~120 ~113 dirt
setblock ~11 ~120 ~114 dirt
setblock ~11 ~120 ~115 dirt
setblock ~11 ~120 ~116 dirt
setblock ~11 ~120 ~117 dirt
setblock ~11 ~120 ~118 dirt
setblock ~11 ~120 ~119 dirt
setblock ~11 ~120 ~120 dirt
setblock ~11 ~120 ~121 dirt
setblock ~11 ~120 ~122 dirt
setblock ~11 ~120 ~123 dirt
setblock ~11 ~120 ~124 dirt
setblock ~11 ~120 ~125 dirt
setblock ~11 ~120 ~126 dirt
setblock ~11 ~120 ~127 dirt
setblock ~11 ~120 ~128 dirt
setblock ~11 ~120 ~129 dirt
setblock ~11 ~121 ~77 dirt
setblock ~11 ~121 ~78 dirt
setblock ~11 ~121 ~79 dirt
setblock ~11 ~121 ~80 dirt
setblock ~11 ~121 ~81 dirt
setblock ~11 ~121 ~82 dirt
setblock ~11 ~121 ~83 dirt
setblock ~11 ~121 ~106 dirt
setblock ~11 ~121 ~107 dirt
setblock ~11 ~121 ~108 dirt
setblock ~11 ~121 ~109 dirt
setblock ~11 ~121 ~110 dirt
setblock ~11 ~121 ~111 dirt
setblock ~11 ~121 ~112 dirt
setblock ~11 ~121 ~113 dirt
setblock ~11 ~121 ~114 dirt
setblock ~11 ~121 ~115 dirt
setblock ~11 ~121 ~116 dirt
setblock ~11 ~121 ~117 dirt
setblock ~11 ~121 ~118 dirt
setblock ~11 ~121 ~119 dirt
setblock ~11 ~121 ~120 dirt
setblock ~11 ~121 ~121 dirt
setblock ~11 ~121 ~122 dirt
setblock ~11 ~121 ~123 dirt
setblock ~11 ~121 ~124 dirt
setblock ~11 ~121 ~125 dirt
setblock ~11 ~121 ~126 dirt
setblock ~11 ~121 ~127 dirt
setblock ~11 ~121 ~128 dirt
setblock ~11 ~121 ~129 dirt
setblock ~11 ~121 ~130 dirt
setblock ~11 ~122 ~77 dirt
setblock ~11 ~122 ~78 dirt
setblock ~11 ~122 ~79 dirt
setblock ~11 ~122 ~80 dirt
setblock ~11 ~122 ~81 dirt
setblock ~11 ~122 ~82 dirt
setblock ~11 ~122 ~83 dirt
setblock ~11 ~122 ~106 dirt
setblock ~11 ~122 ~107 dirt
setblock ~11 ~122 ~108 dirt
setblock ~11 ~122 ~109 dirt
setblock ~11 ~122 ~110 dirt
setblock ~11 ~122 ~111 dirt
setblock ~11 ~122 ~112 dirt
setblock ~11 ~122 ~113 dirt
setblock ~11 ~122 ~114 dirt
setblock ~11 ~122 ~115 dirt
setblock ~11 ~122 ~116 dirt
setblock ~11 ~122 ~117 dirt
setblock ~11 ~122 ~118 dirt
setblock ~11 ~122 ~119 dirt
setblock ~11 ~122 ~120 dirt
setblock ~11 ~122 ~121 dirt
setblock ~11 ~122 ~122 dirt
setblock ~11 ~122 ~123 dirt
setblock ~11 ~122 ~124 dirt
setblock ~11 ~122 ~125 dirt
setblock ~11 ~122 ~126 dirt
setblock ~11 ~122 ~127 dirt
setblock ~11 ~122 ~128 dirt
setblock ~11 ~122 ~129 dirt
setblock ~11 ~122 ~130 dirt
setblock ~11 ~123 ~77 dirt
setblock ~11 ~123 ~78 dirt
setblock ~11 ~123 ~79 dirt
setblock ~11 ~123 ~80 dirt
setblock ~11 ~123 ~81 dirt
setblock ~11 ~123 ~82 dirt
setblock ~11 ~123 ~83 dirt
setblock ~11 ~123 ~106 dirt
setblock ~11 ~123 ~107 dirt
setblock ~11 ~123 ~108 dirt
setblock ~11 ~123 ~109 dirt
setblock ~11 ~123 ~110 dirt
setblock ~11 ~123 ~111 dirt
setblock ~11 ~123 ~112 dirt
setblock ~11 ~123 ~113 dirt
setblock ~11 ~123 ~114 dirt
setblock ~11 ~123 ~115 dirt
setblock ~11 ~123 ~116 dirt
setblock ~11 ~123 ~117 dirt
setblock ~11 ~123 ~118 dirt
setblock ~11 ~123 ~119 dirt
setblock ~11 ~123 ~120 dirt
setblock ~11 ~123 ~121 dirt
setblock ~11 ~123 ~122 dirt
setblock ~11 ~123 ~123 dirt
setblock ~11 ~123 ~124 dirt
setblock ~11 ~123 ~125 dirt
setblock ~11 ~123 ~126 dirt
setblock ~11 ~123 ~127 dirt
setblock ~11 ~123 ~128 dirt
setblock ~11 ~123 ~129 dirt
setblock ~11 ~123 ~130 dirt
setblock ~11 ~124 ~77 dirt
setblock ~11 ~124 ~78 dirt
setblock ~11 ~124 ~79 dirt
setblock ~11 ~124 ~80 dirt
setblock ~11 ~124 ~81 dirt
setblock ~11 ~124 ~82 dirt
setblock ~11 ~124 ~83 dirt
setblock ~11 ~124 ~106 dirt
setblock ~11 ~124 ~107 dirt
setblock ~11 ~124 ~108 dirt
setblock ~11 ~124 ~109 grass_block
setblock ~11 ~124 ~110 grass_block
setblock ~11 ~124 ~111 grass_block
setblock ~11 ~124 ~112 grass_block
setblock ~11 ~124 ~113 dirt
setblock ~11 ~124 ~114 dirt
setblock ~11 ~124 ~115 dirt
setblock ~11 ~124 ~116 dirt
setblock ~11 ~124 ~117 dirt
setblock ~11 ~124 ~118 dirt
setblock ~11 ~124 ~119 dirt
setblock ~11 ~124 ~120 dirt
setblock ~11 ~124 ~121 dirt
setblock ~11 ~124 ~122 dirt
setblock ~11 ~124 ~123 dirt
setblock ~11 ~124 ~124 dirt
setblock ~11 ~124 ~125 dirt
setblock ~11 ~124 ~126 dirt
setblock ~11 ~124 ~127 dirt
setblock ~11 ~124 ~128 dirt
setblock ~11 ~124 ~129 dirt
setblock ~11 ~124 ~130 dirt
setblock ~11 ~125 ~77 dirt
setblock ~11 ~125 ~78 dirt
setblock ~11 ~125 ~79 dirt
setblock ~11 ~125 ~80 dirt
setblock ~11 ~125 ~81 dirt
setblock ~11 ~125 ~82 dirt
setblock ~11 ~125 ~83 grass_block
setblock ~11 ~125 ~106 grass_block
setblock ~11 ~125 ~107 grass_block
setblock ~11 ~125 ~108 grass_block
setblock ~11 ~125 ~110 short_grass
setblock ~11 ~125 ~112 short_grass
setblock ~11 ~125 ~113 grass_block
setblock ~11 ~125 ~114 grass_block
setblock ~11 ~125 ~115 grass_block
setblock ~11 ~125 ~116 grass_block
setblock ~11 ~125 ~117 grass_block
setblock ~11 ~125 ~118 grass_block
setblock ~11 ~125 ~119 grass_block
setblock ~11 ~125 ~120 grass_block
setblock ~11 ~125 ~121 grass_block
setblock ~11 ~125 ~122 grass_block
setblock ~11 ~125 ~123 grass_block
setblock ~11 ~125 ~124 grass_block
setblock ~11 ~125 ~125 grass_block
setblock ~11 ~125 ~126 grass_block
setblock ~11 ~125 ~127 grass_block
setblock ~11 ~125 ~128 grass_block
setblock ~11 ~125 ~129 grass_block
setblock ~11 ~125 ~130 grass_block
setblock ~11 ~126 ~77 grass_block
setblock ~11 ~126 ~78 grass_block
setblock ~11 ~126 ~79 grass_block
setblock ~11 ~126 ~80 grass_block
setblock ~11 ~126 ~81 grass_block
setblock ~11 ~126 ~82 grass_block
setblock ~11 ~126 ~83 short_grass
setblock ~11 ~126 ~113 short_grass
setblock ~11 ~126 ~122 short_grass
setblock ~11 ~126 ~123 short_grass
setblock ~11 ~126 ~124 short_grass
setblock ~11 ~126 ~126 short_grass
setblock ~11 ~126 ~128 short_grass
setblock ~11 ~126 ~130 short_grass
setblock ~11 ~127 ~77 short_grass
setblock ~11 ~127 ~82 short_grass
setblock ~12 ~109 ~116 dirt
setblock ~12 ~109 ~117 dirt
setblock ~12 ~110 ~112 dirt
setblock ~12 ~110 ~115 dirt
setblock ~12 ~110 ~116 dirt
setblock ~12 ~110 ~117 dirt
setblock ~12 ~111 ~111 dirt
setblock ~12 ~111 ~112 dirt
setblock ~12 ~111 ~113 dirt
setblock ~12 ~111 ~115 dirt
setblock ~12 ~111 ~116 dirt
setblock ~12 ~111 ~117 dirt
setblock ~12 ~111 ~118 dirt
setblock ~12 ~112 ~110 dirt
setblock ~12 ~112 ~111 dirt
setblock ~12 ~112 ~112 dirt
setblock ~12 ~112 ~113 dirt
setblock ~12 ~112 ~114 dirt
setblock ~12 ~112 ~115 dirt
setblock ~12 ~112 ~116 dirt
setblock ~12 ~112 ~117 dirt
setblock ~12 ~112 ~118 dirt
setblock ~12 ~112 ~119 dirt
setblock ~12 ~112 ~120 dirt
setblock ~12 ~113 ~109 dirt
setblock ~12 ~113 ~110 dirt
setblock ~12 ~113 ~111 dirt
setblock ~12 ~113 ~112 dirt
setblock ~12 ~113 ~113 dirt
setblock ~12 ~113 ~114 dirt
setblock ~12 ~113 ~115 dirt
setblock ~12 ~113 ~116 dirt
setblock ~12 ~113 ~117 dirt
setblock ~12 ~113 ~118 dirt
setblock ~12 ~113 ~119 dirt
setblock ~12 ~113 ~120 dirt
setblock ~12 ~113 ~121 dirt
setblock ~12 ~114 ~109 dirt
setblock ~12 ~114 ~110 dirt
setblock ~12 ~114 ~111 dirt
setblock ~12 ~114 ~112 dirt
setblock ~12 ~114 ~113 dirt
setblock ~12 ~114 ~114 dirt
setblock ~12 ~114 ~115 dirt
setblock ~12 ~114 ~116 dirt
setblock ~12 ~114 ~117 dirt
setblock ~12 ~114 ~118 dirt
setblock ~12 ~114 ~119 dirt
setblock ~12 ~114 ~120 dirt
setblock ~12 ~114 ~121 dirt
setblock ~12 ~115 ~108 dirt
setblock ~12 ~115 ~109 dirt
setblock ~12 ~115 ~110 dirt
setblock ~12 ~115 ~111 dirt
setblock ~12 ~115 ~112 dirt
setblock ~12 ~115 ~113 dirt
setblock ~12 ~115 ~114 dirt
setblock ~12 ~115 ~115 dirt
setblock ~12 ~115 ~116 dirt
setblock ~12 ~115 ~117 dirt
setblock ~12 ~115 ~118 dirt
setblock ~12 ~115 ~119 dirt
setblock ~12 ~115 ~120 dirt
setblock ~12 ~115 ~121 dirt
setblock ~12 ~115 ~122 dirt
setblock ~12 ~116 ~80 dirt
setblock ~12 ~116 ~108 dirt
setblock ~12 ~116 ~109 dirt
setblock ~12 ~116 ~110 dirt
setblock ~12 ~116 ~111 dirt
setblock ~12 ~116 ~112 dirt
setblock ~12 ~116 ~113 dirt
setblock ~12 ~116 ~114 dirt
setblock ~12 ~116 ~115 dirt
setblock ~12 ~116 ~116 dirt
setblock ~12 ~116 ~117 dirt
setblock ~12 ~116 ~118 dirt
setblock ~12 ~116 ~119 dirt
setblock ~12 ~116 ~120 dirt
setblock ~12 ~116 ~121 dirt
setblock ~12 ~116 ~122 dirt
setblock ~12 ~116 ~123 dirt
setblock ~12 ~116 ~126 dirt
setblock ~12 ~116 ~127 dirt
setblock ~12 ~117 ~80 dirt
setblock ~12 ~117 ~81 dirt
setblock ~12 ~117 ~107 dirt
setblock ~12 ~117 ~108 dirt
setblock ~12 ~117 ~109 dirt
setblock ~12 ~117 ~110 dirt
setblock ~12 ~117 ~111 dirt
setblock ~12 ~117 ~112 dirt
setblock ~12 ~117 ~113 dirt
setblock ~12 ~117 ~114 dirt
setblock ~12 ~117 ~115 dirt
setblock ~12 ~117 ~116 dirt
setblock ~12 ~117 ~117 dirt
setblock ~12 ~117 ~118 dirt
setblock ~12 ~117 ~119 dirt
setblock ~12 ~117 ~120 dirt
setblock ~12 ~117 ~121 dirt
setblock ~12 ~117 ~122 dirt
setblock ~12 ~117 ~123 dirt
setblock ~12 ~117 ~124 dirt
setblock ~12 ~117 ~125 dirt
setblock ~12 ~117 ~126 dirt
setblock ~12 ~117 ~127 dirt
setblock ~12 ~117 ~129 dirt
setblock ~12 ~118 ~80 dirt
setblock ~12 ~118 ~81 dirt
setblock ~12 ~118 ~107 dirt
setblock ~12 ~118 ~108 dirt
setblock ~12 ~118 ~109 dirt
setblock ~12 ~118 ~110 dirt
setblock ~12 ~118 ~111 dirt
setblock ~12 ~118 ~112 dirt
setblock ~12 ~118 ~113 dirt
setblock ~12 ~118 ~114 dirt
setblock ~12 ~118 ~115 dirt
setblock ~12 ~118 ~116 dirt
setblock ~12 ~118 ~117 dirt
setblock ~12 ~118 ~118 dirt
setblock ~12 ~118 ~119 dirt
setblock ~12 ~118 ~120 dirt
setblock ~12 ~118 ~121 dirt
setblock ~12 ~118 ~122 dirt
setblock ~12 ~118 ~123 dirt
setblock ~12 ~118 ~124 dirt
setblock ~12 ~118 ~125 dirt
setblock ~12 ~118 ~126 dirt
setblock ~12 ~118 ~127 dirt
setblock ~12 ~118 ~129 dirt
setblock ~12 ~119 ~79 dirt
setblock ~12 ~119 ~80 dirt
setblock ~12 ~119 ~81 dirt
setblock ~12 ~119 ~82 dirt
setblock ~12 ~119 ~83 dirt
setblock ~12 ~119 ~106 dirt
setblock ~12 ~119 ~107 dirt
setblock ~12 ~119 ~108 dirt
setblock ~12 ~119 ~109 dirt
setblock ~12 ~119 ~110 dirt
setblock ~12 ~119 ~111 dirt
setblock ~12 ~119 ~112 dirt
setblock ~12 ~119 ~113 dirt
setblock ~12 ~119 ~114 dirt
setblock ~12 ~119 ~115 dirt
setblock ~12 ~119 ~116 dirt
setblock ~12 ~119 ~117 dirt
setblock ~12 ~119 ~118 dirt
setblock ~12 ~119 ~119 dirt
setblock ~12 ~119 ~120 dirt
setblock ~12 ~119 ~121 dirt
setblock ~12 ~119 ~122 dirt
setblock ~12 ~119 ~123 dirt
setblock ~12 ~119 ~124 dirt
setblock ~12 ~119 ~125 dirt
setblock ~12 ~119 ~126 dirt
setblock ~12 ~119 ~127 dirt
setblock ~12 ~119 ~128 dirt
setblock ~12 ~119 ~129 dirt
setblock ~12 ~119 ~130 dirt
setblock ~12 ~120 ~78 dirt
setblock ~12 ~120 ~79 dirt
setblock ~12 ~120 ~80 dirt
setblock ~12 ~120 ~81 dirt
setblock ~12 ~120 ~82 dirt
setblock ~12 ~120 ~83 dirt
setblock ~12 ~120 ~106 dirt
setblock ~12 ~120 ~107 dirt
setblock ~12 ~120 ~108 dirt
setblock ~12 ~120 ~109 dirt
setblock ~12 ~120 ~110 dirt
setblock ~12 ~120 ~111 dirt
setblock ~12 ~120 ~112 dirt
setblock ~12 ~120 ~113 dirt
setblock ~12 ~120 ~114 dirt
setblock ~12 ~120 ~115 dirt
setblock ~12 ~120 ~116 dirt
setblock ~12 ~120 ~117 dirt
setblock ~12 ~120 ~118 dirt
setblock ~12 ~120 ~119 dirt
setblock ~12 ~120 ~120 dirt
setblock ~12 ~120 ~121 dirt
setblock ~12 ~120 ~122 dirt
setblock ~12 ~120 ~123 dirt
setblock ~12 ~120 ~124 dirt
setblock ~12 ~120 ~125 dirt
setblock ~12 ~120 ~126 dirt
setblock ~12 ~120 ~127 dirt
setblock ~12 ~120 ~128 dirt
setblock ~12 ~120 ~129 dirt
setblock ~12 ~120 ~130 dirt
setblock ~12 ~121 ~77 dirt
setblock ~12 ~121 ~78 dirt
setblock ~12 ~121 ~79 dirt
setblock ~12 ~121 ~80 dirt
setblock ~12 ~121 ~81 dirt
setblock ~12 ~121 ~82 dirt
setblock ~12 ~121 ~83 dirt
setblock ~12 ~121 ~84 dirt
setblock ~12 ~121 ~86 dirt
setblock ~12 ~121 ~106 dirt
setblock ~12 ~121 ~107 dirt
setblock ~12 ~121 ~108 dirt
setblock ~12 ~121 ~109 dirt
setblock ~12 ~121 ~110 dirt
setblock ~12 ~121 ~111 dirt
setblock ~12 ~121 ~112 dirt
setblock ~12 ~121 ~113 dirt
setblock ~12 ~121 ~114 dirt
setblock ~12 ~121 ~115 dirt
setblock ~12 ~121 ~116 dirt
setblock ~12 ~121 ~117 dirt
setblock ~12 ~121 ~118 dirt
setblock ~12 ~121 ~119 dirt
setblock ~12 ~121 ~120 dirt
setblock ~12 ~121 ~121 dirt
setblock ~12 ~121 ~122 dirt
setblock ~12 ~121 ~123 dirt
setblock ~12 ~121 ~124 dirt
setblock ~12 ~121 ~125 dirt
setblock ~12 ~121 ~126 dirt
setblock ~12 ~121 ~127 dirt
setblock ~12 ~121 ~128 dirt
setblock ~12 ~121 ~129 dirt
setblock ~12 ~121 ~130 dirt
setblock ~12 ~121 ~131 dirt
setblock ~12 ~121 ~132 dirt
setblock ~12 ~121 ~133 dirt
setblock ~12 ~122 ~77 dirt
setblock ~12 ~122 ~78 dirt
setblock ~12 ~122 ~79 dirt
setblock ~12 ~122 ~80 dirt
setblock ~12 ~122 ~81 dirt
setblock ~12 ~122 ~82 dirt
setblock ~12 ~122 ~83 dirt
setblock ~12 ~122 ~84 dirt
setblock ~12 ~122 ~86 dirt
setblock ~12 ~122 ~106 dirt
setblock ~12 ~122 ~107 dirt
setblock ~12 ~122 ~108 dirt
setblock ~12 ~122 ~109 dirt
setblock ~12 ~122 ~110 dirt
setblock ~12 ~122 ~111 dirt
setblock ~12 ~122 ~112 dirt
setblock ~12 ~122 ~113 dirt
setblock ~12 ~122 ~114 dirt
setblock ~12 ~122 ~115 dirt
setblock ~12 ~122 ~116 dirt
setblock ~12 ~122 ~117 dirt
setblock ~12 ~122 ~118 dirt
setblock ~12 ~122 ~119 dirt
setblock ~12 ~122 ~120 dirt
setblock ~12 ~122 ~121 dirt
setblock ~12 ~122 ~122 dirt
setblock ~12 ~122 ~123 dirt
setblock ~12 ~122 ~124 dirt
setblock ~12 ~122 ~125 dirt
setblock ~12 ~122 ~126 dirt
setblock ~12 ~122 ~127 dirt
setblock ~12 ~122 ~128 dirt
setblock ~12 ~122 ~129 dirt
setblock ~12 ~122 ~130 dirt
setblock ~12 ~122 ~131 dirt
setblock ~12 ~122 ~132 dirt
setblock ~12 ~122 ~133 dirt
setblock ~12 ~123 ~77 dirt
setblock ~12 ~123 ~78 dirt
setblock ~12 ~123 ~79 dirt
setblock ~12 ~123 ~80 dirt
setblock ~12 ~123 ~81 dirt
setblock ~12 ~123 ~82 dirt
setblock ~12 ~123 ~83 dirt
setblock ~12 ~123 ~84 dirt
setblock ~12 ~123 ~86 dirt
setblock ~12 ~123 ~106 dirt
setblock ~12 ~123 ~107 dirt
setblock ~12 ~123 ~108 dirt
setblock ~12 ~123 ~109 dirt
setblock ~12 ~123 ~110 dirt
setblock ~12 ~123 ~111 dirt
setblock ~12 ~123 ~112 dirt
setblock ~12 ~123 ~113 dirt
setblock ~12 ~123 ~114 dirt
setblock ~12 ~123 ~115 dirt
setblock ~12 ~123 ~116 dirt
setblock ~12 ~123 ~117 dirt
setblock ~12 ~123 ~118 dirt
setblock ~12 ~123 ~119 dirt
setblock ~12 ~123 ~120 dirt
setblock ~12 ~123 ~121 dirt
setblock ~12 ~123 ~122 dirt
setblock ~12 ~123 ~123 dirt
setblock ~12 ~123 ~124 dirt
setblock ~12 ~123 ~125 dirt
setblock ~12 ~123 ~126 dirt
setblock ~12 ~123 ~127 dirt
setblock ~12 ~123 ~128 dirt
setblock ~12 ~123 ~129 dirt
setblock ~12 ~123 ~130 dirt
setblock ~12 ~123 ~131 dirt
setblock ~12 ~123 ~132 dirt
setblock ~12 ~123 ~133 dirt
setblock ~12 ~124 ~77 dirt
setblock ~12 ~124 ~78 dirt
setblock ~12 ~124 ~79 dirt
setblock ~12 ~124 ~80 dirt
setblock ~12 ~124 ~81 dirt
setblock ~12 ~124 ~82 dirt
setblock ~12 ~124 ~83 dirt
setblock ~12 ~124 ~84 dirt
setblock ~12 ~124 ~86 dirt
setblock ~12 ~124 ~106 dirt
setblock ~12 ~124 ~107 dirt
setblock ~12 ~124 ~108 grass_block
setblock ~12 ~124 ~109 grass_block
setblock ~12 ~124 ~110 grass_block
setblock ~12 ~124 ~111 grass_block
setblock ~12 ~124 ~112 grass_block
setblock ~12 ~124 ~113 grass_block
setblock ~12 ~124 ~114 dirt
setblock ~12 ~124 ~115 dirt
setblock ~12 ~124 ~116 dirt
setblock ~12 ~124 ~117 dirt
setblock ~12 ~124 ~118 dirt
setblock ~12 ~124 ~119 dirt
setblock ~12 ~124 ~120 dirt
setblock ~12 ~124 ~121 dirt
setblock ~12 ~124 ~122 dirt
setblock ~12 ~124 ~123 dirt
setblock ~12 ~124 ~124 dirt
setblock ~12 ~124 ~125 dirt
setblock ~12 ~124 ~126 dirt
setblock ~12 ~124 ~127 dirt
setblock ~12 ~124 ~128 dirt
setblock ~12 ~124 ~129 dirt
setblock ~12 ~124 ~130 dirt
setblock ~12 ~124 ~131 dirt
setblock ~12 ~124 ~132 dirt
setblock ~12 ~124 ~133 dirt
setblock ~12 ~125 ~77 dirt
setblock ~12 ~125 ~78 dirt
setblock ~12 ~125 ~79 dirt
setblock ~12 ~125 ~80 dirt
setblock ~12 ~125 ~81 dirt
setblock ~12 ~125 ~82 dirt
setblock ~12 ~125 ~83 grass_block
setblock ~12 ~125 ~84 grass_block
setblock ~12 ~125 ~86 grass_block
setblock ~12 ~125 ~106 grass_block
setblock ~12 ~125 ~107 grass_block
setblock ~12 ~125 ~109 short_grass
setblock ~12 ~125 ~110 fern
setblock ~12 ~125 ~111 short_grass
setblock ~12 ~125 ~112 short_grass
setblock ~12 ~125 ~113 short_grass
setblock ~12 ~125 ~114 grass_block
setblock ~12 ~125 ~115 grass_block
setblock ~12 ~125 ~116 grass_block
setblock ~12 ~125 ~117 grass_block
setblock ~12 ~125 ~118 grass_block
setblock ~12 ~125 ~119 grass_block
setblock ~12 ~125 ~120 grass_block
setblock ~12 ~125 ~121 grass_block
setblock ~12 ~125 ~122 grass_block
setblock ~12 ~125 ~123 grass_block
setblock ~12 ~125 ~124 grass_block
setblock ~12 ~125 ~125 grass_block
setblock ~12 ~125 ~126 grass_block
setblock ~12 ~125 ~127 grass_block
setblock ~12 ~125 ~128 grass_block
setblock ~12 ~125 ~129 grass_block
setblock ~12 ~125 ~130 grass_block
setblock ~12 ~125 ~131 grass_block
setblock ~12 ~125 ~132 grass_block
setblock ~12 ~125 ~133 grass_block
setblock ~12 ~126 ~77 grass_block
setblock ~12 ~126 ~78 grass_block
setblock ~12 ~126 ~79 grass_block
setblock ~12 ~126 ~80 grass_block
setblock ~12 ~126 ~81 grass_block
setblock ~12 ~126 ~82 grass_block
setblock ~12 ~126 ~83 short_grass
setblock ~12 ~126 ~106 fern
setblock ~12 ~126 ~117 short_grass
setblock ~12 ~126 ~119 short_grass
setblock ~12 ~126 ~120 short_grass
setblock ~12 ~126 ~121 short_grass
setblock ~12 ~126 ~122 poppy
setblock ~12 ~126 ~127 fern
setblock ~12 ~126 ~128 short_grass
setblock ~12 ~126 ~133 short_grass
setblock ~12 ~127 ~80 short_grass
setblock ~12 ~127 ~82 short_grass
setblock ~13 ~105 ~116 dirt
setblock ~13 ~106 ~115 dirt
setblock ~13 ~106 ~116 dirt
setblock ~13 ~107 ~115 dirt
setblock ~13 ~107 ~116 dirt
setblock ~13 ~107 ~118 dirt
setblock ~13 ~108 ~114 dirt
setblock ~13 ~108 ~115 dirt
setblock ~13 ~108 ~116 dirt
setblock ~13 ~108 ~117 dirt
setblock ~13 ~108 ~118 dirt
setblock ~13 ~109 ~112 dirt
setblock ~13 ~109 ~114 dirt
setblock ~13 ~109 ~115 dirt
setblock ~13 ~109 ~116 dirt
setblock ~13 ~109 ~117 dirt
setblock ~13 ~109 ~118 dirt
setblock ~13 ~110 ~111 dirt
setblock ~13 ~110 ~112 dirt
setblock ~13 ~110 ~113 dirt
setblock ~13 ~110 ~114 dirt
setblock ~13 ~110 ~115 dirt
setblock ~13 ~110 ~116 dirt
setblock ~13 ~110 ~117 dirt
setblock ~13 ~110 ~118 dirt
setblock ~13 ~110 ~119 dirt
setblock ~13 ~111 ~110 dirt
setblock ~13 ~111 ~111 dirt
setblock ~13 ~111 ~112 dirt
setblock ~13 ~111 ~113 dirt
setblock ~13 ~111 ~114 dirt
setblock ~13 ~111 ~115 dirt
setblock ~13 ~111 ~116 dirt
setblock ~13 ~111 ~117 dirt
setblock ~13 ~111 ~118 dirt
setblock ~13 ~111 ~119 dirt
setblock ~13 ~111 ~120 dirt
setblock ~13 ~112 ~109 dirt
setblock ~13 ~112 ~110 dirt
setblock ~13 ~112 ~111 dirt
setblock ~13 ~112 ~112 dirt
setblock ~13 ~112 ~113 dirt
setblock ~13 ~112 ~114 dirt
setblock ~13 ~112 ~115 dirt
setblock ~13 ~112 ~116 dirt
setblock ~13 ~112 ~117 dirt
setblock ~13 ~112 ~118 dirt
setblock ~13 ~112 ~119 dirt
setblock ~13 ~112 ~120 dirt
setblock ~13 ~112 ~121 dirt
setblock ~13 ~113 ~109 dirt
setblock ~13 ~113 ~110 dirt
setblock ~13 ~113 ~111 dirt
setblock ~13 ~113 ~112 dirt
setblock ~13 ~113 ~113 dirt
setblock ~13 ~113 ~114 dirt
setblock ~13 ~113 ~115 dirt
setblock ~13 ~113 ~116 dirt
setblock ~13 ~113 ~117 dirt
setblock ~13 ~113 ~118 dirt
setblock ~13 ~113 ~119 dirt
setblock ~13 ~113 ~120 dirt
setblock ~13 ~113 ~121 dirt
setblock ~13 ~113 ~122 dirt
setblock ~13 ~114 ~108 dirt
setblock ~13 ~114 ~109 dirt
setblock ~13 ~114 ~110 dirt
setblock ~13 ~114 ~111 dirt
setblock ~13 ~114 ~112 dirt
setblock ~13 ~114 ~113 dirt
setblock ~13 ~114 ~114 dirt
setblock ~13 ~114 ~115 dirt
setblock ~13 ~114 ~116 dirt
setblock ~13 ~114 ~117 dirt
setblock ~13 ~114 ~118 dirt
setblock ~13 ~114 ~119 dirt
setblock ~13 ~114 ~120 dirt
setblock ~13 ~114 ~121 dirt
setblock ~13 ~114 ~122 dirt
setblock ~13 ~114 ~126 dirt
setblock ~13 ~115 ~80 dirt
setblock ~13 ~115 ~107 dirt
setblock ~13 ~115 ~108 dirt
setblock ~13 ~115 ~109 dirt
setblock ~13 ~115 ~110 dirt
setblock ~13 ~115 ~111 dirt
setblock ~13 ~115 ~112 dirt
setblock ~13 ~115 ~113 dirt
setblock ~13 ~115 ~114 dirt
setblock ~13 ~115 ~115 dirt
setblock ~13 ~115 ~116 dirt
setblock ~13 ~115 ~117 dirt
setblock ~13 ~115 ~118 dirt
setblock ~13 ~115 ~119 dirt
setblock ~13 ~115 ~120 dirt
setblock ~13 ~115 ~121 dirt
setblock ~13 ~115 ~122 dirt
setblock ~13 ~115 ~123 dirt
setblock ~13 ~115 ~124 dirt
setblock ~13 ~115 ~125 dirt
setblock ~13 ~115 ~126 dirt
setblock ~13 ~115 ~127 dirt
setblock ~13 ~116 ~79 dirt
setblock ~13 ~116 ~80 dirt
setblock ~13 ~116 ~81 dirt
setblock ~13 ~116 ~107 dirt
setblock ~13 ~116 ~108 dirt
setblock ~13 ~116 ~109 dirt
setblock ~13 ~116 ~110 dirt
setblock ~13 ~116 ~111 dirt
setblock ~13 ~116 ~112 dirt
setblock ~13 ~116 ~113 dirt
setblock ~13 ~116 ~114 dirt
setblock ~13 ~116 ~115 dirt
setblock ~13 ~116 ~116 dirt
setblock ~13 ~116 ~117 dirt
setblock ~13 ~116 ~118 dirt
setblock ~13 ~116 ~119 dirt
setblock ~13 ~116 ~120 dirt
setblock ~13 ~116 ~121 dirt
setblock ~13 ~116 ~122 dirt
setblock ~13 ~116 ~123 dirt
setblock ~13 ~116 ~124 dirt
setblock ~13 ~116 ~125 dirt
setblock ~13 ~116 ~126 dirt
setblock ~13 ~116 ~127 dirt
setblock ~13 ~116 ~128 dirt
setblock ~13 ~116 ~129 dirt
setblock ~13 ~117 ~79 dirt
setblock ~13 ~117 ~80 dirt
setblock ~13 ~117 ~81 dirt
setblock ~13 ~117 ~82 dirt
setblock ~13 ~117 ~83 dirt
setblock ~13 ~117 ~107 dirt
setblock ~13 ~117 ~108 dirt
setblock ~13 ~117 ~109 dirt
setblock ~13 ~117 ~110 dirt
setblock ~13 ~117 ~111 dirt
setblock ~13 ~117 ~112 dirt
setblock ~13 ~117 ~113 dirt
setblock ~13 ~117 ~114 dirt
setblock ~13 ~117 ~115 dirt
setblock ~13 ~117 ~116 dirt
setblock ~13 ~117 ~117 dirt
setblock ~13 ~117 ~118 dirt
setblock ~13 ~117 ~119 dirt
setblock ~13 ~117 ~120 dirt
setblock ~13 ~117 ~121 dirt
setblock ~13 ~117 ~122 dirt
setblock ~13 ~117 ~123 dirt
setblock ~13 ~117 ~124 dirt
setblock ~13 ~117 ~125 dirt
setblock ~13 ~117 ~126 dirt
setblock ~13 ~117 ~127 dirt
setblock ~13 ~117 ~128 dirt
setblock ~13 ~117 ~129 dirt
setblock ~13 ~117 ~130 dirt
setblock ~13 ~118 ~79 dirt
setblock ~13 ~118 ~80 dirt
setblock ~13 ~118 ~81 dirt
setblock ~13 ~118 ~82 dirt
setblock ~13 ~118 ~83 dirt
setblock ~13 ~118 ~107 dirt
setblock ~13 ~118 ~108 dirt
setblock ~13 ~118 ~109 dirt
setblock ~13 ~118 ~110 dirt
setblock ~13 ~118 ~111 dirt
setblock ~13 ~118 ~112 dirt
setblock ~13 ~118 ~113 dirt
setblock ~13 ~118 ~114 dirt
setblock ~13 ~118 ~115 dirt
setblock ~13 ~118 ~116 dirt
setblock ~13 ~118 ~117 dirt
setblock ~13 ~118 ~118 dirt
setblock ~13 ~118 ~119 dirt
setblock ~13 ~118 ~120 dirt
setblock ~13 ~118 ~121 dirt
setblock ~13 ~118 ~122 dirt
setblock ~13 ~118 ~123 dirt
setblock ~13 ~118 ~124 dirt
setblock ~13 ~118 ~125 dirt
setblock ~13 ~118 ~126 dirt
setblock ~13 ~118 ~127 dirt
setblock ~13 ~118 ~128 dirt
setblock ~13 ~118 ~129 dirt
setblock ~13 ~118 ~130 dirt
setblock ~13 ~119 ~78 dirt
setblock ~13 ~119 ~79 dirt
setblock ~13 ~119 ~80 dirt
setblock ~13 ~119 ~81 dirt
setblock ~13 ~119 ~82 dirt
setblock ~13 ~119 ~83 dirt
setblock ~13 ~119 ~84 dirt
setblock ~13 ~119 ~104 dirt
setblock ~13 ~119 ~106 dirt
setblock ~13 ~119 ~107 dirt
setblock ~13 ~119 ~108 dirt
setblock ~13 ~119 ~109 dirt
setblock ~13 ~119 ~110 dirt
setblock ~13 ~119 ~111 dirt
setblock ~13 ~119 ~112 dirt
setblock ~13 ~119 ~113 dirt
setblock ~13 ~119 ~114 dirt
setblock ~13 ~119 ~115 dirt
setblock ~13 ~119 ~116 dirt
setblock ~13 ~119 ~117 dirt
setblock ~13 ~119 ~118 dirt
setblock ~13 ~119 ~119 dirt
setblock ~13 ~119 ~120 dirt
setblock ~13 ~119 ~121 dirt
setblock ~13 ~119 ~122 dirt
setblock ~13 ~119 ~123 dirt
setblock ~13 ~119 ~124 dirt
setblock ~13 ~119 ~125 dirt
setblock ~13 ~119 ~126 dirt
setblock ~13 ~119 ~127 dirt
setblock ~13 ~119 ~128 dirt
setblock ~13 ~119 ~129 dirt
setblock ~13 ~119 ~130 dirt
setblock ~13 ~119 ~131 dirt
setblock ~13 ~119 ~132 dirt
setblock ~13 ~120 ~77 dirt
setblock ~13 ~120 ~78 dirt
setblock ~13 ~120 ~79 dirt
setblock ~13 ~120 ~80 dirt
setblock ~13 ~120 ~81 dirt
setblock ~13 ~120 ~82 dirt
setblock ~13 ~120 ~83 dirt
setblock ~13 ~120 ~84 dirt
setblock ~13 ~120 ~86 dirt
setblock ~13 ~120 ~87 dirt
setblock ~13 ~120 ~101 dirt
setblock ~13 ~120 ~104 dirt
setblock ~13 ~120 ~105 dirt
setblock ~13 ~120 ~106 dirt
setblock ~13 ~120 ~107 dirt
setblock ~13 ~120 ~108 dirt
setblock ~13 ~120 ~109 dirt
setblock ~13 ~120 ~110 dirt
setblock ~13 ~120 ~111 dirt
setblock ~13 ~120 ~112 dirt
setblock ~13 ~120 ~113 dirt
setblock ~13 ~120 ~114 dirt
setblock ~13 ~120 ~115 dirt
setblock ~13 ~120 ~116 dirt
setblock ~13 ~120 ~117 dirt
setblock ~13 ~120 ~118 dirt
setblock ~13 ~120 ~119 dirt
setblock ~13 ~120 ~120 dirt
setblock ~13 ~120 ~121 dirt
setblock ~13 ~120 ~122 dirt
setblock ~13 ~120 ~123 dirt
setblock ~13 ~120 ~124 dirt
setblock ~13 ~120 ~125 dirt
setblock ~13 ~120 ~126 dirt
setblock ~13 ~120 ~127 dirt
setblock ~13 ~120 ~128 dirt
setblock ~13 ~120 ~129 dirt
setblock ~13 ~120 ~130 dirt
setblock ~13 ~120 ~131 dirt
setblock ~13 ~120 ~132 dirt
setblock ~13 ~120 ~133 dirt
setblock ~13 ~121 ~76 dirt
setblock ~13 ~121 ~77 dirt
setblock ~13 ~121 ~78 dirt
setblock ~13 ~121 ~79 dirt
setblock ~13 ~121 ~80 dirt
setblock ~13 ~121 ~81 dirt
setblock ~13 ~121 ~82 dirt
setblock ~13 ~121 ~83 dirt
setblock ~13 ~121 ~84 dirt
setblock ~13 ~121 ~85 dirt
setblock ~13 ~121 ~86 dirt
setblock ~13 ~121 ~87 dirt
setblock ~13 ~121 ~101 dirt
setblock ~13 ~121 ~103 dirt
setblock ~13 ~121 ~104 dirt
setblock ~13 ~121 ~105 dirt
setblock ~13 ~121 ~106 dirt
setblock ~13 ~121 ~107 dirt
setblock ~13 ~121 ~108 dirt
setblock ~13 ~121 ~109 dirt
setblock ~13 ~121 ~110 dirt
setblock ~13 ~121 ~111 dirt
setblock ~13 ~121 ~112 dirt
setblock ~13 ~121 ~113 dirt
setblock ~13 ~121 ~114 dirt
setblock ~13 ~121 ~115 dirt
setblock ~13 ~121 ~116 dirt
setblock ~13 ~121 ~117 dirt
setblock ~13 ~121 ~118 dirt
setblock ~13 ~121 ~119 dirt
setblock ~13 ~121 ~120 dirt
setblock ~13 ~121 ~121 dirt
setblock ~13 ~121 ~122 dirt
setblock ~13 ~121 ~123 dirt
setblock ~13 ~121 ~124 dirt
setblock ~13 ~121 ~125 dirt
setblock ~13 ~121 ~126 dirt
setblock ~13 ~121 ~127 dirt
setblock ~13 ~121 ~128 dirt
setblock ~13 ~121 ~129 dirt
setblock ~13 ~121 ~130 dirt
setblock ~13 ~121 ~131 dirt
setblock ~13 ~121 ~132 dirt
setblock ~13 ~121 ~133 dirt
setblock ~13 ~121 ~134 dirt
setblock ~13 ~122 ~76 dirt
setblock ~13 ~122 ~77 dirt
setblock ~13 ~122 ~78 dirt
setblock ~13 ~122 ~79 dirt
setblock ~13 ~122 ~80 dirt
setblock ~13 ~122 ~81 dirt
setblock ~13 ~122 ~82 dirt
setblock ~13 ~122 ~83 dirt
setblock ~13 ~122 ~84 dirt
setblock ~13 ~122 ~85 dirt
setblock ~13 ~122 ~86 dirt
setblock ~13 ~122 ~87 dirt
setblock ~13 ~122 ~101 dirt
setblock ~13 ~122 ~103 dirt
setblock ~13 ~122 ~104 dirt
setblock ~13 ~122 ~105 dirt
setblock ~13 ~122 ~106 dirt
setblock ~13 ~122 ~107 dirt
setblock ~13 ~122 ~108 dirt
setblock ~13 ~122 ~109 dirt
setblock ~13 ~122 ~110 dirt
setblock ~13 ~122 ~111 dirt
setblock ~13 ~122 ~112 dirt
setblock ~13 ~122 ~113 dirt
setblock ~13 ~122 ~114 dirt
setblock ~13 ~122 ~115 dirt
setblock ~13 ~122 ~116 dirt
setblock ~13 ~122 ~117 dirt
setblock ~13 ~122 ~118 dirt
setblock ~13 ~122 ~119 dirt
setblock ~13 ~122 ~120 dirt
setblock ~13 ~122 ~121 dirt
setblock ~13 ~122 ~122 dirt
setblock ~13 ~122 ~123 dirt
setblock ~13 ~122 ~124 dirt
setblock ~13 ~122 ~125 dirt
setblock ~13 ~122 ~126 dirt
setblock ~13 ~122 ~127 dirt
setblock ~13 ~122 ~128 dirt
setblock ~13 ~122 ~129 dirt
setblock ~13 ~122 ~130 dirt
setblock ~13 ~122 ~131 dirt
setblock ~13 ~122 ~132 dirt
setblock ~13 ~122 ~133 dirt
setblock ~13 ~122 ~134 dirt
setblock ~13 ~123 ~76 dirt
setblock ~13 ~123 ~77 dirt
setblock ~13 ~123 ~78 dirt
setblock ~13 ~123 ~79 dirt
setblock ~13 ~123 ~80 dirt
setblock ~13 ~123 ~81 dirt
setblock ~13 ~123 ~82 dirt
setblock ~13 ~123 ~83 dirt
setblock ~13 ~123 ~84 dirt
setblock ~13 ~123 ~85 dirt
setblock ~13 ~123 ~86 dirt
setblock ~13 ~123 ~87 dirt
setblock ~13 ~123 ~101 dirt
setblock ~13 ~123 ~103 dirt
setblock ~13 ~123 ~104 dirt
setblock ~13 ~123 ~105 dirt
setblock ~13 ~123 ~106 dirt
setblock ~13 ~123 ~107 dirt
setblock ~13 ~123 ~108 dirt
setblock ~13 ~123 ~109 dirt
setblock ~13 ~123 ~110 dirt
setblock ~13 ~123 ~111 dirt
setblock ~13 ~123 ~112 dirt
setblock ~13 ~123 ~113 dirt
setblock ~13 ~123 ~114 dirt
setblock ~13 ~123 ~115 dirt
setblock ~13 ~123 ~116 dirt
setblock ~13 ~123 ~117 dirt
setblock ~13 ~123 ~118 dirt
setblock ~13 ~123 ~119 dirt
setblock ~13 ~123 ~120 dirt
setblock ~13 ~123 ~121 dirt
setblock ~13 ~123 ~122 dirt
setblock ~13 ~123 ~123 dirt
setblock ~13 ~123 ~124 dirt
setblock ~13 ~123 ~125 dirt
setblock ~13 ~123 ~126 dirt
setblock ~13 ~123 ~127 dirt
setblock ~13 ~123 ~128 dirt
setblock ~13 ~123 ~129 dirt
setblock ~13 ~123 ~130 dirt
setblock ~13 ~123 ~131 dirt
setblock ~13 ~123 ~132 dirt
setblock ~13 ~123 ~133 dirt
setblock ~13 ~123 ~134 dirt
setblock ~13 ~124 ~76 dirt
setblock ~13 ~124 ~77 dirt
setblock ~13 ~124 ~78 dirt
setblock ~13 ~124 ~79 dirt
setblock ~13 ~124 ~80 dirt
setblock ~13 ~124 ~81 dirt
setblock ~13 ~124 ~82 dirt
setblock ~13 ~124 ~83 dirt
setblock ~13 ~124 ~84 dirt
setblock ~13 ~124 ~85 dirt
setblock ~13 ~124 ~86 dirt
setblock ~13 ~124 ~87 grass_block
setblock ~13 ~124 ~101 dirt
setblock ~13 ~124 ~103 dirt
setblock ~13 ~124 ~104 dirt
setblock ~13 ~124 ~105 dirt
setblock ~13 ~124 ~106 dirt
setblock ~13 ~124 ~107 grass_block
setblock ~13 ~124 ~108 grass_block
setblock ~13 ~124 ~109 grass_block
setblock ~13 ~124 ~110 grass_block
setblock ~13 ~124 ~111 grass_block
setblock ~13 ~124 ~112 grass_block
setblock ~13 ~124 ~113 grass_block
setblock ~13 ~124 ~114 dirt
setblock ~13 ~124 ~115 dirt
setblock ~13 ~124 ~116 dirt
setblock ~13 ~124 ~117 dirt
setblock ~13 ~124 ~118 dirt
setblock ~13 ~124 ~119 dirt
setblock ~13 ~124 ~120 dirt
setblock ~13 ~124 ~121 dirt
setblock ~13 ~124 ~122 dirt
setblock ~13 ~124 ~123 dirt
setblock ~13 ~124 ~124 dirt
setblock ~13 ~124 ~125 dirt
setblock ~13 ~124 ~126 dirt
setblock ~13 ~124 ~127 dirt
setblock ~13 ~124 ~128 dirt
setblock ~13 ~124 ~129 dirt
setblock ~13 ~124 ~130 dirt
setblock ~13 ~124 ~131 dirt
setblock ~13 ~124 ~132 dirt
setblock ~13 ~124 ~133 dirt
setblock ~13 ~124 ~134 dirt
setblock ~13 ~125 ~76 dirt
setblock ~13 ~125 ~77 dirt
setblock ~13 ~125 ~78 dirt
setblock ~13 ~125 ~79 dirt
setblock ~13 ~125 ~80 dirt
setblock ~13 ~125 ~81 dirt
setblock ~13 ~125 ~82 dirt
setblock ~13 ~125 ~83 grass_block
setblock ~13 ~125 ~84 grass_block
setblock ~13 ~125 ~85 grass_block
setblock ~13 ~125 ~86 grass_block
setblock ~13 ~125 ~101 grass_block
setblock ~13 ~125 ~103 grass_block
setblock ~13 ~125 ~104 grass_block
setblock ~13 ~125 ~105 grass_block
setblock ~13 ~125 ~106 grass_block
setblock ~13 ~125 ~107 short_grass
setblock ~13 ~125 ~108 short_grass
setblock ~13 ~125 ~111 short_grass
setblock ~13 ~125 ~112 short_grass
setblock ~13 ~125 ~114 grass_block
setblock ~13 ~125 ~115 grass_block
setblock ~13 ~125 ~116 grass_block
setblock ~13 ~125 ~117 grass_block
setblock ~13 ~125 ~118 grass_block
setblock ~13 ~125 ~119 grass_block
setblock ~13 ~125 ~120 grass_block
setblock ~13 ~125 ~121 grass_block
setblock ~13 ~125 ~122 grass_block
setblock ~13 ~125 ~123 grass_block
setblock ~13 ~125 ~124 grass_block
setblock ~13 ~125 ~125 grass_block
setblock ~13 ~125 ~126 grass_block
setblock ~13 ~125 ~127 grass_block
setblock ~13 ~125 ~128 grass_block
setblock ~13 ~125 ~129 grass_block
setblock ~13 ~125 ~130 grass_block
setblock ~13 ~125 ~131 grass_block
setblock ~13 ~125 ~132 grass_block
setblock ~13 ~125 ~133 grass_block
setblock ~13 ~125 ~134 grass_block
setblock ~13 ~126 ~76 grass_block
setblock ~13 ~126 ~77 grass_block
setblock ~13 ~126 ~78 grass_block
setblock ~13 ~126 ~79 grass_block
setblock ~13 ~126 ~80 grass_block
setblock ~13 ~126 ~81 grass_block
setblock ~13 ~126 ~82 grass_block
setblock ~13 ~126 ~85 short_grass
setblock ~13 ~126 ~123 fern
setblock ~13 ~126 ~127 short_grass
setblock ~13 ~126 ~128 short_grass
setblock ~13 ~126 ~131 short_grass
setblock ~13 ~126 ~134 poppy
setblock ~13 ~127 ~81 poppy
setblock ~14 ~104 ~116 dirt
setblock ~14 ~105 ~114 dirt
setblock ~14 ~105 ~115 dirt
setblock ~14 ~105 ~116 dirt
setblock ~14 ~105 ~117 dirt
setblock ~14 ~105 ~118 dirt
setblock ~14 ~106 ~113 dirt
setblock ~14 ~106 ~114 dirt
setblock ~14 ~106 ~115 dirt
setblock ~14 ~106 ~116 dirt
setblock ~14 ~106 ~117 dirt
setblock ~14 ~106 ~118 dirt
setblock ~14 ~107 ~113 dirt
setblock ~14 ~107 ~114 dirt
setblock ~14 ~107 ~115 dirt
setblock ~14 ~107 ~116 dirt
setblock ~14 ~107 ~117 dirt
setblock ~14 ~107 ~118 dirt
setblock ~14 ~107 ~119 dirt
setblock ~14 ~108 ~112 dirt
setblock ~14 ~108 ~113 dirt
setblock ~14 ~108 ~114 dirt
setblock ~14 ~108 ~115 dirt
setblock ~14 ~108 ~116 dirt
setblock ~14 ~108 ~117 dirt
setblock ~14 ~108 ~118 dirt
setblock ~14 ~108 ~119 dirt
setblock ~14 ~108 ~120 dirt
setblock ~14 ~109 ~111 dirt
setblock ~14 ~109 ~112 dirt
setblock ~14 ~109 ~113 dirt
setblock ~14 ~109 ~114 dirt
setblock ~14 ~109 ~115 dirt
setblock ~14 ~109 ~116 dirt
setblock ~14 ~109 ~117 dirt
setblock ~14 ~109 ~118 dirt
setblock ~14 ~109 ~119 dirt
setblock ~14 ~109 ~120 dirt
setblock ~14 ~110 ~110 dirt
setblock ~14 ~110 ~111 dirt
setblock ~14 ~110 ~112 dirt
setblock ~14 ~110 ~113 dirt
setblock ~14 ~110 ~114 dirt
setblock ~14 ~110 ~115 dirt
setblock ~14 ~110 ~116 dirt
setblock ~14 ~110 ~117 dirt
setblock ~14 ~110 ~118 dirt
setblock ~14 ~110 ~119 dirt
setblock ~14 ~110 ~120 dirt
setblock ~14 ~110 ~121 dirt
setblock ~14 ~111 ~109 dirt
setblock ~14 ~111 ~110 dirt
setblock ~14 ~111 ~111 dirt
setblock ~14 ~111 ~112 dirt
setblock ~14 ~111 ~113 dirt
setblock ~14 ~111 ~114 dirt
setblock ~14 ~111 ~115 dirt
setblock ~14 ~111 ~116 dirt
setblock ~14 ~111 ~117 dirt
setblock ~14 ~111 ~118 dirt
setblock ~14 ~111 ~119 dirt
setblock ~14 ~111 ~120 dirt
setblock ~14 ~111 ~121 dirt
setblock ~14 ~111 ~122 dirt
setblock ~14 ~112 ~109 dirt
setblock ~14 ~112 ~110 dirt
setblock ~14 ~112 ~111 dirt
setblock ~14 ~112 ~112 dirt
setblock ~14 ~112 ~113 dirt
setblock ~14 ~112 ~114 dirt
setblock ~14 ~112 ~115 dirt
setblock ~14 ~112 ~116 dirt
setblock ~14 ~112 ~117 dirt
setblock ~14 ~112 ~118 dirt
setblock ~14 ~112 ~119 dirt
setblock ~14 ~112 ~120 dirt
setblock ~14 ~112 ~121 dirt
setblock ~14 ~112 ~122 dirt
setblock ~14 ~112 ~126 dirt
setblock ~14 ~112 ~127 dirt
setblock ~14 ~113 ~109 dirt
setblock ~14 ~113 ~110 dirt
setblock ~14 ~113 ~111 dirt
setblock ~14 ~113 ~112 dirt
setblock ~14 ~113 ~113 dirt
setblock ~14 ~113 ~114 dirt
setblock ~14 ~113 ~115 dirt
setblock ~14 ~113 ~116 dirt
setblock ~14 ~113 ~117 dirt
setblock ~14 ~113 ~118 dirt
setblock ~14 ~113 ~119 dirt
setblock ~14 ~113 ~120 dirt
setblock ~14 ~113 ~121 dirt
setblock ~14 ~113 ~122 dirt
setblock ~14 ~113 ~124 dirt
setblock ~14 ~113 ~125 dirt
setblock ~14 ~113 ~126 dirt
setblock ~14 ~113 ~127 dirt
setblock ~14 ~114 ~80 dirt
setblock ~14 ~114 ~109 dirt
setblock ~14 ~114 ~110 dirt
setblock ~14 ~114 ~111 dirt
setblock ~14 ~114 ~112 dirt
setblock ~14 ~114 ~113 dirt
setblock ~14 ~114 ~114 dirt
setblock ~14 ~114 ~115 dirt
setblock ~14 ~114 ~116 dirt
setblock ~14 ~114 ~117 dirt
setblock ~14 ~114 ~118 dirt
setblock ~14 ~114 ~119 dirt
setblock ~14 ~114 ~120 dirt
setblock ~14 ~114 ~121 dirt
setblock ~14 ~114 ~122 dirt
setblock ~14 ~114 ~123 dirt
setblock ~14 ~114 ~124 dirt
setblock ~14 ~114 ~125 dirt
setblock ~14 ~114 ~126 dirt
setblock ~14 ~114 ~127 dirt
setblock ~14 ~114 ~128 dirt
setblock ~14 ~115 ~79 dirt
setblock ~14 ~115 ~80 dirt
setblock ~14 ~115 ~81 dirt
setblock ~14 ~115 ~83 dirt
setblock ~14 ~115 ~108 dirt
setblock ~14 ~115 ~109 dirt
setblock ~14 ~115 ~110 dirt
setblock ~14 ~115 ~111 dirt
setblock ~14 ~115 ~112 dirt
setblock ~14 ~115 ~113 dirt
setblock ~14 ~115 ~114 dirt
setblock ~14 ~115 ~115 dirt
setblock ~14 ~115 ~116 dirt
setblock ~14 ~115 ~117 dirt
setblock ~14 ~115 ~118 dirt
setblock ~14 ~115 ~119 dirt
setblock ~14 ~115 ~120 dirt
setblock ~14 ~115 ~121 dirt
setblock ~14 ~115 ~122 dirt
setblock ~14 ~115 ~123 dirt
setblock ~14 ~115 ~124 dirt
setblock ~14 ~115 ~125 dirt
setblock ~14 ~115 ~126 dirt
setblock ~14 ~115 ~127 dirt
setblock ~14 ~115 ~128 dirt
setblock ~14 ~115 ~129 dirt
setblock ~14 ~116 ~79 dirt
setblock ~14 ~116 ~80 dirt
setblock ~14 ~116 ~81 dirt
setblock ~14 ~116 ~82 dirt
setblock ~14 ~116 ~83 dirt
setblock ~14 ~116 ~108 dirt
setblock ~14 ~116 ~109 dirt
setblock ~14 ~116 ~110 dirt
setblock ~14 ~116 ~111 dirt
setblock ~14 ~116 ~112 dirt
setblock ~14 ~116 ~113 dirt
setblock ~14 ~116 ~114 dirt
setblock ~14 ~116 ~115 dirt
setblock ~14 ~116 ~116 dirt
setblock ~14 ~116 ~117 dirt
setblock ~14 ~116 ~118 dirt
setblock ~14 ~116 ~119 dirt
setblock ~14 ~116 ~120 dirt
setblock ~14 ~116 ~121 dirt
setblock ~14 ~116 ~122 dirt
setblock ~14 ~116 ~123 dirt
setblock ~14 ~116 ~124 dirt
setblock ~14 ~116 ~125 dirt
setblock ~14 ~116 ~126 dirt
setblock ~14 ~116 ~127 dirt
setblock ~14 ~116 ~128 dirt
setblock ~14 ~116 ~129 dirt
setblock ~14 ~116 ~130 dirt
setblock ~14 ~117 ~78 dirt
setblock ~14 ~117 ~79 dirt
setblock ~14 ~117 ~80 dirt
setblock ~14 ~117 ~81 dirt
setblock ~14 ~117 ~82 dirt
setblock ~14 ~117 ~83 dirt
setblock ~14 ~117 ~84 dirt
setblock ~14 ~117 ~86 dirt
setblock ~14 ~117 ~101 dirt
setblock ~14 ~117 ~107 dirt
setblock ~14 ~117 ~108 dirt
setblock ~14 ~117 ~109 dirt
setblock ~14 ~117 ~110 dirt
setblock ~14 ~117 ~111 dirt
setblock ~14 ~117 ~112 dirt
setblock ~14 ~117 ~113 dirt
setblock ~14 ~117 ~114 dirt
setblock ~14 ~117 ~115 dirt
setblock ~14 ~117 ~116 dirt
setblock ~14 ~117 ~117 dirt
setblock ~14 ~117 ~118 dirt
setblock ~14 ~117 ~119 dirt
setblock ~14 ~117 ~120 dirt
setblock ~14 ~117 ~121 dirt
setblock ~14 ~117 ~122 dirt
setblock ~14 ~117 ~123 dirt
setblock ~14 ~117 ~124 dirt
setblock ~14 ~117 ~125 dirt
setblock ~14 ~117 ~126 dirt
setblock ~14 ~117 ~127 dirt
setblock ~14 ~117 ~128 dirt
setblock ~14 ~117 ~129 dirt
setblock ~14 ~117 ~130 dirt
setblock ~14 ~117 ~131 dirt
setblock ~14 ~118 ~77 dirt
setblock ~14 ~118 ~78 dirt
setblock ~14 ~118 ~79 dirt
setblock ~14 ~118 ~80 dirt
setblock ~14 ~118 ~81 dirt
setblock ~14 ~118 ~82 dirt
setblock ~14 ~118 ~83 dirt
setblock ~14 ~118 ~84 dirt
setblock ~14 ~118 ~86 dirt
setblock ~14 ~118 ~87 dirt
setblock ~14 ~118 ~101 dirt
setblock ~14 ~118 ~104 dirt
setblock ~14 ~118 ~107 dirt
setblock ~14 ~118 ~108 dirt
setblock ~14 ~118 ~109 dirt
setblock ~14 ~118 ~110 dirt
setblock ~14 ~118 ~111 dirt
setblock ~14 ~118 ~112 dirt
setblock ~14 ~118 ~113 dirt
setblock ~14 ~118 ~114 dirt
setblock ~14 ~118 ~115 dirt
setblock ~14 ~118 ~116 dirt
setblock ~14 ~118 ~117 dirt
setblock ~14 ~118 ~118 dirt
setblock ~14 ~118 ~119 dirt
