setblock ~14 ~118 ~120 dirt
setblock ~14 ~118 ~121 dirt
setblock ~14 ~118 ~122 dirt
setblock ~14 ~118 ~123 dirt
setblock ~14 ~118 ~124 dirt
setblock ~14 ~118 ~125 dirt
setblock ~14 ~118 ~126 dirt
setblock ~14 ~118 ~127 dirt
setblock ~14 ~118 ~128 dirt
setblock ~14 ~118 ~129 dirt
setblock ~14 ~118 ~130 dirt
setblock ~14 ~118 ~131 dirt
setblock ~14 ~118 ~132 dirt
setblock ~14 ~119 ~77 dirt
setblock ~14 ~119 ~78 dirt
setblock ~14 ~119 ~79 dirt
setblock ~14 ~119 ~80 dirt
setblock ~14 ~119 ~81 dirt
setblock ~14 ~119 ~82 dirt
setblock ~14 ~119 ~83 dirt
setblock ~14 ~119 ~84 dirt
setblock ~14 ~119 ~85 dirt
setblock ~14 ~119 ~86 dirt
setblock ~14 ~119 ~87 dirt
setblock ~14 ~119 ~88 dirt
setblock ~14 ~119 ~101 dirt
setblock ~14 ~119 ~103 dirt
setblock ~14 ~119 ~104 dirt
setblock ~14 ~119 ~105 dirt
setblock ~14 ~119 ~107 dirt
setblock ~14 ~119 ~108 dirt
setblock ~14 ~119 ~109 dirt
setblock ~14 ~119 ~110 dirt
setblock ~14 ~119 ~111 dirt
setblock ~14 ~119 ~112 dirt
setblock ~14 ~119 ~113 dirt
setblock ~14 ~119 ~114 dirt
setblock ~14 ~119 ~115 dirt
setblock ~14 ~119 ~116 dirt
setblock ~14 ~119 ~117 dirt
setblock ~14 ~119 ~118 dirt
setblock ~14 ~119 ~119 dirt
setblock ~14 ~119 ~120 dirt
setblock ~14 ~119 ~121 dirt
setblock ~14 ~119 ~122 dirt
setblock ~14 ~119 ~123 dirt
setblock ~14 ~119 ~124 dirt
setblock ~14 ~119 ~125 dirt
setblock ~14 ~119 ~126 dirt
setblock ~14 ~119 ~127 dirt
setblock ~14 ~119 ~128 dirt
setblock ~14 ~119 ~129 dirt
setblock ~14 ~119 ~130 dirt
setblock ~14 ~119 ~131 dirt
setblock ~14 ~119 ~132 dirt
setblock ~14 ~119 ~133 dirt
setblock ~14 ~120 ~77 dirt
setblock ~14 ~120 ~78 dirt
setblock ~14 ~120 ~79 dirt
setblock ~14 ~120 ~80 dirt
setblock ~14 ~120 ~81 dirt
setblock ~14 ~120 ~82 dirt
setblock ~14 ~120 ~83 dirt
setblock ~14 ~120 ~84 dirt
setblock ~14 ~120 ~85 dirt
setblock ~14 ~120 ~86 dirt
setblock ~14 ~120 ~87 dirt
setblock ~14 ~120 ~88 dirt
setblock ~14 ~120 ~89 dirt
setblock ~14 ~120 ~94 dirt
setblock ~14 ~120 ~100 dirt
setblock ~14 ~120 ~101 dirt
setblock ~14 ~120 ~102 dirt
setblock ~14 ~120 ~103 dirt
setblock ~14 ~120 ~104 dirt
setblock ~14 ~120 ~105 dirt
setblock ~14 ~120 ~106 dirt
setblock ~14 ~120 ~107 dirt
setblock ~14 ~120 ~108 dirt
setblock ~14 ~120 ~109 dirt
setblock ~14 ~120 ~110 dirt
setblock ~14 ~120 ~111 dirt
setblock ~14 ~120 ~112 dirt
setblock ~14 ~120 ~113 dirt
setblock ~14 ~120 ~114 dirt
setblock ~14 ~120 ~115 dirt
setblock ~14 ~120 ~116 dirt
setblock ~14 ~120 ~117 dirt
setblock ~14 ~120 ~118 dirt
setblock ~14 ~120 ~119 dirt
setblock ~14 ~120 ~120 dirt
setblock ~14 ~120 ~121 dirt
setblock ~14 ~120 ~122 dirt
setblock ~14 ~120 ~123 dirt
setblock ~14 ~120 ~124 dirt
setblock ~14 ~120 ~125 dirt
setblock ~14 ~120 ~126 dirt
setblock ~14 ~120 ~127 dirt
setblock ~14 ~120 ~128 dirt
setblock ~14 ~120 ~129 dirt
setblock ~14 ~120 ~130 dirt
setblock ~14 ~120 ~131 dirt
setblock ~14 ~120 ~132 dirt
setblock ~14 ~120 ~133 dirt
setblock ~14 ~120 ~134 dirt
setblock ~14 ~121 ~73 dirt
setblock ~14 ~121 ~76 dirt
setblock ~14 ~121 ~77 dirt
setblock ~14 ~121 ~78 dirt
setblock ~14 ~121 ~79 dirt
setblock ~14 ~121 ~80 dirt
setblock ~14 ~121 ~81 dirt
setblock ~14 ~121 ~82 dirt
setblock ~14 ~121 ~83 dirt
setblock ~14 ~121 ~84 dirt
setblock ~14 ~121 ~85 dirt
setblock ~14 ~121 ~86 dirt
setblock ~14 ~121 ~87 dirt
setblock ~14 ~121 ~88 dirt
setblock ~14 ~121 ~89 dirt
setblock ~14 ~121 ~94 dirt
setblock ~14 ~121 ~95 dirt
setblock ~14 ~121 ~97 dirt
setblock ~14 ~121 ~100 dirt
setblock ~14 ~121 ~101 dirt
setblock ~14 ~121 ~102 dirt
setblock ~14 ~121 ~103 dirt
setblock ~14 ~121 ~104 dirt
setblock ~14 ~121 ~105 dirt
setblock ~14 ~121 ~106 dirt
setblock ~14 ~121 ~107 dirt
setblock ~14 ~121 ~108 dirt
setblock ~14 ~121 ~109 dirt
setblock ~14 ~121 ~110 dirt
setblock ~14 ~121 ~111 dirt
setblock ~14 ~121 ~112 dirt
setblock ~14 ~121 ~113 dirt
setblock ~14 ~121 ~114 dirt
setblock ~14 ~121 ~115 dirt
setblock ~14 ~121 ~116 dirt
setblock ~14 ~121 ~117 dirt
setblock ~14 ~121 ~118 dirt
setblock ~14 ~121 ~119 dirt
setblock ~14 ~121 ~120 dirt
setblock ~14 ~121 ~121 dirt
setblock ~14 ~121 ~122 dirt
setblock ~14 ~121 ~123 dirt
setblock ~14 ~121 ~124 dirt
setblock ~14 ~121 ~125 dirt
setblock ~14 ~121 ~126 dirt
setblock ~14 ~121 ~127 dirt
setblock ~14 ~121 ~128 dirt
setblock ~14 ~121 ~129 dirt
setblock ~14 ~121 ~130 dirt
setblock ~14 ~121 ~131 dirt
setblock ~14 ~121 ~132 dirt
setblock ~14 ~121 ~133 dirt
setblock ~14 ~121 ~134 dirt
setblock ~14 ~121 ~135 dirt
setblock ~14 ~122 ~73 dirt
setblock ~14 ~122 ~76 dirt
setblock ~14 ~122 ~77 dirt
setblock ~14 ~122 ~78 dirt
setblock ~14 ~122 ~79 dirt
setblock ~14 ~122 ~80 dirt
setblock ~14 ~122 ~81 dirt
setblock ~14 ~122 ~82 dirt
setblock ~14 ~122 ~83 dirt
setblock ~14 ~122 ~84 dirt
setblock ~14 ~122 ~85 dirt
setblock ~14 ~122 ~86 dirt
setblock ~14 ~122 ~87 dirt
setblock ~14 ~122 ~88 dirt
setblock ~14 ~122 ~89 dirt
setblock ~14 ~122 ~94 dirt
setblock ~14 ~122 ~95 dirt
setblock ~14 ~122 ~97 dirt
setblock ~14 ~122 ~100 dirt
setblock ~14 ~122 ~101 dirt
setblock ~14 ~122 ~102 dirt
setblock ~14 ~122 ~103 dirt
setblock ~14 ~122 ~104 dirt
setblock ~14 ~122 ~105 dirt
setblock ~14 ~122 ~106 dirt
setblock ~14 ~122 ~107 dirt
setblock ~14 ~122 ~108 dirt
setblock ~14 ~122 ~109 dirt
setblock ~14 ~122 ~110 dirt
setblock ~14 ~122 ~111 dirt
setblock ~14 ~122 ~112 dirt
setblock ~14 ~122 ~113 dirt
setblock ~14 ~122 ~114 dirt
setblock ~14 ~122 ~115 dirt
setblock ~14 ~122 ~116 dirt
setblock ~14 ~122 ~117 dirt
setblock ~14 ~122 ~118 dirt
setblock ~14 ~122 ~119 dirt
setblock ~14 ~122 ~120 dirt
setblock ~14 ~122 ~121 dirt
setblock ~14 ~122 ~122 dirt
setblock ~14 ~122 ~123 dirt
setblock ~14 ~122 ~124 dirt
setblock ~14 ~122 ~125 dirt
setblock ~14 ~122 ~126 dirt
setblock ~14 ~122 ~127 dirt
setblock ~14 ~122 ~128 dirt
setblock ~14 ~122 ~129 dirt
setblock ~14 ~122 ~130 dirt
setblock ~14 ~122 ~131 dirt
setblock ~14 ~122 ~132 dirt
setblock ~14 ~122 ~133 dirt
setblock ~14 ~122 ~134 dirt
setblock ~14 ~122 ~135 dirt
setblock ~14 ~123 ~73 dirt
setblock ~14 ~123 ~76 dirt
setblock ~14 ~123 ~77 dirt
setblock ~14 ~123 ~78 dirt
setblock ~14 ~123 ~79 dirt
setblock ~14 ~123 ~80 dirt
setblock ~14 ~123 ~81 dirt
setblock ~14 ~123 ~82 dirt
setblock ~14 ~123 ~83 dirt
setblock ~14 ~123 ~84 dirt
setblock ~14 ~123 ~85 dirt
setblock ~14 ~123 ~86 dirt
setblock ~14 ~123 ~87 dirt
setblock ~14 ~123 ~88 dirt
setblock ~14 ~123 ~89 dirt
setblock ~14 ~123 ~94 dirt
setblock ~14 ~123 ~95 dirt
setblock ~14 ~123 ~97 dirt
setblock ~14 ~123 ~100 dirt
setblock ~14 ~123 ~101 dirt
setblock ~14 ~123 ~102 dirt
setblock ~14 ~123 ~103 dirt
setblock ~14 ~123 ~104 dirt
setblock ~14 ~123 ~105 dirt
setblock ~14 ~123 ~106 dirt
setblock ~14 ~123 ~107 dirt
setblock ~14 ~123 ~108 dirt
setblock ~14 ~123 ~109 dirt
setblock ~14 ~123 ~110 dirt
setblock ~14 ~123 ~111 dirt
setblock ~14 ~123 ~112 dirt
setblock ~14 ~123 ~113 dirt
setblock ~14 ~123 ~114 dirt
setblock ~14 ~123 ~115 dirt
setblock ~14 ~123 ~116 dirt
setblock ~14 ~123 ~117 dirt
setblock ~14 ~123 ~118 dirt
setblock ~14 ~123 ~119 dirt
setblock ~14 ~123 ~120 dirt
setblock ~14 ~123 ~121 dirt
setblock ~14 ~123 ~122 dirt
setblock ~14 ~123 ~123 dirt
setblock ~14 ~123 ~124 dirt
setblock ~14 ~123 ~125 dirt
setblock ~14 ~123 ~126 dirt
setblock ~14 ~123 ~127 dirt
setblock ~14 ~123 ~128 dirt
setblock ~14 ~123 ~129 dirt
setblock ~14 ~123 ~130 dirt
setblock ~14 ~123 ~131 dirt
setblock ~14 ~123 ~132 dirt
setblock ~14 ~123 ~133 dirt
setblock ~14 ~123 ~134 dirt
setblock ~14 ~123 ~135 dirt
setblock ~14 ~124 ~73 dirt
setblock ~14 ~124 ~76 dirt
setblock ~14 ~124 ~77 dirt
setblock ~14 ~124 ~78 dirt
setblock ~14 ~124 ~79 dirt
setblock ~14 ~124 ~80 dirt
setblock ~14 ~124 ~81 dirt
setblock ~14 ~124 ~82 dirt
setblock ~14 ~124 ~83 dirt
setblock ~14 ~124 ~84 dirt
setblock ~14 ~124 ~85 dirt
setblock ~14 ~124 ~86 dirt
setblock ~14 ~124 ~87 grass_block
setblock ~14 ~124 ~88 grass_block
setblock ~14 ~124 ~89 grass_block
setblock ~14 ~124 ~94 grass_block
setblock ~14 ~124 ~95 grass_block
setblock ~14 ~124 ~97 dirt
setblock ~14 ~124 ~100 dirt
setblock ~14 ~124 ~101 dirt
setblock ~14 ~124 ~102 dirt
setblock ~14 ~124 ~103 dirt
setblock ~14 ~124 ~104 dirt
setblock ~14 ~124 ~105 dirt
setblock ~14 ~124 ~106 grass_block
setblock ~14 ~124 ~107 grass_block
setblock ~14 ~124 ~108 grass_block
setblock ~14 ~124 ~109 grass_block
setblock ~14 ~124 ~110 grass_block
setblock ~14 ~124 ~111 grass_block
setblock ~14 ~124 ~112 grass_block
setblock ~14 ~124 ~113 grass_block
setblock ~14 ~124 ~114 grass_block
setblock ~14 ~124 ~115 dirt
setblock ~14 ~124 ~116 dirt
setblock ~14 ~124 ~117 dirt
setblock ~14 ~124 ~118 dirt
setblock ~14 ~124 ~119 dirt
setblock ~14 ~124 ~120 dirt
setblock ~14 ~124 ~121 dirt
setblock ~14 ~124 ~122 dirt
setblock ~14 ~124 ~123 dirt
setblock ~14 ~124 ~124 dirt
setblock ~14 ~124 ~125 dirt
setblock ~14 ~124 ~126 dirt
setblock ~14 ~124 ~127 dirt
setblock ~14 ~124 ~128 dirt
setblock ~14 ~124 ~129 dirt
setblock ~14 ~124 ~130 dirt
setblock ~14 ~124 ~131 dirt
setblock ~14 ~124 ~132 dirt
setblock ~14 ~124 ~133 dirt
setblock ~14 ~124 ~134 dirt
setblock ~14 ~124 ~135 dirt
setblock ~14 ~125 ~73 grass_block
setblock ~14 ~125 ~76 dirt
setblock ~14 ~125 ~77 dirt
setblock ~14 ~125 ~78 dirt
setblock ~14 ~125 ~79 dirt
setblock ~14 ~125 ~80 dirt
setblock ~14 ~125 ~81 dirt
setblock ~14 ~125 ~82 grass_block
setblock ~14 ~125 ~83 grass_block
setblock ~14 ~125 ~84 grass_block
setblock ~14 ~125 ~85 grass_block
setblock ~14 ~125 ~86 grass_block
setblock ~14 ~125 ~97 grass_block
setblock ~14 ~125 ~100 grass_block
setblock ~14 ~125 ~101 grass_block
setblock ~14 ~125 ~102 grass_block
setblock ~14 ~125 ~103 grass_block
setblock ~14 ~125 ~104 grass_block
setblock ~14 ~125 ~105 grass_block
setblock ~14 ~125 ~107 short_grass
setblock ~14 ~125 ~109 short_grass
setblock ~14 ~125 ~111 short_grass
setblock ~14 ~125 ~115 grass_block
setblock ~14 ~125 ~116 grass_block
setblock ~14 ~125 ~117 grass_block
setblock ~14 ~125 ~118 grass_block
setblock ~14 ~125 ~119 grass_block
setblock ~14 ~125 ~120 grass_block
setblock ~14 ~125 ~121 grass_block
setblock ~14 ~125 ~122 grass_block
setblock ~14 ~125 ~123 grass_block
setblock ~14 ~125 ~124 grass_block
setblock ~14 ~125 ~125 grass_block
setblock ~14 ~125 ~126 grass_block
setblock ~14 ~125 ~127 grass_block
setblock ~14 ~125 ~128 grass_block
setblock ~14 ~125 ~129 grass_block
setblock ~14 ~125 ~130 grass_block
setblock ~14 ~125 ~131 grass_block
setblock ~14 ~125 ~132 grass_block
setblock ~14 ~125 ~133 grass_block
setblock ~14 ~125 ~134 grass_block
setblock ~14 ~125 ~135 grass_block
setblock ~14 ~126 ~76 grass_block
setblock ~14 ~126 ~77 grass_block
setblock ~14 ~126 ~78 grass_block
setblock ~14 ~126 ~79 grass_block
setblock ~14 ~126 ~80 grass_block
setblock ~14 ~126 ~81 grass_block
setblock ~14 ~126 ~83 short_grass
setblock ~14 ~126 ~84 short_grass
setblock ~14 ~126 ~121 short_grass
setblock ~14 ~126 ~124 short_grass
setblock ~14 ~126 ~128 short_grass
setblock ~14 ~126 ~131 fern
setblock ~14 ~127 ~77 short_grass
setblock ~15 ~102 ~114 dirt
setblock ~15 ~103 ~114 dirt
setblock ~15 ~103 ~116 dirt
setblock ~15 ~103 ~118 dirt
setblock ~15 ~104 ~113 dirt
setblock ~15 ~104 ~114 dirt
setblock ~15 ~104 ~115 dirt
setblock ~15 ~104 ~116 dirt
setblock ~15 ~104 ~117 dirt
setblock ~15 ~104 ~118 dirt
setblock ~15 ~105 ~112 dirt
setblock ~15 ~105 ~113 dirt
setblock ~15 ~105 ~114 dirt
setblock ~15 ~105 ~115 dirt
setblock ~15 ~105 ~116 dirt
setblock ~15 ~105 ~117 dirt
setblock ~15 ~105 ~118 dirt
setblock ~15 ~105 ~119 dirt
setblock ~15 ~106 ~112 dirt
setblock ~15 ~106 ~113 dirt
setblock ~15 ~106 ~114 dirt
setblock ~15 ~106 ~115 dirt
setblock ~15 ~106 ~116 dirt
setblock ~15 ~106 ~117 dirt
setblock ~15 ~106 ~118 dirt
setblock ~15 ~106 ~119 dirt
setblock ~15 ~107 ~112 dirt
setblock ~15 ~107 ~113 dirt
setblock ~15 ~107 ~114 dirt
setblock ~15 ~107 ~115 dirt
setblock ~15 ~107 ~116 dirt
setblock ~15 ~107 ~117 dirt
setblock ~15 ~107 ~118 dirt
setblock ~15 ~107 ~119 dirt
setblock ~15 ~107 ~120 dirt
setblock ~15 ~108 ~111 dirt
setblock ~15 ~108 ~112 dirt
setblock ~15 ~108 ~113 dirt
setblock ~15 ~108 ~114 dirt
setblock ~15 ~108 ~115 dirt
setblock ~15 ~108 ~116 dirt
setblock ~15 ~108 ~117 dirt
setblock ~15 ~108 ~118 dirt
setblock ~15 ~108 ~119 dirt
setblock ~15 ~108 ~120 dirt
setblock ~15 ~108 ~121 dirt
setblock ~15 ~109 ~110 dirt
setblock ~15 ~109 ~111 dirt
setblock ~15 ~109 ~112 dirt
setblock ~15 ~109 ~113 dirt
setblock ~15 ~109 ~114 dirt
setblock ~15 ~109 ~115 dirt
setblock ~15 ~109 ~116 dirt
setblock ~15 ~109 ~117 dirt
setblock ~15 ~109 ~118 dirt
setblock ~15 ~109 ~119 dirt
setblock ~15 ~109 ~120 dirt
setblock ~15 ~109 ~121 dirt
setblock ~15 ~110 ~110 dirt
setblock ~15 ~110 ~111 dirt
setblock ~15 ~110 ~112 dirt
setblock ~15 ~110 ~113 dirt
setblock ~15 ~110 ~114 dirt
setblock ~15 ~110 ~115 dirt
setblock ~15 ~110 ~116 dirt
setblock ~15 ~110 ~117 dirt
setblock ~15 ~110 ~118 dirt
setblock ~15 ~110 ~119 dirt
setblock ~15 ~110 ~120 dirt
setblock ~15 ~110 ~121 dirt
setblock ~15 ~110 ~122 dirt
setblock ~15 ~110 ~125 dirt
setblock ~15 ~110 ~127 dirt
setblock ~15 ~111 ~110 dirt
setblock ~15 ~111 ~111 dirt
setblock ~15 ~111 ~112 dirt
setblock ~15 ~111 ~113 dirt
setblock ~15 ~111 ~114 dirt
setblock ~15 ~111 ~115 dirt
setblock ~15 ~111 ~116 dirt
setblock ~15 ~111 ~117 dirt
setblock ~15 ~111 ~118 dirt
setblock ~15 ~111 ~119 dirt
setblock ~15 ~111 ~120 dirt
setblock ~15 ~111 ~121 dirt
setblock ~15 ~111 ~122 dirt
setblock ~15 ~111 ~123 dirt
setblock ~15 ~111 ~125 dirt
setblock ~15 ~111 ~126 dirt
setblock ~15 ~111 ~127 dirt
setblock ~15 ~111 ~128 dirt
setblock ~15 ~112 ~81 dirt
setblock ~15 ~112 ~108 dirt
setblock ~15 ~112 ~110 dirt
setblock ~15 ~112 ~111 dirt
setblock ~15 ~112 ~112 dirt
setblock ~15 ~112 ~113 dirt
setblock ~15 ~112 ~114 dirt
setblock ~15 ~112 ~115 dirt
setblock ~15 ~112 ~116 dirt
setblock ~15 ~112 ~117 dirt
setblock ~15 ~112 ~118 dirt
setblock ~15 ~112 ~119 dirt
setblock ~15 ~112 ~120 dirt
setblock ~15 ~112 ~121 dirt
setblock ~15 ~112 ~122 dirt
setblock ~15 ~112 ~123 dirt
setblock ~15 ~112 ~124 dirt
setblock ~15 ~112 ~125 dirt
setblock ~15 ~112 ~126 dirt
setblock ~15 ~112 ~127 dirt
setblock ~15 ~112 ~128 dirt
setblock ~15 ~113 ~80 dirt
setblock ~15 ~113 ~81 dirt
setblock ~15 ~113 ~82 dirt
setblock ~15 ~113 ~83 dirt
setblock ~15 ~113 ~108 dirt
setblock ~15 ~113 ~109 dirt
setblock ~15 ~113 ~110 dirt
setblock ~15 ~113 ~111 dirt
setblock ~15 ~113 ~112 dirt
setblock ~15 ~113 ~113 dirt
setblock ~15 ~113 ~114 dirt
setblock ~15 ~113 ~115 dirt
setblock ~15 ~113 ~116 dirt
setblock ~15 ~113 ~117 dirt
setblock ~15 ~113 ~118 dirt
setblock ~15 ~113 ~119 dirt
setblock ~15 ~113 ~120 dirt
setblock ~15 ~113 ~121 dirt
setblock ~15 ~113 ~122 dirt
setblock ~15 ~113 ~123 dirt
setblock ~15 ~113 ~124 dirt
setblock ~15 ~113 ~125 dirt
setblock ~15 ~113 ~126 dirt
setblock ~15 ~113 ~127 dirt
setblock ~15 ~113 ~128 dirt
setblock ~15 ~113 ~130 dirt
setblock ~15 ~114 ~79 dirt
setblock ~15 ~114 ~80 dirt
setblock ~15 ~114 ~81 dirt
setblock ~15 ~114 ~82 dirt
setblock ~15 ~114 ~83 dirt
setblock ~15 ~114 ~84 dirt
setblock ~15 ~114 ~86 dirt
setblock ~15 ~114 ~108 dirt
setblock ~15 ~114 ~109 dirt
setblock ~15 ~114 ~110 dirt
setblock ~15 ~114 ~111 dirt
setblock ~15 ~114 ~112 dirt
setblock ~15 ~114 ~113 dirt
setblock ~15 ~114 ~114 dirt
setblock ~15 ~114 ~115 dirt
setblock ~15 ~114 ~116 dirt
setblock ~15 ~114 ~117 dirt
setblock ~15 ~114 ~118 dirt
setblock ~15 ~114 ~119 dirt
setblock ~15 ~114 ~120 dirt
setblock ~15 ~114 ~121 dirt
setblock ~15 ~114 ~122 dirt
setblock ~15 ~114 ~123 dirt
setblock ~15 ~114 ~124 dirt
setblock ~15 ~114 ~125 dirt
setblock ~15 ~114 ~126 dirt
setblock ~15 ~114 ~127 dirt
setblock ~15 ~114 ~128 dirt
setblock ~15 ~114 ~129 dirt
setblock ~15 ~114 ~130 dirt
setblock ~15 ~114 ~131 dirt
setblock ~15 ~115 ~78 dirt
setblock ~15 ~115 ~79 dirt
setblock ~15 ~115 ~80 dirt
setblock ~15 ~115 ~81 dirt
setblock ~15 ~115 ~82 dirt
setblock ~15 ~115 ~83 dirt
setblock ~15 ~115 ~84 dirt
setblock ~15 ~115 ~85 dirt
setblock ~15 ~115 ~86 dirt
setblock ~15 ~115 ~87 dirt
setblock ~15 ~115 ~108 dirt
setblock ~15 ~115 ~109 dirt
setblock ~15 ~115 ~110 dirt
setblock ~15 ~115 ~111 dirt
setblock ~15 ~115 ~112 dirt
setblock ~15 ~115 ~113 dirt
setblock ~15 ~115 ~114 dirt
setblock ~15 ~115 ~115 dirt
setblock ~15 ~115 ~116 dirt
setblock ~15 ~115 ~117 dirt
setblock ~15 ~115 ~118 dirt
setblock ~15 ~115 ~119 dirt
setblock ~15 ~115 ~120 dirt
setblock ~15 ~115 ~121 dirt
setblock ~15 ~115 ~122 dirt
setblock ~15 ~115 ~123 dirt
setblock ~15 ~115 ~124 dirt
setblock ~15 ~115 ~125 dirt
setblock ~15 ~115 ~126 dirt
setblock ~15 ~115 ~127 dirt
setblock ~15 ~115 ~128 dirt
setblock ~15 ~115 ~129 dirt
setblock ~15 ~115 ~130 dirt
setblock ~15 ~115 ~131 dirt
setblock ~15 ~116 ~77 dirt
setblock ~15 ~116 ~78 dirt
setblock ~15 ~116 ~79 dirt
setblock ~15 ~116 ~80 dirt
setblock ~15 ~116 ~81 dirt
setblock ~15 ~116 ~82 dirt
setblock ~15 ~116 ~83 dirt
setblock ~15 ~116 ~84 dirt
setblock ~15 ~116 ~85 dirt
setblock ~15 ~116 ~86 dirt
setblock ~15 ~116 ~87 dirt
setblock ~15 ~116 ~107 dirt
setblock ~15 ~116 ~108 dirt
setblock ~15 ~116 ~109 dirt
setblock ~15 ~116 ~110 dirt
setblock ~15 ~116 ~111 dirt
setblock ~15 ~116 ~112 dirt
setblock ~15 ~116 ~113 dirt
setblock ~15 ~116 ~114 dirt
setblock ~15 ~116 ~115 dirt
setblock ~15 ~116 ~116 dirt
setblock ~15 ~116 ~117 dirt
setblock ~15 ~116 ~118 dirt
setblock ~15 ~116 ~119 dirt
setblock ~15 ~116 ~120 dirt
setblock ~15 ~116 ~121 dirt
setblock ~15 ~116 ~122 dirt
setblock ~15 ~116 ~123 dirt
setblock ~15 ~116 ~124 dirt
setblock ~15 ~116 ~125 dirt
setblock ~15 ~116 ~126 dirt
setblock ~15 ~116 ~127 dirt
setblock ~15 ~116 ~128 dirt
setblock ~15 ~116 ~129 dirt
setblock ~15 ~116 ~130 dirt
setblock ~15 ~116 ~131 dirt
setblock ~15 ~117 ~77 dirt
setblock ~15 ~117 ~78 dirt
setblock ~15 ~117 ~79 dirt
setblock ~15 ~117 ~80 dirt
setblock ~15 ~117 ~81 dirt
setblock ~15 ~117 ~82 dirt
setblock ~15 ~117 ~83 dirt
setblock ~15 ~117 ~84 dirt
setblock ~15 ~117 ~85 dirt
setblock ~15 ~117 ~86 dirt
setblock ~15 ~117 ~87 dirt
setblock ~15 ~117 ~88 dirt
setblock ~15 ~117 ~104 dirt
setblock ~15 ~117 ~107 dirt
setblock ~15 ~117 ~108 dirt
setblock ~15 ~117 ~109 dirt
setblock ~15 ~117 ~110 dirt
setblock ~15 ~117 ~111 dirt
setblock ~15 ~117 ~112 dirt
setblock ~15 ~117 ~113 dirt
setblock ~15 ~117 ~114 dirt
setblock ~15 ~117 ~115 dirt
setblock ~15 ~117 ~116 dirt
setblock ~15 ~117 ~117 dirt
setblock ~15 ~117 ~118 dirt
setblock ~15 ~117 ~119 dirt
setblock ~15 ~117 ~120 dirt
setblock ~15 ~117 ~121 dirt
setblock ~15 ~117 ~122 dirt
setblock ~15 ~117 ~123 dirt
setblock ~15 ~117 ~124 dirt
setblock ~15 ~117 ~125 dirt
setblock ~15 ~117 ~126 dirt
setblock ~15 ~117 ~127 dirt
setblock ~15 ~117 ~128 dirt
setblock ~15 ~117 ~129 dirt
setblock ~15 ~117 ~130 dirt
setblock ~15 ~117 ~131 dirt
setblock ~15 ~117 ~132 dirt
setblock ~15 ~118 ~76 dirt
setblock ~15 ~118 ~77 dirt
setblock ~15 ~118 ~78 dirt
setblock ~15 ~118 ~79 dirt
setblock ~15 ~118 ~80 dirt
setblock ~15 ~118 ~81 dirt
setblock ~15 ~118 ~82 dirt
setblock ~15 ~118 ~83 dirt
setblock ~15 ~118 ~84 dirt
setblock ~15 ~118 ~85 dirt
setblock ~15 ~118 ~86 dirt
setblock ~15 ~118 ~87 dirt
setblock ~15 ~118 ~88 dirt
setblock ~15 ~118 ~94 dirt
setblock ~15 ~118 ~103 dirt
setblock ~15 ~118 ~104 dirt
setblock ~15 ~118 ~105 dirt
setblock ~15 ~118 ~106 dirt
setblock ~15 ~118 ~107 dirt
setblock ~15 ~118 ~108 dirt
setblock ~15 ~118 ~109 dirt
setblock ~15 ~118 ~110 dirt
setblock ~15 ~118 ~111 dirt
setblock ~15 ~118 ~112 dirt
setblock ~15 ~118 ~113 dirt
setblock ~15 ~118 ~114 dirt
setblock ~15 ~118 ~115 dirt
setblock ~15 ~118 ~116 dirt
setblock ~15 ~118 ~117 dirt
setblock ~15 ~118 ~118 dirt
setblock ~15 ~118 ~119 dirt
setblock ~15 ~118 ~120 dirt
setblock ~15 ~118 ~121 dirt
setblock ~15 ~118 ~122 dirt
setblock ~15 ~118 ~123 dirt
setblock ~15 ~118 ~124 dirt
setblock ~15 ~118 ~125 dirt
setblock ~15 ~118 ~126 dirt
setblock ~15 ~118 ~127 dirt
setblock ~15 ~118 ~128 dirt
setblock ~15 ~118 ~129 dirt
setblock ~15 ~118 ~130 dirt
setblock ~15 ~118 ~131 dirt
setblock ~15 ~118 ~132 dirt
setblock ~15 ~118 ~133 dirt
setblock ~15 ~119 ~75 dirt
setblock ~15 ~119 ~76 dirt
setblock ~15 ~119 ~77 dirt
setblock ~15 ~119 ~78 dirt
setblock ~15 ~119 ~79 dirt
setblock ~15 ~119 ~80 dirt
setblock ~15 ~119 ~81 dirt
setblock ~15 ~119 ~82 dirt
setblock ~15 ~119 ~83 dirt
setblock ~15 ~119 ~84 dirt
setblock ~15 ~119 ~85 dirt
setblock ~15 ~119 ~86 dirt
setblock ~15 ~119 ~87 dirt
setblock ~15 ~119 ~88 dirt
setblock ~15 ~119 ~89 dirt
setblock ~15 ~119 ~94 dirt
setblock ~15 ~119 ~101 dirt
setblock ~15 ~119 ~102 dirt
setblock ~15 ~119 ~103 dirt
setblock ~15 ~119 ~104 dirt
setblock ~15 ~119 ~105 dirt
setblock ~15 ~119 ~106 dirt
setblock ~15 ~119 ~107 dirt
setblock ~15 ~119 ~108 dirt
setblock ~15 ~119 ~109 dirt
setblock ~15 ~119 ~110 dirt
setblock ~15 ~119 ~111 dirt
setblock ~15 ~119 ~112 dirt
setblock ~15 ~119 ~113 dirt
setblock ~15 ~119 ~114 dirt
setblock ~15 ~119 ~115 dirt
setblock ~15 ~119 ~116 dirt
setblock ~15 ~119 ~117 dirt
setblock ~15 ~119 ~118 dirt
setblock ~15 ~119 ~119 dirt
setblock ~15 ~119 ~120 dirt
setblock ~15 ~119 ~121 dirt
setblock ~15 ~119 ~122 dirt
setblock ~15 ~119 ~123 dirt
setblock ~15 ~119 ~124 dirt
setblock ~15 ~119 ~125 dirt
setblock ~15 ~119 ~126 dirt
setblock ~15 ~119 ~127 dirt
setblock ~15 ~119 ~128 dirt
setblock ~15 ~119 ~129 dirt
setblock ~15 ~119 ~130 dirt
setblock ~15 ~119 ~131 dirt
setblock ~15 ~119 ~132 dirt
setblock ~15 ~119 ~133 dirt
setblock ~15 ~119 ~134 dirt
setblock ~15 ~120 ~73 dirt
setblock ~15 ~120 ~75 dirt
setblock ~15 ~120 ~76 dirt
setblock ~15 ~120 ~77 dirt
setblock ~15 ~120 ~78 dirt
setblock ~15 ~120 ~79 dirt
setblock ~15 ~120 ~80 dirt
setblock ~15 ~120 ~81 dirt
setblock ~15 ~120 ~82 dirt
setblock ~15 ~120 ~83 dirt
setblock ~15 ~120 ~84 dirt
setblock ~15 ~120 ~85 dirt
setblock ~15 ~120 ~86 dirt
setblock ~15 ~120 ~87 dirt
setblock ~15 ~120 ~88 dirt
setblock ~15 ~120 ~89 dirt
setblock ~15 ~120 ~90 dirt
setblock ~15 ~120 ~93 dirt
setblock ~15 ~120 ~94 dirt
setblock ~15 ~120 ~95 dirt
setblock ~15 ~120 ~96 dirt
setblock ~15 ~120 ~97 dirt
setblock ~15 ~120 ~101 dirt
setblock ~15 ~120 ~102 dirt
setblock ~15 ~120 ~103 dirt
setblock ~15 ~120 ~104 dirt
setblock ~15 ~120 ~105 dirt
setblock ~15 ~120 ~106 dirt
setblock ~15 ~120 ~107 dirt
setblock ~15 ~120 ~108 dirt
setblock ~15 ~120 ~109 dirt
setblock ~15 ~120 ~110 dirt
setblock ~15 ~120 ~111 dirt
setblock ~15 ~120 ~112 dirt
setblock ~15 ~120 ~113 dirt
setblock ~15 ~120 ~114 dirt
setblock ~15 ~120 ~115 dirt
setblock ~15 ~120 ~116 dirt
setblock ~15 ~120 ~117 dirt
setblock ~15 ~120 ~118 dirt
setblock ~15 ~120 ~119 dirt
setblock ~15 ~120 ~120 dirt
setblock ~15 ~120 ~121 dirt
setblock ~15 ~120 ~122 dirt
setblock ~15 ~120 ~123 dirt
setblock ~15 ~120 ~124 dirt
setblock ~15 ~120 ~125 dirt
setblock ~15 ~120 ~126 dirt
setblock ~15 ~120 ~127 dirt
setblock ~15 ~120 ~128 dirt
setblock ~15 ~120 ~129 dirt
setblock ~15 ~120 ~130 dirt
setblock ~15 ~120 ~131 dirt
setblock ~15 ~120 ~132 dirt
setblock ~15 ~120 ~133 dirt
setblock ~15 ~120 ~134 dirt
setblock ~15 ~121 ~72 dirt
setblock ~15 ~121 ~73 dirt
setblock ~15 ~121 ~74 dirt
setblock ~15 ~121 ~75 dirt
setblock ~15 ~121 ~76 dirt
setblock ~15 ~121 ~77 dirt
setblock ~15 ~121 ~78 dirt
setblock ~15 ~121 ~79 dirt
setblock ~15 ~121 ~80 dirt
setblock ~15 ~121 ~81 dirt
setblock ~15 ~121 ~82 dirt
setblock ~15 ~121 ~83 dirt
setblock ~15 ~121 ~84 dirt
setblock ~15 ~121 ~85 dirt
setblock ~15 ~121 ~86 dirt
setblock ~15 ~121 ~87 dirt
setblock ~15 ~121 ~88 dirt
setblock ~15 ~121 ~89 dirt
setblock ~15 ~121 ~90 dirt
setblock ~15 ~121 ~91 dirt
setblock ~15 ~121 ~93 dirt
setblock ~15 ~121 ~94 dirt
setblock ~15 ~121 ~95 dirt
setblock ~15 ~121 ~96 dirt
setblock ~15 ~121 ~97 dirt
setblock ~15 ~121 ~98 dirt
setblock ~15 ~121 ~100 dirt
setblock ~15 ~121 ~101 dirt
setblock ~15 ~121 ~102 dirt
setblock ~15 ~121 ~103 dirt
setblock ~15 ~121 ~104 dirt
setblock ~15 ~121 ~105 dirt
setblock ~15 ~121 ~106 dirt
setblock ~15 ~121 ~107 dirt
setblock ~15 ~121 ~108 dirt
setblock ~15 ~121 ~109 dirt
setblock ~15 ~121 ~110 dirt
setblock ~15 ~121 ~111 dirt
setblock ~15 ~121 ~112 dirt
setblock ~15 ~121 ~113 dirt
setblock ~15 ~121 ~114 dirt
setblock ~15 ~121 ~115 dirt
setblock ~15 ~121 ~116 dirt
setblock ~15 ~121 ~117 dirt
setblock ~15 ~121 ~118 dirt
setblock ~15 ~121 ~119 dirt
setblock ~15 ~121 ~120 dirt
setblock ~15 ~121 ~121 dirt
setblock ~15 ~121 ~122 dirt
setblock ~15 ~121 ~123 dirt
setblock ~15 ~121 ~124 dirt
setblock ~15 ~121 ~125 dirt
setblock ~15 ~121 ~126 dirt
setblock ~15 ~121 ~127 dirt
setblock ~15 ~121 ~128 dirt
setblock ~15 ~121 ~129 dirt
setblock ~15 ~121 ~130 dirt
setblock ~15 ~121 ~131 dirt
setblock ~15 ~121 ~132 dirt
setblock ~15 ~121 ~133 dirt
setblock ~15 ~121 ~134 dirt
setblock ~15 ~122 ~72 dirt
setblock ~15 ~122 ~73 dirt
setblock ~15 ~122 ~74 dirt
setblock ~15 ~122 ~75 dirt
setblock ~15 ~122 ~76 dirt
setblock ~15 ~122 ~77 dirt
setblock ~15 ~122 ~78 dirt
setblock ~15 ~122 ~79 dirt
setblock ~15 ~122 ~80 dirt
setblock ~15 ~122 ~81 dirt
setblock ~15 ~122 ~82 dirt
setblock ~15 ~122 ~83 dirt
setblock ~15 ~122 ~84 dirt
setblock ~15 ~122 ~85 dirt
setblock ~15 ~122 ~86 dirt
setblock ~15 ~122 ~87 dirt
setblock ~15 ~122 ~88 dirt
setblock ~15 ~122 ~89 dirt
setblock ~15 ~122 ~90 dirt
setblock ~15 ~122 ~91 dirt
setblock ~15 ~122 ~93 dirt
setblock ~15 ~122 ~94 dirt
setblock ~15 ~122 ~95 dirt
setblock ~15 ~122 ~96 dirt
setblock ~15 ~122 ~97 dirt
setblock ~15 ~122 ~98 dirt
setblock ~15 ~122 ~100 dirt
setblock ~15 ~122 ~101 dirt
setblock ~15 ~122 ~102 dirt
setblock ~15 ~122 ~103 dirt
setblock ~15 ~122 ~104 dirt
setblock ~15 ~122 ~105 dirt
setblock ~15 ~122 ~106 dirt
setblock ~15 ~122 ~107 dirt
setblock ~15 ~122 ~108 dirt
setblock ~15 ~122 ~109 dirt
setblock ~15 ~122 ~110 dirt
setblock ~15 ~122 ~111 dirt
setblock ~15 ~122 ~112 dirt
setblock ~15 ~122 ~113 dirt
setblock ~15 ~122 ~114 dirt
setblock ~15 ~122 ~115 dirt
setblock ~15 ~122 ~116 dirt
setblock ~15 ~122 ~117 dirt
setblock ~15 ~122 ~118 dirt
setblock ~15 ~122 ~119 dirt
setblock ~15 ~122 ~120 dirt
setblock ~15 ~122 ~121 dirt
setblock ~15 ~122 ~122 dirt
setblock ~15 ~122 ~123 dirt
setblock ~15 ~122 ~124 dirt
setblock ~15 ~122 ~125 dirt
setblock ~15 ~122 ~126 dirt
setblock ~15 ~122 ~127 dirt
setblock ~15 ~122 ~128 dirt
setblock ~15 ~122 ~129 dirt
setblock ~15 ~122 ~130 dirt
setblock ~15 ~122 ~131 dirt
setblock ~15 ~122 ~132 dirt
setblock ~15 ~122 ~133 dirt
setblock ~15 ~122 ~134 dirt
setblock ~15 ~123 ~72 dirt
setblock ~15 ~123 ~73 dirt
setblock ~15 ~123 ~74 dirt
setblock ~15 ~123 ~75 dirt
setblock ~15 ~123 ~76 dirt
setblock ~15 ~123 ~77 dirt
setblock ~15 ~123 ~78 dirt
setblock ~15 ~123 ~79 dirt
setblock ~15 ~123 ~80 dirt
setblock ~15 ~123 ~81 dirt
setblock ~15 ~123 ~82 dirt
setblock ~15 ~123 ~83 dirt
setblock ~15 ~123 ~84 dirt
setblock ~15 ~123 ~85 dirt
setblock ~15 ~123 ~86 dirt
setblock ~15 ~123 ~87 dirt
setblock ~15 ~123 ~88 dirt
setblock ~15 ~123 ~89 dirt
setblock ~15 ~123 ~90 dirt
setblock ~15 ~123 ~91 dirt
setblock ~15 ~123 ~93 dirt
setblock ~15 ~123 ~94 dirt
setblock ~15 ~123 ~95 dirt
setblock ~15 ~123 ~96 dirt
setblock ~15 ~123 ~97 dirt
setblock ~15 ~123 ~98 dirt
setblock ~15 ~123 ~100 dirt
setblock ~15 ~123 ~101 dirt
setblock ~15 ~123 ~102 dirt
setblock ~15 ~123 ~103 dirt
setblock ~15 ~123 ~104 dirt
setblock ~15 ~123 ~105 dirt
setblock ~15 ~123 ~106 dirt
setblock ~15 ~123 ~107 dirt
setblock ~15 ~123 ~108 dirt
setblock ~15 ~123 ~109 dirt
setblock ~15 ~123 ~110 grass_block
setblock ~15 ~123 ~111 dirt
setblock ~15 ~123 ~112 dirt
setblock ~15 ~123 ~113 dirt
setblock ~15 ~123 ~114 dirt
setblock ~15 ~123 ~115 dirt
setblock ~15 ~123 ~116 dirt
setblock ~15 ~123 ~117 dirt
setblock ~15 ~123 ~118 dirt
setblock ~15 ~123 ~119 dirt
setblock ~15 ~123 ~120 dirt
setblock ~15 ~123 ~121 dirt
setblock ~15 ~123 ~122 dirt
setblock ~15 ~123 ~123 dirt
setblock ~15 ~123 ~124 dirt
setblock ~15 ~123 ~125 dirt
setblock ~15 ~123 ~126 dirt
setblock ~15 ~123 ~127 dirt
setblock ~15 ~123 ~128 dirt
setblock ~15 ~123 ~129 dirt
setblock ~15 ~123 ~130 dirt
setblock ~15 ~123 ~131 dirt
setblock ~15 ~123 ~132 dirt
setblock ~15 ~123 ~133 dirt
setblock ~15 ~123 ~134 dirt
setblock ~15 ~124 ~72 dirt
setblock ~15 ~124 ~73 dirt
setblock ~15 ~124 ~74 dirt
setblock ~15 ~124 ~75 dirt
setblock ~15 ~124 ~76 dirt
setblock ~15 ~124 ~77 dirt
setblock ~15 ~124 ~78 dirt
setblock ~15 ~124 ~79 dirt
setblock ~15 ~124 ~80 dirt
setblock ~15 ~124 ~81 dirt
setblock ~15 ~124 ~82 dirt
setblock ~15 ~124 ~83 dirt
setblock ~15 ~124 ~84 dirt
setblock ~15 ~124 ~85 dirt
setblock ~15 ~124 ~86 dirt
setblock ~15 ~124 ~87 grass_block
setblock ~15 ~124 ~88 grass_block
setblock ~15 ~124 ~89 grass_block
setblock ~15 ~124 ~90 grass_block
setblock ~15 ~124 ~91 grass_block
setblock ~15 ~124 ~93 grass_block
setblock ~15 ~124 ~94 grass_block
setblock ~15 ~124 ~95 grass_block
setblock ~15 ~124 ~96 dirt
setblock ~15 ~124 ~97 dirt
setblock ~15 ~124 ~98 dirt
setblock ~15 ~124 ~100 dirt
setblock ~15 ~124 ~101 dirt
setblock ~15 ~124 ~102 dirt
setblock ~15 ~124 ~103 dirt
setblock ~15 ~124 ~104 dirt
setblock ~15 ~124 ~105 grass_block
setblock ~15 ~124 ~106 grass_block
setblock ~15 ~124 ~107 grass_block
setblock ~15 ~124 ~108 grass_block
setblock ~15 ~124 ~109 grass_block
setblock ~15 ~124 ~111 grass_block
setblock ~15 ~124 ~112 grass_block
setblock ~15 ~124 ~113 grass_block
setblock ~15 ~124 ~114 grass_block
setblock ~15 ~124 ~115 dirt
setblock ~15 ~124 ~116 dirt
setblock ~15 ~124 ~117 dirt
setblock ~15 ~124 ~118 dirt
setblock ~15 ~124 ~119 dirt
setblock ~15 ~124 ~120 dirt
setblock ~15 ~124 ~121 dirt
setblock ~15 ~124 ~122 dirt
setblock ~15 ~124 ~123 dirt
setblock ~15 ~124 ~124 dirt
setblock ~15 ~124 ~125 dirt
setblock ~15 ~124 ~126 dirt
setblock ~15 ~124 ~127 dirt
setblock ~15 ~124 ~128 dirt
setblock ~15 ~124 ~129 dirt
setblock ~15 ~124 ~130 dirt
setblock ~15 ~124 ~131 dirt
setblock ~15 ~124 ~132 dirt
setblock ~15 ~124 ~133 dirt
setblock ~15 ~124 ~134 dirt
setblock ~15 ~125 ~72 grass_block
setblock ~15 ~125 ~73 grass_block
setblock ~15 ~125 ~74 grass_block
setblock ~15 ~125 ~75 grass_block
setblock ~15 ~125 ~76 dirt
setblock ~15 ~125 ~77 dirt
setblock ~15 ~125 ~78 dirt
setblock ~15 ~125 ~79 dirt
setblock ~15 ~125 ~80 dirt
setblock ~15 ~125 ~81 dirt
setblock ~15 ~125 ~82 grass_block
setblock ~15 ~125 ~83 grass_block
setblock ~15 ~125 ~84 grass_block
setblock ~15 ~125 ~85 grass_block
setblock ~15 ~125 ~86 grass_block
setblock ~15 ~125 ~89 short_grass
setblock ~15 ~125 ~93 short_grass
setblock ~15 ~125 ~94 short_grass
setblock ~15 ~125 ~95 short_grass
setblock ~15 ~125 ~96 grass_block
setblock ~15 ~125 ~97 grass_block
setblock ~15 ~125 ~98 grass_block
setblock ~15 ~125 ~100 grass_block
setblock ~15 ~125 ~101 grass_block
setblock ~15 ~125 ~102 grass_block
setblock ~15 ~125 ~103 grass_block
setblock ~15 ~125 ~104 grass_block
setblock ~15 ~125 ~107 short_grass
setblock ~15 ~125 ~112 short_grass
setblock ~15 ~125 ~115 grass_block
setblock ~15 ~125 ~116 grass_block
setblock ~15 ~125 ~117 grass_block
setblock ~15 ~125 ~118 grass_block
setblock ~15 ~125 ~119 grass_block
setblock ~15 ~125 ~120 grass_block
setblock ~15 ~125 ~121 grass_block
setblock ~15 ~125 ~122 grass_block
setblock ~15 ~125 ~123 grass_block
setblock ~15 ~125 ~124 grass_block
setblock ~15 ~125 ~125 grass_block
setblock ~15 ~125 ~126 grass_block
setblock ~15 ~125 ~127 grass_block
setblock ~15 ~125 ~128 grass_block
setblock ~15 ~125 ~129 grass_block
setblock ~15 ~125 ~130 grass_block
setblock ~15 ~125 ~131 grass_block
setblock ~15 ~125 ~132 grass_block
setblock ~15 ~125 ~133 grass_block
setblock ~15 ~125 ~134 grass_block
setblock ~15 ~126 ~76 grass_block
setblock ~15 ~126 ~77 grass_block
setblock ~15 ~126 ~78 grass_block
setblock ~15 ~126 ~79 grass_block
setblock ~15 ~126 ~80 grass_block
setblock ~15 ~126 ~81 grass_block
setblock ~15 ~126 ~97 short_grass
setblock ~15 ~126 ~103 short_grass
setblock ~15 ~126 ~116 short_grass
setblock ~15 ~126 ~118 short_grass
setblock ~15 ~126 ~122 short_grass
setblock ~15 ~126 ~128 short_grass
setblock ~15 ~126 ~134 short_grass
setblock ~15 ~127 ~77 short_grass
setblock ~16 ~101 ~114 dirt
setblock ~16 ~101 ~116 dirt
setblock ~16 ~101 ~117 dirt
setblock ~16 ~102 ~113 dirt
setblock ~16 ~102 ~114 dirt
setblock ~16 ~102 ~115 dirt
setblock ~16 ~102 ~116 dirt
setblock ~16 ~102 ~117 dirt
setblock ~16 ~102 ~118 dirt
setblock ~16 ~103 ~113 dirt
setblock ~16 ~103 ~114 dirt
setblock ~16 ~103 ~115 dirt
setblock ~16 ~103 ~116 dirt
setblock ~16 ~103 ~117 dirt
setblock ~16 ~103 ~118 dirt
setblock ~16 ~103 ~119 dirt
setblock ~16 ~104 ~112 dirt
setblock ~16 ~104 ~113 dirt
setblock ~16 ~104 ~114 dirt
setblock ~16 ~104 ~115 dirt
setblock ~16 ~104 ~116 dirt
setblock ~16 ~104 ~117 dirt
setblock ~16 ~104 ~118 dirt
setblock ~16 ~104 ~119 dirt
setblock ~16 ~104 ~120 dirt
setblock ~16 ~105 ~111 dirt
setblock ~16 ~105 ~112 dirt
setblock ~16 ~105 ~113 dirt
setblock ~16 ~105 ~114 dirt
setblock ~16 ~105 ~115 dirt
setblock ~16 ~105 ~116 dirt
setblock ~16 ~105 ~117 dirt
setblock ~16 ~105 ~118 dirt
setblock ~16 ~105 ~119 dirt
setblock ~16 ~105 ~120 dirt
setblock ~16 ~106 ~111 dirt
setblock ~16 ~106 ~112 dirt
setblock ~16 ~106 ~113 dirt
setblock ~16 ~106 ~114 dirt
setblock ~16 ~106 ~115 dirt
setblock ~16 ~106 ~116 dirt
setblock ~16 ~106 ~117 dirt
setblock ~16 ~106 ~118 dirt
setblock ~16 ~106 ~119 dirt
setblock ~16 ~106 ~120 dirt
setblock ~16 ~107 ~111 dirt
setblock ~16 ~107 ~112 dirt
setblock ~16 ~107 ~113 dirt
setblock ~16 ~107 ~114 dirt
setblock ~16 ~107 ~115 dirt
setblock ~16 ~107 ~116 dirt
setblock ~16 ~107 ~117 dirt
setblock ~16 ~107 ~118 dirt
setblock ~16 ~107 ~119 dirt
setblock ~16 ~107 ~120 dirt
setblock ~16 ~107 ~121 dirt
setblock ~16 ~108 ~110 dirt
setblock ~16 ~108 ~111 dirt
setblock ~16 ~108 ~112 dirt
setblock ~16 ~108 ~113 dirt
setblock ~16 ~108 ~114 dirt
setblock ~16 ~108 ~115 dirt
setblock ~16 ~108 ~116 dirt
setblock ~16 ~108 ~117 dirt
setblock ~16 ~108 ~118 dirt
setblock ~16 ~108 ~119 dirt
setblock ~16 ~108 ~120 dirt
setblock ~16 ~108 ~121 dirt
setblock ~16 ~108 ~122 dirt
setblock ~16 ~109 ~110 dirt
setblock ~16 ~109 ~111 dirt
setblock ~16 ~109 ~112 dirt
setblock ~16 ~109 ~113 dirt
setblock ~16 ~109 ~114 dirt
setblock ~16 ~109 ~115 dirt
setblock ~16 ~109 ~116 dirt
setblock ~16 ~109 ~117 dirt
setblock ~16 ~109 ~118 dirt
setblock ~16 ~109 ~119 dirt
setblock ~16 ~109 ~120 dirt
setblock ~16 ~109 ~121 dirt
setblock ~16 ~109 ~122 dirt
setblock ~16 ~109 ~125 dirt
setblock ~16 ~109 ~127 dirt
setblock ~16 ~110 ~81 dirt
setblock ~16 ~110 ~110 dirt
setblock ~16 ~110 ~111 dirt
setblock ~16 ~110 ~112 dirt
setblock ~16 ~110 ~113 dirt
setblock ~16 ~110 ~114 dirt
setblock ~16 ~110 ~115 dirt
setblock ~16 ~110 ~116 dirt
setblock ~16 ~110 ~117 dirt
setblock ~16 ~110 ~118 dirt
setblock ~16 ~110 ~119 dirt
setblock ~16 ~110 ~120 dirt
setblock ~16 ~110 ~121 dirt
setblock ~16 ~110 ~122 dirt
setblock ~16 ~110 ~123 dirt
setblock ~16 ~110 ~124 dirt
setblock ~16 ~110 ~125 dirt
setblock ~16 ~110 ~126 dirt
setblock ~16 ~110 ~127 dirt
setblock ~16 ~110 ~128 dirt
setblock ~16 ~111 ~80 dirt
setblock ~16 ~111 ~81 dirt
setblock ~16 ~111 ~82 dirt
setblock ~16 ~111 ~108 dirt
setblock ~16 ~111 ~109 dirt
setblock ~16 ~111 ~110 dirt
setblock ~16 ~111 ~111 dirt
setblock ~16 ~111 ~112 dirt
setblock ~16 ~111 ~113 dirt
setblock ~16 ~111 ~114 dirt
setblock ~16 ~111 ~115 dirt
setblock ~16 ~111 ~116 dirt
setblock ~16 ~111 ~117 dirt
setblock ~16 ~111 ~118 dirt
setblock ~16 ~111 ~119 dirt
setblock ~16 ~111 ~120 dirt
setblock ~16 ~111 ~121 dirt
setblock ~16 ~111 ~122 dirt
setblock ~16 ~111 ~123 dirt
setblock ~16 ~111 ~124 dirt
setblock ~16 ~111 ~125 dirt
setblock ~16 ~111 ~126 dirt
setblock ~16 ~111 ~127 dirt
setblock ~16 ~111 ~128 dirt
setblock ~16 ~111 ~129 dirt
setblock ~16 ~112 ~80 dirt
setblock ~16 ~112 ~81 dirt
setblock ~16 ~112 ~82 dirt
setblock ~16 ~112 ~83 dirt
setblock ~16 ~112 ~86 dirt
setblock ~16 ~112 ~107 dirt
setblock ~16 ~112 ~108 dirt
setblock ~16 ~112 ~109 dirt
setblock ~16 ~112 ~110 dirt
setblock ~16 ~112 ~111 dirt
setblock ~16 ~112 ~112 dirt
setblock ~16 ~112 ~113 dirt
setblock ~16 ~112 ~114 dirt
setblock ~16 ~112 ~115 dirt
setblock ~16 ~112 ~116 dirt
setblock ~16 ~112 ~117 dirt
setblock ~16 ~112 ~118 dirt
setblock ~16 ~112 ~119 dirt
setblock ~16 ~112 ~120 dirt
setblock ~16 ~112 ~121 dirt
setblock ~16 ~112 ~122 dirt
setblock ~16 ~112 ~123 dirt
setblock ~16 ~112 ~124 dirt
setblock ~16 ~112 ~125 dirt
setblock ~16 ~112 ~126 dirt
setblock ~16 ~112 ~127 dirt
setblock ~16 ~112 ~128 dirt
setblock ~16 ~112 ~129 dirt
setblock ~16 ~112 ~130 dirt
setblock ~16 ~113 ~79 dirt
setblock ~16 ~113 ~80 dirt
setblock ~16 ~113 ~81 dirt
setblock ~16 ~113 ~82 dirt
setblock ~16 ~113 ~83 dirt
setblock ~16 ~113 ~84 dirt
setblock ~16 ~113 ~86 dirt
setblock ~16 ~113 ~87 dirt
setblock ~16 ~113 ~107 dirt
setblock ~16 ~113 ~108 dirt
setblock ~16 ~113 ~109 dirt
setblock ~16 ~113 ~110 dirt
setblock ~16 ~113 ~111 dirt
setblock ~16 ~113 ~112 dirt
setblock ~16 ~113 ~113 dirt
setblock ~16 ~113 ~114 dirt
setblock ~16 ~113 ~115 dirt
setblock ~16 ~113 ~116 dirt
setblock ~16 ~113 ~117 dirt
setblock ~16 ~113 ~118 dirt
setblock ~16 ~113 ~119 dirt
setblock ~16 ~113 ~120 dirt
setblock ~16 ~113 ~121 dirt
setblock ~16 ~113 ~122 dirt
setblock ~16 ~113 ~123 dirt
setblock ~16 ~113 ~124 dirt
setblock ~16 ~113 ~125 dirt
setblock ~16 ~113 ~126 dirt
setblock ~16 ~113 ~127 dirt
setblock ~16 ~113 ~128 dirt
setblock ~16 ~113 ~129 dirt
setblock ~16 ~113 ~130 dirt
setblock ~16 ~113 ~131 dirt
setblock ~16 ~114 ~78 dirt
setblock ~16 ~114 ~79 dirt
setblock ~16 ~114 ~80 dirt
setblock ~16 ~114 ~81 dirt
setblock ~16 ~114 ~82 dirt
setblock ~16 ~114 ~83 dirt
setblock ~16 ~114 ~84 dirt
setblock ~16 ~114 ~85 dirt
setblock ~16 ~114 ~86 dirt
setblock ~16 ~114 ~87 dirt
setblock ~16 ~114 ~106 dirt
setblock ~16 ~114 ~107 dirt
setblock ~16 ~114 ~108 dirt
setblock ~16 ~114 ~109 dirt
setblock ~16 ~114 ~110 dirt
setblock ~16 ~114 ~111 dirt
setblock ~16 ~114 ~112 dirt
setblock ~16 ~114 ~113 dirt
setblock ~16 ~114 ~114 dirt
setblock ~16 ~114 ~115 dirt
setblock ~16 ~114 ~116 dirt
setblock ~16 ~114 ~117 dirt
setblock ~16 ~114 ~118 dirt
setblock ~16 ~114 ~119 dirt
setblock ~16 ~114 ~120 dirt
setblock ~16 ~114 ~121 dirt
setblock ~16 ~114 ~122 dirt
setblock ~16 ~114 ~123 dirt
setblock ~16 ~114 ~124 dirt
setblock ~16 ~114 ~125 dirt
setblock ~16 ~114 ~126 dirt
setblock ~16 ~114 ~127 dirt
setblock ~16 ~114 ~128 dirt
setblock ~16 ~114 ~129 dirt
setblock ~16 ~114 ~130 dirt
setblock ~16 ~114 ~131 dirt
setblock ~16 ~114 ~132 dirt
setblock ~16 ~115 ~77 dirt
setblock ~16 ~115 ~78 dirt
setblock ~16 ~115 ~79 dirt
setblock ~16 ~115 ~80 dirt
setblock ~16 ~115 ~81 dirt
setblock ~16 ~115 ~82 dirt
setblock ~16 ~115 ~83 dirt
setblock ~16 ~115 ~84 dirt
setblock ~16 ~115 ~85 dirt
setblock ~16 ~115 ~86 dirt
setblock ~16 ~115 ~87 dirt
setblock ~16 ~115 ~88 dirt
setblock ~16 ~115 ~105 dirt
setblock ~16 ~115 ~106 dirt
setblock ~16 ~115 ~107 dirt
setblock ~16 ~115 ~108 dirt
setblock ~16 ~115 ~109 dirt
setblock ~16 ~115 ~110 dirt
setblock ~16 ~115 ~111 dirt
setblock ~16 ~115 ~112 dirt
setblock ~16 ~115 ~113 dirt
setblock ~16 ~115 ~114 dirt
setblock ~16 ~115 ~115 dirt
setblock ~16 ~115 ~116 dirt
setblock ~16 ~115 ~117 dirt
setblock ~16 ~115 ~118 dirt
setblock ~16 ~115 ~119 dirt
setblock ~16 ~115 ~120 dirt
setblock ~16 ~115 ~121 dirt
setblock ~16 ~115 ~122 dirt
setblock ~16 ~115 ~123 dirt
setblock ~16 ~115 ~124 dirt
setblock ~16 ~115 ~125 dirt
setblock ~16 ~115 ~126 dirt
setblock ~16 ~115 ~127 dirt
setblock ~16 ~115 ~128 dirt
setblock ~16 ~115 ~129 dirt
setblock ~16 ~115 ~130 dirt
setblock ~16 ~115 ~131 dirt
setblock ~16 ~115 ~132 dirt
setblock ~16 ~116 ~76 dirt
setblock ~16 ~116 ~77 dirt
setblock ~16 ~116 ~78 dirt
setblock ~16 ~116 ~79 dirt
setblock ~16 ~116 ~80 dirt
setblock ~16 ~116 ~81 dirt
setblock ~16 ~116 ~82 dirt
setblock ~16 ~116 ~83 dirt
setblock ~16 ~116 ~84 dirt
setblock ~16 ~116 ~85 dirt
setblock ~16 ~116 ~86 dirt
setblock ~16 ~116 ~87 dirt
setblock ~16 ~116 ~88 dirt
setblock ~16 ~116 ~104 dirt
setblock ~16 ~116 ~105 dirt
setblock ~16 ~116 ~106 dirt
setblock ~16 ~116 ~107 dirt
setblock ~16 ~116 ~108 dirt
setblock ~16 ~116 ~109 dirt
setblock ~16 ~116 ~110 dirt
setblock ~16 ~116 ~111 dirt
setblock ~16 ~116 ~112 dirt
setblock ~16 ~116 ~113 dirt
setblock ~16 ~116 ~114 dirt
setblock ~16 ~116 ~115 dirt
setblock ~16 ~116 ~116 dirt
setblock ~16 ~116 ~117 dirt
setblock ~16 ~116 ~118 dirt
setblock ~16 ~116 ~119 dirt
setblock ~16 ~116 ~120 dirt
setblock ~16 ~116 ~121 dirt
setblock ~16 ~116 ~122 dirt
setblock ~16 ~116 ~123 dirt
setblock ~16 ~116 ~124 dirt
setblock ~16 ~116 ~125 dirt
setblock ~16 ~116 ~126 dirt
setblock ~16 ~116 ~127 dirt
setblock ~16 ~116 ~128 dirt
setblock ~16 ~116 ~129 dirt
setblock ~16 ~116 ~130 dirt
setblock ~16 ~116 ~131 dirt
setblock ~16 ~116 ~132 dirt
setblock ~16 ~117 ~76 dirt
setblock ~16 ~117 ~77 dirt
setblock ~16 ~117 ~78 dirt
setblock ~16 ~117 ~79 dirt
setblock ~16 ~117 ~80 dirt
setblock ~16 ~117 ~81 dirt
setblock ~16 ~117 ~82 dirt
setblock ~16 ~117 ~83 dirt
setblock ~16 ~117 ~84 dirt
setblock ~16 ~117 ~85 dirt
setblock ~16 ~117 ~86 dirt
setblock ~16 ~117 ~87 dirt
setblock ~16 ~117 ~88 dirt
setblock ~16 ~117 ~89 dirt
setblock ~16 ~117 ~94 dirt
setblock ~16 ~117 ~101 dirt
setblock ~16 ~117 ~103 dirt
setblock ~16 ~117 ~104 dirt
setblock ~16 ~117 ~105 dirt
setblock ~16 ~117 ~106 dirt
setblock ~16 ~117 ~107 dirt
setblock ~16 ~117 ~108 dirt
setblock ~16 ~117 ~109 dirt
setblock ~16 ~117 ~110 dirt
setblock ~16 ~117 ~111 dirt
setblock ~16 ~117 ~112 dirt
setblock ~16 ~117 ~113 dirt
setblock ~16 ~117 ~114 dirt
setblock ~16 ~117 ~115 dirt
setblock ~16 ~117 ~116 dirt
setblock ~16 ~117 ~117 dirt
setblock ~16 ~117 ~118 dirt
setblock ~16 ~117 ~119 dirt
setblock ~16 ~117 ~120 dirt
setblock ~16 ~117 ~121 dirt
setblock ~16 ~117 ~122 dirt
setblock ~16 ~117 ~123 dirt
setblock ~16 ~117 ~124 dirt
setblock ~16 ~117 ~125 dirt
setblock ~16 ~117 ~126 dirt
setblock ~16 ~117 ~127 dirt
setblock ~16 ~117 ~128 dirt
setblock ~16 ~117 ~129 dirt
setblock ~16 ~117 ~130 dirt
setblock ~16 ~117 ~131 dirt
setblock ~16 ~117 ~132 dirt
setblock ~16 ~117 ~133 dirt
setblock ~16 ~118 ~75 dirt
setblock ~16 ~118 ~76 dirt
setblock ~16 ~118 ~77 dirt
setblock ~16 ~118 ~78 dirt
setblock ~16 ~118 ~79 dirt
setblock ~16 ~118 ~80 dirt
setblock ~16 ~118 ~81 dirt
setblock ~16 ~118 ~82 dirt
setblock ~16 ~118 ~83 dirt
setblock ~16 ~118 ~84 dirt
setblock ~16 ~118 ~85 dirt
setblock ~16 ~118 ~86 dirt
setblock ~16 ~118 ~87 dirt
setblock ~16 ~118 ~88 dirt
setblock ~16 ~118 ~89 dirt
setblock ~16 ~118 ~93 dirt
setblock ~16 ~118 ~94 dirt
setblock ~16 ~118 ~95 dirt
setblock ~16 ~118 ~97 dirt
setblock ~16 ~118 ~101 dirt
setblock ~16 ~118 ~103 dirt
setblock ~16 ~118 ~104 dirt
setblock ~16 ~118 ~105 dirt
setblock ~16 ~118 ~106 dirt
setblock ~16 ~118 ~107 dirt
setblock ~16 ~118 ~108 dirt
setblock ~16 ~118 ~109 dirt
setblock ~16 ~118 ~110 dirt
setblock ~16 ~118 ~111 dirt
setblock ~16 ~118 ~112 dirt
setblock ~16 ~118 ~113 dirt
setblock ~16 ~118 ~114 dirt
setblock ~16 ~118 ~115 dirt
setblock ~16 ~118 ~116 dirt
setblock ~16 ~118 ~117 dirt
setblock ~16 ~118 ~118 dirt
setblock ~16 ~118 ~119 dirt
setblock ~16 ~118 ~120 dirt
setblock ~16 ~118 ~121 dirt
setblock ~16 ~118 ~122 dirt
setblock ~16 ~118 ~123 dirt
setblock ~16 ~118 ~124 dirt
setblock ~16 ~118 ~125 dirt
setblock ~16 ~118 ~126 dirt
setblock ~16 ~118 ~127 dirt
setblock ~16 ~118 ~128 dirt
setblock ~16 ~118 ~129 dirt
setblock ~16 ~118 ~130 dirt
setblock ~16 ~118 ~131 dirt
setblock ~16 ~118 ~132 dirt
setblock ~16 ~118 ~133 dirt
setblock ~16 ~119 ~72 dirt
setblock ~16 ~119 ~73 dirt
setblock ~16 ~119 ~74 dirt
setblock ~16 ~119 ~75 dirt
setblock ~16 ~119 ~76 dirt
setblock ~16 ~119 ~77 dirt
setblock ~16 ~119 ~78 dirt
setblock ~16 ~119 ~79 dirt
setblock ~16 ~119 ~80 dirt
setblock ~16 ~119 ~81 dirt
setblock ~16 ~119 ~82 dirt
setblock ~16 ~119 ~83 dirt
setblock ~16 ~119 ~84 dirt
setblock ~16 ~119 ~85 dirt
setblock ~16 ~119 ~86 dirt
setblock ~16 ~119 ~87 dirt
setblock ~16 ~119 ~88 dirt
setblock ~16 ~119 ~89 dirt
setblock ~16 ~119 ~90 dirt
setblock ~16 ~119 ~91 dirt
setblock ~16 ~119 ~93 dirt
setblock ~16 ~119 ~94 dirt
setblock ~16 ~119 ~95 dirt
setblock ~16 ~119 ~96 dirt
setblock ~16 ~119 ~97 dirt
setblock ~16 ~119 ~98 dirt
setblock ~16 ~119 ~100 dirt
setblock ~16 ~119 ~101 dirt
setblock ~16 ~119 ~102 dirt
setblock ~16 ~119 ~103 dirt
setblock ~16 ~119 ~104 dirt
setblock ~16 ~119 ~105 dirt
setblock ~16 ~119 ~106 dirt
setblock ~16 ~119 ~107 dirt
setblock ~16 ~119 ~108 dirt
setblock ~16 ~119 ~109 dirt
setblock ~16 ~119 ~110 dirt
setblock ~16 ~119 ~111 dirt
setblock ~16 ~119 ~112 dirt
setblock ~16 ~119 ~113 dirt
setblock ~16 ~119 ~114 dirt
setblock ~16 ~119 ~115 dirt
setblock ~16 ~119 ~116 dirt
setblock ~16 ~119 ~117 dirt
setblock ~16 ~119 ~118 dirt
setblock ~16 ~119 ~119 dirt
setblock ~16 ~119 ~120 dirt
setblock ~16 ~119 ~121 dirt
setblock ~16 ~119 ~122 dirt
setblock ~16 ~119 ~123 dirt
setblock ~16 ~119 ~124 dirt
setblock ~16 ~119 ~125 dirt
setblock ~16 ~119 ~126 dirt
setblock ~16 ~119 ~127 dirt
setblock ~16 ~119 ~128 dirt
setblock ~16 ~119 ~129 dirt
setblock ~16 ~119 ~130 dirt
setblock ~16 ~119 ~131 dirt
setblock ~16 ~119 ~132 dirt
setblock ~16 ~119 ~133 dirt
setblock ~16 ~119 ~134 dirt
setblock ~16 ~120 ~72 dirt
setblock ~16 ~120 ~73 dirt
setblock ~16 ~120 ~74 dirt
setblock ~16 ~120 ~75 dirt
setblock ~16 ~120 ~76 dirt
setblock ~16 ~120 ~77 dirt
setblock ~16 ~120 ~78 dirt
setblock ~16 ~120 ~79 dirt
setblock ~16 ~120 ~80 dirt
setblock ~16 ~120 ~81 dirt
setblock ~16 ~120 ~82 dirt
setblock ~16 ~120 ~83 dirt
setblock ~16 ~120 ~84 dirt
setblock ~16 ~120 ~85 dirt
setblock ~16 ~120 ~86 dirt
setblock ~16 ~120 ~87 dirt
setblock ~16 ~120 ~88 dirt
setblock ~16 ~120 ~89 dirt
setblock ~16 ~120 ~90 dirt
setblock ~16 ~120 ~91 dirt
setblock ~16 ~120 ~92 dirt
setblock ~16 ~120 ~93 dirt
setblock ~16 ~120 ~94 dirt
setblock ~16 ~120 ~95 dirt
setblock ~16 ~120 ~96 dirt
setblock ~16 ~120 ~97 dirt
setblock ~16 ~120 ~98 dirt
setblock ~16 ~120 ~99 dirt
setblock ~16 ~120 ~100 dirt
setblock ~16 ~120 ~101 dirt
setblock ~16 ~120 ~102 dirt
setblock ~16 ~120 ~103 dirt
setblock ~16 ~120 ~104 dirt
setblock ~16 ~120 ~105 dirt
setblock ~16 ~120 ~106 dirt
setblock ~16 ~120 ~107 dirt
setblock ~16 ~120 ~108 dirt
setblock ~16 ~120 ~109 dirt
setblock ~16 ~120 ~110 dirt
setblock ~16 ~120 ~111 dirt
setblock ~16 ~120 ~112 dirt
setblock ~16 ~120 ~113 dirt
setblock ~16 ~120 ~114 dirt
setblock ~16 ~120 ~115 dirt
setblock ~16 ~120 ~116 dirt
setblock ~16 ~120 ~117 dirt
setblock ~16 ~120 ~118 dirt
setblock ~16 ~120 ~119 dirt
setblock ~16 ~120 ~120 dirt
setblock ~16 ~120 ~121 dirt
setblock ~16 ~120 ~122 dirt
setblock ~16 ~120 ~123 dirt
setblock ~16 ~120 ~124 dirt
setblock ~16 ~120 ~125 dirt
setblock ~16 ~120 ~126 dirt
setblock ~16 ~120 ~127 dirt
setblock ~16 ~120 ~128 dirt
setblock ~16 ~120 ~129 dirt
setblock ~16 ~120 ~130 dirt
setblock ~16 ~120 ~131 dirt
setblock ~16 ~120 ~132 dirt
setblock ~16 ~120 ~133 dirt
setblock ~16 ~120 ~134 dirt
setblock ~16 ~120 ~135 dirt
setblock ~16 ~121 ~51 dirt
setblock ~16 ~121 ~54 dirt
setblock ~16 ~121 ~71 dirt
setblock ~16 ~121 ~72 dirt
setblock ~16 ~121 ~73 dirt
setblock ~16 ~121 ~74 dirt
setblock ~16 ~121 ~75 dirt
setblock ~16 ~121 ~76 dirt
setblock ~16 ~121 ~77 dirt
setblock ~16 ~121 ~78 dirt
setblock ~16 ~121 ~79 dirt
setblock ~16 ~121 ~80 dirt
setblock ~16 ~121 ~81 dirt
setblock ~16 ~121 ~82 dirt
setblock ~16 ~121 ~83 dirt
setblock ~16 ~121 ~84 dirt
setblock ~16 ~121 ~85 dirt
setblock ~16 ~121 ~86 dirt
setblock ~16 ~121 ~87 dirt
setblock ~16 ~121 ~88 dirt
setblock ~16 ~121 ~89 dirt
setblock ~16 ~121 ~90 dirt
setblock ~16 ~121 ~91 dirt
setblock ~16 ~121 ~92 dirt
setblock ~16 ~121 ~93 dirt
setblock ~16 ~121 ~94 dirt
setblock ~16 ~121 ~95 dirt
setblock ~16 ~121 ~96 dirt
setblock ~16 ~121 ~97 dirt
setblock ~16 ~121 ~98 dirt
setblock ~16 ~121 ~99 dirt
setblock ~16 ~121 ~100 dirt
setblock ~16 ~121 ~101 dirt
setblock ~16 ~121 ~102 dirt
setblock ~16 ~121 ~103 dirt
setblock ~16 ~121 ~104 dirt
setblock ~16 ~121 ~105 dirt
setblock ~16 ~121 ~106 dirt
setblock ~16 ~121 ~107 dirt
setblock ~16 ~121 ~108 dirt
setblock ~16 ~121 ~109 dirt
setblock ~16 ~121 ~110 dirt
setblock ~16 ~121 ~111 dirt
setblock ~16 ~121 ~112 dirt
setblock ~16 ~121 ~113 dirt
setblock ~16 ~121 ~114 dirt
setblock ~16 ~121 ~115 dirt
setblock ~16 ~121 ~116 dirt
setblock ~16 ~121 ~117 dirt
setblock ~16 ~121 ~118 dirt
setblock ~16 ~121 ~119 dirt
setblock ~16 ~121 ~120 dirt
setblock ~16 ~121 ~121 dirt
setblock ~16 ~121 ~122 dirt
setblock ~16 ~121 ~123 dirt
setblock ~16 ~121 ~124 dirt
setblock ~16 ~121 ~125 dirt
setblock ~16 ~121 ~126 dirt
setblock ~16 ~121 ~127 dirt
setblock ~16 ~121 ~128 dirt
setblock ~16 ~121 ~129 dirt
setblock ~16 ~121 ~130 dirt
setblock ~16 ~121 ~131 dirt
setblock ~16 ~121 ~132 dirt
setblock ~16 ~121 ~133 dirt
setblock ~16 ~121 ~134 dirt
setblock ~16 ~121 ~135 dirt
setblock ~16 ~122 ~51 dirt
setblock ~16 ~122 ~54 dirt
setblock ~16 ~122 ~71 dirt
setblock ~16 ~122 ~72 dirt
setblock ~16 ~122 ~73 dirt
setblock ~16 ~122 ~74 dirt
setblock ~16 ~122 ~75 dirt
setblock ~16 ~122 ~76 dirt
setblock ~16 ~122 ~77 dirt
setblock ~16 ~122 ~78 dirt
setblock ~16 ~122 ~79 dirt
setblock ~16 ~122 ~80 dirt
setblock ~16 ~122 ~81 dirt
setblock ~16 ~122 ~82 dirt
setblock ~16 ~122 ~83 dirt
setblock ~16 ~122 ~84 dirt
setblock ~16 ~122 ~85 dirt
setblock ~16 ~122 ~86 dirt
setblock ~16 ~122 ~87 dirt
setblock ~16 ~122 ~88 dirt
setblock ~16 ~122 ~89 dirt
setblock ~16 ~122 ~90 dirt
setblock ~16 ~122 ~91 dirt
setblock ~16 ~122 ~92 dirt
setblock ~16 ~122 ~93 dirt
setblock ~16 ~122 ~94 dirt
setblock ~16 ~122 ~95 dirt
setblock ~16 ~122 ~96 dirt
setblock ~16 ~122 ~97 dirt
setblock ~16 ~122 ~98 dirt
setblock ~16 ~122 ~99 dirt
setblock ~16 ~122 ~100 dirt
setblock ~16 ~122 ~101 dirt
setblock ~16 ~122 ~102 dirt
setblock ~16 ~122 ~103 dirt
setblock ~16 ~122 ~104 dirt
setblock ~16 ~122 ~105 dirt
setblock ~16 ~122 ~106 dirt
setblock ~16 ~122 ~107 dirt
setblock ~16 ~122 ~108 dirt
setblock ~16 ~122 ~109 dirt
setblock ~16 ~122 ~110 dirt
setblock ~16 ~122 ~111 dirt
setblock ~16 ~122 ~112 dirt
setblock ~16 ~122 ~113 dirt
setblock ~16 ~122 ~114 dirt
setblock ~16 ~122 ~115 dirt
setblock ~16 ~122 ~116 dirt
setblock ~16 ~122 ~117 dirt
setblock ~16 ~122 ~118 dirt
setblock ~16 ~122 ~119 dirt
setblock ~16 ~122 ~120 dirt
setblock ~16 ~122 ~121 dirt
setblock ~16 ~122 ~122 dirt
setblock ~16 ~122 ~123 dirt
setblock ~16 ~122 ~124 dirt
setblock ~16 ~122 ~125 dirt
setblock ~16 ~122 ~126 dirt
setblock ~16 ~122 ~127 dirt
setblock ~16 ~122 ~128 dirt
setblock ~16 ~122 ~129 dirt
setblock ~16 ~122 ~130 dirt
setblock ~16 ~122 ~131 dirt
setblock ~16 ~122 ~132 dirt
setblock ~16 ~122 ~133 dirt
setblock ~16 ~122 ~134 dirt
setblock ~16 ~122 ~135 dirt
setblock ~16 ~123 ~51 dirt
setblock ~16 ~123 ~54 dirt
setblock ~16 ~123 ~71 dirt
setblock ~16 ~123 ~72 dirt
setblock ~16 ~123 ~73 dirt
setblock ~16 ~123 ~74 dirt
setblock ~16 ~123 ~75 dirt
setblock ~16 ~123 ~76 dirt
setblock ~16 ~123 ~77 dirt
setblock ~16 ~123 ~78 dirt
setblock ~16 ~123 ~79 dirt
setblock ~16 ~123 ~80 dirt
setblock ~16 ~123 ~81 dirt
setblock ~16 ~123 ~82 dirt
setblock ~16 ~123 ~83 dirt
setblock ~16 ~123 ~84 dirt
setblock ~16 ~123 ~85 dirt
setblock ~16 ~123 ~86 dirt
setblock ~16 ~123 ~87 dirt
setblock ~16 ~123 ~88 dirt
setblock ~16 ~123 ~89 dirt
setblock ~16 ~123 ~90 dirt
setblock ~16 ~123 ~91 dirt
setblock ~16 ~123 ~92 dirt
setblock ~16 ~123 ~93 dirt
setblock ~16 ~123 ~94 dirt
setblock ~16 ~123 ~95 dirt
setblock ~16 ~123 ~96 dirt
setblock ~16 ~123 ~97 dirt
setblock ~16 ~123 ~98 dirt
setblock ~16 ~123 ~99 dirt
setblock ~16 ~123 ~100 dirt
setblock ~16 ~123 ~101 dirt
setblock ~16 ~123 ~102 dirt
setblock ~16 ~123 ~103 dirt
setblock ~16 ~123 ~104 dirt
setblock ~16 ~123 ~105 dirt
setblock ~16 ~123 ~106 dirt
setblock ~16 ~123 ~107 dirt
setblock ~16 ~123 ~108 dirt
setblock ~16 ~123 ~109 grass_block
setblock ~16 ~123 ~110 grass_block
setblock ~16 ~123 ~111 grass_block
setblock ~16 ~123 ~112 dirt
setblock ~16 ~123 ~113 dirt
setblock ~16 ~123 ~114 dirt
setblock ~16 ~123 ~115 dirt
setblock ~16 ~123 ~116 dirt
setblock ~16 ~123 ~117 dirt
setblock ~16 ~123 ~118 dirt
setblock ~16 ~123 ~119 dirt
setblock ~16 ~123 ~120 dirt
setblock ~16 ~123 ~121 dirt
setblock ~16 ~123 ~122 dirt
setblock ~16 ~123 ~123 dirt
setblock ~16 ~123 ~124 dirt
setblock ~16 ~123 ~125 dirt
setblock ~16 ~123 ~126 dirt
setblock ~16 ~123 ~127 dirt
setblock ~16 ~123 ~128 dirt
setblock ~16 ~123 ~129 dirt
setblock ~16 ~123 ~130 dirt
setblock ~16 ~123 ~131 dirt
setblock ~16 ~123 ~132 dirt
setblock ~16 ~123 ~133 dirt
setblock ~16 ~123 ~134 dirt
setblock ~16 ~123 ~135 dirt
setblock ~16 ~124 ~51 dirt
setblock ~16 ~124 ~54 dirt
setblock ~16 ~124 ~71 dirt
setblock ~16 ~124 ~72 dirt
setblock ~16 ~124 ~73 dirt
setblock ~16 ~124 ~74 dirt
setblock ~16 ~124 ~75 dirt
setblock ~16 ~124 ~76 dirt
setblock ~16 ~124 ~77 dirt
setblock ~16 ~124 ~78 dirt
setblock ~16 ~124 ~79 dirt
setblock ~16 ~124 ~80 dirt
setblock ~16 ~124 ~81 dirt
setblock ~16 ~124 ~82 dirt
setblock ~16 ~124 ~83 dirt
setblock ~16 ~124 ~84 dirt
setblock ~16 ~124 ~85 dirt
setblock ~16 ~124 ~86 dirt
setblock ~16 ~124 ~87 grass_block
setblock ~16 ~124 ~88 grass_block
setblock ~16 ~124 ~89 grass_block
setblock ~16 ~124 ~90 grass_block
setblock ~16 ~124 ~91 grass_block
setblock ~16 ~124 ~92 grass_block
setblock ~16 ~124 ~93 grass_block
setblock ~16 ~124 ~94 grass_block
setblock ~16 ~124 ~95 grass_block
setblock ~16 ~124 ~96 grass_block
setblock ~16 ~124 ~97 dirt
setblock ~16 ~124 ~98 dirt
setblock ~16 ~124 ~99 dirt
setblock ~16 ~124 ~100 dirt
setblock ~16 ~124 ~101 dirt
setblock ~16 ~124 ~102 dirt
setblock ~16 ~124 ~103 dirt
setblock ~16 ~124 ~104 grass_block
setblock ~16 ~124 ~105 grass_block
setblock ~16 ~124 ~106 grass_block
setblock ~16 ~124 ~107 grass_block
setblock ~16 ~124 ~108 grass_block
setblock ~16 ~124 ~109 short_grass
setblock ~16 ~124 ~112 grass_block
setblock ~16 ~124 ~113 grass_block
setblock ~16 ~124 ~114 grass_block
setblock ~16 ~124 ~115 grass_block
setblock ~16 ~124 ~116 dirt
setblock ~16 ~124 ~117 dirt
setblock ~16 ~124 ~118 dirt
setblock ~16 ~124 ~119 dirt
setblock ~16 ~124 ~120 dirt
setblock ~16 ~124 ~121 dirt
setblock ~16 ~124 ~122 dirt
setblock ~16 ~124 ~123 dirt
setblock ~16 ~124 ~124 dirt
setblock ~16 ~124 ~125 dirt
setblock ~16 ~124 ~126 dirt
setblock ~16 ~124 ~127 dirt
setblock ~16 ~124 ~128 dirt
setblock ~16 ~124 ~129 dirt
setblock ~16 ~124 ~130 grass_block
setblock ~16 ~124 ~131 dirt
setblock ~16 ~124 ~132 dirt
setblock ~16 ~124 ~133 dirt
setblock ~16 ~124 ~134 dirt
setblock ~16 ~124 ~135 dirt
setblock ~16 ~125 ~51 grass_block
setblock ~16 ~125 ~54 grass_block
setblock ~16 ~125 ~71 grass_block
setblock ~16 ~125 ~72 grass_block
setblock ~16 ~125 ~73 grass_block
setblock ~16 ~125 ~74 grass_block
setblock ~16 ~125 ~75 grass_block
setblock ~16 ~125 ~76 grass_block
setblock ~16 ~125 ~77 dirt
setblock ~16 ~125 ~78 dirt
setblock ~16 ~125 ~79 dirt
setblock ~16 ~125 ~80 dirt
setblock ~16 ~125 ~81 dirt
setblock ~16 ~125 ~82 grass_block
setblock ~16 ~125 ~83 grass_block
setblock ~16 ~125 ~84 grass_block
setblock ~16 ~125 ~85 grass_block
setblock ~16 ~125 ~86 grass_block
setblock ~16 ~125 ~87 short_grass
setblock ~16 ~125 ~92 poppy
setblock ~16 ~125 ~95 short_grass
setblock ~16 ~125 ~97 grass_block
setblock ~16 ~125 ~98 grass_block
setblock ~16 ~125 ~99 grass_block
setblock ~16 ~125 ~100 grass_block
setblock ~16 ~125 ~101 grass_block
setblock ~16 ~125 ~102 grass_block
setblock ~16 ~125 ~103 grass_block
setblock ~16 ~125 ~104 short_grass
setblock ~16 ~125 ~107 short_grass
setblock ~16 ~125 ~112 poppy
setblock ~16 ~125 ~116 grass_block
setblock ~16 ~125 ~117 grass_block
setblock ~16 ~125 ~118 grass_block
setblock ~16 ~125 ~119 grass_block
setblock ~16 ~125 ~120 grass_block
setblock ~16 ~125 ~121 grass_block
setblock ~16 ~125 ~122 grass_block
setblock ~16 ~125 ~123 grass_block
setblock ~16 ~125 ~124 grass_block
setblock ~16 ~125 ~125 grass_block
setblock ~16 ~125 ~126 grass_block
setblock ~16 ~125 ~127 grass_block
setblock ~16 ~125 ~128 grass_block
setblock ~16 ~125 ~129 grass_block
setblock ~16 ~125 ~131 grass_block
setblock ~16 ~125 ~132 grass_block
setblock ~16 ~125 ~133 grass_block
setblock ~16 ~125 ~134 grass_block
setblock ~16 ~125 ~135 grass_block
setblock ~16 ~126 ~51 poppy
setblock ~16 ~126 ~71 short_grass
setblock ~16 ~126 ~72 short_grass
setblock ~16 ~126 ~73 fern
setblock ~16 ~126 ~74 fern
setblock ~16 ~126 ~77 grass_block
setblock ~16 ~126 ~78 grass_block
setblock ~16 ~126 ~79 grass_block
setblock ~16 ~126 ~80 grass_block
setblock ~16 ~126 ~81 grass_block
setblock ~16 ~126 ~98 short_grass
setblock ~16 ~126 ~100 short_grass
setblock ~16 ~126 ~102 short_grass
setblock ~16 ~126 ~116 poppy
setblock ~16 ~126 ~119 short_grass
setblock ~16 ~126 ~123 short_grass
setblock ~16 ~126 ~128 short_grass
setblock ~16 ~127 ~78 short_grass
setblock ~16 ~127 ~81 fern
setblock ~17 ~99 ~116 dirt
setblock ~17 ~100 ~114 dirt
setblock ~17 ~100 ~116 dirt
setblock ~17 ~100 ~117 dirt
setblock ~17 ~101 ~113 dirt
setblock ~17 ~101 ~114 dirt
setblock ~17 ~101 ~115 dirt
setblock ~17 ~101 ~116 dirt
setblock ~17 ~101 ~117 dirt
setblock ~17 ~101 ~118 dirt
setblock ~17 ~102 ~113 dirt
setblock ~17 ~102 ~114 dirt
setblock ~17 ~102 ~115 dirt
setblock ~17 ~102 ~116 dirt
setblock ~17 ~102 ~117 dirt
setblock ~17 ~102 ~118 dirt
setblock ~17 ~102 ~119 dirt
setblock ~17 ~103 ~112 dirt
setblock ~17 ~103 ~113 dirt
setblock ~17 ~103 ~114 dirt
setblock ~17 ~103 ~115 dirt
