setblock ~185 ~124 ~20 grass_block
setblock ~185 ~124 ~21 grass_block
setblock ~185 ~124 ~22 grass_block
setblock ~185 ~124 ~23 grass_block
setblock ~185 ~124 ~24 grass_block
setblock ~185 ~124 ~25 grass_block
setblock ~185 ~124 ~26 grass_block
setblock ~185 ~124 ~27 grass_block
setblock ~185 ~124 ~28 grass_block
setblock ~185 ~124 ~29 grass_block
setblock ~185 ~124 ~30 grass_block
setblock ~185 ~124 ~31 grass_block
setblock ~185 ~124 ~32 grass_block
setblock ~185 ~124 ~33 grass_block
setblock ~185 ~124 ~34 grass_block
setblock ~185 ~124 ~35 grass_block
setblock ~185 ~124 ~36 grass_block
setblock ~185 ~124 ~37 grass_block
setblock ~185 ~124 ~38 grass_block
setblock ~185 ~124 ~39 grass_block
setblock ~185 ~124 ~40 grass_block
setblock ~185 ~124 ~41 dirt
setblock ~185 ~124 ~42 dirt
setblock ~185 ~124 ~43 dirt
setblock ~185 ~124 ~44 dirt
setblock ~185 ~124 ~45 dirt
setblock ~185 ~124 ~46 dirt
setblock ~185 ~124 ~47 dirt
setblock ~185 ~124 ~48 dirt
setblock ~185 ~124 ~49 dirt
setblock ~185 ~124 ~50 dirt
setblock ~185 ~124 ~51 dirt
setblock ~185 ~124 ~52 dirt
setblock ~185 ~124 ~53 dirt
setblock ~185 ~124 ~54 dirt
setblock ~185 ~124 ~55 dirt
setblock ~185 ~124 ~56 dirt
setblock ~185 ~124 ~57 dirt
setblock ~185 ~124 ~58 grass_block
setblock ~185 ~124 ~59 grass_block
setblock ~185 ~124 ~61 grass_block
setblock ~185 ~124 ~62 grass_block
setblock ~185 ~124 ~63 grass_block
setblock ~185 ~124 ~64 grass_block
setblock ~185 ~124 ~65 grass_block
setblock ~185 ~124 ~66 grass_block
setblock ~185 ~124 ~67 grass_block
setblock ~185 ~124 ~68 grass_block
setblock ~185 ~124 ~69 grass_block
setblock ~185 ~124 ~70 grass_block
setblock ~185 ~124 ~71 dirt
setblock ~185 ~124 ~72 dirt
setblock ~185 ~124 ~73 dirt
setblock ~185 ~124 ~74 dirt
setblock ~185 ~124 ~75 dirt
setblock ~185 ~124 ~76 dirt
setblock ~185 ~124 ~77 dirt
setblock ~185 ~124 ~78 dirt
setblock ~185 ~124 ~79 dirt
setblock ~185 ~124 ~80 dirt
setblock ~185 ~124 ~81 dirt
setblock ~185 ~124 ~82 dirt
setblock ~185 ~124 ~83 dirt
setblock ~185 ~124 ~84 dirt
setblock ~185 ~124 ~85 dirt
setblock ~185 ~124 ~86 dirt
setblock ~185 ~124 ~87 dirt
setblock ~185 ~124 ~88 dirt
setblock ~185 ~124 ~89 dirt
setblock ~185 ~124 ~90 dirt
setblock ~185 ~124 ~91 dirt
setblock ~185 ~124 ~92 dirt
setblock ~185 ~124 ~93 dirt
setblock ~185 ~124 ~94 dirt
setblock ~185 ~124 ~95 dirt
setblock ~185 ~124 ~96 dirt
setblock ~185 ~124 ~97 grass_block
setblock ~185 ~124 ~98 grass_block
setblock ~185 ~124 ~99 grass_block
setblock ~185 ~124 ~100 grass_block
setblock ~185 ~124 ~101 grass_block
setblock ~185 ~124 ~102 grass_block
setblock ~185 ~124 ~108 fern
setblock ~185 ~124 ~109 short_grass
setblock ~185 ~124 ~111 fern
setblock ~185 ~124 ~112 short_grass
setblock ~185 ~124 ~114 grass_block
setblock ~185 ~124 ~115 grass_block
setblock ~185 ~124 ~116 grass_block
setblock ~185 ~124 ~121 short_grass
setblock ~185 ~124 ~123 short_grass
setblock ~185 ~124 ~125 grass_block
setblock ~185 ~124 ~126 grass_block
setblock ~185 ~124 ~127 grass_block
setblock ~185 ~124 ~128 grass_block
setblock ~185 ~124 ~129 grass_block
setblock ~185 ~124 ~130 grass_block
setblock ~185 ~124 ~131 grass_block
setblock ~185 ~124 ~132 grass_block
setblock ~185 ~124 ~133 grass_block
setblock ~185 ~124 ~134 grass_block
setblock ~185 ~124 ~135 grass_block
setblock ~185 ~124 ~136 grass_block
setblock ~185 ~124 ~137 grass_block
setblock ~185 ~124 ~138 grass_block
setblock ~185 ~124 ~139 grass_block
setblock ~185 ~124 ~140 grass_block
setblock ~185 ~124 ~141 grass_block
setblock ~185 ~124 ~142 grass_block
setblock ~185 ~124 ~143 grass_block
setblock ~185 ~124 ~144 grass_block
setblock ~185 ~124 ~145 grass_block
setblock ~185 ~124 ~146 grass_block
setblock ~185 ~124 ~147 grass_block
setblock ~185 ~124 ~148 grass_block
setblock ~185 ~124 ~149 grass_block
setblock ~185 ~124 ~150 grass_block
setblock ~185 ~124 ~151 grass_block
setblock ~185 ~124 ~152 grass_block
setblock ~185 ~124 ~153 grass_block
setblock ~185 ~124 ~154 grass_block
setblock ~185 ~124 ~155 grass_block
setblock ~185 ~124 ~156 grass_block
setblock ~185 ~124 ~157 grass_block
setblock ~185 ~124 ~158 grass_block
setblock ~185 ~124 ~159 grass_block
setblock ~185 ~124 ~160 grass_block
setblock ~185 ~124 ~161 grass_block
setblock ~185 ~124 ~162 grass_block
setblock ~185 ~124 ~163 grass_block
setblock ~185 ~124 ~164 grass_block
setblock ~185 ~124 ~165 grass_block
setblock ~185 ~124 ~166 grass_block
setblock ~185 ~124 ~167 grass_block
setblock ~185 ~124 ~168 grass_block
setblock ~185 ~124 ~169 grass_block
setblock ~185 ~124 ~170 grass_block
setblock ~185 ~124 ~171 grass_block
setblock ~185 ~124 ~172 dirt
setblock ~185 ~124 ~173 dirt
setblock ~185 ~124 ~174 dirt
setblock ~185 ~124 ~175 dirt
setblock ~185 ~124 ~176 dirt
setblock ~185 ~124 ~177 dirt
setblock ~185 ~124 ~178 dirt
setblock ~185 ~124 ~179 dirt
setblock ~185 ~124 ~180 dirt
setblock ~185 ~124 ~181 dirt
setblock ~185 ~124 ~182 dirt
setblock ~185 ~124 ~183 dirt
setblock ~185 ~124 ~184 dirt
setblock ~185 ~124 ~185 dirt
setblock ~185 ~124 ~186 dirt
setblock ~185 ~124 ~187 dirt
setblock ~185 ~124 ~188 dirt
setblock ~185 ~124 ~189 dirt
setblock ~185 ~124 ~190 dirt
setblock ~185 ~124 ~191 dirt
setblock ~185 ~124 ~192 dirt
setblock ~185 ~124 ~193 dirt
setblock ~185 ~124 ~194 dirt
setblock ~185 ~124 ~195 dirt
setblock ~185 ~124 ~196 dirt
setblock ~185 ~124 ~197 dirt
setblock ~185 ~124 ~198 dirt
setblock ~185 ~124 ~199 dirt
setblock ~185 ~125 ~0 grass_block
setblock ~185 ~125 ~1 grass_block
setblock ~185 ~125 ~2 grass_block
setblock ~185 ~125 ~3 grass_block
setblock ~185 ~125 ~4 grass_block
setblock ~185 ~125 ~5 grass_block
setblock ~185 ~125 ~6 grass_block
setblock ~185 ~125 ~7 grass_block
setblock ~185 ~125 ~8 grass_block
setblock ~185 ~125 ~9 grass_block
setblock ~185 ~125 ~10 grass_block
setblock ~185 ~125 ~11 grass_block
setblock ~185 ~125 ~12 grass_block
setblock ~185 ~125 ~13 grass_block
setblock ~185 ~125 ~14 grass_block
setblock ~185 ~125 ~15 grass_block
setblock ~185 ~125 ~16 grass_block
setblock ~185 ~125 ~19 short_grass
setblock ~185 ~125 ~20 short_grass
setblock ~185 ~125 ~23 short_grass
setblock ~185 ~125 ~30 short_grass
setblock ~185 ~125 ~36 short_grass
setblock ~185 ~125 ~37 fern
setblock ~185 ~125 ~39 short_grass
setblock ~185 ~125 ~41 grass_block
setblock ~185 ~125 ~42 grass_block
setblock ~185 ~125 ~43 grass_block
setblock ~185 ~125 ~44 dirt
setblock ~185 ~125 ~45 dirt
setblock ~185 ~125 ~46 dirt
setblock ~185 ~125 ~47 dirt
setblock ~185 ~125 ~48 dirt
setblock ~185 ~125 ~49 dirt
setblock ~185 ~125 ~50 dirt
setblock ~185 ~125 ~51 dirt
setblock ~185 ~125 ~52 dirt
setblock ~185 ~125 ~53 dirt
setblock ~185 ~125 ~54 dirt
setblock ~185 ~125 ~55 dirt
setblock ~185 ~125 ~56 grass_block
setblock ~185 ~125 ~57 grass_block
setblock ~185 ~125 ~59 short_grass
setblock ~185 ~125 ~62 fern
setblock ~185 ~125 ~68 poppy
setblock ~185 ~125 ~69 short_grass
setblock ~185 ~125 ~71 grass_block
setblock ~185 ~125 ~72 grass_block
setblock ~185 ~125 ~73 grass_block
setblock ~185 ~125 ~74 grass_block
setblock ~185 ~125 ~75 grass_block
setblock ~185 ~125 ~76 grass_block
setblock ~185 ~125 ~77 grass_block
setblock ~185 ~125 ~78 grass_block
setblock ~185 ~125 ~79 grass_block
setblock ~185 ~125 ~80 grass_block
setblock ~185 ~125 ~81 grass_block
setblock ~185 ~125 ~82 grass_block
setblock ~185 ~125 ~83 dirt
setblock ~185 ~125 ~84 dirt
setblock ~185 ~125 ~85 dirt
setblock ~185 ~125 ~86 dirt
setblock ~185 ~125 ~87 dirt
setblock ~185 ~125 ~88 dirt
setblock ~185 ~125 ~89 dirt
setblock ~185 ~125 ~90 dirt
setblock ~185 ~125 ~91 dirt
setblock ~185 ~125 ~92 dirt
setblock ~185 ~125 ~93 dirt
setblock ~185 ~125 ~94 dirt
setblock ~185 ~125 ~95 grass_block
setblock ~185 ~125 ~96 grass_block
setblock ~185 ~125 ~130 short_grass
setblock ~185 ~125 ~131 short_grass
setblock ~185 ~125 ~134 short_grass
setblock ~185 ~125 ~135 short_grass
setblock ~185 ~125 ~137 short_grass
setblock ~185 ~125 ~143 short_grass
setblock ~185 ~125 ~144 short_grass
setblock ~185 ~125 ~146 poppy
setblock ~185 ~125 ~152 poppy
setblock ~185 ~125 ~153 short_grass
setblock ~185 ~125 ~154 short_grass
setblock ~185 ~125 ~156 fern
setblock ~185 ~125 ~157 short_grass
setblock ~185 ~125 ~158 poppy
setblock ~185 ~125 ~159 short_grass
setblock ~185 ~125 ~161 short_grass
setblock ~185 ~125 ~164 short_grass
setblock ~185 ~125 ~166 fern
setblock ~185 ~125 ~172 grass_block
setblock ~185 ~125 ~173 grass_block
setblock ~185 ~125 ~174 grass_block
setblock ~185 ~125 ~175 grass_block
setblock ~185 ~125 ~176 dirt
setblock ~185 ~125 ~177 dirt
setblock ~185 ~125 ~178 dirt
setblock ~185 ~125 ~179 dirt
setblock ~185 ~125 ~180 dirt
setblock ~185 ~125 ~181 dirt
setblock ~185 ~125 ~182 dirt
setblock ~185 ~125 ~183 dirt
setblock ~185 ~125 ~184 dirt
setblock ~185 ~125 ~185 dirt
setblock ~185 ~125 ~186 dirt
setblock ~185 ~125 ~187 dirt
setblock ~185 ~125 ~188 dirt
setblock ~185 ~125 ~189 dirt
setblock ~185 ~125 ~190 dirt
setblock ~185 ~125 ~191 dirt
setblock ~185 ~125 ~192 dirt
setblock ~185 ~125 ~193 grass_block
setblock ~185 ~125 ~194 grass_block
setblock ~185 ~125 ~195 grass_block
setblock ~185 ~125 ~196 grass_block
setblock ~185 ~125 ~197 grass_block
setblock ~185 ~125 ~198 grass_block
setblock ~185 ~125 ~199 grass_block
setblock ~185 ~126 ~0 short_grass
setblock ~185 ~126 ~5 short_grass
setblock ~185 ~126 ~6 short_grass
setblock ~185 ~126 ~10 short_grass
setblock ~185 ~126 ~11 short_grass
setblock ~185 ~126 ~13 fern
setblock ~185 ~126 ~16 short_grass
setblock ~185 ~126 ~41 fern
setblock ~185 ~126 ~42 fern
setblock ~185 ~126 ~44 grass_block
setblock ~185 ~126 ~45 grass_block
setblock ~185 ~126 ~46 grass_block
setblock ~185 ~126 ~47 grass_block
setblock ~185 ~126 ~48 grass_block
setblock ~185 ~126 ~49 dirt
setblock ~185 ~126 ~50 dirt
setblock ~185 ~126 ~51 grass_block
setblock ~185 ~126 ~52 grass_block
setblock ~185 ~126 ~53 grass_block
setblock ~185 ~126 ~54 grass_block
setblock ~185 ~126 ~55 grass_block
setblock ~185 ~126 ~75 fern
setblock ~185 ~126 ~78 short_grass
setblock ~185 ~126 ~79 short_grass
setblock ~185 ~126 ~80 short_grass
setblock ~185 ~126 ~82 short_grass
setblock ~185 ~126 ~83 grass_block
setblock ~185 ~126 ~84 grass_block
setblock ~185 ~126 ~85 grass_block
setblock ~185 ~126 ~86 grass_block
setblock ~185 ~126 ~87 dirt
setblock ~185 ~126 ~88 dirt
setblock ~185 ~126 ~89 dirt
setblock ~185 ~126 ~90 dirt
setblock ~185 ~126 ~91 dirt
setblock ~185 ~126 ~92 dirt
setblock ~185 ~126 ~93 grass_block
setblock ~185 ~126 ~94 grass_block
setblock ~185 ~126 ~176 grass_block
setblock ~185 ~126 ~177 grass_block
setblock ~185 ~126 ~178 grass_block
setblock ~185 ~126 ~179 grass_block
setblock ~185 ~126 ~180 grass_block
setblock ~185 ~126 ~181 grass_block
setblock ~185 ~126 ~182 grass_block
setblock ~185 ~126 ~183 grass_block
setblock ~185 ~126 ~184 grass_block
setblock ~185 ~126 ~185 grass_block
setblock ~185 ~126 ~186 grass_block
setblock ~185 ~126 ~187 grass_block
setblock ~185 ~126 ~188 grass_block
setblock ~185 ~126 ~189 grass_block
setblock ~185 ~126 ~190 grass_block
setblock ~185 ~126 ~191 grass_block
setblock ~185 ~126 ~192 grass_block
setblock ~185 ~126 ~193 short_grass
setblock ~185 ~126 ~197 short_grass
setblock ~185 ~126 ~198 short_grass
setblock ~185 ~127 ~45 short_grass
setblock ~185 ~127 ~49 grass_block
setblock ~185 ~127 ~50 grass_block
setblock ~185 ~127 ~53 short_grass
setblock ~185 ~127 ~83 short_grass
setblock ~185 ~127 ~84 fern
setblock ~185 ~127 ~85 fern
setblock ~185 ~127 ~87 grass_block
setblock ~185 ~127 ~88 grass_block
setblock ~185 ~127 ~89 grass_block
setblock ~185 ~127 ~90 dirt
setblock ~185 ~127 ~91 grass_block
setblock ~185 ~127 ~92 grass_block
setblock ~185 ~127 ~93 short_grass
setblock ~185 ~127 ~177 short_grass
setblock ~185 ~127 ~181 short_grass
setblock ~185 ~127 ~182 short_grass
setblock ~185 ~127 ~183 short_grass
setblock ~185 ~127 ~189 fern
setblock ~185 ~128 ~49 short_grass
setblock ~185 ~128 ~50 poppy
setblock ~185 ~128 ~90 grass_block
setblock ~186 ~122 ~0 dirt
setblock ~186 ~122 ~1 dirt
setblock ~186 ~122 ~2 dirt
setblock ~186 ~122 ~3 dirt
setblock ~186 ~122 ~4 dirt
setblock ~186 ~122 ~5 dirt
setblock ~186 ~122 ~6 dirt
setblock ~186 ~122 ~7 dirt
setblock ~186 ~122 ~8 dirt
setblock ~186 ~122 ~9 dirt
setblock ~186 ~122 ~10 dirt
setblock ~186 ~122 ~11 dirt
setblock ~186 ~122 ~12 dirt
setblock ~186 ~122 ~13 dirt
setblock ~186 ~122 ~14 dirt
setblock ~186 ~122 ~15 dirt
setblock ~186 ~122 ~16 dirt
setblock ~186 ~122 ~17 dirt
setblock ~186 ~122 ~18 dirt
setblock ~186 ~122 ~19 dirt
setblock ~186 ~122 ~20 dirt
setblock ~186 ~122 ~21 dirt
setblock ~186 ~122 ~22 dirt
setblock ~186 ~122 ~23 dirt
setblock ~186 ~122 ~24 dirt
setblock ~186 ~122 ~25 dirt
setblock ~186 ~122 ~26 dirt
setblock ~186 ~122 ~27 dirt
setblock ~186 ~122 ~28 dirt
setblock ~186 ~122 ~29 dirt
setblock ~186 ~122 ~30 dirt
setblock ~186 ~122 ~31 dirt
setblock ~186 ~122 ~32 dirt
setblock ~186 ~122 ~33 dirt
setblock ~186 ~122 ~34 dirt
setblock ~186 ~122 ~35 dirt
setblock ~186 ~122 ~36 dirt
setblock ~186 ~122 ~37 dirt
setblock ~186 ~122 ~38 dirt
setblock ~186 ~122 ~39 dirt
setblock ~186 ~122 ~40 dirt
setblock ~186 ~122 ~41 dirt
setblock ~186 ~122 ~42 dirt
setblock ~186 ~122 ~43 dirt
setblock ~186 ~122 ~44 dirt
setblock ~186 ~122 ~45 dirt
setblock ~186 ~122 ~46 dirt
setblock ~186 ~122 ~47 dirt
setblock ~186 ~122 ~48 dirt
setblock ~186 ~122 ~49 dirt
setblock ~186 ~122 ~50 dirt
setblock ~186 ~122 ~51 dirt
setblock ~186 ~122 ~52 dirt
setblock ~186 ~122 ~53 dirt
setblock ~186 ~122 ~54 dirt
setblock ~186 ~122 ~55 dirt
setblock ~186 ~122 ~56 dirt
setblock ~186 ~122 ~57 dirt
setblock ~186 ~122 ~58 dirt
setblock ~186 ~122 ~59 dirt
setblock ~186 ~122 ~60 dirt
setblock ~186 ~122 ~61 dirt
setblock ~186 ~122 ~62 dirt
setblock ~186 ~122 ~63 dirt
setblock ~186 ~122 ~64 dirt
setblock ~186 ~122 ~65 dirt
setblock ~186 ~122 ~66 dirt
setblock ~186 ~122 ~67 dirt
setblock ~186 ~122 ~68 dirt
setblock ~186 ~122 ~69 dirt
setblock ~186 ~122 ~70 dirt
setblock ~186 ~122 ~71 dirt
setblock ~186 ~122 ~72 dirt
setblock ~186 ~122 ~73 dirt
setblock ~186 ~122 ~74 dirt
setblock ~186 ~122 ~75 dirt
setblock ~186 ~122 ~76 dirt
setblock ~186 ~122 ~77 dirt
setblock ~186 ~122 ~78 dirt
setblock ~186 ~122 ~79 dirt
setblock ~186 ~122 ~80 dirt
setblock ~186 ~122 ~81 dirt
setblock ~186 ~122 ~82 dirt
setblock ~186 ~122 ~83 dirt
setblock ~186 ~122 ~84 dirt
setblock ~186 ~122 ~85 dirt
setblock ~186 ~122 ~86 dirt
setblock ~186 ~122 ~87 dirt
setblock ~186 ~122 ~88 dirt
setblock ~186 ~122 ~89 dirt
setblock ~186 ~122 ~90 dirt
setblock ~186 ~122 ~91 dirt
setblock ~186 ~122 ~92 dirt
setblock ~186 ~122 ~93 dirt
setblock ~186 ~122 ~94 dirt
setblock ~186 ~122 ~95 dirt
setblock ~186 ~122 ~96 dirt
setblock ~186 ~122 ~97 dirt
setblock ~186 ~122 ~98 dirt
setblock ~186 ~122 ~99 dirt
setblock ~186 ~122 ~100 dirt
setblock ~186 ~122 ~101 dirt
setblock ~186 ~122 ~102 dirt
setblock ~186 ~122 ~103 dirt
setblock ~186 ~122 ~104 dirt
setblock ~186 ~122 ~105 dirt
setblock ~186 ~122 ~106 dirt
setblock ~186 ~122 ~107 dirt
setblock ~186 ~122 ~108 dirt
setblock ~186 ~122 ~109 dirt
setblock ~186 ~122 ~110 dirt
setblock ~186 ~122 ~111 dirt
setblock ~186 ~122 ~112 dirt
setblock ~186 ~122 ~113 dirt
setblock ~186 ~122 ~114 dirt
setblock ~186 ~122 ~115 dirt
setblock ~186 ~122 ~116 dirt
setblock ~186 ~122 ~117 dirt
setblock ~186 ~122 ~118 dirt
setblock ~186 ~122 ~119 dirt
setblock ~186 ~122 ~120 dirt
setblock ~186 ~122 ~121 dirt
setblock ~186 ~122 ~122 dirt
setblock ~186 ~122 ~123 dirt
setblock ~186 ~122 ~124 dirt
setblock ~186 ~122 ~125 dirt
setblock ~186 ~122 ~126 dirt
setblock ~186 ~122 ~127 dirt
setblock ~186 ~122 ~128 dirt
setblock ~186 ~122 ~129 dirt
setblock ~186 ~122 ~130 dirt
setblock ~186 ~122 ~131 dirt
setblock ~186 ~122 ~132 dirt
setblock ~186 ~122 ~133 dirt
setblock ~186 ~122 ~134 dirt
setblock ~186 ~122 ~135 dirt
setblock ~186 ~122 ~136 dirt
setblock ~186 ~122 ~137 dirt
setblock ~186 ~122 ~138 dirt
setblock ~186 ~122 ~139 dirt
setblock ~186 ~122 ~140 dirt
setblock ~186 ~122 ~141 dirt
setblock ~186 ~122 ~142 dirt
setblock ~186 ~122 ~143 dirt
setblock ~186 ~122 ~144 dirt
setblock ~186 ~122 ~145 dirt
setblock ~186 ~122 ~146 dirt
setblock ~186 ~122 ~147 dirt
setblock ~186 ~122 ~148 dirt
setblock ~186 ~122 ~149 dirt
setblock ~186 ~122 ~150 dirt
setblock ~186 ~122 ~151 dirt
setblock ~186 ~122 ~152 dirt
setblock ~186 ~122 ~153 dirt
setblock ~186 ~122 ~154 dirt
setblock ~186 ~122 ~155 dirt
setblock ~186 ~122 ~156 dirt
setblock ~186 ~122 ~157 dirt
setblock ~186 ~122 ~158 dirt
setblock ~186 ~122 ~159 dirt
setblock ~186 ~122 ~160 dirt
setblock ~186 ~122 ~161 dirt
setblock ~186 ~122 ~162 dirt
setblock ~186 ~122 ~163 dirt
setblock ~186 ~122 ~164 dirt
setblock ~186 ~122 ~165 dirt
setblock ~186 ~122 ~166 dirt
setblock ~186 ~122 ~167 dirt
setblock ~186 ~122 ~168 dirt
setblock ~186 ~122 ~169 dirt
setblock ~186 ~122 ~170 dirt
setblock ~186 ~122 ~171 dirt
setblock ~186 ~122 ~172 dirt
setblock ~186 ~122 ~173 dirt
setblock ~186 ~122 ~174 dirt
setblock ~186 ~122 ~175 dirt
setblock ~186 ~122 ~176 dirt
setblock ~186 ~122 ~177 dirt
setblock ~186 ~122 ~178 dirt
setblock ~186 ~122 ~179 dirt
setblock ~186 ~122 ~180 dirt
setblock ~186 ~122 ~181 dirt
setblock ~186 ~122 ~182 dirt
setblock ~186 ~122 ~183 dirt
setblock ~186 ~122 ~184 dirt
setblock ~186 ~122 ~185 dirt
setblock ~186 ~122 ~186 dirt
setblock ~186 ~122 ~187 dirt
setblock ~186 ~122 ~188 dirt
setblock ~186 ~122 ~189 dirt
setblock ~186 ~122 ~190 dirt
setblock ~186 ~122 ~191 dirt
setblock ~186 ~122 ~192 dirt
setblock ~186 ~122 ~193 dirt
setblock ~186 ~122 ~194 dirt
setblock ~186 ~122 ~195 dirt
setblock ~186 ~122 ~196 dirt
setblock ~186 ~122 ~197 dirt
setblock ~186 ~122 ~198 dirt
setblock ~186 ~122 ~199 dirt
setblock ~186 ~123 ~0 dirt
setblock ~186 ~123 ~1 dirt
setblock ~186 ~123 ~2 dirt
setblock ~186 ~123 ~3 dirt
setblock ~186 ~123 ~4 dirt
setblock ~186 ~123 ~5 dirt
setblock ~186 ~123 ~6 dirt
setblock ~186 ~123 ~7 dirt
setblock ~186 ~123 ~8 dirt
setblock ~186 ~123 ~9 dirt
setblock ~186 ~123 ~10 dirt
setblock ~186 ~123 ~11 dirt
setblock ~186 ~123 ~12 dirt
setblock ~186 ~123 ~13 dirt
setblock ~186 ~123 ~14 dirt
setblock ~186 ~123 ~15 dirt
setblock ~186 ~123 ~16 dirt
setblock ~186 ~123 ~17 dirt
setblock ~186 ~123 ~18 dirt
setblock ~186 ~123 ~19 dirt
setblock ~186 ~123 ~20 dirt
setblock ~186 ~123 ~21 dirt
setblock ~186 ~123 ~22 dirt
setblock ~186 ~123 ~23 dirt
setblock ~186 ~123 ~24 dirt
setblock ~186 ~123 ~25 dirt
setblock ~186 ~123 ~26 dirt
setblock ~186 ~123 ~27 dirt
setblock ~186 ~123 ~28 dirt
setblock ~186 ~123 ~29 dirt
setblock ~186 ~123 ~30 dirt
setblock ~186 ~123 ~31 dirt
setblock ~186 ~123 ~32 dirt
setblock ~186 ~123 ~33 dirt
setblock ~186 ~123 ~34 dirt
setblock ~186 ~123 ~35 dirt
setblock ~186 ~123 ~36 dirt
setblock ~186 ~123 ~37 dirt
setblock ~186 ~123 ~38 dirt
setblock ~186 ~123 ~39 dirt
setblock ~186 ~123 ~40 dirt
setblock ~186 ~123 ~41 dirt
setblock ~186 ~123 ~42 dirt
setblock ~186 ~123 ~43 dirt
setblock ~186 ~123 ~44 dirt
setblock ~186 ~123 ~45 dirt
setblock ~186 ~123 ~46 dirt
setblock ~186 ~123 ~47 dirt
setblock ~186 ~123 ~48 dirt
setblock ~186 ~123 ~49 dirt
setblock ~186 ~123 ~50 dirt
setblock ~186 ~123 ~51 dirt
setblock ~186 ~123 ~52 dirt
setblock ~186 ~123 ~53 dirt
setblock ~186 ~123 ~54 dirt
setblock ~186 ~123 ~55 dirt
setblock ~186 ~123 ~56 dirt
setblock ~186 ~123 ~57 dirt
setblock ~186 ~123 ~58 dirt
setblock ~186 ~123 ~59 dirt
setblock ~186 ~123 ~60 dirt
setblock ~186 ~123 ~61 dirt
setblock ~186 ~123 ~62 dirt
setblock ~186 ~123 ~63 dirt
setblock ~186 ~123 ~64 dirt
setblock ~186 ~123 ~65 dirt
setblock ~186 ~123 ~66 dirt
setblock ~186 ~123 ~67 dirt
setblock ~186 ~123 ~68 dirt
setblock ~186 ~123 ~69 dirt
setblock ~186 ~123 ~70 dirt
setblock ~186 ~123 ~71 dirt
setblock ~186 ~123 ~72 dirt
setblock ~186 ~123 ~73 dirt
setblock ~186 ~123 ~74 dirt
setblock ~186 ~123 ~75 dirt
setblock ~186 ~123 ~76 dirt
setblock ~186 ~123 ~77 dirt
setblock ~186 ~123 ~78 dirt
setblock ~186 ~123 ~79 dirt
setblock ~186 ~123 ~80 dirt
setblock ~186 ~123 ~81 dirt
setblock ~186 ~123 ~82 dirt
setblock ~186 ~123 ~83 dirt
setblock ~186 ~123 ~84 dirt
setblock ~186 ~123 ~85 dirt
setblock ~186 ~123 ~86 dirt
setblock ~186 ~123 ~87 dirt
setblock ~186 ~123 ~88 dirt
setblock ~186 ~123 ~89 dirt
setblock ~186 ~123 ~90 dirt
setblock ~186 ~123 ~91 dirt
setblock ~186 ~123 ~92 dirt
setblock ~186 ~123 ~93 dirt
setblock ~186 ~123 ~94 dirt
setblock ~186 ~123 ~95 dirt
setblock ~186 ~123 ~96 dirt
setblock ~186 ~123 ~97 dirt
setblock ~186 ~123 ~98 dirt
setblock ~186 ~123 ~99 dirt
setblock ~186 ~123 ~100 grass_block
setblock ~186 ~123 ~101 grass_block
setblock ~186 ~123 ~102 grass_block
setblock ~186 ~123 ~103 grass_block
setblock ~186 ~123 ~104 grass_block
setblock ~186 ~123 ~105 grass_block
setblock ~186 ~123 ~106 grass_block
setblock ~186 ~123 ~107 grass_block
setblock ~186 ~123 ~108 grass_block
setblock ~186 ~123 ~109 grass_block
setblock ~186 ~123 ~110 grass_block
setblock ~186 ~123 ~111 grass_block
setblock ~186 ~123 ~112 grass_block
setblock ~186 ~123 ~113 grass_block
setblock ~186 ~123 ~114 dirt
setblock ~186 ~123 ~115 dirt
setblock ~186 ~123 ~116 dirt
setblock ~186 ~123 ~117 grass_block
setblock ~186 ~123 ~118 grass_block
setblock ~186 ~123 ~119 grass_block
setblock ~186 ~123 ~120 grass_block
setblock ~186 ~123 ~121 grass_block
setblock ~186 ~123 ~122 grass_block
setblock ~186 ~123 ~123 grass_block
setblock ~186 ~123 ~124 grass_block
setblock ~186 ~123 ~125 grass_block
setblock ~186 ~123 ~126 dirt
setblock ~186 ~123 ~127 dirt
setblock ~186 ~123 ~128 dirt
setblock ~186 ~123 ~129 dirt
setblock ~186 ~123 ~130 dirt
setblock ~186 ~123 ~131 dirt
setblock ~186 ~123 ~132 dirt
setblock ~186 ~123 ~133 dirt
setblock ~186 ~123 ~134 dirt
setblock ~186 ~123 ~135 dirt
setblock ~186 ~123 ~136 dirt
setblock ~186 ~123 ~137 dirt
setblock ~186 ~123 ~138 dirt
setblock ~186 ~123 ~139 dirt
setblock ~186 ~123 ~140 dirt
setblock ~186 ~123 ~141 dirt
setblock ~186 ~123 ~142 dirt
setblock ~186 ~123 ~143 dirt
setblock ~186 ~123 ~144 dirt
setblock ~186 ~123 ~145 dirt
setblock ~186 ~123 ~146 dirt
setblock ~186 ~123 ~147 dirt
setblock ~186 ~123 ~148 dirt
setblock ~186 ~123 ~149 dirt
setblock ~186 ~123 ~150 dirt
setblock ~186 ~123 ~151 dirt
setblock ~186 ~123 ~152 dirt
setblock ~186 ~123 ~153 dirt
setblock ~186 ~123 ~154 dirt
setblock ~186 ~123 ~155 dirt
setblock ~186 ~123 ~156 dirt
setblock ~186 ~123 ~157 dirt
setblock ~186 ~123 ~158 dirt
setblock ~186 ~123 ~159 dirt
setblock ~186 ~123 ~160 dirt
setblock ~186 ~123 ~161 dirt
setblock ~186 ~123 ~162 dirt
setblock ~186 ~123 ~163 dirt
setblock ~186 ~123 ~164 dirt
setblock ~186 ~123 ~165 dirt
setblock ~186 ~123 ~166 dirt
setblock ~186 ~123 ~167 dirt
setblock ~186 ~123 ~168 dirt
setblock ~186 ~123 ~169 dirt
setblock ~186 ~123 ~170 dirt
setblock ~186 ~123 ~171 dirt
setblock ~186 ~123 ~172 dirt
setblock ~186 ~123 ~173 dirt
setblock ~186 ~123 ~174 dirt
setblock ~186 ~123 ~175 dirt
setblock ~186 ~123 ~176 dirt
setblock ~186 ~123 ~177 dirt
setblock ~186 ~123 ~178 dirt
setblock ~186 ~123 ~179 dirt
setblock ~186 ~123 ~180 dirt
setblock ~186 ~123 ~181 dirt
setblock ~186 ~123 ~182 dirt
setblock ~186 ~123 ~183 dirt
setblock ~186 ~123 ~184 dirt
setblock ~186 ~123 ~185 dirt
setblock ~186 ~123 ~186 dirt
setblock ~186 ~123 ~187 dirt
setblock ~186 ~123 ~188 dirt
setblock ~186 ~123 ~189 dirt
setblock ~186 ~123 ~190 dirt
setblock ~186 ~123 ~191 dirt
setblock ~186 ~123 ~192 dirt
setblock ~186 ~123 ~193 dirt
setblock ~186 ~123 ~194 dirt
setblock ~186 ~123 ~195 dirt
setblock ~186 ~123 ~196 dirt
setblock ~186 ~123 ~197 dirt
setblock ~186 ~123 ~198 dirt
setblock ~186 ~123 ~199 dirt
setblock ~186 ~124 ~0 grass_block
setblock ~186 ~124 ~1 dirt
setblock ~186 ~124 ~2 dirt
setblock ~186 ~124 ~3 dirt
setblock ~186 ~124 ~4 dirt
setblock ~186 ~124 ~5 dirt
setblock ~186 ~124 ~6 dirt
setblock ~186 ~124 ~7 dirt
setblock ~186 ~124 ~8 dirt
setblock ~186 ~124 ~9 dirt
setblock ~186 ~124 ~10 dirt
setblock ~186 ~124 ~11 dirt
setblock ~186 ~124 ~12 dirt
setblock ~186 ~124 ~13 dirt
setblock ~186 ~124 ~14 dirt
setblock ~186 ~124 ~15 dirt
setblock ~186 ~124 ~16 dirt
setblock ~186 ~124 ~17 dirt
setblock ~186 ~124 ~18 grass_block
setblock ~186 ~124 ~19 grass_block
setblock ~186 ~124 ~20 grass_block
setblock ~186 ~124 ~21 grass_block
setblock ~186 ~124 ~22 grass_block
setblock ~186 ~124 ~23 grass_block
setblock ~186 ~124 ~24 grass_block
setblock ~186 ~124 ~25 grass_block
setblock ~186 ~124 ~26 grass_block
setblock ~186 ~124 ~27 grass_block
setblock ~186 ~124 ~28 grass_block
setblock ~186 ~124 ~29 grass_block
setblock ~186 ~124 ~30 grass_block
setblock ~186 ~124 ~31 grass_block
setblock ~186 ~124 ~32 grass_block
setblock ~186 ~124 ~33 grass_block
setblock ~186 ~124 ~34 grass_block
setblock ~186 ~124 ~35 grass_block
setblock ~186 ~124 ~36 dirt
setblock ~186 ~124 ~37 dirt
setblock ~186 ~124 ~38 dirt
setblock ~186 ~124 ~39 dirt
setblock ~186 ~124 ~40 dirt
setblock ~186 ~124 ~41 dirt
setblock ~186 ~124 ~42 dirt
setblock ~186 ~124 ~43 dirt
setblock ~186 ~124 ~44 dirt
setblock ~186 ~124 ~45 dirt
setblock ~186 ~124 ~46 dirt
setblock ~186 ~124 ~47 dirt
setblock ~186 ~124 ~48 dirt
setblock ~186 ~124 ~49 dirt
setblock ~186 ~124 ~50 dirt
setblock ~186 ~124 ~51 dirt
setblock ~186 ~124 ~52 dirt
setblock ~186 ~124 ~53 dirt
setblock ~186 ~124 ~54 dirt
setblock ~186 ~124 ~55 dirt
setblock ~186 ~124 ~56 dirt
setblock ~186 ~124 ~57 dirt
setblock ~186 ~124 ~58 dirt
setblock ~186 ~124 ~59 grass_block
setblock ~186 ~124 ~60 grass_block
setblock ~186 ~124 ~61 grass_block
setblock ~186 ~124 ~62 grass_block
setblock ~186 ~124 ~63 grass_block
setblock ~186 ~124 ~64 grass_block
setblock ~186 ~124 ~65 grass_block
setblock ~186 ~124 ~66 grass_block
setblock ~186 ~124 ~67 grass_block
setblock ~186 ~124 ~68 grass_block
setblock ~186 ~124 ~69 grass_block
setblock ~186 ~124 ~70 grass_block
setblock ~186 ~124 ~71 grass_block
setblock ~186 ~124 ~72 grass_block
setblock ~186 ~124 ~73 grass_block
setblock ~186 ~124 ~74 dirt
setblock ~186 ~124 ~75 dirt
setblock ~186 ~124 ~76 dirt
setblock ~186 ~124 ~77 dirt
setblock ~186 ~124 ~78 dirt
setblock ~186 ~124 ~79 dirt
setblock ~186 ~124 ~80 dirt
setblock ~186 ~124 ~81 dirt
setblock ~186 ~124 ~82 dirt
setblock ~186 ~124 ~83 dirt
setblock ~186 ~124 ~84 dirt
setblock ~186 ~124 ~85 dirt
setblock ~186 ~124 ~86 dirt
setblock ~186 ~124 ~87 dirt
setblock ~186 ~124 ~88 dirt
setblock ~186 ~124 ~89 dirt
setblock ~186 ~124 ~90 dirt
setblock ~186 ~124 ~91 dirt
setblock ~186 ~124 ~92 dirt
setblock ~186 ~124 ~93 dirt
setblock ~186 ~124 ~94 dirt
setblock ~186 ~124 ~95 dirt
setblock ~186 ~124 ~96 dirt
setblock ~186 ~124 ~97 grass_block
setblock ~186 ~124 ~98 grass_block
setblock ~186 ~124 ~99 grass_block
setblock ~186 ~124 ~100 short_grass
setblock ~186 ~124 ~101 poppy
setblock ~186 ~124 ~110 fern
setblock ~186 ~124 ~113 short_grass
setblock ~186 ~124 ~114 grass_block
setblock ~186 ~124 ~115 grass_block
setblock ~186 ~124 ~116 grass_block
setblock ~186 ~124 ~118 short_grass
setblock ~186 ~124 ~119 short_grass
setblock ~186 ~124 ~121 short_grass
setblock ~186 ~124 ~125 short_grass
setblock ~186 ~124 ~126 grass_block
setblock ~186 ~124 ~127 grass_block
setblock ~186 ~124 ~128 grass_block
setblock ~186 ~124 ~129 grass_block
setblock ~186 ~124 ~130 grass_block
setblock ~186 ~124 ~131 grass_block
setblock ~186 ~124 ~132 grass_block
setblock ~186 ~124 ~133 grass_block
setblock ~186 ~124 ~134 grass_block
setblock ~186 ~124 ~135 grass_block
setblock ~186 ~124 ~136 grass_block
setblock ~186 ~124 ~137 grass_block
setblock ~186 ~124 ~138 grass_block
setblock ~186 ~124 ~139 grass_block
setblock ~186 ~124 ~140 grass_block
setblock ~186 ~124 ~141 grass_block
setblock ~186 ~124 ~142 grass_block
setblock ~186 ~124 ~143 grass_block
setblock ~186 ~124 ~144 grass_block
setblock ~186 ~124 ~145 grass_block
setblock ~186 ~124 ~146 grass_block
setblock ~186 ~124 ~147 grass_block
setblock ~186 ~124 ~148 grass_block
setblock ~186 ~124 ~149 grass_block
setblock ~186 ~124 ~150 grass_block
setblock ~186 ~124 ~151 grass_block
setblock ~186 ~124 ~152 grass_block
setblock ~186 ~124 ~153 grass_block
setblock ~186 ~124 ~154 grass_block
setblock ~186 ~124 ~155 grass_block
setblock ~186 ~124 ~156 grass_block
setblock ~186 ~124 ~157 grass_block
setblock ~186 ~124 ~158 grass_block
setblock ~186 ~124 ~159 grass_block
setblock ~186 ~124 ~160 grass_block
setblock ~186 ~124 ~161 grass_block
setblock ~186 ~124 ~162 grass_block
setblock ~186 ~124 ~163 grass_block
setblock ~186 ~124 ~164 grass_block
setblock ~186 ~124 ~165 grass_block
setblock ~186 ~124 ~166 grass_block
setblock ~186 ~124 ~167 grass_block
setblock ~186 ~124 ~168 grass_block
setblock ~186 ~124 ~169 grass_block
setblock ~186 ~124 ~170 grass_block
setblock ~186 ~124 ~171 dirt
setblock ~186 ~124 ~172 dirt
setblock ~186 ~124 ~173 dirt
setblock ~186 ~124 ~174 dirt
setblock ~186 ~124 ~175 dirt
setblock ~186 ~124 ~176 dirt
setblock ~186 ~124 ~177 dirt
setblock ~186 ~124 ~178 dirt
setblock ~186 ~124 ~179 dirt
setblock ~186 ~124 ~180 dirt
setblock ~186 ~124 ~181 dirt
setblock ~186 ~124 ~182 dirt
setblock ~186 ~124 ~183 dirt
setblock ~186 ~124 ~184 dirt
setblock ~186 ~124 ~185 dirt
setblock ~186 ~124 ~186 dirt
setblock ~186 ~124 ~187 dirt
setblock ~186 ~124 ~188 dirt
setblock ~186 ~124 ~189 dirt
setblock ~186 ~124 ~190 dirt
setblock ~186 ~124 ~191 dirt
setblock ~186 ~124 ~192 dirt
setblock ~186 ~124 ~193 dirt
setblock ~186 ~124 ~194 dirt
setblock ~186 ~124 ~195 dirt
setblock ~186 ~124 ~196 dirt
setblock ~186 ~124 ~197 dirt
setblock ~186 ~124 ~198 dirt
setblock ~186 ~124 ~199 dirt
setblock ~186 ~125 ~0 short_grass
setblock ~186 ~125 ~1 grass_block
setblock ~186 ~125 ~2 grass_block
setblock ~186 ~125 ~3 grass_block
setblock ~186 ~125 ~4 grass_block
setblock ~186 ~125 ~5 grass_block
setblock ~186 ~125 ~6 grass_block
setblock ~186 ~125 ~7 grass_block
setblock ~186 ~125 ~8 grass_block
setblock ~186 ~125 ~9 grass_block
setblock ~186 ~125 ~10 grass_block
setblock ~186 ~125 ~11 grass_block
setblock ~186 ~125 ~12 grass_block
setblock ~186 ~125 ~13 grass_block
setblock ~186 ~125 ~14 grass_block
setblock ~186 ~125 ~15 grass_block
setblock ~186 ~125 ~16 grass_block
setblock ~186 ~125 ~17 grass_block
setblock ~186 ~125 ~19 fern
setblock ~186 ~125 ~22 short_grass
setblock ~186 ~125 ~24 short_grass
setblock ~186 ~125 ~26 short_grass
setblock ~186 ~125 ~36 grass_block
setblock ~186 ~125 ~37 grass_block
setblock ~186 ~125 ~38 grass_block
setblock ~186 ~125 ~39 grass_block
setblock ~186 ~125 ~40 grass_block
setblock ~186 ~125 ~41 dirt
setblock ~186 ~125 ~42 dirt
setblock ~186 ~125 ~43 dirt
setblock ~186 ~125 ~44 dirt
setblock ~186 ~125 ~45 dirt
setblock ~186 ~125 ~46 dirt
setblock ~186 ~125 ~47 dirt
setblock ~186 ~125 ~48 dirt
setblock ~186 ~125 ~49 dirt
setblock ~186 ~125 ~50 dirt
setblock ~186 ~125 ~51 dirt
setblock ~186 ~125 ~52 dirt
setblock ~186 ~125 ~53 dirt
setblock ~186 ~125 ~54 dirt
setblock ~186 ~125 ~55 dirt
setblock ~186 ~125 ~56 grass_block
setblock ~186 ~125 ~57 grass_block
setblock ~186 ~125 ~58 grass_block
setblock ~186 ~125 ~59 short_grass
setblock ~186 ~125 ~60 short_grass
setblock ~186 ~125 ~63 short_grass
setblock ~186 ~125 ~64 short_grass
setblock ~186 ~125 ~66 fern
setblock ~186 ~125 ~69 short_grass
setblock ~186 ~125 ~73 short_grass
setblock ~186 ~125 ~74 grass_block
setblock ~186 ~125 ~75 grass_block
setblock ~186 ~125 ~76 grass_block
setblock ~186 ~125 ~77 grass_block
setblock ~186 ~125 ~78 grass_block
setblock ~186 ~125 ~79 grass_block
setblock ~186 ~125 ~80 grass_block
setblock ~186 ~125 ~81 grass_block
setblock ~186 ~125 ~82 grass_block
setblock ~186 ~125 ~83 grass_block
setblock ~186 ~125 ~84 dirt
setblock ~186 ~125 ~85 dirt
setblock ~186 ~125 ~86 dirt
setblock ~186 ~125 ~87 dirt
setblock ~186 ~125 ~88 dirt
setblock ~186 ~125 ~89 dirt
setblock ~186 ~125 ~90 dirt
setblock ~186 ~125 ~91 dirt
setblock ~186 ~125 ~92 dirt
setblock ~186 ~125 ~93 dirt
setblock ~186 ~125 ~94 grass_block
setblock ~186 ~125 ~95 grass_block
setblock ~186 ~125 ~96 grass_block
setblock ~186 ~125 ~99 short_grass
setblock ~186 ~125 ~114 poppy
setblock ~186 ~125 ~127 short_grass
setblock ~186 ~125 ~129 short_grass
setblock ~186 ~125 ~131 poppy
setblock ~186 ~125 ~134 poppy
setblock ~186 ~125 ~137 short_grass
setblock ~186 ~125 ~138 short_grass
setblock ~186 ~125 ~142 poppy
setblock ~186 ~125 ~145 short_grass
setblock ~186 ~125 ~146 short_grass
setblock ~186 ~125 ~148 short_grass
setblock ~186 ~125 ~151 poppy
setblock ~186 ~125 ~152 short_grass
setblock ~186 ~125 ~155 poppy
setblock ~186 ~125 ~156 short_grass
setblock ~186 ~125 ~159 short_grass
setblock ~186 ~125 ~160 short_grass
setblock ~186 ~125 ~164 short_grass
setblock ~186 ~125 ~166 short_grass
setblock ~186 ~125 ~171 grass_block
setblock ~186 ~125 ~172 grass_block
setblock ~186 ~125 ~173 grass_block
setblock ~186 ~125 ~174 grass_block
setblock ~186 ~125 ~175 dirt
setblock ~186 ~125 ~176 dirt
setblock ~186 ~125 ~177 dirt
setblock ~186 ~125 ~178 dirt
setblock ~186 ~125 ~179 dirt
setblock ~186 ~125 ~180 dirt
setblock ~186 ~125 ~181 dirt
setblock ~186 ~125 ~182 dirt
setblock ~186 ~125 ~183 dirt
setblock ~186 ~125 ~184 dirt
setblock ~186 ~125 ~185 dirt
setblock ~186 ~125 ~186 dirt
setblock ~186 ~125 ~187 dirt
setblock ~186 ~125 ~188 dirt
setblock ~186 ~125 ~189 dirt
setblock ~186 ~125 ~190 grass_block
setblock ~186 ~125 ~191 grass_block
setblock ~186 ~125 ~192 grass_block
setblock ~186 ~125 ~193 grass_block
setblock ~186 ~125 ~194 grass_block
setblock ~186 ~125 ~195 grass_block
setblock ~186 ~125 ~196 grass_block
setblock ~186 ~125 ~197 grass_block
setblock ~186 ~125 ~198 grass_block
setblock ~186 ~125 ~199 grass_block
setblock ~186 ~126 ~1 short_grass
setblock ~186 ~126 ~3 short_grass
setblock ~186 ~126 ~5 short_grass
setblock ~186 ~126 ~8 poppy
setblock ~186 ~126 ~10 short_grass
setblock ~186 ~126 ~11 short_grass
setblock ~186 ~126 ~16 short_grass
setblock ~186 ~126 ~17 short_grass
setblock ~186 ~126 ~37 poppy
setblock ~186 ~126 ~38 short_grass
setblock ~186 ~126 ~41 grass_block
setblock ~186 ~126 ~42 grass_block
setblock ~186 ~126 ~43 grass_block
setblock ~186 ~126 ~44 grass_block
setblock ~186 ~126 ~45 grass_block
setblock ~186 ~126 ~46 grass_block
setblock ~186 ~126 ~47 grass_block
setblock ~186 ~126 ~48 dirt
setblock ~186 ~126 ~49 dirt
setblock ~186 ~126 ~50 dirt
setblock ~186 ~126 ~51 grass_block
setblock ~186 ~126 ~52 grass_block
setblock ~186 ~126 ~53 grass_block
setblock ~186 ~126 ~54 grass_block
setblock ~186 ~126 ~55 grass_block
setblock ~186 ~126 ~74 fern
setblock ~186 ~126 ~75 fern
setblock ~186 ~126 ~76 short_grass
setblock ~186 ~126 ~78 short_grass
setblock ~186 ~126 ~84 grass_block
setblock ~186 ~126 ~85 grass_block
setblock ~186 ~126 ~86 grass_block
setblock ~186 ~126 ~87 grass_block
setblock ~186 ~126 ~88 dirt
setblock ~186 ~126 ~89 dirt
setblock ~186 ~126 ~90 dirt
setblock ~186 ~126 ~91 dirt
setblock ~186 ~126 ~92 grass_block
setblock ~186 ~126 ~93 grass_block
setblock ~186 ~126 ~94 short_grass
setblock ~186 ~126 ~175 grass_block
setblock ~186 ~126 ~176 grass_block
setblock ~186 ~126 ~177 grass_block
setblock ~186 ~126 ~178 grass_block
setblock ~186 ~126 ~179 grass_block
setblock ~186 ~126 ~180 grass_block
setblock ~186 ~126 ~181 grass_block
setblock ~186 ~126 ~182 grass_block
setblock ~186 ~126 ~183 grass_block
setblock ~186 ~126 ~184 grass_block
setblock ~186 ~126 ~185 grass_block
setblock ~186 ~126 ~186 grass_block
setblock ~186 ~126 ~187 grass_block
setblock ~186 ~126 ~188 grass_block
setblock ~186 ~126 ~189 grass_block
setblock ~186 ~126 ~192 poppy
setblock ~186 ~126 ~193 short_grass
setblock ~186 ~126 ~197 poppy
setblock ~186 ~127 ~45 short_grass
setblock ~186 ~127 ~46 short_grass
setblock ~186 ~127 ~47 fern
setblock ~186 ~127 ~48 grass_block
setblock ~186 ~127 ~49 grass_block
setblock ~186 ~127 ~50 grass_block
setblock ~186 ~127 ~86 poppy
setblock ~186 ~127 ~87 poppy
setblock ~186 ~127 ~88 grass_block
setblock ~186 ~127 ~89 grass_block
setblock ~186 ~127 ~90 grass_block
setblock ~186 ~127 ~91 grass_block
setblock ~186 ~127 ~179 short_grass
setblock ~186 ~127 ~185 short_grass
setblock ~186 ~127 ~186 short_grass
setblock ~186 ~127 ~188 short_grass
setblock ~186 ~127 ~189 fern
setblock ~186 ~128 ~90 short_grass
setblock ~187 ~122 ~0 dirt
setblock ~187 ~122 ~1 dirt
setblock ~187 ~122 ~2 dirt
setblock ~187 ~122 ~3 dirt
setblock ~187 ~122 ~4 dirt
setblock ~187 ~122 ~5 dirt
setblock ~187 ~122 ~6 dirt
setblock ~187 ~122 ~7 dirt
setblock ~187 ~122 ~8 dirt
setblock ~187 ~122 ~9 dirt
setblock ~187 ~122 ~10 dirt
setblock ~187 ~122 ~11 dirt
setblock ~187 ~122 ~12 dirt
setblock ~187 ~122 ~13 dirt
setblock ~187 ~122 ~14 dirt
setblock ~187 ~122 ~15 dirt
setblock ~187 ~122 ~16 dirt
setblock ~187 ~122 ~17 dirt
setblock ~187 ~122 ~18 dirt
setblock ~187 ~122 ~19 dirt
setblock ~187 ~122 ~20 dirt
setblock ~187 ~122 ~21 dirt
setblock ~187 ~122 ~22 dirt
setblock ~187 ~122 ~23 dirt
setblock ~187 ~122 ~24 dirt
setblock ~187 ~122 ~25 dirt
setblock ~187 ~122 ~26 dirt
setblock ~187 ~122 ~27 dirt
setblock ~187 ~122 ~28 dirt
setblock ~187 ~122 ~29 dirt
setblock ~187 ~122 ~30 dirt
setblock ~187 ~122 ~31 dirt
setblock ~187 ~122 ~32 dirt
setblock ~187 ~122 ~33 dirt
setblock ~187 ~122 ~34 dirt
setblock ~187 ~122 ~35 dirt
setblock ~187 ~122 ~36 dirt
setblock ~187 ~122 ~37 dirt
setblock ~187 ~122 ~38 dirt
setblock ~187 ~122 ~39 dirt
setblock ~187 ~122 ~40 dirt
setblock ~187 ~122 ~41 dirt
setblock ~187 ~122 ~42 dirt
setblock ~187 ~122 ~43 dirt
setblock ~187 ~122 ~44 dirt
setblock ~187 ~122 ~45 dirt
setblock ~187 ~122 ~46 dirt
setblock ~187 ~122 ~47 dirt
setblock ~187 ~122 ~48 dirt
setblock ~187 ~122 ~49 dirt
setblock ~187 ~122 ~50 dirt
setblock ~187 ~122 ~51 dirt
setblock ~187 ~122 ~52 dirt
setblock ~187 ~122 ~53 dirt
setblock ~187 ~122 ~54 dirt
setblock ~187 ~122 ~55 dirt
setblock ~187 ~122 ~56 dirt
setblock ~187 ~122 ~57 dirt
setblock ~187 ~122 ~58 dirt
setblock ~187 ~122 ~59 dirt
setblock ~187 ~122 ~60 dirt
setblock ~187 ~122 ~61 dirt
setblock ~187 ~122 ~62 dirt
setblock ~187 ~122 ~63 dirt
setblock ~187 ~122 ~64 dirt
setblock ~187 ~122 ~65 dirt
setblock ~187 ~122 ~66 dirt
setblock ~187 ~122 ~67 dirt
setblock ~187 ~122 ~68 dirt
setblock ~187 ~122 ~69 dirt
setblock ~187 ~122 ~70 dirt
setblock ~187 ~122 ~71 dirt
setblock ~187 ~122 ~72 dirt
setblock ~187 ~122 ~73 dirt
setblock ~187 ~122 ~74 dirt
setblock ~187 ~122 ~75 dirt
setblock ~187 ~122 ~76 dirt
setblock ~187 ~122 ~77 dirt
setblock ~187 ~122 ~78 dirt
setblock ~187 ~122 ~79 dirt
setblock ~187 ~122 ~80 dirt
setblock ~187 ~122 ~81 dirt
setblock ~187 ~122 ~82 dirt
setblock ~187 ~122 ~83 dirt
setblock ~187 ~122 ~84 dirt
setblock ~187 ~122 ~85 dirt
setblock ~187 ~122 ~86 dirt
setblock ~187 ~122 ~87 dirt
setblock ~187 ~122 ~88 dirt
setblock ~187 ~122 ~89 dirt
setblock ~187 ~122 ~90 dirt
setblock ~187 ~122 ~91 dirt
setblock ~187 ~122 ~92 dirt
setblock ~187 ~122 ~93 dirt
setblock ~187 ~122 ~94 dirt
setblock ~187 ~122 ~95 dirt
setblock ~187 ~122 ~96 dirt
setblock ~187 ~122 ~97 dirt
setblock ~187 ~122 ~98 dirt
setblock ~187 ~122 ~99 dirt
setblock ~187 ~122 ~100 dirt
setblock ~187 ~122 ~101 dirt
setblock ~187 ~122 ~102 dirt
setblock ~187 ~122 ~103 dirt
setblock ~187 ~122 ~104 dirt
setblock ~187 ~122 ~105 dirt
setblock ~187 ~122 ~106 dirt
setblock ~187 ~122 ~107 dirt
setblock ~187 ~122 ~108 dirt
setblock ~187 ~122 ~109 dirt
setblock ~187 ~122 ~110 dirt
setblock ~187 ~122 ~111 dirt
setblock ~187 ~122 ~112 dirt
setblock ~187 ~122 ~113 dirt
setblock ~187 ~122 ~114 dirt
setblock ~187 ~122 ~115 dirt
setblock ~187 ~122 ~116 dirt
setblock ~187 ~122 ~117 dirt
setblock ~187 ~122 ~118 dirt
setblock ~187 ~122 ~119 dirt
setblock ~187 ~122 ~120 dirt
setblock ~187 ~122 ~121 dirt
setblock ~187 ~122 ~122 dirt
setblock ~187 ~122 ~123 dirt
setblock ~187 ~122 ~124 dirt
setblock ~187 ~122 ~125 dirt
setblock ~187 ~122 ~126 dirt
setblock ~187 ~122 ~127 dirt
setblock ~187 ~122 ~128 dirt
setblock ~187 ~122 ~129 dirt
setblock ~187 ~122 ~130 dirt
setblock ~187 ~122 ~131 dirt
setblock ~187 ~122 ~132 dirt
setblock ~187 ~122 ~133 dirt
setblock ~187 ~122 ~134 dirt
setblock ~187 ~122 ~135 dirt
setblock ~187 ~122 ~136 dirt
setblock ~187 ~122 ~137 dirt
setblock ~187 ~122 ~138 dirt
setblock ~187 ~122 ~139 dirt
setblock ~187 ~122 ~140 dirt
setblock ~187 ~122 ~141 dirt
setblock ~187 ~122 ~142 dirt
setblock ~187 ~122 ~143 dirt
setblock ~187 ~122 ~144 dirt
setblock ~187 ~122 ~145 dirt
setblock ~187 ~122 ~146 dirt
setblock ~187 ~122 ~147 dirt
setblock ~187 ~122 ~148 dirt
setblock ~187 ~122 ~149 dirt
setblock ~187 ~122 ~150 dirt
setblock ~187 ~122 ~151 dirt
setblock ~187 ~122 ~152 dirt
setblock ~187 ~122 ~153 dirt
setblock ~187 ~122 ~154 dirt
setblock ~187 ~122 ~155 dirt
setblock ~187 ~122 ~156 dirt
setblock ~187 ~122 ~157 dirt
setblock ~187 ~122 ~158 dirt
setblock ~187 ~122 ~159 dirt
setblock ~187 ~122 ~160 dirt
setblock ~187 ~122 ~161 dirt
setblock ~187 ~122 ~162 dirt
setblock ~187 ~122 ~163 dirt
setblock ~187 ~122 ~164 dirt
setblock ~187 ~122 ~165 dirt
setblock ~187 ~122 ~166 dirt
setblock ~187 ~122 ~167 dirt
setblock ~187 ~122 ~168 dirt
setblock ~187 ~122 ~169 dirt
setblock ~187 ~122 ~170 dirt
setblock ~187 ~122 ~171 dirt
setblock ~187 ~122 ~172 dirt
setblock ~187 ~122 ~173 dirt
setblock ~187 ~122 ~174 dirt
setblock ~187 ~122 ~175 dirt
setblock ~187 ~122 ~176 dirt
setblock ~187 ~122 ~177 dirt
setblock ~187 ~122 ~178 dirt
setblock ~187 ~122 ~179 dirt
setblock ~187 ~122 ~180 dirt
setblock ~187 ~122 ~181 dirt
setblock ~187 ~122 ~182 dirt
setblock ~187 ~122 ~183 dirt
setblock ~187 ~122 ~184 dirt
setblock ~187 ~122 ~185 dirt
setblock ~187 ~122 ~186 dirt
setblock ~187 ~122 ~187 dirt
setblock ~187 ~122 ~188 dirt
setblock ~187 ~122 ~189 dirt
setblock ~187 ~122 ~190 dirt
setblock ~187 ~122 ~191 dirt
setblock ~187 ~122 ~192 dirt
setblock ~187 ~122 ~193 dirt
setblock ~187 ~122 ~194 dirt
setblock ~187 ~122 ~195 dirt
setblock ~187 ~122 ~196 dirt
setblock ~187 ~122 ~197 dirt
setblock ~187 ~122 ~198 dirt
setblock ~187 ~122 ~199 dirt
setblock ~187 ~123 ~0 dirt
setblock ~187 ~123 ~1 dirt
setblock ~187 ~123 ~2 dirt
setblock ~187 ~123 ~3 dirt
setblock ~187 ~123 ~4 dirt
setblock ~187 ~123 ~5 dirt
setblock ~187 ~123 ~6 dirt
setblock ~187 ~123 ~7 dirt
setblock ~187 ~123 ~8 dirt
setblock ~187 ~123 ~9 dirt
setblock ~187 ~123 ~10 dirt
setblock ~187 ~123 ~11 dirt
setblock ~187 ~123 ~12 dirt
setblock ~187 ~123 ~13 dirt
setblock ~187 ~123 ~14 dirt
setblock ~187 ~123 ~15 dirt
setblock ~187 ~123 ~16 dirt
setblock ~187 ~123 ~17 dirt
setblock ~187 ~123 ~18 dirt
setblock ~187 ~123 ~19 dirt
setblock ~187 ~123 ~20 dirt
setblock ~187 ~123 ~21 dirt
setblock ~187 ~123 ~22 dirt
setblock ~187 ~123 ~23 dirt
setblock ~187 ~123 ~24 dirt
setblock ~187 ~123 ~25 dirt
setblock ~187 ~123 ~26 dirt
setblock ~187 ~123 ~27 dirt
setblock ~187 ~123 ~28 dirt
setblock ~187 ~123 ~29 grass_block
setblock ~187 ~123 ~30 grass_block
setblock ~187 ~123 ~31 dirt
setblock ~187 ~123 ~32 dirt
setblock ~187 ~123 ~33 dirt
setblock ~187 ~123 ~34 dirt
setblock ~187 ~123 ~35 dirt
setblock ~187 ~123 ~36 dirt
setblock ~187 ~123 ~37 dirt
setblock ~187 ~123 ~38 dirt
setblock ~187 ~123 ~39 dirt
setblock ~187 ~123 ~40 dirt
setblock ~187 ~123 ~41 dirt
setblock ~187 ~123 ~42 dirt
setblock ~187 ~123 ~43 dirt
setblock ~187 ~123 ~44 dirt
setblock ~187 ~123 ~45 dirt
setblock ~187 ~123 ~46 dirt
setblock ~187 ~123 ~47 dirt
setblock ~187 ~123 ~48 dirt
setblock ~187 ~123 ~49 dirt
setblock ~187 ~123 ~50 dirt
setblock ~187 ~123 ~51 dirt
setblock ~187 ~123 ~52 dirt
setblock ~187 ~123 ~53 dirt
setblock ~187 ~123 ~54 dirt
setblock ~187 ~123 ~55 dirt
setblock ~187 ~123 ~56 dirt
setblock ~187 ~123 ~57 dirt
setblock ~187 ~123 ~58 dirt
setblock ~187 ~123 ~59 dirt
setblock ~187 ~123 ~60 dirt
setblock ~187 ~123 ~61 dirt
setblock ~187 ~123 ~62 dirt
setblock ~187 ~123 ~63 dirt
setblock ~187 ~123 ~64 dirt
setblock ~187 ~123 ~65 dirt
setblock ~187 ~123 ~66 dirt
setblock ~187 ~123 ~67 dirt
setblock ~187 ~123 ~68 grass_block
setblock ~187 ~123 ~69 grass_block
setblock ~187 ~123 ~70 grass_block
setblock ~187 ~123 ~71 dirt
setblock ~187 ~123 ~72 dirt
setblock ~187 ~123 ~73 dirt
setblock ~187 ~123 ~74 dirt
setblock ~187 ~123 ~75 dirt
setblock ~187 ~123 ~76 dirt
setblock ~187 ~123 ~77 dirt
setblock ~187 ~123 ~78 dirt
setblock ~187 ~123 ~79 dirt
setblock ~187 ~123 ~80 dirt
setblock ~187 ~123 ~81 dirt
setblock ~187 ~123 ~82 dirt
setblock ~187 ~123 ~83 dirt
setblock ~187 ~123 ~84 dirt
setblock ~187 ~123 ~85 dirt
setblock ~187 ~123 ~86 dirt
setblock ~187 ~123 ~87 dirt
setblock ~187 ~123 ~88 dirt
setblock ~187 ~123 ~89 dirt
setblock ~187 ~123 ~90 dirt
setblock ~187 ~123 ~91 dirt
setblock ~187 ~123 ~92 dirt
setblock ~187 ~123 ~93 dirt
setblock ~187 ~123 ~94 dirt
setblock ~187 ~123 ~95 dirt
setblock ~187 ~123 ~96 dirt
setblock ~187 ~123 ~97 dirt
setblock ~187 ~123 ~98 dirt
setblock ~187 ~123 ~99 dirt
setblock ~187 ~123 ~100 grass_block
setblock ~187 ~123 ~101 grass_block
setblock ~187 ~123 ~102 grass_block
setblock ~187 ~123 ~103 grass_block
setblock ~187 ~123 ~104 grass_block
setblock ~187 ~123 ~105 grass_block
setblock ~187 ~123 ~106 grass_block
setblock ~187 ~123 ~107 grass_block
setblock ~187 ~123 ~108 grass_block
setblock ~187 ~123 ~109 grass_block
setblock ~187 ~123 ~110 grass_block
setblock ~187 ~123 ~111 grass_block
setblock ~187 ~123 ~112 grass_block
setblock ~187 ~123 ~113 grass_block
setblock ~187 ~123 ~114 dirt
setblock ~187 ~123 ~115 dirt
setblock ~187 ~123 ~116 dirt
setblock ~187 ~123 ~117 dirt
setblock ~187 ~123 ~118 grass_block
setblock ~187 ~123 ~119 grass_block
setblock ~187 ~123 ~120 grass_block
setblock ~187 ~123 ~121 grass_block
setblock ~187 ~123 ~122 grass_block
setblock ~187 ~123 ~123 grass_block
setblock ~187 ~123 ~124 grass_block
setblock ~187 ~123 ~125 grass_block
setblock ~187 ~123 ~126 grass_block
setblock ~187 ~123 ~127 grass_block
setblock ~187 ~123 ~128 grass_block
setblock ~187 ~123 ~129 grass_block
setblock ~187 ~123 ~130 grass_block
setblock ~187 ~123 ~131 grass_block
setblock ~187 ~123 ~132 dirt
setblock ~187 ~123 ~133 dirt
setblock ~187 ~123 ~134 dirt
setblock ~187 ~123 ~135 dirt
setblock ~187 ~123 ~136 dirt
setblock ~187 ~123 ~137 dirt
setblock ~187 ~123 ~138 dirt
setblock ~187 ~123 ~139 dirt
setblock ~187 ~123 ~140 dirt
setblock ~187 ~123 ~141 dirt
setblock ~187 ~123 ~142 dirt
setblock ~187 ~123 ~143 dirt
setblock ~187 ~123 ~144 dirt
setblock ~187 ~123 ~145 dirt
setblock ~187 ~123 ~146 dirt
setblock ~187 ~123 ~147 dirt
setblock ~187 ~123 ~148 dirt
setblock ~187 ~123 ~149 dirt
setblock ~187 ~123 ~150 dirt
setblock ~187 ~123 ~151 dirt
setblock ~187 ~123 ~152 dirt
setblock ~187 ~123 ~153 dirt
setblock ~187 ~123 ~154 dirt
setblock ~187 ~123 ~155 dirt
setblock ~187 ~123 ~156 dirt
setblock ~187 ~123 ~157 dirt
setblock ~187 ~123 ~158 dirt
setblock ~187 ~123 ~159 dirt
setblock ~187 ~123 ~160 grass_block
setblock ~187 ~123 ~161 dirt
setblock ~187 ~123 ~162 dirt
setblock ~187 ~123 ~163 dirt
setblock ~187 ~123 ~164 dirt
setblock ~187 ~123 ~165 dirt
setblock ~187 ~123 ~166 dirt
setblock ~187 ~123 ~167 dirt
setblock ~187 ~123 ~168 dirt
setblock ~187 ~123 ~169 dirt
setblock ~187 ~123 ~170 dirt
setblock ~187 ~123 ~171 dirt
setblock ~187 ~123 ~172 dirt
setblock ~187 ~123 ~173 dirt
setblock ~187 ~123 ~174 dirt
setblock ~187 ~123 ~175 dirt
setblock ~187 ~123 ~176 dirt
setblock ~187 ~123 ~177 dirt
setblock ~187 ~123 ~178 dirt
setblock ~187 ~123 ~179 dirt
setblock ~187 ~123 ~180 dirt
setblock ~187 ~123 ~181 dirt
setblock ~187 ~123 ~182 dirt
setblock ~187 ~123 ~183 dirt
setblock ~187 ~123 ~184 dirt
setblock ~187 ~123 ~185 dirt
setblock ~187 ~123 ~186 dirt
setblock ~187 ~123 ~187 dirt
setblock ~187 ~123 ~188 dirt
setblock ~187 ~123 ~189 dirt
setblock ~187 ~123 ~190 dirt
setblock ~187 ~123 ~191 dirt
setblock ~187 ~123 ~192 dirt
setblock ~187 ~123 ~193 dirt
setblock ~187 ~123 ~194 dirt
setblock ~187 ~123 ~195 dirt
setblock ~187 ~123 ~196 dirt
setblock ~187 ~123 ~197 dirt
setblock ~187 ~123 ~198 dirt
setblock ~187 ~123 ~199 dirt
setblock ~187 ~124 ~0 grass_block
setblock ~187 ~124 ~1 grass_block
setblock ~187 ~124 ~2 grass_block
setblock ~187 ~124 ~3 grass_block
setblock ~187 ~124 ~4 grass_block
setblock ~187 ~124 ~5 dirt
setblock ~187 ~124 ~6 dirt
setblock ~187 ~124 ~7 dirt
setblock ~187 ~124 ~8 dirt
setblock ~187 ~124 ~9 dirt
setblock ~187 ~124 ~10 dirt
setblock ~187 ~124 ~11 dirt
setblock ~187 ~124 ~12 dirt
setblock ~187 ~124 ~13 dirt
setblock ~187 ~124 ~14 dirt
setblock ~187 ~124 ~15 dirt
setblock ~187 ~124 ~16 dirt
setblock ~187 ~124 ~17 dirt
setblock ~187 ~124 ~18 dirt
setblock ~187 ~124 ~19 grass_block
setblock ~187 ~124 ~20 grass_block
setblock ~187 ~124 ~21 grass_block
setblock ~187 ~124 ~22 grass_block
setblock ~187 ~124 ~23 grass_block
setblock ~187 ~124 ~24 grass_block
setblock ~187 ~124 ~25 grass_block
setblock ~187 ~124 ~26 grass_block
setblock ~187 ~124 ~27 grass_block
setblock ~187 ~124 ~28 grass_block
setblock ~187 ~124 ~31 grass_block
setblock ~187 ~124 ~32 grass_block
setblock ~187 ~124 ~33 grass_block
setblock ~187 ~124 ~34 grass_block
setblock ~187 ~124 ~35 dirt
setblock ~187 ~124 ~36 dirt
setblock ~187 ~124 ~37 dirt
setblock ~187 ~124 ~38 dirt
setblock ~187 ~124 ~39 dirt
setblock ~187 ~124 ~40 dirt
setblock ~187 ~124 ~41 dirt
setblock ~187 ~124 ~42 dirt
setblock ~187 ~124 ~43 dirt
setblock ~187 ~124 ~44 dirt
setblock ~187 ~124 ~45 dirt
setblock ~187 ~124 ~46 dirt
setblock ~187 ~124 ~47 dirt
setblock ~187 ~124 ~48 dirt
setblock ~187 ~124 ~49 dirt
setblock ~187 ~124 ~50 dirt
setblock ~187 ~124 ~51 dirt
setblock ~187 ~124 ~52 dirt
setblock ~187 ~124 ~53 dirt
setblock ~187 ~124 ~54 dirt
setblock ~187 ~124 ~55 dirt
setblock ~187 ~124 ~56 dirt
setblock ~187 ~124 ~57 dirt
setblock ~187 ~124 ~58 dirt
setblock ~187 ~124 ~59 grass_block
setblock ~187 ~124 ~60 grass_block
setblock ~187 ~124 ~61 grass_block
setblock ~187 ~124 ~62 grass_block
setblock ~187 ~124 ~63 grass_block
setblock ~187 ~124 ~64 grass_block
setblock ~187 ~124 ~65 grass_block
setblock ~187 ~124 ~66 grass_block
setblock ~187 ~124 ~67 grass_block
setblock ~187 ~124 ~69 short_grass
setblock ~187 ~124 ~71 grass_block
setblock ~187 ~124 ~72 grass_block
setblock ~187 ~124 ~73 grass_block
setblock ~187 ~124 ~74 grass_block
setblock ~187 ~124 ~75 grass_block
setblock ~187 ~124 ~76 dirt
setblock ~187 ~124 ~77 dirt
setblock ~187 ~124 ~78 dirt
setblock ~187 ~124 ~79 dirt
setblock ~187 ~124 ~80 dirt
setblock ~187 ~124 ~81 dirt
setblock ~187 ~124 ~82 dirt
setblock ~187 ~124 ~83 dirt
setblock ~187 ~124 ~84 dirt
setblock ~187 ~124 ~85 dirt
setblock ~187 ~124 ~86 dirt
setblock ~187 ~124 ~87 dirt
setblock ~187 ~124 ~88 dirt
setblock ~187 ~124 ~89 dirt
setblock ~187 ~124 ~90 dirt
setblock ~187 ~124 ~91 dirt
setblock ~187 ~124 ~92 dirt
setblock ~187 ~124 ~93 dirt
setblock ~187 ~124 ~94 dirt
setblock ~187 ~124 ~95 dirt
setblock ~187 ~124 ~96 dirt
setblock ~187 ~124 ~97 grass_block
setblock ~187 ~124 ~98 grass_block
setblock ~187 ~124 ~99 grass_block
setblock ~187 ~124 ~101 short_grass
setblock ~187 ~124 ~106 short_grass
setblock ~187 ~124 ~114 grass_block
setblock ~187 ~124 ~115 grass_block
setblock ~187 ~124 ~116 grass_block
setblock ~187 ~124 ~117 grass_block
setblock ~187 ~124 ~119 short_grass
setblock ~187 ~124 ~120 short_grass
setblock ~187 ~124 ~121 short_grass
setblock ~187 ~124 ~123 short_grass
setblock ~187 ~124 ~126 poppy
setblock ~187 ~124 ~129 short_grass
setblock ~187 ~124 ~132 grass_block
setblock ~187 ~124 ~133 grass_block
setblock ~187 ~124 ~134 grass_block
setblock ~187 ~124 ~135 grass_block
setblock ~187 ~124 ~136 grass_block
setblock ~187 ~124 ~137 grass_block
setblock ~187 ~124 ~138 grass_block
setblock ~187 ~124 ~139 grass_block
setblock ~187 ~124 ~140 grass_block
setblock ~187 ~124 ~141 grass_block
setblock ~187 ~124 ~142 grass_block
setblock ~187 ~124 ~143 grass_block
setblock ~187 ~124 ~144 grass_block
setblock ~187 ~124 ~145 grass_block
setblock ~187 ~124 ~146 grass_block
setblock ~187 ~124 ~147 grass_block
setblock ~187 ~124 ~148 dirt
setblock ~187 ~124 ~149 dirt
setblock ~187 ~124 ~150 dirt
setblock ~187 ~124 ~151 dirt
setblock ~187 ~124 ~152 dirt
setblock ~187 ~124 ~153 grass_block
setblock ~187 ~124 ~154 grass_block
setblock ~187 ~124 ~155 grass_block
setblock ~187 ~124 ~156 grass_block
setblock ~187 ~124 ~157 grass_block
setblock ~187 ~124 ~158 grass_block
setblock ~187 ~124 ~159 grass_block
setblock ~187 ~124 ~160 poppy
setblock ~187 ~124 ~161 grass_block
setblock ~187 ~124 ~162 grass_block
setblock ~187 ~124 ~163 grass_block
setblock ~187 ~124 ~164 grass_block
setblock ~187 ~124 ~165 grass_block
setblock ~187 ~124 ~166 grass_block
setblock ~187 ~124 ~167 grass_block
setblock ~187 ~124 ~168 grass_block
setblock ~187 ~124 ~169 grass_block
setblock ~187 ~124 ~170 dirt
setblock ~187 ~124 ~171 dirt
setblock ~187 ~124 ~172 dirt
setblock ~187 ~124 ~173 dirt
setblock ~187 ~124 ~174 dirt
setblock ~187 ~124 ~175 dirt
setblock ~187 ~124 ~176 dirt
setblock ~187 ~124 ~177 dirt
setblock ~187 ~124 ~178 dirt
setblock ~187 ~124 ~179 dirt
setblock ~187 ~124 ~180 dirt
setblock ~187 ~124 ~181 dirt
setblock ~187 ~124 ~182 dirt
setblock ~187 ~124 ~183 dirt
setblock ~187 ~124 ~184 dirt
setblock ~187 ~124 ~185 dirt
setblock ~187 ~124 ~186 dirt
setblock ~187 ~124 ~187 dirt
setblock ~187 ~124 ~188 dirt
setblock ~187 ~124 ~189 dirt
setblock ~187 ~124 ~190 dirt
setblock ~187 ~124 ~191 dirt
setblock ~187 ~124 ~192 dirt
setblock ~187 ~124 ~193 dirt
setblock ~187 ~124 ~194 dirt
setblock ~187 ~124 ~195 dirt
setblock ~187 ~124 ~196 dirt
setblock ~187 ~124 ~197 dirt
setblock ~187 ~124 ~198 dirt
setblock ~187 ~124 ~199 dirt
setblock ~187 ~125 ~2 fern
setblock ~187 ~125 ~5 grass_block
setblock ~187 ~125 ~6 grass_block
setblock ~187 ~125 ~7 grass_block
setblock ~187 ~125 ~8 grass_block
setblock ~187 ~125 ~9 grass_block
setblock ~187 ~125 ~10 grass_block
setblock ~187 ~125 ~11 grass_block
setblock ~187 ~125 ~12 grass_block
setblock ~187 ~125 ~13 grass_block
setblock ~187 ~125 ~14 grass_block
setblock ~187 ~125 ~15 grass_block
setblock ~187 ~125 ~16 grass_block
setblock ~187 ~125 ~17 grass_block
setblock ~187 ~125 ~18 grass_block
setblock ~187 ~125 ~21 short_grass
setblock ~187 ~125 ~23 short_grass
setblock ~187 ~125 ~24 short_grass
setblock ~187 ~125 ~25 short_grass
setblock ~187 ~125 ~35 grass_block
setblock ~187 ~125 ~36 grass_block
setblock ~187 ~125 ~37 grass_block
setblock ~187 ~125 ~38 dirt
setblock ~187 ~125 ~39 dirt
setblock ~187 ~125 ~40 dirt
setblock ~187 ~125 ~41 dirt
setblock ~187 ~125 ~42 dirt
setblock ~187 ~125 ~43 dirt
setblock ~187 ~125 ~44 dirt
setblock ~187 ~125 ~45 dirt
setblock ~187 ~125 ~46 dirt
setblock ~187 ~125 ~47 dirt
setblock ~187 ~125 ~48 dirt
setblock ~187 ~125 ~49 dirt
setblock ~187 ~125 ~50 dirt
setblock ~187 ~125 ~51 dirt
setblock ~187 ~125 ~52 dirt
setblock ~187 ~125 ~53 dirt
setblock ~187 ~125 ~54 dirt
setblock ~187 ~125 ~55 dirt
setblock ~187 ~125 ~56 grass_block
setblock ~187 ~125 ~57 grass_block
setblock ~187 ~125 ~58 grass_block
setblock ~187 ~125 ~62 short_grass
setblock ~187 ~125 ~71 poppy
setblock ~187 ~125 ~75 short_grass
setblock ~187 ~125 ~76 grass_block
setblock ~187 ~125 ~77 grass_block
setblock ~187 ~125 ~78 grass_block
setblock ~187 ~125 ~79 grass_block
setblock ~187 ~125 ~80 grass_block
setblock ~187 ~125 ~81 grass_block
setblock ~187 ~125 ~82 grass_block
setblock ~187 ~125 ~83 grass_block
setblock ~187 ~125 ~84 grass_block
setblock ~187 ~125 ~85 dirt
setblock ~187 ~125 ~86 dirt
setblock ~187 ~125 ~87 dirt
setblock ~187 ~125 ~88 dirt
setblock ~187 ~125 ~89 dirt
setblock ~187 ~125 ~90 dirt
setblock ~187 ~125 ~91 dirt
setblock ~187 ~125 ~92 dirt
setblock ~187 ~125 ~93 dirt
setblock ~187 ~125 ~94 grass_block
setblock ~187 ~125 ~95 grass_block
setblock ~187 ~125 ~96 grass_block
setblock ~187 ~125 ~116 fern
setblock ~187 ~125 ~135 short_grass
setblock ~187 ~125 ~138 short_grass
setblock ~187 ~125 ~142 short_grass
setblock ~187 ~125 ~148 grass_block
setblock ~187 ~125 ~149 grass_block
setblock ~187 ~125 ~150 grass_block
setblock ~187 ~125 ~151 grass_block
setblock ~187 ~125 ~152 grass_block
setblock ~187 ~125 ~155 short_grass
setblock ~187 ~125 ~156 short_grass
setblock ~187 ~125 ~157 short_grass
setblock ~187 ~125 ~165 short_grass
setblock ~187 ~125 ~166 short_grass
setblock ~187 ~125 ~167 short_grass
setblock ~187 ~125 ~169 short_grass
setblock ~187 ~125 ~170 grass_block
setblock ~187 ~125 ~171 grass_block
setblock ~187 ~125 ~172 grass_block
setblock ~187 ~125 ~173 grass_block
setblock ~187 ~125 ~174 dirt
setblock ~187 ~125 ~175 dirt
setblock ~187 ~125 ~176 dirt
setblock ~187 ~125 ~177 dirt
setblock ~187 ~125 ~178 dirt
setblock ~187 ~125 ~179 dirt
setblock ~187 ~125 ~180 dirt
setblock ~187 ~125 ~181 dirt
setblock ~187 ~125 ~182 dirt
setblock ~187 ~125 ~183 dirt
setblock ~187 ~125 ~184 dirt
setblock ~187 ~125 ~185 dirt
setblock ~187 ~125 ~186 dirt
setblock ~187 ~125 ~187 grass_block
setblock ~187 ~125 ~188 grass_block
setblock ~187 ~125 ~189 grass_block
setblock ~187 ~125 ~190 grass_block
setblock ~187 ~125 ~191 grass_block
setblock ~187 ~125 ~192 grass_block
setblock ~187 ~125 ~193 grass_block
setblock ~187 ~125 ~194 grass_block
setblock ~187 ~125 ~195 dirt
setblock ~187 ~125 ~196 dirt
setblock ~187 ~125 ~197 dirt
setblock ~187 ~125 ~198 dirt
setblock ~187 ~125 ~199 dirt
setblock ~187 ~126 ~10 short_grass
setblock ~187 ~126 ~11 short_grass
setblock ~187 ~126 ~16 short_grass
setblock ~187 ~126 ~36 short_grass
setblock ~187 ~126 ~38 grass_block
setblock ~187 ~126 ~39 grass_block
setblock ~187 ~126 ~40 grass_block
setblock ~187 ~126 ~41 grass_block
setblock ~187 ~126 ~42 dirt
setblock ~187 ~126 ~43 dirt
setblock ~187 ~126 ~44 dirt
setblock ~187 ~126 ~45 dirt
setblock ~187 ~126 ~46 dirt
setblock ~187 ~126 ~47 dirt
setblock ~187 ~126 ~48 dirt
setblock ~187 ~126 ~49 dirt
setblock ~187 ~126 ~50 dirt
setblock ~187 ~126 ~51 grass_block
setblock ~187 ~126 ~52 grass_block
setblock ~187 ~126 ~53 grass_block
setblock ~187 ~126 ~54 grass_block
setblock ~187 ~126 ~55 grass_block
setblock ~187 ~126 ~56 short_grass
setblock ~187 ~126 ~58 fern
setblock ~187 ~126 ~76 short_grass
setblock ~187 ~126 ~77 fern
setblock ~187 ~126 ~79 short_grass
setblock ~187 ~126 ~80 short_grass
setblock ~187 ~126 ~82 short_grass
setblock ~187 ~126 ~85 grass_block
setblock ~187 ~126 ~86 grass_block
setblock ~187 ~126 ~87 grass_block
setblock ~187 ~126 ~88 grass_block
setblock ~187 ~126 ~89 dirt
setblock ~187 ~126 ~90 dirt
setblock ~187 ~126 ~91 grass_block
setblock ~187 ~126 ~92 grass_block
setblock ~187 ~126 ~93 grass_block
setblock ~187 ~126 ~94 short_grass
setblock ~187 ~126 ~174 grass_block
setblock ~187 ~126 ~175 grass_block
setblock ~187 ~126 ~176 grass_block
setblock ~187 ~126 ~177 grass_block
setblock ~187 ~126 ~178 grass_block
setblock ~187 ~126 ~179 grass_block
setblock ~187 ~126 ~180 grass_block
setblock ~187 ~126 ~181 grass_block
setblock ~187 ~126 ~182 grass_block
setblock ~187 ~126 ~183 grass_block
setblock ~187 ~126 ~184 grass_block
setblock ~187 ~126 ~185 grass_block
setblock ~187 ~126 ~186 grass_block
setblock ~187 ~126 ~188 short_grass
setblock ~187 ~126 ~189 short_grass
setblock ~187 ~126 ~195 grass_block
setblock ~187 ~126 ~196 grass_block
setblock ~187 ~126 ~197 grass_block
setblock ~187 ~126 ~198 grass_block
setblock ~187 ~126 ~199 grass_block
setblock ~187 ~127 ~38 poppy
setblock ~187 ~127 ~42 grass_block
setblock ~187 ~127 ~43 grass_block
setblock ~187 ~127 ~44 grass_block
setblock ~187 ~127 ~45 grass_block
setblock ~187 ~127 ~46 grass_block
setblock ~187 ~127 ~47 grass_block
setblock ~187 ~127 ~48 grass_block
setblock ~187 ~127 ~49 grass_block
setblock ~187 ~127 ~50 grass_block
setblock ~187 ~127 ~85 short_grass
setblock ~187 ~127 ~88 short_grass
setblock ~187 ~127 ~89 grass_block
setblock ~187 ~127 ~90 grass_block
setblock ~187 ~127 ~91 short_grass
setblock ~187 ~127 ~174 short_grass
setblock ~187 ~127 ~175 short_grass
setblock ~187 ~127 ~176 short_grass
setblock ~187 ~127 ~178 short_grass
setblock ~187 ~127 ~180 short_grass
setblock ~187 ~127 ~182 short_grass
setblock ~187 ~127 ~185 poppy
setblock ~187 ~127 ~196 short_grass
setblock ~187 ~128 ~44 short_grass
setblock ~187 ~128 ~45 short_grass
setblock ~187 ~128 ~46 short_grass
setblock ~187 ~128 ~50 short_grass
setblock ~187 ~128 ~89 short_grass
setblock ~188 ~122 ~0 dirt
setblock ~188 ~122 ~1 dirt
setblock ~188 ~122 ~2 dirt
setblock ~188 ~122 ~3 dirt
setblock ~188 ~122 ~4 dirt
setblock ~188 ~122 ~5 dirt
setblock ~188 ~122 ~6 dirt
setblock ~188 ~122 ~7 dirt
setblock ~188 ~122 ~8 dirt
setblock ~188 ~122 ~9 dirt
setblock ~188 ~122 ~10 dirt
setblock ~188 ~122 ~11 dirt
setblock ~188 ~122 ~12 dirt
setblock ~188 ~122 ~13 dirt
setblock ~188 ~122 ~14 dirt
setblock ~188 ~122 ~15 dirt
setblock ~188 ~122 ~16 dirt
setblock ~188 ~122 ~17 dirt
setblock ~188 ~122 ~18 dirt
setblock ~188 ~122 ~19 dirt
setblock ~188 ~122 ~20 dirt
setblock ~188 ~122 ~21 dirt
setblock ~188 ~122 ~22 dirt
setblock ~188 ~122 ~23 dirt
setblock ~188 ~122 ~24 dirt
setblock ~188 ~122 ~25 dirt
setblock ~188 ~122 ~26 dirt
setblock ~188 ~122 ~27 dirt
setblock ~188 ~122 ~28 dirt
setblock ~188 ~122 ~29 dirt
setblock ~188 ~122 ~30 dirt
setblock ~188 ~122 ~31 dirt
setblock ~188 ~122 ~32 dirt
setblock ~188 ~122 ~33 dirt
setblock ~188 ~122 ~34 dirt
setblock ~188 ~122 ~35 dirt
setblock ~188 ~122 ~36 dirt
setblock ~188 ~122 ~37 dirt
setblock ~188 ~122 ~38 dirt
setblock ~188 ~122 ~39 dirt
setblock ~188 ~122 ~40 dirt
setblock ~188 ~122 ~41 dirt
setblock ~188 ~122 ~42 dirt
setblock ~188 ~122 ~43 dirt
setblock ~188 ~122 ~44 dirt
setblock ~188 ~122 ~45 dirt
setblock ~188 ~122 ~46 dirt
setblock ~188 ~122 ~47 dirt
setblock ~188 ~122 ~48 dirt
setblock ~188 ~122 ~49 dirt
setblock ~188 ~122 ~50 dirt
setblock ~188 ~122 ~51 dirt
setblock ~188 ~122 ~52 dirt
setblock ~188 ~122 ~53 dirt
setblock ~188 ~122 ~54 dirt
setblock ~188 ~122 ~55 dirt
setblock ~188 ~122 ~56 dirt
setblock ~188 ~122 ~57 dirt
setblock ~188 ~122 ~58 dirt
setblock ~188 ~122 ~59 dirt
setblock ~188 ~122 ~60 dirt
setblock ~188 ~122 ~61 dirt
setblock ~188 ~122 ~62 dirt
setblock ~188 ~122 ~63 dirt
setblock ~188 ~122 ~64 dirt
setblock ~188 ~122 ~65 dirt
setblock ~188 ~122 ~66 dirt
setblock ~188 ~122 ~67 dirt
setblock ~188 ~122 ~68 dirt
setblock ~188 ~122 ~69 dirt
setblock ~188 ~122 ~70 dirt
setblock ~188 ~122 ~71 dirt
setblock ~188 ~122 ~72 dirt
setblock ~188 ~122 ~73 dirt
setblock ~188 ~122 ~74 dirt
setblock ~188 ~122 ~75 dirt
setblock ~188 ~122 ~76 dirt
