setblock ~91 ~126 ~24 grass_block
setblock ~91 ~126 ~25 grass_block
setblock ~91 ~126 ~26 grass_block
setblock ~91 ~126 ~27 grass_block
setblock ~91 ~126 ~28 grass_block
setblock ~91 ~126 ~29 grass_block
setblock ~91 ~126 ~30 grass_block
setblock ~91 ~126 ~32 short_grass
setblock ~91 ~126 ~55 short_grass
setblock ~91 ~126 ~56 poppy
setblock ~91 ~126 ~90 short_grass
setblock ~91 ~126 ~97 short_grass
setblock ~91 ~126 ~99 short_grass
setblock ~91 ~126 ~122 short_grass
setblock ~91 ~126 ~125 grass_block
setblock ~91 ~126 ~126 grass_block
setblock ~91 ~126 ~127 grass_block
setblock ~91 ~126 ~128 dirt
setblock ~91 ~126 ~129 dirt
setblock ~91 ~126 ~130 dirt
setblock ~91 ~126 ~131 dirt
setblock ~91 ~126 ~132 dirt
setblock ~91 ~126 ~133 dirt
setblock ~91 ~126 ~134 grass_block
setblock ~91 ~126 ~135 grass_block
setblock ~91 ~126 ~136 grass_block
setblock ~91 ~126 ~137 grass_block
setblock ~91 ~126 ~138 grass_block
setblock ~91 ~126 ~139 grass_block
setblock ~91 ~126 ~141 short_grass
setblock ~91 ~126 ~154 short_grass
setblock ~91 ~126 ~155 grass_block
setblock ~91 ~126 ~156 grass_block
setblock ~91 ~126 ~157 grass_block
setblock ~91 ~126 ~158 dirt
setblock ~91 ~126 ~159 dirt
setblock ~91 ~126 ~160 dirt
setblock ~91 ~126 ~161 dirt
setblock ~91 ~126 ~162 grass_block
setblock ~91 ~126 ~163 grass_block
setblock ~91 ~126 ~165 short_grass
setblock ~91 ~126 ~181 short_grass
setblock ~91 ~126 ~183 grass_block
setblock ~91 ~126 ~184 grass_block
setblock ~91 ~126 ~185 dirt
setblock ~91 ~126 ~186 dirt
setblock ~91 ~126 ~187 dirt
setblock ~91 ~126 ~188 dirt
setblock ~91 ~126 ~189 dirt
setblock ~91 ~126 ~190 dirt
setblock ~91 ~126 ~191 dirt
setblock ~91 ~126 ~192 dirt
setblock ~91 ~126 ~193 dirt
setblock ~91 ~126 ~194 grass_block
setblock ~91 ~126 ~195 grass_block
setblock ~91 ~127 ~6 short_grass
setblock ~91 ~127 ~8 grass_block
setblock ~91 ~127 ~9 grass_block
setblock ~91 ~127 ~10 dirt
setblock ~91 ~127 ~11 grass_block
setblock ~91 ~127 ~12 grass_block
setblock ~91 ~127 ~13 grass_block
setblock ~91 ~127 ~14 grass_block
setblock ~91 ~127 ~15 grass_block
setblock ~91 ~127 ~16 grass_block
setblock ~91 ~127 ~17 grass_block
setblock ~91 ~127 ~18 grass_block
setblock ~91 ~127 ~26 short_grass
setblock ~91 ~127 ~29 fern
setblock ~91 ~127 ~125 short_grass
setblock ~91 ~127 ~128 grass_block
setblock ~91 ~127 ~129 grass_block
setblock ~91 ~127 ~130 dirt
setblock ~91 ~127 ~131 grass_block
setblock ~91 ~127 ~132 grass_block
setblock ~91 ~127 ~133 grass_block
setblock ~91 ~127 ~139 fern
setblock ~91 ~127 ~158 grass_block
setblock ~91 ~127 ~159 grass_block
setblock ~91 ~127 ~160 grass_block
setblock ~91 ~127 ~161 grass_block
setblock ~91 ~127 ~185 grass_block
setblock ~91 ~127 ~186 grass_block
setblock ~91 ~127 ~187 dirt
setblock ~91 ~127 ~188 dirt
setblock ~91 ~127 ~189 dirt
setblock ~91 ~127 ~190 dirt
setblock ~91 ~127 ~191 dirt
setblock ~91 ~127 ~192 dirt
setblock ~91 ~127 ~193 grass_block
setblock ~91 ~128 ~9 fern
setblock ~91 ~128 ~10 grass_block
setblock ~91 ~128 ~18 short_grass
setblock ~91 ~128 ~129 short_grass
setblock ~91 ~128 ~130 grass_block
setblock ~91 ~128 ~159 short_grass
setblock ~91 ~128 ~161 short_grass
setblock ~91 ~128 ~187 grass_block
setblock ~91 ~128 ~188 grass_block
setblock ~91 ~128 ~189 dirt
setblock ~91 ~128 ~190 dirt
setblock ~91 ~128 ~191 grass_block
setblock ~91 ~128 ~192 grass_block
setblock ~91 ~129 ~189 grass_block
setblock ~91 ~129 ~190 grass_block
setblock ~91 ~129 ~191 short_grass
setblock ~91 ~130 ~190 fern
setblock ~92 ~122 ~0 dirt
setblock ~92 ~122 ~1 dirt
setblock ~92 ~122 ~2 dirt
setblock ~92 ~122 ~3 dirt
setblock ~92 ~122 ~4 dirt
setblock ~92 ~122 ~5 dirt
setblock ~92 ~122 ~6 dirt
setblock ~92 ~122 ~7 dirt
setblock ~92 ~122 ~8 dirt
setblock ~92 ~122 ~9 dirt
setblock ~92 ~122 ~10 dirt
setblock ~92 ~122 ~11 dirt
setblock ~92 ~122 ~12 dirt
setblock ~92 ~122 ~13 dirt
setblock ~92 ~122 ~14 dirt
setblock ~92 ~122 ~15 dirt
setblock ~92 ~122 ~16 dirt
setblock ~92 ~122 ~17 dirt
setblock ~92 ~122 ~18 dirt
setblock ~92 ~122 ~19 dirt
setblock ~92 ~122 ~20 dirt
setblock ~92 ~122 ~21 dirt
setblock ~92 ~122 ~22 dirt
setblock ~92 ~122 ~23 dirt
setblock ~92 ~122 ~24 dirt
setblock ~92 ~122 ~25 dirt
setblock ~92 ~122 ~26 dirt
setblock ~92 ~122 ~27 dirt
setblock ~92 ~122 ~28 dirt
setblock ~92 ~122 ~29 dirt
setblock ~92 ~122 ~30 dirt
setblock ~92 ~122 ~31 dirt
setblock ~92 ~122 ~32 dirt
setblock ~92 ~122 ~33 dirt
setblock ~92 ~122 ~34 dirt
setblock ~92 ~122 ~35 dirt
setblock ~92 ~122 ~36 dirt
setblock ~92 ~122 ~37 dirt
setblock ~92 ~122 ~38 dirt
setblock ~92 ~122 ~39 dirt
setblock ~92 ~122 ~40 dirt
setblock ~92 ~122 ~41 dirt
setblock ~92 ~122 ~42 dirt
setblock ~92 ~122 ~43 dirt
setblock ~92 ~122 ~44 dirt
setblock ~92 ~122 ~45 dirt
setblock ~92 ~122 ~46 dirt
setblock ~92 ~122 ~47 dirt
setblock ~92 ~122 ~48 dirt
setblock ~92 ~122 ~49 dirt
setblock ~92 ~122 ~50 dirt
setblock ~92 ~122 ~51 dirt
setblock ~92 ~122 ~52 dirt
setblock ~92 ~122 ~53 dirt
setblock ~92 ~122 ~54 dirt
setblock ~92 ~122 ~55 dirt
setblock ~92 ~122 ~56 dirt
setblock ~92 ~122 ~57 dirt
setblock ~92 ~122 ~58 dirt
setblock ~92 ~122 ~59 dirt
setblock ~92 ~122 ~60 dirt
setblock ~92 ~122 ~61 dirt
setblock ~92 ~122 ~62 dirt
setblock ~92 ~122 ~63 dirt
setblock ~92 ~122 ~64 dirt
setblock ~92 ~122 ~65 dirt
setblock ~92 ~122 ~66 dirt
setblock ~92 ~122 ~67 dirt
setblock ~92 ~122 ~68 dirt
setblock ~92 ~122 ~69 grass_block
setblock ~92 ~122 ~70 grass_block
setblock ~92 ~122 ~71 grass_block
setblock ~92 ~122 ~72 grass_block
setblock ~92 ~122 ~73 dirt
setblock ~92 ~122 ~74 dirt
setblock ~92 ~122 ~75 dirt
setblock ~92 ~122 ~76 dirt
setblock ~92 ~122 ~77 dirt
setblock ~92 ~122 ~78 dirt
setblock ~92 ~122 ~79 dirt
setblock ~92 ~122 ~80 dirt
setblock ~92 ~122 ~81 dirt
setblock ~92 ~122 ~82 dirt
setblock ~92 ~122 ~83 dirt
setblock ~92 ~122 ~84 dirt
setblock ~92 ~122 ~85 dirt
setblock ~92 ~122 ~86 dirt
setblock ~92 ~122 ~87 dirt
setblock ~92 ~122 ~88 dirt
setblock ~92 ~122 ~89 dirt
setblock ~92 ~122 ~90 dirt
setblock ~92 ~122 ~91 dirt
setblock ~92 ~122 ~92 dirt
setblock ~92 ~122 ~93 dirt
setblock ~92 ~122 ~94 dirt
setblock ~92 ~122 ~95 dirt
setblock ~92 ~122 ~96 dirt
setblock ~92 ~122 ~97 dirt
setblock ~92 ~122 ~98 dirt
setblock ~92 ~122 ~99 dirt
setblock ~92 ~122 ~100 dirt
setblock ~92 ~122 ~101 dirt
setblock ~92 ~122 ~102 dirt
setblock ~92 ~122 ~103 dirt
setblock ~92 ~122 ~104 dirt
setblock ~92 ~122 ~105 dirt
setblock ~92 ~122 ~106 dirt
setblock ~92 ~122 ~107 dirt
setblock ~92 ~122 ~108 dirt
setblock ~92 ~122 ~109 dirt
setblock ~92 ~122 ~110 dirt
setblock ~92 ~122 ~111 dirt
setblock ~92 ~122 ~112 dirt
setblock ~92 ~122 ~113 dirt
setblock ~92 ~122 ~114 dirt
setblock ~92 ~122 ~115 dirt
setblock ~92 ~122 ~116 dirt
setblock ~92 ~122 ~117 dirt
setblock ~92 ~122 ~118 dirt
setblock ~92 ~122 ~119 dirt
setblock ~92 ~122 ~120 dirt
setblock ~92 ~122 ~121 dirt
setblock ~92 ~122 ~122 dirt
setblock ~92 ~122 ~123 dirt
setblock ~92 ~122 ~124 dirt
setblock ~92 ~122 ~125 dirt
setblock ~92 ~122 ~126 dirt
setblock ~92 ~122 ~127 dirt
setblock ~92 ~122 ~128 dirt
setblock ~92 ~122 ~129 dirt
setblock ~92 ~122 ~130 dirt
setblock ~92 ~122 ~131 dirt
setblock ~92 ~122 ~132 dirt
setblock ~92 ~122 ~133 dirt
setblock ~92 ~122 ~134 dirt
setblock ~92 ~122 ~135 dirt
setblock ~92 ~122 ~136 dirt
setblock ~92 ~122 ~137 dirt
setblock ~92 ~122 ~138 dirt
setblock ~92 ~122 ~139 dirt
setblock ~92 ~122 ~140 dirt
setblock ~92 ~122 ~141 dirt
setblock ~92 ~122 ~142 dirt
setblock ~92 ~122 ~143 dirt
setblock ~92 ~122 ~144 dirt
setblock ~92 ~122 ~145 dirt
setblock ~92 ~122 ~146 dirt
setblock ~92 ~122 ~147 dirt
setblock ~92 ~122 ~148 dirt
setblock ~92 ~122 ~149 dirt
setblock ~92 ~122 ~150 dirt
setblock ~92 ~122 ~151 dirt
setblock ~92 ~122 ~152 dirt
setblock ~92 ~122 ~153 dirt
setblock ~92 ~122 ~154 dirt
setblock ~92 ~122 ~155 dirt
setblock ~92 ~122 ~156 dirt
setblock ~92 ~122 ~157 dirt
setblock ~92 ~122 ~158 dirt
setblock ~92 ~122 ~159 dirt
setblock ~92 ~122 ~160 dirt
setblock ~92 ~122 ~161 dirt
setblock ~92 ~122 ~162 dirt
setblock ~92 ~122 ~163 dirt
setblock ~92 ~122 ~164 dirt
setblock ~92 ~122 ~165 dirt
setblock ~92 ~122 ~166 dirt
setblock ~92 ~122 ~167 dirt
setblock ~92 ~122 ~168 dirt
setblock ~92 ~122 ~169 dirt
setblock ~92 ~122 ~170 grass_block
setblock ~92 ~122 ~171 grass_block
setblock ~92 ~122 ~172 dirt
setblock ~92 ~122 ~173 dirt
setblock ~92 ~122 ~174 dirt
setblock ~92 ~122 ~175 dirt
setblock ~92 ~122 ~176 dirt
setblock ~92 ~122 ~177 dirt
setblock ~92 ~122 ~178 dirt
setblock ~92 ~122 ~179 dirt
setblock ~92 ~122 ~180 dirt
setblock ~92 ~122 ~181 dirt
setblock ~92 ~122 ~182 dirt
setblock ~92 ~122 ~183 dirt
setblock ~92 ~122 ~184 dirt
setblock ~92 ~122 ~185 dirt
setblock ~92 ~122 ~186 dirt
setblock ~92 ~122 ~187 dirt
setblock ~92 ~122 ~188 dirt
setblock ~92 ~122 ~189 dirt
setblock ~92 ~122 ~190 dirt
setblock ~92 ~122 ~191 dirt
setblock ~92 ~122 ~192 dirt
setblock ~92 ~122 ~193 dirt
setblock ~92 ~122 ~194 dirt
setblock ~92 ~122 ~195 dirt
setblock ~92 ~122 ~196 dirt
setblock ~92 ~122 ~197 dirt
setblock ~92 ~122 ~198 dirt
setblock ~92 ~122 ~199 dirt
setblock ~92 ~123 ~0 dirt
setblock ~92 ~123 ~1 dirt
setblock ~92 ~123 ~2 dirt
setblock ~92 ~123 ~3 dirt
setblock ~92 ~123 ~4 dirt
setblock ~92 ~123 ~5 dirt
setblock ~92 ~123 ~6 dirt
setblock ~92 ~123 ~7 dirt
setblock ~92 ~123 ~8 dirt
setblock ~92 ~123 ~9 dirt
setblock ~92 ~123 ~10 dirt
setblock ~92 ~123 ~11 dirt
setblock ~92 ~123 ~12 dirt
setblock ~92 ~123 ~13 dirt
setblock ~92 ~123 ~14 dirt
setblock ~92 ~123 ~15 dirt
setblock ~92 ~123 ~16 dirt
setblock ~92 ~123 ~17 dirt
setblock ~92 ~123 ~18 dirt
setblock ~92 ~123 ~19 dirt
setblock ~92 ~123 ~20 dirt
setblock ~92 ~123 ~21 dirt
setblock ~92 ~123 ~22 dirt
setblock ~92 ~123 ~23 dirt
setblock ~92 ~123 ~24 dirt
setblock ~92 ~123 ~25 dirt
setblock ~92 ~123 ~26 dirt
setblock ~92 ~123 ~27 dirt
setblock ~92 ~123 ~28 dirt
setblock ~92 ~123 ~29 dirt
setblock ~92 ~123 ~30 dirt
setblock ~92 ~123 ~31 dirt
setblock ~92 ~123 ~32 dirt
setblock ~92 ~123 ~33 dirt
setblock ~92 ~123 ~34 dirt
setblock ~92 ~123 ~35 dirt
setblock ~92 ~123 ~36 dirt
setblock ~92 ~123 ~37 dirt
setblock ~92 ~123 ~38 grass_block
setblock ~92 ~123 ~39 grass_block
setblock ~92 ~123 ~40 grass_block
setblock ~92 ~123 ~41 grass_block
setblock ~92 ~123 ~42 grass_block
setblock ~92 ~123 ~43 dirt
setblock ~92 ~123 ~44 dirt
setblock ~92 ~123 ~45 dirt
setblock ~92 ~123 ~46 dirt
setblock ~92 ~123 ~47 dirt
setblock ~92 ~123 ~48 dirt
setblock ~92 ~123 ~49 dirt
setblock ~92 ~123 ~50 dirt
setblock ~92 ~123 ~51 dirt
setblock ~92 ~123 ~52 dirt
setblock ~92 ~123 ~53 dirt
setblock ~92 ~123 ~54 dirt
setblock ~92 ~123 ~55 dirt
setblock ~92 ~123 ~56 dirt
setblock ~92 ~123 ~57 dirt
setblock ~92 ~123 ~58 dirt
setblock ~92 ~123 ~59 dirt
setblock ~92 ~123 ~60 dirt
setblock ~92 ~123 ~61 dirt
setblock ~92 ~123 ~62 dirt
setblock ~92 ~123 ~63 dirt
setblock ~92 ~123 ~64 grass_block
setblock ~92 ~123 ~65 grass_block
setblock ~92 ~123 ~66 grass_block
setblock ~92 ~123 ~67 grass_block
setblock ~92 ~123 ~68 grass_block
setblock ~92 ~123 ~70 short_grass
setblock ~92 ~123 ~73 grass_block
setblock ~92 ~123 ~74 grass_block
setblock ~92 ~123 ~75 grass_block
setblock ~92 ~123 ~76 grass_block
setblock ~92 ~123 ~77 grass_block
setblock ~92 ~123 ~78 grass_block
setblock ~92 ~123 ~79 grass_block
setblock ~92 ~123 ~80 grass_block
setblock ~92 ~123 ~81 dirt
setblock ~92 ~123 ~82 dirt
setblock ~92 ~123 ~83 dirt
setblock ~92 ~123 ~84 dirt
setblock ~92 ~123 ~85 dirt
setblock ~92 ~123 ~86 dirt
setblock ~92 ~123 ~87 dirt
setblock ~92 ~123 ~88 dirt
setblock ~92 ~123 ~89 dirt
setblock ~92 ~123 ~90 dirt
setblock ~92 ~123 ~91 dirt
setblock ~92 ~123 ~92 dirt
setblock ~92 ~123 ~93 dirt
setblock ~92 ~123 ~94 dirt
setblock ~92 ~123 ~95 dirt
setblock ~92 ~123 ~96 dirt
setblock ~92 ~123 ~97 dirt
setblock ~92 ~123 ~98 dirt
setblock ~92 ~123 ~99 dirt
setblock ~92 ~123 ~100 dirt
setblock ~92 ~123 ~101 dirt
setblock ~92 ~123 ~102 dirt
setblock ~92 ~123 ~103 dirt
setblock ~92 ~123 ~104 dirt
setblock ~92 ~123 ~105 dirt
setblock ~92 ~123 ~106 dirt
setblock ~92 ~123 ~107 dirt
setblock ~92 ~123 ~108 dirt
setblock ~92 ~123 ~109 dirt
setblock ~92 ~123 ~110 dirt
setblock ~92 ~123 ~111 dirt
setblock ~92 ~123 ~112 dirt
setblock ~92 ~123 ~113 dirt
setblock ~92 ~123 ~114 dirt
setblock ~92 ~123 ~115 dirt
setblock ~92 ~123 ~116 dirt
setblock ~92 ~123 ~117 dirt
setblock ~92 ~123 ~118 dirt
setblock ~92 ~123 ~119 dirt
setblock ~92 ~123 ~120 dirt
setblock ~92 ~123 ~121 dirt
setblock ~92 ~123 ~122 dirt
setblock ~92 ~123 ~123 dirt
setblock ~92 ~123 ~124 dirt
setblock ~92 ~123 ~125 dirt
setblock ~92 ~123 ~126 dirt
setblock ~92 ~123 ~127 dirt
setblock ~92 ~123 ~128 dirt
setblock ~92 ~123 ~129 dirt
setblock ~92 ~123 ~130 dirt
setblock ~92 ~123 ~131 dirt
setblock ~92 ~123 ~132 dirt
setblock ~92 ~123 ~133 dirt
setblock ~92 ~123 ~134 dirt
setblock ~92 ~123 ~135 dirt
setblock ~92 ~123 ~136 dirt
setblock ~92 ~123 ~137 dirt
setblock ~92 ~123 ~138 dirt
setblock ~92 ~123 ~139 dirt
setblock ~92 ~123 ~140 dirt
setblock ~92 ~123 ~141 dirt
setblock ~92 ~123 ~142 dirt
setblock ~92 ~123 ~143 dirt
setblock ~92 ~123 ~144 dirt
setblock ~92 ~123 ~145 dirt
setblock ~92 ~123 ~146 dirt
setblock ~92 ~123 ~147 dirt
setblock ~92 ~123 ~148 dirt
setblock ~92 ~123 ~149 dirt
setblock ~92 ~123 ~150 dirt
setblock ~92 ~123 ~151 dirt
setblock ~92 ~123 ~152 dirt
setblock ~92 ~123 ~153 dirt
setblock ~92 ~123 ~154 dirt
setblock ~92 ~123 ~155 dirt
setblock ~92 ~123 ~156 dirt
setblock ~92 ~123 ~157 dirt
setblock ~92 ~123 ~158 dirt
setblock ~92 ~123 ~159 dirt
setblock ~92 ~123 ~160 dirt
setblock ~92 ~123 ~161 dirt
setblock ~92 ~123 ~162 dirt
setblock ~92 ~123 ~163 dirt
setblock ~92 ~123 ~164 dirt
setblock ~92 ~123 ~165 dirt
setblock ~92 ~123 ~166 dirt
setblock ~92 ~123 ~167 dirt
setblock ~92 ~123 ~168 grass_block
setblock ~92 ~123 ~169 grass_block
setblock ~92 ~123 ~170 short_grass
setblock ~92 ~123 ~172 grass_block
setblock ~92 ~123 ~173 grass_block
setblock ~92 ~123 ~174 grass_block
setblock ~92 ~123 ~175 grass_block
setblock ~92 ~123 ~176 grass_block
setblock ~92 ~123 ~177 dirt
setblock ~92 ~123 ~178 dirt
setblock ~92 ~123 ~179 dirt
setblock ~92 ~123 ~180 dirt
setblock ~92 ~123 ~181 dirt
setblock ~92 ~123 ~182 dirt
setblock ~92 ~123 ~183 dirt
setblock ~92 ~123 ~184 dirt
setblock ~92 ~123 ~185 dirt
setblock ~92 ~123 ~186 dirt
setblock ~92 ~123 ~187 dirt
setblock ~92 ~123 ~188 dirt
setblock ~92 ~123 ~189 dirt
setblock ~92 ~123 ~190 dirt
setblock ~92 ~123 ~191 dirt
setblock ~92 ~123 ~192 dirt
setblock ~92 ~123 ~193 dirt
setblock ~92 ~123 ~194 dirt
setblock ~92 ~123 ~195 dirt
setblock ~92 ~123 ~196 dirt
setblock ~92 ~123 ~197 dirt
setblock ~92 ~123 ~198 dirt
setblock ~92 ~123 ~199 grass_block
setblock ~92 ~124 ~0 grass_block
setblock ~92 ~124 ~1 grass_block
setblock ~92 ~124 ~2 grass_block
setblock ~92 ~124 ~3 dirt
setblock ~92 ~124 ~4 dirt
setblock ~92 ~124 ~5 dirt
setblock ~92 ~124 ~6 dirt
setblock ~92 ~124 ~7 dirt
setblock ~92 ~124 ~8 dirt
setblock ~92 ~124 ~9 dirt
setblock ~92 ~124 ~10 dirt
setblock ~92 ~124 ~11 dirt
setblock ~92 ~124 ~12 dirt
setblock ~92 ~124 ~13 dirt
setblock ~92 ~124 ~14 dirt
setblock ~92 ~124 ~15 dirt
setblock ~92 ~124 ~16 dirt
setblock ~92 ~124 ~17 dirt
setblock ~92 ~124 ~18 dirt
setblock ~92 ~124 ~19 dirt
setblock ~92 ~124 ~20 dirt
setblock ~92 ~124 ~21 dirt
setblock ~92 ~124 ~22 dirt
setblock ~92 ~124 ~23 dirt
setblock ~92 ~124 ~24 dirt
setblock ~92 ~124 ~25 dirt
setblock ~92 ~124 ~26 dirt
setblock ~92 ~124 ~27 dirt
setblock ~92 ~124 ~28 dirt
setblock ~92 ~124 ~29 dirt
setblock ~92 ~124 ~30 dirt
setblock ~92 ~124 ~31 dirt
setblock ~92 ~124 ~32 dirt
setblock ~92 ~124 ~33 dirt
setblock ~92 ~124 ~34 grass_block
setblock ~92 ~124 ~35 grass_block
setblock ~92 ~124 ~36 grass_block
setblock ~92 ~124 ~37 grass_block
setblock ~92 ~124 ~42 short_grass
setblock ~92 ~124 ~43 grass_block
setblock ~92 ~124 ~44 grass_block
setblock ~92 ~124 ~45 grass_block
setblock ~92 ~124 ~46 grass_block
setblock ~92 ~124 ~47 grass_block
setblock ~92 ~124 ~48 dirt
setblock ~92 ~124 ~49 dirt
setblock ~92 ~124 ~50 dirt
setblock ~92 ~124 ~51 dirt
setblock ~92 ~124 ~52 dirt
setblock ~92 ~124 ~53 dirt
setblock ~92 ~124 ~54 dirt
setblock ~92 ~124 ~55 dirt
setblock ~92 ~124 ~56 dirt
setblock ~92 ~124 ~57 dirt
setblock ~92 ~124 ~58 dirt
setblock ~92 ~124 ~59 grass_block
setblock ~92 ~124 ~60 grass_block
setblock ~92 ~124 ~61 grass_block
setblock ~92 ~124 ~62 grass_block
setblock ~92 ~124 ~63 grass_block
setblock ~92 ~124 ~76 short_grass
setblock ~92 ~124 ~80 short_grass
setblock ~92 ~124 ~81 grass_block
setblock ~92 ~124 ~82 grass_block
setblock ~92 ~124 ~83 grass_block
setblock ~92 ~124 ~84 grass_block
setblock ~92 ~124 ~85 grass_block
setblock ~92 ~124 ~86 grass_block
setblock ~92 ~124 ~87 grass_block
setblock ~92 ~124 ~88 grass_block
setblock ~92 ~124 ~89 grass_block
setblock ~92 ~124 ~90 grass_block
setblock ~92 ~124 ~91 dirt
setblock ~92 ~124 ~92 dirt
setblock ~92 ~124 ~93 dirt
setblock ~92 ~124 ~94 dirt
setblock ~92 ~124 ~95 dirt
setblock ~92 ~124 ~96 dirt
setblock ~92 ~124 ~97 dirt
setblock ~92 ~124 ~98 dirt
setblock ~92 ~124 ~99 dirt
setblock ~92 ~124 ~100 dirt
setblock ~92 ~124 ~101 dirt
setblock ~92 ~124 ~102 dirt
setblock ~92 ~124 ~103 dirt
setblock ~92 ~124 ~104 dirt
setblock ~92 ~124 ~105 dirt
setblock ~92 ~124 ~106 dirt
setblock ~92 ~124 ~107 dirt
setblock ~92 ~124 ~108 grass_block
setblock ~92 ~124 ~109 grass_block
setblock ~92 ~124 ~110 grass_block
setblock ~92 ~124 ~111 grass_block
setblock ~92 ~124 ~112 grass_block
setblock ~92 ~124 ~113 grass_block
setblock ~92 ~124 ~114 grass_block
setblock ~92 ~124 ~115 grass_block
setblock ~92 ~124 ~116 grass_block
setblock ~92 ~124 ~117 grass_block
setblock ~92 ~124 ~118 grass_block
setblock ~92 ~124 ~119 grass_block
setblock ~92 ~124 ~120 grass_block
setblock ~92 ~124 ~121 grass_block
setblock ~92 ~124 ~122 grass_block
setblock ~92 ~124 ~123 dirt
setblock ~92 ~124 ~124 dirt
setblock ~92 ~124 ~125 dirt
setblock ~92 ~124 ~126 dirt
setblock ~92 ~124 ~127 dirt
setblock ~92 ~124 ~128 dirt
setblock ~92 ~124 ~129 dirt
setblock ~92 ~124 ~130 dirt
setblock ~92 ~124 ~131 dirt
setblock ~92 ~124 ~132 dirt
setblock ~92 ~124 ~133 dirt
setblock ~92 ~124 ~134 dirt
setblock ~92 ~124 ~135 dirt
setblock ~92 ~124 ~136 dirt
setblock ~92 ~124 ~137 dirt
setblock ~92 ~124 ~138 dirt
setblock ~92 ~124 ~139 dirt
setblock ~92 ~124 ~140 dirt
setblock ~92 ~124 ~141 dirt
setblock ~92 ~124 ~142 dirt
setblock ~92 ~124 ~143 dirt
setblock ~92 ~124 ~144 dirt
setblock ~92 ~124 ~145 dirt
setblock ~92 ~124 ~146 dirt
setblock ~92 ~124 ~147 dirt
setblock ~92 ~124 ~148 grass_block
setblock ~92 ~124 ~149 grass_block
setblock ~92 ~124 ~150 grass_block
setblock ~92 ~124 ~151 grass_block
setblock ~92 ~124 ~152 dirt
setblock ~92 ~124 ~153 dirt
setblock ~92 ~124 ~154 dirt
setblock ~92 ~124 ~155 dirt
setblock ~92 ~124 ~156 dirt
setblock ~92 ~124 ~157 dirt
setblock ~92 ~124 ~158 dirt
setblock ~92 ~124 ~159 dirt
setblock ~92 ~124 ~160 dirt
setblock ~92 ~124 ~161 dirt
setblock ~92 ~124 ~162 dirt
setblock ~92 ~124 ~163 dirt
setblock ~92 ~124 ~164 dirt
setblock ~92 ~124 ~165 dirt
setblock ~92 ~124 ~166 grass_block
setblock ~92 ~124 ~167 grass_block
setblock ~92 ~124 ~172 poppy
setblock ~92 ~124 ~174 short_grass
setblock ~92 ~124 ~175 short_grass
setblock ~92 ~124 ~177 grass_block
setblock ~92 ~124 ~178 grass_block
setblock ~92 ~124 ~179 grass_block
setblock ~92 ~124 ~180 grass_block
setblock ~92 ~124 ~181 dirt
setblock ~92 ~124 ~182 dirt
setblock ~92 ~124 ~183 dirt
setblock ~92 ~124 ~184 dirt
setblock ~92 ~124 ~185 dirt
setblock ~92 ~124 ~186 dirt
setblock ~92 ~124 ~187 dirt
setblock ~92 ~124 ~188 dirt
setblock ~92 ~124 ~189 dirt
setblock ~92 ~124 ~190 dirt
setblock ~92 ~124 ~191 dirt
setblock ~92 ~124 ~192 dirt
setblock ~92 ~124 ~193 dirt
setblock ~92 ~124 ~194 dirt
setblock ~92 ~124 ~195 dirt
setblock ~92 ~124 ~196 dirt
setblock ~92 ~124 ~197 grass_block
setblock ~92 ~124 ~198 grass_block
setblock ~92 ~125 ~0 short_grass
setblock ~92 ~125 ~1 short_grass
setblock ~92 ~125 ~2 short_grass
setblock ~92 ~125 ~3 grass_block
setblock ~92 ~125 ~4 grass_block
setblock ~92 ~125 ~5 grass_block
setblock ~92 ~125 ~6 dirt
setblock ~92 ~125 ~7 dirt
setblock ~92 ~125 ~8 dirt
setblock ~92 ~125 ~9 dirt
setblock ~92 ~125 ~10 dirt
setblock ~92 ~125 ~11 dirt
setblock ~92 ~125 ~12 dirt
setblock ~92 ~125 ~13 dirt
setblock ~92 ~125 ~14 dirt
setblock ~92 ~125 ~15 dirt
setblock ~92 ~125 ~16 dirt
setblock ~92 ~125 ~17 dirt
setblock ~92 ~125 ~18 dirt
setblock ~92 ~125 ~19 dirt
setblock ~92 ~125 ~20 dirt
setblock ~92 ~125 ~21 dirt
setblock ~92 ~125 ~22 dirt
setblock ~92 ~125 ~23 dirt
setblock ~92 ~125 ~24 dirt
setblock ~92 ~125 ~25 dirt
setblock ~92 ~125 ~26 dirt
setblock ~92 ~125 ~27 dirt
setblock ~92 ~125 ~28 dirt
setblock ~92 ~125 ~29 dirt
setblock ~92 ~125 ~30 dirt
setblock ~92 ~125 ~31 grass_block
setblock ~92 ~125 ~32 grass_block
setblock ~92 ~125 ~33 grass_block
setblock ~92 ~125 ~36 short_grass
setblock ~92 ~125 ~37 short_grass
setblock ~92 ~125 ~47 short_grass
setblock ~92 ~125 ~48 grass_block
setblock ~92 ~125 ~49 grass_block
setblock ~92 ~125 ~50 grass_block
setblock ~92 ~125 ~51 grass_block
setblock ~92 ~125 ~52 grass_block
setblock ~92 ~125 ~53 grass_block
setblock ~92 ~125 ~54 grass_block
setblock ~92 ~125 ~55 grass_block
setblock ~92 ~125 ~56 grass_block
setblock ~92 ~125 ~57 grass_block
setblock ~92 ~125 ~58 grass_block
setblock ~92 ~125 ~59 short_grass
setblock ~92 ~125 ~60 poppy
setblock ~92 ~125 ~61 short_grass
setblock ~92 ~125 ~63 short_grass
setblock ~92 ~125 ~88 poppy
setblock ~92 ~125 ~91 grass_block
setblock ~92 ~125 ~92 grass_block
setblock ~92 ~125 ~93 grass_block
setblock ~92 ~125 ~94 grass_block
setblock ~92 ~125 ~95 grass_block
setblock ~92 ~125 ~96 grass_block
setblock ~92 ~125 ~97 grass_block
setblock ~92 ~125 ~98 grass_block
setblock ~92 ~125 ~99 grass_block
setblock ~92 ~125 ~100 grass_block
setblock ~92 ~125 ~101 grass_block
setblock ~92 ~125 ~102 grass_block
setblock ~92 ~125 ~103 grass_block
setblock ~92 ~125 ~104 grass_block
setblock ~92 ~125 ~105 grass_block
setblock ~92 ~125 ~106 grass_block
setblock ~92 ~125 ~107 grass_block
setblock ~92 ~125 ~108 short_grass
setblock ~92 ~125 ~110 short_grass
setblock ~92 ~125 ~113 short_grass
setblock ~92 ~125 ~118 short_grass
setblock ~92 ~125 ~120 short_grass
setblock ~92 ~125 ~123 grass_block
setblock ~92 ~125 ~124 grass_block
setblock ~92 ~125 ~125 grass_block
setblock ~92 ~125 ~126 dirt
setblock ~92 ~125 ~127 dirt
setblock ~92 ~125 ~128 dirt
setblock ~92 ~125 ~129 dirt
setblock ~92 ~125 ~130 dirt
setblock ~92 ~125 ~131 dirt
setblock ~92 ~125 ~132 dirt
setblock ~92 ~125 ~133 dirt
setblock ~92 ~125 ~134 dirt
setblock ~92 ~125 ~135 dirt
setblock ~92 ~125 ~136 dirt
setblock ~92 ~125 ~137 dirt
setblock ~92 ~125 ~138 dirt
setblock ~92 ~125 ~139 dirt
setblock ~92 ~125 ~140 dirt
setblock ~92 ~125 ~141 dirt
setblock ~92 ~125 ~142 grass_block
setblock ~92 ~125 ~143 grass_block
setblock ~92 ~125 ~144 grass_block
setblock ~92 ~125 ~145 grass_block
setblock ~92 ~125 ~146 grass_block
setblock ~92 ~125 ~147 grass_block
setblock ~92 ~125 ~152 grass_block
setblock ~92 ~125 ~153 grass_block
setblock ~92 ~125 ~154 grass_block
setblock ~92 ~125 ~155 dirt
setblock ~92 ~125 ~156 dirt
setblock ~92 ~125 ~157 dirt
setblock ~92 ~125 ~158 dirt
setblock ~92 ~125 ~159 dirt
setblock ~92 ~125 ~160 dirt
setblock ~92 ~125 ~161 dirt
setblock ~92 ~125 ~162 dirt
setblock ~92 ~125 ~163 dirt
setblock ~92 ~125 ~164 grass_block
setblock ~92 ~125 ~165 grass_block
setblock ~92 ~125 ~181 grass_block
setblock ~92 ~125 ~182 grass_block
setblock ~92 ~125 ~183 dirt
setblock ~92 ~125 ~184 dirt
setblock ~92 ~125 ~185 dirt
setblock ~92 ~125 ~186 dirt
setblock ~92 ~125 ~187 dirt
setblock ~92 ~125 ~188 dirt
setblock ~92 ~125 ~189 dirt
setblock ~92 ~125 ~190 dirt
setblock ~92 ~125 ~191 dirt
setblock ~92 ~125 ~192 dirt
setblock ~92 ~125 ~193 dirt
setblock ~92 ~125 ~194 dirt
setblock ~92 ~125 ~195 grass_block
setblock ~92 ~125 ~196 grass_block
setblock ~92 ~126 ~6 grass_block
setblock ~92 ~126 ~7 grass_block
setblock ~92 ~126 ~8 grass_block
setblock ~92 ~126 ~9 dirt
setblock ~92 ~126 ~10 dirt
setblock ~92 ~126 ~11 dirt
setblock ~92 ~126 ~12 dirt
setblock ~92 ~126 ~13 dirt
setblock ~92 ~126 ~14 dirt
setblock ~92 ~126 ~15 dirt
setblock ~92 ~126 ~16 dirt
setblock ~92 ~126 ~17 grass_block
setblock ~92 ~126 ~18 grass_block
setblock ~92 ~126 ~19 grass_block
setblock ~92 ~126 ~20 grass_block
setblock ~92 ~126 ~21 grass_block
setblock ~92 ~126 ~22 grass_block
setblock ~92 ~126 ~23 grass_block
setblock ~92 ~126 ~24 grass_block
setblock ~92 ~126 ~25 grass_block
setblock ~92 ~126 ~26 grass_block
setblock ~92 ~126 ~27 grass_block
setblock ~92 ~126 ~28 grass_block
setblock ~92 ~126 ~29 grass_block
setblock ~92 ~126 ~30 grass_block
setblock ~92 ~126 ~31 short_grass
setblock ~92 ~126 ~48 short_grass
setblock ~92 ~126 ~52 short_grass
setblock ~92 ~126 ~53 fern
setblock ~92 ~126 ~55 poppy
setblock ~92 ~126 ~58 short_grass
setblock ~92 ~126 ~95 short_grass
setblock ~92 ~126 ~96 short_grass
setblock ~92 ~126 ~105 short_grass
setblock ~92 ~126 ~125 poppy
setblock ~92 ~126 ~126 grass_block
setblock ~92 ~126 ~127 grass_block
setblock ~92 ~126 ~128 grass_block
setblock ~92 ~126 ~129 grass_block
setblock ~92 ~126 ~130 dirt
setblock ~92 ~126 ~131 dirt
setblock ~92 ~126 ~132 grass_block
setblock ~92 ~126 ~133 grass_block
setblock ~92 ~126 ~134 grass_block
setblock ~92 ~126 ~135 grass_block
setblock ~92 ~126 ~136 grass_block
setblock ~92 ~126 ~137 grass_block
setblock ~92 ~126 ~138 grass_block
setblock ~92 ~126 ~139 grass_block
setblock ~92 ~126 ~140 grass_block
setblock ~92 ~126 ~141 grass_block
setblock ~92 ~126 ~143 short_grass
setblock ~92 ~126 ~144 fern
setblock ~92 ~126 ~155 grass_block
setblock ~92 ~126 ~156 grass_block
setblock ~92 ~126 ~157 grass_block
setblock ~92 ~126 ~158 grass_block
setblock ~92 ~126 ~159 dirt
setblock ~92 ~126 ~160 dirt
setblock ~92 ~126 ~161 grass_block
setblock ~92 ~126 ~162 grass_block
setblock ~92 ~126 ~163 grass_block
setblock ~92 ~126 ~183 grass_block
setblock ~92 ~126 ~184 grass_block
setblock ~92 ~126 ~185 dirt
setblock ~92 ~126 ~186 dirt
setblock ~92 ~126 ~187 dirt
setblock ~92 ~126 ~188 dirt
setblock ~92 ~126 ~189 dirt
setblock ~92 ~126 ~190 dirt
setblock ~92 ~126 ~191 dirt
setblock ~92 ~126 ~192 dirt
setblock ~92 ~126 ~193 dirt
setblock ~92 ~126 ~194 grass_block
setblock ~92 ~126 ~196 short_grass
setblock ~92 ~127 ~7 short_grass
setblock ~92 ~127 ~8 poppy
setblock ~92 ~127 ~9 grass_block
setblock ~92 ~127 ~10 grass_block
setblock ~92 ~127 ~11 grass_block
setblock ~92 ~127 ~12 grass_block
setblock ~92 ~127 ~13 grass_block
setblock ~92 ~127 ~14 grass_block
setblock ~92 ~127 ~15 grass_block
setblock ~92 ~127 ~16 grass_block
setblock ~92 ~127 ~19 short_grass
setblock ~92 ~127 ~27 short_grass
setblock ~92 ~127 ~30 short_grass
setblock ~92 ~127 ~126 short_grass
setblock ~92 ~127 ~130 grass_block
setblock ~92 ~127 ~131 grass_block
setblock ~92 ~127 ~132 short_grass
setblock ~92 ~127 ~133 poppy
setblock ~92 ~127 ~135 short_grass
setblock ~92 ~127 ~137 short_grass
setblock ~92 ~127 ~138 fern
setblock ~92 ~127 ~157 fern
setblock ~92 ~127 ~159 grass_block
setblock ~92 ~127 ~160 grass_block
setblock ~92 ~127 ~161 short_grass
setblock ~92 ~127 ~185 grass_block
setblock ~92 ~127 ~186 grass_block
setblock ~92 ~127 ~187 grass_block
setblock ~92 ~127 ~188 dirt
setblock ~92 ~127 ~189 dirt
setblock ~92 ~127 ~190 dirt
setblock ~92 ~127 ~191 dirt
setblock ~92 ~127 ~192 grass_block
setblock ~92 ~127 ~193 grass_block
setblock ~92 ~127 ~194 poppy
setblock ~92 ~128 ~10 short_grass
setblock ~92 ~128 ~12 poppy
setblock ~92 ~128 ~13 fern
setblock ~92 ~128 ~14 short_grass
setblock ~92 ~128 ~159 short_grass
setblock ~92 ~128 ~185 short_grass
setblock ~92 ~128 ~188 grass_block
setblock ~92 ~128 ~189 grass_block
setblock ~92 ~128 ~190 grass_block
setblock ~92 ~128 ~191 grass_block
setblock ~92 ~128 ~192 short_grass
setblock ~92 ~129 ~188 short_grass
setblock ~92 ~129 ~190 short_grass
setblock ~92 ~129 ~191 short_grass
setblock ~93 ~122 ~0 dirt
setblock ~93 ~122 ~1 dirt
setblock ~93 ~122 ~2 dirt
setblock ~93 ~122 ~3 dirt
setblock ~93 ~122 ~4 dirt
setblock ~93 ~122 ~5 dirt
setblock ~93 ~122 ~6 dirt
setblock ~93 ~122 ~7 dirt
setblock ~93 ~122 ~8 dirt
setblock ~93 ~122 ~9 dirt
setblock ~93 ~122 ~10 dirt
setblock ~93 ~122 ~11 dirt
setblock ~93 ~122 ~12 dirt
setblock ~93 ~122 ~13 dirt
setblock ~93 ~122 ~14 dirt
setblock ~93 ~122 ~15 dirt
setblock ~93 ~122 ~16 dirt
setblock ~93 ~122 ~17 dirt
setblock ~93 ~122 ~18 dirt
setblock ~93 ~122 ~19 dirt
setblock ~93 ~122 ~20 dirt
setblock ~93 ~122 ~21 dirt
setblock ~93 ~122 ~22 dirt
setblock ~93 ~122 ~23 dirt
setblock ~93 ~122 ~24 dirt
setblock ~93 ~122 ~25 dirt
setblock ~93 ~122 ~26 dirt
setblock ~93 ~122 ~27 dirt
setblock ~93 ~122 ~28 dirt
setblock ~93 ~122 ~29 dirt
setblock ~93 ~122 ~30 dirt
setblock ~93 ~122 ~31 dirt
setblock ~93 ~122 ~32 dirt
setblock ~93 ~122 ~33 dirt
setblock ~93 ~122 ~34 dirt
setblock ~93 ~122 ~35 dirt
setblock ~93 ~122 ~36 dirt
setblock ~93 ~122 ~37 dirt
setblock ~93 ~122 ~38 dirt
setblock ~93 ~122 ~39 dirt
setblock ~93 ~122 ~40 dirt
setblock ~93 ~122 ~41 dirt
setblock ~93 ~122 ~42 dirt
setblock ~93 ~122 ~43 dirt
setblock ~93 ~122 ~44 dirt
setblock ~93 ~122 ~45 dirt
setblock ~93 ~122 ~46 dirt
setblock ~93 ~122 ~47 dirt
setblock ~93 ~122 ~48 dirt
setblock ~93 ~122 ~49 dirt
setblock ~93 ~122 ~50 dirt
setblock ~93 ~122 ~51 dirt
setblock ~93 ~122 ~52 dirt
setblock ~93 ~122 ~53 dirt
setblock ~93 ~122 ~54 dirt
setblock ~93 ~122 ~55 dirt
setblock ~93 ~122 ~56 dirt
setblock ~93 ~122 ~57 dirt
setblock ~93 ~122 ~58 dirt
setblock ~93 ~122 ~59 dirt
setblock ~93 ~122 ~60 dirt
setblock ~93 ~122 ~61 dirt
setblock ~93 ~122 ~62 dirt
setblock ~93 ~122 ~63 dirt
setblock ~93 ~122 ~64 dirt
setblock ~93 ~122 ~65 dirt
setblock ~93 ~122 ~66 dirt
setblock ~93 ~122 ~67 dirt
setblock ~93 ~122 ~68 dirt
setblock ~93 ~122 ~69 dirt
setblock ~93 ~122 ~70 grass_block
setblock ~93 ~122 ~71 grass_block
setblock ~93 ~122 ~72 dirt
setblock ~93 ~122 ~73 dirt
setblock ~93 ~122 ~74 dirt
setblock ~93 ~122 ~75 dirt
setblock ~93 ~122 ~76 dirt
setblock ~93 ~122 ~77 dirt
setblock ~93 ~122 ~78 dirt
setblock ~93 ~122 ~79 dirt
setblock ~93 ~122 ~80 dirt
setblock ~93 ~122 ~81 dirt
setblock ~93 ~122 ~82 dirt
setblock ~93 ~122 ~83 dirt
setblock ~93 ~122 ~84 dirt
setblock ~93 ~122 ~85 dirt
setblock ~93 ~122 ~86 dirt
setblock ~93 ~122 ~87 dirt
setblock ~93 ~122 ~88 dirt
setblock ~93 ~122 ~89 dirt
setblock ~93 ~122 ~90 dirt
setblock ~93 ~122 ~91 dirt
setblock ~93 ~122 ~92 dirt
setblock ~93 ~122 ~93 dirt
setblock ~93 ~122 ~94 dirt
setblock ~93 ~122 ~95 dirt
setblock ~93 ~122 ~96 dirt
setblock ~93 ~122 ~97 dirt
setblock ~93 ~122 ~98 dirt
setblock ~93 ~122 ~99 dirt
setblock ~93 ~122 ~100 dirt
setblock ~93 ~122 ~101 dirt
setblock ~93 ~122 ~102 dirt
setblock ~93 ~122 ~103 dirt
setblock ~93 ~122 ~104 dirt
setblock ~93 ~122 ~105 dirt
setblock ~93 ~122 ~106 dirt
setblock ~93 ~122 ~107 dirt
setblock ~93 ~122 ~108 dirt
setblock ~93 ~122 ~109 dirt
setblock ~93 ~122 ~110 dirt
setblock ~93 ~122 ~111 dirt
setblock ~93 ~122 ~112 dirt
setblock ~93 ~122 ~113 dirt
setblock ~93 ~122 ~114 dirt
setblock ~93 ~122 ~115 dirt
setblock ~93 ~122 ~116 dirt
setblock ~93 ~122 ~117 dirt
setblock ~93 ~122 ~118 dirt
setblock ~93 ~122 ~119 dirt
setblock ~93 ~122 ~120 dirt
setblock ~93 ~122 ~121 dirt
setblock ~93 ~122 ~122 dirt
setblock ~93 ~122 ~123 dirt
setblock ~93 ~122 ~124 dirt
setblock ~93 ~122 ~125 dirt
setblock ~93 ~122 ~126 dirt
setblock ~93 ~122 ~127 dirt
setblock ~93 ~122 ~128 dirt
setblock ~93 ~122 ~129 dirt
setblock ~93 ~122 ~130 dirt
setblock ~93 ~122 ~131 dirt
setblock ~93 ~122 ~132 dirt
setblock ~93 ~122 ~133 dirt
setblock ~93 ~122 ~134 dirt
setblock ~93 ~122 ~135 dirt
setblock ~93 ~122 ~136 dirt
setblock ~93 ~122 ~137 dirt
setblock ~93 ~122 ~138 dirt
setblock ~93 ~122 ~139 dirt
setblock ~93 ~122 ~140 dirt
setblock ~93 ~122 ~141 dirt
setblock ~93 ~122 ~142 dirt
setblock ~93 ~122 ~143 dirt
setblock ~93 ~122 ~144 dirt
setblock ~93 ~122 ~145 dirt
setblock ~93 ~122 ~146 dirt
setblock ~93 ~122 ~147 dirt
setblock ~93 ~122 ~148 dirt
setblock ~93 ~122 ~149 dirt
setblock ~93 ~122 ~150 dirt
setblock ~93 ~122 ~151 dirt
setblock ~93 ~122 ~152 dirt
setblock ~93 ~122 ~153 dirt
setblock ~93 ~122 ~154 dirt
setblock ~93 ~122 ~155 dirt
setblock ~93 ~122 ~156 dirt
setblock ~93 ~122 ~157 dirt
setblock ~93 ~122 ~158 dirt
setblock ~93 ~122 ~159 dirt
setblock ~93 ~122 ~160 dirt
setblock ~93 ~122 ~161 dirt
setblock ~93 ~122 ~162 dirt
setblock ~93 ~122 ~163 dirt
setblock ~93 ~122 ~164 dirt
setblock ~93 ~122 ~165 dirt
setblock ~93 ~122 ~166 dirt
setblock ~93 ~122 ~167 dirt
setblock ~93 ~122 ~168 dirt
setblock ~93 ~122 ~169 dirt
setblock ~93 ~122 ~170 grass_block
setblock ~93 ~122 ~171 grass_block
setblock ~93 ~122 ~172 dirt
setblock ~93 ~122 ~173 dirt
setblock ~93 ~122 ~174 dirt
setblock ~93 ~122 ~175 dirt
setblock ~93 ~122 ~176 dirt
setblock ~93 ~122 ~177 dirt
setblock ~93 ~122 ~178 dirt
setblock ~93 ~122 ~179 dirt
setblock ~93 ~122 ~180 dirt
setblock ~93 ~122 ~181 dirt
setblock ~93 ~122 ~182 dirt
setblock ~93 ~122 ~183 dirt
setblock ~93 ~122 ~184 dirt
setblock ~93 ~122 ~185 dirt
setblock ~93 ~122 ~186 dirt
setblock ~93 ~122 ~187 dirt
setblock ~93 ~122 ~188 dirt
setblock ~93 ~122 ~189 dirt
setblock ~93 ~122 ~190 dirt
setblock ~93 ~122 ~191 dirt
setblock ~93 ~122 ~192 dirt
setblock ~93 ~122 ~193 dirt
setblock ~93 ~122 ~194 dirt
setblock ~93 ~122 ~195 dirt
setblock ~93 ~122 ~196 dirt
setblock ~93 ~122 ~197 dirt
setblock ~93 ~122 ~198 dirt
setblock ~93 ~122 ~199 dirt
setblock ~93 ~123 ~0 dirt
setblock ~93 ~123 ~1 dirt
setblock ~93 ~123 ~2 dirt
setblock ~93 ~123 ~3 dirt
setblock ~93 ~123 ~4 dirt
setblock ~93 ~123 ~5 dirt
setblock ~93 ~123 ~6 dirt
setblock ~93 ~123 ~7 dirt
setblock ~93 ~123 ~8 dirt
setblock ~93 ~123 ~9 dirt
setblock ~93 ~123 ~10 dirt
setblock ~93 ~123 ~11 dirt
setblock ~93 ~123 ~12 dirt
setblock ~93 ~123 ~13 dirt
setblock ~93 ~123 ~14 dirt
setblock ~93 ~123 ~15 dirt
setblock ~93 ~123 ~16 dirt
setblock ~93 ~123 ~17 dirt
setblock ~93 ~123 ~18 dirt
setblock ~93 ~123 ~19 dirt
setblock ~93 ~123 ~20 dirt
setblock ~93 ~123 ~21 dirt
setblock ~93 ~123 ~22 dirt
setblock ~93 ~123 ~23 dirt
setblock ~93 ~123 ~24 dirt
setblock ~93 ~123 ~25 dirt
setblock ~93 ~123 ~26 dirt
setblock ~93 ~123 ~27 dirt
setblock ~93 ~123 ~28 dirt
setblock ~93 ~123 ~29 dirt
setblock ~93 ~123 ~30 dirt
setblock ~93 ~123 ~31 dirt
setblock ~93 ~123 ~32 dirt
setblock ~93 ~123 ~33 dirt
setblock ~93 ~123 ~34 dirt
setblock ~93 ~123 ~35 dirt
setblock ~93 ~123 ~36 dirt
setblock ~93 ~123 ~37 dirt
setblock ~93 ~123 ~38 grass_block
setblock ~93 ~123 ~39 grass_block
setblock ~93 ~123 ~40 grass_block
setblock ~93 ~123 ~41 grass_block
setblock ~93 ~123 ~42 grass_block
setblock ~93 ~123 ~43 dirt
setblock ~93 ~123 ~44 dirt
setblock ~93 ~123 ~45 dirt
setblock ~93 ~123 ~46 dirt
setblock ~93 ~123 ~47 dirt
setblock ~93 ~123 ~48 dirt
setblock ~93 ~123 ~49 dirt
setblock ~93 ~123 ~50 dirt
setblock ~93 ~123 ~51 dirt
setblock ~93 ~123 ~52 dirt
setblock ~93 ~123 ~53 dirt
setblock ~93 ~123 ~54 dirt
setblock ~93 ~123 ~55 dirt
setblock ~93 ~123 ~56 dirt
setblock ~93 ~123 ~57 dirt
setblock ~93 ~123 ~58 dirt
setblock ~93 ~123 ~59 dirt
setblock ~93 ~123 ~60 dirt
setblock ~93 ~123 ~61 dirt
setblock ~93 ~123 ~62 dirt
setblock ~93 ~123 ~63 dirt
setblock ~93 ~123 ~64 dirt
setblock ~93 ~123 ~65 grass_block
setblock ~93 ~123 ~66 grass_block
setblock ~93 ~123 ~67 grass_block
setblock ~93 ~123 ~68 grass_block
setblock ~93 ~123 ~69 grass_block
setblock ~93 ~123 ~71 short_grass
setblock ~93 ~123 ~72 grass_block
setblock ~93 ~123 ~73 grass_block
setblock ~93 ~123 ~74 grass_block
setblock ~93 ~123 ~75 grass_block
setblock ~93 ~123 ~76 grass_block
setblock ~93 ~123 ~77 grass_block
setblock ~93 ~123 ~78 grass_block
setblock ~93 ~123 ~79 grass_block
setblock ~93 ~123 ~80 grass_block
setblock ~93 ~123 ~81 grass_block
setblock ~93 ~123 ~82 dirt
setblock ~93 ~123 ~83 dirt
setblock ~93 ~123 ~84 dirt
setblock ~93 ~123 ~85 dirt
setblock ~93 ~123 ~86 dirt
setblock ~93 ~123 ~87 dirt
setblock ~93 ~123 ~88 dirt
setblock ~93 ~123 ~89 dirt
setblock ~93 ~123 ~90 dirt
setblock ~93 ~123 ~91 dirt
setblock ~93 ~123 ~92 dirt
setblock ~93 ~123 ~93 dirt
setblock ~93 ~123 ~94 dirt
setblock ~93 ~123 ~95 dirt
setblock ~93 ~123 ~96 dirt
setblock ~93 ~123 ~97 dirt
setblock ~93 ~123 ~98 dirt
setblock ~93 ~123 ~99 dirt
setblock ~93 ~123 ~100 dirt
setblock ~93 ~123 ~101 dirt
setblock ~93 ~123 ~102 dirt
setblock ~93 ~123 ~103 dirt
setblock ~93 ~123 ~104 dirt
setblock ~93 ~123 ~105 dirt
setblock ~93 ~123 ~106 dirt
setblock ~93 ~123 ~107 dirt
setblock ~93 ~123 ~108 dirt
setblock ~93 ~123 ~109 dirt
setblock ~93 ~123 ~110 dirt
setblock ~93 ~123 ~111 dirt
setblock ~93 ~123 ~112 dirt
setblock ~93 ~123 ~113 dirt
setblock ~93 ~123 ~114 dirt
setblock ~93 ~123 ~115 dirt
setblock ~93 ~123 ~116 dirt
setblock ~93 ~123 ~117 dirt
setblock ~93 ~123 ~118 dirt
setblock ~93 ~123 ~119 dirt
setblock ~93 ~123 ~120 dirt
setblock ~93 ~123 ~121 dirt
setblock ~93 ~123 ~122 dirt
setblock ~93 ~123 ~123 dirt
setblock ~93 ~123 ~124 dirt
setblock ~93 ~123 ~125 dirt
setblock ~93 ~123 ~126 dirt
setblock ~93 ~123 ~127 dirt
setblock ~93 ~123 ~128 dirt
setblock ~93 ~123 ~129 dirt
setblock ~93 ~123 ~130 dirt
setblock ~93 ~123 ~131 dirt
setblock ~93 ~123 ~132 dirt
setblock ~93 ~123 ~133 dirt
setblock ~93 ~123 ~134 dirt
setblock ~93 ~123 ~135 dirt
setblock ~93 ~123 ~136 dirt
setblock ~93 ~123 ~137 dirt
setblock ~93 ~123 ~138 dirt
setblock ~93 ~123 ~139 dirt
setblock ~93 ~123 ~140 dirt
setblock ~93 ~123 ~141 dirt
setblock ~93 ~123 ~142 dirt
setblock ~93 ~123 ~143 dirt
setblock ~93 ~123 ~144 dirt
setblock ~93 ~123 ~145 dirt
setblock ~93 ~123 ~146 dirt
setblock ~93 ~123 ~147 dirt
setblock ~93 ~123 ~148 dirt
setblock ~93 ~123 ~149 dirt
setblock ~93 ~123 ~150 dirt
setblock ~93 ~123 ~151 dirt
setblock ~93 ~123 ~152 dirt
setblock ~93 ~123 ~153 dirt
setblock ~93 ~123 ~154 dirt
setblock ~93 ~123 ~155 dirt
setblock ~93 ~123 ~156 dirt
setblock ~93 ~123 ~157 dirt
setblock ~93 ~123 ~158 dirt
setblock ~93 ~123 ~159 dirt
setblock ~93 ~123 ~160 dirt
setblock ~93 ~123 ~161 dirt
setblock ~93 ~123 ~162 dirt
setblock ~93 ~123 ~163 dirt
setblock ~93 ~123 ~164 dirt
setblock ~93 ~123 ~165 dirt
setblock ~93 ~123 ~166 dirt
setblock ~93 ~123 ~167 dirt
setblock ~93 ~123 ~168 grass_block
setblock ~93 ~123 ~169 grass_block
setblock ~93 ~123 ~172 grass_block
setblock ~93 ~123 ~173 grass_block
setblock ~93 ~123 ~174 grass_block
setblock ~93 ~123 ~175 grass_block
setblock ~93 ~123 ~176 dirt
setblock ~93 ~123 ~177 dirt
setblock ~93 ~123 ~178 dirt
setblock ~93 ~123 ~179 dirt
setblock ~93 ~123 ~180 dirt
setblock ~93 ~123 ~181 dirt
setblock ~93 ~123 ~182 dirt
setblock ~93 ~123 ~183 dirt
setblock ~93 ~123 ~184 dirt
setblock ~93 ~123 ~185 dirt
setblock ~93 ~123 ~186 dirt
setblock ~93 ~123 ~187 dirt
setblock ~93 ~123 ~188 dirt
setblock ~93 ~123 ~189 dirt
setblock ~93 ~123 ~190 dirt
setblock ~93 ~123 ~191 dirt
setblock ~93 ~123 ~192 dirt
setblock ~93 ~123 ~193 dirt
setblock ~93 ~123 ~194 dirt
setblock ~93 ~123 ~195 dirt
setblock ~93 ~123 ~196 dirt
setblock ~93 ~123 ~197 dirt
setblock ~93 ~123 ~198 dirt
setblock ~93 ~123 ~199 grass_block
setblock ~93 ~124 ~0 grass_block
setblock ~93 ~124 ~1 grass_block
setblock ~93 ~124 ~2 dirt
setblock ~93 ~124 ~3 dirt
setblock ~93 ~124 ~4 dirt
setblock ~93 ~124 ~5 dirt
setblock ~93 ~124 ~6 dirt
setblock ~93 ~124 ~7 dirt
setblock ~93 ~124 ~8 dirt
setblock ~93 ~124 ~9 dirt
setblock ~93 ~124 ~10 dirt
setblock ~93 ~124 ~11 dirt
setblock ~93 ~124 ~12 dirt
setblock ~93 ~124 ~13 dirt
setblock ~93 ~124 ~14 dirt
setblock ~93 ~124 ~15 dirt
setblock ~93 ~124 ~16 dirt
setblock ~93 ~124 ~17 dirt
setblock ~93 ~124 ~18 dirt
setblock ~93 ~124 ~19 dirt
setblock ~93 ~124 ~20 dirt
setblock ~93 ~124 ~21 dirt
setblock ~93 ~124 ~22 dirt
setblock ~93 ~124 ~23 dirt
setblock ~93 ~124 ~24 dirt
setblock ~93 ~124 ~25 dirt
setblock ~93 ~124 ~26 dirt
setblock ~93 ~124 ~27 dirt
setblock ~93 ~124 ~28 dirt
setblock ~93 ~124 ~29 dirt
setblock ~93 ~124 ~30 dirt
setblock ~93 ~124 ~31 dirt
setblock ~93 ~124 ~32 dirt
setblock ~93 ~124 ~33 dirt
setblock ~93 ~124 ~34 grass_block
setblock ~93 ~124 ~35 grass_block
setblock ~93 ~124 ~36 grass_block
setblock ~93 ~124 ~37 grass_block
setblock ~93 ~124 ~40 short_grass
setblock ~93 ~124 ~43 grass_block
setblock ~93 ~124 ~44 grass_block
setblock ~93 ~124 ~45 grass_block
setblock ~93 ~124 ~46 grass_block
setblock ~93 ~124 ~47 grass_block
setblock ~93 ~124 ~48 dirt
setblock ~93 ~124 ~49 dirt
setblock ~93 ~124 ~50 dirt
setblock ~93 ~124 ~51 dirt
setblock ~93 ~124 ~52 dirt
setblock ~93 ~124 ~53 dirt
setblock ~93 ~124 ~54 dirt
setblock ~93 ~124 ~55 dirt
setblock ~93 ~124 ~56 dirt
setblock ~93 ~124 ~57 dirt
setblock ~93 ~124 ~58 dirt
setblock ~93 ~124 ~59 dirt
setblock ~93 ~124 ~60 dirt
setblock ~93 ~124 ~61 grass_block
setblock ~93 ~124 ~62 grass_block
setblock ~93 ~124 ~63 grass_block
setblock ~93 ~124 ~64 grass_block
setblock ~93 ~124 ~65 short_grass
setblock ~93 ~124 ~76 short_grass
setblock ~93 ~124 ~77 short_grass
setblock ~93 ~124 ~78 short_grass
setblock ~93 ~124 ~80 short_grass
setblock ~93 ~124 ~82 grass_block
setblock ~93 ~124 ~83 grass_block
setblock ~93 ~124 ~84 grass_block
setblock ~93 ~124 ~85 grass_block
setblock ~93 ~124 ~86 grass_block
setblock ~93 ~124 ~87 grass_block
setblock ~93 ~124 ~88 grass_block
setblock ~93 ~124 ~89 grass_block
setblock ~93 ~124 ~90 grass_block
setblock ~93 ~124 ~91 dirt
setblock ~93 ~124 ~92 dirt
setblock ~93 ~124 ~93 dirt
setblock ~93 ~124 ~94 dirt
setblock ~93 ~124 ~95 dirt
setblock ~93 ~124 ~96 dirt
setblock ~93 ~124 ~97 dirt
setblock ~93 ~124 ~98 dirt
setblock ~93 ~124 ~99 dirt
setblock ~93 ~124 ~100 dirt
setblock ~93 ~124 ~101 dirt
setblock ~93 ~124 ~102 dirt
setblock ~93 ~124 ~103 dirt
setblock ~93 ~124 ~104 dirt
setblock ~93 ~124 ~105 dirt
setblock ~93 ~124 ~106 dirt
setblock ~93 ~124 ~107 dirt
setblock ~93 ~124 ~108 grass_block
setblock ~93 ~124 ~109 grass_block
setblock ~93 ~124 ~110 grass_block
setblock ~93 ~124 ~111 grass_block
setblock ~93 ~124 ~112 grass_block
setblock ~93 ~124 ~113 grass_block
setblock ~93 ~124 ~114 grass_block
setblock ~93 ~124 ~115 grass_block
setblock ~93 ~124 ~116 grass_block
setblock ~93 ~124 ~117 grass_block
setblock ~93 ~124 ~118 grass_block
setblock ~93 ~124 ~119 grass_block
setblock ~93 ~124 ~120 grass_block
setblock ~93 ~124 ~121 grass_block
setblock ~93 ~124 ~122 grass_block
setblock ~93 ~124 ~123 grass_block
setblock ~93 ~124 ~124 dirt
setblock ~93 ~124 ~125 dirt
setblock ~93 ~124 ~126 dirt
setblock ~93 ~124 ~127 dirt
setblock ~93 ~124 ~128 dirt
setblock ~93 ~124 ~129 dirt
setblock ~93 ~124 ~130 dirt
setblock ~93 ~124 ~131 dirt
setblock ~93 ~124 ~132 dirt
setblock ~93 ~124 ~133 dirt
setblock ~93 ~124 ~134 dirt
setblock ~93 ~124 ~135 dirt
setblock ~93 ~124 ~136 dirt
setblock ~93 ~124 ~137 dirt
setblock ~93 ~124 ~138 dirt
setblock ~93 ~124 ~139 dirt
setblock ~93 ~124 ~140 dirt
setblock ~93 ~124 ~141 dirt
setblock ~93 ~124 ~142 dirt
setblock ~93 ~124 ~143 dirt
setblock ~93 ~124 ~144 dirt
setblock ~93 ~124 ~145 dirt
setblock ~93 ~124 ~146 dirt
setblock ~93 ~124 ~147 dirt
setblock ~93 ~124 ~148 dirt
setblock ~93 ~124 ~149 dirt
setblock ~93 ~124 ~150 grass_block
setblock ~93 ~124 ~151 dirt
setblock ~93 ~124 ~152 dirt
setblock ~93 ~124 ~153 dirt
setblock ~93 ~124 ~154 dirt
setblock ~93 ~124 ~155 dirt
setblock ~93 ~124 ~156 dirt
setblock ~93 ~124 ~157 dirt
setblock ~93 ~124 ~158 dirt
setblock ~93 ~124 ~159 dirt
setblock ~93 ~124 ~160 dirt
setblock ~93 ~124 ~161 dirt
setblock ~93 ~124 ~162 dirt
setblock ~93 ~124 ~163 dirt
setblock ~93 ~124 ~164 dirt
setblock ~93 ~124 ~165 grass_block
setblock ~93 ~124 ~166 grass_block
setblock ~93 ~124 ~167 grass_block
setblock ~93 ~124 ~174 short_grass
setblock ~93 ~124 ~175 short_grass
setblock ~93 ~124 ~176 grass_block
setblock ~93 ~124 ~177 grass_block
setblock ~93 ~124 ~178 grass_block
setblock ~93 ~124 ~179 grass_block
setblock ~93 ~124 ~180 grass_block
setblock ~93 ~124 ~181 dirt
setblock ~93 ~124 ~182 dirt
setblock ~93 ~124 ~183 dirt
setblock ~93 ~124 ~184 dirt
setblock ~93 ~124 ~185 dirt
setblock ~93 ~124 ~186 dirt
setblock ~93 ~124 ~187 dirt
setblock ~93 ~124 ~188 dirt
setblock ~93 ~124 ~189 dirt
setblock ~93 ~124 ~190 dirt
setblock ~93 ~124 ~191 dirt
setblock ~93 ~124 ~192 dirt
setblock ~93 ~124 ~193 dirt
setblock ~93 ~124 ~194 dirt
setblock ~93 ~124 ~195 dirt
setblock ~93 ~124 ~196 dirt
setblock ~93 ~124 ~197 grass_block
setblock ~93 ~124 ~198 grass_block
setblock ~93 ~125 ~2 grass_block
setblock ~93 ~125 ~3 grass_block
setblock ~93 ~125 ~4 grass_block
setblock ~93 ~125 ~5 grass_block
setblock ~93 ~125 ~6 dirt
setblock ~93 ~125 ~7 dirt
setblock ~93 ~125 ~8 dirt
setblock ~93 ~125 ~9 dirt
setblock ~93 ~125 ~10 dirt
setblock ~93 ~125 ~11 dirt
setblock ~93 ~125 ~12 dirt
setblock ~93 ~125 ~13 dirt
setblock ~93 ~125 ~14 dirt
setblock ~93 ~125 ~15 dirt
setblock ~93 ~125 ~16 dirt
setblock ~93 ~125 ~17 dirt
setblock ~93 ~125 ~18 dirt
setblock ~93 ~125 ~19 dirt
setblock ~93 ~125 ~20 dirt
setblock ~93 ~125 ~21 dirt
setblock ~93 ~125 ~22 dirt
setblock ~93 ~125 ~23 dirt
setblock ~93 ~125 ~24 dirt
setblock ~93 ~125 ~25 dirt
setblock ~93 ~125 ~26 dirt
setblock ~93 ~125 ~27 dirt
setblock ~93 ~125 ~28 dirt
setblock ~93 ~125 ~29 dirt
setblock ~93 ~125 ~30 dirt
setblock ~93 ~125 ~31 grass_block
setblock ~93 ~125 ~32 grass_block
setblock ~93 ~125 ~33 grass_block
setblock ~93 ~125 ~35 short_grass
setblock ~93 ~125 ~37 poppy
setblock ~93 ~125 ~46 short_grass
setblock ~93 ~125 ~48 grass_block
setblock ~93 ~125 ~49 grass_block
setblock ~93 ~125 ~50 grass_block
setblock ~93 ~125 ~51 grass_block
setblock ~93 ~125 ~52 grass_block
setblock ~93 ~125 ~53 grass_block
setblock ~93 ~125 ~54 grass_block
setblock ~93 ~125 ~55 grass_block
setblock ~93 ~125 ~56 grass_block
setblock ~93 ~125 ~57 grass_block
setblock ~93 ~125 ~58 grass_block
setblock ~93 ~125 ~59 grass_block
setblock ~93 ~125 ~60 grass_block
setblock ~93 ~125 ~61 short_grass
setblock ~93 ~125 ~82 poppy
setblock ~93 ~125 ~85 short_grass
setblock ~93 ~125 ~86 short_grass
setblock ~93 ~125 ~91 grass_block
setblock ~93 ~125 ~92 grass_block
setblock ~93 ~125 ~93 grass_block
setblock ~93 ~125 ~94 grass_block
setblock ~93 ~125 ~95 grass_block
setblock ~93 ~125 ~96 grass_block
setblock ~93 ~125 ~97 grass_block
setblock ~93 ~125 ~98 grass_block
setblock ~93 ~125 ~99 grass_block
setblock ~93 ~125 ~100 grass_block
setblock ~93 ~125 ~101 grass_block
setblock ~93 ~125 ~102 grass_block
setblock ~93 ~125 ~103 grass_block
setblock ~93 ~125 ~104 grass_block
setblock ~93 ~125 ~105 grass_block
setblock ~93 ~125 ~106 grass_block
setblock ~93 ~125 ~107 grass_block
setblock ~93 ~125 ~110 short_grass
setblock ~93 ~125 ~113 short_grass
setblock ~93 ~125 ~115 short_grass
setblock ~93 ~125 ~116 short_grass
setblock ~93 ~125 ~117 short_grass
setblock ~93 ~125 ~119 fern
setblock ~93 ~125 ~122 short_grass
setblock ~93 ~125 ~123 short_grass
setblock ~93 ~125 ~124 grass_block
setblock ~93 ~125 ~125 grass_block
setblock ~93 ~125 ~126 grass_block
setblock ~93 ~125 ~127 grass_block
setblock ~93 ~125 ~128 grass_block
setblock ~93 ~125 ~129 dirt
setblock ~93 ~125 ~130 dirt
setblock ~93 ~125 ~131 dirt
setblock ~93 ~125 ~132 dirt
setblock ~93 ~125 ~133 dirt
setblock ~93 ~125 ~134 dirt
setblock ~93 ~125 ~135 dirt
setblock ~93 ~125 ~136 dirt
setblock ~93 ~125 ~137 dirt
setblock ~93 ~125 ~138 dirt
setblock ~93 ~125 ~139 dirt
setblock ~93 ~125 ~140 dirt
setblock ~93 ~125 ~141 dirt
setblock ~93 ~125 ~142 dirt
setblock ~93 ~125 ~143 dirt
setblock ~93 ~125 ~144 dirt
setblock ~93 ~125 ~145 grass_block
setblock ~93 ~125 ~146 grass_block
setblock ~93 ~125 ~147 grass_block
setblock ~93 ~125 ~148 grass_block
setblock ~93 ~125 ~149 grass_block
setblock ~93 ~125 ~150 short_grass
setblock ~93 ~125 ~151 grass_block
setblock ~93 ~125 ~152 grass_block
setblock ~93 ~125 ~153 grass_block
setblock ~93 ~125 ~154 grass_block
setblock ~93 ~125 ~155 dirt
setblock ~93 ~125 ~156 dirt
setblock ~93 ~125 ~157 dirt
setblock ~93 ~125 ~158 dirt
setblock ~93 ~125 ~159 dirt
setblock ~93 ~125 ~160 dirt
setblock ~93 ~125 ~161 dirt
setblock ~93 ~125 ~162 dirt
setblock ~93 ~125 ~163 grass_block
setblock ~93 ~125 ~164 grass_block
setblock ~93 ~125 ~176 fern
setblock ~93 ~125 ~177 short_grass
setblock ~93 ~125 ~181 grass_block
setblock ~93 ~125 ~182 grass_block
setblock ~93 ~125 ~183 dirt
setblock ~93 ~125 ~184 dirt
setblock ~93 ~125 ~185 dirt
setblock ~93 ~125 ~186 dirt
setblock ~93 ~125 ~187 dirt
setblock ~93 ~125 ~188 dirt
setblock ~93 ~125 ~189 dirt
setblock ~93 ~125 ~190 dirt
setblock ~93 ~125 ~191 dirt
setblock ~93 ~125 ~192 dirt
setblock ~93 ~125 ~193 dirt
setblock ~93 ~125 ~194 dirt
setblock ~93 ~125 ~195 grass_block
setblock ~93 ~125 ~196 grass_block
setblock ~93 ~125 ~197 short_grass
setblock ~93 ~126 ~6 grass_block
setblock ~93 ~126 ~7 grass_block
setblock ~93 ~126 ~8 grass_block
setblock ~93 ~126 ~9 dirt
setblock ~93 ~126 ~10 dirt
setblock ~93 ~126 ~11 dirt
setblock ~93 ~126 ~12 dirt
setblock ~93 ~126 ~13 dirt
setblock ~93 ~126 ~14 dirt
setblock ~93 ~126 ~15 dirt
setblock ~93 ~126 ~16 grass_block
setblock ~93 ~126 ~17 grass_block
setblock ~93 ~126 ~18 grass_block
setblock ~93 ~126 ~19 grass_block
setblock ~93 ~126 ~20 grass_block
setblock ~93 ~126 ~21 grass_block
setblock ~93 ~126 ~22 grass_block
setblock ~93 ~126 ~23 grass_block
setblock ~93 ~126 ~24 grass_block
setblock ~93 ~126 ~25 grass_block
setblock ~93 ~126 ~26 grass_block
setblock ~93 ~126 ~27 grass_block
setblock ~93 ~126 ~28 grass_block
setblock ~93 ~126 ~29 grass_block
setblock ~93 ~126 ~30 grass_block
setblock ~93 ~126 ~31 short_grass
setblock ~93 ~126 ~54 short_grass
setblock ~93 ~126 ~59 short_grass
setblock ~93 ~126 ~93 short_grass
setblock ~93 ~126 ~99 short_grass
setblock ~93 ~126 ~107 short_grass
setblock ~93 ~126 ~128 short_grass
setblock ~93 ~126 ~129 grass_block
setblock ~93 ~126 ~130 grass_block
setblock ~93 ~126 ~131 grass_block
setblock ~93 ~126 ~132 grass_block
setblock ~93 ~126 ~133 grass_block
setblock ~93 ~126 ~134 grass_block
setblock ~93 ~126 ~135 grass_block
setblock ~93 ~126 ~136 grass_block
setblock ~93 ~126 ~137 grass_block
setblock ~93 ~126 ~138 grass_block
setblock ~93 ~126 ~139 grass_block
setblock ~93 ~126 ~140 grass_block
setblock ~93 ~126 ~141 grass_block
setblock ~93 ~126 ~142 grass_block
setblock ~93 ~126 ~143 grass_block
setblock ~93 ~126 ~144 grass_block
setblock ~93 ~126 ~148 short_grass
setblock ~93 ~126 ~149 short_grass
setblock ~93 ~126 ~151 fern
setblock ~93 ~126 ~152 short_grass
setblock ~93 ~126 ~154 short_grass
setblock ~93 ~126 ~155 grass_block
setblock ~93 ~126 ~156 grass_block
setblock ~93 ~126 ~157 grass_block
setblock ~93 ~126 ~158 grass_block
setblock ~93 ~126 ~159 grass_block
setblock ~93 ~126 ~160 grass_block
setblock ~93 ~126 ~161 grass_block
setblock ~93 ~126 ~162 grass_block
setblock ~93 ~126 ~181 short_grass
setblock ~93 ~126 ~183 grass_block
setblock ~93 ~126 ~184 grass_block
setblock ~93 ~126 ~185 grass_block
setblock ~93 ~126 ~186 dirt
setblock ~93 ~126 ~187 dirt
setblock ~93 ~126 ~188 dirt
setblock ~93 ~126 ~189 dirt
setblock ~93 ~126 ~190 dirt
setblock ~93 ~126 ~191 dirt
setblock ~93 ~126 ~192 dirt
setblock ~93 ~126 ~193 grass_block
setblock ~93 ~126 ~194 grass_block
setblock ~93 ~127 ~6 short_grass
setblock ~93 ~127 ~9 grass_block
setblock ~93 ~127 ~10 grass_block
setblock ~93 ~127 ~11 grass_block
setblock ~93 ~127 ~12 grass_block
setblock ~93 ~127 ~13 grass_block
setblock ~93 ~127 ~14 grass_block
setblock ~93 ~127 ~15 grass_block
setblock ~93 ~127 ~16 fern
setblock ~93 ~127 ~22 short_grass
setblock ~93 ~127 ~26 short_grass
setblock ~93 ~127 ~27 short_grass
setblock ~93 ~127 ~28 fern
setblock ~93 ~127 ~30 short_grass
setblock ~93 ~127 ~132 short_grass
setblock ~93 ~127 ~133 short_grass
setblock ~93 ~127 ~134 poppy
setblock ~93 ~127 ~135 short_grass
setblock ~93 ~127 ~141 short_grass
setblock ~93 ~127 ~143 short_grass
setblock ~93 ~127 ~183 short_grass
setblock ~93 ~127 ~186 grass_block
setblock ~93 ~127 ~187 grass_block
setblock ~93 ~127 ~188 grass_block
setblock ~93 ~127 ~189 grass_block
setblock ~93 ~127 ~190 dirt
setblock ~93 ~127 ~191 grass_block
setblock ~93 ~127 ~192 grass_block
setblock ~93 ~127 ~193 short_grass
setblock ~93 ~128 ~9 short_grass
setblock ~93 ~128 ~11 fern
setblock ~93 ~128 ~13 short_grass
setblock ~93 ~128 ~14 short_grass
setblock ~93 ~128 ~15 poppy
setblock ~93 ~128 ~190 grass_block
setblock ~93 ~128 ~192 short_grass
setblock ~93 ~129 ~190 poppy
setblock ~94 ~122 ~0 dirt
setblock ~94 ~122 ~1 dirt
setblock ~94 ~122 ~2 dirt
setblock ~94 ~122 ~3 dirt
setblock ~94 ~122 ~4 dirt
setblock ~94 ~122 ~5 dirt
setblock ~94 ~122 ~6 dirt
setblock ~94 ~122 ~7 dirt
setblock ~94 ~122 ~8 dirt
setblock ~94 ~122 ~9 dirt
setblock ~94 ~122 ~10 dirt
setblock ~94 ~122 ~11 dirt
setblock ~94 ~122 ~12 dirt
setblock ~94 ~122 ~13 dirt
setblock ~94 ~122 ~14 dirt
setblock ~94 ~122 ~15 dirt
setblock ~94 ~122 ~16 dirt
setblock ~94 ~122 ~17 dirt
setblock ~94 ~122 ~18 dirt
setblock ~94 ~122 ~19 dirt
setblock ~94 ~122 ~20 dirt
setblock ~94 ~122 ~21 dirt
setblock ~94 ~122 ~22 dirt
setblock ~94 ~122 ~23 dirt
setblock ~94 ~122 ~24 dirt
setblock ~94 ~122 ~25 dirt
setblock ~94 ~122 ~26 dirt
setblock ~94 ~122 ~27 dirt
setblock ~94 ~122 ~28 dirt
setblock ~94 ~122 ~29 dirt
setblock ~94 ~122 ~30 dirt
setblock ~94 ~122 ~31 dirt
setblock ~94 ~122 ~32 dirt
setblock ~94 ~122 ~33 dirt
setblock ~94 ~122 ~34 dirt
setblock ~94 ~122 ~35 dirt
setblock ~94 ~122 ~36 dirt
setblock ~94 ~122 ~37 dirt
setblock ~94 ~122 ~38 dirt
setblock ~94 ~122 ~39 dirt
setblock ~94 ~122 ~40 dirt
setblock ~94 ~122 ~41 dirt
setblock ~94 ~122 ~42 dirt
setblock ~94 ~122 ~43 dirt
setblock ~94 ~122 ~44 dirt
setblock ~94 ~122 ~45 dirt
setblock ~94 ~122 ~46 dirt
setblock ~94 ~122 ~47 dirt
setblock ~94 ~122 ~48 dirt
setblock ~94 ~122 ~49 dirt
setblock ~94 ~122 ~50 dirt
setblock ~94 ~122 ~51 dirt
setblock ~94 ~122 ~52 dirt
setblock ~94 ~122 ~53 dirt
setblock ~94 ~122 ~54 dirt
setblock ~94 ~122 ~55 dirt
setblock ~94 ~122 ~56 dirt
setblock ~94 ~122 ~57 dirt
setblock ~94 ~122 ~58 dirt
setblock ~94 ~122 ~59 dirt
setblock ~94 ~122 ~60 dirt
setblock ~94 ~122 ~61 dirt
setblock ~94 ~122 ~62 dirt
setblock ~94 ~122 ~63 dirt
setblock ~94 ~122 ~64 dirt
setblock ~94 ~122 ~65 dirt
setblock ~94 ~122 ~66 dirt
setblock ~94 ~122 ~67 dirt
setblock ~94 ~122 ~68 dirt
setblock ~94 ~122 ~69 dirt
setblock ~94 ~122 ~70 grass_block
setblock ~94 ~122 ~71 grass_block
setblock ~94 ~122 ~72 dirt
setblock ~94 ~122 ~73 dirt
setblock ~94 ~122 ~74 dirt
setblock ~94 ~122 ~75 dirt
setblock ~94 ~122 ~76 dirt
setblock ~94 ~122 ~77 dirt
setblock ~94 ~122 ~78 dirt
setblock ~94 ~122 ~79 dirt
setblock ~94 ~122 ~80 dirt
setblock ~94 ~122 ~81 dirt
setblock ~94 ~122 ~82 dirt
setblock ~94 ~122 ~83 dirt
setblock ~94 ~122 ~84 dirt
setblock ~94 ~122 ~85 dirt
setblock ~94 ~122 ~86 dirt
setblock ~94 ~122 ~87 dirt
setblock ~94 ~122 ~88 dirt
setblock ~94 ~122 ~89 dirt
setblock ~94 ~122 ~90 dirt
setblock ~94 ~122 ~91 dirt
setblock ~94 ~122 ~92 dirt
setblock ~94 ~122 ~93 dirt
setblock ~94 ~122 ~94 dirt
setblock ~94 ~122 ~95 dirt
setblock ~94 ~122 ~96 dirt
setblock ~94 ~122 ~97 dirt
setblock ~94 ~122 ~98 dirt
setblock ~94 ~122 ~99 dirt
setblock ~94 ~122 ~100 dirt
setblock ~94 ~122 ~101 dirt
setblock ~94 ~122 ~102 dirt
setblock ~94 ~122 ~103 dirt
setblock ~94 ~122 ~104 dirt
setblock ~94 ~122 ~105 dirt
setblock ~94 ~122 ~106 dirt
setblock ~94 ~122 ~107 dirt
setblock ~94 ~122 ~108 dirt
setblock ~94 ~122 ~109 dirt
setblock ~94 ~122 ~110 dirt
setblock ~94 ~122 ~111 dirt
setblock ~94 ~122 ~112 dirt
setblock ~94 ~122 ~113 dirt
setblock ~94 ~122 ~114 dirt
setblock ~94 ~122 ~115 dirt
setblock ~94 ~122 ~116 dirt
setblock ~94 ~122 ~117 dirt
setblock ~94 ~122 ~118 dirt
setblock ~94 ~122 ~119 dirt
setblock ~94 ~122 ~120 dirt
setblock ~94 ~122 ~121 dirt
setblock ~94 ~122 ~122 dirt
setblock ~94 ~122 ~123 dirt
setblock ~94 ~122 ~124 dirt
setblock ~94 ~122 ~125 dirt
setblock ~94 ~122 ~126 dirt
setblock ~94 ~122 ~127 dirt
setblock ~94 ~122 ~128 dirt
setblock ~94 ~122 ~129 dirt
setblock ~94 ~122 ~130 dirt
setblock ~94 ~122 ~131 dirt
setblock ~94 ~122 ~132 dirt
setblock ~94 ~122 ~133 dirt
setblock ~94 ~122 ~134 dirt
setblock ~94 ~122 ~135 dirt
setblock ~94 ~122 ~136 dirt
setblock ~94 ~122 ~137 dirt
setblock ~94 ~122 ~138 dirt
setblock ~94 ~122 ~139 dirt
setblock ~94 ~122 ~140 dirt
setblock ~94 ~122 ~141 dirt
setblock ~94 ~122 ~142 dirt
setblock ~94 ~122 ~143 dirt
setblock ~94 ~122 ~144 dirt
setblock ~94 ~122 ~145 dirt
setblock ~94 ~122 ~146 dirt
setblock ~94 ~122 ~147 dirt
setblock ~94 ~122 ~148 dirt
setblock ~94 ~122 ~149 dirt
setblock ~94 ~122 ~150 dirt
setblock ~94 ~122 ~151 dirt
setblock ~94 ~122 ~152 dirt
setblock ~94 ~122 ~153 dirt
setblock ~94 ~122 ~154 dirt
setblock ~94 ~122 ~155 dirt
setblock ~94 ~122 ~156 dirt
setblock ~94 ~122 ~157 dirt
setblock ~94 ~122 ~158 dirt
setblock ~94 ~122 ~159 dirt
setblock ~94 ~122 ~160 dirt
setblock ~94 ~122 ~161 dirt
setblock ~94 ~122 ~162 dirt
setblock ~94 ~122 ~163 dirt
setblock ~94 ~122 ~164 dirt
setblock ~94 ~122 ~165 dirt
setblock ~94 ~122 ~166 dirt
setblock ~94 ~122 ~167 dirt
setblock ~94 ~122 ~168 dirt
setblock ~94 ~122 ~169 dirt
setblock ~94 ~122 ~170 grass_block
setblock ~94 ~122 ~171 grass_block
setblock ~94 ~122 ~172 dirt
setblock ~94 ~122 ~173 dirt
setblock ~94 ~122 ~174 dirt
setblock ~94 ~122 ~175 dirt
setblock ~94 ~122 ~176 dirt
setblock ~94 ~122 ~177 dirt
setblock ~94 ~122 ~178 dirt
setblock ~94 ~122 ~179 dirt
setblock ~94 ~122 ~180 dirt
setblock ~94 ~122 ~181 dirt
setblock ~94 ~122 ~182 dirt
setblock ~94 ~122 ~183 dirt
setblock ~94 ~122 ~184 dirt
setblock ~94 ~122 ~185 dirt
setblock ~94 ~122 ~186 dirt
setblock ~94 ~122 ~187 dirt
setblock ~94 ~122 ~188 dirt
setblock ~94 ~122 ~189 dirt
setblock ~94 ~122 ~190 dirt
setblock ~94 ~122 ~191 dirt
setblock ~94 ~122 ~192 dirt
setblock ~94 ~122 ~193 dirt
setblock ~94 ~122 ~194 dirt
setblock ~94 ~122 ~195 dirt
setblock ~94 ~122 ~196 dirt
setblock ~94 ~122 ~197 dirt
setblock ~94 ~122 ~198 dirt
setblock ~94 ~122 ~199 dirt
setblock ~94 ~123 ~0 dirt
setblock ~94 ~123 ~1 dirt
setblock ~94 ~123 ~2 dirt
setblock ~94 ~123 ~3 dirt
setblock ~94 ~123 ~4 dirt
setblock ~94 ~123 ~5 dirt
setblock ~94 ~123 ~6 dirt
setblock ~94 ~123 ~7 dirt
setblock ~94 ~123 ~8 dirt
setblock ~94 ~123 ~9 dirt
setblock ~94 ~123 ~10 dirt
setblock ~94 ~123 ~11 dirt
setblock ~94 ~123 ~12 dirt
setblock ~94 ~123 ~13 dirt
setblock ~94 ~123 ~14 dirt
setblock ~94 ~123 ~15 dirt
setblock ~94 ~123 ~16 dirt
setblock ~94 ~123 ~17 dirt
setblock ~94 ~123 ~18 dirt
setblock ~94 ~123 ~19 dirt
setblock ~94 ~123 ~20 dirt
setblock ~94 ~123 ~21 dirt
setblock ~94 ~123 ~22 dirt
setblock ~94 ~123 ~23 dirt
setblock ~94 ~123 ~24 dirt
setblock ~94 ~123 ~25 dirt
setblock ~94 ~123 ~26 dirt
setblock ~94 ~123 ~27 dirt
setblock ~94 ~123 ~28 dirt
setblock ~94 ~123 ~29 dirt
setblock ~94 ~123 ~30 dirt
setblock ~94 ~123 ~31 dirt
setblock ~94 ~123 ~32 dirt
setblock ~94 ~123 ~33 dirt
setblock ~94 ~123 ~34 dirt
setblock ~94 ~123 ~35 dirt
setblock ~94 ~123 ~36 dirt
setblock ~94 ~123 ~37 dirt
setblock ~94 ~123 ~38 grass_block
setblock ~94 ~123 ~39 grass_block
setblock ~94 ~123 ~40 grass_block
setblock ~94 ~123 ~41 grass_block
setblock ~94 ~123 ~42 grass_block
setblock ~94 ~123 ~43 dirt
setblock ~94 ~123 ~44 dirt
setblock ~94 ~123 ~45 dirt
setblock ~94 ~123 ~46 dirt
setblock ~94 ~123 ~47 dirt
