setblock ~160 ~126 ~156 grass_block
setblock ~160 ~126 ~157 grass_block
setblock ~160 ~126 ~158 dirt
setblock ~160 ~126 ~159 dirt
setblock ~160 ~126 ~160 dirt
setblock ~160 ~126 ~161 dirt
setblock ~160 ~126 ~162 dirt
setblock ~160 ~126 ~163 dirt
setblock ~160 ~126 ~164 dirt
setblock ~160 ~126 ~165 dirt
setblock ~160 ~126 ~166 dirt
setblock ~160 ~126 ~167 dirt
setblock ~160 ~126 ~168 dirt
setblock ~160 ~126 ~169 dirt
setblock ~160 ~126 ~170 dirt
setblock ~160 ~126 ~171 dirt
setblock ~160 ~126 ~172 grass_block
setblock ~160 ~126 ~173 grass_block
setblock ~160 ~126 ~185 short_grass
setblock ~160 ~126 ~187 grass_block
setblock ~160 ~126 ~188 grass_block
setblock ~160 ~126 ~189 grass_block
setblock ~160 ~126 ~190 grass_block
setblock ~160 ~126 ~191 grass_block
setblock ~160 ~126 ~192 dirt
setblock ~160 ~126 ~193 dirt
setblock ~160 ~126 ~194 dirt
setblock ~160 ~126 ~195 dirt
setblock ~160 ~126 ~196 dirt
setblock ~160 ~126 ~197 dirt
setblock ~160 ~126 ~198 dirt
setblock ~160 ~126 ~199 dirt
setblock ~160 ~127 ~7 short_grass
setblock ~160 ~127 ~8 grass_block
setblock ~160 ~127 ~9 dirt
setblock ~160 ~127 ~10 dirt
setblock ~160 ~127 ~11 dirt
setblock ~160 ~127 ~37 short_grass
setblock ~160 ~127 ~39 grass_block
setblock ~160 ~127 ~40 grass_block
setblock ~160 ~127 ~41 grass_block
setblock ~160 ~127 ~42 grass_block
setblock ~160 ~127 ~43 grass_block
setblock ~160 ~127 ~44 grass_block
setblock ~160 ~127 ~45 grass_block
setblock ~160 ~127 ~47 short_grass
setblock ~160 ~127 ~77 grass_block
setblock ~160 ~127 ~78 grass_block
setblock ~160 ~127 ~79 dirt
setblock ~160 ~127 ~80 dirt
setblock ~160 ~127 ~81 dirt
setblock ~160 ~127 ~82 dirt
setblock ~160 ~127 ~83 dirt
setblock ~160 ~127 ~84 dirt
setblock ~160 ~127 ~85 grass_block
setblock ~160 ~127 ~86 grass_block
setblock ~160 ~127 ~87 grass_block
setblock ~160 ~127 ~88 grass_block
setblock ~160 ~127 ~89 grass_block
setblock ~160 ~127 ~90 grass_block
setblock ~160 ~127 ~91 grass_block
setblock ~160 ~127 ~95 fern
setblock ~160 ~127 ~156 short_grass
setblock ~160 ~127 ~158 grass_block
setblock ~160 ~127 ~159 dirt
setblock ~160 ~127 ~160 dirt
setblock ~160 ~127 ~161 dirt
setblock ~160 ~127 ~162 dirt
setblock ~160 ~127 ~163 dirt
setblock ~160 ~127 ~164 dirt
setblock ~160 ~127 ~165 dirt
setblock ~160 ~127 ~166 dirt
setblock ~160 ~127 ~167 dirt
setblock ~160 ~127 ~168 dirt
setblock ~160 ~127 ~169 grass_block
setblock ~160 ~127 ~170 grass_block
setblock ~160 ~127 ~171 grass_block
setblock ~160 ~127 ~188 short_grass
setblock ~160 ~127 ~191 short_grass
setblock ~160 ~127 ~192 grass_block
setblock ~160 ~127 ~193 grass_block
setblock ~160 ~127 ~194 grass_block
setblock ~160 ~127 ~195 grass_block
setblock ~160 ~127 ~196 grass_block
setblock ~160 ~127 ~197 grass_block
setblock ~160 ~127 ~198 dirt
setblock ~160 ~127 ~199 dirt
setblock ~160 ~128 ~9 dirt
setblock ~160 ~128 ~10 dirt
setblock ~160 ~128 ~11 dirt
setblock ~160 ~128 ~40 short_grass
setblock ~160 ~128 ~78 fern
setblock ~160 ~128 ~79 grass_block
setblock ~160 ~128 ~80 grass_block
setblock ~160 ~128 ~81 grass_block
setblock ~160 ~128 ~82 grass_block
setblock ~160 ~128 ~83 grass_block
setblock ~160 ~128 ~84 grass_block
setblock ~160 ~128 ~85 short_grass
setblock ~160 ~128 ~88 short_grass
setblock ~160 ~128 ~90 short_grass
setblock ~160 ~128 ~158 short_grass
setblock ~160 ~128 ~159 dirt
setblock ~160 ~128 ~160 dirt
setblock ~160 ~128 ~161 dirt
setblock ~160 ~128 ~162 dirt
setblock ~160 ~128 ~163 dirt
setblock ~160 ~128 ~164 dirt
setblock ~160 ~128 ~165 dirt
setblock ~160 ~128 ~166 grass_block
setblock ~160 ~128 ~167 grass_block
setblock ~160 ~128 ~168 grass_block
setblock ~160 ~128 ~171 short_grass
setblock ~160 ~128 ~196 short_grass
setblock ~160 ~128 ~198 grass_block
setblock ~160 ~128 ~199 grass_block
setblock ~160 ~129 ~9 grass_block
setblock ~160 ~129 ~10 dirt
setblock ~160 ~129 ~11 grass_block
setblock ~160 ~129 ~159 grass_block
setblock ~160 ~129 ~160 dirt
setblock ~160 ~129 ~161 dirt
setblock ~160 ~129 ~162 dirt
setblock ~160 ~129 ~163 grass_block
setblock ~160 ~129 ~164 grass_block
setblock ~160 ~129 ~165 grass_block
setblock ~160 ~129 ~166 short_grass
setblock ~160 ~129 ~199 short_grass
setblock ~160 ~130 ~9 short_grass
setblock ~160 ~130 ~10 dirt
setblock ~160 ~130 ~160 dirt
setblock ~160 ~130 ~161 dirt
setblock ~160 ~130 ~162 grass_block
setblock ~160 ~130 ~163 short_grass
setblock ~160 ~131 ~10 grass_block
setblock ~160 ~131 ~160 grass_block
setblock ~160 ~131 ~161 grass_block
setblock ~161 ~122 ~0 dirt
setblock ~161 ~122 ~1 dirt
setblock ~161 ~122 ~2 dirt
setblock ~161 ~122 ~3 dirt
setblock ~161 ~122 ~4 dirt
setblock ~161 ~122 ~5 dirt
setblock ~161 ~122 ~6 dirt
setblock ~161 ~122 ~7 dirt
setblock ~161 ~122 ~8 dirt
setblock ~161 ~122 ~9 dirt
setblock ~161 ~122 ~10 dirt
setblock ~161 ~122 ~11 dirt
setblock ~161 ~122 ~12 dirt
setblock ~161 ~122 ~13 dirt
setblock ~161 ~122 ~14 dirt
setblock ~161 ~122 ~15 dirt
setblock ~161 ~122 ~16 dirt
setblock ~161 ~122 ~17 dirt
setblock ~161 ~122 ~18 dirt
setblock ~161 ~122 ~19 grass_block
setblock ~161 ~122 ~20 grass_block
setblock ~161 ~122 ~21 grass_block
setblock ~161 ~122 ~22 grass_block
setblock ~161 ~122 ~23 grass_block
setblock ~161 ~122 ~24 grass_block
setblock ~161 ~122 ~25 grass_block
setblock ~161 ~122 ~26 grass_block
setblock ~161 ~122 ~27 grass_block
setblock ~161 ~122 ~28 grass_block
setblock ~161 ~122 ~29 grass_block
setblock ~161 ~122 ~30 grass_block
setblock ~161 ~122 ~31 dirt
setblock ~161 ~122 ~32 dirt
setblock ~161 ~122 ~33 dirt
setblock ~161 ~122 ~34 dirt
setblock ~161 ~122 ~35 dirt
setblock ~161 ~122 ~36 dirt
setblock ~161 ~122 ~37 dirt
setblock ~161 ~122 ~38 dirt
setblock ~161 ~122 ~39 dirt
setblock ~161 ~122 ~40 dirt
setblock ~161 ~122 ~41 dirt
setblock ~161 ~122 ~42 dirt
setblock ~161 ~122 ~43 dirt
setblock ~161 ~122 ~44 dirt
setblock ~161 ~122 ~45 dirt
setblock ~161 ~122 ~46 dirt
setblock ~161 ~122 ~47 dirt
setblock ~161 ~122 ~48 dirt
setblock ~161 ~122 ~49 dirt
setblock ~161 ~122 ~50 dirt
setblock ~161 ~122 ~51 dirt
setblock ~161 ~122 ~52 dirt
setblock ~161 ~122 ~53 dirt
setblock ~161 ~122 ~54 dirt
setblock ~161 ~122 ~55 dirt
setblock ~161 ~122 ~56 dirt
setblock ~161 ~122 ~57 dirt
setblock ~161 ~122 ~58 dirt
setblock ~161 ~122 ~59 dirt
setblock ~161 ~122 ~60 dirt
setblock ~161 ~122 ~61 dirt
setblock ~161 ~122 ~62 dirt
setblock ~161 ~122 ~63 dirt
setblock ~161 ~122 ~64 dirt
setblock ~161 ~122 ~65 dirt
setblock ~161 ~122 ~66 dirt
setblock ~161 ~122 ~67 dirt
setblock ~161 ~122 ~68 dirt
setblock ~161 ~122 ~69 dirt
setblock ~161 ~122 ~70 dirt
setblock ~161 ~122 ~71 dirt
setblock ~161 ~122 ~72 dirt
setblock ~161 ~122 ~73 dirt
setblock ~161 ~122 ~74 dirt
setblock ~161 ~122 ~75 dirt
setblock ~161 ~122 ~76 dirt
setblock ~161 ~122 ~77 dirt
setblock ~161 ~122 ~78 dirt
setblock ~161 ~122 ~79 dirt
setblock ~161 ~122 ~80 dirt
setblock ~161 ~122 ~81 dirt
setblock ~161 ~122 ~82 dirt
setblock ~161 ~122 ~83 dirt
setblock ~161 ~122 ~84 dirt
setblock ~161 ~122 ~85 dirt
setblock ~161 ~122 ~86 dirt
setblock ~161 ~122 ~87 dirt
setblock ~161 ~122 ~88 dirt
setblock ~161 ~122 ~89 dirt
setblock ~161 ~122 ~90 dirt
setblock ~161 ~122 ~91 dirt
setblock ~161 ~122 ~92 dirt
setblock ~161 ~122 ~93 dirt
setblock ~161 ~122 ~94 dirt
setblock ~161 ~122 ~95 dirt
setblock ~161 ~122 ~96 dirt
setblock ~161 ~122 ~97 dirt
setblock ~161 ~122 ~98 dirt
setblock ~161 ~122 ~99 dirt
setblock ~161 ~122 ~100 dirt
setblock ~161 ~122 ~101 dirt
setblock ~161 ~122 ~102 dirt
setblock ~161 ~122 ~103 dirt
setblock ~161 ~122 ~104 dirt
setblock ~161 ~122 ~105 dirt
setblock ~161 ~122 ~106 dirt
setblock ~161 ~122 ~107 dirt
setblock ~161 ~122 ~108 dirt
setblock ~161 ~122 ~109 dirt
setblock ~161 ~122 ~110 dirt
setblock ~161 ~122 ~111 dirt
setblock ~161 ~122 ~112 dirt
setblock ~161 ~122 ~113 dirt
setblock ~161 ~122 ~114 dirt
setblock ~161 ~122 ~115 dirt
setblock ~161 ~122 ~116 dirt
setblock ~161 ~122 ~117 dirt
setblock ~161 ~122 ~118 dirt
setblock ~161 ~122 ~119 dirt
setblock ~161 ~122 ~120 dirt
setblock ~161 ~122 ~121 dirt
setblock ~161 ~122 ~122 dirt
setblock ~161 ~122 ~123 dirt
setblock ~161 ~122 ~124 dirt
setblock ~161 ~122 ~125 dirt
setblock ~161 ~122 ~126 dirt
setblock ~161 ~122 ~127 dirt
setblock ~161 ~122 ~128 dirt
setblock ~161 ~122 ~129 dirt
setblock ~161 ~122 ~130 dirt
setblock ~161 ~122 ~131 dirt
setblock ~161 ~122 ~132 dirt
setblock ~161 ~122 ~133 dirt
setblock ~161 ~122 ~134 dirt
setblock ~161 ~122 ~135 dirt
setblock ~161 ~122 ~136 dirt
setblock ~161 ~122 ~137 dirt
setblock ~161 ~122 ~138 dirt
setblock ~161 ~122 ~139 dirt
setblock ~161 ~122 ~140 grass_block
setblock ~161 ~122 ~141 dirt
setblock ~161 ~122 ~142 dirt
setblock ~161 ~122 ~143 dirt
setblock ~161 ~122 ~144 dirt
setblock ~161 ~122 ~145 dirt
setblock ~161 ~122 ~146 dirt
setblock ~161 ~122 ~147 dirt
setblock ~161 ~122 ~148 dirt
setblock ~161 ~122 ~149 dirt
setblock ~161 ~122 ~150 dirt
setblock ~161 ~122 ~151 dirt
setblock ~161 ~122 ~152 dirt
setblock ~161 ~122 ~153 dirt
setblock ~161 ~122 ~154 dirt
setblock ~161 ~122 ~155 dirt
setblock ~161 ~122 ~156 dirt
setblock ~161 ~122 ~157 dirt
setblock ~161 ~122 ~158 dirt
setblock ~161 ~122 ~159 dirt
setblock ~161 ~122 ~160 dirt
setblock ~161 ~122 ~161 dirt
setblock ~161 ~122 ~162 dirt
setblock ~161 ~122 ~163 dirt
setblock ~161 ~122 ~164 dirt
setblock ~161 ~122 ~165 dirt
setblock ~161 ~122 ~166 dirt
setblock ~161 ~122 ~167 dirt
setblock ~161 ~122 ~168 dirt
setblock ~161 ~122 ~169 dirt
setblock ~161 ~122 ~170 dirt
setblock ~161 ~122 ~171 dirt
setblock ~161 ~122 ~172 dirt
setblock ~161 ~122 ~173 dirt
setblock ~161 ~122 ~174 dirt
setblock ~161 ~122 ~175 dirt
setblock ~161 ~122 ~176 dirt
setblock ~161 ~122 ~177 dirt
setblock ~161 ~122 ~178 dirt
setblock ~161 ~122 ~179 dirt
setblock ~161 ~122 ~180 dirt
setblock ~161 ~122 ~181 dirt
setblock ~161 ~122 ~182 dirt
setblock ~161 ~122 ~183 dirt
setblock ~161 ~122 ~184 dirt
setblock ~161 ~122 ~185 dirt
setblock ~161 ~122 ~186 dirt
setblock ~161 ~122 ~187 dirt
setblock ~161 ~122 ~188 dirt
setblock ~161 ~122 ~189 dirt
setblock ~161 ~122 ~190 dirt
setblock ~161 ~122 ~191 dirt
setblock ~161 ~122 ~192 dirt
setblock ~161 ~122 ~193 dirt
setblock ~161 ~122 ~194 dirt
setblock ~161 ~122 ~195 dirt
setblock ~161 ~122 ~196 dirt
setblock ~161 ~122 ~197 dirt
setblock ~161 ~122 ~198 dirt
setblock ~161 ~122 ~199 dirt
setblock ~161 ~123 ~0 dirt
setblock ~161 ~123 ~1 dirt
setblock ~161 ~123 ~2 dirt
setblock ~161 ~123 ~3 dirt
setblock ~161 ~123 ~4 dirt
setblock ~161 ~123 ~5 dirt
setblock ~161 ~123 ~6 dirt
setblock ~161 ~123 ~7 dirt
setblock ~161 ~123 ~8 dirt
setblock ~161 ~123 ~9 dirt
setblock ~161 ~123 ~10 dirt
setblock ~161 ~123 ~11 dirt
setblock ~161 ~123 ~12 dirt
setblock ~161 ~123 ~13 dirt
setblock ~161 ~123 ~14 dirt
setblock ~161 ~123 ~15 dirt
setblock ~161 ~123 ~16 grass_block
setblock ~161 ~123 ~17 grass_block
setblock ~161 ~123 ~18 grass_block
setblock ~161 ~123 ~20 short_grass
setblock ~161 ~123 ~22 poppy
setblock ~161 ~123 ~25 short_grass
setblock ~161 ~123 ~27 short_grass
setblock ~161 ~123 ~28 short_grass
setblock ~161 ~123 ~31 grass_block
setblock ~161 ~123 ~32 grass_block
setblock ~161 ~123 ~33 dirt
setblock ~161 ~123 ~34 dirt
setblock ~161 ~123 ~35 dirt
setblock ~161 ~123 ~36 dirt
setblock ~161 ~123 ~37 dirt
setblock ~161 ~123 ~38 dirt
setblock ~161 ~123 ~39 dirt
setblock ~161 ~123 ~40 dirt
setblock ~161 ~123 ~41 dirt
setblock ~161 ~123 ~42 dirt
setblock ~161 ~123 ~43 dirt
setblock ~161 ~123 ~44 dirt
setblock ~161 ~123 ~45 dirt
setblock ~161 ~123 ~46 dirt
setblock ~161 ~123 ~47 dirt
setblock ~161 ~123 ~48 dirt
setblock ~161 ~123 ~49 dirt
setblock ~161 ~123 ~50 dirt
setblock ~161 ~123 ~51 dirt
setblock ~161 ~123 ~52 dirt
setblock ~161 ~123 ~53 dirt
setblock ~161 ~123 ~54 dirt
setblock ~161 ~123 ~55 dirt
setblock ~161 ~123 ~56 grass_block
setblock ~161 ~123 ~57 grass_block
setblock ~161 ~123 ~58 grass_block
setblock ~161 ~123 ~59 grass_block
setblock ~161 ~123 ~60 grass_block
setblock ~161 ~123 ~61 grass_block
setblock ~161 ~123 ~62 grass_block
setblock ~161 ~123 ~63 dirt
setblock ~161 ~123 ~64 dirt
setblock ~161 ~123 ~65 dirt
setblock ~161 ~123 ~66 dirt
setblock ~161 ~123 ~67 dirt
setblock ~161 ~123 ~68 dirt
setblock ~161 ~123 ~69 dirt
setblock ~161 ~123 ~70 dirt
setblock ~161 ~123 ~71 dirt
setblock ~161 ~123 ~72 dirt
setblock ~161 ~123 ~73 dirt
setblock ~161 ~123 ~74 dirt
setblock ~161 ~123 ~75 dirt
setblock ~161 ~123 ~76 dirt
setblock ~161 ~123 ~77 dirt
setblock ~161 ~123 ~78 dirt
setblock ~161 ~123 ~79 dirt
setblock ~161 ~123 ~80 dirt
setblock ~161 ~123 ~81 dirt
setblock ~161 ~123 ~82 dirt
setblock ~161 ~123 ~83 dirt
setblock ~161 ~123 ~84 dirt
setblock ~161 ~123 ~85 dirt
setblock ~161 ~123 ~86 dirt
setblock ~161 ~123 ~87 dirt
setblock ~161 ~123 ~88 dirt
setblock ~161 ~123 ~89 dirt
setblock ~161 ~123 ~90 dirt
setblock ~161 ~123 ~91 dirt
setblock ~161 ~123 ~92 dirt
setblock ~161 ~123 ~93 dirt
setblock ~161 ~123 ~94 dirt
setblock ~161 ~123 ~95 dirt
setblock ~161 ~123 ~96 dirt
setblock ~161 ~123 ~97 dirt
setblock ~161 ~123 ~98 dirt
setblock ~161 ~123 ~99 dirt
setblock ~161 ~123 ~100 dirt
setblock ~161 ~123 ~101 dirt
setblock ~161 ~123 ~102 dirt
setblock ~161 ~123 ~103 dirt
setblock ~161 ~123 ~104 dirt
setblock ~161 ~123 ~105 dirt
setblock ~161 ~123 ~106 dirt
setblock ~161 ~123 ~107 dirt
setblock ~161 ~123 ~108 dirt
setblock ~161 ~123 ~109 dirt
setblock ~161 ~123 ~110 dirt
setblock ~161 ~123 ~111 dirt
setblock ~161 ~123 ~112 dirt
setblock ~161 ~123 ~113 dirt
setblock ~161 ~123 ~114 dirt
setblock ~161 ~123 ~115 dirt
setblock ~161 ~123 ~116 dirt
setblock ~161 ~123 ~117 dirt
setblock ~161 ~123 ~118 dirt
setblock ~161 ~123 ~119 dirt
setblock ~161 ~123 ~120 dirt
setblock ~161 ~123 ~121 grass_block
setblock ~161 ~123 ~122 grass_block
setblock ~161 ~123 ~123 grass_block
setblock ~161 ~123 ~124 grass_block
setblock ~161 ~123 ~125 grass_block
setblock ~161 ~123 ~126 grass_block
setblock ~161 ~123 ~127 grass_block
setblock ~161 ~123 ~128 grass_block
setblock ~161 ~123 ~129 grass_block
setblock ~161 ~123 ~130 grass_block
setblock ~161 ~123 ~131 grass_block
setblock ~161 ~123 ~132 grass_block
setblock ~161 ~123 ~133 grass_block
setblock ~161 ~123 ~134 grass_block
setblock ~161 ~123 ~135 grass_block
setblock ~161 ~123 ~136 grass_block
setblock ~161 ~123 ~137 grass_block
setblock ~161 ~123 ~138 grass_block
setblock ~161 ~123 ~139 grass_block
setblock ~161 ~123 ~141 grass_block
setblock ~161 ~123 ~142 grass_block
setblock ~161 ~123 ~143 dirt
setblock ~161 ~123 ~144 dirt
setblock ~161 ~123 ~145 dirt
setblock ~161 ~123 ~146 dirt
setblock ~161 ~123 ~147 dirt
setblock ~161 ~123 ~148 dirt
setblock ~161 ~123 ~149 dirt
setblock ~161 ~123 ~150 dirt
setblock ~161 ~123 ~151 dirt
setblock ~161 ~123 ~152 dirt
setblock ~161 ~123 ~153 dirt
setblock ~161 ~123 ~154 dirt
setblock ~161 ~123 ~155 dirt
setblock ~161 ~123 ~156 dirt
setblock ~161 ~123 ~157 dirt
setblock ~161 ~123 ~158 dirt
setblock ~161 ~123 ~159 dirt
setblock ~161 ~123 ~160 dirt
setblock ~161 ~123 ~161 dirt
setblock ~161 ~123 ~162 dirt
setblock ~161 ~123 ~163 dirt
setblock ~161 ~123 ~164 dirt
setblock ~161 ~123 ~165 dirt
setblock ~161 ~123 ~166 dirt
setblock ~161 ~123 ~167 dirt
setblock ~161 ~123 ~168 dirt
setblock ~161 ~123 ~169 dirt
setblock ~161 ~123 ~170 dirt
setblock ~161 ~123 ~171 dirt
setblock ~161 ~123 ~172 dirt
setblock ~161 ~123 ~173 dirt
setblock ~161 ~123 ~174 dirt
setblock ~161 ~123 ~175 dirt
setblock ~161 ~123 ~176 dirt
setblock ~161 ~123 ~177 dirt
setblock ~161 ~123 ~178 dirt
setblock ~161 ~123 ~179 grass_block
setblock ~161 ~123 ~180 grass_block
setblock ~161 ~123 ~181 grass_block
setblock ~161 ~123 ~182 dirt
setblock ~161 ~123 ~183 dirt
setblock ~161 ~123 ~184 dirt
setblock ~161 ~123 ~185 dirt
setblock ~161 ~123 ~186 dirt
setblock ~161 ~123 ~187 dirt
setblock ~161 ~123 ~188 dirt
setblock ~161 ~123 ~189 dirt
setblock ~161 ~123 ~190 dirt
setblock ~161 ~123 ~191 dirt
setblock ~161 ~123 ~192 dirt
setblock ~161 ~123 ~193 dirt
setblock ~161 ~123 ~194 dirt
setblock ~161 ~123 ~195 dirt
setblock ~161 ~123 ~196 dirt
setblock ~161 ~123 ~197 dirt
setblock ~161 ~123 ~198 dirt
setblock ~161 ~123 ~199 dirt
setblock ~161 ~124 ~0 grass_block
setblock ~161 ~124 ~1 grass_block
setblock ~161 ~124 ~2 grass_block
setblock ~161 ~124 ~3 grass_block
setblock ~161 ~124 ~4 dirt
setblock ~161 ~124 ~5 dirt
setblock ~161 ~124 ~6 dirt
setblock ~161 ~124 ~7 dirt
setblock ~161 ~124 ~8 dirt
setblock ~161 ~124 ~9 dirt
setblock ~161 ~124 ~10 dirt
setblock ~161 ~124 ~11 dirt
setblock ~161 ~124 ~12 dirt
setblock ~161 ~124 ~13 dirt
setblock ~161 ~124 ~14 grass_block
setblock ~161 ~124 ~15 grass_block
setblock ~161 ~124 ~17 short_grass
setblock ~161 ~124 ~33 grass_block
setblock ~161 ~124 ~34 grass_block
setblock ~161 ~124 ~35 dirt
setblock ~161 ~124 ~36 dirt
setblock ~161 ~124 ~37 dirt
setblock ~161 ~124 ~38 dirt
setblock ~161 ~124 ~39 dirt
setblock ~161 ~124 ~40 dirt
setblock ~161 ~124 ~41 dirt
setblock ~161 ~124 ~42 dirt
setblock ~161 ~124 ~43 dirt
setblock ~161 ~124 ~44 dirt
setblock ~161 ~124 ~45 dirt
setblock ~161 ~124 ~46 dirt
setblock ~161 ~124 ~47 dirt
setblock ~161 ~124 ~48 dirt
setblock ~161 ~124 ~49 dirt
setblock ~161 ~124 ~50 grass_block
setblock ~161 ~124 ~51 grass_block
setblock ~161 ~124 ~52 grass_block
setblock ~161 ~124 ~53 grass_block
setblock ~161 ~124 ~54 grass_block
setblock ~161 ~124 ~55 grass_block
setblock ~161 ~124 ~56 fern
setblock ~161 ~124 ~61 short_grass
setblock ~161 ~124 ~63 grass_block
setblock ~161 ~124 ~64 grass_block
setblock ~161 ~124 ~65 grass_block
setblock ~161 ~124 ~66 grass_block
setblock ~161 ~124 ~67 grass_block
setblock ~161 ~124 ~68 dirt
setblock ~161 ~124 ~69 dirt
setblock ~161 ~124 ~70 dirt
setblock ~161 ~124 ~71 dirt
setblock ~161 ~124 ~72 dirt
setblock ~161 ~124 ~73 dirt
setblock ~161 ~124 ~74 dirt
setblock ~161 ~124 ~75 dirt
setblock ~161 ~124 ~76 dirt
setblock ~161 ~124 ~77 dirt
setblock ~161 ~124 ~78 dirt
setblock ~161 ~124 ~79 dirt
setblock ~161 ~124 ~80 dirt
setblock ~161 ~124 ~81 dirt
setblock ~161 ~124 ~82 dirt
setblock ~161 ~124 ~83 dirt
setblock ~161 ~124 ~84 dirt
setblock ~161 ~124 ~85 dirt
setblock ~161 ~124 ~86 dirt
setblock ~161 ~124 ~87 dirt
setblock ~161 ~124 ~88 dirt
setblock ~161 ~124 ~89 dirt
setblock ~161 ~124 ~90 dirt
setblock ~161 ~124 ~91 dirt
setblock ~161 ~124 ~92 dirt
setblock ~161 ~124 ~93 dirt
setblock ~161 ~124 ~94 dirt
setblock ~161 ~124 ~95 dirt
setblock ~161 ~124 ~96 dirt
setblock ~161 ~124 ~97 dirt
setblock ~161 ~124 ~98 dirt
setblock ~161 ~124 ~99 dirt
setblock ~161 ~124 ~100 dirt
setblock ~161 ~124 ~101 dirt
setblock ~161 ~124 ~102 dirt
setblock ~161 ~124 ~103 dirt
setblock ~161 ~124 ~104 dirt
setblock ~161 ~124 ~105 dirt
setblock ~161 ~124 ~106 grass_block
setblock ~161 ~124 ~107 grass_block
setblock ~161 ~124 ~108 grass_block
setblock ~161 ~124 ~109 grass_block
setblock ~161 ~124 ~110 grass_block
setblock ~161 ~124 ~111 grass_block
setblock ~161 ~124 ~112 grass_block
setblock ~161 ~124 ~113 grass_block
setblock ~161 ~124 ~114 grass_block
setblock ~161 ~124 ~115 grass_block
setblock ~161 ~124 ~116 grass_block
setblock ~161 ~124 ~117 grass_block
setblock ~161 ~124 ~118 grass_block
setblock ~161 ~124 ~119 grass_block
setblock ~161 ~124 ~120 grass_block
setblock ~161 ~124 ~124 short_grass
setblock ~161 ~124 ~126 short_grass
setblock ~161 ~124 ~128 short_grass
setblock ~161 ~124 ~135 short_grass
setblock ~161 ~124 ~136 fern
setblock ~161 ~124 ~137 short_grass
setblock ~161 ~124 ~138 short_grass
setblock ~161 ~124 ~139 short_grass
setblock ~161 ~124 ~142 short_grass
setblock ~161 ~124 ~143 grass_block
setblock ~161 ~124 ~144 grass_block
setblock ~161 ~124 ~145 grass_block
setblock ~161 ~124 ~146 grass_block
setblock ~161 ~124 ~147 grass_block
setblock ~161 ~124 ~148 grass_block
setblock ~161 ~124 ~149 grass_block
setblock ~161 ~124 ~150 grass_block
setblock ~161 ~124 ~151 dirt
setblock ~161 ~124 ~152 dirt
setblock ~161 ~124 ~153 dirt
setblock ~161 ~124 ~154 dirt
setblock ~161 ~124 ~155 dirt
setblock ~161 ~124 ~156 dirt
setblock ~161 ~124 ~157 dirt
setblock ~161 ~124 ~158 dirt
setblock ~161 ~124 ~159 dirt
setblock ~161 ~124 ~160 dirt
setblock ~161 ~124 ~161 dirt
setblock ~161 ~124 ~162 dirt
setblock ~161 ~124 ~163 dirt
setblock ~161 ~124 ~164 dirt
setblock ~161 ~124 ~165 dirt
setblock ~161 ~124 ~166 dirt
setblock ~161 ~124 ~167 dirt
setblock ~161 ~124 ~168 dirt
setblock ~161 ~124 ~169 dirt
setblock ~161 ~124 ~170 dirt
setblock ~161 ~124 ~171 dirt
setblock ~161 ~124 ~172 dirt
setblock ~161 ~124 ~173 dirt
setblock ~161 ~124 ~174 dirt
setblock ~161 ~124 ~175 dirt
setblock ~161 ~124 ~176 dirt
setblock ~161 ~124 ~177 grass_block
setblock ~161 ~124 ~178 grass_block
setblock ~161 ~124 ~181 short_grass
setblock ~161 ~124 ~182 grass_block
setblock ~161 ~124 ~183 grass_block
setblock ~161 ~124 ~184 dirt
setblock ~161 ~124 ~185 dirt
setblock ~161 ~124 ~186 dirt
setblock ~161 ~124 ~187 dirt
setblock ~161 ~124 ~188 dirt
setblock ~161 ~124 ~189 dirt
setblock ~161 ~124 ~190 dirt
setblock ~161 ~124 ~191 dirt
setblock ~161 ~124 ~192 dirt
setblock ~161 ~124 ~193 dirt
setblock ~161 ~124 ~194 dirt
setblock ~161 ~124 ~195 dirt
setblock ~161 ~124 ~196 dirt
setblock ~161 ~124 ~197 dirt
setblock ~161 ~124 ~198 dirt
setblock ~161 ~124 ~199 dirt
setblock ~161 ~125 ~2 short_grass
setblock ~161 ~125 ~4 grass_block
setblock ~161 ~125 ~5 grass_block
setblock ~161 ~125 ~6 grass_block
setblock ~161 ~125 ~7 dirt
setblock ~161 ~125 ~8 dirt
setblock ~161 ~125 ~9 dirt
setblock ~161 ~125 ~10 dirt
setblock ~161 ~125 ~11 dirt
setblock ~161 ~125 ~12 dirt
setblock ~161 ~125 ~13 grass_block
setblock ~161 ~125 ~33 poppy
setblock ~161 ~125 ~35 grass_block
setblock ~161 ~125 ~36 grass_block
setblock ~161 ~125 ~37 dirt
setblock ~161 ~125 ~38 dirt
setblock ~161 ~125 ~39 dirt
setblock ~161 ~125 ~40 dirt
setblock ~161 ~125 ~41 dirt
setblock ~161 ~125 ~42 dirt
setblock ~161 ~125 ~43 dirt
setblock ~161 ~125 ~44 dirt
setblock ~161 ~125 ~45 dirt
setblock ~161 ~125 ~46 dirt
setblock ~161 ~125 ~47 dirt
setblock ~161 ~125 ~48 grass_block
setblock ~161 ~125 ~49 grass_block
setblock ~161 ~125 ~54 short_grass
setblock ~161 ~125 ~55 short_grass
setblock ~161 ~125 ~67 short_grass
setblock ~161 ~125 ~68 grass_block
setblock ~161 ~125 ~69 grass_block
setblock ~161 ~125 ~70 grass_block
setblock ~161 ~125 ~71 grass_block
setblock ~161 ~125 ~72 grass_block
setblock ~161 ~125 ~73 grass_block
setblock ~161 ~125 ~74 dirt
setblock ~161 ~125 ~75 dirt
setblock ~161 ~125 ~76 dirt
setblock ~161 ~125 ~77 dirt
setblock ~161 ~125 ~78 dirt
setblock ~161 ~125 ~79 dirt
setblock ~161 ~125 ~80 dirt
setblock ~161 ~125 ~81 dirt
setblock ~161 ~125 ~82 dirt
setblock ~161 ~125 ~83 dirt
setblock ~161 ~125 ~84 dirt
setblock ~161 ~125 ~85 dirt
setblock ~161 ~125 ~86 dirt
setblock ~161 ~125 ~87 dirt
setblock ~161 ~125 ~88 dirt
setblock ~161 ~125 ~89 dirt
setblock ~161 ~125 ~90 dirt
setblock ~161 ~125 ~91 dirt
setblock ~161 ~125 ~92 dirt
setblock ~161 ~125 ~93 dirt
setblock ~161 ~125 ~94 dirt
setblock ~161 ~125 ~95 dirt
setblock ~161 ~125 ~96 dirt
setblock ~161 ~125 ~97 dirt
setblock ~161 ~125 ~98 grass_block
setblock ~161 ~125 ~99 grass_block
setblock ~161 ~125 ~100 grass_block
setblock ~161 ~125 ~101 grass_block
setblock ~161 ~125 ~102 grass_block
setblock ~161 ~125 ~103 grass_block
setblock ~161 ~125 ~104 grass_block
setblock ~161 ~125 ~105 grass_block
setblock ~161 ~125 ~106 fern
setblock ~161 ~125 ~109 short_grass
setblock ~161 ~125 ~113 short_grass
setblock ~161 ~125 ~118 short_grass
setblock ~161 ~125 ~120 fern
setblock ~161 ~125 ~144 short_grass
setblock ~161 ~125 ~145 short_grass
setblock ~161 ~125 ~147 short_grass
setblock ~161 ~125 ~151 grass_block
setblock ~161 ~125 ~152 grass_block
setblock ~161 ~125 ~153 grass_block
setblock ~161 ~125 ~154 grass_block
setblock ~161 ~125 ~155 grass_block
setblock ~161 ~125 ~156 dirt
setblock ~161 ~125 ~157 dirt
setblock ~161 ~125 ~158 dirt
setblock ~161 ~125 ~159 dirt
setblock ~161 ~125 ~160 dirt
setblock ~161 ~125 ~161 dirt
setblock ~161 ~125 ~162 dirt
setblock ~161 ~125 ~163 dirt
setblock ~161 ~125 ~164 dirt
setblock ~161 ~125 ~165 dirt
setblock ~161 ~125 ~166 dirt
setblock ~161 ~125 ~167 dirt
setblock ~161 ~125 ~168 dirt
setblock ~161 ~125 ~169 dirt
setblock ~161 ~125 ~170 dirt
setblock ~161 ~125 ~171 dirt
setblock ~161 ~125 ~172 dirt
setblock ~161 ~125 ~173 dirt
setblock ~161 ~125 ~174 grass_block
setblock ~161 ~125 ~175 grass_block
setblock ~161 ~125 ~176 grass_block
setblock ~161 ~125 ~184 grass_block
setblock ~161 ~125 ~185 grass_block
setblock ~161 ~125 ~186 grass_block
setblock ~161 ~125 ~187 dirt
setblock ~161 ~125 ~188 dirt
setblock ~161 ~125 ~189 dirt
setblock ~161 ~125 ~190 dirt
setblock ~161 ~125 ~191 dirt
setblock ~161 ~125 ~192 dirt
setblock ~161 ~125 ~193 dirt
setblock ~161 ~125 ~194 dirt
setblock ~161 ~125 ~195 dirt
setblock ~161 ~125 ~196 dirt
setblock ~161 ~125 ~197 dirt
setblock ~161 ~125 ~198 dirt
setblock ~161 ~125 ~199 dirt
setblock ~161 ~126 ~6 poppy
setblock ~161 ~126 ~7 grass_block
setblock ~161 ~126 ~8 dirt
setblock ~161 ~126 ~9 dirt
setblock ~161 ~126 ~10 dirt
setblock ~161 ~126 ~11 dirt
setblock ~161 ~126 ~12 grass_block
setblock ~161 ~126 ~37 grass_block
setblock ~161 ~126 ~38 grass_block
setblock ~161 ~126 ~39 dirt
setblock ~161 ~126 ~40 dirt
setblock ~161 ~126 ~41 dirt
setblock ~161 ~126 ~42 dirt
setblock ~161 ~126 ~43 dirt
setblock ~161 ~126 ~44 dirt
setblock ~161 ~126 ~45 grass_block
setblock ~161 ~126 ~46 grass_block
setblock ~161 ~126 ~47 grass_block
setblock ~161 ~126 ~74 grass_block
setblock ~161 ~126 ~75 grass_block
setblock ~161 ~126 ~76 grass_block
setblock ~161 ~126 ~77 grass_block
setblock ~161 ~126 ~78 grass_block
setblock ~161 ~126 ~79 dirt
setblock ~161 ~126 ~80 dirt
setblock ~161 ~126 ~81 dirt
setblock ~161 ~126 ~82 dirt
setblock ~161 ~126 ~83 dirt
setblock ~161 ~126 ~84 dirt
setblock ~161 ~126 ~85 dirt
setblock ~161 ~126 ~86 dirt
setblock ~161 ~126 ~87 dirt
setblock ~161 ~126 ~88 dirt
setblock ~161 ~126 ~89 dirt
setblock ~161 ~126 ~90 dirt
setblock ~161 ~126 ~91 dirt
setblock ~161 ~126 ~92 grass_block
setblock ~161 ~126 ~93 grass_block
setblock ~161 ~126 ~94 grass_block
setblock ~161 ~126 ~95 grass_block
setblock ~161 ~126 ~96 grass_block
setblock ~161 ~126 ~97 grass_block
setblock ~161 ~126 ~99 fern
setblock ~161 ~126 ~104 short_grass
setblock ~161 ~126 ~156 grass_block
setblock ~161 ~126 ~157 grass_block
setblock ~161 ~126 ~158 dirt
setblock ~161 ~126 ~159 dirt
setblock ~161 ~126 ~160 dirt
setblock ~161 ~126 ~161 dirt
setblock ~161 ~126 ~162 dirt
setblock ~161 ~126 ~163 dirt
setblock ~161 ~126 ~164 dirt
setblock ~161 ~126 ~165 dirt
setblock ~161 ~126 ~166 dirt
setblock ~161 ~126 ~167 dirt
setblock ~161 ~126 ~168 dirt
setblock ~161 ~126 ~169 dirt
setblock ~161 ~126 ~170 dirt
setblock ~161 ~126 ~171 dirt
setblock ~161 ~126 ~172 grass_block
setblock ~161 ~126 ~173 grass_block
setblock ~161 ~126 ~174 short_grass
setblock ~161 ~126 ~175 fern
setblock ~161 ~126 ~187 grass_block
setblock ~161 ~126 ~188 grass_block
setblock ~161 ~126 ~189 grass_block
setblock ~161 ~126 ~190 grass_block
setblock ~161 ~126 ~191 grass_block
setblock ~161 ~126 ~192 dirt
setblock ~161 ~126 ~193 dirt
setblock ~161 ~126 ~194 dirt
setblock ~161 ~126 ~195 dirt
setblock ~161 ~126 ~196 dirt
setblock ~161 ~126 ~197 dirt
setblock ~161 ~126 ~198 dirt
setblock ~161 ~126 ~199 dirt
setblock ~161 ~127 ~8 grass_block
setblock ~161 ~127 ~9 dirt
setblock ~161 ~127 ~10 dirt
setblock ~161 ~127 ~11 grass_block
setblock ~161 ~127 ~39 grass_block
setblock ~161 ~127 ~40 grass_block
setblock ~161 ~127 ~41 grass_block
setblock ~161 ~127 ~42 grass_block
setblock ~161 ~127 ~43 grass_block
setblock ~161 ~127 ~44 grass_block
setblock ~161 ~127 ~45 fern
setblock ~161 ~127 ~75 short_grass
setblock ~161 ~127 ~79 grass_block
setblock ~161 ~127 ~80 grass_block
setblock ~161 ~127 ~81 grass_block
setblock ~161 ~127 ~82 grass_block
setblock ~161 ~127 ~83 grass_block
setblock ~161 ~127 ~84 grass_block
setblock ~161 ~127 ~85 grass_block
setblock ~161 ~127 ~86 grass_block
setblock ~161 ~127 ~87 grass_block
setblock ~161 ~127 ~88 grass_block
setblock ~161 ~127 ~89 grass_block
setblock ~161 ~127 ~90 grass_block
setblock ~161 ~127 ~91 grass_block
setblock ~161 ~127 ~93 short_grass
setblock ~161 ~127 ~95 short_grass
setblock ~161 ~127 ~97 short_grass
setblock ~161 ~127 ~158 grass_block
setblock ~161 ~127 ~159 dirt
setblock ~161 ~127 ~160 dirt
setblock ~161 ~127 ~161 dirt
setblock ~161 ~127 ~162 dirt
setblock ~161 ~127 ~163 dirt
setblock ~161 ~127 ~164 dirt
setblock ~161 ~127 ~165 dirt
setblock ~161 ~127 ~166 dirt
setblock ~161 ~127 ~167 dirt
setblock ~161 ~127 ~168 dirt
setblock ~161 ~127 ~169 dirt
setblock ~161 ~127 ~170 grass_block
setblock ~161 ~127 ~171 grass_block
setblock ~161 ~127 ~172 short_grass
setblock ~161 ~127 ~191 short_grass
setblock ~161 ~127 ~192 grass_block
setblock ~161 ~127 ~193 grass_block
setblock ~161 ~127 ~194 grass_block
setblock ~161 ~127 ~195 grass_block
setblock ~161 ~127 ~196 grass_block
setblock ~161 ~127 ~197 dirt
setblock ~161 ~127 ~198 dirt
setblock ~161 ~127 ~199 dirt
setblock ~161 ~128 ~9 grass_block
setblock ~161 ~128 ~10 dirt
setblock ~161 ~128 ~39 poppy
setblock ~161 ~128 ~40 short_grass
setblock ~161 ~128 ~41 short_grass
setblock ~161 ~128 ~79 short_grass
setblock ~161 ~128 ~80 fern
setblock ~161 ~128 ~85 poppy
setblock ~161 ~128 ~86 short_grass
setblock ~161 ~128 ~88 short_grass
setblock ~161 ~128 ~159 grass_block
setblock ~161 ~128 ~160 dirt
setblock ~161 ~128 ~161 dirt
setblock ~161 ~128 ~162 dirt
setblock ~161 ~128 ~163 grass_block
setblock ~161 ~128 ~164 grass_block
setblock ~161 ~128 ~165 grass_block
setblock ~161 ~128 ~166 grass_block
setblock ~161 ~128 ~167 grass_block
setblock ~161 ~128 ~168 grass_block
setblock ~161 ~128 ~169 grass_block
setblock ~161 ~128 ~170 poppy
setblock ~161 ~128 ~192 short_grass
setblock ~161 ~128 ~194 short_grass
setblock ~161 ~128 ~197 grass_block
setblock ~161 ~128 ~198 grass_block
setblock ~161 ~128 ~199 grass_block
setblock ~161 ~129 ~10 dirt
setblock ~161 ~129 ~159 short_grass
setblock ~161 ~129 ~160 grass_block
setblock ~161 ~129 ~161 grass_block
setblock ~161 ~129 ~162 grass_block
setblock ~161 ~129 ~163 short_grass
setblock ~161 ~129 ~198 short_grass
setblock ~161 ~130 ~10 grass_block
setblock ~161 ~130 ~161 fern
setblock ~161 ~130 ~162 poppy
setblock ~162 ~122 ~0 dirt
setblock ~162 ~122 ~1 dirt
setblock ~162 ~122 ~2 dirt
setblock ~162 ~122 ~3 dirt
setblock ~162 ~122 ~4 dirt
setblock ~162 ~122 ~5 dirt
setblock ~162 ~122 ~6 dirt
setblock ~162 ~122 ~7 dirt
setblock ~162 ~122 ~8 dirt
setblock ~162 ~122 ~9 dirt
setblock ~162 ~122 ~10 dirt
setblock ~162 ~122 ~11 dirt
setblock ~162 ~122 ~12 dirt
setblock ~162 ~122 ~13 dirt
setblock ~162 ~122 ~14 dirt
setblock ~162 ~122 ~15 dirt
setblock ~162 ~122 ~16 dirt
setblock ~162 ~122 ~17 dirt
setblock ~162 ~122 ~18 dirt
setblock ~162 ~122 ~19 grass_block
setblock ~162 ~122 ~20 grass_block
setblock ~162 ~122 ~21 grass_block
setblock ~162 ~122 ~22 grass_block
setblock ~162 ~122 ~23 grass_block
setblock ~162 ~122 ~24 grass_block
setblock ~162 ~122 ~25 grass_block
setblock ~162 ~122 ~26 grass_block
setblock ~162 ~122 ~27 grass_block
setblock ~162 ~122 ~28 grass_block
setblock ~162 ~122 ~29 grass_block
setblock ~162 ~122 ~30 grass_block
setblock ~162 ~122 ~31 dirt
setblock ~162 ~122 ~32 dirt
setblock ~162 ~122 ~33 dirt
setblock ~162 ~122 ~34 dirt
setblock ~162 ~122 ~35 dirt
setblock ~162 ~122 ~36 dirt
setblock ~162 ~122 ~37 dirt
setblock ~162 ~122 ~38 dirt
setblock ~162 ~122 ~39 dirt
setblock ~162 ~122 ~40 dirt
setblock ~162 ~122 ~41 dirt
setblock ~162 ~122 ~42 dirt
setblock ~162 ~122 ~43 dirt
setblock ~162 ~122 ~44 dirt
setblock ~162 ~122 ~45 dirt
setblock ~162 ~122 ~46 dirt
setblock ~162 ~122 ~47 dirt
setblock ~162 ~122 ~48 dirt
setblock ~162 ~122 ~49 dirt
setblock ~162 ~122 ~50 dirt
setblock ~162 ~122 ~51 dirt
setblock ~162 ~122 ~52 dirt
setblock ~162 ~122 ~53 dirt
setblock ~162 ~122 ~54 dirt
setblock ~162 ~122 ~55 dirt
setblock ~162 ~122 ~56 dirt
setblock ~162 ~122 ~57 dirt
setblock ~162 ~122 ~58 dirt
setblock ~162 ~122 ~59 dirt
setblock ~162 ~122 ~60 dirt
setblock ~162 ~122 ~61 dirt
setblock ~162 ~122 ~62 dirt
setblock ~162 ~122 ~63 dirt
setblock ~162 ~122 ~64 dirt
setblock ~162 ~122 ~65 dirt
setblock ~162 ~122 ~66 dirt
setblock ~162 ~122 ~67 dirt
setblock ~162 ~122 ~68 dirt
setblock ~162 ~122 ~69 dirt
setblock ~162 ~122 ~70 dirt
setblock ~162 ~122 ~71 dirt
setblock ~162 ~122 ~72 dirt
setblock ~162 ~122 ~73 dirt
setblock ~162 ~122 ~74 dirt
setblock ~162 ~122 ~75 dirt
setblock ~162 ~122 ~76 dirt
setblock ~162 ~122 ~77 dirt
setblock ~162 ~122 ~78 dirt
setblock ~162 ~122 ~79 dirt
setblock ~162 ~122 ~80 dirt
setblock ~162 ~122 ~81 dirt
setblock ~162 ~122 ~82 dirt
setblock ~162 ~122 ~83 dirt
setblock ~162 ~122 ~84 dirt
setblock ~162 ~122 ~85 dirt
setblock ~162 ~122 ~86 dirt
setblock ~162 ~122 ~87 dirt
setblock ~162 ~122 ~88 dirt
setblock ~162 ~122 ~89 dirt
setblock ~162 ~122 ~90 dirt
setblock ~162 ~122 ~91 dirt
setblock ~162 ~122 ~92 dirt
setblock ~162 ~122 ~93 dirt
setblock ~162 ~122 ~94 dirt
setblock ~162 ~122 ~95 dirt
setblock ~162 ~122 ~96 dirt
setblock ~162 ~122 ~97 dirt
setblock ~162 ~122 ~98 dirt
setblock ~162 ~122 ~99 dirt
setblock ~162 ~122 ~100 dirt
setblock ~162 ~122 ~101 dirt
setblock ~162 ~122 ~102 dirt
setblock ~162 ~122 ~103 dirt
setblock ~162 ~122 ~104 dirt
setblock ~162 ~122 ~105 dirt
setblock ~162 ~122 ~106 dirt
setblock ~162 ~122 ~107 dirt
setblock ~162 ~122 ~108 dirt
setblock ~162 ~122 ~109 dirt
setblock ~162 ~122 ~110 dirt
setblock ~162 ~122 ~111 dirt
setblock ~162 ~122 ~112 dirt
setblock ~162 ~122 ~113 dirt
setblock ~162 ~122 ~114 dirt
setblock ~162 ~122 ~115 dirt
setblock ~162 ~122 ~116 dirt
setblock ~162 ~122 ~117 dirt
setblock ~162 ~122 ~118 dirt
setblock ~162 ~122 ~119 dirt
setblock ~162 ~122 ~120 dirt
setblock ~162 ~122 ~121 dirt
setblock ~162 ~122 ~122 dirt
setblock ~162 ~122 ~123 dirt
setblock ~162 ~122 ~124 dirt
setblock ~162 ~122 ~125 dirt
setblock ~162 ~122 ~126 dirt
setblock ~162 ~122 ~127 dirt
setblock ~162 ~122 ~128 dirt
setblock ~162 ~122 ~129 dirt
setblock ~162 ~122 ~130 dirt
setblock ~162 ~122 ~131 dirt
setblock ~162 ~122 ~132 dirt
setblock ~162 ~122 ~133 dirt
setblock ~162 ~122 ~134 dirt
setblock ~162 ~122 ~135 dirt
setblock ~162 ~122 ~136 dirt
setblock ~162 ~122 ~137 dirt
setblock ~162 ~122 ~138 dirt
setblock ~162 ~122 ~139 dirt
setblock ~162 ~122 ~140 grass_block
setblock ~162 ~122 ~141 dirt
setblock ~162 ~122 ~142 dirt
setblock ~162 ~122 ~143 dirt
setblock ~162 ~122 ~144 dirt
setblock ~162 ~122 ~145 dirt
setblock ~162 ~122 ~146 dirt
setblock ~162 ~122 ~147 dirt
setblock ~162 ~122 ~148 dirt
setblock ~162 ~122 ~149 dirt
setblock ~162 ~122 ~150 dirt
setblock ~162 ~122 ~151 dirt
setblock ~162 ~122 ~152 dirt
setblock ~162 ~122 ~153 dirt
setblock ~162 ~122 ~154 dirt
setblock ~162 ~122 ~155 dirt
setblock ~162 ~122 ~156 dirt
setblock ~162 ~122 ~157 dirt
setblock ~162 ~122 ~158 dirt
setblock ~162 ~122 ~159 dirt
setblock ~162 ~122 ~160 dirt
setblock ~162 ~122 ~161 dirt
setblock ~162 ~122 ~162 dirt
setblock ~162 ~122 ~163 dirt
setblock ~162 ~122 ~164 dirt
setblock ~162 ~122 ~165 dirt
setblock ~162 ~122 ~166 dirt
setblock ~162 ~122 ~167 dirt
setblock ~162 ~122 ~168 dirt
setblock ~162 ~122 ~169 dirt
setblock ~162 ~122 ~170 dirt
setblock ~162 ~122 ~171 dirt
setblock ~162 ~122 ~172 dirt
setblock ~162 ~122 ~173 dirt
setblock ~162 ~122 ~174 dirt
setblock ~162 ~122 ~175 dirt
setblock ~162 ~122 ~176 dirt
setblock ~162 ~122 ~177 dirt
setblock ~162 ~122 ~178 dirt
setblock ~162 ~122 ~179 dirt
setblock ~162 ~122 ~180 dirt
setblock ~162 ~122 ~181 dirt
setblock ~162 ~122 ~182 dirt
setblock ~162 ~122 ~183 dirt
setblock ~162 ~122 ~184 dirt
setblock ~162 ~122 ~185 dirt
setblock ~162 ~122 ~186 dirt
setblock ~162 ~122 ~187 dirt
setblock ~162 ~122 ~188 dirt
setblock ~162 ~122 ~189 dirt
setblock ~162 ~122 ~190 dirt
setblock ~162 ~122 ~191 dirt
setblock ~162 ~122 ~192 dirt
setblock ~162 ~122 ~193 dirt
setblock ~162 ~122 ~194 dirt
setblock ~162 ~122 ~195 dirt
setblock ~162 ~122 ~196 dirt
setblock ~162 ~122 ~197 dirt
setblock ~162 ~122 ~198 dirt
setblock ~162 ~122 ~199 dirt
setblock ~162 ~123 ~0 dirt
setblock ~162 ~123 ~1 dirt
setblock ~162 ~123 ~2 dirt
setblock ~162 ~123 ~3 dirt
setblock ~162 ~123 ~4 dirt
setblock ~162 ~123 ~5 dirt
setblock ~162 ~123 ~6 dirt
setblock ~162 ~123 ~7 dirt
setblock ~162 ~123 ~8 dirt
setblock ~162 ~123 ~9 dirt
setblock ~162 ~123 ~10 dirt
setblock ~162 ~123 ~11 dirt
setblock ~162 ~123 ~12 dirt
setblock ~162 ~123 ~13 dirt
setblock ~162 ~123 ~14 dirt
setblock ~162 ~123 ~15 dirt
setblock ~162 ~123 ~16 grass_block
setblock ~162 ~123 ~17 grass_block
setblock ~162 ~123 ~18 grass_block
setblock ~162 ~123 ~21 short_grass
setblock ~162 ~123 ~24 short_grass
setblock ~162 ~123 ~25 fern
setblock ~162 ~123 ~31 grass_block
setblock ~162 ~123 ~32 grass_block
setblock ~162 ~123 ~33 dirt
setblock ~162 ~123 ~34 dirt
setblock ~162 ~123 ~35 dirt
setblock ~162 ~123 ~36 dirt
setblock ~162 ~123 ~37 dirt
setblock ~162 ~123 ~38 dirt
setblock ~162 ~123 ~39 dirt
setblock ~162 ~123 ~40 dirt
setblock ~162 ~123 ~41 dirt
setblock ~162 ~123 ~42 dirt
setblock ~162 ~123 ~43 dirt
setblock ~162 ~123 ~44 dirt
setblock ~162 ~123 ~45 dirt
setblock ~162 ~123 ~46 dirt
setblock ~162 ~123 ~47 dirt
setblock ~162 ~123 ~48 dirt
setblock ~162 ~123 ~49 dirt
setblock ~162 ~123 ~50 dirt
setblock ~162 ~123 ~51 dirt
setblock ~162 ~123 ~52 dirt
setblock ~162 ~123 ~53 dirt
setblock ~162 ~123 ~54 dirt
setblock ~162 ~123 ~55 grass_block
setblock ~162 ~123 ~56 grass_block
setblock ~162 ~123 ~57 grass_block
setblock ~162 ~123 ~58 grass_block
setblock ~162 ~123 ~59 grass_block
setblock ~162 ~123 ~60 grass_block
setblock ~162 ~123 ~61 grass_block
setblock ~162 ~123 ~62 grass_block
setblock ~162 ~123 ~63 dirt
setblock ~162 ~123 ~64 dirt
setblock ~162 ~123 ~65 dirt
setblock ~162 ~123 ~66 dirt
setblock ~162 ~123 ~67 dirt
setblock ~162 ~123 ~68 dirt
setblock ~162 ~123 ~69 dirt
setblock ~162 ~123 ~70 dirt
setblock ~162 ~123 ~71 dirt
setblock ~162 ~123 ~72 dirt
setblock ~162 ~123 ~73 dirt
setblock ~162 ~123 ~74 dirt
setblock ~162 ~123 ~75 dirt
setblock ~162 ~123 ~76 dirt
setblock ~162 ~123 ~77 dirt
setblock ~162 ~123 ~78 dirt
setblock ~162 ~123 ~79 dirt
setblock ~162 ~123 ~80 dirt
setblock ~162 ~123 ~81 dirt
setblock ~162 ~123 ~82 dirt
setblock ~162 ~123 ~83 dirt
setblock ~162 ~123 ~84 dirt
setblock ~162 ~123 ~85 dirt
setblock ~162 ~123 ~86 dirt
setblock ~162 ~123 ~87 dirt
setblock ~162 ~123 ~88 dirt
setblock ~162 ~123 ~89 dirt
setblock ~162 ~123 ~90 dirt
setblock ~162 ~123 ~91 dirt
setblock ~162 ~123 ~92 dirt
setblock ~162 ~123 ~93 dirt
setblock ~162 ~123 ~94 dirt
setblock ~162 ~123 ~95 dirt
setblock ~162 ~123 ~96 dirt
setblock ~162 ~123 ~97 dirt
setblock ~162 ~123 ~98 dirt
setblock ~162 ~123 ~99 dirt
setblock ~162 ~123 ~100 dirt
setblock ~162 ~123 ~101 dirt
setblock ~162 ~123 ~102 dirt
setblock ~162 ~123 ~103 dirt
setblock ~162 ~123 ~104 dirt
setblock ~162 ~123 ~105 dirt
setblock ~162 ~123 ~106 dirt
setblock ~162 ~123 ~107 dirt
setblock ~162 ~123 ~108 dirt
setblock ~162 ~123 ~109 dirt
setblock ~162 ~123 ~110 dirt
setblock ~162 ~123 ~111 dirt
setblock ~162 ~123 ~112 dirt
setblock ~162 ~123 ~113 dirt
setblock ~162 ~123 ~114 dirt
setblock ~162 ~123 ~115 dirt
setblock ~162 ~123 ~116 dirt
setblock ~162 ~123 ~117 dirt
setblock ~162 ~123 ~118 dirt
setblock ~162 ~123 ~119 dirt
setblock ~162 ~123 ~120 dirt
setblock ~162 ~123 ~121 dirt
setblock ~162 ~123 ~122 dirt
setblock ~162 ~123 ~123 dirt
setblock ~162 ~123 ~124 dirt
setblock ~162 ~123 ~125 grass_block
setblock ~162 ~123 ~126 grass_block
setblock ~162 ~123 ~127 grass_block
setblock ~162 ~123 ~128 grass_block
setblock ~162 ~123 ~129 grass_block
setblock ~162 ~123 ~130 grass_block
setblock ~162 ~123 ~131 grass_block
setblock ~162 ~123 ~132 grass_block
setblock ~162 ~123 ~133 grass_block
setblock ~162 ~123 ~134 grass_block
setblock ~162 ~123 ~135 grass_block
setblock ~162 ~123 ~136 grass_block
setblock ~162 ~123 ~137 grass_block
setblock ~162 ~123 ~138 grass_block
setblock ~162 ~123 ~139 grass_block
setblock ~162 ~123 ~140 short_grass
setblock ~162 ~123 ~141 grass_block
setblock ~162 ~123 ~142 grass_block
setblock ~162 ~123 ~143 dirt
setblock ~162 ~123 ~144 dirt
setblock ~162 ~123 ~145 dirt
setblock ~162 ~123 ~146 dirt
setblock ~162 ~123 ~147 dirt
setblock ~162 ~123 ~148 dirt
setblock ~162 ~123 ~149 dirt
setblock ~162 ~123 ~150 dirt
setblock ~162 ~123 ~151 dirt
setblock ~162 ~123 ~152 dirt
setblock ~162 ~123 ~153 dirt
setblock ~162 ~123 ~154 dirt
setblock ~162 ~123 ~155 dirt
setblock ~162 ~123 ~156 dirt
setblock ~162 ~123 ~157 dirt
setblock ~162 ~123 ~158 dirt
setblock ~162 ~123 ~159 dirt
setblock ~162 ~123 ~160 dirt
setblock ~162 ~123 ~161 dirt
setblock ~162 ~123 ~162 dirt
setblock ~162 ~123 ~163 dirt
setblock ~162 ~123 ~164 dirt
setblock ~162 ~123 ~165 dirt
setblock ~162 ~123 ~166 dirt
setblock ~162 ~123 ~167 dirt
setblock ~162 ~123 ~168 dirt
setblock ~162 ~123 ~169 dirt
setblock ~162 ~123 ~170 dirt
setblock ~162 ~123 ~171 dirt
setblock ~162 ~123 ~172 dirt
setblock ~162 ~123 ~173 dirt
setblock ~162 ~123 ~174 dirt
setblock ~162 ~123 ~175 dirt
setblock ~162 ~123 ~176 dirt
setblock ~162 ~123 ~177 dirt
setblock ~162 ~123 ~178 dirt
setblock ~162 ~123 ~179 dirt
setblock ~162 ~123 ~180 grass_block
setblock ~162 ~123 ~181 dirt
setblock ~162 ~123 ~182 dirt
setblock ~162 ~123 ~183 dirt
setblock ~162 ~123 ~184 dirt
setblock ~162 ~123 ~185 dirt
setblock ~162 ~123 ~186 dirt
setblock ~162 ~123 ~187 dirt
setblock ~162 ~123 ~188 dirt
setblock ~162 ~123 ~189 dirt
setblock ~162 ~123 ~190 dirt
setblock ~162 ~123 ~191 dirt
setblock ~162 ~123 ~192 dirt
setblock ~162 ~123 ~193 dirt
setblock ~162 ~123 ~194 dirt
setblock ~162 ~123 ~195 dirt
setblock ~162 ~123 ~196 dirt
setblock ~162 ~123 ~197 dirt
setblock ~162 ~123 ~198 dirt
setblock ~162 ~123 ~199 dirt
setblock ~162 ~124 ~0 grass_block
setblock ~162 ~124 ~1 grass_block
setblock ~162 ~124 ~2 grass_block
setblock ~162 ~124 ~3 grass_block
setblock ~162 ~124 ~4 grass_block
setblock ~162 ~124 ~5 dirt
setblock ~162 ~124 ~6 dirt
setblock ~162 ~124 ~7 dirt
setblock ~162 ~124 ~8 dirt
setblock ~162 ~124 ~9 dirt
setblock ~162 ~124 ~10 dirt
setblock ~162 ~124 ~11 dirt
setblock ~162 ~124 ~12 dirt
setblock ~162 ~124 ~13 dirt
setblock ~162 ~124 ~14 grass_block
setblock ~162 ~124 ~15 grass_block
setblock ~162 ~124 ~17 short_grass
setblock ~162 ~124 ~18 fern
setblock ~162 ~124 ~33 grass_block
setblock ~162 ~124 ~34 grass_block
setblock ~162 ~124 ~35 dirt
setblock ~162 ~124 ~36 dirt
setblock ~162 ~124 ~37 dirt
setblock ~162 ~124 ~38 dirt
setblock ~162 ~124 ~39 dirt
setblock ~162 ~124 ~40 dirt
setblock ~162 ~124 ~41 dirt
setblock ~162 ~124 ~42 dirt
setblock ~162 ~124 ~43 dirt
setblock ~162 ~124 ~44 dirt
setblock ~162 ~124 ~45 dirt
setblock ~162 ~124 ~46 dirt
setblock ~162 ~124 ~47 dirt
setblock ~162 ~124 ~48 dirt
setblock ~162 ~124 ~49 dirt
setblock ~162 ~124 ~50 grass_block
setblock ~162 ~124 ~51 grass_block
setblock ~162 ~124 ~52 grass_block
setblock ~162 ~124 ~53 grass_block
setblock ~162 ~124 ~54 grass_block
setblock ~162 ~124 ~55 fern
setblock ~162 ~124 ~57 short_grass
setblock ~162 ~124 ~59 short_grass
setblock ~162 ~124 ~60 short_grass
setblock ~162 ~124 ~63 grass_block
setblock ~162 ~124 ~64 grass_block
setblock ~162 ~124 ~65 grass_block
setblock ~162 ~124 ~66 grass_block
setblock ~162 ~124 ~67 dirt
setblock ~162 ~124 ~68 dirt
setblock ~162 ~124 ~69 dirt
setblock ~162 ~124 ~70 dirt
setblock ~162 ~124 ~71 dirt
setblock ~162 ~124 ~72 dirt
setblock ~162 ~124 ~73 dirt
setblock ~162 ~124 ~74 dirt
setblock ~162 ~124 ~75 dirt
setblock ~162 ~124 ~76 dirt
setblock ~162 ~124 ~77 dirt
setblock ~162 ~124 ~78 dirt
setblock ~162 ~124 ~79 dirt
setblock ~162 ~124 ~80 dirt
setblock ~162 ~124 ~81 dirt
setblock ~162 ~124 ~82 dirt
setblock ~162 ~124 ~83 dirt
setblock ~162 ~124 ~84 dirt
setblock ~162 ~124 ~85 dirt
setblock ~162 ~124 ~86 dirt
setblock ~162 ~124 ~87 dirt
setblock ~162 ~124 ~88 dirt
setblock ~162 ~124 ~89 dirt
setblock ~162 ~124 ~90 dirt
setblock ~162 ~124 ~91 dirt
setblock ~162 ~124 ~92 dirt
setblock ~162 ~124 ~93 dirt
setblock ~162 ~124 ~94 dirt
setblock ~162 ~124 ~95 dirt
setblock ~162 ~124 ~96 dirt
setblock ~162 ~124 ~97 dirt
setblock ~162 ~124 ~98 dirt
setblock ~162 ~124 ~99 dirt
setblock ~162 ~124 ~100 dirt
setblock ~162 ~124 ~101 dirt
setblock ~162 ~124 ~102 dirt
setblock ~162 ~124 ~103 dirt
setblock ~162 ~124 ~104 dirt
setblock ~162 ~124 ~105 dirt
setblock ~162 ~124 ~106 dirt
setblock ~162 ~124 ~107 grass_block
setblock ~162 ~124 ~108 grass_block
setblock ~162 ~124 ~109 grass_block
setblock ~162 ~124 ~110 grass_block
setblock ~162 ~124 ~111 grass_block
setblock ~162 ~124 ~112 grass_block
setblock ~162 ~124 ~113 grass_block
setblock ~162 ~124 ~114 grass_block
setblock ~162 ~124 ~115 grass_block
setblock ~162 ~124 ~116 grass_block
setblock ~162 ~124 ~117 grass_block
setblock ~162 ~124 ~118 grass_block
setblock ~162 ~124 ~119 grass_block
setblock ~162 ~124 ~120 grass_block
setblock ~162 ~124 ~121 grass_block
setblock ~162 ~124 ~122 grass_block
setblock ~162 ~124 ~123 grass_block
setblock ~162 ~124 ~124 grass_block
setblock ~162 ~124 ~126 short_grass
setblock ~162 ~124 ~129 short_grass
setblock ~162 ~124 ~139 short_grass
setblock ~162 ~124 ~141 short_grass
setblock ~162 ~124 ~142 short_grass
setblock ~162 ~124 ~143 grass_block
setblock ~162 ~124 ~144 grass_block
setblock ~162 ~124 ~145 grass_block
setblock ~162 ~124 ~146 grass_block
setblock ~162 ~124 ~147 grass_block
setblock ~162 ~124 ~148 grass_block
setblock ~162 ~124 ~149 dirt
setblock ~162 ~124 ~150 dirt
setblock ~162 ~124 ~151 dirt
setblock ~162 ~124 ~152 dirt
setblock ~162 ~124 ~153 dirt
setblock ~162 ~124 ~154 dirt
setblock ~162 ~124 ~155 dirt
setblock ~162 ~124 ~156 dirt
setblock ~162 ~124 ~157 dirt
setblock ~162 ~124 ~158 dirt
setblock ~162 ~124 ~159 dirt
setblock ~162 ~124 ~160 dirt
setblock ~162 ~124 ~161 dirt
setblock ~162 ~124 ~162 dirt
setblock ~162 ~124 ~163 dirt
setblock ~162 ~124 ~164 dirt
setblock ~162 ~124 ~165 dirt
setblock ~162 ~124 ~166 dirt
setblock ~162 ~124 ~167 dirt
setblock ~162 ~124 ~168 dirt
setblock ~162 ~124 ~169 dirt
setblock ~162 ~124 ~170 dirt
setblock ~162 ~124 ~171 dirt
setblock ~162 ~124 ~172 dirt
setblock ~162 ~124 ~173 dirt
setblock ~162 ~124 ~174 dirt
setblock ~162 ~124 ~175 dirt
setblock ~162 ~124 ~176 dirt
setblock ~162 ~124 ~177 grass_block
setblock ~162 ~124 ~178 grass_block
setblock ~162 ~124 ~179 grass_block
setblock ~162 ~124 ~181 grass_block
setblock ~162 ~124 ~182 grass_block
setblock ~162 ~124 ~183 dirt
setblock ~162 ~124 ~184 dirt
setblock ~162 ~124 ~185 dirt
setblock ~162 ~124 ~186 dirt
setblock ~162 ~124 ~187 dirt
setblock ~162 ~124 ~188 dirt
setblock ~162 ~124 ~189 dirt
setblock ~162 ~124 ~190 dirt
setblock ~162 ~124 ~191 dirt
setblock ~162 ~124 ~192 dirt
setblock ~162 ~124 ~193 dirt
setblock ~162 ~124 ~194 dirt
setblock ~162 ~124 ~195 dirt
setblock ~162 ~124 ~196 dirt
setblock ~162 ~124 ~197 dirt
setblock ~162 ~124 ~198 dirt
setblock ~162 ~124 ~199 dirt
setblock ~162 ~125 ~5 grass_block
setblock ~162 ~125 ~6 grass_block
setblock ~162 ~125 ~7 grass_block
setblock ~162 ~125 ~8 dirt
setblock ~162 ~125 ~9 dirt
setblock ~162 ~125 ~10 dirt
setblock ~162 ~125 ~11 dirt
setblock ~162 ~125 ~12 grass_block
setblock ~162 ~125 ~13 grass_block
setblock ~162 ~125 ~14 fern
setblock ~162 ~125 ~15 short_grass
setblock ~162 ~125 ~34 short_grass
setblock ~162 ~125 ~35 grass_block
setblock ~162 ~125 ~36 grass_block
setblock ~162 ~125 ~37 dirt
setblock ~162 ~125 ~38 dirt
setblock ~162 ~125 ~39 dirt
setblock ~162 ~125 ~40 dirt
setblock ~162 ~125 ~41 dirt
setblock ~162 ~125 ~42 dirt
setblock ~162 ~125 ~43 dirt
setblock ~162 ~125 ~44 dirt
setblock ~162 ~125 ~45 dirt
setblock ~162 ~125 ~46 dirt
setblock ~162 ~125 ~47 grass_block
setblock ~162 ~125 ~48 grass_block
setblock ~162 ~125 ~49 grass_block
setblock ~162 ~125 ~51 short_grass
setblock ~162 ~125 ~54 short_grass
setblock ~162 ~125 ~67 grass_block
setblock ~162 ~125 ~68 grass_block
setblock ~162 ~125 ~69 grass_block
setblock ~162 ~125 ~70 grass_block
setblock ~162 ~125 ~71 grass_block
setblock ~162 ~125 ~72 grass_block
setblock ~162 ~125 ~73 grass_block
setblock ~162 ~125 ~74 grass_block
setblock ~162 ~125 ~75 dirt
setblock ~162 ~125 ~76 dirt
setblock ~162 ~125 ~77 dirt
setblock ~162 ~125 ~78 dirt
setblock ~162 ~125 ~79 dirt
setblock ~162 ~125 ~80 dirt
setblock ~162 ~125 ~81 dirt
setblock ~162 ~125 ~82 dirt
setblock ~162 ~125 ~83 dirt
setblock ~162 ~125 ~84 dirt
setblock ~162 ~125 ~85 dirt
setblock ~162 ~125 ~86 dirt
setblock ~162 ~125 ~87 dirt
setblock ~162 ~125 ~88 dirt
setblock ~162 ~125 ~89 dirt
setblock ~162 ~125 ~90 dirt
setblock ~162 ~125 ~91 dirt
setblock ~162 ~125 ~92 dirt
setblock ~162 ~125 ~93 dirt
setblock ~162 ~125 ~94 dirt
setblock ~162 ~125 ~95 dirt
setblock ~162 ~125 ~96 dirt
setblock ~162 ~125 ~97 dirt
setblock ~162 ~125 ~98 grass_block
setblock ~162 ~125 ~99 grass_block
setblock ~162 ~125 ~100 grass_block
setblock ~162 ~125 ~101 grass_block
setblock ~162 ~125 ~102 grass_block
setblock ~162 ~125 ~103 grass_block
setblock ~162 ~125 ~104 grass_block
setblock ~162 ~125 ~105 grass_block
setblock ~162 ~125 ~106 grass_block
setblock ~162 ~125 ~107 short_grass
setblock ~162 ~125 ~108 short_grass
setblock ~162 ~125 ~110 short_grass
setblock ~162 ~125 ~111 short_grass
setblock ~162 ~125 ~113 short_grass
setblock ~162 ~125 ~115 short_grass
setblock ~162 ~125 ~116 short_grass
setblock ~162 ~125 ~118 poppy
setblock ~162 ~125 ~122 fern
setblock ~162 ~125 ~146 fern
setblock ~162 ~125 ~148 short_grass
setblock ~162 ~125 ~149 grass_block
setblock ~162 ~125 ~150 grass_block
setblock ~162 ~125 ~151 grass_block
setblock ~162 ~125 ~152 grass_block
setblock ~162 ~125 ~153 grass_block
setblock ~162 ~125 ~154 grass_block
setblock ~162 ~125 ~155 grass_block
setblock ~162 ~125 ~156 dirt
setblock ~162 ~125 ~157 dirt
setblock ~162 ~125 ~158 dirt
setblock ~162 ~125 ~159 dirt
setblock ~162 ~125 ~160 dirt
setblock ~162 ~125 ~161 dirt
setblock ~162 ~125 ~162 dirt
setblock ~162 ~125 ~163 dirt
setblock ~162 ~125 ~164 dirt
setblock ~162 ~125 ~165 dirt
setblock ~162 ~125 ~166 dirt
setblock ~162 ~125 ~167 dirt
setblock ~162 ~125 ~168 dirt
setblock ~162 ~125 ~169 dirt
setblock ~162 ~125 ~170 dirt
setblock ~162 ~125 ~171 dirt
setblock ~162 ~125 ~172 dirt
setblock ~162 ~125 ~173 dirt
setblock ~162 ~125 ~174 dirt
setblock ~162 ~125 ~175 grass_block
setblock ~162 ~125 ~176 grass_block
setblock ~162 ~125 ~178 short_grass
setblock ~162 ~125 ~179 poppy
setblock ~162 ~125 ~182 short_grass
setblock ~162 ~125 ~183 grass_block
setblock ~162 ~125 ~184 grass_block
setblock ~162 ~125 ~185 grass_block
setblock ~162 ~125 ~186 grass_block
setblock ~162 ~125 ~187 dirt
setblock ~162 ~125 ~188 dirt
setblock ~162 ~125 ~189 dirt
setblock ~162 ~125 ~190 dirt
setblock ~162 ~125 ~191 dirt
setblock ~162 ~125 ~192 dirt
setblock ~162 ~125 ~193 dirt
setblock ~162 ~125 ~194 dirt
setblock ~162 ~125 ~195 dirt
setblock ~162 ~125 ~196 dirt
setblock ~162 ~125 ~197 dirt
setblock ~162 ~125 ~198 dirt
setblock ~162 ~125 ~199 dirt
setblock ~162 ~126 ~5 fern
setblock ~162 ~126 ~6 short_grass
setblock ~162 ~126 ~8 grass_block
setblock ~162 ~126 ~9 dirt
setblock ~162 ~126 ~10 dirt
setblock ~162 ~126 ~11 grass_block
setblock ~162 ~126 ~12 short_grass
setblock ~162 ~126 ~35 short_grass
setblock ~162 ~126 ~36 short_grass
setblock ~162 ~126 ~37 grass_block
setblock ~162 ~126 ~38 grass_block
setblock ~162 ~126 ~39 dirt
setblock ~162 ~126 ~40 dirt
setblock ~162 ~126 ~41 dirt
setblock ~162 ~126 ~42 dirt
setblock ~162 ~126 ~43 dirt
setblock ~162 ~126 ~44 grass_block
setblock ~162 ~126 ~45 grass_block
setblock ~162 ~126 ~46 grass_block
setblock ~162 ~126 ~48 short_grass
setblock ~162 ~126 ~49 short_grass
setblock ~162 ~126 ~67 short_grass
setblock ~162 ~126 ~72 short_grass
setblock ~162 ~126 ~74 short_grass
setblock ~162 ~126 ~75 grass_block
setblock ~162 ~126 ~76 grass_block
setblock ~162 ~126 ~77 grass_block
setblock ~162 ~126 ~78 grass_block
setblock ~162 ~126 ~79 grass_block
setblock ~162 ~126 ~80 grass_block
setblock ~162 ~126 ~81 grass_block
setblock ~162 ~126 ~82 grass_block
setblock ~162 ~126 ~83 grass_block
setblock ~162 ~126 ~84 grass_block
setblock ~162 ~126 ~85 grass_block
setblock ~162 ~126 ~86 grass_block
setblock ~162 ~126 ~87 grass_block
setblock ~162 ~126 ~88 grass_block
setblock ~162 ~126 ~89 grass_block
setblock ~162 ~126 ~90 dirt
setblock ~162 ~126 ~91 grass_block
setblock ~162 ~126 ~92 grass_block
setblock ~162 ~126 ~93 grass_block
setblock ~162 ~126 ~94 grass_block
setblock ~162 ~126 ~95 grass_block
setblock ~162 ~126 ~96 grass_block
setblock ~162 ~126 ~97 grass_block
setblock ~162 ~126 ~101 short_grass
setblock ~162 ~126 ~106 short_grass
setblock ~162 ~126 ~150 fern
setblock ~162 ~126 ~154 short_grass
setblock ~162 ~126 ~156 grass_block
setblock ~162 ~126 ~157 grass_block
setblock ~162 ~126 ~158 grass_block
setblock ~162 ~126 ~159 dirt
setblock ~162 ~126 ~160 dirt
setblock ~162 ~126 ~161 dirt
setblock ~162 ~126 ~162 dirt
setblock ~162 ~126 ~163 dirt
setblock ~162 ~126 ~164 dirt
setblock ~162 ~126 ~165 dirt
setblock ~162 ~126 ~166 dirt
setblock ~162 ~126 ~167 dirt
setblock ~162 ~126 ~168 dirt
setblock ~162 ~126 ~169 dirt
setblock ~162 ~126 ~170 dirt
setblock ~162 ~126 ~171 dirt
setblock ~162 ~126 ~172 dirt
setblock ~162 ~126 ~173 grass_block
setblock ~162 ~126 ~174 grass_block
setblock ~162 ~126 ~185 short_grass
setblock ~162 ~126 ~187 grass_block
setblock ~162 ~126 ~188 grass_block
setblock ~162 ~126 ~189 grass_block
setblock ~162 ~126 ~190 grass_block
setblock ~162 ~126 ~191 dirt
setblock ~162 ~126 ~192 dirt
setblock ~162 ~126 ~193 dirt
setblock ~162 ~126 ~194 dirt
setblock ~162 ~126 ~195 dirt
setblock ~162 ~126 ~196 dirt
setblock ~162 ~126 ~197 dirt
setblock ~162 ~126 ~198 dirt
setblock ~162 ~126 ~199 dirt
setblock ~162 ~127 ~9 grass_block
setblock ~162 ~127 ~10 dirt
setblock ~162 ~127 ~39 grass_block
setblock ~162 ~127 ~40 grass_block
setblock ~162 ~127 ~41 grass_block
setblock ~162 ~127 ~42 grass_block
setblock ~162 ~127 ~43 grass_block
setblock ~162 ~127 ~44 poppy
setblock ~162 ~127 ~45 short_grass
setblock ~162 ~127 ~76 short_grass
setblock ~162 ~127 ~82 short_grass
setblock ~162 ~127 ~85 poppy
setblock ~162 ~127 ~87 short_grass
setblock ~162 ~127 ~90 grass_block
setblock ~162 ~127 ~157 poppy
setblock ~162 ~127 ~158 short_grass
setblock ~162 ~127 ~159 grass_block
setblock ~162 ~127 ~160 dirt
setblock ~162 ~127 ~161 dirt
setblock ~162 ~127 ~162 dirt
setblock ~162 ~127 ~163 dirt
setblock ~162 ~127 ~164 dirt
setblock ~162 ~127 ~165 dirt
setblock ~162 ~127 ~166 dirt
setblock ~162 ~127 ~167 dirt
setblock ~162 ~127 ~168 dirt
setblock ~162 ~127 ~169 dirt
setblock ~162 ~127 ~170 dirt
setblock ~162 ~127 ~171 grass_block
setblock ~162 ~127 ~172 grass_block
setblock ~162 ~127 ~173 short_grass
setblock ~162 ~127 ~174 short_grass
setblock ~162 ~127 ~187 short_grass
setblock ~162 ~127 ~191 grass_block
setblock ~162 ~127 ~192 grass_block
setblock ~162 ~127 ~193 grass_block
setblock ~162 ~127 ~194 grass_block
setblock ~162 ~127 ~195 grass_block
setblock ~162 ~127 ~196 grass_block
setblock ~162 ~127 ~197 dirt
setblock ~162 ~127 ~198 dirt
setblock ~162 ~127 ~199 dirt
setblock ~162 ~128 ~10 grass_block
setblock ~162 ~128 ~40 short_grass
setblock ~162 ~128 ~160 grass_block
setblock ~162 ~128 ~161 grass_block
setblock ~162 ~128 ~162 grass_block
setblock ~162 ~128 ~163 grass_block
setblock ~162 ~128 ~164 grass_block
setblock ~162 ~128 ~165 grass_block
setblock ~162 ~128 ~166 grass_block
setblock ~162 ~128 ~167 grass_block
setblock ~162 ~128 ~168 grass_block
setblock ~162 ~128 ~169 grass_block
setblock ~162 ~128 ~170 grass_block
setblock ~162 ~128 ~171 short_grass
setblock ~162 ~128 ~194 short_grass
setblock ~162 ~128 ~197 grass_block
setblock ~162 ~128 ~198 grass_block
setblock ~162 ~128 ~199 grass_block
setblock ~162 ~129 ~10 poppy
setblock ~162 ~129 ~165 short_grass
setblock ~162 ~129 ~170 short_grass
setblock ~163 ~122 ~0 dirt
setblock ~163 ~122 ~1 dirt
setblock ~163 ~122 ~2 dirt
setblock ~163 ~122 ~3 dirt
setblock ~163 ~122 ~4 dirt
setblock ~163 ~122 ~5 dirt
setblock ~163 ~122 ~6 dirt
setblock ~163 ~122 ~7 dirt
setblock ~163 ~122 ~8 dirt
setblock ~163 ~122 ~9 dirt
setblock ~163 ~122 ~10 dirt
setblock ~163 ~122 ~11 dirt
setblock ~163 ~122 ~12 dirt
setblock ~163 ~122 ~13 dirt
setblock ~163 ~122 ~14 dirt
setblock ~163 ~122 ~15 dirt
setblock ~163 ~122 ~16 dirt
setblock ~163 ~122 ~17 dirt
setblock ~163 ~122 ~18 dirt
setblock ~163 ~122 ~19 grass_block
setblock ~163 ~122 ~20 grass_block
setblock ~163 ~122 ~21 grass_block
setblock ~163 ~122 ~22 grass_block
setblock ~163 ~122 ~23 grass_block
setblock ~163 ~122 ~24 grass_block
setblock ~163 ~122 ~25 dirt
setblock ~163 ~122 ~26 dirt
setblock ~163 ~122 ~27 dirt
setblock ~163 ~122 ~28 dirt
setblock ~163 ~122 ~29 dirt
setblock ~163 ~122 ~30 dirt
setblock ~163 ~122 ~31 dirt
setblock ~163 ~122 ~32 dirt
setblock ~163 ~122 ~33 dirt
setblock ~163 ~122 ~34 dirt
setblock ~163 ~122 ~35 dirt
setblock ~163 ~122 ~36 dirt
setblock ~163 ~122 ~37 dirt
setblock ~163 ~122 ~38 dirt
setblock ~163 ~122 ~39 dirt
setblock ~163 ~122 ~40 dirt
setblock ~163 ~122 ~41 dirt
setblock ~163 ~122 ~42 dirt
setblock ~163 ~122 ~43 dirt
setblock ~163 ~122 ~44 dirt
setblock ~163 ~122 ~45 dirt
setblock ~163 ~122 ~46 dirt
setblock ~163 ~122 ~47 dirt
setblock ~163 ~122 ~48 dirt
setblock ~163 ~122 ~49 dirt
setblock ~163 ~122 ~50 dirt
setblock ~163 ~122 ~51 dirt
setblock ~163 ~122 ~52 dirt
setblock ~163 ~122 ~53 dirt
setblock ~163 ~122 ~54 dirt
setblock ~163 ~122 ~55 dirt
setblock ~163 ~122 ~56 dirt
setblock ~163 ~122 ~57 dirt
setblock ~163 ~122 ~58 dirt
setblock ~163 ~122 ~59 dirt
setblock ~163 ~122 ~60 dirt
setblock ~163 ~122 ~61 dirt
setblock ~163 ~122 ~62 dirt
setblock ~163 ~122 ~63 dirt
setblock ~163 ~122 ~64 dirt
setblock ~163 ~122 ~65 dirt
setblock ~163 ~122 ~66 dirt
setblock ~163 ~122 ~67 dirt
setblock ~163 ~122 ~68 dirt
setblock ~163 ~122 ~69 dirt
setblock ~163 ~122 ~70 dirt
setblock ~163 ~122 ~71 dirt
setblock ~163 ~122 ~72 dirt
setblock ~163 ~122 ~73 dirt
setblock ~163 ~122 ~74 dirt
setblock ~163 ~122 ~75 dirt
setblock ~163 ~122 ~76 dirt
setblock ~163 ~122 ~77 dirt
setblock ~163 ~122 ~78 dirt
setblock ~163 ~122 ~79 dirt
setblock ~163 ~122 ~80 dirt
setblock ~163 ~122 ~81 dirt
setblock ~163 ~122 ~82 dirt
setblock ~163 ~122 ~83 dirt
setblock ~163 ~122 ~84 dirt
setblock ~163 ~122 ~85 dirt
setblock ~163 ~122 ~86 dirt
setblock ~163 ~122 ~87 dirt
setblock ~163 ~122 ~88 dirt
setblock ~163 ~122 ~89 dirt
setblock ~163 ~122 ~90 dirt
setblock ~163 ~122 ~91 dirt
setblock ~163 ~122 ~92 dirt
setblock ~163 ~122 ~93 dirt
setblock ~163 ~122 ~94 dirt
setblock ~163 ~122 ~95 dirt
setblock ~163 ~122 ~96 dirt
setblock ~163 ~122 ~97 dirt
setblock ~163 ~122 ~98 dirt
setblock ~163 ~122 ~99 dirt
setblock ~163 ~122 ~100 dirt
setblock ~163 ~122 ~101 dirt
setblock ~163 ~122 ~102 dirt
setblock ~163 ~122 ~103 dirt
setblock ~163 ~122 ~104 dirt
setblock ~163 ~122 ~105 dirt
setblock ~163 ~122 ~106 dirt
setblock ~163 ~122 ~107 dirt
setblock ~163 ~122 ~108 dirt
setblock ~163 ~122 ~109 dirt
setblock ~163 ~122 ~110 dirt
setblock ~163 ~122 ~111 dirt
setblock ~163 ~122 ~112 dirt
setblock ~163 ~122 ~113 dirt
setblock ~163 ~122 ~114 dirt
setblock ~163 ~122 ~115 dirt
setblock ~163 ~122 ~116 dirt
setblock ~163 ~122 ~117 dirt
setblock ~163 ~122 ~118 dirt
setblock ~163 ~122 ~119 dirt
setblock ~163 ~122 ~120 dirt
setblock ~163 ~122 ~121 dirt
setblock ~163 ~122 ~122 dirt
setblock ~163 ~122 ~123 dirt
setblock ~163 ~122 ~124 dirt
setblock ~163 ~122 ~125 dirt
setblock ~163 ~122 ~126 dirt
setblock ~163 ~122 ~127 dirt
setblock ~163 ~122 ~128 dirt
setblock ~163 ~122 ~129 dirt
setblock ~163 ~122 ~130 dirt
setblock ~163 ~122 ~131 dirt
setblock ~163 ~122 ~132 dirt
setblock ~163 ~122 ~133 dirt
setblock ~163 ~122 ~134 dirt
setblock ~163 ~122 ~135 dirt
setblock ~163 ~122 ~136 dirt
setblock ~163 ~122 ~137 dirt
setblock ~163 ~122 ~138 dirt
setblock ~163 ~122 ~139 dirt
setblock ~163 ~122 ~140 dirt
setblock ~163 ~122 ~141 dirt
setblock ~163 ~122 ~142 dirt
setblock ~163 ~122 ~143 dirt
setblock ~163 ~122 ~144 dirt
setblock ~163 ~122 ~145 dirt
setblock ~163 ~122 ~146 dirt
setblock ~163 ~122 ~147 dirt
setblock ~163 ~122 ~148 dirt
setblock ~163 ~122 ~149 dirt
setblock ~163 ~122 ~150 dirt
setblock ~163 ~122 ~151 dirt
setblock ~163 ~122 ~152 dirt
setblock ~163 ~122 ~153 dirt
setblock ~163 ~122 ~154 dirt
setblock ~163 ~122 ~155 dirt
setblock ~163 ~122 ~156 dirt
setblock ~163 ~122 ~157 dirt
setblock ~163 ~122 ~158 dirt
setblock ~163 ~122 ~159 dirt
setblock ~163 ~122 ~160 dirt
setblock ~163 ~122 ~161 dirt
setblock ~163 ~122 ~162 dirt
setblock ~163 ~122 ~163 dirt
setblock ~163 ~122 ~164 dirt
setblock ~163 ~122 ~165 dirt
setblock ~163 ~122 ~166 dirt
setblock ~163 ~122 ~167 dirt
setblock ~163 ~122 ~168 dirt
setblock ~163 ~122 ~169 dirt
setblock ~163 ~122 ~170 dirt
setblock ~163 ~122 ~171 dirt
setblock ~163 ~122 ~172 dirt
setblock ~163 ~122 ~173 dirt
setblock ~163 ~122 ~174 dirt
setblock ~163 ~122 ~175 dirt
setblock ~163 ~122 ~176 dirt
setblock ~163 ~122 ~177 dirt
setblock ~163 ~122 ~178 dirt
setblock ~163 ~122 ~179 dirt
setblock ~163 ~122 ~180 dirt
setblock ~163 ~122 ~181 dirt
setblock ~163 ~122 ~182 dirt
setblock ~163 ~122 ~183 dirt
setblock ~163 ~122 ~184 dirt
setblock ~163 ~122 ~185 dirt
setblock ~163 ~122 ~186 dirt
setblock ~163 ~122 ~187 dirt
setblock ~163 ~122 ~188 dirt
setblock ~163 ~122 ~189 dirt
setblock ~163 ~122 ~190 dirt
