setblock ~161 ~127 ~128 dirt
setblock ~161 ~128 ~91 short_grass
setblock ~161 ~128 ~118 short_grass
setblock ~161 ~128 ~122 short_grass
setblock ~161 ~128 ~123 short_grass
setblock ~161 ~128 ~125 grass_block
setblock ~161 ~128 ~126 grass_block
setblock ~161 ~128 ~127 grass_block
setblock ~161 ~128 ~128 grass_block
setblock ~161 ~129 ~126 short_grass
setblock ~162 ~102 ~95 dirt
setblock ~162 ~102 ~96 dirt
setblock ~162 ~103 ~95 dirt
setblock ~162 ~103 ~96 dirt
setblock ~162 ~103 ~97 dirt
setblock ~162 ~104 ~94 dirt
setblock ~162 ~104 ~95 dirt
setblock ~162 ~104 ~96 dirt
setblock ~162 ~104 ~97 dirt
setblock ~162 ~104 ~109 dirt
setblock ~162 ~105 ~94 dirt
setblock ~162 ~105 ~95 dirt
setblock ~162 ~105 ~96 dirt
setblock ~162 ~105 ~97 dirt
setblock ~162 ~105 ~98 dirt
setblock ~162 ~105 ~108 dirt
setblock ~162 ~105 ~109 dirt
setblock ~162 ~106 ~92 dirt
setblock ~162 ~106 ~93 dirt
setblock ~162 ~106 ~94 dirt
setblock ~162 ~106 ~95 dirt
setblock ~162 ~106 ~96 dirt
setblock ~162 ~106 ~97 dirt
setblock ~162 ~106 ~98 dirt
setblock ~162 ~106 ~107 dirt
setblock ~162 ~106 ~108 dirt
setblock ~162 ~106 ~109 dirt
setblock ~162 ~106 ~110 dirt
setblock ~162 ~107 ~91 dirt
setblock ~162 ~107 ~92 dirt
setblock ~162 ~107 ~93 dirt
setblock ~162 ~107 ~94 dirt
setblock ~162 ~107 ~95 dirt
setblock ~162 ~107 ~96 dirt
setblock ~162 ~107 ~97 dirt
setblock ~162 ~107 ~98 dirt
setblock ~162 ~107 ~107 dirt
setblock ~162 ~107 ~108 dirt
setblock ~162 ~107 ~109 dirt
setblock ~162 ~107 ~110 dirt
setblock ~162 ~107 ~111 dirt
setblock ~162 ~108 ~90 dirt
setblock ~162 ~108 ~91 dirt
setblock ~162 ~108 ~92 dirt
setblock ~162 ~108 ~93 dirt
setblock ~162 ~108 ~94 dirt
setblock ~162 ~108 ~95 dirt
setblock ~162 ~108 ~96 dirt
setblock ~162 ~108 ~97 dirt
setblock ~162 ~108 ~98 dirt
setblock ~162 ~108 ~99 dirt
setblock ~162 ~108 ~107 dirt
setblock ~162 ~108 ~108 dirt
setblock ~162 ~108 ~109 dirt
setblock ~162 ~108 ~110 dirt
setblock ~162 ~108 ~111 dirt
setblock ~162 ~109 ~90 dirt
setblock ~162 ~109 ~91 dirt
setblock ~162 ~109 ~92 dirt
setblock ~162 ~109 ~93 dirt
setblock ~162 ~109 ~94 dirt
setblock ~162 ~109 ~95 dirt
setblock ~162 ~109 ~96 dirt
setblock ~162 ~109 ~97 dirt
setblock ~162 ~109 ~98 dirt
setblock ~162 ~109 ~99 dirt
setblock ~162 ~109 ~102 dirt
setblock ~162 ~109 ~106 dirt
setblock ~162 ~109 ~107 dirt
setblock ~162 ~109 ~108 dirt
setblock ~162 ~109 ~109 dirt
setblock ~162 ~109 ~110 dirt
setblock ~162 ~109 ~111 dirt
setblock ~162 ~109 ~112 dirt
setblock ~162 ~110 ~90 dirt
setblock ~162 ~110 ~91 dirt
setblock ~162 ~110 ~92 dirt
setblock ~162 ~110 ~93 dirt
setblock ~162 ~110 ~94 dirt
setblock ~162 ~110 ~95 dirt
setblock ~162 ~110 ~96 dirt
setblock ~162 ~110 ~97 dirt
setblock ~162 ~110 ~98 dirt
setblock ~162 ~110 ~99 dirt
setblock ~162 ~110 ~100 dirt
setblock ~162 ~110 ~102 dirt
setblock ~162 ~110 ~104 dirt
setblock ~162 ~110 ~105 dirt
setblock ~162 ~110 ~106 dirt
setblock ~162 ~110 ~107 dirt
setblock ~162 ~110 ~108 dirt
setblock ~162 ~110 ~109 dirt
setblock ~162 ~110 ~110 dirt
setblock ~162 ~110 ~111 dirt
setblock ~162 ~110 ~112 dirt
setblock ~162 ~111 ~89 dirt
setblock ~162 ~111 ~90 dirt
setblock ~162 ~111 ~91 dirt
setblock ~162 ~111 ~92 dirt
setblock ~162 ~111 ~93 dirt
setblock ~162 ~111 ~94 dirt
setblock ~162 ~111 ~95 dirt
setblock ~162 ~111 ~96 dirt
setblock ~162 ~111 ~97 dirt
setblock ~162 ~111 ~98 dirt
setblock ~162 ~111 ~99 dirt
setblock ~162 ~111 ~100 dirt
setblock ~162 ~111 ~101 dirt
setblock ~162 ~111 ~102 dirt
setblock ~162 ~111 ~103 dirt
setblock ~162 ~111 ~104 dirt
setblock ~162 ~111 ~105 dirt
setblock ~162 ~111 ~106 dirt
setblock ~162 ~111 ~107 dirt
setblock ~162 ~111 ~108 dirt
setblock ~162 ~111 ~109 dirt
setblock ~162 ~111 ~110 dirt
setblock ~162 ~111 ~111 dirt
setblock ~162 ~111 ~112 dirt
setblock ~162 ~111 ~113 dirt
setblock ~162 ~111 ~114 dirt
setblock ~162 ~112 ~89 dirt
setblock ~162 ~112 ~90 dirt
setblock ~162 ~112 ~91 dirt
setblock ~162 ~112 ~92 dirt
setblock ~162 ~112 ~93 dirt
setblock ~162 ~112 ~94 dirt
setblock ~162 ~112 ~95 dirt
setblock ~162 ~112 ~96 dirt
setblock ~162 ~112 ~97 dirt
setblock ~162 ~112 ~98 dirt
setblock ~162 ~112 ~99 dirt
setblock ~162 ~112 ~100 dirt
setblock ~162 ~112 ~101 dirt
setblock ~162 ~112 ~102 dirt
setblock ~162 ~112 ~103 dirt
setblock ~162 ~112 ~104 dirt
setblock ~162 ~112 ~105 dirt
setblock ~162 ~112 ~106 dirt
setblock ~162 ~112 ~107 dirt
setblock ~162 ~112 ~108 dirt
setblock ~162 ~112 ~109 dirt
setblock ~162 ~112 ~110 dirt
setblock ~162 ~112 ~111 dirt
setblock ~162 ~112 ~112 dirt
setblock ~162 ~112 ~113 dirt
setblock ~162 ~112 ~114 dirt
setblock ~162 ~113 ~88 dirt
setblock ~162 ~113 ~89 dirt
setblock ~162 ~113 ~90 dirt
setblock ~162 ~113 ~91 dirt
setblock ~162 ~113 ~92 dirt
setblock ~162 ~113 ~93 dirt
setblock ~162 ~113 ~94 dirt
setblock ~162 ~113 ~95 dirt
setblock ~162 ~113 ~96 dirt
setblock ~162 ~113 ~97 dirt
setblock ~162 ~113 ~98 dirt
setblock ~162 ~113 ~99 dirt
setblock ~162 ~113 ~100 dirt
setblock ~162 ~113 ~101 dirt
setblock ~162 ~113 ~102 dirt
setblock ~162 ~113 ~103 dirt
setblock ~162 ~113 ~104 dirt
setblock ~162 ~113 ~105 dirt
setblock ~162 ~113 ~106 dirt
setblock ~162 ~113 ~107 dirt
setblock ~162 ~113 ~108 dirt
setblock ~162 ~113 ~109 dirt
setblock ~162 ~113 ~110 dirt
setblock ~162 ~113 ~111 dirt
setblock ~162 ~113 ~112 dirt
setblock ~162 ~113 ~113 dirt
setblock ~162 ~113 ~114 dirt
setblock ~162 ~113 ~115 dirt
setblock ~162 ~114 ~88 dirt
setblock ~162 ~114 ~89 dirt
setblock ~162 ~114 ~90 dirt
setblock ~162 ~114 ~91 dirt
setblock ~162 ~114 ~92 dirt
setblock ~162 ~114 ~93 dirt
setblock ~162 ~114 ~94 dirt
setblock ~162 ~114 ~95 dirt
setblock ~162 ~114 ~96 dirt
setblock ~162 ~114 ~97 dirt
setblock ~162 ~114 ~98 dirt
setblock ~162 ~114 ~99 dirt
setblock ~162 ~114 ~100 dirt
setblock ~162 ~114 ~101 dirt
setblock ~162 ~114 ~102 dirt
setblock ~162 ~114 ~103 dirt
setblock ~162 ~114 ~104 dirt
setblock ~162 ~114 ~105 dirt
setblock ~162 ~114 ~106 dirt
setblock ~162 ~114 ~107 dirt
setblock ~162 ~114 ~108 dirt
setblock ~162 ~114 ~109 dirt
setblock ~162 ~114 ~110 dirt
setblock ~162 ~114 ~111 dirt
setblock ~162 ~114 ~112 dirt
setblock ~162 ~114 ~113 dirt
setblock ~162 ~114 ~114 dirt
setblock ~162 ~114 ~115 dirt
setblock ~162 ~114 ~117 dirt
setblock ~162 ~115 ~87 dirt
setblock ~162 ~115 ~88 dirt
setblock ~162 ~115 ~89 dirt
setblock ~162 ~115 ~90 dirt
setblock ~162 ~115 ~91 dirt
setblock ~162 ~115 ~92 dirt
setblock ~162 ~115 ~93 dirt
setblock ~162 ~115 ~94 dirt
setblock ~162 ~115 ~95 dirt
setblock ~162 ~115 ~96 dirt
setblock ~162 ~115 ~97 dirt
setblock ~162 ~115 ~98 dirt
setblock ~162 ~115 ~99 dirt
setblock ~162 ~115 ~100 dirt
setblock ~162 ~115 ~101 dirt
setblock ~162 ~115 ~102 dirt
setblock ~162 ~115 ~103 dirt
setblock ~162 ~115 ~104 dirt
setblock ~162 ~115 ~105 dirt
setblock ~162 ~115 ~106 dirt
setblock ~162 ~115 ~107 dirt
setblock ~162 ~115 ~108 dirt
setblock ~162 ~115 ~109 dirt
setblock ~162 ~115 ~110 dirt
setblock ~162 ~115 ~111 dirt
setblock ~162 ~115 ~112 dirt
setblock ~162 ~115 ~113 dirt
setblock ~162 ~115 ~114 dirt
setblock ~162 ~115 ~115 dirt
setblock ~162 ~115 ~116 dirt
setblock ~162 ~115 ~117 dirt
setblock ~162 ~115 ~118 dirt
setblock ~162 ~115 ~119 dirt
setblock ~162 ~116 ~75 dirt
setblock ~162 ~116 ~79 dirt
setblock ~162 ~116 ~85 dirt
setblock ~162 ~116 ~87 dirt
setblock ~162 ~116 ~88 dirt
setblock ~162 ~116 ~89 dirt
setblock ~162 ~116 ~90 dirt
setblock ~162 ~116 ~91 dirt
setblock ~162 ~116 ~92 dirt
setblock ~162 ~116 ~93 dirt
setblock ~162 ~116 ~94 dirt
setblock ~162 ~116 ~95 dirt
setblock ~162 ~116 ~96 dirt
setblock ~162 ~116 ~97 dirt
setblock ~162 ~116 ~98 dirt
setblock ~162 ~116 ~99 dirt
setblock ~162 ~116 ~100 dirt
setblock ~162 ~116 ~101 dirt
setblock ~162 ~116 ~102 dirt
setblock ~162 ~116 ~103 dirt
setblock ~162 ~116 ~104 dirt
setblock ~162 ~116 ~105 dirt
setblock ~162 ~116 ~106 dirt
setblock ~162 ~116 ~107 dirt
setblock ~162 ~116 ~108 dirt
setblock ~162 ~116 ~109 dirt
setblock ~162 ~116 ~110 dirt
setblock ~162 ~116 ~111 dirt
setblock ~162 ~116 ~112 dirt
setblock ~162 ~116 ~113 dirt
setblock ~162 ~116 ~114 dirt
setblock ~162 ~116 ~115 dirt
setblock ~162 ~116 ~116 dirt
setblock ~162 ~116 ~117 dirt
setblock ~162 ~116 ~118 dirt
setblock ~162 ~116 ~119 dirt
setblock ~162 ~116 ~120 dirt
setblock ~162 ~116 ~121 dirt
setblock ~162 ~117 ~74 dirt
setblock ~162 ~117 ~75 dirt
setblock ~162 ~117 ~79 dirt
setblock ~162 ~117 ~81 dirt
setblock ~162 ~117 ~85 dirt
setblock ~162 ~117 ~86 dirt
setblock ~162 ~117 ~87 dirt
setblock ~162 ~117 ~88 dirt
setblock ~162 ~117 ~89 dirt
setblock ~162 ~117 ~90 dirt
setblock ~162 ~117 ~91 dirt
setblock ~162 ~117 ~92 dirt
setblock ~162 ~117 ~93 dirt
setblock ~162 ~117 ~94 dirt
setblock ~162 ~117 ~95 dirt
setblock ~162 ~117 ~96 dirt
setblock ~162 ~117 ~97 dirt
setblock ~162 ~117 ~98 dirt
setblock ~162 ~117 ~99 dirt
setblock ~162 ~117 ~100 dirt
setblock ~162 ~117 ~101 dirt
setblock ~162 ~117 ~102 dirt
setblock ~162 ~117 ~103 dirt
setblock ~162 ~117 ~104 dirt
setblock ~162 ~117 ~105 dirt
setblock ~162 ~117 ~106 dirt
setblock ~162 ~117 ~107 dirt
setblock ~162 ~117 ~108 dirt
setblock ~162 ~117 ~109 dirt
setblock ~162 ~117 ~110 dirt
setblock ~162 ~117 ~111 dirt
setblock ~162 ~117 ~112 dirt
setblock ~162 ~117 ~113 dirt
setblock ~162 ~117 ~114 dirt
setblock ~162 ~117 ~115 dirt
setblock ~162 ~117 ~116 dirt
setblock ~162 ~117 ~117 dirt
setblock ~162 ~117 ~118 dirt
setblock ~162 ~117 ~119 dirt
setblock ~162 ~117 ~120 dirt
setblock ~162 ~117 ~121 dirt
setblock ~162 ~118 ~73 dirt
setblock ~162 ~118 ~74 dirt
setblock ~162 ~118 ~75 dirt
setblock ~162 ~118 ~76 dirt
setblock ~162 ~118 ~79 dirt
setblock ~162 ~118 ~80 dirt
setblock ~162 ~118 ~81 dirt
setblock ~162 ~118 ~85 dirt
setblock ~162 ~118 ~86 dirt
setblock ~162 ~118 ~87 dirt
setblock ~162 ~118 ~88 dirt
setblock ~162 ~118 ~89 dirt
setblock ~162 ~118 ~90 dirt
setblock ~162 ~118 ~91 dirt
setblock ~162 ~118 ~92 dirt
setblock ~162 ~118 ~93 dirt
setblock ~162 ~118 ~94 dirt
setblock ~162 ~118 ~95 dirt
setblock ~162 ~118 ~96 dirt
setblock ~162 ~118 ~97 dirt
setblock ~162 ~118 ~98 dirt
setblock ~162 ~118 ~99 dirt
setblock ~162 ~118 ~100 dirt
setblock ~162 ~118 ~101 dirt
setblock ~162 ~118 ~102 dirt
setblock ~162 ~118 ~103 dirt
setblock ~162 ~118 ~104 dirt
setblock ~162 ~118 ~105 dirt
setblock ~162 ~118 ~106 dirt
setblock ~162 ~118 ~107 dirt
setblock ~162 ~118 ~108 dirt
setblock ~162 ~118 ~109 dirt
setblock ~162 ~118 ~110 dirt
setblock ~162 ~118 ~111 dirt
setblock ~162 ~118 ~112 dirt
setblock ~162 ~118 ~113 dirt
setblock ~162 ~118 ~114 dirt
setblock ~162 ~118 ~115 dirt
setblock ~162 ~118 ~116 dirt
setblock ~162 ~118 ~117 dirt
setblock ~162 ~118 ~118 dirt
setblock ~162 ~118 ~119 dirt
setblock ~162 ~118 ~120 dirt
setblock ~162 ~118 ~121 dirt
setblock ~162 ~118 ~122 dirt
setblock ~162 ~119 ~72 dirt
setblock ~162 ~119 ~73 dirt
setblock ~162 ~119 ~74 dirt
setblock ~162 ~119 ~75 dirt
setblock ~162 ~119 ~76 dirt
setblock ~162 ~119 ~77 dirt
setblock ~162 ~119 ~78 dirt
setblock ~162 ~119 ~79 dirt
setblock ~162 ~119 ~80 dirt
setblock ~162 ~119 ~81 dirt
setblock ~162 ~119 ~82 dirt
setblock ~162 ~119 ~83 dirt
setblock ~162 ~119 ~84 dirt
setblock ~162 ~119 ~85 dirt
setblock ~162 ~119 ~86 dirt
setblock ~162 ~119 ~87 dirt
setblock ~162 ~119 ~88 dirt
setblock ~162 ~119 ~89 dirt
setblock ~162 ~119 ~90 dirt
setblock ~162 ~119 ~91 dirt
setblock ~162 ~119 ~92 dirt
setblock ~162 ~119 ~93 dirt
setblock ~162 ~119 ~94 dirt
setblock ~162 ~119 ~95 dirt
setblock ~162 ~119 ~96 dirt
setblock ~162 ~119 ~97 dirt
setblock ~162 ~119 ~98 dirt
setblock ~162 ~119 ~99 dirt
setblock ~162 ~119 ~100 dirt
setblock ~162 ~119 ~101 dirt
setblock ~162 ~119 ~102 dirt
setblock ~162 ~119 ~103 dirt
setblock ~162 ~119 ~104 dirt
setblock ~162 ~119 ~105 dirt
setblock ~162 ~119 ~106 dirt
setblock ~162 ~119 ~107 dirt
setblock ~162 ~119 ~108 dirt
setblock ~162 ~119 ~109 dirt
setblock ~162 ~119 ~110 dirt
setblock ~162 ~119 ~111 dirt
setblock ~162 ~119 ~112 dirt
setblock ~162 ~119 ~113 dirt
setblock ~162 ~119 ~114 dirt
setblock ~162 ~119 ~115 dirt
setblock ~162 ~119 ~116 dirt
setblock ~162 ~119 ~117 dirt
setblock ~162 ~119 ~118 dirt
setblock ~162 ~119 ~119 dirt
setblock ~162 ~119 ~120 dirt
setblock ~162 ~119 ~121 dirt
setblock ~162 ~119 ~122 dirt
setblock ~162 ~120 ~71 dirt
setblock ~162 ~120 ~72 dirt
setblock ~162 ~120 ~73 dirt
setblock ~162 ~120 ~74 dirt
setblock ~162 ~120 ~75 dirt
setblock ~162 ~120 ~76 dirt
setblock ~162 ~120 ~77 dirt
setblock ~162 ~120 ~78 dirt
setblock ~162 ~120 ~79 dirt
setblock ~162 ~120 ~80 dirt
setblock ~162 ~120 ~81 dirt
setblock ~162 ~120 ~82 dirt
setblock ~162 ~120 ~83 dirt
setblock ~162 ~120 ~84 dirt
setblock ~162 ~120 ~85 dirt
setblock ~162 ~120 ~86 dirt
setblock ~162 ~120 ~87 dirt
setblock ~162 ~120 ~88 dirt
setblock ~162 ~120 ~89 dirt
setblock ~162 ~120 ~90 dirt
setblock ~162 ~120 ~91 dirt
setblock ~162 ~120 ~92 dirt
setblock ~162 ~120 ~93 dirt
setblock ~162 ~120 ~94 dirt
setblock ~162 ~120 ~95 dirt
setblock ~162 ~120 ~96 dirt
setblock ~162 ~120 ~97 dirt
setblock ~162 ~120 ~98 dirt
setblock ~162 ~120 ~99 dirt
setblock ~162 ~120 ~100 dirt
setblock ~162 ~120 ~101 dirt
setblock ~162 ~120 ~102 dirt
setblock ~162 ~120 ~103 dirt
setblock ~162 ~120 ~104 dirt
setblock ~162 ~120 ~105 dirt
setblock ~162 ~120 ~106 dirt
setblock ~162 ~120 ~107 dirt
setblock ~162 ~120 ~108 dirt
setblock ~162 ~120 ~109 dirt
setblock ~162 ~120 ~110 dirt
setblock ~162 ~120 ~111 dirt
setblock ~162 ~120 ~112 dirt
setblock ~162 ~120 ~113 dirt
setblock ~162 ~120 ~114 dirt
setblock ~162 ~120 ~115 dirt
setblock ~162 ~120 ~116 dirt
setblock ~162 ~120 ~117 dirt
setblock ~162 ~120 ~118 dirt
setblock ~162 ~120 ~119 dirt
setblock ~162 ~120 ~120 dirt
setblock ~162 ~120 ~121 dirt
setblock ~162 ~120 ~122 dirt
setblock ~162 ~120 ~123 dirt
setblock ~162 ~121 ~70 dirt
setblock ~162 ~121 ~71 dirt
setblock ~162 ~121 ~72 dirt
setblock ~162 ~121 ~73 dirt
setblock ~162 ~121 ~74 dirt
setblock ~162 ~121 ~75 dirt
setblock ~162 ~121 ~76 dirt
setblock ~162 ~121 ~77 dirt
setblock ~162 ~121 ~78 dirt
setblock ~162 ~121 ~79 dirt
setblock ~162 ~121 ~80 dirt
setblock ~162 ~121 ~81 dirt
setblock ~162 ~121 ~82 dirt
setblock ~162 ~121 ~83 dirt
setblock ~162 ~121 ~84 dirt
setblock ~162 ~121 ~85 dirt
setblock ~162 ~121 ~86 dirt
setblock ~162 ~121 ~87 dirt
setblock ~162 ~121 ~88 dirt
setblock ~162 ~121 ~89 dirt
setblock ~162 ~121 ~90 dirt
setblock ~162 ~121 ~91 dirt
setblock ~162 ~121 ~92 dirt
setblock ~162 ~121 ~93 dirt
setblock ~162 ~121 ~94 dirt
setblock ~162 ~121 ~95 dirt
setblock ~162 ~121 ~96 dirt
setblock ~162 ~121 ~97 dirt
setblock ~162 ~121 ~98 dirt
setblock ~162 ~121 ~99 dirt
setblock ~162 ~121 ~100 dirt
setblock ~162 ~121 ~101 dirt
setblock ~162 ~121 ~102 dirt
setblock ~162 ~121 ~103 dirt
setblock ~162 ~121 ~104 dirt
setblock ~162 ~121 ~105 dirt
setblock ~162 ~121 ~106 dirt
setblock ~162 ~121 ~107 dirt
setblock ~162 ~121 ~108 dirt
setblock ~162 ~121 ~109 dirt
setblock ~162 ~121 ~110 dirt
setblock ~162 ~121 ~111 dirt
setblock ~162 ~121 ~112 dirt
setblock ~162 ~121 ~113 dirt
setblock ~162 ~121 ~114 dirt
setblock ~162 ~121 ~115 dirt
setblock ~162 ~121 ~116 dirt
setblock ~162 ~121 ~117 dirt
setblock ~162 ~121 ~118 dirt
setblock ~162 ~121 ~119 dirt
setblock ~162 ~121 ~120 dirt
setblock ~162 ~121 ~121 dirt
setblock ~162 ~121 ~122 dirt
setblock ~162 ~121 ~123 dirt
setblock ~162 ~122 ~70 grass_block
setblock ~162 ~122 ~71 grass_block
setblock ~162 ~122 ~72 dirt
setblock ~162 ~122 ~73 dirt
setblock ~162 ~122 ~74 dirt
setblock ~162 ~122 ~75 dirt
setblock ~162 ~122 ~76 dirt
setblock ~162 ~122 ~77 dirt
setblock ~162 ~122 ~78 dirt
setblock ~162 ~122 ~79 dirt
setblock ~162 ~122 ~80 dirt
setblock ~162 ~122 ~81 dirt
setblock ~162 ~122 ~82 dirt
setblock ~162 ~122 ~83 dirt
setblock ~162 ~122 ~84 dirt
setblock ~162 ~122 ~85 dirt
setblock ~162 ~122 ~86 dirt
setblock ~162 ~122 ~87 dirt
setblock ~162 ~122 ~88 dirt
setblock ~162 ~122 ~89 dirt
setblock ~162 ~122 ~90 dirt
setblock ~162 ~122 ~91 dirt
setblock ~162 ~122 ~92 dirt
setblock ~162 ~122 ~93 dirt
setblock ~162 ~122 ~94 dirt
setblock ~162 ~122 ~95 dirt
setblock ~162 ~122 ~96 dirt
setblock ~162 ~122 ~97 dirt
setblock ~162 ~122 ~98 dirt
setblock ~162 ~122 ~99 dirt
setblock ~162 ~122 ~100 dirt
setblock ~162 ~122 ~101 dirt
setblock ~162 ~122 ~102 dirt
setblock ~162 ~122 ~103 dirt
setblock ~162 ~122 ~104 dirt
setblock ~162 ~122 ~105 dirt
setblock ~162 ~122 ~106 dirt
setblock ~162 ~122 ~107 dirt
setblock ~162 ~122 ~108 dirt
setblock ~162 ~122 ~109 dirt
setblock ~162 ~122 ~110 dirt
setblock ~162 ~122 ~111 dirt
setblock ~162 ~122 ~112 dirt
setblock ~162 ~122 ~113 dirt
setblock ~162 ~122 ~114 dirt
setblock ~162 ~122 ~115 dirt
setblock ~162 ~122 ~116 dirt
setblock ~162 ~122 ~117 dirt
setblock ~162 ~122 ~118 dirt
setblock ~162 ~122 ~119 dirt
setblock ~162 ~122 ~120 dirt
setblock ~162 ~122 ~121 dirt
setblock ~162 ~122 ~122 dirt
setblock ~162 ~122 ~123 dirt
setblock ~162 ~123 ~72 grass_block
setblock ~162 ~123 ~73 grass_block
setblock ~162 ~123 ~74 dirt
setblock ~162 ~123 ~75 dirt
setblock ~162 ~123 ~76 dirt
setblock ~162 ~123 ~77 dirt
setblock ~162 ~123 ~78 dirt
setblock ~162 ~123 ~79 dirt
setblock ~162 ~123 ~80 dirt
setblock ~162 ~123 ~81 dirt
setblock ~162 ~123 ~82 dirt
setblock ~162 ~123 ~83 dirt
setblock ~162 ~123 ~84 dirt
setblock ~162 ~123 ~85 dirt
setblock ~162 ~123 ~86 dirt
setblock ~162 ~123 ~87 dirt
setblock ~162 ~123 ~88 dirt
setblock ~162 ~123 ~89 dirt
setblock ~162 ~123 ~90 dirt
setblock ~162 ~123 ~91 dirt
setblock ~162 ~123 ~92 dirt
setblock ~162 ~123 ~93 dirt
setblock ~162 ~123 ~94 dirt
setblock ~162 ~123 ~95 dirt
setblock ~162 ~123 ~96 dirt
setblock ~162 ~123 ~97 dirt
setblock ~162 ~123 ~98 dirt
setblock ~162 ~123 ~99 dirt
setblock ~162 ~123 ~100 dirt
setblock ~162 ~123 ~101 dirt
setblock ~162 ~123 ~102 dirt
setblock ~162 ~123 ~103 dirt
setblock ~162 ~123 ~104 dirt
setblock ~162 ~123 ~105 dirt
setblock ~162 ~123 ~106 dirt
setblock ~162 ~123 ~107 dirt
setblock ~162 ~123 ~108 dirt
setblock ~162 ~123 ~109 dirt
setblock ~162 ~123 ~110 grass_block
setblock ~162 ~123 ~111 dirt
setblock ~162 ~123 ~112 dirt
setblock ~162 ~123 ~113 dirt
setblock ~162 ~123 ~114 dirt
setblock ~162 ~123 ~115 dirt
setblock ~162 ~123 ~116 dirt
setblock ~162 ~123 ~117 dirt
setblock ~162 ~123 ~118 dirt
setblock ~162 ~123 ~119 dirt
setblock ~162 ~123 ~120 dirt
setblock ~162 ~123 ~121 dirt
setblock ~162 ~123 ~122 dirt
setblock ~162 ~123 ~123 dirt
setblock ~162 ~124 ~72 poppy
setblock ~162 ~124 ~74 grass_block
setblock ~162 ~124 ~75 grass_block
setblock ~162 ~124 ~76 grass_block
setblock ~162 ~124 ~77 grass_block
setblock ~162 ~124 ~78 dirt
setblock ~162 ~124 ~79 dirt
setblock ~162 ~124 ~80 dirt
setblock ~162 ~124 ~81 dirt
setblock ~162 ~124 ~82 dirt
setblock ~162 ~124 ~83 dirt
setblock ~162 ~124 ~84 dirt
setblock ~162 ~124 ~85 dirt
setblock ~162 ~124 ~86 dirt
setblock ~162 ~124 ~87 dirt
setblock ~162 ~124 ~88 dirt
setblock ~162 ~124 ~89 dirt
setblock ~162 ~124 ~90 dirt
setblock ~162 ~124 ~91 dirt
setblock ~162 ~124 ~92 dirt
setblock ~162 ~124 ~93 dirt
setblock ~162 ~124 ~94 dirt
setblock ~162 ~124 ~95 dirt
setblock ~162 ~124 ~96 dirt
setblock ~162 ~124 ~97 dirt
setblock ~162 ~124 ~98 dirt
setblock ~162 ~124 ~99 grass_block
setblock ~162 ~124 ~100 grass_block
setblock ~162 ~124 ~101 grass_block
setblock ~162 ~124 ~102 grass_block
setblock ~162 ~124 ~103 grass_block
setblock ~162 ~124 ~104 grass_block
setblock ~162 ~124 ~105 grass_block
setblock ~162 ~124 ~106 grass_block
setblock ~162 ~124 ~107 grass_block
setblock ~162 ~124 ~108 grass_block
setblock ~162 ~124 ~109 grass_block
setblock ~162 ~124 ~111 grass_block
setblock ~162 ~124 ~112 grass_block
setblock ~162 ~124 ~113 dirt
setblock ~162 ~124 ~114 dirt
setblock ~162 ~124 ~115 dirt
setblock ~162 ~124 ~116 dirt
setblock ~162 ~124 ~117 dirt
setblock ~162 ~124 ~118 dirt
setblock ~162 ~124 ~119 dirt
setblock ~162 ~124 ~120 dirt
setblock ~162 ~124 ~121 dirt
setblock ~162 ~124 ~122 dirt
setblock ~162 ~124 ~123 dirt
setblock ~162 ~125 ~74 short_grass
setblock ~162 ~125 ~75 short_grass
setblock ~162 ~125 ~78 grass_block
setblock ~162 ~125 ~79 grass_block
setblock ~162 ~125 ~80 grass_block
setblock ~162 ~125 ~81 grass_block
setblock ~162 ~125 ~82 grass_block
setblock ~162 ~125 ~83 grass_block
setblock ~162 ~125 ~84 dirt
setblock ~162 ~125 ~85 dirt
setblock ~162 ~125 ~86 dirt
setblock ~162 ~125 ~87 dirt
setblock ~162 ~125 ~88 dirt
setblock ~162 ~125 ~89 dirt
setblock ~162 ~125 ~90 dirt
setblock ~162 ~125 ~91 dirt
setblock ~162 ~125 ~92 dirt
setblock ~162 ~125 ~93 grass_block
setblock ~162 ~125 ~94 grass_block
setblock ~162 ~125 ~95 grass_block
setblock ~162 ~125 ~96 grass_block
setblock ~162 ~125 ~97 grass_block
setblock ~162 ~125 ~98 grass_block
setblock ~162 ~125 ~102 short_grass
setblock ~162 ~125 ~103 short_grass
setblock ~162 ~125 ~105 short_grass
setblock ~162 ~125 ~113 grass_block
setblock ~162 ~125 ~114 grass_block
setblock ~162 ~125 ~115 dirt
setblock ~162 ~125 ~116 dirt
setblock ~162 ~125 ~117 dirt
setblock ~162 ~125 ~118 dirt
setblock ~162 ~125 ~119 dirt
setblock ~162 ~125 ~120 dirt
setblock ~162 ~125 ~121 dirt
setblock ~162 ~125 ~122 dirt
setblock ~162 ~125 ~123 dirt
setblock ~162 ~126 ~80 short_grass
setblock ~162 ~126 ~81 poppy
setblock ~162 ~126 ~84 grass_block
setblock ~162 ~126 ~85 grass_block
setblock ~162 ~126 ~86 grass_block
setblock ~162 ~126 ~87 grass_block
setblock ~162 ~126 ~88 grass_block
setblock ~162 ~126 ~89 grass_block
setblock ~162 ~126 ~90 grass_block
setblock ~162 ~126 ~91 grass_block
setblock ~162 ~126 ~92 grass_block
setblock ~162 ~126 ~95 poppy
setblock ~162 ~126 ~113 short_grass
setblock ~162 ~126 ~114 fern
setblock ~162 ~126 ~115 grass_block
setblock ~162 ~126 ~116 grass_block
setblock ~162 ~126 ~117 grass_block
setblock ~162 ~126 ~118 dirt
setblock ~162 ~126 ~119 dirt
setblock ~162 ~126 ~120 dirt
setblock ~162 ~126 ~121 dirt
setblock ~162 ~126 ~122 dirt
setblock ~162 ~126 ~123 dirt
setblock ~162 ~127 ~85 short_grass
setblock ~162 ~127 ~87 short_grass
setblock ~162 ~127 ~91 fern
setblock ~162 ~127 ~92 short_grass
setblock ~162 ~127 ~118 grass_block
setblock ~162 ~127 ~119 grass_block
setblock ~162 ~127 ~120 grass_block
setblock ~162 ~127 ~121 grass_block
setblock ~162 ~127 ~122 grass_block
setblock ~162 ~127 ~123 grass_block
setblock ~162 ~128 ~122 short_grass
setblock ~162 ~128 ~123 short_grass
setblock ~163 ~104 ~95 dirt
setblock ~163 ~105 ~95 dirt
setblock ~163 ~105 ~97 dirt
setblock ~163 ~106 ~94 dirt
setblock ~163 ~106 ~95 dirt
setblock ~163 ~106 ~96 dirt
setblock ~163 ~106 ~97 dirt
setblock ~163 ~106 ~98 dirt
setblock ~163 ~106 ~108 dirt
setblock ~163 ~106 ~109 dirt
setblock ~163 ~107 ~92 dirt
setblock ~163 ~107 ~94 dirt
setblock ~163 ~107 ~95 dirt
setblock ~163 ~107 ~96 dirt
setblock ~163 ~107 ~97 dirt
setblock ~163 ~107 ~98 dirt
setblock ~163 ~107 ~99 dirt
setblock ~163 ~107 ~108 dirt
setblock ~163 ~107 ~109 dirt
setblock ~163 ~107 ~110 dirt
setblock ~163 ~108 ~92 dirt
setblock ~163 ~108 ~93 dirt
setblock ~163 ~108 ~94 dirt
setblock ~163 ~108 ~95 dirt
setblock ~163 ~108 ~96 dirt
setblock ~163 ~108 ~97 dirt
setblock ~163 ~108 ~98 dirt
setblock ~163 ~108 ~99 dirt
setblock ~163 ~108 ~108 dirt
setblock ~163 ~108 ~109 dirt
setblock ~163 ~108 ~110 dirt
setblock ~163 ~108 ~111 dirt
setblock ~163 ~109 ~91 dirt
setblock ~163 ~109 ~92 dirt
setblock ~163 ~109 ~93 dirt
setblock ~163 ~109 ~94 dirt
setblock ~163 ~109 ~95 dirt
setblock ~163 ~109 ~96 dirt
setblock ~163 ~109 ~97 dirt
setblock ~163 ~109 ~98 dirt
setblock ~163 ~109 ~99 dirt
setblock ~163 ~109 ~107 dirt
setblock ~163 ~109 ~108 dirt
setblock ~163 ~109 ~109 dirt
setblock ~163 ~109 ~110 dirt
setblock ~163 ~109 ~111 dirt
setblock ~163 ~110 ~91 dirt
setblock ~163 ~110 ~92 dirt
setblock ~163 ~110 ~93 dirt
setblock ~163 ~110 ~94 dirt
setblock ~163 ~110 ~95 dirt
setblock ~163 ~110 ~96 dirt
setblock ~163 ~110 ~97 dirt
setblock ~163 ~110 ~98 dirt
setblock ~163 ~110 ~99 dirt
setblock ~163 ~110 ~107 dirt
setblock ~163 ~110 ~108 dirt
setblock ~163 ~110 ~109 dirt
setblock ~163 ~110 ~110 dirt
setblock ~163 ~110 ~111 dirt
setblock ~163 ~110 ~112 dirt
setblock ~163 ~111 ~90 dirt
setblock ~163 ~111 ~91 dirt
setblock ~163 ~111 ~92 dirt
setblock ~163 ~111 ~93 dirt
setblock ~163 ~111 ~94 dirt
setblock ~163 ~111 ~95 dirt
setblock ~163 ~111 ~96 dirt
setblock ~163 ~111 ~97 dirt
setblock ~163 ~111 ~98 dirt
setblock ~163 ~111 ~99 dirt
setblock ~163 ~111 ~100 dirt
setblock ~163 ~111 ~105 dirt
setblock ~163 ~111 ~106 dirt
setblock ~163 ~111 ~107 dirt
setblock ~163 ~111 ~108 dirt
setblock ~163 ~111 ~109 dirt
setblock ~163 ~111 ~110 dirt
setblock ~163 ~111 ~111 dirt
setblock ~163 ~111 ~112 dirt
setblock ~163 ~112 ~90 dirt
setblock ~163 ~112 ~91 dirt
setblock ~163 ~112 ~92 dirt
setblock ~163 ~112 ~93 dirt
setblock ~163 ~112 ~94 dirt
setblock ~163 ~112 ~95 dirt
setblock ~163 ~112 ~96 dirt
setblock ~163 ~112 ~97 dirt
setblock ~163 ~112 ~98 dirt
setblock ~163 ~112 ~99 dirt
setblock ~163 ~112 ~100 dirt
setblock ~163 ~112 ~105 dirt
setblock ~163 ~112 ~106 dirt
setblock ~163 ~112 ~107 dirt
setblock ~163 ~112 ~108 dirt
setblock ~163 ~112 ~109 dirt
setblock ~163 ~112 ~110 dirt
setblock ~163 ~112 ~111 dirt
setblock ~163 ~112 ~112 dirt
setblock ~163 ~112 ~113 dirt
setblock ~163 ~113 ~89 dirt
setblock ~163 ~113 ~90 dirt
setblock ~163 ~113 ~91 dirt
setblock ~163 ~113 ~92 dirt
setblock ~163 ~113 ~93 dirt
setblock ~163 ~113 ~94 dirt
setblock ~163 ~113 ~95 dirt
setblock ~163 ~113 ~96 dirt
setblock ~163 ~113 ~97 dirt
setblock ~163 ~113 ~98 dirt
setblock ~163 ~113 ~99 dirt
setblock ~163 ~113 ~100 dirt
setblock ~163 ~113 ~101 dirt
setblock ~163 ~113 ~102 dirt
setblock ~163 ~113 ~103 dirt
setblock ~163 ~113 ~104 dirt
setblock ~163 ~113 ~105 dirt
setblock ~163 ~113 ~106 dirt
setblock ~163 ~113 ~107 dirt
setblock ~163 ~113 ~108 dirt
setblock ~163 ~113 ~109 dirt
setblock ~163 ~113 ~110 dirt
setblock ~163 ~113 ~111 dirt
setblock ~163 ~113 ~112 dirt
setblock ~163 ~113 ~113 dirt
setblock ~163 ~113 ~114 dirt
setblock ~163 ~114 ~89 dirt
setblock ~163 ~114 ~90 dirt
setblock ~163 ~114 ~91 dirt
setblock ~163 ~114 ~92 dirt
setblock ~163 ~114 ~93 dirt
setblock ~163 ~114 ~94 dirt
setblock ~163 ~114 ~95 dirt
setblock ~163 ~114 ~96 dirt
setblock ~163 ~114 ~97 dirt
setblock ~163 ~114 ~98 dirt
setblock ~163 ~114 ~99 dirt
setblock ~163 ~114 ~100 dirt
setblock ~163 ~114 ~101 dirt
setblock ~163 ~114 ~102 dirt
setblock ~163 ~114 ~103 dirt
setblock ~163 ~114 ~104 dirt
setblock ~163 ~114 ~105 dirt
setblock ~163 ~114 ~106 dirt
setblock ~163 ~114 ~107 dirt
setblock ~163 ~114 ~108 dirt
setblock ~163 ~114 ~109 dirt
setblock ~163 ~114 ~110 dirt
setblock ~163 ~114 ~111 dirt
setblock ~163 ~114 ~112 dirt
setblock ~163 ~114 ~113 dirt
setblock ~163 ~114 ~114 dirt
setblock ~163 ~114 ~115 dirt
setblock ~163 ~115 ~88 dirt
setblock ~163 ~115 ~89 dirt
setblock ~163 ~115 ~90 dirt
setblock ~163 ~115 ~91 dirt
setblock ~163 ~115 ~92 dirt
setblock ~163 ~115 ~93 dirt
setblock ~163 ~115 ~94 dirt
setblock ~163 ~115 ~95 dirt
setblock ~163 ~115 ~96 dirt
setblock ~163 ~115 ~97 dirt
setblock ~163 ~115 ~98 dirt
setblock ~163 ~115 ~99 dirt
setblock ~163 ~115 ~100 dirt
setblock ~163 ~115 ~101 dirt
setblock ~163 ~115 ~102 dirt
setblock ~163 ~115 ~103 dirt
setblock ~163 ~115 ~104 dirt
setblock ~163 ~115 ~105 dirt
setblock ~163 ~115 ~106 dirt
setblock ~163 ~115 ~107 dirt
setblock ~163 ~115 ~108 dirt
setblock ~163 ~115 ~109 dirt
setblock ~163 ~115 ~110 dirt
setblock ~163 ~115 ~111 dirt
setblock ~163 ~115 ~112 dirt
setblock ~163 ~115 ~113 dirt
setblock ~163 ~115 ~114 dirt
setblock ~163 ~115 ~115 dirt
setblock ~163 ~116 ~88 dirt
setblock ~163 ~116 ~89 dirt
setblock ~163 ~116 ~90 dirt
setblock ~163 ~116 ~91 dirt
setblock ~163 ~116 ~92 dirt
setblock ~163 ~116 ~93 dirt
setblock ~163 ~116 ~94 dirt
setblock ~163 ~116 ~95 dirt
setblock ~163 ~116 ~96 dirt
setblock ~163 ~116 ~97 dirt
setblock ~163 ~116 ~98 dirt
setblock ~163 ~116 ~99 dirt
setblock ~163 ~116 ~100 dirt
setblock ~163 ~116 ~101 dirt
setblock ~163 ~116 ~102 dirt
setblock ~163 ~116 ~103 dirt
setblock ~163 ~116 ~104 dirt
setblock ~163 ~116 ~105 dirt
setblock ~163 ~116 ~106 dirt
setblock ~163 ~116 ~107 dirt
setblock ~163 ~116 ~108 dirt
setblock ~163 ~116 ~109 dirt
setblock ~163 ~116 ~110 dirt
setblock ~163 ~116 ~111 dirt
setblock ~163 ~116 ~112 dirt
setblock ~163 ~116 ~113 dirt
setblock ~163 ~116 ~114 dirt
setblock ~163 ~116 ~115 dirt
setblock ~163 ~116 ~116 dirt
setblock ~163 ~117 ~87 dirt
setblock ~163 ~117 ~88 dirt
setblock ~163 ~117 ~89 dirt
setblock ~163 ~117 ~90 dirt
setblock ~163 ~117 ~91 dirt
setblock ~163 ~117 ~92 dirt
setblock ~163 ~117 ~93 dirt
setblock ~163 ~117 ~94 dirt
setblock ~163 ~117 ~95 dirt
setblock ~163 ~117 ~96 dirt
setblock ~163 ~117 ~97 dirt
setblock ~163 ~117 ~98 dirt
setblock ~163 ~117 ~99 dirt
setblock ~163 ~117 ~100 dirt
setblock ~163 ~117 ~101 dirt
setblock ~163 ~117 ~102 dirt
setblock ~163 ~117 ~103 dirt
setblock ~163 ~117 ~104 dirt
setblock ~163 ~117 ~105 dirt
setblock ~163 ~117 ~106 dirt
setblock ~163 ~117 ~107 dirt
setblock ~163 ~117 ~108 dirt
setblock ~163 ~117 ~109 dirt
setblock ~163 ~117 ~110 dirt
setblock ~163 ~117 ~111 dirt
setblock ~163 ~117 ~112 dirt
setblock ~163 ~117 ~113 dirt
setblock ~163 ~117 ~114 dirt
setblock ~163 ~117 ~115 dirt
setblock ~163 ~117 ~116 dirt
setblock ~163 ~117 ~117 dirt
setblock ~163 ~117 ~118 dirt
setblock ~163 ~117 ~119 dirt
setblock ~163 ~118 ~75 dirt
setblock ~163 ~118 ~86 dirt
setblock ~163 ~118 ~87 dirt
setblock ~163 ~118 ~88 dirt
setblock ~163 ~118 ~89 dirt
setblock ~163 ~118 ~90 dirt
setblock ~163 ~118 ~91 dirt
setblock ~163 ~118 ~92 dirt
setblock ~163 ~118 ~93 dirt
setblock ~163 ~118 ~94 dirt
setblock ~163 ~118 ~95 dirt
setblock ~163 ~118 ~96 dirt
setblock ~163 ~118 ~97 dirt
setblock ~163 ~118 ~98 dirt
setblock ~163 ~118 ~99 dirt
setblock ~163 ~118 ~100 dirt
setblock ~163 ~118 ~101 dirt
setblock ~163 ~118 ~102 dirt
setblock ~163 ~118 ~103 dirt
setblock ~163 ~118 ~104 dirt
setblock ~163 ~118 ~105 dirt
setblock ~163 ~118 ~106 dirt
setblock ~163 ~118 ~107 dirt
setblock ~163 ~118 ~108 dirt
setblock ~163 ~118 ~109 dirt
setblock ~163 ~118 ~110 dirt
setblock ~163 ~118 ~111 dirt
setblock ~163 ~118 ~112 dirt
setblock ~163 ~118 ~113 dirt
setblock ~163 ~118 ~114 dirt
setblock ~163 ~118 ~115 dirt
setblock ~163 ~118 ~116 dirt
setblock ~163 ~118 ~117 dirt
setblock ~163 ~118 ~118 dirt
setblock ~163 ~118 ~119 dirt
setblock ~163 ~118 ~120 dirt
setblock ~163 ~119 ~75 dirt
setblock ~163 ~119 ~76 dirt
setblock ~163 ~119 ~85 dirt
setblock ~163 ~119 ~86 dirt
setblock ~163 ~119 ~87 dirt
setblock ~163 ~119 ~88 dirt
setblock ~163 ~119 ~89 dirt
setblock ~163 ~119 ~90 dirt
setblock ~163 ~119 ~91 dirt
setblock ~163 ~119 ~92 dirt
setblock ~163 ~119 ~93 dirt
setblock ~163 ~119 ~94 dirt
setblock ~163 ~119 ~95 dirt
setblock ~163 ~119 ~96 dirt
setblock ~163 ~119 ~97 dirt
setblock ~163 ~119 ~98 dirt
setblock ~163 ~119 ~99 dirt
setblock ~163 ~119 ~100 dirt
setblock ~163 ~119 ~101 dirt
setblock ~163 ~119 ~102 dirt
setblock ~163 ~119 ~103 dirt
setblock ~163 ~119 ~104 dirt
setblock ~163 ~119 ~105 dirt
setblock ~163 ~119 ~106 dirt
setblock ~163 ~119 ~107 dirt
setblock ~163 ~119 ~108 dirt
setblock ~163 ~119 ~109 dirt
setblock ~163 ~119 ~110 dirt
setblock ~163 ~119 ~111 dirt
setblock ~163 ~119 ~112 dirt
setblock ~163 ~119 ~113 dirt
setblock ~163 ~119 ~114 dirt
setblock ~163 ~119 ~115 dirt
setblock ~163 ~119 ~116 dirt
setblock ~163 ~119 ~117 dirt
setblock ~163 ~119 ~118 dirt
setblock ~163 ~119 ~119 dirt
setblock ~163 ~119 ~120 dirt
setblock ~163 ~120 ~72 dirt
setblock ~163 ~120 ~74 dirt
setblock ~163 ~120 ~75 dirt
setblock ~163 ~120 ~76 dirt
setblock ~163 ~120 ~79 dirt
setblock ~163 ~120 ~80 dirt
setblock ~163 ~120 ~81 dirt
setblock ~163 ~120 ~82 dirt
setblock ~163 ~120 ~83 dirt
setblock ~163 ~120 ~84 dirt
setblock ~163 ~120 ~85 dirt
setblock ~163 ~120 ~86 dirt
setblock ~163 ~120 ~87 dirt
setblock ~163 ~120 ~88 dirt
setblock ~163 ~120 ~89 dirt
setblock ~163 ~120 ~90 dirt
setblock ~163 ~120 ~91 dirt
setblock ~163 ~120 ~92 dirt
setblock ~163 ~120 ~93 dirt
setblock ~163 ~120 ~94 dirt
setblock ~163 ~120 ~95 dirt
setblock ~163 ~120 ~96 dirt
setblock ~163 ~120 ~97 dirt
setblock ~163 ~120 ~98 dirt
setblock ~163 ~120 ~99 dirt
setblock ~163 ~120 ~100 dirt
setblock ~163 ~120 ~101 dirt
setblock ~163 ~120 ~102 dirt
setblock ~163 ~120 ~103 dirt
setblock ~163 ~120 ~104 dirt
setblock ~163 ~120 ~105 dirt
setblock ~163 ~120 ~106 dirt
setblock ~163 ~120 ~107 dirt
setblock ~163 ~120 ~108 dirt
setblock ~163 ~120 ~109 dirt
setblock ~163 ~120 ~110 dirt
setblock ~163 ~120 ~111 dirt
setblock ~163 ~120 ~112 dirt
setblock ~163 ~120 ~113 dirt
setblock ~163 ~120 ~114 dirt
setblock ~163 ~120 ~115 dirt
setblock ~163 ~120 ~116 dirt
setblock ~163 ~120 ~117 dirt
setblock ~163 ~120 ~118 dirt
setblock ~163 ~120 ~119 dirt
setblock ~163 ~120 ~120 dirt
setblock ~163 ~120 ~121 dirt
setblock ~163 ~120 ~122 dirt
setblock ~163 ~121 ~71 dirt
setblock ~163 ~121 ~72 dirt
setblock ~163 ~121 ~74 dirt
setblock ~163 ~121 ~75 dirt
setblock ~163 ~121 ~76 dirt
setblock ~163 ~121 ~77 dirt
setblock ~163 ~121 ~78 dirt
setblock ~163 ~121 ~79 dirt
setblock ~163 ~121 ~80 dirt
setblock ~163 ~121 ~81 dirt
setblock ~163 ~121 ~82 dirt
setblock ~163 ~121 ~83 dirt
setblock ~163 ~121 ~84 dirt
setblock ~163 ~121 ~85 dirt
setblock ~163 ~121 ~86 dirt
setblock ~163 ~121 ~87 dirt
setblock ~163 ~121 ~88 dirt
setblock ~163 ~121 ~89 dirt
setblock ~163 ~121 ~90 dirt
setblock ~163 ~121 ~91 dirt
setblock ~163 ~121 ~92 dirt
setblock ~163 ~121 ~93 dirt
setblock ~163 ~121 ~94 dirt
setblock ~163 ~121 ~95 dirt
setblock ~163 ~121 ~96 dirt
setblock ~163 ~121 ~97 dirt
setblock ~163 ~121 ~98 dirt
setblock ~163 ~121 ~99 dirt
setblock ~163 ~121 ~100 dirt
setblock ~163 ~121 ~101 dirt
setblock ~163 ~121 ~102 dirt
setblock ~163 ~121 ~103 dirt
setblock ~163 ~121 ~104 dirt
setblock ~163 ~121 ~105 dirt
setblock ~163 ~121 ~106 dirt
setblock ~163 ~121 ~107 dirt
setblock ~163 ~121 ~108 dirt
setblock ~163 ~121 ~109 dirt
setblock ~163 ~121 ~110 dirt
setblock ~163 ~121 ~111 dirt
setblock ~163 ~121 ~112 dirt
setblock ~163 ~121 ~113 dirt
setblock ~163 ~121 ~114 dirt
setblock ~163 ~121 ~115 dirt
setblock ~163 ~121 ~116 dirt
setblock ~163 ~121 ~117 dirt
setblock ~163 ~121 ~118 dirt
setblock ~163 ~121 ~119 dirt
setblock ~163 ~121 ~120 dirt
setblock ~163 ~121 ~121 dirt
setblock ~163 ~121 ~122 dirt
setblock ~163 ~122 ~71 grass_block
setblock ~163 ~122 ~72 dirt
setblock ~163 ~122 ~74 dirt
setblock ~163 ~122 ~75 dirt
setblock ~163 ~122 ~76 dirt
setblock ~163 ~122 ~77 dirt
setblock ~163 ~122 ~78 dirt
setblock ~163 ~122 ~79 dirt
setblock ~163 ~122 ~80 dirt
setblock ~163 ~122 ~81 dirt
setblock ~163 ~122 ~82 dirt
setblock ~163 ~122 ~83 dirt
setblock ~163 ~122 ~84 dirt
setblock ~163 ~122 ~85 dirt
setblock ~163 ~122 ~86 dirt
setblock ~163 ~122 ~87 dirt
setblock ~163 ~122 ~88 dirt
setblock ~163 ~122 ~89 dirt
setblock ~163 ~122 ~90 dirt
setblock ~163 ~122 ~91 dirt
setblock ~163 ~122 ~92 dirt
setblock ~163 ~122 ~93 dirt
setblock ~163 ~122 ~94 dirt
setblock ~163 ~122 ~95 dirt
setblock ~163 ~122 ~96 dirt
setblock ~163 ~122 ~97 dirt
setblock ~163 ~122 ~98 dirt
setblock ~163 ~122 ~99 dirt
setblock ~163 ~122 ~100 dirt
setblock ~163 ~122 ~101 dirt
setblock ~163 ~122 ~102 dirt
setblock ~163 ~122 ~103 dirt
setblock ~163 ~122 ~104 dirt
setblock ~163 ~122 ~105 dirt
setblock ~163 ~122 ~106 dirt
setblock ~163 ~122 ~107 dirt
setblock ~163 ~122 ~108 dirt
setblock ~163 ~122 ~109 dirt
setblock ~163 ~122 ~110 dirt
setblock ~163 ~122 ~111 dirt
setblock ~163 ~122 ~112 dirt
setblock ~163 ~122 ~113 dirt
setblock ~163 ~122 ~114 dirt
setblock ~163 ~122 ~115 dirt
setblock ~163 ~122 ~116 dirt
setblock ~163 ~122 ~117 dirt
setblock ~163 ~122 ~118 dirt
setblock ~163 ~122 ~119 dirt
setblock ~163 ~122 ~120 dirt
setblock ~163 ~122 ~121 dirt
setblock ~163 ~122 ~122 dirt
setblock ~163 ~123 ~71 fern
setblock ~163 ~123 ~72 grass_block
setblock ~163 ~123 ~74 dirt
setblock ~163 ~123 ~75 dirt
setblock ~163 ~123 ~76 dirt
setblock ~163 ~123 ~77 dirt
setblock ~163 ~123 ~78 dirt
setblock ~163 ~123 ~79 dirt
setblock ~163 ~123 ~80 dirt
setblock ~163 ~123 ~81 dirt
setblock ~163 ~123 ~82 dirt
setblock ~163 ~123 ~83 dirt
setblock ~163 ~123 ~84 dirt
setblock ~163 ~123 ~85 dirt
setblock ~163 ~123 ~86 dirt
setblock ~163 ~123 ~87 dirt
setblock ~163 ~123 ~88 dirt
setblock ~163 ~123 ~89 dirt
setblock ~163 ~123 ~90 dirt
setblock ~163 ~123 ~91 dirt
setblock ~163 ~123 ~92 dirt
setblock ~163 ~123 ~93 dirt
setblock ~163 ~123 ~94 dirt
setblock ~163 ~123 ~95 dirt
setblock ~163 ~123 ~96 dirt
setblock ~163 ~123 ~97 dirt
setblock ~163 ~123 ~98 dirt
setblock ~163 ~123 ~99 dirt
setblock ~163 ~123 ~100 dirt
setblock ~163 ~123 ~101 dirt
setblock ~163 ~123 ~102 dirt
setblock ~163 ~123 ~103 dirt
setblock ~163 ~123 ~104 dirt
setblock ~163 ~123 ~105 dirt
setblock ~163 ~123 ~106 dirt
setblock ~163 ~123 ~107 dirt
setblock ~163 ~123 ~108 dirt
setblock ~163 ~123 ~109 dirt
setblock ~163 ~123 ~110 dirt
setblock ~163 ~123 ~111 dirt
setblock ~163 ~123 ~112 dirt
setblock ~163 ~123 ~113 dirt
setblock ~163 ~123 ~114 dirt
setblock ~163 ~123 ~115 dirt
setblock ~163 ~123 ~116 dirt
setblock ~163 ~123 ~117 dirt
setblock ~163 ~123 ~118 dirt
setblock ~163 ~123 ~119 dirt
setblock ~163 ~123 ~120 dirt
setblock ~163 ~123 ~121 dirt
setblock ~163 ~123 ~122 dirt
setblock ~163 ~124 ~74 grass_block
setblock ~163 ~124 ~75 grass_block
setblock ~163 ~124 ~76 grass_block
setblock ~163 ~124 ~77 dirt
setblock ~163 ~124 ~78 dirt
setblock ~163 ~124 ~79 dirt
setblock ~163 ~124 ~80 dirt
setblock ~163 ~124 ~81 dirt
setblock ~163 ~124 ~82 dirt
setblock ~163 ~124 ~83 dirt
setblock ~163 ~124 ~84 dirt
setblock ~163 ~124 ~85 dirt
setblock ~163 ~124 ~86 dirt
setblock ~163 ~124 ~87 dirt
setblock ~163 ~124 ~88 dirt
setblock ~163 ~124 ~89 dirt
setblock ~163 ~124 ~90 dirt
setblock ~163 ~124 ~91 dirt
setblock ~163 ~124 ~92 dirt
setblock ~163 ~124 ~93 dirt
setblock ~163 ~124 ~94 dirt
setblock ~163 ~124 ~95 dirt
setblock ~163 ~124 ~96 dirt
setblock ~163 ~124 ~97 dirt
setblock ~163 ~124 ~98 dirt
setblock ~163 ~124 ~99 dirt
setblock ~163 ~124 ~100 dirt
setblock ~163 ~124 ~101 dirt
setblock ~163 ~124 ~102 grass_block
setblock ~163 ~124 ~103 grass_block
setblock ~163 ~124 ~104 grass_block
setblock ~163 ~124 ~105 grass_block
setblock ~163 ~124 ~106 grass_block
setblock ~163 ~124 ~107 grass_block
setblock ~163 ~124 ~108 grass_block
setblock ~163 ~124 ~109 grass_block
setblock ~163 ~124 ~110 grass_block
setblock ~163 ~124 ~111 grass_block
setblock ~163 ~124 ~112 dirt
setblock ~163 ~124 ~113 dirt
setblock ~163 ~124 ~114 dirt
setblock ~163 ~124 ~115 dirt
setblock ~163 ~124 ~116 dirt
setblock ~163 ~124 ~117 dirt
setblock ~163 ~124 ~118 dirt
setblock ~163 ~124 ~119 dirt
setblock ~163 ~124 ~120 dirt
setblock ~163 ~124 ~121 dirt
setblock ~163 ~124 ~122 dirt
setblock ~163 ~125 ~75 poppy
setblock ~163 ~125 ~76 short_grass
setblock ~163 ~125 ~77 grass_block
setblock ~163 ~125 ~78 grass_block
setblock ~163 ~125 ~79 grass_block
setblock ~163 ~125 ~80 dirt
setblock ~163 ~125 ~81 dirt
setblock ~163 ~125 ~82 grass_block
setblock ~163 ~125 ~83 grass_block
setblock ~163 ~125 ~84 grass_block
setblock ~163 ~125 ~85 grass_block
setblock ~163 ~125 ~86 grass_block
setblock ~163 ~125 ~87 grass_block
setblock ~163 ~125 ~88 grass_block
setblock ~163 ~125 ~89 grass_block
setblock ~163 ~125 ~90 grass_block
setblock ~163 ~125 ~91 grass_block
setblock ~163 ~125 ~92 grass_block
setblock ~163 ~125 ~93 grass_block
setblock ~163 ~125 ~94 grass_block
setblock ~163 ~125 ~95 grass_block
setblock ~163 ~125 ~96 grass_block
setblock ~163 ~125 ~97 grass_block
setblock ~163 ~125 ~98 grass_block
setblock ~163 ~125 ~99 grass_block
setblock ~163 ~125 ~100 grass_block
setblock ~163 ~125 ~101 grass_block
setblock ~163 ~125 ~107 short_grass
setblock ~163 ~125 ~108 poppy
setblock ~163 ~125 ~111 poppy
setblock ~163 ~125 ~112 grass_block
setblock ~163 ~125 ~113 grass_block
setblock ~163 ~125 ~114 grass_block
setblock ~163 ~125 ~115 dirt
setblock ~163 ~125 ~116 dirt
setblock ~163 ~125 ~117 dirt
setblock ~163 ~125 ~118 dirt
setblock ~163 ~125 ~119 dirt
setblock ~163 ~125 ~120 dirt
setblock ~163 ~125 ~121 dirt
setblock ~163 ~125 ~122 dirt
setblock ~163 ~126 ~77 short_grass
setblock ~163 ~126 ~78 short_grass
setblock ~163 ~126 ~79 short_grass
setblock ~163 ~126 ~80 grass_block
setblock ~163 ~126 ~81 grass_block
setblock ~163 ~126 ~89 fern
setblock ~163 ~126 ~91 fern
setblock ~163 ~126 ~94 short_grass
setblock ~163 ~126 ~98 short_grass
setblock ~163 ~126 ~99 short_grass
setblock ~163 ~126 ~100 poppy
setblock ~163 ~126 ~101 short_grass
setblock ~163 ~126 ~115 grass_block
setblock ~163 ~126 ~116 grass_block
setblock ~163 ~126 ~117 grass_block
setblock ~163 ~126 ~118 dirt
setblock ~163 ~126 ~119 dirt
setblock ~163 ~126 ~120 dirt
setblock ~163 ~126 ~121 dirt
setblock ~163 ~126 ~122 dirt
setblock ~163 ~127 ~80 short_grass
setblock ~163 ~127 ~118 grass_block
setblock ~163 ~127 ~119 grass_block
setblock ~163 ~127 ~120 grass_block
setblock ~163 ~127 ~121 grass_block
setblock ~163 ~127 ~122 grass_block
setblock ~163 ~128 ~118 short_grass
setblock ~163 ~128 ~122 short_grass
setblock ~164 ~106 ~95 dirt
setblock ~164 ~106 ~97 dirt
setblock ~164 ~107 ~95 dirt
setblock ~164 ~107 ~96 dirt
setblock ~164 ~107 ~97 dirt
setblock ~164 ~107 ~98 dirt
setblock ~164 ~107 ~109 dirt
setblock ~164 ~108 ~94 dirt
setblock ~164 ~108 ~95 dirt
setblock ~164 ~108 ~96 dirt
setblock ~164 ~108 ~97 dirt
setblock ~164 ~108 ~98 dirt
setblock ~164 ~108 ~109 dirt
setblock ~164 ~108 ~110 dirt
setblock ~164 ~109 ~93 dirt
setblock ~164 ~109 ~94 dirt
setblock ~164 ~109 ~95 dirt
setblock ~164 ~109 ~96 dirt
setblock ~164 ~109 ~97 dirt
setblock ~164 ~109 ~98 dirt
setblock ~164 ~109 ~108 dirt
setblock ~164 ~109 ~109 dirt
setblock ~164 ~109 ~110 dirt
setblock ~164 ~110 ~92 dirt
setblock ~164 ~110 ~93 dirt
setblock ~164 ~110 ~94 dirt
setblock ~164 ~110 ~95 dirt
setblock ~164 ~110 ~96 dirt
setblock ~164 ~110 ~97 dirt
setblock ~164 ~110 ~98 dirt
setblock ~164 ~110 ~99 dirt
setblock ~164 ~110 ~108 dirt
setblock ~164 ~110 ~109 dirt
setblock ~164 ~110 ~110 dirt
setblock ~164 ~110 ~111 dirt
setblock ~164 ~111 ~91 dirt
setblock ~164 ~111 ~92 dirt
setblock ~164 ~111 ~93 dirt
setblock ~164 ~111 ~94 dirt
setblock ~164 ~111 ~95 dirt
setblock ~164 ~111 ~96 dirt
setblock ~164 ~111 ~97 dirt
setblock ~164 ~111 ~98 dirt
setblock ~164 ~111 ~99 dirt
setblock ~164 ~111 ~107 dirt
setblock ~164 ~111 ~108 dirt
setblock ~164 ~111 ~109 dirt
setblock ~164 ~111 ~110 dirt
setblock ~164 ~111 ~111 dirt
setblock ~164 ~112 ~91 dirt
setblock ~164 ~112 ~92 dirt
setblock ~164 ~112 ~93 dirt
setblock ~164 ~112 ~94 dirt
setblock ~164 ~112 ~95 dirt
setblock ~164 ~112 ~96 dirt
setblock ~164 ~112 ~97 dirt
setblock ~164 ~112 ~98 dirt
setblock ~164 ~112 ~99 dirt
setblock ~164 ~112 ~100 dirt
setblock ~164 ~112 ~106 dirt
setblock ~164 ~112 ~107 dirt
setblock ~164 ~112 ~108 dirt
setblock ~164 ~112 ~109 dirt
setblock ~164 ~112 ~110 dirt
setblock ~164 ~112 ~111 dirt
setblock ~164 ~112 ~112 dirt
setblock ~164 ~113 ~90 dirt
setblock ~164 ~113 ~91 dirt
setblock ~164 ~113 ~92 dirt
setblock ~164 ~113 ~93 dirt
setblock ~164 ~113 ~94 dirt
setblock ~164 ~113 ~95 dirt
setblock ~164 ~113 ~96 dirt
setblock ~164 ~113 ~97 dirt
setblock ~164 ~113 ~98 dirt
setblock ~164 ~113 ~99 dirt
setblock ~164 ~113 ~100 dirt
setblock ~164 ~113 ~105 dirt
setblock ~164 ~113 ~106 dirt
setblock ~164 ~113 ~107 dirt
setblock ~164 ~113 ~108 dirt
setblock ~164 ~113 ~109 dirt
setblock ~164 ~113 ~110 dirt
setblock ~164 ~113 ~111 dirt
setblock ~164 ~113 ~112 dirt
setblock ~164 ~114 ~90 dirt
setblock ~164 ~114 ~91 dirt
setblock ~164 ~114 ~92 dirt
setblock ~164 ~114 ~93 dirt
setblock ~164 ~114 ~94 dirt
setblock ~164 ~114 ~95 dirt
setblock ~164 ~114 ~96 dirt
setblock ~164 ~114 ~97 dirt
setblock ~164 ~114 ~98 dirt
setblock ~164 ~114 ~99 dirt
setblock ~164 ~114 ~100 dirt
setblock ~164 ~114 ~101 dirt
setblock ~164 ~114 ~104 dirt
setblock ~164 ~114 ~105 dirt
setblock ~164 ~114 ~106 dirt
setblock ~164 ~114 ~107 dirt
setblock ~164 ~114 ~108 dirt
setblock ~164 ~114 ~109 dirt
setblock ~164 ~114 ~110 dirt
setblock ~164 ~114 ~111 dirt
setblock ~164 ~114 ~112 dirt
setblock ~164 ~114 ~113 dirt
setblock ~164 ~114 ~114 dirt
setblock ~164 ~115 ~89 dirt
setblock ~164 ~115 ~90 dirt
setblock ~164 ~115 ~91 dirt
setblock ~164 ~115 ~92 dirt
setblock ~164 ~115 ~93 dirt
setblock ~164 ~115 ~94 dirt
setblock ~164 ~115 ~95 dirt
setblock ~164 ~115 ~96 dirt
setblock ~164 ~115 ~97 dirt
setblock ~164 ~115 ~98 dirt
setblock ~164 ~115 ~99 dirt
setblock ~164 ~115 ~100 dirt
setblock ~164 ~115 ~101 dirt
setblock ~164 ~115 ~103 dirt
setblock ~164 ~115 ~104 dirt
setblock ~164 ~115 ~105 dirt
setblock ~164 ~115 ~106 dirt
setblock ~164 ~115 ~107 dirt
setblock ~164 ~115 ~108 dirt
setblock ~164 ~115 ~109 dirt
setblock ~164 ~115 ~110 dirt
setblock ~164 ~115 ~111 dirt
setblock ~164 ~115 ~112 dirt
setblock ~164 ~115 ~113 dirt
setblock ~164 ~115 ~114 dirt
setblock ~164 ~115 ~115 dirt
setblock ~164 ~116 ~88 dirt
setblock ~164 ~116 ~89 dirt
setblock ~164 ~116 ~90 dirt
setblock ~164 ~116 ~91 dirt
setblock ~164 ~116 ~92 dirt
setblock ~164 ~116 ~93 dirt
setblock ~164 ~116 ~94 dirt
setblock ~164 ~116 ~95 dirt
setblock ~164 ~116 ~96 dirt
setblock ~164 ~116 ~97 dirt
setblock ~164 ~116 ~98 dirt
setblock ~164 ~116 ~99 dirt
setblock ~164 ~116 ~100 dirt
setblock ~164 ~116 ~101 dirt
setblock ~164 ~116 ~102 dirt
setblock ~164 ~116 ~103 dirt
setblock ~164 ~116 ~104 dirt
setblock ~164 ~116 ~105 dirt
setblock ~164 ~116 ~106 dirt
setblock ~164 ~116 ~107 dirt
setblock ~164 ~116 ~108 dirt
setblock ~164 ~116 ~109 dirt
setblock ~164 ~116 ~110 dirt
setblock ~164 ~116 ~111 dirt
setblock ~164 ~116 ~112 dirt
setblock ~164 ~116 ~113 dirt
setblock ~164 ~116 ~114 dirt
setblock ~164 ~116 ~115 dirt
setblock ~164 ~117 ~87 dirt
setblock ~164 ~117 ~88 dirt
setblock ~164 ~117 ~89 dirt
setblock ~164 ~117 ~90 dirt
setblock ~164 ~117 ~91 dirt
setblock ~164 ~117 ~92 dirt
setblock ~164 ~117 ~93 dirt
setblock ~164 ~117 ~94 dirt
setblock ~164 ~117 ~95 dirt
setblock ~164 ~117 ~96 dirt
setblock ~164 ~117 ~97 dirt
setblock ~164 ~117 ~98 dirt
setblock ~164 ~117 ~99 dirt
setblock ~164 ~117 ~100 dirt
setblock ~164 ~117 ~101 dirt
setblock ~164 ~117 ~102 dirt
setblock ~164 ~117 ~103 dirt
setblock ~164 ~117 ~104 dirt
setblock ~164 ~117 ~105 dirt
setblock ~164 ~117 ~106 dirt
setblock ~164 ~117 ~107 dirt
setblock ~164 ~117 ~108 dirt
setblock ~164 ~117 ~109 dirt
setblock ~164 ~117 ~110 dirt
setblock ~164 ~117 ~111 dirt
setblock ~164 ~117 ~112 dirt
setblock ~164 ~117 ~113 dirt
setblock ~164 ~117 ~114 dirt
setblock ~164 ~117 ~115 dirt
setblock ~164 ~118 ~87 dirt
setblock ~164 ~118 ~88 dirt
setblock ~164 ~118 ~89 dirt
setblock ~164 ~118 ~90 dirt
setblock ~164 ~118 ~91 dirt
setblock ~164 ~118 ~92 dirt
setblock ~164 ~118 ~93 dirt
setblock ~164 ~118 ~94 dirt
setblock ~164 ~118 ~95 dirt
setblock ~164 ~118 ~96 dirt
setblock ~164 ~118 ~97 dirt
setblock ~164 ~118 ~98 dirt
setblock ~164 ~118 ~99 dirt
setblock ~164 ~118 ~100 dirt
setblock ~164 ~118 ~101 dirt
setblock ~164 ~118 ~102 dirt
setblock ~164 ~118 ~103 dirt
setblock ~164 ~118 ~104 dirt
setblock ~164 ~118 ~105 dirt
setblock ~164 ~118 ~106 dirt
setblock ~164 ~118 ~107 dirt
setblock ~164 ~118 ~108 dirt
setblock ~164 ~118 ~109 dirt
setblock ~164 ~118 ~110 dirt
setblock ~164 ~118 ~111 dirt
setblock ~164 ~118 ~112 dirt
setblock ~164 ~118 ~113 dirt
setblock ~164 ~118 ~114 dirt
setblock ~164 ~118 ~115 dirt
setblock ~164 ~118 ~116 dirt
setblock ~164 ~119 ~87 dirt
setblock ~164 ~119 ~88 dirt
setblock ~164 ~119 ~89 dirt
setblock ~164 ~119 ~90 dirt
setblock ~164 ~119 ~91 dirt
setblock ~164 ~119 ~92 dirt
setblock ~164 ~119 ~93 dirt
setblock ~164 ~119 ~94 dirt
setblock ~164 ~119 ~95 dirt
setblock ~164 ~119 ~96 dirt
setblock ~164 ~119 ~97 dirt
setblock ~164 ~119 ~98 dirt
setblock ~164 ~119 ~99 dirt
setblock ~164 ~119 ~100 dirt
setblock ~164 ~119 ~101 dirt
setblock ~164 ~119 ~102 dirt
setblock ~164 ~119 ~103 dirt
setblock ~164 ~119 ~104 dirt
setblock ~164 ~119 ~105 dirt
setblock ~164 ~119 ~106 dirt
setblock ~164 ~119 ~107 dirt
setblock ~164 ~119 ~108 dirt
setblock ~164 ~119 ~109 dirt
setblock ~164 ~119 ~110 dirt
setblock ~164 ~119 ~111 dirt
setblock ~164 ~119 ~112 dirt
setblock ~164 ~119 ~113 dirt
setblock ~164 ~119 ~114 dirt
setblock ~164 ~119 ~115 dirt
setblock ~164 ~119 ~116 dirt
setblock ~164 ~119 ~117 dirt
setblock ~164 ~119 ~118 dirt
setblock ~164 ~120 ~75 dirt
setblock ~164 ~120 ~87 dirt
setblock ~164 ~120 ~88 dirt
setblock ~164 ~120 ~89 dirt
setblock ~164 ~120 ~90 dirt
setblock ~164 ~120 ~91 dirt
setblock ~164 ~120 ~92 dirt
setblock ~164 ~120 ~93 dirt
setblock ~164 ~120 ~94 dirt
setblock ~164 ~120 ~95 dirt
setblock ~164 ~120 ~96 dirt
setblock ~164 ~120 ~97 dirt
setblock ~164 ~120 ~98 dirt
setblock ~164 ~120 ~99 dirt
setblock ~164 ~120 ~100 dirt
setblock ~164 ~120 ~101 dirt
setblock ~164 ~120 ~102 dirt
setblock ~164 ~120 ~103 dirt
setblock ~164 ~120 ~104 dirt
setblock ~164 ~120 ~105 dirt
setblock ~164 ~120 ~106 dirt
setblock ~164 ~120 ~107 dirt
setblock ~164 ~120 ~108 dirt
setblock ~164 ~120 ~109 dirt
setblock ~164 ~120 ~110 dirt
setblock ~164 ~120 ~111 dirt
setblock ~164 ~120 ~112 dirt
setblock ~164 ~120 ~113 dirt
setblock ~164 ~120 ~114 dirt
setblock ~164 ~120 ~115 dirt
setblock ~164 ~120 ~116 dirt
setblock ~164 ~120 ~117 dirt
setblock ~164 ~120 ~118 dirt
setblock ~164 ~120 ~119 dirt
setblock ~164 ~121 ~75 dirt
setblock ~164 ~121 ~76 dirt
setblock ~164 ~121 ~79 dirt
setblock ~164 ~121 ~81 dirt
setblock ~164 ~121 ~82 dirt
setblock ~164 ~121 ~85 dirt
setblock ~164 ~121 ~86 dirt
setblock ~164 ~121 ~87 dirt
setblock ~164 ~121 ~88 dirt
setblock ~164 ~121 ~89 dirt
setblock ~164 ~121 ~90 dirt
setblock ~164 ~121 ~91 dirt
setblock ~164 ~121 ~92 dirt
setblock ~164 ~121 ~93 dirt
setblock ~164 ~121 ~94 dirt
setblock ~164 ~121 ~95 dirt
setblock ~164 ~121 ~96 dirt
setblock ~164 ~121 ~97 dirt
setblock ~164 ~121 ~98 dirt
setblock ~164 ~121 ~99 dirt
setblock ~164 ~121 ~100 dirt
setblock ~164 ~121 ~101 dirt
setblock ~164 ~121 ~102 dirt
setblock ~164 ~121 ~103 dirt
setblock ~164 ~121 ~104 dirt
setblock ~164 ~121 ~105 dirt
setblock ~164 ~121 ~106 dirt
setblock ~164 ~121 ~107 dirt
setblock ~164 ~121 ~108 dirt
setblock ~164 ~121 ~109 dirt
setblock ~164 ~121 ~110 dirt
setblock ~164 ~121 ~111 dirt
setblock ~164 ~121 ~112 dirt
setblock ~164 ~121 ~113 dirt
setblock ~164 ~121 ~114 dirt
setblock ~164 ~121 ~115 dirt
setblock ~164 ~121 ~116 dirt
setblock ~164 ~121 ~117 dirt
setblock ~164 ~121 ~118 dirt
setblock ~164 ~121 ~119 dirt
setblock ~164 ~121 ~120 dirt
setblock ~164 ~121 ~121 dirt
setblock ~164 ~122 ~75 dirt
setblock ~164 ~122 ~76 dirt
setblock ~164 ~122 ~79 dirt
setblock ~164 ~122 ~81 dirt
setblock ~164 ~122 ~82 dirt
setblock ~164 ~122 ~85 dirt
setblock ~164 ~122 ~86 dirt
setblock ~164 ~122 ~87 dirt
setblock ~164 ~122 ~88 dirt
setblock ~164 ~122 ~89 dirt
setblock ~164 ~122 ~90 dirt
setblock ~164 ~122 ~91 dirt
setblock ~164 ~122 ~92 dirt
setblock ~164 ~122 ~93 dirt
setblock ~164 ~122 ~94 dirt
setblock ~164 ~122 ~95 dirt
setblock ~164 ~122 ~96 dirt
setblock ~164 ~122 ~97 dirt
setblock ~164 ~122 ~98 dirt
setblock ~164 ~122 ~99 dirt
setblock ~164 ~122 ~100 dirt
setblock ~164 ~122 ~101 dirt
setblock ~164 ~122 ~102 dirt
setblock ~164 ~122 ~103 dirt
setblock ~164 ~122 ~104 dirt
setblock ~164 ~122 ~105 dirt
setblock ~164 ~122 ~106 dirt
setblock ~164 ~122 ~107 dirt
setblock ~164 ~122 ~108 dirt
setblock ~164 ~122 ~109 dirt
setblock ~164 ~122 ~110 dirt
setblock ~164 ~122 ~111 dirt
setblock ~164 ~122 ~112 dirt
setblock ~164 ~122 ~113 dirt
setblock ~164 ~122 ~114 dirt
setblock ~164 ~122 ~115 dirt
setblock ~164 ~122 ~116 dirt
setblock ~164 ~122 ~117 dirt
setblock ~164 ~122 ~118 dirt
setblock ~164 ~122 ~119 dirt
setblock ~164 ~122 ~120 dirt
setblock ~164 ~122 ~121 dirt
setblock ~164 ~123 ~75 dirt
setblock ~164 ~123 ~76 dirt
setblock ~164 ~123 ~79 dirt
setblock ~164 ~123 ~81 dirt
setblock ~164 ~123 ~82 dirt
setblock ~164 ~123 ~85 dirt
setblock ~164 ~123 ~86 dirt
setblock ~164 ~123 ~87 dirt
setblock ~164 ~123 ~88 dirt
setblock ~164 ~123 ~89 dirt
setblock ~164 ~123 ~90 dirt
setblock ~164 ~123 ~91 dirt
setblock ~164 ~123 ~92 dirt
setblock ~164 ~123 ~93 dirt
setblock ~164 ~123 ~94 dirt
setblock ~164 ~123 ~95 dirt
setblock ~164 ~123 ~96 dirt
setblock ~164 ~123 ~97 dirt
setblock ~164 ~123 ~98 dirt
setblock ~164 ~123 ~99 dirt
setblock ~164 ~123 ~100 dirt
setblock ~164 ~123 ~101 dirt
setblock ~164 ~123 ~102 dirt
setblock ~164 ~123 ~103 dirt
setblock ~164 ~123 ~104 dirt
setblock ~164 ~123 ~105 dirt
setblock ~164 ~123 ~106 dirt
setblock ~164 ~123 ~107 dirt
setblock ~164 ~123 ~108 dirt
setblock ~164 ~123 ~109 dirt
setblock ~164 ~123 ~110 dirt
setblock ~164 ~123 ~111 dirt
setblock ~164 ~123 ~112 dirt
setblock ~164 ~123 ~113 dirt
setblock ~164 ~123 ~114 dirt
setblock ~164 ~123 ~115 dirt
setblock ~164 ~123 ~116 dirt
setblock ~164 ~123 ~117 dirt
setblock ~164 ~123 ~118 dirt
setblock ~164 ~123 ~119 dirt
setblock ~164 ~123 ~120 dirt
setblock ~164 ~123 ~121 dirt
setblock ~164 ~124 ~75 grass_block
setblock ~164 ~124 ~76 grass_block
setblock ~164 ~124 ~79 dirt
setblock ~164 ~124 ~81 dirt
setblock ~164 ~124 ~82 dirt
setblock ~164 ~124 ~85 dirt
setblock ~164 ~124 ~86 dirt
setblock ~164 ~124 ~87 dirt
setblock ~164 ~124 ~88 dirt
setblock ~164 ~124 ~89 grass_block
setblock ~164 ~124 ~90 grass_block
setblock ~164 ~124 ~91 grass_block
setblock ~164 ~124 ~92 grass_block
setblock ~164 ~124 ~93 grass_block
setblock ~164 ~124 ~94 dirt
setblock ~164 ~124 ~95 dirt
setblock ~164 ~124 ~96 dirt
setblock ~164 ~124 ~97 dirt
setblock ~164 ~124 ~98 dirt
setblock ~164 ~124 ~99 dirt
setblock ~164 ~124 ~100 dirt
setblock ~164 ~124 ~101 dirt
setblock ~164 ~124 ~102 dirt
setblock ~164 ~124 ~103 dirt
setblock ~164 ~124 ~104 dirt
setblock ~164 ~124 ~105 grass_block
setblock ~164 ~124 ~106 grass_block
setblock ~164 ~124 ~107 grass_block
setblock ~164 ~124 ~108 grass_block
setblock ~164 ~124 ~109 grass_block
setblock ~164 ~124 ~110 grass_block
setblock ~164 ~124 ~111 grass_block
setblock ~164 ~124 ~112 dirt
setblock ~164 ~124 ~113 dirt
setblock ~164 ~124 ~114 dirt
setblock ~164 ~124 ~115 dirt
setblock ~164 ~124 ~116 dirt
setblock ~164 ~124 ~117 dirt
setblock ~164 ~124 ~118 dirt
setblock ~164 ~124 ~119 dirt
setblock ~164 ~124 ~120 dirt
setblock ~164 ~124 ~121 dirt
setblock ~164 ~125 ~76 short_grass
setblock ~164 ~125 ~79 grass_block
setblock ~164 ~125 ~81 dirt
setblock ~164 ~125 ~82 dirt
setblock ~164 ~125 ~85 grass_block
setblock ~164 ~125 ~86 grass_block
setblock ~164 ~125 ~87 grass_block
setblock ~164 ~125 ~88 grass_block
setblock ~164 ~125 ~90 fern
setblock ~164 ~125 ~92 fern
setblock ~164 ~125 ~93 short_grass
setblock ~164 ~125 ~94 grass_block
setblock ~164 ~125 ~95 grass_block
setblock ~164 ~125 ~96 grass_block
setblock ~164 ~125 ~97 grass_block
setblock ~164 ~125 ~98 grass_block
setblock ~164 ~125 ~99 grass_block
setblock ~164 ~125 ~100 grass_block
setblock ~164 ~125 ~101 grass_block
setblock ~164 ~125 ~102 grass_block
setblock ~164 ~125 ~103 grass_block
setblock ~164 ~125 ~104 grass_block
setblock ~164 ~125 ~105 short_grass
setblock ~164 ~125 ~106 short_grass
setblock ~164 ~125 ~107 short_grass
setblock ~164 ~125 ~108 short_grass
setblock ~164 ~125 ~112 grass_block
setblock ~164 ~125 ~113 grass_block
setblock ~164 ~125 ~114 grass_block
setblock ~164 ~125 ~115 dirt
setblock ~164 ~125 ~116 dirt
setblock ~164 ~125 ~117 dirt
setblock ~164 ~125 ~118 dirt
setblock ~164 ~125 ~119 dirt
setblock ~164 ~125 ~120 dirt
setblock ~164 ~125 ~121 dirt
setblock ~164 ~126 ~81 grass_block
setblock ~164 ~126 ~82 grass_block
setblock ~164 ~126 ~87 poppy
setblock ~164 ~126 ~96 poppy
setblock ~164 ~126 ~99 short_grass
setblock ~164 ~126 ~101 short_grass
setblock ~164 ~126 ~103 short_grass
setblock ~164 ~126 ~113 short_grass
setblock ~164 ~126 ~114 short_grass
setblock ~164 ~126 ~115 grass_block
setblock ~164 ~126 ~116 grass_block
setblock ~164 ~126 ~117 grass_block
setblock ~164 ~126 ~118 grass_block
setblock ~164 ~126 ~119 dirt
setblock ~164 ~126 ~120 dirt
setblock ~164 ~126 ~121 dirt
setblock ~164 ~127 ~119 grass_block
setblock ~164 ~127 ~120 grass_block
setblock ~164 ~127 ~121 grass_block
setblock ~165 ~108 ~95 dirt
setblock ~165 ~108 ~96 dirt
setblock ~165 ~108 ~97 dirt
setblock ~165 ~109 ~94 dirt
setblock ~165 ~109 ~95 dirt
setblock ~165 ~109 ~96 dirt
setblock ~165 ~109 ~97 dirt
setblock ~165 ~109 ~98 dirt
setblock ~165 ~110 ~94 dirt
setblock ~165 ~110 ~95 dirt
setblock ~165 ~110 ~96 dirt
setblock ~165 ~110 ~97 dirt
setblock ~165 ~110 ~98 dirt
setblock ~165 ~111 ~92 dirt
setblock ~165 ~111 ~93 dirt
setblock ~165 ~111 ~94 dirt
setblock ~165 ~111 ~95 dirt
setblock ~165 ~111 ~96 dirt
setblock ~165 ~111 ~97 dirt
setblock ~165 ~111 ~98 dirt
setblock ~165 ~111 ~99 dirt
setblock ~165 ~111 ~109 dirt
setblock ~165 ~112 ~91 dirt
setblock ~165 ~112 ~92 dirt
setblock ~165 ~112 ~93 dirt
setblock ~165 ~112 ~94 dirt
setblock ~165 ~112 ~95 dirt
setblock ~165 ~112 ~96 dirt
setblock ~165 ~112 ~97 dirt
setblock ~165 ~112 ~98 dirt
setblock ~165 ~112 ~99 dirt
setblock ~165 ~112 ~100 dirt
setblock ~165 ~112 ~108 dirt
setblock ~165 ~112 ~109 dirt
setblock ~165 ~112 ~110 dirt
setblock ~165 ~113 ~91 dirt
setblock ~165 ~113 ~92 dirt
setblock ~165 ~113 ~93 dirt
setblock ~165 ~113 ~94 dirt
setblock ~165 ~113 ~95 dirt
setblock ~165 ~113 ~96 dirt
setblock ~165 ~113 ~97 dirt
setblock ~165 ~113 ~98 dirt
setblock ~165 ~113 ~99 dirt
setblock ~165 ~113 ~100 dirt
setblock ~165 ~113 ~107 dirt
setblock ~165 ~113 ~108 dirt
setblock ~165 ~113 ~109 dirt
setblock ~165 ~113 ~110 dirt
setblock ~165 ~113 ~111 dirt
setblock ~165 ~114 ~91 dirt
setblock ~165 ~114 ~92 dirt
setblock ~165 ~114 ~93 dirt
setblock ~165 ~114 ~94 dirt
setblock ~165 ~114 ~95 dirt
setblock ~165 ~114 ~96 dirt
setblock ~165 ~114 ~97 dirt
setblock ~165 ~114 ~98 dirt
setblock ~165 ~114 ~99 dirt
setblock ~165 ~114 ~100 dirt
setblock ~165 ~114 ~101 dirt
setblock ~165 ~114 ~107 dirt
setblock ~165 ~114 ~108 dirt
setblock ~165 ~114 ~109 dirt
setblock ~165 ~114 ~110 dirt
setblock ~165 ~114 ~111 dirt
setblock ~165 ~114 ~112 dirt
setblock ~165 ~115 ~90 dirt
setblock ~165 ~115 ~91 dirt
setblock ~165 ~115 ~92 dirt
setblock ~165 ~115 ~93 dirt
setblock ~165 ~115 ~94 dirt
setblock ~165 ~115 ~95 dirt
setblock ~165 ~115 ~96 dirt
setblock ~165 ~115 ~97 dirt
setblock ~165 ~115 ~98 dirt
setblock ~165 ~115 ~99 dirt
setblock ~165 ~115 ~100 dirt
setblock ~165 ~115 ~101 dirt
setblock ~165 ~115 ~102 dirt
setblock ~165 ~115 ~105 dirt
setblock ~165 ~115 ~106 dirt
setblock ~165 ~115 ~107 dirt
setblock ~165 ~115 ~108 dirt
setblock ~165 ~115 ~109 dirt
setblock ~165 ~115 ~110 dirt
setblock ~165 ~115 ~111 dirt
setblock ~165 ~115 ~112 dirt
setblock ~165 ~115 ~114 dirt
setblock ~165 ~116 ~89 dirt
setblock ~165 ~116 ~90 dirt
setblock ~165 ~116 ~91 dirt
setblock ~165 ~116 ~92 dirt
setblock ~165 ~116 ~93 dirt
setblock ~165 ~116 ~94 dirt
setblock ~165 ~116 ~95 dirt
setblock ~165 ~116 ~96 dirt
setblock ~165 ~116 ~97 dirt
