setblock ~166 ~125 ~102 grass_block
setblock ~166 ~125 ~103 grass_block
setblock ~166 ~125 ~104 grass_block
setblock ~166 ~125 ~105 grass_block
setblock ~166 ~125 ~110 poppy
setblock ~166 ~125 ~123 poppy
setblock ~166 ~125 ~128 grass_block
setblock ~166 ~125 ~129 grass_block
setblock ~166 ~125 ~130 grass_block
setblock ~166 ~125 ~131 grass_block
setblock ~166 ~125 ~132 dirt
setblock ~166 ~125 ~133 dirt
setblock ~166 ~125 ~134 dirt
setblock ~166 ~125 ~135 dirt
setblock ~166 ~125 ~136 dirt
setblock ~166 ~125 ~137 dirt
setblock ~166 ~125 ~138 dirt
setblock ~166 ~125 ~139 dirt
setblock ~166 ~125 ~140 dirt
setblock ~166 ~126 ~88 poppy
setblock ~166 ~126 ~89 short_grass
setblock ~166 ~126 ~95 short_grass
setblock ~166 ~126 ~99 grass_block
setblock ~166 ~126 ~100 grass_block
setblock ~166 ~126 ~101 grass_block
setblock ~166 ~126 ~102 short_grass
setblock ~166 ~126 ~104 fern
setblock ~166 ~126 ~132 grass_block
setblock ~166 ~126 ~133 grass_block
setblock ~166 ~126 ~134 grass_block
setblock ~166 ~126 ~135 dirt
setblock ~166 ~126 ~136 dirt
setblock ~166 ~126 ~137 dirt
setblock ~166 ~126 ~138 dirt
setblock ~166 ~126 ~139 dirt
setblock ~166 ~126 ~140 dirt
setblock ~166 ~127 ~110 oak_leaves[persistent=null]
setblock ~166 ~127 ~112 oak_leaves[persistent=null]
setblock ~166 ~127 ~113 oak_leaves[persistent=null]
setblock ~166 ~127 ~114 oak_leaves[persistent=null]
setblock ~166 ~127 ~116 oak_leaves[persistent=null]
setblock ~166 ~127 ~133 fern
setblock ~166 ~127 ~135 grass_block
setblock ~166 ~127 ~136 grass_block
setblock ~166 ~127 ~137 dirt
setblock ~166 ~127 ~138 dirt
setblock ~166 ~127 ~139 dirt
setblock ~166 ~127 ~140 dirt
setblock ~166 ~128 ~109 jungle_leaves[persistent=null]
setblock ~166 ~128 ~110 oak_leaves[persistent=null]
setblock ~166 ~128 ~111 oak_leaves[persistent=null]
setblock ~166 ~128 ~113 jungle_leaves[persistent=null]
setblock ~166 ~128 ~114 oak_leaves[persistent=null]
setblock ~166 ~128 ~115 oak_leaves[persistent=null]
setblock ~166 ~128 ~116 jungle_leaves[persistent=null]
setblock ~166 ~128 ~135 short_grass
setblock ~166 ~128 ~136 short_grass
setblock ~166 ~128 ~137 grass_block
setblock ~166 ~128 ~138 grass_block
setblock ~166 ~128 ~139 dirt
setblock ~166 ~128 ~140 dirt
setblock ~166 ~129 ~111 oak_leaves[persistent=null]
setblock ~166 ~129 ~113 oak_wood
setblock ~166 ~129 ~114 jungle_leaves[persistent=null]
setblock ~166 ~129 ~116 oak_leaves[persistent=null]
setblock ~166 ~129 ~138 short_grass
setblock ~166 ~129 ~139 grass_block
setblock ~166 ~129 ~140 dirt
setblock ~166 ~130 ~109 oak_leaves[persistent=null]
setblock ~166 ~130 ~110 oak_leaves[persistent=null]
setblock ~166 ~130 ~111 oak_leaves[persistent=null]
setblock ~166 ~130 ~112 oak_leaves[persistent=null]
setblock ~166 ~130 ~113 jungle_leaves[persistent=null]
setblock ~166 ~130 ~115 oak_leaves[persistent=null]
setblock ~166 ~130 ~116 oak_leaves[persistent=null]
setblock ~166 ~130 ~140 grass_block
setblock ~166 ~131 ~108 oak_leaves[persistent=null]
setblock ~166 ~131 ~109 oak_leaves[persistent=null]
setblock ~166 ~131 ~112 oak_leaves[persistent=null]
setblock ~166 ~131 ~113 oak_leaves[persistent=null]
setblock ~166 ~131 ~114 oak_wood
setblock ~166 ~131 ~116 oak_leaves[persistent=null]
setblock ~166 ~132 ~106 oak_leaves[persistent=null]
setblock ~166 ~132 ~108 oak_leaves[persistent=null]
setblock ~166 ~132 ~110 jungle_leaves[persistent=null]
setblock ~166 ~132 ~111 jungle_leaves[persistent=null]
setblock ~166 ~132 ~112 oak_leaves[persistent=null]
setblock ~166 ~132 ~113 oak_wood
setblock ~166 ~132 ~114 oak_leaves[persistent=null]
setblock ~166 ~132 ~115 oak_leaves[persistent=null]
setblock ~166 ~132 ~116 oak_leaves[persistent=null]
setblock ~166 ~133 ~107 oak_leaves[persistent=null]
setblock ~166 ~133 ~109 oak_leaves[persistent=null]
setblock ~166 ~133 ~110 oak_wood
setblock ~166 ~133 ~111 oak_leaves[persistent=null]
setblock ~166 ~133 ~112 jungle_leaves[persistent=null]
setblock ~166 ~133 ~113 oak_leaves[persistent=null]
setblock ~166 ~133 ~114 oak_leaves[persistent=null]
setblock ~166 ~134 ~107 oak_wood
setblock ~166 ~134 ~108 oak_leaves[persistent=null]
setblock ~166 ~134 ~109 jungle_leaves[persistent=null]
setblock ~166 ~134 ~113 oak_leaves[persistent=null]
setblock ~166 ~134 ~114 oak_leaves[persistent=null]
setblock ~166 ~134 ~115 oak_leaves[persistent=null]
setblock ~166 ~134 ~116 oak_leaves[persistent=null]
setblock ~166 ~134 ~117 jungle_leaves[persistent=null]
setblock ~166 ~135 ~106 oak_leaves[persistent=null]
setblock ~166 ~135 ~107 oak_leaves[persistent=null]
setblock ~166 ~135 ~109 oak_leaves[persistent=null]
setblock ~166 ~135 ~110 oak_leaves[persistent=null]
setblock ~166 ~135 ~111 oak_leaves[persistent=null]
setblock ~166 ~135 ~112 oak_leaves[persistent=null]
setblock ~166 ~135 ~113 oak_wood
setblock ~166 ~135 ~114 oak_wood
setblock ~166 ~135 ~115 oak_leaves[persistent=null]
setblock ~166 ~135 ~117 jungle_leaves[persistent=null]
setblock ~166 ~136 ~106 oak_leaves[persistent=null]
setblock ~166 ~136 ~109 oak_leaves[persistent=null]
setblock ~166 ~136 ~110 oak_leaves[persistent=null]
setblock ~166 ~136 ~111 oak_leaves[persistent=null]
setblock ~166 ~136 ~114 oak_leaves[persistent=null]
setblock ~166 ~136 ~115 oak_wood
setblock ~166 ~136 ~116 jungle_leaves[persistent=null]
setblock ~166 ~136 ~117 oak_leaves[persistent=null]
setblock ~166 ~137 ~108 oak_leaves[persistent=null]
setblock ~166 ~137 ~109 oak_leaves[persistent=null]
setblock ~166 ~137 ~110 oak_leaves[persistent=null]
setblock ~166 ~137 ~111 oak_leaves[persistent=null]
setblock ~166 ~137 ~114 jungle_leaves[persistent=null]
setblock ~166 ~137 ~115 oak_leaves[persistent=null]
setblock ~166 ~137 ~116 oak_leaves[persistent=null]
setblock ~166 ~137 ~117 oak_leaves[persistent=null]
setblock ~167 ~98 ~97 dirt
setblock ~167 ~99 ~97 dirt
setblock ~167 ~100 ~96 dirt
setblock ~167 ~100 ~97 dirt
setblock ~167 ~100 ~98 dirt
setblock ~167 ~101 ~94 dirt
setblock ~167 ~101 ~95 dirt
setblock ~167 ~101 ~96 dirt
setblock ~167 ~101 ~97 dirt
setblock ~167 ~101 ~98 dirt
setblock ~167 ~101 ~99 dirt
setblock ~167 ~101 ~100 dirt
setblock ~167 ~101 ~101 dirt
setblock ~167 ~102 ~94 dirt
setblock ~167 ~102 ~95 dirt
setblock ~167 ~102 ~96 dirt
setblock ~167 ~102 ~97 dirt
setblock ~167 ~102 ~98 dirt
setblock ~167 ~102 ~99 dirt
setblock ~167 ~102 ~100 dirt
setblock ~167 ~102 ~101 dirt
setblock ~167 ~103 ~94 dirt
setblock ~167 ~103 ~95 dirt
setblock ~167 ~103 ~96 dirt
setblock ~167 ~103 ~97 dirt
setblock ~167 ~103 ~98 dirt
setblock ~167 ~103 ~99 dirt
setblock ~167 ~103 ~100 dirt
setblock ~167 ~103 ~101 dirt
setblock ~167 ~103 ~102 dirt
setblock ~167 ~104 ~93 dirt
setblock ~167 ~104 ~94 dirt
setblock ~167 ~104 ~95 dirt
setblock ~167 ~104 ~96 dirt
setblock ~167 ~104 ~97 dirt
setblock ~167 ~104 ~98 dirt
setblock ~167 ~104 ~99 dirt
setblock ~167 ~104 ~100 dirt
setblock ~167 ~104 ~101 dirt
setblock ~167 ~104 ~102 dirt
setblock ~167 ~104 ~103 dirt
setblock ~167 ~105 ~92 dirt
setblock ~167 ~105 ~93 dirt
setblock ~167 ~105 ~94 dirt
setblock ~167 ~105 ~95 dirt
setblock ~167 ~105 ~96 dirt
setblock ~167 ~105 ~97 dirt
setblock ~167 ~105 ~98 dirt
setblock ~167 ~105 ~99 dirt
setblock ~167 ~105 ~100 dirt
setblock ~167 ~105 ~101 dirt
setblock ~167 ~105 ~102 dirt
setblock ~167 ~105 ~103 dirt
setblock ~167 ~105 ~104 dirt
setblock ~167 ~106 ~90 dirt
setblock ~167 ~106 ~92 dirt
setblock ~167 ~106 ~93 dirt
setblock ~167 ~106 ~94 dirt
setblock ~167 ~106 ~95 dirt
setblock ~167 ~106 ~96 dirt
setblock ~167 ~106 ~97 dirt
setblock ~167 ~106 ~98 dirt
setblock ~167 ~106 ~99 dirt
setblock ~167 ~106 ~100 dirt
setblock ~167 ~106 ~101 dirt
setblock ~167 ~106 ~102 dirt
setblock ~167 ~106 ~103 dirt
setblock ~167 ~106 ~104 dirt
setblock ~167 ~106 ~105 dirt
setblock ~167 ~107 ~90 dirt
setblock ~167 ~107 ~91 dirt
setblock ~167 ~107 ~92 dirt
setblock ~167 ~107 ~93 dirt
setblock ~167 ~107 ~94 dirt
setblock ~167 ~107 ~95 dirt
setblock ~167 ~107 ~96 dirt
setblock ~167 ~107 ~97 dirt
setblock ~167 ~107 ~98 dirt
setblock ~167 ~107 ~99 dirt
setblock ~167 ~107 ~100 dirt
setblock ~167 ~107 ~101 dirt
setblock ~167 ~107 ~102 dirt
setblock ~167 ~107 ~103 dirt
setblock ~167 ~107 ~104 dirt
setblock ~167 ~107 ~105 dirt
setblock ~167 ~108 ~89 dirt
setblock ~167 ~108 ~90 dirt
setblock ~167 ~108 ~91 dirt
setblock ~167 ~108 ~92 dirt
setblock ~167 ~108 ~93 dirt
setblock ~167 ~108 ~94 dirt
setblock ~167 ~108 ~95 dirt
setblock ~167 ~108 ~96 dirt
setblock ~167 ~108 ~97 dirt
setblock ~167 ~108 ~98 dirt
setblock ~167 ~108 ~99 dirt
setblock ~167 ~108 ~100 dirt
setblock ~167 ~108 ~101 dirt
setblock ~167 ~108 ~102 dirt
setblock ~167 ~108 ~103 dirt
setblock ~167 ~108 ~104 dirt
setblock ~167 ~108 ~105 dirt
setblock ~167 ~109 ~87 dirt
setblock ~167 ~109 ~88 dirt
setblock ~167 ~109 ~89 dirt
setblock ~167 ~109 ~90 dirt
setblock ~167 ~109 ~91 dirt
setblock ~167 ~109 ~92 dirt
setblock ~167 ~109 ~93 dirt
setblock ~167 ~109 ~94 dirt
setblock ~167 ~109 ~95 dirt
setblock ~167 ~109 ~96 dirt
setblock ~167 ~109 ~97 dirt
setblock ~167 ~109 ~98 dirt
setblock ~167 ~109 ~99 dirt
setblock ~167 ~109 ~100 dirt
setblock ~167 ~109 ~101 dirt
setblock ~167 ~109 ~102 dirt
setblock ~167 ~109 ~103 dirt
setblock ~167 ~109 ~104 dirt
setblock ~167 ~109 ~105 dirt
setblock ~167 ~110 ~86 dirt
setblock ~167 ~110 ~87 dirt
setblock ~167 ~110 ~88 dirt
setblock ~167 ~110 ~89 dirt
setblock ~167 ~110 ~90 dirt
setblock ~167 ~110 ~91 dirt
setblock ~167 ~110 ~92 dirt
setblock ~167 ~110 ~93 dirt
setblock ~167 ~110 ~94 dirt
setblock ~167 ~110 ~95 dirt
setblock ~167 ~110 ~96 dirt
setblock ~167 ~110 ~97 dirt
setblock ~167 ~110 ~98 dirt
setblock ~167 ~110 ~99 dirt
setblock ~167 ~110 ~100 dirt
setblock ~167 ~110 ~101 dirt
setblock ~167 ~110 ~102 dirt
setblock ~167 ~110 ~103 dirt
setblock ~167 ~110 ~104 dirt
setblock ~167 ~110 ~105 dirt
setblock ~167 ~110 ~106 dirt
setblock ~167 ~111 ~85 dirt
setblock ~167 ~111 ~86 dirt
setblock ~167 ~111 ~87 dirt
setblock ~167 ~111 ~88 dirt
setblock ~167 ~111 ~89 dirt
setblock ~167 ~111 ~90 dirt
setblock ~167 ~111 ~91 dirt
setblock ~167 ~111 ~92 dirt
setblock ~167 ~111 ~93 dirt
setblock ~167 ~111 ~94 dirt
setblock ~167 ~111 ~95 dirt
setblock ~167 ~111 ~96 dirt
setblock ~167 ~111 ~97 dirt
setblock ~167 ~111 ~98 dirt
setblock ~167 ~111 ~99 dirt
setblock ~167 ~111 ~100 dirt
setblock ~167 ~111 ~101 dirt
setblock ~167 ~111 ~102 dirt
setblock ~167 ~111 ~103 dirt
setblock ~167 ~111 ~104 dirt
setblock ~167 ~111 ~105 dirt
setblock ~167 ~111 ~106 dirt
setblock ~167 ~111 ~107 dirt
setblock ~167 ~112 ~85 dirt
setblock ~167 ~112 ~86 dirt
setblock ~167 ~112 ~87 dirt
setblock ~167 ~112 ~88 dirt
setblock ~167 ~112 ~89 dirt
setblock ~167 ~112 ~90 dirt
setblock ~167 ~112 ~91 dirt
setblock ~167 ~112 ~92 dirt
setblock ~167 ~112 ~93 dirt
setblock ~167 ~112 ~94 dirt
setblock ~167 ~112 ~95 dirt
setblock ~167 ~112 ~96 dirt
setblock ~167 ~112 ~97 dirt
setblock ~167 ~112 ~98 dirt
setblock ~167 ~112 ~99 dirt
setblock ~167 ~112 ~100 dirt
setblock ~167 ~112 ~101 dirt
setblock ~167 ~112 ~102 dirt
setblock ~167 ~112 ~103 dirt
setblock ~167 ~112 ~104 dirt
setblock ~167 ~112 ~105 dirt
setblock ~167 ~112 ~106 dirt
setblock ~167 ~112 ~107 dirt
setblock ~167 ~112 ~108 dirt
setblock ~167 ~113 ~84 dirt
setblock ~167 ~113 ~85 dirt
setblock ~167 ~113 ~86 dirt
setblock ~167 ~113 ~87 dirt
setblock ~167 ~113 ~88 dirt
setblock ~167 ~113 ~89 dirt
setblock ~167 ~113 ~90 dirt
setblock ~167 ~113 ~91 dirt
setblock ~167 ~113 ~92 dirt
setblock ~167 ~113 ~93 dirt
setblock ~167 ~113 ~94 dirt
setblock ~167 ~113 ~95 dirt
setblock ~167 ~113 ~96 dirt
setblock ~167 ~113 ~97 dirt
setblock ~167 ~113 ~98 dirt
setblock ~167 ~113 ~99 dirt
setblock ~167 ~113 ~100 dirt
setblock ~167 ~113 ~101 dirt
setblock ~167 ~113 ~102 dirt
setblock ~167 ~113 ~103 dirt
setblock ~167 ~113 ~104 dirt
setblock ~167 ~113 ~105 dirt
setblock ~167 ~113 ~106 dirt
setblock ~167 ~113 ~107 dirt
setblock ~167 ~113 ~108 dirt
setblock ~167 ~114 ~83 dirt
setblock ~167 ~114 ~84 dirt
setblock ~167 ~114 ~85 dirt
setblock ~167 ~114 ~86 dirt
setblock ~167 ~114 ~87 dirt
setblock ~167 ~114 ~88 dirt
setblock ~167 ~114 ~89 dirt
setblock ~167 ~114 ~90 dirt
setblock ~167 ~114 ~91 dirt
setblock ~167 ~114 ~92 dirt
setblock ~167 ~114 ~93 dirt
setblock ~167 ~114 ~94 dirt
setblock ~167 ~114 ~95 dirt
setblock ~167 ~114 ~96 dirt
setblock ~167 ~114 ~97 dirt
setblock ~167 ~114 ~98 dirt
setblock ~167 ~114 ~99 dirt
setblock ~167 ~114 ~100 dirt
setblock ~167 ~114 ~101 dirt
setblock ~167 ~114 ~102 dirt
setblock ~167 ~114 ~103 dirt
setblock ~167 ~114 ~104 dirt
setblock ~167 ~114 ~105 dirt
setblock ~167 ~114 ~106 dirt
setblock ~167 ~114 ~107 dirt
setblock ~167 ~114 ~108 dirt
setblock ~167 ~114 ~109 dirt
setblock ~167 ~115 ~82 dirt
setblock ~167 ~115 ~83 dirt
setblock ~167 ~115 ~84 dirt
setblock ~167 ~115 ~85 dirt
setblock ~167 ~115 ~86 dirt
setblock ~167 ~115 ~87 dirt
setblock ~167 ~115 ~88 dirt
setblock ~167 ~115 ~89 dirt
setblock ~167 ~115 ~90 dirt
setblock ~167 ~115 ~91 dirt
setblock ~167 ~115 ~92 dirt
setblock ~167 ~115 ~93 dirt
setblock ~167 ~115 ~94 dirt
setblock ~167 ~115 ~95 dirt
setblock ~167 ~115 ~96 dirt
setblock ~167 ~115 ~97 dirt
setblock ~167 ~115 ~98 dirt
setblock ~167 ~115 ~99 dirt
setblock ~167 ~115 ~100 dirt
setblock ~167 ~115 ~101 dirt
setblock ~167 ~115 ~102 dirt
setblock ~167 ~115 ~103 dirt
setblock ~167 ~115 ~104 dirt
setblock ~167 ~115 ~105 dirt
setblock ~167 ~115 ~106 dirt
setblock ~167 ~115 ~107 dirt
setblock ~167 ~115 ~108 dirt
setblock ~167 ~115 ~109 dirt
setblock ~167 ~115 ~116 dirt
setblock ~167 ~116 ~82 dirt
setblock ~167 ~116 ~83 dirt
setblock ~167 ~116 ~84 dirt
setblock ~167 ~116 ~85 dirt
setblock ~167 ~116 ~86 dirt
setblock ~167 ~116 ~87 dirt
setblock ~167 ~116 ~88 dirt
setblock ~167 ~116 ~89 dirt
setblock ~167 ~116 ~90 dirt
setblock ~167 ~116 ~91 dirt
setblock ~167 ~116 ~92 dirt
setblock ~167 ~116 ~93 dirt
setblock ~167 ~116 ~94 dirt
setblock ~167 ~116 ~95 dirt
setblock ~167 ~116 ~96 dirt
setblock ~167 ~116 ~97 dirt
setblock ~167 ~116 ~98 dirt
setblock ~167 ~116 ~99 dirt
setblock ~167 ~116 ~100 dirt
setblock ~167 ~116 ~101 dirt
setblock ~167 ~116 ~102 dirt
setblock ~167 ~116 ~103 dirt
setblock ~167 ~116 ~104 dirt
setblock ~167 ~116 ~105 dirt
setblock ~167 ~116 ~106 dirt
setblock ~167 ~116 ~107 dirt
setblock ~167 ~116 ~108 dirt
setblock ~167 ~116 ~109 dirt
setblock ~167 ~116 ~110 dirt
setblock ~167 ~116 ~115 dirt
setblock ~167 ~116 ~116 dirt
setblock ~167 ~117 ~81 dirt
setblock ~167 ~117 ~82 dirt
setblock ~167 ~117 ~83 dirt
setblock ~167 ~117 ~84 dirt
setblock ~167 ~117 ~85 dirt
setblock ~167 ~117 ~86 dirt
setblock ~167 ~117 ~87 dirt
setblock ~167 ~117 ~88 dirt
setblock ~167 ~117 ~89 dirt
setblock ~167 ~117 ~90 dirt
setblock ~167 ~117 ~91 dirt
setblock ~167 ~117 ~92 dirt
setblock ~167 ~117 ~93 dirt
setblock ~167 ~117 ~94 dirt
setblock ~167 ~117 ~95 dirt
setblock ~167 ~117 ~96 dirt
setblock ~167 ~117 ~97 dirt
setblock ~167 ~117 ~98 dirt
setblock ~167 ~117 ~99 dirt
setblock ~167 ~117 ~100 dirt
setblock ~167 ~117 ~101 dirt
setblock ~167 ~117 ~102 dirt
setblock ~167 ~117 ~103 dirt
setblock ~167 ~117 ~104 dirt
setblock ~167 ~117 ~105 dirt
setblock ~167 ~117 ~106 dirt
setblock ~167 ~117 ~107 dirt
setblock ~167 ~117 ~108 dirt
setblock ~167 ~117 ~109 dirt
setblock ~167 ~117 ~110 dirt
setblock ~167 ~117 ~111 dirt
setblock ~167 ~117 ~114 dirt
setblock ~167 ~117 ~115 dirt
setblock ~167 ~117 ~116 dirt
setblock ~167 ~117 ~117 dirt
setblock ~167 ~117 ~122 dirt
setblock ~167 ~117 ~126 dirt
setblock ~167 ~117 ~128 dirt
setblock ~167 ~117 ~134 dirt
setblock ~167 ~118 ~81 dirt
setblock ~167 ~118 ~82 dirt
setblock ~167 ~118 ~83 dirt
setblock ~167 ~118 ~84 dirt
setblock ~167 ~118 ~85 dirt
setblock ~167 ~118 ~86 dirt
setblock ~167 ~118 ~87 dirt
setblock ~167 ~118 ~88 dirt
setblock ~167 ~118 ~89 dirt
setblock ~167 ~118 ~90 dirt
setblock ~167 ~118 ~91 dirt
setblock ~167 ~118 ~92 dirt
setblock ~167 ~118 ~93 dirt
setblock ~167 ~118 ~94 dirt
setblock ~167 ~118 ~95 dirt
setblock ~167 ~118 ~96 dirt
setblock ~167 ~118 ~97 dirt
setblock ~167 ~118 ~98 dirt
setblock ~167 ~118 ~99 dirt
setblock ~167 ~118 ~100 dirt
setblock ~167 ~118 ~101 dirt
setblock ~167 ~118 ~102 dirt
setblock ~167 ~118 ~103 dirt
setblock ~167 ~118 ~104 dirt
setblock ~167 ~118 ~105 dirt
setblock ~167 ~118 ~106 dirt
setblock ~167 ~118 ~107 dirt
setblock ~167 ~118 ~108 dirt
setblock ~167 ~118 ~109 dirt
setblock ~167 ~118 ~110 dirt
setblock ~167 ~118 ~111 dirt
setblock ~167 ~118 ~113 dirt
setblock ~167 ~118 ~114 dirt
setblock ~167 ~118 ~115 dirt
setblock ~167 ~118 ~116 dirt
setblock ~167 ~118 ~117 dirt
setblock ~167 ~118 ~118 dirt
setblock ~167 ~118 ~121 dirt
setblock ~167 ~118 ~122 dirt
setblock ~167 ~118 ~123 dirt
setblock ~167 ~118 ~126 dirt
setblock ~167 ~118 ~127 dirt
setblock ~167 ~118 ~128 dirt
setblock ~167 ~118 ~129 dirt
setblock ~167 ~118 ~133 dirt
setblock ~167 ~118 ~134 dirt
setblock ~167 ~118 ~135 dirt
setblock ~167 ~119 ~81 dirt
setblock ~167 ~119 ~82 dirt
setblock ~167 ~119 ~83 dirt
setblock ~167 ~119 ~84 dirt
setblock ~167 ~119 ~85 dirt
setblock ~167 ~119 ~86 dirt
setblock ~167 ~119 ~87 dirt
setblock ~167 ~119 ~88 dirt
setblock ~167 ~119 ~89 dirt
setblock ~167 ~119 ~90 dirt
setblock ~167 ~119 ~91 dirt
setblock ~167 ~119 ~92 dirt
setblock ~167 ~119 ~93 dirt
setblock ~167 ~119 ~94 dirt
setblock ~167 ~119 ~95 dirt
setblock ~167 ~119 ~96 dirt
setblock ~167 ~119 ~97 dirt
setblock ~167 ~119 ~98 dirt
setblock ~167 ~119 ~99 dirt
setblock ~167 ~119 ~100 dirt
setblock ~167 ~119 ~101 dirt
setblock ~167 ~119 ~102 dirt
setblock ~167 ~119 ~103 dirt
setblock ~167 ~119 ~104 dirt
setblock ~167 ~119 ~105 dirt
setblock ~167 ~119 ~106 dirt
setblock ~167 ~119 ~107 dirt
setblock ~167 ~119 ~108 dirt
setblock ~167 ~119 ~109 dirt
setblock ~167 ~119 ~110 dirt
setblock ~167 ~119 ~111 dirt
setblock ~167 ~119 ~112 dirt
setblock ~167 ~119 ~113 dirt
setblock ~167 ~119 ~114 dirt
setblock ~167 ~119 ~115 dirt
setblock ~167 ~119 ~116 dirt
setblock ~167 ~119 ~117 dirt
setblock ~167 ~119 ~118 dirt
setblock ~167 ~119 ~119 dirt
setblock ~167 ~119 ~120 dirt
setblock ~167 ~119 ~121 dirt
setblock ~167 ~119 ~122 dirt
setblock ~167 ~119 ~123 dirt
setblock ~167 ~119 ~124 dirt
setblock ~167 ~119 ~125 dirt
setblock ~167 ~119 ~126 dirt
setblock ~167 ~119 ~127 dirt
setblock ~167 ~119 ~128 dirt
setblock ~167 ~119 ~129 dirt
setblock ~167 ~119 ~130 dirt
setblock ~167 ~119 ~132 dirt
setblock ~167 ~119 ~133 dirt
setblock ~167 ~119 ~134 dirt
setblock ~167 ~119 ~135 dirt
setblock ~167 ~119 ~136 dirt
setblock ~167 ~119 ~138 dirt
setblock ~167 ~120 ~78 dirt
setblock ~167 ~120 ~79 dirt
setblock ~167 ~120 ~80 dirt
setblock ~167 ~120 ~81 dirt
setblock ~167 ~120 ~82 dirt
setblock ~167 ~120 ~83 dirt
setblock ~167 ~120 ~84 dirt
setblock ~167 ~120 ~85 dirt
setblock ~167 ~120 ~86 dirt
setblock ~167 ~120 ~87 dirt
setblock ~167 ~120 ~88 dirt
setblock ~167 ~120 ~89 dirt
setblock ~167 ~120 ~90 dirt
setblock ~167 ~120 ~91 dirt
setblock ~167 ~120 ~92 dirt
setblock ~167 ~120 ~93 dirt
setblock ~167 ~120 ~94 dirt
setblock ~167 ~120 ~95 dirt
setblock ~167 ~120 ~96 dirt
setblock ~167 ~120 ~97 dirt
setblock ~167 ~120 ~98 dirt
setblock ~167 ~120 ~99 dirt
setblock ~167 ~120 ~100 dirt
setblock ~167 ~120 ~101 dirt
setblock ~167 ~120 ~102 dirt
setblock ~167 ~120 ~103 dirt
setblock ~167 ~120 ~104 dirt
setblock ~167 ~120 ~105 dirt
setblock ~167 ~120 ~106 dirt
setblock ~167 ~120 ~107 dirt
setblock ~167 ~120 ~108 dirt
setblock ~167 ~120 ~109 dirt
setblock ~167 ~120 ~110 dirt
setblock ~167 ~120 ~111 dirt
setblock ~167 ~120 ~112 dirt
setblock ~167 ~120 ~113 dirt
setblock ~167 ~120 ~114 dirt
setblock ~167 ~120 ~115 dirt
setblock ~167 ~120 ~116 dirt
setblock ~167 ~120 ~117 dirt
setblock ~167 ~120 ~118 dirt
setblock ~167 ~120 ~119 dirt
setblock ~167 ~120 ~120 dirt
setblock ~167 ~120 ~121 dirt
setblock ~167 ~120 ~122 dirt
setblock ~167 ~120 ~123 dirt
setblock ~167 ~120 ~124 dirt
setblock ~167 ~120 ~125 dirt
setblock ~167 ~120 ~126 dirt
setblock ~167 ~120 ~127 dirt
setblock ~167 ~120 ~128 dirt
setblock ~167 ~120 ~129 dirt
setblock ~167 ~120 ~130 dirt
setblock ~167 ~120 ~131 dirt
setblock ~167 ~120 ~132 dirt
setblock ~167 ~120 ~133 dirt
setblock ~167 ~120 ~134 dirt
setblock ~167 ~120 ~135 dirt
setblock ~167 ~120 ~136 dirt
setblock ~167 ~120 ~137 dirt
setblock ~167 ~120 ~138 dirt
setblock ~167 ~121 ~77 dirt
setblock ~167 ~121 ~78 dirt
setblock ~167 ~121 ~79 dirt
setblock ~167 ~121 ~80 dirt
setblock ~167 ~121 ~81 dirt
setblock ~167 ~121 ~82 dirt
setblock ~167 ~121 ~83 dirt
setblock ~167 ~121 ~84 dirt
setblock ~167 ~121 ~85 dirt
setblock ~167 ~121 ~86 dirt
setblock ~167 ~121 ~87 dirt
setblock ~167 ~121 ~88 dirt
setblock ~167 ~121 ~89 dirt
setblock ~167 ~121 ~90 dirt
setblock ~167 ~121 ~91 dirt
setblock ~167 ~121 ~92 dirt
setblock ~167 ~121 ~93 dirt
setblock ~167 ~121 ~94 dirt
setblock ~167 ~121 ~95 dirt
setblock ~167 ~121 ~96 dirt
setblock ~167 ~121 ~97 dirt
setblock ~167 ~121 ~98 dirt
setblock ~167 ~121 ~99 dirt
setblock ~167 ~121 ~100 dirt
setblock ~167 ~121 ~101 dirt
setblock ~167 ~121 ~102 dirt
setblock ~167 ~121 ~103 dirt
setblock ~167 ~121 ~104 dirt
setblock ~167 ~121 ~105 dirt
setblock ~167 ~121 ~106 dirt
setblock ~167 ~121 ~107 dirt
setblock ~167 ~121 ~108 dirt
setblock ~167 ~121 ~109 dirt
setblock ~167 ~121 ~110 dirt
setblock ~167 ~121 ~111 dirt
setblock ~167 ~121 ~112 dirt
setblock ~167 ~121 ~113 dirt
setblock ~167 ~121 ~114 dirt
setblock ~167 ~121 ~115 dirt
setblock ~167 ~121 ~116 dirt
setblock ~167 ~121 ~117 dirt
setblock ~167 ~121 ~118 dirt
setblock ~167 ~121 ~119 dirt
setblock ~167 ~121 ~120 dirt
setblock ~167 ~121 ~121 dirt
setblock ~167 ~121 ~122 dirt
setblock ~167 ~121 ~123 dirt
setblock ~167 ~121 ~124 dirt
setblock ~167 ~121 ~125 dirt
setblock ~167 ~121 ~126 dirt
setblock ~167 ~121 ~127 dirt
setblock ~167 ~121 ~128 dirt
setblock ~167 ~121 ~129 dirt
setblock ~167 ~121 ~130 dirt
setblock ~167 ~121 ~131 dirt
setblock ~167 ~121 ~132 dirt
setblock ~167 ~121 ~133 dirt
setblock ~167 ~121 ~134 dirt
setblock ~167 ~121 ~135 dirt
setblock ~167 ~121 ~136 dirt
setblock ~167 ~121 ~137 dirt
setblock ~167 ~121 ~138 dirt
setblock ~167 ~121 ~139 dirt
setblock ~167 ~122 ~77 dirt
setblock ~167 ~122 ~78 dirt
setblock ~167 ~122 ~79 dirt
setblock ~167 ~122 ~80 dirt
setblock ~167 ~122 ~81 dirt
setblock ~167 ~122 ~82 dirt
setblock ~167 ~122 ~83 dirt
setblock ~167 ~122 ~84 dirt
setblock ~167 ~122 ~85 dirt
setblock ~167 ~122 ~86 dirt
setblock ~167 ~122 ~87 dirt
setblock ~167 ~122 ~88 dirt
setblock ~167 ~122 ~89 dirt
setblock ~167 ~122 ~90 dirt
setblock ~167 ~122 ~91 dirt
setblock ~167 ~122 ~92 dirt
setblock ~167 ~122 ~93 dirt
setblock ~167 ~122 ~94 dirt
setblock ~167 ~122 ~95 dirt
setblock ~167 ~122 ~96 dirt
setblock ~167 ~122 ~97 dirt
setblock ~167 ~122 ~98 dirt
setblock ~167 ~122 ~99 dirt
setblock ~167 ~122 ~100 dirt
setblock ~167 ~122 ~101 dirt
setblock ~167 ~122 ~102 dirt
setblock ~167 ~122 ~103 dirt
setblock ~167 ~122 ~104 dirt
setblock ~167 ~122 ~105 dirt
setblock ~167 ~122 ~106 dirt
setblock ~167 ~122 ~107 dirt
setblock ~167 ~122 ~108 dirt
setblock ~167 ~122 ~109 dirt
setblock ~167 ~122 ~110 dirt
setblock ~167 ~122 ~111 dirt
setblock ~167 ~122 ~112 dirt
setblock ~167 ~122 ~113 dirt
setblock ~167 ~122 ~114 dirt
setblock ~167 ~122 ~115 dirt
setblock ~167 ~122 ~116 dirt
setblock ~167 ~122 ~117 dirt
setblock ~167 ~122 ~118 dirt
setblock ~167 ~122 ~119 dirt
setblock ~167 ~122 ~120 dirt
setblock ~167 ~122 ~121 dirt
setblock ~167 ~122 ~122 dirt
setblock ~167 ~122 ~123 dirt
setblock ~167 ~122 ~124 dirt
setblock ~167 ~122 ~125 dirt
setblock ~167 ~122 ~126 dirt
setblock ~167 ~122 ~127 dirt
setblock ~167 ~122 ~128 dirt
setblock ~167 ~122 ~129 dirt
setblock ~167 ~122 ~130 dirt
setblock ~167 ~122 ~131 dirt
setblock ~167 ~122 ~132 dirt
setblock ~167 ~122 ~133 dirt
setblock ~167 ~122 ~134 dirt
setblock ~167 ~122 ~135 dirt
setblock ~167 ~122 ~136 dirt
setblock ~167 ~122 ~137 dirt
setblock ~167 ~122 ~138 dirt
setblock ~167 ~122 ~139 dirt
setblock ~167 ~123 ~77 dirt
setblock ~167 ~123 ~78 dirt
setblock ~167 ~123 ~79 dirt
setblock ~167 ~123 ~80 dirt
setblock ~167 ~123 ~81 dirt
setblock ~167 ~123 ~82 dirt
setblock ~167 ~123 ~83 dirt
setblock ~167 ~123 ~84 dirt
setblock ~167 ~123 ~85 dirt
setblock ~167 ~123 ~86 dirt
setblock ~167 ~123 ~87 dirt
setblock ~167 ~123 ~88 dirt
setblock ~167 ~123 ~89 dirt
setblock ~167 ~123 ~90 dirt
setblock ~167 ~123 ~91 dirt
setblock ~167 ~123 ~92 dirt
setblock ~167 ~123 ~93 dirt
setblock ~167 ~123 ~94 dirt
setblock ~167 ~123 ~95 dirt
setblock ~167 ~123 ~96 dirt
setblock ~167 ~123 ~97 dirt
setblock ~167 ~123 ~98 dirt
setblock ~167 ~123 ~99 dirt
setblock ~167 ~123 ~100 dirt
setblock ~167 ~123 ~101 dirt
setblock ~167 ~123 ~102 dirt
setblock ~167 ~123 ~103 dirt
setblock ~167 ~123 ~104 dirt
setblock ~167 ~123 ~105 dirt
setblock ~167 ~123 ~106 dirt
setblock ~167 ~123 ~107 dirt
setblock ~167 ~123 ~108 dirt
setblock ~167 ~123 ~109 dirt
setblock ~167 ~123 ~110 grass_block
setblock ~167 ~123 ~111 grass_block
setblock ~167 ~123 ~112 grass_block
setblock ~167 ~123 ~113 grass_block
setblock ~167 ~123 ~114 grass_block
setblock ~167 ~123 ~115 grass_block
setblock ~167 ~123 ~116 grass_block
setblock ~167 ~123 ~117 grass_block
setblock ~167 ~123 ~118 grass_block
setblock ~167 ~123 ~119 grass_block
setblock ~167 ~123 ~120 grass_block
setblock ~167 ~123 ~121 grass_block
setblock ~167 ~123 ~122 grass_block
setblock ~167 ~123 ~123 dirt
setblock ~167 ~123 ~124 dirt
setblock ~167 ~123 ~125 dirt
setblock ~167 ~123 ~126 dirt
setblock ~167 ~123 ~127 dirt
setblock ~167 ~123 ~128 dirt
setblock ~167 ~123 ~129 dirt
setblock ~167 ~123 ~130 dirt
setblock ~167 ~123 ~131 dirt
setblock ~167 ~123 ~132 dirt
setblock ~167 ~123 ~133 dirt
setblock ~167 ~123 ~134 dirt
setblock ~167 ~123 ~135 dirt
setblock ~167 ~123 ~136 dirt
setblock ~167 ~123 ~137 dirt
setblock ~167 ~123 ~138 dirt
setblock ~167 ~123 ~139 dirt
setblock ~167 ~124 ~77 grass_block
setblock ~167 ~124 ~78 grass_block
setblock ~167 ~124 ~79 grass_block
setblock ~167 ~124 ~80 grass_block
setblock ~167 ~124 ~81 grass_block
setblock ~167 ~124 ~82 grass_block
setblock ~167 ~124 ~83 grass_block
setblock ~167 ~124 ~84 grass_block
setblock ~167 ~124 ~85 grass_block
setblock ~167 ~124 ~86 grass_block
setblock ~167 ~124 ~87 grass_block
setblock ~167 ~124 ~88 dirt
setblock ~167 ~124 ~89 dirt
setblock ~167 ~124 ~90 dirt
setblock ~167 ~124 ~91 dirt
setblock ~167 ~124 ~92 dirt
setblock ~167 ~124 ~93 dirt
setblock ~167 ~124 ~94 dirt
setblock ~167 ~124 ~95 dirt
setblock ~167 ~124 ~96 dirt
setblock ~167 ~124 ~97 dirt
setblock ~167 ~124 ~98 dirt
setblock ~167 ~124 ~99 dirt
setblock ~167 ~124 ~100 dirt
setblock ~167 ~124 ~101 dirt
setblock ~167 ~124 ~102 dirt
setblock ~167 ~124 ~103 dirt
setblock ~167 ~124 ~104 dirt
setblock ~167 ~124 ~105 grass_block
setblock ~167 ~124 ~106 grass_block
setblock ~167 ~124 ~107 grass_block
setblock ~167 ~124 ~108 grass_block
setblock ~167 ~124 ~109 grass_block
setblock ~167 ~124 ~114 short_grass
setblock ~167 ~124 ~123 grass_block
setblock ~167 ~124 ~124 grass_block
setblock ~167 ~124 ~125 grass_block
setblock ~167 ~124 ~126 grass_block
setblock ~167 ~124 ~127 grass_block
setblock ~167 ~124 ~128 grass_block
setblock ~167 ~124 ~129 grass_block
setblock ~167 ~124 ~130 dirt
setblock ~167 ~124 ~131 dirt
setblock ~167 ~124 ~132 dirt
setblock ~167 ~124 ~133 dirt
setblock ~167 ~124 ~134 dirt
setblock ~167 ~124 ~135 dirt
setblock ~167 ~124 ~136 dirt
setblock ~167 ~124 ~137 dirt
setblock ~167 ~124 ~138 dirt
setblock ~167 ~124 ~139 dirt
setblock ~167 ~125 ~78 short_grass
setblock ~167 ~125 ~79 poppy
setblock ~167 ~125 ~84 short_grass
setblock ~167 ~125 ~86 short_grass
setblock ~167 ~125 ~87 fern
setblock ~167 ~125 ~88 grass_block
setblock ~167 ~125 ~89 grass_block
setblock ~167 ~125 ~90 grass_block
setblock ~167 ~125 ~91 grass_block
setblock ~167 ~125 ~92 grass_block
setblock ~167 ~125 ~93 grass_block
setblock ~167 ~125 ~94 grass_block
setblock ~167 ~125 ~95 grass_block
setblock ~167 ~125 ~96 grass_block
setblock ~167 ~125 ~97 grass_block
setblock ~167 ~125 ~98 grass_block
setblock ~167 ~125 ~99 grass_block
setblock ~167 ~125 ~100 grass_block
setblock ~167 ~125 ~101 grass_block
setblock ~167 ~125 ~102 grass_block
setblock ~167 ~125 ~103 grass_block
setblock ~167 ~125 ~104 grass_block
setblock ~167 ~125 ~108 poppy
setblock ~167 ~125 ~124 poppy
setblock ~167 ~125 ~127 short_grass
setblock ~167 ~125 ~130 grass_block
setblock ~167 ~125 ~131 grass_block
setblock ~167 ~125 ~132 grass_block
setblock ~167 ~125 ~133 dirt
setblock ~167 ~125 ~134 dirt
setblock ~167 ~125 ~135 dirt
setblock ~167 ~125 ~136 dirt
setblock ~167 ~125 ~137 dirt
setblock ~167 ~125 ~138 dirt
setblock ~167 ~125 ~139 dirt
setblock ~167 ~126 ~88 fern
setblock ~167 ~126 ~89 short_grass
setblock ~167 ~126 ~90 short_grass
setblock ~167 ~126 ~91 fern
setblock ~167 ~126 ~93 short_grass
setblock ~167 ~126 ~94 short_grass
setblock ~167 ~126 ~96 fern
setblock ~167 ~126 ~97 short_grass
setblock ~167 ~126 ~101 fern
setblock ~167 ~126 ~133 grass_block
setblock ~167 ~126 ~134 grass_block
setblock ~167 ~126 ~135 dirt
setblock ~167 ~126 ~136 dirt
setblock ~167 ~126 ~137 dirt
setblock ~167 ~126 ~138 dirt
setblock ~167 ~126 ~139 dirt
setblock ~167 ~127 ~108 oak_leaves[persistent=null]
setblock ~167 ~127 ~109 oak_leaves[persistent=null]
setblock ~167 ~127 ~110 oak_leaves[persistent=null]
setblock ~167 ~127 ~111 oak_leaves[persistent=null]
setblock ~167 ~127 ~113 oak_leaves[persistent=null]
setblock ~167 ~127 ~135 grass_block
setblock ~167 ~127 ~136 grass_block
setblock ~167 ~127 ~137 dirt
setblock ~167 ~127 ~138 dirt
setblock ~167 ~127 ~139 dirt
setblock ~167 ~128 ~108 jungle_leaves[persistent=null]
setblock ~167 ~128 ~109 oak_leaves[persistent=null]
setblock ~167 ~128 ~111 oak_leaves[persistent=null]
setblock ~167 ~128 ~112 oak_leaves[persistent=null]
setblock ~167 ~128 ~114 jungle_leaves[persistent=null]
setblock ~167 ~128 ~137 grass_block
setblock ~167 ~128 ~138 grass_block
setblock ~167 ~128 ~139 dirt
setblock ~167 ~129 ~108 oak_leaves[persistent=null]
setblock ~167 ~129 ~110 oak_leaves[persistent=null]
setblock ~167 ~129 ~111 oak_wood
setblock ~167 ~129 ~112 oak_wood
setblock ~167 ~129 ~138 short_grass
setblock ~167 ~129 ~139 grass_block
setblock ~167 ~130 ~110 oak_leaves[persistent=null]
setblock ~167 ~130 ~111 jungle_leaves[persistent=null]
setblock ~167 ~131 ~107 oak_leaves[persistent=null]
setblock ~167 ~131 ~108 oak_leaves[persistent=null]
setblock ~167 ~131 ~110 oak_leaves[persistent=null]
setblock ~167 ~131 ~111 oak_leaves[persistent=null]
setblock ~167 ~131 ~112 oak_leaves[persistent=null]
setblock ~167 ~131 ~113 oak_leaves[persistent=null]
setblock ~167 ~132 ~106 oak_leaves[persistent=null]
setblock ~167 ~132 ~110 oak_leaves[persistent=null]
setblock ~167 ~132 ~111 oak_leaves[persistent=null]
setblock ~167 ~132 ~113 oak_wood
setblock ~167 ~133 ~106 oak_leaves[persistent=null]
setblock ~167 ~133 ~107 oak_leaves[persistent=null]
setblock ~167 ~133 ~108 oak_leaves[persistent=null]
setblock ~167 ~133 ~110 oak_wood
setblock ~167 ~133 ~111 oak_leaves[persistent=null]
setblock ~167 ~133 ~112 oak_leaves[persistent=null]
setblock ~167 ~133 ~113 oak_leaves[persistent=null]
setblock ~167 ~133 ~114 oak_leaves[persistent=null]
setblock ~167 ~134 ~106 oak_leaves[persistent=null]
setblock ~167 ~134 ~108 oak_wood
setblock ~167 ~134 ~109 oak_leaves[persistent=null]
setblock ~167 ~134 ~111 oak_leaves[persistent=null]
setblock ~167 ~134 ~112 oak_wood
setblock ~167 ~134 ~113 oak_wood
setblock ~167 ~134 ~115 oak_leaves[persistent=null]
setblock ~167 ~135 ~106 oak_leaves[persistent=null]
setblock ~167 ~135 ~107 oak_leaves[persistent=null]
setblock ~167 ~135 ~108 jungle_leaves[persistent=null]
setblock ~167 ~135 ~109 oak_leaves[persistent=null]
setblock ~167 ~135 ~110 oak_leaves[persistent=null]
setblock ~167 ~135 ~112 oak_leaves[persistent=null]
setblock ~167 ~135 ~113 oak_leaves[persistent=null]
setblock ~167 ~135 ~115 oak_leaves[persistent=null]
setblock ~167 ~136 ~106 oak_leaves[persistent=null]
setblock ~167 ~136 ~107 jungle_leaves[persistent=null]
setblock ~167 ~136 ~108 oak_leaves[persistent=null]
setblock ~167 ~136 ~109 jungle_leaves[persistent=null]
setblock ~167 ~136 ~110 oak_leaves[persistent=null]
setblock ~167 ~136 ~112 oak_leaves[persistent=null]
setblock ~167 ~136 ~113 oak_leaves[persistent=null]
setblock ~167 ~136 ~114 oak_leaves[persistent=null]
setblock ~167 ~136 ~115 oak_leaves[persistent=null]
setblock ~167 ~136 ~116 jungle_leaves[persistent=null]
setblock ~167 ~137 ~107 oak_leaves[persistent=null]
setblock ~167 ~137 ~108 oak_leaves[persistent=null]
setblock ~167 ~137 ~109 oak_leaves[persistent=null]
setblock ~167 ~137 ~111 oak_leaves[persistent=null]
setblock ~167 ~137 ~112 oak_leaves[persistent=null]
setblock ~167 ~137 ~113 jungle_leaves[persistent=null]
setblock ~167 ~137 ~114 oak_leaves[persistent=null]
setblock ~167 ~137 ~115 oak_leaves[persistent=null]
setblock ~167 ~137 ~116 oak_leaves[persistent=null]
setblock ~168 ~100 ~97 dirt
setblock ~168 ~101 ~96 dirt
setblock ~168 ~101 ~97 dirt
setblock ~168 ~101 ~98 dirt
setblock ~168 ~102 ~95 dirt
setblock ~168 ~102 ~96 dirt
setblock ~168 ~102 ~97 dirt
setblock ~168 ~102 ~98 dirt
setblock ~168 ~102 ~99 dirt
setblock ~168 ~103 ~95 dirt
setblock ~168 ~103 ~96 dirt
setblock ~168 ~103 ~97 dirt
setblock ~168 ~103 ~98 dirt
setblock ~168 ~103 ~99 dirt
setblock ~168 ~103 ~100 dirt
setblock ~168 ~103 ~101 dirt
setblock ~168 ~104 ~94 dirt
setblock ~168 ~104 ~95 dirt
setblock ~168 ~104 ~96 dirt
setblock ~168 ~104 ~97 dirt
setblock ~168 ~104 ~98 dirt
setblock ~168 ~104 ~99 dirt
setblock ~168 ~104 ~100 dirt
setblock ~168 ~104 ~101 dirt
setblock ~168 ~104 ~102 dirt
setblock ~168 ~105 ~93 dirt
setblock ~168 ~105 ~94 dirt
setblock ~168 ~105 ~95 dirt
setblock ~168 ~105 ~96 dirt
setblock ~168 ~105 ~97 dirt
setblock ~168 ~105 ~98 dirt
setblock ~168 ~105 ~99 dirt
setblock ~168 ~105 ~100 dirt
setblock ~168 ~105 ~101 dirt
setblock ~168 ~105 ~102 dirt
setblock ~168 ~105 ~103 dirt
setblock ~168 ~106 ~93 dirt
setblock ~168 ~106 ~94 dirt
setblock ~168 ~106 ~95 dirt
setblock ~168 ~106 ~96 dirt
setblock ~168 ~106 ~97 dirt
setblock ~168 ~106 ~98 dirt
setblock ~168 ~106 ~99 dirt
setblock ~168 ~106 ~100 dirt
setblock ~168 ~106 ~101 dirt
setblock ~168 ~106 ~102 dirt
setblock ~168 ~106 ~103 dirt
setblock ~168 ~106 ~104 dirt
setblock ~168 ~107 ~92 dirt
setblock ~168 ~107 ~93 dirt
setblock ~168 ~107 ~94 dirt
setblock ~168 ~107 ~95 dirt
setblock ~168 ~107 ~96 dirt
setblock ~168 ~107 ~97 dirt
setblock ~168 ~107 ~98 dirt
setblock ~168 ~107 ~99 dirt
setblock ~168 ~107 ~100 dirt
setblock ~168 ~107 ~101 dirt
setblock ~168 ~107 ~102 dirt
setblock ~168 ~107 ~103 dirt
setblock ~168 ~107 ~104 dirt
setblock ~168 ~108 ~90 dirt
setblock ~168 ~108 ~91 dirt
setblock ~168 ~108 ~92 dirt
setblock ~168 ~108 ~93 dirt
setblock ~168 ~108 ~94 dirt
setblock ~168 ~108 ~95 dirt
setblock ~168 ~108 ~96 dirt
setblock ~168 ~108 ~97 dirt
setblock ~168 ~108 ~98 dirt
setblock ~168 ~108 ~99 dirt
setblock ~168 ~108 ~100 dirt
setblock ~168 ~108 ~101 dirt
setblock ~168 ~108 ~102 dirt
setblock ~168 ~108 ~103 dirt
setblock ~168 ~108 ~104 dirt
setblock ~168 ~109 ~90 dirt
setblock ~168 ~109 ~91 dirt
setblock ~168 ~109 ~92 dirt
setblock ~168 ~109 ~93 dirt
setblock ~168 ~109 ~94 dirt
setblock ~168 ~109 ~95 dirt
setblock ~168 ~109 ~96 dirt
setblock ~168 ~109 ~97 dirt
setblock ~168 ~109 ~98 dirt
setblock ~168 ~109 ~99 dirt
setblock ~168 ~109 ~100 dirt
setblock ~168 ~109 ~101 dirt
setblock ~168 ~109 ~102 dirt
setblock ~168 ~109 ~103 dirt
setblock ~168 ~109 ~104 dirt
setblock ~168 ~110 ~87 dirt
setblock ~168 ~110 ~88 dirt
setblock ~168 ~110 ~89 dirt
setblock ~168 ~110 ~90 dirt
setblock ~168 ~110 ~91 dirt
setblock ~168 ~110 ~92 dirt
setblock ~168 ~110 ~93 dirt
setblock ~168 ~110 ~94 dirt
setblock ~168 ~110 ~95 dirt
setblock ~168 ~110 ~96 dirt
setblock ~168 ~110 ~97 dirt
setblock ~168 ~110 ~98 dirt
setblock ~168 ~110 ~99 dirt
setblock ~168 ~110 ~100 dirt
setblock ~168 ~110 ~101 dirt
setblock ~168 ~110 ~102 dirt
setblock ~168 ~110 ~103 dirt
setblock ~168 ~110 ~104 dirt
setblock ~168 ~110 ~105 dirt
setblock ~168 ~111 ~86 dirt
setblock ~168 ~111 ~87 dirt
setblock ~168 ~111 ~88 dirt
setblock ~168 ~111 ~89 dirt
setblock ~168 ~111 ~90 dirt
setblock ~168 ~111 ~91 dirt
setblock ~168 ~111 ~92 dirt
setblock ~168 ~111 ~93 dirt
setblock ~168 ~111 ~94 dirt
setblock ~168 ~111 ~95 dirt
setblock ~168 ~111 ~96 dirt
setblock ~168 ~111 ~97 dirt
setblock ~168 ~111 ~98 dirt
setblock ~168 ~111 ~99 dirt
setblock ~168 ~111 ~100 dirt
setblock ~168 ~111 ~101 dirt
setblock ~168 ~111 ~102 dirt
setblock ~168 ~111 ~103 dirt
setblock ~168 ~111 ~104 dirt
setblock ~168 ~111 ~105 dirt
setblock ~168 ~111 ~106 dirt
setblock ~168 ~112 ~85 dirt
setblock ~168 ~112 ~86 dirt
setblock ~168 ~112 ~87 dirt
setblock ~168 ~112 ~88 dirt
setblock ~168 ~112 ~89 dirt
setblock ~168 ~112 ~90 dirt
setblock ~168 ~112 ~91 dirt
setblock ~168 ~112 ~92 dirt
setblock ~168 ~112 ~93 dirt
setblock ~168 ~112 ~94 dirt
setblock ~168 ~112 ~95 dirt
setblock ~168 ~112 ~96 dirt
setblock ~168 ~112 ~97 dirt
setblock ~168 ~112 ~98 dirt
setblock ~168 ~112 ~99 dirt
setblock ~168 ~112 ~100 dirt
setblock ~168 ~112 ~101 dirt
setblock ~168 ~112 ~102 dirt
setblock ~168 ~112 ~103 dirt
setblock ~168 ~112 ~104 dirt
setblock ~168 ~112 ~105 dirt
setblock ~168 ~112 ~106 dirt
setblock ~168 ~112 ~107 dirt
setblock ~168 ~113 ~85 dirt
setblock ~168 ~113 ~86 dirt
setblock ~168 ~113 ~87 dirt
setblock ~168 ~113 ~88 dirt
setblock ~168 ~113 ~89 dirt
setblock ~168 ~113 ~90 dirt
setblock ~168 ~113 ~91 dirt
setblock ~168 ~113 ~92 dirt
setblock ~168 ~113 ~93 dirt
setblock ~168 ~113 ~94 dirt
setblock ~168 ~113 ~95 dirt
setblock ~168 ~113 ~96 dirt
setblock ~168 ~113 ~97 dirt
setblock ~168 ~113 ~98 dirt
setblock ~168 ~113 ~99 dirt
setblock ~168 ~113 ~100 dirt
setblock ~168 ~113 ~101 dirt
setblock ~168 ~113 ~102 dirt
setblock ~168 ~113 ~103 dirt
setblock ~168 ~113 ~104 dirt
setblock ~168 ~113 ~105 dirt
setblock ~168 ~113 ~106 dirt
setblock ~168 ~113 ~107 dirt
setblock ~168 ~113 ~108 dirt
setblock ~168 ~114 ~84 dirt
setblock ~168 ~114 ~85 dirt
setblock ~168 ~114 ~86 dirt
setblock ~168 ~114 ~87 dirt
setblock ~168 ~114 ~88 dirt
setblock ~168 ~114 ~89 dirt
setblock ~168 ~114 ~90 dirt
setblock ~168 ~114 ~91 dirt
setblock ~168 ~114 ~92 dirt
setblock ~168 ~114 ~93 dirt
setblock ~168 ~114 ~94 dirt
setblock ~168 ~114 ~95 dirt
setblock ~168 ~114 ~96 dirt
setblock ~168 ~114 ~97 dirt
setblock ~168 ~114 ~98 dirt
setblock ~168 ~114 ~99 dirt
setblock ~168 ~114 ~100 dirt
setblock ~168 ~114 ~101 dirt
setblock ~168 ~114 ~102 dirt
setblock ~168 ~114 ~103 dirt
setblock ~168 ~114 ~104 dirt
setblock ~168 ~114 ~105 dirt
setblock ~168 ~114 ~106 dirt
setblock ~168 ~114 ~107 dirt
setblock ~168 ~114 ~108 dirt
setblock ~168 ~115 ~83 dirt
setblock ~168 ~115 ~84 dirt
setblock ~168 ~115 ~85 dirt
setblock ~168 ~115 ~86 dirt
setblock ~168 ~115 ~87 dirt
setblock ~168 ~115 ~88 dirt
setblock ~168 ~115 ~89 dirt
setblock ~168 ~115 ~90 dirt
setblock ~168 ~115 ~91 dirt
setblock ~168 ~115 ~92 dirt
setblock ~168 ~115 ~93 dirt
setblock ~168 ~115 ~94 dirt
setblock ~168 ~115 ~95 dirt
setblock ~168 ~115 ~96 dirt
setblock ~168 ~115 ~97 dirt
setblock ~168 ~115 ~98 dirt
setblock ~168 ~115 ~99 dirt
setblock ~168 ~115 ~100 dirt
setblock ~168 ~115 ~101 dirt
setblock ~168 ~115 ~102 dirt
setblock ~168 ~115 ~103 dirt
setblock ~168 ~115 ~104 dirt
setblock ~168 ~115 ~105 dirt
setblock ~168 ~115 ~106 dirt
setblock ~168 ~115 ~107 dirt
setblock ~168 ~115 ~108 dirt
setblock ~168 ~116 ~83 dirt
setblock ~168 ~116 ~84 dirt
setblock ~168 ~116 ~85 dirt
setblock ~168 ~116 ~86 dirt
setblock ~168 ~116 ~87 dirt
setblock ~168 ~116 ~88 dirt
setblock ~168 ~116 ~89 dirt
setblock ~168 ~116 ~90 dirt
setblock ~168 ~116 ~91 dirt
setblock ~168 ~116 ~92 dirt
setblock ~168 ~116 ~93 dirt
setblock ~168 ~116 ~94 dirt
setblock ~168 ~116 ~95 dirt
setblock ~168 ~116 ~96 dirt
setblock ~168 ~116 ~97 dirt
setblock ~168 ~116 ~98 dirt
setblock ~168 ~116 ~99 dirt
setblock ~168 ~116 ~100 dirt
setblock ~168 ~116 ~101 dirt
setblock ~168 ~116 ~102 dirt
setblock ~168 ~116 ~103 dirt
setblock ~168 ~116 ~104 dirt
setblock ~168 ~116 ~105 dirt
setblock ~168 ~116 ~106 dirt
setblock ~168 ~116 ~107 dirt
setblock ~168 ~116 ~108 dirt
setblock ~168 ~116 ~109 dirt
setblock ~168 ~117 ~82 dirt
setblock ~168 ~117 ~83 dirt
setblock ~168 ~117 ~84 dirt
setblock ~168 ~117 ~85 dirt
setblock ~168 ~117 ~86 dirt
setblock ~168 ~117 ~87 dirt
setblock ~168 ~117 ~88 dirt
setblock ~168 ~117 ~89 dirt
setblock ~168 ~117 ~90 dirt
setblock ~168 ~117 ~91 dirt
setblock ~168 ~117 ~92 dirt
setblock ~168 ~117 ~93 dirt
setblock ~168 ~117 ~94 dirt
setblock ~168 ~117 ~95 dirt
setblock ~168 ~117 ~96 dirt
setblock ~168 ~117 ~97 dirt
setblock ~168 ~117 ~98 dirt
setblock ~168 ~117 ~99 dirt
setblock ~168 ~117 ~100 dirt
setblock ~168 ~117 ~101 dirt
setblock ~168 ~117 ~102 dirt
setblock ~168 ~117 ~103 dirt
setblock ~168 ~117 ~104 dirt
setblock ~168 ~117 ~105 dirt
setblock ~168 ~117 ~106 dirt
setblock ~168 ~117 ~107 dirt
setblock ~168 ~117 ~108 dirt
setblock ~168 ~117 ~109 dirt
setblock ~168 ~117 ~110 dirt
setblock ~168 ~118 ~81 dirt
setblock ~168 ~118 ~82 dirt
setblock ~168 ~118 ~83 dirt
setblock ~168 ~118 ~84 dirt
setblock ~168 ~118 ~85 dirt
setblock ~168 ~118 ~86 dirt
setblock ~168 ~118 ~87 dirt
setblock ~168 ~118 ~88 dirt
setblock ~168 ~118 ~89 dirt
setblock ~168 ~118 ~90 dirt
setblock ~168 ~118 ~91 dirt
setblock ~168 ~118 ~92 dirt
setblock ~168 ~118 ~93 dirt
setblock ~168 ~118 ~94 dirt
setblock ~168 ~118 ~95 dirt
setblock ~168 ~118 ~96 dirt
setblock ~168 ~118 ~97 dirt
setblock ~168 ~118 ~98 dirt
setblock ~168 ~118 ~99 dirt
setblock ~168 ~118 ~100 dirt
setblock ~168 ~118 ~101 dirt
setblock ~168 ~118 ~102 dirt
setblock ~168 ~118 ~103 dirt
setblock ~168 ~118 ~104 dirt
setblock ~168 ~118 ~105 dirt
setblock ~168 ~118 ~106 dirt
setblock ~168 ~118 ~107 dirt
setblock ~168 ~118 ~108 dirt
setblock ~168 ~118 ~109 dirt
setblock ~168 ~118 ~110 dirt
setblock ~168 ~118 ~111 dirt
setblock ~168 ~118 ~116 dirt
setblock ~168 ~118 ~117 dirt
setblock ~168 ~118 ~122 dirt
setblock ~168 ~119 ~81 dirt
setblock ~168 ~119 ~82 dirt
setblock ~168 ~119 ~83 dirt
setblock ~168 ~119 ~84 dirt
setblock ~168 ~119 ~85 dirt
setblock ~168 ~119 ~86 dirt
setblock ~168 ~119 ~87 dirt
setblock ~168 ~119 ~88 dirt
setblock ~168 ~119 ~89 dirt
setblock ~168 ~119 ~90 dirt
setblock ~168 ~119 ~91 dirt
setblock ~168 ~119 ~92 dirt
setblock ~168 ~119 ~93 dirt
setblock ~168 ~119 ~94 dirt
setblock ~168 ~119 ~95 dirt
setblock ~168 ~119 ~96 dirt
setblock ~168 ~119 ~97 dirt
setblock ~168 ~119 ~98 dirt
setblock ~168 ~119 ~99 dirt
setblock ~168 ~119 ~100 dirt
setblock ~168 ~119 ~101 dirt
setblock ~168 ~119 ~102 dirt
setblock ~168 ~119 ~103 dirt
setblock ~168 ~119 ~104 dirt
setblock ~168 ~119 ~105 dirt
setblock ~168 ~119 ~106 dirt
setblock ~168 ~119 ~107 dirt
setblock ~168 ~119 ~108 dirt
setblock ~168 ~119 ~109 dirt
setblock ~168 ~119 ~110 dirt
setblock ~168 ~119 ~111 dirt
setblock ~168 ~119 ~114 dirt
setblock ~168 ~119 ~115 dirt
setblock ~168 ~119 ~116 dirt
setblock ~168 ~119 ~117 dirt
setblock ~168 ~119 ~118 dirt
setblock ~168 ~119 ~121 dirt
setblock ~168 ~119 ~122 dirt
setblock ~168 ~119 ~123 dirt
setblock ~168 ~119 ~126 dirt
setblock ~168 ~119 ~135 dirt
setblock ~168 ~120 ~81 dirt
setblock ~168 ~120 ~82 dirt
setblock ~168 ~120 ~83 dirt
setblock ~168 ~120 ~84 dirt
setblock ~168 ~120 ~85 dirt
setblock ~168 ~120 ~86 dirt
setblock ~168 ~120 ~87 dirt
setblock ~168 ~120 ~88 dirt
setblock ~168 ~120 ~89 dirt
setblock ~168 ~120 ~90 dirt
setblock ~168 ~120 ~91 dirt
setblock ~168 ~120 ~92 dirt
setblock ~168 ~120 ~93 dirt
setblock ~168 ~120 ~94 dirt
setblock ~168 ~120 ~95 dirt
setblock ~168 ~120 ~96 dirt
setblock ~168 ~120 ~97 dirt
setblock ~168 ~120 ~98 dirt
setblock ~168 ~120 ~99 dirt
setblock ~168 ~120 ~100 dirt
setblock ~168 ~120 ~101 dirt
setblock ~168 ~120 ~102 dirt
setblock ~168 ~120 ~103 dirt
setblock ~168 ~120 ~104 dirt
setblock ~168 ~120 ~105 dirt
setblock ~168 ~120 ~106 dirt
setblock ~168 ~120 ~107 dirt
setblock ~168 ~120 ~108 dirt
setblock ~168 ~120 ~109 dirt
setblock ~168 ~120 ~110 dirt
setblock ~168 ~120 ~111 dirt
setblock ~168 ~120 ~112 dirt
setblock ~168 ~120 ~114 dirt
setblock ~168 ~120 ~115 dirt
setblock ~168 ~120 ~116 dirt
setblock ~168 ~120 ~117 dirt
setblock ~168 ~120 ~118 dirt
setblock ~168 ~120 ~120 dirt
setblock ~168 ~120 ~121 dirt
setblock ~168 ~120 ~122 dirt
setblock ~168 ~120 ~123 dirt
setblock ~168 ~120 ~125 dirt
setblock ~168 ~120 ~126 dirt
setblock ~168 ~120 ~127 dirt
setblock ~168 ~120 ~128 dirt
setblock ~168 ~120 ~134 dirt
setblock ~168 ~120 ~135 dirt
setblock ~168 ~121 ~78 dirt
setblock ~168 ~121 ~79 dirt
setblock ~168 ~121 ~80 dirt
setblock ~168 ~121 ~81 dirt
setblock ~168 ~121 ~82 dirt
setblock ~168 ~121 ~83 dirt
setblock ~168 ~121 ~84 dirt
setblock ~168 ~121 ~85 dirt
setblock ~168 ~121 ~86 dirt
setblock ~168 ~121 ~87 dirt
setblock ~168 ~121 ~88 dirt
setblock ~168 ~121 ~89 dirt
setblock ~168 ~121 ~90 dirt
setblock ~168 ~121 ~91 dirt
setblock ~168 ~121 ~92 dirt
setblock ~168 ~121 ~93 dirt
setblock ~168 ~121 ~94 dirt
setblock ~168 ~121 ~95 dirt
setblock ~168 ~121 ~96 dirt
setblock ~168 ~121 ~97 dirt
setblock ~168 ~121 ~98 dirt
setblock ~168 ~121 ~99 dirt
setblock ~168 ~121 ~100 dirt
setblock ~168 ~121 ~101 dirt
setblock ~168 ~121 ~102 dirt
setblock ~168 ~121 ~103 dirt
setblock ~168 ~121 ~104 dirt
setblock ~168 ~121 ~105 dirt
setblock ~168 ~121 ~106 dirt
setblock ~168 ~121 ~107 dirt
setblock ~168 ~121 ~108 dirt
setblock ~168 ~121 ~109 dirt
setblock ~168 ~121 ~110 dirt
setblock ~168 ~121 ~111 dirt
setblock ~168 ~121 ~112 dirt
setblock ~168 ~121 ~113 dirt
setblock ~168 ~121 ~114 dirt
setblock ~168 ~121 ~115 dirt
setblock ~168 ~121 ~116 dirt
setblock ~168 ~121 ~117 dirt
setblock ~168 ~121 ~118 dirt
setblock ~168 ~121 ~119 dirt
setblock ~168 ~121 ~120 dirt
setblock ~168 ~121 ~121 dirt
setblock ~168 ~121 ~122 dirt
setblock ~168 ~121 ~123 dirt
setblock ~168 ~121 ~124 dirt
setblock ~168 ~121 ~125 dirt
setblock ~168 ~121 ~126 dirt
setblock ~168 ~121 ~127 dirt
setblock ~168 ~121 ~128 dirt
setblock ~168 ~121 ~129 dirt
setblock ~168 ~121 ~130 dirt
setblock ~168 ~121 ~132 dirt
setblock ~168 ~121 ~133 dirt
setblock ~168 ~121 ~134 dirt
setblock ~168 ~121 ~135 dirt
setblock ~168 ~121 ~136 dirt
setblock ~168 ~121 ~138 dirt
setblock ~168 ~122 ~78 dirt
setblock ~168 ~122 ~79 dirt
setblock ~168 ~122 ~80 dirt
setblock ~168 ~122 ~81 dirt
setblock ~168 ~122 ~82 dirt
setblock ~168 ~122 ~83 dirt
setblock ~168 ~122 ~84 dirt
setblock ~168 ~122 ~85 dirt
setblock ~168 ~122 ~86 dirt
setblock ~168 ~122 ~87 dirt
setblock ~168 ~122 ~88 dirt
setblock ~168 ~122 ~89 dirt
setblock ~168 ~122 ~90 dirt
setblock ~168 ~122 ~91 dirt
setblock ~168 ~122 ~92 dirt
setblock ~168 ~122 ~93 dirt
setblock ~168 ~122 ~94 dirt
setblock ~168 ~122 ~95 dirt
setblock ~168 ~122 ~96 dirt
setblock ~168 ~122 ~97 dirt
setblock ~168 ~122 ~98 dirt
setblock ~168 ~122 ~99 dirt
setblock ~168 ~122 ~100 dirt
setblock ~168 ~122 ~101 dirt
setblock ~168 ~122 ~102 dirt
setblock ~168 ~122 ~103 dirt
setblock ~168 ~122 ~104 dirt
setblock ~168 ~122 ~105 dirt
setblock ~168 ~122 ~106 dirt
setblock ~168 ~122 ~107 dirt
setblock ~168 ~122 ~108 dirt
setblock ~168 ~122 ~109 dirt
setblock ~168 ~122 ~110 dirt
setblock ~168 ~122 ~111 dirt
setblock ~168 ~122 ~112 dirt
setblock ~168 ~122 ~113 dirt
setblock ~168 ~122 ~114 dirt
setblock ~168 ~122 ~115 dirt
setblock ~168 ~122 ~116 dirt
setblock ~168 ~122 ~117 dirt
setblock ~168 ~122 ~118 dirt
setblock ~168 ~122 ~119 dirt
setblock ~168 ~122 ~120 dirt
setblock ~168 ~122 ~121 dirt
setblock ~168 ~122 ~122 dirt
setblock ~168 ~122 ~123 dirt
setblock ~168 ~122 ~124 dirt
setblock ~168 ~122 ~125 dirt
setblock ~168 ~122 ~126 dirt
setblock ~168 ~122 ~127 dirt
setblock ~168 ~122 ~128 dirt
setblock ~168 ~122 ~129 dirt
setblock ~168 ~122 ~130 dirt
setblock ~168 ~122 ~132 dirt
setblock ~168 ~122 ~133 dirt
setblock ~168 ~122 ~134 dirt
setblock ~168 ~122 ~135 dirt
setblock ~168 ~122 ~136 dirt
setblock ~168 ~122 ~138 dirt
setblock ~168 ~123 ~78 dirt
setblock ~168 ~123 ~79 dirt
setblock ~168 ~123 ~80 dirt
setblock ~168 ~123 ~81 dirt
setblock ~168 ~123 ~82 dirt
setblock ~168 ~123 ~83 dirt
setblock ~168 ~123 ~84 dirt
setblock ~168 ~123 ~85 dirt
setblock ~168 ~123 ~86 dirt
setblock ~168 ~123 ~87 dirt
setblock ~168 ~123 ~88 dirt
setblock ~168 ~123 ~89 dirt
setblock ~168 ~123 ~90 dirt
setblock ~168 ~123 ~91 dirt
setblock ~168 ~123 ~92 dirt
setblock ~168 ~123 ~93 dirt
setblock ~168 ~123 ~94 dirt
setblock ~168 ~123 ~95 dirt
setblock ~168 ~123 ~96 dirt
setblock ~168 ~123 ~97 dirt
setblock ~168 ~123 ~98 dirt
setblock ~168 ~123 ~99 dirt
setblock ~168 ~123 ~100 dirt
setblock ~168 ~123 ~101 dirt
setblock ~168 ~123 ~102 dirt
setblock ~168 ~123 ~103 dirt
setblock ~168 ~123 ~104 dirt
setblock ~168 ~123 ~105 dirt
setblock ~168 ~123 ~106 dirt
setblock ~168 ~123 ~107 dirt
setblock ~168 ~123 ~108 dirt
setblock ~168 ~123 ~109 grass_block
setblock ~168 ~123 ~110 grass_block
setblock ~168 ~123 ~111 grass_block
setblock ~168 ~123 ~112 grass_block
setblock ~168 ~123 ~113 grass_block
setblock ~168 ~123 ~114 grass_block
setblock ~168 ~123 ~115 grass_block
setblock ~168 ~123 ~116 grass_block
setblock ~168 ~123 ~117 grass_block
setblock ~168 ~123 ~118 grass_block
setblock ~168 ~123 ~119 grass_block
setblock ~168 ~123 ~120 grass_block
setblock ~168 ~123 ~121 grass_block
setblock ~168 ~123 ~122 grass_block
setblock ~168 ~123 ~123 grass_block
setblock ~168 ~123 ~124 grass_block
setblock ~168 ~123 ~125 dirt
setblock ~168 ~123 ~126 dirt
setblock ~168 ~123 ~127 dirt
setblock ~168 ~123 ~128 dirt
setblock ~168 ~123 ~129 dirt
setblock ~168 ~123 ~130 dirt
setblock ~168 ~123 ~132 dirt
setblock ~168 ~123 ~133 dirt
setblock ~168 ~123 ~134 dirt
setblock ~168 ~123 ~135 dirt
setblock ~168 ~123 ~136 dirt
setblock ~168 ~123 ~138 dirt
setblock ~168 ~124 ~78 grass_block
setblock ~168 ~124 ~79 grass_block
setblock ~168 ~124 ~80 grass_block
setblock ~168 ~124 ~81 grass_block
setblock ~168 ~124 ~82 grass_block
setblock ~168 ~124 ~83 grass_block
setblock ~168 ~124 ~84 grass_block
setblock ~168 ~124 ~85 grass_block
setblock ~168 ~124 ~86 grass_block
setblock ~168 ~124 ~87 grass_block
setblock ~168 ~124 ~88 grass_block
setblock ~168 ~124 ~89 grass_block
setblock ~168 ~124 ~90 grass_block
setblock ~168 ~124 ~91 grass_block
setblock ~168 ~124 ~92 grass_block
setblock ~168 ~124 ~93 dirt
setblock ~168 ~124 ~94 dirt
setblock ~168 ~124 ~95 dirt
setblock ~168 ~124 ~96 dirt
setblock ~168 ~124 ~97 dirt
setblock ~168 ~124 ~98 dirt
setblock ~168 ~124 ~99 dirt
setblock ~168 ~124 ~100 dirt
setblock ~168 ~124 ~101 dirt
setblock ~168 ~124 ~102 dirt
setblock ~168 ~124 ~103 grass_block
setblock ~168 ~124 ~104 grass_block
setblock ~168 ~124 ~105 grass_block
setblock ~168 ~124 ~106 grass_block
setblock ~168 ~124 ~107 grass_block
setblock ~168 ~124 ~108 grass_block
setblock ~168 ~124 ~110 poppy
setblock ~168 ~124 ~115 short_grass
setblock ~168 ~124 ~121 poppy
setblock ~168 ~124 ~123 short_grass
setblock ~168 ~124 ~124 short_grass
setblock ~168 ~124 ~125 grass_block
setblock ~168 ~124 ~126 grass_block
setblock ~168 ~124 ~127 grass_block
setblock ~168 ~124 ~128 grass_block
setblock ~168 ~124 ~129 grass_block
setblock ~168 ~124 ~130 grass_block
setblock ~168 ~124 ~132 dirt
setblock ~168 ~124 ~133 dirt
setblock ~168 ~124 ~134 dirt
setblock ~168 ~124 ~135 dirt
setblock ~168 ~124 ~136 dirt
setblock ~168 ~124 ~138 dirt
setblock ~168 ~125 ~83 short_grass
setblock ~168 ~125 ~87 fern
setblock ~168 ~125 ~93 grass_block
setblock ~168 ~125 ~94 grass_block
setblock ~168 ~125 ~95 grass_block
setblock ~168 ~125 ~96 grass_block
setblock ~168 ~125 ~97 grass_block
setblock ~168 ~125 ~98 grass_block
setblock ~168 ~125 ~99 grass_block
setblock ~168 ~125 ~100 grass_block
setblock ~168 ~125 ~101 grass_block
setblock ~168 ~125 ~102 grass_block
setblock ~168 ~125 ~104 short_grass
setblock ~168 ~125 ~105 short_grass
setblock ~168 ~125 ~132 grass_block
setblock ~168 ~125 ~133 grass_block
setblock ~168 ~125 ~134 dirt
setblock ~168 ~125 ~135 dirt
setblock ~168 ~125 ~136 dirt
setblock ~168 ~125 ~138 dirt
setblock ~168 ~126 ~95 fern
setblock ~168 ~126 ~100 short_grass
setblock ~168 ~126 ~134 grass_block
setblock ~168 ~126 ~135 grass_block
setblock ~168 ~126 ~136 dirt
setblock ~168 ~126 ~138 dirt
setblock ~168 ~127 ~108 jungle_leaves[persistent=null]
setblock ~168 ~127 ~110 oak_leaves[persistent=null]
setblock ~168 ~127 ~111 jungle_leaves[persistent=null]
setblock ~168 ~127 ~112 oak_leaves[persistent=null]
setblock ~168 ~127 ~136 grass_block
setblock ~168 ~127 ~138 dirt
setblock ~168 ~128 ~110 oak_leaves[persistent=null]
setblock ~168 ~128 ~111 oak_leaves[persistent=null]
setblock ~168 ~128 ~138 grass_block
setblock ~168 ~129 ~109 oak_leaves[persistent=null]
setblock ~168 ~129 ~110 oak_wood
setblock ~168 ~129 ~111 oak_leaves[persistent=null]
setblock ~168 ~129 ~112 oak_leaves[persistent=null]
setblock ~168 ~130 ~107 oak_leaves[persistent=null]
setblock ~168 ~130 ~108 oak_leaves[persistent=null]
setblock ~168 ~130 ~109 oak_leaves[persistent=null]
setblock ~168 ~130 ~112 oak_leaves[persistent=null]
setblock ~168 ~130 ~114 oak_leaves[persistent=null]
setblock ~168 ~130 ~115 oak_leaves[persistent=null]
setblock ~168 ~131 ~107 oak_leaves[persistent=null]
setblock ~168 ~131 ~108 oak_leaves[persistent=null]
setblock ~168 ~131 ~109 oak_leaves[persistent=null]
setblock ~168 ~131 ~110 oak_leaves[persistent=null]
setblock ~168 ~131 ~111 oak_leaves[persistent=null]
setblock ~168 ~131 ~113 oak_leaves[persistent=null]
setblock ~168 ~131 ~115 oak_leaves[persistent=null]
setblock ~168 ~132 ~108 oak_leaves[persistent=null]
setblock ~168 ~132 ~109 oak_leaves[persistent=null]
setblock ~168 ~132 ~110 oak_leaves[persistent=null]
setblock ~168 ~132 ~111 oak_leaves[persistent=null]
setblock ~168 ~132 ~112 jungle_leaves[persistent=null]
setblock ~168 ~132 ~115 oak_leaves[persistent=null]
setblock ~168 ~133 ~107 jungle_leaves[persistent=null]
setblock ~168 ~133 ~108 oak_leaves[persistent=null]
setblock ~168 ~133 ~109 oak_leaves[persistent=null]
setblock ~168 ~133 ~110 oak_wood
setblock ~168 ~133 ~111 oak_wood
setblock ~168 ~133 ~112 oak_wood
setblock ~168 ~133 ~113 oak_leaves[persistent=null]
setblock ~168 ~133 ~114 oak_leaves[persistent=null]
setblock ~168 ~133 ~115 oak_leaves[persistent=null]
setblock ~168 ~134 ~106 oak_leaves[persistent=null]
setblock ~168 ~134 ~107 oak_leaves[persistent=null]
setblock ~168 ~134 ~108 oak_leaves[persistent=null]
setblock ~168 ~134 ~109 oak_leaves[persistent=null]
setblock ~168 ~134 ~112 jungle_leaves[persistent=null]
setblock ~168 ~135 ~106 oak_leaves[persistent=null]
setblock ~168 ~135 ~107 jungle_leaves[persistent=null]
setblock ~168 ~135 ~108 oak_leaves[persistent=null]
setblock ~168 ~135 ~109 oak_leaves[persistent=null]
setblock ~168 ~135 ~110 jungle_leaves[persistent=null]
setblock ~168 ~135 ~111 oak_leaves[persistent=null]
setblock ~168 ~135 ~113 jungle_leaves[persistent=null]
setblock ~168 ~135 ~114 oak_leaves[persistent=null]
setblock ~168 ~136 ~106 oak_leaves[persistent=null]
setblock ~168 ~136 ~107 oak_leaves[persistent=null]
setblock ~168 ~136 ~108 oak_leaves[persistent=null]
setblock ~168 ~136 ~109 oak_log
setblock ~168 ~136 ~110 oak_leaves[persistent=null]
setblock ~168 ~136 ~111 oak_leaves[persistent=null]
setblock ~168 ~136 ~112 jungle_leaves[persistent=null]
setblock ~168 ~136 ~113 oak_leaves[persistent=null]
setblock ~168 ~137 ~106 oak_leaves[persistent=null]
setblock ~168 ~137 ~107 oak_leaves[persistent=null]
setblock ~168 ~137 ~108 oak_leaves[persistent=null]
setblock ~168 ~137 ~109 jungle_leaves[persistent=null]
setblock ~168 ~137 ~110 oak_leaves[persistent=null]
setblock ~168 ~137 ~111 oak_leaves[persistent=null]
setblock ~168 ~137 ~113 oak_leaves[persistent=null]
setblock ~168 ~138 ~107 jungle_leaves[persistent=null]
setblock ~168 ~138 ~108 oak_leaves[persistent=null]
setblock ~168 ~138 ~109 oak_leaves[persistent=null]
setblock ~168 ~138 ~110 oak_leaves[persistent=null]
setblock ~168 ~138 ~111 jungle_leaves[persistent=null]
setblock ~169 ~101 ~97 dirt
setblock ~169 ~102 ~96 dirt
setblock ~169 ~102 ~97 dirt
setblock ~169 ~102 ~98 dirt
setblock ~169 ~103 ~96 dirt
setblock ~169 ~103 ~97 dirt
setblock ~169 ~103 ~98 dirt
setblock ~169 ~104 ~95 dirt
setblock ~169 ~104 ~96 dirt
setblock ~169 ~104 ~97 dirt
setblock ~169 ~104 ~98 dirt
setblock ~169 ~105 ~94 dirt
setblock ~169 ~105 ~95 dirt
setblock ~169 ~105 ~96 dirt
setblock ~169 ~105 ~97 dirt
setblock ~169 ~105 ~98 dirt
setblock ~169 ~105 ~99 dirt
setblock ~169 ~106 ~94 dirt
setblock ~169 ~106 ~95 dirt
setblock ~169 ~106 ~96 dirt
setblock ~169 ~106 ~97 dirt
setblock ~169 ~106 ~98 dirt
setblock ~169 ~106 ~99 dirt
setblock ~169 ~106 ~100 dirt
setblock ~169 ~106 ~101 dirt
setblock ~169 ~106 ~102 dirt
setblock ~169 ~106 ~103 dirt
setblock ~169 ~107 ~93 dirt
setblock ~169 ~107 ~94 dirt
setblock ~169 ~107 ~95 dirt
setblock ~169 ~107 ~96 dirt
setblock ~169 ~107 ~97 dirt
setblock ~169 ~107 ~98 dirt
setblock ~169 ~107 ~99 dirt
setblock ~169 ~107 ~100 dirt
setblock ~169 ~107 ~101 dirt
setblock ~169 ~107 ~102 dirt
setblock ~169 ~107 ~103 dirt
setblock ~169 ~108 ~92 dirt
setblock ~169 ~108 ~93 dirt
setblock ~169 ~108 ~94 dirt
setblock ~169 ~108 ~95 dirt
setblock ~169 ~108 ~96 dirt
setblock ~169 ~108 ~97 dirt
setblock ~169 ~108 ~98 dirt
setblock ~169 ~108 ~99 dirt
setblock ~169 ~108 ~100 dirt
setblock ~169 ~108 ~101 dirt
setblock ~169 ~108 ~102 dirt
setblock ~169 ~108 ~103 dirt
setblock ~169 ~108 ~104 dirt
setblock ~169 ~109 ~91 dirt
setblock ~169 ~109 ~92 dirt
setblock ~169 ~109 ~93 dirt
setblock ~169 ~109 ~94 dirt
setblock ~169 ~109 ~95 dirt
setblock ~169 ~109 ~96 dirt
setblock ~169 ~109 ~97 dirt
setblock ~169 ~109 ~98 dirt
setblock ~169 ~109 ~99 dirt
setblock ~169 ~109 ~100 dirt
setblock ~169 ~109 ~101 dirt
setblock ~169 ~109 ~102 dirt
setblock ~169 ~109 ~103 dirt
setblock ~169 ~109 ~104 dirt
setblock ~169 ~110 ~90 dirt
setblock ~169 ~110 ~91 dirt
setblock ~169 ~110 ~92 dirt
setblock ~169 ~110 ~93 dirt
setblock ~169 ~110 ~94 dirt
setblock ~169 ~110 ~95 dirt
setblock ~169 ~110 ~96 dirt
setblock ~169 ~110 ~97 dirt
setblock ~169 ~110 ~98 dirt
setblock ~169 ~110 ~99 dirt
setblock ~169 ~110 ~100 dirt
setblock ~169 ~110 ~101 dirt
setblock ~169 ~110 ~102 dirt
setblock ~169 ~110 ~103 dirt
setblock ~169 ~110 ~104 dirt
setblock ~169 ~111 ~89 dirt
setblock ~169 ~111 ~90 dirt
setblock ~169 ~111 ~91 dirt
setblock ~169 ~111 ~92 dirt
setblock ~169 ~111 ~93 dirt
setblock ~169 ~111 ~94 dirt
setblock ~169 ~111 ~95 dirt
setblock ~169 ~111 ~96 dirt
setblock ~169 ~111 ~97 dirt
setblock ~169 ~111 ~98 dirt
setblock ~169 ~111 ~99 dirt
setblock ~169 ~111 ~100 dirt
setblock ~169 ~111 ~101 dirt
setblock ~169 ~111 ~102 dirt
setblock ~169 ~111 ~103 dirt
setblock ~169 ~111 ~104 dirt
setblock ~169 ~111 ~105 dirt
setblock ~169 ~112 ~86 dirt
setblock ~169 ~112 ~88 dirt
setblock ~169 ~112 ~89 dirt
setblock ~169 ~112 ~90 dirt
setblock ~169 ~112 ~91 dirt
setblock ~169 ~112 ~92 dirt
setblock ~169 ~112 ~93 dirt
setblock ~169 ~112 ~94 dirt
setblock ~169 ~112 ~95 dirt
setblock ~169 ~112 ~96 dirt
setblock ~169 ~112 ~97 dirt
setblock ~169 ~112 ~98 dirt
setblock ~169 ~112 ~99 dirt
setblock ~169 ~112 ~100 dirt
setblock ~169 ~112 ~101 dirt
setblock ~169 ~112 ~102 dirt
setblock ~169 ~112 ~103 dirt
setblock ~169 ~112 ~104 dirt
setblock ~169 ~112 ~105 dirt
setblock ~169 ~112 ~106 dirt
setblock ~169 ~113 ~86 dirt
setblock ~169 ~113 ~88 dirt
setblock ~169 ~113 ~89 dirt
setblock ~169 ~113 ~90 dirt
setblock ~169 ~113 ~91 dirt
setblock ~169 ~113 ~92 dirt
setblock ~169 ~113 ~93 dirt
setblock ~169 ~113 ~94 dirt
setblock ~169 ~113 ~95 dirt
setblock ~169 ~113 ~96 dirt
setblock ~169 ~113 ~97 dirt
setblock ~169 ~113 ~98 dirt
setblock ~169 ~113 ~99 dirt
setblock ~169 ~113 ~100 dirt
setblock ~169 ~113 ~101 dirt
setblock ~169 ~113 ~102 dirt
setblock ~169 ~113 ~103 dirt
setblock ~169 ~113 ~104 dirt
setblock ~169 ~113 ~105 dirt
setblock ~169 ~113 ~106 dirt
setblock ~169 ~113 ~107 dirt
setblock ~169 ~114 ~86 dirt
setblock ~169 ~114 ~87 dirt
setblock ~169 ~114 ~88 dirt
setblock ~169 ~114 ~89 dirt
setblock ~169 ~114 ~90 dirt
setblock ~169 ~114 ~91 dirt
setblock ~169 ~114 ~92 dirt
setblock ~169 ~114 ~93 dirt
setblock ~169 ~114 ~94 dirt
setblock ~169 ~114 ~95 dirt
setblock ~169 ~114 ~96 dirt
setblock ~169 ~114 ~97 dirt
setblock ~169 ~114 ~98 dirt
setblock ~169 ~114 ~99 dirt
setblock ~169 ~114 ~100 dirt
setblock ~169 ~114 ~101 dirt
setblock ~169 ~114 ~102 dirt
setblock ~169 ~114 ~103 dirt
setblock ~169 ~114 ~104 dirt
setblock ~169 ~114 ~105 dirt
setblock ~169 ~114 ~106 dirt
setblock ~169 ~114 ~107 dirt
setblock ~169 ~115 ~85 dirt
setblock ~169 ~115 ~86 dirt
setblock ~169 ~115 ~87 dirt
setblock ~169 ~115 ~88 dirt
setblock ~169 ~115 ~89 dirt
setblock ~169 ~115 ~90 dirt
setblock ~169 ~115 ~91 dirt
setblock ~169 ~115 ~92 dirt
setblock ~169 ~115 ~93 dirt
setblock ~169 ~115 ~94 dirt
setblock ~169 ~115 ~95 dirt
setblock ~169 ~115 ~96 dirt
setblock ~169 ~115 ~97 dirt
setblock ~169 ~115 ~98 dirt
setblock ~169 ~115 ~99 dirt
setblock ~169 ~115 ~100 dirt
setblock ~169 ~115 ~101 dirt
setblock ~169 ~115 ~102 dirt
setblock ~169 ~115 ~103 dirt
setblock ~169 ~115 ~104 dirt
setblock ~169 ~115 ~105 dirt
setblock ~169 ~115 ~106 dirt
setblock ~169 ~115 ~107 dirt
setblock ~169 ~115 ~108 dirt
setblock ~169 ~116 ~84 dirt
setblock ~169 ~116 ~85 dirt
setblock ~169 ~116 ~86 dirt
setblock ~169 ~116 ~87 dirt
setblock ~169 ~116 ~88 dirt
setblock ~169 ~116 ~89 dirt
setblock ~169 ~116 ~90 dirt
setblock ~169 ~116 ~91 dirt
setblock ~169 ~116 ~92 dirt
setblock ~169 ~116 ~93 dirt
setblock ~169 ~116 ~94 dirt
setblock ~169 ~116 ~95 dirt
setblock ~169 ~116 ~96 dirt
setblock ~169 ~116 ~97 dirt
setblock ~169 ~116 ~98 dirt
setblock ~169 ~116 ~99 dirt
setblock ~169 ~116 ~100 dirt
setblock ~169 ~116 ~101 dirt
setblock ~169 ~116 ~102 dirt
setblock ~169 ~116 ~103 dirt
setblock ~169 ~116 ~104 dirt
setblock ~169 ~116 ~105 dirt
setblock ~169 ~116 ~106 dirt
setblock ~169 ~116 ~107 dirt
setblock ~169 ~116 ~108 dirt
setblock ~169 ~117 ~83 dirt
setblock ~169 ~117 ~84 dirt
setblock ~169 ~117 ~85 dirt
setblock ~169 ~117 ~86 dirt
setblock ~169 ~117 ~87 dirt
setblock ~169 ~117 ~88 dirt
setblock ~169 ~117 ~89 dirt
setblock ~169 ~117 ~90 dirt
setblock ~169 ~117 ~91 dirt
setblock ~169 ~117 ~92 dirt
setblock ~169 ~117 ~93 dirt
setblock ~169 ~117 ~94 dirt
setblock ~169 ~117 ~95 dirt
setblock ~169 ~117 ~96 dirt
setblock ~169 ~117 ~97 dirt
setblock ~169 ~117 ~98 dirt
setblock ~169 ~117 ~99 dirt
setblock ~169 ~117 ~100 dirt
setblock ~169 ~117 ~101 dirt
setblock ~169 ~117 ~102 dirt
setblock ~169 ~117 ~103 dirt
setblock ~169 ~117 ~104 dirt
setblock ~169 ~117 ~105 dirt
setblock ~169 ~117 ~106 dirt
setblock ~169 ~117 ~107 dirt
setblock ~169 ~117 ~108 dirt
setblock ~169 ~117 ~109 dirt
setblock ~169 ~118 ~82 dirt
setblock ~169 ~118 ~83 dirt
setblock ~169 ~118 ~84 dirt
setblock ~169 ~118 ~85 dirt
setblock ~169 ~118 ~86 dirt
setblock ~169 ~118 ~87 dirt
setblock ~169 ~118 ~88 dirt
setblock ~169 ~118 ~89 dirt
setblock ~169 ~118 ~90 dirt
setblock ~169 ~118 ~91 dirt
setblock ~169 ~118 ~92 dirt
setblock ~169 ~118 ~93 dirt
setblock ~169 ~118 ~94 dirt
setblock ~169 ~118 ~95 dirt
setblock ~169 ~118 ~96 dirt
setblock ~169 ~118 ~97 dirt
setblock ~169 ~118 ~98 dirt
setblock ~169 ~118 ~99 dirt
setblock ~169 ~118 ~100 dirt
setblock ~169 ~118 ~101 dirt
setblock ~169 ~118 ~102 dirt
setblock ~169 ~118 ~103 dirt
setblock ~169 ~118 ~104 dirt
setblock ~169 ~118 ~105 dirt
setblock ~169 ~118 ~106 dirt
setblock ~169 ~118 ~107 dirt
setblock ~169 ~118 ~108 dirt
setblock ~169 ~118 ~109 dirt
