setblock ~31 ~123 ~76 dirt
setblock ~31 ~123 ~77 dirt
setblock ~31 ~123 ~102 dirt
setblock ~31 ~123 ~103 dirt
setblock ~31 ~123 ~104 dirt
setblock ~31 ~123 ~105 dirt
setblock ~31 ~123 ~106 dirt
setblock ~31 ~123 ~107 dirt
setblock ~31 ~123 ~108 dirt
setblock ~31 ~123 ~109 dirt
setblock ~31 ~123 ~110 dirt
setblock ~31 ~123 ~111 dirt
setblock ~31 ~123 ~112 dirt
setblock ~31 ~123 ~113 dirt
setblock ~31 ~123 ~114 dirt
setblock ~31 ~123 ~116 dirt
setblock ~31 ~123 ~117 dirt
setblock ~31 ~123 ~118 dirt
setblock ~31 ~123 ~119 dirt
setblock ~31 ~123 ~120 dirt
setblock ~31 ~123 ~121 dirt
setblock ~31 ~123 ~122 dirt
setblock ~31 ~123 ~123 dirt
setblock ~31 ~123 ~124 dirt
setblock ~31 ~123 ~125 dirt
setblock ~31 ~123 ~126 dirt
setblock ~31 ~123 ~127 dirt
setblock ~31 ~123 ~128 dirt
setblock ~31 ~123 ~129 dirt
setblock ~31 ~123 ~130 dirt
setblock ~31 ~123 ~131 dirt
setblock ~31 ~123 ~132 dirt
setblock ~31 ~123 ~133 dirt
setblock ~31 ~123 ~136 dirt
setblock ~31 ~123 ~137 dirt
setblock ~31 ~123 ~138 dirt
setblock ~31 ~123 ~139 dirt
setblock ~31 ~123 ~140 dirt
setblock ~31 ~123 ~141 dirt
setblock ~31 ~123 ~142 dirt
setblock ~31 ~123 ~152 dirt
setblock ~31 ~123 ~153 dirt
setblock ~31 ~124 ~57 dirt
setblock ~31 ~124 ~58 dirt
setblock ~31 ~124 ~59 dirt
setblock ~31 ~124 ~60 dirt
setblock ~31 ~124 ~61 dirt
setblock ~31 ~124 ~62 dirt
setblock ~31 ~124 ~63 dirt
setblock ~31 ~124 ~64 dirt
setblock ~31 ~124 ~65 dirt
setblock ~31 ~124 ~66 dirt
setblock ~31 ~124 ~67 dirt
setblock ~31 ~124 ~68 dirt
setblock ~31 ~124 ~69 dirt
setblock ~31 ~124 ~70 dirt
setblock ~31 ~124 ~71 dirt
setblock ~31 ~124 ~72 dirt
setblock ~31 ~124 ~73 dirt
setblock ~31 ~124 ~74 dirt
setblock ~31 ~124 ~75 dirt
setblock ~31 ~124 ~76 dirt
setblock ~31 ~124 ~77 grass_block
setblock ~31 ~124 ~102 dirt
setblock ~31 ~124 ~103 dirt
setblock ~31 ~124 ~104 dirt
setblock ~31 ~124 ~105 dirt
setblock ~31 ~124 ~106 dirt
setblock ~31 ~124 ~107 dirt
setblock ~31 ~124 ~108 dirt
setblock ~31 ~124 ~109 dirt
setblock ~31 ~124 ~110 dirt
setblock ~31 ~124 ~111 dirt
setblock ~31 ~124 ~112 dirt
setblock ~31 ~124 ~113 dirt
setblock ~31 ~124 ~114 dirt
setblock ~31 ~124 ~116 dirt
setblock ~31 ~124 ~117 dirt
setblock ~31 ~124 ~118 dirt
setblock ~31 ~124 ~119 dirt
setblock ~31 ~124 ~120 dirt
setblock ~31 ~124 ~121 dirt
setblock ~31 ~124 ~122 dirt
setblock ~31 ~124 ~123 dirt
setblock ~31 ~124 ~124 dirt
setblock ~31 ~124 ~125 dirt
setblock ~31 ~124 ~126 dirt
setblock ~31 ~124 ~127 dirt
setblock ~31 ~124 ~128 dirt
setblock ~31 ~124 ~129 dirt
setblock ~31 ~124 ~130 dirt
setblock ~31 ~124 ~131 dirt
setblock ~31 ~124 ~132 dirt
setblock ~31 ~124 ~133 dirt
setblock ~31 ~124 ~136 dirt
setblock ~31 ~124 ~137 dirt
setblock ~31 ~124 ~138 dirt
setblock ~31 ~124 ~139 dirt
setblock ~31 ~124 ~140 dirt
setblock ~31 ~124 ~141 dirt
setblock ~31 ~124 ~142 dirt
setblock ~31 ~124 ~152 dirt
setblock ~31 ~124 ~153 dirt
setblock ~31 ~125 ~57 dirt
setblock ~31 ~125 ~58 dirt
setblock ~31 ~125 ~59 dirt
setblock ~31 ~125 ~60 dirt
setblock ~31 ~125 ~61 dirt
setblock ~31 ~125 ~62 dirt
setblock ~31 ~125 ~63 dirt
setblock ~31 ~125 ~64 dirt
setblock ~31 ~125 ~65 dirt
setblock ~31 ~125 ~66 dirt
setblock ~31 ~125 ~67 dirt
setblock ~31 ~125 ~68 dirt
setblock ~31 ~125 ~69 dirt
setblock ~31 ~125 ~70 dirt
setblock ~31 ~125 ~71 dirt
setblock ~31 ~125 ~72 dirt
setblock ~31 ~125 ~73 dirt
setblock ~31 ~125 ~74 dirt
setblock ~31 ~125 ~75 grass_block
setblock ~31 ~125 ~76 grass_block
setblock ~31 ~125 ~102 grass_block
setblock ~31 ~125 ~103 dirt
setblock ~31 ~125 ~104 dirt
setblock ~31 ~125 ~105 dirt
setblock ~31 ~125 ~106 dirt
setblock ~31 ~125 ~107 dirt
setblock ~31 ~125 ~108 dirt
setblock ~31 ~125 ~109 dirt
setblock ~31 ~125 ~110 dirt
setblock ~31 ~125 ~111 dirt
setblock ~31 ~125 ~112 dirt
setblock ~31 ~125 ~113 dirt
setblock ~31 ~125 ~114 dirt
setblock ~31 ~125 ~116 dirt
setblock ~31 ~125 ~117 dirt
setblock ~31 ~125 ~118 dirt
setblock ~31 ~125 ~119 grass_block
setblock ~31 ~125 ~120 grass_block
setblock ~31 ~125 ~121 grass_block
setblock ~31 ~125 ~122 grass_block
setblock ~31 ~125 ~123 dirt
setblock ~31 ~125 ~124 dirt
setblock ~31 ~125 ~125 dirt
setblock ~31 ~125 ~126 dirt
setblock ~31 ~125 ~127 dirt
setblock ~31 ~125 ~128 dirt
setblock ~31 ~125 ~129 dirt
setblock ~31 ~125 ~130 dirt
setblock ~31 ~125 ~131 dirt
setblock ~31 ~125 ~132 dirt
setblock ~31 ~125 ~133 dirt
setblock ~31 ~125 ~136 dirt
setblock ~31 ~125 ~137 dirt
setblock ~31 ~125 ~138 dirt
setblock ~31 ~125 ~139 dirt
setblock ~31 ~125 ~140 dirt
setblock ~31 ~125 ~141 dirt
setblock ~31 ~125 ~142 dirt
setblock ~31 ~125 ~152 grass_block
setblock ~31 ~125 ~153 grass_block
setblock ~31 ~126 ~57 grass_block
setblock ~31 ~126 ~58 grass_block
setblock ~31 ~126 ~59 grass_block
setblock ~31 ~126 ~60 grass_block
setblock ~31 ~126 ~61 dirt
setblock ~31 ~126 ~62 dirt
setblock ~31 ~126 ~63 dirt
setblock ~31 ~126 ~64 dirt
setblock ~31 ~126 ~65 dirt
setblock ~31 ~126 ~66 dirt
setblock ~31 ~126 ~67 dirt
setblock ~31 ~126 ~68 dirt
setblock ~31 ~126 ~69 dirt
setblock ~31 ~126 ~70 dirt
setblock ~31 ~126 ~71 dirt
setblock ~31 ~126 ~72 grass_block
setblock ~31 ~126 ~73 grass_block
setblock ~31 ~126 ~74 grass_block
setblock ~31 ~126 ~75 short_grass
setblock ~31 ~126 ~76 short_grass
setblock ~31 ~126 ~103 grass_block
setblock ~31 ~126 ~104 grass_block
setblock ~31 ~126 ~105 grass_block
setblock ~31 ~126 ~106 grass_block
setblock ~31 ~126 ~107 grass_block
setblock ~31 ~126 ~108 dirt
setblock ~31 ~126 ~109 dirt
setblock ~31 ~126 ~110 dirt
setblock ~31 ~126 ~111 dirt
setblock ~31 ~126 ~112 dirt
setblock ~31 ~126 ~113 dirt
setblock ~31 ~126 ~114 grass_block
setblock ~31 ~126 ~116 grass_block
setblock ~31 ~126 ~117 grass_block
setblock ~31 ~126 ~118 grass_block
setblock ~31 ~126 ~119 short_grass
setblock ~31 ~126 ~121 short_grass
setblock ~31 ~126 ~123 grass_block
setblock ~31 ~126 ~124 grass_block
setblock ~31 ~126 ~125 grass_block
setblock ~31 ~126 ~126 grass_block
setblock ~31 ~126 ~127 grass_block
setblock ~31 ~126 ~128 grass_block
setblock ~31 ~126 ~129 grass_block
setblock ~31 ~126 ~130 grass_block
setblock ~31 ~126 ~131 grass_block
setblock ~31 ~126 ~132 grass_block
setblock ~31 ~126 ~133 dirt
setblock ~31 ~126 ~136 dirt
setblock ~31 ~126 ~137 dirt
setblock ~31 ~126 ~138 dirt
setblock ~31 ~126 ~139 dirt
setblock ~31 ~126 ~140 grass_block
setblock ~31 ~126 ~141 grass_block
setblock ~31 ~126 ~142 grass_block
setblock ~31 ~126 ~152 poppy
setblock ~31 ~126 ~153 short_grass
setblock ~31 ~127 ~61 grass_block
setblock ~31 ~127 ~62 grass_block
setblock ~31 ~127 ~63 grass_block
setblock ~31 ~127 ~64 grass_block
setblock ~31 ~127 ~65 grass_block
setblock ~31 ~127 ~66 grass_block
setblock ~31 ~127 ~67 grass_block
setblock ~31 ~127 ~68 grass_block
setblock ~31 ~127 ~69 grass_block
setblock ~31 ~127 ~70 grass_block
setblock ~31 ~127 ~71 grass_block
setblock ~31 ~127 ~74 short_grass
setblock ~31 ~127 ~106 short_grass
setblock ~31 ~127 ~107 short_grass
setblock ~31 ~127 ~108 grass_block
setblock ~31 ~127 ~109 grass_block
setblock ~31 ~127 ~110 grass_block
setblock ~31 ~127 ~111 grass_block
setblock ~31 ~127 ~112 grass_block
setblock ~31 ~127 ~113 grass_block
setblock ~31 ~127 ~125 short_grass
setblock ~31 ~127 ~129 short_grass
setblock ~31 ~127 ~131 short_grass
setblock ~31 ~127 ~132 short_grass
setblock ~31 ~127 ~133 grass_block
setblock ~31 ~127 ~136 grass_block
setblock ~31 ~127 ~137 grass_block
setblock ~31 ~127 ~138 grass_block
setblock ~31 ~127 ~139 grass_block
setblock ~31 ~128 ~67 short_grass
setblock ~31 ~128 ~70 short_grass
setblock ~31 ~128 ~109 short_grass
setblock ~31 ~128 ~110 short_grass
setblock ~31 ~128 ~133 short_grass
setblock ~31 ~128 ~138 poppy
setblock ~31 ~128 ~139 short_grass
setblock ~32 ~110 ~108 dirt
setblock ~32 ~111 ~107 dirt
setblock ~32 ~111 ~108 dirt
setblock ~32 ~112 ~106 dirt
setblock ~32 ~112 ~107 dirt
setblock ~32 ~112 ~108 dirt
setblock ~32 ~112 ~109 dirt
setblock ~32 ~113 ~105 dirt
setblock ~32 ~113 ~106 dirt
setblock ~32 ~113 ~107 dirt
setblock ~32 ~113 ~108 dirt
setblock ~32 ~113 ~109 dirt
setblock ~32 ~113 ~110 dirt
setblock ~32 ~113 ~123 dirt
setblock ~32 ~113 ~128 dirt
setblock ~32 ~114 ~60 dirt
setblock ~32 ~114 ~105 dirt
setblock ~32 ~114 ~106 dirt
setblock ~32 ~114 ~107 dirt
setblock ~32 ~114 ~108 dirt
setblock ~32 ~114 ~109 dirt
setblock ~32 ~114 ~110 dirt
setblock ~32 ~114 ~122 dirt
setblock ~32 ~114 ~123 dirt
setblock ~32 ~114 ~124 dirt
setblock ~32 ~114 ~127 dirt
setblock ~32 ~114 ~128 dirt
setblock ~32 ~114 ~129 dirt
setblock ~32 ~115 ~60 dirt
setblock ~32 ~115 ~61 dirt
setblock ~32 ~115 ~105 dirt
setblock ~32 ~115 ~106 dirt
setblock ~32 ~115 ~107 dirt
setblock ~32 ~115 ~108 dirt
setblock ~32 ~115 ~109 dirt
setblock ~32 ~115 ~110 dirt
setblock ~32 ~115 ~122 dirt
setblock ~32 ~115 ~123 dirt
setblock ~32 ~115 ~124 dirt
setblock ~32 ~115 ~125 dirt
setblock ~32 ~115 ~126 dirt
setblock ~32 ~115 ~127 dirt
setblock ~32 ~115 ~128 dirt
setblock ~32 ~115 ~129 dirt
setblock ~32 ~116 ~59 dirt
setblock ~32 ~116 ~60 dirt
setblock ~32 ~116 ~61 dirt
setblock ~32 ~116 ~62 dirt
setblock ~32 ~116 ~105 dirt
setblock ~32 ~116 ~106 dirt
setblock ~32 ~116 ~107 dirt
setblock ~32 ~116 ~108 dirt
setblock ~32 ~116 ~109 dirt
setblock ~32 ~116 ~110 dirt
setblock ~32 ~116 ~111 dirt
setblock ~32 ~116 ~121 dirt
setblock ~32 ~116 ~122 dirt
setblock ~32 ~116 ~123 dirt
setblock ~32 ~116 ~124 dirt
setblock ~32 ~116 ~125 dirt
setblock ~32 ~116 ~126 dirt
setblock ~32 ~116 ~127 dirt
setblock ~32 ~116 ~128 dirt
setblock ~32 ~116 ~129 dirt
setblock ~32 ~116 ~140 dirt
setblock ~32 ~117 ~59 dirt
setblock ~32 ~117 ~60 dirt
setblock ~32 ~117 ~61 dirt
setblock ~32 ~117 ~62 dirt
setblock ~32 ~117 ~63 dirt
setblock ~32 ~117 ~69 dirt
setblock ~32 ~117 ~70 dirt
setblock ~32 ~117 ~104 dirt
setblock ~32 ~117 ~105 dirt
setblock ~32 ~117 ~106 dirt
setblock ~32 ~117 ~107 dirt
setblock ~32 ~117 ~108 dirt
setblock ~32 ~117 ~109 dirt
setblock ~32 ~117 ~110 dirt
setblock ~32 ~117 ~111 dirt
setblock ~32 ~117 ~112 dirt
setblock ~32 ~117 ~121 dirt
setblock ~32 ~117 ~122 dirt
setblock ~32 ~117 ~123 dirt
setblock ~32 ~117 ~124 dirt
setblock ~32 ~117 ~125 dirt
setblock ~32 ~117 ~126 dirt
setblock ~32 ~117 ~127 dirt
setblock ~32 ~117 ~128 dirt
setblock ~32 ~117 ~129 dirt
setblock ~32 ~117 ~130 dirt
setblock ~32 ~117 ~139 dirt
setblock ~32 ~117 ~140 dirt
setblock ~32 ~118 ~58 dirt
setblock ~32 ~118 ~59 dirt
setblock ~32 ~118 ~60 dirt
setblock ~32 ~118 ~61 dirt
setblock ~32 ~118 ~62 dirt
setblock ~32 ~118 ~63 dirt
setblock ~32 ~118 ~64 dirt
setblock ~32 ~118 ~69 dirt
setblock ~32 ~118 ~70 dirt
setblock ~32 ~118 ~71 dirt
setblock ~32 ~118 ~72 dirt
setblock ~32 ~118 ~73 dirt
setblock ~32 ~118 ~74 dirt
setblock ~32 ~118 ~75 dirt
setblock ~32 ~118 ~104 dirt
setblock ~32 ~118 ~105 dirt
setblock ~32 ~118 ~106 dirt
setblock ~32 ~118 ~107 dirt
setblock ~32 ~118 ~108 dirt
setblock ~32 ~118 ~109 dirt
setblock ~32 ~118 ~110 dirt
setblock ~32 ~118 ~111 dirt
setblock ~32 ~118 ~112 dirt
setblock ~32 ~118 ~119 dirt
setblock ~32 ~118 ~120 dirt
setblock ~32 ~118 ~121 dirt
setblock ~32 ~118 ~122 dirt
setblock ~32 ~118 ~123 dirt
setblock ~32 ~118 ~124 dirt
setblock ~32 ~118 ~125 dirt
setblock ~32 ~118 ~126 dirt
setblock ~32 ~118 ~127 dirt
setblock ~32 ~118 ~128 dirt
setblock ~32 ~118 ~129 dirt
setblock ~32 ~118 ~130 dirt
setblock ~32 ~118 ~131 dirt
setblock ~32 ~118 ~138 dirt
setblock ~32 ~118 ~139 dirt
setblock ~32 ~118 ~140 dirt
setblock ~32 ~119 ~58 dirt
setblock ~32 ~119 ~59 dirt
setblock ~32 ~119 ~60 dirt
setblock ~32 ~119 ~61 dirt
setblock ~32 ~119 ~62 dirt
setblock ~32 ~119 ~63 dirt
setblock ~32 ~119 ~64 dirt
setblock ~32 ~119 ~68 dirt
setblock ~32 ~119 ~69 dirt
setblock ~32 ~119 ~70 dirt
setblock ~32 ~119 ~71 dirt
setblock ~32 ~119 ~72 dirt
setblock ~32 ~119 ~73 dirt
setblock ~32 ~119 ~74 dirt
setblock ~32 ~119 ~75 dirt
setblock ~32 ~119 ~77 dirt
setblock ~32 ~119 ~103 dirt
setblock ~32 ~119 ~104 dirt
setblock ~32 ~119 ~105 dirt
setblock ~32 ~119 ~106 dirt
setblock ~32 ~119 ~107 dirt
setblock ~32 ~119 ~108 dirt
setblock ~32 ~119 ~109 dirt
setblock ~32 ~119 ~110 dirt
setblock ~32 ~119 ~111 dirt
setblock ~32 ~119 ~112 dirt
setblock ~32 ~119 ~113 dirt
setblock ~32 ~119 ~117 dirt
setblock ~32 ~119 ~118 dirt
setblock ~32 ~119 ~119 dirt
setblock ~32 ~119 ~120 dirt
setblock ~32 ~119 ~121 dirt
setblock ~32 ~119 ~122 dirt
setblock ~32 ~119 ~123 dirt
setblock ~32 ~119 ~124 dirt
setblock ~32 ~119 ~125 dirt
setblock ~32 ~119 ~126 dirt
setblock ~32 ~119 ~127 dirt
setblock ~32 ~119 ~128 dirt
setblock ~32 ~119 ~129 dirt
setblock ~32 ~119 ~130 dirt
setblock ~32 ~119 ~131 dirt
setblock ~32 ~119 ~132 dirt
setblock ~32 ~119 ~137 dirt
setblock ~32 ~119 ~138 dirt
setblock ~32 ~119 ~139 dirt
setblock ~32 ~119 ~140 dirt
setblock ~32 ~119 ~141 dirt
setblock ~32 ~120 ~52 dirt
setblock ~32 ~120 ~57 dirt
setblock ~32 ~120 ~58 dirt
setblock ~32 ~120 ~59 dirt
setblock ~32 ~120 ~60 dirt
setblock ~32 ~120 ~61 dirt
setblock ~32 ~120 ~62 dirt
setblock ~32 ~120 ~63 dirt
setblock ~32 ~120 ~64 dirt
setblock ~32 ~120 ~65 dirt
setblock ~32 ~120 ~66 dirt
setblock ~32 ~120 ~68 dirt
setblock ~32 ~120 ~69 dirt
setblock ~32 ~120 ~70 dirt
setblock ~32 ~120 ~71 dirt
setblock ~32 ~120 ~72 dirt
setblock ~32 ~120 ~73 dirt
setblock ~32 ~120 ~74 dirt
setblock ~32 ~120 ~75 dirt
setblock ~32 ~120 ~76 dirt
setblock ~32 ~120 ~77 dirt
setblock ~32 ~120 ~78 dirt
setblock ~32 ~120 ~102 dirt
setblock ~32 ~120 ~103 dirt
setblock ~32 ~120 ~104 dirt
setblock ~32 ~120 ~105 dirt
setblock ~32 ~120 ~106 dirt
setblock ~32 ~120 ~107 dirt
setblock ~32 ~120 ~108 dirt
setblock ~32 ~120 ~109 dirt
setblock ~32 ~120 ~110 dirt
setblock ~32 ~120 ~111 dirt
setblock ~32 ~120 ~112 dirt
setblock ~32 ~120 ~113 dirt
setblock ~32 ~120 ~114 dirt
setblock ~32 ~120 ~116 dirt
setblock ~32 ~120 ~117 dirt
setblock ~32 ~120 ~118 dirt
setblock ~32 ~120 ~119 dirt
setblock ~32 ~120 ~120 dirt
setblock ~32 ~120 ~121 dirt
setblock ~32 ~120 ~122 dirt
setblock ~32 ~120 ~123 dirt
setblock ~32 ~120 ~124 dirt
setblock ~32 ~120 ~125 dirt
setblock ~32 ~120 ~126 dirt
setblock ~32 ~120 ~127 dirt
setblock ~32 ~120 ~128 dirt
setblock ~32 ~120 ~129 dirt
setblock ~32 ~120 ~130 dirt
setblock ~32 ~120 ~131 dirt
setblock ~32 ~120 ~132 dirt
setblock ~32 ~120 ~133 dirt
setblock ~32 ~120 ~137 dirt
setblock ~32 ~120 ~138 dirt
setblock ~32 ~120 ~139 dirt
setblock ~32 ~120 ~140 dirt
setblock ~32 ~120 ~141 dirt
setblock ~32 ~121 ~52 dirt
setblock ~32 ~121 ~53 dirt
setblock ~32 ~121 ~57 dirt
setblock ~32 ~121 ~58 dirt
setblock ~32 ~121 ~59 dirt
setblock ~32 ~121 ~60 dirt
setblock ~32 ~121 ~61 dirt
setblock ~32 ~121 ~62 dirt
setblock ~32 ~121 ~63 dirt
setblock ~32 ~121 ~64 dirt
setblock ~32 ~121 ~65 dirt
setblock ~32 ~121 ~66 dirt
setblock ~32 ~121 ~67 dirt
setblock ~32 ~121 ~68 dirt
setblock ~32 ~121 ~69 dirt
setblock ~32 ~121 ~70 dirt
setblock ~32 ~121 ~71 dirt
setblock ~32 ~121 ~72 dirt
setblock ~32 ~121 ~73 dirt
setblock ~32 ~121 ~74 dirt
setblock ~32 ~121 ~75 dirt
setblock ~32 ~121 ~76 dirt
setblock ~32 ~121 ~77 dirt
setblock ~32 ~121 ~78 dirt
setblock ~32 ~121 ~99 dirt
setblock ~32 ~121 ~101 dirt
setblock ~32 ~121 ~102 dirt
setblock ~32 ~121 ~103 dirt
setblock ~32 ~121 ~104 dirt
setblock ~32 ~121 ~105 dirt
setblock ~32 ~121 ~106 dirt
setblock ~32 ~121 ~107 dirt
setblock ~32 ~121 ~108 dirt
setblock ~32 ~121 ~109 dirt
setblock ~32 ~121 ~110 dirt
setblock ~32 ~121 ~111 dirt
setblock ~32 ~121 ~112 dirt
setblock ~32 ~121 ~113 dirt
setblock ~32 ~121 ~114 dirt
setblock ~32 ~121 ~115 dirt
setblock ~32 ~121 ~116 dirt
setblock ~32 ~121 ~117 dirt
setblock ~32 ~121 ~118 dirt
setblock ~32 ~121 ~119 dirt
setblock ~32 ~121 ~120 dirt
setblock ~32 ~121 ~121 dirt
setblock ~32 ~121 ~122 dirt
setblock ~32 ~121 ~123 dirt
setblock ~32 ~121 ~124 dirt
setblock ~32 ~121 ~125 dirt
setblock ~32 ~121 ~126 dirt
setblock ~32 ~121 ~127 dirt
setblock ~32 ~121 ~128 dirt
setblock ~32 ~121 ~129 dirt
setblock ~32 ~121 ~130 dirt
setblock ~32 ~121 ~131 dirt
setblock ~32 ~121 ~132 dirt
setblock ~32 ~121 ~133 dirt
setblock ~32 ~121 ~137 dirt
setblock ~32 ~121 ~138 dirt
setblock ~32 ~121 ~139 dirt
setblock ~32 ~121 ~140 dirt
setblock ~32 ~121 ~141 dirt
setblock ~32 ~121 ~142 dirt
setblock ~32 ~122 ~52 dirt
setblock ~32 ~122 ~53 dirt
setblock ~32 ~122 ~57 dirt
setblock ~32 ~122 ~58 dirt
setblock ~32 ~122 ~59 dirt
setblock ~32 ~122 ~60 dirt
setblock ~32 ~122 ~61 dirt
setblock ~32 ~122 ~62 dirt
setblock ~32 ~122 ~63 dirt
setblock ~32 ~122 ~64 dirt
setblock ~32 ~122 ~65 dirt
setblock ~32 ~122 ~66 dirt
setblock ~32 ~122 ~67 dirt
setblock ~32 ~122 ~68 dirt
setblock ~32 ~122 ~69 dirt
setblock ~32 ~122 ~70 dirt
setblock ~32 ~122 ~71 dirt
setblock ~32 ~122 ~72 dirt
setblock ~32 ~122 ~73 dirt
setblock ~32 ~122 ~74 dirt
setblock ~32 ~122 ~75 dirt
setblock ~32 ~122 ~76 dirt
setblock ~32 ~122 ~77 dirt
setblock ~32 ~122 ~78 dirt
setblock ~32 ~122 ~99 dirt
setblock ~32 ~122 ~101 dirt
setblock ~32 ~122 ~102 dirt
setblock ~32 ~122 ~103 dirt
setblock ~32 ~122 ~104 dirt
setblock ~32 ~122 ~105 dirt
setblock ~32 ~122 ~106 dirt
setblock ~32 ~122 ~107 dirt
setblock ~32 ~122 ~108 dirt
setblock ~32 ~122 ~109 dirt
setblock ~32 ~122 ~110 dirt
setblock ~32 ~122 ~111 dirt
setblock ~32 ~122 ~112 dirt
setblock ~32 ~122 ~113 dirt
setblock ~32 ~122 ~114 dirt
setblock ~32 ~122 ~115 dirt
setblock ~32 ~122 ~116 dirt
setblock ~32 ~122 ~117 dirt
setblock ~32 ~122 ~118 dirt
setblock ~32 ~122 ~119 dirt
setblock ~32 ~122 ~120 dirt
setblock ~32 ~122 ~121 dirt
setblock ~32 ~122 ~122 dirt
setblock ~32 ~122 ~123 dirt
setblock ~32 ~122 ~124 dirt
setblock ~32 ~122 ~125 dirt
setblock ~32 ~122 ~126 dirt
setblock ~32 ~122 ~127 dirt
setblock ~32 ~122 ~128 dirt
setblock ~32 ~122 ~129 dirt
setblock ~32 ~122 ~130 dirt
setblock ~32 ~122 ~131 dirt
setblock ~32 ~122 ~132 dirt
setblock ~32 ~122 ~133 dirt
setblock ~32 ~122 ~137 dirt
setblock ~32 ~122 ~138 dirt
setblock ~32 ~122 ~139 dirt
setblock ~32 ~122 ~140 dirt
setblock ~32 ~122 ~141 dirt
setblock ~32 ~122 ~142 dirt
setblock ~32 ~123 ~52 dirt
setblock ~32 ~123 ~53 dirt
setblock ~32 ~123 ~57 dirt
setblock ~32 ~123 ~58 dirt
setblock ~32 ~123 ~59 dirt
setblock ~32 ~123 ~60 dirt
setblock ~32 ~123 ~61 dirt
setblock ~32 ~123 ~62 dirt
setblock ~32 ~123 ~63 dirt
setblock ~32 ~123 ~64 dirt
setblock ~32 ~123 ~65 dirt
setblock ~32 ~123 ~66 dirt
setblock ~32 ~123 ~67 dirt
setblock ~32 ~123 ~68 dirt
setblock ~32 ~123 ~69 dirt
setblock ~32 ~123 ~70 dirt
setblock ~32 ~123 ~71 dirt
setblock ~32 ~123 ~72 dirt
setblock ~32 ~123 ~73 dirt
setblock ~32 ~123 ~74 dirt
setblock ~32 ~123 ~75 dirt
setblock ~32 ~123 ~76 dirt
setblock ~32 ~123 ~77 dirt
setblock ~32 ~123 ~78 dirt
setblock ~32 ~123 ~99 dirt
setblock ~32 ~123 ~101 dirt
setblock ~32 ~123 ~102 dirt
setblock ~32 ~123 ~103 dirt
setblock ~32 ~123 ~104 dirt
setblock ~32 ~123 ~105 dirt
setblock ~32 ~123 ~106 dirt
setblock ~32 ~123 ~107 dirt
setblock ~32 ~123 ~108 dirt
setblock ~32 ~123 ~109 dirt
setblock ~32 ~123 ~110 dirt
setblock ~32 ~123 ~111 dirt
setblock ~32 ~123 ~112 dirt
setblock ~32 ~123 ~113 dirt
setblock ~32 ~123 ~114 dirt
setblock ~32 ~123 ~115 dirt
setblock ~32 ~123 ~116 dirt
setblock ~32 ~123 ~117 dirt
setblock ~32 ~123 ~118 dirt
setblock ~32 ~123 ~119 dirt
setblock ~32 ~123 ~120 dirt
setblock ~32 ~123 ~121 dirt
setblock ~32 ~123 ~122 dirt
setblock ~32 ~123 ~123 dirt
setblock ~32 ~123 ~124 dirt
setblock ~32 ~123 ~125 dirt
setblock ~32 ~123 ~126 dirt
setblock ~32 ~123 ~127 dirt
setblock ~32 ~123 ~128 dirt
setblock ~32 ~123 ~129 dirt
setblock ~32 ~123 ~130 dirt
setblock ~32 ~123 ~131 dirt
setblock ~32 ~123 ~132 dirt
setblock ~32 ~123 ~133 dirt
setblock ~32 ~123 ~137 dirt
setblock ~32 ~123 ~138 dirt
setblock ~32 ~123 ~139 dirt
setblock ~32 ~123 ~140 dirt
setblock ~32 ~123 ~141 dirt
setblock ~32 ~123 ~142 dirt
setblock ~32 ~124 ~52 dirt
setblock ~32 ~124 ~53 dirt
setblock ~32 ~124 ~57 dirt
setblock ~32 ~124 ~58 dirt
setblock ~32 ~124 ~59 dirt
setblock ~32 ~124 ~60 dirt
setblock ~32 ~124 ~61 dirt
setblock ~32 ~124 ~62 dirt
setblock ~32 ~124 ~63 dirt
setblock ~32 ~124 ~64 dirt
setblock ~32 ~124 ~65 dirt
setblock ~32 ~124 ~66 dirt
setblock ~32 ~124 ~67 dirt
setblock ~32 ~124 ~68 dirt
setblock ~32 ~124 ~69 dirt
setblock ~32 ~124 ~70 dirt
setblock ~32 ~124 ~71 dirt
setblock ~32 ~124 ~72 dirt
setblock ~32 ~124 ~73 dirt
setblock ~32 ~124 ~74 dirt
setblock ~32 ~124 ~75 dirt
setblock ~32 ~124 ~76 dirt
setblock ~32 ~124 ~77 grass_block
setblock ~32 ~124 ~78 grass_block
setblock ~32 ~124 ~99 dirt
setblock ~32 ~124 ~101 dirt
setblock ~32 ~124 ~102 dirt
setblock ~32 ~124 ~103 dirt
setblock ~32 ~124 ~104 dirt
setblock ~32 ~124 ~105 dirt
setblock ~32 ~124 ~106 dirt
setblock ~32 ~124 ~107 dirt
setblock ~32 ~124 ~108 dirt
setblock ~32 ~124 ~109 dirt
setblock ~32 ~124 ~110 dirt
setblock ~32 ~124 ~111 dirt
setblock ~32 ~124 ~112 dirt
setblock ~32 ~124 ~113 dirt
setblock ~32 ~124 ~114 dirt
setblock ~32 ~124 ~115 dirt
setblock ~32 ~124 ~116 dirt
setblock ~32 ~124 ~117 dirt
setblock ~32 ~124 ~118 dirt
setblock ~32 ~124 ~119 dirt
setblock ~32 ~124 ~120 dirt
setblock ~32 ~124 ~121 dirt
setblock ~32 ~124 ~122 dirt
setblock ~32 ~124 ~123 dirt
setblock ~32 ~124 ~124 dirt
setblock ~32 ~124 ~125 dirt
setblock ~32 ~124 ~126 dirt
setblock ~32 ~124 ~127 dirt
setblock ~32 ~124 ~128 dirt
setblock ~32 ~124 ~129 dirt
setblock ~32 ~124 ~130 dirt
setblock ~32 ~124 ~131 dirt
setblock ~32 ~124 ~132 dirt
setblock ~32 ~124 ~133 dirt
setblock ~32 ~124 ~137 dirt
setblock ~32 ~124 ~138 dirt
setblock ~32 ~124 ~139 dirt
setblock ~32 ~124 ~140 dirt
setblock ~32 ~124 ~141 dirt
setblock ~32 ~124 ~142 dirt
setblock ~32 ~125 ~52 dirt
setblock ~32 ~125 ~53 dirt
setblock ~32 ~125 ~57 dirt
setblock ~32 ~125 ~58 dirt
setblock ~32 ~125 ~59 dirt
setblock ~32 ~125 ~60 dirt
setblock ~32 ~125 ~61 dirt
setblock ~32 ~125 ~62 dirt
setblock ~32 ~125 ~63 dirt
setblock ~32 ~125 ~64 dirt
setblock ~32 ~125 ~65 dirt
setblock ~32 ~125 ~66 dirt
setblock ~32 ~125 ~67 dirt
setblock ~32 ~125 ~68 dirt
setblock ~32 ~125 ~69 dirt
setblock ~32 ~125 ~70 dirt
setblock ~32 ~125 ~71 dirt
setblock ~32 ~125 ~72 dirt
setblock ~32 ~125 ~73 dirt
setblock ~32 ~125 ~74 dirt
setblock ~32 ~125 ~75 grass_block
setblock ~32 ~125 ~76 grass_block
setblock ~32 ~125 ~77 short_grass
setblock ~32 ~125 ~78 short_grass
setblock ~32 ~125 ~99 grass_block
setblock ~32 ~125 ~101 grass_block
setblock ~32 ~125 ~102 grass_block
setblock ~32 ~125 ~103 grass_block
setblock ~32 ~125 ~104 dirt
setblock ~32 ~125 ~105 dirt
setblock ~32 ~125 ~106 dirt
setblock ~32 ~125 ~107 dirt
setblock ~32 ~125 ~108 dirt
setblock ~32 ~125 ~109 dirt
setblock ~32 ~125 ~110 dirt
setblock ~32 ~125 ~111 dirt
setblock ~32 ~125 ~112 dirt
setblock ~32 ~125 ~113 dirt
setblock ~32 ~125 ~114 dirt
setblock ~32 ~125 ~115 dirt
setblock ~32 ~125 ~116 dirt
setblock ~32 ~125 ~117 dirt
setblock ~32 ~125 ~118 grass_block
setblock ~32 ~125 ~119 grass_block
setblock ~32 ~125 ~120 grass_block
setblock ~32 ~125 ~121 grass_block
setblock ~32 ~125 ~122 grass_block
setblock ~32 ~125 ~123 dirt
setblock ~32 ~125 ~124 dirt
setblock ~32 ~125 ~125 dirt
setblock ~32 ~125 ~126 dirt
setblock ~32 ~125 ~127 dirt
setblock ~32 ~125 ~128 dirt
setblock ~32 ~125 ~129 dirt
setblock ~32 ~125 ~130 dirt
setblock ~32 ~125 ~131 dirt
setblock ~32 ~125 ~132 dirt
setblock ~32 ~125 ~133 dirt
setblock ~32 ~125 ~137 dirt
setblock ~32 ~125 ~138 dirt
setblock ~32 ~125 ~139 dirt
setblock ~32 ~125 ~140 dirt
setblock ~32 ~125 ~141 dirt
setblock ~32 ~125 ~142 dirt
setblock ~32 ~126 ~52 grass_block
setblock ~32 ~126 ~53 grass_block
setblock ~32 ~126 ~57 grass_block
setblock ~32 ~126 ~58 grass_block
setblock ~32 ~126 ~59 grass_block
setblock ~32 ~126 ~60 grass_block
setblock ~32 ~126 ~61 grass_block
setblock ~32 ~126 ~62 grass_block
setblock ~32 ~126 ~63 grass_block
setblock ~32 ~126 ~64 grass_block
setblock ~32 ~126 ~65 grass_block
setblock ~32 ~126 ~66 dirt
setblock ~32 ~126 ~67 dirt
setblock ~32 ~126 ~68 dirt
setblock ~32 ~126 ~69 dirt
setblock ~32 ~126 ~70 dirt
setblock ~32 ~126 ~71 grass_block
setblock ~32 ~126 ~72 grass_block
setblock ~32 ~126 ~73 grass_block
setblock ~32 ~126 ~74 grass_block
setblock ~32 ~126 ~103 short_grass
setblock ~32 ~126 ~104 grass_block
setblock ~32 ~126 ~105 grass_block
setblock ~32 ~126 ~106 grass_block
setblock ~32 ~126 ~107 grass_block
setblock ~32 ~126 ~108 grass_block
setblock ~32 ~126 ~109 dirt
setblock ~32 ~126 ~110 dirt
setblock ~32 ~126 ~111 dirt
setblock ~32 ~126 ~112 grass_block
setblock ~32 ~126 ~113 grass_block
setblock ~32 ~126 ~114 grass_block
setblock ~32 ~126 ~115 grass_block
setblock ~32 ~126 ~116 grass_block
setblock ~32 ~126 ~117 grass_block
setblock ~32 ~126 ~118 short_grass
setblock ~32 ~126 ~119 short_grass
setblock ~32 ~126 ~123 grass_block
setblock ~32 ~126 ~124 grass_block
setblock ~32 ~126 ~125 grass_block
setblock ~32 ~126 ~126 grass_block
setblock ~32 ~126 ~127 grass_block
setblock ~32 ~126 ~128 grass_block
setblock ~32 ~126 ~129 grass_block
setblock ~32 ~126 ~130 grass_block
setblock ~32 ~126 ~131 grass_block
setblock ~32 ~126 ~132 grass_block
setblock ~32 ~126 ~133 dirt
setblock ~32 ~126 ~137 dirt
setblock ~32 ~126 ~138 dirt
setblock ~32 ~126 ~139 grass_block
setblock ~32 ~126 ~140 grass_block
setblock ~32 ~126 ~141 grass_block
setblock ~32 ~126 ~142 grass_block
setblock ~32 ~127 ~53 short_grass
setblock ~32 ~127 ~58 short_grass
setblock ~32 ~127 ~60 short_grass
setblock ~32 ~127 ~61 short_grass
setblock ~32 ~127 ~66 grass_block
setblock ~32 ~127 ~67 grass_block
setblock ~32 ~127 ~68 grass_block
setblock ~32 ~127 ~69 grass_block
setblock ~32 ~127 ~70 grass_block
setblock ~32 ~127 ~71 short_grass
setblock ~32 ~127 ~104 short_grass
setblock ~32 ~127 ~108 fern
setblock ~32 ~127 ~109 grass_block
setblock ~32 ~127 ~110 grass_block
setblock ~32 ~127 ~111 grass_block
setblock ~32 ~127 ~113 short_grass
setblock ~32 ~127 ~123 short_grass
setblock ~32 ~127 ~125 poppy
setblock ~32 ~127 ~127 short_grass
setblock ~32 ~127 ~128 poppy
setblock ~32 ~127 ~133 grass_block
setblock ~32 ~127 ~137 grass_block
setblock ~32 ~127 ~138 grass_block
setblock ~32 ~128 ~110 fern
setblock ~32 ~128 ~137 short_grass
setblock ~33 ~111 ~123 dirt
setblock ~33 ~112 ~108 dirt
setblock ~33 ~112 ~123 dirt
setblock ~33 ~112 ~124 dirt
setblock ~33 ~112 ~126 dirt
setblock ~33 ~112 ~128 dirt
setblock ~33 ~113 ~106 dirt
setblock ~33 ~113 ~108 dirt
setblock ~33 ~113 ~109 dirt
setblock ~33 ~113 ~122 dirt
setblock ~33 ~113 ~123 dirt
setblock ~33 ~113 ~124 dirt
setblock ~33 ~113 ~125 dirt
setblock ~33 ~113 ~126 dirt
setblock ~33 ~113 ~127 dirt
setblock ~33 ~113 ~128 dirt
setblock ~33 ~113 ~129 dirt
setblock ~33 ~114 ~73 dirt
setblock ~33 ~114 ~106 dirt
setblock ~33 ~114 ~108 dirt
setblock ~33 ~114 ~109 dirt
setblock ~33 ~114 ~121 dirt
setblock ~33 ~114 ~122 dirt
setblock ~33 ~114 ~123 dirt
setblock ~33 ~114 ~124 dirt
setblock ~33 ~114 ~125 dirt
setblock ~33 ~114 ~126 dirt
setblock ~33 ~114 ~127 dirt
setblock ~33 ~114 ~128 dirt
setblock ~33 ~114 ~129 dirt
setblock ~33 ~115 ~73 dirt
setblock ~33 ~115 ~106 dirt
setblock ~33 ~115 ~107 dirt
setblock ~33 ~115 ~108 dirt
setblock ~33 ~115 ~109 dirt
setblock ~33 ~115 ~120 dirt
setblock ~33 ~115 ~121 dirt
setblock ~33 ~115 ~122 dirt
setblock ~33 ~115 ~123 dirt
setblock ~33 ~115 ~124 dirt
setblock ~33 ~115 ~125 dirt
setblock ~33 ~115 ~126 dirt
setblock ~33 ~115 ~127 dirt
setblock ~33 ~115 ~128 dirt
setblock ~33 ~115 ~129 dirt
setblock ~33 ~115 ~130 dirt
setblock ~33 ~116 ~60 dirt
setblock ~33 ~116 ~69 dirt
setblock ~33 ~116 ~70 dirt
setblock ~33 ~116 ~72 dirt
setblock ~33 ~116 ~73 dirt
setblock ~33 ~116 ~74 dirt
setblock ~33 ~116 ~106 dirt
setblock ~33 ~116 ~107 dirt
setblock ~33 ~116 ~108 dirt
setblock ~33 ~116 ~109 dirt
setblock ~33 ~116 ~110 dirt
setblock ~33 ~116 ~118 dirt
setblock ~33 ~116 ~120 dirt
setblock ~33 ~116 ~121 dirt
setblock ~33 ~116 ~122 dirt
setblock ~33 ~116 ~123 dirt
setblock ~33 ~116 ~124 dirt
setblock ~33 ~116 ~125 dirt
setblock ~33 ~116 ~126 dirt
setblock ~33 ~116 ~127 dirt
setblock ~33 ~116 ~128 dirt
setblock ~33 ~116 ~129 dirt
setblock ~33 ~116 ~130 dirt
setblock ~33 ~117 ~60 dirt
setblock ~33 ~117 ~68 dirt
setblock ~33 ~117 ~69 dirt
setblock ~33 ~117 ~70 dirt
setblock ~33 ~117 ~71 dirt
setblock ~33 ~117 ~72 dirt
setblock ~33 ~117 ~73 dirt
setblock ~33 ~117 ~74 dirt
setblock ~33 ~117 ~75 dirt
setblock ~33 ~117 ~105 dirt
setblock ~33 ~117 ~106 dirt
setblock ~33 ~117 ~107 dirt
setblock ~33 ~117 ~108 dirt
setblock ~33 ~117 ~109 dirt
setblock ~33 ~117 ~110 dirt
setblock ~33 ~117 ~111 dirt
setblock ~33 ~117 ~117 dirt
setblock ~33 ~117 ~118 dirt
setblock ~33 ~117 ~119 dirt
setblock ~33 ~117 ~120 dirt
setblock ~33 ~117 ~121 dirt
setblock ~33 ~117 ~122 dirt
setblock ~33 ~117 ~123 dirt
setblock ~33 ~117 ~124 dirt
setblock ~33 ~117 ~125 dirt
setblock ~33 ~117 ~126 dirt
setblock ~33 ~117 ~127 dirt
setblock ~33 ~117 ~128 dirt
setblock ~33 ~117 ~129 dirt
setblock ~33 ~117 ~130 dirt
setblock ~33 ~117 ~131 dirt
setblock ~33 ~118 ~59 dirt
setblock ~33 ~118 ~60 dirt
setblock ~33 ~118 ~61 dirt
setblock ~33 ~118 ~62 dirt
setblock ~33 ~118 ~68 dirt
setblock ~33 ~118 ~69 dirt
setblock ~33 ~118 ~70 dirt
setblock ~33 ~118 ~71 dirt
setblock ~33 ~118 ~72 dirt
setblock ~33 ~118 ~73 dirt
setblock ~33 ~118 ~74 dirt
setblock ~33 ~118 ~75 dirt
setblock ~33 ~118 ~76 dirt
setblock ~33 ~118 ~77 dirt
setblock ~33 ~118 ~104 dirt
setblock ~33 ~118 ~105 dirt
setblock ~33 ~118 ~106 dirt
setblock ~33 ~118 ~107 dirt
setblock ~33 ~118 ~108 dirt
setblock ~33 ~118 ~109 dirt
setblock ~33 ~118 ~110 dirt
setblock ~33 ~118 ~111 dirt
setblock ~33 ~118 ~117 dirt
setblock ~33 ~118 ~118 dirt
setblock ~33 ~118 ~119 dirt
setblock ~33 ~118 ~120 dirt
setblock ~33 ~118 ~121 dirt
setblock ~33 ~118 ~122 dirt
setblock ~33 ~118 ~123 dirt
setblock ~33 ~118 ~124 dirt
setblock ~33 ~118 ~125 dirt
setblock ~33 ~118 ~126 dirt
setblock ~33 ~118 ~127 dirt
setblock ~33 ~118 ~128 dirt
setblock ~33 ~118 ~129 dirt
setblock ~33 ~118 ~130 dirt
setblock ~33 ~118 ~131 dirt
setblock ~33 ~118 ~132 dirt
setblock ~33 ~119 ~52 dirt
setblock ~33 ~119 ~58 dirt
setblock ~33 ~119 ~59 dirt
setblock ~33 ~119 ~60 dirt
setblock ~33 ~119 ~61 dirt
setblock ~33 ~119 ~62 dirt
setblock ~33 ~119 ~63 dirt
setblock ~33 ~119 ~67 dirt
setblock ~33 ~119 ~68 dirt
setblock ~33 ~119 ~69 dirt
setblock ~33 ~119 ~70 dirt
setblock ~33 ~119 ~71 dirt
setblock ~33 ~119 ~72 dirt
setblock ~33 ~119 ~73 dirt
setblock ~33 ~119 ~74 dirt
setblock ~33 ~119 ~75 dirt
setblock ~33 ~119 ~76 dirt
setblock ~33 ~119 ~77 dirt
setblock ~33 ~119 ~78 dirt
setblock ~33 ~119 ~99 dirt
setblock ~33 ~119 ~103 dirt
setblock ~33 ~119 ~104 dirt
setblock ~33 ~119 ~105 dirt
setblock ~33 ~119 ~106 dirt
setblock ~33 ~119 ~107 dirt
setblock ~33 ~119 ~108 dirt
setblock ~33 ~119 ~109 dirt
setblock ~33 ~119 ~110 dirt
setblock ~33 ~119 ~111 dirt
setblock ~33 ~119 ~112 dirt
setblock ~33 ~119 ~116 dirt
setblock ~33 ~119 ~117 dirt
setblock ~33 ~119 ~118 dirt
setblock ~33 ~119 ~119 dirt
setblock ~33 ~119 ~120 dirt
setblock ~33 ~119 ~121 dirt
setblock ~33 ~119 ~122 dirt
setblock ~33 ~119 ~123 dirt
setblock ~33 ~119 ~124 dirt
setblock ~33 ~119 ~125 dirt
setblock ~33 ~119 ~126 dirt
setblock ~33 ~119 ~127 dirt
setblock ~33 ~119 ~128 dirt
setblock ~33 ~119 ~129 dirt
setblock ~33 ~119 ~130 dirt
setblock ~33 ~119 ~131 dirt
setblock ~33 ~119 ~132 dirt
setblock ~33 ~119 ~133 dirt
setblock ~33 ~119 ~140 dirt
setblock ~33 ~120 ~51 dirt
setblock ~33 ~120 ~52 dirt
setblock ~33 ~120 ~53 dirt
setblock ~33 ~120 ~58 dirt
setblock ~33 ~120 ~59 dirt
setblock ~33 ~120 ~60 dirt
setblock ~33 ~120 ~61 dirt
setblock ~33 ~120 ~62 dirt
setblock ~33 ~120 ~63 dirt
setblock ~33 ~120 ~64 dirt
setblock ~33 ~120 ~66 dirt
setblock ~33 ~120 ~67 dirt
setblock ~33 ~120 ~68 dirt
setblock ~33 ~120 ~69 dirt
setblock ~33 ~120 ~70 dirt
setblock ~33 ~120 ~71 dirt
setblock ~33 ~120 ~72 dirt
setblock ~33 ~120 ~73 dirt
setblock ~33 ~120 ~74 dirt
setblock ~33 ~120 ~75 dirt
setblock ~33 ~120 ~76 dirt
setblock ~33 ~120 ~77 dirt
setblock ~33 ~120 ~78 dirt
setblock ~33 ~120 ~79 dirt
setblock ~33 ~120 ~99 dirt
setblock ~33 ~120 ~100 dirt
setblock ~33 ~120 ~103 dirt
setblock ~33 ~120 ~104 dirt
setblock ~33 ~120 ~105 dirt
setblock ~33 ~120 ~106 dirt
setblock ~33 ~120 ~107 dirt
setblock ~33 ~120 ~108 dirt
setblock ~33 ~120 ~109 dirt
setblock ~33 ~120 ~110 dirt
setblock ~33 ~120 ~111 dirt
setblock ~33 ~120 ~112 dirt
setblock ~33 ~120 ~113 dirt
setblock ~33 ~120 ~115 dirt
setblock ~33 ~120 ~116 dirt
setblock ~33 ~120 ~117 dirt
setblock ~33 ~120 ~118 dirt
setblock ~33 ~120 ~119 dirt
setblock ~33 ~120 ~120 dirt
setblock ~33 ~120 ~121 dirt
setblock ~33 ~120 ~122 dirt
setblock ~33 ~120 ~123 dirt
setblock ~33 ~120 ~124 dirt
setblock ~33 ~120 ~125 dirt
setblock ~33 ~120 ~126 dirt
setblock ~33 ~120 ~127 dirt
setblock ~33 ~120 ~128 dirt
setblock ~33 ~120 ~129 dirt
setblock ~33 ~120 ~130 dirt
setblock ~33 ~120 ~131 dirt
setblock ~33 ~120 ~132 dirt
setblock ~33 ~120 ~133 dirt
setblock ~33 ~120 ~139 dirt
setblock ~33 ~120 ~140 dirt
setblock ~33 ~120 ~141 dirt
setblock ~33 ~121 ~51 dirt
setblock ~33 ~121 ~52 dirt
setblock ~33 ~121 ~53 dirt
setblock ~33 ~121 ~54 dirt
setblock ~33 ~121 ~57 dirt
setblock ~33 ~121 ~58 dirt
setblock ~33 ~121 ~59 dirt
setblock ~33 ~121 ~60 dirt
setblock ~33 ~121 ~61 dirt
setblock ~33 ~121 ~62 dirt
setblock ~33 ~121 ~63 dirt
setblock ~33 ~121 ~64 dirt
setblock ~33 ~121 ~65 dirt
setblock ~33 ~121 ~66 dirt
setblock ~33 ~121 ~67 dirt
setblock ~33 ~121 ~68 dirt
setblock ~33 ~121 ~69 dirt
setblock ~33 ~121 ~70 dirt
setblock ~33 ~121 ~71 dirt
setblock ~33 ~121 ~72 dirt
setblock ~33 ~121 ~73 dirt
setblock ~33 ~121 ~74 dirt
setblock ~33 ~121 ~75 dirt
setblock ~33 ~121 ~76 dirt
setblock ~33 ~121 ~77 dirt
setblock ~33 ~121 ~78 dirt
setblock ~33 ~121 ~79 dirt
setblock ~33 ~121 ~98 dirt
setblock ~33 ~121 ~99 dirt
setblock ~33 ~121 ~100 dirt
setblock ~33 ~121 ~102 dirt
setblock ~33 ~121 ~103 dirt
setblock ~33 ~121 ~104 dirt
setblock ~33 ~121 ~105 dirt
setblock ~33 ~121 ~106 dirt
setblock ~33 ~121 ~107 dirt
setblock ~33 ~121 ~108 dirt
setblock ~33 ~121 ~109 dirt
setblock ~33 ~121 ~110 dirt
setblock ~33 ~121 ~111 dirt
setblock ~33 ~121 ~112 dirt
setblock ~33 ~121 ~113 dirt
setblock ~33 ~121 ~115 dirt
setblock ~33 ~121 ~116 dirt
setblock ~33 ~121 ~117 dirt
setblock ~33 ~121 ~118 dirt
setblock ~33 ~121 ~119 dirt
setblock ~33 ~121 ~120 dirt
setblock ~33 ~121 ~121 dirt
setblock ~33 ~121 ~122 dirt
setblock ~33 ~121 ~123 dirt
setblock ~33 ~121 ~124 dirt
setblock ~33 ~121 ~125 dirt
setblock ~33 ~121 ~126 dirt
setblock ~33 ~121 ~127 dirt
setblock ~33 ~121 ~128 dirt
setblock ~33 ~121 ~129 dirt
setblock ~33 ~121 ~130 dirt
setblock ~33 ~121 ~131 dirt
setblock ~33 ~121 ~132 dirt
setblock ~33 ~121 ~133 dirt
setblock ~33 ~121 ~134 dirt
setblock ~33 ~121 ~138 dirt
setblock ~33 ~121 ~139 dirt
setblock ~33 ~121 ~140 dirt
setblock ~33 ~121 ~141 dirt
setblock ~33 ~121 ~142 dirt
setblock ~33 ~122 ~51 dirt
setblock ~33 ~122 ~52 dirt
setblock ~33 ~122 ~53 dirt
setblock ~33 ~122 ~54 dirt
setblock ~33 ~122 ~57 dirt
setblock ~33 ~122 ~58 dirt
setblock ~33 ~122 ~59 dirt
setblock ~33 ~122 ~60 dirt
setblock ~33 ~122 ~61 dirt
setblock ~33 ~122 ~62 dirt
setblock ~33 ~122 ~63 dirt
setblock ~33 ~122 ~64 dirt
setblock ~33 ~122 ~65 dirt
setblock ~33 ~122 ~66 dirt
setblock ~33 ~122 ~67 dirt
setblock ~33 ~122 ~68 dirt
setblock ~33 ~122 ~69 dirt
setblock ~33 ~122 ~70 dirt
setblock ~33 ~122 ~71 dirt
setblock ~33 ~122 ~72 dirt
setblock ~33 ~122 ~73 dirt
setblock ~33 ~122 ~74 dirt
setblock ~33 ~122 ~75 dirt
setblock ~33 ~122 ~76 dirt
setblock ~33 ~122 ~77 dirt
setblock ~33 ~122 ~78 dirt
setblock ~33 ~122 ~79 dirt
setblock ~33 ~122 ~98 dirt
setblock ~33 ~122 ~99 dirt
setblock ~33 ~122 ~100 dirt
setblock ~33 ~122 ~102 dirt
setblock ~33 ~122 ~103 dirt
setblock ~33 ~122 ~104 dirt
setblock ~33 ~122 ~105 dirt
setblock ~33 ~122 ~106 dirt
setblock ~33 ~122 ~107 dirt
setblock ~33 ~122 ~108 dirt
setblock ~33 ~122 ~109 dirt
setblock ~33 ~122 ~110 dirt
setblock ~33 ~122 ~111 dirt
setblock ~33 ~122 ~112 dirt
setblock ~33 ~122 ~113 dirt
setblock ~33 ~122 ~115 dirt
setblock ~33 ~122 ~116 dirt
setblock ~33 ~122 ~117 dirt
setblock ~33 ~122 ~118 dirt
setblock ~33 ~122 ~119 dirt
setblock ~33 ~122 ~120 dirt
setblock ~33 ~122 ~121 dirt
setblock ~33 ~122 ~122 dirt
setblock ~33 ~122 ~123 dirt
setblock ~33 ~122 ~124 dirt
setblock ~33 ~122 ~125 dirt
setblock ~33 ~122 ~126 dirt
setblock ~33 ~122 ~127 dirt
setblock ~33 ~122 ~128 dirt
setblock ~33 ~122 ~129 dirt
setblock ~33 ~122 ~130 dirt
setblock ~33 ~122 ~131 dirt
setblock ~33 ~122 ~132 dirt
setblock ~33 ~122 ~133 dirt
setblock ~33 ~122 ~134 dirt
setblock ~33 ~122 ~138 dirt
setblock ~33 ~122 ~139 dirt
setblock ~33 ~122 ~140 dirt
setblock ~33 ~122 ~141 dirt
setblock ~33 ~122 ~142 dirt
setblock ~33 ~123 ~51 dirt
setblock ~33 ~123 ~52 dirt
setblock ~33 ~123 ~53 dirt
setblock ~33 ~123 ~54 dirt
setblock ~33 ~123 ~57 dirt
setblock ~33 ~123 ~58 dirt
setblock ~33 ~123 ~59 dirt
setblock ~33 ~123 ~60 dirt
setblock ~33 ~123 ~61 dirt
setblock ~33 ~123 ~62 dirt
setblock ~33 ~123 ~63 dirt
setblock ~33 ~123 ~64 dirt
setblock ~33 ~123 ~65 dirt
setblock ~33 ~123 ~66 dirt
setblock ~33 ~123 ~67 dirt
setblock ~33 ~123 ~68 dirt
setblock ~33 ~123 ~69 dirt
setblock ~33 ~123 ~70 dirt
setblock ~33 ~123 ~71 dirt
setblock ~33 ~123 ~72 dirt
setblock ~33 ~123 ~73 dirt
setblock ~33 ~123 ~74 dirt
setblock ~33 ~123 ~75 dirt
setblock ~33 ~123 ~76 dirt
setblock ~33 ~123 ~77 dirt
setblock ~33 ~123 ~78 dirt
setblock ~33 ~123 ~79 grass_block
setblock ~33 ~123 ~98 dirt
setblock ~33 ~123 ~99 dirt
setblock ~33 ~123 ~100 dirt
setblock ~33 ~123 ~102 dirt
setblock ~33 ~123 ~103 dirt
setblock ~33 ~123 ~104 dirt
setblock ~33 ~123 ~105 dirt
setblock ~33 ~123 ~106 dirt
setblock ~33 ~123 ~107 dirt
setblock ~33 ~123 ~108 dirt
setblock ~33 ~123 ~109 dirt
setblock ~33 ~123 ~110 dirt
setblock ~33 ~123 ~111 dirt
setblock ~33 ~123 ~112 dirt
setblock ~33 ~123 ~113 dirt
setblock ~33 ~123 ~115 dirt
setblock ~33 ~123 ~116 dirt
setblock ~33 ~123 ~117 dirt
setblock ~33 ~123 ~118 dirt
setblock ~33 ~123 ~119 dirt
setblock ~33 ~123 ~120 dirt
setblock ~33 ~123 ~121 dirt
setblock ~33 ~123 ~122 dirt
setblock ~33 ~123 ~123 dirt
setblock ~33 ~123 ~124 dirt
setblock ~33 ~123 ~125 dirt
setblock ~33 ~123 ~126 dirt
setblock ~33 ~123 ~127 dirt
setblock ~33 ~123 ~128 dirt
setblock ~33 ~123 ~129 dirt
setblock ~33 ~123 ~130 dirt
setblock ~33 ~123 ~131 dirt
setblock ~33 ~123 ~132 dirt
setblock ~33 ~123 ~133 dirt
setblock ~33 ~123 ~134 dirt
setblock ~33 ~123 ~138 dirt
setblock ~33 ~123 ~139 dirt
setblock ~33 ~123 ~140 dirt
setblock ~33 ~123 ~141 dirt
setblock ~33 ~123 ~142 dirt
setblock ~33 ~124 ~51 dirt
setblock ~33 ~124 ~52 dirt
setblock ~33 ~124 ~53 dirt
setblock ~33 ~124 ~54 dirt
setblock ~33 ~124 ~57 dirt
setblock ~33 ~124 ~58 dirt
setblock ~33 ~124 ~59 dirt
setblock ~33 ~124 ~60 dirt
setblock ~33 ~124 ~61 dirt
setblock ~33 ~124 ~62 dirt
setblock ~33 ~124 ~63 dirt
setblock ~33 ~124 ~64 dirt
setblock ~33 ~124 ~65 dirt
setblock ~33 ~124 ~66 dirt
setblock ~33 ~124 ~67 dirt
setblock ~33 ~124 ~68 dirt
setblock ~33 ~124 ~69 dirt
setblock ~33 ~124 ~70 dirt
setblock ~33 ~124 ~71 dirt
setblock ~33 ~124 ~72 dirt
setblock ~33 ~124 ~73 dirt
setblock ~33 ~124 ~74 dirt
setblock ~33 ~124 ~75 dirt
setblock ~33 ~124 ~76 grass_block
setblock ~33 ~124 ~77 grass_block
setblock ~33 ~124 ~78 grass_block
setblock ~33 ~124 ~98 dirt
setblock ~33 ~124 ~99 dirt
setblock ~33 ~124 ~100 dirt
setblock ~33 ~124 ~102 dirt
setblock ~33 ~124 ~103 dirt
setblock ~33 ~124 ~104 dirt
setblock ~33 ~124 ~105 dirt
setblock ~33 ~124 ~106 dirt
setblock ~33 ~124 ~107 dirt
setblock ~33 ~124 ~108 dirt
setblock ~33 ~124 ~109 dirt
setblock ~33 ~124 ~110 dirt
setblock ~33 ~124 ~111 dirt
setblock ~33 ~124 ~112 dirt
setblock ~33 ~124 ~113 dirt
setblock ~33 ~124 ~115 dirt
setblock ~33 ~124 ~116 dirt
setblock ~33 ~124 ~117 dirt
setblock ~33 ~124 ~118 dirt
setblock ~33 ~124 ~119 dirt
setblock ~33 ~124 ~120 dirt
setblock ~33 ~124 ~121 dirt
setblock ~33 ~124 ~122 dirt
setblock ~33 ~124 ~123 dirt
setblock ~33 ~124 ~124 dirt
setblock ~33 ~124 ~125 dirt
setblock ~33 ~124 ~126 dirt
setblock ~33 ~124 ~127 dirt
setblock ~33 ~124 ~128 dirt
setblock ~33 ~124 ~129 dirt
setblock ~33 ~124 ~130 dirt
setblock ~33 ~124 ~131 dirt
setblock ~33 ~124 ~132 dirt
setblock ~33 ~124 ~133 dirt
setblock ~33 ~124 ~134 dirt
setblock ~33 ~124 ~138 dirt
setblock ~33 ~124 ~139 dirt
setblock ~33 ~124 ~140 dirt
setblock ~33 ~124 ~141 dirt
setblock ~33 ~124 ~142 dirt
setblock ~33 ~125 ~51 dirt
setblock ~33 ~125 ~52 dirt
setblock ~33 ~125 ~53 dirt
setblock ~33 ~125 ~54 dirt
setblock ~33 ~125 ~57 dirt
setblock ~33 ~125 ~58 dirt
setblock ~33 ~125 ~59 dirt
setblock ~33 ~125 ~60 dirt
setblock ~33 ~125 ~61 dirt
setblock ~33 ~125 ~62 dirt
setblock ~33 ~125 ~63 dirt
setblock ~33 ~125 ~64 dirt
setblock ~33 ~125 ~65 dirt
setblock ~33 ~125 ~66 dirt
setblock ~33 ~125 ~67 dirt
setblock ~33 ~125 ~68 dirt
setblock ~33 ~125 ~69 dirt
setblock ~33 ~125 ~70 dirt
setblock ~33 ~125 ~71 dirt
setblock ~33 ~125 ~72 dirt
setblock ~33 ~125 ~73 dirt
setblock ~33 ~125 ~74 grass_block
setblock ~33 ~125 ~75 grass_block
setblock ~33 ~125 ~77 poppy
setblock ~33 ~125 ~98 grass_block
setblock ~33 ~125 ~99 grass_block
setblock ~33 ~125 ~100 grass_block
setblock ~33 ~125 ~102 grass_block
setblock ~33 ~125 ~103 grass_block
setblock ~33 ~125 ~104 grass_block
setblock ~33 ~125 ~105 grass_block
setblock ~33 ~125 ~106 dirt
setblock ~33 ~125 ~107 dirt
setblock ~33 ~125 ~108 dirt
setblock ~33 ~125 ~109 dirt
setblock ~33 ~125 ~110 dirt
setblock ~33 ~125 ~111 dirt
setblock ~33 ~125 ~112 dirt
setblock ~33 ~125 ~113 dirt
setblock ~33 ~125 ~115 dirt
setblock ~33 ~125 ~116 dirt
setblock ~33 ~125 ~117 grass_block
setblock ~33 ~125 ~118 grass_block
setblock ~33 ~125 ~119 grass_block
setblock ~33 ~125 ~120 grass_block
setblock ~33 ~125 ~121 grass_block
setblock ~33 ~125 ~122 grass_block
setblock ~33 ~125 ~123 grass_block
setblock ~33 ~125 ~124 dirt
setblock ~33 ~125 ~125 dirt
setblock ~33 ~125 ~126 dirt
setblock ~33 ~125 ~127 dirt
setblock ~33 ~125 ~128 dirt
setblock ~33 ~125 ~129 dirt
setblock ~33 ~125 ~130 dirt
setblock ~33 ~125 ~131 dirt
setblock ~33 ~125 ~132 dirt
setblock ~33 ~125 ~133 dirt
setblock ~33 ~125 ~134 dirt
setblock ~33 ~125 ~138 dirt
setblock ~33 ~125 ~139 dirt
setblock ~33 ~125 ~140 dirt
setblock ~33 ~125 ~141 dirt
setblock ~33 ~125 ~142 dirt
setblock ~33 ~126 ~51 grass_block
setblock ~33 ~126 ~52 grass_block
setblock ~33 ~126 ~53 grass_block
setblock ~33 ~126 ~54 grass_block
setblock ~33 ~126 ~57 grass_block
setblock ~33 ~126 ~58 grass_block
setblock ~33 ~126 ~59 grass_block
setblock ~33 ~126 ~60 grass_block
setblock ~33 ~126 ~61 grass_block
setblock ~33 ~126 ~62 grass_block
setblock ~33 ~126 ~63 grass_block
setblock ~33 ~126 ~64 grass_block
setblock ~33 ~126 ~65 grass_block
setblock ~33 ~126 ~66 grass_block
setblock ~33 ~126 ~67 grass_block
setblock ~33 ~126 ~68 grass_block
setblock ~33 ~126 ~69 dirt
setblock ~33 ~126 ~70 dirt
setblock ~33 ~126 ~71 grass_block
setblock ~33 ~126 ~72 grass_block
setblock ~33 ~126 ~73 grass_block
setblock ~33 ~126 ~98 short_grass
setblock ~33 ~126 ~100 fern
setblock ~33 ~126 ~104 short_grass
setblock ~33 ~126 ~106 grass_block
setblock ~33 ~126 ~107 grass_block
setblock ~33 ~126 ~108 grass_block
setblock ~33 ~126 ~109 grass_block
setblock ~33 ~126 ~110 grass_block
setblock ~33 ~126 ~111 grass_block
setblock ~33 ~126 ~112 grass_block
setblock ~33 ~126 ~113 grass_block
setblock ~33 ~126 ~115 grass_block
setblock ~33 ~126 ~116 grass_block
setblock ~33 ~126 ~119 short_grass
setblock ~33 ~126 ~123 short_grass
setblock ~33 ~126 ~124 grass_block
setblock ~33 ~126 ~125 grass_block
setblock ~33 ~126 ~126 grass_block
setblock ~33 ~126 ~127 grass_block
setblock ~33 ~126 ~128 grass_block
setblock ~33 ~126 ~129 grass_block
setblock ~33 ~126 ~130 grass_block
setblock ~33 ~126 ~131 grass_block
setblock ~33 ~126 ~132 grass_block
setblock ~33 ~126 ~133 grass_block
setblock ~33 ~126 ~134 grass_block
setblock ~33 ~126 ~138 grass_block
setblock ~33 ~126 ~139 grass_block
setblock ~33 ~126 ~140 grass_block
setblock ~33 ~126 ~141 grass_block
setblock ~33 ~126 ~142 grass_block
setblock ~33 ~127 ~51 short_grass
setblock ~33 ~127 ~53 short_grass
setblock ~33 ~127 ~57 short_grass
setblock ~33 ~127 ~63 poppy
setblock ~33 ~127 ~64 short_grass
setblock ~33 ~127 ~67 short_grass
setblock ~33 ~127 ~69 grass_block
setblock ~33 ~127 ~70 grass_block
setblock ~33 ~127 ~107 fern
setblock ~33 ~127 ~111 short_grass
setblock ~33 ~127 ~115 poppy
setblock ~33 ~127 ~125 poppy
setblock ~33 ~127 ~127 short_grass
setblock ~33 ~127 ~128 poppy
setblock ~33 ~127 ~129 short_grass
setblock ~33 ~127 ~142 fern
setblock ~34 ~108 ~123 dirt
setblock ~34 ~109 ~123 dirt
setblock ~34 ~110 ~122 dirt
setblock ~34 ~110 ~123 dirt
setblock ~34 ~111 ~122 dirt
setblock ~34 ~111 ~123 dirt
setblock ~34 ~111 ~124 dirt
setblock ~34 ~111 ~126 dirt
setblock ~34 ~111 ~127 dirt
setblock ~34 ~111 ~128 dirt
setblock ~34 ~112 ~121 dirt
setblock ~34 ~112 ~122 dirt
setblock ~34 ~112 ~123 dirt
setblock ~34 ~112 ~124 dirt
setblock ~34 ~112 ~125 dirt
setblock ~34 ~112 ~126 dirt
setblock ~34 ~112 ~127 dirt
setblock ~34 ~112 ~128 dirt
setblock ~34 ~112 ~129 dirt
setblock ~34 ~113 ~73 dirt
setblock ~34 ~113 ~121 dirt
setblock ~34 ~113 ~122 dirt
setblock ~34 ~113 ~123 dirt
setblock ~34 ~113 ~124 dirt
setblock ~34 ~113 ~125 dirt
setblock ~34 ~113 ~126 dirt
setblock ~34 ~113 ~127 dirt
setblock ~34 ~113 ~128 dirt
setblock ~34 ~113 ~129 dirt
setblock ~34 ~114 ~71 dirt
setblock ~34 ~114 ~72 dirt
setblock ~34 ~114 ~73 dirt
setblock ~34 ~114 ~74 dirt
setblock ~34 ~114 ~120 dirt
setblock ~34 ~114 ~121 dirt
setblock ~34 ~114 ~122 dirt
setblock ~34 ~114 ~123 dirt
setblock ~34 ~114 ~124 dirt
setblock ~34 ~114 ~125 dirt
setblock ~34 ~114 ~126 dirt
setblock ~34 ~114 ~127 dirt
setblock ~34 ~114 ~128 dirt
setblock ~34 ~114 ~129 dirt
setblock ~34 ~114 ~130 dirt
setblock ~34 ~115 ~69 dirt
setblock ~34 ~115 ~70 dirt
setblock ~34 ~115 ~71 dirt
setblock ~34 ~115 ~72 dirt
setblock ~34 ~115 ~73 dirt
setblock ~34 ~115 ~74 dirt
setblock ~34 ~115 ~118 dirt
setblock ~34 ~115 ~119 dirt
setblock ~34 ~115 ~120 dirt
setblock ~34 ~115 ~121 dirt
setblock ~34 ~115 ~122 dirt
setblock ~34 ~115 ~123 dirt
setblock ~34 ~115 ~124 dirt
setblock ~34 ~115 ~125 dirt
setblock ~34 ~115 ~126 dirt
setblock ~34 ~115 ~127 dirt
setblock ~34 ~115 ~128 dirt
setblock ~34 ~115 ~129 dirt
setblock ~34 ~115 ~130 dirt
setblock ~34 ~115 ~131 dirt
setblock ~34 ~116 ~68 dirt
setblock ~34 ~116 ~69 dirt
setblock ~34 ~116 ~70 dirt
setblock ~34 ~116 ~71 dirt
setblock ~34 ~116 ~72 dirt
setblock ~34 ~116 ~73 dirt
setblock ~34 ~116 ~74 dirt
setblock ~34 ~116 ~75 dirt
setblock ~34 ~116 ~76 dirt
setblock ~34 ~116 ~108 dirt
setblock ~34 ~116 ~109 dirt
setblock ~34 ~116 ~117 dirt
setblock ~34 ~116 ~118 dirt
setblock ~34 ~116 ~119 dirt
setblock ~34 ~116 ~120 dirt
setblock ~34 ~116 ~121 dirt
setblock ~34 ~116 ~122 dirt
setblock ~34 ~116 ~123 dirt
setblock ~34 ~116 ~124 dirt
setblock ~34 ~116 ~125 dirt
setblock ~34 ~116 ~126 dirt
setblock ~34 ~116 ~127 dirt
setblock ~34 ~116 ~128 dirt
setblock ~34 ~116 ~129 dirt
setblock ~34 ~116 ~130 dirt
setblock ~34 ~116 ~131 dirt
setblock ~34 ~117 ~68 dirt
setblock ~34 ~117 ~69 dirt
setblock ~34 ~117 ~70 dirt
setblock ~34 ~117 ~71 dirt
setblock ~34 ~117 ~72 dirt
setblock ~34 ~117 ~73 dirt
setblock ~34 ~117 ~74 dirt
setblock ~34 ~117 ~75 dirt
setblock ~34 ~117 ~76 dirt
setblock ~34 ~117 ~77 dirt
setblock ~34 ~117 ~100 dirt
setblock ~34 ~117 ~102 dirt
setblock ~34 ~117 ~103 dirt
setblock ~34 ~117 ~106 dirt
setblock ~34 ~117 ~107 dirt
setblock ~34 ~117 ~108 dirt
setblock ~34 ~117 ~109 dirt
setblock ~34 ~117 ~110 dirt
setblock ~34 ~117 ~116 dirt
setblock ~34 ~117 ~117 dirt
setblock ~34 ~117 ~118 dirt
setblock ~34 ~117 ~119 dirt
setblock ~34 ~117 ~120 dirt
setblock ~34 ~117 ~121 dirt
setblock ~34 ~117 ~122 dirt
setblock ~34 ~117 ~123 dirt
setblock ~34 ~117 ~124 dirt
setblock ~34 ~117 ~125 dirt
setblock ~34 ~117 ~126 dirt
setblock ~34 ~117 ~127 dirt
setblock ~34 ~117 ~128 dirt
setblock ~34 ~117 ~129 dirt
setblock ~34 ~117 ~130 dirt
setblock ~34 ~117 ~131 dirt
setblock ~34 ~117 ~132 dirt
setblock ~34 ~118 ~52 dirt
setblock ~34 ~118 ~67 dirt
setblock ~34 ~118 ~68 dirt
setblock ~34 ~118 ~69 dirt
setblock ~34 ~118 ~70 dirt
setblock ~34 ~118 ~71 dirt
setblock ~34 ~118 ~72 dirt
setblock ~34 ~118 ~73 dirt
setblock ~34 ~118 ~74 dirt
setblock ~34 ~118 ~75 dirt
setblock ~34 ~118 ~76 dirt
setblock ~34 ~118 ~77 dirt
setblock ~34 ~118 ~78 dirt
setblock ~34 ~118 ~99 dirt
setblock ~34 ~118 ~100 dirt
setblock ~34 ~118 ~101 dirt
setblock ~34 ~118 ~102 dirt
setblock ~34 ~118 ~103 dirt
setblock ~34 ~118 ~104 dirt
setblock ~34 ~118 ~105 dirt
setblock ~34 ~118 ~106 dirt
setblock ~34 ~118 ~107 dirt
setblock ~34 ~118 ~108 dirt
setblock ~34 ~118 ~109 dirt
setblock ~34 ~118 ~110 dirt
setblock ~34 ~118 ~111 dirt
setblock ~34 ~118 ~115 dirt
setblock ~34 ~118 ~116 dirt
setblock ~34 ~118 ~117 dirt
setblock ~34 ~118 ~118 dirt
setblock ~34 ~118 ~119 dirt
setblock ~34 ~118 ~120 dirt
setblock ~34 ~118 ~121 dirt
setblock ~34 ~118 ~122 dirt
setblock ~34 ~118 ~123 dirt
setblock ~34 ~118 ~124 dirt
setblock ~34 ~118 ~125 dirt
setblock ~34 ~118 ~126 dirt
setblock ~34 ~118 ~127 dirt
setblock ~34 ~118 ~128 dirt
setblock ~34 ~118 ~129 dirt
setblock ~34 ~118 ~130 dirt
setblock ~34 ~118 ~131 dirt
setblock ~34 ~118 ~132 dirt
setblock ~34 ~118 ~133 dirt
setblock ~34 ~119 ~51 dirt
setblock ~34 ~119 ~52 dirt
setblock ~34 ~119 ~53 dirt
setblock ~34 ~119 ~59 dirt
setblock ~34 ~119 ~60 dirt
setblock ~34 ~119 ~62 dirt
setblock ~34 ~119 ~64 dirt
setblock ~34 ~119 ~66 dirt
setblock ~34 ~119 ~67 dirt
setblock ~34 ~119 ~68 dirt
setblock ~34 ~119 ~69 dirt
setblock ~34 ~119 ~70 dirt
setblock ~34 ~119 ~71 dirt
setblock ~34 ~119 ~72 dirt
setblock ~34 ~119 ~73 dirt
setblock ~34 ~119 ~74 dirt
setblock ~34 ~119 ~75 dirt
setblock ~34 ~119 ~76 dirt
setblock ~34 ~119 ~77 dirt
setblock ~34 ~119 ~78 dirt
setblock ~34 ~119 ~79 dirt
setblock ~34 ~119 ~98 dirt
setblock ~34 ~119 ~99 dirt
setblock ~34 ~119 ~100 dirt
setblock ~34 ~119 ~101 dirt
setblock ~34 ~119 ~102 dirt
setblock ~34 ~119 ~103 dirt
setblock ~34 ~119 ~104 dirt
setblock ~34 ~119 ~105 dirt
setblock ~34 ~119 ~106 dirt
setblock ~34 ~119 ~107 dirt
setblock ~34 ~119 ~108 dirt
setblock ~34 ~119 ~109 dirt
setblock ~34 ~119 ~110 dirt
setblock ~34 ~119 ~111 dirt
setblock ~34 ~119 ~113 dirt
setblock ~34 ~119 ~115 dirt
setblock ~34 ~119 ~116 dirt
setblock ~34 ~119 ~117 dirt
setblock ~34 ~119 ~118 dirt
setblock ~34 ~119 ~119 dirt
setblock ~34 ~119 ~120 dirt
setblock ~34 ~119 ~121 dirt
setblock ~34 ~119 ~122 dirt
setblock ~34 ~119 ~123 dirt
setblock ~34 ~119 ~124 dirt
setblock ~34 ~119 ~125 dirt
setblock ~34 ~119 ~126 dirt
setblock ~34 ~119 ~127 dirt
setblock ~34 ~119 ~128 dirt
setblock ~34 ~119 ~129 dirt
setblock ~34 ~119 ~130 dirt
setblock ~34 ~119 ~131 dirt
setblock ~34 ~119 ~132 dirt
setblock ~34 ~119 ~133 dirt
setblock ~34 ~119 ~134 dirt
setblock ~34 ~120 ~51 dirt
setblock ~34 ~120 ~52 dirt
setblock ~34 ~120 ~53 dirt
setblock ~34 ~120 ~54 dirt
setblock ~34 ~120 ~59 dirt
setblock ~34 ~120 ~60 dirt
setblock ~34 ~120 ~61 dirt
setblock ~34 ~120 ~62 dirt
setblock ~34 ~120 ~63 dirt
setblock ~34 ~120 ~64 dirt
setblock ~34 ~120 ~65 dirt
setblock ~34 ~120 ~66 dirt
setblock ~34 ~120 ~67 dirt
setblock ~34 ~120 ~68 dirt
setblock ~34 ~120 ~69 dirt
setblock ~34 ~120 ~70 dirt
setblock ~34 ~120 ~71 dirt
setblock ~34 ~120 ~72 dirt
setblock ~34 ~120 ~73 dirt
setblock ~34 ~120 ~74 dirt
setblock ~34 ~120 ~75 dirt
setblock ~34 ~120 ~76 dirt
setblock ~34 ~120 ~77 dirt
setblock ~34 ~120 ~78 dirt
setblock ~34 ~120 ~79 dirt
setblock ~34 ~120 ~98 dirt
setblock ~34 ~120 ~99 dirt
setblock ~34 ~120 ~100 dirt
setblock ~34 ~120 ~101 dirt
setblock ~34 ~120 ~102 dirt
setblock ~34 ~120 ~103 dirt
setblock ~34 ~120 ~104 dirt
setblock ~34 ~120 ~105 dirt
setblock ~34 ~120 ~106 dirt
setblock ~34 ~120 ~107 dirt
setblock ~34 ~120 ~108 dirt
setblock ~34 ~120 ~109 dirt
setblock ~34 ~120 ~110 dirt
setblock ~34 ~120 ~111 dirt
setblock ~34 ~120 ~112 dirt
setblock ~34 ~120 ~113 dirt
setblock ~34 ~120 ~115 dirt
setblock ~34 ~120 ~116 dirt
setblock ~34 ~120 ~117 dirt
setblock ~34 ~120 ~118 dirt
setblock ~34 ~120 ~119 dirt
setblock ~34 ~120 ~120 dirt
setblock ~34 ~120 ~121 dirt
setblock ~34 ~120 ~122 dirt
setblock ~34 ~120 ~123 dirt
setblock ~34 ~120 ~124 dirt
setblock ~34 ~120 ~125 dirt
setblock ~34 ~120 ~126 dirt
setblock ~34 ~120 ~127 dirt
setblock ~34 ~120 ~128 dirt
setblock ~34 ~120 ~129 dirt
setblock ~34 ~120 ~130 dirt
setblock ~34 ~120 ~131 dirt
setblock ~34 ~120 ~132 dirt
setblock ~34 ~120 ~133 dirt
setblock ~34 ~120 ~134 dirt
setblock ~34 ~120 ~140 dirt
setblock ~34 ~121 ~49 dirt
setblock ~34 ~121 ~50 dirt
setblock ~34 ~121 ~51 dirt
setblock ~34 ~121 ~52 dirt
setblock ~34 ~121 ~53 dirt
setblock ~34 ~121 ~54 dirt
setblock ~34 ~121 ~58 dirt
setblock ~34 ~121 ~59 dirt
setblock ~34 ~121 ~60 dirt
setblock ~34 ~121 ~61 dirt
setblock ~34 ~121 ~62 dirt
setblock ~34 ~121 ~63 dirt
setblock ~34 ~121 ~64 dirt
setblock ~34 ~121 ~65 dirt
setblock ~34 ~121 ~66 dirt
setblock ~34 ~121 ~67 dirt
setblock ~34 ~121 ~68 dirt
setblock ~34 ~121 ~69 dirt
setblock ~34 ~121 ~70 dirt
setblock ~34 ~121 ~71 dirt
setblock ~34 ~121 ~72 dirt
setblock ~34 ~121 ~73 dirt
setblock ~34 ~121 ~74 dirt
setblock ~34 ~121 ~75 dirt
setblock ~34 ~121 ~76 dirt
setblock ~34 ~121 ~77 dirt
setblock ~34 ~121 ~78 dirt
setblock ~34 ~121 ~79 dirt
setblock ~34 ~121 ~97 dirt
setblock ~34 ~121 ~98 dirt
setblock ~34 ~121 ~99 dirt
setblock ~34 ~121 ~100 dirt
setblock ~34 ~121 ~101 dirt
setblock ~34 ~121 ~102 dirt
setblock ~34 ~121 ~103 dirt
setblock ~34 ~121 ~104 dirt
setblock ~34 ~121 ~105 dirt
setblock ~34 ~121 ~106 dirt
setblock ~34 ~121 ~107 dirt
setblock ~34 ~121 ~108 dirt
setblock ~34 ~121 ~109 dirt
setblock ~34 ~121 ~110 dirt
setblock ~34 ~121 ~111 dirt
setblock ~34 ~121 ~112 dirt
setblock ~34 ~121 ~113 dirt
setblock ~34 ~121 ~114 dirt
setblock ~34 ~121 ~115 dirt
setblock ~34 ~121 ~116 dirt
setblock ~34 ~121 ~117 dirt
setblock ~34 ~121 ~118 dirt
setblock ~34 ~121 ~119 dirt
setblock ~34 ~121 ~120 dirt
setblock ~34 ~121 ~121 dirt
setblock ~34 ~121 ~122 dirt
setblock ~34 ~121 ~123 dirt
setblock ~34 ~121 ~124 dirt
setblock ~34 ~121 ~125 dirt
setblock ~34 ~121 ~126 dirt
setblock ~34 ~121 ~127 dirt
setblock ~34 ~121 ~128 dirt
setblock ~34 ~121 ~129 dirt
setblock ~34 ~121 ~130 dirt
setblock ~34 ~121 ~131 dirt
setblock ~34 ~121 ~132 dirt
setblock ~34 ~121 ~133 dirt
setblock ~34 ~121 ~134 dirt
setblock ~34 ~121 ~135 dirt
setblock ~34 ~121 ~139 dirt
setblock ~34 ~121 ~140 dirt
setblock ~34 ~121 ~141 dirt
setblock ~34 ~122 ~49 dirt
setblock ~34 ~122 ~50 dirt
setblock ~34 ~122 ~51 dirt
setblock ~34 ~122 ~52 dirt
setblock ~34 ~122 ~53 dirt
setblock ~34 ~122 ~54 dirt
setblock ~34 ~122 ~58 dirt
setblock ~34 ~122 ~59 dirt
setblock ~34 ~122 ~60 dirt
setblock ~34 ~122 ~61 dirt
setblock ~34 ~122 ~62 dirt
setblock ~34 ~122 ~63 dirt
setblock ~34 ~122 ~64 dirt
setblock ~34 ~122 ~65 dirt
setblock ~34 ~122 ~66 dirt
setblock ~34 ~122 ~67 dirt
setblock ~34 ~122 ~68 dirt
setblock ~34 ~122 ~69 dirt
setblock ~34 ~122 ~70 dirt
setblock ~34 ~122 ~71 dirt
setblock ~34 ~122 ~72 dirt
setblock ~34 ~122 ~73 dirt
setblock ~34 ~122 ~74 dirt
setblock ~34 ~122 ~75 dirt
setblock ~34 ~122 ~76 dirt
setblock ~34 ~122 ~77 dirt
setblock ~34 ~122 ~78 dirt
setblock ~34 ~122 ~79 dirt
setblock ~34 ~122 ~97 dirt
setblock ~34 ~122 ~98 dirt
setblock ~34 ~122 ~99 dirt
setblock ~34 ~122 ~100 dirt
setblock ~34 ~122 ~101 dirt
setblock ~34 ~122 ~102 dirt
setblock ~34 ~122 ~103 dirt
setblock ~34 ~122 ~104 dirt
setblock ~34 ~122 ~105 dirt
setblock ~34 ~122 ~106 dirt
setblock ~34 ~122 ~107 dirt
setblock ~34 ~122 ~108 dirt
setblock ~34 ~122 ~109 dirt
setblock ~34 ~122 ~110 dirt
setblock ~34 ~122 ~111 dirt
setblock ~34 ~122 ~112 dirt
setblock ~34 ~122 ~113 dirt
setblock ~34 ~122 ~114 dirt
setblock ~34 ~122 ~115 dirt
setblock ~34 ~122 ~116 dirt
setblock ~34 ~122 ~117 dirt
setblock ~34 ~122 ~118 dirt
setblock ~34 ~122 ~119 dirt
setblock ~34 ~122 ~120 dirt
setblock ~34 ~122 ~121 dirt
setblock ~34 ~122 ~122 dirt
setblock ~34 ~122 ~123 dirt
setblock ~34 ~122 ~124 dirt
setblock ~34 ~122 ~125 dirt
setblock ~34 ~122 ~126 dirt
setblock ~34 ~122 ~127 dirt
setblock ~34 ~122 ~128 dirt
setblock ~34 ~122 ~129 dirt
setblock ~34 ~122 ~130 dirt
setblock ~34 ~122 ~131 dirt
setblock ~34 ~122 ~132 dirt
setblock ~34 ~122 ~133 dirt
setblock ~34 ~122 ~134 dirt
setblock ~34 ~122 ~135 dirt
setblock ~34 ~122 ~139 dirt
setblock ~34 ~122 ~140 dirt
setblock ~34 ~122 ~141 dirt
setblock ~34 ~123 ~49 dirt
setblock ~34 ~123 ~50 dirt
setblock ~34 ~123 ~51 dirt
setblock ~34 ~123 ~52 dirt
setblock ~34 ~123 ~53 dirt
setblock ~34 ~123 ~54 dirt
setblock ~34 ~123 ~58 dirt
setblock ~34 ~123 ~59 dirt
setblock ~34 ~123 ~60 dirt
setblock ~34 ~123 ~61 dirt
setblock ~34 ~123 ~62 dirt
setblock ~34 ~123 ~63 dirt
setblock ~34 ~123 ~64 dirt
setblock ~34 ~123 ~65 dirt
setblock ~34 ~123 ~66 dirt
setblock ~34 ~123 ~67 dirt
setblock ~34 ~123 ~68 dirt
setblock ~34 ~123 ~69 dirt
setblock ~34 ~123 ~70 dirt
setblock ~34 ~123 ~71 dirt
setblock ~34 ~123 ~72 dirt
setblock ~34 ~123 ~73 dirt
setblock ~34 ~123 ~74 dirt
setblock ~34 ~123 ~75 dirt
setblock ~34 ~123 ~76 dirt
setblock ~34 ~123 ~77 dirt
setblock ~34 ~123 ~78 grass_block
setblock ~34 ~123 ~79 grass_block
setblock ~34 ~123 ~97 dirt
setblock ~34 ~123 ~98 dirt
setblock ~34 ~123 ~99 dirt
setblock ~34 ~123 ~100 dirt
setblock ~34 ~123 ~101 dirt
setblock ~34 ~123 ~102 dirt
setblock ~34 ~123 ~103 dirt
