setblock ~0 ~1 ~0 gold_block
setblock ~20 ~121 ~97 dirt
setblock ~20 ~122 ~97 dirt
setblock ~20 ~123 ~97 grass_block
setblock ~20 ~124 ~97 short_grass
setblock ~21 ~117 ~97 dirt
setblock ~21 ~118 ~97 dirt
setblock ~21 ~119 ~97 dirt
setblock ~21 ~120 ~97 dirt
setblock ~21 ~120 ~99 dirt
setblock ~21 ~121 ~91 dirt
setblock ~21 ~121 ~95 dirt
setblock ~21 ~121 ~96 dirt
setblock ~21 ~121 ~97 dirt
setblock ~21 ~121 ~98 dirt
setblock ~21 ~121 ~99 dirt
setblock ~21 ~122 ~91 dirt
setblock ~21 ~122 ~95 dirt
setblock ~21 ~122 ~96 dirt
setblock ~21 ~122 ~97 dirt
setblock ~21 ~122 ~98 dirt
setblock ~21 ~122 ~99 dirt
setblock ~21 ~123 ~91 dirt
setblock ~21 ~123 ~95 dirt
setblock ~21 ~123 ~96 dirt
setblock ~21 ~123 ~97 dirt
setblock ~21 ~123 ~98 dirt
setblock ~21 ~123 ~99 dirt
setblock ~21 ~124 ~91 grass_block
setblock ~21 ~124 ~95 grass_block
setblock ~21 ~124 ~96 grass_block
setblock ~21 ~124 ~97 grass_block
setblock ~21 ~124 ~98 grass_block
setblock ~21 ~124 ~99 grass_block
setblock ~21 ~125 ~96 poppy
setblock ~21 ~125 ~98 short_grass
setblock ~22 ~116 ~97 dirt
setblock ~22 ~117 ~96 dirt
setblock ~22 ~117 ~97 dirt
setblock ~22 ~117 ~98 dirt
setblock ~22 ~118 ~96 dirt
setblock ~22 ~118 ~97 dirt
setblock ~22 ~118 ~98 dirt
setblock ~22 ~118 ~99 dirt
setblock ~22 ~119 ~95 dirt
setblock ~22 ~119 ~96 dirt
setblock ~22 ~119 ~97 dirt
setblock ~22 ~119 ~98 dirt
setblock ~22 ~119 ~99 dirt
setblock ~22 ~120 ~89 dirt
setblock ~22 ~120 ~91 dirt
setblock ~22 ~120 ~94 dirt
setblock ~22 ~120 ~95 dirt
setblock ~22 ~120 ~96 dirt
setblock ~22 ~120 ~97 dirt
setblock ~22 ~120 ~98 dirt
setblock ~22 ~120 ~99 dirt
setblock ~22 ~120 ~100 dirt
setblock ~22 ~120 ~101 dirt
setblock ~22 ~121 ~87 dirt
setblock ~22 ~121 ~89 dirt
setblock ~22 ~121 ~90 dirt
setblock ~22 ~121 ~91 dirt
setblock ~22 ~121 ~92 dirt
setblock ~22 ~121 ~93 dirt
setblock ~22 ~121 ~94 dirt
setblock ~22 ~121 ~95 dirt
setblock ~22 ~121 ~96 dirt
setblock ~22 ~121 ~97 dirt
setblock ~22 ~121 ~98 dirt
setblock ~22 ~121 ~99 dirt
setblock ~22 ~121 ~100 dirt
setblock ~22 ~121 ~101 dirt
setblock ~22 ~121 ~102 dirt
setblock ~22 ~121 ~103 dirt
setblock ~22 ~122 ~87 dirt
setblock ~22 ~122 ~89 dirt
setblock ~22 ~122 ~90 dirt
setblock ~22 ~122 ~91 dirt
setblock ~22 ~122 ~92 dirt
setblock ~22 ~122 ~93 dirt
setblock ~22 ~122 ~94 dirt
setblock ~22 ~122 ~95 dirt
setblock ~22 ~122 ~96 dirt
setblock ~22 ~122 ~97 dirt
setblock ~22 ~122 ~98 dirt
setblock ~22 ~122 ~99 dirt
setblock ~22 ~122 ~100 dirt
setblock ~22 ~122 ~101 dirt
setblock ~22 ~122 ~102 dirt
setblock ~22 ~122 ~103 dirt
setblock ~22 ~123 ~87 dirt
setblock ~22 ~123 ~89 dirt
setblock ~22 ~123 ~90 dirt
setblock ~22 ~123 ~91 dirt
setblock ~22 ~123 ~92 dirt
setblock ~22 ~123 ~93 dirt
setblock ~22 ~123 ~94 dirt
setblock ~22 ~123 ~95 dirt
setblock ~22 ~123 ~96 dirt
setblock ~22 ~123 ~97 dirt
setblock ~22 ~123 ~98 dirt
setblock ~22 ~123 ~99 dirt
setblock ~22 ~123 ~100 dirt
setblock ~22 ~123 ~101 dirt
setblock ~22 ~123 ~102 dirt
setblock ~22 ~123 ~103 dirt
setblock ~22 ~124 ~87 dirt
setblock ~22 ~124 ~89 dirt
setblock ~22 ~124 ~90 grass_block
setblock ~22 ~124 ~91 grass_block
setblock ~22 ~124 ~92 grass_block
setblock ~22 ~124 ~93 grass_block
setblock ~22 ~124 ~94 grass_block
setblock ~22 ~124 ~95 grass_block
setblock ~22 ~124 ~96 grass_block
setblock ~22 ~124 ~97 grass_block
setblock ~22 ~124 ~98 grass_block
setblock ~22 ~124 ~99 grass_block
setblock ~22 ~124 ~100 grass_block
setblock ~22 ~124 ~101 grass_block
setblock ~22 ~124 ~102 grass_block
setblock ~22 ~124 ~103 dirt
setblock ~22 ~125 ~87 dirt
setblock ~22 ~125 ~89 grass_block
setblock ~22 ~125 ~92 short_grass
setblock ~22 ~125 ~93 short_grass
setblock ~22 ~125 ~95 short_grass
setblock ~22 ~125 ~99 short_grass
setblock ~22 ~125 ~101 short_grass
setblock ~22 ~125 ~103 grass_block
setblock ~22 ~126 ~87 grass_block
setblock ~22 ~126 ~103 fern
setblock ~23 ~115 ~97 dirt
setblock ~23 ~116 ~96 dirt
setblock ~23 ~116 ~97 dirt
setblock ~23 ~116 ~98 dirt
setblock ~23 ~116 ~99 dirt
setblock ~23 ~117 ~95 dirt
setblock ~23 ~117 ~96 dirt
setblock ~23 ~117 ~97 dirt
setblock ~23 ~117 ~98 dirt
setblock ~23 ~117 ~99 dirt
setblock ~23 ~117 ~102 dirt
setblock ~23 ~118 ~90 dirt
setblock ~23 ~118 ~95 dirt
setblock ~23 ~118 ~96 dirt
setblock ~23 ~118 ~97 dirt
setblock ~23 ~118 ~98 dirt
setblock ~23 ~118 ~99 dirt
setblock ~23 ~118 ~100 dirt
setblock ~23 ~118 ~102 dirt
setblock ~23 ~119 ~89 dirt
setblock ~23 ~119 ~90 dirt
setblock ~23 ~119 ~91 dirt
setblock ~23 ~119 ~92 dirt
setblock ~23 ~119 ~93 dirt
setblock ~23 ~119 ~94 dirt
setblock ~23 ~119 ~95 dirt
setblock ~23 ~119 ~96 dirt
setblock ~23 ~119 ~97 dirt
setblock ~23 ~119 ~98 dirt
setblock ~23 ~119 ~99 dirt
setblock ~23 ~119 ~100 dirt
setblock ~23 ~119 ~101 dirt
setblock ~23 ~119 ~102 dirt
setblock ~23 ~119 ~104 dirt
setblock ~23 ~120 ~87 dirt
setblock ~23 ~120 ~88 dirt
setblock ~23 ~120 ~89 dirt
setblock ~23 ~120 ~90 dirt
setblock ~23 ~120 ~91 dirt
setblock ~23 ~120 ~92 dirt
setblock ~23 ~120 ~93 dirt
setblock ~23 ~120 ~94 dirt
setblock ~23 ~120 ~95 dirt
setblock ~23 ~120 ~96 dirt
setblock ~23 ~120 ~97 dirt
setblock ~23 ~120 ~98 dirt
setblock ~23 ~120 ~99 dirt
setblock ~23 ~120 ~100 dirt
setblock ~23 ~120 ~101 dirt
setblock ~23 ~120 ~102 dirt
setblock ~23 ~120 ~103 dirt
setblock ~23 ~120 ~104 dirt
setblock ~23 ~121 ~84 dirt
setblock ~23 ~121 ~85 dirt
setblock ~23 ~121 ~86 dirt
setblock ~23 ~121 ~87 dirt
setblock ~23 ~121 ~88 dirt
setblock ~23 ~121 ~89 dirt
setblock ~23 ~121 ~90 dirt
setblock ~23 ~121 ~91 dirt
setblock ~23 ~121 ~92 dirt
setblock ~23 ~121 ~93 dirt
setblock ~23 ~121 ~94 dirt
setblock ~23 ~121 ~95 dirt
setblock ~23 ~121 ~96 dirt
setblock ~23 ~121 ~97 dirt
setblock ~23 ~121 ~98 dirt
setblock ~23 ~121 ~99 dirt
setblock ~23 ~121 ~100 dirt
setblock ~23 ~121 ~101 dirt
setblock ~23 ~121 ~102 dirt
setblock ~23 ~121 ~103 dirt
setblock ~23 ~121 ~104 dirt
setblock ~23 ~121 ~105 dirt
setblock ~23 ~121 ~106 dirt
setblock ~23 ~121 ~110 dirt
setblock ~23 ~122 ~84 dirt
setblock ~23 ~122 ~85 dirt
setblock ~23 ~122 ~86 dirt
setblock ~23 ~122 ~87 dirt
setblock ~23 ~122 ~88 dirt
setblock ~23 ~122 ~89 dirt
setblock ~23 ~122 ~90 dirt
setblock ~23 ~122 ~91 dirt
setblock ~23 ~122 ~92 dirt
setblock ~23 ~122 ~93 dirt
setblock ~23 ~122 ~94 dirt
setblock ~23 ~122 ~95 dirt
setblock ~23 ~122 ~96 dirt
setblock ~23 ~122 ~97 dirt
setblock ~23 ~122 ~98 dirt
setblock ~23 ~122 ~99 dirt
setblock ~23 ~122 ~100 dirt
setblock ~23 ~122 ~101 dirt
setblock ~23 ~122 ~102 dirt
setblock ~23 ~122 ~103 dirt
setblock ~23 ~122 ~104 dirt
setblock ~23 ~122 ~105 dirt
setblock ~23 ~122 ~106 dirt
setblock ~23 ~122 ~110 dirt
setblock ~23 ~123 ~84 dirt
setblock ~23 ~123 ~85 dirt
setblock ~23 ~123 ~86 dirt
setblock ~23 ~123 ~87 dirt
setblock ~23 ~123 ~88 dirt
setblock ~23 ~123 ~89 dirt
setblock ~23 ~123 ~90 dirt
setblock ~23 ~123 ~91 dirt
setblock ~23 ~123 ~92 dirt
setblock ~23 ~123 ~93 dirt
setblock ~23 ~123 ~94 dirt
setblock ~23 ~123 ~95 dirt
setblock ~23 ~123 ~96 dirt
setblock ~23 ~123 ~97 dirt
setblock ~23 ~123 ~98 dirt
setblock ~23 ~123 ~99 dirt
setblock ~23 ~123 ~100 dirt
setblock ~23 ~123 ~101 dirt
setblock ~23 ~123 ~102 dirt
setblock ~23 ~123 ~103 dirt
setblock ~23 ~123 ~104 dirt
setblock ~23 ~123 ~105 dirt
setblock ~23 ~123 ~106 dirt
setblock ~23 ~123 ~110 dirt
setblock ~23 ~124 ~84 dirt
setblock ~23 ~124 ~85 dirt
setblock ~23 ~124 ~86 dirt
setblock ~23 ~124 ~87 dirt
setblock ~23 ~124 ~88 dirt
setblock ~23 ~124 ~89 dirt
setblock ~23 ~124 ~90 dirt
setblock ~23 ~124 ~91 dirt
setblock ~23 ~124 ~92 dirt
setblock ~23 ~124 ~93 dirt
setblock ~23 ~124 ~94 dirt
setblock ~23 ~124 ~95 grass_block
setblock ~23 ~124 ~96 grass_block
setblock ~23 ~124 ~97 grass_block
setblock ~23 ~124 ~98 grass_block
setblock ~23 ~124 ~99 grass_block
setblock ~23 ~124 ~100 grass_block
setblock ~23 ~124 ~101 grass_block
setblock ~23 ~124 ~102 dirt
setblock ~23 ~124 ~103 dirt
setblock ~23 ~124 ~104 dirt
setblock ~23 ~124 ~105 dirt
setblock ~23 ~124 ~106 dirt
setblock ~23 ~124 ~110 dirt
setblock ~23 ~125 ~84 dirt
setblock ~23 ~125 ~85 dirt
setblock ~23 ~125 ~86 dirt
setblock ~23 ~125 ~87 dirt
setblock ~23 ~125 ~88 dirt
setblock ~23 ~125 ~89 grass_block
setblock ~23 ~125 ~90 grass_block
setblock ~23 ~125 ~91 grass_block
setblock ~23 ~125 ~92 grass_block
setblock ~23 ~125 ~93 grass_block
setblock ~23 ~125 ~94 grass_block
setblock ~23 ~125 ~96 fern
setblock ~23 ~125 ~98 fern
setblock ~23 ~125 ~100 short_grass
setblock ~23 ~125 ~102 grass_block
setblock ~23 ~125 ~103 grass_block
setblock ~23 ~125 ~104 grass_block
setblock ~23 ~125 ~105 grass_block
setblock ~23 ~125 ~106 dirt
setblock ~23 ~125 ~110 dirt
setblock ~23 ~126 ~84 dirt
setblock ~23 ~126 ~85 dirt
setblock ~23 ~126 ~86 grass_block
setblock ~23 ~126 ~87 grass_block
setblock ~23 ~126 ~88 grass_block
setblock ~23 ~126 ~89 short_grass
setblock ~23 ~126 ~90 short_grass
setblock ~23 ~126 ~102 short_grass
setblock ~23 ~126 ~103 short_grass
setblock ~23 ~126 ~106 grass_block
setblock ~23 ~126 ~110 grass_block
setblock ~23 ~127 ~84 grass_block
setblock ~23 ~127 ~85 grass_block
setblock ~23 ~127 ~86 short_grass
setblock ~23 ~127 ~106 short_grass
setblock ~23 ~128 ~84 short_grass
setblock ~24 ~113 ~97 dirt
setblock ~24 ~114 ~96 dirt
setblock ~24 ~114 ~97 dirt
setblock ~24 ~114 ~98 dirt
setblock ~24 ~114 ~102 dirt
setblock ~24 ~115 ~95 dirt
setblock ~24 ~115 ~96 dirt
setblock ~24 ~115 ~97 dirt
setblock ~24 ~115 ~98 dirt
setblock ~24 ~115 ~99 dirt
setblock ~24 ~115 ~102 dirt
setblock ~24 ~116 ~94 dirt
setblock ~24 ~116 ~95 dirt
setblock ~24 ~116 ~96 dirt
setblock ~24 ~116 ~97 dirt
setblock ~24 ~116 ~98 dirt
setblock ~24 ~116 ~99 dirt
setblock ~24 ~116 ~100 dirt
setblock ~24 ~116 ~101 dirt
setblock ~24 ~116 ~102 dirt
setblock ~24 ~117 ~90 dirt
setblock ~24 ~117 ~94 dirt
setblock ~24 ~117 ~95 dirt
setblock ~24 ~117 ~96 dirt
setblock ~24 ~117 ~97 dirt
setblock ~24 ~117 ~98 dirt
setblock ~24 ~117 ~99 dirt
setblock ~24 ~117 ~100 dirt
setblock ~24 ~117 ~101 dirt
setblock ~24 ~117 ~102 dirt
setblock ~24 ~117 ~103 dirt
setblock ~24 ~118 ~89 dirt
setblock ~24 ~118 ~90 dirt
setblock ~24 ~118 ~91 dirt
setblock ~24 ~118 ~92 dirt
setblock ~24 ~118 ~93 dirt
setblock ~24 ~118 ~94 dirt
setblock ~24 ~118 ~95 dirt
setblock ~24 ~118 ~96 dirt
setblock ~24 ~118 ~97 dirt
setblock ~24 ~118 ~98 dirt
setblock ~24 ~118 ~99 dirt
setblock ~24 ~118 ~100 dirt
setblock ~24 ~118 ~101 dirt
setblock ~24 ~118 ~102 dirt
setblock ~24 ~118 ~103 dirt
setblock ~24 ~118 ~104 dirt
setblock ~24 ~119 ~87 dirt
setblock ~24 ~119 ~88 dirt
setblock ~24 ~119 ~89 dirt
setblock ~24 ~119 ~90 dirt
setblock ~24 ~119 ~91 dirt
setblock ~24 ~119 ~92 dirt
setblock ~24 ~119 ~93 dirt
setblock ~24 ~119 ~94 dirt
setblock ~24 ~119 ~95 dirt
setblock ~24 ~119 ~96 dirt
setblock ~24 ~119 ~97 dirt
setblock ~24 ~119 ~98 dirt
setblock ~24 ~119 ~99 dirt
setblock ~24 ~119 ~100 dirt
setblock ~24 ~119 ~101 dirt
setblock ~24 ~119 ~102 dirt
setblock ~24 ~119 ~103 dirt
setblock ~24 ~119 ~104 dirt
setblock ~24 ~119 ~105 dirt
setblock ~24 ~119 ~106 dirt
setblock ~24 ~120 ~84 dirt
setblock ~24 ~120 ~85 dirt
setblock ~24 ~120 ~86 dirt
setblock ~24 ~120 ~87 dirt
setblock ~24 ~120 ~88 dirt
setblock ~24 ~120 ~89 dirt
setblock ~24 ~120 ~90 dirt
setblock ~24 ~120 ~91 dirt
setblock ~24 ~120 ~92 dirt
setblock ~24 ~120 ~93 dirt
setblock ~24 ~120 ~94 dirt
setblock ~24 ~120 ~95 dirt
setblock ~24 ~120 ~96 dirt
setblock ~24 ~120 ~97 dirt
setblock ~24 ~120 ~98 dirt
setblock ~24 ~120 ~99 dirt
setblock ~24 ~120 ~100 dirt
setblock ~24 ~120 ~101 dirt
setblock ~24 ~120 ~102 dirt
setblock ~24 ~120 ~103 dirt
setblock ~24 ~120 ~104 dirt
setblock ~24 ~120 ~105 dirt
setblock ~24 ~120 ~106 dirt
setblock ~24 ~120 ~107 dirt
setblock ~24 ~120 ~110 dirt
setblock ~24 ~121 ~83 dirt
setblock ~24 ~121 ~84 dirt
setblock ~24 ~121 ~85 dirt
setblock ~24 ~121 ~86 dirt
setblock ~24 ~121 ~87 dirt
setblock ~24 ~121 ~88 dirt
setblock ~24 ~121 ~89 dirt
setblock ~24 ~121 ~90 dirt
setblock ~24 ~121 ~91 dirt
setblock ~24 ~121 ~92 dirt
setblock ~24 ~121 ~93 dirt
setblock ~24 ~121 ~94 dirt
setblock ~24 ~121 ~95 dirt
setblock ~24 ~121 ~96 dirt
setblock ~24 ~121 ~97 dirt
setblock ~24 ~121 ~98 dirt
setblock ~24 ~121 ~99 dirt
setblock ~24 ~121 ~100 dirt
setblock ~24 ~121 ~101 dirt
setblock ~24 ~121 ~102 dirt
setblock ~24 ~121 ~103 dirt
setblock ~24 ~121 ~104 dirt
setblock ~24 ~121 ~105 dirt
setblock ~24 ~121 ~106 dirt
setblock ~24 ~121 ~107 dirt
setblock ~24 ~121 ~109 dirt
setblock ~24 ~121 ~110 dirt
setblock ~24 ~121 ~111 dirt
setblock ~24 ~122 ~83 dirt
setblock ~24 ~122 ~84 dirt
setblock ~24 ~122 ~85 dirt
setblock ~24 ~122 ~86 dirt
setblock ~24 ~122 ~87 dirt
setblock ~24 ~122 ~88 dirt
setblock ~24 ~122 ~89 dirt
setblock ~24 ~122 ~90 dirt
setblock ~24 ~122 ~91 dirt
setblock ~24 ~122 ~92 dirt
setblock ~24 ~122 ~93 dirt
setblock ~24 ~122 ~94 dirt
setblock ~24 ~122 ~95 dirt
setblock ~24 ~122 ~96 dirt
setblock ~24 ~122 ~97 dirt
setblock ~24 ~122 ~98 dirt
setblock ~24 ~122 ~99 dirt
setblock ~24 ~122 ~100 dirt
setblock ~24 ~122 ~101 dirt
setblock ~24 ~122 ~102 dirt
setblock ~24 ~122 ~103 dirt
setblock ~24 ~122 ~104 dirt
setblock ~24 ~122 ~105 dirt
setblock ~24 ~122 ~106 dirt
setblock ~24 ~122 ~107 dirt
setblock ~24 ~122 ~109 dirt
setblock ~24 ~122 ~110 dirt
setblock ~24 ~122 ~111 dirt
setblock ~24 ~123 ~83 dirt
setblock ~24 ~123 ~84 dirt
setblock ~24 ~123 ~85 dirt
setblock ~24 ~123 ~86 dirt
setblock ~24 ~123 ~87 dirt
setblock ~24 ~123 ~88 dirt
setblock ~24 ~123 ~89 dirt
setblock ~24 ~123 ~90 dirt
setblock ~24 ~123 ~91 dirt
setblock ~24 ~123 ~92 dirt
setblock ~24 ~123 ~93 dirt
setblock ~24 ~123 ~94 dirt
setblock ~24 ~123 ~95 dirt
setblock ~24 ~123 ~96 dirt
setblock ~24 ~123 ~97 dirt
setblock ~24 ~123 ~98 dirt
setblock ~24 ~123 ~99 dirt
setblock ~24 ~123 ~100 dirt
setblock ~24 ~123 ~101 dirt
setblock ~24 ~123 ~102 dirt
setblock ~24 ~123 ~103 dirt
setblock ~24 ~123 ~104 dirt
setblock ~24 ~123 ~105 dirt
setblock ~24 ~123 ~106 dirt
setblock ~24 ~123 ~107 dirt
setblock ~24 ~123 ~109 dirt
setblock ~24 ~123 ~110 dirt
setblock ~24 ~123 ~111 dirt
setblock ~24 ~124 ~83 dirt
setblock ~24 ~124 ~84 dirt
setblock ~24 ~124 ~85 dirt
setblock ~24 ~124 ~86 dirt
setblock ~24 ~124 ~87 dirt
setblock ~24 ~124 ~88 dirt
setblock ~24 ~124 ~89 dirt
setblock ~24 ~124 ~90 dirt
setblock ~24 ~124 ~91 dirt
setblock ~24 ~124 ~92 dirt
setblock ~24 ~124 ~93 dirt
setblock ~24 ~124 ~94 dirt
setblock ~24 ~124 ~95 dirt
setblock ~24 ~124 ~96 dirt
setblock ~24 ~124 ~97 dirt
setblock ~24 ~124 ~98 dirt
setblock ~24 ~124 ~99 dirt
setblock ~24 ~124 ~100 grass_block
setblock ~24 ~124 ~101 dirt
setblock ~24 ~124 ~102 dirt
setblock ~24 ~124 ~103 dirt
setblock ~24 ~124 ~104 dirt
setblock ~24 ~124 ~105 dirt
setblock ~24 ~124 ~106 dirt
setblock ~24 ~124 ~107 dirt
setblock ~24 ~124 ~109 dirt
setblock ~24 ~124 ~110 dirt
setblock ~24 ~124 ~111 dirt
setblock ~24 ~125 ~83 dirt
setblock ~24 ~125 ~84 dirt
setblock ~24 ~125 ~85 dirt
setblock ~24 ~125 ~86 dirt
setblock ~24 ~125 ~87 dirt
setblock ~24 ~125 ~88 dirt
setblock ~24 ~125 ~89 dirt
setblock ~24 ~125 ~90 grass_block
setblock ~24 ~125 ~91 grass_block
setblock ~24 ~125 ~92 grass_block
setblock ~24 ~125 ~93 grass_block
setblock ~24 ~125 ~94 grass_block
setblock ~24 ~125 ~95 grass_block
setblock ~24 ~125 ~96 grass_block
setblock ~24 ~125 ~97 grass_block
setblock ~24 ~125 ~98 grass_block
setblock ~24 ~125 ~99 grass_block
setblock ~24 ~125 ~101 grass_block
setblock ~24 ~125 ~102 grass_block
setblock ~24 ~125 ~103 grass_block
setblock ~24 ~125 ~104 grass_block
setblock ~24 ~125 ~105 dirt
setblock ~24 ~125 ~106 dirt
setblock ~24 ~125 ~107 dirt
setblock ~24 ~125 ~109 dirt
setblock ~24 ~125 ~110 dirt
setblock ~24 ~125 ~111 dirt
setblock ~24 ~126 ~83 dirt
setblock ~24 ~126 ~84 dirt
setblock ~24 ~126 ~85 grass_block
setblock ~24 ~126 ~86 grass_block
setblock ~24 ~126 ~87 grass_block
setblock ~24 ~126 ~88 grass_block
setblock ~24 ~126 ~89 grass_block
setblock ~24 ~126 ~91 short_grass
setblock ~24 ~126 ~92 short_grass
setblock ~24 ~126 ~93 short_grass
setblock ~24 ~126 ~97 short_grass
setblock ~24 ~126 ~98 short_grass
setblock ~24 ~126 ~102 short_grass
setblock ~24 ~126 ~103 short_grass
setblock ~24 ~126 ~105 grass_block
setblock ~24 ~126 ~106 grass_block
setblock ~24 ~126 ~107 grass_block
setblock ~24 ~126 ~109 dirt
setblock ~24 ~126 ~110 dirt
setblock ~24 ~126 ~111 dirt
setblock ~24 ~127 ~83 grass_block
setblock ~24 ~127 ~84 grass_block
setblock ~24 ~127 ~86 short_grass
setblock ~24 ~127 ~89 short_grass
setblock ~24 ~127 ~106 short_grass
setblock ~24 ~127 ~107 short_grass
setblock ~24 ~127 ~109 grass_block
setblock ~24 ~127 ~110 grass_block
setblock ~24 ~127 ~111 grass_block
setblock ~24 ~128 ~84 short_grass
setblock ~24 ~128 ~110 fern
setblock ~24 ~128 ~111 fern
setblock ~25 ~112 ~97 dirt
setblock ~25 ~112 ~98 dirt
setblock ~25 ~112 ~99 dirt
setblock ~25 ~113 ~96 dirt
setblock ~25 ~113 ~97 dirt
setblock ~25 ~113 ~98 dirt
setblock ~25 ~113 ~99 dirt
setblock ~25 ~113 ~101 dirt
setblock ~25 ~113 ~102 dirt
setblock ~25 ~114 ~95 dirt
setblock ~25 ~114 ~96 dirt
setblock ~25 ~114 ~97 dirt
setblock ~25 ~114 ~98 dirt
setblock ~25 ~114 ~99 dirt
setblock ~25 ~114 ~101 dirt
setblock ~25 ~114 ~102 dirt
setblock ~25 ~114 ~103 dirt
setblock ~25 ~115 ~88 dirt
setblock ~25 ~115 ~92 dirt
setblock ~25 ~115 ~94 dirt
setblock ~25 ~115 ~95 dirt
setblock ~25 ~115 ~96 dirt
setblock ~25 ~115 ~97 dirt
setblock ~25 ~115 ~98 dirt
setblock ~25 ~115 ~99 dirt
setblock ~25 ~115 ~100 dirt
setblock ~25 ~115 ~101 dirt
setblock ~25 ~115 ~102 dirt
setblock ~25 ~115 ~103 dirt
setblock ~25 ~116 ~85 dirt
setblock ~25 ~116 ~87 dirt
setblock ~25 ~116 ~88 dirt
setblock ~25 ~116 ~90 dirt
setblock ~25 ~116 ~92 dirt
setblock ~25 ~116 ~93 dirt
setblock ~25 ~116 ~94 dirt
setblock ~25 ~116 ~95 dirt
setblock ~25 ~116 ~96 dirt
setblock ~25 ~116 ~97 dirt
setblock ~25 ~116 ~98 dirt
setblock ~25 ~116 ~99 dirt
setblock ~25 ~116 ~100 dirt
setblock ~25 ~116 ~101 dirt
setblock ~25 ~116 ~102 dirt
setblock ~25 ~116 ~103 dirt
setblock ~25 ~117 ~85 dirt
setblock ~25 ~117 ~87 dirt
setblock ~25 ~117 ~88 dirt
setblock ~25 ~117 ~89 dirt
setblock ~25 ~117 ~90 dirt
setblock ~25 ~117 ~91 dirt
setblock ~25 ~117 ~92 dirt
setblock ~25 ~117 ~93 dirt
setblock ~25 ~117 ~94 dirt
setblock ~25 ~117 ~95 dirt
setblock ~25 ~117 ~96 dirt
setblock ~25 ~117 ~97 dirt
setblock ~25 ~117 ~98 dirt
setblock ~25 ~117 ~99 dirt
setblock ~25 ~117 ~100 dirt
setblock ~25 ~117 ~101 dirt
setblock ~25 ~117 ~102 dirt
setblock ~25 ~117 ~103 dirt
setblock ~25 ~117 ~104 dirt
setblock ~25 ~117 ~105 dirt
setblock ~25 ~117 ~106 dirt
setblock ~25 ~118 ~85 dirt
setblock ~25 ~118 ~86 dirt
setblock ~25 ~118 ~87 dirt
setblock ~25 ~118 ~88 dirt
setblock ~25 ~118 ~89 dirt
setblock ~25 ~118 ~90 dirt
setblock ~25 ~118 ~91 dirt
setblock ~25 ~118 ~92 dirt
setblock ~25 ~118 ~93 dirt
setblock ~25 ~118 ~94 dirt
setblock ~25 ~118 ~95 dirt
setblock ~25 ~118 ~96 dirt
setblock ~25 ~118 ~97 dirt
setblock ~25 ~118 ~98 dirt
setblock ~25 ~118 ~99 dirt
setblock ~25 ~118 ~100 dirt
setblock ~25 ~118 ~101 dirt
setblock ~25 ~118 ~102 dirt
setblock ~25 ~118 ~103 dirt
setblock ~25 ~118 ~104 dirt
setblock ~25 ~118 ~105 dirt
setblock ~25 ~118 ~106 dirt
setblock ~25 ~119 ~84 dirt
setblock ~25 ~119 ~85 dirt
setblock ~25 ~119 ~86 dirt
setblock ~25 ~119 ~87 dirt
setblock ~25 ~119 ~88 dirt
setblock ~25 ~119 ~89 dirt
setblock ~25 ~119 ~90 dirt
setblock ~25 ~119 ~91 dirt
setblock ~25 ~119 ~92 dirt
setblock ~25 ~119 ~93 dirt
setblock ~25 ~119 ~94 dirt
setblock ~25 ~119 ~95 dirt
setblock ~25 ~119 ~96 dirt
setblock ~25 ~119 ~97 dirt
setblock ~25 ~119 ~98 dirt
setblock ~25 ~119 ~99 dirt
setblock ~25 ~119 ~100 dirt
setblock ~25 ~119 ~101 dirt
setblock ~25 ~119 ~102 dirt
setblock ~25 ~119 ~103 dirt
setblock ~25 ~119 ~104 dirt
setblock ~25 ~119 ~105 dirt
setblock ~25 ~119 ~106 dirt
setblock ~25 ~119 ~107 dirt
setblock ~25 ~119 ~110 dirt
setblock ~25 ~120 ~83 dirt
setblock ~25 ~120 ~84 dirt
setblock ~25 ~120 ~85 dirt
setblock ~25 ~120 ~86 dirt
setblock ~25 ~120 ~87 dirt
setblock ~25 ~120 ~88 dirt
setblock ~25 ~120 ~89 dirt
setblock ~25 ~120 ~90 dirt
setblock ~25 ~120 ~91 dirt
setblock ~25 ~120 ~92 dirt
setblock ~25 ~120 ~93 dirt
setblock ~25 ~120 ~94 dirt
setblock ~25 ~120 ~95 dirt
setblock ~25 ~120 ~96 dirt
setblock ~25 ~120 ~97 dirt
setblock ~25 ~120 ~98 dirt
setblock ~25 ~120 ~99 dirt
setblock ~25 ~120 ~100 dirt
setblock ~25 ~120 ~101 dirt
setblock ~25 ~120 ~102 dirt
setblock ~25 ~120 ~103 dirt
setblock ~25 ~120 ~104 dirt
setblock ~25 ~120 ~105 dirt
setblock ~25 ~120 ~106 dirt
setblock ~25 ~120 ~107 dirt
setblock ~25 ~120 ~108 dirt
setblock ~25 ~120 ~109 dirt
setblock ~25 ~120 ~110 dirt
setblock ~25 ~120 ~111 dirt
setblock ~25 ~121 ~82 dirt
setblock ~25 ~121 ~83 dirt
setblock ~25 ~121 ~84 dirt
setblock ~25 ~121 ~85 dirt
setblock ~25 ~121 ~86 dirt
setblock ~25 ~121 ~87 dirt
setblock ~25 ~121 ~88 dirt
setblock ~25 ~121 ~89 dirt
setblock ~25 ~121 ~90 dirt
setblock ~25 ~121 ~91 dirt
setblock ~25 ~121 ~92 dirt
setblock ~25 ~121 ~93 dirt
setblock ~25 ~121 ~94 dirt
setblock ~25 ~121 ~95 dirt
setblock ~25 ~121 ~96 dirt
setblock ~25 ~121 ~97 dirt
setblock ~25 ~121 ~98 dirt
setblock ~25 ~121 ~99 dirt
setblock ~25 ~121 ~100 dirt
setblock ~25 ~121 ~101 dirt
setblock ~25 ~121 ~102 dirt
setblock ~25 ~121 ~103 dirt
setblock ~25 ~121 ~104 dirt
setblock ~25 ~121 ~105 dirt
setblock ~25 ~121 ~106 dirt
setblock ~25 ~121 ~107 dirt
setblock ~25 ~121 ~108 dirt
setblock ~25 ~121 ~109 dirt
setblock ~25 ~121 ~110 dirt
setblock ~25 ~121 ~111 dirt
setblock ~25 ~122 ~82 dirt
setblock ~25 ~122 ~83 dirt
setblock ~25 ~122 ~84 dirt
setblock ~25 ~122 ~85 dirt
setblock ~25 ~122 ~86 dirt
setblock ~25 ~122 ~87 dirt
setblock ~25 ~122 ~88 dirt
setblock ~25 ~122 ~89 dirt
setblock ~25 ~122 ~90 dirt
setblock ~25 ~122 ~91 dirt
setblock ~25 ~122 ~92 dirt
setblock ~25 ~122 ~93 dirt
setblock ~25 ~122 ~94 dirt
setblock ~25 ~122 ~95 dirt
setblock ~25 ~122 ~96 dirt
setblock ~25 ~122 ~97 dirt
setblock ~25 ~122 ~98 dirt
setblock ~25 ~122 ~99 dirt
setblock ~25 ~122 ~100 dirt
setblock ~25 ~122 ~101 dirt
setblock ~25 ~122 ~102 dirt
setblock ~25 ~122 ~103 dirt
setblock ~25 ~122 ~104 dirt
setblock ~25 ~122 ~105 dirt
setblock ~25 ~122 ~106 dirt
setblock ~25 ~122 ~107 dirt
setblock ~25 ~122 ~108 dirt
setblock ~25 ~122 ~109 dirt
setblock ~25 ~122 ~110 dirt
setblock ~25 ~122 ~111 dirt
setblock ~25 ~123 ~82 dirt
setblock ~25 ~123 ~83 dirt
setblock ~25 ~123 ~84 dirt
setblock ~25 ~123 ~85 dirt
setblock ~25 ~123 ~86 dirt
setblock ~25 ~123 ~87 dirt
setblock ~25 ~123 ~88 dirt
setblock ~25 ~123 ~89 dirt
setblock ~25 ~123 ~90 dirt
setblock ~25 ~123 ~91 dirt
setblock ~25 ~123 ~92 dirt
setblock ~25 ~123 ~93 dirt
setblock ~25 ~123 ~94 dirt
setblock ~25 ~123 ~95 dirt
setblock ~25 ~123 ~96 dirt
setblock ~25 ~123 ~97 dirt
setblock ~25 ~123 ~98 dirt
setblock ~25 ~123 ~99 dirt
setblock ~25 ~123 ~100 dirt
setblock ~25 ~123 ~101 dirt
setblock ~25 ~123 ~102 dirt
setblock ~25 ~123 ~103 dirt
setblock ~25 ~123 ~104 dirt
setblock ~25 ~123 ~105 dirt
setblock ~25 ~123 ~106 dirt
setblock ~25 ~123 ~107 dirt
setblock ~25 ~123 ~108 dirt
setblock ~25 ~123 ~109 dirt
setblock ~25 ~123 ~110 dirt
setblock ~25 ~123 ~111 dirt
setblock ~25 ~124 ~82 dirt
setblock ~25 ~124 ~83 dirt
setblock ~25 ~124 ~84 dirt
setblock ~25 ~124 ~85 dirt
setblock ~25 ~124 ~86 dirt
setblock ~25 ~124 ~87 dirt
setblock ~25 ~124 ~88 dirt
setblock ~25 ~124 ~89 dirt
setblock ~25 ~124 ~90 dirt
setblock ~25 ~124 ~91 dirt
setblock ~25 ~124 ~92 dirt
setblock ~25 ~124 ~93 dirt
setblock ~25 ~124 ~94 dirt
setblock ~25 ~124 ~95 dirt
setblock ~25 ~124 ~96 dirt
setblock ~25 ~124 ~97 dirt
setblock ~25 ~124 ~98 dirt
setblock ~25 ~124 ~99 dirt
setblock ~25 ~124 ~100 dirt
setblock ~25 ~124 ~101 dirt
setblock ~25 ~124 ~102 dirt
setblock ~25 ~124 ~103 dirt
setblock ~25 ~124 ~104 dirt
setblock ~25 ~124 ~105 dirt
setblock ~25 ~124 ~106 dirt
setblock ~25 ~124 ~107 dirt
setblock ~25 ~124 ~108 dirt
setblock ~25 ~124 ~109 dirt
setblock ~25 ~124 ~110 dirt
setblock ~25 ~124 ~111 dirt
setblock ~25 ~125 ~82 dirt
setblock ~25 ~125 ~83 dirt
setblock ~25 ~125 ~84 dirt
setblock ~25 ~125 ~85 dirt
setblock ~25 ~125 ~86 dirt
setblock ~25 ~125 ~87 dirt
setblock ~25 ~125 ~88 dirt
setblock ~25 ~125 ~89 dirt
setblock ~25 ~125 ~90 dirt
setblock ~25 ~125 ~91 dirt
setblock ~25 ~125 ~92 dirt
setblock ~25 ~125 ~93 grass_block
setblock ~25 ~125 ~94 grass_block
setblock ~25 ~125 ~95 grass_block
setblock ~25 ~125 ~96 grass_block
setblock ~25 ~125 ~97 grass_block
setblock ~25 ~125 ~98 grass_block
setblock ~25 ~125 ~99 grass_block
setblock ~25 ~125 ~100 grass_block
setblock ~25 ~125 ~101 grass_block
setblock ~25 ~125 ~102 grass_block
setblock ~25 ~125 ~103 grass_block
setblock ~25 ~125 ~104 dirt
setblock ~25 ~125 ~105 dirt
setblock ~25 ~125 ~106 dirt
setblock ~25 ~125 ~107 dirt
setblock ~25 ~125 ~108 dirt
setblock ~25 ~125 ~109 dirt
setblock ~25 ~125 ~110 dirt
setblock ~25 ~125 ~111 dirt
setblock ~25 ~126 ~82 grass_block
setblock ~25 ~126 ~83 grass_block
setblock ~25 ~126 ~84 grass_block
setblock ~25 ~126 ~85 grass_block
setblock ~25 ~126 ~86 grass_block
setblock ~25 ~126 ~87 grass_block
setblock ~25 ~126 ~88 grass_block
setblock ~25 ~126 ~89 grass_block
setblock ~25 ~126 ~90 grass_block
setblock ~25 ~126 ~91 grass_block
setblock ~25 ~126 ~92 grass_block
setblock ~25 ~126 ~96 short_grass
setblock ~25 ~126 ~97 fern
setblock ~25 ~126 ~100 poppy
setblock ~25 ~126 ~104 grass_block
setblock ~25 ~126 ~105 grass_block
setblock ~25 ~126 ~106 grass_block
setblock ~25 ~126 ~107 grass_block
setblock ~25 ~126 ~108 dirt
setblock ~25 ~126 ~109 dirt
setblock ~25 ~126 ~110 dirt
setblock ~25 ~126 ~111 dirt
setblock ~25 ~127 ~82 short_grass
setblock ~25 ~127 ~83 short_grass
setblock ~25 ~127 ~85 fern
setblock ~25 ~127 ~86 poppy
setblock ~25 ~127 ~87 poppy
setblock ~25 ~127 ~88 short_grass
setblock ~25 ~127 ~108 grass_block
setblock ~25 ~127 ~109 grass_block
setblock ~25 ~127 ~110 grass_block
setblock ~25 ~127 ~111 grass_block
setblock ~25 ~128 ~110 short_grass
setblock ~26 ~110 ~98 dirt
setblock ~26 ~110 ~99 dirt
setblock ~26 ~111 ~96 dirt
setblock ~26 ~111 ~97 dirt
setblock ~26 ~111 ~98 dirt
setblock ~26 ~111 ~99 dirt
setblock ~26 ~111 ~100 dirt
setblock ~26 ~112 ~96 dirt
setblock ~26 ~112 ~97 dirt
setblock ~26 ~112 ~98 dirt
setblock ~26 ~112 ~99 dirt
setblock ~26 ~112 ~100 dirt
setblock ~26 ~112 ~101 dirt
setblock ~26 ~112 ~102 dirt
setblock ~26 ~113 ~92 dirt
setblock ~26 ~113 ~95 dirt
setblock ~26 ~113 ~96 dirt
setblock ~26 ~113 ~97 dirt
setblock ~26 ~113 ~98 dirt
setblock ~26 ~113 ~99 dirt
setblock ~26 ~113 ~100 dirt
setblock ~26 ~113 ~101 dirt
setblock ~26 ~113 ~102 dirt
setblock ~26 ~113 ~103 dirt
setblock ~26 ~114 ~85 dirt
setblock ~26 ~114 ~87 dirt
setblock ~26 ~114 ~88 dirt
setblock ~26 ~114 ~90 dirt
setblock ~26 ~114 ~92 dirt
setblock ~26 ~114 ~93 dirt
setblock ~26 ~114 ~95 dirt
setblock ~26 ~114 ~96 dirt
setblock ~26 ~114 ~97 dirt
setblock ~26 ~114 ~98 dirt
setblock ~26 ~114 ~99 dirt
setblock ~26 ~114 ~100 dirt
setblock ~26 ~114 ~101 dirt
setblock ~26 ~114 ~102 dirt
setblock ~26 ~114 ~103 dirt
setblock ~26 ~114 ~105 dirt
setblock ~26 ~115 ~85 dirt
setblock ~26 ~115 ~86 dirt
setblock ~26 ~115 ~87 dirt
setblock ~26 ~115 ~88 dirt
setblock ~26 ~115 ~89 dirt
setblock ~26 ~115 ~90 dirt
setblock ~26 ~115 ~91 dirt
setblock ~26 ~115 ~92 dirt
setblock ~26 ~115 ~93 dirt
setblock ~26 ~115 ~94 dirt
setblock ~26 ~115 ~95 dirt
setblock ~26 ~115 ~96 dirt
setblock ~26 ~115 ~97 dirt
setblock ~26 ~115 ~98 dirt
setblock ~26 ~115 ~99 dirt
setblock ~26 ~115 ~100 dirt
setblock ~26 ~115 ~101 dirt
setblock ~26 ~115 ~102 dirt
setblock ~26 ~115 ~103 dirt
setblock ~26 ~115 ~104 dirt
setblock ~26 ~115 ~105 dirt
setblock ~26 ~115 ~107 dirt
setblock ~26 ~116 ~84 dirt
setblock ~26 ~116 ~85 dirt
setblock ~26 ~116 ~86 dirt
setblock ~26 ~116 ~87 dirt
setblock ~26 ~116 ~88 dirt
setblock ~26 ~116 ~89 dirt
setblock ~26 ~116 ~90 dirt
setblock ~26 ~116 ~91 dirt
setblock ~26 ~116 ~92 dirt
setblock ~26 ~116 ~93 dirt
setblock ~26 ~116 ~94 dirt
setblock ~26 ~116 ~95 dirt
setblock ~26 ~116 ~96 dirt
setblock ~26 ~116 ~97 dirt
setblock ~26 ~116 ~98 dirt
setblock ~26 ~116 ~99 dirt
setblock ~26 ~116 ~100 dirt
setblock ~26 ~116 ~101 dirt
setblock ~26 ~116 ~102 dirt
setblock ~26 ~116 ~103 dirt
setblock ~26 ~116 ~104 dirt
setblock ~26 ~116 ~105 dirt
setblock ~26 ~116 ~106 dirt
setblock ~26 ~116 ~107 dirt
setblock ~26 ~116 ~109 dirt
setblock ~26 ~117 ~84 dirt
setblock ~26 ~117 ~85 dirt
setblock ~26 ~117 ~86 dirt
setblock ~26 ~117 ~87 dirt
setblock ~26 ~117 ~88 dirt
setblock ~26 ~117 ~89 dirt
setblock ~26 ~117 ~90 dirt
setblock ~26 ~117 ~91 dirt
setblock ~26 ~117 ~92 dirt
setblock ~26 ~117 ~93 dirt
setblock ~26 ~117 ~94 dirt
setblock ~26 ~117 ~95 dirt
setblock ~26 ~117 ~96 dirt
setblock ~26 ~117 ~97 dirt
setblock ~26 ~117 ~98 dirt
setblock ~26 ~117 ~99 dirt
setblock ~26 ~117 ~100 dirt
setblock ~26 ~117 ~101 dirt
setblock ~26 ~117 ~102 dirt
setblock ~26 ~117 ~103 dirt
setblock ~26 ~117 ~104 dirt
setblock ~26 ~117 ~105 dirt
setblock ~26 ~117 ~106 dirt
setblock ~26 ~117 ~107 dirt
setblock ~26 ~117 ~108 dirt
setblock ~26 ~117 ~109 dirt
setblock ~26 ~117 ~110 dirt
setblock ~26 ~118 ~83 dirt
setblock ~26 ~118 ~84 dirt
setblock ~26 ~118 ~85 dirt
setblock ~26 ~118 ~86 dirt
setblock ~26 ~118 ~87 dirt
setblock ~26 ~118 ~88 dirt
setblock ~26 ~118 ~89 dirt
setblock ~26 ~118 ~90 dirt
setblock ~26 ~118 ~91 dirt
setblock ~26 ~118 ~92 dirt
setblock ~26 ~118 ~93 dirt
setblock ~26 ~118 ~94 dirt
setblock ~26 ~118 ~95 dirt
setblock ~26 ~118 ~96 dirt
setblock ~26 ~118 ~97 dirt
setblock ~26 ~118 ~98 dirt
setblock ~26 ~118 ~99 dirt
setblock ~26 ~118 ~100 dirt
setblock ~26 ~118 ~101 dirt
setblock ~26 ~118 ~102 dirt
setblock ~26 ~118 ~103 dirt
setblock ~26 ~118 ~104 dirt
setblock ~26 ~118 ~105 dirt
setblock ~26 ~118 ~106 dirt
setblock ~26 ~118 ~107 dirt
setblock ~26 ~118 ~108 dirt
setblock ~26 ~118 ~109 dirt
setblock ~26 ~118 ~110 dirt
setblock ~26 ~119 ~82 dirt
setblock ~26 ~119 ~83 dirt
setblock ~26 ~119 ~84 dirt
setblock ~26 ~119 ~85 dirt
setblock ~26 ~119 ~86 dirt
setblock ~26 ~119 ~87 dirt
setblock ~26 ~119 ~88 dirt
setblock ~26 ~119 ~89 dirt
setblock ~26 ~119 ~90 dirt
setblock ~26 ~119 ~91 dirt
setblock ~26 ~119 ~92 dirt
setblock ~26 ~119 ~93 dirt
setblock ~26 ~119 ~94 dirt
setblock ~26 ~119 ~95 dirt
setblock ~26 ~119 ~96 dirt
setblock ~26 ~119 ~97 dirt
setblock ~26 ~119 ~98 dirt
setblock ~26 ~119 ~99 dirt
setblock ~26 ~119 ~100 dirt
setblock ~26 ~119 ~101 dirt
setblock ~26 ~119 ~102 dirt
setblock ~26 ~119 ~103 dirt
setblock ~26 ~119 ~104 dirt
setblock ~26 ~119 ~105 dirt
setblock ~26 ~119 ~106 dirt
setblock ~26 ~119 ~107 dirt
setblock ~26 ~119 ~108 dirt
setblock ~26 ~119 ~109 dirt
setblock ~26 ~119 ~110 dirt
setblock ~26 ~119 ~111 dirt
setblock ~26 ~120 ~81 dirt
setblock ~26 ~120 ~82 dirt
setblock ~26 ~120 ~83 dirt
setblock ~26 ~120 ~84 dirt
setblock ~26 ~120 ~85 dirt
setblock ~26 ~120 ~86 dirt
setblock ~26 ~120 ~87 dirt
setblock ~26 ~120 ~88 dirt
setblock ~26 ~120 ~89 dirt
setblock ~26 ~120 ~90 dirt
setblock ~26 ~120 ~91 dirt
setblock ~26 ~120 ~92 dirt
setblock ~26 ~120 ~93 dirt
setblock ~26 ~120 ~94 dirt
setblock ~26 ~120 ~95 dirt
setblock ~26 ~120 ~96 dirt
setblock ~26 ~120 ~97 dirt
setblock ~26 ~120 ~98 dirt
setblock ~26 ~120 ~99 dirt
setblock ~26 ~120 ~100 dirt
setblock ~26 ~120 ~101 dirt
setblock ~26 ~120 ~102 dirt
setblock ~26 ~120 ~103 dirt
setblock ~26 ~120 ~104 dirt
setblock ~26 ~120 ~105 dirt
setblock ~26 ~120 ~106 dirt
setblock ~26 ~120 ~107 dirt
setblock ~26 ~120 ~108 dirt
setblock ~26 ~120 ~109 dirt
setblock ~26 ~120 ~110 dirt
setblock ~26 ~120 ~111 dirt
setblock ~26 ~121 ~80 dirt
setblock ~26 ~121 ~81 dirt
setblock ~26 ~121 ~82 dirt
setblock ~26 ~121 ~83 dirt
setblock ~26 ~121 ~84 dirt
setblock ~26 ~121 ~85 dirt
setblock ~26 ~121 ~86 dirt
setblock ~26 ~121 ~87 dirt
setblock ~26 ~121 ~88 dirt
setblock ~26 ~121 ~89 dirt
setblock ~26 ~121 ~90 dirt
setblock ~26 ~121 ~91 dirt
setblock ~26 ~121 ~92 dirt
setblock ~26 ~121 ~93 dirt
setblock ~26 ~121 ~94 dirt
setblock ~26 ~121 ~95 dirt
setblock ~26 ~121 ~96 dirt
setblock ~26 ~121 ~97 dirt
setblock ~26 ~121 ~98 dirt
setblock ~26 ~121 ~99 dirt
setblock ~26 ~121 ~100 dirt
setblock ~26 ~121 ~101 dirt
setblock ~26 ~121 ~102 dirt
setblock ~26 ~121 ~103 dirt
setblock ~26 ~121 ~104 dirt
setblock ~26 ~121 ~105 dirt
setblock ~26 ~121 ~106 dirt
setblock ~26 ~121 ~107 dirt
setblock ~26 ~121 ~108 dirt
setblock ~26 ~121 ~109 dirt
setblock ~26 ~121 ~110 dirt
setblock ~26 ~121 ~111 dirt
setblock ~26 ~122 ~80 dirt
setblock ~26 ~122 ~81 dirt
setblock ~26 ~122 ~82 dirt
setblock ~26 ~122 ~83 dirt
setblock ~26 ~122 ~84 dirt
setblock ~26 ~122 ~85 dirt
setblock ~26 ~122 ~86 dirt
setblock ~26 ~122 ~87 dirt
setblock ~26 ~122 ~88 dirt
setblock ~26 ~122 ~89 dirt
setblock ~26 ~122 ~90 dirt
setblock ~26 ~122 ~91 dirt
setblock ~26 ~122 ~92 dirt
setblock ~26 ~122 ~93 dirt
setblock ~26 ~122 ~94 dirt
setblock ~26 ~122 ~95 dirt
setblock ~26 ~122 ~96 dirt
setblock ~26 ~122 ~97 dirt
setblock ~26 ~122 ~98 dirt
setblock ~26 ~122 ~99 dirt
setblock ~26 ~122 ~100 dirt
setblock ~26 ~122 ~101 dirt
setblock ~26 ~122 ~102 dirt
setblock ~26 ~122 ~103 dirt
setblock ~26 ~122 ~104 dirt
setblock ~26 ~122 ~105 dirt
setblock ~26 ~122 ~106 dirt
setblock ~26 ~122 ~107 dirt
setblock ~26 ~122 ~108 dirt
setblock ~26 ~122 ~109 dirt
setblock ~26 ~122 ~110 dirt
setblock ~26 ~122 ~111 dirt
setblock ~26 ~123 ~80 dirt
setblock ~26 ~123 ~81 dirt
setblock ~26 ~123 ~82 dirt
setblock ~26 ~123 ~83 dirt
setblock ~26 ~123 ~84 dirt
setblock ~26 ~123 ~85 dirt
setblock ~26 ~123 ~86 dirt
setblock ~26 ~123 ~87 dirt
setblock ~26 ~123 ~88 dirt
setblock ~26 ~123 ~89 dirt
setblock ~26 ~123 ~90 dirt
setblock ~26 ~123 ~91 dirt
setblock ~26 ~123 ~92 dirt
setblock ~26 ~123 ~93 dirt
setblock ~26 ~123 ~94 dirt
setblock ~26 ~123 ~95 dirt
setblock ~26 ~123 ~96 dirt
setblock ~26 ~123 ~97 dirt
setblock ~26 ~123 ~98 dirt
setblock ~26 ~123 ~99 dirt
setblock ~26 ~123 ~100 dirt
setblock ~26 ~123 ~101 dirt
setblock ~26 ~123 ~102 dirt
setblock ~26 ~123 ~103 dirt
setblock ~26 ~123 ~104 dirt
setblock ~26 ~123 ~105 dirt
setblock ~26 ~123 ~106 dirt
setblock ~26 ~123 ~107 dirt
setblock ~26 ~123 ~108 dirt
setblock ~26 ~123 ~109 dirt
setblock ~26 ~123 ~110 dirt
setblock ~26 ~123 ~111 dirt
setblock ~26 ~124 ~80 dirt
setblock ~26 ~124 ~81 dirt
setblock ~26 ~124 ~82 dirt
setblock ~26 ~124 ~83 dirt
setblock ~26 ~124 ~84 dirt
setblock ~26 ~124 ~85 dirt
setblock ~26 ~124 ~86 dirt
setblock ~26 ~124 ~87 dirt
setblock ~26 ~124 ~88 dirt
setblock ~26 ~124 ~89 dirt
setblock ~26 ~124 ~90 dirt
setblock ~26 ~124 ~91 dirt
setblock ~26 ~124 ~92 dirt
setblock ~26 ~124 ~93 dirt
setblock ~26 ~124 ~94 dirt
setblock ~26 ~124 ~95 dirt
setblock ~26 ~124 ~96 dirt
setblock ~26 ~124 ~97 dirt
setblock ~26 ~124 ~98 dirt
setblock ~26 ~124 ~99 dirt
setblock ~26 ~124 ~100 dirt
setblock ~26 ~124 ~101 dirt
setblock ~26 ~124 ~102 dirt
setblock ~26 ~124 ~103 dirt
setblock ~26 ~124 ~104 dirt
setblock ~26 ~124 ~105 dirt
setblock ~26 ~124 ~106 dirt
setblock ~26 ~124 ~107 dirt
setblock ~26 ~124 ~108 dirt
setblock ~26 ~124 ~109 dirt
setblock ~26 ~124 ~110 dirt
setblock ~26 ~124 ~111 dirt
setblock ~26 ~125 ~80 dirt
setblock ~26 ~125 ~81 dirt
setblock ~26 ~125 ~82 dirt
setblock ~26 ~125 ~83 dirt
setblock ~26 ~125 ~84 dirt
setblock ~26 ~125 ~85 dirt
setblock ~26 ~125 ~86 dirt
setblock ~26 ~125 ~87 dirt
setblock ~26 ~125 ~88 dirt
setblock ~26 ~125 ~89 dirt
setblock ~26 ~125 ~90 dirt
setblock ~26 ~125 ~91 dirt
setblock ~26 ~125 ~92 dirt
setblock ~26 ~125 ~93 dirt
setblock ~26 ~125 ~94 dirt
setblock ~26 ~125 ~95 dirt
setblock ~26 ~125 ~96 grass_block
setblock ~26 ~125 ~97 grass_block
setblock ~26 ~125 ~98 grass_block
setblock ~26 ~125 ~99 grass_block
setblock ~26 ~125 ~100 grass_block
setblock ~26 ~125 ~101 grass_block
setblock ~26 ~125 ~102 dirt
setblock ~26 ~125 ~103 dirt
setblock ~26 ~125 ~104 dirt
setblock ~26 ~125 ~105 dirt
setblock ~26 ~125 ~106 dirt
setblock ~26 ~125 ~107 dirt
setblock ~26 ~125 ~108 dirt
setblock ~26 ~125 ~109 dirt
setblock ~26 ~125 ~110 dirt
setblock ~26 ~125 ~111 dirt
setblock ~26 ~126 ~80 grass_block
setblock ~26 ~126 ~81 grass_block
setblock ~26 ~126 ~82 grass_block
setblock ~26 ~126 ~83 grass_block
setblock ~26 ~126 ~84 grass_block
setblock ~26 ~126 ~85 grass_block
setblock ~26 ~126 ~86 grass_block
setblock ~26 ~126 ~87 grass_block
setblock ~26 ~126 ~88 grass_block
setblock ~26 ~126 ~89 grass_block
setblock ~26 ~126 ~90 grass_block
setblock ~26 ~126 ~91 grass_block
setblock ~26 ~126 ~92 grass_block
setblock ~26 ~126 ~93 grass_block
setblock ~26 ~126 ~94 grass_block
setblock ~26 ~126 ~95 grass_block
setblock ~26 ~126 ~102 grass_block
setblock ~26 ~126 ~103 grass_block
setblock ~26 ~126 ~104 grass_block
setblock ~26 ~126 ~105 grass_block
setblock ~26 ~126 ~106 dirt
setblock ~26 ~126 ~107 dirt
setblock ~26 ~126 ~108 dirt
setblock ~26 ~126 ~109 dirt
setblock ~26 ~126 ~110 dirt
setblock ~26 ~126 ~111 dirt
setblock ~26 ~127 ~82 short_grass
setblock ~26 ~127 ~87 short_grass
setblock ~26 ~127 ~88 fern
setblock ~26 ~127 ~92 fern
setblock ~26 ~127 ~93 short_grass
setblock ~26 ~127 ~106 grass_block
setblock ~26 ~127 ~107 grass_block
setblock ~26 ~127 ~108 grass_block
setblock ~26 ~127 ~109 grass_block
setblock ~26 ~127 ~110 dirt
setblock ~26 ~127 ~111 grass_block
setblock ~26 ~128 ~106 fern
setblock ~26 ~128 ~107 short_grass
setblock ~26 ~128 ~110 grass_block
setblock ~26 ~129 ~110 short_grass
setblock ~27 ~108 ~96 dirt
setblock ~27 ~108 ~99 dirt
setblock ~27 ~109 ~96 dirt
setblock ~27 ~109 ~97 dirt
setblock ~27 ~109 ~98 dirt
setblock ~27 ~109 ~99 dirt
setblock ~27 ~110 ~92 dirt
setblock ~27 ~110 ~95 dirt
setblock ~27 ~110 ~96 dirt
setblock ~27 ~110 ~97 dirt
setblock ~27 ~110 ~98 dirt
setblock ~27 ~110 ~99 dirt
setblock ~27 ~110 ~100 dirt
setblock ~27 ~110 ~102 dirt
setblock ~27 ~111 ~90 dirt
setblock ~27 ~111 ~92 dirt
setblock ~27 ~111 ~94 dirt
setblock ~27 ~111 ~95 dirt
setblock ~27 ~111 ~96 dirt
setblock ~27 ~111 ~97 dirt
setblock ~27 ~111 ~98 dirt
setblock ~27 ~111 ~99 dirt
setblock ~27 ~111 ~100 dirt
setblock ~27 ~111 ~101 dirt
setblock ~27 ~111 ~102 dirt
setblock ~27 ~111 ~103 dirt
setblock ~27 ~112 ~87 dirt
setblock ~27 ~112 ~89 dirt
setblock ~27 ~112 ~90 dirt
setblock ~27 ~112 ~92 dirt
setblock ~27 ~112 ~93 dirt
setblock ~27 ~112 ~94 dirt
setblock ~27 ~112 ~95 dirt
setblock ~27 ~112 ~96 dirt
setblock ~27 ~112 ~97 dirt
setblock ~27 ~112 ~98 dirt
setblock ~27 ~112 ~99 dirt
setblock ~27 ~112 ~100 dirt
setblock ~27 ~112 ~101 dirt
setblock ~27 ~112 ~102 dirt
setblock ~27 ~112 ~103 dirt
setblock ~27 ~113 ~85 dirt
setblock ~27 ~113 ~86 dirt
setblock ~27 ~113 ~87 dirt
setblock ~27 ~113 ~88 dirt
setblock ~27 ~113 ~89 dirt
setblock ~27 ~113 ~90 dirt
setblock ~27 ~113 ~91 dirt
setblock ~27 ~113 ~92 dirt
setblock ~27 ~113 ~93 dirt
setblock ~27 ~113 ~94 dirt
setblock ~27 ~113 ~95 dirt
setblock ~27 ~113 ~96 dirt
setblock ~27 ~113 ~97 dirt
setblock ~27 ~113 ~98 dirt
setblock ~27 ~113 ~99 dirt
setblock ~27 ~113 ~100 dirt
setblock ~27 ~113 ~101 dirt
setblock ~27 ~113 ~102 dirt
setblock ~27 ~113 ~103 dirt
setblock ~27 ~113 ~104 dirt
setblock ~27 ~113 ~105 dirt
setblock ~27 ~114 ~84 dirt
setblock ~27 ~114 ~85 dirt
setblock ~27 ~114 ~86 dirt
setblock ~27 ~114 ~87 dirt
setblock ~27 ~114 ~88 dirt
setblock ~27 ~114 ~89 dirt
setblock ~27 ~114 ~90 dirt
setblock ~27 ~114 ~91 dirt
setblock ~27 ~114 ~92 dirt
setblock ~27 ~114 ~93 dirt
setblock ~27 ~114 ~94 dirt
setblock ~27 ~114 ~95 dirt
setblock ~27 ~114 ~96 dirt
setblock ~27 ~114 ~97 dirt
setblock ~27 ~114 ~98 dirt
setblock ~27 ~114 ~99 dirt
setblock ~27 ~114 ~100 dirt
setblock ~27 ~114 ~101 dirt
setblock ~27 ~114 ~102 dirt
setblock ~27 ~114 ~103 dirt
setblock ~27 ~114 ~104 dirt
setblock ~27 ~114 ~105 dirt
setblock ~27 ~114 ~106 dirt
setblock ~27 ~114 ~107 dirt
setblock ~27 ~115 ~83 dirt
setblock ~27 ~115 ~84 dirt
setblock ~27 ~115 ~85 dirt
setblock ~27 ~115 ~86 dirt
setblock ~27 ~115 ~87 dirt
setblock ~27 ~115 ~88 dirt
setblock ~27 ~115 ~89 dirt
setblock ~27 ~115 ~90 dirt
setblock ~27 ~115 ~91 dirt
setblock ~27 ~115 ~92 dirt
setblock ~27 ~115 ~93 dirt
setblock ~27 ~115 ~94 dirt
setblock ~27 ~115 ~95 dirt
setblock ~27 ~115 ~96 dirt
setblock ~27 ~115 ~97 dirt
setblock ~27 ~115 ~98 dirt
setblock ~27 ~115 ~99 dirt
setblock ~27 ~115 ~100 dirt
setblock ~27 ~115 ~101 dirt
setblock ~27 ~115 ~102 dirt
setblock ~27 ~115 ~103 dirt
setblock ~27 ~115 ~104 dirt
setblock ~27 ~115 ~105 dirt
setblock ~27 ~115 ~106 dirt
setblock ~27 ~115 ~107 dirt
setblock ~27 ~115 ~108 dirt
setblock ~27 ~115 ~109 dirt
setblock ~27 ~116 ~83 dirt
setblock ~27 ~116 ~84 dirt
setblock ~27 ~116 ~85 dirt
setblock ~27 ~116 ~86 dirt
setblock ~27 ~116 ~87 dirt
setblock ~27 ~116 ~88 dirt
setblock ~27 ~116 ~89 dirt
setblock ~27 ~116 ~90 dirt
setblock ~27 ~116 ~91 dirt
setblock ~27 ~116 ~92 dirt
setblock ~27 ~116 ~93 dirt
setblock ~27 ~116 ~94 dirt
setblock ~27 ~116 ~95 dirt
setblock ~27 ~116 ~96 dirt
setblock ~27 ~116 ~97 dirt
setblock ~27 ~116 ~98 dirt
setblock ~27 ~116 ~99 dirt
setblock ~27 ~116 ~100 dirt
setblock ~27 ~116 ~101 dirt
setblock ~27 ~116 ~102 dirt
setblock ~27 ~116 ~103 dirt
setblock ~27 ~116 ~104 dirt
setblock ~27 ~116 ~105 dirt
setblock ~27 ~116 ~106 dirt
setblock ~27 ~116 ~107 dirt
setblock ~27 ~116 ~108 dirt
setblock ~27 ~116 ~109 dirt
setblock ~27 ~116 ~110 dirt
setblock ~27 ~117 ~83 dirt
setblock ~27 ~117 ~84 dirt
setblock ~27 ~117 ~85 dirt
setblock ~27 ~117 ~86 dirt
setblock ~27 ~117 ~87 dirt
setblock ~27 ~117 ~88 dirt
setblock ~27 ~117 ~89 dirt
setblock ~27 ~117 ~90 dirt
setblock ~27 ~117 ~91 dirt
setblock ~27 ~117 ~92 dirt
setblock ~27 ~117 ~93 dirt
setblock ~27 ~117 ~94 dirt
setblock ~27 ~117 ~95 dirt
setblock ~27 ~117 ~96 dirt
setblock ~27 ~117 ~97 dirt
setblock ~27 ~117 ~98 dirt
setblock ~27 ~117 ~99 dirt
setblock ~27 ~117 ~100 dirt
setblock ~27 ~117 ~101 dirt
setblock ~27 ~117 ~102 dirt
setblock ~27 ~117 ~103 dirt
setblock ~27 ~117 ~104 dirt
setblock ~27 ~117 ~105 dirt
setblock ~27 ~117 ~106 dirt
setblock ~27 ~117 ~107 dirt
setblock ~27 ~117 ~108 dirt
setblock ~27 ~117 ~109 dirt
setblock ~27 ~117 ~110 dirt
setblock ~27 ~117 ~111 dirt
setblock ~27 ~118 ~82 dirt
setblock ~27 ~118 ~83 dirt
setblock ~27 ~118 ~84 dirt
setblock ~27 ~118 ~85 dirt
setblock ~27 ~118 ~86 dirt
setblock ~27 ~118 ~87 dirt
setblock ~27 ~118 ~88 dirt
setblock ~27 ~118 ~89 dirt
setblock ~27 ~118 ~90 dirt
setblock ~27 ~118 ~91 dirt
setblock ~27 ~118 ~92 dirt
setblock ~27 ~118 ~93 dirt
setblock ~27 ~118 ~94 dirt
setblock ~27 ~118 ~95 dirt
setblock ~27 ~118 ~96 dirt
setblock ~27 ~118 ~97 dirt
setblock ~27 ~118 ~98 dirt
setblock ~27 ~118 ~99 dirt
setblock ~27 ~118 ~100 dirt
setblock ~27 ~118 ~101 dirt
setblock ~27 ~118 ~102 dirt
setblock ~27 ~118 ~103 dirt
setblock ~27 ~118 ~104 dirt
setblock ~27 ~118 ~105 dirt
setblock ~27 ~118 ~106 dirt
setblock ~27 ~118 ~107 dirt
setblock ~27 ~118 ~108 dirt
setblock ~27 ~118 ~109 dirt
setblock ~27 ~118 ~110 dirt
setblock ~27 ~118 ~111 dirt
setblock ~27 ~119 ~81 dirt
setblock ~27 ~119 ~82 dirt
setblock ~27 ~119 ~83 dirt
setblock ~27 ~119 ~84 dirt
setblock ~27 ~119 ~85 dirt
setblock ~27 ~119 ~86 dirt
setblock ~27 ~119 ~87 dirt
setblock ~27 ~119 ~88 dirt
setblock ~27 ~119 ~89 dirt
setblock ~27 ~119 ~90 dirt
setblock ~27 ~119 ~91 dirt
setblock ~27 ~119 ~92 dirt
setblock ~27 ~119 ~93 dirt
setblock ~27 ~119 ~94 dirt
setblock ~27 ~119 ~95 dirt
setblock ~27 ~119 ~96 dirt
setblock ~27 ~119 ~97 dirt
setblock ~27 ~119 ~98 dirt
setblock ~27 ~119 ~99 dirt
setblock ~27 ~119 ~100 dirt
setblock ~27 ~119 ~101 dirt
setblock ~27 ~119 ~102 dirt
setblock ~27 ~119 ~103 dirt
setblock ~27 ~119 ~104 dirt
setblock ~27 ~119 ~105 dirt
setblock ~27 ~119 ~106 dirt
setblock ~27 ~119 ~107 dirt
setblock ~27 ~119 ~108 dirt
setblock ~27 ~119 ~109 dirt
setblock ~27 ~119 ~110 dirt
setblock ~27 ~119 ~111 dirt
setblock ~27 ~120 ~80 dirt
setblock ~27 ~120 ~81 dirt
setblock ~27 ~120 ~82 dirt
setblock ~27 ~120 ~83 dirt
setblock ~27 ~120 ~84 dirt
setblock ~27 ~120 ~85 dirt
setblock ~27 ~120 ~86 dirt
setblock ~27 ~120 ~87 dirt
setblock ~27 ~120 ~88 dirt
setblock ~27 ~120 ~89 dirt
setblock ~27 ~120 ~90 dirt
setblock ~27 ~120 ~91 dirt
setblock ~27 ~120 ~92 dirt
setblock ~27 ~120 ~93 dirt
setblock ~27 ~120 ~94 dirt
setblock ~27 ~120 ~95 dirt
setblock ~27 ~120 ~96 dirt
setblock ~27 ~120 ~97 dirt
setblock ~27 ~120 ~98 dirt
setblock ~27 ~120 ~99 dirt
setblock ~27 ~120 ~100 dirt
setblock ~27 ~120 ~101 dirt
setblock ~27 ~120 ~102 dirt
setblock ~27 ~120 ~103 dirt
setblock ~27 ~120 ~104 dirt
setblock ~27 ~120 ~105 dirt
setblock ~27 ~120 ~106 dirt
setblock ~27 ~120 ~107 dirt
setblock ~27 ~120 ~108 dirt
setblock ~27 ~120 ~109 dirt
setblock ~27 ~120 ~110 dirt
setblock ~27 ~120 ~111 dirt
setblock ~27 ~120 ~112 dirt
setblock ~27 ~121 ~79 dirt
setblock ~27 ~121 ~80 dirt
setblock ~27 ~121 ~81 dirt
setblock ~27 ~121 ~82 dirt
setblock ~27 ~121 ~83 dirt
setblock ~27 ~121 ~84 dirt
setblock ~27 ~121 ~85 dirt
setblock ~27 ~121 ~86 dirt
setblock ~27 ~121 ~87 dirt
setblock ~27 ~121 ~88 dirt
setblock ~27 ~121 ~89 dirt
setblock ~27 ~121 ~90 dirt
setblock ~27 ~121 ~91 dirt
setblock ~27 ~121 ~92 dirt
setblock ~27 ~121 ~93 dirt
setblock ~27 ~121 ~94 dirt
setblock ~27 ~121 ~95 dirt
setblock ~27 ~121 ~96 dirt
setblock ~27 ~121 ~97 dirt
setblock ~27 ~121 ~98 dirt
setblock ~27 ~121 ~99 dirt
setblock ~27 ~121 ~100 dirt
setblock ~27 ~121 ~101 dirt
setblock ~27 ~121 ~102 dirt
setblock ~27 ~121 ~103 dirt
setblock ~27 ~121 ~104 dirt
setblock ~27 ~121 ~105 dirt
setblock ~27 ~121 ~106 dirt
setblock ~27 ~121 ~107 dirt
setblock ~27 ~121 ~108 dirt
setblock ~27 ~121 ~109 dirt
setblock ~27 ~121 ~110 dirt
setblock ~27 ~121 ~111 dirt
setblock ~27 ~121 ~112 dirt
setblock ~27 ~121 ~113 dirt
setblock ~27 ~122 ~79 dirt
setblock ~27 ~122 ~80 dirt
setblock ~27 ~122 ~81 dirt
setblock ~27 ~122 ~82 dirt
setblock ~27 ~122 ~83 dirt
setblock ~27 ~122 ~84 dirt
setblock ~27 ~122 ~85 dirt
setblock ~27 ~122 ~86 dirt
setblock ~27 ~122 ~87 dirt
setblock ~27 ~122 ~88 dirt
setblock ~27 ~122 ~89 dirt
setblock ~27 ~122 ~90 dirt
setblock ~27 ~122 ~91 dirt
setblock ~27 ~122 ~92 dirt
setblock ~27 ~122 ~93 dirt
setblock ~27 ~122 ~94 dirt
setblock ~27 ~122 ~95 dirt
setblock ~27 ~122 ~96 dirt
setblock ~27 ~122 ~97 dirt
setblock ~27 ~122 ~98 dirt
setblock ~27 ~122 ~99 dirt
setblock ~27 ~122 ~100 dirt
setblock ~27 ~122 ~101 dirt
setblock ~27 ~122 ~102 dirt
setblock ~27 ~122 ~103 dirt
setblock ~27 ~122 ~104 dirt
setblock ~27 ~122 ~105 dirt
setblock ~27 ~122 ~106 dirt
setblock ~27 ~122 ~107 dirt
setblock ~27 ~122 ~108 dirt
setblock ~27 ~122 ~109 dirt
setblock ~27 ~122 ~110 dirt
setblock ~27 ~122 ~111 dirt
setblock ~27 ~122 ~112 dirt
setblock ~27 ~122 ~113 dirt
setblock ~27 ~123 ~79 dirt
setblock ~27 ~123 ~80 dirt
setblock ~27 ~123 ~81 dirt
setblock ~27 ~123 ~82 dirt
setblock ~27 ~123 ~83 dirt
setblock ~27 ~123 ~84 dirt
setblock ~27 ~123 ~85 dirt
setblock ~27 ~123 ~86 dirt
setblock ~27 ~123 ~87 dirt
setblock ~27 ~123 ~88 dirt
setblock ~27 ~123 ~89 dirt
setblock ~27 ~123 ~90 dirt
setblock ~27 ~123 ~91 dirt
setblock ~27 ~123 ~92 dirt
setblock ~27 ~123 ~93 dirt
setblock ~27 ~123 ~94 dirt
setblock ~27 ~123 ~95 dirt
setblock ~27 ~123 ~96 dirt
setblock ~27 ~123 ~97 dirt
setblock ~27 ~123 ~98 dirt
setblock ~27 ~123 ~99 dirt
setblock ~27 ~123 ~100 dirt
setblock ~27 ~123 ~101 dirt
setblock ~27 ~123 ~102 dirt
setblock ~27 ~123 ~103 dirt
setblock ~27 ~123 ~104 dirt
setblock ~27 ~123 ~105 dirt
setblock ~27 ~123 ~106 dirt
setblock ~27 ~123 ~107 dirt
setblock ~27 ~123 ~108 dirt
setblock ~27 ~123 ~109 dirt
setblock ~27 ~123 ~110 dirt
setblock ~27 ~123 ~111 dirt
setblock ~27 ~123 ~112 dirt
setblock ~27 ~123 ~113 dirt
setblock ~27 ~124 ~79 dirt
setblock ~27 ~124 ~80 dirt
setblock ~27 ~124 ~81 dirt
setblock ~27 ~124 ~82 dirt
setblock ~27 ~124 ~83 dirt
setblock ~27 ~124 ~84 dirt
setblock ~27 ~124 ~85 dirt
setblock ~27 ~124 ~86 dirt
setblock ~27 ~124 ~87 dirt
setblock ~27 ~124 ~88 dirt
setblock ~27 ~124 ~89 dirt
setblock ~27 ~124 ~90 dirt
setblock ~27 ~124 ~91 dirt
setblock ~27 ~124 ~92 dirt
setblock ~27 ~124 ~93 dirt
setblock ~27 ~124 ~94 dirt
setblock ~27 ~124 ~95 dirt
setblock ~27 ~124 ~96 dirt
setblock ~27 ~124 ~97 dirt
setblock ~27 ~124 ~98 dirt
setblock ~27 ~124 ~99 dirt
setblock ~27 ~124 ~100 dirt
setblock ~27 ~124 ~101 dirt
setblock ~27 ~124 ~102 dirt
setblock ~27 ~124 ~103 dirt
setblock ~27 ~124 ~104 dirt
setblock ~27 ~124 ~105 dirt
setblock ~27 ~124 ~106 dirt
setblock ~27 ~124 ~107 dirt
setblock ~27 ~124 ~108 dirt
setblock ~27 ~124 ~109 dirt
setblock ~27 ~124 ~110 dirt
setblock ~27 ~124 ~111 dirt
setblock ~27 ~124 ~112 dirt
setblock ~27 ~124 ~113 dirt
setblock ~27 ~125 ~79 grass_block
setblock ~27 ~125 ~80 grass_block
setblock ~27 ~125 ~81 grass_block
setblock ~27 ~125 ~82 dirt
setblock ~27 ~125 ~83 dirt
setblock ~27 ~125 ~84 dirt
setblock ~27 ~125 ~85 dirt
setblock ~27 ~125 ~86 dirt
setblock ~27 ~125 ~87 dirt
setblock ~27 ~125 ~88 dirt
setblock ~27 ~125 ~89 dirt
setblock ~27 ~125 ~90 dirt
setblock ~27 ~125 ~91 dirt
setblock ~27 ~125 ~92 dirt
setblock ~27 ~125 ~93 dirt
setblock ~27 ~125 ~94 dirt
setblock ~27 ~125 ~95 dirt
setblock ~27 ~125 ~96 dirt
setblock ~27 ~125 ~97 dirt
setblock ~27 ~125 ~98 grass_block
setblock ~27 ~125 ~99 grass_block
setblock ~27 ~125 ~100 grass_block
setblock ~27 ~125 ~101 grass_block
setblock ~27 ~125 ~102 dirt
setblock ~27 ~125 ~103 dirt
setblock ~27 ~125 ~104 dirt
setblock ~27 ~125 ~105 dirt
setblock ~27 ~125 ~106 dirt
setblock ~27 ~125 ~107 dirt
setblock ~27 ~125 ~108 dirt
setblock ~27 ~125 ~109 dirt
setblock ~27 ~125 ~110 dirt
setblock ~27 ~125 ~111 dirt
setblock ~27 ~125 ~112 dirt
setblock ~27 ~125 ~113 dirt
setblock ~27 ~126 ~79 fern
setblock ~27 ~126 ~82 grass_block
setblock ~27 ~126 ~83 grass_block
setblock ~27 ~126 ~84 grass_block
setblock ~27 ~126 ~85 grass_block
setblock ~27 ~126 ~86 grass_block
setblock ~27 ~126 ~87 grass_block
setblock ~27 ~126 ~88 grass_block
setblock ~27 ~126 ~89 dirt
setblock ~27 ~126 ~90 dirt
setblock ~27 ~126 ~91 dirt
setblock ~27 ~126 ~92 grass_block
setblock ~27 ~126 ~93 grass_block
setblock ~27 ~126 ~94 grass_block
setblock ~27 ~126 ~95 grass_block
setblock ~27 ~126 ~96 grass_block
setblock ~27 ~126 ~97 grass_block
setblock ~27 ~126 ~100 short_grass
setblock ~27 ~126 ~102 grass_block
setblock ~27 ~126 ~103 grass_block
setblock ~27 ~126 ~104 grass_block
setblock ~27 ~126 ~105 dirt
setblock ~27 ~126 ~106 dirt
setblock ~27 ~126 ~107 dirt
setblock ~27 ~126 ~108 dirt
setblock ~27 ~126 ~109 dirt
setblock ~27 ~126 ~110 dirt
setblock ~27 ~126 ~111 dirt
setblock ~27 ~126 ~112 dirt
setblock ~27 ~126 ~113 dirt
setblock ~27 ~127 ~85 short_grass
setblock ~27 ~127 ~86 short_grass
setblock ~27 ~127 ~87 short_grass
setblock ~27 ~127 ~88 short_grass
setblock ~27 ~127 ~89 grass_block
setblock ~27 ~127 ~90 grass_block
setblock ~27 ~127 ~91 grass_block
setblock ~27 ~127 ~95 short_grass
setblock ~27 ~127 ~96 poppy
setblock ~27 ~127 ~97 short_grass
setblock ~27 ~127 ~105 grass_block
setblock ~27 ~127 ~106 grass_block
setblock ~27 ~127 ~107 grass_block
setblock ~27 ~127 ~108 grass_block
setblock ~27 ~127 ~109 dirt
setblock ~27 ~127 ~110 dirt
setblock ~27 ~127 ~111 grass_block
setblock ~27 ~127 ~112 grass_block
setblock ~27 ~127 ~113 grass_block
setblock ~27 ~128 ~90 short_grass
setblock ~27 ~128 ~91 short_grass
setblock ~27 ~128 ~106 fern
setblock ~27 ~128 ~107 short_grass
setblock ~27 ~128 ~108 fern
setblock ~27 ~128 ~109 grass_block
setblock ~27 ~128 ~110 grass_block
setblock ~28 ~104 ~99 dirt
setblock ~28 ~105 ~99 dirt
setblock ~28 ~106 ~99 dirt
setblock ~28 ~107 ~96 dirt
setblock ~28 ~107 ~99 dirt
setblock ~28 ~107 ~100 dirt
setblock ~28 ~108 ~95 dirt
setblock ~28 ~108 ~96 dirt
setblock ~28 ~108 ~97 dirt
setblock ~28 ~108 ~98 dirt
setblock ~28 ~108 ~99 dirt
setblock ~28 ~108 ~100 dirt
setblock ~28 ~108 ~101 dirt
setblock ~28 ~109 ~90 dirt
setblock ~28 ~109 ~92 dirt
setblock ~28 ~109 ~95 dirt
setblock ~28 ~109 ~96 dirt
setblock ~28 ~109 ~97 dirt
setblock ~28 ~109 ~98 dirt
setblock ~28 ~109 ~99 dirt
setblock ~28 ~109 ~100 dirt
setblock ~28 ~109 ~101 dirt
setblock ~28 ~109 ~102 dirt
setblock ~28 ~109 ~103 dirt
setblock ~28 ~110 ~86 dirt
setblock ~28 ~110 ~89 dirt
setblock ~28 ~110 ~90 dirt
setblock ~28 ~110 ~91 dirt
setblock ~28 ~110 ~92 dirt
setblock ~28 ~110 ~93 dirt
setblock ~28 ~110 ~94 dirt
setblock ~28 ~110 ~95 dirt
setblock ~28 ~110 ~96 dirt
setblock ~28 ~110 ~97 dirt
setblock ~28 ~110 ~98 dirt
setblock ~28 ~110 ~99 dirt
setblock ~28 ~110 ~100 dirt
setblock ~28 ~110 ~101 dirt
setblock ~28 ~110 ~102 dirt
setblock ~28 ~110 ~103 dirt
setblock ~28 ~111 ~86 dirt
setblock ~28 ~111 ~87 dirt
setblock ~28 ~111 ~88 dirt
setblock ~28 ~111 ~89 dirt
setblock ~28 ~111 ~90 dirt
setblock ~28 ~111 ~91 dirt
setblock ~28 ~111 ~92 dirt
setblock ~28 ~111 ~93 dirt
setblock ~28 ~111 ~94 dirt
setblock ~28 ~111 ~95 dirt
setblock ~28 ~111 ~96 dirt
setblock ~28 ~111 ~97 dirt
setblock ~28 ~111 ~98 dirt
setblock ~28 ~111 ~99 dirt
setblock ~28 ~111 ~100 dirt
setblock ~28 ~111 ~101 dirt
setblock ~28 ~111 ~102 dirt
setblock ~28 ~111 ~103 dirt
setblock ~28 ~111 ~104 dirt
setblock ~28 ~111 ~105 dirt
setblock ~28 ~112 ~85 dirt
setblock ~28 ~112 ~86 dirt
setblock ~28 ~112 ~87 dirt
setblock ~28 ~112 ~88 dirt
setblock ~28 ~112 ~89 dirt
setblock ~28 ~112 ~90 dirt
setblock ~28 ~112 ~91 dirt
setblock ~28 ~112 ~92 dirt
setblock ~28 ~112 ~93 dirt
setblock ~28 ~112 ~94 dirt
setblock ~28 ~112 ~95 dirt
setblock ~28 ~112 ~96 dirt
setblock ~28 ~112 ~97 dirt
setblock ~28 ~112 ~98 dirt
setblock ~28 ~112 ~99 dirt
setblock ~28 ~112 ~100 dirt
setblock ~28 ~112 ~101 dirt
setblock ~28 ~112 ~102 dirt
setblock ~28 ~112 ~103 dirt
setblock ~28 ~112 ~104 dirt
setblock ~28 ~112 ~105 dirt
setblock ~28 ~113 ~84 dirt
setblock ~28 ~113 ~85 dirt
setblock ~28 ~113 ~86 dirt
setblock ~28 ~113 ~87 dirt
setblock ~28 ~113 ~88 dirt
setblock ~28 ~113 ~89 dirt
setblock ~28 ~113 ~90 dirt
setblock ~28 ~113 ~91 dirt
setblock ~28 ~113 ~92 dirt
setblock ~28 ~113 ~93 dirt
setblock ~28 ~113 ~94 dirt
setblock ~28 ~113 ~95 dirt
setblock ~28 ~113 ~96 dirt
setblock ~28 ~113 ~97 dirt
setblock ~28 ~113 ~98 dirt
setblock ~28 ~113 ~99 dirt
setblock ~28 ~113 ~100 dirt
setblock ~28 ~113 ~101 dirt
setblock ~28 ~113 ~102 dirt
setblock ~28 ~113 ~103 dirt
setblock ~28 ~113 ~104 dirt
setblock ~28 ~113 ~105 dirt
setblock ~28 ~113 ~106 dirt
setblock ~28 ~113 ~107 dirt
setblock ~28 ~113 ~109 dirt
setblock ~28 ~114 ~83 dirt
setblock ~28 ~114 ~84 dirt
setblock ~28 ~114 ~85 dirt
setblock ~28 ~114 ~86 dirt
setblock ~28 ~114 ~87 dirt
setblock ~28 ~114 ~88 dirt
setblock ~28 ~114 ~89 dirt
setblock ~28 ~114 ~90 dirt
setblock ~28 ~114 ~91 dirt
setblock ~28 ~114 ~92 dirt
setblock ~28 ~114 ~93 dirt
setblock ~28 ~114 ~94 dirt
setblock ~28 ~114 ~95 dirt
setblock ~28 ~114 ~96 dirt
setblock ~28 ~114 ~97 dirt
setblock ~28 ~114 ~98 dirt
setblock ~28 ~114 ~99 dirt
setblock ~28 ~114 ~100 dirt
setblock ~28 ~114 ~101 dirt
setblock ~28 ~114 ~102 dirt
setblock ~28 ~114 ~103 dirt
setblock ~28 ~114 ~104 dirt
setblock ~28 ~114 ~105 dirt
setblock ~28 ~114 ~106 dirt
setblock ~28 ~114 ~107 dirt
setblock ~28 ~114 ~108 dirt
setblock ~28 ~114 ~109 dirt
setblock ~28 ~115 ~82 dirt
setblock ~28 ~115 ~83 dirt
setblock ~28 ~115 ~84 dirt
setblock ~28 ~115 ~85 dirt
setblock ~28 ~115 ~86 dirt
setblock ~28 ~115 ~87 dirt
setblock ~28 ~115 ~88 dirt
setblock ~28 ~115 ~89 dirt
setblock ~28 ~115 ~90 dirt
setblock ~28 ~115 ~91 dirt
setblock ~28 ~115 ~92 dirt
setblock ~28 ~115 ~93 dirt
setblock ~28 ~115 ~94 dirt
setblock ~28 ~115 ~95 dirt
setblock ~28 ~115 ~96 dirt
setblock ~28 ~115 ~97 dirt
setblock ~28 ~115 ~98 dirt
setblock ~28 ~115 ~99 dirt
setblock ~28 ~115 ~100 dirt
setblock ~28 ~115 ~101 dirt
setblock ~28 ~115 ~102 dirt
setblock ~28 ~115 ~103 dirt
setblock ~28 ~115 ~104 dirt
setblock ~28 ~115 ~105 dirt
setblock ~28 ~115 ~106 dirt
setblock ~28 ~115 ~107 dirt
setblock ~28 ~115 ~108 dirt
setblock ~28 ~115 ~109 dirt
setblock ~28 ~115 ~110 dirt
setblock ~28 ~116 ~82 dirt
setblock ~28 ~116 ~83 dirt
setblock ~28 ~116 ~84 dirt
setblock ~28 ~116 ~85 dirt
setblock ~28 ~116 ~86 dirt
setblock ~28 ~116 ~87 dirt
setblock ~28 ~116 ~88 dirt
setblock ~28 ~116 ~89 dirt
setblock ~28 ~116 ~90 dirt
setblock ~28 ~116 ~91 dirt
setblock ~28 ~116 ~92 dirt
setblock ~28 ~116 ~93 dirt
setblock ~28 ~116 ~94 dirt
setblock ~28 ~116 ~95 dirt
setblock ~28 ~116 ~96 dirt
setblock ~28 ~116 ~97 dirt
setblock ~28 ~116 ~98 dirt
setblock ~28 ~116 ~99 dirt
setblock ~28 ~116 ~100 dirt
setblock ~28 ~116 ~101 dirt
setblock ~28 ~116 ~102 dirt
setblock ~28 ~116 ~103 dirt
setblock ~28 ~116 ~104 dirt
setblock ~28 ~116 ~105 dirt
setblock ~28 ~116 ~106 dirt
setblock ~28 ~116 ~107 dirt
setblock ~28 ~116 ~108 dirt
setblock ~28 ~116 ~109 dirt
setblock ~28 ~116 ~110 dirt
setblock ~28 ~117 ~82 dirt
setblock ~28 ~117 ~83 dirt
setblock ~28 ~117 ~84 dirt
setblock ~28 ~117 ~85 dirt
setblock ~28 ~117 ~86 dirt
setblock ~28 ~117 ~87 dirt
