setblock ~182 ~118 ~128 dirt
setblock ~182 ~118 ~131 dirt
setblock ~182 ~119 ~67 dirt
setblock ~182 ~119 ~68 dirt
setblock ~182 ~119 ~69 dirt
setblock ~182 ~119 ~70 dirt
setblock ~182 ~119 ~71 dirt
setblock ~182 ~119 ~72 dirt
setblock ~182 ~119 ~73 dirt
setblock ~182 ~119 ~74 dirt
setblock ~182 ~119 ~75 dirt
setblock ~182 ~119 ~76 dirt
setblock ~182 ~119 ~77 dirt
setblock ~182 ~119 ~79 dirt
setblock ~182 ~119 ~80 dirt
setblock ~182 ~119 ~81 dirt
setblock ~182 ~119 ~82 dirt
setblock ~182 ~119 ~83 dirt
setblock ~182 ~119 ~84 dirt
setblock ~182 ~119 ~85 dirt
setblock ~182 ~119 ~86 dirt
setblock ~182 ~119 ~87 dirt
setblock ~182 ~119 ~88 dirt
setblock ~182 ~119 ~89 dirt
setblock ~182 ~119 ~90 dirt
setblock ~182 ~119 ~91 dirt
setblock ~182 ~119 ~92 dirt
setblock ~182 ~119 ~93 dirt
setblock ~182 ~119 ~94 dirt
setblock ~182 ~119 ~95 dirt
setblock ~182 ~119 ~96 dirt
setblock ~182 ~119 ~97 dirt
setblock ~182 ~119 ~98 dirt
setblock ~182 ~119 ~99 dirt
setblock ~182 ~119 ~100 dirt
setblock ~182 ~119 ~101 dirt
setblock ~182 ~119 ~102 dirt
setblock ~182 ~119 ~108 dirt
setblock ~182 ~119 ~109 dirt
setblock ~182 ~119 ~110 dirt
setblock ~182 ~119 ~111 dirt
setblock ~182 ~119 ~112 dirt
setblock ~182 ~119 ~113 dirt
setblock ~182 ~119 ~114 dirt
setblock ~182 ~119 ~115 dirt
setblock ~182 ~119 ~116 dirt
setblock ~182 ~119 ~117 dirt
setblock ~182 ~119 ~118 dirt
setblock ~182 ~119 ~119 dirt
setblock ~182 ~119 ~120 dirt
setblock ~182 ~119 ~121 dirt
setblock ~182 ~119 ~122 dirt
setblock ~182 ~119 ~123 dirt
setblock ~182 ~119 ~124 dirt
setblock ~182 ~119 ~125 dirt
setblock ~182 ~119 ~126 dirt
setblock ~182 ~119 ~127 dirt
setblock ~182 ~119 ~128 dirt
setblock ~182 ~119 ~129 dirt
setblock ~182 ~119 ~130 dirt
setblock ~182 ~119 ~131 dirt
setblock ~182 ~119 ~132 dirt
setblock ~182 ~120 ~66 dirt
setblock ~182 ~120 ~67 dirt
setblock ~182 ~120 ~68 dirt
setblock ~182 ~120 ~69 dirt
setblock ~182 ~120 ~70 dirt
setblock ~182 ~120 ~71 dirt
setblock ~182 ~120 ~72 dirt
setblock ~182 ~120 ~73 dirt
setblock ~182 ~120 ~74 dirt
setblock ~182 ~120 ~75 dirt
setblock ~182 ~120 ~76 dirt
setblock ~182 ~120 ~77 dirt
setblock ~182 ~120 ~78 dirt
setblock ~182 ~120 ~79 dirt
setblock ~182 ~120 ~80 dirt
setblock ~182 ~120 ~81 dirt
setblock ~182 ~120 ~82 dirt
setblock ~182 ~120 ~83 dirt
setblock ~182 ~120 ~84 dirt
setblock ~182 ~120 ~85 dirt
setblock ~182 ~120 ~86 dirt
setblock ~182 ~120 ~87 dirt
setblock ~182 ~120 ~88 dirt
setblock ~182 ~120 ~89 dirt
setblock ~182 ~120 ~90 dirt
setblock ~182 ~120 ~91 dirt
setblock ~182 ~120 ~92 dirt
setblock ~182 ~120 ~93 dirt
setblock ~182 ~120 ~94 dirt
setblock ~182 ~120 ~95 dirt
setblock ~182 ~120 ~96 dirt
setblock ~182 ~120 ~97 dirt
setblock ~182 ~120 ~98 dirt
setblock ~182 ~120 ~99 dirt
setblock ~182 ~120 ~100 dirt
setblock ~182 ~120 ~101 dirt
setblock ~182 ~120 ~102 dirt
setblock ~182 ~120 ~107 dirt
setblock ~182 ~120 ~108 dirt
setblock ~182 ~120 ~109 dirt
setblock ~182 ~120 ~110 dirt
setblock ~182 ~120 ~111 dirt
setblock ~182 ~120 ~112 dirt
setblock ~182 ~120 ~113 dirt
setblock ~182 ~120 ~114 dirt
setblock ~182 ~120 ~115 dirt
setblock ~182 ~120 ~116 dirt
setblock ~182 ~120 ~117 dirt
setblock ~182 ~120 ~118 dirt
setblock ~182 ~120 ~119 dirt
setblock ~182 ~120 ~120 dirt
setblock ~182 ~120 ~121 dirt
setblock ~182 ~120 ~122 dirt
setblock ~182 ~120 ~123 dirt
setblock ~182 ~120 ~124 dirt
setblock ~182 ~120 ~125 dirt
setblock ~182 ~120 ~126 dirt
setblock ~182 ~120 ~127 dirt
setblock ~182 ~120 ~128 dirt
setblock ~182 ~120 ~129 dirt
setblock ~182 ~120 ~130 dirt
setblock ~182 ~120 ~131 dirt
setblock ~182 ~120 ~132 dirt
setblock ~182 ~120 ~133 dirt
setblock ~182 ~121 ~65 dirt
setblock ~182 ~121 ~66 dirt
setblock ~182 ~121 ~67 dirt
setblock ~182 ~121 ~68 dirt
setblock ~182 ~121 ~69 dirt
setblock ~182 ~121 ~70 dirt
setblock ~182 ~121 ~71 dirt
setblock ~182 ~121 ~72 dirt
setblock ~182 ~121 ~73 dirt
setblock ~182 ~121 ~74 dirt
setblock ~182 ~121 ~75 dirt
setblock ~182 ~121 ~76 dirt
setblock ~182 ~121 ~77 dirt
setblock ~182 ~121 ~78 dirt
setblock ~182 ~121 ~79 dirt
setblock ~182 ~121 ~80 dirt
setblock ~182 ~121 ~81 dirt
setblock ~182 ~121 ~82 dirt
setblock ~182 ~121 ~83 dirt
setblock ~182 ~121 ~84 dirt
setblock ~182 ~121 ~85 dirt
setblock ~182 ~121 ~86 dirt
setblock ~182 ~121 ~87 dirt
setblock ~182 ~121 ~88 dirt
setblock ~182 ~121 ~89 dirt
setblock ~182 ~121 ~90 dirt
setblock ~182 ~121 ~91 dirt
setblock ~182 ~121 ~92 dirt
setblock ~182 ~121 ~93 dirt
setblock ~182 ~121 ~94 dirt
setblock ~182 ~121 ~95 dirt
setblock ~182 ~121 ~96 dirt
setblock ~182 ~121 ~97 dirt
setblock ~182 ~121 ~98 dirt
setblock ~182 ~121 ~99 dirt
setblock ~182 ~121 ~100 dirt
setblock ~182 ~121 ~101 dirt
setblock ~182 ~121 ~102 dirt
setblock ~182 ~121 ~103 dirt
setblock ~182 ~121 ~106 dirt
setblock ~182 ~121 ~107 dirt
setblock ~182 ~121 ~108 dirt
setblock ~182 ~121 ~109 dirt
setblock ~182 ~121 ~110 dirt
setblock ~182 ~121 ~111 dirt
setblock ~182 ~121 ~112 dirt
setblock ~182 ~121 ~113 dirt
setblock ~182 ~121 ~114 dirt
setblock ~182 ~121 ~115 dirt
setblock ~182 ~121 ~116 dirt
setblock ~182 ~121 ~117 dirt
setblock ~182 ~121 ~118 dirt
setblock ~182 ~121 ~119 dirt
setblock ~182 ~121 ~120 dirt
setblock ~182 ~121 ~121 dirt
setblock ~182 ~121 ~122 dirt
setblock ~182 ~121 ~123 dirt
setblock ~182 ~121 ~124 dirt
setblock ~182 ~121 ~125 dirt
setblock ~182 ~121 ~126 dirt
setblock ~182 ~121 ~127 dirt
setblock ~182 ~121 ~128 dirt
setblock ~182 ~121 ~129 dirt
setblock ~182 ~121 ~130 dirt
setblock ~182 ~121 ~131 dirt
setblock ~182 ~121 ~132 dirt
setblock ~182 ~121 ~133 dirt
setblock ~182 ~121 ~134 dirt
setblock ~182 ~122 ~65 dirt
setblock ~182 ~122 ~66 dirt
setblock ~182 ~122 ~67 dirt
setblock ~182 ~122 ~68 dirt
setblock ~182 ~122 ~69 dirt
setblock ~182 ~122 ~70 dirt
setblock ~182 ~122 ~71 dirt
setblock ~182 ~122 ~72 dirt
setblock ~182 ~122 ~73 dirt
setblock ~182 ~122 ~74 dirt
setblock ~182 ~122 ~75 dirt
setblock ~182 ~122 ~76 dirt
setblock ~182 ~122 ~77 dirt
setblock ~182 ~122 ~78 dirt
setblock ~182 ~122 ~79 dirt
setblock ~182 ~122 ~80 dirt
setblock ~182 ~122 ~81 dirt
setblock ~182 ~122 ~82 dirt
setblock ~182 ~122 ~83 dirt
setblock ~182 ~122 ~84 dirt
setblock ~182 ~122 ~85 dirt
setblock ~182 ~122 ~86 dirt
setblock ~182 ~122 ~87 dirt
setblock ~182 ~122 ~88 grass_block
setblock ~182 ~122 ~89 grass_block
setblock ~182 ~122 ~90 grass_block
setblock ~182 ~122 ~91 grass_block
setblock ~182 ~122 ~92 grass_block
setblock ~182 ~122 ~93 dirt
setblock ~182 ~122 ~94 dirt
setblock ~182 ~122 ~95 dirt
setblock ~182 ~122 ~96 dirt
setblock ~182 ~122 ~97 dirt
setblock ~182 ~122 ~98 dirt
setblock ~182 ~122 ~99 dirt
setblock ~182 ~122 ~100 dirt
setblock ~182 ~122 ~101 dirt
setblock ~182 ~122 ~102 dirt
setblock ~182 ~122 ~103 dirt
setblock ~182 ~122 ~106 dirt
setblock ~182 ~122 ~107 dirt
setblock ~182 ~122 ~108 dirt
setblock ~182 ~122 ~109 dirt
setblock ~182 ~122 ~110 dirt
setblock ~182 ~122 ~111 dirt
setblock ~182 ~122 ~112 dirt
setblock ~182 ~122 ~113 dirt
setblock ~182 ~122 ~114 dirt
setblock ~182 ~122 ~115 dirt
setblock ~182 ~122 ~116 dirt
setblock ~182 ~122 ~117 dirt
setblock ~182 ~122 ~118 dirt
setblock ~182 ~122 ~119 dirt
setblock ~182 ~122 ~120 dirt
setblock ~182 ~122 ~121 dirt
setblock ~182 ~122 ~122 dirt
setblock ~182 ~122 ~123 dirt
setblock ~182 ~122 ~124 dirt
setblock ~182 ~122 ~125 dirt
setblock ~182 ~122 ~126 dirt
setblock ~182 ~122 ~127 dirt
setblock ~182 ~122 ~128 dirt
setblock ~182 ~122 ~129 dirt
setblock ~182 ~122 ~130 dirt
setblock ~182 ~122 ~131 dirt
setblock ~182 ~122 ~132 dirt
setblock ~182 ~122 ~133 dirt
setblock ~182 ~122 ~134 dirt
setblock ~182 ~123 ~65 dirt
setblock ~182 ~123 ~66 dirt
setblock ~182 ~123 ~67 dirt
setblock ~182 ~123 ~68 dirt
setblock ~182 ~123 ~69 dirt
setblock ~182 ~123 ~70 dirt
setblock ~182 ~123 ~71 dirt
setblock ~182 ~123 ~72 dirt
setblock ~182 ~123 ~73 dirt
setblock ~182 ~123 ~74 dirt
setblock ~182 ~123 ~75 dirt
setblock ~182 ~123 ~76 dirt
setblock ~182 ~123 ~77 dirt
setblock ~182 ~123 ~78 dirt
setblock ~182 ~123 ~79 dirt
setblock ~182 ~123 ~80 dirt
setblock ~182 ~123 ~81 dirt
setblock ~182 ~123 ~82 dirt
setblock ~182 ~123 ~83 dirt
setblock ~182 ~123 ~84 grass_block
setblock ~182 ~123 ~85 grass_block
setblock ~182 ~123 ~86 grass_block
setblock ~182 ~123 ~87 grass_block
setblock ~182 ~123 ~93 grass_block
setblock ~182 ~123 ~94 grass_block
setblock ~182 ~123 ~95 grass_block
setblock ~182 ~123 ~96 dirt
setblock ~182 ~123 ~97 dirt
setblock ~182 ~123 ~98 dirt
setblock ~182 ~123 ~99 dirt
setblock ~182 ~123 ~100 dirt
setblock ~182 ~123 ~101 dirt
setblock ~182 ~123 ~102 dirt
setblock ~182 ~123 ~103 dirt
setblock ~182 ~123 ~106 dirt
setblock ~182 ~123 ~107 dirt
setblock ~182 ~123 ~108 dirt
setblock ~182 ~123 ~109 grass_block
setblock ~182 ~123 ~110 grass_block
setblock ~182 ~123 ~111 grass_block
setblock ~182 ~123 ~112 dirt
setblock ~182 ~123 ~113 dirt
setblock ~182 ~123 ~114 dirt
setblock ~182 ~123 ~115 dirt
setblock ~182 ~123 ~116 dirt
setblock ~182 ~123 ~117 dirt
setblock ~182 ~123 ~118 dirt
setblock ~182 ~123 ~119 dirt
setblock ~182 ~123 ~120 dirt
setblock ~182 ~123 ~121 dirt
setblock ~182 ~123 ~122 dirt
setblock ~182 ~123 ~123 dirt
setblock ~182 ~123 ~124 dirt
setblock ~182 ~123 ~125 dirt
setblock ~182 ~123 ~126 dirt
setblock ~182 ~123 ~127 dirt
setblock ~182 ~123 ~128 dirt
setblock ~182 ~123 ~129 dirt
setblock ~182 ~123 ~130 dirt
setblock ~182 ~123 ~131 dirt
setblock ~182 ~123 ~132 dirt
setblock ~182 ~123 ~133 dirt
setblock ~182 ~123 ~134 dirt
setblock ~182 ~124 ~65 dirt
setblock ~182 ~124 ~66 dirt
setblock ~182 ~124 ~67 dirt
setblock ~182 ~124 ~68 dirt
setblock ~182 ~124 ~69 grass_block
setblock ~182 ~124 ~70 grass_block
setblock ~182 ~124 ~71 grass_block
setblock ~182 ~124 ~72 grass_block
setblock ~182 ~124 ~73 grass_block
setblock ~182 ~124 ~74 grass_block
setblock ~182 ~124 ~75 dirt
setblock ~182 ~124 ~76 dirt
setblock ~182 ~124 ~77 dirt
setblock ~182 ~124 ~78 dirt
setblock ~182 ~124 ~79 dirt
setblock ~182 ~124 ~80 dirt
setblock ~182 ~124 ~81 grass_block
setblock ~182 ~124 ~82 grass_block
setblock ~182 ~124 ~83 grass_block
setblock ~182 ~124 ~84 short_grass
setblock ~182 ~124 ~85 short_grass
setblock ~182 ~124 ~93 short_grass
setblock ~182 ~124 ~96 grass_block
setblock ~182 ~124 ~97 grass_block
setblock ~182 ~124 ~98 dirt
setblock ~182 ~124 ~99 dirt
setblock ~182 ~124 ~100 dirt
setblock ~182 ~124 ~101 dirt
setblock ~182 ~124 ~102 dirt
setblock ~182 ~124 ~103 dirt
setblock ~182 ~124 ~106 grass_block
setblock ~182 ~124 ~107 grass_block
setblock ~182 ~124 ~108 grass_block
setblock ~182 ~124 ~112 grass_block
setblock ~182 ~124 ~113 grass_block
setblock ~182 ~124 ~114 grass_block
setblock ~182 ~124 ~115 grass_block
setblock ~182 ~124 ~116 grass_block
setblock ~182 ~124 ~117 grass_block
setblock ~182 ~124 ~118 dirt
setblock ~182 ~124 ~119 dirt
setblock ~182 ~124 ~120 dirt
setblock ~182 ~124 ~121 dirt
setblock ~182 ~124 ~122 dirt
setblock ~182 ~124 ~123 dirt
setblock ~182 ~124 ~124 grass_block
setblock ~182 ~124 ~125 grass_block
setblock ~182 ~124 ~126 grass_block
setblock ~182 ~124 ~127 grass_block
setblock ~182 ~124 ~128 grass_block
setblock ~182 ~124 ~129 grass_block
setblock ~182 ~124 ~130 grass_block
setblock ~182 ~124 ~131 grass_block
setblock ~182 ~124 ~132 grass_block
setblock ~182 ~124 ~133 dirt
setblock ~182 ~124 ~134 dirt
setblock ~182 ~125 ~65 grass_block
setblock ~182 ~125 ~66 grass_block
setblock ~182 ~125 ~67 grass_block
setblock ~182 ~125 ~68 grass_block
setblock ~182 ~125 ~75 grass_block
setblock ~182 ~125 ~76 grass_block
setblock ~182 ~125 ~77 grass_block
setblock ~182 ~125 ~78 grass_block
setblock ~182 ~125 ~79 grass_block
setblock ~182 ~125 ~80 grass_block
setblock ~182 ~125 ~96 short_grass
setblock ~182 ~125 ~97 short_grass
setblock ~182 ~125 ~98 grass_block
setblock ~182 ~125 ~99 dirt
setblock ~182 ~125 ~100 dirt
setblock ~182 ~125 ~101 dirt
setblock ~182 ~125 ~102 grass_block
setblock ~182 ~125 ~103 grass_block
setblock ~182 ~125 ~108 poppy
setblock ~182 ~125 ~118 grass_block
setblock ~182 ~125 ~119 grass_block
setblock ~182 ~125 ~120 grass_block
setblock ~182 ~125 ~121 grass_block
setblock ~182 ~125 ~122 grass_block
setblock ~182 ~125 ~123 grass_block
setblock ~182 ~125 ~124 poppy
setblock ~182 ~125 ~130 short_grass
setblock ~182 ~125 ~133 grass_block
setblock ~182 ~125 ~134 grass_block
setblock ~182 ~126 ~65 short_grass
setblock ~182 ~126 ~66 short_grass
setblock ~182 ~126 ~98 short_grass
setblock ~182 ~126 ~99 grass_block
setblock ~182 ~126 ~100 grass_block
setblock ~182 ~126 ~101 grass_block
setblock ~182 ~126 ~118 short_grass
setblock ~182 ~126 ~119 poppy
setblock ~182 ~126 ~121 short_grass
setblock ~182 ~126 ~133 short_grass
setblock ~183 ~107 ~90 dirt
setblock ~183 ~108 ~89 dirt
setblock ~183 ~108 ~90 dirt
setblock ~183 ~108 ~91 dirt
setblock ~183 ~109 ~88 dirt
setblock ~183 ~109 ~89 dirt
setblock ~183 ~109 ~90 dirt
setblock ~183 ~109 ~91 dirt
setblock ~183 ~109 ~92 dirt
setblock ~183 ~109 ~117 dirt
setblock ~183 ~110 ~87 dirt
setblock ~183 ~110 ~88 dirt
setblock ~183 ~110 ~89 dirt
setblock ~183 ~110 ~90 dirt
setblock ~183 ~110 ~91 dirt
setblock ~183 ~110 ~92 dirt
setblock ~183 ~110 ~116 dirt
setblock ~183 ~110 ~117 dirt
setblock ~183 ~110 ~118 dirt
setblock ~183 ~111 ~86 dirt
setblock ~183 ~111 ~87 dirt
setblock ~183 ~111 ~88 dirt
setblock ~183 ~111 ~89 dirt
setblock ~183 ~111 ~90 dirt
setblock ~183 ~111 ~91 dirt
setblock ~183 ~111 ~92 dirt
setblock ~183 ~111 ~93 dirt
setblock ~183 ~111 ~115 dirt
setblock ~183 ~111 ~116 dirt
setblock ~183 ~111 ~117 dirt
setblock ~183 ~111 ~118 dirt
setblock ~183 ~111 ~119 dirt
setblock ~183 ~111 ~120 dirt
setblock ~183 ~112 ~85 dirt
setblock ~183 ~112 ~86 dirt
setblock ~183 ~112 ~87 dirt
setblock ~183 ~112 ~88 dirt
setblock ~183 ~112 ~89 dirt
setblock ~183 ~112 ~90 dirt
setblock ~183 ~112 ~91 dirt
setblock ~183 ~112 ~92 dirt
setblock ~183 ~112 ~93 dirt
setblock ~183 ~112 ~94 dirt
setblock ~183 ~112 ~115 dirt
setblock ~183 ~112 ~116 dirt
setblock ~183 ~112 ~117 dirt
setblock ~183 ~112 ~118 dirt
setblock ~183 ~112 ~119 dirt
setblock ~183 ~112 ~120 dirt
setblock ~183 ~112 ~121 dirt
setblock ~183 ~112 ~122 dirt
setblock ~183 ~113 ~84 dirt
setblock ~183 ~113 ~85 dirt
setblock ~183 ~113 ~86 dirt
setblock ~183 ~113 ~87 dirt
setblock ~183 ~113 ~88 dirt
setblock ~183 ~113 ~89 dirt
setblock ~183 ~113 ~90 dirt
setblock ~183 ~113 ~91 dirt
setblock ~183 ~113 ~92 dirt
setblock ~183 ~113 ~93 dirt
setblock ~183 ~113 ~94 dirt
setblock ~183 ~113 ~95 dirt
setblock ~183 ~113 ~114 dirt
setblock ~183 ~113 ~115 dirt
setblock ~183 ~113 ~116 dirt
setblock ~183 ~113 ~117 dirt
setblock ~183 ~113 ~118 dirt
setblock ~183 ~113 ~119 dirt
setblock ~183 ~113 ~120 dirt
setblock ~183 ~113 ~121 dirt
setblock ~183 ~113 ~122 dirt
setblock ~183 ~113 ~123 dirt
setblock ~183 ~114 ~83 dirt
setblock ~183 ~114 ~84 dirt
setblock ~183 ~114 ~85 dirt
setblock ~183 ~114 ~86 dirt
setblock ~183 ~114 ~87 dirt
setblock ~183 ~114 ~88 dirt
setblock ~183 ~114 ~89 dirt
setblock ~183 ~114 ~90 dirt
setblock ~183 ~114 ~91 dirt
setblock ~183 ~114 ~92 dirt
setblock ~183 ~114 ~93 dirt
setblock ~183 ~114 ~94 dirt
setblock ~183 ~114 ~95 dirt
setblock ~183 ~114 ~96 dirt
setblock ~183 ~114 ~113 dirt
setblock ~183 ~114 ~114 dirt
setblock ~183 ~114 ~115 dirt
setblock ~183 ~114 ~116 dirt
setblock ~183 ~114 ~117 dirt
setblock ~183 ~114 ~118 dirt
setblock ~183 ~114 ~119 dirt
setblock ~183 ~114 ~120 dirt
setblock ~183 ~114 ~121 dirt
setblock ~183 ~114 ~122 dirt
setblock ~183 ~114 ~123 dirt
setblock ~183 ~114 ~124 dirt
setblock ~183 ~115 ~82 dirt
setblock ~183 ~115 ~83 dirt
setblock ~183 ~115 ~84 dirt
setblock ~183 ~115 ~85 dirt
setblock ~183 ~115 ~86 dirt
setblock ~183 ~115 ~87 dirt
setblock ~183 ~115 ~88 dirt
setblock ~183 ~115 ~89 dirt
setblock ~183 ~115 ~90 dirt
setblock ~183 ~115 ~91 dirt
setblock ~183 ~115 ~92 dirt
setblock ~183 ~115 ~93 dirt
setblock ~183 ~115 ~94 dirt
setblock ~183 ~115 ~95 dirt
setblock ~183 ~115 ~96 dirt
setblock ~183 ~115 ~97 dirt
setblock ~183 ~115 ~112 dirt
setblock ~183 ~115 ~113 dirt
setblock ~183 ~115 ~114 dirt
setblock ~183 ~115 ~115 dirt
setblock ~183 ~115 ~116 dirt
setblock ~183 ~115 ~117 dirt
setblock ~183 ~115 ~118 dirt
setblock ~183 ~115 ~119 dirt
setblock ~183 ~115 ~120 dirt
setblock ~183 ~115 ~121 dirt
setblock ~183 ~115 ~122 dirt
setblock ~183 ~115 ~123 dirt
setblock ~183 ~115 ~124 dirt
setblock ~183 ~116 ~81 dirt
setblock ~183 ~116 ~82 dirt
setblock ~183 ~116 ~83 dirt
setblock ~183 ~116 ~84 dirt
setblock ~183 ~116 ~85 dirt
setblock ~183 ~116 ~86 dirt
setblock ~183 ~116 ~87 dirt
setblock ~183 ~116 ~88 dirt
setblock ~183 ~116 ~89 dirt
setblock ~183 ~116 ~90 dirt
setblock ~183 ~116 ~91 dirt
setblock ~183 ~116 ~92 dirt
setblock ~183 ~116 ~93 dirt
setblock ~183 ~116 ~94 dirt
setblock ~183 ~116 ~95 dirt
setblock ~183 ~116 ~96 dirt
setblock ~183 ~116 ~97 dirt
setblock ~183 ~116 ~98 dirt
setblock ~183 ~116 ~111 dirt
setblock ~183 ~116 ~112 dirt
setblock ~183 ~116 ~113 dirt
setblock ~183 ~116 ~114 dirt
setblock ~183 ~116 ~115 dirt
setblock ~183 ~116 ~116 dirt
setblock ~183 ~116 ~117 dirt
setblock ~183 ~116 ~118 dirt
setblock ~183 ~116 ~119 dirt
setblock ~183 ~116 ~120 dirt
setblock ~183 ~116 ~121 dirt
setblock ~183 ~116 ~122 dirt
setblock ~183 ~116 ~123 dirt
setblock ~183 ~116 ~124 dirt
setblock ~183 ~116 ~125 dirt
setblock ~183 ~117 ~71 dirt
setblock ~183 ~117 ~72 dirt
setblock ~183 ~117 ~73 dirt
setblock ~183 ~117 ~81 dirt
setblock ~183 ~117 ~82 dirt
setblock ~183 ~117 ~83 dirt
setblock ~183 ~117 ~84 dirt
setblock ~183 ~117 ~85 dirt
setblock ~183 ~117 ~86 dirt
setblock ~183 ~117 ~87 dirt
setblock ~183 ~117 ~88 dirt
setblock ~183 ~117 ~89 dirt
setblock ~183 ~117 ~90 dirt
setblock ~183 ~117 ~91 dirt
setblock ~183 ~117 ~92 dirt
setblock ~183 ~117 ~93 dirt
setblock ~183 ~117 ~94 dirt
setblock ~183 ~117 ~95 dirt
setblock ~183 ~117 ~96 dirt
setblock ~183 ~117 ~97 dirt
setblock ~183 ~117 ~98 dirt
setblock ~183 ~117 ~99 dirt
setblock ~183 ~117 ~110 dirt
setblock ~183 ~117 ~111 dirt
setblock ~183 ~117 ~112 dirt
setblock ~183 ~117 ~113 dirt
setblock ~183 ~117 ~114 dirt
setblock ~183 ~117 ~115 dirt
setblock ~183 ~117 ~116 dirt
setblock ~183 ~117 ~117 dirt
setblock ~183 ~117 ~118 dirt
setblock ~183 ~117 ~119 dirt
setblock ~183 ~117 ~120 dirt
setblock ~183 ~117 ~121 dirt
setblock ~183 ~117 ~122 dirt
setblock ~183 ~117 ~123 dirt
setblock ~183 ~117 ~124 dirt
setblock ~183 ~117 ~125 dirt
setblock ~183 ~117 ~126 dirt
setblock ~183 ~118 ~69 dirt
setblock ~183 ~118 ~70 dirt
setblock ~183 ~118 ~71 dirt
setblock ~183 ~118 ~72 dirt
setblock ~183 ~118 ~73 dirt
setblock ~183 ~118 ~74 dirt
setblock ~183 ~118 ~80 dirt
setblock ~183 ~118 ~81 dirt
setblock ~183 ~118 ~82 dirt
setblock ~183 ~118 ~83 dirt
setblock ~183 ~118 ~84 dirt
setblock ~183 ~118 ~85 dirt
setblock ~183 ~118 ~86 dirt
setblock ~183 ~118 ~87 dirt
setblock ~183 ~118 ~88 dirt
setblock ~183 ~118 ~89 dirt
setblock ~183 ~118 ~90 dirt
setblock ~183 ~118 ~91 dirt
setblock ~183 ~118 ~92 dirt
setblock ~183 ~118 ~93 dirt
setblock ~183 ~118 ~94 dirt
setblock ~183 ~118 ~95 dirt
setblock ~183 ~118 ~96 dirt
setblock ~183 ~118 ~97 dirt
setblock ~183 ~118 ~98 dirt
setblock ~183 ~118 ~99 dirt
setblock ~183 ~118 ~100 dirt
setblock ~183 ~118 ~109 dirt
setblock ~183 ~118 ~110 dirt
setblock ~183 ~118 ~111 dirt
setblock ~183 ~118 ~112 dirt
setblock ~183 ~118 ~113 dirt
setblock ~183 ~118 ~114 dirt
setblock ~183 ~118 ~115 dirt
setblock ~183 ~118 ~116 dirt
setblock ~183 ~118 ~117 dirt
setblock ~183 ~118 ~118 dirt
setblock ~183 ~118 ~119 dirt
setblock ~183 ~118 ~120 dirt
setblock ~183 ~118 ~121 dirt
setblock ~183 ~118 ~122 dirt
setblock ~183 ~118 ~123 dirt
setblock ~183 ~118 ~124 dirt
setblock ~183 ~118 ~125 dirt
setblock ~183 ~118 ~126 dirt
setblock ~183 ~118 ~127 dirt
setblock ~183 ~119 ~68 dirt
setblock ~183 ~119 ~69 dirt
setblock ~183 ~119 ~70 dirt
setblock ~183 ~119 ~71 dirt
setblock ~183 ~119 ~72 dirt
setblock ~183 ~119 ~73 dirt
setblock ~183 ~119 ~74 dirt
setblock ~183 ~119 ~75 dirt
setblock ~183 ~119 ~79 dirt
setblock ~183 ~119 ~80 dirt
setblock ~183 ~119 ~81 dirt
setblock ~183 ~119 ~82 dirt
setblock ~183 ~119 ~83 dirt
setblock ~183 ~119 ~84 dirt
setblock ~183 ~119 ~85 dirt
setblock ~183 ~119 ~86 dirt
setblock ~183 ~119 ~87 dirt
setblock ~183 ~119 ~88 dirt
setblock ~183 ~119 ~89 dirt
setblock ~183 ~119 ~90 dirt
setblock ~183 ~119 ~91 dirt
setblock ~183 ~119 ~92 dirt
setblock ~183 ~119 ~93 dirt
setblock ~183 ~119 ~94 dirt
setblock ~183 ~119 ~95 dirt
setblock ~183 ~119 ~96 dirt
setblock ~183 ~119 ~97 dirt
setblock ~183 ~119 ~98 dirt
setblock ~183 ~119 ~99 dirt
setblock ~183 ~119 ~100 dirt
setblock ~183 ~119 ~101 dirt
setblock ~183 ~119 ~108 dirt
setblock ~183 ~119 ~109 dirt
setblock ~183 ~119 ~110 dirt
setblock ~183 ~119 ~111 dirt
setblock ~183 ~119 ~112 dirt
setblock ~183 ~119 ~113 dirt
setblock ~183 ~119 ~114 dirt
setblock ~183 ~119 ~115 dirt
setblock ~183 ~119 ~116 dirt
setblock ~183 ~119 ~117 dirt
setblock ~183 ~119 ~118 dirt
setblock ~183 ~119 ~119 dirt
setblock ~183 ~119 ~120 dirt
setblock ~183 ~119 ~121 dirt
setblock ~183 ~119 ~122 dirt
setblock ~183 ~119 ~123 dirt
setblock ~183 ~119 ~124 dirt
setblock ~183 ~119 ~125 dirt
setblock ~183 ~119 ~126 dirt
setblock ~183 ~119 ~127 dirt
setblock ~183 ~119 ~128 dirt
setblock ~183 ~120 ~67 dirt
setblock ~183 ~120 ~68 dirt
setblock ~183 ~120 ~69 dirt
setblock ~183 ~120 ~70 dirt
setblock ~183 ~120 ~71 dirt
setblock ~183 ~120 ~72 dirt
setblock ~183 ~120 ~73 dirt
setblock ~183 ~120 ~74 dirt
setblock ~183 ~120 ~75 dirt
setblock ~183 ~120 ~76 dirt
setblock ~183 ~120 ~78 dirt
setblock ~183 ~120 ~79 dirt
setblock ~183 ~120 ~80 dirt
setblock ~183 ~120 ~81 dirt
setblock ~183 ~120 ~82 dirt
setblock ~183 ~120 ~83 dirt
setblock ~183 ~120 ~84 dirt
setblock ~183 ~120 ~85 dirt
setblock ~183 ~120 ~86 dirt
setblock ~183 ~120 ~87 dirt
setblock ~183 ~120 ~88 dirt
setblock ~183 ~120 ~89 dirt
setblock ~183 ~120 ~90 dirt
setblock ~183 ~120 ~91 dirt
setblock ~183 ~120 ~92 dirt
setblock ~183 ~120 ~93 dirt
setblock ~183 ~120 ~94 dirt
setblock ~183 ~120 ~95 dirt
setblock ~183 ~120 ~96 dirt
setblock ~183 ~120 ~97 dirt
setblock ~183 ~120 ~98 dirt
setblock ~183 ~120 ~99 dirt
setblock ~183 ~120 ~100 dirt
setblock ~183 ~120 ~101 dirt
setblock ~183 ~120 ~102 dirt
setblock ~183 ~120 ~108 dirt
setblock ~183 ~120 ~109 dirt
setblock ~183 ~120 ~110 dirt
setblock ~183 ~120 ~111 dirt
setblock ~183 ~120 ~112 dirt
setblock ~183 ~120 ~113 dirt
setblock ~183 ~120 ~114 dirt
setblock ~183 ~120 ~115 dirt
setblock ~183 ~120 ~116 dirt
setblock ~183 ~120 ~117 dirt
setblock ~183 ~120 ~118 dirt
setblock ~183 ~120 ~119 dirt
setblock ~183 ~120 ~120 dirt
setblock ~183 ~120 ~121 dirt
setblock ~183 ~120 ~122 dirt
setblock ~183 ~120 ~123 dirt
setblock ~183 ~120 ~124 dirt
setblock ~183 ~120 ~125 dirt
setblock ~183 ~120 ~126 dirt
setblock ~183 ~120 ~127 dirt
setblock ~183 ~120 ~128 dirt
setblock ~183 ~120 ~129 dirt
setblock ~183 ~120 ~130 dirt
setblock ~183 ~120 ~131 dirt
setblock ~183 ~120 ~132 dirt
setblock ~183 ~121 ~66 dirt
setblock ~183 ~121 ~67 dirt
setblock ~183 ~121 ~68 dirt
setblock ~183 ~121 ~69 dirt
setblock ~183 ~121 ~70 dirt
setblock ~183 ~121 ~71 dirt
setblock ~183 ~121 ~72 dirt
setblock ~183 ~121 ~73 dirt
setblock ~183 ~121 ~74 dirt
setblock ~183 ~121 ~75 dirt
setblock ~183 ~121 ~76 dirt
setblock ~183 ~121 ~77 dirt
setblock ~183 ~121 ~78 dirt
setblock ~183 ~121 ~79 dirt
setblock ~183 ~121 ~80 dirt
setblock ~183 ~121 ~81 dirt
setblock ~183 ~121 ~82 dirt
setblock ~183 ~121 ~83 dirt
setblock ~183 ~121 ~84 dirt
setblock ~183 ~121 ~85 dirt
setblock ~183 ~121 ~86 dirt
setblock ~183 ~121 ~87 dirt
setblock ~183 ~121 ~88 dirt
setblock ~183 ~121 ~89 dirt
setblock ~183 ~121 ~90 dirt
setblock ~183 ~121 ~91 dirt
setblock ~183 ~121 ~92 dirt
setblock ~183 ~121 ~93 dirt
setblock ~183 ~121 ~94 dirt
setblock ~183 ~121 ~95 dirt
setblock ~183 ~121 ~96 dirt
setblock ~183 ~121 ~97 dirt
setblock ~183 ~121 ~98 dirt
setblock ~183 ~121 ~99 dirt
setblock ~183 ~121 ~100 dirt
setblock ~183 ~121 ~101 dirt
setblock ~183 ~121 ~102 dirt
setblock ~183 ~121 ~103 dirt
setblock ~183 ~121 ~107 dirt
setblock ~183 ~121 ~108 dirt
setblock ~183 ~121 ~109 dirt
setblock ~183 ~121 ~110 dirt
setblock ~183 ~121 ~111 dirt
setblock ~183 ~121 ~112 dirt
setblock ~183 ~121 ~113 dirt
setblock ~183 ~121 ~114 dirt
setblock ~183 ~121 ~115 dirt
setblock ~183 ~121 ~116 dirt
setblock ~183 ~121 ~117 dirt
setblock ~183 ~121 ~118 dirt
setblock ~183 ~121 ~119 dirt
setblock ~183 ~121 ~120 dirt
setblock ~183 ~121 ~121 dirt
setblock ~183 ~121 ~122 dirt
setblock ~183 ~121 ~123 dirt
setblock ~183 ~121 ~124 dirt
setblock ~183 ~121 ~125 dirt
setblock ~183 ~121 ~126 dirt
setblock ~183 ~121 ~127 dirt
setblock ~183 ~121 ~128 dirt
setblock ~183 ~121 ~129 dirt
setblock ~183 ~121 ~130 dirt
setblock ~183 ~121 ~131 dirt
setblock ~183 ~121 ~132 dirt
setblock ~183 ~121 ~133 dirt
setblock ~183 ~122 ~66 dirt
setblock ~183 ~122 ~67 dirt
setblock ~183 ~122 ~68 dirt
setblock ~183 ~122 ~69 dirt
setblock ~183 ~122 ~70 dirt
setblock ~183 ~122 ~71 dirt
setblock ~183 ~122 ~72 dirt
setblock ~183 ~122 ~73 dirt
setblock ~183 ~122 ~74 dirt
setblock ~183 ~122 ~75 dirt
setblock ~183 ~122 ~76 dirt
setblock ~183 ~122 ~77 dirt
setblock ~183 ~122 ~78 dirt
setblock ~183 ~122 ~79 dirt
setblock ~183 ~122 ~80 dirt
setblock ~183 ~122 ~81 dirt
setblock ~183 ~122 ~82 dirt
setblock ~183 ~122 ~83 dirt
setblock ~183 ~122 ~84 dirt
setblock ~183 ~122 ~85 dirt
setblock ~183 ~122 ~86 dirt
setblock ~183 ~122 ~87 dirt
setblock ~183 ~122 ~88 dirt
setblock ~183 ~122 ~89 grass_block
setblock ~183 ~122 ~90 grass_block
setblock ~183 ~122 ~91 grass_block
setblock ~183 ~122 ~92 dirt
setblock ~183 ~122 ~93 dirt
setblock ~183 ~122 ~94 dirt
setblock ~183 ~122 ~95 dirt
setblock ~183 ~122 ~96 dirt
setblock ~183 ~122 ~97 dirt
setblock ~183 ~122 ~98 dirt
setblock ~183 ~122 ~99 dirt
setblock ~183 ~122 ~100 dirt
setblock ~183 ~122 ~101 dirt
setblock ~183 ~122 ~102 dirt
setblock ~183 ~122 ~103 dirt
setblock ~183 ~122 ~107 dirt
setblock ~183 ~122 ~108 dirt
setblock ~183 ~122 ~109 dirt
setblock ~183 ~122 ~110 dirt
setblock ~183 ~122 ~111 dirt
setblock ~183 ~122 ~112 dirt
setblock ~183 ~122 ~113 dirt
setblock ~183 ~122 ~114 dirt
setblock ~183 ~122 ~115 dirt
setblock ~183 ~122 ~116 dirt
setblock ~183 ~122 ~117 dirt
setblock ~183 ~122 ~118 dirt
setblock ~183 ~122 ~119 dirt
setblock ~183 ~122 ~120 dirt
setblock ~183 ~122 ~121 dirt
setblock ~183 ~122 ~122 dirt
setblock ~183 ~122 ~123 dirt
setblock ~183 ~122 ~124 dirt
setblock ~183 ~122 ~125 dirt
setblock ~183 ~122 ~126 dirt
setblock ~183 ~122 ~127 dirt
setblock ~183 ~122 ~128 dirt
setblock ~183 ~122 ~129 dirt
setblock ~183 ~122 ~130 dirt
setblock ~183 ~122 ~131 dirt
setblock ~183 ~122 ~132 dirt
setblock ~183 ~122 ~133 dirt
setblock ~183 ~123 ~66 dirt
setblock ~183 ~123 ~67 dirt
setblock ~183 ~123 ~68 dirt
setblock ~183 ~123 ~69 dirt
setblock ~183 ~123 ~70 dirt
setblock ~183 ~123 ~71 dirt
setblock ~183 ~123 ~72 dirt
setblock ~183 ~123 ~73 dirt
setblock ~183 ~123 ~74 dirt
setblock ~183 ~123 ~75 dirt
setblock ~183 ~123 ~76 dirt
setblock ~183 ~123 ~77 dirt
setblock ~183 ~123 ~78 dirt
setblock ~183 ~123 ~79 dirt
setblock ~183 ~123 ~80 dirt
setblock ~183 ~123 ~81 dirt
setblock ~183 ~123 ~82 dirt
setblock ~183 ~123 ~83 dirt
setblock ~183 ~123 ~84 dirt
setblock ~183 ~123 ~85 grass_block
setblock ~183 ~123 ~86 grass_block
setblock ~183 ~123 ~87 grass_block
setblock ~183 ~123 ~88 grass_block
setblock ~183 ~123 ~89 poppy
setblock ~183 ~123 ~90 poppy
setblock ~183 ~123 ~92 grass_block
setblock ~183 ~123 ~93 grass_block
setblock ~183 ~123 ~94 grass_block
setblock ~183 ~123 ~95 grass_block
setblock ~183 ~123 ~96 dirt
setblock ~183 ~123 ~97 dirt
setblock ~183 ~123 ~98 dirt
setblock ~183 ~123 ~99 dirt
setblock ~183 ~123 ~100 dirt
setblock ~183 ~123 ~101 dirt
setblock ~183 ~123 ~102 dirt
setblock ~183 ~123 ~103 dirt
setblock ~183 ~123 ~107 dirt
setblock ~183 ~123 ~108 dirt
setblock ~183 ~123 ~109 grass_block
setblock ~183 ~123 ~110 grass_block
setblock ~183 ~123 ~111 dirt
setblock ~183 ~123 ~112 dirt
setblock ~183 ~123 ~113 dirt
setblock ~183 ~123 ~114 dirt
setblock ~183 ~123 ~115 dirt
setblock ~183 ~123 ~116 dirt
setblock ~183 ~123 ~117 dirt
setblock ~183 ~123 ~118 dirt
setblock ~183 ~123 ~119 dirt
setblock ~183 ~123 ~120 dirt
setblock ~183 ~123 ~121 dirt
setblock ~183 ~123 ~122 dirt
setblock ~183 ~123 ~123 dirt
setblock ~183 ~123 ~124 dirt
setblock ~183 ~123 ~125 dirt
setblock ~183 ~123 ~126 dirt
setblock ~183 ~123 ~127 dirt
setblock ~183 ~123 ~128 dirt
setblock ~183 ~123 ~129 dirt
setblock ~183 ~123 ~130 dirt
setblock ~183 ~123 ~131 dirt
setblock ~183 ~123 ~132 dirt
setblock ~183 ~123 ~133 dirt
setblock ~183 ~124 ~66 dirt
setblock ~183 ~124 ~67 dirt
setblock ~183 ~124 ~68 dirt
setblock ~183 ~124 ~69 dirt
setblock ~183 ~124 ~70 dirt
setblock ~183 ~124 ~71 dirt
setblock ~183 ~124 ~72 dirt
setblock ~183 ~124 ~73 dirt
setblock ~183 ~124 ~74 dirt
setblock ~183 ~124 ~75 dirt
setblock ~183 ~124 ~76 dirt
setblock ~183 ~124 ~77 dirt
setblock ~183 ~124 ~78 dirt
setblock ~183 ~124 ~79 dirt
setblock ~183 ~124 ~80 dirt
setblock ~183 ~124 ~81 grass_block
setblock ~183 ~124 ~82 grass_block
setblock ~183 ~124 ~83 grass_block
setblock ~183 ~124 ~84 grass_block
setblock ~183 ~124 ~85 fern
setblock ~183 ~124 ~96 grass_block
setblock ~183 ~124 ~97 grass_block
setblock ~183 ~124 ~98 dirt
setblock ~183 ~124 ~99 dirt
setblock ~183 ~124 ~100 dirt
setblock ~183 ~124 ~101 dirt
setblock ~183 ~124 ~102 dirt
setblock ~183 ~124 ~103 dirt
setblock ~183 ~124 ~107 grass_block
setblock ~183 ~124 ~108 grass_block
setblock ~183 ~124 ~110 poppy
setblock ~183 ~124 ~111 grass_block
setblock ~183 ~124 ~112 grass_block
setblock ~183 ~124 ~113 grass_block
setblock ~183 ~124 ~114 grass_block
setblock ~183 ~124 ~115 grass_block
setblock ~183 ~124 ~116 grass_block
setblock ~183 ~124 ~117 dirt
setblock ~183 ~124 ~118 dirt
setblock ~183 ~124 ~119 dirt
setblock ~183 ~124 ~120 dirt
setblock ~183 ~124 ~121 dirt
setblock ~183 ~124 ~122 dirt
setblock ~183 ~124 ~123 dirt
setblock ~183 ~124 ~124 dirt
setblock ~183 ~124 ~125 grass_block
setblock ~183 ~124 ~126 grass_block
setblock ~183 ~124 ~127 grass_block
setblock ~183 ~124 ~128 grass_block
setblock ~183 ~124 ~129 grass_block
setblock ~183 ~124 ~130 grass_block
setblock ~183 ~124 ~131 grass_block
setblock ~183 ~124 ~132 grass_block
setblock ~183 ~124 ~133 grass_block
setblock ~183 ~125 ~66 grass_block
setblock ~183 ~125 ~67 grass_block
setblock ~183 ~125 ~68 grass_block
setblock ~183 ~125 ~69 grass_block
setblock ~183 ~125 ~70 grass_block
setblock ~183 ~125 ~71 grass_block
setblock ~183 ~125 ~72 grass_block
setblock ~183 ~125 ~73 grass_block
setblock ~183 ~125 ~74 grass_block
setblock ~183 ~125 ~75 grass_block
setblock ~183 ~125 ~76 grass_block
setblock ~183 ~125 ~77 grass_block
setblock ~183 ~125 ~78 grass_block
setblock ~183 ~125 ~79 grass_block
setblock ~183 ~125 ~80 grass_block
setblock ~183 ~125 ~97 short_grass
setblock ~183 ~125 ~98 grass_block
setblock ~183 ~125 ~99 grass_block
setblock ~183 ~125 ~100 dirt
setblock ~183 ~125 ~101 dirt
setblock ~183 ~125 ~102 grass_block
setblock ~183 ~125 ~103 grass_block
setblock ~183 ~125 ~107 short_grass
setblock ~183 ~125 ~114 short_grass
setblock ~183 ~125 ~115 short_grass
setblock ~183 ~125 ~116 short_grass
setblock ~183 ~125 ~117 grass_block
setblock ~183 ~125 ~118 grass_block
setblock ~183 ~125 ~119 grass_block
setblock ~183 ~125 ~120 grass_block
setblock ~183 ~125 ~121 grass_block
setblock ~183 ~125 ~122 grass_block
setblock ~183 ~125 ~123 grass_block
setblock ~183 ~125 ~124 grass_block
setblock ~183 ~125 ~132 short_grass
setblock ~183 ~126 ~71 poppy
setblock ~183 ~126 ~72 short_grass
setblock ~183 ~126 ~73 short_grass
setblock ~183 ~126 ~74 poppy
setblock ~183 ~126 ~77 short_grass
setblock ~183 ~126 ~100 grass_block
setblock ~183 ~126 ~101 grass_block
setblock ~183 ~126 ~102 short_grass
setblock ~183 ~126 ~103 short_grass
setblock ~183 ~126 ~118 short_grass
setblock ~183 ~126 ~123 short_grass
setblock ~183 ~127 ~101 poppy
setblock ~184 ~108 ~90 dirt
setblock ~184 ~109 ~89 dirt
setblock ~184 ~109 ~90 dirt
setblock ~184 ~109 ~91 dirt
setblock ~184 ~110 ~88 dirt
setblock ~184 ~110 ~89 dirt
setblock ~184 ~110 ~90 dirt
setblock ~184 ~110 ~91 dirt
setblock ~184 ~111 ~87 dirt
setblock ~184 ~111 ~88 dirt
setblock ~184 ~111 ~89 dirt
setblock ~184 ~111 ~90 dirt
setblock ~184 ~111 ~91 dirt
setblock ~184 ~111 ~92 dirt
setblock ~184 ~111 ~116 dirt
setblock ~184 ~111 ~117 dirt
setblock ~184 ~112 ~86 dirt
setblock ~184 ~112 ~87 dirt
setblock ~184 ~112 ~88 dirt
setblock ~184 ~112 ~89 dirt
setblock ~184 ~112 ~90 dirt
setblock ~184 ~112 ~91 dirt
setblock ~184 ~112 ~92 dirt
setblock ~184 ~112 ~93 dirt
setblock ~184 ~112 ~115 dirt
setblock ~184 ~112 ~116 dirt
setblock ~184 ~112 ~117 dirt
setblock ~184 ~112 ~118 dirt
setblock ~184 ~112 ~119 dirt
setblock ~184 ~113 ~85 dirt
setblock ~184 ~113 ~86 dirt
setblock ~184 ~113 ~87 dirt
setblock ~184 ~113 ~88 dirt
setblock ~184 ~113 ~89 dirt
setblock ~184 ~113 ~90 dirt
setblock ~184 ~113 ~91 dirt
setblock ~184 ~113 ~92 dirt
setblock ~184 ~113 ~93 dirt
setblock ~184 ~113 ~94 dirt
setblock ~184 ~113 ~115 dirt
setblock ~184 ~113 ~116 dirt
setblock ~184 ~113 ~117 dirt
setblock ~184 ~113 ~118 dirt
setblock ~184 ~113 ~119 dirt
setblock ~184 ~113 ~120 dirt
setblock ~184 ~113 ~121 dirt
setblock ~184 ~114 ~84 dirt
setblock ~184 ~114 ~85 dirt
setblock ~184 ~114 ~86 dirt
setblock ~184 ~114 ~87 dirt
setblock ~184 ~114 ~88 dirt
setblock ~184 ~114 ~89 dirt
setblock ~184 ~114 ~90 dirt
setblock ~184 ~114 ~91 dirt
setblock ~184 ~114 ~92 dirt
setblock ~184 ~114 ~93 dirt
setblock ~184 ~114 ~94 dirt
setblock ~184 ~114 ~95 dirt
setblock ~184 ~114 ~114 dirt
setblock ~184 ~114 ~115 dirt
setblock ~184 ~114 ~116 dirt
setblock ~184 ~114 ~117 dirt
setblock ~184 ~114 ~118 dirt
setblock ~184 ~114 ~119 dirt
setblock ~184 ~114 ~120 dirt
setblock ~184 ~114 ~121 dirt
setblock ~184 ~114 ~122 dirt
setblock ~184 ~114 ~123 dirt
setblock ~184 ~115 ~83 dirt
setblock ~184 ~115 ~84 dirt
setblock ~184 ~115 ~85 dirt
setblock ~184 ~115 ~86 dirt
setblock ~184 ~115 ~87 dirt
setblock ~184 ~115 ~88 dirt
setblock ~184 ~115 ~89 dirt
setblock ~184 ~115 ~90 dirt
setblock ~184 ~115 ~91 dirt
setblock ~184 ~115 ~92 dirt
setblock ~184 ~115 ~93 dirt
setblock ~184 ~115 ~94 dirt
setblock ~184 ~115 ~95 dirt
setblock ~184 ~115 ~96 dirt
setblock ~184 ~115 ~113 dirt
setblock ~184 ~115 ~114 dirt
setblock ~184 ~115 ~115 dirt
setblock ~184 ~115 ~116 dirt
setblock ~184 ~115 ~117 dirt
setblock ~184 ~115 ~118 dirt
setblock ~184 ~115 ~119 dirt
setblock ~184 ~115 ~120 dirt
setblock ~184 ~115 ~121 dirt
setblock ~184 ~115 ~122 dirt
setblock ~184 ~115 ~123 dirt
setblock ~184 ~116 ~82 dirt
setblock ~184 ~116 ~83 dirt
setblock ~184 ~116 ~84 dirt
setblock ~184 ~116 ~85 dirt
setblock ~184 ~116 ~86 dirt
setblock ~184 ~116 ~87 dirt
setblock ~184 ~116 ~88 dirt
setblock ~184 ~116 ~89 dirt
setblock ~184 ~116 ~90 dirt
setblock ~184 ~116 ~91 dirt
setblock ~184 ~116 ~92 dirt
setblock ~184 ~116 ~93 dirt
setblock ~184 ~116 ~94 dirt
setblock ~184 ~116 ~95 dirt
setblock ~184 ~116 ~96 dirt
setblock ~184 ~116 ~97 dirt
setblock ~184 ~116 ~112 dirt
setblock ~184 ~116 ~113 dirt
setblock ~184 ~116 ~114 dirt
setblock ~184 ~116 ~115 dirt
setblock ~184 ~116 ~116 dirt
setblock ~184 ~116 ~117 dirt
setblock ~184 ~116 ~118 dirt
setblock ~184 ~116 ~119 dirt
setblock ~184 ~116 ~120 dirt
setblock ~184 ~116 ~121 dirt
setblock ~184 ~116 ~122 dirt
setblock ~184 ~116 ~123 dirt
setblock ~184 ~116 ~124 dirt
setblock ~184 ~117 ~81 dirt
setblock ~184 ~117 ~82 dirt
setblock ~184 ~117 ~83 dirt
setblock ~184 ~117 ~84 dirt
setblock ~184 ~117 ~85 dirt
setblock ~184 ~117 ~86 dirt
setblock ~184 ~117 ~87 dirt
setblock ~184 ~117 ~88 dirt
setblock ~184 ~117 ~89 dirt
setblock ~184 ~117 ~90 dirt
setblock ~184 ~117 ~91 dirt
setblock ~184 ~117 ~92 dirt
setblock ~184 ~117 ~93 dirt
setblock ~184 ~117 ~94 dirt
setblock ~184 ~117 ~95 dirt
setblock ~184 ~117 ~96 dirt
setblock ~184 ~117 ~97 dirt
setblock ~184 ~117 ~98 dirt
setblock ~184 ~117 ~111 dirt
setblock ~184 ~117 ~112 dirt
setblock ~184 ~117 ~113 dirt
setblock ~184 ~117 ~114 dirt
setblock ~184 ~117 ~115 dirt
setblock ~184 ~117 ~116 dirt
setblock ~184 ~117 ~117 dirt
setblock ~184 ~117 ~118 dirt
setblock ~184 ~117 ~119 dirt
setblock ~184 ~117 ~120 dirt
setblock ~184 ~117 ~121 dirt
setblock ~184 ~117 ~122 dirt
setblock ~184 ~117 ~123 dirt
setblock ~184 ~117 ~124 dirt
setblock ~184 ~117 ~125 dirt
setblock ~184 ~118 ~73 dirt
setblock ~184 ~118 ~80 dirt
setblock ~184 ~118 ~81 dirt
setblock ~184 ~118 ~82 dirt
setblock ~184 ~118 ~83 dirt
setblock ~184 ~118 ~84 dirt
setblock ~184 ~118 ~85 dirt
setblock ~184 ~118 ~86 dirt
setblock ~184 ~118 ~87 dirt
setblock ~184 ~118 ~88 dirt
setblock ~184 ~118 ~89 dirt
setblock ~184 ~118 ~90 dirt
setblock ~184 ~118 ~91 dirt
setblock ~184 ~118 ~92 dirt
setblock ~184 ~118 ~93 dirt
setblock ~184 ~118 ~94 dirt
setblock ~184 ~118 ~95 dirt
setblock ~184 ~118 ~96 dirt
setblock ~184 ~118 ~97 dirt
setblock ~184 ~118 ~98 dirt
setblock ~184 ~118 ~99 dirt
setblock ~184 ~118 ~110 dirt
setblock ~184 ~118 ~111 dirt
setblock ~184 ~118 ~112 dirt
setblock ~184 ~118 ~113 dirt
setblock ~184 ~118 ~114 dirt
setblock ~184 ~118 ~115 dirt
setblock ~184 ~118 ~116 dirt
setblock ~184 ~118 ~117 dirt
setblock ~184 ~118 ~118 dirt
setblock ~184 ~118 ~119 dirt
setblock ~184 ~118 ~120 dirt
setblock ~184 ~118 ~121 dirt
setblock ~184 ~118 ~122 dirt
setblock ~184 ~118 ~123 dirt
setblock ~184 ~118 ~124 dirt
setblock ~184 ~118 ~125 dirt
setblock ~184 ~118 ~126 dirt
setblock ~184 ~119 ~69 dirt
setblock ~184 ~119 ~70 dirt
setblock ~184 ~119 ~71 dirt
setblock ~184 ~119 ~72 dirt
setblock ~184 ~119 ~73 dirt
setblock ~184 ~119 ~74 dirt
setblock ~184 ~119 ~80 dirt
setblock ~184 ~119 ~81 dirt
setblock ~184 ~119 ~82 dirt
setblock ~184 ~119 ~83 dirt
setblock ~184 ~119 ~84 dirt
setblock ~184 ~119 ~85 dirt
setblock ~184 ~119 ~86 dirt
setblock ~184 ~119 ~87 dirt
setblock ~184 ~119 ~88 dirt
setblock ~184 ~119 ~89 dirt
setblock ~184 ~119 ~90 dirt
setblock ~184 ~119 ~91 dirt
setblock ~184 ~119 ~92 dirt
setblock ~184 ~119 ~93 dirt
setblock ~184 ~119 ~94 dirt
setblock ~184 ~119 ~95 dirt
setblock ~184 ~119 ~96 dirt
setblock ~184 ~119 ~97 dirt
setblock ~184 ~119 ~98 dirt
setblock ~184 ~119 ~99 dirt
setblock ~184 ~119 ~100 dirt
setblock ~184 ~119 ~109 dirt
setblock ~184 ~119 ~110 dirt
setblock ~184 ~119 ~111 dirt
setblock ~184 ~119 ~112 dirt
setblock ~184 ~119 ~113 dirt
setblock ~184 ~119 ~114 dirt
setblock ~184 ~119 ~115 dirt
setblock ~184 ~119 ~116 dirt
setblock ~184 ~119 ~117 dirt
setblock ~184 ~119 ~118 dirt
setblock ~184 ~119 ~119 dirt
setblock ~184 ~119 ~120 dirt
setblock ~184 ~119 ~121 dirt
setblock ~184 ~119 ~122 dirt
setblock ~184 ~119 ~123 dirt
setblock ~184 ~119 ~124 dirt
setblock ~184 ~119 ~125 dirt
setblock ~184 ~119 ~126 dirt
setblock ~184 ~119 ~127 dirt
setblock ~184 ~120 ~68 dirt
setblock ~184 ~120 ~69 dirt
setblock ~184 ~120 ~70 dirt
setblock ~184 ~120 ~71 dirt
setblock ~184 ~120 ~72 dirt
setblock ~184 ~120 ~73 dirt
setblock ~184 ~120 ~74 dirt
setblock ~184 ~120 ~75 dirt
setblock ~184 ~120 ~79 dirt
setblock ~184 ~120 ~80 dirt
setblock ~184 ~120 ~81 dirt
setblock ~184 ~120 ~82 dirt
setblock ~184 ~120 ~83 dirt
setblock ~184 ~120 ~84 dirt
setblock ~184 ~120 ~85 dirt
setblock ~184 ~120 ~86 dirt
setblock ~184 ~120 ~87 dirt
setblock ~184 ~120 ~88 dirt
setblock ~184 ~120 ~89 dirt
setblock ~184 ~120 ~90 dirt
setblock ~184 ~120 ~91 dirt
setblock ~184 ~120 ~92 dirt
setblock ~184 ~120 ~93 dirt
setblock ~184 ~120 ~94 dirt
setblock ~184 ~120 ~95 dirt
setblock ~184 ~120 ~96 dirt
setblock ~184 ~120 ~97 dirt
setblock ~184 ~120 ~98 dirt
setblock ~184 ~120 ~99 dirt
setblock ~184 ~120 ~100 dirt
setblock ~184 ~120 ~101 dirt
setblock ~184 ~120 ~108 dirt
setblock ~184 ~120 ~109 dirt
setblock ~184 ~120 ~110 dirt
setblock ~184 ~120 ~111 dirt
setblock ~184 ~120 ~112 dirt
setblock ~184 ~120 ~113 dirt
setblock ~184 ~120 ~114 dirt
setblock ~184 ~120 ~115 dirt
setblock ~184 ~120 ~116 dirt
setblock ~184 ~120 ~117 dirt
setblock ~184 ~120 ~118 dirt
setblock ~184 ~120 ~119 dirt
setblock ~184 ~120 ~120 dirt
setblock ~184 ~120 ~121 dirt
setblock ~184 ~120 ~122 dirt
setblock ~184 ~120 ~123 dirt
setblock ~184 ~120 ~124 dirt
setblock ~184 ~120 ~125 dirt
setblock ~184 ~120 ~126 dirt
setblock ~184 ~120 ~127 dirt
setblock ~184 ~120 ~128 dirt
setblock ~184 ~121 ~67 dirt
setblock ~184 ~121 ~68 dirt
setblock ~184 ~121 ~69 dirt
setblock ~184 ~121 ~70 dirt
setblock ~184 ~121 ~71 dirt
setblock ~184 ~121 ~72 dirt
setblock ~184 ~121 ~73 dirt
setblock ~184 ~121 ~74 dirt
setblock ~184 ~121 ~75 dirt
setblock ~184 ~121 ~76 dirt
setblock ~184 ~121 ~78 dirt
setblock ~184 ~121 ~79 dirt
setblock ~184 ~121 ~80 dirt
setblock ~184 ~121 ~81 dirt
setblock ~184 ~121 ~82 dirt
setblock ~184 ~121 ~83 dirt
setblock ~184 ~121 ~84 dirt
setblock ~184 ~121 ~85 dirt
setblock ~184 ~121 ~86 dirt
setblock ~184 ~121 ~87 dirt
setblock ~184 ~121 ~88 dirt
setblock ~184 ~121 ~89 dirt
setblock ~184 ~121 ~90 dirt
setblock ~184 ~121 ~91 dirt
setblock ~184 ~121 ~92 dirt
setblock ~184 ~121 ~93 dirt
setblock ~184 ~121 ~94 dirt
setblock ~184 ~121 ~95 dirt
setblock ~184 ~121 ~96 dirt
setblock ~184 ~121 ~97 dirt
setblock ~184 ~121 ~98 dirt
setblock ~184 ~121 ~99 dirt
setblock ~184 ~121 ~100 dirt
setblock ~184 ~121 ~101 dirt
setblock ~184 ~121 ~102 dirt
setblock ~184 ~121 ~107 dirt
setblock ~184 ~121 ~108 dirt
setblock ~184 ~121 ~109 dirt
setblock ~184 ~121 ~110 dirt
setblock ~184 ~121 ~111 dirt
setblock ~184 ~121 ~112 dirt
setblock ~184 ~121 ~113 dirt
setblock ~184 ~121 ~114 dirt
setblock ~184 ~121 ~115 dirt
setblock ~184 ~121 ~116 dirt
setblock ~184 ~121 ~117 dirt
setblock ~184 ~121 ~118 dirt
setblock ~184 ~121 ~119 dirt
setblock ~184 ~121 ~120 dirt
setblock ~184 ~121 ~121 dirt
setblock ~184 ~121 ~122 dirt
setblock ~184 ~121 ~123 dirt
setblock ~184 ~121 ~124 dirt
setblock ~184 ~121 ~125 dirt
setblock ~184 ~121 ~126 dirt
setblock ~184 ~121 ~127 dirt
setblock ~184 ~121 ~128 dirt
setblock ~184 ~121 ~129 dirt
setblock ~184 ~121 ~130 dirt
setblock ~184 ~121 ~132 dirt
setblock ~184 ~122 ~67 dirt
setblock ~184 ~122 ~68 dirt
setblock ~184 ~122 ~69 dirt
setblock ~184 ~122 ~70 dirt
setblock ~184 ~122 ~71 dirt
setblock ~184 ~122 ~72 dirt
setblock ~184 ~122 ~73 dirt
setblock ~184 ~122 ~74 dirt
setblock ~184 ~122 ~75 dirt
setblock ~184 ~122 ~76 dirt
setblock ~184 ~122 ~78 dirt
setblock ~184 ~122 ~79 dirt
setblock ~184 ~122 ~80 dirt
setblock ~184 ~122 ~81 dirt
setblock ~184 ~122 ~82 dirt
setblock ~184 ~122 ~83 dirt
setblock ~184 ~122 ~84 dirt
setblock ~184 ~122 ~85 dirt
setblock ~184 ~122 ~86 dirt
setblock ~184 ~122 ~87 dirt
setblock ~184 ~122 ~88 dirt
setblock ~184 ~122 ~89 grass_block
setblock ~184 ~122 ~90 grass_block
setblock ~184 ~122 ~91 grass_block
setblock ~184 ~122 ~92 dirt
setblock ~184 ~122 ~93 dirt
setblock ~184 ~122 ~94 dirt
setblock ~184 ~122 ~95 dirt
setblock ~184 ~122 ~96 dirt
setblock ~184 ~122 ~97 dirt
setblock ~184 ~122 ~98 dirt
setblock ~184 ~122 ~99 dirt
setblock ~184 ~122 ~100 dirt
setblock ~184 ~122 ~101 dirt
setblock ~184 ~122 ~102 dirt
setblock ~184 ~122 ~107 dirt
setblock ~184 ~122 ~108 dirt
setblock ~184 ~122 ~109 dirt
setblock ~184 ~122 ~110 dirt
setblock ~184 ~122 ~111 dirt
setblock ~184 ~122 ~112 dirt
setblock ~184 ~122 ~113 dirt
setblock ~184 ~122 ~114 dirt
setblock ~184 ~122 ~115 dirt
setblock ~184 ~122 ~116 dirt
setblock ~184 ~122 ~117 dirt
setblock ~184 ~122 ~118 dirt
setblock ~184 ~122 ~119 dirt
setblock ~184 ~122 ~120 dirt
setblock ~184 ~122 ~121 dirt
setblock ~184 ~122 ~122 dirt
setblock ~184 ~122 ~123 dirt
setblock ~184 ~122 ~124 dirt
setblock ~184 ~122 ~125 dirt
setblock ~184 ~122 ~126 dirt
setblock ~184 ~122 ~127 dirt
setblock ~184 ~122 ~128 dirt
setblock ~184 ~122 ~129 dirt
setblock ~184 ~122 ~130 dirt
setblock ~184 ~122 ~132 dirt
setblock ~184 ~123 ~67 dirt
setblock ~184 ~123 ~68 dirt
setblock ~184 ~123 ~69 dirt
setblock ~184 ~123 ~70 dirt
setblock ~184 ~123 ~71 dirt
setblock ~184 ~123 ~72 dirt
setblock ~184 ~123 ~73 dirt
setblock ~184 ~123 ~74 dirt
setblock ~184 ~123 ~75 dirt
setblock ~184 ~123 ~76 dirt
setblock ~184 ~123 ~78 dirt
setblock ~184 ~123 ~79 dirt
setblock ~184 ~123 ~80 dirt
setblock ~184 ~123 ~81 dirt
setblock ~184 ~123 ~82 dirt
setblock ~184 ~123 ~83 dirt
setblock ~184 ~123 ~84 dirt
setblock ~184 ~123 ~85 grass_block
setblock ~184 ~123 ~86 grass_block
setblock ~184 ~123 ~87 grass_block
setblock ~184 ~123 ~88 grass_block
setblock ~184 ~123 ~90 short_grass
setblock ~184 ~123 ~91 short_grass
setblock ~184 ~123 ~92 grass_block
setblock ~184 ~123 ~93 grass_block
setblock ~184 ~123 ~94 grass_block
setblock ~184 ~123 ~95 dirt
setblock ~184 ~123 ~96 dirt
setblock ~184 ~123 ~97 dirt
setblock ~184 ~123 ~98 dirt
setblock ~184 ~123 ~99 dirt
setblock ~184 ~123 ~100 dirt
setblock ~184 ~123 ~101 dirt
setblock ~184 ~123 ~102 dirt
setblock ~184 ~123 ~107 dirt
setblock ~184 ~123 ~108 dirt
setblock ~184 ~123 ~109 dirt
setblock ~184 ~123 ~110 grass_block
setblock ~184 ~123 ~111 dirt
setblock ~184 ~123 ~112 dirt
setblock ~184 ~123 ~113 dirt
setblock ~184 ~123 ~114 dirt
setblock ~184 ~123 ~115 dirt
setblock ~184 ~123 ~116 dirt
setblock ~184 ~123 ~117 dirt
setblock ~184 ~123 ~118 dirt
setblock ~184 ~123 ~119 dirt
setblock ~184 ~123 ~120 dirt
setblock ~184 ~123 ~121 dirt
setblock ~184 ~123 ~122 dirt
setblock ~184 ~123 ~123 dirt
setblock ~184 ~123 ~124 dirt
setblock ~184 ~123 ~125 dirt
setblock ~184 ~123 ~126 dirt
setblock ~184 ~123 ~127 dirt
setblock ~184 ~123 ~128 dirt
setblock ~184 ~123 ~129 dirt
setblock ~184 ~123 ~130 dirt
setblock ~184 ~123 ~132 dirt
setblock ~184 ~124 ~67 dirt
setblock ~184 ~124 ~68 dirt
setblock ~184 ~124 ~69 dirt
setblock ~184 ~124 ~70 dirt
setblock ~184 ~124 ~71 dirt
setblock ~184 ~124 ~72 dirt
setblock ~184 ~124 ~73 dirt
setblock ~184 ~124 ~74 dirt
setblock ~184 ~124 ~75 dirt
setblock ~184 ~124 ~76 dirt
setblock ~184 ~124 ~78 dirt
setblock ~184 ~124 ~79 dirt
setblock ~184 ~124 ~80 dirt
setblock ~184 ~124 ~81 dirt
setblock ~184 ~124 ~82 grass_block
setblock ~184 ~124 ~83 grass_block
setblock ~184 ~124 ~84 grass_block
setblock ~184 ~124 ~86 short_grass
setblock ~184 ~124 ~95 grass_block
setblock ~184 ~124 ~96 grass_block
setblock ~184 ~124 ~97 grass_block
setblock ~184 ~124 ~98 dirt
setblock ~184 ~124 ~99 dirt
setblock ~184 ~124 ~100 dirt
setblock ~184 ~124 ~101 dirt
setblock ~184 ~124 ~102 dirt
setblock ~184 ~124 ~107 grass_block
setblock ~184 ~124 ~108 grass_block
setblock ~184 ~124 ~109 grass_block
setblock ~184 ~124 ~110 short_grass
setblock ~184 ~124 ~111 grass_block
setblock ~184 ~124 ~112 grass_block
setblock ~184 ~124 ~113 grass_block
setblock ~184 ~124 ~114 grass_block
setblock ~184 ~124 ~115 grass_block
setblock ~184 ~124 ~116 dirt
setblock ~184 ~124 ~117 dirt
setblock ~184 ~124 ~118 dirt
setblock ~184 ~124 ~119 dirt
setblock ~184 ~124 ~120 dirt
setblock ~184 ~124 ~121 dirt
setblock ~184 ~124 ~122 dirt
setblock ~184 ~124 ~123 dirt
setblock ~184 ~124 ~124 dirt
setblock ~184 ~124 ~125 grass_block
setblock ~184 ~124 ~126 grass_block
setblock ~184 ~124 ~127 grass_block
setblock ~184 ~124 ~128 grass_block
setblock ~184 ~124 ~129 grass_block
setblock ~184 ~124 ~130 grass_block
setblock ~184 ~124 ~132 grass_block
setblock ~184 ~125 ~67 grass_block
setblock ~184 ~125 ~68 grass_block
setblock ~184 ~125 ~69 grass_block
setblock ~184 ~125 ~70 grass_block
setblock ~184 ~125 ~71 grass_block
setblock ~184 ~125 ~72 grass_block
setblock ~184 ~125 ~73 grass_block
setblock ~184 ~125 ~74 grass_block
setblock ~184 ~125 ~75 grass_block
setblock ~184 ~125 ~76 grass_block
setblock ~184 ~125 ~78 grass_block
setblock ~184 ~125 ~79 grass_block
setblock ~184 ~125 ~80 grass_block
setblock ~184 ~125 ~81 grass_block
setblock ~184 ~125 ~82 poppy
setblock ~184 ~125 ~84 short_grass
setblock ~184 ~125 ~98 grass_block
setblock ~184 ~125 ~99 grass_block
setblock ~184 ~125 ~100 dirt
setblock ~184 ~125 ~101 dirt
setblock ~184 ~125 ~102 grass_block
setblock ~184 ~125 ~116 grass_block
setblock ~184 ~125 ~117 grass_block
setblock ~184 ~125 ~118 grass_block
setblock ~184 ~125 ~119 grass_block
setblock ~184 ~125 ~120 grass_block
setblock ~184 ~125 ~121 grass_block
setblock ~184 ~125 ~122 grass_block
setblock ~184 ~125 ~123 grass_block
setblock ~184 ~125 ~124 grass_block
setblock ~184 ~125 ~125 short_grass
setblock ~184 ~125 ~126 poppy
setblock ~184 ~125 ~129 short_grass
setblock ~184 ~126 ~67 short_grass
setblock ~184 ~126 ~68 poppy
setblock ~184 ~126 ~74 short_grass
setblock ~184 ~126 ~75 short_grass
setblock ~184 ~126 ~78 short_grass
setblock ~184 ~126 ~79 short_grass
setblock ~184 ~126 ~81 short_grass
setblock ~184 ~126 ~98 short_grass
setblock ~184 ~126 ~99 short_grass
setblock ~184 ~126 ~100 grass_block
setblock ~184 ~126 ~101 grass_block
setblock ~184 ~126 ~117 short_grass
setblock ~184 ~126 ~119 short_grass
setblock ~184 ~126 ~120 short_grass
setblock ~184 ~126 ~123 fern
setblock ~184 ~126 ~124 short_grass
setblock ~185 ~109 ~90 dirt
setblock ~185 ~110 ~89 dirt
setblock ~185 ~110 ~90 dirt
setblock ~185 ~111 ~88 dirt
setblock ~185 ~111 ~89 dirt
setblock ~185 ~111 ~90 dirt
setblock ~185 ~111 ~91 dirt
setblock ~185 ~112 ~87 dirt
setblock ~185 ~112 ~88 dirt
setblock ~185 ~112 ~89 dirt
setblock ~185 ~112 ~90 dirt
setblock ~185 ~112 ~91 dirt
setblock ~185 ~112 ~92 dirt
setblock ~185 ~112 ~116 dirt
setblock ~185 ~113 ~86 dirt
setblock ~185 ~113 ~87 dirt
setblock ~185 ~113 ~88 dirt
setblock ~185 ~113 ~89 dirt
setblock ~185 ~113 ~90 dirt
setblock ~185 ~113 ~91 dirt
setblock ~185 ~113 ~92 dirt
setblock ~185 ~113 ~93 dirt
setblock ~185 ~113 ~115 dirt
setblock ~185 ~113 ~116 dirt
setblock ~185 ~113 ~117 dirt
setblock ~185 ~113 ~119 dirt
setblock ~185 ~114 ~85 dirt
setblock ~185 ~114 ~86 dirt
setblock ~185 ~114 ~87 dirt
setblock ~185 ~114 ~88 dirt
setblock ~185 ~114 ~89 dirt
setblock ~185 ~114 ~90 dirt
setblock ~185 ~114 ~91 dirt
setblock ~185 ~114 ~92 dirt
setblock ~185 ~114 ~93 dirt
setblock ~185 ~114 ~94 dirt
setblock ~185 ~114 ~114 dirt
setblock ~185 ~114 ~115 dirt
setblock ~185 ~114 ~116 dirt
setblock ~185 ~114 ~117 dirt
setblock ~185 ~114 ~118 dirt
setblock ~185 ~114 ~119 dirt
setblock ~185 ~114 ~120 dirt
setblock ~185 ~115 ~84 dirt
setblock ~185 ~115 ~85 dirt
setblock ~185 ~115 ~86 dirt
setblock ~185 ~115 ~87 dirt
setblock ~185 ~115 ~88 dirt
setblock ~185 ~115 ~89 dirt
setblock ~185 ~115 ~90 dirt
setblock ~185 ~115 ~91 dirt
setblock ~185 ~115 ~92 dirt
setblock ~185 ~115 ~93 dirt
setblock ~185 ~115 ~94 dirt
setblock ~185 ~115 ~95 dirt
setblock ~185 ~115 ~114 dirt
setblock ~185 ~115 ~115 dirt
setblock ~185 ~115 ~116 dirt
setblock ~185 ~115 ~117 dirt
setblock ~185 ~115 ~118 dirt
setblock ~185 ~115 ~119 dirt
setblock ~185 ~115 ~120 dirt
setblock ~185 ~115 ~121 dirt
setblock ~185 ~115 ~122 dirt
setblock ~185 ~116 ~83 dirt
setblock ~185 ~116 ~84 dirt
setblock ~185 ~116 ~85 dirt
setblock ~185 ~116 ~86 dirt
setblock ~185 ~116 ~87 dirt
setblock ~185 ~116 ~88 dirt
setblock ~185 ~116 ~89 dirt
setblock ~185 ~116 ~90 dirt
setblock ~185 ~116 ~91 dirt
setblock ~185 ~116 ~92 dirt
setblock ~185 ~116 ~93 dirt
setblock ~185 ~116 ~94 dirt
setblock ~185 ~116 ~95 dirt
setblock ~185 ~116 ~96 dirt
setblock ~185 ~116 ~113 dirt
setblock ~185 ~116 ~114 dirt
setblock ~185 ~116 ~115 dirt
setblock ~185 ~116 ~116 dirt
setblock ~185 ~116 ~117 dirt
setblock ~185 ~116 ~118 dirt
setblock ~185 ~116 ~119 dirt
setblock ~185 ~116 ~120 dirt
setblock ~185 ~116 ~121 dirt
setblock ~185 ~116 ~122 dirt
setblock ~185 ~116 ~123 dirt
setblock ~185 ~117 ~82 dirt
setblock ~185 ~117 ~83 dirt
setblock ~185 ~117 ~84 dirt
setblock ~185 ~117 ~85 dirt
setblock ~185 ~117 ~86 dirt
setblock ~185 ~117 ~87 dirt
setblock ~185 ~117 ~88 dirt
setblock ~185 ~117 ~89 dirt
setblock ~185 ~117 ~90 dirt
setblock ~185 ~117 ~91 dirt
setblock ~185 ~117 ~92 dirt
setblock ~185 ~117 ~93 dirt
setblock ~185 ~117 ~94 dirt
setblock ~185 ~117 ~95 dirt
setblock ~185 ~117 ~96 dirt
setblock ~185 ~117 ~97 dirt
setblock ~185 ~117 ~112 dirt
setblock ~185 ~117 ~113 dirt
setblock ~185 ~117 ~114 dirt
setblock ~185 ~117 ~115 dirt
setblock ~185 ~117 ~116 dirt
setblock ~185 ~117 ~117 dirt
setblock ~185 ~117 ~118 dirt
setblock ~185 ~117 ~119 dirt
setblock ~185 ~117 ~120 dirt
setblock ~185 ~117 ~121 dirt
setblock ~185 ~117 ~122 dirt
setblock ~185 ~117 ~123 dirt
setblock ~185 ~117 ~124 dirt
setblock ~185 ~118 ~81 dirt
setblock ~185 ~118 ~82 dirt
setblock ~185 ~118 ~83 dirt
setblock ~185 ~118 ~84 dirt
setblock ~185 ~118 ~85 dirt
setblock ~185 ~118 ~86 dirt
setblock ~185 ~118 ~87 dirt
setblock ~185 ~118 ~88 dirt
setblock ~185 ~118 ~89 dirt
setblock ~185 ~118 ~90 dirt
setblock ~185 ~118 ~91 dirt
setblock ~185 ~118 ~92 dirt
setblock ~185 ~118 ~93 dirt
setblock ~185 ~118 ~94 dirt
setblock ~185 ~118 ~95 dirt
setblock ~185 ~118 ~96 dirt
setblock ~185 ~118 ~97 dirt
setblock ~185 ~118 ~98 dirt
setblock ~185 ~118 ~111 dirt
setblock ~185 ~118 ~112 dirt
setblock ~185 ~118 ~113 dirt
setblock ~185 ~118 ~114 dirt
setblock ~185 ~118 ~115 dirt
setblock ~185 ~118 ~116 dirt
setblock ~185 ~118 ~117 dirt
setblock ~185 ~118 ~118 dirt
setblock ~185 ~118 ~119 dirt
setblock ~185 ~118 ~120 dirt
setblock ~185 ~118 ~121 dirt
setblock ~185 ~118 ~122 dirt
setblock ~185 ~118 ~123 dirt
setblock ~185 ~118 ~124 dirt
setblock ~185 ~118 ~125 dirt
setblock ~185 ~119 ~73 dirt
setblock ~185 ~119 ~80 dirt
setblock ~185 ~119 ~81 dirt
setblock ~185 ~119 ~82 dirt
setblock ~185 ~119 ~83 dirt
setblock ~185 ~119 ~84 dirt
setblock ~185 ~119 ~85 dirt
setblock ~185 ~119 ~86 dirt
setblock ~185 ~119 ~87 dirt
setblock ~185 ~119 ~88 dirt
setblock ~185 ~119 ~89 dirt
setblock ~185 ~119 ~90 dirt
setblock ~185 ~119 ~91 dirt
setblock ~185 ~119 ~92 dirt
setblock ~185 ~119 ~93 dirt
setblock ~185 ~119 ~94 dirt
setblock ~185 ~119 ~95 dirt
setblock ~185 ~119 ~96 dirt
setblock ~185 ~119 ~97 dirt
setblock ~185 ~119 ~98 dirt
setblock ~185 ~119 ~99 dirt
setblock ~185 ~119 ~110 dirt
setblock ~185 ~119 ~111 dirt
setblock ~185 ~119 ~112 dirt
setblock ~185 ~119 ~113 dirt
setblock ~185 ~119 ~114 dirt
setblock ~185 ~119 ~115 dirt
setblock ~185 ~119 ~116 dirt
setblock ~185 ~119 ~117 dirt
setblock ~185 ~119 ~118 dirt
setblock ~185 ~119 ~119 dirt
setblock ~185 ~119 ~120 dirt
setblock ~185 ~119 ~121 dirt
setblock ~185 ~119 ~122 dirt
setblock ~185 ~119 ~123 dirt
setblock ~185 ~119 ~124 dirt
setblock ~185 ~119 ~125 dirt
setblock ~185 ~119 ~126 dirt
setblock ~185 ~120 ~70 dirt
setblock ~185 ~120 ~71 dirt
setblock ~185 ~120 ~72 dirt
setblock ~185 ~120 ~73 dirt
setblock ~185 ~120 ~74 dirt
setblock ~185 ~120 ~80 dirt
setblock ~185 ~120 ~81 dirt
setblock ~185 ~120 ~82 dirt
setblock ~185 ~120 ~83 dirt
setblock ~185 ~120 ~84 dirt
setblock ~185 ~120 ~85 dirt
setblock ~185 ~120 ~86 dirt
setblock ~185 ~120 ~87 dirt
setblock ~185 ~120 ~88 dirt
setblock ~185 ~120 ~89 dirt
setblock ~185 ~120 ~90 dirt
setblock ~185 ~120 ~91 dirt
setblock ~185 ~120 ~92 dirt
setblock ~185 ~120 ~93 dirt
setblock ~185 ~120 ~94 dirt
setblock ~185 ~120 ~95 dirt
setblock ~185 ~120 ~96 dirt
setblock ~185 ~120 ~97 dirt
setblock ~185 ~120 ~98 dirt
setblock ~185 ~120 ~99 dirt
setblock ~185 ~120 ~100 dirt
setblock ~185 ~120 ~109 dirt
setblock ~185 ~120 ~110 dirt
setblock ~185 ~120 ~111 dirt
setblock ~185 ~120 ~112 dirt
setblock ~185 ~120 ~113 dirt
setblock ~185 ~120 ~114 dirt
setblock ~185 ~120 ~115 dirt
setblock ~185 ~120 ~116 dirt
setblock ~185 ~120 ~117 dirt
setblock ~185 ~120 ~118 dirt
setblock ~185 ~120 ~119 dirt
setblock ~185 ~120 ~120 dirt
setblock ~185 ~120 ~121 dirt
setblock ~185 ~120 ~122 dirt
setblock ~185 ~120 ~123 dirt
setblock ~185 ~120 ~124 dirt
setblock ~185 ~120 ~125 dirt
setblock ~185 ~120 ~126 dirt
setblock ~185 ~120 ~127 dirt
setblock ~185 ~121 ~68 dirt
setblock ~185 ~121 ~69 dirt
setblock ~185 ~121 ~70 dirt
setblock ~185 ~121 ~71 dirt
setblock ~185 ~121 ~72 dirt
setblock ~185 ~121 ~73 dirt
setblock ~185 ~121 ~74 dirt
setblock ~185 ~121 ~75 dirt
setblock ~185 ~121 ~79 dirt
setblock ~185 ~121 ~80 dirt
setblock ~185 ~121 ~81 dirt
setblock ~185 ~121 ~82 dirt
setblock ~185 ~121 ~83 dirt
setblock ~185 ~121 ~84 dirt
setblock ~185 ~121 ~85 dirt
setblock ~185 ~121 ~86 dirt
setblock ~185 ~121 ~87 dirt
setblock ~185 ~121 ~88 dirt
setblock ~185 ~121 ~89 dirt
setblock ~185 ~121 ~90 dirt
setblock ~185 ~121 ~91 dirt
setblock ~185 ~121 ~92 dirt
setblock ~185 ~121 ~93 dirt
setblock ~185 ~121 ~94 dirt
setblock ~185 ~121 ~95 dirt
setblock ~185 ~121 ~96 dirt
setblock ~185 ~121 ~97 dirt
setblock ~185 ~121 ~98 dirt
setblock ~185 ~121 ~99 dirt
setblock ~185 ~121 ~100 dirt
setblock ~185 ~121 ~101 dirt
setblock ~185 ~121 ~108 dirt
setblock ~185 ~121 ~109 dirt
setblock ~185 ~121 ~110 dirt
setblock ~185 ~121 ~111 dirt
setblock ~185 ~121 ~112 dirt
setblock ~185 ~121 ~113 dirt
setblock ~185 ~121 ~114 dirt
setblock ~185 ~121 ~115 dirt
setblock ~185 ~121 ~116 dirt
setblock ~185 ~121 ~117 dirt
setblock ~185 ~121 ~118 dirt
setblock ~185 ~121 ~119 dirt
setblock ~185 ~121 ~120 dirt
setblock ~185 ~121 ~121 dirt
setblock ~185 ~121 ~122 dirt
setblock ~185 ~121 ~123 dirt
setblock ~185 ~121 ~124 dirt
setblock ~185 ~121 ~125 dirt
setblock ~185 ~121 ~126 dirt
setblock ~185 ~121 ~127 dirt
setblock ~185 ~122 ~68 dirt
setblock ~185 ~122 ~69 dirt
setblock ~185 ~122 ~70 dirt
setblock ~185 ~122 ~71 dirt
setblock ~185 ~122 ~72 dirt
setblock ~185 ~122 ~73 dirt
setblock ~185 ~122 ~74 dirt
setblock ~185 ~122 ~75 dirt
setblock ~185 ~122 ~79 dirt
setblock ~185 ~122 ~80 dirt
setblock ~185 ~122 ~81 dirt
setblock ~185 ~122 ~82 dirt
setblock ~185 ~122 ~83 dirt
setblock ~185 ~122 ~84 dirt
setblock ~185 ~122 ~85 dirt
setblock ~185 ~122 ~86 dirt
setblock ~185 ~122 ~87 dirt
setblock ~185 ~122 ~88 dirt
setblock ~185 ~122 ~89 grass_block
setblock ~185 ~122 ~90 grass_block
setblock ~185 ~122 ~91 grass_block
setblock ~185 ~122 ~92 dirt
setblock ~185 ~122 ~93 dirt
setblock ~185 ~122 ~94 dirt
setblock ~185 ~122 ~95 dirt
setblock ~185 ~122 ~96 dirt
setblock ~185 ~122 ~97 dirt
setblock ~185 ~122 ~98 dirt
setblock ~185 ~122 ~99 dirt
setblock ~185 ~122 ~100 dirt
setblock ~185 ~122 ~101 dirt
setblock ~185 ~122 ~108 dirt
setblock ~185 ~122 ~109 dirt
setblock ~185 ~122 ~110 dirt
setblock ~185 ~122 ~111 dirt
setblock ~185 ~122 ~112 dirt
setblock ~185 ~122 ~113 dirt
setblock ~185 ~122 ~114 dirt
setblock ~185 ~122 ~115 dirt
setblock ~185 ~122 ~116 dirt
setblock ~185 ~122 ~117 dirt
setblock ~185 ~122 ~118 dirt
setblock ~185 ~122 ~119 dirt
setblock ~185 ~122 ~120 dirt
setblock ~185 ~122 ~121 dirt
setblock ~185 ~122 ~122 dirt
setblock ~185 ~122 ~123 dirt
setblock ~185 ~122 ~124 dirt
setblock ~185 ~122 ~125 dirt
setblock ~185 ~122 ~126 dirt
setblock ~185 ~122 ~127 dirt
setblock ~185 ~123 ~68 dirt
setblock ~185 ~123 ~69 dirt
setblock ~185 ~123 ~70 dirt
setblock ~185 ~123 ~71 dirt
setblock ~185 ~123 ~72 dirt
setblock ~185 ~123 ~73 dirt
setblock ~185 ~123 ~74 dirt
setblock ~185 ~123 ~75 dirt
setblock ~185 ~123 ~79 dirt
setblock ~185 ~123 ~80 dirt
setblock ~185 ~123 ~81 dirt
setblock ~185 ~123 ~82 dirt
setblock ~185 ~123 ~83 dirt
setblock ~185 ~123 ~84 dirt
setblock ~185 ~123 ~85 dirt
setblock ~185 ~123 ~86 grass_block
setblock ~185 ~123 ~87 grass_block
setblock ~185 ~123 ~88 grass_block
setblock ~185 ~123 ~92 grass_block
setblock ~185 ~123 ~93 grass_block
setblock ~185 ~123 ~94 grass_block
setblock ~185 ~123 ~95 dirt
