setblock ~25 ~115 ~113 dirt
setblock ~25 ~115 ~114 dirt
setblock ~25 ~115 ~115 dirt
setblock ~25 ~115 ~116 dirt
setblock ~25 ~115 ~117 dirt
setblock ~25 ~116 ~53 dirt
setblock ~25 ~116 ~54 dirt
setblock ~25 ~116 ~55 dirt
setblock ~25 ~116 ~56 dirt
setblock ~25 ~116 ~57 dirt
setblock ~25 ~116 ~58 dirt
setblock ~25 ~116 ~59 dirt
setblock ~25 ~116 ~60 dirt
setblock ~25 ~116 ~61 dirt
setblock ~25 ~116 ~62 dirt
setblock ~25 ~116 ~63 dirt
setblock ~25 ~116 ~98 dirt
setblock ~25 ~116 ~99 dirt
setblock ~25 ~116 ~100 dirt
setblock ~25 ~116 ~101 dirt
setblock ~25 ~116 ~102 dirt
setblock ~25 ~116 ~103 dirt
setblock ~25 ~116 ~104 dirt
setblock ~25 ~116 ~105 dirt
setblock ~25 ~116 ~106 dirt
setblock ~25 ~116 ~107 dirt
setblock ~25 ~116 ~108 dirt
setblock ~25 ~116 ~109 dirt
setblock ~25 ~116 ~110 dirt
setblock ~25 ~116 ~111 dirt
setblock ~25 ~116 ~112 dirt
setblock ~25 ~116 ~113 dirt
setblock ~25 ~116 ~114 dirt
setblock ~25 ~116 ~115 dirt
setblock ~25 ~116 ~116 dirt
setblock ~25 ~116 ~117 dirt
setblock ~25 ~116 ~118 dirt
setblock ~25 ~117 ~52 dirt
setblock ~25 ~117 ~53 dirt
setblock ~25 ~117 ~54 dirt
setblock ~25 ~117 ~55 dirt
setblock ~25 ~117 ~56 dirt
setblock ~25 ~117 ~57 dirt
setblock ~25 ~117 ~58 dirt
setblock ~25 ~117 ~59 dirt
setblock ~25 ~117 ~60 dirt
setblock ~25 ~117 ~61 dirt
setblock ~25 ~117 ~62 dirt
setblock ~25 ~117 ~63 dirt
setblock ~25 ~117 ~64 dirt
setblock ~25 ~117 ~97 dirt
setblock ~25 ~117 ~98 dirt
setblock ~25 ~117 ~99 dirt
setblock ~25 ~117 ~100 dirt
setblock ~25 ~117 ~101 dirt
setblock ~25 ~117 ~102 dirt
setblock ~25 ~117 ~103 dirt
setblock ~25 ~117 ~104 dirt
setblock ~25 ~117 ~105 dirt
setblock ~25 ~117 ~106 dirt
setblock ~25 ~117 ~107 dirt
setblock ~25 ~117 ~108 dirt
setblock ~25 ~117 ~109 dirt
setblock ~25 ~117 ~110 dirt
setblock ~25 ~117 ~111 dirt
setblock ~25 ~117 ~112 dirt
setblock ~25 ~117 ~113 dirt
setblock ~25 ~117 ~114 dirt
setblock ~25 ~117 ~115 dirt
setblock ~25 ~117 ~116 dirt
setblock ~25 ~117 ~117 dirt
setblock ~25 ~117 ~118 dirt
setblock ~25 ~117 ~119 dirt
setblock ~25 ~118 ~51 dirt
setblock ~25 ~118 ~52 dirt
setblock ~25 ~118 ~53 dirt
setblock ~25 ~118 ~54 dirt
setblock ~25 ~118 ~55 dirt
setblock ~25 ~118 ~56 dirt
setblock ~25 ~118 ~57 dirt
setblock ~25 ~118 ~58 dirt
setblock ~25 ~118 ~59 dirt
setblock ~25 ~118 ~60 dirt
setblock ~25 ~118 ~61 dirt
setblock ~25 ~118 ~62 dirt
setblock ~25 ~118 ~63 dirt
setblock ~25 ~118 ~64 dirt
setblock ~25 ~118 ~65 dirt
setblock ~25 ~118 ~96 dirt
setblock ~25 ~118 ~97 dirt
setblock ~25 ~118 ~98 dirt
setblock ~25 ~118 ~99 dirt
setblock ~25 ~118 ~100 dirt
setblock ~25 ~118 ~101 dirt
setblock ~25 ~118 ~102 dirt
setblock ~25 ~118 ~103 dirt
setblock ~25 ~118 ~104 dirt
setblock ~25 ~118 ~105 dirt
setblock ~25 ~118 ~106 dirt
setblock ~25 ~118 ~107 dirt
setblock ~25 ~118 ~108 dirt
setblock ~25 ~118 ~109 dirt
setblock ~25 ~118 ~110 dirt
setblock ~25 ~118 ~111 dirt
setblock ~25 ~118 ~112 dirt
setblock ~25 ~118 ~113 dirt
setblock ~25 ~118 ~114 dirt
setblock ~25 ~118 ~115 dirt
setblock ~25 ~118 ~116 dirt
setblock ~25 ~118 ~117 dirt
setblock ~25 ~118 ~118 dirt
setblock ~25 ~118 ~119 dirt
setblock ~25 ~118 ~120 dirt
setblock ~25 ~119 ~51 dirt
setblock ~25 ~119 ~52 dirt
setblock ~25 ~119 ~53 dirt
setblock ~25 ~119 ~54 dirt
setblock ~25 ~119 ~55 dirt
setblock ~25 ~119 ~56 dirt
setblock ~25 ~119 ~57 dirt
setblock ~25 ~119 ~58 dirt
setblock ~25 ~119 ~59 dirt
setblock ~25 ~119 ~60 dirt
setblock ~25 ~119 ~61 dirt
setblock ~25 ~119 ~62 dirt
setblock ~25 ~119 ~63 dirt
setblock ~25 ~119 ~64 dirt
setblock ~25 ~119 ~65 dirt
setblock ~25 ~119 ~66 dirt
setblock ~25 ~119 ~95 dirt
setblock ~25 ~119 ~96 dirt
setblock ~25 ~119 ~97 dirt
setblock ~25 ~119 ~98 dirt
setblock ~25 ~119 ~99 dirt
setblock ~25 ~119 ~100 dirt
setblock ~25 ~119 ~101 dirt
setblock ~25 ~119 ~102 dirt
setblock ~25 ~119 ~103 dirt
setblock ~25 ~119 ~104 dirt
setblock ~25 ~119 ~105 dirt
setblock ~25 ~119 ~106 dirt
setblock ~25 ~119 ~107 dirt
setblock ~25 ~119 ~108 dirt
setblock ~25 ~119 ~109 dirt
setblock ~25 ~119 ~110 dirt
setblock ~25 ~119 ~111 dirt
setblock ~25 ~119 ~112 dirt
setblock ~25 ~119 ~113 dirt
setblock ~25 ~119 ~114 dirt
setblock ~25 ~119 ~115 dirt
setblock ~25 ~119 ~116 dirt
setblock ~25 ~119 ~117 dirt
setblock ~25 ~119 ~118 dirt
setblock ~25 ~119 ~119 dirt
setblock ~25 ~119 ~120 dirt
setblock ~25 ~119 ~121 dirt
setblock ~25 ~120 ~50 dirt
setblock ~25 ~120 ~51 dirt
setblock ~25 ~120 ~52 dirt
setblock ~25 ~120 ~53 dirt
setblock ~25 ~120 ~54 dirt
setblock ~25 ~120 ~55 dirt
setblock ~25 ~120 ~56 dirt
setblock ~25 ~120 ~57 dirt
setblock ~25 ~120 ~58 dirt
setblock ~25 ~120 ~59 dirt
setblock ~25 ~120 ~60 dirt
setblock ~25 ~120 ~61 dirt
setblock ~25 ~120 ~62 dirt
setblock ~25 ~120 ~63 dirt
setblock ~25 ~120 ~64 dirt
setblock ~25 ~120 ~65 dirt
setblock ~25 ~120 ~66 dirt
setblock ~25 ~120 ~67 dirt
setblock ~25 ~120 ~90 dirt
setblock ~25 ~120 ~93 dirt
setblock ~25 ~120 ~94 dirt
setblock ~25 ~120 ~95 dirt
setblock ~25 ~120 ~96 dirt
setblock ~25 ~120 ~97 dirt
setblock ~25 ~120 ~98 dirt
setblock ~25 ~120 ~99 dirt
setblock ~25 ~120 ~100 dirt
setblock ~25 ~120 ~101 dirt
setblock ~25 ~120 ~102 dirt
setblock ~25 ~120 ~103 dirt
setblock ~25 ~120 ~104 dirt
setblock ~25 ~120 ~105 dirt
setblock ~25 ~120 ~106 dirt
setblock ~25 ~120 ~107 dirt
setblock ~25 ~120 ~108 dirt
setblock ~25 ~120 ~109 dirt
setblock ~25 ~120 ~110 dirt
setblock ~25 ~120 ~111 dirt
setblock ~25 ~120 ~112 dirt
setblock ~25 ~120 ~113 dirt
setblock ~25 ~120 ~114 dirt
setblock ~25 ~120 ~115 dirt
setblock ~25 ~120 ~116 dirt
setblock ~25 ~120 ~117 dirt
setblock ~25 ~120 ~118 dirt
setblock ~25 ~120 ~119 dirt
setblock ~25 ~120 ~120 dirt
setblock ~25 ~120 ~121 dirt
setblock ~25 ~121 ~50 dirt
setblock ~25 ~121 ~51 dirt
setblock ~25 ~121 ~52 dirt
setblock ~25 ~121 ~53 dirt
setblock ~25 ~121 ~54 dirt
setblock ~25 ~121 ~55 dirt
setblock ~25 ~121 ~56 dirt
setblock ~25 ~121 ~57 dirt
setblock ~25 ~121 ~58 dirt
setblock ~25 ~121 ~59 dirt
setblock ~25 ~121 ~60 dirt
setblock ~25 ~121 ~61 dirt
setblock ~25 ~121 ~62 dirt
setblock ~25 ~121 ~63 dirt
setblock ~25 ~121 ~64 dirt
setblock ~25 ~121 ~65 dirt
setblock ~25 ~121 ~66 dirt
setblock ~25 ~121 ~67 dirt
setblock ~25 ~121 ~68 dirt
setblock ~25 ~121 ~90 dirt
setblock ~25 ~121 ~91 dirt
setblock ~25 ~121 ~92 dirt
setblock ~25 ~121 ~93 dirt
setblock ~25 ~121 ~94 dirt
setblock ~25 ~121 ~95 dirt
setblock ~25 ~121 ~96 dirt
setblock ~25 ~121 ~97 dirt
setblock ~25 ~121 ~98 dirt
setblock ~25 ~121 ~99 dirt
setblock ~25 ~121 ~100 dirt
setblock ~25 ~121 ~101 dirt
setblock ~25 ~121 ~102 dirt
setblock ~25 ~121 ~103 dirt
setblock ~25 ~121 ~104 dirt
setblock ~25 ~121 ~105 dirt
setblock ~25 ~121 ~106 dirt
setblock ~25 ~121 ~107 dirt
setblock ~25 ~121 ~108 dirt
setblock ~25 ~121 ~109 dirt
setblock ~25 ~121 ~110 dirt
setblock ~25 ~121 ~111 dirt
setblock ~25 ~121 ~112 dirt
setblock ~25 ~121 ~113 dirt
setblock ~25 ~121 ~114 dirt
setblock ~25 ~121 ~115 dirt
setblock ~25 ~121 ~116 dirt
setblock ~25 ~121 ~117 dirt
setblock ~25 ~121 ~118 dirt
setblock ~25 ~121 ~119 dirt
setblock ~25 ~121 ~120 dirt
setblock ~25 ~121 ~121 dirt
setblock ~25 ~121 ~122 dirt
setblock ~25 ~122 ~50 dirt
setblock ~25 ~122 ~51 dirt
setblock ~25 ~122 ~52 dirt
setblock ~25 ~122 ~53 dirt
setblock ~25 ~122 ~54 dirt
setblock ~25 ~122 ~55 dirt
setblock ~25 ~122 ~56 dirt
setblock ~25 ~122 ~57 dirt
setblock ~25 ~122 ~58 dirt
setblock ~25 ~122 ~59 dirt
setblock ~25 ~122 ~60 dirt
setblock ~25 ~122 ~61 dirt
setblock ~25 ~122 ~62 dirt
setblock ~25 ~122 ~63 dirt
setblock ~25 ~122 ~64 dirt
setblock ~25 ~122 ~65 dirt
setblock ~25 ~122 ~66 dirt
setblock ~25 ~122 ~67 dirt
setblock ~25 ~122 ~68 dirt
setblock ~25 ~122 ~90 dirt
setblock ~25 ~122 ~91 dirt
setblock ~25 ~122 ~92 dirt
setblock ~25 ~122 ~93 dirt
setblock ~25 ~122 ~94 dirt
setblock ~25 ~122 ~95 dirt
setblock ~25 ~122 ~96 dirt
setblock ~25 ~122 ~97 dirt
setblock ~25 ~122 ~98 dirt
setblock ~25 ~122 ~99 dirt
setblock ~25 ~122 ~100 dirt
setblock ~25 ~122 ~101 dirt
setblock ~25 ~122 ~102 dirt
setblock ~25 ~122 ~103 dirt
setblock ~25 ~122 ~104 dirt
setblock ~25 ~122 ~105 dirt
setblock ~25 ~122 ~106 dirt
setblock ~25 ~122 ~107 dirt
setblock ~25 ~122 ~108 dirt
setblock ~25 ~122 ~109 dirt
setblock ~25 ~122 ~110 dirt
setblock ~25 ~122 ~111 dirt
setblock ~25 ~122 ~112 dirt
setblock ~25 ~122 ~113 dirt
setblock ~25 ~122 ~114 dirt
setblock ~25 ~122 ~115 dirt
setblock ~25 ~122 ~116 dirt
setblock ~25 ~122 ~117 dirt
setblock ~25 ~122 ~118 dirt
setblock ~25 ~122 ~119 dirt
setblock ~25 ~122 ~120 dirt
setblock ~25 ~122 ~121 dirt
setblock ~25 ~122 ~122 dirt
setblock ~25 ~123 ~50 dirt
setblock ~25 ~123 ~51 dirt
setblock ~25 ~123 ~52 dirt
setblock ~25 ~123 ~53 dirt
setblock ~25 ~123 ~54 dirt
setblock ~25 ~123 ~55 dirt
setblock ~25 ~123 ~56 dirt
setblock ~25 ~123 ~57 dirt
setblock ~25 ~123 ~58 dirt
setblock ~25 ~123 ~59 dirt
setblock ~25 ~123 ~60 dirt
setblock ~25 ~123 ~61 dirt
setblock ~25 ~123 ~62 dirt
setblock ~25 ~123 ~63 dirt
setblock ~25 ~123 ~64 dirt
setblock ~25 ~123 ~65 dirt
setblock ~25 ~123 ~66 dirt
setblock ~25 ~123 ~67 dirt
setblock ~25 ~123 ~68 dirt
setblock ~25 ~123 ~90 dirt
setblock ~25 ~123 ~91 dirt
setblock ~25 ~123 ~92 dirt
setblock ~25 ~123 ~93 dirt
setblock ~25 ~123 ~94 dirt
setblock ~25 ~123 ~95 dirt
setblock ~25 ~123 ~96 dirt
setblock ~25 ~123 ~97 dirt
setblock ~25 ~123 ~98 dirt
setblock ~25 ~123 ~99 dirt
setblock ~25 ~123 ~100 dirt
setblock ~25 ~123 ~101 dirt
setblock ~25 ~123 ~102 dirt
setblock ~25 ~123 ~103 dirt
setblock ~25 ~123 ~104 dirt
setblock ~25 ~123 ~105 dirt
setblock ~25 ~123 ~106 dirt
setblock ~25 ~123 ~107 dirt
setblock ~25 ~123 ~108 dirt
setblock ~25 ~123 ~109 dirt
setblock ~25 ~123 ~110 dirt
setblock ~25 ~123 ~111 dirt
setblock ~25 ~123 ~112 dirt
setblock ~25 ~123 ~113 dirt
setblock ~25 ~123 ~114 dirt
setblock ~25 ~123 ~115 dirt
setblock ~25 ~123 ~116 dirt
setblock ~25 ~123 ~117 dirt
setblock ~25 ~123 ~118 dirt
setblock ~25 ~123 ~119 grass_block
setblock ~25 ~123 ~120 grass_block
setblock ~25 ~123 ~121 grass_block
setblock ~25 ~123 ~122 grass_block
setblock ~25 ~124 ~50 dirt
setblock ~25 ~124 ~51 dirt
setblock ~25 ~124 ~52 dirt
setblock ~25 ~124 ~53 dirt
setblock ~25 ~124 ~54 dirt
setblock ~25 ~124 ~55 dirt
setblock ~25 ~124 ~56 dirt
setblock ~25 ~124 ~57 dirt
setblock ~25 ~124 ~58 dirt
setblock ~25 ~124 ~59 grass_block
setblock ~25 ~124 ~60 grass_block
setblock ~25 ~124 ~61 grass_block
setblock ~25 ~124 ~62 grass_block
setblock ~25 ~124 ~63 dirt
setblock ~25 ~124 ~64 dirt
setblock ~25 ~124 ~65 dirt
setblock ~25 ~124 ~66 dirt
setblock ~25 ~124 ~67 dirt
setblock ~25 ~124 ~68 dirt
setblock ~25 ~124 ~90 dirt
setblock ~25 ~124 ~91 dirt
setblock ~25 ~124 ~92 dirt
setblock ~25 ~124 ~93 dirt
setblock ~25 ~124 ~94 dirt
setblock ~25 ~124 ~95 dirt
setblock ~25 ~124 ~96 dirt
setblock ~25 ~124 ~97 dirt
setblock ~25 ~124 ~98 grass_block
setblock ~25 ~124 ~99 grass_block
setblock ~25 ~124 ~100 grass_block
setblock ~25 ~124 ~101 grass_block
setblock ~25 ~124 ~102 dirt
setblock ~25 ~124 ~103 dirt
setblock ~25 ~124 ~104 dirt
setblock ~25 ~124 ~105 dirt
setblock ~25 ~124 ~106 dirt
setblock ~25 ~124 ~107 dirt
setblock ~25 ~124 ~108 dirt
setblock ~25 ~124 ~109 dirt
setblock ~25 ~124 ~110 dirt
setblock ~25 ~124 ~111 dirt
setblock ~25 ~124 ~112 dirt
setblock ~25 ~124 ~113 dirt
setblock ~25 ~124 ~114 dirt
setblock ~25 ~124 ~115 dirt
setblock ~25 ~124 ~116 dirt
setblock ~25 ~124 ~117 grass_block
setblock ~25 ~124 ~118 grass_block
setblock ~25 ~124 ~119 short_grass
setblock ~25 ~124 ~122 short_grass
setblock ~25 ~125 ~50 dirt
setblock ~25 ~125 ~51 dirt
setblock ~25 ~125 ~52 grass_block
setblock ~25 ~125 ~53 grass_block
setblock ~25 ~125 ~54 grass_block
setblock ~25 ~125 ~55 grass_block
setblock ~25 ~125 ~56 grass_block
setblock ~25 ~125 ~57 grass_block
setblock ~25 ~125 ~58 grass_block
setblock ~25 ~125 ~60 short_grass
setblock ~25 ~125 ~62 short_grass
setblock ~25 ~125 ~63 grass_block
setblock ~25 ~125 ~64 grass_block
setblock ~25 ~125 ~65 grass_block
setblock ~25 ~125 ~66 grass_block
setblock ~25 ~125 ~67 grass_block
setblock ~25 ~125 ~68 grass_block
setblock ~25 ~125 ~90 dirt
setblock ~25 ~125 ~91 dirt
setblock ~25 ~125 ~92 dirt
setblock ~25 ~125 ~93 grass_block
setblock ~25 ~125 ~94 grass_block
setblock ~25 ~125 ~95 grass_block
setblock ~25 ~125 ~96 grass_block
setblock ~25 ~125 ~97 grass_block
setblock ~25 ~125 ~98 short_grass
setblock ~25 ~125 ~99 short_grass
setblock ~25 ~125 ~100 short_grass
setblock ~25 ~125 ~102 grass_block
setblock ~25 ~125 ~103 grass_block
setblock ~25 ~125 ~104 grass_block
setblock ~25 ~125 ~105 dirt
setblock ~25 ~125 ~106 dirt
setblock ~25 ~125 ~107 dirt
setblock ~25 ~125 ~108 dirt
setblock ~25 ~125 ~109 dirt
setblock ~25 ~125 ~110 dirt
setblock ~25 ~125 ~111 dirt
setblock ~25 ~125 ~112 dirt
setblock ~25 ~125 ~113 dirt
setblock ~25 ~125 ~114 grass_block
setblock ~25 ~125 ~115 grass_block
setblock ~25 ~125 ~116 grass_block
setblock ~25 ~126 ~50 grass_block
setblock ~25 ~126 ~51 grass_block
setblock ~25 ~126 ~52 short_grass
setblock ~25 ~126 ~53 short_grass
setblock ~25 ~126 ~54 poppy
setblock ~25 ~126 ~57 poppy
setblock ~25 ~126 ~65 short_grass
setblock ~25 ~126 ~66 poppy
setblock ~25 ~126 ~90 grass_block
setblock ~25 ~126 ~91 grass_block
setblock ~25 ~126 ~92 grass_block
setblock ~25 ~126 ~104 short_grass
setblock ~25 ~126 ~105 grass_block
setblock ~25 ~126 ~106 grass_block
setblock ~25 ~126 ~107 grass_block
setblock ~25 ~126 ~108 dirt
setblock ~25 ~126 ~109 dirt
setblock ~25 ~126 ~110 dirt
setblock ~25 ~126 ~111 dirt
setblock ~25 ~126 ~112 grass_block
setblock ~25 ~126 ~113 grass_block
setblock ~25 ~126 ~114 short_grass
setblock ~25 ~127 ~50 short_grass
setblock ~25 ~127 ~105 short_grass
setblock ~25 ~127 ~108 grass_block
setblock ~25 ~127 ~109 grass_block
setblock ~25 ~127 ~110 grass_block
setblock ~25 ~127 ~111 grass_block
setblock ~25 ~127 ~112 poppy
setblock ~25 ~128 ~108 short_grass
setblock ~25 ~128 ~110 short_grass
setblock ~26 ~108 ~106 dirt
setblock ~26 ~109 ~106 dirt
setblock ~26 ~109 ~107 dirt
setblock ~26 ~109 ~108 dirt
setblock ~26 ~109 ~109 dirt
setblock ~26 ~110 ~105 dirt
setblock ~26 ~110 ~106 dirt
setblock ~26 ~110 ~107 dirt
setblock ~26 ~110 ~108 dirt
setblock ~26 ~110 ~109 dirt
setblock ~26 ~110 ~110 dirt
setblock ~26 ~110 ~111 dirt
setblock ~26 ~111 ~104 dirt
setblock ~26 ~111 ~105 dirt
setblock ~26 ~111 ~106 dirt
setblock ~26 ~111 ~107 dirt
setblock ~26 ~111 ~108 dirt
setblock ~26 ~111 ~109 dirt
setblock ~26 ~111 ~110 dirt
setblock ~26 ~111 ~111 dirt
setblock ~26 ~111 ~112 dirt
setblock ~26 ~112 ~58 dirt
setblock ~26 ~112 ~59 dirt
setblock ~26 ~112 ~103 dirt
setblock ~26 ~112 ~104 dirt
setblock ~26 ~112 ~105 dirt
setblock ~26 ~112 ~106 dirt
setblock ~26 ~112 ~107 dirt
setblock ~26 ~112 ~108 dirt
setblock ~26 ~112 ~109 dirt
setblock ~26 ~112 ~110 dirt
setblock ~26 ~112 ~111 dirt
setblock ~26 ~112 ~112 dirt
setblock ~26 ~112 ~113 dirt
setblock ~26 ~113 ~57 dirt
setblock ~26 ~113 ~58 dirt
setblock ~26 ~113 ~59 dirt
setblock ~26 ~113 ~60 dirt
setblock ~26 ~113 ~61 dirt
setblock ~26 ~113 ~102 dirt
setblock ~26 ~113 ~103 dirt
setblock ~26 ~113 ~104 dirt
setblock ~26 ~113 ~105 dirt
setblock ~26 ~113 ~106 dirt
setblock ~26 ~113 ~107 dirt
setblock ~26 ~113 ~108 dirt
setblock ~26 ~113 ~109 dirt
setblock ~26 ~113 ~110 dirt
setblock ~26 ~113 ~111 dirt
setblock ~26 ~113 ~112 dirt
setblock ~26 ~113 ~113 dirt
setblock ~26 ~113 ~114 dirt
setblock ~26 ~114 ~55 dirt
setblock ~26 ~114 ~56 dirt
setblock ~26 ~114 ~57 dirt
setblock ~26 ~114 ~58 dirt
setblock ~26 ~114 ~59 dirt
setblock ~26 ~114 ~60 dirt
setblock ~26 ~114 ~61 dirt
setblock ~26 ~114 ~62 dirt
setblock ~26 ~114 ~101 dirt
setblock ~26 ~114 ~102 dirt
setblock ~26 ~114 ~103 dirt
setblock ~26 ~114 ~104 dirt
setblock ~26 ~114 ~105 dirt
setblock ~26 ~114 ~106 dirt
setblock ~26 ~114 ~107 dirt
setblock ~26 ~114 ~108 dirt
setblock ~26 ~114 ~109 dirt
setblock ~26 ~114 ~110 dirt
setblock ~26 ~114 ~111 dirt
setblock ~26 ~114 ~112 dirt
setblock ~26 ~114 ~113 dirt
setblock ~26 ~114 ~114 dirt
setblock ~26 ~114 ~115 dirt
setblock ~26 ~115 ~54 dirt
setblock ~26 ~115 ~55 dirt
setblock ~26 ~115 ~56 dirt
setblock ~26 ~115 ~57 dirt
setblock ~26 ~115 ~58 dirt
setblock ~26 ~115 ~59 dirt
setblock ~26 ~115 ~60 dirt
setblock ~26 ~115 ~61 dirt
setblock ~26 ~115 ~62 dirt
setblock ~26 ~115 ~63 dirt
setblock ~26 ~115 ~100 dirt
setblock ~26 ~115 ~101 dirt
setblock ~26 ~115 ~102 dirt
setblock ~26 ~115 ~103 dirt
setblock ~26 ~115 ~104 dirt
setblock ~26 ~115 ~105 dirt
setblock ~26 ~115 ~106 dirt
setblock ~26 ~115 ~107 dirt
setblock ~26 ~115 ~108 dirt
setblock ~26 ~115 ~109 dirt
setblock ~26 ~115 ~110 dirt
setblock ~26 ~115 ~111 dirt
setblock ~26 ~115 ~112 dirt
setblock ~26 ~115 ~113 dirt
setblock ~26 ~115 ~114 dirt
setblock ~26 ~115 ~115 dirt
setblock ~26 ~115 ~116 dirt
setblock ~26 ~116 ~54 dirt
setblock ~26 ~116 ~55 dirt
setblock ~26 ~116 ~56 dirt
setblock ~26 ~116 ~57 dirt
setblock ~26 ~116 ~58 dirt
setblock ~26 ~116 ~59 dirt
setblock ~26 ~116 ~60 dirt
setblock ~26 ~116 ~61 dirt
setblock ~26 ~116 ~62 dirt
setblock ~26 ~116 ~63 dirt
setblock ~26 ~116 ~64 dirt
setblock ~26 ~116 ~99 dirt
setblock ~26 ~116 ~100 dirt
setblock ~26 ~116 ~101 dirt
setblock ~26 ~116 ~102 dirt
setblock ~26 ~116 ~103 dirt
setblock ~26 ~116 ~104 dirt
setblock ~26 ~116 ~105 dirt
setblock ~26 ~116 ~106 dirt
setblock ~26 ~116 ~107 dirt
setblock ~26 ~116 ~108 dirt
setblock ~26 ~116 ~109 dirt
setblock ~26 ~116 ~110 dirt
setblock ~26 ~116 ~111 dirt
setblock ~26 ~116 ~112 dirt
setblock ~26 ~116 ~113 dirt
setblock ~26 ~116 ~114 dirt
setblock ~26 ~116 ~115 dirt
setblock ~26 ~116 ~116 dirt
setblock ~26 ~116 ~117 dirt
setblock ~26 ~117 ~53 dirt
setblock ~26 ~117 ~54 dirt
setblock ~26 ~117 ~55 dirt
setblock ~26 ~117 ~56 dirt
setblock ~26 ~117 ~57 dirt
setblock ~26 ~117 ~58 dirt
setblock ~26 ~117 ~59 dirt
setblock ~26 ~117 ~60 dirt
setblock ~26 ~117 ~61 dirt
setblock ~26 ~117 ~62 dirt
setblock ~26 ~117 ~63 dirt
setblock ~26 ~117 ~64 dirt
setblock ~26 ~117 ~65 dirt
setblock ~26 ~117 ~91 dirt
setblock ~26 ~117 ~95 dirt
setblock ~26 ~117 ~98 dirt
setblock ~26 ~117 ~99 dirt
setblock ~26 ~117 ~100 dirt
setblock ~26 ~117 ~101 dirt
setblock ~26 ~117 ~102 dirt
setblock ~26 ~117 ~103 dirt
setblock ~26 ~117 ~104 dirt
setblock ~26 ~117 ~105 dirt
setblock ~26 ~117 ~106 dirt
setblock ~26 ~117 ~107 dirt
setblock ~26 ~117 ~108 dirt
setblock ~26 ~117 ~109 dirt
setblock ~26 ~117 ~110 dirt
setblock ~26 ~117 ~111 dirt
setblock ~26 ~117 ~112 dirt
setblock ~26 ~117 ~113 dirt
setblock ~26 ~117 ~114 dirt
setblock ~26 ~117 ~115 dirt
setblock ~26 ~117 ~116 dirt
setblock ~26 ~117 ~117 dirt
setblock ~26 ~117 ~118 dirt
setblock ~26 ~118 ~52 dirt
setblock ~26 ~118 ~53 dirt
setblock ~26 ~118 ~54 dirt
setblock ~26 ~118 ~55 dirt
setblock ~26 ~118 ~56 dirt
setblock ~26 ~118 ~57 dirt
setblock ~26 ~118 ~58 dirt
setblock ~26 ~118 ~59 dirt
setblock ~26 ~118 ~60 dirt
setblock ~26 ~118 ~61 dirt
setblock ~26 ~118 ~62 dirt
setblock ~26 ~118 ~63 dirt
setblock ~26 ~118 ~64 dirt
setblock ~26 ~118 ~65 dirt
setblock ~26 ~118 ~66 dirt
setblock ~26 ~118 ~91 dirt
setblock ~26 ~118 ~95 dirt
setblock ~26 ~118 ~97 dirt
setblock ~26 ~118 ~98 dirt
setblock ~26 ~118 ~99 dirt
setblock ~26 ~118 ~100 dirt
setblock ~26 ~118 ~101 dirt
setblock ~26 ~118 ~102 dirt
setblock ~26 ~118 ~103 dirt
setblock ~26 ~118 ~104 dirt
setblock ~26 ~118 ~105 dirt
setblock ~26 ~118 ~106 dirt
setblock ~26 ~118 ~107 dirt
setblock ~26 ~118 ~108 dirt
setblock ~26 ~118 ~109 dirt
setblock ~26 ~118 ~110 dirt
setblock ~26 ~118 ~111 dirt
setblock ~26 ~118 ~112 dirt
setblock ~26 ~118 ~113 dirt
setblock ~26 ~118 ~114 dirt
setblock ~26 ~118 ~115 dirt
setblock ~26 ~118 ~116 dirt
setblock ~26 ~118 ~117 dirt
setblock ~26 ~118 ~118 dirt
setblock ~26 ~118 ~119 dirt
setblock ~26 ~119 ~51 dirt
setblock ~26 ~119 ~52 dirt
setblock ~26 ~119 ~53 dirt
setblock ~26 ~119 ~54 dirt
setblock ~26 ~119 ~55 dirt
setblock ~26 ~119 ~56 dirt
setblock ~26 ~119 ~57 dirt
setblock ~26 ~119 ~58 dirt
setblock ~26 ~119 ~59 dirt
setblock ~26 ~119 ~60 dirt
setblock ~26 ~119 ~61 dirt
setblock ~26 ~119 ~62 dirt
setblock ~26 ~119 ~63 dirt
setblock ~26 ~119 ~64 dirt
setblock ~26 ~119 ~65 dirt
setblock ~26 ~119 ~66 dirt
setblock ~26 ~119 ~67 dirt
setblock ~26 ~119 ~90 dirt
setblock ~26 ~119 ~91 dirt
setblock ~26 ~119 ~92 dirt
setblock ~26 ~119 ~93 dirt
setblock ~26 ~119 ~94 dirt
setblock ~26 ~119 ~95 dirt
setblock ~26 ~119 ~96 dirt
setblock ~26 ~119 ~97 dirt
setblock ~26 ~119 ~98 dirt
setblock ~26 ~119 ~99 dirt
setblock ~26 ~119 ~100 dirt
setblock ~26 ~119 ~101 dirt
setblock ~26 ~119 ~102 dirt
setblock ~26 ~119 ~103 dirt
setblock ~26 ~119 ~104 dirt
setblock ~26 ~119 ~105 dirt
setblock ~26 ~119 ~106 dirt
setblock ~26 ~119 ~107 dirt
setblock ~26 ~119 ~108 dirt
setblock ~26 ~119 ~109 dirt
setblock ~26 ~119 ~110 dirt
setblock ~26 ~119 ~111 dirt
setblock ~26 ~119 ~112 dirt
setblock ~26 ~119 ~113 dirt
setblock ~26 ~119 ~114 dirt
setblock ~26 ~119 ~115 dirt
setblock ~26 ~119 ~116 dirt
setblock ~26 ~119 ~117 dirt
setblock ~26 ~119 ~118 dirt
setblock ~26 ~119 ~119 dirt
setblock ~26 ~119 ~120 dirt
setblock ~26 ~120 ~50 dirt
setblock ~26 ~120 ~51 dirt
setblock ~26 ~120 ~52 dirt
setblock ~26 ~120 ~53 dirt
setblock ~26 ~120 ~54 dirt
setblock ~26 ~120 ~55 dirt
setblock ~26 ~120 ~56 dirt
setblock ~26 ~120 ~57 dirt
setblock ~26 ~120 ~58 dirt
setblock ~26 ~120 ~59 dirt
setblock ~26 ~120 ~60 dirt
setblock ~26 ~120 ~61 dirt
setblock ~26 ~120 ~62 dirt
setblock ~26 ~120 ~63 dirt
setblock ~26 ~120 ~64 dirt
setblock ~26 ~120 ~65 dirt
setblock ~26 ~120 ~66 dirt
setblock ~26 ~120 ~67 dirt
setblock ~26 ~120 ~68 dirt
setblock ~26 ~120 ~89 dirt
setblock ~26 ~120 ~90 dirt
setblock ~26 ~120 ~91 dirt
setblock ~26 ~120 ~92 dirt
setblock ~26 ~120 ~93 dirt
setblock ~26 ~120 ~94 dirt
setblock ~26 ~120 ~95 dirt
setblock ~26 ~120 ~96 dirt
setblock ~26 ~120 ~97 dirt
setblock ~26 ~120 ~98 dirt
setblock ~26 ~120 ~99 dirt
setblock ~26 ~120 ~100 dirt
setblock ~26 ~120 ~101 dirt
setblock ~26 ~120 ~102 dirt
setblock ~26 ~120 ~103 dirt
setblock ~26 ~120 ~104 dirt
setblock ~26 ~120 ~105 dirt
setblock ~26 ~120 ~106 dirt
setblock ~26 ~120 ~107 dirt
setblock ~26 ~120 ~108 dirt
setblock ~26 ~120 ~109 dirt
setblock ~26 ~120 ~110 dirt
setblock ~26 ~120 ~111 dirt
setblock ~26 ~120 ~112 dirt
setblock ~26 ~120 ~113 dirt
setblock ~26 ~120 ~114 dirt
setblock ~26 ~120 ~115 dirt
setblock ~26 ~120 ~116 dirt
setblock ~26 ~120 ~117 dirt
setblock ~26 ~120 ~118 dirt
setblock ~26 ~120 ~119 dirt
setblock ~26 ~120 ~120 dirt
setblock ~26 ~120 ~121 dirt
setblock ~26 ~121 ~49 dirt
setblock ~26 ~121 ~50 dirt
setblock ~26 ~121 ~51 dirt
setblock ~26 ~121 ~52 dirt
setblock ~26 ~121 ~53 dirt
setblock ~26 ~121 ~54 dirt
setblock ~26 ~121 ~55 dirt
setblock ~26 ~121 ~56 dirt
setblock ~26 ~121 ~57 dirt
setblock ~26 ~121 ~58 dirt
setblock ~26 ~121 ~59 dirt
setblock ~26 ~121 ~60 dirt
setblock ~26 ~121 ~61 dirt
setblock ~26 ~121 ~62 dirt
setblock ~26 ~121 ~63 dirt
setblock ~26 ~121 ~64 dirt
setblock ~26 ~121 ~65 dirt
setblock ~26 ~121 ~66 dirt
setblock ~26 ~121 ~67 dirt
setblock ~26 ~121 ~68 dirt
setblock ~26 ~121 ~69 dirt
setblock ~26 ~121 ~89 dirt
setblock ~26 ~121 ~90 dirt
setblock ~26 ~121 ~91 dirt
setblock ~26 ~121 ~92 dirt
setblock ~26 ~121 ~93 dirt
setblock ~26 ~121 ~94 dirt
setblock ~26 ~121 ~95 dirt
setblock ~26 ~121 ~96 dirt
setblock ~26 ~121 ~97 dirt
setblock ~26 ~121 ~98 dirt
setblock ~26 ~121 ~99 dirt
setblock ~26 ~121 ~100 dirt
setblock ~26 ~121 ~101 dirt
setblock ~26 ~121 ~102 dirt
setblock ~26 ~121 ~103 dirt
setblock ~26 ~121 ~104 dirt
setblock ~26 ~121 ~105 dirt
setblock ~26 ~121 ~106 dirt
setblock ~26 ~121 ~107 dirt
setblock ~26 ~121 ~108 dirt
setblock ~26 ~121 ~109 dirt
setblock ~26 ~121 ~110 dirt
setblock ~26 ~121 ~111 dirt
setblock ~26 ~121 ~112 dirt
setblock ~26 ~121 ~113 dirt
setblock ~26 ~121 ~114 dirt
setblock ~26 ~121 ~115 dirt
setblock ~26 ~121 ~116 dirt
setblock ~26 ~121 ~117 dirt
setblock ~26 ~121 ~118 dirt
setblock ~26 ~121 ~119 dirt
setblock ~26 ~121 ~120 dirt
setblock ~26 ~121 ~121 dirt
setblock ~26 ~121 ~122 dirt
setblock ~26 ~122 ~49 dirt
setblock ~26 ~122 ~50 dirt
setblock ~26 ~122 ~51 dirt
setblock ~26 ~122 ~52 dirt
setblock ~26 ~122 ~53 dirt
setblock ~26 ~122 ~54 dirt
setblock ~26 ~122 ~55 dirt
setblock ~26 ~122 ~56 dirt
setblock ~26 ~122 ~57 dirt
setblock ~26 ~122 ~58 dirt
setblock ~26 ~122 ~59 dirt
setblock ~26 ~122 ~60 dirt
setblock ~26 ~122 ~61 dirt
setblock ~26 ~122 ~62 dirt
setblock ~26 ~122 ~63 dirt
setblock ~26 ~122 ~64 dirt
setblock ~26 ~122 ~65 dirt
setblock ~26 ~122 ~66 dirt
setblock ~26 ~122 ~67 dirt
setblock ~26 ~122 ~68 dirt
setblock ~26 ~122 ~69 dirt
setblock ~26 ~122 ~89 dirt
setblock ~26 ~122 ~90 dirt
setblock ~26 ~122 ~91 dirt
setblock ~26 ~122 ~92 dirt
setblock ~26 ~122 ~93 dirt
setblock ~26 ~122 ~94 dirt
setblock ~26 ~122 ~95 dirt
setblock ~26 ~122 ~96 dirt
setblock ~26 ~122 ~97 dirt
setblock ~26 ~122 ~98 dirt
setblock ~26 ~122 ~99 dirt
setblock ~26 ~122 ~100 dirt
setblock ~26 ~122 ~101 dirt
setblock ~26 ~122 ~102 dirt
setblock ~26 ~122 ~103 dirt
setblock ~26 ~122 ~104 dirt
setblock ~26 ~122 ~105 dirt
setblock ~26 ~122 ~106 dirt
setblock ~26 ~122 ~107 dirt
setblock ~26 ~122 ~108 dirt
setblock ~26 ~122 ~109 dirt
setblock ~26 ~122 ~110 dirt
setblock ~26 ~122 ~111 dirt
setblock ~26 ~122 ~112 dirt
setblock ~26 ~122 ~113 dirt
setblock ~26 ~122 ~114 dirt
setblock ~26 ~122 ~115 dirt
setblock ~26 ~122 ~116 dirt
setblock ~26 ~122 ~117 dirt
setblock ~26 ~122 ~118 dirt
setblock ~26 ~122 ~119 dirt
setblock ~26 ~122 ~120 dirt
setblock ~26 ~122 ~121 dirt
setblock ~26 ~122 ~122 dirt
setblock ~26 ~123 ~49 dirt
setblock ~26 ~123 ~50 dirt
setblock ~26 ~123 ~51 dirt
setblock ~26 ~123 ~52 dirt
setblock ~26 ~123 ~53 dirt
setblock ~26 ~123 ~54 dirt
setblock ~26 ~123 ~55 dirt
setblock ~26 ~123 ~56 dirt
setblock ~26 ~123 ~57 dirt
setblock ~26 ~123 ~58 dirt
setblock ~26 ~123 ~59 dirt
setblock ~26 ~123 ~60 dirt
setblock ~26 ~123 ~61 dirt
setblock ~26 ~123 ~62 dirt
setblock ~26 ~123 ~63 dirt
setblock ~26 ~123 ~64 dirt
setblock ~26 ~123 ~65 dirt
setblock ~26 ~123 ~66 dirt
setblock ~26 ~123 ~67 dirt
setblock ~26 ~123 ~68 dirt
setblock ~26 ~123 ~69 dirt
setblock ~26 ~123 ~89 dirt
setblock ~26 ~123 ~90 dirt
setblock ~26 ~123 ~91 dirt
setblock ~26 ~123 ~92 dirt
setblock ~26 ~123 ~93 dirt
setblock ~26 ~123 ~94 dirt
setblock ~26 ~123 ~95 dirt
setblock ~26 ~123 ~96 dirt
setblock ~26 ~123 ~97 dirt
setblock ~26 ~123 ~98 dirt
setblock ~26 ~123 ~99 dirt
setblock ~26 ~123 ~100 dirt
setblock ~26 ~123 ~101 dirt
setblock ~26 ~123 ~102 dirt
setblock ~26 ~123 ~103 dirt
setblock ~26 ~123 ~104 dirt
setblock ~26 ~123 ~105 dirt
setblock ~26 ~123 ~106 dirt
setblock ~26 ~123 ~107 dirt
setblock ~26 ~123 ~108 dirt
setblock ~26 ~123 ~109 dirt
setblock ~26 ~123 ~110 dirt
setblock ~26 ~123 ~111 dirt
setblock ~26 ~123 ~112 dirt
setblock ~26 ~123 ~113 dirt
setblock ~26 ~123 ~114 dirt
setblock ~26 ~123 ~115 dirt
setblock ~26 ~123 ~116 dirt
setblock ~26 ~123 ~117 dirt
setblock ~26 ~123 ~118 dirt
setblock ~26 ~123 ~119 dirt
setblock ~26 ~123 ~120 grass_block
setblock ~26 ~123 ~121 grass_block
setblock ~26 ~123 ~122 dirt
setblock ~26 ~124 ~49 dirt
setblock ~26 ~124 ~50 dirt
setblock ~26 ~124 ~51 dirt
setblock ~26 ~124 ~52 dirt
setblock ~26 ~124 ~53 dirt
setblock ~26 ~124 ~54 dirt
setblock ~26 ~124 ~55 dirt
setblock ~26 ~124 ~56 dirt
setblock ~26 ~124 ~57 dirt
setblock ~26 ~124 ~58 dirt
setblock ~26 ~124 ~59 dirt
setblock ~26 ~124 ~60 grass_block
setblock ~26 ~124 ~61 dirt
setblock ~26 ~124 ~62 dirt
setblock ~26 ~124 ~63 dirt
setblock ~26 ~124 ~64 dirt
setblock ~26 ~124 ~65 dirt
setblock ~26 ~124 ~66 dirt
setblock ~26 ~124 ~67 dirt
setblock ~26 ~124 ~68 dirt
setblock ~26 ~124 ~69 dirt
setblock ~26 ~124 ~89 dirt
setblock ~26 ~124 ~90 dirt
setblock ~26 ~124 ~91 dirt
setblock ~26 ~124 ~92 dirt
setblock ~26 ~124 ~93 dirt
setblock ~26 ~124 ~94 dirt
setblock ~26 ~124 ~95 dirt
setblock ~26 ~124 ~96 dirt
setblock ~26 ~124 ~97 dirt
setblock ~26 ~124 ~98 grass_block
setblock ~26 ~124 ~99 grass_block
setblock ~26 ~124 ~100 grass_block
setblock ~26 ~124 ~101 grass_block
setblock ~26 ~124 ~102 dirt
setblock ~26 ~124 ~103 dirt
setblock ~26 ~124 ~104 dirt
setblock ~26 ~124 ~105 dirt
setblock ~26 ~124 ~106 dirt
setblock ~26 ~124 ~107 dirt
setblock ~26 ~124 ~108 dirt
setblock ~26 ~124 ~109 dirt
setblock ~26 ~124 ~110 dirt
setblock ~26 ~124 ~111 dirt
setblock ~26 ~124 ~112 dirt
setblock ~26 ~124 ~113 dirt
setblock ~26 ~124 ~114 dirt
setblock ~26 ~124 ~115 dirt
setblock ~26 ~124 ~116 dirt
setblock ~26 ~124 ~117 grass_block
setblock ~26 ~124 ~118 grass_block
setblock ~26 ~124 ~119 grass_block
setblock ~26 ~124 ~122 grass_block
setblock ~26 ~125 ~49 grass_block
setblock ~26 ~125 ~50 dirt
setblock ~26 ~125 ~51 dirt
setblock ~26 ~125 ~52 dirt
setblock ~26 ~125 ~53 grass_block
setblock ~26 ~125 ~54 grass_block
setblock ~26 ~125 ~55 grass_block
setblock ~26 ~125 ~56 grass_block
setblock ~26 ~125 ~57 grass_block
setblock ~26 ~125 ~58 grass_block
setblock ~26 ~125 ~59 grass_block
setblock ~26 ~125 ~61 grass_block
setblock ~26 ~125 ~62 grass_block
setblock ~26 ~125 ~63 grass_block
setblock ~26 ~125 ~64 grass_block
setblock ~26 ~125 ~65 grass_block
setblock ~26 ~125 ~66 grass_block
setblock ~26 ~125 ~67 grass_block
setblock ~26 ~125 ~68 dirt
setblock ~26 ~125 ~69 dirt
setblock ~26 ~125 ~89 dirt
setblock ~26 ~125 ~90 dirt
setblock ~26 ~125 ~91 dirt
setblock ~26 ~125 ~92 dirt
setblock ~26 ~125 ~93 grass_block
setblock ~26 ~125 ~94 grass_block
setblock ~26 ~125 ~95 grass_block
setblock ~26 ~125 ~96 grass_block
setblock ~26 ~125 ~97 grass_block
setblock ~26 ~125 ~102 grass_block
setblock ~26 ~125 ~103 grass_block
setblock ~26 ~125 ~104 grass_block
setblock ~26 ~125 ~105 dirt
setblock ~26 ~125 ~106 dirt
setblock ~26 ~125 ~107 dirt
setblock ~26 ~125 ~108 dirt
setblock ~26 ~125 ~109 dirt
setblock ~26 ~125 ~110 dirt
setblock ~26 ~125 ~111 dirt
setblock ~26 ~125 ~112 dirt
setblock ~26 ~125 ~113 dirt
setblock ~26 ~125 ~114 dirt
setblock ~26 ~125 ~115 grass_block
setblock ~26 ~125 ~116 grass_block
setblock ~26 ~125 ~118 short_grass
setblock ~26 ~125 ~119 fern
setblock ~26 ~126 ~49 poppy
setblock ~26 ~126 ~50 grass_block
setblock ~26 ~126 ~51 grass_block
setblock ~26 ~126 ~52 grass_block
setblock ~26 ~126 ~53 short_grass
setblock ~26 ~126 ~54 short_grass
setblock ~26 ~126 ~56 short_grass
setblock ~26 ~126 ~58 short_grass
setblock ~26 ~126 ~61 short_grass
setblock ~26 ~126 ~66 short_grass
setblock ~26 ~126 ~68 grass_block
setblock ~26 ~126 ~69 grass_block
setblock ~26 ~126 ~89 grass_block
setblock ~26 ~126 ~90 grass_block
setblock ~26 ~126 ~91 grass_block
setblock ~26 ~126 ~92 grass_block
setblock ~26 ~126 ~95 poppy
setblock ~26 ~126 ~97 fern
setblock ~26 ~126 ~105 grass_block
setblock ~26 ~126 ~106 grass_block
setblock ~26 ~126 ~107 grass_block
setblock ~26 ~126 ~108 dirt
setblock ~26 ~126 ~109 dirt
setblock ~26 ~126 ~110 dirt
setblock ~26 ~126 ~111 dirt
setblock ~26 ~126 ~112 dirt
setblock ~26 ~126 ~113 grass_block
setblock ~26 ~126 ~114 grass_block
setblock ~26 ~127 ~51 short_grass
setblock ~26 ~127 ~52 short_grass
setblock ~26 ~127 ~68 short_grass
setblock ~26 ~127 ~91 poppy
setblock ~26 ~127 ~92 short_grass
setblock ~26 ~127 ~106 short_grass
setblock ~26 ~127 ~108 grass_block
setblock ~26 ~127 ~109 grass_block
setblock ~26 ~127 ~110 dirt
setblock ~26 ~127 ~111 grass_block
setblock ~26 ~127 ~112 grass_block
setblock ~26 ~128 ~108 short_grass
setblock ~26 ~128 ~110 grass_block
setblock ~26 ~128 ~111 short_grass
setblock ~27 ~110 ~58 dirt
setblock ~27 ~110 ~59 dirt
setblock ~27 ~110 ~106 dirt
setblock ~27 ~110 ~108 dirt
setblock ~27 ~110 ~109 dirt
setblock ~27 ~111 ~57 dirt
setblock ~27 ~111 ~58 dirt
setblock ~27 ~111 ~59 dirt
setblock ~27 ~111 ~60 dirt
setblock ~27 ~111 ~105 dirt
setblock ~27 ~111 ~106 dirt
setblock ~27 ~111 ~107 dirt
setblock ~27 ~111 ~108 dirt
setblock ~27 ~111 ~109 dirt
setblock ~27 ~111 ~110 dirt
setblock ~27 ~112 ~57 dirt
setblock ~27 ~112 ~58 dirt
setblock ~27 ~112 ~59 dirt
setblock ~27 ~112 ~60 dirt
setblock ~27 ~112 ~61 dirt
setblock ~27 ~112 ~104 dirt
setblock ~27 ~112 ~105 dirt
setblock ~27 ~112 ~106 dirt
setblock ~27 ~112 ~107 dirt
setblock ~27 ~112 ~108 dirt
setblock ~27 ~112 ~109 dirt
setblock ~27 ~112 ~110 dirt
setblock ~27 ~112 ~111 dirt
setblock ~27 ~112 ~112 dirt
setblock ~27 ~113 ~55 dirt
setblock ~27 ~113 ~56 dirt
setblock ~27 ~113 ~57 dirt
setblock ~27 ~113 ~58 dirt
setblock ~27 ~113 ~59 dirt
setblock ~27 ~113 ~60 dirt
setblock ~27 ~113 ~61 dirt
setblock ~27 ~113 ~62 dirt
setblock ~27 ~113 ~103 dirt
setblock ~27 ~113 ~104 dirt
setblock ~27 ~113 ~105 dirt
setblock ~27 ~113 ~106 dirt
setblock ~27 ~113 ~107 dirt
setblock ~27 ~113 ~108 dirt
setblock ~27 ~113 ~109 dirt
setblock ~27 ~113 ~110 dirt
setblock ~27 ~113 ~111 dirt
setblock ~27 ~113 ~112 dirt
setblock ~27 ~113 ~113 dirt
setblock ~27 ~114 ~54 dirt
setblock ~27 ~114 ~55 dirt
setblock ~27 ~114 ~56 dirt
setblock ~27 ~114 ~57 dirt
setblock ~27 ~114 ~58 dirt
setblock ~27 ~114 ~59 dirt
setblock ~27 ~114 ~60 dirt
setblock ~27 ~114 ~61 dirt
setblock ~27 ~114 ~62 dirt
setblock ~27 ~114 ~63 dirt
setblock ~27 ~114 ~102 dirt
setblock ~27 ~114 ~103 dirt
setblock ~27 ~114 ~104 dirt
setblock ~27 ~114 ~105 dirt
setblock ~27 ~114 ~106 dirt
setblock ~27 ~114 ~107 dirt
setblock ~27 ~114 ~108 dirt
setblock ~27 ~114 ~109 dirt
setblock ~27 ~114 ~110 dirt
setblock ~27 ~114 ~111 dirt
setblock ~27 ~114 ~112 dirt
setblock ~27 ~114 ~113 dirt
setblock ~27 ~114 ~114 dirt
setblock ~27 ~115 ~54 dirt
setblock ~27 ~115 ~55 dirt
setblock ~27 ~115 ~56 dirt
setblock ~27 ~115 ~57 dirt
setblock ~27 ~115 ~58 dirt
setblock ~27 ~115 ~59 dirt
setblock ~27 ~115 ~60 dirt
setblock ~27 ~115 ~61 dirt
setblock ~27 ~115 ~62 dirt
setblock ~27 ~115 ~63 dirt
setblock ~27 ~115 ~64 dirt
setblock ~27 ~115 ~92 dirt
setblock ~27 ~115 ~101 dirt
setblock ~27 ~115 ~102 dirt
setblock ~27 ~115 ~103 dirt
setblock ~27 ~115 ~104 dirt
setblock ~27 ~115 ~105 dirt
setblock ~27 ~115 ~106 dirt
setblock ~27 ~115 ~107 dirt
setblock ~27 ~115 ~108 dirt
setblock ~27 ~115 ~109 dirt
setblock ~27 ~115 ~110 dirt
setblock ~27 ~115 ~111 dirt
setblock ~27 ~115 ~112 dirt
setblock ~27 ~115 ~113 dirt
setblock ~27 ~115 ~114 dirt
setblock ~27 ~115 ~115 dirt
setblock ~27 ~116 ~53 dirt
setblock ~27 ~116 ~54 dirt
setblock ~27 ~116 ~55 dirt
setblock ~27 ~116 ~56 dirt
setblock ~27 ~116 ~57 dirt
setblock ~27 ~116 ~58 dirt
setblock ~27 ~116 ~59 dirt
setblock ~27 ~116 ~60 dirt
setblock ~27 ~116 ~61 dirt
setblock ~27 ~116 ~62 dirt
setblock ~27 ~116 ~63 dirt
setblock ~27 ~116 ~64 dirt
setblock ~27 ~116 ~65 dirt
setblock ~27 ~116 ~91 dirt
setblock ~27 ~116 ~92 dirt
setblock ~27 ~116 ~93 dirt
setblock ~27 ~116 ~94 dirt
setblock ~27 ~116 ~95 dirt
setblock ~27 ~116 ~101 dirt
setblock ~27 ~116 ~102 dirt
setblock ~27 ~116 ~103 dirt
setblock ~27 ~116 ~104 dirt
setblock ~27 ~116 ~105 dirt
setblock ~27 ~116 ~106 dirt
setblock ~27 ~116 ~107 dirt
setblock ~27 ~116 ~108 dirt
setblock ~27 ~116 ~109 dirt
setblock ~27 ~116 ~110 dirt
setblock ~27 ~116 ~111 dirt
setblock ~27 ~116 ~112 dirt
setblock ~27 ~116 ~113 dirt
setblock ~27 ~116 ~114 dirt
setblock ~27 ~116 ~115 dirt
setblock ~27 ~116 ~116 dirt
setblock ~27 ~116 ~118 dirt
setblock ~27 ~117 ~52 dirt
setblock ~27 ~117 ~53 dirt
setblock ~27 ~117 ~54 dirt
setblock ~27 ~117 ~55 dirt
setblock ~27 ~117 ~56 dirt
setblock ~27 ~117 ~57 dirt
setblock ~27 ~117 ~58 dirt
setblock ~27 ~117 ~59 dirt
setblock ~27 ~117 ~60 dirt
setblock ~27 ~117 ~61 dirt
setblock ~27 ~117 ~62 dirt
setblock ~27 ~117 ~63 dirt
setblock ~27 ~117 ~64 dirt
setblock ~27 ~117 ~65 dirt
setblock ~27 ~117 ~66 dirt
setblock ~27 ~117 ~90 dirt
setblock ~27 ~117 ~91 dirt
setblock ~27 ~117 ~92 dirt
setblock ~27 ~117 ~93 dirt
setblock ~27 ~117 ~94 dirt
setblock ~27 ~117 ~95 dirt
setblock ~27 ~117 ~96 dirt
setblock ~27 ~117 ~100 dirt
setblock ~27 ~117 ~101 dirt
setblock ~27 ~117 ~102 dirt
setblock ~27 ~117 ~103 dirt
setblock ~27 ~117 ~104 dirt
setblock ~27 ~117 ~105 dirt
setblock ~27 ~117 ~106 dirt
setblock ~27 ~117 ~107 dirt
setblock ~27 ~117 ~108 dirt
setblock ~27 ~117 ~109 dirt
setblock ~27 ~117 ~110 dirt
setblock ~27 ~117 ~111 dirt
setblock ~27 ~117 ~112 dirt
setblock ~27 ~117 ~113 dirt
setblock ~27 ~117 ~114 dirt
setblock ~27 ~117 ~115 dirt
setblock ~27 ~117 ~116 dirt
setblock ~27 ~117 ~117 dirt
setblock ~27 ~117 ~118 dirt
setblock ~27 ~117 ~119 dirt
setblock ~27 ~118 ~51 dirt
setblock ~27 ~118 ~52 dirt
setblock ~27 ~118 ~53 dirt
setblock ~27 ~118 ~54 dirt
setblock ~27 ~118 ~55 dirt
setblock ~27 ~118 ~56 dirt
setblock ~27 ~118 ~57 dirt
setblock ~27 ~118 ~58 dirt
setblock ~27 ~118 ~59 dirt
setblock ~27 ~118 ~60 dirt
setblock ~27 ~118 ~61 dirt
setblock ~27 ~118 ~62 dirt
setblock ~27 ~118 ~63 dirt
setblock ~27 ~118 ~64 dirt
setblock ~27 ~118 ~65 dirt
setblock ~27 ~118 ~66 dirt
setblock ~27 ~118 ~67 dirt
setblock ~27 ~118 ~89 dirt
setblock ~27 ~118 ~90 dirt
setblock ~27 ~118 ~91 dirt
setblock ~27 ~118 ~92 dirt
setblock ~27 ~118 ~93 dirt
setblock ~27 ~118 ~94 dirt
setblock ~27 ~118 ~95 dirt
setblock ~27 ~118 ~96 dirt
setblock ~27 ~118 ~98 dirt
setblock ~27 ~118 ~99 dirt
setblock ~27 ~118 ~100 dirt
setblock ~27 ~118 ~101 dirt
setblock ~27 ~118 ~102 dirt
setblock ~27 ~118 ~103 dirt
setblock ~27 ~118 ~104 dirt
setblock ~27 ~118 ~105 dirt
setblock ~27 ~118 ~106 dirt
setblock ~27 ~118 ~107 dirt
setblock ~27 ~118 ~108 dirt
setblock ~27 ~118 ~109 dirt
setblock ~27 ~118 ~110 dirt
setblock ~27 ~118 ~111 dirt
setblock ~27 ~118 ~112 dirt
setblock ~27 ~118 ~113 dirt
setblock ~27 ~118 ~114 dirt
setblock ~27 ~118 ~115 dirt
setblock ~27 ~118 ~116 dirt
setblock ~27 ~118 ~117 dirt
setblock ~27 ~118 ~118 dirt
setblock ~27 ~118 ~119 dirt
setblock ~27 ~119 ~50 dirt
setblock ~27 ~119 ~51 dirt
setblock ~27 ~119 ~52 dirt
setblock ~27 ~119 ~53 dirt
setblock ~27 ~119 ~54 dirt
setblock ~27 ~119 ~55 dirt
setblock ~27 ~119 ~56 dirt
setblock ~27 ~119 ~57 dirt
setblock ~27 ~119 ~58 dirt
setblock ~27 ~119 ~59 dirt
setblock ~27 ~119 ~60 dirt
setblock ~27 ~119 ~61 dirt
setblock ~27 ~119 ~62 dirt
setblock ~27 ~119 ~63 dirt
setblock ~27 ~119 ~64 dirt
setblock ~27 ~119 ~65 dirt
setblock ~27 ~119 ~66 dirt
setblock ~27 ~119 ~67 dirt
setblock ~27 ~119 ~68 dirt
setblock ~27 ~119 ~89 dirt
setblock ~27 ~119 ~90 dirt
setblock ~27 ~119 ~91 dirt
setblock ~27 ~119 ~92 dirt
setblock ~27 ~119 ~93 dirt
setblock ~27 ~119 ~94 dirt
setblock ~27 ~119 ~95 dirt
setblock ~27 ~119 ~96 dirt
setblock ~27 ~119 ~97 dirt
setblock ~27 ~119 ~98 dirt
setblock ~27 ~119 ~99 dirt
setblock ~27 ~119 ~100 dirt
setblock ~27 ~119 ~101 dirt
setblock ~27 ~119 ~102 dirt
setblock ~27 ~119 ~103 dirt
setblock ~27 ~119 ~104 dirt
setblock ~27 ~119 ~105 dirt
setblock ~27 ~119 ~106 dirt
setblock ~27 ~119 ~107 dirt
setblock ~27 ~119 ~108 dirt
setblock ~27 ~119 ~109 dirt
setblock ~27 ~119 ~110 dirt
setblock ~27 ~119 ~111 dirt
setblock ~27 ~119 ~112 dirt
setblock ~27 ~119 ~113 dirt
setblock ~27 ~119 ~114 dirt
setblock ~27 ~119 ~115 dirt
setblock ~27 ~119 ~116 dirt
setblock ~27 ~119 ~117 dirt
setblock ~27 ~119 ~118 dirt
setblock ~27 ~119 ~119 dirt
setblock ~27 ~119 ~120 dirt
setblock ~27 ~120 ~49 dirt
setblock ~27 ~120 ~50 dirt
setblock ~27 ~120 ~51 dirt
setblock ~27 ~120 ~52 dirt
setblock ~27 ~120 ~53 dirt
setblock ~27 ~120 ~54 dirt
setblock ~27 ~120 ~55 dirt
setblock ~27 ~120 ~56 dirt
setblock ~27 ~120 ~57 dirt
setblock ~27 ~120 ~58 dirt
setblock ~27 ~120 ~59 dirt
setblock ~27 ~120 ~60 dirt
setblock ~27 ~120 ~61 dirt
setblock ~27 ~120 ~62 dirt
setblock ~27 ~120 ~63 dirt
setblock ~27 ~120 ~64 dirt
setblock ~27 ~120 ~65 dirt
setblock ~27 ~120 ~66 dirt
setblock ~27 ~120 ~67 dirt
setblock ~27 ~120 ~68 dirt
setblock ~27 ~120 ~69 dirt
setblock ~27 ~120 ~79 dirt
setblock ~27 ~120 ~80 dirt
setblock ~27 ~120 ~88 dirt
setblock ~27 ~120 ~89 dirt
setblock ~27 ~120 ~90 dirt
setblock ~27 ~120 ~91 dirt
setblock ~27 ~120 ~92 dirt
setblock ~27 ~120 ~93 dirt
setblock ~27 ~120 ~94 dirt
setblock ~27 ~120 ~95 dirt
setblock ~27 ~120 ~96 dirt
setblock ~27 ~120 ~97 dirt
setblock ~27 ~120 ~98 dirt
setblock ~27 ~120 ~99 dirt
setblock ~27 ~120 ~100 dirt
setblock ~27 ~120 ~101 dirt
setblock ~27 ~120 ~102 dirt
setblock ~27 ~120 ~103 dirt
setblock ~27 ~120 ~104 dirt
setblock ~27 ~120 ~105 dirt
setblock ~27 ~120 ~106 dirt
setblock ~27 ~120 ~107 dirt
setblock ~27 ~120 ~108 dirt
setblock ~27 ~120 ~109 dirt
setblock ~27 ~120 ~110 dirt
setblock ~27 ~120 ~111 dirt
setblock ~27 ~120 ~112 dirt
setblock ~27 ~120 ~113 dirt
setblock ~27 ~120 ~114 dirt
setblock ~27 ~120 ~115 dirt
setblock ~27 ~120 ~116 dirt
setblock ~27 ~120 ~117 dirt
setblock ~27 ~120 ~118 dirt
setblock ~27 ~120 ~119 dirt
setblock ~27 ~120 ~120 dirt
setblock ~27 ~120 ~121 dirt
setblock ~27 ~121 ~48 dirt
setblock ~27 ~121 ~49 dirt
setblock ~27 ~121 ~50 dirt
setblock ~27 ~121 ~51 dirt
setblock ~27 ~121 ~52 dirt
setblock ~27 ~121 ~53 dirt
setblock ~27 ~121 ~54 dirt
setblock ~27 ~121 ~55 dirt
setblock ~27 ~121 ~56 dirt
setblock ~27 ~121 ~57 dirt
setblock ~27 ~121 ~58 dirt
setblock ~27 ~121 ~59 dirt
setblock ~27 ~121 ~60 dirt
setblock ~27 ~121 ~61 dirt
setblock ~27 ~121 ~62 dirt
setblock ~27 ~121 ~63 dirt
setblock ~27 ~121 ~64 dirt
setblock ~27 ~121 ~65 dirt
setblock ~27 ~121 ~66 dirt
setblock ~27 ~121 ~67 dirt
setblock ~27 ~121 ~68 dirt
setblock ~27 ~121 ~69 dirt
setblock ~27 ~121 ~70 dirt
setblock ~27 ~121 ~79 dirt
setblock ~27 ~121 ~80 dirt
setblock ~27 ~121 ~88 dirt
setblock ~27 ~121 ~89 dirt
setblock ~27 ~121 ~90 dirt
setblock ~27 ~121 ~91 dirt
setblock ~27 ~121 ~92 dirt
setblock ~27 ~121 ~93 dirt
setblock ~27 ~121 ~94 dirt
setblock ~27 ~121 ~95 dirt
setblock ~27 ~121 ~96 dirt
setblock ~27 ~121 ~97 dirt
setblock ~27 ~121 ~98 dirt
setblock ~27 ~121 ~99 dirt
setblock ~27 ~121 ~100 dirt
setblock ~27 ~121 ~101 dirt
setblock ~27 ~121 ~102 dirt
setblock ~27 ~121 ~103 dirt
setblock ~27 ~121 ~104 dirt
setblock ~27 ~121 ~105 dirt
setblock ~27 ~121 ~106 dirt
setblock ~27 ~121 ~107 dirt
setblock ~27 ~121 ~108 dirt
setblock ~27 ~121 ~109 dirt
setblock ~27 ~121 ~110 dirt
setblock ~27 ~121 ~111 dirt
setblock ~27 ~121 ~112 dirt
setblock ~27 ~121 ~113 dirt
setblock ~27 ~121 ~114 dirt
setblock ~27 ~121 ~115 dirt
setblock ~27 ~121 ~116 dirt
setblock ~27 ~121 ~117 dirt
setblock ~27 ~121 ~118 dirt
setblock ~27 ~121 ~119 dirt
setblock ~27 ~121 ~120 dirt
setblock ~27 ~121 ~121 dirt
setblock ~27 ~122 ~48 dirt
setblock ~27 ~122 ~49 dirt
setblock ~27 ~122 ~50 dirt
setblock ~27 ~122 ~51 dirt
setblock ~27 ~122 ~52 dirt
setblock ~27 ~122 ~53 dirt
setblock ~27 ~122 ~54 dirt
setblock ~27 ~122 ~55 dirt
setblock ~27 ~122 ~56 dirt
setblock ~27 ~122 ~57 dirt
setblock ~27 ~122 ~58 dirt
setblock ~27 ~122 ~59 dirt
setblock ~27 ~122 ~60 dirt
setblock ~27 ~122 ~61 dirt
setblock ~27 ~122 ~62 dirt
setblock ~27 ~122 ~63 dirt
setblock ~27 ~122 ~64 dirt
setblock ~27 ~122 ~65 dirt
setblock ~27 ~122 ~66 dirt
setblock ~27 ~122 ~67 dirt
setblock ~27 ~122 ~68 dirt
setblock ~27 ~122 ~69 dirt
setblock ~27 ~122 ~70 dirt
setblock ~27 ~122 ~79 dirt
setblock ~27 ~122 ~80 dirt
setblock ~27 ~122 ~88 dirt
setblock ~27 ~122 ~89 dirt
setblock ~27 ~122 ~90 dirt
setblock ~27 ~122 ~91 dirt
setblock ~27 ~122 ~92 dirt
setblock ~27 ~122 ~93 dirt
setblock ~27 ~122 ~94 dirt
setblock ~27 ~122 ~95 dirt
setblock ~27 ~122 ~96 dirt
setblock ~27 ~122 ~97 dirt
setblock ~27 ~122 ~98 dirt
setblock ~27 ~122 ~99 dirt
setblock ~27 ~122 ~100 dirt
setblock ~27 ~122 ~101 dirt
setblock ~27 ~122 ~102 dirt
setblock ~27 ~122 ~103 dirt
setblock ~27 ~122 ~104 dirt
setblock ~27 ~122 ~105 dirt
setblock ~27 ~122 ~106 dirt
setblock ~27 ~122 ~107 dirt
setblock ~27 ~122 ~108 dirt
setblock ~27 ~122 ~109 dirt
setblock ~27 ~122 ~110 dirt
setblock ~27 ~122 ~111 dirt
setblock ~27 ~122 ~112 dirt
setblock ~27 ~122 ~113 dirt
setblock ~27 ~122 ~114 dirt
setblock ~27 ~122 ~115 dirt
setblock ~27 ~122 ~116 dirt
setblock ~27 ~122 ~117 dirt
setblock ~27 ~122 ~118 dirt
setblock ~27 ~122 ~119 dirt
setblock ~27 ~122 ~120 dirt
setblock ~27 ~122 ~121 dirt
setblock ~27 ~123 ~48 dirt
setblock ~27 ~123 ~49 dirt
setblock ~27 ~123 ~50 dirt
setblock ~27 ~123 ~51 dirt
setblock ~27 ~123 ~52 dirt
setblock ~27 ~123 ~53 dirt
setblock ~27 ~123 ~54 dirt
setblock ~27 ~123 ~55 dirt
setblock ~27 ~123 ~56 dirt
setblock ~27 ~123 ~57 dirt
setblock ~27 ~123 ~58 dirt
setblock ~27 ~123 ~59 dirt
setblock ~27 ~123 ~60 dirt
setblock ~27 ~123 ~61 dirt
setblock ~27 ~123 ~62 dirt
setblock ~27 ~123 ~63 dirt
setblock ~27 ~123 ~64 dirt
setblock ~27 ~123 ~65 dirt
setblock ~27 ~123 ~66 dirt
setblock ~27 ~123 ~67 dirt
setblock ~27 ~123 ~68 dirt
setblock ~27 ~123 ~69 dirt
setblock ~27 ~123 ~70 dirt
setblock ~27 ~123 ~79 dirt
setblock ~27 ~123 ~80 dirt
setblock ~27 ~123 ~88 dirt
setblock ~27 ~123 ~89 dirt
setblock ~27 ~123 ~90 dirt
setblock ~27 ~123 ~91 dirt
setblock ~27 ~123 ~92 dirt
setblock ~27 ~123 ~93 dirt
setblock ~27 ~123 ~94 dirt
setblock ~27 ~123 ~95 dirt
setblock ~27 ~123 ~96 dirt
setblock ~27 ~123 ~97 dirt
setblock ~27 ~123 ~98 dirt
setblock ~27 ~123 ~99 dirt
setblock ~27 ~123 ~100 dirt
setblock ~27 ~123 ~101 dirt
setblock ~27 ~123 ~102 dirt
setblock ~27 ~123 ~103 dirt
setblock ~27 ~123 ~104 dirt
setblock ~27 ~123 ~105 dirt
setblock ~27 ~123 ~106 dirt
setblock ~27 ~123 ~107 dirt
setblock ~27 ~123 ~108 dirt
setblock ~27 ~123 ~109 dirt
setblock ~27 ~123 ~110 dirt
setblock ~27 ~123 ~111 dirt
setblock ~27 ~123 ~112 dirt
setblock ~27 ~123 ~113 dirt
setblock ~27 ~123 ~114 dirt
setblock ~27 ~123 ~115 dirt
setblock ~27 ~123 ~116 dirt
setblock ~27 ~123 ~117 dirt
setblock ~27 ~123 ~118 dirt
setblock ~27 ~123 ~119 dirt
setblock ~27 ~123 ~120 dirt
setblock ~27 ~123 ~121 dirt
setblock ~27 ~124 ~48 dirt
setblock ~27 ~124 ~49 dirt
setblock ~27 ~124 ~50 dirt
setblock ~27 ~124 ~51 dirt
setblock ~27 ~124 ~52 dirt
setblock ~27 ~124 ~53 dirt
setblock ~27 ~124 ~54 dirt
setblock ~27 ~124 ~55 dirt
setblock ~27 ~124 ~56 dirt
setblock ~27 ~124 ~57 dirt
setblock ~27 ~124 ~58 dirt
setblock ~27 ~124 ~59 dirt
setblock ~27 ~124 ~60 dirt
setblock ~27 ~124 ~61 dirt
setblock ~27 ~124 ~62 dirt
setblock ~27 ~124 ~63 dirt
setblock ~27 ~124 ~64 dirt
setblock ~27 ~124 ~65 dirt
setblock ~27 ~124 ~66 dirt
setblock ~27 ~124 ~67 dirt
setblock ~27 ~124 ~68 dirt
setblock ~27 ~124 ~69 dirt
setblock ~27 ~124 ~70 dirt
setblock ~27 ~124 ~79 dirt
setblock ~27 ~124 ~80 dirt
setblock ~27 ~124 ~88 dirt
setblock ~27 ~124 ~89 dirt
setblock ~27 ~124 ~90 dirt
setblock ~27 ~124 ~91 dirt
setblock ~27 ~124 ~92 dirt
setblock ~27 ~124 ~93 dirt
setblock ~27 ~124 ~94 dirt
setblock ~27 ~124 ~95 dirt
setblock ~27 ~124 ~96 dirt
setblock ~27 ~124 ~97 dirt
setblock ~27 ~124 ~98 grass_block
setblock ~27 ~124 ~99 grass_block
setblock ~27 ~124 ~100 grass_block
setblock ~27 ~124 ~101 grass_block
setblock ~27 ~124 ~102 dirt
setblock ~27 ~124 ~103 dirt
setblock ~27 ~124 ~104 dirt
setblock ~27 ~124 ~105 dirt
setblock ~27 ~124 ~106 dirt
setblock ~27 ~124 ~107 dirt
setblock ~27 ~124 ~108 dirt
setblock ~27 ~124 ~109 dirt
setblock ~27 ~124 ~110 dirt
setblock ~27 ~124 ~111 dirt
setblock ~27 ~124 ~112 dirt
setblock ~27 ~124 ~113 dirt
setblock ~27 ~124 ~114 dirt
setblock ~27 ~124 ~115 dirt
setblock ~27 ~124 ~116 dirt
setblock ~27 ~124 ~117 dirt
setblock ~27 ~124 ~118 grass_block
setblock ~27 ~124 ~119 grass_block
setblock ~27 ~124 ~120 grass_block
setblock ~27 ~124 ~121 grass_block
setblock ~27 ~125 ~48 grass_block
setblock ~27 ~125 ~49 grass_block
setblock ~27 ~125 ~50 dirt
setblock ~27 ~125 ~51 dirt
setblock ~27 ~125 ~52 dirt
setblock ~27 ~125 ~53 dirt
setblock ~27 ~125 ~54 grass_block
setblock ~27 ~125 ~55 grass_block
setblock ~27 ~125 ~56 grass_block
setblock ~27 ~125 ~57 grass_block
setblock ~27 ~125 ~58 grass_block
setblock ~27 ~125 ~59 grass_block
setblock ~27 ~125 ~60 grass_block
setblock ~27 ~125 ~61 grass_block
setblock ~27 ~125 ~62 grass_block
setblock ~27 ~125 ~63 grass_block
setblock ~27 ~125 ~64 grass_block
setblock ~27 ~125 ~65 grass_block
setblock ~27 ~125 ~66 dirt
setblock ~27 ~125 ~67 dirt
setblock ~27 ~125 ~68 dirt
setblock ~27 ~125 ~69 dirt
setblock ~27 ~125 ~70 dirt
setblock ~27 ~125 ~79 grass_block
setblock ~27 ~125 ~80 grass_block
setblock ~27 ~125 ~88 dirt
setblock ~27 ~125 ~89 dirt
setblock ~27 ~125 ~90 dirt
setblock ~27 ~125 ~91 dirt
setblock ~27 ~125 ~92 dirt
setblock ~27 ~125 ~93 grass_block
setblock ~27 ~125 ~94 grass_block
setblock ~27 ~125 ~95 grass_block
setblock ~27 ~125 ~96 grass_block
setblock ~27 ~125 ~97 grass_block
setblock ~27 ~125 ~101 short_grass
setblock ~27 ~125 ~102 grass_block
setblock ~27 ~125 ~103 grass_block
setblock ~27 ~125 ~104 grass_block
setblock ~27 ~125 ~105 dirt
setblock ~27 ~125 ~106 dirt
setblock ~27 ~125 ~107 dirt
setblock ~27 ~125 ~108 dirt
setblock ~27 ~125 ~109 dirt
setblock ~27 ~125 ~110 dirt
setblock ~27 ~125 ~111 dirt
setblock ~27 ~125 ~112 dirt
setblock ~27 ~125 ~113 dirt
setblock ~27 ~125 ~114 dirt
setblock ~27 ~125 ~115 grass_block
setblock ~27 ~125 ~116 grass_block
setblock ~27 ~125 ~117 grass_block
setblock ~27 ~126 ~48 short_grass
setblock ~27 ~126 ~49 fern
setblock ~27 ~126 ~50 grass_block
setblock ~27 ~126 ~51 grass_block
setblock ~27 ~126 ~52 grass_block
setblock ~27 ~126 ~53 grass_block
setblock ~27 ~126 ~58 short_grass
setblock ~27 ~126 ~60 short_grass
setblock ~27 ~126 ~63 short_grass
setblock ~27 ~126 ~66 grass_block
setblock ~27 ~126 ~67 grass_block
setblock ~27 ~126 ~68 grass_block
setblock ~27 ~126 ~69 grass_block
setblock ~27 ~126 ~70 grass_block
setblock ~27 ~126 ~80 short_grass
setblock ~27 ~126 ~88 grass_block
setblock ~27 ~126 ~89 grass_block
setblock ~27 ~126 ~90 grass_block
setblock ~27 ~126 ~91 grass_block
setblock ~27 ~126 ~92 grass_block
setblock ~27 ~126 ~93 short_grass
setblock ~27 ~126 ~102 short_grass
setblock ~27 ~126 ~105 grass_block
setblock ~27 ~126 ~106 grass_block
setblock ~27 ~126 ~107 grass_block
setblock ~27 ~126 ~108 dirt
setblock ~27 ~126 ~109 dirt
setblock ~27 ~126 ~110 dirt
setblock ~27 ~126 ~111 dirt
setblock ~27 ~126 ~112 dirt
setblock ~27 ~126 ~113 grass_block
setblock ~27 ~126 ~114 grass_block
setblock ~27 ~126 ~116 short_grass
setblock ~27 ~126 ~117 fern
setblock ~27 ~127 ~68 short_grass
setblock ~27 ~127 ~69 short_grass
setblock ~27 ~127 ~90 short_grass
setblock ~27 ~127 ~92 poppy
setblock ~27 ~127 ~107 short_grass
setblock ~27 ~127 ~108 grass_block
setblock ~27 ~127 ~109 grass_block
setblock ~27 ~127 ~110 dirt
setblock ~27 ~127 ~111 grass_block
setblock ~27 ~127 ~112 grass_block
setblock ~27 ~127 ~113 short_grass
setblock ~27 ~127 ~114 short_grass
setblock ~27 ~128 ~108 poppy
setblock ~27 ~128 ~109 short_grass
setblock ~27 ~128 ~110 grass_block
setblock ~28 ~109 ~58 dirt
setblock ~28 ~109 ~59 dirt
setblock ~28 ~109 ~60 dirt
setblock ~28 ~110 ~57 dirt
setblock ~28 ~110 ~58 dirt
setblock ~28 ~110 ~59 dirt
setblock ~28 ~110 ~60 dirt
setblock ~28 ~110 ~61 dirt
setblock ~28 ~111 ~56 dirt
setblock ~28 ~111 ~57 dirt
setblock ~28 ~111 ~58 dirt
setblock ~28 ~111 ~59 dirt
setblock ~28 ~111 ~60 dirt
setblock ~28 ~111 ~61 dirt
setblock ~28 ~111 ~108 dirt
setblock ~28 ~112 ~55 dirt
setblock ~28 ~112 ~56 dirt
setblock ~28 ~112 ~57 dirt
setblock ~28 ~112 ~58 dirt
setblock ~28 ~112 ~59 dirt
setblock ~28 ~112 ~60 dirt
setblock ~28 ~112 ~61 dirt
setblock ~28 ~112 ~62 dirt
setblock ~28 ~112 ~92 dirt
setblock ~28 ~112 ~105 dirt
setblock ~28 ~112 ~106 dirt
setblock ~28 ~112 ~107 dirt
setblock ~28 ~112 ~108 dirt
setblock ~28 ~112 ~109 dirt
setblock ~28 ~113 ~54 dirt
setblock ~28 ~113 ~55 dirt
setblock ~28 ~113 ~56 dirt
setblock ~28 ~113 ~57 dirt
setblock ~28 ~113 ~58 dirt
setblock ~28 ~113 ~59 dirt
setblock ~28 ~113 ~60 dirt
setblock ~28 ~113 ~61 dirt
setblock ~28 ~113 ~62 dirt
setblock ~28 ~113 ~63 dirt
setblock ~28 ~113 ~91 dirt
setblock ~28 ~113 ~92 dirt
setblock ~28 ~113 ~104 dirt
setblock ~28 ~113 ~105 dirt
setblock ~28 ~113 ~106 dirt
setblock ~28 ~113 ~107 dirt
setblock ~28 ~113 ~108 dirt
setblock ~28 ~113 ~109 dirt
setblock ~28 ~113 ~110 dirt
setblock ~28 ~113 ~111 dirt
setblock ~28 ~113 ~112 dirt
setblock ~28 ~114 ~54 dirt
setblock ~28 ~114 ~55 dirt
setblock ~28 ~114 ~56 dirt
setblock ~28 ~114 ~57 dirt
setblock ~28 ~114 ~58 dirt
setblock ~28 ~114 ~59 dirt
setblock ~28 ~114 ~60 dirt
setblock ~28 ~114 ~61 dirt
setblock ~28 ~114 ~62 dirt
setblock ~28 ~114 ~63 dirt
setblock ~28 ~114 ~64 dirt
setblock ~28 ~114 ~91 dirt
setblock ~28 ~114 ~92 dirt
setblock ~28 ~114 ~93 dirt
setblock ~28 ~114 ~94 dirt
setblock ~28 ~114 ~103 dirt
setblock ~28 ~114 ~104 dirt
setblock ~28 ~114 ~105 dirt
setblock ~28 ~114 ~106 dirt
setblock ~28 ~114 ~107 dirt
setblock ~28 ~114 ~108 dirt
setblock ~28 ~114 ~109 dirt
setblock ~28 ~114 ~110 dirt
setblock ~28 ~114 ~111 dirt
setblock ~28 ~114 ~112 dirt
setblock ~28 ~114 ~113 dirt
setblock ~28 ~114 ~118 dirt
setblock ~28 ~115 ~53 dirt
setblock ~28 ~115 ~54 dirt
setblock ~28 ~115 ~55 dirt
setblock ~28 ~115 ~56 dirt
setblock ~28 ~115 ~57 dirt
setblock ~28 ~115 ~58 dirt
setblock ~28 ~115 ~59 dirt
setblock ~28 ~115 ~60 dirt
setblock ~28 ~115 ~61 dirt
setblock ~28 ~115 ~62 dirt
setblock ~28 ~115 ~63 dirt
setblock ~28 ~115 ~64 dirt
setblock ~28 ~115 ~65 dirt
setblock ~28 ~115 ~90 dirt
setblock ~28 ~115 ~91 dirt
setblock ~28 ~115 ~92 dirt
setblock ~28 ~115 ~93 dirt
setblock ~28 ~115 ~94 dirt
setblock ~28 ~115 ~95 dirt
setblock ~28 ~115 ~102 dirt
setblock ~28 ~115 ~103 dirt
setblock ~28 ~115 ~104 dirt
setblock ~28 ~115 ~105 dirt
setblock ~28 ~115 ~106 dirt
setblock ~28 ~115 ~107 dirt
setblock ~28 ~115 ~108 dirt
setblock ~28 ~115 ~109 dirt
setblock ~28 ~115 ~110 dirt
setblock ~28 ~115 ~111 dirt
setblock ~28 ~115 ~112 dirt
setblock ~28 ~115 ~113 dirt
setblock ~28 ~115 ~114 dirt
setblock ~28 ~115 ~118 dirt
setblock ~28 ~116 ~52 dirt
setblock ~28 ~116 ~53 dirt
setblock ~28 ~116 ~54 dirt
setblock ~28 ~116 ~55 dirt
setblock ~28 ~116 ~56 dirt
setblock ~28 ~116 ~57 dirt
setblock ~28 ~116 ~58 dirt
setblock ~28 ~116 ~59 dirt
setblock ~28 ~116 ~60 dirt
setblock ~28 ~116 ~61 dirt
setblock ~28 ~116 ~62 dirt
setblock ~28 ~116 ~63 dirt
setblock ~28 ~116 ~64 dirt
setblock ~28 ~116 ~65 dirt
setblock ~28 ~116 ~66 dirt
setblock ~28 ~116 ~90 dirt
setblock ~28 ~116 ~91 dirt
setblock ~28 ~116 ~92 dirt
setblock ~28 ~116 ~93 dirt
setblock ~28 ~116 ~94 dirt
setblock ~28 ~116 ~95 dirt
setblock ~28 ~116 ~96 dirt
setblock ~28 ~116 ~101 dirt
setblock ~28 ~116 ~102 dirt
setblock ~28 ~116 ~103 dirt
setblock ~28 ~116 ~104 dirt
setblock ~28 ~116 ~105 dirt
setblock ~28 ~116 ~106 dirt
setblock ~28 ~116 ~107 dirt
setblock ~28 ~116 ~108 dirt
setblock ~28 ~116 ~109 dirt
setblock ~28 ~116 ~110 dirt
setblock ~28 ~116 ~111 dirt
setblock ~28 ~116 ~112 dirt
setblock ~28 ~116 ~113 dirt
setblock ~28 ~116 ~114 dirt
setblock ~28 ~116 ~115 dirt
setblock ~28 ~116 ~117 dirt
setblock ~28 ~116 ~118 dirt
setblock ~28 ~116 ~119 dirt
setblock ~28 ~117 ~51 dirt
setblock ~28 ~117 ~52 dirt
setblock ~28 ~117 ~53 dirt
setblock ~28 ~117 ~54 dirt
setblock ~28 ~117 ~55 dirt
setblock ~28 ~117 ~56 dirt
setblock ~28 ~117 ~57 dirt
setblock ~28 ~117 ~58 dirt
setblock ~28 ~117 ~59 dirt
setblock ~28 ~117 ~60 dirt
setblock ~28 ~117 ~61 dirt
setblock ~28 ~117 ~62 dirt
setblock ~28 ~117 ~63 dirt
setblock ~28 ~117 ~64 dirt
setblock ~28 ~117 ~65 dirt
setblock ~28 ~117 ~66 dirt
setblock ~28 ~117 ~67 dirt
setblock ~28 ~117 ~89 dirt
setblock ~28 ~117 ~90 dirt
setblock ~28 ~117 ~91 dirt
setblock ~28 ~117 ~92 dirt
setblock ~28 ~117 ~93 dirt
setblock ~28 ~117 ~94 dirt
setblock ~28 ~117 ~95 dirt
setblock ~28 ~117 ~96 dirt
setblock ~28 ~117 ~101 dirt
setblock ~28 ~117 ~102 dirt
setblock ~28 ~117 ~103 dirt
setblock ~28 ~117 ~104 dirt
setblock ~28 ~117 ~105 dirt
setblock ~28 ~117 ~106 dirt
setblock ~28 ~117 ~107 dirt
setblock ~28 ~117 ~108 dirt
setblock ~28 ~117 ~109 dirt
setblock ~28 ~117 ~110 dirt
setblock ~28 ~117 ~111 dirt
setblock ~28 ~117 ~112 dirt
setblock ~28 ~117 ~113 dirt
setblock ~28 ~117 ~114 dirt
setblock ~28 ~117 ~115 dirt
setblock ~28 ~117 ~116 dirt
setblock ~28 ~117 ~117 dirt
setblock ~28 ~117 ~118 dirt
setblock ~28 ~117 ~119 dirt
setblock ~28 ~117 ~120 dirt
setblock ~28 ~118 ~50 dirt
setblock ~28 ~118 ~51 dirt
setblock ~28 ~118 ~52 dirt
setblock ~28 ~118 ~53 dirt
setblock ~28 ~118 ~54 dirt
setblock ~28 ~118 ~55 dirt
setblock ~28 ~118 ~56 dirt
setblock ~28 ~118 ~57 dirt
setblock ~28 ~118 ~58 dirt
setblock ~28 ~118 ~59 dirt
setblock ~28 ~118 ~60 dirt
setblock ~28 ~118 ~61 dirt
setblock ~28 ~118 ~62 dirt
setblock ~28 ~118 ~63 dirt
setblock ~28 ~118 ~64 dirt
setblock ~28 ~118 ~65 dirt
setblock ~28 ~118 ~66 dirt
setblock ~28 ~118 ~67 dirt
setblock ~28 ~118 ~68 dirt
setblock ~28 ~118 ~80 dirt
setblock ~28 ~118 ~88 dirt
setblock ~28 ~118 ~89 dirt
setblock ~28 ~118 ~90 dirt
setblock ~28 ~118 ~91 dirt
setblock ~28 ~118 ~92 dirt
setblock ~28 ~118 ~93 dirt
setblock ~28 ~118 ~94 dirt
setblock ~28 ~118 ~95 dirt
setblock ~28 ~118 ~96 dirt
setblock ~28 ~118 ~100 dirt
setblock ~28 ~118 ~101 dirt
setblock ~28 ~118 ~102 dirt
setblock ~28 ~118 ~103 dirt
setblock ~28 ~118 ~104 dirt
setblock ~28 ~118 ~105 dirt
setblock ~28 ~118 ~106 dirt
setblock ~28 ~118 ~107 dirt
setblock ~28 ~118 ~108 dirt
setblock ~28 ~118 ~109 dirt
setblock ~28 ~118 ~110 dirt
setblock ~28 ~118 ~111 dirt
