setblock ~0 ~1 ~0 gold_block
setblock ~15 ~130 ~122 jungle_leaves[persistent=true]
setblock ~15 ~130 ~123 jungle_leaves[persistent=true]
setblock ~15 ~130 ~124 oak_leaves[persistent=true]
setblock ~15 ~130 ~125 oak_leaves[persistent=true]
setblock ~15 ~131 ~122 jungle_leaves[persistent=true]
setblock ~15 ~131 ~123 oak_leaves[persistent=true]
setblock ~15 ~131 ~124 oak_leaves[persistent=true]
setblock ~15 ~131 ~125 jungle_leaves[persistent=true]
setblock ~15 ~132 ~122 oak_leaves[persistent=true]
setblock ~15 ~132 ~124 oak_leaves[persistent=true]
setblock ~15 ~132 ~125 oak_leaves[persistent=true]
setblock ~15 ~133 ~122 oak_leaves[persistent=true]
setblock ~15 ~133 ~123 jungle_leaves[persistent=true]
setblock ~15 ~133 ~124 oak_leaves[persistent=true]
setblock ~16 ~130 ~122 oak_leaves[persistent=true]
setblock ~16 ~130 ~123 oak_leaves[persistent=true]
setblock ~16 ~130 ~124 oak_leaves[persistent=true]
setblock ~16 ~131 ~122 oak_leaves[persistent=true]
setblock ~16 ~131 ~123 oak_leaves[persistent=true]
setblock ~16 ~131 ~124 oak_leaves[persistent=true]
setblock ~16 ~131 ~125 oak_leaves[persistent=true]
setblock ~16 ~132 ~122 oak_leaves[persistent=true]
setblock ~16 ~132 ~123 oak_leaves[persistent=true]
setblock ~16 ~132 ~124 oak_leaves[persistent=true]
setblock ~16 ~133 ~122 oak_leaves[persistent=true]
setblock ~16 ~133 ~123 oak_leaves[persistent=true]
setblock ~16 ~133 ~124 jungle_leaves[persistent=true]
setblock ~16 ~133 ~125 oak_leaves[persistent=true]
setblock ~16 ~134 ~106 oak_leaves[persistent=true]
setblock ~16 ~134 ~107 oak_leaves[persistent=true]
setblock ~16 ~135 ~105 oak_leaves[persistent=true]
setblock ~16 ~135 ~106 oak_leaves[persistent=true]
setblock ~16 ~135 ~107 oak_leaves[persistent=true]
setblock ~16 ~136 ~106 jungle_leaves[persistent=true]
setblock ~16 ~136 ~107 jungle_leaves[persistent=true]
setblock ~17 ~130 ~122 jungle_leaves[persistent=true]
setblock ~17 ~130 ~123 oak_leaves[persistent=true]
setblock ~17 ~130 ~124 oak_leaves[persistent=true]
setblock ~17 ~130 ~125 oak_leaves[persistent=true]
setblock ~17 ~131 ~119 oak_leaves[persistent=true]
setblock ~17 ~131 ~120 oak_leaves[persistent=true]
setblock ~17 ~131 ~122 oak_leaves[persistent=true]
setblock ~17 ~131 ~123 oak_leaves[persistent=true]
setblock ~17 ~131 ~124 jungle_leaves[persistent=true]
setblock ~17 ~131 ~125 jungle_leaves[persistent=true]
setblock ~17 ~132 ~119 oak_leaves[persistent=true]
setblock ~17 ~132 ~120 oak_leaves[persistent=true]
setblock ~17 ~132 ~121 oak_leaves[persistent=true]
setblock ~17 ~132 ~122 oak_leaves[persistent=true]
setblock ~17 ~132 ~123 jungle_leaves[persistent=true]
setblock ~17 ~132 ~124 oak_leaves[persistent=true]
setblock ~17 ~132 ~125 oak_leaves[persistent=true]
setblock ~17 ~133 ~105 jungle_leaves[persistent=true]
setblock ~17 ~133 ~106 oak_leaves[persistent=true]
setblock ~17 ~133 ~107 oak_leaves[persistent=true]
setblock ~17 ~133 ~108 oak_leaves[persistent=true]
setblock ~17 ~133 ~120 oak_leaves[persistent=true]
setblock ~17 ~133 ~121 oak_leaves[persistent=true]
setblock ~17 ~133 ~122 oak_leaves[persistent=true]
setblock ~17 ~133 ~123 oak_leaves[persistent=true]
setblock ~17 ~133 ~124 jungle_leaves[persistent=true]
setblock ~17 ~133 ~125 jungle_leaves[persistent=true]
setblock ~17 ~134 ~105 oak_leaves[persistent=true]
setblock ~17 ~134 ~106 oak_leaves[persistent=true]
setblock ~17 ~134 ~107 jungle_leaves[persistent=true]
setblock ~17 ~134 ~108 oak_leaves[persistent=true]
setblock ~17 ~134 ~120 oak_leaves[persistent=true]
setblock ~17 ~134 ~121 oak_leaves[persistent=true]
setblock ~17 ~134 ~122 oak_leaves[persistent=true]
setblock ~17 ~134 ~123 oak_leaves[persistent=true]
setblock ~17 ~135 ~105 oak_leaves[persistent=true]
setblock ~17 ~135 ~106 oak_leaves[persistent=true]
setblock ~17 ~135 ~107 oak_leaves[persistent=true]
setblock ~17 ~135 ~108 oak_leaves[persistent=true]
setblock ~17 ~135 ~120 oak_leaves[persistent=true]
setblock ~17 ~135 ~122 oak_leaves[persistent=true]
setblock ~17 ~135 ~123 oak_leaves[persistent=true]
setblock ~17 ~136 ~105 jungle_leaves[persistent=true]
setblock ~17 ~136 ~106 oak_leaves[persistent=true]
setblock ~17 ~136 ~107 oak_leaves[persistent=true]
setblock ~17 ~136 ~108 jungle_leaves[persistent=true]
setblock ~18 ~128 ~118 oak_leaves[persistent=true]
setblock ~18 ~128 ~119 oak_leaves[persistent=true]
setblock ~18 ~128 ~120 oak_leaves[persistent=true]
setblock ~18 ~129 ~117 oak_leaves[persistent=true]
setblock ~18 ~129 ~118 oak_leaves[persistent=true]
setblock ~18 ~129 ~119 oak_leaves[persistent=true]
setblock ~18 ~129 ~120 oak_leaves[persistent=true]
setblock ~18 ~130 ~117 oak_leaves[persistent=true]
setblock ~18 ~130 ~118 oak_leaves[persistent=true]
setblock ~18 ~130 ~119 oak_leaves[persistent=true]
setblock ~18 ~130 ~122 oak_leaves[persistent=true]
setblock ~18 ~130 ~123 oak_leaves[persistent=true]
setblock ~18 ~130 ~124 oak_leaves[persistent=true]
setblock ~18 ~130 ~125 oak_leaves[persistent=true]
setblock ~18 ~131 ~117 jungle_leaves[persistent=true]
setblock ~18 ~131 ~118 oak_leaves[persistent=true]
setblock ~18 ~131 ~119 oak_leaves[persistent=true]
setblock ~18 ~131 ~121 oak_leaves[persistent=true]
setblock ~18 ~131 ~122 jungle_leaves[persistent=true]
setblock ~18 ~131 ~123 oak_leaves[persistent=true]
setblock ~18 ~131 ~124 oak_leaves[persistent=true]
setblock ~18 ~131 ~125 oak_leaves[persistent=true]
setblock ~18 ~132 ~96 oak_leaves[persistent=true]
setblock ~18 ~132 ~97 jungle_leaves[persistent=true]
setblock ~18 ~132 ~98 oak_leaves[persistent=true]
setblock ~18 ~132 ~117 oak_leaves[persistent=true]
setblock ~18 ~132 ~118 oak_leaves[persistent=true]
setblock ~18 ~132 ~119 oak_leaves[persistent=true]
setblock ~18 ~132 ~121 oak_leaves[persistent=true]
setblock ~18 ~132 ~123 oak_leaves[persistent=true]
setblock ~18 ~132 ~124 oak_wood
setblock ~18 ~132 ~125 jungle_leaves[persistent=true]
setblock ~18 ~133 ~92 oak_leaves[persistent=true]
setblock ~18 ~133 ~93 oak_leaves[persistent=true]
setblock ~18 ~133 ~95 jungle_leaves[persistent=true]
setblock ~18 ~133 ~96 oak_leaves[persistent=true]
setblock ~18 ~133 ~97 oak_leaves[persistent=true]
setblock ~18 ~133 ~98 oak_leaves[persistent=true]
setblock ~18 ~133 ~99 jungle_leaves[persistent=true]
setblock ~18 ~133 ~105 oak_leaves[persistent=true]
setblock ~18 ~133 ~106 oak_leaves[persistent=true]
setblock ~18 ~133 ~107 oak_leaves[persistent=true]
setblock ~18 ~133 ~108 oak_leaves[persistent=true]
setblock ~18 ~133 ~109 oak_leaves[persistent=true]
setblock ~18 ~133 ~115 oak_leaves[persistent=true]
setblock ~18 ~133 ~116 jungle_leaves[persistent=true]
setblock ~18 ~133 ~117 oak_leaves[persistent=true]
setblock ~18 ~133 ~118 oak_leaves[persistent=true]
setblock ~18 ~133 ~119 oak_leaves[persistent=true]
setblock ~18 ~133 ~120 oak_leaves[persistent=true]
setblock ~18 ~133 ~121 oak_leaves[persistent=true]
setblock ~18 ~133 ~122 oak_leaves[persistent=true]
setblock ~18 ~133 ~123 jungle_leaves[persistent=true]
setblock ~18 ~133 ~124 jungle_leaves[persistent=true]
setblock ~18 ~133 ~125 oak_leaves[persistent=true]
setblock ~18 ~134 ~92 oak_leaves[persistent=true]
setblock ~18 ~134 ~93 jungle_leaves[persistent=true]
setblock ~18 ~134 ~94 oak_leaves[persistent=true]
setblock ~18 ~134 ~95 oak_leaves[persistent=true]
setblock ~18 ~134 ~96 oak_leaves[persistent=true]
setblock ~18 ~134 ~97 jungle_leaves[persistent=true]
setblock ~18 ~134 ~98 oak_leaves[persistent=true]
setblock ~18 ~134 ~99 oak_leaves[persistent=true]
setblock ~18 ~134 ~105 oak_leaves[persistent=true]
setblock ~18 ~134 ~107 oak_leaves[persistent=true]
setblock ~18 ~134 ~108 jungle_leaves[persistent=true]
setblock ~18 ~134 ~109 oak_leaves[persistent=true]
setblock ~18 ~134 ~111 oak_leaves[persistent=true]
setblock ~18 ~134 ~112 oak_leaves[persistent=true]
setblock ~18 ~134 ~114 oak_leaves[persistent=true]
setblock ~18 ~134 ~115 oak_leaves[persistent=true]
setblock ~18 ~134 ~117 jungle_leaves[persistent=true]
setblock ~18 ~134 ~118 oak_leaves[persistent=true]
setblock ~18 ~134 ~119 oak_leaves[persistent=true]
setblock ~18 ~134 ~120 oak_leaves[persistent=true]
setblock ~18 ~134 ~121 oak_leaves[persistent=true]
setblock ~18 ~134 ~122 oak_leaves[persistent=true]
setblock ~18 ~134 ~123 jungle_leaves[persistent=true]
setblock ~18 ~135 ~92 oak_leaves[persistent=true]
setblock ~18 ~135 ~93 oak_leaves[persistent=true]
setblock ~18 ~135 ~94 jungle_leaves[persistent=true]
setblock ~18 ~135 ~95 oak_leaves[persistent=true]
setblock ~18 ~135 ~96 oak_leaves[persistent=true]
setblock ~18 ~135 ~97 oak_leaves[persistent=true]
setblock ~18 ~135 ~98 oak_leaves[persistent=true]
setblock ~18 ~135 ~99 jungle_leaves[persistent=true]
setblock ~18 ~135 ~105 oak_leaves[persistent=true]
setblock ~18 ~135 ~106 oak_wood
setblock ~18 ~135 ~107 oak_leaves[persistent=true]
setblock ~18 ~135 ~108 oak_leaves[persistent=true]
setblock ~18 ~135 ~109 jungle_leaves[persistent=true]
setblock ~18 ~135 ~111 jungle_leaves[persistent=true]
setblock ~18 ~135 ~112 oak_leaves[persistent=true]
setblock ~18 ~135 ~114 jungle_leaves[persistent=true]
setblock ~18 ~135 ~115 oak_leaves[persistent=true]
setblock ~18 ~135 ~116 oak_leaves[persistent=true]
setblock ~18 ~135 ~117 oak_leaves[persistent=true]
setblock ~18 ~135 ~118 oak_leaves[persistent=true]
setblock ~18 ~135 ~119 oak_leaves[persistent=true]
setblock ~18 ~135 ~120 oak_leaves[persistent=true]
setblock ~18 ~135 ~121 oak_leaves[persistent=true]
setblock ~18 ~135 ~122 jungle_leaves[persistent=true]
setblock ~18 ~135 ~123 oak_leaves[persistent=true]
setblock ~18 ~136 ~92 oak_leaves[persistent=true]
setblock ~18 ~136 ~93 oak_leaves[persistent=true]
setblock ~18 ~136 ~94 jungle_leaves[persistent=true]
setblock ~18 ~136 ~105 oak_leaves[persistent=true]
setblock ~18 ~136 ~106 oak_leaves[persistent=true]
setblock ~18 ~136 ~107 oak_leaves[persistent=true]
setblock ~18 ~136 ~108 jungle_leaves[persistent=true]
setblock ~18 ~136 ~109 jungle_leaves[persistent=true]
setblock ~18 ~136 ~115 jungle_leaves[persistent=true]
setblock ~18 ~136 ~116 oak_leaves[persistent=true]
setblock ~18 ~136 ~118 oak_leaves[persistent=true]
setblock ~18 ~137 ~114 oak_leaves[persistent=true]
setblock ~18 ~137 ~115 jungle_leaves[persistent=true]
setblock ~18 ~137 ~116 oak_leaves[persistent=true]
setblock ~18 ~137 ~117 oak_leaves[persistent=true]
setblock ~18 ~138 ~115 jungle_leaves[persistent=true]
setblock ~18 ~138 ~116 oak_leaves[persistent=true]
setblock ~18 ~138 ~117 oak_leaves[persistent=true]
setblock ~19 ~127 ~116 oak_leaves[persistent=true]
setblock ~19 ~127 ~117 oak_leaves[persistent=true]
setblock ~19 ~127 ~118 oak_leaves[persistent=true]
setblock ~19 ~128 ~105 oak_leaves[persistent=true]
setblock ~19 ~128 ~106 jungle_leaves[persistent=true]
setblock ~19 ~128 ~107 oak_leaves[persistent=true]
setblock ~19 ~128 ~108 jungle_leaves[persistent=true]
setblock ~19 ~128 ~115 oak_leaves[persistent=true]
setblock ~19 ~128 ~116 jungle_leaves[persistent=true]
setblock ~19 ~128 ~117 oak_leaves[persistent=true]
setblock ~19 ~128 ~118 oak_leaves[persistent=true]
setblock ~19 ~128 ~119 oak_leaves[persistent=true]
setblock ~19 ~128 ~120 oak_leaves[persistent=true]
setblock ~19 ~129 ~105 jungle_leaves[persistent=true]
setblock ~19 ~129 ~106 jungle_leaves[persistent=true]
setblock ~19 ~129 ~107 oak_leaves[persistent=true]
setblock ~19 ~129 ~108 oak_leaves[persistent=true]
setblock ~19 ~129 ~115 oak_leaves[persistent=true]
setblock ~19 ~129 ~116 oak_leaves[persistent=true]
setblock ~19 ~129 ~117 jungle_leaves[persistent=true]
setblock ~19 ~129 ~119 oak_leaves[persistent=true]
setblock ~19 ~129 ~120 oak_leaves[persistent=true]
setblock ~19 ~130 ~105 oak_leaves[persistent=true]
setblock ~19 ~130 ~107 oak_leaves[persistent=true]
setblock ~19 ~130 ~108 jungle_leaves[persistent=true]
setblock ~19 ~130 ~115 jungle_leaves[persistent=true]
setblock ~19 ~130 ~116 oak_leaves[persistent=true]
setblock ~19 ~130 ~117 jungle_leaves[persistent=true]
setblock ~19 ~130 ~118 oak_leaves[persistent=true]
setblock ~19 ~130 ~119 oak_leaves[persistent=true]
setblock ~19 ~130 ~120 jungle_leaves[persistent=true]
setblock ~19 ~131 ~105 oak_leaves[persistent=true]
setblock ~19 ~131 ~106 jungle_leaves[persistent=true]
setblock ~19 ~131 ~107 oak_leaves[persistent=true]
setblock ~19 ~131 ~116 jungle_leaves[persistent=true]
setblock ~19 ~131 ~117 oak_leaves[persistent=true]
setblock ~19 ~131 ~118 oak_leaves[persistent=true]
setblock ~19 ~131 ~119 oak_leaves[persistent=true]
setblock ~19 ~131 ~120 jungle_leaves[persistent=true]
setblock ~19 ~131 ~121 oak_leaves[persistent=true]
setblock ~19 ~131 ~124 oak_leaves[persistent=true]
setblock ~19 ~132 ~96 oak_leaves[persistent=true]
setblock ~19 ~132 ~98 oak_leaves[persistent=true]
setblock ~19 ~132 ~99 oak_leaves[persistent=true]
setblock ~19 ~132 ~116 oak_leaves[persistent=true]
setblock ~19 ~132 ~117 oak_leaves[persistent=true]
setblock ~19 ~132 ~118 oak_leaves[persistent=true]
setblock ~19 ~132 ~119 oak_wood
setblock ~19 ~132 ~120 oak_leaves[persistent=true]
setblock ~19 ~132 ~121 oak_leaves[persistent=true]
setblock ~19 ~132 ~122 oak_leaves[persistent=true]
setblock ~19 ~132 ~123 oak_leaves[persistent=true]
setblock ~19 ~132 ~124 oak_leaves[persistent=true]
setblock ~19 ~132 ~125 oak_leaves[persistent=true]
setblock ~19 ~133 ~92 jungle_leaves[persistent=true]
setblock ~19 ~133 ~93 oak_leaves[persistent=true]
setblock ~19 ~133 ~94 oak_leaves[persistent=true]
setblock ~19 ~133 ~95 oak_leaves[persistent=true]
setblock ~19 ~133 ~97 oak_leaves[persistent=true]
setblock ~19 ~133 ~98 oak_leaves[persistent=true]
setblock ~19 ~133 ~99 jungle_leaves[persistent=true]
setblock ~19 ~133 ~101 oak_leaves[persistent=true]
setblock ~19 ~133 ~102 jungle_leaves[persistent=true]
setblock ~19 ~133 ~103 oak_leaves[persistent=true]
setblock ~19 ~133 ~107 oak_leaves[persistent=true]
setblock ~19 ~133 ~108 oak_leaves[persistent=true]
setblock ~19 ~133 ~111 oak_leaves[persistent=true]
setblock ~19 ~133 ~112 oak_leaves[persistent=true]
setblock ~19 ~133 ~115 oak_leaves[persistent=true]
setblock ~19 ~133 ~116 jungle_leaves[persistent=true]
setblock ~19 ~133 ~117 jungle_leaves[persistent=true]
setblock ~19 ~133 ~118 jungle_leaves[persistent=true]
setblock ~19 ~133 ~119 oak_wood
setblock ~19 ~133 ~120 oak_leaves[persistent=true]
setblock ~19 ~133 ~121 jungle_leaves[persistent=true]
setblock ~19 ~133 ~122 oak_leaves[persistent=true]
setblock ~19 ~133 ~123 oak_wood
setblock ~19 ~134 ~92 oak_leaves[persistent=true]
setblock ~19 ~134 ~93 oak_leaves[persistent=true]
setblock ~19 ~134 ~94 jungle_leaves[persistent=true]
setblock ~19 ~134 ~95 jungle_leaves[persistent=true]
setblock ~19 ~134 ~96 oak_leaves[persistent=true]
setblock ~19 ~134 ~97 oak_leaves[persistent=true]
setblock ~19 ~134 ~99 oak_leaves[persistent=true]
setblock ~19 ~134 ~100 oak_leaves[persistent=true]
setblock ~19 ~134 ~101 oak_leaves[persistent=true]
setblock ~19 ~134 ~102 oak_leaves[persistent=true]
setblock ~19 ~134 ~103 oak_leaves[persistent=true]
setblock ~19 ~134 ~105 oak_leaves[persistent=true]
setblock ~19 ~134 ~106 oak_leaves[persistent=true]
setblock ~19 ~134 ~107 oak_leaves[persistent=true]
setblock ~19 ~134 ~108 jungle_leaves[persistent=true]
setblock ~19 ~134 ~109 oak_leaves[persistent=true]
setblock ~19 ~134 ~111 oak_leaves[persistent=true]
setblock ~19 ~134 ~114 oak_leaves[persistent=true]
setblock ~19 ~134 ~115 jungle_leaves[persistent=true]
setblock ~19 ~134 ~116 jungle_leaves[persistent=true]
setblock ~19 ~134 ~117 oak_leaves[persistent=true]
setblock ~19 ~134 ~118 oak_leaves[persistent=true]
setblock ~19 ~134 ~120 oak_leaves[persistent=true]
setblock ~19 ~134 ~121 oak_leaves[persistent=true]
setblock ~19 ~134 ~122 jungle_leaves[persistent=true]
setblock ~19 ~134 ~123 oak_leaves[persistent=true]
setblock ~19 ~135 ~92 oak_leaves[persistent=true]
setblock ~19 ~135 ~93 oak_leaves[persistent=true]
setblock ~19 ~135 ~94 oak_leaves[persistent=true]
setblock ~19 ~135 ~95 jungle_leaves[persistent=true]
setblock ~19 ~135 ~96 oak_leaves[persistent=true]
setblock ~19 ~135 ~97 oak_leaves[persistent=true]
setblock ~19 ~135 ~98 oak_leaves[persistent=true]
setblock ~19 ~135 ~99 oak_leaves[persistent=true]
setblock ~19 ~135 ~100 oak_leaves[persistent=true]
setblock ~19 ~135 ~101 oak_leaves[persistent=true]
setblock ~19 ~135 ~102 oak_leaves[persistent=true]
setblock ~19 ~135 ~103 oak_leaves[persistent=true]
setblock ~19 ~135 ~105 oak_leaves[persistent=true]
setblock ~19 ~135 ~106 oak_leaves[persistent=true]
setblock ~19 ~135 ~107 oak_wood
setblock ~19 ~135 ~108 oak_leaves[persistent=true]
setblock ~19 ~135 ~109 oak_leaves[persistent=true]
setblock ~19 ~135 ~112 oak_leaves[persistent=true]
setblock ~19 ~135 ~113 oak_leaves[persistent=true]
setblock ~19 ~135 ~114 oak_leaves[persistent=true]
setblock ~19 ~135 ~115 oak_leaves[persistent=true]
setblock ~19 ~135 ~116 oak_leaves[persistent=true]
setblock ~19 ~135 ~117 oak_leaves[persistent=true]
setblock ~19 ~135 ~119 oak_leaves[persistent=true]
setblock ~19 ~135 ~120 oak_leaves[persistent=true]
setblock ~19 ~135 ~122 oak_leaves[persistent=true]
setblock ~19 ~135 ~123 jungle_leaves[persistent=true]
setblock ~19 ~135 ~125 jungle_leaves[persistent=true]
setblock ~19 ~135 ~126 oak_leaves[persistent=true]
setblock ~19 ~135 ~127 oak_leaves[persistent=true]
setblock ~19 ~135 ~128 oak_leaves[persistent=true]
setblock ~19 ~136 ~92 oak_leaves[persistent=true]
setblock ~19 ~136 ~93 oak_leaves[persistent=true]
setblock ~19 ~136 ~94 oak_leaves[persistent=true]
setblock ~19 ~136 ~95 oak_leaves[persistent=true]
setblock ~19 ~136 ~98 oak_leaves[persistent=true]
setblock ~19 ~136 ~99 oak_leaves[persistent=true]
setblock ~19 ~136 ~100 oak_leaves[persistent=true]
setblock ~19 ~136 ~101 oak_leaves[persistent=true]
setblock ~19 ~136 ~105 jungle_leaves[persistent=true]
setblock ~19 ~136 ~106 oak_leaves[persistent=true]
setblock ~19 ~136 ~107 jungle_leaves[persistent=true]
setblock ~19 ~136 ~108 oak_leaves[persistent=true]
setblock ~19 ~136 ~109 oak_leaves[persistent=true]
setblock ~19 ~136 ~111 oak_leaves[persistent=true]
setblock ~19 ~136 ~113 oak_leaves[persistent=true]
setblock ~19 ~136 ~115 oak_leaves[persistent=true]
setblock ~19 ~136 ~116 oak_leaves[persistent=true]
setblock ~19 ~136 ~117 oak_leaves[persistent=true]
setblock ~19 ~136 ~118 oak_leaves[persistent=true]
setblock ~19 ~136 ~125 oak_leaves[persistent=true]
setblock ~19 ~136 ~126 oak_leaves[persistent=true]
setblock ~19 ~136 ~127 oak_leaves[persistent=true]
setblock ~19 ~137 ~98 jungle_leaves[persistent=true]
setblock ~19 ~137 ~99 jungle_leaves[persistent=true]
setblock ~19 ~137 ~100 oak_leaves[persistent=true]
setblock ~19 ~137 ~111 oak_leaves[persistent=true]
setblock ~19 ~137 ~113 oak_leaves[persistent=true]
setblock ~19 ~137 ~114 jungle_leaves[persistent=true]
setblock ~19 ~137 ~115 jungle_leaves[persistent=true]
setblock ~19 ~137 ~116 oak_leaves[persistent=true]
setblock ~19 ~137 ~117 oak_leaves[persistent=true]
setblock ~19 ~137 ~125 oak_leaves[persistent=true]
setblock ~19 ~137 ~126 oak_leaves[persistent=true]
setblock ~19 ~137 ~127 oak_leaves[persistent=true]
setblock ~19 ~137 ~128 jungle_leaves[persistent=true]
setblock ~19 ~138 ~111 oak_leaves[persistent=true]
setblock ~19 ~138 ~112 oak_leaves[persistent=true]
setblock ~19 ~138 ~113 jungle_leaves[persistent=true]
setblock ~19 ~138 ~114 jungle_leaves[persistent=true]
setblock ~19 ~138 ~115 oak_leaves[persistent=true]
setblock ~19 ~138 ~116 oak_leaves[persistent=true]
setblock ~19 ~138 ~117 oak_leaves[persistent=true]
setblock ~19 ~138 ~125 oak_leaves[persistent=true]
setblock ~19 ~138 ~126 oak_leaves[persistent=true]
setblock ~19 ~138 ~127 oak_leaves[persistent=true]
setblock ~19 ~138 ~128 oak_leaves[persistent=true]
setblock ~19 ~139 ~98 oak_leaves[persistent=true]
setblock ~19 ~139 ~99 jungle_leaves[persistent=true]
setblock ~20 ~127 ~115 oak_leaves[persistent=true]
setblock ~20 ~127 ~116 oak_leaves[persistent=true]
setblock ~20 ~127 ~117 jungle_leaves[persistent=true]
setblock ~20 ~127 ~118 oak_leaves[persistent=true]
setblock ~20 ~128 ~106 jungle_leaves[persistent=true]
setblock ~20 ~128 ~107 oak_leaves[persistent=true]
setblock ~20 ~128 ~108 jungle_leaves[persistent=true]
setblock ~20 ~128 ~109 oak_leaves[persistent=true]
setblock ~20 ~128 ~110 jungle_leaves[persistent=true]
setblock ~20 ~128 ~115 oak_leaves[persistent=true]
setblock ~20 ~128 ~116 jungle_leaves[persistent=true]
setblock ~20 ~128 ~117 oak_leaves[persistent=true]
setblock ~20 ~128 ~118 oak_leaves[persistent=true]
setblock ~20 ~128 ~119 oak_leaves[persistent=true]
setblock ~20 ~128 ~120 oak_leaves[persistent=true]
setblock ~20 ~129 ~105 oak_leaves[persistent=true]
setblock ~20 ~129 ~106 oak_leaves[persistent=true]
setblock ~20 ~129 ~107 jungle_leaves[persistent=true]
setblock ~20 ~129 ~108 oak_leaves[persistent=true]
setblock ~20 ~129 ~109 oak_leaves[persistent=true]
setblock ~20 ~129 ~110 jungle_leaves[persistent=true]
setblock ~20 ~129 ~113 oak_leaves[persistent=true]
setblock ~20 ~129 ~115 oak_leaves[persistent=true]
setblock ~20 ~129 ~116 oak_leaves[persistent=true]
setblock ~20 ~129 ~117 oak_leaves[persistent=true]
setblock ~20 ~129 ~118 oak_leaves[persistent=true]
setblock ~20 ~129 ~119 oak_leaves[persistent=true]
setblock ~20 ~129 ~120 oak_leaves[persistent=true]
setblock ~20 ~130 ~102 oak_leaves[persistent=true]
setblock ~20 ~130 ~103 oak_leaves[persistent=true]
setblock ~20 ~130 ~105 oak_leaves[persistent=true]
setblock ~20 ~130 ~106 jungle_leaves[persistent=true]
setblock ~20 ~130 ~107 oak_leaves[persistent=true]
setblock ~20 ~130 ~108 oak_leaves[persistent=true]
setblock ~20 ~130 ~109 oak_leaves[persistent=true]
setblock ~20 ~130 ~110 jungle_leaves[persistent=true]
setblock ~20 ~130 ~113 oak_leaves[persistent=true]
setblock ~20 ~130 ~115 jungle_leaves[persistent=true]
setblock ~20 ~130 ~116 oak_leaves[persistent=true]
setblock ~20 ~130 ~117 oak_leaves[persistent=true]
setblock ~20 ~130 ~118 jungle_leaves[persistent=true]
setblock ~20 ~130 ~119 oak_leaves[persistent=true]
setblock ~20 ~130 ~120 oak_leaves[persistent=true]
setblock ~20 ~131 ~101 oak_leaves[persistent=true]
setblock ~20 ~131 ~102 oak_leaves[persistent=true]
setblock ~20 ~131 ~103 oak_leaves[persistent=true]
setblock ~20 ~131 ~105 oak_leaves[persistent=true]
setblock ~20 ~131 ~106 oak_leaves[persistent=true]
setblock ~20 ~131 ~107 jungle_leaves[persistent=true]
setblock ~20 ~131 ~108 jungle_leaves[persistent=true]
setblock ~20 ~131 ~110 oak_leaves[persistent=true]
setblock ~20 ~131 ~111 jungle_leaves[persistent=true]
setblock ~20 ~131 ~113 oak_leaves[persistent=true]
setblock ~20 ~131 ~114 oak_leaves[persistent=true]
setblock ~20 ~131 ~115 oak_leaves[persistent=true]
setblock ~20 ~131 ~116 oak_leaves[persistent=true]
setblock ~20 ~131 ~117 jungle_leaves[persistent=true]
setblock ~20 ~131 ~118 oak_leaves[persistent=true]
setblock ~20 ~131 ~119 oak_wood
setblock ~20 ~131 ~120 jungle_leaves[persistent=true]
setblock ~20 ~131 ~121 oak_leaves[persistent=true]
setblock ~20 ~131 ~123 oak_leaves[persistent=true]
setblock ~20 ~131 ~124 oak_leaves[persistent=true]
setblock ~20 ~131 ~125 oak_leaves[persistent=true]
setblock ~20 ~132 ~96 jungle_leaves[persistent=true]
setblock ~20 ~132 ~97 oak_leaves[persistent=true]
setblock ~20 ~132 ~98 oak_leaves[persistent=true]
setblock ~20 ~132 ~99 oak_leaves[persistent=true]
setblock ~20 ~132 ~101 jungle_leaves[persistent=true]
setblock ~20 ~132 ~102 oak_leaves[persistent=true]
setblock ~20 ~132 ~103 jungle_leaves[persistent=true]
setblock ~20 ~132 ~108 oak_leaves[persistent=true]
setblock ~20 ~132 ~109 oak_leaves[persistent=true]
setblock ~20 ~132 ~110 oak_leaves[persistent=true]
setblock ~20 ~132 ~114 oak_leaves[persistent=true]
setblock ~20 ~132 ~115 oak_leaves[persistent=true]
setblock ~20 ~132 ~116 oak_leaves[persistent=true]
setblock ~20 ~132 ~117 oak_leaves[persistent=true]
setblock ~20 ~132 ~118 oak_leaves[persistent=true]
setblock ~20 ~132 ~119 oak_leaves[persistent=true]
setblock ~20 ~132 ~120 oak_leaves[persistent=true]
setblock ~20 ~132 ~121 oak_leaves[persistent=true]
setblock ~20 ~132 ~122 oak_leaves[persistent=true]
setblock ~20 ~132 ~123 oak_leaves[persistent=true]
setblock ~20 ~132 ~124 oak_leaves[persistent=true]
setblock ~20 ~132 ~125 jungle_leaves[persistent=true]
setblock ~20 ~133 ~92 oak_leaves[persistent=true]
setblock ~20 ~133 ~93 oak_leaves[persistent=true]
setblock ~20 ~133 ~94 oak_leaves[persistent=true]
setblock ~20 ~133 ~95 oak_leaves[persistent=true]
setblock ~20 ~133 ~96 oak_leaves[persistent=true]
setblock ~20 ~133 ~97 oak_leaves[persistent=true]
setblock ~20 ~133 ~98 oak_leaves[persistent=true]
setblock ~20 ~133 ~99 oak_leaves[persistent=true]
setblock ~20 ~133 ~101 jungle_leaves[persistent=true]
setblock ~20 ~133 ~102 oak_leaves[persistent=true]
setblock ~20 ~133 ~103 jungle_leaves[persistent=true]
setblock ~20 ~133 ~104 oak_leaves[persistent=true]
setblock ~20 ~133 ~105 oak_leaves[persistent=true]
setblock ~20 ~133 ~106 oak_leaves[persistent=true]
setblock ~20 ~133 ~107 jungle_leaves[persistent=true]
setblock ~20 ~133 ~109 oak_leaves[persistent=true]
setblock ~20 ~133 ~110 oak_leaves[persistent=true]
setblock ~20 ~133 ~111 jungle_leaves[persistent=true]
setblock ~20 ~133 ~112 oak_leaves[persistent=true]
setblock ~20 ~133 ~113 oak_leaves[persistent=true]
setblock ~20 ~133 ~114 oak_leaves[persistent=true]
setblock ~20 ~133 ~115 oak_leaves[persistent=true]
setblock ~20 ~133 ~116 jungle_leaves[persistent=true]
setblock ~20 ~133 ~117 oak_leaves[persistent=true]
setblock ~20 ~133 ~118 oak_wood
setblock ~20 ~133 ~119 oak_leaves[persistent=true]
setblock ~20 ~133 ~120 oak_leaves[persistent=true]
setblock ~20 ~133 ~121 oak_leaves[persistent=true]
setblock ~20 ~133 ~122 oak_wood
setblock ~20 ~133 ~123 oak_leaves[persistent=true]
setblock ~20 ~133 ~124 oak_leaves[persistent=true]
setblock ~20 ~133 ~125 jungle_leaves[persistent=true]
setblock ~20 ~134 ~92 oak_leaves[persistent=true]
setblock ~20 ~134 ~93 oak_leaves[persistent=true]
setblock ~20 ~134 ~94 jungle_leaves[persistent=true]
setblock ~20 ~134 ~96 oak_leaves[persistent=true]
setblock ~20 ~134 ~97 oak_leaves[persistent=true]
setblock ~20 ~134 ~98 oak_wood
setblock ~20 ~134 ~99 oak_leaves[persistent=true]
setblock ~20 ~134 ~100 oak_leaves[persistent=true]
setblock ~20 ~134 ~101 oak_leaves[persistent=true]
setblock ~20 ~134 ~102 oak_leaves[persistent=true]
setblock ~20 ~134 ~103 oak_leaves[persistent=true]
setblock ~20 ~134 ~104 oak_leaves[persistent=true]
setblock ~20 ~134 ~105 jungle_leaves[persistent=true]
setblock ~20 ~134 ~106 jungle_leaves[persistent=true]
setblock ~20 ~134 ~107 oak_leaves[persistent=true]
setblock ~20 ~134 ~108 jungle_leaves[persistent=true]
setblock ~20 ~134 ~109 jungle_leaves[persistent=true]
setblock ~20 ~134 ~110 oak_leaves[persistent=true]
setblock ~20 ~134 ~111 oak_leaves[persistent=true]
setblock ~20 ~134 ~112 oak_wood
setblock ~20 ~134 ~113 oak_leaves[persistent=true]
setblock ~20 ~134 ~114 jungle_leaves[persistent=true]
setblock ~20 ~134 ~115 oak_leaves[persistent=true]
setblock ~20 ~134 ~116 oak_leaves[persistent=true]
setblock ~20 ~134 ~117 oak_leaves[persistent=true]
setblock ~20 ~134 ~118 oak_leaves[persistent=true]
setblock ~20 ~134 ~120 oak_leaves[persistent=true]
setblock ~20 ~134 ~121 oak_wood
setblock ~20 ~134 ~122 oak_leaves[persistent=true]
setblock ~20 ~134 ~123 jungle_leaves[persistent=true]
setblock ~20 ~135 ~92 oak_leaves[persistent=true]
setblock ~20 ~135 ~94 jungle_leaves[persistent=true]
setblock ~20 ~135 ~95 oak_leaves[persistent=true]
setblock ~20 ~135 ~96 oak_leaves[persistent=true]
setblock ~20 ~135 ~97 jungle_leaves[persistent=true]
setblock ~20 ~135 ~98 oak_leaves[persistent=true]
setblock ~20 ~135 ~99 oak_leaves[persistent=true]
setblock ~20 ~135 ~100 oak_leaves[persistent=true]
setblock ~20 ~135 ~102 oak_leaves[persistent=true]
setblock ~20 ~135 ~103 oak_leaves[persistent=true]
setblock ~20 ~135 ~105 oak_leaves[persistent=true]
setblock ~20 ~135 ~106 jungle_leaves[persistent=true]
setblock ~20 ~135 ~107 jungle_leaves[persistent=true]
setblock ~20 ~135 ~108 oak_wood
setblock ~20 ~135 ~110 oak_leaves[persistent=true]
setblock ~20 ~135 ~111 oak_leaves[persistent=true]
setblock ~20 ~135 ~112 oak_leaves[persistent=true]
setblock ~20 ~135 ~114 oak_leaves[persistent=true]
setblock ~20 ~135 ~115 oak_leaves[persistent=true]
setblock ~20 ~135 ~116 oak_leaves[persistent=true]
setblock ~20 ~135 ~117 oak_leaves[persistent=true]
setblock ~20 ~135 ~118 oak_leaves[persistent=true]
setblock ~20 ~135 ~119 oak_leaves[persistent=true]
setblock ~20 ~135 ~121 oak_leaves[persistent=true]
setblock ~20 ~135 ~122 oak_leaves[persistent=true]
setblock ~20 ~135 ~123 oak_leaves[persistent=true]
setblock ~20 ~135 ~125 oak_leaves[persistent=true]
setblock ~20 ~135 ~126 jungle_leaves[persistent=true]
setblock ~20 ~135 ~128 oak_leaves[persistent=true]
setblock ~20 ~136 ~92 oak_leaves[persistent=true]
setblock ~20 ~136 ~93 oak_leaves[persistent=true]
setblock ~20 ~136 ~94 oak_leaves[persistent=true]
setblock ~20 ~136 ~96 oak_leaves[persistent=true]
setblock ~20 ~136 ~98 oak_leaves[persistent=true]
setblock ~20 ~136 ~99 oak_leaves[persistent=true]
setblock ~20 ~136 ~100 oak_leaves[persistent=true]
setblock ~20 ~136 ~101 oak_leaves[persistent=true]
setblock ~20 ~136 ~102 oak_leaves[persistent=true]
setblock ~20 ~136 ~103 oak_leaves[persistent=true]
setblock ~20 ~136 ~104 oak_leaves[persistent=true]
setblock ~20 ~136 ~106 oak_leaves[persistent=true]
setblock ~20 ~136 ~107 jungle_leaves[persistent=true]
setblock ~20 ~136 ~108 oak_leaves[persistent=true]
setblock ~20 ~136 ~109 oak_leaves[persistent=true]
setblock ~20 ~136 ~110 oak_leaves[persistent=true]
setblock ~20 ~136 ~111 oak_leaves[persistent=true]
setblock ~20 ~136 ~112 oak_leaves[persistent=true]
setblock ~20 ~136 ~113 oak_leaves[persistent=true]
setblock ~20 ~136 ~114 oak_leaves[persistent=true]
setblock ~20 ~136 ~115 oak_leaves[persistent=true]
setblock ~20 ~136 ~116 oak_wood
setblock ~20 ~136 ~117 oak_leaves[persistent=true]
setblock ~20 ~136 ~118 oak_leaves[persistent=true]
setblock ~20 ~136 ~119 oak_leaves[persistent=true]
setblock ~20 ~136 ~120 oak_leaves[persistent=true]
setblock ~20 ~136 ~125 jungle_leaves[persistent=true]
setblock ~20 ~136 ~126 oak_leaves[persistent=true]
setblock ~20 ~136 ~127 oak_leaves[persistent=true]
setblock ~20 ~136 ~128 oak_leaves[persistent=true]
setblock ~20 ~137 ~98 oak_leaves[persistent=true]
setblock ~20 ~137 ~99 jungle_leaves[persistent=true]
setblock ~20 ~137 ~100 oak_leaves[persistent=true]
setblock ~20 ~137 ~101 oak_leaves[persistent=true]
setblock ~20 ~137 ~111 oak_leaves[persistent=true]
setblock ~20 ~137 ~112 oak_leaves[persistent=true]
setblock ~20 ~137 ~113 oak_leaves[persistent=true]
setblock ~20 ~137 ~114 oak_leaves[persistent=true]
setblock ~20 ~137 ~115 oak_leaves[persistent=true]
setblock ~20 ~137 ~116 oak_leaves[persistent=true]
setblock ~20 ~137 ~117 oak_leaves[persistent=true]
setblock ~20 ~137 ~118 oak_leaves[persistent=true]
setblock ~20 ~137 ~119 jungle_leaves[persistent=true]
setblock ~20 ~137 ~120 oak_leaves[persistent=true]
setblock ~20 ~137 ~125 oak_leaves[persistent=true]
setblock ~20 ~137 ~126 jungle_leaves[persistent=true]
setblock ~20 ~137 ~127 oak_leaves[persistent=true]
setblock ~20 ~137 ~128 oak_leaves[persistent=true]
setblock ~20 ~138 ~98 jungle_leaves[persistent=true]
setblock ~20 ~138 ~99 oak_wood
setblock ~20 ~138 ~100 oak_leaves[persistent=true]
setblock ~20 ~138 ~111 oak_leaves[persistent=true]
setblock ~20 ~138 ~112 oak_leaves[persistent=true]
setblock ~20 ~138 ~113 oak_leaves[persistent=true]
setblock ~20 ~138 ~114 oak_leaves[persistent=true]
setblock ~20 ~138 ~115 jungle_leaves[persistent=true]
setblock ~20 ~138 ~116 oak_leaves[persistent=true]
setblock ~20 ~138 ~117 oak_leaves[persistent=true]
setblock ~20 ~138 ~118 jungle_leaves[persistent=true]
setblock ~20 ~138 ~120 oak_leaves[persistent=true]
setblock ~20 ~138 ~125 oak_leaves[persistent=true]
setblock ~20 ~138 ~126 oak_leaves[persistent=true]
setblock ~20 ~138 ~128 oak_leaves[persistent=true]
setblock ~20 ~139 ~98 oak_leaves[persistent=true]
setblock ~20 ~139 ~99 oak_leaves[persistent=true]
setblock ~20 ~139 ~100 oak_leaves[persistent=true]
setblock ~21 ~127 ~115 oak_leaves[persistent=true]
setblock ~21 ~127 ~117 jungle_leaves[persistent=true]
setblock ~21 ~127 ~118 oak_leaves[persistent=true]
setblock ~21 ~128 ~105 oak_leaves[persistent=true]
setblock ~21 ~128 ~106 oak_leaves[persistent=true]
setblock ~21 ~128 ~107 oak_leaves[persistent=true]
setblock ~21 ~128 ~108 oak_leaves[persistent=true]
setblock ~21 ~128 ~109 oak_leaves[persistent=true]
setblock ~21 ~128 ~110 oak_leaves[persistent=true]
setblock ~21 ~128 ~115 oak_leaves[persistent=true]
setblock ~21 ~128 ~116 jungle_leaves[persistent=true]
setblock ~21 ~128 ~117 oak_leaves[persistent=true]
setblock ~21 ~128 ~118 jungle_leaves[persistent=true]
setblock ~21 ~128 ~119 oak_leaves[persistent=true]
setblock ~21 ~128 ~120 jungle_leaves[persistent=true]
setblock ~21 ~129 ~95 oak_leaves[persistent=true]
setblock ~21 ~129 ~96 oak_leaves[persistent=true]
setblock ~21 ~129 ~97 oak_leaves[persistent=true]
setblock ~21 ~129 ~98 oak_leaves[persistent=true]
setblock ~21 ~129 ~105 oak_leaves[persistent=true]
setblock ~21 ~129 ~106 jungle_leaves[persistent=true]
setblock ~21 ~129 ~107 oak_leaves[persistent=true]
setblock ~21 ~129 ~108 oak_leaves[persistent=true]
setblock ~21 ~129 ~109 oak_leaves[persistent=true]
setblock ~21 ~129 ~110 oak_leaves[persistent=true]
setblock ~21 ~129 ~112 oak_leaves[persistent=true]
setblock ~21 ~129 ~113 oak_leaves[persistent=true]
setblock ~21 ~129 ~115 oak_leaves[persistent=true]
setblock ~21 ~129 ~116 oak_leaves[persistent=true]
setblock ~21 ~129 ~117 oak_leaves[persistent=true]
setblock ~21 ~129 ~118 jungle_leaves[persistent=true]
setblock ~21 ~129 ~119 oak_leaves[persistent=true]
setblock ~21 ~129 ~120 oak_leaves[persistent=true]
setblock ~21 ~129 ~121 oak_leaves[persistent=true]
setblock ~21 ~129 ~122 oak_leaves[persistent=true]
setblock ~21 ~129 ~123 oak_leaves[persistent=true]
setblock ~21 ~130 ~95 jungle_leaves[persistent=true]
setblock ~21 ~130 ~96 oak_leaves[persistent=true]
setblock ~21 ~130 ~97 jungle_leaves[persistent=true]
setblock ~21 ~130 ~98 oak_leaves[persistent=true]
setblock ~21 ~130 ~101 jungle_leaves[persistent=true]
setblock ~21 ~130 ~102 oak_leaves[persistent=true]
setblock ~21 ~130 ~103 oak_leaves[persistent=true]
setblock ~21 ~130 ~105 oak_leaves[persistent=true]
setblock ~21 ~130 ~106 jungle_leaves[persistent=true]
setblock ~21 ~130 ~107 oak_leaves[persistent=true]
setblock ~21 ~130 ~108 jungle_leaves[persistent=true]
setblock ~21 ~130 ~109 oak_leaves[persistent=true]
setblock ~21 ~130 ~110 oak_leaves[persistent=true]
setblock ~21 ~130 ~112 jungle_leaves[persistent=true]
setblock ~21 ~130 ~113 oak_leaves[persistent=true]
setblock ~21 ~130 ~114 oak_leaves[persistent=true]
setblock ~21 ~130 ~116 jungle_leaves[persistent=true]
setblock ~21 ~130 ~117 oak_leaves[persistent=true]
setblock ~21 ~130 ~118 jungle_leaves[persistent=true]
setblock ~21 ~130 ~119 oak_leaves[persistent=true]
setblock ~21 ~130 ~120 oak_leaves[persistent=true]
setblock ~21 ~130 ~121 oak_leaves[persistent=true]
setblock ~21 ~130 ~122 jungle_leaves[persistent=true]
setblock ~21 ~130 ~123 oak_leaves[persistent=true]
setblock ~21 ~130 ~124 oak_leaves[persistent=true]
setblock ~21 ~131 ~93 oak_leaves[persistent=true]
setblock ~21 ~131 ~95 oak_leaves[persistent=true]
setblock ~21 ~131 ~96 jungle_leaves[persistent=true]
setblock ~21 ~131 ~97 oak_leaves[persistent=true]
setblock ~21 ~131 ~101 jungle_leaves[persistent=true]
setblock ~21 ~131 ~102 oak_leaves[persistent=true]
setblock ~21 ~131 ~103 oak_wood
setblock ~21 ~131 ~104 oak_leaves[persistent=true]
setblock ~21 ~131 ~105 oak_leaves[persistent=true]
setblock ~21 ~131 ~106 jungle_leaves[persistent=true]
setblock ~21 ~131 ~107 oak_leaves[persistent=true]
setblock ~21 ~131 ~108 jungle_leaves[persistent=true]
setblock ~21 ~131 ~109 oak_leaves[persistent=true]
setblock ~21 ~131 ~111 oak_leaves[persistent=true]
setblock ~21 ~131 ~112 oak_leaves[persistent=true]
setblock ~21 ~131 ~113 oak_leaves[persistent=true]
setblock ~21 ~131 ~114 jungle_leaves[persistent=true]
setblock ~21 ~131 ~115 oak_leaves[persistent=true]
setblock ~21 ~131 ~117 oak_leaves[persistent=true]
setblock ~21 ~131 ~119 oak_wood
setblock ~21 ~131 ~120 oak_leaves[persistent=true]
setblock ~21 ~131 ~122 oak_leaves[persistent=true]
setblock ~21 ~131 ~123 oak_leaves[persistent=true]
setblock ~21 ~131 ~124 oak_leaves[persistent=true]
setblock ~21 ~131 ~125 jungle_leaves[persistent=true]
setblock ~21 ~132 ~94 oak_leaves[persistent=true]
setblock ~21 ~132 ~95 oak_leaves[persistent=true]
setblock ~21 ~132 ~96 jungle_leaves[persistent=true]
setblock ~21 ~132 ~97 oak_leaves[persistent=true]
setblock ~21 ~132 ~99 oak_leaves[persistent=true]
setblock ~21 ~132 ~101 oak_leaves[persistent=true]
setblock ~21 ~132 ~102 oak_leaves[persistent=true]
setblock ~21 ~132 ~103 oak_leaves[persistent=true]
setblock ~21 ~132 ~104 oak_leaves[persistent=true]
setblock ~21 ~132 ~105 oak_leaves[persistent=true]
setblock ~21 ~132 ~106 oak_leaves[persistent=true]
setblock ~21 ~132 ~107 oak_leaves[persistent=true]
setblock ~21 ~132 ~108 jungle_leaves[persistent=true]
setblock ~21 ~132 ~109 oak_leaves[persistent=true]
setblock ~21 ~132 ~111 oak_leaves[persistent=true]
setblock ~21 ~132 ~112 oak_leaves[persistent=true]
setblock ~21 ~132 ~113 jungle_leaves[persistent=true]
setblock ~21 ~132 ~114 oak_leaves[persistent=true]
setblock ~21 ~132 ~115 oak_leaves[persistent=true]
setblock ~21 ~132 ~116 jungle_leaves[persistent=true]
setblock ~21 ~132 ~117 oak_leaves[persistent=true]
setblock ~21 ~132 ~118 oak_leaves[persistent=true]
setblock ~21 ~132 ~119 oak_leaves[persistent=true]
setblock ~21 ~132 ~120 jungle_leaves[persistent=true]
setblock ~21 ~132 ~121 oak_leaves[persistent=true]
setblock ~21 ~132 ~122 oak_leaves[persistent=true]
setblock ~21 ~132 ~123 oak_leaves[persistent=true]
setblock ~21 ~132 ~124 oak_wood
setblock ~21 ~132 ~125 jungle_leaves[persistent=true]
setblock ~21 ~133 ~92 oak_leaves[persistent=true]
setblock ~21 ~133 ~93 oak_leaves[persistent=true]
setblock ~21 ~133 ~94 jungle_leaves[persistent=true]
setblock ~21 ~133 ~95 oak_leaves[persistent=true]
setblock ~21 ~133 ~96 jungle_leaves[persistent=true]
setblock ~21 ~133 ~97 oak_leaves[persistent=true]
setblock ~21 ~133 ~98 oak_leaves[persistent=true]
setblock ~21 ~133 ~99 oak_leaves[persistent=true]
setblock ~21 ~133 ~101 oak_leaves[persistent=true]
setblock ~21 ~133 ~102 oak_leaves[persistent=true]
setblock ~21 ~133 ~103 oak_leaves[persistent=true]
setblock ~21 ~133 ~104 oak_leaves[persistent=true]
setblock ~21 ~133 ~106 oak_leaves[persistent=true]
setblock ~21 ~133 ~107 oak_leaves[persistent=true]
setblock ~21 ~133 ~108 oak_leaves[persistent=true]
setblock ~21 ~133 ~110 oak_leaves[persistent=true]
setblock ~21 ~133 ~111 oak_leaves[persistent=true]
setblock ~21 ~133 ~112 oak_leaves[persistent=true]
setblock ~21 ~133 ~113 oak_leaves[persistent=true]
setblock ~21 ~133 ~114 oak_leaves[persistent=true]
setblock ~21 ~133 ~115 oak_leaves[persistent=true]
setblock ~21 ~133 ~116 jungle_leaves[persistent=true]
setblock ~21 ~133 ~117 oak_leaves[persistent=true]
setblock ~21 ~133 ~118 oak_wood
setblock ~21 ~133 ~119 oak_leaves[persistent=true]
setblock ~21 ~133 ~120 oak_wood
setblock ~21 ~133 ~121 jungle_leaves[persistent=true]
setblock ~21 ~133 ~122 oak_leaves[persistent=true]
setblock ~21 ~133 ~123 oak_leaves[persistent=true]
setblock ~21 ~133 ~125 oak_leaves[persistent=true]
setblock ~21 ~134 ~93 oak_leaves[persistent=true]
setblock ~21 ~134 ~94 oak_leaves[persistent=true]
setblock ~21 ~134 ~95 jungle_leaves[persistent=true]
setblock ~21 ~134 ~96 oak_leaves[persistent=true]
setblock ~21 ~134 ~97 oak_leaves[persistent=true]
setblock ~21 ~134 ~98 oak_wood
setblock ~21 ~134 ~99 oak_leaves[persistent=true]
setblock ~21 ~134 ~100 oak_leaves[persistent=true]
setblock ~21 ~134 ~101 oak_leaves[persistent=true]
setblock ~21 ~134 ~102 oak_leaves[persistent=true]
setblock ~21 ~134 ~103 oak_wood
setblock ~21 ~134 ~104 jungle_leaves[persistent=true]
setblock ~21 ~134 ~105 oak_leaves[persistent=true]
setblock ~21 ~134 ~106 oak_leaves[persistent=true]
setblock ~21 ~134 ~107 oak_leaves[persistent=true]
setblock ~21 ~134 ~109 oak_leaves[persistent=true]
setblock ~21 ~134 ~110 oak_leaves[persistent=true]
setblock ~21 ~134 ~111 oak_wood
setblock ~21 ~134 ~112 oak_leaves[persistent=true]
setblock ~21 ~134 ~113 oak_leaves[persistent=true]
setblock ~21 ~134 ~114 oak_leaves[persistent=true]
setblock ~21 ~134 ~115 oak_leaves[persistent=true]
setblock ~21 ~134 ~117 oak_leaves[persistent=true]
setblock ~21 ~134 ~118 oak_wood
setblock ~21 ~134 ~119 oak_wood
setblock ~21 ~134 ~120 oak_wood
setblock ~21 ~134 ~121 oak_wood
setblock ~21 ~134 ~122 oak_leaves[persistent=true]
setblock ~21 ~134 ~123 jungle_leaves[persistent=true]
setblock ~21 ~135 ~92 oak_leaves[persistent=true]
setblock ~21 ~135 ~93 oak_leaves[persistent=true]
setblock ~21 ~135 ~94 oak_leaves[persistent=true]
setblock ~21 ~135 ~95 oak_wood
setblock ~21 ~135 ~96 jungle_leaves[persistent=true]
setblock ~21 ~135 ~97 oak_leaves[persistent=true]
setblock ~21 ~135 ~98 oak_leaves[persistent=true]
setblock ~21 ~135 ~99 oak_leaves[persistent=true]
setblock ~21 ~135 ~100 oak_leaves[persistent=true]
setblock ~21 ~135 ~102 oak_leaves[persistent=true]
setblock ~21 ~135 ~103 jungle_leaves[persistent=true]
setblock ~21 ~135 ~104 oak_leaves[persistent=true]
setblock ~21 ~135 ~105 jungle_leaves[persistent=true]
setblock ~21 ~135 ~107 oak_leaves[persistent=true]
setblock ~21 ~135 ~108 jungle_leaves[persistent=true]
setblock ~21 ~135 ~109 oak_wood
setblock ~21 ~135 ~110 oak_wood
setblock ~21 ~135 ~111 oak_leaves[persistent=true]
setblock ~21 ~135 ~112 oak_leaves[persistent=true]
setblock ~21 ~135 ~113 oak_leaves[persistent=true]
setblock ~21 ~135 ~114 oak_leaves[persistent=true]
setblock ~21 ~135 ~115 jungle_leaves[persistent=true]
setblock ~21 ~135 ~116 oak_wood
setblock ~21 ~135 ~117 oak_leaves[persistent=true]
setblock ~21 ~135 ~118 oak_leaves[persistent=true]
setblock ~21 ~135 ~120 oak_leaves[persistent=true]
setblock ~21 ~135 ~122 oak_leaves[persistent=true]
setblock ~21 ~135 ~123 oak_leaves[persistent=true]
setblock ~21 ~135 ~125 oak_leaves[persistent=true]
setblock ~21 ~135 ~126 oak_leaves[persistent=true]
setblock ~21 ~135 ~127 jungle_leaves[persistent=true]
setblock ~21 ~135 ~128 jungle_leaves[persistent=true]
setblock ~21 ~136 ~93 oak_leaves[persistent=true]
setblock ~21 ~136 ~94 oak_leaves[persistent=true]
setblock ~21 ~136 ~95 oak_leaves[persistent=true]
setblock ~21 ~136 ~96 oak_leaves[persistent=true]
setblock ~21 ~136 ~97 oak_leaves[persistent=true]
setblock ~21 ~136 ~99 jungle_leaves[persistent=true]
setblock ~21 ~136 ~101 oak_leaves[persistent=true]
setblock ~21 ~136 ~102 jungle_leaves[persistent=true]
setblock ~21 ~136 ~103 oak_leaves[persistent=true]
setblock ~21 ~136 ~106 oak_leaves[persistent=true]
setblock ~21 ~136 ~107 oak_leaves[persistent=true]
setblock ~21 ~136 ~108 oak_leaves[persistent=true]
setblock ~21 ~136 ~109 oak_leaves[persistent=true]
setblock ~21 ~136 ~110 oak_leaves[persistent=true]
setblock ~21 ~136 ~111 oak_leaves[persistent=true]
setblock ~21 ~136 ~112 jungle_leaves[persistent=true]
setblock ~21 ~136 ~113 oak_wood
setblock ~21 ~136 ~114 oak_leaves[persistent=true]
setblock ~21 ~136 ~115 oak_wood
setblock ~21 ~136 ~116 oak_leaves[persistent=true]
setblock ~21 ~136 ~117 oak_leaves[persistent=true]
setblock ~21 ~136 ~118 oak_leaves[persistent=true]
setblock ~21 ~136 ~119 oak_leaves[persistent=true]
setblock ~21 ~136 ~120 oak_leaves[persistent=true]
setblock ~21 ~136 ~125 oak_leaves[persistent=true]
setblock ~21 ~136 ~126 oak_leaves[persistent=true]
setblock ~21 ~136 ~127 oak_leaves[persistent=true]
setblock ~21 ~136 ~128 oak_leaves[persistent=true]
setblock ~21 ~137 ~92 oak_leaves[persistent=true]
setblock ~21 ~137 ~93 oak_leaves[persistent=true]
setblock ~21 ~137 ~94 oak_leaves[persistent=true]
setblock ~21 ~137 ~95 jungle_leaves[persistent=true]
setblock ~21 ~137 ~96 oak_leaves[persistent=true]
setblock ~21 ~137 ~97 oak_leaves[persistent=true]
setblock ~21 ~137 ~98 oak_leaves[persistent=true]
setblock ~21 ~137 ~99 oak_leaves[persistent=true]
setblock ~21 ~137 ~100 oak_leaves[persistent=true]
setblock ~21 ~137 ~101 oak_leaves[persistent=true]
setblock ~21 ~137 ~107 oak_leaves[persistent=true]
setblock ~21 ~137 ~108 oak_leaves[persistent=true]
setblock ~21 ~137 ~109 oak_leaves[persistent=true]
setblock ~21 ~137 ~110 oak_leaves[persistent=true]
setblock ~21 ~137 ~111 oak_leaves[persistent=true]
setblock ~21 ~137 ~112 oak_leaves[persistent=true]
setblock ~21 ~137 ~113 oak_leaves[persistent=true]
setblock ~21 ~137 ~114 oak_leaves[persistent=true]
setblock ~21 ~137 ~115 oak_leaves[persistent=true]
setblock ~21 ~137 ~116 oak_leaves[persistent=true]
setblock ~21 ~137 ~117 oak_leaves[persistent=true]
setblock ~21 ~137 ~118 oak_leaves[persistent=true]
setblock ~21 ~137 ~119 jungle_leaves[persistent=true]
setblock ~21 ~137 ~120 oak_leaves[persistent=true]
setblock ~21 ~137 ~125 oak_leaves[persistent=true]
setblock ~21 ~137 ~126 oak_leaves[persistent=true]
setblock ~21 ~137 ~127 oak_leaves[persistent=true]
setblock ~21 ~137 ~128 oak_leaves[persistent=true]
setblock ~21 ~138 ~92 oak_leaves[persistent=true]
setblock ~21 ~138 ~93 oak_leaves[persistent=true]
setblock ~21 ~138 ~94 oak_leaves[persistent=true]
setblock ~21 ~138 ~95 oak_leaves[persistent=true]
setblock ~21 ~138 ~96 oak_leaves[persistent=true]
setblock ~21 ~138 ~98 oak_leaves[persistent=true]
setblock ~21 ~138 ~99 oak_wood
setblock ~21 ~138 ~100 oak_leaves[persistent=true]
setblock ~21 ~138 ~106 oak_leaves[persistent=true]
setblock ~21 ~138 ~107 jungle_leaves[persistent=true]
setblock ~21 ~138 ~108 oak_leaves[persistent=true]
setblock ~21 ~138 ~109 oak_leaves[persistent=true]
setblock ~21 ~138 ~110 oak_leaves[persistent=true]
setblock ~21 ~138 ~112 oak_leaves[persistent=true]
setblock ~21 ~138 ~113 oak_leaves[persistent=true]
setblock ~21 ~138 ~114 oak_leaves[persistent=true]
setblock ~21 ~138 ~115 oak_leaves[persistent=true]
setblock ~21 ~138 ~116 oak_leaves[persistent=true]
setblock ~21 ~138 ~117 oak_leaves[persistent=true]
setblock ~21 ~138 ~118 oak_leaves[persistent=true]
setblock ~21 ~138 ~119 oak_leaves[persistent=true]
setblock ~21 ~138 ~125 jungle_leaves[persistent=true]
setblock ~21 ~138 ~126 jungle_leaves[persistent=true]
setblock ~21 ~138 ~127 jungle_leaves[persistent=true]
setblock ~21 ~138 ~128 oak_leaves[persistent=true]
setblock ~21 ~139 ~94 oak_leaves[persistent=true]
setblock ~21 ~139 ~96 oak_leaves[persistent=true]
setblock ~21 ~139 ~98 oak_leaves[persistent=true]
setblock ~21 ~139 ~100 oak_leaves[persistent=true]
setblock ~21 ~139 ~109 oak_leaves[persistent=true]
setblock ~21 ~139 ~110 oak_leaves[persistent=true]
setblock ~21 ~139 ~111 oak_leaves[persistent=true]
setblock ~21 ~139 ~112 jungle_leaves[persistent=true]
setblock ~21 ~140 ~91 oak_leaves[persistent=true]
setblock ~21 ~140 ~92 oak_leaves[persistent=true]
setblock ~21 ~140 ~93 oak_leaves[persistent=true]
setblock ~21 ~140 ~109 oak_leaves[persistent=true]
setblock ~21 ~140 ~110 oak_leaves[persistent=true]
setblock ~21 ~140 ~112 oak_leaves[persistent=true]
setblock ~22 ~126 ~107 oak_leaves[persistent=true]
setblock ~22 ~126 ~108 oak_leaves[persistent=true]
setblock ~22 ~126 ~109 jungle_leaves[persistent=true]
setblock ~22 ~126 ~110 oak_leaves[persistent=true]
setblock ~22 ~127 ~99 oak_leaves[persistent=true]
setblock ~22 ~127 ~100 oak_leaves[persistent=true]
setblock ~22 ~127 ~101 jungle_leaves[persistent=true]
setblock ~22 ~127 ~102 oak_leaves[persistent=true]
setblock ~22 ~127 ~107 oak_leaves[persistent=true]
setblock ~22 ~127 ~108 oak_leaves[persistent=true]
setblock ~22 ~127 ~109 oak_leaves[persistent=true]
setblock ~22 ~127 ~110 oak_leaves[persistent=true]
setblock ~22 ~127 ~111 jungle_leaves[persistent=true]
setblock ~22 ~127 ~115 oak_leaves[persistent=true]
setblock ~22 ~127 ~116 oak_leaves[persistent=true]
setblock ~22 ~127 ~117 oak_leaves[persistent=true]
setblock ~22 ~127 ~118 oak_leaves[persistent=true]
setblock ~22 ~128 ~98 jungle_leaves[persistent=true]
setblock ~22 ~128 ~100 oak_leaves[persistent=true]
setblock ~22 ~128 ~101 oak_leaves[persistent=true]
setblock ~22 ~128 ~102 oak_leaves[persistent=true]
setblock ~22 ~128 ~105 jungle_leaves[persistent=true]
setblock ~22 ~128 ~106 oak_leaves[persistent=true]
setblock ~22 ~128 ~107 oak_leaves[persistent=true]
setblock ~22 ~128 ~108 oak_leaves[persistent=true]
setblock ~22 ~128 ~109 oak_leaves[persistent=true]
setblock ~22 ~128 ~110 oak_leaves[persistent=true]
setblock ~22 ~128 ~112 oak_leaves[persistent=true]
setblock ~22 ~128 ~113 oak_leaves[persistent=true]
setblock ~22 ~128 ~114 oak_leaves[persistent=true]
setblock ~22 ~128 ~115 jungle_leaves[persistent=true]
setblock ~22 ~128 ~116 oak_leaves[persistent=true]
setblock ~22 ~128 ~117 oak_leaves[persistent=true]
setblock ~22 ~128 ~118 jungle_leaves[persistent=true]
setblock ~22 ~128 ~119 oak_leaves[persistent=true]
setblock ~22 ~129 ~96 jungle_leaves[persistent=true]
setblock ~22 ~129 ~97 oak_leaves[persistent=true]
setblock ~22 ~129 ~98 jungle_leaves[persistent=true]
setblock ~22 ~129 ~99 oak_leaves[persistent=true]
setblock ~22 ~129 ~100 oak_leaves[persistent=true]
setblock ~22 ~129 ~101 oak_leaves[persistent=true]
setblock ~22 ~129 ~102 jungle_leaves[persistent=true]
setblock ~22 ~129 ~103 oak_leaves[persistent=true]
setblock ~22 ~129 ~104 oak_leaves[persistent=true]
setblock ~22 ~129 ~105 oak_leaves[persistent=true]
setblock ~22 ~129 ~106 jungle_leaves[persistent=true]
setblock ~22 ~129 ~107 oak_leaves[persistent=true]
setblock ~22 ~129 ~108 oak_leaves[persistent=true]
setblock ~22 ~129 ~109 oak_leaves[persistent=true]
setblock ~22 ~129 ~110 oak_leaves[persistent=true]
setblock ~22 ~129 ~111 oak_leaves[persistent=true]
setblock ~22 ~129 ~112 oak_leaves[persistent=true]
setblock ~22 ~129 ~113 oak_leaves[persistent=true]
setblock ~22 ~129 ~114 oak_leaves[persistent=true]
setblock ~22 ~129 ~115 oak_leaves[persistent=true]
setblock ~22 ~129 ~118 oak_wood
setblock ~22 ~129 ~119 oak_leaves[persistent=true]
setblock ~22 ~129 ~120 oak_leaves[persistent=true]
setblock ~22 ~129 ~121 oak_leaves[persistent=true]
setblock ~22 ~129 ~122 oak_leaves[persistent=true]
setblock ~22 ~129 ~123 oak_leaves[persistent=true]
setblock ~22 ~130 ~95 oak_leaves[persistent=true]
setblock ~22 ~130 ~96 jungle_leaves[persistent=true]
setblock ~22 ~130 ~97 oak_leaves[persistent=true]
setblock ~22 ~130 ~98 jungle_leaves[persistent=true]
setblock ~22 ~130 ~99 oak_leaves[persistent=true]
setblock ~22 ~130 ~101 oak_leaves[persistent=true]
setblock ~22 ~130 ~102 oak_leaves[persistent=true]
setblock ~22 ~130 ~103 oak_leaves[persistent=true]
setblock ~22 ~130 ~104 oak_leaves[persistent=true]
setblock ~22 ~130 ~105 oak_leaves[persistent=true]
setblock ~22 ~130 ~106 oak_leaves[persistent=true]
setblock ~22 ~130 ~107 oak_leaves[persistent=true]
setblock ~22 ~130 ~108 oak_wood
setblock ~22 ~130 ~109 oak_wood
setblock ~22 ~130 ~110 oak_leaves[persistent=true]
setblock ~22 ~130 ~113 jungle_leaves[persistent=true]
setblock ~22 ~130 ~114 jungle_leaves[persistent=true]
setblock ~22 ~130 ~115 oak_leaves[persistent=true]
setblock ~22 ~130 ~116 oak_leaves[persistent=true]
setblock ~22 ~130 ~117 oak_leaves[persistent=true]
setblock ~22 ~130 ~118 oak_leaves[persistent=true]
setblock ~22 ~130 ~119 oak_leaves[persistent=true]
setblock ~22 ~130 ~120 oak_leaves[persistent=true]
setblock ~22 ~130 ~121 jungle_leaves[persistent=true]
setblock ~22 ~130 ~122 jungle_leaves[persistent=true]
setblock ~22 ~130 ~123 jungle_leaves[persistent=true]
setblock ~22 ~130 ~124 jungle_leaves[persistent=true]
setblock ~22 ~130 ~125 oak_leaves[persistent=true]
setblock ~22 ~130 ~126 oak_leaves[persistent=true]
setblock ~22 ~131 ~94 oak_leaves[persistent=true]
setblock ~22 ~131 ~95 oak_leaves[persistent=true]
setblock ~22 ~131 ~96 oak_leaves[persistent=true]
setblock ~22 ~131 ~97 oak_leaves[persistent=true]
setblock ~22 ~131 ~98 oak_leaves[persistent=true]
setblock ~22 ~131 ~99 oak_leaves[persistent=true]
setblock ~22 ~131 ~100 oak_leaves[persistent=true]
setblock ~22 ~131 ~101 oak_leaves[persistent=true]
setblock ~22 ~131 ~102 jungle_leaves[persistent=true]
setblock ~22 ~131 ~103 jungle_leaves[persistent=true]
setblock ~22 ~131 ~105 oak_leaves[persistent=true]
setblock ~22 ~131 ~106 jungle_leaves[persistent=true]
setblock ~22 ~131 ~107 oak_leaves[persistent=true]
setblock ~22 ~131 ~108 oak_leaves[persistent=true]
setblock ~22 ~131 ~109 oak_leaves[persistent=true]
setblock ~22 ~131 ~110 oak_leaves[persistent=true]
setblock ~22 ~131 ~111 jungle_leaves[persistent=true]
setblock ~22 ~131 ~112 oak_leaves[persistent=true]
setblock ~22 ~131 ~113 oak_wood
setblock ~22 ~131 ~114 oak_leaves[persistent=true]
setblock ~22 ~131 ~115 oak_leaves[persistent=true]
setblock ~22 ~131 ~116 oak_wood
setblock ~22 ~131 ~117 jungle_leaves[persistent=true]
setblock ~22 ~131 ~118 oak_leaves[persistent=true]
setblock ~22 ~131 ~119 oak_wood
setblock ~22 ~131 ~120 oak_leaves[persistent=true]
setblock ~22 ~131 ~121 jungle_leaves[persistent=true]
setblock ~22 ~131 ~123 oak_leaves[persistent=true]
setblock ~22 ~131 ~124 oak_leaves[persistent=true]
setblock ~22 ~131 ~126 jungle_leaves[persistent=true]
setblock ~22 ~132 ~93 oak_leaves[persistent=true]
setblock ~22 ~132 ~94 oak_leaves[persistent=true]
setblock ~22 ~132 ~95 oak_leaves[persistent=true]
setblock ~22 ~132 ~96 oak_leaves[persistent=true]
setblock ~22 ~132 ~97 jungle_leaves[persistent=true]
setblock ~22 ~132 ~100 oak_leaves[persistent=true]
setblock ~22 ~132 ~101 jungle_leaves[persistent=true]
setblock ~22 ~132 ~103 oak_leaves[persistent=true]
setblock ~22 ~132 ~104 oak_wood
setblock ~22 ~132 ~107 oak_leaves[persistent=true]
setblock ~22 ~132 ~109 jungle_leaves[persistent=true]
setblock ~22 ~132 ~110 jungle_leaves[persistent=true]
setblock ~22 ~132 ~112 oak_leaves[persistent=true]
setblock ~22 ~132 ~113 oak_leaves[persistent=true]
setblock ~22 ~132 ~114 oak_wood
setblock ~22 ~132 ~115 oak_wood
setblock ~22 ~132 ~116 jungle_leaves[persistent=true]
setblock ~22 ~132 ~117 oak_leaves[persistent=true]
setblock ~22 ~132 ~118 jungle_leaves[persistent=true]
setblock ~22 ~132 ~119 oak_wood
setblock ~22 ~132 ~120 oak_leaves[persistent=true]
setblock ~22 ~132 ~121 oak_leaves[persistent=true]
setblock ~22 ~132 ~122 oak_leaves[persistent=true]
setblock ~22 ~132 ~123 oak_wood
setblock ~22 ~132 ~124 oak_leaves[persistent=true]
setblock ~22 ~132 ~125 oak_leaves[persistent=true]
setblock ~22 ~132 ~126 oak_leaves[persistent=true]
setblock ~22 ~133 ~88 jungle_leaves[persistent=true]
setblock ~22 ~133 ~89 oak_leaves[persistent=true]
setblock ~22 ~133 ~90 oak_leaves[persistent=true]
setblock ~22 ~133 ~91 oak_leaves[persistent=true]
setblock ~22 ~133 ~93 oak_leaves[persistent=true]
setblock ~22 ~133 ~94 oak_leaves[persistent=true]
setblock ~22 ~133 ~95 oak_leaves[persistent=true]
setblock ~22 ~133 ~96 oak_leaves[persistent=true]
setblock ~22 ~133 ~97 oak_leaves[persistent=true]
setblock ~22 ~133 ~98 jungle_leaves[persistent=true]
setblock ~22 ~133 ~99 oak_leaves[persistent=true]
setblock ~22 ~133 ~100 jungle_leaves[persistent=true]
setblock ~22 ~133 ~102 oak_leaves[persistent=true]
setblock ~22 ~133 ~103 oak_leaves[persistent=true]
setblock ~22 ~133 ~104 jungle_leaves[persistent=true]
setblock ~22 ~133 ~105 oak_leaves[persistent=true]
setblock ~22 ~133 ~106 oak_wood
setblock ~22 ~133 ~107 oak_leaves[persistent=true]
setblock ~22 ~133 ~108 jungle_leaves[persistent=true]
setblock ~22 ~133 ~109 oak_leaves[persistent=true]
setblock ~22 ~133 ~110 oak_wood
setblock ~22 ~133 ~111 oak_leaves[persistent=true]
setblock ~22 ~133 ~113 oak_leaves[persistent=true]
setblock ~22 ~133 ~114 jungle_leaves[persistent=true]
setblock ~22 ~133 ~115 jungle_leaves[persistent=true]
setblock ~22 ~133 ~117 oak_leaves[persistent=true]
setblock ~22 ~133 ~118 oak_leaves[persistent=true]
setblock ~22 ~133 ~119 oak_wood
setblock ~22 ~133 ~120 oak_leaves[persistent=true]
setblock ~22 ~133 ~121 oak_leaves[persistent=true]
setblock ~22 ~133 ~122 oak_leaves[persistent=true]
setblock ~22 ~133 ~123 jungle_leaves[persistent=true]
setblock ~22 ~133 ~124 oak_leaves[persistent=true]
setblock ~22 ~133 ~125 jungle_leaves[persistent=true]
setblock ~22 ~133 ~126 oak_leaves[persistent=true]
setblock ~22 ~134 ~88 oak_leaves[persistent=true]
setblock ~22 ~134 ~89 oak_leaves[persistent=true]
setblock ~22 ~134 ~90 oak_leaves[persistent=true]
setblock ~22 ~134 ~91 jungle_leaves[persistent=true]
setblock ~22 ~134 ~93 oak_leaves[persistent=true]
setblock ~22 ~134 ~94 oak_leaves[persistent=true]
setblock ~22 ~134 ~95 oak_leaves[persistent=true]
setblock ~22 ~134 ~96 jungle_leaves[persistent=true]
setblock ~22 ~134 ~97 jungle_leaves[persistent=true]
setblock ~22 ~134 ~98 oak_wood
setblock ~22 ~134 ~99 oak_leaves[persistent=true]
setblock ~22 ~134 ~100 oak_leaves[persistent=true]
setblock ~22 ~134 ~101 oak_leaves[persistent=true]
setblock ~22 ~134 ~102 oak_leaves[persistent=true]
setblock ~22 ~134 ~103 oak_wood
setblock ~22 ~134 ~104 oak_leaves[persistent=true]
setblock ~22 ~134 ~105 oak_leaves[persistent=true]
setblock ~22 ~134 ~107 oak_leaves[persistent=true]
setblock ~22 ~134 ~108 oak_leaves[persistent=true]
setblock ~22 ~134 ~109 jungle_leaves[persistent=true]
setblock ~22 ~134 ~110 oak_wood
setblock ~22 ~134 ~111 oak_wood
setblock ~22 ~134 ~112 oak_wood
setblock ~22 ~134 ~113 oak_leaves[persistent=true]
setblock ~22 ~134 ~114 jungle_leaves[persistent=true]
setblock ~22 ~134 ~115 oak_leaves[persistent=true]
setblock ~22 ~134 ~116 jungle_leaves[persistent=true]
setblock ~22 ~134 ~117 oak_wood
setblock ~22 ~134 ~118 oak_wood
setblock ~22 ~134 ~120 oak_wood
setblock ~22 ~134 ~122 jungle_leaves[persistent=true]
setblock ~22 ~134 ~123 oak_leaves[persistent=true]
setblock ~22 ~134 ~124 jungle_leaves[persistent=true]
setblock ~22 ~135 ~88 jungle_leaves[persistent=true]
setblock ~22 ~135 ~89 oak_leaves[persistent=true]
setblock ~22 ~135 ~90 oak_leaves[persistent=true]
setblock ~22 ~135 ~91 oak_leaves[persistent=true]
setblock ~22 ~135 ~92 jungle_leaves[persistent=true]
setblock ~22 ~135 ~93 oak_leaves[persistent=true]
setblock ~22 ~135 ~94 jungle_leaves[persistent=true]
setblock ~22 ~135 ~95 oak_wood
setblock ~22 ~135 ~96 oak_leaves[persistent=true]
setblock ~22 ~135 ~97 oak_leaves[persistent=true]
setblock ~22 ~135 ~98 jungle_leaves[persistent=true]
setblock ~22 ~135 ~99 oak_leaves[persistent=true]
setblock ~22 ~135 ~100 oak_leaves[persistent=true]
setblock ~22 ~135 ~101 jungle_leaves[persistent=true]
setblock ~22 ~135 ~103 oak_wood
setblock ~22 ~135 ~104 oak_leaves[persistent=true]
setblock ~22 ~135 ~105 jungle_leaves[persistent=true]
setblock ~22 ~135 ~106 oak_leaves[persistent=true]
setblock ~22 ~135 ~107 oak_leaves[persistent=true]
setblock ~22 ~135 ~108 oak_leaves[persistent=true]
setblock ~22 ~135 ~109 jungle_leaves[persistent=true]
setblock ~22 ~135 ~110 oak_wood
setblock ~22 ~135 ~111 oak_leaves[persistent=true]
setblock ~22 ~135 ~112 oak_leaves[persistent=true]
setblock ~22 ~135 ~113 oak_leaves[persistent=true]
setblock ~22 ~135 ~114 oak_leaves[persistent=true]
setblock ~22 ~135 ~115 oak_wood
setblock ~22 ~135 ~116 oak_wood
setblock ~22 ~135 ~117 oak_leaves[persistent=true]
setblock ~22 ~135 ~118 oak_leaves[persistent=true]
setblock ~22 ~135 ~119 oak_wood
setblock ~22 ~135 ~120 jungle_leaves[persistent=true]
setblock ~22 ~135 ~121 oak_leaves[persistent=true]
setblock ~22 ~135 ~122 oak_leaves[persistent=true]
setblock ~22 ~135 ~124 oak_leaves[persistent=true]
setblock ~22 ~135 ~125 oak_leaves[persistent=true]
setblock ~22 ~135 ~127 oak_leaves[persistent=true]
setblock ~22 ~135 ~128 oak_leaves[persistent=true]
setblock ~22 ~136 ~88 oak_leaves[persistent=true]
setblock ~22 ~136 ~89 oak_leaves[persistent=true]
setblock ~22 ~136 ~90 oak_leaves[persistent=true]
setblock ~22 ~136 ~91 oak_leaves[persistent=true]
setblock ~22 ~136 ~92 jungle_leaves[persistent=true]
setblock ~22 ~136 ~93 oak_leaves[persistent=true]
setblock ~22 ~136 ~95 oak_leaves[persistent=true]
setblock ~22 ~136 ~96 oak_leaves[persistent=true]
setblock ~22 ~136 ~98 oak_leaves[persistent=true]
setblock ~22 ~136 ~99 oak_leaves[persistent=true]
setblock ~22 ~136 ~100 oak_wood
setblock ~22 ~136 ~101 oak_leaves[persistent=true]
setblock ~22 ~136 ~102 oak_leaves[persistent=true]
setblock ~22 ~136 ~104 oak_leaves[persistent=true]
setblock ~22 ~136 ~106 oak_leaves[persistent=true]
setblock ~22 ~136 ~107 jungle_leaves[persistent=true]
setblock ~22 ~136 ~108 oak_leaves[persistent=true]
setblock ~22 ~136 ~109 oak_leaves[persistent=true]
setblock ~22 ~136 ~110 oak_leaves[persistent=true]
setblock ~22 ~136 ~111 oak_leaves[persistent=true]
setblock ~22 ~136 ~112 oak_leaves[persistent=true]
setblock ~22 ~136 ~113 oak_wood
setblock ~22 ~136 ~114 oak_wood
setblock ~22 ~136 ~115 oak_leaves[persistent=true]
setblock ~22 ~136 ~116 oak_leaves[persistent=true]
setblock ~22 ~136 ~117 jungle_leaves[persistent=true]
setblock ~22 ~136 ~119 oak_leaves[persistent=true]
setblock ~22 ~136 ~121 oak_leaves[persistent=true]
setblock ~22 ~136 ~122 oak_leaves[persistent=true]
setblock ~22 ~136 ~125 jungle_leaves[persistent=true]
setblock ~22 ~136 ~126 oak_leaves[persistent=true]
setblock ~22 ~136 ~127 oak_leaves[persistent=true]
setblock ~22 ~137 ~91 oak_leaves[persistent=true]
setblock ~22 ~137 ~94 oak_leaves[persistent=true]
setblock ~22 ~137 ~95 oak_leaves[persistent=true]
setblock ~22 ~137 ~96 oak_leaves[persistent=true]
setblock ~22 ~137 ~98 oak_wood
setblock ~22 ~137 ~99 oak_leaves[persistent=true]
setblock ~22 ~137 ~100 oak_leaves[persistent=true]
setblock ~22 ~137 ~101 oak_leaves[persistent=true]
setblock ~22 ~137 ~102 oak_leaves[persistent=true]
setblock ~22 ~137 ~103 oak_leaves[persistent=true]
setblock ~22 ~137 ~104 oak_leaves[persistent=true]
setblock ~22 ~137 ~106 oak_leaves[persistent=true]
setblock ~22 ~137 ~108 oak_leaves[persistent=true]
setblock ~22 ~137 ~109 oak_leaves[persistent=true]
setblock ~22 ~137 ~110 oak_leaves[persistent=true]
setblock ~22 ~137 ~111 oak_leaves[persistent=true]
setblock ~22 ~137 ~113 oak_leaves[persistent=true]
setblock ~22 ~137 ~115 oak_leaves[persistent=true]
setblock ~22 ~137 ~116 oak_leaves[persistent=true]
setblock ~22 ~137 ~117 oak_leaves[persistent=true]
setblock ~22 ~137 ~119 oak_leaves[persistent=true]
setblock ~22 ~137 ~120 oak_leaves[persistent=true]
setblock ~22 ~137 ~121 oak_leaves[persistent=true]
setblock ~22 ~137 ~122 jungle_leaves[persistent=true]
setblock ~22 ~137 ~123 oak_leaves[persistent=true]
setblock ~22 ~137 ~125 oak_leaves[persistent=true]
setblock ~22 ~137 ~126 oak_leaves[persistent=true]
setblock ~22 ~137 ~127 oak_wood
setblock ~22 ~137 ~128 oak_leaves[persistent=true]
setblock ~22 ~138 ~93 oak_leaves[persistent=true]
setblock ~22 ~138 ~94 oak_leaves[persistent=true]
setblock ~22 ~138 ~95 oak_leaves[persistent=true]
setblock ~22 ~138 ~96 oak_leaves[persistent=true]
setblock ~22 ~138 ~97 oak_leaves[persistent=true]
setblock ~22 ~138 ~98 oak_leaves[persistent=true]
setblock ~22 ~138 ~99 jungle_leaves[persistent=true]
setblock ~22 ~138 ~100 oak_leaves[persistent=true]
setblock ~22 ~138 ~106 oak_leaves[persistent=true]
setblock ~22 ~138 ~107 oak_leaves[persistent=true]
setblock ~22 ~138 ~108 oak_leaves[persistent=true]
setblock ~22 ~138 ~109 jungle_leaves[persistent=true]
setblock ~22 ~138 ~110 oak_leaves[persistent=true]
setblock ~22 ~138 ~111 oak_leaves[persistent=true]
setblock ~22 ~138 ~112 oak_leaves[persistent=true]
setblock ~22 ~138 ~113 oak_leaves[persistent=true]
setblock ~22 ~138 ~114 oak_leaves[persistent=true]
setblock ~22 ~138 ~115 jungle_leaves[persistent=true]
setblock ~22 ~138 ~117 oak_leaves[persistent=true]
setblock ~22 ~138 ~118 oak_leaves[persistent=true]
setblock ~22 ~138 ~119 oak_leaves[persistent=true]
setblock ~22 ~138 ~120 oak_leaves[persistent=true]
setblock ~22 ~138 ~121 oak_leaves[persistent=true]
setblock ~22 ~138 ~122 oak_leaves[persistent=true]
setblock ~22 ~138 ~123 jungle_leaves[persistent=true]
setblock ~22 ~138 ~125 oak_leaves[persistent=true]
setblock ~22 ~138 ~126 oak_leaves[persistent=true]
setblock ~22 ~138 ~127 oak_leaves[persistent=true]
setblock ~22 ~138 ~128 oak_leaves[persistent=true]
setblock ~22 ~139 ~91 oak_leaves[persistent=true]
setblock ~22 ~139 ~92 oak_leaves[persistent=true]
setblock ~22 ~139 ~94 oak_leaves[persistent=true]
setblock ~22 ~139 ~95 jungle_leaves[persistent=true]
setblock ~22 ~139 ~96 oak_leaves[persistent=true]
setblock ~22 ~139 ~98 oak_leaves[persistent=true]
setblock ~22 ~139 ~99 oak_leaves[persistent=true]
setblock ~22 ~139 ~100 jungle_leaves[persistent=true]
setblock ~22 ~139 ~109 oak_leaves[persistent=true]
setblock ~22 ~139 ~110 oak_leaves[persistent=true]
setblock ~22 ~139 ~111 oak_leaves[persistent=true]
setblock ~22 ~139 ~112 oak_leaves[persistent=true]
setblock ~22 ~139 ~113 oak_leaves[persistent=true]
setblock ~22 ~139 ~114 oak_leaves[persistent=true]
setblock ~22 ~139 ~115 oak_leaves[persistent=true]
setblock ~22 ~139 ~116 oak_leaves[persistent=true]
setblock ~22 ~139 ~117 oak_leaves[persistent=true]
setblock ~22 ~139 ~118 jungle_leaves[persistent=true]
setblock ~22 ~139 ~119 jungle_leaves[persistent=true]
setblock ~22 ~139 ~120 oak_leaves[persistent=true]
setblock ~22 ~139 ~122 oak_leaves[persistent=true]
setblock ~22 ~139 ~123 oak_leaves[persistent=true]
setblock ~22 ~140 ~91 oak_leaves[persistent=true]
setblock ~22 ~140 ~92 oak_leaves[persistent=true]
setblock ~22 ~140 ~93 oak_leaves[persistent=true]
setblock ~22 ~140 ~109 oak_leaves[persistent=true]
setblock ~22 ~140 ~110 oak_leaves[persistent=true]
setblock ~22 ~140 ~111 oak_leaves[persistent=true]
setblock ~22 ~140 ~112 oak_leaves[persistent=true]
setblock ~22 ~140 ~113 oak_leaves[persistent=true]
setblock ~23 ~126 ~107 oak_leaves[persistent=true]
setblock ~23 ~126 ~109 oak_leaves[persistent=true]
setblock ~23 ~126 ~110 oak_leaves[persistent=true]
setblock ~23 ~127 ~98 jungle_leaves[persistent=true]
setblock ~23 ~127 ~99 oak_leaves[persistent=true]
setblock ~23 ~127 ~100 oak_leaves[persistent=true]
setblock ~23 ~127 ~102 oak_leaves[persistent=true]
setblock ~23 ~127 ~107 oak_leaves[persistent=true]
setblock ~23 ~127 ~108 oak_leaves[persistent=true]
setblock ~23 ~127 ~109 jungle_leaves[persistent=true]
setblock ~23 ~127 ~110 oak_leaves[persistent=true]
setblock ~23 ~127 ~111 jungle_leaves[persistent=true]
setblock ~23 ~127 ~131 oak_leaves[persistent=true]
setblock ~23 ~127 ~132 jungle_leaves[persistent=true]
setblock ~23 ~127 ~133 oak_leaves[persistent=true]
setblock ~23 ~127 ~134 jungle_leaves[persistent=true]
setblock ~23 ~128 ~98 oak_leaves[persistent=true]
setblock ~23 ~128 ~99 jungle_leaves[persistent=true]
setblock ~23 ~128 ~100 oak_leaves[persistent=true]
setblock ~23 ~128 ~101 jungle_leaves[persistent=true]
setblock ~23 ~128 ~102 jungle_leaves[persistent=true]
setblock ~23 ~128 ~103 oak_leaves[persistent=true]
setblock ~23 ~128 ~105 oak_leaves[persistent=true]
setblock ~23 ~128 ~106 oak_leaves[persistent=true]
setblock ~23 ~128 ~107 oak_leaves[persistent=true]
setblock ~23 ~128 ~108 oak_leaves[persistent=true]
setblock ~23 ~128 ~109 oak_leaves[persistent=true]
setblock ~23 ~128 ~110 oak_leaves[persistent=true]
setblock ~23 ~128 ~111 oak_leaves[persistent=true]
setblock ~23 ~128 ~112 oak_leaves[persistent=true]
setblock ~23 ~128 ~113 oak_leaves[persistent=true]
setblock ~23 ~128 ~116 oak_leaves[persistent=true]
setblock ~23 ~128 ~117 oak_leaves[persistent=true]
setblock ~23 ~128 ~119 oak_leaves[persistent=true]
setblock ~23 ~128 ~131 oak_leaves[persistent=true]
setblock ~23 ~128 ~132 oak_leaves[persistent=true]
setblock ~23 ~128 ~134 oak_leaves[persistent=true]
setblock ~23 ~129 ~95 oak_leaves[persistent=true]
setblock ~23 ~129 ~96 jungle_leaves[persistent=true]
setblock ~23 ~129 ~97 oak_leaves[persistent=true]
setblock ~23 ~129 ~98 jungle_leaves[persistent=true]
setblock ~23 ~129 ~99 oak_leaves[persistent=true]
setblock ~23 ~129 ~100 oak_leaves[persistent=true]
setblock ~23 ~129 ~101 oak_leaves[persistent=true]
setblock ~23 ~129 ~102 oak_leaves[persistent=true]
setblock ~23 ~129 ~103 jungle_leaves[persistent=true]
setblock ~23 ~129 ~104 oak_leaves[persistent=true]
setblock ~23 ~129 ~105 oak_leaves[persistent=true]
setblock ~23 ~129 ~106 oak_leaves[persistent=true]
setblock ~23 ~129 ~108 jungle_leaves[persistent=true]
setblock ~23 ~129 ~109 oak_leaves[persistent=true]
setblock ~23 ~129 ~110 oak_leaves[persistent=true]
setblock ~23 ~129 ~111 oak_leaves[persistent=true]
setblock ~23 ~129 ~112 jungle_leaves[persistent=true]
setblock ~23 ~129 ~113 oak_leaves[persistent=true]
setblock ~23 ~129 ~114 jungle_leaves[persistent=true]
setblock ~23 ~129 ~115 oak_leaves[persistent=true]
setblock ~23 ~129 ~116 oak_leaves[persistent=true]
setblock ~23 ~129 ~117 oak_leaves[persistent=true]
setblock ~23 ~129 ~118 jungle_leaves[persistent=true]
setblock ~23 ~129 ~119 oak_leaves[persistent=true]
setblock ~23 ~129 ~121 oak_leaves[persistent=true]
setblock ~23 ~129 ~122 oak_leaves[persistent=true]
setblock ~23 ~129 ~123 oak_leaves[persistent=true]
setblock ~23 ~129 ~125 oak_leaves[persistent=true]
setblock ~23 ~129 ~126 oak_leaves[persistent=true]
setblock ~23 ~129 ~128 oak_leaves[persistent=true]
setblock ~23 ~129 ~131 oak_leaves[persistent=true]
setblock ~23 ~129 ~132 jungle_leaves[persistent=true]
setblock ~23 ~129 ~133 jungle_leaves[persistent=true]
setblock ~23 ~129 ~134 oak_leaves[persistent=true]
setblock ~23 ~130 ~95 jungle_leaves[persistent=true]
setblock ~23 ~130 ~96 oak_leaves[persistent=true]
setblock ~23 ~130 ~99 oak_leaves[persistent=true]
setblock ~23 ~130 ~100 jungle_leaves[persistent=true]
setblock ~23 ~130 ~101 oak_leaves[persistent=true]
setblock ~23 ~130 ~102 jungle_leaves[persistent=true]
setblock ~23 ~130 ~103 oak_leaves[persistent=true]
setblock ~23 ~130 ~105 oak_leaves[persistent=true]
setblock ~23 ~130 ~106 oak_leaves[persistent=true]
setblock ~23 ~130 ~107 oak_leaves[persistent=true]
setblock ~23 ~130 ~108 jungle_leaves[persistent=true]
setblock ~23 ~130 ~109 oak_leaves[persistent=true]
setblock ~23 ~130 ~110 oak_wood
setblock ~23 ~130 ~112 oak_leaves[persistent=true]
setblock ~23 ~130 ~113 oak_leaves[persistent=true]
setblock ~23 ~130 ~115 jungle_leaves[persistent=true]
setblock ~23 ~130 ~116 oak_leaves[persistent=true]
setblock ~23 ~130 ~117 oak_leaves[persistent=true]
setblock ~23 ~130 ~118 oak_wood
setblock ~23 ~130 ~120 jungle_leaves[persistent=true]
setblock ~23 ~130 ~121 oak_leaves[persistent=true]
setblock ~23 ~130 ~122 oak_leaves[persistent=true]
setblock ~23 ~130 ~123 oak_leaves[persistent=true]
setblock ~23 ~130 ~124 jungle_leaves[persistent=true]
setblock ~23 ~130 ~125 oak_leaves[persistent=true]
setblock ~23 ~130 ~126 oak_leaves[persistent=true]
setblock ~23 ~130 ~127 oak_leaves[persistent=true]
setblock ~23 ~130 ~128 oak_leaves[persistent=true]
setblock ~23 ~130 ~129 oak_leaves[persistent=true]
setblock ~23 ~130 ~131 oak_leaves[persistent=true]
setblock ~23 ~130 ~132 oak_leaves[persistent=true]
setblock ~23 ~130 ~133 jungle_leaves[persistent=true]
setblock ~23 ~130 ~134 oak_leaves[persistent=true]
setblock ~23 ~131 ~93 oak_leaves[persistent=true]
setblock ~23 ~131 ~94 jungle_leaves[persistent=true]
setblock ~23 ~131 ~95 oak_leaves[persistent=true]
setblock ~23 ~131 ~96 oak_leaves[persistent=true]
setblock ~23 ~131 ~97 oak_leaves[persistent=true]
setblock ~23 ~131 ~98 jungle_leaves[persistent=true]
setblock ~23 ~131 ~99 jungle_leaves[persistent=true]
setblock ~23 ~131 ~101 oak_leaves[persistent=true]
setblock ~23 ~131 ~102 jungle_leaves[persistent=true]
setblock ~23 ~131 ~103 oak_leaves[persistent=true]
setblock ~23 ~131 ~104 oak_leaves[persistent=true]
setblock ~23 ~131 ~105 oak_leaves[persistent=true]
setblock ~23 ~131 ~106 jungle_leaves[persistent=true]
setblock ~23 ~131 ~107 oak_leaves[persistent=true]
setblock ~23 ~131 ~108 jungle_leaves[persistent=true]
setblock ~23 ~131 ~110 oak_leaves[persistent=true]
setblock ~23 ~131 ~111 oak_leaves[persistent=true]
setblock ~23 ~131 ~112 oak_leaves[persistent=true]
setblock ~23 ~131 ~113 oak_wood
setblock ~23 ~131 ~114 oak_leaves[persistent=true]
setblock ~23 ~131 ~115 oak_wood
setblock ~23 ~131 ~116 oak_wood
setblock ~23 ~131 ~117 oak_leaves[persistent=true]
setblock ~23 ~131 ~118 oak_leaves[persistent=true]
setblock ~23 ~131 ~120 oak_leaves[persistent=true]
setblock ~23 ~131 ~121 oak_leaves[persistent=true]
setblock ~23 ~131 ~122 oak_wood
setblock ~23 ~131 ~123 jungle_leaves[persistent=true]
setblock ~23 ~131 ~124 oak_leaves[persistent=true]
setblock ~23 ~131 ~125 oak_leaves[persistent=true]
setblock ~23 ~131 ~126 oak_leaves[persistent=true]
setblock ~23 ~131 ~127 oak_leaves[persistent=true]
setblock ~23 ~131 ~129 oak_leaves[persistent=true]
setblock ~23 ~132 ~93 jungle_leaves[persistent=true]
setblock ~23 ~132 ~94 oak_leaves[persistent=true]
setblock ~23 ~132 ~95 oak_leaves[persistent=true]
setblock ~23 ~132 ~96 jungle_leaves[persistent=true]
setblock ~23 ~132 ~97 jungle_leaves[persistent=true]
setblock ~23 ~132 ~98 oak_leaves[persistent=true]
setblock ~23 ~132 ~99 jungle_leaves[persistent=true]
setblock ~23 ~132 ~100 jungle_leaves[persistent=true]
setblock ~23 ~132 ~101 oak_leaves[persistent=true]
setblock ~23 ~132 ~102 oak_leaves[persistent=true]
setblock ~23 ~132 ~103 oak_leaves[persistent=true]
setblock ~23 ~132 ~104 oak_wood
setblock ~23 ~132 ~105 oak_leaves[persistent=true]
setblock ~23 ~132 ~106 oak_leaves[persistent=true]
setblock ~23 ~132 ~107 oak_leaves[persistent=true]
setblock ~23 ~132 ~108 oak_wood
setblock ~23 ~132 ~109 oak_leaves[persistent=true]
setblock ~23 ~132 ~110 oak_leaves[persistent=true]
setblock ~23 ~132 ~112 jungle_leaves[persistent=true]
setblock ~23 ~132 ~113 oak_leaves[persistent=true]
setblock ~23 ~132 ~114 oak_wood
setblock ~23 ~132 ~115 oak_wood
setblock ~23 ~132 ~116 oak_leaves[persistent=true]
setblock ~23 ~132 ~117 oak_leaves[persistent=true]
setblock ~23 ~132 ~119 oak_wood
setblock ~23 ~132 ~120 oak_leaves[persistent=true]
setblock ~23 ~132 ~121 oak_leaves[persistent=true]
setblock ~23 ~132 ~122 oak_wood
setblock ~23 ~132 ~123 oak_wood
setblock ~23 ~132 ~124 oak_leaves[persistent=true]
setblock ~23 ~132 ~126 oak_leaves[persistent=true]
setblock ~23 ~132 ~127 oak_leaves[persistent=true]
setblock ~23 ~132 ~128 oak_leaves[persistent=true]
setblock ~23 ~132 ~129 oak_leaves[persistent=true]
setblock ~23 ~133 ~88 oak_leaves[persistent=true]
setblock ~23 ~133 ~89 oak_leaves[persistent=true]
setblock ~23 ~133 ~90 oak_leaves[persistent=true]
setblock ~23 ~133 ~91 oak_leaves[persistent=true]
setblock ~23 ~133 ~92 jungle_leaves[persistent=true]
setblock ~23 ~133 ~93 jungle_leaves[persistent=true]
setblock ~23 ~133 ~94 jungle_leaves[persistent=true]
setblock ~23 ~133 ~96 oak_leaves[persistent=true]
setblock ~23 ~133 ~98 oak_leaves[persistent=true]
setblock ~23 ~133 ~100 oak_leaves[persistent=true]
setblock ~23 ~133 ~101 oak_leaves[persistent=true]
setblock ~23 ~133 ~103 oak_leaves[persistent=true]
setblock ~23 ~133 ~104 jungle_leaves[persistent=true]
setblock ~23 ~133 ~105 oak_leaves[persistent=true]
setblock ~23 ~133 ~106 oak_leaves[persistent=true]
setblock ~23 ~133 ~107 oak_wood
setblock ~23 ~133 ~108 oak_leaves[persistent=true]
setblock ~23 ~133 ~109 oak_leaves[persistent=true]
setblock ~23 ~133 ~110 oak_wood
setblock ~23 ~133 ~111 oak_wood
setblock ~23 ~133 ~113 jungle_leaves[persistent=true]
setblock ~23 ~133 ~114 oak_wood
setblock ~23 ~133 ~115 oak_leaves[persistent=true]
setblock ~23 ~133 ~116 oak_leaves[persistent=true]
setblock ~23 ~133 ~117 jungle_leaves[persistent=true]
setblock ~23 ~133 ~118 oak_leaves[persistent=true]
setblock ~23 ~133 ~119 oak_wood
setblock ~23 ~133 ~120 oak_wood
setblock ~23 ~133 ~121 oak_leaves[persistent=true]
setblock ~23 ~133 ~122 oak_leaves[persistent=true]
setblock ~23 ~133 ~123 oak_leaves[persistent=true]
setblock ~23 ~133 ~124 jungle_leaves[persistent=true]
setblock ~23 ~133 ~125 oak_leaves[persistent=true]
setblock ~23 ~133 ~126 oak_leaves[persistent=true]
setblock ~23 ~133 ~127 oak_leaves[persistent=true]
setblock ~23 ~134 ~88 oak_leaves[persistent=true]
setblock ~23 ~134 ~89 oak_leaves[persistent=true]
setblock ~23 ~134 ~90 oak_leaves[persistent=true]
setblock ~23 ~134 ~91 oak_leaves[persistent=true]
setblock ~23 ~134 ~92 oak_leaves[persistent=true]
setblock ~23 ~134 ~93 oak_leaves[persistent=true]
setblock ~23 ~134 ~94 oak_leaves[persistent=true]
setblock ~23 ~134 ~95 jungle_leaves[persistent=true]
setblock ~23 ~134 ~96 oak_leaves[persistent=true]
setblock ~23 ~134 ~97 oak_leaves[persistent=true]
setblock ~23 ~134 ~98 oak_wood
setblock ~23 ~134 ~99 oak_leaves[persistent=true]
setblock ~23 ~134 ~100 oak_leaves[persistent=true]
setblock ~23 ~134 ~101 oak_leaves[persistent=true]
setblock ~23 ~134 ~102 jungle_leaves[persistent=true]
setblock ~23 ~134 ~103 oak_wood
setblock ~23 ~134 ~104 oak_leaves[persistent=true]
setblock ~23 ~134 ~105 oak_wood
setblock ~23 ~134 ~106 oak_leaves[persistent=true]
setblock ~23 ~134 ~107 oak_leaves[persistent=true]
setblock ~23 ~134 ~108 oak_wood
setblock ~23 ~134 ~109 jungle_leaves[persistent=true]
setblock ~23 ~134 ~110 oak_wood
setblock ~23 ~134 ~111 oak_wood
setblock ~23 ~134 ~112 oak_leaves[persistent=true]
setblock ~23 ~134 ~113 oak_wood
setblock ~23 ~134 ~114 oak_wood
setblock ~23 ~134 ~115 oak_wood
setblock ~23 ~134 ~116 jungle_leaves[persistent=true]
setblock ~23 ~134 ~117 oak_wood
setblock ~23 ~134 ~118 jungle_leaves[persistent=true]
setblock ~23 ~134 ~119 oak_wood
setblock ~23 ~134 ~120 oak_leaves[persistent=true]
setblock ~23 ~134 ~121 oak_leaves[persistent=true]
setblock ~23 ~134 ~122 jungle_leaves[persistent=true]
setblock ~23 ~134 ~123 oak_leaves[persistent=true]
setblock ~23 ~134 ~124 oak_leaves[persistent=true]
setblock ~23 ~134 ~125 oak_leaves[persistent=true]
setblock ~23 ~134 ~126 oak_leaves[persistent=true]
setblock ~23 ~134 ~127 oak_leaves[persistent=true]
setblock ~23 ~135 ~88 oak_leaves[persistent=true]
setblock ~23 ~135 ~89 oak_leaves[persistent=true]
setblock ~23 ~135 ~90 jungle_leaves[persistent=true]
setblock ~23 ~135 ~92 jungle_leaves[persistent=true]
setblock ~23 ~135 ~93 oak_leaves[persistent=true]
setblock ~23 ~135 ~94 jungle_leaves[persistent=true]
setblock ~23 ~135 ~95 jungle_leaves[persistent=true]
setblock ~23 ~135 ~96 oak_wood
setblock ~23 ~135 ~97 jungle_leaves[persistent=true]
setblock ~23 ~135 ~98 oak_wood
setblock ~23 ~135 ~99 oak_wood
setblock ~23 ~135 ~100 jungle_leaves[persistent=true]
setblock ~23 ~135 ~101 oak_leaves[persistent=true]
setblock ~23 ~135 ~102 jungle_leaves[persistent=true]
setblock ~23 ~135 ~103 oak_wood
setblock ~23 ~135 ~104 oak_leaves[persistent=true]
setblock ~23 ~135 ~105 oak_leaves[persistent=true]
setblock ~23 ~135 ~106 oak_leaves[persistent=true]
setblock ~23 ~135 ~107 oak_leaves[persistent=true]
setblock ~23 ~135 ~108 oak_leaves[persistent=true]
setblock ~23 ~135 ~109 oak_wood
setblock ~23 ~135 ~110 oak_wood
setblock ~23 ~135 ~111 oak_wood
setblock ~23 ~135 ~112 oak_leaves[persistent=true]
setblock ~23 ~135 ~113 oak_wood
setblock ~23 ~135 ~115 oak_wood
setblock ~23 ~135 ~116 oak_leaves[persistent=true]
setblock ~23 ~135 ~117 oak_leaves[persistent=true]
setblock ~23 ~135 ~118 oak_wood
setblock ~23 ~135 ~119 oak_wood
setblock ~23 ~135 ~120 oak_wood
setblock ~23 ~135 ~121 oak_leaves[persistent=true]
setblock ~23 ~135 ~122 oak_leaves[persistent=true]
setblock ~23 ~135 ~123 oak_leaves[persistent=true]
setblock ~23 ~135 ~124 oak_leaves[persistent=true]
setblock ~23 ~135 ~125 jungle_leaves[persistent=true]
setblock ~23 ~135 ~126 oak_leaves[persistent=true]
setblock ~23 ~135 ~127 oak_leaves[persistent=true]
setblock ~23 ~135 ~128 oak_leaves[persistent=true]
setblock ~23 ~136 ~88 oak_leaves[persistent=true]
setblock ~23 ~136 ~89 oak_leaves[persistent=true]
setblock ~23 ~136 ~90 jungle_leaves[persistent=true]
setblock ~23 ~136 ~91 jungle_leaves[persistent=true]
setblock ~23 ~136 ~92 oak_leaves[persistent=true]
setblock ~23 ~136 ~93 oak_leaves[persistent=true]
setblock ~23 ~136 ~94 jungle_leaves[persistent=true]
setblock ~23 ~136 ~95 oak_leaves[persistent=true]
setblock ~23 ~136 ~96 oak_leaves[persistent=true]
setblock ~23 ~136 ~97 oak_leaves[persistent=true]
setblock ~23 ~136 ~98 oak_wood
setblock ~23 ~136 ~100 oak_leaves[persistent=true]
setblock ~23 ~136 ~101 oak_wood
setblock ~23 ~136 ~102 oak_leaves[persistent=true]
setblock ~23 ~136 ~103 oak_leaves[persistent=true]
setblock ~23 ~136 ~104 jungle_leaves[persistent=true]
setblock ~23 ~136 ~105 oak_leaves[persistent=true]
setblock ~23 ~136 ~106 oak_leaves[persistent=true]
setblock ~23 ~136 ~107 oak_leaves[persistent=true]
setblock ~23 ~136 ~108 oak_leaves[persistent=true]
setblock ~23 ~136 ~110 oak_leaves[persistent=true]
setblock ~23 ~136 ~111 jungle_leaves[persistent=true]
setblock ~23 ~136 ~112 oak_leaves[persistent=true]
setblock ~23 ~136 ~113 oak_wood
setblock ~23 ~136 ~114 oak_wood
setblock ~23 ~136 ~115 oak_leaves[persistent=true]
setblock ~23 ~136 ~116 oak_leaves[persistent=true]
setblock ~23 ~136 ~117 oak_leaves[persistent=true]
setblock ~23 ~136 ~118 oak_log
setblock ~23 ~136 ~119 oak_leaves[persistent=true]
setblock ~23 ~136 ~120 oak_leaves[persistent=true]
setblock ~23 ~136 ~121 jungle_leaves[persistent=true]
setblock ~23 ~136 ~122 oak_leaves[persistent=true]
setblock ~23 ~136 ~123 jungle_leaves[persistent=true]
setblock ~23 ~136 ~124 oak_leaves[persistent=true]
setblock ~23 ~136 ~125 oak_leaves[persistent=true]
setblock ~23 ~136 ~126 oak_wood
setblock ~23 ~136 ~127 oak_wood
setblock ~23 ~136 ~128 oak_leaves[persistent=true]
setblock ~23 ~137 ~89 oak_leaves[persistent=true]
setblock ~23 ~137 ~90 oak_leaves[persistent=true]
setblock ~23 ~137 ~91 oak_leaves[persistent=true]
setblock ~23 ~137 ~92 oak_leaves[persistent=true]
setblock ~23 ~137 ~93 oak_leaves[persistent=true]
setblock ~23 ~137 ~94 oak_wood
setblock ~23 ~137 ~95 oak_leaves[persistent=true]
setblock ~23 ~137 ~96 jungle_leaves[persistent=true]
setblock ~23 ~137 ~97 oak_leaves[persistent=true]
setblock ~23 ~137 ~98 oak_wood
setblock ~23 ~137 ~99 oak_leaves[persistent=true]
setblock ~23 ~137 ~100 oak_leaves[persistent=true]
setblock ~23 ~137 ~101 oak_leaves[persistent=true]
setblock ~23 ~137 ~102 oak_leaves[persistent=true]
setblock ~23 ~137 ~103 oak_leaves[persistent=true]
setblock ~23 ~137 ~104 oak_leaves[persistent=true]
setblock ~23 ~137 ~106 oak_leaves[persistent=true]
setblock ~23 ~137 ~107 oak_leaves[persistent=true]
setblock ~23 ~137 ~108 oak_wood
setblock ~23 ~137 ~109 oak_leaves[persistent=true]
setblock ~23 ~137 ~110 oak_leaves[persistent=true]
setblock ~23 ~137 ~111 oak_leaves[persistent=true]
setblock ~23 ~137 ~112 oak_leaves[persistent=true]
setblock ~23 ~137 ~114 oak_leaves[persistent=true]
setblock ~23 ~137 ~115 jungle_leaves[persistent=true]
setblock ~23 ~137 ~117 oak_leaves[persistent=true]
setblock ~23 ~137 ~118 oak_log
setblock ~23 ~137 ~119 oak_wood
setblock ~23 ~137 ~120 oak_leaves[persistent=true]
setblock ~23 ~137 ~121 oak_leaves[persistent=true]
setblock ~23 ~137 ~122 jungle_leaves[persistent=true]
setblock ~23 ~137 ~123 jungle_leaves[persistent=true]
setblock ~23 ~137 ~124 oak_leaves[persistent=true]
setblock ~23 ~137 ~125 oak_leaves[persistent=true]
setblock ~23 ~137 ~127 jungle_leaves[persistent=true]
setblock ~23 ~138 ~91 oak_leaves[persistent=true]
setblock ~23 ~138 ~92 oak_wood
setblock ~23 ~138 ~93 oak_leaves[persistent=true]
setblock ~23 ~138 ~94 oak_leaves[persistent=true]
setblock ~23 ~138 ~95 oak_leaves[persistent=true]
setblock ~23 ~138 ~97 oak_leaves[persistent=true]
setblock ~23 ~138 ~98 oak_leaves[persistent=true]
setblock ~23 ~138 ~99 oak_leaves[persistent=true]
setblock ~23 ~138 ~100 oak_leaves[persistent=true]
setblock ~23 ~138 ~101 oak_leaves[persistent=true]
setblock ~23 ~138 ~102 oak_leaves[persistent=true]
setblock ~23 ~138 ~103 oak_leaves[persistent=true]
setblock ~23 ~138 ~106 oak_leaves[persistent=true]
setblock ~23 ~138 ~107 oak_leaves[persistent=true]
setblock ~23 ~138 ~109 oak_leaves[persistent=true]
setblock ~23 ~138 ~110 oak_leaves[persistent=true]
setblock ~23 ~138 ~111 oak_wood
setblock ~23 ~138 ~112 oak_leaves[persistent=true]
setblock ~23 ~138 ~113 oak_leaves[persistent=true]
setblock ~23 ~138 ~114 oak_leaves[persistent=true]
setblock ~23 ~138 ~115 jungle_leaves[persistent=true]
setblock ~23 ~138 ~116 oak_leaves[persistent=true]
setblock ~23 ~138 ~117 jungle_leaves[persistent=true]
setblock ~23 ~138 ~118 oak_leaves[persistent=true]
setblock ~23 ~138 ~119 oak_leaves[persistent=true]
setblock ~23 ~138 ~120 oak_leaves[persistent=true]
setblock ~23 ~138 ~122 oak_wood
setblock ~23 ~138 ~123 jungle_leaves[persistent=true]
setblock ~23 ~138 ~124 oak_leaves[persistent=true]
setblock ~23 ~138 ~125 oak_leaves[persistent=true]
setblock ~23 ~138 ~126 jungle_leaves[persistent=true]
setblock ~23 ~138 ~128 oak_leaves[persistent=true]
setblock ~23 ~139 ~92 oak_leaves[persistent=true]
setblock ~23 ~139 ~93 oak_leaves[persistent=true]
setblock ~23 ~139 ~94 oak_leaves[persistent=true]
setblock ~23 ~139 ~95 oak_leaves[persistent=true]
setblock ~23 ~139 ~96 oak_leaves[persistent=true]
setblock ~23 ~139 ~101 oak_leaves[persistent=true]
setblock ~23 ~139 ~102 oak_leaves[persistent=true]
setblock ~23 ~139 ~103 oak_leaves[persistent=true]
setblock ~23 ~139 ~108 jungle_leaves[persistent=true]
setblock ~23 ~139 ~109 oak_leaves[persistent=true]
setblock ~23 ~139 ~110 oak_leaves[persistent=true]
setblock ~23 ~139 ~111 oak_wood
setblock ~23 ~139 ~113 oak_leaves[persistent=true]
setblock ~23 ~139 ~114 oak_leaves[persistent=true]
setblock ~23 ~139 ~115 oak_leaves[persistent=true]
setblock ~23 ~139 ~116 oak_leaves[persistent=true]
setblock ~23 ~139 ~117 oak_leaves[persistent=true]
setblock ~23 ~139 ~118 oak_leaves[persistent=true]
setblock ~23 ~139 ~119 jungle_leaves[persistent=true]
setblock ~23 ~139 ~120 jungle_leaves[persistent=true]
setblock ~23 ~139 ~121 oak_leaves[persistent=true]
setblock ~23 ~139 ~122 jungle_leaves[persistent=true]
setblock ~23 ~140 ~91 oak_leaves[persistent=true]
setblock ~23 ~140 ~92 oak_leaves[persistent=true]
setblock ~23 ~140 ~109 oak_leaves[persistent=true]
setblock ~23 ~140 ~110 oak_leaves[persistent=true]
setblock ~23 ~140 ~111 jungle_leaves[persistent=true]
setblock ~23 ~140 ~112 oak_leaves[persistent=true]
setblock ~23 ~140 ~113 oak_leaves[persistent=true]
setblock ~23 ~140 ~115 oak_leaves[persistent=true]
setblock ~23 ~140 ~116 oak_leaves[persistent=true]
setblock ~23 ~140 ~117 jungle_leaves[persistent=true]
setblock ~23 ~140 ~119 oak_leaves[persistent=true]
setblock ~24 ~126 ~107 oak_leaves[persistent=true]
setblock ~24 ~126 ~108 oak_leaves[persistent=true]
setblock ~24 ~126 ~109 jungle_leaves[persistent=true]
setblock ~24 ~126 ~110 oak_leaves[persistent=true]
setblock ~24 ~126 ~116 oak_leaves[persistent=true]
setblock ~24 ~126 ~118 oak_leaves[persistent=true]
setblock ~24 ~126 ~119 jungle_leaves[persistent=true]
setblock ~24 ~126 ~120 oak_leaves[persistent=true]
setblock ~24 ~126 ~121 oak_leaves[persistent=true]
setblock ~24 ~126 ~122 oak_leaves[persistent=true]
setblock ~24 ~126 ~124 oak_leaves[persistent=true]
setblock ~24 ~126 ~132 oak_leaves[persistent=true]
setblock ~24 ~126 ~133 jungle_leaves[persistent=true]
setblock ~24 ~126 ~135 oak_leaves[persistent=true]
setblock ~24 ~127 ~96 oak_leaves[persistent=true]
setblock ~24 ~127 ~97 oak_leaves[persistent=true]
setblock ~24 ~127 ~98 oak_leaves[persistent=true]
setblock ~24 ~127 ~99 jungle_leaves[persistent=true]
setblock ~24 ~127 ~100 oak_leaves[persistent=true]
setblock ~24 ~127 ~101 oak_leaves[persistent=true]
setblock ~24 ~127 ~102 oak_leaves[persistent=true]
setblock ~24 ~127 ~107 oak_leaves[persistent=true]
setblock ~24 ~127 ~108 oak_leaves[persistent=true]
setblock ~24 ~127 ~109 jungle_leaves[persistent=true]
setblock ~24 ~127 ~110 oak_leaves[persistent=true]
setblock ~24 ~127 ~111 oak_leaves[persistent=true]
setblock ~24 ~127 ~116 oak_leaves[persistent=true]
setblock ~24 ~127 ~117 oak_leaves[persistent=true]
setblock ~24 ~127 ~118 jungle_leaves[persistent=true]
setblock ~24 ~127 ~119 jungle_leaves[persistent=true]
setblock ~24 ~127 ~120 oak_leaves[persistent=true]
setblock ~24 ~127 ~121 oak_leaves[persistent=true]
setblock ~24 ~127 ~122 oak_leaves[persistent=true]
setblock ~24 ~127 ~123 oak_leaves[persistent=true]
setblock ~24 ~127 ~124 oak_leaves[persistent=true]
setblock ~24 ~127 ~130 oak_leaves[persistent=true]
setblock ~24 ~127 ~131 jungle_leaves[persistent=true]
setblock ~24 ~127 ~132 oak_leaves[persistent=true]
setblock ~24 ~127 ~133 oak_leaves[persistent=true]
setblock ~24 ~127 ~134 oak_leaves[persistent=true]
setblock ~24 ~127 ~135 jungle_leaves[persistent=true]
setblock ~24 ~128 ~83 jungle_leaves[persistent=true]
setblock ~24 ~128 ~84 oak_leaves[persistent=true]
setblock ~24 ~128 ~85 oak_leaves[persistent=true]
setblock ~24 ~128 ~86 oak_leaves[persistent=true]
setblock ~24 ~128 ~96 oak_leaves[persistent=true]
setblock ~24 ~128 ~97 oak_leaves[persistent=true]
setblock ~24 ~128 ~98 oak_leaves[persistent=true]
setblock ~24 ~128 ~99 oak_leaves[persistent=true]
setblock ~24 ~128 ~100 oak_leaves[persistent=true]
setblock ~24 ~128 ~101 oak_leaves[persistent=true]
setblock ~24 ~128 ~102 jungle_leaves[persistent=true]
setblock ~24 ~128 ~103 oak_leaves[persistent=true]
setblock ~24 ~128 ~104 jungle_leaves[persistent=true]
setblock ~24 ~128 ~105 jungle_leaves[persistent=true]
setblock ~24 ~128 ~106 oak_leaves[persistent=true]
setblock ~24 ~128 ~107 oak_leaves[persistent=true]
setblock ~24 ~128 ~108 jungle_leaves[persistent=true]
setblock ~24 ~128 ~109 oak_wood
setblock ~24 ~128 ~110 oak_leaves[persistent=true]
setblock ~24 ~128 ~111 oak_leaves[persistent=true]
setblock ~24 ~128 ~112 oak_leaves[persistent=true]
setblock ~24 ~128 ~113 jungle_leaves[persistent=true]
setblock ~24 ~128 ~114 oak_leaves[persistent=true]
setblock ~24 ~128 ~116 oak_leaves[persistent=true]
setblock ~24 ~128 ~118 oak_leaves[persistent=true]
setblock ~24 ~128 ~119 oak_leaves[persistent=true]
setblock ~24 ~128 ~120 oak_leaves[persistent=true]
setblock ~24 ~128 ~121 oak_leaves[persistent=true]
setblock ~24 ~128 ~130 jungle_leaves[persistent=true]
setblock ~24 ~128 ~131 jungle_leaves[persistent=true]
setblock ~24 ~128 ~132 jungle_leaves[persistent=true]
setblock ~24 ~128 ~133 jungle_leaves[persistent=true]
setblock ~24 ~128 ~134 jungle_leaves[persistent=true]
setblock ~24 ~128 ~135 jungle_leaves[persistent=true]
setblock ~24 ~129 ~84 oak_leaves[persistent=true]
setblock ~24 ~129 ~85 oak_leaves[persistent=true]
setblock ~24 ~129 ~86 oak_leaves[persistent=true]
setblock ~24 ~129 ~87 oak_leaves[persistent=true]
setblock ~24 ~129 ~95 jungle_leaves[persistent=true]
setblock ~24 ~129 ~97 oak_leaves[persistent=true]
setblock ~24 ~129 ~98 oak_leaves[persistent=true]
setblock ~24 ~129 ~99 oak_leaves[persistent=true]
setblock ~24 ~129 ~100 oak_leaves[persistent=true]
setblock ~24 ~129 ~101 oak_wood
setblock ~24 ~129 ~102 oak_leaves[persistent=true]
setblock ~24 ~129 ~103 oak_leaves[persistent=true]
setblock ~24 ~129 ~104 jungle_leaves[persistent=true]
setblock ~24 ~129 ~105 oak_leaves[persistent=true]
setblock ~24 ~129 ~106 oak_leaves[persistent=true]
setblock ~24 ~129 ~107 oak_leaves[persistent=true]
setblock ~24 ~129 ~108 oak_leaves[persistent=true]
setblock ~24 ~129 ~109 oak_leaves[persistent=true]
setblock ~24 ~129 ~110 oak_wood
setblock ~24 ~129 ~111 oak_leaves[persistent=true]
setblock ~24 ~129 ~112 jungle_leaves[persistent=true]
setblock ~24 ~129 ~113 oak_leaves[persistent=true]
setblock ~24 ~129 ~114 oak_leaves[persistent=true]
setblock ~24 ~129 ~116 oak_leaves[persistent=true]
setblock ~24 ~129 ~117 oak_leaves[persistent=true]
setblock ~24 ~129 ~118 jungle_leaves[persistent=true]
setblock ~24 ~129 ~119 oak_leaves[persistent=true]
setblock ~24 ~129 ~120 oak_leaves[persistent=true]
setblock ~24 ~129 ~121 oak_leaves[persistent=true]
setblock ~24 ~129 ~122 oak_leaves[persistent=true]
setblock ~24 ~129 ~123 oak_leaves[persistent=true]
setblock ~24 ~129 ~125 jungle_leaves[persistent=true]
setblock ~24 ~129 ~127 oak_leaves[persistent=true]
setblock ~24 ~129 ~128 oak_leaves[persistent=true]
setblock ~24 ~129 ~130 jungle_leaves[persistent=true]
setblock ~24 ~129 ~131 oak_leaves[persistent=true]
setblock ~24 ~129 ~132 oak_leaves[persistent=true]
setblock ~24 ~129 ~133 oak_leaves[persistent=true]
setblock ~24 ~129 ~134 jungle_leaves[persistent=true]
setblock ~24 ~130 ~83 jungle_leaves[persistent=true]
setblock ~24 ~130 ~84 oak_leaves[persistent=true]
setblock ~24 ~130 ~85 oak_leaves[persistent=true]
setblock ~24 ~130 ~86 oak_leaves[persistent=true]
setblock ~24 ~130 ~87 oak_leaves[persistent=true]
setblock ~24 ~130 ~95 oak_leaves[persistent=true]
setblock ~24 ~130 ~96 oak_leaves[persistent=true]
setblock ~24 ~130 ~97 jungle_leaves[persistent=true]
setblock ~24 ~130 ~98 jungle_leaves[persistent=true]
setblock ~24 ~130 ~101 oak_leaves[persistent=true]
setblock ~24 ~130 ~102 oak_leaves[persistent=true]
setblock ~24 ~130 ~103 oak_leaves[persistent=true]
setblock ~24 ~130 ~104 jungle_leaves[persistent=true]
setblock ~24 ~130 ~105 oak_wood
setblock ~24 ~130 ~106 oak_leaves[persistent=true]
setblock ~24 ~130 ~108 oak_leaves[persistent=true]
setblock ~24 ~130 ~109 oak_wood
setblock ~24 ~130 ~110 oak_leaves[persistent=true]
setblock ~24 ~130 ~111 oak_wood
setblock ~24 ~130 ~112 oak_wood
setblock ~24 ~130 ~113 oak_wood
setblock ~24 ~130 ~114 jungle_leaves[persistent=true]
setblock ~24 ~130 ~115 jungle_leaves[persistent=true]
setblock ~24 ~130 ~116 oak_leaves[persistent=true]
setblock ~24 ~130 ~117 oak_leaves[persistent=true]
setblock ~24 ~130 ~119 oak_wood
setblock ~24 ~130 ~120 oak_leaves[persistent=true]
setblock ~24 ~130 ~121 oak_leaves[persistent=true]
setblock ~24 ~130 ~122 oak_leaves[persistent=true]
setblock ~24 ~130 ~123 oak_leaves[persistent=true]
setblock ~24 ~130 ~124 oak_leaves[persistent=true]
setblock ~24 ~130 ~125 oak_leaves[persistent=true]
setblock ~24 ~130 ~126 oak_leaves[persistent=true]
setblock ~24 ~130 ~127 oak_leaves[persistent=true]
setblock ~24 ~130 ~128 oak_leaves[persistent=true]
setblock ~24 ~130 ~129 oak_leaves[persistent=true]
setblock ~24 ~130 ~130 oak_leaves[persistent=true]
setblock ~24 ~130 ~131 jungle_leaves[persistent=true]
setblock ~24 ~130 ~132 oak_leaves[persistent=true]
setblock ~24 ~130 ~133 oak_leaves[persistent=true]
setblock ~24 ~130 ~134 oak_leaves[persistent=true]
setblock ~24 ~131 ~83 oak_leaves[persistent=true]
setblock ~24 ~131 ~84 oak_leaves[persistent=true]
setblock ~24 ~131 ~85 oak_leaves[persistent=true]
setblock ~24 ~131 ~86 oak_leaves[persistent=true]
setblock ~24 ~131 ~87 oak_leaves[persistent=true]
setblock ~24 ~131 ~93 oak_leaves[persistent=true]
setblock ~24 ~131 ~94 oak_leaves[persistent=true]
setblock ~24 ~131 ~95 oak_leaves[persistent=true]
setblock ~24 ~131 ~96 oak_leaves[persistent=true]
setblock ~24 ~131 ~97 oak_leaves[persistent=true]
setblock ~24 ~131 ~98 oak_leaves[persistent=true]
setblock ~24 ~131 ~99 oak_wood
setblock ~24 ~131 ~100 oak_leaves[persistent=true]
setblock ~24 ~131 ~101 oak_leaves[persistent=true]
setblock ~24 ~131 ~102 oak_leaves[persistent=true]
setblock ~24 ~131 ~103 oak_leaves[persistent=true]
setblock ~24 ~131 ~104 oak_leaves[persistent=true]
setblock ~24 ~131 ~105 oak_leaves[persistent=true]
setblock ~24 ~131 ~106 oak_leaves[persistent=true]
setblock ~24 ~131 ~107 oak_leaves[persistent=true]
setblock ~24 ~131 ~108 oak_leaves[persistent=true]
setblock ~24 ~131 ~109 oak_leaves[persistent=true]
setblock ~24 ~131 ~110 oak_wood
setblock ~24 ~131 ~111 oak_leaves[persistent=true]
setblock ~24 ~131 ~113 oak_wood
setblock ~24 ~131 ~114 oak_leaves[persistent=true]
setblock ~24 ~131 ~115 oak_wood
setblock ~24 ~131 ~116 oak_leaves[persistent=true]
setblock ~24 ~131 ~118 oak_wood
setblock ~24 ~131 ~119 oak_leaves[persistent=true]
setblock ~24 ~131 ~120 oak_wood
setblock ~24 ~131 ~121 oak_wood
setblock ~24 ~131 ~122 oak_leaves[persistent=true]
setblock ~24 ~131 ~123 jungle_leaves[persistent=true]
setblock ~24 ~131 ~124 oak_leaves[persistent=true]
setblock ~24 ~131 ~125 jungle_leaves[persistent=true]
setblock ~24 ~131 ~126 jungle_leaves[persistent=true]
setblock ~24 ~131 ~128 oak_wood
setblock ~24 ~131 ~129 oak_leaves[persistent=true]
setblock ~24 ~132 ~84 oak_leaves[persistent=true]
setblock ~24 ~132 ~85 oak_leaves[persistent=true]
setblock ~24 ~132 ~86 oak_leaves[persistent=true]
setblock ~24 ~132 ~87 oak_leaves[persistent=true]
setblock ~24 ~132 ~93 oak_leaves[persistent=true]
setblock ~24 ~132 ~94 oak_leaves[persistent=true]
setblock ~24 ~132 ~95 oak_leaves[persistent=true]
setblock ~24 ~132 ~97 oak_wood
setblock ~24 ~132 ~99 oak_leaves[persistent=true]
setblock ~24 ~132 ~100 oak_leaves[persistent=true]
setblock ~24 ~132 ~101 oak_leaves[persistent=true]
setblock ~24 ~132 ~102 oak_leaves[persistent=true]
setblock ~24 ~132 ~103 oak_wood
setblock ~24 ~132 ~104 oak_leaves[persistent=true]
setblock ~24 ~132 ~105 oak_wood
setblock ~24 ~132 ~106 oak_wood
setblock ~24 ~132 ~107 oak_leaves[persistent=true]
setblock ~24 ~132 ~108 oak_leaves[persistent=true]
setblock ~24 ~132 ~109 oak_wood
setblock ~24 ~132 ~110 oak_leaves[persistent=true]
setblock ~24 ~132 ~111 oak_leaves[persistent=true]
setblock ~24 ~132 ~112 jungle_leaves[persistent=true]
setblock ~24 ~132 ~113 oak_wood
setblock ~24 ~132 ~114 oak_wood
setblock ~24 ~132 ~115 oak_wood
setblock ~24 ~132 ~116 oak_wood
setblock ~24 ~132 ~117 oak_wood
setblock ~24 ~132 ~118 oak_leaves[persistent=true]
setblock ~24 ~132 ~119 oak_wood
setblock ~24 ~132 ~120 oak_leaves[persistent=true]
setblock ~24 ~132 ~121 oak_wood
setblock ~24 ~132 ~122 oak_wood
setblock ~24 ~132 ~123 oak_leaves[persistent=true]
setblock ~24 ~132 ~124 jungle_leaves[persistent=true]
setblock ~24 ~132 ~125 jungle_leaves[persistent=true]
setblock ~24 ~132 ~126 oak_leaves[persistent=true]
setblock ~24 ~132 ~127 oak_leaves[persistent=true]
setblock ~24 ~132 ~128 oak_leaves[persistent=true]
setblock ~24 ~132 ~129 oak_leaves[persistent=true]
setblock ~24 ~132 ~130 oak_leaves[persistent=true]
setblock ~24 ~132 ~131 oak_leaves[persistent=true]
setblock ~24 ~133 ~89 oak_leaves[persistent=true]
setblock ~24 ~133 ~90 oak_leaves[persistent=true]
setblock ~24 ~133 ~92 oak_leaves[persistent=true]
setblock ~24 ~133 ~93 oak_leaves[persistent=true]
setblock ~24 ~133 ~94 oak_leaves[persistent=true]
setblock ~24 ~133 ~95 oak_wood
setblock ~24 ~133 ~96 oak_leaves[persistent=true]
setblock ~24 ~133 ~97 oak_leaves[persistent=true]
setblock ~24 ~133 ~98 oak_wood
setblock ~24 ~133 ~99 oak_leaves[persistent=true]
setblock ~24 ~133 ~100 oak_wood
setblock ~24 ~133 ~101 oak_wood
setblock ~24 ~133 ~102 oak_leaves[persistent=true]
setblock ~24 ~133 ~103 oak_leaves[persistent=true]
setblock ~24 ~133 ~105 oak_leaves[persistent=true]
setblock ~24 ~133 ~106 oak_leaves[persistent=true]
setblock ~24 ~133 ~107 oak_leaves[persistent=true]
setblock ~24 ~133 ~108 oak_leaves[persistent=true]
setblock ~24 ~133 ~109 oak_wood
setblock ~24 ~133 ~110 oak_wood
setblock ~24 ~133 ~111 oak_wood
setblock ~24 ~133 ~112 oak_leaves[persistent=true]
setblock ~24 ~133 ~113 oak_leaves[persistent=true]
setblock ~24 ~133 ~114 oak_leaves[persistent=true]
setblock ~24 ~133 ~115 oak_wood
setblock ~24 ~133 ~116 oak_wood
setblock ~24 ~133 ~118 oak_wood
setblock ~24 ~133 ~119 oak_wood
setblock ~24 ~133 ~121 oak_wood
setblock ~24 ~133 ~122 oak_leaves[persistent=true]
setblock ~24 ~133 ~123 oak_leaves[persistent=true]
setblock ~24 ~133 ~124 oak_leaves[persistent=true]
setblock ~24 ~133 ~125 oak_leaves[persistent=true]
setblock ~24 ~133 ~126 jungle_leaves[persistent=true]
setblock ~24 ~133 ~127 oak_leaves[persistent=true]
setblock ~24 ~133 ~128 oak_leaves[persistent=true]
setblock ~24 ~133 ~130 oak_leaves[persistent=true]
setblock ~24 ~133 ~131 jungle_leaves[persistent=true]
setblock ~24 ~134 ~88 oak_leaves[persistent=true]
setblock ~24 ~134 ~89 oak_leaves[persistent=true]
