setblock ~190 ~125 ~16 grass_block
setblock ~190 ~125 ~17 grass_block
setblock ~190 ~125 ~18 grass_block
setblock ~190 ~125 ~21 short_grass
setblock ~190 ~125 ~23 short_grass
setblock ~190 ~125 ~34 grass_block
setblock ~190 ~125 ~35 grass_block
setblock ~190 ~125 ~36 dirt
setblock ~190 ~125 ~37 dirt
setblock ~190 ~125 ~38 dirt
setblock ~190 ~125 ~39 dirt
setblock ~190 ~125 ~40 dirt
setblock ~190 ~125 ~41 dirt
setblock ~190 ~125 ~42 dirt
setblock ~190 ~125 ~43 dirt
setblock ~190 ~125 ~44 dirt
setblock ~190 ~125 ~45 dirt
setblock ~190 ~125 ~46 dirt
setblock ~190 ~125 ~47 dirt
setblock ~190 ~125 ~48 dirt
setblock ~190 ~125 ~49 dirt
setblock ~190 ~125 ~50 dirt
setblock ~190 ~125 ~51 dirt
setblock ~190 ~125 ~52 dirt
setblock ~190 ~125 ~53 dirt
setblock ~190 ~125 ~54 dirt
setblock ~190 ~125 ~55 dirt
setblock ~190 ~125 ~56 dirt
setblock ~190 ~125 ~57 grass_block
setblock ~190 ~125 ~58 grass_block
setblock ~190 ~125 ~59 grass_block
setblock ~190 ~125 ~61 poppy
setblock ~190 ~125 ~63 poppy
setblock ~190 ~125 ~78 grass_block
setblock ~190 ~125 ~79 grass_block
setblock ~190 ~125 ~80 grass_block
setblock ~190 ~125 ~81 grass_block
setblock ~190 ~125 ~82 grass_block
setblock ~190 ~125 ~83 grass_block
setblock ~190 ~125 ~84 grass_block
setblock ~190 ~125 ~85 grass_block
setblock ~190 ~125 ~86 grass_block
setblock ~190 ~125 ~87 dirt
setblock ~190 ~125 ~88 dirt
setblock ~190 ~125 ~89 dirt
setblock ~190 ~125 ~90 dirt
setblock ~190 ~125 ~91 dirt
setblock ~190 ~125 ~92 grass_block
setblock ~190 ~125 ~93 grass_block
setblock ~190 ~125 ~94 grass_block
setblock ~190 ~125 ~95 grass_block
setblock ~190 ~125 ~97 short_grass
setblock ~190 ~125 ~98 fern
setblock ~190 ~125 ~115 poppy
setblock ~190 ~125 ~116 short_grass
setblock ~190 ~125 ~118 short_grass
setblock ~190 ~125 ~143 poppy
setblock ~190 ~125 ~144 short_grass
setblock ~190 ~125 ~145 short_grass
setblock ~190 ~125 ~146 grass_block
setblock ~190 ~125 ~147 grass_block
setblock ~190 ~125 ~148 grass_block
setblock ~190 ~125 ~149 dirt
setblock ~190 ~125 ~150 dirt
setblock ~190 ~125 ~151 dirt
setblock ~190 ~125 ~152 grass_block
setblock ~190 ~125 ~153 grass_block
setblock ~190 ~125 ~156 short_grass
setblock ~190 ~125 ~164 short_grass
setblock ~190 ~125 ~167 grass_block
setblock ~190 ~125 ~168 grass_block
setblock ~190 ~125 ~169 grass_block
setblock ~190 ~125 ~170 dirt
setblock ~190 ~125 ~171 dirt
setblock ~190 ~125 ~172 dirt
setblock ~190 ~125 ~173 dirt
setblock ~190 ~125 ~174 dirt
setblock ~190 ~125 ~175 dirt
setblock ~190 ~125 ~176 dirt
setblock ~190 ~125 ~177 dirt
setblock ~190 ~125 ~178 dirt
setblock ~190 ~125 ~179 dirt
setblock ~190 ~125 ~180 dirt
setblock ~190 ~125 ~181 dirt
setblock ~190 ~125 ~182 dirt
setblock ~190 ~125 ~183 dirt
setblock ~190 ~125 ~184 dirt
setblock ~190 ~125 ~185 grass_block
setblock ~190 ~125 ~186 grass_block
setblock ~190 ~125 ~187 grass_block
setblock ~190 ~125 ~188 fern
setblock ~190 ~125 ~193 grass_block
setblock ~190 ~125 ~194 dirt
setblock ~190 ~125 ~195 dirt
setblock ~190 ~125 ~196 dirt
setblock ~190 ~125 ~197 dirt
setblock ~190 ~125 ~198 dirt
setblock ~190 ~125 ~199 dirt
setblock ~190 ~126 ~11 short_grass
setblock ~190 ~126 ~15 short_grass
setblock ~190 ~126 ~34 short_grass
setblock ~190 ~126 ~36 grass_block
setblock ~190 ~126 ~37 dirt
setblock ~190 ~126 ~38 dirt
setblock ~190 ~126 ~39 dirt
setblock ~190 ~126 ~40 dirt
setblock ~190 ~126 ~41 dirt
setblock ~190 ~126 ~42 dirt
setblock ~190 ~126 ~43 dirt
setblock ~190 ~126 ~44 dirt
setblock ~190 ~126 ~45 dirt
setblock ~190 ~126 ~46 dirt
setblock ~190 ~126 ~47 dirt
setblock ~190 ~126 ~48 dirt
setblock ~190 ~126 ~49 dirt
setblock ~190 ~126 ~50 grass_block
setblock ~190 ~126 ~51 grass_block
setblock ~190 ~126 ~52 grass_block
setblock ~190 ~126 ~53 grass_block
setblock ~190 ~126 ~54 grass_block
setblock ~190 ~126 ~55 grass_block
setblock ~190 ~126 ~56 grass_block
setblock ~190 ~126 ~57 fern
setblock ~190 ~126 ~59 short_grass
setblock ~190 ~126 ~82 short_grass
setblock ~190 ~126 ~85 short_grass
setblock ~190 ~126 ~86 fern
setblock ~190 ~126 ~87 grass_block
setblock ~190 ~126 ~88 grass_block
setblock ~190 ~126 ~89 grass_block
setblock ~190 ~126 ~90 grass_block
setblock ~190 ~126 ~91 grass_block
setblock ~190 ~126 ~94 fern
setblock ~190 ~126 ~147 short_grass
setblock ~190 ~126 ~149 grass_block
setblock ~190 ~126 ~150 grass_block
setblock ~190 ~126 ~151 grass_block
setblock ~190 ~126 ~153 short_grass
setblock ~190 ~126 ~170 grass_block
setblock ~190 ~126 ~171 grass_block
setblock ~190 ~126 ~172 grass_block
setblock ~190 ~126 ~173 grass_block
setblock ~190 ~126 ~174 dirt
setblock ~190 ~126 ~175 dirt
setblock ~190 ~126 ~176 dirt
setblock ~190 ~126 ~177 dirt
setblock ~190 ~126 ~178 dirt
setblock ~190 ~126 ~179 dirt
setblock ~190 ~126 ~180 dirt
setblock ~190 ~126 ~181 grass_block
setblock ~190 ~126 ~182 grass_block
setblock ~190 ~126 ~183 grass_block
setblock ~190 ~126 ~184 grass_block
setblock ~190 ~126 ~185 short_grass
setblock ~190 ~126 ~193 poppy
setblock ~190 ~126 ~194 grass_block
setblock ~190 ~126 ~195 grass_block
setblock ~190 ~126 ~196 dirt
setblock ~190 ~126 ~197 dirt
setblock ~190 ~126 ~198 dirt
setblock ~190 ~126 ~199 dirt
setblock ~190 ~127 ~37 grass_block
setblock ~190 ~127 ~38 dirt
setblock ~190 ~127 ~39 dirt
setblock ~190 ~127 ~40 dirt
setblock ~190 ~127 ~41 dirt
setblock ~190 ~127 ~42 dirt
setblock ~190 ~127 ~43 dirt
setblock ~190 ~127 ~44 dirt
setblock ~190 ~127 ~45 dirt
setblock ~190 ~127 ~46 dirt
setblock ~190 ~127 ~47 grass_block
setblock ~190 ~127 ~48 grass_block
setblock ~190 ~127 ~49 grass_block
setblock ~190 ~127 ~52 short_grass
setblock ~190 ~127 ~87 poppy
setblock ~190 ~127 ~88 short_grass
setblock ~190 ~127 ~150 poppy
setblock ~190 ~127 ~173 poppy
setblock ~190 ~127 ~174 grass_block
setblock ~190 ~127 ~175 grass_block
setblock ~190 ~127 ~176 grass_block
setblock ~190 ~127 ~177 grass_block
setblock ~190 ~127 ~178 grass_block
setblock ~190 ~127 ~179 grass_block
setblock ~190 ~127 ~180 grass_block
setblock ~190 ~127 ~183 poppy
setblock ~190 ~127 ~184 short_grass
setblock ~190 ~127 ~196 grass_block
setblock ~190 ~127 ~197 grass_block
setblock ~190 ~127 ~198 grass_block
setblock ~190 ~127 ~199 dirt
setblock ~190 ~128 ~38 grass_block
setblock ~190 ~128 ~39 dirt
setblock ~190 ~128 ~40 dirt
setblock ~190 ~128 ~41 dirt
setblock ~190 ~128 ~42 dirt
setblock ~190 ~128 ~43 dirt
setblock ~190 ~128 ~44 dirt
setblock ~190 ~128 ~45 grass_block
setblock ~190 ~128 ~46 grass_block
setblock ~190 ~128 ~174 short_grass
setblock ~190 ~128 ~175 short_grass
setblock ~190 ~128 ~177 short_grass
setblock ~190 ~128 ~199 grass_block
setblock ~190 ~129 ~39 dirt
setblock ~190 ~129 ~40 dirt
setblock ~190 ~129 ~41 dirt
setblock ~190 ~129 ~42 dirt
setblock ~190 ~129 ~43 grass_block
setblock ~190 ~129 ~44 grass_block
setblock ~190 ~129 ~46 short_grass
setblock ~190 ~130 ~39 grass_block
setblock ~190 ~130 ~40 dirt
setblock ~190 ~130 ~41 dirt
setblock ~190 ~130 ~42 grass_block
setblock ~190 ~131 ~40 grass_block
setblock ~190 ~131 ~41 grass_block
setblock ~191 ~122 ~0 dirt
setblock ~191 ~122 ~1 dirt
setblock ~191 ~122 ~2 dirt
setblock ~191 ~122 ~3 dirt
setblock ~191 ~122 ~4 dirt
setblock ~191 ~122 ~5 dirt
setblock ~191 ~122 ~6 dirt
setblock ~191 ~122 ~7 dirt
setblock ~191 ~122 ~8 dirt
setblock ~191 ~122 ~9 dirt
setblock ~191 ~122 ~10 dirt
setblock ~191 ~122 ~11 dirt
setblock ~191 ~122 ~12 dirt
setblock ~191 ~122 ~13 dirt
setblock ~191 ~122 ~14 dirt
setblock ~191 ~122 ~15 dirt
setblock ~191 ~122 ~16 dirt
setblock ~191 ~122 ~17 dirt
setblock ~191 ~122 ~18 dirt
setblock ~191 ~122 ~19 dirt
setblock ~191 ~122 ~20 dirt
setblock ~191 ~122 ~21 dirt
setblock ~191 ~122 ~22 dirt
setblock ~191 ~122 ~23 dirt
setblock ~191 ~122 ~24 dirt
setblock ~191 ~122 ~25 dirt
setblock ~191 ~122 ~26 dirt
setblock ~191 ~122 ~27 dirt
setblock ~191 ~122 ~28 dirt
setblock ~191 ~122 ~29 dirt
setblock ~191 ~122 ~30 dirt
setblock ~191 ~122 ~31 dirt
setblock ~191 ~122 ~32 dirt
setblock ~191 ~122 ~33 dirt
setblock ~191 ~122 ~34 dirt
setblock ~191 ~122 ~35 dirt
setblock ~191 ~122 ~36 dirt
setblock ~191 ~122 ~37 dirt
setblock ~191 ~122 ~38 dirt
setblock ~191 ~122 ~39 dirt
setblock ~191 ~122 ~40 dirt
setblock ~191 ~122 ~41 dirt
setblock ~191 ~122 ~42 dirt
setblock ~191 ~122 ~43 dirt
setblock ~191 ~122 ~44 dirt
setblock ~191 ~122 ~45 dirt
setblock ~191 ~122 ~46 dirt
setblock ~191 ~122 ~47 dirt
setblock ~191 ~122 ~48 dirt
setblock ~191 ~122 ~49 dirt
setblock ~191 ~122 ~50 dirt
setblock ~191 ~122 ~51 dirt
setblock ~191 ~122 ~52 dirt
setblock ~191 ~122 ~53 dirt
setblock ~191 ~122 ~54 dirt
setblock ~191 ~122 ~55 dirt
setblock ~191 ~122 ~56 dirt
setblock ~191 ~122 ~57 dirt
setblock ~191 ~122 ~58 dirt
setblock ~191 ~122 ~59 dirt
setblock ~191 ~122 ~60 dirt
setblock ~191 ~122 ~61 dirt
setblock ~191 ~122 ~62 dirt
setblock ~191 ~122 ~63 dirt
setblock ~191 ~122 ~64 dirt
setblock ~191 ~122 ~65 dirt
setblock ~191 ~122 ~66 dirt
setblock ~191 ~122 ~67 dirt
setblock ~191 ~122 ~68 grass_block
setblock ~191 ~122 ~69 grass_block
setblock ~191 ~122 ~70 grass_block
setblock ~191 ~122 ~71 dirt
setblock ~191 ~122 ~72 dirt
setblock ~191 ~122 ~73 dirt
setblock ~191 ~122 ~74 dirt
setblock ~191 ~122 ~75 dirt
setblock ~191 ~122 ~76 dirt
setblock ~191 ~122 ~77 dirt
setblock ~191 ~122 ~78 dirt
setblock ~191 ~122 ~79 dirt
setblock ~191 ~122 ~80 dirt
setblock ~191 ~122 ~81 dirt
setblock ~191 ~122 ~82 dirt
setblock ~191 ~122 ~83 dirt
setblock ~191 ~122 ~84 dirt
setblock ~191 ~122 ~85 dirt
setblock ~191 ~122 ~86 dirt
setblock ~191 ~122 ~87 dirt
setblock ~191 ~122 ~88 dirt
setblock ~191 ~122 ~89 dirt
setblock ~191 ~122 ~90 dirt
setblock ~191 ~122 ~91 dirt
setblock ~191 ~122 ~92 dirt
setblock ~191 ~122 ~93 dirt
setblock ~191 ~122 ~94 dirt
setblock ~191 ~122 ~95 dirt
setblock ~191 ~122 ~96 dirt
setblock ~191 ~122 ~97 dirt
setblock ~191 ~122 ~98 dirt
setblock ~191 ~122 ~99 dirt
setblock ~191 ~122 ~100 dirt
setblock ~191 ~122 ~101 dirt
setblock ~191 ~122 ~102 dirt
setblock ~191 ~122 ~103 dirt
setblock ~191 ~122 ~104 dirt
setblock ~191 ~122 ~105 dirt
setblock ~191 ~122 ~106 dirt
setblock ~191 ~122 ~107 dirt
setblock ~191 ~122 ~108 dirt
setblock ~191 ~122 ~109 dirt
setblock ~191 ~122 ~110 dirt
setblock ~191 ~122 ~111 dirt
setblock ~191 ~122 ~112 dirt
setblock ~191 ~122 ~113 dirt
setblock ~191 ~122 ~114 dirt
setblock ~191 ~122 ~115 dirt
setblock ~191 ~122 ~116 dirt
setblock ~191 ~122 ~117 dirt
setblock ~191 ~122 ~118 dirt
setblock ~191 ~122 ~119 dirt
setblock ~191 ~122 ~120 dirt
setblock ~191 ~122 ~121 dirt
setblock ~191 ~122 ~122 dirt
setblock ~191 ~122 ~123 dirt
setblock ~191 ~122 ~124 dirt
setblock ~191 ~122 ~125 dirt
setblock ~191 ~122 ~126 dirt
setblock ~191 ~122 ~127 dirt
setblock ~191 ~122 ~128 dirt
setblock ~191 ~122 ~129 dirt
setblock ~191 ~122 ~130 dirt
setblock ~191 ~122 ~131 dirt
setblock ~191 ~122 ~132 dirt
setblock ~191 ~122 ~133 dirt
setblock ~191 ~122 ~134 dirt
setblock ~191 ~122 ~135 dirt
setblock ~191 ~122 ~136 dirt
setblock ~191 ~122 ~137 dirt
setblock ~191 ~122 ~138 dirt
setblock ~191 ~122 ~139 dirt
setblock ~191 ~122 ~140 dirt
setblock ~191 ~122 ~141 dirt
setblock ~191 ~122 ~142 dirt
setblock ~191 ~122 ~143 dirt
setblock ~191 ~122 ~144 dirt
setblock ~191 ~122 ~145 dirt
setblock ~191 ~122 ~146 dirt
setblock ~191 ~122 ~147 dirt
setblock ~191 ~122 ~148 dirt
setblock ~191 ~122 ~149 dirt
setblock ~191 ~122 ~150 dirt
setblock ~191 ~122 ~151 dirt
setblock ~191 ~122 ~152 dirt
setblock ~191 ~122 ~153 dirt
setblock ~191 ~122 ~154 dirt
setblock ~191 ~122 ~155 dirt
setblock ~191 ~122 ~156 dirt
setblock ~191 ~122 ~157 dirt
setblock ~191 ~122 ~158 dirt
setblock ~191 ~122 ~159 dirt
setblock ~191 ~122 ~160 dirt
setblock ~191 ~122 ~161 dirt
setblock ~191 ~122 ~162 dirt
setblock ~191 ~122 ~163 dirt
setblock ~191 ~122 ~164 dirt
setblock ~191 ~122 ~165 dirt
setblock ~191 ~122 ~166 dirt
setblock ~191 ~122 ~167 dirt
setblock ~191 ~122 ~168 dirt
setblock ~191 ~122 ~169 dirt
setblock ~191 ~122 ~170 dirt
setblock ~191 ~122 ~171 dirt
setblock ~191 ~122 ~172 dirt
setblock ~191 ~122 ~173 dirt
setblock ~191 ~122 ~174 dirt
setblock ~191 ~122 ~175 dirt
setblock ~191 ~122 ~176 dirt
setblock ~191 ~122 ~177 dirt
setblock ~191 ~122 ~178 dirt
setblock ~191 ~122 ~179 dirt
setblock ~191 ~122 ~180 dirt
setblock ~191 ~122 ~181 dirt
setblock ~191 ~122 ~182 dirt
setblock ~191 ~122 ~183 dirt
setblock ~191 ~122 ~184 dirt
setblock ~191 ~122 ~185 dirt
setblock ~191 ~122 ~186 dirt
setblock ~191 ~122 ~187 dirt
setblock ~191 ~122 ~188 dirt
setblock ~191 ~122 ~189 dirt
setblock ~191 ~122 ~190 dirt
setblock ~191 ~122 ~191 dirt
setblock ~191 ~122 ~192 dirt
setblock ~191 ~122 ~193 dirt
setblock ~191 ~122 ~194 dirt
setblock ~191 ~122 ~195 dirt
setblock ~191 ~122 ~196 dirt
setblock ~191 ~122 ~197 dirt
setblock ~191 ~122 ~198 dirt
setblock ~191 ~122 ~199 dirt
setblock ~191 ~123 ~0 grass_block
setblock ~191 ~123 ~1 grass_block
setblock ~191 ~123 ~2 grass_block
setblock ~191 ~123 ~3 grass_block
setblock ~191 ~123 ~4 dirt
setblock ~191 ~123 ~5 dirt
setblock ~191 ~123 ~6 dirt
setblock ~191 ~123 ~7 dirt
setblock ~191 ~123 ~8 dirt
setblock ~191 ~123 ~9 dirt
setblock ~191 ~123 ~10 dirt
setblock ~191 ~123 ~11 dirt
setblock ~191 ~123 ~12 dirt
setblock ~191 ~123 ~13 dirt
setblock ~191 ~123 ~14 dirt
setblock ~191 ~123 ~15 dirt
setblock ~191 ~123 ~16 dirt
setblock ~191 ~123 ~17 dirt
setblock ~191 ~123 ~18 dirt
setblock ~191 ~123 ~19 dirt
setblock ~191 ~123 ~20 dirt
setblock ~191 ~123 ~21 dirt
setblock ~191 ~123 ~22 dirt
setblock ~191 ~123 ~23 dirt
setblock ~191 ~123 ~24 dirt
setblock ~191 ~123 ~25 dirt
setblock ~191 ~123 ~26 dirt
setblock ~191 ~123 ~27 dirt
setblock ~191 ~123 ~28 grass_block
setblock ~191 ~123 ~29 grass_block
setblock ~191 ~123 ~30 grass_block
setblock ~191 ~123 ~31 dirt
setblock ~191 ~123 ~32 dirt
setblock ~191 ~123 ~33 dirt
setblock ~191 ~123 ~34 dirt
setblock ~191 ~123 ~35 dirt
setblock ~191 ~123 ~36 dirt
setblock ~191 ~123 ~37 dirt
setblock ~191 ~123 ~38 dirt
setblock ~191 ~123 ~39 dirt
setblock ~191 ~123 ~40 dirt
setblock ~191 ~123 ~41 dirt
setblock ~191 ~123 ~42 dirt
setblock ~191 ~123 ~43 dirt
setblock ~191 ~123 ~44 dirt
setblock ~191 ~123 ~45 dirt
setblock ~191 ~123 ~46 dirt
setblock ~191 ~123 ~47 dirt
setblock ~191 ~123 ~48 dirt
setblock ~191 ~123 ~49 dirt
setblock ~191 ~123 ~50 dirt
setblock ~191 ~123 ~51 dirt
setblock ~191 ~123 ~52 dirt
setblock ~191 ~123 ~53 dirt
setblock ~191 ~123 ~54 dirt
setblock ~191 ~123 ~55 dirt
setblock ~191 ~123 ~56 dirt
setblock ~191 ~123 ~57 dirt
setblock ~191 ~123 ~58 dirt
setblock ~191 ~123 ~59 dirt
setblock ~191 ~123 ~60 dirt
setblock ~191 ~123 ~61 dirt
setblock ~191 ~123 ~62 dirt
setblock ~191 ~123 ~63 dirt
setblock ~191 ~123 ~64 grass_block
setblock ~191 ~123 ~65 grass_block
setblock ~191 ~123 ~66 grass_block
setblock ~191 ~123 ~67 grass_block
setblock ~191 ~123 ~68 short_grass
setblock ~191 ~123 ~69 short_grass
setblock ~191 ~123 ~71 grass_block
setblock ~191 ~123 ~72 grass_block
setblock ~191 ~123 ~73 grass_block
setblock ~191 ~123 ~74 dirt
setblock ~191 ~123 ~75 dirt
setblock ~191 ~123 ~76 dirt
setblock ~191 ~123 ~77 dirt
setblock ~191 ~123 ~78 dirt
setblock ~191 ~123 ~79 dirt
setblock ~191 ~123 ~80 dirt
setblock ~191 ~123 ~81 dirt
setblock ~191 ~123 ~82 dirt
setblock ~191 ~123 ~83 dirt
setblock ~191 ~123 ~84 dirt
setblock ~191 ~123 ~85 dirt
setblock ~191 ~123 ~86 dirt
setblock ~191 ~123 ~87 dirt
setblock ~191 ~123 ~88 dirt
setblock ~191 ~123 ~89 dirt
setblock ~191 ~123 ~90 dirt
setblock ~191 ~123 ~91 dirt
setblock ~191 ~123 ~92 dirt
setblock ~191 ~123 ~93 dirt
setblock ~191 ~123 ~94 dirt
setblock ~191 ~123 ~95 dirt
setblock ~191 ~123 ~96 dirt
setblock ~191 ~123 ~97 dirt
setblock ~191 ~123 ~98 dirt
setblock ~191 ~123 ~99 dirt
setblock ~191 ~123 ~100 dirt
setblock ~191 ~123 ~101 dirt
setblock ~191 ~123 ~102 dirt
setblock ~191 ~123 ~103 dirt
setblock ~191 ~123 ~104 dirt
setblock ~191 ~123 ~105 dirt
setblock ~191 ~123 ~106 dirt
setblock ~191 ~123 ~107 dirt
setblock ~191 ~123 ~108 grass_block
setblock ~191 ~123 ~109 grass_block
setblock ~191 ~123 ~110 grass_block
setblock ~191 ~123 ~111 dirt
setblock ~191 ~123 ~112 dirt
setblock ~191 ~123 ~113 dirt
setblock ~191 ~123 ~114 dirt
setblock ~191 ~123 ~115 dirt
setblock ~191 ~123 ~116 dirt
setblock ~191 ~123 ~117 dirt
setblock ~191 ~123 ~118 dirt
setblock ~191 ~123 ~119 dirt
setblock ~191 ~123 ~120 dirt
setblock ~191 ~123 ~121 dirt
setblock ~191 ~123 ~122 dirt
setblock ~191 ~123 ~123 dirt
setblock ~191 ~123 ~124 grass_block
setblock ~191 ~123 ~125 grass_block
setblock ~191 ~123 ~126 grass_block
setblock ~191 ~123 ~127 grass_block
setblock ~191 ~123 ~128 grass_block
setblock ~191 ~123 ~129 grass_block
setblock ~191 ~123 ~130 grass_block
setblock ~191 ~123 ~131 grass_block
setblock ~191 ~123 ~132 grass_block
setblock ~191 ~123 ~133 grass_block
setblock ~191 ~123 ~134 grass_block
setblock ~191 ~123 ~135 grass_block
setblock ~191 ~123 ~136 grass_block
setblock ~191 ~123 ~137 grass_block
setblock ~191 ~123 ~138 grass_block
setblock ~191 ~123 ~139 grass_block
setblock ~191 ~123 ~140 grass_block
setblock ~191 ~123 ~141 grass_block
setblock ~191 ~123 ~142 dirt
setblock ~191 ~123 ~143 dirt
setblock ~191 ~123 ~144 dirt
setblock ~191 ~123 ~145 dirt
setblock ~191 ~123 ~146 dirt
setblock ~191 ~123 ~147 dirt
setblock ~191 ~123 ~148 dirt
setblock ~191 ~123 ~149 dirt
setblock ~191 ~123 ~150 dirt
setblock ~191 ~123 ~151 dirt
setblock ~191 ~123 ~152 dirt
setblock ~191 ~123 ~153 dirt
setblock ~191 ~123 ~154 dirt
setblock ~191 ~123 ~155 dirt
setblock ~191 ~123 ~156 dirt
setblock ~191 ~123 ~157 grass_block
setblock ~191 ~123 ~158 grass_block
setblock ~191 ~123 ~159 grass_block
setblock ~191 ~123 ~160 grass_block
setblock ~191 ~123 ~161 grass_block
setblock ~191 ~123 ~162 grass_block
setblock ~191 ~123 ~163 grass_block
setblock ~191 ~123 ~164 dirt
setblock ~191 ~123 ~165 dirt
setblock ~191 ~123 ~166 dirt
setblock ~191 ~123 ~167 dirt
setblock ~191 ~123 ~168 dirt
setblock ~191 ~123 ~169 dirt
setblock ~191 ~123 ~170 dirt
setblock ~191 ~123 ~171 dirt
setblock ~191 ~123 ~172 dirt
setblock ~191 ~123 ~173 dirt
setblock ~191 ~123 ~174 dirt
setblock ~191 ~123 ~175 dirt
setblock ~191 ~123 ~176 dirt
setblock ~191 ~123 ~177 dirt
setblock ~191 ~123 ~178 dirt
setblock ~191 ~123 ~179 dirt
setblock ~191 ~123 ~180 dirt
setblock ~191 ~123 ~181 dirt
setblock ~191 ~123 ~182 dirt
setblock ~191 ~123 ~183 dirt
setblock ~191 ~123 ~184 dirt
setblock ~191 ~123 ~185 dirt
setblock ~191 ~123 ~186 dirt
setblock ~191 ~123 ~187 dirt
setblock ~191 ~123 ~188 dirt
setblock ~191 ~123 ~189 dirt
setblock ~191 ~123 ~190 dirt
setblock ~191 ~123 ~191 dirt
setblock ~191 ~123 ~192 dirt
setblock ~191 ~123 ~193 dirt
setblock ~191 ~123 ~194 dirt
setblock ~191 ~123 ~195 dirt
setblock ~191 ~123 ~196 dirt
setblock ~191 ~123 ~197 dirt
setblock ~191 ~123 ~198 dirt
setblock ~191 ~123 ~199 dirt
setblock ~191 ~124 ~2 short_grass
setblock ~191 ~124 ~3 poppy
setblock ~191 ~124 ~4 grass_block
setblock ~191 ~124 ~5 grass_block
setblock ~191 ~124 ~6 grass_block
setblock ~191 ~124 ~7 grass_block
setblock ~191 ~124 ~8 grass_block
setblock ~191 ~124 ~9 dirt
setblock ~191 ~124 ~10 dirt
setblock ~191 ~124 ~11 dirt
setblock ~191 ~124 ~12 dirt
setblock ~191 ~124 ~13 dirt
setblock ~191 ~124 ~14 dirt
setblock ~191 ~124 ~15 dirt
setblock ~191 ~124 ~16 dirt
setblock ~191 ~124 ~17 dirt
setblock ~191 ~124 ~18 dirt
setblock ~191 ~124 ~19 grass_block
setblock ~191 ~124 ~20 grass_block
setblock ~191 ~124 ~21 grass_block
setblock ~191 ~124 ~22 grass_block
setblock ~191 ~124 ~23 grass_block
setblock ~191 ~124 ~24 grass_block
setblock ~191 ~124 ~25 grass_block
setblock ~191 ~124 ~26 grass_block
setblock ~191 ~124 ~27 grass_block
setblock ~191 ~124 ~31 grass_block
setblock ~191 ~124 ~32 grass_block
setblock ~191 ~124 ~33 dirt
setblock ~191 ~124 ~34 dirt
setblock ~191 ~124 ~35 dirt
setblock ~191 ~124 ~36 dirt
setblock ~191 ~124 ~37 dirt
setblock ~191 ~124 ~38 dirt
setblock ~191 ~124 ~39 dirt
setblock ~191 ~124 ~40 dirt
setblock ~191 ~124 ~41 dirt
setblock ~191 ~124 ~42 dirt
setblock ~191 ~124 ~43 dirt
setblock ~191 ~124 ~44 dirt
setblock ~191 ~124 ~45 dirt
setblock ~191 ~124 ~46 dirt
setblock ~191 ~124 ~47 dirt
setblock ~191 ~124 ~48 dirt
setblock ~191 ~124 ~49 dirt
setblock ~191 ~124 ~50 dirt
setblock ~191 ~124 ~51 dirt
setblock ~191 ~124 ~52 dirt
setblock ~191 ~124 ~53 dirt
setblock ~191 ~124 ~54 dirt
setblock ~191 ~124 ~55 dirt
setblock ~191 ~124 ~56 dirt
setblock ~191 ~124 ~57 dirt
setblock ~191 ~124 ~58 dirt
setblock ~191 ~124 ~59 dirt
setblock ~191 ~124 ~60 grass_block
setblock ~191 ~124 ~61 grass_block
setblock ~191 ~124 ~62 grass_block
setblock ~191 ~124 ~63 grass_block
setblock ~191 ~124 ~74 grass_block
setblock ~191 ~124 ~75 grass_block
setblock ~191 ~124 ~76 grass_block
setblock ~191 ~124 ~77 grass_block
setblock ~191 ~124 ~78 grass_block
setblock ~191 ~124 ~79 dirt
setblock ~191 ~124 ~80 dirt
setblock ~191 ~124 ~81 dirt
setblock ~191 ~124 ~82 dirt
setblock ~191 ~124 ~83 dirt
setblock ~191 ~124 ~84 dirt
setblock ~191 ~124 ~85 dirt
setblock ~191 ~124 ~86 dirt
setblock ~191 ~124 ~87 dirt
setblock ~191 ~124 ~88 dirt
setblock ~191 ~124 ~89 dirt
setblock ~191 ~124 ~90 dirt
setblock ~191 ~124 ~91 dirt
setblock ~191 ~124 ~92 dirt
setblock ~191 ~124 ~93 dirt
setblock ~191 ~124 ~94 dirt
setblock ~191 ~124 ~95 dirt
setblock ~191 ~124 ~96 grass_block
setblock ~191 ~124 ~97 grass_block
setblock ~191 ~124 ~98 grass_block
setblock ~191 ~124 ~99 grass_block
setblock ~191 ~124 ~100 grass_block
setblock ~191 ~124 ~101 grass_block
setblock ~191 ~124 ~102 grass_block
setblock ~191 ~124 ~103 grass_block
setblock ~191 ~124 ~104 grass_block
setblock ~191 ~124 ~105 grass_block
setblock ~191 ~124 ~106 grass_block
setblock ~191 ~124 ~107 grass_block
setblock ~191 ~124 ~111 grass_block
setblock ~191 ~124 ~112 grass_block
setblock ~191 ~124 ~113 grass_block
setblock ~191 ~124 ~114 grass_block
setblock ~191 ~124 ~115 grass_block
setblock ~191 ~124 ~116 grass_block
setblock ~191 ~124 ~117 grass_block
setblock ~191 ~124 ~118 grass_block
setblock ~191 ~124 ~119 grass_block
setblock ~191 ~124 ~120 grass_block
setblock ~191 ~124 ~121 grass_block
setblock ~191 ~124 ~122 grass_block
setblock ~191 ~124 ~123 grass_block
setblock ~191 ~124 ~131 short_grass
setblock ~191 ~124 ~135 short_grass
setblock ~191 ~124 ~139 poppy
setblock ~191 ~124 ~140 short_grass
setblock ~191 ~124 ~142 grass_block
setblock ~191 ~124 ~143 grass_block
setblock ~191 ~124 ~144 grass_block
setblock ~191 ~124 ~145 grass_block
setblock ~191 ~124 ~146 dirt
setblock ~191 ~124 ~147 dirt
setblock ~191 ~124 ~148 dirt
setblock ~191 ~124 ~149 dirt
setblock ~191 ~124 ~150 dirt
setblock ~191 ~124 ~151 dirt
setblock ~191 ~124 ~152 dirt
setblock ~191 ~124 ~153 dirt
setblock ~191 ~124 ~154 dirt
setblock ~191 ~124 ~155 grass_block
setblock ~191 ~124 ~156 grass_block
setblock ~191 ~124 ~157 short_grass
setblock ~191 ~124 ~161 short_grass
setblock ~191 ~124 ~162 short_grass
setblock ~191 ~124 ~164 grass_block
setblock ~191 ~124 ~165 grass_block
setblock ~191 ~124 ~166 grass_block
setblock ~191 ~124 ~167 dirt
setblock ~191 ~124 ~168 dirt
setblock ~191 ~124 ~169 dirt
setblock ~191 ~124 ~170 dirt
setblock ~191 ~124 ~171 dirt
setblock ~191 ~124 ~172 dirt
setblock ~191 ~124 ~173 dirt
setblock ~191 ~124 ~174 dirt
setblock ~191 ~124 ~175 dirt
setblock ~191 ~124 ~176 dirt
setblock ~191 ~124 ~177 dirt
setblock ~191 ~124 ~178 dirt
setblock ~191 ~124 ~179 dirt
setblock ~191 ~124 ~180 dirt
setblock ~191 ~124 ~181 dirt
setblock ~191 ~124 ~182 dirt
setblock ~191 ~124 ~183 dirt
setblock ~191 ~124 ~184 dirt
setblock ~191 ~124 ~185 dirt
setblock ~191 ~124 ~186 dirt
setblock ~191 ~124 ~187 dirt
setblock ~191 ~124 ~188 grass_block
setblock ~191 ~124 ~189 grass_block
setblock ~191 ~124 ~190 grass_block
setblock ~191 ~124 ~191 grass_block
setblock ~191 ~124 ~192 dirt
setblock ~191 ~124 ~193 dirt
setblock ~191 ~124 ~194 dirt
setblock ~191 ~124 ~195 dirt
setblock ~191 ~124 ~196 dirt
setblock ~191 ~124 ~197 dirt
setblock ~191 ~124 ~198 dirt
setblock ~191 ~124 ~199 dirt
setblock ~191 ~125 ~7 short_grass
setblock ~191 ~125 ~8 short_grass
setblock ~191 ~125 ~9 grass_block
setblock ~191 ~125 ~10 grass_block
setblock ~191 ~125 ~11 grass_block
setblock ~191 ~125 ~12 grass_block
setblock ~191 ~125 ~13 grass_block
setblock ~191 ~125 ~14 grass_block
setblock ~191 ~125 ~15 grass_block
setblock ~191 ~125 ~16 grass_block
setblock ~191 ~125 ~17 grass_block
setblock ~191 ~125 ~18 grass_block
setblock ~191 ~125 ~21 short_grass
setblock ~191 ~125 ~33 grass_block
setblock ~191 ~125 ~34 grass_block
setblock ~191 ~125 ~35 dirt
setblock ~191 ~125 ~36 dirt
setblock ~191 ~125 ~37 dirt
setblock ~191 ~125 ~38 dirt
setblock ~191 ~125 ~39 dirt
setblock ~191 ~125 ~40 dirt
setblock ~191 ~125 ~41 dirt
setblock ~191 ~125 ~42 dirt
setblock ~191 ~125 ~43 dirt
setblock ~191 ~125 ~44 dirt
setblock ~191 ~125 ~45 dirt
setblock ~191 ~125 ~46 dirt
setblock ~191 ~125 ~47 dirt
setblock ~191 ~125 ~48 dirt
setblock ~191 ~125 ~49 dirt
setblock ~191 ~125 ~50 dirt
setblock ~191 ~125 ~51 dirt
setblock ~191 ~125 ~52 dirt
setblock ~191 ~125 ~53 dirt
setblock ~191 ~125 ~54 dirt
setblock ~191 ~125 ~55 dirt
setblock ~191 ~125 ~56 dirt
setblock ~191 ~125 ~57 grass_block
setblock ~191 ~125 ~58 grass_block
setblock ~191 ~125 ~59 grass_block
setblock ~191 ~125 ~60 short_grass
setblock ~191 ~125 ~63 short_grass
setblock ~191 ~125 ~74 short_grass
setblock ~191 ~125 ~76 short_grass
setblock ~191 ~125 ~79 grass_block
setblock ~191 ~125 ~80 grass_block
setblock ~191 ~125 ~81 grass_block
setblock ~191 ~125 ~82 grass_block
setblock ~191 ~125 ~83 grass_block
setblock ~191 ~125 ~84 grass_block
setblock ~191 ~125 ~85 grass_block
setblock ~191 ~125 ~86 grass_block
setblock ~191 ~125 ~87 grass_block
setblock ~191 ~125 ~88 grass_block
setblock ~191 ~125 ~89 dirt
setblock ~191 ~125 ~90 dirt
setblock ~191 ~125 ~91 grass_block
setblock ~191 ~125 ~92 grass_block
setblock ~191 ~125 ~93 grass_block
setblock ~191 ~125 ~94 grass_block
setblock ~191 ~125 ~95 grass_block
setblock ~191 ~125 ~98 short_grass
setblock ~191 ~125 ~100 short_grass
setblock ~191 ~125 ~104 poppy
setblock ~191 ~125 ~111 short_grass
setblock ~191 ~125 ~112 fern
setblock ~191 ~125 ~116 fern
setblock ~191 ~125 ~118 poppy
setblock ~191 ~125 ~142 short_grass
setblock ~191 ~125 ~144 poppy
setblock ~191 ~125 ~146 grass_block
setblock ~191 ~125 ~147 grass_block
setblock ~191 ~125 ~148 grass_block
setblock ~191 ~125 ~149 dirt
setblock ~191 ~125 ~150 dirt
setblock ~191 ~125 ~151 dirt
setblock ~191 ~125 ~152 grass_block
setblock ~191 ~125 ~153 grass_block
setblock ~191 ~125 ~154 grass_block
setblock ~191 ~125 ~165 short_grass
setblock ~191 ~125 ~167 grass_block
setblock ~191 ~125 ~168 grass_block
setblock ~191 ~125 ~169 grass_block
setblock ~191 ~125 ~170 dirt
setblock ~191 ~125 ~171 dirt
setblock ~191 ~125 ~172 dirt
setblock ~191 ~125 ~173 dirt
setblock ~191 ~125 ~174 dirt
setblock ~191 ~125 ~175 dirt
setblock ~191 ~125 ~176 dirt
setblock ~191 ~125 ~177 dirt
setblock ~191 ~125 ~178 dirt
setblock ~191 ~125 ~179 dirt
setblock ~191 ~125 ~180 dirt
setblock ~191 ~125 ~181 dirt
setblock ~191 ~125 ~182 dirt
setblock ~191 ~125 ~183 dirt
setblock ~191 ~125 ~184 dirt
setblock ~191 ~125 ~185 grass_block
setblock ~191 ~125 ~186 grass_block
setblock ~191 ~125 ~187 grass_block
setblock ~191 ~125 ~188 fern
setblock ~191 ~125 ~189 fern
setblock ~191 ~125 ~192 grass_block
setblock ~191 ~125 ~193 grass_block
setblock ~191 ~125 ~194 dirt
setblock ~191 ~125 ~195 dirt
setblock ~191 ~125 ~196 dirt
setblock ~191 ~125 ~197 dirt
setblock ~191 ~125 ~198 dirt
setblock ~191 ~125 ~199 dirt
setblock ~191 ~126 ~18 short_grass
setblock ~191 ~126 ~34 short_grass
setblock ~191 ~126 ~35 grass_block
setblock ~191 ~126 ~36 dirt
setblock ~191 ~126 ~37 dirt
setblock ~191 ~126 ~38 dirt
setblock ~191 ~126 ~39 dirt
setblock ~191 ~126 ~40 dirt
setblock ~191 ~126 ~41 dirt
setblock ~191 ~126 ~42 dirt
setblock ~191 ~126 ~43 dirt
setblock ~191 ~126 ~44 dirt
setblock ~191 ~126 ~45 dirt
setblock ~191 ~126 ~46 dirt
setblock ~191 ~126 ~47 dirt
setblock ~191 ~126 ~48 dirt
setblock ~191 ~126 ~49 dirt
setblock ~191 ~126 ~50 dirt
setblock ~191 ~126 ~51 dirt
setblock ~191 ~126 ~52 grass_block
setblock ~191 ~126 ~53 grass_block
setblock ~191 ~126 ~54 grass_block
setblock ~191 ~126 ~55 grass_block
setblock ~191 ~126 ~56 grass_block
setblock ~191 ~126 ~58 short_grass
setblock ~191 ~126 ~79 short_grass
setblock ~191 ~126 ~87 short_grass
setblock ~191 ~126 ~89 grass_block
setblock ~191 ~126 ~90 grass_block
setblock ~191 ~126 ~91 short_grass
setblock ~191 ~126 ~93 short_grass
setblock ~191 ~126 ~146 short_grass
setblock ~191 ~126 ~147 short_grass
setblock ~191 ~126 ~149 grass_block
setblock ~191 ~126 ~150 grass_block
setblock ~191 ~126 ~151 grass_block
setblock ~191 ~126 ~153 short_grass
setblock ~191 ~126 ~154 short_grass
setblock ~191 ~126 ~168 short_grass
setblock ~191 ~126 ~170 grass_block
setblock ~191 ~126 ~171 grass_block
setblock ~191 ~126 ~172 grass_block
setblock ~191 ~126 ~173 grass_block
setblock ~191 ~126 ~174 grass_block
setblock ~191 ~126 ~175 grass_block
setblock ~191 ~126 ~176 grass_block
setblock ~191 ~126 ~177 grass_block
setblock ~191 ~126 ~178 grass_block
setblock ~191 ~126 ~179 grass_block
setblock ~191 ~126 ~180 grass_block
setblock ~191 ~126 ~181 grass_block
setblock ~191 ~126 ~182 grass_block
setblock ~191 ~126 ~183 grass_block
setblock ~191 ~126 ~184 grass_block
setblock ~191 ~126 ~192 fern
setblock ~191 ~126 ~194 grass_block
setblock ~191 ~126 ~195 grass_block
setblock ~191 ~126 ~196 grass_block
setblock ~191 ~126 ~197 dirt
setblock ~191 ~126 ~198 dirt
setblock ~191 ~126 ~199 dirt
setblock ~191 ~127 ~35 poppy
setblock ~191 ~127 ~36 grass_block
setblock ~191 ~127 ~37 grass_block
setblock ~191 ~127 ~38 dirt
setblock ~191 ~127 ~39 dirt
setblock ~191 ~127 ~40 dirt
setblock ~191 ~127 ~41 dirt
setblock ~191 ~127 ~42 dirt
setblock ~191 ~127 ~43 dirt
setblock ~191 ~127 ~44 dirt
setblock ~191 ~127 ~45 dirt
setblock ~191 ~127 ~46 dirt
setblock ~191 ~127 ~47 dirt
setblock ~191 ~127 ~48 grass_block
setblock ~191 ~127 ~49 grass_block
setblock ~191 ~127 ~50 grass_block
setblock ~191 ~127 ~51 grass_block
setblock ~191 ~127 ~55 short_grass
setblock ~191 ~127 ~89 short_grass
setblock ~191 ~127 ~150 fern
setblock ~191 ~127 ~172 short_grass
setblock ~191 ~127 ~174 short_grass
setblock ~191 ~127 ~175 short_grass
setblock ~191 ~127 ~179 short_grass
setblock ~191 ~127 ~181 short_grass
setblock ~191 ~127 ~182 short_grass
setblock ~191 ~127 ~195 poppy
setblock ~191 ~127 ~197 grass_block
setblock ~191 ~127 ~198 grass_block
setblock ~191 ~127 ~199 grass_block
setblock ~191 ~128 ~36 short_grass
setblock ~191 ~128 ~38 grass_block
setblock ~191 ~128 ~39 dirt
setblock ~191 ~128 ~40 dirt
setblock ~191 ~128 ~41 dirt
setblock ~191 ~128 ~42 dirt
setblock ~191 ~128 ~43 dirt
setblock ~191 ~128 ~44 grass_block
setblock ~191 ~128 ~45 grass_block
setblock ~191 ~128 ~46 grass_block
setblock ~191 ~128 ~47 grass_block
setblock ~191 ~128 ~48 short_grass
setblock ~191 ~128 ~50 short_grass
setblock ~191 ~128 ~199 fern
setblock ~191 ~129 ~39 grass_block
setblock ~191 ~129 ~40 dirt
setblock ~191 ~129 ~41 dirt
setblock ~191 ~129 ~42 grass_block
setblock ~191 ~129 ~43 grass_block
setblock ~191 ~129 ~46 short_grass
setblock ~191 ~130 ~40 grass_block
setblock ~191 ~130 ~41 grass_block
setblock ~191 ~131 ~40 short_grass
setblock ~191 ~131 ~41 short_grass
setblock ~192 ~122 ~0 dirt
setblock ~192 ~122 ~1 dirt
setblock ~192 ~122 ~2 dirt
setblock ~192 ~122 ~3 dirt
setblock ~192 ~122 ~4 dirt
setblock ~192 ~122 ~5 dirt
setblock ~192 ~122 ~6 dirt
setblock ~192 ~122 ~7 dirt
setblock ~192 ~122 ~8 dirt
setblock ~192 ~122 ~9 dirt
setblock ~192 ~122 ~10 dirt
setblock ~192 ~122 ~11 dirt
setblock ~192 ~122 ~12 dirt
setblock ~192 ~122 ~13 dirt
setblock ~192 ~122 ~14 dirt
setblock ~192 ~122 ~15 dirt
setblock ~192 ~122 ~16 dirt
setblock ~192 ~122 ~17 dirt
setblock ~192 ~122 ~18 dirt
setblock ~192 ~122 ~19 dirt
setblock ~192 ~122 ~20 dirt
setblock ~192 ~122 ~21 dirt
setblock ~192 ~122 ~22 dirt
setblock ~192 ~122 ~23 dirt
setblock ~192 ~122 ~24 dirt
setblock ~192 ~122 ~25 dirt
setblock ~192 ~122 ~26 dirt
setblock ~192 ~122 ~27 dirt
setblock ~192 ~122 ~28 dirt
setblock ~192 ~122 ~29 dirt
setblock ~192 ~122 ~30 dirt
setblock ~192 ~122 ~31 dirt
setblock ~192 ~122 ~32 dirt
setblock ~192 ~122 ~33 dirt
setblock ~192 ~122 ~34 dirt
setblock ~192 ~122 ~35 dirt
setblock ~192 ~122 ~36 dirt
setblock ~192 ~122 ~37 dirt
setblock ~192 ~122 ~38 dirt
setblock ~192 ~122 ~39 dirt
setblock ~192 ~122 ~40 dirt
setblock ~192 ~122 ~41 dirt
setblock ~192 ~122 ~42 dirt
setblock ~192 ~122 ~43 dirt
setblock ~192 ~122 ~44 dirt
setblock ~192 ~122 ~45 dirt
setblock ~192 ~122 ~46 dirt
setblock ~192 ~122 ~47 dirt
setblock ~192 ~122 ~48 dirt
setblock ~192 ~122 ~49 dirt
setblock ~192 ~122 ~50 dirt
setblock ~192 ~122 ~51 dirt
setblock ~192 ~122 ~52 dirt
setblock ~192 ~122 ~53 dirt
setblock ~192 ~122 ~54 dirt
setblock ~192 ~122 ~55 dirt
setblock ~192 ~122 ~56 dirt
setblock ~192 ~122 ~57 dirt
setblock ~192 ~122 ~58 dirt
setblock ~192 ~122 ~59 dirt
setblock ~192 ~122 ~60 dirt
setblock ~192 ~122 ~61 dirt
setblock ~192 ~122 ~62 dirt
setblock ~192 ~122 ~63 dirt
setblock ~192 ~122 ~64 dirt
setblock ~192 ~122 ~65 dirt
setblock ~192 ~122 ~66 dirt
setblock ~192 ~122 ~67 dirt
setblock ~192 ~122 ~68 dirt
setblock ~192 ~122 ~69 grass_block
setblock ~192 ~122 ~70 grass_block
setblock ~192 ~122 ~71 dirt
setblock ~192 ~122 ~72 dirt
setblock ~192 ~122 ~73 dirt
setblock ~192 ~122 ~74 dirt
setblock ~192 ~122 ~75 dirt
setblock ~192 ~122 ~76 dirt
setblock ~192 ~122 ~77 dirt
setblock ~192 ~122 ~78 dirt
setblock ~192 ~122 ~79 dirt
setblock ~192 ~122 ~80 dirt
setblock ~192 ~122 ~81 dirt
setblock ~192 ~122 ~82 dirt
setblock ~192 ~122 ~83 dirt
setblock ~192 ~122 ~84 dirt
setblock ~192 ~122 ~85 dirt
setblock ~192 ~122 ~86 dirt
setblock ~192 ~122 ~87 dirt
setblock ~192 ~122 ~88 dirt
setblock ~192 ~122 ~89 dirt
setblock ~192 ~122 ~90 dirt
setblock ~192 ~122 ~91 dirt
setblock ~192 ~122 ~92 dirt
setblock ~192 ~122 ~93 dirt
setblock ~192 ~122 ~94 dirt
setblock ~192 ~122 ~95 dirt
setblock ~192 ~122 ~96 dirt
setblock ~192 ~122 ~97 dirt
setblock ~192 ~122 ~98 dirt
setblock ~192 ~122 ~99 dirt
setblock ~192 ~122 ~100 dirt
setblock ~192 ~122 ~101 dirt
setblock ~192 ~122 ~102 dirt
setblock ~192 ~122 ~103 dirt
setblock ~192 ~122 ~104 dirt
setblock ~192 ~122 ~105 dirt
setblock ~192 ~122 ~106 dirt
setblock ~192 ~122 ~107 dirt
setblock ~192 ~122 ~108 dirt
setblock ~192 ~122 ~109 dirt
setblock ~192 ~122 ~110 dirt
setblock ~192 ~122 ~111 dirt
setblock ~192 ~122 ~112 dirt
setblock ~192 ~122 ~113 dirt
setblock ~192 ~122 ~114 dirt
setblock ~192 ~122 ~115 dirt
setblock ~192 ~122 ~116 dirt
setblock ~192 ~122 ~117 dirt
setblock ~192 ~122 ~118 dirt
setblock ~192 ~122 ~119 dirt
setblock ~192 ~122 ~120 dirt
setblock ~192 ~122 ~121 dirt
setblock ~192 ~122 ~122 dirt
setblock ~192 ~122 ~123 dirt
setblock ~192 ~122 ~124 dirt
setblock ~192 ~122 ~125 dirt
setblock ~192 ~122 ~126 dirt
setblock ~192 ~122 ~127 dirt
setblock ~192 ~122 ~128 dirt
setblock ~192 ~122 ~129 dirt
setblock ~192 ~122 ~130 dirt
setblock ~192 ~122 ~131 dirt
setblock ~192 ~122 ~132 dirt
setblock ~192 ~122 ~133 dirt
setblock ~192 ~122 ~134 dirt
setblock ~192 ~122 ~135 dirt
setblock ~192 ~122 ~136 dirt
setblock ~192 ~122 ~137 dirt
setblock ~192 ~122 ~138 dirt
setblock ~192 ~122 ~139 dirt
setblock ~192 ~122 ~140 dirt
setblock ~192 ~122 ~141 dirt
setblock ~192 ~122 ~142 dirt
setblock ~192 ~122 ~143 dirt
setblock ~192 ~122 ~144 dirt
setblock ~192 ~122 ~145 dirt
setblock ~192 ~122 ~146 dirt
setblock ~192 ~122 ~147 dirt
setblock ~192 ~122 ~148 dirt
setblock ~192 ~122 ~149 dirt
setblock ~192 ~122 ~150 dirt
setblock ~192 ~122 ~151 dirt
setblock ~192 ~122 ~152 dirt
setblock ~192 ~122 ~153 dirt
setblock ~192 ~122 ~154 dirt
setblock ~192 ~122 ~155 dirt
setblock ~192 ~122 ~156 dirt
setblock ~192 ~122 ~157 dirt
setblock ~192 ~122 ~158 dirt
setblock ~192 ~122 ~159 dirt
setblock ~192 ~122 ~160 dirt
setblock ~192 ~122 ~161 dirt
setblock ~192 ~122 ~162 dirt
setblock ~192 ~122 ~163 dirt
setblock ~192 ~122 ~164 dirt
setblock ~192 ~122 ~165 dirt
setblock ~192 ~122 ~166 dirt
setblock ~192 ~122 ~167 dirt
setblock ~192 ~122 ~168 dirt
setblock ~192 ~122 ~169 dirt
setblock ~192 ~122 ~170 dirt
setblock ~192 ~122 ~171 dirt
setblock ~192 ~122 ~172 dirt
setblock ~192 ~122 ~173 dirt
setblock ~192 ~122 ~174 dirt
setblock ~192 ~122 ~175 dirt
setblock ~192 ~122 ~176 dirt
setblock ~192 ~122 ~177 dirt
setblock ~192 ~122 ~178 dirt
setblock ~192 ~122 ~179 dirt
setblock ~192 ~122 ~180 dirt
setblock ~192 ~122 ~181 dirt
setblock ~192 ~122 ~182 dirt
setblock ~192 ~122 ~183 dirt
setblock ~192 ~122 ~184 dirt
setblock ~192 ~122 ~185 dirt
setblock ~192 ~122 ~186 dirt
setblock ~192 ~122 ~187 dirt
setblock ~192 ~122 ~188 dirt
setblock ~192 ~122 ~189 dirt
setblock ~192 ~122 ~190 dirt
setblock ~192 ~122 ~191 dirt
setblock ~192 ~122 ~192 dirt
setblock ~192 ~122 ~193 dirt
setblock ~192 ~122 ~194 dirt
setblock ~192 ~122 ~195 dirt
setblock ~192 ~122 ~196 dirt
setblock ~192 ~122 ~197 dirt
setblock ~192 ~122 ~198 dirt
setblock ~192 ~122 ~199 dirt
setblock ~192 ~123 ~0 grass_block
setblock ~192 ~123 ~1 dirt
setblock ~192 ~123 ~2 dirt
setblock ~192 ~123 ~3 dirt
setblock ~192 ~123 ~4 dirt
setblock ~192 ~123 ~5 dirt
setblock ~192 ~123 ~6 dirt
setblock ~192 ~123 ~7 dirt
setblock ~192 ~123 ~8 dirt
setblock ~192 ~123 ~9 dirt
setblock ~192 ~123 ~10 dirt
setblock ~192 ~123 ~11 dirt
setblock ~192 ~123 ~12 dirt
setblock ~192 ~123 ~13 dirt
setblock ~192 ~123 ~14 dirt
setblock ~192 ~123 ~15 dirt
setblock ~192 ~123 ~16 dirt
setblock ~192 ~123 ~17 dirt
setblock ~192 ~123 ~18 dirt
setblock ~192 ~123 ~19 dirt
setblock ~192 ~123 ~20 dirt
setblock ~192 ~123 ~21 dirt
setblock ~192 ~123 ~22 dirt
setblock ~192 ~123 ~23 dirt
setblock ~192 ~123 ~24 dirt
setblock ~192 ~123 ~25 dirt
setblock ~192 ~123 ~26 dirt
setblock ~192 ~123 ~27 dirt
setblock ~192 ~123 ~28 dirt
setblock ~192 ~123 ~29 dirt
setblock ~192 ~123 ~30 dirt
setblock ~192 ~123 ~31 dirt
setblock ~192 ~123 ~32 dirt
setblock ~192 ~123 ~33 dirt
setblock ~192 ~123 ~34 dirt
setblock ~192 ~123 ~35 dirt
setblock ~192 ~123 ~36 dirt
setblock ~192 ~123 ~37 dirt
setblock ~192 ~123 ~38 dirt
setblock ~192 ~123 ~39 dirt
setblock ~192 ~123 ~40 dirt
setblock ~192 ~123 ~41 dirt
setblock ~192 ~123 ~42 dirt
setblock ~192 ~123 ~43 dirt
setblock ~192 ~123 ~44 dirt
setblock ~192 ~123 ~45 dirt
setblock ~192 ~123 ~46 dirt
setblock ~192 ~123 ~47 dirt
setblock ~192 ~123 ~48 dirt
setblock ~192 ~123 ~49 dirt
setblock ~192 ~123 ~50 dirt
setblock ~192 ~123 ~51 dirt
setblock ~192 ~123 ~52 dirt
setblock ~192 ~123 ~53 dirt
setblock ~192 ~123 ~54 dirt
setblock ~192 ~123 ~55 dirt
setblock ~192 ~123 ~56 dirt
setblock ~192 ~123 ~57 dirt
setblock ~192 ~123 ~58 dirt
setblock ~192 ~123 ~59 dirt
setblock ~192 ~123 ~60 dirt
setblock ~192 ~123 ~61 dirt
setblock ~192 ~123 ~62 dirt
setblock ~192 ~123 ~63 dirt
setblock ~192 ~123 ~64 grass_block
setblock ~192 ~123 ~65 grass_block
setblock ~192 ~123 ~66 grass_block
setblock ~192 ~123 ~67 grass_block
setblock ~192 ~123 ~68 grass_block
setblock ~192 ~123 ~69 short_grass
setblock ~192 ~123 ~70 poppy
setblock ~192 ~123 ~71 grass_block
setblock ~192 ~123 ~72 grass_block
setblock ~192 ~123 ~73 grass_block
setblock ~192 ~123 ~74 dirt
setblock ~192 ~123 ~75 dirt
setblock ~192 ~123 ~76 dirt
setblock ~192 ~123 ~77 dirt
setblock ~192 ~123 ~78 dirt
setblock ~192 ~123 ~79 dirt
setblock ~192 ~123 ~80 dirt
setblock ~192 ~123 ~81 dirt
setblock ~192 ~123 ~82 dirt
setblock ~192 ~123 ~83 dirt
setblock ~192 ~123 ~84 dirt
setblock ~192 ~123 ~85 dirt
setblock ~192 ~123 ~86 dirt
setblock ~192 ~123 ~87 dirt
setblock ~192 ~123 ~88 dirt
setblock ~192 ~123 ~89 dirt
setblock ~192 ~123 ~90 dirt
setblock ~192 ~123 ~91 dirt
setblock ~192 ~123 ~92 dirt
setblock ~192 ~123 ~93 dirt
setblock ~192 ~123 ~94 dirt
setblock ~192 ~123 ~95 dirt
setblock ~192 ~123 ~96 dirt
setblock ~192 ~123 ~97 dirt
setblock ~192 ~123 ~98 dirt
setblock ~192 ~123 ~99 dirt
setblock ~192 ~123 ~100 dirt
setblock ~192 ~123 ~101 dirt
setblock ~192 ~123 ~102 dirt
setblock ~192 ~123 ~103 dirt
setblock ~192 ~123 ~104 dirt
setblock ~192 ~123 ~105 dirt
setblock ~192 ~123 ~106 dirt
setblock ~192 ~123 ~107 dirt
setblock ~192 ~123 ~108 dirt
setblock ~192 ~123 ~109 dirt
setblock ~192 ~123 ~110 dirt
setblock ~192 ~123 ~111 dirt
setblock ~192 ~123 ~112 dirt
setblock ~192 ~123 ~113 dirt
setblock ~192 ~123 ~114 dirt
setblock ~192 ~123 ~115 dirt
setblock ~192 ~123 ~116 dirt
setblock ~192 ~123 ~117 dirt
setblock ~192 ~123 ~118 dirt
setblock ~192 ~123 ~119 dirt
setblock ~192 ~123 ~120 dirt
setblock ~192 ~123 ~121 dirt
setblock ~192 ~123 ~122 dirt
setblock ~192 ~123 ~123 dirt
setblock ~192 ~123 ~124 dirt
setblock ~192 ~123 ~125 dirt
setblock ~192 ~123 ~126 grass_block
setblock ~192 ~123 ~127 grass_block
setblock ~192 ~123 ~128 grass_block
setblock ~192 ~123 ~129 grass_block
setblock ~192 ~123 ~130 grass_block
setblock ~192 ~123 ~131 grass_block
setblock ~192 ~123 ~132 grass_block
setblock ~192 ~123 ~133 grass_block
setblock ~192 ~123 ~134 grass_block
setblock ~192 ~123 ~135 grass_block
setblock ~192 ~123 ~136 grass_block
setblock ~192 ~123 ~137 grass_block
setblock ~192 ~123 ~138 grass_block
setblock ~192 ~123 ~139 grass_block
setblock ~192 ~123 ~140 grass_block
setblock ~192 ~123 ~141 grass_block
setblock ~192 ~123 ~142 dirt
setblock ~192 ~123 ~143 dirt
setblock ~192 ~123 ~144 dirt
setblock ~192 ~123 ~145 dirt
setblock ~192 ~123 ~146 dirt
setblock ~192 ~123 ~147 dirt
setblock ~192 ~123 ~148 dirt
setblock ~192 ~123 ~149 dirt
setblock ~192 ~123 ~150 dirt
setblock ~192 ~123 ~151 dirt
setblock ~192 ~123 ~152 dirt
setblock ~192 ~123 ~153 dirt
setblock ~192 ~123 ~154 dirt
setblock ~192 ~123 ~155 dirt
setblock ~192 ~123 ~156 dirt
setblock ~192 ~123 ~157 dirt
setblock ~192 ~123 ~158 grass_block
setblock ~192 ~123 ~159 grass_block
setblock ~192 ~123 ~160 grass_block
setblock ~192 ~123 ~161 grass_block
setblock ~192 ~123 ~162 grass_block
setblock ~192 ~123 ~163 dirt
setblock ~192 ~123 ~164 dirt
setblock ~192 ~123 ~165 dirt
setblock ~192 ~123 ~166 dirt
setblock ~192 ~123 ~167 dirt
setblock ~192 ~123 ~168 dirt
setblock ~192 ~123 ~169 dirt
setblock ~192 ~123 ~170 dirt
setblock ~192 ~123 ~171 dirt
setblock ~192 ~123 ~172 dirt
setblock ~192 ~123 ~173 dirt
setblock ~192 ~123 ~174 dirt
setblock ~192 ~123 ~175 dirt
setblock ~192 ~123 ~176 dirt
setblock ~192 ~123 ~177 dirt
setblock ~192 ~123 ~178 dirt
setblock ~192 ~123 ~179 dirt
setblock ~192 ~123 ~180 dirt
setblock ~192 ~123 ~181 dirt
setblock ~192 ~123 ~182 dirt
setblock ~192 ~123 ~183 dirt
setblock ~192 ~123 ~184 dirt
setblock ~192 ~123 ~185 dirt
setblock ~192 ~123 ~186 dirt
setblock ~192 ~123 ~187 dirt
setblock ~192 ~123 ~188 dirt
setblock ~192 ~123 ~189 dirt
setblock ~192 ~123 ~190 dirt
setblock ~192 ~123 ~191 dirt
setblock ~192 ~123 ~192 dirt
setblock ~192 ~123 ~193 dirt
setblock ~192 ~123 ~194 dirt
setblock ~192 ~123 ~195 dirt
setblock ~192 ~123 ~196 dirt
setblock ~192 ~123 ~197 dirt
setblock ~192 ~123 ~198 dirt
setblock ~192 ~123 ~199 dirt
setblock ~192 ~124 ~1 grass_block
setblock ~192 ~124 ~2 grass_block
setblock ~192 ~124 ~3 grass_block
setblock ~192 ~124 ~4 grass_block
setblock ~192 ~124 ~5 grass_block
setblock ~192 ~124 ~6 grass_block
setblock ~192 ~124 ~7 grass_block
setblock ~192 ~124 ~8 grass_block
setblock ~192 ~124 ~9 dirt
setblock ~192 ~124 ~10 dirt
setblock ~192 ~124 ~11 dirt
setblock ~192 ~124 ~12 dirt
setblock ~192 ~124 ~13 dirt
setblock ~192 ~124 ~14 dirt
setblock ~192 ~124 ~15 dirt
setblock ~192 ~124 ~16 dirt
setblock ~192 ~124 ~17 dirt
setblock ~192 ~124 ~18 dirt
setblock ~192 ~124 ~19 grass_block
setblock ~192 ~124 ~20 grass_block
setblock ~192 ~124 ~21 grass_block
setblock ~192 ~124 ~22 grass_block
setblock ~192 ~124 ~23 grass_block
setblock ~192 ~124 ~24 grass_block
setblock ~192 ~124 ~25 grass_block
setblock ~192 ~124 ~26 grass_block
setblock ~192 ~124 ~27 grass_block
setblock ~192 ~124 ~28 grass_block
setblock ~192 ~124 ~29 grass_block
setblock ~192 ~124 ~30 grass_block
setblock ~192 ~124 ~31 grass_block
setblock ~192 ~124 ~32 dirt
setblock ~192 ~124 ~33 dirt
setblock ~192 ~124 ~34 dirt
setblock ~192 ~124 ~35 dirt
setblock ~192 ~124 ~36 dirt
setblock ~192 ~124 ~37 dirt
setblock ~192 ~124 ~38 dirt
setblock ~192 ~124 ~39 dirt
setblock ~192 ~124 ~40 dirt
setblock ~192 ~124 ~41 dirt
setblock ~192 ~124 ~42 dirt
setblock ~192 ~124 ~43 dirt
setblock ~192 ~124 ~44 dirt
setblock ~192 ~124 ~45 dirt
setblock ~192 ~124 ~46 dirt
setblock ~192 ~124 ~47 dirt
setblock ~192 ~124 ~48 dirt
setblock ~192 ~124 ~49 dirt
setblock ~192 ~124 ~50 dirt
setblock ~192 ~124 ~51 dirt
setblock ~192 ~124 ~52 dirt
setblock ~192 ~124 ~53 dirt
setblock ~192 ~124 ~54 dirt
setblock ~192 ~124 ~55 dirt
setblock ~192 ~124 ~56 dirt
setblock ~192 ~124 ~57 dirt
setblock ~192 ~124 ~58 dirt
setblock ~192 ~124 ~59 grass_block
setblock ~192 ~124 ~60 grass_block
setblock ~192 ~124 ~61 grass_block
setblock ~192 ~124 ~62 grass_block
setblock ~192 ~124 ~63 grass_block
setblock ~192 ~124 ~64 short_grass
setblock ~192 ~124 ~74 grass_block
setblock ~192 ~124 ~75 grass_block
setblock ~192 ~124 ~76 grass_block
setblock ~192 ~124 ~77 grass_block
setblock ~192 ~124 ~78 grass_block
setblock ~192 ~124 ~79 grass_block
setblock ~192 ~124 ~80 grass_block
setblock ~192 ~124 ~81 dirt
setblock ~192 ~124 ~82 dirt
setblock ~192 ~124 ~83 dirt
setblock ~192 ~124 ~84 dirt
setblock ~192 ~124 ~85 dirt
setblock ~192 ~124 ~86 dirt
setblock ~192 ~124 ~87 dirt
setblock ~192 ~124 ~88 dirt
setblock ~192 ~124 ~89 dirt
setblock ~192 ~124 ~90 dirt
setblock ~192 ~124 ~91 dirt
setblock ~192 ~124 ~92 dirt
setblock ~192 ~124 ~93 dirt
setblock ~192 ~124 ~94 dirt
setblock ~192 ~124 ~95 dirt
setblock ~192 ~124 ~96 grass_block
setblock ~192 ~124 ~97 grass_block
setblock ~192 ~124 ~98 grass_block
setblock ~192 ~124 ~99 grass_block
setblock ~192 ~124 ~100 grass_block
setblock ~192 ~124 ~101 grass_block
setblock ~192 ~124 ~102 grass_block
setblock ~192 ~124 ~103 grass_block
setblock ~192 ~124 ~104 grass_block
setblock ~192 ~124 ~105 grass_block
setblock ~192 ~124 ~106 grass_block
setblock ~192 ~124 ~107 grass_block
setblock ~192 ~124 ~108 grass_block
setblock ~192 ~124 ~109 grass_block
setblock ~192 ~124 ~110 grass_block
setblock ~192 ~124 ~111 grass_block
setblock ~192 ~124 ~112 grass_block
setblock ~192 ~124 ~113 grass_block
setblock ~192 ~124 ~114 grass_block
setblock ~192 ~124 ~115 grass_block
setblock ~192 ~124 ~116 grass_block
setblock ~192 ~124 ~117 grass_block
setblock ~192 ~124 ~118 grass_block
setblock ~192 ~124 ~119 grass_block
setblock ~192 ~124 ~120 grass_block
setblock ~192 ~124 ~121 grass_block
setblock ~192 ~124 ~122 grass_block
setblock ~192 ~124 ~123 grass_block
setblock ~192 ~124 ~124 grass_block
setblock ~192 ~124 ~125 grass_block
setblock ~192 ~124 ~128 short_grass
setblock ~192 ~124 ~129 short_grass
setblock ~192 ~124 ~132 fern
setblock ~192 ~124 ~142 grass_block
setblock ~192 ~124 ~143 grass_block
setblock ~192 ~124 ~144 grass_block
setblock ~192 ~124 ~145 grass_block
setblock ~192 ~124 ~146 dirt
setblock ~192 ~124 ~147 dirt
setblock ~192 ~124 ~148 dirt
setblock ~192 ~124 ~149 dirt
setblock ~192 ~124 ~150 dirt
setblock ~192 ~124 ~151 dirt
setblock ~192 ~124 ~152 dirt
setblock ~192 ~124 ~153 dirt
setblock ~192 ~124 ~154 dirt
setblock ~192 ~124 ~155 grass_block
setblock ~192 ~124 ~156 grass_block
setblock ~192 ~124 ~157 grass_block
setblock ~192 ~124 ~159 short_grass
setblock ~192 ~124 ~161 short_grass
setblock ~192 ~124 ~163 grass_block
setblock ~192 ~124 ~164 grass_block
setblock ~192 ~124 ~165 grass_block
setblock ~192 ~124 ~166 dirt
setblock ~192 ~124 ~167 dirt
setblock ~192 ~124 ~168 dirt
setblock ~192 ~124 ~169 dirt
setblock ~192 ~124 ~170 dirt
setblock ~192 ~124 ~171 dirt
setblock ~192 ~124 ~172 dirt
setblock ~192 ~124 ~173 dirt
setblock ~192 ~124 ~174 dirt
setblock ~192 ~124 ~175 dirt
setblock ~192 ~124 ~176 dirt
setblock ~192 ~124 ~177 dirt
setblock ~192 ~124 ~178 dirt
setblock ~192 ~124 ~179 dirt
setblock ~192 ~124 ~180 dirt
setblock ~192 ~124 ~181 dirt
setblock ~192 ~124 ~182 dirt
setblock ~192 ~124 ~183 dirt
setblock ~192 ~124 ~184 dirt
setblock ~192 ~124 ~185 dirt
setblock ~192 ~124 ~186 dirt
setblock ~192 ~124 ~187 dirt
setblock ~192 ~124 ~188 dirt
setblock ~192 ~124 ~189 grass_block
setblock ~192 ~124 ~190 grass_block
setblock ~192 ~124 ~191 dirt
setblock ~192 ~124 ~192 dirt
setblock ~192 ~124 ~193 dirt
setblock ~192 ~124 ~194 dirt
setblock ~192 ~124 ~195 dirt
setblock ~192 ~124 ~196 dirt
setblock ~192 ~124 ~197 dirt
setblock ~192 ~124 ~198 dirt
setblock ~192 ~124 ~199 dirt
setblock ~192 ~125 ~1 short_grass
setblock ~192 ~125 ~4 fern
setblock ~192 ~125 ~6 short_grass
setblock ~192 ~125 ~9 grass_block
setblock ~192 ~125 ~10 grass_block
setblock ~192 ~125 ~11 grass_block
setblock ~192 ~125 ~12 grass_block
setblock ~192 ~125 ~13 grass_block
setblock ~192 ~125 ~14 grass_block
setblock ~192 ~125 ~15 grass_block
setblock ~192 ~125 ~16 grass_block
setblock ~192 ~125 ~17 grass_block
setblock ~192 ~125 ~18 grass_block
setblock ~192 ~125 ~22 short_grass
setblock ~192 ~125 ~26 short_grass
setblock ~192 ~125 ~30 short_grass
setblock ~192 ~125 ~32 grass_block
setblock ~192 ~125 ~33 grass_block
setblock ~192 ~125 ~34 dirt
setblock ~192 ~125 ~35 dirt
setblock ~192 ~125 ~36 dirt
setblock ~192 ~125 ~37 dirt
setblock ~192 ~125 ~38 dirt
setblock ~192 ~125 ~39 dirt
setblock ~192 ~125 ~40 dirt
setblock ~192 ~125 ~41 dirt
setblock ~192 ~125 ~42 dirt
setblock ~192 ~125 ~43 dirt
setblock ~192 ~125 ~44 dirt
setblock ~192 ~125 ~45 dirt
setblock ~192 ~125 ~46 dirt
setblock ~192 ~125 ~47 dirt
setblock ~192 ~125 ~48 dirt
setblock ~192 ~125 ~49 dirt
setblock ~192 ~125 ~50 dirt
setblock ~192 ~125 ~51 dirt
setblock ~192 ~125 ~52 dirt
setblock ~192 ~125 ~53 dirt
setblock ~192 ~125 ~54 dirt
setblock ~192 ~125 ~55 dirt
setblock ~192 ~125 ~56 dirt
setblock ~192 ~125 ~57 grass_block
setblock ~192 ~125 ~58 grass_block
setblock ~192 ~125 ~74 short_grass
setblock ~192 ~125 ~78 short_grass
setblock ~192 ~125 ~80 short_grass
setblock ~192 ~125 ~81 grass_block
setblock ~192 ~125 ~82 grass_block
setblock ~192 ~125 ~83 grass_block
setblock ~192 ~125 ~84 grass_block
setblock ~192 ~125 ~85 grass_block
setblock ~192 ~125 ~86 grass_block
setblock ~192 ~125 ~87 grass_block
setblock ~192 ~125 ~88 grass_block
setblock ~192 ~125 ~89 grass_block
setblock ~192 ~125 ~90 grass_block
setblock ~192 ~125 ~91 grass_block
setblock ~192 ~125 ~92 grass_block
setblock ~192 ~125 ~93 grass_block
setblock ~192 ~125 ~94 grass_block
setblock ~192 ~125 ~95 grass_block
setblock ~192 ~125 ~97 short_grass
setblock ~192 ~125 ~100 short_grass
setblock ~192 ~125 ~101 short_grass
setblock ~192 ~125 ~107 short_grass
setblock ~192 ~125 ~112 short_grass
setblock ~192 ~125 ~114 short_grass
setblock ~192 ~125 ~117 poppy
setblock ~192 ~125 ~118 short_grass
setblock ~192 ~125 ~123 fern
setblock ~192 ~125 ~124 short_grass
setblock ~192 ~125 ~144 short_grass
setblock ~192 ~125 ~146 grass_block
setblock ~192 ~125 ~147 grass_block
setblock ~192 ~125 ~148 grass_block
setblock ~192 ~125 ~149 dirt
setblock ~192 ~125 ~150 dirt
setblock ~192 ~125 ~151 dirt
setblock ~192 ~125 ~152 grass_block
setblock ~192 ~125 ~153 grass_block
setblock ~192 ~125 ~154 grass_block
setblock ~192 ~125 ~163 fern
setblock ~192 ~125 ~164 short_grass
setblock ~192 ~125 ~166 grass_block
setblock ~192 ~125 ~167 grass_block
setblock ~192 ~125 ~168 grass_block
setblock ~192 ~125 ~169 grass_block
setblock ~192 ~125 ~170 dirt
setblock ~192 ~125 ~171 dirt
setblock ~192 ~125 ~172 dirt
setblock ~192 ~125 ~173 dirt
setblock ~192 ~125 ~174 dirt
setblock ~192 ~125 ~175 dirt
setblock ~192 ~125 ~176 dirt
setblock ~192 ~125 ~177 dirt
setblock ~192 ~125 ~178 dirt
setblock ~192 ~125 ~179 dirt
setblock ~192 ~125 ~180 dirt
setblock ~192 ~125 ~181 dirt
setblock ~192 ~125 ~182 dirt
setblock ~192 ~125 ~183 dirt
setblock ~192 ~125 ~184 dirt
setblock ~192 ~125 ~185 grass_block
setblock ~192 ~125 ~186 grass_block
setblock ~192 ~125 ~187 grass_block
setblock ~192 ~125 ~188 grass_block
setblock ~192 ~125 ~190 short_grass
setblock ~192 ~125 ~191 grass_block
setblock ~192 ~125 ~192 grass_block
setblock ~192 ~125 ~193 grass_block
setblock ~192 ~125 ~194 dirt
setblock ~192 ~125 ~195 dirt
setblock ~192 ~125 ~196 dirt
setblock ~192 ~125 ~197 dirt
setblock ~192 ~125 ~198 dirt
setblock ~192 ~125 ~199 dirt
setblock ~192 ~126 ~9 short_grass
setblock ~192 ~126 ~11 fern
setblock ~192 ~126 ~17 short_grass
setblock ~192 ~126 ~32 short_grass
setblock ~192 ~126 ~34 grass_block
setblock ~192 ~126 ~35 grass_block
setblock ~192 ~126 ~36 dirt
setblock ~192 ~126 ~37 dirt
setblock ~192 ~126 ~38 dirt
setblock ~192 ~126 ~39 dirt
setblock ~192 ~126 ~40 dirt
setblock ~192 ~126 ~41 dirt
setblock ~192 ~126 ~42 dirt
setblock ~192 ~126 ~43 dirt
setblock ~192 ~126 ~44 dirt
setblock ~192 ~126 ~45 dirt
setblock ~192 ~126 ~46 dirt
setblock ~192 ~126 ~47 dirt
setblock ~192 ~126 ~48 dirt
setblock ~192 ~126 ~49 dirt
setblock ~192 ~126 ~50 dirt
setblock ~192 ~126 ~51 dirt
setblock ~192 ~126 ~52 dirt
setblock ~192 ~126 ~53 grass_block
setblock ~192 ~126 ~54 grass_block
setblock ~192 ~126 ~55 grass_block
setblock ~192 ~126 ~56 grass_block
setblock ~192 ~126 ~58 short_grass
setblock ~192 ~126 ~81 short_grass
setblock ~192 ~126 ~84 short_grass
setblock ~192 ~126 ~86 short_grass
setblock ~192 ~126 ~87 short_grass
setblock ~192 ~126 ~95 short_grass
setblock ~192 ~126 ~147 short_grass
setblock ~192 ~126 ~149 grass_block
setblock ~192 ~126 ~150 grass_block
setblock ~192 ~126 ~151 grass_block
setblock ~192 ~126 ~152 short_grass
setblock ~192 ~126 ~170 grass_block
setblock ~192 ~126 ~171 grass_block
setblock ~192 ~126 ~172 grass_block
setblock ~192 ~126 ~173 grass_block
setblock ~192 ~126 ~174 grass_block
setblock ~192 ~126 ~175 grass_block
setblock ~192 ~126 ~176 grass_block
setblock ~192 ~126 ~177 grass_block
setblock ~192 ~126 ~178 grass_block
setblock ~192 ~126 ~179 grass_block
setblock ~192 ~126 ~180 grass_block
setblock ~192 ~126 ~181 grass_block
setblock ~192 ~126 ~182 grass_block
setblock ~192 ~126 ~183 grass_block
setblock ~192 ~126 ~184 grass_block
setblock ~192 ~126 ~185 short_grass
setblock ~192 ~126 ~187 short_grass
setblock ~192 ~126 ~188 short_grass
setblock ~192 ~126 ~193 short_grass
setblock ~192 ~126 ~194 grass_block
setblock ~192 ~126 ~195 grass_block
setblock ~192 ~126 ~196 grass_block
setblock ~192 ~126 ~197 grass_block
setblock ~192 ~126 ~198 dirt
setblock ~192 ~126 ~199 dirt
setblock ~192 ~127 ~36 grass_block
setblock ~192 ~127 ~37 grass_block
setblock ~192 ~127 ~38 dirt
setblock ~192 ~127 ~39 dirt
setblock ~192 ~127 ~40 dirt
setblock ~192 ~127 ~41 dirt
setblock ~192 ~127 ~42 dirt
setblock ~192 ~127 ~43 dirt
setblock ~192 ~127 ~44 dirt
setblock ~192 ~127 ~45 dirt
setblock ~192 ~127 ~46 dirt
setblock ~192 ~127 ~47 dirt
setblock ~192 ~127 ~48 dirt
setblock ~192 ~127 ~49 grass_block
setblock ~192 ~127 ~50 grass_block
setblock ~192 ~127 ~51 grass_block
setblock ~192 ~127 ~52 grass_block
setblock ~192 ~127 ~53 short_grass
setblock ~192 ~127 ~54 short_grass
setblock ~192 ~127 ~149 short_grass
setblock ~192 ~127 ~150 short_grass
setblock ~192 ~127 ~171 fern
setblock ~192 ~127 ~174 short_grass
setblock ~192 ~127 ~181 short_grass
setblock ~192 ~127 ~198 grass_block
setblock ~192 ~127 ~199 grass_block
setblock ~192 ~128 ~36 short_grass
setblock ~192 ~128 ~37 short_grass
setblock ~192 ~128 ~38 grass_block
setblock ~192 ~128 ~39 dirt
setblock ~192 ~128 ~40 dirt
setblock ~192 ~128 ~41 dirt
setblock ~192 ~128 ~42 dirt
setblock ~192 ~128 ~43 grass_block
setblock ~192 ~128 ~44 grass_block
setblock ~192 ~128 ~45 grass_block
setblock ~192 ~128 ~46 grass_block
setblock ~192 ~128 ~47 grass_block
setblock ~192 ~128 ~48 grass_block
setblock ~192 ~128 ~50 short_grass
setblock ~192 ~129 ~39 grass_block
setblock ~192 ~129 ~40 grass_block
setblock ~192 ~129 ~41 grass_block
setblock ~192 ~129 ~42 grass_block
setblock ~192 ~129 ~47 short_grass
setblock ~192 ~130 ~40 short_grass
setblock ~192 ~130 ~42 short_grass
setblock ~193 ~122 ~0 dirt
setblock ~193 ~122 ~1 dirt
setblock ~193 ~122 ~2 dirt
setblock ~193 ~122 ~3 dirt
setblock ~193 ~122 ~4 dirt
setblock ~193 ~122 ~5 dirt
setblock ~193 ~122 ~6 dirt
setblock ~193 ~122 ~7 dirt
setblock ~193 ~122 ~8 dirt
setblock ~193 ~122 ~9 dirt
setblock ~193 ~122 ~10 dirt
setblock ~193 ~122 ~11 dirt
setblock ~193 ~122 ~12 dirt
setblock ~193 ~122 ~13 dirt
setblock ~193 ~122 ~14 dirt
setblock ~193 ~122 ~15 dirt
setblock ~193 ~122 ~16 dirt
setblock ~193 ~122 ~17 dirt
setblock ~193 ~122 ~18 dirt
setblock ~193 ~122 ~19 dirt
setblock ~193 ~122 ~20 dirt
setblock ~193 ~122 ~21 dirt
setblock ~193 ~122 ~22 dirt
setblock ~193 ~122 ~23 dirt
setblock ~193 ~122 ~24 dirt
setblock ~193 ~122 ~25 dirt
setblock ~193 ~122 ~26 dirt
setblock ~193 ~122 ~27 dirt
setblock ~193 ~122 ~28 dirt
setblock ~193 ~122 ~29 dirt
setblock ~193 ~122 ~30 dirt
setblock ~193 ~122 ~31 dirt
setblock ~193 ~122 ~32 dirt
setblock ~193 ~122 ~33 dirt
setblock ~193 ~122 ~34 dirt
setblock ~193 ~122 ~35 dirt
setblock ~193 ~122 ~36 dirt
setblock ~193 ~122 ~37 dirt
setblock ~193 ~122 ~38 dirt
setblock ~193 ~122 ~39 dirt
setblock ~193 ~122 ~40 dirt
setblock ~193 ~122 ~41 dirt
setblock ~193 ~122 ~42 dirt
setblock ~193 ~122 ~43 dirt
setblock ~193 ~122 ~44 dirt
setblock ~193 ~122 ~45 dirt
setblock ~193 ~122 ~46 dirt
setblock ~193 ~122 ~47 dirt
setblock ~193 ~122 ~48 dirt
setblock ~193 ~122 ~49 dirt
setblock ~193 ~122 ~50 dirt
setblock ~193 ~122 ~51 dirt
setblock ~193 ~122 ~52 dirt
setblock ~193 ~122 ~53 dirt
setblock ~193 ~122 ~54 dirt
setblock ~193 ~122 ~55 dirt
setblock ~193 ~122 ~56 dirt
setblock ~193 ~122 ~57 dirt
setblock ~193 ~122 ~58 dirt
setblock ~193 ~122 ~59 dirt
setblock ~193 ~122 ~60 dirt
setblock ~193 ~122 ~61 dirt
setblock ~193 ~122 ~62 dirt
setblock ~193 ~122 ~63 dirt
setblock ~193 ~122 ~64 dirt
setblock ~193 ~122 ~65 dirt
setblock ~193 ~122 ~66 dirt
setblock ~193 ~122 ~67 dirt
setblock ~193 ~122 ~68 dirt
setblock ~193 ~122 ~69 dirt
setblock ~193 ~122 ~70 grass_block
setblock ~193 ~122 ~71 dirt
setblock ~193 ~122 ~72 dirt
setblock ~193 ~122 ~73 dirt
setblock ~193 ~122 ~74 dirt
setblock ~193 ~122 ~75 dirt
setblock ~193 ~122 ~76 dirt
setblock ~193 ~122 ~77 dirt
setblock ~193 ~122 ~78 dirt
setblock ~193 ~122 ~79 dirt
setblock ~193 ~122 ~80 dirt
setblock ~193 ~122 ~81 dirt
setblock ~193 ~122 ~82 dirt
setblock ~193 ~122 ~83 dirt
setblock ~193 ~122 ~84 dirt
setblock ~193 ~122 ~85 dirt
setblock ~193 ~122 ~86 dirt
setblock ~193 ~122 ~87 dirt
setblock ~193 ~122 ~88 dirt
setblock ~193 ~122 ~89 dirt
setblock ~193 ~122 ~90 dirt
setblock ~193 ~122 ~91 dirt
setblock ~193 ~122 ~92 dirt
setblock ~193 ~122 ~93 dirt
setblock ~193 ~122 ~94 dirt
setblock ~193 ~122 ~95 dirt
setblock ~193 ~122 ~96 dirt
setblock ~193 ~122 ~97 dirt
setblock ~193 ~122 ~98 dirt
setblock ~193 ~122 ~99 dirt
setblock ~193 ~122 ~100 dirt
setblock ~193 ~122 ~101 dirt
setblock ~193 ~122 ~102 dirt
setblock ~193 ~122 ~103 dirt
setblock ~193 ~122 ~104 dirt
setblock ~193 ~122 ~105 dirt
setblock ~193 ~122 ~106 dirt
setblock ~193 ~122 ~107 dirt
setblock ~193 ~122 ~108 dirt
setblock ~193 ~122 ~109 dirt
setblock ~193 ~122 ~110 dirt
setblock ~193 ~122 ~111 dirt
setblock ~193 ~122 ~112 dirt
setblock ~193 ~122 ~113 dirt
setblock ~193 ~122 ~114 dirt
setblock ~193 ~122 ~115 dirt
setblock ~193 ~122 ~116 dirt
setblock ~193 ~122 ~117 dirt
setblock ~193 ~122 ~118 dirt
setblock ~193 ~122 ~119 dirt
setblock ~193 ~122 ~120 dirt
setblock ~193 ~122 ~121 dirt
setblock ~193 ~122 ~122 dirt
setblock ~193 ~122 ~123 dirt
setblock ~193 ~122 ~124 dirt
setblock ~193 ~122 ~125 dirt
setblock ~193 ~122 ~126 dirt
setblock ~193 ~122 ~127 dirt
setblock ~193 ~122 ~128 dirt
setblock ~193 ~122 ~129 dirt
setblock ~193 ~122 ~130 dirt
setblock ~193 ~122 ~131 dirt
setblock ~193 ~122 ~132 dirt
setblock ~193 ~122 ~133 dirt
setblock ~193 ~122 ~134 dirt
setblock ~193 ~122 ~135 dirt
setblock ~193 ~122 ~136 dirt
setblock ~193 ~122 ~137 dirt
setblock ~193 ~122 ~138 dirt
setblock ~193 ~122 ~139 dirt
setblock ~193 ~122 ~140 dirt
setblock ~193 ~122 ~141 dirt
setblock ~193 ~122 ~142 dirt
setblock ~193 ~122 ~143 dirt
setblock ~193 ~122 ~144 dirt
setblock ~193 ~122 ~145 dirt
setblock ~193 ~122 ~146 dirt
setblock ~193 ~122 ~147 dirt
setblock ~193 ~122 ~148 dirt
setblock ~193 ~122 ~149 dirt
setblock ~193 ~122 ~150 dirt
setblock ~193 ~122 ~151 dirt
setblock ~193 ~122 ~152 dirt
setblock ~193 ~122 ~153 dirt
setblock ~193 ~122 ~154 dirt
setblock ~193 ~122 ~155 dirt
setblock ~193 ~122 ~156 dirt
setblock ~193 ~122 ~157 dirt
setblock ~193 ~122 ~158 dirt
setblock ~193 ~122 ~159 dirt
setblock ~193 ~122 ~160 dirt
setblock ~193 ~122 ~161 dirt
setblock ~193 ~122 ~162 dirt
setblock ~193 ~122 ~163 dirt
setblock ~193 ~122 ~164 dirt
setblock ~193 ~122 ~165 dirt
setblock ~193 ~122 ~166 dirt
setblock ~193 ~122 ~167 dirt
setblock ~193 ~122 ~168 dirt
setblock ~193 ~122 ~169 dirt
setblock ~193 ~122 ~170 dirt
setblock ~193 ~122 ~171 dirt
setblock ~193 ~122 ~172 dirt
setblock ~193 ~122 ~173 dirt
setblock ~193 ~122 ~174 dirt
setblock ~193 ~122 ~175 dirt
setblock ~193 ~122 ~176 dirt
setblock ~193 ~122 ~177 dirt
setblock ~193 ~122 ~178 dirt
setblock ~193 ~122 ~179 dirt
setblock ~193 ~122 ~180 dirt
setblock ~193 ~122 ~181 dirt
setblock ~193 ~122 ~182 dirt
setblock ~193 ~122 ~183 dirt
setblock ~193 ~122 ~184 dirt
setblock ~193 ~122 ~185 dirt
setblock ~193 ~122 ~186 dirt
setblock ~193 ~122 ~187 dirt
setblock ~193 ~122 ~188 dirt
setblock ~193 ~122 ~189 dirt
setblock ~193 ~122 ~190 dirt
setblock ~193 ~122 ~191 dirt
setblock ~193 ~122 ~192 dirt
setblock ~193 ~122 ~193 dirt
