setblock ~169 ~122 ~92 dirt
setblock ~169 ~122 ~93 dirt
setblock ~169 ~122 ~94 dirt
setblock ~169 ~122 ~95 dirt
setblock ~169 ~122 ~96 dirt
setblock ~169 ~122 ~97 dirt
setblock ~169 ~122 ~98 dirt
setblock ~169 ~122 ~99 dirt
setblock ~169 ~122 ~100 dirt
setblock ~169 ~122 ~101 dirt
setblock ~169 ~122 ~102 dirt
setblock ~169 ~122 ~103 dirt
setblock ~169 ~122 ~104 dirt
setblock ~169 ~122 ~105 dirt
setblock ~169 ~122 ~106 dirt
setblock ~169 ~122 ~107 dirt
setblock ~169 ~122 ~108 dirt
setblock ~169 ~122 ~109 dirt
setblock ~169 ~122 ~110 grass_block
setblock ~169 ~122 ~111 dirt
setblock ~169 ~122 ~112 dirt
setblock ~169 ~122 ~113 dirt
setblock ~169 ~122 ~114 dirt
setblock ~169 ~122 ~115 dirt
setblock ~169 ~122 ~116 dirt
setblock ~169 ~122 ~117 dirt
setblock ~169 ~123 ~62 dirt
setblock ~169 ~123 ~63 dirt
setblock ~169 ~123 ~64 dirt
setblock ~169 ~123 ~65 dirt
setblock ~169 ~123 ~66 dirt
setblock ~169 ~123 ~67 dirt
setblock ~169 ~123 ~68 dirt
setblock ~169 ~123 ~69 dirt
setblock ~169 ~123 ~70 dirt
setblock ~169 ~123 ~71 dirt
setblock ~169 ~123 ~72 dirt
setblock ~169 ~123 ~73 dirt
setblock ~169 ~123 ~74 dirt
setblock ~169 ~123 ~75 dirt
setblock ~169 ~123 ~76 dirt
setblock ~169 ~123 ~77 dirt
setblock ~169 ~123 ~78 dirt
setblock ~169 ~123 ~79 dirt
setblock ~169 ~123 ~80 dirt
setblock ~169 ~123 ~81 dirt
setblock ~169 ~123 ~82 dirt
setblock ~169 ~123 ~83 dirt
setblock ~169 ~123 ~84 dirt
setblock ~169 ~123 ~85 dirt
setblock ~169 ~123 ~86 dirt
setblock ~169 ~123 ~87 dirt
setblock ~169 ~123 ~88 dirt
setblock ~169 ~123 ~89 dirt
setblock ~169 ~123 ~90 dirt
setblock ~169 ~123 ~91 dirt
setblock ~169 ~123 ~92 dirt
setblock ~169 ~123 ~93 dirt
setblock ~169 ~123 ~94 dirt
setblock ~169 ~123 ~95 dirt
setblock ~169 ~123 ~96 dirt
setblock ~169 ~123 ~97 dirt
setblock ~169 ~123 ~98 dirt
setblock ~169 ~123 ~99 dirt
setblock ~169 ~123 ~100 dirt
setblock ~169 ~123 ~101 dirt
setblock ~169 ~123 ~102 dirt
setblock ~169 ~123 ~103 dirt
setblock ~169 ~123 ~104 dirt
setblock ~169 ~123 ~105 dirt
setblock ~169 ~123 ~106 dirt
setblock ~169 ~123 ~107 dirt
setblock ~169 ~123 ~108 grass_block
setblock ~169 ~123 ~109 grass_block
setblock ~169 ~123 ~111 grass_block
setblock ~169 ~123 ~112 grass_block
setblock ~169 ~123 ~113 dirt
setblock ~169 ~123 ~114 dirt
setblock ~169 ~123 ~115 dirt
setblock ~169 ~123 ~116 dirt
setblock ~169 ~123 ~117 dirt
setblock ~169 ~124 ~62 dirt
setblock ~169 ~124 ~63 dirt
setblock ~169 ~124 ~64 dirt
setblock ~169 ~124 ~65 dirt
setblock ~169 ~124 ~66 dirt
setblock ~169 ~124 ~67 dirt
setblock ~169 ~124 ~68 dirt
setblock ~169 ~124 ~69 dirt
setblock ~169 ~124 ~70 dirt
setblock ~169 ~124 ~71 dirt
setblock ~169 ~124 ~72 dirt
setblock ~169 ~124 ~73 dirt
setblock ~169 ~124 ~74 dirt
setblock ~169 ~124 ~75 dirt
setblock ~169 ~124 ~76 dirt
setblock ~169 ~124 ~77 dirt
setblock ~169 ~124 ~78 dirt
setblock ~169 ~124 ~79 dirt
setblock ~169 ~124 ~80 dirt
setblock ~169 ~124 ~81 dirt
setblock ~169 ~124 ~82 dirt
setblock ~169 ~124 ~83 dirt
setblock ~169 ~124 ~84 dirt
setblock ~169 ~124 ~85 dirt
setblock ~169 ~124 ~86 dirt
setblock ~169 ~124 ~87 dirt
setblock ~169 ~124 ~88 dirt
setblock ~169 ~124 ~89 dirt
setblock ~169 ~124 ~90 dirt
setblock ~169 ~124 ~91 dirt
setblock ~169 ~124 ~92 dirt
setblock ~169 ~124 ~93 dirt
setblock ~169 ~124 ~94 dirt
setblock ~169 ~124 ~95 dirt
setblock ~169 ~124 ~96 dirt
setblock ~169 ~124 ~97 dirt
setblock ~169 ~124 ~98 dirt
setblock ~169 ~124 ~99 dirt
setblock ~169 ~124 ~100 dirt
setblock ~169 ~124 ~101 dirt
setblock ~169 ~124 ~102 dirt
setblock ~169 ~124 ~103 dirt
setblock ~169 ~124 ~104 dirt
setblock ~169 ~124 ~105 dirt
setblock ~169 ~124 ~106 grass_block
setblock ~169 ~124 ~107 grass_block
setblock ~169 ~124 ~108 short_grass
setblock ~169 ~124 ~109 short_grass
setblock ~169 ~124 ~113 grass_block
setblock ~169 ~124 ~114 grass_block
setblock ~169 ~124 ~115 grass_block
setblock ~169 ~124 ~116 dirt
setblock ~169 ~124 ~117 dirt
setblock ~169 ~125 ~62 dirt
setblock ~169 ~125 ~63 dirt
setblock ~169 ~125 ~64 dirt
setblock ~169 ~125 ~65 dirt
setblock ~169 ~125 ~66 dirt
setblock ~169 ~125 ~67 grass_block
setblock ~169 ~125 ~68 grass_block
setblock ~169 ~125 ~69 grass_block
setblock ~169 ~125 ~70 grass_block
setblock ~169 ~125 ~71 grass_block
setblock ~169 ~125 ~72 grass_block
setblock ~169 ~125 ~73 grass_block
setblock ~169 ~125 ~74 grass_block
setblock ~169 ~125 ~75 grass_block
setblock ~169 ~125 ~76 grass_block
setblock ~169 ~125 ~77 grass_block
setblock ~169 ~125 ~78 grass_block
setblock ~169 ~125 ~79 grass_block
setblock ~169 ~125 ~80 grass_block
setblock ~169 ~125 ~81 grass_block
setblock ~169 ~125 ~82 grass_block
setblock ~169 ~125 ~83 grass_block
setblock ~169 ~125 ~84 grass_block
setblock ~169 ~125 ~85 grass_block
setblock ~169 ~125 ~86 grass_block
setblock ~169 ~125 ~87 grass_block
setblock ~169 ~125 ~88 grass_block
setblock ~169 ~125 ~89 grass_block
setblock ~169 ~125 ~90 grass_block
setblock ~169 ~125 ~91 grass_block
setblock ~169 ~125 ~92 grass_block
setblock ~169 ~125 ~93 grass_block
setblock ~169 ~125 ~94 dirt
setblock ~169 ~125 ~95 dirt
setblock ~169 ~125 ~96 dirt
setblock ~169 ~125 ~97 dirt
setblock ~169 ~125 ~98 dirt
setblock ~169 ~125 ~99 dirt
setblock ~169 ~125 ~100 dirt
setblock ~169 ~125 ~101 dirt
setblock ~169 ~125 ~102 dirt
setblock ~169 ~125 ~103 dirt
setblock ~169 ~125 ~104 dirt
setblock ~169 ~125 ~105 grass_block
setblock ~169 ~125 ~113 short_grass
setblock ~169 ~125 ~114 short_grass
setblock ~169 ~125 ~116 grass_block
setblock ~169 ~125 ~117 grass_block
setblock ~169 ~126 ~62 grass_block
setblock ~169 ~126 ~63 grass_block
setblock ~169 ~126 ~64 grass_block
setblock ~169 ~126 ~65 grass_block
setblock ~169 ~126 ~66 grass_block
setblock ~169 ~126 ~67 fern
setblock ~169 ~126 ~75 short_grass
setblock ~169 ~126 ~81 poppy
setblock ~169 ~126 ~86 short_grass
setblock ~169 ~126 ~88 short_grass
setblock ~169 ~126 ~89 short_grass
setblock ~169 ~126 ~91 short_grass
setblock ~169 ~126 ~94 grass_block
setblock ~169 ~126 ~95 grass_block
setblock ~169 ~126 ~96 dirt
setblock ~169 ~126 ~97 dirt
setblock ~169 ~126 ~98 dirt
setblock ~169 ~126 ~99 dirt
setblock ~169 ~126 ~100 dirt
setblock ~169 ~126 ~101 dirt
setblock ~169 ~126 ~102 dirt
setblock ~169 ~126 ~103 dirt
setblock ~169 ~126 ~104 grass_block
setblock ~169 ~126 ~116 short_grass
setblock ~169 ~127 ~62 fern
setblock ~169 ~127 ~96 grass_block
setblock ~169 ~127 ~97 dirt
setblock ~169 ~127 ~98 dirt
setblock ~169 ~127 ~99 dirt
setblock ~169 ~127 ~100 dirt
setblock ~169 ~127 ~101 dirt
setblock ~169 ~127 ~102 dirt
setblock ~169 ~127 ~103 grass_block
setblock ~169 ~128 ~96 short_grass
setblock ~169 ~128 ~97 grass_block
setblock ~169 ~128 ~98 dirt
setblock ~169 ~128 ~99 dirt
setblock ~169 ~128 ~100 dirt
setblock ~169 ~128 ~101 dirt
setblock ~169 ~128 ~102 grass_block
setblock ~169 ~129 ~97 short_grass
setblock ~169 ~129 ~98 grass_block
setblock ~169 ~129 ~99 dirt
setblock ~169 ~129 ~100 dirt
setblock ~169 ~129 ~101 dirt
setblock ~169 ~130 ~90 jungle_leaves[persistent=true]
setblock ~169 ~130 ~91 oak_leaves[persistent=true]
setblock ~169 ~130 ~92 oak_leaves[persistent=true]
setblock ~169 ~130 ~99 dirt
setblock ~169 ~130 ~100 dirt
setblock ~169 ~130 ~101 grass_block
setblock ~169 ~131 ~90 oak_leaves[persistent=true]
setblock ~169 ~131 ~91 oak_leaves[persistent=true]
setblock ~169 ~131 ~92 oak_leaves[persistent=true]
setblock ~169 ~131 ~99 grass_block
setblock ~169 ~131 ~100 grass_block
setblock ~169 ~131 ~107 oak_leaves[persistent=true]
setblock ~169 ~131 ~108 oak_leaves[persistent=true]
setblock ~169 ~131 ~109 oak_leaves[persistent=true]
setblock ~169 ~132 ~90 oak_leaves[persistent=true]
setblock ~169 ~132 ~91 oak_leaves[persistent=true]
setblock ~169 ~132 ~92 oak_leaves[persistent=true]
setblock ~169 ~132 ~99 short_grass
setblock ~169 ~132 ~107 oak_leaves[persistent=true]
setblock ~169 ~132 ~108 oak_wood
setblock ~169 ~132 ~109 oak_leaves[persistent=true]
setblock ~169 ~133 ~87 oak_leaves[persistent=true]
setblock ~169 ~133 ~88 oak_leaves[persistent=true]
setblock ~169 ~133 ~89 oak_leaves[persistent=true]
setblock ~169 ~133 ~90 oak_leaves[persistent=true]
setblock ~169 ~133 ~91 jungle_leaves[persistent=true]
setblock ~169 ~133 ~107 oak_leaves[persistent=true]
setblock ~169 ~133 ~108 jungle_leaves[persistent=true]
setblock ~169 ~133 ~109 oak_leaves[persistent=true]
setblock ~169 ~134 ~87 oak_leaves[persistent=true]
setblock ~169 ~134 ~88 oak_leaves[persistent=true]
setblock ~169 ~134 ~89 jungle_leaves[persistent=true]
setblock ~169 ~134 ~90 oak_leaves[persistent=true]
setblock ~169 ~134 ~91 oak_leaves[persistent=true]
setblock ~169 ~135 ~87 oak_leaves[persistent=true]
setblock ~169 ~135 ~88 oak_leaves[persistent=true]
setblock ~169 ~135 ~89 oak_wood
setblock ~169 ~135 ~90 oak_leaves[persistent=true]
setblock ~169 ~135 ~91 jungle_leaves[persistent=true]
setblock ~169 ~136 ~87 oak_leaves[persistent=true]
setblock ~169 ~136 ~88 oak_leaves[persistent=true]
setblock ~169 ~136 ~89 jungle_leaves[persistent=true]
setblock ~169 ~136 ~90 oak_leaves[persistent=true]
setblock ~169 ~136 ~91 oak_leaves[persistent=true]
setblock ~169 ~137 ~103 oak_leaves[persistent=true]
setblock ~169 ~137 ~104 oak_leaves[persistent=true]
setblock ~169 ~137 ~105 oak_leaves[persistent=true]
setblock ~169 ~138 ~103 jungle_leaves[persistent=true]
setblock ~169 ~138 ~105 jungle_leaves[persistent=true]
setblock ~169 ~139 ~103 oak_leaves[persistent=true]
setblock ~169 ~139 ~104 jungle_leaves[persistent=true]
setblock ~169 ~139 ~105 jungle_leaves[persistent=true]
setblock ~169 ~139 ~118 oak_leaves[persistent=true]
setblock ~169 ~139 ~119 oak_leaves[persistent=true]
setblock ~169 ~139 ~120 oak_leaves[persistent=true]
setblock ~169 ~139 ~121 oak_leaves[persistent=true]
setblock ~169 ~140 ~118 oak_leaves[persistent=true]
setblock ~169 ~140 ~119 oak_leaves[persistent=true]
setblock ~169 ~140 ~120 oak_leaves[persistent=true]
setblock ~169 ~140 ~121 jungle_leaves[persistent=true]
setblock ~169 ~141 ~118 oak_leaves[persistent=true]
setblock ~169 ~141 ~119 oak_leaves[persistent=true]
setblock ~169 ~141 ~120 oak_leaves[persistent=true]
setblock ~169 ~141 ~121 oak_leaves[persistent=true]
setblock ~169 ~142 ~118 oak_leaves[persistent=true]
setblock ~169 ~142 ~119 jungle_leaves[persistent=true]
setblock ~169 ~142 ~120 oak_leaves[persistent=true]
setblock ~169 ~142 ~121 oak_leaves[persistent=true]
setblock ~170 ~109 ~103 dirt
setblock ~170 ~109 ~105 dirt
setblock ~170 ~110 ~102 dirt
setblock ~170 ~110 ~103 dirt
setblock ~170 ~110 ~105 dirt
setblock ~170 ~111 ~102 dirt
setblock ~170 ~111 ~103 dirt
setblock ~170 ~111 ~104 dirt
setblock ~170 ~111 ~105 dirt
setblock ~170 ~111 ~106 dirt
setblock ~170 ~112 ~102 dirt
setblock ~170 ~112 ~103 dirt
setblock ~170 ~112 ~104 dirt
setblock ~170 ~112 ~105 dirt
setblock ~170 ~112 ~106 dirt
setblock ~170 ~112 ~107 dirt
setblock ~170 ~112 ~108 dirt
setblock ~170 ~113 ~76 dirt
setblock ~170 ~113 ~101 dirt
setblock ~170 ~113 ~102 dirt
setblock ~170 ~113 ~103 dirt
setblock ~170 ~113 ~104 dirt
setblock ~170 ~113 ~105 dirt
setblock ~170 ~113 ~106 dirt
setblock ~170 ~113 ~107 dirt
setblock ~170 ~113 ~108 dirt
setblock ~170 ~114 ~71 dirt
setblock ~170 ~114 ~75 dirt
setblock ~170 ~114 ~76 dirt
setblock ~170 ~114 ~77 dirt
setblock ~170 ~114 ~78 dirt
setblock ~170 ~114 ~100 dirt
setblock ~170 ~114 ~101 dirt
setblock ~170 ~114 ~102 dirt
setblock ~170 ~114 ~103 dirt
setblock ~170 ~114 ~104 dirt
setblock ~170 ~114 ~105 dirt
setblock ~170 ~114 ~106 dirt
setblock ~170 ~114 ~107 dirt
setblock ~170 ~114 ~108 dirt
setblock ~170 ~114 ~109 dirt
setblock ~170 ~114 ~111 dirt
setblock ~170 ~114 ~112 dirt
setblock ~170 ~115 ~70 dirt
setblock ~170 ~115 ~71 dirt
setblock ~170 ~115 ~72 dirt
setblock ~170 ~115 ~75 dirt
setblock ~170 ~115 ~76 dirt
setblock ~170 ~115 ~77 dirt
setblock ~170 ~115 ~78 dirt
setblock ~170 ~115 ~79 dirt
setblock ~170 ~115 ~93 dirt
setblock ~170 ~115 ~100 dirt
setblock ~170 ~115 ~101 dirt
setblock ~170 ~115 ~102 dirt
setblock ~170 ~115 ~103 dirt
setblock ~170 ~115 ~104 dirt
setblock ~170 ~115 ~105 dirt
setblock ~170 ~115 ~106 dirt
setblock ~170 ~115 ~107 dirt
setblock ~170 ~115 ~108 dirt
setblock ~170 ~115 ~109 dirt
setblock ~170 ~115 ~110 dirt
setblock ~170 ~115 ~111 dirt
setblock ~170 ~115 ~112 dirt
setblock ~170 ~115 ~113 dirt
setblock ~170 ~116 ~70 dirt
setblock ~170 ~116 ~71 dirt
setblock ~170 ~116 ~72 dirt
setblock ~170 ~116 ~75 dirt
setblock ~170 ~116 ~76 dirt
setblock ~170 ~116 ~77 dirt
setblock ~170 ~116 ~78 dirt
setblock ~170 ~116 ~79 dirt
setblock ~170 ~116 ~80 dirt
setblock ~170 ~116 ~93 dirt
setblock ~170 ~116 ~94 dirt
setblock ~170 ~116 ~98 dirt
setblock ~170 ~116 ~100 dirt
setblock ~170 ~116 ~101 dirt
setblock ~170 ~116 ~102 dirt
setblock ~170 ~116 ~103 dirt
setblock ~170 ~116 ~104 dirt
setblock ~170 ~116 ~105 dirt
setblock ~170 ~116 ~106 dirt
setblock ~170 ~116 ~107 dirt
setblock ~170 ~116 ~108 dirt
setblock ~170 ~116 ~109 dirt
setblock ~170 ~116 ~110 dirt
setblock ~170 ~116 ~111 dirt
setblock ~170 ~116 ~112 dirt
setblock ~170 ~116 ~113 dirt
setblock ~170 ~117 ~69 dirt
setblock ~170 ~117 ~70 dirt
setblock ~170 ~117 ~71 dirt
setblock ~170 ~117 ~72 dirt
setblock ~170 ~117 ~73 dirt
setblock ~170 ~117 ~74 dirt
setblock ~170 ~117 ~75 dirt
setblock ~170 ~117 ~76 dirt
setblock ~170 ~117 ~77 dirt
setblock ~170 ~117 ~78 dirt
setblock ~170 ~117 ~79 dirt
setblock ~170 ~117 ~80 dirt
setblock ~170 ~117 ~93 dirt
setblock ~170 ~117 ~94 dirt
setblock ~170 ~117 ~95 dirt
setblock ~170 ~117 ~98 dirt
setblock ~170 ~117 ~99 dirt
setblock ~170 ~117 ~100 dirt
setblock ~170 ~117 ~101 dirt
setblock ~170 ~117 ~102 dirt
setblock ~170 ~117 ~103 dirt
setblock ~170 ~117 ~104 dirt
setblock ~170 ~117 ~105 dirt
setblock ~170 ~117 ~106 dirt
setblock ~170 ~117 ~107 dirt
setblock ~170 ~117 ~108 dirt
setblock ~170 ~117 ~109 dirt
setblock ~170 ~117 ~110 dirt
setblock ~170 ~117 ~111 dirt
setblock ~170 ~117 ~112 dirt
setblock ~170 ~117 ~113 dirt
setblock ~170 ~117 ~114 dirt
setblock ~170 ~118 ~69 dirt
setblock ~170 ~118 ~70 dirt
setblock ~170 ~118 ~71 dirt
setblock ~170 ~118 ~72 dirt
setblock ~170 ~118 ~73 dirt
setblock ~170 ~118 ~74 dirt
setblock ~170 ~118 ~75 dirt
setblock ~170 ~118 ~76 dirt
setblock ~170 ~118 ~77 dirt
setblock ~170 ~118 ~78 dirt
setblock ~170 ~118 ~79 dirt
setblock ~170 ~118 ~80 dirt
setblock ~170 ~118 ~81 dirt
setblock ~170 ~118 ~92 dirt
setblock ~170 ~118 ~93 dirt
setblock ~170 ~118 ~94 dirt
setblock ~170 ~118 ~95 dirt
setblock ~170 ~118 ~97 dirt
setblock ~170 ~118 ~98 dirt
setblock ~170 ~118 ~99 dirt
setblock ~170 ~118 ~100 dirt
setblock ~170 ~118 ~101 dirt
setblock ~170 ~118 ~102 dirt
setblock ~170 ~118 ~103 dirt
setblock ~170 ~118 ~104 dirt
setblock ~170 ~118 ~105 dirt
setblock ~170 ~118 ~106 dirt
setblock ~170 ~118 ~107 dirt
setblock ~170 ~118 ~108 dirt
setblock ~170 ~118 ~109 dirt
setblock ~170 ~118 ~110 dirt
setblock ~170 ~118 ~111 dirt
setblock ~170 ~118 ~112 dirt
setblock ~170 ~118 ~113 dirt
setblock ~170 ~118 ~114 dirt
setblock ~170 ~119 ~69 dirt
setblock ~170 ~119 ~70 dirt
setblock ~170 ~119 ~71 dirt
setblock ~170 ~119 ~72 dirt
setblock ~170 ~119 ~73 dirt
setblock ~170 ~119 ~74 dirt
setblock ~170 ~119 ~75 dirt
setblock ~170 ~119 ~76 dirt
setblock ~170 ~119 ~77 dirt
setblock ~170 ~119 ~78 dirt
setblock ~170 ~119 ~79 dirt
setblock ~170 ~119 ~80 dirt
setblock ~170 ~119 ~81 dirt
setblock ~170 ~119 ~92 dirt
setblock ~170 ~119 ~93 dirt
setblock ~170 ~119 ~94 dirt
setblock ~170 ~119 ~95 dirt
setblock ~170 ~119 ~96 dirt
setblock ~170 ~119 ~97 dirt
setblock ~170 ~119 ~98 dirt
setblock ~170 ~119 ~99 dirt
setblock ~170 ~119 ~100 dirt
setblock ~170 ~119 ~101 dirt
setblock ~170 ~119 ~102 dirt
setblock ~170 ~119 ~103 dirt
setblock ~170 ~119 ~104 dirt
setblock ~170 ~119 ~105 dirt
setblock ~170 ~119 ~106 dirt
setblock ~170 ~119 ~107 dirt
setblock ~170 ~119 ~108 dirt
setblock ~170 ~119 ~109 dirt
setblock ~170 ~119 ~110 dirt
setblock ~170 ~119 ~111 dirt
setblock ~170 ~119 ~112 dirt
setblock ~170 ~119 ~113 dirt
setblock ~170 ~119 ~114 dirt
setblock ~170 ~119 ~115 dirt
setblock ~170 ~120 ~65 dirt
setblock ~170 ~120 ~68 dirt
setblock ~170 ~120 ~69 dirt
setblock ~170 ~120 ~70 dirt
setblock ~170 ~120 ~71 dirt
setblock ~170 ~120 ~72 dirt
setblock ~170 ~120 ~73 dirt
setblock ~170 ~120 ~74 dirt
setblock ~170 ~120 ~75 dirt
setblock ~170 ~120 ~76 dirt
setblock ~170 ~120 ~77 dirt
setblock ~170 ~120 ~78 dirt
setblock ~170 ~120 ~79 dirt
setblock ~170 ~120 ~80 dirt
setblock ~170 ~120 ~81 dirt
setblock ~170 ~120 ~82 dirt
setblock ~170 ~120 ~91 dirt
setblock ~170 ~120 ~92 dirt
setblock ~170 ~120 ~93 dirt
setblock ~170 ~120 ~94 dirt
setblock ~170 ~120 ~95 dirt
setblock ~170 ~120 ~96 dirt
setblock ~170 ~120 ~97 dirt
setblock ~170 ~120 ~98 dirt
setblock ~170 ~120 ~99 dirt
setblock ~170 ~120 ~100 dirt
setblock ~170 ~120 ~101 dirt
setblock ~170 ~120 ~102 dirt
setblock ~170 ~120 ~103 dirt
setblock ~170 ~120 ~104 dirt
setblock ~170 ~120 ~105 dirt
setblock ~170 ~120 ~106 dirt
setblock ~170 ~120 ~107 dirt
setblock ~170 ~120 ~108 dirt
setblock ~170 ~120 ~109 dirt
setblock ~170 ~120 ~110 dirt
setblock ~170 ~120 ~111 dirt
setblock ~170 ~120 ~112 dirt
setblock ~170 ~120 ~113 dirt
setblock ~170 ~120 ~114 dirt
setblock ~170 ~120 ~115 dirt
setblock ~170 ~121 ~64 dirt
setblock ~170 ~121 ~65 dirt
setblock ~170 ~121 ~66 dirt
setblock ~170 ~121 ~67 dirt
setblock ~170 ~121 ~68 dirt
setblock ~170 ~121 ~69 dirt
setblock ~170 ~121 ~70 dirt
setblock ~170 ~121 ~71 dirt
setblock ~170 ~121 ~72 dirt
setblock ~170 ~121 ~73 dirt
setblock ~170 ~121 ~74 dirt
setblock ~170 ~121 ~75 dirt
setblock ~170 ~121 ~76 dirt
setblock ~170 ~121 ~77 dirt
setblock ~170 ~121 ~78 dirt
setblock ~170 ~121 ~79 dirt
setblock ~170 ~121 ~80 dirt
setblock ~170 ~121 ~81 dirt
setblock ~170 ~121 ~82 dirt
setblock ~170 ~121 ~83 dirt
setblock ~170 ~121 ~84 dirt
setblock ~170 ~121 ~90 dirt
setblock ~170 ~121 ~91 dirt
setblock ~170 ~121 ~92 dirt
setblock ~170 ~121 ~93 dirt
setblock ~170 ~121 ~94 dirt
setblock ~170 ~121 ~95 dirt
setblock ~170 ~121 ~96 dirt
setblock ~170 ~121 ~97 dirt
setblock ~170 ~121 ~98 dirt
setblock ~170 ~121 ~99 dirt
setblock ~170 ~121 ~100 dirt
setblock ~170 ~121 ~101 dirt
setblock ~170 ~121 ~102 dirt
setblock ~170 ~121 ~103 dirt
setblock ~170 ~121 ~104 dirt
setblock ~170 ~121 ~105 dirt
setblock ~170 ~121 ~106 dirt
setblock ~170 ~121 ~107 dirt
setblock ~170 ~121 ~108 dirt
setblock ~170 ~121 ~109 dirt
setblock ~170 ~121 ~110 dirt
setblock ~170 ~121 ~111 dirt
setblock ~170 ~121 ~112 dirt
setblock ~170 ~121 ~113 dirt
setblock ~170 ~121 ~114 dirt
setblock ~170 ~121 ~115 dirt
setblock ~170 ~122 ~64 dirt
setblock ~170 ~122 ~65 dirt
setblock ~170 ~122 ~66 dirt
setblock ~170 ~122 ~67 dirt
setblock ~170 ~122 ~68 dirt
setblock ~170 ~122 ~69 dirt
setblock ~170 ~122 ~70 dirt
setblock ~170 ~122 ~71 dirt
setblock ~170 ~122 ~72 dirt
setblock ~170 ~122 ~73 dirt
setblock ~170 ~122 ~74 dirt
setblock ~170 ~122 ~75 dirt
setblock ~170 ~122 ~76 dirt
setblock ~170 ~122 ~77 dirt
setblock ~170 ~122 ~78 dirt
setblock ~170 ~122 ~79 dirt
setblock ~170 ~122 ~80 dirt
setblock ~170 ~122 ~81 dirt
setblock ~170 ~122 ~82 dirt
setblock ~170 ~122 ~83 dirt
setblock ~170 ~122 ~84 dirt
setblock ~170 ~122 ~90 dirt
setblock ~170 ~122 ~91 dirt
setblock ~170 ~122 ~92 dirt
setblock ~170 ~122 ~93 dirt
setblock ~170 ~122 ~94 dirt
setblock ~170 ~122 ~95 dirt
setblock ~170 ~122 ~96 dirt
setblock ~170 ~122 ~97 dirt
setblock ~170 ~122 ~98 dirt
setblock ~170 ~122 ~99 dirt
setblock ~170 ~122 ~100 dirt
setblock ~170 ~122 ~101 dirt
setblock ~170 ~122 ~102 dirt
setblock ~170 ~122 ~103 dirt
setblock ~170 ~122 ~104 dirt
setblock ~170 ~122 ~105 dirt
setblock ~170 ~122 ~106 dirt
setblock ~170 ~122 ~107 dirt
setblock ~170 ~122 ~108 dirt
setblock ~170 ~122 ~109 dirt
setblock ~170 ~122 ~110 grass_block
setblock ~170 ~122 ~111 dirt
setblock ~170 ~122 ~112 dirt
setblock ~170 ~122 ~113 dirt
setblock ~170 ~122 ~114 dirt
setblock ~170 ~122 ~115 dirt
setblock ~170 ~123 ~64 dirt
setblock ~170 ~123 ~65 dirt
setblock ~170 ~123 ~66 dirt
setblock ~170 ~123 ~67 dirt
setblock ~170 ~123 ~68 dirt
setblock ~170 ~123 ~69 dirt
setblock ~170 ~123 ~70 dirt
setblock ~170 ~123 ~71 dirt
setblock ~170 ~123 ~72 dirt
setblock ~170 ~123 ~73 dirt
setblock ~170 ~123 ~74 dirt
setblock ~170 ~123 ~75 dirt
setblock ~170 ~123 ~76 dirt
setblock ~170 ~123 ~77 dirt
setblock ~170 ~123 ~78 dirt
setblock ~170 ~123 ~79 dirt
setblock ~170 ~123 ~80 dirt
setblock ~170 ~123 ~81 dirt
setblock ~170 ~123 ~82 dirt
setblock ~170 ~123 ~83 dirt
setblock ~170 ~123 ~84 dirt
setblock ~170 ~123 ~90 dirt
setblock ~170 ~123 ~91 dirt
setblock ~170 ~123 ~92 dirt
setblock ~170 ~123 ~93 dirt
setblock ~170 ~123 ~94 dirt
setblock ~170 ~123 ~95 dirt
setblock ~170 ~123 ~96 dirt
setblock ~170 ~123 ~97 dirt
setblock ~170 ~123 ~98 dirt
setblock ~170 ~123 ~99 dirt
setblock ~170 ~123 ~100 dirt
setblock ~170 ~123 ~101 dirt
setblock ~170 ~123 ~102 dirt
setblock ~170 ~123 ~103 dirt
setblock ~170 ~123 ~104 dirt
setblock ~170 ~123 ~105 dirt
setblock ~170 ~123 ~106 dirt
setblock ~170 ~123 ~107 grass_block
setblock ~170 ~123 ~108 grass_block
setblock ~170 ~123 ~109 grass_block
setblock ~170 ~123 ~110 fern
setblock ~170 ~123 ~111 grass_block
setblock ~170 ~123 ~112 grass_block
setblock ~170 ~123 ~113 grass_block
setblock ~170 ~123 ~114 dirt
setblock ~170 ~123 ~115 dirt
setblock ~170 ~124 ~64 dirt
setblock ~170 ~124 ~65 dirt
setblock ~170 ~124 ~66 dirt
setblock ~170 ~124 ~67 dirt
setblock ~170 ~124 ~68 dirt
setblock ~170 ~124 ~69 dirt
setblock ~170 ~124 ~70 dirt
setblock ~170 ~124 ~71 dirt
setblock ~170 ~124 ~72 dirt
setblock ~170 ~124 ~73 dirt
setblock ~170 ~124 ~74 dirt
setblock ~170 ~124 ~75 dirt
setblock ~170 ~124 ~76 dirt
setblock ~170 ~124 ~77 dirt
setblock ~170 ~124 ~78 dirt
setblock ~170 ~124 ~79 dirt
setblock ~170 ~124 ~80 dirt
setblock ~170 ~124 ~81 dirt
setblock ~170 ~124 ~82 dirt
setblock ~170 ~124 ~83 dirt
setblock ~170 ~124 ~84 dirt
setblock ~170 ~124 ~90 grass_block
setblock ~170 ~124 ~91 dirt
setblock ~170 ~124 ~92 dirt
setblock ~170 ~124 ~93 dirt
setblock ~170 ~124 ~94 dirt
setblock ~170 ~124 ~95 dirt
setblock ~170 ~124 ~96 dirt
setblock ~170 ~124 ~97 dirt
setblock ~170 ~124 ~98 dirt
setblock ~170 ~124 ~99 dirt
setblock ~170 ~124 ~100 dirt
setblock ~170 ~124 ~101 dirt
setblock ~170 ~124 ~102 dirt
setblock ~170 ~124 ~103 dirt
setblock ~170 ~124 ~104 dirt
setblock ~170 ~124 ~105 dirt
setblock ~170 ~124 ~106 grass_block
setblock ~170 ~124 ~107 poppy
setblock ~170 ~124 ~111 fern
setblock ~170 ~124 ~113 fern
setblock ~170 ~124 ~114 grass_block
setblock ~170 ~124 ~115 grass_block
setblock ~170 ~125 ~64 dirt
setblock ~170 ~125 ~65 grass_block
setblock ~170 ~125 ~66 grass_block
setblock ~170 ~125 ~67 grass_block
setblock ~170 ~125 ~68 grass_block
setblock ~170 ~125 ~69 grass_block
setblock ~170 ~125 ~70 grass_block
setblock ~170 ~125 ~71 grass_block
setblock ~170 ~125 ~72 grass_block
setblock ~170 ~125 ~73 grass_block
setblock ~170 ~125 ~74 grass_block
setblock ~170 ~125 ~75 grass_block
setblock ~170 ~125 ~76 grass_block
setblock ~170 ~125 ~77 grass_block
setblock ~170 ~125 ~78 grass_block
setblock ~170 ~125 ~79 grass_block
setblock ~170 ~125 ~80 grass_block
setblock ~170 ~125 ~81 grass_block
setblock ~170 ~125 ~82 grass_block
setblock ~170 ~125 ~83 grass_block
setblock ~170 ~125 ~84 grass_block
setblock ~170 ~125 ~90 short_grass
setblock ~170 ~125 ~91 grass_block
setblock ~170 ~125 ~92 grass_block
setblock ~170 ~125 ~93 grass_block
setblock ~170 ~125 ~94 dirt
setblock ~170 ~125 ~95 dirt
setblock ~170 ~125 ~96 dirt
setblock ~170 ~125 ~97 dirt
setblock ~170 ~125 ~98 dirt
setblock ~170 ~125 ~99 dirt
setblock ~170 ~125 ~100 dirt
setblock ~170 ~125 ~101 dirt
setblock ~170 ~125 ~102 dirt
setblock ~170 ~125 ~103 dirt
setblock ~170 ~125 ~104 dirt
setblock ~170 ~125 ~105 grass_block
setblock ~170 ~126 ~64 grass_block
setblock ~170 ~126 ~67 short_grass
setblock ~170 ~126 ~69 poppy
setblock ~170 ~126 ~73 short_grass
setblock ~170 ~126 ~75 short_grass
setblock ~170 ~126 ~76 short_grass
setblock ~170 ~126 ~77 poppy
setblock ~170 ~126 ~80 short_grass
setblock ~170 ~126 ~83 short_grass
setblock ~170 ~126 ~91 short_grass
setblock ~170 ~126 ~94 grass_block
setblock ~170 ~126 ~95 grass_block
setblock ~170 ~126 ~96 dirt
setblock ~170 ~126 ~97 dirt
setblock ~170 ~126 ~98 dirt
setblock ~170 ~126 ~99 dirt
setblock ~170 ~126 ~100 dirt
setblock ~170 ~126 ~101 dirt
setblock ~170 ~126 ~102 dirt
setblock ~170 ~126 ~103 dirt
setblock ~170 ~126 ~104 grass_block
setblock ~170 ~127 ~96 grass_block
setblock ~170 ~127 ~97 dirt
setblock ~170 ~127 ~98 dirt
setblock ~170 ~127 ~99 dirt
setblock ~170 ~127 ~100 dirt
setblock ~170 ~127 ~101 dirt
setblock ~170 ~127 ~102 dirt
setblock ~170 ~127 ~103 grass_block
setblock ~170 ~127 ~104 short_grass
setblock ~170 ~128 ~97 grass_block
setblock ~170 ~128 ~98 dirt
setblock ~170 ~128 ~99 dirt
setblock ~170 ~128 ~100 dirt
setblock ~170 ~128 ~101 dirt
setblock ~170 ~128 ~102 dirt
setblock ~170 ~129 ~98 dirt
setblock ~170 ~129 ~99 dirt
setblock ~170 ~129 ~100 dirt
setblock ~170 ~129 ~101 dirt
setblock ~170 ~129 ~102 grass_block
setblock ~170 ~130 ~98 grass_block
setblock ~170 ~130 ~99 dirt
setblock ~170 ~130 ~100 dirt
setblock ~170 ~130 ~101 dirt
setblock ~170 ~131 ~99 grass_block
setblock ~170 ~131 ~100 dirt
setblock ~170 ~131 ~101 grass_block
setblock ~170 ~131 ~107 oak_leaves[persistent=true]
setblock ~170 ~131 ~108 oak_leaves[persistent=true]
setblock ~170 ~131 ~109 oak_leaves[persistent=true]
setblock ~170 ~132 ~100 grass_block
setblock ~170 ~132 ~107 jungle_leaves[persistent=true]
setblock ~170 ~132 ~108 oak_leaves[persistent=true]
setblock ~170 ~132 ~109 oak_leaves[persistent=true]
setblock ~170 ~133 ~87 oak_leaves[persistent=true]
setblock ~170 ~133 ~88 oak_leaves[persistent=true]
setblock ~170 ~133 ~89 oak_leaves[persistent=true]
setblock ~170 ~133 ~90 oak_leaves[persistent=true]
setblock ~170 ~133 ~91 oak_leaves[persistent=true]
setblock ~170 ~133 ~107 oak_leaves[persistent=true]
setblock ~170 ~133 ~108 oak_leaves[persistent=true]
setblock ~170 ~133 ~109 jungle_leaves[persistent=true]
setblock ~170 ~134 ~87 jungle_leaves[persistent=true]
setblock ~170 ~134 ~88 oak_leaves[persistent=true]
setblock ~170 ~134 ~90 oak_leaves[persistent=true]
setblock ~170 ~134 ~91 jungle_leaves[persistent=true]
setblock ~170 ~135 ~88 oak_leaves[persistent=true]
setblock ~170 ~135 ~89 oak_leaves[persistent=true]
setblock ~170 ~135 ~90 oak_wood
setblock ~170 ~135 ~91 oak_leaves[persistent=true]
setblock ~170 ~136 ~87 oak_leaves[persistent=true]
setblock ~170 ~136 ~88 oak_leaves[persistent=true]
setblock ~170 ~136 ~89 jungle_leaves[persistent=true]
setblock ~170 ~136 ~90 oak_leaves[persistent=true]
setblock ~170 ~136 ~91 oak_leaves[persistent=true]
setblock ~170 ~139 ~118 oak_leaves[persistent=true]
setblock ~170 ~139 ~119 oak_leaves[persistent=true]
setblock ~170 ~139 ~120 oak_leaves[persistent=true]
setblock ~170 ~139 ~121 jungle_leaves[persistent=true]
setblock ~170 ~140 ~118 oak_leaves[persistent=true]
setblock ~170 ~140 ~119 jungle_leaves[persistent=true]
setblock ~170 ~140 ~120 oak_leaves[persistent=true]
setblock ~170 ~140 ~121 oak_leaves[persistent=true]
setblock ~170 ~141 ~118 oak_leaves[persistent=true]
setblock ~170 ~141 ~119 oak_leaves[persistent=true]
setblock ~170 ~141 ~121 oak_leaves[persistent=true]
setblock ~170 ~142 ~118 jungle_leaves[persistent=true]
setblock ~170 ~142 ~119 jungle_leaves[persistent=true]
setblock ~170 ~142 ~120 oak_leaves[persistent=true]
setblock ~170 ~142 ~121 oak_leaves[persistent=true]
setblock ~171 ~112 ~103 dirt
setblock ~171 ~112 ~105 dirt
setblock ~171 ~113 ~102 dirt
setblock ~171 ~113 ~103 dirt
setblock ~171 ~113 ~104 dirt
setblock ~171 ~113 ~105 dirt
setblock ~171 ~113 ~106 dirt
setblock ~171 ~114 ~102 dirt
setblock ~171 ~114 ~103 dirt
setblock ~171 ~114 ~104 dirt
setblock ~171 ~114 ~105 dirt
setblock ~171 ~114 ~106 dirt
setblock ~171 ~114 ~108 dirt
setblock ~171 ~115 ~78 dirt
setblock ~171 ~115 ~101 dirt
setblock ~171 ~115 ~102 dirt
setblock ~171 ~115 ~103 dirt
setblock ~171 ~115 ~104 dirt
setblock ~171 ~115 ~105 dirt
setblock ~171 ~115 ~106 dirt
setblock ~171 ~115 ~107 dirt
setblock ~171 ~115 ~108 dirt
setblock ~171 ~115 ~109 dirt
setblock ~171 ~115 ~111 dirt
setblock ~171 ~115 ~112 dirt
setblock ~171 ~116 ~76 dirt
setblock ~171 ~116 ~77 dirt
setblock ~171 ~116 ~78 dirt
setblock ~171 ~116 ~79 dirt
setblock ~171 ~116 ~101 dirt
setblock ~171 ~116 ~102 dirt
setblock ~171 ~116 ~103 dirt
setblock ~171 ~116 ~104 dirt
setblock ~171 ~116 ~105 dirt
setblock ~171 ~116 ~106 dirt
setblock ~171 ~116 ~107 dirt
setblock ~171 ~116 ~108 dirt
setblock ~171 ~116 ~109 dirt
setblock ~171 ~116 ~110 dirt
setblock ~171 ~116 ~111 dirt
setblock ~171 ~116 ~112 dirt
setblock ~171 ~116 ~113 dirt
setblock ~171 ~117 ~70 dirt
setblock ~171 ~117 ~71 dirt
setblock ~171 ~117 ~75 dirt
setblock ~171 ~117 ~76 dirt
setblock ~171 ~117 ~77 dirt
setblock ~171 ~117 ~78 dirt
setblock ~171 ~117 ~79 dirt
setblock ~171 ~117 ~100 dirt
setblock ~171 ~117 ~101 dirt
setblock ~171 ~117 ~102 dirt
setblock ~171 ~117 ~103 dirt
setblock ~171 ~117 ~104 dirt
setblock ~171 ~117 ~105 dirt
setblock ~171 ~117 ~106 dirt
setblock ~171 ~117 ~107 dirt
setblock ~171 ~117 ~108 dirt
setblock ~171 ~117 ~109 dirt
setblock ~171 ~117 ~110 dirt
setblock ~171 ~117 ~111 dirt
setblock ~171 ~117 ~112 dirt
setblock ~171 ~117 ~113 dirt
setblock ~171 ~117 ~114 dirt
setblock ~171 ~118 ~70 dirt
setblock ~171 ~118 ~71 dirt
setblock ~171 ~118 ~74 dirt
setblock ~171 ~118 ~75 dirt
setblock ~171 ~118 ~76 dirt
setblock ~171 ~118 ~77 dirt
setblock ~171 ~118 ~78 dirt
setblock ~171 ~118 ~79 dirt
setblock ~171 ~118 ~80 dirt
setblock ~171 ~118 ~94 dirt
setblock ~171 ~118 ~100 dirt
setblock ~171 ~118 ~101 dirt
setblock ~171 ~118 ~102 dirt
setblock ~171 ~118 ~103 dirt
setblock ~171 ~118 ~104 dirt
setblock ~171 ~118 ~105 dirt
setblock ~171 ~118 ~106 dirt
setblock ~171 ~118 ~107 dirt
setblock ~171 ~118 ~108 dirt
setblock ~171 ~118 ~109 dirt
setblock ~171 ~118 ~110 dirt
setblock ~171 ~118 ~111 dirt
setblock ~171 ~118 ~112 dirt
setblock ~171 ~118 ~113 dirt
setblock ~171 ~118 ~114 dirt
setblock ~171 ~119 ~70 dirt
setblock ~171 ~119 ~71 dirt
setblock ~171 ~119 ~72 dirt
setblock ~171 ~119 ~74 dirt
setblock ~171 ~119 ~75 dirt
setblock ~171 ~119 ~76 dirt
setblock ~171 ~119 ~77 dirt
setblock ~171 ~119 ~78 dirt
setblock ~171 ~119 ~79 dirt
setblock ~171 ~119 ~80 dirt
setblock ~171 ~119 ~81 dirt
setblock ~171 ~119 ~93 dirt
setblock ~171 ~119 ~94 dirt
setblock ~171 ~119 ~100 dirt
setblock ~171 ~119 ~101 dirt
setblock ~171 ~119 ~102 dirt
setblock ~171 ~119 ~103 dirt
setblock ~171 ~119 ~104 dirt
setblock ~171 ~119 ~105 dirt
setblock ~171 ~119 ~106 dirt
setblock ~171 ~119 ~107 dirt
setblock ~171 ~119 ~108 dirt
setblock ~171 ~119 ~109 dirt
setblock ~171 ~119 ~110 dirt
setblock ~171 ~119 ~111 dirt
setblock ~171 ~119 ~112 dirt
setblock ~171 ~119 ~113 dirt
setblock ~171 ~119 ~114 dirt
setblock ~171 ~120 ~69 dirt
setblock ~171 ~120 ~70 dirt
setblock ~171 ~120 ~71 dirt
setblock ~171 ~120 ~72 dirt
setblock ~171 ~120 ~73 dirt
setblock ~171 ~120 ~74 dirt
setblock ~171 ~120 ~75 dirt
setblock ~171 ~120 ~76 dirt
setblock ~171 ~120 ~77 dirt
setblock ~171 ~120 ~78 dirt
setblock ~171 ~120 ~79 dirt
setblock ~171 ~120 ~80 dirt
setblock ~171 ~120 ~81 dirt
setblock ~171 ~120 ~92 dirt
setblock ~171 ~120 ~93 dirt
setblock ~171 ~120 ~94 dirt
setblock ~171 ~120 ~95 dirt
setblock ~171 ~120 ~96 dirt
setblock ~171 ~120 ~98 dirt
setblock ~171 ~120 ~99 dirt
setblock ~171 ~120 ~100 dirt
setblock ~171 ~120 ~101 dirt
setblock ~171 ~120 ~102 dirt
setblock ~171 ~120 ~103 dirt
setblock ~171 ~120 ~104 dirt
setblock ~171 ~120 ~105 dirt
setblock ~171 ~120 ~106 dirt
setblock ~171 ~120 ~107 dirt
setblock ~171 ~120 ~108 dirt
setblock ~171 ~120 ~109 dirt
setblock ~171 ~120 ~110 dirt
setblock ~171 ~120 ~111 dirt
setblock ~171 ~120 ~112 dirt
setblock ~171 ~120 ~113 dirt
setblock ~171 ~120 ~114 dirt
setblock ~171 ~121 ~68 dirt
setblock ~171 ~121 ~69 dirt
setblock ~171 ~121 ~70 dirt
setblock ~171 ~121 ~71 dirt
setblock ~171 ~121 ~72 dirt
setblock ~171 ~121 ~73 dirt
setblock ~171 ~121 ~74 dirt
setblock ~171 ~121 ~75 dirt
setblock ~171 ~121 ~76 dirt
setblock ~171 ~121 ~77 dirt
setblock ~171 ~121 ~78 dirt
setblock ~171 ~121 ~79 dirt
setblock ~171 ~121 ~80 dirt
setblock ~171 ~121 ~81 dirt
setblock ~171 ~121 ~82 dirt
setblock ~171 ~121 ~92 dirt
setblock ~171 ~121 ~93 dirt
setblock ~171 ~121 ~94 dirt
setblock ~171 ~121 ~95 dirt
setblock ~171 ~121 ~96 dirt
setblock ~171 ~121 ~97 dirt
setblock ~171 ~121 ~98 dirt
setblock ~171 ~121 ~99 dirt
setblock ~171 ~121 ~100 dirt
setblock ~171 ~121 ~101 dirt
setblock ~171 ~121 ~102 dirt
setblock ~171 ~121 ~103 dirt
setblock ~171 ~121 ~104 dirt
setblock ~171 ~121 ~105 dirt
setblock ~171 ~121 ~106 dirt
setblock ~171 ~121 ~107 dirt
setblock ~171 ~121 ~108 dirt
setblock ~171 ~121 ~109 dirt
setblock ~171 ~121 ~110 dirt
setblock ~171 ~121 ~111 dirt
setblock ~171 ~121 ~112 dirt
setblock ~171 ~121 ~113 dirt
setblock ~171 ~121 ~114 dirt
setblock ~171 ~121 ~115 dirt
setblock ~171 ~122 ~68 dirt
setblock ~171 ~122 ~69 dirt
setblock ~171 ~122 ~70 dirt
setblock ~171 ~122 ~71 dirt
setblock ~171 ~122 ~72 dirt
setblock ~171 ~122 ~73 dirt
setblock ~171 ~122 ~74 dirt
setblock ~171 ~122 ~75 dirt
setblock ~171 ~122 ~76 dirt
setblock ~171 ~122 ~77 dirt
setblock ~171 ~122 ~78 dirt
setblock ~171 ~122 ~79 dirt
setblock ~171 ~122 ~80 dirt
setblock ~171 ~122 ~81 dirt
setblock ~171 ~122 ~82 dirt
setblock ~171 ~122 ~92 dirt
setblock ~171 ~122 ~93 dirt
setblock ~171 ~122 ~94 dirt
setblock ~171 ~122 ~95 dirt
setblock ~171 ~122 ~96 dirt
setblock ~171 ~122 ~97 dirt
setblock ~171 ~122 ~98 dirt
setblock ~171 ~122 ~99 dirt
setblock ~171 ~122 ~100 dirt
setblock ~171 ~122 ~101 dirt
setblock ~171 ~122 ~102 dirt
setblock ~171 ~122 ~103 dirt
setblock ~171 ~122 ~104 dirt
setblock ~171 ~122 ~105 dirt
setblock ~171 ~122 ~106 dirt
setblock ~171 ~122 ~107 dirt
setblock ~171 ~122 ~108 dirt
setblock ~171 ~122 ~109 dirt
setblock ~171 ~122 ~110 dirt
setblock ~171 ~122 ~111 dirt
setblock ~171 ~122 ~112 dirt
setblock ~171 ~122 ~113 dirt
setblock ~171 ~122 ~114 dirt
setblock ~171 ~122 ~115 dirt
setblock ~171 ~123 ~68 dirt
setblock ~171 ~123 ~69 dirt
setblock ~171 ~123 ~70 dirt
setblock ~171 ~123 ~71 dirt
setblock ~171 ~123 ~72 dirt
setblock ~171 ~123 ~73 dirt
setblock ~171 ~123 ~74 dirt
setblock ~171 ~123 ~75 dirt
setblock ~171 ~123 ~76 dirt
setblock ~171 ~123 ~77 dirt
setblock ~171 ~123 ~78 dirt
setblock ~171 ~123 ~79 dirt
setblock ~171 ~123 ~80 dirt
setblock ~171 ~123 ~81 dirt
setblock ~171 ~123 ~82 dirt
setblock ~171 ~123 ~92 dirt
setblock ~171 ~123 ~93 dirt
setblock ~171 ~123 ~94 dirt
setblock ~171 ~123 ~95 dirt
setblock ~171 ~123 ~96 dirt
setblock ~171 ~123 ~97 dirt
setblock ~171 ~123 ~98 dirt
setblock ~171 ~123 ~99 dirt
setblock ~171 ~123 ~100 dirt
setblock ~171 ~123 ~101 dirt
setblock ~171 ~123 ~102 dirt
setblock ~171 ~123 ~103 dirt
setblock ~171 ~123 ~104 dirt
setblock ~171 ~123 ~105 dirt
setblock ~171 ~123 ~106 dirt
setblock ~171 ~123 ~107 dirt
setblock ~171 ~123 ~108 grass_block
setblock ~171 ~123 ~109 grass_block
setblock ~171 ~123 ~110 grass_block
setblock ~171 ~123 ~111 grass_block
setblock ~171 ~123 ~112 grass_block
setblock ~171 ~123 ~113 dirt
setblock ~171 ~123 ~114 dirt
setblock ~171 ~123 ~115 dirt
setblock ~171 ~124 ~68 dirt
setblock ~171 ~124 ~69 dirt
setblock ~171 ~124 ~70 dirt
setblock ~171 ~124 ~71 dirt
setblock ~171 ~124 ~72 dirt
setblock ~171 ~124 ~73 dirt
setblock ~171 ~124 ~74 dirt
setblock ~171 ~124 ~75 dirt
setblock ~171 ~124 ~76 dirt
setblock ~171 ~124 ~77 dirt
setblock ~171 ~124 ~78 dirt
setblock ~171 ~124 ~79 dirt
setblock ~171 ~124 ~80 dirt
setblock ~171 ~124 ~81 dirt
setblock ~171 ~124 ~82 dirt
setblock ~171 ~124 ~92 dirt
setblock ~171 ~124 ~93 dirt
setblock ~171 ~124 ~94 dirt
setblock ~171 ~124 ~95 dirt
setblock ~171 ~124 ~96 dirt
setblock ~171 ~124 ~97 dirt
setblock ~171 ~124 ~98 dirt
setblock ~171 ~124 ~99 dirt
setblock ~171 ~124 ~100 dirt
setblock ~171 ~124 ~101 dirt
setblock ~171 ~124 ~102 dirt
setblock ~171 ~124 ~103 dirt
setblock ~171 ~124 ~104 dirt
setblock ~171 ~124 ~105 dirt
setblock ~171 ~124 ~106 grass_block
setblock ~171 ~124 ~107 grass_block
setblock ~171 ~124 ~108 short_grass
setblock ~171 ~124 ~109 fern
setblock ~171 ~124 ~112 poppy
setblock ~171 ~124 ~113 grass_block
setblock ~171 ~124 ~114 grass_block
setblock ~171 ~124 ~115 grass_block
setblock ~171 ~125 ~68 grass_block
setblock ~171 ~125 ~69 grass_block
setblock ~171 ~125 ~70 grass_block
setblock ~171 ~125 ~71 grass_block
setblock ~171 ~125 ~72 grass_block
setblock ~171 ~125 ~73 grass_block
setblock ~171 ~125 ~74 grass_block
setblock ~171 ~125 ~75 grass_block
setblock ~171 ~125 ~76 grass_block
setblock ~171 ~125 ~77 grass_block
setblock ~171 ~125 ~78 grass_block
setblock ~171 ~125 ~79 grass_block
setblock ~171 ~125 ~80 grass_block
setblock ~171 ~125 ~81 grass_block
setblock ~171 ~125 ~82 grass_block
setblock ~171 ~125 ~92 grass_block
setblock ~171 ~125 ~93 grass_block
setblock ~171 ~125 ~94 dirt
setblock ~171 ~125 ~95 dirt
setblock ~171 ~125 ~96 dirt
setblock ~171 ~125 ~97 dirt
setblock ~171 ~125 ~98 dirt
setblock ~171 ~125 ~99 dirt
setblock ~171 ~125 ~100 dirt
setblock ~171 ~125 ~101 dirt
setblock ~171 ~125 ~102 dirt
setblock ~171 ~125 ~103 dirt
setblock ~171 ~125 ~104 dirt
setblock ~171 ~125 ~105 grass_block
setblock ~171 ~125 ~106 short_grass
setblock ~171 ~125 ~113 poppy
setblock ~171 ~125 ~115 short_grass
setblock ~171 ~126 ~68 poppy
setblock ~171 ~126 ~82 poppy
setblock ~171 ~126 ~94 grass_block
setblock ~171 ~126 ~95 grass_block
setblock ~171 ~126 ~96 dirt
setblock ~171 ~126 ~97 dirt
setblock ~171 ~126 ~98 dirt
setblock ~171 ~126 ~99 dirt
setblock ~171 ~126 ~100 dirt
setblock ~171 ~126 ~101 dirt
setblock ~171 ~126 ~102 dirt
setblock ~171 ~126 ~103 dirt
setblock ~171 ~126 ~104 grass_block
setblock ~171 ~127 ~96 grass_block
setblock ~171 ~127 ~97 dirt
setblock ~171 ~127 ~98 dirt
setblock ~171 ~127 ~99 dirt
setblock ~171 ~127 ~100 dirt
setblock ~171 ~127 ~101 dirt
setblock ~171 ~127 ~102 dirt
setblock ~171 ~127 ~103 grass_block
setblock ~171 ~128 ~97 grass_block
setblock ~171 ~128 ~98 dirt
setblock ~171 ~128 ~99 dirt
setblock ~171 ~128 ~100 dirt
setblock ~171 ~128 ~101 dirt
setblock ~171 ~128 ~102 dirt
setblock ~171 ~129 ~97 short_grass
setblock ~171 ~129 ~98 grass_block
setblock ~171 ~129 ~99 dirt
setblock ~171 ~129 ~100 dirt
setblock ~171 ~129 ~101 dirt
setblock ~171 ~129 ~102 grass_block
setblock ~171 ~130 ~99 dirt
setblock ~171 ~130 ~100 dirt
setblock ~171 ~130 ~101 dirt
setblock ~171 ~131 ~99 grass_block
setblock ~171 ~131 ~100 dirt
setblock ~171 ~131 ~101 grass_block
setblock ~171 ~131 ~107 oak_leaves[persistent=true]
setblock ~171 ~131 ~108 oak_leaves[persistent=true]
setblock ~171 ~132 ~100 grass_block
setblock ~171 ~132 ~107 jungle_leaves[persistent=true]
setblock ~171 ~132 ~108 oak_leaves[persistent=true]
setblock ~171 ~132 ~109 jungle_leaves[persistent=true]
setblock ~171 ~133 ~88 oak_leaves[persistent=true]
setblock ~171 ~133 ~89 oak_leaves[persistent=true]
setblock ~171 ~133 ~90 jungle_leaves[persistent=true]
setblock ~171 ~133 ~91 oak_leaves[persistent=true]
setblock ~171 ~133 ~92 jungle_leaves[persistent=true]
setblock ~171 ~133 ~93 oak_leaves[persistent=true]
setblock ~171 ~133 ~100 fern
setblock ~171 ~133 ~107 oak_leaves[persistent=true]
setblock ~171 ~133 ~108 oak_leaves[persistent=true]
setblock ~171 ~133 ~109 oak_leaves[persistent=true]
setblock ~171 ~134 ~88 oak_leaves[persistent=true]
setblock ~171 ~134 ~89 oak_leaves[persistent=true]
setblock ~171 ~134 ~90 oak_leaves[persistent=true]
setblock ~171 ~134 ~91 oak_wood
setblock ~171 ~134 ~92 oak_leaves[persistent=true]
setblock ~171 ~134 ~93 oak_leaves[persistent=true]
setblock ~171 ~135 ~88 oak_leaves[persistent=true]
setblock ~171 ~135 ~89 oak_leaves[persistent=true]
setblock ~171 ~135 ~90 jungle_leaves[persistent=true]
setblock ~171 ~135 ~91 oak_leaves[persistent=true]
setblock ~171 ~135 ~92 oak_leaves[persistent=true]
setblock ~171 ~136 ~88 oak_leaves[persistent=true]
setblock ~171 ~136 ~89 oak_leaves[persistent=true]
setblock ~171 ~136 ~90 oak_leaves[persistent=true]
setblock ~171 ~136 ~91 oak_leaves[persistent=true]
setblock ~172 ~113 ~105 dirt
setblock ~172 ~114 ~103 dirt
setblock ~172 ~114 ~105 dirt
setblock ~172 ~115 ~102 dirt
setblock ~172 ~115 ~103 dirt
setblock ~172 ~115 ~104 dirt
setblock ~172 ~115 ~105 dirt
setblock ~172 ~115 ~106 dirt
setblock ~172 ~116 ~78 dirt
setblock ~172 ~116 ~101 dirt
setblock ~172 ~116 ~102 dirt
setblock ~172 ~116 ~103 dirt
setblock ~172 ~116 ~104 dirt
setblock ~172 ~116 ~105 dirt
setblock ~172 ~116 ~106 dirt
setblock ~172 ~116 ~107 dirt
setblock ~172 ~116 ~111 dirt
setblock ~172 ~116 ~112 dirt
setblock ~172 ~117 ~78 dirt
setblock ~172 ~117 ~101 dirt
setblock ~172 ~117 ~102 dirt
setblock ~172 ~117 ~103 dirt
setblock ~172 ~117 ~104 dirt
setblock ~172 ~117 ~105 dirt
setblock ~172 ~117 ~106 dirt
setblock ~172 ~117 ~107 dirt
setblock ~172 ~117 ~108 dirt
setblock ~172 ~117 ~110 dirt
setblock ~172 ~117 ~111 dirt
setblock ~172 ~117 ~112 dirt
setblock ~172 ~117 ~113 dirt
setblock ~172 ~118 ~76 dirt
setblock ~172 ~118 ~78 dirt
setblock ~172 ~118 ~79 dirt
setblock ~172 ~118 ~101 dirt
setblock ~172 ~118 ~102 dirt
setblock ~172 ~118 ~103 dirt
setblock ~172 ~118 ~104 dirt
setblock ~172 ~118 ~105 dirt
setblock ~172 ~118 ~106 dirt
setblock ~172 ~118 ~107 dirt
setblock ~172 ~118 ~108 dirt
setblock ~172 ~118 ~109 dirt
setblock ~172 ~118 ~110 dirt
setblock ~172 ~118 ~111 dirt
setblock ~172 ~118 ~112 dirt
setblock ~172 ~118 ~113 dirt
setblock ~172 ~119 ~71 dirt
setblock ~172 ~119 ~75 dirt
setblock ~172 ~119 ~76 dirt
setblock ~172 ~119 ~77 dirt
setblock ~172 ~119 ~78 dirt
setblock ~172 ~119 ~79 dirt
setblock ~172 ~119 ~80 dirt
setblock ~172 ~119 ~100 dirt
setblock ~172 ~119 ~101 dirt
setblock ~172 ~119 ~102 dirt
setblock ~172 ~119 ~103 dirt
setblock ~172 ~119 ~104 dirt
setblock ~172 ~119 ~105 dirt
setblock ~172 ~119 ~106 dirt
setblock ~172 ~119 ~107 dirt
setblock ~172 ~119 ~108 dirt
setblock ~172 ~119 ~109 dirt
setblock ~172 ~119 ~110 dirt
setblock ~172 ~119 ~111 dirt
setblock ~172 ~119 ~112 dirt
setblock ~172 ~119 ~113 dirt
setblock ~172 ~119 ~114 dirt
setblock ~172 ~120 ~70 dirt
setblock ~172 ~120 ~71 dirt
setblock ~172 ~120 ~74 dirt
setblock ~172 ~120 ~75 dirt
setblock ~172 ~120 ~76 dirt
setblock ~172 ~120 ~77 dirt
setblock ~172 ~120 ~78 dirt
setblock ~172 ~120 ~79 dirt
setblock ~172 ~120 ~80 dirt
setblock ~172 ~120 ~81 dirt
setblock ~172 ~120 ~94 dirt
setblock ~172 ~120 ~99 dirt
setblock ~172 ~120 ~100 dirt
setblock ~172 ~120 ~101 dirt
setblock ~172 ~120 ~102 dirt
setblock ~172 ~120 ~103 dirt
setblock ~172 ~120 ~104 dirt
setblock ~172 ~120 ~105 dirt
setblock ~172 ~120 ~106 dirt
setblock ~172 ~120 ~107 dirt
setblock ~172 ~120 ~108 dirt
setblock ~172 ~120 ~109 dirt
setblock ~172 ~120 ~110 dirt
setblock ~172 ~120 ~111 dirt
setblock ~172 ~120 ~112 dirt
setblock ~172 ~120 ~113 dirt
setblock ~172 ~120 ~114 dirt
setblock ~172 ~121 ~69 dirt
setblock ~172 ~121 ~70 dirt
setblock ~172 ~121 ~71 dirt
setblock ~172 ~121 ~72 dirt
setblock ~172 ~121 ~73 dirt
setblock ~172 ~121 ~74 dirt
setblock ~172 ~121 ~75 dirt
setblock ~172 ~121 ~76 dirt
setblock ~172 ~121 ~77 dirt
setblock ~172 ~121 ~78 dirt
setblock ~172 ~121 ~79 dirt
setblock ~172 ~121 ~80 dirt
setblock ~172 ~121 ~81 dirt
setblock ~172 ~121 ~82 dirt
setblock ~172 ~121 ~94 dirt
setblock ~172 ~121 ~98 dirt
setblock ~172 ~121 ~99 dirt
setblock ~172 ~121 ~100 dirt
setblock ~172 ~121 ~101 dirt
setblock ~172 ~121 ~102 dirt
setblock ~172 ~121 ~103 dirt
setblock ~172 ~121 ~104 dirt
setblock ~172 ~121 ~105 dirt
setblock ~172 ~121 ~106 dirt
setblock ~172 ~121 ~107 dirt
setblock ~172 ~121 ~108 dirt
setblock ~172 ~121 ~109 dirt
setblock ~172 ~121 ~110 dirt
setblock ~172 ~121 ~111 dirt
setblock ~172 ~121 ~112 dirt
setblock ~172 ~121 ~113 dirt
setblock ~172 ~121 ~114 dirt
setblock ~172 ~121 ~115 dirt
setblock ~172 ~122 ~69 dirt
setblock ~172 ~122 ~70 dirt
setblock ~172 ~122 ~71 dirt
setblock ~172 ~122 ~72 dirt
setblock ~172 ~122 ~73 dirt
setblock ~172 ~122 ~74 dirt
setblock ~172 ~122 ~75 dirt
setblock ~172 ~122 ~76 dirt
setblock ~172 ~122 ~77 dirt
setblock ~172 ~122 ~78 dirt
setblock ~172 ~122 ~79 dirt
setblock ~172 ~122 ~80 dirt
setblock ~172 ~122 ~81 dirt
setblock ~172 ~122 ~82 dirt
setblock ~172 ~122 ~94 dirt
setblock ~172 ~122 ~98 dirt
setblock ~172 ~122 ~99 dirt
setblock ~172 ~122 ~100 dirt
setblock ~172 ~122 ~101 dirt
setblock ~172 ~122 ~102 dirt
setblock ~172 ~122 ~103 dirt
setblock ~172 ~122 ~104 dirt
setblock ~172 ~122 ~105 dirt
setblock ~172 ~122 ~106 dirt
setblock ~172 ~122 ~107 dirt
setblock ~172 ~122 ~108 dirt
setblock ~172 ~122 ~109 dirt
setblock ~172 ~122 ~110 dirt
setblock ~172 ~122 ~111 dirt
setblock ~172 ~122 ~112 dirt
setblock ~172 ~122 ~113 dirt
setblock ~172 ~122 ~114 dirt
setblock ~172 ~122 ~115 dirt
setblock ~172 ~123 ~69 dirt
setblock ~172 ~123 ~70 dirt
setblock ~172 ~123 ~71 dirt
setblock ~172 ~123 ~72 dirt
setblock ~172 ~123 ~73 dirt
setblock ~172 ~123 ~74 dirt
setblock ~172 ~123 ~75 dirt
setblock ~172 ~123 ~76 dirt
setblock ~172 ~123 ~77 dirt
setblock ~172 ~123 ~78 dirt
setblock ~172 ~123 ~79 dirt
setblock ~172 ~123 ~80 dirt
setblock ~172 ~123 ~81 dirt
setblock ~172 ~123 ~82 dirt
setblock ~172 ~123 ~94 dirt
setblock ~172 ~123 ~98 dirt
setblock ~172 ~123 ~99 dirt
setblock ~172 ~123 ~100 dirt
setblock ~172 ~123 ~101 dirt
setblock ~172 ~123 ~102 dirt
setblock ~172 ~123 ~103 dirt
setblock ~172 ~123 ~104 dirt
setblock ~172 ~123 ~105 dirt
setblock ~172 ~123 ~106 dirt
setblock ~172 ~123 ~107 dirt
setblock ~172 ~123 ~108 dirt
setblock ~172 ~123 ~109 grass_block
setblock ~172 ~123 ~110 grass_block
setblock ~172 ~123 ~111 grass_block
setblock ~172 ~123 ~112 dirt
setblock ~172 ~123 ~113 dirt
setblock ~172 ~123 ~114 dirt
setblock ~172 ~123 ~115 dirt
setblock ~172 ~124 ~69 dirt
setblock ~172 ~124 ~70 dirt
setblock ~172 ~124 ~71 dirt
setblock ~172 ~124 ~72 dirt
setblock ~172 ~124 ~73 dirt
setblock ~172 ~124 ~74 dirt
setblock ~172 ~124 ~75 dirt
setblock ~172 ~124 ~76 dirt
setblock ~172 ~124 ~77 dirt
setblock ~172 ~124 ~78 dirt
setblock ~172 ~124 ~79 dirt
setblock ~172 ~124 ~80 dirt
setblock ~172 ~124 ~81 dirt
setblock ~172 ~124 ~82 dirt
setblock ~172 ~124 ~94 dirt
setblock ~172 ~124 ~98 dirt
setblock ~172 ~124 ~99 dirt
setblock ~172 ~124 ~100 dirt
setblock ~172 ~124 ~101 dirt
setblock ~172 ~124 ~102 dirt
setblock ~172 ~124 ~103 dirt
setblock ~172 ~124 ~104 dirt
setblock ~172 ~124 ~105 dirt
setblock ~172 ~124 ~106 dirt
setblock ~172 ~124 ~107 grass_block
setblock ~172 ~124 ~108 grass_block
setblock ~172 ~124 ~111 short_grass
setblock ~172 ~124 ~112 grass_block
setblock ~172 ~124 ~113 grass_block
setblock ~172 ~124 ~114 grass_block
setblock ~172 ~124 ~115 dirt
setblock ~172 ~125 ~69 grass_block
setblock ~172 ~125 ~70 grass_block
setblock ~172 ~125 ~71 grass_block
setblock ~172 ~125 ~72 grass_block
setblock ~172 ~125 ~73 grass_block
setblock ~172 ~125 ~74 grass_block
setblock ~172 ~125 ~75 grass_block
setblock ~172 ~125 ~76 grass_block
setblock ~172 ~125 ~77 grass_block
setblock ~172 ~125 ~78 grass_block
setblock ~172 ~125 ~79 grass_block
setblock ~172 ~125 ~80 grass_block
setblock ~172 ~125 ~81 grass_block
setblock ~172 ~125 ~82 grass_block
setblock ~172 ~125 ~94 grass_block
setblock ~172 ~125 ~98 dirt
setblock ~172 ~125 ~99 dirt
setblock ~172 ~125 ~100 dirt
setblock ~172 ~125 ~101 dirt
setblock ~172 ~125 ~102 dirt
setblock ~172 ~125 ~103 dirt
setblock ~172 ~125 ~104 dirt
setblock ~172 ~125 ~105 grass_block
setblock ~172 ~125 ~106 grass_block
setblock ~172 ~125 ~113 short_grass
setblock ~172 ~125 ~115 grass_block
setblock ~172 ~126 ~76 short_grass
setblock ~172 ~126 ~77 short_grass
setblock ~172 ~126 ~80 poppy
setblock ~172 ~126 ~98 dirt
setblock ~172 ~126 ~99 dirt
setblock ~172 ~126 ~100 dirt
setblock ~172 ~126 ~101 dirt
setblock ~172 ~126 ~102 dirt
setblock ~172 ~126 ~103 dirt
setblock ~172 ~126 ~104 grass_block
setblock ~172 ~127 ~98 dirt
setblock ~172 ~127 ~99 dirt
setblock ~172 ~127 ~100 dirt
setblock ~172 ~127 ~101 dirt
setblock ~172 ~127 ~102 dirt
setblock ~172 ~127 ~103 grass_block
setblock ~172 ~128 ~98 dirt
setblock ~172 ~128 ~99 dirt
setblock ~172 ~128 ~100 dirt
setblock ~172 ~128 ~101 dirt
setblock ~172 ~128 ~102 dirt
setblock ~172 ~129 ~98 grass_block
setblock ~172 ~129 ~99 dirt
setblock ~172 ~129 ~100 dirt
setblock ~172 ~129 ~101 dirt
setblock ~172 ~129 ~102 grass_block
setblock ~172 ~130 ~99 dirt
setblock ~172 ~130 ~100 dirt
setblock ~172 ~130 ~101 dirt
setblock ~172 ~131 ~99 grass_block
setblock ~172 ~131 ~100 dirt
setblock ~172 ~131 ~101 grass_block
setblock ~172 ~132 ~100 grass_block
setblock ~172 ~133 ~91 jungle_leaves[persistent=true]
setblock ~172 ~133 ~92 oak_leaves[persistent=true]
setblock ~172 ~133 ~93 jungle_leaves[persistent=true]
setblock ~172 ~134 ~91 jungle_leaves[persistent=true]
setblock ~172 ~134 ~92 oak_leaves[persistent=true]
setblock ~172 ~134 ~93 oak_leaves[persistent=true]
setblock ~172 ~135 ~91 oak_leaves[persistent=true]
setblock ~172 ~135 ~92 jungle_leaves[persistent=true]
setblock ~172 ~135 ~93 oak_leaves[persistent=true]
setblock ~173 ~115 ~103 dirt
setblock ~173 ~115 ~105 dirt
setblock ~173 ~116 ~102 dirt
setblock ~173 ~116 ~103 dirt
setblock ~173 ~116 ~104 dirt
setblock ~173 ~116 ~105 dirt
setblock ~173 ~116 ~106 dirt
setblock ~173 ~117 ~102 dirt
setblock ~173 ~117 ~103 dirt
setblock ~173 ~117 ~104 dirt
setblock ~173 ~117 ~105 dirt
setblock ~173 ~117 ~106 dirt
setblock ~173 ~117 ~107 dirt
setblock ~173 ~118 ~101 dirt
setblock ~173 ~118 ~102 dirt
setblock ~173 ~118 ~103 dirt
setblock ~173 ~118 ~104 dirt
setblock ~173 ~118 ~105 dirt
setblock ~173 ~118 ~106 dirt
setblock ~173 ~118 ~107 dirt
setblock ~173 ~118 ~112 dirt
setblock ~173 ~119 ~78 dirt
setblock ~173 ~119 ~101 dirt
setblock ~173 ~119 ~102 dirt
setblock ~173 ~119 ~103 dirt
setblock ~173 ~119 ~104 dirt
setblock ~173 ~119 ~105 dirt
setblock ~173 ~119 ~106 dirt
setblock ~173 ~119 ~107 dirt
setblock ~173 ~119 ~108 dirt
setblock ~173 ~119 ~111 dirt
setblock ~173 ~119 ~112 dirt
setblock ~173 ~119 ~113 dirt
setblock ~173 ~120 ~78 dirt
setblock ~173 ~120 ~79 dirt
setblock ~173 ~120 ~80 dirt
setblock ~173 ~120 ~100 dirt
setblock ~173 ~120 ~101 dirt
setblock ~173 ~120 ~102 dirt
setblock ~173 ~120 ~103 dirt
setblock ~173 ~120 ~104 dirt
setblock ~173 ~120 ~105 dirt
setblock ~173 ~120 ~106 dirt
setblock ~173 ~120 ~107 dirt
setblock ~173 ~120 ~108 dirt
setblock ~173 ~120 ~109 dirt
setblock ~173 ~120 ~110 dirt
setblock ~173 ~120 ~111 dirt
setblock ~173 ~120 ~112 dirt
setblock ~173 ~120 ~113 dirt
setblock ~173 ~121 ~74 dirt
setblock ~173 ~121 ~75 dirt
setblock ~173 ~121 ~77 dirt
setblock ~173 ~121 ~78 dirt
setblock ~173 ~121 ~79 dirt
setblock ~173 ~121 ~80 dirt
setblock ~173 ~121 ~81 dirt
setblock ~173 ~121 ~99 dirt
setblock ~173 ~121 ~100 dirt
setblock ~173 ~121 ~101 dirt
setblock ~173 ~121 ~102 dirt
setblock ~173 ~121 ~103 dirt
setblock ~173 ~121 ~104 dirt
setblock ~173 ~121 ~105 dirt
setblock ~173 ~121 ~106 dirt
setblock ~173 ~121 ~107 dirt
setblock ~173 ~121 ~108 dirt
setblock ~173 ~121 ~109 dirt
setblock ~173 ~121 ~110 dirt
setblock ~173 ~121 ~111 dirt
setblock ~173 ~121 ~112 dirt
setblock ~173 ~121 ~113 dirt
setblock ~173 ~121 ~114 dirt
setblock ~173 ~122 ~74 dirt
setblock ~173 ~122 ~75 dirt
setblock ~173 ~122 ~77 dirt
setblock ~173 ~122 ~78 dirt
setblock ~173 ~122 ~79 dirt
setblock ~173 ~122 ~80 dirt
setblock ~173 ~122 ~81 dirt
setblock ~173 ~122 ~99 dirt
setblock ~173 ~122 ~100 dirt
setblock ~173 ~122 ~101 dirt
setblock ~173 ~122 ~102 dirt
setblock ~173 ~122 ~103 dirt
setblock ~173 ~122 ~104 dirt
setblock ~173 ~122 ~105 dirt
setblock ~173 ~122 ~106 dirt
setblock ~173 ~122 ~107 dirt
setblock ~173 ~122 ~108 dirt
setblock ~173 ~122 ~109 dirt
setblock ~173 ~122 ~110 dirt
setblock ~173 ~122 ~111 dirt
setblock ~173 ~122 ~112 dirt
setblock ~173 ~122 ~113 dirt
setblock ~173 ~122 ~114 dirt
setblock ~173 ~123 ~74 dirt
setblock ~173 ~123 ~75 dirt
setblock ~173 ~123 ~77 dirt
setblock ~173 ~123 ~78 dirt
setblock ~173 ~123 ~79 dirt
setblock ~173 ~123 ~80 dirt
setblock ~173 ~123 ~81 dirt
setblock ~173 ~123 ~99 dirt
setblock ~173 ~123 ~100 dirt
setblock ~173 ~123 ~101 dirt
setblock ~173 ~123 ~102 dirt
setblock ~173 ~123 ~103 dirt
setblock ~173 ~123 ~104 dirt
setblock ~173 ~123 ~105 dirt
setblock ~173 ~123 ~106 dirt
setblock ~173 ~123 ~107 dirt
setblock ~173 ~123 ~108 dirt
setblock ~173 ~123 ~109 dirt
setblock ~173 ~123 ~110 grass_block
setblock ~173 ~123 ~111 dirt
setblock ~173 ~123 ~112 dirt
setblock ~173 ~123 ~113 dirt
setblock ~173 ~123 ~114 dirt
setblock ~173 ~124 ~74 dirt
setblock ~173 ~124 ~75 dirt
setblock ~173 ~124 ~77 dirt
setblock ~173 ~124 ~78 dirt
setblock ~173 ~124 ~79 dirt
setblock ~173 ~124 ~80 dirt
setblock ~173 ~124 ~81 dirt
setblock ~173 ~124 ~99 dirt
setblock ~173 ~124 ~100 dirt
setblock ~173 ~124 ~101 dirt
setblock ~173 ~124 ~102 dirt
setblock ~173 ~124 ~103 dirt
setblock ~173 ~124 ~104 dirt
setblock ~173 ~124 ~105 dirt
setblock ~173 ~124 ~106 dirt
setblock ~173 ~124 ~107 dirt
setblock ~173 ~124 ~108 grass_block
setblock ~173 ~124 ~109 grass_block
setblock ~173 ~124 ~111 grass_block
setblock ~173 ~124 ~112 grass_block
setblock ~173 ~124 ~113 grass_block
setblock ~173 ~124 ~114 dirt
setblock ~173 ~125 ~74 grass_block
setblock ~173 ~125 ~75 grass_block
setblock ~173 ~125 ~77 grass_block
setblock ~173 ~125 ~78 grass_block
setblock ~173 ~125 ~79 grass_block
setblock ~173 ~125 ~80 grass_block
setblock ~173 ~125 ~81 grass_block
setblock ~173 ~125 ~99 dirt
setblock ~173 ~125 ~100 dirt
setblock ~173 ~125 ~101 dirt
setblock ~173 ~125 ~102 dirt
setblock ~173 ~125 ~103 dirt
setblock ~173 ~125 ~104 dirt
setblock ~173 ~125 ~105 dirt
setblock ~173 ~125 ~106 grass_block
setblock ~173 ~125 ~107 grass_block
setblock ~173 ~125 ~108 fern
setblock ~173 ~125 ~109 short_grass
setblock ~173 ~125 ~112 short_grass
setblock ~173 ~125 ~114 grass_block
setblock ~173 ~126 ~79 short_grass
setblock ~173 ~126 ~81 short_grass
setblock ~173 ~126 ~99 dirt
setblock ~173 ~126 ~100 dirt
setblock ~173 ~126 ~101 dirt
setblock ~173 ~126 ~102 dirt
setblock ~173 ~126 ~103 dirt
setblock ~173 ~126 ~104 grass_block
setblock ~173 ~126 ~105 grass_block
setblock ~173 ~127 ~99 dirt
setblock ~173 ~127 ~100 dirt
setblock ~173 ~127 ~101 dirt
setblock ~173 ~127 ~102 dirt
setblock ~173 ~127 ~103 grass_block
setblock ~173 ~127 ~104 fern
setblock ~173 ~127 ~105 poppy
setblock ~173 ~128 ~99 dirt
setblock ~173 ~128 ~100 dirt
setblock ~173 ~128 ~101 dirt
setblock ~173 ~128 ~102 grass_block
setblock ~173 ~129 ~99 dirt
setblock ~173 ~129 ~100 dirt
setblock ~173 ~129 ~101 dirt
setblock ~173 ~130 ~99 grass_block
setblock ~173 ~130 ~100 dirt
setblock ~173 ~130 ~101 grass_block
setblock ~173 ~131 ~100 grass_block
setblock ~173 ~133 ~91 jungle_leaves[persistent=true]
setblock ~173 ~133 ~92 oak_leaves[persistent=true]
setblock ~173 ~133 ~93 oak_leaves[persistent=true]
setblock ~173 ~134 ~91 oak_leaves[persistent=true]
setblock ~173 ~134 ~93 jungle_leaves[persistent=true]
setblock ~173 ~135 ~91 oak_leaves[persistent=true]
setblock ~173 ~135 ~92 oak_leaves[persistent=true]
setblock ~173 ~135 ~93 oak_leaves[persistent=true]
setblock ~174 ~116 ~103 dirt
setblock ~174 ~116 ~105 dirt
setblock ~174 ~117 ~103 dirt
setblock ~174 ~117 ~104 dirt
setblock ~174 ~117 ~105 dirt
setblock ~174 ~118 ~102 dirt
setblock ~174 ~118 ~103 dirt
setblock ~174 ~118 ~104 dirt
setblock ~174 ~118 ~105 dirt
setblock ~174 ~118 ~106 dirt
setblock ~174 ~119 ~102 dirt
setblock ~174 ~119 ~103 dirt
setblock ~174 ~119 ~104 dirt
setblock ~174 ~119 ~105 dirt
setblock ~174 ~119 ~106 dirt
setblock ~174 ~119 ~107 dirt
setblock ~174 ~119 ~112 dirt
setblock ~174 ~120 ~102 dirt
setblock ~174 ~120 ~103 dirt
setblock ~174 ~120 ~104 dirt
setblock ~174 ~120 ~105 dirt
setblock ~174 ~120 ~106 dirt
setblock ~174 ~120 ~107 dirt
setblock ~174 ~120 ~108 dirt
setblock ~174 ~120 ~112 dirt
setblock ~174 ~121 ~78 dirt
setblock ~174 ~121 ~79 dirt
setblock ~174 ~121 ~80 dirt
setblock ~174 ~121 ~100 dirt
setblock ~174 ~121 ~101 dirt
setblock ~174 ~121 ~102 dirt
setblock ~174 ~121 ~103 dirt
setblock ~174 ~121 ~104 dirt
setblock ~174 ~121 ~105 dirt
setblock ~174 ~121 ~106 dirt
setblock ~174 ~121 ~107 dirt
setblock ~174 ~121 ~108 dirt
setblock ~174 ~121 ~109 dirt
setblock ~174 ~121 ~111 dirt
setblock ~174 ~121 ~112 dirt
setblock ~174 ~121 ~113 dirt
setblock ~174 ~122 ~78 dirt
setblock ~174 ~122 ~79 dirt
setblock ~174 ~122 ~80 dirt
setblock ~174 ~122 ~100 dirt
setblock ~174 ~122 ~101 dirt
setblock ~174 ~122 ~102 dirt
setblock ~174 ~122 ~103 dirt
setblock ~174 ~122 ~104 dirt
setblock ~174 ~122 ~105 dirt
setblock ~174 ~122 ~106 dirt
setblock ~174 ~122 ~107 dirt
setblock ~174 ~122 ~108 dirt
setblock ~174 ~122 ~109 dirt
setblock ~174 ~122 ~111 dirt
setblock ~174 ~122 ~112 dirt
setblock ~174 ~122 ~113 dirt
setblock ~174 ~123 ~78 dirt
setblock ~174 ~123 ~79 dirt
setblock ~174 ~123 ~80 dirt
setblock ~174 ~123 ~100 dirt
setblock ~174 ~123 ~101 dirt
setblock ~174 ~123 ~102 dirt
setblock ~174 ~123 ~103 dirt
setblock ~174 ~123 ~104 dirt
setblock ~174 ~123 ~105 dirt
setblock ~174 ~123 ~106 dirt
setblock ~174 ~123 ~107 dirt
setblock ~174 ~123 ~108 dirt
setblock ~174 ~123 ~109 dirt
setblock ~174 ~123 ~111 dirt
setblock ~174 ~123 ~112 dirt
setblock ~174 ~123 ~113 dirt
setblock ~174 ~124 ~78 dirt
setblock ~174 ~124 ~79 dirt
setblock ~174 ~124 ~80 dirt
setblock ~174 ~124 ~100 dirt
setblock ~174 ~124 ~101 dirt
setblock ~174 ~124 ~102 dirt
setblock ~174 ~124 ~103 dirt
setblock ~174 ~124 ~104 dirt
setblock ~174 ~124 ~105 dirt
setblock ~174 ~124 ~106 dirt
setblock ~174 ~124 ~107 dirt
setblock ~174 ~124 ~108 dirt
setblock ~174 ~124 ~109 grass_block
setblock ~174 ~124 ~111 grass_block
setblock ~174 ~124 ~112 grass_block
setblock ~174 ~124 ~113 dirt
setblock ~174 ~125 ~78 grass_block
setblock ~174 ~125 ~79 grass_block
setblock ~174 ~125 ~80 grass_block
setblock ~174 ~125 ~100 dirt
setblock ~174 ~125 ~101 dirt
setblock ~174 ~125 ~102 dirt
setblock ~174 ~125 ~103 dirt
setblock ~174 ~125 ~104 dirt
setblock ~174 ~125 ~105 dirt
setblock ~174 ~125 ~106 grass_block
setblock ~174 ~125 ~107 grass_block
setblock ~174 ~125 ~108 grass_block
setblock ~174 ~125 ~109 short_grass
setblock ~174 ~125 ~113 grass_block
setblock ~174 ~126 ~100 dirt
setblock ~174 ~126 ~101 dirt
setblock ~174 ~126 ~102 dirt
setblock ~174 ~126 ~103 dirt
setblock ~174 ~126 ~104 grass_block
setblock ~174 ~126 ~105 grass_block
setblock ~174 ~126 ~108 short_grass
setblock ~174 ~126 ~113 fern
setblock ~174 ~127 ~100 dirt
setblock ~174 ~127 ~101 dirt
setblock ~174 ~127 ~102 dirt
setblock ~174 ~127 ~103 grass_block
setblock ~174 ~128 ~100 dirt
setblock ~174 ~128 ~101 dirt
setblock ~174 ~128 ~102 grass_block
setblock ~174 ~129 ~100 dirt
setblock ~174 ~129 ~101 grass_block
setblock ~174 ~130 ~100 dirt
setblock ~174 ~130 ~101 short_grass
setblock ~174 ~131 ~100 grass_block
setblock ~174 ~132 ~100 fern
setblock ~175 ~119 ~103 dirt
setblock ~175 ~119 ~106 dirt
setblock ~175 ~120 ~103 dirt
setblock ~175 ~120 ~105 dirt
setblock ~175 ~120 ~106 dirt
setblock ~175 ~120 ~107 dirt
setblock ~175 ~121 ~102 dirt
setblock ~175 ~121 ~103 dirt
setblock ~175 ~121 ~104 dirt
setblock ~175 ~121 ~105 dirt
setblock ~175 ~121 ~106 dirt
setblock ~175 ~121 ~107 dirt
setblock ~175 ~121 ~108 dirt
setblock ~175 ~121 ~112 dirt
setblock ~175 ~122 ~102 dirt
setblock ~175 ~122 ~103 dirt
setblock ~175 ~122 ~104 dirt
setblock ~175 ~122 ~105 dirt
setblock ~175 ~122 ~106 dirt
setblock ~175 ~122 ~107 dirt
setblock ~175 ~122 ~108 dirt
setblock ~175 ~122 ~112 dirt
setblock ~175 ~123 ~102 dirt
setblock ~175 ~123 ~103 dirt
setblock ~175 ~123 ~104 dirt
setblock ~175 ~123 ~105 dirt
setblock ~175 ~123 ~106 dirt
setblock ~175 ~123 ~107 dirt
setblock ~175 ~123 ~108 dirt
setblock ~175 ~123 ~112 dirt
setblock ~175 ~124 ~102 dirt
setblock ~175 ~124 ~103 dirt
setblock ~175 ~124 ~104 dirt
setblock ~175 ~124 ~105 dirt
setblock ~175 ~124 ~106 dirt
setblock ~175 ~124 ~107 dirt
setblock ~175 ~124 ~108 dirt
setblock ~175 ~124 ~112 dirt
setblock ~175 ~125 ~102 dirt
setblock ~175 ~125 ~103 dirt
setblock ~175 ~125 ~104 dirt
setblock ~175 ~125 ~105 dirt
setblock ~175 ~125 ~106 dirt
setblock ~175 ~125 ~107 grass_block
setblock ~175 ~125 ~108 grass_block
setblock ~175 ~125 ~112 grass_block
setblock ~175 ~126 ~102 dirt
setblock ~175 ~126 ~103 dirt
setblock ~175 ~126 ~104 dirt
setblock ~175 ~126 ~105 grass_block
setblock ~175 ~126 ~106 grass_block
setblock ~175 ~127 ~102 dirt
setblock ~175 ~127 ~103 grass_block
setblock ~175 ~127 ~104 grass_block
setblock ~175 ~127 ~106 short_grass
setblock ~175 ~128 ~102 grass_block
setblock ~176 ~121 ~107 dirt
setblock ~176 ~122 ~107 dirt
setblock ~176 ~123 ~107 dirt
setblock ~176 ~124 ~107 dirt
setblock ~176 ~125 ~107 dirt
setblock ~176 ~126 ~107 grass_block
setblock ~199 ~200 ~199 gold_block
