setblock ~32 ~119 ~97 dirt
setblock ~32 ~119 ~98 dirt
setblock ~32 ~119 ~99 dirt
setblock ~32 ~119 ~100 dirt
setblock ~32 ~119 ~101 dirt
setblock ~32 ~119 ~102 dirt
setblock ~32 ~119 ~103 dirt
setblock ~32 ~119 ~104 dirt
setblock ~32 ~119 ~105 dirt
setblock ~32 ~119 ~106 dirt
setblock ~32 ~119 ~107 dirt
setblock ~32 ~119 ~108 dirt
setblock ~32 ~119 ~109 dirt
setblock ~32 ~119 ~115 dirt
setblock ~32 ~119 ~116 dirt
setblock ~32 ~119 ~117 dirt
setblock ~32 ~119 ~118 dirt
setblock ~32 ~119 ~119 dirt
setblock ~32 ~119 ~120 dirt
setblock ~32 ~120 ~62 dirt
setblock ~32 ~120 ~65 dirt
setblock ~32 ~120 ~66 dirt
setblock ~32 ~120 ~67 dirt
setblock ~32 ~120 ~84 dirt
setblock ~32 ~120 ~86 dirt
setblock ~32 ~120 ~87 dirt
setblock ~32 ~120 ~88 dirt
setblock ~32 ~120 ~89 dirt
setblock ~32 ~120 ~90 dirt
setblock ~32 ~120 ~91 dirt
setblock ~32 ~120 ~92 dirt
setblock ~32 ~120 ~93 dirt
setblock ~32 ~120 ~94 dirt
setblock ~32 ~120 ~95 dirt
setblock ~32 ~120 ~96 dirt
setblock ~32 ~120 ~97 dirt
setblock ~32 ~120 ~98 dirt
setblock ~32 ~120 ~99 dirt
setblock ~32 ~120 ~100 dirt
setblock ~32 ~120 ~101 dirt
setblock ~32 ~120 ~102 dirt
setblock ~32 ~120 ~103 dirt
setblock ~32 ~120 ~104 dirt
setblock ~32 ~120 ~105 dirt
setblock ~32 ~120 ~106 dirt
setblock ~32 ~120 ~107 dirt
setblock ~32 ~120 ~108 dirt
setblock ~32 ~120 ~109 dirt
setblock ~32 ~120 ~110 dirt
setblock ~32 ~120 ~114 dirt
setblock ~32 ~120 ~115 dirt
setblock ~32 ~120 ~116 dirt
setblock ~32 ~120 ~117 dirt
setblock ~32 ~120 ~118 dirt
setblock ~32 ~120 ~119 dirt
setblock ~32 ~120 ~120 dirt
setblock ~32 ~120 ~121 dirt
setblock ~32 ~121 ~61 dirt
setblock ~32 ~121 ~62 dirt
setblock ~32 ~121 ~63 dirt
setblock ~32 ~121 ~65 dirt
setblock ~32 ~121 ~66 dirt
setblock ~32 ~121 ~67 dirt
setblock ~32 ~121 ~68 dirt
setblock ~32 ~121 ~69 dirt
setblock ~32 ~121 ~71 dirt
setblock ~32 ~121 ~78 dirt
setblock ~32 ~121 ~83 dirt
setblock ~32 ~121 ~84 dirt
setblock ~32 ~121 ~85 dirt
setblock ~32 ~121 ~86 dirt
setblock ~32 ~121 ~87 dirt
setblock ~32 ~121 ~88 dirt
setblock ~32 ~121 ~89 dirt
setblock ~32 ~121 ~90 dirt
setblock ~32 ~121 ~91 dirt
setblock ~32 ~121 ~92 dirt
setblock ~32 ~121 ~93 dirt
setblock ~32 ~121 ~94 dirt
setblock ~32 ~121 ~95 dirt
setblock ~32 ~121 ~96 dirt
setblock ~32 ~121 ~97 dirt
setblock ~32 ~121 ~98 dirt
setblock ~32 ~121 ~99 dirt
setblock ~32 ~121 ~100 dirt
setblock ~32 ~121 ~101 dirt
setblock ~32 ~121 ~102 dirt
setblock ~32 ~121 ~103 dirt
setblock ~32 ~121 ~104 dirt
setblock ~32 ~121 ~105 dirt
setblock ~32 ~121 ~106 dirt
setblock ~32 ~121 ~107 dirt
setblock ~32 ~121 ~108 dirt
setblock ~32 ~121 ~109 dirt
setblock ~32 ~121 ~110 dirt
setblock ~32 ~121 ~111 dirt
setblock ~32 ~121 ~113 dirt
setblock ~32 ~121 ~114 dirt
setblock ~32 ~121 ~115 dirt
setblock ~32 ~121 ~116 dirt
setblock ~32 ~121 ~117 dirt
setblock ~32 ~121 ~118 dirt
setblock ~32 ~121 ~119 dirt
setblock ~32 ~121 ~120 dirt
setblock ~32 ~121 ~121 dirt
setblock ~32 ~122 ~61 dirt
setblock ~32 ~122 ~62 dirt
setblock ~32 ~122 ~63 dirt
setblock ~32 ~122 ~65 dirt
setblock ~32 ~122 ~66 dirt
setblock ~32 ~122 ~67 dirt
setblock ~32 ~122 ~68 dirt
setblock ~32 ~122 ~69 dirt
setblock ~32 ~122 ~71 dirt
setblock ~32 ~122 ~78 dirt
setblock ~32 ~122 ~83 dirt
setblock ~32 ~122 ~84 dirt
setblock ~32 ~122 ~85 dirt
setblock ~32 ~122 ~86 dirt
setblock ~32 ~122 ~87 dirt
setblock ~32 ~122 ~88 dirt
setblock ~32 ~122 ~89 dirt
setblock ~32 ~122 ~90 dirt
setblock ~32 ~122 ~91 dirt
setblock ~32 ~122 ~92 dirt
setblock ~32 ~122 ~93 dirt
setblock ~32 ~122 ~94 dirt
setblock ~32 ~122 ~95 dirt
setblock ~32 ~122 ~96 dirt
setblock ~32 ~122 ~97 dirt
setblock ~32 ~122 ~98 dirt
setblock ~32 ~122 ~99 dirt
setblock ~32 ~122 ~100 dirt
setblock ~32 ~122 ~101 dirt
setblock ~32 ~122 ~102 dirt
setblock ~32 ~122 ~103 dirt
setblock ~32 ~122 ~104 dirt
setblock ~32 ~122 ~105 dirt
setblock ~32 ~122 ~106 dirt
setblock ~32 ~122 ~107 dirt
setblock ~32 ~122 ~108 dirt
setblock ~32 ~122 ~109 dirt
setblock ~32 ~122 ~110 dirt
setblock ~32 ~122 ~111 dirt
setblock ~32 ~122 ~113 dirt
setblock ~32 ~122 ~114 dirt
setblock ~32 ~122 ~115 dirt
setblock ~32 ~122 ~116 dirt
setblock ~32 ~122 ~117 dirt
setblock ~32 ~122 ~118 dirt
setblock ~32 ~122 ~119 dirt
setblock ~32 ~122 ~120 dirt
setblock ~32 ~122 ~121 dirt
setblock ~32 ~123 ~61 dirt
setblock ~32 ~123 ~62 dirt
setblock ~32 ~123 ~63 dirt
setblock ~32 ~123 ~65 dirt
setblock ~32 ~123 ~66 dirt
setblock ~32 ~123 ~67 dirt
setblock ~32 ~123 ~68 dirt
setblock ~32 ~123 ~69 dirt
setblock ~32 ~123 ~71 dirt
setblock ~32 ~123 ~78 dirt
setblock ~32 ~123 ~83 dirt
setblock ~32 ~123 ~84 dirt
setblock ~32 ~123 ~85 dirt
setblock ~32 ~123 ~86 dirt
setblock ~32 ~123 ~87 dirt
setblock ~32 ~123 ~88 dirt
setblock ~32 ~123 ~89 grass_block
setblock ~32 ~123 ~90 grass_block
setblock ~32 ~123 ~91 grass_block
setblock ~32 ~123 ~92 dirt
setblock ~32 ~123 ~93 dirt
setblock ~32 ~123 ~94 dirt
setblock ~32 ~123 ~95 dirt
setblock ~32 ~123 ~96 dirt
setblock ~32 ~123 ~97 dirt
setblock ~32 ~123 ~98 dirt
setblock ~32 ~123 ~99 dirt
setblock ~32 ~123 ~100 dirt
setblock ~32 ~123 ~101 dirt
setblock ~32 ~123 ~102 dirt
setblock ~32 ~123 ~103 dirt
setblock ~32 ~123 ~104 dirt
setblock ~32 ~123 ~105 dirt
setblock ~32 ~123 ~106 dirt
setblock ~32 ~123 ~107 dirt
setblock ~32 ~123 ~108 dirt
setblock ~32 ~123 ~109 dirt
setblock ~32 ~123 ~110 dirt
setblock ~32 ~123 ~111 dirt
setblock ~32 ~123 ~113 dirt
setblock ~32 ~123 ~114 dirt
setblock ~32 ~123 ~115 dirt
setblock ~32 ~123 ~116 dirt
setblock ~32 ~123 ~117 dirt
setblock ~32 ~123 ~118 dirt
setblock ~32 ~123 ~119 dirt
setblock ~32 ~123 ~120 dirt
setblock ~32 ~123 ~121 dirt
setblock ~32 ~124 ~61 dirt
setblock ~32 ~124 ~62 dirt
setblock ~32 ~124 ~63 dirt
setblock ~32 ~124 ~65 dirt
setblock ~32 ~124 ~66 dirt
setblock ~32 ~124 ~67 dirt
setblock ~32 ~124 ~68 dirt
setblock ~32 ~124 ~69 dirt
setblock ~32 ~124 ~71 dirt
setblock ~32 ~124 ~78 dirt
setblock ~32 ~124 ~83 grass_block
setblock ~32 ~124 ~84 grass_block
setblock ~32 ~124 ~85 grass_block
setblock ~32 ~124 ~86 grass_block
setblock ~32 ~124 ~87 grass_block
setblock ~32 ~124 ~88 grass_block
setblock ~32 ~124 ~90 short_grass
setblock ~32 ~124 ~91 short_grass
setblock ~32 ~124 ~92 grass_block
setblock ~32 ~124 ~93 grass_block
setblock ~32 ~124 ~94 grass_block
setblock ~32 ~124 ~95 grass_block
setblock ~32 ~124 ~96 grass_block
setblock ~32 ~124 ~97 grass_block
setblock ~32 ~124 ~98 dirt
setblock ~32 ~124 ~99 dirt
setblock ~32 ~124 ~100 dirt
setblock ~32 ~124 ~101 dirt
setblock ~32 ~124 ~102 dirt
setblock ~32 ~124 ~103 dirt
setblock ~32 ~124 ~104 grass_block
setblock ~32 ~124 ~105 grass_block
setblock ~32 ~124 ~106 grass_block
setblock ~32 ~124 ~107 grass_block
setblock ~32 ~124 ~108 grass_block
setblock ~32 ~124 ~109 grass_block
setblock ~32 ~124 ~110 grass_block
setblock ~32 ~124 ~111 grass_block
setblock ~32 ~124 ~113 dirt
setblock ~32 ~124 ~114 dirt
setblock ~32 ~124 ~115 dirt
setblock ~32 ~124 ~116 dirt
setblock ~32 ~124 ~117 dirt
setblock ~32 ~124 ~118 dirt
setblock ~32 ~124 ~119 dirt
setblock ~32 ~124 ~120 dirt
setblock ~32 ~124 ~121 dirt
setblock ~32 ~125 ~61 dirt
setblock ~32 ~125 ~62 dirt
setblock ~32 ~125 ~63 dirt
setblock ~32 ~125 ~65 dirt
setblock ~32 ~125 ~66 dirt
setblock ~32 ~125 ~67 dirt
setblock ~32 ~125 ~68 dirt
setblock ~32 ~125 ~69 dirt
setblock ~32 ~125 ~71 dirt
setblock ~32 ~125 ~78 grass_block
setblock ~32 ~125 ~98 grass_block
setblock ~32 ~125 ~99 grass_block
setblock ~32 ~125 ~100 grass_block
setblock ~32 ~125 ~101 grass_block
setblock ~32 ~125 ~102 grass_block
setblock ~32 ~125 ~103 grass_block
setblock ~32 ~125 ~105 short_grass
setblock ~32 ~125 ~113 grass_block
setblock ~32 ~125 ~114 grass_block
setblock ~32 ~125 ~115 dirt
setblock ~32 ~125 ~116 dirt
setblock ~32 ~125 ~117 dirt
setblock ~32 ~125 ~118 dirt
setblock ~32 ~125 ~119 dirt
setblock ~32 ~125 ~120 dirt
setblock ~32 ~125 ~121 dirt
setblock ~32 ~126 ~61 dirt
setblock ~32 ~126 ~62 dirt
setblock ~32 ~126 ~63 dirt
setblock ~32 ~126 ~65 dirt
setblock ~32 ~126 ~66 dirt
setblock ~32 ~126 ~67 dirt
setblock ~32 ~126 ~68 dirt
setblock ~32 ~126 ~69 dirt
setblock ~32 ~126 ~71 dirt
setblock ~32 ~126 ~78 short_grass
setblock ~32 ~126 ~103 short_grass
setblock ~32 ~126 ~115 grass_block
setblock ~32 ~126 ~116 grass_block
setblock ~32 ~126 ~117 dirt
setblock ~32 ~126 ~118 dirt
setblock ~32 ~126 ~119 dirt
setblock ~32 ~126 ~120 dirt
setblock ~32 ~126 ~121 dirt
setblock ~32 ~127 ~61 grass_block
setblock ~32 ~127 ~62 grass_block
setblock ~32 ~127 ~63 grass_block
setblock ~32 ~127 ~65 grass_block
setblock ~32 ~127 ~66 grass_block
setblock ~32 ~127 ~67 grass_block
setblock ~32 ~127 ~68 grass_block
setblock ~32 ~127 ~69 grass_block
setblock ~32 ~127 ~71 grass_block
setblock ~32 ~127 ~117 grass_block
setblock ~32 ~127 ~118 grass_block
setblock ~32 ~127 ~119 dirt
setblock ~32 ~127 ~120 dirt
setblock ~32 ~127 ~121 dirt
setblock ~32 ~128 ~61 poppy
setblock ~32 ~128 ~62 short_grass
setblock ~32 ~128 ~65 short_grass
setblock ~32 ~128 ~69 short_grass
setblock ~32 ~128 ~119 grass_block
setblock ~32 ~128 ~120 dirt
setblock ~32 ~128 ~121 grass_block
setblock ~32 ~129 ~120 grass_block
setblock ~32 ~129 ~121 short_grass
setblock ~32 ~130 ~120 short_grass
setblock ~33 ~110 ~102 dirt
setblock ~33 ~111 ~91 dirt
setblock ~33 ~111 ~92 dirt
setblock ~33 ~111 ~101 dirt
setblock ~33 ~111 ~102 dirt
setblock ~33 ~111 ~103 dirt
setblock ~33 ~111 ~118 dirt
setblock ~33 ~112 ~90 dirt
setblock ~33 ~112 ~91 dirt
setblock ~33 ~112 ~92 dirt
setblock ~33 ~112 ~93 dirt
setblock ~33 ~112 ~101 dirt
setblock ~33 ~112 ~102 dirt
setblock ~33 ~112 ~103 dirt
setblock ~33 ~112 ~118 dirt
setblock ~33 ~113 ~89 dirt
setblock ~33 ~113 ~90 dirt
setblock ~33 ~113 ~91 dirt
setblock ~33 ~113 ~92 dirt
setblock ~33 ~113 ~93 dirt
setblock ~33 ~113 ~94 dirt
setblock ~33 ~113 ~95 dirt
setblock ~33 ~113 ~101 dirt
setblock ~33 ~113 ~102 dirt
setblock ~33 ~113 ~103 dirt
setblock ~33 ~113 ~104 dirt
setblock ~33 ~113 ~117 dirt
setblock ~33 ~113 ~118 dirt
setblock ~33 ~113 ~119 dirt
setblock ~33 ~114 ~89 dirt
setblock ~33 ~114 ~90 dirt
setblock ~33 ~114 ~91 dirt
setblock ~33 ~114 ~92 dirt
setblock ~33 ~114 ~93 dirt
setblock ~33 ~114 ~94 dirt
setblock ~33 ~114 ~95 dirt
setblock ~33 ~114 ~100 dirt
setblock ~33 ~114 ~101 dirt
setblock ~33 ~114 ~102 dirt
setblock ~33 ~114 ~103 dirt
setblock ~33 ~114 ~104 dirt
setblock ~33 ~114 ~105 dirt
setblock ~33 ~114 ~117 dirt
setblock ~33 ~114 ~118 dirt
setblock ~33 ~114 ~119 dirt
setblock ~33 ~115 ~66 dirt
setblock ~33 ~115 ~89 dirt
setblock ~33 ~115 ~90 dirt
setblock ~33 ~115 ~91 dirt
setblock ~33 ~115 ~92 dirt
setblock ~33 ~115 ~93 dirt
setblock ~33 ~115 ~94 dirt
setblock ~33 ~115 ~95 dirt
setblock ~33 ~115 ~96 dirt
setblock ~33 ~115 ~98 dirt
setblock ~33 ~115 ~99 dirt
setblock ~33 ~115 ~100 dirt
setblock ~33 ~115 ~101 dirt
setblock ~33 ~115 ~102 dirt
setblock ~33 ~115 ~103 dirt
setblock ~33 ~115 ~104 dirt
setblock ~33 ~115 ~105 dirt
setblock ~33 ~115 ~117 dirt
setblock ~33 ~115 ~118 dirt
setblock ~33 ~115 ~119 dirt
setblock ~33 ~116 ~66 dirt
setblock ~33 ~116 ~88 dirt
setblock ~33 ~116 ~89 dirt
setblock ~33 ~116 ~90 dirt
setblock ~33 ~116 ~91 dirt
setblock ~33 ~116 ~92 dirt
setblock ~33 ~116 ~93 dirt
setblock ~33 ~116 ~94 dirt
setblock ~33 ~116 ~95 dirt
setblock ~33 ~116 ~96 dirt
setblock ~33 ~116 ~98 dirt
setblock ~33 ~116 ~99 dirt
setblock ~33 ~116 ~100 dirt
setblock ~33 ~116 ~101 dirt
setblock ~33 ~116 ~102 dirt
setblock ~33 ~116 ~103 dirt
setblock ~33 ~116 ~104 dirt
setblock ~33 ~116 ~105 dirt
setblock ~33 ~116 ~106 dirt
setblock ~33 ~116 ~116 dirt
setblock ~33 ~116 ~117 dirt
setblock ~33 ~116 ~118 dirt
setblock ~33 ~116 ~119 dirt
setblock ~33 ~116 ~120 dirt
setblock ~33 ~117 ~66 dirt
setblock ~33 ~117 ~68 dirt
setblock ~33 ~117 ~85 dirt
setblock ~33 ~117 ~86 dirt
setblock ~33 ~117 ~88 dirt
setblock ~33 ~117 ~89 dirt
setblock ~33 ~117 ~90 dirt
setblock ~33 ~117 ~91 dirt
setblock ~33 ~117 ~92 dirt
setblock ~33 ~117 ~93 dirt
setblock ~33 ~117 ~94 dirt
setblock ~33 ~117 ~95 dirt
setblock ~33 ~117 ~96 dirt
setblock ~33 ~117 ~97 dirt
setblock ~33 ~117 ~98 dirt
setblock ~33 ~117 ~99 dirt
setblock ~33 ~117 ~100 dirt
setblock ~33 ~117 ~101 dirt
setblock ~33 ~117 ~102 dirt
setblock ~33 ~117 ~103 dirt
setblock ~33 ~117 ~104 dirt
setblock ~33 ~117 ~105 dirt
setblock ~33 ~117 ~106 dirt
setblock ~33 ~117 ~116 dirt
setblock ~33 ~117 ~117 dirt
setblock ~33 ~117 ~118 dirt
setblock ~33 ~117 ~119 dirt
setblock ~33 ~117 ~120 dirt
setblock ~33 ~118 ~62 dirt
setblock ~33 ~118 ~65 dirt
setblock ~33 ~118 ~66 dirt
setblock ~33 ~118 ~67 dirt
setblock ~33 ~118 ~68 dirt
setblock ~33 ~118 ~69 dirt
setblock ~33 ~118 ~83 dirt
setblock ~33 ~118 ~84 dirt
setblock ~33 ~118 ~85 dirt
setblock ~33 ~118 ~86 dirt
setblock ~33 ~118 ~87 dirt
setblock ~33 ~118 ~88 dirt
setblock ~33 ~118 ~89 dirt
setblock ~33 ~118 ~90 dirt
setblock ~33 ~118 ~91 dirt
setblock ~33 ~118 ~92 dirt
setblock ~33 ~118 ~93 dirt
setblock ~33 ~118 ~94 dirt
setblock ~33 ~118 ~95 dirt
setblock ~33 ~118 ~96 dirt
setblock ~33 ~118 ~97 dirt
setblock ~33 ~118 ~98 dirt
setblock ~33 ~118 ~99 dirt
setblock ~33 ~118 ~100 dirt
setblock ~33 ~118 ~101 dirt
setblock ~33 ~118 ~102 dirt
setblock ~33 ~118 ~103 dirt
setblock ~33 ~118 ~104 dirt
setblock ~33 ~118 ~105 dirt
setblock ~33 ~118 ~106 dirt
setblock ~33 ~118 ~107 dirt
setblock ~33 ~118 ~108 dirt
setblock ~33 ~118 ~109 dirt
setblock ~33 ~118 ~115 dirt
setblock ~33 ~118 ~116 dirt
setblock ~33 ~118 ~117 dirt
setblock ~33 ~118 ~118 dirt
setblock ~33 ~118 ~119 dirt
setblock ~33 ~118 ~120 dirt
setblock ~33 ~119 ~61 dirt
setblock ~33 ~119 ~62 dirt
setblock ~33 ~119 ~63 dirt
setblock ~33 ~119 ~65 dirt
setblock ~33 ~119 ~66 dirt
setblock ~33 ~119 ~67 dirt
setblock ~33 ~119 ~68 dirt
setblock ~33 ~119 ~69 dirt
setblock ~33 ~119 ~70 dirt
setblock ~33 ~119 ~78 dirt
setblock ~33 ~119 ~83 dirt
setblock ~33 ~119 ~84 dirt
setblock ~33 ~119 ~85 dirt
setblock ~33 ~119 ~86 dirt
setblock ~33 ~119 ~87 dirt
setblock ~33 ~119 ~88 dirt
setblock ~33 ~119 ~89 dirt
setblock ~33 ~119 ~90 dirt
setblock ~33 ~119 ~91 dirt
setblock ~33 ~119 ~92 dirt
setblock ~33 ~119 ~93 dirt
setblock ~33 ~119 ~94 dirt
setblock ~33 ~119 ~95 dirt
setblock ~33 ~119 ~96 dirt
setblock ~33 ~119 ~97 dirt
setblock ~33 ~119 ~98 dirt
setblock ~33 ~119 ~99 dirt
setblock ~33 ~119 ~100 dirt
setblock ~33 ~119 ~101 dirt
setblock ~33 ~119 ~102 dirt
setblock ~33 ~119 ~103 dirt
setblock ~33 ~119 ~104 dirt
setblock ~33 ~119 ~105 dirt
setblock ~33 ~119 ~106 dirt
setblock ~33 ~119 ~107 dirt
setblock ~33 ~119 ~108 dirt
setblock ~33 ~119 ~109 dirt
setblock ~33 ~119 ~110 dirt
setblock ~33 ~119 ~114 dirt
setblock ~33 ~119 ~115 dirt
setblock ~33 ~119 ~116 dirt
setblock ~33 ~119 ~117 dirt
setblock ~33 ~119 ~118 dirt
setblock ~33 ~119 ~119 dirt
setblock ~33 ~119 ~120 dirt
setblock ~33 ~119 ~121 dirt
setblock ~33 ~120 ~61 dirt
setblock ~33 ~120 ~62 dirt
setblock ~33 ~120 ~63 dirt
setblock ~33 ~120 ~64 dirt
setblock ~33 ~120 ~65 dirt
setblock ~33 ~120 ~66 dirt
setblock ~33 ~120 ~67 dirt
setblock ~33 ~120 ~68 dirt
setblock ~33 ~120 ~69 dirt
setblock ~33 ~120 ~70 dirt
setblock ~33 ~120 ~71 dirt
setblock ~33 ~120 ~77 dirt
setblock ~33 ~120 ~78 dirt
setblock ~33 ~120 ~81 dirt
setblock ~33 ~120 ~82 dirt
setblock ~33 ~120 ~83 dirt
setblock ~33 ~120 ~84 dirt
setblock ~33 ~120 ~85 dirt
setblock ~33 ~120 ~86 dirt
setblock ~33 ~120 ~87 dirt
setblock ~33 ~120 ~88 dirt
setblock ~33 ~120 ~89 dirt
setblock ~33 ~120 ~90 dirt
setblock ~33 ~120 ~91 dirt
setblock ~33 ~120 ~92 dirt
setblock ~33 ~120 ~93 dirt
setblock ~33 ~120 ~94 dirt
setblock ~33 ~120 ~95 dirt
setblock ~33 ~120 ~96 dirt
setblock ~33 ~120 ~97 dirt
setblock ~33 ~120 ~98 dirt
setblock ~33 ~120 ~99 dirt
setblock ~33 ~120 ~100 dirt
setblock ~33 ~120 ~101 dirt
setblock ~33 ~120 ~102 dirt
setblock ~33 ~120 ~103 dirt
setblock ~33 ~120 ~104 dirt
setblock ~33 ~120 ~105 dirt
setblock ~33 ~120 ~106 dirt
setblock ~33 ~120 ~107 dirt
setblock ~33 ~120 ~108 dirt
setblock ~33 ~120 ~109 dirt
setblock ~33 ~120 ~110 dirt
setblock ~33 ~120 ~111 dirt
setblock ~33 ~120 ~114 dirt
setblock ~33 ~120 ~115 dirt
setblock ~33 ~120 ~116 dirt
setblock ~33 ~120 ~117 dirt
setblock ~33 ~120 ~118 dirt
setblock ~33 ~120 ~119 dirt
setblock ~33 ~120 ~120 dirt
setblock ~33 ~120 ~121 dirt
setblock ~33 ~121 ~60 dirt
setblock ~33 ~121 ~61 dirt
setblock ~33 ~121 ~62 dirt
setblock ~33 ~121 ~63 dirt
setblock ~33 ~121 ~64 dirt
setblock ~33 ~121 ~65 dirt
setblock ~33 ~121 ~66 dirt
setblock ~33 ~121 ~67 dirt
setblock ~33 ~121 ~68 dirt
setblock ~33 ~121 ~69 dirt
setblock ~33 ~121 ~70 dirt
setblock ~33 ~121 ~71 dirt
setblock ~33 ~121 ~72 dirt
setblock ~33 ~121 ~77 dirt
setblock ~33 ~121 ~78 dirt
setblock ~33 ~121 ~79 dirt
setblock ~33 ~121 ~81 dirt
setblock ~33 ~121 ~82 dirt
setblock ~33 ~121 ~83 dirt
setblock ~33 ~121 ~84 dirt
setblock ~33 ~121 ~85 dirt
setblock ~33 ~121 ~86 dirt
setblock ~33 ~121 ~87 dirt
setblock ~33 ~121 ~88 dirt
setblock ~33 ~121 ~89 dirt
setblock ~33 ~121 ~90 dirt
setblock ~33 ~121 ~91 dirt
setblock ~33 ~121 ~92 dirt
setblock ~33 ~121 ~93 dirt
setblock ~33 ~121 ~94 dirt
setblock ~33 ~121 ~95 dirt
setblock ~33 ~121 ~96 dirt
setblock ~33 ~121 ~97 dirt
setblock ~33 ~121 ~98 dirt
setblock ~33 ~121 ~99 dirt
setblock ~33 ~121 ~100 dirt
setblock ~33 ~121 ~101 dirt
setblock ~33 ~121 ~102 dirt
setblock ~33 ~121 ~103 dirt
setblock ~33 ~121 ~104 dirt
setblock ~33 ~121 ~105 dirt
setblock ~33 ~121 ~106 dirt
setblock ~33 ~121 ~107 dirt
setblock ~33 ~121 ~108 dirt
setblock ~33 ~121 ~109 dirt
setblock ~33 ~121 ~110 dirt
setblock ~33 ~121 ~111 dirt
setblock ~33 ~121 ~112 dirt
setblock ~33 ~121 ~114 dirt
setblock ~33 ~121 ~115 dirt
setblock ~33 ~121 ~116 dirt
setblock ~33 ~121 ~117 dirt
setblock ~33 ~121 ~118 dirt
setblock ~33 ~121 ~119 dirt
setblock ~33 ~121 ~120 dirt
setblock ~33 ~121 ~121 dirt
setblock ~33 ~121 ~122 dirt
setblock ~33 ~122 ~60 dirt
setblock ~33 ~122 ~61 dirt
setblock ~33 ~122 ~62 dirt
setblock ~33 ~122 ~63 dirt
setblock ~33 ~122 ~64 dirt
setblock ~33 ~122 ~65 dirt
setblock ~33 ~122 ~66 dirt
setblock ~33 ~122 ~67 dirt
setblock ~33 ~122 ~68 dirt
setblock ~33 ~122 ~69 dirt
setblock ~33 ~122 ~70 dirt
setblock ~33 ~122 ~71 dirt
setblock ~33 ~122 ~72 dirt
setblock ~33 ~122 ~77 dirt
setblock ~33 ~122 ~78 dirt
setblock ~33 ~122 ~79 dirt
setblock ~33 ~122 ~81 dirt
setblock ~33 ~122 ~82 dirt
setblock ~33 ~122 ~83 dirt
setblock ~33 ~122 ~84 dirt
setblock ~33 ~122 ~85 dirt
setblock ~33 ~122 ~86 dirt
setblock ~33 ~122 ~87 dirt
setblock ~33 ~122 ~88 dirt
setblock ~33 ~122 ~89 dirt
setblock ~33 ~122 ~90 dirt
setblock ~33 ~122 ~91 dirt
setblock ~33 ~122 ~92 dirt
setblock ~33 ~122 ~93 dirt
setblock ~33 ~122 ~94 dirt
setblock ~33 ~122 ~95 dirt
setblock ~33 ~122 ~96 dirt
setblock ~33 ~122 ~97 dirt
setblock ~33 ~122 ~98 dirt
setblock ~33 ~122 ~99 dirt
setblock ~33 ~122 ~100 dirt
setblock ~33 ~122 ~101 dirt
setblock ~33 ~122 ~102 dirt
setblock ~33 ~122 ~103 dirt
setblock ~33 ~122 ~104 dirt
setblock ~33 ~122 ~105 dirt
setblock ~33 ~122 ~106 dirt
setblock ~33 ~122 ~107 dirt
setblock ~33 ~122 ~108 dirt
setblock ~33 ~122 ~109 dirt
setblock ~33 ~122 ~110 dirt
setblock ~33 ~122 ~111 dirt
setblock ~33 ~122 ~112 dirt
setblock ~33 ~122 ~114 dirt
setblock ~33 ~122 ~115 dirt
setblock ~33 ~122 ~116 dirt
setblock ~33 ~122 ~117 dirt
setblock ~33 ~122 ~118 dirt
setblock ~33 ~122 ~119 dirt
setblock ~33 ~122 ~120 dirt
setblock ~33 ~122 ~121 dirt
setblock ~33 ~122 ~122 dirt
setblock ~33 ~123 ~60 dirt
setblock ~33 ~123 ~61 dirt
setblock ~33 ~123 ~62 dirt
setblock ~33 ~123 ~63 dirt
setblock ~33 ~123 ~64 dirt
setblock ~33 ~123 ~65 dirt
setblock ~33 ~123 ~66 dirt
setblock ~33 ~123 ~67 dirt
setblock ~33 ~123 ~68 dirt
setblock ~33 ~123 ~69 dirt
setblock ~33 ~123 ~70 dirt
setblock ~33 ~123 ~71 dirt
setblock ~33 ~123 ~72 dirt
setblock ~33 ~123 ~77 dirt
setblock ~33 ~123 ~78 dirt
setblock ~33 ~123 ~79 dirt
setblock ~33 ~123 ~81 dirt
setblock ~33 ~123 ~82 dirt
setblock ~33 ~123 ~83 dirt
setblock ~33 ~123 ~84 dirt
setblock ~33 ~123 ~85 dirt
setblock ~33 ~123 ~86 dirt
setblock ~33 ~123 ~87 dirt
setblock ~33 ~123 ~88 dirt
setblock ~33 ~123 ~89 dirt
setblock ~33 ~123 ~90 grass_block
setblock ~33 ~123 ~91 dirt
setblock ~33 ~123 ~92 dirt
setblock ~33 ~123 ~93 dirt
setblock ~33 ~123 ~94 dirt
setblock ~33 ~123 ~95 dirt
setblock ~33 ~123 ~96 dirt
setblock ~33 ~123 ~97 dirt
setblock ~33 ~123 ~98 dirt
setblock ~33 ~123 ~99 dirt
setblock ~33 ~123 ~100 dirt
setblock ~33 ~123 ~101 dirt
setblock ~33 ~123 ~102 dirt
setblock ~33 ~123 ~103 dirt
setblock ~33 ~123 ~104 dirt
setblock ~33 ~123 ~105 dirt
setblock ~33 ~123 ~106 dirt
setblock ~33 ~123 ~107 dirt
setblock ~33 ~123 ~108 dirt
setblock ~33 ~123 ~109 dirt
setblock ~33 ~123 ~110 dirt
setblock ~33 ~123 ~111 dirt
setblock ~33 ~123 ~112 dirt
setblock ~33 ~123 ~114 dirt
setblock ~33 ~123 ~115 dirt
setblock ~33 ~123 ~116 dirt
setblock ~33 ~123 ~117 dirt
setblock ~33 ~123 ~118 dirt
setblock ~33 ~123 ~119 dirt
setblock ~33 ~123 ~120 dirt
setblock ~33 ~123 ~121 dirt
setblock ~33 ~123 ~122 dirt
setblock ~33 ~124 ~60 dirt
setblock ~33 ~124 ~61 dirt
setblock ~33 ~124 ~62 dirt
setblock ~33 ~124 ~63 dirt
setblock ~33 ~124 ~64 dirt
setblock ~33 ~124 ~65 dirt
setblock ~33 ~124 ~66 dirt
setblock ~33 ~124 ~67 dirt
setblock ~33 ~124 ~68 dirt
setblock ~33 ~124 ~69 dirt
setblock ~33 ~124 ~70 dirt
setblock ~33 ~124 ~71 dirt
setblock ~33 ~124 ~72 dirt
setblock ~33 ~124 ~77 dirt
setblock ~33 ~124 ~78 dirt
setblock ~33 ~124 ~79 dirt
setblock ~33 ~124 ~81 dirt
setblock ~33 ~124 ~82 dirt
setblock ~33 ~124 ~83 grass_block
setblock ~33 ~124 ~84 grass_block
setblock ~33 ~124 ~85 grass_block
setblock ~33 ~124 ~86 grass_block
setblock ~33 ~124 ~87 grass_block
setblock ~33 ~124 ~88 grass_block
setblock ~33 ~124 ~89 grass_block
setblock ~33 ~124 ~91 grass_block
setblock ~33 ~124 ~92 grass_block
setblock ~33 ~124 ~93 grass_block
setblock ~33 ~124 ~94 grass_block
setblock ~33 ~124 ~95 grass_block
setblock ~33 ~124 ~96 grass_block
setblock ~33 ~124 ~97 grass_block
setblock ~33 ~124 ~98 dirt
setblock ~33 ~124 ~99 dirt
setblock ~33 ~124 ~100 dirt
setblock ~33 ~124 ~101 dirt
setblock ~33 ~124 ~102 dirt
setblock ~33 ~124 ~103 dirt
setblock ~33 ~124 ~104 grass_block
setblock ~33 ~124 ~105 grass_block
setblock ~33 ~124 ~106 grass_block
setblock ~33 ~124 ~107 grass_block
setblock ~33 ~124 ~108 grass_block
setblock ~33 ~124 ~109 grass_block
setblock ~33 ~124 ~110 grass_block
setblock ~33 ~124 ~111 grass_block
setblock ~33 ~124 ~112 grass_block
setblock ~33 ~124 ~114 dirt
setblock ~33 ~124 ~115 dirt
setblock ~33 ~124 ~116 dirt
setblock ~33 ~124 ~117 dirt
setblock ~33 ~124 ~118 dirt
setblock ~33 ~124 ~119 dirt
setblock ~33 ~124 ~120 dirt
setblock ~33 ~124 ~121 dirt
setblock ~33 ~124 ~122 dirt
setblock ~33 ~125 ~60 dirt
setblock ~33 ~125 ~61 dirt
setblock ~33 ~125 ~62 dirt
setblock ~33 ~125 ~63 dirt
setblock ~33 ~125 ~64 dirt
setblock ~33 ~125 ~65 dirt
setblock ~33 ~125 ~66 dirt
setblock ~33 ~125 ~67 dirt
setblock ~33 ~125 ~68 dirt
setblock ~33 ~125 ~69 dirt
setblock ~33 ~125 ~70 dirt
setblock ~33 ~125 ~71 dirt
setblock ~33 ~125 ~72 dirt
setblock ~33 ~125 ~77 dirt
setblock ~33 ~125 ~78 grass_block
setblock ~33 ~125 ~79 grass_block
setblock ~33 ~125 ~81 grass_block
setblock ~33 ~125 ~82 grass_block
setblock ~33 ~125 ~85 short_grass
setblock ~33 ~125 ~88 short_grass
setblock ~33 ~125 ~91 short_grass
setblock ~33 ~125 ~92 short_grass
setblock ~33 ~125 ~95 poppy
setblock ~33 ~125 ~96 fern
setblock ~33 ~125 ~97 fern
setblock ~33 ~125 ~98 grass_block
setblock ~33 ~125 ~99 grass_block
setblock ~33 ~125 ~100 grass_block
setblock ~33 ~125 ~101 grass_block
setblock ~33 ~125 ~102 grass_block
setblock ~33 ~125 ~103 grass_block
setblock ~33 ~125 ~104 short_grass
setblock ~33 ~125 ~108 short_grass
setblock ~33 ~125 ~111 short_grass
setblock ~33 ~125 ~112 short_grass
setblock ~33 ~125 ~114 grass_block
setblock ~33 ~125 ~115 grass_block
setblock ~33 ~125 ~116 dirt
setblock ~33 ~125 ~117 dirt
setblock ~33 ~125 ~118 dirt
setblock ~33 ~125 ~119 dirt
setblock ~33 ~125 ~120 dirt
setblock ~33 ~125 ~121 dirt
setblock ~33 ~125 ~122 dirt
setblock ~33 ~126 ~60 dirt
setblock ~33 ~126 ~61 dirt
setblock ~33 ~126 ~62 dirt
setblock ~33 ~126 ~63 dirt
setblock ~33 ~126 ~64 dirt
setblock ~33 ~126 ~65 dirt
setblock ~33 ~126 ~66 dirt
setblock ~33 ~126 ~67 dirt
setblock ~33 ~126 ~68 dirt
setblock ~33 ~126 ~69 dirt
setblock ~33 ~126 ~70 dirt
setblock ~33 ~126 ~71 dirt
setblock ~33 ~126 ~72 dirt
setblock ~33 ~126 ~77 grass_block
setblock ~33 ~126 ~82 short_grass
setblock ~33 ~126 ~99 poppy
setblock ~33 ~126 ~103 short_grass
setblock ~33 ~126 ~116 grass_block
setblock ~33 ~126 ~117 grass_block
setblock ~33 ~126 ~118 dirt
setblock ~33 ~126 ~119 dirt
setblock ~33 ~126 ~120 dirt
setblock ~33 ~126 ~121 dirt
setblock ~33 ~126 ~122 dirt
setblock ~33 ~127 ~60 grass_block
setblock ~33 ~127 ~61 grass_block
setblock ~33 ~127 ~62 grass_block
setblock ~33 ~127 ~63 grass_block
setblock ~33 ~127 ~64 grass_block
setblock ~33 ~127 ~65 grass_block
setblock ~33 ~127 ~66 grass_block
setblock ~33 ~127 ~67 grass_block
setblock ~33 ~127 ~68 grass_block
setblock ~33 ~127 ~69 grass_block
setblock ~33 ~127 ~70 grass_block
setblock ~33 ~127 ~71 grass_block
setblock ~33 ~127 ~72 grass_block
setblock ~33 ~127 ~77 short_grass
setblock ~33 ~127 ~116 short_grass
setblock ~33 ~127 ~117 short_grass
setblock ~33 ~127 ~118 grass_block
setblock ~33 ~127 ~119 grass_block
setblock ~33 ~127 ~120 dirt
setblock ~33 ~127 ~121 grass_block
setblock ~33 ~127 ~122 grass_block
setblock ~33 ~128 ~64 short_grass
setblock ~33 ~128 ~66 short_grass
setblock ~33 ~128 ~68 short_grass
setblock ~33 ~128 ~70 short_grass
setblock ~33 ~128 ~120 grass_block
setblock ~33 ~128 ~121 short_grass
setblock ~34 ~109 ~91 dirt
setblock ~34 ~110 ~91 dirt
setblock ~34 ~110 ~92 dirt
setblock ~34 ~110 ~93 dirt
setblock ~34 ~111 ~90 dirt
setblock ~34 ~111 ~91 dirt
setblock ~34 ~111 ~92 dirt
setblock ~34 ~111 ~93 dirt
setblock ~34 ~112 ~89 dirt
setblock ~34 ~112 ~90 dirt
setblock ~34 ~112 ~91 dirt
setblock ~34 ~112 ~92 dirt
setblock ~34 ~112 ~93 dirt
setblock ~34 ~112 ~94 dirt
setblock ~34 ~112 ~95 dirt
setblock ~34 ~112 ~102 dirt
setblock ~34 ~113 ~66 dirt
setblock ~34 ~113 ~88 dirt
setblock ~34 ~113 ~89 dirt
setblock ~34 ~113 ~90 dirt
setblock ~34 ~113 ~91 dirt
setblock ~34 ~113 ~92 dirt
setblock ~34 ~113 ~93 dirt
setblock ~34 ~113 ~94 dirt
setblock ~34 ~113 ~95 dirt
setblock ~34 ~113 ~96 dirt
setblock ~34 ~113 ~102 dirt
setblock ~34 ~113 ~103 dirt
setblock ~34 ~113 ~118 dirt
setblock ~34 ~114 ~66 dirt
setblock ~34 ~114 ~67 dirt
setblock ~34 ~114 ~88 dirt
setblock ~34 ~114 ~89 dirt
setblock ~34 ~114 ~90 dirt
setblock ~34 ~114 ~91 dirt
setblock ~34 ~114 ~92 dirt
setblock ~34 ~114 ~93 dirt
setblock ~34 ~114 ~94 dirt
setblock ~34 ~114 ~95 dirt
setblock ~34 ~114 ~96 dirt
setblock ~34 ~114 ~100 dirt
setblock ~34 ~114 ~101 dirt
setblock ~34 ~114 ~102 dirt
setblock ~34 ~114 ~103 dirt
setblock ~34 ~114 ~104 dirt
setblock ~34 ~114 ~118 dirt
setblock ~34 ~115 ~63 dirt
setblock ~34 ~115 ~65 dirt
setblock ~34 ~115 ~66 dirt
setblock ~34 ~115 ~67 dirt
setblock ~34 ~115 ~68 dirt
setblock ~34 ~115 ~83 dirt
setblock ~34 ~115 ~85 dirt
setblock ~34 ~115 ~86 dirt
setblock ~34 ~115 ~88 dirt
setblock ~34 ~115 ~89 dirt
setblock ~34 ~115 ~90 dirt
setblock ~34 ~115 ~91 dirt
setblock ~34 ~115 ~92 dirt
setblock ~34 ~115 ~93 dirt
setblock ~34 ~115 ~94 dirt
setblock ~34 ~115 ~95 dirt
setblock ~34 ~115 ~96 dirt
setblock ~34 ~115 ~100 dirt
setblock ~34 ~115 ~101 dirt
setblock ~34 ~115 ~102 dirt
setblock ~34 ~115 ~103 dirt
setblock ~34 ~115 ~104 dirt
setblock ~34 ~115 ~117 dirt
setblock ~34 ~115 ~118 dirt
setblock ~34 ~115 ~119 dirt
setblock ~34 ~116 ~63 dirt
setblock ~34 ~116 ~65 dirt
setblock ~34 ~116 ~66 dirt
setblock ~34 ~116 ~67 dirt
setblock ~34 ~116 ~68 dirt
setblock ~34 ~116 ~82 dirt
setblock ~34 ~116 ~83 dirt
setblock ~34 ~116 ~85 dirt
setblock ~34 ~116 ~86 dirt
setblock ~34 ~116 ~87 dirt
setblock ~34 ~116 ~88 dirt
setblock ~34 ~116 ~89 dirt
setblock ~34 ~116 ~90 dirt
setblock ~34 ~116 ~91 dirt
setblock ~34 ~116 ~92 dirt
setblock ~34 ~116 ~93 dirt
setblock ~34 ~116 ~94 dirt
setblock ~34 ~116 ~95 dirt
setblock ~34 ~116 ~96 dirt
setblock ~34 ~116 ~97 dirt
setblock ~34 ~116 ~99 dirt
setblock ~34 ~116 ~100 dirt
setblock ~34 ~116 ~101 dirt
setblock ~34 ~116 ~102 dirt
setblock ~34 ~116 ~103 dirt
setblock ~34 ~116 ~104 dirt
setblock ~34 ~116 ~107 dirt
setblock ~34 ~116 ~108 dirt
setblock ~34 ~116 ~116 dirt
setblock ~34 ~116 ~117 dirt
setblock ~34 ~116 ~118 dirt
setblock ~34 ~116 ~119 dirt
setblock ~34 ~117 ~62 dirt
setblock ~34 ~117 ~63 dirt
setblock ~34 ~117 ~65 dirt
setblock ~34 ~117 ~66 dirt
setblock ~34 ~117 ~67 dirt
setblock ~34 ~117 ~68 dirt
setblock ~34 ~117 ~69 dirt
setblock ~34 ~117 ~82 dirt
setblock ~34 ~117 ~83 dirt
setblock ~34 ~117 ~84 dirt
setblock ~34 ~117 ~85 dirt
setblock ~34 ~117 ~86 dirt
setblock ~34 ~117 ~87 dirt
setblock ~34 ~117 ~88 dirt
setblock ~34 ~117 ~89 dirt
setblock ~34 ~117 ~90 dirt
setblock ~34 ~117 ~91 dirt
setblock ~34 ~117 ~92 dirt
setblock ~34 ~117 ~93 dirt
setblock ~34 ~117 ~94 dirt
setblock ~34 ~117 ~95 dirt
setblock ~34 ~117 ~96 dirt
setblock ~34 ~117 ~97 dirt
setblock ~34 ~117 ~98 dirt
setblock ~34 ~117 ~99 dirt
setblock ~34 ~117 ~100 dirt
setblock ~34 ~117 ~101 dirt
setblock ~34 ~117 ~102 dirt
setblock ~34 ~117 ~103 dirt
setblock ~34 ~117 ~104 dirt
setblock ~34 ~117 ~105 dirt
setblock ~34 ~117 ~107 dirt
setblock ~34 ~117 ~108 dirt
setblock ~34 ~117 ~109 dirt
setblock ~34 ~117 ~115 dirt
setblock ~34 ~117 ~116 dirt
setblock ~34 ~117 ~117 dirt
setblock ~34 ~117 ~118 dirt
setblock ~34 ~117 ~119 dirt
setblock ~34 ~117 ~120 dirt
setblock ~34 ~118 ~61 dirt
setblock ~34 ~118 ~62 dirt
setblock ~34 ~118 ~63 dirt
setblock ~34 ~118 ~64 dirt
setblock ~34 ~118 ~65 dirt
setblock ~34 ~118 ~66 dirt
setblock ~34 ~118 ~67 dirt
setblock ~34 ~118 ~68 dirt
setblock ~34 ~118 ~69 dirt
setblock ~34 ~118 ~70 dirt
setblock ~34 ~118 ~76 dirt
setblock ~34 ~118 ~77 dirt
setblock ~34 ~118 ~78 dirt
setblock ~34 ~118 ~79 dirt
setblock ~34 ~118 ~82 dirt
setblock ~34 ~118 ~83 dirt
setblock ~34 ~118 ~84 dirt
setblock ~34 ~118 ~85 dirt
setblock ~34 ~118 ~86 dirt
setblock ~34 ~118 ~87 dirt
setblock ~34 ~118 ~88 dirt
setblock ~34 ~118 ~89 dirt
setblock ~34 ~118 ~90 dirt
setblock ~34 ~118 ~91 dirt
setblock ~34 ~118 ~92 dirt
setblock ~34 ~118 ~93 dirt
setblock ~34 ~118 ~94 dirt
setblock ~34 ~118 ~95 dirt
setblock ~34 ~118 ~96 dirt
setblock ~34 ~118 ~97 dirt
setblock ~34 ~118 ~98 dirt
setblock ~34 ~118 ~99 dirt
setblock ~34 ~118 ~100 dirt
setblock ~34 ~118 ~101 dirt
setblock ~34 ~118 ~102 dirt
setblock ~34 ~118 ~103 dirt
setblock ~34 ~118 ~104 dirt
setblock ~34 ~118 ~105 dirt
setblock ~34 ~118 ~107 dirt
setblock ~34 ~118 ~108 dirt
setblock ~34 ~118 ~109 dirt
setblock ~34 ~118 ~110 dirt
setblock ~34 ~118 ~115 dirt
setblock ~34 ~118 ~116 dirt
setblock ~34 ~118 ~117 dirt
setblock ~34 ~118 ~118 dirt
setblock ~34 ~118 ~119 dirt
setblock ~34 ~118 ~120 dirt
setblock ~34 ~119 ~51 dirt
setblock ~34 ~119 ~60 dirt
setblock ~34 ~119 ~61 dirt
setblock ~34 ~119 ~62 dirt
setblock ~34 ~119 ~63 dirt
setblock ~34 ~119 ~64 dirt
setblock ~34 ~119 ~65 dirt
setblock ~34 ~119 ~66 dirt
setblock ~34 ~119 ~67 dirt
setblock ~34 ~119 ~68 dirt
setblock ~34 ~119 ~69 dirt
setblock ~34 ~119 ~70 dirt
setblock ~34 ~119 ~71 dirt
setblock ~34 ~119 ~75 dirt
setblock ~34 ~119 ~76 dirt
setblock ~34 ~119 ~77 dirt
setblock ~34 ~119 ~78 dirt
setblock ~34 ~119 ~79 dirt
setblock ~34 ~119 ~80 dirt
setblock ~34 ~119 ~81 dirt
setblock ~34 ~119 ~82 dirt
setblock ~34 ~119 ~83 dirt
setblock ~34 ~119 ~84 dirt
setblock ~34 ~119 ~85 dirt
setblock ~34 ~119 ~86 dirt
setblock ~34 ~119 ~87 dirt
setblock ~34 ~119 ~88 dirt
setblock ~34 ~119 ~89 dirt
setblock ~34 ~119 ~90 dirt
setblock ~34 ~119 ~91 dirt
setblock ~34 ~119 ~92 dirt
setblock ~34 ~119 ~93 dirt
setblock ~34 ~119 ~94 dirt
setblock ~34 ~119 ~95 dirt
setblock ~34 ~119 ~96 dirt
setblock ~34 ~119 ~97 dirt
setblock ~34 ~119 ~98 dirt
setblock ~34 ~119 ~99 dirt
setblock ~34 ~119 ~100 dirt
setblock ~34 ~119 ~101 dirt
setblock ~34 ~119 ~102 dirt
setblock ~34 ~119 ~103 dirt
setblock ~34 ~119 ~104 dirt
setblock ~34 ~119 ~105 dirt
setblock ~34 ~119 ~106 dirt
setblock ~34 ~119 ~107 dirt
setblock ~34 ~119 ~108 dirt
setblock ~34 ~119 ~109 dirt
setblock ~34 ~119 ~110 dirt
setblock ~34 ~119 ~111 dirt
setblock ~34 ~119 ~114 dirt
setblock ~34 ~119 ~115 dirt
setblock ~34 ~119 ~116 dirt
setblock ~34 ~119 ~117 dirt
setblock ~34 ~119 ~118 dirt
setblock ~34 ~119 ~119 dirt
setblock ~34 ~119 ~120 dirt
setblock ~34 ~119 ~121 dirt
setblock ~34 ~120 ~50 dirt
setblock ~34 ~120 ~51 dirt
setblock ~34 ~120 ~54 dirt
setblock ~34 ~120 ~60 dirt
setblock ~34 ~120 ~61 dirt
setblock ~34 ~120 ~62 dirt
setblock ~34 ~120 ~63 dirt
setblock ~34 ~120 ~64 dirt
setblock ~34 ~120 ~65 dirt
setblock ~34 ~120 ~66 dirt
setblock ~34 ~120 ~67 dirt
setblock ~34 ~120 ~68 dirt
setblock ~34 ~120 ~69 dirt
setblock ~34 ~120 ~70 dirt
setblock ~34 ~120 ~71 dirt
setblock ~34 ~120 ~72 dirt
setblock ~34 ~120 ~75 dirt
setblock ~34 ~120 ~76 dirt
setblock ~34 ~120 ~77 dirt
setblock ~34 ~120 ~78 dirt
setblock ~34 ~120 ~79 dirt
setblock ~34 ~120 ~80 dirt
setblock ~34 ~120 ~81 dirt
setblock ~34 ~120 ~82 dirt
setblock ~34 ~120 ~83 dirt
setblock ~34 ~120 ~84 dirt
setblock ~34 ~120 ~85 dirt
setblock ~34 ~120 ~86 dirt
setblock ~34 ~120 ~87 dirt
setblock ~34 ~120 ~88 dirt
setblock ~34 ~120 ~89 dirt
setblock ~34 ~120 ~90 dirt
setblock ~34 ~120 ~91 dirt
setblock ~34 ~120 ~92 dirt
setblock ~34 ~120 ~93 dirt
setblock ~34 ~120 ~94 dirt
setblock ~34 ~120 ~95 dirt
setblock ~34 ~120 ~96 dirt
setblock ~34 ~120 ~97 dirt
setblock ~34 ~120 ~98 dirt
setblock ~34 ~120 ~99 dirt
setblock ~34 ~120 ~100 dirt
setblock ~34 ~120 ~101 dirt
setblock ~34 ~120 ~102 dirt
setblock ~34 ~120 ~103 dirt
setblock ~34 ~120 ~104 dirt
setblock ~34 ~120 ~105 dirt
setblock ~34 ~120 ~106 dirt
setblock ~34 ~120 ~107 dirt
setblock ~34 ~120 ~108 dirt
setblock ~34 ~120 ~109 dirt
setblock ~34 ~120 ~110 dirt
setblock ~34 ~120 ~111 dirt
setblock ~34 ~120 ~114 dirt
setblock ~34 ~120 ~115 dirt
setblock ~34 ~120 ~116 dirt
setblock ~34 ~120 ~117 dirt
setblock ~34 ~120 ~118 dirt
setblock ~34 ~120 ~119 dirt
setblock ~34 ~120 ~120 dirt
setblock ~34 ~120 ~121 dirt
setblock ~34 ~121 ~50 dirt
setblock ~34 ~121 ~51 dirt
setblock ~34 ~121 ~53 dirt
setblock ~34 ~121 ~54 dirt
setblock ~34 ~121 ~60 dirt
setblock ~34 ~121 ~61 dirt
setblock ~34 ~121 ~62 dirt
setblock ~34 ~121 ~63 dirt
setblock ~34 ~121 ~64 dirt
setblock ~34 ~121 ~65 dirt
setblock ~34 ~121 ~66 dirt
setblock ~34 ~121 ~67 dirt
setblock ~34 ~121 ~68 dirt
setblock ~34 ~121 ~69 dirt
setblock ~34 ~121 ~70 dirt
setblock ~34 ~121 ~71 dirt
setblock ~34 ~121 ~72 dirt
setblock ~34 ~121 ~73 dirt
setblock ~34 ~121 ~74 dirt
setblock ~34 ~121 ~75 dirt
setblock ~34 ~121 ~76 dirt
setblock ~34 ~121 ~77 dirt
setblock ~34 ~121 ~78 dirt
setblock ~34 ~121 ~79 dirt
setblock ~34 ~121 ~80 dirt
setblock ~34 ~121 ~81 dirt
setblock ~34 ~121 ~82 dirt
setblock ~34 ~121 ~83 dirt
setblock ~34 ~121 ~84 dirt
setblock ~34 ~121 ~85 dirt
setblock ~34 ~121 ~86 dirt
setblock ~34 ~121 ~87 dirt
setblock ~34 ~121 ~88 dirt
setblock ~34 ~121 ~89 dirt
setblock ~34 ~121 ~90 dirt
setblock ~34 ~121 ~91 dirt
setblock ~34 ~121 ~92 dirt
setblock ~34 ~121 ~93 dirt
setblock ~34 ~121 ~94 dirt
setblock ~34 ~121 ~95 dirt
setblock ~34 ~121 ~96 dirt
setblock ~34 ~121 ~97 dirt
setblock ~34 ~121 ~98 dirt
setblock ~34 ~121 ~99 dirt
setblock ~34 ~121 ~100 dirt
setblock ~34 ~121 ~101 dirt
setblock ~34 ~121 ~102 dirt
setblock ~34 ~121 ~103 dirt
setblock ~34 ~121 ~104 dirt
setblock ~34 ~121 ~105 dirt
setblock ~34 ~121 ~106 dirt
setblock ~34 ~121 ~107 dirt
setblock ~34 ~121 ~108 dirt
setblock ~34 ~121 ~109 dirt
setblock ~34 ~121 ~110 dirt
setblock ~34 ~121 ~111 dirt
setblock ~34 ~121 ~114 dirt
setblock ~34 ~121 ~115 dirt
setblock ~34 ~121 ~116 dirt
setblock ~34 ~121 ~117 dirt
setblock ~34 ~121 ~118 dirt
setblock ~34 ~121 ~119 dirt
setblock ~34 ~121 ~120 dirt
setblock ~34 ~121 ~121 dirt
setblock ~34 ~122 ~50 dirt
setblock ~34 ~122 ~51 dirt
setblock ~34 ~122 ~53 dirt
setblock ~34 ~122 ~54 dirt
setblock ~34 ~122 ~60 dirt
setblock ~34 ~122 ~61 dirt
setblock ~34 ~122 ~62 dirt
setblock ~34 ~122 ~63 dirt
setblock ~34 ~122 ~64 dirt
setblock ~34 ~122 ~65 dirt
setblock ~34 ~122 ~66 dirt
setblock ~34 ~122 ~67 dirt
setblock ~34 ~122 ~68 dirt
setblock ~34 ~122 ~69 dirt
setblock ~34 ~122 ~70 dirt
setblock ~34 ~122 ~71 dirt
setblock ~34 ~122 ~72 dirt
setblock ~34 ~122 ~73 dirt
setblock ~34 ~122 ~74 dirt
setblock ~34 ~122 ~75 dirt
setblock ~34 ~122 ~76 dirt
setblock ~34 ~122 ~77 dirt
setblock ~34 ~122 ~78 dirt
setblock ~34 ~122 ~79 dirt
setblock ~34 ~122 ~80 dirt
setblock ~34 ~122 ~81 dirt
setblock ~34 ~122 ~82 dirt
setblock ~34 ~122 ~83 dirt
setblock ~34 ~122 ~84 dirt
setblock ~34 ~122 ~85 dirt
setblock ~34 ~122 ~86 dirt
setblock ~34 ~122 ~87 dirt
setblock ~34 ~122 ~88 dirt
setblock ~34 ~122 ~89 dirt
setblock ~34 ~122 ~90 dirt
setblock ~34 ~122 ~91 dirt
setblock ~34 ~122 ~92 dirt
setblock ~34 ~122 ~93 dirt
setblock ~34 ~122 ~94 dirt
setblock ~34 ~122 ~95 dirt
setblock ~34 ~122 ~96 dirt
setblock ~34 ~122 ~97 dirt
setblock ~34 ~122 ~98 dirt
setblock ~34 ~122 ~99 dirt
setblock ~34 ~122 ~100 dirt
setblock ~34 ~122 ~101 dirt
setblock ~34 ~122 ~102 dirt
setblock ~34 ~122 ~103 dirt
setblock ~34 ~122 ~104 dirt
setblock ~34 ~122 ~105 dirt
setblock ~34 ~122 ~106 dirt
setblock ~34 ~122 ~107 dirt
setblock ~34 ~122 ~108 dirt
setblock ~34 ~122 ~109 dirt
setblock ~34 ~122 ~110 dirt
setblock ~34 ~122 ~111 dirt
setblock ~34 ~122 ~114 dirt
setblock ~34 ~122 ~115 dirt
setblock ~34 ~122 ~116 dirt
setblock ~34 ~122 ~117 dirt
setblock ~34 ~122 ~118 dirt
setblock ~34 ~122 ~119 dirt
setblock ~34 ~122 ~120 dirt
setblock ~34 ~122 ~121 dirt
setblock ~34 ~123 ~50 grass_block
setblock ~34 ~123 ~51 grass_block
setblock ~34 ~123 ~53 dirt
setblock ~34 ~123 ~54 dirt
setblock ~34 ~123 ~60 dirt
setblock ~34 ~123 ~61 dirt
setblock ~34 ~123 ~62 dirt
setblock ~34 ~123 ~63 dirt
setblock ~34 ~123 ~64 dirt
setblock ~34 ~123 ~65 dirt
setblock ~34 ~123 ~66 dirt
setblock ~34 ~123 ~67 dirt
setblock ~34 ~123 ~68 dirt
setblock ~34 ~123 ~69 dirt
setblock ~34 ~123 ~70 dirt
setblock ~34 ~123 ~71 dirt
setblock ~34 ~123 ~72 dirt
setblock ~34 ~123 ~73 dirt
setblock ~34 ~123 ~74 dirt
setblock ~34 ~123 ~75 dirt
setblock ~34 ~123 ~76 dirt
setblock ~34 ~123 ~77 dirt
setblock ~34 ~123 ~78 dirt
setblock ~34 ~123 ~79 dirt
setblock ~34 ~123 ~80 dirt
setblock ~34 ~123 ~81 dirt
setblock ~34 ~123 ~82 dirt
setblock ~34 ~123 ~83 dirt
setblock ~34 ~123 ~84 dirt
setblock ~34 ~123 ~85 dirt
setblock ~34 ~123 ~86 dirt
setblock ~34 ~123 ~87 dirt
setblock ~34 ~123 ~88 dirt
setblock ~34 ~123 ~89 dirt
setblock ~34 ~123 ~90 grass_block
setblock ~34 ~123 ~91 dirt
setblock ~34 ~123 ~92 dirt
setblock ~34 ~123 ~93 dirt
setblock ~34 ~123 ~94 dirt
setblock ~34 ~123 ~95 dirt
setblock ~34 ~123 ~96 dirt
setblock ~34 ~123 ~97 dirt
setblock ~34 ~123 ~98 dirt
setblock ~34 ~123 ~99 dirt
setblock ~34 ~123 ~100 dirt
setblock ~34 ~123 ~101 dirt
setblock ~34 ~123 ~102 dirt
setblock ~34 ~123 ~103 dirt
setblock ~34 ~123 ~104 dirt
setblock ~34 ~123 ~105 dirt
setblock ~34 ~123 ~106 dirt
setblock ~34 ~123 ~107 dirt
setblock ~34 ~123 ~108 dirt
setblock ~34 ~123 ~109 dirt
setblock ~34 ~123 ~110 dirt
setblock ~34 ~123 ~111 dirt
setblock ~34 ~123 ~114 dirt
setblock ~34 ~123 ~115 dirt
setblock ~34 ~123 ~116 dirt
setblock ~34 ~123 ~117 dirt
setblock ~34 ~123 ~118 dirt
setblock ~34 ~123 ~119 dirt
setblock ~34 ~123 ~120 dirt
setblock ~34 ~123 ~121 dirt
setblock ~34 ~124 ~50 short_grass
setblock ~34 ~124 ~53 grass_block
setblock ~34 ~124 ~54 grass_block
setblock ~34 ~124 ~60 dirt
setblock ~34 ~124 ~61 dirt
setblock ~34 ~124 ~62 dirt
setblock ~34 ~124 ~63 dirt
setblock ~34 ~124 ~64 dirt
setblock ~34 ~124 ~65 dirt
setblock ~34 ~124 ~66 dirt
setblock ~34 ~124 ~67 dirt
setblock ~34 ~124 ~68 dirt
setblock ~34 ~124 ~69 dirt
setblock ~34 ~124 ~70 dirt
setblock ~34 ~124 ~71 dirt
setblock ~34 ~124 ~72 dirt
setblock ~34 ~124 ~73 dirt
setblock ~34 ~124 ~74 dirt
setblock ~34 ~124 ~75 dirt
setblock ~34 ~124 ~76 dirt
setblock ~34 ~124 ~77 dirt
setblock ~34 ~124 ~78 dirt
setblock ~34 ~124 ~79 dirt
setblock ~34 ~124 ~80 dirt
setblock ~34 ~124 ~81 dirt
setblock ~34 ~124 ~82 dirt
setblock ~34 ~124 ~83 dirt
setblock ~34 ~124 ~84 grass_block
setblock ~34 ~124 ~85 grass_block
setblock ~34 ~124 ~86 grass_block
setblock ~34 ~124 ~87 grass_block
setblock ~34 ~124 ~88 grass_block
setblock ~34 ~124 ~89 grass_block
setblock ~34 ~124 ~91 grass_block
setblock ~34 ~124 ~92 grass_block
setblock ~34 ~124 ~93 grass_block
setblock ~34 ~124 ~94 grass_block
setblock ~34 ~124 ~95 grass_block
setblock ~34 ~124 ~96 grass_block
setblock ~34 ~124 ~97 grass_block
setblock ~34 ~124 ~98 dirt
setblock ~34 ~124 ~99 dirt
setblock ~34 ~124 ~100 dirt
setblock ~34 ~124 ~101 dirt
setblock ~34 ~124 ~102 dirt
setblock ~34 ~124 ~103 dirt
setblock ~34 ~124 ~104 grass_block
setblock ~34 ~124 ~105 grass_block
setblock ~34 ~124 ~106 grass_block
setblock ~34 ~124 ~107 grass_block
setblock ~34 ~124 ~108 grass_block
setblock ~34 ~124 ~109 grass_block
setblock ~34 ~124 ~110 grass_block
setblock ~34 ~124 ~111 grass_block
setblock ~34 ~124 ~114 dirt
setblock ~34 ~124 ~115 dirt
setblock ~34 ~124 ~116 dirt
setblock ~34 ~124 ~117 dirt
setblock ~34 ~124 ~118 dirt
setblock ~34 ~124 ~119 dirt
setblock ~34 ~124 ~120 dirt
setblock ~34 ~124 ~121 dirt
setblock ~34 ~125 ~60 dirt
setblock ~34 ~125 ~61 dirt
setblock ~34 ~125 ~62 dirt
setblock ~34 ~125 ~63 dirt
setblock ~34 ~125 ~64 dirt
setblock ~34 ~125 ~65 dirt
setblock ~34 ~125 ~66 dirt
setblock ~34 ~125 ~67 dirt
setblock ~34 ~125 ~68 dirt
setblock ~34 ~125 ~69 dirt
setblock ~34 ~125 ~70 dirt
setblock ~34 ~125 ~71 dirt
setblock ~34 ~125 ~72 dirt
setblock ~34 ~125 ~73 dirt
setblock ~34 ~125 ~74 dirt
setblock ~34 ~125 ~75 dirt
setblock ~34 ~125 ~76 dirt
setblock ~34 ~125 ~77 dirt
setblock ~34 ~125 ~78 grass_block
setblock ~34 ~125 ~79 grass_block
setblock ~34 ~125 ~80 grass_block
setblock ~34 ~125 ~81 grass_block
setblock ~34 ~125 ~82 grass_block
setblock ~34 ~125 ~83 grass_block
setblock ~34 ~125 ~86 short_grass
setblock ~34 ~125 ~89 poppy
setblock ~34 ~125 ~98 grass_block
setblock ~34 ~125 ~99 grass_block
setblock ~34 ~125 ~100 grass_block
setblock ~34 ~125 ~101 grass_block
setblock ~34 ~125 ~102 grass_block
setblock ~34 ~125 ~103 grass_block
setblock ~34 ~125 ~114 grass_block
setblock ~34 ~125 ~115 grass_block
setblock ~34 ~125 ~116 grass_block
setblock ~34 ~125 ~117 dirt
setblock ~34 ~125 ~118 dirt
setblock ~34 ~125 ~119 dirt
setblock ~34 ~125 ~120 dirt
setblock ~34 ~125 ~121 dirt
setblock ~34 ~126 ~60 grass_block
setblock ~34 ~126 ~61 grass_block
setblock ~34 ~126 ~62 dirt
setblock ~34 ~126 ~63 dirt
setblock ~34 ~126 ~64 dirt
setblock ~34 ~126 ~65 dirt
setblock ~34 ~126 ~66 dirt
setblock ~34 ~126 ~67 dirt
setblock ~34 ~126 ~68 dirt
setblock ~34 ~126 ~69 dirt
setblock ~34 ~126 ~70 dirt
setblock ~34 ~126 ~71 dirt
setblock ~34 ~126 ~72 grass_block
setblock ~34 ~126 ~73 grass_block
setblock ~34 ~126 ~74 grass_block
setblock ~34 ~126 ~75 grass_block
setblock ~34 ~126 ~76 grass_block
setblock ~34 ~126 ~77 grass_block
setblock ~34 ~126 ~81 short_grass
setblock ~34 ~126 ~83 short_grass
setblock ~34 ~126 ~99 short_grass
setblock ~34 ~126 ~103 short_grass
setblock ~34 ~126 ~114 short_grass
setblock ~34 ~126 ~117 grass_block
setblock ~34 ~126 ~118 grass_block
setblock ~34 ~126 ~119 grass_block
setblock ~34 ~126 ~120 dirt
setblock ~34 ~126 ~121 dirt
setblock ~34 ~127 ~60 short_grass
setblock ~34 ~127 ~62 grass_block
setblock ~34 ~127 ~63 grass_block
setblock ~34 ~127 ~64 grass_block
setblock ~34 ~127 ~65 grass_block
setblock ~34 ~127 ~66 grass_block
setblock ~34 ~127 ~67 grass_block
setblock ~34 ~127 ~68 grass_block
setblock ~34 ~127 ~69 grass_block
setblock ~34 ~127 ~70 grass_block
setblock ~34 ~127 ~71 grass_block
setblock ~34 ~127 ~75 short_grass
setblock ~34 ~127 ~117 short_grass
setblock ~34 ~127 ~120 grass_block
setblock ~34 ~127 ~121 grass_block
setblock ~34 ~128 ~63 short_grass
setblock ~34 ~128 ~65 short_grass
setblock ~34 ~128 ~66 fern
setblock ~35 ~106 ~91 dirt
setblock ~35 ~107 ~91 dirt
setblock ~35 ~108 ~90 dirt
setblock ~35 ~108 ~91 dirt
setblock ~35 ~108 ~92 dirt
setblock ~35 ~109 ~90 dirt
setblock ~35 ~109 ~91 dirt
setblock ~35 ~109 ~92 dirt
setblock ~35 ~109 ~93 dirt
setblock ~35 ~110 ~89 dirt
setblock ~35 ~110 ~90 dirt
setblock ~35 ~110 ~91 dirt
setblock ~35 ~110 ~92 dirt
setblock ~35 ~110 ~93 dirt
setblock ~35 ~110 ~94 dirt
setblock ~35 ~111 ~89 dirt
setblock ~35 ~111 ~90 dirt
setblock ~35 ~111 ~91 dirt
setblock ~35 ~111 ~92 dirt
setblock ~35 ~111 ~93 dirt
setblock ~35 ~111 ~94 dirt
setblock ~35 ~111 ~95 dirt
setblock ~35 ~112 ~66 dirt
setblock ~35 ~112 ~83 dirt
setblock ~35 ~112 ~85 dirt
setblock ~35 ~112 ~88 dirt
setblock ~35 ~112 ~89 dirt
setblock ~35 ~112 ~90 dirt
setblock ~35 ~112 ~91 dirt
setblock ~35 ~112 ~92 dirt
setblock ~35 ~112 ~93 dirt
setblock ~35 ~112 ~94 dirt
setblock ~35 ~112 ~95 dirt
setblock ~35 ~112 ~96 dirt
setblock ~35 ~112 ~100 dirt
setblock ~35 ~113 ~65 dirt
setblock ~35 ~113 ~66 dirt
setblock ~35 ~113 ~67 dirt
setblock ~35 ~113 ~68 dirt
setblock ~35 ~113 ~83 dirt
setblock ~35 ~113 ~85 dirt
setblock ~35 ~113 ~86 dirt
setblock ~35 ~113 ~88 dirt
setblock ~35 ~113 ~89 dirt
setblock ~35 ~113 ~90 dirt
setblock ~35 ~113 ~91 dirt
setblock ~35 ~113 ~92 dirt
setblock ~35 ~113 ~93 dirt
setblock ~35 ~113 ~94 dirt
setblock ~35 ~113 ~95 dirt
setblock ~35 ~113 ~96 dirt
setblock ~35 ~113 ~100 dirt
setblock ~35 ~113 ~101 dirt
setblock ~35 ~114 ~63 dirt
setblock ~35 ~114 ~65 dirt
setblock ~35 ~114 ~66 dirt
setblock ~35 ~114 ~67 dirt
setblock ~35 ~114 ~68 dirt
setblock ~35 ~114 ~69 dirt
setblock ~35 ~114 ~83 dirt
setblock ~35 ~114 ~84 dirt
setblock ~35 ~114 ~85 dirt
setblock ~35 ~114 ~86 dirt
setblock ~35 ~114 ~88 dirt
setblock ~35 ~114 ~89 dirt
setblock ~35 ~114 ~90 dirt
setblock ~35 ~114 ~91 dirt
setblock ~35 ~114 ~92 dirt
setblock ~35 ~114 ~93 dirt
setblock ~35 ~114 ~94 dirt
setblock ~35 ~114 ~95 dirt
setblock ~35 ~114 ~96 dirt
setblock ~35 ~114 ~97 dirt
setblock ~35 ~114 ~98 dirt
setblock ~35 ~114 ~99 dirt
setblock ~35 ~114 ~100 dirt
setblock ~35 ~114 ~101 dirt
setblock ~35 ~114 ~102 dirt
setblock ~35 ~114 ~103 dirt
setblock ~35 ~114 ~107 dirt
setblock ~35 ~115 ~62 dirt
setblock ~35 ~115 ~63 dirt
setblock ~35 ~115 ~64 dirt
setblock ~35 ~115 ~65 dirt
setblock ~35 ~115 ~66 dirt
setblock ~35 ~115 ~67 dirt
setblock ~35 ~115 ~68 dirt
setblock ~35 ~115 ~69 dirt
setblock ~35 ~115 ~82 dirt
setblock ~35 ~115 ~83 dirt
setblock ~35 ~115 ~84 dirt
setblock ~35 ~115 ~85 dirt
setblock ~35 ~115 ~86 dirt
setblock ~35 ~115 ~87 dirt
setblock ~35 ~115 ~88 dirt
setblock ~35 ~115 ~89 dirt
setblock ~35 ~115 ~90 dirt
setblock ~35 ~115 ~91 dirt
setblock ~35 ~115 ~92 dirt
setblock ~35 ~115 ~93 dirt
setblock ~35 ~115 ~94 dirt
setblock ~35 ~115 ~95 dirt
setblock ~35 ~115 ~96 dirt
setblock ~35 ~115 ~97 dirt
setblock ~35 ~115 ~98 dirt
setblock ~35 ~115 ~99 dirt
setblock ~35 ~115 ~100 dirt
setblock ~35 ~115 ~101 dirt
setblock ~35 ~115 ~102 dirt
setblock ~35 ~115 ~103 dirt
setblock ~35 ~115 ~104 dirt
setblock ~35 ~115 ~107 dirt
setblock ~35 ~115 ~108 dirt
setblock ~35 ~115 ~109 dirt
setblock ~35 ~115 ~118 dirt
setblock ~35 ~116 ~62 dirt
setblock ~35 ~116 ~63 dirt
setblock ~35 ~116 ~64 dirt
setblock ~35 ~116 ~65 dirt
setblock ~35 ~116 ~66 dirt
setblock ~35 ~116 ~67 dirt
setblock ~35 ~116 ~68 dirt
setblock ~35 ~116 ~69 dirt
setblock ~35 ~116 ~76 dirt
setblock ~35 ~116 ~78 dirt
setblock ~35 ~116 ~81 dirt
setblock ~35 ~116 ~82 dirt
setblock ~35 ~116 ~83 dirt
setblock ~35 ~116 ~84 dirt
setblock ~35 ~116 ~85 dirt
setblock ~35 ~116 ~86 dirt
setblock ~35 ~116 ~87 dirt
setblock ~35 ~116 ~88 dirt
setblock ~35 ~116 ~89 dirt
setblock ~35 ~116 ~90 dirt
setblock ~35 ~116 ~91 dirt
setblock ~35 ~116 ~92 dirt
setblock ~35 ~116 ~93 dirt
setblock ~35 ~116 ~94 dirt
setblock ~35 ~116 ~95 dirt
setblock ~35 ~116 ~96 dirt
setblock ~35 ~116 ~97 dirt
setblock ~35 ~116 ~98 dirt
setblock ~35 ~116 ~99 dirt
setblock ~35 ~116 ~100 dirt
setblock ~35 ~116 ~101 dirt
setblock ~35 ~116 ~102 dirt
setblock ~35 ~116 ~103 dirt
setblock ~35 ~116 ~104 dirt
setblock ~35 ~116 ~105 dirt
setblock ~35 ~116 ~106 dirt
setblock ~35 ~116 ~107 dirt
setblock ~35 ~116 ~108 dirt
setblock ~35 ~116 ~109 dirt
setblock ~35 ~116 ~110 dirt
setblock ~35 ~116 ~117 dirt
setblock ~35 ~116 ~118 dirt
setblock ~35 ~117 ~50 dirt
setblock ~35 ~117 ~51 dirt
setblock ~35 ~117 ~61 dirt
setblock ~35 ~117 ~62 dirt
setblock ~35 ~117 ~63 dirt
setblock ~35 ~117 ~64 dirt
setblock ~35 ~117 ~65 dirt
setblock ~35 ~117 ~66 dirt
setblock ~35 ~117 ~67 dirt
setblock ~35 ~117 ~68 dirt
setblock ~35 ~117 ~69 dirt
setblock ~35 ~117 ~70 dirt
setblock ~35 ~117 ~76 dirt
setblock ~35 ~117 ~77 dirt
setblock ~35 ~117 ~78 dirt
setblock ~35 ~117 ~79 dirt
setblock ~35 ~117 ~80 dirt
setblock ~35 ~117 ~81 dirt
setblock ~35 ~117 ~82 dirt
setblock ~35 ~117 ~83 dirt
setblock ~35 ~117 ~84 dirt
setblock ~35 ~117 ~85 dirt
setblock ~35 ~117 ~86 dirt
setblock ~35 ~117 ~87 dirt
setblock ~35 ~117 ~88 dirt
setblock ~35 ~117 ~89 dirt
setblock ~35 ~117 ~90 dirt
setblock ~35 ~117 ~91 dirt
setblock ~35 ~117 ~92 dirt
setblock ~35 ~117 ~93 dirt
setblock ~35 ~117 ~94 dirt
setblock ~35 ~117 ~95 dirt
setblock ~35 ~117 ~96 dirt
setblock ~35 ~117 ~97 dirt
setblock ~35 ~117 ~98 dirt
setblock ~35 ~117 ~99 dirt
setblock ~35 ~117 ~100 dirt
setblock ~35 ~117 ~101 dirt
setblock ~35 ~117 ~102 dirt
setblock ~35 ~117 ~103 dirt
setblock ~35 ~117 ~104 dirt
setblock ~35 ~117 ~105 dirt
setblock ~35 ~117 ~106 dirt
setblock ~35 ~117 ~107 dirt
setblock ~35 ~117 ~108 dirt
setblock ~35 ~117 ~109 dirt
setblock ~35 ~117 ~110 dirt
setblock ~35 ~117 ~116 dirt
setblock ~35 ~117 ~117 dirt
setblock ~35 ~117 ~118 dirt
setblock ~35 ~117 ~119 dirt
setblock ~35 ~118 ~49 dirt
setblock ~35 ~118 ~50 dirt
setblock ~35 ~118 ~51 dirt
setblock ~35 ~118 ~52 dirt
setblock ~35 ~118 ~60 dirt
setblock ~35 ~118 ~61 dirt
setblock ~35 ~118 ~62 dirt
setblock ~35 ~118 ~63 dirt
setblock ~35 ~118 ~64 dirt
setblock ~35 ~118 ~65 dirt
setblock ~35 ~118 ~66 dirt
setblock ~35 ~118 ~67 dirt
setblock ~35 ~118 ~68 dirt
setblock ~35 ~118 ~69 dirt
setblock ~35 ~118 ~70 dirt
setblock ~35 ~118 ~71 dirt
setblock ~35 ~118 ~75 dirt
setblock ~35 ~118 ~76 dirt
setblock ~35 ~118 ~77 dirt
setblock ~35 ~118 ~78 dirt
setblock ~35 ~118 ~79 dirt
setblock ~35 ~118 ~80 dirt
setblock ~35 ~118 ~81 dirt
setblock ~35 ~118 ~82 dirt
setblock ~35 ~118 ~83 dirt
setblock ~35 ~118 ~84 dirt
setblock ~35 ~118 ~85 dirt
setblock ~35 ~118 ~86 dirt
setblock ~35 ~118 ~87 dirt
setblock ~35 ~118 ~88 dirt
setblock ~35 ~118 ~89 dirt
setblock ~35 ~118 ~90 dirt
setblock ~35 ~118 ~91 dirt
setblock ~35 ~118 ~92 dirt
setblock ~35 ~118 ~93 dirt
setblock ~35 ~118 ~94 dirt
setblock ~35 ~118 ~95 dirt
setblock ~35 ~118 ~96 dirt
setblock ~35 ~118 ~97 dirt
setblock ~35 ~118 ~98 dirt
setblock ~35 ~118 ~99 dirt
setblock ~35 ~118 ~100 dirt
setblock ~35 ~118 ~101 dirt
setblock ~35 ~118 ~102 dirt
setblock ~35 ~118 ~103 dirt
setblock ~35 ~118 ~104 dirt
setblock ~35 ~118 ~105 dirt
setblock ~35 ~118 ~106 dirt
setblock ~35 ~118 ~107 dirt
setblock ~35 ~118 ~108 dirt
setblock ~35 ~118 ~109 dirt
setblock ~35 ~118 ~110 dirt
setblock ~35 ~118 ~111 dirt
setblock ~35 ~118 ~116 dirt
setblock ~35 ~118 ~117 dirt
setblock ~35 ~118 ~118 dirt
setblock ~35 ~118 ~119 dirt
setblock ~35 ~119 ~49 dirt
setblock ~35 ~119 ~50 dirt
setblock ~35 ~119 ~51 dirt
setblock ~35 ~119 ~52 dirt
setblock ~35 ~119 ~54 dirt
setblock ~35 ~119 ~60 dirt
setblock ~35 ~119 ~61 dirt
setblock ~35 ~119 ~62 dirt
setblock ~35 ~119 ~63 dirt
setblock ~35 ~119 ~64 dirt
setblock ~35 ~119 ~65 dirt
setblock ~35 ~119 ~66 dirt
setblock ~35 ~119 ~67 dirt
setblock ~35 ~119 ~68 dirt
setblock ~35 ~119 ~69 dirt
setblock ~35 ~119 ~70 dirt
setblock ~35 ~119 ~71 dirt
setblock ~35 ~119 ~74 dirt
setblock ~35 ~119 ~75 dirt
setblock ~35 ~119 ~76 dirt
setblock ~35 ~119 ~77 dirt
setblock ~35 ~119 ~78 dirt
setblock ~35 ~119 ~79 dirt
setblock ~35 ~119 ~80 dirt
setblock ~35 ~119 ~81 dirt
setblock ~35 ~119 ~82 dirt
setblock ~35 ~119 ~83 dirt
setblock ~35 ~119 ~84 dirt
setblock ~35 ~119 ~85 dirt
setblock ~35 ~119 ~86 dirt
setblock ~35 ~119 ~87 dirt
setblock ~35 ~119 ~88 dirt
setblock ~35 ~119 ~89 dirt
setblock ~35 ~119 ~90 dirt
setblock ~35 ~119 ~91 dirt
setblock ~35 ~119 ~92 dirt
setblock ~35 ~119 ~93 dirt
setblock ~35 ~119 ~94 dirt
setblock ~35 ~119 ~95 dirt
setblock ~35 ~119 ~96 dirt
setblock ~35 ~119 ~97 dirt
setblock ~35 ~119 ~98 dirt
setblock ~35 ~119 ~99 dirt
setblock ~35 ~119 ~100 dirt
setblock ~35 ~119 ~101 dirt
setblock ~35 ~119 ~102 dirt
setblock ~35 ~119 ~103 dirt
setblock ~35 ~119 ~104 dirt
setblock ~35 ~119 ~105 dirt
setblock ~35 ~119 ~106 dirt
setblock ~35 ~119 ~107 dirt
setblock ~35 ~119 ~108 dirt
setblock ~35 ~119 ~109 dirt
setblock ~35 ~119 ~110 dirt
setblock ~35 ~119 ~111 dirt
setblock ~35 ~119 ~115 dirt
setblock ~35 ~119 ~116 dirt
setblock ~35 ~119 ~117 dirt
setblock ~35 ~119 ~118 dirt
setblock ~35 ~119 ~119 dirt
setblock ~35 ~119 ~120 dirt
setblock ~35 ~120 ~48 dirt
setblock ~35 ~120 ~49 dirt
setblock ~35 ~120 ~50 dirt
setblock ~35 ~120 ~51 dirt
setblock ~35 ~120 ~52 dirt
setblock ~35 ~120 ~53 dirt
setblock ~35 ~120 ~54 dirt
setblock ~35 ~120 ~55 dirt
setblock ~35 ~120 ~60 dirt
setblock ~35 ~120 ~61 dirt
setblock ~35 ~120 ~62 dirt
setblock ~35 ~120 ~63 dirt
setblock ~35 ~120 ~64 dirt
setblock ~35 ~120 ~65 dirt
setblock ~35 ~120 ~66 dirt
setblock ~35 ~120 ~67 dirt
setblock ~35 ~120 ~68 dirt
setblock ~35 ~120 ~69 dirt
setblock ~35 ~120 ~70 dirt
setblock ~35 ~120 ~71 dirt
setblock ~35 ~120 ~72 dirt
setblock ~35 ~120 ~74 dirt
setblock ~35 ~120 ~75 dirt
setblock ~35 ~120 ~76 dirt
setblock ~35 ~120 ~77 dirt
setblock ~35 ~120 ~78 dirt
setblock ~35 ~120 ~79 dirt
setblock ~35 ~120 ~80 dirt
setblock ~35 ~120 ~81 dirt
setblock ~35 ~120 ~82 dirt
setblock ~35 ~120 ~83 dirt
setblock ~35 ~120 ~84 dirt
setblock ~35 ~120 ~85 dirt
setblock ~35 ~120 ~86 dirt
setblock ~35 ~120 ~87 dirt
setblock ~35 ~120 ~88 dirt
setblock ~35 ~120 ~89 dirt
setblock ~35 ~120 ~90 dirt
setblock ~35 ~120 ~91 dirt
setblock ~35 ~120 ~92 dirt
setblock ~35 ~120 ~93 dirt
setblock ~35 ~120 ~94 dirt
setblock ~35 ~120 ~95 dirt
setblock ~35 ~120 ~96 dirt
setblock ~35 ~120 ~97 dirt
setblock ~35 ~120 ~98 dirt
setblock ~35 ~120 ~99 dirt
setblock ~35 ~120 ~100 dirt
setblock ~35 ~120 ~101 dirt
setblock ~35 ~120 ~102 dirt
setblock ~35 ~120 ~103 dirt
setblock ~35 ~120 ~104 dirt
setblock ~35 ~120 ~105 dirt
setblock ~35 ~120 ~106 dirt
setblock ~35 ~120 ~107 dirt
setblock ~35 ~120 ~108 dirt
setblock ~35 ~120 ~109 dirt
setblock ~35 ~120 ~110 dirt
setblock ~35 ~120 ~111 dirt
setblock ~35 ~120 ~114 dirt
setblock ~35 ~120 ~115 dirt
setblock ~35 ~120 ~116 dirt
setblock ~35 ~120 ~117 dirt
setblock ~35 ~120 ~118 dirt
setblock ~35 ~120 ~119 dirt
setblock ~35 ~120 ~120 dirt
setblock ~35 ~121 ~47 dirt
setblock ~35 ~121 ~48 dirt
setblock ~35 ~121 ~49 dirt
setblock ~35 ~121 ~50 dirt
setblock ~35 ~121 ~51 dirt
setblock ~35 ~121 ~52 dirt
setblock ~35 ~121 ~53 dirt
setblock ~35 ~121 ~54 dirt
setblock ~35 ~121 ~55 dirt
setblock ~35 ~121 ~59 dirt
setblock ~35 ~121 ~60 dirt
setblock ~35 ~121 ~61 dirt
setblock ~35 ~121 ~62 dirt
setblock ~35 ~121 ~63 dirt
setblock ~35 ~121 ~64 dirt
setblock ~35 ~121 ~65 dirt
setblock ~35 ~121 ~66 dirt
setblock ~35 ~121 ~67 dirt
setblock ~35 ~121 ~68 dirt
setblock ~35 ~121 ~69 dirt
setblock ~35 ~121 ~70 dirt
setblock ~35 ~121 ~71 dirt
setblock ~35 ~121 ~72 dirt
setblock ~35 ~121 ~73 dirt
setblock ~35 ~121 ~74 dirt
setblock ~35 ~121 ~75 dirt
setblock ~35 ~121 ~76 dirt
setblock ~35 ~121 ~77 dirt
setblock ~35 ~121 ~78 dirt
setblock ~35 ~121 ~79 dirt
setblock ~35 ~121 ~80 dirt
setblock ~35 ~121 ~81 dirt
setblock ~35 ~121 ~82 dirt
setblock ~35 ~121 ~83 dirt
setblock ~35 ~121 ~84 dirt
setblock ~35 ~121 ~85 dirt
setblock ~35 ~121 ~86 dirt
setblock ~35 ~121 ~87 dirt
setblock ~35 ~121 ~88 dirt
setblock ~35 ~121 ~89 dirt
setblock ~35 ~121 ~90 dirt
setblock ~35 ~121 ~91 dirt
setblock ~35 ~121 ~92 dirt
setblock ~35 ~121 ~93 dirt
setblock ~35 ~121 ~94 dirt
setblock ~35 ~121 ~95 dirt
setblock ~35 ~121 ~96 dirt
setblock ~35 ~121 ~97 dirt
setblock ~35 ~121 ~98 dirt
setblock ~35 ~121 ~99 dirt
setblock ~35 ~121 ~100 dirt
setblock ~35 ~121 ~101 dirt
setblock ~35 ~121 ~102 dirt
setblock ~35 ~121 ~103 dirt
setblock ~35 ~121 ~104 dirt
setblock ~35 ~121 ~105 dirt
setblock ~35 ~121 ~106 dirt
setblock ~35 ~121 ~107 dirt
setblock ~35 ~121 ~108 dirt
setblock ~35 ~121 ~109 dirt
setblock ~35 ~121 ~110 dirt
setblock ~35 ~121 ~111 dirt
setblock ~35 ~121 ~112 dirt
setblock ~35 ~121 ~113 dirt
setblock ~35 ~121 ~114 dirt
setblock ~35 ~121 ~115 dirt
setblock ~35 ~121 ~116 dirt
