setblock ~165 ~124 ~196 dirt
setblock ~165 ~124 ~197 dirt
setblock ~165 ~124 ~198 dirt
setblock ~165 ~124 ~199 dirt
setblock ~165 ~125 ~0 short_grass
setblock ~165 ~125 ~2 fern
setblock ~165 ~125 ~6 grass_block
setblock ~165 ~125 ~7 grass_block
setblock ~165 ~125 ~8 grass_block
setblock ~165 ~125 ~9 grass_block
setblock ~165 ~125 ~10 grass_block
setblock ~165 ~125 ~11 grass_block
setblock ~165 ~125 ~12 grass_block
setblock ~165 ~125 ~14 short_grass
setblock ~165 ~125 ~31 short_grass
setblock ~165 ~125 ~32 short_grass
setblock ~165 ~125 ~33 fern
setblock ~165 ~125 ~34 grass_block
setblock ~165 ~125 ~35 grass_block
setblock ~165 ~125 ~36 grass_block
setblock ~165 ~125 ~37 dirt
setblock ~165 ~125 ~38 dirt
setblock ~165 ~125 ~39 dirt
setblock ~165 ~125 ~40 dirt
setblock ~165 ~125 ~41 dirt
setblock ~165 ~125 ~42 dirt
setblock ~165 ~125 ~43 dirt
setblock ~165 ~125 ~44 grass_block
setblock ~165 ~125 ~45 grass_block
setblock ~165 ~125 ~46 grass_block
setblock ~165 ~125 ~48 short_grass
setblock ~165 ~125 ~64 short_grass
setblock ~165 ~125 ~67 grass_block
setblock ~165 ~125 ~68 grass_block
setblock ~165 ~125 ~69 grass_block
setblock ~165 ~125 ~70 dirt
setblock ~165 ~125 ~71 dirt
setblock ~165 ~125 ~72 dirt
setblock ~165 ~125 ~73 grass_block
setblock ~165 ~125 ~74 grass_block
setblock ~165 ~125 ~75 grass_block
setblock ~165 ~125 ~76 grass_block
setblock ~165 ~125 ~77 grass_block
setblock ~165 ~125 ~78 grass_block
setblock ~165 ~125 ~80 short_grass
setblock ~165 ~125 ~82 grass_block
setblock ~165 ~125 ~83 grass_block
setblock ~165 ~125 ~84 grass_block
setblock ~165 ~125 ~85 grass_block
setblock ~165 ~125 ~86 grass_block
setblock ~165 ~125 ~87 grass_block
setblock ~165 ~125 ~88 dirt
setblock ~165 ~125 ~89 dirt
setblock ~165 ~125 ~90 dirt
setblock ~165 ~125 ~91 dirt
setblock ~165 ~125 ~92 dirt
setblock ~165 ~125 ~93 dirt
setblock ~165 ~125 ~94 dirt
setblock ~165 ~125 ~95 dirt
setblock ~165 ~125 ~96 dirt
setblock ~165 ~125 ~97 dirt
setblock ~165 ~125 ~98 grass_block
setblock ~165 ~125 ~99 grass_block
setblock ~165 ~125 ~100 grass_block
setblock ~165 ~125 ~101 grass_block
setblock ~165 ~125 ~102 grass_block
setblock ~165 ~125 ~103 grass_block
setblock ~165 ~125 ~104 grass_block
setblock ~165 ~125 ~105 grass_block
setblock ~165 ~125 ~106 grass_block
setblock ~165 ~125 ~107 fern
setblock ~165 ~125 ~109 fern
setblock ~165 ~125 ~110 short_grass
setblock ~165 ~125 ~111 short_grass
setblock ~165 ~125 ~113 short_grass
setblock ~165 ~125 ~117 short_grass
setblock ~165 ~125 ~118 grass_block
setblock ~165 ~125 ~119 grass_block
setblock ~165 ~125 ~120 grass_block
setblock ~165 ~125 ~121 grass_block
setblock ~165 ~125 ~122 grass_block
setblock ~165 ~125 ~128 short_grass
setblock ~165 ~125 ~130 poppy
setblock ~165 ~125 ~144 short_grass
setblock ~165 ~125 ~146 grass_block
setblock ~165 ~125 ~147 grass_block
setblock ~165 ~125 ~148 grass_block
setblock ~165 ~125 ~149 grass_block
setblock ~165 ~125 ~150 grass_block
setblock ~165 ~125 ~151 grass_block
setblock ~165 ~125 ~152 grass_block
setblock ~165 ~125 ~153 grass_block
setblock ~165 ~125 ~154 grass_block
setblock ~165 ~125 ~155 grass_block
setblock ~165 ~125 ~156 grass_block
setblock ~165 ~125 ~157 grass_block
setblock ~165 ~125 ~158 grass_block
setblock ~165 ~125 ~159 grass_block
setblock ~165 ~125 ~160 grass_block
setblock ~165 ~125 ~161 grass_block
setblock ~165 ~125 ~162 dirt
setblock ~165 ~125 ~163 dirt
setblock ~165 ~125 ~164 dirt
setblock ~165 ~125 ~165 dirt
setblock ~165 ~125 ~166 dirt
setblock ~165 ~125 ~167 dirt
setblock ~165 ~125 ~168 dirt
setblock ~165 ~125 ~169 dirt
setblock ~165 ~125 ~170 dirt
setblock ~165 ~125 ~171 dirt
setblock ~165 ~125 ~172 dirt
setblock ~165 ~125 ~173 dirt
setblock ~165 ~125 ~174 dirt
setblock ~165 ~125 ~175 dirt
setblock ~165 ~125 ~176 grass_block
setblock ~165 ~125 ~177 grass_block
setblock ~165 ~125 ~178 grass_block
setblock ~165 ~125 ~179 grass_block
setblock ~165 ~125 ~181 grass_block
setblock ~165 ~125 ~182 grass_block
setblock ~165 ~125 ~183 grass_block
setblock ~165 ~125 ~184 grass_block
setblock ~165 ~125 ~185 dirt
setblock ~165 ~125 ~186 dirt
setblock ~165 ~125 ~187 dirt
setblock ~165 ~125 ~188 dirt
setblock ~165 ~125 ~189 dirt
setblock ~165 ~125 ~190 dirt
setblock ~165 ~125 ~191 dirt
setblock ~165 ~125 ~192 dirt
setblock ~165 ~125 ~193 dirt
setblock ~165 ~125 ~194 dirt
setblock ~165 ~125 ~195 dirt
setblock ~165 ~125 ~196 dirt
setblock ~165 ~125 ~197 dirt
setblock ~165 ~125 ~198 dirt
setblock ~165 ~125 ~199 dirt
setblock ~165 ~126 ~37 grass_block
setblock ~165 ~126 ~38 grass_block
setblock ~165 ~126 ~39 grass_block
setblock ~165 ~126 ~40 dirt
setblock ~165 ~126 ~41 grass_block
setblock ~165 ~126 ~42 grass_block
setblock ~165 ~126 ~43 grass_block
setblock ~165 ~126 ~46 short_grass
setblock ~165 ~126 ~68 short_grass
setblock ~165 ~126 ~70 grass_block
setblock ~165 ~126 ~71 grass_block
setblock ~165 ~126 ~72 grass_block
setblock ~165 ~126 ~73 short_grass
setblock ~165 ~126 ~83 poppy
setblock ~165 ~126 ~86 fern
setblock ~165 ~126 ~88 grass_block
setblock ~165 ~126 ~89 grass_block
setblock ~165 ~126 ~90 grass_block
setblock ~165 ~126 ~91 grass_block
setblock ~165 ~126 ~92 grass_block
setblock ~165 ~126 ~93 grass_block
setblock ~165 ~126 ~94 grass_block
setblock ~165 ~126 ~95 grass_block
setblock ~165 ~126 ~96 grass_block
setblock ~165 ~126 ~97 grass_block
setblock ~165 ~126 ~98 short_grass
setblock ~165 ~126 ~103 short_grass
setblock ~165 ~126 ~146 poppy
setblock ~165 ~126 ~151 short_grass
setblock ~165 ~126 ~152 short_grass
setblock ~165 ~126 ~156 fern
setblock ~165 ~126 ~157 short_grass
setblock ~165 ~126 ~162 grass_block
setblock ~165 ~126 ~163 grass_block
setblock ~165 ~126 ~164 grass_block
setblock ~165 ~126 ~165 dirt
setblock ~165 ~126 ~166 dirt
setblock ~165 ~126 ~167 dirt
setblock ~165 ~126 ~168 dirt
setblock ~165 ~126 ~169 dirt
setblock ~165 ~126 ~170 dirt
setblock ~165 ~126 ~171 dirt
setblock ~165 ~126 ~172 dirt
setblock ~165 ~126 ~173 dirt
setblock ~165 ~126 ~174 grass_block
setblock ~165 ~126 ~175 grass_block
setblock ~165 ~126 ~178 short_grass
setblock ~165 ~126 ~184 short_grass
setblock ~165 ~126 ~185 grass_block
setblock ~165 ~126 ~186 grass_block
setblock ~165 ~126 ~187 grass_block
setblock ~165 ~126 ~188 grass_block
setblock ~165 ~126 ~189 dirt
setblock ~165 ~126 ~190 dirt
setblock ~165 ~126 ~191 dirt
setblock ~165 ~126 ~192 dirt
setblock ~165 ~126 ~193 dirt
setblock ~165 ~126 ~194 dirt
setblock ~165 ~126 ~195 dirt
setblock ~165 ~126 ~196 dirt
setblock ~165 ~126 ~197 dirt
setblock ~165 ~126 ~198 dirt
setblock ~165 ~126 ~199 dirt
setblock ~165 ~127 ~39 short_grass
setblock ~165 ~127 ~40 grass_block
setblock ~165 ~127 ~42 short_grass
setblock ~165 ~127 ~88 fern
setblock ~165 ~127 ~90 short_grass
setblock ~165 ~127 ~92 short_grass
setblock ~165 ~127 ~93 short_grass
setblock ~165 ~127 ~94 short_grass
setblock ~165 ~127 ~95 poppy
setblock ~165 ~127 ~165 grass_block
setblock ~165 ~127 ~166 grass_block
setblock ~165 ~127 ~167 grass_block
setblock ~165 ~127 ~168 dirt
setblock ~165 ~127 ~169 dirt
setblock ~165 ~127 ~170 dirt
setblock ~165 ~127 ~171 grass_block
setblock ~165 ~127 ~172 grass_block
setblock ~165 ~127 ~173 grass_block
setblock ~165 ~127 ~174 short_grass
setblock ~165 ~127 ~186 short_grass
setblock ~165 ~127 ~189 grass_block
setblock ~165 ~127 ~190 grass_block
setblock ~165 ~127 ~191 grass_block
setblock ~165 ~127 ~192 grass_block
setblock ~165 ~127 ~193 grass_block
setblock ~165 ~127 ~194 grass_block
setblock ~165 ~127 ~195 dirt
setblock ~165 ~127 ~196 dirt
setblock ~165 ~127 ~197 dirt
setblock ~165 ~127 ~198 dirt
setblock ~165 ~127 ~199 dirt
setblock ~165 ~128 ~40 short_grass
setblock ~165 ~128 ~166 short_grass
setblock ~165 ~128 ~168 grass_block
setblock ~165 ~128 ~169 grass_block
setblock ~165 ~128 ~170 grass_block
setblock ~165 ~128 ~189 poppy
setblock ~165 ~128 ~190 short_grass
setblock ~165 ~128 ~194 short_grass
setblock ~165 ~128 ~195 grass_block
setblock ~165 ~128 ~196 grass_block
setblock ~165 ~128 ~197 grass_block
setblock ~165 ~128 ~198 grass_block
setblock ~165 ~128 ~199 dirt
setblock ~165 ~129 ~169 short_grass
setblock ~165 ~129 ~197 short_grass
setblock ~165 ~129 ~198 fern
setblock ~165 ~129 ~199 grass_block
setblock ~165 ~130 ~199 short_grass
setblock ~166 ~122 ~0 dirt
setblock ~166 ~122 ~1 dirt
setblock ~166 ~122 ~2 dirt
setblock ~166 ~122 ~3 dirt
setblock ~166 ~122 ~4 dirt
setblock ~166 ~122 ~5 dirt
setblock ~166 ~122 ~6 dirt
setblock ~166 ~122 ~7 dirt
setblock ~166 ~122 ~8 dirt
setblock ~166 ~122 ~9 dirt
setblock ~166 ~122 ~10 dirt
setblock ~166 ~122 ~11 dirt
setblock ~166 ~122 ~12 dirt
setblock ~166 ~122 ~13 dirt
setblock ~166 ~122 ~14 dirt
setblock ~166 ~122 ~15 dirt
setblock ~166 ~122 ~16 dirt
setblock ~166 ~122 ~17 dirt
setblock ~166 ~122 ~18 dirt
setblock ~166 ~122 ~19 dirt
setblock ~166 ~122 ~20 dirt
setblock ~166 ~122 ~21 dirt
setblock ~166 ~122 ~22 dirt
setblock ~166 ~122 ~23 dirt
setblock ~166 ~122 ~24 dirt
setblock ~166 ~122 ~25 dirt
setblock ~166 ~122 ~26 dirt
setblock ~166 ~122 ~27 dirt
setblock ~166 ~122 ~28 dirt
setblock ~166 ~122 ~29 dirt
setblock ~166 ~122 ~30 dirt
setblock ~166 ~122 ~31 dirt
setblock ~166 ~122 ~32 dirt
setblock ~166 ~122 ~33 dirt
setblock ~166 ~122 ~34 dirt
setblock ~166 ~122 ~35 dirt
setblock ~166 ~122 ~36 dirt
setblock ~166 ~122 ~37 dirt
setblock ~166 ~122 ~38 dirt
setblock ~166 ~122 ~39 dirt
setblock ~166 ~122 ~40 dirt
setblock ~166 ~122 ~41 dirt
setblock ~166 ~122 ~42 dirt
setblock ~166 ~122 ~43 dirt
setblock ~166 ~122 ~44 dirt
setblock ~166 ~122 ~45 dirt
setblock ~166 ~122 ~46 dirt
setblock ~166 ~122 ~47 dirt
setblock ~166 ~122 ~48 dirt
setblock ~166 ~122 ~49 dirt
setblock ~166 ~122 ~50 dirt
setblock ~166 ~122 ~51 dirt
setblock ~166 ~122 ~52 dirt
setblock ~166 ~122 ~53 dirt
setblock ~166 ~122 ~54 dirt
setblock ~166 ~122 ~55 dirt
setblock ~166 ~122 ~56 dirt
setblock ~166 ~122 ~57 dirt
setblock ~166 ~122 ~58 dirt
setblock ~166 ~122 ~59 dirt
setblock ~166 ~122 ~60 dirt
setblock ~166 ~122 ~61 dirt
setblock ~166 ~122 ~62 dirt
setblock ~166 ~122 ~63 dirt
setblock ~166 ~122 ~64 dirt
setblock ~166 ~122 ~65 dirt
setblock ~166 ~122 ~66 dirt
setblock ~166 ~122 ~67 dirt
setblock ~166 ~122 ~68 dirt
setblock ~166 ~122 ~69 dirt
setblock ~166 ~122 ~70 dirt
setblock ~166 ~122 ~71 dirt
setblock ~166 ~122 ~72 dirt
setblock ~166 ~122 ~73 dirt
setblock ~166 ~122 ~74 dirt
setblock ~166 ~122 ~75 dirt
setblock ~166 ~122 ~76 dirt
setblock ~166 ~122 ~77 dirt
setblock ~166 ~122 ~78 dirt
setblock ~166 ~122 ~79 dirt
setblock ~166 ~122 ~80 dirt
setblock ~166 ~122 ~81 dirt
setblock ~166 ~122 ~82 dirt
setblock ~166 ~122 ~83 dirt
setblock ~166 ~122 ~84 dirt
setblock ~166 ~122 ~85 dirt
setblock ~166 ~122 ~86 dirt
setblock ~166 ~122 ~87 dirt
setblock ~166 ~122 ~88 dirt
setblock ~166 ~122 ~89 dirt
setblock ~166 ~122 ~90 dirt
setblock ~166 ~122 ~91 dirt
setblock ~166 ~122 ~92 dirt
setblock ~166 ~122 ~93 dirt
setblock ~166 ~122 ~94 dirt
setblock ~166 ~122 ~95 dirt
setblock ~166 ~122 ~96 dirt
setblock ~166 ~122 ~97 dirt
setblock ~166 ~122 ~98 dirt
setblock ~166 ~122 ~99 dirt
setblock ~166 ~122 ~100 dirt
setblock ~166 ~122 ~101 dirt
setblock ~166 ~122 ~102 dirt
setblock ~166 ~122 ~103 dirt
setblock ~166 ~122 ~104 dirt
setblock ~166 ~122 ~105 dirt
setblock ~166 ~122 ~106 dirt
setblock ~166 ~122 ~107 dirt
setblock ~166 ~122 ~108 dirt
setblock ~166 ~122 ~109 dirt
setblock ~166 ~122 ~110 dirt
setblock ~166 ~122 ~111 dirt
setblock ~166 ~122 ~112 dirt
setblock ~166 ~122 ~113 dirt
setblock ~166 ~122 ~114 dirt
setblock ~166 ~122 ~115 dirt
setblock ~166 ~122 ~116 dirt
setblock ~166 ~122 ~117 dirt
setblock ~166 ~122 ~118 dirt
setblock ~166 ~122 ~119 dirt
setblock ~166 ~122 ~120 dirt
setblock ~166 ~122 ~121 dirt
setblock ~166 ~122 ~122 dirt
setblock ~166 ~122 ~123 dirt
setblock ~166 ~122 ~124 dirt
setblock ~166 ~122 ~125 dirt
setblock ~166 ~122 ~126 dirt
setblock ~166 ~122 ~127 dirt
setblock ~166 ~122 ~128 dirt
setblock ~166 ~122 ~129 dirt
setblock ~166 ~122 ~130 dirt
setblock ~166 ~122 ~131 dirt
setblock ~166 ~122 ~132 dirt
setblock ~166 ~122 ~133 dirt
setblock ~166 ~122 ~134 dirt
setblock ~166 ~122 ~135 dirt
setblock ~166 ~122 ~136 dirt
setblock ~166 ~122 ~137 dirt
setblock ~166 ~122 ~138 dirt
setblock ~166 ~122 ~139 dirt
setblock ~166 ~122 ~140 dirt
setblock ~166 ~122 ~141 dirt
setblock ~166 ~122 ~142 dirt
setblock ~166 ~122 ~143 dirt
setblock ~166 ~122 ~144 dirt
setblock ~166 ~122 ~145 dirt
setblock ~166 ~122 ~146 dirt
setblock ~166 ~122 ~147 dirt
setblock ~166 ~122 ~148 dirt
setblock ~166 ~122 ~149 dirt
setblock ~166 ~122 ~150 dirt
setblock ~166 ~122 ~151 dirt
setblock ~166 ~122 ~152 dirt
setblock ~166 ~122 ~153 dirt
setblock ~166 ~122 ~154 dirt
setblock ~166 ~122 ~155 dirt
setblock ~166 ~122 ~156 dirt
setblock ~166 ~122 ~157 dirt
setblock ~166 ~122 ~158 dirt
setblock ~166 ~122 ~159 dirt
setblock ~166 ~122 ~160 dirt
setblock ~166 ~122 ~161 dirt
setblock ~166 ~122 ~162 dirt
setblock ~166 ~122 ~163 dirt
setblock ~166 ~122 ~164 dirt
setblock ~166 ~122 ~165 dirt
setblock ~166 ~122 ~166 dirt
setblock ~166 ~122 ~167 dirt
setblock ~166 ~122 ~168 dirt
setblock ~166 ~122 ~169 dirt
setblock ~166 ~122 ~170 dirt
setblock ~166 ~122 ~171 dirt
setblock ~166 ~122 ~172 dirt
setblock ~166 ~122 ~173 dirt
setblock ~166 ~122 ~174 dirt
setblock ~166 ~122 ~175 dirt
setblock ~166 ~122 ~176 dirt
setblock ~166 ~122 ~177 dirt
setblock ~166 ~122 ~178 dirt
setblock ~166 ~122 ~179 dirt
setblock ~166 ~122 ~180 dirt
setblock ~166 ~122 ~181 dirt
setblock ~166 ~122 ~182 dirt
setblock ~166 ~122 ~183 dirt
setblock ~166 ~122 ~184 dirt
setblock ~166 ~122 ~185 dirt
setblock ~166 ~122 ~186 dirt
setblock ~166 ~122 ~187 dirt
setblock ~166 ~122 ~188 dirt
setblock ~166 ~122 ~189 dirt
setblock ~166 ~122 ~190 dirt
setblock ~166 ~122 ~191 dirt
setblock ~166 ~122 ~192 dirt
setblock ~166 ~122 ~193 dirt
setblock ~166 ~122 ~194 dirt
setblock ~166 ~122 ~195 dirt
setblock ~166 ~122 ~196 dirt
setblock ~166 ~122 ~197 dirt
setblock ~166 ~122 ~198 dirt
setblock ~166 ~122 ~199 dirt
setblock ~166 ~123 ~0 grass_block
setblock ~166 ~123 ~1 dirt
setblock ~166 ~123 ~2 dirt
setblock ~166 ~123 ~3 dirt
setblock ~166 ~123 ~4 dirt
setblock ~166 ~123 ~5 dirt
setblock ~166 ~123 ~6 dirt
setblock ~166 ~123 ~7 dirt
setblock ~166 ~123 ~8 dirt
setblock ~166 ~123 ~9 dirt
setblock ~166 ~123 ~10 dirt
setblock ~166 ~123 ~11 dirt
setblock ~166 ~123 ~12 dirt
setblock ~166 ~123 ~13 dirt
setblock ~166 ~123 ~14 dirt
setblock ~166 ~123 ~15 dirt
setblock ~166 ~123 ~16 grass_block
setblock ~166 ~123 ~17 grass_block
setblock ~166 ~123 ~18 grass_block
setblock ~166 ~123 ~19 grass_block
setblock ~166 ~123 ~20 grass_block
setblock ~166 ~123 ~21 grass_block
setblock ~166 ~123 ~22 grass_block
setblock ~166 ~123 ~23 grass_block
setblock ~166 ~123 ~24 grass_block
setblock ~166 ~123 ~25 grass_block
setblock ~166 ~123 ~26 grass_block
setblock ~166 ~123 ~27 grass_block
setblock ~166 ~123 ~28 grass_block
setblock ~166 ~123 ~29 grass_block
setblock ~166 ~123 ~30 dirt
setblock ~166 ~123 ~31 dirt
setblock ~166 ~123 ~32 dirt
setblock ~166 ~123 ~33 dirt
setblock ~166 ~123 ~34 dirt
setblock ~166 ~123 ~35 dirt
setblock ~166 ~123 ~36 dirt
setblock ~166 ~123 ~37 dirt
setblock ~166 ~123 ~38 dirt
setblock ~166 ~123 ~39 dirt
setblock ~166 ~123 ~40 dirt
setblock ~166 ~123 ~41 dirt
setblock ~166 ~123 ~42 dirt
setblock ~166 ~123 ~43 dirt
setblock ~166 ~123 ~44 dirt
setblock ~166 ~123 ~45 dirt
setblock ~166 ~123 ~46 dirt
setblock ~166 ~123 ~47 dirt
setblock ~166 ~123 ~48 dirt
setblock ~166 ~123 ~49 dirt
setblock ~166 ~123 ~50 grass_block
setblock ~166 ~123 ~51 grass_block
setblock ~166 ~123 ~52 grass_block
setblock ~166 ~123 ~53 grass_block
setblock ~166 ~123 ~54 grass_block
setblock ~166 ~123 ~55 grass_block
setblock ~166 ~123 ~56 grass_block
setblock ~166 ~123 ~57 grass_block
setblock ~166 ~123 ~58 grass_block
setblock ~166 ~123 ~59 grass_block
setblock ~166 ~123 ~60 grass_block
setblock ~166 ~123 ~61 grass_block
setblock ~166 ~123 ~62 grass_block
setblock ~166 ~123 ~63 grass_block
setblock ~166 ~123 ~64 dirt
setblock ~166 ~123 ~65 dirt
setblock ~166 ~123 ~66 dirt
setblock ~166 ~123 ~67 dirt
setblock ~166 ~123 ~68 dirt
setblock ~166 ~123 ~69 dirt
setblock ~166 ~123 ~70 dirt
setblock ~166 ~123 ~71 dirt
setblock ~166 ~123 ~72 dirt
setblock ~166 ~123 ~73 dirt
setblock ~166 ~123 ~74 dirt
setblock ~166 ~123 ~75 dirt
setblock ~166 ~123 ~76 dirt
setblock ~166 ~123 ~77 dirt
setblock ~166 ~123 ~78 dirt
setblock ~166 ~123 ~79 dirt
setblock ~166 ~123 ~80 dirt
setblock ~166 ~123 ~81 dirt
setblock ~166 ~123 ~82 dirt
setblock ~166 ~123 ~83 dirt
setblock ~166 ~123 ~84 dirt
setblock ~166 ~123 ~85 dirt
setblock ~166 ~123 ~86 dirt
setblock ~166 ~123 ~87 dirt
setblock ~166 ~123 ~88 dirt
setblock ~166 ~123 ~89 dirt
setblock ~166 ~123 ~90 dirt
setblock ~166 ~123 ~91 dirt
setblock ~166 ~123 ~92 dirt
setblock ~166 ~123 ~93 dirt
setblock ~166 ~123 ~94 dirt
setblock ~166 ~123 ~95 dirt
setblock ~166 ~123 ~96 dirt
setblock ~166 ~123 ~97 dirt
setblock ~166 ~123 ~98 dirt
setblock ~166 ~123 ~99 dirt
setblock ~166 ~123 ~100 dirt
setblock ~166 ~123 ~101 dirt
setblock ~166 ~123 ~102 dirt
setblock ~166 ~123 ~103 dirt
setblock ~166 ~123 ~104 dirt
setblock ~166 ~123 ~105 dirt
setblock ~166 ~123 ~106 dirt
setblock ~166 ~123 ~107 dirt
setblock ~166 ~123 ~108 dirt
setblock ~166 ~123 ~109 dirt
setblock ~166 ~123 ~110 dirt
setblock ~166 ~123 ~111 dirt
setblock ~166 ~123 ~112 dirt
setblock ~166 ~123 ~113 dirt
setblock ~166 ~123 ~114 dirt
setblock ~166 ~123 ~115 dirt
setblock ~166 ~123 ~116 dirt
setblock ~166 ~123 ~117 dirt
setblock ~166 ~123 ~118 dirt
setblock ~166 ~123 ~119 dirt
setblock ~166 ~123 ~120 dirt
setblock ~166 ~123 ~121 dirt
setblock ~166 ~123 ~122 dirt
setblock ~166 ~123 ~123 dirt
setblock ~166 ~123 ~124 dirt
setblock ~166 ~123 ~125 dirt
setblock ~166 ~123 ~126 dirt
setblock ~166 ~123 ~127 dirt
setblock ~166 ~123 ~128 dirt
setblock ~166 ~123 ~129 dirt
setblock ~166 ~123 ~130 dirt
setblock ~166 ~123 ~131 dirt
setblock ~166 ~123 ~132 dirt
setblock ~166 ~123 ~133 dirt
setblock ~166 ~123 ~134 dirt
setblock ~166 ~123 ~135 dirt
setblock ~166 ~123 ~136 grass_block
setblock ~166 ~123 ~137 grass_block
setblock ~166 ~123 ~138 grass_block
setblock ~166 ~123 ~139 grass_block
setblock ~166 ~123 ~140 grass_block
setblock ~166 ~123 ~141 grass_block
setblock ~166 ~123 ~142 grass_block
setblock ~166 ~123 ~143 dirt
setblock ~166 ~123 ~144 dirt
setblock ~166 ~123 ~145 dirt
setblock ~166 ~123 ~146 dirt
setblock ~166 ~123 ~147 dirt
setblock ~166 ~123 ~148 dirt
setblock ~166 ~123 ~149 dirt
setblock ~166 ~123 ~150 dirt
setblock ~166 ~123 ~151 dirt
setblock ~166 ~123 ~152 dirt
setblock ~166 ~123 ~153 dirt
setblock ~166 ~123 ~154 dirt
setblock ~166 ~123 ~155 dirt
setblock ~166 ~123 ~156 dirt
setblock ~166 ~123 ~157 dirt
setblock ~166 ~123 ~158 dirt
setblock ~166 ~123 ~159 dirt
setblock ~166 ~123 ~160 dirt
setblock ~166 ~123 ~161 dirt
setblock ~166 ~123 ~162 dirt
setblock ~166 ~123 ~163 dirt
setblock ~166 ~123 ~164 dirt
setblock ~166 ~123 ~165 dirt
setblock ~166 ~123 ~166 dirt
setblock ~166 ~123 ~167 dirt
setblock ~166 ~123 ~168 dirt
setblock ~166 ~123 ~169 dirt
setblock ~166 ~123 ~170 dirt
setblock ~166 ~123 ~171 dirt
setblock ~166 ~123 ~172 dirt
setblock ~166 ~123 ~173 dirt
setblock ~166 ~123 ~174 dirt
setblock ~166 ~123 ~175 dirt
setblock ~166 ~123 ~176 dirt
setblock ~166 ~123 ~177 dirt
setblock ~166 ~123 ~178 dirt
setblock ~166 ~123 ~179 dirt
setblock ~166 ~123 ~180 dirt
setblock ~166 ~123 ~181 dirt
setblock ~166 ~123 ~182 dirt
setblock ~166 ~123 ~183 dirt
setblock ~166 ~123 ~184 dirt
setblock ~166 ~123 ~185 dirt
setblock ~166 ~123 ~186 dirt
setblock ~166 ~123 ~187 dirt
setblock ~166 ~123 ~188 dirt
setblock ~166 ~123 ~189 dirt
setblock ~166 ~123 ~190 dirt
setblock ~166 ~123 ~191 dirt
setblock ~166 ~123 ~192 dirt
setblock ~166 ~123 ~193 dirt
setblock ~166 ~123 ~194 dirt
setblock ~166 ~123 ~195 dirt
setblock ~166 ~123 ~196 dirt
setblock ~166 ~123 ~197 dirt
setblock ~166 ~123 ~198 dirt
setblock ~166 ~123 ~199 dirt
setblock ~166 ~124 ~1 grass_block
setblock ~166 ~124 ~2 grass_block
setblock ~166 ~124 ~3 grass_block
setblock ~166 ~124 ~4 grass_block
setblock ~166 ~124 ~5 grass_block
setblock ~166 ~124 ~6 grass_block
setblock ~166 ~124 ~7 dirt
setblock ~166 ~124 ~8 dirt
setblock ~166 ~124 ~9 dirt
setblock ~166 ~124 ~10 dirt
setblock ~166 ~124 ~11 dirt
setblock ~166 ~124 ~12 grass_block
setblock ~166 ~124 ~13 grass_block
setblock ~166 ~124 ~14 grass_block
setblock ~166 ~124 ~15 grass_block
setblock ~166 ~124 ~16 poppy
setblock ~166 ~124 ~17 short_grass
setblock ~166 ~124 ~18 short_grass
setblock ~166 ~124 ~20 short_grass
setblock ~166 ~124 ~29 short_grass
setblock ~166 ~124 ~30 grass_block
setblock ~166 ~124 ~31 grass_block
setblock ~166 ~124 ~32 grass_block
setblock ~166 ~124 ~33 grass_block
setblock ~166 ~124 ~34 dirt
setblock ~166 ~124 ~35 dirt
setblock ~166 ~124 ~36 dirt
setblock ~166 ~124 ~37 dirt
setblock ~166 ~124 ~38 dirt
setblock ~166 ~124 ~39 dirt
setblock ~166 ~124 ~40 dirt
setblock ~166 ~124 ~41 dirt
setblock ~166 ~124 ~42 dirt
setblock ~166 ~124 ~43 dirt
setblock ~166 ~124 ~44 dirt
setblock ~166 ~124 ~45 dirt
setblock ~166 ~124 ~46 dirt
setblock ~166 ~124 ~47 grass_block
setblock ~166 ~124 ~48 grass_block
setblock ~166 ~124 ~49 grass_block
setblock ~166 ~124 ~52 short_grass
setblock ~166 ~124 ~57 poppy
setblock ~166 ~124 ~60 short_grass
setblock ~166 ~124 ~61 fern
setblock ~166 ~124 ~64 grass_block
setblock ~166 ~124 ~65 grass_block
setblock ~166 ~124 ~66 dirt
setblock ~166 ~124 ~67 dirt
setblock ~166 ~124 ~68 dirt
setblock ~166 ~124 ~69 dirt
setblock ~166 ~124 ~70 dirt
setblock ~166 ~124 ~71 dirt
setblock ~166 ~124 ~72 dirt
setblock ~166 ~124 ~73 dirt
setblock ~166 ~124 ~74 dirt
setblock ~166 ~124 ~75 dirt
setblock ~166 ~124 ~76 dirt
setblock ~166 ~124 ~77 grass_block
setblock ~166 ~124 ~78 grass_block
setblock ~166 ~124 ~79 grass_block
setblock ~166 ~124 ~80 grass_block
setblock ~166 ~124 ~81 grass_block
setblock ~166 ~124 ~82 grass_block
setblock ~166 ~124 ~83 grass_block
setblock ~166 ~124 ~84 grass_block
setblock ~166 ~124 ~85 dirt
setblock ~166 ~124 ~86 dirt
setblock ~166 ~124 ~87 dirt
setblock ~166 ~124 ~88 dirt
setblock ~166 ~124 ~89 dirt
setblock ~166 ~124 ~90 dirt
setblock ~166 ~124 ~91 dirt
setblock ~166 ~124 ~92 dirt
setblock ~166 ~124 ~93 dirt
setblock ~166 ~124 ~94 dirt
setblock ~166 ~124 ~95 dirt
setblock ~166 ~124 ~96 dirt
setblock ~166 ~124 ~97 dirt
setblock ~166 ~124 ~98 dirt
setblock ~166 ~124 ~99 dirt
setblock ~166 ~124 ~100 dirt
setblock ~166 ~124 ~101 dirt
setblock ~166 ~124 ~102 dirt
setblock ~166 ~124 ~103 dirt
setblock ~166 ~124 ~104 dirt
setblock ~166 ~124 ~105 dirt
setblock ~166 ~124 ~106 dirt
setblock ~166 ~124 ~107 grass_block
setblock ~166 ~124 ~108 grass_block
setblock ~166 ~124 ~109 grass_block
setblock ~166 ~124 ~110 grass_block
setblock ~166 ~124 ~111 grass_block
setblock ~166 ~124 ~112 grass_block
setblock ~166 ~124 ~113 grass_block
setblock ~166 ~124 ~114 grass_block
setblock ~166 ~124 ~115 grass_block
setblock ~166 ~124 ~116 grass_block
setblock ~166 ~124 ~117 dirt
setblock ~166 ~124 ~118 dirt
setblock ~166 ~124 ~119 dirt
setblock ~166 ~124 ~120 dirt
setblock ~166 ~124 ~121 dirt
setblock ~166 ~124 ~122 dirt
setblock ~166 ~124 ~123 dirt
setblock ~166 ~124 ~124 dirt
setblock ~166 ~124 ~125 dirt
setblock ~166 ~124 ~126 dirt
setblock ~166 ~124 ~127 dirt
setblock ~166 ~124 ~128 dirt
setblock ~166 ~124 ~129 grass_block
setblock ~166 ~124 ~130 grass_block
setblock ~166 ~124 ~131 grass_block
setblock ~166 ~124 ~132 grass_block
setblock ~166 ~124 ~133 grass_block
setblock ~166 ~124 ~134 grass_block
setblock ~166 ~124 ~135 grass_block
setblock ~166 ~124 ~137 short_grass
setblock ~166 ~124 ~143 grass_block
setblock ~166 ~124 ~144 grass_block
setblock ~166 ~124 ~145 grass_block
setblock ~166 ~124 ~146 dirt
setblock ~166 ~124 ~147 dirt
setblock ~166 ~124 ~148 dirt
setblock ~166 ~124 ~149 dirt
setblock ~166 ~124 ~150 dirt
setblock ~166 ~124 ~151 dirt
setblock ~166 ~124 ~152 dirt
setblock ~166 ~124 ~153 dirt
setblock ~166 ~124 ~154 dirt
setblock ~166 ~124 ~155 dirt
setblock ~166 ~124 ~156 dirt
setblock ~166 ~124 ~157 dirt
setblock ~166 ~124 ~158 dirt
setblock ~166 ~124 ~159 grass_block
setblock ~166 ~124 ~160 grass_block
setblock ~166 ~124 ~161 dirt
setblock ~166 ~124 ~162 dirt
setblock ~166 ~124 ~163 dirt
setblock ~166 ~124 ~164 dirt
setblock ~166 ~124 ~165 dirt
setblock ~166 ~124 ~166 dirt
setblock ~166 ~124 ~167 dirt
setblock ~166 ~124 ~168 dirt
setblock ~166 ~124 ~169 dirt
setblock ~166 ~124 ~170 dirt
setblock ~166 ~124 ~171 dirt
setblock ~166 ~124 ~172 dirt
setblock ~166 ~124 ~173 dirt
setblock ~166 ~124 ~174 dirt
setblock ~166 ~124 ~175 dirt
setblock ~166 ~124 ~176 dirt
setblock ~166 ~124 ~177 dirt
setblock ~166 ~124 ~178 dirt
setblock ~166 ~124 ~179 dirt
setblock ~166 ~124 ~180 grass_block
setblock ~166 ~124 ~181 dirt
setblock ~166 ~124 ~182 dirt
setblock ~166 ~124 ~183 dirt
setblock ~166 ~124 ~184 dirt
setblock ~166 ~124 ~185 dirt
setblock ~166 ~124 ~186 dirt
setblock ~166 ~124 ~187 dirt
setblock ~166 ~124 ~188 dirt
setblock ~166 ~124 ~189 dirt
setblock ~166 ~124 ~190 dirt
setblock ~166 ~124 ~191 dirt
setblock ~166 ~124 ~192 dirt
setblock ~166 ~124 ~193 dirt
setblock ~166 ~124 ~194 dirt
setblock ~166 ~124 ~195 dirt
setblock ~166 ~124 ~196 dirt
setblock ~166 ~124 ~197 dirt
setblock ~166 ~124 ~198 dirt
setblock ~166 ~124 ~199 dirt
setblock ~166 ~125 ~5 short_grass
setblock ~166 ~125 ~7 grass_block
setblock ~166 ~125 ~8 grass_block
setblock ~166 ~125 ~9 grass_block
setblock ~166 ~125 ~10 grass_block
setblock ~166 ~125 ~11 grass_block
setblock ~166 ~125 ~13 short_grass
setblock ~166 ~125 ~15 short_grass
setblock ~166 ~125 ~32 poppy
setblock ~166 ~125 ~34 grass_block
setblock ~166 ~125 ~35 grass_block
setblock ~166 ~125 ~36 grass_block
setblock ~166 ~125 ~37 dirt
setblock ~166 ~125 ~38 dirt
setblock ~166 ~125 ~39 dirt
setblock ~166 ~125 ~40 dirt
setblock ~166 ~125 ~41 dirt
setblock ~166 ~125 ~42 dirt
setblock ~166 ~125 ~43 dirt
setblock ~166 ~125 ~44 grass_block
setblock ~166 ~125 ~45 grass_block
setblock ~166 ~125 ~46 grass_block
setblock ~166 ~125 ~48 fern
setblock ~166 ~125 ~49 short_grass
setblock ~166 ~125 ~66 grass_block
setblock ~166 ~125 ~67 grass_block
setblock ~166 ~125 ~68 grass_block
setblock ~166 ~125 ~69 dirt
setblock ~166 ~125 ~70 dirt
setblock ~166 ~125 ~71 dirt
setblock ~166 ~125 ~72 dirt
setblock ~166 ~125 ~73 grass_block
setblock ~166 ~125 ~74 grass_block
setblock ~166 ~125 ~75 grass_block
setblock ~166 ~125 ~76 grass_block
setblock ~166 ~125 ~77 short_grass
setblock ~166 ~125 ~80 short_grass
setblock ~166 ~125 ~83 short_grass
setblock ~166 ~125 ~84 poppy
setblock ~166 ~125 ~85 grass_block
setblock ~166 ~125 ~86 grass_block
setblock ~166 ~125 ~87 grass_block
setblock ~166 ~125 ~88 grass_block
setblock ~166 ~125 ~89 grass_block
setblock ~166 ~125 ~90 dirt
setblock ~166 ~125 ~91 dirt
setblock ~166 ~125 ~92 dirt
setblock ~166 ~125 ~93 dirt
setblock ~166 ~125 ~94 dirt
setblock ~166 ~125 ~95 dirt
setblock ~166 ~125 ~96 dirt
setblock ~166 ~125 ~97 dirt
setblock ~166 ~125 ~98 grass_block
setblock ~166 ~125 ~99 grass_block
setblock ~166 ~125 ~100 grass_block
setblock ~166 ~125 ~101 grass_block
setblock ~166 ~125 ~102 grass_block
setblock ~166 ~125 ~103 grass_block
setblock ~166 ~125 ~104 grass_block
setblock ~166 ~125 ~105 grass_block
setblock ~166 ~125 ~106 grass_block
setblock ~166 ~125 ~107 short_grass
setblock ~166 ~125 ~112 short_grass
setblock ~166 ~125 ~113 short_grass
setblock ~166 ~125 ~114 short_grass
setblock ~166 ~125 ~116 short_grass
setblock ~166 ~125 ~117 grass_block
setblock ~166 ~125 ~118 grass_block
setblock ~166 ~125 ~119 grass_block
setblock ~166 ~125 ~120 grass_block
setblock ~166 ~125 ~121 grass_block
setblock ~166 ~125 ~122 grass_block
setblock ~166 ~125 ~123 grass_block
setblock ~166 ~125 ~124 grass_block
setblock ~166 ~125 ~125 grass_block
setblock ~166 ~125 ~126 grass_block
setblock ~166 ~125 ~127 grass_block
setblock ~166 ~125 ~128 grass_block
setblock ~166 ~125 ~132 short_grass
setblock ~166 ~125 ~146 grass_block
setblock ~166 ~125 ~147 grass_block
setblock ~166 ~125 ~148 grass_block
setblock ~166 ~125 ~149 grass_block
setblock ~166 ~125 ~150 dirt
setblock ~166 ~125 ~151 grass_block
setblock ~166 ~125 ~152 grass_block
setblock ~166 ~125 ~153 grass_block
setblock ~166 ~125 ~154 grass_block
setblock ~166 ~125 ~155 grass_block
setblock ~166 ~125 ~156 grass_block
setblock ~166 ~125 ~157 grass_block
setblock ~166 ~125 ~158 grass_block
setblock ~166 ~125 ~159 short_grass
setblock ~166 ~125 ~161 grass_block
setblock ~166 ~125 ~162 grass_block
setblock ~166 ~125 ~163 dirt
setblock ~166 ~125 ~164 dirt
setblock ~166 ~125 ~165 dirt
setblock ~166 ~125 ~166 dirt
setblock ~166 ~125 ~167 dirt
setblock ~166 ~125 ~168 dirt
setblock ~166 ~125 ~169 dirt
setblock ~166 ~125 ~170 dirt
setblock ~166 ~125 ~171 dirt
setblock ~166 ~125 ~172 dirt
setblock ~166 ~125 ~173 dirt
setblock ~166 ~125 ~174 dirt
setblock ~166 ~125 ~175 dirt
setblock ~166 ~125 ~176 dirt
setblock ~166 ~125 ~177 grass_block
setblock ~166 ~125 ~178 grass_block
setblock ~166 ~125 ~179 grass_block
setblock ~166 ~125 ~181 grass_block
setblock ~166 ~125 ~182 grass_block
setblock ~166 ~125 ~183 grass_block
setblock ~166 ~125 ~184 grass_block
setblock ~166 ~125 ~185 dirt
setblock ~166 ~125 ~186 dirt
setblock ~166 ~125 ~187 dirt
setblock ~166 ~125 ~188 dirt
setblock ~166 ~125 ~189 dirt
setblock ~166 ~125 ~190 dirt
setblock ~166 ~125 ~191 dirt
setblock ~166 ~125 ~192 dirt
setblock ~166 ~125 ~193 dirt
setblock ~166 ~125 ~194 dirt
setblock ~166 ~125 ~195 dirt
setblock ~166 ~125 ~196 dirt
setblock ~166 ~125 ~197 dirt
setblock ~166 ~125 ~198 dirt
setblock ~166 ~125 ~199 dirt
setblock ~166 ~126 ~8 short_grass
setblock ~166 ~126 ~9 short_grass
setblock ~166 ~126 ~35 short_grass
setblock ~166 ~126 ~37 grass_block
setblock ~166 ~126 ~38 grass_block
setblock ~166 ~126 ~39 grass_block
setblock ~166 ~126 ~40 grass_block
setblock ~166 ~126 ~41 grass_block
setblock ~166 ~126 ~42 grass_block
setblock ~166 ~126 ~43 grass_block
setblock ~166 ~126 ~44 fern
setblock ~166 ~126 ~45 short_grass
setblock ~166 ~126 ~66 short_grass
setblock ~166 ~126 ~68 short_grass
setblock ~166 ~126 ~69 grass_block
setblock ~166 ~126 ~70 grass_block
setblock ~166 ~126 ~71 grass_block
setblock ~166 ~126 ~72 grass_block
setblock ~166 ~126 ~73 short_grass
setblock ~166 ~126 ~85 short_grass
setblock ~166 ~126 ~88 short_grass
setblock ~166 ~126 ~90 grass_block
setblock ~166 ~126 ~91 grass_block
setblock ~166 ~126 ~92 grass_block
setblock ~166 ~126 ~93 grass_block
setblock ~166 ~126 ~94 grass_block
setblock ~166 ~126 ~95 grass_block
setblock ~166 ~126 ~96 grass_block
setblock ~166 ~126 ~97 grass_block
setblock ~166 ~126 ~100 short_grass
setblock ~166 ~126 ~102 short_grass
setblock ~166 ~126 ~104 short_grass
setblock ~166 ~126 ~105 short_grass
setblock ~166 ~126 ~120 short_grass
setblock ~166 ~126 ~127 short_grass
setblock ~166 ~126 ~148 short_grass
setblock ~166 ~126 ~149 short_grass
setblock ~166 ~126 ~150 grass_block
setblock ~166 ~126 ~154 short_grass
setblock ~166 ~126 ~155 short_grass
setblock ~166 ~126 ~156 short_grass
setblock ~166 ~126 ~163 grass_block
setblock ~166 ~126 ~164 grass_block
setblock ~166 ~126 ~165 grass_block
setblock ~166 ~126 ~166 dirt
setblock ~166 ~126 ~167 dirt
setblock ~166 ~126 ~168 dirt
setblock ~166 ~126 ~169 dirt
setblock ~166 ~126 ~170 dirt
setblock ~166 ~126 ~171 dirt
setblock ~166 ~126 ~172 dirt
setblock ~166 ~126 ~173 dirt
setblock ~166 ~126 ~174 grass_block
setblock ~166 ~126 ~175 grass_block
setblock ~166 ~126 ~176 grass_block
setblock ~166 ~126 ~177 short_grass
setblock ~166 ~126 ~178 short_grass
setblock ~166 ~126 ~179 short_grass
setblock ~166 ~126 ~181 short_grass
setblock ~166 ~126 ~185 grass_block
setblock ~166 ~126 ~186 grass_block
setblock ~166 ~126 ~187 grass_block
setblock ~166 ~126 ~188 grass_block
setblock ~166 ~126 ~189 dirt
setblock ~166 ~126 ~190 dirt
setblock ~166 ~126 ~191 dirt
setblock ~166 ~126 ~192 dirt
setblock ~166 ~126 ~193 dirt
setblock ~166 ~126 ~194 dirt
setblock ~166 ~126 ~195 dirt
setblock ~166 ~126 ~196 dirt
setblock ~166 ~126 ~197 dirt
setblock ~166 ~126 ~198 dirt
setblock ~166 ~126 ~199 dirt
setblock ~166 ~127 ~91 short_grass
setblock ~166 ~127 ~93 short_grass
setblock ~166 ~127 ~94 short_grass
setblock ~166 ~127 ~95 short_grass
setblock ~166 ~127 ~166 grass_block
setblock ~166 ~127 ~167 grass_block
setblock ~166 ~127 ~168 dirt
setblock ~166 ~127 ~169 dirt
setblock ~166 ~127 ~170 dirt
setblock ~166 ~127 ~171 dirt
setblock ~166 ~127 ~172 grass_block
setblock ~166 ~127 ~173 grass_block
setblock ~166 ~127 ~186 short_grass
setblock ~166 ~127 ~187 short_grass
setblock ~166 ~127 ~188 short_grass
setblock ~166 ~127 ~189 grass_block
setblock ~166 ~127 ~190 grass_block
setblock ~166 ~127 ~191 grass_block
setblock ~166 ~127 ~192 grass_block
setblock ~166 ~127 ~193 grass_block
setblock ~166 ~127 ~194 grass_block
setblock ~166 ~127 ~195 dirt
setblock ~166 ~127 ~196 dirt
setblock ~166 ~127 ~197 dirt
setblock ~166 ~127 ~198 dirt
setblock ~166 ~127 ~199 dirt
setblock ~166 ~128 ~168 grass_block
setblock ~166 ~128 ~169 grass_block
setblock ~166 ~128 ~170 grass_block
setblock ~166 ~128 ~171 grass_block
setblock ~166 ~128 ~172 short_grass
setblock ~166 ~128 ~194 short_grass
setblock ~166 ~128 ~195 grass_block
setblock ~166 ~128 ~196 grass_block
setblock ~166 ~128 ~197 grass_block
setblock ~166 ~128 ~198 grass_block
setblock ~166 ~128 ~199 dirt
setblock ~166 ~129 ~199 grass_block
setblock ~166 ~130 ~199 poppy
setblock ~167 ~122 ~0 dirt
setblock ~167 ~122 ~1 dirt
setblock ~167 ~122 ~2 dirt
setblock ~167 ~122 ~3 dirt
setblock ~167 ~122 ~4 dirt
setblock ~167 ~122 ~5 dirt
setblock ~167 ~122 ~6 dirt
setblock ~167 ~122 ~7 dirt
setblock ~167 ~122 ~8 dirt
setblock ~167 ~122 ~9 dirt
setblock ~167 ~122 ~10 dirt
setblock ~167 ~122 ~11 dirt
setblock ~167 ~122 ~12 dirt
setblock ~167 ~122 ~13 dirt
setblock ~167 ~122 ~14 dirt
setblock ~167 ~122 ~15 dirt
setblock ~167 ~122 ~16 dirt
setblock ~167 ~122 ~17 dirt
setblock ~167 ~122 ~18 dirt
setblock ~167 ~122 ~19 dirt
setblock ~167 ~122 ~20 dirt
setblock ~167 ~122 ~21 dirt
setblock ~167 ~122 ~22 dirt
setblock ~167 ~122 ~23 dirt
setblock ~167 ~122 ~24 dirt
setblock ~167 ~122 ~25 dirt
setblock ~167 ~122 ~26 dirt
setblock ~167 ~122 ~27 dirt
setblock ~167 ~122 ~28 dirt
setblock ~167 ~122 ~29 dirt
setblock ~167 ~122 ~30 dirt
setblock ~167 ~122 ~31 dirt
setblock ~167 ~122 ~32 dirt
setblock ~167 ~122 ~33 dirt
setblock ~167 ~122 ~34 dirt
setblock ~167 ~122 ~35 dirt
setblock ~167 ~122 ~36 dirt
setblock ~167 ~122 ~37 dirt
setblock ~167 ~122 ~38 dirt
setblock ~167 ~122 ~39 dirt
setblock ~167 ~122 ~40 dirt
setblock ~167 ~122 ~41 dirt
setblock ~167 ~122 ~42 dirt
setblock ~167 ~122 ~43 dirt
setblock ~167 ~122 ~44 dirt
setblock ~167 ~122 ~45 dirt
setblock ~167 ~122 ~46 dirt
setblock ~167 ~122 ~47 dirt
setblock ~167 ~122 ~48 dirt
setblock ~167 ~122 ~49 dirt
setblock ~167 ~122 ~50 dirt
setblock ~167 ~122 ~51 dirt
setblock ~167 ~122 ~52 dirt
setblock ~167 ~122 ~53 dirt
setblock ~167 ~122 ~54 dirt
setblock ~167 ~122 ~55 dirt
setblock ~167 ~122 ~56 dirt
setblock ~167 ~122 ~57 dirt
setblock ~167 ~122 ~58 dirt
setblock ~167 ~122 ~59 grass_block
setblock ~167 ~122 ~60 grass_block
setblock ~167 ~122 ~61 dirt
setblock ~167 ~122 ~62 dirt
setblock ~167 ~122 ~63 dirt
setblock ~167 ~122 ~64 dirt
setblock ~167 ~122 ~65 dirt
setblock ~167 ~122 ~66 dirt
setblock ~167 ~122 ~67 dirt
setblock ~167 ~122 ~68 dirt
setblock ~167 ~122 ~69 dirt
setblock ~167 ~122 ~70 dirt
setblock ~167 ~122 ~71 dirt
setblock ~167 ~122 ~72 dirt
setblock ~167 ~122 ~73 dirt
setblock ~167 ~122 ~74 dirt
setblock ~167 ~122 ~75 dirt
setblock ~167 ~122 ~76 dirt
setblock ~167 ~122 ~77 dirt
setblock ~167 ~122 ~78 dirt
setblock ~167 ~122 ~79 dirt
setblock ~167 ~122 ~80 dirt
setblock ~167 ~122 ~81 dirt
setblock ~167 ~122 ~82 dirt
setblock ~167 ~122 ~83 dirt
setblock ~167 ~122 ~84 dirt
setblock ~167 ~122 ~85 dirt
setblock ~167 ~122 ~86 dirt
setblock ~167 ~122 ~87 dirt
setblock ~167 ~122 ~88 dirt
setblock ~167 ~122 ~89 dirt
setblock ~167 ~122 ~90 dirt
setblock ~167 ~122 ~91 dirt
setblock ~167 ~122 ~92 dirt
setblock ~167 ~122 ~93 dirt
setblock ~167 ~122 ~94 dirt
setblock ~167 ~122 ~95 dirt
setblock ~167 ~122 ~96 dirt
setblock ~167 ~122 ~97 dirt
setblock ~167 ~122 ~98 dirt
setblock ~167 ~122 ~99 dirt
setblock ~167 ~122 ~100 dirt
setblock ~167 ~122 ~101 dirt
setblock ~167 ~122 ~102 dirt
setblock ~167 ~122 ~103 dirt
setblock ~167 ~122 ~104 dirt
setblock ~167 ~122 ~105 dirt
setblock ~167 ~122 ~106 dirt
setblock ~167 ~122 ~107 dirt
setblock ~167 ~122 ~108 dirt
setblock ~167 ~122 ~109 dirt
setblock ~167 ~122 ~110 dirt
setblock ~167 ~122 ~111 dirt
setblock ~167 ~122 ~112 dirt
setblock ~167 ~122 ~113 dirt
setblock ~167 ~122 ~114 dirt
setblock ~167 ~122 ~115 dirt
setblock ~167 ~122 ~116 dirt
setblock ~167 ~122 ~117 dirt
setblock ~167 ~122 ~118 dirt
setblock ~167 ~122 ~119 dirt
setblock ~167 ~122 ~120 dirt
setblock ~167 ~122 ~121 dirt
setblock ~167 ~122 ~122 dirt
setblock ~167 ~122 ~123 dirt
setblock ~167 ~122 ~124 dirt
setblock ~167 ~122 ~125 dirt
setblock ~167 ~122 ~126 dirt
setblock ~167 ~122 ~127 dirt
setblock ~167 ~122 ~128 dirt
setblock ~167 ~122 ~129 dirt
setblock ~167 ~122 ~130 dirt
setblock ~167 ~122 ~131 dirt
setblock ~167 ~122 ~132 dirt
setblock ~167 ~122 ~133 dirt
setblock ~167 ~122 ~134 dirt
setblock ~167 ~122 ~135 dirt
setblock ~167 ~122 ~136 dirt
setblock ~167 ~122 ~137 dirt
setblock ~167 ~122 ~138 dirt
setblock ~167 ~122 ~139 dirt
setblock ~167 ~122 ~140 dirt
setblock ~167 ~122 ~141 dirt
setblock ~167 ~122 ~142 dirt
setblock ~167 ~122 ~143 dirt
setblock ~167 ~122 ~144 dirt
setblock ~167 ~122 ~145 dirt
setblock ~167 ~122 ~146 dirt
setblock ~167 ~122 ~147 dirt
setblock ~167 ~122 ~148 dirt
setblock ~167 ~122 ~149 dirt
setblock ~167 ~122 ~150 dirt
setblock ~167 ~122 ~151 dirt
setblock ~167 ~122 ~152 dirt
setblock ~167 ~122 ~153 dirt
setblock ~167 ~122 ~154 dirt
setblock ~167 ~122 ~155 dirt
setblock ~167 ~122 ~156 dirt
setblock ~167 ~122 ~157 dirt
setblock ~167 ~122 ~158 dirt
setblock ~167 ~122 ~159 dirt
setblock ~167 ~122 ~160 dirt
setblock ~167 ~122 ~161 dirt
setblock ~167 ~122 ~162 dirt
setblock ~167 ~122 ~163 dirt
setblock ~167 ~122 ~164 dirt
setblock ~167 ~122 ~165 dirt
setblock ~167 ~122 ~166 dirt
setblock ~167 ~122 ~167 dirt
setblock ~167 ~122 ~168 dirt
setblock ~167 ~122 ~169 dirt
setblock ~167 ~122 ~170 dirt
setblock ~167 ~122 ~171 dirt
setblock ~167 ~122 ~172 dirt
setblock ~167 ~122 ~173 dirt
setblock ~167 ~122 ~174 dirt
setblock ~167 ~122 ~175 dirt
setblock ~167 ~122 ~176 dirt
setblock ~167 ~122 ~177 dirt
setblock ~167 ~122 ~178 dirt
setblock ~167 ~122 ~179 dirt
setblock ~167 ~122 ~180 dirt
setblock ~167 ~122 ~181 dirt
setblock ~167 ~122 ~182 dirt
setblock ~167 ~122 ~183 dirt
setblock ~167 ~122 ~184 dirt
setblock ~167 ~122 ~185 dirt
setblock ~167 ~122 ~186 dirt
setblock ~167 ~122 ~187 dirt
setblock ~167 ~122 ~188 dirt
setblock ~167 ~122 ~189 dirt
setblock ~167 ~122 ~190 dirt
setblock ~167 ~122 ~191 dirt
setblock ~167 ~122 ~192 dirt
setblock ~167 ~122 ~193 dirt
setblock ~167 ~122 ~194 dirt
setblock ~167 ~122 ~195 dirt
setblock ~167 ~122 ~196 dirt
setblock ~167 ~122 ~197 dirt
setblock ~167 ~122 ~198 dirt
setblock ~167 ~122 ~199 dirt
setblock ~167 ~123 ~0 grass_block
setblock ~167 ~123 ~1 dirt
setblock ~167 ~123 ~2 dirt
setblock ~167 ~123 ~3 dirt
setblock ~167 ~123 ~4 dirt
setblock ~167 ~123 ~5 dirt
setblock ~167 ~123 ~6 dirt
setblock ~167 ~123 ~7 dirt
setblock ~167 ~123 ~8 dirt
setblock ~167 ~123 ~9 dirt
setblock ~167 ~123 ~10 dirt
setblock ~167 ~123 ~11 dirt
setblock ~167 ~123 ~12 dirt
setblock ~167 ~123 ~13 dirt
setblock ~167 ~123 ~14 dirt
setblock ~167 ~123 ~15 dirt
setblock ~167 ~123 ~16 grass_block
setblock ~167 ~123 ~17 grass_block
setblock ~167 ~123 ~18 grass_block
setblock ~167 ~123 ~19 grass_block
setblock ~167 ~123 ~20 grass_block
setblock ~167 ~123 ~21 grass_block
setblock ~167 ~123 ~22 grass_block
setblock ~167 ~123 ~23 grass_block
setblock ~167 ~123 ~24 grass_block
setblock ~167 ~123 ~25 grass_block
setblock ~167 ~123 ~26 grass_block
setblock ~167 ~123 ~27 dirt
setblock ~167 ~123 ~28 dirt
setblock ~167 ~123 ~29 dirt
setblock ~167 ~123 ~30 dirt
setblock ~167 ~123 ~31 dirt
setblock ~167 ~123 ~32 dirt
setblock ~167 ~123 ~33 dirt
setblock ~167 ~123 ~34 dirt
setblock ~167 ~123 ~35 dirt
setblock ~167 ~123 ~36 dirt
setblock ~167 ~123 ~37 dirt
setblock ~167 ~123 ~38 dirt
setblock ~167 ~123 ~39 dirt
setblock ~167 ~123 ~40 dirt
setblock ~167 ~123 ~41 dirt
setblock ~167 ~123 ~42 dirt
setblock ~167 ~123 ~43 dirt
setblock ~167 ~123 ~44 dirt
setblock ~167 ~123 ~45 dirt
setblock ~167 ~123 ~46 dirt
setblock ~167 ~123 ~47 dirt
setblock ~167 ~123 ~48 dirt
setblock ~167 ~123 ~49 grass_block
setblock ~167 ~123 ~50 grass_block
setblock ~167 ~123 ~51 grass_block
setblock ~167 ~123 ~52 grass_block
setblock ~167 ~123 ~53 grass_block
setblock ~167 ~123 ~54 grass_block
setblock ~167 ~123 ~55 grass_block
setblock ~167 ~123 ~56 grass_block
setblock ~167 ~123 ~57 grass_block
setblock ~167 ~123 ~58 grass_block
setblock ~167 ~123 ~59 short_grass
setblock ~167 ~123 ~61 grass_block
setblock ~167 ~123 ~62 grass_block
setblock ~167 ~123 ~63 grass_block
setblock ~167 ~123 ~64 dirt
setblock ~167 ~123 ~65 dirt
setblock ~167 ~123 ~66 dirt
setblock ~167 ~123 ~67 dirt
setblock ~167 ~123 ~68 dirt
setblock ~167 ~123 ~69 dirt
setblock ~167 ~123 ~70 dirt
setblock ~167 ~123 ~71 dirt
setblock ~167 ~123 ~72 dirt
setblock ~167 ~123 ~73 dirt
setblock ~167 ~123 ~74 dirt
setblock ~167 ~123 ~75 dirt
setblock ~167 ~123 ~76 dirt
setblock ~167 ~123 ~77 dirt
setblock ~167 ~123 ~78 dirt
setblock ~167 ~123 ~79 dirt
setblock ~167 ~123 ~80 grass_block
setblock ~167 ~123 ~81 dirt
setblock ~167 ~123 ~82 dirt
setblock ~167 ~123 ~83 dirt
setblock ~167 ~123 ~84 dirt
setblock ~167 ~123 ~85 dirt
setblock ~167 ~123 ~86 dirt
setblock ~167 ~123 ~87 dirt
setblock ~167 ~123 ~88 dirt
setblock ~167 ~123 ~89 dirt
setblock ~167 ~123 ~90 dirt
setblock ~167 ~123 ~91 dirt
setblock ~167 ~123 ~92 dirt
setblock ~167 ~123 ~93 dirt
setblock ~167 ~123 ~94 dirt
setblock ~167 ~123 ~95 dirt
setblock ~167 ~123 ~96 dirt
setblock ~167 ~123 ~97 dirt
setblock ~167 ~123 ~98 dirt
setblock ~167 ~123 ~99 dirt
setblock ~167 ~123 ~100 dirt
setblock ~167 ~123 ~101 dirt
setblock ~167 ~123 ~102 dirt
setblock ~167 ~123 ~103 dirt
setblock ~167 ~123 ~104 dirt
setblock ~167 ~123 ~105 dirt
setblock ~167 ~123 ~106 dirt
setblock ~167 ~123 ~107 dirt
setblock ~167 ~123 ~108 dirt
setblock ~167 ~123 ~109 dirt
setblock ~167 ~123 ~110 dirt
setblock ~167 ~123 ~111 dirt
setblock ~167 ~123 ~112 dirt
setblock ~167 ~123 ~113 dirt
setblock ~167 ~123 ~114 dirt
setblock ~167 ~123 ~115 dirt
setblock ~167 ~123 ~116 dirt
setblock ~167 ~123 ~117 dirt
setblock ~167 ~123 ~118 dirt
setblock ~167 ~123 ~119 dirt
setblock ~167 ~123 ~120 dirt
setblock ~167 ~123 ~121 dirt
setblock ~167 ~123 ~122 dirt
setblock ~167 ~123 ~123 dirt
setblock ~167 ~123 ~124 dirt
setblock ~167 ~123 ~125 dirt
setblock ~167 ~123 ~126 dirt
setblock ~167 ~123 ~127 dirt
setblock ~167 ~123 ~128 dirt
setblock ~167 ~123 ~129 dirt
setblock ~167 ~123 ~130 dirt
setblock ~167 ~123 ~131 dirt
setblock ~167 ~123 ~132 dirt
setblock ~167 ~123 ~133 dirt
setblock ~167 ~123 ~134 dirt
setblock ~167 ~123 ~135 dirt
setblock ~167 ~123 ~136 dirt
setblock ~167 ~123 ~137 grass_block
setblock ~167 ~123 ~138 grass_block
setblock ~167 ~123 ~139 grass_block
setblock ~167 ~123 ~140 grass_block
setblock ~167 ~123 ~141 grass_block
setblock ~167 ~123 ~142 dirt
setblock ~167 ~123 ~143 dirt
setblock ~167 ~123 ~144 dirt
setblock ~167 ~123 ~145 dirt
setblock ~167 ~123 ~146 dirt
setblock ~167 ~123 ~147 dirt
setblock ~167 ~123 ~148 dirt
setblock ~167 ~123 ~149 dirt
setblock ~167 ~123 ~150 dirt
setblock ~167 ~123 ~151 dirt
setblock ~167 ~123 ~152 dirt
setblock ~167 ~123 ~153 dirt
setblock ~167 ~123 ~154 dirt
setblock ~167 ~123 ~155 dirt
setblock ~167 ~123 ~156 dirt
setblock ~167 ~123 ~157 dirt
setblock ~167 ~123 ~158 dirt
setblock ~167 ~123 ~159 dirt
setblock ~167 ~123 ~160 grass_block
setblock ~167 ~123 ~161 dirt
setblock ~167 ~123 ~162 dirt
setblock ~167 ~123 ~163 dirt
setblock ~167 ~123 ~164 dirt
setblock ~167 ~123 ~165 dirt
setblock ~167 ~123 ~166 dirt
setblock ~167 ~123 ~167 dirt
setblock ~167 ~123 ~168 dirt
setblock ~167 ~123 ~169 dirt
setblock ~167 ~123 ~170 dirt
setblock ~167 ~123 ~171 dirt
setblock ~167 ~123 ~172 dirt
setblock ~167 ~123 ~173 dirt
setblock ~167 ~123 ~174 dirt
setblock ~167 ~123 ~175 dirt
setblock ~167 ~123 ~176 dirt
setblock ~167 ~123 ~177 dirt
setblock ~167 ~123 ~178 dirt
setblock ~167 ~123 ~179 dirt
setblock ~167 ~123 ~180 dirt
setblock ~167 ~123 ~181 dirt
setblock ~167 ~123 ~182 dirt
setblock ~167 ~123 ~183 dirt
setblock ~167 ~123 ~184 dirt
setblock ~167 ~123 ~185 dirt
setblock ~167 ~123 ~186 dirt
setblock ~167 ~123 ~187 dirt
setblock ~167 ~123 ~188 dirt
setblock ~167 ~123 ~189 dirt
setblock ~167 ~123 ~190 dirt
setblock ~167 ~123 ~191 dirt
setblock ~167 ~123 ~192 dirt
setblock ~167 ~123 ~193 dirt
setblock ~167 ~123 ~194 dirt
setblock ~167 ~123 ~195 dirt
setblock ~167 ~123 ~196 dirt
setblock ~167 ~123 ~197 dirt
setblock ~167 ~123 ~198 dirt
setblock ~167 ~123 ~199 dirt
setblock ~167 ~124 ~1 grass_block
setblock ~167 ~124 ~2 grass_block
setblock ~167 ~124 ~3 grass_block
setblock ~167 ~124 ~4 grass_block
setblock ~167 ~124 ~5 grass_block
setblock ~167 ~124 ~6 grass_block
setblock ~167 ~124 ~7 grass_block
setblock ~167 ~124 ~8 grass_block
setblock ~167 ~124 ~9 dirt
setblock ~167 ~124 ~10 dirt
setblock ~167 ~124 ~11 grass_block
setblock ~167 ~124 ~12 grass_block
setblock ~167 ~124 ~13 grass_block
setblock ~167 ~124 ~14 grass_block
setblock ~167 ~124 ~15 grass_block
setblock ~167 ~124 ~20 short_grass
setblock ~167 ~124 ~25 short_grass
setblock ~167 ~124 ~27 grass_block
setblock ~167 ~124 ~28 grass_block
setblock ~167 ~124 ~29 grass_block
setblock ~167 ~124 ~30 grass_block
setblock ~167 ~124 ~31 grass_block
setblock ~167 ~124 ~32 grass_block
setblock ~167 ~124 ~33 dirt
setblock ~167 ~124 ~34 dirt
setblock ~167 ~124 ~35 dirt
setblock ~167 ~124 ~36 dirt
setblock ~167 ~124 ~37 dirt
setblock ~167 ~124 ~38 dirt
setblock ~167 ~124 ~39 dirt
setblock ~167 ~124 ~40 dirt
setblock ~167 ~124 ~41 dirt
setblock ~167 ~124 ~42 dirt
setblock ~167 ~124 ~43 dirt
setblock ~167 ~124 ~44 dirt
setblock ~167 ~124 ~45 dirt
setblock ~167 ~124 ~46 grass_block
setblock ~167 ~124 ~47 grass_block
setblock ~167 ~124 ~48 grass_block
setblock ~167 ~124 ~50 short_grass
setblock ~167 ~124 ~63 short_grass
setblock ~167 ~124 ~64 grass_block
setblock ~167 ~124 ~65 grass_block
setblock ~167 ~124 ~66 dirt
setblock ~167 ~124 ~67 dirt
setblock ~167 ~124 ~68 dirt
setblock ~167 ~124 ~69 dirt
setblock ~167 ~124 ~70 dirt
setblock ~167 ~124 ~71 dirt
setblock ~167 ~124 ~72 dirt
setblock ~167 ~124 ~73 dirt
setblock ~167 ~124 ~74 dirt
setblock ~167 ~124 ~75 dirt
setblock ~167 ~124 ~76 grass_block
setblock ~167 ~124 ~77 grass_block
setblock ~167 ~124 ~78 grass_block
setblock ~167 ~124 ~79 grass_block
setblock ~167 ~124 ~80 short_grass
setblock ~167 ~124 ~81 grass_block
setblock ~167 ~124 ~82 grass_block
setblock ~167 ~124 ~83 grass_block
setblock ~167 ~124 ~84 grass_block
setblock ~167 ~124 ~85 grass_block
setblock ~167 ~124 ~86 dirt
setblock ~167 ~124 ~87 dirt
setblock ~167 ~124 ~88 dirt
setblock ~167 ~124 ~89 dirt
setblock ~167 ~124 ~90 dirt
setblock ~167 ~124 ~91 dirt
setblock ~167 ~124 ~92 dirt
setblock ~167 ~124 ~93 dirt
setblock ~167 ~124 ~94 dirt
setblock ~167 ~124 ~95 dirt
setblock ~167 ~124 ~96 dirt
setblock ~167 ~124 ~97 dirt
setblock ~167 ~124 ~98 dirt
setblock ~167 ~124 ~99 dirt
setblock ~167 ~124 ~100 dirt
setblock ~167 ~124 ~101 dirt
setblock ~167 ~124 ~102 dirt
setblock ~167 ~124 ~103 dirt
setblock ~167 ~124 ~104 dirt
setblock ~167 ~124 ~105 dirt
setblock ~167 ~124 ~106 dirt
setblock ~167 ~124 ~107 grass_block
setblock ~167 ~124 ~108 grass_block
setblock ~167 ~124 ~109 grass_block
setblock ~167 ~124 ~110 grass_block
setblock ~167 ~124 ~111 grass_block
setblock ~167 ~124 ~112 grass_block
setblock ~167 ~124 ~113 grass_block
setblock ~167 ~124 ~114 grass_block
setblock ~167 ~124 ~115 grass_block
setblock ~167 ~124 ~116 dirt
setblock ~167 ~124 ~117 dirt
setblock ~167 ~124 ~118 dirt
setblock ~167 ~124 ~119 dirt
setblock ~167 ~124 ~120 dirt
setblock ~167 ~124 ~121 dirt
setblock ~167 ~124 ~122 dirt
setblock ~167 ~124 ~123 dirt
setblock ~167 ~124 ~124 dirt
setblock ~167 ~124 ~125 dirt
setblock ~167 ~124 ~126 dirt
setblock ~167 ~124 ~127 dirt
setblock ~167 ~124 ~128 dirt
setblock ~167 ~124 ~129 dirt
setblock ~167 ~124 ~130 dirt
setblock ~167 ~124 ~131 dirt
setblock ~167 ~124 ~132 grass_block
setblock ~167 ~124 ~133 grass_block
setblock ~167 ~124 ~134 grass_block
setblock ~167 ~124 ~135 grass_block
setblock ~167 ~124 ~136 grass_block
setblock ~167 ~124 ~137 short_grass
setblock ~167 ~124 ~139 fern
setblock ~167 ~124 ~142 grass_block
setblock ~167 ~124 ~143 grass_block
setblock ~167 ~124 ~144 grass_block
setblock ~167 ~124 ~145 grass_block
setblock ~167 ~124 ~146 dirt
setblock ~167 ~124 ~147 dirt
setblock ~167 ~124 ~148 dirt
setblock ~167 ~124 ~149 dirt
setblock ~167 ~124 ~150 dirt
setblock ~167 ~124 ~151 dirt
setblock ~167 ~124 ~152 dirt
setblock ~167 ~124 ~153 dirt
setblock ~167 ~124 ~154 dirt
setblock ~167 ~124 ~155 dirt
setblock ~167 ~124 ~156 dirt
setblock ~167 ~124 ~157 dirt
setblock ~167 ~124 ~158 grass_block
setblock ~167 ~124 ~159 grass_block
setblock ~167 ~124 ~160 fern
setblock ~167 ~124 ~161 grass_block
setblock ~167 ~124 ~162 dirt
setblock ~167 ~124 ~163 dirt
setblock ~167 ~124 ~164 dirt
setblock ~167 ~124 ~165 dirt
setblock ~167 ~124 ~166 dirt
setblock ~167 ~124 ~167 dirt
setblock ~167 ~124 ~168 dirt
setblock ~167 ~124 ~169 dirt
setblock ~167 ~124 ~170 dirt
setblock ~167 ~124 ~171 dirt
setblock ~167 ~124 ~172 dirt
setblock ~167 ~124 ~173 dirt
setblock ~167 ~124 ~174 dirt
setblock ~167 ~124 ~175 dirt
setblock ~167 ~124 ~176 dirt
setblock ~167 ~124 ~177 dirt
setblock ~167 ~124 ~178 dirt
setblock ~167 ~124 ~179 dirt
setblock ~167 ~124 ~180 dirt
setblock ~167 ~124 ~181 dirt
setblock ~167 ~124 ~182 dirt
setblock ~167 ~124 ~183 dirt
setblock ~167 ~124 ~184 dirt
setblock ~167 ~124 ~185 dirt
setblock ~167 ~124 ~186 dirt
setblock ~167 ~124 ~187 dirt
setblock ~167 ~124 ~188 dirt
setblock ~167 ~124 ~189 dirt
setblock ~167 ~124 ~190 dirt
setblock ~167 ~124 ~191 dirt
setblock ~167 ~124 ~192 dirt
setblock ~167 ~124 ~193 dirt
setblock ~167 ~124 ~194 dirt
setblock ~167 ~124 ~195 dirt
setblock ~167 ~124 ~196 dirt
setblock ~167 ~124 ~197 dirt
setblock ~167 ~124 ~198 dirt
setblock ~167 ~124 ~199 dirt
setblock ~167 ~125 ~1 short_grass
setblock ~167 ~125 ~2 short_grass
setblock ~167 ~125 ~4 short_grass
setblock ~167 ~125 ~5 poppy
setblock ~167 ~125 ~9 grass_block
setblock ~167 ~125 ~10 grass_block
setblock ~167 ~125 ~11 short_grass
setblock ~167 ~125 ~31 poppy
setblock ~167 ~125 ~33 grass_block
setblock ~167 ~125 ~34 grass_block
setblock ~167 ~125 ~35 grass_block
setblock ~167 ~125 ~36 grass_block
setblock ~167 ~125 ~37 dirt
setblock ~167 ~125 ~38 dirt
setblock ~167 ~125 ~39 dirt
setblock ~167 ~125 ~40 dirt
setblock ~167 ~125 ~41 dirt
setblock ~167 ~125 ~42 dirt
setblock ~167 ~125 ~43 grass_block
setblock ~167 ~125 ~44 grass_block
setblock ~167 ~125 ~45 grass_block
setblock ~167 ~125 ~46 poppy
setblock ~167 ~125 ~66 grass_block
setblock ~167 ~125 ~67 grass_block
setblock ~167 ~125 ~68 grass_block
setblock ~167 ~125 ~69 dirt
setblock ~167 ~125 ~70 dirt
setblock ~167 ~125 ~71 dirt
setblock ~167 ~125 ~72 dirt
setblock ~167 ~125 ~73 grass_block
setblock ~167 ~125 ~74 grass_block
setblock ~167 ~125 ~75 grass_block
setblock ~167 ~125 ~77 short_grass
setblock ~167 ~125 ~79 short_grass
setblock ~167 ~125 ~83 short_grass
setblock ~167 ~125 ~86 grass_block
setblock ~167 ~125 ~87 grass_block
setblock ~167 ~125 ~88 grass_block
setblock ~167 ~125 ~89 grass_block
setblock ~167 ~125 ~90 grass_block
setblock ~167 ~125 ~91 grass_block
setblock ~167 ~125 ~92 dirt
setblock ~167 ~125 ~93 dirt
setblock ~167 ~125 ~94 dirt
setblock ~167 ~125 ~95 dirt
setblock ~167 ~125 ~96 dirt
setblock ~167 ~125 ~97 dirt
setblock ~167 ~125 ~98 grass_block
setblock ~167 ~125 ~99 grass_block
setblock ~167 ~125 ~100 grass_block
setblock ~167 ~125 ~101 grass_block
setblock ~167 ~125 ~102 grass_block
setblock ~167 ~125 ~103 grass_block
setblock ~167 ~125 ~104 grass_block
setblock ~167 ~125 ~105 grass_block
setblock ~167 ~125 ~106 grass_block
setblock ~167 ~125 ~109 short_grass
setblock ~167 ~125 ~114 short_grass
setblock ~167 ~125 ~116 grass_block
setblock ~167 ~125 ~117 grass_block
setblock ~167 ~125 ~118 grass_block
setblock ~167 ~125 ~119 grass_block
setblock ~167 ~125 ~120 grass_block
setblock ~167 ~125 ~121 grass_block
setblock ~167 ~125 ~122 grass_block
setblock ~167 ~125 ~123 grass_block
setblock ~167 ~125 ~124 grass_block
setblock ~167 ~125 ~125 grass_block
setblock ~167 ~125 ~126 grass_block
setblock ~167 ~125 ~127 grass_block
setblock ~167 ~125 ~128 grass_block
setblock ~167 ~125 ~129 grass_block
setblock ~167 ~125 ~130 grass_block
setblock ~167 ~125 ~131 grass_block
setblock ~167 ~125 ~133 fern
setblock ~167 ~125 ~134 short_grass
setblock ~167 ~125 ~143 short_grass
setblock ~167 ~125 ~145 short_grass
setblock ~167 ~125 ~146 grass_block
setblock ~167 ~125 ~147 grass_block
setblock ~167 ~125 ~148 grass_block
setblock ~167 ~125 ~149 dirt
setblock ~167 ~125 ~150 dirt
setblock ~167 ~125 ~151 dirt
setblock ~167 ~125 ~152 dirt
setblock ~167 ~125 ~153 grass_block
setblock ~167 ~125 ~154 grass_block
setblock ~167 ~125 ~155 grass_block
setblock ~167 ~125 ~156 grass_block
setblock ~167 ~125 ~157 grass_block
setblock ~167 ~125 ~159 short_grass
setblock ~167 ~125 ~161 short_grass
setblock ~167 ~125 ~162 grass_block
setblock ~167 ~125 ~163 grass_block
setblock ~167 ~125 ~164 dirt
setblock ~167 ~125 ~165 dirt
setblock ~167 ~125 ~166 dirt
setblock ~167 ~125 ~167 dirt
setblock ~167 ~125 ~168 dirt
setblock ~167 ~125 ~169 dirt
setblock ~167 ~125 ~170 dirt
setblock ~167 ~125 ~171 dirt
setblock ~167 ~125 ~172 dirt
setblock ~167 ~125 ~173 dirt
setblock ~167 ~125 ~174 dirt
setblock ~167 ~125 ~175 dirt
setblock ~167 ~125 ~176 dirt
setblock ~167 ~125 ~177 grass_block
setblock ~167 ~125 ~178 grass_block
setblock ~167 ~125 ~179 grass_block
setblock ~167 ~125 ~180 grass_block
setblock ~167 ~125 ~181 grass_block
setblock ~167 ~125 ~182 grass_block
setblock ~167 ~125 ~183 grass_block
setblock ~167 ~125 ~184 dirt
setblock ~167 ~125 ~185 dirt
setblock ~167 ~125 ~186 dirt
setblock ~167 ~125 ~187 dirt
setblock ~167 ~125 ~188 dirt
setblock ~167 ~125 ~189 dirt
setblock ~167 ~125 ~190 dirt
setblock ~167 ~125 ~191 dirt
setblock ~167 ~125 ~192 dirt
setblock ~167 ~125 ~193 dirt
setblock ~167 ~125 ~194 dirt
setblock ~167 ~125 ~195 dirt
setblock ~167 ~125 ~196 dirt
setblock ~167 ~125 ~197 dirt
setblock ~167 ~125 ~198 dirt
setblock ~167 ~125 ~199 dirt
setblock ~167 ~126 ~33 poppy
setblock ~167 ~126 ~37 grass_block
setblock ~167 ~126 ~38 grass_block
setblock ~167 ~126 ~39 grass_block
setblock ~167 ~126 ~40 grass_block
setblock ~167 ~126 ~41 grass_block
setblock ~167 ~126 ~42 grass_block
setblock ~167 ~126 ~45 short_grass
setblock ~167 ~126 ~69 grass_block
setblock ~167 ~126 ~70 grass_block
setblock ~167 ~126 ~71 grass_block
setblock ~167 ~126 ~72 grass_block
setblock ~167 ~126 ~91 fern
setblock ~167 ~126 ~92 grass_block
setblock ~167 ~126 ~93 grass_block
setblock ~167 ~126 ~94 grass_block
setblock ~167 ~126 ~95 grass_block
setblock ~167 ~126 ~96 grass_block
setblock ~167 ~126 ~97 grass_block
setblock ~167 ~126 ~101 short_grass
setblock ~167 ~126 ~102 short_grass
setblock ~167 ~126 ~103 fern
setblock ~167 ~126 ~105 short_grass
setblock ~167 ~126 ~121 fern
setblock ~167 ~126 ~125 short_grass
setblock ~167 ~126 ~126 short_grass
setblock ~167 ~126 ~127 short_grass
setblock ~167 ~126 ~129 short_grass
setblock ~167 ~126 ~130 short_grass
setblock ~167 ~126 ~146 fern
setblock ~167 ~126 ~149 grass_block
setblock ~167 ~126 ~150 grass_block
setblock ~167 ~126 ~151 grass_block
setblock ~167 ~126 ~152 grass_block
setblock ~167 ~126 ~154 short_grass
setblock ~167 ~126 ~164 grass_block
setblock ~167 ~126 ~165 grass_block
setblock ~167 ~126 ~166 dirt
setblock ~167 ~126 ~167 dirt
setblock ~167 ~126 ~168 dirt
setblock ~167 ~126 ~169 dirt
setblock ~167 ~126 ~170 dirt
setblock ~167 ~126 ~171 dirt
setblock ~167 ~126 ~172 dirt
setblock ~167 ~126 ~173 dirt
setblock ~167 ~126 ~174 grass_block
setblock ~167 ~126 ~175 grass_block
setblock ~167 ~126 ~176 grass_block
setblock ~167 ~126 ~178 short_grass
setblock ~167 ~126 ~181 short_grass
setblock ~167 ~126 ~182 poppy
setblock ~167 ~126 ~183 short_grass
setblock ~167 ~126 ~184 grass_block
setblock ~167 ~126 ~185 grass_block
setblock ~167 ~126 ~186 grass_block
setblock ~167 ~126 ~187 grass_block
setblock ~167 ~126 ~188 grass_block
setblock ~167 ~126 ~189 dirt
setblock ~167 ~126 ~190 dirt
setblock ~167 ~126 ~191 dirt
setblock ~167 ~126 ~192 dirt
setblock ~167 ~126 ~193 dirt
setblock ~167 ~126 ~194 dirt
setblock ~167 ~126 ~195 dirt
setblock ~167 ~126 ~196 dirt
setblock ~167 ~126 ~197 dirt
setblock ~167 ~126 ~198 dirt
setblock ~167 ~126 ~199 dirt
setblock ~167 ~127 ~38 short_grass
setblock ~167 ~127 ~39 short_grass
setblock ~167 ~127 ~40 short_grass
setblock ~167 ~127 ~41 poppy
setblock ~167 ~127 ~69 short_grass
setblock ~167 ~127 ~71 fern
setblock ~167 ~127 ~72 short_grass
setblock ~167 ~127 ~96 short_grass
setblock ~167 ~127 ~97 short_grass
setblock ~167 ~127 ~149 short_grass
setblock ~167 ~127 ~166 grass_block
setblock ~167 ~127 ~167 grass_block
setblock ~167 ~127 ~168 grass_block
setblock ~167 ~127 ~169 dirt
setblock ~167 ~127 ~170 dirt
setblock ~167 ~127 ~171 dirt
setblock ~167 ~127 ~172 grass_block
setblock ~167 ~127 ~173 grass_block
setblock ~167 ~127 ~174 fern
setblock ~167 ~127 ~187 short_grass
setblock ~167 ~127 ~188 short_grass
setblock ~167 ~127 ~189 grass_block
setblock ~167 ~127 ~190 grass_block
setblock ~167 ~127 ~191 grass_block
setblock ~167 ~127 ~192 grass_block
setblock ~167 ~127 ~193 grass_block
setblock ~167 ~127 ~194 dirt
setblock ~167 ~127 ~195 dirt
setblock ~167 ~127 ~196 dirt
setblock ~167 ~127 ~197 dirt
setblock ~167 ~127 ~198 dirt
setblock ~167 ~127 ~199 dirt
setblock ~167 ~128 ~168 short_grass
setblock ~167 ~128 ~169 grass_block
setblock ~167 ~128 ~170 grass_block
setblock ~167 ~128 ~171 grass_block
setblock ~167 ~128 ~172 poppy
setblock ~167 ~128 ~173 short_grass
setblock ~167 ~128 ~189 short_grass
setblock ~167 ~128 ~194 grass_block
setblock ~167 ~128 ~195 grass_block
setblock ~167 ~128 ~196 grass_block
setblock ~167 ~128 ~197 grass_block
setblock ~167 ~128 ~198 dirt
setblock ~167 ~128 ~199 dirt
setblock ~167 ~129 ~169 poppy
setblock ~167 ~129 ~197 short_grass
setblock ~167 ~129 ~198 grass_block
setblock ~167 ~129 ~199 grass_block
setblock ~167 ~130 ~198 short_grass
setblock ~168 ~122 ~0 dirt
setblock ~168 ~122 ~1 dirt
setblock ~168 ~122 ~2 dirt
setblock ~168 ~122 ~3 dirt
setblock ~168 ~122 ~4 dirt
setblock ~168 ~122 ~5 dirt
setblock ~168 ~122 ~6 dirt
setblock ~168 ~122 ~7 dirt
setblock ~168 ~122 ~8 dirt
setblock ~168 ~122 ~9 dirt
setblock ~168 ~122 ~10 dirt
setblock ~168 ~122 ~11 dirt
setblock ~168 ~122 ~12 dirt
setblock ~168 ~122 ~13 dirt
setblock ~168 ~122 ~14 dirt
setblock ~168 ~122 ~15 dirt
setblock ~168 ~122 ~16 dirt
setblock ~168 ~122 ~17 dirt
setblock ~168 ~122 ~18 dirt
setblock ~168 ~122 ~19 dirt
setblock ~168 ~122 ~20 dirt
setblock ~168 ~122 ~21 dirt
setblock ~168 ~122 ~22 dirt
setblock ~168 ~122 ~23 dirt
setblock ~168 ~122 ~24 dirt
setblock ~168 ~122 ~25 dirt
setblock ~168 ~122 ~26 dirt
setblock ~168 ~122 ~27 dirt
setblock ~168 ~122 ~28 dirt
setblock ~168 ~122 ~29 dirt
setblock ~168 ~122 ~30 dirt
setblock ~168 ~122 ~31 dirt
setblock ~168 ~122 ~32 dirt
setblock ~168 ~122 ~33 dirt
setblock ~168 ~122 ~34 dirt
setblock ~168 ~122 ~35 dirt
setblock ~168 ~122 ~36 dirt
setblock ~168 ~122 ~37 dirt
setblock ~168 ~122 ~38 dirt
setblock ~168 ~122 ~39 dirt
setblock ~168 ~122 ~40 dirt
setblock ~168 ~122 ~41 dirt
setblock ~168 ~122 ~42 dirt
setblock ~168 ~122 ~43 dirt
setblock ~168 ~122 ~44 dirt
setblock ~168 ~122 ~45 dirt
setblock ~168 ~122 ~46 dirt
setblock ~168 ~122 ~47 dirt
setblock ~168 ~122 ~48 dirt
setblock ~168 ~122 ~49 dirt
setblock ~168 ~122 ~50 dirt
setblock ~168 ~122 ~51 dirt
setblock ~168 ~122 ~52 dirt
setblock ~168 ~122 ~53 dirt
setblock ~168 ~122 ~54 dirt
setblock ~168 ~122 ~55 dirt
setblock ~168 ~122 ~56 grass_block
setblock ~168 ~122 ~57 grass_block
setblock ~168 ~122 ~58 grass_block
setblock ~168 ~122 ~59 grass_block
setblock ~168 ~122 ~60 grass_block
setblock ~168 ~122 ~61 dirt
setblock ~168 ~122 ~62 dirt
setblock ~168 ~122 ~63 dirt
setblock ~168 ~122 ~64 dirt
setblock ~168 ~122 ~65 dirt
setblock ~168 ~122 ~66 dirt
setblock ~168 ~122 ~67 dirt
setblock ~168 ~122 ~68 dirt
setblock ~168 ~122 ~69 dirt
setblock ~168 ~122 ~70 dirt
setblock ~168 ~122 ~71 dirt
setblock ~168 ~122 ~72 dirt
setblock ~168 ~122 ~73 dirt
setblock ~168 ~122 ~74 dirt
setblock ~168 ~122 ~75 dirt
setblock ~168 ~122 ~76 dirt
setblock ~168 ~122 ~77 dirt
setblock ~168 ~122 ~78 dirt
setblock ~168 ~122 ~79 dirt
setblock ~168 ~122 ~80 dirt
setblock ~168 ~122 ~81 dirt
setblock ~168 ~122 ~82 dirt
setblock ~168 ~122 ~83 dirt
setblock ~168 ~122 ~84 dirt
setblock ~168 ~122 ~85 dirt
setblock ~168 ~122 ~86 dirt
setblock ~168 ~122 ~87 dirt
setblock ~168 ~122 ~88 dirt
setblock ~168 ~122 ~89 dirt
setblock ~168 ~122 ~90 dirt
setblock ~168 ~122 ~91 dirt
setblock ~168 ~122 ~92 dirt
setblock ~168 ~122 ~93 dirt
setblock ~168 ~122 ~94 dirt
setblock ~168 ~122 ~95 dirt
setblock ~168 ~122 ~96 dirt
setblock ~168 ~122 ~97 dirt
setblock ~168 ~122 ~98 dirt
setblock ~168 ~122 ~99 dirt
setblock ~168 ~122 ~100 dirt
setblock ~168 ~122 ~101 dirt
setblock ~168 ~122 ~102 dirt
setblock ~168 ~122 ~103 dirt
setblock ~168 ~122 ~104 dirt
setblock ~168 ~122 ~105 dirt
setblock ~168 ~122 ~106 dirt
setblock ~168 ~122 ~107 dirt
setblock ~168 ~122 ~108 dirt
setblock ~168 ~122 ~109 dirt
setblock ~168 ~122 ~110 dirt
setblock ~168 ~122 ~111 dirt
setblock ~168 ~122 ~112 dirt
