setblock ~167 ~110 ~106 dirt
setblock ~167 ~110 ~107 dirt
setblock ~167 ~111 ~89 dirt
setblock ~167 ~111 ~90 dirt
setblock ~167 ~111 ~91 dirt
setblock ~167 ~111 ~92 dirt
setblock ~167 ~111 ~93 dirt
setblock ~167 ~111 ~94 dirt
setblock ~167 ~111 ~95 dirt
setblock ~167 ~111 ~96 dirt
setblock ~167 ~111 ~97 dirt
setblock ~167 ~111 ~98 dirt
setblock ~167 ~111 ~99 dirt
setblock ~167 ~111 ~100 dirt
setblock ~167 ~111 ~101 dirt
setblock ~167 ~111 ~102 dirt
setblock ~167 ~111 ~103 dirt
setblock ~167 ~111 ~104 dirt
setblock ~167 ~111 ~105 dirt
setblock ~167 ~111 ~106 dirt
setblock ~167 ~111 ~107 dirt
setblock ~167 ~112 ~82 dirt
setblock ~167 ~112 ~83 dirt
setblock ~167 ~112 ~87 dirt
setblock ~167 ~112 ~89 dirt
setblock ~167 ~112 ~90 dirt
setblock ~167 ~112 ~91 dirt
setblock ~167 ~112 ~92 dirt
setblock ~167 ~112 ~93 dirt
setblock ~167 ~112 ~94 dirt
setblock ~167 ~112 ~95 dirt
setblock ~167 ~112 ~96 dirt
setblock ~167 ~112 ~97 dirt
setblock ~167 ~112 ~98 dirt
setblock ~167 ~112 ~99 dirt
setblock ~167 ~112 ~100 dirt
setblock ~167 ~112 ~101 dirt
setblock ~167 ~112 ~102 dirt
setblock ~167 ~112 ~103 dirt
setblock ~167 ~112 ~104 dirt
setblock ~167 ~112 ~105 dirt
setblock ~167 ~112 ~106 dirt
setblock ~167 ~112 ~107 dirt
setblock ~167 ~112 ~108 dirt
setblock ~167 ~113 ~80 dirt
setblock ~167 ~113 ~81 dirt
setblock ~167 ~113 ~82 dirt
setblock ~167 ~113 ~83 dirt
setblock ~167 ~113 ~84 dirt
setblock ~167 ~113 ~85 dirt
setblock ~167 ~113 ~87 dirt
setblock ~167 ~113 ~88 dirt
setblock ~167 ~113 ~89 dirt
setblock ~167 ~113 ~90 dirt
setblock ~167 ~113 ~91 dirt
setblock ~167 ~113 ~92 dirt
setblock ~167 ~113 ~93 dirt
setblock ~167 ~113 ~94 dirt
setblock ~167 ~113 ~95 dirt
setblock ~167 ~113 ~96 dirt
setblock ~167 ~113 ~97 dirt
setblock ~167 ~113 ~98 dirt
setblock ~167 ~113 ~99 dirt
setblock ~167 ~113 ~100 dirt
setblock ~167 ~113 ~101 dirt
setblock ~167 ~113 ~102 dirt
setblock ~167 ~113 ~103 dirt
setblock ~167 ~113 ~104 dirt
setblock ~167 ~113 ~105 dirt
setblock ~167 ~113 ~106 dirt
setblock ~167 ~113 ~107 dirt
setblock ~167 ~113 ~108 dirt
setblock ~167 ~114 ~80 dirt
setblock ~167 ~114 ~81 dirt
setblock ~167 ~114 ~82 dirt
setblock ~167 ~114 ~83 dirt
setblock ~167 ~114 ~84 dirt
setblock ~167 ~114 ~85 dirt
setblock ~167 ~114 ~86 dirt
setblock ~167 ~114 ~87 dirt
setblock ~167 ~114 ~88 dirt
setblock ~167 ~114 ~89 dirt
setblock ~167 ~114 ~90 dirt
setblock ~167 ~114 ~91 dirt
setblock ~167 ~114 ~92 dirt
setblock ~167 ~114 ~93 dirt
setblock ~167 ~114 ~94 dirt
setblock ~167 ~114 ~95 dirt
setblock ~167 ~114 ~96 dirt
setblock ~167 ~114 ~97 dirt
setblock ~167 ~114 ~98 dirt
setblock ~167 ~114 ~99 dirt
setblock ~167 ~114 ~100 dirt
setblock ~167 ~114 ~101 dirt
setblock ~167 ~114 ~102 dirt
setblock ~167 ~114 ~103 dirt
setblock ~167 ~114 ~104 dirt
setblock ~167 ~114 ~105 dirt
setblock ~167 ~114 ~106 dirt
setblock ~167 ~114 ~107 dirt
setblock ~167 ~114 ~108 dirt
setblock ~167 ~115 ~78 dirt
setblock ~167 ~115 ~79 dirt
setblock ~167 ~115 ~80 dirt
setblock ~167 ~115 ~81 dirt
setblock ~167 ~115 ~82 dirt
setblock ~167 ~115 ~83 dirt
setblock ~167 ~115 ~84 dirt
setblock ~167 ~115 ~85 dirt
setblock ~167 ~115 ~86 dirt
setblock ~167 ~115 ~87 dirt
setblock ~167 ~115 ~88 dirt
setblock ~167 ~115 ~89 dirt
setblock ~167 ~115 ~90 dirt
setblock ~167 ~115 ~91 dirt
setblock ~167 ~115 ~92 dirt
setblock ~167 ~115 ~93 dirt
setblock ~167 ~115 ~94 dirt
setblock ~167 ~115 ~95 dirt
setblock ~167 ~115 ~96 dirt
setblock ~167 ~115 ~97 dirt
setblock ~167 ~115 ~98 dirt
setblock ~167 ~115 ~99 dirt
setblock ~167 ~115 ~100 dirt
setblock ~167 ~115 ~101 dirt
setblock ~167 ~115 ~102 dirt
setblock ~167 ~115 ~103 dirt
setblock ~167 ~115 ~104 dirt
setblock ~167 ~115 ~105 dirt
setblock ~167 ~115 ~106 dirt
setblock ~167 ~115 ~107 dirt
setblock ~167 ~115 ~108 dirt
setblock ~167 ~116 ~74 dirt
setblock ~167 ~116 ~77 dirt
setblock ~167 ~116 ~78 dirt
setblock ~167 ~116 ~79 dirt
setblock ~167 ~116 ~80 dirt
setblock ~167 ~116 ~81 dirt
setblock ~167 ~116 ~82 dirt
setblock ~167 ~116 ~83 dirt
setblock ~167 ~116 ~84 dirt
setblock ~167 ~116 ~85 dirt
setblock ~167 ~116 ~86 dirt
setblock ~167 ~116 ~87 dirt
setblock ~167 ~116 ~88 dirt
setblock ~167 ~116 ~89 dirt
setblock ~167 ~116 ~90 dirt
setblock ~167 ~116 ~91 dirt
setblock ~167 ~116 ~92 dirt
setblock ~167 ~116 ~93 dirt
setblock ~167 ~116 ~94 dirt
setblock ~167 ~116 ~95 dirt
setblock ~167 ~116 ~96 dirt
setblock ~167 ~116 ~97 dirt
setblock ~167 ~116 ~98 dirt
setblock ~167 ~116 ~99 dirt
setblock ~167 ~116 ~100 dirt
setblock ~167 ~116 ~101 dirt
setblock ~167 ~116 ~102 dirt
setblock ~167 ~116 ~103 dirt
setblock ~167 ~116 ~104 dirt
setblock ~167 ~116 ~105 dirt
setblock ~167 ~116 ~106 dirt
setblock ~167 ~116 ~107 dirt
setblock ~167 ~116 ~108 dirt
setblock ~167 ~116 ~109 dirt
setblock ~167 ~117 ~73 dirt
setblock ~167 ~117 ~74 dirt
setblock ~167 ~117 ~75 dirt
setblock ~167 ~117 ~76 dirt
setblock ~167 ~117 ~77 dirt
setblock ~167 ~117 ~78 dirt
setblock ~167 ~117 ~79 dirt
setblock ~167 ~117 ~80 dirt
setblock ~167 ~117 ~81 dirt
setblock ~167 ~117 ~82 dirt
setblock ~167 ~117 ~83 dirt
setblock ~167 ~117 ~84 dirt
setblock ~167 ~117 ~85 dirt
setblock ~167 ~117 ~86 dirt
setblock ~167 ~117 ~87 dirt
setblock ~167 ~117 ~88 dirt
setblock ~167 ~117 ~89 dirt
setblock ~167 ~117 ~90 dirt
setblock ~167 ~117 ~91 dirt
setblock ~167 ~117 ~92 dirt
setblock ~167 ~117 ~93 dirt
setblock ~167 ~117 ~94 dirt
setblock ~167 ~117 ~95 dirt
setblock ~167 ~117 ~96 dirt
setblock ~167 ~117 ~97 dirt
setblock ~167 ~117 ~98 dirt
setblock ~167 ~117 ~99 dirt
setblock ~167 ~117 ~100 dirt
setblock ~167 ~117 ~101 dirt
setblock ~167 ~117 ~102 dirt
setblock ~167 ~117 ~103 dirt
setblock ~167 ~117 ~104 dirt
setblock ~167 ~117 ~105 dirt
setblock ~167 ~117 ~106 dirt
setblock ~167 ~117 ~107 dirt
setblock ~167 ~117 ~108 dirt
setblock ~167 ~117 ~109 dirt
setblock ~167 ~117 ~110 dirt
setblock ~167 ~118 ~72 dirt
setblock ~167 ~118 ~73 dirt
setblock ~167 ~118 ~74 dirt
setblock ~167 ~118 ~75 dirt
setblock ~167 ~118 ~76 dirt
setblock ~167 ~118 ~77 dirt
setblock ~167 ~118 ~78 dirt
setblock ~167 ~118 ~79 dirt
setblock ~167 ~118 ~80 dirt
setblock ~167 ~118 ~81 dirt
setblock ~167 ~118 ~82 dirt
setblock ~167 ~118 ~83 dirt
setblock ~167 ~118 ~84 dirt
setblock ~167 ~118 ~85 dirt
setblock ~167 ~118 ~86 dirt
setblock ~167 ~118 ~87 dirt
setblock ~167 ~118 ~88 dirt
setblock ~167 ~118 ~89 dirt
setblock ~167 ~118 ~90 dirt
setblock ~167 ~118 ~91 dirt
setblock ~167 ~118 ~92 dirt
setblock ~167 ~118 ~93 dirt
setblock ~167 ~118 ~94 dirt
setblock ~167 ~118 ~95 dirt
setblock ~167 ~118 ~96 dirt
setblock ~167 ~118 ~97 dirt
setblock ~167 ~118 ~98 dirt
setblock ~167 ~118 ~99 dirt
setblock ~167 ~118 ~100 dirt
setblock ~167 ~118 ~101 dirt
setblock ~167 ~118 ~102 dirt
setblock ~167 ~118 ~103 dirt
setblock ~167 ~118 ~104 dirt
setblock ~167 ~118 ~105 dirt
setblock ~167 ~118 ~106 dirt
setblock ~167 ~118 ~107 dirt
setblock ~167 ~118 ~108 dirt
setblock ~167 ~118 ~109 dirt
setblock ~167 ~118 ~110 dirt
setblock ~167 ~119 ~70 dirt
setblock ~167 ~119 ~71 dirt
setblock ~167 ~119 ~72 dirt
setblock ~167 ~119 ~73 dirt
setblock ~167 ~119 ~74 dirt
setblock ~167 ~119 ~75 dirt
setblock ~167 ~119 ~76 dirt
setblock ~167 ~119 ~77 dirt
setblock ~167 ~119 ~78 dirt
setblock ~167 ~119 ~79 dirt
setblock ~167 ~119 ~80 dirt
setblock ~167 ~119 ~81 dirt
setblock ~167 ~119 ~82 dirt
setblock ~167 ~119 ~83 dirt
setblock ~167 ~119 ~84 dirt
setblock ~167 ~119 ~85 dirt
setblock ~167 ~119 ~86 dirt
setblock ~167 ~119 ~87 dirt
setblock ~167 ~119 ~88 dirt
setblock ~167 ~119 ~89 dirt
setblock ~167 ~119 ~90 dirt
setblock ~167 ~119 ~91 dirt
setblock ~167 ~119 ~92 dirt
setblock ~167 ~119 ~93 dirt
setblock ~167 ~119 ~94 dirt
setblock ~167 ~119 ~95 dirt
setblock ~167 ~119 ~96 dirt
setblock ~167 ~119 ~97 dirt
setblock ~167 ~119 ~98 dirt
setblock ~167 ~119 ~99 dirt
setblock ~167 ~119 ~100 dirt
setblock ~167 ~119 ~101 dirt
setblock ~167 ~119 ~102 dirt
setblock ~167 ~119 ~103 dirt
setblock ~167 ~119 ~104 dirt
setblock ~167 ~119 ~105 dirt
setblock ~167 ~119 ~106 dirt
setblock ~167 ~119 ~107 dirt
setblock ~167 ~119 ~108 dirt
setblock ~167 ~119 ~109 dirt
setblock ~167 ~119 ~110 dirt
setblock ~167 ~119 ~111 dirt
setblock ~167 ~120 ~70 dirt
setblock ~167 ~120 ~71 dirt
setblock ~167 ~120 ~72 dirt
setblock ~167 ~120 ~73 dirt
setblock ~167 ~120 ~74 dirt
setblock ~167 ~120 ~75 dirt
setblock ~167 ~120 ~76 dirt
setblock ~167 ~120 ~77 dirt
setblock ~167 ~120 ~78 dirt
setblock ~167 ~120 ~79 dirt
setblock ~167 ~120 ~80 dirt
setblock ~167 ~120 ~81 dirt
setblock ~167 ~120 ~82 dirt
setblock ~167 ~120 ~83 dirt
setblock ~167 ~120 ~84 dirt
setblock ~167 ~120 ~85 dirt
setblock ~167 ~120 ~86 dirt
setblock ~167 ~120 ~87 dirt
setblock ~167 ~120 ~88 dirt
setblock ~167 ~120 ~89 dirt
setblock ~167 ~120 ~90 dirt
setblock ~167 ~120 ~91 dirt
setblock ~167 ~120 ~92 dirt
setblock ~167 ~120 ~93 dirt
setblock ~167 ~120 ~94 dirt
setblock ~167 ~120 ~95 dirt
setblock ~167 ~120 ~96 dirt
setblock ~167 ~120 ~97 dirt
setblock ~167 ~120 ~98 dirt
setblock ~167 ~120 ~99 dirt
setblock ~167 ~120 ~100 dirt
setblock ~167 ~120 ~101 dirt
setblock ~167 ~120 ~102 dirt
setblock ~167 ~120 ~103 dirt
setblock ~167 ~120 ~104 dirt
setblock ~167 ~120 ~105 dirt
setblock ~167 ~120 ~106 dirt
setblock ~167 ~120 ~107 dirt
setblock ~167 ~120 ~108 dirt
setblock ~167 ~120 ~109 dirt
setblock ~167 ~120 ~110 dirt
setblock ~167 ~120 ~111 dirt
setblock ~167 ~120 ~112 dirt
setblock ~167 ~121 ~68 dirt
setblock ~167 ~121 ~69 dirt
setblock ~167 ~121 ~70 dirt
setblock ~167 ~121 ~71 dirt
setblock ~167 ~121 ~72 dirt
setblock ~167 ~121 ~73 dirt
setblock ~167 ~121 ~74 dirt
setblock ~167 ~121 ~75 dirt
setblock ~167 ~121 ~76 dirt
setblock ~167 ~121 ~77 dirt
setblock ~167 ~121 ~78 dirt
setblock ~167 ~121 ~79 dirt
setblock ~167 ~121 ~80 dirt
setblock ~167 ~121 ~81 dirt
setblock ~167 ~121 ~82 dirt
setblock ~167 ~121 ~83 dirt
setblock ~167 ~121 ~84 dirt
setblock ~167 ~121 ~85 dirt
setblock ~167 ~121 ~86 dirt
setblock ~167 ~121 ~87 dirt
setblock ~167 ~121 ~88 dirt
setblock ~167 ~121 ~89 dirt
setblock ~167 ~121 ~90 dirt
setblock ~167 ~121 ~91 dirt
setblock ~167 ~121 ~92 dirt
setblock ~167 ~121 ~93 dirt
setblock ~167 ~121 ~94 dirt
setblock ~167 ~121 ~95 dirt
setblock ~167 ~121 ~96 dirt
setblock ~167 ~121 ~97 dirt
setblock ~167 ~121 ~98 dirt
setblock ~167 ~121 ~99 dirt
setblock ~167 ~121 ~100 dirt
setblock ~167 ~121 ~101 dirt
setblock ~167 ~121 ~102 dirt
setblock ~167 ~121 ~103 dirt
setblock ~167 ~121 ~104 dirt
setblock ~167 ~121 ~105 dirt
setblock ~167 ~121 ~106 dirt
setblock ~167 ~121 ~107 dirt
setblock ~167 ~121 ~108 dirt
setblock ~167 ~121 ~109 dirt
setblock ~167 ~121 ~110 dirt
setblock ~167 ~121 ~111 dirt
setblock ~167 ~121 ~112 dirt
setblock ~167 ~121 ~113 dirt
setblock ~167 ~121 ~114 dirt
setblock ~167 ~121 ~118 dirt
setblock ~167 ~122 ~68 dirt
setblock ~167 ~122 ~69 dirt
setblock ~167 ~122 ~70 dirt
setblock ~167 ~122 ~71 dirt
setblock ~167 ~122 ~72 dirt
setblock ~167 ~122 ~73 dirt
setblock ~167 ~122 ~74 dirt
setblock ~167 ~122 ~75 dirt
setblock ~167 ~122 ~76 dirt
setblock ~167 ~122 ~77 dirt
setblock ~167 ~122 ~78 dirt
setblock ~167 ~122 ~79 dirt
setblock ~167 ~122 ~80 dirt
setblock ~167 ~122 ~81 dirt
setblock ~167 ~122 ~82 dirt
setblock ~167 ~122 ~83 dirt
setblock ~167 ~122 ~84 dirt
setblock ~167 ~122 ~85 dirt
setblock ~167 ~122 ~86 dirt
setblock ~167 ~122 ~87 dirt
setblock ~167 ~122 ~88 dirt
setblock ~167 ~122 ~89 dirt
setblock ~167 ~122 ~90 dirt
setblock ~167 ~122 ~91 dirt
setblock ~167 ~122 ~92 dirt
setblock ~167 ~122 ~93 dirt
setblock ~167 ~122 ~94 dirt
setblock ~167 ~122 ~95 dirt
setblock ~167 ~122 ~96 dirt
setblock ~167 ~122 ~97 dirt
setblock ~167 ~122 ~98 dirt
setblock ~167 ~122 ~99 dirt
setblock ~167 ~122 ~100 dirt
setblock ~167 ~122 ~101 dirt
setblock ~167 ~122 ~102 dirt
setblock ~167 ~122 ~103 dirt
setblock ~167 ~122 ~104 dirt
setblock ~167 ~122 ~105 dirt
setblock ~167 ~122 ~106 dirt
setblock ~167 ~122 ~107 dirt
setblock ~167 ~122 ~108 dirt
setblock ~167 ~122 ~109 dirt
setblock ~167 ~122 ~110 dirt
setblock ~167 ~122 ~111 dirt
setblock ~167 ~122 ~112 dirt
setblock ~167 ~122 ~113 dirt
setblock ~167 ~122 ~114 dirt
setblock ~167 ~122 ~118 dirt
setblock ~167 ~123 ~68 dirt
setblock ~167 ~123 ~69 dirt
setblock ~167 ~123 ~70 dirt
setblock ~167 ~123 ~71 dirt
setblock ~167 ~123 ~72 dirt
setblock ~167 ~123 ~73 dirt
setblock ~167 ~123 ~74 dirt
setblock ~167 ~123 ~75 dirt
setblock ~167 ~123 ~76 dirt
setblock ~167 ~123 ~77 dirt
setblock ~167 ~123 ~78 dirt
setblock ~167 ~123 ~79 dirt
setblock ~167 ~123 ~80 dirt
setblock ~167 ~123 ~81 dirt
setblock ~167 ~123 ~82 dirt
setblock ~167 ~123 ~83 dirt
setblock ~167 ~123 ~84 dirt
setblock ~167 ~123 ~85 dirt
setblock ~167 ~123 ~86 dirt
setblock ~167 ~123 ~87 grass_block
setblock ~167 ~123 ~88 grass_block
setblock ~167 ~123 ~89 grass_block
setblock ~167 ~123 ~90 grass_block
setblock ~167 ~123 ~91 grass_block
setblock ~167 ~123 ~92 grass_block
setblock ~167 ~123 ~93 grass_block
setblock ~167 ~123 ~94 grass_block
setblock ~167 ~123 ~95 dirt
setblock ~167 ~123 ~96 dirt
setblock ~167 ~123 ~97 dirt
setblock ~167 ~123 ~98 dirt
setblock ~167 ~123 ~99 dirt
setblock ~167 ~123 ~100 dirt
setblock ~167 ~123 ~101 dirt
setblock ~167 ~123 ~102 dirt
setblock ~167 ~123 ~103 dirt
setblock ~167 ~123 ~104 dirt
setblock ~167 ~123 ~105 dirt
setblock ~167 ~123 ~106 dirt
setblock ~167 ~123 ~107 dirt
setblock ~167 ~123 ~108 dirt
setblock ~167 ~123 ~109 dirt
setblock ~167 ~123 ~110 dirt
setblock ~167 ~123 ~111 dirt
setblock ~167 ~123 ~112 dirt
setblock ~167 ~123 ~113 dirt
setblock ~167 ~123 ~114 dirt
setblock ~167 ~123 ~118 dirt
setblock ~167 ~124 ~68 dirt
setblock ~167 ~124 ~69 dirt
setblock ~167 ~124 ~70 dirt
setblock ~167 ~124 ~71 dirt
setblock ~167 ~124 ~72 dirt
setblock ~167 ~124 ~73 dirt
setblock ~167 ~124 ~74 dirt
setblock ~167 ~124 ~75 dirt
setblock ~167 ~124 ~76 dirt
setblock ~167 ~124 ~77 dirt
setblock ~167 ~124 ~78 dirt
setblock ~167 ~124 ~79 dirt
setblock ~167 ~124 ~80 dirt
setblock ~167 ~124 ~81 dirt
setblock ~167 ~124 ~82 dirt
setblock ~167 ~124 ~83 grass_block
setblock ~167 ~124 ~84 grass_block
setblock ~167 ~124 ~85 grass_block
setblock ~167 ~124 ~86 grass_block
setblock ~167 ~124 ~88 short_grass
setblock ~167 ~124 ~90 short_grass
setblock ~167 ~124 ~91 short_grass
setblock ~167 ~124 ~93 short_grass
setblock ~167 ~124 ~94 fern
setblock ~167 ~124 ~95 grass_block
setblock ~167 ~124 ~96 grass_block
setblock ~167 ~124 ~97 grass_block
setblock ~167 ~124 ~98 dirt
setblock ~167 ~124 ~99 dirt
setblock ~167 ~124 ~100 dirt
setblock ~167 ~124 ~101 dirt
setblock ~167 ~124 ~102 dirt
setblock ~167 ~124 ~103 dirt
setblock ~167 ~124 ~104 dirt
setblock ~167 ~124 ~105 dirt
setblock ~167 ~124 ~106 dirt
setblock ~167 ~124 ~107 dirt
setblock ~167 ~124 ~108 dirt
setblock ~167 ~124 ~109 dirt
setblock ~167 ~124 ~110 dirt
setblock ~167 ~124 ~111 dirt
setblock ~167 ~124 ~112 dirt
setblock ~167 ~124 ~113 dirt
setblock ~167 ~124 ~114 dirt
setblock ~167 ~124 ~118 grass_block
setblock ~167 ~125 ~68 grass_block
setblock ~167 ~125 ~69 grass_block
setblock ~167 ~125 ~70 grass_block
setblock ~167 ~125 ~71 grass_block
setblock ~167 ~125 ~72 grass_block
setblock ~167 ~125 ~73 grass_block
setblock ~167 ~125 ~74 grass_block
setblock ~167 ~125 ~75 grass_block
setblock ~167 ~125 ~76 grass_block
setblock ~167 ~125 ~77 grass_block
setblock ~167 ~125 ~78 grass_block
setblock ~167 ~125 ~79 grass_block
setblock ~167 ~125 ~80 grass_block
setblock ~167 ~125 ~81 grass_block
setblock ~167 ~125 ~82 grass_block
setblock ~167 ~125 ~84 short_grass
setblock ~167 ~125 ~96 short_grass
setblock ~167 ~125 ~98 grass_block
setblock ~167 ~125 ~99 grass_block
setblock ~167 ~125 ~100 grass_block
setblock ~167 ~125 ~101 grass_block
setblock ~167 ~125 ~102 dirt
setblock ~167 ~125 ~103 dirt
setblock ~167 ~125 ~104 dirt
setblock ~167 ~125 ~105 dirt
setblock ~167 ~125 ~106 dirt
setblock ~167 ~125 ~107 dirt
setblock ~167 ~125 ~108 dirt
setblock ~167 ~125 ~109 dirt
setblock ~167 ~125 ~110 dirt
setblock ~167 ~125 ~111 dirt
setblock ~167 ~125 ~112 dirt
setblock ~167 ~125 ~113 grass_block
setblock ~167 ~125 ~114 grass_block
setblock ~167 ~126 ~71 fern
setblock ~167 ~126 ~74 fern
setblock ~167 ~126 ~75 short_grass
setblock ~167 ~126 ~77 short_grass
setblock ~167 ~126 ~78 poppy
setblock ~167 ~126 ~81 fern
setblock ~167 ~126 ~102 grass_block
setblock ~167 ~126 ~103 grass_block
setblock ~167 ~126 ~104 grass_block
setblock ~167 ~126 ~105 grass_block
setblock ~167 ~126 ~106 grass_block
setblock ~167 ~126 ~107 grass_block
setblock ~167 ~126 ~108 grass_block
setblock ~167 ~126 ~109 grass_block
setblock ~167 ~126 ~110 grass_block
setblock ~167 ~126 ~111 grass_block
setblock ~167 ~126 ~112 grass_block
setblock ~167 ~127 ~102 short_grass
setblock ~167 ~127 ~104 fern
setblock ~167 ~127 ~105 short_grass
setblock ~167 ~127 ~110 short_grass
setblock ~167 ~132 ~92 oak_leaves
setblock ~167 ~132 ~93 oak_leaves
setblock ~167 ~132 ~94 oak_leaves
setblock ~167 ~133 ~93 oak_leaves
setblock ~167 ~133 ~94 oak_leaves
setblock ~167 ~134 ~92 oak_leaves
setblock ~167 ~134 ~93 oak_leaves
setblock ~167 ~134 ~94 oak_leaves
setblock ~167 ~134 ~95 oak_leaves
setblock ~167 ~135 ~92 jungle_leaves
setblock ~167 ~135 ~93 oak_leaves
setblock ~167 ~135 ~95 jungle_leaves
setblock ~168 ~102 ~97 dirt
setblock ~168 ~103 ~96 dirt
setblock ~168 ~103 ~97 dirt
setblock ~168 ~104 ~95 dirt
setblock ~168 ~104 ~96 dirt
setblock ~168 ~104 ~97 dirt
setblock ~168 ~105 ~95 dirt
setblock ~168 ~105 ~96 dirt
setblock ~168 ~105 ~97 dirt
setblock ~168 ~105 ~98 dirt
setblock ~168 ~106 ~93 dirt
setblock ~168 ~106 ~94 dirt
setblock ~168 ~106 ~95 dirt
setblock ~168 ~106 ~96 dirt
setblock ~168 ~106 ~97 dirt
setblock ~168 ~106 ~98 dirt
setblock ~168 ~107 ~92 dirt
setblock ~168 ~107 ~93 dirt
setblock ~168 ~107 ~94 dirt
setblock ~168 ~107 ~95 dirt
setblock ~168 ~107 ~96 dirt
setblock ~168 ~107 ~97 dirt
setblock ~168 ~107 ~98 dirt
setblock ~168 ~107 ~99 dirt
setblock ~168 ~108 ~92 dirt
setblock ~168 ~108 ~93 dirt
setblock ~168 ~108 ~94 dirt
setblock ~168 ~108 ~95 dirt
setblock ~168 ~108 ~96 dirt
setblock ~168 ~108 ~97 dirt
setblock ~168 ~108 ~98 dirt
setblock ~168 ~108 ~99 dirt
setblock ~168 ~108 ~102 dirt
setblock ~168 ~109 ~91 dirt
setblock ~168 ~109 ~92 dirt
setblock ~168 ~109 ~93 dirt
setblock ~168 ~109 ~94 dirt
setblock ~168 ~109 ~95 dirt
setblock ~168 ~109 ~96 dirt
setblock ~168 ~109 ~97 dirt
setblock ~168 ~109 ~98 dirt
setblock ~168 ~109 ~99 dirt
setblock ~168 ~109 ~100 dirt
setblock ~168 ~109 ~101 dirt
setblock ~168 ~109 ~102 dirt
setblock ~168 ~109 ~103 dirt
setblock ~168 ~109 ~104 dirt
setblock ~168 ~110 ~90 dirt
setblock ~168 ~110 ~91 dirt
setblock ~168 ~110 ~92 dirt
setblock ~168 ~110 ~93 dirt
setblock ~168 ~110 ~94 dirt
setblock ~168 ~110 ~95 dirt
setblock ~168 ~110 ~96 dirt
setblock ~168 ~110 ~97 dirt
setblock ~168 ~110 ~98 dirt
setblock ~168 ~110 ~99 dirt
setblock ~168 ~110 ~100 dirt
setblock ~168 ~110 ~101 dirt
setblock ~168 ~110 ~102 dirt
setblock ~168 ~110 ~103 dirt
setblock ~168 ~110 ~104 dirt
setblock ~168 ~111 ~89 dirt
setblock ~168 ~111 ~90 dirt
setblock ~168 ~111 ~91 dirt
setblock ~168 ~111 ~92 dirt
setblock ~168 ~111 ~93 dirt
setblock ~168 ~111 ~94 dirt
setblock ~168 ~111 ~95 dirt
setblock ~168 ~111 ~96 dirt
setblock ~168 ~111 ~97 dirt
setblock ~168 ~111 ~98 dirt
setblock ~168 ~111 ~99 dirt
setblock ~168 ~111 ~100 dirt
setblock ~168 ~111 ~101 dirt
setblock ~168 ~111 ~102 dirt
setblock ~168 ~111 ~103 dirt
setblock ~168 ~111 ~104 dirt
setblock ~168 ~111 ~105 dirt
setblock ~168 ~111 ~106 dirt
setblock ~168 ~112 ~89 dirt
setblock ~168 ~112 ~90 dirt
setblock ~168 ~112 ~91 dirt
setblock ~168 ~112 ~92 dirt
setblock ~168 ~112 ~93 dirt
setblock ~168 ~112 ~94 dirt
setblock ~168 ~112 ~95 dirt
setblock ~168 ~112 ~96 dirt
setblock ~168 ~112 ~97 dirt
setblock ~168 ~112 ~98 dirt
setblock ~168 ~112 ~99 dirt
setblock ~168 ~112 ~100 dirt
setblock ~168 ~112 ~101 dirt
setblock ~168 ~112 ~102 dirt
setblock ~168 ~112 ~103 dirt
setblock ~168 ~112 ~104 dirt
setblock ~168 ~112 ~105 dirt
setblock ~168 ~112 ~106 dirt
setblock ~168 ~112 ~107 dirt
setblock ~168 ~113 ~82 dirt
setblock ~168 ~113 ~83 dirt
setblock ~168 ~113 ~88 dirt
setblock ~168 ~113 ~89 dirt
setblock ~168 ~113 ~90 dirt
setblock ~168 ~113 ~91 dirt
setblock ~168 ~113 ~92 dirt
setblock ~168 ~113 ~93 dirt
setblock ~168 ~113 ~94 dirt
setblock ~168 ~113 ~95 dirt
setblock ~168 ~113 ~96 dirt
setblock ~168 ~113 ~97 dirt
setblock ~168 ~113 ~98 dirt
setblock ~168 ~113 ~99 dirt
setblock ~168 ~113 ~100 dirt
setblock ~168 ~113 ~101 dirt
setblock ~168 ~113 ~102 dirt
setblock ~168 ~113 ~103 dirt
setblock ~168 ~113 ~104 dirt
setblock ~168 ~113 ~105 dirt
setblock ~168 ~113 ~106 dirt
setblock ~168 ~113 ~107 dirt
setblock ~168 ~114 ~82 dirt
setblock ~168 ~114 ~83 dirt
setblock ~168 ~114 ~88 dirt
setblock ~168 ~114 ~89 dirt
setblock ~168 ~114 ~90 dirt
setblock ~168 ~114 ~91 dirt
setblock ~168 ~114 ~92 dirt
setblock ~168 ~114 ~93 dirt
setblock ~168 ~114 ~94 dirt
setblock ~168 ~114 ~95 dirt
setblock ~168 ~114 ~96 dirt
setblock ~168 ~114 ~97 dirt
setblock ~168 ~114 ~98 dirt
setblock ~168 ~114 ~99 dirt
setblock ~168 ~114 ~100 dirt
setblock ~168 ~114 ~101 dirt
setblock ~168 ~114 ~102 dirt
setblock ~168 ~114 ~103 dirt
setblock ~168 ~114 ~104 dirt
setblock ~168 ~114 ~105 dirt
setblock ~168 ~114 ~106 dirt
setblock ~168 ~114 ~107 dirt
setblock ~168 ~114 ~108 dirt
setblock ~168 ~115 ~82 dirt
setblock ~168 ~115 ~83 dirt
setblock ~168 ~115 ~84 dirt
setblock ~168 ~115 ~87 dirt
setblock ~168 ~115 ~88 dirt
setblock ~168 ~115 ~89 dirt
setblock ~168 ~115 ~90 dirt
setblock ~168 ~115 ~91 dirt
setblock ~168 ~115 ~92 dirt
setblock ~168 ~115 ~93 dirt
setblock ~168 ~115 ~94 dirt
setblock ~168 ~115 ~95 dirt
setblock ~168 ~115 ~96 dirt
setblock ~168 ~115 ~97 dirt
setblock ~168 ~115 ~98 dirt
setblock ~168 ~115 ~99 dirt
setblock ~168 ~115 ~100 dirt
setblock ~168 ~115 ~101 dirt
setblock ~168 ~115 ~102 dirt
setblock ~168 ~115 ~103 dirt
setblock ~168 ~115 ~104 dirt
setblock ~168 ~115 ~105 dirt
setblock ~168 ~115 ~106 dirt
setblock ~168 ~115 ~107 dirt
setblock ~168 ~115 ~108 dirt
setblock ~168 ~115 ~109 dirt
setblock ~168 ~116 ~79 dirt
setblock ~168 ~116 ~82 dirt
setblock ~168 ~116 ~83 dirt
setblock ~168 ~116 ~84 dirt
setblock ~168 ~116 ~85 dirt
setblock ~168 ~116 ~86 dirt
setblock ~168 ~116 ~87 dirt
setblock ~168 ~116 ~88 dirt
setblock ~168 ~116 ~89 dirt
setblock ~168 ~116 ~90 dirt
setblock ~168 ~116 ~91 dirt
setblock ~168 ~116 ~92 dirt
setblock ~168 ~116 ~93 dirt
setblock ~168 ~116 ~94 dirt
setblock ~168 ~116 ~95 dirt
setblock ~168 ~116 ~96 dirt
setblock ~168 ~116 ~97 dirt
setblock ~168 ~116 ~98 dirt
setblock ~168 ~116 ~99 dirt
setblock ~168 ~116 ~100 dirt
setblock ~168 ~116 ~101 dirt
setblock ~168 ~116 ~102 dirt
setblock ~168 ~116 ~103 dirt
setblock ~168 ~116 ~104 dirt
setblock ~168 ~116 ~105 dirt
setblock ~168 ~116 ~106 dirt
setblock ~168 ~116 ~107 dirt
setblock ~168 ~116 ~108 dirt
setblock ~168 ~116 ~109 dirt
setblock ~168 ~116 ~110 dirt
setblock ~168 ~117 ~74 dirt
setblock ~168 ~117 ~77 dirt
setblock ~168 ~117 ~79 dirt
setblock ~168 ~117 ~80 dirt
setblock ~168 ~117 ~81 dirt
setblock ~168 ~117 ~82 dirt
setblock ~168 ~117 ~83 dirt
setblock ~168 ~117 ~84 dirt
setblock ~168 ~117 ~85 dirt
setblock ~168 ~117 ~86 dirt
setblock ~168 ~117 ~87 dirt
setblock ~168 ~117 ~88 dirt
setblock ~168 ~117 ~89 dirt
setblock ~168 ~117 ~90 dirt
setblock ~168 ~117 ~91 dirt
setblock ~168 ~117 ~92 dirt
setblock ~168 ~117 ~93 dirt
setblock ~168 ~117 ~94 dirt
setblock ~168 ~117 ~95 dirt
setblock ~168 ~117 ~96 dirt
setblock ~168 ~117 ~97 dirt
setblock ~168 ~117 ~98 dirt
setblock ~168 ~117 ~99 dirt
setblock ~168 ~117 ~100 dirt
setblock ~168 ~117 ~101 dirt
setblock ~168 ~117 ~102 dirt
setblock ~168 ~117 ~103 dirt
setblock ~168 ~117 ~104 dirt
setblock ~168 ~117 ~105 dirt
setblock ~168 ~117 ~106 dirt
setblock ~168 ~117 ~107 dirt
setblock ~168 ~117 ~108 dirt
setblock ~168 ~117 ~109 dirt
setblock ~168 ~117 ~110 dirt
setblock ~168 ~118 ~73 dirt
setblock ~168 ~118 ~74 dirt
setblock ~168 ~118 ~75 dirt
setblock ~168 ~118 ~76 dirt
setblock ~168 ~118 ~77 dirt
setblock ~168 ~118 ~78 dirt
setblock ~168 ~118 ~79 dirt
setblock ~168 ~118 ~80 dirt
setblock ~168 ~118 ~81 dirt
setblock ~168 ~118 ~82 dirt
setblock ~168 ~118 ~83 dirt
setblock ~168 ~118 ~84 dirt
setblock ~168 ~118 ~85 dirt
setblock ~168 ~118 ~86 dirt
setblock ~168 ~118 ~87 dirt
setblock ~168 ~118 ~88 dirt
setblock ~168 ~118 ~89 dirt
setblock ~168 ~118 ~90 dirt
setblock ~168 ~118 ~91 dirt
setblock ~168 ~118 ~92 dirt
setblock ~168 ~118 ~93 dirt
setblock ~168 ~118 ~94 dirt
setblock ~168 ~118 ~95 dirt
setblock ~168 ~118 ~96 dirt
setblock ~168 ~118 ~97 dirt
setblock ~168 ~118 ~98 dirt
setblock ~168 ~118 ~99 dirt
setblock ~168 ~118 ~100 dirt
setblock ~168 ~118 ~101 dirt
setblock ~168 ~118 ~102 dirt
setblock ~168 ~118 ~103 dirt
setblock ~168 ~118 ~104 dirt
setblock ~168 ~118 ~105 dirt
setblock ~168 ~118 ~106 dirt
setblock ~168 ~118 ~107 dirt
setblock ~168 ~118 ~108 dirt
setblock ~168 ~118 ~109 dirt
setblock ~168 ~118 ~110 dirt
setblock ~168 ~119 ~72 dirt
setblock ~168 ~119 ~73 dirt
setblock ~168 ~119 ~74 dirt
setblock ~168 ~119 ~75 dirt
setblock ~168 ~119 ~76 dirt
setblock ~168 ~119 ~77 dirt
setblock ~168 ~119 ~78 dirt
setblock ~168 ~119 ~79 dirt
setblock ~168 ~119 ~80 dirt
setblock ~168 ~119 ~81 dirt
setblock ~168 ~119 ~82 dirt
setblock ~168 ~119 ~83 dirt
setblock ~168 ~119 ~84 dirt
setblock ~168 ~119 ~85 dirt
setblock ~168 ~119 ~86 dirt
setblock ~168 ~119 ~87 dirt
setblock ~168 ~119 ~88 dirt
setblock ~168 ~119 ~89 dirt
setblock ~168 ~119 ~90 dirt
setblock ~168 ~119 ~91 dirt
setblock ~168 ~119 ~92 dirt
setblock ~168 ~119 ~93 dirt
setblock ~168 ~119 ~94 dirt
setblock ~168 ~119 ~95 dirt
setblock ~168 ~119 ~96 dirt
setblock ~168 ~119 ~97 dirt
setblock ~168 ~119 ~98 dirt
setblock ~168 ~119 ~99 dirt
setblock ~168 ~119 ~100 dirt
setblock ~168 ~119 ~101 dirt
setblock ~168 ~119 ~102 dirt
setblock ~168 ~119 ~103 dirt
setblock ~168 ~119 ~104 dirt
setblock ~168 ~119 ~105 dirt
setblock ~168 ~119 ~106 dirt
setblock ~168 ~119 ~107 dirt
setblock ~168 ~119 ~108 dirt
setblock ~168 ~119 ~109 dirt
setblock ~168 ~119 ~110 dirt
setblock ~168 ~119 ~111 dirt
setblock ~168 ~120 ~72 dirt
setblock ~168 ~120 ~73 dirt
setblock ~168 ~120 ~74 dirt
setblock ~168 ~120 ~75 dirt
setblock ~168 ~120 ~76 dirt
setblock ~168 ~120 ~77 dirt
setblock ~168 ~120 ~78 dirt
setblock ~168 ~120 ~79 dirt
setblock ~168 ~120 ~80 dirt
setblock ~168 ~120 ~81 dirt
setblock ~168 ~120 ~82 dirt
setblock ~168 ~120 ~83 dirt
setblock ~168 ~120 ~84 dirt
setblock ~168 ~120 ~85 dirt
setblock ~168 ~120 ~86 dirt
setblock ~168 ~120 ~87 dirt
setblock ~168 ~120 ~88 dirt
setblock ~168 ~120 ~89 dirt
setblock ~168 ~120 ~90 dirt
setblock ~168 ~120 ~91 dirt
setblock ~168 ~120 ~92 dirt
setblock ~168 ~120 ~93 dirt
setblock ~168 ~120 ~94 dirt
setblock ~168 ~120 ~95 dirt
setblock ~168 ~120 ~96 dirt
setblock ~168 ~120 ~97 dirt
setblock ~168 ~120 ~98 dirt
setblock ~168 ~120 ~99 dirt
setblock ~168 ~120 ~100 dirt
setblock ~168 ~120 ~101 dirt
setblock ~168 ~120 ~102 dirt
setblock ~168 ~120 ~103 dirt
setblock ~168 ~120 ~104 dirt
setblock ~168 ~120 ~105 dirt
setblock ~168 ~120 ~106 dirt
setblock ~168 ~120 ~107 dirt
setblock ~168 ~120 ~108 dirt
setblock ~168 ~120 ~109 dirt
setblock ~168 ~120 ~110 dirt
setblock ~168 ~120 ~111 dirt
setblock ~168 ~121 ~72 dirt
setblock ~168 ~121 ~73 dirt
setblock ~168 ~121 ~74 dirt
setblock ~168 ~121 ~75 dirt
setblock ~168 ~121 ~76 dirt
setblock ~168 ~121 ~77 dirt
setblock ~168 ~121 ~78 dirt
setblock ~168 ~121 ~79 dirt
setblock ~168 ~121 ~80 dirt
setblock ~168 ~121 ~81 dirt
setblock ~168 ~121 ~82 dirt
setblock ~168 ~121 ~83 dirt
setblock ~168 ~121 ~84 dirt
setblock ~168 ~121 ~85 dirt
setblock ~168 ~121 ~86 dirt
setblock ~168 ~121 ~87 dirt
setblock ~168 ~121 ~88 dirt
setblock ~168 ~121 ~89 dirt
setblock ~168 ~121 ~90 dirt
setblock ~168 ~121 ~91 dirt
setblock ~168 ~121 ~92 dirt
setblock ~168 ~121 ~93 dirt
setblock ~168 ~121 ~94 dirt
setblock ~168 ~121 ~95 dirt
setblock ~168 ~121 ~96 dirt
setblock ~168 ~121 ~97 dirt
setblock ~168 ~121 ~98 dirt
setblock ~168 ~121 ~99 dirt
setblock ~168 ~121 ~100 dirt
setblock ~168 ~121 ~101 dirt
setblock ~168 ~121 ~102 dirt
setblock ~168 ~121 ~103 dirt
setblock ~168 ~121 ~104 dirt
setblock ~168 ~121 ~105 dirt
setblock ~168 ~121 ~106 dirt
setblock ~168 ~121 ~107 dirt
setblock ~168 ~121 ~108 dirt
setblock ~168 ~121 ~109 dirt
setblock ~168 ~121 ~110 dirt
setblock ~168 ~121 ~111 dirt
setblock ~168 ~121 ~112 dirt
setblock ~168 ~122 ~72 dirt
setblock ~168 ~122 ~73 dirt
setblock ~168 ~122 ~74 dirt
setblock ~168 ~122 ~75 dirt
setblock ~168 ~122 ~76 dirt
setblock ~168 ~122 ~77 dirt
setblock ~168 ~122 ~78 dirt
setblock ~168 ~122 ~79 dirt
setblock ~168 ~122 ~80 dirt
setblock ~168 ~122 ~81 dirt
setblock ~168 ~122 ~82 dirt
setblock ~168 ~122 ~83 dirt
setblock ~168 ~122 ~84 dirt
setblock ~168 ~122 ~85 dirt
setblock ~168 ~122 ~86 dirt
setblock ~168 ~122 ~87 dirt
setblock ~168 ~122 ~88 dirt
setblock ~168 ~122 ~89 dirt
setblock ~168 ~122 ~90 grass_block
setblock ~168 ~122 ~91 dirt
setblock ~168 ~122 ~92 dirt
setblock ~168 ~122 ~93 dirt
setblock ~168 ~122 ~94 dirt
setblock ~168 ~122 ~95 dirt
setblock ~168 ~122 ~96 dirt
setblock ~168 ~122 ~97 dirt
setblock ~168 ~122 ~98 dirt
setblock ~168 ~122 ~99 dirt
setblock ~168 ~122 ~100 dirt
setblock ~168 ~122 ~101 dirt
setblock ~168 ~122 ~102 dirt
setblock ~168 ~122 ~103 dirt
setblock ~168 ~122 ~104 dirt
setblock ~168 ~122 ~105 dirt
setblock ~168 ~122 ~106 dirt
setblock ~168 ~122 ~107 dirt
setblock ~168 ~122 ~108 dirt
setblock ~168 ~122 ~109 dirt
setblock ~168 ~122 ~110 dirt
setblock ~168 ~122 ~111 dirt
setblock ~168 ~122 ~112 dirt
setblock ~168 ~123 ~72 dirt
setblock ~168 ~123 ~73 dirt
setblock ~168 ~123 ~74 dirt
setblock ~168 ~123 ~75 dirt
setblock ~168 ~123 ~76 dirt
setblock ~168 ~123 ~77 dirt
setblock ~168 ~123 ~78 dirt
setblock ~168 ~123 ~79 dirt
setblock ~168 ~123 ~80 dirt
setblock ~168 ~123 ~81 dirt
setblock ~168 ~123 ~82 dirt
setblock ~168 ~123 ~83 dirt
setblock ~168 ~123 ~84 dirt
setblock ~168 ~123 ~85 dirt
setblock ~168 ~123 ~86 grass_block
setblock ~168 ~123 ~87 grass_block
setblock ~168 ~123 ~88 grass_block
setblock ~168 ~123 ~89 grass_block
setblock ~168 ~123 ~91 grass_block
setblock ~168 ~123 ~92 grass_block
setblock ~168 ~123 ~93 grass_block
setblock ~168 ~123 ~94 grass_block
setblock ~168 ~123 ~95 dirt
setblock ~168 ~123 ~96 dirt
setblock ~168 ~123 ~97 dirt
setblock ~168 ~123 ~98 dirt
setblock ~168 ~123 ~99 dirt
setblock ~168 ~123 ~100 dirt
setblock ~168 ~123 ~101 dirt
setblock ~168 ~123 ~102 dirt
setblock ~168 ~123 ~103 dirt
setblock ~168 ~123 ~104 dirt
setblock ~168 ~123 ~105 dirt
setblock ~168 ~123 ~106 dirt
setblock ~168 ~123 ~107 dirt
setblock ~168 ~123 ~108 dirt
setblock ~168 ~123 ~109 dirt
setblock ~168 ~123 ~110 dirt
setblock ~168 ~123 ~111 dirt
setblock ~168 ~123 ~112 dirt
setblock ~168 ~124 ~72 dirt
setblock ~168 ~124 ~73 dirt
setblock ~168 ~124 ~74 dirt
setblock ~168 ~124 ~75 dirt
setblock ~168 ~124 ~76 dirt
setblock ~168 ~124 ~77 dirt
setblock ~168 ~124 ~78 dirt
setblock ~168 ~124 ~79 dirt
setblock ~168 ~124 ~80 dirt
setblock ~168 ~124 ~81 dirt
setblock ~168 ~124 ~82 grass_block
setblock ~168 ~124 ~83 grass_block
setblock ~168 ~124 ~84 grass_block
setblock ~168 ~124 ~85 grass_block
setblock ~168 ~124 ~95 grass_block
setblock ~168 ~124 ~96 grass_block
setblock ~168 ~124 ~97 grass_block
setblock ~168 ~124 ~98 dirt
setblock ~168 ~124 ~99 dirt
setblock ~168 ~124 ~100 dirt
setblock ~168 ~124 ~101 dirt
setblock ~168 ~124 ~102 dirt
setblock ~168 ~124 ~103 dirt
setblock ~168 ~124 ~104 dirt
setblock ~168 ~124 ~105 dirt
setblock ~168 ~124 ~106 dirt
setblock ~168 ~124 ~107 dirt
setblock ~168 ~124 ~108 dirt
setblock ~168 ~124 ~109 dirt
setblock ~168 ~124 ~110 dirt
setblock ~168 ~124 ~111 dirt
setblock ~168 ~124 ~112 dirt
setblock ~168 ~125 ~72 grass_block
setblock ~168 ~125 ~73 grass_block
setblock ~168 ~125 ~74 grass_block
setblock ~168 ~125 ~75 grass_block
setblock ~168 ~125 ~76 grass_block
setblock ~168 ~125 ~77 grass_block
setblock ~168 ~125 ~78 grass_block
setblock ~168 ~125 ~79 grass_block
setblock ~168 ~125 ~80 grass_block
setblock ~168 ~125 ~81 grass_block
setblock ~168 ~125 ~96 fern
setblock ~168 ~125 ~98 grass_block
setblock ~168 ~125 ~99 grass_block
setblock ~168 ~125 ~100 grass_block
setblock ~168 ~125 ~101 dirt
setblock ~168 ~125 ~102 dirt
setblock ~168 ~125 ~103 dirt
setblock ~168 ~125 ~104 dirt
setblock ~168 ~125 ~105 dirt
setblock ~168 ~125 ~106 dirt
setblock ~168 ~125 ~107 dirt
setblock ~168 ~125 ~108 dirt
setblock ~168 ~125 ~109 dirt
setblock ~168 ~125 ~110 dirt
setblock ~168 ~125 ~111 dirt
setblock ~168 ~125 ~112 dirt
setblock ~168 ~126 ~74 fern
setblock ~168 ~126 ~78 short_grass
setblock ~168 ~126 ~99 short_grass
setblock ~168 ~126 ~101 grass_block
setblock ~168 ~126 ~102 grass_block
setblock ~168 ~126 ~103 grass_block
setblock ~168 ~126 ~104 grass_block
setblock ~168 ~126 ~105 grass_block
setblock ~168 ~126 ~106 grass_block
setblock ~168 ~126 ~107 grass_block
setblock ~168 ~126 ~108 grass_block
setblock ~168 ~126 ~109 grass_block
setblock ~168 ~126 ~110 grass_block
setblock ~168 ~126 ~111 grass_block
setblock ~168 ~126 ~112 grass_block
setblock ~168 ~127 ~103 short_grass
setblock ~168 ~127 ~105 poppy
setblock ~168 ~127 ~111 poppy
setblock ~168 ~127 ~112 short_grass
setblock ~169 ~104 ~96 dirt
setblock ~169 ~105 ~95 dirt
setblock ~169 ~105 ~96 dirt
setblock ~169 ~105 ~97 dirt
setblock ~169 ~106 ~95 dirt
setblock ~169 ~106 ~96 dirt
setblock ~169 ~106 ~97 dirt
setblock ~169 ~106 ~98 dirt
setblock ~169 ~107 ~95 dirt
setblock ~169 ~107 ~96 dirt
setblock ~169 ~107 ~97 dirt
setblock ~169 ~107 ~98 dirt
setblock ~169 ~107 ~99 dirt
setblock ~169 ~108 ~93 dirt
setblock ~169 ~108 ~95 dirt
setblock ~169 ~108 ~96 dirt
setblock ~169 ~108 ~97 dirt
setblock ~169 ~108 ~98 dirt
setblock ~169 ~108 ~99 dirt
setblock ~169 ~109 ~92 dirt
setblock ~169 ~109 ~93 dirt
setblock ~169 ~109 ~94 dirt
setblock ~169 ~109 ~95 dirt
setblock ~169 ~109 ~96 dirt
setblock ~169 ~109 ~97 dirt
setblock ~169 ~109 ~98 dirt
setblock ~169 ~109 ~99 dirt
setblock ~169 ~109 ~102 dirt
setblock ~169 ~110 ~91 dirt
setblock ~169 ~110 ~92 dirt
setblock ~169 ~110 ~93 dirt
setblock ~169 ~110 ~94 dirt
setblock ~169 ~110 ~95 dirt
setblock ~169 ~110 ~96 dirt
setblock ~169 ~110 ~97 dirt
setblock ~169 ~110 ~98 dirt
setblock ~169 ~110 ~99 dirt
setblock ~169 ~110 ~100 dirt
setblock ~169 ~110 ~101 dirt
setblock ~169 ~110 ~102 dirt
setblock ~169 ~110 ~103 dirt
setblock ~169 ~111 ~90 dirt
setblock ~169 ~111 ~91 dirt
setblock ~169 ~111 ~92 dirt
setblock ~169 ~111 ~93 dirt
setblock ~169 ~111 ~94 dirt
setblock ~169 ~111 ~95 dirt
setblock ~169 ~111 ~96 dirt
setblock ~169 ~111 ~97 dirt
setblock ~169 ~111 ~98 dirt
setblock ~169 ~111 ~99 dirt
setblock ~169 ~111 ~100 dirt
setblock ~169 ~111 ~101 dirt
setblock ~169 ~111 ~102 dirt
setblock ~169 ~111 ~103 dirt
setblock ~169 ~111 ~104 dirt
setblock ~169 ~112 ~89 dirt
setblock ~169 ~112 ~90 dirt
setblock ~169 ~112 ~91 dirt
setblock ~169 ~112 ~92 dirt
setblock ~169 ~112 ~93 dirt
setblock ~169 ~112 ~94 dirt
setblock ~169 ~112 ~95 dirt
setblock ~169 ~112 ~96 dirt
setblock ~169 ~112 ~97 dirt
setblock ~169 ~112 ~98 dirt
setblock ~169 ~112 ~99 dirt
setblock ~169 ~112 ~100 dirt
setblock ~169 ~112 ~101 dirt
setblock ~169 ~112 ~102 dirt
setblock ~169 ~112 ~103 dirt
setblock ~169 ~112 ~104 dirt
setblock ~169 ~113 ~89 dirt
setblock ~169 ~113 ~90 dirt
setblock ~169 ~113 ~91 dirt
setblock ~169 ~113 ~92 dirt
setblock ~169 ~113 ~93 dirt
setblock ~169 ~113 ~94 dirt
setblock ~169 ~113 ~95 dirt
setblock ~169 ~113 ~96 dirt
setblock ~169 ~113 ~97 dirt
setblock ~169 ~113 ~98 dirt
setblock ~169 ~113 ~99 dirt
setblock ~169 ~113 ~100 dirt
setblock ~169 ~113 ~101 dirt
setblock ~169 ~113 ~102 dirt
setblock ~169 ~113 ~103 dirt
setblock ~169 ~113 ~104 dirt
setblock ~169 ~113 ~106 dirt
setblock ~169 ~114 ~89 dirt
setblock ~169 ~114 ~90 dirt
setblock ~169 ~114 ~91 dirt
setblock ~169 ~114 ~92 dirt
setblock ~169 ~114 ~93 dirt
setblock ~169 ~114 ~94 dirt
setblock ~169 ~114 ~95 dirt
setblock ~169 ~114 ~96 dirt
setblock ~169 ~114 ~97 dirt
setblock ~169 ~114 ~98 dirt
setblock ~169 ~114 ~99 dirt
setblock ~169 ~114 ~100 dirt
setblock ~169 ~114 ~101 dirt
setblock ~169 ~114 ~102 dirt
setblock ~169 ~114 ~103 dirt
setblock ~169 ~114 ~104 dirt
setblock ~169 ~114 ~105 dirt
setblock ~169 ~114 ~106 dirt
setblock ~169 ~114 ~107 dirt
setblock ~169 ~115 ~83 dirt
setblock ~169 ~115 ~88 dirt
setblock ~169 ~115 ~89 dirt
setblock ~169 ~115 ~90 dirt
setblock ~169 ~115 ~91 dirt
setblock ~169 ~115 ~92 dirt
setblock ~169 ~115 ~93 dirt
setblock ~169 ~115 ~94 dirt
setblock ~169 ~115 ~95 dirt
setblock ~169 ~115 ~96 dirt
setblock ~169 ~115 ~97 dirt
setblock ~169 ~115 ~98 dirt
setblock ~169 ~115 ~99 dirt
setblock ~169 ~115 ~100 dirt
setblock ~169 ~115 ~101 dirt
setblock ~169 ~115 ~102 dirt
setblock ~169 ~115 ~103 dirt
setblock ~169 ~115 ~104 dirt
setblock ~169 ~115 ~105 dirt
setblock ~169 ~115 ~106 dirt
setblock ~169 ~115 ~107 dirt
setblock ~169 ~115 ~108 dirt
setblock ~169 ~116 ~83 dirt
setblock ~169 ~116 ~84 dirt
setblock ~169 ~116 ~87 dirt
setblock ~169 ~116 ~88 dirt
setblock ~169 ~116 ~89 dirt
setblock ~169 ~116 ~90 dirt
setblock ~169 ~116 ~91 dirt
setblock ~169 ~116 ~92 dirt
setblock ~169 ~116 ~93 dirt
setblock ~169 ~116 ~94 dirt
setblock ~169 ~116 ~95 dirt
setblock ~169 ~116 ~96 dirt
setblock ~169 ~116 ~97 dirt
setblock ~169 ~116 ~98 dirt
setblock ~169 ~116 ~99 dirt
setblock ~169 ~116 ~100 dirt
setblock ~169 ~116 ~101 dirt
setblock ~169 ~116 ~102 dirt
setblock ~169 ~116 ~103 dirt
setblock ~169 ~116 ~104 dirt
setblock ~169 ~116 ~105 dirt
setblock ~169 ~116 ~106 dirt
setblock ~169 ~116 ~107 dirt
setblock ~169 ~116 ~108 dirt
setblock ~169 ~116 ~109 dirt
setblock ~169 ~117 ~82 dirt
setblock ~169 ~117 ~83 dirt
setblock ~169 ~117 ~84 dirt
setblock ~169 ~117 ~86 dirt
setblock ~169 ~117 ~87 dirt
setblock ~169 ~117 ~88 dirt
setblock ~169 ~117 ~89 dirt
setblock ~169 ~117 ~90 dirt
setblock ~169 ~117 ~91 dirt
setblock ~169 ~117 ~92 dirt
setblock ~169 ~117 ~93 dirt
setblock ~169 ~117 ~94 dirt
setblock ~169 ~117 ~95 dirt
setblock ~169 ~117 ~96 dirt
setblock ~169 ~117 ~97 dirt
setblock ~169 ~117 ~98 dirt
setblock ~169 ~117 ~99 dirt
setblock ~169 ~117 ~100 dirt
setblock ~169 ~117 ~101 dirt
setblock ~169 ~117 ~102 dirt
setblock ~169 ~117 ~103 dirt
setblock ~169 ~117 ~104 dirt
setblock ~169 ~117 ~105 dirt
setblock ~169 ~117 ~106 dirt
setblock ~169 ~117 ~107 dirt
setblock ~169 ~117 ~108 dirt
setblock ~169 ~117 ~109 dirt
setblock ~169 ~117 ~110 dirt
setblock ~169 ~118 ~74 dirt
setblock ~169 ~118 ~77 dirt
setblock ~169 ~118 ~81 dirt
setblock ~169 ~118 ~82 dirt
setblock ~169 ~118 ~83 dirt
setblock ~169 ~118 ~84 dirt
setblock ~169 ~118 ~85 dirt
setblock ~169 ~118 ~86 dirt
setblock ~169 ~118 ~87 dirt
setblock ~169 ~118 ~88 dirt
setblock ~169 ~118 ~89 dirt
setblock ~169 ~118 ~90 dirt
setblock ~169 ~118 ~91 dirt
setblock ~169 ~118 ~92 dirt
setblock ~169 ~118 ~93 dirt
setblock ~169 ~118 ~94 dirt
setblock ~169 ~118 ~95 dirt
setblock ~169 ~118 ~96 dirt
setblock ~169 ~118 ~97 dirt
setblock ~169 ~118 ~98 dirt
setblock ~169 ~118 ~99 dirt
setblock ~169 ~118 ~100 dirt
setblock ~169 ~118 ~101 dirt
setblock ~169 ~118 ~102 dirt
setblock ~169 ~118 ~103 dirt
setblock ~169 ~118 ~104 dirt
setblock ~169 ~118 ~105 dirt
setblock ~169 ~118 ~106 dirt
setblock ~169 ~118 ~107 dirt
setblock ~169 ~118 ~108 dirt
setblock ~169 ~118 ~109 dirt
setblock ~169 ~118 ~110 dirt
setblock ~169 ~118 ~111 dirt
setblock ~169 ~119 ~74 dirt
setblock ~169 ~119 ~76 dirt
setblock ~169 ~119 ~77 dirt
setblock ~169 ~119 ~80 dirt
setblock ~169 ~119 ~81 dirt
setblock ~169 ~119 ~82 dirt
setblock ~169 ~119 ~83 dirt
setblock ~169 ~119 ~84 dirt
setblock ~169 ~119 ~85 dirt
setblock ~169 ~119 ~86 dirt
setblock ~169 ~119 ~87 dirt
setblock ~169 ~119 ~88 dirt
setblock ~169 ~119 ~89 dirt
setblock ~169 ~119 ~90 dirt
setblock ~169 ~119 ~91 dirt
setblock ~169 ~119 ~92 dirt
setblock ~169 ~119 ~93 dirt
setblock ~169 ~119 ~94 dirt
setblock ~169 ~119 ~95 dirt
setblock ~169 ~119 ~96 dirt
setblock ~169 ~119 ~97 dirt
setblock ~169 ~119 ~98 dirt
setblock ~169 ~119 ~99 dirt
setblock ~169 ~119 ~100 dirt
setblock ~169 ~119 ~101 dirt
setblock ~169 ~119 ~102 dirt
setblock ~169 ~119 ~103 dirt
setblock ~169 ~119 ~104 dirt
setblock ~169 ~119 ~105 dirt
setblock ~169 ~119 ~106 dirt
setblock ~169 ~119 ~107 dirt
setblock ~169 ~119 ~108 dirt
setblock ~169 ~119 ~109 dirt
setblock ~169 ~119 ~110 dirt
setblock ~169 ~119 ~111 dirt
setblock ~169 ~119 ~112 dirt
setblock ~169 ~120 ~74 dirt
setblock ~169 ~120 ~75 dirt
setblock ~169 ~120 ~76 dirt
setblock ~169 ~120 ~77 dirt
setblock ~169 ~120 ~78 dirt
setblock ~169 ~120 ~79 dirt
setblock ~169 ~120 ~80 dirt
setblock ~169 ~120 ~81 dirt
setblock ~169 ~120 ~82 dirt
setblock ~169 ~120 ~83 dirt
setblock ~169 ~120 ~84 dirt
setblock ~169 ~120 ~85 dirt
setblock ~169 ~120 ~86 dirt
setblock ~169 ~120 ~87 dirt
setblock ~169 ~120 ~88 dirt
setblock ~169 ~120 ~89 dirt
setblock ~169 ~120 ~90 dirt
setblock ~169 ~120 ~91 dirt
setblock ~169 ~120 ~92 dirt
setblock ~169 ~120 ~93 dirt
setblock ~169 ~120 ~94 dirt
setblock ~169 ~120 ~95 dirt
setblock ~169 ~120 ~96 dirt
setblock ~169 ~120 ~97 dirt
setblock ~169 ~120 ~98 dirt
setblock ~169 ~120 ~99 dirt
setblock ~169 ~120 ~100 dirt
setblock ~169 ~120 ~101 dirt
setblock ~169 ~120 ~102 dirt
setblock ~169 ~120 ~103 dirt
setblock ~169 ~120 ~104 dirt
setblock ~169 ~120 ~105 dirt
setblock ~169 ~120 ~106 dirt
setblock ~169 ~120 ~107 dirt
setblock ~169 ~120 ~108 dirt
setblock ~169 ~120 ~109 dirt
setblock ~169 ~120 ~110 dirt
setblock ~169 ~120 ~111 dirt
setblock ~169 ~120 ~112 dirt
setblock ~169 ~121 ~73 dirt
setblock ~169 ~121 ~74 dirt
setblock ~169 ~121 ~75 dirt
setblock ~169 ~121 ~76 dirt
setblock ~169 ~121 ~77 dirt
setblock ~169 ~121 ~78 dirt
setblock ~169 ~121 ~79 dirt
setblock ~169 ~121 ~80 dirt
setblock ~169 ~121 ~81 dirt
setblock ~169 ~121 ~82 dirt
setblock ~169 ~121 ~83 dirt
setblock ~169 ~121 ~84 dirt
setblock ~169 ~121 ~85 dirt
setblock ~169 ~121 ~86 dirt
setblock ~169 ~121 ~87 dirt
setblock ~169 ~121 ~88 dirt
setblock ~169 ~121 ~89 dirt
setblock ~169 ~121 ~90 dirt
setblock ~169 ~121 ~91 dirt
setblock ~169 ~121 ~92 dirt
setblock ~169 ~121 ~93 dirt
setblock ~169 ~121 ~94 dirt
setblock ~169 ~121 ~95 dirt
setblock ~169 ~121 ~96 dirt
setblock ~169 ~121 ~97 dirt
setblock ~169 ~121 ~98 dirt
setblock ~169 ~121 ~99 dirt
setblock ~169 ~121 ~100 dirt
setblock ~169 ~121 ~101 dirt
setblock ~169 ~121 ~102 dirt
setblock ~169 ~121 ~103 dirt
setblock ~169 ~121 ~104 dirt
setblock ~169 ~121 ~105 dirt
setblock ~169 ~121 ~106 dirt
setblock ~169 ~121 ~107 dirt
setblock ~169 ~121 ~108 dirt
setblock ~169 ~121 ~109 dirt
setblock ~169 ~121 ~110 dirt
setblock ~169 ~121 ~111 dirt
setblock ~169 ~121 ~112 dirt
setblock ~169 ~122 ~73 dirt
setblock ~169 ~122 ~74 dirt
setblock ~169 ~122 ~75 dirt
setblock ~169 ~122 ~76 dirt
setblock ~169 ~122 ~77 dirt
setblock ~169 ~122 ~78 dirt
setblock ~169 ~122 ~79 dirt
setblock ~169 ~122 ~80 dirt
setblock ~169 ~122 ~81 dirt
setblock ~169 ~122 ~82 dirt
setblock ~169 ~122 ~83 dirt
setblock ~169 ~122 ~84 dirt
setblock ~169 ~122 ~85 dirt
setblock ~169 ~122 ~86 dirt
setblock ~169 ~122 ~87 dirt
setblock ~169 ~122 ~88 dirt
setblock ~169 ~122 ~89 grass_block
setblock ~169 ~122 ~90 grass_block
setblock ~169 ~122 ~91 grass_block
setblock ~169 ~122 ~92 dirt
setblock ~169 ~122 ~93 dirt
setblock ~169 ~122 ~94 dirt
setblock ~169 ~122 ~95 dirt
setblock ~169 ~122 ~96 dirt
setblock ~169 ~122 ~97 dirt
setblock ~169 ~122 ~98 dirt
setblock ~169 ~122 ~99 dirt
setblock ~169 ~122 ~100 dirt
setblock ~169 ~122 ~101 dirt
setblock ~169 ~122 ~102 dirt
setblock ~169 ~122 ~103 dirt
setblock ~169 ~122 ~104 dirt
setblock ~169 ~122 ~105 dirt
setblock ~169 ~122 ~106 dirt
setblock ~169 ~122 ~107 dirt
setblock ~169 ~122 ~108 dirt
setblock ~169 ~122 ~109 dirt
setblock ~169 ~122 ~110 dirt
setblock ~169 ~122 ~111 dirt
setblock ~169 ~122 ~112 dirt
setblock ~169 ~123 ~73 dirt
setblock ~169 ~123 ~74 dirt
setblock ~169 ~123 ~75 dirt
setblock ~169 ~123 ~76 dirt
setblock ~169 ~123 ~77 dirt
setblock ~169 ~123 ~78 dirt
setblock ~169 ~123 ~79 dirt
setblock ~169 ~123 ~80 dirt
setblock ~169 ~123 ~81 dirt
setblock ~169 ~123 ~82 dirt
setblock ~169 ~123 ~83 dirt
setblock ~169 ~123 ~84 dirt
setblock ~169 ~123 ~85 dirt
setblock ~169 ~123 ~86 grass_block
setblock ~169 ~123 ~87 grass_block
setblock ~169 ~123 ~88 grass_block
setblock ~169 ~123 ~92 grass_block
setblock ~169 ~123 ~93 grass_block
setblock ~169 ~123 ~94 grass_block
setblock ~169 ~123 ~95 dirt
setblock ~169 ~123 ~96 dirt
setblock ~169 ~123 ~97 dirt
setblock ~169 ~123 ~98 dirt
setblock ~169 ~123 ~99 dirt
setblock ~169 ~123 ~100 dirt
setblock ~169 ~123 ~101 dirt
setblock ~169 ~123 ~102 dirt
setblock ~169 ~123 ~103 dirt
setblock ~169 ~123 ~104 dirt
setblock ~169 ~123 ~105 dirt
setblock ~169 ~123 ~106 dirt
setblock ~169 ~123 ~107 dirt
setblock ~169 ~123 ~108 dirt
setblock ~169 ~123 ~109 dirt
setblock ~169 ~123 ~110 dirt
setblock ~169 ~123 ~111 dirt
setblock ~169 ~123 ~112 dirt
setblock ~169 ~124 ~73 dirt
setblock ~169 ~124 ~74 dirt
setblock ~169 ~124 ~75 dirt
setblock ~169 ~124 ~76 dirt
setblock ~169 ~124 ~77 dirt
setblock ~169 ~124 ~78 dirt
setblock ~169 ~124 ~79 dirt
setblock ~169 ~124 ~80 dirt
setblock ~169 ~124 ~81 dirt
setblock ~169 ~124 ~82 grass_block
setblock ~169 ~124 ~83 grass_block
setblock ~169 ~124 ~84 grass_block
setblock ~169 ~124 ~85 grass_block
setblock ~169 ~124 ~88 short_grass
setblock ~169 ~124 ~92 short_grass
setblock ~169 ~124 ~95 grass_block
setblock ~169 ~124 ~96 grass_block
setblock ~169 ~124 ~97 dirt
setblock ~169 ~124 ~98 dirt
setblock ~169 ~124 ~99 dirt
setblock ~169 ~124 ~100 dirt
setblock ~169 ~124 ~101 dirt
setblock ~169 ~124 ~102 dirt
setblock ~169 ~124 ~103 dirt
setblock ~169 ~124 ~104 dirt
setblock ~169 ~124 ~105 dirt
setblock ~169 ~124 ~106 dirt
setblock ~169 ~124 ~107 dirt
setblock ~169 ~124 ~108 dirt
setblock ~169 ~124 ~109 dirt
setblock ~169 ~124 ~110 dirt
setblock ~169 ~124 ~111 dirt
setblock ~169 ~124 ~112 dirt
setblock ~169 ~125 ~73 grass_block
setblock ~169 ~125 ~74 grass_block
setblock ~169 ~125 ~75 grass_block
setblock ~169 ~125 ~76 grass_block
setblock ~169 ~125 ~77 grass_block
setblock ~169 ~125 ~78 grass_block
setblock ~169 ~125 ~79 grass_block
setblock ~169 ~125 ~80 grass_block
setblock ~169 ~125 ~81 grass_block
setblock ~169 ~125 ~83 fern
setblock ~169 ~125 ~84 short_grass
setblock ~169 ~125 ~96 short_grass
setblock ~169 ~125 ~97 grass_block
setblock ~169 ~125 ~98 grass_block
setblock ~169 ~125 ~99 grass_block
setblock ~169 ~125 ~100 dirt
setblock ~169 ~125 ~101 dirt
setblock ~169 ~125 ~102 dirt
setblock ~169 ~125 ~103 dirt
setblock ~169 ~125 ~104 dirt
setblock ~169 ~125 ~105 dirt
setblock ~169 ~125 ~106 dirt
setblock ~169 ~125 ~107 dirt
setblock ~169 ~125 ~108 dirt
setblock ~169 ~125 ~109 dirt
setblock ~169 ~125 ~110 dirt
setblock ~169 ~125 ~111 dirt
setblock ~169 ~125 ~112 dirt
setblock ~169 ~126 ~75 poppy
setblock ~169 ~126 ~97 short_grass
setblock ~169 ~126 ~100 grass_block
setblock ~169 ~126 ~101 grass_block
setblock ~169 ~126 ~102 grass_block
setblock ~169 ~126 ~103 grass_block
setblock ~169 ~126 ~104 grass_block
setblock ~169 ~126 ~105 grass_block
setblock ~169 ~126 ~106 grass_block
setblock ~169 ~126 ~107 grass_block
setblock ~169 ~126 ~108 dirt
setblock ~169 ~126 ~109 dirt
setblock ~169 ~126 ~110 dirt
setblock ~169 ~126 ~111 grass_block
setblock ~169 ~126 ~112 grass_block
setblock ~169 ~127 ~104 fern
setblock ~169 ~127 ~107 short_grass
setblock ~169 ~127 ~108 grass_block
setblock ~169 ~127 ~109 grass_block
setblock ~169 ~127 ~110 grass_block
setblock ~169 ~128 ~108 short_grass
setblock ~169 ~128 ~109 short_grass
setblock ~169 ~128 ~110 fern
setblock ~170 ~105 ~96 dirt
setblock ~170 ~106 ~96 dirt
setblock ~170 ~106 ~97 dirt
setblock ~170 ~107 ~95 dirt
setblock ~170 ~107 ~96 dirt
setblock ~170 ~107 ~97 dirt
setblock ~170 ~107 ~98 dirt
setblock ~170 ~108 ~95 dirt
setblock ~170 ~108 ~96 dirt
setblock ~170 ~108 ~97 dirt
setblock ~170 ~108 ~98 dirt
setblock ~170 ~109 ~94 dirt
setblock ~170 ~109 ~95 dirt
setblock ~170 ~109 ~96 dirt
setblock ~170 ~109 ~97 dirt
setblock ~170 ~109 ~98 dirt
setblock ~170 ~109 ~99 dirt
setblock ~170 ~110 ~94 dirt
setblock ~170 ~110 ~95 dirt
setblock ~170 ~110 ~96 dirt
setblock ~170 ~110 ~97 dirt
setblock ~170 ~110 ~98 dirt
setblock ~170 ~110 ~99 dirt
setblock ~170 ~110 ~102 dirt
setblock ~170 ~111 ~94 dirt
setblock ~170 ~111 ~95 dirt
setblock ~170 ~111 ~96 dirt
setblock ~170 ~111 ~97 dirt
setblock ~170 ~111 ~98 dirt
setblock ~170 ~111 ~99 dirt
setblock ~170 ~111 ~102 dirt
setblock ~170 ~111 ~103 dirt
setblock ~170 ~112 ~90 dirt
setblock ~170 ~112 ~91 dirt
setblock ~170 ~112 ~92 dirt
setblock ~170 ~112 ~93 dirt
setblock ~170 ~112 ~94 dirt
setblock ~170 ~112 ~95 dirt
setblock ~170 ~112 ~96 dirt
setblock ~170 ~112 ~97 dirt
setblock ~170 ~112 ~98 dirt
setblock ~170 ~112 ~99 dirt
setblock ~170 ~112 ~100 dirt
setblock ~170 ~112 ~101 dirt
setblock ~170 ~112 ~102 dirt
setblock ~170 ~112 ~103 dirt
setblock ~170 ~113 ~90 dirt
setblock ~170 ~113 ~91 dirt
setblock ~170 ~113 ~92 dirt
setblock ~170 ~113 ~93 dirt
setblock ~170 ~113 ~94 dirt
setblock ~170 ~113 ~95 dirt
setblock ~170 ~113 ~96 dirt
setblock ~170 ~113 ~97 dirt
setblock ~170 ~113 ~98 dirt
setblock ~170 ~113 ~99 dirt
setblock ~170 ~113 ~100 dirt
setblock ~170 ~113 ~101 dirt
setblock ~170 ~113 ~102 dirt
setblock ~170 ~113 ~103 dirt
setblock ~170 ~113 ~104 dirt
setblock ~170 ~114 ~90 dirt
setblock ~170 ~114 ~91 dirt
setblock ~170 ~114 ~92 dirt
setblock ~170 ~114 ~93 dirt
setblock ~170 ~114 ~94 dirt
setblock ~170 ~114 ~95 dirt
setblock ~170 ~114 ~96 dirt
setblock ~170 ~114 ~97 dirt
setblock ~170 ~114 ~98 dirt
setblock ~170 ~114 ~99 dirt
setblock ~170 ~114 ~100 dirt
setblock ~170 ~114 ~101 dirt
setblock ~170 ~114 ~102 dirt
setblock ~170 ~114 ~103 dirt
setblock ~170 ~114 ~104 dirt
setblock ~170 ~115 ~89 dirt
setblock ~170 ~115 ~90 dirt
setblock ~170 ~115 ~91 dirt
setblock ~170 ~115 ~92 dirt
setblock ~170 ~115 ~93 dirt
setblock ~170 ~115 ~94 dirt
setblock ~170 ~115 ~95 dirt
setblock ~170 ~115 ~96 dirt
setblock ~170 ~115 ~97 dirt
setblock ~170 ~115 ~98 dirt
setblock ~170 ~115 ~99 dirt
setblock ~170 ~115 ~100 dirt
setblock ~170 ~115 ~101 dirt
setblock ~170 ~115 ~102 dirt
setblock ~170 ~115 ~103 dirt
setblock ~170 ~115 ~104 dirt
setblock ~170 ~116 ~88 dirt
setblock ~170 ~116 ~89 dirt
setblock ~170 ~116 ~90 dirt
setblock ~170 ~116 ~91 dirt
setblock ~170 ~116 ~92 dirt
setblock ~170 ~116 ~93 dirt
setblock ~170 ~116 ~94 dirt
setblock ~170 ~116 ~95 dirt
setblock ~170 ~116 ~96 dirt
setblock ~170 ~116 ~97 dirt
setblock ~170 ~116 ~98 dirt
setblock ~170 ~116 ~99 dirt
setblock ~170 ~116 ~100 dirt
setblock ~170 ~116 ~101 dirt
setblock ~170 ~116 ~102 dirt
setblock ~170 ~116 ~103 dirt
setblock ~170 ~116 ~104 dirt
setblock ~170 ~116 ~105 dirt
setblock ~170 ~116 ~106 dirt
setblock ~170 ~117 ~83 dirt
setblock ~170 ~117 ~87 dirt
setblock ~170 ~117 ~88 dirt
setblock ~170 ~117 ~89 dirt
setblock ~170 ~117 ~90 dirt
setblock ~170 ~117 ~91 dirt
setblock ~170 ~117 ~92 dirt
setblock ~170 ~117 ~93 dirt
setblock ~170 ~117 ~94 dirt
setblock ~170 ~117 ~95 dirt
setblock ~170 ~117 ~96 dirt
setblock ~170 ~117 ~97 dirt
setblock ~170 ~117 ~98 dirt
setblock ~170 ~117 ~99 dirt
setblock ~170 ~117 ~100 dirt
setblock ~170 ~117 ~101 dirt
setblock ~170 ~117 ~102 dirt
setblock ~170 ~117 ~103 dirt
setblock ~170 ~117 ~104 dirt
setblock ~170 ~117 ~105 dirt
setblock ~170 ~117 ~106 dirt
setblock ~170 ~117 ~107 dirt
setblock ~170 ~117 ~109 dirt
setblock ~170 ~118 ~82 dirt
setblock ~170 ~118 ~83 dirt
setblock ~170 ~118 ~84 dirt
setblock ~170 ~118 ~87 dirt
setblock ~170 ~118 ~88 dirt
setblock ~170 ~118 ~89 dirt
setblock ~170 ~118 ~90 dirt
setblock ~170 ~118 ~91 dirt
setblock ~170 ~118 ~92 dirt
setblock ~170 ~118 ~93 dirt
setblock ~170 ~118 ~94 dirt
setblock ~170 ~118 ~95 dirt
setblock ~170 ~118 ~96 dirt
setblock ~170 ~118 ~97 dirt
setblock ~170 ~118 ~98 dirt
setblock ~170 ~118 ~99 dirt
setblock ~170 ~118 ~100 dirt
setblock ~170 ~118 ~101 dirt
setblock ~170 ~118 ~102 dirt
setblock ~170 ~118 ~103 dirt
setblock ~170 ~118 ~104 dirt
setblock ~170 ~118 ~105 dirt
setblock ~170 ~118 ~106 dirt
setblock ~170 ~118 ~107 dirt
setblock ~170 ~118 ~108 dirt
setblock ~170 ~118 ~109 dirt
setblock ~170 ~118 ~110 dirt
setblock ~170 ~119 ~81 dirt
setblock ~170 ~119 ~82 dirt
setblock ~170 ~119 ~83 dirt
setblock ~170 ~119 ~84 dirt
setblock ~170 ~119 ~85 dirt
setblock ~170 ~119 ~86 dirt
setblock ~170 ~119 ~87 dirt
setblock ~170 ~119 ~88 dirt
setblock ~170 ~119 ~89 dirt
setblock ~170 ~119 ~90 dirt
setblock ~170 ~119 ~91 dirt
setblock ~170 ~119 ~92 dirt
setblock ~170 ~119 ~93 dirt
setblock ~170 ~119 ~94 dirt
setblock ~170 ~119 ~95 dirt
setblock ~170 ~119 ~96 dirt
setblock ~170 ~119 ~97 dirt
setblock ~170 ~119 ~98 dirt
setblock ~170 ~119 ~99 dirt
setblock ~170 ~119 ~100 dirt
setblock ~170 ~119 ~101 dirt
setblock ~170 ~119 ~102 dirt
setblock ~170 ~119 ~103 dirt
setblock ~170 ~119 ~104 dirt
setblock ~170 ~119 ~105 dirt
setblock ~170 ~119 ~106 dirt
setblock ~170 ~119 ~107 dirt
setblock ~170 ~119 ~108 dirt
setblock ~170 ~119 ~109 dirt
setblock ~170 ~119 ~110 dirt
setblock ~170 ~119 ~111 dirt
setblock ~170 ~120 ~77 dirt
setblock ~170 ~120 ~80 dirt
setblock ~170 ~120 ~81 dirt
setblock ~170 ~120 ~82 dirt
setblock ~170 ~120 ~83 dirt
setblock ~170 ~120 ~84 dirt
setblock ~170 ~120 ~85 dirt
setblock ~170 ~120 ~86 dirt
setblock ~170 ~120 ~87 dirt
setblock ~170 ~120 ~88 dirt
setblock ~170 ~120 ~89 dirt
setblock ~170 ~120 ~90 dirt
setblock ~170 ~120 ~91 dirt
setblock ~170 ~120 ~92 dirt
setblock ~170 ~120 ~93 dirt
setblock ~170 ~120 ~94 dirt
setblock ~170 ~120 ~95 dirt
setblock ~170 ~120 ~96 dirt
setblock ~170 ~120 ~97 dirt
setblock ~170 ~120 ~98 dirt
setblock ~170 ~120 ~99 dirt
setblock ~170 ~120 ~100 dirt
setblock ~170 ~120 ~101 dirt
setblock ~170 ~120 ~102 dirt
setblock ~170 ~120 ~103 dirt
setblock ~170 ~120 ~104 dirt
setblock ~170 ~120 ~105 dirt
setblock ~170 ~120 ~106 dirt
setblock ~170 ~120 ~107 dirt
setblock ~170 ~120 ~108 dirt
setblock ~170 ~120 ~109 dirt
setblock ~170 ~120 ~110 dirt
setblock ~170 ~120 ~111 dirt
setblock ~170 ~121 ~74 dirt
setblock ~170 ~121 ~76 dirt
setblock ~170 ~121 ~77 dirt
setblock ~170 ~121 ~78 dirt
setblock ~170 ~121 ~79 dirt
setblock ~170 ~121 ~80 dirt
setblock ~170 ~121 ~81 dirt
setblock ~170 ~121 ~82 dirt
setblock ~170 ~121 ~83 dirt
setblock ~170 ~121 ~84 dirt
setblock ~170 ~121 ~85 dirt
setblock ~170 ~121 ~86 dirt
setblock ~170 ~121 ~87 dirt
setblock ~170 ~121 ~88 dirt
setblock ~170 ~121 ~89 dirt
setblock ~170 ~121 ~90 dirt
setblock ~170 ~121 ~91 dirt
setblock ~170 ~121 ~92 dirt
setblock ~170 ~121 ~93 dirt
setblock ~170 ~121 ~94 dirt
setblock ~170 ~121 ~95 dirt
setblock ~170 ~121 ~96 dirt
setblock ~170 ~121 ~97 dirt
setblock ~170 ~121 ~98 dirt
setblock ~170 ~121 ~99 dirt
setblock ~170 ~121 ~100 dirt
setblock ~170 ~121 ~101 dirt
setblock ~170 ~121 ~102 dirt
setblock ~170 ~121 ~103 dirt
setblock ~170 ~121 ~104 dirt
setblock ~170 ~121 ~105 dirt
setblock ~170 ~121 ~106 dirt
setblock ~170 ~121 ~107 dirt
setblock ~170 ~121 ~108 dirt
setblock ~170 ~121 ~109 dirt
setblock ~170 ~121 ~110 dirt
setblock ~170 ~121 ~111 dirt
setblock ~170 ~121 ~112 dirt
setblock ~170 ~122 ~74 dirt
setblock ~170 ~122 ~76 dirt
setblock ~170 ~122 ~77 dirt
setblock ~170 ~122 ~78 dirt
setblock ~170 ~122 ~79 dirt
setblock ~170 ~122 ~80 dirt
setblock ~170 ~122 ~81 dirt
setblock ~170 ~122 ~82 dirt
setblock ~170 ~122 ~83 dirt
setblock ~170 ~122 ~84 dirt
setblock ~170 ~122 ~85 dirt
setblock ~170 ~122 ~86 dirt
setblock ~170 ~122 ~87 dirt
setblock ~170 ~122 ~88 dirt
setblock ~170 ~122 ~89 grass_block
setblock ~170 ~122 ~90 grass_block
setblock ~170 ~122 ~91 grass_block
setblock ~170 ~122 ~92 dirt
setblock ~170 ~122 ~93 dirt
setblock ~170 ~122 ~94 dirt
setblock ~170 ~122 ~95 dirt
setblock ~170 ~122 ~96 dirt
setblock ~170 ~122 ~97 dirt
setblock ~170 ~122 ~98 dirt
setblock ~170 ~122 ~99 dirt
setblock ~170 ~122 ~100 dirt
setblock ~170 ~122 ~101 dirt
setblock ~170 ~122 ~102 dirt
setblock ~170 ~122 ~103 dirt
setblock ~170 ~122 ~104 dirt
setblock ~170 ~122 ~105 dirt
setblock ~170 ~122 ~106 dirt
setblock ~170 ~122 ~107 dirt
setblock ~170 ~122 ~108 dirt
setblock ~170 ~122 ~109 dirt
setblock ~170 ~122 ~110 dirt
setblock ~170 ~122 ~111 dirt
setblock ~170 ~122 ~112 dirt
setblock ~170 ~123 ~74 dirt
setblock ~170 ~123 ~76 dirt
setblock ~170 ~123 ~77 dirt
setblock ~170 ~123 ~78 dirt
setblock ~170 ~123 ~79 dirt
setblock ~170 ~123 ~80 dirt
setblock ~170 ~123 ~81 dirt
setblock ~170 ~123 ~82 dirt
setblock ~170 ~123 ~83 dirt
setblock ~170 ~123 ~84 dirt
setblock ~170 ~123 ~85 dirt
setblock ~170 ~123 ~86 grass_block
setblock ~170 ~123 ~87 grass_block
setblock ~170 ~123 ~88 grass_block
setblock ~170 ~123 ~92 grass_block
setblock ~170 ~123 ~93 grass_block
setblock ~170 ~123 ~94 grass_block
setblock ~170 ~123 ~95 dirt
setblock ~170 ~123 ~96 dirt
setblock ~170 ~123 ~97 dirt
setblock ~170 ~123 ~98 dirt
setblock ~170 ~123 ~99 dirt
setblock ~170 ~123 ~100 dirt
setblock ~170 ~123 ~101 dirt
setblock ~170 ~123 ~102 dirt
setblock ~170 ~123 ~103 dirt
setblock ~170 ~123 ~104 dirt
setblock ~170 ~123 ~105 dirt
setblock ~170 ~123 ~106 dirt
setblock ~170 ~123 ~107 dirt
setblock ~170 ~123 ~108 dirt
setblock ~170 ~123 ~109 dirt
setblock ~170 ~123 ~110 dirt
setblock ~170 ~123 ~111 dirt
setblock ~170 ~123 ~112 dirt
setblock ~170 ~124 ~74 dirt
setblock ~170 ~124 ~76 dirt
setblock ~170 ~124 ~77 dirt
setblock ~170 ~124 ~78 dirt
setblock ~170 ~124 ~79 dirt
setblock ~170 ~124 ~80 dirt
setblock ~170 ~124 ~81 dirt
setblock ~170 ~124 ~82 grass_block
setblock ~170 ~124 ~83 grass_block
setblock ~170 ~124 ~84 grass_block
setblock ~170 ~124 ~85 grass_block
setblock ~170 ~124 ~87 short_grass
setblock ~170 ~124 ~95 grass_block
setblock ~170 ~124 ~96 grass_block
setblock ~170 ~124 ~97 dirt
setblock ~170 ~124 ~98 dirt
setblock ~170 ~124 ~99 dirt
setblock ~170 ~124 ~100 dirt
setblock ~170 ~124 ~101 dirt
setblock ~170 ~124 ~102 dirt
setblock ~170 ~124 ~103 dirt
setblock ~170 ~124 ~104 dirt
setblock ~170 ~124 ~105 dirt
setblock ~170 ~124 ~106 dirt
setblock ~170 ~124 ~107 dirt
setblock ~170 ~124 ~108 dirt
setblock ~170 ~124 ~109 dirt
setblock ~170 ~124 ~110 dirt
setblock ~170 ~124 ~111 dirt
setblock ~170 ~124 ~112 dirt
setblock ~170 ~125 ~74 grass_block
setblock ~170 ~125 ~76 grass_block
setblock ~170 ~125 ~77 grass_block
setblock ~170 ~125 ~78 grass_block
setblock ~170 ~125 ~79 grass_block
setblock ~170 ~125 ~80 grass_block
setblock ~170 ~125 ~81 grass_block
setblock ~170 ~125 ~82 short_grass
