setblock ~0 ~1 ~0 gold_block
setblock ~31 ~134 ~117 oak_leaves[persistent=true]
setblock ~31 ~134 ~118 jungle_leaves[persistent=true]
setblock ~31 ~134 ~119 oak_leaves[persistent=true]
setblock ~31 ~134 ~120 oak_leaves[persistent=true]
setblock ~31 ~135 ~117 jungle_leaves[persistent=true]
setblock ~31 ~135 ~118 oak_leaves[persistent=true]
setblock ~31 ~135 ~119 oak_leaves[persistent=true]
setblock ~31 ~135 ~120 oak_leaves[persistent=true]
setblock ~31 ~136 ~117 oak_leaves[persistent=true]
setblock ~31 ~136 ~118 oak_leaves[persistent=true]
setblock ~31 ~136 ~119 oak_leaves[persistent=true]
setblock ~31 ~136 ~120 oak_leaves[persistent=true]
setblock ~31 ~137 ~117 jungle_leaves[persistent=true]
setblock ~31 ~137 ~120 oak_leaves[persistent=true]
setblock ~32 ~120 ~120 dirt
setblock ~32 ~121 ~97 dirt
setblock ~32 ~121 ~119 dirt
setblock ~32 ~121 ~120 dirt
setblock ~32 ~122 ~97 dirt
setblock ~32 ~122 ~119 dirt
setblock ~32 ~122 ~120 dirt
setblock ~32 ~123 ~97 dirt
setblock ~32 ~123 ~119 dirt
setblock ~32 ~123 ~120 dirt
setblock ~32 ~124 ~97 dirt
setblock ~32 ~124 ~119 dirt
setblock ~32 ~124 ~120 dirt
setblock ~32 ~125 ~97 grass_block
setblock ~32 ~125 ~119 grass_block
setblock ~32 ~125 ~120 grass_block
setblock ~32 ~126 ~97 short_grass
setblock ~32 ~129 ~129 jungle_leaves[persistent=true]
setblock ~32 ~129 ~130 oak_leaves[persistent=true]
setblock ~32 ~129 ~131 jungle_leaves[persistent=true]
setblock ~32 ~129 ~132 oak_leaves[persistent=true]
setblock ~32 ~130 ~129 oak_leaves[persistent=true]
setblock ~32 ~130 ~130 oak_leaves[persistent=true]
setblock ~32 ~130 ~131 jungle_leaves[persistent=true]
setblock ~32 ~130 ~132 oak_leaves[persistent=true]
setblock ~32 ~131 ~129 oak_leaves[persistent=true]
setblock ~32 ~131 ~130 oak_leaves[persistent=true]
setblock ~32 ~131 ~131 oak_leaves[persistent=true]
setblock ~32 ~131 ~132 oak_leaves[persistent=true]
setblock ~32 ~132 ~129 oak_leaves[persistent=true]
setblock ~32 ~132 ~130 oak_leaves[persistent=true]
setblock ~32 ~132 ~131 jungle_leaves[persistent=true]
setblock ~32 ~132 ~132 oak_leaves[persistent=true]
setblock ~32 ~134 ~117 oak_leaves[persistent=true]
setblock ~32 ~134 ~118 oak_leaves[persistent=true]
setblock ~32 ~134 ~119 oak_leaves[persistent=true]
setblock ~32 ~134 ~120 oak_leaves[persistent=true]
setblock ~32 ~135 ~117 oak_leaves[persistent=true]
setblock ~32 ~135 ~118 oak_leaves[persistent=true]
setblock ~32 ~135 ~119 jungle_leaves[persistent=true]
setblock ~32 ~135 ~120 oak_leaves[persistent=true]
setblock ~32 ~136 ~117 oak_leaves[persistent=true]
setblock ~32 ~136 ~118 oak_leaves[persistent=true]
setblock ~32 ~136 ~119 oak_leaves[persistent=true]
setblock ~32 ~136 ~120 oak_leaves[persistent=true]
setblock ~32 ~137 ~118 jungle_leaves[persistent=true]
setblock ~32 ~137 ~119 oak_leaves[persistent=true]
setblock ~32 ~137 ~120 oak_leaves[persistent=true]
setblock ~33 ~119 ~97 dirt
setblock ~33 ~119 ~120 dirt
setblock ~33 ~120 ~97 dirt
setblock ~33 ~120 ~119 dirt
setblock ~33 ~120 ~120 dirt
setblock ~33 ~120 ~121 dirt
setblock ~33 ~121 ~95 dirt
setblock ~33 ~121 ~96 dirt
setblock ~33 ~121 ~97 dirt
setblock ~33 ~121 ~98 dirt
setblock ~33 ~121 ~100 dirt
setblock ~33 ~121 ~118 dirt
setblock ~33 ~121 ~119 dirt
setblock ~33 ~121 ~120 dirt
setblock ~33 ~121 ~121 dirt
setblock ~33 ~121 ~122 dirt
setblock ~33 ~122 ~95 dirt
setblock ~33 ~122 ~96 dirt
setblock ~33 ~122 ~97 dirt
setblock ~33 ~122 ~98 dirt
setblock ~33 ~122 ~100 dirt
setblock ~33 ~122 ~118 dirt
setblock ~33 ~122 ~119 dirt
setblock ~33 ~122 ~120 dirt
setblock ~33 ~122 ~121 dirt
setblock ~33 ~122 ~122 dirt
setblock ~33 ~123 ~95 dirt
setblock ~33 ~123 ~96 dirt
setblock ~33 ~123 ~97 dirt
setblock ~33 ~123 ~98 dirt
setblock ~33 ~123 ~100 dirt
setblock ~33 ~123 ~118 dirt
setblock ~33 ~123 ~119 dirt
setblock ~33 ~123 ~120 dirt
setblock ~33 ~123 ~121 dirt
setblock ~33 ~123 ~122 dirt
setblock ~33 ~124 ~95 dirt
setblock ~33 ~124 ~96 dirt
setblock ~33 ~124 ~97 dirt
setblock ~33 ~124 ~98 dirt
setblock ~33 ~124 ~100 dirt
setblock ~33 ~124 ~118 dirt
setblock ~33 ~124 ~119 dirt
setblock ~33 ~124 ~120 dirt
setblock ~33 ~124 ~121 dirt
setblock ~33 ~124 ~122 dirt
setblock ~33 ~125 ~95 grass_block
setblock ~33 ~125 ~96 grass_block
setblock ~33 ~125 ~97 grass_block
setblock ~33 ~125 ~98 grass_block
setblock ~33 ~125 ~100 grass_block
setblock ~33 ~125 ~118 grass_block
setblock ~33 ~125 ~119 grass_block
setblock ~33 ~125 ~120 grass_block
setblock ~33 ~125 ~121 grass_block
setblock ~33 ~125 ~122 grass_block
setblock ~33 ~126 ~95 short_grass
setblock ~33 ~126 ~97 short_grass
setblock ~33 ~126 ~118 short_grass
setblock ~33 ~126 ~119 fern
setblock ~33 ~129 ~129 oak_leaves[persistent=true]
setblock ~33 ~129 ~130 oak_leaves[persistent=true]
setblock ~33 ~129 ~131 jungle_leaves[persistent=true]
setblock ~33 ~129 ~132 oak_leaves[persistent=true]
setblock ~33 ~130 ~129 oak_leaves[persistent=true]
setblock ~33 ~130 ~131 oak_leaves[persistent=true]
setblock ~33 ~131 ~129 oak_leaves[persistent=true]
setblock ~33 ~131 ~130 jungle_leaves[persistent=true]
setblock ~33 ~131 ~131 oak_leaves[persistent=true]
setblock ~33 ~131 ~132 oak_leaves[persistent=true]
setblock ~33 ~132 ~129 oak_leaves[persistent=true]
setblock ~33 ~132 ~130 jungle_leaves[persistent=true]
setblock ~33 ~132 ~131 oak_leaves[persistent=true]
setblock ~33 ~132 ~132 oak_leaves[persistent=true]
setblock ~33 ~133 ~138 oak_leaves[persistent=true]
setblock ~33 ~133 ~139 oak_leaves[persistent=true]
setblock ~33 ~133 ~140 oak_leaves[persistent=true]
setblock ~33 ~133 ~141 oak_leaves[persistent=true]
setblock ~33 ~134 ~117 oak_leaves[persistent=true]
setblock ~33 ~134 ~118 oak_leaves[persistent=true]
setblock ~33 ~134 ~120 oak_leaves[persistent=true]
setblock ~33 ~134 ~121 oak_leaves[persistent=true]
setblock ~33 ~134 ~138 oak_leaves[persistent=true]
setblock ~33 ~134 ~139 oak_leaves[persistent=true]
setblock ~33 ~134 ~140 oak_leaves[persistent=true]
setblock ~33 ~134 ~141 oak_leaves[persistent=true]
setblock ~33 ~135 ~117 oak_leaves[persistent=true]
setblock ~33 ~135 ~118 oak_leaves[persistent=true]
setblock ~33 ~135 ~119 oak_leaves[persistent=true]
setblock ~33 ~135 ~120 oak_leaves[persistent=true]
setblock ~33 ~135 ~121 oak_leaves[persistent=true]
setblock ~33 ~135 ~138 jungle_leaves[persistent=true]
setblock ~33 ~135 ~139 jungle_leaves[persistent=true]
setblock ~33 ~135 ~140 oak_leaves[persistent=true]
setblock ~33 ~135 ~141 oak_leaves[persistent=true]
setblock ~33 ~136 ~117 jungle_leaves[persistent=true]
setblock ~33 ~136 ~118 oak_leaves[persistent=true]
setblock ~33 ~136 ~119 oak_wood
setblock ~33 ~136 ~120 oak_leaves[persistent=true]
setblock ~33 ~136 ~121 jungle_leaves[persistent=true]
setblock ~33 ~136 ~138 jungle_leaves[persistent=true]
setblock ~33 ~136 ~139 oak_leaves[persistent=true]
setblock ~33 ~136 ~140 oak_leaves[persistent=true]
setblock ~33 ~136 ~141 jungle_leaves[persistent=true]
setblock ~33 ~137 ~117 oak_leaves[persistent=true]
setblock ~33 ~137 ~118 oak_leaves[persistent=true]
setblock ~33 ~137 ~119 oak_leaves[persistent=true]
setblock ~33 ~137 ~121 jungle_leaves[persistent=true]
setblock ~33 ~137 ~122 oak_leaves[persistent=true]
setblock ~33 ~138 ~120 oak_leaves[persistent=true]
setblock ~33 ~138 ~121 oak_leaves[persistent=true]
setblock ~33 ~138 ~122 oak_leaves[persistent=true]
setblock ~33 ~139 ~120 jungle_leaves[persistent=true]
setblock ~33 ~139 ~121 jungle_leaves[persistent=true]
setblock ~33 ~139 ~122 oak_leaves[persistent=true]
setblock ~34 ~117 ~97 dirt
setblock ~34 ~118 ~96 dirt
setblock ~34 ~118 ~97 dirt
setblock ~34 ~118 ~120 dirt
setblock ~34 ~119 ~96 dirt
setblock ~34 ~119 ~97 dirt
setblock ~34 ~119 ~98 dirt
setblock ~34 ~119 ~100 dirt
setblock ~34 ~119 ~119 dirt
setblock ~34 ~119 ~120 dirt
setblock ~34 ~119 ~121 dirt
setblock ~34 ~120 ~94 dirt
setblock ~34 ~120 ~95 dirt
setblock ~34 ~120 ~96 dirt
setblock ~34 ~120 ~97 dirt
setblock ~34 ~120 ~98 dirt
setblock ~34 ~120 ~99 dirt
setblock ~34 ~120 ~100 dirt
setblock ~34 ~120 ~101 dirt
setblock ~34 ~120 ~117 dirt
setblock ~34 ~120 ~118 dirt
setblock ~34 ~120 ~119 dirt
setblock ~34 ~120 ~120 dirt
setblock ~34 ~120 ~121 dirt
setblock ~34 ~120 ~122 dirt
setblock ~34 ~121 ~93 dirt
setblock ~34 ~121 ~94 dirt
setblock ~34 ~121 ~95 dirt
setblock ~34 ~121 ~96 dirt
setblock ~34 ~121 ~97 dirt
setblock ~34 ~121 ~98 dirt
setblock ~34 ~121 ~99 dirt
setblock ~34 ~121 ~100 dirt
setblock ~34 ~121 ~101 dirt
setblock ~34 ~121 ~102 dirt
setblock ~34 ~121 ~116 dirt
setblock ~34 ~121 ~117 dirt
setblock ~34 ~121 ~118 dirt
setblock ~34 ~121 ~119 dirt
setblock ~34 ~121 ~120 dirt
setblock ~34 ~121 ~121 dirt
setblock ~34 ~121 ~122 dirt
setblock ~34 ~121 ~123 dirt
setblock ~34 ~122 ~93 dirt
setblock ~34 ~122 ~94 dirt
setblock ~34 ~122 ~95 dirt
setblock ~34 ~122 ~96 dirt
setblock ~34 ~122 ~97 dirt
setblock ~34 ~122 ~98 dirt
setblock ~34 ~122 ~99 dirt
setblock ~34 ~122 ~100 dirt
setblock ~34 ~122 ~101 dirt
setblock ~34 ~122 ~102 dirt
setblock ~34 ~122 ~116 dirt
setblock ~34 ~122 ~117 dirt
setblock ~34 ~122 ~118 dirt
setblock ~34 ~122 ~119 dirt
setblock ~34 ~122 ~120 dirt
setblock ~34 ~122 ~121 dirt
setblock ~34 ~122 ~122 dirt
setblock ~34 ~122 ~123 dirt
setblock ~34 ~123 ~93 dirt
setblock ~34 ~123 ~94 dirt
setblock ~34 ~123 ~95 dirt
setblock ~34 ~123 ~96 dirt
setblock ~34 ~123 ~97 dirt
setblock ~34 ~123 ~98 dirt
setblock ~34 ~123 ~99 dirt
setblock ~34 ~123 ~100 dirt
setblock ~34 ~123 ~101 dirt
setblock ~34 ~123 ~102 dirt
setblock ~34 ~123 ~116 dirt
setblock ~34 ~123 ~117 dirt
setblock ~34 ~123 ~118 dirt
setblock ~34 ~123 ~119 dirt
setblock ~34 ~123 ~120 dirt
setblock ~34 ~123 ~121 dirt
setblock ~34 ~123 ~122 dirt
setblock ~34 ~123 ~123 dirt
setblock ~34 ~124 ~93 dirt
setblock ~34 ~124 ~94 dirt
setblock ~34 ~124 ~95 dirt
setblock ~34 ~124 ~96 dirt
setblock ~34 ~124 ~97 dirt
setblock ~34 ~124 ~98 dirt
setblock ~34 ~124 ~99 dirt
setblock ~34 ~124 ~100 dirt
setblock ~34 ~124 ~101 dirt
setblock ~34 ~124 ~102 dirt
setblock ~34 ~124 ~116 dirt
setblock ~34 ~124 ~117 dirt
setblock ~34 ~124 ~118 dirt
setblock ~34 ~124 ~119 dirt
setblock ~34 ~124 ~120 dirt
setblock ~34 ~124 ~121 dirt
setblock ~34 ~124 ~122 dirt
setblock ~34 ~124 ~123 dirt
setblock ~34 ~125 ~93 dirt
setblock ~34 ~125 ~94 dirt
setblock ~34 ~125 ~95 dirt
setblock ~34 ~125 ~96 dirt
setblock ~34 ~125 ~97 dirt
setblock ~34 ~125 ~98 grass_block
setblock ~34 ~125 ~99 grass_block
setblock ~34 ~125 ~100 grass_block
setblock ~34 ~125 ~101 grass_block
setblock ~34 ~125 ~102 dirt
setblock ~34 ~125 ~116 grass_block
setblock ~34 ~125 ~117 grass_block
setblock ~34 ~125 ~118 grass_block
setblock ~34 ~125 ~119 grass_block
setblock ~34 ~125 ~120 grass_block
setblock ~34 ~125 ~121 grass_block
setblock ~34 ~125 ~122 grass_block
setblock ~34 ~125 ~123 grass_block
setblock ~34 ~126 ~93 grass_block
setblock ~34 ~126 ~94 grass_block
setblock ~34 ~126 ~95 grass_block
setblock ~34 ~126 ~96 grass_block
setblock ~34 ~126 ~97 grass_block
setblock ~34 ~126 ~102 grass_block
setblock ~34 ~126 ~117 short_grass
setblock ~34 ~126 ~118 short_grass
setblock ~34 ~127 ~93 short_grass
setblock ~34 ~127 ~94 short_grass
setblock ~34 ~127 ~96 short_grass
setblock ~34 ~129 ~129 oak_leaves[persistent=true]
setblock ~34 ~129 ~130 oak_leaves[persistent=true]
setblock ~34 ~129 ~131 oak_leaves[persistent=true]
setblock ~34 ~129 ~132 jungle_leaves[persistent=true]
setblock ~34 ~130 ~128 oak_leaves[persistent=true]
setblock ~34 ~130 ~129 jungle_leaves[persistent=true]
setblock ~34 ~130 ~130 oak_leaves[persistent=true]
setblock ~34 ~130 ~131 oak_leaves[persistent=true]
setblock ~34 ~130 ~132 oak_leaves[persistent=true]
setblock ~34 ~130 ~141 oak_leaves[persistent=true]
setblock ~34 ~130 ~142 oak_leaves[persistent=true]
setblock ~34 ~130 ~143 oak_leaves[persistent=true]
setblock ~34 ~130 ~144 oak_leaves[persistent=true]
setblock ~34 ~131 ~128 oak_leaves[persistent=true]
setblock ~34 ~131 ~129 oak_leaves[persistent=true]
setblock ~34 ~131 ~130 oak_leaves[persistent=true]
setblock ~34 ~131 ~131 oak_leaves[persistent=true]
setblock ~34 ~131 ~132 oak_leaves[persistent=true]
setblock ~34 ~131 ~141 oak_leaves[persistent=true]
setblock ~34 ~131 ~142 oak_leaves[persistent=true]
setblock ~34 ~131 ~143 oak_leaves[persistent=true]
setblock ~34 ~132 ~128 oak_leaves[persistent=true]
setblock ~34 ~132 ~129 jungle_leaves[persistent=true]
setblock ~34 ~132 ~130 oak_leaves[persistent=true]
setblock ~34 ~132 ~132 jungle_leaves[persistent=true]
setblock ~34 ~132 ~141 oak_leaves[persistent=true]
setblock ~34 ~132 ~142 oak_leaves[persistent=true]
setblock ~34 ~132 ~143 oak_leaves[persistent=true]
setblock ~34 ~132 ~144 oak_leaves[persistent=true]
setblock ~34 ~133 ~123 oak_leaves[persistent=true]
setblock ~34 ~133 ~124 oak_leaves[persistent=true]
setblock ~34 ~133 ~125 oak_leaves[persistent=true]
setblock ~34 ~133 ~128 oak_leaves[persistent=true]
setblock ~34 ~133 ~129 oak_leaves[persistent=true]
setblock ~34 ~133 ~130 oak_leaves[persistent=true]
setblock ~34 ~133 ~131 oak_leaves[persistent=true]
setblock ~34 ~133 ~138 oak_leaves[persistent=true]
setblock ~34 ~133 ~139 oak_leaves[persistent=true]
setblock ~34 ~133 ~140 oak_leaves[persistent=true]
setblock ~34 ~133 ~141 oak_leaves[persistent=true]
setblock ~34 ~133 ~143 oak_leaves[persistent=true]
setblock ~34 ~133 ~144 oak_leaves[persistent=true]
setblock ~34 ~134 ~117 oak_leaves[persistent=true]
setblock ~34 ~134 ~118 jungle_leaves[persistent=true]
setblock ~34 ~134 ~119 oak_leaves[persistent=true]
setblock ~34 ~134 ~120 oak_leaves[persistent=true]
setblock ~34 ~134 ~121 oak_leaves[persistent=true]
setblock ~34 ~134 ~123 oak_leaves[persistent=true]
setblock ~34 ~134 ~124 oak_leaves[persistent=true]
setblock ~34 ~134 ~125 oak_leaves[persistent=true]
setblock ~34 ~134 ~129 oak_leaves[persistent=true]
setblock ~34 ~134 ~130 jungle_leaves[persistent=true]
setblock ~34 ~134 ~131 oak_leaves[persistent=true]
setblock ~34 ~134 ~137 jungle_leaves[persistent=true]
setblock ~34 ~134 ~139 oak_leaves[persistent=true]
setblock ~34 ~134 ~140 oak_leaves[persistent=true]
setblock ~34 ~134 ~141 oak_leaves[persistent=true]
setblock ~34 ~135 ~117 oak_leaves[persistent=true]
setblock ~34 ~135 ~118 oak_leaves[persistent=true]
setblock ~34 ~135 ~119 oak_leaves[persistent=true]
setblock ~34 ~135 ~120 jungle_leaves[persistent=true]
setblock ~34 ~135 ~123 oak_leaves[persistent=true]
setblock ~34 ~135 ~124 oak_leaves[persistent=true]
setblock ~34 ~135 ~125 oak_leaves[persistent=true]
setblock ~34 ~135 ~129 oak_leaves[persistent=true]
setblock ~34 ~135 ~130 oak_leaves[persistent=true]
setblock ~34 ~135 ~131 oak_leaves[persistent=true]
setblock ~34 ~135 ~136 oak_leaves[persistent=true]
setblock ~34 ~135 ~137 oak_leaves[persistent=true]
setblock ~34 ~135 ~138 oak_leaves[persistent=true]
setblock ~34 ~135 ~140 oak_leaves[persistent=true]
setblock ~34 ~135 ~141 oak_leaves[persistent=true]
setblock ~34 ~136 ~117 oak_leaves[persistent=true]
setblock ~34 ~136 ~118 oak_leaves[persistent=true]
setblock ~34 ~136 ~119 oak_wood
setblock ~34 ~136 ~120 jungle_leaves[persistent=true]
setblock ~34 ~136 ~121 oak_leaves[persistent=true]
setblock ~34 ~136 ~129 oak_leaves[persistent=true]
setblock ~34 ~136 ~130 oak_leaves[persistent=true]
setblock ~34 ~136 ~136 oak_leaves[persistent=true]
setblock ~34 ~136 ~137 oak_leaves[persistent=true]
setblock ~34 ~136 ~138 oak_leaves[persistent=true]
setblock ~34 ~136 ~139 jungle_leaves[persistent=true]
setblock ~34 ~136 ~140 oak_leaves[persistent=true]
setblock ~34 ~136 ~141 oak_leaves[persistent=true]
setblock ~34 ~137 ~117 oak_leaves[persistent=true]
setblock ~34 ~137 ~118 jungle_leaves[persistent=true]
setblock ~34 ~137 ~119 oak_leaves[persistent=true]
setblock ~34 ~137 ~120 jungle_leaves[persistent=true]
setblock ~34 ~137 ~121 jungle_leaves[persistent=true]
setblock ~34 ~137 ~122 oak_leaves[persistent=true]
setblock ~34 ~138 ~120 oak_leaves[persistent=true]
setblock ~34 ~138 ~121 oak_leaves[persistent=true]
setblock ~34 ~138 ~122 oak_leaves[persistent=true]
setblock ~34 ~139 ~120 oak_leaves[persistent=true]
setblock ~34 ~139 ~121 oak_leaves[persistent=true]
setblock ~34 ~139 ~122 oak_leaves[persistent=true]
setblock ~35 ~116 ~97 dirt
setblock ~35 ~116 ~118 dirt
setblock ~35 ~117 ~96 dirt
setblock ~35 ~117 ~97 dirt
setblock ~35 ~117 ~98 dirt
setblock ~35 ~117 ~100 dirt
setblock ~35 ~117 ~101 dirt
setblock ~35 ~117 ~118 dirt
setblock ~35 ~117 ~119 dirt
setblock ~35 ~117 ~120 dirt
setblock ~35 ~118 ~95 dirt
setblock ~35 ~118 ~96 dirt
setblock ~35 ~118 ~97 dirt
setblock ~35 ~118 ~98 dirt
setblock ~35 ~118 ~99 dirt
setblock ~35 ~118 ~100 dirt
setblock ~35 ~118 ~101 dirt
setblock ~35 ~118 ~117 dirt
setblock ~35 ~118 ~118 dirt
setblock ~35 ~118 ~119 dirt
setblock ~35 ~118 ~120 dirt
setblock ~35 ~118 ~121 dirt
setblock ~35 ~119 ~94 dirt
setblock ~35 ~119 ~95 dirt
setblock ~35 ~119 ~96 dirt
setblock ~35 ~119 ~97 dirt
setblock ~35 ~119 ~98 dirt
setblock ~35 ~119 ~99 dirt
setblock ~35 ~119 ~100 dirt
setblock ~35 ~119 ~101 dirt
setblock ~35 ~119 ~117 dirt
setblock ~35 ~119 ~118 dirt
setblock ~35 ~119 ~119 dirt
setblock ~35 ~119 ~120 dirt
setblock ~35 ~119 ~121 dirt
setblock ~35 ~120 ~83 dirt
setblock ~35 ~120 ~93 dirt
setblock ~35 ~120 ~94 dirt
setblock ~35 ~120 ~95 dirt
setblock ~35 ~120 ~96 dirt
setblock ~35 ~120 ~97 dirt
setblock ~35 ~120 ~98 dirt
setblock ~35 ~120 ~99 dirt
setblock ~35 ~120 ~100 dirt
setblock ~35 ~120 ~101 dirt
setblock ~35 ~120 ~102 dirt
setblock ~35 ~120 ~116 dirt
setblock ~35 ~120 ~117 dirt
setblock ~35 ~120 ~118 dirt
setblock ~35 ~120 ~119 dirt
setblock ~35 ~120 ~120 dirt
setblock ~35 ~120 ~121 dirt
setblock ~35 ~121 ~83 dirt
setblock ~35 ~121 ~84 dirt
setblock ~35 ~121 ~92 dirt
setblock ~35 ~121 ~93 dirt
setblock ~35 ~121 ~94 dirt
setblock ~35 ~121 ~95 dirt
setblock ~35 ~121 ~96 dirt
setblock ~35 ~121 ~97 dirt
setblock ~35 ~121 ~98 dirt
setblock ~35 ~121 ~99 dirt
setblock ~35 ~121 ~100 dirt
setblock ~35 ~121 ~101 dirt
setblock ~35 ~121 ~102 dirt
setblock ~35 ~121 ~103 dirt
setblock ~35 ~121 ~104 dirt
setblock ~35 ~121 ~115 dirt
setblock ~35 ~121 ~116 dirt
setblock ~35 ~121 ~117 dirt
setblock ~35 ~121 ~118 dirt
setblock ~35 ~121 ~119 dirt
setblock ~35 ~121 ~120 dirt
setblock ~35 ~121 ~121 dirt
setblock ~35 ~121 ~122 dirt
setblock ~35 ~122 ~83 dirt
setblock ~35 ~122 ~84 dirt
setblock ~35 ~122 ~92 dirt
setblock ~35 ~122 ~93 dirt
setblock ~35 ~122 ~94 dirt
setblock ~35 ~122 ~95 dirt
setblock ~35 ~122 ~96 dirt
setblock ~35 ~122 ~97 dirt
setblock ~35 ~122 ~98 dirt
setblock ~35 ~122 ~99 dirt
setblock ~35 ~122 ~100 dirt
setblock ~35 ~122 ~101 dirt
setblock ~35 ~122 ~102 dirt
setblock ~35 ~122 ~103 dirt
setblock ~35 ~122 ~104 dirt
setblock ~35 ~122 ~115 dirt
setblock ~35 ~122 ~116 dirt
setblock ~35 ~122 ~117 dirt
setblock ~35 ~122 ~118 dirt
setblock ~35 ~122 ~119 dirt
setblock ~35 ~122 ~120 dirt
setblock ~35 ~122 ~121 dirt
setblock ~35 ~122 ~122 dirt
setblock ~35 ~123 ~83 dirt
setblock ~35 ~123 ~84 dirt
setblock ~35 ~123 ~92 dirt
setblock ~35 ~123 ~93 dirt
setblock ~35 ~123 ~94 dirt
setblock ~35 ~123 ~95 dirt
setblock ~35 ~123 ~96 dirt
setblock ~35 ~123 ~97 dirt
setblock ~35 ~123 ~98 dirt
setblock ~35 ~123 ~99 dirt
setblock ~35 ~123 ~100 dirt
setblock ~35 ~123 ~101 dirt
setblock ~35 ~123 ~102 dirt
setblock ~35 ~123 ~103 dirt
setblock ~35 ~123 ~104 dirt
setblock ~35 ~123 ~115 dirt
setblock ~35 ~123 ~116 dirt
setblock ~35 ~123 ~117 dirt
setblock ~35 ~123 ~118 dirt
setblock ~35 ~123 ~119 dirt
setblock ~35 ~123 ~120 dirt
setblock ~35 ~123 ~121 dirt
setblock ~35 ~123 ~122 dirt
setblock ~35 ~124 ~83 dirt
setblock ~35 ~124 ~84 dirt
setblock ~35 ~124 ~92 dirt
setblock ~35 ~124 ~93 dirt
setblock ~35 ~124 ~94 dirt
setblock ~35 ~124 ~95 dirt
setblock ~35 ~124 ~96 dirt
setblock ~35 ~124 ~97 dirt
setblock ~35 ~124 ~98 dirt
setblock ~35 ~124 ~99 dirt
setblock ~35 ~124 ~100 dirt
setblock ~35 ~124 ~101 dirt
setblock ~35 ~124 ~102 dirt
setblock ~35 ~124 ~103 dirt
setblock ~35 ~124 ~104 dirt
setblock ~35 ~124 ~115 dirt
setblock ~35 ~124 ~116 dirt
setblock ~35 ~124 ~117 dirt
setblock ~35 ~124 ~118 dirt
setblock ~35 ~124 ~119 dirt
setblock ~35 ~124 ~120 grass_block
setblock ~35 ~124 ~121 dirt
setblock ~35 ~124 ~122 dirt
setblock ~35 ~125 ~83 dirt
setblock ~35 ~125 ~84 dirt
setblock ~35 ~125 ~92 dirt
setblock ~35 ~125 ~93 dirt
setblock ~35 ~125 ~94 dirt
setblock ~35 ~125 ~95 dirt
setblock ~35 ~125 ~96 dirt
setblock ~35 ~125 ~97 dirt
setblock ~35 ~125 ~98 dirt
setblock ~35 ~125 ~99 dirt
setblock ~35 ~125 ~100 dirt
setblock ~35 ~125 ~101 dirt
setblock ~35 ~125 ~102 dirt
setblock ~35 ~125 ~103 dirt
setblock ~35 ~125 ~104 dirt
setblock ~35 ~125 ~115 dirt
setblock ~35 ~125 ~116 grass_block
setblock ~35 ~125 ~117 grass_block
setblock ~35 ~125 ~118 grass_block
setblock ~35 ~125 ~119 grass_block
setblock ~35 ~125 ~121 grass_block
setblock ~35 ~125 ~122 grass_block
setblock ~35 ~126 ~83 grass_block
setblock ~35 ~126 ~84 grass_block
setblock ~35 ~126 ~92 dirt
setblock ~35 ~126 ~93 grass_block
setblock ~35 ~126 ~94 grass_block
setblock ~35 ~126 ~95 grass_block
setblock ~35 ~126 ~96 grass_block
setblock ~35 ~126 ~97 grass_block
setblock ~35 ~126 ~98 grass_block
setblock ~35 ~126 ~99 grass_block
setblock ~35 ~126 ~100 grass_block
setblock ~35 ~126 ~101 grass_block
setblock ~35 ~126 ~102 grass_block
setblock ~35 ~126 ~103 grass_block
setblock ~35 ~126 ~104 grass_block
setblock ~35 ~126 ~115 grass_block
setblock ~35 ~126 ~118 short_grass
setblock ~35 ~126 ~119 short_grass
setblock ~35 ~127 ~83 short_grass
setblock ~35 ~127 ~92 grass_block
setblock ~35 ~127 ~94 fern
setblock ~35 ~127 ~96 short_grass
setblock ~35 ~127 ~97 short_grass
setblock ~35 ~127 ~102 fern
setblock ~35 ~127 ~115 short_grass
setblock ~35 ~129 ~129 jungle_leaves[persistent=true]
setblock ~35 ~129 ~130 oak_leaves[persistent=true]
setblock ~35 ~129 ~131 jungle_leaves[persistent=true]
setblock ~35 ~129 ~132 jungle_leaves[persistent=true]
setblock ~35 ~130 ~128 oak_leaves[persistent=true]
setblock ~35 ~130 ~129 jungle_leaves[persistent=true]
setblock ~35 ~130 ~130 oak_leaves[persistent=true]
setblock ~35 ~130 ~141 oak_leaves[persistent=true]
setblock ~35 ~130 ~142 oak_leaves[persistent=true]
setblock ~35 ~130 ~143 oak_leaves[persistent=true]
setblock ~35 ~130 ~144 oak_leaves[persistent=true]
setblock ~35 ~131 ~128 oak_leaves[persistent=true]
setblock ~35 ~131 ~129 oak_leaves[persistent=true]
setblock ~35 ~131 ~130 oak_wood
setblock ~35 ~131 ~132 oak_leaves[persistent=true]
setblock ~35 ~131 ~141 oak_leaves[persistent=true]
setblock ~35 ~131 ~142 oak_leaves[persistent=true]
setblock ~35 ~131 ~143 oak_leaves[persistent=true]
setblock ~35 ~131 ~144 jungle_leaves[persistent=true]
setblock ~35 ~132 ~128 oak_leaves[persistent=true]
setblock ~35 ~132 ~129 oak_leaves[persistent=true]
setblock ~35 ~132 ~130 oak_leaves[persistent=true]
setblock ~35 ~132 ~131 oak_leaves[persistent=true]
setblock ~35 ~132 ~141 oak_leaves[persistent=true]
setblock ~35 ~132 ~142 oak_leaves[persistent=true]
setblock ~35 ~132 ~143 oak_leaves[persistent=true]
setblock ~35 ~132 ~144 oak_leaves[persistent=true]
setblock ~35 ~133 ~123 oak_leaves[persistent=true]
setblock ~35 ~133 ~124 oak_leaves[persistent=true]
setblock ~35 ~133 ~125 oak_leaves[persistent=true]
setblock ~35 ~133 ~128 oak_leaves[persistent=true]
setblock ~35 ~133 ~130 jungle_leaves[persistent=true]
setblock ~35 ~133 ~131 oak_leaves[persistent=true]
setblock ~35 ~133 ~132 jungle_leaves[persistent=true]
setblock ~35 ~133 ~135 oak_leaves[persistent=true]
setblock ~35 ~133 ~136 jungle_leaves[persistent=true]
setblock ~35 ~133 ~138 oak_leaves[persistent=true]
setblock ~35 ~133 ~139 oak_leaves[persistent=true]
setblock ~35 ~133 ~140 oak_leaves[persistent=true]
setblock ~35 ~133 ~141 oak_leaves[persistent=true]
setblock ~35 ~133 ~142 oak_leaves[persistent=true]
setblock ~35 ~133 ~143 oak_leaves[persistent=true]
setblock ~35 ~133 ~144 jungle_leaves[persistent=true]
setblock ~35 ~134 ~119 jungle_leaves[persistent=true]
setblock ~35 ~134 ~120 jungle_leaves[persistent=true]
setblock ~35 ~134 ~121 jungle_leaves[persistent=true]
setblock ~35 ~134 ~122 oak_leaves[persistent=true]
setblock ~35 ~134 ~125 oak_leaves[persistent=true]
setblock ~35 ~134 ~129 oak_leaves[persistent=true]
setblock ~35 ~134 ~130 jungle_leaves[persistent=true]
setblock ~35 ~134 ~131 jungle_leaves[persistent=true]
setblock ~35 ~134 ~132 oak_leaves[persistent=true]
setblock ~35 ~134 ~135 jungle_leaves[persistent=true]
setblock ~35 ~134 ~136 oak_leaves[persistent=true]
setblock ~35 ~134 ~137 jungle_leaves[persistent=true]
setblock ~35 ~134 ~138 oak_leaves[persistent=true]
setblock ~35 ~134 ~139 oak_leaves[persistent=true]
setblock ~35 ~134 ~140 oak_leaves[persistent=true]
setblock ~35 ~135 ~119 oak_leaves[persistent=true]
setblock ~35 ~135 ~120 jungle_leaves[persistent=true]
setblock ~35 ~135 ~121 oak_leaves[persistent=true]
setblock ~35 ~135 ~122 oak_leaves[persistent=true]
setblock ~35 ~135 ~123 oak_leaves[persistent=true]
setblock ~35 ~135 ~124 jungle_leaves[persistent=true]
setblock ~35 ~135 ~125 oak_leaves[persistent=true]
setblock ~35 ~135 ~126 oak_leaves[persistent=true]
setblock ~35 ~135 ~127 oak_leaves[persistent=true]
setblock ~35 ~135 ~128 oak_leaves[persistent=true]
setblock ~35 ~135 ~129 oak_leaves[persistent=true]
setblock ~35 ~135 ~130 oak_leaves[persistent=true]
setblock ~35 ~135 ~131 oak_leaves[persistent=true]
setblock ~35 ~135 ~135 oak_leaves[persistent=true]
setblock ~35 ~135 ~136 oak_leaves[persistent=true]
setblock ~35 ~135 ~137 jungle_leaves[persistent=true]
setblock ~35 ~135 ~138 oak_leaves[persistent=true]
setblock ~35 ~135 ~139 jungle_leaves[persistent=true]
setblock ~35 ~135 ~140 oak_leaves[persistent=true]
setblock ~35 ~135 ~141 oak_leaves[persistent=true]
setblock ~35 ~136 ~118 oak_leaves[persistent=true]
setblock ~35 ~136 ~119 oak_leaves[persistent=true]
setblock ~35 ~136 ~120 oak_wood
setblock ~35 ~136 ~121 oak_leaves[persistent=true]
setblock ~35 ~136 ~122 oak_leaves[persistent=true]
setblock ~35 ~136 ~123 oak_leaves[persistent=true]
setblock ~35 ~136 ~124 oak_leaves[persistent=true]
setblock ~35 ~136 ~125 jungle_leaves[persistent=true]
setblock ~35 ~136 ~126 oak_leaves[persistent=true]
setblock ~35 ~136 ~127 oak_leaves[persistent=true]
setblock ~35 ~136 ~128 jungle_leaves[persistent=true]
setblock ~35 ~136 ~129 oak_leaves[persistent=true]
setblock ~35 ~136 ~130 oak_leaves[persistent=true]
setblock ~35 ~136 ~131 oak_leaves[persistent=true]
setblock ~35 ~136 ~135 oak_leaves[persistent=true]
setblock ~35 ~136 ~136 oak_leaves[persistent=true]
setblock ~35 ~136 ~138 oak_leaves[persistent=true]
setblock ~35 ~136 ~139 jungle_leaves[persistent=true]
setblock ~35 ~136 ~140 oak_leaves[persistent=true]
setblock ~35 ~136 ~141 jungle_leaves[persistent=true]
setblock ~35 ~137 ~118 oak_leaves[persistent=true]
setblock ~35 ~137 ~119 oak_leaves[persistent=true]
setblock ~35 ~137 ~120 oak_leaves[persistent=true]
setblock ~35 ~137 ~121 oak_wood
setblock ~35 ~137 ~122 oak_leaves[persistent=true]
setblock ~35 ~137 ~123 jungle_leaves[persistent=true]
setblock ~35 ~137 ~124 oak_leaves[persistent=true]
setblock ~35 ~137 ~125 oak_leaves[persistent=true]
setblock ~35 ~137 ~126 oak_leaves[persistent=true]
setblock ~35 ~137 ~127 jungle_leaves[persistent=true]
setblock ~35 ~137 ~129 jungle_leaves[persistent=true]
setblock ~35 ~138 ~120 oak_leaves[persistent=true]
setblock ~35 ~138 ~121 oak_leaves[persistent=true]
setblock ~35 ~138 ~122 oak_leaves[persistent=true]
setblock ~35 ~138 ~123 oak_leaves[persistent=true]
setblock ~35 ~138 ~124 oak_leaves[persistent=true]
setblock ~35 ~138 ~125 oak_leaves[persistent=true]
setblock ~35 ~138 ~126 jungle_leaves[persistent=true]
setblock ~35 ~138 ~127 oak_leaves[persistent=true]
setblock ~35 ~138 ~128 oak_leaves[persistent=true]
setblock ~35 ~138 ~129 oak_leaves[persistent=true]
setblock ~35 ~139 ~120 oak_leaves[persistent=true]
setblock ~35 ~139 ~121 oak_leaves[persistent=true]
setblock ~35 ~139 ~122 oak_leaves[persistent=true]
setblock ~35 ~139 ~123 oak_leaves[persistent=true]
setblock ~35 ~139 ~125 jungle_leaves[persistent=true]
setblock ~36 ~115 ~97 dirt
setblock ~36 ~115 ~99 dirt
setblock ~36 ~115 ~100 dirt
setblock ~36 ~115 ~101 dirt
setblock ~36 ~115 ~118 dirt
setblock ~36 ~115 ~120 dirt
setblock ~36 ~116 ~95 dirt
setblock ~36 ~116 ~96 dirt
setblock ~36 ~116 ~97 dirt
setblock ~36 ~116 ~98 dirt
setblock ~36 ~116 ~99 dirt
setblock ~36 ~116 ~100 dirt
setblock ~36 ~116 ~101 dirt
setblock ~36 ~116 ~117 dirt
setblock ~36 ~116 ~118 dirt
setblock ~36 ~116 ~119 dirt
setblock ~36 ~116 ~120 dirt
setblock ~36 ~117 ~94 dirt
setblock ~36 ~117 ~95 dirt
setblock ~36 ~117 ~96 dirt
setblock ~36 ~117 ~97 dirt
setblock ~36 ~117 ~98 dirt
setblock ~36 ~117 ~99 dirt
setblock ~36 ~117 ~100 dirt
setblock ~36 ~117 ~101 dirt
setblock ~36 ~117 ~102 dirt
setblock ~36 ~117 ~117 dirt
setblock ~36 ~117 ~118 dirt
setblock ~36 ~117 ~119 dirt
setblock ~36 ~117 ~120 dirt
setblock ~36 ~117 ~121 dirt
setblock ~36 ~118 ~83 dirt
setblock ~36 ~118 ~94 dirt
setblock ~36 ~118 ~95 dirt
setblock ~36 ~118 ~96 dirt
setblock ~36 ~118 ~97 dirt
setblock ~36 ~118 ~98 dirt
setblock ~36 ~118 ~99 dirt
setblock ~36 ~118 ~100 dirt
setblock ~36 ~118 ~101 dirt
setblock ~36 ~118 ~102 dirt
setblock ~36 ~118 ~116 dirt
setblock ~36 ~118 ~117 dirt
setblock ~36 ~118 ~118 dirt
setblock ~36 ~118 ~119 dirt
setblock ~36 ~118 ~120 dirt
setblock ~36 ~118 ~121 dirt
setblock ~36 ~118 ~122 dirt
setblock ~36 ~119 ~82 dirt
setblock ~36 ~119 ~83 dirt
setblock ~36 ~119 ~93 dirt
setblock ~36 ~119 ~94 dirt
setblock ~36 ~119 ~95 dirt
setblock ~36 ~119 ~96 dirt
setblock ~36 ~119 ~97 dirt
setblock ~36 ~119 ~98 dirt
setblock ~36 ~119 ~99 dirt
setblock ~36 ~119 ~100 dirt
setblock ~36 ~119 ~101 dirt
setblock ~36 ~119 ~102 dirt
setblock ~36 ~119 ~104 dirt
setblock ~36 ~119 ~115 dirt
setblock ~36 ~119 ~116 dirt
setblock ~36 ~119 ~117 dirt
setblock ~36 ~119 ~118 dirt
setblock ~36 ~119 ~119 dirt
setblock ~36 ~119 ~120 dirt
setblock ~36 ~119 ~121 dirt
setblock ~36 ~119 ~122 dirt
setblock ~36 ~119 ~123 dirt
setblock ~36 ~120 ~78 dirt
setblock ~36 ~120 ~81 dirt
setblock ~36 ~120 ~82 dirt
setblock ~36 ~120 ~83 dirt
setblock ~36 ~120 ~84 dirt
setblock ~36 ~120 ~92 dirt
setblock ~36 ~120 ~93 dirt
setblock ~36 ~120 ~94 dirt
setblock ~36 ~120 ~95 dirt
setblock ~36 ~120 ~96 dirt
setblock ~36 ~120 ~97 dirt
setblock ~36 ~120 ~98 dirt
setblock ~36 ~120 ~99 dirt
setblock ~36 ~120 ~100 dirt
setblock ~36 ~120 ~101 dirt
setblock ~36 ~120 ~102 dirt
setblock ~36 ~120 ~103 dirt
setblock ~36 ~120 ~104 dirt
setblock ~36 ~120 ~105 dirt
setblock ~36 ~120 ~106 dirt
setblock ~36 ~120 ~115 dirt
setblock ~36 ~120 ~116 dirt
setblock ~36 ~120 ~117 dirt
setblock ~36 ~120 ~118 dirt
setblock ~36 ~120 ~119 dirt
setblock ~36 ~120 ~120 dirt
setblock ~36 ~120 ~121 dirt
setblock ~36 ~120 ~122 dirt
setblock ~36 ~120 ~123 dirt
setblock ~36 ~121 ~77 dirt
setblock ~36 ~121 ~78 dirt
setblock ~36 ~121 ~79 dirt
setblock ~36 ~121 ~80 dirt
setblock ~36 ~121 ~81 dirt
setblock ~36 ~121 ~82 dirt
setblock ~36 ~121 ~83 dirt
setblock ~36 ~121 ~84 dirt
setblock ~36 ~121 ~85 dirt
setblock ~36 ~121 ~91 dirt
setblock ~36 ~121 ~92 dirt
setblock ~36 ~121 ~93 dirt
setblock ~36 ~121 ~94 dirt
setblock ~36 ~121 ~95 dirt
setblock ~36 ~121 ~96 dirt
setblock ~36 ~121 ~97 dirt
setblock ~36 ~121 ~98 dirt
setblock ~36 ~121 ~99 dirt
setblock ~36 ~121 ~100 dirt
setblock ~36 ~121 ~101 dirt
setblock ~36 ~121 ~102 dirt
setblock ~36 ~121 ~103 dirt
setblock ~36 ~121 ~104 dirt
setblock ~36 ~121 ~105 dirt
setblock ~36 ~121 ~106 dirt
setblock ~36 ~121 ~107 dirt
setblock ~36 ~121 ~108 dirt
setblock ~36 ~121 ~111 dirt
setblock ~36 ~121 ~113 dirt
setblock ~36 ~121 ~114 dirt
setblock ~36 ~121 ~115 dirt
setblock ~36 ~121 ~116 dirt
setblock ~36 ~121 ~117 dirt
setblock ~36 ~121 ~118 dirt
setblock ~36 ~121 ~119 dirt
setblock ~36 ~121 ~120 dirt
setblock ~36 ~121 ~121 dirt
setblock ~36 ~121 ~122 dirt
setblock ~36 ~121 ~123 dirt
setblock ~36 ~122 ~77 dirt
setblock ~36 ~122 ~78 dirt
setblock ~36 ~122 ~79 dirt
setblock ~36 ~122 ~80 dirt
setblock ~36 ~122 ~81 dirt
setblock ~36 ~122 ~82 dirt
setblock ~36 ~122 ~83 dirt
setblock ~36 ~122 ~84 dirt
setblock ~36 ~122 ~85 dirt
setblock ~36 ~122 ~91 dirt
setblock ~36 ~122 ~92 dirt
setblock ~36 ~122 ~93 dirt
setblock ~36 ~122 ~94 dirt
setblock ~36 ~122 ~95 dirt
setblock ~36 ~122 ~96 dirt
setblock ~36 ~122 ~97 dirt
setblock ~36 ~122 ~98 dirt
setblock ~36 ~122 ~99 dirt
setblock ~36 ~122 ~100 dirt
setblock ~36 ~122 ~101 dirt
setblock ~36 ~122 ~102 dirt
setblock ~36 ~122 ~103 dirt
setblock ~36 ~122 ~104 dirt
setblock ~36 ~122 ~105 dirt
setblock ~36 ~122 ~106 dirt
setblock ~36 ~122 ~107 dirt
setblock ~36 ~122 ~108 dirt
setblock ~36 ~122 ~111 dirt
setblock ~36 ~122 ~113 dirt
setblock ~36 ~122 ~114 dirt
setblock ~36 ~122 ~115 dirt
setblock ~36 ~122 ~116 dirt
setblock ~36 ~122 ~117 dirt
setblock ~36 ~122 ~118 dirt
setblock ~36 ~122 ~119 dirt
setblock ~36 ~122 ~120 dirt
setblock ~36 ~122 ~121 dirt
setblock ~36 ~122 ~122 dirt
setblock ~36 ~122 ~123 dirt
setblock ~36 ~123 ~77 dirt
setblock ~36 ~123 ~78 dirt
setblock ~36 ~123 ~79 dirt
setblock ~36 ~123 ~80 dirt
setblock ~36 ~123 ~81 dirt
setblock ~36 ~123 ~82 dirt
setblock ~36 ~123 ~83 dirt
setblock ~36 ~123 ~84 dirt
setblock ~36 ~123 ~85 dirt
setblock ~36 ~123 ~91 dirt
setblock ~36 ~123 ~92 dirt
setblock ~36 ~123 ~93 dirt
setblock ~36 ~123 ~94 dirt
setblock ~36 ~123 ~95 dirt
setblock ~36 ~123 ~96 dirt
setblock ~36 ~123 ~97 dirt
setblock ~36 ~123 ~98 dirt
setblock ~36 ~123 ~99 dirt
setblock ~36 ~123 ~100 dirt
setblock ~36 ~123 ~101 dirt
setblock ~36 ~123 ~102 dirt
setblock ~36 ~123 ~103 dirt
setblock ~36 ~123 ~104 dirt
setblock ~36 ~123 ~105 dirt
setblock ~36 ~123 ~106 dirt
setblock ~36 ~123 ~107 dirt
setblock ~36 ~123 ~108 dirt
setblock ~36 ~123 ~111 dirt
setblock ~36 ~123 ~113 dirt
setblock ~36 ~123 ~114 dirt
setblock ~36 ~123 ~115 dirt
setblock ~36 ~123 ~116 dirt
setblock ~36 ~123 ~117 dirt
setblock ~36 ~123 ~118 dirt
setblock ~36 ~123 ~119 dirt
setblock ~36 ~123 ~120 dirt
setblock ~36 ~123 ~121 dirt
setblock ~36 ~123 ~122 dirt
setblock ~36 ~123 ~123 dirt
setblock ~36 ~124 ~77 dirt
setblock ~36 ~124 ~78 dirt
setblock ~36 ~124 ~79 dirt
setblock ~36 ~124 ~80 dirt
setblock ~36 ~124 ~81 dirt
setblock ~36 ~124 ~82 dirt
setblock ~36 ~124 ~83 dirt
setblock ~36 ~124 ~84 dirt
setblock ~36 ~124 ~85 dirt
setblock ~36 ~124 ~91 dirt
setblock ~36 ~124 ~92 dirt
setblock ~36 ~124 ~93 dirt
setblock ~36 ~124 ~94 dirt
setblock ~36 ~124 ~95 dirt
setblock ~36 ~124 ~96 dirt
setblock ~36 ~124 ~97 dirt
setblock ~36 ~124 ~98 dirt
setblock ~36 ~124 ~99 dirt
setblock ~36 ~124 ~100 dirt
setblock ~36 ~124 ~101 dirt
setblock ~36 ~124 ~102 dirt
setblock ~36 ~124 ~103 dirt
setblock ~36 ~124 ~104 dirt
setblock ~36 ~124 ~105 dirt
setblock ~36 ~124 ~106 dirt
setblock ~36 ~124 ~107 dirt
setblock ~36 ~124 ~108 dirt
setblock ~36 ~124 ~111 dirt
setblock ~36 ~124 ~113 dirt
setblock ~36 ~124 ~114 dirt
setblock ~36 ~124 ~115 dirt
setblock ~36 ~124 ~116 dirt
setblock ~36 ~124 ~117 dirt
setblock ~36 ~124 ~118 dirt
setblock ~36 ~124 ~119 grass_block
setblock ~36 ~124 ~120 grass_block
setblock ~36 ~124 ~121 grass_block
setblock ~36 ~124 ~122 dirt
setblock ~36 ~124 ~123 dirt
setblock ~36 ~125 ~77 dirt
setblock ~36 ~125 ~78 dirt
setblock ~36 ~125 ~79 dirt
setblock ~36 ~125 ~80 dirt
setblock ~36 ~125 ~81 dirt
setblock ~36 ~125 ~82 dirt
setblock ~36 ~125 ~83 dirt
setblock ~36 ~125 ~84 dirt
setblock ~36 ~125 ~85 dirt
setblock ~36 ~125 ~91 dirt
setblock ~36 ~125 ~92 dirt
setblock ~36 ~125 ~93 dirt
setblock ~36 ~125 ~94 dirt
setblock ~36 ~125 ~95 dirt
setblock ~36 ~125 ~96 dirt
setblock ~36 ~125 ~97 dirt
setblock ~36 ~125 ~98 dirt
setblock ~36 ~125 ~99 dirt
setblock ~36 ~125 ~100 dirt
setblock ~36 ~125 ~101 dirt
setblock ~36 ~125 ~102 dirt
setblock ~36 ~125 ~103 dirt
setblock ~36 ~125 ~104 dirt
setblock ~36 ~125 ~105 dirt
setblock ~36 ~125 ~106 dirt
setblock ~36 ~125 ~107 dirt
setblock ~36 ~125 ~108 dirt
setblock ~36 ~125 ~111 dirt
setblock ~36 ~125 ~113 dirt
setblock ~36 ~125 ~114 dirt
setblock ~36 ~125 ~115 grass_block
setblock ~36 ~125 ~116 grass_block
setblock ~36 ~125 ~117 grass_block
setblock ~36 ~125 ~118 grass_block
setblock ~36 ~125 ~120 short_grass
setblock ~36 ~125 ~122 grass_block
setblock ~36 ~125 ~123 grass_block
setblock ~36 ~126 ~77 grass_block
setblock ~36 ~126 ~78 grass_block
setblock ~36 ~126 ~79 grass_block
setblock ~36 ~126 ~80 grass_block
setblock ~36 ~126 ~81 grass_block
setblock ~36 ~126 ~82 grass_block
setblock ~36 ~126 ~83 grass_block
setblock ~36 ~126 ~84 dirt
setblock ~36 ~126 ~85 dirt
setblock ~36 ~126 ~91 dirt
setblock ~36 ~126 ~92 dirt
setblock ~36 ~126 ~93 dirt
setblock ~36 ~126 ~94 dirt
setblock ~36 ~126 ~95 dirt
setblock ~36 ~126 ~96 dirt
setblock ~36 ~126 ~97 grass_block
setblock ~36 ~126 ~98 grass_block
setblock ~36 ~126 ~99 grass_block
setblock ~36 ~126 ~100 grass_block
setblock ~36 ~126 ~101 grass_block
setblock ~36 ~126 ~102 grass_block
setblock ~36 ~126 ~103 grass_block
setblock ~36 ~126 ~104 grass_block
setblock ~36 ~126 ~105 grass_block
setblock ~36 ~126 ~106 dirt
setblock ~36 ~126 ~107 dirt
setblock ~36 ~126 ~108 dirt
setblock ~36 ~126 ~111 dirt
setblock ~36 ~126 ~113 grass_block
setblock ~36 ~126 ~114 grass_block
setblock ~36 ~126 ~115 short_grass
setblock ~36 ~126 ~123 short_grass
setblock ~36 ~127 ~78 short_grass
setblock ~36 ~127 ~83 short_grass
setblock ~36 ~127 ~84 grass_block
setblock ~36 ~127 ~85 grass_block
setblock ~36 ~127 ~91 grass_block
setblock ~36 ~127 ~92 grass_block
setblock ~36 ~127 ~93 grass_block
setblock ~36 ~127 ~94 grass_block
setblock ~36 ~127 ~95 grass_block
setblock ~36 ~127 ~96 grass_block
setblock ~36 ~127 ~97 poppy
setblock ~36 ~127 ~99 short_grass
setblock ~36 ~127 ~106 grass_block
setblock ~36 ~127 ~107 grass_block
setblock ~36 ~127 ~108 grass_block
setblock ~36 ~127 ~111 grass_block
setblock ~36 ~127 ~113 short_grass
setblock ~36 ~128 ~84 short_grass
setblock ~36 ~128 ~85 short_grass
setblock ~36 ~128 ~92 poppy
setblock ~36 ~128 ~96 short_grass
setblock ~36 ~130 ~128 oak_leaves[persistent=true]
setblock ~36 ~130 ~129 oak_leaves[persistent=true]
setblock ~36 ~130 ~130 oak_leaves[persistent=true]
setblock ~36 ~130 ~131 oak_leaves[persistent=true]
setblock ~36 ~130 ~141 oak_leaves[persistent=true]
setblock ~36 ~130 ~143 jungle_leaves[persistent=true]
setblock ~36 ~130 ~144 oak_leaves[persistent=true]
setblock ~36 ~131 ~127 jungle_leaves[persistent=true]
setblock ~36 ~131 ~129 oak_leaves[persistent=true]
setblock ~36 ~131 ~130 oak_leaves[persistent=true]
setblock ~36 ~131 ~131 oak_leaves[persistent=true]
setblock ~36 ~131 ~141 oak_leaves[persistent=true]
setblock ~36 ~131 ~142 oak_leaves[persistent=true]
setblock ~36 ~131 ~143 oak_leaves[persistent=true]
setblock ~36 ~131 ~144 oak_leaves[persistent=true]
setblock ~36 ~132 ~122 jungle_leaves[persistent=true]
setblock ~36 ~132 ~123 oak_leaves[persistent=true]
setblock ~36 ~132 ~124 jungle_leaves[persistent=true]
setblock ~36 ~132 ~125 oak_leaves[persistent=true]
setblock ~36 ~132 ~127 jungle_leaves[persistent=true]
setblock ~36 ~132 ~129 oak_wood
setblock ~36 ~132 ~130 oak_wood
setblock ~36 ~132 ~131 jungle_leaves[persistent=true]
setblock ~36 ~132 ~140 oak_leaves[persistent=true]
setblock ~36 ~132 ~142 oak_leaves[persistent=true]
setblock ~36 ~132 ~144 jungle_leaves[persistent=true]
setblock ~36 ~133 ~122 oak_leaves[persistent=true]
setblock ~36 ~133 ~123 oak_leaves[persistent=true]
setblock ~36 ~133 ~124 jungle_leaves[persistent=true]
setblock ~36 ~133 ~125 oak_leaves[persistent=true]
setblock ~36 ~133 ~127 oak_leaves[persistent=true]
setblock ~36 ~133 ~128 oak_leaves[persistent=true]
setblock ~36 ~133 ~130 jungle_leaves[persistent=true]
setblock ~36 ~133 ~131 oak_leaves[persistent=true]
setblock ~36 ~133 ~132 oak_leaves[persistent=true]
setblock ~36 ~133 ~133 oak_leaves[persistent=true]
setblock ~36 ~133 ~135 oak_leaves[persistent=true]
setblock ~36 ~133 ~136 oak_leaves[persistent=true]
setblock ~36 ~133 ~138 oak_leaves[persistent=true]
setblock ~36 ~133 ~139 oak_leaves[persistent=true]
setblock ~36 ~133 ~140 oak_leaves[persistent=true]
setblock ~36 ~133 ~141 oak_leaves[persistent=true]
setblock ~36 ~133 ~142 jungle_leaves[persistent=true]
setblock ~36 ~133 ~143 oak_leaves[persistent=true]
setblock ~36 ~133 ~144 oak_leaves[persistent=true]
setblock ~36 ~134 ~116 oak_leaves[persistent=true]
setblock ~36 ~134 ~117 oak_leaves[persistent=true]
setblock ~36 ~134 ~118 oak_leaves[persistent=true]
setblock ~36 ~134 ~119 oak_leaves[persistent=true]
setblock ~36 ~134 ~120 oak_leaves[persistent=true]
setblock ~36 ~134 ~121 oak_leaves[persistent=true]
setblock ~36 ~134 ~122 jungle_leaves[persistent=true]
setblock ~36 ~134 ~123 oak_leaves[persistent=true]
setblock ~36 ~134 ~124 oak_wood
setblock ~36 ~134 ~125 oak_leaves[persistent=true]
setblock ~36 ~134 ~129 oak_leaves[persistent=true]
setblock ~36 ~134 ~130 oak_leaves[persistent=true]
setblock ~36 ~134 ~131 oak_leaves[persistent=true]
setblock ~36 ~134 ~132 oak_leaves[persistent=true]
setblock ~36 ~134 ~133 oak_leaves[persistent=true]
setblock ~36 ~134 ~136 jungle_leaves[persistent=true]
setblock ~36 ~134 ~137 oak_leaves[persistent=true]
setblock ~36 ~134 ~138 jungle_leaves[persistent=true]
setblock ~36 ~134 ~139 jungle_leaves[persistent=true]
setblock ~36 ~134 ~142 oak_leaves[persistent=true]
setblock ~36 ~134 ~143 oak_leaves[persistent=true]
setblock ~36 ~135 ~114 oak_leaves[persistent=true]
setblock ~36 ~135 ~115 oak_leaves[persistent=true]
setblock ~36 ~135 ~117 oak_leaves[persistent=true]
setblock ~36 ~135 ~118 oak_leaves[persistent=true]
setblock ~36 ~135 ~119 oak_leaves[persistent=true]
setblock ~36 ~135 ~120 oak_leaves[persistent=true]
setblock ~36 ~135 ~122 jungle_leaves[persistent=true]
setblock ~36 ~135 ~123 oak_leaves[persistent=true]
setblock ~36 ~135 ~124 oak_leaves[persistent=true]
setblock ~36 ~135 ~125 oak_leaves[persistent=true]
setblock ~36 ~135 ~126 oak_leaves[persistent=true]
setblock ~36 ~135 ~127 oak_leaves[persistent=true]
setblock ~36 ~135 ~128 oak_leaves[persistent=true]
setblock ~36 ~135 ~129 oak_leaves[persistent=true]
setblock ~36 ~135 ~130 oak_wood
setblock ~36 ~135 ~132 oak_leaves[persistent=true]
setblock ~36 ~135 ~133 oak_leaves[persistent=true]
setblock ~36 ~135 ~134 oak_leaves[persistent=true]
setblock ~36 ~135 ~135 jungle_leaves[persistent=true]
setblock ~36 ~135 ~136 oak_leaves[persistent=true]
setblock ~36 ~135 ~137 oak_leaves[persistent=true]
setblock ~36 ~135 ~138 oak_wood
setblock ~36 ~135 ~139 oak_wood
setblock ~36 ~135 ~140 jungle_leaves[persistent=true]
setblock ~36 ~135 ~141 oak_leaves[persistent=true]
setblock ~36 ~136 ~114 oak_leaves[persistent=true]
setblock ~36 ~136 ~115 oak_leaves[persistent=true]
setblock ~36 ~136 ~116 oak_leaves[persistent=true]
setblock ~36 ~136 ~117 oak_leaves[persistent=true]
setblock ~36 ~136 ~118 jungle_leaves[persistent=true]
setblock ~36 ~136 ~119 jungle_leaves[persistent=true]
setblock ~36 ~136 ~120 oak_wood
setblock ~36 ~136 ~121 oak_leaves[persistent=true]
setblock ~36 ~136 ~122 oak_leaves[persistent=true]
setblock ~36 ~136 ~123 oak_leaves[persistent=true]
setblock ~36 ~136 ~124 oak_leaves[persistent=true]
setblock ~36 ~136 ~125 oak_leaves[persistent=true]
setblock ~36 ~136 ~126 jungle_leaves[persistent=true]
setblock ~36 ~136 ~128 oak_leaves[persistent=true]
setblock ~36 ~136 ~129 oak_leaves[persistent=true]
setblock ~36 ~136 ~130 oak_leaves[persistent=true]
setblock ~36 ~136 ~131 oak_leaves[persistent=true]
setblock ~36 ~136 ~132 oak_leaves[persistent=true]
setblock ~36 ~136 ~133 oak_leaves[persistent=true]
setblock ~36 ~136 ~134 jungle_leaves[persistent=true]
setblock ~36 ~136 ~135 oak_leaves[persistent=true]
setblock ~36 ~136 ~136 jungle_leaves[persistent=true]
setblock ~36 ~136 ~138 oak_leaves[persistent=true]
setblock ~36 ~136 ~139 oak_leaves[persistent=true]
setblock ~36 ~136 ~140 oak_leaves[persistent=true]
setblock ~36 ~136 ~141 oak_leaves[persistent=true]
setblock ~36 ~137 ~116 oak_leaves[persistent=true]
setblock ~36 ~137 ~117 oak_leaves[persistent=true]
setblock ~36 ~137 ~118 oak_leaves[persistent=true]
setblock ~36 ~137 ~119 oak_leaves[persistent=true]
setblock ~36 ~137 ~120 oak_leaves[persistent=true]
setblock ~36 ~137 ~121 jungle_leaves[persistent=true]
setblock ~36 ~137 ~122 oak_wood
setblock ~36 ~137 ~123 jungle_leaves[persistent=true]
setblock ~36 ~137 ~124 oak_leaves[persistent=true]
setblock ~36 ~137 ~125 jungle_leaves[persistent=true]
setblock ~36 ~137 ~126 jungle_leaves[persistent=true]
setblock ~36 ~137 ~127 oak_leaves[persistent=true]
setblock ~36 ~137 ~128 oak_leaves[persistent=true]
setblock ~36 ~137 ~129 jungle_leaves[persistent=true]
setblock ~36 ~137 ~130 jungle_leaves[persistent=true]
setblock ~36 ~137 ~131 oak_leaves[persistent=true]
setblock ~36 ~137 ~132 oak_leaves[persistent=true]
setblock ~36 ~137 ~133 oak_leaves[persistent=true]
setblock ~36 ~137 ~135 oak_leaves[persistent=true]
setblock ~36 ~138 ~121 oak_leaves[persistent=true]
setblock ~36 ~138 ~122 oak_leaves[persistent=true]
setblock ~36 ~138 ~123 oak_leaves[persistent=true]
setblock ~36 ~138 ~124 oak_leaves[persistent=true]
setblock ~36 ~138 ~126 oak_leaves[persistent=true]
setblock ~36 ~138 ~127 oak_leaves[persistent=true]
setblock ~36 ~138 ~128 oak_leaves[persistent=true]
setblock ~36 ~138 ~130 oak_leaves[persistent=true]
setblock ~36 ~138 ~131 jungle_leaves[persistent=true]
setblock ~36 ~138 ~132 oak_leaves[persistent=true]
setblock ~36 ~138 ~133 oak_leaves[persistent=true]
setblock ~36 ~138 ~134 oak_leaves[persistent=true]
setblock ~36 ~138 ~135 jungle_leaves[persistent=true]
setblock ~36 ~139 ~121 oak_leaves[persistent=true]
setblock ~36 ~139 ~122 oak_leaves[persistent=true]
setblock ~36 ~139 ~123 oak_leaves[persistent=true]
setblock ~36 ~139 ~124 oak_leaves[persistent=true]
setblock ~36 ~139 ~125 jungle_leaves[persistent=true]
setblock ~36 ~139 ~130 oak_leaves[persistent=true]
setblock ~36 ~139 ~131 oak_leaves[persistent=true]
setblock ~36 ~139 ~132 jungle_leaves[persistent=true]
setblock ~36 ~139 ~133 jungle_leaves[persistent=true]
setblock ~36 ~139 ~135 oak_leaves[persistent=true]
setblock ~36 ~140 ~130 oak_leaves[persistent=true]
setblock ~36 ~140 ~131 oak_leaves[persistent=true]
setblock ~36 ~140 ~132 oak_leaves[persistent=true]
setblock ~36 ~140 ~133 oak_leaves[persistent=true]
setblock ~36 ~140 ~134 oak_leaves[persistent=true]
setblock ~36 ~140 ~135 jungle_leaves[persistent=true]
setblock ~37 ~112 ~95 dirt
setblock ~37 ~112 ~98 dirt
setblock ~37 ~112 ~119 dirt
setblock ~37 ~113 ~95 dirt
setblock ~37 ~113 ~96 dirt
setblock ~37 ~113 ~97 dirt
setblock ~37 ~113 ~98 dirt
setblock ~37 ~113 ~99 dirt
setblock ~37 ~113 ~100 dirt
setblock ~37 ~113 ~119 dirt
setblock ~37 ~113 ~120 dirt
setblock ~37 ~114 ~94 dirt
setblock ~37 ~114 ~95 dirt
setblock ~37 ~114 ~96 dirt
setblock ~37 ~114 ~97 dirt
setblock ~37 ~114 ~98 dirt
setblock ~37 ~114 ~99 dirt
setblock ~37 ~114 ~100 dirt
setblock ~37 ~114 ~101 dirt
setblock ~37 ~114 ~118 dirt
setblock ~37 ~114 ~119 dirt
setblock ~37 ~114 ~120 dirt
setblock ~37 ~115 ~94 dirt
setblock ~37 ~115 ~95 dirt
setblock ~37 ~115 ~96 dirt
setblock ~37 ~115 ~97 dirt
setblock ~37 ~115 ~98 dirt
setblock ~37 ~115 ~99 dirt
setblock ~37 ~115 ~100 dirt
setblock ~37 ~115 ~101 dirt
setblock ~37 ~115 ~102 dirt
setblock ~37 ~115 ~117 dirt
setblock ~37 ~115 ~118 dirt
setblock ~37 ~115 ~119 dirt
setblock ~37 ~115 ~120 dirt
setblock ~37 ~115 ~121 dirt
setblock ~37 ~116 ~83 dirt
setblock ~37 ~116 ~93 dirt
setblock ~37 ~116 ~94 dirt
setblock ~37 ~116 ~95 dirt
setblock ~37 ~116 ~96 dirt
setblock ~37 ~116 ~97 dirt
setblock ~37 ~116 ~98 dirt
setblock ~37 ~116 ~99 dirt
setblock ~37 ~116 ~100 dirt
setblock ~37 ~116 ~101 dirt
setblock ~37 ~116 ~102 dirt
setblock ~37 ~116 ~105 dirt
setblock ~37 ~116 ~117 dirt
setblock ~37 ~116 ~118 dirt
setblock ~37 ~116 ~119 dirt
setblock ~37 ~116 ~120 dirt
setblock ~37 ~116 ~121 dirt
setblock ~37 ~117 ~83 dirt
setblock ~37 ~117 ~93 dirt
setblock ~37 ~117 ~94 dirt
setblock ~37 ~117 ~95 dirt
setblock ~37 ~117 ~96 dirt
setblock ~37 ~117 ~97 dirt
setblock ~37 ~117 ~98 dirt
setblock ~37 ~117 ~99 dirt
setblock ~37 ~117 ~100 dirt
setblock ~37 ~117 ~101 dirt
setblock ~37 ~117 ~102 dirt
setblock ~37 ~117 ~103 dirt
setblock ~37 ~117 ~104 dirt
setblock ~37 ~117 ~105 dirt
setblock ~37 ~117 ~115 dirt
setblock ~37 ~117 ~116 dirt
setblock ~37 ~117 ~117 dirt
setblock ~37 ~117 ~118 dirt
setblock ~37 ~117 ~119 dirt
setblock ~37 ~117 ~120 dirt
setblock ~37 ~117 ~121 dirt
setblock ~37 ~117 ~122 dirt
setblock ~37 ~118 ~82 dirt
setblock ~37 ~118 ~83 dirt
setblock ~37 ~118 ~84 dirt
setblock ~37 ~118 ~93 dirt
setblock ~37 ~118 ~94 dirt
setblock ~37 ~118 ~95 dirt
setblock ~37 ~118 ~96 dirt
setblock ~37 ~118 ~97 dirt
setblock ~37 ~118 ~98 dirt
setblock ~37 ~118 ~99 dirt
setblock ~37 ~118 ~100 dirt
setblock ~37 ~118 ~101 dirt
setblock ~37 ~118 ~102 dirt
setblock ~37 ~118 ~103 dirt
setblock ~37 ~118 ~104 dirt
setblock ~37 ~118 ~105 dirt
setblock ~37 ~118 ~115 dirt
setblock ~37 ~118 ~116 dirt
setblock ~37 ~118 ~117 dirt
setblock ~37 ~118 ~118 dirt
setblock ~37 ~118 ~119 dirt
setblock ~37 ~118 ~120 dirt
setblock ~37 ~118 ~121 dirt
setblock ~37 ~118 ~122 dirt
setblock ~37 ~118 ~123 dirt
setblock ~37 ~119 ~77 dirt
setblock ~37 ~119 ~78 dirt
setblock ~37 ~119 ~80 dirt
setblock ~37 ~119 ~81 dirt
setblock ~37 ~119 ~82 dirt
setblock ~37 ~119 ~83 dirt
setblock ~37 ~119 ~84 dirt
setblock ~37 ~119 ~92 dirt
setblock ~37 ~119 ~93 dirt
setblock ~37 ~119 ~94 dirt
setblock ~37 ~119 ~95 dirt
setblock ~37 ~119 ~96 dirt
setblock ~37 ~119 ~97 dirt
setblock ~37 ~119 ~98 dirt
setblock ~37 ~119 ~99 dirt
setblock ~37 ~119 ~100 dirt
setblock ~37 ~119 ~101 dirt
setblock ~37 ~119 ~102 dirt
setblock ~37 ~119 ~103 dirt
setblock ~37 ~119 ~104 dirt
setblock ~37 ~119 ~105 dirt
setblock ~37 ~119 ~106 dirt
setblock ~37 ~119 ~113 dirt
setblock ~37 ~119 ~114 dirt
setblock ~37 ~119 ~115 dirt
setblock ~37 ~119 ~116 dirt
setblock ~37 ~119 ~117 dirt
setblock ~37 ~119 ~118 dirt
setblock ~37 ~119 ~119 dirt
setblock ~37 ~119 ~120 dirt
setblock ~37 ~119 ~121 dirt
setblock ~37 ~119 ~122 dirt
setblock ~37 ~119 ~123 dirt
setblock ~37 ~119 ~124 dirt
setblock ~37 ~120 ~76 dirt
setblock ~37 ~120 ~77 dirt
setblock ~37 ~120 ~78 dirt
setblock ~37 ~120 ~79 dirt
setblock ~37 ~120 ~80 dirt
setblock ~37 ~120 ~81 dirt
setblock ~37 ~120 ~82 dirt
setblock ~37 ~120 ~83 dirt
setblock ~37 ~120 ~84 dirt
setblock ~37 ~120 ~85 dirt
setblock ~37 ~120 ~91 dirt
setblock ~37 ~120 ~92 dirt
setblock ~37 ~120 ~93 dirt
setblock ~37 ~120 ~94 dirt
setblock ~37 ~120 ~95 dirt
setblock ~37 ~120 ~96 dirt
setblock ~37 ~120 ~97 dirt
setblock ~37 ~120 ~98 dirt
setblock ~37 ~120 ~99 dirt
setblock ~37 ~120 ~100 dirt
setblock ~37 ~120 ~101 dirt
setblock ~37 ~120 ~102 dirt
setblock ~37 ~120 ~103 dirt
setblock ~37 ~120 ~104 dirt
setblock ~37 ~120 ~105 dirt
setblock ~37 ~120 ~106 dirt
setblock ~37 ~120 ~107 dirt
setblock ~37 ~120 ~108 dirt
setblock ~37 ~120 ~109 dirt
setblock ~37 ~120 ~111 dirt
setblock ~37 ~120 ~112 dirt
setblock ~37 ~120 ~113 dirt
setblock ~37 ~120 ~114 dirt
setblock ~37 ~120 ~115 dirt
setblock ~37 ~120 ~116 dirt
setblock ~37 ~120 ~117 dirt
setblock ~37 ~120 ~118 dirt
setblock ~37 ~120 ~119 dirt
setblock ~37 ~120 ~120 dirt
setblock ~37 ~120 ~121 dirt
setblock ~37 ~120 ~122 dirt
setblock ~37 ~120 ~123 dirt
setblock ~37 ~120 ~124 dirt
setblock ~37 ~120 ~125 dirt
setblock ~37 ~121 ~75 dirt
setblock ~37 ~121 ~76 dirt
setblock ~37 ~121 ~77 dirt
setblock ~37 ~121 ~78 dirt
setblock ~37 ~121 ~79 dirt
setblock ~37 ~121 ~80 dirt
setblock ~37 ~121 ~81 dirt
setblock ~37 ~121 ~82 dirt
setblock ~37 ~121 ~83 dirt
setblock ~37 ~121 ~84 dirt
setblock ~37 ~121 ~85 dirt
setblock ~37 ~121 ~91 dirt
setblock ~37 ~121 ~92 dirt
setblock ~37 ~121 ~93 dirt
setblock ~37 ~121 ~94 dirt
setblock ~37 ~121 ~95 dirt
setblock ~37 ~121 ~96 dirt
setblock ~37 ~121 ~97 dirt
setblock ~37 ~121 ~98 dirt
setblock ~37 ~121 ~99 dirt
setblock ~37 ~121 ~100 dirt
setblock ~37 ~121 ~101 dirt
setblock ~37 ~121 ~102 dirt
setblock ~37 ~121 ~103 dirt
setblock ~37 ~121 ~104 dirt
setblock ~37 ~121 ~105 dirt
setblock ~37 ~121 ~106 dirt
setblock ~37 ~121 ~107 dirt
setblock ~37 ~121 ~108 dirt
setblock ~37 ~121 ~109 dirt
setblock ~37 ~121 ~110 dirt
setblock ~37 ~121 ~111 dirt
setblock ~37 ~121 ~112 dirt
setblock ~37 ~121 ~113 dirt
setblock ~37 ~121 ~114 dirt
setblock ~37 ~121 ~115 dirt
setblock ~37 ~121 ~116 dirt
setblock ~37 ~121 ~117 dirt
setblock ~37 ~121 ~118 dirt
setblock ~37 ~121 ~119 dirt
setblock ~37 ~121 ~120 dirt
setblock ~37 ~121 ~121 dirt
setblock ~37 ~121 ~122 dirt
setblock ~37 ~121 ~123 dirt
setblock ~37 ~121 ~124 dirt
setblock ~37 ~121 ~125 dirt
setblock ~37 ~121 ~126 dirt
setblock ~37 ~122 ~75 dirt
setblock ~37 ~122 ~76 dirt
setblock ~37 ~122 ~77 dirt
setblock ~37 ~122 ~78 dirt
setblock ~37 ~122 ~79 dirt
setblock ~37 ~122 ~80 dirt
setblock ~37 ~122 ~81 dirt
setblock ~37 ~122 ~82 dirt
setblock ~37 ~122 ~83 dirt
setblock ~37 ~122 ~84 dirt
setblock ~37 ~122 ~85 dirt
setblock ~37 ~122 ~91 dirt
setblock ~37 ~122 ~92 dirt
setblock ~37 ~122 ~93 dirt
setblock ~37 ~122 ~94 dirt
setblock ~37 ~122 ~95 dirt
setblock ~37 ~122 ~96 dirt
setblock ~37 ~122 ~97 dirt
setblock ~37 ~122 ~98 dirt
setblock ~37 ~122 ~99 dirt
setblock ~37 ~122 ~100 dirt
setblock ~37 ~122 ~101 dirt
setblock ~37 ~122 ~102 dirt
setblock ~37 ~122 ~103 dirt
setblock ~37 ~122 ~104 dirt
setblock ~37 ~122 ~105 dirt
setblock ~37 ~122 ~106 dirt
setblock ~37 ~122 ~107 dirt
setblock ~37 ~122 ~108 dirt
setblock ~37 ~122 ~109 dirt
setblock ~37 ~122 ~110 dirt
setblock ~37 ~122 ~111 dirt
setblock ~37 ~122 ~112 dirt
setblock ~37 ~122 ~113 dirt
setblock ~37 ~122 ~114 dirt
setblock ~37 ~122 ~115 dirt
setblock ~37 ~122 ~116 dirt
setblock ~37 ~122 ~117 dirt
setblock ~37 ~122 ~118 dirt
setblock ~37 ~122 ~119 dirt
setblock ~37 ~122 ~120 dirt
setblock ~37 ~122 ~121 dirt
setblock ~37 ~122 ~122 dirt
setblock ~37 ~122 ~123 dirt
setblock ~37 ~122 ~124 dirt
setblock ~37 ~122 ~125 dirt
setblock ~37 ~122 ~126 dirt
setblock ~37 ~123 ~75 dirt
setblock ~37 ~123 ~76 dirt
setblock ~37 ~123 ~77 dirt
setblock ~37 ~123 ~78 dirt
setblock ~37 ~123 ~79 dirt
setblock ~37 ~123 ~80 dirt
setblock ~37 ~123 ~81 dirt
setblock ~37 ~123 ~82 dirt
setblock ~37 ~123 ~83 dirt
setblock ~37 ~123 ~84 dirt
setblock ~37 ~123 ~85 dirt
setblock ~37 ~123 ~91 dirt
setblock ~37 ~123 ~92 dirt
setblock ~37 ~123 ~93 dirt
setblock ~37 ~123 ~94 dirt
setblock ~37 ~123 ~95 dirt
setblock ~37 ~123 ~96 dirt
setblock ~37 ~123 ~97 dirt
setblock ~37 ~123 ~98 dirt
setblock ~37 ~123 ~99 dirt
setblock ~37 ~123 ~100 dirt
setblock ~37 ~123 ~101 dirt
setblock ~37 ~123 ~102 dirt
setblock ~37 ~123 ~103 dirt
setblock ~37 ~123 ~104 dirt
setblock ~37 ~123 ~105 dirt
setblock ~37 ~123 ~106 dirt
setblock ~37 ~123 ~107 dirt
setblock ~37 ~123 ~108 dirt
setblock ~37 ~123 ~109 dirt
setblock ~37 ~123 ~110 dirt
setblock ~37 ~123 ~111 dirt
setblock ~37 ~123 ~112 dirt
setblock ~37 ~123 ~113 dirt
setblock ~37 ~123 ~114 dirt
setblock ~37 ~123 ~115 dirt
setblock ~37 ~123 ~116 dirt
setblock ~37 ~123 ~117 dirt
setblock ~37 ~123 ~118 dirt
setblock ~37 ~123 ~119 dirt
setblock ~37 ~123 ~120 dirt
setblock ~37 ~123 ~121 dirt
setblock ~37 ~123 ~122 dirt
setblock ~37 ~123 ~123 dirt
setblock ~37 ~123 ~124 dirt
setblock ~37 ~123 ~125 dirt
setblock ~37 ~123 ~126 dirt
setblock ~37 ~124 ~75 dirt
setblock ~37 ~124 ~76 dirt
setblock ~37 ~124 ~77 dirt
setblock ~37 ~124 ~78 dirt
setblock ~37 ~124 ~79 dirt
setblock ~37 ~124 ~80 dirt
setblock ~37 ~124 ~81 dirt
setblock ~37 ~124 ~82 dirt
setblock ~37 ~124 ~83 dirt
setblock ~37 ~124 ~84 dirt
setblock ~37 ~124 ~85 dirt
setblock ~37 ~124 ~91 dirt
setblock ~37 ~124 ~92 dirt
setblock ~37 ~124 ~93 dirt
setblock ~37 ~124 ~94 dirt
setblock ~37 ~124 ~95 dirt
setblock ~37 ~124 ~96 dirt
setblock ~37 ~124 ~97 dirt
setblock ~37 ~124 ~98 dirt
setblock ~37 ~124 ~99 dirt
setblock ~37 ~124 ~100 dirt
setblock ~37 ~124 ~101 dirt
setblock ~37 ~124 ~102 dirt
setblock ~37 ~124 ~103 dirt
setblock ~37 ~124 ~104 dirt
setblock ~37 ~124 ~105 dirt
setblock ~37 ~124 ~106 dirt
setblock ~37 ~124 ~107 dirt
setblock ~37 ~124 ~108 dirt
setblock ~37 ~124 ~109 dirt
setblock ~37 ~124 ~110 dirt
setblock ~37 ~124 ~111 dirt
setblock ~37 ~124 ~112 dirt
setblock ~37 ~124 ~113 dirt
setblock ~37 ~124 ~114 dirt
setblock ~37 ~124 ~115 dirt
setblock ~37 ~124 ~116 dirt
setblock ~37 ~124 ~117 dirt
setblock ~37 ~124 ~118 grass_block
setblock ~37 ~124 ~119 grass_block
setblock ~37 ~124 ~120 grass_block
setblock ~37 ~124 ~121 grass_block
setblock ~37 ~124 ~122 grass_block
setblock ~37 ~124 ~123 grass_block
setblock ~37 ~124 ~124 dirt
setblock ~37 ~124 ~125 dirt
setblock ~37 ~124 ~126 dirt
setblock ~37 ~125 ~75 dirt
setblock ~37 ~125 ~76 dirt
setblock ~37 ~125 ~77 dirt
setblock ~37 ~125 ~78 dirt
setblock ~37 ~125 ~79 dirt
setblock ~37 ~125 ~80 dirt
setblock ~37 ~125 ~81 dirt
setblock ~37 ~125 ~82 dirt
setblock ~37 ~125 ~83 dirt
setblock ~37 ~125 ~84 dirt
setblock ~37 ~125 ~85 dirt
setblock ~37 ~125 ~91 dirt
setblock ~37 ~125 ~92 dirt
setblock ~37 ~125 ~93 dirt
setblock ~37 ~125 ~94 dirt
setblock ~37 ~125 ~95 dirt
setblock ~37 ~125 ~96 dirt
setblock ~37 ~125 ~97 dirt
setblock ~37 ~125 ~98 dirt
setblock ~37 ~125 ~99 dirt
setblock ~37 ~125 ~100 dirt
setblock ~37 ~125 ~101 dirt
setblock ~37 ~125 ~102 dirt
setblock ~37 ~125 ~103 dirt
setblock ~37 ~125 ~104 dirt
setblock ~37 ~125 ~105 dirt
setblock ~37 ~125 ~106 dirt
setblock ~37 ~125 ~107 dirt
setblock ~37 ~125 ~108 dirt
setblock ~37 ~125 ~109 dirt
setblock ~37 ~125 ~110 dirt
setblock ~37 ~125 ~111 dirt
setblock ~37 ~125 ~112 dirt
setblock ~37 ~125 ~113 dirt
setblock ~37 ~125 ~114 dirt
setblock ~37 ~125 ~115 grass_block
setblock ~37 ~125 ~116 grass_block
setblock ~37 ~125 ~117 grass_block
setblock ~37 ~125 ~121 short_grass
setblock ~37 ~125 ~124 grass_block
setblock ~37 ~125 ~125 grass_block
setblock ~37 ~125 ~126 grass_block
setblock ~37 ~126 ~75 grass_block
setblock ~37 ~126 ~76 grass_block
setblock ~37 ~126 ~77 grass_block
setblock ~37 ~126 ~78 grass_block
setblock ~37 ~126 ~79 grass_block
setblock ~37 ~126 ~80 grass_block
setblock ~37 ~126 ~81 grass_block
setblock ~37 ~126 ~82 grass_block
setblock ~37 ~126 ~83 dirt
setblock ~37 ~126 ~84 dirt
setblock ~37 ~126 ~85 dirt
setblock ~37 ~126 ~91 dirt
setblock ~37 ~126 ~92 dirt
setblock ~37 ~126 ~93 dirt
setblock ~37 ~126 ~94 dirt
setblock ~37 ~126 ~95 dirt
setblock ~37 ~126 ~96 dirt
setblock ~37 ~126 ~97 dirt
setblock ~37 ~126 ~98 dirt
setblock ~37 ~126 ~99 grass_block
setblock ~37 ~126 ~100 grass_block
setblock ~37 ~126 ~101 grass_block
setblock ~37 ~126 ~102 grass_block
setblock ~37 ~126 ~103 grass_block
setblock ~37 ~126 ~104 dirt
setblock ~37 ~126 ~105 dirt
setblock ~37 ~126 ~106 dirt
setblock ~37 ~126 ~107 dirt
setblock ~37 ~126 ~108 dirt
setblock ~37 ~126 ~109 dirt
setblock ~37 ~126 ~110 dirt
setblock ~37 ~126 ~111 dirt
setblock ~37 ~126 ~112 grass_block
setblock ~37 ~126 ~113 grass_block
setblock ~37 ~126 ~114 grass_block
setblock ~37 ~126 ~125 short_grass
setblock ~37 ~127 ~76 short_grass
setblock ~37 ~127 ~79 short_grass
setblock ~37 ~127 ~81 short_grass
setblock ~37 ~127 ~83 grass_block
setblock ~37 ~127 ~84 grass_block
setblock ~37 ~127 ~85 grass_block
setblock ~37 ~127 ~91 dirt
setblock ~37 ~127 ~92 dirt
setblock ~37 ~127 ~93 dirt
setblock ~37 ~127 ~94 dirt
setblock ~37 ~127 ~95 grass_block
setblock ~37 ~127 ~96 grass_block
setblock ~37 ~127 ~97 grass_block
setblock ~37 ~127 ~98 grass_block
setblock ~37 ~127 ~104 grass_block
setblock ~37 ~127 ~105 grass_block
setblock ~37 ~127 ~106 grass_block
setblock ~37 ~127 ~107 grass_block
setblock ~37 ~127 ~108 grass_block
setblock ~37 ~127 ~109 grass_block
setblock ~37 ~127 ~110 grass_block
setblock ~37 ~127 ~111 grass_block
setblock ~37 ~127 ~113 fern
setblock ~37 ~127 ~114 short_grass
setblock ~37 ~128 ~85 short_grass
setblock ~37 ~128 ~91 grass_block
setblock ~37 ~128 ~92 grass_block
setblock ~37 ~128 ~93 grass_block
setblock ~37 ~128 ~94 grass_block
setblock ~37 ~128 ~96 short_grass
setblock ~37 ~128 ~98 poppy
setblock ~37 ~128 ~107 short_grass
setblock ~37 ~128 ~109 short_grass
setblock ~37 ~128 ~111 short_grass
setblock ~37 ~129 ~93 fern
setblock ~37 ~129 ~94 short_grass
setblock ~37 ~130 ~124 oak_leaves[persistent=true]
setblock ~37 ~130 ~125 oak_leaves[persistent=true]
setblock ~37 ~130 ~126 jungle_leaves[persistent=true]
setblock ~37 ~130 ~127 oak_leaves[persistent=true]
setblock ~37 ~130 ~128 oak_leaves[persistent=true]
setblock ~37 ~130 ~129 oak_leaves[persistent=true]
setblock ~37 ~130 ~130 oak_leaves[persistent=true]
setblock ~37 ~130 ~141 oak_leaves[persistent=true]
setblock ~37 ~130 ~142 oak_leaves[persistent=true]
setblock ~37 ~130 ~143 oak_leaves[persistent=true]
setblock ~37 ~131 ~54 oak_leaves[persistent=true]
setblock ~37 ~131 ~55 oak_leaves[persistent=true]
setblock ~37 ~131 ~56 oak_leaves[persistent=true]
setblock ~37 ~131 ~124 jungle_leaves[persistent=true]
setblock ~37 ~131 ~125 oak_leaves[persistent=true]
setblock ~37 ~131 ~127 oak_leaves[persistent=true]
setblock ~37 ~131 ~128 oak_leaves[persistent=true]
setblock ~37 ~131 ~129 oak_leaves[persistent=true]
setblock ~37 ~131 ~130 oak_leaves[persistent=true]
setblock ~37 ~131 ~131 oak_leaves[persistent=true]
setblock ~37 ~131 ~142 oak_leaves[persistent=true]
setblock ~37 ~131 ~143 oak_leaves[persistent=true]
setblock ~37 ~132 ~53 oak_leaves[persistent=true]
setblock ~37 ~132 ~54 oak_leaves[persistent=true]
setblock ~37 ~132 ~55 oak_leaves[persistent=true]
setblock ~37 ~132 ~56 oak_leaves[persistent=true]
setblock ~37 ~132 ~57 oak_leaves[persistent=true]
setblock ~37 ~132 ~122 oak_leaves[persistent=true]
setblock ~37 ~132 ~123 oak_leaves[persistent=true]
setblock ~37 ~132 ~124 jungle_leaves[persistent=true]
setblock ~37 ~132 ~125 jungle_leaves[persistent=true]
setblock ~37 ~132 ~126 oak_leaves[persistent=true]
setblock ~37 ~132 ~128 oak_wood
setblock ~37 ~132 ~129 oak_leaves[persistent=true]
setblock ~37 ~132 ~130 oak_leaves[persistent=true]
setblock ~37 ~132 ~131 oak_leaves[persistent=true]
setblock ~37 ~132 ~139 jungle_leaves[persistent=true]
setblock ~37 ~132 ~141 jungle_leaves[persistent=true]
setblock ~37 ~132 ~142 oak_leaves[persistent=true]
setblock ~37 ~132 ~143 oak_leaves[persistent=true]
setblock ~37 ~133 ~53 jungle_leaves[persistent=true]
setblock ~37 ~133 ~54 oak_leaves[persistent=true]
setblock ~37 ~133 ~55 jungle_leaves[persistent=true]
setblock ~37 ~133 ~56 oak_leaves[persistent=true]
setblock ~37 ~133 ~57 oak_leaves[persistent=true]
setblock ~37 ~133 ~120 oak_leaves[persistent=true]
setblock ~37 ~133 ~121 oak_leaves[persistent=true]
setblock ~37 ~133 ~122 oak_leaves[persistent=true]
setblock ~37 ~133 ~123 oak_leaves[persistent=true]
setblock ~37 ~133 ~124 jungle_leaves[persistent=true]
setblock ~37 ~133 ~125 oak_leaves[persistent=true]
setblock ~37 ~133 ~126 oak_leaves[persistent=true]
setblock ~37 ~133 ~127 oak_leaves[persistent=true]
setblock ~37 ~133 ~128 oak_leaves[persistent=true]
setblock ~37 ~133 ~130 jungle_leaves[persistent=true]
setblock ~37 ~133 ~131 oak_leaves[persistent=true]
setblock ~37 ~133 ~132 oak_leaves[persistent=true]
setblock ~37 ~133 ~133 oak_leaves[persistent=true]
setblock ~37 ~133 ~135 oak_leaves[persistent=true]
setblock ~37 ~133 ~136 jungle_leaves[persistent=true]
setblock ~37 ~133 ~137 oak_leaves[persistent=true]
setblock ~37 ~133 ~139 oak_leaves[persistent=true]
setblock ~37 ~133 ~140 oak_leaves[persistent=true]
setblock ~37 ~133 ~141 oak_wood
setblock ~37 ~133 ~142 oak_wood
setblock ~37 ~133 ~143 oak_leaves[persistent=true]
setblock ~37 ~133 ~144 oak_leaves[persistent=true]
setblock ~37 ~134 ~53 oak_leaves[persistent=true]
setblock ~37 ~134 ~54 oak_leaves[persistent=true]
setblock ~37 ~134 ~55 oak_leaves[persistent=true]
setblock ~37 ~134 ~56 oak_leaves[persistent=true]
setblock ~37 ~134 ~57 oak_leaves[persistent=true]
setblock ~37 ~134 ~116 oak_leaves[persistent=true]
setblock ~37 ~134 ~117 oak_leaves[persistent=true]
setblock ~37 ~134 ~118 jungle_leaves[persistent=true]
setblock ~37 ~134 ~119 oak_leaves[persistent=true]
setblock ~37 ~134 ~120 jungle_leaves[persistent=true]
setblock ~37 ~134 ~121 jungle_leaves[persistent=true]
setblock ~37 ~134 ~122 oak_leaves[persistent=true]
setblock ~37 ~134 ~124 oak_wood
setblock ~37 ~134 ~125 oak_leaves[persistent=true]
setblock ~37 ~134 ~126 oak_leaves[persistent=true]
setblock ~37 ~134 ~127 jungle_leaves[persistent=true]
setblock ~37 ~134 ~128 oak_leaves[persistent=true]
setblock ~37 ~134 ~129 jungle_leaves[persistent=true]
setblock ~37 ~134 ~130 oak_leaves[persistent=true]
setblock ~37 ~134 ~131 oak_leaves[persistent=true]
setblock ~37 ~134 ~132 oak_wood
setblock ~37 ~134 ~133 oak_leaves[persistent=true]
setblock ~37 ~134 ~134 oak_leaves[persistent=true]
setblock ~37 ~134 ~135 oak_leaves[persistent=true]
setblock ~37 ~134 ~137 jungle_leaves[persistent=true]
setblock ~37 ~134 ~138 oak_leaves[persistent=true]
setblock ~37 ~134 ~140 jungle_leaves[persistent=true]
setblock ~37 ~134 ~141 oak_leaves[persistent=true]
setblock ~37 ~134 ~143 oak_leaves[persistent=true]
setblock ~37 ~135 ~114 jungle_leaves[persistent=true]
setblock ~37 ~135 ~115 oak_leaves[persistent=true]
setblock ~37 ~135 ~116 oak_leaves[persistent=true]
setblock ~37 ~135 ~117 jungle_leaves[persistent=true]
setblock ~37 ~135 ~118 oak_leaves[persistent=true]
setblock ~37 ~135 ~119 jungle_leaves[persistent=true]
setblock ~37 ~135 ~120 oak_leaves[persistent=true]
setblock ~37 ~135 ~121 oak_leaves[persistent=true]
setblock ~37 ~135 ~122 oak_leaves[persistent=true]
setblock ~37 ~135 ~123 oak_leaves[persistent=true]
setblock ~37 ~135 ~124 oak_leaves[persistent=true]
setblock ~37 ~135 ~125 oak_leaves[persistent=true]
setblock ~37 ~135 ~126 oak_leaves[persistent=true]
setblock ~37 ~135 ~127 oak_leaves[persistent=true]
setblock ~37 ~135 ~128 oak_leaves[persistent=true]
setblock ~37 ~135 ~129 oak_leaves[persistent=true]
setblock ~37 ~135 ~130 oak_leaves[persistent=true]
setblock ~37 ~135 ~131 oak_wood
setblock ~37 ~135 ~133 oak_leaves[persistent=true]
setblock ~37 ~135 ~134 oak_leaves[persistent=true]
setblock ~37 ~135 ~135 oak_leaves[persistent=true]
setblock ~37 ~135 ~136 oak_leaves[persistent=true]
setblock ~37 ~135 ~137 oak_wood
setblock ~37 ~135 ~138 oak_leaves[persistent=true]
setblock ~37 ~135 ~139 oak_leaves[persistent=true]
setblock ~37 ~135 ~140 oak_leaves[persistent=true]
setblock ~37 ~136 ~114 oak_leaves[persistent=true]
setblock ~37 ~136 ~115 oak_leaves[persistent=true]
setblock ~37 ~136 ~116 oak_leaves[persistent=true]
setblock ~37 ~136 ~117 oak_leaves[persistent=true]
setblock ~37 ~136 ~118 oak_leaves[persistent=true]
setblock ~37 ~136 ~119 jungle_leaves[persistent=true]
setblock ~37 ~136 ~120 oak_wood
setblock ~37 ~136 ~121 oak_wood
setblock ~37 ~136 ~122 oak_wood
setblock ~37 ~136 ~124 oak_leaves[persistent=true]
setblock ~37 ~136 ~125 oak_leaves[persistent=true]
setblock ~37 ~136 ~126 jungle_leaves[persistent=true]
setblock ~37 ~136 ~127 oak_leaves[persistent=true]
setblock ~37 ~136 ~129 oak_leaves[persistent=true]
setblock ~37 ~136 ~130 oak_leaves[persistent=true]
setblock ~37 ~136 ~131 oak_leaves[persistent=true]
setblock ~37 ~136 ~132 oak_leaves[persistent=true]
setblock ~37 ~136 ~133 oak_leaves[persistent=true]
setblock ~37 ~136 ~134 oak_leaves[persistent=true]
setblock ~37 ~136 ~135 oak_leaves[persistent=true]
setblock ~37 ~136 ~136 jungle_leaves[persistent=true]
setblock ~37 ~136 ~138 oak_leaves[persistent=true]
setblock ~37 ~136 ~139 oak_leaves[persistent=true]
setblock ~37 ~136 ~140 oak_leaves[persistent=true]
setblock ~37 ~137 ~115 oak_leaves[persistent=true]
setblock ~37 ~137 ~116 jungle_leaves[persistent=true]
setblock ~37 ~137 ~117 oak_leaves[persistent=true]
setblock ~37 ~137 ~118 oak_leaves[persistent=true]
setblock ~37 ~137 ~119 oak_leaves[persistent=true]
setblock ~37 ~137 ~120 oak_leaves[persistent=true]
setblock ~37 ~137 ~121 oak_leaves[persistent=true]
setblock ~37 ~137 ~122 oak_leaves[persistent=true]
setblock ~37 ~137 ~123 oak_leaves[persistent=true]
setblock ~37 ~137 ~124 oak_leaves[persistent=true]
setblock ~37 ~137 ~126 oak_leaves[persistent=true]
setblock ~37 ~137 ~127 jungle_leaves[persistent=true]
setblock ~37 ~137 ~128 jungle_leaves[persistent=true]
setblock ~37 ~137 ~129 jungle_leaves[persistent=true]
setblock ~37 ~137 ~130 oak_leaves[persistent=true]
setblock ~37 ~137 ~131 oak_leaves[persistent=true]
setblock ~37 ~137 ~132 oak_leaves[persistent=true]
setblock ~37 ~137 ~133 oak_leaves[persistent=true]
setblock ~37 ~137 ~134 oak_leaves[persistent=true]
setblock ~37 ~137 ~135 oak_leaves[persistent=true]
setblock ~37 ~137 ~136 oak_leaves[persistent=true]
setblock ~37 ~138 ~120 jungle_leaves[persistent=true]
setblock ~37 ~138 ~121 oak_leaves[persistent=true]
setblock ~37 ~138 ~123 oak_leaves[persistent=true]
setblock ~37 ~138 ~124 oak_leaves[persistent=true]
setblock ~37 ~138 ~127 jungle_leaves[persistent=true]
setblock ~37 ~138 ~128 oak_leaves[persistent=true]
setblock ~37 ~138 ~129 oak_leaves[persistent=true]
setblock ~37 ~138 ~130 oak_leaves[persistent=true]
setblock ~37 ~138 ~131 oak_leaves[persistent=true]
setblock ~37 ~138 ~132 jungle_leaves[persistent=true]
setblock ~37 ~138 ~133 jungle_leaves[persistent=true]
setblock ~37 ~138 ~134 jungle_leaves[persistent=true]
setblock ~37 ~138 ~135 jungle_leaves[persistent=true]
setblock ~37 ~138 ~136 oak_leaves[persistent=true]
setblock ~37 ~139 ~121 oak_leaves[persistent=true]
setblock ~37 ~139 ~122 oak_leaves[persistent=true]
setblock ~37 ~139 ~123 oak_leaves[persistent=true]
setblock ~37 ~139 ~124 oak_leaves[persistent=true]
setblock ~37 ~139 ~125 oak_leaves[persistent=true]
setblock ~37 ~139 ~126 oak_leaves[persistent=true]
setblock ~37 ~139 ~127 oak_leaves[persistent=true]
setblock ~37 ~139 ~128 jungle_leaves[persistent=true]
setblock ~37 ~139 ~129 oak_leaves[persistent=true]
setblock ~37 ~139 ~130 oak_leaves[persistent=true]
setblock ~37 ~139 ~131 oak_leaves[persistent=true]
setblock ~37 ~139 ~132 jungle_leaves[persistent=true]
setblock ~37 ~139 ~133 oak_leaves[persistent=true]
setblock ~37 ~139 ~134 oak_leaves[persistent=true]
setblock ~37 ~139 ~136 jungle_leaves[persistent=true]
setblock ~37 ~140 ~131 oak_leaves[persistent=true]
setblock ~37 ~140 ~132 oak_leaves[persistent=true]
setblock ~37 ~140 ~134 jungle_leaves[persistent=true]
setblock ~38 ~109 ~97 dirt
setblock ~38 ~109 ~98 dirt
setblock ~38 ~110 ~97 dirt
setblock ~38 ~110 ~98 dirt
setblock ~38 ~110 ~99 dirt
setblock ~38 ~111 ~95 dirt
setblock ~38 ~111 ~97 dirt
setblock ~38 ~111 ~98 dirt
setblock ~38 ~111 ~99 dirt
setblock ~38 ~111 ~119 dirt
setblock ~38 ~111 ~120 dirt
setblock ~38 ~112 ~94 dirt
setblock ~38 ~112 ~95 dirt
setblock ~38 ~112 ~96 dirt
setblock ~38 ~112 ~97 dirt
setblock ~38 ~112 ~98 dirt
setblock ~38 ~112 ~99 dirt
setblock ~38 ~112 ~100 dirt
setblock ~38 ~112 ~117 dirt
setblock ~38 ~112 ~118 dirt
setblock ~38 ~112 ~119 dirt
setblock ~38 ~112 ~120 dirt
setblock ~38 ~112 ~121 dirt
setblock ~38 ~113 ~94 dirt
setblock ~38 ~113 ~95 dirt
setblock ~38 ~113 ~96 dirt
setblock ~38 ~113 ~97 dirt
setblock ~38 ~113 ~98 dirt
setblock ~38 ~113 ~99 dirt
setblock ~38 ~113 ~100 dirt
setblock ~38 ~113 ~101 dirt
setblock ~38 ~113 ~105 dirt
setblock ~38 ~113 ~117 dirt
setblock ~38 ~113 ~118 dirt
setblock ~38 ~113 ~119 dirt
setblock ~38 ~113 ~120 dirt
setblock ~38 ~113 ~121 dirt
setblock ~38 ~114 ~93 dirt
setblock ~38 ~114 ~94 dirt
setblock ~38 ~114 ~95 dirt
setblock ~38 ~114 ~96 dirt
setblock ~38 ~114 ~97 dirt
setblock ~38 ~114 ~98 dirt
setblock ~38 ~114 ~99 dirt
setblock ~38 ~114 ~100 dirt
setblock ~38 ~114 ~101 dirt
setblock ~38 ~114 ~102 dirt
setblock ~38 ~114 ~103 dirt
setblock ~38 ~114 ~105 dirt
setblock ~38 ~114 ~115 dirt
setblock ~38 ~114 ~117 dirt
setblock ~38 ~114 ~118 dirt
setblock ~38 ~114 ~119 dirt
setblock ~38 ~114 ~120 dirt
setblock ~38 ~114 ~121 dirt
setblock ~38 ~115 ~82 dirt
setblock ~38 ~115 ~83 dirt
setblock ~38 ~115 ~93 dirt
setblock ~38 ~115 ~94 dirt
setblock ~38 ~115 ~95 dirt
setblock ~38 ~115 ~96 dirt
setblock ~38 ~115 ~97 dirt
setblock ~38 ~115 ~98 dirt
setblock ~38 ~115 ~99 dirt
setblock ~38 ~115 ~100 dirt
setblock ~38 ~115 ~101 dirt
setblock ~38 ~115 ~102 dirt
setblock ~38 ~115 ~103 dirt
setblock ~38 ~115 ~104 dirt
setblock ~38 ~115 ~105 dirt
setblock ~38 ~115 ~106 dirt
setblock ~38 ~115 ~115 dirt
setblock ~38 ~115 ~116 dirt
setblock ~38 ~115 ~117 dirt
setblock ~38 ~115 ~118 dirt
setblock ~38 ~115 ~119 dirt
setblock ~38 ~115 ~120 dirt
setblock ~38 ~115 ~121 dirt
setblock ~38 ~116 ~82 dirt
setblock ~38 ~116 ~83 dirt
setblock ~38 ~116 ~84 dirt
setblock ~38 ~116 ~92 dirt
setblock ~38 ~116 ~93 dirt
setblock ~38 ~116 ~94 dirt
setblock ~38 ~116 ~95 dirt
setblock ~38 ~116 ~96 dirt
setblock ~38 ~116 ~97 dirt
setblock ~38 ~116 ~98 dirt
setblock ~38 ~116 ~99 dirt
setblock ~38 ~116 ~100 dirt
setblock ~38 ~116 ~101 dirt
setblock ~38 ~116 ~102 dirt
setblock ~38 ~116 ~103 dirt
setblock ~38 ~116 ~104 dirt
setblock ~38 ~116 ~105 dirt
setblock ~38 ~116 ~106 dirt
