setblock ~0 ~1 ~0 gold_block
setblock ~21 ~133 ~69 oak_leaves[persistent=null]
setblock ~21 ~133 ~70 oak_leaves[persistent=null]
setblock ~21 ~133 ~71 oak_leaves[persistent=null]
setblock ~21 ~133 ~72 oak_leaves[persistent=null]
setblock ~21 ~134 ~70 oak_leaves[persistent=null]
setblock ~21 ~134 ~71 oak_leaves[persistent=null]
setblock ~21 ~134 ~72 oak_leaves[persistent=null]
setblock ~21 ~135 ~69 oak_leaves[persistent=null]
setblock ~21 ~135 ~70 oak_leaves[persistent=null]
setblock ~21 ~135 ~71 oak_leaves[persistent=null]
setblock ~21 ~136 ~70 oak_leaves[persistent=null]
setblock ~21 ~136 ~71 oak_leaves[persistent=null]
setblock ~21 ~136 ~72 oak_leaves[persistent=null]
setblock ~22 ~133 ~69 oak_leaves[persistent=null]
setblock ~22 ~133 ~71 oak_leaves[persistent=null]
setblock ~22 ~133 ~72 oak_leaves[persistent=null]
setblock ~22 ~134 ~70 oak_leaves[persistent=null]
setblock ~22 ~134 ~71 jungle_leaves[persistent=null]
setblock ~22 ~134 ~72 oak_leaves[persistent=null]
setblock ~22 ~135 ~69 oak_leaves[persistent=null]
setblock ~22 ~135 ~70 oak_leaves[persistent=null]
setblock ~22 ~135 ~71 oak_leaves[persistent=null]
setblock ~22 ~135 ~72 oak_leaves[persistent=null]
setblock ~22 ~136 ~69 jungle_leaves[persistent=null]
setblock ~22 ~136 ~71 oak_leaves[persistent=null]
setblock ~22 ~137 ~69 oak_leaves[persistent=null]
setblock ~22 ~137 ~70 jungle_leaves[persistent=null]
setblock ~22 ~137 ~71 oak_leaves[persistent=null]
setblock ~23 ~133 ~69 oak_leaves[persistent=null]
setblock ~23 ~133 ~70 jungle_leaves[persistent=null]
setblock ~23 ~133 ~71 oak_leaves[persistent=null]
setblock ~23 ~133 ~72 oak_leaves[persistent=null]
setblock ~23 ~134 ~70 oak_leaves[persistent=null]
setblock ~23 ~134 ~71 oak_leaves[persistent=null]
setblock ~23 ~134 ~72 oak_leaves[persistent=null]
setblock ~23 ~135 ~71 oak_wood
setblock ~23 ~135 ~72 oak_leaves[persistent=null]
setblock ~23 ~136 ~70 jungle_leaves[persistent=null]
setblock ~23 ~136 ~71 oak_leaves[persistent=null]
setblock ~23 ~136 ~72 oak_leaves[persistent=null]
setblock ~23 ~136 ~73 jungle_leaves[persistent=null]
setblock ~23 ~137 ~69 jungle_leaves[persistent=null]
setblock ~23 ~137 ~71 oak_leaves[persistent=null]
setblock ~24 ~133 ~69 oak_leaves[persistent=null]
setblock ~24 ~133 ~70 jungle_leaves[persistent=null]
setblock ~24 ~133 ~71 oak_leaves[persistent=null]
setblock ~24 ~133 ~72 oak_leaves[persistent=null]
setblock ~24 ~134 ~69 oak_leaves[persistent=null]
setblock ~24 ~134 ~70 jungle_leaves[persistent=null]
setblock ~24 ~134 ~71 oak_leaves[persistent=null]
setblock ~24 ~134 ~73 oak_leaves[persistent=null]
setblock ~24 ~135 ~70 oak_leaves[persistent=null]
setblock ~24 ~135 ~71 oak_leaves[persistent=null]
setblock ~24 ~135 ~72 oak_leaves[persistent=null]
setblock ~24 ~135 ~73 jungle_leaves[persistent=null]
setblock ~24 ~136 ~70 jungle_leaves[persistent=null]
setblock ~24 ~136 ~71 oak_wood
setblock ~24 ~136 ~73 oak_leaves[persistent=null]
setblock ~24 ~137 ~69 oak_leaves[persistent=null]
setblock ~24 ~137 ~70 jungle_leaves[persistent=null]
setblock ~24 ~137 ~71 oak_leaves[persistent=null]
setblock ~24 ~137 ~72 oak_leaves[persistent=null]
setblock ~24 ~137 ~73 oak_leaves[persistent=null]
setblock ~24 ~138 ~67 oak_leaves[persistent=null]
setblock ~24 ~138 ~68 oak_leaves[persistent=null]
setblock ~24 ~138 ~69 oak_leaves[persistent=null]
setblock ~24 ~139 ~67 oak_leaves[persistent=null]
setblock ~24 ~139 ~68 jungle_leaves[persistent=null]
setblock ~24 ~139 ~69 oak_leaves[persistent=null]
setblock ~24 ~140 ~67 oak_leaves[persistent=null]
setblock ~24 ~140 ~68 oak_leaves[persistent=null]
setblock ~24 ~140 ~69 oak_leaves[persistent=null]
setblock ~25 ~134 ~69 oak_leaves[persistent=null]
setblock ~25 ~134 ~70 oak_leaves[persistent=null]
setblock ~25 ~134 ~72 jungle_leaves[persistent=null]
setblock ~25 ~134 ~73 oak_leaves[persistent=null]
setblock ~25 ~135 ~69 oak_leaves[persistent=null]
setblock ~25 ~135 ~70 oak_leaves[persistent=null]
setblock ~25 ~135 ~72 oak_leaves[persistent=null]
setblock ~25 ~136 ~69 oak_leaves[persistent=null]
setblock ~25 ~136 ~71 oak_leaves[persistent=null]
setblock ~25 ~136 ~72 oak_wood
setblock ~25 ~136 ~73 oak_leaves[persistent=null]
setblock ~25 ~137 ~70 jungle_leaves[persistent=null]
setblock ~25 ~137 ~71 oak_leaves[persistent=null]
setblock ~25 ~137 ~72 oak_leaves[persistent=null]
setblock ~25 ~137 ~73 oak_leaves[persistent=null]
setblock ~25 ~137 ~75 jungle_leaves[persistent=null]
setblock ~25 ~138 ~67 oak_leaves[persistent=null]
setblock ~25 ~138 ~68 oak_leaves[persistent=null]
setblock ~25 ~138 ~71 oak_leaves[persistent=null]
setblock ~25 ~138 ~72 oak_leaves[persistent=null]
setblock ~25 ~138 ~74 jungle_leaves[persistent=null]
setblock ~25 ~139 ~67 oak_leaves[persistent=null]
setblock ~25 ~139 ~68 oak_leaves[persistent=null]
setblock ~25 ~139 ~69 oak_leaves[persistent=null]
setblock ~25 ~139 ~70 oak_leaves[persistent=null]
setblock ~25 ~139 ~72 oak_leaves[persistent=null]
setblock ~25 ~139 ~73 oak_leaves[persistent=null]
setblock ~25 ~139 ~74 jungle_leaves[persistent=null]
setblock ~25 ~139 ~75 jungle_leaves[persistent=null]
setblock ~25 ~140 ~67 jungle_leaves[persistent=null]
setblock ~25 ~140 ~70 oak_leaves[persistent=null]
setblock ~25 ~140 ~71 oak_leaves[persistent=null]
setblock ~25 ~140 ~72 oak_leaves[persistent=null]
setblock ~25 ~140 ~73 oak_leaves[persistent=null]
setblock ~25 ~140 ~75 jungle_leaves[persistent=null]
setblock ~25 ~141 ~71 oak_leaves[persistent=null]
setblock ~25 ~141 ~72 oak_leaves[persistent=null]
setblock ~25 ~141 ~73 jungle_leaves[persistent=null]
setblock ~25 ~141 ~74 oak_leaves[persistent=null]
setblock ~25 ~142 ~70 oak_leaves[persistent=null]
setblock ~25 ~142 ~71 oak_leaves[persistent=null]
setblock ~25 ~142 ~73 oak_leaves[persistent=null]
setblock ~25 ~142 ~74 oak_leaves[persistent=null]
setblock ~25 ~142 ~75 jungle_leaves[persistent=null]
setblock ~26 ~134 ~70 oak_leaves[persistent=null]
setblock ~26 ~134 ~71 jungle_leaves[persistent=null]
setblock ~26 ~134 ~72 oak_leaves[persistent=null]
setblock ~26 ~134 ~73 oak_leaves[persistent=null]
setblock ~26 ~135 ~71 oak_leaves[persistent=null]
setblock ~26 ~135 ~72 oak_leaves[persistent=null]
setblock ~26 ~135 ~74 oak_leaves[persistent=null]
setblock ~26 ~136 ~70 oak_leaves[persistent=null]
setblock ~26 ~136 ~72 oak_wood
setblock ~26 ~136 ~73 oak_leaves[persistent=null]
setblock ~26 ~136 ~76 oak_leaves[persistent=null]
setblock ~26 ~136 ~77 jungle_leaves[persistent=null]
setblock ~26 ~137 ~69 jungle_leaves[persistent=null]
setblock ~26 ~137 ~73 oak_leaves[persistent=null]
setblock ~26 ~137 ~75 jungle_leaves[persistent=null]
setblock ~26 ~137 ~76 oak_leaves[persistent=null]
setblock ~26 ~137 ~77 jungle_leaves[persistent=null]
setblock ~26 ~138 ~67 oak_leaves[persistent=null]
setblock ~26 ~138 ~69 oak_leaves[persistent=null]
setblock ~26 ~138 ~70 oak_leaves[persistent=null]
setblock ~26 ~138 ~71 oak_leaves[persistent=null]
setblock ~26 ~138 ~72 jungle_leaves[persistent=null]
setblock ~26 ~138 ~73 oak_leaves[persistent=null]
setblock ~26 ~138 ~74 oak_leaves[persistent=null]
setblock ~26 ~138 ~75 oak_leaves[persistent=null]
setblock ~26 ~138 ~76 oak_leaves[persistent=null]
setblock ~26 ~138 ~77 oak_leaves[persistent=null]
setblock ~26 ~139 ~69 oak_wood
setblock ~26 ~139 ~70 oak_leaves[persistent=null]
setblock ~26 ~139 ~71 oak_leaves[persistent=null]
setblock ~26 ~139 ~73 oak_leaves[persistent=null]
setblock ~26 ~139 ~75 oak_leaves[persistent=null]
setblock ~26 ~139 ~77 oak_leaves[persistent=null]
setblock ~26 ~140 ~67 oak_leaves[persistent=null]
setblock ~26 ~140 ~70 jungle_leaves[persistent=null]
setblock ~26 ~140 ~71 oak_leaves[persistent=null]
setblock ~26 ~140 ~75 oak_leaves[persistent=null]
setblock ~26 ~141 ~70 oak_leaves[persistent=null]
setblock ~26 ~141 ~71 oak_leaves[persistent=null]
setblock ~26 ~141 ~72 oak_leaves[persistent=null]
setblock ~26 ~141 ~75 oak_leaves[persistent=null]
setblock ~26 ~142 ~70 oak_leaves[persistent=null]
setblock ~26 ~142 ~71 oak_leaves[persistent=null]
setblock ~26 ~142 ~72 oak_leaves[persistent=null]
setblock ~26 ~142 ~73 oak_leaves[persistent=null]
setblock ~26 ~142 ~74 oak_leaves[persistent=null]
setblock ~27 ~133 ~72 jungle_leaves[persistent=null]
setblock ~27 ~133 ~73 oak_leaves[persistent=null]
setblock ~27 ~133 ~74 jungle_leaves[persistent=null]
setblock ~27 ~133 ~75 oak_leaves[persistent=null]
setblock ~27 ~133 ~76 oak_leaves[persistent=null]
setblock ~27 ~134 ~70 oak_leaves[persistent=null]
setblock ~27 ~134 ~71 oak_leaves[persistent=null]
setblock ~27 ~134 ~72 oak_leaves[persistent=null]
setblock ~27 ~134 ~73 jungle_leaves[persistent=null]
setblock ~27 ~134 ~75 oak_leaves[persistent=null]
setblock ~27 ~135 ~70 oak_leaves[persistent=null]
setblock ~27 ~135 ~71 oak_leaves[persistent=null]
setblock ~27 ~135 ~72 jungle_leaves[persistent=null]
setblock ~27 ~135 ~73 oak_leaves[persistent=null]
setblock ~27 ~135 ~76 oak_leaves[persistent=null]
setblock ~27 ~136 ~70 oak_leaves[persistent=null]
setblock ~27 ~136 ~71 oak_leaves[persistent=null]
setblock ~27 ~136 ~73 oak_leaves[persistent=null]
setblock ~27 ~136 ~75 oak_leaves[persistent=null]
setblock ~27 ~136 ~76 oak_leaves[persistent=null]
setblock ~27 ~136 ~77 oak_leaves[persistent=null]
setblock ~27 ~137 ~69 oak_leaves[persistent=null]
setblock ~27 ~137 ~71 oak_leaves[persistent=null]
setblock ~27 ~137 ~72 oak_wood
setblock ~27 ~137 ~73 oak_leaves[persistent=null]
setblock ~27 ~137 ~75 oak_leaves[persistent=null]
setblock ~27 ~137 ~76 oak_leaves[persistent=null]
setblock ~27 ~137 ~77 oak_leaves[persistent=null]
setblock ~27 ~138 ~69 oak_leaves[persistent=null]
setblock ~27 ~138 ~72 oak_leaves[persistent=null]
setblock ~27 ~138 ~73 oak_leaves[persistent=null]
setblock ~27 ~138 ~74 oak_leaves[persistent=null]
setblock ~27 ~138 ~75 oak_leaves[persistent=null]
setblock ~27 ~138 ~76 oak_leaves[persistent=null]
setblock ~27 ~139 ~69 oak_leaves[persistent=null]
setblock ~27 ~139 ~70 oak_wood
setblock ~27 ~139 ~71 jungle_leaves[persistent=null]
setblock ~27 ~139 ~74 oak_leaves[persistent=null]
setblock ~27 ~139 ~75 oak_leaves[persistent=null]
setblock ~27 ~139 ~76 oak_leaves[persistent=null]
setblock ~27 ~140 ~68 oak_leaves[persistent=null]
setblock ~27 ~140 ~69 oak_leaves[persistent=null]
setblock ~27 ~140 ~70 oak_leaves[persistent=null]
setblock ~27 ~140 ~71 oak_leaves[persistent=null]
setblock ~27 ~140 ~72 oak_leaves[persistent=null]
setblock ~27 ~140 ~73 oak_leaves[persistent=null]
setblock ~27 ~140 ~74 oak_leaves[persistent=null]
setblock ~27 ~140 ~75 oak_leaves[persistent=null]
setblock ~27 ~140 ~77 oak_leaves[persistent=null]
setblock ~27 ~141 ~71 oak_leaves[persistent=null]
setblock ~27 ~141 ~73 oak_leaves[persistent=null]
setblock ~27 ~141 ~75 jungle_leaves[persistent=null]
setblock ~27 ~141 ~76 oak_leaves[persistent=null]
setblock ~27 ~141 ~77 jungle_leaves[persistent=null]
setblock ~27 ~142 ~70 oak_leaves[persistent=null]
setblock ~27 ~142 ~71 oak_leaves[persistent=null]
setblock ~27 ~142 ~73 oak_wood
setblock ~27 ~142 ~74 oak_leaves[persistent=null]
setblock ~27 ~142 ~75 oak_leaves[persistent=null]
setblock ~27 ~142 ~76 oak_leaves[persistent=null]
setblock ~27 ~142 ~77 oak_leaves[persistent=null]
setblock ~28 ~133 ~74 oak_leaves[persistent=null]
setblock ~28 ~134 ~70 oak_leaves[persistent=null]
setblock ~28 ~134 ~71 oak_leaves[persistent=null]
setblock ~28 ~134 ~72 oak_leaves[persistent=null]
setblock ~28 ~134 ~73 oak_leaves[persistent=null]
setblock ~28 ~134 ~74 oak_wood
setblock ~28 ~134 ~75 oak_wood
setblock ~28 ~134 ~76 oak_leaves[persistent=null]
setblock ~28 ~135 ~69 oak_leaves[persistent=null]
setblock ~28 ~135 ~71 oak_leaves[persistent=null]
setblock ~28 ~135 ~72 oak_leaves[persistent=null]
setblock ~28 ~135 ~73 oak_leaves[persistent=null]
setblock ~28 ~135 ~74 oak_leaves[persistent=null]
setblock ~28 ~135 ~75 jungle_leaves[persistent=null]
setblock ~28 ~136 ~69 jungle_leaves[persistent=null]
setblock ~28 ~136 ~75 oak_leaves[persistent=null]
setblock ~28 ~136 ~76 jungle_leaves[persistent=null]
setblock ~28 ~137 ~69 oak_leaves[persistent=null]
setblock ~28 ~137 ~70 oak_leaves[persistent=null]
setblock ~28 ~137 ~71 oak_leaves[persistent=null]
setblock ~28 ~137 ~72 oak_wood
setblock ~28 ~137 ~74 oak_leaves[persistent=null]
setblock ~28 ~137 ~76 oak_wood
setblock ~28 ~137 ~77 oak_wood
setblock ~28 ~138 ~69 oak_leaves[persistent=null]
setblock ~28 ~138 ~70 oak_leaves[persistent=null]
setblock ~28 ~138 ~71 oak_wood
setblock ~28 ~138 ~72 oak_leaves[persistent=null]
setblock ~28 ~138 ~74 oak_leaves[persistent=null]
setblock ~28 ~138 ~75 oak_leaves[persistent=null]
setblock ~28 ~138 ~76 oak_wood
setblock ~28 ~138 ~77 oak_leaves[persistent=null]
setblock ~28 ~138 ~78 oak_leaves[persistent=null]
setblock ~28 ~139 ~70 oak_leaves[persistent=null]
setblock ~28 ~139 ~71 oak_leaves[persistent=null]
setblock ~28 ~139 ~72 oak_leaves[persistent=null]
setblock ~28 ~139 ~73 oak_leaves[persistent=null]
setblock ~28 ~139 ~74 jungle_leaves[persistent=null]
setblock ~28 ~139 ~75 oak_leaves[persistent=null]
setblock ~28 ~139 ~76 oak_leaves[persistent=null]
setblock ~28 ~140 ~69 jungle_leaves[persistent=null]
setblock ~28 ~140 ~70 oak_leaves[persistent=null]
setblock ~28 ~140 ~71 jungle_leaves[persistent=null]
setblock ~28 ~140 ~72 oak_leaves[persistent=null]
setblock ~28 ~140 ~73 oak_log
setblock ~28 ~140 ~74 oak_leaves[persistent=null]
setblock ~28 ~140 ~75 oak_leaves[persistent=null]
setblock ~28 ~140 ~76 oak_leaves[persistent=null]
setblock ~28 ~140 ~78 oak_leaves[persistent=null]
setblock ~28 ~141 ~70 oak_leaves[persistent=null]
setblock ~28 ~141 ~72 oak_leaves[persistent=null]
setblock ~28 ~141 ~73 oak_wood
setblock ~28 ~141 ~74 oak_leaves[persistent=null]
setblock ~28 ~141 ~76 oak_leaves[persistent=null]
setblock ~28 ~141 ~77 oak_leaves[persistent=null]
setblock ~28 ~141 ~78 jungle_leaves[persistent=null]
setblock ~28 ~142 ~71 oak_leaves[persistent=null]
setblock ~28 ~142 ~72 jungle_leaves[persistent=null]
setblock ~28 ~142 ~73 oak_leaves[persistent=null]
setblock ~28 ~142 ~74 jungle_leaves[persistent=null]
setblock ~28 ~142 ~75 oak_leaves[persistent=null]
setblock ~28 ~142 ~76 oak_leaves[persistent=null]
setblock ~29 ~120 ~75 dirt
setblock ~29 ~121 ~74 dirt
setblock ~29 ~121 ~75 dirt
setblock ~29 ~121 ~76 dirt
setblock ~29 ~121 ~78 dirt
setblock ~29 ~122 ~74 dirt
setblock ~29 ~122 ~75 dirt
setblock ~29 ~122 ~76 dirt
setblock ~29 ~122 ~78 dirt
setblock ~29 ~123 ~74 dirt
setblock ~29 ~123 ~75 dirt
setblock ~29 ~123 ~76 dirt
setblock ~29 ~123 ~78 dirt
setblock ~29 ~124 ~74 dirt
setblock ~29 ~124 ~75 dirt
setblock ~29 ~124 ~76 dirt
setblock ~29 ~124 ~78 dirt
setblock ~29 ~125 ~74 dirt
setblock ~29 ~125 ~75 dirt
setblock ~29 ~125 ~76 dirt
setblock ~29 ~125 ~78 grass_block
setblock ~29 ~126 ~74 dirt
setblock ~29 ~126 ~75 grass_block
setblock ~29 ~126 ~76 grass_block
setblock ~29 ~127 ~74 grass_block
setblock ~29 ~127 ~75 poppy
setblock ~29 ~133 ~73 oak_leaves[persistent=null]
setblock ~29 ~133 ~74 oak_leaves[persistent=null]
setblock ~29 ~134 ~70 oak_leaves[persistent=null]
setblock ~29 ~134 ~71 jungle_leaves[persistent=null]
setblock ~29 ~134 ~72 oak_leaves[persistent=null]
setblock ~29 ~134 ~73 oak_leaves[persistent=null]
setblock ~29 ~134 ~74 oak_leaves[persistent=null]
setblock ~29 ~134 ~75 oak_leaves[persistent=null]
setblock ~29 ~134 ~76 oak_leaves[persistent=null]
setblock ~29 ~135 ~69 oak_leaves[persistent=null]
setblock ~29 ~135 ~70 oak_leaves[persistent=null]
setblock ~29 ~135 ~71 oak_leaves[persistent=null]
setblock ~29 ~135 ~72 oak_leaves[persistent=null]
setblock ~29 ~135 ~73 oak_leaves[persistent=null]
setblock ~29 ~135 ~74 oak_wood
setblock ~29 ~135 ~75 jungle_leaves[persistent=null]
setblock ~29 ~135 ~76 oak_leaves[persistent=null]
setblock ~29 ~136 ~69 oak_leaves[persistent=null]
setblock ~29 ~136 ~71 oak_wood
setblock ~29 ~136 ~72 oak_wood
setblock ~29 ~136 ~73 oak_wood
setblock ~29 ~136 ~76 oak_leaves[persistent=null]
setblock ~29 ~136 ~77 oak_leaves[persistent=null]
setblock ~29 ~137 ~69 oak_leaves[persistent=null]
setblock ~29 ~137 ~70 oak_leaves[persistent=null]
setblock ~29 ~137 ~72 jungle_leaves[persistent=null]
setblock ~29 ~137 ~73 oak_leaves[persistent=null]
setblock ~29 ~137 ~74 oak_leaves[persistent=null]
setblock ~29 ~137 ~76 oak_leaves[persistent=null]
setblock ~29 ~137 ~77 oak_leaves[persistent=null]
setblock ~29 ~138 ~72 oak_wood
setblock ~29 ~138 ~73 oak_wood
setblock ~29 ~138 ~74 oak_wood
setblock ~29 ~138 ~75 oak_wood
setblock ~29 ~138 ~76 oak_leaves[persistent=null]
setblock ~29 ~138 ~78 jungle_leaves[persistent=null]
setblock ~29 ~139 ~69 oak_leaves[persistent=null]
setblock ~29 ~139 ~71 jungle_leaves[persistent=null]
setblock ~29 ~139 ~72 oak_leaves[persistent=null]
setblock ~29 ~139 ~73 oak_log
setblock ~29 ~139 ~74 oak_leaves[persistent=null]
setblock ~29 ~139 ~75 oak_wood
setblock ~29 ~139 ~77 oak_leaves[persistent=null]
setblock ~29 ~139 ~78 oak_leaves[persistent=null]
setblock ~29 ~139 ~79 oak_leaves[persistent=null]
setblock ~29 ~140 ~70 oak_leaves[persistent=null]
setblock ~29 ~140 ~71 oak_leaves[persistent=null]
setblock ~29 ~140 ~73 oak_leaves[persistent=null]
setblock ~29 ~140 ~74 oak_log
setblock ~29 ~140 ~75 oak_leaves[persistent=null]
setblock ~29 ~140 ~76 oak_leaves[persistent=null]
setblock ~29 ~140 ~77 oak_leaves[persistent=null]
setblock ~29 ~140 ~79 oak_leaves[persistent=null]
setblock ~29 ~140 ~80 oak_leaves[persistent=null]
setblock ~29 ~141 ~70 oak_leaves[persistent=null]
setblock ~29 ~141 ~72 jungle_leaves[persistent=null]
setblock ~29 ~141 ~74 oak_leaves[persistent=null]
setblock ~29 ~141 ~75 oak_leaves[persistent=null]
setblock ~29 ~141 ~78 jungle_leaves[persistent=null]
setblock ~29 ~141 ~80 oak_leaves[persistent=null]
setblock ~29 ~142 ~71 oak_leaves[persistent=null]
setblock ~29 ~142 ~72 oak_leaves[persistent=null]
setblock ~29 ~142 ~73 oak_leaves[persistent=null]
setblock ~29 ~142 ~74 jungle_leaves[persistent=null]
setblock ~29 ~142 ~75 oak_leaves[persistent=null]
setblock ~29 ~142 ~76 oak_leaves[persistent=null]
setblock ~29 ~142 ~78 oak_leaves[persistent=null]
setblock ~29 ~142 ~79 oak_leaves[persistent=null]
setblock ~29 ~142 ~80 oak_leaves[persistent=null]
setblock ~29 ~143 ~77 oak_leaves[persistent=null]
setblock ~29 ~143 ~78 jungle_leaves[persistent=null]
setblock ~29 ~143 ~80 oak_leaves[persistent=null]
setblock ~30 ~117 ~76 dirt
setblock ~30 ~118 ~76 dirt
setblock ~30 ~119 ~75 dirt
setblock ~30 ~119 ~76 dirt
setblock ~30 ~120 ~74 dirt
setblock ~30 ~120 ~75 dirt
setblock ~30 ~120 ~76 dirt
setblock ~30 ~120 ~78 dirt
setblock ~30 ~121 ~68 dirt
setblock ~30 ~121 ~73 dirt
setblock ~30 ~121 ~74 dirt
setblock ~30 ~121 ~75 dirt
setblock ~30 ~121 ~76 dirt
setblock ~30 ~121 ~77 dirt
setblock ~30 ~121 ~78 dirt
setblock ~30 ~121 ~79 dirt
setblock ~30 ~121 ~80 dirt
setblock ~30 ~122 ~68 dirt
setblock ~30 ~122 ~73 dirt
setblock ~30 ~122 ~74 dirt
setblock ~30 ~122 ~75 dirt
setblock ~30 ~122 ~76 dirt
setblock ~30 ~122 ~77 dirt
setblock ~30 ~122 ~78 dirt
setblock ~30 ~122 ~79 dirt
setblock ~30 ~122 ~80 dirt
setblock ~30 ~123 ~68 dirt
setblock ~30 ~123 ~73 dirt
setblock ~30 ~123 ~74 dirt
setblock ~30 ~123 ~75 dirt
setblock ~30 ~123 ~76 dirt
setblock ~30 ~123 ~77 dirt
setblock ~30 ~123 ~78 dirt
setblock ~30 ~123 ~79 dirt
setblock ~30 ~123 ~80 dirt
setblock ~30 ~124 ~68 dirt
setblock ~30 ~124 ~73 dirt
setblock ~30 ~124 ~74 dirt
setblock ~30 ~124 ~75 dirt
setblock ~30 ~124 ~76 dirt
setblock ~30 ~124 ~77 dirt
setblock ~30 ~124 ~78 dirt
setblock ~30 ~124 ~79 dirt
setblock ~30 ~124 ~80 grass_block
setblock ~30 ~125 ~68 dirt
setblock ~30 ~125 ~73 dirt
setblock ~30 ~125 ~74 dirt
setblock ~30 ~125 ~75 dirt
setblock ~30 ~125 ~76 dirt
setblock ~30 ~125 ~77 dirt
setblock ~30 ~125 ~78 grass_block
setblock ~30 ~125 ~79 grass_block
setblock ~30 ~125 ~80 short_grass
setblock ~30 ~126 ~68 dirt
setblock ~30 ~126 ~73 dirt
setblock ~30 ~126 ~74 dirt
setblock ~30 ~126 ~75 dirt
setblock ~30 ~126 ~76 grass_block
setblock ~30 ~126 ~77 grass_block
setblock ~30 ~127 ~68 grass_block
setblock ~30 ~127 ~73 grass_block
setblock ~30 ~127 ~74 grass_block
setblock ~30 ~127 ~75 grass_block
setblock ~30 ~127 ~76 short_grass
setblock ~30 ~132 ~65 oak_leaves[persistent=null]
setblock ~30 ~133 ~65 oak_leaves[persistent=null]
setblock ~30 ~133 ~67 oak_leaves[persistent=null]
setblock ~30 ~133 ~68 oak_leaves[persistent=null]
setblock ~30 ~133 ~72 oak_leaves[persistent=null]
setblock ~30 ~133 ~75 oak_leaves[persistent=null]
setblock ~30 ~134 ~66 jungle_leaves[persistent=null]
setblock ~30 ~134 ~67 oak_leaves[persistent=null]
setblock ~30 ~134 ~68 jungle_leaves[persistent=null]
setblock ~30 ~134 ~71 jungle_leaves[persistent=null]
setblock ~30 ~134 ~72 jungle_leaves[persistent=null]
setblock ~30 ~134 ~73 oak_leaves[persistent=null]
setblock ~30 ~134 ~74 oak_leaves[persistent=null]
setblock ~30 ~134 ~75 oak_leaves[persistent=null]
setblock ~30 ~135 ~65 oak_leaves[persistent=null]
setblock ~30 ~135 ~66 oak_leaves[persistent=null]
setblock ~30 ~135 ~67 oak_leaves[persistent=null]
setblock ~30 ~135 ~68 oak_leaves[persistent=null]
setblock ~30 ~135 ~71 oak_leaves[persistent=null]
setblock ~30 ~135 ~72 jungle_leaves[persistent=null]
setblock ~30 ~135 ~73 oak_leaves[persistent=null]
setblock ~30 ~135 ~75 jungle_leaves[persistent=null]
setblock ~30 ~136 ~71 oak_leaves[persistent=null]
setblock ~30 ~136 ~72 oak_leaves[persistent=null]
setblock ~30 ~136 ~73 oak_leaves[persistent=null]
setblock ~30 ~136 ~74 oak_wood
setblock ~30 ~136 ~75 jungle_leaves[persistent=null]
setblock ~30 ~136 ~76 oak_leaves[persistent=null]
setblock ~30 ~136 ~77 jungle_leaves[persistent=null]
setblock ~30 ~136 ~78 oak_leaves[persistent=null]
setblock ~30 ~136 ~79 oak_leaves[persistent=null]
setblock ~30 ~137 ~70 jungle_leaves[persistent=null]
setblock ~30 ~137 ~72 oak_leaves[persistent=null]
setblock ~30 ~137 ~73 oak_leaves[persistent=null]
setblock ~30 ~137 ~74 oak_log
setblock ~30 ~137 ~76 oak_leaves[persistent=null]
setblock ~30 ~137 ~78 oak_leaves[persistent=null]
setblock ~30 ~137 ~79 oak_leaves[persistent=null]
setblock ~30 ~138 ~70 oak_leaves[persistent=null]
setblock ~30 ~138 ~71 oak_leaves[persistent=null]
setblock ~30 ~138 ~72 oak_leaves[persistent=null]
setblock ~30 ~138 ~74 oak_leaves[persistent=null]
setblock ~30 ~138 ~78 oak_leaves[persistent=null]
setblock ~30 ~138 ~79 oak_leaves[persistent=null]
setblock ~30 ~139 ~71 oak_leaves[persistent=null]
setblock ~30 ~139 ~72 oak_leaves[persistent=null]
setblock ~30 ~139 ~73 oak_wood
setblock ~30 ~139 ~74 oak_wood
setblock ~30 ~139 ~75 oak_wood
setblock ~30 ~139 ~77 oak_leaves[persistent=null]
setblock ~30 ~139 ~79 oak_leaves[persistent=null]
setblock ~30 ~140 ~71 oak_leaves[persistent=null]
setblock ~30 ~140 ~72 oak_leaves[persistent=null]
setblock ~30 ~140 ~73 oak_wood
setblock ~30 ~140 ~75 oak_log
setblock ~30 ~140 ~76 oak_wood
setblock ~30 ~140 ~77 oak_wood
setblock ~30 ~140 ~79 oak_leaves[persistent=null]
setblock ~30 ~140 ~80 oak_leaves[persistent=null]
setblock ~30 ~141 ~71 oak_leaves[persistent=null]
setblock ~30 ~141 ~72 oak_leaves[persistent=null]
setblock ~30 ~141 ~73 oak_leaves[persistent=null]
setblock ~30 ~141 ~74 oak_leaves[persistent=null]
setblock ~30 ~141 ~76 oak_leaves[persistent=null]
setblock ~30 ~141 ~77 oak_wood
setblock ~30 ~141 ~78 oak_leaves[persistent=null]
setblock ~30 ~141 ~79 oak_leaves[persistent=null]
setblock ~30 ~141 ~80 oak_leaves[persistent=null]
setblock ~30 ~142 ~72 oak_leaves[persistent=null]
setblock ~30 ~142 ~74 jungle_leaves[persistent=null]
setblock ~30 ~142 ~75 oak_leaves[persistent=null]
setblock ~30 ~142 ~77 jungle_leaves[persistent=null]
setblock ~30 ~142 ~79 oak_leaves[persistent=null]
setblock ~30 ~142 ~80 oak_leaves[persistent=null]
setblock ~30 ~143 ~77 oak_leaves[persistent=null]
setblock ~30 ~143 ~78 oak_leaves[persistent=null]
setblock ~31 ~114 ~76 dirt
setblock ~31 ~115 ~75 dirt
setblock ~31 ~115 ~76 dirt
setblock ~31 ~116 ~75 dirt
setblock ~31 ~116 ~76 dirt
setblock ~31 ~117 ~74 dirt
setblock ~31 ~117 ~75 dirt
setblock ~31 ~117 ~76 dirt
setblock ~31 ~117 ~77 dirt
setblock ~31 ~118 ~74 dirt
setblock ~31 ~118 ~75 dirt
setblock ~31 ~118 ~76 dirt
setblock ~31 ~118 ~77 dirt
setblock ~31 ~118 ~78 dirt
setblock ~31 ~119 ~69 dirt
setblock ~31 ~119 ~73 dirt
setblock ~31 ~119 ~74 dirt
setblock ~31 ~119 ~75 dirt
setblock ~31 ~119 ~76 dirt
setblock ~31 ~119 ~77 dirt
setblock ~31 ~119 ~78 dirt
setblock ~31 ~120 ~68 dirt
setblock ~31 ~120 ~69 dirt
setblock ~31 ~120 ~71 dirt
setblock ~31 ~120 ~72 dirt
setblock ~31 ~120 ~73 dirt
setblock ~31 ~120 ~74 dirt
setblock ~31 ~120 ~75 dirt
setblock ~31 ~120 ~76 dirt
setblock ~31 ~120 ~77 dirt
setblock ~31 ~120 ~78 dirt
setblock ~31 ~120 ~79 dirt
setblock ~31 ~120 ~80 dirt
setblock ~31 ~121 ~67 dirt
setblock ~31 ~121 ~68 dirt
setblock ~31 ~121 ~69 dirt
setblock ~31 ~121 ~71 dirt
setblock ~31 ~121 ~72 dirt
setblock ~31 ~121 ~73 dirt
setblock ~31 ~121 ~74 dirt
setblock ~31 ~121 ~75 dirt
setblock ~31 ~121 ~76 dirt
setblock ~31 ~121 ~77 dirt
setblock ~31 ~121 ~78 dirt
setblock ~31 ~121 ~79 dirt
setblock ~31 ~121 ~80 dirt
setblock ~31 ~121 ~81 dirt
setblock ~31 ~122 ~67 dirt
setblock ~31 ~122 ~68 dirt
setblock ~31 ~122 ~69 dirt
setblock ~31 ~122 ~71 dirt
setblock ~31 ~122 ~72 dirt
setblock ~31 ~122 ~73 dirt
setblock ~31 ~122 ~74 dirt
setblock ~31 ~122 ~75 dirt
setblock ~31 ~122 ~76 dirt
setblock ~31 ~122 ~77 dirt
setblock ~31 ~122 ~78 dirt
setblock ~31 ~122 ~79 dirt
setblock ~31 ~122 ~80 dirt
setblock ~31 ~122 ~81 dirt
setblock ~31 ~123 ~67 dirt
setblock ~31 ~123 ~68 dirt
setblock ~31 ~123 ~69 dirt
setblock ~31 ~123 ~71 dirt
setblock ~31 ~123 ~72 dirt
setblock ~31 ~123 ~73 dirt
setblock ~31 ~123 ~74 dirt
setblock ~31 ~123 ~75 dirt
setblock ~31 ~123 ~76 dirt
setblock ~31 ~123 ~77 dirt
setblock ~31 ~123 ~78 dirt
setblock ~31 ~123 ~79 dirt
setblock ~31 ~123 ~80 dirt
setblock ~31 ~123 ~81 dirt
setblock ~31 ~124 ~67 dirt
setblock ~31 ~124 ~68 dirt
setblock ~31 ~124 ~69 dirt
setblock ~31 ~124 ~71 dirt
setblock ~31 ~124 ~72 dirt
setblock ~31 ~124 ~73 dirt
setblock ~31 ~124 ~74 dirt
setblock ~31 ~124 ~75 dirt
setblock ~31 ~124 ~76 dirt
setblock ~31 ~124 ~77 dirt
setblock ~31 ~124 ~78 dirt
setblock ~31 ~124 ~79 dirt
setblock ~31 ~124 ~80 dirt
setblock ~31 ~124 ~81 grass_block
setblock ~31 ~125 ~67 dirt
setblock ~31 ~125 ~68 dirt
setblock ~31 ~125 ~69 dirt
setblock ~31 ~125 ~71 dirt
setblock ~31 ~125 ~72 dirt
setblock ~31 ~125 ~73 dirt
setblock ~31 ~125 ~74 dirt
setblock ~31 ~125 ~75 dirt
setblock ~31 ~125 ~76 dirt
setblock ~31 ~125 ~77 dirt
setblock ~31 ~125 ~78 grass_block
setblock ~31 ~125 ~79 grass_block
setblock ~31 ~125 ~80 grass_block
setblock ~31 ~126 ~67 grass_block
setblock ~31 ~126 ~68 dirt
setblock ~31 ~126 ~69 dirt
setblock ~31 ~126 ~71 dirt
setblock ~31 ~126 ~72 dirt
setblock ~31 ~126 ~73 dirt
setblock ~31 ~126 ~74 dirt
setblock ~31 ~126 ~75 grass_block
setblock ~31 ~126 ~76 grass_block
setblock ~31 ~126 ~77 grass_block
setblock ~31 ~126 ~79 short_grass
setblock ~31 ~127 ~67 short_grass
setblock ~31 ~127 ~68 grass_block
setblock ~31 ~127 ~69 dirt
setblock ~31 ~127 ~71 dirt
setblock ~31 ~127 ~72 dirt
setblock ~31 ~127 ~73 grass_block
setblock ~31 ~127 ~74 grass_block
setblock ~31 ~128 ~69 grass_block
setblock ~31 ~128 ~71 grass_block
setblock ~31 ~128 ~72 grass_block
setblock ~31 ~132 ~65 oak_leaves[persistent=null]
setblock ~31 ~132 ~66 oak_leaves[persistent=null]
setblock ~31 ~132 ~67 oak_leaves[persistent=null]
setblock ~31 ~132 ~68 jungle_leaves[persistent=null]
setblock ~31 ~132 ~73 jungle_leaves[persistent=null]
setblock ~31 ~132 ~74 oak_leaves[persistent=null]
setblock ~31 ~133 ~65 jungle_leaves[persistent=null]
setblock ~31 ~133 ~68 oak_leaves[persistent=null]
setblock ~31 ~133 ~73 oak_leaves[persistent=null]
setblock ~31 ~133 ~74 oak_leaves[persistent=null]
setblock ~31 ~133 ~75 spruce_slab[type=null]
setblock ~31 ~133 ~76 oak_leaves[persistent=null]
setblock ~31 ~134 ~65 oak_leaves[persistent=null]
setblock ~31 ~134 ~66 oak_leaves[persistent=null]
setblock ~31 ~134 ~67 oak_wood
setblock ~31 ~134 ~68 oak_leaves[persistent=null]
setblock ~31 ~134 ~73 oak_leaves[persistent=null]
setblock ~31 ~134 ~74 oak_leaves[persistent=null]
setblock ~31 ~134 ~75 oak_log
setblock ~31 ~134 ~76 oak_leaves[persistent=null]
setblock ~31 ~135 ~66 jungle_leaves[persistent=null]
setblock ~31 ~135 ~70 oak_leaves[persistent=null]
setblock ~31 ~135 ~71 oak_leaves[persistent=null]
setblock ~31 ~135 ~72 oak_leaves[persistent=null]
setblock ~31 ~135 ~73 oak_leaves[persistent=null]
setblock ~31 ~135 ~74 oak_leaves[persistent=null]
setblock ~31 ~135 ~75 oak_log
setblock ~31 ~135 ~76 oak_leaves[persistent=null]
setblock ~31 ~136 ~70 oak_leaves[persistent=null]
setblock ~31 ~136 ~71 oak_leaves[persistent=null]
setblock ~31 ~136 ~72 oak_leaves[persistent=null]
setblock ~31 ~136 ~74 oak_leaves[persistent=null]
setblock ~31 ~136 ~75 oak_leaves[persistent=null]
setblock ~31 ~136 ~77 oak_leaves[persistent=null]
setblock ~31 ~136 ~78 oak_leaves[persistent=null]
setblock ~31 ~136 ~79 oak_leaves[persistent=null]
setblock ~31 ~136 ~80 oak_leaves[persistent=null]
setblock ~31 ~137 ~70 oak_leaves[persistent=null]
setblock ~31 ~137 ~71 oak_leaves[persistent=null]
setblock ~31 ~137 ~74 jungle_leaves[persistent=null]
setblock ~31 ~137 ~75 oak_leaves[persistent=null]
setblock ~31 ~137 ~76 oak_leaves[persistent=null]
setblock ~31 ~137 ~77 oak_leaves[persistent=null]
setblock ~31 ~137 ~78 oak_leaves[persistent=null]
setblock ~31 ~137 ~79 jungle_leaves[persistent=null]
setblock ~31 ~137 ~80 oak_leaves[persistent=null]
setblock ~31 ~138 ~71 oak_leaves[persistent=null]
setblock ~31 ~138 ~72 jungle_leaves[persistent=null]
setblock ~31 ~138 ~73 jungle_leaves[persistent=null]
setblock ~31 ~138 ~74 oak_wood
setblock ~31 ~138 ~75 oak_wood
setblock ~31 ~138 ~76 oak_wood
setblock ~31 ~138 ~78 oak_leaves[persistent=null]
setblock ~31 ~138 ~80 oak_leaves[persistent=null]
setblock ~31 ~139 ~70 jungle_leaves[persistent=null]
setblock ~31 ~139 ~71 jungle_leaves[persistent=null]
setblock ~31 ~139 ~72 jungle_leaves[persistent=null]
setblock ~31 ~139 ~73 oak_wood
setblock ~31 ~139 ~74 oak_wood
setblock ~31 ~139 ~75 oak_leaves[persistent=null]
setblock ~31 ~139 ~76 oak_leaves[persistent=null]
setblock ~31 ~139 ~77 oak_leaves[persistent=null]
setblock ~31 ~139 ~79 oak_leaves[persistent=null]
setblock ~31 ~139 ~80 oak_leaves[persistent=null]
setblock ~31 ~140 ~70 oak_leaves[persistent=null]
setblock ~31 ~140 ~76 oak_leaves[persistent=null]
setblock ~31 ~140 ~77 oak_leaves[persistent=null]
setblock ~31 ~140 ~78 oak_leaves[persistent=null]
setblock ~31 ~140 ~79 jungle_leaves[persistent=null]
setblock ~31 ~140 ~80 oak_leaves[persistent=null]
setblock ~31 ~141 ~71 oak_leaves[persistent=null]
setblock ~31 ~141 ~72 oak_leaves[persistent=null]
setblock ~31 ~141 ~73 oak_leaves[persistent=null]
setblock ~31 ~141 ~75 oak_leaves[persistent=null]
setblock ~31 ~141 ~76 oak_leaves[persistent=null]
setblock ~31 ~141 ~78 oak_wood
setblock ~31 ~141 ~79 oak_leaves[persistent=null]
setblock ~31 ~142 ~74 oak_leaves[persistent=null]
setblock ~31 ~142 ~77 oak_leaves[persistent=null]
setblock ~31 ~142 ~78 jungle_leaves[persistent=null]
setblock ~31 ~142 ~79 oak_leaves[persistent=null]
setblock ~31 ~142 ~80 oak_leaves[persistent=null]
setblock ~31 ~143 ~77 jungle_leaves[persistent=null]
setblock ~31 ~143 ~78 oak_leaves[persistent=null]
setblock ~31 ~143 ~79 oak_leaves[persistent=null]
setblock ~31 ~143 ~80 jungle_leaves[persistent=null]
setblock ~32 ~113 ~76 dirt
setblock ~32 ~114 ~75 dirt
setblock ~32 ~114 ~76 dirt
setblock ~32 ~114 ~77 dirt
setblock ~32 ~115 ~74 dirt
setblock ~32 ~115 ~75 dirt
setblock ~32 ~115 ~76 dirt
setblock ~32 ~115 ~77 dirt
setblock ~32 ~116 ~69 dirt
setblock ~32 ~116 ~74 dirt
setblock ~32 ~116 ~75 dirt
setblock ~32 ~116 ~76 dirt
setblock ~32 ~116 ~77 dirt
setblock ~32 ~117 ~68 dirt
setblock ~32 ~117 ~69 dirt
setblock ~32 ~117 ~73 dirt
setblock ~32 ~117 ~74 dirt
setblock ~32 ~117 ~75 dirt
setblock ~32 ~117 ~76 dirt
setblock ~32 ~117 ~77 dirt
setblock ~32 ~117 ~78 dirt
setblock ~32 ~118 ~68 dirt
setblock ~32 ~118 ~69 dirt
setblock ~32 ~118 ~70 dirt
setblock ~32 ~118 ~71 dirt
setblock ~32 ~118 ~72 dirt
setblock ~32 ~118 ~73 dirt
setblock ~32 ~118 ~74 dirt
setblock ~32 ~118 ~75 dirt
setblock ~32 ~118 ~76 dirt
setblock ~32 ~118 ~77 dirt
setblock ~32 ~118 ~78 dirt
setblock ~32 ~118 ~79 dirt
setblock ~32 ~119 ~68 dirt
setblock ~32 ~119 ~69 dirt
setblock ~32 ~119 ~70 dirt
setblock ~32 ~119 ~71 dirt
setblock ~32 ~119 ~72 dirt
setblock ~32 ~119 ~73 dirt
setblock ~32 ~119 ~74 dirt
setblock ~32 ~119 ~75 dirt
setblock ~32 ~119 ~76 dirt
setblock ~32 ~119 ~77 dirt
setblock ~32 ~119 ~78 dirt
setblock ~32 ~119 ~79 dirt
setblock ~32 ~119 ~80 dirt
setblock ~32 ~120 ~67 dirt
setblock ~32 ~120 ~68 dirt
setblock ~32 ~120 ~69 dirt
setblock ~32 ~120 ~70 dirt
setblock ~32 ~120 ~71 dirt
setblock ~32 ~120 ~72 dirt
setblock ~32 ~120 ~73 dirt
setblock ~32 ~120 ~74 dirt
setblock ~32 ~120 ~75 dirt
setblock ~32 ~120 ~76 dirt
setblock ~32 ~120 ~77 dirt
setblock ~32 ~120 ~78 dirt
setblock ~32 ~120 ~79 dirt
setblock ~32 ~120 ~80 dirt
setblock ~32 ~120 ~81 dirt
setblock ~32 ~121 ~62 dirt
setblock ~32 ~121 ~66 dirt
setblock ~32 ~121 ~67 dirt
setblock ~32 ~121 ~68 dirt
setblock ~32 ~121 ~69 dirt
setblock ~32 ~121 ~70 dirt
setblock ~32 ~121 ~71 dirt
setblock ~32 ~121 ~72 dirt
setblock ~32 ~121 ~73 dirt
setblock ~32 ~121 ~74 dirt
setblock ~32 ~121 ~75 dirt
setblock ~32 ~121 ~76 dirt
setblock ~32 ~121 ~77 dirt
setblock ~32 ~121 ~78 dirt
setblock ~32 ~121 ~79 dirt
setblock ~32 ~121 ~80 dirt
setblock ~32 ~121 ~81 dirt
setblock ~32 ~121 ~100 dirt
setblock ~32 ~122 ~62 dirt
setblock ~32 ~122 ~66 dirt
setblock ~32 ~122 ~67 dirt
setblock ~32 ~122 ~68 dirt
setblock ~32 ~122 ~69 dirt
setblock ~32 ~122 ~70 dirt
setblock ~32 ~122 ~71 dirt
setblock ~32 ~122 ~72 dirt
setblock ~32 ~122 ~73 dirt
setblock ~32 ~122 ~74 dirt
setblock ~32 ~122 ~75 dirt
setblock ~32 ~122 ~76 dirt
setblock ~32 ~122 ~77 dirt
setblock ~32 ~122 ~78 dirt
setblock ~32 ~122 ~79 dirt
setblock ~32 ~122 ~80 dirt
setblock ~32 ~122 ~81 dirt
setblock ~32 ~122 ~100 dirt
setblock ~32 ~123 ~62 grass_block
setblock ~32 ~123 ~66 dirt
setblock ~32 ~123 ~67 dirt
setblock ~32 ~123 ~68 dirt
setblock ~32 ~123 ~69 dirt
setblock ~32 ~123 ~70 dirt
setblock ~32 ~123 ~71 dirt
setblock ~32 ~123 ~72 dirt
setblock ~32 ~123 ~73 dirt
setblock ~32 ~123 ~74 dirt
setblock ~32 ~123 ~75 dirt
setblock ~32 ~123 ~76 dirt
setblock ~32 ~123 ~77 dirt
setblock ~32 ~123 ~78 dirt
setblock ~32 ~123 ~79 dirt
setblock ~32 ~123 ~80 dirt
setblock ~32 ~123 ~81 dirt
setblock ~32 ~123 ~100 dirt
setblock ~32 ~124 ~66 dirt
setblock ~32 ~124 ~67 dirt
setblock ~32 ~124 ~68 dirt
setblock ~32 ~124 ~69 dirt
setblock ~32 ~124 ~70 dirt
setblock ~32 ~124 ~71 dirt
setblock ~32 ~124 ~72 dirt
setblock ~32 ~124 ~73 dirt
setblock ~32 ~124 ~74 dirt
setblock ~32 ~124 ~75 dirt
setblock ~32 ~124 ~76 dirt
setblock ~32 ~124 ~77 dirt
setblock ~32 ~124 ~78 dirt
setblock ~32 ~124 ~79 dirt
setblock ~32 ~124 ~80 dirt
setblock ~32 ~124 ~81 dirt
setblock ~32 ~124 ~100 grass_block
setblock ~32 ~125 ~66 grass_block
setblock ~32 ~125 ~67 dirt
setblock ~32 ~125 ~68 dirt
setblock ~32 ~125 ~69 dirt
setblock ~32 ~125 ~70 dirt
setblock ~32 ~125 ~71 dirt
setblock ~32 ~125 ~72 dirt
setblock ~32 ~125 ~73 dirt
setblock ~32 ~125 ~74 dirt
setblock ~32 ~125 ~75 dirt
setblock ~32 ~125 ~76 dirt
setblock ~32 ~125 ~77 dirt
setblock ~32 ~125 ~78 grass_block
setblock ~32 ~125 ~79 grass_block
setblock ~32 ~125 ~80 grass_block
setblock ~32 ~125 ~81 grass_block
setblock ~32 ~126 ~67 grass_block
setblock ~32 ~126 ~68 dirt
setblock ~32 ~126 ~69 dirt
setblock ~32 ~126 ~70 dirt
setblock ~32 ~126 ~71 dirt
setblock ~32 ~126 ~72 dirt
setblock ~32 ~126 ~73 dirt
setblock ~32 ~126 ~74 dirt
setblock ~32 ~126 ~75 grass_block
setblock ~32 ~126 ~76 grass_block
setblock ~32 ~126 ~77 grass_block
setblock ~32 ~126 ~80 short_grass
setblock ~32 ~127 ~68 grass_block
setblock ~32 ~127 ~69 grass_block
setblock ~32 ~127 ~70 dirt
setblock ~32 ~127 ~71 dirt
setblock ~32 ~127 ~72 grass_block
setblock ~32 ~127 ~73 grass_block
setblock ~32 ~127 ~74 grass_block
setblock ~32 ~127 ~76 fern
setblock ~32 ~128 ~70 grass_block
setblock ~32 ~128 ~71 grass_block
setblock ~32 ~129 ~71 short_grass
setblock ~32 ~132 ~65 oak_leaves[persistent=null]
setblock ~32 ~132 ~66 oak_leaves[persistent=null]
setblock ~32 ~132 ~67 oak_leaves[persistent=null]
setblock ~32 ~132 ~73 oak_leaves[persistent=null]
setblock ~32 ~132 ~74 oak_leaves[persistent=null]
setblock ~32 ~132 ~75 oak_leaves[persistent=null]
setblock ~32 ~133 ~65 oak_leaves[persistent=null]
setblock ~32 ~133 ~66 oak_leaves[persistent=null]
setblock ~32 ~133 ~67 oak_leaves[persistent=null]
setblock ~32 ~133 ~68 oak_leaves[persistent=null]
setblock ~32 ~133 ~73 oak_leaves[persistent=null]
setblock ~32 ~133 ~74 oak_log
setblock ~32 ~133 ~75 jungle_leaves[persistent=null]
setblock ~32 ~133 ~76 oak_leaves[persistent=null]
setblock ~32 ~134 ~65 oak_leaves[persistent=null]
setblock ~32 ~134 ~66 oak_leaves[persistent=null]
setblock ~32 ~134 ~67 oak_wood
setblock ~32 ~134 ~73 oak_leaves[persistent=null]
setblock ~32 ~134 ~74 spruce_fence
setblock ~32 ~135 ~66 oak_leaves[persistent=null]
setblock ~32 ~135 ~68 oak_leaves[persistent=null]
setblock ~32 ~135 ~73 oak_leaves[persistent=null]
setblock ~32 ~135 ~74 oak_leaves[persistent=null]
setblock ~32 ~135 ~75 oak_leaves[persistent=null]
setblock ~32 ~135 ~76 oak_leaves[persistent=null]
setblock ~32 ~136 ~67 oak_leaves[persistent=null]
setblock ~32 ~136 ~72 oak_leaves[persistent=null]
setblock ~32 ~136 ~74 jungle_leaves[persistent=null]
setblock ~32 ~136 ~75 oak_leaves[persistent=null]
setblock ~32 ~136 ~76 oak_leaves[persistent=null]
setblock ~32 ~136 ~77 oak_leaves[persistent=null]
setblock ~32 ~136 ~79 oak_leaves[persistent=null]
setblock ~32 ~136 ~80 oak_leaves[persistent=null]
setblock ~32 ~137 ~72 jungle_leaves[persistent=null]
setblock ~32 ~137 ~73 oak_leaves[persistent=null]
setblock ~32 ~137 ~74 jungle_leaves[persistent=null]
setblock ~32 ~137 ~78 jungle_leaves[persistent=null]
setblock ~32 ~137 ~79 jungle_leaves[persistent=null]
setblock ~32 ~137 ~80 oak_leaves[persistent=null]
setblock ~32 ~138 ~71 oak_leaves[persistent=null]
setblock ~32 ~138 ~72 jungle_leaves[persistent=null]
setblock ~32 ~138 ~74 oak_wood
setblock ~32 ~138 ~75 oak_leaves[persistent=null]
setblock ~32 ~138 ~76 oak_wood
setblock ~32 ~138 ~77 oak_wood
setblock ~32 ~138 ~78 oak_wood
setblock ~32 ~138 ~79 jungle_leaves[persistent=null]
setblock ~32 ~139 ~71 oak_leaves[persistent=null]
setblock ~32 ~139 ~73 oak_leaves[persistent=null]
setblock ~32 ~139 ~74 jungle_leaves[persistent=null]
setblock ~32 ~139 ~75 oak_leaves[persistent=null]
setblock ~32 ~139 ~76 oak_log
setblock ~32 ~139 ~77 oak_leaves[persistent=null]
setblock ~32 ~139 ~78 jungle_leaves[persistent=null]
setblock ~32 ~139 ~79 jungle_leaves[persistent=null]
setblock ~32 ~139 ~80 oak_leaves[persistent=null]
setblock ~32 ~140 ~71 oak_leaves[persistent=null]
setblock ~32 ~140 ~72 oak_wood
setblock ~32 ~140 ~75 oak_leaves[persistent=null]
setblock ~32 ~140 ~76 oak_log
setblock ~32 ~140 ~80 oak_leaves[persistent=null]
setblock ~32 ~141 ~73 oak_leaves[persistent=null]
setblock ~32 ~141 ~74 oak_leaves[persistent=null]
setblock ~32 ~141 ~75 jungle_leaves[persistent=null]
setblock ~32 ~141 ~76 oak_leaves[persistent=null]
setblock ~32 ~141 ~77 oak_leaves[persistent=null]
setblock ~32 ~141 ~78 oak_leaves[persistent=null]
setblock ~32 ~141 ~79 oak_leaves[persistent=null]
setblock ~32 ~141 ~80 oak_leaves[persistent=null]
setblock ~32 ~142 ~73 oak_leaves[persistent=null]
setblock ~32 ~142 ~74 oak_leaves[persistent=null]
setblock ~32 ~142 ~75 oak_leaves[persistent=null]
setblock ~32 ~142 ~78 jungle_leaves[persistent=null]
setblock ~32 ~142 ~79 oak_leaves[persistent=null]
setblock ~32 ~142 ~80 oak_leaves[persistent=null]
setblock ~32 ~143 ~77 oak_leaves[persistent=null]
setblock ~32 ~143 ~78 jungle_leaves[persistent=null]
setblock ~32 ~143 ~79 oak_leaves[persistent=null]
setblock ~32 ~143 ~80 oak_leaves[persistent=null]
setblock ~33 ~112 ~76 dirt
setblock ~33 ~113 ~75 dirt
setblock ~33 ~113 ~76 dirt
setblock ~33 ~113 ~77 dirt
setblock ~33 ~114 ~75 dirt
setblock ~33 ~114 ~76 dirt
setblock ~33 ~114 ~77 dirt
setblock ~33 ~115 ~69 dirt
setblock ~33 ~115 ~70 dirt
setblock ~33 ~115 ~71 dirt
setblock ~33 ~115 ~72 dirt
setblock ~33 ~115 ~73 dirt
setblock ~33 ~115 ~74 dirt
setblock ~33 ~115 ~75 dirt
setblock ~33 ~115 ~76 dirt
setblock ~33 ~115 ~77 dirt
setblock ~33 ~115 ~78 dirt
setblock ~33 ~115 ~79 dirt
setblock ~33 ~116 ~68 dirt
setblock ~33 ~116 ~69 dirt
setblock ~33 ~116 ~70 dirt
setblock ~33 ~116 ~71 dirt
setblock ~33 ~116 ~72 dirt
setblock ~33 ~116 ~73 dirt
setblock ~33 ~116 ~74 dirt
setblock ~33 ~116 ~75 dirt
setblock ~33 ~116 ~76 dirt
setblock ~33 ~116 ~77 dirt
setblock ~33 ~116 ~78 dirt
setblock ~33 ~116 ~79 dirt
setblock ~33 ~117 ~67 dirt
setblock ~33 ~117 ~68 dirt
setblock ~33 ~117 ~69 dirt
setblock ~33 ~117 ~70 dirt
setblock ~33 ~117 ~71 dirt
setblock ~33 ~117 ~72 dirt
setblock ~33 ~117 ~73 dirt
setblock ~33 ~117 ~74 dirt
setblock ~33 ~117 ~75 dirt
setblock ~33 ~117 ~76 dirt
setblock ~33 ~117 ~77 dirt
setblock ~33 ~117 ~78 dirt
setblock ~33 ~117 ~79 dirt
setblock ~33 ~117 ~80 dirt
setblock ~33 ~118 ~67 dirt
setblock ~33 ~118 ~68 dirt
setblock ~33 ~118 ~69 dirt
setblock ~33 ~118 ~70 dirt
setblock ~33 ~118 ~71 dirt
setblock ~33 ~118 ~72 dirt
setblock ~33 ~118 ~73 dirt
setblock ~33 ~118 ~74 dirt
setblock ~33 ~118 ~75 dirt
setblock ~33 ~118 ~76 dirt
setblock ~33 ~118 ~77 dirt
setblock ~33 ~118 ~78 dirt
setblock ~33 ~118 ~79 dirt
setblock ~33 ~118 ~80 dirt
setblock ~33 ~119 ~63 dirt
setblock ~33 ~119 ~66 dirt
setblock ~33 ~119 ~67 dirt
setblock ~33 ~119 ~68 dirt
setblock ~33 ~119 ~69 dirt
setblock ~33 ~119 ~70 dirt
setblock ~33 ~119 ~71 dirt
setblock ~33 ~119 ~72 dirt
setblock ~33 ~119 ~73 dirt
setblock ~33 ~119 ~74 dirt
setblock ~33 ~119 ~75 dirt
setblock ~33 ~119 ~76 dirt
setblock ~33 ~119 ~77 dirt
setblock ~33 ~119 ~78 dirt
setblock ~33 ~119 ~79 dirt
setblock ~33 ~119 ~80 dirt
setblock ~33 ~119 ~81 dirt
setblock ~33 ~120 ~62 dirt
setblock ~33 ~120 ~63 dirt
setblock ~33 ~120 ~66 dirt
setblock ~33 ~120 ~67 dirt
setblock ~33 ~120 ~68 dirt
setblock ~33 ~120 ~69 dirt
setblock ~33 ~120 ~70 dirt
setblock ~33 ~120 ~71 dirt
setblock ~33 ~120 ~72 dirt
setblock ~33 ~120 ~73 dirt
setblock ~33 ~120 ~74 dirt
setblock ~33 ~120 ~75 dirt
setblock ~33 ~120 ~76 dirt
setblock ~33 ~120 ~77 dirt
setblock ~33 ~120 ~78 dirt
setblock ~33 ~120 ~79 dirt
setblock ~33 ~120 ~80 dirt
setblock ~33 ~120 ~81 dirt
setblock ~33 ~120 ~82 dirt
setblock ~33 ~120 ~100 dirt
setblock ~33 ~121 ~60 dirt
setblock ~33 ~121 ~61 dirt
setblock ~33 ~121 ~62 dirt
setblock ~33 ~121 ~63 dirt
setblock ~33 ~121 ~65 dirt
setblock ~33 ~121 ~66 dirt
setblock ~33 ~121 ~67 dirt
setblock ~33 ~121 ~68 dirt
setblock ~33 ~121 ~69 dirt
setblock ~33 ~121 ~70 dirt
setblock ~33 ~121 ~71 dirt
setblock ~33 ~121 ~72 dirt
setblock ~33 ~121 ~73 dirt
setblock ~33 ~121 ~74 dirt
setblock ~33 ~121 ~75 dirt
setblock ~33 ~121 ~76 dirt
setblock ~33 ~121 ~77 dirt
setblock ~33 ~121 ~78 dirt
setblock ~33 ~121 ~79 dirt
setblock ~33 ~121 ~80 dirt
setblock ~33 ~121 ~81 dirt
setblock ~33 ~121 ~82 dirt
setblock ~33 ~121 ~83 dirt
setblock ~33 ~121 ~97 dirt
setblock ~33 ~121 ~98 dirt
setblock ~33 ~121 ~99 dirt
setblock ~33 ~121 ~100 dirt
setblock ~33 ~121 ~101 dirt
setblock ~33 ~121 ~102 dirt
setblock ~33 ~121 ~103 dirt
setblock ~33 ~122 ~60 grass_block
setblock ~33 ~122 ~61 dirt
setblock ~33 ~122 ~62 dirt
setblock ~33 ~122 ~63 dirt
setblock ~33 ~122 ~65 dirt
setblock ~33 ~122 ~66 dirt
setblock ~33 ~122 ~67 dirt
setblock ~33 ~122 ~68 dirt
setblock ~33 ~122 ~69 dirt
setblock ~33 ~122 ~70 dirt
setblock ~33 ~122 ~71 dirt
setblock ~33 ~122 ~72 dirt
setblock ~33 ~122 ~73 dirt
setblock ~33 ~122 ~74 dirt
setblock ~33 ~122 ~75 dirt
setblock ~33 ~122 ~76 dirt
setblock ~33 ~122 ~77 dirt
setblock ~33 ~122 ~78 dirt
setblock ~33 ~122 ~79 dirt
setblock ~33 ~122 ~80 dirt
setblock ~33 ~122 ~81 dirt
setblock ~33 ~122 ~82 dirt
setblock ~33 ~122 ~83 dirt
setblock ~33 ~122 ~97 dirt
setblock ~33 ~122 ~98 dirt
setblock ~33 ~122 ~99 dirt
setblock ~33 ~122 ~100 dirt
setblock ~33 ~122 ~101 dirt
setblock ~33 ~122 ~102 dirt
setblock ~33 ~122 ~103 dirt
setblock ~33 ~123 ~61 grass_block
setblock ~33 ~123 ~62 grass_block
setblock ~33 ~123 ~63 dirt
setblock ~33 ~123 ~65 dirt
setblock ~33 ~123 ~66 dirt
setblock ~33 ~123 ~67 dirt
setblock ~33 ~123 ~68 dirt
setblock ~33 ~123 ~69 dirt
setblock ~33 ~123 ~70 dirt
setblock ~33 ~123 ~71 dirt
setblock ~33 ~123 ~72 dirt
setblock ~33 ~123 ~73 dirt
setblock ~33 ~123 ~74 dirt
setblock ~33 ~123 ~75 dirt
setblock ~33 ~123 ~76 dirt
setblock ~33 ~123 ~77 dirt
setblock ~33 ~123 ~78 dirt
setblock ~33 ~123 ~79 dirt
setblock ~33 ~123 ~80 dirt
setblock ~33 ~123 ~81 dirt
setblock ~33 ~123 ~82 dirt
setblock ~33 ~123 ~83 dirt
setblock ~33 ~123 ~97 dirt
setblock ~33 ~123 ~98 dirt
setblock ~33 ~123 ~99 dirt
setblock ~33 ~123 ~100 dirt
setblock ~33 ~123 ~101 dirt
setblock ~33 ~123 ~102 dirt
setblock ~33 ~123 ~103 dirt
setblock ~33 ~124 ~61 poppy
setblock ~33 ~124 ~62 fern
setblock ~33 ~124 ~63 grass_block
setblock ~33 ~124 ~65 dirt
setblock ~33 ~124 ~66 dirt
setblock ~33 ~124 ~67 dirt
setblock ~33 ~124 ~68 dirt
setblock ~33 ~124 ~69 dirt
setblock ~33 ~124 ~70 dirt
setblock ~33 ~124 ~71 dirt
setblock ~33 ~124 ~72 dirt
setblock ~33 ~124 ~73 dirt
setblock ~33 ~124 ~74 dirt
setblock ~33 ~124 ~75 dirt
setblock ~33 ~124 ~76 dirt
setblock ~33 ~124 ~77 dirt
setblock ~33 ~124 ~78 dirt
setblock ~33 ~124 ~79 dirt
setblock ~33 ~124 ~80 dirt
setblock ~33 ~124 ~81 dirt
setblock ~33 ~124 ~82 dirt
setblock ~33 ~124 ~83 dirt
setblock ~33 ~124 ~97 grass_block
setblock ~33 ~124 ~98 grass_block
setblock ~33 ~124 ~99 grass_block
setblock ~33 ~124 ~100 grass_block
setblock ~33 ~124 ~101 grass_block
setblock ~33 ~124 ~102 dirt
setblock ~33 ~124 ~103 dirt
setblock ~33 ~125 ~65 grass_block
setblock ~33 ~125 ~66 grass_block
setblock ~33 ~125 ~67 dirt
setblock ~33 ~125 ~68 dirt
setblock ~33 ~125 ~69 dirt
setblock ~33 ~125 ~70 dirt
setblock ~33 ~125 ~71 dirt
setblock ~33 ~125 ~72 dirt
setblock ~33 ~125 ~73 dirt
setblock ~33 ~125 ~74 dirt
setblock ~33 ~125 ~75 dirt
setblock ~33 ~125 ~76 dirt
setblock ~33 ~125 ~77 dirt
setblock ~33 ~125 ~78 dirt
setblock ~33 ~125 ~79 grass_block
setblock ~33 ~125 ~80 grass_block
setblock ~33 ~125 ~81 grass_block
setblock ~33 ~125 ~82 grass_block
setblock ~33 ~125 ~83 grass_block
setblock ~33 ~125 ~99 short_grass
setblock ~33 ~125 ~100 short_grass
setblock ~33 ~125 ~102 grass_block
setblock ~33 ~125 ~103 grass_block
setblock ~33 ~126 ~65 short_grass
setblock ~33 ~126 ~66 short_grass
setblock ~33 ~126 ~67 grass_block
setblock ~33 ~126 ~68 grass_block
setblock ~33 ~126 ~69 dirt
setblock ~33 ~126 ~70 dirt
setblock ~33 ~126 ~71 dirt
setblock ~33 ~126 ~72 dirt
setblock ~33 ~126 ~73 dirt
setblock ~33 ~126 ~74 dirt
setblock ~33 ~126 ~75 grass_block
setblock ~33 ~126 ~76 grass_block
setblock ~33 ~126 ~77 grass_block
setblock ~33 ~126 ~78 grass_block
setblock ~33 ~126 ~79 short_grass
setblock ~33 ~126 ~81 short_grass
setblock ~33 ~127 ~69 grass_block
setblock ~33 ~127 ~70 dirt
setblock ~33 ~127 ~71 grass_block
setblock ~33 ~127 ~72 grass_block
setblock ~33 ~127 ~73 grass_block
setblock ~33 ~127 ~74 grass_block
setblock ~33 ~127 ~75 poppy
setblock ~33 ~128 ~69 fern
setblock ~33 ~128 ~70 grass_block
setblock ~33 ~128 ~72 spruce_slab
setblock ~33 ~128 ~73 oak_log
setblock ~33 ~129 ~73 oak_log
setblock ~33 ~130 ~73 oak_log
setblock ~33 ~131 ~73 oak_log
setblock ~33 ~132 ~66 oak_leaves[persistent=null]
setblock ~33 ~132 ~67 oak_leaves[persistent=null]
setblock ~33 ~132 ~73 oak_log
setblock ~33 ~132 ~74 oak_leaves[persistent=null]
setblock ~33 ~132 ~75 oak_leaves[persistent=null]
setblock ~33 ~133 ~65 jungle_leaves[persistent=null]
setblock ~33 ~133 ~66 oak_leaves[persistent=null]
setblock ~33 ~133 ~67 oak_leaves[persistent=null]
setblock ~33 ~133 ~68 oak_leaves[persistent=null]
setblock ~33 ~133 ~73 jungle_leaves[persistent=null]
setblock ~33 ~133 ~75 oak_leaves[persistent=null]
setblock ~33 ~133 ~76 oak_leaves[persistent=null]
setblock ~33 ~134 ~65 oak_leaves[persistent=null]
setblock ~33 ~134 ~66 oak_leaves[persistent=null]
setblock ~33 ~134 ~67 oak_leaves[persistent=null]
setblock ~33 ~134 ~68 oak_leaves[persistent=null]
setblock ~33 ~134 ~73 oak_leaves[persistent=null]
setblock ~33 ~134 ~74 oak_leaves[persistent=null]
setblock ~33 ~134 ~75 oak_wood
setblock ~33 ~134 ~76 jungle_leaves[persistent=null]
setblock ~33 ~135 ~65 oak_leaves[persistent=null]
setblock ~33 ~135 ~66 oak_wood
setblock ~33 ~135 ~67 oak_leaves[persistent=null]
setblock ~33 ~135 ~73 oak_leaves[persistent=null]
setblock ~33 ~135 ~75 oak_log
setblock ~33 ~135 ~76 oak_leaves[persistent=null]
setblock ~33 ~136 ~65 oak_leaves[persistent=null]
setblock ~33 ~136 ~66 jungle_leaves[persistent=null]
setblock ~33 ~136 ~67 oak_leaves[persistent=null]
setblock ~33 ~136 ~75 oak_log
setblock ~33 ~136 ~76 jungle_leaves[persistent=null]
setblock ~33 ~136 ~78 oak_leaves[persistent=null]
setblock ~33 ~136 ~79 oak_leaves[persistent=null]
setblock ~33 ~136 ~80 oak_leaves[persistent=null]
setblock ~33 ~137 ~72 oak_leaves[persistent=null]
setblock ~33 ~137 ~73 jungle_leaves[persistent=null]
setblock ~33 ~137 ~74 oak_leaves[persistent=null]
setblock ~33 ~137 ~75 oak_leaves[persistent=null]
setblock ~33 ~137 ~76 oak_leaves[persistent=null]
setblock ~33 ~137 ~77 oak_leaves[persistent=null]
setblock ~33 ~137 ~79 jungle_leaves[persistent=null]
setblock ~33 ~137 ~80 oak_leaves[persistent=null]
setblock ~33 ~138 ~72 oak_leaves[persistent=null]
setblock ~33 ~138 ~73 oak_leaves[persistent=null]
setblock ~33 ~138 ~74 jungle_leaves[persistent=null]
setblock ~33 ~138 ~75 oak_wood
setblock ~33 ~138 ~76 jungle_leaves[persistent=null]
setblock ~33 ~138 ~77 oak_leaves[persistent=null]
setblock ~33 ~138 ~78 oak_leaves[persistent=null]
setblock ~33 ~138 ~79 oak_wood
setblock ~33 ~139 ~69 oak_leaves[persistent=null]
setblock ~33 ~139 ~70 oak_leaves[persistent=null]
setblock ~33 ~139 ~72 oak_leaves[persistent=null]
setblock ~33 ~139 ~73 oak_leaves[persistent=null]
setblock ~33 ~139 ~74 jungle_leaves[persistent=null]
setblock ~33 ~139 ~76 jungle_leaves[persistent=null]
setblock ~33 ~139 ~77 jungle_leaves[persistent=null]
setblock ~33 ~139 ~78 oak_leaves[persistent=null]
setblock ~33 ~139 ~80 oak_leaves[persistent=null]
setblock ~33 ~140 ~69 jungle_leaves[persistent=null]
setblock ~33 ~140 ~70 jungle_leaves[persistent=null]
setblock ~33 ~140 ~71 oak_leaves[persistent=null]
setblock ~33 ~140 ~72 oak_wood
setblock ~33 ~140 ~73 jungle_leaves[persistent=null]
setblock ~33 ~140 ~74 oak_leaves[persistent=null]
setblock ~33 ~140 ~75 oak_log
setblock ~33 ~140 ~76 jungle_leaves[persistent=null]
setblock ~33 ~140 ~77 oak_leaves[persistent=null]
setblock ~33 ~141 ~69 oak_leaves[persistent=null]
setblock ~33 ~141 ~70 oak_leaves[persistent=null]
setblock ~33 ~141 ~71 oak_leaves[persistent=null]
setblock ~33 ~141 ~72 oak_leaves[persistent=null]
setblock ~33 ~141 ~73 oak_leaves[persistent=null]
setblock ~33 ~141 ~75 oak_leaves[persistent=null]
setblock ~33 ~142 ~69 oak_leaves[persistent=null]
setblock ~33 ~142 ~70 jungle_leaves[persistent=null]
setblock ~33 ~142 ~72 oak_leaves[persistent=null]
setblock ~33 ~142 ~73 jungle_leaves[persistent=null]
setblock ~33 ~142 ~74 oak_leaves[persistent=null]
setblock ~33 ~142 ~75 jungle_leaves[persistent=null]
setblock ~33 ~142 ~76 oak_leaves[persistent=null]
setblock ~33 ~142 ~77 oak_leaves[persistent=null]
setblock ~34 ~111 ~72 dirt
setblock ~34 ~111 ~76 dirt
setblock ~34 ~112 ~72 dirt
setblock ~34 ~112 ~73 dirt
setblock ~34 ~112 ~75 dirt
setblock ~34 ~112 ~76 dirt
setblock ~34 ~112 ~77 dirt
setblock ~34 ~112 ~79 dirt
setblock ~34 ~113 ~70 dirt
setblock ~34 ~113 ~72 dirt
setblock ~34 ~113 ~73 dirt
setblock ~34 ~113 ~74 dirt
setblock ~34 ~113 ~75 dirt
setblock ~34 ~113 ~76 dirt
setblock ~34 ~113 ~77 dirt
setblock ~34 ~113 ~79 dirt
setblock ~34 ~114 ~68 dirt
setblock ~34 ~114 ~69 dirt
setblock ~34 ~114 ~70 dirt
setblock ~34 ~114 ~71 dirt
setblock ~34 ~114 ~72 dirt
setblock ~34 ~114 ~73 dirt
setblock ~34 ~114 ~74 dirt
setblock ~34 ~114 ~75 dirt
setblock ~34 ~114 ~76 dirt
setblock ~34 ~114 ~77 dirt
setblock ~34 ~114 ~78 dirt
setblock ~34 ~114 ~79 dirt
setblock ~34 ~115 ~66 dirt
setblock ~34 ~115 ~67 dirt
setblock ~34 ~115 ~68 dirt
setblock ~34 ~115 ~69 dirt
setblock ~34 ~115 ~70 dirt
setblock ~34 ~115 ~71 dirt
setblock ~34 ~115 ~72 dirt
setblock ~34 ~115 ~73 dirt
setblock ~34 ~115 ~74 dirt
setblock ~34 ~115 ~75 dirt
setblock ~34 ~115 ~76 dirt
setblock ~34 ~115 ~77 dirt
setblock ~34 ~115 ~78 dirt
setblock ~34 ~115 ~79 dirt
setblock ~34 ~115 ~80 dirt
setblock ~34 ~116 ~66 dirt
setblock ~34 ~116 ~67 dirt
setblock ~34 ~116 ~68 dirt
setblock ~34 ~116 ~69 dirt
setblock ~34 ~116 ~70 dirt
setblock ~34 ~116 ~71 dirt
setblock ~34 ~116 ~72 dirt
setblock ~34 ~116 ~73 dirt
setblock ~34 ~116 ~74 dirt
setblock ~34 ~116 ~75 dirt
setblock ~34 ~116 ~76 dirt
setblock ~34 ~116 ~77 dirt
setblock ~34 ~116 ~78 dirt
setblock ~34 ~116 ~79 dirt
setblock ~34 ~116 ~80 dirt
setblock ~34 ~117 ~66 dirt
setblock ~34 ~117 ~67 dirt
setblock ~34 ~117 ~68 dirt
setblock ~34 ~117 ~69 dirt
setblock ~34 ~117 ~70 dirt
setblock ~34 ~117 ~71 dirt
setblock ~34 ~117 ~72 dirt
setblock ~34 ~117 ~73 dirt
setblock ~34 ~117 ~74 dirt
setblock ~34 ~117 ~75 dirt
setblock ~34 ~117 ~76 dirt
setblock ~34 ~117 ~77 dirt
setblock ~34 ~117 ~78 dirt
setblock ~34 ~117 ~79 dirt
setblock ~34 ~117 ~80 dirt
setblock ~34 ~117 ~81 dirt
setblock ~34 ~117 ~99 dirt
setblock ~34 ~118 ~63 dirt
setblock ~34 ~118 ~66 dirt
setblock ~34 ~118 ~67 dirt
setblock ~34 ~118 ~68 dirt
setblock ~34 ~118 ~69 dirt
setblock ~34 ~118 ~70 dirt
setblock ~34 ~118 ~71 dirt
setblock ~34 ~118 ~72 dirt
setblock ~34 ~118 ~73 dirt
setblock ~34 ~118 ~74 dirt
setblock ~34 ~118 ~75 dirt
setblock ~34 ~118 ~76 dirt
setblock ~34 ~118 ~77 dirt
setblock ~34 ~118 ~78 dirt
setblock ~34 ~118 ~79 dirt
setblock ~34 ~118 ~80 dirt
setblock ~34 ~118 ~81 dirt
setblock ~34 ~118 ~99 dirt
setblock ~34 ~118 ~100 dirt
setblock ~34 ~118 ~101 dirt
setblock ~34 ~119 ~61 dirt
setblock ~34 ~119 ~62 dirt
setblock ~34 ~119 ~63 dirt
setblock ~34 ~119 ~64 dirt
setblock ~34 ~119 ~65 dirt
setblock ~34 ~119 ~66 dirt
setblock ~34 ~119 ~67 dirt
setblock ~34 ~119 ~68 dirt
setblock ~34 ~119 ~69 dirt
setblock ~34 ~119 ~70 dirt
setblock ~34 ~119 ~71 dirt
setblock ~34 ~119 ~72 dirt
setblock ~34 ~119 ~73 dirt
setblock ~34 ~119 ~74 dirt
setblock ~34 ~119 ~75 dirt
setblock ~34 ~119 ~76 dirt
setblock ~34 ~119 ~77 dirt
setblock ~34 ~119 ~78 dirt
setblock ~34 ~119 ~79 dirt
setblock ~34 ~119 ~80 dirt
setblock ~34 ~119 ~81 dirt
setblock ~34 ~119 ~82 dirt
setblock ~34 ~119 ~83 dirt
setblock ~34 ~119 ~98 dirt
setblock ~34 ~119 ~99 dirt
setblock ~34 ~119 ~100 dirt
setblock ~34 ~119 ~101 dirt
setblock ~34 ~119 ~102 dirt
setblock ~34 ~119 ~103 dirt
setblock ~34 ~119 ~121 dirt
setblock ~34 ~120 ~60 dirt
setblock ~34 ~120 ~61 dirt
setblock ~34 ~120 ~62 dirt
setblock ~34 ~120 ~63 dirt
setblock ~34 ~120 ~64 dirt
setblock ~34 ~120 ~65 dirt
setblock ~34 ~120 ~66 dirt
setblock ~34 ~120 ~67 dirt
setblock ~34 ~120 ~68 dirt
setblock ~34 ~120 ~69 dirt
setblock ~34 ~120 ~70 dirt
setblock ~34 ~120 ~71 dirt
setblock ~34 ~120 ~72 dirt
setblock ~34 ~120 ~73 dirt
setblock ~34 ~120 ~74 dirt
setblock ~34 ~120 ~75 dirt
setblock ~34 ~120 ~76 dirt
setblock ~34 ~120 ~77 dirt
setblock ~34 ~120 ~78 dirt
setblock ~34 ~120 ~79 dirt
setblock ~34 ~120 ~80 dirt
setblock ~34 ~120 ~81 dirt
setblock ~34 ~120 ~82 dirt
setblock ~34 ~120 ~83 dirt
setblock ~34 ~120 ~84 dirt
setblock ~34 ~120 ~97 dirt
setblock ~34 ~120 ~98 dirt
setblock ~34 ~120 ~99 dirt
setblock ~34 ~120 ~100 dirt
setblock ~34 ~120 ~101 dirt
setblock ~34 ~120 ~102 dirt
setblock ~34 ~120 ~103 dirt
setblock ~34 ~120 ~120 dirt
setblock ~34 ~120 ~121 dirt
setblock ~34 ~120 ~122 dirt
setblock ~34 ~120 ~124 dirt
setblock ~34 ~121 ~59 dirt
setblock ~34 ~121 ~60 dirt
setblock ~34 ~121 ~61 dirt
setblock ~34 ~121 ~62 dirt
setblock ~34 ~121 ~63 dirt
setblock ~34 ~121 ~64 dirt
setblock ~34 ~121 ~65 dirt
setblock ~34 ~121 ~66 dirt
setblock ~34 ~121 ~67 dirt
setblock ~34 ~121 ~68 dirt
setblock ~34 ~121 ~69 dirt
setblock ~34 ~121 ~70 dirt
setblock ~34 ~121 ~71 dirt
setblock ~34 ~121 ~72 dirt
setblock ~34 ~121 ~73 dirt
setblock ~34 ~121 ~74 dirt
setblock ~34 ~121 ~75 dirt
setblock ~34 ~121 ~76 dirt
setblock ~34 ~121 ~77 dirt
setblock ~34 ~121 ~78 dirt
setblock ~34 ~121 ~79 dirt
setblock ~34 ~121 ~80 dirt
setblock ~34 ~121 ~81 dirt
setblock ~34 ~121 ~82 dirt
setblock ~34 ~121 ~83 dirt
setblock ~34 ~121 ~84 dirt
setblock ~34 ~121 ~85 dirt
setblock ~34 ~121 ~96 dirt
setblock ~34 ~121 ~97 dirt
setblock ~34 ~121 ~98 dirt
setblock ~34 ~121 ~99 dirt
setblock ~34 ~121 ~100 dirt
setblock ~34 ~121 ~101 dirt
setblock ~34 ~121 ~102 dirt
setblock ~34 ~121 ~103 dirt
setblock ~34 ~121 ~104 dirt
setblock ~34 ~121 ~120 dirt
setblock ~34 ~121 ~121 dirt
setblock ~34 ~121 ~122 dirt
setblock ~34 ~121 ~123 dirt
setblock ~34 ~121 ~124 dirt
setblock ~34 ~122 ~59 dirt
setblock ~34 ~122 ~60 grass_block
setblock ~34 ~122 ~61 dirt
setblock ~34 ~122 ~62 dirt
setblock ~34 ~122 ~63 dirt
setblock ~34 ~122 ~64 dirt
setblock ~34 ~122 ~65 dirt
setblock ~34 ~122 ~66 dirt
setblock ~34 ~122 ~67 dirt
setblock ~34 ~122 ~68 dirt
setblock ~34 ~122 ~69 dirt
setblock ~34 ~122 ~70 dirt
setblock ~34 ~122 ~71 dirt
setblock ~34 ~122 ~72 dirt
setblock ~34 ~122 ~73 dirt
setblock ~34 ~122 ~74 dirt
setblock ~34 ~122 ~75 dirt
setblock ~34 ~122 ~76 dirt
setblock ~34 ~122 ~77 dirt
setblock ~34 ~122 ~78 dirt
setblock ~34 ~122 ~79 dirt
setblock ~34 ~122 ~80 dirt
setblock ~34 ~122 ~81 dirt
setblock ~34 ~122 ~82 dirt
setblock ~34 ~122 ~83 dirt
setblock ~34 ~122 ~84 dirt
setblock ~34 ~122 ~85 dirt
setblock ~34 ~122 ~96 dirt
setblock ~34 ~122 ~97 dirt
setblock ~34 ~122 ~98 dirt
setblock ~34 ~122 ~99 dirt
setblock ~34 ~122 ~100 dirt
setblock ~34 ~122 ~101 dirt
setblock ~34 ~122 ~102 dirt
setblock ~34 ~122 ~103 dirt
setblock ~34 ~122 ~104 dirt
setblock ~34 ~122 ~120 dirt
setblock ~34 ~122 ~121 dirt
setblock ~34 ~122 ~122 dirt
setblock ~34 ~122 ~123 dirt
setblock ~34 ~122 ~124 dirt
setblock ~34 ~123 ~59 grass_block
setblock ~34 ~123 ~61 grass_block
setblock ~34 ~123 ~62 grass_block
setblock ~34 ~123 ~63 dirt
setblock ~34 ~123 ~64 dirt
setblock ~34 ~123 ~65 dirt
setblock ~34 ~123 ~66 dirt
setblock ~34 ~123 ~67 dirt
setblock ~34 ~123 ~68 dirt
setblock ~34 ~123 ~69 dirt
setblock ~34 ~123 ~70 dirt
setblock ~34 ~123 ~71 dirt
setblock ~34 ~123 ~72 dirt
setblock ~34 ~123 ~73 dirt
setblock ~34 ~123 ~74 dirt
setblock ~34 ~123 ~75 dirt
setblock ~34 ~123 ~76 dirt
setblock ~34 ~123 ~77 dirt
setblock ~34 ~123 ~78 dirt
setblock ~34 ~123 ~79 dirt
setblock ~34 ~123 ~80 dirt
setblock ~34 ~123 ~81 dirt
setblock ~34 ~123 ~82 dirt
setblock ~34 ~123 ~83 dirt
setblock ~34 ~123 ~84 dirt
setblock ~34 ~123 ~85 dirt
setblock ~34 ~123 ~96 dirt
setblock ~34 ~123 ~97 dirt
setblock ~34 ~123 ~98 dirt
setblock ~34 ~123 ~99 dirt
setblock ~34 ~123 ~100 dirt
setblock ~34 ~123 ~101 dirt
setblock ~34 ~123 ~102 dirt
setblock ~34 ~123 ~103 dirt
setblock ~34 ~123 ~104 dirt
setblock ~34 ~123 ~120 grass_block
setblock ~34 ~123 ~121 grass_block
setblock ~34 ~123 ~122 grass_block
setblock ~34 ~123 ~123 dirt
setblock ~34 ~123 ~124 dirt
setblock ~34 ~124 ~59 short_grass
setblock ~34 ~124 ~62 poppy
setblock ~34 ~124 ~63 grass_block
setblock ~34 ~124 ~64 grass_block
setblock ~34 ~124 ~65 dirt
setblock ~34 ~124 ~66 dirt
setblock ~34 ~124 ~67 dirt
setblock ~34 ~124 ~68 dirt
setblock ~34 ~124 ~69 dirt
setblock ~34 ~124 ~70 dirt
setblock ~34 ~124 ~71 dirt
setblock ~34 ~124 ~72 dirt
setblock ~34 ~124 ~73 dirt
setblock ~34 ~124 ~74 dirt
setblock ~34 ~124 ~75 dirt
setblock ~34 ~124 ~76 dirt
setblock ~34 ~124 ~77 dirt
setblock ~34 ~124 ~78 dirt
setblock ~34 ~124 ~79 dirt
setblock ~34 ~124 ~80 dirt
setblock ~34 ~124 ~81 dirt
setblock ~34 ~124 ~82 dirt
setblock ~34 ~124 ~83 dirt
setblock ~34 ~124 ~84 dirt
setblock ~34 ~124 ~85 dirt
setblock ~34 ~124 ~96 grass_block
setblock ~34 ~124 ~97 grass_block
setblock ~34 ~124 ~98 grass_block
setblock ~34 ~124 ~99 grass_block
setblock ~34 ~124 ~100 grass_block
setblock ~34 ~124 ~101 dirt
setblock ~34 ~124 ~102 dirt
setblock ~34 ~124 ~103 dirt
setblock ~34 ~124 ~104 dirt
setblock ~34 ~124 ~123 grass_block
setblock ~34 ~124 ~124 grass_block
setblock ~34 ~125 ~65 grass_block
setblock ~34 ~125 ~66 grass_block
setblock ~34 ~125 ~67 dirt
setblock ~34 ~125 ~68 dirt
setblock ~34 ~125 ~69 dirt
setblock ~34 ~125 ~70 dirt
setblock ~34 ~125 ~71 dirt
setblock ~34 ~125 ~72 dirt
setblock ~34 ~125 ~73 dirt
setblock ~34 ~125 ~74 dirt
setblock ~34 ~125 ~75 dirt
setblock ~34 ~125 ~76 dirt
setblock ~34 ~125 ~77 dirt
setblock ~34 ~125 ~78 dirt
setblock ~34 ~125 ~79 dirt
setblock ~34 ~125 ~80 grass_block
setblock ~34 ~125 ~81 grass_block
setblock ~34 ~125 ~82 grass_block
setblock ~34 ~125 ~83 grass_block
setblock ~34 ~125 ~84 grass_block
setblock ~34 ~125 ~85 grass_block
setblock ~34 ~125 ~96 short_grass
setblock ~34 ~125 ~97 short_grass
setblock ~34 ~125 ~98 fern
setblock ~34 ~125 ~101 grass_block
setblock ~34 ~125 ~102 grass_block
setblock ~34 ~125 ~103 grass_block
setblock ~34 ~125 ~104 grass_block
setblock ~34 ~125 ~124 short_grass
setblock ~34 ~126 ~65 poppy
setblock ~34 ~126 ~67 grass_block
setblock ~34 ~126 ~68 grass_block
setblock ~34 ~126 ~69 dirt
setblock ~34 ~126 ~70 dirt
setblock ~34 ~126 ~71 dirt
setblock ~34 ~126 ~72 dirt
setblock ~34 ~126 ~73 dirt
setblock ~34 ~126 ~74 grass_block
setblock ~34 ~126 ~75 grass_block
setblock ~34 ~126 ~76 grass_block
setblock ~34 ~126 ~77 grass_block
setblock ~34 ~126 ~78 grass_block
setblock ~34 ~126 ~79 grass_block
setblock ~34 ~126 ~102 short_grass
setblock ~34 ~126 ~103 poppy
setblock ~34 ~127 ~68 short_grass
setblock ~34 ~127 ~69 grass_block
setblock ~34 ~127 ~70 grass_block
setblock ~34 ~127 ~71 grass_block
setblock ~34 ~127 ~72 grass_block
setblock ~34 ~127 ~73 grass_block
setblock ~34 ~127 ~74 poppy
setblock ~34 ~127 ~76 short_grass
setblock ~34 ~127 ~77 short_grass
setblock ~34 ~128 ~69 fern
setblock ~34 ~128 ~70 short_grass
setblock ~34 ~128 ~72 short_grass
setblock ~34 ~131 ~68 oak_leaves[persistent=null]
setblock ~34 ~131 ~69 jungle_leaves[persistent=null]
setblock ~34 ~132 ~67 oak_leaves[persistent=null]
setblock ~34 ~132 ~70 oak_leaves[persistent=null]
setblock ~34 ~132 ~73 jungle_leaves[persistent=null]
setblock ~34 ~132 ~74 oak_leaves[persistent=null]
setblock ~34 ~132 ~75 oak_leaves[persistent=null]
setblock ~34 ~132 ~76 oak_leaves[persistent=null]
setblock ~34 ~133 ~66 oak_leaves[persistent=null]
setblock ~34 ~133 ~67 oak_leaves[persistent=null]
setblock ~34 ~133 ~69 oak_leaves[persistent=null]
setblock ~34 ~133 ~74 jungle_leaves[persistent=null]
setblock ~34 ~133 ~75 jungle_leaves[persistent=null]
setblock ~34 ~134 ~64 oak_leaves[persistent=null]
setblock ~34 ~134 ~65 oak_leaves[persistent=null]
setblock ~34 ~134 ~67 oak_leaves[persistent=null]
setblock ~34 ~134 ~68 oak_leaves[persistent=null]
setblock ~34 ~134 ~69 jungle_leaves[persistent=null]
setblock ~34 ~134 ~70 oak_leaves[persistent=null]
setblock ~34 ~134 ~73 oak_leaves[persistent=null]
setblock ~34 ~134 ~74 oak_leaves[persistent=null]
setblock ~34 ~134 ~75 oak_wood
setblock ~34 ~134 ~76 oak_leaves[persistent=null]
setblock ~34 ~135 ~64 jungle_leaves[persistent=null]
setblock ~34 ~135 ~65 jungle_leaves[persistent=null]
setblock ~34 ~135 ~66 oak_wood
setblock ~34 ~135 ~67 oak_leaves[persistent=null]
setblock ~34 ~135 ~73 jungle_leaves[persistent=null]
setblock ~34 ~135 ~74 jungle_leaves[persistent=null]
setblock ~34 ~135 ~75 oak_leaves[persistent=null]
setblock ~34 ~135 ~76 oak_leaves[persistent=null]
setblock ~34 ~136 ~64 oak_leaves[persistent=null]
setblock ~34 ~136 ~66 oak_leaves[persistent=null]
setblock ~34 ~136 ~73 oak_leaves[persistent=null]
setblock ~34 ~136 ~74 oak_leaves[persistent=null]
setblock ~34 ~136 ~76 oak_leaves[persistent=null]
setblock ~34 ~136 ~77 oak_leaves[persistent=null]
setblock ~34 ~137 ~73 oak_leaves[persistent=null]
setblock ~34 ~137 ~74 jungle_leaves[persistent=null]
setblock ~34 ~137 ~75 oak_leaves[persistent=null]
setblock ~34 ~137 ~76 oak_leaves[persistent=null]
setblock ~34 ~137 ~77 oak_leaves[persistent=null]
setblock ~34 ~137 ~78 jungle_leaves[persistent=null]
setblock ~34 ~137 ~79 jungle_leaves[persistent=null]
setblock ~34 ~137 ~80 oak_leaves[persistent=null]
setblock ~34 ~138 ~73 oak_leaves[persistent=null]
setblock ~34 ~138 ~74 oak_leaves[persistent=null]
setblock ~34 ~138 ~75 oak_leaves[persistent=null]
setblock ~34 ~138 ~78 oak_leaves[persistent=null]
setblock ~34 ~138 ~80 oak_leaves[persistent=null]
setblock ~34 ~139 ~70 oak_leaves[persistent=null]
setblock ~34 ~139 ~71 oak_leaves[persistent=null]
setblock ~34 ~139 ~72 oak_leaves[persistent=null]
setblock ~34 ~139 ~74 oak_leaves[persistent=null]
setblock ~34 ~139 ~75 oak_leaves[persistent=null]
setblock ~34 ~139 ~77 jungle_leaves[persistent=null]
setblock ~34 ~139 ~78 oak_leaves[persistent=null]
setblock ~34 ~139 ~79 jungle_leaves[persistent=null]
setblock ~34 ~140 ~69 oak_leaves[persistent=null]
setblock ~34 ~140 ~70 oak_leaves[persistent=null]
setblock ~34 ~140 ~71 oak_leaves[persistent=null]
setblock ~34 ~140 ~72 oak_wood
setblock ~34 ~140 ~74 oak_leaves[persistent=null]
setblock ~34 ~140 ~75 oak_leaves[persistent=null]
setblock ~34 ~140 ~76 oak_leaves[persistent=null]
setblock ~34 ~140 ~78 oak_leaves[persistent=null]
setblock ~34 ~141 ~69 jungle_leaves[persistent=null]
setblock ~34 ~141 ~70 jungle_leaves[persistent=null]
setblock ~34 ~141 ~71 oak_leaves[persistent=null]
setblock ~34 ~141 ~72 jungle_leaves[persistent=null]
setblock ~34 ~141 ~73 oak_leaves[persistent=null]
setblock ~34 ~141 ~74 oak_leaves[persistent=null]
setblock ~34 ~141 ~75 oak_leaves[persistent=null]
setblock ~34 ~141 ~77 oak_leaves[persistent=null]
setblock ~34 ~142 ~69 oak_leaves[persistent=null]
setblock ~34 ~142 ~73 jungle_leaves[persistent=null]
setblock ~34 ~142 ~75 oak_leaves[persistent=null]
setblock ~34 ~142 ~76 oak_leaves[persistent=null]
setblock ~34 ~142 ~77 oak_leaves[persistent=null]
setblock ~35 ~109 ~72 dirt
setblock ~35 ~109 ~75 dirt
setblock ~35 ~109 ~76 dirt
setblock ~35 ~110 ~70 dirt
setblock ~35 ~110 ~71 dirt
setblock ~35 ~110 ~72 dirt
setblock ~35 ~110 ~73 dirt
setblock ~35 ~110 ~74 dirt
setblock ~35 ~110 ~75 dirt
setblock ~35 ~110 ~76 dirt
setblock ~35 ~110 ~77 dirt
setblock ~35 ~110 ~78 dirt
setblock ~35 ~111 ~70 dirt
setblock ~35 ~111 ~71 dirt
setblock ~35 ~111 ~72 dirt
setblock ~35 ~111 ~73 dirt
setblock ~35 ~111 ~74 dirt
setblock ~35 ~111 ~75 dirt
setblock ~35 ~111 ~76 dirt
setblock ~35 ~111 ~77 dirt
setblock ~35 ~111 ~78 dirt
setblock ~35 ~111 ~79 dirt
setblock ~35 ~112 ~68 dirt
setblock ~35 ~112 ~70 dirt
setblock ~35 ~112 ~71 dirt
setblock ~35 ~112 ~72 dirt
setblock ~35 ~112 ~73 dirt
setblock ~35 ~112 ~74 dirt
setblock ~35 ~112 ~75 dirt
setblock ~35 ~112 ~76 dirt
setblock ~35 ~112 ~77 dirt
setblock ~35 ~112 ~78 dirt
setblock ~35 ~112 ~79 dirt
setblock ~35 ~112 ~80 dirt
setblock ~35 ~113 ~66 dirt
setblock ~35 ~113 ~67 dirt
setblock ~35 ~113 ~68 dirt
setblock ~35 ~113 ~69 dirt
setblock ~35 ~113 ~70 dirt
setblock ~35 ~113 ~71 dirt
setblock ~35 ~113 ~72 dirt
setblock ~35 ~113 ~73 dirt
setblock ~35 ~113 ~74 dirt
setblock ~35 ~113 ~75 dirt
setblock ~35 ~113 ~76 dirt
setblock ~35 ~113 ~77 dirt
setblock ~35 ~113 ~78 dirt
setblock ~35 ~113 ~79 dirt
setblock ~35 ~113 ~80 dirt
setblock ~35 ~114 ~66 dirt
setblock ~35 ~114 ~67 dirt
setblock ~35 ~114 ~68 dirt
setblock ~35 ~114 ~69 dirt
setblock ~35 ~114 ~70 dirt
setblock ~35 ~114 ~71 dirt
setblock ~35 ~114 ~72 dirt
setblock ~35 ~114 ~73 dirt
setblock ~35 ~114 ~74 dirt
setblock ~35 ~114 ~75 dirt
setblock ~35 ~114 ~76 dirt
setblock ~35 ~114 ~77 dirt
setblock ~35 ~114 ~78 dirt
setblock ~35 ~114 ~79 dirt
setblock ~35 ~114 ~80 dirt
setblock ~35 ~115 ~63 dirt
setblock ~35 ~115 ~65 dirt
setblock ~35 ~115 ~66 dirt
setblock ~35 ~115 ~67 dirt
setblock ~35 ~115 ~68 dirt
setblock ~35 ~115 ~69 dirt
setblock ~35 ~115 ~70 dirt
setblock ~35 ~115 ~71 dirt
setblock ~35 ~115 ~72 dirt
setblock ~35 ~115 ~73 dirt
setblock ~35 ~115 ~74 dirt
setblock ~35 ~115 ~75 dirt
setblock ~35 ~115 ~76 dirt
setblock ~35 ~115 ~77 dirt
setblock ~35 ~115 ~78 dirt
setblock ~35 ~115 ~79 dirt
setblock ~35 ~115 ~80 dirt
setblock ~35 ~115 ~81 dirt
setblock ~35 ~115 ~98 dirt
setblock ~35 ~115 ~99 dirt
setblock ~35 ~115 ~101 dirt
setblock ~35 ~116 ~62 dirt
setblock ~35 ~116 ~63 dirt
setblock ~35 ~116 ~65 dirt
setblock ~35 ~116 ~66 dirt
setblock ~35 ~116 ~67 dirt
setblock ~35 ~116 ~68 dirt
setblock ~35 ~116 ~69 dirt
setblock ~35 ~116 ~70 dirt
setblock ~35 ~116 ~71 dirt
setblock ~35 ~116 ~72 dirt
setblock ~35 ~116 ~73 dirt
setblock ~35 ~116 ~74 dirt
setblock ~35 ~116 ~75 dirt
setblock ~35 ~116 ~76 dirt
setblock ~35 ~116 ~77 dirt
setblock ~35 ~116 ~78 dirt
setblock ~35 ~116 ~79 dirt
setblock ~35 ~116 ~80 dirt
setblock ~35 ~116 ~81 dirt
setblock ~35 ~116 ~97 dirt
setblock ~35 ~116 ~98 dirt
setblock ~35 ~116 ~99 dirt
setblock ~35 ~116 ~101 dirt
setblock ~35 ~117 ~61 dirt
setblock ~35 ~117 ~62 dirt
setblock ~35 ~117 ~63 dirt
setblock ~35 ~117 ~64 dirt
setblock ~35 ~117 ~65 dirt
setblock ~35 ~117 ~66 dirt
setblock ~35 ~117 ~67 dirt
setblock ~35 ~117 ~68 dirt
setblock ~35 ~117 ~69 dirt
setblock ~35 ~117 ~70 dirt
setblock ~35 ~117 ~71 dirt
setblock ~35 ~117 ~72 dirt
setblock ~35 ~117 ~73 dirt
setblock ~35 ~117 ~74 dirt
setblock ~35 ~117 ~75 dirt
setblock ~35 ~117 ~76 dirt
setblock ~35 ~117 ~77 dirt
setblock ~35 ~117 ~78 dirt
setblock ~35 ~117 ~79 dirt
setblock ~35 ~117 ~80 dirt
setblock ~35 ~117 ~81 dirt
setblock ~35 ~117 ~82 dirt
setblock ~35 ~117 ~96 dirt
setblock ~35 ~117 ~97 dirt
setblock ~35 ~117 ~98 dirt
setblock ~35 ~117 ~99 dirt
setblock ~35 ~117 ~100 dirt
setblock ~35 ~117 ~101 dirt
setblock ~35 ~117 ~102 dirt
setblock ~35 ~117 ~103 dirt
setblock ~35 ~117 ~124 dirt
setblock ~35 ~118 ~61 dirt
setblock ~35 ~118 ~62 dirt
setblock ~35 ~118 ~63 dirt
setblock ~35 ~118 ~64 dirt
setblock ~35 ~118 ~65 dirt
setblock ~35 ~118 ~66 dirt
setblock ~35 ~118 ~67 dirt
setblock ~35 ~118 ~68 dirt
setblock ~35 ~118 ~69 dirt
setblock ~35 ~118 ~70 dirt
setblock ~35 ~118 ~71 dirt
setblock ~35 ~118 ~72 dirt
setblock ~35 ~118 ~73 dirt
setblock ~35 ~118 ~74 dirt
setblock ~35 ~118 ~75 dirt
setblock ~35 ~118 ~76 dirt
setblock ~35 ~118 ~77 dirt
setblock ~35 ~118 ~78 dirt
setblock ~35 ~118 ~79 dirt
setblock ~35 ~118 ~80 dirt
setblock ~35 ~118 ~81 dirt
setblock ~35 ~118 ~82 dirt
setblock ~35 ~118 ~83 dirt
setblock ~35 ~118 ~96 dirt
setblock ~35 ~118 ~97 dirt
setblock ~35 ~118 ~98 dirt
setblock ~35 ~118 ~99 dirt
setblock ~35 ~118 ~100 dirt
setblock ~35 ~118 ~101 dirt
setblock ~35 ~118 ~102 dirt
setblock ~35 ~118 ~103 dirt
setblock ~35 ~118 ~121 dirt
setblock ~35 ~118 ~123 dirt
setblock ~35 ~118 ~124 dirt
setblock ~35 ~119 ~60 dirt
setblock ~35 ~119 ~61 dirt
setblock ~35 ~119 ~62 dirt
setblock ~35 ~119 ~63 dirt
setblock ~35 ~119 ~64 dirt
setblock ~35 ~119 ~65 dirt
setblock ~35 ~119 ~66 dirt
setblock ~35 ~119 ~67 dirt
setblock ~35 ~119 ~68 dirt
setblock ~35 ~119 ~69 dirt
setblock ~35 ~119 ~70 dirt
setblock ~35 ~119 ~71 dirt
setblock ~35 ~119 ~72 dirt
setblock ~35 ~119 ~73 dirt
setblock ~35 ~119 ~74 dirt
setblock ~35 ~119 ~75 dirt
setblock ~35 ~119 ~76 dirt
setblock ~35 ~119 ~77 dirt
setblock ~35 ~119 ~78 dirt
setblock ~35 ~119 ~79 dirt
setblock ~35 ~119 ~80 dirt
setblock ~35 ~119 ~81 dirt
setblock ~35 ~119 ~82 dirt
setblock ~35 ~119 ~83 dirt
setblock ~35 ~119 ~84 dirt
setblock ~35 ~119 ~96 dirt
setblock ~35 ~119 ~97 dirt
setblock ~35 ~119 ~98 dirt
setblock ~35 ~119 ~99 dirt
setblock ~35 ~119 ~100 dirt
setblock ~35 ~119 ~101 dirt
setblock ~35 ~119 ~102 dirt
setblock ~35 ~119 ~103 dirt
setblock ~35 ~119 ~104 dirt
setblock ~35 ~119 ~120 dirt
setblock ~35 ~119 ~121 dirt
setblock ~35 ~119 ~122 dirt
setblock ~35 ~119 ~123 dirt
setblock ~35 ~119 ~124 dirt
setblock ~35 ~120 ~59 dirt
setblock ~35 ~120 ~60 dirt
setblock ~35 ~120 ~61 dirt
