setblock ~162 ~119 ~92 dirt
setblock ~162 ~119 ~93 dirt
setblock ~162 ~119 ~94 dirt
setblock ~162 ~119 ~95 dirt
setblock ~162 ~119 ~96 dirt
setblock ~162 ~119 ~97 dirt
setblock ~162 ~119 ~98 dirt
setblock ~162 ~119 ~99 dirt
setblock ~162 ~119 ~100 dirt
setblock ~162 ~119 ~101 dirt
setblock ~162 ~119 ~102 dirt
setblock ~162 ~119 ~103 dirt
setblock ~162 ~119 ~104 dirt
setblock ~162 ~119 ~105 dirt
setblock ~162 ~119 ~106 dirt
setblock ~162 ~119 ~107 dirt
setblock ~162 ~119 ~108 dirt
setblock ~162 ~119 ~109 dirt
setblock ~162 ~119 ~110 dirt
setblock ~162 ~119 ~116 dirt
setblock ~162 ~120 ~72 dirt
setblock ~162 ~120 ~76 dirt
setblock ~162 ~120 ~78 dirt
setblock ~162 ~120 ~79 dirt
setblock ~162 ~120 ~80 dirt
setblock ~162 ~120 ~81 dirt
setblock ~162 ~120 ~82 dirt
setblock ~162 ~120 ~83 dirt
setblock ~162 ~120 ~84 dirt
setblock ~162 ~120 ~85 dirt
setblock ~162 ~120 ~86 dirt
setblock ~162 ~120 ~87 dirt
setblock ~162 ~120 ~88 dirt
setblock ~162 ~120 ~89 dirt
setblock ~162 ~120 ~90 dirt
setblock ~162 ~120 ~91 dirt
setblock ~162 ~120 ~92 dirt
setblock ~162 ~120 ~93 dirt
setblock ~162 ~120 ~94 dirt
setblock ~162 ~120 ~95 dirt
setblock ~162 ~120 ~96 dirt
setblock ~162 ~120 ~97 dirt
setblock ~162 ~120 ~98 dirt
setblock ~162 ~120 ~99 dirt
setblock ~162 ~120 ~100 dirt
setblock ~162 ~120 ~101 dirt
setblock ~162 ~120 ~102 dirt
setblock ~162 ~120 ~103 dirt
setblock ~162 ~120 ~104 dirt
setblock ~162 ~120 ~105 dirt
setblock ~162 ~120 ~106 dirt
setblock ~162 ~120 ~107 dirt
setblock ~162 ~120 ~108 dirt
setblock ~162 ~120 ~109 dirt
setblock ~162 ~120 ~110 dirt
setblock ~162 ~120 ~116 dirt
setblock ~162 ~120 ~118 dirt
setblock ~162 ~121 ~71 dirt
setblock ~162 ~121 ~72 dirt
setblock ~162 ~121 ~74 dirt
setblock ~162 ~121 ~76 dirt
setblock ~162 ~121 ~77 dirt
setblock ~162 ~121 ~78 dirt
setblock ~162 ~121 ~79 dirt
setblock ~162 ~121 ~80 dirt
setblock ~162 ~121 ~81 dirt
setblock ~162 ~121 ~82 dirt
setblock ~162 ~121 ~83 dirt
setblock ~162 ~121 ~84 dirt
setblock ~162 ~121 ~85 dirt
setblock ~162 ~121 ~86 dirt
setblock ~162 ~121 ~87 dirt
setblock ~162 ~121 ~88 dirt
setblock ~162 ~121 ~89 dirt
setblock ~162 ~121 ~90 dirt
setblock ~162 ~121 ~91 dirt
setblock ~162 ~121 ~92 dirt
setblock ~162 ~121 ~93 dirt
setblock ~162 ~121 ~94 dirt
setblock ~162 ~121 ~95 dirt
setblock ~162 ~121 ~96 dirt
setblock ~162 ~121 ~97 dirt
setblock ~162 ~121 ~98 dirt
setblock ~162 ~121 ~99 dirt
setblock ~162 ~121 ~100 dirt
setblock ~162 ~121 ~101 dirt
setblock ~162 ~121 ~102 dirt
setblock ~162 ~121 ~103 dirt
setblock ~162 ~121 ~104 dirt
setblock ~162 ~121 ~105 dirt
setblock ~162 ~121 ~106 dirt
setblock ~162 ~121 ~107 dirt
setblock ~162 ~121 ~108 dirt
setblock ~162 ~121 ~109 dirt
setblock ~162 ~121 ~110 dirt
setblock ~162 ~121 ~111 dirt
setblock ~162 ~121 ~116 dirt
setblock ~162 ~121 ~118 dirt
setblock ~162 ~121 ~119 dirt
setblock ~162 ~121 ~120 dirt
setblock ~162 ~121 ~125 dirt
setblock ~162 ~121 ~126 dirt
setblock ~162 ~121 ~128 dirt
setblock ~162 ~122 ~71 dirt
setblock ~162 ~122 ~72 dirt
setblock ~162 ~122 ~74 dirt
setblock ~162 ~122 ~76 dirt
setblock ~162 ~122 ~77 dirt
setblock ~162 ~122 ~78 dirt
setblock ~162 ~122 ~79 dirt
setblock ~162 ~122 ~80 dirt
setblock ~162 ~122 ~81 dirt
setblock ~162 ~122 ~82 dirt
setblock ~162 ~122 ~83 dirt
setblock ~162 ~122 ~84 dirt
setblock ~162 ~122 ~85 dirt
setblock ~162 ~122 ~86 dirt
setblock ~162 ~122 ~87 dirt
setblock ~162 ~122 ~88 dirt
setblock ~162 ~122 ~89 dirt
setblock ~162 ~122 ~90 dirt
setblock ~162 ~122 ~91 dirt
setblock ~162 ~122 ~92 dirt
setblock ~162 ~122 ~93 dirt
setblock ~162 ~122 ~94 dirt
setblock ~162 ~122 ~95 dirt
setblock ~162 ~122 ~96 dirt
setblock ~162 ~122 ~97 dirt
setblock ~162 ~122 ~98 dirt
setblock ~162 ~122 ~99 dirt
setblock ~162 ~122 ~100 dirt
setblock ~162 ~122 ~101 dirt
setblock ~162 ~122 ~102 dirt
setblock ~162 ~122 ~103 dirt
setblock ~162 ~122 ~104 dirt
setblock ~162 ~122 ~105 dirt
setblock ~162 ~122 ~106 dirt
setblock ~162 ~122 ~107 dirt
setblock ~162 ~122 ~108 dirt
setblock ~162 ~122 ~109 dirt
setblock ~162 ~122 ~110 dirt
setblock ~162 ~122 ~111 dirt
setblock ~162 ~122 ~116 dirt
setblock ~162 ~122 ~118 dirt
setblock ~162 ~122 ~119 dirt
setblock ~162 ~122 ~120 dirt
setblock ~162 ~122 ~125 dirt
setblock ~162 ~122 ~126 dirt
setblock ~162 ~122 ~128 dirt
setblock ~162 ~123 ~71 dirt
setblock ~162 ~123 ~72 dirt
setblock ~162 ~123 ~74 dirt
setblock ~162 ~123 ~76 dirt
setblock ~162 ~123 ~77 dirt
setblock ~162 ~123 ~78 dirt
setblock ~162 ~123 ~79 dirt
setblock ~162 ~123 ~80 dirt
setblock ~162 ~123 ~81 dirt
setblock ~162 ~123 ~82 dirt
setblock ~162 ~123 ~83 dirt
setblock ~162 ~123 ~84 dirt
setblock ~162 ~123 ~85 dirt
setblock ~162 ~123 ~86 dirt
setblock ~162 ~123 ~87 dirt
setblock ~162 ~123 ~88 dirt
setblock ~162 ~123 ~89 dirt
setblock ~162 ~123 ~90 dirt
setblock ~162 ~123 ~91 dirt
setblock ~162 ~123 ~92 dirt
setblock ~162 ~123 ~93 dirt
setblock ~162 ~123 ~94 dirt
setblock ~162 ~123 ~95 dirt
setblock ~162 ~123 ~96 dirt
setblock ~162 ~123 ~97 dirt
setblock ~162 ~123 ~98 dirt
setblock ~162 ~123 ~99 dirt
setblock ~162 ~123 ~100 dirt
setblock ~162 ~123 ~101 dirt
setblock ~162 ~123 ~102 dirt
setblock ~162 ~123 ~103 dirt
setblock ~162 ~123 ~104 dirt
setblock ~162 ~123 ~105 dirt
setblock ~162 ~123 ~106 grass_block
setblock ~162 ~123 ~107 grass_block
setblock ~162 ~123 ~108 grass_block
setblock ~162 ~123 ~109 grass_block
setblock ~162 ~123 ~110 grass_block
setblock ~162 ~123 ~111 grass_block
setblock ~162 ~123 ~116 dirt
setblock ~162 ~123 ~118 dirt
setblock ~162 ~123 ~119 dirt
setblock ~162 ~123 ~120 dirt
setblock ~162 ~123 ~125 dirt
setblock ~162 ~123 ~126 dirt
setblock ~162 ~123 ~128 dirt
setblock ~162 ~124 ~71 dirt
setblock ~162 ~124 ~72 dirt
setblock ~162 ~124 ~74 dirt
setblock ~162 ~124 ~76 dirt
setblock ~162 ~124 ~77 dirt
setblock ~162 ~124 ~78 dirt
setblock ~162 ~124 ~79 dirt
setblock ~162 ~124 ~80 dirt
setblock ~162 ~124 ~81 dirt
setblock ~162 ~124 ~82 dirt
setblock ~162 ~124 ~83 dirt
setblock ~162 ~124 ~84 dirt
setblock ~162 ~124 ~85 dirt
setblock ~162 ~124 ~86 dirt
setblock ~162 ~124 ~87 dirt
setblock ~162 ~124 ~88 dirt
setblock ~162 ~124 ~89 dirt
setblock ~162 ~124 ~90 dirt
setblock ~162 ~124 ~91 dirt
setblock ~162 ~124 ~92 dirt
setblock ~162 ~124 ~93 dirt
setblock ~162 ~124 ~94 dirt
setblock ~162 ~124 ~95 dirt
setblock ~162 ~124 ~96 dirt
setblock ~162 ~124 ~97 grass_block
setblock ~162 ~124 ~98 grass_block
setblock ~162 ~124 ~99 grass_block
setblock ~162 ~124 ~100 grass_block
setblock ~162 ~124 ~101 grass_block
setblock ~162 ~124 ~102 grass_block
setblock ~162 ~124 ~103 grass_block
setblock ~162 ~124 ~104 grass_block
setblock ~162 ~124 ~105 grass_block
setblock ~162 ~124 ~116 dirt
setblock ~162 ~124 ~118 dirt
setblock ~162 ~124 ~119 dirt
setblock ~162 ~124 ~120 dirt
setblock ~162 ~124 ~125 dirt
setblock ~162 ~124 ~126 grass_block
setblock ~162 ~124 ~128 grass_block
setblock ~162 ~125 ~71 dirt
setblock ~162 ~125 ~72 dirt
setblock ~162 ~125 ~74 dirt
setblock ~162 ~125 ~76 dirt
setblock ~162 ~125 ~77 dirt
setblock ~162 ~125 ~78 dirt
setblock ~162 ~125 ~79 dirt
setblock ~162 ~125 ~80 dirt
setblock ~162 ~125 ~81 dirt
setblock ~162 ~125 ~82 dirt
setblock ~162 ~125 ~83 dirt
setblock ~162 ~125 ~84 dirt
setblock ~162 ~125 ~85 dirt
setblock ~162 ~125 ~86 grass_block
setblock ~162 ~125 ~87 grass_block
setblock ~162 ~125 ~88 grass_block
setblock ~162 ~125 ~89 grass_block
setblock ~162 ~125 ~90 grass_block
setblock ~162 ~125 ~91 grass_block
setblock ~162 ~125 ~92 grass_block
setblock ~162 ~125 ~93 grass_block
setblock ~162 ~125 ~94 grass_block
setblock ~162 ~125 ~95 grass_block
setblock ~162 ~125 ~96 grass_block
setblock ~162 ~125 ~97 poppy
setblock ~162 ~125 ~98 short_grass
setblock ~162 ~125 ~103 fern
setblock ~162 ~125 ~104 short_grass
setblock ~162 ~125 ~105 fern
setblock ~162 ~125 ~116 grass_block
setblock ~162 ~125 ~118 grass_block
setblock ~162 ~125 ~119 dirt
setblock ~162 ~125 ~120 dirt
setblock ~162 ~125 ~125 grass_block
setblock ~162 ~126 ~71 grass_block
setblock ~162 ~126 ~72 grass_block
setblock ~162 ~126 ~74 grass_block
setblock ~162 ~126 ~76 grass_block
setblock ~162 ~126 ~77 grass_block
setblock ~162 ~126 ~78 grass_block
setblock ~162 ~126 ~79 grass_block
setblock ~162 ~126 ~80 grass_block
setblock ~162 ~126 ~81 grass_block
setblock ~162 ~126 ~82 grass_block
setblock ~162 ~126 ~83 grass_block
setblock ~162 ~126 ~84 grass_block
setblock ~162 ~126 ~85 grass_block
setblock ~162 ~126 ~86 fern
setblock ~162 ~126 ~88 short_grass
setblock ~162 ~126 ~89 short_grass
setblock ~162 ~126 ~93 short_grass
setblock ~162 ~126 ~94 short_grass
setblock ~162 ~126 ~116 short_grass
setblock ~162 ~126 ~119 grass_block
setblock ~162 ~126 ~120 grass_block
setblock ~162 ~127 ~72 fern
setblock ~162 ~127 ~76 short_grass
setblock ~162 ~127 ~79 short_grass
setblock ~162 ~127 ~80 short_grass
setblock ~162 ~127 ~85 short_grass
setblock ~163 ~103 ~90 dirt
setblock ~163 ~103 ~96 dirt
setblock ~163 ~104 ~89 dirt
setblock ~163 ~104 ~90 dirt
setblock ~163 ~104 ~91 dirt
setblock ~163 ~104 ~96 dirt
setblock ~163 ~104 ~97 dirt
setblock ~163 ~104 ~99 dirt
setblock ~163 ~105 ~89 dirt
setblock ~163 ~105 ~90 dirt
setblock ~163 ~105 ~91 dirt
setblock ~163 ~105 ~94 dirt
setblock ~163 ~105 ~95 dirt
setblock ~163 ~105 ~96 dirt
setblock ~163 ~105 ~97 dirt
setblock ~163 ~105 ~98 dirt
setblock ~163 ~105 ~99 dirt
setblock ~163 ~106 ~88 dirt
setblock ~163 ~106 ~89 dirt
setblock ~163 ~106 ~90 dirt
setblock ~163 ~106 ~91 dirt
setblock ~163 ~106 ~93 dirt
setblock ~163 ~106 ~94 dirt
setblock ~163 ~106 ~95 dirt
setblock ~163 ~106 ~96 dirt
setblock ~163 ~106 ~97 dirt
setblock ~163 ~106 ~98 dirt
setblock ~163 ~106 ~99 dirt
setblock ~163 ~106 ~100 dirt
setblock ~163 ~107 ~87 dirt
setblock ~163 ~107 ~88 dirt
setblock ~163 ~107 ~89 dirt
setblock ~163 ~107 ~90 dirt
setblock ~163 ~107 ~91 dirt
setblock ~163 ~107 ~92 dirt
setblock ~163 ~107 ~93 dirt
setblock ~163 ~107 ~94 dirt
setblock ~163 ~107 ~95 dirt
setblock ~163 ~107 ~96 dirt
setblock ~163 ~107 ~97 dirt
setblock ~163 ~107 ~98 dirt
setblock ~163 ~107 ~99 dirt
setblock ~163 ~107 ~100 dirt
setblock ~163 ~107 ~101 dirt
setblock ~163 ~108 ~86 dirt
setblock ~163 ~108 ~87 dirt
setblock ~163 ~108 ~88 dirt
setblock ~163 ~108 ~89 dirt
setblock ~163 ~108 ~90 dirt
setblock ~163 ~108 ~91 dirt
setblock ~163 ~108 ~92 dirt
setblock ~163 ~108 ~93 dirt
setblock ~163 ~108 ~94 dirt
setblock ~163 ~108 ~95 dirt
setblock ~163 ~108 ~96 dirt
setblock ~163 ~108 ~97 dirt
setblock ~163 ~108 ~98 dirt
setblock ~163 ~108 ~99 dirt
setblock ~163 ~108 ~100 dirt
setblock ~163 ~108 ~101 dirt
setblock ~163 ~108 ~102 dirt
setblock ~163 ~109 ~86 dirt
setblock ~163 ~109 ~87 dirt
setblock ~163 ~109 ~88 dirt
setblock ~163 ~109 ~89 dirt
setblock ~163 ~109 ~90 dirt
setblock ~163 ~109 ~91 dirt
setblock ~163 ~109 ~92 dirt
setblock ~163 ~109 ~93 dirt
setblock ~163 ~109 ~94 dirt
setblock ~163 ~109 ~95 dirt
setblock ~163 ~109 ~96 dirt
setblock ~163 ~109 ~97 dirt
setblock ~163 ~109 ~98 dirt
setblock ~163 ~109 ~99 dirt
setblock ~163 ~109 ~100 dirt
setblock ~163 ~109 ~101 dirt
setblock ~163 ~109 ~102 dirt
setblock ~163 ~109 ~103 dirt
setblock ~163 ~110 ~85 dirt
setblock ~163 ~110 ~86 dirt
setblock ~163 ~110 ~87 dirt
setblock ~163 ~110 ~88 dirt
setblock ~163 ~110 ~89 dirt
setblock ~163 ~110 ~90 dirt
setblock ~163 ~110 ~91 dirt
setblock ~163 ~110 ~92 dirt
setblock ~163 ~110 ~93 dirt
setblock ~163 ~110 ~94 dirt
setblock ~163 ~110 ~95 dirt
setblock ~163 ~110 ~96 dirt
setblock ~163 ~110 ~97 dirt
setblock ~163 ~110 ~98 dirt
setblock ~163 ~110 ~99 dirt
setblock ~163 ~110 ~100 dirt
setblock ~163 ~110 ~101 dirt
setblock ~163 ~110 ~102 dirt
setblock ~163 ~110 ~103 dirt
setblock ~163 ~111 ~84 dirt
setblock ~163 ~111 ~85 dirt
setblock ~163 ~111 ~86 dirt
setblock ~163 ~111 ~87 dirt
setblock ~163 ~111 ~88 dirt
setblock ~163 ~111 ~89 dirt
setblock ~163 ~111 ~90 dirt
setblock ~163 ~111 ~91 dirt
setblock ~163 ~111 ~92 dirt
setblock ~163 ~111 ~93 dirt
setblock ~163 ~111 ~94 dirt
setblock ~163 ~111 ~95 dirt
setblock ~163 ~111 ~96 dirt
setblock ~163 ~111 ~97 dirt
setblock ~163 ~111 ~98 dirt
setblock ~163 ~111 ~99 dirt
setblock ~163 ~111 ~100 dirt
setblock ~163 ~111 ~101 dirt
setblock ~163 ~111 ~102 dirt
setblock ~163 ~111 ~103 dirt
setblock ~163 ~112 ~83 dirt
setblock ~163 ~112 ~84 dirt
setblock ~163 ~112 ~85 dirt
setblock ~163 ~112 ~86 dirt
setblock ~163 ~112 ~87 dirt
setblock ~163 ~112 ~88 dirt
setblock ~163 ~112 ~89 dirt
setblock ~163 ~112 ~90 dirt
setblock ~163 ~112 ~91 dirt
setblock ~163 ~112 ~92 dirt
setblock ~163 ~112 ~93 dirt
setblock ~163 ~112 ~94 dirt
setblock ~163 ~112 ~95 dirt
setblock ~163 ~112 ~96 dirt
setblock ~163 ~112 ~97 dirt
setblock ~163 ~112 ~98 dirt
setblock ~163 ~112 ~99 dirt
setblock ~163 ~112 ~100 dirt
setblock ~163 ~112 ~101 dirt
setblock ~163 ~112 ~102 dirt
setblock ~163 ~112 ~103 dirt
setblock ~163 ~112 ~104 dirt
setblock ~163 ~113 ~82 dirt
setblock ~163 ~113 ~83 dirt
setblock ~163 ~113 ~84 dirt
setblock ~163 ~113 ~85 dirt
setblock ~163 ~113 ~86 dirt
setblock ~163 ~113 ~87 dirt
setblock ~163 ~113 ~88 dirt
setblock ~163 ~113 ~89 dirt
setblock ~163 ~113 ~90 dirt
setblock ~163 ~113 ~91 dirt
setblock ~163 ~113 ~92 dirt
setblock ~163 ~113 ~93 dirt
setblock ~163 ~113 ~94 dirt
setblock ~163 ~113 ~95 dirt
setblock ~163 ~113 ~96 dirt
setblock ~163 ~113 ~97 dirt
setblock ~163 ~113 ~98 dirt
setblock ~163 ~113 ~99 dirt
setblock ~163 ~113 ~100 dirt
setblock ~163 ~113 ~101 dirt
setblock ~163 ~113 ~102 dirt
setblock ~163 ~113 ~103 dirt
setblock ~163 ~113 ~104 dirt
setblock ~163 ~114 ~82 dirt
setblock ~163 ~114 ~83 dirt
setblock ~163 ~114 ~84 dirt
setblock ~163 ~114 ~85 dirt
setblock ~163 ~114 ~86 dirt
setblock ~163 ~114 ~87 dirt
setblock ~163 ~114 ~88 dirt
setblock ~163 ~114 ~89 dirt
setblock ~163 ~114 ~90 dirt
setblock ~163 ~114 ~91 dirt
setblock ~163 ~114 ~92 dirt
setblock ~163 ~114 ~93 dirt
setblock ~163 ~114 ~94 dirt
setblock ~163 ~114 ~95 dirt
setblock ~163 ~114 ~96 dirt
setblock ~163 ~114 ~97 dirt
setblock ~163 ~114 ~98 dirt
setblock ~163 ~114 ~99 dirt
setblock ~163 ~114 ~100 dirt
setblock ~163 ~114 ~101 dirt
setblock ~163 ~114 ~102 dirt
setblock ~163 ~114 ~103 dirt
setblock ~163 ~114 ~104 dirt
setblock ~163 ~114 ~105 dirt
setblock ~163 ~115 ~82 dirt
setblock ~163 ~115 ~83 dirt
setblock ~163 ~115 ~84 dirt
setblock ~163 ~115 ~85 dirt
setblock ~163 ~115 ~86 dirt
setblock ~163 ~115 ~87 dirt
setblock ~163 ~115 ~88 dirt
setblock ~163 ~115 ~89 dirt
setblock ~163 ~115 ~90 dirt
setblock ~163 ~115 ~91 dirt
setblock ~163 ~115 ~92 dirt
setblock ~163 ~115 ~93 dirt
setblock ~163 ~115 ~94 dirt
setblock ~163 ~115 ~95 dirt
setblock ~163 ~115 ~96 dirt
setblock ~163 ~115 ~97 dirt
setblock ~163 ~115 ~98 dirt
setblock ~163 ~115 ~99 dirt
setblock ~163 ~115 ~100 dirt
setblock ~163 ~115 ~101 dirt
setblock ~163 ~115 ~102 dirt
setblock ~163 ~115 ~103 dirt
setblock ~163 ~115 ~104 dirt
setblock ~163 ~115 ~105 dirt
setblock ~163 ~115 ~106 dirt
setblock ~163 ~116 ~81 dirt
setblock ~163 ~116 ~82 dirt
setblock ~163 ~116 ~83 dirt
setblock ~163 ~116 ~84 dirt
setblock ~163 ~116 ~85 dirt
setblock ~163 ~116 ~86 dirt
setblock ~163 ~116 ~87 dirt
setblock ~163 ~116 ~88 dirt
setblock ~163 ~116 ~89 dirt
setblock ~163 ~116 ~90 dirt
setblock ~163 ~116 ~91 dirt
setblock ~163 ~116 ~92 dirt
setblock ~163 ~116 ~93 dirt
setblock ~163 ~116 ~94 dirt
setblock ~163 ~116 ~95 dirt
setblock ~163 ~116 ~96 dirt
setblock ~163 ~116 ~97 dirt
setblock ~163 ~116 ~98 dirt
setblock ~163 ~116 ~99 dirt
setblock ~163 ~116 ~100 dirt
setblock ~163 ~116 ~101 dirt
setblock ~163 ~116 ~102 dirt
setblock ~163 ~116 ~103 dirt
setblock ~163 ~116 ~104 dirt
setblock ~163 ~116 ~105 dirt
setblock ~163 ~116 ~106 dirt
setblock ~163 ~116 ~107 dirt
setblock ~163 ~117 ~81 dirt
setblock ~163 ~117 ~82 dirt
setblock ~163 ~117 ~83 dirt
setblock ~163 ~117 ~84 dirt
setblock ~163 ~117 ~85 dirt
setblock ~163 ~117 ~86 dirt
setblock ~163 ~117 ~87 dirt
setblock ~163 ~117 ~88 dirt
setblock ~163 ~117 ~89 dirt
setblock ~163 ~117 ~90 dirt
setblock ~163 ~117 ~91 dirt
setblock ~163 ~117 ~92 dirt
setblock ~163 ~117 ~93 dirt
setblock ~163 ~117 ~94 dirt
setblock ~163 ~117 ~95 dirt
setblock ~163 ~117 ~96 dirt
setblock ~163 ~117 ~97 dirt
setblock ~163 ~117 ~98 dirt
setblock ~163 ~117 ~99 dirt
setblock ~163 ~117 ~100 dirt
setblock ~163 ~117 ~101 dirt
setblock ~163 ~117 ~102 dirt
setblock ~163 ~117 ~103 dirt
setblock ~163 ~117 ~104 dirt
setblock ~163 ~117 ~105 dirt
setblock ~163 ~117 ~106 dirt
setblock ~163 ~117 ~107 dirt
setblock ~163 ~117 ~108 dirt
setblock ~163 ~118 ~80 dirt
setblock ~163 ~118 ~81 dirt
setblock ~163 ~118 ~82 dirt
setblock ~163 ~118 ~83 dirt
setblock ~163 ~118 ~84 dirt
setblock ~163 ~118 ~85 dirt
setblock ~163 ~118 ~86 dirt
setblock ~163 ~118 ~87 dirt
setblock ~163 ~118 ~88 dirt
setblock ~163 ~118 ~89 dirt
setblock ~163 ~118 ~90 dirt
setblock ~163 ~118 ~91 dirt
setblock ~163 ~118 ~92 dirt
setblock ~163 ~118 ~93 dirt
setblock ~163 ~118 ~94 dirt
setblock ~163 ~118 ~95 dirt
setblock ~163 ~118 ~96 dirt
setblock ~163 ~118 ~97 dirt
setblock ~163 ~118 ~98 dirt
setblock ~163 ~118 ~99 dirt
setblock ~163 ~118 ~100 dirt
setblock ~163 ~118 ~101 dirt
setblock ~163 ~118 ~102 dirt
setblock ~163 ~118 ~103 dirt
setblock ~163 ~118 ~104 dirt
setblock ~163 ~118 ~105 dirt
setblock ~163 ~118 ~106 dirt
setblock ~163 ~118 ~107 dirt
setblock ~163 ~118 ~108 dirt
setblock ~163 ~118 ~109 dirt
setblock ~163 ~119 ~80 dirt
setblock ~163 ~119 ~81 dirt
setblock ~163 ~119 ~82 dirt
setblock ~163 ~119 ~83 dirt
setblock ~163 ~119 ~84 dirt
setblock ~163 ~119 ~85 dirt
setblock ~163 ~119 ~86 dirt
setblock ~163 ~119 ~87 dirt
setblock ~163 ~119 ~88 dirt
setblock ~163 ~119 ~89 dirt
setblock ~163 ~119 ~90 dirt
setblock ~163 ~119 ~91 dirt
setblock ~163 ~119 ~92 dirt
setblock ~163 ~119 ~93 dirt
setblock ~163 ~119 ~94 dirt
setblock ~163 ~119 ~95 dirt
setblock ~163 ~119 ~96 dirt
setblock ~163 ~119 ~97 dirt
setblock ~163 ~119 ~98 dirt
setblock ~163 ~119 ~99 dirt
setblock ~163 ~119 ~100 dirt
setblock ~163 ~119 ~101 dirt
setblock ~163 ~119 ~102 dirt
setblock ~163 ~119 ~103 dirt
setblock ~163 ~119 ~104 dirt
setblock ~163 ~119 ~105 dirt
setblock ~163 ~119 ~106 dirt
setblock ~163 ~119 ~107 dirt
setblock ~163 ~119 ~108 dirt
setblock ~163 ~119 ~109 dirt
setblock ~163 ~119 ~110 dirt
setblock ~163 ~120 ~80 dirt
setblock ~163 ~120 ~81 dirt
setblock ~163 ~120 ~82 dirt
setblock ~163 ~120 ~83 dirt
setblock ~163 ~120 ~84 dirt
setblock ~163 ~120 ~85 dirt
setblock ~163 ~120 ~86 dirt
setblock ~163 ~120 ~87 dirt
setblock ~163 ~120 ~88 dirt
setblock ~163 ~120 ~89 dirt
setblock ~163 ~120 ~90 dirt
setblock ~163 ~120 ~91 dirt
setblock ~163 ~120 ~92 dirt
setblock ~163 ~120 ~93 dirt
setblock ~163 ~120 ~94 dirt
setblock ~163 ~120 ~95 dirt
setblock ~163 ~120 ~96 dirt
setblock ~163 ~120 ~97 dirt
setblock ~163 ~120 ~98 dirt
setblock ~163 ~120 ~99 dirt
setblock ~163 ~120 ~100 dirt
setblock ~163 ~120 ~101 dirt
setblock ~163 ~120 ~102 dirt
setblock ~163 ~120 ~103 dirt
setblock ~163 ~120 ~104 dirt
setblock ~163 ~120 ~105 dirt
setblock ~163 ~120 ~106 dirt
setblock ~163 ~120 ~107 dirt
setblock ~163 ~120 ~108 dirt
setblock ~163 ~120 ~109 dirt
setblock ~163 ~120 ~110 dirt
setblock ~163 ~121 ~79 dirt
setblock ~163 ~121 ~80 dirt
setblock ~163 ~121 ~81 dirt
setblock ~163 ~121 ~82 dirt
setblock ~163 ~121 ~83 dirt
setblock ~163 ~121 ~84 dirt
setblock ~163 ~121 ~85 dirt
setblock ~163 ~121 ~86 dirt
setblock ~163 ~121 ~87 dirt
setblock ~163 ~121 ~88 dirt
setblock ~163 ~121 ~89 dirt
setblock ~163 ~121 ~90 dirt
setblock ~163 ~121 ~91 dirt
setblock ~163 ~121 ~92 dirt
setblock ~163 ~121 ~93 dirt
setblock ~163 ~121 ~94 dirt
setblock ~163 ~121 ~95 dirt
setblock ~163 ~121 ~96 dirt
setblock ~163 ~121 ~97 dirt
setblock ~163 ~121 ~98 dirt
setblock ~163 ~121 ~99 dirt
setblock ~163 ~121 ~100 dirt
setblock ~163 ~121 ~101 dirt
setblock ~163 ~121 ~102 dirt
setblock ~163 ~121 ~103 dirt
setblock ~163 ~121 ~104 dirt
setblock ~163 ~121 ~105 dirt
setblock ~163 ~121 ~106 dirt
setblock ~163 ~121 ~107 dirt
setblock ~163 ~121 ~108 dirt
setblock ~163 ~121 ~109 dirt
setblock ~163 ~121 ~110 dirt
setblock ~163 ~122 ~79 dirt
setblock ~163 ~122 ~80 dirt
setblock ~163 ~122 ~81 dirt
setblock ~163 ~122 ~82 dirt
setblock ~163 ~122 ~83 dirt
setblock ~163 ~122 ~84 dirt
setblock ~163 ~122 ~85 dirt
setblock ~163 ~122 ~86 dirt
setblock ~163 ~122 ~87 dirt
setblock ~163 ~122 ~88 dirt
setblock ~163 ~122 ~89 dirt
setblock ~163 ~122 ~90 dirt
setblock ~163 ~122 ~91 dirt
setblock ~163 ~122 ~92 dirt
setblock ~163 ~122 ~93 dirt
setblock ~163 ~122 ~94 dirt
setblock ~163 ~122 ~95 dirt
setblock ~163 ~122 ~96 dirt
setblock ~163 ~122 ~97 dirt
setblock ~163 ~122 ~98 dirt
setblock ~163 ~122 ~99 dirt
setblock ~163 ~122 ~100 dirt
setblock ~163 ~122 ~101 dirt
setblock ~163 ~122 ~102 dirt
setblock ~163 ~122 ~103 dirt
setblock ~163 ~122 ~104 dirt
setblock ~163 ~122 ~105 dirt
setblock ~163 ~122 ~106 dirt
setblock ~163 ~122 ~107 dirt
setblock ~163 ~122 ~108 dirt
setblock ~163 ~122 ~109 dirt
setblock ~163 ~122 ~110 dirt
setblock ~163 ~123 ~79 dirt
setblock ~163 ~123 ~80 dirt
setblock ~163 ~123 ~81 dirt
setblock ~163 ~123 ~82 dirt
setblock ~163 ~123 ~83 dirt
setblock ~163 ~123 ~84 dirt
setblock ~163 ~123 ~85 dirt
setblock ~163 ~123 ~86 dirt
setblock ~163 ~123 ~87 dirt
setblock ~163 ~123 ~88 dirt
setblock ~163 ~123 ~89 dirt
setblock ~163 ~123 ~90 dirt
setblock ~163 ~123 ~91 dirt
setblock ~163 ~123 ~92 dirt
setblock ~163 ~123 ~93 dirt
setblock ~163 ~123 ~94 dirt
setblock ~163 ~123 ~95 dirt
setblock ~163 ~123 ~96 dirt
setblock ~163 ~123 ~97 dirt
setblock ~163 ~123 ~98 dirt
setblock ~163 ~123 ~99 dirt
setblock ~163 ~123 ~100 dirt
setblock ~163 ~123 ~101 dirt
setblock ~163 ~123 ~102 dirt
setblock ~163 ~123 ~103 dirt
setblock ~163 ~123 ~104 dirt
setblock ~163 ~123 ~105 dirt
setblock ~163 ~123 ~106 grass_block
setblock ~163 ~123 ~107 grass_block
setblock ~163 ~123 ~108 grass_block
setblock ~163 ~123 ~109 grass_block
setblock ~163 ~123 ~110 grass_block
setblock ~163 ~124 ~79 dirt
setblock ~163 ~124 ~80 dirt
setblock ~163 ~124 ~81 dirt
setblock ~163 ~124 ~82 dirt
setblock ~163 ~124 ~83 dirt
setblock ~163 ~124 ~84 dirt
setblock ~163 ~124 ~85 dirt
setblock ~163 ~124 ~86 dirt
setblock ~163 ~124 ~87 dirt
setblock ~163 ~124 ~88 dirt
setblock ~163 ~124 ~89 dirt
setblock ~163 ~124 ~90 dirt
setblock ~163 ~124 ~91 dirt
setblock ~163 ~124 ~92 dirt
setblock ~163 ~124 ~93 dirt
setblock ~163 ~124 ~94 dirt
setblock ~163 ~124 ~95 dirt
setblock ~163 ~124 ~96 dirt
setblock ~163 ~124 ~97 dirt
setblock ~163 ~124 ~98 dirt
setblock ~163 ~124 ~99 grass_block
setblock ~163 ~124 ~100 grass_block
setblock ~163 ~124 ~101 grass_block
setblock ~163 ~124 ~102 grass_block
setblock ~163 ~124 ~103 grass_block
setblock ~163 ~124 ~104 grass_block
setblock ~163 ~124 ~105 grass_block
setblock ~163 ~124 ~108 fern
setblock ~163 ~124 ~109 short_grass
setblock ~163 ~124 ~110 poppy
setblock ~163 ~125 ~79 dirt
setblock ~163 ~125 ~80 dirt
setblock ~163 ~125 ~81 dirt
setblock ~163 ~125 ~82 dirt
setblock ~163 ~125 ~83 dirt
setblock ~163 ~125 ~84 dirt
setblock ~163 ~125 ~85 dirt
setblock ~163 ~125 ~86 dirt
setblock ~163 ~125 ~87 grass_block
setblock ~163 ~125 ~88 grass_block
setblock ~163 ~125 ~89 grass_block
setblock ~163 ~125 ~90 grass_block
setblock ~163 ~125 ~91 grass_block
setblock ~163 ~125 ~92 grass_block
setblock ~163 ~125 ~93 grass_block
setblock ~163 ~125 ~94 grass_block
setblock ~163 ~125 ~95 grass_block
setblock ~163 ~125 ~96 grass_block
setblock ~163 ~125 ~97 grass_block
setblock ~163 ~125 ~98 grass_block
setblock ~163 ~125 ~101 short_grass
setblock ~163 ~125 ~102 short_grass
setblock ~163 ~125 ~103 short_grass
setblock ~163 ~125 ~105 short_grass
setblock ~163 ~126 ~79 grass_block
setblock ~163 ~126 ~80 grass_block
setblock ~163 ~126 ~81 grass_block
setblock ~163 ~126 ~82 grass_block
setblock ~163 ~126 ~83 grass_block
setblock ~163 ~126 ~84 grass_block
setblock ~163 ~126 ~85 grass_block
setblock ~163 ~126 ~86 grass_block
setblock ~163 ~126 ~98 short_grass
setblock ~163 ~127 ~80 short_grass
setblock ~163 ~127 ~81 short_grass
setblock ~163 ~127 ~82 short_grass
setblock ~163 ~127 ~83 short_grass
setblock ~163 ~127 ~84 fern
setblock ~164 ~105 ~96 dirt
setblock ~164 ~106 ~96 dirt
setblock ~164 ~106 ~97 dirt
setblock ~164 ~106 ~99 dirt
setblock ~164 ~107 ~90 dirt
setblock ~164 ~107 ~93 dirt
setblock ~164 ~107 ~95 dirt
setblock ~164 ~107 ~96 dirt
setblock ~164 ~107 ~97 dirt
setblock ~164 ~107 ~99 dirt
setblock ~164 ~107 ~100 dirt
setblock ~164 ~108 ~87 dirt
setblock ~164 ~108 ~89 dirt
setblock ~164 ~108 ~90 dirt
setblock ~164 ~108 ~91 dirt
setblock ~164 ~108 ~92 dirt
setblock ~164 ~108 ~93 dirt
setblock ~164 ~108 ~94 dirt
setblock ~164 ~108 ~95 dirt
setblock ~164 ~108 ~96 dirt
setblock ~164 ~108 ~97 dirt
setblock ~164 ~108 ~98 dirt
setblock ~164 ~108 ~99 dirt
setblock ~164 ~108 ~100 dirt
setblock ~164 ~108 ~101 dirt
setblock ~164 ~109 ~87 dirt
setblock ~164 ~109 ~89 dirt
setblock ~164 ~109 ~90 dirt
setblock ~164 ~109 ~91 dirt
setblock ~164 ~109 ~92 dirt
setblock ~164 ~109 ~93 dirt
setblock ~164 ~109 ~94 dirt
setblock ~164 ~109 ~95 dirt
setblock ~164 ~109 ~96 dirt
setblock ~164 ~109 ~97 dirt
setblock ~164 ~109 ~98 dirt
setblock ~164 ~109 ~99 dirt
setblock ~164 ~109 ~100 dirt
setblock ~164 ~109 ~101 dirt
setblock ~164 ~109 ~102 dirt
setblock ~164 ~110 ~86 dirt
setblock ~164 ~110 ~87 dirt
setblock ~164 ~110 ~88 dirt
setblock ~164 ~110 ~89 dirt
setblock ~164 ~110 ~90 dirt
setblock ~164 ~110 ~91 dirt
setblock ~164 ~110 ~92 dirt
setblock ~164 ~110 ~93 dirt
setblock ~164 ~110 ~94 dirt
setblock ~164 ~110 ~95 dirt
setblock ~164 ~110 ~96 dirt
setblock ~164 ~110 ~97 dirt
setblock ~164 ~110 ~98 dirt
setblock ~164 ~110 ~99 dirt
setblock ~164 ~110 ~100 dirt
setblock ~164 ~110 ~101 dirt
setblock ~164 ~110 ~102 dirt
setblock ~164 ~110 ~103 dirt
setblock ~164 ~111 ~85 dirt
setblock ~164 ~111 ~86 dirt
setblock ~164 ~111 ~87 dirt
setblock ~164 ~111 ~88 dirt
setblock ~164 ~111 ~89 dirt
setblock ~164 ~111 ~90 dirt
setblock ~164 ~111 ~91 dirt
setblock ~164 ~111 ~92 dirt
setblock ~164 ~111 ~93 dirt
setblock ~164 ~111 ~94 dirt
setblock ~164 ~111 ~95 dirt
setblock ~164 ~111 ~96 dirt
setblock ~164 ~111 ~97 dirt
setblock ~164 ~111 ~98 dirt
setblock ~164 ~111 ~99 dirt
setblock ~164 ~111 ~100 dirt
setblock ~164 ~111 ~101 dirt
setblock ~164 ~111 ~102 dirt
setblock ~164 ~111 ~103 dirt
setblock ~164 ~112 ~84 dirt
setblock ~164 ~112 ~85 dirt
setblock ~164 ~112 ~86 dirt
setblock ~164 ~112 ~87 dirt
setblock ~164 ~112 ~88 dirt
setblock ~164 ~112 ~89 dirt
setblock ~164 ~112 ~90 dirt
setblock ~164 ~112 ~91 dirt
setblock ~164 ~112 ~92 dirt
setblock ~164 ~112 ~93 dirt
setblock ~164 ~112 ~94 dirt
setblock ~164 ~112 ~95 dirt
setblock ~164 ~112 ~96 dirt
setblock ~164 ~112 ~97 dirt
setblock ~164 ~112 ~98 dirt
setblock ~164 ~112 ~99 dirt
setblock ~164 ~112 ~100 dirt
setblock ~164 ~112 ~101 dirt
setblock ~164 ~112 ~102 dirt
setblock ~164 ~112 ~103 dirt
setblock ~164 ~112 ~104 dirt
setblock ~164 ~113 ~83 dirt
setblock ~164 ~113 ~84 dirt
setblock ~164 ~113 ~85 dirt
setblock ~164 ~113 ~86 dirt
setblock ~164 ~113 ~87 dirt
setblock ~164 ~113 ~88 dirt
setblock ~164 ~113 ~89 dirt
setblock ~164 ~113 ~90 dirt
setblock ~164 ~113 ~91 dirt
setblock ~164 ~113 ~92 dirt
setblock ~164 ~113 ~93 dirt
setblock ~164 ~113 ~94 dirt
setblock ~164 ~113 ~95 dirt
setblock ~164 ~113 ~96 dirt
setblock ~164 ~113 ~97 dirt
setblock ~164 ~113 ~98 dirt
setblock ~164 ~113 ~99 dirt
setblock ~164 ~113 ~100 dirt
setblock ~164 ~113 ~101 dirt
setblock ~164 ~113 ~102 dirt
setblock ~164 ~113 ~103 dirt
setblock ~164 ~113 ~104 dirt
setblock ~164 ~114 ~83 dirt
setblock ~164 ~114 ~84 dirt
setblock ~164 ~114 ~85 dirt
setblock ~164 ~114 ~86 dirt
setblock ~164 ~114 ~87 dirt
setblock ~164 ~114 ~88 dirt
setblock ~164 ~114 ~89 dirt
setblock ~164 ~114 ~90 dirt
setblock ~164 ~114 ~91 dirt
setblock ~164 ~114 ~92 dirt
setblock ~164 ~114 ~93 dirt
setblock ~164 ~114 ~94 dirt
setblock ~164 ~114 ~95 dirt
setblock ~164 ~114 ~96 dirt
setblock ~164 ~114 ~97 dirt
setblock ~164 ~114 ~98 dirt
setblock ~164 ~114 ~99 dirt
setblock ~164 ~114 ~100 dirt
setblock ~164 ~114 ~101 dirt
setblock ~164 ~114 ~102 dirt
setblock ~164 ~114 ~103 dirt
setblock ~164 ~114 ~104 dirt
setblock ~164 ~115 ~82 dirt
setblock ~164 ~115 ~83 dirt
setblock ~164 ~115 ~84 dirt
setblock ~164 ~115 ~85 dirt
setblock ~164 ~115 ~86 dirt
setblock ~164 ~115 ~87 dirt
setblock ~164 ~115 ~88 dirt
setblock ~164 ~115 ~89 dirt
setblock ~164 ~115 ~90 dirt
setblock ~164 ~115 ~91 dirt
setblock ~164 ~115 ~92 dirt
setblock ~164 ~115 ~93 dirt
setblock ~164 ~115 ~94 dirt
setblock ~164 ~115 ~95 dirt
setblock ~164 ~115 ~96 dirt
setblock ~164 ~115 ~97 dirt
setblock ~164 ~115 ~98 dirt
setblock ~164 ~115 ~99 dirt
setblock ~164 ~115 ~100 dirt
setblock ~164 ~115 ~101 dirt
setblock ~164 ~115 ~102 dirt
setblock ~164 ~115 ~103 dirt
setblock ~164 ~115 ~104 dirt
setblock ~164 ~115 ~105 dirt
setblock ~164 ~116 ~81 dirt
setblock ~164 ~116 ~82 dirt
setblock ~164 ~116 ~83 dirt
setblock ~164 ~116 ~84 dirt
setblock ~164 ~116 ~85 dirt
setblock ~164 ~116 ~86 dirt
setblock ~164 ~116 ~87 dirt
setblock ~164 ~116 ~88 dirt
setblock ~164 ~116 ~89 dirt
setblock ~164 ~116 ~90 dirt
setblock ~164 ~116 ~91 dirt
setblock ~164 ~116 ~92 dirt
setblock ~164 ~116 ~93 dirt
setblock ~164 ~116 ~94 dirt
setblock ~164 ~116 ~95 dirt
setblock ~164 ~116 ~96 dirt
setblock ~164 ~116 ~97 dirt
setblock ~164 ~116 ~98 dirt
setblock ~164 ~116 ~99 dirt
setblock ~164 ~116 ~100 dirt
setblock ~164 ~116 ~101 dirt
setblock ~164 ~116 ~102 dirt
setblock ~164 ~116 ~103 dirt
setblock ~164 ~116 ~104 dirt
setblock ~164 ~116 ~105 dirt
setblock ~164 ~116 ~106 dirt
setblock ~164 ~117 ~80 dirt
setblock ~164 ~117 ~81 dirt
setblock ~164 ~117 ~82 dirt
setblock ~164 ~117 ~83 dirt
setblock ~164 ~117 ~84 dirt
setblock ~164 ~117 ~85 dirt
setblock ~164 ~117 ~86 dirt
setblock ~164 ~117 ~87 dirt
setblock ~164 ~117 ~88 dirt
setblock ~164 ~117 ~89 dirt
setblock ~164 ~117 ~90 dirt
setblock ~164 ~117 ~91 dirt
setblock ~164 ~117 ~92 dirt
setblock ~164 ~117 ~93 dirt
setblock ~164 ~117 ~94 dirt
setblock ~164 ~117 ~95 dirt
setblock ~164 ~117 ~96 dirt
setblock ~164 ~117 ~97 dirt
setblock ~164 ~117 ~98 dirt
setblock ~164 ~117 ~99 dirt
setblock ~164 ~117 ~100 dirt
setblock ~164 ~117 ~101 dirt
setblock ~164 ~117 ~102 dirt
setblock ~164 ~117 ~103 dirt
setblock ~164 ~117 ~104 dirt
setblock ~164 ~117 ~105 dirt
setblock ~164 ~117 ~106 dirt
setblock ~164 ~117 ~107 dirt
setblock ~164 ~118 ~79 dirt
setblock ~164 ~118 ~80 dirt
setblock ~164 ~118 ~81 dirt
setblock ~164 ~118 ~82 dirt
setblock ~164 ~118 ~83 dirt
setblock ~164 ~118 ~84 dirt
setblock ~164 ~118 ~85 dirt
setblock ~164 ~118 ~86 dirt
setblock ~164 ~118 ~87 dirt
setblock ~164 ~118 ~88 dirt
setblock ~164 ~118 ~89 dirt
setblock ~164 ~118 ~90 dirt
setblock ~164 ~118 ~91 dirt
setblock ~164 ~118 ~92 dirt
setblock ~164 ~118 ~93 dirt
setblock ~164 ~118 ~94 dirt
setblock ~164 ~118 ~95 dirt
setblock ~164 ~118 ~96 dirt
setblock ~164 ~118 ~97 dirt
setblock ~164 ~118 ~98 dirt
setblock ~164 ~118 ~99 dirt
setblock ~164 ~118 ~100 dirt
setblock ~164 ~118 ~101 dirt
setblock ~164 ~118 ~102 dirt
setblock ~164 ~118 ~103 dirt
setblock ~164 ~118 ~104 dirt
setblock ~164 ~118 ~105 dirt
setblock ~164 ~118 ~106 dirt
setblock ~164 ~118 ~107 dirt
setblock ~164 ~118 ~108 dirt
setblock ~164 ~119 ~79 dirt
setblock ~164 ~119 ~80 dirt
setblock ~164 ~119 ~81 dirt
setblock ~164 ~119 ~82 dirt
setblock ~164 ~119 ~83 dirt
setblock ~164 ~119 ~84 dirt
setblock ~164 ~119 ~85 dirt
setblock ~164 ~119 ~86 dirt
setblock ~164 ~119 ~87 dirt
setblock ~164 ~119 ~88 dirt
setblock ~164 ~119 ~89 dirt
setblock ~164 ~119 ~90 dirt
setblock ~164 ~119 ~91 dirt
setblock ~164 ~119 ~92 dirt
setblock ~164 ~119 ~93 dirt
setblock ~164 ~119 ~94 dirt
setblock ~164 ~119 ~95 dirt
setblock ~164 ~119 ~96 dirt
setblock ~164 ~119 ~97 dirt
setblock ~164 ~119 ~98 dirt
setblock ~164 ~119 ~99 dirt
setblock ~164 ~119 ~100 dirt
setblock ~164 ~119 ~101 dirt
setblock ~164 ~119 ~102 dirt
setblock ~164 ~119 ~103 dirt
setblock ~164 ~119 ~104 dirt
setblock ~164 ~119 ~105 dirt
setblock ~164 ~119 ~106 dirt
setblock ~164 ~119 ~107 dirt
setblock ~164 ~119 ~108 dirt
setblock ~164 ~119 ~109 dirt
setblock ~164 ~120 ~79 dirt
setblock ~164 ~120 ~80 dirt
setblock ~164 ~120 ~81 dirt
setblock ~164 ~120 ~82 dirt
setblock ~164 ~120 ~83 dirt
setblock ~164 ~120 ~84 dirt
setblock ~164 ~120 ~85 dirt
setblock ~164 ~120 ~86 dirt
setblock ~164 ~120 ~87 dirt
setblock ~164 ~120 ~88 dirt
setblock ~164 ~120 ~89 dirt
setblock ~164 ~120 ~90 dirt
setblock ~164 ~120 ~91 dirt
setblock ~164 ~120 ~92 dirt
setblock ~164 ~120 ~93 dirt
setblock ~164 ~120 ~94 dirt
setblock ~164 ~120 ~95 dirt
setblock ~164 ~120 ~96 dirt
setblock ~164 ~120 ~97 dirt
setblock ~164 ~120 ~98 dirt
setblock ~164 ~120 ~99 dirt
setblock ~164 ~120 ~100 dirt
setblock ~164 ~120 ~101 dirt
setblock ~164 ~120 ~102 dirt
setblock ~164 ~120 ~103 dirt
setblock ~164 ~120 ~104 dirt
setblock ~164 ~120 ~105 dirt
setblock ~164 ~120 ~106 dirt
setblock ~164 ~120 ~107 dirt
setblock ~164 ~120 ~108 dirt
setblock ~164 ~120 ~109 dirt
setblock ~164 ~121 ~78 dirt
setblock ~164 ~121 ~79 dirt
setblock ~164 ~121 ~80 dirt
setblock ~164 ~121 ~81 dirt
setblock ~164 ~121 ~82 dirt
setblock ~164 ~121 ~83 dirt
setblock ~164 ~121 ~84 dirt
setblock ~164 ~121 ~85 dirt
setblock ~164 ~121 ~86 dirt
setblock ~164 ~121 ~87 dirt
setblock ~164 ~121 ~88 dirt
setblock ~164 ~121 ~89 dirt
setblock ~164 ~121 ~90 dirt
setblock ~164 ~121 ~91 dirt
setblock ~164 ~121 ~92 dirt
setblock ~164 ~121 ~93 dirt
setblock ~164 ~121 ~94 dirt
setblock ~164 ~121 ~95 dirt
setblock ~164 ~121 ~96 dirt
setblock ~164 ~121 ~97 dirt
setblock ~164 ~121 ~98 dirt
setblock ~164 ~121 ~99 dirt
setblock ~164 ~121 ~100 dirt
setblock ~164 ~121 ~101 dirt
setblock ~164 ~121 ~102 dirt
setblock ~164 ~121 ~103 dirt
setblock ~164 ~121 ~104 dirt
setblock ~164 ~121 ~105 dirt
setblock ~164 ~121 ~106 dirt
setblock ~164 ~121 ~107 dirt
setblock ~164 ~121 ~108 dirt
setblock ~164 ~121 ~109 dirt
setblock ~164 ~121 ~110 dirt
setblock ~164 ~122 ~78 dirt
setblock ~164 ~122 ~79 dirt
setblock ~164 ~122 ~80 dirt
setblock ~164 ~122 ~81 dirt
setblock ~164 ~122 ~82 dirt
setblock ~164 ~122 ~83 dirt
setblock ~164 ~122 ~84 dirt
setblock ~164 ~122 ~85 dirt
setblock ~164 ~122 ~86 dirt
setblock ~164 ~122 ~87 dirt
setblock ~164 ~122 ~88 dirt
setblock ~164 ~122 ~89 dirt
setblock ~164 ~122 ~90 dirt
setblock ~164 ~122 ~91 dirt
setblock ~164 ~122 ~92 dirt
setblock ~164 ~122 ~93 dirt
setblock ~164 ~122 ~94 dirt
setblock ~164 ~122 ~95 dirt
setblock ~164 ~122 ~96 dirt
setblock ~164 ~122 ~97 dirt
setblock ~164 ~122 ~98 dirt
setblock ~164 ~122 ~99 dirt
setblock ~164 ~122 ~100 dirt
setblock ~164 ~122 ~101 dirt
setblock ~164 ~122 ~102 dirt
setblock ~164 ~122 ~103 dirt
setblock ~164 ~122 ~104 dirt
setblock ~164 ~122 ~105 dirt
setblock ~164 ~122 ~106 dirt
setblock ~164 ~122 ~107 dirt
setblock ~164 ~122 ~108 dirt
setblock ~164 ~122 ~109 dirt
setblock ~164 ~122 ~110 dirt
setblock ~164 ~123 ~78 dirt
setblock ~164 ~123 ~79 dirt
setblock ~164 ~123 ~80 dirt
setblock ~164 ~123 ~81 dirt
setblock ~164 ~123 ~82 dirt
setblock ~164 ~123 ~83 dirt
setblock ~164 ~123 ~84 dirt
setblock ~164 ~123 ~85 dirt
setblock ~164 ~123 ~86 dirt
setblock ~164 ~123 ~87 dirt
setblock ~164 ~123 ~88 dirt
setblock ~164 ~123 ~89 dirt
setblock ~164 ~123 ~90 dirt
setblock ~164 ~123 ~91 dirt
setblock ~164 ~123 ~92 dirt
setblock ~164 ~123 ~93 dirt
setblock ~164 ~123 ~94 dirt
setblock ~164 ~123 ~95 dirt
setblock ~164 ~123 ~96 dirt
setblock ~164 ~123 ~97 dirt
setblock ~164 ~123 ~98 dirt
setblock ~164 ~123 ~99 dirt
setblock ~164 ~123 ~100 dirt
setblock ~164 ~123 ~101 dirt
setblock ~164 ~123 ~102 dirt
setblock ~164 ~123 ~103 dirt
setblock ~164 ~123 ~104 dirt
setblock ~164 ~123 ~105 dirt
setblock ~164 ~123 ~106 grass_block
setblock ~164 ~123 ~107 grass_block
setblock ~164 ~123 ~108 grass_block
setblock ~164 ~123 ~109 grass_block
setblock ~164 ~123 ~110 grass_block
setblock ~164 ~124 ~78 dirt
setblock ~164 ~124 ~79 dirt
setblock ~164 ~124 ~80 dirt
setblock ~164 ~124 ~81 dirt
setblock ~164 ~124 ~82 dirt
setblock ~164 ~124 ~83 dirt
setblock ~164 ~124 ~84 dirt
setblock ~164 ~124 ~85 dirt
setblock ~164 ~124 ~86 dirt
setblock ~164 ~124 ~87 dirt
setblock ~164 ~124 ~88 dirt
setblock ~164 ~124 ~89 dirt
setblock ~164 ~124 ~90 dirt
setblock ~164 ~124 ~91 dirt
setblock ~164 ~124 ~92 dirt
setblock ~164 ~124 ~93 dirt
setblock ~164 ~124 ~94 dirt
setblock ~164 ~124 ~95 dirt
setblock ~164 ~124 ~96 dirt
setblock ~164 ~124 ~97 dirt
setblock ~164 ~124 ~98 dirt
setblock ~164 ~124 ~99 dirt
setblock ~164 ~124 ~100 grass_block
setblock ~164 ~124 ~101 grass_block
setblock ~164 ~124 ~102 grass_block
setblock ~164 ~124 ~103 grass_block
setblock ~164 ~124 ~104 grass_block
setblock ~164 ~124 ~105 grass_block
setblock ~164 ~124 ~107 short_grass
setblock ~164 ~124 ~108 short_grass
setblock ~164 ~125 ~78 dirt
setblock ~164 ~125 ~79 dirt
setblock ~164 ~125 ~80 dirt
setblock ~164 ~125 ~81 dirt
setblock ~164 ~125 ~82 dirt
setblock ~164 ~125 ~83 dirt
setblock ~164 ~125 ~84 dirt
setblock ~164 ~125 ~85 dirt
setblock ~164 ~125 ~86 dirt
setblock ~164 ~125 ~87 grass_block
setblock ~164 ~125 ~88 grass_block
setblock ~164 ~125 ~89 grass_block
setblock ~164 ~125 ~90 grass_block
setblock ~164 ~125 ~91 grass_block
setblock ~164 ~125 ~92 grass_block
setblock ~164 ~125 ~93 grass_block
setblock ~164 ~125 ~94 grass_block
setblock ~164 ~125 ~95 grass_block
setblock ~164 ~125 ~96 grass_block
setblock ~164 ~125 ~97 grass_block
setblock ~164 ~125 ~98 grass_block
setblock ~164 ~125 ~99 grass_block
setblock ~164 ~125 ~104 short_grass
setblock ~164 ~126 ~78 grass_block
setblock ~164 ~126 ~79 grass_block
setblock ~164 ~126 ~80 grass_block
setblock ~164 ~126 ~81 grass_block
setblock ~164 ~126 ~82 grass_block
setblock ~164 ~126 ~83 grass_block
setblock ~164 ~126 ~84 grass_block
setblock ~164 ~126 ~85 grass_block
setblock ~164 ~126 ~86 grass_block
setblock ~164 ~126 ~88 short_grass
setblock ~164 ~126 ~95 poppy
setblock ~164 ~126 ~97 short_grass
setblock ~164 ~127 ~80 short_grass
setblock ~164 ~127 ~86 short_grass
setblock ~165 ~107 ~96 dirt
setblock ~165 ~108 ~93 dirt
setblock ~165 ~108 ~95 dirt
setblock ~165 ~108 ~96 dirt
setblock ~165 ~108 ~97 dirt
setblock ~165 ~108 ~99 dirt
setblock ~165 ~109 ~92 dirt
setblock ~165 ~109 ~93 dirt
setblock ~165 ~109 ~94 dirt
setblock ~165 ~109 ~95 dirt
setblock ~165 ~109 ~96 dirt
setblock ~165 ~109 ~97 dirt
setblock ~165 ~109 ~99 dirt
setblock ~165 ~110 ~91 dirt
setblock ~165 ~110 ~92 dirt
setblock ~165 ~110 ~93 dirt
setblock ~165 ~110 ~94 dirt
setblock ~165 ~110 ~95 dirt
setblock ~165 ~110 ~96 dirt
setblock ~165 ~110 ~97 dirt
setblock ~165 ~110 ~98 dirt
setblock ~165 ~110 ~99 dirt
setblock ~165 ~110 ~100 dirt
setblock ~165 ~110 ~102 dirt
setblock ~165 ~111 ~87 dirt
setblock ~165 ~111 ~90 dirt
setblock ~165 ~111 ~91 dirt
setblock ~165 ~111 ~92 dirt
setblock ~165 ~111 ~93 dirt
setblock ~165 ~111 ~94 dirt
setblock ~165 ~111 ~95 dirt
setblock ~165 ~111 ~96 dirt
setblock ~165 ~111 ~97 dirt
setblock ~165 ~111 ~98 dirt
setblock ~165 ~111 ~99 dirt
setblock ~165 ~111 ~100 dirt
setblock ~165 ~111 ~102 dirt
setblock ~165 ~112 ~86 dirt
setblock ~165 ~112 ~87 dirt
setblock ~165 ~112 ~89 dirt
setblock ~165 ~112 ~90 dirt
setblock ~165 ~112 ~91 dirt
setblock ~165 ~112 ~92 dirt
setblock ~165 ~112 ~93 dirt
setblock ~165 ~112 ~94 dirt
setblock ~165 ~112 ~95 dirt
setblock ~165 ~112 ~96 dirt
setblock ~165 ~112 ~97 dirt
setblock ~165 ~112 ~98 dirt
setblock ~165 ~112 ~99 dirt
setblock ~165 ~112 ~100 dirt
setblock ~165 ~112 ~101 dirt
setblock ~165 ~112 ~102 dirt
setblock ~165 ~112 ~103 dirt
setblock ~165 ~113 ~84 dirt
setblock ~165 ~113 ~85 dirt
setblock ~165 ~113 ~86 dirt
setblock ~165 ~113 ~87 dirt
setblock ~165 ~113 ~88 dirt
setblock ~165 ~113 ~89 dirt
setblock ~165 ~113 ~90 dirt
setblock ~165 ~113 ~91 dirt
setblock ~165 ~113 ~92 dirt
setblock ~165 ~113 ~93 dirt
setblock ~165 ~113 ~94 dirt
setblock ~165 ~113 ~95 dirt
setblock ~165 ~113 ~96 dirt
setblock ~165 ~113 ~97 dirt
setblock ~165 ~113 ~98 dirt
setblock ~165 ~113 ~99 dirt
setblock ~165 ~113 ~100 dirt
setblock ~165 ~113 ~101 dirt
setblock ~165 ~113 ~102 dirt
setblock ~165 ~113 ~103 dirt
setblock ~165 ~113 ~104 dirt
setblock ~165 ~114 ~84 dirt
setblock ~165 ~114 ~85 dirt
setblock ~165 ~114 ~86 dirt
setblock ~165 ~114 ~87 dirt
setblock ~165 ~114 ~88 dirt
setblock ~165 ~114 ~89 dirt
setblock ~165 ~114 ~90 dirt
setblock ~165 ~114 ~91 dirt
setblock ~165 ~114 ~92 dirt
setblock ~165 ~114 ~93 dirt
setblock ~165 ~114 ~94 dirt
setblock ~165 ~114 ~95 dirt
setblock ~165 ~114 ~96 dirt
setblock ~165 ~114 ~97 dirt
setblock ~165 ~114 ~98 dirt
setblock ~165 ~114 ~99 dirt
setblock ~165 ~114 ~100 dirt
setblock ~165 ~114 ~101 dirt
setblock ~165 ~114 ~102 dirt
setblock ~165 ~114 ~103 dirt
setblock ~165 ~114 ~104 dirt
setblock ~165 ~115 ~83 dirt
setblock ~165 ~115 ~84 dirt
setblock ~165 ~115 ~85 dirt
setblock ~165 ~115 ~86 dirt
setblock ~165 ~115 ~87 dirt
setblock ~165 ~115 ~88 dirt
setblock ~165 ~115 ~89 dirt
setblock ~165 ~115 ~90 dirt
setblock ~165 ~115 ~91 dirt
setblock ~165 ~115 ~92 dirt
setblock ~165 ~115 ~93 dirt
setblock ~165 ~115 ~94 dirt
setblock ~165 ~115 ~95 dirt
setblock ~165 ~115 ~96 dirt
setblock ~165 ~115 ~97 dirt
setblock ~165 ~115 ~98 dirt
setblock ~165 ~115 ~99 dirt
setblock ~165 ~115 ~100 dirt
setblock ~165 ~115 ~101 dirt
setblock ~165 ~115 ~102 dirt
setblock ~165 ~115 ~103 dirt
setblock ~165 ~115 ~104 dirt
setblock ~165 ~116 ~82 dirt
setblock ~165 ~116 ~83 dirt
setblock ~165 ~116 ~84 dirt
setblock ~165 ~116 ~85 dirt
setblock ~165 ~116 ~86 dirt
setblock ~165 ~116 ~87 dirt
setblock ~165 ~116 ~88 dirt
setblock ~165 ~116 ~89 dirt
setblock ~165 ~116 ~90 dirt
setblock ~165 ~116 ~91 dirt
setblock ~165 ~116 ~92 dirt
setblock ~165 ~116 ~93 dirt
setblock ~165 ~116 ~94 dirt
setblock ~165 ~116 ~95 dirt
setblock ~165 ~116 ~96 dirt
setblock ~165 ~116 ~97 dirt
setblock ~165 ~116 ~98 dirt
setblock ~165 ~116 ~99 dirt
setblock ~165 ~116 ~100 dirt
setblock ~165 ~116 ~101 dirt
setblock ~165 ~116 ~102 dirt
setblock ~165 ~116 ~103 dirt
setblock ~165 ~116 ~104 dirt
setblock ~165 ~116 ~105 dirt
setblock ~165 ~117 ~81 dirt
setblock ~165 ~117 ~82 dirt
setblock ~165 ~117 ~83 dirt
setblock ~165 ~117 ~84 dirt
setblock ~165 ~117 ~85 dirt
setblock ~165 ~117 ~86 dirt
setblock ~165 ~117 ~87 dirt
setblock ~165 ~117 ~88 dirt
setblock ~165 ~117 ~89 dirt
setblock ~165 ~117 ~90 dirt
setblock ~165 ~117 ~91 dirt
setblock ~165 ~117 ~92 dirt
setblock ~165 ~117 ~93 dirt
setblock ~165 ~117 ~94 dirt
setblock ~165 ~117 ~95 dirt
setblock ~165 ~117 ~96 dirt
setblock ~165 ~117 ~97 dirt
setblock ~165 ~117 ~98 dirt
setblock ~165 ~117 ~99 dirt
setblock ~165 ~117 ~100 dirt
setblock ~165 ~117 ~101 dirt
setblock ~165 ~117 ~102 dirt
setblock ~165 ~117 ~103 dirt
setblock ~165 ~117 ~104 dirt
setblock ~165 ~117 ~105 dirt
setblock ~165 ~117 ~106 dirt
setblock ~165 ~118 ~80 dirt
setblock ~165 ~118 ~81 dirt
setblock ~165 ~118 ~82 dirt
setblock ~165 ~118 ~83 dirt
setblock ~165 ~118 ~84 dirt
setblock ~165 ~118 ~85 dirt
setblock ~165 ~118 ~86 dirt
setblock ~165 ~118 ~87 dirt
setblock ~165 ~118 ~88 dirt
setblock ~165 ~118 ~89 dirt
setblock ~165 ~118 ~90 dirt
setblock ~165 ~118 ~91 dirt
setblock ~165 ~118 ~92 dirt
setblock ~165 ~118 ~93 dirt
setblock ~165 ~118 ~94 dirt
setblock ~165 ~118 ~95 dirt
setblock ~165 ~118 ~96 dirt
setblock ~165 ~118 ~97 dirt
setblock ~165 ~118 ~98 dirt
setblock ~165 ~118 ~99 dirt
setblock ~165 ~118 ~100 dirt
setblock ~165 ~118 ~101 dirt
setblock ~165 ~118 ~102 dirt
setblock ~165 ~118 ~103 dirt
setblock ~165 ~118 ~104 dirt
setblock ~165 ~118 ~105 dirt
setblock ~165 ~118 ~106 dirt
setblock ~165 ~118 ~107 dirt
setblock ~165 ~119 ~79 dirt
setblock ~165 ~119 ~80 dirt
setblock ~165 ~119 ~81 dirt
setblock ~165 ~119 ~82 dirt
setblock ~165 ~119 ~83 dirt
setblock ~165 ~119 ~84 dirt
setblock ~165 ~119 ~85 dirt
setblock ~165 ~119 ~86 dirt
setblock ~165 ~119 ~87 dirt
setblock ~165 ~119 ~88 dirt
setblock ~165 ~119 ~89 dirt
setblock ~165 ~119 ~90 dirt
setblock ~165 ~119 ~91 dirt
setblock ~165 ~119 ~92 dirt
setblock ~165 ~119 ~93 dirt
setblock ~165 ~119 ~94 dirt
setblock ~165 ~119 ~95 dirt
setblock ~165 ~119 ~96 dirt
setblock ~165 ~119 ~97 dirt
setblock ~165 ~119 ~98 dirt
setblock ~165 ~119 ~99 dirt
setblock ~165 ~119 ~100 dirt
setblock ~165 ~119 ~101 dirt
setblock ~165 ~119 ~102 dirt
setblock ~165 ~119 ~103 dirt
setblock ~165 ~119 ~104 dirt
setblock ~165 ~119 ~105 dirt
setblock ~165 ~119 ~106 dirt
setblock ~165 ~119 ~107 dirt
setblock ~165 ~119 ~108 dirt
setblock ~165 ~120 ~78 dirt
setblock ~165 ~120 ~79 dirt
setblock ~165 ~120 ~80 dirt
setblock ~165 ~120 ~81 dirt
setblock ~165 ~120 ~82 dirt
setblock ~165 ~120 ~83 dirt
setblock ~165 ~120 ~84 dirt
setblock ~165 ~120 ~85 dirt
setblock ~165 ~120 ~86 dirt
setblock ~165 ~120 ~87 dirt
setblock ~165 ~120 ~88 dirt
setblock ~165 ~120 ~89 dirt
setblock ~165 ~120 ~90 dirt
setblock ~165 ~120 ~91 dirt
setblock ~165 ~120 ~92 dirt
setblock ~165 ~120 ~93 dirt
setblock ~165 ~120 ~94 dirt
setblock ~165 ~120 ~95 dirt
setblock ~165 ~120 ~96 dirt
setblock ~165 ~120 ~97 dirt
setblock ~165 ~120 ~98 dirt
setblock ~165 ~120 ~99 dirt
setblock ~165 ~120 ~100 dirt
setblock ~165 ~120 ~101 dirt
setblock ~165 ~120 ~102 dirt
setblock ~165 ~120 ~103 dirt
setblock ~165 ~120 ~104 dirt
setblock ~165 ~120 ~105 dirt
setblock ~165 ~120 ~106 dirt
setblock ~165 ~120 ~107 dirt
setblock ~165 ~120 ~108 dirt
setblock ~165 ~120 ~109 dirt
setblock ~165 ~121 ~78 dirt
setblock ~165 ~121 ~79 dirt
setblock ~165 ~121 ~80 dirt
setblock ~165 ~121 ~81 dirt
setblock ~165 ~121 ~82 dirt
setblock ~165 ~121 ~83 dirt
setblock ~165 ~121 ~84 dirt
setblock ~165 ~121 ~85 dirt
setblock ~165 ~121 ~86 dirt
setblock ~165 ~121 ~87 dirt
setblock ~165 ~121 ~88 dirt
setblock ~165 ~121 ~89 dirt
setblock ~165 ~121 ~90 dirt
setblock ~165 ~121 ~91 dirt
setblock ~165 ~121 ~92 dirt
setblock ~165 ~121 ~93 dirt
setblock ~165 ~121 ~94 dirt
setblock ~165 ~121 ~95 dirt
setblock ~165 ~121 ~96 dirt
setblock ~165 ~121 ~97 dirt
setblock ~165 ~121 ~98 dirt
setblock ~165 ~121 ~99 dirt
setblock ~165 ~121 ~100 dirt
setblock ~165 ~121 ~101 dirt
setblock ~165 ~121 ~102 dirt
setblock ~165 ~121 ~103 dirt
setblock ~165 ~121 ~104 dirt
setblock ~165 ~121 ~105 dirt
setblock ~165 ~121 ~106 dirt
setblock ~165 ~121 ~107 dirt
setblock ~165 ~121 ~108 dirt
setblock ~165 ~121 ~109 dirt
setblock ~165 ~122 ~78 dirt
setblock ~165 ~122 ~79 dirt
setblock ~165 ~122 ~80 dirt
setblock ~165 ~122 ~81 dirt
setblock ~165 ~122 ~82 dirt
setblock ~165 ~122 ~83 dirt
setblock ~165 ~122 ~84 dirt
setblock ~165 ~122 ~85 dirt
setblock ~165 ~122 ~86 dirt
setblock ~165 ~122 ~87 dirt
setblock ~165 ~122 ~88 dirt
setblock ~165 ~122 ~89 dirt
setblock ~165 ~122 ~90 dirt
setblock ~165 ~122 ~91 dirt
setblock ~165 ~122 ~92 dirt
setblock ~165 ~122 ~93 dirt
setblock ~165 ~122 ~94 dirt
setblock ~165 ~122 ~95 dirt
setblock ~165 ~122 ~96 dirt
setblock ~165 ~122 ~97 dirt
setblock ~165 ~122 ~98 dirt
setblock ~165 ~122 ~99 dirt
setblock ~165 ~122 ~100 dirt
setblock ~165 ~122 ~101 dirt
setblock ~165 ~122 ~102 dirt
setblock ~165 ~122 ~103 dirt
setblock ~165 ~122 ~104 dirt
setblock ~165 ~122 ~105 dirt
setblock ~165 ~122 ~106 dirt
setblock ~165 ~122 ~107 dirt
setblock ~165 ~122 ~108 dirt
setblock ~165 ~122 ~109 dirt
setblock ~165 ~123 ~78 dirt
setblock ~165 ~123 ~79 dirt
setblock ~165 ~123 ~80 dirt
setblock ~165 ~123 ~81 dirt
setblock ~165 ~123 ~82 dirt
setblock ~165 ~123 ~83 dirt
setblock ~165 ~123 ~84 dirt
setblock ~165 ~123 ~85 dirt
setblock ~165 ~123 ~86 dirt
setblock ~165 ~123 ~87 dirt
setblock ~165 ~123 ~88 dirt
setblock ~165 ~123 ~89 dirt
setblock ~165 ~123 ~90 dirt
setblock ~165 ~123 ~91 dirt
setblock ~165 ~123 ~92 dirt
setblock ~165 ~123 ~93 dirt
setblock ~165 ~123 ~94 dirt
setblock ~165 ~123 ~95 dirt
setblock ~165 ~123 ~96 dirt
setblock ~165 ~123 ~97 dirt
setblock ~165 ~123 ~98 dirt
setblock ~165 ~123 ~99 dirt
setblock ~165 ~123 ~100 dirt
setblock ~165 ~123 ~101 dirt
setblock ~165 ~123 ~102 dirt
setblock ~165 ~123 ~103 dirt
setblock ~165 ~123 ~104 dirt
setblock ~165 ~123 ~105 dirt
setblock ~165 ~123 ~106 grass_block
setblock ~165 ~123 ~107 grass_block
setblock ~165 ~123 ~108 grass_block
setblock ~165 ~123 ~109 grass_block
setblock ~165 ~124 ~78 dirt
setblock ~165 ~124 ~79 dirt
setblock ~165 ~124 ~80 dirt
setblock ~165 ~124 ~81 dirt
setblock ~165 ~124 ~82 dirt
setblock ~165 ~124 ~83 dirt
setblock ~165 ~124 ~84 dirt
setblock ~165 ~124 ~85 dirt
setblock ~165 ~124 ~86 dirt
setblock ~165 ~124 ~87 dirt
setblock ~165 ~124 ~88 dirt
setblock ~165 ~124 ~89 dirt
setblock ~165 ~124 ~90 dirt
setblock ~165 ~124 ~91 dirt
setblock ~165 ~124 ~92 dirt
setblock ~165 ~124 ~93 dirt
setblock ~165 ~124 ~94 dirt
setblock ~165 ~124 ~95 dirt
setblock ~165 ~124 ~96 dirt
setblock ~165 ~124 ~97 dirt
setblock ~165 ~124 ~98 dirt
setblock ~165 ~124 ~99 dirt
setblock ~165 ~124 ~100 grass_block
setblock ~165 ~124 ~101 grass_block
setblock ~165 ~124 ~102 grass_block
setblock ~165 ~124 ~103 grass_block
setblock ~165 ~124 ~104 grass_block
setblock ~165 ~124 ~105 grass_block
setblock ~165 ~125 ~78 dirt
setblock ~165 ~125 ~79 dirt
setblock ~165 ~125 ~80 dirt
setblock ~165 ~125 ~81 dirt
setblock ~165 ~125 ~82 dirt
setblock ~165 ~125 ~83 dirt
setblock ~165 ~125 ~84 dirt
setblock ~165 ~125 ~85 dirt
setblock ~165 ~125 ~86 dirt
setblock ~165 ~125 ~87 dirt
setblock ~165 ~125 ~88 dirt
setblock ~165 ~125 ~89 dirt
setblock ~165 ~125 ~90 dirt
setblock ~165 ~125 ~91 grass_block
setblock ~165 ~125 ~92 grass_block
setblock ~165 ~125 ~93 grass_block
setblock ~165 ~125 ~94 grass_block
setblock ~165 ~125 ~95 grass_block
setblock ~165 ~125 ~96 grass_block
setblock ~165 ~125 ~97 grass_block
setblock ~165 ~125 ~98 grass_block
setblock ~165 ~125 ~99 grass_block
setblock ~165 ~125 ~103 short_grass
setblock ~165 ~126 ~78 grass_block
setblock ~165 ~126 ~79 grass_block
setblock ~165 ~126 ~80 grass_block
setblock ~165 ~126 ~81 grass_block
setblock ~165 ~126 ~82 grass_block
setblock ~165 ~126 ~83 grass_block
setblock ~165 ~126 ~84 grass_block
setblock ~165 ~126 ~85 grass_block
setblock ~165 ~126 ~86 grass_block
setblock ~165 ~126 ~87 grass_block
setblock ~165 ~126 ~88 grass_block
setblock ~165 ~126 ~89 grass_block
setblock ~165 ~126 ~90 grass_block
setblock ~165 ~126 ~92 short_grass
setblock ~165 ~126 ~93 short_grass
setblock ~165 ~126 ~94 short_grass
setblock ~165 ~126 ~99 short_grass
setblock ~165 ~127 ~85 poppy
setblock ~165 ~127 ~87 short_grass
setblock ~166 ~108 ~96 dirt
setblock ~166 ~109 ~93 dirt
setblock ~166 ~109 ~95 dirt
setblock ~166 ~109 ~96 dirt
setblock ~166 ~110 ~92 dirt
setblock ~166 ~110 ~93 dirt
setblock ~166 ~110 ~94 dirt
setblock ~166 ~110 ~95 dirt
setblock ~166 ~110 ~96 dirt
setblock ~166 ~111 ~92 dirt
setblock ~166 ~111 ~93 dirt
setblock ~166 ~111 ~94 dirt
setblock ~166 ~111 ~95 dirt
setblock ~166 ~111 ~96 dirt
setblock ~166 ~111 ~99 dirt
setblock ~166 ~112 ~91 dirt
setblock ~166 ~112 ~92 dirt
setblock ~166 ~112 ~93 dirt
setblock ~166 ~112 ~94 dirt
setblock ~166 ~112 ~95 dirt
setblock ~166 ~112 ~96 dirt
setblock ~166 ~112 ~97 dirt
setblock ~166 ~112 ~98 dirt
setblock ~166 ~112 ~99 dirt
setblock ~166 ~112 ~100 dirt
setblock ~166 ~112 ~102 dirt
setblock ~166 ~113 ~90 dirt
setblock ~166 ~113 ~91 dirt
setblock ~166 ~113 ~92 dirt
setblock ~166 ~113 ~93 dirt
setblock ~166 ~113 ~94 dirt
setblock ~166 ~113 ~95 dirt
setblock ~166 ~113 ~96 dirt
setblock ~166 ~113 ~97 dirt
setblock ~166 ~113 ~98 dirt
setblock ~166 ~113 ~99 dirt
setblock ~166 ~113 ~100 dirt
setblock ~166 ~113 ~101 dirt
setblock ~166 ~113 ~102 dirt
setblock ~166 ~113 ~103 dirt
setblock ~166 ~114 ~86 dirt
setblock ~166 ~114 ~87 dirt
setblock ~166 ~114 ~89 dirt
setblock ~166 ~114 ~90 dirt
setblock ~166 ~114 ~91 dirt
setblock ~166 ~114 ~92 dirt
setblock ~166 ~114 ~93 dirt
setblock ~166 ~114 ~94 dirt
setblock ~166 ~114 ~95 dirt
setblock ~166 ~114 ~96 dirt
setblock ~166 ~114 ~97 dirt
setblock ~166 ~114 ~98 dirt
setblock ~166 ~114 ~99 dirt
setblock ~166 ~114 ~100 dirt
setblock ~166 ~114 ~101 dirt
setblock ~166 ~114 ~102 dirt
setblock ~166 ~114 ~103 dirt
setblock ~166 ~114 ~104 dirt
setblock ~166 ~115 ~84 dirt
setblock ~166 ~115 ~86 dirt
setblock ~166 ~115 ~87 dirt
setblock ~166 ~115 ~89 dirt
setblock ~166 ~115 ~90 dirt
setblock ~166 ~115 ~91 dirt
setblock ~166 ~115 ~92 dirt
setblock ~166 ~115 ~93 dirt
setblock ~166 ~115 ~94 dirt
setblock ~166 ~115 ~95 dirt
setblock ~166 ~115 ~96 dirt
setblock ~166 ~115 ~97 dirt
setblock ~166 ~115 ~98 dirt
setblock ~166 ~115 ~99 dirt
setblock ~166 ~115 ~100 dirt
setblock ~166 ~115 ~101 dirt
setblock ~166 ~115 ~102 dirt
setblock ~166 ~115 ~103 dirt
setblock ~166 ~115 ~104 dirt
setblock ~166 ~116 ~84 dirt
setblock ~166 ~116 ~85 dirt
setblock ~166 ~116 ~86 dirt
setblock ~166 ~116 ~87 dirt
setblock ~166 ~116 ~88 dirt
setblock ~166 ~116 ~89 dirt
setblock ~166 ~116 ~90 dirt
setblock ~166 ~116 ~91 dirt
setblock ~166 ~116 ~92 dirt
setblock ~166 ~116 ~93 dirt
setblock ~166 ~116 ~94 dirt
setblock ~166 ~116 ~95 dirt
setblock ~166 ~116 ~96 dirt
setblock ~166 ~116 ~97 dirt
setblock ~166 ~116 ~98 dirt
setblock ~166 ~116 ~99 dirt
setblock ~166 ~116 ~100 dirt
setblock ~166 ~116 ~101 dirt
setblock ~166 ~116 ~102 dirt
setblock ~166 ~116 ~103 dirt
setblock ~166 ~116 ~104 dirt
setblock ~166 ~117 ~83 dirt
setblock ~166 ~117 ~84 dirt
setblock ~166 ~117 ~85 dirt
setblock ~166 ~117 ~86 dirt
setblock ~166 ~117 ~87 dirt
setblock ~166 ~117 ~88 dirt
setblock ~166 ~117 ~89 dirt
setblock ~166 ~117 ~90 dirt
setblock ~166 ~117 ~91 dirt
setblock ~166 ~117 ~92 dirt
setblock ~166 ~117 ~93 dirt
setblock ~166 ~117 ~94 dirt
setblock ~166 ~117 ~95 dirt
setblock ~166 ~117 ~96 dirt
setblock ~166 ~117 ~97 dirt
setblock ~166 ~117 ~98 dirt
setblock ~166 ~117 ~99 dirt
setblock ~166 ~117 ~100 dirt
setblock ~166 ~117 ~101 dirt
setblock ~166 ~117 ~102 dirt
setblock ~166 ~117 ~103 dirt
setblock ~166 ~117 ~104 dirt
setblock ~166 ~117 ~105 dirt
setblock ~166 ~118 ~81 dirt
setblock ~166 ~118 ~82 dirt
setblock ~166 ~118 ~83 dirt
setblock ~166 ~118 ~84 dirt
setblock ~166 ~118 ~85 dirt
setblock ~166 ~118 ~86 dirt
setblock ~166 ~118 ~87 dirt
setblock ~166 ~118 ~88 dirt
setblock ~166 ~118 ~89 dirt
setblock ~166 ~118 ~90 dirt
setblock ~166 ~118 ~91 dirt
setblock ~166 ~118 ~92 dirt
setblock ~166 ~118 ~93 dirt
setblock ~166 ~118 ~94 dirt
setblock ~166 ~118 ~95 dirt
setblock ~166 ~118 ~96 dirt
setblock ~166 ~118 ~97 dirt
setblock ~166 ~118 ~98 dirt
setblock ~166 ~118 ~99 dirt
setblock ~166 ~118 ~100 dirt
setblock ~166 ~118 ~101 dirt
setblock ~166 ~118 ~102 dirt
setblock ~166 ~118 ~103 dirt
setblock ~166 ~118 ~104 dirt
setblock ~166 ~118 ~105 dirt
setblock ~166 ~118 ~106 dirt
setblock ~166 ~119 ~80 dirt
setblock ~166 ~119 ~81 dirt
setblock ~166 ~119 ~82 dirt
setblock ~166 ~119 ~83 dirt
setblock ~166 ~119 ~84 dirt
setblock ~166 ~119 ~85 dirt
setblock ~166 ~119 ~86 dirt
setblock ~166 ~119 ~87 dirt
setblock ~166 ~119 ~88 dirt
setblock ~166 ~119 ~89 dirt
setblock ~166 ~119 ~90 dirt
setblock ~166 ~119 ~91 dirt
setblock ~166 ~119 ~92 dirt
setblock ~166 ~119 ~93 dirt
setblock ~166 ~119 ~94 dirt
setblock ~166 ~119 ~95 dirt
setblock ~166 ~119 ~96 dirt
setblock ~166 ~119 ~97 dirt
setblock ~166 ~119 ~98 dirt
setblock ~166 ~119 ~99 dirt
setblock ~166 ~119 ~100 dirt
setblock ~166 ~119 ~101 dirt
setblock ~166 ~119 ~102 dirt
setblock ~166 ~119 ~103 dirt
setblock ~166 ~119 ~104 dirt
setblock ~166 ~119 ~105 dirt
setblock ~166 ~119 ~106 dirt
setblock ~166 ~120 ~79 dirt
setblock ~166 ~120 ~80 dirt
setblock ~166 ~120 ~81 dirt
setblock ~166 ~120 ~82 dirt
setblock ~166 ~120 ~83 dirt
setblock ~166 ~120 ~84 dirt
setblock ~166 ~120 ~85 dirt
setblock ~166 ~120 ~86 dirt
setblock ~166 ~120 ~87 dirt
setblock ~166 ~120 ~88 dirt
setblock ~166 ~120 ~89 dirt
setblock ~166 ~120 ~90 dirt
setblock ~166 ~120 ~91 dirt
setblock ~166 ~120 ~92 dirt
setblock ~166 ~120 ~93 dirt
setblock ~166 ~120 ~94 dirt
setblock ~166 ~120 ~95 dirt
setblock ~166 ~120 ~96 dirt
setblock ~166 ~120 ~97 dirt
setblock ~166 ~120 ~98 dirt
setblock ~166 ~120 ~99 dirt
setblock ~166 ~120 ~100 dirt
setblock ~166 ~120 ~101 dirt
setblock ~166 ~120 ~102 dirt
setblock ~166 ~120 ~103 dirt
setblock ~166 ~120 ~104 dirt
setblock ~166 ~120 ~105 dirt
setblock ~166 ~120 ~106 dirt
setblock ~166 ~120 ~108 dirt
setblock ~166 ~121 ~79 dirt
setblock ~166 ~121 ~80 dirt
setblock ~166 ~121 ~81 dirt
setblock ~166 ~121 ~82 dirt
setblock ~166 ~121 ~83 dirt
setblock ~166 ~121 ~84 dirt
setblock ~166 ~121 ~85 dirt
setblock ~166 ~121 ~86 dirt
setblock ~166 ~121 ~87 dirt
setblock ~166 ~121 ~88 dirt
setblock ~166 ~121 ~89 dirt
setblock ~166 ~121 ~90 dirt
setblock ~166 ~121 ~91 dirt
setblock ~166 ~121 ~92 dirt
setblock ~166 ~121 ~93 dirt
setblock ~166 ~121 ~94 dirt
setblock ~166 ~121 ~95 dirt
setblock ~166 ~121 ~96 dirt
setblock ~166 ~121 ~97 dirt
setblock ~166 ~121 ~98 dirt
setblock ~166 ~121 ~99 dirt
setblock ~166 ~121 ~100 dirt
setblock ~166 ~121 ~101 dirt
setblock ~166 ~121 ~102 dirt
setblock ~166 ~121 ~103 dirt
setblock ~166 ~121 ~104 dirt
setblock ~166 ~121 ~105 dirt
setblock ~166 ~121 ~106 dirt
setblock ~166 ~121 ~107 dirt
setblock ~166 ~121 ~108 dirt
setblock ~166 ~121 ~109 dirt
setblock ~166 ~122 ~79 dirt
setblock ~166 ~122 ~80 dirt
setblock ~166 ~122 ~81 dirt
setblock ~166 ~122 ~82 dirt
setblock ~166 ~122 ~83 dirt
setblock ~166 ~122 ~84 dirt
setblock ~166 ~122 ~85 dirt
setblock ~166 ~122 ~86 dirt
setblock ~166 ~122 ~87 dirt
setblock ~166 ~122 ~88 dirt
setblock ~166 ~122 ~89 dirt
setblock ~166 ~122 ~90 dirt
setblock ~166 ~122 ~91 dirt
setblock ~166 ~122 ~92 dirt
setblock ~166 ~122 ~93 dirt
setblock ~166 ~122 ~94 dirt
setblock ~166 ~122 ~95 dirt
setblock ~166 ~122 ~96 dirt
setblock ~166 ~122 ~97 dirt
setblock ~166 ~122 ~98 dirt
setblock ~166 ~122 ~99 dirt
setblock ~166 ~122 ~100 dirt
setblock ~166 ~122 ~101 dirt
setblock ~166 ~122 ~102 dirt
setblock ~166 ~122 ~103 dirt
setblock ~166 ~122 ~104 dirt
setblock ~166 ~122 ~105 dirt
setblock ~166 ~122 ~106 dirt
setblock ~166 ~122 ~107 dirt
setblock ~166 ~122 ~108 dirt
setblock ~166 ~122 ~109 dirt
setblock ~166 ~123 ~79 dirt
setblock ~166 ~123 ~80 dirt
setblock ~166 ~123 ~81 dirt
setblock ~166 ~123 ~82 dirt
setblock ~166 ~123 ~83 dirt
setblock ~166 ~123 ~84 dirt
setblock ~166 ~123 ~85 dirt
setblock ~166 ~123 ~86 dirt
setblock ~166 ~123 ~87 dirt
setblock ~166 ~123 ~88 dirt
setblock ~166 ~123 ~89 dirt
setblock ~166 ~123 ~90 dirt
setblock ~166 ~123 ~91 dirt
setblock ~166 ~123 ~92 dirt
setblock ~166 ~123 ~93 dirt
setblock ~166 ~123 ~94 dirt
