setblock ~24 ~134 ~90 oak_leaves[persistent=true]
setblock ~24 ~134 ~91 oak_leaves[persistent=true]
setblock ~24 ~134 ~92 oak_leaves[persistent=true]
setblock ~24 ~134 ~93 oak_leaves[persistent=true]
setblock ~24 ~134 ~94 jungle_leaves[persistent=true]
setblock ~24 ~134 ~95 jungle_leaves[persistent=true]
setblock ~24 ~134 ~96 oak_leaves[persistent=true]
setblock ~24 ~134 ~97 oak_leaves[persistent=true]
setblock ~24 ~134 ~98 oak_wood
setblock ~24 ~134 ~99 oak_leaves[persistent=true]
setblock ~24 ~134 ~101 oak_leaves[persistent=true]
setblock ~24 ~134 ~102 oak_leaves[persistent=true]
setblock ~24 ~134 ~103 oak_wood
setblock ~24 ~134 ~104 oak_leaves[persistent=true]
setblock ~24 ~134 ~105 oak_leaves[persistent=true]
setblock ~24 ~134 ~106 oak_wood
setblock ~24 ~134 ~107 oak_leaves[persistent=true]
setblock ~24 ~134 ~108 oak_leaves[persistent=true]
setblock ~24 ~134 ~109 oak_wood
setblock ~24 ~134 ~110 oak_wood
setblock ~24 ~134 ~111 oak_wood
setblock ~24 ~134 ~112 oak_wood
setblock ~24 ~134 ~113 oak_wood
setblock ~24 ~134 ~114 oak_wood
setblock ~24 ~134 ~115 oak_wood
setblock ~24 ~134 ~116 oak_wood
setblock ~24 ~134 ~117 oak_wood
setblock ~24 ~134 ~118 oak_wood
setblock ~24 ~134 ~119 oak_leaves[persistent=true]
setblock ~24 ~134 ~120 oak_wood
setblock ~24 ~134 ~121 oak_leaves[persistent=true]
setblock ~24 ~134 ~122 jungle_leaves[persistent=true]
setblock ~24 ~134 ~123 oak_leaves[persistent=true]
setblock ~24 ~134 ~124 oak_leaves[persistent=true]
setblock ~24 ~134 ~125 oak_leaves[persistent=true]
setblock ~24 ~134 ~126 oak_leaves[persistent=true]
setblock ~24 ~134 ~127 jungle_leaves[persistent=true]
setblock ~24 ~134 ~129 oak_leaves[persistent=true]
setblock ~24 ~134 ~130 oak_leaves[persistent=true]
setblock ~24 ~134 ~131 oak_leaves[persistent=true]
setblock ~24 ~135 ~88 oak_leaves[persistent=true]
setblock ~24 ~135 ~89 oak_leaves[persistent=true]
setblock ~24 ~135 ~90 oak_wood
setblock ~24 ~135 ~91 oak_leaves[persistent=true]
setblock ~24 ~135 ~92 oak_leaves[persistent=true]
setblock ~24 ~135 ~93 jungle_leaves[persistent=true]
setblock ~24 ~135 ~94 oak_leaves[persistent=true]
setblock ~24 ~135 ~95 oak_leaves[persistent=true]
setblock ~24 ~135 ~96 oak_wood
setblock ~24 ~135 ~97 oak_leaves[persistent=true]
setblock ~24 ~135 ~98 jungle_leaves[persistent=true]
setblock ~24 ~135 ~99 oak_leaves[persistent=true]
setblock ~24 ~135 ~100 oak_wood
setblock ~24 ~135 ~101 oak_wood
setblock ~24 ~135 ~102 oak_leaves[persistent=true]
setblock ~24 ~135 ~104 oak_wood
setblock ~24 ~135 ~105 oak_leaves[persistent=true]
setblock ~24 ~135 ~106 oak_leaves[persistent=true]
setblock ~24 ~135 ~107 oak_leaves[persistent=true]
setblock ~24 ~135 ~108 oak_leaves[persistent=true]
setblock ~24 ~135 ~109 oak_wood
setblock ~24 ~135 ~110 oak_wood
setblock ~24 ~135 ~111 oak_leaves[persistent=true]
setblock ~24 ~135 ~112 oak_wood
setblock ~24 ~135 ~113 oak_leaves[persistent=true]
setblock ~24 ~135 ~114 oak_leaves[persistent=true]
setblock ~24 ~135 ~115 oak_leaves[persistent=true]
setblock ~24 ~135 ~116 jungle_leaves[persistent=true]
setblock ~24 ~135 ~117 oak_wood
setblock ~24 ~135 ~118 oak_wood
setblock ~24 ~135 ~119 oak_wood
setblock ~24 ~135 ~120 oak_leaves[persistent=true]
setblock ~24 ~135 ~121 oak_leaves[persistent=true]
setblock ~24 ~135 ~122 oak_leaves[persistent=true]
setblock ~24 ~135 ~124 oak_leaves[persistent=true]
setblock ~24 ~135 ~125 oak_leaves[persistent=true]
setblock ~24 ~135 ~126 oak_wood
setblock ~24 ~135 ~127 oak_leaves[persistent=true]
setblock ~24 ~135 ~128 oak_leaves[persistent=true]
setblock ~24 ~135 ~129 oak_leaves[persistent=true]
setblock ~24 ~135 ~130 oak_leaves[persistent=true]
setblock ~24 ~135 ~131 oak_leaves[persistent=true]
setblock ~24 ~136 ~88 oak_leaves[persistent=true]
setblock ~24 ~136 ~89 oak_leaves[persistent=true]
setblock ~24 ~136 ~90 jungle_leaves[persistent=true]
setblock ~24 ~136 ~91 oak_leaves[persistent=true]
setblock ~24 ~136 ~92 oak_leaves[persistent=true]
setblock ~24 ~136 ~93 jungle_leaves[persistent=true]
setblock ~24 ~136 ~94 oak_wood
setblock ~24 ~136 ~95 oak_leaves[persistent=true]
setblock ~24 ~136 ~96 oak_leaves[persistent=true]
setblock ~24 ~136 ~97 oak_wood
setblock ~24 ~136 ~98 oak_leaves[persistent=true]
setblock ~24 ~136 ~99 oak_leaves[persistent=true]
setblock ~24 ~136 ~100 oak_leaves[persistent=true]
setblock ~24 ~136 ~103 oak_leaves[persistent=true]
setblock ~24 ~136 ~104 oak_leaves[persistent=true]
setblock ~24 ~136 ~105 oak_leaves[persistent=true]
setblock ~24 ~136 ~106 jungle_leaves[persistent=true]
setblock ~24 ~136 ~107 oak_leaves[persistent=true]
setblock ~24 ~136 ~108 oak_wood
setblock ~24 ~136 ~110 jungle_leaves[persistent=true]
setblock ~24 ~136 ~111 oak_leaves[persistent=true]
setblock ~24 ~136 ~112 jungle_leaves[persistent=true]
setblock ~24 ~136 ~113 jungle_leaves[persistent=true]
setblock ~24 ~136 ~114 oak_wood
setblock ~24 ~136 ~115 oak_leaves[persistent=true]
setblock ~24 ~136 ~116 oak_leaves[persistent=true]
setblock ~24 ~136 ~117 oak_leaves[persistent=true]
setblock ~24 ~136 ~118 oak_wood
setblock ~24 ~136 ~119 oak_leaves[persistent=true]
setblock ~24 ~136 ~120 oak_wood
setblock ~24 ~136 ~121 oak_leaves[persistent=true]
setblock ~24 ~136 ~122 oak_leaves[persistent=true]
setblock ~24 ~136 ~123 oak_leaves[persistent=true]
setblock ~24 ~136 ~124 oak_leaves[persistent=true]
setblock ~24 ~136 ~125 oak_leaves[persistent=true]
setblock ~24 ~136 ~126 oak_wood
setblock ~24 ~136 ~127 oak_leaves[persistent=true]
setblock ~24 ~136 ~128 jungle_leaves[persistent=true]
setblock ~24 ~137 ~89 oak_leaves[persistent=true]
setblock ~24 ~137 ~90 oak_leaves[persistent=true]
setblock ~24 ~137 ~91 jungle_leaves[persistent=true]
setblock ~24 ~137 ~92 oak_leaves[persistent=true]
setblock ~24 ~137 ~93 oak_leaves[persistent=true]
setblock ~24 ~137 ~94 oak_leaves[persistent=true]
setblock ~24 ~137 ~95 jungle_leaves[persistent=true]
setblock ~24 ~137 ~96 oak_wood
setblock ~24 ~137 ~97 oak_leaves[persistent=true]
setblock ~24 ~137 ~98 oak_leaves[persistent=true]
setblock ~24 ~137 ~100 oak_leaves[persistent=true]
setblock ~24 ~137 ~101 oak_leaves[persistent=true]
setblock ~24 ~137 ~102 jungle_leaves[persistent=true]
setblock ~24 ~137 ~103 jungle_leaves[persistent=true]
setblock ~24 ~137 ~104 jungle_leaves[persistent=true]
setblock ~24 ~137 ~105 oak_leaves[persistent=true]
setblock ~24 ~137 ~106 jungle_leaves[persistent=true]
setblock ~24 ~137 ~107 oak_leaves[persistent=true]
setblock ~24 ~137 ~108 oak_leaves[persistent=true]
setblock ~24 ~137 ~109 jungle_leaves[persistent=true]
setblock ~24 ~137 ~110 oak_wood
setblock ~24 ~137 ~111 oak_wood
setblock ~24 ~137 ~112 oak_wood
setblock ~24 ~137 ~113 jungle_leaves[persistent=true]
setblock ~24 ~137 ~114 jungle_leaves[persistent=true]
setblock ~24 ~137 ~115 oak_leaves[persistent=true]
setblock ~24 ~137 ~116 oak_leaves[persistent=true]
setblock ~24 ~137 ~117 oak_log
setblock ~24 ~137 ~118 oak_log
setblock ~24 ~137 ~119 oak_log
setblock ~24 ~137 ~120 oak_wood
setblock ~24 ~137 ~121 oak_wood
setblock ~24 ~137 ~122 jungle_leaves[persistent=true]
setblock ~24 ~137 ~123 oak_leaves[persistent=true]
setblock ~24 ~137 ~124 oak_leaves[persistent=true]
setblock ~24 ~137 ~125 oak_leaves[persistent=true]
setblock ~24 ~138 ~91 oak_leaves[persistent=true]
setblock ~24 ~138 ~92 oak_wood
setblock ~24 ~138 ~93 oak_leaves[persistent=true]
setblock ~24 ~138 ~94 jungle_leaves[persistent=true]
setblock ~24 ~138 ~95 jungle_leaves[persistent=true]
setblock ~24 ~138 ~96 oak_leaves[persistent=true]
setblock ~24 ~138 ~97 oak_leaves[persistent=true]
setblock ~24 ~138 ~98 oak_leaves[persistent=true]
setblock ~24 ~138 ~99 jungle_leaves[persistent=true]
setblock ~24 ~138 ~101 oak_leaves[persistent=true]
setblock ~24 ~138 ~102 oak_leaves[persistent=true]
setblock ~24 ~138 ~103 oak_leaves[persistent=true]
setblock ~24 ~138 ~104 jungle_leaves[persistent=true]
setblock ~24 ~138 ~105 oak_leaves[persistent=true]
setblock ~24 ~138 ~106 oak_leaves[persistent=true]
setblock ~24 ~138 ~107 jungle_leaves[persistent=true]
setblock ~24 ~138 ~108 oak_leaves[persistent=true]
setblock ~24 ~138 ~110 jungle_leaves[persistent=true]
setblock ~24 ~138 ~111 oak_wood
setblock ~24 ~138 ~112 oak_wood
setblock ~24 ~138 ~113 jungle_leaves[persistent=true]
setblock ~24 ~138 ~114 oak_leaves[persistent=true]
setblock ~24 ~138 ~115 oak_leaves[persistent=true]
setblock ~24 ~138 ~117 jungle_leaves[persistent=true]
setblock ~24 ~138 ~118 oak_leaves[persistent=true]
setblock ~24 ~138 ~119 oak_log
setblock ~24 ~138 ~120 jungle_leaves[persistent=true]
setblock ~24 ~138 ~121 oak_leaves[persistent=true]
setblock ~24 ~138 ~122 oak_leaves[persistent=true]
setblock ~24 ~138 ~123 oak_leaves[persistent=true]
setblock ~24 ~138 ~124 jungle_leaves[persistent=true]
setblock ~24 ~138 ~125 oak_leaves[persistent=true]
setblock ~24 ~139 ~91 oak_leaves[persistent=true]
setblock ~24 ~139 ~92 jungle_leaves[persistent=true]
setblock ~24 ~139 ~93 oak_leaves[persistent=true]
setblock ~24 ~139 ~94 oak_leaves[persistent=true]
setblock ~24 ~139 ~95 oak_leaves[persistent=true]
setblock ~24 ~139 ~96 oak_leaves[persistent=true]
setblock ~24 ~139 ~98 oak_leaves[persistent=true]
setblock ~24 ~139 ~99 oak_leaves[persistent=true]
setblock ~24 ~139 ~100 jungle_leaves[persistent=true]
setblock ~24 ~139 ~101 oak_leaves[persistent=true]
setblock ~24 ~139 ~102 oak_leaves[persistent=true]
setblock ~24 ~139 ~103 jungle_leaves[persistent=true]
setblock ~24 ~139 ~107 oak_leaves[persistent=true]
setblock ~24 ~139 ~108 jungle_leaves[persistent=true]
setblock ~24 ~139 ~109 oak_leaves[persistent=true]
setblock ~24 ~139 ~110 oak_leaves[persistent=true]
setblock ~24 ~139 ~111 oak_leaves[persistent=true]
setblock ~24 ~139 ~112 jungle_leaves[persistent=true]
setblock ~24 ~139 ~113 oak_leaves[persistent=true]
setblock ~24 ~139 ~114 jungle_leaves[persistent=true]
setblock ~24 ~139 ~115 oak_leaves[persistent=true]
setblock ~24 ~139 ~116 oak_leaves[persistent=true]
setblock ~24 ~139 ~117 oak_leaves[persistent=true]
setblock ~24 ~139 ~118 oak_leaves[persistent=true]
setblock ~24 ~139 ~120 oak_leaves[persistent=true]
setblock ~24 ~139 ~121 oak_leaves[persistent=true]
setblock ~24 ~139 ~122 jungle_leaves[persistent=true]
setblock ~24 ~140 ~98 oak_leaves[persistent=true]
setblock ~24 ~140 ~99 oak_leaves[persistent=true]
setblock ~24 ~140 ~109 oak_leaves[persistent=true]
setblock ~24 ~140 ~111 oak_leaves[persistent=true]
setblock ~24 ~140 ~112 oak_leaves[persistent=true]
setblock ~24 ~140 ~113 oak_leaves[persistent=true]
setblock ~24 ~140 ~114 oak_leaves[persistent=true]
setblock ~24 ~140 ~115 jungle_leaves[persistent=true]
setblock ~24 ~140 ~116 oak_leaves[persistent=true]
setblock ~24 ~140 ~117 oak_leaves[persistent=true]
setblock ~24 ~140 ~118 oak_leaves[persistent=true]
setblock ~24 ~140 ~119 oak_leaves[persistent=true]
setblock ~25 ~121 ~117 dirt
setblock ~25 ~122 ~117 dirt
setblock ~25 ~123 ~117 dirt
setblock ~25 ~124 ~117 dirt
setblock ~25 ~125 ~113 oak_leaves[persistent=true]
setblock ~25 ~125 ~114 oak_leaves[persistent=true]
setblock ~25 ~125 ~116 oak_leaves[persistent=true]
setblock ~25 ~125 ~117 jungle_leaves[persistent=true]
setblock ~25 ~126 ~109 oak_leaves[persistent=true]
setblock ~25 ~126 ~110 oak_leaves[persistent=true]
setblock ~25 ~126 ~113 oak_leaves[persistent=true]
setblock ~25 ~126 ~115 jungle_leaves[persistent=true]
setblock ~25 ~126 ~116 jungle_leaves[persistent=true]
setblock ~25 ~126 ~117 oak_log
setblock ~25 ~126 ~118 jungle_leaves[persistent=true]
setblock ~25 ~126 ~119 oak_leaves[persistent=true]
setblock ~25 ~126 ~121 oak_leaves[persistent=true]
setblock ~25 ~126 ~122 oak_leaves[persistent=true]
setblock ~25 ~126 ~124 oak_leaves[persistent=true]
setblock ~25 ~126 ~132 jungle_leaves[persistent=true]
setblock ~25 ~126 ~133 oak_leaves[persistent=true]
setblock ~25 ~126 ~134 oak_leaves[persistent=true]
setblock ~25 ~126 ~135 oak_leaves[persistent=true]
setblock ~25 ~127 ~96 jungle_leaves[persistent=true]
setblock ~25 ~127 ~97 jungle_leaves[persistent=true]
setblock ~25 ~127 ~98 oak_leaves[persistent=true]
setblock ~25 ~127 ~99 jungle_leaves[persistent=true]
setblock ~25 ~127 ~100 oak_leaves[persistent=true]
setblock ~25 ~127 ~101 jungle_leaves[persistent=true]
setblock ~25 ~127 ~103 oak_leaves[persistent=true]
setblock ~25 ~127 ~104 oak_leaves[persistent=true]
setblock ~25 ~127 ~105 oak_leaves[persistent=true]
setblock ~25 ~127 ~106 jungle_leaves[persistent=true]
setblock ~25 ~127 ~107 oak_leaves[persistent=true]
setblock ~25 ~127 ~108 oak_leaves[persistent=true]
setblock ~25 ~127 ~109 jungle_leaves[persistent=true]
setblock ~25 ~127 ~110 oak_leaves[persistent=true]
setblock ~25 ~127 ~111 jungle_leaves[persistent=true]
setblock ~25 ~127 ~112 oak_leaves[persistent=true]
setblock ~25 ~127 ~113 oak_leaves[persistent=true]
setblock ~25 ~127 ~114 oak_leaves[persistent=true]
setblock ~25 ~127 ~115 oak_leaves[persistent=true]
setblock ~25 ~127 ~117 oak_log
setblock ~25 ~127 ~118 oak_leaves[persistent=true]
setblock ~25 ~127 ~119 oak_leaves[persistent=true]
setblock ~25 ~127 ~120 oak_leaves[persistent=true]
setblock ~25 ~127 ~123 jungle_leaves[persistent=true]
setblock ~25 ~127 ~124 oak_leaves[persistent=true]
setblock ~25 ~127 ~130 oak_leaves[persistent=true]
setblock ~25 ~127 ~131 oak_leaves[persistent=true]
setblock ~25 ~127 ~132 oak_leaves[persistent=true]
setblock ~25 ~127 ~133 oak_leaves[persistent=true]
setblock ~25 ~127 ~134 oak_leaves[persistent=true]
setblock ~25 ~127 ~135 oak_leaves[persistent=true]
setblock ~25 ~128 ~83 oak_leaves[persistent=true]
setblock ~25 ~128 ~84 oak_leaves[persistent=true]
setblock ~25 ~128 ~85 oak_leaves[persistent=true]
setblock ~25 ~128 ~86 oak_leaves[persistent=true]
setblock ~25 ~128 ~96 oak_leaves[persistent=true]
setblock ~25 ~128 ~97 oak_leaves[persistent=true]
setblock ~25 ~128 ~101 oak_leaves[persistent=true]
setblock ~25 ~128 ~102 jungle_leaves[persistent=true]
setblock ~25 ~128 ~103 jungle_leaves[persistent=true]
setblock ~25 ~128 ~105 jungle_leaves[persistent=true]
setblock ~25 ~128 ~106 oak_leaves[persistent=true]
setblock ~25 ~128 ~107 jungle_leaves[persistent=true]
setblock ~25 ~128 ~108 jungle_leaves[persistent=true]
setblock ~25 ~128 ~109 oak_leaves[persistent=true]
setblock ~25 ~128 ~110 oak_leaves[persistent=true]
setblock ~25 ~128 ~111 oak_leaves[persistent=true]
setblock ~25 ~128 ~112 jungle_leaves[persistent=true]
setblock ~25 ~128 ~113 jungle_leaves[persistent=true]
setblock ~25 ~128 ~114 oak_leaves[persistent=true]
setblock ~25 ~128 ~116 oak_leaves[persistent=true]
setblock ~25 ~128 ~117 oak_log
setblock ~25 ~128 ~118 oak_leaves[persistent=true]
setblock ~25 ~128 ~119 oak_leaves[persistent=true]
setblock ~25 ~128 ~121 oak_leaves[persistent=true]
setblock ~25 ~128 ~122 jungle_leaves[persistent=true]
setblock ~25 ~128 ~123 oak_leaves[persistent=true]
setblock ~25 ~128 ~124 oak_leaves[persistent=true]
setblock ~25 ~128 ~125 jungle_leaves[persistent=true]
setblock ~25 ~128 ~126 oak_leaves[persistent=true]
setblock ~25 ~128 ~130 oak_leaves[persistent=true]
setblock ~25 ~128 ~131 oak_leaves[persistent=true]
setblock ~25 ~128 ~132 oak_leaves[persistent=true]
setblock ~25 ~128 ~133 jungle_leaves[persistent=true]
setblock ~25 ~128 ~134 jungle_leaves[persistent=true]
setblock ~25 ~128 ~135 oak_leaves[persistent=true]
setblock ~25 ~129 ~83 oak_leaves[persistent=true]
setblock ~25 ~129 ~84 oak_leaves[persistent=true]
setblock ~25 ~129 ~85 oak_leaves[persistent=true]
setblock ~25 ~129 ~86 oak_leaves[persistent=true]
setblock ~25 ~129 ~87 oak_leaves[persistent=true]
setblock ~25 ~129 ~96 oak_leaves[persistent=true]
setblock ~25 ~129 ~97 oak_leaves[persistent=true]
setblock ~25 ~129 ~98 jungle_leaves[persistent=true]
setblock ~25 ~129 ~99 oak_leaves[persistent=true]
setblock ~25 ~129 ~100 oak_leaves[persistent=true]
setblock ~25 ~129 ~101 oak_leaves[persistent=true]
setblock ~25 ~129 ~102 oak_leaves[persistent=true]
setblock ~25 ~129 ~103 oak_leaves[persistent=true]
setblock ~25 ~129 ~104 oak_leaves[persistent=true]
setblock ~25 ~129 ~105 oak_leaves[persistent=true]
setblock ~25 ~129 ~106 jungle_leaves[persistent=true]
setblock ~25 ~129 ~107 oak_leaves[persistent=true]
setblock ~25 ~129 ~108 oak_leaves[persistent=true]
setblock ~25 ~129 ~109 oak_leaves[persistent=true]
setblock ~25 ~129 ~110 oak_leaves[persistent=true]
setblock ~25 ~129 ~111 oak_wood
setblock ~25 ~129 ~112 oak_leaves[persistent=true]
setblock ~25 ~129 ~113 oak_leaves[persistent=true]
setblock ~25 ~129 ~114 oak_leaves[persistent=true]
setblock ~25 ~129 ~115 jungle_leaves[persistent=true]
setblock ~25 ~129 ~116 oak_leaves[persistent=true]
setblock ~25 ~129 ~117 oak_leaves[persistent=true]
setblock ~25 ~129 ~118 jungle_leaves[persistent=true]
setblock ~25 ~129 ~119 oak_leaves[persistent=true]
setblock ~25 ~129 ~120 oak_leaves[persistent=true]
setblock ~25 ~129 ~121 oak_leaves[persistent=true]
setblock ~25 ~129 ~122 oak_leaves[persistent=true]
setblock ~25 ~129 ~124 jungle_leaves[persistent=true]
setblock ~25 ~129 ~127 oak_leaves[persistent=true]
setblock ~25 ~129 ~128 oak_leaves[persistent=true]
setblock ~25 ~129 ~129 oak_leaves[persistent=true]
setblock ~25 ~129 ~130 jungle_leaves[persistent=true]
setblock ~25 ~129 ~131 oak_leaves[persistent=true]
setblock ~25 ~129 ~132 oak_leaves[persistent=true]
setblock ~25 ~129 ~133 oak_leaves[persistent=true]
setblock ~25 ~129 ~134 oak_leaves[persistent=true]
setblock ~25 ~129 ~135 oak_leaves[persistent=true]
setblock ~25 ~130 ~83 oak_leaves[persistent=true]
setblock ~25 ~130 ~84 oak_leaves[persistent=true]
setblock ~25 ~130 ~85 oak_leaves[persistent=true]
setblock ~25 ~130 ~86 jungle_leaves[persistent=true]
setblock ~25 ~130 ~87 oak_leaves[persistent=true]
setblock ~25 ~130 ~92 oak_leaves[persistent=true]
setblock ~25 ~130 ~93 oak_leaves[persistent=true]
setblock ~25 ~130 ~94 oak_leaves[persistent=true]
setblock ~25 ~130 ~95 oak_leaves[persistent=true]
setblock ~25 ~130 ~97 oak_leaves[persistent=true]
setblock ~25 ~130 ~98 oak_leaves[persistent=true]
setblock ~25 ~130 ~99 oak_leaves[persistent=true]
setblock ~25 ~130 ~101 oak_leaves[persistent=true]
setblock ~25 ~130 ~102 oak_wood
setblock ~25 ~130 ~103 oak_wood
setblock ~25 ~130 ~104 oak_leaves[persistent=true]
setblock ~25 ~130 ~105 oak_leaves[persistent=true]
setblock ~25 ~130 ~106 oak_leaves[persistent=true]
setblock ~25 ~130 ~107 oak_wood
setblock ~25 ~130 ~108 oak_wood
setblock ~25 ~130 ~109 oak_leaves[persistent=true]
setblock ~25 ~130 ~110 oak_wood
setblock ~25 ~130 ~111 oak_wood
setblock ~25 ~130 ~112 oak_leaves[persistent=true]
setblock ~25 ~130 ~113 oak_wood
setblock ~25 ~130 ~115 oak_leaves[persistent=true]
setblock ~25 ~130 ~116 oak_log
setblock ~25 ~130 ~117 oak_log
setblock ~25 ~130 ~119 oak_wood
setblock ~25 ~130 ~120 oak_leaves[persistent=true]
setblock ~25 ~130 ~121 oak_leaves[persistent=true]
setblock ~25 ~130 ~123 oak_leaves[persistent=true]
setblock ~25 ~130 ~124 oak_leaves[persistent=true]
setblock ~25 ~130 ~125 oak_leaves[persistent=true]
setblock ~25 ~130 ~126 oak_leaves[persistent=true]
setblock ~25 ~130 ~127 jungle_leaves[persistent=true]
setblock ~25 ~130 ~128 oak_leaves[persistent=true]
setblock ~25 ~130 ~130 oak_leaves[persistent=true]
setblock ~25 ~130 ~131 oak_leaves[persistent=true]
setblock ~25 ~130 ~132 jungle_leaves[persistent=true]
setblock ~25 ~130 ~133 oak_leaves[persistent=true]
setblock ~25 ~130 ~134 oak_leaves[persistent=true]
setblock ~25 ~130 ~135 jungle_leaves[persistent=true]
setblock ~25 ~131 ~72 oak_leaves[persistent=true]
setblock ~25 ~131 ~73 jungle_leaves[persistent=true]
setblock ~25 ~131 ~74 oak_leaves[persistent=true]
setblock ~25 ~131 ~83 oak_leaves[persistent=true]
setblock ~25 ~131 ~85 oak_leaves[persistent=true]
setblock ~25 ~131 ~86 oak_leaves[persistent=true]
setblock ~25 ~131 ~87 oak_leaves[persistent=true]
setblock ~25 ~131 ~91 oak_leaves[persistent=true]
setblock ~25 ~131 ~92 oak_leaves[persistent=true]
setblock ~25 ~131 ~93 jungle_leaves[persistent=true]
setblock ~25 ~131 ~94 oak_leaves[persistent=true]
setblock ~25 ~131 ~95 oak_leaves[persistent=true]
setblock ~25 ~131 ~96 oak_leaves[persistent=true]
setblock ~25 ~131 ~97 oak_leaves[persistent=true]
setblock ~25 ~131 ~98 oak_leaves[persistent=true]
setblock ~25 ~131 ~99 oak_leaves[persistent=true]
setblock ~25 ~131 ~100 oak_leaves[persistent=true]
setblock ~25 ~131 ~102 oak_leaves[persistent=true]
setblock ~25 ~131 ~103 oak_leaves[persistent=true]
setblock ~25 ~131 ~104 oak_leaves[persistent=true]
setblock ~25 ~131 ~105 oak_wood
setblock ~25 ~131 ~106 oak_leaves[persistent=true]
setblock ~25 ~131 ~108 oak_wood
setblock ~25 ~131 ~109 oak_leaves[persistent=true]
setblock ~25 ~131 ~110 oak_wood
setblock ~25 ~131 ~111 oak_leaves[persistent=true]
setblock ~25 ~131 ~112 oak_leaves[persistent=true]
setblock ~25 ~131 ~113 jungle_leaves[persistent=true]
setblock ~25 ~131 ~114 oak_wood
setblock ~25 ~131 ~115 oak_wood
setblock ~25 ~131 ~116 oak_leaves[persistent=true]
setblock ~25 ~131 ~117 oak_log
setblock ~25 ~131 ~118 oak_wood
setblock ~25 ~131 ~119 oak_leaves[persistent=true]
setblock ~25 ~131 ~120 oak_wood
setblock ~25 ~131 ~121 oak_wood
setblock ~25 ~131 ~122 oak_leaves[persistent=true]
setblock ~25 ~131 ~123 jungle_leaves[persistent=true]
setblock ~25 ~131 ~124 oak_leaves[persistent=true]
setblock ~25 ~131 ~125 jungle_leaves[persistent=true]
setblock ~25 ~131 ~126 oak_leaves[persistent=true]
setblock ~25 ~131 ~127 oak_wood
setblock ~25 ~131 ~128 oak_leaves[persistent=true]
setblock ~25 ~131 ~129 oak_leaves[persistent=true]
setblock ~25 ~131 ~130 oak_leaves[persistent=true]
setblock ~25 ~132 ~72 oak_leaves[persistent=true]
setblock ~25 ~132 ~74 oak_leaves[persistent=true]
setblock ~25 ~132 ~75 oak_leaves[persistent=true]
setblock ~25 ~132 ~84 oak_leaves[persistent=true]
setblock ~25 ~132 ~86 jungle_leaves[persistent=true]
setblock ~25 ~132 ~87 oak_leaves[persistent=true]
setblock ~25 ~132 ~91 oak_leaves[persistent=true]
setblock ~25 ~132 ~92 oak_leaves[persistent=true]
setblock ~25 ~132 ~93 oak_leaves[persistent=true]
setblock ~25 ~132 ~94 oak_leaves[persistent=true]
setblock ~25 ~132 ~95 oak_leaves[persistent=true]
setblock ~25 ~132 ~96 oak_leaves[persistent=true]
setblock ~25 ~132 ~97 oak_wood
setblock ~25 ~132 ~98 oak_wood
setblock ~25 ~132 ~99 oak_leaves[persistent=true]
setblock ~25 ~132 ~100 oak_wood
setblock ~25 ~132 ~101 oak_wood
setblock ~25 ~132 ~102 oak_wood
setblock ~25 ~132 ~103 oak_leaves[persistent=true]
setblock ~25 ~132 ~104 oak_leaves[persistent=true]
setblock ~25 ~132 ~105 oak_leaves[persistent=true]
setblock ~25 ~132 ~106 oak_wood
setblock ~25 ~132 ~107 oak_leaves[persistent=true]
setblock ~25 ~132 ~109 jungle_leaves[persistent=true]
setblock ~25 ~132 ~110 jungle_leaves[persistent=true]
setblock ~25 ~132 ~111 oak_leaves[persistent=true]
setblock ~25 ~132 ~112 oak_leaves[persistent=true]
setblock ~25 ~132 ~113 oak_wood
setblock ~25 ~132 ~114 oak_wood
setblock ~25 ~132 ~115 oak_wood
setblock ~25 ~132 ~116 oak_wood
setblock ~25 ~132 ~117 oak_wood
setblock ~25 ~132 ~118 oak_wood
setblock ~25 ~132 ~119 oak_leaves[persistent=true]
setblock ~25 ~132 ~120 oak_leaves[persistent=true]
setblock ~25 ~132 ~121 oak_wood
setblock ~25 ~132 ~122 oak_wood
setblock ~25 ~132 ~123 jungle_leaves[persistent=true]
setblock ~25 ~132 ~124 oak_wood
setblock ~25 ~132 ~125 jungle_leaves[persistent=true]
setblock ~25 ~132 ~127 jungle_leaves[persistent=true]
setblock ~25 ~132 ~129 oak_leaves[persistent=true]
setblock ~25 ~132 ~130 oak_leaves[persistent=true]
setblock ~25 ~133 ~72 oak_leaves[persistent=true]
setblock ~25 ~133 ~73 oak_leaves[persistent=true]
setblock ~25 ~133 ~75 oak_leaves[persistent=true]
setblock ~25 ~133 ~86 oak_leaves[persistent=true]
setblock ~25 ~133 ~87 oak_leaves[persistent=true]
setblock ~25 ~133 ~88 jungle_leaves[persistent=true]
setblock ~25 ~133 ~89 oak_leaves[persistent=true]
setblock ~25 ~133 ~90 oak_leaves[persistent=true]
setblock ~25 ~133 ~91 oak_leaves[persistent=true]
setblock ~25 ~133 ~92 oak_leaves[persistent=true]
setblock ~25 ~133 ~93 jungle_leaves[persistent=true]
setblock ~25 ~133 ~94 oak_leaves[persistent=true]
setblock ~25 ~133 ~95 jungle_leaves[persistent=true]
setblock ~25 ~133 ~96 oak_leaves[persistent=true]
setblock ~25 ~133 ~97 oak_leaves[persistent=true]
setblock ~25 ~133 ~98 oak_wood
setblock ~25 ~133 ~99 oak_leaves[persistent=true]
setblock ~25 ~133 ~100 oak_leaves[persistent=true]
setblock ~25 ~133 ~101 oak_wood
setblock ~25 ~133 ~102 oak_wood
setblock ~25 ~133 ~103 oak_wood
setblock ~25 ~133 ~104 oak_wood
setblock ~25 ~133 ~105 oak_leaves[persistent=true]
setblock ~25 ~133 ~106 oak_leaves[persistent=true]
setblock ~25 ~133 ~107 oak_wood
setblock ~25 ~133 ~108 oak_wood
setblock ~25 ~133 ~109 oak_wood
setblock ~25 ~133 ~110 oak_wood
setblock ~25 ~133 ~111 oak_wood
setblock ~25 ~133 ~112 oak_wood
setblock ~25 ~133 ~113 oak_wood
setblock ~25 ~133 ~114 oak_leaves[persistent=true]
setblock ~25 ~133 ~115 oak_wood
setblock ~25 ~133 ~116 oak_leaves[persistent=true]
setblock ~25 ~133 ~117 oak_wood
setblock ~25 ~133 ~118 oak_wood
setblock ~25 ~133 ~119 oak_wood
setblock ~25 ~133 ~120 oak_leaves[persistent=true]
setblock ~25 ~133 ~121 oak_wood
setblock ~25 ~133 ~122 oak_wood
setblock ~25 ~133 ~123 oak_wood
setblock ~25 ~133 ~124 jungle_leaves[persistent=true]
setblock ~25 ~133 ~125 oak_leaves[persistent=true]
setblock ~25 ~133 ~126 oak_leaves[persistent=true]
setblock ~25 ~133 ~128 oak_leaves[persistent=true]
setblock ~25 ~133 ~130 oak_leaves[persistent=true]
setblock ~25 ~133 ~131 oak_leaves[persistent=true]
setblock ~25 ~134 ~72 jungle_leaves[persistent=true]
setblock ~25 ~134 ~73 oak_leaves[persistent=true]
setblock ~25 ~134 ~74 oak_leaves[persistent=true]
setblock ~25 ~134 ~75 oak_leaves[persistent=true]
setblock ~25 ~134 ~82 oak_leaves[persistent=true]
setblock ~25 ~134 ~83 oak_leaves[persistent=true]
setblock ~25 ~134 ~86 oak_leaves[persistent=true]
setblock ~25 ~134 ~88 oak_leaves[persistent=true]
setblock ~25 ~134 ~89 oak_leaves[persistent=true]
setblock ~25 ~134 ~91 jungle_leaves[persistent=true]
setblock ~25 ~134 ~92 jungle_leaves[persistent=true]
setblock ~25 ~134 ~94 oak_leaves[persistent=true]
setblock ~25 ~134 ~95 oak_leaves[persistent=true]
setblock ~25 ~134 ~96 oak_wood
setblock ~25 ~134 ~97 oak_leaves[persistent=true]
setblock ~25 ~134 ~98 oak_wood
setblock ~25 ~134 ~99 oak_wood
setblock ~25 ~134 ~100 oak_leaves[persistent=true]
setblock ~25 ~134 ~101 oak_wood
setblock ~25 ~134 ~102 jungle_leaves[persistent=true]
setblock ~25 ~134 ~103 oak_leaves[persistent=true]
setblock ~25 ~134 ~104 oak_wood
setblock ~25 ~134 ~105 oak_leaves[persistent=true]
setblock ~25 ~134 ~106 oak_leaves[persistent=true]
setblock ~25 ~134 ~107 oak_leaves[persistent=true]
setblock ~25 ~134 ~108 oak_leaves[persistent=true]
setblock ~25 ~134 ~109 oak_wood
setblock ~25 ~134 ~110 oak_wood
setblock ~25 ~134 ~111 oak_wood
setblock ~25 ~134 ~112 oak_wood
setblock ~25 ~134 ~113 oak_wood
setblock ~25 ~134 ~114 oak_wood
setblock ~25 ~134 ~115 oak_wood
setblock ~25 ~134 ~116 oak_wood
setblock ~25 ~134 ~117 oak_wood
setblock ~25 ~134 ~118 oak_wood
setblock ~25 ~134 ~119 oak_log
setblock ~25 ~134 ~120 oak_wood
setblock ~25 ~134 ~121 oak_leaves[persistent=true]
setblock ~25 ~134 ~122 oak_wood
setblock ~25 ~134 ~123 oak_wood
setblock ~25 ~134 ~124 oak_leaves[persistent=true]
setblock ~25 ~134 ~125 jungle_leaves[persistent=true]
setblock ~25 ~134 ~126 oak_leaves[persistent=true]
setblock ~25 ~134 ~128 jungle_leaves[persistent=true]
setblock ~25 ~134 ~129 oak_leaves[persistent=true]
setblock ~25 ~134 ~130 oak_leaves[persistent=true]
setblock ~25 ~134 ~131 oak_leaves[persistent=true]
setblock ~25 ~135 ~78 oak_leaves[persistent=true]
setblock ~25 ~135 ~79 oak_leaves[persistent=true]
setblock ~25 ~135 ~80 oak_leaves[persistent=true]
setblock ~25 ~135 ~81 jungle_leaves[persistent=true]
setblock ~25 ~135 ~83 oak_leaves[persistent=true]
setblock ~25 ~135 ~86 oak_leaves[persistent=true]
setblock ~25 ~135 ~88 oak_leaves[persistent=true]
setblock ~25 ~135 ~89 oak_leaves[persistent=true]
setblock ~25 ~135 ~90 oak_leaves[persistent=true]
setblock ~25 ~135 ~91 oak_wood
setblock ~25 ~135 ~92 oak_wood
setblock ~25 ~135 ~93 oak_wood
setblock ~25 ~135 ~94 oak_wood
setblock ~25 ~135 ~96 oak_leaves[persistent=true]
setblock ~25 ~135 ~97 oak_wood
setblock ~25 ~135 ~98 jungle_leaves[persistent=true]
setblock ~25 ~135 ~99 jungle_leaves[persistent=true]
setblock ~25 ~135 ~100 oak_leaves[persistent=true]
setblock ~25 ~135 ~101 oak_wood
setblock ~25 ~135 ~102 oak_wood
setblock ~25 ~135 ~103 oak_wood
setblock ~25 ~135 ~104 oak_wood
setblock ~25 ~135 ~105 oak_leaves[persistent=true]
setblock ~25 ~135 ~106 oak_wood
setblock ~25 ~135 ~107 oak_wood
setblock ~25 ~135 ~108 oak_leaves[persistent=true]
setblock ~25 ~135 ~109 oak_wood
setblock ~25 ~135 ~110 oak_wood
setblock ~25 ~135 ~111 oak_leaves[persistent=true]
setblock ~25 ~135 ~112 oak_wood
setblock ~25 ~135 ~113 oak_wood
setblock ~25 ~135 ~114 oak_leaves[persistent=true]
setblock ~25 ~135 ~115 oak_leaves[persistent=true]
setblock ~25 ~135 ~116 oak_wood
setblock ~25 ~135 ~117 oak_wood
setblock ~25 ~135 ~118 oak_leaves[persistent=true]
setblock ~25 ~135 ~119 oak_wood
setblock ~25 ~135 ~120 oak_wood
setblock ~25 ~135 ~121 oak_wood
setblock ~25 ~135 ~122 oak_leaves[persistent=true]
setblock ~25 ~135 ~123 oak_wood
setblock ~25 ~135 ~124 oak_leaves[persistent=true]
setblock ~25 ~135 ~125 oak_leaves[persistent=true]
setblock ~25 ~135 ~126 oak_wood
setblock ~25 ~135 ~127 oak_leaves[persistent=true]
setblock ~25 ~135 ~128 oak_leaves[persistent=true]
setblock ~25 ~135 ~129 oak_leaves[persistent=true]
setblock ~25 ~135 ~130 oak_leaves[persistent=true]
setblock ~25 ~135 ~131 oak_leaves[persistent=true]
setblock ~25 ~136 ~78 oak_leaves[persistent=true]
setblock ~25 ~136 ~80 jungle_leaves[persistent=true]
setblock ~25 ~136 ~81 oak_leaves[persistent=true]
setblock ~25 ~136 ~82 oak_leaves[persistent=true]
setblock ~25 ~136 ~86 oak_leaves[persistent=true]
setblock ~25 ~136 ~87 oak_leaves[persistent=true]
setblock ~25 ~136 ~88 oak_leaves[persistent=true]
setblock ~25 ~136 ~89 jungle_leaves[persistent=true]
setblock ~25 ~136 ~90 jungle_leaves[persistent=true]
setblock ~25 ~136 ~91 oak_leaves[persistent=true]
setblock ~25 ~136 ~92 oak_leaves[persistent=true]
setblock ~25 ~136 ~93 oak_leaves[persistent=true]
setblock ~25 ~136 ~94 oak_leaves[persistent=true]
setblock ~25 ~136 ~95 oak_wood
setblock ~25 ~136 ~96 oak_leaves[persistent=true]
setblock ~25 ~136 ~97 jungle_leaves[persistent=true]
setblock ~25 ~136 ~98 jungle_leaves[persistent=true]
setblock ~25 ~136 ~99 oak_leaves[persistent=true]
setblock ~25 ~136 ~100 oak_leaves[persistent=true]
setblock ~25 ~136 ~102 jungle_leaves[persistent=true]
setblock ~25 ~136 ~103 oak_wood
setblock ~25 ~136 ~105 oak_leaves[persistent=true]
setblock ~25 ~136 ~106 oak_leaves[persistent=true]
setblock ~25 ~136 ~107 oak_leaves[persistent=true]
setblock ~25 ~136 ~108 oak_leaves[persistent=true]
setblock ~25 ~136 ~109 oak_wood
setblock ~25 ~136 ~110 oak_wood
setblock ~25 ~136 ~111 oak_leaves[persistent=true]
setblock ~25 ~136 ~112 oak_leaves[persistent=true]
setblock ~25 ~136 ~113 oak_wood
setblock ~25 ~136 ~114 oak_wood
setblock ~25 ~136 ~115 oak_wood
setblock ~25 ~136 ~116 oak_wood
setblock ~25 ~136 ~117 oak_leaves[persistent=true]
setblock ~25 ~136 ~118 oak_wood
setblock ~25 ~136 ~119 jungle_leaves[persistent=true]
setblock ~25 ~136 ~120 oak_leaves[persistent=true]
setblock ~25 ~136 ~121 oak_wood
setblock ~25 ~136 ~122 oak_wood
setblock ~25 ~136 ~123 oak_wood
setblock ~25 ~136 ~124 jungle_leaves[persistent=true]
setblock ~25 ~136 ~125 oak_leaves[persistent=true]
setblock ~25 ~136 ~126 oak_leaves[persistent=true]
setblock ~25 ~136 ~127 oak_leaves[persistent=true]
setblock ~25 ~136 ~128 oak_leaves[persistent=true]
setblock ~25 ~137 ~78 oak_leaves[persistent=true]
setblock ~25 ~137 ~79 oak_leaves[persistent=true]
setblock ~25 ~137 ~80 oak_leaves[persistent=true]
setblock ~25 ~137 ~81 oak_leaves[persistent=true]
setblock ~25 ~137 ~82 jungle_leaves[persistent=true]
setblock ~25 ~137 ~88 oak_leaves[persistent=true]
setblock ~25 ~137 ~89 oak_leaves[persistent=true]
setblock ~25 ~137 ~90 oak_leaves[persistent=true]
setblock ~25 ~137 ~91 oak_leaves[persistent=true]
setblock ~25 ~137 ~92 oak_wood
setblock ~25 ~137 ~93 oak_leaves[persistent=true]
setblock ~25 ~137 ~94 oak_leaves[persistent=true]
setblock ~25 ~137 ~96 oak_wood
setblock ~25 ~137 ~98 oak_leaves[persistent=true]
setblock ~25 ~137 ~99 oak_leaves[persistent=true]
setblock ~25 ~137 ~100 oak_wood
setblock ~25 ~137 ~101 oak_leaves[persistent=true]
setblock ~25 ~137 ~102 oak_wood
setblock ~25 ~137 ~103 oak_leaves[persistent=true]
setblock ~25 ~137 ~104 oak_leaves[persistent=true]
setblock ~25 ~137 ~105 oak_leaves[persistent=true]
setblock ~25 ~137 ~106 oak_leaves[persistent=true]
setblock ~25 ~137 ~107 oak_leaves[persistent=true]
setblock ~25 ~137 ~108 oak_leaves[persistent=true]
setblock ~25 ~137 ~109 oak_leaves[persistent=true]
setblock ~25 ~137 ~110 oak_wood
setblock ~25 ~137 ~111 oak_leaves[persistent=true]
setblock ~25 ~137 ~112 jungle_leaves[persistent=true]
setblock ~25 ~137 ~113 oak_wood
setblock ~25 ~137 ~114 oak_leaves[persistent=true]
setblock ~25 ~137 ~115 oak_leaves[persistent=true]
setblock ~25 ~137 ~116 oak_log
setblock ~25 ~137 ~117 oak_log
setblock ~25 ~137 ~119 oak_log
setblock ~25 ~137 ~120 oak_wood
setblock ~25 ~137 ~121 oak_leaves[persistent=true]
setblock ~25 ~137 ~122 jungle_leaves[persistent=true]
setblock ~25 ~137 ~123 jungle_leaves[persistent=true]
setblock ~25 ~137 ~125 oak_leaves[persistent=true]
setblock ~25 ~138 ~78 oak_leaves[persistent=true]
setblock ~25 ~138 ~79 jungle_leaves[persistent=true]
setblock ~25 ~138 ~80 oak_leaves[persistent=true]
setblock ~25 ~138 ~81 jungle_leaves[persistent=true]
setblock ~25 ~138 ~91 jungle_leaves[persistent=true]
setblock ~25 ~138 ~92 jungle_leaves[persistent=true]
setblock ~25 ~138 ~93 oak_leaves[persistent=true]
setblock ~25 ~138 ~94 oak_leaves[persistent=true]
setblock ~25 ~138 ~95 oak_leaves[persistent=true]
setblock ~25 ~138 ~96 oak_leaves[persistent=true]
setblock ~25 ~138 ~97 oak_leaves[persistent=true]
setblock ~25 ~138 ~98 oak_leaves[persistent=true]
setblock ~25 ~138 ~99 jungle_leaves[persistent=true]
setblock ~25 ~138 ~100 jungle_leaves[persistent=true]
setblock ~25 ~138 ~101 oak_leaves[persistent=true]
setblock ~25 ~138 ~102 oak_leaves[persistent=true]
setblock ~25 ~138 ~103 oak_leaves[persistent=true]
setblock ~25 ~138 ~104 oak_leaves[persistent=true]
setblock ~25 ~138 ~105 jungle_leaves[persistent=true]
setblock ~25 ~138 ~106 jungle_leaves[persistent=true]
setblock ~25 ~138 ~107 jungle_leaves[persistent=true]
setblock ~25 ~138 ~108 oak_leaves[persistent=true]
setblock ~25 ~138 ~109 jungle_leaves[persistent=true]
setblock ~25 ~138 ~110 oak_leaves[persistent=true]
setblock ~25 ~138 ~111 oak_wood
setblock ~25 ~138 ~112 oak_wood
setblock ~25 ~138 ~113 jungle_leaves[persistent=true]
setblock ~25 ~138 ~114 oak_leaves[persistent=true]
setblock ~25 ~138 ~116 oak_leaves[persistent=true]
setblock ~25 ~138 ~117 oak_log
setblock ~25 ~138 ~118 oak_leaves[persistent=true]
setblock ~25 ~138 ~119 jungle_leaves[persistent=true]
setblock ~25 ~138 ~120 oak_leaves[persistent=true]
setblock ~25 ~138 ~121 jungle_leaves[persistent=true]
setblock ~25 ~138 ~122 oak_leaves[persistent=true]
setblock ~25 ~138 ~123 oak_leaves[persistent=true]
setblock ~25 ~138 ~124 jungle_leaves[persistent=true]
setblock ~25 ~138 ~125 jungle_leaves[persistent=true]
setblock ~25 ~139 ~93 oak_leaves[persistent=true]
setblock ~25 ~139 ~95 oak_leaves[persistent=true]
setblock ~25 ~139 ~96 oak_leaves[persistent=true]
setblock ~25 ~139 ~97 jungle_leaves[persistent=true]
setblock ~25 ~139 ~98 jungle_leaves[persistent=true]
setblock ~25 ~139 ~99 jungle_leaves[persistent=true]
setblock ~25 ~139 ~100 oak_leaves[persistent=true]
setblock ~25 ~139 ~101 oak_leaves[persistent=true]
setblock ~25 ~139 ~102 oak_leaves[persistent=true]
setblock ~25 ~139 ~103 jungle_leaves[persistent=true]
setblock ~25 ~139 ~104 oak_leaves[persistent=true]
setblock ~25 ~139 ~105 oak_leaves[persistent=true]
setblock ~25 ~139 ~106 jungle_leaves[persistent=true]
setblock ~25 ~139 ~107 oak_leaves[persistent=true]
setblock ~25 ~139 ~108 jungle_leaves[persistent=true]
setblock ~25 ~139 ~109 jungle_leaves[persistent=true]
setblock ~25 ~139 ~110 oak_leaves[persistent=true]
setblock ~25 ~139 ~111 oak_leaves[persistent=true]
setblock ~25 ~139 ~112 oak_leaves[persistent=true]
setblock ~25 ~139 ~113 oak_wood
setblock ~25 ~139 ~114 oak_leaves[persistent=true]
setblock ~25 ~139 ~115 jungle_leaves[persistent=true]
setblock ~25 ~139 ~116 oak_leaves[persistent=true]
setblock ~25 ~139 ~118 oak_leaves[persistent=true]
setblock ~25 ~139 ~120 oak_leaves[persistent=true]
setblock ~25 ~139 ~122 oak_leaves[persistent=true]
setblock ~25 ~140 ~98 jungle_leaves[persistent=true]
setblock ~25 ~140 ~99 oak_leaves[persistent=true]
setblock ~25 ~140 ~100 oak_leaves[persistent=true]
setblock ~25 ~140 ~101 jungle_leaves[persistent=true]
setblock ~25 ~140 ~103 oak_leaves[persistent=true]
setblock ~25 ~140 ~104 oak_leaves[persistent=true]
setblock ~25 ~140 ~106 oak_leaves[persistent=true]
setblock ~25 ~140 ~107 oak_leaves[persistent=true]
setblock ~25 ~140 ~108 oak_leaves[persistent=true]
setblock ~25 ~140 ~109 oak_leaves[persistent=true]
setblock ~25 ~140 ~110 oak_leaves[persistent=true]
setblock ~25 ~140 ~111 oak_leaves[persistent=true]
setblock ~25 ~140 ~112 oak_leaves[persistent=true]
setblock ~25 ~140 ~113 oak_leaves[persistent=true]
setblock ~25 ~140 ~114 oak_leaves[persistent=true]
setblock ~25 ~140 ~116 jungle_leaves[persistent=true]
setblock ~25 ~140 ~118 oak_leaves[persistent=true]
setblock ~25 ~140 ~119 oak_leaves[persistent=true]
setblock ~26 ~119 ~117 dirt
setblock ~26 ~120 ~117 dirt
setblock ~26 ~121 ~115 dirt
setblock ~26 ~121 ~116 dirt
setblock ~26 ~121 ~117 dirt
setblock ~26 ~121 ~118 dirt
setblock ~26 ~122 ~115 dirt
setblock ~26 ~122 ~116 dirt
setblock ~26 ~122 ~117 dirt
setblock ~26 ~122 ~118 dirt
setblock ~26 ~123 ~115 dirt
setblock ~26 ~123 ~116 dirt
setblock ~26 ~123 ~117 dirt
setblock ~26 ~123 ~118 dirt
setblock ~26 ~124 ~115 dirt
setblock ~26 ~124 ~116 grass_block
setblock ~26 ~124 ~117 grass_block
setblock ~26 ~124 ~118 grass_block
setblock ~26 ~124 ~119 spruce_slab
setblock ~26 ~124 ~120 spruce_slab
setblock ~26 ~125 ~111 spruce_slab
setblock ~26 ~125 ~113 oak_leaves[persistent=true]
setblock ~26 ~125 ~114 jungle_leaves[persistent=true]
setblock ~26 ~125 ~115 oak_leaves[persistent=true]
setblock ~26 ~125 ~116 oak_log
setblock ~26 ~125 ~117 oak_leaves[persistent=true]
setblock ~26 ~125 ~118 oak_log
setblock ~26 ~125 ~119 spruce_slab
setblock ~26 ~126 ~106 oak_leaves[persistent=true]
setblock ~26 ~126 ~107 oak_leaves[persistent=true]
setblock ~26 ~126 ~108 jungle_leaves[persistent=true]
setblock ~26 ~126 ~113 oak_leaves[persistent=true]
setblock ~26 ~126 ~114 oak_leaves[persistent=true]
setblock ~26 ~126 ~115 oak_log
setblock ~26 ~126 ~116 oak_log
setblock ~26 ~126 ~117 oak_leaves[persistent=true]
setblock ~26 ~126 ~118 oak_log
setblock ~26 ~126 ~119 oak_leaves[persistent=true]
setblock ~26 ~126 ~120 jungle_leaves[persistent=true]
setblock ~26 ~126 ~121 oak_leaves[persistent=true]
setblock ~26 ~126 ~122 jungle_leaves[persistent=true]
setblock ~26 ~126 ~123 oak_leaves[persistent=true]
setblock ~26 ~126 ~124 oak_leaves[persistent=true]
setblock ~26 ~126 ~128 oak_leaves[persistent=true]
setblock ~26 ~126 ~129 oak_leaves[persistent=true]
setblock ~26 ~126 ~130 oak_leaves[persistent=true]
setblock ~26 ~126 ~131 jungle_leaves[persistent=true]
setblock ~26 ~126 ~132 oak_leaves[persistent=true]
setblock ~26 ~126 ~133 oak_leaves[persistent=true]
setblock ~26 ~126 ~134 oak_leaves[persistent=true]
setblock ~26 ~126 ~135 oak_leaves[persistent=true]
setblock ~26 ~127 ~96 oak_leaves[persistent=true]
setblock ~26 ~127 ~97 oak_leaves[persistent=true]
setblock ~26 ~127 ~98 oak_leaves[persistent=true]
setblock ~26 ~127 ~99 oak_leaves[persistent=true]
setblock ~26 ~127 ~100 oak_leaves[persistent=true]
setblock ~26 ~127 ~101 oak_leaves[persistent=true]
setblock ~26 ~127 ~102 jungle_leaves[persistent=true]
setblock ~26 ~127 ~103 oak_leaves[persistent=true]
setblock ~26 ~127 ~104 oak_leaves[persistent=true]
setblock ~26 ~127 ~105 oak_leaves[persistent=true]
setblock ~26 ~127 ~106 oak_leaves[persistent=true]
setblock ~26 ~127 ~107 oak_leaves[persistent=true]
setblock ~26 ~127 ~108 jungle_leaves[persistent=true]
setblock ~26 ~127 ~109 oak_leaves[persistent=true]
setblock ~26 ~127 ~110 oak_leaves[persistent=true]
setblock ~26 ~127 ~111 jungle_leaves[persistent=true]
setblock ~26 ~127 ~112 oak_leaves[persistent=true]
setblock ~26 ~127 ~114 oak_leaves[persistent=true]
setblock ~26 ~127 ~115 oak_log
setblock ~26 ~127 ~116 oak_log
setblock ~26 ~127 ~117 jungle_leaves[persistent=true]
setblock ~26 ~127 ~118 oak_log
setblock ~26 ~127 ~119 oak_leaves[persistent=true]
setblock ~26 ~127 ~120 oak_leaves[persistent=true]
setblock ~26 ~127 ~121 oak_leaves[persistent=true]
setblock ~26 ~127 ~122 oak_leaves[persistent=true]
setblock ~26 ~127 ~124 oak_leaves[persistent=true]
setblock ~26 ~127 ~125 oak_leaves[persistent=true]
setblock ~26 ~127 ~128 oak_leaves[persistent=true]
setblock ~26 ~127 ~129 oak_leaves[persistent=true]
setblock ~26 ~127 ~130 jungle_leaves[persistent=true]
setblock ~26 ~127 ~131 oak_leaves[persistent=true]
setblock ~26 ~127 ~132 oak_leaves[persistent=true]
setblock ~26 ~127 ~133 jungle_leaves[persistent=true]
setblock ~26 ~127 ~134 oak_leaves[persistent=true]
setblock ~26 ~127 ~135 oak_leaves[persistent=true]
setblock ~26 ~128 ~83 oak_leaves[persistent=true]
setblock ~26 ~128 ~84 oak_leaves[persistent=true]
setblock ~26 ~128 ~85 oak_leaves[persistent=true]
setblock ~26 ~128 ~86 oak_leaves[persistent=true]
setblock ~26 ~128 ~96 oak_leaves[persistent=true]
setblock ~26 ~128 ~97 oak_leaves[persistent=true]
setblock ~26 ~128 ~98 oak_wood
setblock ~26 ~128 ~99 jungle_leaves[persistent=true]
setblock ~26 ~128 ~100 oak_leaves[persistent=true]
setblock ~26 ~128 ~102 oak_leaves[persistent=true]
setblock ~26 ~128 ~103 oak_leaves[persistent=true]
setblock ~26 ~128 ~104 oak_leaves[persistent=true]
setblock ~26 ~128 ~105 oak_leaves[persistent=true]
setblock ~26 ~128 ~107 oak_leaves[persistent=true]
setblock ~26 ~128 ~109 oak_leaves[persistent=true]
setblock ~26 ~128 ~110 jungle_leaves[persistent=true]
setblock ~26 ~128 ~111 jungle_leaves[persistent=true]
setblock ~26 ~128 ~112 oak_leaves[persistent=true]
setblock ~26 ~128 ~113 oak_leaves[persistent=true]
setblock ~26 ~128 ~114 oak_leaves[persistent=true]
setblock ~26 ~128 ~115 oak_log
setblock ~26 ~128 ~116 oak_log
setblock ~26 ~128 ~117 oak_leaves[persistent=true]
setblock ~26 ~128 ~118 oak_wood
setblock ~26 ~128 ~119 oak_leaves[persistent=true]
setblock ~26 ~128 ~120 oak_leaves[persistent=true]
setblock ~26 ~128 ~121 oak_leaves[persistent=true]
setblock ~26 ~128 ~122 oak_wood
setblock ~26 ~128 ~124 oak_leaves[persistent=true]
setblock ~26 ~128 ~125 jungle_leaves[persistent=true]
setblock ~26 ~128 ~126 oak_leaves[persistent=true]
setblock ~26 ~128 ~128 oak_leaves[persistent=true]
setblock ~26 ~128 ~129 oak_leaves[persistent=true]
setblock ~26 ~128 ~130 oak_leaves[persistent=true]
setblock ~26 ~128 ~131 oak_leaves[persistent=true]
setblock ~26 ~128 ~132 oak_leaves[persistent=true]
setblock ~26 ~128 ~133 oak_leaves[persistent=true]
setblock ~26 ~128 ~134 jungle_leaves[persistent=true]
setblock ~26 ~128 ~135 oak_leaves[persistent=true]
setblock ~26 ~129 ~84 oak_leaves[persistent=true]
setblock ~26 ~129 ~85 jungle_leaves[persistent=true]
setblock ~26 ~129 ~86 jungle_leaves[persistent=true]
setblock ~26 ~129 ~87 oak_leaves[persistent=true]
setblock ~26 ~129 ~96 oak_leaves[persistent=true]
setblock ~26 ~129 ~97 oak_leaves[persistent=true]
setblock ~26 ~129 ~98 oak_leaves[persistent=true]
setblock ~26 ~129 ~99 oak_wood
setblock ~26 ~129 ~100 jungle_leaves[persistent=true]
setblock ~26 ~129 ~101 jungle_leaves[persistent=true]
setblock ~26 ~129 ~102 oak_leaves[persistent=true]
setblock ~26 ~129 ~103 oak_leaves[persistent=true]
setblock ~26 ~129 ~104 jungle_leaves[persistent=true]
setblock ~26 ~129 ~105 oak_leaves[persistent=true]
setblock ~26 ~129 ~106 oak_leaves[persistent=true]
setblock ~26 ~129 ~107 oak_leaves[persistent=true]
setblock ~26 ~129 ~108 oak_leaves[persistent=true]
setblock ~26 ~129 ~110 oak_leaves[persistent=true]
setblock ~26 ~129 ~111 oak_wood
setblock ~26 ~129 ~112 jungle_leaves[persistent=true]
setblock ~26 ~129 ~113 oak_leaves[persistent=true]
setblock ~26 ~129 ~114 oak_leaves[persistent=true]
setblock ~26 ~129 ~115 oak_log
setblock ~26 ~129 ~116 oak_log
setblock ~26 ~129 ~117 oak_leaves[persistent=true]
setblock ~26 ~129 ~118 oak_wood
setblock ~26 ~129 ~119 oak_leaves[persistent=true]
setblock ~26 ~129 ~120 oak_leaves[persistent=true]
setblock ~26 ~129 ~121 oak_leaves[persistent=true]
setblock ~26 ~129 ~122 oak_leaves[persistent=true]
setblock ~26 ~129 ~123 oak_leaves[persistent=true]
setblock ~26 ~129 ~124 oak_leaves[persistent=true]
setblock ~26 ~129 ~125 oak_leaves[persistent=true]
setblock ~26 ~129 ~126 oak_leaves[persistent=true]
setblock ~26 ~129 ~127 oak_leaves[persistent=true]
setblock ~26 ~129 ~128 oak_leaves[persistent=true]
setblock ~26 ~129 ~129 oak_leaves[persistent=true]
setblock ~26 ~129 ~130 oak_leaves[persistent=true]
setblock ~26 ~129 ~131 oak_leaves[persistent=true]
setblock ~26 ~129 ~132 oak_wood
setblock ~26 ~129 ~133 oak_leaves[persistent=true]
setblock ~26 ~129 ~134 oak_leaves[persistent=true]
setblock ~26 ~129 ~135 oak_leaves[persistent=true]
setblock ~26 ~130 ~83 oak_leaves[persistent=true]
setblock ~26 ~130 ~84 jungle_leaves[persistent=true]
setblock ~26 ~130 ~85 oak_leaves[persistent=true]
setblock ~26 ~130 ~86 oak_leaves[persistent=true]
setblock ~26 ~130 ~87 oak_leaves[persistent=true]
setblock ~26 ~130 ~88 oak_leaves[persistent=true]
setblock ~26 ~130 ~91 oak_leaves[persistent=true]
setblock ~26 ~130 ~92 oak_leaves[persistent=true]
setblock ~26 ~130 ~93 oak_leaves[persistent=true]
setblock ~26 ~130 ~94 oak_leaves[persistent=true]
setblock ~26 ~130 ~95 oak_leaves[persistent=true]
setblock ~26 ~130 ~96 oak_leaves[persistent=true]
setblock ~26 ~130 ~97 oak_leaves[persistent=true]
setblock ~26 ~130 ~98 oak_leaves[persistent=true]
setblock ~26 ~130 ~99 oak_leaves[persistent=true]
setblock ~26 ~130 ~100 jungle_leaves[persistent=true]
setblock ~26 ~130 ~101 oak_leaves[persistent=true]
setblock ~26 ~130 ~102 oak_leaves[persistent=true]
setblock ~26 ~130 ~103 oak_wood
setblock ~26 ~130 ~104 oak_leaves[persistent=true]
setblock ~26 ~130 ~105 oak_leaves[persistent=true]
setblock ~26 ~130 ~106 oak_leaves[persistent=true]
setblock ~26 ~130 ~107 oak_leaves[persistent=true]
setblock ~26 ~130 ~108 oak_leaves[persistent=true]
setblock ~26 ~130 ~109 oak_leaves[persistent=true]
setblock ~26 ~130 ~110 jungle_leaves[persistent=true]
setblock ~26 ~130 ~111 oak_wood
setblock ~26 ~130 ~112 oak_wood
setblock ~26 ~130 ~113 oak_leaves[persistent=true]
setblock ~26 ~130 ~114 oak_log
setblock ~26 ~130 ~115 oak_log
setblock ~26 ~130 ~116 oak_wood
setblock ~26 ~130 ~117 oak_wood
setblock ~26 ~130 ~118 oak_log
setblock ~26 ~130 ~119 jungle_leaves[persistent=true]
setblock ~26 ~130 ~120 oak_leaves[persistent=true]
setblock ~26 ~130 ~121 jungle_leaves[persistent=true]
setblock ~26 ~130 ~122 jungle_leaves[persistent=true]
setblock ~26 ~130 ~123 oak_leaves[persistent=true]
setblock ~26 ~130 ~124 jungle_leaves[persistent=true]
setblock ~26 ~130 ~125 oak_leaves[persistent=true]
setblock ~26 ~130 ~126 oak_leaves[persistent=true]
setblock ~26 ~130 ~127 oak_leaves[persistent=true]
setblock ~26 ~130 ~128 oak_leaves[persistent=true]
setblock ~26 ~130 ~129 oak_leaves[persistent=true]
setblock ~26 ~130 ~130 oak_leaves[persistent=true]
setblock ~26 ~130 ~131 oak_leaves[persistent=true]
setblock ~26 ~130 ~132 jungle_leaves[persistent=true]
setblock ~26 ~130 ~133 oak_leaves[persistent=true]
setblock ~26 ~130 ~134 oak_leaves[persistent=true]
setblock ~26 ~130 ~135 oak_leaves[persistent=true]
setblock ~26 ~131 ~68 oak_leaves[persistent=true]
setblock ~26 ~131 ~70 jungle_leaves[persistent=true]
setblock ~26 ~131 ~72 oak_leaves[persistent=true]
setblock ~26 ~131 ~73 oak_leaves[persistent=true]
setblock ~26 ~131 ~74 oak_leaves[persistent=true]
setblock ~26 ~131 ~75 oak_leaves[persistent=true]
setblock ~26 ~131 ~83 oak_leaves[persistent=true]
setblock ~26 ~131 ~84 jungle_leaves[persistent=true]
setblock ~26 ~131 ~85 oak_leaves[persistent=true]
setblock ~26 ~131 ~86 oak_wood
setblock ~26 ~131 ~87 oak_leaves[persistent=true]
setblock ~26 ~131 ~88 oak_leaves[persistent=true]
setblock ~26 ~131 ~89 oak_leaves[persistent=true]
setblock ~26 ~131 ~90 oak_leaves[persistent=true]
setblock ~26 ~131 ~91 oak_leaves[persistent=true]
setblock ~26 ~131 ~92 oak_leaves[persistent=true]
setblock ~26 ~131 ~93 oak_leaves[persistent=true]
setblock ~26 ~131 ~94 oak_leaves[persistent=true]
setblock ~26 ~131 ~95 oak_leaves[persistent=true]
setblock ~26 ~131 ~96 oak_leaves[persistent=true]
setblock ~26 ~131 ~98 oak_leaves[persistent=true]
setblock ~26 ~131 ~99 jungle_leaves[persistent=true]
setblock ~26 ~131 ~101 oak_leaves[persistent=true]
setblock ~26 ~131 ~102 oak_leaves[persistent=true]
setblock ~26 ~131 ~103 oak_wood
setblock ~26 ~131 ~104 oak_wood
setblock ~26 ~131 ~105 oak_leaves[persistent=true]
setblock ~26 ~131 ~106 oak_wood
setblock ~26 ~131 ~107 jungle_leaves[persistent=true]
setblock ~26 ~131 ~108 oak_leaves[persistent=true]
setblock ~26 ~131 ~109 oak_wood
setblock ~26 ~131 ~110 oak_leaves[persistent=true]
setblock ~26 ~131 ~111 oak_leaves[persistent=true]
setblock ~26 ~131 ~112 oak_wood
setblock ~26 ~131 ~113 oak_leaves[persistent=true]
setblock ~26 ~131 ~114 oak_wood
setblock ~26 ~131 ~115 oak_leaves[persistent=true]
setblock ~26 ~131 ~116 oak_wood
setblock ~26 ~131 ~117 oak_leaves[persistent=true]
setblock ~26 ~131 ~118 oak_leaves[persistent=true]
setblock ~26 ~131 ~119 oak_wood
setblock ~26 ~131 ~120 oak_wood
setblock ~26 ~131 ~121 oak_leaves[persistent=true]
setblock ~26 ~131 ~122 oak_leaves[persistent=true]
setblock ~26 ~131 ~123 oak_leaves[persistent=true]
setblock ~26 ~131 ~125 oak_leaves[persistent=true]
setblock ~26 ~131 ~126 oak_leaves[persistent=true]
setblock ~26 ~131 ~127 oak_leaves[persistent=true]
setblock ~26 ~131 ~128 jungle_leaves[persistent=true]
setblock ~26 ~131 ~129 oak_leaves[persistent=true]
setblock ~26 ~131 ~130 oak_leaves[persistent=true]
setblock ~26 ~131 ~131 oak_leaves[persistent=true]
setblock ~26 ~132 ~68 oak_leaves[persistent=true]
setblock ~26 ~132 ~69 jungle_leaves[persistent=true]
setblock ~26 ~132 ~71 oak_leaves[persistent=true]
setblock ~26 ~132 ~73 oak_leaves[persistent=true]
setblock ~26 ~132 ~74 jungle_leaves[persistent=true]
setblock ~26 ~132 ~75 oak_leaves[persistent=true]
setblock ~26 ~132 ~84 oak_leaves[persistent=true]
setblock ~26 ~132 ~85 jungle_leaves[persistent=true]
setblock ~26 ~132 ~86 oak_leaves[persistent=true]
setblock ~26 ~132 ~87 jungle_leaves[persistent=true]
setblock ~26 ~132 ~88 oak_leaves[persistent=true]
setblock ~26 ~132 ~89 oak_leaves[persistent=true]
setblock ~26 ~132 ~91 oak_leaves[persistent=true]
setblock ~26 ~132 ~92 oak_leaves[persistent=true]
setblock ~26 ~132 ~93 oak_leaves[persistent=true]
setblock ~26 ~132 ~94 oak_leaves[persistent=true]
setblock ~26 ~132 ~95 oak_leaves[persistent=true]
setblock ~26 ~132 ~96 oak_leaves[persistent=true]
setblock ~26 ~132 ~97 oak_leaves[persistent=true]
setblock ~26 ~132 ~99 oak_wood
setblock ~26 ~132 ~100 oak_leaves[persistent=true]
setblock ~26 ~132 ~101 oak_leaves[persistent=true]
setblock ~26 ~132 ~102 oak_wood
setblock ~26 ~132 ~103 oak_wood
setblock ~26 ~132 ~104 oak_leaves[persistent=true]
setblock ~26 ~132 ~105 jungle_leaves[persistent=true]
setblock ~26 ~132 ~106 oak_leaves[persistent=true]
setblock ~26 ~132 ~107 jungle_leaves[persistent=true]
setblock ~26 ~132 ~108 jungle_leaves[persistent=true]
setblock ~26 ~132 ~109 oak_wood
setblock ~26 ~132 ~110 oak_wood
setblock ~26 ~132 ~111 oak_leaves[persistent=true]
setblock ~26 ~132 ~112 oak_leaves[persistent=true]
setblock ~26 ~132 ~113 oak_wood
setblock ~26 ~132 ~114 oak_wood
setblock ~26 ~132 ~115 oak_wood
setblock ~26 ~132 ~116 oak_wood
setblock ~26 ~132 ~117 oak_leaves[persistent=true]
setblock ~26 ~132 ~118 oak_log
setblock ~26 ~132 ~119 oak_wood
setblock ~26 ~132 ~120 oak_wood
setblock ~26 ~132 ~121 oak_wood
setblock ~26 ~132 ~122 oak_wood
setblock ~26 ~132 ~123 oak_leaves[persistent=true]
setblock ~26 ~132 ~124 oak_wood
setblock ~26 ~132 ~125 oak_leaves[persistent=true]
setblock ~26 ~132 ~126 oak_leaves[persistent=true]
setblock ~26 ~132 ~127 oak_wood
setblock ~26 ~132 ~128 oak_leaves[persistent=true]
setblock ~26 ~132 ~129 oak_leaves[persistent=true]
setblock ~26 ~132 ~130 oak_leaves[persistent=true]
setblock ~26 ~132 ~131 oak_leaves[persistent=true]
setblock ~26 ~132 ~132 oak_leaves[persistent=true]
setblock ~26 ~133 ~68 oak_leaves[persistent=true]
setblock ~26 ~133 ~69 jungle_leaves[persistent=true]
setblock ~26 ~133 ~70 oak_leaves[persistent=true]
setblock ~26 ~133 ~71 oak_leaves[persistent=true]
setblock ~26 ~133 ~72 oak_leaves[persistent=true]
setblock ~26 ~133 ~73 oak_leaves[persistent=true]
setblock ~26 ~133 ~75 oak_leaves[persistent=true]
setblock ~26 ~133 ~85 jungle_leaves[persistent=true]
setblock ~26 ~133 ~86 oak_leaves[persistent=true]
setblock ~26 ~133 ~88 oak_leaves[persistent=true]
setblock ~26 ~133 ~89 oak_leaves[persistent=true]
setblock ~26 ~133 ~90 oak_leaves[persistent=true]
setblock ~26 ~133 ~91 jungle_leaves[persistent=true]
setblock ~26 ~133 ~92 oak_leaves[persistent=true]
setblock ~26 ~133 ~93 oak_leaves[persistent=true]
setblock ~26 ~133 ~94 oak_leaves[persistent=true]
setblock ~26 ~133 ~95 oak_wood
setblock ~26 ~133 ~96 oak_wood
setblock ~26 ~133 ~97 oak_wood
setblock ~26 ~133 ~99 oak_leaves[persistent=true]
setblock ~26 ~133 ~100 oak_leaves[persistent=true]
setblock ~26 ~133 ~101 oak_leaves[persistent=true]
setblock ~26 ~133 ~102 oak_wood
setblock ~26 ~133 ~103 oak_leaves[persistent=true]
setblock ~26 ~133 ~105 oak_wood
setblock ~26 ~133 ~106 oak_wood
setblock ~26 ~133 ~107 oak_leaves[persistent=true]
setblock ~26 ~133 ~108 oak_wood
setblock ~26 ~133 ~109 oak_leaves[persistent=true]
setblock ~26 ~133 ~110 oak_wood
setblock ~26 ~133 ~111 oak_wood
setblock ~26 ~133 ~112 oak_wood
setblock ~26 ~133 ~113 oak_wood
setblock ~26 ~133 ~114 oak_wood
setblock ~26 ~133 ~115 oak_wood
setblock ~26 ~133 ~116 oak_leaves[persistent=true]
setblock ~26 ~133 ~117 oak_wood
setblock ~26 ~133 ~118 oak_wood
setblock ~26 ~133 ~119 oak_wood
setblock ~26 ~133 ~120 oak_wood
setblock ~26 ~133 ~121 oak_leaves[persistent=true]
setblock ~26 ~133 ~122 oak_wood
setblock ~26 ~133 ~123 oak_wood
setblock ~26 ~133 ~124 oak_leaves[persistent=true]
setblock ~26 ~133 ~125 oak_leaves[persistent=true]
setblock ~26 ~133 ~128 oak_leaves[persistent=true]
setblock ~26 ~133 ~129 jungle_leaves[persistent=true]
setblock ~26 ~133 ~130 oak_leaves[persistent=true]
setblock ~26 ~133 ~131 oak_leaves[persistent=true]
setblock ~26 ~134 ~70 oak_leaves[persistent=true]
setblock ~26 ~134 ~71 jungle_leaves[persistent=true]
setblock ~26 ~134 ~72 oak_leaves[persistent=true]
setblock ~26 ~134 ~73 oak_leaves[persistent=true]
setblock ~26 ~134 ~74 oak_leaves[persistent=true]
setblock ~26 ~134 ~75 oak_leaves[persistent=true]
setblock ~26 ~134 ~82 oak_leaves[persistent=true]
setblock ~26 ~134 ~83 jungle_leaves[persistent=true]
setblock ~26 ~134 ~84 oak_leaves[persistent=true]
setblock ~26 ~134 ~85 oak_leaves[persistent=true]
setblock ~26 ~134 ~86 oak_leaves[persistent=true]
setblock ~26 ~134 ~87 oak_leaves[persistent=true]
setblock ~26 ~134 ~88 oak_leaves[persistent=true]
setblock ~26 ~134 ~89 oak_leaves[persistent=true]
setblock ~26 ~134 ~90 oak_leaves[persistent=true]
setblock ~26 ~134 ~91 jungle_leaves[persistent=true]
setblock ~26 ~134 ~92 oak_leaves[persistent=true]
setblock ~26 ~134 ~93 jungle_leaves[persistent=true]
setblock ~26 ~134 ~94 oak_wood
setblock ~26 ~134 ~95 oak_wood
setblock ~26 ~134 ~96 oak_wood
setblock ~26 ~134 ~97 oak_wood
setblock ~26 ~134 ~98 oak_wood
setblock ~26 ~134 ~99 oak_wood
setblock ~26 ~134 ~100 oak_wood
setblock ~26 ~134 ~101 oak_wood
setblock ~26 ~134 ~102 oak_wood
setblock ~26 ~134 ~104 oak_wood
setblock ~26 ~134 ~105 oak_wood
setblock ~26 ~134 ~106 oak_wood
setblock ~26 ~134 ~107 oak_wood
setblock ~26 ~134 ~108 oak_wood
setblock ~26 ~134 ~109 oak_wood
setblock ~26 ~134 ~110 oak_wood
setblock ~26 ~134 ~111 oak_wood
setblock ~26 ~134 ~112 oak_wood
setblock ~26 ~134 ~113 oak_leaves[persistent=true]
setblock ~26 ~134 ~114 oak_leaves[persistent=true]
setblock ~26 ~134 ~116 oak_wood
setblock ~26 ~134 ~117 oak_wood
setblock ~26 ~134 ~118 oak_wood
setblock ~26 ~134 ~119 oak_wood
setblock ~26 ~134 ~120 oak_wood
setblock ~26 ~134 ~121 oak_wood
setblock ~26 ~134 ~122 oak_leaves[persistent=true]
setblock ~26 ~134 ~123 oak_wood
setblock ~26 ~134 ~124 jungle_leaves[persistent=true]
setblock ~26 ~134 ~125 oak_leaves[persistent=true]
setblock ~26 ~134 ~126 oak_wood
setblock ~26 ~134 ~127 jungle_leaves[persistent=true]
setblock ~26 ~134 ~128 oak_leaves[persistent=true]
setblock ~26 ~134 ~129 oak_leaves[persistent=true]
setblock ~26 ~134 ~131 oak_leaves[persistent=true]
setblock ~26 ~135 ~70 jungle_leaves[persistent=true]
setblock ~26 ~135 ~71 oak_leaves[persistent=true]
setblock ~26 ~135 ~72 oak_leaves[persistent=true]
setblock ~26 ~135 ~73 oak_leaves[persistent=true]
setblock ~26 ~135 ~78 oak_leaves[persistent=true]
setblock ~26 ~135 ~79 oak_leaves[persistent=true]
setblock ~26 ~135 ~80 jungle_leaves[persistent=true]
setblock ~26 ~135 ~81 oak_leaves[persistent=true]
setblock ~26 ~135 ~82 oak_leaves[persistent=true]
setblock ~26 ~135 ~83 oak_leaves[persistent=true]
setblock ~26 ~135 ~84 jungle_leaves[persistent=true]
setblock ~26 ~135 ~85 jungle_leaves[persistent=true]
setblock ~26 ~135 ~86 oak_leaves[persistent=true]
setblock ~26 ~135 ~88 jungle_leaves[persistent=true]
setblock ~26 ~135 ~89 oak_leaves[persistent=true]
setblock ~26 ~135 ~91 oak_leaves[persistent=true]
setblock ~26 ~135 ~92 oak_leaves[persistent=true]
setblock ~26 ~135 ~93 oak_leaves[persistent=true]
setblock ~26 ~135 ~94 oak_leaves[persistent=true]
setblock ~26 ~135 ~95 oak_wood
setblock ~26 ~135 ~96 oak_wood
setblock ~26 ~135 ~97 oak_wood
setblock ~26 ~135 ~98 oak_wood
setblock ~26 ~135 ~100 oak_leaves[persistent=true]
setblock ~26 ~135 ~101 oak_wood
setblock ~26 ~135 ~102 oak_wood
setblock ~26 ~135 ~103 oak_wood
setblock ~26 ~135 ~104 oak_wood
setblock ~26 ~135 ~105 oak_leaves[persistent=true]
setblock ~26 ~135 ~106 oak_wood
setblock ~26 ~135 ~107 oak_wood
setblock ~26 ~135 ~108 oak_wood
setblock ~26 ~135 ~109 oak_wood
setblock ~26 ~135 ~110 oak_log
setblock ~26 ~135 ~111 oak_wood
setblock ~26 ~135 ~112 oak_wood
setblock ~26 ~135 ~113 oak_wood
setblock ~26 ~135 ~114 oak_wood
setblock ~26 ~135 ~115 oak_wood
setblock ~26 ~135 ~116 oak_wood
setblock ~26 ~135 ~117 oak_wood
setblock ~26 ~135 ~118 oak_wood
setblock ~26 ~135 ~119 oak_wood
setblock ~26 ~135 ~120 oak_wood
setblock ~26 ~135 ~121 oak_wood
setblock ~26 ~135 ~122 oak_leaves[persistent=true]
setblock ~26 ~135 ~123 oak_wood
setblock ~26 ~135 ~124 oak_leaves[persistent=true]
setblock ~26 ~135 ~125 oak_log
setblock ~26 ~135 ~126 oak_wood
setblock ~26 ~135 ~127 oak_wood
setblock ~26 ~135 ~128 oak_leaves[persistent=true]
setblock ~26 ~135 ~129 oak_leaves[persistent=true]
setblock ~26 ~135 ~130 oak_leaves[persistent=true]
setblock ~26 ~136 ~79 jungle_leaves[persistent=true]
setblock ~26 ~136 ~80 oak_leaves[persistent=true]
setblock ~26 ~136 ~81 oak_leaves[persistent=true]
setblock ~26 ~136 ~82 oak_leaves[persistent=true]
setblock ~26 ~136 ~83 jungle_leaves[persistent=true]
setblock ~26 ~136 ~84 oak_leaves[persistent=true]
setblock ~26 ~136 ~85 oak_leaves[persistent=true]
setblock ~26 ~136 ~86 oak_leaves[persistent=true]
setblock ~26 ~136 ~87 oak_leaves[persistent=true]
setblock ~26 ~136 ~88 oak_leaves[persistent=true]
setblock ~26 ~136 ~89 oak_leaves[persistent=true]
setblock ~26 ~136 ~90 oak_leaves[persistent=true]
setblock ~26 ~136 ~91 oak_leaves[persistent=true]
setblock ~26 ~136 ~92 oak_wood
setblock ~26 ~136 ~93 oak_wood
setblock ~26 ~136 ~94 oak_wood
setblock ~26 ~136 ~95 jungle_leaves[persistent=true]
setblock ~26 ~136 ~96 oak_wood
setblock ~26 ~136 ~97 oak_leaves[persistent=true]
setblock ~26 ~136 ~98 oak_wood
setblock ~26 ~136 ~99 oak_leaves[persistent=true]
setblock ~26 ~136 ~100 oak_leaves[persistent=true]
setblock ~26 ~136 ~101 oak_leaves[persistent=true]
setblock ~26 ~136 ~102 oak_wood
setblock ~26 ~136 ~104 oak_wood
setblock ~26 ~136 ~105 oak_wood
setblock ~26 ~136 ~107 oak_leaves[persistent=true]
setblock ~26 ~136 ~108 oak_leaves[persistent=true]
setblock ~26 ~136 ~109 oak_wood
setblock ~26 ~136 ~110 oak_wood
setblock ~26 ~136 ~111 oak_leaves[persistent=true]
setblock ~26 ~136 ~112 oak_wood
setblock ~26 ~136 ~113 oak_wood
setblock ~26 ~136 ~114 oak_log
setblock ~26 ~136 ~116 oak_wood
setblock ~26 ~136 ~117 oak_wood
setblock ~26 ~136 ~119 jungle_leaves[persistent=true]
setblock ~26 ~136 ~120 oak_wood
setblock ~26 ~136 ~121 oak_wood
setblock ~26 ~136 ~123 jungle_leaves[persistent=true]
setblock ~26 ~136 ~124 jungle_leaves[persistent=true]
setblock ~26 ~136 ~125 oak_leaves[persistent=true]
setblock ~26 ~136 ~126 oak_leaves[persistent=true]
setblock ~26 ~136 ~127 jungle_leaves[persistent=true]
setblock ~26 ~136 ~128 oak_leaves[persistent=true]
setblock ~26 ~136 ~129 jungle_leaves[persistent=true]
setblock ~26 ~137 ~79 oak_leaves[persistent=true]
setblock ~26 ~137 ~81 oak_leaves[persistent=true]
setblock ~26 ~137 ~82 jungle_leaves[persistent=true]
setblock ~26 ~137 ~83 oak_leaves[persistent=true]
setblock ~26 ~137 ~90 oak_leaves[persistent=true]
setblock ~26 ~137 ~91 oak_leaves[persistent=true]
setblock ~26 ~137 ~92 oak_wood
setblock ~26 ~137 ~94 oak_leaves[persistent=true]
setblock ~26 ~137 ~95 oak_leaves[persistent=true]
setblock ~26 ~137 ~96 oak_wood
setblock ~26 ~137 ~97 oak_wood
setblock ~26 ~137 ~98 oak_log
setblock ~26 ~137 ~99 oak_leaves[persistent=true]
setblock ~26 ~137 ~100 oak_wood
setblock ~26 ~137 ~101 oak_leaves[persistent=true]
setblock ~26 ~137 ~102 oak_wood
setblock ~26 ~137 ~103 oak_leaves[persistent=true]
setblock ~26 ~137 ~104 oak_wood
setblock ~26 ~137 ~105 oak_leaves[persistent=true]
setblock ~26 ~137 ~107 oak_wood
setblock ~26 ~137 ~108 oak_leaves[persistent=true]
setblock ~26 ~137 ~109 oak_wood
setblock ~26 ~137 ~110 oak_wood
setblock ~26 ~137 ~111 oak_wood
setblock ~26 ~137 ~112 oak_wood
setblock ~26 ~137 ~113 oak_leaves[persistent=true]
setblock ~26 ~137 ~114 oak_log
setblock ~26 ~137 ~115 oak_log
setblock ~26 ~137 ~116 oak_leaves[persistent=true]
setblock ~26 ~137 ~117 oak_log
setblock ~26 ~137 ~118 oak_leaves[persistent=true]
setblock ~26 ~137 ~120 oak_leaves[persistent=true]
setblock ~26 ~137 ~121 jungle_leaves[persistent=true]
setblock ~26 ~137 ~122 oak_leaves[persistent=true]
setblock ~26 ~137 ~123 oak_leaves[persistent=true]
setblock ~26 ~137 ~124 oak_leaves[persistent=true]
setblock ~26 ~137 ~125 jungle_leaves[persistent=true]
setblock ~26 ~137 ~126 oak_leaves[persistent=true]
setblock ~26 ~137 ~127 oak_leaves[persistent=true]
setblock ~26 ~138 ~78 oak_leaves[persistent=true]
setblock ~26 ~138 ~79 oak_leaves[persistent=true]
setblock ~26 ~138 ~80 jungle_leaves[persistent=true]
setblock ~26 ~138 ~81 oak_leaves[persistent=true]
setblock ~26 ~138 ~91 jungle_leaves[persistent=true]
setblock ~26 ~138 ~92 oak_leaves[persistent=true]
setblock ~26 ~138 ~93 oak_leaves[persistent=true]
setblock ~26 ~138 ~94 oak_leaves[persistent=true]
setblock ~26 ~138 ~95 jungle_leaves[persistent=true]
setblock ~26 ~138 ~96 oak_leaves[persistent=true]
setblock ~26 ~138 ~97 oak_leaves[persistent=true]
setblock ~26 ~138 ~98 oak_leaves[persistent=true]
setblock ~26 ~138 ~99 jungle_leaves[persistent=true]
setblock ~26 ~138 ~100 oak_wood
setblock ~26 ~138 ~101 oak_leaves[persistent=true]
setblock ~26 ~138 ~102 oak_leaves[persistent=true]
setblock ~26 ~138 ~103 oak_wood
setblock ~26 ~138 ~104 oak_leaves[persistent=true]
setblock ~26 ~138 ~105 oak_leaves[persistent=true]
setblock ~26 ~138 ~106 oak_leaves[persistent=true]
setblock ~26 ~138 ~107 oak_leaves[persistent=true]
setblock ~26 ~138 ~108 oak_wood
setblock ~26 ~138 ~109 oak_wood
setblock ~26 ~138 ~110 oak_wood
setblock ~26 ~138 ~111 oak_leaves[persistent=true]
setblock ~26 ~138 ~112 oak_leaves[persistent=true]
setblock ~26 ~138 ~113 oak_leaves[persistent=true]
setblock ~26 ~138 ~115 jungle_leaves[persistent=true]
setblock ~26 ~138 ~116 jungle_leaves[persistent=true]
setblock ~26 ~138 ~117 oak_leaves[persistent=true]
setblock ~26 ~138 ~118 oak_leaves[persistent=true]
setblock ~26 ~138 ~119 oak_leaves[persistent=true]
setblock ~26 ~138 ~120 oak_leaves[persistent=true]
setblock ~26 ~138 ~121 jungle_leaves[persistent=true]
setblock ~26 ~138 ~122 jungle_leaves[persistent=true]
setblock ~26 ~138 ~123 oak_leaves[persistent=true]
setblock ~26 ~138 ~124 oak_leaves[persistent=true]
setblock ~26 ~138 ~125 jungle_leaves[persistent=true]
setblock ~26 ~139 ~91 oak_leaves[persistent=true]
setblock ~26 ~139 ~92 oak_leaves[persistent=true]
setblock ~26 ~139 ~93 oak_leaves[persistent=true]
setblock ~26 ~139 ~94 oak_leaves[persistent=true]
setblock ~26 ~139 ~95 oak_leaves[persistent=true]
setblock ~26 ~139 ~96 jungle_leaves[persistent=true]
setblock ~26 ~139 ~97 oak_leaves[persistent=true]
setblock ~26 ~139 ~98 oak_leaves[persistent=true]
setblock ~26 ~139 ~99 jungle_leaves[persistent=true]
setblock ~26 ~139 ~100 oak_wood
setblock ~26 ~139 ~101 oak_leaves[persistent=true]
setblock ~26 ~139 ~102 oak_leaves[persistent=true]
setblock ~26 ~139 ~104 oak_leaves[persistent=true]
setblock ~26 ~139 ~105 jungle_leaves[persistent=true]
setblock ~26 ~139 ~106 oak_leaves[persistent=true]
setblock ~26 ~139 ~107 oak_leaves[persistent=true]
setblock ~26 ~139 ~108 jungle_leaves[persistent=true]
setblock ~26 ~139 ~109 oak_leaves[persistent=true]
setblock ~26 ~139 ~110 oak_leaves[persistent=true]
setblock ~26 ~139 ~111 jungle_leaves[persistent=true]
setblock ~26 ~139 ~112 jungle_leaves[persistent=true]
setblock ~26 ~139 ~113 oak_leaves[persistent=true]
setblock ~26 ~139 ~114 oak_leaves[persistent=true]
setblock ~26 ~139 ~115 oak_leaves[persistent=true]
setblock ~26 ~139 ~116 oak_leaves[persistent=true]
setblock ~26 ~139 ~117 oak_leaves[persistent=true]
setblock ~26 ~139 ~118 oak_leaves[persistent=true]
setblock ~26 ~139 ~119 oak_leaves[persistent=true]
setblock ~26 ~139 ~120 jungle_leaves[persistent=true]
setblock ~26 ~139 ~121 oak_leaves[persistent=true]
setblock ~26 ~139 ~122 oak_leaves[persistent=true]
setblock ~26 ~140 ~91 oak_leaves[persistent=true]
setblock ~26 ~140 ~92 oak_leaves[persistent=true]
setblock ~26 ~140 ~93 oak_leaves[persistent=true]
setblock ~26 ~140 ~95 jungle_leaves[persistent=true]
setblock ~26 ~140 ~96 oak_leaves[persistent=true]
setblock ~26 ~140 ~97 oak_leaves[persistent=true]
setblock ~26 ~140 ~99 oak_leaves[persistent=true]
setblock ~26 ~140 ~100 oak_leaves[persistent=true]
setblock ~26 ~140 ~101 oak_leaves[persistent=true]
setblock ~26 ~140 ~103 jungle_leaves[persistent=true]
setblock ~26 ~140 ~104 oak_leaves[persistent=true]
setblock ~26 ~140 ~105 jungle_leaves[persistent=true]
setblock ~26 ~140 ~106 oak_leaves[persistent=true]
setblock ~26 ~140 ~107 oak_leaves[persistent=true]
setblock ~26 ~140 ~109 jungle_leaves[persistent=true]
setblock ~26 ~140 ~111 jungle_leaves[persistent=true]
setblock ~26 ~140 ~112 oak_leaves[persistent=true]
setblock ~26 ~140 ~113 oak_leaves[persistent=true]
setblock ~26 ~140 ~115 oak_leaves[persistent=true]
setblock ~26 ~140 ~116 oak_leaves[persistent=true]
setblock ~26 ~140 ~117 jungle_leaves[persistent=true]
setblock ~26 ~140 ~118 oak_leaves[persistent=true]
setblock ~26 ~140 ~119 jungle_leaves[persistent=true]
setblock ~26 ~141 ~111 oak_leaves[persistent=true]
setblock ~26 ~141 ~113 oak_leaves[persistent=true]
setblock ~26 ~141 ~114 oak_leaves[persistent=true]
setblock ~26 ~142 ~113 oak_leaves[persistent=true]
setblock ~26 ~142 ~114 oak_leaves[persistent=true]
setblock ~27 ~117 ~117 dirt
setblock ~27 ~118 ~117 dirt
setblock ~27 ~118 ~118 dirt
setblock ~27 ~119 ~115 dirt
setblock ~27 ~119 ~116 dirt
setblock ~27 ~119 ~117 dirt
setblock ~27 ~119 ~118 dirt
setblock ~27 ~120 ~115 dirt
setblock ~27 ~120 ~116 dirt
setblock ~27 ~120 ~117 dirt
setblock ~27 ~120 ~118 dirt
setblock ~27 ~121 ~111 dirt
setblock ~27 ~121 ~112 dirt
setblock ~27 ~121 ~114 dirt
setblock ~27 ~121 ~115 dirt
setblock ~27 ~121 ~116 dirt
setblock ~27 ~121 ~117 dirt
setblock ~27 ~121 ~118 dirt
setblock ~27 ~121 ~119 dirt
setblock ~27 ~122 ~111 dirt
setblock ~27 ~122 ~112 dirt
setblock ~27 ~122 ~114 dirt
setblock ~27 ~122 ~115 dirt
setblock ~27 ~122 ~116 dirt
setblock ~27 ~122 ~117 dirt
setblock ~27 ~122 ~118 dirt
setblock ~27 ~122 ~119 dirt
setblock ~27 ~123 ~111 dirt
setblock ~27 ~123 ~112 dirt
setblock ~27 ~123 ~114 dirt
setblock ~27 ~123 ~115 dirt
setblock ~27 ~123 ~116 dirt
setblock ~27 ~123 ~117 dirt
setblock ~27 ~123 ~118 dirt
setblock ~27 ~123 ~119 grass_block
setblock ~27 ~124 ~111 grass_block
setblock ~27 ~124 ~112 grass_block
setblock ~27 ~124 ~114 grass_block
setblock ~27 ~124 ~115 grass_block
setblock ~27 ~124 ~116 spruce_slab
setblock ~27 ~124 ~117 spruce_slab
setblock ~27 ~124 ~118 spruce_slab
setblock ~27 ~124 ~119 oak_log
setblock ~27 ~125 ~110 spruce_slab
setblock ~27 ~125 ~111 oak_log
setblock ~27 ~125 ~112 oak_log
setblock ~27 ~125 ~113 oak_leaves[persistent=true]
setblock ~27 ~125 ~114 oak_leaves[persistent=true]
setblock ~27 ~125 ~115 oak_log
setblock ~27 ~125 ~116 oak_leaves[persistent=true]
setblock ~27 ~125 ~117 oak_log
setblock ~27 ~125 ~118 oak_log
setblock ~27 ~125 ~119 oak_log
setblock ~27 ~125 ~120 oak_leaves[persistent=true]
setblock ~27 ~126 ~106 oak_leaves[persistent=true]
setblock ~27 ~126 ~107 oak_leaves[persistent=true]
setblock ~27 ~126 ~108 oak_leaves[persistent=true]
setblock ~27 ~126 ~109 jungle_leaves[persistent=true]
setblock ~27 ~126 ~110 jungle_leaves[persistent=true]
setblock ~27 ~126 ~111 oak_log
setblock ~27 ~126 ~112 oak_log
setblock ~27 ~126 ~114 oak_log
setblock ~27 ~126 ~115 oak_log
setblock ~27 ~126 ~116 oak_leaves[persistent=true]
setblock ~27 ~126 ~117 oak_log
setblock ~27 ~126 ~118 oak_log
setblock ~27 ~126 ~119 oak_log
setblock ~27 ~126 ~120 oak_leaves[persistent=true]
setblock ~27 ~126 ~121 jungle_leaves[persistent=true]
setblock ~27 ~126 ~122 oak_leaves[persistent=true]
setblock ~27 ~126 ~123 jungle_leaves[persistent=true]
setblock ~27 ~126 ~124 oak_leaves[persistent=true]
setblock ~27 ~126 ~128 oak_leaves[persistent=true]
setblock ~27 ~126 ~129 oak_leaves[persistent=true]
setblock ~27 ~126 ~130 oak_leaves[persistent=true]
setblock ~27 ~126 ~131 oak_leaves[persistent=true]
setblock ~27 ~126 ~132 oak_leaves[persistent=true]
setblock ~27 ~126 ~133 oak_leaves[persistent=true]
setblock ~27 ~126 ~134 jungle_leaves[persistent=true]
setblock ~27 ~126 ~135 oak_leaves[persistent=true]
setblock ~27 ~127 ~98 jungle_leaves[persistent=true]
setblock ~27 ~127 ~99 oak_leaves[persistent=true]
setblock ~27 ~127 ~100 oak_leaves[persistent=true]
setblock ~27 ~127 ~101 jungle_leaves[persistent=true]
setblock ~27 ~127 ~102 oak_leaves[persistent=true]
setblock ~27 ~127 ~103 oak_leaves[persistent=true]
setblock ~27 ~127 ~104 oak_leaves[persistent=true]
setblock ~27 ~127 ~105 oak_leaves[persistent=true]
setblock ~27 ~127 ~106 oak_leaves[persistent=true]
setblock ~27 ~127 ~107 jungle_leaves[persistent=true]
setblock ~27 ~127 ~108 oak_leaves[persistent=true]
setblock ~27 ~127 ~109 oak_leaves[persistent=true]
setblock ~27 ~127 ~110 oak_leaves[persistent=true]
setblock ~27 ~127 ~111 oak_log
setblock ~27 ~127 ~112 oak_log
setblock ~27 ~127 ~113 oak_leaves[persistent=true]
setblock ~27 ~127 ~114 oak_log
setblock ~27 ~127 ~115 oak_log
setblock ~27 ~127 ~116 oak_wood
setblock ~27 ~127 ~117 oak_log
setblock ~27 ~127 ~118 oak_log
setblock ~27 ~127 ~119 oak_log
setblock ~27 ~127 ~120 oak_leaves[persistent=true]
setblock ~27 ~127 ~121 oak_leaves[persistent=true]
setblock ~27 ~127 ~122 oak_leaves[persistent=true]
setblock ~27 ~127 ~123 jungle_leaves[persistent=true]
setblock ~27 ~127 ~125 oak_leaves[persistent=true]
setblock ~27 ~127 ~128 jungle_leaves[persistent=true]
setblock ~27 ~127 ~129 oak_leaves[persistent=true]
setblock ~27 ~127 ~130 oak_leaves[persistent=true]
setblock ~27 ~127 ~131 oak_leaves[persistent=true]
setblock ~27 ~127 ~132 oak_leaves[persistent=true]
setblock ~27 ~127 ~133 oak_leaves[persistent=true]
setblock ~27 ~127 ~134 oak_leaves[persistent=true]
setblock ~27 ~127 ~135 oak_leaves[persistent=true]
setblock ~27 ~128 ~83 oak_leaves[persistent=true]
setblock ~27 ~128 ~84 oak_leaves[persistent=true]
setblock ~27 ~128 ~85 oak_leaves[persistent=true]
setblock ~27 ~128 ~86 jungle_leaves[persistent=true]
setblock ~27 ~128 ~96 jungle_leaves[persistent=true]
setblock ~27 ~128 ~98 oak_leaves[persistent=true]
setblock ~27 ~128 ~99 jungle_leaves[persistent=true]
setblock ~27 ~128 ~100 oak_leaves[persistent=true]
setblock ~27 ~128 ~101 jungle_leaves[persistent=true]
setblock ~27 ~128 ~102 jungle_leaves[persistent=true]
setblock ~27 ~128 ~103 oak_leaves[persistent=true]
setblock ~27 ~128 ~104 oak_leaves[persistent=true]
setblock ~27 ~128 ~105 oak_leaves[persistent=true]
setblock ~27 ~128 ~106 jungle_leaves[persistent=true]
setblock ~27 ~128 ~107 oak_leaves[persistent=true]
setblock ~27 ~128 ~108 oak_wood
setblock ~27 ~128 ~109 oak_leaves[persistent=true]
setblock ~27 ~128 ~110 oak_leaves[persistent=true]
setblock ~27 ~128 ~111 oak_log
setblock ~27 ~128 ~112 oak_log
setblock ~27 ~128 ~113 oak_leaves[persistent=true]
setblock ~27 ~128 ~114 oak_log
setblock ~27 ~128 ~115 oak_log
setblock ~27 ~128 ~116 oak_wood
setblock ~27 ~128 ~117 oak_wood
setblock ~27 ~128 ~118 oak_log
setblock ~27 ~128 ~119 oak_log
setblock ~27 ~128 ~120 oak_leaves[persistent=true]
setblock ~27 ~128 ~121 oak_leaves[persistent=true]
setblock ~27 ~128 ~122 oak_wood
setblock ~27 ~128 ~123 oak_wood
setblock ~27 ~128 ~124 oak_leaves[persistent=true]
setblock ~27 ~128 ~125 oak_leaves[persistent=true]
setblock ~27 ~128 ~128 oak_leaves[persistent=true]
setblock ~27 ~128 ~129 oak_leaves[persistent=true]
setblock ~27 ~128 ~130 oak_leaves[persistent=true]
setblock ~27 ~128 ~131 jungle_leaves[persistent=true]
setblock ~27 ~128 ~132 jungle_leaves[persistent=true]
setblock ~27 ~128 ~133 jungle_leaves[persistent=true]
setblock ~27 ~128 ~134 jungle_leaves[persistent=true]
setblock ~27 ~128 ~135 oak_leaves[persistent=true]
setblock ~27 ~129 ~83 oak_leaves[persistent=true]
setblock ~27 ~129 ~85 jungle_leaves[persistent=true]
setblock ~27 ~129 ~86 oak_leaves[persistent=true]
setblock ~27 ~129 ~87 oak_leaves[persistent=true]
setblock ~27 ~129 ~89 oak_leaves[persistent=true]
setblock ~27 ~129 ~90 jungle_leaves[persistent=true]
setblock ~27 ~129 ~91 oak_leaves[persistent=true]
setblock ~27 ~129 ~95 oak_leaves[persistent=true]
setblock ~27 ~129 ~96 jungle_leaves[persistent=true]
setblock ~27 ~129 ~97 jungle_leaves[persistent=true]
setblock ~27 ~129 ~98 oak_leaves[persistent=true]
setblock ~27 ~129 ~99 oak_leaves[persistent=true]
setblock ~27 ~129 ~100 oak_wood
setblock ~27 ~129 ~101 oak_leaves[persistent=true]
setblock ~27 ~129 ~102 jungle_leaves[persistent=true]
setblock ~27 ~129 ~104 oak_wood
setblock ~27 ~129 ~105 oak_wood
setblock ~27 ~129 ~106 oak_leaves[persistent=true]
setblock ~27 ~129 ~107 jungle_leaves[persistent=true]
setblock ~27 ~129 ~108 oak_wood
setblock ~27 ~129 ~109 oak_wood
setblock ~27 ~129 ~110 oak_leaves[persistent=true]
setblock ~27 ~129 ~111 oak_leaves[persistent=true]
setblock ~27 ~129 ~112 oak_log
setblock ~27 ~129 ~113 oak_leaves[persistent=true]
setblock ~27 ~129 ~114 oak_log
setblock ~27 ~129 ~115 oak_log
setblock ~27 ~129 ~116 oak_wood
setblock ~27 ~129 ~117 oak_wood
setblock ~27 ~129 ~118 oak_wood
setblock ~27 ~129 ~119 oak_log
setblock ~27 ~129 ~120 oak_leaves[persistent=true]
setblock ~27 ~129 ~121 oak_leaves[persistent=true]
setblock ~27 ~129 ~122 oak_leaves[persistent=true]
setblock ~27 ~129 ~123 jungle_leaves[persistent=true]
setblock ~27 ~129 ~124 oak_leaves[persistent=true]
setblock ~27 ~129 ~125 oak_leaves[persistent=true]
setblock ~27 ~129 ~126 oak_leaves[persistent=true]
setblock ~27 ~129 ~127 jungle_leaves[persistent=true]
setblock ~27 ~129 ~128 oak_leaves[persistent=true]
setblock ~27 ~129 ~129 oak_leaves[persistent=true]
setblock ~27 ~129 ~130 jungle_leaves[persistent=true]
setblock ~27 ~129 ~131 oak_leaves[persistent=true]
setblock ~27 ~129 ~132 oak_leaves[persistent=true]
setblock ~27 ~129 ~133 oak_leaves[persistent=true]
setblock ~27 ~129 ~134 oak_wood
setblock ~27 ~129 ~135 oak_leaves[persistent=true]
setblock ~27 ~130 ~83 oak_leaves[persistent=true]
setblock ~27 ~130 ~84 oak_leaves[persistent=true]
setblock ~27 ~130 ~85 oak_leaves[persistent=true]
setblock ~27 ~130 ~86 oak_leaves[persistent=true]
setblock ~27 ~130 ~87 oak_leaves[persistent=true]
setblock ~27 ~130 ~88 oak_leaves[persistent=true]
setblock ~27 ~130 ~89 oak_leaves[persistent=true]
setblock ~27 ~130 ~90 jungle_leaves[persistent=true]
setblock ~27 ~130 ~91 oak_leaves[persistent=true]
setblock ~27 ~130 ~92 oak_leaves[persistent=true]
setblock ~27 ~130 ~93 oak_leaves[persistent=true]
setblock ~27 ~130 ~94 jungle_leaves[persistent=true]
setblock ~27 ~130 ~95 oak_leaves[persistent=true]
setblock ~27 ~130 ~96 oak_leaves[persistent=true]
setblock ~27 ~130 ~97 jungle_leaves[persistent=true]
setblock ~27 ~130 ~98 oak_leaves[persistent=true]
setblock ~27 ~130 ~99 oak_leaves[persistent=true]
setblock ~27 ~130 ~101 jungle_leaves[persistent=true]
setblock ~27 ~130 ~102 oak_leaves[persistent=true]
setblock ~27 ~130 ~103 oak_leaves[persistent=true]
setblock ~27 ~130 ~104 oak_leaves[persistent=true]
setblock ~27 ~130 ~105 oak_leaves[persistent=true]
setblock ~27 ~130 ~106 oak_leaves[persistent=true]
setblock ~27 ~130 ~107 jungle_leaves[persistent=true]
setblock ~27 ~130 ~108 oak_leaves[persistent=true]
setblock ~27 ~130 ~109 oak_wood
setblock ~27 ~130 ~110 oak_wood
setblock ~27 ~130 ~111 oak_log
setblock ~27 ~130 ~112 oak_wood
setblock ~27 ~130 ~113 oak_wood
setblock ~27 ~130 ~114 oak_log
setblock ~27 ~130 ~115 oak_wood
setblock ~27 ~130 ~116 oak_wood
setblock ~27 ~130 ~117 oak_wood
setblock ~27 ~130 ~118 jungle_leaves[persistent=true]
setblock ~27 ~130 ~119 jungle_leaves[persistent=true]
setblock ~27 ~130 ~120 oak_leaves[persistent=true]
setblock ~27 ~130 ~121 oak_wood
setblock ~27 ~130 ~122 oak_wood
setblock ~27 ~130 ~123 oak_leaves[persistent=true]
setblock ~27 ~130 ~124 oak_wood
setblock ~27 ~130 ~125 oak_wood
setblock ~27 ~130 ~126 oak_leaves[persistent=true]
setblock ~27 ~130 ~127 oak_leaves[persistent=true]
setblock ~27 ~130 ~128 oak_leaves[persistent=true]
setblock ~27 ~130 ~129 oak_leaves[persistent=true]
setblock ~27 ~130 ~131 oak_wood
setblock ~27 ~130 ~132 jungle_leaves[persistent=true]
setblock ~27 ~130 ~133 oak_leaves[persistent=true]
setblock ~27 ~130 ~134 oak_leaves[persistent=true]
setblock ~27 ~130 ~135 oak_leaves[persistent=true]
setblock ~27 ~131 ~68 jungle_leaves[persistent=true]
setblock ~27 ~131 ~69 jungle_leaves[persistent=true]
setblock ~27 ~131 ~70 oak_leaves[persistent=true]
setblock ~27 ~131 ~72 oak_leaves[persistent=true]
setblock ~27 ~131 ~73 oak_leaves[persistent=true]
setblock ~27 ~131 ~74 jungle_leaves[persistent=true]
setblock ~27 ~131 ~75 oak_leaves[persistent=true]
setblock ~27 ~131 ~80 oak_leaves[persistent=true]
setblock ~27 ~131 ~81 jungle_leaves[persistent=true]
setblock ~27 ~131 ~82 jungle_leaves[persistent=true]
setblock ~27 ~131 ~83 oak_leaves[persistent=true]
setblock ~27 ~131 ~85 oak_leaves[persistent=true]
setblock ~27 ~131 ~86 jungle_leaves[persistent=true]
setblock ~27 ~131 ~87 oak_wood
setblock ~27 ~131 ~88 oak_leaves[persistent=true]
setblock ~27 ~131 ~89 oak_leaves[persistent=true]
setblock ~27 ~131 ~90 jungle_leaves[persistent=true]
setblock ~27 ~131 ~91 oak_leaves[persistent=true]
setblock ~27 ~131 ~92 oak_leaves[persistent=true]
setblock ~27 ~131 ~93 oak_leaves[persistent=true]
setblock ~27 ~131 ~94 oak_leaves[persistent=true]
setblock ~27 ~131 ~95 oak_leaves[persistent=true]
setblock ~27 ~131 ~96 jungle_leaves[persistent=true]
setblock ~27 ~131 ~97 oak_wood
setblock ~27 ~131 ~98 jungle_leaves[persistent=true]
setblock ~27 ~131 ~100 oak_leaves[persistent=true]
setblock ~27 ~131 ~101 oak_leaves[persistent=true]
setblock ~27 ~131 ~102 oak_wood
setblock ~27 ~131 ~103 oak_wood
setblock ~27 ~131 ~104 oak_leaves[persistent=true]
setblock ~27 ~131 ~105 oak_leaves[persistent=true]
setblock ~27 ~131 ~106 oak_wood
setblock ~27 ~131 ~107 oak_wood
setblock ~27 ~131 ~108 oak_leaves[persistent=true]
setblock ~27 ~131 ~109 oak_wood
setblock ~27 ~131 ~110 oak_leaves[persistent=true]
setblock ~27 ~131 ~111 oak_wood
setblock ~27 ~131 ~112 oak_wood
setblock ~27 ~131 ~113 oak_wood
setblock ~27 ~131 ~114 oak_wood
setblock ~27 ~131 ~115 oak_wood
setblock ~27 ~131 ~116 oak_leaves[persistent=true]
setblock ~27 ~131 ~117 oak_wood
setblock ~27 ~131 ~118 oak_wood
setblock ~27 ~131 ~119 oak_wood
setblock ~27 ~131 ~120 jungle_leaves[persistent=true]
setblock ~27 ~131 ~121 oak_wood
setblock ~27 ~131 ~122 oak_leaves[persistent=true]
setblock ~27 ~131 ~123 oak_leaves[persistent=true]
setblock ~27 ~131 ~124 jungle_leaves[persistent=true]
setblock ~27 ~131 ~125 oak_wood
setblock ~27 ~131 ~126 oak_leaves[persistent=true]
setblock ~27 ~131 ~127 oak_leaves[persistent=true]
setblock ~27 ~131 ~128 oak_leaves[persistent=true]
setblock ~27 ~131 ~129 oak_wood
setblock ~27 ~131 ~130 oak_leaves[persistent=true]
setblock ~27 ~131 ~131 jungle_leaves[persistent=true]
setblock ~27 ~131 ~132 jungle_leaves[persistent=true]
setblock ~27 ~132 ~68 oak_leaves[persistent=true]
setblock ~27 ~132 ~69 jungle_leaves[persistent=true]
setblock ~27 ~132 ~70 oak_leaves[persistent=true]
setblock ~27 ~132 ~71 oak_leaves[persistent=true]
setblock ~27 ~132 ~72 oak_leaves[persistent=true]
setblock ~27 ~132 ~73 oak_leaves[persistent=true]
setblock ~27 ~132 ~74 oak_leaves[persistent=true]
setblock ~27 ~132 ~75 oak_leaves[persistent=true]
setblock ~27 ~132 ~76 oak_leaves[persistent=true]
setblock ~27 ~132 ~80 oak_leaves[persistent=true]
setblock ~27 ~132 ~81 oak_leaves[persistent=true]
setblock ~27 ~132 ~82 jungle_leaves[persistent=true]
setblock ~27 ~132 ~83 oak_leaves[persistent=true]
setblock ~27 ~132 ~84 oak_leaves[persistent=true]
setblock ~27 ~132 ~85 oak_leaves[persistent=true]
setblock ~27 ~132 ~86 oak_leaves[persistent=true]
setblock ~27 ~132 ~87 oak_leaves[persistent=true]
setblock ~27 ~132 ~88 oak_leaves[persistent=true]
setblock ~27 ~132 ~89 oak_leaves[persistent=true]
setblock ~27 ~132 ~90 oak_leaves[persistent=true]
setblock ~27 ~132 ~91 oak_leaves[persistent=true]
setblock ~27 ~132 ~92 oak_wood
setblock ~27 ~132 ~93 oak_wood
setblock ~27 ~132 ~94 jungle_leaves[persistent=true]
setblock ~27 ~132 ~95 oak_leaves[persistent=true]
setblock ~27 ~132 ~96 oak_leaves[persistent=true]
setblock ~27 ~132 ~97 jungle_leaves[persistent=true]
setblock ~27 ~132 ~98 jungle_leaves[persistent=true]
setblock ~27 ~132 ~99 oak_leaves[persistent=true]
setblock ~27 ~132 ~100 jungle_leaves[persistent=true]
setblock ~27 ~132 ~101 jungle_leaves[persistent=true]
setblock ~27 ~132 ~102 oak_leaves[persistent=true]
setblock ~27 ~132 ~103 oak_wood
setblock ~27 ~132 ~104 oak_leaves[persistent=true]
setblock ~27 ~132 ~105 oak_wood
setblock ~27 ~132 ~106 oak_wood
setblock ~27 ~132 ~107 oak_leaves[persistent=true]
setblock ~27 ~132 ~108 oak_wood
setblock ~27 ~132 ~109 oak_wood
setblock ~27 ~132 ~110 oak_wood
setblock ~27 ~132 ~111 oak_wood
setblock ~27 ~132 ~112 oak_wood
setblock ~27 ~132 ~113 oak_wood
setblock ~27 ~132 ~114 oak_wood
setblock ~27 ~132 ~115 oak_wood
setblock ~27 ~132 ~116 oak_wood
setblock ~27 ~132 ~117 oak_wood
setblock ~27 ~132 ~118 oak_wood
setblock ~27 ~132 ~119 oak_wood
setblock ~27 ~132 ~120 oak_wood
setblock ~27 ~132 ~121 oak_wood
setblock ~27 ~132 ~122 oak_leaves[persistent=true]
setblock ~27 ~132 ~123 oak_wood
setblock ~27 ~132 ~124 oak_wood
setblock ~27 ~132 ~125 oak_leaves[persistent=true]
setblock ~27 ~132 ~126 oak_wood
setblock ~27 ~132 ~127 jungle_leaves[persistent=true]
setblock ~27 ~132 ~128 oak_leaves[persistent=true]
setblock ~27 ~132 ~129 oak_wood
setblock ~27 ~132 ~130 jungle_leaves[persistent=true]
setblock ~27 ~133 ~68 oak_leaves[persistent=true]
setblock ~27 ~133 ~69 oak_leaves[persistent=true]
setblock ~27 ~133 ~70 oak_leaves[persistent=true]
setblock ~27 ~133 ~71 oak_leaves[persistent=true]
setblock ~27 ~133 ~72 oak_leaves[persistent=true]
setblock ~27 ~133 ~73 oak_leaves[persistent=true]
setblock ~27 ~133 ~74 oak_leaves[persistent=true]
setblock ~27 ~133 ~75 oak_leaves[persistent=true]
setblock ~27 ~133 ~76 oak_leaves[persistent=true]
setblock ~27 ~133 ~80 oak_leaves[persistent=true]
setblock ~27 ~133 ~82 oak_leaves[persistent=true]
setblock ~27 ~133 ~83 jungle_leaves[persistent=true]
setblock ~27 ~133 ~84 oak_leaves[persistent=true]
setblock ~27 ~133 ~85 oak_leaves[persistent=true]
setblock ~27 ~133 ~86 oak_leaves[persistent=true]
setblock ~27 ~133 ~87 oak_leaves[persistent=true]
setblock ~27 ~133 ~89 jungle_leaves[persistent=true]
setblock ~27 ~133 ~90 oak_leaves[persistent=true]
setblock ~27 ~133 ~91 oak_leaves[persistent=true]
setblock ~27 ~133 ~92 oak_leaves[persistent=true]
setblock ~27 ~133 ~93 oak_wood
setblock ~27 ~133 ~94 oak_wood
setblock ~27 ~133 ~95 oak_wood
setblock ~27 ~133 ~96 oak_wood
setblock ~27 ~133 ~97 jungle_leaves[persistent=true]
setblock ~27 ~133 ~98 oak_leaves[persistent=true]
setblock ~27 ~133 ~99 oak_wood
setblock ~27 ~133 ~100 oak_leaves[persistent=true]
setblock ~27 ~133 ~101 oak_leaves[persistent=true]
setblock ~27 ~133 ~102 oak_wood
setblock ~27 ~133 ~103 oak_wood
setblock ~27 ~133 ~104 oak_wood
setblock ~27 ~133 ~105 oak_wood
setblock ~27 ~133 ~106 oak_wood
setblock ~27 ~133 ~107 oak_wood
setblock ~27 ~133 ~108 oak_wood
setblock ~27 ~133 ~109 oak_wood
setblock ~27 ~133 ~110 oak_wood
setblock ~27 ~133 ~111 oak_wood
setblock ~27 ~133 ~112 oak_leaves[persistent=true]
setblock ~27 ~133 ~113 oak_wood
setblock ~27 ~133 ~114 oak_wood
setblock ~27 ~133 ~115 oak_wood
setblock ~27 ~133 ~116 oak_wood
setblock ~27 ~133 ~117 oak_wood
setblock ~27 ~133 ~118 oak_wood
setblock ~27 ~133 ~119 oak_leaves[persistent=true]
setblock ~27 ~133 ~120 oak_wood
setblock ~27 ~133 ~121 oak_wood
setblock ~27 ~133 ~122 oak_wood
setblock ~27 ~133 ~123 oak_wood
setblock ~27 ~133 ~124 oak_leaves[persistent=true]
setblock ~27 ~133 ~125 jungle_leaves[persistent=true]
setblock ~27 ~133 ~126 jungle_leaves[persistent=true]
setblock ~27 ~133 ~127 jungle_leaves[persistent=true]
setblock ~27 ~133 ~128 oak_leaves[persistent=true]
setblock ~27 ~133 ~129 jungle_leaves[persistent=true]
setblock ~27 ~133 ~130 oak_leaves[persistent=true]
setblock ~27 ~133 ~131 oak_leaves[persistent=true]
setblock ~27 ~134 ~71 oak_leaves[persistent=true]
setblock ~27 ~134 ~72 oak_leaves[persistent=true]
setblock ~27 ~134 ~73 oak_leaves[persistent=true]
setblock ~27 ~134 ~74 oak_leaves[persistent=true]
setblock ~27 ~134 ~75 oak_leaves[persistent=true]
setblock ~27 ~134 ~76 jungle_leaves[persistent=true]
setblock ~27 ~134 ~84 oak_leaves[persistent=true]
setblock ~27 ~134 ~85 oak_leaves[persistent=true]
setblock ~27 ~134 ~86 oak_leaves[persistent=true]
setblock ~27 ~134 ~87 jungle_leaves[persistent=true]
setblock ~27 ~134 ~88 oak_leaves[persistent=true]
setblock ~27 ~134 ~89 jungle_leaves[persistent=true]
setblock ~27 ~134 ~90 jungle_leaves[persistent=true]
setblock ~27 ~134 ~91 jungle_leaves[persistent=true]
setblock ~27 ~134 ~92 oak_leaves[persistent=true]
setblock ~27 ~134 ~93 jungle_leaves[persistent=true]
setblock ~27 ~134 ~94 oak_leaves[persistent=true]
setblock ~27 ~134 ~95 oak_wood
setblock ~27 ~134 ~96 oak_wood
setblock ~27 ~134 ~97 oak_wood
setblock ~27 ~134 ~98 oak_wood
setblock ~27 ~134 ~99 oak_wood
setblock ~27 ~134 ~100 oak_wood
setblock ~27 ~134 ~101 oak_wood
setblock ~27 ~134 ~102 oak_wood
setblock ~27 ~134 ~103 oak_wood
setblock ~27 ~134 ~104 oak_wood
setblock ~27 ~134 ~105 oak_wood
setblock ~27 ~134 ~106 oak_wood
setblock ~27 ~134 ~107 oak_wood
setblock ~27 ~134 ~108 oak_wood
setblock ~27 ~134 ~109 oak_wood
setblock ~27 ~134 ~110 oak_wood
setblock ~27 ~134 ~111 oak_leaves[persistent=true]
setblock ~27 ~134 ~112 oak_wood
setblock ~27 ~134 ~113 oak_wood
setblock ~27 ~134 ~114 oak_wood
setblock ~27 ~134 ~115 oak_wood
setblock ~27 ~134 ~116 oak_leaves[persistent=true]
setblock ~27 ~134 ~117 oak_wood
setblock ~27 ~134 ~118 oak_wood
setblock ~27 ~134 ~119 oak_leaves[persistent=true]
setblock ~27 ~134 ~120 jungle_leaves[persistent=true]
setblock ~27 ~134 ~121 oak_wood
setblock ~27 ~134 ~122 jungle_leaves[persistent=true]
setblock ~27 ~134 ~123 oak_wood
setblock ~27 ~134 ~124 oak_log
setblock ~27 ~134 ~126 oak_wood
setblock ~27 ~134 ~127 jungle_leaves[persistent=true]
setblock ~27 ~134 ~128 oak_leaves[persistent=true]
setblock ~27 ~134 ~129 oak_leaves[persistent=true]
setblock ~27 ~134 ~130 oak_wood
setblock ~27 ~134 ~131 oak_leaves[persistent=true]
setblock ~27 ~135 ~72 jungle_leaves[persistent=true]
setblock ~27 ~135 ~73 oak_leaves[persistent=true]
setblock ~27 ~135 ~74 jungle_leaves[persistent=true]
setblock ~27 ~135 ~78 oak_leaves[persistent=true]
setblock ~27 ~135 ~79 oak_leaves[persistent=true]
setblock ~27 ~135 ~80 oak_leaves[persistent=true]
setblock ~27 ~135 ~81 jungle_leaves[persistent=true]
setblock ~27 ~135 ~83 jungle_leaves[persistent=true]
setblock ~27 ~135 ~84 oak_wood
setblock ~27 ~135 ~85 oak_wood
setblock ~27 ~135 ~87 jungle_leaves[persistent=true]
setblock ~27 ~135 ~88 oak_leaves[persistent=true]
setblock ~27 ~135 ~89 oak_leaves[persistent=true]
setblock ~27 ~135 ~90 oak_leaves[persistent=true]
setblock ~27 ~135 ~91 jungle_leaves[persistent=true]
setblock ~27 ~135 ~92 jungle_leaves[persistent=true]
setblock ~27 ~135 ~93 oak_wood
setblock ~27 ~135 ~94 oak_leaves[persistent=true]
setblock ~27 ~135 ~95 oak_leaves[persistent=true]
setblock ~27 ~135 ~96 oak_wood
setblock ~27 ~135 ~97 oak_wood
setblock ~27 ~135 ~98 oak_wood
setblock ~27 ~135 ~99 jungle_leaves[persistent=true]
setblock ~27 ~135 ~100 oak_wood
setblock ~27 ~135 ~101 oak_wood
setblock ~27 ~135 ~102 oak_wood
setblock ~27 ~135 ~103 oak_wood
setblock ~27 ~135 ~104 oak_wood
setblock ~27 ~135 ~105 oak_wood
setblock ~27 ~135 ~106 oak_wood
setblock ~27 ~135 ~107 jungle_leaves[persistent=true]
setblock ~27 ~135 ~108 oak_wood
setblock ~27 ~135 ~109 oak_wood
setblock ~27 ~135 ~110 oak_wood
setblock ~27 ~135 ~111 oak_wood
setblock ~27 ~135 ~112 oak_wood
setblock ~27 ~135 ~113 oak_log
setblock ~27 ~135 ~114 oak_wood
setblock ~27 ~135 ~115 oak_wood
setblock ~27 ~135 ~116 oak_wood
setblock ~27 ~135 ~117 oak_log
setblock ~27 ~135 ~118 oak_wood
setblock ~27 ~135 ~119 oak_log
setblock ~27 ~135 ~120 oak_leaves[persistent=true]
setblock ~27 ~135 ~121 oak_wood
setblock ~27 ~135 ~122 oak_leaves[persistent=true]
setblock ~27 ~135 ~123 jungle_leaves[persistent=true]
setblock ~27 ~135 ~125 oak_log
setblock ~27 ~135 ~127 oak_wood
setblock ~27 ~135 ~128 oak_leaves[persistent=true]
setblock ~27 ~135 ~129 oak_leaves[persistent=true]
setblock ~27 ~135 ~130 jungle_leaves[persistent=true]
setblock ~27 ~136 ~71 oak_leaves[persistent=true]
setblock ~27 ~136 ~72 oak_leaves[persistent=true]
setblock ~27 ~136 ~73 oak_leaves[persistent=true]
