setblock ~172 ~120 ~118 dirt
setblock ~172 ~120 ~119 dirt
setblock ~172 ~120 ~120 dirt
setblock ~172 ~120 ~121 dirt
setblock ~172 ~120 ~122 dirt
setblock ~172 ~120 ~123 dirt
setblock ~172 ~120 ~124 dirt
setblock ~172 ~120 ~125 dirt
setblock ~172 ~120 ~127 dirt
setblock ~172 ~121 ~92 dirt
setblock ~172 ~121 ~93 dirt
setblock ~172 ~121 ~94 dirt
setblock ~172 ~121 ~95 dirt
setblock ~172 ~121 ~96 dirt
setblock ~172 ~121 ~97 dirt
setblock ~172 ~121 ~98 dirt
setblock ~172 ~121 ~99 dirt
setblock ~172 ~121 ~100 dirt
setblock ~172 ~121 ~101 dirt
setblock ~172 ~121 ~102 dirt
setblock ~172 ~121 ~103 dirt
setblock ~172 ~121 ~104 dirt
setblock ~172 ~121 ~105 dirt
setblock ~172 ~121 ~106 dirt
setblock ~172 ~121 ~107 dirt
setblock ~172 ~121 ~108 dirt
setblock ~172 ~121 ~109 dirt
setblock ~172 ~121 ~110 dirt
setblock ~172 ~121 ~111 dirt
setblock ~172 ~121 ~112 dirt
setblock ~172 ~121 ~113 dirt
setblock ~172 ~121 ~114 dirt
setblock ~172 ~121 ~115 dirt
setblock ~172 ~121 ~116 dirt
setblock ~172 ~121 ~117 dirt
setblock ~172 ~121 ~118 dirt
setblock ~172 ~121 ~119 dirt
setblock ~172 ~121 ~120 dirt
setblock ~172 ~121 ~121 dirt
setblock ~172 ~121 ~122 dirt
setblock ~172 ~121 ~123 dirt
setblock ~172 ~121 ~124 dirt
setblock ~172 ~121 ~125 dirt
setblock ~172 ~121 ~127 dirt
setblock ~172 ~122 ~92 dirt
setblock ~172 ~122 ~93 dirt
setblock ~172 ~122 ~94 dirt
setblock ~172 ~122 ~95 dirt
setblock ~172 ~122 ~96 dirt
setblock ~172 ~122 ~97 dirt
setblock ~172 ~122 ~98 dirt
setblock ~172 ~122 ~99 dirt
setblock ~172 ~122 ~100 dirt
setblock ~172 ~122 ~101 dirt
setblock ~172 ~122 ~102 dirt
setblock ~172 ~122 ~103 dirt
setblock ~172 ~122 ~104 dirt
setblock ~172 ~122 ~105 dirt
setblock ~172 ~122 ~106 dirt
setblock ~172 ~122 ~107 dirt
setblock ~172 ~122 ~108 dirt
setblock ~172 ~122 ~109 dirt
setblock ~172 ~122 ~110 dirt
setblock ~172 ~122 ~111 dirt
setblock ~172 ~122 ~112 dirt
setblock ~172 ~122 ~113 dirt
setblock ~172 ~122 ~114 dirt
setblock ~172 ~122 ~115 dirt
setblock ~172 ~122 ~116 dirt
setblock ~172 ~122 ~117 dirt
setblock ~172 ~122 ~118 dirt
setblock ~172 ~122 ~119 dirt
setblock ~172 ~122 ~120 dirt
setblock ~172 ~122 ~121 dirt
setblock ~172 ~122 ~122 dirt
setblock ~172 ~122 ~123 dirt
setblock ~172 ~122 ~124 dirt
setblock ~172 ~122 ~125 dirt
setblock ~172 ~122 ~127 dirt
setblock ~172 ~123 ~92 dirt
setblock ~172 ~123 ~93 dirt
setblock ~172 ~123 ~94 dirt
setblock ~172 ~123 ~95 dirt
setblock ~172 ~123 ~96 dirt
setblock ~172 ~123 ~97 dirt
setblock ~172 ~123 ~98 dirt
setblock ~172 ~123 ~99 dirt
setblock ~172 ~123 ~100 dirt
setblock ~172 ~123 ~101 dirt
setblock ~172 ~123 ~102 dirt
setblock ~172 ~123 ~103 dirt
setblock ~172 ~123 ~104 dirt
setblock ~172 ~123 ~105 dirt
setblock ~172 ~123 ~106 dirt
setblock ~172 ~123 ~107 dirt
setblock ~172 ~123 ~108 grass_block
setblock ~172 ~123 ~109 grass_block
setblock ~172 ~123 ~110 grass_block
setblock ~172 ~123 ~111 grass_block
setblock ~172 ~123 ~112 grass_block
setblock ~172 ~123 ~113 grass_block
setblock ~172 ~123 ~114 grass_block
setblock ~172 ~123 ~115 grass_block
setblock ~172 ~123 ~116 grass_block
setblock ~172 ~123 ~117 grass_block
setblock ~172 ~123 ~118 grass_block
setblock ~172 ~123 ~119 dirt
setblock ~172 ~123 ~120 dirt
setblock ~172 ~123 ~121 dirt
setblock ~172 ~123 ~122 dirt
setblock ~172 ~123 ~123 dirt
setblock ~172 ~123 ~124 dirt
setblock ~172 ~123 ~125 dirt
setblock ~172 ~123 ~127 dirt
setblock ~172 ~124 ~92 dirt
setblock ~172 ~124 ~93 dirt
setblock ~172 ~124 ~94 dirt
setblock ~172 ~124 ~95 dirt
setblock ~172 ~124 ~96 dirt
setblock ~172 ~124 ~97 dirt
setblock ~172 ~124 ~98 dirt
setblock ~172 ~124 ~99 dirt
setblock ~172 ~124 ~100 dirt
setblock ~172 ~124 ~101 dirt
setblock ~172 ~124 ~102 dirt
setblock ~172 ~124 ~103 dirt
setblock ~172 ~124 ~104 dirt
setblock ~172 ~124 ~105 grass_block
setblock ~172 ~124 ~106 grass_block
setblock ~172 ~124 ~107 grass_block
setblock ~172 ~124 ~109 short_grass
setblock ~172 ~124 ~112 short_grass
setblock ~172 ~124 ~119 grass_block
setblock ~172 ~124 ~120 grass_block
setblock ~172 ~124 ~121 grass_block
setblock ~172 ~124 ~122 grass_block
setblock ~172 ~124 ~123 grass_block
setblock ~172 ~124 ~124 dirt
setblock ~172 ~124 ~125 dirt
setblock ~172 ~124 ~127 dirt
setblock ~172 ~125 ~92 dirt
setblock ~172 ~125 ~93 dirt
setblock ~172 ~125 ~94 dirt
setblock ~172 ~125 ~95 dirt
setblock ~172 ~125 ~96 dirt
setblock ~172 ~125 ~97 dirt
setblock ~172 ~125 ~98 dirt
setblock ~172 ~125 ~99 dirt
setblock ~172 ~125 ~100 dirt
setblock ~172 ~125 ~101 dirt
setblock ~172 ~125 ~102 grass_block
setblock ~172 ~125 ~103 grass_block
setblock ~172 ~125 ~104 grass_block
setblock ~172 ~125 ~120 short_grass
setblock ~172 ~125 ~121 short_grass
setblock ~172 ~125 ~124 grass_block
setblock ~172 ~125 ~125 grass_block
setblock ~172 ~125 ~127 dirt
setblock ~172 ~126 ~92 dirt
setblock ~172 ~126 ~93 dirt
setblock ~172 ~126 ~94 dirt
setblock ~172 ~126 ~95 grass_block
setblock ~172 ~126 ~96 grass_block
setblock ~172 ~126 ~97 grass_block
setblock ~172 ~126 ~98 grass_block
setblock ~172 ~126 ~99 grass_block
setblock ~172 ~126 ~100 grass_block
setblock ~172 ~126 ~101 grass_block
setblock ~172 ~126 ~102 short_grass
setblock ~172 ~126 ~103 short_grass
setblock ~172 ~126 ~104 short_grass
setblock ~172 ~126 ~127 grass_block
setblock ~172 ~127 ~92 grass_block
setblock ~172 ~127 ~93 grass_block
setblock ~172 ~127 ~94 grass_block
setblock ~172 ~128 ~92 short_grass
setblock ~173 ~110 ~102 dirt
setblock ~173 ~111 ~102 dirt
setblock ~173 ~112 ~102 dirt
setblock ~173 ~112 ~103 dirt
setblock ~173 ~113 ~102 dirt
setblock ~173 ~113 ~103 dirt
setblock ~173 ~114 ~99 dirt
setblock ~173 ~114 ~100 dirt
setblock ~173 ~114 ~101 dirt
setblock ~173 ~114 ~102 dirt
setblock ~173 ~114 ~103 dirt
setblock ~173 ~114 ~104 dirt
setblock ~173 ~115 ~97 dirt
setblock ~173 ~115 ~98 dirt
setblock ~173 ~115 ~99 dirt
setblock ~173 ~115 ~100 dirt
setblock ~173 ~115 ~101 dirt
setblock ~173 ~115 ~102 dirt
setblock ~173 ~115 ~103 dirt
setblock ~173 ~115 ~104 dirt
setblock ~173 ~116 ~97 dirt
setblock ~173 ~116 ~98 dirt
setblock ~173 ~116 ~99 dirt
setblock ~173 ~116 ~100 dirt
setblock ~173 ~116 ~101 dirt
setblock ~173 ~116 ~102 dirt
setblock ~173 ~116 ~103 dirt
setblock ~173 ~116 ~104 dirt
setblock ~173 ~116 ~105 dirt
setblock ~173 ~117 ~95 dirt
setblock ~173 ~117 ~96 dirt
setblock ~173 ~117 ~97 dirt
setblock ~173 ~117 ~98 dirt
setblock ~173 ~117 ~99 dirt
setblock ~173 ~117 ~100 dirt
setblock ~173 ~117 ~101 dirt
setblock ~173 ~117 ~102 dirt
setblock ~173 ~117 ~103 dirt
setblock ~173 ~117 ~104 dirt
setblock ~173 ~117 ~105 dirt
setblock ~173 ~117 ~106 dirt
setblock ~173 ~117 ~121 dirt
setblock ~173 ~118 ~95 dirt
setblock ~173 ~118 ~96 dirt
setblock ~173 ~118 ~97 dirt
setblock ~173 ~118 ~98 dirt
setblock ~173 ~118 ~99 dirt
setblock ~173 ~118 ~100 dirt
setblock ~173 ~118 ~101 dirt
setblock ~173 ~118 ~102 dirt
setblock ~173 ~118 ~103 dirt
setblock ~173 ~118 ~104 dirt
setblock ~173 ~118 ~105 dirt
setblock ~173 ~118 ~106 dirt
setblock ~173 ~118 ~118 dirt
setblock ~173 ~118 ~120 dirt
setblock ~173 ~118 ~121 dirt
setblock ~173 ~118 ~122 dirt
setblock ~173 ~119 ~95 dirt
setblock ~173 ~119 ~96 dirt
setblock ~173 ~119 ~97 dirt
setblock ~173 ~119 ~98 dirt
setblock ~173 ~119 ~99 dirt
setblock ~173 ~119 ~100 dirt
setblock ~173 ~119 ~101 dirt
setblock ~173 ~119 ~102 dirt
setblock ~173 ~119 ~103 dirt
setblock ~173 ~119 ~104 dirt
setblock ~173 ~119 ~105 dirt
setblock ~173 ~119 ~106 dirt
setblock ~173 ~119 ~107 dirt
setblock ~173 ~119 ~118 dirt
setblock ~173 ~119 ~119 dirt
setblock ~173 ~119 ~120 dirt
setblock ~173 ~119 ~121 dirt
setblock ~173 ~119 ~122 dirt
setblock ~173 ~120 ~94 dirt
setblock ~173 ~120 ~95 dirt
setblock ~173 ~120 ~96 dirt
setblock ~173 ~120 ~97 dirt
setblock ~173 ~120 ~98 dirt
setblock ~173 ~120 ~99 dirt
setblock ~173 ~120 ~100 dirt
setblock ~173 ~120 ~101 dirt
setblock ~173 ~120 ~102 dirt
setblock ~173 ~120 ~103 dirt
setblock ~173 ~120 ~104 dirt
setblock ~173 ~120 ~105 dirt
setblock ~173 ~120 ~106 dirt
setblock ~173 ~120 ~107 dirt
setblock ~173 ~120 ~108 dirt
setblock ~173 ~120 ~111 dirt
setblock ~173 ~120 ~112 dirt
setblock ~173 ~120 ~117 dirt
setblock ~173 ~120 ~118 dirt
setblock ~173 ~120 ~119 dirt
setblock ~173 ~120 ~120 dirt
setblock ~173 ~120 ~121 dirt
setblock ~173 ~120 ~122 dirt
setblock ~173 ~120 ~123 dirt
setblock ~173 ~120 ~124 dirt
setblock ~173 ~121 ~93 dirt
setblock ~173 ~121 ~94 dirt
setblock ~173 ~121 ~95 dirt
setblock ~173 ~121 ~96 dirt
setblock ~173 ~121 ~97 dirt
setblock ~173 ~121 ~98 dirt
setblock ~173 ~121 ~99 dirt
setblock ~173 ~121 ~100 dirt
setblock ~173 ~121 ~101 dirt
setblock ~173 ~121 ~102 dirt
setblock ~173 ~121 ~103 dirt
setblock ~173 ~121 ~104 dirt
setblock ~173 ~121 ~105 dirt
setblock ~173 ~121 ~106 dirt
setblock ~173 ~121 ~107 dirt
setblock ~173 ~121 ~108 dirt
setblock ~173 ~121 ~109 dirt
setblock ~173 ~121 ~110 dirt
setblock ~173 ~121 ~111 dirt
setblock ~173 ~121 ~112 dirt
setblock ~173 ~121 ~113 dirt
setblock ~173 ~121 ~115 dirt
setblock ~173 ~121 ~116 dirt
setblock ~173 ~121 ~117 dirt
setblock ~173 ~121 ~118 dirt
setblock ~173 ~121 ~119 dirt
setblock ~173 ~121 ~120 dirt
setblock ~173 ~121 ~121 dirt
setblock ~173 ~121 ~122 dirt
setblock ~173 ~121 ~123 dirt
setblock ~173 ~121 ~124 dirt
setblock ~173 ~121 ~125 dirt
setblock ~173 ~122 ~93 dirt
setblock ~173 ~122 ~94 dirt
setblock ~173 ~122 ~95 dirt
setblock ~173 ~122 ~96 dirt
setblock ~173 ~122 ~97 dirt
setblock ~173 ~122 ~98 dirt
setblock ~173 ~122 ~99 dirt
setblock ~173 ~122 ~100 dirt
setblock ~173 ~122 ~101 dirt
setblock ~173 ~122 ~102 dirt
setblock ~173 ~122 ~103 dirt
setblock ~173 ~122 ~104 dirt
setblock ~173 ~122 ~105 dirt
setblock ~173 ~122 ~106 dirt
setblock ~173 ~122 ~107 dirt
setblock ~173 ~122 ~108 dirt
setblock ~173 ~122 ~109 dirt
setblock ~173 ~122 ~110 dirt
setblock ~173 ~122 ~111 dirt
setblock ~173 ~122 ~112 dirt
setblock ~173 ~122 ~113 dirt
setblock ~173 ~122 ~115 dirt
setblock ~173 ~122 ~116 dirt
setblock ~173 ~122 ~117 dirt
setblock ~173 ~122 ~118 dirt
setblock ~173 ~122 ~119 dirt
setblock ~173 ~122 ~120 dirt
setblock ~173 ~122 ~121 dirt
setblock ~173 ~122 ~122 dirt
setblock ~173 ~122 ~123 dirt
setblock ~173 ~122 ~124 dirt
setblock ~173 ~122 ~125 dirt
setblock ~173 ~123 ~93 dirt
setblock ~173 ~123 ~94 dirt
setblock ~173 ~123 ~95 dirt
setblock ~173 ~123 ~96 dirt
setblock ~173 ~123 ~97 dirt
setblock ~173 ~123 ~98 dirt
setblock ~173 ~123 ~99 dirt
setblock ~173 ~123 ~100 dirt
setblock ~173 ~123 ~101 dirt
setblock ~173 ~123 ~102 dirt
setblock ~173 ~123 ~103 dirt
setblock ~173 ~123 ~104 dirt
setblock ~173 ~123 ~105 dirt
setblock ~173 ~123 ~106 dirt
setblock ~173 ~123 ~107 dirt
setblock ~173 ~123 ~108 grass_block
setblock ~173 ~123 ~109 grass_block
setblock ~173 ~123 ~110 grass_block
setblock ~173 ~123 ~111 grass_block
setblock ~173 ~123 ~112 grass_block
setblock ~173 ~123 ~113 grass_block
setblock ~173 ~123 ~115 grass_block
setblock ~173 ~123 ~116 grass_block
setblock ~173 ~123 ~117 dirt
setblock ~173 ~123 ~118 dirt
setblock ~173 ~123 ~119 dirt
setblock ~173 ~123 ~120 dirt
setblock ~173 ~123 ~121 dirt
setblock ~173 ~123 ~122 dirt
setblock ~173 ~123 ~123 dirt
setblock ~173 ~123 ~124 dirt
setblock ~173 ~123 ~125 dirt
setblock ~173 ~124 ~93 dirt
setblock ~173 ~124 ~94 dirt
setblock ~173 ~124 ~95 dirt
setblock ~173 ~124 ~96 dirt
setblock ~173 ~124 ~97 dirt
setblock ~173 ~124 ~98 dirt
setblock ~173 ~124 ~99 dirt
setblock ~173 ~124 ~100 dirt
setblock ~173 ~124 ~101 dirt
setblock ~173 ~124 ~102 dirt
setblock ~173 ~124 ~103 dirt
setblock ~173 ~124 ~104 dirt
setblock ~173 ~124 ~105 grass_block
setblock ~173 ~124 ~106 grass_block
setblock ~173 ~124 ~107 grass_block
setblock ~173 ~124 ~108 short_grass
setblock ~173 ~124 ~109 short_grass
setblock ~173 ~124 ~112 short_grass
setblock ~173 ~124 ~113 short_grass
setblock ~173 ~124 ~117 grass_block
setblock ~173 ~124 ~118 grass_block
setblock ~173 ~124 ~119 grass_block
setblock ~173 ~124 ~120 grass_block
setblock ~173 ~124 ~121 grass_block
setblock ~173 ~124 ~122 grass_block
setblock ~173 ~124 ~123 dirt
setblock ~173 ~124 ~124 dirt
setblock ~173 ~124 ~125 dirt
setblock ~173 ~125 ~93 dirt
setblock ~173 ~125 ~94 dirt
setblock ~173 ~125 ~95 dirt
setblock ~173 ~125 ~96 dirt
setblock ~173 ~125 ~97 dirt
setblock ~173 ~125 ~98 dirt
setblock ~173 ~125 ~99 dirt
setblock ~173 ~125 ~100 dirt
setblock ~173 ~125 ~101 dirt
setblock ~173 ~125 ~102 grass_block
setblock ~173 ~125 ~103 grass_block
setblock ~173 ~125 ~104 grass_block
setblock ~173 ~125 ~105 short_grass
setblock ~173 ~125 ~123 grass_block
setblock ~173 ~125 ~124 grass_block
setblock ~173 ~125 ~125 grass_block
setblock ~173 ~126 ~93 dirt
setblock ~173 ~126 ~94 grass_block
setblock ~173 ~126 ~95 grass_block
setblock ~173 ~126 ~96 grass_block
setblock ~173 ~126 ~97 grass_block
setblock ~173 ~126 ~98 grass_block
setblock ~173 ~126 ~99 grass_block
setblock ~173 ~126 ~100 grass_block
setblock ~173 ~126 ~101 grass_block
setblock ~173 ~126 ~102 short_grass
setblock ~173 ~126 ~104 short_grass
setblock ~173 ~126 ~124 short_grass
setblock ~173 ~127 ~93 grass_block
setblock ~173 ~127 ~97 poppy
setblock ~173 ~127 ~98 short_grass
setblock ~174 ~114 ~102 dirt
setblock ~174 ~114 ~103 dirt
setblock ~174 ~115 ~101 dirt
setblock ~174 ~115 ~102 dirt
setblock ~174 ~115 ~103 dirt
setblock ~174 ~115 ~104 dirt
setblock ~174 ~116 ~99 dirt
setblock ~174 ~116 ~100 dirt
setblock ~174 ~116 ~101 dirt
setblock ~174 ~116 ~102 dirt
setblock ~174 ~116 ~103 dirt
setblock ~174 ~116 ~104 dirt
setblock ~174 ~117 ~97 dirt
setblock ~174 ~117 ~98 dirt
setblock ~174 ~117 ~99 dirt
setblock ~174 ~117 ~100 dirt
setblock ~174 ~117 ~101 dirt
setblock ~174 ~117 ~102 dirt
setblock ~174 ~117 ~103 dirt
setblock ~174 ~117 ~104 dirt
setblock ~174 ~117 ~105 dirt
setblock ~174 ~118 ~96 dirt
setblock ~174 ~118 ~97 dirt
setblock ~174 ~118 ~98 dirt
setblock ~174 ~118 ~99 dirt
setblock ~174 ~118 ~100 dirt
setblock ~174 ~118 ~101 dirt
setblock ~174 ~118 ~102 dirt
setblock ~174 ~118 ~103 dirt
setblock ~174 ~118 ~104 dirt
setblock ~174 ~118 ~105 dirt
setblock ~174 ~119 ~95 dirt
setblock ~174 ~119 ~96 dirt
setblock ~174 ~119 ~97 dirt
setblock ~174 ~119 ~98 dirt
setblock ~174 ~119 ~99 dirt
setblock ~174 ~119 ~100 dirt
setblock ~174 ~119 ~101 dirt
setblock ~174 ~119 ~102 dirt
setblock ~174 ~119 ~103 dirt
setblock ~174 ~119 ~104 dirt
setblock ~174 ~119 ~105 dirt
setblock ~174 ~119 ~106 dirt
setblock ~174 ~120 ~94 dirt
setblock ~174 ~120 ~95 dirt
setblock ~174 ~120 ~96 dirt
setblock ~174 ~120 ~97 dirt
setblock ~174 ~120 ~98 dirt
setblock ~174 ~120 ~99 dirt
setblock ~174 ~120 ~100 dirt
setblock ~174 ~120 ~101 dirt
setblock ~174 ~120 ~102 dirt
setblock ~174 ~120 ~103 dirt
setblock ~174 ~120 ~104 dirt
setblock ~174 ~120 ~105 dirt
setblock ~174 ~120 ~106 dirt
setblock ~174 ~120 ~118 dirt
setblock ~174 ~120 ~119 dirt
setblock ~174 ~120 ~120 dirt
setblock ~174 ~120 ~121 dirt
setblock ~174 ~121 ~94 dirt
setblock ~174 ~121 ~95 dirt
setblock ~174 ~121 ~96 dirt
setblock ~174 ~121 ~97 dirt
setblock ~174 ~121 ~98 dirt
setblock ~174 ~121 ~99 dirt
setblock ~174 ~121 ~100 dirt
setblock ~174 ~121 ~101 dirt
setblock ~174 ~121 ~102 dirt
setblock ~174 ~121 ~103 dirt
setblock ~174 ~121 ~104 dirt
setblock ~174 ~121 ~105 dirt
setblock ~174 ~121 ~106 dirt
setblock ~174 ~121 ~107 dirt
setblock ~174 ~121 ~108 dirt
setblock ~174 ~121 ~118 dirt
setblock ~174 ~121 ~119 dirt
setblock ~174 ~121 ~120 dirt
setblock ~174 ~121 ~121 dirt
setblock ~174 ~121 ~122 dirt
setblock ~174 ~121 ~124 dirt
setblock ~174 ~122 ~94 dirt
setblock ~174 ~122 ~95 dirt
setblock ~174 ~122 ~96 dirt
setblock ~174 ~122 ~97 dirt
setblock ~174 ~122 ~98 dirt
setblock ~174 ~122 ~99 dirt
setblock ~174 ~122 ~100 dirt
setblock ~174 ~122 ~101 dirt
setblock ~174 ~122 ~102 dirt
setblock ~174 ~122 ~103 dirt
setblock ~174 ~122 ~104 dirt
setblock ~174 ~122 ~105 dirt
setblock ~174 ~122 ~106 dirt
setblock ~174 ~122 ~107 dirt
setblock ~174 ~122 ~108 dirt
setblock ~174 ~122 ~118 dirt
setblock ~174 ~122 ~119 dirt
setblock ~174 ~122 ~120 dirt
setblock ~174 ~122 ~121 dirt
setblock ~174 ~122 ~122 dirt
setblock ~174 ~122 ~124 dirt
setblock ~174 ~123 ~94 dirt
setblock ~174 ~123 ~95 dirt
setblock ~174 ~123 ~96 dirt
setblock ~174 ~123 ~97 dirt
setblock ~174 ~123 ~98 dirt
setblock ~174 ~123 ~99 dirt
setblock ~174 ~123 ~100 dirt
setblock ~174 ~123 ~101 dirt
setblock ~174 ~123 ~102 dirt
setblock ~174 ~123 ~103 dirt
setblock ~174 ~123 ~104 dirt
setblock ~174 ~123 ~105 dirt
setblock ~174 ~123 ~106 dirt
setblock ~174 ~123 ~107 dirt
setblock ~174 ~123 ~108 grass_block
setblock ~174 ~123 ~118 dirt
setblock ~174 ~123 ~119 dirt
setblock ~174 ~123 ~120 dirt
setblock ~174 ~123 ~121 dirt
setblock ~174 ~123 ~122 dirt
setblock ~174 ~123 ~124 dirt
setblock ~174 ~124 ~94 dirt
setblock ~174 ~124 ~95 dirt
setblock ~174 ~124 ~96 dirt
setblock ~174 ~124 ~97 dirt
setblock ~174 ~124 ~98 dirt
setblock ~174 ~124 ~99 dirt
setblock ~174 ~124 ~100 dirt
setblock ~174 ~124 ~101 dirt
setblock ~174 ~124 ~102 dirt
setblock ~174 ~124 ~103 dirt
setblock ~174 ~124 ~104 dirt
setblock ~174 ~124 ~105 grass_block
setblock ~174 ~124 ~106 grass_block
setblock ~174 ~124 ~107 grass_block
setblock ~174 ~124 ~108 short_grass
setblock ~174 ~124 ~118 grass_block
setblock ~174 ~124 ~119 grass_block
setblock ~174 ~124 ~120 grass_block
setblock ~174 ~124 ~121 grass_block
setblock ~174 ~124 ~122 dirt
setblock ~174 ~124 ~124 dirt
setblock ~174 ~125 ~94 dirt
setblock ~174 ~125 ~95 dirt
setblock ~174 ~125 ~96 dirt
setblock ~174 ~125 ~97 dirt
setblock ~174 ~125 ~98 dirt
setblock ~174 ~125 ~99 dirt
setblock ~174 ~125 ~100 dirt
setblock ~174 ~125 ~101 grass_block
setblock ~174 ~125 ~102 grass_block
setblock ~174 ~125 ~103 grass_block
setblock ~174 ~125 ~104 grass_block
setblock ~174 ~125 ~120 short_grass
setblock ~174 ~125 ~122 grass_block
setblock ~174 ~125 ~124 grass_block
setblock ~174 ~126 ~94 grass_block
setblock ~174 ~126 ~95 grass_block
setblock ~174 ~126 ~96 grass_block
setblock ~174 ~126 ~97 grass_block
setblock ~174 ~126 ~98 grass_block
setblock ~174 ~126 ~99 grass_block
setblock ~174 ~126 ~100 grass_block
setblock ~174 ~126 ~103 fern
setblock ~174 ~126 ~122 fern
setblock ~174 ~126 ~124 poppy
setblock ~174 ~127 ~95 short_grass
setblock ~174 ~127 ~98 fern
setblock ~175 ~115 ~103 dirt
setblock ~175 ~116 ~101 dirt
setblock ~175 ~116 ~103 dirt
setblock ~175 ~117 ~101 dirt
setblock ~175 ~117 ~103 dirt
setblock ~175 ~118 ~98 dirt
setblock ~175 ~118 ~101 dirt
setblock ~175 ~118 ~102 dirt
setblock ~175 ~118 ~103 dirt
setblock ~175 ~119 ~96 dirt
setblock ~175 ~119 ~98 dirt
setblock ~175 ~119 ~101 dirt
setblock ~175 ~119 ~102 dirt
setblock ~175 ~119 ~103 dirt
setblock ~175 ~119 ~104 dirt
setblock ~175 ~119 ~105 dirt
setblock ~175 ~120 ~95 dirt
setblock ~175 ~120 ~96 dirt
setblock ~175 ~120 ~97 dirt
setblock ~175 ~120 ~98 dirt
setblock ~175 ~120 ~99 dirt
setblock ~175 ~120 ~100 dirt
setblock ~175 ~120 ~101 dirt
setblock ~175 ~120 ~102 dirt
setblock ~175 ~120 ~103 dirt
setblock ~175 ~120 ~104 dirt
setblock ~175 ~120 ~105 dirt
setblock ~175 ~121 ~95 dirt
setblock ~175 ~121 ~96 dirt
setblock ~175 ~121 ~97 dirt
setblock ~175 ~121 ~98 dirt
setblock ~175 ~121 ~99 dirt
setblock ~175 ~121 ~100 dirt
setblock ~175 ~121 ~101 dirt
setblock ~175 ~121 ~102 dirt
setblock ~175 ~121 ~103 dirt
setblock ~175 ~121 ~104 dirt
setblock ~175 ~121 ~105 dirt
setblock ~175 ~122 ~95 dirt
setblock ~175 ~122 ~96 dirt
setblock ~175 ~122 ~97 dirt
setblock ~175 ~122 ~98 dirt
setblock ~175 ~122 ~99 dirt
setblock ~175 ~122 ~100 dirt
setblock ~175 ~122 ~101 dirt
setblock ~175 ~122 ~102 dirt
setblock ~175 ~122 ~103 dirt
setblock ~175 ~122 ~104 dirt
setblock ~175 ~122 ~105 dirt
setblock ~175 ~123 ~95 dirt
setblock ~175 ~123 ~96 dirt
setblock ~175 ~123 ~97 dirt
setblock ~175 ~123 ~98 dirt
setblock ~175 ~123 ~99 dirt
setblock ~175 ~123 ~100 dirt
setblock ~175 ~123 ~101 dirt
setblock ~175 ~123 ~102 dirt
setblock ~175 ~123 ~103 dirt
setblock ~175 ~123 ~104 dirt
setblock ~175 ~123 ~105 dirt
setblock ~175 ~124 ~95 dirt
setblock ~175 ~124 ~96 dirt
setblock ~175 ~124 ~97 dirt
setblock ~175 ~124 ~98 dirt
setblock ~175 ~124 ~99 dirt
setblock ~175 ~124 ~100 dirt
setblock ~175 ~124 ~101 dirt
setblock ~175 ~124 ~102 dirt
setblock ~175 ~124 ~103 dirt
setblock ~175 ~124 ~104 dirt
setblock ~175 ~124 ~105 grass_block
setblock ~175 ~125 ~95 dirt
setblock ~175 ~125 ~96 dirt
setblock ~175 ~125 ~97 dirt
setblock ~175 ~125 ~98 dirt
setblock ~175 ~125 ~99 dirt
setblock ~175 ~125 ~100 dirt
setblock ~175 ~125 ~101 grass_block
setblock ~175 ~125 ~102 grass_block
setblock ~175 ~125 ~103 grass_block
setblock ~175 ~125 ~104 grass_block
setblock ~175 ~126 ~95 grass_block
setblock ~175 ~126 ~96 grass_block
setblock ~175 ~126 ~97 grass_block
setblock ~175 ~126 ~98 grass_block
setblock ~175 ~126 ~99 grass_block
setblock ~175 ~126 ~100 grass_block
setblock ~175 ~126 ~101 poppy
setblock ~175 ~126 ~104 poppy
setblock ~176 ~119 ~103 dirt
setblock ~176 ~120 ~101 dirt
setblock ~176 ~120 ~103 dirt
setblock ~176 ~120 ~104 dirt
setblock ~176 ~121 ~97 dirt
setblock ~176 ~121 ~98 dirt
setblock ~176 ~121 ~100 dirt
setblock ~176 ~121 ~101 dirt
setblock ~176 ~121 ~103 dirt
setblock ~176 ~121 ~104 dirt
setblock ~176 ~122 ~97 dirt
setblock ~176 ~122 ~98 dirt
setblock ~176 ~122 ~100 dirt
setblock ~176 ~122 ~101 dirt
setblock ~176 ~122 ~103 dirt
setblock ~176 ~122 ~104 dirt
setblock ~176 ~123 ~97 dirt
setblock ~176 ~123 ~98 dirt
setblock ~176 ~123 ~100 dirt
setblock ~176 ~123 ~101 dirt
setblock ~176 ~123 ~103 dirt
setblock ~176 ~123 ~104 dirt
setblock ~176 ~124 ~97 dirt
setblock ~176 ~124 ~98 dirt
setblock ~176 ~124 ~100 dirt
setblock ~176 ~124 ~101 dirt
setblock ~176 ~124 ~103 dirt
setblock ~176 ~124 ~104 dirt
setblock ~176 ~125 ~97 dirt
setblock ~176 ~125 ~98 grass_block
setblock ~176 ~125 ~100 grass_block
setblock ~176 ~125 ~101 grass_block
setblock ~176 ~125 ~103 grass_block
setblock ~176 ~125 ~104 grass_block
setblock ~176 ~126 ~97 grass_block
setblock ~176 ~126 ~100 short_grass
setblock ~199 ~200 ~199 gold_block
