setblock ~165 ~126 ~128 grass_block
setblock ~165 ~127 ~80 grass_block
setblock ~165 ~127 ~81 grass_block
setblock ~165 ~127 ~82 grass_block
setblock ~165 ~127 ~83 grass_block
setblock ~165 ~127 ~84 grass_block
setblock ~165 ~127 ~89 poppy
setblock ~165 ~127 ~111 oak_leaves[persistent=true]
setblock ~165 ~127 ~113 oak_leaves[persistent=true]
setblock ~165 ~127 ~114 oak_leaves[persistent=true]
setblock ~165 ~127 ~122 short_grass
setblock ~165 ~127 ~123 fern
setblock ~165 ~127 ~124 short_grass
setblock ~165 ~127 ~125 short_grass
setblock ~165 ~127 ~126 grass_block
setblock ~165 ~127 ~127 grass_block
setblock ~165 ~127 ~128 fern
setblock ~165 ~128 ~81 short_grass
setblock ~165 ~128 ~83 poppy
setblock ~165 ~128 ~106 oak_leaves[persistent=true]
setblock ~165 ~128 ~109 oak_leaves[persistent=true]
setblock ~165 ~128 ~111 jungle_leaves[persistent=true]
setblock ~165 ~128 ~112 oak_leaves[persistent=true]
setblock ~165 ~128 ~113 jungle_leaves[persistent=true]
setblock ~165 ~128 ~114 jungle_leaves[persistent=true]
setblock ~165 ~128 ~126 fern
setblock ~165 ~129 ~107 oak_leaves[persistent=true]
setblock ~165 ~129 ~108 oak_leaves[persistent=true]
setblock ~165 ~129 ~109 oak_leaves[persistent=true]
setblock ~165 ~129 ~111 oak_leaves[persistent=true]
setblock ~165 ~129 ~112 jungle_leaves[persistent=true]
setblock ~165 ~129 ~113 oak_leaves[persistent=true]
setblock ~165 ~129 ~114 jungle_leaves[persistent=true]
setblock ~165 ~130 ~107 oak_leaves[persistent=true]
setblock ~165 ~130 ~108 oak_leaves[persistent=true]
setblock ~165 ~130 ~109 oak_leaves[persistent=true]
setblock ~165 ~130 ~111 oak_leaves[persistent=true]
setblock ~165 ~130 ~112 jungle_leaves[persistent=true]
setblock ~165 ~130 ~113 oak_leaves[persistent=true]
setblock ~165 ~130 ~114 jungle_leaves[persistent=true]
setblock ~165 ~131 ~106 oak_leaves[persistent=true]
setblock ~165 ~131 ~107 oak_leaves[persistent=true]
setblock ~165 ~131 ~108 oak_leaves[persistent=true]
setblock ~165 ~131 ~109 oak_leaves[persistent=true]
setblock ~165 ~131 ~110 oak_leaves[persistent=true]
setblock ~165 ~131 ~111 oak_leaves[persistent=true]
setblock ~165 ~131 ~112 oak_leaves[persistent=true]
setblock ~165 ~131 ~113 oak_leaves[persistent=true]
setblock ~165 ~132 ~105 oak_leaves[persistent=true]
setblock ~165 ~132 ~106 jungle_leaves[persistent=true]
setblock ~165 ~132 ~107 oak_leaves[persistent=true]
setblock ~165 ~132 ~108 oak_leaves[persistent=true]
setblock ~165 ~132 ~109 oak_leaves[persistent=true]
setblock ~165 ~132 ~110 jungle_leaves[persistent=true]
setblock ~165 ~133 ~105 oak_leaves[persistent=true]
setblock ~165 ~133 ~106 oak_leaves[persistent=true]
setblock ~165 ~133 ~107 oak_leaves[persistent=true]
setblock ~165 ~133 ~108 oak_leaves[persistent=true]
setblock ~165 ~133 ~109 oak_leaves[persistent=true]
setblock ~165 ~133 ~110 oak_wood
setblock ~165 ~134 ~105 jungle_leaves[persistent=true]
setblock ~165 ~134 ~106 oak_leaves[persistent=true]
setblock ~165 ~134 ~107 oak_leaves[persistent=true]
setblock ~165 ~134 ~108 oak_leaves[persistent=true]
setblock ~165 ~134 ~109 oak_leaves[persistent=true]
setblock ~165 ~134 ~110 oak_leaves[persistent=true]
setblock ~165 ~135 ~105 oak_leaves[persistent=true]
setblock ~165 ~135 ~106 oak_leaves[persistent=true]
setblock ~165 ~135 ~107 oak_leaves[persistent=true]
setblock ~165 ~135 ~108 oak_leaves[persistent=true]
setblock ~165 ~135 ~109 jungle_leaves[persistent=true]
setblock ~165 ~135 ~110 oak_leaves[persistent=true]
setblock ~165 ~136 ~105 oak_leaves[persistent=true]
setblock ~165 ~136 ~107 oak_leaves[persistent=true]
setblock ~165 ~136 ~108 jungle_leaves[persistent=true]
setblock ~165 ~136 ~109 oak_leaves[persistent=true]
setblock ~165 ~136 ~110 jungle_leaves[persistent=true]
setblock ~165 ~137 ~105 oak_leaves[persistent=true]
setblock ~165 ~137 ~106 oak_leaves[persistent=true]
setblock ~165 ~137 ~107 jungle_leaves[persistent=true]
setblock ~165 ~137 ~108 oak_leaves[persistent=true]
setblock ~165 ~137 ~110 jungle_leaves[persistent=true]
setblock ~166 ~102 ~81 dirt
setblock ~166 ~102 ~82 dirt
setblock ~166 ~102 ~83 dirt
setblock ~166 ~102 ~85 dirt
setblock ~166 ~103 ~81 dirt
setblock ~166 ~103 ~82 dirt
setblock ~166 ~103 ~83 dirt
setblock ~166 ~103 ~84 dirt
setblock ~166 ~103 ~85 dirt
setblock ~166 ~103 ~86 dirt
setblock ~166 ~104 ~80 dirt
setblock ~166 ~104 ~81 dirt
setblock ~166 ~104 ~82 dirt
setblock ~166 ~104 ~83 dirt
setblock ~166 ~104 ~84 dirt
setblock ~166 ~104 ~85 dirt
setblock ~166 ~104 ~86 dirt
setblock ~166 ~105 ~78 dirt
setblock ~166 ~105 ~80 dirt
setblock ~166 ~105 ~81 dirt
setblock ~166 ~105 ~82 dirt
setblock ~166 ~105 ~83 dirt
setblock ~166 ~105 ~84 dirt
setblock ~166 ~105 ~85 dirt
setblock ~166 ~105 ~86 dirt
setblock ~166 ~105 ~87 dirt
setblock ~166 ~106 ~77 dirt
setblock ~166 ~106 ~78 dirt
setblock ~166 ~106 ~79 dirt
setblock ~166 ~106 ~80 dirt
setblock ~166 ~106 ~81 dirt
setblock ~166 ~106 ~82 dirt
setblock ~166 ~106 ~83 dirt
setblock ~166 ~106 ~84 dirt
setblock ~166 ~106 ~85 dirt
setblock ~166 ~106 ~86 dirt
setblock ~166 ~106 ~87 dirt
setblock ~166 ~107 ~76 dirt
setblock ~166 ~107 ~77 dirt
setblock ~166 ~107 ~78 dirt
setblock ~166 ~107 ~79 dirt
setblock ~166 ~107 ~80 dirt
setblock ~166 ~107 ~81 dirt
setblock ~166 ~107 ~82 dirt
setblock ~166 ~107 ~83 dirt
setblock ~166 ~107 ~84 dirt
setblock ~166 ~107 ~85 dirt
setblock ~166 ~107 ~86 dirt
setblock ~166 ~107 ~87 dirt
setblock ~166 ~107 ~88 dirt
setblock ~166 ~108 ~76 dirt
setblock ~166 ~108 ~77 dirt
setblock ~166 ~108 ~78 dirt
setblock ~166 ~108 ~79 dirt
setblock ~166 ~108 ~80 dirt
setblock ~166 ~108 ~81 dirt
setblock ~166 ~108 ~82 dirt
setblock ~166 ~108 ~83 dirt
setblock ~166 ~108 ~84 dirt
setblock ~166 ~108 ~85 dirt
setblock ~166 ~108 ~86 dirt
setblock ~166 ~108 ~87 dirt
setblock ~166 ~108 ~88 dirt
setblock ~166 ~108 ~89 dirt
setblock ~166 ~109 ~75 dirt
setblock ~166 ~109 ~76 dirt
setblock ~166 ~109 ~77 dirt
setblock ~166 ~109 ~78 dirt
setblock ~166 ~109 ~79 dirt
setblock ~166 ~109 ~80 dirt
setblock ~166 ~109 ~81 dirt
setblock ~166 ~109 ~82 dirt
setblock ~166 ~109 ~83 dirt
setblock ~166 ~109 ~84 dirt
setblock ~166 ~109 ~85 dirt
setblock ~166 ~109 ~86 dirt
setblock ~166 ~109 ~87 dirt
setblock ~166 ~109 ~88 dirt
setblock ~166 ~109 ~89 dirt
setblock ~166 ~109 ~90 dirt
setblock ~166 ~110 ~75 dirt
setblock ~166 ~110 ~76 dirt
setblock ~166 ~110 ~77 dirt
setblock ~166 ~110 ~78 dirt
setblock ~166 ~110 ~79 dirt
setblock ~166 ~110 ~80 dirt
setblock ~166 ~110 ~81 dirt
setblock ~166 ~110 ~82 dirt
setblock ~166 ~110 ~83 dirt
setblock ~166 ~110 ~84 dirt
setblock ~166 ~110 ~85 dirt
setblock ~166 ~110 ~86 dirt
setblock ~166 ~110 ~87 dirt
setblock ~166 ~110 ~88 dirt
setblock ~166 ~110 ~89 dirt
setblock ~166 ~110 ~90 dirt
setblock ~166 ~110 ~91 dirt
setblock ~166 ~110 ~97 dirt
setblock ~166 ~111 ~74 dirt
setblock ~166 ~111 ~75 dirt
setblock ~166 ~111 ~76 dirt
setblock ~166 ~111 ~77 dirt
setblock ~166 ~111 ~78 dirt
setblock ~166 ~111 ~79 dirt
setblock ~166 ~111 ~80 dirt
setblock ~166 ~111 ~81 dirt
setblock ~166 ~111 ~82 dirt
setblock ~166 ~111 ~83 dirt
setblock ~166 ~111 ~84 dirt
setblock ~166 ~111 ~85 dirt
setblock ~166 ~111 ~86 dirt
setblock ~166 ~111 ~87 dirt
setblock ~166 ~111 ~88 dirt
setblock ~166 ~111 ~89 dirt
setblock ~166 ~111 ~90 dirt
setblock ~166 ~111 ~91 dirt
setblock ~166 ~111 ~97 dirt
setblock ~166 ~112 ~72 dirt
setblock ~166 ~112 ~73 dirt
setblock ~166 ~112 ~74 dirt
setblock ~166 ~112 ~75 dirt
setblock ~166 ~112 ~76 dirt
setblock ~166 ~112 ~77 dirt
setblock ~166 ~112 ~78 dirt
setblock ~166 ~112 ~79 dirt
setblock ~166 ~112 ~80 dirt
setblock ~166 ~112 ~81 dirt
setblock ~166 ~112 ~82 dirt
setblock ~166 ~112 ~83 dirt
setblock ~166 ~112 ~84 dirt
setblock ~166 ~112 ~85 dirt
setblock ~166 ~112 ~86 dirt
setblock ~166 ~112 ~87 dirt
setblock ~166 ~112 ~88 dirt
setblock ~166 ~112 ~89 dirt
setblock ~166 ~112 ~90 dirt
setblock ~166 ~112 ~91 dirt
setblock ~166 ~112 ~92 dirt
setblock ~166 ~112 ~96 dirt
setblock ~166 ~112 ~97 dirt
setblock ~166 ~112 ~103 dirt
setblock ~166 ~113 ~71 dirt
setblock ~166 ~113 ~72 dirt
setblock ~166 ~113 ~73 dirt
setblock ~166 ~113 ~74 dirt
setblock ~166 ~113 ~75 dirt
setblock ~166 ~113 ~76 dirt
setblock ~166 ~113 ~77 dirt
setblock ~166 ~113 ~78 dirt
setblock ~166 ~113 ~79 dirt
setblock ~166 ~113 ~80 dirt
setblock ~166 ~113 ~81 dirt
setblock ~166 ~113 ~82 dirt
setblock ~166 ~113 ~83 dirt
setblock ~166 ~113 ~84 dirt
setblock ~166 ~113 ~85 dirt
setblock ~166 ~113 ~86 dirt
setblock ~166 ~113 ~87 dirt
setblock ~166 ~113 ~88 dirt
setblock ~166 ~113 ~89 dirt
setblock ~166 ~113 ~90 dirt
setblock ~166 ~113 ~91 dirt
setblock ~166 ~113 ~92 dirt
setblock ~166 ~113 ~96 dirt
setblock ~166 ~113 ~97 dirt
setblock ~166 ~113 ~98 dirt
setblock ~166 ~113 ~103 dirt
setblock ~166 ~113 ~105 dirt
setblock ~166 ~113 ~107 dirt
setblock ~166 ~114 ~70 dirt
setblock ~166 ~114 ~71 dirt
setblock ~166 ~114 ~72 dirt
setblock ~166 ~114 ~73 dirt
setblock ~166 ~114 ~74 dirt
setblock ~166 ~114 ~75 dirt
setblock ~166 ~114 ~76 dirt
setblock ~166 ~114 ~77 dirt
setblock ~166 ~114 ~78 dirt
setblock ~166 ~114 ~79 dirt
setblock ~166 ~114 ~80 dirt
setblock ~166 ~114 ~81 dirt
setblock ~166 ~114 ~82 dirt
setblock ~166 ~114 ~83 dirt
setblock ~166 ~114 ~84 dirt
setblock ~166 ~114 ~85 dirt
setblock ~166 ~114 ~86 dirt
setblock ~166 ~114 ~87 dirt
setblock ~166 ~114 ~88 dirt
setblock ~166 ~114 ~89 dirt
setblock ~166 ~114 ~90 dirt
setblock ~166 ~114 ~91 dirt
setblock ~166 ~114 ~92 dirt
setblock ~166 ~114 ~93 dirt
setblock ~166 ~114 ~95 dirt
setblock ~166 ~114 ~96 dirt
setblock ~166 ~114 ~97 dirt
setblock ~166 ~114 ~98 dirt
setblock ~166 ~114 ~101 dirt
setblock ~166 ~114 ~102 dirt
setblock ~166 ~114 ~103 dirt
setblock ~166 ~114 ~104 dirt
setblock ~166 ~114 ~105 dirt
setblock ~166 ~114 ~106 dirt
setblock ~166 ~114 ~107 dirt
setblock ~166 ~114 ~108 dirt
setblock ~166 ~115 ~70 dirt
setblock ~166 ~115 ~71 dirt
setblock ~166 ~115 ~72 dirt
setblock ~166 ~115 ~73 dirt
setblock ~166 ~115 ~74 dirt
setblock ~166 ~115 ~75 dirt
setblock ~166 ~115 ~76 dirt
setblock ~166 ~115 ~77 dirt
setblock ~166 ~115 ~78 dirt
setblock ~166 ~115 ~79 dirt
setblock ~166 ~115 ~80 dirt
setblock ~166 ~115 ~81 dirt
setblock ~166 ~115 ~82 dirt
setblock ~166 ~115 ~83 dirt
setblock ~166 ~115 ~84 dirt
setblock ~166 ~115 ~85 dirt
setblock ~166 ~115 ~86 dirt
setblock ~166 ~115 ~87 dirt
setblock ~166 ~115 ~88 dirt
setblock ~166 ~115 ~89 dirt
setblock ~166 ~115 ~90 dirt
setblock ~166 ~115 ~91 dirt
setblock ~166 ~115 ~92 dirt
setblock ~166 ~115 ~93 dirt
setblock ~166 ~115 ~94 dirt
setblock ~166 ~115 ~95 dirt
setblock ~166 ~115 ~96 dirt
setblock ~166 ~115 ~97 dirt
setblock ~166 ~115 ~98 dirt
setblock ~166 ~115 ~99 dirt
setblock ~166 ~115 ~100 dirt
setblock ~166 ~115 ~101 dirt
setblock ~166 ~115 ~102 dirt
setblock ~166 ~115 ~103 dirt
setblock ~166 ~115 ~104 dirt
setblock ~166 ~115 ~105 dirt
setblock ~166 ~115 ~106 dirt
setblock ~166 ~115 ~107 dirt
setblock ~166 ~115 ~108 dirt
setblock ~166 ~116 ~69 dirt
setblock ~166 ~116 ~70 dirt
setblock ~166 ~116 ~71 dirt
setblock ~166 ~116 ~72 dirt
setblock ~166 ~116 ~73 dirt
setblock ~166 ~116 ~74 dirt
setblock ~166 ~116 ~75 dirt
setblock ~166 ~116 ~76 dirt
setblock ~166 ~116 ~77 dirt
setblock ~166 ~116 ~78 dirt
setblock ~166 ~116 ~79 dirt
setblock ~166 ~116 ~80 dirt
setblock ~166 ~116 ~81 dirt
setblock ~166 ~116 ~82 dirt
setblock ~166 ~116 ~83 dirt
setblock ~166 ~116 ~84 dirt
setblock ~166 ~116 ~85 dirt
setblock ~166 ~116 ~86 dirt
setblock ~166 ~116 ~87 dirt
setblock ~166 ~116 ~88 dirt
setblock ~166 ~116 ~89 dirt
setblock ~166 ~116 ~90 dirt
setblock ~166 ~116 ~91 dirt
setblock ~166 ~116 ~92 dirt
setblock ~166 ~116 ~93 dirt
setblock ~166 ~116 ~94 dirt
setblock ~166 ~116 ~95 dirt
setblock ~166 ~116 ~96 dirt
setblock ~166 ~116 ~97 dirt
setblock ~166 ~116 ~98 dirt
setblock ~166 ~116 ~99 dirt
setblock ~166 ~116 ~100 dirt
setblock ~166 ~116 ~101 dirt
setblock ~166 ~116 ~102 dirt
setblock ~166 ~116 ~103 dirt
setblock ~166 ~116 ~104 dirt
setblock ~166 ~116 ~105 dirt
setblock ~166 ~116 ~106 dirt
setblock ~166 ~116 ~107 dirt
setblock ~166 ~116 ~108 dirt
setblock ~166 ~117 ~68 dirt
setblock ~166 ~117 ~69 dirt
setblock ~166 ~117 ~70 dirt
setblock ~166 ~117 ~71 dirt
setblock ~166 ~117 ~72 dirt
setblock ~166 ~117 ~73 dirt
setblock ~166 ~117 ~74 dirt
setblock ~166 ~117 ~75 dirt
setblock ~166 ~117 ~76 dirt
setblock ~166 ~117 ~77 dirt
setblock ~166 ~117 ~78 dirt
setblock ~166 ~117 ~79 dirt
setblock ~166 ~117 ~80 dirt
setblock ~166 ~117 ~81 dirt
setblock ~166 ~117 ~82 dirt
setblock ~166 ~117 ~83 dirt
setblock ~166 ~117 ~84 dirt
setblock ~166 ~117 ~85 dirt
setblock ~166 ~117 ~86 dirt
setblock ~166 ~117 ~87 dirt
setblock ~166 ~117 ~88 dirt
setblock ~166 ~117 ~89 dirt
setblock ~166 ~117 ~90 dirt
setblock ~166 ~117 ~91 dirt
setblock ~166 ~117 ~92 dirt
setblock ~166 ~117 ~93 dirt
setblock ~166 ~117 ~94 dirt
setblock ~166 ~117 ~95 dirt
setblock ~166 ~117 ~96 dirt
setblock ~166 ~117 ~97 dirt
setblock ~166 ~117 ~98 dirt
setblock ~166 ~117 ~99 dirt
setblock ~166 ~117 ~100 dirt
setblock ~166 ~117 ~101 dirt
setblock ~166 ~117 ~102 dirt
setblock ~166 ~117 ~103 dirt
setblock ~166 ~117 ~104 dirt
setblock ~166 ~117 ~105 dirt
setblock ~166 ~117 ~106 dirt
setblock ~166 ~117 ~107 dirt
setblock ~166 ~117 ~108 dirt
setblock ~166 ~117 ~109 dirt
setblock ~166 ~118 ~67 dirt
setblock ~166 ~118 ~68 dirt
setblock ~166 ~118 ~69 dirt
setblock ~166 ~118 ~70 dirt
setblock ~166 ~118 ~71 dirt
setblock ~166 ~118 ~72 dirt
setblock ~166 ~118 ~73 dirt
setblock ~166 ~118 ~74 dirt
setblock ~166 ~118 ~75 dirt
setblock ~166 ~118 ~76 dirt
setblock ~166 ~118 ~77 dirt
setblock ~166 ~118 ~78 dirt
setblock ~166 ~118 ~79 dirt
setblock ~166 ~118 ~80 dirt
setblock ~166 ~118 ~81 dirt
setblock ~166 ~118 ~82 dirt
setblock ~166 ~118 ~83 dirt
setblock ~166 ~118 ~84 dirt
setblock ~166 ~118 ~85 dirt
setblock ~166 ~118 ~86 dirt
setblock ~166 ~118 ~87 dirt
setblock ~166 ~118 ~88 dirt
setblock ~166 ~118 ~89 dirt
setblock ~166 ~118 ~90 dirt
setblock ~166 ~118 ~91 dirt
setblock ~166 ~118 ~92 dirt
setblock ~166 ~118 ~93 dirt
setblock ~166 ~118 ~94 dirt
setblock ~166 ~118 ~95 dirt
setblock ~166 ~118 ~96 dirt
setblock ~166 ~118 ~97 dirt
setblock ~166 ~118 ~98 dirt
setblock ~166 ~118 ~99 dirt
setblock ~166 ~118 ~100 dirt
setblock ~166 ~118 ~101 dirt
setblock ~166 ~118 ~102 dirt
setblock ~166 ~118 ~103 dirt
setblock ~166 ~118 ~104 dirt
setblock ~166 ~118 ~105 dirt
setblock ~166 ~118 ~106 dirt
setblock ~166 ~118 ~107 dirt
setblock ~166 ~118 ~108 dirt
setblock ~166 ~118 ~109 dirt
setblock ~166 ~118 ~110 dirt
setblock ~166 ~119 ~67 dirt
setblock ~166 ~119 ~68 dirt
setblock ~166 ~119 ~69 dirt
setblock ~166 ~119 ~70 dirt
setblock ~166 ~119 ~71 dirt
setblock ~166 ~119 ~72 dirt
setblock ~166 ~119 ~73 dirt
setblock ~166 ~119 ~74 dirt
setblock ~166 ~119 ~75 dirt
setblock ~166 ~119 ~76 dirt
setblock ~166 ~119 ~77 dirt
setblock ~166 ~119 ~78 dirt
setblock ~166 ~119 ~79 dirt
setblock ~166 ~119 ~80 dirt
setblock ~166 ~119 ~81 dirt
setblock ~166 ~119 ~82 dirt
setblock ~166 ~119 ~83 dirt
setblock ~166 ~119 ~84 dirt
setblock ~166 ~119 ~85 dirt
setblock ~166 ~119 ~86 dirt
setblock ~166 ~119 ~87 dirt
setblock ~166 ~119 ~88 dirt
setblock ~166 ~119 ~89 dirt
setblock ~166 ~119 ~90 dirt
setblock ~166 ~119 ~91 dirt
setblock ~166 ~119 ~92 dirt
setblock ~166 ~119 ~93 dirt
setblock ~166 ~119 ~94 dirt
setblock ~166 ~119 ~95 dirt
setblock ~166 ~119 ~96 dirt
setblock ~166 ~119 ~97 dirt
setblock ~166 ~119 ~98 dirt
setblock ~166 ~119 ~99 dirt
setblock ~166 ~119 ~100 dirt
setblock ~166 ~119 ~101 dirt
setblock ~166 ~119 ~102 dirt
setblock ~166 ~119 ~103 dirt
setblock ~166 ~119 ~104 dirt
setblock ~166 ~119 ~105 dirt
setblock ~166 ~119 ~106 dirt
setblock ~166 ~119 ~107 dirt
setblock ~166 ~119 ~108 dirt
setblock ~166 ~119 ~109 dirt
setblock ~166 ~119 ~110 dirt
setblock ~166 ~119 ~111 dirt
setblock ~166 ~120 ~66 dirt
setblock ~166 ~120 ~67 dirt
setblock ~166 ~120 ~68 dirt
setblock ~166 ~120 ~69 dirt
setblock ~166 ~120 ~70 dirt
setblock ~166 ~120 ~71 dirt
setblock ~166 ~120 ~72 dirt
setblock ~166 ~120 ~73 dirt
setblock ~166 ~120 ~74 dirt
setblock ~166 ~120 ~75 dirt
setblock ~166 ~120 ~76 dirt
setblock ~166 ~120 ~77 dirt
setblock ~166 ~120 ~78 dirt
setblock ~166 ~120 ~79 dirt
setblock ~166 ~120 ~80 dirt
setblock ~166 ~120 ~81 dirt
setblock ~166 ~120 ~82 dirt
setblock ~166 ~120 ~83 dirt
setblock ~166 ~120 ~84 dirt
setblock ~166 ~120 ~85 dirt
setblock ~166 ~120 ~86 dirt
setblock ~166 ~120 ~87 dirt
setblock ~166 ~120 ~88 dirt
setblock ~166 ~120 ~89 dirt
setblock ~166 ~120 ~90 dirt
setblock ~166 ~120 ~91 dirt
setblock ~166 ~120 ~92 dirt
setblock ~166 ~120 ~93 dirt
setblock ~166 ~120 ~94 dirt
setblock ~166 ~120 ~95 dirt
setblock ~166 ~120 ~96 dirt
setblock ~166 ~120 ~97 dirt
setblock ~166 ~120 ~98 dirt
setblock ~166 ~120 ~99 dirt
setblock ~166 ~120 ~100 dirt
setblock ~166 ~120 ~101 dirt
setblock ~166 ~120 ~102 dirt
setblock ~166 ~120 ~103 dirt
setblock ~166 ~120 ~104 dirt
setblock ~166 ~120 ~105 dirt
setblock ~166 ~120 ~106 dirt
setblock ~166 ~120 ~107 dirt
setblock ~166 ~120 ~108 dirt
setblock ~166 ~120 ~109 dirt
setblock ~166 ~120 ~110 dirt
setblock ~166 ~120 ~111 dirt
setblock ~166 ~120 ~112 dirt
setblock ~166 ~120 ~124 dirt
setblock ~166 ~121 ~65 dirt
setblock ~166 ~121 ~66 dirt
setblock ~166 ~121 ~67 dirt
setblock ~166 ~121 ~68 dirt
setblock ~166 ~121 ~69 dirt
setblock ~166 ~121 ~70 dirt
setblock ~166 ~121 ~71 dirt
setblock ~166 ~121 ~72 dirt
setblock ~166 ~121 ~73 dirt
setblock ~166 ~121 ~74 dirt
setblock ~166 ~121 ~75 dirt
setblock ~166 ~121 ~76 dirt
setblock ~166 ~121 ~77 dirt
setblock ~166 ~121 ~78 dirt
setblock ~166 ~121 ~79 dirt
setblock ~166 ~121 ~80 dirt
setblock ~166 ~121 ~81 dirt
setblock ~166 ~121 ~82 dirt
setblock ~166 ~121 ~83 dirt
setblock ~166 ~121 ~84 dirt
setblock ~166 ~121 ~85 dirt
setblock ~166 ~121 ~86 dirt
setblock ~166 ~121 ~87 dirt
setblock ~166 ~121 ~88 dirt
setblock ~166 ~121 ~89 dirt
setblock ~166 ~121 ~90 dirt
setblock ~166 ~121 ~91 dirt
setblock ~166 ~121 ~92 dirt
setblock ~166 ~121 ~93 dirt
setblock ~166 ~121 ~94 dirt
setblock ~166 ~121 ~95 dirt
setblock ~166 ~121 ~96 dirt
setblock ~166 ~121 ~97 dirt
setblock ~166 ~121 ~98 dirt
setblock ~166 ~121 ~99 dirt
setblock ~166 ~121 ~100 dirt
setblock ~166 ~121 ~101 dirt
setblock ~166 ~121 ~102 dirt
setblock ~166 ~121 ~103 dirt
setblock ~166 ~121 ~104 dirt
setblock ~166 ~121 ~105 dirt
setblock ~166 ~121 ~106 dirt
setblock ~166 ~121 ~107 dirt
setblock ~166 ~121 ~108 dirt
setblock ~166 ~121 ~109 dirt
setblock ~166 ~121 ~110 dirt
setblock ~166 ~121 ~111 dirt
setblock ~166 ~121 ~112 dirt
setblock ~166 ~121 ~124 dirt
setblock ~166 ~121 ~127 dirt
setblock ~166 ~122 ~65 dirt
setblock ~166 ~122 ~66 dirt
setblock ~166 ~122 ~67 dirt
setblock ~166 ~122 ~68 dirt
setblock ~166 ~122 ~69 dirt
setblock ~166 ~122 ~70 dirt
setblock ~166 ~122 ~71 dirt
setblock ~166 ~122 ~72 dirt
setblock ~166 ~122 ~73 dirt
setblock ~166 ~122 ~74 dirt
setblock ~166 ~122 ~75 dirt
setblock ~166 ~122 ~76 dirt
setblock ~166 ~122 ~77 dirt
setblock ~166 ~122 ~78 dirt
setblock ~166 ~122 ~79 dirt
setblock ~166 ~122 ~80 dirt
setblock ~166 ~122 ~81 dirt
setblock ~166 ~122 ~82 dirt
setblock ~166 ~122 ~83 dirt
setblock ~166 ~122 ~84 dirt
setblock ~166 ~122 ~85 dirt
setblock ~166 ~122 ~86 dirt
setblock ~166 ~122 ~87 dirt
setblock ~166 ~122 ~88 dirt
setblock ~166 ~122 ~89 dirt
setblock ~166 ~122 ~90 dirt
setblock ~166 ~122 ~91 dirt
setblock ~166 ~122 ~92 dirt
setblock ~166 ~122 ~93 dirt
setblock ~166 ~122 ~94 dirt
setblock ~166 ~122 ~95 dirt
setblock ~166 ~122 ~96 dirt
setblock ~166 ~122 ~97 dirt
setblock ~166 ~122 ~98 dirt
setblock ~166 ~122 ~99 dirt
setblock ~166 ~122 ~100 dirt
setblock ~166 ~122 ~101 dirt
setblock ~166 ~122 ~102 dirt
setblock ~166 ~122 ~103 dirt
setblock ~166 ~122 ~104 dirt
setblock ~166 ~122 ~105 dirt
setblock ~166 ~122 ~106 dirt
setblock ~166 ~122 ~107 dirt
setblock ~166 ~122 ~108 dirt
setblock ~166 ~122 ~109 dirt
setblock ~166 ~122 ~110 dirt
setblock ~166 ~122 ~111 dirt
setblock ~166 ~122 ~112 dirt
setblock ~166 ~122 ~124 dirt
setblock ~166 ~122 ~127 dirt
setblock ~166 ~123 ~65 grass_block
setblock ~166 ~123 ~66 grass_block
setblock ~166 ~123 ~67 grass_block
setblock ~166 ~123 ~68 grass_block
setblock ~166 ~123 ~69 grass_block
setblock ~166 ~123 ~70 grass_block
setblock ~166 ~123 ~71 grass_block
setblock ~166 ~123 ~72 grass_block
setblock ~166 ~123 ~73 dirt
setblock ~166 ~123 ~74 dirt
setblock ~166 ~123 ~75 dirt
setblock ~166 ~123 ~76 dirt
setblock ~166 ~123 ~77 dirt
setblock ~166 ~123 ~78 dirt
setblock ~166 ~123 ~79 dirt
setblock ~166 ~123 ~80 dirt
setblock ~166 ~123 ~81 dirt
setblock ~166 ~123 ~82 dirt
setblock ~166 ~123 ~83 dirt
setblock ~166 ~123 ~84 dirt
setblock ~166 ~123 ~85 dirt
setblock ~166 ~123 ~86 dirt
setblock ~166 ~123 ~87 dirt
setblock ~166 ~123 ~88 dirt
setblock ~166 ~123 ~89 dirt
setblock ~166 ~123 ~90 dirt
setblock ~166 ~123 ~91 dirt
setblock ~166 ~123 ~92 dirt
setblock ~166 ~123 ~93 dirt
setblock ~166 ~123 ~94 dirt
setblock ~166 ~123 ~95 dirt
setblock ~166 ~123 ~96 dirt
setblock ~166 ~123 ~97 dirt
setblock ~166 ~123 ~98 dirt
setblock ~166 ~123 ~99 dirt
setblock ~166 ~123 ~100 dirt
setblock ~166 ~123 ~101 dirt
setblock ~166 ~123 ~102 dirt
setblock ~166 ~123 ~103 dirt
setblock ~166 ~123 ~104 dirt
setblock ~166 ~123 ~105 dirt
setblock ~166 ~123 ~106 dirt
setblock ~166 ~123 ~107 dirt
setblock ~166 ~123 ~108 grass_block
setblock ~166 ~123 ~109 grass_block
setblock ~166 ~123 ~110 grass_block
setblock ~166 ~123 ~111 grass_block
setblock ~166 ~123 ~112 grass_block
setblock ~166 ~123 ~124 dirt
setblock ~166 ~123 ~127 dirt
setblock ~166 ~124 ~68 poppy
setblock ~166 ~124 ~70 short_grass
setblock ~166 ~124 ~71 short_grass
setblock ~166 ~124 ~73 grass_block
setblock ~166 ~124 ~74 grass_block
setblock ~166 ~124 ~75 dirt
setblock ~166 ~124 ~76 dirt
setblock ~166 ~124 ~77 dirt
setblock ~166 ~124 ~78 dirt
setblock ~166 ~124 ~79 dirt
setblock ~166 ~124 ~80 dirt
setblock ~166 ~124 ~81 dirt
setblock ~166 ~124 ~82 dirt
setblock ~166 ~124 ~83 dirt
setblock ~166 ~124 ~84 dirt
setblock ~166 ~124 ~85 dirt
setblock ~166 ~124 ~86 dirt
setblock ~166 ~124 ~87 dirt
setblock ~166 ~124 ~88 dirt
setblock ~166 ~124 ~89 dirt
setblock ~166 ~124 ~90 dirt
setblock ~166 ~124 ~91 dirt
setblock ~166 ~124 ~92 dirt
setblock ~166 ~124 ~93 dirt
setblock ~166 ~124 ~94 dirt
setblock ~166 ~124 ~95 dirt
setblock ~166 ~124 ~96 dirt
setblock ~166 ~124 ~97 dirt
setblock ~166 ~124 ~98 grass_block
setblock ~166 ~124 ~99 grass_block
setblock ~166 ~124 ~100 grass_block
setblock ~166 ~124 ~101 grass_block
setblock ~166 ~124 ~102 grass_block
setblock ~166 ~124 ~103 grass_block
setblock ~166 ~124 ~104 grass_block
setblock ~166 ~124 ~105 grass_block
setblock ~166 ~124 ~106 grass_block
setblock ~166 ~124 ~107 grass_block
setblock ~166 ~124 ~108 fern
setblock ~166 ~124 ~109 short_grass
setblock ~166 ~124 ~112 short_grass
setblock ~166 ~124 ~124 dirt
setblock ~166 ~124 ~127 dirt
setblock ~166 ~125 ~75 grass_block
setblock ~166 ~125 ~76 grass_block
setblock ~166 ~125 ~77 grass_block
setblock ~166 ~125 ~78 dirt
setblock ~166 ~125 ~79 dirt
setblock ~166 ~125 ~80 dirt
setblock ~166 ~125 ~81 dirt
setblock ~166 ~125 ~82 dirt
setblock ~166 ~125 ~83 dirt
setblock ~166 ~125 ~84 dirt
setblock ~166 ~125 ~85 dirt
setblock ~166 ~125 ~86 dirt
setblock ~166 ~125 ~87 dirt
setblock ~166 ~125 ~88 dirt
setblock ~166 ~125 ~89 dirt
setblock ~166 ~125 ~90 dirt
setblock ~166 ~125 ~91 dirt
setblock ~166 ~125 ~92 dirt
setblock ~166 ~125 ~93 grass_block
setblock ~166 ~125 ~94 grass_block
setblock ~166 ~125 ~95 grass_block
setblock ~166 ~125 ~96 grass_block
setblock ~166 ~125 ~97 grass_block
setblock ~166 ~125 ~100 short_grass
setblock ~166 ~125 ~101 fern
setblock ~166 ~125 ~106 short_grass
setblock ~166 ~125 ~107 short_grass
setblock ~166 ~125 ~124 dirt
setblock ~166 ~125 ~127 dirt
setblock ~166 ~126 ~75 short_grass
setblock ~166 ~126 ~78 grass_block
setblock ~166 ~126 ~79 grass_block
setblock ~166 ~126 ~80 grass_block
setblock ~166 ~126 ~81 grass_block
setblock ~166 ~126 ~82 grass_block
setblock ~166 ~126 ~83 grass_block
setblock ~166 ~126 ~84 grass_block
setblock ~166 ~126 ~85 grass_block
setblock ~166 ~126 ~86 grass_block
setblock ~166 ~126 ~87 grass_block
setblock ~166 ~126 ~88 grass_block
setblock ~166 ~126 ~89 grass_block
setblock ~166 ~126 ~90 grass_block
setblock ~166 ~126 ~91 grass_block
setblock ~166 ~126 ~92 grass_block
setblock ~166 ~126 ~94 poppy
setblock ~166 ~126 ~95 short_grass
setblock ~166 ~126 ~97 fern
setblock ~166 ~126 ~124 grass_block
setblock ~166 ~126 ~127 dirt
setblock ~166 ~127 ~79 short_grass
setblock ~166 ~127 ~83 short_grass
setblock ~166 ~127 ~86 short_grass
setblock ~166 ~127 ~87 short_grass
setblock ~166 ~127 ~91 short_grass
setblock ~166 ~127 ~111 oak_leaves[persistent=true]
setblock ~166 ~127 ~112 oak_leaves[persistent=true]
setblock ~166 ~127 ~113 jungle_leaves[persistent=true]
setblock ~166 ~127 ~114 oak_leaves[persistent=true]
setblock ~166 ~127 ~124 short_grass
setblock ~166 ~127 ~127 grass_block
setblock ~166 ~128 ~111 jungle_leaves[persistent=true]
setblock ~166 ~128 ~112 oak_leaves[persistent=true]
setblock ~166 ~128 ~113 oak_leaves[persistent=true]
setblock ~166 ~128 ~114 oak_leaves[persistent=true]
setblock ~166 ~129 ~111 oak_leaves[persistent=true]
setblock ~166 ~129 ~112 oak_leaves[persistent=true]
setblock ~166 ~129 ~113 jungle_leaves[persistent=true]
setblock ~166 ~129 ~114 oak_leaves[persistent=true]
setblock ~166 ~130 ~111 jungle_leaves[persistent=true]
setblock ~166 ~130 ~112 jungle_leaves[persistent=true]
setblock ~166 ~130 ~113 oak_leaves[persistent=true]
setblock ~166 ~130 ~114 jungle_leaves[persistent=true]
setblock ~166 ~132 ~106 oak_leaves[persistent=true]
setblock ~166 ~132 ~107 oak_leaves[persistent=true]
setblock ~166 ~132 ~108 jungle_leaves[persistent=true]
setblock ~166 ~132 ~109 jungle_leaves[persistent=true]
setblock ~166 ~132 ~110 oak_leaves[persistent=true]
setblock ~166 ~133 ~106 oak_leaves[persistent=true]
setblock ~166 ~133 ~107 oak_leaves[persistent=true]
setblock ~166 ~133 ~108 oak_leaves[persistent=true]
setblock ~166 ~133 ~109 oak_leaves[persistent=true]
setblock ~166 ~133 ~110 oak_leaves[persistent=true]
setblock ~166 ~134 ~106 jungle_leaves[persistent=true]
setblock ~166 ~134 ~107 oak_leaves[persistent=true]
setblock ~166 ~134 ~110 oak_leaves[persistent=true]
setblock ~166 ~135 ~106 jungle_leaves[persistent=true]
setblock ~166 ~135 ~107 oak_leaves[persistent=true]
setblock ~166 ~135 ~108 oak_leaves[persistent=true]
setblock ~166 ~135 ~109 oak_leaves[persistent=true]
setblock ~166 ~135 ~110 oak_leaves[persistent=true]
setblock ~166 ~136 ~106 oak_leaves[persistent=true]
setblock ~166 ~136 ~107 oak_leaves[persistent=true]
setblock ~166 ~136 ~108 oak_leaves[persistent=true]
setblock ~166 ~136 ~109 jungle_leaves[persistent=true]
setblock ~166 ~136 ~110 jungle_leaves[persistent=true]
setblock ~167 ~103 ~82 dirt
setblock ~167 ~103 ~85 dirt
setblock ~167 ~104 ~81 dirt
setblock ~167 ~104 ~82 dirt
setblock ~167 ~104 ~85 dirt
setblock ~167 ~105 ~80 dirt
setblock ~167 ~105 ~81 dirt
setblock ~167 ~105 ~82 dirt
setblock ~167 ~105 ~84 dirt
setblock ~167 ~105 ~85 dirt
setblock ~167 ~105 ~86 dirt
setblock ~167 ~106 ~80 dirt
setblock ~167 ~106 ~81 dirt
setblock ~167 ~106 ~82 dirt
setblock ~167 ~106 ~83 dirt
setblock ~167 ~106 ~84 dirt
setblock ~167 ~106 ~85 dirt
setblock ~167 ~106 ~86 dirt
setblock ~167 ~107 ~77 dirt
setblock ~167 ~107 ~80 dirt
setblock ~167 ~107 ~81 dirt
setblock ~167 ~107 ~82 dirt
setblock ~167 ~107 ~83 dirt
setblock ~167 ~107 ~84 dirt
setblock ~167 ~107 ~85 dirt
setblock ~167 ~107 ~86 dirt
setblock ~167 ~107 ~87 dirt
setblock ~167 ~108 ~77 dirt
setblock ~167 ~108 ~78 dirt
setblock ~167 ~108 ~79 dirt
setblock ~167 ~108 ~80 dirt
setblock ~167 ~108 ~81 dirt
setblock ~167 ~108 ~82 dirt
setblock ~167 ~108 ~83 dirt
setblock ~167 ~108 ~84 dirt
setblock ~167 ~108 ~85 dirt
setblock ~167 ~108 ~86 dirt
setblock ~167 ~108 ~87 dirt
setblock ~167 ~108 ~88 dirt
setblock ~167 ~109 ~77 dirt
setblock ~167 ~109 ~78 dirt
setblock ~167 ~109 ~79 dirt
setblock ~167 ~109 ~80 dirt
setblock ~167 ~109 ~81 dirt
setblock ~167 ~109 ~82 dirt
setblock ~167 ~109 ~83 dirt
setblock ~167 ~109 ~84 dirt
setblock ~167 ~109 ~85 dirt
setblock ~167 ~109 ~86 dirt
setblock ~167 ~109 ~87 dirt
setblock ~167 ~109 ~88 dirt
setblock ~167 ~109 ~89 dirt
setblock ~167 ~110 ~77 dirt
setblock ~167 ~110 ~78 dirt
setblock ~167 ~110 ~79 dirt
setblock ~167 ~110 ~80 dirt
setblock ~167 ~110 ~81 dirt
setblock ~167 ~110 ~82 dirt
setblock ~167 ~110 ~83 dirt
setblock ~167 ~110 ~84 dirt
setblock ~167 ~110 ~85 dirt
setblock ~167 ~110 ~86 dirt
setblock ~167 ~110 ~87 dirt
setblock ~167 ~110 ~88 dirt
setblock ~167 ~110 ~89 dirt
setblock ~167 ~111 ~75 dirt
setblock ~167 ~111 ~76 dirt
setblock ~167 ~111 ~77 dirt
setblock ~167 ~111 ~78 dirt
setblock ~167 ~111 ~79 dirt
setblock ~167 ~111 ~80 dirt
setblock ~167 ~111 ~81 dirt
setblock ~167 ~111 ~82 dirt
setblock ~167 ~111 ~83 dirt
setblock ~167 ~111 ~84 dirt
setblock ~167 ~111 ~85 dirt
setblock ~167 ~111 ~86 dirt
setblock ~167 ~111 ~87 dirt
setblock ~167 ~111 ~88 dirt
setblock ~167 ~111 ~89 dirt
setblock ~167 ~111 ~90 dirt
setblock ~167 ~112 ~74 dirt
setblock ~167 ~112 ~75 dirt
setblock ~167 ~112 ~76 dirt
setblock ~167 ~112 ~77 dirt
setblock ~167 ~112 ~78 dirt
setblock ~167 ~112 ~79 dirt
setblock ~167 ~112 ~80 dirt
setblock ~167 ~112 ~81 dirt
setblock ~167 ~112 ~82 dirt
setblock ~167 ~112 ~83 dirt
setblock ~167 ~112 ~84 dirt
setblock ~167 ~112 ~85 dirt
setblock ~167 ~112 ~86 dirt
setblock ~167 ~112 ~87 dirt
setblock ~167 ~112 ~88 dirt
setblock ~167 ~112 ~89 dirt
setblock ~167 ~112 ~90 dirt
setblock ~167 ~112 ~91 dirt
setblock ~167 ~113 ~72 dirt
setblock ~167 ~113 ~73 dirt
setblock ~167 ~113 ~74 dirt
setblock ~167 ~113 ~75 dirt
setblock ~167 ~113 ~76 dirt
setblock ~167 ~113 ~77 dirt
setblock ~167 ~113 ~78 dirt
setblock ~167 ~113 ~79 dirt
setblock ~167 ~113 ~80 dirt
setblock ~167 ~113 ~81 dirt
setblock ~167 ~113 ~82 dirt
setblock ~167 ~113 ~83 dirt
setblock ~167 ~113 ~84 dirt
setblock ~167 ~113 ~85 dirt
setblock ~167 ~113 ~86 dirt
setblock ~167 ~113 ~87 dirt
setblock ~167 ~113 ~88 dirt
setblock ~167 ~113 ~89 dirt
setblock ~167 ~113 ~90 dirt
setblock ~167 ~113 ~91 dirt
setblock ~167 ~114 ~71 dirt
setblock ~167 ~114 ~72 dirt
setblock ~167 ~114 ~73 dirt
setblock ~167 ~114 ~74 dirt
setblock ~167 ~114 ~75 dirt
setblock ~167 ~114 ~76 dirt
setblock ~167 ~114 ~77 dirt
setblock ~167 ~114 ~78 dirt
setblock ~167 ~114 ~79 dirt
setblock ~167 ~114 ~80 dirt
setblock ~167 ~114 ~81 dirt
setblock ~167 ~114 ~82 dirt
setblock ~167 ~114 ~83 dirt
setblock ~167 ~114 ~84 dirt
setblock ~167 ~114 ~85 dirt
setblock ~167 ~114 ~86 dirt
setblock ~167 ~114 ~87 dirt
setblock ~167 ~114 ~88 dirt
setblock ~167 ~114 ~89 dirt
setblock ~167 ~114 ~90 dirt
setblock ~167 ~114 ~91 dirt
setblock ~167 ~114 ~92 dirt
setblock ~167 ~114 ~96 dirt
setblock ~167 ~114 ~97 dirt
setblock ~167 ~115 ~71 dirt
setblock ~167 ~115 ~72 dirt
setblock ~167 ~115 ~73 dirt
setblock ~167 ~115 ~74 dirt
setblock ~167 ~115 ~75 dirt
setblock ~167 ~115 ~76 dirt
setblock ~167 ~115 ~77 dirt
setblock ~167 ~115 ~78 dirt
setblock ~167 ~115 ~79 dirt
setblock ~167 ~115 ~80 dirt
setblock ~167 ~115 ~81 dirt
setblock ~167 ~115 ~82 dirt
setblock ~167 ~115 ~83 dirt
setblock ~167 ~115 ~84 dirt
setblock ~167 ~115 ~85 dirt
setblock ~167 ~115 ~86 dirt
setblock ~167 ~115 ~87 dirt
setblock ~167 ~115 ~88 dirt
setblock ~167 ~115 ~89 dirt
setblock ~167 ~115 ~90 dirt
setblock ~167 ~115 ~91 dirt
setblock ~167 ~115 ~92 dirt
setblock ~167 ~115 ~93 dirt
setblock ~167 ~115 ~95 dirt
setblock ~167 ~115 ~96 dirt
setblock ~167 ~115 ~97 dirt
setblock ~167 ~115 ~98 dirt
setblock ~167 ~115 ~101 dirt
setblock ~167 ~115 ~104 dirt
setblock ~167 ~115 ~106 dirt
setblock ~167 ~116 ~71 dirt
setblock ~167 ~116 ~72 dirt
setblock ~167 ~116 ~73 dirt
setblock ~167 ~116 ~74 dirt
setblock ~167 ~116 ~75 dirt
setblock ~167 ~116 ~76 dirt
setblock ~167 ~116 ~77 dirt
setblock ~167 ~116 ~78 dirt
setblock ~167 ~116 ~79 dirt
setblock ~167 ~116 ~80 dirt
setblock ~167 ~116 ~81 dirt
setblock ~167 ~116 ~82 dirt
setblock ~167 ~116 ~83 dirt
setblock ~167 ~116 ~84 dirt
setblock ~167 ~116 ~85 dirt
setblock ~167 ~116 ~86 dirt
setblock ~167 ~116 ~87 dirt
setblock ~167 ~116 ~88 dirt
setblock ~167 ~116 ~89 dirt
setblock ~167 ~116 ~90 dirt
setblock ~167 ~116 ~91 dirt
setblock ~167 ~116 ~92 dirt
setblock ~167 ~116 ~93 dirt
setblock ~167 ~116 ~94 dirt
setblock ~167 ~116 ~95 dirt
setblock ~167 ~116 ~96 dirt
setblock ~167 ~116 ~97 dirt
setblock ~167 ~116 ~98 dirt
setblock ~167 ~116 ~100 dirt
setblock ~167 ~116 ~101 dirt
setblock ~167 ~116 ~102 dirt
setblock ~167 ~116 ~103 dirt
setblock ~167 ~116 ~104 dirt
setblock ~167 ~116 ~105 dirt
setblock ~167 ~116 ~106 dirt
setblock ~167 ~116 ~107 dirt
setblock ~167 ~117 ~69 dirt
setblock ~167 ~117 ~70 dirt
setblock ~167 ~117 ~71 dirt
setblock ~167 ~117 ~72 dirt
setblock ~167 ~117 ~73 dirt
setblock ~167 ~117 ~74 dirt
setblock ~167 ~117 ~75 dirt
setblock ~167 ~117 ~76 dirt
setblock ~167 ~117 ~77 dirt
setblock ~167 ~117 ~78 dirt
setblock ~167 ~117 ~79 dirt
setblock ~167 ~117 ~80 dirt
setblock ~167 ~117 ~81 dirt
setblock ~167 ~117 ~82 dirt
setblock ~167 ~117 ~83 dirt
setblock ~167 ~117 ~84 dirt
setblock ~167 ~117 ~85 dirt
setblock ~167 ~117 ~86 dirt
setblock ~167 ~117 ~87 dirt
setblock ~167 ~117 ~88 dirt
setblock ~167 ~117 ~89 dirt
setblock ~167 ~117 ~90 dirt
setblock ~167 ~117 ~91 dirt
setblock ~167 ~117 ~92 dirt
setblock ~167 ~117 ~93 dirt
setblock ~167 ~117 ~94 dirt
setblock ~167 ~117 ~95 dirt
setblock ~167 ~117 ~96 dirt
setblock ~167 ~117 ~97 dirt
setblock ~167 ~117 ~98 dirt
setblock ~167 ~117 ~99 dirt
setblock ~167 ~117 ~100 dirt
setblock ~167 ~117 ~101 dirt
setblock ~167 ~117 ~102 dirt
setblock ~167 ~117 ~103 dirt
setblock ~167 ~117 ~104 dirt
setblock ~167 ~117 ~105 dirt
setblock ~167 ~117 ~106 dirt
setblock ~167 ~117 ~107 dirt
setblock ~167 ~117 ~108 dirt
setblock ~167 ~118 ~69 dirt
setblock ~167 ~118 ~70 dirt
setblock ~167 ~118 ~71 dirt
setblock ~167 ~118 ~72 dirt
setblock ~167 ~118 ~73 dirt
setblock ~167 ~118 ~74 dirt
setblock ~167 ~118 ~75 dirt
setblock ~167 ~118 ~76 dirt
setblock ~167 ~118 ~77 dirt
setblock ~167 ~118 ~78 dirt
setblock ~167 ~118 ~79 dirt
setblock ~167 ~118 ~80 dirt
setblock ~167 ~118 ~81 dirt
setblock ~167 ~118 ~82 dirt
setblock ~167 ~118 ~83 dirt
setblock ~167 ~118 ~84 dirt
setblock ~167 ~118 ~85 dirt
setblock ~167 ~118 ~86 dirt
setblock ~167 ~118 ~87 dirt
setblock ~167 ~118 ~88 dirt
setblock ~167 ~118 ~89 dirt
setblock ~167 ~118 ~90 dirt
setblock ~167 ~118 ~91 dirt
setblock ~167 ~118 ~92 dirt
setblock ~167 ~118 ~93 dirt
setblock ~167 ~118 ~94 dirt
setblock ~167 ~118 ~95 dirt
setblock ~167 ~118 ~96 dirt
setblock ~167 ~118 ~97 dirt
setblock ~167 ~118 ~98 dirt
setblock ~167 ~118 ~99 dirt
setblock ~167 ~118 ~100 dirt
setblock ~167 ~118 ~101 dirt
setblock ~167 ~118 ~102 dirt
setblock ~167 ~118 ~103 dirt
setblock ~167 ~118 ~104 dirt
setblock ~167 ~118 ~105 dirt
setblock ~167 ~118 ~106 dirt
setblock ~167 ~118 ~107 dirt
setblock ~167 ~118 ~108 dirt
setblock ~167 ~119 ~68 dirt
setblock ~167 ~119 ~69 dirt
setblock ~167 ~119 ~70 dirt
setblock ~167 ~119 ~71 dirt
setblock ~167 ~119 ~72 dirt
setblock ~167 ~119 ~73 dirt
setblock ~167 ~119 ~74 dirt
setblock ~167 ~119 ~75 dirt
setblock ~167 ~119 ~76 dirt
setblock ~167 ~119 ~77 dirt
setblock ~167 ~119 ~78 dirt
setblock ~167 ~119 ~79 dirt
setblock ~167 ~119 ~80 dirt
setblock ~167 ~119 ~81 dirt
setblock ~167 ~119 ~82 dirt
setblock ~167 ~119 ~83 dirt
setblock ~167 ~119 ~84 dirt
setblock ~167 ~119 ~85 dirt
setblock ~167 ~119 ~86 dirt
setblock ~167 ~119 ~87 dirt
setblock ~167 ~119 ~88 dirt
setblock ~167 ~119 ~89 dirt
setblock ~167 ~119 ~90 dirt
setblock ~167 ~119 ~91 dirt
setblock ~167 ~119 ~92 dirt
setblock ~167 ~119 ~93 dirt
setblock ~167 ~119 ~94 dirt
setblock ~167 ~119 ~95 dirt
setblock ~167 ~119 ~96 dirt
setblock ~167 ~119 ~97 dirt
setblock ~167 ~119 ~98 dirt
setblock ~167 ~119 ~99 dirt
setblock ~167 ~119 ~100 dirt
setblock ~167 ~119 ~101 dirt
setblock ~167 ~119 ~102 dirt
setblock ~167 ~119 ~103 dirt
setblock ~167 ~119 ~104 dirt
setblock ~167 ~119 ~105 dirt
setblock ~167 ~119 ~106 dirt
setblock ~167 ~119 ~107 dirt
setblock ~167 ~119 ~108 dirt
setblock ~167 ~119 ~109 dirt
setblock ~167 ~119 ~110 dirt
setblock ~167 ~120 ~67 dirt
setblock ~167 ~120 ~68 dirt
setblock ~167 ~120 ~69 dirt
setblock ~167 ~120 ~70 dirt
setblock ~167 ~120 ~71 dirt
setblock ~167 ~120 ~72 dirt
setblock ~167 ~120 ~73 dirt
setblock ~167 ~120 ~74 dirt
setblock ~167 ~120 ~75 dirt
setblock ~167 ~120 ~76 dirt
setblock ~167 ~120 ~77 dirt
setblock ~167 ~120 ~78 dirt
setblock ~167 ~120 ~79 dirt
setblock ~167 ~120 ~80 dirt
setblock ~167 ~120 ~81 dirt
setblock ~167 ~120 ~82 dirt
setblock ~167 ~120 ~83 dirt
setblock ~167 ~120 ~84 dirt
setblock ~167 ~120 ~85 dirt
setblock ~167 ~120 ~86 dirt
setblock ~167 ~120 ~87 dirt
setblock ~167 ~120 ~88 dirt
setblock ~167 ~120 ~89 dirt
setblock ~167 ~120 ~90 dirt
setblock ~167 ~120 ~91 dirt
setblock ~167 ~120 ~92 dirt
setblock ~167 ~120 ~93 dirt
setblock ~167 ~120 ~94 dirt
setblock ~167 ~120 ~95 dirt
setblock ~167 ~120 ~96 dirt
setblock ~167 ~120 ~97 dirt
setblock ~167 ~120 ~98 dirt
setblock ~167 ~120 ~99 dirt
setblock ~167 ~120 ~100 dirt
setblock ~167 ~120 ~101 dirt
setblock ~167 ~120 ~102 dirt
setblock ~167 ~120 ~103 dirt
setblock ~167 ~120 ~104 dirt
setblock ~167 ~120 ~105 dirt
setblock ~167 ~120 ~106 dirt
setblock ~167 ~120 ~107 dirt
setblock ~167 ~120 ~108 dirt
setblock ~167 ~120 ~109 dirt
setblock ~167 ~120 ~110 dirt
setblock ~167 ~121 ~67 dirt
setblock ~167 ~121 ~68 dirt
setblock ~167 ~121 ~69 dirt
setblock ~167 ~121 ~70 dirt
setblock ~167 ~121 ~71 dirt
setblock ~167 ~121 ~72 dirt
setblock ~167 ~121 ~73 dirt
setblock ~167 ~121 ~74 dirt
setblock ~167 ~121 ~75 dirt
setblock ~167 ~121 ~76 dirt
setblock ~167 ~121 ~77 dirt
setblock ~167 ~121 ~78 dirt
setblock ~167 ~121 ~79 dirt
setblock ~167 ~121 ~80 dirt
setblock ~167 ~121 ~81 dirt
setblock ~167 ~121 ~82 dirt
setblock ~167 ~121 ~83 dirt
setblock ~167 ~121 ~84 dirt
setblock ~167 ~121 ~85 dirt
setblock ~167 ~121 ~86 dirt
setblock ~167 ~121 ~87 dirt
setblock ~167 ~121 ~88 dirt
setblock ~167 ~121 ~89 dirt
setblock ~167 ~121 ~90 dirt
setblock ~167 ~121 ~91 dirt
setblock ~167 ~121 ~92 dirt
setblock ~167 ~121 ~93 dirt
setblock ~167 ~121 ~94 dirt
setblock ~167 ~121 ~95 dirt
setblock ~167 ~121 ~96 dirt
setblock ~167 ~121 ~97 dirt
setblock ~167 ~121 ~98 dirt
setblock ~167 ~121 ~99 dirt
setblock ~167 ~121 ~100 dirt
setblock ~167 ~121 ~101 dirt
setblock ~167 ~121 ~102 dirt
setblock ~167 ~121 ~103 dirt
setblock ~167 ~121 ~104 dirt
setblock ~167 ~121 ~105 dirt
setblock ~167 ~121 ~106 dirt
setblock ~167 ~121 ~107 dirt
setblock ~167 ~121 ~108 dirt
setblock ~167 ~121 ~109 dirt
setblock ~167 ~121 ~110 dirt
setblock ~167 ~121 ~111 dirt
setblock ~167 ~122 ~67 dirt
setblock ~167 ~122 ~68 dirt
setblock ~167 ~122 ~69 dirt
setblock ~167 ~122 ~70 dirt
setblock ~167 ~122 ~71 dirt
setblock ~167 ~122 ~72 dirt
setblock ~167 ~122 ~73 dirt
setblock ~167 ~122 ~74 dirt
setblock ~167 ~122 ~75 dirt
setblock ~167 ~122 ~76 dirt
setblock ~167 ~122 ~77 dirt
setblock ~167 ~122 ~78 dirt
setblock ~167 ~122 ~79 dirt
setblock ~167 ~122 ~80 dirt
setblock ~167 ~122 ~81 dirt
setblock ~167 ~122 ~82 dirt
setblock ~167 ~122 ~83 dirt
setblock ~167 ~122 ~84 dirt
setblock ~167 ~122 ~85 dirt
setblock ~167 ~122 ~86 dirt
setblock ~167 ~122 ~87 dirt
setblock ~167 ~122 ~88 dirt
setblock ~167 ~122 ~89 dirt
setblock ~167 ~122 ~90 dirt
setblock ~167 ~122 ~91 dirt
setblock ~167 ~122 ~92 dirt
setblock ~167 ~122 ~93 dirt
setblock ~167 ~122 ~94 dirt
setblock ~167 ~122 ~95 dirt
setblock ~167 ~122 ~96 dirt
setblock ~167 ~122 ~97 dirt
setblock ~167 ~122 ~98 dirt
setblock ~167 ~122 ~99 dirt
setblock ~167 ~122 ~100 dirt
setblock ~167 ~122 ~101 dirt
setblock ~167 ~122 ~102 dirt
setblock ~167 ~122 ~103 dirt
setblock ~167 ~122 ~104 dirt
setblock ~167 ~122 ~105 dirt
setblock ~167 ~122 ~106 dirt
setblock ~167 ~122 ~107 dirt
setblock ~167 ~122 ~108 dirt
setblock ~167 ~122 ~109 dirt
setblock ~167 ~122 ~110 dirt
setblock ~167 ~122 ~111 dirt
setblock ~167 ~123 ~67 grass_block
setblock ~167 ~123 ~68 grass_block
setblock ~167 ~123 ~69 grass_block
setblock ~167 ~123 ~70 grass_block
setblock ~167 ~123 ~71 grass_block
setblock ~167 ~123 ~72 grass_block
setblock ~167 ~123 ~73 dirt
setblock ~167 ~123 ~74 dirt
setblock ~167 ~123 ~75 dirt
setblock ~167 ~123 ~76 dirt
setblock ~167 ~123 ~77 dirt
setblock ~167 ~123 ~78 dirt
setblock ~167 ~123 ~79 dirt
setblock ~167 ~123 ~80 dirt
setblock ~167 ~123 ~81 dirt
setblock ~167 ~123 ~82 dirt
setblock ~167 ~123 ~83 dirt
setblock ~167 ~123 ~84 dirt
setblock ~167 ~123 ~85 dirt
setblock ~167 ~123 ~86 dirt
setblock ~167 ~123 ~87 dirt
setblock ~167 ~123 ~88 dirt
setblock ~167 ~123 ~89 dirt
setblock ~167 ~123 ~90 dirt
setblock ~167 ~123 ~91 dirt
setblock ~167 ~123 ~92 dirt
setblock ~167 ~123 ~93 dirt
setblock ~167 ~123 ~94 dirt
setblock ~167 ~123 ~95 dirt
setblock ~167 ~123 ~96 dirt
setblock ~167 ~123 ~97 dirt
setblock ~167 ~123 ~98 dirt
setblock ~167 ~123 ~99 dirt
setblock ~167 ~123 ~100 dirt
setblock ~167 ~123 ~101 dirt
setblock ~167 ~123 ~102 dirt
setblock ~167 ~123 ~103 dirt
setblock ~167 ~123 ~104 dirt
setblock ~167 ~123 ~105 grass_block
setblock ~167 ~123 ~106 grass_block
setblock ~167 ~123 ~107 grass_block
setblock ~167 ~123 ~108 grass_block
setblock ~167 ~123 ~109 grass_block
setblock ~167 ~123 ~110 grass_block
setblock ~167 ~123 ~111 grass_block
setblock ~167 ~124 ~67 short_grass
setblock ~167 ~124 ~70 short_grass
setblock ~167 ~124 ~73 grass_block
setblock ~167 ~124 ~74 grass_block
setblock ~167 ~124 ~75 grass_block
setblock ~167 ~124 ~76 dirt
setblock ~167 ~124 ~77 dirt
setblock ~167 ~124 ~78 dirt
setblock ~167 ~124 ~79 dirt
setblock ~167 ~124 ~80 dirt
setblock ~167 ~124 ~81 dirt
setblock ~167 ~124 ~82 dirt
setblock ~167 ~124 ~83 dirt
setblock ~167 ~124 ~84 dirt
setblock ~167 ~124 ~85 dirt
setblock ~167 ~124 ~86 dirt
setblock ~167 ~124 ~87 dirt
setblock ~167 ~124 ~88 dirt
setblock ~167 ~124 ~89 dirt
setblock ~167 ~124 ~90 dirt
setblock ~167 ~124 ~91 dirt
setblock ~167 ~124 ~92 dirt
setblock ~167 ~124 ~93 dirt
setblock ~167 ~124 ~94 dirt
setblock ~167 ~124 ~95 dirt
setblock ~167 ~124 ~96 dirt
setblock ~167 ~124 ~97 grass_block
setblock ~167 ~124 ~98 grass_block
setblock ~167 ~124 ~99 grass_block
setblock ~167 ~124 ~100 grass_block
setblock ~167 ~124 ~101 grass_block
setblock ~167 ~124 ~102 grass_block
setblock ~167 ~124 ~103 grass_block
setblock ~167 ~124 ~104 grass_block
setblock ~167 ~124 ~107 short_grass
setblock ~167 ~124 ~111 short_grass
setblock ~167 ~125 ~75 short_grass
setblock ~167 ~125 ~76 grass_block
setblock ~167 ~125 ~77 grass_block
setblock ~167 ~125 ~78 grass_block
setblock ~167 ~125 ~79 dirt
setblock ~167 ~125 ~80 dirt
setblock ~167 ~125 ~81 dirt
setblock ~167 ~125 ~82 dirt
setblock ~167 ~125 ~83 dirt
setblock ~167 ~125 ~84 dirt
setblock ~167 ~125 ~85 dirt
setblock ~167 ~125 ~86 dirt
setblock ~167 ~125 ~87 dirt
setblock ~167 ~125 ~88 dirt
setblock ~167 ~125 ~89 dirt
setblock ~167 ~125 ~90 dirt
setblock ~167 ~125 ~91 dirt
setblock ~167 ~125 ~92 dirt
setblock ~167 ~125 ~93 grass_block
setblock ~167 ~125 ~94 grass_block
setblock ~167 ~125 ~95 grass_block
setblock ~167 ~125 ~96 grass_block
setblock ~167 ~126 ~78 short_grass
setblock ~167 ~126 ~79 grass_block
setblock ~167 ~126 ~80 grass_block
setblock ~167 ~126 ~81 grass_block
setblock ~167 ~126 ~82 grass_block
setblock ~167 ~126 ~83 grass_block
setblock ~167 ~126 ~84 grass_block
setblock ~167 ~126 ~85 grass_block
setblock ~167 ~126 ~86 grass_block
setblock ~167 ~126 ~87 grass_block
setblock ~167 ~126 ~88 grass_block
setblock ~167 ~126 ~89 grass_block
setblock ~167 ~126 ~90 grass_block
setblock ~167 ~126 ~91 grass_block
setblock ~167 ~126 ~92 grass_block
setblock ~167 ~127 ~79 short_grass
setblock ~167 ~127 ~81 poppy
setblock ~167 ~127 ~87 short_grass
setblock ~167 ~127 ~88 short_grass
setblock ~167 ~127 ~90 poppy
setblock ~168 ~105 ~81 dirt
setblock ~168 ~105 ~85 dirt
setblock ~168 ~106 ~81 dirt
setblock ~168 ~106 ~85 dirt
setblock ~168 ~107 ~81 dirt
setblock ~168 ~107 ~82 dirt
setblock ~168 ~107 ~84 dirt
setblock ~168 ~107 ~85 dirt
setblock ~168 ~107 ~86 dirt
setblock ~168 ~108 ~80 dirt
setblock ~168 ~108 ~81 dirt
setblock ~168 ~108 ~82 dirt
setblock ~168 ~108 ~83 dirt
setblock ~168 ~108 ~84 dirt
setblock ~168 ~108 ~85 dirt
setblock ~168 ~108 ~86 dirt
setblock ~168 ~109 ~80 dirt
setblock ~168 ~109 ~81 dirt
setblock ~168 ~109 ~82 dirt
setblock ~168 ~109 ~83 dirt
setblock ~168 ~109 ~84 dirt
setblock ~168 ~109 ~85 dirt
setblock ~168 ~109 ~86 dirt
setblock ~168 ~109 ~87 dirt
setblock ~168 ~110 ~79 dirt
setblock ~168 ~110 ~80 dirt
setblock ~168 ~110 ~81 dirt
setblock ~168 ~110 ~82 dirt
setblock ~168 ~110 ~83 dirt
setblock ~168 ~110 ~84 dirt
setblock ~168 ~110 ~85 dirt
setblock ~168 ~110 ~86 dirt
setblock ~168 ~110 ~87 dirt
setblock ~168 ~110 ~88 dirt
setblock ~168 ~111 ~77 dirt
setblock ~168 ~111 ~78 dirt
setblock ~168 ~111 ~79 dirt
setblock ~168 ~111 ~80 dirt
setblock ~168 ~111 ~81 dirt
setblock ~168 ~111 ~82 dirt
setblock ~168 ~111 ~83 dirt
setblock ~168 ~111 ~84 dirt
setblock ~168 ~111 ~85 dirt
setblock ~168 ~111 ~86 dirt
setblock ~168 ~111 ~87 dirt
setblock ~168 ~111 ~88 dirt
setblock ~168 ~111 ~89 dirt
setblock ~168 ~112 ~75 dirt
setblock ~168 ~112 ~77 dirt
setblock ~168 ~112 ~78 dirt
setblock ~168 ~112 ~79 dirt
setblock ~168 ~112 ~80 dirt
setblock ~168 ~112 ~81 dirt
setblock ~168 ~112 ~82 dirt
setblock ~168 ~112 ~83 dirt
setblock ~168 ~112 ~84 dirt
setblock ~168 ~112 ~85 dirt
setblock ~168 ~112 ~86 dirt
setblock ~168 ~112 ~87 dirt
setblock ~168 ~112 ~88 dirt
setblock ~168 ~112 ~89 dirt
setblock ~168 ~112 ~90 dirt
setblock ~168 ~113 ~74 dirt
setblock ~168 ~113 ~75 dirt
setblock ~168 ~113 ~76 dirt
setblock ~168 ~113 ~77 dirt
setblock ~168 ~113 ~78 dirt
setblock ~168 ~113 ~79 dirt
setblock ~168 ~113 ~80 dirt
setblock ~168 ~113 ~81 dirt
setblock ~168 ~113 ~82 dirt
setblock ~168 ~113 ~83 dirt
setblock ~168 ~113 ~84 dirt
setblock ~168 ~113 ~85 dirt
setblock ~168 ~113 ~86 dirt
setblock ~168 ~113 ~87 dirt
setblock ~168 ~113 ~88 dirt
setblock ~168 ~113 ~89 dirt
setblock ~168 ~113 ~90 dirt
setblock ~168 ~114 ~72 dirt
setblock ~168 ~114 ~73 dirt
setblock ~168 ~114 ~74 dirt
setblock ~168 ~114 ~75 dirt
setblock ~168 ~114 ~76 dirt
setblock ~168 ~114 ~77 dirt
setblock ~168 ~114 ~78 dirt
setblock ~168 ~114 ~79 dirt
setblock ~168 ~114 ~80 dirt
setblock ~168 ~114 ~81 dirt
setblock ~168 ~114 ~82 dirt
setblock ~168 ~114 ~83 dirt
setblock ~168 ~114 ~84 dirt
setblock ~168 ~114 ~85 dirt
setblock ~168 ~114 ~86 dirt
setblock ~168 ~114 ~87 dirt
setblock ~168 ~114 ~88 dirt
setblock ~168 ~114 ~89 dirt
setblock ~168 ~114 ~90 dirt
setblock ~168 ~114 ~91 dirt
setblock ~168 ~115 ~72 dirt
setblock ~168 ~115 ~73 dirt
setblock ~168 ~115 ~74 dirt
setblock ~168 ~115 ~75 dirt
setblock ~168 ~115 ~76 dirt
setblock ~168 ~115 ~77 dirt
setblock ~168 ~115 ~78 dirt
setblock ~168 ~115 ~79 dirt
setblock ~168 ~115 ~80 dirt
setblock ~168 ~115 ~81 dirt
setblock ~168 ~115 ~82 dirt
setblock ~168 ~115 ~83 dirt
setblock ~168 ~115 ~84 dirt
setblock ~168 ~115 ~85 dirt
setblock ~168 ~115 ~86 dirt
setblock ~168 ~115 ~87 dirt
setblock ~168 ~115 ~88 dirt
setblock ~168 ~115 ~89 dirt
setblock ~168 ~115 ~90 dirt
setblock ~168 ~115 ~91 dirt
setblock ~168 ~115 ~96 dirt
setblock ~168 ~116 ~72 dirt
setblock ~168 ~116 ~73 dirt
setblock ~168 ~116 ~74 dirt
setblock ~168 ~116 ~75 dirt
setblock ~168 ~116 ~76 dirt
setblock ~168 ~116 ~77 dirt
setblock ~168 ~116 ~78 dirt
setblock ~168 ~116 ~79 dirt
setblock ~168 ~116 ~80 dirt
setblock ~168 ~116 ~81 dirt
setblock ~168 ~116 ~82 dirt
setblock ~168 ~116 ~83 dirt
setblock ~168 ~116 ~84 dirt
setblock ~168 ~116 ~85 dirt
setblock ~168 ~116 ~86 dirt
setblock ~168 ~116 ~87 dirt
setblock ~168 ~116 ~88 dirt
setblock ~168 ~116 ~89 dirt
setblock ~168 ~116 ~90 dirt
setblock ~168 ~116 ~91 dirt
setblock ~168 ~116 ~96 dirt
setblock ~168 ~116 ~101 dirt
setblock ~168 ~117 ~71 dirt
setblock ~168 ~117 ~72 dirt
setblock ~168 ~117 ~73 dirt
setblock ~168 ~117 ~74 dirt
setblock ~168 ~117 ~75 dirt
setblock ~168 ~117 ~76 dirt
setblock ~168 ~117 ~77 dirt
setblock ~168 ~117 ~78 dirt
setblock ~168 ~117 ~79 dirt
setblock ~168 ~117 ~80 dirt
setblock ~168 ~117 ~81 dirt
setblock ~168 ~117 ~82 dirt
setblock ~168 ~117 ~83 dirt
setblock ~168 ~117 ~84 dirt
setblock ~168 ~117 ~85 dirt
setblock ~168 ~117 ~86 dirt
setblock ~168 ~117 ~87 dirt
setblock ~168 ~117 ~88 dirt
setblock ~168 ~117 ~89 dirt
setblock ~168 ~117 ~90 dirt
setblock ~168 ~117 ~91 dirt
setblock ~168 ~117 ~92 dirt
setblock ~168 ~117 ~96 dirt
setblock ~168 ~117 ~97 dirt
setblock ~168 ~117 ~100 dirt
setblock ~168 ~117 ~101 dirt
setblock ~168 ~117 ~102 dirt
setblock ~168 ~117 ~106 dirt
setblock ~168 ~118 ~71 dirt
setblock ~168 ~118 ~72 dirt
setblock ~168 ~118 ~73 dirt
setblock ~168 ~118 ~74 dirt
setblock ~168 ~118 ~75 dirt
setblock ~168 ~118 ~76 dirt
setblock ~168 ~118 ~77 dirt
setblock ~168 ~118 ~78 dirt
setblock ~168 ~118 ~79 dirt
setblock ~168 ~118 ~80 dirt
setblock ~168 ~118 ~81 dirt
setblock ~168 ~118 ~82 dirt
setblock ~168 ~118 ~83 dirt
setblock ~168 ~118 ~84 dirt
setblock ~168 ~118 ~85 dirt
setblock ~168 ~118 ~86 dirt
setblock ~168 ~118 ~87 dirt
setblock ~168 ~118 ~88 dirt
setblock ~168 ~118 ~89 dirt
setblock ~168 ~118 ~90 dirt
setblock ~168 ~118 ~91 dirt
setblock ~168 ~118 ~92 dirt
setblock ~168 ~118 ~93 dirt
setblock ~168 ~118 ~94 dirt
setblock ~168 ~118 ~95 dirt
setblock ~168 ~118 ~96 dirt
setblock ~168 ~118 ~97 dirt
setblock ~168 ~118 ~98 dirt
setblock ~168 ~118 ~99 dirt
setblock ~168 ~118 ~100 dirt
setblock ~168 ~118 ~101 dirt
setblock ~168 ~118 ~102 dirt
setblock ~168 ~118 ~106 dirt
setblock ~168 ~118 ~107 dirt
setblock ~168 ~119 ~69 dirt
setblock ~168 ~119 ~70 dirt
setblock ~168 ~119 ~71 dirt
setblock ~168 ~119 ~72 dirt
setblock ~168 ~119 ~73 dirt
setblock ~168 ~119 ~74 dirt
setblock ~168 ~119 ~75 dirt
setblock ~168 ~119 ~76 dirt
setblock ~168 ~119 ~77 dirt
setblock ~168 ~119 ~78 dirt
setblock ~168 ~119 ~79 dirt
setblock ~168 ~119 ~80 dirt
setblock ~168 ~119 ~81 dirt
setblock ~168 ~119 ~82 dirt
setblock ~168 ~119 ~83 dirt
setblock ~168 ~119 ~84 dirt
setblock ~168 ~119 ~85 dirt
setblock ~168 ~119 ~86 dirt
setblock ~168 ~119 ~87 dirt
setblock ~168 ~119 ~88 dirt
setblock ~168 ~119 ~89 dirt
setblock ~168 ~119 ~90 dirt
setblock ~168 ~119 ~91 dirt
setblock ~168 ~119 ~92 dirt
setblock ~168 ~119 ~93 dirt
setblock ~168 ~119 ~94 dirt
setblock ~168 ~119 ~95 dirt
setblock ~168 ~119 ~96 dirt
setblock ~168 ~119 ~97 dirt
setblock ~168 ~119 ~98 dirt
setblock ~168 ~119 ~99 dirt
setblock ~168 ~119 ~100 dirt
setblock ~168 ~119 ~101 dirt
setblock ~168 ~119 ~102 dirt
setblock ~168 ~119 ~103 dirt
setblock ~168 ~119 ~104 dirt
setblock ~168 ~119 ~106 dirt
setblock ~168 ~119 ~107 dirt
setblock ~168 ~119 ~108 dirt
setblock ~168 ~120 ~69 dirt
setblock ~168 ~120 ~70 dirt
setblock ~168 ~120 ~71 dirt
setblock ~168 ~120 ~72 dirt
setblock ~168 ~120 ~73 dirt
setblock ~168 ~120 ~74 dirt
setblock ~168 ~120 ~75 dirt
setblock ~168 ~120 ~76 dirt
setblock ~168 ~120 ~77 dirt
setblock ~168 ~120 ~78 dirt
setblock ~168 ~120 ~79 dirt
setblock ~168 ~120 ~80 dirt
setblock ~168 ~120 ~81 dirt
setblock ~168 ~120 ~82 dirt
setblock ~168 ~120 ~83 dirt
setblock ~168 ~120 ~84 dirt
setblock ~168 ~120 ~85 dirt
setblock ~168 ~120 ~86 dirt
setblock ~168 ~120 ~87 dirt
setblock ~168 ~120 ~88 dirt
setblock ~168 ~120 ~89 dirt
setblock ~168 ~120 ~90 dirt
setblock ~168 ~120 ~91 dirt
setblock ~168 ~120 ~92 dirt
setblock ~168 ~120 ~93 dirt
setblock ~168 ~120 ~94 dirt
setblock ~168 ~120 ~95 dirt
setblock ~168 ~120 ~96 dirt
setblock ~168 ~120 ~97 dirt
setblock ~168 ~120 ~98 dirt
setblock ~168 ~120 ~99 dirt
setblock ~168 ~120 ~100 dirt
setblock ~168 ~120 ~101 dirt
setblock ~168 ~120 ~102 dirt
setblock ~168 ~120 ~103 dirt
setblock ~168 ~120 ~104 dirt
setblock ~168 ~120 ~105 dirt
setblock ~168 ~120 ~106 dirt
setblock ~168 ~120 ~107 dirt
setblock ~168 ~120 ~108 dirt
setblock ~168 ~121 ~68 dirt
setblock ~168 ~121 ~69 dirt
setblock ~168 ~121 ~70 dirt
setblock ~168 ~121 ~71 dirt
setblock ~168 ~121 ~72 dirt
setblock ~168 ~121 ~73 dirt
setblock ~168 ~121 ~74 dirt
setblock ~168 ~121 ~75 dirt
setblock ~168 ~121 ~76 dirt
setblock ~168 ~121 ~77 dirt
setblock ~168 ~121 ~78 dirt
setblock ~168 ~121 ~79 dirt
setblock ~168 ~121 ~80 dirt
setblock ~168 ~121 ~81 dirt
setblock ~168 ~121 ~82 dirt
setblock ~168 ~121 ~83 dirt
setblock ~168 ~121 ~84 dirt
setblock ~168 ~121 ~85 dirt
setblock ~168 ~121 ~86 dirt
setblock ~168 ~121 ~87 dirt
setblock ~168 ~121 ~88 dirt
setblock ~168 ~121 ~89 dirt
setblock ~168 ~121 ~90 dirt
setblock ~168 ~121 ~91 dirt
setblock ~168 ~121 ~92 dirt
setblock ~168 ~121 ~93 dirt
setblock ~168 ~121 ~94 dirt
setblock ~168 ~121 ~95 dirt
setblock ~168 ~121 ~96 dirt
setblock ~168 ~121 ~97 dirt
setblock ~168 ~121 ~98 dirt
setblock ~168 ~121 ~99 dirt
setblock ~168 ~121 ~100 dirt
setblock ~168 ~121 ~101 dirt
setblock ~168 ~121 ~102 dirt
setblock ~168 ~121 ~103 dirt
setblock ~168 ~121 ~104 dirt
setblock ~168 ~121 ~105 dirt
setblock ~168 ~121 ~106 dirt
setblock ~168 ~121 ~107 dirt
setblock ~168 ~121 ~108 dirt
setblock ~168 ~121 ~109 dirt
setblock ~168 ~121 ~110 dirt
setblock ~168 ~122 ~68 dirt
setblock ~168 ~122 ~69 dirt
setblock ~168 ~122 ~70 dirt
setblock ~168 ~122 ~71 dirt
setblock ~168 ~122 ~72 dirt
setblock ~168 ~122 ~73 dirt
setblock ~168 ~122 ~74 dirt
setblock ~168 ~122 ~75 dirt
setblock ~168 ~122 ~76 dirt
setblock ~168 ~122 ~77 dirt
setblock ~168 ~122 ~78 dirt
setblock ~168 ~122 ~79 dirt
setblock ~168 ~122 ~80 dirt
setblock ~168 ~122 ~81 dirt
setblock ~168 ~122 ~82 dirt
setblock ~168 ~122 ~83 dirt
setblock ~168 ~122 ~84 dirt
setblock ~168 ~122 ~85 dirt
setblock ~168 ~122 ~86 dirt
setblock ~168 ~122 ~87 dirt
setblock ~168 ~122 ~88 dirt
setblock ~168 ~122 ~89 dirt
setblock ~168 ~122 ~90 dirt
setblock ~168 ~122 ~91 dirt
setblock ~168 ~122 ~92 dirt
setblock ~168 ~122 ~93 dirt
setblock ~168 ~122 ~94 dirt
setblock ~168 ~122 ~95 dirt
setblock ~168 ~122 ~96 dirt
setblock ~168 ~122 ~97 dirt
setblock ~168 ~122 ~98 dirt
setblock ~168 ~122 ~99 dirt
setblock ~168 ~122 ~100 dirt
setblock ~168 ~122 ~101 dirt
setblock ~168 ~122 ~102 dirt
setblock ~168 ~122 ~103 dirt
setblock ~168 ~122 ~104 dirt
setblock ~168 ~122 ~105 dirt
setblock ~168 ~122 ~106 dirt
setblock ~168 ~122 ~107 dirt
setblock ~168 ~122 ~108 dirt
setblock ~168 ~122 ~109 dirt
setblock ~168 ~122 ~110 grass_block
setblock ~168 ~123 ~68 grass_block
setblock ~168 ~123 ~69 grass_block
setblock ~168 ~123 ~70 grass_block
setblock ~168 ~123 ~71 grass_block
setblock ~168 ~123 ~72 grass_block
setblock ~168 ~123 ~73 dirt
setblock ~168 ~123 ~74 dirt
setblock ~168 ~123 ~75 dirt
setblock ~168 ~123 ~76 dirt
setblock ~168 ~123 ~77 dirt
setblock ~168 ~123 ~78 dirt
setblock ~168 ~123 ~79 dirt
setblock ~168 ~123 ~80 dirt
setblock ~168 ~123 ~81 dirt
setblock ~168 ~123 ~82 dirt
setblock ~168 ~123 ~83 dirt
setblock ~168 ~123 ~84 dirt
setblock ~168 ~123 ~85 dirt
setblock ~168 ~123 ~86 dirt
setblock ~168 ~123 ~87 dirt
setblock ~168 ~123 ~88 dirt
setblock ~168 ~123 ~89 dirt
setblock ~168 ~123 ~90 dirt
setblock ~168 ~123 ~91 dirt
setblock ~168 ~123 ~92 dirt
setblock ~168 ~123 ~93 dirt
setblock ~168 ~123 ~94 dirt
setblock ~168 ~123 ~95 dirt
setblock ~168 ~123 ~96 dirt
setblock ~168 ~123 ~97 dirt
setblock ~168 ~123 ~98 dirt
setblock ~168 ~123 ~99 grass_block
setblock ~168 ~123 ~100 grass_block
setblock ~168 ~123 ~101 grass_block
setblock ~168 ~123 ~102 grass_block
setblock ~168 ~123 ~103 grass_block
setblock ~168 ~123 ~104 grass_block
setblock ~168 ~123 ~105 grass_block
setblock ~168 ~123 ~106 grass_block
setblock ~168 ~123 ~107 grass_block
setblock ~168 ~123 ~108 grass_block
setblock ~168 ~123 ~109 grass_block
setblock ~168 ~124 ~73 grass_block
setblock ~168 ~124 ~74 grass_block
setblock ~168 ~124 ~75 grass_block
setblock ~168 ~124 ~76 dirt
setblock ~168 ~124 ~77 dirt
setblock ~168 ~124 ~78 dirt
setblock ~168 ~124 ~79 dirt
setblock ~168 ~124 ~80 dirt
setblock ~168 ~124 ~81 dirt
setblock ~168 ~124 ~82 dirt
setblock ~168 ~124 ~83 dirt
setblock ~168 ~124 ~84 dirt
setblock ~168 ~124 ~85 dirt
setblock ~168 ~124 ~86 dirt
setblock ~168 ~124 ~87 dirt
setblock ~168 ~124 ~88 dirt
setblock ~168 ~124 ~89 dirt
setblock ~168 ~124 ~90 dirt
setblock ~168 ~124 ~91 dirt
setblock ~168 ~124 ~92 dirt
setblock ~168 ~124 ~93 dirt
setblock ~168 ~124 ~94 dirt
setblock ~168 ~124 ~95 dirt
setblock ~168 ~124 ~96 grass_block
setblock ~168 ~124 ~97 grass_block
setblock ~168 ~124 ~98 grass_block
setblock ~168 ~124 ~104 short_grass
setblock ~168 ~124 ~108 fern
setblock ~168 ~125 ~73 short_grass
setblock ~168 ~125 ~76 grass_block
setblock ~168 ~125 ~77 grass_block
setblock ~168 ~125 ~78 grass_block
setblock ~168 ~125 ~79 dirt
setblock ~168 ~125 ~80 dirt
setblock ~168 ~125 ~81 dirt
setblock ~168 ~125 ~82 dirt
setblock ~168 ~125 ~83 dirt
setblock ~168 ~125 ~84 dirt
setblock ~168 ~125 ~85 dirt
setblock ~168 ~125 ~86 dirt
setblock ~168 ~125 ~87 dirt
setblock ~168 ~125 ~88 dirt
setblock ~168 ~125 ~89 dirt
setblock ~168 ~125 ~90 dirt
setblock ~168 ~125 ~91 dirt
setblock ~168 ~125 ~92 dirt
setblock ~168 ~125 ~93 grass_block
setblock ~168 ~125 ~94 grass_block
setblock ~168 ~125 ~95 grass_block
setblock ~168 ~125 ~97 poppy
setblock ~168 ~126 ~79 grass_block
setblock ~168 ~126 ~80 grass_block
setblock ~168 ~126 ~81 grass_block
setblock ~168 ~126 ~82 grass_block
setblock ~168 ~126 ~83 grass_block
setblock ~168 ~126 ~84 grass_block
setblock ~168 ~126 ~85 grass_block
setblock ~168 ~126 ~86 grass_block
setblock ~168 ~126 ~87 grass_block
setblock ~168 ~126 ~88 grass_block
setblock ~168 ~126 ~89 grass_block
setblock ~168 ~126 ~90 grass_block
setblock ~168 ~126 ~91 grass_block
setblock ~168 ~126 ~92 grass_block
setblock ~168 ~126 ~95 short_grass
setblock ~168 ~127 ~88 short_grass
setblock ~168 ~127 ~90 fern
setblock ~169 ~107 ~85 dirt
setblock ~169 ~108 ~82 dirt
setblock ~169 ~108 ~85 dirt
setblock ~169 ~109 ~81 dirt
setblock ~169 ~109 ~82 dirt
setblock ~169 ~109 ~83 dirt
setblock ~169 ~109 ~84 dirt
setblock ~169 ~109 ~85 dirt
setblock ~169 ~109 ~86 dirt
setblock ~169 ~110 ~80 dirt
setblock ~169 ~110 ~81 dirt
setblock ~169 ~110 ~82 dirt
setblock ~169 ~110 ~83 dirt
setblock ~169 ~110 ~84 dirt
setblock ~169 ~110 ~85 dirt
setblock ~169 ~110 ~86 dirt
setblock ~169 ~110 ~87 dirt
setblock ~169 ~111 ~80 dirt
setblock ~169 ~111 ~81 dirt
setblock ~169 ~111 ~82 dirt
setblock ~169 ~111 ~83 dirt
setblock ~169 ~111 ~84 dirt
setblock ~169 ~111 ~85 dirt
setblock ~169 ~111 ~86 dirt
setblock ~169 ~111 ~87 dirt
setblock ~169 ~111 ~88 dirt
setblock ~169 ~112 ~79 dirt
setblock ~169 ~112 ~80 dirt
setblock ~169 ~112 ~81 dirt
setblock ~169 ~112 ~82 dirt
setblock ~169 ~112 ~83 dirt
setblock ~169 ~112 ~84 dirt
setblock ~169 ~112 ~85 dirt
setblock ~169 ~112 ~86 dirt
setblock ~169 ~112 ~87 dirt
setblock ~169 ~112 ~88 dirt
setblock ~169 ~112 ~89 dirt
setblock ~169 ~113 ~77 dirt
setblock ~169 ~113 ~79 dirt
setblock ~169 ~113 ~80 dirt
setblock ~169 ~113 ~81 dirt
setblock ~169 ~113 ~82 dirt
setblock ~169 ~113 ~83 dirt
setblock ~169 ~113 ~84 dirt
setblock ~169 ~113 ~85 dirt
setblock ~169 ~113 ~86 dirt
setblock ~169 ~113 ~87 dirt
setblock ~169 ~113 ~88 dirt
setblock ~169 ~113 ~89 dirt
setblock ~169 ~113 ~90 dirt
setblock ~169 ~114 ~74 dirt
setblock ~169 ~114 ~76 dirt
setblock ~169 ~114 ~77 dirt
setblock ~169 ~114 ~78 dirt
setblock ~169 ~114 ~79 dirt
setblock ~169 ~114 ~80 dirt
setblock ~169 ~114 ~81 dirt
setblock ~169 ~114 ~82 dirt
setblock ~169 ~114 ~83 dirt
setblock ~169 ~114 ~84 dirt
setblock ~169 ~114 ~85 dirt
setblock ~169 ~114 ~86 dirt
setblock ~169 ~114 ~87 dirt
setblock ~169 ~114 ~88 dirt
setblock ~169 ~114 ~89 dirt
setblock ~169 ~114 ~90 dirt
setblock ~169 ~115 ~74 dirt
setblock ~169 ~115 ~75 dirt
setblock ~169 ~115 ~76 dirt
setblock ~169 ~115 ~77 dirt
setblock ~169 ~115 ~78 dirt
setblock ~169 ~115 ~79 dirt
setblock ~169 ~115 ~80 dirt
setblock ~169 ~115 ~81 dirt
setblock ~169 ~115 ~82 dirt
setblock ~169 ~115 ~83 dirt
setblock ~169 ~115 ~84 dirt
setblock ~169 ~115 ~85 dirt
setblock ~169 ~115 ~86 dirt
setblock ~169 ~115 ~87 dirt
setblock ~169 ~115 ~88 dirt
setblock ~169 ~115 ~89 dirt
setblock ~169 ~115 ~90 dirt
setblock ~169 ~116 ~73 dirt
setblock ~169 ~116 ~74 dirt
setblock ~169 ~116 ~75 dirt
setblock ~169 ~116 ~76 dirt
setblock ~169 ~116 ~77 dirt
setblock ~169 ~116 ~78 dirt
setblock ~169 ~116 ~79 dirt
setblock ~169 ~116 ~80 dirt
setblock ~169 ~116 ~81 dirt
setblock ~169 ~116 ~82 dirt
setblock ~169 ~116 ~83 dirt
setblock ~169 ~116 ~84 dirt
setblock ~169 ~116 ~85 dirt
setblock ~169 ~116 ~86 dirt
setblock ~169 ~116 ~87 dirt
setblock ~169 ~116 ~88 dirt
setblock ~169 ~116 ~89 dirt
