setblock ~0 ~1 ~0 gold_block
setblock ~9 ~120 ~119 dirt
setblock ~9 ~121 ~118 dirt
setblock ~9 ~121 ~119 dirt
setblock ~9 ~122 ~118 dirt
setblock ~9 ~122 ~119 dirt
setblock ~9 ~123 ~118 dirt
setblock ~9 ~123 ~119 dirt
setblock ~9 ~124 ~118 dirt
setblock ~9 ~124 ~119 dirt
setblock ~9 ~125 ~118 dirt
setblock ~9 ~125 ~119 dirt
setblock ~9 ~126 ~118 grass_block
setblock ~9 ~126 ~119 grass_block
setblock ~9 ~127 ~119 fern
setblock ~10 ~118 ~120 dirt
setblock ~10 ~119 ~119 dirt
setblock ~10 ~119 ~120 dirt
setblock ~10 ~120 ~118 dirt
setblock ~10 ~120 ~119 dirt
setblock ~10 ~120 ~120 dirt
setblock ~10 ~121 ~117 dirt
setblock ~10 ~121 ~118 dirt
setblock ~10 ~121 ~119 dirt
setblock ~10 ~121 ~120 dirt
setblock ~10 ~121 ~121 dirt
setblock ~10 ~122 ~117 dirt
setblock ~10 ~122 ~118 dirt
setblock ~10 ~122 ~119 dirt
setblock ~10 ~122 ~120 dirt
setblock ~10 ~122 ~121 dirt
setblock ~10 ~123 ~117 dirt
setblock ~10 ~123 ~118 dirt
setblock ~10 ~123 ~119 dirt
setblock ~10 ~123 ~120 dirt
setblock ~10 ~123 ~121 dirt
setblock ~10 ~124 ~117 dirt
setblock ~10 ~124 ~118 dirt
setblock ~10 ~124 ~119 dirt
setblock ~10 ~124 ~120 dirt
setblock ~10 ~124 ~121 dirt
setblock ~10 ~125 ~117 dirt
setblock ~10 ~125 ~118 dirt
setblock ~10 ~125 ~119 dirt
setblock ~10 ~125 ~120 grass_block
setblock ~10 ~125 ~121 grass_block
setblock ~10 ~126 ~117 dirt
setblock ~10 ~126 ~118 grass_block
setblock ~10 ~126 ~119 grass_block
setblock ~10 ~126 ~120 fern
setblock ~10 ~127 ~117 grass_block
setblock ~11 ~116 ~118 dirt
setblock ~11 ~116 ~119 dirt
setblock ~11 ~117 ~118 dirt
setblock ~11 ~117 ~119 dirt
setblock ~11 ~117 ~120 dirt
setblock ~11 ~118 ~118 dirt
setblock ~11 ~118 ~119 dirt
setblock ~11 ~118 ~120 dirt
setblock ~11 ~118 ~121 dirt
setblock ~11 ~119 ~118 dirt
setblock ~11 ~119 ~119 dirt
setblock ~11 ~119 ~120 dirt
setblock ~11 ~119 ~121 dirt
setblock ~11 ~120 ~117 dirt
setblock ~11 ~120 ~118 dirt
setblock ~11 ~120 ~119 dirt
setblock ~11 ~120 ~120 dirt
setblock ~11 ~120 ~121 dirt
setblock ~11 ~121 ~116 dirt
setblock ~11 ~121 ~117 dirt
setblock ~11 ~121 ~118 dirt
setblock ~11 ~121 ~119 dirt
setblock ~11 ~121 ~120 dirt
setblock ~11 ~121 ~121 dirt
setblock ~11 ~121 ~122 dirt
setblock ~11 ~122 ~116 dirt
setblock ~11 ~122 ~117 dirt
setblock ~11 ~122 ~118 dirt
setblock ~11 ~122 ~119 dirt
setblock ~11 ~122 ~120 dirt
setblock ~11 ~122 ~121 dirt
setblock ~11 ~122 ~122 dirt
setblock ~11 ~123 ~116 dirt
setblock ~11 ~123 ~117 dirt
setblock ~11 ~123 ~118 dirt
setblock ~11 ~123 ~119 dirt
setblock ~11 ~123 ~120 dirt
setblock ~11 ~123 ~121 dirt
setblock ~11 ~123 ~122 dirt
setblock ~11 ~124 ~116 dirt
setblock ~11 ~124 ~117 dirt
setblock ~11 ~124 ~118 dirt
setblock ~11 ~124 ~119 dirt
setblock ~11 ~124 ~120 dirt
setblock ~11 ~124 ~121 dirt
setblock ~11 ~124 ~122 dirt
setblock ~11 ~125 ~116 dirt
setblock ~11 ~125 ~117 dirt
setblock ~11 ~125 ~118 dirt
setblock ~11 ~125 ~119 dirt
setblock ~11 ~125 ~120 grass_block
setblock ~11 ~125 ~121 grass_block
setblock ~11 ~125 ~122 grass_block
setblock ~11 ~126 ~116 dirt
setblock ~11 ~126 ~117 dirt
setblock ~11 ~126 ~118 grass_block
setblock ~11 ~126 ~119 grass_block
setblock ~11 ~127 ~116 dirt
setblock ~11 ~127 ~117 grass_block
setblock ~11 ~127 ~118 short_grass
setblock ~11 ~128 ~116 grass_block
setblock ~11 ~129 ~116 short_grass
setblock ~12 ~113 ~119 dirt
setblock ~12 ~114 ~118 dirt
setblock ~12 ~114 ~119 dirt
setblock ~12 ~115 ~118 dirt
setblock ~12 ~115 ~119 dirt
setblock ~12 ~116 ~117 dirt
setblock ~12 ~116 ~118 dirt
setblock ~12 ~116 ~119 dirt
setblock ~12 ~116 ~120 dirt
setblock ~12 ~117 ~117 dirt
setblock ~12 ~117 ~118 dirt
setblock ~12 ~117 ~119 dirt
setblock ~12 ~117 ~120 dirt
setblock ~12 ~117 ~121 dirt
setblock ~12 ~118 ~117 dirt
setblock ~12 ~118 ~118 dirt
setblock ~12 ~118 ~119 dirt
setblock ~12 ~118 ~120 dirt
setblock ~12 ~118 ~121 dirt
setblock ~12 ~119 ~117 dirt
setblock ~12 ~119 ~118 dirt
setblock ~12 ~119 ~119 dirt
setblock ~12 ~119 ~120 dirt
setblock ~12 ~119 ~121 dirt
setblock ~12 ~120 ~116 dirt
setblock ~12 ~120 ~117 dirt
setblock ~12 ~120 ~118 dirt
setblock ~12 ~120 ~119 dirt
setblock ~12 ~120 ~120 dirt
setblock ~12 ~120 ~121 dirt
setblock ~12 ~121 ~115 dirt
setblock ~12 ~121 ~116 dirt
setblock ~12 ~121 ~117 dirt
setblock ~12 ~121 ~118 dirt
setblock ~12 ~121 ~119 dirt
setblock ~12 ~121 ~120 dirt
setblock ~12 ~121 ~121 dirt
setblock ~12 ~121 ~122 dirt
setblock ~12 ~122 ~115 dirt
setblock ~12 ~122 ~116 dirt
setblock ~12 ~122 ~117 dirt
setblock ~12 ~122 ~118 dirt
setblock ~12 ~122 ~119 dirt
setblock ~12 ~122 ~120 dirt
setblock ~12 ~122 ~121 dirt
setblock ~12 ~122 ~122 dirt
setblock ~12 ~123 ~115 dirt
setblock ~12 ~123 ~116 dirt
setblock ~12 ~123 ~117 dirt
setblock ~12 ~123 ~118 dirt
setblock ~12 ~123 ~119 dirt
setblock ~12 ~123 ~120 dirt
setblock ~12 ~123 ~121 dirt
setblock ~12 ~123 ~122 dirt
setblock ~12 ~124 ~115 dirt
setblock ~12 ~124 ~116 dirt
setblock ~12 ~124 ~117 dirt
setblock ~12 ~124 ~118 dirt
setblock ~12 ~124 ~119 dirt
setblock ~12 ~124 ~120 dirt
setblock ~12 ~124 ~121 dirt
setblock ~12 ~124 ~122 dirt
setblock ~12 ~125 ~115 dirt
setblock ~12 ~125 ~116 dirt
setblock ~12 ~125 ~117 dirt
setblock ~12 ~125 ~118 dirt
setblock ~12 ~125 ~119 dirt
setblock ~12 ~125 ~120 grass_block
setblock ~12 ~125 ~121 grass_block
setblock ~12 ~125 ~122 grass_block
setblock ~12 ~126 ~115 dirt
setblock ~12 ~126 ~116 dirt
setblock ~12 ~126 ~117 dirt
setblock ~12 ~126 ~118 grass_block
setblock ~12 ~126 ~119 grass_block
setblock ~12 ~127 ~115 dirt
setblock ~12 ~127 ~116 grass_block
setblock ~12 ~127 ~117 grass_block
setblock ~12 ~128 ~115 grass_block
setblock ~12 ~128 ~117 short_grass
setblock ~12 ~129 ~115 short_grass
setblock ~13 ~112 ~119 dirt
setblock ~13 ~113 ~118 dirt
setblock ~13 ~113 ~119 dirt
setblock ~13 ~113 ~120 dirt
setblock ~13 ~114 ~117 dirt
setblock ~13 ~114 ~118 dirt
setblock ~13 ~114 ~119 dirt
setblock ~13 ~114 ~120 dirt
setblock ~13 ~115 ~117 dirt
setblock ~13 ~115 ~118 dirt
setblock ~13 ~115 ~119 dirt
setblock ~13 ~115 ~120 dirt
setblock ~13 ~116 ~117 dirt
setblock ~13 ~116 ~118 dirt
setblock ~13 ~116 ~119 dirt
setblock ~13 ~116 ~120 dirt
setblock ~13 ~117 ~116 dirt
setblock ~13 ~117 ~117 dirt
setblock ~13 ~117 ~118 dirt
setblock ~13 ~117 ~119 dirt
setblock ~13 ~117 ~120 dirt
setblock ~13 ~117 ~121 dirt
setblock ~13 ~118 ~116 dirt
setblock ~13 ~118 ~117 dirt
setblock ~13 ~118 ~118 dirt
setblock ~13 ~118 ~119 dirt
setblock ~13 ~118 ~120 dirt
setblock ~13 ~118 ~121 dirt
setblock ~13 ~119 ~116 dirt
setblock ~13 ~119 ~117 dirt
setblock ~13 ~119 ~118 dirt
setblock ~13 ~119 ~119 dirt
setblock ~13 ~119 ~120 dirt
setblock ~13 ~119 ~121 dirt
setblock ~13 ~119 ~122 dirt
setblock ~13 ~120 ~94 dirt
setblock ~13 ~120 ~115 dirt
setblock ~13 ~120 ~116 dirt
setblock ~13 ~120 ~117 dirt
setblock ~13 ~120 ~118 dirt
setblock ~13 ~120 ~119 dirt
setblock ~13 ~120 ~120 dirt
setblock ~13 ~120 ~121 dirt
setblock ~13 ~120 ~122 dirt
setblock ~13 ~121 ~93 dirt
setblock ~13 ~121 ~94 dirt
setblock ~13 ~121 ~114 dirt
setblock ~13 ~121 ~115 dirt
setblock ~13 ~121 ~116 dirt
setblock ~13 ~121 ~117 dirt
setblock ~13 ~121 ~118 dirt
setblock ~13 ~121 ~119 dirt
setblock ~13 ~121 ~120 dirt
setblock ~13 ~121 ~121 dirt
setblock ~13 ~121 ~122 dirt
setblock ~13 ~121 ~123 dirt
setblock ~13 ~122 ~93 dirt
setblock ~13 ~122 ~94 dirt
setblock ~13 ~122 ~114 dirt
setblock ~13 ~122 ~115 dirt
setblock ~13 ~122 ~116 dirt
setblock ~13 ~122 ~117 dirt
setblock ~13 ~122 ~118 dirt
setblock ~13 ~122 ~119 dirt
setblock ~13 ~122 ~120 dirt
setblock ~13 ~122 ~121 dirt
setblock ~13 ~122 ~122 dirt
setblock ~13 ~122 ~123 dirt
setblock ~13 ~123 ~93 dirt
setblock ~13 ~123 ~94 dirt
setblock ~13 ~123 ~114 dirt
setblock ~13 ~123 ~115 dirt
setblock ~13 ~123 ~116 dirt
setblock ~13 ~123 ~117 dirt
setblock ~13 ~123 ~118 dirt
setblock ~13 ~123 ~119 dirt
setblock ~13 ~123 ~120 dirt
setblock ~13 ~123 ~121 dirt
setblock ~13 ~123 ~122 dirt
setblock ~13 ~123 ~123 dirt
setblock ~13 ~124 ~93 grass_block
setblock ~13 ~124 ~94 grass_block
setblock ~13 ~124 ~114 dirt
setblock ~13 ~124 ~115 dirt
setblock ~13 ~124 ~116 dirt
setblock ~13 ~124 ~117 dirt
setblock ~13 ~124 ~118 dirt
setblock ~13 ~124 ~119 dirt
setblock ~13 ~124 ~120 dirt
setblock ~13 ~124 ~121 dirt
setblock ~13 ~124 ~122 dirt
setblock ~13 ~124 ~123 dirt
setblock ~13 ~125 ~93 short_grass
setblock ~13 ~125 ~114 dirt
setblock ~13 ~125 ~115 dirt
setblock ~13 ~125 ~116 dirt
setblock ~13 ~125 ~117 dirt
setblock ~13 ~125 ~118 dirt
setblock ~13 ~125 ~119 dirt
setblock ~13 ~125 ~120 dirt
setblock ~13 ~125 ~121 dirt
setblock ~13 ~125 ~122 grass_block
setblock ~13 ~125 ~123 grass_block
setblock ~13 ~126 ~114 dirt
setblock ~13 ~126 ~115 dirt
setblock ~13 ~126 ~116 dirt
setblock ~13 ~126 ~117 dirt
setblock ~13 ~126 ~118 grass_block
setblock ~13 ~126 ~119 grass_block
setblock ~13 ~126 ~120 grass_block
setblock ~13 ~126 ~121 grass_block
setblock ~13 ~127 ~114 dirt
setblock ~13 ~127 ~115 grass_block
setblock ~13 ~127 ~116 grass_block
setblock ~13 ~127 ~117 grass_block
setblock ~13 ~127 ~120 fern
setblock ~13 ~128 ~114 grass_block
setblock ~13 ~128 ~115 short_grass
setblock ~13 ~128 ~116 short_grass
setblock ~13 ~128 ~117 short_grass
setblock ~14 ~113 ~119 dirt
setblock ~14 ~114 ~118 dirt
setblock ~14 ~114 ~119 dirt
setblock ~14 ~114 ~120 dirt
setblock ~14 ~115 ~118 dirt
setblock ~14 ~115 ~119 dirt
setblock ~14 ~115 ~120 dirt
setblock ~14 ~116 ~117 dirt
setblock ~14 ~116 ~118 dirt
setblock ~14 ~116 ~119 dirt
setblock ~14 ~116 ~120 dirt
setblock ~14 ~117 ~116 dirt
setblock ~14 ~117 ~117 dirt
setblock ~14 ~117 ~118 dirt
setblock ~14 ~117 ~119 dirt
setblock ~14 ~117 ~120 dirt
setblock ~14 ~117 ~121 dirt
setblock ~14 ~118 ~116 dirt
setblock ~14 ~118 ~117 dirt
setblock ~14 ~118 ~118 dirt
setblock ~14 ~118 ~119 dirt
setblock ~14 ~118 ~120 dirt
setblock ~14 ~118 ~121 dirt
setblock ~14 ~119 ~94 dirt
setblock ~14 ~119 ~116 dirt
setblock ~14 ~119 ~117 dirt
setblock ~14 ~119 ~118 dirt
setblock ~14 ~119 ~119 dirt
setblock ~14 ~119 ~120 dirt
setblock ~14 ~119 ~121 dirt
setblock ~14 ~120 ~93 dirt
setblock ~14 ~120 ~94 dirt
setblock ~14 ~120 ~95 dirt
setblock ~14 ~120 ~115 dirt
setblock ~14 ~120 ~116 dirt
setblock ~14 ~120 ~117 dirt
setblock ~14 ~120 ~118 dirt
setblock ~14 ~120 ~119 dirt
setblock ~14 ~120 ~120 dirt
setblock ~14 ~120 ~121 dirt
setblock ~14 ~120 ~122 dirt
setblock ~14 ~121 ~92 dirt
setblock ~14 ~121 ~93 dirt
setblock ~14 ~121 ~94 dirt
setblock ~14 ~121 ~95 dirt
setblock ~14 ~121 ~115 dirt
setblock ~14 ~121 ~116 dirt
setblock ~14 ~121 ~117 dirt
setblock ~14 ~121 ~118 dirt
setblock ~14 ~121 ~119 dirt
setblock ~14 ~121 ~120 dirt
setblock ~14 ~121 ~121 dirt
setblock ~14 ~121 ~122 dirt
setblock ~14 ~121 ~123 dirt
setblock ~14 ~122 ~92 dirt
setblock ~14 ~122 ~93 dirt
setblock ~14 ~122 ~94 dirt
setblock ~14 ~122 ~95 dirt
setblock ~14 ~122 ~115 dirt
setblock ~14 ~122 ~116 dirt
setblock ~14 ~122 ~117 dirt
setblock ~14 ~122 ~118 dirt
setblock ~14 ~122 ~119 dirt
setblock ~14 ~122 ~120 dirt
setblock ~14 ~122 ~121 dirt
setblock ~14 ~122 ~122 dirt
setblock ~14 ~122 ~123 dirt
setblock ~14 ~123 ~92 dirt
setblock ~14 ~123 ~93 dirt
setblock ~14 ~123 ~94 dirt
setblock ~14 ~123 ~95 dirt
setblock ~14 ~123 ~115 dirt
setblock ~14 ~123 ~116 dirt
setblock ~14 ~123 ~117 dirt
setblock ~14 ~123 ~118 dirt
setblock ~14 ~123 ~119 dirt
setblock ~14 ~123 ~120 dirt
setblock ~14 ~123 ~121 dirt
setblock ~14 ~123 ~122 dirt
setblock ~14 ~123 ~123 dirt
setblock ~14 ~124 ~92 grass_block
setblock ~14 ~124 ~93 grass_block
setblock ~14 ~124 ~94 grass_block
setblock ~14 ~124 ~95 grass_block
setblock ~14 ~124 ~115 dirt
setblock ~14 ~124 ~116 dirt
setblock ~14 ~124 ~117 dirt
setblock ~14 ~124 ~118 dirt
setblock ~14 ~124 ~119 dirt
setblock ~14 ~124 ~120 dirt
setblock ~14 ~124 ~121 dirt
setblock ~14 ~124 ~122 dirt
setblock ~14 ~124 ~123 dirt
setblock ~14 ~125 ~93 short_grass
setblock ~14 ~125 ~95 short_grass
setblock ~14 ~125 ~115 dirt
setblock ~14 ~125 ~116 dirt
setblock ~14 ~125 ~117 dirt
setblock ~14 ~125 ~118 dirt
setblock ~14 ~125 ~119 dirt
setblock ~14 ~125 ~120 dirt
setblock ~14 ~125 ~121 dirt
setblock ~14 ~125 ~122 dirt
setblock ~14 ~125 ~123 grass_block
setblock ~14 ~126 ~115 dirt
setblock ~14 ~126 ~116 dirt
setblock ~14 ~126 ~117 dirt
setblock ~14 ~126 ~118 grass_block
setblock ~14 ~126 ~119 grass_block
setblock ~14 ~126 ~120 grass_block
setblock ~14 ~126 ~121 grass_block
setblock ~14 ~126 ~122 grass_block
setblock ~14 ~126 ~123 fern
setblock ~14 ~127 ~115 grass_block
setblock ~14 ~127 ~116 grass_block
setblock ~14 ~127 ~117 grass_block
setblock ~14 ~127 ~118 short_grass
setblock ~14 ~127 ~120 short_grass
setblock ~14 ~127 ~121 short_grass
setblock ~15 ~114 ~119 dirt
setblock ~15 ~115 ~119 dirt
setblock ~15 ~116 ~118 dirt
setblock ~15 ~116 ~119 dirt
setblock ~15 ~117 ~117 dirt
setblock ~15 ~117 ~118 dirt
setblock ~15 ~117 ~119 dirt
setblock ~15 ~117 ~120 dirt
setblock ~15 ~118 ~94 dirt
setblock ~15 ~118 ~117 dirt
setblock ~15 ~118 ~118 dirt
setblock ~15 ~118 ~119 dirt
setblock ~15 ~118 ~120 dirt
setblock ~15 ~119 ~93 dirt
setblock ~15 ~119 ~94 dirt
setblock ~15 ~119 ~95 dirt
setblock ~15 ~119 ~116 dirt
setblock ~15 ~119 ~117 dirt
setblock ~15 ~119 ~118 dirt
setblock ~15 ~119 ~119 dirt
setblock ~15 ~119 ~120 dirt
setblock ~15 ~119 ~121 dirt
setblock ~15 ~120 ~92 dirt
setblock ~15 ~120 ~93 dirt
setblock ~15 ~120 ~94 dirt
setblock ~15 ~120 ~95 dirt
setblock ~15 ~120 ~96 dirt
setblock ~15 ~120 ~116 dirt
setblock ~15 ~120 ~117 dirt
setblock ~15 ~120 ~118 dirt
setblock ~15 ~120 ~119 dirt
setblock ~15 ~120 ~120 dirt
setblock ~15 ~120 ~121 dirt
setblock ~15 ~120 ~122 dirt
setblock ~15 ~121 ~91 dirt
setblock ~15 ~121 ~92 dirt
setblock ~15 ~121 ~93 dirt
setblock ~15 ~121 ~94 dirt
setblock ~15 ~121 ~95 dirt
setblock ~15 ~121 ~96 dirt
setblock ~15 ~121 ~97 dirt
setblock ~15 ~121 ~116 dirt
setblock ~15 ~121 ~117 dirt
setblock ~15 ~121 ~118 dirt
setblock ~15 ~121 ~119 dirt
setblock ~15 ~121 ~120 dirt
setblock ~15 ~121 ~121 dirt
setblock ~15 ~121 ~122 dirt
setblock ~15 ~121 ~123 dirt
setblock ~15 ~122 ~91 dirt
setblock ~15 ~122 ~92 dirt
setblock ~15 ~122 ~93 dirt
setblock ~15 ~122 ~94 dirt
setblock ~15 ~122 ~95 dirt
setblock ~15 ~122 ~96 dirt
setblock ~15 ~122 ~97 dirt
setblock ~15 ~122 ~116 dirt
setblock ~15 ~122 ~117 dirt
setblock ~15 ~122 ~118 dirt
setblock ~15 ~122 ~119 dirt
setblock ~15 ~122 ~120 dirt
setblock ~15 ~122 ~121 dirt
setblock ~15 ~122 ~122 dirt
setblock ~15 ~122 ~123 dirt
setblock ~15 ~123 ~91 dirt
setblock ~15 ~123 ~92 dirt
setblock ~15 ~123 ~93 dirt
setblock ~15 ~123 ~94 dirt
setblock ~15 ~123 ~95 dirt
setblock ~15 ~123 ~96 dirt
setblock ~15 ~123 ~97 dirt
setblock ~15 ~123 ~116 dirt
setblock ~15 ~123 ~117 dirt
setblock ~15 ~123 ~118 dirt
setblock ~15 ~123 ~119 dirt
setblock ~15 ~123 ~120 dirt
setblock ~15 ~123 ~121 dirt
setblock ~15 ~123 ~122 dirt
setblock ~15 ~123 ~123 dirt
setblock ~15 ~124 ~91 grass_block
setblock ~15 ~124 ~92 grass_block
setblock ~15 ~124 ~93 grass_block
setblock ~15 ~124 ~94 grass_block
setblock ~15 ~124 ~95 dirt
setblock ~15 ~124 ~96 dirt
setblock ~15 ~124 ~97 dirt
setblock ~15 ~124 ~116 dirt
setblock ~15 ~124 ~117 dirt
setblock ~15 ~124 ~118 dirt
setblock ~15 ~124 ~119 dirt
setblock ~15 ~124 ~120 dirt
setblock ~15 ~124 ~121 dirt
setblock ~15 ~124 ~122 dirt
setblock ~15 ~124 ~123 dirt
setblock ~15 ~125 ~91 short_grass
setblock ~15 ~125 ~94 short_grass
setblock ~15 ~125 ~95 grass_block
setblock ~15 ~125 ~96 grass_block
setblock ~15 ~125 ~97 grass_block
setblock ~15 ~125 ~116 dirt
setblock ~15 ~125 ~117 dirt
setblock ~15 ~125 ~118 dirt
setblock ~15 ~125 ~119 dirt
setblock ~15 ~125 ~120 dirt
setblock ~15 ~125 ~121 dirt
setblock ~15 ~125 ~122 dirt
setblock ~15 ~125 ~123 grass_block
setblock ~15 ~126 ~96 short_grass
setblock ~15 ~126 ~116 dirt
setblock ~15 ~126 ~117 grass_block
setblock ~15 ~126 ~118 grass_block
setblock ~15 ~126 ~119 grass_block
setblock ~15 ~126 ~120 grass_block
setblock ~15 ~126 ~121 grass_block
setblock ~15 ~126 ~122 grass_block
setblock ~15 ~127 ~116 grass_block
setblock ~15 ~127 ~118 short_grass
setblock ~15 ~127 ~119 short_grass
setblock ~15 ~128 ~116 poppy
setblock ~16 ~116 ~94 dirt
setblock ~16 ~117 ~93 dirt
setblock ~16 ~117 ~94 dirt
setblock ~16 ~117 ~118 dirt
setblock ~16 ~117 ~119 dirt
setblock ~16 ~118 ~92 dirt
setblock ~16 ~118 ~93 dirt
setblock ~16 ~118 ~94 dirt
setblock ~16 ~118 ~95 dirt
setblock ~16 ~118 ~118 dirt
setblock ~16 ~118 ~119 dirt
setblock ~16 ~119 ~92 dirt
setblock ~16 ~119 ~93 dirt
setblock ~16 ~119 ~94 dirt
setblock ~16 ~119 ~95 dirt
setblock ~16 ~119 ~96 dirt
setblock ~16 ~119 ~117 dirt
setblock ~16 ~119 ~118 dirt
setblock ~16 ~119 ~119 dirt
setblock ~16 ~119 ~120 dirt
setblock ~16 ~120 ~91 dirt
setblock ~16 ~120 ~92 dirt
setblock ~16 ~120 ~93 dirt
setblock ~16 ~120 ~94 dirt
setblock ~16 ~120 ~95 dirt
setblock ~16 ~120 ~96 dirt
setblock ~16 ~120 ~97 dirt
setblock ~16 ~120 ~117 dirt
setblock ~16 ~120 ~118 dirt
setblock ~16 ~120 ~119 dirt
setblock ~16 ~120 ~120 dirt
setblock ~16 ~120 ~121 dirt
setblock ~16 ~121 ~90 dirt
setblock ~16 ~121 ~91 dirt
setblock ~16 ~121 ~92 dirt
setblock ~16 ~121 ~93 dirt
setblock ~16 ~121 ~94 dirt
setblock ~16 ~121 ~95 dirt
setblock ~16 ~121 ~96 dirt
setblock ~16 ~121 ~97 dirt
setblock ~16 ~121 ~98 dirt
setblock ~16 ~121 ~116 dirt
setblock ~16 ~121 ~117 dirt
setblock ~16 ~121 ~118 dirt
setblock ~16 ~121 ~119 dirt
setblock ~16 ~121 ~120 dirt
setblock ~16 ~121 ~121 dirt
setblock ~16 ~121 ~122 dirt
setblock ~16 ~122 ~90 dirt
setblock ~16 ~122 ~91 dirt
setblock ~16 ~122 ~92 dirt
setblock ~16 ~122 ~93 dirt
setblock ~16 ~122 ~94 dirt
setblock ~16 ~122 ~95 dirt
setblock ~16 ~122 ~96 dirt
setblock ~16 ~122 ~97 dirt
setblock ~16 ~122 ~98 dirt
setblock ~16 ~122 ~116 dirt
setblock ~16 ~122 ~117 dirt
setblock ~16 ~122 ~118 dirt
setblock ~16 ~122 ~119 dirt
setblock ~16 ~122 ~120 dirt
setblock ~16 ~122 ~121 dirt
setblock ~16 ~122 ~122 dirt
setblock ~16 ~123 ~90 dirt
setblock ~16 ~123 ~91 dirt
setblock ~16 ~123 ~92 dirt
setblock ~16 ~123 ~93 dirt
setblock ~16 ~123 ~94 dirt
setblock ~16 ~123 ~95 dirt
setblock ~16 ~123 ~96 dirt
setblock ~16 ~123 ~97 dirt
setblock ~16 ~123 ~98 dirt
setblock ~16 ~123 ~116 dirt
setblock ~16 ~123 ~117 dirt
setblock ~16 ~123 ~118 dirt
setblock ~16 ~123 ~119 dirt
setblock ~16 ~123 ~120 dirt
setblock ~16 ~123 ~121 dirt
setblock ~16 ~123 ~122 dirt
setblock ~16 ~124 ~90 grass_block
setblock ~16 ~124 ~91 grass_block
setblock ~16 ~124 ~92 grass_block
setblock ~16 ~124 ~93 grass_block
setblock ~16 ~124 ~94 dirt
setblock ~16 ~124 ~95 dirt
setblock ~16 ~124 ~96 dirt
setblock ~16 ~124 ~97 dirt
setblock ~16 ~124 ~98 dirt
setblock ~16 ~124 ~116 dirt
setblock ~16 ~124 ~117 dirt
setblock ~16 ~124 ~118 dirt
setblock ~16 ~124 ~119 dirt
setblock ~16 ~124 ~120 dirt
setblock ~16 ~124 ~121 dirt
setblock ~16 ~124 ~122 dirt
setblock ~16 ~125 ~94 grass_block
setblock ~16 ~125 ~95 grass_block
setblock ~16 ~125 ~96 grass_block
setblock ~16 ~125 ~97 grass_block
setblock ~16 ~125 ~98 grass_block
setblock ~16 ~125 ~116 dirt
setblock ~16 ~125 ~117 dirt
setblock ~16 ~125 ~118 dirt
setblock ~16 ~125 ~119 dirt
setblock ~16 ~125 ~120 dirt
setblock ~16 ~125 ~121 dirt
setblock ~16 ~125 ~122 dirt
setblock ~16 ~126 ~96 short_grass
setblock ~16 ~126 ~116 grass_block
setblock ~16 ~126 ~117 grass_block
setblock ~16 ~126 ~118 grass_block
setblock ~16 ~126 ~119 grass_block
setblock ~16 ~126 ~120 grass_block
setblock ~16 ~126 ~121 grass_block
setblock ~16 ~126 ~122 grass_block
setblock ~16 ~127 ~119 fern
setblock ~16 ~127 ~121 short_grass
setblock ~16 ~127 ~122 fern
setblock ~17 ~114 ~94 dirt
setblock ~17 ~115 ~93 dirt
setblock ~17 ~115 ~94 dirt
setblock ~17 ~116 ~93 dirt
setblock ~17 ~116 ~94 dirt
setblock ~17 ~116 ~95 dirt
setblock ~17 ~117 ~92 dirt
setblock ~17 ~117 ~93 dirt
setblock ~17 ~117 ~94 dirt
setblock ~17 ~117 ~95 dirt
setblock ~17 ~117 ~96 dirt
setblock ~17 ~118 ~91 dirt
setblock ~17 ~118 ~92 dirt
setblock ~17 ~118 ~93 dirt
setblock ~17 ~118 ~94 dirt
setblock ~17 ~118 ~95 dirt
setblock ~17 ~118 ~96 dirt
setblock ~17 ~118 ~97 dirt
setblock ~17 ~119 ~91 dirt
setblock ~17 ~119 ~92 dirt
setblock ~17 ~119 ~93 dirt
setblock ~17 ~119 ~94 dirt
setblock ~17 ~119 ~95 dirt
setblock ~17 ~119 ~96 dirt
setblock ~17 ~119 ~97 dirt
setblock ~17 ~119 ~119 dirt
setblock ~17 ~120 ~90 dirt
setblock ~17 ~120 ~91 dirt
setblock ~17 ~120 ~92 dirt
setblock ~17 ~120 ~93 dirt
setblock ~17 ~120 ~94 dirt
setblock ~17 ~120 ~95 dirt
setblock ~17 ~120 ~96 dirt
setblock ~17 ~120 ~97 dirt
setblock ~17 ~120 ~98 dirt
setblock ~17 ~120 ~119 dirt
setblock ~17 ~120 ~120 dirt
setblock ~17 ~121 ~89 dirt
setblock ~17 ~121 ~90 dirt
setblock ~17 ~121 ~91 dirt
setblock ~17 ~121 ~92 dirt
setblock ~17 ~121 ~93 dirt
setblock ~17 ~121 ~94 dirt
setblock ~17 ~121 ~95 dirt
setblock ~17 ~121 ~96 dirt
setblock ~17 ~121 ~97 dirt
setblock ~17 ~121 ~98 dirt
setblock ~17 ~121 ~99 dirt
setblock ~17 ~121 ~117 dirt
setblock ~17 ~121 ~118 dirt
setblock ~17 ~121 ~119 dirt
setblock ~17 ~121 ~120 dirt
setblock ~17 ~121 ~121 dirt
setblock ~17 ~122 ~89 dirt
setblock ~17 ~122 ~90 dirt
setblock ~17 ~122 ~91 dirt
setblock ~17 ~122 ~92 dirt
setblock ~17 ~122 ~93 dirt
setblock ~17 ~122 ~94 dirt
setblock ~17 ~122 ~95 dirt
setblock ~17 ~122 ~96 dirt
setblock ~17 ~122 ~97 dirt
setblock ~17 ~122 ~98 dirt
setblock ~17 ~122 ~99 dirt
setblock ~17 ~122 ~117 dirt
setblock ~17 ~122 ~118 dirt
setblock ~17 ~122 ~119 dirt
setblock ~17 ~122 ~120 dirt
setblock ~17 ~122 ~121 dirt
setblock ~17 ~123 ~89 dirt
setblock ~17 ~123 ~90 dirt
setblock ~17 ~123 ~91 dirt
setblock ~17 ~123 ~92 dirt
setblock ~17 ~123 ~93 dirt
setblock ~17 ~123 ~94 dirt
setblock ~17 ~123 ~95 dirt
setblock ~17 ~123 ~96 dirt
setblock ~17 ~123 ~97 dirt
setblock ~17 ~123 ~98 dirt
setblock ~17 ~123 ~99 dirt
setblock ~17 ~123 ~117 dirt
setblock ~17 ~123 ~118 dirt
setblock ~17 ~123 ~119 dirt
setblock ~17 ~123 ~120 dirt
setblock ~17 ~123 ~121 dirt
setblock ~17 ~124 ~89 grass_block
setblock ~17 ~124 ~90 grass_block
setblock ~17 ~124 ~91 grass_block
setblock ~17 ~124 ~92 grass_block
setblock ~17 ~124 ~93 dirt
setblock ~17 ~124 ~94 dirt
setblock ~17 ~124 ~95 dirt
setblock ~17 ~124 ~96 dirt
setblock ~17 ~124 ~97 dirt
setblock ~17 ~124 ~98 dirt
setblock ~17 ~124 ~99 dirt
setblock ~17 ~124 ~117 dirt
setblock ~17 ~124 ~118 dirt
setblock ~17 ~124 ~119 dirt
setblock ~17 ~124 ~120 dirt
setblock ~17 ~124 ~121 dirt
setblock ~17 ~125 ~90 short_grass
setblock ~17 ~125 ~91 short_grass
setblock ~17 ~125 ~93 grass_block
setblock ~17 ~125 ~94 grass_block
setblock ~17 ~125 ~95 grass_block
setblock ~17 ~125 ~96 grass_block
setblock ~17 ~125 ~97 grass_block
setblock ~17 ~125 ~98 grass_block
setblock ~17 ~125 ~99 dirt
setblock ~17 ~125 ~117 dirt
setblock ~17 ~125 ~118 dirt
setblock ~17 ~125 ~119 dirt
setblock ~17 ~125 ~120 dirt
setblock ~17 ~125 ~121 dirt
setblock ~17 ~126 ~93 fern
setblock ~17 ~126 ~95 short_grass
setblock ~17 ~126 ~98 short_grass
setblock ~17 ~126 ~99 grass_block
setblock ~17 ~126 ~117 grass_block
setblock ~17 ~126 ~118 grass_block
setblock ~17 ~126 ~119 grass_block
setblock ~17 ~126 ~120 grass_block
setblock ~17 ~126 ~121 grass_block
setblock ~17 ~127 ~99 short_grass
setblock ~17 ~127 ~119 short_grass
setblock ~17 ~127 ~121 short_grass
setblock ~18 ~113 ~94 dirt
setblock ~18 ~114 ~93 dirt
setblock ~18 ~114 ~94 dirt
setblock ~18 ~114 ~95 dirt
setblock ~18 ~115 ~92 dirt
setblock ~18 ~115 ~93 dirt
setblock ~18 ~115 ~94 dirt
setblock ~18 ~115 ~95 dirt
setblock ~18 ~116 ~92 dirt
setblock ~18 ~116 ~93 dirt
setblock ~18 ~116 ~94 dirt
setblock ~18 ~116 ~95 dirt
setblock ~18 ~116 ~96 dirt
setblock ~18 ~117 ~91 dirt
setblock ~18 ~117 ~92 dirt
setblock ~18 ~117 ~93 dirt
setblock ~18 ~117 ~94 dirt
setblock ~18 ~117 ~95 dirt
setblock ~18 ~117 ~96 dirt
setblock ~18 ~117 ~97 dirt
setblock ~18 ~118 ~90 dirt
setblock ~18 ~118 ~91 dirt
setblock ~18 ~118 ~92 dirt
setblock ~18 ~118 ~93 dirt
setblock ~18 ~118 ~94 dirt
setblock ~18 ~118 ~95 dirt
setblock ~18 ~118 ~96 dirt
setblock ~18 ~118 ~97 dirt
setblock ~18 ~118 ~98 dirt
setblock ~18 ~119 ~90 dirt
setblock ~18 ~119 ~91 dirt
setblock ~18 ~119 ~92 dirt
setblock ~18 ~119 ~93 dirt
setblock ~18 ~119 ~94 dirt
setblock ~18 ~119 ~95 dirt
setblock ~18 ~119 ~96 dirt
setblock ~18 ~119 ~97 dirt
setblock ~18 ~119 ~98 dirt
setblock ~18 ~120 ~89 dirt
setblock ~18 ~120 ~90 dirt
setblock ~18 ~120 ~91 dirt
setblock ~18 ~120 ~92 dirt
setblock ~18 ~120 ~93 dirt
setblock ~18 ~120 ~94 dirt
setblock ~18 ~120 ~95 dirt
setblock ~18 ~120 ~96 dirt
setblock ~18 ~120 ~97 dirt
setblock ~18 ~120 ~98 dirt
setblock ~18 ~120 ~99 dirt
setblock ~18 ~121 ~62 dirt
setblock ~18 ~121 ~88 dirt
setblock ~18 ~121 ~89 dirt
setblock ~18 ~121 ~90 dirt
setblock ~18 ~121 ~91 dirt
setblock ~18 ~121 ~92 dirt
setblock ~18 ~121 ~93 dirt
setblock ~18 ~121 ~94 dirt
setblock ~18 ~121 ~95 dirt
setblock ~18 ~121 ~96 dirt
setblock ~18 ~121 ~97 dirt
setblock ~18 ~121 ~98 dirt
setblock ~18 ~121 ~99 dirt
setblock ~18 ~121 ~100 dirt
setblock ~18 ~122 ~62 dirt
setblock ~18 ~122 ~88 dirt
setblock ~18 ~122 ~89 dirt
setblock ~18 ~122 ~90 dirt
setblock ~18 ~122 ~91 dirt
setblock ~18 ~122 ~92 dirt
setblock ~18 ~122 ~93 dirt
setblock ~18 ~122 ~94 dirt
setblock ~18 ~122 ~95 dirt
setblock ~18 ~122 ~96 dirt
setblock ~18 ~122 ~97 dirt
setblock ~18 ~122 ~98 dirt
setblock ~18 ~122 ~99 dirt
setblock ~18 ~122 ~100 dirt
setblock ~18 ~123 ~62 dirt
setblock ~18 ~123 ~88 dirt
setblock ~18 ~123 ~89 dirt
setblock ~18 ~123 ~90 dirt
setblock ~18 ~123 ~91 dirt
setblock ~18 ~123 ~92 dirt
setblock ~18 ~123 ~93 dirt
setblock ~18 ~123 ~94 dirt
setblock ~18 ~123 ~95 dirt
setblock ~18 ~123 ~96 dirt
setblock ~18 ~123 ~97 dirt
setblock ~18 ~123 ~98 dirt
setblock ~18 ~123 ~99 dirt
setblock ~18 ~123 ~100 dirt
setblock ~18 ~124 ~62 grass_block
setblock ~18 ~124 ~88 dirt
setblock ~18 ~124 ~89 grass_block
setblock ~18 ~124 ~90 grass_block
setblock ~18 ~124 ~91 grass_block
setblock ~18 ~124 ~92 dirt
setblock ~18 ~124 ~93 dirt
setblock ~18 ~124 ~94 dirt
setblock ~18 ~124 ~95 dirt
setblock ~18 ~124 ~96 dirt
setblock ~18 ~124 ~97 dirt
setblock ~18 ~124 ~98 dirt
setblock ~18 ~124 ~99 dirt
setblock ~18 ~124 ~100 dirt
setblock ~18 ~125 ~88 grass_block
setblock ~18 ~125 ~92 grass_block
setblock ~18 ~125 ~93 grass_block
setblock ~18 ~125 ~94 grass_block
setblock ~18 ~125 ~95 grass_block
setblock ~18 ~125 ~96 grass_block
setblock ~18 ~125 ~97 dirt
setblock ~18 ~125 ~98 dirt
setblock ~18 ~125 ~99 dirt
setblock ~18 ~125 ~100 dirt
setblock ~18 ~126 ~92 short_grass
setblock ~18 ~126 ~93 fern
setblock ~18 ~126 ~97 grass_block
setblock ~18 ~126 ~98 grass_block
setblock ~18 ~126 ~99 grass_block
setblock ~18 ~126 ~100 grass_block
setblock ~19 ~112 ~94 dirt
setblock ~19 ~113 ~93 dirt
setblock ~19 ~113 ~94 dirt
setblock ~19 ~113 ~95 dirt
setblock ~19 ~114 ~93 dirt
setblock ~19 ~114 ~94 dirt
setblock ~19 ~114 ~95 dirt
setblock ~19 ~115 ~92 dirt
setblock ~19 ~115 ~93 dirt
setblock ~19 ~115 ~94 dirt
setblock ~19 ~115 ~95 dirt
setblock ~19 ~115 ~96 dirt
setblock ~19 ~116 ~91 dirt
setblock ~19 ~116 ~92 dirt
setblock ~19 ~116 ~93 dirt
setblock ~19 ~116 ~94 dirt
setblock ~19 ~116 ~95 dirt
setblock ~19 ~116 ~96 dirt
setblock ~19 ~116 ~97 dirt
setblock ~19 ~117 ~62 dirt
setblock ~19 ~117 ~91 dirt
setblock ~19 ~117 ~92 dirt
setblock ~19 ~117 ~93 dirt
setblock ~19 ~117 ~94 dirt
setblock ~19 ~117 ~95 dirt
setblock ~19 ~117 ~96 dirt
setblock ~19 ~117 ~97 dirt
setblock ~19 ~118 ~62 dirt
setblock ~19 ~118 ~91 dirt
setblock ~19 ~118 ~92 dirt
setblock ~19 ~118 ~93 dirt
setblock ~19 ~118 ~94 dirt
setblock ~19 ~118 ~95 dirt
setblock ~19 ~118 ~96 dirt
setblock ~19 ~118 ~97 dirt
setblock ~19 ~118 ~98 dirt
setblock ~19 ~119 ~62 dirt
setblock ~19 ~119 ~90 dirt
setblock ~19 ~119 ~91 dirt
setblock ~19 ~119 ~92 dirt
setblock ~19 ~119 ~93 dirt
setblock ~19 ~119 ~94 dirt
setblock ~19 ~119 ~95 dirt
setblock ~19 ~119 ~96 dirt
setblock ~19 ~119 ~97 dirt
setblock ~19 ~119 ~98 dirt
setblock ~19 ~119 ~99 dirt
setblock ~19 ~120 ~62 dirt
setblock ~19 ~120 ~90 dirt
setblock ~19 ~120 ~91 dirt
setblock ~19 ~120 ~92 dirt
setblock ~19 ~120 ~93 dirt
setblock ~19 ~120 ~94 dirt
setblock ~19 ~120 ~95 dirt
setblock ~19 ~120 ~96 dirt
setblock ~19 ~120 ~97 dirt
setblock ~19 ~120 ~98 dirt
setblock ~19 ~120 ~99 dirt
setblock ~19 ~121 ~61 dirt
setblock ~19 ~121 ~62 dirt
setblock ~19 ~121 ~63 dirt
setblock ~19 ~121 ~89 dirt
setblock ~19 ~121 ~90 dirt
setblock ~19 ~121 ~91 dirt
setblock ~19 ~121 ~92 dirt
setblock ~19 ~121 ~93 dirt
setblock ~19 ~121 ~94 dirt
setblock ~19 ~121 ~95 dirt
setblock ~19 ~121 ~96 dirt
setblock ~19 ~121 ~97 dirt
setblock ~19 ~121 ~98 dirt
setblock ~19 ~121 ~99 dirt
setblock ~19 ~121 ~100 dirt
setblock ~19 ~122 ~61 dirt
setblock ~19 ~122 ~62 dirt
setblock ~19 ~122 ~63 dirt
setblock ~19 ~122 ~89 dirt
setblock ~19 ~122 ~90 dirt
setblock ~19 ~122 ~91 dirt
setblock ~19 ~122 ~92 dirt
setblock ~19 ~122 ~93 dirt
setblock ~19 ~122 ~94 dirt
setblock ~19 ~122 ~95 dirt
setblock ~19 ~122 ~96 dirt
setblock ~19 ~122 ~97 dirt
setblock ~19 ~122 ~98 dirt
setblock ~19 ~122 ~99 dirt
setblock ~19 ~122 ~100 dirt
setblock ~19 ~123 ~61 dirt
setblock ~19 ~123 ~62 dirt
setblock ~19 ~123 ~63 dirt
setblock ~19 ~123 ~89 dirt
setblock ~19 ~123 ~90 dirt
setblock ~19 ~123 ~91 dirt
setblock ~19 ~123 ~92 dirt
setblock ~19 ~123 ~93 dirt
setblock ~19 ~123 ~94 dirt
setblock ~19 ~123 ~95 dirt
setblock ~19 ~123 ~96 dirt
setblock ~19 ~123 ~97 dirt
setblock ~19 ~123 ~98 dirt
setblock ~19 ~123 ~99 dirt
setblock ~19 ~123 ~100 dirt
setblock ~19 ~124 ~61 grass_block
setblock ~19 ~124 ~62 grass_block
setblock ~19 ~124 ~63 grass_block
setblock ~19 ~124 ~89 dirt
setblock ~19 ~124 ~90 grass_block
setblock ~19 ~124 ~91 dirt
setblock ~19 ~124 ~92 dirt
setblock ~19 ~124 ~93 dirt
setblock ~19 ~124 ~94 dirt
setblock ~19 ~124 ~95 dirt
setblock ~19 ~124 ~96 dirt
setblock ~19 ~124 ~97 dirt
setblock ~19 ~124 ~98 dirt
setblock ~19 ~124 ~99 dirt
setblock ~19 ~124 ~100 dirt
setblock ~19 ~125 ~63 short_grass
setblock ~19 ~125 ~89 grass_block
setblock ~19 ~125 ~90 short_grass
setblock ~19 ~125 ~91 grass_block
setblock ~19 ~125 ~92 grass_block
setblock ~19 ~125 ~93 grass_block
setblock ~19 ~125 ~94 grass_block
setblock ~19 ~125 ~95 grass_block
setblock ~19 ~125 ~96 dirt
setblock ~19 ~125 ~97 dirt
setblock ~19 ~125 ~98 dirt
setblock ~19 ~125 ~99 dirt
setblock ~19 ~125 ~100 dirt
setblock ~19 ~126 ~89 short_grass
setblock ~19 ~126 ~93 short_grass
setblock ~19 ~126 ~95 short_grass
setblock ~19 ~126 ~96 grass_block
setblock ~19 ~126 ~97 grass_block
setblock ~19 ~126 ~98 grass_block
setblock ~19 ~126 ~99 grass_block
setblock ~19 ~126 ~100 grass_block
setblock ~19 ~127 ~96 short_grass
setblock ~19 ~127 ~97 fern
setblock ~19 ~127 ~99 short_grass
setblock ~19 ~127 ~100 short_grass
setblock ~20 ~111 ~94 dirt
setblock ~20 ~112 ~93 dirt
setblock ~20 ~112 ~94 dirt
setblock ~20 ~112 ~95 dirt
setblock ~20 ~113 ~93 dirt
setblock ~20 ~113 ~94 dirt
setblock ~20 ~113 ~95 dirt
setblock ~20 ~113 ~96 dirt
setblock ~20 ~114 ~92 dirt
setblock ~20 ~114 ~93 dirt
setblock ~20 ~114 ~94 dirt
setblock ~20 ~114 ~95 dirt
setblock ~20 ~114 ~96 dirt
setblock ~20 ~115 ~91 dirt
setblock ~20 ~115 ~92 dirt
setblock ~20 ~115 ~93 dirt
setblock ~20 ~115 ~94 dirt
setblock ~20 ~115 ~95 dirt
setblock ~20 ~115 ~96 dirt
setblock ~20 ~115 ~97 dirt
setblock ~20 ~116 ~91 dirt
setblock ~20 ~116 ~92 dirt
setblock ~20 ~116 ~93 dirt
setblock ~20 ~116 ~94 dirt
setblock ~20 ~116 ~95 dirt
setblock ~20 ~116 ~96 dirt
setblock ~20 ~116 ~97 dirt
setblock ~20 ~116 ~98 dirt
setblock ~20 ~117 ~90 dirt
setblock ~20 ~117 ~91 dirt
setblock ~20 ~117 ~92 dirt
setblock ~20 ~117 ~93 dirt
setblock ~20 ~117 ~94 dirt
setblock ~20 ~117 ~95 dirt
setblock ~20 ~117 ~96 dirt
setblock ~20 ~117 ~97 dirt
setblock ~20 ~117 ~98 dirt
setblock ~20 ~118 ~90 dirt
setblock ~20 ~118 ~91 dirt
setblock ~20 ~118 ~92 dirt
setblock ~20 ~118 ~93 dirt
setblock ~20 ~118 ~94 dirt
setblock ~20 ~118 ~95 dirt
setblock ~20 ~118 ~96 dirt
setblock ~20 ~118 ~97 dirt
setblock ~20 ~118 ~98 dirt
setblock ~20 ~118 ~99 dirt
setblock ~20 ~119 ~90 dirt
setblock ~20 ~119 ~91 dirt
setblock ~20 ~119 ~92 dirt
setblock ~20 ~119 ~93 dirt
setblock ~20 ~119 ~94 dirt
setblock ~20 ~119 ~95 dirt
setblock ~20 ~119 ~96 dirt
setblock ~20 ~119 ~97 dirt
setblock ~20 ~119 ~98 dirt
setblock ~20 ~119 ~99 dirt
setblock ~20 ~119 ~100 dirt
setblock ~20 ~120 ~89 dirt
setblock ~20 ~120 ~90 dirt
setblock ~20 ~120 ~91 dirt
setblock ~20 ~120 ~92 dirt
setblock ~20 ~120 ~93 dirt
setblock ~20 ~120 ~94 dirt
setblock ~20 ~120 ~95 dirt
setblock ~20 ~120 ~96 dirt
setblock ~20 ~120 ~97 dirt
setblock ~20 ~120 ~98 dirt
setblock ~20 ~120 ~99 dirt
setblock ~20 ~120 ~100 dirt
setblock ~20 ~121 ~62 dirt
setblock ~20 ~121 ~89 dirt
setblock ~20 ~121 ~90 dirt
setblock ~20 ~121 ~91 dirt
setblock ~20 ~121 ~92 dirt
setblock ~20 ~121 ~93 dirt
setblock ~20 ~121 ~94 dirt
setblock ~20 ~121 ~95 dirt
setblock ~20 ~121 ~96 dirt
setblock ~20 ~121 ~97 dirt
setblock ~20 ~121 ~98 dirt
setblock ~20 ~121 ~99 dirt
setblock ~20 ~121 ~100 dirt
setblock ~20 ~121 ~101 dirt
setblock ~20 ~122 ~62 dirt
setblock ~20 ~122 ~89 dirt
setblock ~20 ~122 ~90 dirt
setblock ~20 ~122 ~91 dirt
setblock ~20 ~122 ~92 dirt
setblock ~20 ~122 ~93 dirt
setblock ~20 ~122 ~94 dirt
setblock ~20 ~122 ~95 dirt
setblock ~20 ~122 ~96 dirt
setblock ~20 ~122 ~97 dirt
setblock ~20 ~122 ~98 dirt
setblock ~20 ~122 ~99 dirt
setblock ~20 ~122 ~100 dirt
setblock ~20 ~122 ~101 dirt
setblock ~20 ~123 ~62 dirt
setblock ~20 ~123 ~89 dirt
setblock ~20 ~123 ~90 dirt
setblock ~20 ~123 ~91 dirt
setblock ~20 ~123 ~92 dirt
setblock ~20 ~123 ~93 dirt
setblock ~20 ~123 ~94 dirt
setblock ~20 ~123 ~95 dirt
setblock ~20 ~123 ~96 dirt
setblock ~20 ~123 ~97 dirt
setblock ~20 ~123 ~98 dirt
setblock ~20 ~123 ~99 dirt
setblock ~20 ~123 ~100 dirt
setblock ~20 ~123 ~101 dirt
setblock ~20 ~124 ~62 grass_block
setblock ~20 ~124 ~89 dirt
setblock ~20 ~124 ~90 dirt
setblock ~20 ~124 ~91 dirt
setblock ~20 ~124 ~92 dirt
setblock ~20 ~124 ~93 dirt
setblock ~20 ~124 ~94 dirt
setblock ~20 ~124 ~95 dirt
setblock ~20 ~124 ~96 dirt
setblock ~20 ~124 ~97 dirt
setblock ~20 ~124 ~98 dirt
setblock ~20 ~124 ~99 dirt
setblock ~20 ~124 ~100 dirt
setblock ~20 ~124 ~101 dirt
setblock ~20 ~125 ~62 short_grass
setblock ~20 ~125 ~89 grass_block
setblock ~20 ~125 ~90 grass_block
setblock ~20 ~125 ~91 grass_block
setblock ~20 ~125 ~92 grass_block
setblock ~20 ~125 ~93 grass_block
setblock ~20 ~125 ~94 dirt
setblock ~20 ~125 ~95 dirt
setblock ~20 ~125 ~96 dirt
setblock ~20 ~125 ~97 dirt
setblock ~20 ~125 ~98 dirt
setblock ~20 ~125 ~99 dirt
setblock ~20 ~125 ~100 dirt
setblock ~20 ~125 ~101 dirt
setblock ~20 ~126 ~94 grass_block
setblock ~20 ~126 ~95 grass_block
setblock ~20 ~126 ~96 grass_block
setblock ~20 ~126 ~97 grass_block
setblock ~20 ~126 ~98 grass_block
setblock ~20 ~126 ~99 grass_block
setblock ~20 ~126 ~100 grass_block
setblock ~20 ~126 ~101 grass_block
setblock ~20 ~127 ~94 short_grass
setblock ~20 ~127 ~98 short_grass
setblock ~20 ~127 ~99 poppy
setblock ~21 ~110 ~94 dirt
setblock ~21 ~111 ~93 dirt
setblock ~21 ~111 ~94 dirt
setblock ~21 ~111 ~95 dirt
setblock ~21 ~112 ~93 dirt
setblock ~21 ~112 ~94 dirt
setblock ~21 ~112 ~95 dirt
setblock ~21 ~112 ~96 dirt
setblock ~21 ~113 ~93 dirt
setblock ~21 ~113 ~94 dirt
setblock ~21 ~113 ~95 dirt
setblock ~21 ~113 ~96 dirt
setblock ~21 ~114 ~92 dirt
setblock ~21 ~114 ~93 dirt
setblock ~21 ~114 ~94 dirt
setblock ~21 ~114 ~95 dirt
setblock ~21 ~114 ~96 dirt
setblock ~21 ~115 ~92 dirt
setblock ~21 ~115 ~93 dirt
setblock ~21 ~115 ~94 dirt
setblock ~21 ~115 ~95 dirt
setblock ~21 ~115 ~96 dirt
setblock ~21 ~115 ~97 dirt
setblock ~21 ~116 ~92 dirt
setblock ~21 ~116 ~93 dirt
setblock ~21 ~116 ~94 dirt
setblock ~21 ~116 ~95 dirt
setblock ~21 ~116 ~96 dirt
setblock ~21 ~116 ~97 dirt
setblock ~21 ~116 ~98 dirt
setblock ~21 ~117 ~91 dirt
setblock ~21 ~117 ~92 dirt
setblock ~21 ~117 ~93 dirt
setblock ~21 ~117 ~94 dirt
setblock ~21 ~117 ~95 dirt
setblock ~21 ~117 ~96 dirt
setblock ~21 ~117 ~97 dirt
setblock ~21 ~117 ~98 dirt
setblock ~21 ~118 ~90 dirt
setblock ~21 ~118 ~91 dirt
setblock ~21 ~118 ~92 dirt
setblock ~21 ~118 ~93 dirt
setblock ~21 ~118 ~94 dirt
setblock ~21 ~118 ~95 dirt
setblock ~21 ~118 ~96 dirt
setblock ~21 ~118 ~97 dirt
setblock ~21 ~118 ~98 dirt
setblock ~21 ~119 ~90 dirt
setblock ~21 ~119 ~91 dirt
setblock ~21 ~119 ~92 dirt
setblock ~21 ~119 ~93 dirt
setblock ~21 ~119 ~94 dirt
setblock ~21 ~119 ~95 dirt
setblock ~21 ~119 ~96 dirt
setblock ~21 ~119 ~97 dirt
setblock ~21 ~119 ~98 dirt
setblock ~21 ~119 ~99 dirt
setblock ~21 ~120 ~89 dirt
setblock ~21 ~120 ~90 dirt
setblock ~21 ~120 ~91 dirt
setblock ~21 ~120 ~92 dirt
setblock ~21 ~120 ~93 dirt
setblock ~21 ~120 ~94 dirt
setblock ~21 ~120 ~95 dirt
setblock ~21 ~120 ~96 dirt
setblock ~21 ~120 ~97 dirt
setblock ~21 ~120 ~98 dirt
setblock ~21 ~120 ~99 dirt
setblock ~21 ~120 ~100 dirt
setblock ~21 ~121 ~89 dirt
setblock ~21 ~121 ~90 dirt
setblock ~21 ~121 ~91 dirt
setblock ~21 ~121 ~92 dirt
setblock ~21 ~121 ~93 dirt
setblock ~21 ~121 ~94 dirt
setblock ~21 ~121 ~95 dirt
setblock ~21 ~121 ~96 dirt
setblock ~21 ~121 ~97 dirt
setblock ~21 ~121 ~98 dirt
setblock ~21 ~121 ~99 dirt
setblock ~21 ~121 ~100 dirt
setblock ~21 ~122 ~89 dirt
setblock ~21 ~122 ~90 dirt
setblock ~21 ~122 ~91 dirt
setblock ~21 ~122 ~92 dirt
setblock ~21 ~122 ~93 dirt
setblock ~21 ~122 ~94 dirt
setblock ~21 ~122 ~95 dirt
setblock ~21 ~122 ~96 dirt
setblock ~21 ~122 ~97 dirt
setblock ~21 ~122 ~98 dirt
setblock ~21 ~122 ~99 dirt
setblock ~21 ~122 ~100 dirt
setblock ~21 ~123 ~89 dirt
setblock ~21 ~123 ~90 dirt
setblock ~21 ~123 ~91 dirt
setblock ~21 ~123 ~92 dirt
setblock ~21 ~123 ~93 dirt
setblock ~21 ~123 ~94 dirt
setblock ~21 ~123 ~95 dirt
setblock ~21 ~123 ~96 dirt
setblock ~21 ~123 ~97 dirt
setblock ~21 ~123 ~98 dirt
setblock ~21 ~123 ~99 dirt
setblock ~21 ~123 ~100 dirt
setblock ~21 ~124 ~89 dirt
setblock ~21 ~124 ~90 grass_block
setblock ~21 ~124 ~91 dirt
setblock ~21 ~124 ~92 dirt
setblock ~21 ~124 ~93 dirt
setblock ~21 ~124 ~94 dirt
setblock ~21 ~124 ~95 dirt
setblock ~21 ~124 ~96 dirt
setblock ~21 ~124 ~97 dirt
setblock ~21 ~124 ~98 dirt
setblock ~21 ~124 ~99 dirt
setblock ~21 ~124 ~100 dirt
setblock ~21 ~125 ~89 grass_block
setblock ~21 ~125 ~91 grass_block
setblock ~21 ~125 ~92 grass_block
setblock ~21 ~125 ~93 grass_block
setblock ~21 ~125 ~94 grass_block
setblock ~21 ~125 ~95 dirt
setblock ~21 ~125 ~96 dirt
setblock ~21 ~125 ~97 dirt
setblock ~21 ~125 ~98 dirt
setblock ~21 ~125 ~99 dirt
setblock ~21 ~125 ~100 dirt
setblock ~21 ~126 ~95 grass_block
setblock ~21 ~126 ~96 grass_block
setblock ~21 ~126 ~97 grass_block
setblock ~21 ~126 ~98 grass_block
setblock ~21 ~126 ~99 grass_block
setblock ~21 ~126 ~100 grass_block
setblock ~21 ~127 ~96 short_grass
setblock ~22 ~111 ~94 dirt
setblock ~22 ~112 ~94 dirt
setblock ~22 ~112 ~95 dirt
setblock ~22 ~113 ~94 dirt
setblock ~22 ~113 ~95 dirt
setblock ~22 ~113 ~96 dirt
setblock ~22 ~114 ~93 dirt
setblock ~22 ~114 ~94 dirt
setblock ~22 ~114 ~95 dirt
setblock ~22 ~114 ~96 dirt
setblock ~22 ~114 ~97 dirt
setblock ~22 ~115 ~93 dirt
setblock ~22 ~115 ~94 dirt
setblock ~22 ~115 ~95 dirt
setblock ~22 ~115 ~96 dirt
setblock ~22 ~115 ~97 dirt
setblock ~22 ~116 ~92 dirt
setblock ~22 ~116 ~93 dirt
setblock ~22 ~116 ~94 dirt
setblock ~22 ~116 ~95 dirt
setblock ~22 ~116 ~96 dirt
setblock ~22 ~116 ~97 dirt
setblock ~22 ~117 ~92 dirt
setblock ~22 ~117 ~93 dirt
setblock ~22 ~117 ~94 dirt
setblock ~22 ~117 ~95 dirt
setblock ~22 ~117 ~96 dirt
setblock ~22 ~117 ~97 dirt
setblock ~22 ~117 ~98 dirt
setblock ~22 ~118 ~91 dirt
setblock ~22 ~118 ~92 dirt
setblock ~22 ~118 ~93 dirt
setblock ~22 ~118 ~94 dirt
setblock ~22 ~118 ~95 dirt
setblock ~22 ~118 ~96 dirt
setblock ~22 ~118 ~97 dirt
setblock ~22 ~118 ~98 dirt
setblock ~22 ~118 ~99 dirt
setblock ~22 ~119 ~91 dirt
setblock ~22 ~119 ~92 dirt
setblock ~22 ~119 ~93 dirt
setblock ~22 ~119 ~94 dirt
setblock ~22 ~119 ~95 dirt
setblock ~22 ~119 ~96 dirt
setblock ~22 ~119 ~97 dirt
setblock ~22 ~119 ~98 dirt
setblock ~22 ~119 ~99 dirt
setblock ~22 ~120 ~90 dirt
setblock ~22 ~120 ~91 dirt
setblock ~22 ~120 ~92 dirt
setblock ~22 ~120 ~93 dirt
setblock ~22 ~120 ~94 dirt
setblock ~22 ~120 ~95 dirt
setblock ~22 ~120 ~96 dirt
setblock ~22 ~120 ~97 dirt
setblock ~22 ~120 ~98 dirt
setblock ~22 ~120 ~99 dirt
setblock ~22 ~120 ~100 dirt
setblock ~22 ~121 ~89 dirt
setblock ~22 ~121 ~90 dirt
setblock ~22 ~121 ~91 dirt
setblock ~22 ~121 ~92 dirt
setblock ~22 ~121 ~93 dirt
setblock ~22 ~121 ~94 dirt
setblock ~22 ~121 ~95 dirt
setblock ~22 ~121 ~96 dirt
setblock ~22 ~121 ~97 dirt
setblock ~22 ~121 ~98 dirt
setblock ~22 ~121 ~99 dirt
setblock ~22 ~121 ~100 dirt
setblock ~22 ~122 ~89 dirt
setblock ~22 ~122 ~90 dirt
setblock ~22 ~122 ~91 dirt
setblock ~22 ~122 ~92 dirt
setblock ~22 ~122 ~93 dirt
setblock ~22 ~122 ~94 dirt
setblock ~22 ~122 ~95 dirt
setblock ~22 ~122 ~96 dirt
setblock ~22 ~122 ~97 dirt
setblock ~22 ~122 ~98 dirt
setblock ~22 ~122 ~99 dirt
setblock ~22 ~122 ~100 dirt
setblock ~22 ~123 ~89 dirt
setblock ~22 ~123 ~90 dirt
setblock ~22 ~123 ~91 dirt
setblock ~22 ~123 ~92 dirt
setblock ~22 ~123 ~93 dirt
setblock ~22 ~123 ~94 dirt
setblock ~22 ~123 ~95 dirt
setblock ~22 ~123 ~96 dirt
setblock ~22 ~123 ~97 dirt
setblock ~22 ~123 ~98 dirt
setblock ~22 ~123 ~99 dirt
setblock ~22 ~123 ~100 dirt
setblock ~22 ~124 ~89 grass_block
setblock ~22 ~124 ~90 grass_block
setblock ~22 ~124 ~91 grass_block
setblock ~22 ~124 ~92 dirt
setblock ~22 ~124 ~93 dirt
setblock ~22 ~124 ~94 dirt
setblock ~22 ~124 ~95 dirt
setblock ~22 ~124 ~96 dirt
setblock ~22 ~124 ~97 dirt
setblock ~22 ~124 ~98 dirt
setblock ~22 ~124 ~99 dirt
setblock ~22 ~124 ~100 dirt
setblock ~22 ~125 ~92 grass_block
setblock ~22 ~125 ~93 grass_block
setblock ~22 ~125 ~94 grass_block
setblock ~22 ~125 ~95 grass_block
setblock ~22 ~125 ~96 grass_block
setblock ~22 ~125 ~97 dirt
setblock ~22 ~125 ~98 dirt
setblock ~22 ~125 ~99 dirt
setblock ~22 ~125 ~100 dirt
setblock ~22 ~126 ~94 short_grass
setblock ~22 ~126 ~96 short_grass
setblock ~22 ~126 ~97 grass_block
setblock ~22 ~126 ~98 grass_block
setblock ~22 ~126 ~99 grass_block
setblock ~22 ~126 ~100 grass_block
setblock ~23 ~113 ~95 dirt
setblock ~23 ~114 ~94 dirt
setblock ~23 ~114 ~95 dirt
setblock ~23 ~114 ~96 dirt
setblock ~23 ~115 ~94 dirt
setblock ~23 ~115 ~95 dirt
setblock ~23 ~115 ~96 dirt
setblock ~23 ~115 ~97 dirt
setblock ~23 ~116 ~93 dirt
setblock ~23 ~116 ~94 dirt
setblock ~23 ~116 ~95 dirt
setblock ~23 ~116 ~96 dirt
setblock ~23 ~116 ~97 dirt
setblock ~23 ~117 ~92 dirt
setblock ~23 ~117 ~93 dirt
setblock ~23 ~117 ~94 dirt
setblock ~23 ~117 ~95 dirt
setblock ~23 ~117 ~96 dirt
setblock ~23 ~117 ~97 dirt
setblock ~23 ~117 ~98 dirt
setblock ~23 ~118 ~92 dirt
setblock ~23 ~118 ~93 dirt
setblock ~23 ~118 ~94 dirt
setblock ~23 ~118 ~95 dirt
setblock ~23 ~118 ~96 dirt
setblock ~23 ~118 ~97 dirt
setblock ~23 ~118 ~98 dirt
setblock ~23 ~118 ~99 dirt
setblock ~23 ~119 ~91 dirt
setblock ~23 ~119 ~92 dirt
setblock ~23 ~119 ~93 dirt
setblock ~23 ~119 ~94 dirt
setblock ~23 ~119 ~95 dirt
setblock ~23 ~119 ~96 dirt
setblock ~23 ~119 ~97 dirt
setblock ~23 ~119 ~98 dirt
setblock ~23 ~119 ~99 dirt
setblock ~23 ~119 ~100 dirt
setblock ~23 ~120 ~91 dirt
setblock ~23 ~120 ~92 dirt
setblock ~23 ~120 ~93 dirt
setblock ~23 ~120 ~94 dirt
setblock ~23 ~120 ~95 dirt
setblock ~23 ~120 ~96 dirt
setblock ~23 ~120 ~97 dirt
setblock ~23 ~120 ~98 dirt
setblock ~23 ~120 ~99 dirt
setblock ~23 ~120 ~100 dirt
setblock ~23 ~121 ~90 dirt
setblock ~23 ~121 ~91 dirt
setblock ~23 ~121 ~92 dirt
setblock ~23 ~121 ~93 dirt
setblock ~23 ~121 ~94 dirt
setblock ~23 ~121 ~95 dirt
setblock ~23 ~121 ~96 dirt
setblock ~23 ~121 ~97 dirt
setblock ~23 ~121 ~98 dirt
setblock ~23 ~121 ~99 dirt
setblock ~23 ~121 ~100 dirt
setblock ~23 ~121 ~148 dirt
setblock ~23 ~122 ~90 dirt
setblock ~23 ~122 ~91 dirt
setblock ~23 ~122 ~92 dirt
setblock ~23 ~122 ~93 dirt
setblock ~23 ~122 ~94 dirt
setblock ~23 ~122 ~95 dirt
setblock ~23 ~122 ~96 dirt
setblock ~23 ~122 ~97 dirt
setblock ~23 ~122 ~98 dirt
setblock ~23 ~122 ~99 dirt
setblock ~23 ~122 ~100 dirt
setblock ~23 ~122 ~148 dirt
setblock ~23 ~123 ~90 dirt
setblock ~23 ~123 ~91 dirt
setblock ~23 ~123 ~92 dirt
setblock ~23 ~123 ~93 dirt
setblock ~23 ~123 ~94 dirt
setblock ~23 ~123 ~95 dirt
setblock ~23 ~123 ~96 dirt
setblock ~23 ~123 ~97 dirt
setblock ~23 ~123 ~98 dirt
setblock ~23 ~123 ~99 dirt
setblock ~23 ~123 ~100 dirt
setblock ~23 ~123 ~148 dirt
setblock ~23 ~124 ~90 grass_block
setblock ~23 ~124 ~91 grass_block
setblock ~23 ~124 ~92 grass_block
setblock ~23 ~124 ~93 dirt
setblock ~23 ~124 ~94 dirt
setblock ~23 ~124 ~95 dirt
setblock ~23 ~124 ~96 dirt
setblock ~23 ~124 ~97 dirt
setblock ~23 ~124 ~98 dirt
setblock ~23 ~124 ~99 dirt
setblock ~23 ~124 ~100 dirt
setblock ~23 ~124 ~148 grass_block
setblock ~23 ~125 ~93 grass_block
setblock ~23 ~125 ~94 grass_block
setblock ~23 ~125 ~95 grass_block
setblock ~23 ~125 ~96 grass_block
setblock ~23 ~125 ~97 dirt
setblock ~23 ~125 ~98 dirt
setblock ~23 ~125 ~99 dirt
setblock ~23 ~125 ~100 dirt
setblock ~23 ~125 ~148 short_grass
setblock ~23 ~126 ~95 short_grass
setblock ~23 ~126 ~97 grass_block
setblock ~23 ~126 ~98 grass_block
setblock ~23 ~126 ~99 grass_block
setblock ~23 ~126 ~100 grass_block
setblock ~24 ~115 ~96 dirt
setblock ~24 ~116 ~94 dirt
setblock ~24 ~116 ~95 dirt
setblock ~24 ~116 ~96 dirt
setblock ~24 ~117 ~93 dirt
setblock ~24 ~117 ~94 dirt
setblock ~24 ~117 ~95 dirt
setblock ~24 ~117 ~96 dirt
setblock ~24 ~117 ~97 dirt
setblock ~24 ~118 ~93 dirt
setblock ~24 ~118 ~94 dirt
setblock ~24 ~118 ~95 dirt
setblock ~24 ~118 ~96 dirt
setblock ~24 ~118 ~97 dirt
setblock ~24 ~118 ~98 dirt
setblock ~24 ~119 ~92 dirt
setblock ~24 ~119 ~93 dirt
setblock ~24 ~119 ~94 dirt
setblock ~24 ~119 ~95 dirt
setblock ~24 ~119 ~96 dirt
setblock ~24 ~119 ~97 dirt
setblock ~24 ~119 ~98 dirt
setblock ~24 ~119 ~99 dirt
setblock ~24 ~119 ~151 dirt
setblock ~24 ~119 ~153 dirt
setblock ~24 ~120 ~91 dirt
setblock ~24 ~120 ~92 dirt
setblock ~24 ~120 ~93 dirt
setblock ~24 ~120 ~94 dirt
setblock ~24 ~120 ~95 dirt
setblock ~24 ~120 ~96 dirt
setblock ~24 ~120 ~97 dirt
setblock ~24 ~120 ~98 dirt
setblock ~24 ~120 ~99 dirt
setblock ~24 ~120 ~148 dirt
setblock ~24 ~120 ~151 dirt
setblock ~24 ~120 ~152 dirt
setblock ~24 ~120 ~153 dirt
setblock ~24 ~120 ~154 dirt
setblock ~24 ~121 ~90 dirt
setblock ~24 ~121 ~91 dirt
setblock ~24 ~121 ~92 dirt
setblock ~24 ~121 ~93 dirt
setblock ~24 ~121 ~94 dirt
setblock ~24 ~121 ~95 dirt
setblock ~24 ~121 ~96 dirt
setblock ~24 ~121 ~97 dirt
setblock ~24 ~121 ~98 dirt
setblock ~24 ~121 ~99 dirt
setblock ~24 ~121 ~100 dirt
setblock ~24 ~121 ~147 dirt
setblock ~24 ~121 ~148 dirt
setblock ~24 ~121 ~149 dirt
setblock ~24 ~121 ~151 dirt
setblock ~24 ~121 ~152 dirt
setblock ~24 ~121 ~153 dirt
setblock ~24 ~121 ~154 dirt
setblock ~24 ~121 ~155 dirt
setblock ~24 ~122 ~90 dirt
setblock ~24 ~122 ~91 dirt
setblock ~24 ~122 ~92 dirt
setblock ~24 ~122 ~93 dirt
setblock ~24 ~122 ~94 dirt
setblock ~24 ~122 ~95 dirt
setblock ~24 ~122 ~96 dirt
setblock ~24 ~122 ~97 dirt
setblock ~24 ~122 ~98 dirt
setblock ~24 ~122 ~99 dirt
setblock ~24 ~122 ~100 dirt
setblock ~24 ~122 ~147 dirt
setblock ~24 ~122 ~148 dirt
setblock ~24 ~122 ~149 dirt
setblock ~24 ~122 ~151 dirt
setblock ~24 ~122 ~152 dirt
setblock ~24 ~122 ~153 dirt
setblock ~24 ~122 ~154 dirt
setblock ~24 ~122 ~155 dirt
setblock ~24 ~123 ~90 dirt
setblock ~24 ~123 ~91 dirt
setblock ~24 ~123 ~92 dirt
setblock ~24 ~123 ~93 dirt
setblock ~24 ~123 ~94 dirt
setblock ~24 ~123 ~95 dirt
setblock ~24 ~123 ~96 dirt
setblock ~24 ~123 ~97 dirt
setblock ~24 ~123 ~98 dirt
setblock ~24 ~123 ~99 dirt
setblock ~24 ~123 ~100 dirt
setblock ~24 ~123 ~147 dirt
setblock ~24 ~123 ~148 dirt
setblock ~24 ~123 ~149 dirt
setblock ~24 ~123 ~151 dirt
setblock ~24 ~123 ~152 dirt
setblock ~24 ~123 ~153 dirt
setblock ~24 ~123 ~154 dirt
setblock ~24 ~123 ~155 dirt
setblock ~24 ~124 ~90 grass_block
setblock ~24 ~124 ~91 grass_block
setblock ~24 ~124 ~92 grass_block
setblock ~24 ~124 ~93 grass_block
setblock ~24 ~124 ~94 dirt
setblock ~24 ~124 ~95 dirt
setblock ~24 ~124 ~96 dirt
setblock ~24 ~124 ~97 dirt
setblock ~24 ~124 ~98 dirt
setblock ~24 ~124 ~99 dirt
setblock ~24 ~124 ~100 dirt
setblock ~24 ~124 ~147 grass_block
setblock ~24 ~124 ~148 dirt
setblock ~24 ~124 ~149 dirt
setblock ~24 ~124 ~151 dirt
setblock ~24 ~124 ~152 dirt
setblock ~24 ~124 ~153 dirt
setblock ~24 ~124 ~154 dirt
setblock ~24 ~124 ~155 dirt
setblock ~24 ~125 ~90 short_grass
setblock ~24 ~125 ~94 grass_block
setblock ~24 ~125 ~95 grass_block
setblock ~24 ~125 ~96 grass_block
setblock ~24 ~125 ~97 grass_block
setblock ~24 ~125 ~98 dirt
setblock ~24 ~125 ~99 dirt
setblock ~24 ~125 ~100 dirt
setblock ~24 ~125 ~148 grass_block
setblock ~24 ~125 ~149 grass_block
setblock ~24 ~125 ~151 grass_block
setblock ~24 ~125 ~152 grass_block
setblock ~24 ~125 ~153 grass_block
setblock ~24 ~125 ~154 grass_block
setblock ~24 ~125 ~155 grass_block
setblock ~24 ~126 ~98 grass_block
setblock ~24 ~126 ~99 grass_block
setblock ~24 ~126 ~100 grass_block
setblock ~24 ~126 ~149 short_grass
setblock ~24 ~126 ~154 short_grass
setblock ~25 ~116 ~152 dirt
setblock ~25 ~117 ~96 dirt
setblock ~25 ~117 ~151 dirt
setblock ~25 ~117 ~152 dirt
setblock ~25 ~117 ~153 dirt
setblock ~25 ~118 ~95 dirt
setblock ~25 ~118 ~96 dirt
setblock ~25 ~118 ~97 dirt
setblock ~25 ~118 ~151 dirt
setblock ~25 ~118 ~152 dirt
setblock ~25 ~118 ~153 dirt
setblock ~25 ~119 ~94 dirt
setblock ~25 ~119 ~95 dirt
setblock ~25 ~119 ~96 dirt
setblock ~25 ~119 ~97 dirt
setblock ~25 ~119 ~150 dirt
setblock ~25 ~119 ~151 dirt
setblock ~25 ~119 ~152 dirt
setblock ~25 ~119 ~153 dirt
setblock ~25 ~119 ~154 dirt
setblock ~25 ~120 ~64 dirt
setblock ~25 ~120 ~92 dirt
setblock ~25 ~120 ~93 dirt
setblock ~25 ~120 ~94 dirt
setblock ~25 ~120 ~95 dirt
setblock ~25 ~120 ~96 dirt
setblock ~25 ~120 ~97 dirt
setblock ~25 ~120 ~98 dirt
setblock ~25 ~120 ~150 dirt
setblock ~25 ~120 ~151 dirt
setblock ~25 ~120 ~152 dirt
setblock ~25 ~120 ~153 dirt
setblock ~25 ~120 ~154 dirt
setblock ~25 ~120 ~155 dirt
setblock ~25 ~121 ~64 dirt
setblock ~25 ~121 ~91 dirt
setblock ~25 ~121 ~92 dirt
setblock ~25 ~121 ~93 dirt
setblock ~25 ~121 ~94 dirt
setblock ~25 ~121 ~95 dirt
setblock ~25 ~121 ~96 dirt
setblock ~25 ~121 ~97 dirt
setblock ~25 ~121 ~98 dirt
setblock ~25 ~121 ~99 dirt
setblock ~25 ~121 ~105 dirt
setblock ~25 ~121 ~107 dirt
setblock ~25 ~121 ~108 dirt
setblock ~25 ~121 ~148 dirt
setblock ~25 ~121 ~150 dirt
setblock ~25 ~121 ~151 dirt
setblock ~25 ~121 ~152 dirt
setblock ~25 ~121 ~153 dirt
setblock ~25 ~121 ~154 dirt
setblock ~25 ~121 ~155 dirt
setblock ~25 ~121 ~156 dirt
setblock ~25 ~122 ~64 dirt
setblock ~25 ~122 ~91 dirt
setblock ~25 ~122 ~92 dirt
setblock ~25 ~122 ~93 dirt
setblock ~25 ~122 ~94 dirt
setblock ~25 ~122 ~95 dirt
setblock ~25 ~122 ~96 dirt
setblock ~25 ~122 ~97 dirt
setblock ~25 ~122 ~98 dirt
setblock ~25 ~122 ~99 dirt
setblock ~25 ~122 ~105 dirt
setblock ~25 ~122 ~107 dirt
setblock ~25 ~122 ~108 dirt
setblock ~25 ~122 ~148 dirt
setblock ~25 ~122 ~150 dirt
setblock ~25 ~122 ~151 dirt
setblock ~25 ~122 ~152 dirt
setblock ~25 ~122 ~153 dirt
setblock ~25 ~122 ~154 dirt
setblock ~25 ~122 ~155 dirt
setblock ~25 ~122 ~156 dirt
setblock ~25 ~123 ~64 dirt
setblock ~25 ~123 ~91 dirt
setblock ~25 ~123 ~92 dirt
setblock ~25 ~123 ~93 dirt
setblock ~25 ~123 ~94 dirt
setblock ~25 ~123 ~95 dirt
setblock ~25 ~123 ~96 dirt
setblock ~25 ~123 ~97 dirt
setblock ~25 ~123 ~98 dirt
setblock ~25 ~123 ~99 dirt
setblock ~25 ~123 ~105 dirt
setblock ~25 ~123 ~107 dirt
setblock ~25 ~123 ~108 dirt
setblock ~25 ~123 ~148 dirt
setblock ~25 ~123 ~150 dirt
setblock ~25 ~123 ~151 dirt
setblock ~25 ~123 ~152 dirt
setblock ~25 ~123 ~153 dirt
setblock ~25 ~123 ~154 dirt
setblock ~25 ~123 ~155 dirt
setblock ~25 ~123 ~156 dirt
setblock ~25 ~124 ~64 dirt
setblock ~25 ~124 ~91 grass_block
setblock ~25 ~124 ~92 grass_block
setblock ~25 ~124 ~93 grass_block
setblock ~25 ~124 ~94 grass_block
setblock ~25 ~124 ~95 dirt
setblock ~25 ~124 ~96 dirt
setblock ~25 ~124 ~97 dirt
setblock ~25 ~124 ~98 dirt
setblock ~25 ~124 ~99 dirt
setblock ~25 ~124 ~105 dirt
setblock ~25 ~124 ~107 dirt
setblock ~25 ~124 ~108 dirt
setblock ~25 ~124 ~148 dirt
setblock ~25 ~124 ~150 dirt
setblock ~25 ~124 ~151 dirt
setblock ~25 ~124 ~152 dirt
setblock ~25 ~124 ~153 dirt
setblock ~25 ~124 ~154 dirt
setblock ~25 ~124 ~155 dirt
setblock ~25 ~124 ~156 dirt
setblock ~25 ~125 ~64 dirt
setblock ~25 ~125 ~92 short_grass
setblock ~25 ~125 ~93 short_grass
setblock ~25 ~125 ~95 grass_block
setblock ~25 ~125 ~96 grass_block
setblock ~25 ~125 ~97 grass_block
setblock ~25 ~125 ~98 grass_block
setblock ~25 ~125 ~99 dirt
setblock ~25 ~125 ~105 dirt
setblock ~25 ~125 ~107 grass_block
setblock ~25 ~125 ~108 grass_block
setblock ~25 ~125 ~148 grass_block
setblock ~25 ~125 ~150 grass_block
setblock ~25 ~125 ~151 grass_block
setblock ~25 ~125 ~152 grass_block
setblock ~25 ~125 ~153 grass_block
setblock ~25 ~125 ~154 grass_block
setblock ~25 ~125 ~155 grass_block
setblock ~25 ~125 ~156 grass_block
setblock ~25 ~126 ~64 grass_block
setblock ~25 ~126 ~96 short_grass
setblock ~25 ~126 ~99 grass_block
setblock ~25 ~126 ~105 grass_block
setblock ~25 ~126 ~108 short_grass
setblock ~25 ~126 ~151 short_grass
setblock ~25 ~126 ~153 short_grass
setblock ~25 ~126 ~155 short_grass
setblock ~25 ~127 ~99 short_grass
setblock ~26 ~114 ~152 dirt
setblock ~26 ~115 ~151 dirt
setblock ~26 ~115 ~152 dirt
setblock ~26 ~115 ~153 dirt
setblock ~26 ~116 ~151 dirt
setblock ~26 ~116 ~152 dirt
setblock ~26 ~116 ~153 dirt
setblock ~26 ~117 ~150 dirt
setblock ~26 ~117 ~151 dirt
setblock ~26 ~117 ~152 dirt
setblock ~26 ~117 ~153 dirt
setblock ~26 ~117 ~154 dirt
setblock ~26 ~118 ~64 dirt
setblock ~26 ~118 ~96 dirt
setblock ~26 ~118 ~108 dirt
setblock ~26 ~118 ~150 dirt
setblock ~26 ~118 ~151 dirt
setblock ~26 ~118 ~152 dirt
setblock ~26 ~118 ~153 dirt
setblock ~26 ~118 ~154 dirt
setblock ~26 ~119 ~63 dirt
setblock ~26 ~119 ~64 dirt
setblock ~26 ~119 ~65 dirt
setblock ~26 ~119 ~96 dirt
setblock ~26 ~119 ~108 dirt
setblock ~26 ~119 ~109 dirt
setblock ~26 ~119 ~150 dirt
setblock ~26 ~119 ~151 dirt
setblock ~26 ~119 ~152 dirt
setblock ~26 ~119 ~153 dirt
setblock ~26 ~119 ~154 dirt
setblock ~26 ~120 ~63 dirt
setblock ~26 ~120 ~64 dirt
setblock ~26 ~120 ~65 dirt
setblock ~26 ~120 ~95 dirt
setblock ~26 ~120 ~96 dirt
setblock ~26 ~120 ~97 dirt
setblock ~26 ~120 ~105 dirt
setblock ~26 ~120 ~107 dirt
setblock ~26 ~120 ~108 dirt
setblock ~26 ~120 ~109 dirt
setblock ~26 ~120 ~150 dirt
setblock ~26 ~120 ~151 dirt
setblock ~26 ~120 ~152 dirt
setblock ~26 ~120 ~153 dirt
setblock ~26 ~120 ~154 dirt
setblock ~26 ~120 ~155 dirt
setblock ~26 ~121 ~63 dirt
setblock ~26 ~121 ~64 dirt
setblock ~26 ~121 ~65 dirt
setblock ~26 ~121 ~93 dirt
setblock ~26 ~121 ~94 dirt
setblock ~26 ~121 ~95 dirt
setblock ~26 ~121 ~96 dirt
setblock ~26 ~121 ~97 dirt
setblock ~26 ~121 ~104 dirt
setblock ~26 ~121 ~105 dirt
setblock ~26 ~121 ~106 dirt
setblock ~26 ~121 ~107 dirt
setblock ~26 ~121 ~108 dirt
setblock ~26 ~121 ~109 dirt
setblock ~26 ~121 ~110 dirt
setblock ~26 ~121 ~149 dirt
setblock ~26 ~121 ~150 dirt
setblock ~26 ~121 ~151 dirt
setblock ~26 ~121 ~152 dirt
setblock ~26 ~121 ~153 dirt
setblock ~26 ~121 ~154 dirt
setblock ~26 ~121 ~155 dirt
setblock ~26 ~121 ~156 dirt
setblock ~26 ~122 ~63 dirt
setblock ~26 ~122 ~64 dirt
setblock ~26 ~122 ~65 dirt
setblock ~26 ~122 ~93 dirt
setblock ~26 ~122 ~94 dirt
setblock ~26 ~122 ~95 dirt
setblock ~26 ~122 ~96 dirt
setblock ~26 ~122 ~97 dirt
setblock ~26 ~122 ~104 dirt
setblock ~26 ~122 ~105 dirt
setblock ~26 ~122 ~106 dirt
setblock ~26 ~122 ~107 dirt
setblock ~26 ~122 ~108 dirt
setblock ~26 ~122 ~109 dirt
setblock ~26 ~122 ~110 dirt
setblock ~26 ~122 ~149 dirt
setblock ~26 ~122 ~150 dirt
setblock ~26 ~122 ~151 dirt
setblock ~26 ~122 ~152 dirt
setblock ~26 ~122 ~153 dirt
setblock ~26 ~122 ~154 dirt
setblock ~26 ~122 ~155 dirt
setblock ~26 ~122 ~156 dirt
setblock ~26 ~123 ~63 dirt
setblock ~26 ~123 ~64 dirt
setblock ~26 ~123 ~65 dirt
setblock ~26 ~123 ~93 dirt
setblock ~26 ~123 ~94 dirt
setblock ~26 ~123 ~95 dirt
setblock ~26 ~123 ~96 dirt
setblock ~26 ~123 ~97 dirt
setblock ~26 ~123 ~104 dirt
setblock ~26 ~123 ~105 dirt
setblock ~26 ~123 ~106 dirt
setblock ~26 ~123 ~107 dirt
setblock ~26 ~123 ~108 dirt
setblock ~26 ~123 ~109 dirt
setblock ~26 ~123 ~110 dirt
setblock ~26 ~123 ~149 dirt
setblock ~26 ~123 ~150 dirt
setblock ~26 ~123 ~151 dirt
setblock ~26 ~123 ~152 dirt
setblock ~26 ~123 ~153 dirt
setblock ~26 ~123 ~154 dirt
setblock ~26 ~123 ~155 dirt
setblock ~26 ~123 ~156 dirt
setblock ~26 ~124 ~63 dirt
setblock ~26 ~124 ~64 dirt
setblock ~26 ~124 ~65 dirt
setblock ~26 ~124 ~93 grass_block
setblock ~26 ~124 ~94 grass_block
setblock ~26 ~124 ~95 grass_block
setblock ~26 ~124 ~96 dirt
setblock ~26 ~124 ~97 dirt
setblock ~26 ~124 ~104 dirt
setblock ~26 ~124 ~105 dirt
setblock ~26 ~124 ~106 dirt
setblock ~26 ~124 ~107 dirt
setblock ~26 ~124 ~108 dirt
setblock ~26 ~124 ~109 dirt
setblock ~26 ~124 ~110 dirt
setblock ~26 ~124 ~149 dirt
setblock ~26 ~124 ~150 dirt
setblock ~26 ~124 ~151 dirt
setblock ~26 ~124 ~152 dirt
setblock ~26 ~124 ~153 dirt
setblock ~26 ~124 ~154 dirt
setblock ~26 ~124 ~155 dirt
setblock ~26 ~124 ~156 dirt
setblock ~26 ~125 ~63 dirt
setblock ~26 ~125 ~64 dirt
