setblock ~181 ~120 ~95 dirt
setblock ~181 ~120 ~96 dirt
setblock ~181 ~120 ~97 dirt
setblock ~181 ~120 ~98 dirt
setblock ~181 ~120 ~99 dirt
setblock ~181 ~120 ~100 dirt
setblock ~181 ~120 ~101 dirt
setblock ~181 ~120 ~102 dirt
setblock ~181 ~120 ~103 dirt
setblock ~181 ~120 ~104 dirt
setblock ~181 ~120 ~105 dirt
setblock ~181 ~120 ~106 dirt
setblock ~181 ~120 ~107 dirt
setblock ~181 ~120 ~108 dirt
setblock ~181 ~120 ~109 dirt
setblock ~181 ~120 ~110 dirt
setblock ~181 ~120 ~111 dirt
setblock ~181 ~120 ~112 dirt
setblock ~181 ~120 ~113 dirt
setblock ~181 ~120 ~114 dirt
setblock ~181 ~120 ~115 dirt
setblock ~181 ~120 ~116 dirt
setblock ~181 ~120 ~117 dirt
setblock ~181 ~120 ~118 dirt
setblock ~181 ~120 ~119 dirt
setblock ~181 ~120 ~120 dirt
setblock ~181 ~120 ~121 dirt
setblock ~181 ~120 ~122 dirt
setblock ~181 ~120 ~123 dirt
setblock ~181 ~120 ~124 dirt
setblock ~181 ~120 ~125 dirt
setblock ~181 ~120 ~126 dirt
setblock ~181 ~120 ~127 dirt
setblock ~181 ~121 ~57 dirt
setblock ~181 ~121 ~58 dirt
setblock ~181 ~121 ~59 dirt
setblock ~181 ~121 ~60 dirt
setblock ~181 ~121 ~61 dirt
setblock ~181 ~121 ~62 dirt
setblock ~181 ~121 ~63 dirt
setblock ~181 ~121 ~64 dirt
setblock ~181 ~121 ~65 dirt
setblock ~181 ~121 ~82 dirt
setblock ~181 ~121 ~83 dirt
setblock ~181 ~121 ~84 dirt
setblock ~181 ~121 ~85 dirt
setblock ~181 ~121 ~86 dirt
setblock ~181 ~121 ~87 dirt
setblock ~181 ~121 ~88 dirt
setblock ~181 ~121 ~89 dirt
setblock ~181 ~121 ~90 dirt
setblock ~181 ~121 ~91 dirt
setblock ~181 ~121 ~92 dirt
setblock ~181 ~121 ~93 dirt
setblock ~181 ~121 ~94 dirt
setblock ~181 ~121 ~95 dirt
setblock ~181 ~121 ~96 dirt
setblock ~181 ~121 ~97 dirt
setblock ~181 ~121 ~98 dirt
setblock ~181 ~121 ~99 dirt
setblock ~181 ~121 ~100 dirt
setblock ~181 ~121 ~101 dirt
setblock ~181 ~121 ~102 dirt
setblock ~181 ~121 ~103 dirt
setblock ~181 ~121 ~104 dirt
setblock ~181 ~121 ~105 dirt
setblock ~181 ~121 ~106 dirt
setblock ~181 ~121 ~107 dirt
setblock ~181 ~121 ~108 dirt
setblock ~181 ~121 ~109 dirt
setblock ~181 ~121 ~110 dirt
setblock ~181 ~121 ~111 dirt
setblock ~181 ~121 ~112 dirt
setblock ~181 ~121 ~113 dirt
setblock ~181 ~121 ~114 dirt
setblock ~181 ~121 ~115 dirt
setblock ~181 ~121 ~116 dirt
setblock ~181 ~121 ~117 dirt
setblock ~181 ~121 ~118 dirt
setblock ~181 ~121 ~119 dirt
setblock ~181 ~121 ~120 dirt
setblock ~181 ~121 ~121 dirt
setblock ~181 ~121 ~122 dirt
setblock ~181 ~121 ~123 dirt
setblock ~181 ~121 ~124 dirt
setblock ~181 ~121 ~125 dirt
setblock ~181 ~121 ~126 dirt
setblock ~181 ~121 ~127 dirt
setblock ~181 ~121 ~128 dirt
setblock ~181 ~122 ~57 dirt
setblock ~181 ~122 ~58 dirt
setblock ~181 ~122 ~59 dirt
setblock ~181 ~122 ~60 dirt
setblock ~181 ~122 ~61 dirt
setblock ~181 ~122 ~62 dirt
setblock ~181 ~122 ~63 dirt
setblock ~181 ~122 ~64 dirt
setblock ~181 ~122 ~65 dirt
setblock ~181 ~122 ~82 dirt
setblock ~181 ~122 ~83 dirt
setblock ~181 ~122 ~84 dirt
setblock ~181 ~122 ~85 dirt
setblock ~181 ~122 ~86 dirt
setblock ~181 ~122 ~87 dirt
setblock ~181 ~122 ~88 dirt
setblock ~181 ~122 ~89 dirt
setblock ~181 ~122 ~90 dirt
setblock ~181 ~122 ~91 dirt
setblock ~181 ~122 ~92 dirt
setblock ~181 ~122 ~93 dirt
setblock ~181 ~122 ~94 dirt
setblock ~181 ~122 ~95 dirt
setblock ~181 ~122 ~96 dirt
setblock ~181 ~122 ~97 dirt
setblock ~181 ~122 ~98 dirt
setblock ~181 ~122 ~99 dirt
setblock ~181 ~122 ~100 dirt
setblock ~181 ~122 ~101 dirt
setblock ~181 ~122 ~102 dirt
setblock ~181 ~122 ~103 dirt
setblock ~181 ~122 ~104 dirt
setblock ~181 ~122 ~105 dirt
setblock ~181 ~122 ~106 dirt
setblock ~181 ~122 ~107 dirt
setblock ~181 ~122 ~108 dirt
setblock ~181 ~122 ~109 dirt
setblock ~181 ~122 ~110 dirt
setblock ~181 ~122 ~111 dirt
setblock ~181 ~122 ~112 dirt
setblock ~181 ~122 ~113 dirt
setblock ~181 ~122 ~114 dirt
setblock ~181 ~122 ~115 dirt
setblock ~181 ~122 ~116 dirt
setblock ~181 ~122 ~117 dirt
setblock ~181 ~122 ~118 dirt
setblock ~181 ~122 ~119 dirt
setblock ~181 ~122 ~120 dirt
setblock ~181 ~122 ~121 dirt
setblock ~181 ~122 ~122 dirt
setblock ~181 ~122 ~123 dirt
setblock ~181 ~122 ~124 dirt
setblock ~181 ~122 ~125 dirt
setblock ~181 ~122 ~126 dirt
setblock ~181 ~122 ~127 dirt
setblock ~181 ~122 ~128 dirt
setblock ~181 ~123 ~57 dirt
setblock ~181 ~123 ~58 dirt
setblock ~181 ~123 ~59 dirt
setblock ~181 ~123 ~60 dirt
setblock ~181 ~123 ~61 dirt
setblock ~181 ~123 ~62 dirt
setblock ~181 ~123 ~63 dirt
setblock ~181 ~123 ~64 dirt
setblock ~181 ~123 ~65 dirt
setblock ~181 ~123 ~82 grass_block
setblock ~181 ~123 ~83 grass_block
setblock ~181 ~123 ~84 grass_block
setblock ~181 ~123 ~85 grass_block
setblock ~181 ~123 ~86 grass_block
setblock ~181 ~123 ~87 grass_block
setblock ~181 ~123 ~88 grass_block
setblock ~181 ~123 ~89 grass_block
setblock ~181 ~123 ~90 grass_block
setblock ~181 ~123 ~91 grass_block
setblock ~181 ~123 ~92 dirt
setblock ~181 ~123 ~93 dirt
setblock ~181 ~123 ~94 dirt
setblock ~181 ~123 ~95 dirt
setblock ~181 ~123 ~96 dirt
setblock ~181 ~123 ~97 dirt
setblock ~181 ~123 ~98 dirt
setblock ~181 ~123 ~99 dirt
setblock ~181 ~123 ~100 dirt
setblock ~181 ~123 ~101 dirt
setblock ~181 ~123 ~102 dirt
setblock ~181 ~123 ~103 dirt
setblock ~181 ~123 ~104 dirt
setblock ~181 ~123 ~105 dirt
setblock ~181 ~123 ~106 dirt
setblock ~181 ~123 ~107 dirt
setblock ~181 ~123 ~108 dirt
setblock ~181 ~123 ~109 dirt
setblock ~181 ~123 ~110 dirt
setblock ~181 ~123 ~111 dirt
setblock ~181 ~123 ~112 dirt
setblock ~181 ~123 ~113 dirt
setblock ~181 ~123 ~114 dirt
setblock ~181 ~123 ~115 dirt
setblock ~181 ~123 ~116 dirt
setblock ~181 ~123 ~117 dirt
setblock ~181 ~123 ~118 dirt
setblock ~181 ~123 ~119 dirt
setblock ~181 ~123 ~120 dirt
setblock ~181 ~123 ~121 dirt
setblock ~181 ~123 ~122 dirt
setblock ~181 ~123 ~123 dirt
setblock ~181 ~123 ~124 dirt
setblock ~181 ~123 ~125 dirt
setblock ~181 ~123 ~126 dirt
setblock ~181 ~123 ~127 dirt
setblock ~181 ~123 ~128 dirt
setblock ~181 ~124 ~57 dirt
setblock ~181 ~124 ~58 dirt
setblock ~181 ~124 ~59 dirt
setblock ~181 ~124 ~60 dirt
setblock ~181 ~124 ~61 dirt
setblock ~181 ~124 ~62 dirt
setblock ~181 ~124 ~63 dirt
setblock ~181 ~124 ~64 dirt
setblock ~181 ~124 ~65 dirt
setblock ~181 ~124 ~82 short_grass
setblock ~181 ~124 ~84 short_grass
setblock ~181 ~124 ~87 short_grass
setblock ~181 ~124 ~88 short_grass
setblock ~181 ~124 ~90 short_grass
setblock ~181 ~124 ~92 grass_block
setblock ~181 ~124 ~93 grass_block
setblock ~181 ~124 ~94 grass_block
setblock ~181 ~124 ~95 dirt
setblock ~181 ~124 ~96 dirt
setblock ~181 ~124 ~97 dirt
setblock ~181 ~124 ~98 dirt
setblock ~181 ~124 ~99 dirt
setblock ~181 ~124 ~100 dirt
setblock ~181 ~124 ~101 dirt
setblock ~181 ~124 ~102 dirt
setblock ~181 ~124 ~103 dirt
setblock ~181 ~124 ~104 dirt
setblock ~181 ~124 ~105 dirt
setblock ~181 ~124 ~106 dirt
setblock ~181 ~124 ~107 dirt
setblock ~181 ~124 ~108 grass_block
setblock ~181 ~124 ~109 grass_block
setblock ~181 ~124 ~110 grass_block
setblock ~181 ~124 ~111 grass_block
setblock ~181 ~124 ~112 dirt
setblock ~181 ~124 ~113 dirt
setblock ~181 ~124 ~114 dirt
setblock ~181 ~124 ~115 dirt
setblock ~181 ~124 ~116 dirt
setblock ~181 ~124 ~117 dirt
setblock ~181 ~124 ~118 dirt
setblock ~181 ~124 ~119 dirt
setblock ~181 ~124 ~120 dirt
setblock ~181 ~124 ~121 dirt
setblock ~181 ~124 ~122 dirt
setblock ~181 ~124 ~123 dirt
setblock ~181 ~124 ~124 dirt
setblock ~181 ~124 ~125 dirt
setblock ~181 ~124 ~126 dirt
setblock ~181 ~124 ~127 grass_block
setblock ~181 ~124 ~128 grass_block
setblock ~181 ~125 ~57 dirt
setblock ~181 ~125 ~58 dirt
setblock ~181 ~125 ~59 dirt
setblock ~181 ~125 ~60 dirt
setblock ~181 ~125 ~61 dirt
setblock ~181 ~125 ~62 dirt
setblock ~181 ~125 ~63 dirt
setblock ~181 ~125 ~64 dirt
setblock ~181 ~125 ~65 dirt
setblock ~181 ~125 ~95 grass_block
setblock ~181 ~125 ~96 grass_block
setblock ~181 ~125 ~97 grass_block
setblock ~181 ~125 ~98 dirt
setblock ~181 ~125 ~99 dirt
setblock ~181 ~125 ~100 dirt
setblock ~181 ~125 ~101 dirt
setblock ~181 ~125 ~102 dirt
setblock ~181 ~125 ~103 dirt
setblock ~181 ~125 ~104 dirt
setblock ~181 ~125 ~105 grass_block
setblock ~181 ~125 ~106 grass_block
setblock ~181 ~125 ~107 grass_block
setblock ~181 ~125 ~110 short_grass
setblock ~181 ~125 ~112 grass_block
setblock ~181 ~125 ~113 grass_block
setblock ~181 ~125 ~114 grass_block
setblock ~181 ~125 ~115 dirt
setblock ~181 ~125 ~116 dirt
setblock ~181 ~125 ~117 dirt
setblock ~181 ~125 ~118 dirt
setblock ~181 ~125 ~119 dirt
setblock ~181 ~125 ~120 dirt
setblock ~181 ~125 ~121 dirt
setblock ~181 ~125 ~122 dirt
setblock ~181 ~125 ~123 dirt
setblock ~181 ~125 ~124 dirt
setblock ~181 ~125 ~125 grass_block
setblock ~181 ~125 ~126 grass_block
setblock ~181 ~125 ~127 short_grass
setblock ~181 ~126 ~57 dirt
setblock ~181 ~126 ~58 dirt
setblock ~181 ~126 ~59 dirt
setblock ~181 ~126 ~60 dirt
setblock ~181 ~126 ~61 dirt
setblock ~181 ~126 ~62 dirt
setblock ~181 ~126 ~63 dirt
setblock ~181 ~126 ~64 grass_block
setblock ~181 ~126 ~65 grass_block
setblock ~181 ~126 ~96 short_grass
setblock ~181 ~126 ~97 poppy
setblock ~181 ~126 ~98 grass_block
setblock ~181 ~126 ~99 grass_block
setblock ~181 ~126 ~100 grass_block
setblock ~181 ~126 ~101 grass_block
setblock ~181 ~126 ~102 grass_block
setblock ~181 ~126 ~103 grass_block
setblock ~181 ~126 ~104 grass_block
setblock ~181 ~126 ~112 short_grass
setblock ~181 ~126 ~113 short_grass
setblock ~181 ~126 ~115 grass_block
setblock ~181 ~126 ~116 grass_block
setblock ~181 ~126 ~117 grass_block
setblock ~181 ~126 ~118 dirt
setblock ~181 ~126 ~119 dirt
setblock ~181 ~126 ~120 dirt
setblock ~181 ~126 ~121 dirt
setblock ~181 ~126 ~122 dirt
setblock ~181 ~126 ~123 grass_block
setblock ~181 ~126 ~124 grass_block
setblock ~181 ~126 ~125 short_grass
setblock ~181 ~127 ~57 dirt
setblock ~181 ~127 ~58 dirt
setblock ~181 ~127 ~59 dirt
setblock ~181 ~127 ~60 dirt
setblock ~181 ~127 ~61 dirt
setblock ~181 ~127 ~62 grass_block
setblock ~181 ~127 ~63 grass_block
setblock ~181 ~127 ~65 short_grass
setblock ~181 ~127 ~99 short_grass
setblock ~181 ~127 ~100 fern
setblock ~181 ~127 ~103 short_grass
setblock ~181 ~127 ~104 short_grass
setblock ~181 ~127 ~118 grass_block
setblock ~181 ~127 ~119 grass_block
setblock ~181 ~127 ~120 grass_block
setblock ~181 ~127 ~121 grass_block
setblock ~181 ~127 ~122 grass_block
setblock ~181 ~128 ~57 grass_block
setblock ~181 ~128 ~58 grass_block
setblock ~181 ~128 ~59 grass_block
setblock ~181 ~128 ~60 dirt
setblock ~181 ~128 ~61 grass_block
setblock ~181 ~128 ~118 short_grass
setblock ~181 ~128 ~121 short_grass
setblock ~181 ~128 ~122 poppy
setblock ~181 ~129 ~57 short_grass
setblock ~181 ~129 ~58 short_grass
setblock ~181 ~129 ~60 grass_block
setblock ~181 ~129 ~61 short_grass
setblock ~181 ~130 ~60 short_grass
setblock ~182 ~107 ~95 dirt
setblock ~182 ~107 ~96 dirt
setblock ~182 ~107 ~97 dirt
setblock ~182 ~107 ~98 dirt
setblock ~182 ~108 ~94 dirt
setblock ~182 ~108 ~95 dirt
setblock ~182 ~108 ~96 dirt
setblock ~182 ~108 ~97 dirt
setblock ~182 ~108 ~98 dirt
setblock ~182 ~108 ~99 dirt
setblock ~182 ~109 ~93 dirt
setblock ~182 ~109 ~94 dirt
setblock ~182 ~109 ~95 dirt
setblock ~182 ~109 ~96 dirt
setblock ~182 ~109 ~97 dirt
setblock ~182 ~109 ~98 dirt
setblock ~182 ~109 ~99 dirt
setblock ~182 ~109 ~100 dirt
setblock ~182 ~110 ~92 dirt
setblock ~182 ~110 ~93 dirt
setblock ~182 ~110 ~94 dirt
setblock ~182 ~110 ~95 dirt
setblock ~182 ~110 ~96 dirt
setblock ~182 ~110 ~97 dirt
setblock ~182 ~110 ~98 dirt
setblock ~182 ~110 ~99 dirt
setblock ~182 ~110 ~100 dirt
setblock ~182 ~110 ~101 dirt
setblock ~182 ~111 ~91 dirt
setblock ~182 ~111 ~92 dirt
setblock ~182 ~111 ~93 dirt
setblock ~182 ~111 ~94 dirt
setblock ~182 ~111 ~95 dirt
setblock ~182 ~111 ~96 dirt
setblock ~182 ~111 ~97 dirt
setblock ~182 ~111 ~98 dirt
setblock ~182 ~111 ~99 dirt
setblock ~182 ~111 ~100 dirt
setblock ~182 ~111 ~101 dirt
setblock ~182 ~112 ~90 dirt
setblock ~182 ~112 ~91 dirt
setblock ~182 ~112 ~92 dirt
setblock ~182 ~112 ~93 dirt
setblock ~182 ~112 ~94 dirt
setblock ~182 ~112 ~95 dirt
setblock ~182 ~112 ~96 dirt
setblock ~182 ~112 ~97 dirt
setblock ~182 ~112 ~98 dirt
setblock ~182 ~112 ~99 dirt
setblock ~182 ~112 ~100 dirt
setblock ~182 ~112 ~101 dirt
setblock ~182 ~112 ~102 dirt
setblock ~182 ~113 ~90 dirt
setblock ~182 ~113 ~91 dirt
setblock ~182 ~113 ~92 dirt
setblock ~182 ~113 ~93 dirt
setblock ~182 ~113 ~94 dirt
setblock ~182 ~113 ~95 dirt
setblock ~182 ~113 ~96 dirt
setblock ~182 ~113 ~97 dirt
setblock ~182 ~113 ~98 dirt
setblock ~182 ~113 ~99 dirt
setblock ~182 ~113 ~100 dirt
setblock ~182 ~113 ~101 dirt
setblock ~182 ~113 ~102 dirt
setblock ~182 ~113 ~103 dirt
setblock ~182 ~113 ~106 dirt
setblock ~182 ~114 ~89 dirt
setblock ~182 ~114 ~90 dirt
setblock ~182 ~114 ~91 dirt
setblock ~182 ~114 ~92 dirt
setblock ~182 ~114 ~93 dirt
setblock ~182 ~114 ~94 dirt
setblock ~182 ~114 ~95 dirt
setblock ~182 ~114 ~96 dirt
setblock ~182 ~114 ~97 dirt
setblock ~182 ~114 ~98 dirt
setblock ~182 ~114 ~99 dirt
setblock ~182 ~114 ~100 dirt
setblock ~182 ~114 ~101 dirt
setblock ~182 ~114 ~102 dirt
setblock ~182 ~114 ~103 dirt
setblock ~182 ~114 ~104 dirt
setblock ~182 ~114 ~105 dirt
setblock ~182 ~114 ~106 dirt
setblock ~182 ~114 ~107 dirt
setblock ~182 ~115 ~88 dirt
setblock ~182 ~115 ~89 dirt
setblock ~182 ~115 ~90 dirt
setblock ~182 ~115 ~91 dirt
setblock ~182 ~115 ~92 dirt
setblock ~182 ~115 ~93 dirt
setblock ~182 ~115 ~94 dirt
setblock ~182 ~115 ~95 dirt
setblock ~182 ~115 ~96 dirt
setblock ~182 ~115 ~97 dirt
setblock ~182 ~115 ~98 dirt
setblock ~182 ~115 ~99 dirt
setblock ~182 ~115 ~100 dirt
setblock ~182 ~115 ~101 dirt
setblock ~182 ~115 ~102 dirt
setblock ~182 ~115 ~103 dirt
setblock ~182 ~115 ~104 dirt
setblock ~182 ~115 ~105 dirt
setblock ~182 ~115 ~106 dirt
setblock ~182 ~115 ~107 dirt
setblock ~182 ~115 ~108 dirt
setblock ~182 ~116 ~87 dirt
setblock ~182 ~116 ~88 dirt
setblock ~182 ~116 ~89 dirt
setblock ~182 ~116 ~90 dirt
setblock ~182 ~116 ~91 dirt
setblock ~182 ~116 ~92 dirt
setblock ~182 ~116 ~93 dirt
setblock ~182 ~116 ~94 dirt
setblock ~182 ~116 ~95 dirt
setblock ~182 ~116 ~96 dirt
setblock ~182 ~116 ~97 dirt
setblock ~182 ~116 ~98 dirt
setblock ~182 ~116 ~99 dirt
setblock ~182 ~116 ~100 dirt
setblock ~182 ~116 ~101 dirt
setblock ~182 ~116 ~102 dirt
setblock ~182 ~116 ~103 dirt
setblock ~182 ~116 ~104 dirt
setblock ~182 ~116 ~105 dirt
setblock ~182 ~116 ~106 dirt
setblock ~182 ~116 ~107 dirt
setblock ~182 ~116 ~108 dirt
setblock ~182 ~116 ~109 dirt
setblock ~182 ~117 ~87 dirt
setblock ~182 ~117 ~88 dirt
setblock ~182 ~117 ~89 dirt
setblock ~182 ~117 ~90 dirt
setblock ~182 ~117 ~91 dirt
setblock ~182 ~117 ~92 dirt
setblock ~182 ~117 ~93 dirt
setblock ~182 ~117 ~94 dirt
setblock ~182 ~117 ~95 dirt
setblock ~182 ~117 ~96 dirt
setblock ~182 ~117 ~97 dirt
setblock ~182 ~117 ~98 dirt
setblock ~182 ~117 ~99 dirt
setblock ~182 ~117 ~100 dirt
setblock ~182 ~117 ~101 dirt
setblock ~182 ~117 ~102 dirt
setblock ~182 ~117 ~103 dirt
setblock ~182 ~117 ~104 dirt
setblock ~182 ~117 ~105 dirt
setblock ~182 ~117 ~106 dirt
setblock ~182 ~117 ~107 dirt
setblock ~182 ~117 ~108 dirt
setblock ~182 ~117 ~109 dirt
setblock ~182 ~117 ~110 dirt
setblock ~182 ~117 ~119 dirt
setblock ~182 ~117 ~120 dirt
setblock ~182 ~117 ~121 dirt
setblock ~182 ~118 ~86 dirt
setblock ~182 ~118 ~87 dirt
setblock ~182 ~118 ~88 dirt
setblock ~182 ~118 ~89 dirt
setblock ~182 ~118 ~90 dirt
setblock ~182 ~118 ~91 dirt
setblock ~182 ~118 ~92 dirt
setblock ~182 ~118 ~93 dirt
setblock ~182 ~118 ~94 dirt
setblock ~182 ~118 ~95 dirt
setblock ~182 ~118 ~96 dirt
setblock ~182 ~118 ~97 dirt
setblock ~182 ~118 ~98 dirt
setblock ~182 ~118 ~99 dirt
setblock ~182 ~118 ~100 dirt
setblock ~182 ~118 ~101 dirt
setblock ~182 ~118 ~102 dirt
setblock ~182 ~118 ~103 dirt
setblock ~182 ~118 ~104 dirt
setblock ~182 ~118 ~105 dirt
setblock ~182 ~118 ~106 dirt
setblock ~182 ~118 ~107 dirt
setblock ~182 ~118 ~108 dirt
setblock ~182 ~118 ~109 dirt
setblock ~182 ~118 ~110 dirt
setblock ~182 ~118 ~111 dirt
setblock ~182 ~118 ~118 dirt
setblock ~182 ~118 ~119 dirt
setblock ~182 ~118 ~120 dirt
setblock ~182 ~118 ~121 dirt
setblock ~182 ~118 ~122 dirt
setblock ~182 ~118 ~123 dirt
setblock ~182 ~119 ~85 dirt
setblock ~182 ~119 ~86 dirt
setblock ~182 ~119 ~87 dirt
setblock ~182 ~119 ~88 dirt
setblock ~182 ~119 ~89 dirt
setblock ~182 ~119 ~90 dirt
setblock ~182 ~119 ~91 dirt
setblock ~182 ~119 ~92 dirt
setblock ~182 ~119 ~93 dirt
setblock ~182 ~119 ~94 dirt
setblock ~182 ~119 ~95 dirt
setblock ~182 ~119 ~96 dirt
setblock ~182 ~119 ~97 dirt
setblock ~182 ~119 ~98 dirt
setblock ~182 ~119 ~99 dirt
setblock ~182 ~119 ~100 dirt
setblock ~182 ~119 ~101 dirt
setblock ~182 ~119 ~102 dirt
setblock ~182 ~119 ~103 dirt
setblock ~182 ~119 ~104 dirt
setblock ~182 ~119 ~105 dirt
setblock ~182 ~119 ~106 dirt
setblock ~182 ~119 ~107 dirt
setblock ~182 ~119 ~108 dirt
setblock ~182 ~119 ~109 dirt
setblock ~182 ~119 ~110 dirt
setblock ~182 ~119 ~111 dirt
setblock ~182 ~119 ~112 dirt
setblock ~182 ~119 ~117 dirt
setblock ~182 ~119 ~118 dirt
setblock ~182 ~119 ~119 dirt
setblock ~182 ~119 ~120 dirt
setblock ~182 ~119 ~121 dirt
setblock ~182 ~119 ~122 dirt
setblock ~182 ~119 ~123 dirt
setblock ~182 ~119 ~124 dirt
setblock ~182 ~120 ~84 dirt
setblock ~182 ~120 ~85 dirt
setblock ~182 ~120 ~86 dirt
setblock ~182 ~120 ~87 dirt
setblock ~182 ~120 ~88 dirt
setblock ~182 ~120 ~89 dirt
setblock ~182 ~120 ~90 dirt
setblock ~182 ~120 ~91 dirt
setblock ~182 ~120 ~92 dirt
setblock ~182 ~120 ~93 dirt
setblock ~182 ~120 ~94 dirt
setblock ~182 ~120 ~95 dirt
setblock ~182 ~120 ~96 dirt
setblock ~182 ~120 ~97 dirt
setblock ~182 ~120 ~98 dirt
setblock ~182 ~120 ~99 dirt
setblock ~182 ~120 ~100 dirt
setblock ~182 ~120 ~101 dirt
setblock ~182 ~120 ~102 dirt
setblock ~182 ~120 ~103 dirt
setblock ~182 ~120 ~104 dirt
setblock ~182 ~120 ~105 dirt
setblock ~182 ~120 ~106 dirt
setblock ~182 ~120 ~107 dirt
setblock ~182 ~120 ~108 dirt
setblock ~182 ~120 ~109 dirt
setblock ~182 ~120 ~110 dirt
setblock ~182 ~120 ~111 dirt
setblock ~182 ~120 ~112 dirt
setblock ~182 ~120 ~113 dirt
setblock ~182 ~120 ~116 dirt
setblock ~182 ~120 ~117 dirt
setblock ~182 ~120 ~118 dirt
setblock ~182 ~120 ~119 dirt
setblock ~182 ~120 ~120 dirt
setblock ~182 ~120 ~121 dirt
setblock ~182 ~120 ~122 dirt
setblock ~182 ~120 ~123 dirt
setblock ~182 ~120 ~124 dirt
setblock ~182 ~120 ~125 dirt
setblock ~182 ~121 ~60 dirt
setblock ~182 ~121 ~63 dirt
setblock ~182 ~121 ~83 dirt
setblock ~182 ~121 ~84 dirt
setblock ~182 ~121 ~85 dirt
setblock ~182 ~121 ~86 dirt
setblock ~182 ~121 ~87 dirt
setblock ~182 ~121 ~88 dirt
setblock ~182 ~121 ~89 dirt
setblock ~182 ~121 ~90 dirt
setblock ~182 ~121 ~91 dirt
setblock ~182 ~121 ~92 dirt
setblock ~182 ~121 ~93 dirt
setblock ~182 ~121 ~94 dirt
setblock ~182 ~121 ~95 dirt
setblock ~182 ~121 ~96 dirt
setblock ~182 ~121 ~97 dirt
setblock ~182 ~121 ~98 dirt
setblock ~182 ~121 ~99 dirt
setblock ~182 ~121 ~100 dirt
setblock ~182 ~121 ~101 dirt
setblock ~182 ~121 ~102 dirt
setblock ~182 ~121 ~103 dirt
setblock ~182 ~121 ~104 dirt
setblock ~182 ~121 ~105 dirt
setblock ~182 ~121 ~106 dirt
setblock ~182 ~121 ~107 dirt
setblock ~182 ~121 ~108 dirt
setblock ~182 ~121 ~109 dirt
setblock ~182 ~121 ~110 dirt
setblock ~182 ~121 ~111 dirt
setblock ~182 ~121 ~112 dirt
setblock ~182 ~121 ~113 dirt
setblock ~182 ~121 ~114 dirt
setblock ~182 ~121 ~115 dirt
setblock ~182 ~121 ~116 dirt
setblock ~182 ~121 ~117 dirt
setblock ~182 ~121 ~118 dirt
setblock ~182 ~121 ~119 dirt
setblock ~182 ~121 ~120 dirt
setblock ~182 ~121 ~121 dirt
setblock ~182 ~121 ~122 dirt
setblock ~182 ~121 ~123 dirt
setblock ~182 ~121 ~124 dirt
setblock ~182 ~121 ~125 dirt
setblock ~182 ~121 ~126 dirt
setblock ~182 ~121 ~127 dirt
setblock ~182 ~122 ~60 dirt
setblock ~182 ~122 ~63 dirt
setblock ~182 ~122 ~83 dirt
setblock ~182 ~122 ~84 dirt
setblock ~182 ~122 ~85 dirt
setblock ~182 ~122 ~86 dirt
setblock ~182 ~122 ~87 dirt
setblock ~182 ~122 ~88 dirt
setblock ~182 ~122 ~89 dirt
setblock ~182 ~122 ~90 dirt
setblock ~182 ~122 ~91 dirt
setblock ~182 ~122 ~92 dirt
setblock ~182 ~122 ~93 dirt
setblock ~182 ~122 ~94 dirt
setblock ~182 ~122 ~95 dirt
setblock ~182 ~122 ~96 dirt
setblock ~182 ~122 ~97 dirt
setblock ~182 ~122 ~98 dirt
setblock ~182 ~122 ~99 dirt
setblock ~182 ~122 ~100 dirt
setblock ~182 ~122 ~101 dirt
setblock ~182 ~122 ~102 dirt
setblock ~182 ~122 ~103 dirt
setblock ~182 ~122 ~104 dirt
setblock ~182 ~122 ~105 dirt
setblock ~182 ~122 ~106 dirt
setblock ~182 ~122 ~107 dirt
setblock ~182 ~122 ~108 dirt
setblock ~182 ~122 ~109 dirt
setblock ~182 ~122 ~110 dirt
setblock ~182 ~122 ~111 dirt
setblock ~182 ~122 ~112 dirt
setblock ~182 ~122 ~113 dirt
setblock ~182 ~122 ~114 dirt
setblock ~182 ~122 ~115 dirt
setblock ~182 ~122 ~116 dirt
setblock ~182 ~122 ~117 dirt
setblock ~182 ~122 ~118 dirt
setblock ~182 ~122 ~119 dirt
setblock ~182 ~122 ~120 dirt
setblock ~182 ~122 ~121 dirt
setblock ~182 ~122 ~122 dirt
setblock ~182 ~122 ~123 dirt
setblock ~182 ~122 ~124 dirt
setblock ~182 ~122 ~125 dirt
setblock ~182 ~122 ~126 dirt
setblock ~182 ~122 ~127 dirt
setblock ~182 ~123 ~60 dirt
setblock ~182 ~123 ~63 dirt
setblock ~182 ~123 ~83 grass_block
setblock ~182 ~123 ~84 grass_block
setblock ~182 ~123 ~85 grass_block
setblock ~182 ~123 ~86 grass_block
setblock ~182 ~123 ~87 grass_block
setblock ~182 ~123 ~88 grass_block
setblock ~182 ~123 ~89 grass_block
setblock ~182 ~123 ~90 grass_block
setblock ~182 ~123 ~91 dirt
setblock ~182 ~123 ~92 dirt
setblock ~182 ~123 ~93 dirt
setblock ~182 ~123 ~94 dirt
setblock ~182 ~123 ~95 dirt
setblock ~182 ~123 ~96 dirt
setblock ~182 ~123 ~97 dirt
setblock ~182 ~123 ~98 dirt
setblock ~182 ~123 ~99 dirt
setblock ~182 ~123 ~100 dirt
setblock ~182 ~123 ~101 dirt
setblock ~182 ~123 ~102 dirt
setblock ~182 ~123 ~103 dirt
setblock ~182 ~123 ~104 dirt
setblock ~182 ~123 ~105 dirt
setblock ~182 ~123 ~106 dirt
setblock ~182 ~123 ~107 dirt
setblock ~182 ~123 ~108 dirt
setblock ~182 ~123 ~109 dirt
setblock ~182 ~123 ~110 dirt
setblock ~182 ~123 ~111 dirt
setblock ~182 ~123 ~112 dirt
setblock ~182 ~123 ~113 dirt
setblock ~182 ~123 ~114 dirt
setblock ~182 ~123 ~115 dirt
setblock ~182 ~123 ~116 dirt
setblock ~182 ~123 ~117 dirt
setblock ~182 ~123 ~118 dirt
setblock ~182 ~123 ~119 dirt
setblock ~182 ~123 ~120 dirt
setblock ~182 ~123 ~121 dirt
setblock ~182 ~123 ~122 dirt
setblock ~182 ~123 ~123 dirt
setblock ~182 ~123 ~124 dirt
setblock ~182 ~123 ~125 dirt
setblock ~182 ~123 ~126 dirt
setblock ~182 ~123 ~127 dirt
setblock ~182 ~124 ~60 dirt
setblock ~182 ~124 ~63 dirt
setblock ~182 ~124 ~87 short_grass
setblock ~182 ~124 ~91 grass_block
setblock ~182 ~124 ~92 grass_block
setblock ~182 ~124 ~93 grass_block
setblock ~182 ~124 ~94 dirt
setblock ~182 ~124 ~95 dirt
setblock ~182 ~124 ~96 dirt
setblock ~182 ~124 ~97 dirt
setblock ~182 ~124 ~98 dirt
setblock ~182 ~124 ~99 dirt
setblock ~182 ~124 ~100 dirt
setblock ~182 ~124 ~101 dirt
setblock ~182 ~124 ~102 dirt
setblock ~182 ~124 ~103 dirt
setblock ~182 ~124 ~104 dirt
setblock ~182 ~124 ~105 dirt
setblock ~182 ~124 ~106 dirt
setblock ~182 ~124 ~107 dirt
setblock ~182 ~124 ~108 grass_block
setblock ~182 ~124 ~109 grass_block
setblock ~182 ~124 ~110 grass_block
setblock ~182 ~124 ~111 grass_block
setblock ~182 ~124 ~112 grass_block
setblock ~182 ~124 ~113 dirt
setblock ~182 ~124 ~114 dirt
setblock ~182 ~124 ~115 dirt
setblock ~182 ~124 ~116 dirt
setblock ~182 ~124 ~117 dirt
setblock ~182 ~124 ~118 dirt
setblock ~182 ~124 ~119 dirt
setblock ~182 ~124 ~120 dirt
setblock ~182 ~124 ~121 dirt
setblock ~182 ~124 ~122 dirt
setblock ~182 ~124 ~123 dirt
setblock ~182 ~124 ~124 dirt
setblock ~182 ~124 ~125 dirt
setblock ~182 ~124 ~126 dirt
setblock ~182 ~124 ~127 dirt
setblock ~182 ~125 ~60 dirt
setblock ~182 ~125 ~63 dirt
setblock ~182 ~125 ~92 short_grass
setblock ~182 ~125 ~94 grass_block
setblock ~182 ~125 ~95 grass_block
setblock ~182 ~125 ~96 grass_block
setblock ~182 ~125 ~97 grass_block
setblock ~182 ~125 ~98 dirt
setblock ~182 ~125 ~99 dirt
setblock ~182 ~125 ~100 dirt
setblock ~182 ~125 ~101 dirt
setblock ~182 ~125 ~102 dirt
setblock ~182 ~125 ~103 grass_block
setblock ~182 ~125 ~104 grass_block
setblock ~182 ~125 ~105 grass_block
setblock ~182 ~125 ~106 grass_block
setblock ~182 ~125 ~107 grass_block
setblock ~182 ~125 ~108 short_grass
setblock ~182 ~125 ~110 fern
setblock ~182 ~125 ~112 short_grass
setblock ~182 ~125 ~113 grass_block
setblock ~182 ~125 ~114 grass_block
setblock ~182 ~125 ~115 grass_block
setblock ~182 ~125 ~116 dirt
setblock ~182 ~125 ~117 dirt
setblock ~182 ~125 ~118 dirt
setblock ~182 ~125 ~119 dirt
setblock ~182 ~125 ~120 dirt
setblock ~182 ~125 ~121 dirt
setblock ~182 ~125 ~122 dirt
setblock ~182 ~125 ~123 dirt
setblock ~182 ~125 ~124 grass_block
setblock ~182 ~125 ~125 grass_block
setblock ~182 ~125 ~126 grass_block
setblock ~182 ~125 ~127 grass_block
setblock ~182 ~126 ~60 dirt
setblock ~182 ~126 ~63 dirt
setblock ~182 ~126 ~96 poppy
setblock ~182 ~126 ~98 grass_block
setblock ~182 ~126 ~99 grass_block
setblock ~182 ~126 ~100 grass_block
setblock ~182 ~126 ~101 grass_block
setblock ~182 ~126 ~102 grass_block
setblock ~182 ~126 ~105 short_grass
setblock ~182 ~126 ~107 poppy
setblock ~182 ~126 ~114 short_grass
setblock ~182 ~126 ~115 short_grass
setblock ~182 ~126 ~116 grass_block
setblock ~182 ~126 ~117 grass_block
setblock ~182 ~126 ~118 grass_block
setblock ~182 ~126 ~119 grass_block
setblock ~182 ~126 ~120 dirt
setblock ~182 ~126 ~121 grass_block
setblock ~182 ~126 ~122 grass_block
setblock ~182 ~126 ~123 grass_block
setblock ~182 ~126 ~125 short_grass
setblock ~182 ~126 ~127 short_grass
setblock ~182 ~127 ~60 dirt
setblock ~182 ~127 ~63 grass_block
setblock ~182 ~127 ~98 short_grass
setblock ~182 ~127 ~99 short_grass
setblock ~182 ~127 ~100 short_grass
setblock ~182 ~127 ~102 short_grass
setblock ~182 ~127 ~120 grass_block
setblock ~182 ~127 ~122 short_grass
setblock ~182 ~127 ~123 short_grass
setblock ~182 ~128 ~60 dirt
setblock ~182 ~129 ~60 grass_block
setblock ~183 ~108 ~95 dirt
setblock ~183 ~108 ~96 dirt
setblock ~183 ~108 ~97 dirt
setblock ~183 ~109 ~94 dirt
setblock ~183 ~109 ~95 dirt
setblock ~183 ~109 ~96 dirt
setblock ~183 ~109 ~97 dirt
setblock ~183 ~109 ~98 dirt
setblock ~183 ~109 ~99 dirt
setblock ~183 ~110 ~93 dirt
setblock ~183 ~110 ~94 dirt
setblock ~183 ~110 ~95 dirt
setblock ~183 ~110 ~96 dirt
setblock ~183 ~110 ~97 dirt
setblock ~183 ~110 ~98 dirt
setblock ~183 ~110 ~99 dirt
setblock ~183 ~110 ~100 dirt
setblock ~183 ~111 ~92 dirt
setblock ~183 ~111 ~93 dirt
setblock ~183 ~111 ~94 dirt
setblock ~183 ~111 ~95 dirt
setblock ~183 ~111 ~96 dirt
setblock ~183 ~111 ~97 dirt
setblock ~183 ~111 ~98 dirt
setblock ~183 ~111 ~99 dirt
setblock ~183 ~111 ~100 dirt
setblock ~183 ~112 ~91 dirt
setblock ~183 ~112 ~92 dirt
setblock ~183 ~112 ~93 dirt
setblock ~183 ~112 ~94 dirt
setblock ~183 ~112 ~95 dirt
setblock ~183 ~112 ~96 dirt
setblock ~183 ~112 ~97 dirt
setblock ~183 ~112 ~98 dirt
setblock ~183 ~112 ~99 dirt
setblock ~183 ~112 ~100 dirt
setblock ~183 ~112 ~101 dirt
setblock ~183 ~113 ~90 dirt
setblock ~183 ~113 ~91 dirt
setblock ~183 ~113 ~92 dirt
setblock ~183 ~113 ~93 dirt
setblock ~183 ~113 ~94 dirt
setblock ~183 ~113 ~95 dirt
setblock ~183 ~113 ~96 dirt
setblock ~183 ~113 ~97 dirt
setblock ~183 ~113 ~98 dirt
setblock ~183 ~113 ~99 dirt
setblock ~183 ~113 ~100 dirt
setblock ~183 ~113 ~101 dirt
setblock ~183 ~113 ~102 dirt
setblock ~183 ~114 ~89 dirt
setblock ~183 ~114 ~90 dirt
setblock ~183 ~114 ~91 dirt
setblock ~183 ~114 ~92 dirt
setblock ~183 ~114 ~93 dirt
setblock ~183 ~114 ~94 dirt
setblock ~183 ~114 ~95 dirt
setblock ~183 ~114 ~96 dirt
setblock ~183 ~114 ~97 dirt
setblock ~183 ~114 ~98 dirt
setblock ~183 ~114 ~99 dirt
setblock ~183 ~114 ~100 dirt
setblock ~183 ~114 ~101 dirt
setblock ~183 ~114 ~102 dirt
setblock ~183 ~114 ~103 dirt
setblock ~183 ~114 ~106 dirt
setblock ~183 ~115 ~88 dirt
setblock ~183 ~115 ~89 dirt
setblock ~183 ~115 ~90 dirt
setblock ~183 ~115 ~91 dirt
setblock ~183 ~115 ~92 dirt
setblock ~183 ~115 ~93 dirt
setblock ~183 ~115 ~94 dirt
setblock ~183 ~115 ~95 dirt
setblock ~183 ~115 ~96 dirt
setblock ~183 ~115 ~97 dirt
setblock ~183 ~115 ~98 dirt
setblock ~183 ~115 ~99 dirt
setblock ~183 ~115 ~100 dirt
setblock ~183 ~115 ~101 dirt
setblock ~183 ~115 ~102 dirt
setblock ~183 ~115 ~103 dirt
setblock ~183 ~115 ~104 dirt
setblock ~183 ~115 ~105 dirt
setblock ~183 ~115 ~106 dirt
setblock ~183 ~115 ~107 dirt
setblock ~183 ~116 ~87 dirt
setblock ~183 ~116 ~88 dirt
setblock ~183 ~116 ~89 dirt
setblock ~183 ~116 ~90 dirt
setblock ~183 ~116 ~91 dirt
setblock ~183 ~116 ~92 dirt
setblock ~183 ~116 ~93 dirt
setblock ~183 ~116 ~94 dirt
setblock ~183 ~116 ~95 dirt
setblock ~183 ~116 ~96 dirt
setblock ~183 ~116 ~97 dirt
setblock ~183 ~116 ~98 dirt
setblock ~183 ~116 ~99 dirt
setblock ~183 ~116 ~100 dirt
setblock ~183 ~116 ~101 dirt
setblock ~183 ~116 ~102 dirt
setblock ~183 ~116 ~103 dirt
setblock ~183 ~116 ~104 dirt
setblock ~183 ~116 ~105 dirt
setblock ~183 ~116 ~106 dirt
setblock ~183 ~116 ~107 dirt
setblock ~183 ~116 ~108 dirt
setblock ~183 ~117 ~86 dirt
setblock ~183 ~117 ~87 dirt
setblock ~183 ~117 ~88 dirt
setblock ~183 ~117 ~89 dirt
setblock ~183 ~117 ~90 dirt
setblock ~183 ~117 ~91 dirt
setblock ~183 ~117 ~92 dirt
setblock ~183 ~117 ~93 dirt
setblock ~183 ~117 ~94 dirt
setblock ~183 ~117 ~95 dirt
setblock ~183 ~117 ~96 dirt
setblock ~183 ~117 ~97 dirt
setblock ~183 ~117 ~98 dirt
setblock ~183 ~117 ~99 dirt
setblock ~183 ~117 ~100 dirt
setblock ~183 ~117 ~101 dirt
setblock ~183 ~117 ~102 dirt
setblock ~183 ~117 ~103 dirt
setblock ~183 ~117 ~104 dirt
setblock ~183 ~117 ~105 dirt
setblock ~183 ~117 ~106 dirt
setblock ~183 ~117 ~107 dirt
setblock ~183 ~117 ~108 dirt
setblock ~183 ~117 ~109 dirt
setblock ~183 ~118 ~86 dirt
setblock ~183 ~118 ~87 dirt
setblock ~183 ~118 ~88 dirt
setblock ~183 ~118 ~89 dirt
setblock ~183 ~118 ~90 dirt
setblock ~183 ~118 ~91 dirt
setblock ~183 ~118 ~92 dirt
setblock ~183 ~118 ~93 dirt
setblock ~183 ~118 ~94 dirt
setblock ~183 ~118 ~95 dirt
setblock ~183 ~118 ~96 dirt
setblock ~183 ~118 ~97 dirt
setblock ~183 ~118 ~98 dirt
setblock ~183 ~118 ~99 dirt
setblock ~183 ~118 ~100 dirt
setblock ~183 ~118 ~101 dirt
setblock ~183 ~118 ~102 dirt
setblock ~183 ~118 ~103 dirt
setblock ~183 ~118 ~104 dirt
setblock ~183 ~118 ~105 dirt
setblock ~183 ~118 ~106 dirt
setblock ~183 ~118 ~107 dirt
setblock ~183 ~118 ~108 dirt
setblock ~183 ~118 ~109 dirt
setblock ~183 ~118 ~110 dirt
setblock ~183 ~118 ~121 dirt
setblock ~183 ~119 ~85 dirt
setblock ~183 ~119 ~86 dirt
setblock ~183 ~119 ~87 dirt
setblock ~183 ~119 ~88 dirt
setblock ~183 ~119 ~89 dirt
setblock ~183 ~119 ~90 dirt
setblock ~183 ~119 ~91 dirt
setblock ~183 ~119 ~92 dirt
setblock ~183 ~119 ~93 dirt
setblock ~183 ~119 ~94 dirt
setblock ~183 ~119 ~95 dirt
setblock ~183 ~119 ~96 dirt
setblock ~183 ~119 ~97 dirt
setblock ~183 ~119 ~98 dirt
setblock ~183 ~119 ~99 dirt
setblock ~183 ~119 ~100 dirt
setblock ~183 ~119 ~101 dirt
setblock ~183 ~119 ~102 dirt
setblock ~183 ~119 ~103 dirt
setblock ~183 ~119 ~104 dirt
setblock ~183 ~119 ~105 dirt
setblock ~183 ~119 ~106 dirt
setblock ~183 ~119 ~107 dirt
setblock ~183 ~119 ~108 dirt
setblock ~183 ~119 ~109 dirt
setblock ~183 ~119 ~110 dirt
setblock ~183 ~119 ~111 dirt
setblock ~183 ~119 ~118 dirt
setblock ~183 ~119 ~119 dirt
setblock ~183 ~119 ~120 dirt
setblock ~183 ~119 ~121 dirt
setblock ~183 ~119 ~122 dirt
setblock ~183 ~119 ~123 dirt
setblock ~183 ~120 ~85 dirt
setblock ~183 ~120 ~86 dirt
setblock ~183 ~120 ~87 dirt
setblock ~183 ~120 ~88 dirt
setblock ~183 ~120 ~89 dirt
setblock ~183 ~120 ~90 dirt
setblock ~183 ~120 ~91 dirt
setblock ~183 ~120 ~92 dirt
setblock ~183 ~120 ~93 dirt
setblock ~183 ~120 ~94 dirt
setblock ~183 ~120 ~95 dirt
setblock ~183 ~120 ~96 dirt
setblock ~183 ~120 ~97 dirt
setblock ~183 ~120 ~98 dirt
setblock ~183 ~120 ~99 dirt
setblock ~183 ~120 ~100 dirt
setblock ~183 ~120 ~101 dirt
setblock ~183 ~120 ~102 dirt
setblock ~183 ~120 ~103 dirt
setblock ~183 ~120 ~104 dirt
setblock ~183 ~120 ~105 dirt
setblock ~183 ~120 ~106 dirt
setblock ~183 ~120 ~107 dirt
setblock ~183 ~120 ~108 dirt
setblock ~183 ~120 ~109 dirt
setblock ~183 ~120 ~110 dirt
setblock ~183 ~120 ~111 dirt
setblock ~183 ~120 ~112 dirt
setblock ~183 ~120 ~117 dirt
setblock ~183 ~120 ~118 dirt
setblock ~183 ~120 ~119 dirt
setblock ~183 ~120 ~120 dirt
setblock ~183 ~120 ~121 dirt
setblock ~183 ~120 ~122 dirt
setblock ~183 ~120 ~123 dirt
setblock ~183 ~120 ~124 dirt
setblock ~183 ~121 ~72 dirt
setblock ~183 ~121 ~84 dirt
setblock ~183 ~121 ~85 dirt
setblock ~183 ~121 ~86 dirt
setblock ~183 ~121 ~87 dirt
setblock ~183 ~121 ~88 dirt
setblock ~183 ~121 ~89 dirt
setblock ~183 ~121 ~90 dirt
setblock ~183 ~121 ~91 dirt
setblock ~183 ~121 ~92 dirt
setblock ~183 ~121 ~93 dirt
setblock ~183 ~121 ~94 dirt
setblock ~183 ~121 ~95 dirt
setblock ~183 ~121 ~96 dirt
setblock ~183 ~121 ~97 dirt
setblock ~183 ~121 ~98 dirt
setblock ~183 ~121 ~99 dirt
setblock ~183 ~121 ~100 dirt
setblock ~183 ~121 ~101 dirt
setblock ~183 ~121 ~102 dirt
setblock ~183 ~121 ~103 dirt
setblock ~183 ~121 ~104 dirt
setblock ~183 ~121 ~105 dirt
setblock ~183 ~121 ~106 dirt
setblock ~183 ~121 ~107 dirt
setblock ~183 ~121 ~108 dirt
setblock ~183 ~121 ~109 dirt
setblock ~183 ~121 ~110 dirt
setblock ~183 ~121 ~111 dirt
setblock ~183 ~121 ~112 dirt
setblock ~183 ~121 ~113 dirt
setblock ~183 ~121 ~116 dirt
setblock ~183 ~121 ~117 dirt
setblock ~183 ~121 ~118 dirt
setblock ~183 ~121 ~119 dirt
setblock ~183 ~121 ~120 dirt
setblock ~183 ~121 ~121 dirt
setblock ~183 ~121 ~122 dirt
setblock ~183 ~121 ~123 dirt
setblock ~183 ~121 ~124 dirt
setblock ~183 ~121 ~125 dirt
setblock ~183 ~121 ~130 dirt
setblock ~183 ~122 ~72 dirt
setblock ~183 ~122 ~84 dirt
setblock ~183 ~122 ~85 dirt
setblock ~183 ~122 ~86 dirt
setblock ~183 ~122 ~87 dirt
setblock ~183 ~122 ~88 dirt
setblock ~183 ~122 ~89 dirt
setblock ~183 ~122 ~90 dirt
setblock ~183 ~122 ~91 dirt
setblock ~183 ~122 ~92 dirt
setblock ~183 ~122 ~93 dirt
setblock ~183 ~122 ~94 dirt
setblock ~183 ~122 ~95 dirt
setblock ~183 ~122 ~96 dirt
setblock ~183 ~122 ~97 dirt
setblock ~183 ~122 ~98 dirt
setblock ~183 ~122 ~99 dirt
setblock ~183 ~122 ~100 dirt
setblock ~183 ~122 ~101 dirt
setblock ~183 ~122 ~102 dirt
setblock ~183 ~122 ~103 dirt
setblock ~183 ~122 ~104 dirt
setblock ~183 ~122 ~105 dirt
setblock ~183 ~122 ~106 dirt
setblock ~183 ~122 ~107 dirt
setblock ~183 ~122 ~108 dirt
setblock ~183 ~122 ~109 dirt
setblock ~183 ~122 ~110 dirt
setblock ~183 ~122 ~111 dirt
setblock ~183 ~122 ~112 dirt
setblock ~183 ~122 ~113 dirt
setblock ~183 ~122 ~116 dirt
setblock ~183 ~122 ~117 dirt
setblock ~183 ~122 ~118 dirt
setblock ~183 ~122 ~119 dirt
setblock ~183 ~122 ~120 dirt
setblock ~183 ~122 ~121 dirt
setblock ~183 ~122 ~122 dirt
setblock ~183 ~122 ~123 dirt
setblock ~183 ~122 ~124 dirt
setblock ~183 ~122 ~125 dirt
setblock ~183 ~122 ~130 dirt
setblock ~183 ~123 ~72 dirt
setblock ~183 ~123 ~84 dirt
setblock ~183 ~123 ~85 dirt
setblock ~183 ~123 ~86 dirt
setblock ~183 ~123 ~87 dirt
setblock ~183 ~123 ~88 dirt
setblock ~183 ~123 ~89 dirt
setblock ~183 ~123 ~90 dirt
setblock ~183 ~123 ~91 dirt
setblock ~183 ~123 ~92 dirt
setblock ~183 ~123 ~93 dirt
setblock ~183 ~123 ~94 dirt
setblock ~183 ~123 ~95 dirt
setblock ~183 ~123 ~96 dirt
setblock ~183 ~123 ~97 dirt
setblock ~183 ~123 ~98 dirt
setblock ~183 ~123 ~99 dirt
setblock ~183 ~123 ~100 dirt
setblock ~183 ~123 ~101 dirt
setblock ~183 ~123 ~102 dirt
setblock ~183 ~123 ~103 dirt
setblock ~183 ~123 ~104 dirt
setblock ~183 ~123 ~105 dirt
setblock ~183 ~123 ~106 dirt
setblock ~183 ~123 ~107 dirt
setblock ~183 ~123 ~108 dirt
setblock ~183 ~123 ~109 dirt
setblock ~183 ~123 ~110 grass_block
setblock ~183 ~123 ~111 dirt
setblock ~183 ~123 ~112 dirt
setblock ~183 ~123 ~113 dirt
setblock ~183 ~123 ~116 dirt
setblock ~183 ~123 ~117 dirt
setblock ~183 ~123 ~118 dirt
setblock ~183 ~123 ~119 dirt
setblock ~183 ~123 ~120 dirt
setblock ~183 ~123 ~121 dirt
setblock ~183 ~123 ~122 dirt
setblock ~183 ~123 ~123 dirt
setblock ~183 ~123 ~124 dirt
setblock ~183 ~123 ~125 dirt
setblock ~183 ~123 ~130 dirt
setblock ~183 ~124 ~72 grass_block
setblock ~183 ~124 ~84 grass_block
setblock ~183 ~124 ~85 grass_block
setblock ~183 ~124 ~86 grass_block
setblock ~183 ~124 ~87 grass_block
setblock ~183 ~124 ~88 grass_block
setblock ~183 ~124 ~89 grass_block
setblock ~183 ~124 ~90 grass_block
setblock ~183 ~124 ~91 grass_block
setblock ~183 ~124 ~92 grass_block
setblock ~183 ~124 ~93 dirt
setblock ~183 ~124 ~94 dirt
setblock ~183 ~124 ~95 dirt
setblock ~183 ~124 ~96 dirt
setblock ~183 ~124 ~97 dirt
setblock ~183 ~124 ~98 dirt
setblock ~183 ~124 ~99 dirt
setblock ~183 ~124 ~100 dirt
setblock ~183 ~124 ~101 dirt
setblock ~183 ~124 ~102 dirt
setblock ~183 ~124 ~103 dirt
setblock ~183 ~124 ~104 dirt
setblock ~183 ~124 ~105 dirt
setblock ~183 ~124 ~106 dirt
setblock ~183 ~124 ~107 grass_block
setblock ~183 ~124 ~108 grass_block
setblock ~183 ~124 ~109 grass_block
setblock ~183 ~124 ~110 fern
setblock ~183 ~124 ~111 grass_block
setblock ~183 ~124 ~112 grass_block
setblock ~183 ~124 ~113 grass_block
setblock ~183 ~124 ~116 dirt
setblock ~183 ~124 ~117 dirt
setblock ~183 ~124 ~118 dirt
setblock ~183 ~124 ~119 dirt
setblock ~183 ~124 ~120 dirt
setblock ~183 ~124 ~121 dirt
setblock ~183 ~124 ~122 dirt
setblock ~183 ~124 ~123 dirt
setblock ~183 ~124 ~124 dirt
setblock ~183 ~124 ~125 dirt
setblock ~183 ~124 ~130 grass_block
setblock ~183 ~125 ~89 short_grass
setblock ~183 ~125 ~92 short_grass
setblock ~183 ~125 ~93 grass_block
setblock ~183 ~125 ~94 grass_block
setblock ~183 ~125 ~95 grass_block
setblock ~183 ~125 ~96 grass_block
setblock ~183 ~125 ~97 grass_block
setblock ~183 ~125 ~98 grass_block
setblock ~183 ~125 ~99 dirt
setblock ~183 ~125 ~100 dirt
setblock ~183 ~125 ~101 dirt
setblock ~183 ~125 ~102 grass_block
setblock ~183 ~125 ~103 grass_block
setblock ~183 ~125 ~104 grass_block
setblock ~183 ~125 ~105 grass_block
setblock ~183 ~125 ~106 grass_block
setblock ~183 ~125 ~108 short_grass
setblock ~183 ~125 ~112 short_grass
setblock ~183 ~125 ~116 grass_block
setblock ~183 ~125 ~117 grass_block
setblock ~183 ~125 ~118 dirt
setblock ~183 ~125 ~119 dirt
setblock ~183 ~125 ~120 dirt
setblock ~183 ~125 ~121 dirt
setblock ~183 ~125 ~122 dirt
setblock ~183 ~125 ~123 grass_block
setblock ~183 ~125 ~124 grass_block
setblock ~183 ~125 ~125 grass_block
setblock ~183 ~125 ~130 short_grass
setblock ~183 ~126 ~95 short_grass
setblock ~183 ~126 ~99 grass_block
setblock ~183 ~126 ~100 grass_block
setblock ~183 ~126 ~101 grass_block
setblock ~183 ~126 ~102 short_grass
setblock ~183 ~126 ~103 short_grass
setblock ~183 ~126 ~106 short_grass
setblock ~183 ~126 ~118 grass_block
setblock ~183 ~126 ~119 grass_block
setblock ~183 ~126 ~120 grass_block
setblock ~183 ~126 ~121 grass_block
setblock ~183 ~126 ~122 grass_block
setblock ~183 ~126 ~123 short_grass
setblock ~183 ~127 ~100 short_grass
setblock ~183 ~127 ~101 short_grass
setblock ~183 ~127 ~122 short_grass
setblock ~184 ~109 ~96 dirt
setblock ~184 ~109 ~97 dirt
setblock ~184 ~110 ~95 dirt
setblock ~184 ~110 ~96 dirt
setblock ~184 ~110 ~97 dirt
setblock ~184 ~110 ~98 dirt
setblock ~184 ~110 ~99 dirt
setblock ~184 ~111 ~94 dirt
setblock ~184 ~111 ~95 dirt
setblock ~184 ~111 ~96 dirt
setblock ~184 ~111 ~97 dirt
setblock ~184 ~111 ~98 dirt
setblock ~184 ~111 ~99 dirt
setblock ~184 ~112 ~92 dirt
setblock ~184 ~112 ~93 dirt
setblock ~184 ~112 ~94 dirt
setblock ~184 ~112 ~95 dirt
setblock ~184 ~112 ~96 dirt
setblock ~184 ~112 ~97 dirt
setblock ~184 ~112 ~98 dirt
setblock ~184 ~112 ~99 dirt
setblock ~184 ~112 ~100 dirt
setblock ~184 ~113 ~91 dirt
setblock ~184 ~113 ~92 dirt
setblock ~184 ~113 ~93 dirt
setblock ~184 ~113 ~94 dirt
setblock ~184 ~113 ~95 dirt
setblock ~184 ~113 ~96 dirt
setblock ~184 ~113 ~97 dirt
setblock ~184 ~113 ~98 dirt
setblock ~184 ~113 ~99 dirt
setblock ~184 ~113 ~100 dirt
setblock ~184 ~113 ~101 dirt
setblock ~184 ~114 ~90 dirt
setblock ~184 ~114 ~91 dirt
setblock ~184 ~114 ~92 dirt
setblock ~184 ~114 ~93 dirt
setblock ~184 ~114 ~94 dirt
setblock ~184 ~114 ~95 dirt
setblock ~184 ~114 ~96 dirt
setblock ~184 ~114 ~97 dirt
setblock ~184 ~114 ~98 dirt
setblock ~184 ~114 ~99 dirt
setblock ~184 ~114 ~100 dirt
setblock ~184 ~114 ~101 dirt
setblock ~184 ~114 ~102 dirt
setblock ~184 ~115 ~89 dirt
setblock ~184 ~115 ~90 dirt
setblock ~184 ~115 ~91 dirt
setblock ~184 ~115 ~92 dirt
setblock ~184 ~115 ~93 dirt
setblock ~184 ~115 ~94 dirt
setblock ~184 ~115 ~95 dirt
setblock ~184 ~115 ~96 dirt
setblock ~184 ~115 ~97 dirt
setblock ~184 ~115 ~98 dirt
setblock ~184 ~115 ~99 dirt
setblock ~184 ~115 ~100 dirt
setblock ~184 ~115 ~101 dirt
setblock ~184 ~115 ~102 dirt
setblock ~184 ~115 ~103 dirt
setblock ~184 ~116 ~88 dirt
setblock ~184 ~116 ~89 dirt
setblock ~184 ~116 ~90 dirt
setblock ~184 ~116 ~91 dirt
setblock ~184 ~116 ~92 dirt
setblock ~184 ~116 ~93 dirt
setblock ~184 ~116 ~94 dirt
setblock ~184 ~116 ~95 dirt
setblock ~184 ~116 ~96 dirt
setblock ~184 ~116 ~97 dirt
setblock ~184 ~116 ~98 dirt
setblock ~184 ~116 ~99 dirt
setblock ~184 ~116 ~100 dirt
setblock ~184 ~116 ~101 dirt
setblock ~184 ~116 ~102 dirt
setblock ~184 ~116 ~103 dirt
setblock ~184 ~116 ~104 dirt
setblock ~184 ~116 ~105 dirt
setblock ~184 ~116 ~106 dirt
setblock ~184 ~117 ~87 dirt
setblock ~184 ~117 ~88 dirt
setblock ~184 ~117 ~89 dirt
setblock ~184 ~117 ~90 dirt
setblock ~184 ~117 ~91 dirt
setblock ~184 ~117 ~92 dirt
setblock ~184 ~117 ~93 dirt
setblock ~184 ~117 ~94 dirt
setblock ~184 ~117 ~95 dirt
setblock ~184 ~117 ~96 dirt
setblock ~184 ~117 ~97 dirt
setblock ~184 ~117 ~98 dirt
setblock ~184 ~117 ~99 dirt
setblock ~184 ~117 ~100 dirt
setblock ~184 ~117 ~101 dirt
setblock ~184 ~117 ~102 dirt
setblock ~184 ~117 ~103 dirt
setblock ~184 ~117 ~104 dirt
setblock ~184 ~117 ~105 dirt
setblock ~184 ~117 ~106 dirt
setblock ~184 ~117 ~107 dirt
setblock ~184 ~117 ~108 dirt
setblock ~184 ~118 ~86 dirt
setblock ~184 ~118 ~87 dirt
setblock ~184 ~118 ~88 dirt
setblock ~184 ~118 ~89 dirt
setblock ~184 ~118 ~90 dirt
setblock ~184 ~118 ~91 dirt
setblock ~184 ~118 ~92 dirt
setblock ~184 ~118 ~93 dirt
setblock ~184 ~118 ~94 dirt
setblock ~184 ~118 ~95 dirt
setblock ~184 ~118 ~96 dirt
setblock ~184 ~118 ~97 dirt
setblock ~184 ~118 ~98 dirt
setblock ~184 ~118 ~99 dirt
setblock ~184 ~118 ~100 dirt
setblock ~184 ~118 ~101 dirt
setblock ~184 ~118 ~102 dirt
setblock ~184 ~118 ~103 dirt
setblock ~184 ~118 ~104 dirt
setblock ~184 ~118 ~105 dirt
setblock ~184 ~118 ~106 dirt
setblock ~184 ~118 ~107 dirt
setblock ~184 ~118 ~108 dirt
setblock ~184 ~118 ~109 dirt
setblock ~184 ~119 ~85 dirt
setblock ~184 ~119 ~86 dirt
setblock ~184 ~119 ~87 dirt
setblock ~184 ~119 ~88 dirt
setblock ~184 ~119 ~89 dirt
setblock ~184 ~119 ~90 dirt
setblock ~184 ~119 ~91 dirt
setblock ~184 ~119 ~92 dirt
setblock ~184 ~119 ~93 dirt
setblock ~184 ~119 ~94 dirt
setblock ~184 ~119 ~95 dirt
setblock ~184 ~119 ~96 dirt
setblock ~184 ~119 ~97 dirt
setblock ~184 ~119 ~98 dirt
setblock ~184 ~119 ~99 dirt
setblock ~184 ~119 ~100 dirt
setblock ~184 ~119 ~101 dirt
setblock ~184 ~119 ~102 dirt
setblock ~184 ~119 ~103 dirt
setblock ~184 ~119 ~104 dirt
setblock ~184 ~119 ~105 dirt
setblock ~184 ~119 ~106 dirt
setblock ~184 ~119 ~107 dirt
setblock ~184 ~119 ~108 dirt
setblock ~184 ~119 ~109 dirt
setblock ~184 ~119 ~110 dirt
setblock ~184 ~119 ~121 dirt
setblock ~184 ~119 ~130 dirt
setblock ~184 ~120 ~72 dirt
setblock ~184 ~120 ~84 dirt
setblock ~184 ~120 ~85 dirt
setblock ~184 ~120 ~86 dirt
setblock ~184 ~120 ~87 dirt
setblock ~184 ~120 ~88 dirt
setblock ~184 ~120 ~89 dirt
setblock ~184 ~120 ~90 dirt
setblock ~184 ~120 ~91 dirt
setblock ~184 ~120 ~92 dirt
setblock ~184 ~120 ~93 dirt
setblock ~184 ~120 ~94 dirt
setblock ~184 ~120 ~95 dirt
setblock ~184 ~120 ~96 dirt
setblock ~184 ~120 ~97 dirt
setblock ~184 ~120 ~98 dirt
setblock ~184 ~120 ~99 dirt
setblock ~184 ~120 ~100 dirt
setblock ~184 ~120 ~101 dirt
setblock ~184 ~120 ~102 dirt
setblock ~184 ~120 ~103 dirt
setblock ~184 ~120 ~104 dirt
setblock ~184 ~120 ~105 dirt
setblock ~184 ~120 ~106 dirt
setblock ~184 ~120 ~107 dirt
setblock ~184 ~120 ~108 dirt
setblock ~184 ~120 ~109 dirt
setblock ~184 ~120 ~110 dirt
setblock ~184 ~120 ~111 dirt
setblock ~184 ~120 ~118 dirt
setblock ~184 ~120 ~119 dirt
setblock ~184 ~120 ~120 dirt
setblock ~184 ~120 ~121 dirt
setblock ~184 ~120 ~130 dirt
setblock ~184 ~121 ~71 dirt
setblock ~184 ~121 ~72 dirt
setblock ~184 ~121 ~73 dirt
setblock ~184 ~121 ~83 dirt
setblock ~184 ~121 ~84 dirt
setblock ~184 ~121 ~85 dirt
setblock ~184 ~121 ~86 dirt
setblock ~184 ~121 ~87 dirt
setblock ~184 ~121 ~88 dirt
setblock ~184 ~121 ~89 dirt
setblock ~184 ~121 ~90 dirt
setblock ~184 ~121 ~91 dirt
setblock ~184 ~121 ~92 dirt
setblock ~184 ~121 ~93 dirt
setblock ~184 ~121 ~94 dirt
setblock ~184 ~121 ~95 dirt
setblock ~184 ~121 ~96 dirt
setblock ~184 ~121 ~97 dirt
setblock ~184 ~121 ~98 dirt
setblock ~184 ~121 ~99 dirt
setblock ~184 ~121 ~100 dirt
setblock ~184 ~121 ~101 dirt
setblock ~184 ~121 ~102 dirt
setblock ~184 ~121 ~103 dirt
setblock ~184 ~121 ~104 dirt
setblock ~184 ~121 ~105 dirt
setblock ~184 ~121 ~106 dirt
setblock ~184 ~121 ~107 dirt
setblock ~184 ~121 ~108 dirt
setblock ~184 ~121 ~109 dirt
setblock ~184 ~121 ~110 dirt
setblock ~184 ~121 ~111 dirt
setblock ~184 ~121 ~112 dirt
setblock ~184 ~121 ~117 dirt
setblock ~184 ~121 ~118 dirt
setblock ~184 ~121 ~119 dirt
setblock ~184 ~121 ~120 dirt
setblock ~184 ~121 ~121 dirt
setblock ~184 ~121 ~122 dirt
setblock ~184 ~121 ~123 dirt
setblock ~184 ~121 ~124 dirt
setblock ~184 ~121 ~129 dirt
setblock ~184 ~121 ~130 dirt
setblock ~184 ~121 ~131 dirt
setblock ~184 ~122 ~71 dirt
setblock ~184 ~122 ~72 dirt
setblock ~184 ~122 ~73 dirt
setblock ~184 ~122 ~83 dirt
setblock ~184 ~122 ~84 dirt
setblock ~184 ~122 ~85 dirt
setblock ~184 ~122 ~86 dirt
setblock ~184 ~122 ~87 dirt
setblock ~184 ~122 ~88 dirt
setblock ~184 ~122 ~89 dirt
setblock ~184 ~122 ~90 dirt
setblock ~184 ~122 ~91 dirt
setblock ~184 ~122 ~92 dirt
setblock ~184 ~122 ~93 dirt
setblock ~184 ~122 ~94 dirt
setblock ~184 ~122 ~95 dirt
setblock ~184 ~122 ~96 dirt
setblock ~184 ~122 ~97 dirt
setblock ~184 ~122 ~98 dirt
setblock ~184 ~122 ~99 dirt
setblock ~184 ~122 ~100 dirt
setblock ~184 ~122 ~101 dirt
setblock ~184 ~122 ~102 dirt
setblock ~184 ~122 ~103 dirt
setblock ~184 ~122 ~104 dirt
setblock ~184 ~122 ~105 dirt
setblock ~184 ~122 ~106 dirt
setblock ~184 ~122 ~107 dirt
setblock ~184 ~122 ~108 dirt
setblock ~184 ~122 ~109 dirt
setblock ~184 ~122 ~110 dirt
setblock ~184 ~122 ~111 dirt
setblock ~184 ~122 ~112 dirt
setblock ~184 ~122 ~117 dirt
setblock ~184 ~122 ~118 dirt
setblock ~184 ~122 ~119 dirt
setblock ~184 ~122 ~120 dirt
setblock ~184 ~122 ~121 dirt
setblock ~184 ~122 ~122 dirt
setblock ~184 ~122 ~123 dirt
setblock ~184 ~122 ~124 dirt
setblock ~184 ~122 ~129 dirt
setblock ~184 ~122 ~130 dirt
setblock ~184 ~122 ~131 dirt
setblock ~184 ~123 ~71 dirt
setblock ~184 ~123 ~72 dirt
setblock ~184 ~123 ~73 dirt
setblock ~184 ~123 ~83 dirt
setblock ~184 ~123 ~84 dirt
setblock ~184 ~123 ~85 dirt
setblock ~184 ~123 ~86 dirt
setblock ~184 ~123 ~87 dirt
setblock ~184 ~123 ~88 dirt
setblock ~184 ~123 ~89 dirt
setblock ~184 ~123 ~90 dirt
setblock ~184 ~123 ~91 dirt
setblock ~184 ~123 ~92 dirt
setblock ~184 ~123 ~93 dirt
setblock ~184 ~123 ~94 dirt
setblock ~184 ~123 ~95 dirt
setblock ~184 ~123 ~96 dirt
setblock ~184 ~123 ~97 dirt
setblock ~184 ~123 ~98 dirt
setblock ~184 ~123 ~99 dirt
setblock ~184 ~123 ~100 dirt
setblock ~184 ~123 ~101 dirt
setblock ~184 ~123 ~102 dirt
setblock ~184 ~123 ~103 dirt
setblock ~184 ~123 ~104 dirt
setblock ~184 ~123 ~105 dirt
setblock ~184 ~123 ~106 dirt
setblock ~184 ~123 ~107 dirt
setblock ~184 ~123 ~108 dirt
setblock ~184 ~123 ~109 grass_block
setblock ~184 ~123 ~110 grass_block
setblock ~184 ~123 ~111 grass_block
setblock ~184 ~123 ~112 dirt
setblock ~184 ~123 ~117 dirt
setblock ~184 ~123 ~118 dirt
setblock ~184 ~123 ~119 dirt
setblock ~184 ~123 ~120 dirt
setblock ~184 ~123 ~121 dirt
setblock ~184 ~123 ~122 dirt
setblock ~184 ~123 ~123 dirt
setblock ~184 ~123 ~124 dirt
setblock ~184 ~123 ~129 dirt
setblock ~184 ~123 ~130 dirt
setblock ~184 ~123 ~131 dirt
setblock ~184 ~124 ~71 grass_block
setblock ~184 ~124 ~72 grass_block
setblock ~184 ~124 ~73 grass_block
setblock ~184 ~124 ~83 grass_block
setblock ~184 ~124 ~84 grass_block
setblock ~184 ~124 ~85 grass_block
setblock ~184 ~124 ~86 grass_block
setblock ~184 ~124 ~87 grass_block
setblock ~184 ~124 ~88 grass_block
setblock ~184 ~124 ~89 dirt
setblock ~184 ~124 ~90 dirt
setblock ~184 ~124 ~91 dirt
setblock ~184 ~124 ~92 dirt
setblock ~184 ~124 ~93 dirt
setblock ~184 ~124 ~94 dirt
setblock ~184 ~124 ~95 dirt
setblock ~184 ~124 ~96 dirt
setblock ~184 ~124 ~97 dirt
setblock ~184 ~124 ~98 dirt
setblock ~184 ~124 ~99 dirt
setblock ~184 ~124 ~100 dirt
setblock ~184 ~124 ~101 dirt
setblock ~184 ~124 ~102 dirt
setblock ~184 ~124 ~103 dirt
setblock ~184 ~124 ~104 dirt
setblock ~184 ~124 ~105 dirt
setblock ~184 ~124 ~106 grass_block
setblock ~184 ~124 ~107 grass_block
setblock ~184 ~124 ~108 grass_block
setblock ~184 ~124 ~110 poppy
setblock ~184 ~124 ~112 grass_block
setblock ~184 ~124 ~117 dirt
setblock ~184 ~124 ~118 dirt
setblock ~184 ~124 ~119 dirt
setblock ~184 ~124 ~120 dirt
setblock ~184 ~124 ~121 dirt
setblock ~184 ~124 ~122 dirt
setblock ~184 ~124 ~123 dirt
setblock ~184 ~124 ~124 dirt
setblock ~184 ~124 ~129 dirt
setblock ~184 ~124 ~130 dirt
setblock ~184 ~124 ~131 dirt
setblock ~184 ~125 ~83 short_grass
setblock ~184 ~125 ~86 short_grass
setblock ~184 ~125 ~89 grass_block
setblock ~184 ~125 ~90 grass_block
setblock ~184 ~125 ~91 grass_block
setblock ~184 ~125 ~92 grass_block
setblock ~184 ~125 ~93 grass_block
setblock ~184 ~125 ~94 grass_block
setblock ~184 ~125 ~95 grass_block
setblock ~184 ~125 ~96 grass_block
setblock ~184 ~125 ~97 grass_block
setblock ~184 ~125 ~98 grass_block
setblock ~184 ~125 ~99 grass_block
setblock ~184 ~125 ~100 grass_block
setblock ~184 ~125 ~101 grass_block
setblock ~184 ~125 ~102 grass_block
setblock ~184 ~125 ~103 grass_block
setblock ~184 ~125 ~104 grass_block
setblock ~184 ~125 ~105 grass_block
setblock ~184 ~125 ~117 grass_block
setblock ~184 ~125 ~118 grass_block
setblock ~184 ~125 ~119 grass_block
setblock ~184 ~125 ~120 grass_block
setblock ~184 ~125 ~121 grass_block
setblock ~184 ~125 ~122 grass_block
setblock ~184 ~125 ~123 grass_block
setblock ~184 ~125 ~124 grass_block
setblock ~184 ~125 ~129 grass_block
setblock ~184 ~125 ~130 grass_block
setblock ~184 ~125 ~131 grass_block
setblock ~184 ~126 ~89 short_grass
setblock ~184 ~126 ~90 short_grass
setblock ~184 ~126 ~91 short_grass
setblock ~184 ~126 ~92 fern
setblock ~184 ~126 ~97 short_grass
setblock ~184 ~126 ~99 fern
setblock ~184 ~126 ~104 short_grass
setblock ~184 ~126 ~122 fern
setblock ~184 ~126 ~123 short_grass
setblock ~184 ~126 ~129 short_grass
setblock ~184 ~126 ~131 short_grass
setblock ~185 ~111 ~95 dirt
setblock ~185 ~111 ~96 dirt
setblock ~185 ~111 ~97 dirt
setblock ~185 ~111 ~98 dirt
setblock ~185 ~112 ~94 dirt
setblock ~185 ~112 ~95 dirt
setblock ~185 ~112 ~96 dirt
setblock ~185 ~112 ~97 dirt
setblock ~185 ~112 ~98 dirt
setblock ~185 ~112 ~99 dirt
setblock ~185 ~113 ~93 dirt
setblock ~185 ~113 ~94 dirt
setblock ~185 ~113 ~95 dirt
setblock ~185 ~113 ~96 dirt
setblock ~185 ~113 ~97 dirt
setblock ~185 ~113 ~98 dirt
setblock ~185 ~113 ~99 dirt
setblock ~185 ~113 ~100 dirt
setblock ~185 ~114 ~91 dirt
setblock ~185 ~114 ~92 dirt
setblock ~185 ~114 ~93 dirt
setblock ~185 ~114 ~94 dirt
setblock ~185 ~114 ~95 dirt
setblock ~185 ~114 ~96 dirt
setblock ~185 ~114 ~97 dirt
setblock ~185 ~114 ~98 dirt
setblock ~185 ~114 ~99 dirt
setblock ~185 ~114 ~100 dirt
setblock ~185 ~114 ~101 dirt
setblock ~185 ~115 ~91 dirt
setblock ~185 ~115 ~92 dirt
setblock ~185 ~115 ~93 dirt
setblock ~185 ~115 ~94 dirt
setblock ~185 ~115 ~95 dirt
setblock ~185 ~115 ~96 dirt
setblock ~185 ~115 ~97 dirt
setblock ~185 ~115 ~98 dirt
setblock ~185 ~115 ~99 dirt
setblock ~185 ~115 ~100 dirt
setblock ~185 ~115 ~101 dirt
setblock ~185 ~115 ~102 dirt
setblock ~185 ~116 ~72 dirt
setblock ~185 ~116 ~89 dirt
setblock ~185 ~116 ~90 dirt
setblock ~185 ~116 ~91 dirt
setblock ~185 ~116 ~92 dirt
setblock ~185 ~116 ~93 dirt
setblock ~185 ~116 ~94 dirt
setblock ~185 ~116 ~95 dirt
setblock ~185 ~116 ~96 dirt
setblock ~185 ~116 ~97 dirt
setblock ~185 ~116 ~98 dirt
setblock ~185 ~116 ~99 dirt
setblock ~185 ~116 ~100 dirt
setblock ~185 ~116 ~101 dirt
setblock ~185 ~116 ~102 dirt
setblock ~185 ~116 ~103 dirt
setblock ~185 ~117 ~72 dirt
setblock ~185 ~117 ~88 dirt
setblock ~185 ~117 ~89 dirt
setblock ~185 ~117 ~90 dirt
setblock ~185 ~117 ~91 dirt
setblock ~185 ~117 ~92 dirt
setblock ~185 ~117 ~93 dirt
setblock ~185 ~117 ~94 dirt
setblock ~185 ~117 ~95 dirt
setblock ~185 ~117 ~96 dirt
setblock ~185 ~117 ~97 dirt
setblock ~185 ~117 ~98 dirt
setblock ~185 ~117 ~99 dirt
setblock ~185 ~117 ~100 dirt
setblock ~185 ~117 ~101 dirt
setblock ~185 ~117 ~102 dirt
setblock ~185 ~117 ~103 dirt
setblock ~185 ~117 ~104 dirt
setblock ~185 ~117 ~105 dirt
setblock ~185 ~117 ~106 dirt
setblock ~185 ~118 ~72 dirt
setblock ~185 ~118 ~87 dirt
setblock ~185 ~118 ~88 dirt
setblock ~185 ~118 ~89 dirt
setblock ~185 ~118 ~90 dirt
setblock ~185 ~118 ~91 dirt
setblock ~185 ~118 ~92 dirt
setblock ~185 ~118 ~93 dirt
setblock ~185 ~118 ~94 dirt
setblock ~185 ~118 ~95 dirt
setblock ~185 ~118 ~96 dirt
setblock ~185 ~118 ~97 dirt
setblock ~185 ~118 ~98 dirt
setblock ~185 ~118 ~99 dirt
setblock ~185 ~118 ~100 dirt
setblock ~185 ~118 ~101 dirt
setblock ~185 ~118 ~102 dirt
setblock ~185 ~118 ~103 dirt
setblock ~185 ~118 ~104 dirt
setblock ~185 ~118 ~105 dirt
setblock ~185 ~118 ~106 dirt
setblock ~185 ~118 ~107 dirt
setblock ~185 ~119 ~72 dirt
setblock ~185 ~119 ~86 dirt
setblock ~185 ~119 ~87 dirt
setblock ~185 ~119 ~88 dirt
setblock ~185 ~119 ~89 dirt
setblock ~185 ~119 ~90 dirt
setblock ~185 ~119 ~91 dirt
setblock ~185 ~119 ~92 dirt
setblock ~185 ~119 ~93 dirt
setblock ~185 ~119 ~94 dirt
setblock ~185 ~119 ~95 dirt
setblock ~185 ~119 ~96 dirt
setblock ~185 ~119 ~97 dirt
setblock ~185 ~119 ~98 dirt
setblock ~185 ~119 ~99 dirt
setblock ~185 ~119 ~100 dirt
setblock ~185 ~119 ~101 dirt
setblock ~185 ~119 ~102 dirt
setblock ~185 ~119 ~103 dirt
setblock ~185 ~119 ~104 dirt
setblock ~185 ~119 ~105 dirt
setblock ~185 ~119 ~106 dirt
setblock ~185 ~119 ~107 dirt
setblock ~185 ~119 ~108 dirt
setblock ~185 ~119 ~109 dirt
setblock ~185 ~120 ~71 dirt
setblock ~185 ~120 ~72 dirt
setblock ~185 ~120 ~73 dirt
setblock ~185 ~120 ~85 dirt
setblock ~185 ~120 ~86 dirt
setblock ~185 ~120 ~87 dirt
setblock ~185 ~120 ~88 dirt
setblock ~185 ~120 ~89 dirt
setblock ~185 ~120 ~90 dirt
setblock ~185 ~120 ~91 dirt
setblock ~185 ~120 ~92 dirt
setblock ~185 ~120 ~93 dirt
setblock ~185 ~120 ~94 dirt
setblock ~185 ~120 ~95 dirt
setblock ~185 ~120 ~96 dirt
setblock ~185 ~120 ~97 dirt
setblock ~185 ~120 ~98 dirt
setblock ~185 ~120 ~99 dirt
setblock ~185 ~120 ~100 dirt
setblock ~185 ~120 ~101 dirt
setblock ~185 ~120 ~102 dirt
setblock ~185 ~120 ~103 dirt
setblock ~185 ~120 ~104 dirt
setblock ~185 ~120 ~105 dirt
setblock ~185 ~120 ~106 dirt
setblock ~185 ~120 ~107 dirt
setblock ~185 ~120 ~108 dirt
setblock ~185 ~120 ~109 dirt
setblock ~185 ~120 ~110 dirt
setblock ~185 ~120 ~115 dirt
setblock ~185 ~121 ~70 dirt
setblock ~185 ~121 ~71 dirt
setblock ~185 ~121 ~72 dirt
setblock ~185 ~121 ~73 dirt
setblock ~185 ~121 ~84 dirt
setblock ~185 ~121 ~85 dirt
setblock ~185 ~121 ~86 dirt
setblock ~185 ~121 ~87 dirt
setblock ~185 ~121 ~88 dirt
setblock ~185 ~121 ~89 dirt
setblock ~185 ~121 ~90 dirt
setblock ~185 ~121 ~91 dirt
setblock ~185 ~121 ~92 dirt
setblock ~185 ~121 ~93 dirt
setblock ~185 ~121 ~94 dirt
setblock ~185 ~121 ~95 dirt
setblock ~185 ~121 ~96 dirt
setblock ~185 ~121 ~97 dirt
setblock ~185 ~121 ~98 dirt
setblock ~185 ~121 ~99 dirt
setblock ~185 ~121 ~100 dirt
setblock ~185 ~121 ~101 dirt
setblock ~185 ~121 ~102 dirt
setblock ~185 ~121 ~103 dirt
setblock ~185 ~121 ~104 dirt
setblock ~185 ~121 ~105 dirt
setblock ~185 ~121 ~106 dirt
setblock ~185 ~121 ~107 dirt
setblock ~185 ~121 ~108 dirt
setblock ~185 ~121 ~109 dirt
setblock ~185 ~121 ~110 dirt
setblock ~185 ~121 ~111 dirt
setblock ~185 ~121 ~115 dirt
setblock ~185 ~121 ~120 dirt
setblock ~185 ~121 ~121 dirt
setblock ~185 ~121 ~130 dirt
setblock ~185 ~122 ~70 dirt
setblock ~185 ~122 ~71 dirt
setblock ~185 ~122 ~72 dirt
setblock ~185 ~122 ~73 dirt
setblock ~185 ~122 ~84 dirt
setblock ~185 ~122 ~85 dirt
setblock ~185 ~122 ~86 dirt
setblock ~185 ~122 ~87 dirt
setblock ~185 ~122 ~88 dirt
setblock ~185 ~122 ~89 dirt
setblock ~185 ~122 ~90 dirt
setblock ~185 ~122 ~91 dirt
setblock ~185 ~122 ~92 dirt
setblock ~185 ~122 ~93 dirt
setblock ~185 ~122 ~94 dirt
setblock ~185 ~122 ~95 dirt
setblock ~185 ~122 ~96 dirt
setblock ~185 ~122 ~97 dirt
setblock ~185 ~122 ~98 dirt
setblock ~185 ~122 ~99 dirt
setblock ~185 ~122 ~100 dirt
setblock ~185 ~122 ~101 dirt
setblock ~185 ~122 ~102 dirt
setblock ~185 ~122 ~103 dirt
setblock ~185 ~122 ~104 dirt
setblock ~185 ~122 ~105 dirt
setblock ~185 ~122 ~106 dirt
setblock ~185 ~122 ~107 dirt
setblock ~185 ~122 ~108 dirt
setblock ~185 ~122 ~109 dirt
setblock ~185 ~122 ~110 dirt
setblock ~185 ~122 ~111 dirt
setblock ~185 ~122 ~115 dirt
setblock ~185 ~122 ~120 dirt
setblock ~185 ~122 ~121 dirt
setblock ~185 ~122 ~130 dirt
setblock ~185 ~123 ~70 dirt
setblock ~185 ~123 ~71 dirt
setblock ~185 ~123 ~72 dirt
setblock ~185 ~123 ~73 dirt
setblock ~185 ~123 ~84 dirt
setblock ~185 ~123 ~85 dirt
setblock ~185 ~123 ~86 dirt
setblock ~185 ~123 ~87 dirt
setblock ~185 ~123 ~88 dirt
setblock ~185 ~123 ~89 dirt
setblock ~185 ~123 ~90 dirt
setblock ~185 ~123 ~91 dirt
setblock ~185 ~123 ~92 dirt
setblock ~185 ~123 ~93 dirt
setblock ~185 ~123 ~94 dirt
setblock ~185 ~123 ~95 dirt
setblock ~185 ~123 ~96 dirt
setblock ~185 ~123 ~97 dirt
setblock ~185 ~123 ~98 dirt
setblock ~185 ~123 ~99 dirt
setblock ~185 ~123 ~100 dirt
setblock ~185 ~123 ~101 dirt
setblock ~185 ~123 ~102 dirt
setblock ~185 ~123 ~103 dirt
setblock ~185 ~123 ~104 dirt
setblock ~185 ~123 ~105 dirt
setblock ~185 ~123 ~106 dirt
setblock ~185 ~123 ~107 dirt
setblock ~185 ~123 ~108 dirt
setblock ~185 ~123 ~109 grass_block
setblock ~185 ~123 ~110 grass_block
setblock ~185 ~123 ~111 grass_block
setblock ~185 ~123 ~115 dirt
setblock ~185 ~123 ~120 dirt
setblock ~185 ~123 ~121 dirt
setblock ~185 ~123 ~130 dirt
setblock ~185 ~124 ~70 grass_block
setblock ~185 ~124 ~71 grass_block
setblock ~185 ~124 ~72 grass_block
setblock ~185 ~124 ~73 grass_block
setblock ~185 ~124 ~84 grass_block
setblock ~185 ~124 ~85 dirt
setblock ~185 ~124 ~86 dirt
setblock ~185 ~124 ~87 dirt
setblock ~185 ~124 ~88 dirt
setblock ~185 ~124 ~89 dirt
setblock ~185 ~124 ~90 dirt
setblock ~185 ~124 ~91 dirt
setblock ~185 ~124 ~92 dirt
setblock ~185 ~124 ~93 dirt
setblock ~185 ~124 ~94 dirt
setblock ~185 ~124 ~95 dirt
setblock ~185 ~124 ~96 dirt
setblock ~185 ~124 ~97 dirt
setblock ~185 ~124 ~98 dirt
setblock ~185 ~124 ~99 dirt
setblock ~185 ~124 ~100 dirt
setblock ~185 ~124 ~101 dirt
setblock ~185 ~124 ~102 dirt
setblock ~185 ~124 ~103 dirt
setblock ~185 ~124 ~104 dirt
setblock ~185 ~124 ~105 grass_block
setblock ~185 ~124 ~106 grass_block
setblock ~185 ~124 ~107 grass_block
setblock ~185 ~124 ~108 grass_block
setblock ~185 ~124 ~109 short_grass
