setblock ~72 ~125 ~9 dirt
setblock ~72 ~125 ~10 dirt
setblock ~72 ~125 ~11 dirt
setblock ~72 ~125 ~12 dirt
setblock ~72 ~125 ~13 dirt
setblock ~72 ~125 ~14 dirt
setblock ~72 ~125 ~15 dirt
setblock ~72 ~125 ~16 dirt
setblock ~72 ~125 ~17 dirt
setblock ~72 ~125 ~18 dirt
setblock ~72 ~125 ~19 dirt
setblock ~72 ~125 ~20 grass_block
setblock ~72 ~125 ~21 grass_block
setblock ~72 ~125 ~22 grass_block
setblock ~72 ~125 ~23 grass_block
setblock ~72 ~125 ~24 grass_block
setblock ~72 ~125 ~25 grass_block
setblock ~72 ~125 ~27 short_grass
setblock ~72 ~125 ~29 short_grass
setblock ~72 ~125 ~33 short_grass
setblock ~72 ~125 ~35 short_grass
setblock ~72 ~125 ~37 poppy
setblock ~72 ~125 ~41 fern
setblock ~72 ~125 ~46 short_grass
setblock ~72 ~125 ~52 short_grass
setblock ~72 ~125 ~56 grass_block
setblock ~72 ~125 ~57 grass_block
setblock ~72 ~125 ~58 grass_block
setblock ~72 ~125 ~59 grass_block
setblock ~72 ~125 ~60 dirt
setblock ~72 ~125 ~61 dirt
setblock ~72 ~125 ~62 dirt
setblock ~72 ~125 ~63 dirt
setblock ~72 ~125 ~64 dirt
setblock ~72 ~125 ~65 dirt
setblock ~72 ~125 ~66 dirt
setblock ~72 ~125 ~67 dirt
setblock ~72 ~125 ~68 dirt
setblock ~72 ~125 ~69 dirt
setblock ~72 ~125 ~70 dirt
setblock ~72 ~125 ~71 dirt
setblock ~72 ~125 ~72 grass_block
setblock ~72 ~125 ~73 grass_block
setblock ~72 ~125 ~74 grass_block
setblock ~72 ~125 ~75 grass_block
setblock ~72 ~125 ~76 grass_block
setblock ~72 ~125 ~77 grass_block
setblock ~72 ~125 ~78 grass_block
setblock ~72 ~125 ~79 short_grass
setblock ~72 ~125 ~81 short_grass
setblock ~72 ~125 ~84 short_grass
setblock ~72 ~125 ~86 short_grass
setblock ~72 ~125 ~88 short_grass
setblock ~72 ~125 ~92 short_grass
setblock ~72 ~125 ~93 grass_block
setblock ~72 ~125 ~94 grass_block
setblock ~72 ~125 ~95 grass_block
setblock ~72 ~125 ~96 grass_block
setblock ~72 ~125 ~97 grass_block
setblock ~72 ~125 ~98 grass_block
setblock ~72 ~125 ~99 grass_block
setblock ~72 ~125 ~100 dirt
setblock ~72 ~125 ~101 grass_block
setblock ~72 ~125 ~102 grass_block
setblock ~72 ~125 ~103 grass_block
setblock ~72 ~125 ~104 grass_block
setblock ~72 ~125 ~105 grass_block
setblock ~72 ~125 ~106 grass_block
setblock ~72 ~125 ~107 grass_block
setblock ~72 ~125 ~112 grass_block
setblock ~72 ~125 ~113 grass_block
setblock ~72 ~125 ~114 grass_block
setblock ~72 ~125 ~115 dirt
setblock ~72 ~125 ~116 dirt
setblock ~72 ~125 ~117 dirt
setblock ~72 ~125 ~118 dirt
setblock ~72 ~125 ~119 dirt
setblock ~72 ~125 ~120 dirt
setblock ~72 ~125 ~121 dirt
setblock ~72 ~125 ~122 dirt
setblock ~72 ~125 ~123 dirt
setblock ~72 ~125 ~124 dirt
setblock ~72 ~125 ~125 grass_block
setblock ~72 ~125 ~126 grass_block
setblock ~72 ~125 ~127 short_grass
setblock ~72 ~125 ~135 fern
setblock ~72 ~125 ~136 short_grass
setblock ~72 ~125 ~139 grass_block
setblock ~72 ~125 ~140 grass_block
setblock ~72 ~125 ~141 grass_block
setblock ~72 ~125 ~142 grass_block
setblock ~72 ~125 ~143 poppy
setblock ~72 ~125 ~144 short_grass
setblock ~72 ~125 ~153 short_grass
setblock ~72 ~125 ~156 short_grass
setblock ~72 ~125 ~157 grass_block
setblock ~72 ~125 ~158 grass_block
setblock ~72 ~125 ~159 grass_block
setblock ~72 ~125 ~160 grass_block
setblock ~72 ~125 ~161 grass_block
setblock ~72 ~125 ~162 grass_block
setblock ~72 ~125 ~163 dirt
setblock ~72 ~125 ~164 dirt
setblock ~72 ~125 ~165 dirt
setblock ~72 ~125 ~166 dirt
setblock ~72 ~125 ~167 dirt
setblock ~72 ~125 ~168 dirt
setblock ~72 ~125 ~169 dirt
setblock ~72 ~125 ~170 dirt
setblock ~72 ~125 ~171 dirt
setblock ~72 ~125 ~172 dirt
setblock ~72 ~125 ~173 dirt
setblock ~72 ~125 ~174 dirt
setblock ~72 ~125 ~175 grass_block
setblock ~72 ~125 ~176 grass_block
setblock ~72 ~125 ~177 grass_block
setblock ~72 ~125 ~178 short_grass
setblock ~72 ~125 ~179 fern
setblock ~72 ~125 ~195 short_grass
setblock ~72 ~125 ~197 short_grass
setblock ~72 ~125 ~198 grass_block
setblock ~72 ~125 ~199 grass_block
setblock ~72 ~126 ~6 short_grass
setblock ~72 ~126 ~9 grass_block
setblock ~72 ~126 ~10 grass_block
setblock ~72 ~126 ~11 grass_block
setblock ~72 ~126 ~12 grass_block
setblock ~72 ~126 ~13 grass_block
setblock ~72 ~126 ~14 grass_block
setblock ~72 ~126 ~15 grass_block
setblock ~72 ~126 ~16 grass_block
setblock ~72 ~126 ~17 grass_block
setblock ~72 ~126 ~18 grass_block
setblock ~72 ~126 ~19 grass_block
setblock ~72 ~126 ~20 short_grass
setblock ~72 ~126 ~21 short_grass
setblock ~72 ~126 ~25 short_grass
setblock ~72 ~126 ~56 poppy
setblock ~72 ~126 ~59 short_grass
setblock ~72 ~126 ~60 grass_block
setblock ~72 ~126 ~61 grass_block
setblock ~72 ~126 ~62 grass_block
setblock ~72 ~126 ~63 grass_block
setblock ~72 ~126 ~64 grass_block
setblock ~72 ~126 ~65 grass_block
setblock ~72 ~126 ~66 grass_block
setblock ~72 ~126 ~67 grass_block
setblock ~72 ~126 ~68 grass_block
setblock ~72 ~126 ~69 grass_block
setblock ~72 ~126 ~70 grass_block
setblock ~72 ~126 ~71 grass_block
setblock ~72 ~126 ~73 short_grass
setblock ~72 ~126 ~74 short_grass
setblock ~72 ~126 ~78 short_grass
setblock ~72 ~126 ~100 grass_block
setblock ~72 ~126 ~102 short_grass
setblock ~72 ~126 ~105 short_grass
setblock ~72 ~126 ~113 short_grass
setblock ~72 ~126 ~115 grass_block
setblock ~72 ~126 ~116 grass_block
setblock ~72 ~126 ~117 dirt
setblock ~72 ~126 ~118 dirt
setblock ~72 ~126 ~119 dirt
setblock ~72 ~126 ~120 dirt
setblock ~72 ~126 ~121 dirt
setblock ~72 ~126 ~122 dirt
setblock ~72 ~126 ~123 grass_block
setblock ~72 ~126 ~124 grass_block
setblock ~72 ~126 ~126 short_grass
setblock ~72 ~126 ~140 short_grass
setblock ~72 ~126 ~163 grass_block
setblock ~72 ~126 ~164 grass_block
setblock ~72 ~126 ~165 grass_block
setblock ~72 ~126 ~166 dirt
setblock ~72 ~126 ~167 dirt
setblock ~72 ~126 ~168 dirt
setblock ~72 ~126 ~169 dirt
setblock ~72 ~126 ~170 dirt
setblock ~72 ~126 ~171 dirt
setblock ~72 ~126 ~172 dirt
setblock ~72 ~126 ~173 grass_block
setblock ~72 ~126 ~174 grass_block
setblock ~72 ~126 ~175 short_grass
setblock ~72 ~126 ~177 short_grass
setblock ~72 ~127 ~9 short_grass
setblock ~72 ~127 ~12 fern
setblock ~72 ~127 ~13 short_grass
setblock ~72 ~127 ~60 short_grass
setblock ~72 ~127 ~62 poppy
setblock ~72 ~127 ~65 short_grass
setblock ~72 ~127 ~66 short_grass
setblock ~72 ~127 ~100 fern
setblock ~72 ~127 ~117 grass_block
setblock ~72 ~127 ~118 grass_block
setblock ~72 ~127 ~119 grass_block
setblock ~72 ~127 ~120 dirt
setblock ~72 ~127 ~121 grass_block
setblock ~72 ~127 ~122 grass_block
setblock ~72 ~127 ~166 grass_block
setblock ~72 ~127 ~167 grass_block
setblock ~72 ~127 ~168 grass_block
setblock ~72 ~127 ~169 dirt
setblock ~72 ~127 ~170 dirt
setblock ~72 ~127 ~171 grass_block
setblock ~72 ~127 ~172 grass_block
setblock ~72 ~128 ~120 grass_block
setblock ~72 ~128 ~166 short_grass
setblock ~72 ~128 ~169 grass_block
setblock ~72 ~128 ~170 grass_block
setblock ~72 ~129 ~120 short_grass
setblock ~73 ~122 ~0 grass_block
setblock ~73 ~122 ~1 dirt
setblock ~73 ~122 ~2 dirt
setblock ~73 ~122 ~3 dirt
setblock ~73 ~122 ~4 dirt
setblock ~73 ~122 ~5 dirt
setblock ~73 ~122 ~6 dirt
setblock ~73 ~122 ~7 dirt
setblock ~73 ~122 ~8 dirt
setblock ~73 ~122 ~9 dirt
setblock ~73 ~122 ~10 dirt
setblock ~73 ~122 ~11 dirt
setblock ~73 ~122 ~12 dirt
setblock ~73 ~122 ~13 dirt
setblock ~73 ~122 ~14 dirt
setblock ~73 ~122 ~15 dirt
setblock ~73 ~122 ~16 dirt
setblock ~73 ~122 ~17 dirt
setblock ~73 ~122 ~18 dirt
setblock ~73 ~122 ~19 dirt
setblock ~73 ~122 ~20 dirt
setblock ~73 ~122 ~21 dirt
setblock ~73 ~122 ~22 dirt
setblock ~73 ~122 ~23 dirt
setblock ~73 ~122 ~24 dirt
setblock ~73 ~122 ~25 dirt
setblock ~73 ~122 ~26 dirt
setblock ~73 ~122 ~27 dirt
setblock ~73 ~122 ~28 dirt
setblock ~73 ~122 ~29 dirt
setblock ~73 ~122 ~30 dirt
setblock ~73 ~122 ~31 dirt
setblock ~73 ~122 ~32 dirt
setblock ~73 ~122 ~33 dirt
setblock ~73 ~122 ~34 dirt
setblock ~73 ~122 ~35 dirt
setblock ~73 ~122 ~36 dirt
setblock ~73 ~122 ~37 dirt
setblock ~73 ~122 ~38 dirt
setblock ~73 ~122 ~39 dirt
setblock ~73 ~122 ~40 dirt
setblock ~73 ~122 ~41 dirt
setblock ~73 ~122 ~42 dirt
setblock ~73 ~122 ~43 dirt
setblock ~73 ~122 ~44 dirt
setblock ~73 ~122 ~45 dirt
setblock ~73 ~122 ~46 dirt
setblock ~73 ~122 ~47 dirt
setblock ~73 ~122 ~48 dirt
setblock ~73 ~122 ~49 dirt
setblock ~73 ~122 ~50 dirt
setblock ~73 ~122 ~51 dirt
setblock ~73 ~122 ~52 dirt
setblock ~73 ~122 ~53 dirt
setblock ~73 ~122 ~54 dirt
setblock ~73 ~122 ~55 dirt
setblock ~73 ~122 ~56 dirt
setblock ~73 ~122 ~57 dirt
setblock ~73 ~122 ~58 dirt
setblock ~73 ~122 ~59 dirt
setblock ~73 ~122 ~60 dirt
setblock ~73 ~122 ~61 dirt
setblock ~73 ~122 ~62 dirt
setblock ~73 ~122 ~63 dirt
setblock ~73 ~122 ~64 dirt
setblock ~73 ~122 ~65 dirt
setblock ~73 ~122 ~66 dirt
setblock ~73 ~122 ~67 dirt
setblock ~73 ~122 ~68 dirt
setblock ~73 ~122 ~69 dirt
setblock ~73 ~122 ~70 dirt
setblock ~73 ~122 ~71 dirt
setblock ~73 ~122 ~72 dirt
setblock ~73 ~122 ~73 dirt
setblock ~73 ~122 ~74 dirt
setblock ~73 ~122 ~75 dirt
setblock ~73 ~122 ~76 dirt
setblock ~73 ~122 ~77 dirt
setblock ~73 ~122 ~78 dirt
setblock ~73 ~122 ~79 dirt
setblock ~73 ~122 ~80 dirt
setblock ~73 ~122 ~81 dirt
setblock ~73 ~122 ~82 dirt
setblock ~73 ~122 ~83 dirt
setblock ~73 ~122 ~84 dirt
setblock ~73 ~122 ~85 dirt
setblock ~73 ~122 ~86 dirt
setblock ~73 ~122 ~87 dirt
setblock ~73 ~122 ~88 dirt
setblock ~73 ~122 ~89 dirt
setblock ~73 ~122 ~90 dirt
setblock ~73 ~122 ~91 dirt
setblock ~73 ~122 ~92 dirt
setblock ~73 ~122 ~93 dirt
setblock ~73 ~122 ~94 dirt
setblock ~73 ~122 ~95 dirt
setblock ~73 ~122 ~96 dirt
setblock ~73 ~122 ~97 dirt
setblock ~73 ~122 ~98 dirt
setblock ~73 ~122 ~99 dirt
setblock ~73 ~122 ~100 dirt
setblock ~73 ~122 ~101 dirt
setblock ~73 ~122 ~102 dirt
setblock ~73 ~122 ~103 dirt
setblock ~73 ~122 ~104 dirt
setblock ~73 ~122 ~105 dirt
setblock ~73 ~122 ~106 dirt
setblock ~73 ~122 ~107 dirt
setblock ~73 ~122 ~108 dirt
setblock ~73 ~122 ~109 dirt
setblock ~73 ~122 ~110 dirt
setblock ~73 ~122 ~111 dirt
setblock ~73 ~122 ~112 dirt
setblock ~73 ~122 ~113 dirt
setblock ~73 ~122 ~114 dirt
setblock ~73 ~122 ~115 dirt
setblock ~73 ~122 ~116 dirt
setblock ~73 ~122 ~117 dirt
setblock ~73 ~122 ~118 dirt
setblock ~73 ~122 ~119 dirt
setblock ~73 ~122 ~120 dirt
setblock ~73 ~122 ~121 dirt
setblock ~73 ~122 ~122 dirt
setblock ~73 ~122 ~123 dirt
setblock ~73 ~122 ~124 dirt
setblock ~73 ~122 ~125 dirt
setblock ~73 ~122 ~126 dirt
setblock ~73 ~122 ~127 dirt
setblock ~73 ~122 ~128 dirt
setblock ~73 ~122 ~129 dirt
setblock ~73 ~122 ~130 grass_block
setblock ~73 ~122 ~131 dirt
setblock ~73 ~122 ~132 dirt
setblock ~73 ~122 ~133 dirt
setblock ~73 ~122 ~134 dirt
setblock ~73 ~122 ~135 dirt
setblock ~73 ~122 ~136 dirt
setblock ~73 ~122 ~137 dirt
setblock ~73 ~122 ~138 dirt
setblock ~73 ~122 ~139 dirt
setblock ~73 ~122 ~140 dirt
setblock ~73 ~122 ~141 dirt
setblock ~73 ~122 ~142 dirt
setblock ~73 ~122 ~143 dirt
setblock ~73 ~122 ~144 dirt
setblock ~73 ~122 ~145 dirt
setblock ~73 ~122 ~146 dirt
setblock ~73 ~122 ~147 dirt
setblock ~73 ~122 ~148 dirt
setblock ~73 ~122 ~149 dirt
setblock ~73 ~122 ~150 dirt
setblock ~73 ~122 ~151 dirt
setblock ~73 ~122 ~152 dirt
setblock ~73 ~122 ~153 dirt
setblock ~73 ~122 ~154 dirt
setblock ~73 ~122 ~155 dirt
setblock ~73 ~122 ~156 dirt
setblock ~73 ~122 ~157 dirt
setblock ~73 ~122 ~158 dirt
setblock ~73 ~122 ~159 dirt
setblock ~73 ~122 ~160 dirt
setblock ~73 ~122 ~161 dirt
setblock ~73 ~122 ~162 dirt
setblock ~73 ~122 ~163 dirt
setblock ~73 ~122 ~164 dirt
setblock ~73 ~122 ~165 dirt
setblock ~73 ~122 ~166 dirt
setblock ~73 ~122 ~167 dirt
setblock ~73 ~122 ~168 dirt
setblock ~73 ~122 ~169 dirt
setblock ~73 ~122 ~170 dirt
setblock ~73 ~122 ~171 dirt
setblock ~73 ~122 ~172 dirt
setblock ~73 ~122 ~173 dirt
setblock ~73 ~122 ~174 dirt
setblock ~73 ~122 ~175 dirt
setblock ~73 ~122 ~176 dirt
setblock ~73 ~122 ~177 dirt
setblock ~73 ~122 ~178 dirt
setblock ~73 ~122 ~179 dirt
setblock ~73 ~122 ~180 dirt
setblock ~73 ~122 ~181 dirt
setblock ~73 ~122 ~182 dirt
setblock ~73 ~122 ~183 dirt
setblock ~73 ~122 ~184 dirt
setblock ~73 ~122 ~185 dirt
setblock ~73 ~122 ~186 dirt
setblock ~73 ~122 ~187 dirt
setblock ~73 ~122 ~188 dirt
setblock ~73 ~122 ~189 dirt
setblock ~73 ~122 ~190 dirt
setblock ~73 ~122 ~191 dirt
setblock ~73 ~122 ~192 dirt
setblock ~73 ~122 ~193 dirt
setblock ~73 ~122 ~194 dirt
setblock ~73 ~122 ~195 dirt
setblock ~73 ~122 ~196 dirt
setblock ~73 ~122 ~197 dirt
setblock ~73 ~122 ~198 dirt
setblock ~73 ~122 ~199 dirt
setblock ~73 ~123 ~0 short_grass
setblock ~73 ~123 ~1 grass_block
setblock ~73 ~123 ~2 grass_block
setblock ~73 ~123 ~3 grass_block
setblock ~73 ~123 ~4 dirt
setblock ~73 ~123 ~5 dirt
setblock ~73 ~123 ~6 dirt
setblock ~73 ~123 ~7 dirt
setblock ~73 ~123 ~8 dirt
setblock ~73 ~123 ~9 dirt
setblock ~73 ~123 ~10 dirt
setblock ~73 ~123 ~11 dirt
setblock ~73 ~123 ~12 dirt
setblock ~73 ~123 ~13 dirt
setblock ~73 ~123 ~14 dirt
setblock ~73 ~123 ~15 dirt
setblock ~73 ~123 ~16 dirt
setblock ~73 ~123 ~17 dirt
setblock ~73 ~123 ~18 dirt
setblock ~73 ~123 ~19 dirt
setblock ~73 ~123 ~20 dirt
setblock ~73 ~123 ~21 dirt
setblock ~73 ~123 ~22 dirt
setblock ~73 ~123 ~23 dirt
setblock ~73 ~123 ~24 dirt
setblock ~73 ~123 ~25 dirt
setblock ~73 ~123 ~26 dirt
setblock ~73 ~123 ~27 dirt
setblock ~73 ~123 ~28 dirt
setblock ~73 ~123 ~29 dirt
setblock ~73 ~123 ~30 dirt
setblock ~73 ~123 ~31 dirt
setblock ~73 ~123 ~32 dirt
setblock ~73 ~123 ~33 dirt
setblock ~73 ~123 ~34 dirt
setblock ~73 ~123 ~35 dirt
setblock ~73 ~123 ~36 dirt
setblock ~73 ~123 ~37 dirt
setblock ~73 ~123 ~38 dirt
setblock ~73 ~123 ~39 dirt
setblock ~73 ~123 ~40 dirt
setblock ~73 ~123 ~41 dirt
setblock ~73 ~123 ~42 dirt
setblock ~73 ~123 ~43 dirt
setblock ~73 ~123 ~44 dirt
setblock ~73 ~123 ~45 dirt
setblock ~73 ~123 ~46 dirt
setblock ~73 ~123 ~47 dirt
setblock ~73 ~123 ~48 grass_block
setblock ~73 ~123 ~49 grass_block
setblock ~73 ~123 ~50 grass_block
setblock ~73 ~123 ~51 grass_block
setblock ~73 ~123 ~52 dirt
setblock ~73 ~123 ~53 dirt
setblock ~73 ~123 ~54 dirt
setblock ~73 ~123 ~55 dirt
setblock ~73 ~123 ~56 dirt
setblock ~73 ~123 ~57 dirt
setblock ~73 ~123 ~58 dirt
setblock ~73 ~123 ~59 dirt
setblock ~73 ~123 ~60 dirt
setblock ~73 ~123 ~61 dirt
setblock ~73 ~123 ~62 dirt
setblock ~73 ~123 ~63 dirt
setblock ~73 ~123 ~64 dirt
setblock ~73 ~123 ~65 dirt
setblock ~73 ~123 ~66 dirt
setblock ~73 ~123 ~67 dirt
setblock ~73 ~123 ~68 dirt
setblock ~73 ~123 ~69 dirt
setblock ~73 ~123 ~70 dirt
setblock ~73 ~123 ~71 dirt
setblock ~73 ~123 ~72 dirt
setblock ~73 ~123 ~73 dirt
setblock ~73 ~123 ~74 dirt
setblock ~73 ~123 ~75 dirt
setblock ~73 ~123 ~76 dirt
setblock ~73 ~123 ~77 dirt
setblock ~73 ~123 ~78 dirt
setblock ~73 ~123 ~79 dirt
setblock ~73 ~123 ~80 dirt
setblock ~73 ~123 ~81 dirt
setblock ~73 ~123 ~82 dirt
setblock ~73 ~123 ~83 dirt
setblock ~73 ~123 ~84 dirt
setblock ~73 ~123 ~85 dirt
setblock ~73 ~123 ~86 dirt
setblock ~73 ~123 ~87 dirt
setblock ~73 ~123 ~88 dirt
setblock ~73 ~123 ~89 dirt
setblock ~73 ~123 ~90 dirt
setblock ~73 ~123 ~91 dirt
setblock ~73 ~123 ~92 dirt
setblock ~73 ~123 ~93 dirt
setblock ~73 ~123 ~94 dirt
setblock ~73 ~123 ~95 dirt
setblock ~73 ~123 ~96 dirt
setblock ~73 ~123 ~97 dirt
setblock ~73 ~123 ~98 dirt
setblock ~73 ~123 ~99 dirt
setblock ~73 ~123 ~100 dirt
setblock ~73 ~123 ~101 dirt
setblock ~73 ~123 ~102 dirt
setblock ~73 ~123 ~103 dirt
setblock ~73 ~123 ~104 dirt
setblock ~73 ~123 ~105 dirt
setblock ~73 ~123 ~106 dirt
setblock ~73 ~123 ~107 dirt
setblock ~73 ~123 ~108 dirt
setblock ~73 ~123 ~109 dirt
setblock ~73 ~123 ~110 dirt
setblock ~73 ~123 ~111 dirt
setblock ~73 ~123 ~112 dirt
setblock ~73 ~123 ~113 dirt
setblock ~73 ~123 ~114 dirt
setblock ~73 ~123 ~115 dirt
setblock ~73 ~123 ~116 dirt
setblock ~73 ~123 ~117 dirt
setblock ~73 ~123 ~118 dirt
setblock ~73 ~123 ~119 dirt
setblock ~73 ~123 ~120 dirt
setblock ~73 ~123 ~121 dirt
setblock ~73 ~123 ~122 dirt
setblock ~73 ~123 ~123 dirt
setblock ~73 ~123 ~124 dirt
setblock ~73 ~123 ~125 dirt
setblock ~73 ~123 ~126 dirt
setblock ~73 ~123 ~127 dirt
setblock ~73 ~123 ~128 grass_block
setblock ~73 ~123 ~129 grass_block
setblock ~73 ~123 ~130 fern
setblock ~73 ~123 ~131 grass_block
setblock ~73 ~123 ~132 grass_block
setblock ~73 ~123 ~133 dirt
setblock ~73 ~123 ~134 dirt
setblock ~73 ~123 ~135 dirt
setblock ~73 ~123 ~136 dirt
setblock ~73 ~123 ~137 dirt
setblock ~73 ~123 ~138 dirt
setblock ~73 ~123 ~139 dirt
setblock ~73 ~123 ~140 dirt
setblock ~73 ~123 ~141 dirt
setblock ~73 ~123 ~142 dirt
setblock ~73 ~123 ~143 dirt
setblock ~73 ~123 ~144 dirt
setblock ~73 ~123 ~145 dirt
setblock ~73 ~123 ~146 dirt
setblock ~73 ~123 ~147 dirt
setblock ~73 ~123 ~148 dirt
setblock ~73 ~123 ~149 dirt
setblock ~73 ~123 ~150 grass_block
setblock ~73 ~123 ~151 dirt
setblock ~73 ~123 ~152 dirt
setblock ~73 ~123 ~153 dirt
setblock ~73 ~123 ~154 dirt
setblock ~73 ~123 ~155 dirt
setblock ~73 ~123 ~156 dirt
setblock ~73 ~123 ~157 dirt
setblock ~73 ~123 ~158 dirt
setblock ~73 ~123 ~159 dirt
setblock ~73 ~123 ~160 dirt
setblock ~73 ~123 ~161 dirt
setblock ~73 ~123 ~162 dirt
setblock ~73 ~123 ~163 dirt
setblock ~73 ~123 ~164 dirt
setblock ~73 ~123 ~165 dirt
setblock ~73 ~123 ~166 dirt
setblock ~73 ~123 ~167 dirt
setblock ~73 ~123 ~168 dirt
setblock ~73 ~123 ~169 dirt
setblock ~73 ~123 ~170 dirt
setblock ~73 ~123 ~171 dirt
setblock ~73 ~123 ~172 dirt
setblock ~73 ~123 ~173 dirt
setblock ~73 ~123 ~174 dirt
setblock ~73 ~123 ~175 dirt
setblock ~73 ~123 ~176 dirt
setblock ~73 ~123 ~177 dirt
setblock ~73 ~123 ~178 dirt
setblock ~73 ~123 ~179 dirt
setblock ~73 ~123 ~180 dirt
setblock ~73 ~123 ~181 dirt
setblock ~73 ~123 ~182 grass_block
setblock ~73 ~123 ~183 grass_block
setblock ~73 ~123 ~184 grass_block
setblock ~73 ~123 ~185 grass_block
setblock ~73 ~123 ~186 grass_block
setblock ~73 ~123 ~187 grass_block
setblock ~73 ~123 ~188 grass_block
setblock ~73 ~123 ~189 grass_block
setblock ~73 ~123 ~190 grass_block
setblock ~73 ~123 ~191 grass_block
setblock ~73 ~123 ~192 dirt
setblock ~73 ~123 ~193 dirt
setblock ~73 ~123 ~194 dirt
setblock ~73 ~123 ~195 dirt
setblock ~73 ~123 ~196 dirt
setblock ~73 ~123 ~197 dirt
setblock ~73 ~123 ~198 dirt
setblock ~73 ~123 ~199 dirt
setblock ~73 ~124 ~1 short_grass
setblock ~73 ~124 ~4 grass_block
setblock ~73 ~124 ~5 grass_block
setblock ~73 ~124 ~6 dirt
setblock ~73 ~124 ~7 dirt
setblock ~73 ~124 ~8 dirt
setblock ~73 ~124 ~9 dirt
setblock ~73 ~124 ~10 dirt
setblock ~73 ~124 ~11 dirt
setblock ~73 ~124 ~12 dirt
setblock ~73 ~124 ~13 dirt
setblock ~73 ~124 ~14 dirt
setblock ~73 ~124 ~15 dirt
setblock ~73 ~124 ~16 dirt
setblock ~73 ~124 ~17 dirt
setblock ~73 ~124 ~18 dirt
setblock ~73 ~124 ~19 dirt
setblock ~73 ~124 ~20 dirt
setblock ~73 ~124 ~21 dirt
setblock ~73 ~124 ~22 dirt
setblock ~73 ~124 ~23 dirt
setblock ~73 ~124 ~24 dirt
setblock ~73 ~124 ~25 dirt
setblock ~73 ~124 ~26 grass_block
setblock ~73 ~124 ~27 grass_block
setblock ~73 ~124 ~28 grass_block
setblock ~73 ~124 ~29 grass_block
setblock ~73 ~124 ~30 grass_block
setblock ~73 ~124 ~31 grass_block
setblock ~73 ~124 ~32 grass_block
setblock ~73 ~124 ~33 grass_block
setblock ~73 ~124 ~34 grass_block
setblock ~73 ~124 ~35 grass_block
setblock ~73 ~124 ~36 grass_block
setblock ~73 ~124 ~37 grass_block
setblock ~73 ~124 ~38 grass_block
setblock ~73 ~124 ~39 grass_block
setblock ~73 ~124 ~40 grass_block
setblock ~73 ~124 ~41 grass_block
setblock ~73 ~124 ~42 grass_block
setblock ~73 ~124 ~43 grass_block
setblock ~73 ~124 ~44 grass_block
setblock ~73 ~124 ~45 grass_block
setblock ~73 ~124 ~46 grass_block
setblock ~73 ~124 ~47 grass_block
setblock ~73 ~124 ~50 short_grass
setblock ~73 ~124 ~52 grass_block
setblock ~73 ~124 ~53 grass_block
setblock ~73 ~124 ~54 grass_block
setblock ~73 ~124 ~55 grass_block
setblock ~73 ~124 ~56 grass_block
setblock ~73 ~124 ~57 dirt
setblock ~73 ~124 ~58 dirt
setblock ~73 ~124 ~59 dirt
setblock ~73 ~124 ~60 dirt
setblock ~73 ~124 ~61 dirt
setblock ~73 ~124 ~62 dirt
setblock ~73 ~124 ~63 dirt
setblock ~73 ~124 ~64 dirt
setblock ~73 ~124 ~65 dirt
setblock ~73 ~124 ~66 dirt
setblock ~73 ~124 ~67 dirt
setblock ~73 ~124 ~68 dirt
setblock ~73 ~124 ~69 dirt
setblock ~73 ~124 ~70 dirt
setblock ~73 ~124 ~71 dirt
setblock ~73 ~124 ~72 dirt
setblock ~73 ~124 ~73 dirt
setblock ~73 ~124 ~74 dirt
setblock ~73 ~124 ~75 dirt
setblock ~73 ~124 ~76 dirt
setblock ~73 ~124 ~77 dirt
setblock ~73 ~124 ~78 dirt
setblock ~73 ~124 ~79 grass_block
setblock ~73 ~124 ~80 grass_block
setblock ~73 ~124 ~81 grass_block
setblock ~73 ~124 ~82 grass_block
setblock ~73 ~124 ~83 grass_block
setblock ~73 ~124 ~84 grass_block
setblock ~73 ~124 ~85 grass_block
setblock ~73 ~124 ~86 grass_block
setblock ~73 ~124 ~87 grass_block
setblock ~73 ~124 ~88 grass_block
setblock ~73 ~124 ~89 grass_block
setblock ~73 ~124 ~90 grass_block
setblock ~73 ~124 ~91 grass_block
setblock ~73 ~124 ~92 dirt
setblock ~73 ~124 ~93 dirt
setblock ~73 ~124 ~94 dirt
setblock ~73 ~124 ~95 dirt
setblock ~73 ~124 ~96 dirt
setblock ~73 ~124 ~97 dirt
setblock ~73 ~124 ~98 dirt
setblock ~73 ~124 ~99 dirt
setblock ~73 ~124 ~100 dirt
setblock ~73 ~124 ~101 dirt
setblock ~73 ~124 ~102 dirt
setblock ~73 ~124 ~103 dirt
setblock ~73 ~124 ~104 dirt
setblock ~73 ~124 ~105 dirt
setblock ~73 ~124 ~106 dirt
setblock ~73 ~124 ~107 dirt
setblock ~73 ~124 ~108 dirt
setblock ~73 ~124 ~109 dirt
setblock ~73 ~124 ~110 grass_block
setblock ~73 ~124 ~111 dirt
setblock ~73 ~124 ~112 dirt
setblock ~73 ~124 ~113 dirt
setblock ~73 ~124 ~114 dirt
setblock ~73 ~124 ~115 dirt
setblock ~73 ~124 ~116 dirt
setblock ~73 ~124 ~117 dirt
setblock ~73 ~124 ~118 dirt
setblock ~73 ~124 ~119 dirt
setblock ~73 ~124 ~120 dirt
setblock ~73 ~124 ~121 dirt
setblock ~73 ~124 ~122 dirt
setblock ~73 ~124 ~123 dirt
setblock ~73 ~124 ~124 dirt
setblock ~73 ~124 ~125 dirt
setblock ~73 ~124 ~126 grass_block
setblock ~73 ~124 ~127 grass_block
setblock ~73 ~124 ~129 short_grass
setblock ~73 ~124 ~133 grass_block
setblock ~73 ~124 ~134 grass_block
setblock ~73 ~124 ~135 grass_block
setblock ~73 ~124 ~136 grass_block
setblock ~73 ~124 ~137 dirt
setblock ~73 ~124 ~138 dirt
setblock ~73 ~124 ~139 dirt
setblock ~73 ~124 ~140 dirt
setblock ~73 ~124 ~141 dirt
setblock ~73 ~124 ~142 dirt
setblock ~73 ~124 ~143 dirt
setblock ~73 ~124 ~144 grass_block
setblock ~73 ~124 ~145 grass_block
setblock ~73 ~124 ~146 grass_block
setblock ~73 ~124 ~147 grass_block
setblock ~73 ~124 ~148 grass_block
setblock ~73 ~124 ~149 grass_block
setblock ~73 ~124 ~150 short_grass
setblock ~73 ~124 ~151 grass_block
setblock ~73 ~124 ~152 grass_block
setblock ~73 ~124 ~153 grass_block
setblock ~73 ~124 ~154 grass_block
setblock ~73 ~124 ~155 grass_block
setblock ~73 ~124 ~156 dirt
setblock ~73 ~124 ~157 dirt
setblock ~73 ~124 ~158 dirt
setblock ~73 ~124 ~159 dirt
setblock ~73 ~124 ~160 dirt
setblock ~73 ~124 ~161 dirt
setblock ~73 ~124 ~162 dirt
setblock ~73 ~124 ~163 dirt
setblock ~73 ~124 ~164 dirt
setblock ~73 ~124 ~165 dirt
setblock ~73 ~124 ~166 dirt
setblock ~73 ~124 ~167 dirt
setblock ~73 ~124 ~168 dirt
setblock ~73 ~124 ~169 dirt
setblock ~73 ~124 ~170 dirt
setblock ~73 ~124 ~171 dirt
setblock ~73 ~124 ~172 dirt
setblock ~73 ~124 ~173 dirt
setblock ~73 ~124 ~174 dirt
setblock ~73 ~124 ~175 dirt
setblock ~73 ~124 ~176 dirt
setblock ~73 ~124 ~177 dirt
setblock ~73 ~124 ~178 grass_block
setblock ~73 ~124 ~179 grass_block
setblock ~73 ~124 ~180 grass_block
setblock ~73 ~124 ~181 grass_block
setblock ~73 ~124 ~184 short_grass
setblock ~73 ~124 ~185 short_grass
setblock ~73 ~124 ~186 fern
setblock ~73 ~124 ~192 grass_block
setblock ~73 ~124 ~193 grass_block
setblock ~73 ~124 ~194 grass_block
setblock ~73 ~124 ~195 grass_block
setblock ~73 ~124 ~196 grass_block
setblock ~73 ~124 ~197 grass_block
setblock ~73 ~124 ~198 dirt
setblock ~73 ~124 ~199 dirt
setblock ~73 ~125 ~4 poppy
setblock ~73 ~125 ~6 grass_block
setblock ~73 ~125 ~7 grass_block
setblock ~73 ~125 ~8 grass_block
setblock ~73 ~125 ~9 dirt
setblock ~73 ~125 ~10 dirt
setblock ~73 ~125 ~11 dirt
setblock ~73 ~125 ~12 dirt
setblock ~73 ~125 ~13 dirt
setblock ~73 ~125 ~14 dirt
setblock ~73 ~125 ~15 dirt
setblock ~73 ~125 ~16 dirt
setblock ~73 ~125 ~17 dirt
setblock ~73 ~125 ~18 dirt
setblock ~73 ~125 ~19 grass_block
setblock ~73 ~125 ~20 grass_block
setblock ~73 ~125 ~21 grass_block
setblock ~73 ~125 ~22 grass_block
setblock ~73 ~125 ~23 grass_block
setblock ~73 ~125 ~24 grass_block
setblock ~73 ~125 ~25 grass_block
setblock ~73 ~125 ~26 short_grass
setblock ~73 ~125 ~29 short_grass
setblock ~73 ~125 ~33 short_grass
setblock ~73 ~125 ~34 short_grass
setblock ~73 ~125 ~35 short_grass
setblock ~73 ~125 ~36 short_grass
setblock ~73 ~125 ~38 short_grass
setblock ~73 ~125 ~39 poppy
setblock ~73 ~125 ~41 poppy
setblock ~73 ~125 ~42 poppy
setblock ~73 ~125 ~46 short_grass
setblock ~73 ~125 ~52 short_grass
setblock ~73 ~125 ~53 short_grass
setblock ~73 ~125 ~57 grass_block
setblock ~73 ~125 ~58 grass_block
setblock ~73 ~125 ~59 grass_block
setblock ~73 ~125 ~60 grass_block
setblock ~73 ~125 ~61 grass_block
setblock ~73 ~125 ~62 grass_block
setblock ~73 ~125 ~63 grass_block
setblock ~73 ~125 ~64 grass_block
setblock ~73 ~125 ~65 dirt
setblock ~73 ~125 ~66 dirt
setblock ~73 ~125 ~67 dirt
setblock ~73 ~125 ~68 dirt
setblock ~73 ~125 ~69 dirt
setblock ~73 ~125 ~70 dirt
setblock ~73 ~125 ~71 grass_block
setblock ~73 ~125 ~72 grass_block
setblock ~73 ~125 ~73 grass_block
setblock ~73 ~125 ~74 grass_block
setblock ~73 ~125 ~75 grass_block
setblock ~73 ~125 ~76 grass_block
setblock ~73 ~125 ~77 grass_block
setblock ~73 ~125 ~78 grass_block
setblock ~73 ~125 ~79 short_grass
setblock ~73 ~125 ~80 short_grass
setblock ~73 ~125 ~83 short_grass
setblock ~73 ~125 ~87 short_grass
setblock ~73 ~125 ~90 short_grass
setblock ~73 ~125 ~92 grass_block
setblock ~73 ~125 ~93 grass_block
setblock ~73 ~125 ~94 grass_block
setblock ~73 ~125 ~95 grass_block
setblock ~73 ~125 ~96 grass_block
setblock ~73 ~125 ~97 grass_block
setblock ~73 ~125 ~98 grass_block
setblock ~73 ~125 ~99 dirt
setblock ~73 ~125 ~100 dirt
setblock ~73 ~125 ~101 grass_block
setblock ~73 ~125 ~102 grass_block
setblock ~73 ~125 ~103 grass_block
setblock ~73 ~125 ~104 grass_block
setblock ~73 ~125 ~105 grass_block
setblock ~73 ~125 ~106 grass_block
setblock ~73 ~125 ~107 grass_block
setblock ~73 ~125 ~108 grass_block
setblock ~73 ~125 ~109 grass_block
setblock ~73 ~125 ~111 grass_block
setblock ~73 ~125 ~112 grass_block
setblock ~73 ~125 ~113 grass_block
setblock ~73 ~125 ~114 dirt
setblock ~73 ~125 ~115 dirt
setblock ~73 ~125 ~116 dirt
setblock ~73 ~125 ~117 dirt
setblock ~73 ~125 ~118 dirt
setblock ~73 ~125 ~119 dirt
setblock ~73 ~125 ~120 dirt
setblock ~73 ~125 ~121 dirt
setblock ~73 ~125 ~122 dirt
setblock ~73 ~125 ~123 dirt
setblock ~73 ~125 ~124 grass_block
setblock ~73 ~125 ~125 grass_block
setblock ~73 ~125 ~137 grass_block
setblock ~73 ~125 ~138 grass_block
setblock ~73 ~125 ~139 grass_block
setblock ~73 ~125 ~140 grass_block
setblock ~73 ~125 ~141 grass_block
setblock ~73 ~125 ~142 grass_block
setblock ~73 ~125 ~143 grass_block
setblock ~73 ~125 ~144 poppy
setblock ~73 ~125 ~145 short_grass
setblock ~73 ~125 ~146 short_grass
setblock ~73 ~125 ~148 short_grass
setblock ~73 ~125 ~149 short_grass
setblock ~73 ~125 ~152 short_grass
setblock ~73 ~125 ~153 fern
setblock ~73 ~125 ~156 grass_block
setblock ~73 ~125 ~157 grass_block
setblock ~73 ~125 ~158 grass_block
setblock ~73 ~125 ~159 grass_block
setblock ~73 ~125 ~160 grass_block
setblock ~73 ~125 ~161 dirt
setblock ~73 ~125 ~162 dirt
setblock ~73 ~125 ~163 dirt
setblock ~73 ~125 ~164 dirt
setblock ~73 ~125 ~165 dirt
setblock ~73 ~125 ~166 dirt
setblock ~73 ~125 ~167 dirt
setblock ~73 ~125 ~168 dirt
setblock ~73 ~125 ~169 dirt
setblock ~73 ~125 ~170 dirt
setblock ~73 ~125 ~171 dirt
setblock ~73 ~125 ~172 dirt
setblock ~73 ~125 ~173 dirt
setblock ~73 ~125 ~174 dirt
setblock ~73 ~125 ~175 dirt
setblock ~73 ~125 ~176 grass_block
setblock ~73 ~125 ~177 grass_block
setblock ~73 ~125 ~192 short_grass
setblock ~73 ~125 ~193 poppy
setblock ~73 ~125 ~198 grass_block
setblock ~73 ~125 ~199 grass_block
setblock ~73 ~126 ~7 short_grass
setblock ~73 ~126 ~8 short_grass
setblock ~73 ~126 ~9 grass_block
setblock ~73 ~126 ~10 grass_block
setblock ~73 ~126 ~11 grass_block
setblock ~73 ~126 ~12 grass_block
setblock ~73 ~126 ~13 grass_block
setblock ~73 ~126 ~14 grass_block
setblock ~73 ~126 ~15 grass_block
setblock ~73 ~126 ~16 grass_block
setblock ~73 ~126 ~17 grass_block
setblock ~73 ~126 ~18 grass_block
setblock ~73 ~126 ~25 poppy
setblock ~73 ~126 ~61 fern
setblock ~73 ~126 ~64 poppy
setblock ~73 ~126 ~65 grass_block
setblock ~73 ~126 ~66 grass_block
setblock ~73 ~126 ~67 grass_block
setblock ~73 ~126 ~68 grass_block
setblock ~73 ~126 ~69 grass_block
setblock ~73 ~126 ~70 grass_block
setblock ~73 ~126 ~78 short_grass
setblock ~73 ~126 ~94 short_grass
setblock ~73 ~126 ~98 poppy
setblock ~73 ~126 ~99 grass_block
setblock ~73 ~126 ~100 grass_block
setblock ~73 ~126 ~104 poppy
setblock ~73 ~126 ~106 short_grass
setblock ~73 ~126 ~107 fern
setblock ~73 ~126 ~111 short_grass
setblock ~73 ~126 ~112 short_grass
setblock ~73 ~126 ~114 grass_block
setblock ~73 ~126 ~115 grass_block
setblock ~73 ~126 ~116 grass_block
setblock ~73 ~126 ~117 dirt
setblock ~73 ~126 ~118 dirt
setblock ~73 ~126 ~119 dirt
setblock ~73 ~126 ~120 dirt
setblock ~73 ~126 ~121 dirt
setblock ~73 ~126 ~122 grass_block
setblock ~73 ~126 ~123 grass_block
setblock ~73 ~126 ~142 short_grass
setblock ~73 ~126 ~160 poppy
setblock ~73 ~126 ~161 grass_block
setblock ~73 ~126 ~162 grass_block
setblock ~73 ~126 ~163 grass_block
setblock ~73 ~126 ~164 grass_block
setblock ~73 ~126 ~165 dirt
setblock ~73 ~126 ~166 dirt
setblock ~73 ~126 ~167 dirt
setblock ~73 ~126 ~168 dirt
setblock ~73 ~126 ~169 dirt
setblock ~73 ~126 ~170 dirt
setblock ~73 ~126 ~171 dirt
setblock ~73 ~126 ~172 dirt
setblock ~73 ~126 ~173 grass_block
setblock ~73 ~126 ~174 grass_block
setblock ~73 ~126 ~175 grass_block
setblock ~73 ~126 ~177 fern
setblock ~73 ~126 ~199 short_grass
setblock ~73 ~127 ~9 short_grass
setblock ~73 ~127 ~117 grass_block
setblock ~73 ~127 ~118 grass_block
setblock ~73 ~127 ~119 grass_block
setblock ~73 ~127 ~120 grass_block
setblock ~73 ~127 ~121 grass_block
setblock ~73 ~127 ~122 poppy
setblock ~73 ~127 ~123 short_grass
setblock ~73 ~127 ~161 short_grass
setblock ~73 ~127 ~162 short_grass
setblock ~73 ~127 ~163 short_grass
setblock ~73 ~127 ~165 grass_block
setblock ~73 ~127 ~166 grass_block
setblock ~73 ~127 ~167 grass_block
setblock ~73 ~127 ~168 grass_block
setblock ~73 ~127 ~169 dirt
setblock ~73 ~127 ~170 dirt
setblock ~73 ~127 ~171 grass_block
setblock ~73 ~127 ~172 grass_block
setblock ~73 ~127 ~174 short_grass
setblock ~73 ~128 ~117 short_grass
setblock ~73 ~128 ~166 short_grass
setblock ~73 ~128 ~169 grass_block
setblock ~73 ~128 ~170 grass_block
setblock ~73 ~129 ~169 short_grass
setblock ~74 ~122 ~0 grass_block
setblock ~74 ~122 ~1 dirt
setblock ~74 ~122 ~2 dirt
setblock ~74 ~122 ~3 dirt
setblock ~74 ~122 ~4 dirt
setblock ~74 ~122 ~5 dirt
setblock ~74 ~122 ~6 dirt
setblock ~74 ~122 ~7 dirt
setblock ~74 ~122 ~8 dirt
setblock ~74 ~122 ~9 dirt
setblock ~74 ~122 ~10 dirt
setblock ~74 ~122 ~11 dirt
setblock ~74 ~122 ~12 dirt
setblock ~74 ~122 ~13 dirt
setblock ~74 ~122 ~14 dirt
setblock ~74 ~122 ~15 dirt
setblock ~74 ~122 ~16 dirt
setblock ~74 ~122 ~17 dirt
setblock ~74 ~122 ~18 dirt
setblock ~74 ~122 ~19 dirt
setblock ~74 ~122 ~20 dirt
setblock ~74 ~122 ~21 dirt
setblock ~74 ~122 ~22 dirt
setblock ~74 ~122 ~23 dirt
setblock ~74 ~122 ~24 dirt
setblock ~74 ~122 ~25 dirt
setblock ~74 ~122 ~26 dirt
setblock ~74 ~122 ~27 dirt
setblock ~74 ~122 ~28 dirt
setblock ~74 ~122 ~29 dirt
setblock ~74 ~122 ~30 dirt
setblock ~74 ~122 ~31 dirt
setblock ~74 ~122 ~32 dirt
setblock ~74 ~122 ~33 dirt
setblock ~74 ~122 ~34 dirt
setblock ~74 ~122 ~35 dirt
setblock ~74 ~122 ~36 dirt
setblock ~74 ~122 ~37 dirt
setblock ~74 ~122 ~38 dirt
setblock ~74 ~122 ~39 dirt
setblock ~74 ~122 ~40 dirt
setblock ~74 ~122 ~41 dirt
setblock ~74 ~122 ~42 dirt
setblock ~74 ~122 ~43 dirt
setblock ~74 ~122 ~44 dirt
setblock ~74 ~122 ~45 dirt
setblock ~74 ~122 ~46 dirt
setblock ~74 ~122 ~47 dirt
setblock ~74 ~122 ~48 dirt
setblock ~74 ~122 ~49 dirt
setblock ~74 ~122 ~50 dirt
setblock ~74 ~122 ~51 dirt
setblock ~74 ~122 ~52 dirt
setblock ~74 ~122 ~53 dirt
setblock ~74 ~122 ~54 dirt
setblock ~74 ~122 ~55 dirt
setblock ~74 ~122 ~56 dirt
setblock ~74 ~122 ~57 dirt
setblock ~74 ~122 ~58 dirt
setblock ~74 ~122 ~59 dirt
setblock ~74 ~122 ~60 dirt
setblock ~74 ~122 ~61 dirt
setblock ~74 ~122 ~62 dirt
setblock ~74 ~122 ~63 dirt
setblock ~74 ~122 ~64 dirt
setblock ~74 ~122 ~65 dirt
setblock ~74 ~122 ~66 dirt
setblock ~74 ~122 ~67 dirt
setblock ~74 ~122 ~68 dirt
setblock ~74 ~122 ~69 dirt
setblock ~74 ~122 ~70 dirt
setblock ~74 ~122 ~71 dirt
setblock ~74 ~122 ~72 dirt
setblock ~74 ~122 ~73 dirt
setblock ~74 ~122 ~74 dirt
setblock ~74 ~122 ~75 dirt
setblock ~74 ~122 ~76 dirt
setblock ~74 ~122 ~77 dirt
setblock ~74 ~122 ~78 dirt
setblock ~74 ~122 ~79 dirt
setblock ~74 ~122 ~80 dirt
setblock ~74 ~122 ~81 dirt
setblock ~74 ~122 ~82 dirt
setblock ~74 ~122 ~83 dirt
setblock ~74 ~122 ~84 dirt
setblock ~74 ~122 ~85 dirt
setblock ~74 ~122 ~86 dirt
setblock ~74 ~122 ~87 dirt
setblock ~74 ~122 ~88 dirt
setblock ~74 ~122 ~89 dirt
setblock ~74 ~122 ~90 dirt
setblock ~74 ~122 ~91 dirt
setblock ~74 ~122 ~92 dirt
setblock ~74 ~122 ~93 dirt
setblock ~74 ~122 ~94 dirt
setblock ~74 ~122 ~95 dirt
setblock ~74 ~122 ~96 dirt
setblock ~74 ~122 ~97 dirt
setblock ~74 ~122 ~98 dirt
setblock ~74 ~122 ~99 dirt
setblock ~74 ~122 ~100 dirt
setblock ~74 ~122 ~101 dirt
setblock ~74 ~122 ~102 dirt
setblock ~74 ~122 ~103 dirt
setblock ~74 ~122 ~104 dirt
setblock ~74 ~122 ~105 dirt
setblock ~74 ~122 ~106 dirt
setblock ~74 ~122 ~107 dirt
setblock ~74 ~122 ~108 dirt
setblock ~74 ~122 ~109 dirt
setblock ~74 ~122 ~110 dirt
setblock ~74 ~122 ~111 dirt
setblock ~74 ~122 ~112 dirt
setblock ~74 ~122 ~113 dirt
setblock ~74 ~122 ~114 dirt
setblock ~74 ~122 ~115 dirt
setblock ~74 ~122 ~116 dirt
setblock ~74 ~122 ~117 dirt
setblock ~74 ~122 ~118 dirt
setblock ~74 ~122 ~119 dirt
setblock ~74 ~122 ~120 dirt
setblock ~74 ~122 ~121 dirt
setblock ~74 ~122 ~122 dirt
setblock ~74 ~122 ~123 dirt
setblock ~74 ~122 ~124 dirt
setblock ~74 ~122 ~125 dirt
setblock ~74 ~122 ~126 dirt
setblock ~74 ~122 ~127 dirt
setblock ~74 ~122 ~128 dirt
setblock ~74 ~122 ~129 dirt
setblock ~74 ~122 ~130 grass_block
setblock ~74 ~122 ~131 dirt
setblock ~74 ~122 ~132 dirt
setblock ~74 ~122 ~133 dirt
setblock ~74 ~122 ~134 dirt
setblock ~74 ~122 ~135 dirt
setblock ~74 ~122 ~136 dirt
setblock ~74 ~122 ~137 dirt
setblock ~74 ~122 ~138 dirt
setblock ~74 ~122 ~139 dirt
setblock ~74 ~122 ~140 dirt
setblock ~74 ~122 ~141 dirt
setblock ~74 ~122 ~142 dirt
setblock ~74 ~122 ~143 dirt
setblock ~74 ~122 ~144 dirt
setblock ~74 ~122 ~145 dirt
setblock ~74 ~122 ~146 dirt
setblock ~74 ~122 ~147 dirt
setblock ~74 ~122 ~148 dirt
setblock ~74 ~122 ~149 dirt
setblock ~74 ~122 ~150 dirt
setblock ~74 ~122 ~151 dirt
setblock ~74 ~122 ~152 dirt
setblock ~74 ~122 ~153 dirt
setblock ~74 ~122 ~154 dirt
setblock ~74 ~122 ~155 dirt
setblock ~74 ~122 ~156 dirt
setblock ~74 ~122 ~157 dirt
setblock ~74 ~122 ~158 dirt
setblock ~74 ~122 ~159 dirt
setblock ~74 ~122 ~160 dirt
setblock ~74 ~122 ~161 dirt
setblock ~74 ~122 ~162 dirt
setblock ~74 ~122 ~163 dirt
setblock ~74 ~122 ~164 dirt
setblock ~74 ~122 ~165 dirt
setblock ~74 ~122 ~166 dirt
setblock ~74 ~122 ~167 dirt
setblock ~74 ~122 ~168 dirt
setblock ~74 ~122 ~169 dirt
setblock ~74 ~122 ~170 dirt
setblock ~74 ~122 ~171 dirt
setblock ~74 ~122 ~172 dirt
setblock ~74 ~122 ~173 dirt
setblock ~74 ~122 ~174 dirt
setblock ~74 ~122 ~175 dirt
setblock ~74 ~122 ~176 dirt
setblock ~74 ~122 ~177 dirt
setblock ~74 ~122 ~178 dirt
setblock ~74 ~122 ~179 dirt
setblock ~74 ~122 ~180 dirt
setblock ~74 ~122 ~181 dirt
setblock ~74 ~122 ~182 dirt
setblock ~74 ~122 ~183 dirt
setblock ~74 ~122 ~184 dirt
setblock ~74 ~122 ~185 dirt
setblock ~74 ~122 ~186 dirt
setblock ~74 ~122 ~187 dirt
setblock ~74 ~122 ~188 dirt
setblock ~74 ~122 ~189 dirt
setblock ~74 ~122 ~190 dirt
setblock ~74 ~122 ~191 dirt
setblock ~74 ~122 ~192 dirt
setblock ~74 ~122 ~193 dirt
setblock ~74 ~122 ~194 dirt
setblock ~74 ~122 ~195 dirt
setblock ~74 ~122 ~196 dirt
setblock ~74 ~122 ~197 dirt
setblock ~74 ~122 ~198 dirt
setblock ~74 ~122 ~199 dirt
setblock ~74 ~123 ~0 short_grass
setblock ~74 ~123 ~1 grass_block
setblock ~74 ~123 ~2 grass_block
setblock ~74 ~123 ~3 grass_block
setblock ~74 ~123 ~4 dirt
setblock ~74 ~123 ~5 dirt
setblock ~74 ~123 ~6 dirt
setblock ~74 ~123 ~7 dirt
setblock ~74 ~123 ~8 dirt
setblock ~74 ~123 ~9 dirt
setblock ~74 ~123 ~10 dirt
setblock ~74 ~123 ~11 dirt
setblock ~74 ~123 ~12 dirt
setblock ~74 ~123 ~13 dirt
setblock ~74 ~123 ~14 dirt
setblock ~74 ~123 ~15 dirt
setblock ~74 ~123 ~16 dirt
setblock ~74 ~123 ~17 dirt
setblock ~74 ~123 ~18 dirt
setblock ~74 ~123 ~19 dirt
setblock ~74 ~123 ~20 dirt
setblock ~74 ~123 ~21 dirt
setblock ~74 ~123 ~22 dirt
setblock ~74 ~123 ~23 dirt
setblock ~74 ~123 ~24 dirt
setblock ~74 ~123 ~25 dirt
setblock ~74 ~123 ~26 dirt
setblock ~74 ~123 ~27 dirt
setblock ~74 ~123 ~28 dirt
setblock ~74 ~123 ~29 dirt
setblock ~74 ~123 ~30 dirt
setblock ~74 ~123 ~31 dirt
setblock ~74 ~123 ~32 dirt
setblock ~74 ~123 ~33 dirt
setblock ~74 ~123 ~34 dirt
setblock ~74 ~123 ~35 dirt
setblock ~74 ~123 ~36 dirt
setblock ~74 ~123 ~37 dirt
setblock ~74 ~123 ~38 dirt
setblock ~74 ~123 ~39 dirt
setblock ~74 ~123 ~40 dirt
setblock ~74 ~123 ~41 dirt
setblock ~74 ~123 ~42 dirt
setblock ~74 ~123 ~43 dirt
setblock ~74 ~123 ~44 dirt
setblock ~74 ~123 ~45 dirt
setblock ~74 ~123 ~46 dirt
setblock ~74 ~123 ~47 dirt
setblock ~74 ~123 ~48 grass_block
setblock ~74 ~123 ~49 grass_block
setblock ~74 ~123 ~50 grass_block
setblock ~74 ~123 ~51 grass_block
setblock ~74 ~123 ~52 grass_block
setblock ~74 ~123 ~53 dirt
setblock ~74 ~123 ~54 dirt
setblock ~74 ~123 ~55 dirt
setblock ~74 ~123 ~56 dirt
setblock ~74 ~123 ~57 dirt
setblock ~74 ~123 ~58 dirt
setblock ~74 ~123 ~59 dirt
setblock ~74 ~123 ~60 dirt
setblock ~74 ~123 ~61 dirt
setblock ~74 ~123 ~62 dirt
setblock ~74 ~123 ~63 dirt
setblock ~74 ~123 ~64 dirt
setblock ~74 ~123 ~65 dirt
setblock ~74 ~123 ~66 dirt
setblock ~74 ~123 ~67 dirt
setblock ~74 ~123 ~68 dirt
setblock ~74 ~123 ~69 dirt
setblock ~74 ~123 ~70 dirt
setblock ~74 ~123 ~71 dirt
setblock ~74 ~123 ~72 dirt
setblock ~74 ~123 ~73 dirt
setblock ~74 ~123 ~74 dirt
setblock ~74 ~123 ~75 dirt
setblock ~74 ~123 ~76 dirt
setblock ~74 ~123 ~77 dirt
setblock ~74 ~123 ~78 dirt
setblock ~74 ~123 ~79 dirt
setblock ~74 ~123 ~80 dirt
setblock ~74 ~123 ~81 dirt
setblock ~74 ~123 ~82 dirt
setblock ~74 ~123 ~83 dirt
setblock ~74 ~123 ~84 dirt
setblock ~74 ~123 ~85 dirt
setblock ~74 ~123 ~86 dirt
setblock ~74 ~123 ~87 dirt
setblock ~74 ~123 ~88 dirt
setblock ~74 ~123 ~89 dirt
setblock ~74 ~123 ~90 dirt
setblock ~74 ~123 ~91 dirt
setblock ~74 ~123 ~92 dirt
setblock ~74 ~123 ~93 dirt
setblock ~74 ~123 ~94 dirt
setblock ~74 ~123 ~95 dirt
setblock ~74 ~123 ~96 dirt
setblock ~74 ~123 ~97 dirt
setblock ~74 ~123 ~98 dirt
setblock ~74 ~123 ~99 dirt
setblock ~74 ~123 ~100 dirt
setblock ~74 ~123 ~101 dirt
setblock ~74 ~123 ~102 dirt
setblock ~74 ~123 ~103 dirt
setblock ~74 ~123 ~104 dirt
setblock ~74 ~123 ~105 dirt
setblock ~74 ~123 ~106 dirt
setblock ~74 ~123 ~107 dirt
setblock ~74 ~123 ~108 dirt
setblock ~74 ~123 ~109 dirt
setblock ~74 ~123 ~110 dirt
setblock ~74 ~123 ~111 dirt
setblock ~74 ~123 ~112 dirt
setblock ~74 ~123 ~113 dirt
setblock ~74 ~123 ~114 dirt
setblock ~74 ~123 ~115 dirt
setblock ~74 ~123 ~116 dirt
setblock ~74 ~123 ~117 dirt
setblock ~74 ~123 ~118 dirt
setblock ~74 ~123 ~119 dirt
setblock ~74 ~123 ~120 dirt
setblock ~74 ~123 ~121 dirt
setblock ~74 ~123 ~122 dirt
setblock ~74 ~123 ~123 dirt
setblock ~74 ~123 ~124 dirt
setblock ~74 ~123 ~125 dirt
setblock ~74 ~123 ~126 dirt
setblock ~74 ~123 ~127 dirt
setblock ~74 ~123 ~128 grass_block
setblock ~74 ~123 ~129 grass_block
setblock ~74 ~123 ~131 grass_block
setblock ~74 ~123 ~132 grass_block
setblock ~74 ~123 ~133 dirt
setblock ~74 ~123 ~134 dirt
setblock ~74 ~123 ~135 dirt
setblock ~74 ~123 ~136 dirt
setblock ~74 ~123 ~137 dirt
setblock ~74 ~123 ~138 dirt
setblock ~74 ~123 ~139 dirt
setblock ~74 ~123 ~140 dirt
setblock ~74 ~123 ~141 dirt
setblock ~74 ~123 ~142 dirt
setblock ~74 ~123 ~143 dirt
setblock ~74 ~123 ~144 dirt
setblock ~74 ~123 ~145 dirt
setblock ~74 ~123 ~146 dirt
setblock ~74 ~123 ~147 dirt
setblock ~74 ~123 ~148 dirt
setblock ~74 ~123 ~149 dirt
setblock ~74 ~123 ~150 grass_block
setblock ~74 ~123 ~151 dirt
setblock ~74 ~123 ~152 dirt
setblock ~74 ~123 ~153 dirt
setblock ~74 ~123 ~154 dirt
setblock ~74 ~123 ~155 dirt
setblock ~74 ~123 ~156 dirt
setblock ~74 ~123 ~157 dirt
setblock ~74 ~123 ~158 dirt
setblock ~74 ~123 ~159 dirt
setblock ~74 ~123 ~160 dirt
setblock ~74 ~123 ~161 dirt
setblock ~74 ~123 ~162 dirt
setblock ~74 ~123 ~163 dirt
setblock ~74 ~123 ~164 dirt
setblock ~74 ~123 ~165 dirt
setblock ~74 ~123 ~166 dirt
setblock ~74 ~123 ~167 dirt
setblock ~74 ~123 ~168 dirt
setblock ~74 ~123 ~169 dirt
setblock ~74 ~123 ~170 dirt
setblock ~74 ~123 ~171 dirt
setblock ~74 ~123 ~172 dirt
setblock ~74 ~123 ~173 dirt
setblock ~74 ~123 ~174 dirt
setblock ~74 ~123 ~175 dirt
setblock ~74 ~123 ~176 dirt
setblock ~74 ~123 ~177 dirt
setblock ~74 ~123 ~178 dirt
setblock ~74 ~123 ~179 dirt
setblock ~74 ~123 ~180 dirt
setblock ~74 ~123 ~181 dirt
setblock ~74 ~123 ~182 dirt
setblock ~74 ~123 ~183 dirt
setblock ~74 ~123 ~184 dirt
setblock ~74 ~123 ~185 grass_block
setblock ~74 ~123 ~186 grass_block
setblock ~74 ~123 ~187 grass_block
setblock ~74 ~123 ~188 grass_block
setblock ~74 ~123 ~189 grass_block
setblock ~74 ~123 ~190 grass_block
setblock ~74 ~123 ~191 grass_block
setblock ~74 ~123 ~192 dirt
setblock ~74 ~123 ~193 dirt
setblock ~74 ~123 ~194 dirt
setblock ~74 ~123 ~195 dirt
setblock ~74 ~123 ~196 dirt
setblock ~74 ~123 ~197 dirt
setblock ~74 ~123 ~198 dirt
setblock ~74 ~123 ~199 dirt
setblock ~74 ~124 ~1 short_grass
setblock ~74 ~124 ~3 short_grass
setblock ~74 ~124 ~4 grass_block
setblock ~74 ~124 ~5 grass_block
setblock ~74 ~124 ~6 dirt
setblock ~74 ~124 ~7 dirt
setblock ~74 ~124 ~8 dirt
setblock ~74 ~124 ~9 dirt
setblock ~74 ~124 ~10 dirt
setblock ~74 ~124 ~11 dirt
setblock ~74 ~124 ~12 dirt
setblock ~74 ~124 ~13 dirt
setblock ~74 ~124 ~14 dirt
setblock ~74 ~124 ~15 dirt
setblock ~74 ~124 ~16 dirt
setblock ~74 ~124 ~17 dirt
setblock ~74 ~124 ~18 dirt
setblock ~74 ~124 ~19 dirt
setblock ~74 ~124 ~20 dirt
setblock ~74 ~124 ~21 dirt
setblock ~74 ~124 ~22 dirt
setblock ~74 ~124 ~23 dirt
setblock ~74 ~124 ~24 dirt
setblock ~74 ~124 ~25 dirt
setblock ~74 ~124 ~26 grass_block
setblock ~74 ~124 ~27 grass_block
setblock ~74 ~124 ~28 grass_block
setblock ~74 ~124 ~29 grass_block
setblock ~74 ~124 ~30 grass_block
setblock ~74 ~124 ~31 grass_block
setblock ~74 ~124 ~32 grass_block
setblock ~74 ~124 ~33 grass_block
setblock ~74 ~124 ~34 grass_block
setblock ~74 ~124 ~35 grass_block
setblock ~74 ~124 ~36 grass_block
setblock ~74 ~124 ~37 grass_block
setblock ~74 ~124 ~38 grass_block
setblock ~74 ~124 ~39 grass_block
setblock ~74 ~124 ~40 grass_block
setblock ~74 ~124 ~41 grass_block
setblock ~74 ~124 ~42 grass_block
setblock ~74 ~124 ~43 grass_block
setblock ~74 ~124 ~44 grass_block
setblock ~74 ~124 ~45 grass_block
setblock ~74 ~124 ~46 grass_block
setblock ~74 ~124 ~47 grass_block
setblock ~74 ~124 ~52 short_grass
setblock ~74 ~124 ~53 grass_block
setblock ~74 ~124 ~54 grass_block
setblock ~74 ~124 ~55 grass_block
setblock ~74 ~124 ~56 grass_block
setblock ~74 ~124 ~57 grass_block
setblock ~74 ~124 ~58 grass_block
setblock ~74 ~124 ~59 dirt
setblock ~74 ~124 ~60 dirt
setblock ~74 ~124 ~61 dirt
setblock ~74 ~124 ~62 dirt
setblock ~74 ~124 ~63 dirt
setblock ~74 ~124 ~64 dirt
setblock ~74 ~124 ~65 dirt
setblock ~74 ~124 ~66 dirt
setblock ~74 ~124 ~67 dirt
setblock ~74 ~124 ~68 dirt
setblock ~74 ~124 ~69 dirt
setblock ~74 ~124 ~70 dirt
setblock ~74 ~124 ~71 dirt
setblock ~74 ~124 ~72 dirt
setblock ~74 ~124 ~73 dirt
setblock ~74 ~124 ~74 dirt
setblock ~74 ~124 ~75 dirt
setblock ~74 ~124 ~76 dirt
setblock ~74 ~124 ~77 dirt
setblock ~74 ~124 ~78 dirt
setblock ~74 ~124 ~79 dirt
setblock ~74 ~124 ~80 grass_block
setblock ~74 ~124 ~81 grass_block
setblock ~74 ~124 ~82 dirt
setblock ~74 ~124 ~83 dirt
setblock ~74 ~124 ~84 dirt
setblock ~74 ~124 ~85 dirt
setblock ~74 ~124 ~86 dirt
setblock ~74 ~124 ~87 dirt
setblock ~74 ~124 ~88 dirt
setblock ~74 ~124 ~89 dirt
setblock ~74 ~124 ~90 dirt
setblock ~74 ~124 ~91 dirt
setblock ~74 ~124 ~92 dirt
setblock ~74 ~124 ~93 dirt
setblock ~74 ~124 ~94 dirt
setblock ~74 ~124 ~95 dirt
setblock ~74 ~124 ~96 dirt
setblock ~74 ~124 ~97 dirt
setblock ~74 ~124 ~98 dirt
setblock ~74 ~124 ~99 dirt
setblock ~74 ~124 ~100 dirt
setblock ~74 ~124 ~101 dirt
setblock ~74 ~124 ~102 dirt
setblock ~74 ~124 ~103 dirt
setblock ~74 ~124 ~104 dirt
setblock ~74 ~124 ~105 dirt
setblock ~74 ~124 ~106 dirt
setblock ~74 ~124 ~107 dirt
setblock ~74 ~124 ~108 dirt
setblock ~74 ~124 ~109 dirt
setblock ~74 ~124 ~110 dirt
setblock ~74 ~124 ~111 dirt
setblock ~74 ~124 ~112 dirt
setblock ~74 ~124 ~113 dirt
setblock ~74 ~124 ~114 dirt
setblock ~74 ~124 ~115 dirt
setblock ~74 ~124 ~116 dirt
setblock ~74 ~124 ~117 dirt
setblock ~74 ~124 ~118 dirt
setblock ~74 ~124 ~119 dirt
setblock ~74 ~124 ~120 dirt
setblock ~74 ~124 ~121 dirt
setblock ~74 ~124 ~122 dirt
setblock ~74 ~124 ~123 dirt
setblock ~74 ~124 ~124 dirt
setblock ~74 ~124 ~125 dirt
setblock ~74 ~124 ~126 grass_block
setblock ~74 ~124 ~127 grass_block
setblock ~74 ~124 ~129 short_grass
setblock ~74 ~124 ~133 grass_block
setblock ~74 ~124 ~134 grass_block
setblock ~74 ~124 ~135 grass_block
setblock ~74 ~124 ~136 dirt
setblock ~74 ~124 ~137 dirt
setblock ~74 ~124 ~138 dirt
setblock ~74 ~124 ~139 dirt
setblock ~74 ~124 ~140 dirt
setblock ~74 ~124 ~141 dirt
setblock ~74 ~124 ~142 dirt
setblock ~74 ~124 ~143 dirt
setblock ~74 ~124 ~144 dirt
setblock ~74 ~124 ~145 grass_block
setblock ~74 ~124 ~146 grass_block
setblock ~74 ~124 ~147 grass_block
setblock ~74 ~124 ~148 grass_block
setblock ~74 ~124 ~149 grass_block
setblock ~74 ~124 ~150 short_grass
setblock ~74 ~124 ~151 grass_block
setblock ~74 ~124 ~152 grass_block
setblock ~74 ~124 ~153 grass_block
setblock ~74 ~124 ~154 grass_block
setblock ~74 ~124 ~155 dirt
setblock ~74 ~124 ~156 dirt
setblock ~74 ~124 ~157 dirt
setblock ~74 ~124 ~158 dirt
setblock ~74 ~124 ~159 dirt
setblock ~74 ~124 ~160 dirt
setblock ~74 ~124 ~161 dirt
setblock ~74 ~124 ~162 dirt
setblock ~74 ~124 ~163 dirt
setblock ~74 ~124 ~164 dirt
setblock ~74 ~124 ~165 dirt
setblock ~74 ~124 ~166 dirt
setblock ~74 ~124 ~167 dirt
setblock ~74 ~124 ~168 dirt
setblock ~74 ~124 ~169 dirt
setblock ~74 ~124 ~170 dirt
setblock ~74 ~124 ~171 dirt
setblock ~74 ~124 ~172 dirt
setblock ~74 ~124 ~173 dirt
setblock ~74 ~124 ~174 dirt
setblock ~74 ~124 ~175 dirt
setblock ~74 ~124 ~176 dirt
setblock ~74 ~124 ~177 dirt
setblock ~74 ~124 ~178 grass_block
setblock ~74 ~124 ~179 grass_block
setblock ~74 ~124 ~180 grass_block
setblock ~74 ~124 ~181 grass_block
setblock ~74 ~124 ~182 grass_block
setblock ~74 ~124 ~183 grass_block
setblock ~74 ~124 ~184 grass_block
setblock ~74 ~124 ~190 short_grass
setblock ~74 ~124 ~192 grass_block
setblock ~74 ~124 ~193 grass_block
setblock ~74 ~124 ~194 grass_block
setblock ~74 ~124 ~195 grass_block
setblock ~74 ~124 ~196 grass_block
setblock ~74 ~124 ~197 grass_block
setblock ~74 ~124 ~198 grass_block
setblock ~74 ~124 ~199 dirt
setblock ~74 ~125 ~6 grass_block
setblock ~74 ~125 ~7 grass_block
setblock ~74 ~125 ~8 grass_block
setblock ~74 ~125 ~9 dirt
setblock ~74 ~125 ~10 dirt
setblock ~74 ~125 ~11 dirt
setblock ~74 ~125 ~12 dirt
setblock ~74 ~125 ~13 dirt
setblock ~74 ~125 ~14 dirt
setblock ~74 ~125 ~15 dirt
setblock ~74 ~125 ~16 dirt
setblock ~74 ~125 ~17 grass_block
setblock ~74 ~125 ~18 grass_block
setblock ~74 ~125 ~19 grass_block
setblock ~74 ~125 ~20 grass_block
setblock ~74 ~125 ~21 grass_block
setblock ~74 ~125 ~22 grass_block
setblock ~74 ~125 ~23 grass_block
setblock ~74 ~125 ~24 grass_block
setblock ~74 ~125 ~25 grass_block
setblock ~74 ~125 ~35 short_grass
setblock ~74 ~125 ~39 short_grass
setblock ~74 ~125 ~42 short_grass
setblock ~74 ~125 ~44 fern
setblock ~74 ~125 ~59 grass_block
setblock ~74 ~125 ~60 grass_block
setblock ~74 ~125 ~61 grass_block
setblock ~74 ~125 ~62 grass_block
setblock ~74 ~125 ~63 grass_block
setblock ~74 ~125 ~64 grass_block
setblock ~74 ~125 ~65 grass_block
setblock ~74 ~125 ~66 grass_block
setblock ~74 ~125 ~67 grass_block
setblock ~74 ~125 ~68 grass_block
setblock ~74 ~125 ~69 grass_block
setblock ~74 ~125 ~70 grass_block
setblock ~74 ~125 ~71 grass_block
setblock ~74 ~125 ~72 grass_block
setblock ~74 ~125 ~73 grass_block
setblock ~74 ~125 ~74 grass_block
setblock ~74 ~125 ~75 grass_block
setblock ~74 ~125 ~76 grass_block
setblock ~74 ~125 ~77 grass_block
setblock ~74 ~125 ~78 grass_block
setblock ~74 ~125 ~79 grass_block
setblock ~74 ~125 ~82 grass_block
setblock ~74 ~125 ~83 grass_block
setblock ~74 ~125 ~84 grass_block
setblock ~74 ~125 ~85 grass_block
setblock ~74 ~125 ~86 grass_block
setblock ~74 ~125 ~87 grass_block
setblock ~74 ~125 ~88 grass_block
setblock ~74 ~125 ~89 grass_block
setblock ~74 ~125 ~90 grass_block
setblock ~74 ~125 ~91 grass_block
setblock ~74 ~125 ~92 grass_block
setblock ~74 ~125 ~93 grass_block
setblock ~74 ~125 ~94 grass_block
setblock ~74 ~125 ~95 grass_block
setblock ~74 ~125 ~96 grass_block
setblock ~74 ~125 ~97 grass_block
setblock ~74 ~125 ~98 grass_block
setblock ~74 ~125 ~99 dirt
setblock ~74 ~125 ~100 dirt
setblock ~74 ~125 ~101 dirt
setblock ~74 ~125 ~102 grass_block
setblock ~74 ~125 ~103 grass_block
setblock ~74 ~125 ~104 grass_block
setblock ~74 ~125 ~105 grass_block
setblock ~74 ~125 ~106 grass_block
setblock ~74 ~125 ~107 grass_block
setblock ~74 ~125 ~108 grass_block
setblock ~74 ~125 ~109 grass_block
setblock ~74 ~125 ~110 grass_block
setblock ~74 ~125 ~111 grass_block
setblock ~74 ~125 ~112 dirt
setblock ~74 ~125 ~113 dirt
setblock ~74 ~125 ~114 dirt
setblock ~74 ~125 ~115 dirt
setblock ~74 ~125 ~116 dirt
setblock ~74 ~125 ~117 dirt
setblock ~74 ~125 ~118 dirt
setblock ~74 ~125 ~119 dirt
setblock ~74 ~125 ~120 dirt
setblock ~74 ~125 ~121 dirt
setblock ~74 ~125 ~122 dirt
setblock ~74 ~125 ~123 dirt
setblock ~74 ~125 ~124 grass_block
setblock ~74 ~125 ~125 grass_block
setblock ~74 ~125 ~127 short_grass
setblock ~74 ~125 ~133 short_grass
setblock ~74 ~125 ~134 fern
setblock ~74 ~125 ~136 grass_block
setblock ~74 ~125 ~137 grass_block
setblock ~74 ~125 ~138 grass_block
setblock ~74 ~125 ~139 grass_block
setblock ~74 ~125 ~140 grass_block
setblock ~74 ~125 ~141 grass_block
setblock ~74 ~125 ~142 grass_block
setblock ~74 ~125 ~143 grass_block
setblock ~74 ~125 ~144 grass_block
setblock ~74 ~125 ~147 short_grass
setblock ~74 ~125 ~148 short_grass
setblock ~74 ~125 ~149 short_grass
setblock ~74 ~125 ~151 short_grass
setblock ~74 ~125 ~155 grass_block
setblock ~74 ~125 ~156 grass_block
setblock ~74 ~125 ~157 grass_block
setblock ~74 ~125 ~158 grass_block
setblock ~74 ~125 ~159 dirt
setblock ~74 ~125 ~160 dirt
setblock ~74 ~125 ~161 dirt
setblock ~74 ~125 ~162 dirt
setblock ~74 ~125 ~163 dirt
setblock ~74 ~125 ~164 dirt
setblock ~74 ~125 ~165 dirt
setblock ~74 ~125 ~166 dirt
setblock ~74 ~125 ~167 dirt
setblock ~74 ~125 ~168 dirt
setblock ~74 ~125 ~169 dirt
setblock ~74 ~125 ~170 dirt
setblock ~74 ~125 ~171 dirt
setblock ~74 ~125 ~172 dirt
setblock ~74 ~125 ~173 dirt
setblock ~74 ~125 ~174 dirt
setblock ~74 ~125 ~175 dirt
setblock ~74 ~125 ~176 grass_block
setblock ~74 ~125 ~177 grass_block
setblock ~74 ~125 ~180 short_grass
setblock ~74 ~125 ~181 short_grass
setblock ~74 ~125 ~183 short_grass
setblock ~74 ~125 ~184 short_grass
setblock ~74 ~125 ~192 poppy
setblock ~74 ~125 ~193 short_grass
setblock ~74 ~125 ~196 short_grass
setblock ~74 ~125 ~198 short_grass
setblock ~74 ~125 ~199 grass_block
setblock ~74 ~126 ~6 short_grass
setblock ~74 ~126 ~9 grass_block
setblock ~74 ~126 ~10 grass_block
setblock ~74 ~126 ~11 grass_block
setblock ~74 ~126 ~12 grass_block
setblock ~74 ~126 ~13 grass_block
setblock ~74 ~126 ~14 grass_block
setblock ~74 ~126 ~15 grass_block
setblock ~74 ~126 ~16 grass_block
setblock ~74 ~126 ~22 poppy
setblock ~74 ~126 ~63 short_grass
setblock ~74 ~126 ~68 poppy
setblock ~74 ~126 ~78 fern
setblock ~74 ~126 ~86 short_grass
setblock ~74 ~126 ~90 short_grass
setblock ~74 ~126 ~92 short_grass
setblock ~74 ~126 ~99 grass_block
setblock ~74 ~126 ~100 grass_block
setblock ~74 ~126 ~101 grass_block
setblock ~74 ~126 ~102 short_grass
setblock ~74 ~126 ~104 short_grass
setblock ~74 ~126 ~105 short_grass
setblock ~74 ~126 ~106 fern
setblock ~74 ~126 ~107 short_grass
setblock ~74 ~126 ~110 short_grass
setblock ~74 ~126 ~112 grass_block
setblock ~74 ~126 ~113 grass_block
setblock ~74 ~126 ~114 grass_block
setblock ~74 ~126 ~115 grass_block
setblock ~74 ~126 ~116 grass_block
setblock ~74 ~126 ~117 grass_block
setblock ~74 ~126 ~118 dirt
setblock ~74 ~126 ~119 dirt
setblock ~74 ~126 ~120 dirt
setblock ~74 ~126 ~121 grass_block
setblock ~74 ~126 ~122 grass_block
setblock ~74 ~126 ~123 grass_block
setblock ~74 ~126 ~125 short_grass
setblock ~74 ~126 ~140 short_grass
setblock ~74 ~126 ~143 short_grass
setblock ~74 ~126 ~157 poppy
setblock ~74 ~126 ~159 grass_block
setblock ~74 ~126 ~160 grass_block
setblock ~74 ~126 ~161 grass_block
setblock ~74 ~126 ~162 grass_block
setblock ~74 ~126 ~163 grass_block
setblock ~74 ~126 ~164 dirt
setblock ~74 ~126 ~165 dirt
setblock ~74 ~126 ~166 dirt
setblock ~74 ~126 ~167 dirt
setblock ~74 ~126 ~168 dirt
setblock ~74 ~126 ~169 dirt
setblock ~74 ~126 ~170 dirt
setblock ~74 ~126 ~171 dirt
setblock ~74 ~126 ~172 dirt
setblock ~74 ~126 ~173 grass_block
setblock ~74 ~126 ~174 grass_block
setblock ~74 ~126 ~175 grass_block
setblock ~74 ~126 ~176 short_grass
setblock ~74 ~126 ~177 short_grass
setblock ~74 ~127 ~16 short_grass
setblock ~74 ~127 ~112 poppy
setblock ~74 ~127 ~114 short_grass
setblock ~74 ~127 ~115 short_grass
setblock ~74 ~127 ~117 fern
setblock ~74 ~127 ~118 grass_block
setblock ~74 ~127 ~119 grass_block
setblock ~74 ~127 ~120 grass_block
setblock ~74 ~127 ~159 short_grass
setblock ~74 ~127 ~160 short_grass
setblock ~74 ~127 ~161 short_grass
setblock ~74 ~127 ~162 short_grass
setblock ~74 ~127 ~164 grass_block
setblock ~74 ~127 ~165 grass_block
setblock ~74 ~127 ~166 grass_block
setblock ~74 ~127 ~167 grass_block
setblock ~74 ~127 ~168 grass_block
setblock ~74 ~127 ~169 dirt
setblock ~74 ~127 ~170 dirt
setblock ~74 ~127 ~171 grass_block
setblock ~74 ~127 ~172 grass_block
setblock ~74 ~127 ~173 poppy
setblock ~74 ~127 ~175 fern
setblock ~74 ~128 ~169 grass_block
setblock ~74 ~128 ~170 grass_block
setblock ~74 ~129 ~170 short_grass
setblock ~75 ~122 ~0 dirt
setblock ~75 ~122 ~1 dirt
setblock ~75 ~122 ~2 dirt
setblock ~75 ~122 ~3 dirt
setblock ~75 ~122 ~4 dirt
setblock ~75 ~122 ~5 dirt
setblock ~75 ~122 ~6 dirt
setblock ~75 ~122 ~7 dirt
setblock ~75 ~122 ~8 dirt
setblock ~75 ~122 ~9 dirt
setblock ~75 ~122 ~10 dirt
setblock ~75 ~122 ~11 dirt
setblock ~75 ~122 ~12 dirt
setblock ~75 ~122 ~13 dirt
setblock ~75 ~122 ~14 dirt
setblock ~75 ~122 ~15 dirt
setblock ~75 ~122 ~16 dirt
setblock ~75 ~122 ~17 dirt
setblock ~75 ~122 ~18 dirt
setblock ~75 ~122 ~19 dirt
setblock ~75 ~122 ~20 dirt
setblock ~75 ~122 ~21 dirt
setblock ~75 ~122 ~22 dirt
setblock ~75 ~122 ~23 dirt
setblock ~75 ~122 ~24 dirt
setblock ~75 ~122 ~25 dirt
setblock ~75 ~122 ~26 dirt
setblock ~75 ~122 ~27 dirt
setblock ~75 ~122 ~28 dirt
setblock ~75 ~122 ~29 dirt
setblock ~75 ~122 ~30 dirt
setblock ~75 ~122 ~31 dirt
setblock ~75 ~122 ~32 dirt
setblock ~75 ~122 ~33 dirt
setblock ~75 ~122 ~34 dirt
setblock ~75 ~122 ~35 dirt
setblock ~75 ~122 ~36 dirt
setblock ~75 ~122 ~37 dirt
setblock ~75 ~122 ~38 dirt
setblock ~75 ~122 ~39 dirt
setblock ~75 ~122 ~40 dirt
setblock ~75 ~122 ~41 dirt
setblock ~75 ~122 ~42 dirt
setblock ~75 ~122 ~43 dirt
setblock ~75 ~122 ~44 dirt
setblock ~75 ~122 ~45 dirt
setblock ~75 ~122 ~46 dirt
setblock ~75 ~122 ~47 dirt
setblock ~75 ~122 ~48 dirt
setblock ~75 ~122 ~49 dirt
setblock ~75 ~122 ~50 dirt
setblock ~75 ~122 ~51 dirt
setblock ~75 ~122 ~52 dirt
setblock ~75 ~122 ~53 dirt
setblock ~75 ~122 ~54 dirt
setblock ~75 ~122 ~55 dirt
setblock ~75 ~122 ~56 dirt
setblock ~75 ~122 ~57 dirt
setblock ~75 ~122 ~58 dirt
setblock ~75 ~122 ~59 dirt
setblock ~75 ~122 ~60 dirt
setblock ~75 ~122 ~61 dirt
setblock ~75 ~122 ~62 dirt
setblock ~75 ~122 ~63 dirt
setblock ~75 ~122 ~64 dirt
setblock ~75 ~122 ~65 dirt
setblock ~75 ~122 ~66 dirt
setblock ~75 ~122 ~67 dirt
setblock ~75 ~122 ~68 dirt
setblock ~75 ~122 ~69 dirt
setblock ~75 ~122 ~70 dirt
setblock ~75 ~122 ~71 dirt
setblock ~75 ~122 ~72 dirt
setblock ~75 ~122 ~73 dirt
setblock ~75 ~122 ~74 dirt
setblock ~75 ~122 ~75 dirt
setblock ~75 ~122 ~76 dirt
setblock ~75 ~122 ~77 dirt
setblock ~75 ~122 ~78 dirt
setblock ~75 ~122 ~79 dirt
setblock ~75 ~122 ~80 dirt
setblock ~75 ~122 ~81 dirt
setblock ~75 ~122 ~82 dirt
setblock ~75 ~122 ~83 dirt
setblock ~75 ~122 ~84 dirt
setblock ~75 ~122 ~85 dirt
setblock ~75 ~122 ~86 dirt
setblock ~75 ~122 ~87 dirt
setblock ~75 ~122 ~88 dirt
setblock ~75 ~122 ~89 dirt
setblock ~75 ~122 ~90 dirt
setblock ~75 ~122 ~91 dirt
setblock ~75 ~122 ~92 dirt
setblock ~75 ~122 ~93 dirt
setblock ~75 ~122 ~94 dirt
setblock ~75 ~122 ~95 dirt
setblock ~75 ~122 ~96 dirt
setblock ~75 ~122 ~97 dirt
setblock ~75 ~122 ~98 dirt
setblock ~75 ~122 ~99 dirt
setblock ~75 ~122 ~100 dirt
setblock ~75 ~122 ~101 dirt
setblock ~75 ~122 ~102 dirt
setblock ~75 ~122 ~103 dirt
setblock ~75 ~122 ~104 dirt
setblock ~75 ~122 ~105 dirt
setblock ~75 ~122 ~106 dirt
setblock ~75 ~122 ~107 dirt
setblock ~75 ~122 ~108 dirt
setblock ~75 ~122 ~109 dirt
setblock ~75 ~122 ~110 dirt
setblock ~75 ~122 ~111 dirt
setblock ~75 ~122 ~112 dirt
setblock ~75 ~122 ~113 dirt
setblock ~75 ~122 ~114 dirt
setblock ~75 ~122 ~115 dirt
setblock ~75 ~122 ~116 dirt
setblock ~75 ~122 ~117 dirt
setblock ~75 ~122 ~118 dirt
setblock ~75 ~122 ~119 dirt
setblock ~75 ~122 ~120 dirt
setblock ~75 ~122 ~121 dirt
setblock ~75 ~122 ~122 dirt
setblock ~75 ~122 ~123 dirt
setblock ~75 ~122 ~124 dirt
setblock ~75 ~122 ~125 dirt
setblock ~75 ~122 ~126 dirt
setblock ~75 ~122 ~127 dirt
setblock ~75 ~122 ~128 dirt
setblock ~75 ~122 ~129 dirt
setblock ~75 ~122 ~130 grass_block
setblock ~75 ~122 ~131 dirt
setblock ~75 ~122 ~132 dirt
setblock ~75 ~122 ~133 dirt
setblock ~75 ~122 ~134 dirt
setblock ~75 ~122 ~135 dirt
setblock ~75 ~122 ~136 dirt
setblock ~75 ~122 ~137 dirt
setblock ~75 ~122 ~138 dirt
setblock ~75 ~122 ~139 dirt
setblock ~75 ~122 ~140 dirt
setblock ~75 ~122 ~141 dirt
setblock ~75 ~122 ~142 dirt
setblock ~75 ~122 ~143 dirt
setblock ~75 ~122 ~144 dirt
setblock ~75 ~122 ~145 dirt
setblock ~75 ~122 ~146 dirt
setblock ~75 ~122 ~147 dirt
setblock ~75 ~122 ~148 dirt
setblock ~75 ~122 ~149 dirt
setblock ~75 ~122 ~150 dirt
setblock ~75 ~122 ~151 dirt
setblock ~75 ~122 ~152 dirt
setblock ~75 ~122 ~153 dirt
setblock ~75 ~122 ~154 dirt
setblock ~75 ~122 ~155 dirt
setblock ~75 ~122 ~156 dirt
setblock ~75 ~122 ~157 dirt
setblock ~75 ~122 ~158 dirt
setblock ~75 ~122 ~159 dirt
setblock ~75 ~122 ~160 dirt
setblock ~75 ~122 ~161 dirt
setblock ~75 ~122 ~162 dirt
setblock ~75 ~122 ~163 dirt
setblock ~75 ~122 ~164 dirt
setblock ~75 ~122 ~165 dirt
setblock ~75 ~122 ~166 dirt
setblock ~75 ~122 ~167 dirt
setblock ~75 ~122 ~168 dirt
setblock ~75 ~122 ~169 dirt
setblock ~75 ~122 ~170 dirt
setblock ~75 ~122 ~171 dirt
setblock ~75 ~122 ~172 dirt
setblock ~75 ~122 ~173 dirt
setblock ~75 ~122 ~174 dirt
setblock ~75 ~122 ~175 dirt
setblock ~75 ~122 ~176 dirt
setblock ~75 ~122 ~177 dirt
setblock ~75 ~122 ~178 dirt
setblock ~75 ~122 ~179 dirt
setblock ~75 ~122 ~180 dirt
setblock ~75 ~122 ~181 dirt
setblock ~75 ~122 ~182 dirt
