setblock ~170 ~137 ~73 jungle_leaves[persistent=true]
setblock ~170 ~137 ~74 oak_leaves[persistent=true]
setblock ~170 ~137 ~75 oak_leaves[persistent=true]
setblock ~170 ~137 ~76 jungle_leaves[persistent=true]
setblock ~170 ~137 ~77 jungle_leaves[persistent=true]
setblock ~170 ~137 ~78 jungle_leaves[persistent=true]
setblock ~170 ~137 ~79 oak_leaves[persistent=true]
setblock ~170 ~137 ~80 oak_leaves[persistent=true]
setblock ~170 ~137 ~81 oak_leaves[persistent=true]
setblock ~170 ~138 ~73 jungle_leaves[persistent=true]
setblock ~170 ~138 ~74 oak_leaves[persistent=true]
setblock ~170 ~138 ~75 oak_leaves[persistent=true]
setblock ~170 ~138 ~76 oak_leaves[persistent=true]
setblock ~170 ~138 ~78 oak_wood
setblock ~170 ~138 ~79 oak_wood
setblock ~170 ~138 ~81 oak_leaves[persistent=true]
setblock ~170 ~138 ~82 oak_leaves[persistent=true]
setblock ~170 ~138 ~83 oak_leaves[persistent=true]
setblock ~170 ~139 ~74 jungle_leaves[persistent=true]
setblock ~170 ~139 ~75 jungle_leaves[persistent=true]
setblock ~170 ~139 ~76 oak_leaves[persistent=true]
setblock ~170 ~139 ~77 jungle_leaves[persistent=true]
setblock ~170 ~139 ~78 oak_log
setblock ~170 ~139 ~79 oak_leaves[persistent=true]
setblock ~170 ~139 ~80 oak_leaves[persistent=true]
setblock ~170 ~139 ~81 oak_leaves[persistent=true]
setblock ~170 ~139 ~82 oak_leaves[persistent=true]
setblock ~170 ~139 ~83 oak_leaves[persistent=true]
setblock ~170 ~140 ~74 oak_leaves[persistent=true]
setblock ~170 ~140 ~76 oak_leaves[persistent=true]
setblock ~170 ~140 ~77 oak_log
setblock ~170 ~140 ~78 oak_log
setblock ~170 ~140 ~79 oak_leaves[persistent=true]
setblock ~170 ~140 ~81 jungle_leaves[persistent=true]
setblock ~170 ~140 ~82 oak_leaves[persistent=true]
setblock ~170 ~140 ~83 oak_leaves[persistent=true]
setblock ~170 ~141 ~74 jungle_leaves[persistent=true]
setblock ~170 ~141 ~75 oak_leaves[persistent=true]
setblock ~170 ~141 ~76 oak_leaves[persistent=true]
setblock ~170 ~141 ~77 oak_leaves[persistent=true]
setblock ~170 ~141 ~78 jungle_leaves[persistent=true]
setblock ~170 ~141 ~79 jungle_leaves[persistent=true]
setblock ~170 ~141 ~80 oak_leaves[persistent=true]
setblock ~170 ~141 ~81 oak_leaves[persistent=true]
setblock ~170 ~141 ~82 oak_leaves[persistent=true]
setblock ~170 ~141 ~83 oak_leaves[persistent=true]
setblock ~170 ~142 ~74 oak_leaves[persistent=true]
setblock ~170 ~142 ~75 jungle_leaves[persistent=true]
setblock ~170 ~142 ~76 oak_leaves[persistent=true]
setblock ~170 ~142 ~77 oak_leaves[persistent=true]
setblock ~170 ~142 ~79 jungle_leaves[persistent=true]
setblock ~170 ~142 ~80 jungle_leaves[persistent=true]
setblock ~171 ~120 ~75 dirt
setblock ~171 ~120 ~77 dirt
setblock ~171 ~121 ~74 dirt
setblock ~171 ~121 ~75 dirt
setblock ~171 ~121 ~76 dirt
setblock ~171 ~121 ~77 dirt
setblock ~171 ~121 ~78 dirt
setblock ~171 ~122 ~74 dirt
setblock ~171 ~122 ~75 dirt
setblock ~171 ~122 ~76 dirt
setblock ~171 ~122 ~77 dirt
setblock ~171 ~122 ~78 dirt
setblock ~171 ~123 ~74 dirt
setblock ~171 ~123 ~75 dirt
setblock ~171 ~123 ~76 dirt
setblock ~171 ~123 ~77 dirt
setblock ~171 ~123 ~78 dirt
setblock ~171 ~124 ~74 dirt
setblock ~171 ~124 ~75 dirt
setblock ~171 ~124 ~76 dirt
setblock ~171 ~124 ~77 dirt
setblock ~171 ~124 ~78 dirt
setblock ~171 ~125 ~74 dirt
setblock ~171 ~125 ~75 dirt
setblock ~171 ~125 ~76 dirt
setblock ~171 ~125 ~77 dirt
setblock ~171 ~125 ~78 dirt
setblock ~171 ~126 ~74 dirt
setblock ~171 ~126 ~75 dirt
setblock ~171 ~126 ~76 dirt
setblock ~171 ~126 ~77 dirt
setblock ~171 ~126 ~78 dirt
setblock ~171 ~127 ~74 dirt
setblock ~171 ~127 ~75 dirt
setblock ~171 ~127 ~76 dirt
setblock ~171 ~127 ~77 dirt
setblock ~171 ~127 ~78 dirt
setblock ~171 ~128 ~74 dirt
setblock ~171 ~128 ~75 dirt
setblock ~171 ~128 ~76 grass_block
setblock ~171 ~128 ~77 grass_block
setblock ~171 ~128 ~78 grass_block
setblock ~171 ~129 ~74 grass_block
setblock ~171 ~129 ~75 grass_block
setblock ~171 ~129 ~76 short_grass
setblock ~171 ~132 ~71 jungle_leaves[persistent=true]
setblock ~171 ~132 ~72 oak_leaves[persistent=true]
setblock ~171 ~132 ~73 oak_leaves[persistent=true]
setblock ~171 ~132 ~74 oak_leaves[persistent=true]
setblock ~171 ~133 ~71 jungle_leaves[persistent=true]
setblock ~171 ~133 ~72 jungle_leaves[persistent=true]
setblock ~171 ~133 ~73 oak_leaves[persistent=true]
setblock ~171 ~133 ~74 oak_leaves[persistent=true]
setblock ~171 ~134 ~71 oak_leaves[persistent=true]
setblock ~171 ~134 ~72 oak_leaves[persistent=true]
setblock ~171 ~134 ~73 oak_leaves[persistent=true]
setblock ~171 ~134 ~74 oak_leaves[persistent=true]
setblock ~171 ~134 ~75 oak_leaves[persistent=true]
setblock ~171 ~134 ~76 oak_leaves[persistent=true]
setblock ~171 ~134 ~77 oak_leaves[persistent=true]
setblock ~171 ~134 ~78 oak_leaves[persistent=true]
setblock ~171 ~135 ~70 oak_leaves[persistent=true]
setblock ~171 ~135 ~71 oak_leaves[persistent=true]
setblock ~171 ~135 ~72 jungle_leaves[persistent=true]
setblock ~171 ~135 ~73 jungle_leaves[persistent=true]
setblock ~171 ~135 ~75 oak_wood
setblock ~171 ~135 ~76 oak_leaves[persistent=true]
setblock ~171 ~135 ~77 oak_leaves[persistent=true]
setblock ~171 ~135 ~78 oak_leaves[persistent=true]
setblock ~171 ~135 ~79 oak_leaves[persistent=true]
setblock ~171 ~135 ~80 oak_leaves[persistent=true]
setblock ~171 ~136 ~70 jungle_leaves[persistent=true]
setblock ~171 ~136 ~71 oak_leaves[persistent=true]
setblock ~171 ~136 ~72 oak_leaves[persistent=true]
setblock ~171 ~136 ~74 oak_leaves[persistent=true]
setblock ~171 ~136 ~75 oak_leaves[persistent=true]
setblock ~171 ~136 ~76 oak_wood
setblock ~171 ~136 ~77 oak_wood
setblock ~171 ~136 ~79 jungle_leaves[persistent=true]
setblock ~171 ~136 ~80 oak_leaves[persistent=true]
setblock ~171 ~136 ~81 oak_leaves[persistent=true]
setblock ~171 ~136 ~82 oak_leaves[persistent=true]
setblock ~171 ~137 ~70 oak_leaves[persistent=true]
setblock ~171 ~137 ~71 oak_leaves[persistent=true]
setblock ~171 ~137 ~72 oak_leaves[persistent=true]
setblock ~171 ~137 ~73 oak_leaves[persistent=true]
setblock ~171 ~137 ~74 jungle_leaves[persistent=true]
setblock ~171 ~137 ~75 oak_leaves[persistent=true]
setblock ~171 ~137 ~77 jungle_leaves[persistent=true]
setblock ~171 ~137 ~78 oak_leaves[persistent=true]
setblock ~171 ~137 ~79 oak_leaves[persistent=true]
setblock ~171 ~137 ~80 oak_leaves[persistent=true]
setblock ~171 ~137 ~81 oak_leaves[persistent=true]
setblock ~171 ~137 ~82 oak_leaves[persistent=true]
setblock ~171 ~138 ~74 oak_leaves[persistent=true]
setblock ~171 ~138 ~75 oak_leaves[persistent=true]
setblock ~171 ~138 ~77 oak_leaves[persistent=true]
setblock ~171 ~138 ~78 oak_leaves[persistent=true]
setblock ~171 ~138 ~79 oak_leaves[persistent=true]
setblock ~171 ~138 ~83 oak_leaves[persistent=true]
setblock ~171 ~139 ~74 oak_leaves[persistent=true]
setblock ~171 ~139 ~75 oak_leaves[persistent=true]
setblock ~171 ~139 ~76 oak_leaves[persistent=true]
setblock ~171 ~139 ~77 oak_leaves[persistent=true]
setblock ~171 ~139 ~78 oak_leaves[persistent=true]
setblock ~171 ~139 ~79 oak_wood
setblock ~171 ~139 ~80 oak_wood
setblock ~171 ~139 ~81 oak_wood
setblock ~171 ~139 ~82 oak_leaves[persistent=true]
setblock ~171 ~139 ~83 oak_leaves[persistent=true]
setblock ~171 ~140 ~75 oak_leaves[persistent=true]
setblock ~171 ~140 ~76 jungle_leaves[persistent=true]
setblock ~171 ~140 ~77 jungle_leaves[persistent=true]
setblock ~171 ~140 ~78 oak_log
setblock ~171 ~140 ~79 oak_leaves[persistent=true]
setblock ~171 ~140 ~80 oak_log
setblock ~171 ~140 ~81 oak_wood
setblock ~171 ~140 ~82 oak_leaves[persistent=true]
setblock ~171 ~140 ~83 oak_leaves[persistent=true]
setblock ~171 ~141 ~74 oak_leaves[persistent=true]
setblock ~171 ~141 ~75 jungle_leaves[persistent=true]
setblock ~171 ~141 ~76 jungle_leaves[persistent=true]
setblock ~171 ~141 ~77 jungle_leaves[persistent=true]
setblock ~171 ~141 ~78 oak_leaves[persistent=true]
setblock ~171 ~141 ~80 oak_leaves[persistent=true]
setblock ~171 ~141 ~81 oak_leaves[persistent=true]
setblock ~171 ~141 ~82 oak_leaves[persistent=true]
setblock ~171 ~141 ~83 jungle_leaves[persistent=true]
setblock ~171 ~142 ~74 oak_leaves[persistent=true]
setblock ~171 ~142 ~75 oak_leaves[persistent=true]
setblock ~171 ~142 ~76 jungle_leaves[persistent=true]
setblock ~171 ~142 ~78 oak_leaves[persistent=true]
setblock ~171 ~142 ~79 oak_leaves[persistent=true]
setblock ~171 ~142 ~80 oak_leaves[persistent=true]
setblock ~172 ~121 ~75 dirt
setblock ~172 ~121 ~77 dirt
setblock ~172 ~122 ~75 dirt
setblock ~172 ~122 ~77 dirt
setblock ~172 ~123 ~75 dirt
setblock ~172 ~123 ~77 dirt
setblock ~172 ~124 ~75 dirt
setblock ~172 ~124 ~77 dirt
setblock ~172 ~125 ~75 dirt
setblock ~172 ~125 ~77 dirt
setblock ~172 ~126 ~75 dirt
setblock ~172 ~126 ~77 dirt
setblock ~172 ~127 ~75 dirt
setblock ~172 ~127 ~77 dirt
setblock ~172 ~128 ~75 grass_block
setblock ~172 ~128 ~77 grass_block
setblock ~172 ~129 ~75 fern
setblock ~172 ~132 ~71 jungle_leaves[persistent=true]
setblock ~172 ~132 ~72 jungle_leaves[persistent=true]
setblock ~172 ~132 ~73 oak_leaves[persistent=true]
setblock ~172 ~133 ~71 oak_leaves[persistent=true]
setblock ~172 ~133 ~72 oak_leaves[persistent=true]
setblock ~172 ~133 ~73 oak_leaves[persistent=true]
setblock ~172 ~133 ~74 oak_leaves[persistent=true]
setblock ~172 ~134 ~71 jungle_leaves[persistent=true]
setblock ~172 ~134 ~72 oak_leaves[persistent=true]
setblock ~172 ~134 ~73 oak_wood
setblock ~172 ~134 ~75 oak_leaves[persistent=true]
setblock ~172 ~134 ~76 oak_leaves[persistent=true]
setblock ~172 ~135 ~71 jungle_leaves[persistent=true]
setblock ~172 ~135 ~73 oak_leaves[persistent=true]
setblock ~172 ~135 ~74 oak_wood
setblock ~172 ~135 ~76 oak_leaves[persistent=true]
setblock ~172 ~135 ~77 oak_leaves[persistent=true]
setblock ~172 ~136 ~72 oak_leaves[persistent=true]
setblock ~172 ~136 ~73 oak_leaves[persistent=true]
setblock ~172 ~136 ~75 oak_wood
setblock ~172 ~136 ~76 oak_wood
setblock ~172 ~136 ~77 jungle_leaves[persistent=true]
setblock ~172 ~136 ~79 oak_leaves[persistent=true]
setblock ~172 ~136 ~82 oak_leaves[persistent=true]
setblock ~172 ~137 ~72 oak_leaves[persistent=true]
setblock ~172 ~137 ~73 oak_leaves[persistent=true]
setblock ~172 ~137 ~74 jungle_leaves[persistent=true]
setblock ~172 ~137 ~75 oak_leaves[persistent=true]
setblock ~172 ~137 ~76 jungle_leaves[persistent=true]
setblock ~172 ~137 ~78 jungle_leaves[persistent=true]
setblock ~172 ~137 ~79 oak_leaves[persistent=true]
setblock ~172 ~137 ~80 oak_leaves[persistent=true]
setblock ~172 ~137 ~81 oak_leaves[persistent=true]
setblock ~172 ~137 ~82 jungle_leaves[persistent=true]
setblock ~172 ~138 ~74 oak_leaves[persistent=true]
setblock ~172 ~138 ~75 oak_leaves[persistent=true]
setblock ~172 ~138 ~76 jungle_leaves[persistent=true]
setblock ~172 ~138 ~77 oak_leaves[persistent=true]
setblock ~172 ~138 ~78 oak_leaves[persistent=true]
setblock ~172 ~138 ~79 oak_leaves[persistent=true]
setblock ~172 ~138 ~80 oak_leaves[persistent=true]
setblock ~172 ~138 ~81 oak_leaves[persistent=true]
setblock ~172 ~138 ~82 oak_leaves[persistent=true]
setblock ~172 ~138 ~83 oak_leaves[persistent=true]
setblock ~172 ~139 ~74 oak_leaves[persistent=true]
setblock ~172 ~139 ~76 jungle_leaves[persistent=true]
setblock ~172 ~139 ~77 jungle_leaves[persistent=true]
setblock ~172 ~139 ~78 oak_leaves[persistent=true]
setblock ~172 ~139 ~79 oak_leaves[persistent=true]
setblock ~172 ~139 ~81 oak_leaves[persistent=true]
setblock ~172 ~139 ~82 oak_leaves[persistent=true]
setblock ~172 ~139 ~83 jungle_leaves[persistent=true]
setblock ~172 ~140 ~74 oak_leaves[persistent=true]
setblock ~172 ~140 ~75 oak_leaves[persistent=true]
setblock ~172 ~140 ~76 oak_leaves[persistent=true]
setblock ~172 ~140 ~77 oak_leaves[persistent=true]
setblock ~172 ~140 ~78 oak_leaves[persistent=true]
setblock ~172 ~140 ~79 oak_log
setblock ~172 ~140 ~80 oak_leaves[persistent=true]
setblock ~172 ~140 ~81 jungle_leaves[persistent=true]
setblock ~172 ~140 ~82 oak_wood
setblock ~172 ~140 ~83 oak_leaves[persistent=true]
setblock ~172 ~141 ~74 oak_leaves[persistent=true]
setblock ~172 ~141 ~75 jungle_leaves[persistent=true]
setblock ~172 ~141 ~76 oak_leaves[persistent=true]
setblock ~172 ~141 ~77 oak_leaves[persistent=true]
setblock ~172 ~141 ~78 oak_leaves[persistent=true]
setblock ~172 ~141 ~79 oak_leaves[persistent=true]
setblock ~172 ~141 ~80 oak_leaves[persistent=true]
setblock ~172 ~141 ~81 oak_leaves[persistent=true]
setblock ~172 ~141 ~82 oak_leaves[persistent=true]
setblock ~172 ~142 ~75 oak_leaves[persistent=true]
setblock ~172 ~142 ~77 oak_leaves[persistent=true]
setblock ~172 ~142 ~79 oak_leaves[persistent=true]
setblock ~172 ~142 ~80 jungle_leaves[persistent=true]
setblock ~173 ~132 ~69 oak_leaves[persistent=true]
setblock ~173 ~132 ~70 oak_leaves[persistent=true]
setblock ~173 ~132 ~72 oak_leaves[persistent=true]
setblock ~173 ~132 ~73 oak_leaves[persistent=true]
setblock ~173 ~132 ~74 jungle_leaves[persistent=true]
setblock ~173 ~133 ~69 jungle_leaves[persistent=true]
setblock ~173 ~133 ~70 jungle_leaves[persistent=true]
setblock ~173 ~133 ~71 oak_leaves[persistent=true]
setblock ~173 ~133 ~72 oak_leaves[persistent=true]
setblock ~173 ~133 ~73 oak_leaves[persistent=true]
setblock ~173 ~133 ~74 oak_leaves[persistent=true]
setblock ~173 ~134 ~70 oak_leaves[persistent=true]
setblock ~173 ~134 ~71 oak_leaves[persistent=true]
setblock ~173 ~134 ~72 oak_wood
setblock ~173 ~134 ~73 oak_leaves[persistent=true]
setblock ~173 ~134 ~74 oak_leaves[persistent=true]
setblock ~173 ~134 ~75 oak_leaves[persistent=true]
setblock ~173 ~134 ~76 oak_leaves[persistent=true]
setblock ~173 ~135 ~71 jungle_leaves[persistent=true]
setblock ~173 ~135 ~72 oak_leaves[persistent=true]
setblock ~173 ~135 ~73 oak_leaves[persistent=true]
setblock ~173 ~135 ~74 jungle_leaves[persistent=true]
setblock ~173 ~135 ~75 oak_leaves[persistent=true]
setblock ~173 ~135 ~76 oak_leaves[persistent=true]
setblock ~173 ~136 ~72 oak_leaves[persistent=true]
setblock ~173 ~136 ~73 oak_leaves[persistent=true]
setblock ~173 ~136 ~74 oak_wood
setblock ~173 ~136 ~76 oak_leaves[persistent=true]
setblock ~173 ~136 ~77 oak_leaves[persistent=true]
setblock ~173 ~136 ~79 oak_leaves[persistent=true]
setblock ~173 ~136 ~80 jungle_leaves[persistent=true]
setblock ~173 ~136 ~81 jungle_leaves[persistent=true]
setblock ~173 ~136 ~82 oak_leaves[persistent=true]
setblock ~173 ~137 ~72 oak_leaves[persistent=true]
setblock ~173 ~137 ~73 oak_leaves[persistent=true]
setblock ~173 ~137 ~74 oak_leaves[persistent=true]
setblock ~173 ~137 ~75 oak_leaves[persistent=true]
setblock ~173 ~137 ~77 oak_leaves[persistent=true]
setblock ~173 ~137 ~78 oak_leaves[persistent=true]
setblock ~173 ~137 ~79 jungle_leaves[persistent=true]
setblock ~173 ~137 ~80 jungle_leaves[persistent=true]
setblock ~173 ~137 ~81 jungle_leaves[persistent=true]
setblock ~173 ~138 ~76 oak_leaves[persistent=true]
setblock ~173 ~138 ~77 jungle_leaves[persistent=true]
setblock ~173 ~138 ~78 oak_leaves[persistent=true]
setblock ~173 ~138 ~80 oak_leaves[persistent=true]
setblock ~173 ~138 ~81 oak_leaves[persistent=true]
setblock ~173 ~138 ~82 oak_leaves[persistent=true]
setblock ~173 ~138 ~83 oak_leaves[persistent=true]
setblock ~173 ~139 ~77 jungle_leaves[persistent=true]
setblock ~173 ~139 ~78 oak_leaves[persistent=true]
setblock ~173 ~139 ~79 oak_leaves[persistent=true]
setblock ~173 ~139 ~80 oak_leaves[persistent=true]
setblock ~173 ~139 ~81 oak_leaves[persistent=true]
setblock ~173 ~139 ~82 jungle_leaves[persistent=true]
setblock ~173 ~139 ~83 oak_leaves[persistent=true]
setblock ~173 ~140 ~76 oak_leaves[persistent=true]
setblock ~173 ~140 ~77 oak_leaves[persistent=true]
setblock ~173 ~140 ~78 oak_leaves[persistent=true]
setblock ~173 ~140 ~79 oak_leaves[persistent=true]
setblock ~173 ~140 ~80 oak_leaves[persistent=true]
setblock ~173 ~140 ~81 oak_leaves[persistent=true]
setblock ~173 ~140 ~82 oak_leaves[persistent=true]
setblock ~173 ~140 ~83 oak_leaves[persistent=true]
setblock ~173 ~141 ~76 jungle_leaves[persistent=true]
setblock ~173 ~141 ~77 oak_leaves[persistent=true]
setblock ~173 ~141 ~79 oak_leaves[persistent=true]
setblock ~173 ~141 ~80 oak_leaves[persistent=true]
setblock ~173 ~141 ~81 oak_leaves[persistent=true]
setblock ~173 ~141 ~82 oak_leaves[persistent=true]
setblock ~173 ~141 ~83 oak_leaves[persistent=true]
setblock ~173 ~142 ~76 jungle_leaves[persistent=true]
setblock ~173 ~142 ~77 oak_leaves[persistent=true]
setblock ~173 ~142 ~78 jungle_leaves[persistent=true]
setblock ~173 ~142 ~79 oak_leaves[persistent=true]
setblock ~173 ~142 ~80 oak_leaves[persistent=true]
setblock ~174 ~132 ~69 oak_leaves[persistent=true]
setblock ~174 ~132 ~70 oak_leaves[persistent=true]
setblock ~174 ~133 ~69 oak_leaves[persistent=true]
setblock ~174 ~133 ~70 oak_leaves[persistent=true]
setblock ~174 ~133 ~71 jungle_leaves[persistent=true]
setblock ~174 ~133 ~72 jungle_leaves[persistent=true]
setblock ~174 ~133 ~73 jungle_leaves[persistent=true]
setblock ~174 ~134 ~70 oak_leaves[persistent=true]
setblock ~174 ~134 ~71 oak_wood
setblock ~174 ~134 ~72 oak_leaves[persistent=true]
setblock ~174 ~134 ~73 oak_leaves[persistent=true]
setblock ~174 ~134 ~74 oak_leaves[persistent=true]
setblock ~174 ~134 ~75 oak_leaves[persistent=true]
setblock ~174 ~135 ~71 oak_leaves[persistent=true]
setblock ~174 ~135 ~72 oak_leaves[persistent=true]
setblock ~174 ~135 ~73 oak_leaves[persistent=true]
setblock ~174 ~135 ~74 jungle_leaves[persistent=true]
setblock ~174 ~135 ~75 oak_leaves[persistent=true]
setblock ~174 ~136 ~72 oak_leaves[persistent=true]
setblock ~174 ~136 ~73 jungle_leaves[persistent=true]
setblock ~174 ~136 ~74 jungle_leaves[persistent=true]
setblock ~174 ~136 ~75 oak_leaves[persistent=true]
setblock ~174 ~137 ~72 oak_leaves[persistent=true]
setblock ~174 ~137 ~73 oak_leaves[persistent=true]
setblock ~174 ~137 ~74 oak_leaves[persistent=true]
setblock ~174 ~137 ~75 jungle_leaves[persistent=true]
setblock ~199 ~200 ~199 gold_block
