setblock ~0 ~1 ~0 gold_block
setblock ~28 ~121 ~93 dirt
setblock ~28 ~121 ~95 dirt
setblock ~28 ~122 ~93 dirt
setblock ~28 ~122 ~95 dirt
setblock ~28 ~123 ~93 dirt
setblock ~28 ~123 ~95 dirt
setblock ~28 ~124 ~93 dirt
setblock ~28 ~124 ~95 dirt
setblock ~28 ~125 ~93 grass_block
setblock ~28 ~125 ~95 grass_block
setblock ~29 ~119 ~93 dirt
setblock ~29 ~119 ~95 dirt
setblock ~29 ~120 ~93 dirt
setblock ~29 ~120 ~94 dirt
setblock ~29 ~120 ~95 dirt
setblock ~29 ~120 ~96 dirt
setblock ~29 ~121 ~91 dirt
setblock ~29 ~121 ~92 dirt
setblock ~29 ~121 ~93 dirt
setblock ~29 ~121 ~94 dirt
setblock ~29 ~121 ~95 dirt
setblock ~29 ~121 ~96 dirt
setblock ~29 ~121 ~101 dirt
setblock ~29 ~122 ~91 dirt
setblock ~29 ~122 ~92 dirt
setblock ~29 ~122 ~93 dirt
setblock ~29 ~122 ~94 dirt
setblock ~29 ~122 ~95 dirt
setblock ~29 ~122 ~96 dirt
setblock ~29 ~122 ~101 dirt
setblock ~29 ~123 ~91 dirt
setblock ~29 ~123 ~92 dirt
setblock ~29 ~123 ~93 dirt
setblock ~29 ~123 ~94 dirt
setblock ~29 ~123 ~95 dirt
setblock ~29 ~123 ~96 dirt
setblock ~29 ~123 ~101 grass_block
setblock ~29 ~124 ~91 dirt
setblock ~29 ~124 ~92 dirt
setblock ~29 ~124 ~93 dirt
setblock ~29 ~124 ~94 dirt
setblock ~29 ~124 ~95 dirt
setblock ~29 ~124 ~96 grass_block
setblock ~29 ~125 ~91 dirt
setblock ~29 ~125 ~92 dirt
setblock ~29 ~125 ~93 grass_block
setblock ~29 ~125 ~94 grass_block
setblock ~29 ~125 ~95 grass_block
setblock ~29 ~126 ~91 grass_block
setblock ~29 ~126 ~92 grass_block
setblock ~29 ~127 ~91 poppy
setblock ~29 ~127 ~92 short_grass
setblock ~30 ~116 ~94 dirt
setblock ~30 ~117 ~93 dirt
setblock ~30 ~117 ~94 dirt
setblock ~30 ~117 ~95 dirt
setblock ~30 ~118 ~93 dirt
setblock ~30 ~118 ~94 dirt
setblock ~30 ~118 ~95 dirt
setblock ~30 ~118 ~97 dirt
setblock ~30 ~119 ~88 dirt
setblock ~30 ~119 ~89 dirt
setblock ~30 ~119 ~91 dirt
setblock ~30 ~119 ~92 dirt
setblock ~30 ~119 ~93 dirt
setblock ~30 ~119 ~94 dirt
setblock ~30 ~119 ~95 dirt
setblock ~30 ~119 ~96 dirt
setblock ~30 ~119 ~97 dirt
setblock ~30 ~120 ~88 dirt
setblock ~30 ~120 ~89 dirt
setblock ~30 ~120 ~90 dirt
setblock ~30 ~120 ~91 dirt
setblock ~30 ~120 ~92 dirt
setblock ~30 ~120 ~93 dirt
setblock ~30 ~120 ~94 dirt
setblock ~30 ~120 ~95 dirt
setblock ~30 ~120 ~96 dirt
setblock ~30 ~120 ~97 dirt
setblock ~30 ~120 ~98 dirt
setblock ~30 ~120 ~100 dirt
setblock ~30 ~120 ~101 dirt
setblock ~30 ~120 ~105 dirt
setblock ~30 ~121 ~87 dirt
setblock ~30 ~121 ~88 dirt
setblock ~30 ~121 ~89 dirt
setblock ~30 ~121 ~90 dirt
setblock ~30 ~121 ~91 dirt
setblock ~30 ~121 ~92 dirt
setblock ~30 ~121 ~93 dirt
setblock ~30 ~121 ~94 dirt
setblock ~30 ~121 ~95 dirt
setblock ~30 ~121 ~96 dirt
setblock ~30 ~121 ~97 dirt
setblock ~30 ~121 ~98 dirt
setblock ~30 ~121 ~99 dirt
setblock ~30 ~121 ~100 dirt
setblock ~30 ~121 ~101 dirt
setblock ~30 ~121 ~102 dirt
setblock ~30 ~121 ~105 dirt
setblock ~30 ~122 ~87 dirt
setblock ~30 ~122 ~88 dirt
setblock ~30 ~122 ~89 dirt
setblock ~30 ~122 ~90 dirt
setblock ~30 ~122 ~91 dirt
setblock ~30 ~122 ~92 dirt
setblock ~30 ~122 ~93 dirt
setblock ~30 ~122 ~94 dirt
setblock ~30 ~122 ~95 dirt
setblock ~30 ~122 ~96 dirt
setblock ~30 ~122 ~97 dirt
setblock ~30 ~122 ~98 dirt
setblock ~30 ~122 ~99 grass_block
setblock ~30 ~122 ~100 grass_block
setblock ~30 ~122 ~101 grass_block
setblock ~30 ~122 ~102 dirt
setblock ~30 ~122 ~105 dirt
setblock ~30 ~123 ~87 dirt
setblock ~30 ~123 ~88 dirt
setblock ~30 ~123 ~89 dirt
setblock ~30 ~123 ~90 dirt
setblock ~30 ~123 ~91 dirt
setblock ~30 ~123 ~92 dirt
setblock ~30 ~123 ~93 dirt
setblock ~30 ~123 ~94 dirt
setblock ~30 ~123 ~95 dirt
setblock ~30 ~123 ~96 dirt
setblock ~30 ~123 ~97 grass_block
setblock ~30 ~123 ~98 grass_block
setblock ~30 ~123 ~100 short_grass
setblock ~30 ~123 ~102 grass_block
setblock ~30 ~123 ~105 grass_block
setblock ~30 ~124 ~87 dirt
setblock ~30 ~124 ~88 dirt
setblock ~30 ~124 ~89 dirt
setblock ~30 ~124 ~90 dirt
setblock ~30 ~124 ~91 dirt
setblock ~30 ~124 ~92 dirt
setblock ~30 ~124 ~93 dirt
setblock ~30 ~124 ~94 dirt
setblock ~30 ~124 ~95 grass_block
setblock ~30 ~124 ~96 grass_block
setblock ~30 ~125 ~87 dirt
setblock ~30 ~125 ~88 dirt
setblock ~30 ~125 ~89 dirt
setblock ~30 ~125 ~90 dirt
setblock ~30 ~125 ~91 dirt
setblock ~30 ~125 ~92 dirt
setblock ~30 ~125 ~93 grass_block
setblock ~30 ~125 ~94 grass_block
setblock ~30 ~125 ~95 short_grass
setblock ~30 ~126 ~87 grass_block
setblock ~30 ~126 ~88 grass_block
setblock ~30 ~126 ~89 dirt
setblock ~30 ~126 ~90 dirt
setblock ~30 ~126 ~91 grass_block
setblock ~30 ~126 ~92 grass_block
setblock ~30 ~127 ~89 grass_block
setblock ~30 ~127 ~90 grass_block
setblock ~30 ~127 ~92 short_grass
setblock ~31 ~115 ~94 dirt
setblock ~31 ~115 ~95 dirt
setblock ~31 ~115 ~96 dirt
setblock ~31 ~116 ~93 dirt
setblock ~31 ~116 ~94 dirt
setblock ~31 ~116 ~95 dirt
setblock ~31 ~116 ~96 dirt
setblock ~31 ~117 ~89 dirt
setblock ~31 ~117 ~92 dirt
setblock ~31 ~117 ~93 dirt
setblock ~31 ~117 ~94 dirt
setblock ~31 ~117 ~95 dirt
setblock ~31 ~117 ~96 dirt
setblock ~31 ~117 ~97 dirt
setblock ~31 ~117 ~100 dirt
setblock ~31 ~118 ~88 dirt
setblock ~31 ~118 ~89 dirt
setblock ~31 ~118 ~90 dirt
setblock ~31 ~118 ~91 dirt
setblock ~31 ~118 ~92 dirt
setblock ~31 ~118 ~93 dirt
setblock ~31 ~118 ~94 dirt
setblock ~31 ~118 ~95 dirt
setblock ~31 ~118 ~96 dirt
setblock ~31 ~118 ~97 dirt
setblock ~31 ~118 ~98 dirt
setblock ~31 ~118 ~100 dirt
setblock ~31 ~118 ~101 dirt
setblock ~31 ~119 ~87 dirt
setblock ~31 ~119 ~88 dirt
setblock ~31 ~119 ~89 dirt
setblock ~31 ~119 ~90 dirt
setblock ~31 ~119 ~91 dirt
setblock ~31 ~119 ~92 dirt
setblock ~31 ~119 ~93 dirt
setblock ~31 ~119 ~94 dirt
setblock ~31 ~119 ~95 dirt
setblock ~31 ~119 ~96 dirt
setblock ~31 ~119 ~97 dirt
setblock ~31 ~119 ~98 dirt
setblock ~31 ~119 ~99 dirt
setblock ~31 ~119 ~100 dirt
setblock ~31 ~119 ~101 dirt
setblock ~31 ~119 ~103 dirt
setblock ~31 ~119 ~105 dirt
setblock ~31 ~120 ~86 dirt
setblock ~31 ~120 ~87 dirt
setblock ~31 ~120 ~88 dirt
setblock ~31 ~120 ~89 dirt
setblock ~31 ~120 ~90 dirt
setblock ~31 ~120 ~91 dirt
setblock ~31 ~120 ~92 dirt
setblock ~31 ~120 ~93 dirt
setblock ~31 ~120 ~94 dirt
setblock ~31 ~120 ~95 dirt
setblock ~31 ~120 ~96 dirt
setblock ~31 ~120 ~97 dirt
setblock ~31 ~120 ~98 dirt
setblock ~31 ~120 ~99 dirt
setblock ~31 ~120 ~100 dirt
setblock ~31 ~120 ~101 dirt
setblock ~31 ~120 ~102 dirt
setblock ~31 ~120 ~103 dirt
setblock ~31 ~120 ~104 dirt
setblock ~31 ~120 ~105 dirt
setblock ~31 ~120 ~106 dirt
setblock ~31 ~121 ~86 dirt
setblock ~31 ~121 ~87 dirt
setblock ~31 ~121 ~88 dirt
setblock ~31 ~121 ~89 dirt
setblock ~31 ~121 ~90 dirt
setblock ~31 ~121 ~91 dirt
setblock ~31 ~121 ~92 dirt
setblock ~31 ~121 ~93 dirt
setblock ~31 ~121 ~94 dirt
setblock ~31 ~121 ~95 dirt
setblock ~31 ~121 ~96 dirt
setblock ~31 ~121 ~97 dirt
setblock ~31 ~121 ~98 dirt
setblock ~31 ~121 ~99 dirt
setblock ~31 ~121 ~100 dirt
setblock ~31 ~121 ~101 dirt
setblock ~31 ~121 ~102 dirt
setblock ~31 ~121 ~103 dirt
setblock ~31 ~121 ~104 dirt
setblock ~31 ~121 ~105 dirt
setblock ~31 ~121 ~106 dirt
setblock ~31 ~122 ~86 dirt
setblock ~31 ~122 ~87 dirt
setblock ~31 ~122 ~88 dirt
setblock ~31 ~122 ~89 dirt
setblock ~31 ~122 ~90 dirt
setblock ~31 ~122 ~91 dirt
setblock ~31 ~122 ~92 dirt
setblock ~31 ~122 ~93 dirt
setblock ~31 ~122 ~94 dirt
setblock ~31 ~122 ~95 dirt
setblock ~31 ~122 ~96 dirt
setblock ~31 ~122 ~97 dirt
setblock ~31 ~122 ~98 dirt
setblock ~31 ~122 ~99 dirt
setblock ~31 ~122 ~100 grass_block
setblock ~31 ~122 ~101 dirt
setblock ~31 ~122 ~102 dirt
setblock ~31 ~122 ~103 dirt
setblock ~31 ~122 ~104 dirt
setblock ~31 ~122 ~105 dirt
setblock ~31 ~122 ~106 dirt
setblock ~31 ~123 ~86 dirt
setblock ~31 ~123 ~87 dirt
setblock ~31 ~123 ~88 dirt
setblock ~31 ~123 ~89 dirt
setblock ~31 ~123 ~90 dirt
setblock ~31 ~123 ~91 dirt
setblock ~31 ~123 ~92 dirt
setblock ~31 ~123 ~93 dirt
setblock ~31 ~123 ~94 dirt
setblock ~31 ~123 ~95 dirt
setblock ~31 ~123 ~96 dirt
setblock ~31 ~123 ~97 dirt
setblock ~31 ~123 ~98 grass_block
setblock ~31 ~123 ~99 grass_block
setblock ~31 ~123 ~101 grass_block
setblock ~31 ~123 ~102 grass_block
setblock ~31 ~123 ~103 grass_block
setblock ~31 ~123 ~104 grass_block
setblock ~31 ~123 ~105 grass_block
setblock ~31 ~123 ~106 grass_block
setblock ~31 ~124 ~86 dirt
setblock ~31 ~124 ~87 dirt
setblock ~31 ~124 ~88 dirt
setblock ~31 ~124 ~89 dirt
setblock ~31 ~124 ~90 dirt
setblock ~31 ~124 ~91 dirt
setblock ~31 ~124 ~92 dirt
setblock ~31 ~124 ~93 dirt
setblock ~31 ~124 ~94 dirt
setblock ~31 ~124 ~95 dirt
setblock ~31 ~124 ~96 grass_block
setblock ~31 ~124 ~97 grass_block
setblock ~31 ~124 ~98 short_grass
setblock ~31 ~124 ~101 short_grass
setblock ~31 ~124 ~103 short_grass
setblock ~31 ~124 ~105 short_grass
setblock ~31 ~125 ~86 dirt
setblock ~31 ~125 ~87 dirt
setblock ~31 ~125 ~88 dirt
setblock ~31 ~125 ~89 dirt
setblock ~31 ~125 ~90 dirt
setblock ~31 ~125 ~91 dirt
setblock ~31 ~125 ~92 dirt
setblock ~31 ~125 ~93 grass_block
setblock ~31 ~125 ~94 grass_block
setblock ~31 ~125 ~95 grass_block
setblock ~31 ~126 ~86 grass_block
setblock ~31 ~126 ~87 grass_block
setblock ~31 ~126 ~88 grass_block
setblock ~31 ~126 ~89 grass_block
setblock ~31 ~126 ~90 dirt
setblock ~31 ~126 ~91 grass_block
setblock ~31 ~126 ~92 grass_block
setblock ~31 ~126 ~93 short_grass
setblock ~31 ~127 ~90 grass_block
setblock ~31 ~127 ~92 short_grass
setblock ~32 ~114 ~93 dirt
setblock ~32 ~114 ~94 dirt
setblock ~32 ~114 ~95 dirt
setblock ~32 ~114 ~96 dirt
setblock ~32 ~114 ~101 dirt
setblock ~32 ~115 ~89 dirt
setblock ~32 ~115 ~92 dirt
setblock ~32 ~115 ~93 dirt
setblock ~32 ~115 ~94 dirt
setblock ~32 ~115 ~95 dirt
setblock ~32 ~115 ~96 dirt
setblock ~32 ~115 ~97 dirt
setblock ~32 ~115 ~100 dirt
setblock ~32 ~115 ~101 dirt
setblock ~32 ~115 ~103 dirt
setblock ~32 ~116 ~88 dirt
setblock ~32 ~116 ~89 dirt
setblock ~32 ~116 ~90 dirt
setblock ~32 ~116 ~91 dirt
setblock ~32 ~116 ~92 dirt
setblock ~32 ~116 ~93 dirt
setblock ~32 ~116 ~94 dirt
setblock ~32 ~116 ~95 dirt
setblock ~32 ~116 ~96 dirt
setblock ~32 ~116 ~97 dirt
setblock ~32 ~116 ~99 dirt
setblock ~32 ~116 ~100 dirt
setblock ~32 ~116 ~101 dirt
setblock ~32 ~116 ~103 dirt
setblock ~32 ~117 ~88 dirt
setblock ~32 ~117 ~89 dirt
setblock ~32 ~117 ~90 dirt
setblock ~32 ~117 ~91 dirt
setblock ~32 ~117 ~92 dirt
setblock ~32 ~117 ~93 dirt
setblock ~32 ~117 ~94 dirt
setblock ~32 ~117 ~95 dirt
setblock ~32 ~117 ~96 dirt
setblock ~32 ~117 ~97 dirt
setblock ~32 ~117 ~98 dirt
setblock ~32 ~117 ~99 dirt
setblock ~32 ~117 ~100 dirt
setblock ~32 ~117 ~101 dirt
setblock ~32 ~117 ~102 dirt
setblock ~32 ~117 ~103 dirt
setblock ~32 ~117 ~105 dirt
setblock ~32 ~118 ~86 dirt
setblock ~32 ~118 ~87 dirt
setblock ~32 ~118 ~88 dirt
setblock ~32 ~118 ~89 dirt
setblock ~32 ~118 ~90 dirt
setblock ~32 ~118 ~91 dirt
setblock ~32 ~118 ~92 dirt
setblock ~32 ~118 ~93 dirt
setblock ~32 ~118 ~94 dirt
setblock ~32 ~118 ~95 dirt
setblock ~32 ~118 ~96 dirt
setblock ~32 ~118 ~97 dirt
setblock ~32 ~118 ~98 dirt
setblock ~32 ~118 ~99 dirt
setblock ~32 ~118 ~100 dirt
setblock ~32 ~118 ~101 dirt
setblock ~32 ~118 ~102 dirt
setblock ~32 ~118 ~103 dirt
setblock ~32 ~118 ~104 dirt
setblock ~32 ~118 ~105 dirt
setblock ~32 ~119 ~86 dirt
setblock ~32 ~119 ~87 dirt
setblock ~32 ~119 ~88 dirt
setblock ~32 ~119 ~89 dirt
setblock ~32 ~119 ~90 dirt
setblock ~32 ~119 ~91 dirt
setblock ~32 ~119 ~92 dirt
setblock ~32 ~119 ~93 dirt
setblock ~32 ~119 ~94 dirt
setblock ~32 ~119 ~95 dirt
setblock ~32 ~119 ~96 dirt
setblock ~32 ~119 ~97 dirt
setblock ~32 ~119 ~98 dirt
setblock ~32 ~119 ~99 dirt
setblock ~32 ~119 ~100 dirt
setblock ~32 ~119 ~101 dirt
setblock ~32 ~119 ~102 dirt
setblock ~32 ~119 ~103 dirt
setblock ~32 ~119 ~104 dirt
setblock ~32 ~119 ~105 dirt
setblock ~32 ~119 ~106 dirt
setblock ~32 ~120 ~84 dirt
setblock ~32 ~120 ~85 dirt
setblock ~32 ~120 ~86 dirt
setblock ~32 ~120 ~87 dirt
setblock ~32 ~120 ~88 dirt
setblock ~32 ~120 ~89 dirt
setblock ~32 ~120 ~90 dirt
setblock ~32 ~120 ~91 dirt
setblock ~32 ~120 ~92 dirt
setblock ~32 ~120 ~93 dirt
setblock ~32 ~120 ~94 dirt
setblock ~32 ~120 ~95 dirt
setblock ~32 ~120 ~96 dirt
setblock ~32 ~120 ~97 dirt
setblock ~32 ~120 ~98 dirt
setblock ~32 ~120 ~99 dirt
setblock ~32 ~120 ~100 dirt
setblock ~32 ~120 ~101 dirt
setblock ~32 ~120 ~102 dirt
setblock ~32 ~120 ~103 dirt
setblock ~32 ~120 ~104 dirt
setblock ~32 ~120 ~105 dirt
setblock ~32 ~120 ~106 dirt
setblock ~32 ~121 ~76 dirt
setblock ~32 ~121 ~83 dirt
setblock ~32 ~121 ~84 dirt
setblock ~32 ~121 ~85 dirt
setblock ~32 ~121 ~86 dirt
setblock ~32 ~121 ~87 dirt
setblock ~32 ~121 ~88 dirt
setblock ~32 ~121 ~89 dirt
setblock ~32 ~121 ~90 dirt
setblock ~32 ~121 ~91 dirt
setblock ~32 ~121 ~92 dirt
setblock ~32 ~121 ~93 dirt
setblock ~32 ~121 ~94 dirt
setblock ~32 ~121 ~95 dirt
setblock ~32 ~121 ~96 dirt
setblock ~32 ~121 ~97 dirt
setblock ~32 ~121 ~98 dirt
setblock ~32 ~121 ~99 dirt
setblock ~32 ~121 ~100 dirt
setblock ~32 ~121 ~101 dirt
setblock ~32 ~121 ~102 dirt
setblock ~32 ~121 ~103 dirt
setblock ~32 ~121 ~104 dirt
setblock ~32 ~121 ~105 dirt
setblock ~32 ~121 ~106 dirt
setblock ~32 ~121 ~107 dirt
setblock ~32 ~122 ~76 dirt
setblock ~32 ~122 ~83 dirt
setblock ~32 ~122 ~84 dirt
setblock ~32 ~122 ~85 dirt
setblock ~32 ~122 ~86 dirt
setblock ~32 ~122 ~87 dirt
setblock ~32 ~122 ~88 dirt
setblock ~32 ~122 ~89 dirt
setblock ~32 ~122 ~90 dirt
setblock ~32 ~122 ~91 dirt
setblock ~32 ~122 ~92 dirt
setblock ~32 ~122 ~93 dirt
setblock ~32 ~122 ~94 dirt
setblock ~32 ~122 ~95 dirt
setblock ~32 ~122 ~96 dirt
setblock ~32 ~122 ~97 dirt
setblock ~32 ~122 ~98 dirt
setblock ~32 ~122 ~99 dirt
setblock ~32 ~122 ~100 dirt
setblock ~32 ~122 ~101 dirt
setblock ~32 ~122 ~102 dirt
setblock ~32 ~122 ~103 dirt
setblock ~32 ~122 ~104 dirt
setblock ~32 ~122 ~105 dirt
setblock ~32 ~122 ~106 dirt
setblock ~32 ~122 ~107 dirt
setblock ~32 ~123 ~76 dirt
setblock ~32 ~123 ~83 dirt
setblock ~32 ~123 ~84 dirt
setblock ~32 ~123 ~85 dirt
setblock ~32 ~123 ~86 dirt
setblock ~32 ~123 ~87 dirt
setblock ~32 ~123 ~88 dirt
setblock ~32 ~123 ~89 dirt
setblock ~32 ~123 ~90 dirt
setblock ~32 ~123 ~91 dirt
setblock ~32 ~123 ~92 dirt
setblock ~32 ~123 ~93 dirt
setblock ~32 ~123 ~94 dirt
setblock ~32 ~123 ~95 dirt
setblock ~32 ~123 ~96 dirt
setblock ~32 ~123 ~97 dirt
setblock ~32 ~123 ~98 grass_block
setblock ~32 ~123 ~99 grass_block
setblock ~32 ~123 ~100 grass_block
setblock ~32 ~123 ~101 grass_block
setblock ~32 ~123 ~102 grass_block
setblock ~32 ~123 ~103 grass_block
setblock ~32 ~123 ~104 grass_block
setblock ~32 ~123 ~105 dirt
setblock ~32 ~123 ~106 dirt
setblock ~32 ~123 ~107 dirt
setblock ~32 ~124 ~76 dirt
setblock ~32 ~124 ~83 dirt
setblock ~32 ~124 ~84 dirt
setblock ~32 ~124 ~85 dirt
setblock ~32 ~124 ~86 dirt
setblock ~32 ~124 ~87 dirt
setblock ~32 ~124 ~88 dirt
setblock ~32 ~124 ~89 dirt
setblock ~32 ~124 ~90 dirt
setblock ~32 ~124 ~91 dirt
setblock ~32 ~124 ~92 dirt
setblock ~32 ~124 ~93 dirt
setblock ~32 ~124 ~94 dirt
setblock ~32 ~124 ~95 dirt
setblock ~32 ~124 ~96 grass_block
setblock ~32 ~124 ~97 grass_block
setblock ~32 ~124 ~99 short_grass
setblock ~32 ~124 ~100 short_grass
setblock ~32 ~124 ~102 fern
setblock ~32 ~124 ~105 grass_block
setblock ~32 ~124 ~106 grass_block
setblock ~32 ~124 ~107 grass_block
setblock ~32 ~125 ~76 dirt
setblock ~32 ~125 ~83 dirt
setblock ~32 ~125 ~84 dirt
setblock ~32 ~125 ~85 dirt
setblock ~32 ~125 ~86 dirt
setblock ~32 ~125 ~87 dirt
setblock ~32 ~125 ~88 dirt
setblock ~32 ~125 ~89 dirt
setblock ~32 ~125 ~90 dirt
setblock ~32 ~125 ~91 dirt
setblock ~32 ~125 ~92 dirt
setblock ~32 ~125 ~93 dirt
setblock ~32 ~125 ~94 grass_block
setblock ~32 ~125 ~95 grass_block
setblock ~32 ~125 ~96 short_grass
setblock ~32 ~126 ~76 grass_block
setblock ~32 ~126 ~83 grass_block
setblock ~32 ~126 ~84 grass_block
setblock ~32 ~126 ~85 grass_block
setblock ~32 ~126 ~86 grass_block
setblock ~32 ~126 ~87 grass_block
setblock ~32 ~126 ~88 grass_block
setblock ~32 ~126 ~89 grass_block
setblock ~32 ~126 ~90 grass_block
setblock ~32 ~126 ~91 grass_block
setblock ~32 ~126 ~92 grass_block
setblock ~32 ~126 ~93 grass_block
setblock ~32 ~127 ~76 short_grass
setblock ~32 ~127 ~89 short_grass
setblock ~32 ~127 ~93 short_grass
setblock ~33 ~112 ~91 dirt
setblock ~33 ~112 ~95 dirt
setblock ~33 ~112 ~96 dirt
setblock ~33 ~112 ~101 dirt
setblock ~33 ~113 ~90 dirt
setblock ~33 ~113 ~91 dirt
setblock ~33 ~113 ~92 dirt
setblock ~33 ~113 ~93 dirt
setblock ~33 ~113 ~94 dirt
setblock ~33 ~113 ~95 dirt
setblock ~33 ~113 ~96 dirt
setblock ~33 ~113 ~97 dirt
setblock ~33 ~113 ~100 dirt
setblock ~33 ~113 ~101 dirt
setblock ~33 ~113 ~103 dirt
setblock ~33 ~114 ~88 dirt
setblock ~33 ~114 ~89 dirt
setblock ~33 ~114 ~90 dirt
setblock ~33 ~114 ~91 dirt
setblock ~33 ~114 ~92 dirt
setblock ~33 ~114 ~93 dirt
setblock ~33 ~114 ~94 dirt
setblock ~33 ~114 ~95 dirt
setblock ~33 ~114 ~96 dirt
setblock ~33 ~114 ~97 dirt
setblock ~33 ~114 ~100 dirt
setblock ~33 ~114 ~101 dirt
setblock ~33 ~114 ~102 dirt
setblock ~33 ~114 ~103 dirt
setblock ~33 ~114 ~104 dirt
setblock ~33 ~115 ~88 dirt
setblock ~33 ~115 ~89 dirt
setblock ~33 ~115 ~90 dirt
setblock ~33 ~115 ~91 dirt
setblock ~33 ~115 ~92 dirt
setblock ~33 ~115 ~93 dirt
setblock ~33 ~115 ~94 dirt
setblock ~33 ~115 ~95 dirt
setblock ~33 ~115 ~96 dirt
setblock ~33 ~115 ~97 dirt
setblock ~33 ~115 ~98 dirt
setblock ~33 ~115 ~99 dirt
setblock ~33 ~115 ~100 dirt
setblock ~33 ~115 ~101 dirt
setblock ~33 ~115 ~102 dirt
setblock ~33 ~115 ~103 dirt
setblock ~33 ~115 ~104 dirt
setblock ~33 ~116 ~87 dirt
setblock ~33 ~116 ~88 dirt
setblock ~33 ~116 ~89 dirt
setblock ~33 ~116 ~90 dirt
setblock ~33 ~116 ~91 dirt
setblock ~33 ~116 ~92 dirt
setblock ~33 ~116 ~93 dirt
setblock ~33 ~116 ~94 dirt
setblock ~33 ~116 ~95 dirt
setblock ~33 ~116 ~96 dirt
setblock ~33 ~116 ~97 dirt
setblock ~33 ~116 ~98 dirt
setblock ~33 ~116 ~99 dirt
setblock ~33 ~116 ~100 dirt
setblock ~33 ~116 ~101 dirt
setblock ~33 ~116 ~102 dirt
setblock ~33 ~116 ~103 dirt
setblock ~33 ~116 ~104 dirt
setblock ~33 ~116 ~105 dirt
setblock ~33 ~117 ~86 dirt
setblock ~33 ~117 ~87 dirt
setblock ~33 ~117 ~88 dirt
setblock ~33 ~117 ~89 dirt
setblock ~33 ~117 ~90 dirt
setblock ~33 ~117 ~91 dirt
setblock ~33 ~117 ~92 dirt
setblock ~33 ~117 ~93 dirt
setblock ~33 ~117 ~94 dirt
setblock ~33 ~117 ~95 dirt
setblock ~33 ~117 ~96 dirt
setblock ~33 ~117 ~97 dirt
setblock ~33 ~117 ~98 dirt
setblock ~33 ~117 ~99 dirt
setblock ~33 ~117 ~100 dirt
setblock ~33 ~117 ~101 dirt
setblock ~33 ~117 ~102 dirt
setblock ~33 ~117 ~103 dirt
setblock ~33 ~117 ~104 dirt
setblock ~33 ~117 ~105 dirt
setblock ~33 ~117 ~106 dirt
setblock ~33 ~118 ~82 dirt
setblock ~33 ~118 ~84 dirt
setblock ~33 ~118 ~85 dirt
setblock ~33 ~118 ~86 dirt
setblock ~33 ~118 ~87 dirt
setblock ~33 ~118 ~88 dirt
setblock ~33 ~118 ~89 dirt
setblock ~33 ~118 ~90 dirt
setblock ~33 ~118 ~91 dirt
setblock ~33 ~118 ~92 dirt
setblock ~33 ~118 ~93 dirt
setblock ~33 ~118 ~94 dirt
setblock ~33 ~118 ~95 dirt
setblock ~33 ~118 ~96 dirt
setblock ~33 ~118 ~97 dirt
setblock ~33 ~118 ~98 dirt
setblock ~33 ~118 ~99 dirt
setblock ~33 ~118 ~100 dirt
setblock ~33 ~118 ~101 dirt
setblock ~33 ~118 ~102 dirt
setblock ~33 ~118 ~103 dirt
setblock ~33 ~118 ~104 dirt
setblock ~33 ~118 ~105 dirt
setblock ~33 ~118 ~106 dirt
setblock ~33 ~119 ~82 dirt
setblock ~33 ~119 ~84 dirt
setblock ~33 ~119 ~85 dirt
setblock ~33 ~119 ~86 dirt
setblock ~33 ~119 ~87 dirt
setblock ~33 ~119 ~88 dirt
setblock ~33 ~119 ~89 dirt
setblock ~33 ~119 ~90 dirt
setblock ~33 ~119 ~91 dirt
setblock ~33 ~119 ~92 dirt
setblock ~33 ~119 ~93 dirt
setblock ~33 ~119 ~94 dirt
setblock ~33 ~119 ~95 dirt
setblock ~33 ~119 ~96 dirt
setblock ~33 ~119 ~97 dirt
setblock ~33 ~119 ~98 dirt
setblock ~33 ~119 ~99 dirt
setblock ~33 ~119 ~100 dirt
setblock ~33 ~119 ~101 dirt
setblock ~33 ~119 ~102 dirt
setblock ~33 ~119 ~103 dirt
setblock ~33 ~119 ~104 dirt
setblock ~33 ~119 ~105 dirt
setblock ~33 ~119 ~106 dirt
setblock ~33 ~120 ~76 dirt
setblock ~33 ~120 ~77 dirt
setblock ~33 ~120 ~79 dirt
setblock ~33 ~120 ~82 dirt
setblock ~33 ~120 ~83 dirt
setblock ~33 ~120 ~84 dirt
setblock ~33 ~120 ~85 dirt
setblock ~33 ~120 ~86 dirt
setblock ~33 ~120 ~87 dirt
setblock ~33 ~120 ~88 dirt
setblock ~33 ~120 ~89 dirt
setblock ~33 ~120 ~90 dirt
setblock ~33 ~120 ~91 dirt
setblock ~33 ~120 ~92 dirt
setblock ~33 ~120 ~93 dirt
setblock ~33 ~120 ~94 dirt
setblock ~33 ~120 ~95 dirt
setblock ~33 ~120 ~96 dirt
setblock ~33 ~120 ~97 dirt
setblock ~33 ~120 ~98 dirt
setblock ~33 ~120 ~99 dirt
setblock ~33 ~120 ~100 dirt
setblock ~33 ~120 ~101 dirt
setblock ~33 ~120 ~102 dirt
setblock ~33 ~120 ~103 dirt
setblock ~33 ~120 ~104 dirt
setblock ~33 ~120 ~105 dirt
setblock ~33 ~120 ~106 dirt
setblock ~33 ~120 ~107 dirt
setblock ~33 ~121 ~75 dirt
setblock ~33 ~121 ~76 dirt
setblock ~33 ~121 ~77 dirt
setblock ~33 ~121 ~79 dirt
setblock ~33 ~121 ~80 dirt
setblock ~33 ~121 ~81 dirt
setblock ~33 ~121 ~82 dirt
setblock ~33 ~121 ~83 dirt
setblock ~33 ~121 ~84 dirt
setblock ~33 ~121 ~85 dirt
setblock ~33 ~121 ~86 dirt
setblock ~33 ~121 ~87 dirt
setblock ~33 ~121 ~88 dirt
setblock ~33 ~121 ~89 dirt
setblock ~33 ~121 ~90 dirt
setblock ~33 ~121 ~91 dirt
setblock ~33 ~121 ~92 dirt
setblock ~33 ~121 ~93 dirt
setblock ~33 ~121 ~94 dirt
setblock ~33 ~121 ~95 dirt
setblock ~33 ~121 ~96 dirt
setblock ~33 ~121 ~97 dirt
setblock ~33 ~121 ~98 dirt
setblock ~33 ~121 ~99 dirt
setblock ~33 ~121 ~100 dirt
setblock ~33 ~121 ~101 dirt
setblock ~33 ~121 ~102 dirt
setblock ~33 ~121 ~103 dirt
setblock ~33 ~121 ~104 dirt
setblock ~33 ~121 ~105 dirt
setblock ~33 ~121 ~106 dirt
setblock ~33 ~121 ~107 dirt
setblock ~33 ~121 ~108 dirt
setblock ~33 ~122 ~75 dirt
setblock ~33 ~122 ~76 dirt
setblock ~33 ~122 ~77 dirt
setblock ~33 ~122 ~79 dirt
setblock ~33 ~122 ~80 dirt
setblock ~33 ~122 ~81 dirt
setblock ~33 ~122 ~82 dirt
setblock ~33 ~122 ~83 dirt
setblock ~33 ~122 ~84 dirt
setblock ~33 ~122 ~85 dirt
setblock ~33 ~122 ~86 dirt
setblock ~33 ~122 ~87 dirt
setblock ~33 ~122 ~88 dirt
setblock ~33 ~122 ~89 dirt
setblock ~33 ~122 ~90 dirt
setblock ~33 ~122 ~91 dirt
setblock ~33 ~122 ~92 dirt
setblock ~33 ~122 ~93 dirt
setblock ~33 ~122 ~94 dirt
setblock ~33 ~122 ~95 dirt
setblock ~33 ~122 ~96 dirt
setblock ~33 ~122 ~97 dirt
setblock ~33 ~122 ~98 dirt
setblock ~33 ~122 ~99 dirt
setblock ~33 ~122 ~100 dirt
setblock ~33 ~122 ~101 dirt
setblock ~33 ~122 ~102 dirt
setblock ~33 ~122 ~103 dirt
setblock ~33 ~122 ~104 dirt
setblock ~33 ~122 ~105 dirt
setblock ~33 ~122 ~106 dirt
setblock ~33 ~122 ~107 dirt
setblock ~33 ~122 ~108 dirt
setblock ~33 ~123 ~75 dirt
setblock ~33 ~123 ~76 dirt
setblock ~33 ~123 ~77 dirt
setblock ~33 ~123 ~79 dirt
setblock ~33 ~123 ~80 dirt
setblock ~33 ~123 ~81 dirt
setblock ~33 ~123 ~82 dirt
setblock ~33 ~123 ~83 dirt
setblock ~33 ~123 ~84 dirt
setblock ~33 ~123 ~85 dirt
setblock ~33 ~123 ~86 dirt
setblock ~33 ~123 ~87 dirt
setblock ~33 ~123 ~88 dirt
setblock ~33 ~123 ~89 dirt
setblock ~33 ~123 ~90 dirt
setblock ~33 ~123 ~91 dirt
setblock ~33 ~123 ~92 dirt
setblock ~33 ~123 ~93 dirt
setblock ~33 ~123 ~94 dirt
setblock ~33 ~123 ~95 dirt
setblock ~33 ~123 ~96 dirt
setblock ~33 ~123 ~97 dirt
setblock ~33 ~123 ~98 dirt
setblock ~33 ~123 ~99 grass_block
setblock ~33 ~123 ~100 grass_block
setblock ~33 ~123 ~101 grass_block
setblock ~33 ~123 ~102 grass_block
setblock ~33 ~123 ~103 dirt
setblock ~33 ~123 ~104 dirt
setblock ~33 ~123 ~105 dirt
setblock ~33 ~123 ~106 dirt
setblock ~33 ~123 ~107 dirt
setblock ~33 ~123 ~108 dirt
setblock ~33 ~124 ~75 dirt
setblock ~33 ~124 ~76 dirt
setblock ~33 ~124 ~77 dirt
setblock ~33 ~124 ~79 dirt
setblock ~33 ~124 ~80 dirt
setblock ~33 ~124 ~81 dirt
setblock ~33 ~124 ~82 dirt
setblock ~33 ~124 ~83 dirt
setblock ~33 ~124 ~84 dirt
setblock ~33 ~124 ~85 dirt
setblock ~33 ~124 ~86 dirt
setblock ~33 ~124 ~87 dirt
setblock ~33 ~124 ~88 dirt
setblock ~33 ~124 ~89 dirt
setblock ~33 ~124 ~90 dirt
setblock ~33 ~124 ~91 dirt
setblock ~33 ~124 ~92 dirt
setblock ~33 ~124 ~93 dirt
setblock ~33 ~124 ~94 dirt
setblock ~33 ~124 ~95 dirt
setblock ~33 ~124 ~96 dirt
setblock ~33 ~124 ~97 grass_block
setblock ~33 ~124 ~98 grass_block
setblock ~33 ~124 ~103 grass_block
setblock ~33 ~124 ~104 grass_block
setblock ~33 ~124 ~105 grass_block
setblock ~33 ~124 ~106 grass_block
setblock ~33 ~124 ~107 grass_block
setblock ~33 ~124 ~108 grass_block
setblock ~33 ~125 ~75 dirt
setblock ~33 ~125 ~76 dirt
setblock ~33 ~125 ~77 dirt
setblock ~33 ~125 ~79 dirt
setblock ~33 ~125 ~80 dirt
setblock ~33 ~125 ~81 dirt
setblock ~33 ~125 ~82 dirt
setblock ~33 ~125 ~83 dirt
setblock ~33 ~125 ~84 dirt
setblock ~33 ~125 ~85 dirt
setblock ~33 ~125 ~86 dirt
setblock ~33 ~125 ~87 dirt
setblock ~33 ~125 ~88 dirt
setblock ~33 ~125 ~89 dirt
setblock ~33 ~125 ~90 dirt
setblock ~33 ~125 ~91 dirt
setblock ~33 ~125 ~92 dirt
setblock ~33 ~125 ~93 dirt
setblock ~33 ~125 ~94 grass_block
setblock ~33 ~125 ~95 grass_block
setblock ~33 ~125 ~96 grass_block
setblock ~33 ~125 ~107 short_grass
setblock ~33 ~125 ~108 short_grass
setblock ~33 ~126 ~75 grass_block
setblock ~33 ~126 ~76 grass_block
setblock ~33 ~126 ~77 grass_block
setblock ~33 ~126 ~79 grass_block
setblock ~33 ~126 ~80 grass_block
setblock ~33 ~126 ~81 grass_block
setblock ~33 ~126 ~82 grass_block
setblock ~33 ~126 ~83 grass_block
setblock ~33 ~126 ~84 grass_block
setblock ~33 ~126 ~85 grass_block
setblock ~33 ~126 ~86 grass_block
setblock ~33 ~126 ~87 grass_block
setblock ~33 ~126 ~88 grass_block
setblock ~33 ~126 ~89 grass_block
setblock ~33 ~126 ~90 grass_block
setblock ~33 ~126 ~91 grass_block
setblock ~33 ~126 ~92 grass_block
setblock ~33 ~126 ~93 grass_block
setblock ~33 ~126 ~96 fern
setblock ~33 ~127 ~77 short_grass
setblock ~33 ~127 ~81 poppy
setblock ~33 ~127 ~85 short_grass
setblock ~33 ~127 ~91 short_grass
setblock ~34 ~109 ~92 dirt
setblock ~34 ~109 ~93 dirt
setblock ~34 ~110 ~89 dirt
setblock ~34 ~110 ~92 dirt
setblock ~34 ~110 ~93 dirt
setblock ~34 ~110 ~94 dirt
setblock ~34 ~110 ~101 dirt
setblock ~34 ~111 ~89 dirt
setblock ~34 ~111 ~90 dirt
setblock ~34 ~111 ~91 dirt
setblock ~34 ~111 ~92 dirt
setblock ~34 ~111 ~93 dirt
setblock ~34 ~111 ~94 dirt
setblock ~34 ~111 ~95 dirt
setblock ~34 ~111 ~96 dirt
setblock ~34 ~111 ~101 dirt
setblock ~34 ~111 ~102 dirt
setblock ~34 ~111 ~103 dirt
setblock ~34 ~112 ~88 dirt
setblock ~34 ~112 ~89 dirt
setblock ~34 ~112 ~90 dirt
setblock ~34 ~112 ~91 dirt
setblock ~34 ~112 ~92 dirt
setblock ~34 ~112 ~93 dirt
setblock ~34 ~112 ~94 dirt
setblock ~34 ~112 ~95 dirt
setblock ~34 ~112 ~96 dirt
setblock ~34 ~112 ~97 dirt
setblock ~34 ~112 ~100 dirt
setblock ~34 ~112 ~101 dirt
setblock ~34 ~112 ~102 dirt
setblock ~34 ~112 ~103 dirt
setblock ~34 ~113 ~88 dirt
setblock ~34 ~113 ~89 dirt
setblock ~34 ~113 ~90 dirt
setblock ~34 ~113 ~91 dirt
setblock ~34 ~113 ~92 dirt
setblock ~34 ~113 ~93 dirt
setblock ~34 ~113 ~94 dirt
setblock ~34 ~113 ~95 dirt
setblock ~34 ~113 ~96 dirt
setblock ~34 ~113 ~97 dirt
setblock ~34 ~113 ~98 dirt
setblock ~34 ~113 ~99 dirt
setblock ~34 ~113 ~100 dirt
setblock ~34 ~113 ~101 dirt
setblock ~34 ~113 ~102 dirt
setblock ~34 ~113 ~103 dirt
setblock ~34 ~113 ~104 dirt
setblock ~34 ~114 ~87 dirt
setblock ~34 ~114 ~88 dirt
setblock ~34 ~114 ~89 dirt
setblock ~34 ~114 ~90 dirt
setblock ~34 ~114 ~91 dirt
setblock ~34 ~114 ~92 dirt
setblock ~34 ~114 ~93 dirt
setblock ~34 ~114 ~94 dirt
setblock ~34 ~114 ~95 dirt
setblock ~34 ~114 ~96 dirt
setblock ~34 ~114 ~97 dirt
setblock ~34 ~114 ~98 dirt
setblock ~34 ~114 ~99 dirt
setblock ~34 ~114 ~100 dirt
setblock ~34 ~114 ~101 dirt
setblock ~34 ~114 ~102 dirt
setblock ~34 ~114 ~103 dirt
setblock ~34 ~114 ~104 dirt
setblock ~34 ~114 ~105 dirt
setblock ~34 ~115 ~84 dirt
setblock ~34 ~115 ~85 dirt
setblock ~34 ~115 ~86 dirt
setblock ~34 ~115 ~87 dirt
setblock ~34 ~115 ~88 dirt
setblock ~34 ~115 ~89 dirt
setblock ~34 ~115 ~90 dirt
setblock ~34 ~115 ~91 dirt
setblock ~34 ~115 ~92 dirt
setblock ~34 ~115 ~93 dirt
setblock ~34 ~115 ~94 dirt
setblock ~34 ~115 ~95 dirt
setblock ~34 ~115 ~96 dirt
setblock ~34 ~115 ~97 dirt
setblock ~34 ~115 ~98 dirt
setblock ~34 ~115 ~99 dirt
setblock ~34 ~115 ~100 dirt
setblock ~34 ~115 ~101 dirt
setblock ~34 ~115 ~102 dirt
setblock ~34 ~115 ~103 dirt
setblock ~34 ~115 ~104 dirt
setblock ~34 ~115 ~105 dirt
setblock ~34 ~116 ~82 dirt
setblock ~34 ~116 ~83 dirt
setblock ~34 ~116 ~84 dirt
setblock ~34 ~116 ~85 dirt
setblock ~34 ~116 ~86 dirt
setblock ~34 ~116 ~87 dirt
setblock ~34 ~116 ~88 dirt
setblock ~34 ~116 ~89 dirt
setblock ~34 ~116 ~90 dirt
setblock ~34 ~116 ~91 dirt
setblock ~34 ~116 ~92 dirt
setblock ~34 ~116 ~93 dirt
setblock ~34 ~116 ~94 dirt
setblock ~34 ~116 ~95 dirt
setblock ~34 ~116 ~96 dirt
setblock ~34 ~116 ~97 dirt
setblock ~34 ~116 ~98 dirt
setblock ~34 ~116 ~99 dirt
setblock ~34 ~116 ~100 dirt
setblock ~34 ~116 ~101 dirt
setblock ~34 ~116 ~102 dirt
setblock ~34 ~116 ~103 dirt
setblock ~34 ~116 ~104 dirt
setblock ~34 ~116 ~105 dirt
setblock ~34 ~116 ~106 dirt
setblock ~34 ~117 ~82 dirt
setblock ~34 ~117 ~83 dirt
setblock ~34 ~117 ~84 dirt
setblock ~34 ~117 ~85 dirt
setblock ~34 ~117 ~86 dirt
setblock ~34 ~117 ~87 dirt
setblock ~34 ~117 ~88 dirt
setblock ~34 ~117 ~89 dirt
setblock ~34 ~117 ~90 dirt
setblock ~34 ~117 ~91 dirt
setblock ~34 ~117 ~92 dirt
setblock ~34 ~117 ~93 dirt
setblock ~34 ~117 ~94 dirt
setblock ~34 ~117 ~95 dirt
setblock ~34 ~117 ~96 dirt
setblock ~34 ~117 ~97 dirt
setblock ~34 ~117 ~98 dirt
setblock ~34 ~117 ~99 dirt
setblock ~34 ~117 ~100 dirt
setblock ~34 ~117 ~101 dirt
setblock ~34 ~117 ~102 dirt
setblock ~34 ~117 ~103 dirt
setblock ~34 ~117 ~104 dirt
setblock ~34 ~117 ~105 dirt
setblock ~34 ~117 ~106 dirt
setblock ~34 ~118 ~76 dirt
setblock ~34 ~118 ~77 dirt
setblock ~34 ~118 ~79 dirt
setblock ~34 ~118 ~81 dirt
setblock ~34 ~118 ~82 dirt
setblock ~34 ~118 ~83 dirt
setblock ~34 ~118 ~84 dirt
setblock ~34 ~118 ~85 dirt
setblock ~34 ~118 ~86 dirt
setblock ~34 ~118 ~87 dirt
setblock ~34 ~118 ~88 dirt
setblock ~34 ~118 ~89 dirt
setblock ~34 ~118 ~90 dirt
setblock ~34 ~118 ~91 dirt
setblock ~34 ~118 ~92 dirt
setblock ~34 ~118 ~93 dirt
setblock ~34 ~118 ~94 dirt
setblock ~34 ~118 ~95 dirt
setblock ~34 ~118 ~96 dirt
setblock ~34 ~118 ~97 dirt
setblock ~34 ~118 ~98 dirt
setblock ~34 ~118 ~99 dirt
setblock ~34 ~118 ~100 dirt
setblock ~34 ~118 ~101 dirt
setblock ~34 ~118 ~102 dirt
setblock ~34 ~118 ~103 dirt
setblock ~34 ~118 ~104 dirt
setblock ~34 ~118 ~105 dirt
setblock ~34 ~118 ~106 dirt
setblock ~34 ~118 ~107 dirt
setblock ~34 ~119 ~76 dirt
setblock ~34 ~119 ~77 dirt
setblock ~34 ~119 ~78 dirt
setblock ~34 ~119 ~79 dirt
setblock ~34 ~119 ~81 dirt
setblock ~34 ~119 ~82 dirt
setblock ~34 ~119 ~83 dirt
setblock ~34 ~119 ~84 dirt
setblock ~34 ~119 ~85 dirt
setblock ~34 ~119 ~86 dirt
setblock ~34 ~119 ~87 dirt
setblock ~34 ~119 ~88 dirt
setblock ~34 ~119 ~89 dirt
setblock ~34 ~119 ~90 dirt
setblock ~34 ~119 ~91 dirt
setblock ~34 ~119 ~92 dirt
setblock ~34 ~119 ~93 dirt
setblock ~34 ~119 ~94 dirt
setblock ~34 ~119 ~95 dirt
setblock ~34 ~119 ~96 dirt
setblock ~34 ~119 ~97 dirt
setblock ~34 ~119 ~98 dirt
setblock ~34 ~119 ~99 dirt
setblock ~34 ~119 ~100 dirt
setblock ~34 ~119 ~101 dirt
setblock ~34 ~119 ~102 dirt
setblock ~34 ~119 ~103 dirt
setblock ~34 ~119 ~104 dirt
setblock ~34 ~119 ~105 dirt
setblock ~34 ~119 ~106 dirt
setblock ~34 ~119 ~107 dirt
setblock ~34 ~120 ~75 dirt
setblock ~34 ~120 ~76 dirt
setblock ~34 ~120 ~77 dirt
setblock ~34 ~120 ~78 dirt
setblock ~34 ~120 ~79 dirt
setblock ~34 ~120 ~80 dirt
setblock ~34 ~120 ~81 dirt
setblock ~34 ~120 ~82 dirt
setblock ~34 ~120 ~83 dirt
setblock ~34 ~120 ~84 dirt
setblock ~34 ~120 ~85 dirt
setblock ~34 ~120 ~86 dirt
setblock ~34 ~120 ~87 dirt
setblock ~34 ~120 ~88 dirt
setblock ~34 ~120 ~89 dirt
setblock ~34 ~120 ~90 dirt
setblock ~34 ~120 ~91 dirt
setblock ~34 ~120 ~92 dirt
setblock ~34 ~120 ~93 dirt
setblock ~34 ~120 ~94 dirt
setblock ~34 ~120 ~95 dirt
setblock ~34 ~120 ~96 dirt
setblock ~34 ~120 ~97 dirt
setblock ~34 ~120 ~98 dirt
setblock ~34 ~120 ~99 dirt
setblock ~34 ~120 ~100 dirt
setblock ~34 ~120 ~101 dirt
setblock ~34 ~120 ~102 dirt
setblock ~34 ~120 ~103 dirt
setblock ~34 ~120 ~104 dirt
setblock ~34 ~120 ~105 dirt
setblock ~34 ~120 ~106 dirt
setblock ~34 ~120 ~107 dirt
setblock ~34 ~121 ~75 dirt
setblock ~34 ~121 ~76 dirt
setblock ~34 ~121 ~77 dirt
setblock ~34 ~121 ~78 dirt
setblock ~34 ~121 ~79 dirt
setblock ~34 ~121 ~80 dirt
setblock ~34 ~121 ~81 dirt
setblock ~34 ~121 ~82 dirt
setblock ~34 ~121 ~83 dirt
setblock ~34 ~121 ~84 dirt
setblock ~34 ~121 ~85 dirt
setblock ~34 ~121 ~86 dirt
setblock ~34 ~121 ~87 dirt
setblock ~34 ~121 ~88 dirt
setblock ~34 ~121 ~89 dirt
setblock ~34 ~121 ~90 dirt
setblock ~34 ~121 ~91 dirt
setblock ~34 ~121 ~92 dirt
setblock ~34 ~121 ~93 dirt
setblock ~34 ~121 ~94 dirt
setblock ~34 ~121 ~95 dirt
setblock ~34 ~121 ~96 dirt
setblock ~34 ~121 ~97 dirt
setblock ~34 ~121 ~98 dirt
setblock ~34 ~121 ~99 dirt
setblock ~34 ~121 ~100 dirt
setblock ~34 ~121 ~101 dirt
setblock ~34 ~121 ~102 dirt
setblock ~34 ~121 ~103 dirt
setblock ~34 ~121 ~104 dirt
setblock ~34 ~121 ~105 dirt
setblock ~34 ~121 ~106 dirt
setblock ~34 ~121 ~107 dirt
setblock ~34 ~121 ~108 dirt
setblock ~34 ~122 ~75 dirt
setblock ~34 ~122 ~76 dirt
setblock ~34 ~122 ~77 dirt
setblock ~34 ~122 ~78 dirt
setblock ~34 ~122 ~79 dirt
setblock ~34 ~122 ~80 dirt
setblock ~34 ~122 ~81 dirt
setblock ~34 ~122 ~82 dirt
setblock ~34 ~122 ~83 dirt
setblock ~34 ~122 ~84 dirt
setblock ~34 ~122 ~85 dirt
setblock ~34 ~122 ~86 dirt
setblock ~34 ~122 ~87 dirt
setblock ~34 ~122 ~88 dirt
setblock ~34 ~122 ~89 dirt
setblock ~34 ~122 ~90 dirt
setblock ~34 ~122 ~91 dirt
setblock ~34 ~122 ~92 dirt
setblock ~34 ~122 ~93 dirt
setblock ~34 ~122 ~94 dirt
setblock ~34 ~122 ~95 dirt
setblock ~34 ~122 ~96 dirt
setblock ~34 ~122 ~97 dirt
setblock ~34 ~122 ~98 dirt
setblock ~34 ~122 ~99 dirt
setblock ~34 ~122 ~100 dirt
setblock ~34 ~122 ~101 dirt
setblock ~34 ~122 ~102 dirt
setblock ~34 ~122 ~103 dirt
setblock ~34 ~122 ~104 dirt
setblock ~34 ~122 ~105 dirt
setblock ~34 ~122 ~106 dirt
setblock ~34 ~122 ~107 dirt
setblock ~34 ~122 ~108 dirt
setblock ~34 ~123 ~75 dirt
setblock ~34 ~123 ~76 dirt
setblock ~34 ~123 ~77 dirt
setblock ~34 ~123 ~78 dirt
setblock ~34 ~123 ~79 dirt
setblock ~34 ~123 ~80 dirt
setblock ~34 ~123 ~81 dirt
setblock ~34 ~123 ~82 dirt
setblock ~34 ~123 ~83 dirt
setblock ~34 ~123 ~84 dirt
setblock ~34 ~123 ~85 dirt
setblock ~34 ~123 ~86 dirt
setblock ~34 ~123 ~87 dirt
setblock ~34 ~123 ~88 dirt
setblock ~34 ~123 ~89 dirt
setblock ~34 ~123 ~90 dirt
setblock ~34 ~123 ~91 dirt
setblock ~34 ~123 ~92 dirt
setblock ~34 ~123 ~93 dirt
setblock ~34 ~123 ~94 dirt
setblock ~34 ~123 ~95 dirt
setblock ~34 ~123 ~96 dirt
setblock ~34 ~123 ~97 dirt
setblock ~34 ~123 ~98 dirt
setblock ~34 ~123 ~99 dirt
setblock ~34 ~123 ~100 grass_block
setblock ~34 ~123 ~101 dirt
setblock ~34 ~123 ~102 dirt
setblock ~34 ~123 ~103 dirt
setblock ~34 ~123 ~104 dirt
setblock ~34 ~123 ~105 dirt
setblock ~34 ~123 ~106 dirt
setblock ~34 ~123 ~107 dirt
setblock ~34 ~123 ~108 dirt
setblock ~34 ~124 ~75 dirt
setblock ~34 ~124 ~76 dirt
setblock ~34 ~124 ~77 dirt
setblock ~34 ~124 ~78 dirt
setblock ~34 ~124 ~79 dirt
setblock ~34 ~124 ~80 dirt
setblock ~34 ~124 ~81 dirt
setblock ~34 ~124 ~82 dirt
setblock ~34 ~124 ~83 dirt
setblock ~34 ~124 ~84 dirt
setblock ~34 ~124 ~85 dirt
setblock ~34 ~124 ~86 dirt
setblock ~34 ~124 ~87 dirt
setblock ~34 ~124 ~88 dirt
setblock ~34 ~124 ~89 dirt
setblock ~34 ~124 ~90 dirt
setblock ~34 ~124 ~91 dirt
setblock ~34 ~124 ~92 dirt
setblock ~34 ~124 ~93 dirt
setblock ~34 ~124 ~94 dirt
setblock ~34 ~124 ~95 dirt
setblock ~34 ~124 ~96 dirt
setblock ~34 ~124 ~97 grass_block
setblock ~34 ~124 ~98 grass_block
setblock ~34 ~124 ~99 grass_block
setblock ~34 ~124 ~101 grass_block
setblock ~34 ~124 ~102 grass_block
setblock ~34 ~124 ~103 grass_block
setblock ~34 ~124 ~104 grass_block
setblock ~34 ~124 ~105 grass_block
setblock ~34 ~124 ~106 grass_block
setblock ~34 ~124 ~107 grass_block
setblock ~34 ~124 ~108 grass_block
setblock ~34 ~125 ~75 dirt
setblock ~34 ~125 ~76 dirt
setblock ~34 ~125 ~77 dirt
setblock ~34 ~125 ~78 dirt
setblock ~34 ~125 ~79 dirt
setblock ~34 ~125 ~80 dirt
setblock ~34 ~125 ~81 dirt
setblock ~34 ~125 ~82 dirt
setblock ~34 ~125 ~83 dirt
setblock ~34 ~125 ~84 dirt
setblock ~34 ~125 ~85 dirt
setblock ~34 ~125 ~86 dirt
setblock ~34 ~125 ~87 dirt
setblock ~34 ~125 ~88 dirt
setblock ~34 ~125 ~89 dirt
setblock ~34 ~125 ~90 dirt
setblock ~34 ~125 ~91 dirt
setblock ~34 ~125 ~92 dirt
setblock ~34 ~125 ~93 dirt
setblock ~34 ~125 ~94 grass_block
setblock ~34 ~125 ~95 grass_block
setblock ~34 ~125 ~96 grass_block
setblock ~34 ~125 ~97 short_grass
setblock ~34 ~125 ~104 short_grass
setblock ~34 ~125 ~105 short_grass
setblock ~34 ~126 ~75 grass_block
setblock ~34 ~126 ~76 grass_block
setblock ~34 ~126 ~77 grass_block
setblock ~34 ~126 ~78 grass_block
setblock ~34 ~126 ~79 grass_block
setblock ~34 ~126 ~80 dirt
setblock ~34 ~126 ~81 dirt
setblock ~34 ~126 ~82 dirt
setblock ~34 ~126 ~83 grass_block
setblock ~34 ~126 ~84 grass_block
setblock ~34 ~126 ~85 grass_block
setblock ~34 ~126 ~86 grass_block
setblock ~34 ~126 ~87 grass_block
setblock ~34 ~126 ~88 grass_block
setblock ~34 ~126 ~89 grass_block
setblock ~34 ~126 ~90 grass_block
setblock ~34 ~126 ~91 grass_block
setblock ~34 ~126 ~92 grass_block
setblock ~34 ~126 ~93 grass_block
setblock ~34 ~127 ~77 fern
setblock ~34 ~127 ~78 short_grass
setblock ~34 ~127 ~80 grass_block
setblock ~34 ~127 ~81 grass_block
setblock ~34 ~127 ~82 grass_block
setblock ~34 ~127 ~83 short_grass
setblock ~34 ~127 ~88 short_grass
setblock ~34 ~127 ~92 short_grass
setblock ~34 ~127 ~93 short_grass
setblock ~34 ~128 ~81 short_grass
setblock ~35 ~106 ~93 dirt
setblock ~35 ~107 ~93 dirt
setblock ~35 ~107 ~102 dirt
setblock ~35 ~107 ~103 dirt
setblock ~35 ~108 ~92 dirt
setblock ~35 ~108 ~93 dirt
setblock ~35 ~108 ~94 dirt
setblock ~35 ~108 ~101 dirt
setblock ~35 ~108 ~102 dirt
setblock ~35 ~108 ~103 dirt
setblock ~35 ~109 ~89 dirt
setblock ~35 ~109 ~91 dirt
setblock ~35 ~109 ~92 dirt
setblock ~35 ~109 ~93 dirt
setblock ~35 ~109 ~94 dirt
setblock ~35 ~109 ~95 dirt
setblock ~35 ~109 ~96 dirt
setblock ~35 ~109 ~101 dirt
setblock ~35 ~109 ~102 dirt
setblock ~35 ~109 ~103 dirt
setblock ~35 ~110 ~88 dirt
setblock ~35 ~110 ~89 dirt
setblock ~35 ~110 ~90 dirt
setblock ~35 ~110 ~91 dirt
setblock ~35 ~110 ~92 dirt
setblock ~35 ~110 ~93 dirt
setblock ~35 ~110 ~94 dirt
setblock ~35 ~110 ~95 dirt
setblock ~35 ~110 ~96 dirt
setblock ~35 ~110 ~100 dirt
setblock ~35 ~110 ~101 dirt
setblock ~35 ~110 ~102 dirt
setblock ~35 ~110 ~103 dirt
setblock ~35 ~111 ~88 dirt
setblock ~35 ~111 ~89 dirt
setblock ~35 ~111 ~90 dirt
setblock ~35 ~111 ~91 dirt
setblock ~35 ~111 ~92 dirt
setblock ~35 ~111 ~93 dirt
setblock ~35 ~111 ~94 dirt
setblock ~35 ~111 ~95 dirt
setblock ~35 ~111 ~96 dirt
setblock ~35 ~111 ~97 dirt
setblock ~35 ~111 ~100 dirt
setblock ~35 ~111 ~101 dirt
setblock ~35 ~111 ~102 dirt
setblock ~35 ~111 ~103 dirt
setblock ~35 ~111 ~104 dirt
setblock ~35 ~112 ~87 dirt
setblock ~35 ~112 ~88 dirt
setblock ~35 ~112 ~89 dirt
setblock ~35 ~112 ~90 dirt
setblock ~35 ~112 ~91 dirt
setblock ~35 ~112 ~92 dirt
setblock ~35 ~112 ~93 dirt
setblock ~35 ~112 ~94 dirt
setblock ~35 ~112 ~95 dirt
setblock ~35 ~112 ~96 dirt
setblock ~35 ~112 ~97 dirt
setblock ~35 ~112 ~99 dirt
setblock ~35 ~112 ~100 dirt
setblock ~35 ~112 ~101 dirt
setblock ~35 ~112 ~102 dirt
setblock ~35 ~112 ~103 dirt
setblock ~35 ~112 ~104 dirt
setblock ~35 ~112 ~105 dirt
setblock ~35 ~113 ~82 dirt
setblock ~35 ~113 ~85 dirt
setblock ~35 ~113 ~86 dirt
setblock ~35 ~113 ~87 dirt
setblock ~35 ~113 ~88 dirt
setblock ~35 ~113 ~89 dirt
setblock ~35 ~113 ~90 dirt
setblock ~35 ~113 ~91 dirt
setblock ~35 ~113 ~92 dirt
setblock ~35 ~113 ~93 dirt
setblock ~35 ~113 ~94 dirt
setblock ~35 ~113 ~95 dirt
setblock ~35 ~113 ~96 dirt
setblock ~35 ~113 ~97 dirt
setblock ~35 ~113 ~98 dirt
setblock ~35 ~113 ~99 dirt
setblock ~35 ~113 ~100 dirt
setblock ~35 ~113 ~101 dirt
setblock ~35 ~113 ~102 dirt
setblock ~35 ~113 ~103 dirt
setblock ~35 ~113 ~104 dirt
setblock ~35 ~113 ~105 dirt
setblock ~35 ~114 ~82 dirt
setblock ~35 ~114 ~84 dirt
setblock ~35 ~114 ~85 dirt
setblock ~35 ~114 ~86 dirt
setblock ~35 ~114 ~87 dirt
setblock ~35 ~114 ~88 dirt
setblock ~35 ~114 ~89 dirt
setblock ~35 ~114 ~90 dirt
setblock ~35 ~114 ~91 dirt
setblock ~35 ~114 ~92 dirt
setblock ~35 ~114 ~93 dirt
setblock ~35 ~114 ~94 dirt
setblock ~35 ~114 ~95 dirt
setblock ~35 ~114 ~96 dirt
setblock ~35 ~114 ~97 dirt
setblock ~35 ~114 ~98 dirt
setblock ~35 ~114 ~99 dirt
setblock ~35 ~114 ~100 dirt
setblock ~35 ~114 ~101 dirt
setblock ~35 ~114 ~102 dirt
setblock ~35 ~114 ~103 dirt
setblock ~35 ~114 ~104 dirt
setblock ~35 ~114 ~105 dirt
setblock ~35 ~114 ~106 dirt
setblock ~35 ~115 ~77 dirt
setblock ~35 ~115 ~82 dirt
setblock ~35 ~115 ~83 dirt
setblock ~35 ~115 ~84 dirt
setblock ~35 ~115 ~85 dirt
setblock ~35 ~115 ~86 dirt
setblock ~35 ~115 ~87 dirt
setblock ~35 ~115 ~88 dirt
setblock ~35 ~115 ~89 dirt
setblock ~35 ~115 ~90 dirt
setblock ~35 ~115 ~91 dirt
setblock ~35 ~115 ~92 dirt
setblock ~35 ~115 ~93 dirt
setblock ~35 ~115 ~94 dirt
setblock ~35 ~115 ~95 dirt
setblock ~35 ~115 ~96 dirt
setblock ~35 ~115 ~97 dirt
setblock ~35 ~115 ~98 dirt
setblock ~35 ~115 ~99 dirt
setblock ~35 ~115 ~100 dirt
setblock ~35 ~115 ~101 dirt
setblock ~35 ~115 ~102 dirt
setblock ~35 ~115 ~103 dirt
setblock ~35 ~115 ~104 dirt
setblock ~35 ~115 ~105 dirt
setblock ~35 ~115 ~106 dirt
setblock ~35 ~115 ~107 dirt
setblock ~35 ~116 ~76 dirt
setblock ~35 ~116 ~77 dirt
setblock ~35 ~116 ~81 dirt
setblock ~35 ~116 ~82 dirt
setblock ~35 ~116 ~83 dirt
setblock ~35 ~116 ~84 dirt
setblock ~35 ~116 ~85 dirt
setblock ~35 ~116 ~86 dirt
setblock ~35 ~116 ~87 dirt
setblock ~35 ~116 ~88 dirt
setblock ~35 ~116 ~89 dirt
setblock ~35 ~116 ~90 dirt
setblock ~35 ~116 ~91 dirt
setblock ~35 ~116 ~92 dirt
setblock ~35 ~116 ~93 dirt
setblock ~35 ~116 ~94 dirt
setblock ~35 ~116 ~95 dirt
setblock ~35 ~116 ~96 dirt
setblock ~35 ~116 ~97 dirt
setblock ~35 ~116 ~98 dirt
setblock ~35 ~116 ~99 dirt
setblock ~35 ~116 ~100 dirt
setblock ~35 ~116 ~101 dirt
setblock ~35 ~116 ~102 dirt
setblock ~35 ~116 ~103 dirt
setblock ~35 ~116 ~104 dirt
setblock ~35 ~116 ~105 dirt
setblock ~35 ~116 ~106 dirt
setblock ~35 ~116 ~107 dirt
setblock ~35 ~117 ~76 dirt
setblock ~35 ~117 ~77 dirt
setblock ~35 ~117 ~78 dirt
setblock ~35 ~117 ~79 dirt
setblock ~35 ~117 ~81 dirt
setblock ~35 ~117 ~82 dirt
setblock ~35 ~117 ~83 dirt
setblock ~35 ~117 ~84 dirt
setblock ~35 ~117 ~85 dirt
setblock ~35 ~117 ~86 dirt
setblock ~35 ~117 ~87 dirt
setblock ~35 ~117 ~88 dirt
setblock ~35 ~117 ~89 dirt
setblock ~35 ~117 ~90 dirt
setblock ~35 ~117 ~91 dirt
setblock ~35 ~117 ~92 dirt
setblock ~35 ~117 ~93 dirt
setblock ~35 ~117 ~94 dirt
setblock ~35 ~117 ~95 dirt
setblock ~35 ~117 ~96 dirt
setblock ~35 ~117 ~97 dirt
setblock ~35 ~117 ~98 dirt
setblock ~35 ~117 ~99 dirt
setblock ~35 ~117 ~100 dirt
setblock ~35 ~117 ~101 dirt
setblock ~35 ~117 ~102 dirt
setblock ~35 ~117 ~103 dirt
setblock ~35 ~117 ~104 dirt
setblock ~35 ~117 ~105 dirt
setblock ~35 ~117 ~106 dirt
setblock ~35 ~117 ~107 dirt
setblock ~35 ~117 ~108 dirt
setblock ~35 ~118 ~75 dirt
setblock ~35 ~118 ~76 dirt
setblock ~35 ~118 ~77 dirt
setblock ~35 ~118 ~78 dirt
setblock ~35 ~118 ~79 dirt
setblock ~35 ~118 ~80 dirt
setblock ~35 ~118 ~81 dirt
setblock ~35 ~118 ~82 dirt
setblock ~35 ~118 ~83 dirt
setblock ~35 ~118 ~84 dirt
setblock ~35 ~118 ~85 dirt
setblock ~35 ~118 ~86 dirt
setblock ~35 ~118 ~87 dirt
setblock ~35 ~118 ~88 dirt
setblock ~35 ~118 ~89 dirt
setblock ~35 ~118 ~90 dirt
setblock ~35 ~118 ~91 dirt
setblock ~35 ~118 ~92 dirt
setblock ~35 ~118 ~93 dirt
setblock ~35 ~118 ~94 dirt
setblock ~35 ~118 ~95 dirt
setblock ~35 ~118 ~96 dirt
setblock ~35 ~118 ~97 dirt
setblock ~35 ~118 ~98 dirt
setblock ~35 ~118 ~99 dirt
setblock ~35 ~118 ~100 dirt
setblock ~35 ~118 ~101 dirt
setblock ~35 ~118 ~102 dirt
setblock ~35 ~118 ~103 dirt
setblock ~35 ~118 ~104 dirt
setblock ~35 ~118 ~105 dirt
setblock ~35 ~118 ~106 dirt
setblock ~35 ~118 ~107 dirt
setblock ~35 ~118 ~108 dirt
setblock ~35 ~119 ~75 dirt
setblock ~35 ~119 ~76 dirt
setblock ~35 ~119 ~77 dirt
setblock ~35 ~119 ~78 dirt
setblock ~35 ~119 ~79 dirt
setblock ~35 ~119 ~80 dirt
setblock ~35 ~119 ~81 dirt
setblock ~35 ~119 ~82 dirt
setblock ~35 ~119 ~83 dirt
setblock ~35 ~119 ~84 dirt
setblock ~35 ~119 ~85 dirt
setblock ~35 ~119 ~86 dirt
setblock ~35 ~119 ~87 dirt
setblock ~35 ~119 ~88 dirt
setblock ~35 ~119 ~89 dirt
setblock ~35 ~119 ~90 dirt
setblock ~35 ~119 ~91 dirt
setblock ~35 ~119 ~92 dirt
setblock ~35 ~119 ~93 dirt
setblock ~35 ~119 ~94 dirt
setblock ~35 ~119 ~95 dirt
setblock ~35 ~119 ~96 dirt
setblock ~35 ~119 ~97 dirt
setblock ~35 ~119 ~98 dirt
setblock ~35 ~119 ~99 dirt
setblock ~35 ~119 ~100 dirt
setblock ~35 ~119 ~101 dirt
setblock ~35 ~119 ~102 dirt
setblock ~35 ~119 ~103 dirt
setblock ~35 ~119 ~104 dirt
setblock ~35 ~119 ~105 dirt
setblock ~35 ~119 ~106 dirt
setblock ~35 ~119 ~107 dirt
setblock ~35 ~119 ~108 dirt
setblock ~35 ~120 ~74 dirt
setblock ~35 ~120 ~75 dirt
setblock ~35 ~120 ~76 dirt
setblock ~35 ~120 ~77 dirt
setblock ~35 ~120 ~78 dirt
setblock ~35 ~120 ~79 dirt
setblock ~35 ~120 ~80 dirt
setblock ~35 ~120 ~81 dirt
setblock ~35 ~120 ~82 dirt
setblock ~35 ~120 ~83 dirt
setblock ~35 ~120 ~84 dirt
setblock ~35 ~120 ~85 dirt
setblock ~35 ~120 ~86 dirt
setblock ~35 ~120 ~87 dirt
setblock ~35 ~120 ~88 dirt
setblock ~35 ~120 ~89 dirt
setblock ~35 ~120 ~90 dirt
setblock ~35 ~120 ~91 dirt
setblock ~35 ~120 ~92 dirt
setblock ~35 ~120 ~93 dirt
setblock ~35 ~120 ~94 dirt
setblock ~35 ~120 ~95 dirt
setblock ~35 ~120 ~96 dirt
setblock ~35 ~120 ~97 dirt
setblock ~35 ~120 ~98 dirt
setblock ~35 ~120 ~99 dirt
setblock ~35 ~120 ~100 dirt
setblock ~35 ~120 ~101 dirt
setblock ~35 ~120 ~102 dirt
setblock ~35 ~120 ~103 dirt
setblock ~35 ~120 ~104 dirt
setblock ~35 ~120 ~105 dirt
setblock ~35 ~120 ~106 dirt
setblock ~35 ~120 ~107 dirt
setblock ~35 ~120 ~108 dirt
setblock ~35 ~121 ~74 dirt
setblock ~35 ~121 ~75 dirt
setblock ~35 ~121 ~76 dirt
setblock ~35 ~121 ~77 dirt
setblock ~35 ~121 ~78 dirt
setblock ~35 ~121 ~79 dirt
setblock ~35 ~121 ~80 dirt
setblock ~35 ~121 ~81 dirt
setblock ~35 ~121 ~82 dirt
setblock ~35 ~121 ~83 dirt
setblock ~35 ~121 ~84 dirt
setblock ~35 ~121 ~85 dirt
setblock ~35 ~121 ~86 dirt
setblock ~35 ~121 ~87 dirt
setblock ~35 ~121 ~88 dirt
setblock ~35 ~121 ~89 dirt
setblock ~35 ~121 ~90 dirt
setblock ~35 ~121 ~91 dirt
setblock ~35 ~121 ~92 dirt
setblock ~35 ~121 ~93 dirt
setblock ~35 ~121 ~94 dirt
setblock ~35 ~121 ~95 dirt
setblock ~35 ~121 ~96 dirt
setblock ~35 ~121 ~97 dirt
setblock ~35 ~121 ~98 dirt
setblock ~35 ~121 ~99 dirt
setblock ~35 ~121 ~100 dirt
setblock ~35 ~121 ~101 dirt
setblock ~35 ~121 ~102 dirt
setblock ~35 ~121 ~103 dirt
setblock ~35 ~121 ~104 dirt
setblock ~35 ~121 ~105 dirt
setblock ~35 ~121 ~106 dirt
setblock ~35 ~121 ~107 dirt
setblock ~35 ~121 ~108 dirt
setblock ~35 ~121 ~109 dirt
setblock ~35 ~122 ~74 dirt
setblock ~35 ~122 ~75 dirt
setblock ~35 ~122 ~76 dirt
setblock ~35 ~122 ~77 dirt
setblock ~35 ~122 ~78 dirt
setblock ~35 ~122 ~79 dirt
setblock ~35 ~122 ~80 dirt
setblock ~35 ~122 ~81 dirt
setblock ~35 ~122 ~82 dirt
setblock ~35 ~122 ~83 dirt
setblock ~35 ~122 ~84 dirt
setblock ~35 ~122 ~85 dirt
setblock ~35 ~122 ~86 dirt
setblock ~35 ~122 ~87 dirt
setblock ~35 ~122 ~88 dirt
setblock ~35 ~122 ~89 dirt
setblock ~35 ~122 ~90 dirt
setblock ~35 ~122 ~91 dirt
setblock ~35 ~122 ~92 dirt
setblock ~35 ~122 ~93 dirt
setblock ~35 ~122 ~94 dirt
setblock ~35 ~122 ~95 dirt
setblock ~35 ~122 ~96 dirt
setblock ~35 ~122 ~97 dirt
setblock ~35 ~122 ~98 dirt
setblock ~35 ~122 ~99 dirt
setblock ~35 ~122 ~100 dirt
setblock ~35 ~122 ~101 dirt
setblock ~35 ~122 ~102 dirt
setblock ~35 ~122 ~103 dirt
setblock ~35 ~122 ~104 dirt
setblock ~35 ~122 ~105 dirt
setblock ~35 ~122 ~106 dirt
setblock ~35 ~122 ~107 dirt
setblock ~35 ~122 ~108 dirt
setblock ~35 ~122 ~109 dirt
setblock ~35 ~123 ~74 dirt
setblock ~35 ~123 ~75 dirt
setblock ~35 ~123 ~76 dirt
setblock ~35 ~123 ~77 dirt
setblock ~35 ~123 ~78 dirt
setblock ~35 ~123 ~79 dirt
setblock ~35 ~123 ~80 dirt
setblock ~35 ~123 ~81 dirt
setblock ~35 ~123 ~82 dirt
setblock ~35 ~123 ~83 dirt
setblock ~35 ~123 ~84 dirt
setblock ~35 ~123 ~85 dirt
setblock ~35 ~123 ~86 dirt
setblock ~35 ~123 ~87 dirt
setblock ~35 ~123 ~88 dirt
setblock ~35 ~123 ~89 dirt
setblock ~35 ~123 ~90 dirt
setblock ~35 ~123 ~91 dirt
setblock ~35 ~123 ~92 dirt
setblock ~35 ~123 ~93 dirt
setblock ~35 ~123 ~94 dirt
setblock ~35 ~123 ~95 dirt
setblock ~35 ~123 ~96 dirt
setblock ~35 ~123 ~97 dirt
setblock ~35 ~123 ~98 dirt
setblock ~35 ~123 ~99 dirt
setblock ~35 ~123 ~100 dirt
setblock ~35 ~123 ~101 dirt
setblock ~35 ~123 ~102 dirt
setblock ~35 ~123 ~103 dirt
setblock ~35 ~123 ~104 dirt
setblock ~35 ~123 ~105 dirt
setblock ~35 ~123 ~106 dirt
setblock ~35 ~123 ~107 dirt
setblock ~35 ~123 ~108 dirt
setblock ~35 ~123 ~109 dirt
setblock ~35 ~124 ~74 dirt
setblock ~35 ~124 ~75 dirt
setblock ~35 ~124 ~76 dirt
setblock ~35 ~124 ~77 dirt
setblock ~35 ~124 ~78 dirt
setblock ~35 ~124 ~79 dirt
setblock ~35 ~124 ~80 dirt
setblock ~35 ~124 ~81 dirt
setblock ~35 ~124 ~82 dirt
setblock ~35 ~124 ~83 dirt
setblock ~35 ~124 ~84 dirt
setblock ~35 ~124 ~85 dirt
setblock ~35 ~124 ~86 dirt
setblock ~35 ~124 ~87 dirt
setblock ~35 ~124 ~88 dirt
setblock ~35 ~124 ~89 dirt
setblock ~35 ~124 ~90 dirt
setblock ~35 ~124 ~91 dirt
setblock ~35 ~124 ~92 dirt
setblock ~35 ~124 ~93 dirt
setblock ~35 ~124 ~94 dirt
setblock ~35 ~124 ~95 dirt
setblock ~35 ~124 ~96 dirt
setblock ~35 ~124 ~97 dirt
setblock ~35 ~124 ~98 grass_block
setblock ~35 ~124 ~99 grass_block
setblock ~35 ~124 ~100 grass_block
setblock ~35 ~124 ~101 grass_block
setblock ~35 ~124 ~102 grass_block
setblock ~35 ~124 ~103 grass_block
setblock ~35 ~124 ~104 grass_block
setblock ~35 ~124 ~105 grass_block
setblock ~35 ~124 ~106 grass_block
setblock ~35 ~124 ~107 grass_block
setblock ~35 ~124 ~108 grass_block
setblock ~35 ~124 ~109 grass_block
setblock ~35 ~125 ~74 dirt
setblock ~35 ~125 ~75 dirt
setblock ~35 ~125 ~76 dirt
setblock ~35 ~125 ~77 dirt
setblock ~35 ~125 ~78 dirt
setblock ~35 ~125 ~79 dirt
setblock ~35 ~125 ~80 dirt
setblock ~35 ~125 ~81 dirt
setblock ~35 ~125 ~82 dirt
setblock ~35 ~125 ~83 dirt
setblock ~35 ~125 ~84 dirt
setblock ~35 ~125 ~85 dirt
setblock ~35 ~125 ~86 dirt
setblock ~35 ~125 ~87 dirt
setblock ~35 ~125 ~88 dirt
setblock ~35 ~125 ~89 dirt
setblock ~35 ~125 ~90 dirt
setblock ~35 ~125 ~91 dirt
setblock ~35 ~125 ~92 dirt
setblock ~35 ~125 ~93 dirt
setblock ~35 ~125 ~94 grass_block
setblock ~35 ~125 ~95 grass_block
setblock ~35 ~125 ~96 grass_block
setblock ~35 ~125 ~97 grass_block
setblock ~35 ~125 ~100 short_grass
setblock ~35 ~125 ~102 short_grass
setblock ~35 ~125 ~104 short_grass
setblock ~35 ~126 ~74 grass_block
setblock ~35 ~126 ~75 grass_block
setblock ~35 ~126 ~76 grass_block
setblock ~35 ~126 ~77 dirt
setblock ~35 ~126 ~78 dirt
setblock ~35 ~126 ~79 dirt
setblock ~35 ~126 ~80 dirt
setblock ~35 ~126 ~81 dirt
setblock ~35 ~126 ~82 dirt
setblock ~35 ~126 ~83 dirt
setblock ~35 ~126 ~84 dirt
setblock ~35 ~126 ~85 dirt
setblock ~35 ~126 ~86 grass_block
setblock ~35 ~126 ~87 grass_block
setblock ~35 ~126 ~88 grass_block
setblock ~35 ~126 ~89 grass_block
setblock ~35 ~126 ~90 grass_block
setblock ~35 ~126 ~91 grass_block
setblock ~35 ~126 ~92 grass_block
setblock ~35 ~126 ~93 grass_block
setblock ~35 ~126 ~95 short_grass
setblock ~35 ~127 ~75 short_grass
setblock ~35 ~127 ~77 grass_block
setblock ~35 ~127 ~78 grass_block
setblock ~35 ~127 ~79 grass_block
setblock ~35 ~127 ~80 grass_block
setblock ~35 ~127 ~81 grass_block
setblock ~35 ~127 ~82 grass_block
setblock ~35 ~127 ~83 grass_block
setblock ~35 ~127 ~84 grass_block
setblock ~35 ~127 ~85 grass_block
setblock ~35 ~127 ~92 short_grass
setblock ~35 ~127 ~93 short_grass
setblock ~35 ~128 ~78 short_grass
setblock ~35 ~128 ~79 fern
setblock ~35 ~128 ~81 short_grass
setblock ~35 ~128 ~82 short_grass
setblock ~36 ~104 ~92 dirt
setblock ~36 ~105 ~92 dirt
setblock ~36 ~105 ~93 dirt
setblock ~36 ~106 ~92 dirt
setblock ~36 ~106 ~93 dirt
setblock ~36 ~106 ~94 dirt
setblock ~36 ~106 ~102 dirt
setblock ~36 ~106 ~103 dirt
setblock ~36 ~107 ~90 dirt
setblock ~36 ~107 ~91 dirt
setblock ~36 ~107 ~92 dirt
setblock ~36 ~107 ~93 dirt
setblock ~36 ~107 ~94 dirt
setblock ~36 ~107 ~95 dirt
setblock ~36 ~107 ~96 dirt
setblock ~36 ~107 ~101 dirt
setblock ~36 ~107 ~102 dirt
setblock ~36 ~107 ~103 dirt
setblock ~36 ~107 ~104 dirt
setblock ~36 ~108 ~89 dirt
setblock ~36 ~108 ~90 dirt
setblock ~36 ~108 ~91 dirt
setblock ~36 ~108 ~92 dirt
setblock ~36 ~108 ~93 dirt
setblock ~36 ~108 ~94 dirt
setblock ~36 ~108 ~95 dirt
setblock ~36 ~108 ~96 dirt
setblock ~36 ~108 ~100 dirt
setblock ~36 ~108 ~101 dirt
setblock ~36 ~108 ~102 dirt
setblock ~36 ~108 ~103 dirt
setblock ~36 ~108 ~104 dirt
setblock ~36 ~109 ~88 dirt
setblock ~36 ~109 ~89 dirt
setblock ~36 ~109 ~90 dirt
setblock ~36 ~109 ~91 dirt
setblock ~36 ~109 ~92 dirt
setblock ~36 ~109 ~93 dirt
setblock ~36 ~109 ~94 dirt
setblock ~36 ~109 ~95 dirt
setblock ~36 ~109 ~96 dirt
setblock ~36 ~109 ~97 dirt
setblock ~36 ~109 ~100 dirt
setblock ~36 ~109 ~101 dirt
setblock ~36 ~109 ~102 dirt
setblock ~36 ~109 ~103 dirt
setblock ~36 ~109 ~104 dirt
setblock ~36 ~110 ~87 dirt
setblock ~36 ~110 ~88 dirt
setblock ~36 ~110 ~89 dirt
setblock ~36 ~110 ~90 dirt
setblock ~36 ~110 ~91 dirt
setblock ~36 ~110 ~92 dirt
setblock ~36 ~110 ~93 dirt
setblock ~36 ~110 ~94 dirt
setblock ~36 ~110 ~95 dirt
setblock ~36 ~110 ~96 dirt
setblock ~36 ~110 ~97 dirt
setblock ~36 ~110 ~98 dirt
setblock ~36 ~110 ~100 dirt
setblock ~36 ~110 ~101 dirt
setblock ~36 ~110 ~102 dirt
setblock ~36 ~110 ~103 dirt
setblock ~36 ~110 ~104 dirt
setblock ~36 ~111 ~85 dirt
setblock ~36 ~111 ~86 dirt
setblock ~36 ~111 ~87 dirt
setblock ~36 ~111 ~88 dirt
setblock ~36 ~111 ~89 dirt
setblock ~36 ~111 ~90 dirt
setblock ~36 ~111 ~91 dirt
setblock ~36 ~111 ~92 dirt
setblock ~36 ~111 ~93 dirt
setblock ~36 ~111 ~94 dirt
setblock ~36 ~111 ~95 dirt
setblock ~36 ~111 ~96 dirt
setblock ~36 ~111 ~97 dirt
setblock ~36 ~111 ~98 dirt
setblock ~36 ~111 ~99 dirt
setblock ~36 ~111 ~100 dirt
setblock ~36 ~111 ~101 dirt
setblock ~36 ~111 ~102 dirt
setblock ~36 ~111 ~103 dirt
setblock ~36 ~111 ~104 dirt
setblock ~36 ~111 ~105 dirt
setblock ~36 ~112 ~82 dirt
setblock ~36 ~112 ~84 dirt
setblock ~36 ~112 ~85 dirt
setblock ~36 ~112 ~86 dirt
setblock ~36 ~112 ~87 dirt
setblock ~36 ~112 ~88 dirt
setblock ~36 ~112 ~89 dirt
setblock ~36 ~112 ~90 dirt
setblock ~36 ~112 ~91 dirt
setblock ~36 ~112 ~92 dirt
setblock ~36 ~112 ~93 dirt
setblock ~36 ~112 ~94 dirt
setblock ~36 ~112 ~95 dirt
setblock ~36 ~112 ~96 dirt
setblock ~36 ~112 ~97 dirt
setblock ~36 ~112 ~98 dirt
setblock ~36 ~112 ~99 dirt
setblock ~36 ~112 ~100 dirt
setblock ~36 ~112 ~101 dirt
setblock ~36 ~112 ~102 dirt
setblock ~36 ~112 ~103 dirt
setblock ~36 ~112 ~104 dirt
setblock ~36 ~112 ~105 dirt
setblock ~36 ~112 ~106 dirt
setblock ~36 ~113 ~77 dirt
setblock ~36 ~113 ~79 dirt
setblock ~36 ~113 ~81 dirt
setblock ~36 ~113 ~82 dirt
setblock ~36 ~113 ~83 dirt
setblock ~36 ~113 ~84 dirt
setblock ~36 ~113 ~85 dirt
setblock ~36 ~113 ~86 dirt
setblock ~36 ~113 ~87 dirt
setblock ~36 ~113 ~88 dirt
setblock ~36 ~113 ~89 dirt
setblock ~36 ~113 ~90 dirt
setblock ~36 ~113 ~91 dirt
setblock ~36 ~113 ~92 dirt
setblock ~36 ~113 ~93 dirt
setblock ~36 ~113 ~94 dirt
setblock ~36 ~113 ~95 dirt
setblock ~36 ~113 ~96 dirt
setblock ~36 ~113 ~97 dirt
setblock ~36 ~113 ~98 dirt
setblock ~36 ~113 ~99 dirt
setblock ~36 ~113 ~100 dirt
setblock ~36 ~113 ~101 dirt
setblock ~36 ~113 ~102 dirt
setblock ~36 ~113 ~103 dirt
setblock ~36 ~113 ~104 dirt
setblock ~36 ~113 ~105 dirt
setblock ~36 ~113 ~106 dirt
setblock ~36 ~114 ~76 dirt
setblock ~36 ~114 ~77 dirt
setblock ~36 ~114 ~79 dirt
setblock ~36 ~114 ~80 dirt
setblock ~36 ~114 ~81 dirt
setblock ~36 ~114 ~82 dirt
setblock ~36 ~114 ~83 dirt
setblock ~36 ~114 ~84 dirt
setblock ~36 ~114 ~85 dirt
setblock ~36 ~114 ~86 dirt
setblock ~36 ~114 ~87 dirt
setblock ~36 ~114 ~88 dirt
setblock ~36 ~114 ~89 dirt
setblock ~36 ~114 ~90 dirt
setblock ~36 ~114 ~91 dirt
setblock ~36 ~114 ~92 dirt
setblock ~36 ~114 ~93 dirt
setblock ~36 ~114 ~94 dirt
setblock ~36 ~114 ~95 dirt
setblock ~36 ~114 ~96 dirt
setblock ~36 ~114 ~97 dirt
setblock ~36 ~114 ~98 dirt
setblock ~36 ~114 ~99 dirt
setblock ~36 ~114 ~100 dirt
setblock ~36 ~114 ~101 dirt
setblock ~36 ~114 ~102 dirt
setblock ~36 ~114 ~103 dirt
