setblock ~172 ~122 ~100 dirt
setblock ~172 ~122 ~101 dirt
setblock ~172 ~122 ~102 dirt
setblock ~172 ~122 ~103 dirt
setblock ~172 ~122 ~126 dirt
setblock ~172 ~122 ~127 dirt
setblock ~172 ~122 ~128 dirt
setblock ~172 ~122 ~129 dirt
setblock ~172 ~122 ~130 dirt
setblock ~172 ~123 ~46 dirt
setblock ~172 ~123 ~47 dirt
setblock ~172 ~123 ~48 dirt
setblock ~172 ~123 ~49 dirt
setblock ~172 ~123 ~50 grass_block
setblock ~172 ~123 ~51 dirt
setblock ~172 ~123 ~62 dirt
setblock ~172 ~123 ~63 dirt
setblock ~172 ~123 ~64 dirt
setblock ~172 ~123 ~65 dirt
setblock ~172 ~123 ~66 dirt
setblock ~172 ~123 ~67 dirt
setblock ~172 ~123 ~68 dirt
setblock ~172 ~123 ~69 dirt
setblock ~172 ~123 ~70 dirt
setblock ~172 ~123 ~71 dirt
setblock ~172 ~123 ~85 dirt
setblock ~172 ~123 ~86 dirt
setblock ~172 ~123 ~87 dirt
setblock ~172 ~123 ~88 dirt
setblock ~172 ~123 ~89 dirt
setblock ~172 ~123 ~90 dirt
setblock ~172 ~123 ~91 dirt
setblock ~172 ~123 ~92 dirt
setblock ~172 ~123 ~93 dirt
setblock ~172 ~123 ~94 dirt
setblock ~172 ~123 ~95 dirt
setblock ~172 ~123 ~96 dirt
setblock ~172 ~123 ~97 dirt
setblock ~172 ~123 ~98 dirt
setblock ~172 ~123 ~99 dirt
setblock ~172 ~123 ~100 dirt
setblock ~172 ~123 ~101 dirt
setblock ~172 ~123 ~102 dirt
setblock ~172 ~123 ~103 dirt
setblock ~172 ~123 ~126 dirt
setblock ~172 ~123 ~127 dirt
setblock ~172 ~123 ~128 dirt
setblock ~172 ~123 ~129 dirt
setblock ~172 ~123 ~130 dirt
setblock ~172 ~124 ~46 grass_block
setblock ~172 ~124 ~47 grass_block
setblock ~172 ~124 ~48 grass_block
setblock ~172 ~124 ~49 grass_block
setblock ~172 ~124 ~51 grass_block
setblock ~172 ~124 ~62 dirt
setblock ~172 ~124 ~63 dirt
setblock ~172 ~124 ~64 dirt
setblock ~172 ~124 ~65 dirt
setblock ~172 ~124 ~66 dirt
setblock ~172 ~124 ~67 dirt
setblock ~172 ~124 ~68 dirt
setblock ~172 ~124 ~69 dirt
setblock ~172 ~124 ~70 dirt
setblock ~172 ~124 ~71 dirt
setblock ~172 ~124 ~85 dirt
setblock ~172 ~124 ~86 dirt
setblock ~172 ~124 ~87 dirt
setblock ~172 ~124 ~88 dirt
setblock ~172 ~124 ~89 dirt
setblock ~172 ~124 ~90 dirt
setblock ~172 ~124 ~91 dirt
setblock ~172 ~124 ~92 dirt
setblock ~172 ~124 ~93 dirt
setblock ~172 ~124 ~94 dirt
setblock ~172 ~124 ~95 dirt
setblock ~172 ~124 ~96 dirt
setblock ~172 ~124 ~97 dirt
setblock ~172 ~124 ~98 dirt
setblock ~172 ~124 ~99 dirt
setblock ~172 ~124 ~100 dirt
setblock ~172 ~124 ~101 dirt
setblock ~172 ~124 ~102 dirt
setblock ~172 ~124 ~103 dirt
setblock ~172 ~124 ~126 grass_block
setblock ~172 ~124 ~127 grass_block
setblock ~172 ~124 ~128 grass_block
setblock ~172 ~124 ~129 dirt
setblock ~172 ~124 ~130 dirt
setblock ~172 ~125 ~51 short_grass
setblock ~172 ~125 ~62 grass_block
setblock ~172 ~125 ~63 grass_block
setblock ~172 ~125 ~64 grass_block
setblock ~172 ~125 ~65 grass_block
setblock ~172 ~125 ~66 grass_block
setblock ~172 ~125 ~67 grass_block
setblock ~172 ~125 ~68 grass_block
setblock ~172 ~125 ~69 grass_block
setblock ~172 ~125 ~70 grass_block
setblock ~172 ~125 ~71 grass_block
setblock ~172 ~125 ~85 grass_block
setblock ~172 ~125 ~86 grass_block
setblock ~172 ~125 ~87 grass_block
setblock ~172 ~125 ~88 grass_block
setblock ~172 ~125 ~89 grass_block
setblock ~172 ~125 ~90 grass_block
setblock ~172 ~125 ~91 grass_block
setblock ~172 ~125 ~92 grass_block
setblock ~172 ~125 ~93 grass_block
setblock ~172 ~125 ~94 grass_block
setblock ~172 ~125 ~95 grass_block
setblock ~172 ~125 ~96 grass_block
setblock ~172 ~125 ~97 grass_block
setblock ~172 ~125 ~98 grass_block
setblock ~172 ~125 ~99 grass_block
setblock ~172 ~125 ~100 grass_block
setblock ~172 ~125 ~101 grass_block
setblock ~172 ~125 ~102 grass_block
setblock ~172 ~125 ~103 grass_block
setblock ~172 ~125 ~126 short_grass
setblock ~172 ~125 ~127 poppy
setblock ~172 ~125 ~129 grass_block
setblock ~172 ~125 ~130 grass_block
setblock ~172 ~126 ~62 fern
setblock ~172 ~126 ~69 short_grass
setblock ~172 ~126 ~71 short_grass
setblock ~172 ~126 ~87 short_grass
setblock ~172 ~126 ~88 short_grass
setblock ~172 ~126 ~89 short_grass
setblock ~172 ~126 ~97 short_grass
setblock ~172 ~126 ~100 short_grass
setblock ~172 ~126 ~101 short_grass
setblock ~172 ~126 ~102 fern
setblock ~172 ~126 ~130 short_grass
setblock ~173 ~112 ~49 dirt
setblock ~173 ~113 ~49 dirt
setblock ~173 ~114 ~49 dirt
setblock ~173 ~114 ~91 dirt
setblock ~173 ~115 ~49 dirt
setblock ~173 ~115 ~67 dirt
setblock ~173 ~115 ~90 dirt
setblock ~173 ~115 ~91 dirt
setblock ~173 ~115 ~92 dirt
setblock ~173 ~116 ~48 dirt
setblock ~173 ~116 ~49 dirt
setblock ~173 ~116 ~50 dirt
setblock ~173 ~116 ~66 dirt
setblock ~173 ~116 ~67 dirt
setblock ~173 ~116 ~89 dirt
setblock ~173 ~116 ~90 dirt
setblock ~173 ~116 ~91 dirt
setblock ~173 ~116 ~92 dirt
setblock ~173 ~116 ~98 dirt
setblock ~173 ~117 ~47 dirt
setblock ~173 ~117 ~48 dirt
setblock ~173 ~117 ~49 dirt
setblock ~173 ~117 ~50 dirt
setblock ~173 ~117 ~65 dirt
setblock ~173 ~117 ~66 dirt
setblock ~173 ~117 ~67 dirt
setblock ~173 ~117 ~68 dirt
setblock ~173 ~117 ~89 dirt
setblock ~173 ~117 ~90 dirt
setblock ~173 ~117 ~91 dirt
setblock ~173 ~117 ~92 dirt
setblock ~173 ~117 ~93 dirt
setblock ~173 ~117 ~94 dirt
setblock ~173 ~117 ~95 dirt
setblock ~173 ~117 ~98 dirt
setblock ~173 ~117 ~128 dirt
setblock ~173 ~118 ~47 dirt
setblock ~173 ~118 ~48 dirt
setblock ~173 ~118 ~49 dirt
setblock ~173 ~118 ~50 dirt
setblock ~173 ~118 ~51 dirt
setblock ~173 ~118 ~65 dirt
setblock ~173 ~118 ~66 dirt
setblock ~173 ~118 ~67 dirt
setblock ~173 ~118 ~68 dirt
setblock ~173 ~118 ~69 dirt
setblock ~173 ~118 ~89 dirt
setblock ~173 ~118 ~90 dirt
setblock ~173 ~118 ~91 dirt
setblock ~173 ~118 ~92 dirt
setblock ~173 ~118 ~93 dirt
setblock ~173 ~118 ~94 dirt
setblock ~173 ~118 ~95 dirt
setblock ~173 ~118 ~96 dirt
setblock ~173 ~118 ~97 dirt
setblock ~173 ~118 ~98 dirt
setblock ~173 ~118 ~127 dirt
setblock ~173 ~118 ~128 dirt
setblock ~173 ~118 ~129 dirt
setblock ~173 ~119 ~46 dirt
setblock ~173 ~119 ~47 dirt
setblock ~173 ~119 ~48 dirt
setblock ~173 ~119 ~49 dirt
setblock ~173 ~119 ~50 dirt
setblock ~173 ~119 ~51 dirt
setblock ~173 ~119 ~65 dirt
setblock ~173 ~119 ~66 dirt
setblock ~173 ~119 ~67 dirt
setblock ~173 ~119 ~68 dirt
setblock ~173 ~119 ~69 dirt
setblock ~173 ~119 ~87 dirt
setblock ~173 ~119 ~88 dirt
setblock ~173 ~119 ~89 dirt
setblock ~173 ~119 ~90 dirt
setblock ~173 ~119 ~91 dirt
setblock ~173 ~119 ~92 dirt
setblock ~173 ~119 ~93 dirt
setblock ~173 ~119 ~94 dirt
setblock ~173 ~119 ~95 dirt
setblock ~173 ~119 ~96 dirt
setblock ~173 ~119 ~97 dirt
setblock ~173 ~119 ~98 dirt
setblock ~173 ~119 ~99 dirt
setblock ~173 ~119 ~127 dirt
setblock ~173 ~119 ~128 dirt
setblock ~173 ~119 ~129 dirt
setblock ~173 ~120 ~46 dirt
setblock ~173 ~120 ~47 dirt
setblock ~173 ~120 ~48 dirt
setblock ~173 ~120 ~49 dirt
setblock ~173 ~120 ~50 dirt
setblock ~173 ~120 ~51 dirt
setblock ~173 ~120 ~64 dirt
setblock ~173 ~120 ~65 dirt
setblock ~173 ~120 ~66 dirt
setblock ~173 ~120 ~67 dirt
setblock ~173 ~120 ~68 dirt
setblock ~173 ~120 ~69 dirt
setblock ~173 ~120 ~70 dirt
setblock ~173 ~120 ~87 dirt
setblock ~173 ~120 ~88 dirt
setblock ~173 ~120 ~89 dirt
setblock ~173 ~120 ~90 dirt
setblock ~173 ~120 ~91 dirt
setblock ~173 ~120 ~92 dirt
setblock ~173 ~120 ~93 dirt
setblock ~173 ~120 ~94 dirt
setblock ~173 ~120 ~95 dirt
setblock ~173 ~120 ~96 dirt
setblock ~173 ~120 ~97 dirt
setblock ~173 ~120 ~98 dirt
setblock ~173 ~120 ~99 dirt
setblock ~173 ~120 ~100 dirt
setblock ~173 ~120 ~126 dirt
setblock ~173 ~120 ~127 dirt
setblock ~173 ~120 ~128 dirt
setblock ~173 ~120 ~129 dirt
setblock ~173 ~120 ~130 dirt
setblock ~173 ~121 ~45 dirt
setblock ~173 ~121 ~46 dirt
setblock ~173 ~121 ~47 dirt
setblock ~173 ~121 ~48 dirt
setblock ~173 ~121 ~49 dirt
setblock ~173 ~121 ~50 dirt
setblock ~173 ~121 ~51 dirt
setblock ~173 ~121 ~63 dirt
setblock ~173 ~121 ~64 dirt
setblock ~173 ~121 ~65 dirt
setblock ~173 ~121 ~66 dirt
setblock ~173 ~121 ~67 dirt
setblock ~173 ~121 ~68 dirt
setblock ~173 ~121 ~69 dirt
setblock ~173 ~121 ~70 dirt
setblock ~173 ~121 ~71 dirt
setblock ~173 ~121 ~86 dirt
setblock ~173 ~121 ~87 dirt
setblock ~173 ~121 ~88 dirt
setblock ~173 ~121 ~89 dirt
setblock ~173 ~121 ~90 dirt
setblock ~173 ~121 ~91 dirt
setblock ~173 ~121 ~92 dirt
setblock ~173 ~121 ~93 dirt
setblock ~173 ~121 ~94 dirt
setblock ~173 ~121 ~95 dirt
setblock ~173 ~121 ~96 dirt
setblock ~173 ~121 ~97 dirt
setblock ~173 ~121 ~98 dirt
setblock ~173 ~121 ~99 dirt
setblock ~173 ~121 ~100 dirt
setblock ~173 ~121 ~101 dirt
setblock ~173 ~121 ~125 dirt
setblock ~173 ~121 ~126 dirt
setblock ~173 ~121 ~127 dirt
setblock ~173 ~121 ~128 dirt
setblock ~173 ~121 ~129 dirt
setblock ~173 ~121 ~130 dirt
setblock ~173 ~122 ~45 dirt
setblock ~173 ~122 ~46 dirt
setblock ~173 ~122 ~47 dirt
setblock ~173 ~122 ~48 dirt
setblock ~173 ~122 ~49 dirt
setblock ~173 ~122 ~50 dirt
setblock ~173 ~122 ~51 dirt
setblock ~173 ~122 ~63 dirt
setblock ~173 ~122 ~64 dirt
setblock ~173 ~122 ~65 dirt
setblock ~173 ~122 ~66 dirt
setblock ~173 ~122 ~67 dirt
setblock ~173 ~122 ~68 dirt
setblock ~173 ~122 ~69 dirt
setblock ~173 ~122 ~70 dirt
setblock ~173 ~122 ~71 dirt
setblock ~173 ~122 ~86 dirt
setblock ~173 ~122 ~87 dirt
setblock ~173 ~122 ~88 dirt
setblock ~173 ~122 ~89 dirt
setblock ~173 ~122 ~90 dirt
setblock ~173 ~122 ~91 dirt
setblock ~173 ~122 ~92 dirt
setblock ~173 ~122 ~93 dirt
setblock ~173 ~122 ~94 dirt
setblock ~173 ~122 ~95 dirt
setblock ~173 ~122 ~96 dirt
setblock ~173 ~122 ~97 dirt
setblock ~173 ~122 ~98 dirt
setblock ~173 ~122 ~99 dirt
setblock ~173 ~122 ~100 dirt
setblock ~173 ~122 ~101 dirt
setblock ~173 ~122 ~125 dirt
setblock ~173 ~122 ~126 dirt
setblock ~173 ~122 ~127 dirt
setblock ~173 ~122 ~128 dirt
setblock ~173 ~122 ~129 dirt
setblock ~173 ~122 ~130 dirt
setblock ~173 ~123 ~45 dirt
setblock ~173 ~123 ~46 dirt
setblock ~173 ~123 ~47 dirt
setblock ~173 ~123 ~48 dirt
setblock ~173 ~123 ~49 dirt
setblock ~173 ~123 ~50 dirt
setblock ~173 ~123 ~51 dirt
setblock ~173 ~123 ~63 dirt
setblock ~173 ~123 ~64 dirt
setblock ~173 ~123 ~65 dirt
setblock ~173 ~123 ~66 dirt
setblock ~173 ~123 ~67 dirt
setblock ~173 ~123 ~68 dirt
setblock ~173 ~123 ~69 dirt
setblock ~173 ~123 ~70 dirt
setblock ~173 ~123 ~71 dirt
setblock ~173 ~123 ~86 dirt
setblock ~173 ~123 ~87 dirt
setblock ~173 ~123 ~88 dirt
setblock ~173 ~123 ~89 dirt
setblock ~173 ~123 ~90 dirt
setblock ~173 ~123 ~91 dirt
setblock ~173 ~123 ~92 dirt
setblock ~173 ~123 ~93 dirt
setblock ~173 ~123 ~94 dirt
setblock ~173 ~123 ~95 dirt
setblock ~173 ~123 ~96 dirt
setblock ~173 ~123 ~97 dirt
setblock ~173 ~123 ~98 dirt
setblock ~173 ~123 ~99 dirt
setblock ~173 ~123 ~100 dirt
setblock ~173 ~123 ~101 dirt
setblock ~173 ~123 ~125 dirt
setblock ~173 ~123 ~126 dirt
setblock ~173 ~123 ~127 dirt
setblock ~173 ~123 ~128 dirt
setblock ~173 ~123 ~129 dirt
setblock ~173 ~123 ~130 dirt
setblock ~173 ~124 ~45 grass_block
setblock ~173 ~124 ~46 grass_block
setblock ~173 ~124 ~47 grass_block
setblock ~173 ~124 ~48 grass_block
setblock ~173 ~124 ~49 grass_block
setblock ~173 ~124 ~50 grass_block
setblock ~173 ~124 ~51 grass_block
setblock ~173 ~124 ~63 dirt
setblock ~173 ~124 ~64 dirt
setblock ~173 ~124 ~65 dirt
setblock ~173 ~124 ~66 dirt
setblock ~173 ~124 ~67 dirt
setblock ~173 ~124 ~68 dirt
setblock ~173 ~124 ~69 dirt
setblock ~173 ~124 ~70 dirt
setblock ~173 ~124 ~71 dirt
setblock ~173 ~124 ~86 dirt
setblock ~173 ~124 ~87 dirt
setblock ~173 ~124 ~88 dirt
setblock ~173 ~124 ~89 dirt
setblock ~173 ~124 ~90 dirt
setblock ~173 ~124 ~91 dirt
setblock ~173 ~124 ~92 dirt
setblock ~173 ~124 ~93 dirt
setblock ~173 ~124 ~94 dirt
setblock ~173 ~124 ~95 dirt
setblock ~173 ~124 ~96 dirt
setblock ~173 ~124 ~97 dirt
setblock ~173 ~124 ~98 dirt
setblock ~173 ~124 ~99 dirt
setblock ~173 ~124 ~100 dirt
setblock ~173 ~124 ~101 dirt
setblock ~173 ~124 ~125 grass_block
setblock ~173 ~124 ~126 grass_block
setblock ~173 ~124 ~127 grass_block
setblock ~173 ~124 ~128 grass_block
setblock ~173 ~124 ~129 grass_block
setblock ~173 ~124 ~130 grass_block
setblock ~173 ~125 ~46 short_grass
setblock ~173 ~125 ~63 grass_block
setblock ~173 ~125 ~64 grass_block
setblock ~173 ~125 ~65 grass_block
setblock ~173 ~125 ~66 grass_block
setblock ~173 ~125 ~67 grass_block
setblock ~173 ~125 ~68 grass_block
setblock ~173 ~125 ~69 grass_block
setblock ~173 ~125 ~70 grass_block
setblock ~173 ~125 ~71 grass_block
setblock ~173 ~125 ~86 grass_block
setblock ~173 ~125 ~87 grass_block
setblock ~173 ~125 ~88 grass_block
setblock ~173 ~125 ~89 grass_block
setblock ~173 ~125 ~90 grass_block
setblock ~173 ~125 ~91 grass_block
setblock ~173 ~125 ~92 grass_block
setblock ~173 ~125 ~93 grass_block
setblock ~173 ~125 ~94 grass_block
setblock ~173 ~125 ~95 grass_block
setblock ~173 ~125 ~96 grass_block
setblock ~173 ~125 ~97 grass_block
setblock ~173 ~125 ~98 grass_block
setblock ~173 ~125 ~99 grass_block
setblock ~173 ~125 ~100 grass_block
setblock ~173 ~125 ~101 grass_block
setblock ~173 ~125 ~126 short_grass
setblock ~173 ~126 ~70 fern
setblock ~173 ~126 ~71 short_grass
setblock ~173 ~126 ~87 fern
setblock ~173 ~126 ~89 poppy
setblock ~173 ~126 ~90 short_grass
setblock ~173 ~126 ~92 short_grass
setblock ~173 ~126 ~93 short_grass
setblock ~173 ~126 ~101 short_grass
setblock ~174 ~115 ~128 dirt
setblock ~174 ~116 ~49 dirt
setblock ~174 ~116 ~90 dirt
setblock ~174 ~116 ~91 dirt
setblock ~174 ~116 ~128 dirt
setblock ~174 ~117 ~48 dirt
setblock ~174 ~117 ~49 dirt
setblock ~174 ~117 ~50 dirt
setblock ~174 ~117 ~66 dirt
setblock ~174 ~117 ~89 dirt
setblock ~174 ~117 ~90 dirt
setblock ~174 ~117 ~91 dirt
setblock ~174 ~117 ~127 dirt
setblock ~174 ~117 ~128 dirt
setblock ~174 ~117 ~129 dirt
setblock ~174 ~118 ~47 dirt
setblock ~174 ~118 ~48 dirt
setblock ~174 ~118 ~49 dirt
setblock ~174 ~118 ~50 dirt
setblock ~174 ~118 ~66 dirt
setblock ~174 ~118 ~67 dirt
setblock ~174 ~118 ~68 dirt
setblock ~174 ~118 ~89 dirt
setblock ~174 ~118 ~90 dirt
setblock ~174 ~118 ~91 dirt
setblock ~174 ~118 ~92 dirt
setblock ~174 ~118 ~127 dirt
setblock ~174 ~118 ~128 dirt
setblock ~174 ~118 ~129 dirt
setblock ~174 ~119 ~47 dirt
setblock ~174 ~119 ~48 dirt
setblock ~174 ~119 ~49 dirt
setblock ~174 ~119 ~50 dirt
setblock ~174 ~119 ~65 dirt
setblock ~174 ~119 ~66 dirt
setblock ~174 ~119 ~67 dirt
setblock ~174 ~119 ~68 dirt
setblock ~174 ~119 ~89 dirt
setblock ~174 ~119 ~90 dirt
setblock ~174 ~119 ~91 dirt
setblock ~174 ~119 ~92 dirt
setblock ~174 ~119 ~93 dirt
setblock ~174 ~119 ~94 dirt
setblock ~174 ~119 ~95 dirt
setblock ~174 ~119 ~96 dirt
setblock ~174 ~119 ~97 dirt
setblock ~174 ~119 ~98 dirt
setblock ~174 ~119 ~126 dirt
setblock ~174 ~119 ~127 dirt
setblock ~174 ~119 ~128 dirt
setblock ~174 ~119 ~129 dirt
setblock ~174 ~120 ~47 dirt
setblock ~174 ~120 ~48 dirt
setblock ~174 ~120 ~49 dirt
setblock ~174 ~120 ~50 dirt
setblock ~174 ~120 ~64 dirt
setblock ~174 ~120 ~65 dirt
setblock ~174 ~120 ~66 dirt
setblock ~174 ~120 ~67 dirt
setblock ~174 ~120 ~68 dirt
setblock ~174 ~120 ~69 dirt
setblock ~174 ~120 ~88 dirt
setblock ~174 ~120 ~89 dirt
setblock ~174 ~120 ~90 dirt
setblock ~174 ~120 ~91 dirt
setblock ~174 ~120 ~92 dirt
setblock ~174 ~120 ~93 dirt
setblock ~174 ~120 ~94 dirt
setblock ~174 ~120 ~95 dirt
setblock ~174 ~120 ~96 dirt
setblock ~174 ~120 ~97 dirt
setblock ~174 ~120 ~98 dirt
setblock ~174 ~120 ~99 dirt
setblock ~174 ~120 ~126 dirt
setblock ~174 ~120 ~127 dirt
setblock ~174 ~120 ~128 dirt
setblock ~174 ~120 ~129 dirt
setblock ~174 ~120 ~130 dirt
setblock ~174 ~121 ~46 dirt
setblock ~174 ~121 ~47 dirt
setblock ~174 ~121 ~48 dirt
setblock ~174 ~121 ~49 dirt
setblock ~174 ~121 ~50 dirt
setblock ~174 ~121 ~51 dirt
setblock ~174 ~121 ~64 dirt
setblock ~174 ~121 ~65 dirt
setblock ~174 ~121 ~66 dirt
setblock ~174 ~121 ~67 dirt
setblock ~174 ~121 ~68 dirt
setblock ~174 ~121 ~69 dirt
setblock ~174 ~121 ~70 dirt
setblock ~174 ~121 ~87 dirt
setblock ~174 ~121 ~88 dirt
setblock ~174 ~121 ~89 dirt
setblock ~174 ~121 ~90 dirt
setblock ~174 ~121 ~91 dirt
setblock ~174 ~121 ~92 dirt
setblock ~174 ~121 ~93 dirt
setblock ~174 ~121 ~94 dirt
setblock ~174 ~121 ~95 dirt
setblock ~174 ~121 ~96 dirt
setblock ~174 ~121 ~97 dirt
setblock ~174 ~121 ~98 dirt
setblock ~174 ~121 ~99 dirt
setblock ~174 ~121 ~100 dirt
setblock ~174 ~121 ~126 dirt
setblock ~174 ~121 ~127 dirt
setblock ~174 ~121 ~128 dirt
setblock ~174 ~121 ~129 dirt
setblock ~174 ~121 ~130 dirt
setblock ~174 ~121 ~131 dirt
setblock ~174 ~122 ~46 dirt
setblock ~174 ~122 ~47 dirt
setblock ~174 ~122 ~48 dirt
setblock ~174 ~122 ~49 dirt
setblock ~174 ~122 ~50 dirt
setblock ~174 ~122 ~51 dirt
setblock ~174 ~122 ~64 dirt
setblock ~174 ~122 ~65 dirt
setblock ~174 ~122 ~66 dirt
setblock ~174 ~122 ~67 dirt
setblock ~174 ~122 ~68 dirt
setblock ~174 ~122 ~69 dirt
setblock ~174 ~122 ~70 dirt
setblock ~174 ~122 ~87 dirt
setblock ~174 ~122 ~88 dirt
setblock ~174 ~122 ~89 dirt
setblock ~174 ~122 ~90 dirt
setblock ~174 ~122 ~91 dirt
setblock ~174 ~122 ~92 dirt
setblock ~174 ~122 ~93 dirt
setblock ~174 ~122 ~94 dirt
setblock ~174 ~122 ~95 dirt
setblock ~174 ~122 ~96 dirt
setblock ~174 ~122 ~97 dirt
setblock ~174 ~122 ~98 dirt
setblock ~174 ~122 ~99 dirt
setblock ~174 ~122 ~100 dirt
setblock ~174 ~122 ~126 dirt
setblock ~174 ~122 ~127 dirt
setblock ~174 ~122 ~128 dirt
setblock ~174 ~122 ~129 dirt
setblock ~174 ~122 ~130 dirt
setblock ~174 ~122 ~131 dirt
setblock ~174 ~123 ~46 dirt
setblock ~174 ~123 ~47 dirt
setblock ~174 ~123 ~48 dirt
setblock ~174 ~123 ~49 dirt
setblock ~174 ~123 ~50 dirt
setblock ~174 ~123 ~51 dirt
setblock ~174 ~123 ~64 dirt
setblock ~174 ~123 ~65 dirt
setblock ~174 ~123 ~66 dirt
setblock ~174 ~123 ~67 dirt
setblock ~174 ~123 ~68 dirt
setblock ~174 ~123 ~69 dirt
setblock ~174 ~123 ~70 dirt
setblock ~174 ~123 ~87 dirt
setblock ~174 ~123 ~88 dirt
setblock ~174 ~123 ~89 dirt
setblock ~174 ~123 ~90 dirt
setblock ~174 ~123 ~91 dirt
setblock ~174 ~123 ~92 dirt
setblock ~174 ~123 ~93 dirt
setblock ~174 ~123 ~94 dirt
setblock ~174 ~123 ~95 dirt
setblock ~174 ~123 ~96 dirt
setblock ~174 ~123 ~97 dirt
setblock ~174 ~123 ~98 dirt
setblock ~174 ~123 ~99 dirt
setblock ~174 ~123 ~100 dirt
setblock ~174 ~123 ~126 dirt
setblock ~174 ~123 ~127 dirt
setblock ~174 ~123 ~128 dirt
setblock ~174 ~123 ~129 dirt
setblock ~174 ~123 ~130 dirt
setblock ~174 ~123 ~131 dirt
setblock ~174 ~124 ~46 grass_block
setblock ~174 ~124 ~47 grass_block
setblock ~174 ~124 ~48 grass_block
setblock ~174 ~124 ~49 grass_block
setblock ~174 ~124 ~50 grass_block
setblock ~174 ~124 ~51 grass_block
setblock ~174 ~124 ~64 dirt
setblock ~174 ~124 ~65 dirt
setblock ~174 ~124 ~66 dirt
setblock ~174 ~124 ~67 dirt
setblock ~174 ~124 ~68 dirt
setblock ~174 ~124 ~69 dirt
setblock ~174 ~124 ~70 dirt
setblock ~174 ~124 ~87 dirt
setblock ~174 ~124 ~88 dirt
setblock ~174 ~124 ~89 grass_block
setblock ~174 ~124 ~90 grass_block
setblock ~174 ~124 ~91 grass_block
setblock ~174 ~124 ~92 grass_block
setblock ~174 ~124 ~93 grass_block
setblock ~174 ~124 ~94 grass_block
setblock ~174 ~124 ~95 grass_block
setblock ~174 ~124 ~96 grass_block
setblock ~174 ~124 ~97 grass_block
setblock ~174 ~124 ~98 dirt
setblock ~174 ~124 ~99 dirt
setblock ~174 ~124 ~100 dirt
setblock ~174 ~124 ~126 grass_block
setblock ~174 ~124 ~127 grass_block
setblock ~174 ~124 ~128 grass_block
setblock ~174 ~124 ~129 grass_block
setblock ~174 ~124 ~130 grass_block
setblock ~174 ~124 ~131 grass_block
setblock ~174 ~125 ~46 poppy
setblock ~174 ~125 ~64 grass_block
setblock ~174 ~125 ~65 grass_block
setblock ~174 ~125 ~66 grass_block
setblock ~174 ~125 ~67 grass_block
setblock ~174 ~125 ~68 grass_block
setblock ~174 ~125 ~69 grass_block
setblock ~174 ~125 ~70 grass_block
setblock ~174 ~125 ~87 grass_block
setblock ~174 ~125 ~88 grass_block
setblock ~174 ~125 ~91 short_grass
setblock ~174 ~125 ~97 poppy
setblock ~174 ~125 ~98 grass_block
setblock ~174 ~125 ~99 grass_block
setblock ~174 ~125 ~100 grass_block
setblock ~174 ~125 ~128 short_grass
setblock ~174 ~125 ~130 short_grass
setblock ~174 ~126 ~98 short_grass
setblock ~175 ~117 ~49 dirt
setblock ~175 ~117 ~90 dirt
setblock ~175 ~117 ~128 dirt
setblock ~175 ~118 ~48 dirt
setblock ~175 ~118 ~49 dirt
setblock ~175 ~118 ~50 dirt
setblock ~175 ~118 ~90 dirt
setblock ~175 ~118 ~91 dirt
setblock ~175 ~118 ~127 dirt
setblock ~175 ~118 ~128 dirt
setblock ~175 ~118 ~129 dirt
setblock ~175 ~119 ~48 dirt
setblock ~175 ~119 ~49 dirt
setblock ~175 ~119 ~50 dirt
setblock ~175 ~119 ~66 dirt
setblock ~175 ~119 ~90 dirt
setblock ~175 ~119 ~91 dirt
setblock ~175 ~119 ~92 dirt
setblock ~175 ~119 ~126 dirt
setblock ~175 ~119 ~127 dirt
setblock ~175 ~119 ~128 dirt
setblock ~175 ~119 ~129 dirt
setblock ~175 ~119 ~147 dirt
setblock ~175 ~120 ~47 dirt
setblock ~175 ~120 ~48 dirt
setblock ~175 ~120 ~49 dirt
setblock ~175 ~120 ~50 dirt
setblock ~175 ~120 ~65 dirt
setblock ~175 ~120 ~66 dirt
setblock ~175 ~120 ~67 dirt
setblock ~175 ~120 ~89 dirt
setblock ~175 ~120 ~90 dirt
setblock ~175 ~120 ~91 dirt
setblock ~175 ~120 ~92 dirt
setblock ~175 ~120 ~93 dirt
setblock ~175 ~120 ~94 dirt
setblock ~175 ~120 ~125 dirt
setblock ~175 ~120 ~126 dirt
setblock ~175 ~120 ~127 dirt
setblock ~175 ~120 ~128 dirt
setblock ~175 ~120 ~129 dirt
setblock ~175 ~120 ~130 dirt
setblock ~175 ~120 ~147 dirt
setblock ~175 ~120 ~148 dirt
setblock ~175 ~121 ~47 dirt
setblock ~175 ~121 ~48 dirt
setblock ~175 ~121 ~49 dirt
setblock ~175 ~121 ~50 dirt
setblock ~175 ~121 ~65 dirt
setblock ~175 ~121 ~66 dirt
setblock ~175 ~121 ~67 dirt
setblock ~175 ~121 ~68 dirt
setblock ~175 ~121 ~88 dirt
setblock ~175 ~121 ~89 dirt
setblock ~175 ~121 ~90 dirt
setblock ~175 ~121 ~91 dirt
setblock ~175 ~121 ~92 dirt
setblock ~175 ~121 ~93 dirt
setblock ~175 ~121 ~94 dirt
setblock ~175 ~121 ~95 dirt
setblock ~175 ~121 ~96 dirt
setblock ~175 ~121 ~98 dirt
setblock ~175 ~121 ~99 dirt
setblock ~175 ~121 ~102 dirt
setblock ~175 ~121 ~103 dirt
setblock ~175 ~121 ~104 dirt
setblock ~175 ~121 ~125 dirt
setblock ~175 ~121 ~126 dirt
setblock ~175 ~121 ~127 dirt
setblock ~175 ~121 ~128 dirt
setblock ~175 ~121 ~129 dirt
setblock ~175 ~121 ~130 dirt
setblock ~175 ~121 ~131 dirt
setblock ~175 ~121 ~146 dirt
setblock ~175 ~121 ~147 dirt
setblock ~175 ~121 ~148 dirt
setblock ~175 ~122 ~47 dirt
setblock ~175 ~122 ~48 dirt
setblock ~175 ~122 ~49 dirt
setblock ~175 ~122 ~50 dirt
setblock ~175 ~122 ~65 dirt
setblock ~175 ~122 ~66 dirt
setblock ~175 ~122 ~67 dirt
setblock ~175 ~122 ~68 dirt
setblock ~175 ~122 ~88 dirt
setblock ~175 ~122 ~89 dirt
setblock ~175 ~122 ~90 dirt
setblock ~175 ~122 ~91 dirt
setblock ~175 ~122 ~92 dirt
setblock ~175 ~122 ~93 dirt
setblock ~175 ~122 ~94 dirt
setblock ~175 ~122 ~95 dirt
setblock ~175 ~122 ~96 dirt
setblock ~175 ~122 ~98 dirt
setblock ~175 ~122 ~99 dirt
setblock ~175 ~122 ~102 dirt
setblock ~175 ~122 ~103 dirt
setblock ~175 ~122 ~104 dirt
setblock ~175 ~122 ~125 dirt
setblock ~175 ~122 ~126 dirt
setblock ~175 ~122 ~127 dirt
setblock ~175 ~122 ~128 dirt
setblock ~175 ~122 ~129 dirt
setblock ~175 ~122 ~130 dirt
setblock ~175 ~122 ~131 dirt
setblock ~175 ~122 ~146 dirt
setblock ~175 ~122 ~147 dirt
setblock ~175 ~122 ~148 dirt
setblock ~175 ~123 ~47 dirt
setblock ~175 ~123 ~48 dirt
setblock ~175 ~123 ~49 dirt
setblock ~175 ~123 ~50 dirt
setblock ~175 ~123 ~65 dirt
setblock ~175 ~123 ~66 dirt
setblock ~175 ~123 ~67 dirt
setblock ~175 ~123 ~68 dirt
setblock ~175 ~123 ~88 dirt
setblock ~175 ~123 ~89 dirt
setblock ~175 ~123 ~90 dirt
setblock ~175 ~123 ~91 dirt
setblock ~175 ~123 ~92 dirt
setblock ~175 ~123 ~93 dirt
setblock ~175 ~123 ~94 dirt
setblock ~175 ~123 ~95 dirt
setblock ~175 ~123 ~96 dirt
setblock ~175 ~123 ~98 dirt
setblock ~175 ~123 ~99 dirt
setblock ~175 ~123 ~102 dirt
setblock ~175 ~123 ~103 dirt
setblock ~175 ~123 ~104 dirt
setblock ~175 ~123 ~125 dirt
setblock ~175 ~123 ~126 dirt
setblock ~175 ~123 ~127 dirt
setblock ~175 ~123 ~128 dirt
setblock ~175 ~123 ~129 dirt
setblock ~175 ~123 ~130 dirt
setblock ~175 ~123 ~131 dirt
setblock ~175 ~123 ~146 dirt
setblock ~175 ~123 ~147 dirt
setblock ~175 ~123 ~148 dirt
setblock ~175 ~124 ~47 dirt
setblock ~175 ~124 ~48 grass_block
setblock ~175 ~124 ~49 grass_block
setblock ~175 ~124 ~50 grass_block
setblock ~175 ~124 ~65 dirt
setblock ~175 ~124 ~66 dirt
setblock ~175 ~124 ~67 dirt
setblock ~175 ~124 ~68 dirt
setblock ~175 ~124 ~88 grass_block
setblock ~175 ~124 ~89 grass_block
setblock ~175 ~124 ~90 grass_block
setblock ~175 ~124 ~91 grass_block
setblock ~175 ~124 ~92 grass_block
setblock ~175 ~124 ~93 grass_block
setblock ~175 ~124 ~94 grass_block
setblock ~175 ~124 ~95 grass_block
setblock ~175 ~124 ~96 grass_block
setblock ~175 ~124 ~98 grass_block
setblock ~175 ~124 ~99 grass_block
setblock ~175 ~124 ~102 dirt
setblock ~175 ~124 ~103 dirt
setblock ~175 ~124 ~104 dirt
setblock ~175 ~124 ~125 grass_block
setblock ~175 ~124 ~126 grass_block
setblock ~175 ~124 ~127 grass_block
setblock ~175 ~124 ~128 grass_block
setblock ~175 ~124 ~129 grass_block
setblock ~175 ~124 ~130 grass_block
setblock ~175 ~124 ~131 grass_block
setblock ~175 ~124 ~146 dirt
setblock ~175 ~124 ~147 dirt
setblock ~175 ~124 ~148 grass_block
setblock ~175 ~125 ~47 grass_block
setblock ~175 ~125 ~48 short_grass
setblock ~175 ~125 ~65 grass_block
setblock ~175 ~125 ~66 grass_block
setblock ~175 ~125 ~67 grass_block
setblock ~175 ~125 ~68 grass_block
setblock ~175 ~125 ~90 fern
setblock ~175 ~125 ~91 short_grass
setblock ~175 ~125 ~92 short_grass
setblock ~175 ~125 ~93 fern
setblock ~175 ~125 ~95 short_grass
setblock ~175 ~125 ~102 grass_block
setblock ~175 ~125 ~103 grass_block
setblock ~175 ~125 ~104 grass_block
setblock ~175 ~125 ~130 short_grass
setblock ~175 ~125 ~146 grass_block
setblock ~175 ~125 ~147 grass_block
setblock ~175 ~126 ~66 short_grass
setblock ~175 ~126 ~67 short_grass
setblock ~176 ~115 ~147 dirt
setblock ~176 ~116 ~147 dirt
setblock ~176 ~117 ~147 dirt
setblock ~176 ~118 ~49 dirt
setblock ~176 ~118 ~103 dirt
setblock ~176 ~118 ~104 dirt
setblock ~176 ~118 ~128 dirt
setblock ~176 ~118 ~147 dirt
setblock ~176 ~119 ~48 dirt
setblock ~176 ~119 ~49 dirt
setblock ~176 ~119 ~50 dirt
setblock ~176 ~119 ~102 dirt
setblock ~176 ~119 ~103 dirt
setblock ~176 ~119 ~104 dirt
setblock ~176 ~119 ~127 dirt
setblock ~176 ~119 ~128 dirt
setblock ~176 ~119 ~129 dirt
setblock ~176 ~119 ~146 dirt
setblock ~176 ~119 ~147 dirt
setblock ~176 ~119 ~148 dirt
setblock ~176 ~120 ~48 dirt
setblock ~176 ~120 ~49 dirt
setblock ~176 ~120 ~50 dirt
setblock ~176 ~120 ~51 dirt
setblock ~176 ~120 ~90 dirt
setblock ~176 ~120 ~93 dirt
setblock ~176 ~120 ~102 dirt
setblock ~176 ~120 ~103 dirt
setblock ~176 ~120 ~104 dirt
setblock ~176 ~120 ~105 dirt
setblock ~176 ~120 ~126 dirt
setblock ~176 ~120 ~127 dirt
setblock ~176 ~120 ~128 dirt
setblock ~176 ~120 ~129 dirt
setblock ~176 ~120 ~146 dirt
setblock ~176 ~120 ~147 dirt
setblock ~176 ~120 ~148 dirt
setblock ~176 ~120 ~149 dirt
setblock ~176 ~121 ~47 dirt
setblock ~176 ~121 ~48 dirt
setblock ~176 ~121 ~49 dirt
setblock ~176 ~121 ~50 dirt
setblock ~176 ~121 ~51 dirt
setblock ~176 ~121 ~89 dirt
setblock ~176 ~121 ~90 dirt
setblock ~176 ~121 ~91 dirt
setblock ~176 ~121 ~92 dirt
setblock ~176 ~121 ~93 dirt
setblock ~176 ~121 ~94 dirt
setblock ~176 ~121 ~95 dirt
setblock ~176 ~121 ~101 dirt
setblock ~176 ~121 ~102 dirt
setblock ~176 ~121 ~103 dirt
setblock ~176 ~121 ~104 dirt
setblock ~176 ~121 ~105 dirt
setblock ~176 ~121 ~106 dirt
setblock ~176 ~121 ~126 dirt
setblock ~176 ~121 ~127 dirt
setblock ~176 ~121 ~128 dirt
setblock ~176 ~121 ~129 dirt
setblock ~176 ~121 ~130 dirt
setblock ~176 ~121 ~145 dirt
setblock ~176 ~121 ~146 dirt
setblock ~176 ~121 ~147 dirt
setblock ~176 ~121 ~148 dirt
setblock ~176 ~121 ~149 dirt
setblock ~176 ~122 ~47 dirt
setblock ~176 ~122 ~48 dirt
setblock ~176 ~122 ~49 dirt
setblock ~176 ~122 ~50 dirt
setblock ~176 ~122 ~51 dirt
setblock ~176 ~122 ~89 dirt
setblock ~176 ~122 ~90 dirt
setblock ~176 ~122 ~91 dirt
setblock ~176 ~122 ~92 dirt
setblock ~176 ~122 ~93 dirt
setblock ~176 ~122 ~94 dirt
setblock ~176 ~122 ~95 dirt
setblock ~176 ~122 ~101 dirt
setblock ~176 ~122 ~102 dirt
setblock ~176 ~122 ~103 dirt
setblock ~176 ~122 ~104 dirt
setblock ~176 ~122 ~105 dirt
setblock ~176 ~122 ~106 dirt
setblock ~176 ~122 ~126 dirt
setblock ~176 ~122 ~127 dirt
setblock ~176 ~122 ~128 dirt
setblock ~176 ~122 ~129 dirt
setblock ~176 ~122 ~130 dirt
setblock ~176 ~122 ~145 dirt
setblock ~176 ~122 ~146 dirt
setblock ~176 ~122 ~147 dirt
setblock ~176 ~122 ~148 dirt
setblock ~176 ~122 ~149 dirt
setblock ~176 ~123 ~47 dirt
setblock ~176 ~123 ~48 dirt
setblock ~176 ~123 ~49 dirt
setblock ~176 ~123 ~50 dirt
setblock ~176 ~123 ~51 dirt
setblock ~176 ~123 ~89 dirt
setblock ~176 ~123 ~90 dirt
setblock ~176 ~123 ~91 dirt
setblock ~176 ~123 ~92 dirt
setblock ~176 ~123 ~93 dirt
setblock ~176 ~123 ~94 dirt
setblock ~176 ~123 ~95 dirt
setblock ~176 ~123 ~101 dirt
setblock ~176 ~123 ~102 dirt
setblock ~176 ~123 ~103 dirt
setblock ~176 ~123 ~104 dirt
setblock ~176 ~123 ~105 dirt
setblock ~176 ~123 ~106 dirt
setblock ~176 ~123 ~126 grass_block
setblock ~176 ~123 ~127 dirt
setblock ~176 ~123 ~128 dirt
setblock ~176 ~123 ~129 dirt
setblock ~176 ~123 ~130 dirt
setblock ~176 ~123 ~145 dirt
setblock ~176 ~123 ~146 dirt
setblock ~176 ~123 ~147 dirt
setblock ~176 ~123 ~148 dirt
setblock ~176 ~123 ~149 dirt
setblock ~176 ~124 ~47 dirt
setblock ~176 ~124 ~48 dirt
setblock ~176 ~124 ~49 dirt
setblock ~176 ~124 ~50 dirt
setblock ~176 ~124 ~51 dirt
setblock ~176 ~124 ~89 grass_block
setblock ~176 ~124 ~90 grass_block
setblock ~176 ~124 ~91 grass_block
setblock ~176 ~124 ~92 grass_block
setblock ~176 ~124 ~93 grass_block
setblock ~176 ~124 ~94 grass_block
setblock ~176 ~124 ~95 grass_block
setblock ~176 ~124 ~101 grass_block
setblock ~176 ~124 ~102 grass_block
setblock ~176 ~124 ~103 grass_block
setblock ~176 ~124 ~104 grass_block
setblock ~176 ~124 ~105 grass_block
setblock ~176 ~124 ~106 grass_block
setblock ~176 ~124 ~127 grass_block
setblock ~176 ~124 ~128 grass_block
setblock ~176 ~124 ~129 grass_block
setblock ~176 ~124 ~130 grass_block
setblock ~176 ~124 ~145 dirt
setblock ~176 ~124 ~146 dirt
setblock ~176 ~124 ~147 dirt
setblock ~176 ~124 ~148 dirt
setblock ~176 ~124 ~149 dirt
setblock ~176 ~125 ~47 grass_block
setblock ~176 ~125 ~48 grass_block
setblock ~176 ~125 ~49 grass_block
setblock ~176 ~125 ~50 grass_block
setblock ~176 ~125 ~51 grass_block
setblock ~176 ~125 ~91 short_grass
setblock ~176 ~125 ~93 short_grass
setblock ~176 ~125 ~103 short_grass
setblock ~176 ~125 ~145 grass_block
setblock ~176 ~125 ~146 grass_block
setblock ~176 ~125 ~147 grass_block
setblock ~176 ~125 ~148 grass_block
setblock ~176 ~125 ~149 grass_block
setblock ~176 ~126 ~47 poppy
setblock ~176 ~126 ~49 short_grass
setblock ~176 ~126 ~145 fern
setblock ~177 ~115 ~104 dirt
setblock ~177 ~116 ~103 dirt
setblock ~177 ~116 ~104 dirt
setblock ~177 ~117 ~102 dirt
setblock ~177 ~117 ~103 dirt
setblock ~177 ~117 ~104 dirt
setblock ~177 ~118 ~93 dirt
setblock ~177 ~118 ~102 dirt
setblock ~177 ~118 ~103 dirt
setblock ~177 ~118 ~104 dirt
setblock ~177 ~118 ~105 dirt
setblock ~177 ~119 ~49 dirt
setblock ~177 ~119 ~92 dirt
setblock ~177 ~119 ~93 dirt
setblock ~177 ~119 ~94 dirt
setblock ~177 ~119 ~101 dirt
setblock ~177 ~119 ~102 dirt
setblock ~177 ~119 ~103 dirt
setblock ~177 ~119 ~104 dirt
setblock ~177 ~119 ~105 dirt
setblock ~177 ~119 ~128 dirt
setblock ~177 ~119 ~147 dirt
setblock ~177 ~120 ~49 dirt
setblock ~177 ~120 ~50 dirt
setblock ~177 ~120 ~91 dirt
setblock ~177 ~120 ~92 dirt
setblock ~177 ~120 ~93 dirt
setblock ~177 ~120 ~94 dirt
setblock ~177 ~120 ~95 dirt
setblock ~177 ~120 ~101 dirt
setblock ~177 ~120 ~102 dirt
setblock ~177 ~120 ~103 dirt
setblock ~177 ~120 ~104 dirt
setblock ~177 ~120 ~105 dirt
setblock ~177 ~120 ~106 dirt
setblock ~177 ~120 ~127 dirt
setblock ~177 ~120 ~128 dirt
setblock ~177 ~120 ~129 dirt
setblock ~177 ~120 ~147 dirt
setblock ~177 ~120 ~148 dirt
setblock ~177 ~121 ~48 dirt
setblock ~177 ~121 ~49 dirt
setblock ~177 ~121 ~50 dirt
setblock ~177 ~121 ~90 dirt
setblock ~177 ~121 ~91 dirt
setblock ~177 ~121 ~92 dirt
setblock ~177 ~121 ~93 dirt
setblock ~177 ~121 ~94 dirt
setblock ~177 ~121 ~95 dirt
setblock ~177 ~121 ~96 dirt
setblock ~177 ~121 ~100 dirt
setblock ~177 ~121 ~101 dirt
setblock ~177 ~121 ~102 dirt
setblock ~177 ~121 ~103 dirt
setblock ~177 ~121 ~104 dirt
setblock ~177 ~121 ~105 dirt
setblock ~177 ~121 ~106 dirt
setblock ~177 ~121 ~107 dirt
setblock ~177 ~121 ~127 dirt
setblock ~177 ~121 ~128 dirt
setblock ~177 ~121 ~129 dirt
setblock ~177 ~121 ~146 dirt
setblock ~177 ~121 ~147 dirt
setblock ~177 ~121 ~148 dirt
setblock ~177 ~122 ~48 dirt
setblock ~177 ~122 ~49 dirt
setblock ~177 ~122 ~50 dirt
setblock ~177 ~122 ~90 dirt
setblock ~177 ~122 ~91 dirt
setblock ~177 ~122 ~92 dirt
setblock ~177 ~122 ~93 dirt
setblock ~177 ~122 ~94 dirt
setblock ~177 ~122 ~95 dirt
setblock ~177 ~122 ~96 dirt
setblock ~177 ~122 ~100 dirt
setblock ~177 ~122 ~101 dirt
setblock ~177 ~122 ~102 dirt
setblock ~177 ~122 ~103 dirt
setblock ~177 ~122 ~104 dirt
setblock ~177 ~122 ~105 dirt
setblock ~177 ~122 ~106 dirt
setblock ~177 ~122 ~107 dirt
setblock ~177 ~122 ~127 dirt
setblock ~177 ~122 ~128 dirt
setblock ~177 ~122 ~129 dirt
setblock ~177 ~122 ~146 dirt
setblock ~177 ~122 ~147 dirt
setblock ~177 ~122 ~148 dirt
setblock ~177 ~123 ~48 dirt
setblock ~177 ~123 ~49 dirt
setblock ~177 ~123 ~50 dirt
setblock ~177 ~123 ~90 grass_block
setblock ~177 ~123 ~91 grass_block
setblock ~177 ~123 ~92 dirt
setblock ~177 ~123 ~93 dirt
setblock ~177 ~123 ~94 dirt
setblock ~177 ~123 ~95 dirt
setblock ~177 ~123 ~96 dirt
setblock ~177 ~123 ~100 dirt
setblock ~177 ~123 ~101 dirt
setblock ~177 ~123 ~102 dirt
setblock ~177 ~123 ~103 dirt
setblock ~177 ~123 ~104 dirt
setblock ~177 ~123 ~105 dirt
setblock ~177 ~123 ~106 dirt
setblock ~177 ~123 ~107 dirt
setblock ~177 ~123 ~127 grass_block
setblock ~177 ~123 ~128 grass_block
setblock ~177 ~123 ~129 grass_block
setblock ~177 ~123 ~146 dirt
setblock ~177 ~123 ~147 dirt
setblock ~177 ~123 ~148 dirt
setblock ~177 ~124 ~48 dirt
setblock ~177 ~124 ~49 dirt
setblock ~177 ~124 ~50 dirt
setblock ~177 ~124 ~92 grass_block
setblock ~177 ~124 ~93 grass_block
setblock ~177 ~124 ~94 grass_block
setblock ~177 ~124 ~95 grass_block
setblock ~177 ~124 ~96 grass_block
setblock ~177 ~124 ~100 grass_block
setblock ~177 ~124 ~101 grass_block
setblock ~177 ~124 ~102 grass_block
setblock ~177 ~124 ~103 grass_block
setblock ~177 ~124 ~104 grass_block
setblock ~177 ~124 ~105 grass_block
setblock ~177 ~124 ~106 grass_block
setblock ~177 ~124 ~107 grass_block
setblock ~177 ~124 ~128 short_grass
setblock ~177 ~124 ~146 dirt
setblock ~177 ~124 ~147 dirt
setblock ~177 ~124 ~148 dirt
setblock ~177 ~125 ~48 grass_block
setblock ~177 ~125 ~49 grass_block
setblock ~177 ~125 ~50 grass_block
setblock ~177 ~125 ~93 short_grass
setblock ~177 ~125 ~104 short_grass
setblock ~177 ~125 ~146 grass_block
setblock ~177 ~125 ~147 grass_block
setblock ~177 ~125 ~148 grass_block
setblock ~177 ~126 ~48 poppy
setblock ~177 ~126 ~49 short_grass
setblock ~177 ~126 ~146 short_grass
setblock ~178 ~113 ~103 dirt
setblock ~178 ~114 ~103 dirt
setblock ~178 ~114 ~104 dirt
setblock ~178 ~115 ~103 dirt
setblock ~178 ~115 ~104 dirt
setblock ~178 ~115 ~105 dirt
setblock ~178 ~116 ~92 dirt
setblock ~178 ~116 ~102 dirt
setblock ~178 ~116 ~103 dirt
setblock ~178 ~116 ~104 dirt
setblock ~178 ~116 ~105 dirt
setblock ~178 ~117 ~92 dirt
setblock ~178 ~117 ~93 dirt
setblock ~178 ~117 ~101 dirt
setblock ~178 ~117 ~102 dirt
setblock ~178 ~117 ~103 dirt
setblock ~178 ~117 ~104 dirt
setblock ~178 ~117 ~105 dirt
setblock ~178 ~118 ~92 dirt
setblock ~178 ~118 ~93 dirt
setblock ~178 ~118 ~94 dirt
setblock ~178 ~118 ~101 dirt
setblock ~178 ~118 ~102 dirt
setblock ~178 ~118 ~103 dirt
setblock ~178 ~118 ~104 dirt
setblock ~178 ~118 ~105 dirt
setblock ~178 ~118 ~106 dirt
setblock ~178 ~119 ~91 dirt
setblock ~178 ~119 ~92 dirt
setblock ~178 ~119 ~93 dirt
setblock ~178 ~119 ~94 dirt
setblock ~178 ~119 ~95 dirt
setblock ~178 ~119 ~100 dirt
setblock ~178 ~119 ~101 dirt
setblock ~178 ~119 ~102 dirt
setblock ~178 ~119 ~103 dirt
setblock ~178 ~119 ~104 dirt
setblock ~178 ~119 ~105 dirt
setblock ~178 ~119 ~106 dirt
setblock ~178 ~120 ~90 dirt
setblock ~178 ~120 ~91 dirt
setblock ~178 ~120 ~92 dirt
setblock ~178 ~120 ~93 dirt
setblock ~178 ~120 ~94 dirt
setblock ~178 ~120 ~95 dirt
setblock ~178 ~120 ~96 dirt
setblock ~178 ~120 ~99 dirt
setblock ~178 ~120 ~100 dirt
setblock ~178 ~120 ~101 dirt
setblock ~178 ~120 ~102 dirt
setblock ~178 ~120 ~103 dirt
setblock ~178 ~120 ~104 dirt
setblock ~178 ~120 ~105 dirt
setblock ~178 ~120 ~106 dirt
setblock ~178 ~120 ~107 dirt
setblock ~178 ~120 ~128 dirt
setblock ~178 ~121 ~89 dirt
setblock ~178 ~121 ~90 dirt
setblock ~178 ~121 ~91 dirt
setblock ~178 ~121 ~92 dirt
setblock ~178 ~121 ~93 dirt
setblock ~178 ~121 ~94 dirt
setblock ~178 ~121 ~95 dirt
setblock ~178 ~121 ~96 dirt
setblock ~178 ~121 ~97 dirt
setblock ~178 ~121 ~98 dirt
setblock ~178 ~121 ~99 dirt
setblock ~178 ~121 ~100 dirt
setblock ~178 ~121 ~101 dirt
setblock ~178 ~121 ~102 dirt
setblock ~178 ~121 ~103 dirt
setblock ~178 ~121 ~104 dirt
setblock ~178 ~121 ~105 dirt
setblock ~178 ~121 ~106 dirt
setblock ~178 ~121 ~107 dirt
setblock ~178 ~121 ~108 dirt
setblock ~178 ~121 ~127 dirt
setblock ~178 ~121 ~128 dirt
setblock ~178 ~121 ~129 dirt
setblock ~178 ~121 ~147 dirt
setblock ~178 ~122 ~89 dirt
setblock ~178 ~122 ~90 dirt
setblock ~178 ~122 ~91 dirt
setblock ~178 ~122 ~92 dirt
setblock ~178 ~122 ~93 dirt
setblock ~178 ~122 ~94 dirt
setblock ~178 ~122 ~95 dirt
setblock ~178 ~122 ~96 dirt
setblock ~178 ~122 ~97 dirt
setblock ~178 ~122 ~98 dirt
setblock ~178 ~122 ~99 dirt
setblock ~178 ~122 ~100 dirt
setblock ~178 ~122 ~101 dirt
setblock ~178 ~122 ~102 dirt
setblock ~178 ~122 ~103 dirt
setblock ~178 ~122 ~104 dirt
setblock ~178 ~122 ~105 dirt
setblock ~178 ~122 ~106 dirt
setblock ~178 ~122 ~107 dirt
setblock ~178 ~122 ~108 dirt
setblock ~178 ~122 ~127 dirt
setblock ~178 ~122 ~128 dirt
setblock ~178 ~122 ~129 dirt
setblock ~178 ~122 ~147 dirt
setblock ~178 ~123 ~89 grass_block
setblock ~178 ~123 ~90 grass_block
setblock ~178 ~123 ~91 grass_block
setblock ~178 ~123 ~92 grass_block
setblock ~178 ~123 ~93 grass_block
setblock ~178 ~123 ~94 grass_block
setblock ~178 ~123 ~95 dirt
setblock ~178 ~123 ~96 dirt
setblock ~178 ~123 ~97 dirt
setblock ~178 ~123 ~98 dirt
setblock ~178 ~123 ~99 dirt
setblock ~178 ~123 ~100 dirt
setblock ~178 ~123 ~101 dirt
setblock ~178 ~123 ~102 dirt
setblock ~178 ~123 ~103 dirt
setblock ~178 ~123 ~104 dirt
setblock ~178 ~123 ~105 dirt
setblock ~178 ~123 ~106 dirt
setblock ~178 ~123 ~107 dirt
setblock ~178 ~123 ~108 dirt
setblock ~178 ~123 ~127 grass_block
setblock ~178 ~123 ~128 grass_block
setblock ~178 ~123 ~129 grass_block
setblock ~178 ~123 ~147 dirt
setblock ~178 ~124 ~89 poppy
setblock ~178 ~124 ~93 short_grass
setblock ~178 ~124 ~95 grass_block
setblock ~178 ~124 ~96 grass_block
setblock ~178 ~124 ~97 grass_block
setblock ~178 ~124 ~98 grass_block
setblock ~178 ~124 ~99 grass_block
setblock ~178 ~124 ~100 grass_block
setblock ~178 ~124 ~101 grass_block
setblock ~178 ~124 ~102 grass_block
setblock ~178 ~124 ~103 grass_block
setblock ~178 ~124 ~104 grass_block
setblock ~178 ~124 ~105 grass_block
setblock ~178 ~124 ~106 grass_block
setblock ~178 ~124 ~107 grass_block
setblock ~178 ~124 ~108 grass_block
setblock ~178 ~124 ~147 dirt
setblock ~178 ~125 ~96 short_grass
setblock ~178 ~125 ~98 short_grass
setblock ~178 ~125 ~101 short_grass
setblock ~178 ~125 ~147 grass_block
setblock ~179 ~112 ~103 dirt
setblock ~179 ~113 ~92 dirt
setblock ~179 ~113 ~102 dirt
setblock ~179 ~113 ~103 dirt
setblock ~179 ~113 ~104 dirt
setblock ~179 ~114 ~92 dirt
setblock ~179 ~114 ~102 dirt
setblock ~179 ~114 ~103 dirt
setblock ~179 ~114 ~104 dirt
setblock ~179 ~114 ~105 dirt
setblock ~179 ~115 ~92 dirt
setblock ~179 ~115 ~102 dirt
setblock ~179 ~115 ~103 dirt
setblock ~179 ~115 ~104 dirt
setblock ~179 ~115 ~105 dirt
setblock ~179 ~116 ~91 dirt
setblock ~179 ~116 ~92 dirt
setblock ~179 ~116 ~93 dirt
setblock ~179 ~116 ~101 dirt
setblock ~179 ~116 ~102 dirt
setblock ~179 ~116 ~103 dirt
setblock ~179 ~116 ~104 dirt
setblock ~179 ~116 ~105 dirt
setblock ~179 ~117 ~91 dirt
setblock ~179 ~117 ~92 dirt
setblock ~179 ~117 ~93 dirt
setblock ~179 ~117 ~94 dirt
setblock ~179 ~117 ~101 dirt
setblock ~179 ~117 ~102 dirt
setblock ~179 ~117 ~103 dirt
setblock ~179 ~117 ~104 dirt
setblock ~179 ~117 ~105 dirt
setblock ~179 ~117 ~106 dirt
setblock ~179 ~118 ~91 dirt
setblock ~179 ~118 ~92 dirt
setblock ~179 ~118 ~93 dirt
setblock ~179 ~118 ~94 dirt
setblock ~179 ~118 ~95 dirt
setblock ~179 ~118 ~100 dirt
setblock ~179 ~118 ~101 dirt
setblock ~179 ~118 ~102 dirt
setblock ~179 ~118 ~103 dirt
setblock ~179 ~118 ~104 dirt
setblock ~179 ~118 ~105 dirt
setblock ~179 ~118 ~106 dirt
setblock ~179 ~118 ~107 dirt
setblock ~179 ~119 ~90 dirt
setblock ~179 ~119 ~91 dirt
setblock ~179 ~119 ~92 dirt
setblock ~179 ~119 ~93 dirt
setblock ~179 ~119 ~94 dirt
setblock ~179 ~119 ~95 dirt
setblock ~179 ~119 ~96 dirt
setblock ~179 ~119 ~99 dirt
setblock ~179 ~119 ~100 dirt
setblock ~179 ~119 ~101 dirt
setblock ~179 ~119 ~102 dirt
setblock ~179 ~119 ~103 dirt
setblock ~179 ~119 ~104 dirt
setblock ~179 ~119 ~105 dirt
setblock ~179 ~119 ~106 dirt
setblock ~179 ~119 ~107 dirt
setblock ~179 ~120 ~90 dirt
setblock ~179 ~120 ~91 dirt
setblock ~179 ~120 ~92 dirt
setblock ~179 ~120 ~93 dirt
setblock ~179 ~120 ~94 dirt
setblock ~179 ~120 ~95 dirt
setblock ~179 ~120 ~96 dirt
setblock ~179 ~120 ~97 dirt
setblock ~179 ~120 ~98 dirt
setblock ~179 ~120 ~99 dirt
setblock ~179 ~120 ~100 dirt
setblock ~179 ~120 ~101 dirt
setblock ~179 ~120 ~102 dirt
setblock ~179 ~120 ~103 dirt
setblock ~179 ~120 ~104 dirt
setblock ~179 ~120 ~105 dirt
setblock ~179 ~120 ~106 dirt
setblock ~179 ~120 ~107 dirt
setblock ~179 ~120 ~108 dirt
setblock ~179 ~121 ~89 dirt
setblock ~179 ~121 ~90 dirt
setblock ~179 ~121 ~91 dirt
setblock ~179 ~121 ~92 dirt
setblock ~179 ~121 ~93 dirt
setblock ~179 ~121 ~94 dirt
setblock ~179 ~121 ~95 dirt
setblock ~179 ~121 ~96 dirt
setblock ~179 ~121 ~97 dirt
setblock ~179 ~121 ~98 dirt
setblock ~179 ~121 ~99 dirt
setblock ~179 ~121 ~100 dirt
setblock ~179 ~121 ~101 dirt
setblock ~179 ~121 ~102 dirt
setblock ~179 ~121 ~103 dirt
setblock ~179 ~121 ~104 dirt
setblock ~179 ~121 ~105 dirt
setblock ~179 ~121 ~106 dirt
setblock ~179 ~121 ~107 dirt
setblock ~179 ~121 ~108 dirt
setblock ~179 ~121 ~128 dirt
setblock ~179 ~122 ~89 dirt
setblock ~179 ~122 ~90 dirt
setblock ~179 ~122 ~91 dirt
setblock ~179 ~122 ~92 dirt
setblock ~179 ~122 ~93 dirt
setblock ~179 ~122 ~94 dirt
setblock ~179 ~122 ~95 dirt
setblock ~179 ~122 ~96 dirt
setblock ~179 ~122 ~97 dirt
setblock ~179 ~122 ~98 dirt
setblock ~179 ~122 ~99 dirt
setblock ~179 ~122 ~100 dirt
setblock ~179 ~122 ~101 dirt
setblock ~179 ~122 ~102 dirt
setblock ~179 ~122 ~103 dirt
setblock ~179 ~122 ~104 dirt
setblock ~179 ~122 ~105 dirt
setblock ~179 ~122 ~106 dirt
setblock ~179 ~122 ~107 dirt
setblock ~179 ~122 ~108 dirt
setblock ~179 ~122 ~128 dirt
setblock ~179 ~123 ~89 grass_block
setblock ~179 ~123 ~90 grass_block
setblock ~179 ~123 ~91 grass_block
setblock ~179 ~123 ~92 grass_block
setblock ~179 ~123 ~93 grass_block
setblock ~179 ~123 ~94 grass_block
setblock ~179 ~123 ~95 grass_block
setblock ~179 ~123 ~96 grass_block
setblock ~179 ~123 ~97 dirt
setblock ~179 ~123 ~98 dirt
setblock ~179 ~123 ~99 dirt
setblock ~179 ~123 ~100 dirt
setblock ~179 ~123 ~101 dirt
setblock ~179 ~123 ~102 dirt
setblock ~179 ~123 ~103 dirt
setblock ~179 ~123 ~104 dirt
setblock ~179 ~123 ~105 grass_block
setblock ~179 ~123 ~106 grass_block
setblock ~179 ~123 ~107 grass_block
setblock ~179 ~123 ~108 grass_block
setblock ~179 ~123 ~128 grass_block
setblock ~179 ~124 ~89 short_grass
setblock ~179 ~124 ~92 short_grass
setblock ~179 ~124 ~97 grass_block
setblock ~179 ~124 ~98 grass_block
setblock ~179 ~124 ~99 grass_block
setblock ~179 ~124 ~100 grass_block
setblock ~179 ~124 ~101 grass_block
setblock ~179 ~124 ~102 grass_block
setblock ~179 ~124 ~103 grass_block
setblock ~179 ~124 ~104 grass_block
setblock ~179 ~124 ~105 short_grass
setblock ~179 ~124 ~107 short_grass
setblock ~179 ~124 ~108 fern
setblock ~179 ~124 ~128 short_grass
setblock ~179 ~125 ~98 short_grass
setblock ~180 ~113 ~103 dirt
setblock ~180 ~114 ~103 dirt
setblock ~180 ~114 ~104 dirt
setblock ~180 ~115 ~102 dirt
setblock ~180 ~115 ~103 dirt
setblock ~180 ~115 ~104 dirt
setblock ~180 ~115 ~105 dirt
setblock ~180 ~116 ~92 dirt
setblock ~180 ~116 ~102 dirt
setblock ~180 ~116 ~103 dirt
setblock ~180 ~116 ~104 dirt
setblock ~180 ~116 ~105 dirt
setblock ~180 ~117 ~92 dirt
setblock ~180 ~117 ~93 dirt
setblock ~180 ~117 ~102 dirt
setblock ~180 ~117 ~103 dirt
setblock ~180 ~117 ~104 dirt
setblock ~180 ~117 ~105 dirt
setblock ~180 ~117 ~106 dirt
setblock ~180 ~118 ~91 dirt
setblock ~180 ~118 ~92 dirt
setblock ~180 ~118 ~93 dirt
setblock ~180 ~118 ~94 dirt
setblock ~180 ~118 ~101 dirt
setblock ~180 ~118 ~102 dirt
setblock ~180 ~118 ~103 dirt
setblock ~180 ~118 ~104 dirt
setblock ~180 ~118 ~105 dirt
setblock ~180 ~118 ~106 dirt
setblock ~180 ~118 ~107 dirt
setblock ~180 ~119 ~91 dirt
setblock ~180 ~119 ~92 dirt
setblock ~180 ~119 ~93 dirt
setblock ~180 ~119 ~94 dirt
setblock ~180 ~119 ~95 dirt
setblock ~180 ~119 ~100 dirt
setblock ~180 ~119 ~101 dirt
setblock ~180 ~119 ~102 dirt
setblock ~180 ~119 ~103 dirt
setblock ~180 ~119 ~104 dirt
setblock ~180 ~119 ~105 dirt
setblock ~180 ~119 ~106 dirt
setblock ~180 ~119 ~107 dirt
setblock ~180 ~120 ~90 dirt
setblock ~180 ~120 ~91 dirt
setblock ~180 ~120 ~92 dirt
setblock ~180 ~120 ~93 dirt
setblock ~180 ~120 ~94 dirt
setblock ~180 ~120 ~95 dirt
setblock ~180 ~120 ~96 dirt
setblock ~180 ~120 ~99 dirt
setblock ~180 ~120 ~100 dirt
setblock ~180 ~120 ~101 dirt
setblock ~180 ~120 ~102 dirt
setblock ~180 ~120 ~103 dirt
setblock ~180 ~120 ~104 dirt
setblock ~180 ~120 ~105 dirt
setblock ~180 ~120 ~106 dirt
setblock ~180 ~120 ~107 dirt
setblock ~180 ~121 ~89 dirt
setblock ~180 ~121 ~90 dirt
setblock ~180 ~121 ~91 dirt
setblock ~180 ~121 ~92 dirt
setblock ~180 ~121 ~93 dirt
setblock ~180 ~121 ~94 dirt
setblock ~180 ~121 ~95 dirt
setblock ~180 ~121 ~96 dirt
setblock ~180 ~121 ~97 dirt
setblock ~180 ~121 ~98 dirt
setblock ~180 ~121 ~99 dirt
setblock ~180 ~121 ~100 dirt
setblock ~180 ~121 ~101 dirt
setblock ~180 ~121 ~102 dirt
setblock ~180 ~121 ~103 dirt
setblock ~180 ~121 ~104 dirt
setblock ~180 ~121 ~105 dirt
setblock ~180 ~121 ~106 dirt
setblock ~180 ~121 ~107 dirt
setblock ~180 ~121 ~108 dirt
setblock ~180 ~122 ~89 dirt
setblock ~180 ~122 ~90 grass_block
setblock ~180 ~122 ~91 dirt
setblock ~180 ~122 ~92 dirt
setblock ~180 ~122 ~93 dirt
setblock ~180 ~122 ~94 dirt
setblock ~180 ~122 ~95 dirt
setblock ~180 ~122 ~96 dirt
setblock ~180 ~122 ~97 dirt
setblock ~180 ~122 ~98 dirt
setblock ~180 ~122 ~99 dirt
setblock ~180 ~122 ~100 dirt
setblock ~180 ~122 ~101 dirt
setblock ~180 ~122 ~102 dirt
setblock ~180 ~122 ~103 dirt
setblock ~180 ~122 ~104 dirt
setblock ~180 ~122 ~105 dirt
setblock ~180 ~122 ~106 dirt
setblock ~180 ~122 ~107 dirt
setblock ~180 ~122 ~108 dirt
setblock ~180 ~123 ~89 grass_block
setblock ~180 ~123 ~90 short_grass
setblock ~180 ~123 ~91 grass_block
setblock ~180 ~123 ~92 grass_block
setblock ~180 ~123 ~93 grass_block
setblock ~180 ~123 ~94 grass_block
setblock ~180 ~123 ~95 grass_block
setblock ~180 ~123 ~96 grass_block
setblock ~180 ~123 ~97 grass_block
setblock ~180 ~123 ~98 grass_block
setblock ~180 ~123 ~99 dirt
setblock ~180 ~123 ~100 dirt
setblock ~180 ~123 ~101 dirt
setblock ~180 ~123 ~102 grass_block
setblock ~180 ~123 ~103 grass_block
setblock ~180 ~123 ~104 grass_block
setblock ~180 ~123 ~105 grass_block
setblock ~180 ~123 ~106 grass_block
setblock ~180 ~123 ~107 grass_block
setblock ~180 ~123 ~108 grass_block
setblock ~180 ~124 ~92 poppy
setblock ~180 ~124 ~93 short_grass
setblock ~180 ~124 ~98 short_grass
setblock ~180 ~124 ~99 grass_block
setblock ~180 ~124 ~100 grass_block
setblock ~180 ~124 ~101 grass_block
setblock ~180 ~124 ~105 short_grass
setblock ~181 ~115 ~103 dirt
setblock ~181 ~115 ~104 dirt
setblock ~181 ~116 ~103 dirt
setblock ~181 ~116 ~104 dirt
setblock ~181 ~117 ~102 dirt
setblock ~181 ~117 ~103 dirt
setblock ~181 ~117 ~104 dirt
setblock ~181 ~117 ~105 dirt
setblock ~181 ~118 ~92 dirt
setblock ~181 ~118 ~93 dirt
setblock ~181 ~118 ~102 dirt
setblock ~181 ~118 ~103 dirt
setblock ~181 ~118 ~104 dirt
setblock ~181 ~118 ~105 dirt
setblock ~181 ~118 ~106 dirt
setblock ~181 ~119 ~92 dirt
setblock ~181 ~119 ~93 dirt
setblock ~181 ~119 ~101 dirt
setblock ~181 ~119 ~102 dirt
setblock ~181 ~119 ~103 dirt
setblock ~181 ~119 ~104 dirt
setblock ~181 ~119 ~105 dirt
setblock ~181 ~119 ~106 dirt
setblock ~181 ~120 ~91 dirt
setblock ~181 ~120 ~92 dirt
setblock ~181 ~120 ~93 dirt
setblock ~181 ~120 ~100 dirt
setblock ~181 ~120 ~101 dirt
setblock ~181 ~120 ~102 dirt
setblock ~181 ~120 ~103 dirt
setblock ~181 ~120 ~104 dirt
setblock ~181 ~120 ~105 dirt
setblock ~181 ~120 ~106 dirt
setblock ~181 ~120 ~107 dirt
setblock ~181 ~121 ~90 dirt
setblock ~181 ~121 ~91 dirt
setblock ~181 ~121 ~92 dirt
setblock ~181 ~121 ~93 dirt
setblock ~181 ~121 ~94 dirt
setblock ~181 ~121 ~95 dirt
setblock ~181 ~121 ~96 dirt
setblock ~181 ~121 ~99 dirt
setblock ~181 ~121 ~100 dirt
setblock ~181 ~121 ~101 dirt
setblock ~181 ~121 ~102 dirt
setblock ~181 ~121 ~103 dirt
setblock ~181 ~121 ~104 dirt
setblock ~181 ~121 ~105 dirt
setblock ~181 ~121 ~106 dirt
setblock ~181 ~121 ~107 dirt
setblock ~181 ~122 ~90 dirt
setblock ~181 ~122 ~91 dirt
setblock ~181 ~122 ~92 dirt
setblock ~181 ~122 ~93 dirt
setblock ~181 ~122 ~94 dirt
setblock ~181 ~122 ~95 dirt
setblock ~181 ~122 ~96 dirt
setblock ~181 ~122 ~99 dirt
setblock ~181 ~122 ~100 dirt
setblock ~181 ~122 ~101 dirt
setblock ~181 ~122 ~102 dirt
setblock ~181 ~122 ~103 dirt
setblock ~181 ~122 ~104 dirt
setblock ~181 ~122 ~105 dirt
setblock ~181 ~122 ~106 dirt
setblock ~181 ~122 ~107 dirt
setblock ~181 ~123 ~90 grass_block
setblock ~181 ~123 ~91 grass_block
setblock ~181 ~123 ~92 grass_block
setblock ~181 ~123 ~93 grass_block
setblock ~181 ~123 ~94 grass_block
setblock ~181 ~123 ~95 grass_block
setblock ~181 ~123 ~96 dirt
setblock ~181 ~123 ~99 dirt
setblock ~181 ~123 ~100 dirt
setblock ~181 ~123 ~101 dirt
setblock ~181 ~123 ~102 dirt
setblock ~181 ~123 ~103 dirt
setblock ~181 ~123 ~104 dirt
setblock ~181 ~123 ~105 dirt
setblock ~181 ~123 ~106 grass_block
setblock ~181 ~123 ~107 grass_block
setblock ~181 ~124 ~96 grass_block
setblock ~181 ~124 ~99 grass_block
setblock ~181 ~124 ~100 grass_block
setblock ~181 ~124 ~101 grass_block
setblock ~181 ~124 ~102 grass_block
setblock ~181 ~124 ~103 grass_block
setblock ~181 ~124 ~104 grass_block
setblock ~181 ~124 ~105 grass_block
setblock ~181 ~124 ~106 poppy
setblock ~181 ~124 ~107 fern
setblock ~181 ~125 ~96 short_grass
setblock ~181 ~125 ~102 fern
setblock ~181 ~125 ~103 poppy
setblock ~181 ~125 ~104 short_grass
setblock ~181 ~125 ~105 short_grass
setblock ~182 ~117 ~103 dirt
setblock ~182 ~117 ~104 dirt
setblock ~182 ~118 ~103 dirt
setblock ~182 ~118 ~104 dirt
setblock ~182 ~118 ~105 dirt
setblock ~182 ~119 ~103 dirt
setblock ~182 ~119 ~104 dirt
setblock ~182 ~119 ~105 dirt
setblock ~182 ~120 ~92 dirt
setblock ~182 ~120 ~101 dirt
setblock ~182 ~120 ~102 dirt
setblock ~182 ~120 ~103 dirt
setblock ~182 ~120 ~104 dirt
setblock ~182 ~120 ~105 dirt
setblock ~182 ~120 ~106 dirt
setblock ~182 ~121 ~68 dirt
setblock ~182 ~121 ~92 dirt
setblock ~182 ~121 ~93 dirt
setblock ~182 ~121 ~100 dirt
setblock ~182 ~121 ~101 dirt
setblock ~182 ~121 ~102 dirt
setblock ~182 ~121 ~103 dirt
setblock ~182 ~121 ~104 dirt
setblock ~182 ~121 ~105 dirt
setblock ~182 ~121 ~106 dirt
setblock ~182 ~121 ~107 dirt
setblock ~182 ~122 ~68 dirt
setblock ~182 ~122 ~92 dirt
setblock ~182 ~122 ~93 dirt
setblock ~182 ~122 ~100 dirt
setblock ~182 ~122 ~101 dirt
setblock ~182 ~122 ~102 dirt
setblock ~182 ~122 ~103 dirt
setblock ~182 ~122 ~104 dirt
setblock ~182 ~122 ~105 dirt
setblock ~182 ~122 ~106 dirt
setblock ~182 ~122 ~107 dirt
setblock ~182 ~123 ~68 dirt
setblock ~182 ~123 ~92 grass_block
setblock ~182 ~123 ~93 grass_block
setblock ~182 ~123 ~100 dirt
setblock ~182 ~123 ~101 dirt
setblock ~182 ~123 ~102 dirt
setblock ~182 ~123 ~103 dirt
setblock ~182 ~123 ~104 dirt
setblock ~182 ~123 ~105 dirt
setblock ~182 ~123 ~106 dirt
setblock ~182 ~123 ~107 dirt
setblock ~182 ~124 ~68 grass_block
setblock ~182 ~124 ~100 dirt
setblock ~182 ~124 ~101 grass_block
setblock ~182 ~124 ~102 grass_block
setblock ~182 ~124 ~103 grass_block
setblock ~182 ~124 ~104 grass_block
setblock ~182 ~124 ~105 grass_block
setblock ~182 ~124 ~106 grass_block
setblock ~182 ~124 ~107 grass_block
setblock ~182 ~125 ~68 short_grass
setblock ~182 ~125 ~100 grass_block
setblock ~182 ~125 ~106 short_grass
setblock ~183 ~119 ~104 dirt
setblock ~183 ~120 ~68 dirt
setblock ~183 ~120 ~103 dirt
setblock ~183 ~120 ~104 dirt
setblock ~183 ~121 ~67 dirt
setblock ~183 ~121 ~68 dirt
setblock ~183 ~121 ~69 dirt
setblock ~183 ~121 ~102 dirt
setblock ~183 ~121 ~103 dirt
setblock ~183 ~121 ~104 dirt
setblock ~183 ~121 ~105 dirt
setblock ~183 ~121 ~106 dirt
setblock ~183 ~122 ~67 dirt
setblock ~183 ~122 ~68 dirt
setblock ~183 ~122 ~69 dirt
setblock ~183 ~122 ~102 dirt
setblock ~183 ~122 ~103 dirt
setblock ~183 ~122 ~104 dirt
setblock ~183 ~122 ~105 dirt
setblock ~183 ~122 ~106 dirt
setblock ~183 ~123 ~67 dirt
setblock ~183 ~123 ~68 dirt
setblock ~183 ~123 ~69 dirt
setblock ~183 ~123 ~102 dirt
setblock ~183 ~123 ~103 dirt
setblock ~183 ~123 ~104 dirt
setblock ~183 ~123 ~105 dirt
setblock ~183 ~123 ~106 dirt
setblock ~183 ~124 ~67 grass_block
setblock ~183 ~124 ~68 grass_block
setblock ~183 ~124 ~69 grass_block
setblock ~183 ~124 ~102 dirt
setblock ~183 ~124 ~103 dirt
setblock ~183 ~124 ~104 grass_block
setblock ~183 ~124 ~105 grass_block
setblock ~183 ~124 ~106 grass_block
setblock ~183 ~125 ~68 short_grass
setblock ~183 ~125 ~69 short_grass
setblock ~183 ~125 ~102 grass_block
setblock ~183 ~125 ~103 grass_block
setblock ~183 ~125 ~104 fern
setblock ~183 ~126 ~102 short_grass
setblock ~184 ~118 ~68 dirt
setblock ~184 ~119 ~68 dirt
setblock ~184 ~120 ~67 dirt
setblock ~184 ~120 ~68 dirt
setblock ~184 ~120 ~69 dirt
setblock ~184 ~121 ~67 dirt
setblock ~184 ~121 ~68 dirt
setblock ~184 ~121 ~69 dirt
setblock ~184 ~121 ~104 dirt
setblock ~184 ~122 ~67 dirt
setblock ~184 ~122 ~68 dirt
setblock ~184 ~122 ~69 dirt
setblock ~184 ~122 ~104 dirt
setblock ~184 ~123 ~67 dirt
setblock ~184 ~123 ~68 dirt
setblock ~184 ~123 ~69 dirt
setblock ~184 ~123 ~104 dirt
setblock ~184 ~124 ~67 grass_block
setblock ~184 ~124 ~68 grass_block
setblock ~184 ~124 ~69 grass_block
setblock ~184 ~124 ~104 dirt
setblock ~184 ~125 ~104 grass_block
setblock ~185 ~120 ~68 dirt
setblock ~185 ~120 ~78 dirt
setblock ~185 ~121 ~68 dirt
setblock ~185 ~121 ~78 dirt
setblock ~185 ~121 ~79 dirt
setblock ~185 ~122 ~68 dirt
setblock ~185 ~122 ~78 dirt
setblock ~185 ~122 ~79 dirt
setblock ~185 ~123 ~68 grass_block
setblock ~185 ~123 ~78 dirt
setblock ~185 ~123 ~79 dirt
setblock ~185 ~124 ~78 dirt
setblock ~185 ~124 ~79 dirt
setblock ~185 ~125 ~78 grass_block
setblock ~185 ~125 ~79 dirt
setblock ~185 ~126 ~78 short_grass
setblock ~185 ~126 ~79 grass_block
setblock ~186 ~118 ~78 dirt
setblock ~186 ~119 ~78 dirt
setblock ~186 ~120 ~77 dirt
setblock ~186 ~120 ~78 dirt
setblock ~186 ~120 ~79 dirt
setblock ~186 ~121 ~77 dirt
setblock ~186 ~121 ~78 dirt
setblock ~186 ~121 ~79 dirt
setblock ~186 ~121 ~80 dirt
setblock ~186 ~122 ~77 dirt
setblock ~186 ~122 ~78 dirt
setblock ~186 ~122 ~79 dirt
setblock ~186 ~122 ~80 dirt
setblock ~186 ~123 ~77 dirt
setblock ~186 ~123 ~78 dirt
setblock ~186 ~123 ~79 dirt
setblock ~186 ~123 ~80 dirt
setblock ~186 ~124 ~77 dirt
setblock ~186 ~124 ~78 dirt
setblock ~186 ~124 ~79 dirt
setblock ~186 ~124 ~80 dirt
setblock ~186 ~125 ~77 grass_block
setblock ~186 ~125 ~78 dirt
setblock ~186 ~125 ~79 dirt
setblock ~186 ~125 ~80 dirt
setblock ~186 ~126 ~77 short_grass
setblock ~186 ~126 ~78 grass_block
setblock ~186 ~126 ~79 grass_block
setblock ~186 ~126 ~80 grass_block
setblock ~186 ~127 ~78 short_grass
setblock ~187 ~116 ~78 dirt
setblock ~187 ~117 ~78 dirt
setblock ~187 ~118 ~77 dirt
setblock ~187 ~118 ~78 dirt
setblock ~187 ~118 ~79 dirt
setblock ~187 ~119 ~77 dirt
setblock ~187 ~119 ~78 dirt
setblock ~187 ~119 ~79 dirt
setblock ~187 ~120 ~77 dirt
setblock ~187 ~120 ~78 dirt
setblock ~187 ~120 ~79 dirt
setblock ~187 ~120 ~80 dirt
setblock ~187 ~121 ~76 dirt
setblock ~187 ~121 ~77 dirt
setblock ~187 ~121 ~78 dirt
setblock ~187 ~121 ~79 dirt
setblock ~187 ~121 ~80 dirt
setblock ~187 ~122 ~76 dirt
setblock ~187 ~122 ~77 dirt
setblock ~187 ~122 ~78 dirt
setblock ~187 ~122 ~79 dirt
setblock ~187 ~122 ~80 dirt
setblock ~187 ~123 ~76 dirt
setblock ~187 ~123 ~77 dirt
setblock ~187 ~123 ~78 dirt
setblock ~187 ~123 ~79 dirt
setblock ~187 ~123 ~80 dirt
setblock ~187 ~124 ~76 dirt
setblock ~187 ~124 ~77 dirt
setblock ~187 ~124 ~78 dirt
setblock ~187 ~124 ~79 dirt
setblock ~187 ~124 ~80 dirt
setblock ~187 ~125 ~76 grass_block
setblock ~187 ~125 ~77 grass_block
setblock ~187 ~125 ~78 dirt
setblock ~187 ~125 ~79 dirt
setblock ~187 ~125 ~80 dirt
setblock ~187 ~126 ~76 short_grass
setblock ~187 ~126 ~77 poppy
setblock ~187 ~126 ~78 grass_block
setblock ~187 ~126 ~79 grass_block
setblock ~187 ~126 ~80 grass_block
setblock ~187 ~127 ~78 short_grass
setblock ~188 ~118 ~78 dirt
setblock ~188 ~119 ~78 dirt
setblock ~188 ~120 ~77 dirt
setblock ~188 ~120 ~78 dirt
setblock ~188 ~120 ~79 dirt
setblock ~188 ~121 ~77 dirt
setblock ~188 ~121 ~78 dirt
setblock ~188 ~121 ~79 dirt
setblock ~188 ~121 ~80 dirt
setblock ~188 ~122 ~77 dirt
setblock ~188 ~122 ~78 dirt
setblock ~188 ~122 ~79 dirt
setblock ~188 ~122 ~80 dirt
setblock ~188 ~123 ~77 dirt
setblock ~188 ~123 ~78 dirt
setblock ~188 ~123 ~79 dirt
setblock ~188 ~123 ~80 dirt
setblock ~188 ~124 ~77 dirt
setblock ~188 ~124 ~78 dirt
setblock ~188 ~124 ~79 dirt
setblock ~188 ~124 ~80 dirt
setblock ~188 ~125 ~77 grass_block
setblock ~188 ~125 ~78 dirt
setblock ~188 ~125 ~79 dirt
setblock ~188 ~125 ~80 dirt
setblock ~188 ~126 ~78 grass_block
setblock ~188 ~126 ~79 grass_block
setblock ~188 ~126 ~80 grass_block
setblock ~189 ~120 ~78 dirt
setblock ~189 ~121 ~78 dirt
setblock ~189 ~121 ~79 dirt
setblock ~189 ~122 ~78 dirt
setblock ~189 ~122 ~79 dirt
setblock ~189 ~123 ~78 dirt
setblock ~189 ~123 ~79 dirt
setblock ~189 ~124 ~78 dirt
setblock ~189 ~124 ~79 dirt
setblock ~189 ~125 ~78 dirt
setblock ~189 ~125 ~79 dirt
setblock ~189 ~126 ~78 grass_block
setblock ~189 ~126 ~79 grass_block
setblock ~199 ~200 ~199 gold_block
