setblock ~172 ~159 ~95 oak_wood
setblock ~172 ~159 ~96 jungle_leaves[persistent=true]
setblock ~172 ~159 ~97 oak_wood
setblock ~172 ~159 ~98 oak_leaves[persistent=true]
setblock ~172 ~159 ~99 oak_wood
setblock ~172 ~159 ~101 oak_leaves[persistent=true]
setblock ~172 ~159 ~102 oak_leaves[persistent=true]
setblock ~172 ~159 ~103 oak_leaves[persistent=true]
setblock ~172 ~159 ~105 oak_leaves[persistent=true]
setblock ~172 ~160 ~83 oak_leaves[persistent=true]
setblock ~172 ~160 ~84 oak_leaves[persistent=true]
setblock ~172 ~160 ~86 oak_leaves[persistent=true]
setblock ~172 ~160 ~87 oak_leaves[persistent=true]
setblock ~172 ~160 ~88 oak_wood
setblock ~172 ~160 ~89 oak_wood
setblock ~172 ~160 ~90 oak_leaves[persistent=true]
setblock ~172 ~160 ~91 oak_wood
setblock ~172 ~160 ~92 oak_leaves[persistent=true]
setblock ~172 ~160 ~93 oak_wood
setblock ~172 ~160 ~94 oak_wood
setblock ~172 ~160 ~95 oak_wood
setblock ~172 ~160 ~96 oak_wood
setblock ~172 ~160 ~97 jungle_leaves[persistent=true]
setblock ~172 ~160 ~98 oak_wood
setblock ~172 ~160 ~99 oak_wood
setblock ~172 ~160 ~100 oak_leaves[persistent=true]
setblock ~172 ~160 ~101 jungle_leaves[persistent=true]
setblock ~172 ~160 ~102 oak_leaves[persistent=true]
setblock ~172 ~160 ~103 oak_leaves[persistent=true]
setblock ~172 ~160 ~104 jungle_leaves[persistent=true]
setblock ~172 ~160 ~105 oak_leaves[persistent=true]
setblock ~172 ~161 ~83 oak_leaves[persistent=true]
setblock ~172 ~161 ~84 oak_leaves[persistent=true]
setblock ~172 ~161 ~85 oak_leaves[persistent=true]
setblock ~172 ~161 ~86 oak_leaves[persistent=true]
setblock ~172 ~161 ~87 oak_leaves[persistent=true]
setblock ~172 ~161 ~89 oak_wood
setblock ~172 ~161 ~90 oak_leaves[persistent=true]
setblock ~172 ~161 ~91 oak_leaves[persistent=true]
setblock ~172 ~161 ~92 oak_wood
setblock ~172 ~161 ~93 oak_wood
setblock ~172 ~161 ~94 oak_leaves[persistent=true]
setblock ~172 ~161 ~95 oak_wood
setblock ~172 ~161 ~96 oak_wood
setblock ~172 ~161 ~97 oak_wood
setblock ~172 ~161 ~98 oak_wood
setblock ~172 ~161 ~99 oak_wood
setblock ~172 ~161 ~100 jungle_leaves[persistent=true]
setblock ~172 ~161 ~101 oak_leaves[persistent=true]
setblock ~172 ~161 ~102 oak_leaves[persistent=true]
setblock ~172 ~161 ~103 jungle_leaves[persistent=true]
setblock ~172 ~161 ~105 jungle_leaves[persistent=true]
setblock ~172 ~162 ~83 oak_leaves[persistent=true]
setblock ~172 ~162 ~84 oak_leaves[persistent=true]
setblock ~172 ~162 ~85 oak_leaves[persistent=true]
setblock ~172 ~162 ~87 oak_leaves[persistent=true]
setblock ~172 ~162 ~88 oak_leaves[persistent=true]
setblock ~172 ~162 ~89 oak_wood
setblock ~172 ~162 ~90 oak_wood
setblock ~172 ~162 ~91 oak_wood
setblock ~172 ~162 ~92 oak_wood
setblock ~172 ~162 ~93 oak_wood
setblock ~172 ~162 ~94 oak_wood
setblock ~172 ~162 ~95 oak_wood
setblock ~172 ~162 ~96 oak_wood
setblock ~172 ~162 ~97 oak_leaves[persistent=true]
setblock ~172 ~162 ~98 oak_wood
setblock ~172 ~162 ~99 oak_wood
setblock ~172 ~162 ~100 oak_leaves[persistent=true]
setblock ~172 ~162 ~101 oak_leaves[persistent=true]
setblock ~172 ~162 ~102 jungle_leaves[persistent=true]
setblock ~172 ~162 ~103 oak_leaves[persistent=true]
setblock ~172 ~162 ~104 oak_leaves[persistent=true]
setblock ~172 ~162 ~105 oak_leaves[persistent=true]
setblock ~172 ~163 ~82 oak_leaves[persistent=true]
setblock ~172 ~163 ~83 oak_leaves[persistent=true]
setblock ~172 ~163 ~84 oak_leaves[persistent=true]
setblock ~172 ~163 ~85 jungle_leaves[persistent=true]
setblock ~172 ~163 ~86 oak_leaves[persistent=true]
setblock ~172 ~163 ~87 oak_wood
setblock ~172 ~163 ~88 oak_wood
setblock ~172 ~163 ~89 oak_wood
setblock ~172 ~163 ~90 oak_log
setblock ~172 ~163 ~91 jungle_leaves[persistent=true]
setblock ~172 ~163 ~92 oak_wood
setblock ~172 ~163 ~93 oak_wood
setblock ~172 ~163 ~95 oak_wood
setblock ~172 ~163 ~96 oak_wood
setblock ~172 ~163 ~97 oak_wood
setblock ~172 ~163 ~98 oak_wood
setblock ~172 ~163 ~99 oak_leaves[persistent=true]
setblock ~172 ~163 ~100 oak_wood
setblock ~172 ~163 ~101 oak_leaves[persistent=true]
setblock ~172 ~163 ~102 oak_leaves[persistent=true]
setblock ~172 ~163 ~103 oak_leaves[persistent=true]
setblock ~172 ~164 ~81 oak_leaves[persistent=true]
setblock ~172 ~164 ~82 oak_leaves[persistent=true]
setblock ~172 ~164 ~83 oak_leaves[persistent=true]
setblock ~172 ~164 ~84 oak_leaves[persistent=true]
setblock ~172 ~164 ~85 oak_leaves[persistent=true]
setblock ~172 ~164 ~86 oak_wood
setblock ~172 ~164 ~87 jungle_leaves[persistent=true]
setblock ~172 ~164 ~88 oak_wood
setblock ~172 ~164 ~89 oak_leaves[persistent=true]
setblock ~172 ~164 ~90 oak_leaves[persistent=true]
setblock ~172 ~164 ~91 oak_wood
setblock ~172 ~164 ~92 oak_log
setblock ~172 ~164 ~93 oak_wood
setblock ~172 ~164 ~94 oak_wood
setblock ~172 ~164 ~95 oak_leaves[persistent=true]
setblock ~172 ~164 ~96 oak_wood
setblock ~172 ~164 ~97 oak_wood
setblock ~172 ~164 ~98 oak_wood
setblock ~172 ~164 ~99 oak_leaves[persistent=true]
setblock ~172 ~164 ~100 oak_leaves[persistent=true]
setblock ~172 ~164 ~101 oak_leaves[persistent=true]
setblock ~172 ~164 ~102 oak_leaves[persistent=true]
setblock ~172 ~164 ~103 oak_leaves[persistent=true]
setblock ~172 ~164 ~104 oak_leaves[persistent=true]
setblock ~172 ~164 ~105 oak_leaves[persistent=true]
setblock ~172 ~165 ~81 oak_leaves[persistent=true]
setblock ~172 ~165 ~82 oak_leaves[persistent=true]
setblock ~172 ~165 ~83 oak_leaves[persistent=true]
setblock ~172 ~165 ~84 oak_leaves[persistent=true]
setblock ~172 ~165 ~85 oak_wood
setblock ~172 ~165 ~86 jungle_leaves[persistent=true]
setblock ~172 ~165 ~87 oak_wood
setblock ~172 ~165 ~88 oak_wood
setblock ~172 ~165 ~89 oak_wood
setblock ~172 ~165 ~90 oak_wood
setblock ~172 ~165 ~91 oak_wood
setblock ~172 ~165 ~92 oak_log
setblock ~172 ~165 ~93 oak_wood
setblock ~172 ~165 ~94 oak_leaves[persistent=true]
setblock ~172 ~165 ~95 oak_wood
setblock ~172 ~165 ~96 oak_wood
setblock ~172 ~165 ~97 oak_leaves[persistent=true]
setblock ~172 ~165 ~98 oak_wood
setblock ~172 ~165 ~99 oak_wood
setblock ~172 ~165 ~100 oak_wood
setblock ~172 ~165 ~101 oak_wood
setblock ~172 ~165 ~102 oak_wood
setblock ~172 ~165 ~103 oak_leaves[persistent=true]
setblock ~172 ~165 ~105 oak_leaves[persistent=true]
setblock ~172 ~166 ~81 oak_leaves[persistent=true]
setblock ~172 ~166 ~82 oak_leaves[persistent=true]
setblock ~172 ~166 ~83 oak_wood
setblock ~172 ~166 ~84 oak_leaves[persistent=true]
setblock ~172 ~166 ~85 oak_leaves[persistent=true]
setblock ~172 ~166 ~86 oak_leaves[persistent=true]
setblock ~172 ~166 ~87 oak_wood
setblock ~172 ~166 ~88 oak_wood
setblock ~172 ~166 ~89 jungle_leaves[persistent=true]
setblock ~172 ~166 ~90 oak_leaves[persistent=true]
setblock ~172 ~166 ~91 oak_wood
setblock ~172 ~166 ~92 oak_wood
setblock ~172 ~166 ~93 oak_wood
setblock ~172 ~166 ~94 oak_wood
setblock ~172 ~166 ~95 oak_wood
setblock ~172 ~166 ~96 oak_leaves[persistent=true]
setblock ~172 ~166 ~97 oak_wood
setblock ~172 ~166 ~98 oak_wood
setblock ~172 ~166 ~99 oak_leaves[persistent=true]
setblock ~172 ~166 ~100 oak_leaves[persistent=true]
setblock ~172 ~166 ~101 jungle_leaves[persistent=true]
setblock ~172 ~166 ~102 oak_leaves[persistent=true]
setblock ~172 ~166 ~103 oak_wood
setblock ~172 ~166 ~104 jungle_leaves[persistent=true]
setblock ~172 ~166 ~105 oak_leaves[persistent=true]
setblock ~172 ~167 ~81 oak_leaves[persistent=true]
setblock ~172 ~167 ~82 oak_leaves[persistent=true]
setblock ~172 ~167 ~83 oak_leaves[persistent=true]
setblock ~172 ~167 ~84 oak_leaves[persistent=true]
setblock ~172 ~167 ~85 oak_leaves[persistent=true]
setblock ~172 ~167 ~86 oak_wood
setblock ~172 ~167 ~87 oak_leaves[persistent=true]
setblock ~172 ~167 ~88 oak_wood
setblock ~172 ~167 ~89 jungle_leaves[persistent=true]
setblock ~172 ~167 ~90 oak_wood
setblock ~172 ~167 ~91 oak_log
setblock ~172 ~167 ~92 oak_log
setblock ~172 ~167 ~93 oak_wood
setblock ~172 ~167 ~94 oak_wood
setblock ~172 ~167 ~95 oak_leaves[persistent=true]
setblock ~172 ~167 ~96 oak_wood
setblock ~172 ~167 ~97 oak_wood
setblock ~172 ~167 ~98 oak_wood
setblock ~172 ~167 ~99 oak_leaves[persistent=true]
setblock ~172 ~167 ~100 oak_wood
setblock ~172 ~167 ~101 oak_wood
setblock ~172 ~167 ~102 oak_leaves[persistent=true]
setblock ~172 ~167 ~103 oak_wood
setblock ~172 ~167 ~104 jungle_leaves[persistent=true]
setblock ~172 ~167 ~105 oak_leaves[persistent=true]
setblock ~172 ~168 ~82 jungle_leaves[persistent=true]
setblock ~172 ~168 ~83 oak_leaves[persistent=true]
setblock ~172 ~168 ~84 jungle_leaves[persistent=true]
setblock ~172 ~168 ~85 oak_wood
setblock ~172 ~168 ~86 oak_leaves[persistent=true]
setblock ~172 ~168 ~88 oak_leaves[persistent=true]
setblock ~172 ~168 ~89 oak_leaves[persistent=true]
setblock ~172 ~168 ~90 oak_leaves[persistent=true]
setblock ~172 ~168 ~91 oak_wood
setblock ~172 ~168 ~92 jungle_leaves[persistent=true]
setblock ~172 ~168 ~93 oak_wood
setblock ~172 ~168 ~94 oak_log
setblock ~172 ~168 ~95 oak_log
setblock ~172 ~168 ~96 oak_wood
setblock ~172 ~168 ~97 oak_log
setblock ~172 ~168 ~98 oak_log
setblock ~172 ~168 ~99 oak_wood
setblock ~172 ~168 ~100 oak_leaves[persistent=true]
setblock ~172 ~168 ~101 oak_leaves[persistent=true]
setblock ~172 ~168 ~103 oak_leaves[persistent=true]
setblock ~172 ~168 ~104 oak_leaves[persistent=true]
setblock ~172 ~168 ~105 jungle_leaves[persistent=true]
setblock ~172 ~169 ~82 oak_leaves[persistent=true]
setblock ~172 ~169 ~83 oak_leaves[persistent=true]
setblock ~172 ~169 ~84 oak_leaves[persistent=true]
setblock ~172 ~169 ~85 oak_leaves[persistent=true]
setblock ~172 ~169 ~86 jungle_leaves[persistent=true]
setblock ~172 ~169 ~87 oak_leaves[persistent=true]
setblock ~172 ~169 ~88 oak_leaves[persistent=true]
setblock ~172 ~169 ~89 oak_log
setblock ~172 ~169 ~90 oak_log
setblock ~172 ~169 ~92 oak_wood
setblock ~172 ~169 ~93 oak_log
setblock ~172 ~169 ~94 oak_log
setblock ~172 ~169 ~95 oak_leaves[persistent=true]
setblock ~172 ~169 ~97 oak_log
setblock ~172 ~169 ~98 oak_leaves[persistent=true]
setblock ~172 ~169 ~99 oak_log
setblock ~172 ~169 ~100 oak_log
setblock ~172 ~169 ~101 oak_leaves[persistent=true]
setblock ~172 ~169 ~102 oak_leaves[persistent=true]
setblock ~172 ~169 ~103 jungle_leaves[persistent=true]
setblock ~172 ~169 ~104 oak_leaves[persistent=true]
setblock ~172 ~169 ~105 oak_leaves[persistent=true]
setblock ~172 ~170 ~83 oak_leaves[persistent=true]
setblock ~172 ~170 ~84 oak_leaves[persistent=true]
setblock ~172 ~170 ~85 oak_leaves[persistent=true]
setblock ~172 ~170 ~86 oak_leaves[persistent=true]
setblock ~172 ~170 ~87 oak_leaves[persistent=true]
setblock ~172 ~170 ~88 oak_leaves[persistent=true]
setblock ~172 ~170 ~90 jungle_leaves[persistent=true]
setblock ~172 ~170 ~93 oak_wood
setblock ~172 ~170 ~94 oak_leaves[persistent=true]
setblock ~172 ~170 ~95 jungle_leaves[persistent=true]
setblock ~172 ~170 ~96 oak_leaves[persistent=true]
setblock ~172 ~170 ~97 oak_leaves[persistent=true]
setblock ~172 ~170 ~98 oak_wood
setblock ~172 ~170 ~100 jungle_leaves[persistent=true]
setblock ~172 ~170 ~102 oak_leaves[persistent=true]
setblock ~172 ~170 ~103 oak_leaves[persistent=true]
setblock ~172 ~170 ~104 jungle_leaves[persistent=true]
setblock ~172 ~171 ~83 jungle_leaves[persistent=true]
setblock ~172 ~171 ~84 oak_leaves[persistent=true]
setblock ~172 ~171 ~85 oak_leaves[persistent=true]
setblock ~172 ~171 ~87 jungle_leaves[persistent=true]
setblock ~172 ~171 ~88 oak_leaves[persistent=true]
setblock ~172 ~171 ~91 oak_leaves[persistent=true]
setblock ~172 ~171 ~92 jungle_leaves[persistent=true]
setblock ~172 ~171 ~93 oak_leaves[persistent=true]
setblock ~172 ~171 ~94 oak_leaves[persistent=true]
setblock ~172 ~171 ~95 oak_leaves[persistent=true]
setblock ~172 ~171 ~96 jungle_leaves[persistent=true]
setblock ~172 ~171 ~97 oak_leaves[persistent=true]
setblock ~172 ~171 ~98 oak_leaves[persistent=true]
setblock ~172 ~171 ~100 oak_leaves[persistent=true]
setblock ~172 ~171 ~101 jungle_leaves[persistent=true]
setblock ~172 ~171 ~102 oak_leaves[persistent=true]
setblock ~173 ~120 ~118 dirt
setblock ~173 ~120 ~119 dirt
setblock ~173 ~121 ~117 dirt
setblock ~173 ~121 ~118 dirt
setblock ~173 ~121 ~119 dirt
setblock ~173 ~122 ~117 dirt
setblock ~173 ~122 ~118 dirt
setblock ~173 ~122 ~119 dirt
setblock ~173 ~123 ~117 dirt
setblock ~173 ~123 ~118 dirt
setblock ~173 ~123 ~119 dirt
setblock ~173 ~124 ~117 dirt
setblock ~173 ~124 ~118 dirt
setblock ~173 ~124 ~119 dirt
setblock ~173 ~125 ~117 grass_block
setblock ~173 ~125 ~118 grass_block
setblock ~173 ~125 ~119 grass_block
setblock ~173 ~126 ~117 short_grass
setblock ~173 ~141 ~96 oak_leaves[persistent=true]
setblock ~173 ~141 ~97 oak_leaves[persistent=true]
setblock ~173 ~141 ~98 oak_leaves[persistent=true]
setblock ~173 ~142 ~96 oak_leaves[persistent=true]
setblock ~173 ~142 ~97 jungle_leaves[persistent=true]
setblock ~173 ~143 ~96 oak_leaves[persistent=true]
setblock ~173 ~143 ~97 oak_leaves[persistent=true]
setblock ~173 ~143 ~98 oak_leaves[persistent=true]
setblock ~173 ~147 ~92 oak_leaves[persistent=true]
setblock ~173 ~147 ~93 jungle_leaves[persistent=true]
setblock ~173 ~147 ~94 oak_leaves[persistent=true]
setblock ~173 ~147 ~95 oak_leaves[persistent=true]
setblock ~173 ~147 ~96 oak_leaves[persistent=true]
setblock ~173 ~147 ~97 jungle_leaves[persistent=true]
setblock ~173 ~147 ~98 oak_leaves[persistent=true]
setblock ~173 ~147 ~99 oak_leaves[persistent=true]
setblock ~173 ~148 ~92 oak_leaves[persistent=true]
setblock ~173 ~148 ~93 oak_leaves[persistent=true]
setblock ~173 ~148 ~94 oak_leaves[persistent=true]
setblock ~173 ~148 ~95 oak_leaves[persistent=true]
setblock ~173 ~148 ~97 oak_leaves[persistent=true]
setblock ~173 ~148 ~98 oak_leaves[persistent=true]
setblock ~173 ~148 ~99 oak_leaves[persistent=true]
setblock ~173 ~148 ~100 oak_leaves[persistent=true]
setblock ~173 ~149 ~92 oak_leaves[persistent=true]
setblock ~173 ~149 ~93 oak_leaves[persistent=true]
setblock ~173 ~149 ~94 jungle_leaves[persistent=true]
setblock ~173 ~149 ~95 oak_leaves[persistent=true]
setblock ~173 ~149 ~96 jungle_leaves[persistent=true]
setblock ~173 ~149 ~97 oak_leaves[persistent=true]
setblock ~173 ~149 ~98 oak_leaves[persistent=true]
setblock ~173 ~149 ~99 oak_leaves[persistent=true]
setblock ~173 ~149 ~100 oak_leaves[persistent=true]
setblock ~173 ~150 ~83 oak_leaves[persistent=true]
setblock ~173 ~150 ~85 oak_leaves[persistent=true]
setblock ~173 ~150 ~86 oak_leaves[persistent=true]
setblock ~173 ~150 ~91 oak_leaves[persistent=true]
setblock ~173 ~150 ~92 oak_leaves[persistent=true]
setblock ~173 ~150 ~93 oak_leaves[persistent=true]
setblock ~173 ~150 ~94 oak_wood
setblock ~173 ~150 ~96 oak_leaves[persistent=true]
setblock ~173 ~150 ~97 oak_leaves[persistent=true]
setblock ~173 ~150 ~98 jungle_leaves[persistent=true]
setblock ~173 ~150 ~99 oak_leaves[persistent=true]
setblock ~173 ~150 ~100 oak_leaves[persistent=true]
setblock ~173 ~151 ~83 oak_leaves[persistent=true]
setblock ~173 ~151 ~84 oak_leaves[persistent=true]
setblock ~173 ~151 ~86 oak_leaves[persistent=true]
setblock ~173 ~151 ~87 oak_leaves[persistent=true]
setblock ~173 ~151 ~88 oak_leaves[persistent=true]
setblock ~173 ~151 ~91 oak_leaves[persistent=true]
setblock ~173 ~151 ~92 oak_leaves[persistent=true]
setblock ~173 ~151 ~93 jungle_leaves[persistent=true]
setblock ~173 ~151 ~94 oak_leaves[persistent=true]
setblock ~173 ~151 ~95 jungle_leaves[persistent=true]
setblock ~173 ~151 ~96 oak_wood
setblock ~173 ~151 ~97 oak_leaves[persistent=true]
setblock ~173 ~151 ~98 jungle_leaves[persistent=true]
setblock ~173 ~151 ~99 oak_leaves[persistent=true]
setblock ~173 ~152 ~83 oak_leaves[persistent=true]
setblock ~173 ~152 ~84 jungle_leaves[persistent=true]
setblock ~173 ~152 ~85 oak_leaves[persistent=true]
setblock ~173 ~152 ~86 oak_leaves[persistent=true]
setblock ~173 ~152 ~87 oak_leaves[persistent=true]
setblock ~173 ~152 ~88 oak_leaves[persistent=true]
setblock ~173 ~152 ~91 jungle_leaves[persistent=true]
setblock ~173 ~152 ~92 oak_leaves[persistent=true]
setblock ~173 ~152 ~93 oak_leaves[persistent=true]
setblock ~173 ~152 ~94 oak_wood
setblock ~173 ~152 ~95 oak_leaves[persistent=true]
setblock ~173 ~152 ~96 jungle_leaves[persistent=true]
setblock ~173 ~152 ~97 jungle_leaves[persistent=true]
setblock ~173 ~152 ~98 oak_leaves[persistent=true]
setblock ~173 ~153 ~83 oak_leaves[persistent=true]
setblock ~173 ~153 ~85 oak_leaves[persistent=true]
setblock ~173 ~153 ~87 jungle_leaves[persistent=true]
setblock ~173 ~153 ~88 jungle_leaves[persistent=true]
setblock ~173 ~153 ~89 oak_leaves[persistent=true]
setblock ~173 ~153 ~90 oak_leaves[persistent=true]
setblock ~173 ~153 ~91 oak_leaves[persistent=true]
setblock ~173 ~153 ~92 oak_leaves[persistent=true]
setblock ~173 ~153 ~93 oak_leaves[persistent=true]
setblock ~173 ~153 ~95 jungle_leaves[persistent=true]
setblock ~173 ~153 ~96 oak_leaves[persistent=true]
setblock ~173 ~153 ~97 oak_leaves[persistent=true]
setblock ~173 ~153 ~99 oak_leaves[persistent=true]
setblock ~173 ~154 ~84 oak_leaves[persistent=true]
setblock ~173 ~154 ~85 oak_leaves[persistent=true]
setblock ~173 ~154 ~86 oak_leaves[persistent=true]
setblock ~173 ~154 ~87 oak_leaves[persistent=true]
setblock ~173 ~154 ~88 oak_leaves[persistent=true]
setblock ~173 ~154 ~89 oak_leaves[persistent=true]
setblock ~173 ~154 ~90 oak_leaves[persistent=true]
setblock ~173 ~154 ~91 oak_leaves[persistent=true]
setblock ~173 ~154 ~92 oak_leaves[persistent=true]
setblock ~173 ~154 ~93 jungle_leaves[persistent=true]
setblock ~173 ~154 ~94 oak_wood
setblock ~173 ~154 ~95 oak_leaves[persistent=true]
setblock ~173 ~154 ~97 oak_leaves[persistent=true]
setblock ~173 ~154 ~98 jungle_leaves[persistent=true]
setblock ~173 ~154 ~99 oak_leaves[persistent=true]
setblock ~173 ~155 ~85 oak_leaves[persistent=true]
setblock ~173 ~155 ~86 oak_leaves[persistent=true]
setblock ~173 ~155 ~87 oak_leaves[persistent=true]
setblock ~173 ~155 ~88 oak_leaves[persistent=true]
setblock ~173 ~155 ~89 jungle_leaves[persistent=true]
setblock ~173 ~155 ~90 oak_leaves[persistent=true]
setblock ~173 ~155 ~91 oak_leaves[persistent=true]
setblock ~173 ~155 ~92 oak_leaves[persistent=true]
setblock ~173 ~155 ~93 oak_wood
setblock ~173 ~155 ~94 oak_log
setblock ~173 ~155 ~95 oak_leaves[persistent=true]
setblock ~173 ~155 ~96 oak_leaves[persistent=true]
setblock ~173 ~155 ~97 oak_leaves[persistent=true]
setblock ~173 ~156 ~85 oak_leaves[persistent=true]
setblock ~173 ~156 ~86 oak_leaves[persistent=true]
setblock ~173 ~156 ~88 oak_leaves[persistent=true]
setblock ~173 ~156 ~90 oak_leaves[persistent=true]
setblock ~173 ~156 ~91 oak_leaves[persistent=true]
setblock ~173 ~156 ~92 oak_wood
setblock ~173 ~156 ~93 oak_wood
setblock ~173 ~156 ~94 oak_wood
setblock ~173 ~156 ~95 oak_wood
setblock ~173 ~156 ~97 oak_leaves[persistent=true]
setblock ~173 ~156 ~98 oak_leaves[persistent=true]
setblock ~173 ~156 ~99 oak_leaves[persistent=true]
setblock ~173 ~157 ~85 oak_leaves[persistent=true]
setblock ~173 ~157 ~86 oak_leaves[persistent=true]
setblock ~173 ~157 ~87 oak_leaves[persistent=true]
setblock ~173 ~157 ~88 oak_leaves[persistent=true]
setblock ~173 ~157 ~89 oak_leaves[persistent=true]
setblock ~173 ~157 ~90 oak_leaves[persistent=true]
setblock ~173 ~157 ~91 oak_wood
setblock ~173 ~157 ~92 oak_leaves[persistent=true]
setblock ~173 ~157 ~93 oak_wood
setblock ~173 ~157 ~94 oak_wood
setblock ~173 ~157 ~95 oak_leaves[persistent=true]
setblock ~173 ~157 ~96 oak_leaves[persistent=true]
setblock ~173 ~157 ~98 oak_leaves[persistent=true]
setblock ~173 ~157 ~100 oak_leaves[persistent=true]
setblock ~173 ~158 ~85 oak_leaves[persistent=true]
setblock ~173 ~158 ~86 jungle_leaves[persistent=true]
setblock ~173 ~158 ~87 oak_leaves[persistent=true]
setblock ~173 ~158 ~88 oak_leaves[persistent=true]
setblock ~173 ~158 ~90 oak_wood
setblock ~173 ~158 ~91 oak_wood
setblock ~173 ~158 ~92 oak_wood
setblock ~173 ~158 ~93 oak_leaves[persistent=true]
setblock ~173 ~158 ~94 jungle_leaves[persistent=true]
setblock ~173 ~158 ~95 oak_wood
setblock ~173 ~158 ~96 oak_wood
setblock ~173 ~158 ~97 oak_leaves[persistent=true]
setblock ~173 ~158 ~98 oak_leaves[persistent=true]
setblock ~173 ~158 ~99 oak_leaves[persistent=true]
setblock ~173 ~158 ~101 jungle_leaves[persistent=true]
setblock ~173 ~159 ~85 oak_leaves[persistent=true]
setblock ~173 ~159 ~86 jungle_leaves[persistent=true]
setblock ~173 ~159 ~87 jungle_leaves[persistent=true]
setblock ~173 ~159 ~88 oak_leaves[persistent=true]
setblock ~173 ~159 ~89 oak_wood
setblock ~173 ~159 ~90 oak_wood
setblock ~173 ~159 ~91 oak_leaves[persistent=true]
setblock ~173 ~159 ~92 oak_log
setblock ~173 ~159 ~93 oak_wood
setblock ~173 ~159 ~94 oak_leaves[persistent=true]
setblock ~173 ~159 ~95 oak_wood
setblock ~173 ~159 ~96 oak_leaves[persistent=true]
setblock ~173 ~159 ~97 oak_wood
setblock ~173 ~159 ~98 oak_wood
setblock ~173 ~159 ~99 oak_leaves[persistent=true]
setblock ~173 ~159 ~100 oak_leaves[persistent=true]
setblock ~173 ~159 ~101 oak_leaves[persistent=true]
setblock ~173 ~159 ~102 oak_leaves[persistent=true]
setblock ~173 ~160 ~85 oak_leaves[persistent=true]
setblock ~173 ~160 ~86 oak_leaves[persistent=true]
setblock ~173 ~160 ~87 oak_leaves[persistent=true]
setblock ~173 ~160 ~88 oak_wood
setblock ~173 ~160 ~89 oak_wood
setblock ~173 ~160 ~90 oak_wood
setblock ~173 ~160 ~91 jungle_leaves[persistent=true]
setblock ~173 ~160 ~92 oak_leaves[persistent=true]
setblock ~173 ~160 ~93 oak_wood
setblock ~173 ~160 ~94 oak_wood
setblock ~173 ~160 ~95 oak_wood
setblock ~173 ~160 ~96 oak_wood
setblock ~173 ~160 ~97 jungle_leaves[persistent=true]
setblock ~173 ~160 ~98 oak_leaves[persistent=true]
setblock ~173 ~160 ~99 oak_leaves[persistent=true]
setblock ~173 ~160 ~100 oak_wood
setblock ~173 ~160 ~101 oak_leaves[persistent=true]
setblock ~173 ~160 ~102 oak_leaves[persistent=true]
setblock ~173 ~161 ~86 oak_leaves[persistent=true]
setblock ~173 ~161 ~87 oak_leaves[persistent=true]
setblock ~173 ~161 ~88 oak_wood
setblock ~173 ~161 ~89 jungle_leaves[persistent=true]
setblock ~173 ~161 ~90 oak_wood
setblock ~173 ~161 ~91 oak_leaves[persistent=true]
setblock ~173 ~161 ~93 oak_wood
setblock ~173 ~161 ~94 oak_wood
setblock ~173 ~161 ~95 oak_wood
setblock ~173 ~161 ~96 oak_wood
setblock ~173 ~161 ~97 oak_wood
setblock ~173 ~161 ~98 oak_leaves[persistent=true]
setblock ~173 ~161 ~99 oak_leaves[persistent=true]
setblock ~173 ~161 ~100 jungle_leaves[persistent=true]
setblock ~173 ~161 ~101 jungle_leaves[persistent=true]
setblock ~173 ~161 ~102 oak_leaves[persistent=true]
setblock ~173 ~162 ~84 oak_leaves[persistent=true]
setblock ~173 ~162 ~85 oak_leaves[persistent=true]
setblock ~173 ~162 ~86 oak_leaves[persistent=true]
setblock ~173 ~162 ~87 jungle_leaves[persistent=true]
setblock ~173 ~162 ~88 oak_wood
setblock ~173 ~162 ~89 oak_wood
setblock ~173 ~162 ~90 oak_wood
setblock ~173 ~162 ~91 oak_wood
setblock ~173 ~162 ~92 oak_leaves[persistent=true]
setblock ~173 ~162 ~93 oak_wood
setblock ~173 ~162 ~94 oak_wood
setblock ~173 ~162 ~96 oak_wood
setblock ~173 ~162 ~97 oak_leaves[persistent=true]
setblock ~173 ~162 ~98 oak_wood
setblock ~173 ~162 ~99 oak_leaves[persistent=true]
setblock ~173 ~162 ~100 oak_leaves[persistent=true]
setblock ~173 ~162 ~101 oak_leaves[persistent=true]
setblock ~173 ~162 ~102 oak_leaves[persistent=true]
setblock ~173 ~163 ~82 oak_leaves[persistent=true]
setblock ~173 ~163 ~83 oak_leaves[persistent=true]
setblock ~173 ~163 ~84 oak_leaves[persistent=true]
setblock ~173 ~163 ~85 jungle_leaves[persistent=true]
setblock ~173 ~163 ~86 jungle_leaves[persistent=true]
setblock ~173 ~163 ~87 oak_wood
setblock ~173 ~163 ~88 oak_wood
setblock ~173 ~163 ~89 oak_leaves[persistent=true]
setblock ~173 ~163 ~90 oak_leaves[persistent=true]
setblock ~173 ~163 ~91 oak_wood
setblock ~173 ~163 ~92 oak_log
setblock ~173 ~163 ~93 oak_wood
setblock ~173 ~163 ~94 oak_leaves[persistent=true]
setblock ~173 ~163 ~95 oak_wood
setblock ~173 ~163 ~96 oak_wood
setblock ~173 ~163 ~97 oak_wood
setblock ~173 ~163 ~98 oak_wood
setblock ~173 ~163 ~99 oak_wood
setblock ~173 ~163 ~100 oak_leaves[persistent=true]
setblock ~173 ~163 ~101 oak_leaves[persistent=true]
setblock ~173 ~163 ~102 oak_leaves[persistent=true]
setblock ~173 ~163 ~103 oak_leaves[persistent=true]
setblock ~173 ~164 ~82 oak_leaves[persistent=true]
setblock ~173 ~164 ~83 oak_leaves[persistent=true]
setblock ~173 ~164 ~84 jungle_leaves[persistent=true]
setblock ~173 ~164 ~85 oak_leaves[persistent=true]
setblock ~173 ~164 ~86 jungle_leaves[persistent=true]
setblock ~173 ~164 ~87 oak_leaves[persistent=true]
setblock ~173 ~164 ~88 oak_wood
setblock ~173 ~164 ~89 oak_leaves[persistent=true]
setblock ~173 ~164 ~90 oak_leaves[persistent=true]
setblock ~173 ~164 ~91 oak_wood
setblock ~173 ~164 ~92 oak_wood
setblock ~173 ~164 ~93 oak_wood
setblock ~173 ~164 ~94 oak_wood
setblock ~173 ~164 ~95 oak_wood
setblock ~173 ~164 ~96 oak_wood
setblock ~173 ~164 ~97 oak_wood
setblock ~173 ~164 ~98 oak_leaves[persistent=true]
setblock ~173 ~164 ~99 oak_leaves[persistent=true]
setblock ~173 ~164 ~100 oak_leaves[persistent=true]
setblock ~173 ~164 ~101 oak_leaves[persistent=true]
setblock ~173 ~164 ~102 oak_leaves[persistent=true]
setblock ~173 ~164 ~103 oak_leaves[persistent=true]
setblock ~173 ~164 ~104 oak_leaves[persistent=true]
setblock ~173 ~164 ~105 oak_leaves[persistent=true]
setblock ~173 ~165 ~81 oak_leaves[persistent=true]
setblock ~173 ~165 ~82 oak_leaves[persistent=true]
setblock ~173 ~165 ~83 oak_leaves[persistent=true]
setblock ~173 ~165 ~84 jungle_leaves[persistent=true]
setblock ~173 ~165 ~85 oak_leaves[persistent=true]
setblock ~173 ~165 ~86 oak_wood
setblock ~173 ~165 ~87 oak_leaves[persistent=true]
setblock ~173 ~165 ~88 oak_leaves[persistent=true]
setblock ~173 ~165 ~89 oak_wood
setblock ~173 ~165 ~90 oak_log
setblock ~173 ~165 ~91 oak_wood
setblock ~173 ~165 ~92 oak_wood
setblock ~173 ~165 ~93 oak_wood
setblock ~173 ~165 ~94 oak_wood
setblock ~173 ~165 ~95 oak_wood
setblock ~173 ~165 ~96 oak_wood
setblock ~173 ~165 ~97 oak_leaves[persistent=true]
setblock ~173 ~165 ~98 jungle_leaves[persistent=true]
setblock ~173 ~165 ~99 oak_wood
setblock ~173 ~165 ~101 oak_leaves[persistent=true]
setblock ~173 ~165 ~102 oak_leaves[persistent=true]
setblock ~173 ~165 ~103 oak_leaves[persistent=true]
setblock ~173 ~165 ~104 oak_leaves[persistent=true]
setblock ~173 ~165 ~105 jungle_leaves[persistent=true]
setblock ~173 ~166 ~81 oak_leaves[persistent=true]
setblock ~173 ~166 ~82 oak_leaves[persistent=true]
setblock ~173 ~166 ~83 oak_leaves[persistent=true]
setblock ~173 ~166 ~85 oak_leaves[persistent=true]
setblock ~173 ~166 ~86 oak_wood
setblock ~173 ~166 ~87 oak_wood
setblock ~173 ~166 ~88 oak_leaves[persistent=true]
setblock ~173 ~166 ~89 oak_wood
setblock ~173 ~166 ~90 oak_log
setblock ~173 ~166 ~91 oak_wood
setblock ~173 ~166 ~92 oak_wood
setblock ~173 ~166 ~93 oak_wood
setblock ~173 ~166 ~94 oak_wood
setblock ~173 ~166 ~95 oak_wood
setblock ~173 ~166 ~96 oak_wood
setblock ~173 ~166 ~97 oak_wood
setblock ~173 ~166 ~98 oak_wood
setblock ~173 ~166 ~99 oak_wood
setblock ~173 ~166 ~100 oak_leaves[persistent=true]
setblock ~173 ~166 ~103 oak_leaves[persistent=true]
setblock ~173 ~166 ~104 oak_leaves[persistent=true]
setblock ~173 ~166 ~105 jungle_leaves[persistent=true]
setblock ~173 ~167 ~81 jungle_leaves[persistent=true]
setblock ~173 ~167 ~83 oak_leaves[persistent=true]
setblock ~173 ~167 ~85 oak_leaves[persistent=true]
setblock ~173 ~167 ~86 oak_leaves[persistent=true]
setblock ~173 ~167 ~87 oak_leaves[persistent=true]
setblock ~173 ~167 ~88 oak_wood
setblock ~173 ~167 ~89 oak_leaves[persistent=true]
setblock ~173 ~167 ~90 oak_wood
setblock ~173 ~167 ~91 oak_leaves[persistent=true]
setblock ~173 ~167 ~92 oak_wood
setblock ~173 ~167 ~93 oak_leaves[persistent=true]
setblock ~173 ~167 ~94 oak_wood
setblock ~173 ~167 ~95 oak_wood
setblock ~173 ~167 ~96 oak_wood
setblock ~173 ~167 ~97 oak_log
setblock ~173 ~167 ~98 oak_wood
setblock ~173 ~167 ~99 oak_wood
setblock ~173 ~167 ~101 oak_leaves[persistent=true]
setblock ~173 ~167 ~102 oak_leaves[persistent=true]
setblock ~173 ~167 ~103 oak_leaves[persistent=true]
setblock ~173 ~167 ~104 oak_leaves[persistent=true]
setblock ~173 ~167 ~105 oak_leaves[persistent=true]
setblock ~173 ~168 ~82 jungle_leaves[persistent=true]
setblock ~173 ~168 ~84 jungle_leaves[persistent=true]
setblock ~173 ~168 ~85 jungle_leaves[persistent=true]
setblock ~173 ~168 ~86 oak_wood
setblock ~173 ~168 ~87 oak_wood
setblock ~173 ~168 ~88 oak_wood
setblock ~173 ~168 ~89 oak_wood
setblock ~173 ~168 ~91 oak_log
setblock ~173 ~168 ~92 oak_leaves[persistent=true]
setblock ~173 ~168 ~93 oak_wood
setblock ~173 ~168 ~94 oak_wood
setblock ~173 ~168 ~95 oak_wood
setblock ~173 ~168 ~96 oak_leaves[persistent=true]
setblock ~173 ~168 ~97 oak_log
setblock ~173 ~168 ~98 oak_wood
setblock ~173 ~168 ~99 oak_log
setblock ~173 ~168 ~100 oak_leaves[persistent=true]
setblock ~173 ~168 ~101 oak_leaves[persistent=true]
setblock ~173 ~168 ~102 jungle_leaves[persistent=true]
setblock ~173 ~168 ~103 oak_leaves[persistent=true]
setblock ~173 ~168 ~104 oak_leaves[persistent=true]
setblock ~173 ~168 ~105 oak_leaves[persistent=true]
setblock ~173 ~169 ~83 jungle_leaves[persistent=true]
setblock ~173 ~169 ~84 oak_leaves[persistent=true]
setblock ~173 ~169 ~85 oak_leaves[persistent=true]
setblock ~173 ~169 ~86 jungle_leaves[persistent=true]
setblock ~173 ~169 ~87 oak_leaves[persistent=true]
setblock ~173 ~169 ~88 oak_leaves[persistent=true]
setblock ~173 ~169 ~89 oak_leaves[persistent=true]
setblock ~173 ~169 ~90 oak_log
setblock ~173 ~169 ~91 oak_leaves[persistent=true]
setblock ~173 ~169 ~92 oak_log
setblock ~173 ~169 ~93 oak_leaves[persistent=true]
setblock ~173 ~169 ~94 oak_leaves[persistent=true]
setblock ~173 ~169 ~95 oak_log
setblock ~173 ~169 ~96 oak_log
setblock ~173 ~169 ~97 oak_log
setblock ~173 ~169 ~98 oak_leaves[persistent=true]
setblock ~173 ~169 ~99 oak_log
setblock ~173 ~169 ~100 oak_log
setblock ~173 ~169 ~101 oak_leaves[persistent=true]
setblock ~173 ~169 ~102 oak_leaves[persistent=true]
setblock ~173 ~169 ~103 oak_leaves[persistent=true]
setblock ~173 ~169 ~104 jungle_leaves[persistent=true]
setblock ~173 ~169 ~105 jungle_leaves[persistent=true]
setblock ~173 ~170 ~83 oak_leaves[persistent=true]
setblock ~173 ~170 ~84 oak_leaves[persistent=true]
setblock ~173 ~170 ~85 oak_leaves[persistent=true]
setblock ~173 ~170 ~86 oak_leaves[persistent=true]
setblock ~173 ~170 ~87 oak_leaves[persistent=true]
setblock ~173 ~170 ~88 oak_leaves[persistent=true]
setblock ~173 ~170 ~89 jungle_leaves[persistent=true]
setblock ~173 ~170 ~90 jungle_leaves[persistent=true]
setblock ~173 ~170 ~91 jungle_leaves[persistent=true]
setblock ~173 ~170 ~92 oak_leaves[persistent=true]
setblock ~173 ~170 ~93 jungle_leaves[persistent=true]
setblock ~173 ~170 ~94 oak_leaves[persistent=true]
setblock ~173 ~170 ~95 oak_leaves[persistent=true]
setblock ~173 ~170 ~96 jungle_leaves[persistent=true]
setblock ~173 ~170 ~97 oak_leaves[persistent=true]
setblock ~173 ~170 ~98 jungle_leaves[persistent=true]
setblock ~173 ~170 ~99 jungle_leaves[persistent=true]
setblock ~173 ~170 ~100 oak_leaves[persistent=true]
setblock ~173 ~170 ~102 oak_leaves[persistent=true]
setblock ~173 ~171 ~83 oak_leaves[persistent=true]
setblock ~173 ~171 ~84 jungle_leaves[persistent=true]
setblock ~173 ~171 ~87 oak_leaves[persistent=true]
setblock ~173 ~171 ~88 oak_leaves[persistent=true]
setblock ~173 ~171 ~89 jungle_leaves[persistent=true]
setblock ~173 ~171 ~90 oak_leaves[persistent=true]
setblock ~173 ~171 ~91 oak_leaves[persistent=true]
setblock ~173 ~171 ~93 oak_leaves[persistent=true]
setblock ~173 ~171 ~95 jungle_leaves[persistent=true]
setblock ~173 ~171 ~96 jungle_leaves[persistent=true]
setblock ~173 ~171 ~97 jungle_leaves[persistent=true]
setblock ~173 ~171 ~98 oak_leaves[persistent=true]
setblock ~173 ~171 ~99 oak_leaves[persistent=true]
setblock ~173 ~171 ~100 oak_leaves[persistent=true]
setblock ~173 ~171 ~101 oak_leaves[persistent=true]
setblock ~173 ~171 ~102 oak_leaves[persistent=true]
setblock ~174 ~121 ~118 dirt
setblock ~174 ~122 ~118 dirt
setblock ~174 ~123 ~118 dirt
setblock ~174 ~124 ~118 dirt
setblock ~174 ~125 ~118 grass_block
setblock ~174 ~126 ~118 short_grass
setblock ~174 ~147 ~92 jungle_leaves[persistent=true]
setblock ~174 ~147 ~93 oak_leaves[persistent=true]
setblock ~174 ~147 ~94 oak_leaves[persistent=true]
setblock ~174 ~147 ~95 oak_leaves[persistent=true]
setblock ~174 ~148 ~92 oak_leaves[persistent=true]
setblock ~174 ~148 ~93 oak_leaves[persistent=true]
setblock ~174 ~148 ~94 oak_leaves[persistent=true]
setblock ~174 ~148 ~95 oak_leaves[persistent=true]
setblock ~174 ~148 ~98 oak_leaves[persistent=true]
setblock ~174 ~148 ~99 oak_leaves[persistent=true]
setblock ~174 ~148 ~100 oak_leaves[persistent=true]
setblock ~174 ~149 ~92 oak_leaves[persistent=true]
setblock ~174 ~149 ~93 oak_leaves[persistent=true]
setblock ~174 ~149 ~94 oak_wood
setblock ~174 ~149 ~96 oak_leaves[persistent=true]
setblock ~174 ~149 ~97 jungle_leaves[persistent=true]
setblock ~174 ~149 ~98 oak_leaves[persistent=true]
setblock ~174 ~149 ~99 oak_leaves[persistent=true]
setblock ~174 ~149 ~100 oak_leaves[persistent=true]
setblock ~174 ~150 ~83 oak_leaves[persistent=true]
setblock ~174 ~150 ~84 oak_leaves[persistent=true]
setblock ~174 ~150 ~85 oak_leaves[persistent=true]
setblock ~174 ~150 ~86 jungle_leaves[persistent=true]
setblock ~174 ~150 ~92 oak_leaves[persistent=true]
setblock ~174 ~150 ~93 oak_leaves[persistent=true]
setblock ~174 ~150 ~94 jungle_leaves[persistent=true]
setblock ~174 ~150 ~95 oak_leaves[persistent=true]
setblock ~174 ~150 ~96 oak_leaves[persistent=true]
setblock ~174 ~150 ~97 oak_leaves[persistent=true]
setblock ~174 ~150 ~98 jungle_leaves[persistent=true]
setblock ~174 ~150 ~99 oak_leaves[persistent=true]
setblock ~174 ~150 ~100 oak_leaves[persistent=true]
setblock ~174 ~151 ~83 oak_leaves[persistent=true]
setblock ~174 ~151 ~85 oak_leaves[persistent=true]
setblock ~174 ~151 ~86 oak_leaves[persistent=true]
setblock ~174 ~151 ~92 oak_leaves[persistent=true]
setblock ~174 ~151 ~93 oak_leaves[persistent=true]
setblock ~174 ~151 ~94 oak_leaves[persistent=true]
setblock ~174 ~151 ~95 oak_leaves[persistent=true]
setblock ~174 ~151 ~96 oak_leaves[persistent=true]
setblock ~174 ~152 ~83 jungle_leaves[persistent=true]
setblock ~174 ~152 ~84 oak_leaves[persistent=true]
setblock ~174 ~152 ~85 oak_leaves[persistent=true]
setblock ~174 ~152 ~86 oak_leaves[persistent=true]
setblock ~174 ~152 ~91 oak_leaves[persistent=true]
setblock ~174 ~152 ~92 oak_leaves[persistent=true]
setblock ~174 ~152 ~93 oak_leaves[persistent=true]
setblock ~174 ~152 ~94 oak_leaves[persistent=true]
setblock ~174 ~152 ~95 oak_leaves[persistent=true]
setblock ~174 ~152 ~96 oak_leaves[persistent=true]
setblock ~174 ~152 ~97 oak_leaves[persistent=true]
setblock ~174 ~153 ~83 jungle_leaves[persistent=true]
setblock ~174 ~153 ~85 jungle_leaves[persistent=true]
setblock ~174 ~153 ~86 oak_leaves[persistent=true]
setblock ~174 ~153 ~88 oak_leaves[persistent=true]
setblock ~174 ~153 ~89 jungle_leaves[persistent=true]
setblock ~174 ~153 ~90 oak_leaves[persistent=true]
setblock ~174 ~153 ~91 oak_leaves[persistent=true]
setblock ~174 ~153 ~92 oak_leaves[persistent=true]
setblock ~174 ~153 ~94 jungle_leaves[persistent=true]
setblock ~174 ~153 ~95 oak_leaves[persistent=true]
setblock ~174 ~153 ~96 oak_leaves[persistent=true]
setblock ~174 ~153 ~97 oak_leaves[persistent=true]
setblock ~174 ~154 ~89 oak_leaves[persistent=true]
setblock ~174 ~154 ~90 jungle_leaves[persistent=true]
setblock ~174 ~154 ~91 oak_leaves[persistent=true]
setblock ~174 ~154 ~92 oak_leaves[persistent=true]
setblock ~174 ~154 ~93 oak_leaves[persistent=true]
setblock ~174 ~154 ~94 jungle_leaves[persistent=true]
setblock ~174 ~154 ~95 oak_leaves[persistent=true]
setblock ~174 ~154 ~96 oak_leaves[persistent=true]
setblock ~174 ~154 ~97 oak_leaves[persistent=true]
setblock ~174 ~155 ~87 jungle_leaves[persistent=true]
setblock ~174 ~155 ~88 oak_leaves[persistent=true]
setblock ~174 ~155 ~89 jungle_leaves[persistent=true]
setblock ~174 ~155 ~90 oak_leaves[persistent=true]
setblock ~174 ~155 ~91 jungle_leaves[persistent=true]
setblock ~174 ~155 ~92 oak_leaves[persistent=true]
setblock ~174 ~155 ~93 oak_leaves[persistent=true]
setblock ~174 ~155 ~94 jungle_leaves[persistent=true]
setblock ~174 ~155 ~95 oak_leaves[persistent=true]
setblock ~174 ~155 ~96 oak_leaves[persistent=true]
setblock ~174 ~155 ~97 oak_leaves[persistent=true]
setblock ~174 ~156 ~86 oak_leaves[persistent=true]
setblock ~174 ~156 ~87 oak_leaves[persistent=true]
setblock ~174 ~156 ~88 oak_leaves[persistent=true]
setblock ~174 ~156 ~89 oak_leaves[persistent=true]
setblock ~174 ~156 ~90 oak_leaves[persistent=true]
setblock ~174 ~156 ~91 oak_leaves[persistent=true]
setblock ~174 ~156 ~93 oak_leaves[persistent=true]
setblock ~174 ~156 ~94 oak_wood
setblock ~174 ~156 ~95 oak_leaves[persistent=true]
setblock ~174 ~156 ~97 jungle_leaves[persistent=true]
setblock ~174 ~157 ~85 oak_leaves[persistent=true]
setblock ~174 ~157 ~86 oak_leaves[persistent=true]
setblock ~174 ~157 ~87 jungle_leaves[persistent=true]
setblock ~174 ~157 ~88 jungle_leaves[persistent=true]
setblock ~174 ~157 ~90 oak_leaves[persistent=true]
setblock ~174 ~157 ~91 oak_leaves[persistent=true]
setblock ~174 ~157 ~92 oak_leaves[persistent=true]
setblock ~174 ~157 ~93 oak_leaves[persistent=true]
setblock ~174 ~157 ~94 oak_leaves[persistent=true]
setblock ~174 ~157 ~95 oak_leaves[persistent=true]
setblock ~174 ~157 ~97 oak_leaves[persistent=true]
setblock ~174 ~157 ~99 oak_leaves[persistent=true]
setblock ~174 ~158 ~85 oak_leaves[persistent=true]
setblock ~174 ~158 ~87 jungle_leaves[persistent=true]
setblock ~174 ~158 ~88 oak_wood
setblock ~174 ~158 ~89 oak_wood
setblock ~174 ~158 ~90 oak_wood
setblock ~174 ~158 ~91 jungle_leaves[persistent=true]
setblock ~174 ~158 ~92 oak_leaves[persistent=true]
setblock ~174 ~158 ~93 jungle_leaves[persistent=true]
setblock ~174 ~158 ~94 oak_leaves[persistent=true]
setblock ~174 ~158 ~95 oak_leaves[persistent=true]
setblock ~174 ~158 ~96 oak_leaves[persistent=true]
setblock ~174 ~158 ~97 oak_leaves[persistent=true]
setblock ~174 ~158 ~98 oak_leaves[persistent=true]
setblock ~174 ~158 ~99 oak_leaves[persistent=true]
setblock ~174 ~158 ~100 oak_leaves[persistent=true]
setblock ~174 ~158 ~101 oak_leaves[persistent=true]
setblock ~174 ~159 ~85 oak_leaves[persistent=true]
setblock ~174 ~159 ~86 oak_leaves[persistent=true]
setblock ~174 ~159 ~87 oak_leaves[persistent=true]
setblock ~174 ~159 ~88 oak_leaves[persistent=true]
setblock ~174 ~159 ~89 jungle_leaves[persistent=true]
setblock ~174 ~159 ~91 oak_leaves[persistent=true]
setblock ~174 ~159 ~92 oak_wood
setblock ~174 ~159 ~93 oak_leaves[persistent=true]
setblock ~174 ~159 ~95 oak_leaves[persistent=true]
setblock ~174 ~159 ~96 oak_leaves[persistent=true]
setblock ~174 ~159 ~97 oak_wood
setblock ~174 ~159 ~98 oak_wood
setblock ~174 ~159 ~99 jungle_leaves[persistent=true]
setblock ~174 ~159 ~100 oak_leaves[persistent=true]
setblock ~174 ~159 ~101 jungle_leaves[persistent=true]
setblock ~174 ~160 ~85 jungle_leaves[persistent=true]
setblock ~174 ~160 ~86 oak_leaves[persistent=true]
setblock ~174 ~160 ~87 oak_leaves[persistent=true]
setblock ~174 ~160 ~88 oak_leaves[persistent=true]
setblock ~174 ~160 ~89 oak_leaves[persistent=true]
setblock ~174 ~160 ~90 oak_leaves[persistent=true]
setblock ~174 ~160 ~91 oak_wood
setblock ~174 ~160 ~92 jungle_leaves[persistent=true]
setblock ~174 ~160 ~93 oak_wood
setblock ~174 ~160 ~94 oak_wood
setblock ~174 ~160 ~95 oak_leaves[persistent=true]
setblock ~174 ~160 ~96 oak_wood
setblock ~174 ~160 ~99 oak_leaves[persistent=true]
setblock ~174 ~160 ~100 oak_leaves[persistent=true]
setblock ~174 ~160 ~101 oak_leaves[persistent=true]
setblock ~174 ~161 ~85 oak_leaves[persistent=true]
setblock ~174 ~161 ~86 oak_leaves[persistent=true]
setblock ~174 ~161 ~88 jungle_leaves[persistent=true]
setblock ~174 ~161 ~89 oak_wood
setblock ~174 ~161 ~90 oak_wood
setblock ~174 ~161 ~91 oak_leaves[persistent=true]
setblock ~174 ~161 ~92 oak_wood
setblock ~174 ~161 ~93 oak_wood
setblock ~174 ~161 ~94 jungle_leaves[persistent=true]
setblock ~174 ~161 ~95 oak_wood
setblock ~174 ~161 ~96 oak_leaves[persistent=true]
setblock ~174 ~161 ~97 oak_wood
setblock ~174 ~161 ~98 jungle_leaves[persistent=true]
setblock ~174 ~161 ~99 oak_wood
setblock ~174 ~161 ~100 oak_leaves[persistent=true]
setblock ~174 ~161 ~101 jungle_leaves[persistent=true]
setblock ~174 ~162 ~84 oak_leaves[persistent=true]
setblock ~174 ~162 ~85 oak_leaves[persistent=true]
setblock ~174 ~162 ~86 jungle_leaves[persistent=true]
setblock ~174 ~162 ~87 jungle_leaves[persistent=true]
setblock ~174 ~162 ~88 oak_leaves[persistent=true]
setblock ~174 ~162 ~89 oak_wood
setblock ~174 ~162 ~90 oak_leaves[persistent=true]
setblock ~174 ~162 ~91 oak_wood
setblock ~174 ~162 ~92 oak_leaves[persistent=true]
setblock ~174 ~162 ~93 oak_leaves[persistent=true]
setblock ~174 ~162 ~94 oak_wood
setblock ~174 ~162 ~95 oak_wood
setblock ~174 ~162 ~96 oak_wood
setblock ~174 ~162 ~97 jungle_leaves[persistent=true]
setblock ~174 ~162 ~98 oak_leaves[persistent=true]
setblock ~174 ~162 ~99 oak_leaves[persistent=true]
setblock ~174 ~162 ~100 oak_leaves[persistent=true]
setblock ~174 ~162 ~101 oak_leaves[persistent=true]
setblock ~174 ~163 ~84 oak_leaves[persistent=true]
setblock ~174 ~163 ~85 oak_leaves[persistent=true]
setblock ~174 ~163 ~86 oak_leaves[persistent=true]
setblock ~174 ~163 ~87 oak_wood
setblock ~174 ~163 ~88 oak_leaves[persistent=true]
setblock ~174 ~163 ~89 oak_wood
setblock ~174 ~163 ~90 oak_leaves[persistent=true]
setblock ~174 ~163 ~91 oak_wood
setblock ~174 ~163 ~92 oak_wood
setblock ~174 ~163 ~93 oak_wood
setblock ~174 ~163 ~94 oak_wood
setblock ~174 ~163 ~95 oak_wood
setblock ~174 ~163 ~96 oak_log
setblock ~174 ~163 ~97 oak_wood
setblock ~174 ~163 ~98 oak_leaves[persistent=true]
setblock ~174 ~163 ~99 oak_leaves[persistent=true]
setblock ~174 ~163 ~100 oak_wood
setblock ~174 ~163 ~101 oak_leaves[persistent=true]
setblock ~174 ~164 ~84 oak_leaves[persistent=true]
setblock ~174 ~164 ~85 oak_leaves[persistent=true]
setblock ~174 ~164 ~86 oak_leaves[persistent=true]
setblock ~174 ~164 ~87 oak_wood
setblock ~174 ~164 ~88 oak_wood
setblock ~174 ~164 ~90 oak_leaves[persistent=true]
setblock ~174 ~164 ~91 oak_wood
setblock ~174 ~164 ~92 oak_leaves[persistent=true]
setblock ~174 ~164 ~93 oak_wood
setblock ~174 ~164 ~94 oak_leaves[persistent=true]
setblock ~174 ~164 ~95 oak_wood
setblock ~174 ~164 ~96 oak_log
setblock ~174 ~164 ~97 oak_wood
setblock ~174 ~164 ~98 oak_wood
setblock ~174 ~164 ~99 oak_wood
setblock ~174 ~164 ~100 oak_leaves[persistent=true]
setblock ~174 ~164 ~101 jungle_leaves[persistent=true]
setblock ~174 ~164 ~103 oak_leaves[persistent=true]
setblock ~174 ~164 ~104 oak_leaves[persistent=true]
setblock ~174 ~164 ~105 oak_leaves[persistent=true]
setblock ~174 ~165 ~83 oak_leaves[persistent=true]
setblock ~174 ~165 ~84 oak_leaves[persistent=true]
setblock ~174 ~165 ~85 oak_leaves[persistent=true]
setblock ~174 ~165 ~86 oak_wood
setblock ~174 ~165 ~87 oak_leaves[persistent=true]
setblock ~174 ~165 ~88 oak_leaves[persistent=true]
setblock ~174 ~165 ~89 jungle_leaves[persistent=true]
setblock ~174 ~165 ~90 oak_wood
setblock ~174 ~165 ~91 oak_wood
setblock ~174 ~165 ~92 oak_wood
setblock ~174 ~165 ~93 oak_wood
setblock ~174 ~165 ~94 oak_wood
setblock ~174 ~165 ~95 oak_wood
setblock ~174 ~165 ~96 oak_log
setblock ~174 ~165 ~97 oak_log
setblock ~174 ~165 ~98 oak_leaves[persistent=true]
setblock ~174 ~165 ~99 oak_leaves[persistent=true]
setblock ~174 ~165 ~100 oak_leaves[persistent=true]
setblock ~174 ~165 ~101 jungle_leaves[persistent=true]
setblock ~174 ~165 ~103 oak_leaves[persistent=true]
setblock ~174 ~165 ~104 oak_leaves[persistent=true]
setblock ~174 ~165 ~105 jungle_leaves[persistent=true]
setblock ~174 ~166 ~82 oak_leaves[persistent=true]
setblock ~174 ~166 ~83 oak_leaves[persistent=true]
setblock ~174 ~166 ~84 oak_leaves[persistent=true]
setblock ~174 ~166 ~85 oak_leaves[persistent=true]
setblock ~174 ~166 ~86 oak_wood
setblock ~174 ~166 ~87 oak_leaves[persistent=true]
setblock ~174 ~166 ~88 oak_wood
setblock ~174 ~166 ~89 oak_wood
setblock ~174 ~166 ~90 oak_wood
setblock ~174 ~166 ~91 oak_wood
setblock ~174 ~166 ~92 oak_wood
setblock ~174 ~166 ~93 oak_wood
setblock ~174 ~166 ~94 oak_wood
setblock ~174 ~166 ~95 oak_wood
setblock ~174 ~166 ~96 oak_wood
setblock ~174 ~166 ~97 oak_wood
setblock ~174 ~166 ~98 oak_leaves[persistent=true]
setblock ~174 ~166 ~99 oak_wood
setblock ~174 ~166 ~100 oak_wood
setblock ~174 ~166 ~101 oak_leaves[persistent=true]
setblock ~174 ~166 ~102 oak_leaves[persistent=true]
setblock ~174 ~166 ~103 oak_leaves[persistent=true]
setblock ~174 ~166 ~104 oak_leaves[persistent=true]
setblock ~174 ~166 ~105 oak_leaves[persistent=true]
setblock ~174 ~167 ~85 oak_leaves[persistent=true]
setblock ~174 ~167 ~86 oak_leaves[persistent=true]
setblock ~174 ~167 ~87 oak_wood
setblock ~174 ~167 ~88 oak_leaves[persistent=true]
setblock ~174 ~167 ~89 oak_wood
setblock ~174 ~167 ~90 oak_wood
setblock ~174 ~167 ~91 oak_wood
setblock ~174 ~167 ~92 oak_wood
setblock ~174 ~167 ~93 oak_wood
setblock ~174 ~167 ~94 oak_wood
setblock ~174 ~167 ~95 oak_leaves[persistent=true]
setblock ~174 ~167 ~96 oak_log
setblock ~174 ~167 ~97 oak_leaves[persistent=true]
setblock ~174 ~167 ~98 oak_wood
setblock ~174 ~167 ~99 oak_leaves[persistent=true]
setblock ~174 ~167 ~100 oak_leaves[persistent=true]
setblock ~174 ~167 ~101 oak_leaves[persistent=true]
setblock ~174 ~167 ~102 oak_leaves[persistent=true]
setblock ~174 ~167 ~103 jungle_leaves[persistent=true]
setblock ~174 ~167 ~104 oak_leaves[persistent=true]
setblock ~174 ~167 ~105 oak_leaves[persistent=true]
setblock ~174 ~168 ~82 oak_leaves[persistent=true]
setblock ~174 ~168 ~83 oak_leaves[persistent=true]
setblock ~174 ~168 ~84 oak_leaves[persistent=true]
setblock ~174 ~168 ~85 oak_leaves[persistent=true]
setblock ~174 ~168 ~86 oak_leaves[persistent=true]
setblock ~174 ~168 ~90 oak_log
setblock ~174 ~168 ~91 oak_wood
setblock ~174 ~168 ~92 oak_wood
setblock ~174 ~168 ~93 oak_wood
setblock ~174 ~168 ~95 oak_log
setblock ~174 ~168 ~96 oak_wood
setblock ~174 ~168 ~97 oak_wood
setblock ~174 ~168 ~98 oak_leaves[persistent=true]
setblock ~174 ~168 ~99 oak_log
setblock ~174 ~168 ~100 jungle_leaves[persistent=true]
setblock ~174 ~168 ~101 oak_leaves[persistent=true]
setblock ~174 ~168 ~102 oak_leaves[persistent=true]
setblock ~174 ~168 ~103 oak_leaves[persistent=true]
setblock ~174 ~168 ~104 oak_leaves[persistent=true]
setblock ~174 ~168 ~105 oak_leaves[persistent=true]
setblock ~174 ~169 ~82 oak_leaves[persistent=true]
setblock ~174 ~169 ~83 oak_leaves[persistent=true]
setblock ~174 ~169 ~84 jungle_leaves[persistent=true]
setblock ~174 ~169 ~85 jungle_leaves[persistent=true]
setblock ~174 ~169 ~86 oak_leaves[persistent=true]
setblock ~174 ~169 ~87 oak_leaves[persistent=true]
setblock ~174 ~169 ~88 oak_log
setblock ~174 ~169 ~89 oak_leaves[persistent=true]
setblock ~174 ~169 ~90 oak_log
setblock ~174 ~169 ~91 jungle_leaves[persistent=true]
setblock ~174 ~169 ~92 oak_log
setblock ~174 ~169 ~93 oak_log
setblock ~174 ~169 ~94 oak_log
setblock ~174 ~169 ~95 oak_wood
setblock ~174 ~169 ~96 oak_log
setblock ~174 ~169 ~97 oak_log
setblock ~174 ~169 ~99 oak_leaves[persistent=true]
setblock ~174 ~169 ~100 oak_leaves[persistent=true]
setblock ~174 ~169 ~101 jungle_leaves[persistent=true]
setblock ~174 ~169 ~102 oak_leaves[persistent=true]
setblock ~174 ~169 ~103 oak_leaves[persistent=true]
setblock ~174 ~169 ~104 jungle_leaves[persistent=true]
setblock ~174 ~169 ~105 oak_leaves[persistent=true]
setblock ~174 ~170 ~86 oak_leaves[persistent=true]
setblock ~174 ~170 ~87 oak_leaves[persistent=true]
setblock ~174 ~170 ~88 oak_leaves[persistent=true]
setblock ~174 ~170 ~89 oak_leaves[persistent=true]
setblock ~174 ~170 ~90 oak_leaves[persistent=true]
setblock ~174 ~170 ~91 oak_leaves[persistent=true]
setblock ~174 ~170 ~92 oak_leaves[persistent=true]
setblock ~174 ~170 ~93 oak_leaves[persistent=true]
setblock ~174 ~170 ~94 oak_leaves[persistent=true]
setblock ~174 ~170 ~95 oak_leaves[persistent=true]
setblock ~174 ~170 ~96 oak_leaves[persistent=true]
setblock ~174 ~170 ~97 oak_leaves[persistent=true]
setblock ~174 ~170 ~98 oak_leaves[persistent=true]
setblock ~174 ~170 ~99 jungle_leaves[persistent=true]
setblock ~174 ~170 ~100 oak_leaves[persistent=true]
setblock ~174 ~170 ~102 oak_leaves[persistent=true]
setblock ~174 ~171 ~87 oak_leaves[persistent=true]
setblock ~174 ~171 ~88 oak_leaves[persistent=true]
setblock ~174 ~171 ~89 oak_leaves[persistent=true]
setblock ~174 ~171 ~90 oak_leaves[persistent=true]
setblock ~174 ~171 ~91 oak_leaves[persistent=true]
setblock ~174 ~171 ~92 oak_leaves[persistent=true]
setblock ~174 ~171 ~93 oak_leaves[persistent=true]
setblock ~174 ~171 ~94 oak_leaves[persistent=true]
setblock ~174 ~171 ~95 oak_leaves[persistent=true]
setblock ~174 ~171 ~96 jungle_leaves[persistent=true]
setblock ~174 ~171 ~97 oak_leaves[persistent=true]
setblock ~174 ~171 ~98 jungle_leaves[persistent=true]
setblock ~174 ~171 ~99 jungle_leaves[persistent=true]
setblock ~174 ~171 ~100 oak_leaves[persistent=true]
setblock ~174 ~171 ~101 oak_leaves[persistent=true]
setblock ~174 ~171 ~102 oak_leaves[persistent=true]
setblock ~175 ~147 ~92 jungle_leaves[persistent=true]
setblock ~175 ~147 ~93 oak_leaves[persistent=true]
setblock ~175 ~147 ~94 oak_leaves[persistent=true]
setblock ~175 ~147 ~95 oak_leaves[persistent=true]
setblock ~175 ~148 ~92 jungle_leaves[persistent=true]
setblock ~175 ~148 ~93 jungle_leaves[persistent=true]
setblock ~175 ~148 ~94 oak_leaves[persistent=true]
setblock ~175 ~148 ~95 oak_leaves[persistent=true]
setblock ~175 ~149 ~92 oak_leaves[persistent=true]
setblock ~175 ~149 ~93 jungle_leaves[persistent=true]
setblock ~175 ~149 ~94 oak_leaves[persistent=true]
setblock ~175 ~149 ~95 oak_leaves[persistent=true]
setblock ~175 ~150 ~92 oak_leaves[persistent=true]
setblock ~175 ~150 ~93 oak_leaves[persistent=true]
setblock ~175 ~150 ~94 oak_leaves[persistent=true]
setblock ~175 ~150 ~95 jungle_leaves[persistent=true]
setblock ~175 ~152 ~92 oak_leaves[persistent=true]
setblock ~175 ~152 ~93 oak_leaves[persistent=true]
setblock ~175 ~152 ~94 jungle_leaves[persistent=true]
setblock ~175 ~152 ~95 oak_leaves[persistent=true]
setblock ~175 ~153 ~93 oak_leaves[persistent=true]
setblock ~175 ~153 ~94 oak_leaves[persistent=true]
setblock ~175 ~153 ~95 jungle_leaves[persistent=true]
setblock ~175 ~153 ~96 oak_leaves[persistent=true]
setblock ~175 ~154 ~90 oak_leaves[persistent=true]
setblock ~175 ~154 ~91 oak_leaves[persistent=true]
setblock ~175 ~154 ~92 oak_leaves[persistent=true]
setblock ~175 ~154 ~93 oak_leaves[persistent=true]
setblock ~175 ~154 ~94 oak_leaves[persistent=true]
setblock ~175 ~154 ~95 oak_leaves[persistent=true]
setblock ~175 ~154 ~96 jungle_leaves[persistent=true]
setblock ~175 ~155 ~90 oak_leaves[persistent=true]
setblock ~175 ~155 ~91 oak_leaves[persistent=true]
setblock ~175 ~155 ~92 oak_leaves[persistent=true]
setblock ~175 ~155 ~93 oak_leaves[persistent=true]
setblock ~175 ~155 ~94 jungle_leaves[persistent=true]
setblock ~175 ~155 ~95 oak_leaves[persistent=true]
setblock ~175 ~155 ~96 jungle_leaves[persistent=true]
setblock ~175 ~156 ~86 jungle_leaves[persistent=true]
setblock ~175 ~156 ~87 oak_leaves[persistent=true]
setblock ~175 ~156 ~89 oak_leaves[persistent=true]
setblock ~175 ~156 ~90 oak_leaves[persistent=true]
setblock ~175 ~156 ~91 oak_leaves[persistent=true]
setblock ~175 ~156 ~92 oak_leaves[persistent=true]
setblock ~175 ~156 ~94 oak_leaves[persistent=true]
setblock ~175 ~156 ~95 oak_leaves[persistent=true]
setblock ~175 ~156 ~96 oak_leaves[persistent=true]
setblock ~175 ~157 ~85 oak_leaves[persistent=true]
setblock ~175 ~157 ~86 jungle_leaves[persistent=true]
setblock ~175 ~157 ~87 oak_leaves[persistent=true]
setblock ~175 ~157 ~88 oak_leaves[persistent=true]
setblock ~175 ~157 ~89 oak_leaves[persistent=true]
setblock ~175 ~157 ~91 oak_leaves[persistent=true]
setblock ~175 ~157 ~92 oak_leaves[persistent=true]
setblock ~175 ~157 ~93 oak_leaves[persistent=true]
setblock ~175 ~157 ~94 jungle_leaves[persistent=true]
setblock ~175 ~157 ~95 oak_leaves[persistent=true]
setblock ~175 ~157 ~96 oak_leaves[persistent=true]
setblock ~175 ~157 ~97 jungle_leaves[persistent=true]
setblock ~175 ~157 ~98 oak_leaves[persistent=true]
setblock ~175 ~157 ~99 jungle_leaves[persistent=true]
setblock ~175 ~158 ~84 oak_leaves[persistent=true]
setblock ~175 ~158 ~85 oak_leaves[persistent=true]
setblock ~175 ~158 ~86 oak_leaves[persistent=true]
setblock ~175 ~158 ~87 oak_wood
setblock ~175 ~158 ~89 oak_leaves[persistent=true]
setblock ~175 ~158 ~90 oak_leaves[persistent=true]
setblock ~175 ~158 ~91 oak_leaves[persistent=true]
setblock ~175 ~158 ~92 oak_leaves[persistent=true]
setblock ~175 ~158 ~93 oak_leaves[persistent=true]
setblock ~175 ~158 ~97 oak_leaves[persistent=true]
setblock ~175 ~158 ~98 jungle_leaves[persistent=true]
setblock ~175 ~158 ~99 oak_leaves[persistent=true]
setblock ~175 ~158 ~100 oak_leaves[persistent=true]
setblock ~175 ~158 ~101 jungle_leaves[persistent=true]
setblock ~175 ~159 ~84 oak_leaves[persistent=true]
setblock ~175 ~159 ~85 oak_leaves[persistent=true]
setblock ~175 ~159 ~86 oak_leaves[persistent=true]
setblock ~175 ~159 ~87 oak_leaves[persistent=true]
setblock ~175 ~159 ~89 oak_leaves[persistent=true]
setblock ~175 ~159 ~90 oak_leaves[persistent=true]
setblock ~175 ~159 ~91 oak_wood
setblock ~175 ~159 ~92 oak_leaves[persistent=true]
setblock ~175 ~159 ~93 jungle_leaves[persistent=true]
setblock ~175 ~159 ~94 oak_leaves[persistent=true]
setblock ~175 ~159 ~95 oak_leaves[persistent=true]
setblock ~175 ~159 ~96 oak_leaves[persistent=true]
setblock ~175 ~159 ~97 oak_leaves[persistent=true]
setblock ~175 ~159 ~98 oak_wood
setblock ~175 ~159 ~99 jungle_leaves[persistent=true]
setblock ~175 ~159 ~100 oak_leaves[persistent=true]
setblock ~175 ~159 ~101 oak_leaves[persistent=true]
setblock ~175 ~160 ~85 oak_leaves[persistent=true]
setblock ~175 ~160 ~87 jungle_leaves[persistent=true]
setblock ~175 ~160 ~88 jungle_leaves[persistent=true]
setblock ~175 ~160 ~89 oak_leaves[persistent=true]
setblock ~175 ~160 ~90 oak_leaves[persistent=true]
setblock ~175 ~160 ~91 oak_leaves[persistent=true]
setblock ~175 ~160 ~93 oak_wood
setblock ~175 ~160 ~94 oak_leaves[persistent=true]
setblock ~175 ~160 ~95 oak_leaves[persistent=true]
setblock ~175 ~160 ~96 oak_leaves[persistent=true]
setblock ~175 ~160 ~97 oak_leaves[persistent=true]
setblock ~175 ~160 ~98 oak_leaves[persistent=true]
setblock ~175 ~160 ~99 oak_leaves[persistent=true]
setblock ~175 ~160 ~100 oak_leaves[persistent=true]
setblock ~175 ~160 ~101 jungle_leaves[persistent=true]
setblock ~175 ~161 ~85 jungle_leaves[persistent=true]
setblock ~175 ~161 ~87 oak_leaves[persistent=true]
setblock ~175 ~161 ~88 oak_wood
setblock ~175 ~161 ~89 jungle_leaves[persistent=true]
setblock ~175 ~161 ~90 jungle_leaves[persistent=true]
setblock ~175 ~161 ~91 oak_leaves[persistent=true]
setblock ~175 ~161 ~92 jungle_leaves[persistent=true]
setblock ~175 ~161 ~93 oak_wood
setblock ~175 ~161 ~94 oak_wood
setblock ~175 ~161 ~95 jungle_leaves[persistent=true]
setblock ~175 ~161 ~96 oak_leaves[persistent=true]
setblock ~175 ~161 ~97 oak_wood
setblock ~175 ~161 ~98 oak_leaves[persistent=true]
setblock ~175 ~161 ~99 jungle_leaves[persistent=true]
setblock ~175 ~161 ~100 oak_leaves[persistent=true]
setblock ~175 ~161 ~101 oak_leaves[persistent=true]
setblock ~175 ~162 ~85 oak_leaves[persistent=true]
setblock ~175 ~162 ~86 oak_leaves[persistent=true]
setblock ~175 ~162 ~87 oak_leaves[persistent=true]
setblock ~175 ~162 ~88 oak_leaves[persistent=true]
setblock ~175 ~162 ~89 oak_wood
setblock ~175 ~162 ~90 oak_wood
setblock ~175 ~162 ~92 oak_leaves[persistent=true]
setblock ~175 ~162 ~93 oak_leaves[persistent=true]
setblock ~175 ~162 ~94 oak_leaves[persistent=true]
setblock ~175 ~162 ~95 oak_wood
setblock ~175 ~162 ~97 oak_leaves[persistent=true]
setblock ~175 ~162 ~98 oak_leaves[persistent=true]
setblock ~175 ~162 ~100 oak_leaves[persistent=true]
setblock ~175 ~162 ~101 oak_leaves[persistent=true]
setblock ~175 ~163 ~84 oak_leaves[persistent=true]
setblock ~175 ~163 ~85 oak_leaves[persistent=true]
setblock ~175 ~163 ~86 oak_wood
setblock ~175 ~163 ~87 oak_leaves[persistent=true]
setblock ~175 ~163 ~88 oak_wood
setblock ~175 ~163 ~89 jungle_leaves[persistent=true]
setblock ~175 ~163 ~90 oak_wood
setblock ~175 ~163 ~91 oak_wood
setblock ~175 ~163 ~92 oak_wood
setblock ~175 ~163 ~93 oak_leaves[persistent=true]
setblock ~175 ~163 ~94 oak_wood
setblock ~175 ~163 ~95 oak_wood
setblock ~175 ~163 ~96 jungle_leaves[persistent=true]
setblock ~175 ~163 ~97 oak_leaves[persistent=true]
setblock ~175 ~163 ~98 oak_leaves[persistent=true]
setblock ~175 ~163 ~99 oak_leaves[persistent=true]
setblock ~175 ~163 ~101 jungle_leaves[persistent=true]
setblock ~175 ~164 ~84 oak_leaves[persistent=true]
setblock ~175 ~164 ~85 jungle_leaves[persistent=true]
setblock ~175 ~164 ~86 oak_leaves[persistent=true]
setblock ~175 ~164 ~87 oak_leaves[persistent=true]
setblock ~175 ~164 ~88 oak_leaves[persistent=true]
setblock ~175 ~164 ~90 oak_wood
setblock ~175 ~164 ~91 oak_wood
setblock ~175 ~164 ~92 oak_leaves[persistent=true]
setblock ~175 ~164 ~93 oak_wood
setblock ~175 ~164 ~94 oak_wood
setblock ~175 ~164 ~95 jungle_leaves[persistent=true]
setblock ~175 ~164 ~96 oak_wood
setblock ~175 ~164 ~97 oak_wood
setblock ~175 ~164 ~98 oak_leaves[persistent=true]
setblock ~175 ~164 ~99 oak_leaves[persistent=true]
setblock ~175 ~164 ~100 oak_leaves[persistent=true]
setblock ~175 ~164 ~101 oak_leaves[persistent=true]
setblock ~175 ~165 ~84 oak_leaves[persistent=true]
setblock ~175 ~165 ~85 oak_leaves[persistent=true]
setblock ~175 ~165 ~86 oak_leaves[persistent=true]
setblock ~175 ~165 ~87 oak_leaves[persistent=true]
setblock ~175 ~165 ~88 oak_leaves[persistent=true]
setblock ~175 ~165 ~89 oak_leaves[persistent=true]
setblock ~175 ~165 ~90 oak_wood
setblock ~175 ~165 ~91 oak_wood
setblock ~175 ~165 ~92 oak_wood
setblock ~175 ~165 ~93 oak_wood
setblock ~175 ~165 ~94 oak_leaves[persistent=true]
setblock ~175 ~165 ~95 oak_wood
setblock ~175 ~165 ~96 oak_leaves[persistent=true]
setblock ~175 ~165 ~97 oak_leaves[persistent=true]
setblock ~175 ~165 ~98 oak_leaves[persistent=true]
setblock ~175 ~165 ~99 oak_leaves[persistent=true]
setblock ~175 ~165 ~101 oak_leaves[persistent=true]
setblock ~175 ~166 ~85 oak_leaves[persistent=true]
setblock ~175 ~166 ~86 oak_leaves[persistent=true]
setblock ~175 ~166 ~87 oak_leaves[persistent=true]
setblock ~175 ~166 ~88 oak_leaves[persistent=true]
setblock ~175 ~166 ~89 oak_leaves[persistent=true]
setblock ~175 ~166 ~90 oak_wood
setblock ~175 ~166 ~91 oak_wood
setblock ~175 ~166 ~92 oak_leaves[persistent=true]
setblock ~175 ~166 ~93 oak_wood
setblock ~175 ~166 ~94 oak_wood
setblock ~175 ~166 ~95 jungle_leaves[persistent=true]
setblock ~175 ~166 ~96 oak_wood
setblock ~175 ~166 ~97 oak_wood
setblock ~175 ~166 ~98 jungle_leaves[persistent=true]
setblock ~175 ~166 ~99 oak_wood
setblock ~175 ~166 ~100 oak_leaves[persistent=true]
setblock ~175 ~166 ~101 oak_leaves[persistent=true]
setblock ~175 ~166 ~102 oak_leaves[persistent=true]
setblock ~175 ~167 ~84 oak_leaves[persistent=true]
setblock ~175 ~167 ~85 jungle_leaves[persistent=true]
setblock ~175 ~167 ~86 oak_leaves[persistent=true]
setblock ~175 ~167 ~87 oak_leaves[persistent=true]
setblock ~175 ~167 ~88 oak_leaves[persistent=true]
setblock ~175 ~167 ~89 oak_leaves[persistent=true]
setblock ~175 ~167 ~90 oak_wood
setblock ~175 ~167 ~91 oak_wood
setblock ~175 ~167 ~92 oak_wood
setblock ~175 ~167 ~93 oak_leaves[persistent=true]
setblock ~175 ~167 ~94 oak_wood
setblock ~175 ~167 ~95 oak_wood
setblock ~175 ~167 ~96 oak_wood
setblock ~175 ~167 ~97 oak_leaves[persistent=true]
setblock ~175 ~167 ~98 jungle_leaves[persistent=true]
setblock ~175 ~167 ~99 oak_leaves[persistent=true]
setblock ~175 ~167 ~100 oak_wood
setblock ~175 ~167 ~101 jungle_leaves[persistent=true]
setblock ~175 ~167 ~102 oak_leaves[persistent=true]
setblock ~175 ~168 ~84 oak_leaves[persistent=true]
setblock ~175 ~168 ~85 jungle_leaves[persistent=true]
setblock ~175 ~168 ~86 oak_leaves[persistent=true]
setblock ~175 ~168 ~87 oak_leaves[persistent=true]
setblock ~175 ~168 ~88 oak_leaves[persistent=true]
setblock ~175 ~168 ~89 oak_leaves[persistent=true]
setblock ~175 ~168 ~90 oak_leaves[persistent=true]
setblock ~175 ~168 ~91 oak_leaves[persistent=true]
setblock ~175 ~168 ~92 jungle_leaves[persistent=true]
setblock ~175 ~168 ~93 oak_leaves[persistent=true]
setblock ~175 ~168 ~95 jungle_leaves[persistent=true]
setblock ~175 ~168 ~96 oak_leaves[persistent=true]
setblock ~175 ~168 ~97 oak_leaves[persistent=true]
setblock ~175 ~168 ~98 jungle_leaves[persistent=true]
setblock ~175 ~168 ~99 oak_leaves[persistent=true]
setblock ~175 ~168 ~100 oak_leaves[persistent=true]
setblock ~175 ~168 ~101 oak_leaves[persistent=true]
setblock ~175 ~168 ~102 oak_leaves[persistent=true]
setblock ~175 ~169 ~85 jungle_leaves[persistent=true]
setblock ~175 ~169 ~86 jungle_leaves[persistent=true]
setblock ~175 ~169 ~87 oak_leaves[persistent=true]
setblock ~175 ~169 ~88 oak_leaves[persistent=true]
setblock ~175 ~169 ~89 oak_leaves[persistent=true]
setblock ~175 ~169 ~90 oak_leaves[persistent=true]
setblock ~175 ~169 ~91 jungle_leaves[persistent=true]
setblock ~175 ~169 ~92 oak_log
setblock ~175 ~169 ~93 jungle_leaves[persistent=true]
setblock ~175 ~169 ~94 oak_log
setblock ~175 ~169 ~95 oak_leaves[persistent=true]
setblock ~175 ~169 ~96 oak_leaves[persistent=true]
setblock ~175 ~169 ~97 oak_leaves[persistent=true]
setblock ~175 ~169 ~98 oak_leaves[persistent=true]
setblock ~175 ~169 ~99 oak_log
setblock ~175 ~169 ~100 oak_leaves[persistent=true]
setblock ~175 ~169 ~101 oak_leaves[persistent=true]
setblock ~175 ~169 ~102 oak_leaves[persistent=true]
setblock ~175 ~170 ~87 oak_leaves[persistent=true]
setblock ~175 ~170 ~90 oak_leaves[persistent=true]
setblock ~175 ~170 ~93 oak_leaves[persistent=true]
setblock ~175 ~170 ~94 oak_leaves[persistent=true]
setblock ~175 ~170 ~95 oak_wood
setblock ~175 ~170 ~96 oak_leaves[persistent=true]
setblock ~175 ~170 ~98 oak_leaves[persistent=true]
setblock ~175 ~170 ~99 jungle_leaves[persistent=true]
setblock ~175 ~170 ~100 jungle_leaves[persistent=true]
setblock ~175 ~170 ~101 oak_leaves[persistent=true]
setblock ~175 ~171 ~87 oak_leaves[persistent=true]
setblock ~175 ~171 ~88 jungle_leaves[persistent=true]
setblock ~175 ~171 ~89 oak_leaves[persistent=true]
setblock ~175 ~171 ~90 oak_leaves[persistent=true]
setblock ~175 ~171 ~91 oak_leaves[persistent=true]
setblock ~175 ~171 ~92 oak_leaves[persistent=true]
setblock ~175 ~171 ~93 oak_leaves[persistent=true]
setblock ~175 ~171 ~94 oak_leaves[persistent=true]
setblock ~175 ~171 ~95 oak_leaves[persistent=true]
setblock ~175 ~171 ~97 oak_leaves[persistent=true]
setblock ~175 ~171 ~98 jungle_leaves[persistent=true]
setblock ~175 ~171 ~99 oak_leaves[persistent=true]
setblock ~175 ~171 ~100 oak_leaves[persistent=true]
setblock ~175 ~171 ~101 oak_leaves[persistent=true]
setblock ~176 ~148 ~93 oak_leaves[persistent=true]
setblock ~176 ~148 ~94 oak_leaves[persistent=true]
setblock ~176 ~148 ~95 oak_leaves[persistent=true]
setblock ~176 ~149 ~93 jungle_leaves[persistent=true]
setblock ~176 ~149 ~94 oak_leaves[persistent=true]
setblock ~176 ~150 ~93 jungle_leaves[persistent=true]
setblock ~176 ~150 ~94 oak_leaves[persistent=true]
setblock ~176 ~150 ~95 oak_leaves[persistent=true]
setblock ~176 ~156 ~85 oak_leaves[persistent=true]
setblock ~176 ~157 ~85 oak_leaves[persistent=true]
setblock ~176 ~157 ~86 oak_leaves[persistent=true]
setblock ~176 ~157 ~89 oak_leaves[persistent=true]
setblock ~176 ~157 ~90 oak_leaves[persistent=true]
setblock ~176 ~157 ~91 oak_leaves[persistent=true]
setblock ~176 ~157 ~92 jungle_leaves[persistent=true]
setblock ~176 ~157 ~96 oak_leaves[persistent=true]
setblock ~176 ~157 ~97 oak_leaves[persistent=true]
setblock ~176 ~157 ~98 oak_leaves[persistent=true]
setblock ~176 ~157 ~99 oak_leaves[persistent=true]
setblock ~176 ~158 ~84 oak_leaves[persistent=true]
setblock ~176 ~158 ~85 oak_leaves[persistent=true]
setblock ~176 ~158 ~86 oak_leaves[persistent=true]
setblock ~176 ~158 ~87 oak_leaves[persistent=true]
setblock ~176 ~158 ~88 oak_leaves[persistent=true]
setblock ~176 ~158 ~89 jungle_leaves[persistent=true]
setblock ~176 ~158 ~90 oak_leaves[persistent=true]
setblock ~176 ~158 ~91 jungle_leaves[persistent=true]
setblock ~176 ~158 ~92 oak_leaves[persistent=true]
setblock ~176 ~158 ~93 oak_leaves[persistent=true]
setblock ~176 ~158 ~96 oak_leaves[persistent=true]
setblock ~176 ~158 ~97 oak_leaves[persistent=true]
setblock ~176 ~158 ~98 oak_leaves[persistent=true]
setblock ~176 ~158 ~99 oak_leaves[persistent=true]
setblock ~176 ~158 ~100 oak_leaves[persistent=true]
setblock ~176 ~159 ~84 oak_leaves[persistent=true]
setblock ~176 ~159 ~85 oak_leaves[persistent=true]
setblock ~176 ~159 ~86 jungle_leaves[persistent=true]
setblock ~176 ~159 ~87 oak_leaves[persistent=true]
setblock ~176 ~159 ~88 jungle_leaves[persistent=true]
setblock ~176 ~159 ~89 oak_leaves[persistent=true]
setblock ~176 ~159 ~90 oak_leaves[persistent=true]
setblock ~176 ~159 ~92 jungle_leaves[persistent=true]
setblock ~176 ~159 ~93 oak_leaves[persistent=true]
setblock ~176 ~159 ~94 oak_leaves[persistent=true]
setblock ~176 ~159 ~95 oak_leaves[persistent=true]
setblock ~176 ~159 ~96 oak_leaves[persistent=true]
setblock ~176 ~159 ~97 oak_leaves[persistent=true]
setblock ~176 ~159 ~98 oak_leaves[persistent=true]
setblock ~176 ~159 ~99 oak_leaves[persistent=true]
setblock ~176 ~159 ~100 oak_leaves[persistent=true]
setblock ~176 ~159 ~101 oak_leaves[persistent=true]
setblock ~176 ~160 ~84 oak_leaves[persistent=true]
setblock ~176 ~160 ~85 oak_leaves[persistent=true]
setblock ~176 ~160 ~86 jungle_leaves[persistent=true]
setblock ~176 ~160 ~87 oak_wood
setblock ~176 ~160 ~88 oak_leaves[persistent=true]
setblock ~176 ~160 ~90 oak_leaves[persistent=true]
setblock ~176 ~160 ~91 oak_leaves[persistent=true]
setblock ~176 ~160 ~92 oak_leaves[persistent=true]
setblock ~176 ~160 ~93 oak_leaves[persistent=true]
setblock ~176 ~160 ~95 oak_leaves[persistent=true]
setblock ~176 ~160 ~96 oak_leaves[persistent=true]
setblock ~176 ~160 ~97 jungle_leaves[persistent=true]
setblock ~176 ~160 ~98 oak_leaves[persistent=true]
setblock ~176 ~160 ~99 jungle_leaves[persistent=true]
setblock ~176 ~160 ~100 oak_leaves[persistent=true]
setblock ~176 ~161 ~84 oak_leaves[persistent=true]
setblock ~176 ~161 ~85 oak_leaves[persistent=true]
setblock ~176 ~161 ~86 oak_leaves[persistent=true]
setblock ~176 ~161 ~87 oak_leaves[persistent=true]
setblock ~176 ~161 ~88 oak_leaves[persistent=true]
setblock ~176 ~161 ~89 oak_leaves[persistent=true]
setblock ~176 ~161 ~90 oak_leaves[persistent=true]
setblock ~176 ~161 ~91 oak_leaves[persistent=true]
setblock ~176 ~161 ~92 oak_wood
setblock ~176 ~161 ~93 oak_leaves[persistent=true]
setblock ~176 ~161 ~94 jungle_leaves[persistent=true]
setblock ~176 ~161 ~95 oak_leaves[persistent=true]
setblock ~176 ~161 ~97 jungle_leaves[persistent=true]
setblock ~176 ~161 ~98 jungle_leaves[persistent=true]
setblock ~176 ~161 ~99 oak_leaves[persistent=true]
setblock ~176 ~161 ~101 jungle_leaves[persistent=true]
setblock ~176 ~162 ~84 oak_leaves[persistent=true]
setblock ~176 ~162 ~85 jungle_leaves[persistent=true]
setblock ~176 ~162 ~86 oak_leaves[persistent=true]
setblock ~176 ~162 ~87 oak_leaves[persistent=true]
setblock ~176 ~162 ~88 oak_leaves[persistent=true]
setblock ~176 ~162 ~89 oak_leaves[persistent=true]
setblock ~176 ~162 ~91 jungle_leaves[persistent=true]
setblock ~176 ~162 ~92 oak_leaves[persistent=true]
setblock ~176 ~162 ~93 jungle_leaves[persistent=true]
setblock ~176 ~162 ~94 oak_leaves[persistent=true]
setblock ~176 ~162 ~95 oak_leaves[persistent=true]
setblock ~176 ~162 ~96 oak_wood
setblock ~176 ~162 ~97 jungle_leaves[persistent=true]
setblock ~176 ~162 ~98 oak_leaves[persistent=true]
setblock ~176 ~162 ~101 oak_leaves[persistent=true]
setblock ~176 ~163 ~84 jungle_leaves[persistent=true]
setblock ~176 ~163 ~85 oak_leaves[persistent=true]
setblock ~176 ~163 ~86 oak_leaves[persistent=true]
setblock ~176 ~163 ~87 jungle_leaves[persistent=true]
setblock ~176 ~163 ~88 oak_leaves[persistent=true]
setblock ~176 ~163 ~90 oak_leaves[persistent=true]
setblock ~176 ~163 ~91 oak_leaves[persistent=true]
setblock ~176 ~163 ~92 oak_leaves[persistent=true]
setblock ~176 ~163 ~93 oak_wood
setblock ~176 ~163 ~94 oak_wood
setblock ~176 ~163 ~95 oak_leaves[persistent=true]
setblock ~176 ~163 ~96 oak_leaves[persistent=true]
setblock ~176 ~163 ~97 oak_wood
setblock ~176 ~163 ~98 oak_leaves[persistent=true]
setblock ~176 ~163 ~100 oak_leaves[persistent=true]
setblock ~176 ~163 ~101 jungle_leaves[persistent=true]
setblock ~176 ~164 ~84 oak_leaves[persistent=true]
setblock ~176 ~164 ~85 oak_leaves[persistent=true]
setblock ~176 ~164 ~86 oak_leaves[persistent=true]
setblock ~176 ~164 ~87 jungle_leaves[persistent=true]
setblock ~176 ~164 ~88 oak_leaves[persistent=true]
setblock ~176 ~164 ~89 oak_leaves[persistent=true]
setblock ~176 ~164 ~90 oak_leaves[persistent=true]
setblock ~176 ~164 ~91 oak_leaves[persistent=true]
setblock ~176 ~164 ~92 jungle_leaves[persistent=true]
setblock ~176 ~164 ~93 oak_wood
setblock ~176 ~164 ~94 jungle_leaves[persistent=true]
setblock ~176 ~164 ~95 oak_leaves[persistent=true]
setblock ~176 ~164 ~96 oak_wood
setblock ~176 ~164 ~97 oak_wood
setblock ~176 ~164 ~98 oak_wood
setblock ~176 ~164 ~99 oak_wood
setblock ~176 ~164 ~100 oak_leaves[persistent=true]
setblock ~176 ~164 ~101 oak_leaves[persistent=true]
setblock ~176 ~165 ~84 oak_leaves[persistent=true]
setblock ~176 ~165 ~85 oak_leaves[persistent=true]
setblock ~176 ~165 ~86 jungle_leaves[persistent=true]
setblock ~176 ~165 ~87 oak_leaves[persistent=true]
setblock ~176 ~165 ~88 oak_leaves[persistent=true]
setblock ~176 ~165 ~89 oak_leaves[persistent=true]
setblock ~176 ~165 ~90 oak_wood
setblock ~176 ~165 ~91 oak_leaves[persistent=true]
setblock ~176 ~165 ~92 oak_leaves[persistent=true]
setblock ~176 ~165 ~93 oak_leaves[persistent=true]
setblock ~176 ~165 ~95 oak_leaves[persistent=true]
setblock ~176 ~165 ~96 oak_leaves[persistent=true]
setblock ~176 ~165 ~97 oak_leaves[persistent=true]
setblock ~176 ~165 ~98 oak_leaves[persistent=true]
setblock ~176 ~165 ~99 oak_leaves[persistent=true]
setblock ~176 ~165 ~101 oak_leaves[persistent=true]
setblock ~176 ~166 ~84 jungle_leaves[persistent=true]
setblock ~176 ~166 ~85 oak_leaves[persistent=true]
setblock ~176 ~166 ~86 jungle_leaves[persistent=true]
setblock ~176 ~166 ~87 oak_leaves[persistent=true]
setblock ~176 ~166 ~88 oak_leaves[persistent=true]
setblock ~176 ~166 ~89 oak_leaves[persistent=true]
setblock ~176 ~166 ~90 oak_wood
setblock ~176 ~166 ~91 jungle_leaves[persistent=true]
setblock ~176 ~166 ~92 oak_leaves[persistent=true]
setblock ~176 ~166 ~93 oak_leaves[persistent=true]
setblock ~176 ~166 ~94 oak_leaves[persistent=true]
setblock ~176 ~166 ~95 oak_leaves[persistent=true]
setblock ~176 ~166 ~96 oak_leaves[persistent=true]
setblock ~176 ~166 ~97 oak_leaves[persistent=true]
setblock ~176 ~166 ~98 oak_leaves[persistent=true]
setblock ~176 ~166 ~99 oak_leaves[persistent=true]
setblock ~176 ~166 ~100 oak_leaves[persistent=true]
setblock ~176 ~166 ~101 jungle_leaves[persistent=true]
setblock ~176 ~167 ~84 oak_leaves[persistent=true]
setblock ~176 ~167 ~86 jungle_leaves[persistent=true]
setblock ~176 ~167 ~87 oak_leaves[persistent=true]
setblock ~176 ~167 ~88 oak_leaves[persistent=true]
setblock ~176 ~167 ~89 oak_leaves[persistent=true]
setblock ~176 ~167 ~90 oak_leaves[persistent=true]
setblock ~176 ~167 ~91 jungle_leaves[persistent=true]
setblock ~176 ~167 ~92 oak_leaves[persistent=true]
setblock ~176 ~167 ~93 oak_leaves[persistent=true]
setblock ~176 ~167 ~94 oak_wood
setblock ~176 ~167 ~95 oak_wood
setblock ~176 ~167 ~96 oak_leaves[persistent=true]
setblock ~176 ~167 ~97 oak_wood
setblock ~176 ~167 ~98 oak_leaves[persistent=true]
setblock ~176 ~167 ~99 oak_leaves[persistent=true]
setblock ~176 ~167 ~100 oak_leaves[persistent=true]
setblock ~176 ~167 ~101 oak_leaves[persistent=true]
setblock ~176 ~168 ~84 oak_leaves[persistent=true]
setblock ~176 ~168 ~85 oak_leaves[persistent=true]
setblock ~176 ~168 ~86 oak_leaves[persistent=true]
setblock ~176 ~168 ~87 oak_leaves[persistent=true]
setblock ~176 ~168 ~88 jungle_leaves[persistent=true]
setblock ~176 ~168 ~89 jungle_leaves[persistent=true]
setblock ~176 ~168 ~90 oak_wood
setblock ~176 ~168 ~91 oak_leaves[persistent=true]
setblock ~176 ~168 ~92 jungle_leaves[persistent=true]
setblock ~176 ~168 ~93 oak_leaves[persistent=true]
setblock ~176 ~168 ~94 oak_leaves[persistent=true]
setblock ~176 ~168 ~95 oak_leaves[persistent=true]
setblock ~176 ~168 ~96 oak_leaves[persistent=true]
setblock ~176 ~168 ~97 jungle_leaves[persistent=true]
setblock ~176 ~168 ~98 oak_leaves[persistent=true]
setblock ~176 ~168 ~99 oak_leaves[persistent=true]
setblock ~176 ~168 ~100 oak_leaves[persistent=true]
setblock ~176 ~168 ~101 oak_leaves[persistent=true]
setblock ~176 ~169 ~87 oak_leaves[persistent=true]
setblock ~176 ~169 ~88 oak_leaves[persistent=true]
setblock ~176 ~169 ~89 oak_leaves[persistent=true]
setblock ~176 ~169 ~90 oak_log
setblock ~176 ~169 ~91 oak_leaves[persistent=true]
setblock ~176 ~169 ~92 oak_leaves[persistent=true]
setblock ~176 ~169 ~93 oak_leaves[persistent=true]
setblock ~176 ~169 ~94 oak_leaves[persistent=true]
setblock ~176 ~169 ~95 oak_leaves[persistent=true]
setblock ~176 ~169 ~96 jungle_leaves[persistent=true]
setblock ~176 ~169 ~97 oak_leaves[persistent=true]
setblock ~176 ~169 ~98 oak_leaves[persistent=true]
setblock ~176 ~169 ~99 oak_leaves[persistent=true]
setblock ~176 ~169 ~100 oak_leaves[persistent=true]
setblock ~176 ~169 ~101 oak_leaves[persistent=true]
setblock ~176 ~170 ~87 jungle_leaves[persistent=true]
setblock ~176 ~170 ~88 oak_leaves[persistent=true]
setblock ~176 ~170 ~89 oak_leaves[persistent=true]
setblock ~176 ~170 ~90 oak_leaves[persistent=true]
setblock ~176 ~170 ~91 oak_leaves[persistent=true]
setblock ~176 ~170 ~92 oak_leaves[persistent=true]
setblock ~176 ~170 ~93 oak_leaves[persistent=true]
setblock ~176 ~170 ~94 jungle_leaves[persistent=true]
setblock ~176 ~170 ~95 oak_leaves[persistent=true]
setblock ~176 ~170 ~96 oak_leaves[persistent=true]
setblock ~176 ~170 ~97 oak_leaves[persistent=true]
setblock ~176 ~170 ~98 oak_leaves[persistent=true]
setblock ~176 ~170 ~99 oak_leaves[persistent=true]
setblock ~176 ~170 ~100 jungle_leaves[persistent=true]
setblock ~176 ~171 ~89 jungle_leaves[persistent=true]
setblock ~176 ~171 ~90 jungle_leaves[persistent=true]
setblock ~176 ~171 ~91 oak_leaves[persistent=true]
setblock ~176 ~171 ~92 oak_leaves[persistent=true]
setblock ~176 ~171 ~93 jungle_leaves[persistent=true]
setblock ~176 ~171 ~94 oak_leaves[persistent=true]
setblock ~176 ~171 ~95 oak_leaves[persistent=true]
setblock ~176 ~171 ~97 oak_leaves[persistent=true]
setblock ~176 ~171 ~98 oak_leaves[persistent=true]
setblock ~177 ~157 ~89 oak_leaves[persistent=true]
setblock ~177 ~157 ~90 jungle_leaves[persistent=true]
setblock ~177 ~157 ~91 oak_leaves[persistent=true]
setblock ~177 ~157 ~92 oak_leaves[persistent=true]
setblock ~177 ~158 ~84 jungle_leaves[persistent=true]
setblock ~177 ~158 ~86 oak_leaves[persistent=true]
setblock ~177 ~158 ~87 oak_leaves[persistent=true]
setblock ~177 ~158 ~88 jungle_leaves[persistent=true]
setblock ~177 ~158 ~89 oak_leaves[persistent=true]
setblock ~177 ~158 ~90 oak_leaves[persistent=true]
setblock ~177 ~158 ~91 oak_leaves[persistent=true]
setblock ~177 ~159 ~86 oak_leaves[persistent=true]
setblock ~177 ~159 ~87 oak_leaves[persistent=true]
setblock ~177 ~159 ~88 oak_leaves[persistent=true]
setblock ~177 ~159 ~89 oak_leaves[persistent=true]
setblock ~177 ~159 ~90 jungle_leaves[persistent=true]
setblock ~177 ~159 ~91 oak_leaves[persistent=true]
setblock ~177 ~159 ~92 oak_leaves[persistent=true]
setblock ~177 ~159 ~95 oak_leaves[persistent=true]
setblock ~177 ~159 ~96 oak_leaves[persistent=true]
setblock ~177 ~159 ~97 oak_leaves[persistent=true]
setblock ~177 ~159 ~98 oak_leaves[persistent=true]
setblock ~177 ~160 ~84 oak_leaves[persistent=true]
setblock ~177 ~160 ~85 oak_leaves[persistent=true]
setblock ~177 ~160 ~86 oak_leaves[persistent=true]
setblock ~177 ~160 ~87 oak_leaves[persistent=true]
setblock ~177 ~160 ~88 oak_leaves[persistent=true]
setblock ~177 ~160 ~89 oak_leaves[persistent=true]
setblock ~177 ~160 ~90 oak_leaves[persistent=true]
setblock ~177 ~160 ~91 oak_wood
setblock ~177 ~160 ~92 oak_leaves[persistent=true]
setblock ~177 ~160 ~94 oak_leaves[persistent=true]
setblock ~177 ~160 ~95 oak_leaves[persistent=true]
setblock ~177 ~160 ~96 oak_leaves[persistent=true]
setblock ~177 ~160 ~97 oak_leaves[persistent=true]
setblock ~177 ~160 ~98 oak_leaves[persistent=true]
setblock ~177 ~161 ~84 oak_leaves[persistent=true]
setblock ~177 ~161 ~85 oak_leaves[persistent=true]
setblock ~177 ~161 ~86 oak_leaves[persistent=true]
setblock ~177 ~161 ~87 oak_leaves[persistent=true]
setblock ~177 ~161 ~88 oak_leaves[persistent=true]
setblock ~177 ~161 ~90 oak_leaves[persistent=true]
setblock ~177 ~161 ~91 oak_leaves[persistent=true]
setblock ~177 ~161 ~93 oak_leaves[persistent=true]
setblock ~177 ~161 ~94 oak_leaves[persistent=true]
setblock ~177 ~161 ~95 oak_leaves[persistent=true]
setblock ~177 ~161 ~96 oak_leaves[persistent=true]
setblock ~177 ~161 ~97 oak_leaves[persistent=true]
setblock ~177 ~161 ~99 oak_leaves[persistent=true]
setblock ~177 ~162 ~86 jungle_leaves[persistent=true]
setblock ~177 ~162 ~87 jungle_leaves[persistent=true]
setblock ~177 ~162 ~88 oak_leaves[persistent=true]
setblock ~177 ~162 ~89 oak_leaves[persistent=true]
setblock ~177 ~162 ~90 jungle_leaves[persistent=true]
setblock ~177 ~162 ~91 oak_leaves[persistent=true]
setblock ~177 ~162 ~92 oak_leaves[persistent=true]
setblock ~177 ~162 ~93 oak_leaves[persistent=true]
setblock ~177 ~162 ~94 oak_leaves[persistent=true]
setblock ~177 ~162 ~95 oak_leaves[persistent=true]
setblock ~177 ~162 ~96 oak_leaves[persistent=true]
setblock ~177 ~162 ~97 oak_wood
setblock ~177 ~162 ~98 oak_leaves[persistent=true]
setblock ~177 ~162 ~99 jungle_leaves[persistent=true]
setblock ~177 ~162 ~100 oak_leaves[persistent=true]
setblock ~177 ~162 ~101 oak_leaves[persistent=true]
setblock ~177 ~163 ~84 oak_leaves[persistent=true]
setblock ~177 ~163 ~85 jungle_leaves[persistent=true]
setblock ~177 ~163 ~86 oak_leaves[persistent=true]
setblock ~177 ~163 ~87 oak_leaves[persistent=true]
setblock ~177 ~163 ~89 oak_leaves[persistent=true]
setblock ~177 ~163 ~90 oak_leaves[persistent=true]
setblock ~177 ~163 ~91 oak_leaves[persistent=true]
setblock ~177 ~163 ~92 jungle_leaves[persistent=true]
setblock ~177 ~163 ~93 jungle_leaves[persistent=true]
setblock ~177 ~163 ~94 oak_leaves[persistent=true]
setblock ~177 ~163 ~95 oak_leaves[persistent=true]
setblock ~177 ~163 ~96 jungle_leaves[persistent=true]
setblock ~177 ~163 ~98 oak_leaves[persistent=true]
setblock ~177 ~163 ~100 oak_leaves[persistent=true]
setblock ~177 ~163 ~101 jungle_leaves[persistent=true]
setblock ~177 ~164 ~86 oak_leaves[persistent=true]
setblock ~177 ~164 ~87 oak_leaves[persistent=true]
setblock ~177 ~164 ~88 oak_leaves[persistent=true]
setblock ~177 ~164 ~89 oak_leaves[persistent=true]
setblock ~177 ~164 ~90 jungle_leaves[persistent=true]
setblock ~177 ~164 ~91 oak_leaves[persistent=true]
setblock ~177 ~164 ~92 jungle_leaves[persistent=true]
setblock ~177 ~164 ~93 oak_leaves[persistent=true]
setblock ~177 ~164 ~94 oak_leaves[persistent=true]
setblock ~177 ~164 ~95 oak_leaves[persistent=true]
setblock ~177 ~164 ~96 oak_leaves[persistent=true]
setblock ~177 ~164 ~97 jungle_leaves[persistent=true]
setblock ~177 ~164 ~99 jungle_leaves[persistent=true]
setblock ~177 ~164 ~100 oak_leaves[persistent=true]
setblock ~177 ~164 ~101 oak_leaves[persistent=true]
setblock ~177 ~165 ~84 jungle_leaves[persistent=true]
setblock ~177 ~165 ~85 oak_leaves[persistent=true]
setblock ~177 ~165 ~86 oak_leaves[persistent=true]
setblock ~177 ~165 ~88 oak_leaves[persistent=true]
setblock ~177 ~165 ~89 oak_wood
setblock ~177 ~165 ~90 oak_leaves[persistent=true]
setblock ~177 ~165 ~91 jungle_leaves[persistent=true]
setblock ~177 ~165 ~92 oak_leaves[persistent=true]
setblock ~177 ~165 ~93 oak_leaves[persistent=true]
setblock ~177 ~165 ~94 oak_leaves[persistent=true]
setblock ~177 ~165 ~95 oak_leaves[persistent=true]
setblock ~177 ~165 ~96 oak_leaves[persistent=true]
setblock ~177 ~165 ~98 oak_leaves[persistent=true]
setblock ~177 ~165 ~99 oak_leaves[persistent=true]
setblock ~177 ~165 ~101 oak_leaves[persistent=true]
setblock ~177 ~166 ~87 oak_leaves[persistent=true]
setblock ~177 ~166 ~88 jungle_leaves[persistent=true]
setblock ~177 ~166 ~89 oak_leaves[persistent=true]
setblock ~177 ~166 ~90 oak_leaves[persistent=true]
setblock ~177 ~166 ~91 oak_leaves[persistent=true]
setblock ~177 ~166 ~93 oak_leaves[persistent=true]
setblock ~177 ~166 ~94 oak_leaves[persistent=true]
setblock ~177 ~166 ~95 oak_leaves[persistent=true]
setblock ~177 ~166 ~96 oak_leaves[persistent=true]
setblock ~177 ~166 ~97 oak_leaves[persistent=true]
setblock ~177 ~166 ~98 oak_leaves[persistent=true]
setblock ~177 ~167 ~87 jungle_leaves[persistent=true]
setblock ~177 ~167 ~88 oak_leaves[persistent=true]
setblock ~177 ~167 ~89 oak_leaves[persistent=true]
setblock ~177 ~167 ~90 jungle_leaves[persistent=true]
setblock ~177 ~167 ~92 oak_leaves[persistent=true]
setblock ~177 ~167 ~93 jungle_leaves[persistent=true]
setblock ~177 ~167 ~94 oak_leaves[persistent=true]
setblock ~177 ~167 ~95 oak_leaves[persistent=true]
setblock ~177 ~167 ~96 jungle_leaves[persistent=true]
setblock ~177 ~167 ~97 oak_leaves[persistent=true]
setblock ~177 ~167 ~98 jungle_leaves[persistent=true]
setblock ~177 ~167 ~99 oak_leaves[persistent=true]
setblock ~177 ~167 ~100 oak_leaves[persistent=true]
setblock ~177 ~167 ~101 oak_leaves[persistent=true]
setblock ~177 ~168 ~87 oak_leaves[persistent=true]
setblock ~177 ~168 ~88 oak_leaves[persistent=true]
setblock ~177 ~168 ~89 oak_leaves[persistent=true]
setblock ~177 ~168 ~90 oak_wood
setblock ~177 ~168 ~91 oak_leaves[persistent=true]
setblock ~177 ~168 ~92 jungle_leaves[persistent=true]
setblock ~177 ~168 ~93 oak_leaves[persistent=true]
setblock ~177 ~168 ~94 oak_leaves[persistent=true]
setblock ~177 ~168 ~95 jungle_leaves[persistent=true]
setblock ~177 ~168 ~96 oak_leaves[persistent=true]
setblock ~177 ~168 ~97 jungle_leaves[persistent=true]
setblock ~177 ~168 ~98 oak_leaves[persistent=true]
setblock ~177 ~168 ~99 oak_leaves[persistent=true]
setblock ~177 ~168 ~100 oak_leaves[persistent=true]
setblock ~177 ~168 ~101 jungle_leaves[persistent=true]
setblock ~177 ~169 ~87 oak_leaves[persistent=true]
setblock ~177 ~169 ~88 jungle_leaves[persistent=true]
setblock ~177 ~169 ~89 oak_leaves[persistent=true]
setblock ~177 ~169 ~90 oak_leaves[persistent=true]
setblock ~177 ~169 ~91 oak_leaves[persistent=true]
setblock ~177 ~169 ~92 oak_leaves[persistent=true]
setblock ~177 ~169 ~93 jungle_leaves[persistent=true]
setblock ~177 ~169 ~94 jungle_leaves[persistent=true]
setblock ~177 ~169 ~96 oak_leaves[persistent=true]
setblock ~177 ~169 ~99 oak_leaves[persistent=true]
setblock ~177 ~169 ~101 oak_leaves[persistent=true]
setblock ~177 ~170 ~87 oak_leaves[persistent=true]
setblock ~177 ~170 ~88 oak_leaves[persistent=true]
setblock ~177 ~170 ~89 oak_leaves[persistent=true]
setblock ~177 ~170 ~90 oak_leaves[persistent=true]
setblock ~177 ~170 ~91 oak_leaves[persistent=true]
setblock ~177 ~170 ~92 oak_leaves[persistent=true]
setblock ~177 ~170 ~93 oak_leaves[persistent=true]
setblock ~177 ~170 ~94 oak_leaves[persistent=true]
setblock ~177 ~170 ~95 jungle_leaves[persistent=true]
setblock ~177 ~170 ~96 oak_leaves[persistent=true]
setblock ~177 ~171 ~88 oak_leaves[persistent=true]
setblock ~177 ~171 ~92 oak_leaves[persistent=true]
setblock ~177 ~171 ~93 oak_leaves[persistent=true]
setblock ~177 ~171 ~94 jungle_leaves[persistent=true]
setblock ~177 ~171 ~95 oak_leaves[persistent=true]
setblock ~178 ~158 ~84 oak_leaves[persistent=true]
setblock ~178 ~158 ~85 oak_leaves[persistent=true]
setblock ~178 ~158 ~86 oak_leaves[persistent=true]
setblock ~178 ~158 ~87 jungle_leaves[persistent=true]
setblock ~178 ~158 ~88 oak_leaves[persistent=true]
setblock ~178 ~158 ~90 oak_leaves[persistent=true]
setblock ~178 ~158 ~91 oak_leaves[persistent=true]
setblock ~178 ~159 ~84 oak_leaves[persistent=true]
setblock ~178 ~159 ~85 oak_leaves[persistent=true]
setblock ~178 ~159 ~86 oak_leaves[persistent=true]
setblock ~178 ~159 ~88 oak_leaves[persistent=true]
setblock ~178 ~159 ~89 oak_leaves[persistent=true]
setblock ~178 ~159 ~90 oak_leaves[persistent=true]
setblock ~178 ~159 ~91 jungle_leaves[persistent=true]
setblock ~178 ~159 ~92 oak_leaves[persistent=true]
setblock ~178 ~160 ~84 oak_leaves[persistent=true]
setblock ~178 ~160 ~85 oak_leaves[persistent=true]
setblock ~178 ~160 ~86 oak_leaves[persistent=true]
setblock ~178 ~160 ~87 oak_leaves[persistent=true]
setblock ~178 ~160 ~89 oak_leaves[persistent=true]
setblock ~178 ~160 ~91 oak_leaves[persistent=true]
setblock ~178 ~160 ~92 oak_leaves[persistent=true]
setblock ~178 ~161 ~84 oak_leaves[persistent=true]
setblock ~178 ~161 ~85 oak_leaves[persistent=true]
setblock ~178 ~161 ~86 oak_leaves[persistent=true]
setblock ~178 ~161 ~87 oak_leaves[persistent=true]
setblock ~178 ~161 ~88 oak_leaves[persistent=true]
setblock ~178 ~161 ~89 oak_leaves[persistent=true]
setblock ~178 ~161 ~90 jungle_leaves[persistent=true]
setblock ~178 ~161 ~91 oak_leaves[persistent=true]
setblock ~178 ~161 ~92 oak_leaves[persistent=true]
setblock ~178 ~161 ~93 oak_leaves[persistent=true]
setblock ~178 ~161 ~96 oak_leaves[persistent=true]
setblock ~178 ~161 ~97 jungle_leaves[persistent=true]
setblock ~178 ~161 ~99 oak_leaves[persistent=true]
setblock ~178 ~162 ~90 oak_leaves[persistent=true]
setblock ~178 ~162 ~91 jungle_leaves[persistent=true]
setblock ~178 ~162 ~92 oak_leaves[persistent=true]
setblock ~178 ~162 ~93 oak_leaves[persistent=true]
setblock ~178 ~162 ~94 oak_leaves[persistent=true]
setblock ~178 ~162 ~95 oak_leaves[persistent=true]
setblock ~178 ~162 ~96 oak_leaves[persistent=true]
setblock ~178 ~162 ~97 oak_leaves[persistent=true]
setblock ~178 ~162 ~98 oak_leaves[persistent=true]
setblock ~178 ~162 ~99 oak_leaves[persistent=true]
setblock ~178 ~162 ~100 oak_leaves[persistent=true]
setblock ~178 ~162 ~101 oak_leaves[persistent=true]
setblock ~178 ~163 ~90 jungle_leaves[persistent=true]
setblock ~178 ~163 ~91 oak_leaves[persistent=true]
setblock ~178 ~163 ~92 oak_leaves[persistent=true]
setblock ~178 ~163 ~93 oak_leaves[persistent=true]
setblock ~178 ~163 ~94 oak_leaves[persistent=true]
setblock ~178 ~163 ~95 oak_leaves[persistent=true]
setblock ~178 ~163 ~96 oak_leaves[persistent=true]
setblock ~178 ~163 ~97 oak_leaves[persistent=true]
setblock ~178 ~163 ~98 oak_leaves[persistent=true]
setblock ~178 ~163 ~99 oak_leaves[persistent=true]
setblock ~178 ~163 ~100 jungle_leaves[persistent=true]
setblock ~178 ~164 ~86 oak_leaves[persistent=true]
setblock ~178 ~164 ~87 jungle_leaves[persistent=true]
setblock ~178 ~164 ~89 oak_leaves[persistent=true]
setblock ~178 ~164 ~90 oak_leaves[persistent=true]
setblock ~178 ~164 ~91 oak_leaves[persistent=true]
setblock ~178 ~164 ~92 oak_leaves[persistent=true]
setblock ~178 ~164 ~93 oak_leaves[persistent=true]
setblock ~178 ~164 ~94 oak_leaves[persistent=true]
setblock ~178 ~164 ~95 oak_leaves[persistent=true]
setblock ~178 ~164 ~96 oak_leaves[persistent=true]
setblock ~178 ~164 ~97 oak_leaves[persistent=true]
setblock ~178 ~164 ~99 oak_leaves[persistent=true]
setblock ~178 ~164 ~100 oak_leaves[persistent=true]
setblock ~178 ~164 ~101 jungle_leaves[persistent=true]
setblock ~178 ~165 ~86 oak_leaves[persistent=true]
setblock ~178 ~165 ~87 jungle_leaves[persistent=true]
setblock ~178 ~165 ~88 oak_wood
setblock ~178 ~165 ~89 oak_leaves[persistent=true]
setblock ~178 ~165 ~90 oak_leaves[persistent=true]
setblock ~178 ~165 ~91 oak_leaves[persistent=true]
setblock ~178 ~165 ~92 oak_leaves[persistent=true]
setblock ~178 ~165 ~93 oak_leaves[persistent=true]
setblock ~178 ~165 ~94 oak_leaves[persistent=true]
setblock ~178 ~165 ~95 jungle_leaves[persistent=true]
setblock ~178 ~165 ~96 jungle_leaves[persistent=true]
setblock ~178 ~165 ~97 oak_leaves[persistent=true]
setblock ~178 ~165 ~99 jungle_leaves[persistent=true]
setblock ~178 ~165 ~100 oak_leaves[persistent=true]
setblock ~178 ~165 ~101 oak_leaves[persistent=true]
setblock ~178 ~166 ~87 oak_leaves[persistent=true]
setblock ~178 ~166 ~88 oak_leaves[persistent=true]
setblock ~178 ~166 ~90 oak_leaves[persistent=true]
setblock ~178 ~166 ~91 oak_leaves[persistent=true]
setblock ~178 ~166 ~92 jungle_leaves[persistent=true]
setblock ~178 ~166 ~95 oak_leaves[persistent=true]
setblock ~178 ~166 ~96 oak_leaves[persistent=true]
setblock ~178 ~166 ~97 jungle_leaves[persistent=true]
setblock ~178 ~166 ~98 oak_leaves[persistent=true]
setblock ~178 ~167 ~87 oak_leaves[persistent=true]
setblock ~178 ~167 ~88 oak_leaves[persistent=true]
setblock ~178 ~167 ~89 oak_leaves[persistent=true]
setblock ~178 ~167 ~90 oak_leaves[persistent=true]
setblock ~178 ~167 ~91 oak_leaves[persistent=true]
setblock ~178 ~167 ~92 oak_leaves[persistent=true]
setblock ~178 ~167 ~93 jungle_leaves[persistent=true]
setblock ~178 ~167 ~94 oak_leaves[persistent=true]
setblock ~178 ~167 ~95 oak_leaves[persistent=true]
setblock ~178 ~167 ~96 oak_leaves[persistent=true]
setblock ~178 ~167 ~98 jungle_leaves[persistent=true]
setblock ~178 ~168 ~87 oak_leaves[persistent=true]
setblock ~178 ~168 ~89 oak_leaves[persistent=true]
setblock ~178 ~168 ~90 jungle_leaves[persistent=true]
setblock ~178 ~168 ~91 oak_leaves[persistent=true]
setblock ~178 ~168 ~92 oak_leaves[persistent=true]
setblock ~178 ~168 ~93 oak_leaves[persistent=true]
setblock ~178 ~168 ~94 oak_leaves[persistent=true]
setblock ~178 ~168 ~95 oak_leaves[persistent=true]
setblock ~178 ~168 ~96 oak_leaves[persistent=true]
setblock ~178 ~168 ~97 oak_leaves[persistent=true]
setblock ~178 ~169 ~87 jungle_leaves[persistent=true]
setblock ~178 ~169 ~89 oak_leaves[persistent=true]
setblock ~178 ~169 ~90 oak_wood
setblock ~178 ~169 ~91 oak_leaves[persistent=true]
setblock ~178 ~169 ~92 jungle_leaves[persistent=true]
setblock ~178 ~170 ~87 oak_leaves[persistent=true]
setblock ~178 ~170 ~88 oak_leaves[persistent=true]
setblock ~178 ~170 ~89 oak_leaves[persistent=true]
setblock ~178 ~170 ~90 oak_leaves[persistent=true]
setblock ~178 ~170 ~91 oak_leaves[persistent=true]
setblock ~178 ~170 ~92 oak_leaves[persistent=true]
setblock ~178 ~171 ~88 jungle_leaves[persistent=true]
setblock ~178 ~171 ~89 oak_leaves[persistent=true]
setblock ~178 ~171 ~90 oak_leaves[persistent=true]
setblock ~178 ~171 ~91 oak_leaves[persistent=true]
setblock ~179 ~161 ~97 oak_leaves[persistent=true]
setblock ~179 ~161 ~98 oak_leaves[persistent=true]
setblock ~179 ~161 ~99 oak_leaves[persistent=true]
setblock ~179 ~162 ~97 oak_leaves[persistent=true]
setblock ~179 ~162 ~98 jungle_leaves[persistent=true]
setblock ~179 ~162 ~99 oak_leaves[persistent=true]
setblock ~179 ~163 ~97 jungle_leaves[persistent=true]
setblock ~179 ~163 ~98 oak_leaves[persistent=true]
setblock ~179 ~163 ~99 oak_leaves[persistent=true]
setblock ~179 ~164 ~86 oak_leaves[persistent=true]
setblock ~179 ~164 ~87 oak_leaves[persistent=true]
setblock ~179 ~164 ~88 oak_leaves[persistent=true]
setblock ~179 ~164 ~89 oak_leaves[persistent=true]
setblock ~179 ~165 ~86 oak_leaves[persistent=true]
setblock ~179 ~165 ~87 oak_leaves[persistent=true]
setblock ~179 ~165 ~88 oak_leaves[persistent=true]
setblock ~179 ~165 ~89 oak_leaves[persistent=true]
setblock ~179 ~166 ~87 oak_leaves[persistent=true]
setblock ~179 ~166 ~88 oak_leaves[persistent=true]
setblock ~179 ~166 ~89 jungle_leaves[persistent=true]
setblock ~179 ~168 ~88 oak_leaves[persistent=true]
setblock ~179 ~168 ~89 oak_leaves[persistent=true]
setblock ~179 ~168 ~90 oak_leaves[persistent=true]
setblock ~179 ~168 ~91 oak_leaves[persistent=true]
setblock ~179 ~169 ~88 oak_leaves[persistent=true]
setblock ~179 ~169 ~89 oak_leaves[persistent=true]
setblock ~179 ~169 ~90 jungle_leaves[persistent=true]
setblock ~179 ~169 ~91 oak_leaves[persistent=true]
setblock ~179 ~170 ~88 oak_leaves[persistent=true]
setblock ~179 ~170 ~89 jungle_leaves[persistent=true]
setblock ~179 ~170 ~90 oak_leaves[persistent=true]
setblock ~179 ~170 ~91 oak_leaves[persistent=true]
setblock ~179 ~171 ~88 jungle_leaves[persistent=true]
setblock ~179 ~171 ~89 oak_leaves[persistent=true]
setblock ~179 ~171 ~90 jungle_leaves[persistent=true]
setblock ~179 ~171 ~91 oak_leaves[persistent=true]
setblock ~180 ~168 ~88 oak_leaves[persistent=true]
setblock ~180 ~168 ~89 oak_leaves[persistent=true]
setblock ~180 ~168 ~91 oak_leaves[persistent=true]
setblock ~180 ~169 ~88 jungle_leaves[persistent=true]
setblock ~180 ~169 ~89 oak_leaves[persistent=true]
setblock ~180 ~169 ~90 oak_leaves[persistent=true]
setblock ~180 ~169 ~91 oak_leaves[persistent=true]
setblock ~180 ~170 ~88 oak_leaves[persistent=true]
setblock ~180 ~170 ~89 oak_leaves[persistent=true]
setblock ~180 ~170 ~90 jungle_leaves[persistent=true]
setblock ~180 ~170 ~91 oak_leaves[persistent=true]
setblock ~180 ~171 ~88 jungle_leaves[persistent=true]
setblock ~180 ~171 ~89 oak_leaves[persistent=true]
setblock ~180 ~171 ~90 oak_leaves[persistent=true]
setblock ~180 ~171 ~91 jungle_leaves[persistent=true]
setblock ~199 ~200 ~199 gold_block
