setblock ~21 ~122 ~102 dirt
setblock ~21 ~122 ~103 dirt
setblock ~21 ~122 ~104 dirt
setblock ~21 ~122 ~105 dirt
setblock ~21 ~122 ~106 dirt
setblock ~21 ~122 ~107 dirt
setblock ~21 ~122 ~108 dirt
setblock ~21 ~122 ~109 dirt
setblock ~21 ~122 ~110 dirt
setblock ~21 ~122 ~111 dirt
setblock ~21 ~122 ~112 dirt
setblock ~21 ~122 ~113 dirt
setblock ~21 ~122 ~114 dirt
setblock ~21 ~122 ~115 dirt
setblock ~21 ~122 ~116 dirt
setblock ~21 ~122 ~117 dirt
setblock ~21 ~122 ~118 dirt
setblock ~21 ~122 ~119 dirt
setblock ~21 ~122 ~120 grass_block
setblock ~21 ~122 ~121 dirt
setblock ~21 ~122 ~122 dirt
setblock ~21 ~122 ~123 dirt
setblock ~21 ~122 ~124 dirt
setblock ~21 ~123 ~52 dirt
setblock ~21 ~123 ~53 dirt
setblock ~21 ~123 ~54 dirt
setblock ~21 ~123 ~55 dirt
setblock ~21 ~123 ~56 dirt
setblock ~21 ~123 ~57 dirt
setblock ~21 ~123 ~58 dirt
setblock ~21 ~123 ~59 grass_block
setblock ~21 ~123 ~60 grass_block
setblock ~21 ~123 ~61 grass_block
setblock ~21 ~123 ~62 grass_block
setblock ~21 ~123 ~63 dirt
setblock ~21 ~123 ~93 dirt
setblock ~21 ~123 ~94 dirt
setblock ~21 ~123 ~95 dirt
setblock ~21 ~123 ~96 dirt
setblock ~21 ~123 ~97 dirt
setblock ~21 ~123 ~98 dirt
setblock ~21 ~123 ~99 dirt
setblock ~21 ~123 ~100 dirt
setblock ~21 ~123 ~101 dirt
setblock ~21 ~123 ~102 dirt
setblock ~21 ~123 ~103 dirt
setblock ~21 ~123 ~104 dirt
setblock ~21 ~123 ~105 dirt
setblock ~21 ~123 ~106 dirt
setblock ~21 ~123 ~107 dirt
setblock ~21 ~123 ~108 dirt
setblock ~21 ~123 ~109 dirt
setblock ~21 ~123 ~110 dirt
setblock ~21 ~123 ~111 dirt
setblock ~21 ~123 ~112 dirt
setblock ~21 ~123 ~113 dirt
setblock ~21 ~123 ~114 dirt
setblock ~21 ~123 ~115 dirt
setblock ~21 ~123 ~116 dirt
setblock ~21 ~123 ~117 grass_block
setblock ~21 ~123 ~118 grass_block
setblock ~21 ~123 ~119 grass_block
setblock ~21 ~123 ~121 grass_block
setblock ~21 ~123 ~122 grass_block
setblock ~21 ~123 ~123 grass_block
setblock ~21 ~123 ~124 dirt
setblock ~21 ~124 ~52 dirt
setblock ~21 ~124 ~53 dirt
setblock ~21 ~124 ~54 grass_block
setblock ~21 ~124 ~55 grass_block
setblock ~21 ~124 ~56 grass_block
setblock ~21 ~124 ~57 grass_block
setblock ~21 ~124 ~58 grass_block
setblock ~21 ~124 ~59 short_grass
setblock ~21 ~124 ~62 short_grass
setblock ~21 ~124 ~63 grass_block
setblock ~21 ~124 ~93 dirt
setblock ~21 ~124 ~94 dirt
setblock ~21 ~124 ~95 dirt
setblock ~21 ~124 ~96 dirt
setblock ~21 ~124 ~97 dirt
setblock ~21 ~124 ~98 dirt
setblock ~21 ~124 ~99 dirt
setblock ~21 ~124 ~100 grass_block
setblock ~21 ~124 ~101 dirt
setblock ~21 ~124 ~102 dirt
setblock ~21 ~124 ~103 dirt
setblock ~21 ~124 ~104 dirt
setblock ~21 ~124 ~105 dirt
setblock ~21 ~124 ~106 dirt
setblock ~21 ~124 ~107 dirt
setblock ~21 ~124 ~108 dirt
setblock ~21 ~124 ~109 dirt
setblock ~21 ~124 ~110 dirt
setblock ~21 ~124 ~111 dirt
setblock ~21 ~124 ~112 dirt
setblock ~21 ~124 ~113 dirt
setblock ~21 ~124 ~114 dirt
setblock ~21 ~124 ~115 grass_block
setblock ~21 ~124 ~116 grass_block
setblock ~21 ~124 ~118 poppy
setblock ~21 ~124 ~124 grass_block
setblock ~21 ~125 ~52 grass_block
setblock ~21 ~125 ~53 grass_block
setblock ~21 ~125 ~63 short_grass
setblock ~21 ~125 ~93 dirt
setblock ~21 ~125 ~94 grass_block
setblock ~21 ~125 ~95 grass_block
setblock ~21 ~125 ~96 grass_block
setblock ~21 ~125 ~97 grass_block
setblock ~21 ~125 ~98 grass_block
setblock ~21 ~125 ~99 grass_block
setblock ~21 ~125 ~101 grass_block
setblock ~21 ~125 ~102 grass_block
setblock ~21 ~125 ~103 grass_block
setblock ~21 ~125 ~104 grass_block
setblock ~21 ~125 ~105 dirt
setblock ~21 ~125 ~106 dirt
setblock ~21 ~125 ~107 dirt
setblock ~21 ~125 ~108 dirt
setblock ~21 ~125 ~109 dirt
setblock ~21 ~125 ~110 dirt
setblock ~21 ~125 ~111 dirt
setblock ~21 ~125 ~112 dirt
setblock ~21 ~125 ~113 grass_block
setblock ~21 ~125 ~114 grass_block
setblock ~21 ~125 ~124 fern
setblock ~21 ~126 ~93 grass_block
setblock ~21 ~126 ~98 poppy
setblock ~21 ~126 ~101 short_grass
setblock ~21 ~126 ~102 poppy
setblock ~21 ~126 ~105 grass_block
setblock ~21 ~126 ~106 grass_block
setblock ~21 ~126 ~107 grass_block
setblock ~21 ~126 ~108 grass_block
setblock ~21 ~126 ~109 grass_block
setblock ~21 ~126 ~110 dirt
setblock ~21 ~126 ~111 grass_block
setblock ~21 ~126 ~112 grass_block
setblock ~21 ~127 ~106 short_grass
setblock ~21 ~127 ~110 grass_block
setblock ~21 ~127 ~111 short_grass
setblock ~22 ~102 ~108 dirt
setblock ~22 ~103 ~107 dirt
setblock ~22 ~103 ~108 dirt
setblock ~22 ~103 ~109 dirt
setblock ~22 ~104 ~106 dirt
setblock ~22 ~104 ~107 dirt
setblock ~22 ~104 ~108 dirt
setblock ~22 ~104 ~109 dirt
setblock ~22 ~104 ~110 dirt
setblock ~22 ~105 ~105 dirt
setblock ~22 ~105 ~106 dirt
setblock ~22 ~105 ~107 dirt
setblock ~22 ~105 ~108 dirt
setblock ~22 ~105 ~109 dirt
setblock ~22 ~105 ~110 dirt
setblock ~22 ~105 ~111 dirt
setblock ~22 ~106 ~104 dirt
setblock ~22 ~106 ~105 dirt
setblock ~22 ~106 ~106 dirt
setblock ~22 ~106 ~107 dirt
setblock ~22 ~106 ~108 dirt
setblock ~22 ~106 ~109 dirt
setblock ~22 ~106 ~110 dirt
setblock ~22 ~106 ~111 dirt
setblock ~22 ~107 ~104 dirt
setblock ~22 ~107 ~105 dirt
setblock ~22 ~107 ~106 dirt
setblock ~22 ~107 ~107 dirt
setblock ~22 ~107 ~108 dirt
setblock ~22 ~107 ~109 dirt
setblock ~22 ~107 ~110 dirt
setblock ~22 ~107 ~111 dirt
setblock ~22 ~107 ~112 dirt
setblock ~22 ~108 ~103 dirt
setblock ~22 ~108 ~104 dirt
setblock ~22 ~108 ~105 dirt
setblock ~22 ~108 ~106 dirt
setblock ~22 ~108 ~107 dirt
setblock ~22 ~108 ~108 dirt
setblock ~22 ~108 ~109 dirt
setblock ~22 ~108 ~110 dirt
setblock ~22 ~108 ~111 dirt
setblock ~22 ~108 ~112 dirt
setblock ~22 ~108 ~113 dirt
setblock ~22 ~109 ~102 dirt
setblock ~22 ~109 ~103 dirt
setblock ~22 ~109 ~104 dirt
setblock ~22 ~109 ~105 dirt
setblock ~22 ~109 ~106 dirt
setblock ~22 ~109 ~107 dirt
setblock ~22 ~109 ~108 dirt
setblock ~22 ~109 ~109 dirt
setblock ~22 ~109 ~110 dirt
setblock ~22 ~109 ~111 dirt
setblock ~22 ~109 ~112 dirt
setblock ~22 ~109 ~113 dirt
setblock ~22 ~109 ~114 dirt
setblock ~22 ~110 ~101 dirt
setblock ~22 ~110 ~102 dirt
setblock ~22 ~110 ~103 dirt
setblock ~22 ~110 ~104 dirt
setblock ~22 ~110 ~105 dirt
setblock ~22 ~110 ~106 dirt
setblock ~22 ~110 ~107 dirt
setblock ~22 ~110 ~108 dirt
setblock ~22 ~110 ~109 dirt
setblock ~22 ~110 ~110 dirt
setblock ~22 ~110 ~111 dirt
setblock ~22 ~110 ~112 dirt
setblock ~22 ~110 ~113 dirt
setblock ~22 ~110 ~114 dirt
setblock ~22 ~110 ~115 dirt
setblock ~22 ~111 ~100 dirt
setblock ~22 ~111 ~101 dirt
setblock ~22 ~111 ~102 dirt
setblock ~22 ~111 ~103 dirt
setblock ~22 ~111 ~104 dirt
setblock ~22 ~111 ~105 dirt
setblock ~22 ~111 ~106 dirt
setblock ~22 ~111 ~107 dirt
setblock ~22 ~111 ~108 dirt
setblock ~22 ~111 ~109 dirt
setblock ~22 ~111 ~110 dirt
setblock ~22 ~111 ~111 dirt
setblock ~22 ~111 ~112 dirt
setblock ~22 ~111 ~113 dirt
setblock ~22 ~111 ~114 dirt
setblock ~22 ~111 ~115 dirt
setblock ~22 ~112 ~55 dirt
setblock ~22 ~112 ~99 dirt
setblock ~22 ~112 ~100 dirt
setblock ~22 ~112 ~101 dirt
setblock ~22 ~112 ~102 dirt
setblock ~22 ~112 ~103 dirt
setblock ~22 ~112 ~104 dirt
setblock ~22 ~112 ~105 dirt
setblock ~22 ~112 ~106 dirt
setblock ~22 ~112 ~107 dirt
setblock ~22 ~112 ~108 dirt
setblock ~22 ~112 ~109 dirt
setblock ~22 ~112 ~110 dirt
setblock ~22 ~112 ~111 dirt
setblock ~22 ~112 ~112 dirt
setblock ~22 ~112 ~113 dirt
setblock ~22 ~112 ~114 dirt
setblock ~22 ~112 ~115 dirt
setblock ~22 ~112 ~116 dirt
setblock ~22 ~113 ~55 dirt
setblock ~22 ~113 ~56 dirt
setblock ~22 ~113 ~98 dirt
setblock ~22 ~113 ~99 dirt
setblock ~22 ~113 ~100 dirt
setblock ~22 ~113 ~101 dirt
setblock ~22 ~113 ~102 dirt
setblock ~22 ~113 ~103 dirt
setblock ~22 ~113 ~104 dirt
setblock ~22 ~113 ~105 dirt
setblock ~22 ~113 ~106 dirt
setblock ~22 ~113 ~107 dirt
setblock ~22 ~113 ~108 dirt
setblock ~22 ~113 ~109 dirt
setblock ~22 ~113 ~110 dirt
setblock ~22 ~113 ~111 dirt
setblock ~22 ~113 ~112 dirt
setblock ~22 ~113 ~113 dirt
setblock ~22 ~113 ~114 dirt
setblock ~22 ~113 ~115 dirt
setblock ~22 ~113 ~116 dirt
setblock ~22 ~113 ~117 dirt
setblock ~22 ~114 ~54 dirt
setblock ~22 ~114 ~55 dirt
setblock ~22 ~114 ~56 dirt
setblock ~22 ~114 ~57 dirt
setblock ~22 ~114 ~98 dirt
setblock ~22 ~114 ~99 dirt
setblock ~22 ~114 ~100 dirt
setblock ~22 ~114 ~101 dirt
setblock ~22 ~114 ~102 dirt
setblock ~22 ~114 ~103 dirt
setblock ~22 ~114 ~104 dirt
setblock ~22 ~114 ~105 dirt
setblock ~22 ~114 ~106 dirt
setblock ~22 ~114 ~107 dirt
setblock ~22 ~114 ~108 dirt
setblock ~22 ~114 ~109 dirt
setblock ~22 ~114 ~110 dirt
setblock ~22 ~114 ~111 dirt
setblock ~22 ~114 ~112 dirt
setblock ~22 ~114 ~113 dirt
setblock ~22 ~114 ~114 dirt
setblock ~22 ~114 ~115 dirt
setblock ~22 ~114 ~116 dirt
setblock ~22 ~114 ~117 dirt
setblock ~22 ~114 ~118 dirt
setblock ~22 ~115 ~53 dirt
setblock ~22 ~115 ~54 dirt
setblock ~22 ~115 ~55 dirt
setblock ~22 ~115 ~56 dirt
setblock ~22 ~115 ~57 dirt
setblock ~22 ~115 ~58 dirt
setblock ~22 ~115 ~97 dirt
setblock ~22 ~115 ~98 dirt
setblock ~22 ~115 ~99 dirt
setblock ~22 ~115 ~100 dirt
setblock ~22 ~115 ~101 dirt
setblock ~22 ~115 ~102 dirt
setblock ~22 ~115 ~103 dirt
setblock ~22 ~115 ~104 dirt
setblock ~22 ~115 ~105 dirt
setblock ~22 ~115 ~106 dirt
setblock ~22 ~115 ~107 dirt
setblock ~22 ~115 ~108 dirt
setblock ~22 ~115 ~109 dirt
setblock ~22 ~115 ~110 dirt
setblock ~22 ~115 ~111 dirt
setblock ~22 ~115 ~112 dirt
setblock ~22 ~115 ~113 dirt
setblock ~22 ~115 ~114 dirt
setblock ~22 ~115 ~115 dirt
setblock ~22 ~115 ~116 dirt
setblock ~22 ~115 ~117 dirt
setblock ~22 ~115 ~118 dirt
setblock ~22 ~116 ~53 dirt
setblock ~22 ~116 ~54 dirt
setblock ~22 ~116 ~55 dirt
setblock ~22 ~116 ~56 dirt
setblock ~22 ~116 ~57 dirt
setblock ~22 ~116 ~58 dirt
setblock ~22 ~116 ~97 dirt
setblock ~22 ~116 ~98 dirt
setblock ~22 ~116 ~99 dirt
setblock ~22 ~116 ~100 dirt
setblock ~22 ~116 ~101 dirt
setblock ~22 ~116 ~102 dirt
setblock ~22 ~116 ~103 dirt
setblock ~22 ~116 ~104 dirt
setblock ~22 ~116 ~105 dirt
setblock ~22 ~116 ~106 dirt
setblock ~22 ~116 ~107 dirt
setblock ~22 ~116 ~108 dirt
setblock ~22 ~116 ~109 dirt
setblock ~22 ~116 ~110 dirt
setblock ~22 ~116 ~111 dirt
setblock ~22 ~116 ~112 dirt
setblock ~22 ~116 ~113 dirt
setblock ~22 ~116 ~114 dirt
setblock ~22 ~116 ~115 dirt
setblock ~22 ~116 ~116 dirt
setblock ~22 ~116 ~117 dirt
setblock ~22 ~116 ~118 dirt
setblock ~22 ~116 ~119 dirt
setblock ~22 ~117 ~53 dirt
setblock ~22 ~117 ~54 dirt
setblock ~22 ~117 ~55 dirt
setblock ~22 ~117 ~56 dirt
setblock ~22 ~117 ~57 dirt
setblock ~22 ~117 ~58 dirt
setblock ~22 ~117 ~96 dirt
setblock ~22 ~117 ~97 dirt
setblock ~22 ~117 ~98 dirt
setblock ~22 ~117 ~99 dirt
setblock ~22 ~117 ~100 dirt
setblock ~22 ~117 ~101 dirt
setblock ~22 ~117 ~102 dirt
setblock ~22 ~117 ~103 dirt
setblock ~22 ~117 ~104 dirt
setblock ~22 ~117 ~105 dirt
setblock ~22 ~117 ~106 dirt
setblock ~22 ~117 ~107 dirt
setblock ~22 ~117 ~108 dirt
setblock ~22 ~117 ~109 dirt
setblock ~22 ~117 ~110 dirt
setblock ~22 ~117 ~111 dirt
setblock ~22 ~117 ~112 dirt
setblock ~22 ~117 ~113 dirt
setblock ~22 ~117 ~114 dirt
setblock ~22 ~117 ~115 dirt
setblock ~22 ~117 ~116 dirt
setblock ~22 ~117 ~117 dirt
setblock ~22 ~117 ~118 dirt
setblock ~22 ~117 ~119 dirt
setblock ~22 ~117 ~120 dirt
setblock ~22 ~118 ~52 dirt
setblock ~22 ~118 ~53 dirt
setblock ~22 ~118 ~54 dirt
setblock ~22 ~118 ~55 dirt
setblock ~22 ~118 ~56 dirt
setblock ~22 ~118 ~57 dirt
setblock ~22 ~118 ~58 dirt
setblock ~22 ~118 ~59 dirt
setblock ~22 ~118 ~60 dirt
setblock ~22 ~118 ~96 dirt
setblock ~22 ~118 ~97 dirt
setblock ~22 ~118 ~98 dirt
setblock ~22 ~118 ~99 dirt
setblock ~22 ~118 ~100 dirt
setblock ~22 ~118 ~101 dirt
setblock ~22 ~118 ~102 dirt
setblock ~22 ~118 ~103 dirt
setblock ~22 ~118 ~104 dirt
setblock ~22 ~118 ~105 dirt
setblock ~22 ~118 ~106 dirt
setblock ~22 ~118 ~107 dirt
setblock ~22 ~118 ~108 dirt
setblock ~22 ~118 ~109 dirt
setblock ~22 ~118 ~110 dirt
setblock ~22 ~118 ~111 dirt
setblock ~22 ~118 ~112 dirt
setblock ~22 ~118 ~113 dirt
setblock ~22 ~118 ~114 dirt
setblock ~22 ~118 ~115 dirt
setblock ~22 ~118 ~116 dirt
setblock ~22 ~118 ~117 dirt
setblock ~22 ~118 ~118 dirt
setblock ~22 ~118 ~119 dirt
setblock ~22 ~118 ~120 dirt
setblock ~22 ~119 ~52 dirt
setblock ~22 ~119 ~53 dirt
setblock ~22 ~119 ~54 dirt
setblock ~22 ~119 ~55 dirt
setblock ~22 ~119 ~56 dirt
setblock ~22 ~119 ~57 dirt
setblock ~22 ~119 ~58 dirt
setblock ~22 ~119 ~59 dirt
setblock ~22 ~119 ~60 dirt
setblock ~22 ~119 ~61 dirt
setblock ~22 ~119 ~63 dirt
setblock ~22 ~119 ~95 dirt
setblock ~22 ~119 ~96 dirt
setblock ~22 ~119 ~97 dirt
setblock ~22 ~119 ~98 dirt
setblock ~22 ~119 ~99 dirt
setblock ~22 ~119 ~100 dirt
setblock ~22 ~119 ~101 dirt
setblock ~22 ~119 ~102 dirt
setblock ~22 ~119 ~103 dirt
setblock ~22 ~119 ~104 dirt
setblock ~22 ~119 ~105 dirt
setblock ~22 ~119 ~106 dirt
setblock ~22 ~119 ~107 dirt
setblock ~22 ~119 ~108 dirt
setblock ~22 ~119 ~109 dirt
setblock ~22 ~119 ~110 dirt
setblock ~22 ~119 ~111 dirt
setblock ~22 ~119 ~112 dirt
setblock ~22 ~119 ~113 dirt
setblock ~22 ~119 ~114 dirt
setblock ~22 ~119 ~115 dirt
setblock ~22 ~119 ~116 dirt
setblock ~22 ~119 ~117 dirt
setblock ~22 ~119 ~118 dirt
setblock ~22 ~119 ~119 dirt
setblock ~22 ~119 ~120 dirt
setblock ~22 ~119 ~121 dirt
setblock ~22 ~120 ~52 dirt
setblock ~22 ~120 ~53 dirt
setblock ~22 ~120 ~54 dirt
setblock ~22 ~120 ~55 dirt
setblock ~22 ~120 ~56 dirt
setblock ~22 ~120 ~57 dirt
setblock ~22 ~120 ~58 dirt
setblock ~22 ~120 ~59 dirt
setblock ~22 ~120 ~60 dirt
setblock ~22 ~120 ~61 dirt
setblock ~22 ~120 ~62 dirt
setblock ~22 ~120 ~63 dirt
setblock ~22 ~120 ~94 dirt
setblock ~22 ~120 ~95 dirt
setblock ~22 ~120 ~96 dirt
setblock ~22 ~120 ~97 dirt
setblock ~22 ~120 ~98 dirt
setblock ~22 ~120 ~99 dirt
setblock ~22 ~120 ~100 dirt
setblock ~22 ~120 ~101 dirt
setblock ~22 ~120 ~102 dirt
setblock ~22 ~120 ~103 dirt
setblock ~22 ~120 ~104 dirt
setblock ~22 ~120 ~105 dirt
setblock ~22 ~120 ~106 dirt
setblock ~22 ~120 ~107 dirt
setblock ~22 ~120 ~108 dirt
setblock ~22 ~120 ~109 dirt
setblock ~22 ~120 ~110 dirt
setblock ~22 ~120 ~111 dirt
setblock ~22 ~120 ~112 dirt
setblock ~22 ~120 ~113 dirt
setblock ~22 ~120 ~114 dirt
setblock ~22 ~120 ~115 dirt
setblock ~22 ~120 ~116 dirt
setblock ~22 ~120 ~117 dirt
setblock ~22 ~120 ~118 dirt
setblock ~22 ~120 ~119 dirt
setblock ~22 ~120 ~120 dirt
setblock ~22 ~120 ~121 dirt
setblock ~22 ~120 ~122 dirt
setblock ~22 ~121 ~51 dirt
setblock ~22 ~121 ~52 dirt
setblock ~22 ~121 ~53 dirt
setblock ~22 ~121 ~54 dirt
setblock ~22 ~121 ~55 dirt
setblock ~22 ~121 ~56 dirt
setblock ~22 ~121 ~57 dirt
setblock ~22 ~121 ~58 dirt
setblock ~22 ~121 ~59 dirt
setblock ~22 ~121 ~60 dirt
setblock ~22 ~121 ~61 dirt
setblock ~22 ~121 ~62 dirt
setblock ~22 ~121 ~63 dirt
setblock ~22 ~121 ~64 dirt
setblock ~22 ~121 ~65 dirt
setblock ~22 ~121 ~93 dirt
setblock ~22 ~121 ~94 dirt
setblock ~22 ~121 ~95 dirt
setblock ~22 ~121 ~96 dirt
setblock ~22 ~121 ~97 dirt
setblock ~22 ~121 ~98 dirt
setblock ~22 ~121 ~99 dirt
setblock ~22 ~121 ~100 dirt
setblock ~22 ~121 ~101 dirt
setblock ~22 ~121 ~102 dirt
setblock ~22 ~121 ~103 dirt
setblock ~22 ~121 ~104 dirt
setblock ~22 ~121 ~105 dirt
setblock ~22 ~121 ~106 dirt
setblock ~22 ~121 ~107 dirt
setblock ~22 ~121 ~108 dirt
setblock ~22 ~121 ~109 dirt
setblock ~22 ~121 ~110 dirt
setblock ~22 ~121 ~111 dirt
setblock ~22 ~121 ~112 dirt
setblock ~22 ~121 ~113 dirt
setblock ~22 ~121 ~114 dirt
setblock ~22 ~121 ~115 dirt
setblock ~22 ~121 ~116 dirt
setblock ~22 ~121 ~117 dirt
setblock ~22 ~121 ~118 dirt
setblock ~22 ~121 ~119 dirt
setblock ~22 ~121 ~120 dirt
setblock ~22 ~121 ~121 dirt
setblock ~22 ~121 ~122 dirt
setblock ~22 ~121 ~123 dirt
setblock ~22 ~122 ~51 dirt
setblock ~22 ~122 ~52 dirt
setblock ~22 ~122 ~53 dirt
setblock ~22 ~122 ~54 dirt
setblock ~22 ~122 ~55 dirt
setblock ~22 ~122 ~56 dirt
setblock ~22 ~122 ~57 dirt
setblock ~22 ~122 ~58 dirt
setblock ~22 ~122 ~59 dirt
setblock ~22 ~122 ~60 dirt
setblock ~22 ~122 ~61 dirt
setblock ~22 ~122 ~62 dirt
setblock ~22 ~122 ~63 dirt
setblock ~22 ~122 ~64 dirt
setblock ~22 ~122 ~65 dirt
setblock ~22 ~122 ~93 dirt
setblock ~22 ~122 ~94 dirt
setblock ~22 ~122 ~95 dirt
setblock ~22 ~122 ~96 dirt
setblock ~22 ~122 ~97 dirt
setblock ~22 ~122 ~98 dirt
setblock ~22 ~122 ~99 dirt
setblock ~22 ~122 ~100 dirt
setblock ~22 ~122 ~101 dirt
setblock ~22 ~122 ~102 dirt
setblock ~22 ~122 ~103 dirt
setblock ~22 ~122 ~104 dirt
setblock ~22 ~122 ~105 dirt
setblock ~22 ~122 ~106 dirt
setblock ~22 ~122 ~107 dirt
setblock ~22 ~122 ~108 dirt
setblock ~22 ~122 ~109 dirt
setblock ~22 ~122 ~110 dirt
setblock ~22 ~122 ~111 dirt
setblock ~22 ~122 ~112 dirt
setblock ~22 ~122 ~113 dirt
setblock ~22 ~122 ~114 dirt
setblock ~22 ~122 ~115 dirt
setblock ~22 ~122 ~116 dirt
setblock ~22 ~122 ~117 dirt
setblock ~22 ~122 ~118 dirt
setblock ~22 ~122 ~119 dirt
setblock ~22 ~122 ~120 dirt
setblock ~22 ~122 ~121 dirt
setblock ~22 ~122 ~122 dirt
setblock ~22 ~122 ~123 dirt
setblock ~22 ~123 ~51 dirt
setblock ~22 ~123 ~52 dirt
setblock ~22 ~123 ~53 dirt
setblock ~22 ~123 ~54 dirt
setblock ~22 ~123 ~55 dirt
setblock ~22 ~123 ~56 dirt
setblock ~22 ~123 ~57 dirt
setblock ~22 ~123 ~58 dirt
setblock ~22 ~123 ~59 dirt
setblock ~22 ~123 ~60 grass_block
setblock ~22 ~123 ~61 dirt
setblock ~22 ~123 ~62 dirt
setblock ~22 ~123 ~63 dirt
setblock ~22 ~123 ~64 dirt
setblock ~22 ~123 ~65 dirt
setblock ~22 ~123 ~93 dirt
setblock ~22 ~123 ~94 dirt
setblock ~22 ~123 ~95 dirt
setblock ~22 ~123 ~96 dirt
setblock ~22 ~123 ~97 dirt
setblock ~22 ~123 ~98 dirt
setblock ~22 ~123 ~99 dirt
setblock ~22 ~123 ~100 dirt
setblock ~22 ~123 ~101 dirt
setblock ~22 ~123 ~102 dirt
setblock ~22 ~123 ~103 dirt
setblock ~22 ~123 ~104 dirt
setblock ~22 ~123 ~105 dirt
setblock ~22 ~123 ~106 dirt
setblock ~22 ~123 ~107 dirt
setblock ~22 ~123 ~108 dirt
setblock ~22 ~123 ~109 dirt
setblock ~22 ~123 ~110 dirt
setblock ~22 ~123 ~111 dirt
setblock ~22 ~123 ~112 dirt
setblock ~22 ~123 ~113 dirt
setblock ~22 ~123 ~114 dirt
setblock ~22 ~123 ~115 dirt
setblock ~22 ~123 ~116 dirt
setblock ~22 ~123 ~117 dirt
setblock ~22 ~123 ~118 grass_block
setblock ~22 ~123 ~119 grass_block
setblock ~22 ~123 ~120 grass_block
setblock ~22 ~123 ~121 grass_block
setblock ~22 ~123 ~122 grass_block
setblock ~22 ~123 ~123 grass_block
setblock ~22 ~124 ~51 dirt
setblock ~22 ~124 ~52 dirt
setblock ~22 ~124 ~53 dirt
setblock ~22 ~124 ~54 dirt
setblock ~22 ~124 ~55 grass_block
setblock ~22 ~124 ~56 grass_block
setblock ~22 ~124 ~57 grass_block
setblock ~22 ~124 ~58 grass_block
setblock ~22 ~124 ~59 grass_block
setblock ~22 ~124 ~60 short_grass
setblock ~22 ~124 ~61 grass_block
setblock ~22 ~124 ~62 grass_block
setblock ~22 ~124 ~63 grass_block
setblock ~22 ~124 ~64 grass_block
setblock ~22 ~124 ~65 grass_block
setblock ~22 ~124 ~93 dirt
setblock ~22 ~124 ~94 dirt
setblock ~22 ~124 ~95 dirt
setblock ~22 ~124 ~96 dirt
setblock ~22 ~124 ~97 dirt
setblock ~22 ~124 ~98 dirt
setblock ~22 ~124 ~99 dirt
setblock ~22 ~124 ~100 grass_block
setblock ~22 ~124 ~101 dirt
setblock ~22 ~124 ~102 dirt
setblock ~22 ~124 ~103 dirt
setblock ~22 ~124 ~104 dirt
setblock ~22 ~124 ~105 dirt
setblock ~22 ~124 ~106 dirt
setblock ~22 ~124 ~107 dirt
setblock ~22 ~124 ~108 dirt
setblock ~22 ~124 ~109 dirt
setblock ~22 ~124 ~110 dirt
setblock ~22 ~124 ~111 dirt
setblock ~22 ~124 ~112 dirt
setblock ~22 ~124 ~113 dirt
setblock ~22 ~124 ~114 dirt
setblock ~22 ~124 ~115 grass_block
setblock ~22 ~124 ~116 grass_block
setblock ~22 ~124 ~117 grass_block
setblock ~22 ~124 ~118 short_grass
setblock ~22 ~125 ~51 grass_block
setblock ~22 ~125 ~52 grass_block
setblock ~22 ~125 ~53 grass_block
setblock ~22 ~125 ~54 grass_block
setblock ~22 ~125 ~55 short_grass
setblock ~22 ~125 ~56 short_grass
setblock ~22 ~125 ~62 short_grass
setblock ~22 ~125 ~64 short_grass
setblock ~22 ~125 ~93 dirt
setblock ~22 ~125 ~94 grass_block
setblock ~22 ~125 ~95 grass_block
setblock ~22 ~125 ~96 grass_block
setblock ~22 ~125 ~97 grass_block
setblock ~22 ~125 ~98 grass_block
setblock ~22 ~125 ~99 grass_block
setblock ~22 ~125 ~100 short_grass
setblock ~22 ~125 ~101 grass_block
setblock ~22 ~125 ~102 grass_block
setblock ~22 ~125 ~103 grass_block
setblock ~22 ~125 ~104 grass_block
setblock ~22 ~125 ~105 dirt
setblock ~22 ~125 ~106 dirt
setblock ~22 ~125 ~107 dirt
setblock ~22 ~125 ~108 dirt
setblock ~22 ~125 ~109 dirt
setblock ~22 ~125 ~110 dirt
setblock ~22 ~125 ~111 dirt
setblock ~22 ~125 ~112 dirt
setblock ~22 ~125 ~113 grass_block
setblock ~22 ~125 ~114 grass_block
setblock ~22 ~126 ~53 fern
setblock ~22 ~126 ~93 grass_block
setblock ~22 ~126 ~95 short_grass
setblock ~22 ~126 ~99 short_grass
setblock ~22 ~126 ~101 poppy
setblock ~22 ~126 ~102 poppy
setblock ~22 ~126 ~103 fern
setblock ~22 ~126 ~104 short_grass
setblock ~22 ~126 ~105 grass_block
setblock ~22 ~126 ~106 grass_block
setblock ~22 ~126 ~107 grass_block
setblock ~22 ~126 ~108 grass_block
setblock ~22 ~126 ~109 dirt
setblock ~22 ~126 ~110 dirt
setblock ~22 ~126 ~111 grass_block
setblock ~22 ~126 ~112 grass_block
setblock ~22 ~126 ~114 short_grass
setblock ~22 ~127 ~108 fern
setblock ~22 ~127 ~109 grass_block
setblock ~22 ~127 ~110 grass_block
setblock ~23 ~104 ~108 dirt
setblock ~23 ~105 ~106 dirt
setblock ~23 ~105 ~107 dirt
setblock ~23 ~105 ~108 dirt
setblock ~23 ~105 ~109 dirt
setblock ~23 ~105 ~110 dirt
setblock ~23 ~106 ~105 dirt
setblock ~23 ~106 ~106 dirt
setblock ~23 ~106 ~107 dirt
setblock ~23 ~106 ~108 dirt
setblock ~23 ~106 ~109 dirt
setblock ~23 ~106 ~110 dirt
setblock ~23 ~107 ~105 dirt
setblock ~23 ~107 ~106 dirt
setblock ~23 ~107 ~107 dirt
setblock ~23 ~107 ~108 dirt
setblock ~23 ~107 ~109 dirt
setblock ~23 ~107 ~110 dirt
setblock ~23 ~107 ~111 dirt
setblock ~23 ~108 ~104 dirt
setblock ~23 ~108 ~105 dirt
setblock ~23 ~108 ~106 dirt
setblock ~23 ~108 ~107 dirt
setblock ~23 ~108 ~108 dirt
setblock ~23 ~108 ~109 dirt
setblock ~23 ~108 ~110 dirt
setblock ~23 ~108 ~111 dirt
setblock ~23 ~108 ~112 dirt
setblock ~23 ~109 ~103 dirt
setblock ~23 ~109 ~104 dirt
setblock ~23 ~109 ~105 dirt
setblock ~23 ~109 ~106 dirt
setblock ~23 ~109 ~107 dirt
setblock ~23 ~109 ~108 dirt
setblock ~23 ~109 ~109 dirt
setblock ~23 ~109 ~110 dirt
setblock ~23 ~109 ~111 dirt
setblock ~23 ~109 ~112 dirt
setblock ~23 ~109 ~113 dirt
setblock ~23 ~110 ~102 dirt
setblock ~23 ~110 ~103 dirt
setblock ~23 ~110 ~104 dirt
setblock ~23 ~110 ~105 dirt
setblock ~23 ~110 ~106 dirt
setblock ~23 ~110 ~107 dirt
setblock ~23 ~110 ~108 dirt
setblock ~23 ~110 ~109 dirt
setblock ~23 ~110 ~110 dirt
setblock ~23 ~110 ~111 dirt
setblock ~23 ~110 ~112 dirt
setblock ~23 ~110 ~113 dirt
setblock ~23 ~110 ~114 dirt
setblock ~23 ~111 ~55 dirt
setblock ~23 ~111 ~101 dirt
setblock ~23 ~111 ~102 dirt
setblock ~23 ~111 ~103 dirt
setblock ~23 ~111 ~104 dirt
setblock ~23 ~111 ~105 dirt
setblock ~23 ~111 ~106 dirt
setblock ~23 ~111 ~107 dirt
setblock ~23 ~111 ~108 dirt
setblock ~23 ~111 ~109 dirt
setblock ~23 ~111 ~110 dirt
setblock ~23 ~111 ~111 dirt
setblock ~23 ~111 ~112 dirt
setblock ~23 ~111 ~113 dirt
setblock ~23 ~111 ~114 dirt
setblock ~23 ~111 ~115 dirt
setblock ~23 ~112 ~54 dirt
setblock ~23 ~112 ~55 dirt
setblock ~23 ~112 ~56 dirt
setblock ~23 ~112 ~100 dirt
setblock ~23 ~112 ~101 dirt
setblock ~23 ~112 ~102 dirt
setblock ~23 ~112 ~103 dirt
setblock ~23 ~112 ~104 dirt
setblock ~23 ~112 ~105 dirt
setblock ~23 ~112 ~106 dirt
setblock ~23 ~112 ~107 dirt
setblock ~23 ~112 ~108 dirt
setblock ~23 ~112 ~109 dirt
setblock ~23 ~112 ~110 dirt
setblock ~23 ~112 ~111 dirt
setblock ~23 ~112 ~112 dirt
setblock ~23 ~112 ~113 dirt
setblock ~23 ~112 ~114 dirt
setblock ~23 ~112 ~115 dirt
setblock ~23 ~112 ~116 dirt
setblock ~23 ~113 ~54 dirt
setblock ~23 ~113 ~55 dirt
setblock ~23 ~113 ~56 dirt
setblock ~23 ~113 ~57 dirt
setblock ~23 ~113 ~99 dirt
setblock ~23 ~113 ~100 dirt
setblock ~23 ~113 ~101 dirt
setblock ~23 ~113 ~102 dirt
setblock ~23 ~113 ~103 dirt
setblock ~23 ~113 ~104 dirt
setblock ~23 ~113 ~105 dirt
setblock ~23 ~113 ~106 dirt
setblock ~23 ~113 ~107 dirt
setblock ~23 ~113 ~108 dirt
setblock ~23 ~113 ~109 dirt
setblock ~23 ~113 ~110 dirt
setblock ~23 ~113 ~111 dirt
setblock ~23 ~113 ~112 dirt
setblock ~23 ~113 ~113 dirt
setblock ~23 ~113 ~114 dirt
setblock ~23 ~113 ~115 dirt
setblock ~23 ~113 ~116 dirt
setblock ~23 ~113 ~117 dirt
setblock ~23 ~114 ~53 dirt
setblock ~23 ~114 ~54 dirt
setblock ~23 ~114 ~55 dirt
setblock ~23 ~114 ~56 dirt
setblock ~23 ~114 ~57 dirt
setblock ~23 ~114 ~98 dirt
setblock ~23 ~114 ~99 dirt
setblock ~23 ~114 ~100 dirt
setblock ~23 ~114 ~101 dirt
setblock ~23 ~114 ~102 dirt
setblock ~23 ~114 ~103 dirt
setblock ~23 ~114 ~104 dirt
setblock ~23 ~114 ~105 dirt
setblock ~23 ~114 ~106 dirt
setblock ~23 ~114 ~107 dirt
setblock ~23 ~114 ~108 dirt
setblock ~23 ~114 ~109 dirt
setblock ~23 ~114 ~110 dirt
setblock ~23 ~114 ~111 dirt
setblock ~23 ~114 ~112 dirt
setblock ~23 ~114 ~113 dirt
setblock ~23 ~114 ~114 dirt
setblock ~23 ~114 ~115 dirt
setblock ~23 ~114 ~116 dirt
setblock ~23 ~114 ~117 dirt
setblock ~23 ~115 ~53 dirt
setblock ~23 ~115 ~54 dirt
setblock ~23 ~115 ~55 dirt
setblock ~23 ~115 ~56 dirt
setblock ~23 ~115 ~57 dirt
setblock ~23 ~115 ~98 dirt
setblock ~23 ~115 ~99 dirt
setblock ~23 ~115 ~100 dirt
setblock ~23 ~115 ~101 dirt
setblock ~23 ~115 ~102 dirt
setblock ~23 ~115 ~103 dirt
setblock ~23 ~115 ~104 dirt
setblock ~23 ~115 ~105 dirt
setblock ~23 ~115 ~106 dirt
setblock ~23 ~115 ~107 dirt
setblock ~23 ~115 ~108 dirt
setblock ~23 ~115 ~109 dirt
setblock ~23 ~115 ~110 dirt
setblock ~23 ~115 ~111 dirt
setblock ~23 ~115 ~112 dirt
setblock ~23 ~115 ~113 dirt
setblock ~23 ~115 ~114 dirt
setblock ~23 ~115 ~115 dirt
setblock ~23 ~115 ~116 dirt
setblock ~23 ~115 ~117 dirt
setblock ~23 ~115 ~118 dirt
setblock ~23 ~116 ~53 dirt
setblock ~23 ~116 ~54 dirt
setblock ~23 ~116 ~55 dirt
setblock ~23 ~116 ~56 dirt
setblock ~23 ~116 ~57 dirt
setblock ~23 ~116 ~58 dirt
setblock ~23 ~116 ~59 dirt
setblock ~23 ~116 ~97 dirt
setblock ~23 ~116 ~98 dirt
setblock ~23 ~116 ~99 dirt
setblock ~23 ~116 ~100 dirt
setblock ~23 ~116 ~101 dirt
setblock ~23 ~116 ~102 dirt
setblock ~23 ~116 ~103 dirt
setblock ~23 ~116 ~104 dirt
setblock ~23 ~116 ~105 dirt
setblock ~23 ~116 ~106 dirt
setblock ~23 ~116 ~107 dirt
setblock ~23 ~116 ~108 dirt
setblock ~23 ~116 ~109 dirt
setblock ~23 ~116 ~110 dirt
setblock ~23 ~116 ~111 dirt
setblock ~23 ~116 ~112 dirt
setblock ~23 ~116 ~113 dirt
setblock ~23 ~116 ~114 dirt
setblock ~23 ~116 ~115 dirt
setblock ~23 ~116 ~116 dirt
setblock ~23 ~116 ~117 dirt
setblock ~23 ~116 ~118 dirt
setblock ~23 ~117 ~53 dirt
setblock ~23 ~117 ~54 dirt
setblock ~23 ~117 ~55 dirt
setblock ~23 ~117 ~56 dirt
setblock ~23 ~117 ~57 dirt
setblock ~23 ~117 ~58 dirt
setblock ~23 ~117 ~59 dirt
setblock ~23 ~117 ~60 dirt
setblock ~23 ~117 ~61 dirt
setblock ~23 ~117 ~96 dirt
setblock ~23 ~117 ~97 dirt
setblock ~23 ~117 ~98 dirt
setblock ~23 ~117 ~99 dirt
setblock ~23 ~117 ~100 dirt
setblock ~23 ~117 ~101 dirt
setblock ~23 ~117 ~102 dirt
setblock ~23 ~117 ~103 dirt
setblock ~23 ~117 ~104 dirt
setblock ~23 ~117 ~105 dirt
setblock ~23 ~117 ~106 dirt
setblock ~23 ~117 ~107 dirt
setblock ~23 ~117 ~108 dirt
setblock ~23 ~117 ~109 dirt
setblock ~23 ~117 ~110 dirt
setblock ~23 ~117 ~111 dirt
setblock ~23 ~117 ~112 dirt
setblock ~23 ~117 ~113 dirt
setblock ~23 ~117 ~114 dirt
setblock ~23 ~117 ~115 dirt
setblock ~23 ~117 ~116 dirt
setblock ~23 ~117 ~117 dirt
setblock ~23 ~117 ~118 dirt
setblock ~23 ~117 ~119 dirt
setblock ~23 ~118 ~52 dirt
setblock ~23 ~118 ~53 dirt
setblock ~23 ~118 ~54 dirt
setblock ~23 ~118 ~55 dirt
setblock ~23 ~118 ~56 dirt
setblock ~23 ~118 ~57 dirt
setblock ~23 ~118 ~58 dirt
setblock ~23 ~118 ~59 dirt
setblock ~23 ~118 ~60 dirt
setblock ~23 ~118 ~61 dirt
setblock ~23 ~118 ~62 dirt
setblock ~23 ~118 ~63 dirt
setblock ~23 ~118 ~95 dirt
setblock ~23 ~118 ~96 dirt
setblock ~23 ~118 ~97 dirt
setblock ~23 ~118 ~98 dirt
setblock ~23 ~118 ~99 dirt
setblock ~23 ~118 ~100 dirt
setblock ~23 ~118 ~101 dirt
setblock ~23 ~118 ~102 dirt
setblock ~23 ~118 ~103 dirt
setblock ~23 ~118 ~104 dirt
setblock ~23 ~118 ~105 dirt
setblock ~23 ~118 ~106 dirt
setblock ~23 ~118 ~107 dirt
setblock ~23 ~118 ~108 dirt
setblock ~23 ~118 ~109 dirt
setblock ~23 ~118 ~110 dirt
setblock ~23 ~118 ~111 dirt
setblock ~23 ~118 ~112 dirt
setblock ~23 ~118 ~113 dirt
setblock ~23 ~118 ~114 dirt
setblock ~23 ~118 ~115 dirt
setblock ~23 ~118 ~116 dirt
setblock ~23 ~118 ~117 dirt
setblock ~23 ~118 ~118 dirt
setblock ~23 ~118 ~119 dirt
setblock ~23 ~118 ~120 dirt
setblock ~23 ~119 ~51 dirt
setblock ~23 ~119 ~52 dirt
setblock ~23 ~119 ~53 dirt
setblock ~23 ~119 ~54 dirt
setblock ~23 ~119 ~55 dirt
setblock ~23 ~119 ~56 dirt
setblock ~23 ~119 ~57 dirt
setblock ~23 ~119 ~58 dirt
setblock ~23 ~119 ~59 dirt
setblock ~23 ~119 ~60 dirt
setblock ~23 ~119 ~61 dirt
setblock ~23 ~119 ~62 dirt
setblock ~23 ~119 ~63 dirt
setblock ~23 ~119 ~64 dirt
setblock ~23 ~119 ~94 dirt
setblock ~23 ~119 ~95 dirt
setblock ~23 ~119 ~96 dirt
setblock ~23 ~119 ~97 dirt
setblock ~23 ~119 ~98 dirt
setblock ~23 ~119 ~99 dirt
setblock ~23 ~119 ~100 dirt
setblock ~23 ~119 ~101 dirt
setblock ~23 ~119 ~102 dirt
setblock ~23 ~119 ~103 dirt
setblock ~23 ~119 ~104 dirt
setblock ~23 ~119 ~105 dirt
setblock ~23 ~119 ~106 dirt
setblock ~23 ~119 ~107 dirt
setblock ~23 ~119 ~108 dirt
setblock ~23 ~119 ~109 dirt
setblock ~23 ~119 ~110 dirt
setblock ~23 ~119 ~111 dirt
setblock ~23 ~119 ~112 dirt
setblock ~23 ~119 ~113 dirt
setblock ~23 ~119 ~114 dirt
setblock ~23 ~119 ~115 dirt
setblock ~23 ~119 ~116 dirt
setblock ~23 ~119 ~117 dirt
setblock ~23 ~119 ~118 dirt
setblock ~23 ~119 ~119 dirt
setblock ~23 ~119 ~120 dirt
setblock ~23 ~119 ~121 dirt
setblock ~23 ~120 ~51 dirt
setblock ~23 ~120 ~52 dirt
setblock ~23 ~120 ~53 dirt
setblock ~23 ~120 ~54 dirt
setblock ~23 ~120 ~55 dirt
setblock ~23 ~120 ~56 dirt
setblock ~23 ~120 ~57 dirt
setblock ~23 ~120 ~58 dirt
setblock ~23 ~120 ~59 dirt
setblock ~23 ~120 ~60 dirt
setblock ~23 ~120 ~61 dirt
setblock ~23 ~120 ~62 dirt
setblock ~23 ~120 ~63 dirt
setblock ~23 ~120 ~64 dirt
setblock ~23 ~120 ~65 dirt
setblock ~23 ~120 ~93 dirt
setblock ~23 ~120 ~94 dirt
setblock ~23 ~120 ~95 dirt
setblock ~23 ~120 ~96 dirt
setblock ~23 ~120 ~97 dirt
setblock ~23 ~120 ~98 dirt
setblock ~23 ~120 ~99 dirt
setblock ~23 ~120 ~100 dirt
setblock ~23 ~120 ~101 dirt
setblock ~23 ~120 ~102 dirt
setblock ~23 ~120 ~103 dirt
setblock ~23 ~120 ~104 dirt
setblock ~23 ~120 ~105 dirt
setblock ~23 ~120 ~106 dirt
setblock ~23 ~120 ~107 dirt
setblock ~23 ~120 ~108 dirt
setblock ~23 ~120 ~109 dirt
setblock ~23 ~120 ~110 dirt
setblock ~23 ~120 ~111 dirt
setblock ~23 ~120 ~112 dirt
setblock ~23 ~120 ~113 dirt
setblock ~23 ~120 ~114 dirt
setblock ~23 ~120 ~115 dirt
setblock ~23 ~120 ~116 dirt
setblock ~23 ~120 ~117 dirt
setblock ~23 ~120 ~118 dirt
setblock ~23 ~120 ~119 dirt
setblock ~23 ~120 ~120 dirt
setblock ~23 ~120 ~121 dirt
setblock ~23 ~120 ~122 dirt
setblock ~23 ~121 ~51 dirt
setblock ~23 ~121 ~52 dirt
setblock ~23 ~121 ~53 dirt
setblock ~23 ~121 ~54 dirt
setblock ~23 ~121 ~55 dirt
setblock ~23 ~121 ~56 dirt
setblock ~23 ~121 ~57 dirt
setblock ~23 ~121 ~58 dirt
setblock ~23 ~121 ~59 dirt
setblock ~23 ~121 ~60 dirt
setblock ~23 ~121 ~61 dirt
setblock ~23 ~121 ~62 dirt
setblock ~23 ~121 ~63 dirt
setblock ~23 ~121 ~64 dirt
setblock ~23 ~121 ~65 dirt
setblock ~23 ~121 ~66 dirt
setblock ~23 ~121 ~92 dirt
setblock ~23 ~121 ~93 dirt
setblock ~23 ~121 ~94 dirt
setblock ~23 ~121 ~95 dirt
setblock ~23 ~121 ~96 dirt
setblock ~23 ~121 ~97 dirt
setblock ~23 ~121 ~98 dirt
setblock ~23 ~121 ~99 dirt
setblock ~23 ~121 ~100 dirt
setblock ~23 ~121 ~101 dirt
setblock ~23 ~121 ~102 dirt
setblock ~23 ~121 ~103 dirt
setblock ~23 ~121 ~104 dirt
setblock ~23 ~121 ~105 dirt
setblock ~23 ~121 ~106 dirt
setblock ~23 ~121 ~107 dirt
setblock ~23 ~121 ~108 dirt
setblock ~23 ~121 ~109 dirt
setblock ~23 ~121 ~110 dirt
setblock ~23 ~121 ~111 dirt
setblock ~23 ~121 ~112 dirt
setblock ~23 ~121 ~113 dirt
setblock ~23 ~121 ~114 dirt
setblock ~23 ~121 ~115 dirt
setblock ~23 ~121 ~116 dirt
setblock ~23 ~121 ~117 dirt
setblock ~23 ~121 ~118 dirt
setblock ~23 ~121 ~119 dirt
setblock ~23 ~121 ~120 dirt
setblock ~23 ~121 ~121 dirt
setblock ~23 ~121 ~122 dirt
setblock ~23 ~121 ~123 dirt
setblock ~23 ~122 ~51 dirt
setblock ~23 ~122 ~52 dirt
setblock ~23 ~122 ~53 dirt
setblock ~23 ~122 ~54 dirt
setblock ~23 ~122 ~55 dirt
setblock ~23 ~122 ~56 dirt
setblock ~23 ~122 ~57 dirt
setblock ~23 ~122 ~58 dirt
setblock ~23 ~122 ~59 dirt
setblock ~23 ~122 ~60 dirt
setblock ~23 ~122 ~61 dirt
setblock ~23 ~122 ~62 dirt
setblock ~23 ~122 ~63 dirt
setblock ~23 ~122 ~64 dirt
setblock ~23 ~122 ~65 dirt
setblock ~23 ~122 ~66 dirt
setblock ~23 ~122 ~92 dirt
setblock ~23 ~122 ~93 dirt
setblock ~23 ~122 ~94 dirt
setblock ~23 ~122 ~95 dirt
setblock ~23 ~122 ~96 dirt
setblock ~23 ~122 ~97 dirt
setblock ~23 ~122 ~98 dirt
setblock ~23 ~122 ~99 dirt
setblock ~23 ~122 ~100 dirt
setblock ~23 ~122 ~101 dirt
setblock ~23 ~122 ~102 dirt
setblock ~23 ~122 ~103 dirt
setblock ~23 ~122 ~104 dirt
setblock ~23 ~122 ~105 dirt
setblock ~23 ~122 ~106 dirt
setblock ~23 ~122 ~107 dirt
setblock ~23 ~122 ~108 dirt
setblock ~23 ~122 ~109 dirt
setblock ~23 ~122 ~110 dirt
setblock ~23 ~122 ~111 dirt
setblock ~23 ~122 ~112 dirt
setblock ~23 ~122 ~113 dirt
setblock ~23 ~122 ~114 dirt
setblock ~23 ~122 ~115 dirt
setblock ~23 ~122 ~116 dirt
setblock ~23 ~122 ~117 dirt
setblock ~23 ~122 ~118 dirt
setblock ~23 ~122 ~119 dirt
setblock ~23 ~122 ~120 dirt
setblock ~23 ~122 ~121 dirt
setblock ~23 ~122 ~122 dirt
setblock ~23 ~122 ~123 dirt
setblock ~23 ~123 ~51 dirt
setblock ~23 ~123 ~52 dirt
setblock ~23 ~123 ~53 dirt
setblock ~23 ~123 ~54 dirt
setblock ~23 ~123 ~55 dirt
setblock ~23 ~123 ~56 dirt
setblock ~23 ~123 ~57 dirt
setblock ~23 ~123 ~58 dirt
setblock ~23 ~123 ~59 dirt
setblock ~23 ~123 ~60 dirt
setblock ~23 ~123 ~61 dirt
setblock ~23 ~123 ~62 dirt
setblock ~23 ~123 ~63 dirt
setblock ~23 ~123 ~64 dirt
setblock ~23 ~123 ~65 dirt
setblock ~23 ~123 ~66 dirt
setblock ~23 ~123 ~92 dirt
setblock ~23 ~123 ~93 dirt
setblock ~23 ~123 ~94 dirt
setblock ~23 ~123 ~95 dirt
setblock ~23 ~123 ~96 dirt
setblock ~23 ~123 ~97 dirt
setblock ~23 ~123 ~98 dirt
setblock ~23 ~123 ~99 dirt
setblock ~23 ~123 ~100 dirt
setblock ~23 ~123 ~101 dirt
setblock ~23 ~123 ~102 dirt
setblock ~23 ~123 ~103 dirt
setblock ~23 ~123 ~104 dirt
setblock ~23 ~123 ~105 dirt
setblock ~23 ~123 ~106 dirt
setblock ~23 ~123 ~107 dirt
setblock ~23 ~123 ~108 dirt
setblock ~23 ~123 ~109 dirt
setblock ~23 ~123 ~110 dirt
setblock ~23 ~123 ~111 dirt
setblock ~23 ~123 ~112 dirt
setblock ~23 ~123 ~113 dirt
setblock ~23 ~123 ~114 dirt
setblock ~23 ~123 ~115 dirt
setblock ~23 ~123 ~116 dirt
setblock ~23 ~123 ~117 dirt
setblock ~23 ~123 ~118 grass_block
setblock ~23 ~123 ~119 grass_block
setblock ~23 ~123 ~120 grass_block
setblock ~23 ~123 ~121 grass_block
setblock ~23 ~123 ~122 grass_block
setblock ~23 ~123 ~123 grass_block
setblock ~23 ~124 ~51 dirt
setblock ~23 ~124 ~52 dirt
setblock ~23 ~124 ~53 dirt
setblock ~23 ~124 ~54 dirt
setblock ~23 ~124 ~55 dirt
setblock ~23 ~124 ~56 grass_block
setblock ~23 ~124 ~57 grass_block
setblock ~23 ~124 ~58 grass_block
setblock ~23 ~124 ~59 grass_block
setblock ~23 ~124 ~60 grass_block
setblock ~23 ~124 ~61 grass_block
setblock ~23 ~124 ~62 grass_block
setblock ~23 ~124 ~63 grass_block
setblock ~23 ~124 ~64 grass_block
setblock ~23 ~124 ~65 grass_block
setblock ~23 ~124 ~66 dirt
setblock ~23 ~124 ~92 dirt
setblock ~23 ~124 ~93 dirt
setblock ~23 ~124 ~94 dirt
setblock ~23 ~124 ~95 dirt
setblock ~23 ~124 ~96 dirt
setblock ~23 ~124 ~97 dirt
setblock ~23 ~124 ~98 dirt
setblock ~23 ~124 ~99 grass_block
setblock ~23 ~124 ~100 grass_block
setblock ~23 ~124 ~101 grass_block
setblock ~23 ~124 ~102 dirt
setblock ~23 ~124 ~103 dirt
setblock ~23 ~124 ~104 dirt
setblock ~23 ~124 ~105 dirt
setblock ~23 ~124 ~106 dirt
setblock ~23 ~124 ~107 dirt
setblock ~23 ~124 ~108 dirt
setblock ~23 ~124 ~109 dirt
setblock ~23 ~124 ~110 dirt
setblock ~23 ~124 ~111 dirt
setblock ~23 ~124 ~112 dirt
setblock ~23 ~124 ~113 dirt
setblock ~23 ~124 ~114 dirt
setblock ~23 ~124 ~115 dirt
setblock ~23 ~124 ~116 grass_block
setblock ~23 ~124 ~117 grass_block
setblock ~23 ~124 ~121 short_grass
setblock ~23 ~125 ~51 grass_block
setblock ~23 ~125 ~52 grass_block
setblock ~23 ~125 ~53 grass_block
setblock ~23 ~125 ~54 grass_block
setblock ~23 ~125 ~55 grass_block
setblock ~23 ~125 ~58 short_grass
setblock ~23 ~125 ~60 short_grass
setblock ~23 ~125 ~65 short_grass
setblock ~23 ~125 ~66 grass_block
setblock ~23 ~125 ~92 dirt
setblock ~23 ~125 ~93 dirt
setblock ~23 ~125 ~94 grass_block
setblock ~23 ~125 ~95 grass_block
setblock ~23 ~125 ~96 grass_block
setblock ~23 ~125 ~97 grass_block
setblock ~23 ~125 ~98 grass_block
setblock ~23 ~125 ~100 short_grass
setblock ~23 ~125 ~102 grass_block
setblock ~23 ~125 ~103 grass_block
setblock ~23 ~125 ~104 grass_block
setblock ~23 ~125 ~105 dirt
setblock ~23 ~125 ~106 dirt
setblock ~23 ~125 ~107 dirt
setblock ~23 ~125 ~108 dirt
setblock ~23 ~125 ~109 dirt
setblock ~23 ~125 ~110 dirt
setblock ~23 ~125 ~111 dirt
setblock ~23 ~125 ~112 dirt
setblock ~23 ~125 ~113 dirt
setblock ~23 ~125 ~114 grass_block
setblock ~23 ~125 ~115 grass_block
setblock ~23 ~125 ~116 short_grass
setblock ~23 ~126 ~52 fern
setblock ~23 ~126 ~66 short_grass
setblock ~23 ~126 ~92 grass_block
setblock ~23 ~126 ~93 grass_block
setblock ~23 ~126 ~96 fern
setblock ~23 ~126 ~102 poppy
setblock ~23 ~126 ~103 short_grass
setblock ~23 ~126 ~105 grass_block
setblock ~23 ~126 ~106 grass_block
setblock ~23 ~126 ~107 grass_block
setblock ~23 ~126 ~108 grass_block
setblock ~23 ~126 ~109 dirt
setblock ~23 ~126 ~110 dirt
setblock ~23 ~126 ~111 dirt
setblock ~23 ~126 ~112 grass_block
setblock ~23 ~126 ~113 grass_block
setblock ~23 ~127 ~93 poppy
setblock ~23 ~127 ~108 short_grass
setblock ~23 ~127 ~109 grass_block
setblock ~23 ~127 ~110 grass_block
setblock ~23 ~127 ~111 grass_block
setblock ~23 ~128 ~111 poppy
setblock ~24 ~105 ~108 dirt
setblock ~24 ~106 ~106 dirt
setblock ~24 ~106 ~107 dirt
setblock ~24 ~106 ~108 dirt
setblock ~24 ~107 ~105 dirt
setblock ~24 ~107 ~106 dirt
setblock ~24 ~107 ~107 dirt
setblock ~24 ~107 ~108 dirt
setblock ~24 ~107 ~109 dirt
setblock ~24 ~107 ~110 dirt
setblock ~24 ~108 ~105 dirt
setblock ~24 ~108 ~106 dirt
setblock ~24 ~108 ~107 dirt
setblock ~24 ~108 ~108 dirt
setblock ~24 ~108 ~109 dirt
setblock ~24 ~108 ~110 dirt
setblock ~24 ~108 ~111 dirt
setblock ~24 ~109 ~104 dirt
setblock ~24 ~109 ~105 dirt
setblock ~24 ~109 ~106 dirt
setblock ~24 ~109 ~107 dirt
setblock ~24 ~109 ~108 dirt
setblock ~24 ~109 ~109 dirt
setblock ~24 ~109 ~110 dirt
setblock ~24 ~109 ~111 dirt
setblock ~24 ~109 ~112 dirt
setblock ~24 ~110 ~103 dirt
setblock ~24 ~110 ~104 dirt
setblock ~24 ~110 ~105 dirt
setblock ~24 ~110 ~106 dirt
setblock ~24 ~110 ~107 dirt
setblock ~24 ~110 ~108 dirt
setblock ~24 ~110 ~109 dirt
setblock ~24 ~110 ~110 dirt
setblock ~24 ~110 ~111 dirt
setblock ~24 ~110 ~112 dirt
setblock ~24 ~110 ~113 dirt
setblock ~24 ~111 ~102 dirt
setblock ~24 ~111 ~103 dirt
setblock ~24 ~111 ~104 dirt
setblock ~24 ~111 ~105 dirt
setblock ~24 ~111 ~106 dirt
setblock ~24 ~111 ~107 dirt
setblock ~24 ~111 ~108 dirt
setblock ~24 ~111 ~109 dirt
setblock ~24 ~111 ~110 dirt
setblock ~24 ~111 ~111 dirt
setblock ~24 ~111 ~112 dirt
setblock ~24 ~111 ~113 dirt
setblock ~24 ~111 ~114 dirt
setblock ~24 ~112 ~55 dirt
setblock ~24 ~112 ~101 dirt
setblock ~24 ~112 ~102 dirt
setblock ~24 ~112 ~103 dirt
setblock ~24 ~112 ~104 dirt
setblock ~24 ~112 ~105 dirt
setblock ~24 ~112 ~106 dirt
setblock ~24 ~112 ~107 dirt
setblock ~24 ~112 ~108 dirt
setblock ~24 ~112 ~109 dirt
setblock ~24 ~112 ~110 dirt
setblock ~24 ~112 ~111 dirt
setblock ~24 ~112 ~112 dirt
setblock ~24 ~112 ~113 dirt
setblock ~24 ~112 ~114 dirt
setblock ~24 ~112 ~115 dirt
setblock ~24 ~113 ~54 dirt
setblock ~24 ~113 ~55 dirt
setblock ~24 ~113 ~56 dirt
setblock ~24 ~113 ~100 dirt
setblock ~24 ~113 ~101 dirt
setblock ~24 ~113 ~102 dirt
setblock ~24 ~113 ~103 dirt
setblock ~24 ~113 ~104 dirt
setblock ~24 ~113 ~105 dirt
setblock ~24 ~113 ~106 dirt
setblock ~24 ~113 ~107 dirt
setblock ~24 ~113 ~108 dirt
setblock ~24 ~113 ~109 dirt
setblock ~24 ~113 ~110 dirt
setblock ~24 ~113 ~111 dirt
setblock ~24 ~113 ~112 dirt
setblock ~24 ~113 ~113 dirt
setblock ~24 ~113 ~114 dirt
setblock ~24 ~113 ~115 dirt
setblock ~24 ~113 ~116 dirt
setblock ~24 ~114 ~53 dirt
setblock ~24 ~114 ~54 dirt
setblock ~24 ~114 ~55 dirt
setblock ~24 ~114 ~56 dirt
setblock ~24 ~114 ~57 dirt
setblock ~24 ~114 ~99 dirt
setblock ~24 ~114 ~100 dirt
setblock ~24 ~114 ~101 dirt
setblock ~24 ~114 ~102 dirt
setblock ~24 ~114 ~103 dirt
setblock ~24 ~114 ~104 dirt
setblock ~24 ~114 ~105 dirt
setblock ~24 ~114 ~106 dirt
setblock ~24 ~114 ~107 dirt
setblock ~24 ~114 ~108 dirt
setblock ~24 ~114 ~109 dirt
setblock ~24 ~114 ~110 dirt
setblock ~24 ~114 ~111 dirt
setblock ~24 ~114 ~112 dirt
setblock ~24 ~114 ~113 dirt
setblock ~24 ~114 ~114 dirt
setblock ~24 ~114 ~115 dirt
setblock ~24 ~114 ~116 dirt
setblock ~24 ~114 ~117 dirt
setblock ~24 ~115 ~53 dirt
setblock ~24 ~115 ~54 dirt
setblock ~24 ~115 ~55 dirt
setblock ~24 ~115 ~56 dirt
setblock ~24 ~115 ~57 dirt
setblock ~24 ~115 ~58 dirt
setblock ~24 ~115 ~59 dirt
setblock ~24 ~115 ~98 dirt
setblock ~24 ~115 ~99 dirt
setblock ~24 ~115 ~100 dirt
setblock ~24 ~115 ~101 dirt
setblock ~24 ~115 ~102 dirt
setblock ~24 ~115 ~103 dirt
setblock ~24 ~115 ~104 dirt
setblock ~24 ~115 ~105 dirt
setblock ~24 ~115 ~106 dirt
setblock ~24 ~115 ~107 dirt
setblock ~24 ~115 ~108 dirt
setblock ~24 ~115 ~109 dirt
setblock ~24 ~115 ~110 dirt
setblock ~24 ~115 ~111 dirt
setblock ~24 ~115 ~112 dirt
setblock ~24 ~115 ~113 dirt
setblock ~24 ~115 ~114 dirt
setblock ~24 ~115 ~115 dirt
setblock ~24 ~115 ~116 dirt
setblock ~24 ~115 ~117 dirt
setblock ~24 ~116 ~52 dirt
setblock ~24 ~116 ~53 dirt
setblock ~24 ~116 ~54 dirt
setblock ~24 ~116 ~55 dirt
setblock ~24 ~116 ~56 dirt
setblock ~24 ~116 ~57 dirt
setblock ~24 ~116 ~58 dirt
setblock ~24 ~116 ~59 dirt
setblock ~24 ~116 ~60 dirt
setblock ~24 ~116 ~61 dirt
setblock ~24 ~116 ~62 dirt
setblock ~24 ~116 ~97 dirt
setblock ~24 ~116 ~98 dirt
setblock ~24 ~116 ~99 dirt
setblock ~24 ~116 ~100 dirt
setblock ~24 ~116 ~101 dirt
setblock ~24 ~116 ~102 dirt
setblock ~24 ~116 ~103 dirt
setblock ~24 ~116 ~104 dirt
setblock ~24 ~116 ~105 dirt
setblock ~24 ~116 ~106 dirt
setblock ~24 ~116 ~107 dirt
setblock ~24 ~116 ~108 dirt
setblock ~24 ~116 ~109 dirt
setblock ~24 ~116 ~110 dirt
setblock ~24 ~116 ~111 dirt
setblock ~24 ~116 ~112 dirt
setblock ~24 ~116 ~113 dirt
setblock ~24 ~116 ~114 dirt
setblock ~24 ~116 ~115 dirt
setblock ~24 ~116 ~116 dirt
setblock ~24 ~116 ~117 dirt
setblock ~24 ~116 ~118 dirt
setblock ~24 ~117 ~52 dirt
setblock ~24 ~117 ~53 dirt
setblock ~24 ~117 ~54 dirt
setblock ~24 ~117 ~55 dirt
setblock ~24 ~117 ~56 dirt
setblock ~24 ~117 ~57 dirt
setblock ~24 ~117 ~58 dirt
setblock ~24 ~117 ~59 dirt
setblock ~24 ~117 ~60 dirt
setblock ~24 ~117 ~61 dirt
setblock ~24 ~117 ~62 dirt
setblock ~24 ~117 ~63 dirt
setblock ~24 ~117 ~96 dirt
setblock ~24 ~117 ~97 dirt
setblock ~24 ~117 ~98 dirt
setblock ~24 ~117 ~99 dirt
setblock ~24 ~117 ~100 dirt
setblock ~24 ~117 ~101 dirt
setblock ~24 ~117 ~102 dirt
setblock ~24 ~117 ~103 dirt
setblock ~24 ~117 ~104 dirt
setblock ~24 ~117 ~105 dirt
setblock ~24 ~117 ~106 dirt
setblock ~24 ~117 ~107 dirt
setblock ~24 ~117 ~108 dirt
setblock ~24 ~117 ~109 dirt
setblock ~24 ~117 ~110 dirt
setblock ~24 ~117 ~111 dirt
setblock ~24 ~117 ~112 dirt
setblock ~24 ~117 ~113 dirt
setblock ~24 ~117 ~114 dirt
setblock ~24 ~117 ~115 dirt
setblock ~24 ~117 ~116 dirt
setblock ~24 ~117 ~117 dirt
setblock ~24 ~117 ~118 dirt
setblock ~24 ~117 ~119 dirt
setblock ~24 ~118 ~52 dirt
setblock ~24 ~118 ~53 dirt
setblock ~24 ~118 ~54 dirt
setblock ~24 ~118 ~55 dirt
setblock ~24 ~118 ~56 dirt
setblock ~24 ~118 ~57 dirt
setblock ~24 ~118 ~58 dirt
setblock ~24 ~118 ~59 dirt
setblock ~24 ~118 ~60 dirt
setblock ~24 ~118 ~61 dirt
setblock ~24 ~118 ~62 dirt
setblock ~24 ~118 ~63 dirt
setblock ~24 ~118 ~64 dirt
setblock ~24 ~118 ~95 dirt
setblock ~24 ~118 ~96 dirt
setblock ~24 ~118 ~97 dirt
setblock ~24 ~118 ~98 dirt
setblock ~24 ~118 ~99 dirt
setblock ~24 ~118 ~100 dirt
setblock ~24 ~118 ~101 dirt
setblock ~24 ~118 ~102 dirt
setblock ~24 ~118 ~103 dirt
setblock ~24 ~118 ~104 dirt
setblock ~24 ~118 ~105 dirt
setblock ~24 ~118 ~106 dirt
setblock ~24 ~118 ~107 dirt
setblock ~24 ~118 ~108 dirt
setblock ~24 ~118 ~109 dirt
setblock ~24 ~118 ~110 dirt
setblock ~24 ~118 ~111 dirt
setblock ~24 ~118 ~112 dirt
setblock ~24 ~118 ~113 dirt
setblock ~24 ~118 ~114 dirt
setblock ~24 ~118 ~115 dirt
setblock ~24 ~118 ~116 dirt
setblock ~24 ~118 ~117 dirt
setblock ~24 ~118 ~118 dirt
setblock ~24 ~118 ~119 dirt
setblock ~24 ~119 ~52 dirt
setblock ~24 ~119 ~53 dirt
setblock ~24 ~119 ~54 dirt
setblock ~24 ~119 ~55 dirt
setblock ~24 ~119 ~56 dirt
setblock ~24 ~119 ~57 dirt
setblock ~24 ~119 ~58 dirt
setblock ~24 ~119 ~59 dirt
setblock ~24 ~119 ~60 dirt
setblock ~24 ~119 ~61 dirt
setblock ~24 ~119 ~62 dirt
setblock ~24 ~119 ~63 dirt
setblock ~24 ~119 ~64 dirt
setblock ~24 ~119 ~65 dirt
setblock ~24 ~119 ~95 dirt
setblock ~24 ~119 ~96 dirt
setblock ~24 ~119 ~97 dirt
setblock ~24 ~119 ~98 dirt
setblock ~24 ~119 ~99 dirt
setblock ~24 ~119 ~100 dirt
setblock ~24 ~119 ~101 dirt
setblock ~24 ~119 ~102 dirt
setblock ~24 ~119 ~103 dirt
setblock ~24 ~119 ~104 dirt
setblock ~24 ~119 ~105 dirt
setblock ~24 ~119 ~106 dirt
setblock ~24 ~119 ~107 dirt
setblock ~24 ~119 ~108 dirt
setblock ~24 ~119 ~109 dirt
setblock ~24 ~119 ~110 dirt
setblock ~24 ~119 ~111 dirt
setblock ~24 ~119 ~112 dirt
setblock ~24 ~119 ~113 dirt
setblock ~24 ~119 ~114 dirt
setblock ~24 ~119 ~115 dirt
setblock ~24 ~119 ~116 dirt
setblock ~24 ~119 ~117 dirt
setblock ~24 ~119 ~118 dirt
setblock ~24 ~119 ~119 dirt
setblock ~24 ~119 ~120 dirt
setblock ~24 ~120 ~51 dirt
setblock ~24 ~120 ~52 dirt
setblock ~24 ~120 ~53 dirt
setblock ~24 ~120 ~54 dirt
setblock ~24 ~120 ~55 dirt
setblock ~24 ~120 ~56 dirt
setblock ~24 ~120 ~57 dirt
setblock ~24 ~120 ~58 dirt
setblock ~24 ~120 ~59 dirt
setblock ~24 ~120 ~60 dirt
setblock ~24 ~120 ~61 dirt
setblock ~24 ~120 ~62 dirt
setblock ~24 ~120 ~63 dirt
setblock ~24 ~120 ~64 dirt
setblock ~24 ~120 ~65 dirt
setblock ~24 ~120 ~66 dirt
setblock ~24 ~120 ~94 dirt
setblock ~24 ~120 ~95 dirt
setblock ~24 ~120 ~96 dirt
setblock ~24 ~120 ~97 dirt
setblock ~24 ~120 ~98 dirt
setblock ~24 ~120 ~99 dirt
setblock ~24 ~120 ~100 dirt
setblock ~24 ~120 ~101 dirt
setblock ~24 ~120 ~102 dirt
setblock ~24 ~120 ~103 dirt
setblock ~24 ~120 ~104 dirt
setblock ~24 ~120 ~105 dirt
setblock ~24 ~120 ~106 dirt
setblock ~24 ~120 ~107 dirt
setblock ~24 ~120 ~108 dirt
setblock ~24 ~120 ~109 dirt
setblock ~24 ~120 ~110 dirt
setblock ~24 ~120 ~111 dirt
setblock ~24 ~120 ~112 dirt
setblock ~24 ~120 ~113 dirt
setblock ~24 ~120 ~114 dirt
setblock ~24 ~120 ~115 dirt
setblock ~24 ~120 ~116 dirt
setblock ~24 ~120 ~117 dirt
setblock ~24 ~120 ~118 dirt
setblock ~24 ~120 ~119 dirt
setblock ~24 ~120 ~120 dirt
setblock ~24 ~120 ~121 dirt
setblock ~24 ~121 ~51 dirt
setblock ~24 ~121 ~52 dirt
setblock ~24 ~121 ~53 dirt
setblock ~24 ~121 ~54 dirt
setblock ~24 ~121 ~55 dirt
setblock ~24 ~121 ~56 dirt
setblock ~24 ~121 ~57 dirt
setblock ~24 ~121 ~58 dirt
setblock ~24 ~121 ~59 dirt
setblock ~24 ~121 ~60 dirt
setblock ~24 ~121 ~61 dirt
setblock ~24 ~121 ~62 dirt
setblock ~24 ~121 ~63 dirt
setblock ~24 ~121 ~64 dirt
setblock ~24 ~121 ~65 dirt
setblock ~24 ~121 ~66 dirt
setblock ~24 ~121 ~67 dirt
setblock ~24 ~121 ~93 dirt
setblock ~24 ~121 ~94 dirt
setblock ~24 ~121 ~95 dirt
setblock ~24 ~121 ~96 dirt
setblock ~24 ~121 ~97 dirt
setblock ~24 ~121 ~98 dirt
setblock ~24 ~121 ~99 dirt
setblock ~24 ~121 ~100 dirt
setblock ~24 ~121 ~101 dirt
setblock ~24 ~121 ~102 dirt
setblock ~24 ~121 ~103 dirt
setblock ~24 ~121 ~104 dirt
setblock ~24 ~121 ~105 dirt
setblock ~24 ~121 ~106 dirt
setblock ~24 ~121 ~107 dirt
setblock ~24 ~121 ~108 dirt
setblock ~24 ~121 ~109 dirt
setblock ~24 ~121 ~110 dirt
setblock ~24 ~121 ~111 dirt
setblock ~24 ~121 ~112 dirt
setblock ~24 ~121 ~113 dirt
setblock ~24 ~121 ~114 dirt
setblock ~24 ~121 ~115 dirt
setblock ~24 ~121 ~116 dirt
setblock ~24 ~121 ~117 dirt
setblock ~24 ~121 ~118 dirt
setblock ~24 ~121 ~119 dirt
setblock ~24 ~121 ~120 dirt
setblock ~24 ~121 ~121 dirt
setblock ~24 ~121 ~122 dirt
setblock ~24 ~122 ~51 dirt
setblock ~24 ~122 ~52 dirt
setblock ~24 ~122 ~53 dirt
setblock ~24 ~122 ~54 dirt
setblock ~24 ~122 ~55 dirt
setblock ~24 ~122 ~56 dirt
setblock ~24 ~122 ~57 dirt
setblock ~24 ~122 ~58 dirt
setblock ~24 ~122 ~59 dirt
setblock ~24 ~122 ~60 dirt
setblock ~24 ~122 ~61 dirt
setblock ~24 ~122 ~62 dirt
setblock ~24 ~122 ~63 dirt
setblock ~24 ~122 ~64 dirt
setblock ~24 ~122 ~65 dirt
setblock ~24 ~122 ~66 dirt
setblock ~24 ~122 ~67 dirt
setblock ~24 ~122 ~93 dirt
setblock ~24 ~122 ~94 dirt
setblock ~24 ~122 ~95 dirt
setblock ~24 ~122 ~96 dirt
setblock ~24 ~122 ~97 dirt
setblock ~24 ~122 ~98 dirt
setblock ~24 ~122 ~99 dirt
setblock ~24 ~122 ~100 dirt
setblock ~24 ~122 ~101 dirt
setblock ~24 ~122 ~102 dirt
setblock ~24 ~122 ~103 dirt
setblock ~24 ~122 ~104 dirt
setblock ~24 ~122 ~105 dirt
setblock ~24 ~122 ~106 dirt
setblock ~24 ~122 ~107 dirt
setblock ~24 ~122 ~108 dirt
setblock ~24 ~122 ~109 dirt
setblock ~24 ~122 ~110 dirt
setblock ~24 ~122 ~111 dirt
setblock ~24 ~122 ~112 dirt
setblock ~24 ~122 ~113 dirt
setblock ~24 ~122 ~114 dirt
setblock ~24 ~122 ~115 dirt
setblock ~24 ~122 ~116 dirt
setblock ~24 ~122 ~117 dirt
setblock ~24 ~122 ~118 dirt
setblock ~24 ~122 ~119 dirt
setblock ~24 ~122 ~120 dirt
setblock ~24 ~122 ~121 dirt
setblock ~24 ~122 ~122 dirt
setblock ~24 ~123 ~51 dirt
setblock ~24 ~123 ~52 dirt
setblock ~24 ~123 ~53 dirt
setblock ~24 ~123 ~54 dirt
setblock ~24 ~123 ~55 dirt
setblock ~24 ~123 ~56 dirt
setblock ~24 ~123 ~57 dirt
setblock ~24 ~123 ~58 dirt
setblock ~24 ~123 ~59 dirt
setblock ~24 ~123 ~60 dirt
setblock ~24 ~123 ~61 dirt
setblock ~24 ~123 ~62 dirt
setblock ~24 ~123 ~63 dirt
setblock ~24 ~123 ~64 dirt
setblock ~24 ~123 ~65 dirt
setblock ~24 ~123 ~66 dirt
setblock ~24 ~123 ~67 dirt
setblock ~24 ~123 ~93 dirt
setblock ~24 ~123 ~94 dirt
setblock ~24 ~123 ~95 dirt
setblock ~24 ~123 ~96 dirt
setblock ~24 ~123 ~97 dirt
setblock ~24 ~123 ~98 dirt
setblock ~24 ~123 ~99 dirt
setblock ~24 ~123 ~100 dirt
setblock ~24 ~123 ~101 dirt
setblock ~24 ~123 ~102 dirt
setblock ~24 ~123 ~103 dirt
setblock ~24 ~123 ~104 dirt
setblock ~24 ~123 ~105 dirt
setblock ~24 ~123 ~106 dirt
setblock ~24 ~123 ~107 dirt
setblock ~24 ~123 ~108 dirt
setblock ~24 ~123 ~109 dirt
setblock ~24 ~123 ~110 dirt
setblock ~24 ~123 ~111 dirt
setblock ~24 ~123 ~112 dirt
setblock ~24 ~123 ~113 dirt
setblock ~24 ~123 ~114 dirt
setblock ~24 ~123 ~115 dirt
setblock ~24 ~123 ~116 dirt
setblock ~24 ~123 ~117 dirt
setblock ~24 ~123 ~118 dirt
setblock ~24 ~123 ~119 grass_block
setblock ~24 ~123 ~120 grass_block
setblock ~24 ~123 ~121 grass_block
setblock ~24 ~123 ~122 grass_block
setblock ~24 ~124 ~51 dirt
setblock ~24 ~124 ~52 dirt
setblock ~24 ~124 ~53 dirt
setblock ~24 ~124 ~54 dirt
setblock ~24 ~124 ~55 dirt
setblock ~24 ~124 ~56 dirt
setblock ~24 ~124 ~57 grass_block
setblock ~24 ~124 ~58 grass_block
setblock ~24 ~124 ~59 grass_block
setblock ~24 ~124 ~60 grass_block
setblock ~24 ~124 ~61 grass_block
setblock ~24 ~124 ~62 grass_block
setblock ~24 ~124 ~63 grass_block
setblock ~24 ~124 ~64 grass_block
setblock ~24 ~124 ~65 dirt
setblock ~24 ~124 ~66 dirt
setblock ~24 ~124 ~67 dirt
setblock ~24 ~124 ~93 dirt
setblock ~24 ~124 ~94 dirt
setblock ~24 ~124 ~95 dirt
setblock ~24 ~124 ~96 dirt
setblock ~24 ~124 ~97 dirt
setblock ~24 ~124 ~98 dirt
setblock ~24 ~124 ~99 grass_block
setblock ~24 ~124 ~100 grass_block
setblock ~24 ~124 ~101 grass_block
setblock ~24 ~124 ~102 dirt
setblock ~24 ~124 ~103 dirt
setblock ~24 ~124 ~104 dirt
setblock ~24 ~124 ~105 dirt
setblock ~24 ~124 ~106 dirt
setblock ~24 ~124 ~107 dirt
setblock ~24 ~124 ~108 dirt
setblock ~24 ~124 ~109 dirt
setblock ~24 ~124 ~110 dirt
setblock ~24 ~124 ~111 dirt
setblock ~24 ~124 ~112 dirt
setblock ~24 ~124 ~113 dirt
setblock ~24 ~124 ~114 dirt
setblock ~24 ~124 ~115 dirt
setblock ~24 ~124 ~116 grass_block
setblock ~24 ~124 ~117 grass_block
setblock ~24 ~124 ~118 grass_block
setblock ~24 ~124 ~120 poppy
setblock ~24 ~124 ~121 fern
setblock ~24 ~125 ~51 dirt
setblock ~24 ~125 ~52 grass_block
setblock ~24 ~125 ~53 grass_block
setblock ~24 ~125 ~54 grass_block
setblock ~24 ~125 ~55 grass_block
setblock ~24 ~125 ~56 grass_block
setblock ~24 ~125 ~57 short_grass
setblock ~24 ~125 ~65 grass_block
setblock ~24 ~125 ~66 grass_block
setblock ~24 ~125 ~67 grass_block
setblock ~24 ~125 ~93 dirt
setblock ~24 ~125 ~94 grass_block
setblock ~24 ~125 ~95 grass_block
setblock ~24 ~125 ~96 grass_block
setblock ~24 ~125 ~97 grass_block
setblock ~24 ~125 ~98 grass_block
setblock ~24 ~125 ~100 short_grass
setblock ~24 ~125 ~102 grass_block
setblock ~24 ~125 ~103 grass_block
setblock ~24 ~125 ~104 grass_block
setblock ~24 ~125 ~105 dirt
setblock ~24 ~125 ~106 dirt
setblock ~24 ~125 ~107 dirt
setblock ~24 ~125 ~108 dirt
setblock ~24 ~125 ~109 dirt
setblock ~24 ~125 ~110 dirt
setblock ~24 ~125 ~111 dirt
setblock ~24 ~125 ~112 dirt
setblock ~24 ~125 ~113 dirt
setblock ~24 ~125 ~114 grass_block
setblock ~24 ~125 ~115 grass_block
setblock ~24 ~125 ~116 short_grass
setblock ~24 ~125 ~118 fern
setblock ~24 ~126 ~51 grass_block
setblock ~24 ~126 ~54 short_grass
setblock ~24 ~126 ~65 short_grass
setblock ~24 ~126 ~66 poppy
setblock ~24 ~126 ~93 grass_block
setblock ~24 ~126 ~98 short_grass
setblock ~24 ~126 ~102 short_grass
setblock ~24 ~126 ~104 short_grass
setblock ~24 ~126 ~105 grass_block
setblock ~24 ~126 ~106 grass_block
setblock ~24 ~126 ~107 grass_block
setblock ~24 ~126 ~108 dirt
setblock ~24 ~126 ~109 dirt
setblock ~24 ~126 ~110 dirt
setblock ~24 ~126 ~111 dirt
setblock ~24 ~126 ~112 grass_block
setblock ~24 ~126 ~113 grass_block
setblock ~24 ~126 ~115 fern
setblock ~24 ~127 ~51 short_grass
setblock ~24 ~127 ~93 short_grass
setblock ~24 ~127 ~108 grass_block
setblock ~24 ~127 ~109 grass_block
setblock ~24 ~127 ~110 grass_block
setblock ~24 ~127 ~111 grass_block
setblock ~24 ~128 ~108 short_grass
setblock ~24 ~128 ~110 short_grass
setblock ~25 ~107 ~106 dirt
setblock ~25 ~107 ~108 dirt
setblock ~25 ~108 ~105 dirt
setblock ~25 ~108 ~106 dirt
setblock ~25 ~108 ~107 dirt
setblock ~25 ~108 ~108 dirt
setblock ~25 ~108 ~109 dirt
setblock ~25 ~108 ~110 dirt
setblock ~25 ~109 ~105 dirt
setblock ~25 ~109 ~106 dirt
setblock ~25 ~109 ~107 dirt
setblock ~25 ~109 ~108 dirt
setblock ~25 ~109 ~109 dirt
setblock ~25 ~109 ~110 dirt
setblock ~25 ~109 ~111 dirt
setblock ~25 ~110 ~104 dirt
setblock ~25 ~110 ~105 dirt
setblock ~25 ~110 ~106 dirt
setblock ~25 ~110 ~107 dirt
setblock ~25 ~110 ~108 dirt
setblock ~25 ~110 ~109 dirt
setblock ~25 ~110 ~110 dirt
setblock ~25 ~110 ~111 dirt
setblock ~25 ~110 ~112 dirt
setblock ~25 ~111 ~103 dirt
setblock ~25 ~111 ~104 dirt
setblock ~25 ~111 ~105 dirt
setblock ~25 ~111 ~106 dirt
setblock ~25 ~111 ~107 dirt
setblock ~25 ~111 ~108 dirt
setblock ~25 ~111 ~109 dirt
setblock ~25 ~111 ~110 dirt
setblock ~25 ~111 ~111 dirt
setblock ~25 ~111 ~112 dirt
setblock ~25 ~111 ~113 dirt
setblock ~25 ~112 ~102 dirt
setblock ~25 ~112 ~103 dirt
setblock ~25 ~112 ~104 dirt
setblock ~25 ~112 ~105 dirt
setblock ~25 ~112 ~106 dirt
setblock ~25 ~112 ~107 dirt
setblock ~25 ~112 ~108 dirt
setblock ~25 ~112 ~109 dirt
setblock ~25 ~112 ~110 dirt
setblock ~25 ~112 ~111 dirt
setblock ~25 ~112 ~112 dirt
setblock ~25 ~112 ~113 dirt
setblock ~25 ~112 ~114 dirt
setblock ~25 ~113 ~55 dirt
setblock ~25 ~113 ~59 dirt
setblock ~25 ~113 ~101 dirt
setblock ~25 ~113 ~102 dirt
setblock ~25 ~113 ~103 dirt
setblock ~25 ~113 ~104 dirt
setblock ~25 ~113 ~105 dirt
setblock ~25 ~113 ~106 dirt
setblock ~25 ~113 ~107 dirt
setblock ~25 ~113 ~108 dirt
setblock ~25 ~113 ~109 dirt
setblock ~25 ~113 ~110 dirt
setblock ~25 ~113 ~111 dirt
setblock ~25 ~113 ~112 dirt
setblock ~25 ~113 ~113 dirt
setblock ~25 ~113 ~114 dirt
setblock ~25 ~113 ~115 dirt
setblock ~25 ~114 ~54 dirt
setblock ~25 ~114 ~55 dirt
setblock ~25 ~114 ~56 dirt
setblock ~25 ~114 ~57 dirt
setblock ~25 ~114 ~58 dirt
setblock ~25 ~114 ~59 dirt
setblock ~25 ~114 ~60 dirt
setblock ~25 ~114 ~100 dirt
setblock ~25 ~114 ~101 dirt
setblock ~25 ~114 ~102 dirt
setblock ~25 ~114 ~103 dirt
setblock ~25 ~114 ~104 dirt
setblock ~25 ~114 ~105 dirt
setblock ~25 ~114 ~106 dirt
setblock ~25 ~114 ~107 dirt
setblock ~25 ~114 ~108 dirt
setblock ~25 ~114 ~109 dirt
setblock ~25 ~114 ~110 dirt
setblock ~25 ~114 ~111 dirt
setblock ~25 ~114 ~112 dirt
setblock ~25 ~114 ~113 dirt
setblock ~25 ~114 ~114 dirt
setblock ~25 ~114 ~115 dirt
setblock ~25 ~114 ~116 dirt
setblock ~25 ~115 ~54 dirt
setblock ~25 ~115 ~55 dirt
setblock ~25 ~115 ~56 dirt
setblock ~25 ~115 ~57 dirt
setblock ~25 ~115 ~58 dirt
setblock ~25 ~115 ~59 dirt
setblock ~25 ~115 ~60 dirt
setblock ~25 ~115 ~61 dirt
setblock ~25 ~115 ~62 dirt
setblock ~25 ~115 ~99 dirt
setblock ~25 ~115 ~100 dirt
setblock ~25 ~115 ~101 dirt
setblock ~25 ~115 ~102 dirt
setblock ~25 ~115 ~103 dirt
setblock ~25 ~115 ~104 dirt
setblock ~25 ~115 ~105 dirt
setblock ~25 ~115 ~106 dirt
setblock ~25 ~115 ~107 dirt
setblock ~25 ~115 ~108 dirt
setblock ~25 ~115 ~109 dirt
setblock ~25 ~115 ~110 dirt
setblock ~25 ~115 ~111 dirt
setblock ~25 ~115 ~112 dirt
