setblock ~163 ~111 ~76 dirt
setblock ~163 ~111 ~77 dirt
setblock ~163 ~111 ~78 dirt
setblock ~163 ~111 ~79 dirt
setblock ~163 ~111 ~80 dirt
setblock ~163 ~111 ~81 dirt
setblock ~163 ~111 ~82 dirt
setblock ~163 ~111 ~83 dirt
setblock ~163 ~111 ~84 dirt
setblock ~163 ~111 ~85 dirt
setblock ~163 ~111 ~86 dirt
setblock ~163 ~112 ~74 dirt
setblock ~163 ~112 ~75 dirt
setblock ~163 ~112 ~76 dirt
setblock ~163 ~112 ~77 dirt
setblock ~163 ~112 ~78 dirt
setblock ~163 ~112 ~79 dirt
setblock ~163 ~112 ~80 dirt
setblock ~163 ~112 ~81 dirt
setblock ~163 ~112 ~82 dirt
setblock ~163 ~112 ~83 dirt
setblock ~163 ~112 ~84 dirt
setblock ~163 ~112 ~85 dirt
setblock ~163 ~112 ~86 dirt
setblock ~163 ~112 ~87 dirt
setblock ~163 ~113 ~74 dirt
setblock ~163 ~113 ~75 dirt
setblock ~163 ~113 ~76 dirt
setblock ~163 ~113 ~77 dirt
setblock ~163 ~113 ~78 dirt
setblock ~163 ~113 ~79 dirt
setblock ~163 ~113 ~80 dirt
setblock ~163 ~113 ~81 dirt
setblock ~163 ~113 ~82 dirt
setblock ~163 ~113 ~83 dirt
setblock ~163 ~113 ~84 dirt
setblock ~163 ~113 ~85 dirt
setblock ~163 ~113 ~86 dirt
setblock ~163 ~113 ~87 dirt
setblock ~163 ~114 ~74 dirt
setblock ~163 ~114 ~75 dirt
setblock ~163 ~114 ~76 dirt
setblock ~163 ~114 ~77 dirt
setblock ~163 ~114 ~78 dirt
setblock ~163 ~114 ~79 dirt
setblock ~163 ~114 ~80 dirt
setblock ~163 ~114 ~81 dirt
setblock ~163 ~114 ~82 dirt
setblock ~163 ~114 ~83 dirt
setblock ~163 ~114 ~84 dirt
setblock ~163 ~114 ~85 dirt
setblock ~163 ~114 ~86 dirt
setblock ~163 ~114 ~87 dirt
setblock ~163 ~114 ~97 dirt
setblock ~163 ~114 ~99 dirt
setblock ~163 ~115 ~73 dirt
setblock ~163 ~115 ~74 dirt
setblock ~163 ~115 ~75 dirt
setblock ~163 ~115 ~76 dirt
setblock ~163 ~115 ~77 dirt
setblock ~163 ~115 ~78 dirt
setblock ~163 ~115 ~79 dirt
setblock ~163 ~115 ~80 dirt
setblock ~163 ~115 ~81 dirt
setblock ~163 ~115 ~82 dirt
setblock ~163 ~115 ~83 dirt
setblock ~163 ~115 ~84 dirt
setblock ~163 ~115 ~85 dirt
setblock ~163 ~115 ~86 dirt
setblock ~163 ~115 ~87 dirt
setblock ~163 ~115 ~88 dirt
setblock ~163 ~115 ~89 dirt
setblock ~163 ~115 ~96 dirt
setblock ~163 ~115 ~97 dirt
setblock ~163 ~115 ~99 dirt
setblock ~163 ~115 ~100 dirt
setblock ~163 ~116 ~73 dirt
setblock ~163 ~116 ~74 dirt
setblock ~163 ~116 ~75 dirt
setblock ~163 ~116 ~76 dirt
setblock ~163 ~116 ~77 dirt
setblock ~163 ~116 ~78 dirt
setblock ~163 ~116 ~79 dirt
setblock ~163 ~116 ~80 dirt
setblock ~163 ~116 ~81 dirt
setblock ~163 ~116 ~82 dirt
setblock ~163 ~116 ~83 dirt
setblock ~163 ~116 ~84 dirt
setblock ~163 ~116 ~85 dirt
setblock ~163 ~116 ~86 dirt
setblock ~163 ~116 ~87 dirt
setblock ~163 ~116 ~88 dirt
setblock ~163 ~116 ~89 dirt
setblock ~163 ~116 ~90 dirt
setblock ~163 ~116 ~94 dirt
setblock ~163 ~116 ~96 dirt
setblock ~163 ~116 ~97 dirt
setblock ~163 ~116 ~98 dirt
setblock ~163 ~116 ~99 dirt
setblock ~163 ~116 ~100 dirt
setblock ~163 ~116 ~101 dirt
setblock ~163 ~116 ~122 dirt
setblock ~163 ~117 ~54 dirt
setblock ~163 ~117 ~72 dirt
setblock ~163 ~117 ~73 dirt
setblock ~163 ~117 ~74 dirt
setblock ~163 ~117 ~75 dirt
setblock ~163 ~117 ~76 dirt
setblock ~163 ~117 ~77 dirt
setblock ~163 ~117 ~78 dirt
setblock ~163 ~117 ~79 dirt
setblock ~163 ~117 ~80 dirt
setblock ~163 ~117 ~81 dirt
setblock ~163 ~117 ~82 dirt
setblock ~163 ~117 ~83 dirt
setblock ~163 ~117 ~84 dirt
setblock ~163 ~117 ~85 dirt
setblock ~163 ~117 ~86 dirt
setblock ~163 ~117 ~87 dirt
setblock ~163 ~117 ~88 dirt
setblock ~163 ~117 ~89 dirt
setblock ~163 ~117 ~90 dirt
setblock ~163 ~117 ~91 dirt
setblock ~163 ~117 ~94 dirt
setblock ~163 ~117 ~96 dirt
setblock ~163 ~117 ~97 dirt
setblock ~163 ~117 ~98 dirt
setblock ~163 ~117 ~99 dirt
setblock ~163 ~117 ~100 dirt
setblock ~163 ~117 ~101 dirt
setblock ~163 ~117 ~121 dirt
setblock ~163 ~117 ~122 dirt
setblock ~163 ~117 ~129 dirt
setblock ~163 ~118 ~53 dirt
setblock ~163 ~118 ~54 dirt
setblock ~163 ~118 ~55 dirt
setblock ~163 ~118 ~72 dirt
setblock ~163 ~118 ~73 dirt
setblock ~163 ~118 ~74 dirt
setblock ~163 ~118 ~75 dirt
setblock ~163 ~118 ~76 dirt
setblock ~163 ~118 ~77 dirt
setblock ~163 ~118 ~78 dirt
setblock ~163 ~118 ~79 dirt
setblock ~163 ~118 ~80 dirt
setblock ~163 ~118 ~81 dirt
setblock ~163 ~118 ~82 dirt
setblock ~163 ~118 ~83 dirt
setblock ~163 ~118 ~84 dirt
setblock ~163 ~118 ~85 dirt
setblock ~163 ~118 ~86 dirt
setblock ~163 ~118 ~87 dirt
setblock ~163 ~118 ~88 dirt
setblock ~163 ~118 ~89 dirt
setblock ~163 ~118 ~90 dirt
setblock ~163 ~118 ~91 dirt
setblock ~163 ~118 ~92 dirt
setblock ~163 ~118 ~93 dirt
setblock ~163 ~118 ~94 dirt
setblock ~163 ~118 ~95 dirt
setblock ~163 ~118 ~96 dirt
setblock ~163 ~118 ~97 dirt
setblock ~163 ~118 ~98 dirt
setblock ~163 ~118 ~99 dirt
setblock ~163 ~118 ~100 dirt
setblock ~163 ~118 ~101 dirt
setblock ~163 ~118 ~102 dirt
setblock ~163 ~118 ~103 dirt
setblock ~163 ~118 ~120 dirt
setblock ~163 ~118 ~121 dirt
setblock ~163 ~118 ~122 dirt
setblock ~163 ~118 ~123 dirt
setblock ~163 ~118 ~125 dirt
setblock ~163 ~118 ~128 dirt
setblock ~163 ~118 ~129 dirt
setblock ~163 ~118 ~130 dirt
setblock ~163 ~119 ~53 dirt
setblock ~163 ~119 ~54 dirt
setblock ~163 ~119 ~55 dirt
setblock ~163 ~119 ~71 dirt
setblock ~163 ~119 ~72 dirt
setblock ~163 ~119 ~73 dirt
setblock ~163 ~119 ~74 dirt
setblock ~163 ~119 ~75 dirt
setblock ~163 ~119 ~76 dirt
setblock ~163 ~119 ~77 dirt
setblock ~163 ~119 ~78 dirt
setblock ~163 ~119 ~79 dirt
setblock ~163 ~119 ~80 dirt
setblock ~163 ~119 ~81 dirt
setblock ~163 ~119 ~82 dirt
setblock ~163 ~119 ~83 dirt
setblock ~163 ~119 ~84 dirt
setblock ~163 ~119 ~85 dirt
setblock ~163 ~119 ~86 dirt
setblock ~163 ~119 ~87 dirt
setblock ~163 ~119 ~88 dirt
setblock ~163 ~119 ~89 dirt
setblock ~163 ~119 ~90 dirt
setblock ~163 ~119 ~91 dirt
setblock ~163 ~119 ~92 dirt
setblock ~163 ~119 ~93 dirt
setblock ~163 ~119 ~94 dirt
setblock ~163 ~119 ~95 dirt
setblock ~163 ~119 ~96 dirt
setblock ~163 ~119 ~97 dirt
setblock ~163 ~119 ~98 dirt
setblock ~163 ~119 ~99 dirt
setblock ~163 ~119 ~100 dirt
setblock ~163 ~119 ~101 dirt
setblock ~163 ~119 ~102 dirt
setblock ~163 ~119 ~103 dirt
setblock ~163 ~119 ~104 dirt
setblock ~163 ~119 ~118 dirt
setblock ~163 ~119 ~120 dirt
setblock ~163 ~119 ~121 dirt
setblock ~163 ~119 ~122 dirt
setblock ~163 ~119 ~123 dirt
setblock ~163 ~119 ~124 dirt
setblock ~163 ~119 ~125 dirt
setblock ~163 ~119 ~126 dirt
setblock ~163 ~119 ~127 dirt
setblock ~163 ~119 ~128 dirt
setblock ~163 ~119 ~129 dirt
setblock ~163 ~119 ~130 dirt
setblock ~163 ~119 ~131 dirt
setblock ~163 ~120 ~53 dirt
setblock ~163 ~120 ~54 dirt
setblock ~163 ~120 ~55 dirt
setblock ~163 ~120 ~56 dirt
setblock ~163 ~120 ~70 dirt
setblock ~163 ~120 ~71 dirt
setblock ~163 ~120 ~72 dirt
setblock ~163 ~120 ~73 dirt
setblock ~163 ~120 ~74 dirt
setblock ~163 ~120 ~75 dirt
setblock ~163 ~120 ~76 dirt
setblock ~163 ~120 ~77 dirt
setblock ~163 ~120 ~78 dirt
setblock ~163 ~120 ~79 dirt
setblock ~163 ~120 ~80 dirt
setblock ~163 ~120 ~81 dirt
setblock ~163 ~120 ~82 dirt
setblock ~163 ~120 ~83 dirt
setblock ~163 ~120 ~84 dirt
setblock ~163 ~120 ~85 dirt
setblock ~163 ~120 ~86 dirt
setblock ~163 ~120 ~87 dirt
setblock ~163 ~120 ~88 dirt
setblock ~163 ~120 ~89 dirt
setblock ~163 ~120 ~90 dirt
setblock ~163 ~120 ~91 dirt
setblock ~163 ~120 ~92 dirt
setblock ~163 ~120 ~93 dirt
setblock ~163 ~120 ~94 dirt
setblock ~163 ~120 ~95 dirt
setblock ~163 ~120 ~96 dirt
setblock ~163 ~120 ~97 dirt
setblock ~163 ~120 ~98 dirt
setblock ~163 ~120 ~99 dirt
setblock ~163 ~120 ~100 dirt
setblock ~163 ~120 ~101 dirt
setblock ~163 ~120 ~102 dirt
setblock ~163 ~120 ~103 dirt
setblock ~163 ~120 ~104 dirt
setblock ~163 ~120 ~118 dirt
setblock ~163 ~120 ~119 dirt
setblock ~163 ~120 ~120 dirt
setblock ~163 ~120 ~121 dirt
setblock ~163 ~120 ~122 dirt
setblock ~163 ~120 ~123 dirt
setblock ~163 ~120 ~124 dirt
setblock ~163 ~120 ~125 dirt
setblock ~163 ~120 ~126 dirt
setblock ~163 ~120 ~127 dirt
setblock ~163 ~120 ~128 dirt
setblock ~163 ~120 ~129 dirt
setblock ~163 ~120 ~130 dirt
setblock ~163 ~120 ~131 dirt
setblock ~163 ~120 ~132 dirt
setblock ~163 ~121 ~52 dirt
setblock ~163 ~121 ~53 dirt
setblock ~163 ~121 ~54 dirt
setblock ~163 ~121 ~55 dirt
setblock ~163 ~121 ~56 dirt
setblock ~163 ~121 ~67 dirt
setblock ~163 ~121 ~68 dirt
setblock ~163 ~121 ~70 dirt
setblock ~163 ~121 ~71 dirt
setblock ~163 ~121 ~72 dirt
setblock ~163 ~121 ~73 dirt
setblock ~163 ~121 ~74 dirt
setblock ~163 ~121 ~75 dirt
setblock ~163 ~121 ~76 dirt
setblock ~163 ~121 ~77 dirt
setblock ~163 ~121 ~78 dirt
setblock ~163 ~121 ~79 dirt
setblock ~163 ~121 ~80 dirt
setblock ~163 ~121 ~81 dirt
setblock ~163 ~121 ~82 dirt
setblock ~163 ~121 ~83 dirt
setblock ~163 ~121 ~84 dirt
setblock ~163 ~121 ~85 dirt
setblock ~163 ~121 ~86 dirt
setblock ~163 ~121 ~87 dirt
setblock ~163 ~121 ~88 dirt
setblock ~163 ~121 ~89 dirt
setblock ~163 ~121 ~90 dirt
setblock ~163 ~121 ~91 dirt
setblock ~163 ~121 ~92 dirt
setblock ~163 ~121 ~93 dirt
setblock ~163 ~121 ~94 dirt
setblock ~163 ~121 ~95 dirt
setblock ~163 ~121 ~96 dirt
setblock ~163 ~121 ~97 dirt
setblock ~163 ~121 ~98 dirt
setblock ~163 ~121 ~99 dirt
setblock ~163 ~121 ~100 dirt
setblock ~163 ~121 ~101 dirt
setblock ~163 ~121 ~102 dirt
setblock ~163 ~121 ~103 dirt
setblock ~163 ~121 ~104 dirt
setblock ~163 ~121 ~105 dirt
setblock ~163 ~121 ~106 dirt
setblock ~163 ~121 ~117 dirt
setblock ~163 ~121 ~118 dirt
setblock ~163 ~121 ~119 dirt
setblock ~163 ~121 ~120 dirt
setblock ~163 ~121 ~121 dirt
setblock ~163 ~121 ~122 dirt
setblock ~163 ~121 ~123 dirt
setblock ~163 ~121 ~124 dirt
setblock ~163 ~121 ~125 dirt
setblock ~163 ~121 ~126 dirt
setblock ~163 ~121 ~127 dirt
setblock ~163 ~121 ~128 dirt
setblock ~163 ~121 ~129 dirt
setblock ~163 ~121 ~130 dirt
setblock ~163 ~121 ~131 dirt
setblock ~163 ~121 ~132 dirt
setblock ~163 ~121 ~133 dirt
setblock ~163 ~122 ~52 dirt
setblock ~163 ~122 ~53 dirt
setblock ~163 ~122 ~54 dirt
setblock ~163 ~122 ~55 dirt
setblock ~163 ~122 ~56 dirt
setblock ~163 ~122 ~67 dirt
setblock ~163 ~122 ~68 dirt
setblock ~163 ~122 ~70 dirt
setblock ~163 ~122 ~71 dirt
setblock ~163 ~122 ~72 dirt
setblock ~163 ~122 ~73 dirt
setblock ~163 ~122 ~74 dirt
setblock ~163 ~122 ~75 dirt
setblock ~163 ~122 ~76 dirt
setblock ~163 ~122 ~77 dirt
setblock ~163 ~122 ~78 dirt
setblock ~163 ~122 ~79 dirt
setblock ~163 ~122 ~80 dirt
setblock ~163 ~122 ~81 dirt
setblock ~163 ~122 ~82 dirt
setblock ~163 ~122 ~83 dirt
setblock ~163 ~122 ~84 dirt
setblock ~163 ~122 ~85 dirt
setblock ~163 ~122 ~86 dirt
setblock ~163 ~122 ~87 dirt
setblock ~163 ~122 ~88 dirt
setblock ~163 ~122 ~89 dirt
setblock ~163 ~122 ~90 dirt
setblock ~163 ~122 ~91 dirt
setblock ~163 ~122 ~92 dirt
setblock ~163 ~122 ~93 dirt
setblock ~163 ~122 ~94 dirt
setblock ~163 ~122 ~95 dirt
setblock ~163 ~122 ~96 dirt
setblock ~163 ~122 ~97 dirt
setblock ~163 ~122 ~98 dirt
setblock ~163 ~122 ~99 dirt
setblock ~163 ~122 ~100 dirt
setblock ~163 ~122 ~101 dirt
setblock ~163 ~122 ~102 dirt
setblock ~163 ~122 ~103 dirt
setblock ~163 ~122 ~104 dirt
setblock ~163 ~122 ~105 dirt
setblock ~163 ~122 ~106 dirt
setblock ~163 ~122 ~117 dirt
setblock ~163 ~122 ~118 dirt
setblock ~163 ~122 ~119 dirt
setblock ~163 ~122 ~120 dirt
setblock ~163 ~122 ~121 dirt
setblock ~163 ~122 ~122 dirt
setblock ~163 ~122 ~123 dirt
setblock ~163 ~122 ~124 dirt
setblock ~163 ~122 ~125 dirt
setblock ~163 ~122 ~126 dirt
setblock ~163 ~122 ~127 dirt
setblock ~163 ~122 ~128 dirt
setblock ~163 ~122 ~129 dirt
setblock ~163 ~122 ~130 dirt
setblock ~163 ~122 ~131 dirt
setblock ~163 ~122 ~132 dirt
setblock ~163 ~122 ~133 dirt
setblock ~163 ~123 ~52 dirt
setblock ~163 ~123 ~53 dirt
setblock ~163 ~123 ~54 dirt
setblock ~163 ~123 ~55 dirt
setblock ~163 ~123 ~56 dirt
setblock ~163 ~123 ~67 grass_block
setblock ~163 ~123 ~68 grass_block
setblock ~163 ~123 ~70 grass_block
setblock ~163 ~123 ~71 grass_block
setblock ~163 ~123 ~72 grass_block
setblock ~163 ~123 ~73 grass_block
setblock ~163 ~123 ~74 grass_block
setblock ~163 ~123 ~75 dirt
setblock ~163 ~123 ~76 dirt
setblock ~163 ~123 ~77 dirt
setblock ~163 ~123 ~78 dirt
setblock ~163 ~123 ~79 dirt
setblock ~163 ~123 ~80 dirt
setblock ~163 ~123 ~81 dirt
setblock ~163 ~123 ~82 dirt
setblock ~163 ~123 ~83 dirt
setblock ~163 ~123 ~84 dirt
setblock ~163 ~123 ~85 dirt
setblock ~163 ~123 ~86 dirt
setblock ~163 ~123 ~87 dirt
setblock ~163 ~123 ~88 dirt
setblock ~163 ~123 ~89 dirt
setblock ~163 ~123 ~90 dirt
setblock ~163 ~123 ~91 dirt
setblock ~163 ~123 ~92 dirt
setblock ~163 ~123 ~93 dirt
setblock ~163 ~123 ~94 dirt
setblock ~163 ~123 ~95 dirt
setblock ~163 ~123 ~96 dirt
setblock ~163 ~123 ~97 dirt
setblock ~163 ~123 ~98 dirt
setblock ~163 ~123 ~99 dirt
setblock ~163 ~123 ~100 dirt
setblock ~163 ~123 ~101 dirt
setblock ~163 ~123 ~102 dirt
setblock ~163 ~123 ~103 dirt
setblock ~163 ~123 ~104 dirt
setblock ~163 ~123 ~105 dirt
setblock ~163 ~123 ~106 dirt
setblock ~163 ~123 ~117 dirt
setblock ~163 ~123 ~118 dirt
setblock ~163 ~123 ~119 dirt
setblock ~163 ~123 ~120 dirt
setblock ~163 ~123 ~121 dirt
setblock ~163 ~123 ~122 dirt
setblock ~163 ~123 ~123 dirt
setblock ~163 ~123 ~124 dirt
setblock ~163 ~123 ~125 dirt
setblock ~163 ~123 ~126 dirt
setblock ~163 ~123 ~127 dirt
setblock ~163 ~123 ~128 dirt
setblock ~163 ~123 ~129 dirt
setblock ~163 ~123 ~130 dirt
setblock ~163 ~123 ~131 dirt
setblock ~163 ~123 ~132 dirt
setblock ~163 ~123 ~133 dirt
setblock ~163 ~124 ~52 dirt
setblock ~163 ~124 ~53 dirt
setblock ~163 ~124 ~54 dirt
setblock ~163 ~124 ~55 dirt
setblock ~163 ~124 ~56 dirt
setblock ~163 ~124 ~75 grass_block
setblock ~163 ~124 ~76 grass_block
setblock ~163 ~124 ~77 grass_block
setblock ~163 ~124 ~78 grass_block
setblock ~163 ~124 ~79 dirt
setblock ~163 ~124 ~80 dirt
setblock ~163 ~124 ~81 dirt
setblock ~163 ~124 ~82 dirt
setblock ~163 ~124 ~83 dirt
setblock ~163 ~124 ~84 dirt
setblock ~163 ~124 ~85 dirt
setblock ~163 ~124 ~86 dirt
setblock ~163 ~124 ~87 dirt
setblock ~163 ~124 ~88 dirt
setblock ~163 ~124 ~89 dirt
setblock ~163 ~124 ~90 dirt
setblock ~163 ~124 ~91 dirt
setblock ~163 ~124 ~92 dirt
setblock ~163 ~124 ~93 dirt
setblock ~163 ~124 ~94 dirt
setblock ~163 ~124 ~95 dirt
setblock ~163 ~124 ~96 dirt
setblock ~163 ~124 ~97 dirt
setblock ~163 ~124 ~98 dirt
setblock ~163 ~124 ~99 dirt
setblock ~163 ~124 ~100 dirt
setblock ~163 ~124 ~101 dirt
setblock ~163 ~124 ~102 dirt
setblock ~163 ~124 ~103 dirt
setblock ~163 ~124 ~104 dirt
setblock ~163 ~124 ~105 dirt
setblock ~163 ~124 ~106 dirt
setblock ~163 ~124 ~117 dirt
setblock ~163 ~124 ~118 dirt
setblock ~163 ~124 ~119 dirt
setblock ~163 ~124 ~120 dirt
setblock ~163 ~124 ~121 dirt
setblock ~163 ~124 ~122 dirt
setblock ~163 ~124 ~123 dirt
setblock ~163 ~124 ~124 dirt
setblock ~163 ~124 ~125 dirt
setblock ~163 ~124 ~126 dirt
setblock ~163 ~124 ~127 dirt
setblock ~163 ~124 ~128 dirt
setblock ~163 ~124 ~129 dirt
setblock ~163 ~124 ~130 dirt
setblock ~163 ~124 ~131 dirt
setblock ~163 ~124 ~132 dirt
setblock ~163 ~124 ~133 dirt
setblock ~163 ~125 ~52 dirt
setblock ~163 ~125 ~53 dirt
setblock ~163 ~125 ~54 dirt
setblock ~163 ~125 ~55 grass_block
setblock ~163 ~125 ~56 grass_block
setblock ~163 ~125 ~77 short_grass
setblock ~163 ~125 ~79 grass_block
setblock ~163 ~125 ~80 grass_block
setblock ~163 ~125 ~81 dirt
setblock ~163 ~125 ~82 dirt
setblock ~163 ~125 ~83 dirt
setblock ~163 ~125 ~84 dirt
setblock ~163 ~125 ~85 dirt
setblock ~163 ~125 ~86 dirt
setblock ~163 ~125 ~87 dirt
setblock ~163 ~125 ~88 dirt
setblock ~163 ~125 ~89 dirt
setblock ~163 ~125 ~90 dirt
setblock ~163 ~125 ~91 dirt
setblock ~163 ~125 ~92 dirt
setblock ~163 ~125 ~93 dirt
setblock ~163 ~125 ~94 dirt
setblock ~163 ~125 ~95 dirt
setblock ~163 ~125 ~96 dirt
setblock ~163 ~125 ~97 grass_block
setblock ~163 ~125 ~98 grass_block
setblock ~163 ~125 ~99 grass_block
setblock ~163 ~125 ~100 grass_block
setblock ~163 ~125 ~101 grass_block
setblock ~163 ~125 ~102 grass_block
setblock ~163 ~125 ~103 grass_block
setblock ~163 ~125 ~104 grass_block
setblock ~163 ~125 ~105 grass_block
setblock ~163 ~125 ~106 grass_block
setblock ~163 ~125 ~117 dirt
setblock ~163 ~125 ~118 dirt
setblock ~163 ~125 ~119 dirt
setblock ~163 ~125 ~120 dirt
setblock ~163 ~125 ~121 dirt
setblock ~163 ~125 ~122 dirt
setblock ~163 ~125 ~123 dirt
setblock ~163 ~125 ~124 grass_block
setblock ~163 ~125 ~125 grass_block
setblock ~163 ~125 ~126 grass_block
setblock ~163 ~125 ~127 grass_block
setblock ~163 ~125 ~128 grass_block
setblock ~163 ~125 ~129 grass_block
setblock ~163 ~125 ~130 grass_block
setblock ~163 ~125 ~131 grass_block
setblock ~163 ~125 ~132 grass_block
setblock ~163 ~125 ~133 grass_block
setblock ~163 ~126 ~52 grass_block
setblock ~163 ~126 ~53 grass_block
setblock ~163 ~126 ~54 grass_block
setblock ~163 ~126 ~56 fern
setblock ~163 ~126 ~81 grass_block
setblock ~163 ~126 ~82 grass_block
setblock ~163 ~126 ~83 dirt
setblock ~163 ~126 ~84 dirt
setblock ~163 ~126 ~85 dirt
setblock ~163 ~126 ~86 dirt
setblock ~163 ~126 ~87 dirt
setblock ~163 ~126 ~88 dirt
setblock ~163 ~126 ~89 dirt
setblock ~163 ~126 ~90 dirt
setblock ~163 ~126 ~91 dirt
setblock ~163 ~126 ~92 dirt
setblock ~163 ~126 ~93 dirt
setblock ~163 ~126 ~94 dirt
setblock ~163 ~126 ~95 grass_block
setblock ~163 ~126 ~96 grass_block
setblock ~163 ~126 ~99 short_grass
setblock ~163 ~126 ~101 short_grass
setblock ~163 ~126 ~105 short_grass
setblock ~163 ~126 ~117 grass_block
setblock ~163 ~126 ~118 grass_block
setblock ~163 ~126 ~119 grass_block
setblock ~163 ~126 ~120 grass_block
setblock ~163 ~126 ~121 grass_block
setblock ~163 ~126 ~122 grass_block
setblock ~163 ~126 ~123 grass_block
setblock ~163 ~126 ~124 short_grass
setblock ~163 ~126 ~128 short_grass
setblock ~163 ~127 ~52 short_grass
setblock ~163 ~127 ~53 short_grass
setblock ~163 ~127 ~83 grass_block
setblock ~163 ~127 ~84 dirt
setblock ~163 ~127 ~85 dirt
setblock ~163 ~127 ~86 dirt
setblock ~163 ~127 ~87 dirt
setblock ~163 ~127 ~88 dirt
setblock ~163 ~127 ~89 dirt
setblock ~163 ~127 ~90 dirt
setblock ~163 ~127 ~91 dirt
setblock ~163 ~127 ~92 dirt
setblock ~163 ~127 ~93 grass_block
setblock ~163 ~127 ~94 grass_block
setblock ~163 ~127 ~96 fern
setblock ~163 ~127 ~118 short_grass
setblock ~163 ~127 ~119 short_grass
setblock ~163 ~127 ~121 short_grass
setblock ~163 ~127 ~123 short_grass
setblock ~163 ~128 ~83 short_grass
setblock ~163 ~128 ~84 grass_block
setblock ~163 ~128 ~85 grass_block
setblock ~163 ~128 ~86 dirt
setblock ~163 ~128 ~87 dirt
setblock ~163 ~128 ~88 dirt
setblock ~163 ~128 ~89 dirt
setblock ~163 ~128 ~90 dirt
setblock ~163 ~128 ~91 dirt
setblock ~163 ~128 ~92 grass_block
setblock ~163 ~128 ~93 short_grass
setblock ~163 ~129 ~86 grass_block
setblock ~163 ~129 ~87 dirt
setblock ~163 ~129 ~88 dirt
setblock ~163 ~129 ~89 dirt
setblock ~163 ~129 ~90 dirt
setblock ~163 ~129 ~91 grass_block
setblock ~163 ~130 ~87 grass_block
setblock ~163 ~130 ~88 grass_block
setblock ~163 ~130 ~89 dirt
setblock ~163 ~130 ~90 dirt
setblock ~163 ~131 ~89 grass_block
setblock ~163 ~131 ~90 grass_block
setblock ~163 ~132 ~90 short_grass
setblock ~164 ~105 ~77 dirt
setblock ~164 ~106 ~77 dirt
setblock ~164 ~106 ~79 dirt
setblock ~164 ~107 ~76 dirt
setblock ~164 ~107 ~77 dirt
setblock ~164 ~107 ~78 dirt
setblock ~164 ~107 ~79 dirt
setblock ~164 ~108 ~76 dirt
setblock ~164 ~108 ~77 dirt
setblock ~164 ~108 ~78 dirt
setblock ~164 ~108 ~79 dirt
setblock ~164 ~108 ~80 dirt
setblock ~164 ~109 ~76 dirt
setblock ~164 ~109 ~77 dirt
setblock ~164 ~109 ~78 dirt
setblock ~164 ~109 ~79 dirt
setblock ~164 ~109 ~80 dirt
setblock ~164 ~109 ~83 dirt
setblock ~164 ~109 ~85 dirt
setblock ~164 ~110 ~76 dirt
setblock ~164 ~110 ~77 dirt
setblock ~164 ~110 ~78 dirt
setblock ~164 ~110 ~79 dirt
setblock ~164 ~110 ~80 dirt
setblock ~164 ~110 ~81 dirt
setblock ~164 ~110 ~82 dirt
setblock ~164 ~110 ~83 dirt
setblock ~164 ~110 ~84 dirt
setblock ~164 ~110 ~85 dirt
setblock ~164 ~111 ~75 dirt
setblock ~164 ~111 ~76 dirt
setblock ~164 ~111 ~77 dirt
setblock ~164 ~111 ~78 dirt
setblock ~164 ~111 ~79 dirt
setblock ~164 ~111 ~80 dirt
setblock ~164 ~111 ~81 dirt
setblock ~164 ~111 ~82 dirt
setblock ~164 ~111 ~83 dirt
setblock ~164 ~111 ~84 dirt
setblock ~164 ~111 ~85 dirt
setblock ~164 ~111 ~86 dirt
setblock ~164 ~112 ~74 dirt
setblock ~164 ~112 ~75 dirt
setblock ~164 ~112 ~76 dirt
setblock ~164 ~112 ~77 dirt
setblock ~164 ~112 ~78 dirt
setblock ~164 ~112 ~79 dirt
setblock ~164 ~112 ~80 dirt
setblock ~164 ~112 ~81 dirt
setblock ~164 ~112 ~82 dirt
setblock ~164 ~112 ~83 dirt
setblock ~164 ~112 ~84 dirt
setblock ~164 ~112 ~85 dirt
setblock ~164 ~112 ~86 dirt
setblock ~164 ~113 ~74 dirt
setblock ~164 ~113 ~75 dirt
setblock ~164 ~113 ~76 dirt
setblock ~164 ~113 ~77 dirt
setblock ~164 ~113 ~78 dirt
setblock ~164 ~113 ~79 dirt
setblock ~164 ~113 ~80 dirt
setblock ~164 ~113 ~81 dirt
setblock ~164 ~113 ~82 dirt
setblock ~164 ~113 ~83 dirt
setblock ~164 ~113 ~84 dirt
setblock ~164 ~113 ~85 dirt
setblock ~164 ~113 ~86 dirt
setblock ~164 ~114 ~73 dirt
setblock ~164 ~114 ~74 dirt
setblock ~164 ~114 ~75 dirt
setblock ~164 ~114 ~76 dirt
setblock ~164 ~114 ~77 dirt
setblock ~164 ~114 ~78 dirt
setblock ~164 ~114 ~79 dirt
setblock ~164 ~114 ~80 dirt
setblock ~164 ~114 ~81 dirt
setblock ~164 ~114 ~82 dirt
setblock ~164 ~114 ~83 dirt
setblock ~164 ~114 ~84 dirt
setblock ~164 ~114 ~85 dirt
setblock ~164 ~114 ~86 dirt
setblock ~164 ~114 ~87 dirt
setblock ~164 ~115 ~72 dirt
setblock ~164 ~115 ~73 dirt
setblock ~164 ~115 ~74 dirt
setblock ~164 ~115 ~75 dirt
setblock ~164 ~115 ~76 dirt
setblock ~164 ~115 ~77 dirt
setblock ~164 ~115 ~78 dirt
setblock ~164 ~115 ~79 dirt
setblock ~164 ~115 ~80 dirt
setblock ~164 ~115 ~81 dirt
setblock ~164 ~115 ~82 dirt
setblock ~164 ~115 ~83 dirt
setblock ~164 ~115 ~84 dirt
setblock ~164 ~115 ~85 dirt
setblock ~164 ~115 ~86 dirt
setblock ~164 ~115 ~87 dirt
setblock ~164 ~116 ~54 dirt
setblock ~164 ~116 ~72 dirt
setblock ~164 ~116 ~73 dirt
setblock ~164 ~116 ~74 dirt
setblock ~164 ~116 ~75 dirt
setblock ~164 ~116 ~76 dirt
setblock ~164 ~116 ~77 dirt
setblock ~164 ~116 ~78 dirt
setblock ~164 ~116 ~79 dirt
setblock ~164 ~116 ~80 dirt
setblock ~164 ~116 ~81 dirt
setblock ~164 ~116 ~82 dirt
setblock ~164 ~116 ~83 dirt
setblock ~164 ~116 ~84 dirt
setblock ~164 ~116 ~85 dirt
setblock ~164 ~116 ~86 dirt
setblock ~164 ~116 ~87 dirt
setblock ~164 ~116 ~88 dirt
setblock ~164 ~116 ~89 dirt
setblock ~164 ~116 ~97 dirt
setblock ~164 ~116 ~100 dirt
setblock ~164 ~117 ~53 dirt
setblock ~164 ~117 ~54 dirt
setblock ~164 ~117 ~55 dirt
setblock ~164 ~117 ~72 dirt
setblock ~164 ~117 ~73 dirt
setblock ~164 ~117 ~74 dirt
setblock ~164 ~117 ~75 dirt
setblock ~164 ~117 ~76 dirt
setblock ~164 ~117 ~77 dirt
setblock ~164 ~117 ~78 dirt
setblock ~164 ~117 ~79 dirt
setblock ~164 ~117 ~80 dirt
setblock ~164 ~117 ~81 dirt
setblock ~164 ~117 ~82 dirt
setblock ~164 ~117 ~83 dirt
setblock ~164 ~117 ~84 dirt
setblock ~164 ~117 ~85 dirt
setblock ~164 ~117 ~86 dirt
setblock ~164 ~117 ~87 dirt
setblock ~164 ~117 ~88 dirt
setblock ~164 ~117 ~89 dirt
setblock ~164 ~117 ~90 dirt
setblock ~164 ~117 ~97 dirt
setblock ~164 ~117 ~99 dirt
setblock ~164 ~117 ~100 dirt
setblock ~164 ~118 ~53 dirt
setblock ~164 ~118 ~54 dirt
setblock ~164 ~118 ~55 dirt
setblock ~164 ~118 ~71 dirt
setblock ~164 ~118 ~72 dirt
setblock ~164 ~118 ~73 dirt
setblock ~164 ~118 ~74 dirt
setblock ~164 ~118 ~75 dirt
setblock ~164 ~118 ~76 dirt
setblock ~164 ~118 ~77 dirt
setblock ~164 ~118 ~78 dirt
setblock ~164 ~118 ~79 dirt
setblock ~164 ~118 ~80 dirt
setblock ~164 ~118 ~81 dirt
setblock ~164 ~118 ~82 dirt
setblock ~164 ~118 ~83 dirt
setblock ~164 ~118 ~84 dirt
setblock ~164 ~118 ~85 dirt
setblock ~164 ~118 ~86 dirt
setblock ~164 ~118 ~87 dirt
setblock ~164 ~118 ~88 dirt
setblock ~164 ~118 ~89 dirt
setblock ~164 ~118 ~90 dirt
setblock ~164 ~118 ~96 dirt
setblock ~164 ~118 ~97 dirt
setblock ~164 ~118 ~98 dirt
setblock ~164 ~118 ~99 dirt
setblock ~164 ~118 ~100 dirt
setblock ~164 ~118 ~101 dirt
setblock ~164 ~118 ~104 dirt
setblock ~164 ~118 ~129 dirt
setblock ~164 ~119 ~52 dirt
setblock ~164 ~119 ~53 dirt
setblock ~164 ~119 ~54 dirt
setblock ~164 ~119 ~55 dirt
setblock ~164 ~119 ~56 dirt
setblock ~164 ~119 ~71 dirt
setblock ~164 ~119 ~72 dirt
setblock ~164 ~119 ~73 dirt
setblock ~164 ~119 ~74 dirt
setblock ~164 ~119 ~75 dirt
setblock ~164 ~119 ~76 dirt
setblock ~164 ~119 ~77 dirt
setblock ~164 ~119 ~78 dirt
setblock ~164 ~119 ~79 dirt
setblock ~164 ~119 ~80 dirt
setblock ~164 ~119 ~81 dirt
setblock ~164 ~119 ~82 dirt
setblock ~164 ~119 ~83 dirt
setblock ~164 ~119 ~84 dirt
setblock ~164 ~119 ~85 dirt
setblock ~164 ~119 ~86 dirt
setblock ~164 ~119 ~87 dirt
setblock ~164 ~119 ~88 dirt
setblock ~164 ~119 ~89 dirt
setblock ~164 ~119 ~90 dirt
setblock ~164 ~119 ~91 dirt
setblock ~164 ~119 ~93 dirt
setblock ~164 ~119 ~95 dirt
setblock ~164 ~119 ~96 dirt
setblock ~164 ~119 ~97 dirt
setblock ~164 ~119 ~98 dirt
setblock ~164 ~119 ~99 dirt
setblock ~164 ~119 ~100 dirt
setblock ~164 ~119 ~101 dirt
setblock ~164 ~119 ~102 dirt
setblock ~164 ~119 ~104 dirt
setblock ~164 ~119 ~105 dirt
setblock ~164 ~119 ~122 dirt
setblock ~164 ~119 ~125 dirt
setblock ~164 ~119 ~128 dirt
setblock ~164 ~119 ~129 dirt
setblock ~164 ~119 ~130 dirt
setblock ~164 ~120 ~52 dirt
setblock ~164 ~120 ~53 dirt
setblock ~164 ~120 ~54 dirt
setblock ~164 ~120 ~55 dirt
setblock ~164 ~120 ~56 dirt
setblock ~164 ~120 ~71 dirt
setblock ~164 ~120 ~72 dirt
setblock ~164 ~120 ~73 dirt
setblock ~164 ~120 ~74 dirt
setblock ~164 ~120 ~75 dirt
setblock ~164 ~120 ~76 dirt
setblock ~164 ~120 ~77 dirt
setblock ~164 ~120 ~78 dirt
setblock ~164 ~120 ~79 dirt
setblock ~164 ~120 ~80 dirt
setblock ~164 ~120 ~81 dirt
setblock ~164 ~120 ~82 dirt
setblock ~164 ~120 ~83 dirt
setblock ~164 ~120 ~84 dirt
setblock ~164 ~120 ~85 dirt
setblock ~164 ~120 ~86 dirt
setblock ~164 ~120 ~87 dirt
setblock ~164 ~120 ~88 dirt
setblock ~164 ~120 ~89 dirt
setblock ~164 ~120 ~90 dirt
setblock ~164 ~120 ~91 dirt
setblock ~164 ~120 ~92 dirt
setblock ~164 ~120 ~93 dirt
setblock ~164 ~120 ~94 dirt
setblock ~164 ~120 ~95 dirt
setblock ~164 ~120 ~96 dirt
setblock ~164 ~120 ~97 dirt
setblock ~164 ~120 ~98 dirt
setblock ~164 ~120 ~99 dirt
setblock ~164 ~120 ~100 dirt
setblock ~164 ~120 ~101 dirt
setblock ~164 ~120 ~102 dirt
setblock ~164 ~120 ~103 dirt
setblock ~164 ~120 ~104 dirt
setblock ~164 ~120 ~105 dirt
setblock ~164 ~120 ~106 dirt
setblock ~164 ~120 ~120 dirt
setblock ~164 ~120 ~121 dirt
setblock ~164 ~120 ~122 dirt
setblock ~164 ~120 ~125 dirt
setblock ~164 ~120 ~128 dirt
setblock ~164 ~120 ~129 dirt
setblock ~164 ~120 ~130 dirt
setblock ~164 ~121 ~52 dirt
setblock ~164 ~121 ~53 dirt
setblock ~164 ~121 ~54 dirt
setblock ~164 ~121 ~55 dirt
setblock ~164 ~121 ~56 dirt
setblock ~164 ~121 ~70 dirt
setblock ~164 ~121 ~71 dirt
setblock ~164 ~121 ~72 dirt
setblock ~164 ~121 ~73 dirt
setblock ~164 ~121 ~74 dirt
setblock ~164 ~121 ~75 dirt
setblock ~164 ~121 ~76 dirt
setblock ~164 ~121 ~77 dirt
setblock ~164 ~121 ~78 dirt
setblock ~164 ~121 ~79 dirt
setblock ~164 ~121 ~80 dirt
setblock ~164 ~121 ~81 dirt
setblock ~164 ~121 ~82 dirt
setblock ~164 ~121 ~83 dirt
setblock ~164 ~121 ~84 dirt
setblock ~164 ~121 ~85 dirt
setblock ~164 ~121 ~86 dirt
setblock ~164 ~121 ~87 dirt
setblock ~164 ~121 ~88 dirt
setblock ~164 ~121 ~89 dirt
setblock ~164 ~121 ~90 dirt
setblock ~164 ~121 ~91 dirt
setblock ~164 ~121 ~92 dirt
setblock ~164 ~121 ~93 dirt
setblock ~164 ~121 ~94 dirt
setblock ~164 ~121 ~95 dirt
setblock ~164 ~121 ~96 dirt
setblock ~164 ~121 ~97 dirt
setblock ~164 ~121 ~98 dirt
setblock ~164 ~121 ~99 dirt
setblock ~164 ~121 ~100 dirt
setblock ~164 ~121 ~101 dirt
setblock ~164 ~121 ~102 dirt
setblock ~164 ~121 ~103 dirt
setblock ~164 ~121 ~104 dirt
setblock ~164 ~121 ~105 dirt
setblock ~164 ~121 ~106 dirt
setblock ~164 ~121 ~118 dirt
setblock ~164 ~121 ~119 dirt
setblock ~164 ~121 ~120 dirt
setblock ~164 ~121 ~121 dirt
setblock ~164 ~121 ~122 dirt
setblock ~164 ~121 ~124 dirt
setblock ~164 ~121 ~125 dirt
setblock ~164 ~121 ~126 dirt
setblock ~164 ~121 ~128 dirt
setblock ~164 ~121 ~129 dirt
setblock ~164 ~121 ~130 dirt
setblock ~164 ~121 ~132 dirt
setblock ~164 ~122 ~52 dirt
setblock ~164 ~122 ~53 dirt
setblock ~164 ~122 ~54 dirt
setblock ~164 ~122 ~55 dirt
setblock ~164 ~122 ~56 dirt
setblock ~164 ~122 ~70 dirt
setblock ~164 ~122 ~71 dirt
setblock ~164 ~122 ~72 dirt
setblock ~164 ~122 ~73 dirt
setblock ~164 ~122 ~74 dirt
setblock ~164 ~122 ~75 dirt
setblock ~164 ~122 ~76 dirt
setblock ~164 ~122 ~77 dirt
setblock ~164 ~122 ~78 dirt
setblock ~164 ~122 ~79 dirt
setblock ~164 ~122 ~80 dirt
setblock ~164 ~122 ~81 dirt
setblock ~164 ~122 ~82 dirt
setblock ~164 ~122 ~83 dirt
setblock ~164 ~122 ~84 dirt
setblock ~164 ~122 ~85 dirt
setblock ~164 ~122 ~86 dirt
setblock ~164 ~122 ~87 dirt
setblock ~164 ~122 ~88 dirt
setblock ~164 ~122 ~89 dirt
setblock ~164 ~122 ~90 dirt
setblock ~164 ~122 ~91 dirt
setblock ~164 ~122 ~92 dirt
setblock ~164 ~122 ~93 dirt
setblock ~164 ~122 ~94 dirt
setblock ~164 ~122 ~95 dirt
setblock ~164 ~122 ~96 dirt
setblock ~164 ~122 ~97 dirt
setblock ~164 ~122 ~98 dirt
setblock ~164 ~122 ~99 dirt
setblock ~164 ~122 ~100 dirt
setblock ~164 ~122 ~101 dirt
setblock ~164 ~122 ~102 dirt
setblock ~164 ~122 ~103 dirt
setblock ~164 ~122 ~104 dirt
setblock ~164 ~122 ~105 dirt
setblock ~164 ~122 ~106 dirt
setblock ~164 ~122 ~118 dirt
setblock ~164 ~122 ~119 dirt
setblock ~164 ~122 ~120 dirt
setblock ~164 ~122 ~121 dirt
setblock ~164 ~122 ~122 dirt
setblock ~164 ~122 ~124 dirt
setblock ~164 ~122 ~125 dirt
setblock ~164 ~122 ~126 dirt
setblock ~164 ~122 ~128 dirt
setblock ~164 ~122 ~129 dirt
setblock ~164 ~122 ~130 dirt
setblock ~164 ~122 ~132 dirt
setblock ~164 ~123 ~52 dirt
setblock ~164 ~123 ~53 dirt
setblock ~164 ~123 ~54 dirt
setblock ~164 ~123 ~55 dirt
setblock ~164 ~123 ~56 dirt
setblock ~164 ~123 ~70 grass_block
setblock ~164 ~123 ~71 grass_block
setblock ~164 ~123 ~72 grass_block
setblock ~164 ~123 ~73 dirt
setblock ~164 ~123 ~74 dirt
setblock ~164 ~123 ~75 dirt
setblock ~164 ~123 ~76 dirt
setblock ~164 ~123 ~77 dirt
setblock ~164 ~123 ~78 dirt
setblock ~164 ~123 ~79 dirt
setblock ~164 ~123 ~80 dirt
setblock ~164 ~123 ~81 dirt
setblock ~164 ~123 ~82 dirt
setblock ~164 ~123 ~83 dirt
setblock ~164 ~123 ~84 dirt
setblock ~164 ~123 ~85 dirt
setblock ~164 ~123 ~86 dirt
setblock ~164 ~123 ~87 dirt
setblock ~164 ~123 ~88 dirt
setblock ~164 ~123 ~89 dirt
setblock ~164 ~123 ~90 dirt
setblock ~164 ~123 ~91 dirt
setblock ~164 ~123 ~92 dirt
setblock ~164 ~123 ~93 dirt
setblock ~164 ~123 ~94 dirt
setblock ~164 ~123 ~95 dirt
setblock ~164 ~123 ~96 dirt
setblock ~164 ~123 ~97 dirt
setblock ~164 ~123 ~98 dirt
setblock ~164 ~123 ~99 dirt
setblock ~164 ~123 ~100 dirt
setblock ~164 ~123 ~101 dirt
setblock ~164 ~123 ~102 dirt
setblock ~164 ~123 ~103 dirt
setblock ~164 ~123 ~104 dirt
setblock ~164 ~123 ~105 dirt
setblock ~164 ~123 ~106 dirt
setblock ~164 ~123 ~118 dirt
setblock ~164 ~123 ~119 dirt
setblock ~164 ~123 ~120 dirt
setblock ~164 ~123 ~121 dirt
setblock ~164 ~123 ~122 dirt
setblock ~164 ~123 ~124 dirt
setblock ~164 ~123 ~125 dirt
setblock ~164 ~123 ~126 dirt
setblock ~164 ~123 ~128 dirt
setblock ~164 ~123 ~129 dirt
setblock ~164 ~123 ~130 dirt
setblock ~164 ~123 ~132 dirt
setblock ~164 ~124 ~52 dirt
setblock ~164 ~124 ~53 dirt
setblock ~164 ~124 ~54 dirt
setblock ~164 ~124 ~55 dirt
setblock ~164 ~124 ~56 dirt
setblock ~164 ~124 ~71 poppy
setblock ~164 ~124 ~73 grass_block
setblock ~164 ~124 ~74 grass_block
setblock ~164 ~124 ~75 grass_block
setblock ~164 ~124 ~76 grass_block
setblock ~164 ~124 ~77 grass_block
setblock ~164 ~124 ~78 dirt
setblock ~164 ~124 ~79 dirt
setblock ~164 ~124 ~80 dirt
setblock ~164 ~124 ~81 dirt
setblock ~164 ~124 ~82 dirt
setblock ~164 ~124 ~83 dirt
setblock ~164 ~124 ~84 dirt
setblock ~164 ~124 ~85 dirt
setblock ~164 ~124 ~86 dirt
setblock ~164 ~124 ~87 dirt
setblock ~164 ~124 ~88 dirt
setblock ~164 ~124 ~89 dirt
setblock ~164 ~124 ~90 dirt
setblock ~164 ~124 ~91 dirt
setblock ~164 ~124 ~92 dirt
setblock ~164 ~124 ~93 dirt
setblock ~164 ~124 ~94 dirt
setblock ~164 ~124 ~95 dirt
setblock ~164 ~124 ~96 dirt
setblock ~164 ~124 ~97 dirt
setblock ~164 ~124 ~98 dirt
setblock ~164 ~124 ~99 dirt
setblock ~164 ~124 ~100 dirt
setblock ~164 ~124 ~101 dirt
setblock ~164 ~124 ~102 dirt
setblock ~164 ~124 ~103 dirt
setblock ~164 ~124 ~104 dirt
setblock ~164 ~124 ~105 dirt
setblock ~164 ~124 ~106 dirt
setblock ~164 ~124 ~118 dirt
setblock ~164 ~124 ~119 dirt
setblock ~164 ~124 ~120 dirt
setblock ~164 ~124 ~121 dirt
setblock ~164 ~124 ~122 dirt
setblock ~164 ~124 ~124 dirt
setblock ~164 ~124 ~125 dirt
setblock ~164 ~124 ~126 dirt
setblock ~164 ~124 ~128 dirt
setblock ~164 ~124 ~129 dirt
setblock ~164 ~124 ~130 dirt
setblock ~164 ~124 ~132 dirt
setblock ~164 ~125 ~52 dirt
setblock ~164 ~125 ~53 dirt
setblock ~164 ~125 ~54 dirt
setblock ~164 ~125 ~55 dirt
setblock ~164 ~125 ~56 dirt
setblock ~164 ~125 ~74 short_grass
setblock ~164 ~125 ~78 grass_block
setblock ~164 ~125 ~79 grass_block
setblock ~164 ~125 ~80 dirt
setblock ~164 ~125 ~81 dirt
setblock ~164 ~125 ~82 dirt
setblock ~164 ~125 ~83 dirt
setblock ~164 ~125 ~84 dirt
setblock ~164 ~125 ~85 dirt
setblock ~164 ~125 ~86 dirt
setblock ~164 ~125 ~87 dirt
setblock ~164 ~125 ~88 dirt
setblock ~164 ~125 ~89 dirt
setblock ~164 ~125 ~90 dirt
setblock ~164 ~125 ~91 dirt
setblock ~164 ~125 ~92 dirt
setblock ~164 ~125 ~93 dirt
setblock ~164 ~125 ~94 dirt
setblock ~164 ~125 ~95 dirt
setblock ~164 ~125 ~96 dirt
setblock ~164 ~125 ~97 grass_block
setblock ~164 ~125 ~98 grass_block
setblock ~164 ~125 ~99 grass_block
setblock ~164 ~125 ~100 grass_block
setblock ~164 ~125 ~101 grass_block
setblock ~164 ~125 ~102 grass_block
setblock ~164 ~125 ~103 grass_block
setblock ~164 ~125 ~104 grass_block
setblock ~164 ~125 ~105 grass_block
setblock ~164 ~125 ~106 grass_block
setblock ~164 ~125 ~118 dirt
setblock ~164 ~125 ~119 dirt
setblock ~164 ~125 ~120 dirt
setblock ~164 ~125 ~121 dirt
setblock ~164 ~125 ~122 dirt
setblock ~164 ~125 ~124 grass_block
setblock ~164 ~125 ~125 grass_block
setblock ~164 ~125 ~126 grass_block
setblock ~164 ~125 ~128 grass_block
setblock ~164 ~125 ~129 grass_block
setblock ~164 ~125 ~130 grass_block
setblock ~164 ~125 ~132 grass_block
setblock ~164 ~126 ~52 dirt
setblock ~164 ~126 ~53 grass_block
setblock ~164 ~126 ~54 grass_block
setblock ~164 ~126 ~55 grass_block
setblock ~164 ~126 ~56 grass_block
setblock ~164 ~126 ~80 grass_block
setblock ~164 ~126 ~81 grass_block
setblock ~164 ~126 ~82 dirt
setblock ~164 ~126 ~83 dirt
setblock ~164 ~126 ~84 dirt
setblock ~164 ~126 ~85 dirt
setblock ~164 ~126 ~86 dirt
setblock ~164 ~126 ~87 dirt
setblock ~164 ~126 ~88 dirt
setblock ~164 ~126 ~89 dirt
setblock ~164 ~126 ~90 dirt
setblock ~164 ~126 ~91 dirt
setblock ~164 ~126 ~92 dirt
setblock ~164 ~126 ~93 dirt
setblock ~164 ~126 ~94 dirt
setblock ~164 ~126 ~95 grass_block
setblock ~164 ~126 ~96 grass_block
setblock ~164 ~126 ~97 short_grass
setblock ~164 ~126 ~98 short_grass
setblock ~164 ~126 ~103 poppy
setblock ~164 ~126 ~118 grass_block
setblock ~164 ~126 ~119 grass_block
setblock ~164 ~126 ~120 grass_block
setblock ~164 ~126 ~121 grass_block
setblock ~164 ~126 ~122 grass_block
setblock ~164 ~126 ~132 short_grass
setblock ~164 ~127 ~52 grass_block
setblock ~164 ~127 ~54 short_grass
setblock ~164 ~127 ~55 poppy
setblock ~164 ~127 ~56 short_grass
setblock ~164 ~127 ~82 grass_block
setblock ~164 ~127 ~83 grass_block
setblock ~164 ~127 ~84 dirt
setblock ~164 ~127 ~85 dirt
setblock ~164 ~127 ~86 dirt
setblock ~164 ~127 ~87 dirt
setblock ~164 ~127 ~88 dirt
setblock ~164 ~127 ~89 dirt
setblock ~164 ~127 ~90 dirt
setblock ~164 ~127 ~91 dirt
setblock ~164 ~127 ~92 dirt
setblock ~164 ~127 ~93 grass_block
setblock ~164 ~127 ~94 grass_block
setblock ~164 ~127 ~95 short_grass
setblock ~164 ~127 ~122 short_grass
setblock ~164 ~128 ~84 grass_block
setblock ~164 ~128 ~85 grass_block
setblock ~164 ~128 ~86 dirt
setblock ~164 ~128 ~87 dirt
setblock ~164 ~128 ~88 dirt
setblock ~164 ~128 ~89 dirt
setblock ~164 ~128 ~90 dirt
setblock ~164 ~128 ~91 dirt
setblock ~164 ~128 ~92 grass_block
setblock ~164 ~129 ~84 poppy
setblock ~164 ~129 ~85 fern
setblock ~164 ~129 ~86 grass_block
setblock ~164 ~129 ~87 grass_block
setblock ~164 ~129 ~88 dirt
setblock ~164 ~129 ~89 dirt
setblock ~164 ~129 ~90 dirt
setblock ~164 ~129 ~91 grass_block
setblock ~164 ~129 ~92 poppy
setblock ~164 ~130 ~87 short_grass
setblock ~164 ~130 ~88 grass_block
setblock ~164 ~130 ~89 dirt
setblock ~164 ~130 ~90 dirt
setblock ~164 ~131 ~88 short_grass
setblock ~164 ~131 ~89 grass_block
setblock ~164 ~131 ~90 grass_block
setblock ~165 ~103 ~77 dirt
setblock ~165 ~104 ~77 dirt
setblock ~165 ~105 ~76 dirt
setblock ~165 ~105 ~77 dirt
setblock ~165 ~105 ~78 dirt
setblock ~165 ~106 ~76 dirt
setblock ~165 ~106 ~77 dirt
setblock ~165 ~106 ~78 dirt
setblock ~165 ~107 ~75 dirt
setblock ~165 ~107 ~76 dirt
setblock ~165 ~107 ~77 dirt
setblock ~165 ~107 ~78 dirt
setblock ~165 ~107 ~79 dirt
setblock ~165 ~108 ~75 dirt
setblock ~165 ~108 ~76 dirt
setblock ~165 ~108 ~77 dirt
setblock ~165 ~108 ~78 dirt
setblock ~165 ~108 ~79 dirt
setblock ~165 ~109 ~75 dirt
setblock ~165 ~109 ~76 dirt
setblock ~165 ~109 ~77 dirt
setblock ~165 ~109 ~78 dirt
setblock ~165 ~109 ~79 dirt
setblock ~165 ~109 ~80 dirt
setblock ~165 ~110 ~75 dirt
setblock ~165 ~110 ~76 dirt
setblock ~165 ~110 ~77 dirt
setblock ~165 ~110 ~78 dirt
setblock ~165 ~110 ~79 dirt
setblock ~165 ~110 ~80 dirt
setblock ~165 ~110 ~81 dirt
setblock ~165 ~111 ~74 dirt
setblock ~165 ~111 ~75 dirt
setblock ~165 ~111 ~76 dirt
setblock ~165 ~111 ~77 dirt
setblock ~165 ~111 ~78 dirt
setblock ~165 ~111 ~79 dirt
setblock ~165 ~111 ~80 dirt
setblock ~165 ~111 ~81 dirt
setblock ~165 ~111 ~82 dirt
setblock ~165 ~111 ~85 dirt
setblock ~165 ~112 ~73 dirt
setblock ~165 ~112 ~74 dirt
setblock ~165 ~112 ~75 dirt
setblock ~165 ~112 ~76 dirt
setblock ~165 ~112 ~77 dirt
setblock ~165 ~112 ~78 dirt
setblock ~165 ~112 ~79 dirt
setblock ~165 ~112 ~80 dirt
setblock ~165 ~112 ~81 dirt
setblock ~165 ~112 ~82 dirt
setblock ~165 ~112 ~84 dirt
setblock ~165 ~112 ~85 dirt
setblock ~165 ~113 ~73 dirt
setblock ~165 ~113 ~74 dirt
setblock ~165 ~113 ~75 dirt
setblock ~165 ~113 ~76 dirt
setblock ~165 ~113 ~77 dirt
setblock ~165 ~113 ~78 dirt
setblock ~165 ~113 ~79 dirt
setblock ~165 ~113 ~80 dirt
setblock ~165 ~113 ~81 dirt
setblock ~165 ~113 ~82 dirt
setblock ~165 ~113 ~83 dirt
setblock ~165 ~113 ~84 dirt
setblock ~165 ~113 ~85 dirt
setblock ~165 ~114 ~72 dirt
setblock ~165 ~114 ~73 dirt
setblock ~165 ~114 ~74 dirt
setblock ~165 ~114 ~75 dirt
setblock ~165 ~114 ~76 dirt
setblock ~165 ~114 ~77 dirt
setblock ~165 ~114 ~78 dirt
setblock ~165 ~114 ~79 dirt
setblock ~165 ~114 ~80 dirt
setblock ~165 ~114 ~81 dirt
setblock ~165 ~114 ~82 dirt
setblock ~165 ~114 ~83 dirt
setblock ~165 ~114 ~84 dirt
setblock ~165 ~114 ~85 dirt
setblock ~165 ~114 ~86 dirt
setblock ~165 ~115 ~72 dirt
setblock ~165 ~115 ~73 dirt
setblock ~165 ~115 ~74 dirt
setblock ~165 ~115 ~75 dirt
setblock ~165 ~115 ~76 dirt
setblock ~165 ~115 ~77 dirt
setblock ~165 ~115 ~78 dirt
setblock ~165 ~115 ~79 dirt
setblock ~165 ~115 ~80 dirt
setblock ~165 ~115 ~81 dirt
setblock ~165 ~115 ~82 dirt
setblock ~165 ~115 ~83 dirt
setblock ~165 ~115 ~84 dirt
setblock ~165 ~115 ~85 dirt
setblock ~165 ~115 ~86 dirt
setblock ~165 ~115 ~105 dirt
setblock ~165 ~116 ~72 dirt
setblock ~165 ~116 ~73 dirt
setblock ~165 ~116 ~74 dirt
setblock ~165 ~116 ~75 dirt
setblock ~165 ~116 ~76 dirt
setblock ~165 ~116 ~77 dirt
setblock ~165 ~116 ~78 dirt
setblock ~165 ~116 ~79 dirt
setblock ~165 ~116 ~80 dirt
setblock ~165 ~116 ~81 dirt
setblock ~165 ~116 ~82 dirt
setblock ~165 ~116 ~83 dirt
setblock ~165 ~116 ~84 dirt
setblock ~165 ~116 ~85 dirt
setblock ~165 ~116 ~86 dirt
setblock ~165 ~116 ~87 dirt
setblock ~165 ~116 ~104 dirt
setblock ~165 ~116 ~105 dirt
setblock ~165 ~117 ~54 dirt
setblock ~165 ~117 ~71 dirt
setblock ~165 ~117 ~72 dirt
setblock ~165 ~117 ~73 dirt
setblock ~165 ~117 ~74 dirt
setblock ~165 ~117 ~75 dirt
setblock ~165 ~117 ~76 dirt
setblock ~165 ~117 ~77 dirt
setblock ~165 ~117 ~78 dirt
setblock ~165 ~117 ~79 dirt
setblock ~165 ~117 ~80 dirt
setblock ~165 ~117 ~81 dirt
setblock ~165 ~117 ~82 dirt
setblock ~165 ~117 ~83 dirt
setblock ~165 ~117 ~84 dirt
setblock ~165 ~117 ~85 dirt
setblock ~165 ~117 ~86 dirt
setblock ~165 ~117 ~87 dirt
setblock ~165 ~117 ~88 dirt
setblock ~165 ~117 ~104 dirt
setblock ~165 ~117 ~105 dirt
setblock ~165 ~118 ~54 dirt
setblock ~165 ~118 ~71 dirt
setblock ~165 ~118 ~72 dirt
setblock ~165 ~118 ~73 dirt
setblock ~165 ~118 ~74 dirt
setblock ~165 ~118 ~75 dirt
setblock ~165 ~118 ~76 dirt
setblock ~165 ~118 ~77 dirt
setblock ~165 ~118 ~78 dirt
setblock ~165 ~118 ~79 dirt
setblock ~165 ~118 ~80 dirt
setblock ~165 ~118 ~81 dirt
setblock ~165 ~118 ~82 dirt
setblock ~165 ~118 ~83 dirt
setblock ~165 ~118 ~84 dirt
setblock ~165 ~118 ~85 dirt
setblock ~165 ~118 ~86 dirt
setblock ~165 ~118 ~87 dirt
setblock ~165 ~118 ~88 dirt
setblock ~165 ~118 ~100 dirt
setblock ~165 ~118 ~103 dirt
setblock ~165 ~118 ~104 dirt
setblock ~165 ~118 ~105 dirt
setblock ~165 ~119 ~53 dirt
setblock ~165 ~119 ~54 dirt
setblock ~165 ~119 ~55 dirt
setblock ~165 ~119 ~71 dirt
setblock ~165 ~119 ~72 dirt
setblock ~165 ~119 ~73 dirt
setblock ~165 ~119 ~74 dirt
setblock ~165 ~119 ~75 dirt
setblock ~165 ~119 ~76 dirt
setblock ~165 ~119 ~77 dirt
setblock ~165 ~119 ~78 dirt
setblock ~165 ~119 ~79 dirt
setblock ~165 ~119 ~80 dirt
setblock ~165 ~119 ~81 dirt
setblock ~165 ~119 ~82 dirt
setblock ~165 ~119 ~83 dirt
setblock ~165 ~119 ~84 dirt
setblock ~165 ~119 ~85 dirt
setblock ~165 ~119 ~86 dirt
setblock ~165 ~119 ~87 dirt
setblock ~165 ~119 ~88 dirt
setblock ~165 ~119 ~96 dirt
setblock ~165 ~119 ~100 dirt
setblock ~165 ~119 ~103 dirt
setblock ~165 ~119 ~104 dirt
setblock ~165 ~119 ~105 dirt
setblock ~165 ~119 ~106 dirt
setblock ~165 ~119 ~129 dirt
setblock ~165 ~120 ~52 dirt
setblock ~165 ~120 ~53 dirt
setblock ~165 ~120 ~54 dirt
setblock ~165 ~120 ~55 dirt
setblock ~165 ~120 ~56 dirt
setblock ~165 ~120 ~70 dirt
setblock ~165 ~120 ~71 dirt
setblock ~165 ~120 ~72 dirt
setblock ~165 ~120 ~73 dirt
setblock ~165 ~120 ~74 dirt
setblock ~165 ~120 ~75 dirt
setblock ~165 ~120 ~76 dirt
setblock ~165 ~120 ~77 dirt
setblock ~165 ~120 ~78 dirt
setblock ~165 ~120 ~79 dirt
setblock ~165 ~120 ~80 dirt
setblock ~165 ~120 ~81 dirt
setblock ~165 ~120 ~82 dirt
setblock ~165 ~120 ~83 dirt
setblock ~165 ~120 ~84 dirt
setblock ~165 ~120 ~85 dirt
setblock ~165 ~120 ~86 dirt
setblock ~165 ~120 ~87 dirt
setblock ~165 ~120 ~88 dirt
setblock ~165 ~120 ~89 dirt
setblock ~165 ~120 ~96 dirt
setblock ~165 ~120 ~97 dirt
setblock ~165 ~120 ~98 dirt
setblock ~165 ~120 ~99 dirt
setblock ~165 ~120 ~100 dirt
setblock ~165 ~120 ~101 dirt
setblock ~165 ~120 ~102 dirt
setblock ~165 ~120 ~103 dirt
setblock ~165 ~120 ~104 dirt
setblock ~165 ~120 ~105 dirt
setblock ~165 ~120 ~106 dirt
setblock ~165 ~120 ~107 dirt
setblock ~165 ~120 ~129 dirt
setblock ~165 ~120 ~139 dirt
setblock ~165 ~121 ~52 dirt
setblock ~165 ~121 ~53 dirt
setblock ~165 ~121 ~54 dirt
setblock ~165 ~121 ~55 dirt
setblock ~165 ~121 ~56 dirt
setblock ~165 ~121 ~69 dirt
setblock ~165 ~121 ~70 dirt
setblock ~165 ~121 ~71 dirt
setblock ~165 ~121 ~72 dirt
setblock ~165 ~121 ~73 dirt
setblock ~165 ~121 ~74 dirt
setblock ~165 ~121 ~75 dirt
setblock ~165 ~121 ~76 dirt
setblock ~165 ~121 ~77 dirt
setblock ~165 ~121 ~78 dirt
setblock ~165 ~121 ~79 dirt
setblock ~165 ~121 ~80 dirt
setblock ~165 ~121 ~81 dirt
setblock ~165 ~121 ~82 dirt
setblock ~165 ~121 ~83 dirt
setblock ~165 ~121 ~84 dirt
setblock ~165 ~121 ~85 dirt
setblock ~165 ~121 ~86 dirt
setblock ~165 ~121 ~87 dirt
setblock ~165 ~121 ~88 dirt
setblock ~165 ~121 ~89 dirt
setblock ~165 ~121 ~90 dirt
setblock ~165 ~121 ~94 dirt
setblock ~165 ~121 ~95 dirt
setblock ~165 ~121 ~96 dirt
setblock ~165 ~121 ~97 dirt
setblock ~165 ~121 ~98 dirt
setblock ~165 ~121 ~99 dirt
setblock ~165 ~121 ~100 dirt
setblock ~165 ~121 ~101 dirt
setblock ~165 ~121 ~102 dirt
setblock ~165 ~121 ~103 dirt
setblock ~165 ~121 ~104 dirt
setblock ~165 ~121 ~105 dirt
setblock ~165 ~121 ~106 dirt
setblock ~165 ~121 ~107 dirt
setblock ~165 ~121 ~120 dirt
setblock ~165 ~121 ~128 dirt
setblock ~165 ~121 ~129 dirt
setblock ~165 ~121 ~130 dirt
setblock ~165 ~121 ~139 dirt
setblock ~165 ~122 ~52 dirt
setblock ~165 ~122 ~53 dirt
setblock ~165 ~122 ~54 dirt
setblock ~165 ~122 ~55 dirt
setblock ~165 ~122 ~56 dirt
setblock ~165 ~122 ~69 dirt
setblock ~165 ~122 ~70 dirt
setblock ~165 ~122 ~71 dirt
setblock ~165 ~122 ~72 dirt
setblock ~165 ~122 ~73 dirt
setblock ~165 ~122 ~74 dirt
setblock ~165 ~122 ~75 dirt
setblock ~165 ~122 ~76 dirt
setblock ~165 ~122 ~77 dirt
setblock ~165 ~122 ~78 dirt
setblock ~165 ~122 ~79 dirt
setblock ~165 ~122 ~80 dirt
setblock ~165 ~122 ~81 dirt
setblock ~165 ~122 ~82 dirt
setblock ~165 ~122 ~83 dirt
setblock ~165 ~122 ~84 dirt
setblock ~165 ~122 ~85 dirt
setblock ~165 ~122 ~86 dirt
setblock ~165 ~122 ~87 dirt
setblock ~165 ~122 ~88 dirt
setblock ~165 ~122 ~89 dirt
setblock ~165 ~122 ~90 dirt
setblock ~165 ~122 ~94 dirt
setblock ~165 ~122 ~95 dirt
setblock ~165 ~122 ~96 dirt
setblock ~165 ~122 ~97 dirt
setblock ~165 ~122 ~98 dirt
setblock ~165 ~122 ~99 dirt
setblock ~165 ~122 ~100 dirt
setblock ~165 ~122 ~101 dirt
setblock ~165 ~122 ~102 dirt
setblock ~165 ~122 ~103 dirt
setblock ~165 ~122 ~104 dirt
setblock ~165 ~122 ~105 dirt
setblock ~165 ~122 ~106 dirt
setblock ~165 ~122 ~107 dirt
setblock ~165 ~122 ~120 dirt
setblock ~165 ~122 ~128 dirt
setblock ~165 ~122 ~129 dirt
setblock ~165 ~122 ~130 dirt
setblock ~165 ~122 ~139 dirt
setblock ~165 ~123 ~52 dirt
setblock ~165 ~123 ~53 dirt
setblock ~165 ~123 ~54 dirt
setblock ~165 ~123 ~55 dirt
setblock ~165 ~123 ~56 dirt
setblock ~165 ~123 ~69 dirt
setblock ~165 ~123 ~70 grass_block
setblock ~165 ~123 ~71 dirt
setblock ~165 ~123 ~72 dirt
setblock ~165 ~123 ~73 dirt
setblock ~165 ~123 ~74 dirt
setblock ~165 ~123 ~75 dirt
setblock ~165 ~123 ~76 dirt
setblock ~165 ~123 ~77 dirt
setblock ~165 ~123 ~78 dirt
setblock ~165 ~123 ~79 dirt
setblock ~165 ~123 ~80 dirt
setblock ~165 ~123 ~81 dirt
setblock ~165 ~123 ~82 dirt
setblock ~165 ~123 ~83 dirt
setblock ~165 ~123 ~84 dirt
setblock ~165 ~123 ~85 dirt
setblock ~165 ~123 ~86 dirt
setblock ~165 ~123 ~87 dirt
setblock ~165 ~123 ~88 dirt
setblock ~165 ~123 ~89 dirt
setblock ~165 ~123 ~90 dirt
setblock ~165 ~123 ~94 dirt
setblock ~165 ~123 ~95 dirt
setblock ~165 ~123 ~96 dirt
setblock ~165 ~123 ~97 dirt
setblock ~165 ~123 ~98 dirt
setblock ~165 ~123 ~99 dirt
setblock ~165 ~123 ~100 dirt
setblock ~165 ~123 ~101 dirt
setblock ~165 ~123 ~102 dirt
setblock ~165 ~123 ~103 dirt
setblock ~165 ~123 ~104 dirt
setblock ~165 ~123 ~105 dirt
setblock ~165 ~123 ~106 dirt
setblock ~165 ~123 ~107 dirt
setblock ~165 ~123 ~120 dirt
setblock ~165 ~123 ~128 dirt
setblock ~165 ~123 ~129 dirt
setblock ~165 ~123 ~130 dirt
setblock ~165 ~123 ~139 dirt
setblock ~165 ~124 ~52 dirt
setblock ~165 ~124 ~53 dirt
setblock ~165 ~124 ~54 dirt
setblock ~165 ~124 ~55 dirt
setblock ~165 ~124 ~56 dirt
setblock ~165 ~124 ~69 grass_block
setblock ~165 ~124 ~71 grass_block
setblock ~165 ~124 ~72 grass_block
setblock ~165 ~124 ~73 grass_block
setblock ~165 ~124 ~74 grass_block
setblock ~165 ~124 ~75 grass_block
setblock ~165 ~124 ~76 dirt
setblock ~165 ~124 ~77 dirt
setblock ~165 ~124 ~78 dirt
setblock ~165 ~124 ~79 dirt
setblock ~165 ~124 ~80 dirt
setblock ~165 ~124 ~81 dirt
setblock ~165 ~124 ~82 dirt
setblock ~165 ~124 ~83 dirt
setblock ~165 ~124 ~84 dirt
setblock ~165 ~124 ~85 dirt
setblock ~165 ~124 ~86 dirt
setblock ~165 ~124 ~87 dirt
setblock ~165 ~124 ~88 dirt
setblock ~165 ~124 ~89 dirt
setblock ~165 ~124 ~90 dirt
setblock ~165 ~124 ~94 dirt
setblock ~165 ~124 ~95 dirt
setblock ~165 ~124 ~96 dirt
setblock ~165 ~124 ~97 dirt
setblock ~165 ~124 ~98 dirt
setblock ~165 ~124 ~99 dirt
setblock ~165 ~124 ~100 grass_block
setblock ~165 ~124 ~101 dirt
setblock ~165 ~124 ~102 dirt
setblock ~165 ~124 ~103 dirt
setblock ~165 ~124 ~104 dirt
setblock ~165 ~124 ~105 dirt
setblock ~165 ~124 ~106 dirt
setblock ~165 ~124 ~107 dirt
setblock ~165 ~124 ~120 dirt
setblock ~165 ~124 ~128 dirt
setblock ~165 ~124 ~129 dirt
setblock ~165 ~124 ~130 dirt
setblock ~165 ~124 ~139 dirt
setblock ~165 ~125 ~52 dirt
setblock ~165 ~125 ~53 dirt
setblock ~165 ~125 ~54 dirt
setblock ~165 ~125 ~55 dirt
setblock ~165 ~125 ~56 dirt
setblock ~165 ~125 ~72 short_grass
setblock ~165 ~125 ~76 grass_block
setblock ~165 ~125 ~77 grass_block
setblock ~165 ~125 ~78 grass_block
setblock ~165 ~125 ~79 grass_block
setblock ~165 ~125 ~80 dirt
setblock ~165 ~125 ~81 dirt
setblock ~165 ~125 ~82 dirt
setblock ~165 ~125 ~83 dirt
setblock ~165 ~125 ~84 dirt
setblock ~165 ~125 ~85 dirt
setblock ~165 ~125 ~86 dirt
setblock ~165 ~125 ~87 dirt
setblock ~165 ~125 ~88 dirt
setblock ~165 ~125 ~89 dirt
setblock ~165 ~125 ~90 dirt
setblock ~165 ~125 ~94 dirt
setblock ~165 ~125 ~95 dirt
setblock ~165 ~125 ~96 dirt
setblock ~165 ~125 ~97 grass_block
setblock ~165 ~125 ~98 grass_block
setblock ~165 ~125 ~99 grass_block
setblock ~165 ~125 ~101 grass_block
setblock ~165 ~125 ~102 grass_block
setblock ~165 ~125 ~103 grass_block
setblock ~165 ~125 ~104 grass_block
setblock ~165 ~125 ~105 grass_block
setblock ~165 ~125 ~106 grass_block
setblock ~165 ~125 ~107 grass_block
setblock ~165 ~125 ~120 dirt
setblock ~165 ~125 ~128 grass_block
setblock ~165 ~125 ~129 grass_block
setblock ~165 ~125 ~130 grass_block
setblock ~165 ~125 ~139 grass_block
setblock ~165 ~126 ~52 dirt
setblock ~165 ~126 ~53 dirt
setblock ~165 ~126 ~54 dirt
setblock ~165 ~126 ~55 grass_block
setblock ~165 ~126 ~56 grass_block
setblock ~165 ~126 ~78 short_grass
setblock ~165 ~126 ~79 short_grass
setblock ~165 ~126 ~80 grass_block
setblock ~165 ~126 ~81 grass_block
setblock ~165 ~126 ~82 dirt
setblock ~165 ~126 ~83 dirt
setblock ~165 ~126 ~84 dirt
setblock ~165 ~126 ~85 dirt
setblock ~165 ~126 ~86 dirt
setblock ~165 ~126 ~87 dirt
setblock ~165 ~126 ~88 dirt
setblock ~165 ~126 ~89 dirt
setblock ~165 ~126 ~90 dirt
setblock ~165 ~126 ~94 dirt
setblock ~165 ~126 ~95 grass_block
setblock ~165 ~126 ~96 grass_block
setblock ~165 ~126 ~97 short_grass
setblock ~165 ~126 ~98 short_grass
setblock ~165 ~126 ~105 short_grass
setblock ~165 ~126 ~120 grass_block
setblock ~165 ~126 ~129 short_grass
setblock ~165 ~127 ~52 grass_block
setblock ~165 ~127 ~53 grass_block
setblock ~165 ~127 ~54 grass_block
setblock ~165 ~127 ~80 poppy
setblock ~165 ~127 ~81 short_grass
setblock ~165 ~127 ~82 grass_block
setblock ~165 ~127 ~83 grass_block
setblock ~165 ~127 ~84 dirt
setblock ~165 ~127 ~85 dirt
setblock ~165 ~127 ~86 dirt
setblock ~165 ~127 ~87 dirt
setblock ~165 ~127 ~88 dirt
setblock ~165 ~127 ~89 dirt
setblock ~165 ~127 ~90 dirt
setblock ~165 ~127 ~94 grass_block
setblock ~165 ~127 ~95 short_grass
setblock ~165 ~128 ~84 grass_block
setblock ~165 ~128 ~85 grass_block
setblock ~165 ~128 ~86 dirt
setblock ~165 ~128 ~87 dirt
setblock ~165 ~128 ~88 dirt
setblock ~165 ~128 ~89 dirt
setblock ~165 ~128 ~90 dirt
setblock ~165 ~129 ~86 grass_block
setblock ~165 ~129 ~87 grass_block
setblock ~165 ~129 ~88 dirt
setblock ~165 ~129 ~89 dirt
setblock ~165 ~129 ~90 dirt
setblock ~165 ~130 ~88 grass_block
setblock ~165 ~130 ~89 dirt
setblock ~165 ~130 ~90 dirt
setblock ~165 ~131 ~88 short_grass
setblock ~165 ~131 ~89 grass_block
setblock ~165 ~131 ~90 grass_block
setblock ~166 ~105 ~77 dirt
setblock ~166 ~106 ~77 dirt
setblock ~166 ~107 ~76 dirt
setblock ~166 ~107 ~77 dirt
setblock ~166 ~107 ~78 dirt
setblock ~166 ~108 ~75 dirt
setblock ~166 ~108 ~76 dirt
setblock ~166 ~108 ~77 dirt
setblock ~166 ~108 ~78 dirt
setblock ~166 ~109 ~75 dirt
setblock ~166 ~109 ~76 dirt
setblock ~166 ~109 ~77 dirt
setblock ~166 ~109 ~78 dirt
setblock ~166 ~109 ~79 dirt
setblock ~166 ~109 ~80 dirt
setblock ~166 ~110 ~74 dirt
setblock ~166 ~110 ~75 dirt
setblock ~166 ~110 ~76 dirt
setblock ~166 ~110 ~77 dirt
setblock ~166 ~110 ~78 dirt
setblock ~166 ~110 ~79 dirt
setblock ~166 ~110 ~80 dirt
setblock ~166 ~110 ~81 dirt
setblock ~166 ~111 ~73 dirt
setblock ~166 ~111 ~74 dirt
setblock ~166 ~111 ~75 dirt
setblock ~166 ~111 ~76 dirt
setblock ~166 ~111 ~77 dirt
setblock ~166 ~111 ~78 dirt
setblock ~166 ~111 ~79 dirt
setblock ~166 ~111 ~80 dirt
setblock ~166 ~111 ~81 dirt
setblock ~166 ~111 ~82 dirt
setblock ~166 ~112 ~73 dirt
setblock ~166 ~112 ~74 dirt
setblock ~166 ~112 ~75 dirt
setblock ~166 ~112 ~76 dirt
setblock ~166 ~112 ~77 dirt
setblock ~166 ~112 ~78 dirt
setblock ~166 ~112 ~79 dirt
setblock ~166 ~112 ~80 dirt
setblock ~166 ~112 ~81 dirt
setblock ~166 ~112 ~82 dirt
setblock ~166 ~112 ~83 dirt
setblock ~166 ~113 ~73 dirt
setblock ~166 ~113 ~74 dirt
setblock ~166 ~113 ~75 dirt
setblock ~166 ~113 ~76 dirt
setblock ~166 ~113 ~77 dirt
setblock ~166 ~113 ~78 dirt
setblock ~166 ~113 ~79 dirt
setblock ~166 ~113 ~80 dirt
setblock ~166 ~113 ~81 dirt
setblock ~166 ~113 ~82 dirt
setblock ~166 ~113 ~83 dirt
setblock ~166 ~114 ~72 dirt
setblock ~166 ~114 ~73 dirt
setblock ~166 ~114 ~74 dirt
setblock ~166 ~114 ~75 dirt
setblock ~166 ~114 ~76 dirt
setblock ~166 ~114 ~77 dirt
setblock ~166 ~114 ~78 dirt
setblock ~166 ~114 ~79 dirt
setblock ~166 ~114 ~80 dirt
setblock ~166 ~114 ~81 dirt
setblock ~166 ~114 ~82 dirt
setblock ~166 ~114 ~83 dirt
setblock ~166 ~114 ~85 dirt
setblock ~166 ~114 ~105 dirt
setblock ~166 ~115 ~72 dirt
setblock ~166 ~115 ~73 dirt
setblock ~166 ~115 ~74 dirt
setblock ~166 ~115 ~75 dirt
setblock ~166 ~115 ~76 dirt
setblock ~166 ~115 ~77 dirt
setblock ~166 ~115 ~78 dirt
setblock ~166 ~115 ~79 dirt
setblock ~166 ~115 ~80 dirt
setblock ~166 ~115 ~81 dirt
setblock ~166 ~115 ~82 dirt
setblock ~166 ~115 ~83 dirt
setblock ~166 ~115 ~85 dirt
setblock ~166 ~115 ~104 dirt
setblock ~166 ~115 ~105 dirt
setblock ~166 ~115 ~106 dirt
setblock ~166 ~116 ~72 dirt
setblock ~166 ~116 ~73 dirt
setblock ~166 ~116 ~74 dirt
setblock ~166 ~116 ~75 dirt
setblock ~166 ~116 ~76 dirt
setblock ~166 ~116 ~77 dirt
setblock ~166 ~116 ~78 dirt
setblock ~166 ~116 ~79 dirt
setblock ~166 ~116 ~80 dirt
setblock ~166 ~116 ~81 dirt
setblock ~166 ~116 ~82 dirt
setblock ~166 ~116 ~83 dirt
setblock ~166 ~116 ~84 dirt
setblock ~166 ~116 ~85 dirt
setblock ~166 ~116 ~86 dirt
setblock ~166 ~116 ~103 dirt
setblock ~166 ~116 ~104 dirt
setblock ~166 ~116 ~105 dirt
setblock ~166 ~116 ~106 dirt
setblock ~166 ~117 ~71 dirt
setblock ~166 ~117 ~72 dirt
setblock ~166 ~117 ~73 dirt
setblock ~166 ~117 ~74 dirt
setblock ~166 ~117 ~75 dirt
setblock ~166 ~117 ~76 dirt
setblock ~166 ~117 ~77 dirt
setblock ~166 ~117 ~78 dirt
setblock ~166 ~117 ~79 dirt
setblock ~166 ~117 ~80 dirt
setblock ~166 ~117 ~81 dirt
setblock ~166 ~117 ~82 dirt
setblock ~166 ~117 ~83 dirt
setblock ~166 ~117 ~84 dirt
setblock ~166 ~117 ~85 dirt
setblock ~166 ~117 ~86 dirt
setblock ~166 ~117 ~87 dirt
setblock ~166 ~117 ~103 dirt
setblock ~166 ~117 ~104 dirt
setblock ~166 ~117 ~105 dirt
setblock ~166 ~117 ~106 dirt
setblock ~166 ~118 ~71 dirt
setblock ~166 ~118 ~72 dirt
setblock ~166 ~118 ~73 dirt
setblock ~166 ~118 ~74 dirt
setblock ~166 ~118 ~75 dirt
setblock ~166 ~118 ~76 dirt
setblock ~166 ~118 ~77 dirt
setblock ~166 ~118 ~78 dirt
setblock ~166 ~118 ~79 dirt
setblock ~166 ~118 ~80 dirt
setblock ~166 ~118 ~81 dirt
setblock ~166 ~118 ~82 dirt
setblock ~166 ~118 ~83 dirt
setblock ~166 ~118 ~84 dirt
setblock ~166 ~118 ~85 dirt
setblock ~166 ~118 ~86 dirt
setblock ~166 ~118 ~87 dirt
setblock ~166 ~118 ~103 dirt
setblock ~166 ~118 ~104 dirt
setblock ~166 ~118 ~105 dirt
setblock ~166 ~118 ~106 dirt
setblock ~166 ~119 ~70 dirt
setblock ~166 ~119 ~71 dirt
setblock ~166 ~119 ~72 dirt
setblock ~166 ~119 ~73 dirt
setblock ~166 ~119 ~74 dirt
setblock ~166 ~119 ~75 dirt
setblock ~166 ~119 ~76 dirt
setblock ~166 ~119 ~77 dirt
setblock ~166 ~119 ~78 dirt
setblock ~166 ~119 ~79 dirt
setblock ~166 ~119 ~80 dirt
setblock ~166 ~119 ~81 dirt
setblock ~166 ~119 ~82 dirt
setblock ~166 ~119 ~83 dirt
setblock ~166 ~119 ~84 dirt
setblock ~166 ~119 ~85 dirt
setblock ~166 ~119 ~86 dirt
setblock ~166 ~119 ~87 dirt
setblock ~166 ~119 ~102 dirt
setblock ~166 ~119 ~103 dirt
setblock ~166 ~119 ~104 dirt
setblock ~166 ~119 ~105 dirt
setblock ~166 ~119 ~106 dirt
setblock ~166 ~119 ~107 dirt
setblock ~166 ~119 ~139 dirt
setblock ~166 ~120 ~53 dirt
setblock ~166 ~120 ~55 dirt
setblock ~166 ~120 ~69 dirt
setblock ~166 ~120 ~70 dirt
setblock ~166 ~120 ~71 dirt
setblock ~166 ~120 ~72 dirt
setblock ~166 ~120 ~73 dirt
setblock ~166 ~120 ~74 dirt
setblock ~166 ~120 ~75 dirt
setblock ~166 ~120 ~76 dirt
setblock ~166 ~120 ~77 dirt
setblock ~166 ~120 ~78 dirt
setblock ~166 ~120 ~79 dirt
setblock ~166 ~120 ~80 dirt
setblock ~166 ~120 ~81 dirt
setblock ~166 ~120 ~82 dirt
setblock ~166 ~120 ~83 dirt
setblock ~166 ~120 ~84 dirt
setblock ~166 ~120 ~85 dirt
setblock ~166 ~120 ~86 dirt
setblock ~166 ~120 ~87 dirt
setblock ~166 ~120 ~88 dirt
setblock ~166 ~120 ~100 dirt
setblock ~166 ~120 ~102 dirt
setblock ~166 ~120 ~103 dirt
setblock ~166 ~120 ~104 dirt
setblock ~166 ~120 ~105 dirt
setblock ~166 ~120 ~106 dirt
setblock ~166 ~120 ~107 dirt
setblock ~166 ~120 ~108 dirt
setblock ~166 ~120 ~138 dirt
setblock ~166 ~120 ~139 dirt
setblock ~166 ~120 ~140 dirt
setblock ~166 ~121 ~52 dirt
setblock ~166 ~121 ~53 dirt
setblock ~166 ~121 ~54 dirt
setblock ~166 ~121 ~55 dirt
setblock ~166 ~121 ~69 dirt
setblock ~166 ~121 ~70 dirt
setblock ~166 ~121 ~71 dirt
setblock ~166 ~121 ~72 dirt
setblock ~166 ~121 ~73 dirt
setblock ~166 ~121 ~74 dirt
setblock ~166 ~121 ~75 dirt
setblock ~166 ~121 ~76 dirt
setblock ~166 ~121 ~77 dirt
setblock ~166 ~121 ~78 dirt
setblock ~166 ~121 ~79 dirt
setblock ~166 ~121 ~80 dirt
setblock ~166 ~121 ~81 dirt
setblock ~166 ~121 ~82 dirt
setblock ~166 ~121 ~83 dirt
setblock ~166 ~121 ~84 dirt
setblock ~166 ~121 ~85 dirt
setblock ~166 ~121 ~86 dirt
setblock ~166 ~121 ~87 dirt
setblock ~166 ~121 ~88 dirt
setblock ~166 ~121 ~99 dirt
setblock ~166 ~121 ~100 dirt
setblock ~166 ~121 ~101 dirt
setblock ~166 ~121 ~102 dirt
setblock ~166 ~121 ~103 dirt
setblock ~166 ~121 ~104 dirt
setblock ~166 ~121 ~105 dirt
setblock ~166 ~121 ~106 dirt
setblock ~166 ~121 ~107 dirt
setblock ~166 ~121 ~108 dirt
setblock ~166 ~121 ~129 dirt
setblock ~166 ~121 ~138 dirt
setblock ~166 ~121 ~139 dirt
setblock ~166 ~121 ~140 dirt
setblock ~166 ~122 ~52 dirt
setblock ~166 ~122 ~53 dirt
setblock ~166 ~122 ~54 dirt
setblock ~166 ~122 ~55 dirt
setblock ~166 ~122 ~69 dirt
setblock ~166 ~122 ~70 dirt
setblock ~166 ~122 ~71 dirt
