setblock ~170 ~135 ~74 oak_leaves
setblock ~170 ~135 ~75 oak_leaves
setblock ~170 ~135 ~76 jungle_leaves
setblock ~170 ~135 ~111 jungle_leaves
setblock ~170 ~135 ~112 jungle_leaves
setblock ~170 ~135 ~113 oak_leaves
setblock ~170 ~135 ~114 jungle_leaves
setblock ~170 ~135 ~117 oak_wood
setblock ~170 ~135 ~118 oak_leaves
setblock ~170 ~136 ~61 oak_wood
setblock ~170 ~136 ~62 oak_leaves
setblock ~170 ~136 ~63 oak_leaves
setblock ~170 ~136 ~64 oak_leaves
setblock ~170 ~136 ~65 oak_leaves
setblock ~170 ~136 ~66 oak_leaves
setblock ~170 ~136 ~67 oak_leaves
setblock ~170 ~136 ~68 oak_log
setblock ~170 ~136 ~69 oak_leaves
setblock ~170 ~136 ~72 oak_leaves
setblock ~170 ~136 ~73 oak_leaves
setblock ~170 ~136 ~75 jungle_leaves
setblock ~170 ~136 ~110 oak_leaves
setblock ~170 ~136 ~111 jungle_leaves
setblock ~170 ~136 ~112 oak_leaves
setblock ~170 ~136 ~113 oak_leaves
setblock ~170 ~136 ~114 oak_leaves
setblock ~170 ~136 ~116 oak_wood
setblock ~170 ~136 ~117 oak_leaves
setblock ~170 ~137 ~61 jungle_leaves
setblock ~170 ~137 ~62 jungle_leaves
setblock ~170 ~137 ~67 oak_leaves
setblock ~170 ~137 ~69 oak_leaves
setblock ~170 ~137 ~70 jungle_leaves
setblock ~170 ~137 ~71 jungle_leaves
setblock ~170 ~137 ~72 oak_leaves
setblock ~170 ~137 ~73 jungle_leaves
setblock ~170 ~137 ~75 jungle_leaves
setblock ~170 ~137 ~76 jungle_leaves
setblock ~170 ~137 ~77 oak_leaves
setblock ~170 ~137 ~111 oak_leaves
setblock ~170 ~137 ~112 oak_leaves
setblock ~170 ~137 ~115 oak_leaves
setblock ~170 ~137 ~116 oak_wood
setblock ~170 ~137 ~118 oak_leaves
setblock ~170 ~137 ~119 oak_leaves
setblock ~170 ~138 ~65 oak_leaves
setblock ~170 ~138 ~67 oak_leaves
setblock ~170 ~138 ~68 oak_leaves
setblock ~170 ~138 ~71 oak_leaves
setblock ~170 ~138 ~72 oak_leaves
setblock ~170 ~138 ~73 oak_leaves
setblock ~170 ~138 ~74 jungle_leaves
setblock ~170 ~138 ~111 oak_leaves
setblock ~170 ~138 ~112 jungle_leaves
setblock ~170 ~138 ~113 oak_leaves
setblock ~170 ~138 ~114 oak_leaves
setblock ~170 ~138 ~115 oak_leaves
setblock ~170 ~138 ~116 oak_leaves
setblock ~170 ~138 ~117 oak_leaves
setblock ~170 ~139 ~114 oak_leaves
setblock ~170 ~139 ~115 oak_leaves
setblock ~170 ~139 ~116 jungle_leaves
setblock ~170 ~139 ~117 jungle_leaves
setblock ~170 ~139 ~118 oak_leaves
setblock ~170 ~139 ~119 oak_leaves
setblock ~171 ~109 ~113 dirt
setblock ~171 ~110 ~113 dirt
setblock ~171 ~111 ~113 dirt
setblock ~171 ~112 ~110 dirt
setblock ~171 ~112 ~113 dirt
setblock ~171 ~112 ~114 dirt
setblock ~171 ~113 ~109 dirt
setblock ~171 ~113 ~110 dirt
setblock ~171 ~113 ~112 dirt
setblock ~171 ~113 ~113 dirt
setblock ~171 ~113 ~114 dirt
setblock ~171 ~114 ~74 dirt
setblock ~171 ~114 ~109 dirt
setblock ~171 ~114 ~110 dirt
setblock ~171 ~114 ~111 dirt
setblock ~171 ~114 ~112 dirt
setblock ~171 ~114 ~113 dirt
setblock ~171 ~114 ~114 dirt
setblock ~171 ~114 ~115 dirt
setblock ~171 ~114 ~116 dirt
setblock ~171 ~115 ~73 dirt
setblock ~171 ~115 ~74 dirt
setblock ~171 ~115 ~75 dirt
setblock ~171 ~115 ~108 dirt
setblock ~171 ~115 ~109 dirt
setblock ~171 ~115 ~110 dirt
setblock ~171 ~115 ~111 dirt
setblock ~171 ~115 ~112 dirt
setblock ~171 ~115 ~113 dirt
setblock ~171 ~115 ~114 dirt
setblock ~171 ~115 ~115 dirt
setblock ~171 ~115 ~116 dirt
setblock ~171 ~115 ~117 dirt
setblock ~171 ~116 ~72 dirt
setblock ~171 ~116 ~73 dirt
setblock ~171 ~116 ~74 dirt
setblock ~171 ~116 ~75 dirt
setblock ~171 ~116 ~76 dirt
setblock ~171 ~116 ~97 dirt
setblock ~171 ~116 ~98 dirt
setblock ~171 ~116 ~99 dirt
setblock ~171 ~116 ~107 dirt
setblock ~171 ~116 ~108 dirt
setblock ~171 ~116 ~109 dirt
setblock ~171 ~116 ~110 dirt
setblock ~171 ~116 ~111 dirt
setblock ~171 ~116 ~112 dirt
setblock ~171 ~116 ~113 dirt
setblock ~171 ~116 ~114 dirt
setblock ~171 ~116 ~115 dirt
setblock ~171 ~116 ~116 dirt
setblock ~171 ~116 ~117 dirt
setblock ~171 ~116 ~118 dirt
setblock ~171 ~117 ~72 dirt
setblock ~171 ~117 ~73 dirt
setblock ~171 ~117 ~74 dirt
setblock ~171 ~117 ~75 dirt
setblock ~171 ~117 ~76 dirt
setblock ~171 ~117 ~77 dirt
setblock ~171 ~117 ~79 dirt
setblock ~171 ~117 ~96 dirt
setblock ~171 ~117 ~97 dirt
setblock ~171 ~117 ~98 dirt
setblock ~171 ~117 ~99 dirt
setblock ~171 ~117 ~107 dirt
setblock ~171 ~117 ~108 dirt
setblock ~171 ~117 ~109 dirt
setblock ~171 ~117 ~110 dirt
setblock ~171 ~117 ~111 dirt
setblock ~171 ~117 ~112 dirt
setblock ~171 ~117 ~113 dirt
setblock ~171 ~117 ~114 dirt
setblock ~171 ~117 ~115 dirt
setblock ~171 ~117 ~116 dirt
setblock ~171 ~117 ~117 dirt
setblock ~171 ~117 ~118 dirt
setblock ~171 ~117 ~119 dirt
setblock ~171 ~117 ~121 dirt
setblock ~171 ~118 ~71 dirt
setblock ~171 ~118 ~72 dirt
setblock ~171 ~118 ~73 dirt
setblock ~171 ~118 ~74 dirt
setblock ~171 ~118 ~75 dirt
setblock ~171 ~118 ~76 dirt
setblock ~171 ~118 ~77 dirt
setblock ~171 ~118 ~78 dirt
setblock ~171 ~118 ~79 dirt
setblock ~171 ~118 ~80 dirt
setblock ~171 ~118 ~95 dirt
setblock ~171 ~118 ~96 dirt
setblock ~171 ~118 ~97 dirt
setblock ~171 ~118 ~98 dirt
setblock ~171 ~118 ~99 dirt
setblock ~171 ~118 ~100 dirt
setblock ~171 ~118 ~102 dirt
setblock ~171 ~118 ~103 dirt
setblock ~171 ~118 ~106 dirt
setblock ~171 ~118 ~107 dirt
setblock ~171 ~118 ~108 dirt
setblock ~171 ~118 ~109 dirt
setblock ~171 ~118 ~110 dirt
setblock ~171 ~118 ~111 dirt
setblock ~171 ~118 ~112 dirt
setblock ~171 ~118 ~113 dirt
setblock ~171 ~118 ~114 dirt
setblock ~171 ~118 ~115 dirt
setblock ~171 ~118 ~116 dirt
setblock ~171 ~118 ~117 dirt
setblock ~171 ~118 ~118 dirt
setblock ~171 ~118 ~119 dirt
setblock ~171 ~118 ~120 dirt
setblock ~171 ~118 ~121 dirt
setblock ~171 ~118 ~122 dirt
setblock ~171 ~118 ~128 dirt
setblock ~171 ~119 ~70 dirt
setblock ~171 ~119 ~71 dirt
setblock ~171 ~119 ~72 dirt
setblock ~171 ~119 ~73 dirt
setblock ~171 ~119 ~74 dirt
setblock ~171 ~119 ~75 dirt
setblock ~171 ~119 ~76 dirt
setblock ~171 ~119 ~77 dirt
setblock ~171 ~119 ~78 dirt
setblock ~171 ~119 ~79 dirt
setblock ~171 ~119 ~80 dirt
setblock ~171 ~119 ~94 dirt
setblock ~171 ~119 ~95 dirt
setblock ~171 ~119 ~96 dirt
setblock ~171 ~119 ~97 dirt
setblock ~171 ~119 ~98 dirt
setblock ~171 ~119 ~99 dirt
setblock ~171 ~119 ~100 dirt
setblock ~171 ~119 ~101 dirt
setblock ~171 ~119 ~102 dirt
setblock ~171 ~119 ~103 dirt
setblock ~171 ~119 ~105 dirt
setblock ~171 ~119 ~106 dirt
setblock ~171 ~119 ~107 dirt
setblock ~171 ~119 ~108 dirt
setblock ~171 ~119 ~109 dirt
setblock ~171 ~119 ~110 dirt
setblock ~171 ~119 ~111 dirt
setblock ~171 ~119 ~112 dirt
setblock ~171 ~119 ~113 dirt
setblock ~171 ~119 ~114 dirt
setblock ~171 ~119 ~115 dirt
setblock ~171 ~119 ~116 dirt
setblock ~171 ~119 ~117 dirt
setblock ~171 ~119 ~118 dirt
setblock ~171 ~119 ~119 dirt
setblock ~171 ~119 ~120 dirt
setblock ~171 ~119 ~121 dirt
setblock ~171 ~119 ~122 dirt
setblock ~171 ~119 ~123 dirt
setblock ~171 ~119 ~128 dirt
setblock ~171 ~119 ~129 dirt
setblock ~171 ~120 ~69 dirt
setblock ~171 ~120 ~70 dirt
setblock ~171 ~120 ~71 dirt
setblock ~171 ~120 ~72 dirt
setblock ~171 ~120 ~73 dirt
setblock ~171 ~120 ~74 dirt
setblock ~171 ~120 ~75 dirt
setblock ~171 ~120 ~76 dirt
setblock ~171 ~120 ~77 dirt
setblock ~171 ~120 ~78 dirt
setblock ~171 ~120 ~79 dirt
setblock ~171 ~120 ~80 dirt
setblock ~171 ~120 ~81 dirt
setblock ~171 ~120 ~83 dirt
setblock ~171 ~120 ~94 dirt
setblock ~171 ~120 ~95 dirt
setblock ~171 ~120 ~96 dirt
setblock ~171 ~120 ~97 dirt
setblock ~171 ~120 ~98 dirt
setblock ~171 ~120 ~99 dirt
setblock ~171 ~120 ~100 dirt
setblock ~171 ~120 ~101 dirt
setblock ~171 ~120 ~102 dirt
setblock ~171 ~120 ~103 dirt
setblock ~171 ~120 ~105 dirt
setblock ~171 ~120 ~106 dirt
setblock ~171 ~120 ~107 dirt
setblock ~171 ~120 ~108 dirt
setblock ~171 ~120 ~109 dirt
setblock ~171 ~120 ~110 dirt
setblock ~171 ~120 ~111 dirt
setblock ~171 ~120 ~112 dirt
setblock ~171 ~120 ~113 dirt
setblock ~171 ~120 ~114 dirt
setblock ~171 ~120 ~115 dirt
setblock ~171 ~120 ~116 dirt
setblock ~171 ~120 ~117 dirt
setblock ~171 ~120 ~118 dirt
setblock ~171 ~120 ~119 dirt
setblock ~171 ~120 ~120 dirt
setblock ~171 ~120 ~121 dirt
setblock ~171 ~120 ~122 dirt
setblock ~171 ~120 ~123 dirt
setblock ~171 ~120 ~124 dirt
setblock ~171 ~120 ~126 dirt
setblock ~171 ~120 ~128 dirt
setblock ~171 ~120 ~129 dirt
setblock ~171 ~120 ~130 dirt
setblock ~171 ~121 ~68 dirt
setblock ~171 ~121 ~69 dirt
setblock ~171 ~121 ~70 dirt
setblock ~171 ~121 ~71 dirt
setblock ~171 ~121 ~72 dirt
setblock ~171 ~121 ~73 dirt
setblock ~171 ~121 ~74 dirt
setblock ~171 ~121 ~75 dirt
setblock ~171 ~121 ~76 dirt
setblock ~171 ~121 ~77 dirt
setblock ~171 ~121 ~78 dirt
setblock ~171 ~121 ~79 dirt
setblock ~171 ~121 ~80 dirt
setblock ~171 ~121 ~81 dirt
setblock ~171 ~121 ~82 dirt
setblock ~171 ~121 ~83 dirt
setblock ~171 ~121 ~84 dirt
setblock ~171 ~121 ~94 dirt
setblock ~171 ~121 ~95 dirt
setblock ~171 ~121 ~96 dirt
setblock ~171 ~121 ~97 dirt
setblock ~171 ~121 ~98 dirt
setblock ~171 ~121 ~99 dirt
setblock ~171 ~121 ~100 dirt
setblock ~171 ~121 ~101 dirt
setblock ~171 ~121 ~102 dirt
setblock ~171 ~121 ~103 dirt
setblock ~171 ~121 ~104 dirt
setblock ~171 ~121 ~105 dirt
setblock ~171 ~121 ~106 dirt
setblock ~171 ~121 ~107 dirt
setblock ~171 ~121 ~108 dirt
setblock ~171 ~121 ~109 dirt
setblock ~171 ~121 ~110 dirt
setblock ~171 ~121 ~111 dirt
setblock ~171 ~121 ~112 dirt
setblock ~171 ~121 ~113 dirt
setblock ~171 ~121 ~114 dirt
setblock ~171 ~121 ~115 dirt
setblock ~171 ~121 ~116 dirt
setblock ~171 ~121 ~117 dirt
setblock ~171 ~121 ~118 dirt
setblock ~171 ~121 ~119 dirt
setblock ~171 ~121 ~120 dirt
setblock ~171 ~121 ~121 dirt
setblock ~171 ~121 ~122 dirt
setblock ~171 ~121 ~123 dirt
setblock ~171 ~121 ~124 dirt
setblock ~171 ~121 ~125 dirt
setblock ~171 ~121 ~126 dirt
setblock ~171 ~121 ~127 dirt
setblock ~171 ~121 ~128 dirt
setblock ~171 ~121 ~129 dirt
setblock ~171 ~121 ~130 dirt
setblock ~171 ~122 ~68 dirt
setblock ~171 ~122 ~69 dirt
setblock ~171 ~122 ~70 dirt
setblock ~171 ~122 ~71 dirt
setblock ~171 ~122 ~72 dirt
setblock ~171 ~122 ~73 dirt
setblock ~171 ~122 ~74 dirt
setblock ~171 ~122 ~75 dirt
setblock ~171 ~122 ~76 dirt
setblock ~171 ~122 ~77 dirt
setblock ~171 ~122 ~78 dirt
setblock ~171 ~122 ~79 dirt
setblock ~171 ~122 ~80 dirt
setblock ~171 ~122 ~81 dirt
setblock ~171 ~122 ~82 dirt
setblock ~171 ~122 ~83 dirt
setblock ~171 ~122 ~84 dirt
setblock ~171 ~122 ~94 dirt
setblock ~171 ~122 ~95 dirt
setblock ~171 ~122 ~96 dirt
setblock ~171 ~122 ~97 dirt
setblock ~171 ~122 ~98 dirt
setblock ~171 ~122 ~99 dirt
setblock ~171 ~122 ~100 dirt
setblock ~171 ~122 ~101 dirt
setblock ~171 ~122 ~102 dirt
setblock ~171 ~122 ~103 dirt
setblock ~171 ~122 ~104 dirt
setblock ~171 ~122 ~105 dirt
setblock ~171 ~122 ~106 dirt
setblock ~171 ~122 ~107 grass_block
setblock ~171 ~122 ~108 grass_block
setblock ~171 ~122 ~109 grass_block
setblock ~171 ~122 ~110 grass_block
setblock ~171 ~122 ~111 grass_block
setblock ~171 ~122 ~112 grass_block
setblock ~171 ~122 ~113 grass_block
setblock ~171 ~122 ~114 grass_block
setblock ~171 ~122 ~115 grass_block
setblock ~171 ~122 ~116 grass_block
setblock ~171 ~122 ~117 dirt
setblock ~171 ~122 ~118 dirt
setblock ~171 ~122 ~119 dirt
setblock ~171 ~122 ~120 dirt
setblock ~171 ~122 ~121 dirt
setblock ~171 ~122 ~122 dirt
setblock ~171 ~122 ~123 dirt
setblock ~171 ~122 ~124 dirt
setblock ~171 ~122 ~125 dirt
setblock ~171 ~122 ~126 dirt
setblock ~171 ~122 ~127 dirt
setblock ~171 ~122 ~128 dirt
setblock ~171 ~122 ~129 dirt
setblock ~171 ~122 ~130 dirt
setblock ~171 ~123 ~68 grass_block
setblock ~171 ~123 ~69 grass_block
setblock ~171 ~123 ~70 grass_block
setblock ~171 ~123 ~71 grass_block
setblock ~171 ~123 ~72 grass_block
setblock ~171 ~123 ~73 grass_block
setblock ~171 ~123 ~74 grass_block
setblock ~171 ~123 ~75 grass_block
setblock ~171 ~123 ~76 dirt
setblock ~171 ~123 ~77 dirt
setblock ~171 ~123 ~78 dirt
setblock ~171 ~123 ~79 dirt
setblock ~171 ~123 ~80 dirt
setblock ~171 ~123 ~81 dirt
setblock ~171 ~123 ~82 dirt
setblock ~171 ~123 ~83 dirt
setblock ~171 ~123 ~84 dirt
setblock ~171 ~123 ~94 dirt
setblock ~171 ~123 ~95 dirt
setblock ~171 ~123 ~96 dirt
setblock ~171 ~123 ~97 dirt
setblock ~171 ~123 ~98 dirt
setblock ~171 ~123 ~99 dirt
setblock ~171 ~123 ~100 dirt
setblock ~171 ~123 ~101 dirt
setblock ~171 ~123 ~102 dirt
setblock ~171 ~123 ~103 dirt
setblock ~171 ~123 ~104 grass_block
setblock ~171 ~123 ~105 grass_block
setblock ~171 ~123 ~106 grass_block
setblock ~171 ~123 ~111 poppy
setblock ~171 ~123 ~112 short_grass
setblock ~171 ~123 ~114 poppy
setblock ~171 ~123 ~115 short_grass
setblock ~171 ~123 ~117 grass_block
setblock ~171 ~123 ~118 grass_block
setblock ~171 ~123 ~119 grass_block
setblock ~171 ~123 ~120 grass_block
setblock ~171 ~123 ~121 grass_block
setblock ~171 ~123 ~122 dirt
setblock ~171 ~123 ~123 dirt
setblock ~171 ~123 ~124 dirt
setblock ~171 ~123 ~125 dirt
setblock ~171 ~123 ~126 dirt
setblock ~171 ~123 ~127 dirt
setblock ~171 ~123 ~128 dirt
setblock ~171 ~123 ~129 dirt
setblock ~171 ~123 ~130 dirt
setblock ~171 ~124 ~68 poppy
setblock ~171 ~124 ~74 short_grass
setblock ~171 ~124 ~76 grass_block
setblock ~171 ~124 ~77 grass_block
setblock ~171 ~124 ~78 grass_block
setblock ~171 ~124 ~79 grass_block
setblock ~171 ~124 ~80 grass_block
setblock ~171 ~124 ~81 grass_block
setblock ~171 ~124 ~82 dirt
setblock ~171 ~124 ~83 dirt
setblock ~171 ~124 ~84 dirt
setblock ~171 ~124 ~94 dirt
setblock ~171 ~124 ~95 dirt
setblock ~171 ~124 ~96 dirt
setblock ~171 ~124 ~97 dirt
setblock ~171 ~124 ~98 dirt
setblock ~171 ~124 ~99 dirt
setblock ~171 ~124 ~100 dirt
setblock ~171 ~124 ~101 grass_block
setblock ~171 ~124 ~102 grass_block
setblock ~171 ~124 ~103 grass_block
setblock ~171 ~124 ~105 short_grass
setblock ~171 ~124 ~106 short_grass
setblock ~171 ~124 ~119 short_grass
setblock ~171 ~124 ~120 short_grass
setblock ~171 ~124 ~122 grass_block
setblock ~171 ~124 ~123 grass_block
setblock ~171 ~124 ~124 grass_block
setblock ~171 ~124 ~125 dirt
setblock ~171 ~124 ~126 dirt
setblock ~171 ~124 ~127 dirt
setblock ~171 ~124 ~128 dirt
setblock ~171 ~124 ~129 dirt
setblock ~171 ~124 ~130 dirt
setblock ~171 ~125 ~80 short_grass
setblock ~171 ~125 ~81 short_grass
setblock ~171 ~125 ~82 grass_block
setblock ~171 ~125 ~83 grass_block
setblock ~171 ~125 ~84 grass_block
setblock ~171 ~125 ~94 dirt
setblock ~171 ~125 ~95 dirt
setblock ~171 ~125 ~96 dirt
setblock ~171 ~125 ~97 grass_block
setblock ~171 ~125 ~98 grass_block
setblock ~171 ~125 ~99 grass_block
setblock ~171 ~125 ~100 grass_block
setblock ~171 ~125 ~102 fern
setblock ~171 ~125 ~103 short_grass
setblock ~171 ~125 ~122 short_grass
setblock ~171 ~125 ~123 short_grass
setblock ~171 ~125 ~125 grass_block
setblock ~171 ~125 ~126 grass_block
setblock ~171 ~125 ~127 grass_block
setblock ~171 ~125 ~128 dirt
setblock ~171 ~125 ~129 dirt
setblock ~171 ~125 ~130 dirt
setblock ~171 ~126 ~94 grass_block
setblock ~171 ~126 ~95 grass_block
setblock ~171 ~126 ~96 grass_block
setblock ~171 ~126 ~97 short_grass
setblock ~171 ~126 ~98 fern
setblock ~171 ~126 ~99 short_grass
setblock ~171 ~126 ~128 grass_block
setblock ~171 ~126 ~129 grass_block
setblock ~171 ~126 ~130 grass_block
setblock ~171 ~127 ~128 short_grass
setblock ~171 ~128 ~69 oak_leaves
setblock ~171 ~128 ~70 jungle_leaves
setblock ~171 ~128 ~71 oak_leaves
setblock ~171 ~128 ~72 oak_leaves
setblock ~171 ~128 ~73 oak_leaves
setblock ~171 ~129 ~66 jungle_leaves
setblock ~171 ~129 ~67 oak_leaves
setblock ~171 ~129 ~68 oak_leaves
setblock ~171 ~129 ~70 oak_leaves
setblock ~171 ~129 ~72 oak_leaves
setblock ~171 ~129 ~73 oak_leaves
setblock ~171 ~130 ~64 oak_leaves
setblock ~171 ~130 ~65 oak_leaves
setblock ~171 ~130 ~66 oak_leaves
setblock ~171 ~130 ~68 oak_leaves
setblock ~171 ~130 ~69 oak_log
setblock ~171 ~130 ~70 oak_leaves
setblock ~171 ~130 ~71 jungle_leaves
setblock ~171 ~130 ~72 oak_leaves
setblock ~171 ~130 ~73 oak_leaves
setblock ~171 ~130 ~112 oak_leaves
setblock ~171 ~130 ~113 oak_leaves
setblock ~171 ~130 ~114 oak_leaves
setblock ~171 ~130 ~116 jungle_leaves
setblock ~171 ~130 ~117 jungle_leaves
setblock ~171 ~131 ~65 oak_leaves
setblock ~171 ~131 ~66 jungle_leaves
setblock ~171 ~131 ~67 oak_wood
setblock ~171 ~131 ~68 oak_wood
setblock ~171 ~131 ~69 oak_wood
setblock ~171 ~131 ~70 oak_log
setblock ~171 ~131 ~71 oak_leaves
setblock ~171 ~131 ~72 oak_leaves
setblock ~171 ~131 ~73 oak_leaves
setblock ~171 ~131 ~108 oak_leaves
setblock ~171 ~131 ~109 oak_leaves
setblock ~171 ~131 ~111 oak_leaves
setblock ~171 ~131 ~112 oak_leaves
setblock ~171 ~131 ~114 jungle_leaves
setblock ~171 ~131 ~116 oak_leaves
setblock ~171 ~131 ~117 oak_leaves
setblock ~171 ~131 ~118 oak_leaves
setblock ~171 ~132 ~64 oak_leaves
setblock ~171 ~132 ~65 oak_wood
setblock ~171 ~132 ~66 oak_leaves
setblock ~171 ~132 ~68 oak_leaves
setblock ~171 ~132 ~69 oak_wood
setblock ~171 ~132 ~70 oak_wood
setblock ~171 ~132 ~71 jungle_leaves
setblock ~171 ~132 ~73 oak_leaves
setblock ~171 ~132 ~109 jungle_leaves
setblock ~171 ~132 ~110 oak_wood
setblock ~171 ~132 ~112 jungle_leaves
setblock ~171 ~132 ~117 oak_leaves
setblock ~171 ~132 ~118 oak_leaves
setblock ~171 ~133 ~61 oak_leaves
setblock ~171 ~133 ~62 jungle_leaves
setblock ~171 ~133 ~63 oak_leaves
setblock ~171 ~133 ~66 oak_leaves
setblock ~171 ~133 ~67 oak_leaves
setblock ~171 ~133 ~68 oak_wood
setblock ~171 ~133 ~69 oak_wood
setblock ~171 ~133 ~70 oak_leaves
setblock ~171 ~133 ~71 oak_leaves
setblock ~171 ~133 ~72 jungle_leaves
setblock ~171 ~133 ~108 oak_leaves
setblock ~171 ~133 ~109 oak_leaves
setblock ~171 ~133 ~110 jungle_leaves
setblock ~171 ~133 ~111 oak_leaves
setblock ~171 ~133 ~112 oak_wood
setblock ~171 ~133 ~113 oak_leaves
setblock ~171 ~133 ~114 oak_leaves
setblock ~171 ~133 ~115 oak_leaves
setblock ~171 ~133 ~118 jungle_leaves
setblock ~171 ~134 ~63 oak_leaves
setblock ~171 ~134 ~64 oak_leaves
setblock ~171 ~134 ~65 oak_leaves
setblock ~171 ~134 ~68 oak_leaves
setblock ~171 ~134 ~69 oak_wood
setblock ~171 ~134 ~70 oak_wood
setblock ~171 ~134 ~71 oak_wood
setblock ~171 ~134 ~73 oak_leaves
setblock ~171 ~134 ~74 oak_leaves
setblock ~171 ~134 ~108 oak_leaves
setblock ~171 ~134 ~110 oak_leaves
setblock ~171 ~134 ~111 oak_leaves
setblock ~171 ~134 ~112 oak_leaves
setblock ~171 ~134 ~113 oak_leaves
setblock ~171 ~134 ~114 oak_wood
setblock ~171 ~134 ~115 oak_wood
setblock ~171 ~134 ~116 oak_wood
setblock ~171 ~134 ~117 oak_leaves
setblock ~171 ~134 ~118 oak_leaves
setblock ~171 ~134 ~119 oak_leaves
setblock ~171 ~135 ~59 oak_leaves
setblock ~171 ~135 ~60 oak_leaves
setblock ~171 ~135 ~63 oak_leaves
setblock ~171 ~135 ~64 oak_leaves
setblock ~171 ~135 ~65 oak_leaves
setblock ~171 ~135 ~66 oak_leaves
setblock ~171 ~135 ~67 oak_wood
setblock ~171 ~135 ~68 oak_leaves
setblock ~171 ~135 ~69 oak_leaves
setblock ~171 ~135 ~70 oak_wood
setblock ~171 ~135 ~71 oak_log
setblock ~171 ~135 ~72 jungle_leaves
setblock ~171 ~135 ~108 oak_leaves
setblock ~171 ~135 ~109 oak_leaves
setblock ~171 ~135 ~110 oak_leaves
setblock ~171 ~135 ~111 oak_leaves
setblock ~171 ~135 ~112 oak_leaves
setblock ~171 ~135 ~113 jungle_leaves
setblock ~171 ~135 ~114 oak_leaves
setblock ~171 ~135 ~116 oak_leaves
setblock ~171 ~135 ~117 oak_leaves
setblock ~171 ~135 ~118 oak_leaves
setblock ~171 ~135 ~119 oak_leaves
setblock ~171 ~136 ~59 oak_leaves
setblock ~171 ~136 ~60 oak_leaves
setblock ~171 ~136 ~61 oak_wood
setblock ~171 ~136 ~63 oak_leaves
setblock ~171 ~136 ~66 oak_leaves
setblock ~171 ~136 ~69 oak_log
setblock ~171 ~136 ~70 oak_log
setblock ~171 ~136 ~71 oak_leaves
setblock ~171 ~136 ~72 oak_log
setblock ~171 ~136 ~108 oak_leaves
setblock ~171 ~136 ~109 oak_leaves
setblock ~171 ~136 ~110 oak_leaves
setblock ~171 ~136 ~111 oak_leaves
setblock ~171 ~136 ~112 oak_leaves
setblock ~171 ~136 ~113 oak_leaves
setblock ~171 ~136 ~114 oak_leaves
setblock ~171 ~136 ~115 oak_leaves
setblock ~171 ~136 ~116 oak_wood
setblock ~171 ~136 ~117 oak_leaves
setblock ~171 ~136 ~118 jungle_leaves
setblock ~171 ~136 ~119 oak_leaves
setblock ~171 ~137 ~60 oak_leaves
setblock ~171 ~137 ~61 jungle_leaves
setblock ~171 ~137 ~66 jungle_leaves
setblock ~171 ~137 ~67 jungle_leaves
setblock ~171 ~137 ~68 oak_leaves
setblock ~171 ~137 ~70 oak_leaves
setblock ~171 ~137 ~71 oak_leaves
setblock ~171 ~137 ~72 oak_leaves
setblock ~171 ~137 ~74 jungle_leaves
setblock ~171 ~137 ~110 oak_leaves
setblock ~171 ~137 ~112 oak_leaves
setblock ~171 ~137 ~113 oak_leaves
setblock ~171 ~137 ~115 oak_leaves
setblock ~171 ~137 ~116 oak_leaves
setblock ~171 ~137 ~117 jungle_leaves
setblock ~171 ~137 ~118 jungle_leaves
setblock ~171 ~137 ~119 oak_leaves
setblock ~171 ~138 ~65 oak_leaves
setblock ~171 ~138 ~67 oak_leaves
setblock ~171 ~138 ~69 oak_leaves
setblock ~171 ~138 ~70 oak_leaves
setblock ~171 ~138 ~71 oak_leaves
setblock ~171 ~138 ~72 jungle_leaves
setblock ~171 ~138 ~74 oak_leaves
setblock ~171 ~138 ~110 jungle_leaves
setblock ~171 ~138 ~111 oak_leaves
setblock ~171 ~138 ~112 jungle_leaves
setblock ~171 ~138 ~116 oak_leaves
setblock ~171 ~139 ~114 oak_leaves
setblock ~171 ~139 ~115 oak_leaves
setblock ~171 ~139 ~118 oak_leaves
setblock ~171 ~139 ~119 oak_leaves
setblock ~172 ~113 ~113 dirt
setblock ~172 ~114 ~112 dirt
setblock ~172 ~114 ~113 dirt
setblock ~172 ~114 ~114 dirt
setblock ~172 ~115 ~109 dirt
setblock ~172 ~115 ~112 dirt
setblock ~172 ~115 ~113 dirt
setblock ~172 ~115 ~114 dirt
setblock ~172 ~115 ~115 dirt
setblock ~172 ~115 ~116 dirt
setblock ~172 ~116 ~75 dirt
setblock ~172 ~116 ~108 dirt
setblock ~172 ~116 ~109 dirt
setblock ~172 ~116 ~110 dirt
setblock ~172 ~116 ~111 dirt
setblock ~172 ~116 ~112 dirt
setblock ~172 ~116 ~113 dirt
setblock ~172 ~116 ~114 dirt
setblock ~172 ~116 ~115 dirt
setblock ~172 ~116 ~116 dirt
setblock ~172 ~116 ~117 dirt
setblock ~172 ~117 ~73 dirt
setblock ~172 ~117 ~74 dirt
setblock ~172 ~117 ~75 dirt
setblock ~172 ~117 ~76 dirt
setblock ~172 ~117 ~97 dirt
setblock ~172 ~117 ~98 dirt
setblock ~172 ~117 ~108 dirt
setblock ~172 ~117 ~109 dirt
setblock ~172 ~117 ~110 dirt
setblock ~172 ~117 ~111 dirt
setblock ~172 ~117 ~112 dirt
setblock ~172 ~117 ~113 dirt
setblock ~172 ~117 ~114 dirt
setblock ~172 ~117 ~115 dirt
setblock ~172 ~117 ~116 dirt
setblock ~172 ~117 ~117 dirt
setblock ~172 ~117 ~118 dirt
setblock ~172 ~118 ~72 dirt
setblock ~172 ~118 ~73 dirt
setblock ~172 ~118 ~74 dirt
setblock ~172 ~118 ~75 dirt
setblock ~172 ~118 ~76 dirt
setblock ~172 ~118 ~77 dirt
setblock ~172 ~118 ~79 dirt
setblock ~172 ~118 ~97 dirt
setblock ~172 ~118 ~98 dirt
setblock ~172 ~118 ~99 dirt
setblock ~172 ~118 ~107 dirt
setblock ~172 ~118 ~108 dirt
setblock ~172 ~118 ~109 dirt
setblock ~172 ~118 ~110 dirt
setblock ~172 ~118 ~111 dirt
setblock ~172 ~118 ~112 dirt
setblock ~172 ~118 ~113 dirt
setblock ~172 ~118 ~114 dirt
setblock ~172 ~118 ~115 dirt
setblock ~172 ~118 ~116 dirt
setblock ~172 ~118 ~117 dirt
setblock ~172 ~118 ~118 dirt
setblock ~172 ~119 ~71 dirt
setblock ~172 ~119 ~72 dirt
setblock ~172 ~119 ~73 dirt
setblock ~172 ~119 ~74 dirt
setblock ~172 ~119 ~75 dirt
setblock ~172 ~119 ~76 dirt
setblock ~172 ~119 ~77 dirt
setblock ~172 ~119 ~79 dirt
setblock ~172 ~119 ~95 dirt
setblock ~172 ~119 ~96 dirt
setblock ~172 ~119 ~97 dirt
setblock ~172 ~119 ~98 dirt
setblock ~172 ~119 ~99 dirt
setblock ~172 ~119 ~106 dirt
setblock ~172 ~119 ~107 dirt
setblock ~172 ~119 ~108 dirt
setblock ~172 ~119 ~109 dirt
setblock ~172 ~119 ~110 dirt
setblock ~172 ~119 ~111 dirt
setblock ~172 ~119 ~112 dirt
setblock ~172 ~119 ~113 dirt
setblock ~172 ~119 ~114 dirt
setblock ~172 ~119 ~115 dirt
setblock ~172 ~119 ~116 dirt
setblock ~172 ~119 ~117 dirt
setblock ~172 ~119 ~118 dirt
setblock ~172 ~119 ~122 dirt
setblock ~172 ~120 ~70 dirt
setblock ~172 ~120 ~71 dirt
setblock ~172 ~120 ~72 dirt
setblock ~172 ~120 ~73 dirt
setblock ~172 ~120 ~74 dirt
setblock ~172 ~120 ~75 dirt
setblock ~172 ~120 ~76 dirt
setblock ~172 ~120 ~77 dirt
setblock ~172 ~120 ~79 dirt
setblock ~172 ~120 ~80 dirt
setblock ~172 ~120 ~94 dirt
setblock ~172 ~120 ~95 dirt
setblock ~172 ~120 ~96 dirt
setblock ~172 ~120 ~97 dirt
setblock ~172 ~120 ~98 dirt
setblock ~172 ~120 ~99 dirt
setblock ~172 ~120 ~100 dirt
setblock ~172 ~120 ~106 dirt
setblock ~172 ~120 ~107 dirt
setblock ~172 ~120 ~108 dirt
setblock ~172 ~120 ~109 dirt
setblock ~172 ~120 ~110 dirt
setblock ~172 ~120 ~111 dirt
setblock ~172 ~120 ~112 dirt
setblock ~172 ~120 ~113 dirt
setblock ~172 ~120 ~114 dirt
setblock ~172 ~120 ~115 dirt
setblock ~172 ~120 ~116 dirt
setblock ~172 ~120 ~117 dirt
setblock ~172 ~120 ~118 dirt
setblock ~172 ~120 ~119 dirt
setblock ~172 ~120 ~120 dirt
setblock ~172 ~120 ~121 dirt
setblock ~172 ~120 ~122 dirt
setblock ~172 ~120 ~123 dirt
setblock ~172 ~121 ~70 dirt
setblock ~172 ~121 ~71 dirt
setblock ~172 ~121 ~72 dirt
setblock ~172 ~121 ~73 dirt
setblock ~172 ~121 ~74 dirt
setblock ~172 ~121 ~75 dirt
setblock ~172 ~121 ~76 dirt
setblock ~172 ~121 ~77 dirt
setblock ~172 ~121 ~78 dirt
setblock ~172 ~121 ~79 dirt
setblock ~172 ~121 ~80 dirt
setblock ~172 ~121 ~81 dirt
setblock ~172 ~121 ~83 dirt
setblock ~172 ~121 ~94 dirt
setblock ~172 ~121 ~95 dirt
setblock ~172 ~121 ~96 dirt
setblock ~172 ~121 ~97 dirt
setblock ~172 ~121 ~98 dirt
setblock ~172 ~121 ~99 dirt
setblock ~172 ~121 ~100 dirt
setblock ~172 ~121 ~101 dirt
setblock ~172 ~121 ~103 dirt
setblock ~172 ~121 ~106 dirt
setblock ~172 ~121 ~107 dirt
setblock ~172 ~121 ~108 dirt
setblock ~172 ~121 ~109 dirt
setblock ~172 ~121 ~110 dirt
setblock ~172 ~121 ~111 dirt
setblock ~172 ~121 ~112 dirt
setblock ~172 ~121 ~113 dirt
setblock ~172 ~121 ~114 dirt
setblock ~172 ~121 ~115 dirt
setblock ~172 ~121 ~116 dirt
setblock ~172 ~121 ~117 dirt
setblock ~172 ~121 ~118 dirt
setblock ~172 ~121 ~119 dirt
setblock ~172 ~121 ~120 dirt
setblock ~172 ~121 ~121 dirt
setblock ~172 ~121 ~122 dirt
setblock ~172 ~121 ~123 dirt
setblock ~172 ~121 ~124 dirt
setblock ~172 ~122 ~70 dirt
setblock ~172 ~122 ~71 dirt
setblock ~172 ~122 ~72 dirt
setblock ~172 ~122 ~73 dirt
setblock ~172 ~122 ~74 dirt
setblock ~172 ~122 ~75 dirt
setblock ~172 ~122 ~76 dirt
setblock ~172 ~122 ~77 dirt
setblock ~172 ~122 ~78 dirt
setblock ~172 ~122 ~79 dirt
setblock ~172 ~122 ~80 dirt
setblock ~172 ~122 ~81 dirt
setblock ~172 ~122 ~83 dirt
setblock ~172 ~122 ~94 dirt
setblock ~172 ~122 ~95 dirt
setblock ~172 ~122 ~96 dirt
setblock ~172 ~122 ~97 dirt
setblock ~172 ~122 ~98 dirt
setblock ~172 ~122 ~99 dirt
setblock ~172 ~122 ~100 dirt
setblock ~172 ~122 ~101 dirt
setblock ~172 ~122 ~103 dirt
setblock ~172 ~122 ~106 dirt
setblock ~172 ~122 ~107 dirt
setblock ~172 ~122 ~108 dirt
setblock ~172 ~122 ~109 grass_block
setblock ~172 ~122 ~110 grass_block
setblock ~172 ~122 ~111 grass_block
setblock ~172 ~122 ~112 grass_block
setblock ~172 ~122 ~113 dirt
setblock ~172 ~122 ~114 dirt
setblock ~172 ~122 ~115 dirt
setblock ~172 ~122 ~116 dirt
setblock ~172 ~122 ~117 dirt
setblock ~172 ~122 ~118 dirt
setblock ~172 ~122 ~119 dirt
setblock ~172 ~122 ~120 dirt
setblock ~172 ~122 ~121 dirt
setblock ~172 ~122 ~122 dirt
setblock ~172 ~122 ~123 dirt
setblock ~172 ~122 ~124 dirt
setblock ~172 ~123 ~70 grass_block
setblock ~172 ~123 ~71 grass_block
setblock ~172 ~123 ~72 grass_block
setblock ~172 ~123 ~73 grass_block
setblock ~172 ~123 ~74 grass_block
setblock ~172 ~123 ~75 dirt
setblock ~172 ~123 ~76 dirt
setblock ~172 ~123 ~77 dirt
setblock ~172 ~123 ~78 dirt
setblock ~172 ~123 ~79 dirt
setblock ~172 ~123 ~80 dirt
setblock ~172 ~123 ~81 dirt
setblock ~172 ~123 ~83 dirt
setblock ~172 ~123 ~94 dirt
setblock ~172 ~123 ~95 dirt
setblock ~172 ~123 ~96 dirt
setblock ~172 ~123 ~97 dirt
setblock ~172 ~123 ~98 dirt
setblock ~172 ~123 ~99 dirt
setblock ~172 ~123 ~100 dirt
setblock ~172 ~123 ~101 dirt
setblock ~172 ~123 ~103 dirt
setblock ~172 ~123 ~106 grass_block
setblock ~172 ~123 ~107 grass_block
setblock ~172 ~123 ~108 grass_block
setblock ~172 ~123 ~113 grass_block
setblock ~172 ~123 ~114 grass_block
setblock ~172 ~123 ~115 grass_block
setblock ~172 ~123 ~116 grass_block
setblock ~172 ~123 ~117 grass_block
setblock ~172 ~123 ~118 grass_block
setblock ~172 ~123 ~119 grass_block
setblock ~172 ~123 ~120 grass_block
setblock ~172 ~123 ~121 dirt
setblock ~172 ~123 ~122 dirt
setblock ~172 ~123 ~123 dirt
setblock ~172 ~123 ~124 dirt
setblock ~172 ~124 ~71 short_grass
setblock ~172 ~124 ~75 grass_block
setblock ~172 ~124 ~76 grass_block
setblock ~172 ~124 ~77 grass_block
setblock ~172 ~124 ~78 grass_block
setblock ~172 ~124 ~79 grass_block
setblock ~172 ~124 ~80 grass_block
setblock ~172 ~124 ~81 grass_block
setblock ~172 ~124 ~83 dirt
setblock ~172 ~124 ~94 dirt
setblock ~172 ~124 ~95 dirt
setblock ~172 ~124 ~96 dirt
setblock ~172 ~124 ~97 dirt
setblock ~172 ~124 ~98 dirt
setblock ~172 ~124 ~99 dirt
setblock ~172 ~124 ~100 dirt
setblock ~172 ~124 ~101 grass_block
setblock ~172 ~124 ~103 grass_block
setblock ~172 ~124 ~121 grass_block
setblock ~172 ~124 ~122 grass_block
setblock ~172 ~124 ~123 grass_block
setblock ~172 ~124 ~124 grass_block
setblock ~172 ~125 ~76 short_grass
setblock ~172 ~125 ~83 grass_block
setblock ~172 ~125 ~94 dirt
setblock ~172 ~125 ~95 dirt
setblock ~172 ~125 ~96 dirt
setblock ~172 ~125 ~97 dirt
setblock ~172 ~125 ~98 grass_block
setblock ~172 ~125 ~99 grass_block
setblock ~172 ~125 ~100 grass_block
setblock ~172 ~125 ~121 short_grass
setblock ~172 ~126 ~94 grass_block
setblock ~172 ~126 ~95 grass_block
setblock ~172 ~126 ~96 grass_block
setblock ~172 ~126 ~97 grass_block
setblock ~172 ~127 ~96 poppy
setblock ~172 ~128 ~69 oak_leaves
setblock ~172 ~128 ~70 oak_leaves
setblock ~172 ~128 ~72 oak_leaves
setblock ~172 ~128 ~73 oak_leaves
setblock ~172 ~128 ~74 oak_leaves
setblock ~172 ~129 ~62 oak_leaves
setblock ~172 ~129 ~63 oak_leaves
setblock ~172 ~129 ~68 jungle_leaves
setblock ~172 ~129 ~73 oak_leaves
setblock ~172 ~130 ~62 oak_leaves
setblock ~172 ~130 ~63 oak_leaves
setblock ~172 ~130 ~64 oak_leaves
setblock ~172 ~130 ~65 oak_leaves
setblock ~172 ~130 ~66 oak_wood
setblock ~172 ~130 ~67 jungle_leaves
setblock ~172 ~130 ~68 oak_leaves
setblock ~172 ~130 ~70 oak_leaves
setblock ~172 ~130 ~71 oak_wood
setblock ~172 ~130 ~74 oak_leaves
setblock ~172 ~130 ~112 oak_leaves
setblock ~172 ~130 ~113 oak_leaves
setblock ~172 ~130 ~114 oak_leaves
setblock ~172 ~130 ~115 oak_leaves
setblock ~172 ~131 ~62 oak_leaves
setblock ~172 ~131 ~63 oak_leaves
setblock ~172 ~131 ~64 oak_leaves
setblock ~172 ~131 ~65 oak_leaves
setblock ~172 ~131 ~66 oak_leaves
setblock ~172 ~131 ~67 oak_wood
setblock ~172 ~131 ~68 oak_log
setblock ~172 ~131 ~69 oak_leaves
setblock ~172 ~131 ~70 oak_wood
setblock ~172 ~131 ~71 oak_leaves
setblock ~172 ~131 ~72 oak_leaves
setblock ~172 ~131 ~108 oak_leaves
setblock ~172 ~131 ~109 oak_leaves
setblock ~172 ~131 ~110 oak_leaves
setblock ~172 ~131 ~114 jungle_leaves
setblock ~172 ~131 ~115 oak_leaves
setblock ~172 ~131 ~117 oak_leaves
setblock ~172 ~131 ~118 jungle_leaves
setblock ~172 ~132 ~63 oak_leaves
setblock ~172 ~132 ~64 oak_leaves
setblock ~172 ~132 ~65 oak_wood
setblock ~172 ~132 ~66 oak_leaves
setblock ~172 ~132 ~67 jungle_leaves
setblock ~172 ~132 ~68 oak_leaves
setblock ~172 ~132 ~69 oak_leaves
setblock ~172 ~132 ~70 oak_wood
setblock ~172 ~132 ~71 oak_leaves
setblock ~172 ~132 ~108 oak_leaves
setblock ~172 ~132 ~109 oak_leaves
setblock ~172 ~132 ~110 oak_leaves
setblock ~172 ~132 ~113 jungle_leaves
setblock ~172 ~132 ~116 oak_wood
setblock ~172 ~132 ~117 oak_leaves
setblock ~172 ~132 ~118 oak_leaves
setblock ~172 ~133 ~64 jungle_leaves
setblock ~172 ~133 ~66 oak_leaves
setblock ~172 ~133 ~67 oak_wood
setblock ~172 ~133 ~68 oak_wood
setblock ~172 ~133 ~70 oak_wood
setblock ~172 ~133 ~71 oak_leaves
setblock ~172 ~133 ~72 oak_leaves
setblock ~172 ~133 ~109 oak_leaves
setblock ~172 ~133 ~110 oak_leaves
setblock ~172 ~133 ~111 oak_leaves
setblock ~172 ~133 ~112 oak_leaves
setblock ~172 ~133 ~113 oak_leaves
setblock ~172 ~133 ~115 oak_wood
setblock ~172 ~133 ~116 jungle_leaves
setblock ~172 ~133 ~118 oak_leaves
setblock ~172 ~133 ~119 oak_leaves
setblock ~172 ~134 ~63 oak_leaves
setblock ~172 ~134 ~64 oak_leaves
setblock ~172 ~134 ~67 oak_leaves
setblock ~172 ~134 ~68 jungle_leaves
setblock ~172 ~134 ~69 oak_wood
setblock ~172 ~134 ~73 oak_leaves
setblock ~172 ~134 ~109 jungle_leaves
setblock ~172 ~134 ~110 oak_leaves
setblock ~172 ~134 ~112 oak_wood
setblock ~172 ~134 ~115 oak_wood
setblock ~172 ~134 ~116 oak_wood
setblock ~172 ~134 ~117 oak_leaves
setblock ~172 ~134 ~118 oak_leaves
setblock ~172 ~134 ~119 oak_leaves
setblock ~172 ~135 ~63 oak_leaves
setblock ~172 ~135 ~64 oak_leaves
setblock ~172 ~135 ~65 jungle_leaves
setblock ~172 ~135 ~66 oak_wood
setblock ~172 ~135 ~67 oak_wood
setblock ~172 ~135 ~68 oak_leaves
setblock ~172 ~135 ~69 oak_log
setblock ~172 ~135 ~72 jungle_leaves
setblock ~172 ~135 ~74 jungle_leaves
setblock ~172 ~135 ~106 oak_leaves
setblock ~172 ~135 ~109 oak_leaves
setblock ~172 ~135 ~111 jungle_leaves
setblock ~172 ~135 ~112 oak_leaves
setblock ~172 ~135 ~113 oak_leaves
setblock ~172 ~135 ~114 oak_leaves
setblock ~172 ~135 ~115 oak_leaves
setblock ~172 ~135 ~116 oak_wood
setblock ~172 ~135 ~118 oak_leaves
setblock ~172 ~136 ~63 oak_leaves
setblock ~172 ~136 ~65 oak_leaves
setblock ~172 ~136 ~67 oak_leaves
setblock ~172 ~136 ~68 oak_log
setblock ~172 ~136 ~69 oak_log
setblock ~172 ~136 ~71 oak_log
setblock ~172 ~136 ~72 oak_leaves
setblock ~172 ~136 ~105 oak_leaves
setblock ~172 ~136 ~108 oak_leaves
setblock ~172 ~136 ~109 oak_leaves
setblock ~172 ~136 ~111 oak_leaves
setblock ~172 ~136 ~112 oak_leaves
setblock ~172 ~136 ~113 oak_leaves
setblock ~172 ~136 ~114 jungle_leaves
setblock ~172 ~136 ~115 oak_leaves
setblock ~172 ~136 ~118 jungle_leaves
setblock ~172 ~136 ~119 oak_leaves
setblock ~172 ~137 ~64 oak_leaves
setblock ~172 ~137 ~65 oak_leaves
setblock ~172 ~137 ~68 oak_leaves
setblock ~172 ~137 ~70 oak_leaves
setblock ~172 ~137 ~71 oak_leaves
setblock ~172 ~137 ~105 oak_leaves
setblock ~172 ~137 ~106 oak_leaves
setblock ~172 ~137 ~107 oak_leaves
setblock ~172 ~137 ~109 oak_leaves
setblock ~172 ~137 ~111 oak_leaves
setblock ~172 ~137 ~112 oak_leaves
setblock ~172 ~137 ~113 oak_leaves
setblock ~172 ~137 ~114 jungle_leaves
setblock ~172 ~137 ~115 oak_leaves
setblock ~172 ~137 ~116 oak_leaves
setblock ~172 ~137 ~117 oak_leaves
setblock ~172 ~137 ~118 jungle_leaves
setblock ~172 ~137 ~119 oak_leaves
setblock ~172 ~138 ~65 oak_leaves
setblock ~172 ~138 ~67 oak_leaves
setblock ~172 ~138 ~69 oak_leaves
setblock ~172 ~138 ~72 jungle_leaves
setblock ~172 ~138 ~74 oak_leaves
setblock ~172 ~138 ~110 oak_leaves
setblock ~172 ~138 ~112 oak_leaves
setblock ~172 ~138 ~113 jungle_leaves
setblock ~172 ~138 ~114 oak_leaves
setblock ~172 ~138 ~115 oak_leaves
setblock ~172 ~138 ~117 oak_leaves
setblock ~172 ~138 ~118 jungle_leaves
setblock ~172 ~138 ~119 oak_leaves
setblock ~172 ~139 ~114 jungle_leaves
setblock ~172 ~139 ~115 oak_leaves
setblock ~172 ~139 ~116 oak_leaves
setblock ~172 ~139 ~117 oak_leaves
setblock ~173 ~114 ~113 dirt
setblock ~173 ~115 ~113 dirt
setblock ~173 ~115 ~114 dirt
setblock ~173 ~116 ~112 dirt
setblock ~173 ~116 ~113 dirt
setblock ~173 ~116 ~114 dirt
setblock ~173 ~116 ~115 dirt
setblock ~173 ~117 ~109 dirt
setblock ~173 ~117 ~111 dirt
setblock ~173 ~117 ~112 dirt
setblock ~173 ~117 ~113 dirt
setblock ~173 ~117 ~114 dirt
setblock ~173 ~117 ~115 dirt
setblock ~173 ~117 ~116 dirt
setblock ~173 ~117 ~117 dirt
setblock ~173 ~118 ~73 dirt
setblock ~173 ~118 ~76 dirt
setblock ~173 ~118 ~98 dirt
setblock ~173 ~118 ~108 dirt
setblock ~173 ~118 ~109 dirt
setblock ~173 ~118 ~111 dirt
setblock ~173 ~118 ~112 dirt
setblock ~173 ~118 ~113 dirt
setblock ~173 ~118 ~114 dirt
setblock ~173 ~118 ~115 dirt
setblock ~173 ~118 ~116 dirt
setblock ~173 ~118 ~117 dirt
setblock ~173 ~119 ~73 dirt
setblock ~173 ~119 ~75 dirt
setblock ~173 ~119 ~76 dirt
setblock ~173 ~119 ~98 dirt
setblock ~173 ~119 ~108 dirt
setblock ~173 ~119 ~109 dirt
setblock ~173 ~119 ~110 dirt
setblock ~173 ~119 ~111 dirt
setblock ~173 ~119 ~112 dirt
setblock ~173 ~119 ~113 dirt
setblock ~173 ~119 ~114 dirt
setblock ~173 ~119 ~115 dirt
setblock ~173 ~119 ~116 dirt
setblock ~173 ~119 ~117 dirt
setblock ~173 ~119 ~118 dirt
setblock ~173 ~120 ~71 dirt
setblock ~173 ~120 ~72 dirt
setblock ~173 ~120 ~73 dirt
setblock ~173 ~120 ~74 dirt
setblock ~173 ~120 ~75 dirt
setblock ~173 ~120 ~76 dirt
setblock ~173 ~120 ~77 dirt
setblock ~173 ~120 ~95 dirt
setblock ~173 ~120 ~98 dirt
setblock ~173 ~120 ~108 dirt
setblock ~173 ~120 ~109 dirt
setblock ~173 ~120 ~110 dirt
setblock ~173 ~120 ~111 dirt
setblock ~173 ~120 ~112 dirt
setblock ~173 ~120 ~113 dirt
setblock ~173 ~120 ~114 dirt
setblock ~173 ~120 ~115 dirt
setblock ~173 ~120 ~116 dirt
setblock ~173 ~120 ~117 dirt
setblock ~173 ~120 ~118 dirt
setblock ~173 ~120 ~122 dirt
setblock ~173 ~121 ~71 dirt
setblock ~173 ~121 ~72 dirt
setblock ~173 ~121 ~73 dirt
setblock ~173 ~121 ~74 dirt
setblock ~173 ~121 ~75 dirt
setblock ~173 ~121 ~76 dirt
setblock ~173 ~121 ~77 dirt
setblock ~173 ~121 ~80 dirt
setblock ~173 ~121 ~95 dirt
setblock ~173 ~121 ~97 dirt
setblock ~173 ~121 ~98 dirt
setblock ~173 ~121 ~100 dirt
setblock ~173 ~121 ~107 dirt
setblock ~173 ~121 ~108 dirt
setblock ~173 ~121 ~109 dirt
setblock ~173 ~121 ~110 dirt
setblock ~173 ~121 ~111 dirt
setblock ~173 ~121 ~112 dirt
setblock ~173 ~121 ~113 dirt
setblock ~173 ~121 ~114 dirt
setblock ~173 ~121 ~115 dirt
setblock ~173 ~121 ~116 dirt
setblock ~173 ~121 ~117 dirt
setblock ~173 ~121 ~118 dirt
setblock ~173 ~121 ~119 dirt
setblock ~173 ~121 ~120 dirt
setblock ~173 ~121 ~121 dirt
setblock ~173 ~121 ~122 dirt
setblock ~173 ~121 ~123 dirt
setblock ~173 ~122 ~71 dirt
setblock ~173 ~122 ~72 dirt
setblock ~173 ~122 ~73 dirt
setblock ~173 ~122 ~74 dirt
setblock ~173 ~122 ~75 dirt
setblock ~173 ~122 ~76 dirt
setblock ~173 ~122 ~77 dirt
setblock ~173 ~122 ~80 dirt
setblock ~173 ~122 ~95 dirt
setblock ~173 ~122 ~97 dirt
setblock ~173 ~122 ~98 dirt
setblock ~173 ~122 ~100 dirt
setblock ~173 ~122 ~107 dirt
setblock ~173 ~122 ~108 dirt
setblock ~173 ~122 ~109 dirt
setblock ~173 ~122 ~110 dirt
setblock ~173 ~122 ~111 dirt
setblock ~173 ~122 ~112 dirt
setblock ~173 ~122 ~113 dirt
setblock ~173 ~122 ~114 dirt
setblock ~173 ~122 ~115 dirt
setblock ~173 ~122 ~116 dirt
setblock ~173 ~122 ~117 dirt
setblock ~173 ~122 ~118 dirt
setblock ~173 ~122 ~119 dirt
setblock ~173 ~122 ~120 dirt
setblock ~173 ~122 ~121 dirt
setblock ~173 ~122 ~122 dirt
setblock ~173 ~122 ~123 dirt
setblock ~173 ~123 ~71 grass_block
setblock ~173 ~123 ~72 grass_block
setblock ~173 ~123 ~73 grass_block
setblock ~173 ~123 ~74 grass_block
setblock ~173 ~123 ~75 dirt
setblock ~173 ~123 ~76 dirt
setblock ~173 ~123 ~77 dirt
setblock ~173 ~123 ~80 dirt
setblock ~173 ~123 ~95 dirt
setblock ~173 ~123 ~97 dirt
setblock ~173 ~123 ~98 dirt
setblock ~173 ~123 ~100 dirt
setblock ~173 ~123 ~107 grass_block
setblock ~173 ~123 ~108 grass_block
setblock ~173 ~123 ~109 grass_block
setblock ~173 ~123 ~110 grass_block
setblock ~173 ~123 ~111 grass_block
setblock ~173 ~123 ~112 grass_block
setblock ~173 ~123 ~113 grass_block
setblock ~173 ~123 ~114 grass_block
setblock ~173 ~123 ~115 grass_block
setblock ~173 ~123 ~116 grass_block
setblock ~173 ~123 ~117 grass_block
setblock ~173 ~123 ~118 grass_block
setblock ~173 ~123 ~119 grass_block
setblock ~173 ~123 ~120 dirt
setblock ~173 ~123 ~121 dirt
setblock ~173 ~123 ~122 dirt
setblock ~173 ~123 ~123 dirt
setblock ~173 ~124 ~74 short_grass
setblock ~173 ~124 ~75 grass_block
setblock ~173 ~124 ~76 grass_block
setblock ~173 ~124 ~77 grass_block
setblock ~173 ~124 ~80 grass_block
setblock ~173 ~124 ~95 dirt
setblock ~173 ~124 ~97 dirt
setblock ~173 ~124 ~98 dirt
setblock ~173 ~124 ~100 dirt
setblock ~173 ~124 ~107 short_grass
setblock ~173 ~124 ~108 fern
setblock ~173 ~124 ~109 poppy
setblock ~173 ~124 ~110 poppy
setblock ~173 ~124 ~115 short_grass
setblock ~173 ~124 ~117 fern
setblock ~173 ~124 ~120 grass_block
setblock ~173 ~124 ~121 grass_block
setblock ~173 ~124 ~122 grass_block
setblock ~173 ~124 ~123 grass_block
setblock ~173 ~125 ~77 fern
setblock ~173 ~125 ~95 dirt
setblock ~173 ~125 ~97 dirt
setblock ~173 ~125 ~98 grass_block
setblock ~173 ~125 ~100 grass_block
setblock ~173 ~125 ~113 spruce_slab
setblock ~173 ~125 ~115 spruce_slab
setblock ~173 ~125 ~122 short_grass
setblock ~173 ~126 ~95 grass_block
setblock ~173 ~126 ~97 grass_block
setblock ~173 ~127 ~74 oak_leaves
setblock ~173 ~127 ~76 oak_leaves
setblock ~173 ~127 ~95 poppy
setblock ~173 ~127 ~97 fern
setblock ~173 ~128 ~69 oak_leaves
setblock ~173 ~128 ~70 oak_leaves
setblock ~173 ~128 ~71 oak_leaves
setblock ~173 ~128 ~72 oak_leaves
setblock ~173 ~128 ~74 oak_leaves
setblock ~173 ~128 ~75 jungle_leaves
setblock ~173 ~128 ~76 oak_leaves
setblock ~173 ~129 ~63 oak_leaves
setblock ~173 ~129 ~64 oak_leaves
setblock ~173 ~129 ~65 oak_leaves
setblock ~173 ~129 ~66 oak_leaves
setblock ~173 ~129 ~67 oak_leaves
setblock ~173 ~129 ~68 jungle_leaves
setblock ~173 ~129 ~69 oak_leaves
setblock ~173 ~129 ~70 jungle_leaves
setblock ~173 ~129 ~71 oak_leaves
setblock ~173 ~129 ~72 oak_leaves
setblock ~173 ~129 ~73 oak_wood
setblock ~173 ~129 ~75 oak_leaves
setblock ~173 ~129 ~114 spruce_slab
setblock ~173 ~129 ~116 oak_leaves
setblock ~173 ~130 ~62 oak_leaves
setblock ~173 ~130 ~63 oak_leaves
setblock ~173 ~130 ~64 jungle_leaves
setblock ~173 ~130 ~66 oak_leaves
setblock ~173 ~130 ~67 oak_leaves
setblock ~173 ~130 ~68 oak_leaves
setblock ~173 ~130 ~69 oak_leaves
setblock ~173 ~130 ~70 jungle_leaves
setblock ~173 ~130 ~71 oak_leaves
setblock ~173 ~130 ~72 oak_wood
setblock ~173 ~130 ~73 oak_leaves
setblock ~173 ~130 ~74 oak_leaves
setblock ~173 ~130 ~75 oak_leaves
setblock ~173 ~130 ~112 oak_leaves
setblock ~173 ~130 ~114 oak_log
setblock ~173 ~130 ~115 jungle_leaves
setblock ~173 ~130 ~116 oak_leaves
setblock ~173 ~130 ~117 oak_leaves
setblock ~173 ~130 ~118 oak_leaves
setblock ~173 ~131 ~64 oak_wood
setblock ~173 ~131 ~65 oak_leaves
setblock ~173 ~131 ~66 oak_leaves
setblock ~173 ~131 ~67 oak_wood
setblock ~173 ~131 ~69 oak_wood
setblock ~173 ~131 ~70 oak_leaves
setblock ~173 ~131 ~71 jungle_leaves
setblock ~173 ~131 ~73 oak_leaves
setblock ~173 ~131 ~114 oak_log
setblock ~173 ~131 ~116 oak_leaves
setblock ~173 ~131 ~117 oak_leaves
setblock ~173 ~131 ~118 oak_leaves
setblock ~173 ~132 ~65 oak_wood
setblock ~173 ~132 ~66 oak_wood
setblock ~173 ~132 ~67 oak_leaves
setblock ~173 ~132 ~68 oak_wood
setblock ~173 ~132 ~69 oak_leaves
setblock ~173 ~132 ~70 jungle_leaves
setblock ~173 ~132 ~71 oak_wood
setblock ~173 ~132 ~73 oak_leaves
setblock ~173 ~132 ~105 oak_leaves
setblock ~173 ~132 ~106 jungle_leaves
setblock ~173 ~132 ~107 oak_leaves
setblock ~173 ~132 ~108 oak_leaves
setblock ~173 ~132 ~111 oak_leaves
setblock ~173 ~132 ~112 jungle_leaves
setblock ~173 ~132 ~113 oak_leaves
setblock ~173 ~132 ~114 oak_wood
setblock ~173 ~132 ~115 oak_log
setblock ~173 ~132 ~117 oak_leaves
setblock ~173 ~133 ~65 oak_leaves
setblock ~173 ~133 ~66 oak_leaves
setblock ~173 ~133 ~67 jungle_leaves
setblock ~173 ~133 ~69 oak_wood
setblock ~173 ~133 ~70 oak_wood
setblock ~173 ~133 ~71 oak_wood
setblock ~173 ~133 ~72 oak_leaves
setblock ~173 ~133 ~73 oak_leaves
setblock ~173 ~133 ~106 oak_leaves
setblock ~173 ~133 ~107 oak_leaves
setblock ~173 ~133 ~109 oak_leaves
setblock ~173 ~133 ~110 oak_leaves
setblock ~173 ~133 ~111 oak_leaves
setblock ~173 ~133 ~112 jungle_leaves
setblock ~173 ~133 ~113 oak_wood
setblock ~173 ~133 ~114 oak_wood
setblock ~173 ~133 ~115 oak_wood
setblock ~173 ~133 ~116 oak_leaves
setblock ~173 ~133 ~119 oak_leaves
setblock ~173 ~134 ~64 oak_leaves
setblock ~173 ~134 ~65 oak_leaves
setblock ~173 ~134 ~66 jungle_leaves
setblock ~173 ~134 ~69 oak_log
setblock ~173 ~134 ~70 oak_leaves
setblock ~173 ~134 ~71 oak_leaves
setblock ~173 ~134 ~72 jungle_leaves
setblock ~173 ~134 ~73 oak_leaves
setblock ~173 ~134 ~104 oak_leaves
setblock ~173 ~134 ~105 jungle_leaves
setblock ~173 ~134 ~108 jungle_leaves
setblock ~173 ~134 ~109 oak_wood
setblock ~173 ~134 ~110 oak_wood
setblock ~173 ~134 ~111 oak_wood
setblock ~173 ~134 ~112 oak_wood
setblock ~173 ~134 ~113 oak_wood
setblock ~173 ~134 ~114 oak_leaves
setblock ~173 ~134 ~115 oak_wood
setblock ~173 ~134 ~116 oak_wood
setblock ~173 ~134 ~119 oak_leaves
setblock ~173 ~135 ~63 oak_leaves
setblock ~173 ~135 ~64 oak_leaves
setblock ~173 ~135 ~65 oak_leaves
setblock ~173 ~135 ~68 oak_leaves
setblock ~173 ~135 ~69 oak_log
setblock ~173 ~135 ~70 oak_leaves
setblock ~173 ~135 ~71 oak_leaves
setblock ~173 ~135 ~73 jungle_leaves
setblock ~173 ~135 ~74 oak_leaves
setblock ~173 ~135 ~106 jungle_leaves
setblock ~173 ~135 ~108 oak_leaves
setblock ~173 ~135 ~109 oak_wood
setblock ~173 ~135 ~110 oak_wood
setblock ~173 ~135 ~111 oak_wood
setblock ~173 ~135 ~112 oak_wood
setblock ~173 ~135 ~113 oak_leaves
setblock ~173 ~135 ~114 oak_leaves
setblock ~173 ~135 ~115 oak_leaves
setblock ~173 ~135 ~116 oak_wood
setblock ~173 ~135 ~118 oak_leaves
setblock ~173 ~135 ~119 oak_leaves
setblock ~173 ~136 ~63 oak_leaves
setblock ~173 ~136 ~64 oak_leaves
setblock ~173 ~136 ~65 jungle_leaves
setblock ~173 ~136 ~66 oak_wood
setblock ~173 ~136 ~67 jungle_leaves
setblock ~173 ~136 ~68 oak_leaves
setblock ~173 ~136 ~70 oak_leaves
setblock ~173 ~136 ~71 oak_leaves
setblock ~173 ~136 ~72 jungle_leaves
setblock ~173 ~136 ~73 oak_leaves
setblock ~173 ~136 ~74 oak_leaves
setblock ~173 ~136 ~105 oak_leaves
setblock ~173 ~136 ~106 oak_leaves
setblock ~173 ~136 ~107 oak_wood
setblock ~173 ~136 ~108 oak_wood
setblock ~173 ~136 ~109 oak_leaves
setblock ~173 ~136 ~110 oak_leaves
setblock ~173 ~136 ~111 oak_leaves
setblock ~173 ~136 ~113 oak_wood
setblock ~173 ~136 ~114 oak_leaves
setblock ~173 ~136 ~115 oak_leaves
setblock ~173 ~136 ~116 oak_leaves
setblock ~173 ~136 ~117 oak_leaves
setblock ~173 ~136 ~118 jungle_leaves
setblock ~173 ~136 ~119 oak_leaves
setblock ~173 ~137 ~63 oak_leaves
setblock ~173 ~137 ~64 oak_leaves
setblock ~173 ~137 ~65 oak_leaves
setblock ~173 ~137 ~66 oak_leaves
setblock ~173 ~137 ~67 oak_leaves
setblock ~173 ~137 ~68 jungle_leaves
setblock ~173 ~137 ~69 oak_leaves
setblock ~173 ~137 ~70 jungle_leaves
setblock ~173 ~137 ~71 oak_leaves
setblock ~173 ~137 ~73 oak_leaves
setblock ~173 ~137 ~74 oak_leaves
setblock ~173 ~137 ~105 oak_leaves
setblock ~173 ~137 ~108 oak_leaves
setblock ~173 ~137 ~109 oak_leaves
setblock ~173 ~137 ~110 oak_leaves
setblock ~173 ~137 ~111 oak_leaves
setblock ~173 ~137 ~112 oak_leaves
setblock ~173 ~137 ~113 oak_leaves
setblock ~173 ~137 ~114 oak_leaves
setblock ~173 ~137 ~116 oak_log
setblock ~173 ~137 ~117 oak_log
setblock ~173 ~137 ~118 jungle_leaves
setblock ~173 ~137 ~119 oak_leaves
setblock ~173 ~138 ~65 jungle_leaves
setblock ~173 ~138 ~67 jungle_leaves
setblock ~173 ~138 ~68 oak_leaves
setblock ~173 ~138 ~70 oak_leaves
setblock ~173 ~138 ~73 oak_leaves
setblock ~173 ~138 ~74 jungle_leaves
setblock ~173 ~138 ~110 oak_leaves
setblock ~173 ~138 ~113 jungle_leaves
setblock ~173 ~138 ~114 oak_leaves
setblock ~173 ~138 ~115 jungle_leaves
setblock ~173 ~138 ~116 oak_leaves
setblock ~173 ~138 ~118 oak_leaves
setblock ~173 ~139 ~113 jungle_leaves
setblock ~173 ~139 ~114 oak_leaves
setblock ~173 ~139 ~115 oak_leaves
setblock ~173 ~139 ~116 oak_leaves
setblock ~173 ~139 ~117 jungle_leaves
setblock ~173 ~139 ~118 oak_leaves
setblock ~173 ~139 ~119 oak_leaves
setblock ~174 ~116 ~113 dirt
setblock ~174 ~117 ~112 dirt
setblock ~174 ~117 ~113 dirt
setblock ~174 ~117 ~114 dirt
setblock ~174 ~117 ~115 dirt
setblock ~174 ~118 ~111 dirt
setblock ~174 ~118 ~112 dirt
setblock ~174 ~118 ~113 dirt
setblock ~174 ~118 ~114 dirt
setblock ~174 ~118 ~115 dirt
setblock ~174 ~118 ~116 dirt
setblock ~174 ~119 ~111 dirt
setblock ~174 ~119 ~112 dirt
setblock ~174 ~119 ~113 dirt
setblock ~174 ~119 ~114 dirt
setblock ~174 ~119 ~115 dirt
setblock ~174 ~119 ~116 dirt
setblock ~174 ~119 ~117 dirt
setblock ~174 ~120 ~75 dirt
setblock ~174 ~120 ~76 dirt
setblock ~174 ~120 ~110 dirt
setblock ~174 ~120 ~111 dirt
setblock ~174 ~120 ~112 dirt
setblock ~174 ~120 ~113 dirt
setblock ~174 ~120 ~114 dirt
setblock ~174 ~120 ~115 dirt
setblock ~174 ~120 ~116 dirt
setblock ~174 ~120 ~117 dirt
setblock ~174 ~121 ~73 dirt
setblock ~174 ~121 ~75 dirt
setblock ~174 ~121 ~76 dirt
setblock ~174 ~121 ~77 dirt
setblock ~174 ~121 ~108 dirt
setblock ~174 ~121 ~109 dirt
setblock ~174 ~121 ~110 dirt
setblock ~174 ~121 ~111 dirt
setblock ~174 ~121 ~112 dirt
setblock ~174 ~121 ~113 dirt
setblock ~174 ~121 ~114 dirt
setblock ~174 ~121 ~115 dirt
setblock ~174 ~121 ~116 dirt
setblock ~174 ~121 ~117 dirt
setblock ~174 ~121 ~118 dirt
setblock ~174 ~121 ~122 dirt
setblock ~174 ~122 ~73 dirt
setblock ~174 ~122 ~75 dirt
setblock ~174 ~122 ~76 dirt
setblock ~174 ~122 ~77 dirt
setblock ~174 ~122 ~108 dirt
setblock ~174 ~122 ~109 dirt
setblock ~174 ~122 ~110 dirt
setblock ~174 ~122 ~111 dirt
setblock ~174 ~122 ~112 dirt
setblock ~174 ~122 ~113 dirt
setblock ~174 ~122 ~114 dirt
setblock ~174 ~122 ~115 dirt
setblock ~174 ~122 ~116 dirt
setblock ~174 ~122 ~117 dirt
setblock ~174 ~122 ~118 dirt
setblock ~174 ~122 ~122 dirt
setblock ~174 ~123 ~73 grass_block
setblock ~174 ~123 ~75 dirt
setblock ~174 ~123 ~76 dirt
setblock ~174 ~123 ~77 dirt
setblock ~174 ~123 ~108 dirt
setblock ~174 ~123 ~109 dirt
setblock ~174 ~123 ~110 grass_block
setblock ~174 ~123 ~111 grass_block
setblock ~174 ~123 ~112 dirt
setblock ~174 ~123 ~113 dirt
setblock ~174 ~123 ~114 dirt
setblock ~174 ~123 ~115 dirt
setblock ~174 ~123 ~116 dirt
setblock ~174 ~123 ~117 dirt
setblock ~174 ~123 ~118 dirt
setblock ~174 ~123 ~122 dirt
setblock ~174 ~124 ~75 grass_block
setblock ~174 ~124 ~76 grass_block
setblock ~174 ~124 ~77 grass_block
setblock ~174 ~124 ~108 grass_block
setblock ~174 ~124 ~109 grass_block
setblock ~174 ~124 ~110 poppy
setblock ~174 ~124 ~112 grass_block
setblock ~174 ~124 ~113 grass_block
setblock ~174 ~124 ~114 grass_block
setblock ~174 ~124 ~115 grass_block
setblock ~174 ~124 ~116 grass_block
setblock ~174 ~124 ~117 grass_block
setblock ~174 ~124 ~118 grass_block
setblock ~174 ~124 ~122 grass_block
setblock ~174 ~125 ~76 short_grass
setblock ~174 ~125 ~114 oak_log
setblock ~174 ~125 ~116 short_grass
setblock ~174 ~125 ~122 short_grass
setblock ~174 ~126 ~114 oak_log
setblock ~174 ~127 ~74 oak_leaves
setblock ~174 ~127 ~76 oak_leaves
setblock ~174 ~127 ~114 oak_log
setblock ~174 ~128 ~69 oak_leaves
setblock ~174 ~128 ~71 oak_leaves
setblock ~174 ~128 ~75 oak_wood
setblock ~174 ~128 ~76 jungle_leaves
setblock ~174 ~128 ~77 jungle_leaves
setblock ~174 ~128 ~114 oak_log
setblock ~174 ~129 ~62 oak_leaves
setblock ~174 ~129 ~63 oak_leaves
setblock ~174 ~129 ~64 oak_leaves
setblock ~174 ~129 ~65 oak_leaves
setblock ~174 ~129 ~66 oak_leaves
setblock ~174 ~129 ~67 jungle_leaves
setblock ~174 ~129 ~69 oak_leaves
setblock ~174 ~129 ~70 oak_leaves
setblock ~174 ~129 ~71 oak_leaves
setblock ~174 ~129 ~72 oak_leaves
setblock ~174 ~129 ~74 oak_wood
setblock ~174 ~129 ~75 oak_leaves
setblock ~174 ~129 ~76 oak_leaves
setblock ~174 ~129 ~77 oak_leaves
setblock ~174 ~129 ~114 oak_log
setblock ~174 ~129 ~115 spruce_slab
setblock ~174 ~129 ~116 oak_leaves
setblock ~174 ~129 ~117 oak_leaves
setblock ~174 ~129 ~118 oak_leaves
setblock ~174 ~129 ~119 oak_leaves
setblock ~174 ~130 ~64 jungle_leaves
setblock ~174 ~130 ~65 oak_leaves
setblock ~174 ~130 ~66 oak_leaves
setblock ~174 ~130 ~67 oak_leaves
setblock ~174 ~130 ~68 jungle_leaves
setblock ~174 ~130 ~69 oak_leaves
setblock ~174 ~130 ~70 oak_leaves
setblock ~174 ~130 ~73 oak_leaves
setblock ~174 ~130 ~74 jungle_leaves
setblock ~174 ~130 ~112 oak_leaves
setblock ~174 ~130 ~113 oak_leaves
setblock ~174 ~130 ~114 oak_leaves
setblock ~174 ~130 ~115 oak_log
setblock ~174 ~130 ~116 oak_leaves
setblock ~174 ~130 ~117 oak_wood
setblock ~174 ~130 ~119 oak_leaves
setblock ~174 ~131 ~62 oak_leaves
setblock ~174 ~131 ~63 oak_leaves
setblock ~174 ~131 ~64 oak_wood
setblock ~174 ~131 ~65 oak_wood
setblock ~174 ~131 ~66 oak_wood
setblock ~174 ~131 ~69 oak_wood
setblock ~174 ~131 ~70 oak_wood
setblock ~174 ~131 ~71 oak_leaves
setblock ~174 ~131 ~73 oak_leaves
setblock ~174 ~131 ~104 jungle_leaves
setblock ~174 ~131 ~105 oak_leaves
setblock ~174 ~131 ~106 jungle_leaves
setblock ~174 ~131 ~113 oak_leaves
setblock ~174 ~131 ~114 oak_leaves
setblock ~174 ~131 ~116 oak_log
setblock ~174 ~131 ~117 oak_wood
setblock ~174 ~131 ~118 oak_leaves
setblock ~174 ~131 ~119 oak_leaves
setblock ~174 ~132 ~62 oak_leaves
setblock ~174 ~132 ~63 oak_leaves
setblock ~174 ~132 ~66 oak_leaves
setblock ~174 ~132 ~67 oak_wood
setblock ~174 ~132 ~69 jungle_leaves
setblock ~174 ~132 ~70 oak_leaves
setblock ~174 ~132 ~71 jungle_leaves
setblock ~174 ~132 ~104 oak_leaves
setblock ~174 ~132 ~107 jungle_leaves
setblock ~174 ~132 ~109 oak_leaves
setblock ~174 ~132 ~110 oak_leaves
setblock ~174 ~132 ~111 oak_leaves
setblock ~174 ~132 ~112 oak_leaves
setblock ~174 ~132 ~114 jungle_leaves
setblock ~174 ~132 ~115 oak_wood
setblock ~174 ~132 ~116 oak_leaves
setblock ~174 ~132 ~118 oak_leaves
setblock ~174 ~133 ~65 oak_leaves
setblock ~174 ~133 ~66 oak_leaves
setblock ~174 ~133 ~67 oak_leaves
setblock ~174 ~133 ~68 oak_leaves
setblock ~174 ~133 ~70 jungle_leaves
setblock ~174 ~133 ~71 oak_wood
setblock ~174 ~133 ~72 oak_leaves
setblock ~174 ~133 ~104 oak_leaves
setblock ~174 ~133 ~105 oak_wood
setblock ~174 ~133 ~106 oak_wood
setblock ~174 ~133 ~107 oak_wood
setblock ~174 ~133 ~108 oak_leaves
setblock ~174 ~133 ~109 oak_leaves
setblock ~174 ~133 ~110 oak_leaves
setblock ~174 ~133 ~111 oak_leaves
setblock ~174 ~133 ~112 oak_leaves
setblock ~174 ~133 ~113 oak_wood
setblock ~174 ~133 ~114 oak_wood
setblock ~174 ~133 ~115 oak_wood
setblock ~174 ~133 ~116 oak_wood
setblock ~174 ~133 ~117 oak_leaves
setblock ~174 ~133 ~118 oak_leaves
setblock ~174 ~133 ~119 oak_leaves
setblock ~174 ~134 ~63 oak_leaves
setblock ~174 ~134 ~64 oak_leaves
setblock ~174 ~134 ~68 oak_leaves
setblock ~174 ~134 ~69 oak_leaves
setblock ~174 ~134 ~70 oak_leaves
setblock ~174 ~134 ~71 jungle_leaves
setblock ~174 ~134 ~72 oak_leaves
setblock ~174 ~134 ~73 oak_leaves
setblock ~174 ~134 ~105 oak_leaves
setblock ~174 ~134 ~106 jungle_leaves
setblock ~174 ~134 ~107 jungle_leaves
setblock ~174 ~134 ~108 oak_wood
setblock ~174 ~134 ~109 jungle_leaves
setblock ~174 ~134 ~110 oak_leaves
setblock ~174 ~134 ~113 oak_leaves
setblock ~174 ~134 ~114 oak_leaves
setblock ~174 ~134 ~116 oak_log
setblock ~174 ~134 ~117 oak_leaves
setblock ~174 ~135 ~63 oak_leaves
setblock ~174 ~135 ~66 oak_leaves
setblock ~174 ~135 ~67 oak_leaves
setblock ~174 ~135 ~69 oak_leaves
setblock ~174 ~135 ~70 oak_leaves
setblock ~174 ~135 ~71 oak_leaves
setblock ~174 ~135 ~72 oak_leaves
setblock ~174 ~135 ~108 oak_leaves
setblock ~174 ~135 ~113 oak_leaves
setblock ~174 ~135 ~114 oak_wood
setblock ~174 ~135 ~115 oak_log
setblock ~174 ~135 ~117 oak_wood
setblock ~174 ~135 ~118 oak_leaves
setblock ~174 ~135 ~119 oak_leaves
setblock ~174 ~136 ~63 oak_leaves
setblock ~174 ~136 ~64 oak_leaves
setblock ~174 ~136 ~65 oak_wood
setblock ~174 ~136 ~66 oak_wood
setblock ~174 ~136 ~69 oak_leaves
setblock ~174 ~136 ~70 oak_log
setblock ~174 ~136 ~71 oak_leaves
setblock ~174 ~136 ~72 jungle_leaves
setblock ~174 ~136 ~106 oak_leaves
setblock ~174 ~136 ~108 oak_leaves
setblock ~174 ~136 ~109 oak_leaves
setblock ~174 ~136 ~110 oak_leaves
setblock ~174 ~136 ~111 jungle_leaves
setblock ~174 ~136 ~112 oak_leaves
setblock ~174 ~136 ~113 oak_leaves
setblock ~174 ~136 ~114 oak_leaves
setblock ~174 ~136 ~115 oak_log
setblock ~174 ~136 ~117 oak_log
setblock ~174 ~136 ~119 oak_leaves
setblock ~174 ~137 ~64 oak_leaves
setblock ~174 ~137 ~65 jungle_leaves
setblock ~174 ~137 ~66 oak_leaves
setblock ~174 ~137 ~67 oak_leaves
setblock ~174 ~137 ~68 oak_leaves
setblock ~174 ~137 ~69 oak_leaves
setblock ~174 ~137 ~72 oak_leaves
setblock ~174 ~137 ~106 jungle_leaves
setblock ~174 ~137 ~107 oak_leaves
setblock ~174 ~137 ~108 oak_leaves
setblock ~174 ~137 ~109 oak_leaves
setblock ~174 ~137 ~111 oak_leaves
setblock ~174 ~137 ~112 oak_log
setblock ~174 ~137 ~113 oak_log
setblock ~174 ~137 ~114 oak_leaves
setblock ~174 ~137 ~115 oak_leaves
setblock ~174 ~137 ~116 oak_log
setblock ~174 ~137 ~117 oak_leaves
setblock ~174 ~137 ~118 oak_leaves
setblock ~174 ~137 ~119 oak_leaves
setblock ~174 ~138 ~64 jungle_leaves
setblock ~174 ~138 ~66 oak_leaves
setblock ~174 ~138 ~67 oak_leaves
setblock ~174 ~138 ~69 oak_leaves
setblock ~174 ~138 ~71 oak_leaves
setblock ~174 ~138 ~72 oak_leaves
setblock ~174 ~138 ~110 oak_leaves
setblock ~174 ~138 ~111 oak_leaves
setblock ~174 ~138 ~113 jungle_leaves
setblock ~174 ~138 ~115 jungle_leaves
setblock ~174 ~138 ~116 oak_leaves
setblock ~174 ~138 ~117 oak_leaves
setblock ~174 ~138 ~118 oak_leaves
setblock ~174 ~138 ~119 oak_leaves
setblock ~174 ~139 ~113 oak_leaves
setblock ~174 ~139 ~116 oak_leaves
setblock ~174 ~139 ~118 oak_leaves
setblock ~174 ~139 ~119 oak_leaves
setblock ~175 ~117 ~113 dirt
setblock ~175 ~118 ~112 dirt
setblock ~175 ~118 ~113 dirt
setblock ~175 ~119 ~112 dirt
setblock ~175 ~119 ~113 dirt
setblock ~175 ~119 ~116 dirt
setblock ~175 ~120 ~111 dirt
setblock ~175 ~120 ~112 dirt
setblock ~175 ~120 ~113 dirt
setblock ~175 ~120 ~114 dirt
setblock ~175 ~120 ~115 dirt
setblock ~175 ~120 ~116 dirt
setblock ~175 ~121 ~76 dirt
setblock ~175 ~121 ~111 dirt
setblock ~175 ~121 ~112 dirt
setblock ~175 ~121 ~113 dirt
setblock ~175 ~121 ~114 dirt
setblock ~175 ~121 ~115 dirt
setblock ~175 ~121 ~116 dirt
setblock ~175 ~122 ~76 dirt
setblock ~175 ~122 ~111 dirt
setblock ~175 ~122 ~112 dirt
setblock ~175 ~122 ~113 dirt
setblock ~175 ~122 ~114 dirt
setblock ~175 ~122 ~115 dirt
setblock ~175 ~122 ~116 dirt
setblock ~175 ~123 ~76 dirt
setblock ~175 ~123 ~111 dirt
setblock ~175 ~123 ~112 dirt
setblock ~175 ~123 ~113 dirt
setblock ~175 ~123 ~114 dirt
setblock ~175 ~123 ~115 dirt
setblock ~175 ~123 ~116 dirt
setblock ~175 ~124 ~76 grass_block
setblock ~175 ~124 ~111 grass_block
setblock ~175 ~124 ~112 grass_block
setblock ~175 ~124 ~113 grass_block
setblock ~175 ~124 ~114 grass_block
setblock ~175 ~124 ~115 grass_block
setblock ~175 ~124 ~116 grass_block
setblock ~175 ~125 ~112 fern
setblock ~175 ~127 ~74 oak_leaves
setblock ~175 ~127 ~75 oak_leaves
setblock ~175 ~127 ~77 oak_leaves
setblock ~175 ~128 ~69 oak_leaves
setblock ~175 ~128 ~71 jungle_leaves
setblock ~175 ~128 ~74 oak_leaves
setblock ~175 ~128 ~75 oak_leaves
setblock ~175 ~128 ~76 jungle_leaves
setblock ~175 ~128 ~77 oak_leaves
setblock ~175 ~129 ~63 oak_leaves
setblock ~175 ~129 ~64 oak_leaves
setblock ~175 ~129 ~65 oak_leaves
setblock ~175 ~129 ~66 oak_leaves
setblock ~175 ~129 ~67 oak_leaves
setblock ~175 ~129 ~69 oak_leaves
setblock ~175 ~129 ~70 oak_leaves
setblock ~175 ~129 ~75 jungle_leaves
setblock ~175 ~129 ~76 jungle_leaves
setblock ~175 ~129 ~77 oak_leaves
setblock ~175 ~129 ~117 oak_leaves
setblock ~175 ~129 ~118 oak_leaves
setblock ~175 ~130 ~62 oak_leaves
setblock ~175 ~130 ~64 jungle_leaves
setblock ~175 ~130 ~66 oak_leaves
setblock ~175 ~130 ~67 oak_leaves
setblock ~175 ~130 ~68 oak_leaves
setblock ~175 ~130 ~70 oak_leaves
setblock ~175 ~130 ~71 oak_leaves
setblock ~175 ~130 ~72 oak_leaves
setblock ~175 ~130 ~75 jungle_leaves
setblock ~175 ~130 ~114 oak_leaves
setblock ~175 ~130 ~115 jungle_leaves
setblock ~175 ~130 ~117 jungle_leaves
setblock ~175 ~130 ~118 oak_wood
setblock ~175 ~130 ~119 oak_leaves
setblock ~175 ~131 ~62 oak_leaves
setblock ~175 ~131 ~63 oak_leaves
setblock ~175 ~131 ~64 oak_wood
setblock ~175 ~131 ~65 oak_leaves
setblock ~175 ~131 ~66 oak_wood
setblock ~175 ~131 ~68 oak_leaves
setblock ~175 ~131 ~69 oak_leaves
setblock ~175 ~131 ~70 oak_wood
setblock ~175 ~131 ~71 oak_leaves
setblock ~175 ~131 ~72 oak_leaves
setblock ~175 ~131 ~73 oak_leaves
setblock ~175 ~131 ~104 jungle_leaves
setblock ~175 ~131 ~105 jungle_leaves
setblock ~175 ~131 ~106 jungle_leaves
setblock ~175 ~131 ~111 oak_leaves
setblock ~175 ~131 ~113 oak_leaves
setblock ~175 ~131 ~114 oak_leaves
setblock ~175 ~131 ~115 oak_leaves
setblock ~175 ~131 ~116 oak_leaves
setblock ~175 ~131 ~118 jungle_leaves
setblock ~175 ~131 ~119 oak_leaves
setblock ~175 ~132 ~63 jungle_leaves
setblock ~175 ~132 ~65 oak_leaves
setblock ~175 ~132 ~66 oak_wood
setblock ~175 ~132 ~67 oak_wood
setblock ~175 ~132 ~69 oak_leaves
setblock ~175 ~132 ~70 jungle_leaves
setblock ~175 ~132 ~71 oak_leaves
setblock ~175 ~132 ~72 oak_leaves
setblock ~175 ~132 ~73 oak_leaves
setblock ~175 ~132 ~105 oak_leaves
setblock ~175 ~132 ~106 jungle_leaves
setblock ~175 ~132 ~107 jungle_leaves
setblock ~175 ~132 ~110 jungle_leaves
setblock ~175 ~132 ~111 oak_leaves
setblock ~175 ~132 ~112 oak_leaves
setblock ~175 ~132 ~113 jungle_leaves
setblock ~175 ~132 ~114 oak_wood
setblock ~175 ~132 ~115 jungle_leaves
setblock ~175 ~132 ~116 oak_leaves
setblock ~175 ~132 ~117 jungle_leaves
setblock ~175 ~133 ~64 oak_leaves
setblock ~175 ~133 ~65 oak_leaves
setblock ~175 ~133 ~67 oak_leaves
setblock ~175 ~133 ~69 oak_leaves
setblock ~175 ~133 ~71 oak_leaves
setblock ~175 ~133 ~72 oak_wood
setblock ~175 ~133 ~73 oak_leaves
setblock ~175 ~133 ~104 oak_leaves
setblock ~175 ~133 ~105 oak_leaves
setblock ~175 ~133 ~106 oak_leaves
setblock ~175 ~133 ~110 jungle_leaves
setblock ~175 ~133 ~112 oak_wood
setblock ~175 ~133 ~113 oak_leaves
setblock ~175 ~133 ~114 oak_wood
setblock ~175 ~133 ~115 oak_leaves
setblock ~175 ~133 ~117 oak_leaves
setblock ~175 ~133 ~118 oak_leaves
setblock ~175 ~134 ~63 oak_leaves
setblock ~175 ~134 ~64 oak_leaves
setblock ~175 ~134 ~65 oak_leaves
setblock ~175 ~134 ~66 oak_leaves
setblock ~175 ~134 ~67 oak_leaves
setblock ~175 ~134 ~70 oak_leaves
setblock ~175 ~134 ~71 oak_leaves
setblock ~175 ~134 ~72 oak_leaves
setblock ~175 ~134 ~73 oak_leaves
setblock ~175 ~134 ~104 oak_leaves
setblock ~175 ~134 ~106 jungle_leaves
setblock ~175 ~134 ~110 oak_leaves
setblock ~175 ~134 ~112 oak_leaves
setblock ~175 ~134 ~113 oak_leaves
setblock ~175 ~134 ~114 oak_wood
setblock ~175 ~134 ~115 oak_leaves
setblock ~175 ~134 ~116 oak_wood
setblock ~175 ~134 ~117 oak_leaves
setblock ~175 ~134 ~119 oak_leaves
setblock ~175 ~135 ~64 oak_leaves
setblock ~175 ~135 ~66 oak_leaves
setblock ~175 ~135 ~72 oak_leaves
setblock ~175 ~135 ~111 oak_leaves
setblock ~175 ~135 ~112 jungle_leaves
setblock ~175 ~135 ~115 oak_wood
setblock ~175 ~135 ~116 oak_wood
setblock ~175 ~135 ~117 oak_wood
setblock ~175 ~135 ~119 oak_leaves
setblock ~175 ~136 ~64 oak_leaves
setblock ~175 ~136 ~65 oak_wood
setblock ~175 ~136 ~66 jungle_leaves
setblock ~175 ~136 ~67 jungle_leaves
setblock ~175 ~136 ~68 oak_leaves
setblock ~175 ~136 ~69 oak_leaves
setblock ~175 ~136 ~71 oak_leaves
setblock ~175 ~136 ~110 oak_leaves
setblock ~175 ~136 ~111 oak_leaves
setblock ~175 ~136 ~113 oak_leaves
setblock ~175 ~136 ~115 oak_leaves
setblock ~175 ~136 ~116 oak_log
setblock ~175 ~136 ~117 oak_log
setblock ~175 ~136 ~118 oak_leaves
setblock ~175 ~136 ~119 oak_leaves
setblock ~175 ~137 ~64 oak_leaves
setblock ~175 ~137 ~65 oak_wood
setblock ~175 ~137 ~66 oak_leaves
setblock ~175 ~137 ~68 oak_leaves
setblock ~175 ~137 ~69 jungle_leaves
setblock ~175 ~137 ~72 oak_leaves
setblock ~175 ~137 ~110 oak_leaves
setblock ~175 ~137 ~111 oak_leaves
setblock ~175 ~137 ~112 oak_leaves
setblock ~175 ~137 ~113 oak_leaves
setblock ~175 ~137 ~114 oak_leaves
setblock ~175 ~137 ~115 oak_leaves
setblock ~175 ~137 ~116 oak_log
setblock ~175 ~137 ~117 oak_log
setblock ~175 ~137 ~118 oak_leaves
setblock ~175 ~137 ~119 oak_leaves
setblock ~175 ~138 ~63 oak_leaves
setblock ~175 ~138 ~64 oak_leaves
setblock ~175 ~138 ~65 jungle_leaves
setblock ~175 ~138 ~66 oak_leaves
setblock ~175 ~138 ~68 oak_leaves
setblock ~175 ~138 ~71 oak_leaves
setblock ~175 ~138 ~72 oak_leaves
setblock ~175 ~138 ~110 oak_leaves
setblock ~175 ~138 ~111 jungle_leaves
setblock ~175 ~138 ~113 jungle_leaves
setblock ~175 ~138 ~115 jungle_leaves
setblock ~175 ~138 ~116 oak_leaves
setblock ~175 ~138 ~117 oak_leaves
setblock ~175 ~138 ~118 oak_leaves
setblock ~175 ~138 ~119 oak_leaves
setblock ~175 ~139 ~115 oak_leaves
setblock ~175 ~139 ~116 jungle_leaves
setblock ~175 ~139 ~119 oak_leaves
setblock ~176 ~120 ~112 dirt
setblock ~176 ~121 ~112 dirt
setblock ~176 ~121 ~113 dirt
setblock ~176 ~121 ~115 dirt
setblock ~176 ~122 ~112 dirt
setblock ~176 ~122 ~113 dirt
setblock ~176 ~122 ~115 dirt
setblock ~176 ~123 ~112 dirt
setblock ~176 ~123 ~113 dirt
setblock ~176 ~123 ~115 dirt
setblock ~176 ~124 ~112 dirt
setblock ~176 ~124 ~113 dirt
setblock ~176 ~124 ~115 dirt
setblock ~176 ~125 ~112 grass_block
setblock ~176 ~125 ~113 grass_block
setblock ~176 ~125 ~115 grass_block
setblock ~176 ~126 ~113 short_grass
setblock ~176 ~127 ~77 oak_leaves
setblock ~176 ~128 ~69 oak_leaves
setblock ~176 ~128 ~70 jungle_leaves
setblock ~176 ~128 ~71 jungle_leaves
setblock ~176 ~128 ~72 oak_leaves
setblock ~176 ~128 ~77 oak_leaves
setblock ~176 ~129 ~62 oak_leaves
setblock ~176 ~129 ~66 jungle_leaves
setblock ~176 ~129 ~67 oak_leaves
setblock ~176 ~129 ~69 oak_leaves
