setblock ~147 ~126 ~79 grass_block
setblock ~147 ~126 ~80 grass_block
setblock ~147 ~126 ~81 grass_block
setblock ~147 ~126 ~83 fern
setblock ~147 ~126 ~84 short_grass
setblock ~147 ~126 ~95 grass_block
setblock ~147 ~126 ~96 grass_block
setblock ~147 ~126 ~97 dirt
setblock ~147 ~126 ~98 dirt
setblock ~147 ~126 ~99 dirt
setblock ~147 ~126 ~100 dirt
setblock ~147 ~126 ~101 dirt
setblock ~147 ~126 ~102 dirt
setblock ~147 ~126 ~103 dirt
setblock ~147 ~126 ~104 dirt
setblock ~147 ~126 ~105 dirt
setblock ~147 ~126 ~106 dirt
setblock ~147 ~126 ~107 grass_block
setblock ~147 ~126 ~108 grass_block
setblock ~147 ~126 ~110 short_grass
setblock ~147 ~126 ~111 short_grass
setblock ~147 ~126 ~112 short_grass
setblock ~147 ~126 ~125 short_grass
setblock ~147 ~126 ~130 grass_block
setblock ~147 ~126 ~149 grass_block
setblock ~147 ~126 ~150 grass_block
setblock ~147 ~126 ~151 grass_block
setblock ~147 ~126 ~152 grass_block
setblock ~147 ~126 ~153 grass_block
setblock ~147 ~126 ~158 fern
setblock ~147 ~126 ~160 short_grass
setblock ~147 ~126 ~179 short_grass
setblock ~147 ~126 ~180 short_grass
setblock ~147 ~126 ~183 short_grass
setblock ~147 ~127 ~42 short_grass
setblock ~147 ~127 ~43 short_grass
setblock ~147 ~127 ~44 short_grass
setblock ~147 ~127 ~45 grass_block
setblock ~147 ~127 ~46 grass_block
setblock ~147 ~127 ~47 grass_block
setblock ~147 ~127 ~48 dirt
setblock ~147 ~127 ~49 dirt
setblock ~147 ~127 ~50 dirt
setblock ~147 ~127 ~51 dirt
setblock ~147 ~127 ~52 dirt
setblock ~147 ~127 ~53 grass_block
setblock ~147 ~127 ~54 grass_block
setblock ~147 ~127 ~56 fern
setblock ~147 ~127 ~79 short_grass
setblock ~147 ~127 ~96 short_grass
setblock ~147 ~127 ~97 grass_block
setblock ~147 ~127 ~98 dirt
setblock ~147 ~127 ~99 dirt
setblock ~147 ~127 ~100 dirt
setblock ~147 ~127 ~101 dirt
setblock ~147 ~127 ~102 dirt
setblock ~147 ~127 ~103 dirt
setblock ~147 ~127 ~104 dirt
setblock ~147 ~127 ~105 grass_block
setblock ~147 ~127 ~106 grass_block
setblock ~147 ~127 ~108 short_grass
setblock ~147 ~127 ~149 short_grass
setblock ~147 ~127 ~152 fern
setblock ~147 ~127 ~153 fern
setblock ~147 ~128 ~45 short_grass
setblock ~147 ~128 ~48 grass_block
setblock ~147 ~128 ~49 grass_block
setblock ~147 ~128 ~50 dirt
setblock ~147 ~128 ~51 grass_block
setblock ~147 ~128 ~52 grass_block
setblock ~147 ~128 ~97 short_grass
setblock ~147 ~128 ~98 grass_block
setblock ~147 ~128 ~99 dirt
setblock ~147 ~128 ~100 dirt
setblock ~147 ~128 ~101 dirt
setblock ~147 ~128 ~102 dirt
setblock ~147 ~128 ~103 grass_block
setblock ~147 ~128 ~104 grass_block
setblock ~147 ~129 ~48 poppy
setblock ~147 ~129 ~49 poppy
setblock ~147 ~129 ~50 grass_block
setblock ~147 ~129 ~51 short_grass
setblock ~147 ~129 ~99 grass_block
setblock ~147 ~129 ~100 grass_block
setblock ~147 ~129 ~101 grass_block
setblock ~147 ~129 ~102 grass_block
setblock ~147 ~130 ~99 short_grass
setblock ~147 ~130 ~100 short_grass
setblock ~147 ~130 ~101 short_grass
setblock ~148 ~122 ~0 dirt
setblock ~148 ~122 ~1 dirt
setblock ~148 ~122 ~2 dirt
setblock ~148 ~122 ~3 dirt
setblock ~148 ~122 ~4 dirt
setblock ~148 ~122 ~5 dirt
setblock ~148 ~122 ~6 dirt
setblock ~148 ~122 ~7 dirt
setblock ~148 ~122 ~8 dirt
setblock ~148 ~122 ~9 dirt
setblock ~148 ~122 ~10 dirt
setblock ~148 ~122 ~11 dirt
setblock ~148 ~122 ~12 dirt
setblock ~148 ~122 ~13 dirt
setblock ~148 ~122 ~14 dirt
setblock ~148 ~122 ~15 dirt
setblock ~148 ~122 ~16 dirt
setblock ~148 ~122 ~17 dirt
setblock ~148 ~122 ~18 dirt
setblock ~148 ~122 ~19 dirt
setblock ~148 ~122 ~20 dirt
setblock ~148 ~122 ~21 dirt
setblock ~148 ~122 ~22 dirt
setblock ~148 ~122 ~23 dirt
setblock ~148 ~122 ~24 dirt
setblock ~148 ~122 ~25 dirt
setblock ~148 ~122 ~26 dirt
setblock ~148 ~122 ~27 dirt
setblock ~148 ~122 ~28 dirt
setblock ~148 ~122 ~29 dirt
setblock ~148 ~122 ~30 dirt
setblock ~148 ~122 ~31 dirt
setblock ~148 ~122 ~32 dirt
setblock ~148 ~122 ~33 dirt
setblock ~148 ~122 ~34 dirt
setblock ~148 ~122 ~35 dirt
setblock ~148 ~122 ~36 dirt
setblock ~148 ~122 ~37 dirt
setblock ~148 ~122 ~38 dirt
setblock ~148 ~122 ~39 dirt
setblock ~148 ~122 ~40 dirt
setblock ~148 ~122 ~41 dirt
setblock ~148 ~122 ~42 dirt
setblock ~148 ~122 ~43 dirt
setblock ~148 ~122 ~44 dirt
setblock ~148 ~122 ~45 dirt
setblock ~148 ~122 ~46 dirt
setblock ~148 ~122 ~47 dirt
setblock ~148 ~122 ~48 dirt
setblock ~148 ~122 ~49 dirt
setblock ~148 ~122 ~50 dirt
setblock ~148 ~122 ~51 dirt
setblock ~148 ~122 ~52 dirt
setblock ~148 ~122 ~53 dirt
setblock ~148 ~122 ~54 dirt
setblock ~148 ~122 ~55 dirt
setblock ~148 ~122 ~56 dirt
setblock ~148 ~122 ~57 dirt
setblock ~148 ~122 ~58 dirt
setblock ~148 ~122 ~59 dirt
setblock ~148 ~122 ~60 dirt
setblock ~148 ~122 ~61 dirt
setblock ~148 ~122 ~62 dirt
setblock ~148 ~122 ~63 dirt
setblock ~148 ~122 ~64 dirt
setblock ~148 ~122 ~65 dirt
setblock ~148 ~122 ~66 dirt
setblock ~148 ~122 ~67 dirt
setblock ~148 ~122 ~68 dirt
setblock ~148 ~122 ~69 dirt
setblock ~148 ~122 ~70 dirt
setblock ~148 ~122 ~71 dirt
setblock ~148 ~122 ~72 dirt
setblock ~148 ~122 ~73 dirt
setblock ~148 ~122 ~74 dirt
setblock ~148 ~122 ~75 dirt
setblock ~148 ~122 ~76 dirt
setblock ~148 ~122 ~77 dirt
setblock ~148 ~122 ~78 dirt
setblock ~148 ~122 ~79 dirt
setblock ~148 ~122 ~80 dirt
setblock ~148 ~122 ~81 dirt
setblock ~148 ~122 ~82 dirt
setblock ~148 ~122 ~83 dirt
setblock ~148 ~122 ~84 dirt
setblock ~148 ~122 ~85 dirt
setblock ~148 ~122 ~86 dirt
setblock ~148 ~122 ~87 dirt
setblock ~148 ~122 ~88 dirt
setblock ~148 ~122 ~89 dirt
setblock ~148 ~122 ~90 dirt
setblock ~148 ~122 ~91 dirt
setblock ~148 ~122 ~92 dirt
setblock ~148 ~122 ~93 dirt
setblock ~148 ~122 ~94 dirt
setblock ~148 ~122 ~95 dirt
setblock ~148 ~122 ~96 dirt
setblock ~148 ~122 ~97 dirt
setblock ~148 ~122 ~98 dirt
setblock ~148 ~122 ~99 dirt
setblock ~148 ~122 ~100 dirt
setblock ~148 ~122 ~101 dirt
setblock ~148 ~122 ~102 dirt
setblock ~148 ~122 ~103 dirt
setblock ~148 ~122 ~104 dirt
setblock ~148 ~122 ~105 dirt
setblock ~148 ~122 ~106 dirt
setblock ~148 ~122 ~107 dirt
setblock ~148 ~122 ~108 dirt
setblock ~148 ~122 ~109 dirt
setblock ~148 ~122 ~110 dirt
setblock ~148 ~122 ~111 dirt
setblock ~148 ~122 ~112 dirt
setblock ~148 ~122 ~113 dirt
setblock ~148 ~122 ~114 dirt
setblock ~148 ~122 ~115 dirt
setblock ~148 ~122 ~116 dirt
setblock ~148 ~122 ~117 dirt
setblock ~148 ~122 ~118 dirt
setblock ~148 ~122 ~119 dirt
setblock ~148 ~122 ~120 dirt
setblock ~148 ~122 ~121 dirt
setblock ~148 ~122 ~122 dirt
setblock ~148 ~122 ~123 dirt
setblock ~148 ~122 ~124 dirt
setblock ~148 ~122 ~125 dirt
setblock ~148 ~122 ~126 dirt
setblock ~148 ~122 ~127 dirt
setblock ~148 ~122 ~128 dirt
setblock ~148 ~122 ~129 dirt
setblock ~148 ~122 ~130 dirt
setblock ~148 ~122 ~131 dirt
setblock ~148 ~122 ~132 dirt
setblock ~148 ~122 ~133 dirt
setblock ~148 ~122 ~134 dirt
setblock ~148 ~122 ~135 dirt
setblock ~148 ~122 ~136 dirt
setblock ~148 ~122 ~137 dirt
setblock ~148 ~122 ~138 grass_block
setblock ~148 ~122 ~139 grass_block
setblock ~148 ~122 ~140 grass_block
setblock ~148 ~122 ~141 grass_block
setblock ~148 ~122 ~142 dirt
setblock ~148 ~122 ~143 dirt
setblock ~148 ~122 ~144 dirt
setblock ~148 ~122 ~145 dirt
setblock ~148 ~122 ~146 dirt
setblock ~148 ~122 ~147 dirt
setblock ~148 ~122 ~148 dirt
setblock ~148 ~122 ~149 dirt
setblock ~148 ~122 ~150 dirt
setblock ~148 ~122 ~151 dirt
setblock ~148 ~122 ~152 dirt
setblock ~148 ~122 ~153 dirt
setblock ~148 ~122 ~154 dirt
setblock ~148 ~122 ~155 dirt
setblock ~148 ~122 ~156 dirt
setblock ~148 ~122 ~157 dirt
setblock ~148 ~122 ~158 dirt
setblock ~148 ~122 ~159 dirt
setblock ~148 ~122 ~160 dirt
setblock ~148 ~122 ~161 dirt
setblock ~148 ~122 ~162 dirt
setblock ~148 ~122 ~163 dirt
setblock ~148 ~122 ~164 dirt
setblock ~148 ~122 ~165 dirt
setblock ~148 ~122 ~166 dirt
setblock ~148 ~122 ~167 dirt
setblock ~148 ~122 ~168 dirt
setblock ~148 ~122 ~169 grass_block
setblock ~148 ~122 ~170 grass_block
setblock ~148 ~122 ~171 grass_block
setblock ~148 ~122 ~172 dirt
setblock ~148 ~122 ~173 dirt
setblock ~148 ~122 ~174 dirt
setblock ~148 ~122 ~175 dirt
setblock ~148 ~122 ~176 dirt
setblock ~148 ~122 ~177 dirt
setblock ~148 ~122 ~178 dirt
setblock ~148 ~122 ~179 dirt
setblock ~148 ~122 ~180 dirt
setblock ~148 ~122 ~181 dirt
setblock ~148 ~122 ~182 dirt
setblock ~148 ~122 ~183 dirt
setblock ~148 ~122 ~184 dirt
setblock ~148 ~122 ~185 dirt
setblock ~148 ~122 ~186 dirt
setblock ~148 ~122 ~187 dirt
setblock ~148 ~122 ~188 dirt
setblock ~148 ~122 ~189 dirt
setblock ~148 ~122 ~190 dirt
setblock ~148 ~122 ~191 dirt
setblock ~148 ~122 ~192 dirt
setblock ~148 ~122 ~193 dirt
setblock ~148 ~122 ~194 dirt
setblock ~148 ~122 ~195 dirt
setblock ~148 ~122 ~196 dirt
setblock ~148 ~122 ~197 dirt
setblock ~148 ~122 ~198 dirt
setblock ~148 ~122 ~199 dirt
setblock ~148 ~123 ~0 grass_block
setblock ~148 ~123 ~1 grass_block
setblock ~148 ~123 ~2 grass_block
setblock ~148 ~123 ~3 grass_block
setblock ~148 ~123 ~4 grass_block
setblock ~148 ~123 ~5 grass_block
setblock ~148 ~123 ~6 grass_block
setblock ~148 ~123 ~7 grass_block
setblock ~148 ~123 ~8 grass_block
setblock ~148 ~123 ~9 grass_block
setblock ~148 ~123 ~10 grass_block
setblock ~148 ~123 ~11 grass_block
setblock ~148 ~123 ~12 grass_block
setblock ~148 ~123 ~13 grass_block
setblock ~148 ~123 ~14 grass_block
setblock ~148 ~123 ~15 dirt
setblock ~148 ~123 ~16 dirt
setblock ~148 ~123 ~17 dirt
setblock ~148 ~123 ~18 dirt
setblock ~148 ~123 ~19 dirt
setblock ~148 ~123 ~20 dirt
setblock ~148 ~123 ~21 dirt
setblock ~148 ~123 ~22 dirt
setblock ~148 ~123 ~23 dirt
setblock ~148 ~123 ~24 dirt
setblock ~148 ~123 ~25 dirt
setblock ~148 ~123 ~26 dirt
setblock ~148 ~123 ~27 dirt
setblock ~148 ~123 ~28 grass_block
setblock ~148 ~123 ~29 grass_block
setblock ~148 ~123 ~30 grass_block
setblock ~148 ~123 ~31 grass_block
setblock ~148 ~123 ~32 dirt
setblock ~148 ~123 ~33 dirt
setblock ~148 ~123 ~34 dirt
setblock ~148 ~123 ~35 dirt
setblock ~148 ~123 ~36 dirt
setblock ~148 ~123 ~37 dirt
setblock ~148 ~123 ~38 dirt
setblock ~148 ~123 ~39 dirt
setblock ~148 ~123 ~40 dirt
setblock ~148 ~123 ~41 dirt
setblock ~148 ~123 ~42 dirt
setblock ~148 ~123 ~43 dirt
setblock ~148 ~123 ~44 dirt
setblock ~148 ~123 ~45 dirt
setblock ~148 ~123 ~46 dirt
setblock ~148 ~123 ~47 dirt
setblock ~148 ~123 ~48 dirt
setblock ~148 ~123 ~49 dirt
setblock ~148 ~123 ~50 dirt
setblock ~148 ~123 ~51 dirt
setblock ~148 ~123 ~52 dirt
setblock ~148 ~123 ~53 dirt
setblock ~148 ~123 ~54 dirt
setblock ~148 ~123 ~55 dirt
setblock ~148 ~123 ~56 dirt
setblock ~148 ~123 ~57 dirt
setblock ~148 ~123 ~58 dirt
setblock ~148 ~123 ~59 dirt
setblock ~148 ~123 ~60 dirt
setblock ~148 ~123 ~61 dirt
setblock ~148 ~123 ~62 dirt
setblock ~148 ~123 ~63 dirt
setblock ~148 ~123 ~64 dirt
setblock ~148 ~123 ~65 dirt
setblock ~148 ~123 ~66 dirt
setblock ~148 ~123 ~67 dirt
setblock ~148 ~123 ~68 dirt
setblock ~148 ~123 ~69 dirt
setblock ~148 ~123 ~70 grass_block
setblock ~148 ~123 ~71 dirt
setblock ~148 ~123 ~72 dirt
setblock ~148 ~123 ~73 dirt
setblock ~148 ~123 ~74 dirt
setblock ~148 ~123 ~75 dirt
setblock ~148 ~123 ~76 dirt
setblock ~148 ~123 ~77 dirt
setblock ~148 ~123 ~78 dirt
setblock ~148 ~123 ~79 dirt
setblock ~148 ~123 ~80 dirt
setblock ~148 ~123 ~81 dirt
setblock ~148 ~123 ~82 dirt
setblock ~148 ~123 ~83 dirt
setblock ~148 ~123 ~84 dirt
setblock ~148 ~123 ~85 dirt
setblock ~148 ~123 ~86 dirt
setblock ~148 ~123 ~87 dirt
setblock ~148 ~123 ~88 dirt
setblock ~148 ~123 ~89 dirt
setblock ~148 ~123 ~90 grass_block
setblock ~148 ~123 ~91 dirt
setblock ~148 ~123 ~92 dirt
setblock ~148 ~123 ~93 dirt
setblock ~148 ~123 ~94 dirt
setblock ~148 ~123 ~95 dirt
setblock ~148 ~123 ~96 dirt
setblock ~148 ~123 ~97 dirt
setblock ~148 ~123 ~98 dirt
setblock ~148 ~123 ~99 dirt
setblock ~148 ~123 ~100 dirt
setblock ~148 ~123 ~101 dirt
setblock ~148 ~123 ~102 dirt
setblock ~148 ~123 ~103 dirt
setblock ~148 ~123 ~104 dirt
setblock ~148 ~123 ~105 dirt
setblock ~148 ~123 ~106 dirt
setblock ~148 ~123 ~107 dirt
setblock ~148 ~123 ~108 dirt
setblock ~148 ~123 ~109 dirt
setblock ~148 ~123 ~110 dirt
setblock ~148 ~123 ~111 dirt
setblock ~148 ~123 ~112 dirt
setblock ~148 ~123 ~113 dirt
setblock ~148 ~123 ~114 dirt
setblock ~148 ~123 ~115 dirt
setblock ~148 ~123 ~116 dirt
setblock ~148 ~123 ~117 dirt
setblock ~148 ~123 ~118 grass_block
setblock ~148 ~123 ~119 grass_block
setblock ~148 ~123 ~120 grass_block
setblock ~148 ~123 ~121 grass_block
setblock ~148 ~123 ~122 grass_block
setblock ~148 ~123 ~123 dirt
setblock ~148 ~123 ~124 dirt
setblock ~148 ~123 ~125 dirt
setblock ~148 ~123 ~126 dirt
setblock ~148 ~123 ~127 dirt
setblock ~148 ~123 ~128 dirt
setblock ~148 ~123 ~129 dirt
setblock ~148 ~123 ~130 dirt
setblock ~148 ~123 ~131 dirt
setblock ~148 ~123 ~132 dirt
setblock ~148 ~123 ~133 dirt
setblock ~148 ~123 ~134 dirt
setblock ~148 ~123 ~135 grass_block
setblock ~148 ~123 ~136 grass_block
setblock ~148 ~123 ~137 grass_block
setblock ~148 ~123 ~140 short_grass
setblock ~148 ~123 ~142 grass_block
setblock ~148 ~123 ~143 grass_block
setblock ~148 ~123 ~144 dirt
setblock ~148 ~123 ~145 dirt
setblock ~148 ~123 ~146 dirt
setblock ~148 ~123 ~147 dirt
setblock ~148 ~123 ~148 dirt
setblock ~148 ~123 ~149 dirt
setblock ~148 ~123 ~150 dirt
setblock ~148 ~123 ~151 dirt
setblock ~148 ~123 ~152 dirt
setblock ~148 ~123 ~153 dirt
setblock ~148 ~123 ~154 dirt
setblock ~148 ~123 ~155 dirt
setblock ~148 ~123 ~156 dirt
setblock ~148 ~123 ~157 dirt
setblock ~148 ~123 ~158 dirt
setblock ~148 ~123 ~159 dirt
setblock ~148 ~123 ~160 dirt
setblock ~148 ~123 ~161 dirt
setblock ~148 ~123 ~162 dirt
setblock ~148 ~123 ~163 dirt
setblock ~148 ~123 ~164 dirt
setblock ~148 ~123 ~165 grass_block
setblock ~148 ~123 ~166 grass_block
setblock ~148 ~123 ~167 grass_block
setblock ~148 ~123 ~168 grass_block
setblock ~148 ~123 ~172 grass_block
setblock ~148 ~123 ~173 grass_block
setblock ~148 ~123 ~174 grass_block
setblock ~148 ~123 ~175 dirt
setblock ~148 ~123 ~176 dirt
setblock ~148 ~123 ~177 dirt
setblock ~148 ~123 ~178 dirt
setblock ~148 ~123 ~179 dirt
setblock ~148 ~123 ~180 dirt
setblock ~148 ~123 ~181 dirt
setblock ~148 ~123 ~182 dirt
setblock ~148 ~123 ~183 dirt
setblock ~148 ~123 ~184 dirt
setblock ~148 ~123 ~185 dirt
setblock ~148 ~123 ~186 dirt
setblock ~148 ~123 ~187 dirt
setblock ~148 ~123 ~188 dirt
setblock ~148 ~123 ~189 dirt
setblock ~148 ~123 ~190 dirt
setblock ~148 ~123 ~191 dirt
setblock ~148 ~123 ~192 dirt
setblock ~148 ~123 ~193 dirt
setblock ~148 ~123 ~194 dirt
setblock ~148 ~123 ~195 dirt
setblock ~148 ~123 ~196 dirt
setblock ~148 ~123 ~197 dirt
setblock ~148 ~123 ~198 dirt
setblock ~148 ~123 ~199 dirt
setblock ~148 ~124 ~4 short_grass
setblock ~148 ~124 ~9 short_grass
setblock ~148 ~124 ~11 fern
setblock ~148 ~124 ~13 short_grass
setblock ~148 ~124 ~14 short_grass
setblock ~148 ~124 ~15 grass_block
setblock ~148 ~124 ~16 grass_block
setblock ~148 ~124 ~17 grass_block
setblock ~148 ~124 ~18 grass_block
setblock ~148 ~124 ~19 grass_block
setblock ~148 ~124 ~20 grass_block
setblock ~148 ~124 ~21 grass_block
setblock ~148 ~124 ~22 grass_block
setblock ~148 ~124 ~23 grass_block
setblock ~148 ~124 ~24 grass_block
setblock ~148 ~124 ~25 grass_block
setblock ~148 ~124 ~26 grass_block
setblock ~148 ~124 ~27 grass_block
setblock ~148 ~124 ~30 short_grass
setblock ~148 ~124 ~32 grass_block
setblock ~148 ~124 ~33 grass_block
setblock ~148 ~124 ~34 grass_block
setblock ~148 ~124 ~35 grass_block
setblock ~148 ~124 ~36 dirt
setblock ~148 ~124 ~37 dirt
setblock ~148 ~124 ~38 dirt
setblock ~148 ~124 ~39 dirt
setblock ~148 ~124 ~40 dirt
setblock ~148 ~124 ~41 dirt
setblock ~148 ~124 ~42 dirt
setblock ~148 ~124 ~43 dirt
setblock ~148 ~124 ~44 dirt
setblock ~148 ~124 ~45 dirt
setblock ~148 ~124 ~46 dirt
setblock ~148 ~124 ~47 dirt
setblock ~148 ~124 ~48 dirt
setblock ~148 ~124 ~49 dirt
setblock ~148 ~124 ~50 dirt
setblock ~148 ~124 ~51 dirt
setblock ~148 ~124 ~52 dirt
setblock ~148 ~124 ~53 dirt
setblock ~148 ~124 ~54 dirt
setblock ~148 ~124 ~55 dirt
setblock ~148 ~124 ~56 dirt
setblock ~148 ~124 ~57 dirt
setblock ~148 ~124 ~58 dirt
setblock ~148 ~124 ~59 dirt
setblock ~148 ~124 ~60 dirt
setblock ~148 ~124 ~61 dirt
setblock ~148 ~124 ~62 dirt
setblock ~148 ~124 ~63 dirt
setblock ~148 ~124 ~64 dirt
setblock ~148 ~124 ~65 grass_block
setblock ~148 ~124 ~66 grass_block
setblock ~148 ~124 ~67 grass_block
setblock ~148 ~124 ~68 grass_block
setblock ~148 ~124 ~69 grass_block
setblock ~148 ~124 ~71 grass_block
setblock ~148 ~124 ~72 grass_block
setblock ~148 ~124 ~73 grass_block
setblock ~148 ~124 ~74 dirt
setblock ~148 ~124 ~75 dirt
setblock ~148 ~124 ~76 dirt
setblock ~148 ~124 ~77 dirt
setblock ~148 ~124 ~78 dirt
setblock ~148 ~124 ~79 dirt
setblock ~148 ~124 ~80 dirt
setblock ~148 ~124 ~81 dirt
setblock ~148 ~124 ~82 dirt
setblock ~148 ~124 ~83 dirt
setblock ~148 ~124 ~84 dirt
setblock ~148 ~124 ~85 dirt
setblock ~148 ~124 ~86 grass_block
setblock ~148 ~124 ~87 grass_block
setblock ~148 ~124 ~88 grass_block
setblock ~148 ~124 ~89 grass_block
setblock ~148 ~124 ~91 grass_block
setblock ~148 ~124 ~92 grass_block
setblock ~148 ~124 ~93 dirt
setblock ~148 ~124 ~94 dirt
setblock ~148 ~124 ~95 dirt
setblock ~148 ~124 ~96 dirt
setblock ~148 ~124 ~97 dirt
setblock ~148 ~124 ~98 dirt
setblock ~148 ~124 ~99 dirt
setblock ~148 ~124 ~100 dirt
setblock ~148 ~124 ~101 dirt
setblock ~148 ~124 ~102 dirt
setblock ~148 ~124 ~103 dirt
setblock ~148 ~124 ~104 dirt
setblock ~148 ~124 ~105 dirt
setblock ~148 ~124 ~106 dirt
setblock ~148 ~124 ~107 dirt
setblock ~148 ~124 ~108 dirt
setblock ~148 ~124 ~109 grass_block
setblock ~148 ~124 ~110 grass_block
setblock ~148 ~124 ~111 grass_block
setblock ~148 ~124 ~112 grass_block
setblock ~148 ~124 ~113 grass_block
setblock ~148 ~124 ~114 grass_block
setblock ~148 ~124 ~115 grass_block
setblock ~148 ~124 ~116 grass_block
setblock ~148 ~124 ~117 grass_block
setblock ~148 ~124 ~120 short_grass
setblock ~148 ~124 ~123 grass_block
setblock ~148 ~124 ~124 grass_block
setblock ~148 ~124 ~125 grass_block
setblock ~148 ~124 ~126 grass_block
setblock ~148 ~124 ~127 dirt
setblock ~148 ~124 ~128 dirt
setblock ~148 ~124 ~129 dirt
setblock ~148 ~124 ~130 dirt
setblock ~148 ~124 ~131 dirt
setblock ~148 ~124 ~132 dirt
setblock ~148 ~124 ~133 grass_block
setblock ~148 ~124 ~134 grass_block
setblock ~148 ~124 ~137 short_grass
setblock ~148 ~124 ~142 short_grass
setblock ~148 ~124 ~144 grass_block
setblock ~148 ~124 ~145 grass_block
setblock ~148 ~124 ~146 dirt
setblock ~148 ~124 ~147 dirt
setblock ~148 ~124 ~148 dirt
setblock ~148 ~124 ~149 dirt
setblock ~148 ~124 ~150 dirt
setblock ~148 ~124 ~151 dirt
setblock ~148 ~124 ~152 dirt
setblock ~148 ~124 ~153 dirt
setblock ~148 ~124 ~154 dirt
setblock ~148 ~124 ~155 dirt
setblock ~148 ~124 ~156 dirt
setblock ~148 ~124 ~157 dirt
setblock ~148 ~124 ~158 dirt
setblock ~148 ~124 ~159 dirt
setblock ~148 ~124 ~160 grass_block
setblock ~148 ~124 ~161 grass_block
setblock ~148 ~124 ~162 grass_block
setblock ~148 ~124 ~163 grass_block
setblock ~148 ~124 ~164 grass_block
setblock ~148 ~124 ~172 fern
setblock ~148 ~124 ~175 grass_block
setblock ~148 ~124 ~176 grass_block
setblock ~148 ~124 ~177 grass_block
setblock ~148 ~124 ~178 dirt
setblock ~148 ~124 ~179 dirt
setblock ~148 ~124 ~180 dirt
setblock ~148 ~124 ~181 dirt
setblock ~148 ~124 ~182 dirt
setblock ~148 ~124 ~183 dirt
setblock ~148 ~124 ~184 dirt
setblock ~148 ~124 ~185 dirt
setblock ~148 ~124 ~186 dirt
setblock ~148 ~124 ~187 dirt
setblock ~148 ~124 ~188 grass_block
setblock ~148 ~124 ~189 grass_block
setblock ~148 ~124 ~190 grass_block
setblock ~148 ~124 ~191 grass_block
setblock ~148 ~124 ~192 grass_block
setblock ~148 ~124 ~193 grass_block
setblock ~148 ~124 ~194 grass_block
setblock ~148 ~124 ~195 grass_block
setblock ~148 ~124 ~196 grass_block
setblock ~148 ~124 ~197 grass_block
setblock ~148 ~124 ~198 grass_block
setblock ~148 ~124 ~199 grass_block
setblock ~148 ~125 ~22 short_grass
setblock ~148 ~125 ~24 poppy
setblock ~148 ~125 ~25 short_grass
setblock ~148 ~125 ~27 fern
setblock ~148 ~125 ~32 short_grass
setblock ~148 ~125 ~34 short_grass
setblock ~148 ~125 ~35 short_grass
setblock ~148 ~125 ~36 grass_block
setblock ~148 ~125 ~37 grass_block
setblock ~148 ~125 ~38 grass_block
setblock ~148 ~125 ~39 grass_block
setblock ~148 ~125 ~40 grass_block
setblock ~148 ~125 ~41 grass_block
setblock ~148 ~125 ~42 dirt
setblock ~148 ~125 ~43 dirt
setblock ~148 ~125 ~44 dirt
setblock ~148 ~125 ~45 dirt
setblock ~148 ~125 ~46 dirt
setblock ~148 ~125 ~47 dirt
setblock ~148 ~125 ~48 dirt
setblock ~148 ~125 ~49 dirt
setblock ~148 ~125 ~50 dirt
setblock ~148 ~125 ~51 dirt
setblock ~148 ~125 ~52 dirt
setblock ~148 ~125 ~53 dirt
setblock ~148 ~125 ~54 dirt
setblock ~148 ~125 ~55 dirt
setblock ~148 ~125 ~56 dirt
setblock ~148 ~125 ~57 dirt
setblock ~148 ~125 ~58 grass_block
setblock ~148 ~125 ~59 grass_block
setblock ~148 ~125 ~60 grass_block
setblock ~148 ~125 ~61 grass_block
setblock ~148 ~125 ~62 grass_block
setblock ~148 ~125 ~63 grass_block
setblock ~148 ~125 ~64 grass_block
setblock ~148 ~125 ~65 short_grass
setblock ~148 ~125 ~67 fern
setblock ~148 ~125 ~74 grass_block
setblock ~148 ~125 ~75 grass_block
setblock ~148 ~125 ~76 grass_block
setblock ~148 ~125 ~77 dirt
setblock ~148 ~125 ~78 dirt
setblock ~148 ~125 ~79 dirt
setblock ~148 ~125 ~80 dirt
setblock ~148 ~125 ~81 dirt
setblock ~148 ~125 ~82 dirt
setblock ~148 ~125 ~83 grass_block
setblock ~148 ~125 ~84 grass_block
setblock ~148 ~125 ~85 grass_block
setblock ~148 ~125 ~86 short_grass
setblock ~148 ~125 ~88 short_grass
setblock ~148 ~125 ~92 fern
setblock ~148 ~125 ~93 grass_block
setblock ~148 ~125 ~94 grass_block
setblock ~148 ~125 ~95 dirt
setblock ~148 ~125 ~96 dirt
setblock ~148 ~125 ~97 dirt
setblock ~148 ~125 ~98 dirt
setblock ~148 ~125 ~99 dirt
setblock ~148 ~125 ~100 dirt
setblock ~148 ~125 ~101 dirt
setblock ~148 ~125 ~102 dirt
setblock ~148 ~125 ~103 dirt
setblock ~148 ~125 ~104 dirt
setblock ~148 ~125 ~105 dirt
setblock ~148 ~125 ~106 dirt
setblock ~148 ~125 ~107 dirt
setblock ~148 ~125 ~108 grass_block
setblock ~148 ~125 ~109 short_grass
setblock ~148 ~125 ~111 short_grass
setblock ~148 ~125 ~112 poppy
setblock ~148 ~125 ~114 short_grass
setblock ~148 ~125 ~123 short_grass
setblock ~148 ~125 ~127 grass_block
setblock ~148 ~125 ~128 grass_block
setblock ~148 ~125 ~129 dirt
setblock ~148 ~125 ~130 dirt
setblock ~148 ~125 ~131 grass_block
setblock ~148 ~125 ~132 grass_block
setblock ~148 ~125 ~145 short_grass
setblock ~148 ~125 ~146 grass_block
setblock ~148 ~125 ~147 grass_block
setblock ~148 ~125 ~148 grass_block
setblock ~148 ~125 ~149 dirt
setblock ~148 ~125 ~150 dirt
setblock ~148 ~125 ~151 dirt
setblock ~148 ~125 ~152 dirt
setblock ~148 ~125 ~153 dirt
setblock ~148 ~125 ~154 grass_block
setblock ~148 ~125 ~155 grass_block
setblock ~148 ~125 ~156 grass_block
setblock ~148 ~125 ~157 grass_block
setblock ~148 ~125 ~158 grass_block
setblock ~148 ~125 ~159 grass_block
setblock ~148 ~125 ~176 short_grass
setblock ~148 ~125 ~178 grass_block
setblock ~148 ~125 ~179 grass_block
setblock ~148 ~125 ~180 dirt
setblock ~148 ~125 ~181 dirt
setblock ~148 ~125 ~182 grass_block
setblock ~148 ~125 ~183 grass_block
setblock ~148 ~125 ~184 grass_block
setblock ~148 ~125 ~185 grass_block
setblock ~148 ~125 ~186 grass_block
setblock ~148 ~125 ~187 grass_block
setblock ~148 ~125 ~195 fern
setblock ~148 ~125 ~196 short_grass
setblock ~148 ~125 ~198 short_grass
setblock ~148 ~126 ~38 short_grass
setblock ~148 ~126 ~40 fern
setblock ~148 ~126 ~41 short_grass
setblock ~148 ~126 ~42 grass_block
setblock ~148 ~126 ~43 grass_block
setblock ~148 ~126 ~44 grass_block
setblock ~148 ~126 ~45 dirt
setblock ~148 ~126 ~46 dirt
setblock ~148 ~126 ~47 dirt
setblock ~148 ~126 ~48 dirt
setblock ~148 ~126 ~49 dirt
setblock ~148 ~126 ~50 dirt
setblock ~148 ~126 ~51 dirt
setblock ~148 ~126 ~52 dirt
setblock ~148 ~126 ~53 dirt
setblock ~148 ~126 ~54 dirt
setblock ~148 ~126 ~55 grass_block
setblock ~148 ~126 ~56 grass_block
setblock ~148 ~126 ~57 grass_block
setblock ~148 ~126 ~63 short_grass
setblock ~148 ~126 ~75 short_grass
setblock ~148 ~126 ~77 grass_block
setblock ~148 ~126 ~78 grass_block
setblock ~148 ~126 ~79 grass_block
setblock ~148 ~126 ~80 dirt
setblock ~148 ~126 ~81 grass_block
setblock ~148 ~126 ~82 grass_block
setblock ~148 ~126 ~84 short_grass
setblock ~148 ~126 ~85 short_grass
setblock ~148 ~126 ~95 grass_block
setblock ~148 ~126 ~96 grass_block
setblock ~148 ~126 ~97 dirt
setblock ~148 ~126 ~98 dirt
setblock ~148 ~126 ~99 dirt
setblock ~148 ~126 ~100 dirt
setblock ~148 ~126 ~101 dirt
setblock ~148 ~126 ~102 dirt
setblock ~148 ~126 ~103 dirt
setblock ~148 ~126 ~104 dirt
setblock ~148 ~126 ~105 dirt
setblock ~148 ~126 ~106 grass_block
setblock ~148 ~126 ~107 grass_block
setblock ~148 ~126 ~108 fern
setblock ~148 ~126 ~127 short_grass
setblock ~148 ~126 ~129 grass_block
setblock ~148 ~126 ~130 grass_block
setblock ~148 ~126 ~131 short_grass
setblock ~148 ~126 ~149 grass_block
setblock ~148 ~126 ~150 grass_block
setblock ~148 ~126 ~151 grass_block
setblock ~148 ~126 ~152 grass_block
setblock ~148 ~126 ~153 grass_block
setblock ~148 ~126 ~154 fern
setblock ~148 ~126 ~156 short_grass
setblock ~148 ~126 ~180 grass_block
setblock ~148 ~126 ~181 grass_block
setblock ~148 ~127 ~45 grass_block
setblock ~148 ~127 ~46 grass_block
setblock ~148 ~127 ~47 grass_block
setblock ~148 ~127 ~48 dirt
setblock ~148 ~127 ~49 dirt
setblock ~148 ~127 ~50 dirt
setblock ~148 ~127 ~51 dirt
setblock ~148 ~127 ~52 dirt
setblock ~148 ~127 ~53 grass_block
setblock ~148 ~127 ~54 grass_block
setblock ~148 ~127 ~56 short_grass
setblock ~148 ~127 ~80 grass_block
setblock ~148 ~127 ~82 short_grass
setblock ~148 ~127 ~97 grass_block
setblock ~148 ~127 ~98 dirt
setblock ~148 ~127 ~99 dirt
setblock ~148 ~127 ~100 dirt
setblock ~148 ~127 ~101 dirt
setblock ~148 ~127 ~102 dirt
setblock ~148 ~127 ~103 dirt
setblock ~148 ~127 ~104 grass_block
setblock ~148 ~127 ~105 grass_block
setblock ~148 ~127 ~106 short_grass
setblock ~148 ~127 ~107 short_grass
setblock ~148 ~127 ~130 short_grass
setblock ~148 ~127 ~149 short_grass
setblock ~148 ~127 ~150 short_grass
setblock ~148 ~127 ~152 fern
setblock ~148 ~127 ~180 short_grass
setblock ~148 ~128 ~45 short_grass
setblock ~148 ~128 ~47 short_grass
setblock ~148 ~128 ~48 grass_block
setblock ~148 ~128 ~49 grass_block
setblock ~148 ~128 ~50 dirt
setblock ~148 ~128 ~51 grass_block
setblock ~148 ~128 ~52 grass_block
setblock ~148 ~128 ~53 short_grass
setblock ~148 ~128 ~97 fern
setblock ~148 ~128 ~98 grass_block
setblock ~148 ~128 ~99 dirt
setblock ~148 ~128 ~100 dirt
setblock ~148 ~128 ~101 dirt
setblock ~148 ~128 ~102 dirt
setblock ~148 ~128 ~103 grass_block
setblock ~148 ~128 ~104 short_grass
setblock ~148 ~129 ~48 fern
setblock ~148 ~129 ~49 short_grass
setblock ~148 ~129 ~50 grass_block
setblock ~148 ~129 ~99 grass_block
setblock ~148 ~129 ~100 dirt
setblock ~148 ~129 ~101 grass_block
setblock ~148 ~129 ~102 grass_block
setblock ~148 ~130 ~100 grass_block
setblock ~148 ~131 ~100 short_grass
setblock ~149 ~122 ~0 dirt
setblock ~149 ~122 ~1 dirt
setblock ~149 ~122 ~2 dirt
setblock ~149 ~122 ~3 dirt
setblock ~149 ~122 ~4 dirt
setblock ~149 ~122 ~5 dirt
setblock ~149 ~122 ~6 dirt
setblock ~149 ~122 ~7 dirt
setblock ~149 ~122 ~8 dirt
setblock ~149 ~122 ~9 dirt
setblock ~149 ~122 ~10 dirt
setblock ~149 ~122 ~11 dirt
setblock ~149 ~122 ~12 dirt
setblock ~149 ~122 ~13 dirt
setblock ~149 ~122 ~14 dirt
setblock ~149 ~122 ~15 dirt
setblock ~149 ~122 ~16 dirt
setblock ~149 ~122 ~17 dirt
setblock ~149 ~122 ~18 dirt
setblock ~149 ~122 ~19 dirt
setblock ~149 ~122 ~20 dirt
setblock ~149 ~122 ~21 dirt
setblock ~149 ~122 ~22 dirt
setblock ~149 ~122 ~23 dirt
setblock ~149 ~122 ~24 dirt
setblock ~149 ~122 ~25 dirt
setblock ~149 ~122 ~26 dirt
setblock ~149 ~122 ~27 dirt
setblock ~149 ~122 ~28 dirt
setblock ~149 ~122 ~29 dirt
setblock ~149 ~122 ~30 dirt
setblock ~149 ~122 ~31 dirt
setblock ~149 ~122 ~32 dirt
setblock ~149 ~122 ~33 dirt
setblock ~149 ~122 ~34 dirt
setblock ~149 ~122 ~35 dirt
setblock ~149 ~122 ~36 dirt
setblock ~149 ~122 ~37 dirt
setblock ~149 ~122 ~38 dirt
setblock ~149 ~122 ~39 dirt
setblock ~149 ~122 ~40 dirt
setblock ~149 ~122 ~41 dirt
setblock ~149 ~122 ~42 dirt
setblock ~149 ~122 ~43 dirt
setblock ~149 ~122 ~44 dirt
setblock ~149 ~122 ~45 dirt
setblock ~149 ~122 ~46 dirt
setblock ~149 ~122 ~47 dirt
setblock ~149 ~122 ~48 dirt
setblock ~149 ~122 ~49 dirt
setblock ~149 ~122 ~50 dirt
setblock ~149 ~122 ~51 dirt
setblock ~149 ~122 ~52 dirt
setblock ~149 ~122 ~53 dirt
setblock ~149 ~122 ~54 dirt
setblock ~149 ~122 ~55 dirt
setblock ~149 ~122 ~56 dirt
setblock ~149 ~122 ~57 dirt
setblock ~149 ~122 ~58 dirt
setblock ~149 ~122 ~59 dirt
setblock ~149 ~122 ~60 dirt
setblock ~149 ~122 ~61 dirt
setblock ~149 ~122 ~62 dirt
setblock ~149 ~122 ~63 dirt
setblock ~149 ~122 ~64 dirt
setblock ~149 ~122 ~65 dirt
setblock ~149 ~122 ~66 dirt
setblock ~149 ~122 ~67 dirt
setblock ~149 ~122 ~68 dirt
setblock ~149 ~122 ~69 dirt
setblock ~149 ~122 ~70 dirt
setblock ~149 ~122 ~71 dirt
setblock ~149 ~122 ~72 dirt
setblock ~149 ~122 ~73 dirt
setblock ~149 ~122 ~74 dirt
setblock ~149 ~122 ~75 dirt
setblock ~149 ~122 ~76 dirt
setblock ~149 ~122 ~77 dirt
setblock ~149 ~122 ~78 dirt
setblock ~149 ~122 ~79 dirt
setblock ~149 ~122 ~80 dirt
setblock ~149 ~122 ~81 dirt
setblock ~149 ~122 ~82 dirt
setblock ~149 ~122 ~83 dirt
setblock ~149 ~122 ~84 dirt
setblock ~149 ~122 ~85 dirt
setblock ~149 ~122 ~86 dirt
setblock ~149 ~122 ~87 dirt
setblock ~149 ~122 ~88 dirt
setblock ~149 ~122 ~89 dirt
setblock ~149 ~122 ~90 dirt
setblock ~149 ~122 ~91 dirt
setblock ~149 ~122 ~92 dirt
setblock ~149 ~122 ~93 dirt
setblock ~149 ~122 ~94 dirt
setblock ~149 ~122 ~95 dirt
setblock ~149 ~122 ~96 dirt
setblock ~149 ~122 ~97 dirt
setblock ~149 ~122 ~98 dirt
setblock ~149 ~122 ~99 dirt
setblock ~149 ~122 ~100 dirt
setblock ~149 ~122 ~101 dirt
setblock ~149 ~122 ~102 dirt
setblock ~149 ~122 ~103 dirt
setblock ~149 ~122 ~104 dirt
setblock ~149 ~122 ~105 dirt
setblock ~149 ~122 ~106 dirt
setblock ~149 ~122 ~107 dirt
setblock ~149 ~122 ~108 dirt
setblock ~149 ~122 ~109 dirt
setblock ~149 ~122 ~110 dirt
setblock ~149 ~122 ~111 dirt
setblock ~149 ~122 ~112 dirt
setblock ~149 ~122 ~113 dirt
setblock ~149 ~122 ~114 dirt
setblock ~149 ~122 ~115 dirt
setblock ~149 ~122 ~116 dirt
setblock ~149 ~122 ~117 dirt
setblock ~149 ~122 ~118 dirt
setblock ~149 ~122 ~119 dirt
setblock ~149 ~122 ~120 dirt
setblock ~149 ~122 ~121 dirt
setblock ~149 ~122 ~122 dirt
setblock ~149 ~122 ~123 dirt
setblock ~149 ~122 ~124 dirt
setblock ~149 ~122 ~125 dirt
setblock ~149 ~122 ~126 dirt
setblock ~149 ~122 ~127 dirt
setblock ~149 ~122 ~128 dirt
setblock ~149 ~122 ~129 dirt
setblock ~149 ~122 ~130 dirt
setblock ~149 ~122 ~131 dirt
setblock ~149 ~122 ~132 dirt
setblock ~149 ~122 ~133 dirt
setblock ~149 ~122 ~134 dirt
setblock ~149 ~122 ~135 dirt
setblock ~149 ~122 ~136 dirt
setblock ~149 ~122 ~137 dirt
setblock ~149 ~122 ~138 grass_block
setblock ~149 ~122 ~139 grass_block
setblock ~149 ~122 ~140 grass_block
setblock ~149 ~122 ~141 grass_block
setblock ~149 ~122 ~142 dirt
setblock ~149 ~122 ~143 dirt
setblock ~149 ~122 ~144 dirt
setblock ~149 ~122 ~145 dirt
setblock ~149 ~122 ~146 dirt
setblock ~149 ~122 ~147 dirt
setblock ~149 ~122 ~148 dirt
setblock ~149 ~122 ~149 dirt
setblock ~149 ~122 ~150 dirt
setblock ~149 ~122 ~151 dirt
setblock ~149 ~122 ~152 dirt
setblock ~149 ~122 ~153 dirt
setblock ~149 ~122 ~154 dirt
setblock ~149 ~122 ~155 dirt
setblock ~149 ~122 ~156 dirt
setblock ~149 ~122 ~157 dirt
setblock ~149 ~122 ~158 dirt
setblock ~149 ~122 ~159 dirt
setblock ~149 ~122 ~160 dirt
setblock ~149 ~122 ~161 dirt
setblock ~149 ~122 ~162 dirt
setblock ~149 ~122 ~163 dirt
setblock ~149 ~122 ~164 dirt
setblock ~149 ~122 ~165 dirt
setblock ~149 ~122 ~166 dirt
setblock ~149 ~122 ~167 dirt
setblock ~149 ~122 ~168 grass_block
setblock ~149 ~122 ~169 grass_block
setblock ~149 ~122 ~170 grass_block
setblock ~149 ~122 ~171 grass_block
setblock ~149 ~122 ~172 grass_block
setblock ~149 ~122 ~173 dirt
setblock ~149 ~122 ~174 dirt
setblock ~149 ~122 ~175 dirt
setblock ~149 ~122 ~176 dirt
setblock ~149 ~122 ~177 dirt
setblock ~149 ~122 ~178 dirt
setblock ~149 ~122 ~179 dirt
setblock ~149 ~122 ~180 dirt
setblock ~149 ~122 ~181 dirt
setblock ~149 ~122 ~182 dirt
setblock ~149 ~122 ~183 dirt
setblock ~149 ~122 ~184 dirt
setblock ~149 ~122 ~185 dirt
setblock ~149 ~122 ~186 dirt
setblock ~149 ~122 ~187 dirt
setblock ~149 ~122 ~188 dirt
setblock ~149 ~122 ~189 dirt
setblock ~149 ~122 ~190 dirt
setblock ~149 ~122 ~191 dirt
setblock ~149 ~122 ~192 dirt
setblock ~149 ~122 ~193 dirt
setblock ~149 ~122 ~194 dirt
setblock ~149 ~122 ~195 dirt
setblock ~149 ~122 ~196 dirt
setblock ~149 ~122 ~197 dirt
setblock ~149 ~122 ~198 dirt
setblock ~149 ~122 ~199 dirt
setblock ~149 ~123 ~0 grass_block
setblock ~149 ~123 ~1 grass_block
setblock ~149 ~123 ~2 grass_block
setblock ~149 ~123 ~3 grass_block
setblock ~149 ~123 ~4 grass_block
setblock ~149 ~123 ~5 grass_block
setblock ~149 ~123 ~6 grass_block
setblock ~149 ~123 ~7 grass_block
setblock ~149 ~123 ~8 grass_block
setblock ~149 ~123 ~9 grass_block
setblock ~149 ~123 ~10 grass_block
setblock ~149 ~123 ~11 grass_block
setblock ~149 ~123 ~12 grass_block
setblock ~149 ~123 ~13 grass_block
setblock ~149 ~123 ~14 grass_block
setblock ~149 ~123 ~15 grass_block
setblock ~149 ~123 ~16 grass_block
setblock ~149 ~123 ~17 dirt
setblock ~149 ~123 ~18 dirt
setblock ~149 ~123 ~19 dirt
setblock ~149 ~123 ~20 dirt
setblock ~149 ~123 ~21 dirt
setblock ~149 ~123 ~22 dirt
setblock ~149 ~123 ~23 dirt
setblock ~149 ~123 ~24 dirt
setblock ~149 ~123 ~25 dirt
setblock ~149 ~123 ~26 grass_block
setblock ~149 ~123 ~27 grass_block
setblock ~149 ~123 ~28 grass_block
setblock ~149 ~123 ~29 grass_block
setblock ~149 ~123 ~30 grass_block
setblock ~149 ~123 ~31 grass_block
setblock ~149 ~123 ~32 dirt
setblock ~149 ~123 ~33 dirt
setblock ~149 ~123 ~34 dirt
setblock ~149 ~123 ~35 dirt
setblock ~149 ~123 ~36 dirt
setblock ~149 ~123 ~37 dirt
setblock ~149 ~123 ~38 dirt
setblock ~149 ~123 ~39 dirt
setblock ~149 ~123 ~40 dirt
setblock ~149 ~123 ~41 dirt
setblock ~149 ~123 ~42 dirt
setblock ~149 ~123 ~43 dirt
setblock ~149 ~123 ~44 dirt
setblock ~149 ~123 ~45 dirt
setblock ~149 ~123 ~46 dirt
setblock ~149 ~123 ~47 dirt
setblock ~149 ~123 ~48 dirt
setblock ~149 ~123 ~49 dirt
setblock ~149 ~123 ~50 dirt
setblock ~149 ~123 ~51 dirt
setblock ~149 ~123 ~52 dirt
setblock ~149 ~123 ~53 dirt
setblock ~149 ~123 ~54 dirt
setblock ~149 ~123 ~55 dirt
setblock ~149 ~123 ~56 dirt
setblock ~149 ~123 ~57 dirt
setblock ~149 ~123 ~58 dirt
setblock ~149 ~123 ~59 dirt
setblock ~149 ~123 ~60 dirt
setblock ~149 ~123 ~61 dirt
setblock ~149 ~123 ~62 dirt
setblock ~149 ~123 ~63 dirt
setblock ~149 ~123 ~64 dirt
setblock ~149 ~123 ~65 dirt
setblock ~149 ~123 ~66 dirt
setblock ~149 ~123 ~67 dirt
setblock ~149 ~123 ~68 dirt
setblock ~149 ~123 ~69 grass_block
setblock ~149 ~123 ~70 grass_block
setblock ~149 ~123 ~71 grass_block
setblock ~149 ~123 ~72 dirt
setblock ~149 ~123 ~73 dirt
setblock ~149 ~123 ~74 dirt
setblock ~149 ~123 ~75 dirt
setblock ~149 ~123 ~76 dirt
setblock ~149 ~123 ~77 dirt
setblock ~149 ~123 ~78 dirt
setblock ~149 ~123 ~79 dirt
setblock ~149 ~123 ~80 dirt
setblock ~149 ~123 ~81 dirt
setblock ~149 ~123 ~82 dirt
setblock ~149 ~123 ~83 dirt
setblock ~149 ~123 ~84 dirt
setblock ~149 ~123 ~85 dirt
setblock ~149 ~123 ~86 dirt
setblock ~149 ~123 ~87 dirt
setblock ~149 ~123 ~88 dirt
setblock ~149 ~123 ~89 grass_block
setblock ~149 ~123 ~90 grass_block
setblock ~149 ~123 ~91 dirt
setblock ~149 ~123 ~92 dirt
setblock ~149 ~123 ~93 dirt
setblock ~149 ~123 ~94 dirt
setblock ~149 ~123 ~95 dirt
setblock ~149 ~123 ~96 dirt
setblock ~149 ~123 ~97 dirt
setblock ~149 ~123 ~98 dirt
setblock ~149 ~123 ~99 dirt
setblock ~149 ~123 ~100 dirt
setblock ~149 ~123 ~101 dirt
setblock ~149 ~123 ~102 dirt
setblock ~149 ~123 ~103 dirt
setblock ~149 ~123 ~104 dirt
setblock ~149 ~123 ~105 dirt
setblock ~149 ~123 ~106 dirt
setblock ~149 ~123 ~107 dirt
setblock ~149 ~123 ~108 dirt
setblock ~149 ~123 ~109 dirt
setblock ~149 ~123 ~110 grass_block
setblock ~149 ~123 ~111 grass_block
setblock ~149 ~123 ~112 grass_block
setblock ~149 ~123 ~113 grass_block
setblock ~149 ~123 ~114 grass_block
setblock ~149 ~123 ~115 grass_block
setblock ~149 ~123 ~116 grass_block
setblock ~149 ~123 ~117 grass_block
setblock ~149 ~123 ~118 grass_block
setblock ~149 ~123 ~119 grass_block
setblock ~149 ~123 ~120 grass_block
setblock ~149 ~123 ~121 grass_block
setblock ~149 ~123 ~122 grass_block
setblock ~149 ~123 ~123 grass_block
setblock ~149 ~123 ~124 grass_block
setblock ~149 ~123 ~125 dirt
setblock ~149 ~123 ~126 dirt
setblock ~149 ~123 ~127 dirt
setblock ~149 ~123 ~128 dirt
setblock ~149 ~123 ~129 dirt
setblock ~149 ~123 ~130 dirt
setblock ~149 ~123 ~131 dirt
setblock ~149 ~123 ~132 dirt
setblock ~149 ~123 ~133 dirt
setblock ~149 ~123 ~134 dirt
setblock ~149 ~123 ~135 grass_block
setblock ~149 ~123 ~136 grass_block
setblock ~149 ~123 ~137 grass_block
setblock ~149 ~123 ~140 poppy
setblock ~149 ~123 ~142 grass_block
setblock ~149 ~123 ~143 grass_block
setblock ~149 ~123 ~144 dirt
setblock ~149 ~123 ~145 dirt
setblock ~149 ~123 ~146 dirt
setblock ~149 ~123 ~147 dirt
setblock ~149 ~123 ~148 dirt
setblock ~149 ~123 ~149 dirt
setblock ~149 ~123 ~150 dirt
setblock ~149 ~123 ~151 dirt
setblock ~149 ~123 ~152 dirt
setblock ~149 ~123 ~153 dirt
setblock ~149 ~123 ~154 dirt
setblock ~149 ~123 ~155 dirt
setblock ~149 ~123 ~156 dirt
setblock ~149 ~123 ~157 dirt
setblock ~149 ~123 ~158 dirt
setblock ~149 ~123 ~159 dirt
setblock ~149 ~123 ~160 dirt
setblock ~149 ~123 ~161 dirt
setblock ~149 ~123 ~162 dirt
setblock ~149 ~123 ~163 dirt
setblock ~149 ~123 ~164 grass_block
setblock ~149 ~123 ~165 grass_block
setblock ~149 ~123 ~166 grass_block
setblock ~149 ~123 ~167 grass_block
setblock ~149 ~123 ~168 fern
setblock ~149 ~123 ~170 short_grass
setblock ~149 ~123 ~173 grass_block
setblock ~149 ~123 ~174 grass_block
setblock ~149 ~123 ~175 dirt
setblock ~149 ~123 ~176 dirt
setblock ~149 ~123 ~177 dirt
setblock ~149 ~123 ~178 dirt
setblock ~149 ~123 ~179 dirt
setblock ~149 ~123 ~180 dirt
setblock ~149 ~123 ~181 dirt
setblock ~149 ~123 ~182 dirt
setblock ~149 ~123 ~183 dirt
setblock ~149 ~123 ~184 dirt
setblock ~149 ~123 ~185 dirt
setblock ~149 ~123 ~186 dirt
setblock ~149 ~123 ~187 dirt
setblock ~149 ~123 ~188 dirt
setblock ~149 ~123 ~189 dirt
setblock ~149 ~123 ~190 dirt
setblock ~149 ~123 ~191 dirt
setblock ~149 ~123 ~192 dirt
setblock ~149 ~123 ~193 dirt
setblock ~149 ~123 ~194 dirt
setblock ~149 ~123 ~195 dirt
setblock ~149 ~123 ~196 dirt
setblock ~149 ~123 ~197 dirt
setblock ~149 ~123 ~198 dirt
setblock ~149 ~123 ~199 dirt
setblock ~149 ~124 ~0 short_grass
setblock ~149 ~124 ~2 short_grass
setblock ~149 ~124 ~3 short_grass
setblock ~149 ~124 ~9 short_grass
setblock ~149 ~124 ~12 short_grass
setblock ~149 ~124 ~13 fern
setblock ~149 ~124 ~14 short_grass
setblock ~149 ~124 ~15 short_grass
setblock ~149 ~124 ~17 grass_block
setblock ~149 ~124 ~18 grass_block
setblock ~149 ~124 ~19 grass_block
setblock ~149 ~124 ~20 grass_block
setblock ~149 ~124 ~21 grass_block
setblock ~149 ~124 ~22 grass_block
setblock ~149 ~124 ~23 grass_block
setblock ~149 ~124 ~24 grass_block
setblock ~149 ~124 ~25 grass_block
setblock ~149 ~124 ~26 short_grass
setblock ~149 ~124 ~27 fern
setblock ~149 ~124 ~32 grass_block
setblock ~149 ~124 ~33 grass_block
setblock ~149 ~124 ~34 grass_block
setblock ~149 ~124 ~35 grass_block
setblock ~149 ~124 ~36 grass_block
setblock ~149 ~124 ~37 dirt
setblock ~149 ~124 ~38 dirt
setblock ~149 ~124 ~39 dirt
setblock ~149 ~124 ~40 dirt
setblock ~149 ~124 ~41 dirt
setblock ~149 ~124 ~42 dirt
setblock ~149 ~124 ~43 dirt
setblock ~149 ~124 ~44 dirt
setblock ~149 ~124 ~45 dirt
setblock ~149 ~124 ~46 dirt
setblock ~149 ~124 ~47 dirt
setblock ~149 ~124 ~48 dirt
setblock ~149 ~124 ~49 dirt
setblock ~149 ~124 ~50 dirt
setblock ~149 ~124 ~51 dirt
setblock ~149 ~124 ~52 dirt
setblock ~149 ~124 ~53 dirt
setblock ~149 ~124 ~54 dirt
setblock ~149 ~124 ~55 dirt
setblock ~149 ~124 ~56 dirt
setblock ~149 ~124 ~57 dirt
setblock ~149 ~124 ~58 dirt
setblock ~149 ~124 ~59 dirt
setblock ~149 ~124 ~60 dirt
setblock ~149 ~124 ~61 dirt
setblock ~149 ~124 ~62 dirt
setblock ~149 ~124 ~63 grass_block
setblock ~149 ~124 ~64 grass_block
setblock ~149 ~124 ~65 grass_block
setblock ~149 ~124 ~66 grass_block
setblock ~149 ~124 ~67 grass_block
setblock ~149 ~124 ~68 grass_block
setblock ~149 ~124 ~72 grass_block
setblock ~149 ~124 ~73 grass_block
setblock ~149 ~124 ~74 dirt
setblock ~149 ~124 ~75 dirt
setblock ~149 ~124 ~76 dirt
setblock ~149 ~124 ~77 dirt
setblock ~149 ~124 ~78 dirt
setblock ~149 ~124 ~79 dirt
setblock ~149 ~124 ~80 dirt
setblock ~149 ~124 ~81 dirt
setblock ~149 ~124 ~82 dirt
setblock ~149 ~124 ~83 dirt
setblock ~149 ~124 ~84 dirt
setblock ~149 ~124 ~85 dirt
setblock ~149 ~124 ~86 grass_block
setblock ~149 ~124 ~87 grass_block
setblock ~149 ~124 ~88 grass_block
setblock ~149 ~124 ~89 short_grass
setblock ~149 ~124 ~90 poppy
setblock ~149 ~124 ~91 grass_block
setblock ~149 ~124 ~92 grass_block
setblock ~149 ~124 ~93 dirt
setblock ~149 ~124 ~94 dirt
setblock ~149 ~124 ~95 dirt
setblock ~149 ~124 ~96 dirt
setblock ~149 ~124 ~97 dirt
setblock ~149 ~124 ~98 dirt
setblock ~149 ~124 ~99 dirt
setblock ~149 ~124 ~100 dirt
setblock ~149 ~124 ~101 dirt
setblock ~149 ~124 ~102 dirt
setblock ~149 ~124 ~103 dirt
setblock ~149 ~124 ~104 dirt
setblock ~149 ~124 ~105 dirt
setblock ~149 ~124 ~106 dirt
setblock ~149 ~124 ~107 dirt
setblock ~149 ~124 ~108 grass_block
setblock ~149 ~124 ~109 grass_block
setblock ~149 ~124 ~112 short_grass
setblock ~149 ~124 ~119 short_grass
setblock ~149 ~124 ~125 grass_block
setblock ~149 ~124 ~126 grass_block
setblock ~149 ~124 ~127 dirt
setblock ~149 ~124 ~128 dirt
setblock ~149 ~124 ~129 dirt
setblock ~149 ~124 ~130 dirt
setblock ~149 ~124 ~131 dirt
setblock ~149 ~124 ~132 dirt
setblock ~149 ~124 ~133 grass_block
setblock ~149 ~124 ~134 grass_block
setblock ~149 ~124 ~136 short_grass
setblock ~149 ~124 ~137 fern
setblock ~149 ~124 ~142 short_grass
setblock ~149 ~124 ~144 grass_block
setblock ~149 ~124 ~145 grass_block
setblock ~149 ~124 ~146 dirt
setblock ~149 ~124 ~147 dirt
setblock ~149 ~124 ~148 dirt
setblock ~149 ~124 ~149 dirt
setblock ~149 ~124 ~150 dirt
setblock ~149 ~124 ~151 dirt
setblock ~149 ~124 ~152 dirt
setblock ~149 ~124 ~153 dirt
setblock ~149 ~124 ~154 dirt
setblock ~149 ~124 ~155 dirt
setblock ~149 ~124 ~156 dirt
setblock ~149 ~124 ~157 dirt
setblock ~149 ~124 ~158 dirt
setblock ~149 ~124 ~159 grass_block
setblock ~149 ~124 ~160 grass_block
setblock ~149 ~124 ~161 grass_block
setblock ~149 ~124 ~162 grass_block
setblock ~149 ~124 ~163 grass_block
setblock ~149 ~124 ~166 fern
setblock ~149 ~124 ~175 grass_block
setblock ~149 ~124 ~176 grass_block
setblock ~149 ~124 ~177 grass_block
setblock ~149 ~124 ~178 dirt
setblock ~149 ~124 ~179 dirt
setblock ~149 ~124 ~180 dirt
setblock ~149 ~124 ~181 dirt
setblock ~149 ~124 ~182 dirt
setblock ~149 ~124 ~183 dirt
setblock ~149 ~124 ~184 dirt
setblock ~149 ~124 ~185 dirt
setblock ~149 ~124 ~186 dirt
setblock ~149 ~124 ~187 dirt
setblock ~149 ~124 ~188 dirt
setblock ~149 ~124 ~189 grass_block
setblock ~149 ~124 ~190 grass_block
setblock ~149 ~124 ~191 grass_block
setblock ~149 ~124 ~192 grass_block
setblock ~149 ~124 ~193 grass_block
setblock ~149 ~124 ~194 grass_block
setblock ~149 ~124 ~195 grass_block
setblock ~149 ~124 ~196 grass_block
setblock ~149 ~124 ~197 grass_block
setblock ~149 ~124 ~198 grass_block
setblock ~149 ~124 ~199 grass_block
setblock ~149 ~125 ~20 short_grass
setblock ~149 ~125 ~32 short_grass
setblock ~149 ~125 ~34 short_grass
setblock ~149 ~125 ~35 short_grass
setblock ~149 ~125 ~37 grass_block
setblock ~149 ~125 ~38 grass_block
setblock ~149 ~125 ~39 grass_block
setblock ~149 ~125 ~40 grass_block
setblock ~149 ~125 ~41 grass_block
setblock ~149 ~125 ~42 dirt
setblock ~149 ~125 ~43 dirt
setblock ~149 ~125 ~44 dirt
setblock ~149 ~125 ~45 dirt
setblock ~149 ~125 ~46 dirt
setblock ~149 ~125 ~47 dirt
setblock ~149 ~125 ~48 dirt
setblock ~149 ~125 ~49 dirt
setblock ~149 ~125 ~50 dirt
setblock ~149 ~125 ~51 dirt
setblock ~149 ~125 ~52 dirt
setblock ~149 ~125 ~53 dirt
setblock ~149 ~125 ~54 dirt
setblock ~149 ~125 ~55 dirt
setblock ~149 ~125 ~56 dirt
setblock ~149 ~125 ~57 dirt
setblock ~149 ~125 ~58 grass_block
setblock ~149 ~125 ~59 grass_block
setblock ~149 ~125 ~60 grass_block
setblock ~149 ~125 ~61 grass_block
setblock ~149 ~125 ~62 grass_block
setblock ~149 ~125 ~63 short_grass
setblock ~149 ~125 ~64 short_grass
setblock ~149 ~125 ~72 short_grass
setblock ~149 ~125 ~73 short_grass
setblock ~149 ~125 ~74 grass_block
setblock ~149 ~125 ~75 grass_block
setblock ~149 ~125 ~76 grass_block
setblock ~149 ~125 ~77 dirt
setblock ~149 ~125 ~78 dirt
setblock ~149 ~125 ~79 dirt
setblock ~149 ~125 ~80 dirt
setblock ~149 ~125 ~81 dirt
setblock ~149 ~125 ~82 dirt
setblock ~149 ~125 ~83 dirt
setblock ~149 ~125 ~84 grass_block
setblock ~149 ~125 ~85 grass_block
setblock ~149 ~125 ~87 short_grass
setblock ~149 ~125 ~88 short_grass
setblock ~149 ~125 ~92 short_grass
setblock ~149 ~125 ~93 grass_block
setblock ~149 ~125 ~94 grass_block
setblock ~149 ~125 ~95 dirt
setblock ~149 ~125 ~96 dirt
setblock ~149 ~125 ~97 dirt
setblock ~149 ~125 ~98 dirt
setblock ~149 ~125 ~99 dirt
setblock ~149 ~125 ~100 dirt
setblock ~149 ~125 ~101 dirt
setblock ~149 ~125 ~102 dirt
setblock ~149 ~125 ~103 dirt
setblock ~149 ~125 ~104 dirt
setblock ~149 ~125 ~105 dirt
setblock ~149 ~125 ~106 dirt
setblock ~149 ~125 ~107 grass_block
setblock ~149 ~125 ~127 grass_block
setblock ~149 ~125 ~128 grass_block
setblock ~149 ~125 ~129 dirt
setblock ~149 ~125 ~130 dirt
setblock ~149 ~125 ~131 dirt
setblock ~149 ~125 ~132 grass_block
setblock ~149 ~125 ~133 short_grass
setblock ~149 ~125 ~134 short_grass
setblock ~149 ~125 ~146 grass_block
setblock ~149 ~125 ~147 grass_block
setblock ~149 ~125 ~148 grass_block
setblock ~149 ~125 ~149 dirt
setblock ~149 ~125 ~150 dirt
setblock ~149 ~125 ~151 dirt
setblock ~149 ~125 ~152 dirt
setblock ~149 ~125 ~153 dirt
setblock ~149 ~125 ~154 grass_block
setblock ~149 ~125 ~155 grass_block
setblock ~149 ~125 ~156 grass_block
setblock ~149 ~125 ~157 grass_block
setblock ~149 ~125 ~158 grass_block
setblock ~149 ~125 ~163 short_grass
setblock ~149 ~125 ~177 short_grass
setblock ~149 ~125 ~178 grass_block
setblock ~149 ~125 ~179 grass_block
setblock ~149 ~125 ~180 dirt
setblock ~149 ~125 ~181 dirt
setblock ~149 ~125 ~182 dirt
setblock ~149 ~125 ~183 grass_block
setblock ~149 ~125 ~184 grass_block
setblock ~149 ~125 ~185 grass_block
setblock ~149 ~125 ~186 grass_block
setblock ~149 ~125 ~187 grass_block
setblock ~149 ~125 ~188 grass_block
setblock ~149 ~125 ~199 short_grass
setblock ~149 ~126 ~39 short_grass
setblock ~149 ~126 ~40 short_grass
setblock ~149 ~126 ~42 grass_block
setblock ~149 ~126 ~43 grass_block
setblock ~149 ~126 ~44 grass_block
setblock ~149 ~126 ~45 dirt
setblock ~149 ~126 ~46 dirt
setblock ~149 ~126 ~47 dirt
setblock ~149 ~126 ~48 dirt
setblock ~149 ~126 ~49 dirt
setblock ~149 ~126 ~50 dirt
setblock ~149 ~126 ~51 dirt
setblock ~149 ~126 ~52 dirt
setblock ~149 ~126 ~53 dirt
setblock ~149 ~126 ~54 dirt
setblock ~149 ~126 ~55 grass_block
setblock ~149 ~126 ~56 grass_block
setblock ~149 ~126 ~57 grass_block
setblock ~149 ~126 ~59 short_grass
setblock ~149 ~126 ~77 grass_block
setblock ~149 ~126 ~78 grass_block
setblock ~149 ~126 ~79 dirt
setblock ~149 ~126 ~80 dirt
setblock ~149 ~126 ~81 dirt
setblock ~149 ~126 ~82 grass_block
setblock ~149 ~126 ~83 grass_block
setblock ~149 ~126 ~84 poppy
setblock ~149 ~126 ~95 grass_block
setblock ~149 ~126 ~96 grass_block
setblock ~149 ~126 ~97 dirt
setblock ~149 ~126 ~98 dirt
setblock ~149 ~126 ~99 dirt
setblock ~149 ~126 ~100 dirt
setblock ~149 ~126 ~101 dirt
setblock ~149 ~126 ~102 dirt
setblock ~149 ~126 ~103 dirt
setblock ~149 ~126 ~104 dirt
setblock ~149 ~126 ~105 grass_block
setblock ~149 ~126 ~106 grass_block
setblock ~149 ~126 ~107 short_grass
setblock ~149 ~126 ~129 grass_block
setblock ~149 ~126 ~130 dirt
setblock ~149 ~126 ~131 grass_block
setblock ~149 ~126 ~149 grass_block
setblock ~149 ~126 ~150 grass_block
setblock ~149 ~126 ~151 grass_block
setblock ~149 ~126 ~152 grass_block
setblock ~149 ~126 ~153 grass_block
setblock ~149 ~126 ~157 short_grass
setblock ~149 ~126 ~178 short_grass
setblock ~149 ~126 ~180 grass_block
setblock ~149 ~126 ~181 grass_block
setblock ~149 ~126 ~182 grass_block
setblock ~149 ~126 ~183 poppy
setblock ~149 ~126 ~186 short_grass
setblock ~149 ~126 ~188 short_grass
setblock ~149 ~127 ~45 grass_block
setblock ~149 ~127 ~46 grass_block
setblock ~149 ~127 ~47 dirt
setblock ~149 ~127 ~48 dirt
setblock ~149 ~127 ~49 dirt
setblock ~149 ~127 ~50 dirt
setblock ~149 ~127 ~51 dirt
setblock ~149 ~127 ~52 dirt
setblock ~149 ~127 ~53 grass_block
setblock ~149 ~127 ~54 grass_block
setblock ~149 ~127 ~57 short_grass
setblock ~149 ~127 ~77 short_grass
setblock ~149 ~127 ~79 grass_block
setblock ~149 ~127 ~80 grass_block
setblock ~149 ~127 ~81 grass_block
setblock ~149 ~127 ~96 short_grass
setblock ~149 ~127 ~97 grass_block
setblock ~149 ~127 ~98 dirt
setblock ~149 ~127 ~99 dirt
setblock ~149 ~127 ~100 dirt
setblock ~149 ~127 ~101 dirt
setblock ~149 ~127 ~102 dirt
setblock ~149 ~127 ~103 dirt
setblock ~149 ~127 ~104 grass_block
setblock ~149 ~127 ~129 short_grass
setblock ~149 ~127 ~130 grass_block
setblock ~149 ~127 ~149 short_grass
setblock ~149 ~127 ~151 poppy
setblock ~149 ~127 ~153 poppy
setblock ~149 ~127 ~182 short_grass
setblock ~149 ~128 ~46 short_grass
setblock ~149 ~128 ~47 grass_block
setblock ~149 ~128 ~48 grass_block
setblock ~149 ~128 ~49 dirt
setblock ~149 ~128 ~50 dirt
setblock ~149 ~128 ~51 grass_block
setblock ~149 ~128 ~52 grass_block
setblock ~149 ~128 ~98 grass_block
setblock ~149 ~128 ~99 dirt
setblock ~149 ~128 ~100 dirt
setblock ~149 ~128 ~101 dirt
setblock ~149 ~128 ~102 dirt
setblock ~149 ~128 ~103 grass_block
setblock ~149 ~129 ~47 short_grass
setblock ~149 ~129 ~49 grass_block
setblock ~149 ~129 ~50 grass_block
setblock ~149 ~129 ~99 grass_block
setblock ~149 ~129 ~100 dirt
setblock ~149 ~129 ~101 grass_block
setblock ~149 ~129 ~102 grass_block
setblock ~149 ~129 ~103 fern
setblock ~149 ~130 ~100 grass_block
setblock ~149 ~130 ~101 poppy
setblock ~149 ~131 ~100 fern
setblock ~150 ~122 ~0 dirt
setblock ~150 ~122 ~1 dirt
setblock ~150 ~122 ~2 dirt
setblock ~150 ~122 ~3 dirt
setblock ~150 ~122 ~4 dirt
setblock ~150 ~122 ~5 dirt
setblock ~150 ~122 ~6 dirt
setblock ~150 ~122 ~7 dirt
setblock ~150 ~122 ~8 dirt
setblock ~150 ~122 ~9 dirt
setblock ~150 ~122 ~10 dirt
setblock ~150 ~122 ~11 dirt
setblock ~150 ~122 ~12 dirt
setblock ~150 ~122 ~13 dirt
setblock ~150 ~122 ~14 dirt
setblock ~150 ~122 ~15 dirt
setblock ~150 ~122 ~16 dirt
setblock ~150 ~122 ~17 dirt
setblock ~150 ~122 ~18 dirt
setblock ~150 ~122 ~19 dirt
setblock ~150 ~122 ~20 dirt
setblock ~150 ~122 ~21 dirt
setblock ~150 ~122 ~22 dirt
setblock ~150 ~122 ~23 dirt
setblock ~150 ~122 ~24 dirt
setblock ~150 ~122 ~25 dirt
setblock ~150 ~122 ~26 dirt
setblock ~150 ~122 ~27 dirt
setblock ~150 ~122 ~28 dirt
setblock ~150 ~122 ~29 dirt
setblock ~150 ~122 ~30 dirt
setblock ~150 ~122 ~31 dirt
setblock ~150 ~122 ~32 dirt
setblock ~150 ~122 ~33 dirt
setblock ~150 ~122 ~34 dirt
setblock ~150 ~122 ~35 dirt
setblock ~150 ~122 ~36 dirt
setblock ~150 ~122 ~37 dirt
setblock ~150 ~122 ~38 dirt
setblock ~150 ~122 ~39 dirt
setblock ~150 ~122 ~40 dirt
setblock ~150 ~122 ~41 dirt
setblock ~150 ~122 ~42 dirt
setblock ~150 ~122 ~43 dirt
setblock ~150 ~122 ~44 dirt
setblock ~150 ~122 ~45 dirt
setblock ~150 ~122 ~46 dirt
setblock ~150 ~122 ~47 dirt
setblock ~150 ~122 ~48 dirt
setblock ~150 ~122 ~49 dirt
setblock ~150 ~122 ~50 dirt
setblock ~150 ~122 ~51 dirt
setblock ~150 ~122 ~52 dirt
setblock ~150 ~122 ~53 dirt
setblock ~150 ~122 ~54 dirt
setblock ~150 ~122 ~55 dirt
setblock ~150 ~122 ~56 dirt
setblock ~150 ~122 ~57 dirt
setblock ~150 ~122 ~58 dirt
setblock ~150 ~122 ~59 dirt
setblock ~150 ~122 ~60 dirt
setblock ~150 ~122 ~61 dirt
setblock ~150 ~122 ~62 dirt
setblock ~150 ~122 ~63 dirt
setblock ~150 ~122 ~64 dirt
setblock ~150 ~122 ~65 dirt
setblock ~150 ~122 ~66 dirt
setblock ~150 ~122 ~67 dirt
setblock ~150 ~122 ~68 dirt
setblock ~150 ~122 ~69 dirt
setblock ~150 ~122 ~70 dirt
setblock ~150 ~122 ~71 dirt
setblock ~150 ~122 ~72 dirt
setblock ~150 ~122 ~73 dirt
setblock ~150 ~122 ~74 dirt
setblock ~150 ~122 ~75 dirt
setblock ~150 ~122 ~76 dirt
setblock ~150 ~122 ~77 dirt
setblock ~150 ~122 ~78 dirt
setblock ~150 ~122 ~79 dirt
setblock ~150 ~122 ~80 dirt
setblock ~150 ~122 ~81 dirt
setblock ~150 ~122 ~82 dirt
setblock ~150 ~122 ~83 dirt
setblock ~150 ~122 ~84 dirt
setblock ~150 ~122 ~85 dirt
setblock ~150 ~122 ~86 dirt
setblock ~150 ~122 ~87 dirt
setblock ~150 ~122 ~88 dirt
setblock ~150 ~122 ~89 dirt
setblock ~150 ~122 ~90 dirt
setblock ~150 ~122 ~91 dirt
setblock ~150 ~122 ~92 dirt
setblock ~150 ~122 ~93 dirt
setblock ~150 ~122 ~94 dirt
setblock ~150 ~122 ~95 dirt
setblock ~150 ~122 ~96 dirt
setblock ~150 ~122 ~97 dirt
setblock ~150 ~122 ~98 dirt
setblock ~150 ~122 ~99 dirt
setblock ~150 ~122 ~100 dirt
setblock ~150 ~122 ~101 dirt
setblock ~150 ~122 ~102 dirt
setblock ~150 ~122 ~103 dirt
setblock ~150 ~122 ~104 dirt
setblock ~150 ~122 ~105 dirt
setblock ~150 ~122 ~106 dirt
setblock ~150 ~122 ~107 dirt
setblock ~150 ~122 ~108 dirt
setblock ~150 ~122 ~109 dirt
setblock ~150 ~122 ~110 dirt
setblock ~150 ~122 ~111 dirt
setblock ~150 ~122 ~112 dirt
setblock ~150 ~122 ~113 dirt
setblock ~150 ~122 ~114 dirt
setblock ~150 ~122 ~115 dirt
setblock ~150 ~122 ~116 dirt
setblock ~150 ~122 ~117 dirt
setblock ~150 ~122 ~118 dirt
setblock ~150 ~122 ~119 grass_block
setblock ~150 ~122 ~120 grass_block
setblock ~150 ~122 ~121 grass_block
setblock ~150 ~122 ~122 grass_block
setblock ~150 ~122 ~123 dirt
setblock ~150 ~122 ~124 dirt
setblock ~150 ~122 ~125 dirt
setblock ~150 ~122 ~126 dirt
setblock ~150 ~122 ~127 dirt
setblock ~150 ~122 ~128 dirt
setblock ~150 ~122 ~129 dirt
setblock ~150 ~122 ~130 dirt
setblock ~150 ~122 ~131 dirt
setblock ~150 ~122 ~132 dirt
setblock ~150 ~122 ~133 dirt
setblock ~150 ~122 ~134 dirt
setblock ~150 ~122 ~135 dirt
setblock ~150 ~122 ~136 dirt
setblock ~150 ~122 ~137 grass_block
setblock ~150 ~122 ~138 grass_block
setblock ~150 ~122 ~139 grass_block
setblock ~150 ~122 ~140 grass_block
setblock ~150 ~122 ~141 grass_block
setblock ~150 ~122 ~142 dirt
setblock ~150 ~122 ~143 dirt
setblock ~150 ~122 ~144 dirt
setblock ~150 ~122 ~145 dirt
setblock ~150 ~122 ~146 dirt
setblock ~150 ~122 ~147 dirt
setblock ~150 ~122 ~148 dirt
setblock ~150 ~122 ~149 dirt
setblock ~150 ~122 ~150 dirt
setblock ~150 ~122 ~151 dirt
setblock ~150 ~122 ~152 dirt
setblock ~150 ~122 ~153 dirt
setblock ~150 ~122 ~154 dirt
setblock ~150 ~122 ~155 dirt
setblock ~150 ~122 ~156 dirt
setblock ~150 ~122 ~157 dirt
setblock ~150 ~122 ~158 dirt
setblock ~150 ~122 ~159 dirt
setblock ~150 ~122 ~160 dirt
setblock ~150 ~122 ~161 dirt
setblock ~150 ~122 ~162 dirt
setblock ~150 ~122 ~163 dirt
setblock ~150 ~122 ~164 dirt
setblock ~150 ~122 ~165 dirt
setblock ~150 ~122 ~166 dirt
setblock ~150 ~122 ~167 dirt
setblock ~150 ~122 ~168 grass_block
setblock ~150 ~122 ~169 grass_block
setblock ~150 ~122 ~170 grass_block
setblock ~150 ~122 ~171 grass_block
setblock ~150 ~122 ~172 grass_block
setblock ~150 ~122 ~173 dirt
setblock ~150 ~122 ~174 dirt
setblock ~150 ~122 ~175 dirt
setblock ~150 ~122 ~176 dirt
setblock ~150 ~122 ~177 dirt
setblock ~150 ~122 ~178 dirt
setblock ~150 ~122 ~179 dirt
setblock ~150 ~122 ~180 dirt
setblock ~150 ~122 ~181 dirt
setblock ~150 ~122 ~182 dirt
setblock ~150 ~122 ~183 dirt
setblock ~150 ~122 ~184 dirt
setblock ~150 ~122 ~185 dirt
setblock ~150 ~122 ~186 dirt
setblock ~150 ~122 ~187 dirt
setblock ~150 ~122 ~188 dirt
setblock ~150 ~122 ~189 dirt
setblock ~150 ~122 ~190 dirt
setblock ~150 ~122 ~191 dirt
setblock ~150 ~122 ~192 dirt
setblock ~150 ~122 ~193 dirt
setblock ~150 ~122 ~194 dirt
setblock ~150 ~122 ~195 dirt
setblock ~150 ~122 ~196 dirt
setblock ~150 ~122 ~197 dirt
setblock ~150 ~122 ~198 dirt
setblock ~150 ~122 ~199 dirt
setblock ~150 ~123 ~0 grass_block
setblock ~150 ~123 ~1 grass_block
setblock ~150 ~123 ~2 grass_block
setblock ~150 ~123 ~3 grass_block
setblock ~150 ~123 ~4 grass_block
setblock ~150 ~123 ~5 grass_block
setblock ~150 ~123 ~6 grass_block
setblock ~150 ~123 ~7 grass_block
setblock ~150 ~123 ~8 grass_block
setblock ~150 ~123 ~9 grass_block
setblock ~150 ~123 ~10 grass_block
setblock ~150 ~123 ~11 grass_block
setblock ~150 ~123 ~12 grass_block
setblock ~150 ~123 ~13 grass_block
setblock ~150 ~123 ~14 grass_block
setblock ~150 ~123 ~15 grass_block
setblock ~150 ~123 ~16 grass_block
setblock ~150 ~123 ~17 grass_block
setblock ~150 ~123 ~18 grass_block
setblock ~150 ~123 ~19 grass_block
setblock ~150 ~123 ~20 grass_block
setblock ~150 ~123 ~21 grass_block
setblock ~150 ~123 ~22 grass_block
setblock ~150 ~123 ~23 grass_block
setblock ~150 ~123 ~24 grass_block
setblock ~150 ~123 ~25 grass_block
setblock ~150 ~123 ~26 grass_block
setblock ~150 ~123 ~27 grass_block
setblock ~150 ~123 ~28 grass_block
setblock ~150 ~123 ~29 grass_block
setblock ~150 ~123 ~30 grass_block
setblock ~150 ~123 ~31 grass_block
setblock ~150 ~123 ~32 dirt
setblock ~150 ~123 ~33 dirt
setblock ~150 ~123 ~34 dirt
setblock ~150 ~123 ~35 dirt
setblock ~150 ~123 ~36 dirt
setblock ~150 ~123 ~37 dirt
setblock ~150 ~123 ~38 dirt
setblock ~150 ~123 ~39 dirt
setblock ~150 ~123 ~40 dirt
setblock ~150 ~123 ~41 dirt
setblock ~150 ~123 ~42 dirt
setblock ~150 ~123 ~43 dirt
setblock ~150 ~123 ~44 dirt
setblock ~150 ~123 ~45 dirt
setblock ~150 ~123 ~46 dirt
setblock ~150 ~123 ~47 dirt
setblock ~150 ~123 ~48 dirt
setblock ~150 ~123 ~49 dirt
setblock ~150 ~123 ~50 dirt
setblock ~150 ~123 ~51 dirt
setblock ~150 ~123 ~52 dirt
setblock ~150 ~123 ~53 dirt
setblock ~150 ~123 ~54 dirt
setblock ~150 ~123 ~55 dirt
setblock ~150 ~123 ~56 dirt
setblock ~150 ~123 ~57 dirt
setblock ~150 ~123 ~58 dirt
setblock ~150 ~123 ~59 dirt
setblock ~150 ~123 ~60 dirt
setblock ~150 ~123 ~61 dirt
setblock ~150 ~123 ~62 dirt
setblock ~150 ~123 ~63 dirt
setblock ~150 ~123 ~64 dirt
setblock ~150 ~123 ~65 dirt
setblock ~150 ~123 ~66 dirt
setblock ~150 ~123 ~67 grass_block
setblock ~150 ~123 ~68 grass_block
setblock ~150 ~123 ~69 grass_block
setblock ~150 ~123 ~70 grass_block
setblock ~150 ~123 ~71 grass_block
setblock ~150 ~123 ~72 dirt
setblock ~150 ~123 ~73 dirt
setblock ~150 ~123 ~74 dirt
setblock ~150 ~123 ~75 dirt
setblock ~150 ~123 ~76 dirt
setblock ~150 ~123 ~77 dirt
setblock ~150 ~123 ~78 dirt
setblock ~150 ~123 ~79 dirt
setblock ~150 ~123 ~80 dirt
setblock ~150 ~123 ~81 dirt
setblock ~150 ~123 ~82 dirt
setblock ~150 ~123 ~83 dirt
setblock ~150 ~123 ~84 dirt
setblock ~150 ~123 ~85 dirt
setblock ~150 ~123 ~86 dirt
setblock ~150 ~123 ~87 dirt
setblock ~150 ~123 ~88 dirt
setblock ~150 ~123 ~89 grass_block
setblock ~150 ~123 ~90 grass_block
setblock ~150 ~123 ~91 grass_block
setblock ~150 ~123 ~92 dirt
setblock ~150 ~123 ~93 dirt
setblock ~150 ~123 ~94 dirt
setblock ~150 ~123 ~95 dirt
setblock ~150 ~123 ~96 dirt
setblock ~150 ~123 ~97 dirt
setblock ~150 ~123 ~98 dirt
setblock ~150 ~123 ~99 dirt
setblock ~150 ~123 ~100 dirt
setblock ~150 ~123 ~101 dirt
setblock ~150 ~123 ~102 dirt
setblock ~150 ~123 ~103 dirt
setblock ~150 ~123 ~104 dirt
setblock ~150 ~123 ~105 dirt
setblock ~150 ~123 ~106 dirt
setblock ~150 ~123 ~107 dirt
setblock ~150 ~123 ~108 dirt
setblock ~150 ~123 ~109 grass_block
setblock ~150 ~123 ~110 grass_block
setblock ~150 ~123 ~111 grass_block
setblock ~150 ~123 ~112 grass_block
setblock ~150 ~123 ~113 grass_block
setblock ~150 ~123 ~114 grass_block
setblock ~150 ~123 ~115 grass_block
setblock ~150 ~123 ~116 grass_block
setblock ~150 ~123 ~117 grass_block
setblock ~150 ~123 ~118 grass_block
setblock ~150 ~123 ~123 grass_block
setblock ~150 ~123 ~124 grass_block
setblock ~150 ~123 ~125 grass_block
setblock ~150 ~123 ~126 dirt
setblock ~150 ~123 ~127 dirt
setblock ~150 ~123 ~128 dirt
setblock ~150 ~123 ~129 dirt
setblock ~150 ~123 ~130 dirt
setblock ~150 ~123 ~131 dirt
setblock ~150 ~123 ~132 dirt
setblock ~150 ~123 ~133 dirt
setblock ~150 ~123 ~134 grass_block
setblock ~150 ~123 ~135 grass_block
setblock ~150 ~123 ~136 grass_block
setblock ~150 ~123 ~137 short_grass
setblock ~150 ~123 ~138 poppy
setblock ~150 ~123 ~139 fern
setblock ~150 ~123 ~140 short_grass
setblock ~150 ~123 ~141 short_grass
setblock ~150 ~123 ~142 grass_block
setblock ~150 ~123 ~143 grass_block
setblock ~150 ~123 ~144 dirt
setblock ~150 ~123 ~145 dirt
setblock ~150 ~123 ~146 dirt
setblock ~150 ~123 ~147 dirt
setblock ~150 ~123 ~148 dirt
setblock ~150 ~123 ~149 dirt
setblock ~150 ~123 ~150 dirt
setblock ~150 ~123 ~151 dirt
setblock ~150 ~123 ~152 dirt
setblock ~150 ~123 ~153 dirt
setblock ~150 ~123 ~154 dirt
setblock ~150 ~123 ~155 dirt
setblock ~150 ~123 ~156 dirt
setblock ~150 ~123 ~157 dirt
setblock ~150 ~123 ~158 dirt
setblock ~150 ~123 ~159 dirt
setblock ~150 ~123 ~160 dirt
setblock ~150 ~123 ~161 dirt
setblock ~150 ~123 ~162 dirt
setblock ~150 ~123 ~163 grass_block
setblock ~150 ~123 ~164 grass_block
setblock ~150 ~123 ~165 grass_block
setblock ~150 ~123 ~166 grass_block
setblock ~150 ~123 ~167 grass_block
setblock ~150 ~123 ~169 short_grass
setblock ~150 ~123 ~170 short_grass
setblock ~150 ~123 ~173 grass_block
setblock ~150 ~123 ~174 grass_block
setblock ~150 ~123 ~175 dirt
setblock ~150 ~123 ~176 dirt
setblock ~150 ~123 ~177 dirt
setblock ~150 ~123 ~178 dirt
setblock ~150 ~123 ~179 dirt
setblock ~150 ~123 ~180 dirt
setblock ~150 ~123 ~181 dirt
setblock ~150 ~123 ~182 dirt
