setblock ~28 ~117 ~88 dirt
setblock ~28 ~117 ~89 dirt
setblock ~28 ~117 ~90 dirt
setblock ~28 ~117 ~91 dirt
setblock ~28 ~117 ~92 dirt
setblock ~28 ~117 ~93 dirt
setblock ~28 ~117 ~94 dirt
setblock ~28 ~117 ~95 dirt
setblock ~28 ~117 ~96 dirt
setblock ~28 ~117 ~97 dirt
setblock ~28 ~117 ~98 dirt
setblock ~28 ~117 ~99 dirt
setblock ~28 ~117 ~100 dirt
setblock ~28 ~117 ~101 dirt
setblock ~28 ~117 ~102 dirt
setblock ~28 ~117 ~103 dirt
setblock ~28 ~117 ~104 dirt
setblock ~28 ~117 ~105 dirt
setblock ~28 ~117 ~106 dirt
setblock ~28 ~117 ~107 dirt
setblock ~28 ~117 ~108 dirt
setblock ~28 ~117 ~109 dirt
setblock ~28 ~117 ~110 dirt
setblock ~28 ~117 ~111 dirt
setblock ~28 ~118 ~81 dirt
setblock ~28 ~118 ~82 dirt
setblock ~28 ~118 ~83 dirt
setblock ~28 ~118 ~84 dirt
setblock ~28 ~118 ~85 dirt
setblock ~28 ~118 ~86 dirt
setblock ~28 ~118 ~87 dirt
setblock ~28 ~118 ~88 dirt
setblock ~28 ~118 ~89 dirt
setblock ~28 ~118 ~90 dirt
setblock ~28 ~118 ~91 dirt
setblock ~28 ~118 ~92 dirt
setblock ~28 ~118 ~93 dirt
setblock ~28 ~118 ~94 dirt
setblock ~28 ~118 ~95 dirt
setblock ~28 ~118 ~96 dirt
setblock ~28 ~118 ~97 dirt
setblock ~28 ~118 ~98 dirt
setblock ~28 ~118 ~99 dirt
setblock ~28 ~118 ~100 dirt
setblock ~28 ~118 ~101 dirt
setblock ~28 ~118 ~102 dirt
setblock ~28 ~118 ~103 dirt
setblock ~28 ~118 ~104 dirt
setblock ~28 ~118 ~105 dirt
setblock ~28 ~118 ~106 dirt
setblock ~28 ~118 ~107 dirt
setblock ~28 ~118 ~108 dirt
setblock ~28 ~118 ~109 dirt
setblock ~28 ~118 ~110 dirt
setblock ~28 ~118 ~111 dirt
setblock ~28 ~119 ~80 dirt
setblock ~28 ~119 ~81 dirt
setblock ~28 ~119 ~82 dirt
setblock ~28 ~119 ~83 dirt
setblock ~28 ~119 ~84 dirt
setblock ~28 ~119 ~85 dirt
setblock ~28 ~119 ~86 dirt
setblock ~28 ~119 ~87 dirt
setblock ~28 ~119 ~88 dirt
setblock ~28 ~119 ~89 dirt
setblock ~28 ~119 ~90 dirt
setblock ~28 ~119 ~91 dirt
setblock ~28 ~119 ~92 dirt
setblock ~28 ~119 ~93 dirt
setblock ~28 ~119 ~94 dirt
setblock ~28 ~119 ~95 dirt
setblock ~28 ~119 ~96 dirt
setblock ~28 ~119 ~97 dirt
setblock ~28 ~119 ~98 dirt
setblock ~28 ~119 ~99 dirt
setblock ~28 ~119 ~100 dirt
setblock ~28 ~119 ~101 dirt
setblock ~28 ~119 ~102 dirt
setblock ~28 ~119 ~103 dirt
setblock ~28 ~119 ~104 dirt
setblock ~28 ~119 ~105 dirt
setblock ~28 ~119 ~106 dirt
setblock ~28 ~119 ~107 dirt
setblock ~28 ~119 ~108 dirt
setblock ~28 ~119 ~109 dirt
setblock ~28 ~119 ~110 dirt
setblock ~28 ~119 ~111 dirt
setblock ~28 ~119 ~112 dirt
setblock ~28 ~119 ~113 dirt
setblock ~28 ~120 ~79 dirt
setblock ~28 ~120 ~80 dirt
setblock ~28 ~120 ~81 dirt
setblock ~28 ~120 ~82 dirt
setblock ~28 ~120 ~83 dirt
setblock ~28 ~120 ~84 dirt
setblock ~28 ~120 ~85 dirt
setblock ~28 ~120 ~86 dirt
setblock ~28 ~120 ~87 dirt
setblock ~28 ~120 ~88 dirt
setblock ~28 ~120 ~89 dirt
setblock ~28 ~120 ~90 dirt
setblock ~28 ~120 ~91 dirt
setblock ~28 ~120 ~92 dirt
setblock ~28 ~120 ~93 dirt
setblock ~28 ~120 ~94 dirt
setblock ~28 ~120 ~95 dirt
setblock ~28 ~120 ~96 dirt
setblock ~28 ~120 ~97 dirt
setblock ~28 ~120 ~98 dirt
setblock ~28 ~120 ~99 dirt
setblock ~28 ~120 ~100 dirt
setblock ~28 ~120 ~101 dirt
setblock ~28 ~120 ~102 dirt
setblock ~28 ~120 ~103 dirt
setblock ~28 ~120 ~104 dirt
setblock ~28 ~120 ~105 dirt
setblock ~28 ~120 ~106 dirt
setblock ~28 ~120 ~107 dirt
setblock ~28 ~120 ~108 dirt
setblock ~28 ~120 ~109 dirt
setblock ~28 ~120 ~110 dirt
setblock ~28 ~120 ~111 dirt
setblock ~28 ~120 ~112 dirt
setblock ~28 ~120 ~113 dirt
setblock ~28 ~121 ~79 dirt
setblock ~28 ~121 ~80 dirt
setblock ~28 ~121 ~81 dirt
setblock ~28 ~121 ~82 dirt
setblock ~28 ~121 ~83 dirt
setblock ~28 ~121 ~84 dirt
setblock ~28 ~121 ~85 dirt
setblock ~28 ~121 ~86 dirt
setblock ~28 ~121 ~87 dirt
setblock ~28 ~121 ~88 dirt
setblock ~28 ~121 ~89 dirt
setblock ~28 ~121 ~90 dirt
setblock ~28 ~121 ~91 dirt
setblock ~28 ~121 ~92 dirt
setblock ~28 ~121 ~93 dirt
setblock ~28 ~121 ~94 dirt
setblock ~28 ~121 ~95 dirt
setblock ~28 ~121 ~96 dirt
setblock ~28 ~121 ~97 dirt
setblock ~28 ~121 ~98 dirt
setblock ~28 ~121 ~99 dirt
setblock ~28 ~121 ~100 dirt
setblock ~28 ~121 ~101 dirt
setblock ~28 ~121 ~102 dirt
setblock ~28 ~121 ~103 dirt
setblock ~28 ~121 ~104 dirt
setblock ~28 ~121 ~105 dirt
setblock ~28 ~121 ~106 dirt
setblock ~28 ~121 ~107 dirt
setblock ~28 ~121 ~108 dirt
setblock ~28 ~121 ~109 dirt
setblock ~28 ~121 ~110 dirt
setblock ~28 ~121 ~111 dirt
setblock ~28 ~121 ~112 dirt
setblock ~28 ~121 ~113 dirt
setblock ~28 ~121 ~114 dirt
setblock ~28 ~121 ~115 dirt
setblock ~28 ~122 ~79 dirt
setblock ~28 ~122 ~80 dirt
setblock ~28 ~122 ~81 dirt
setblock ~28 ~122 ~82 dirt
setblock ~28 ~122 ~83 dirt
setblock ~28 ~122 ~84 dirt
setblock ~28 ~122 ~85 dirt
setblock ~28 ~122 ~86 dirt
setblock ~28 ~122 ~87 dirt
setblock ~28 ~122 ~88 dirt
setblock ~28 ~122 ~89 dirt
setblock ~28 ~122 ~90 dirt
setblock ~28 ~122 ~91 dirt
setblock ~28 ~122 ~92 dirt
setblock ~28 ~122 ~93 dirt
setblock ~28 ~122 ~94 dirt
setblock ~28 ~122 ~95 dirt
setblock ~28 ~122 ~96 dirt
setblock ~28 ~122 ~97 dirt
setblock ~28 ~122 ~98 dirt
setblock ~28 ~122 ~99 dirt
setblock ~28 ~122 ~100 dirt
setblock ~28 ~122 ~101 dirt
setblock ~28 ~122 ~102 dirt
setblock ~28 ~122 ~103 dirt
setblock ~28 ~122 ~104 dirt
setblock ~28 ~122 ~105 dirt
setblock ~28 ~122 ~106 dirt
setblock ~28 ~122 ~107 dirt
setblock ~28 ~122 ~108 dirt
setblock ~28 ~122 ~109 dirt
setblock ~28 ~122 ~110 dirt
setblock ~28 ~122 ~111 dirt
setblock ~28 ~122 ~112 dirt
setblock ~28 ~122 ~113 dirt
setblock ~28 ~122 ~114 dirt
setblock ~28 ~122 ~115 dirt
setblock ~28 ~123 ~79 dirt
setblock ~28 ~123 ~80 dirt
setblock ~28 ~123 ~81 dirt
setblock ~28 ~123 ~82 dirt
setblock ~28 ~123 ~83 dirt
setblock ~28 ~123 ~84 dirt
setblock ~28 ~123 ~85 dirt
setblock ~28 ~123 ~86 dirt
setblock ~28 ~123 ~87 dirt
setblock ~28 ~123 ~88 dirt
setblock ~28 ~123 ~89 dirt
setblock ~28 ~123 ~90 dirt
setblock ~28 ~123 ~91 dirt
setblock ~28 ~123 ~92 dirt
setblock ~28 ~123 ~93 dirt
setblock ~28 ~123 ~94 dirt
setblock ~28 ~123 ~95 dirt
setblock ~28 ~123 ~96 dirt
setblock ~28 ~123 ~97 dirt
setblock ~28 ~123 ~98 dirt
setblock ~28 ~123 ~99 dirt
setblock ~28 ~123 ~100 dirt
setblock ~28 ~123 ~101 dirt
setblock ~28 ~123 ~102 dirt
setblock ~28 ~123 ~103 dirt
setblock ~28 ~123 ~104 dirt
setblock ~28 ~123 ~105 dirt
setblock ~28 ~123 ~106 dirt
setblock ~28 ~123 ~107 dirt
setblock ~28 ~123 ~108 dirt
setblock ~28 ~123 ~109 dirt
setblock ~28 ~123 ~110 dirt
setblock ~28 ~123 ~111 dirt
setblock ~28 ~123 ~112 dirt
setblock ~28 ~123 ~113 dirt
setblock ~28 ~123 ~114 dirt
setblock ~28 ~123 ~115 dirt
setblock ~28 ~124 ~79 dirt
setblock ~28 ~124 ~80 dirt
setblock ~28 ~124 ~81 dirt
setblock ~28 ~124 ~82 dirt
setblock ~28 ~124 ~83 dirt
setblock ~28 ~124 ~84 dirt
setblock ~28 ~124 ~85 dirt
setblock ~28 ~124 ~86 dirt
setblock ~28 ~124 ~87 dirt
setblock ~28 ~124 ~88 dirt
setblock ~28 ~124 ~89 dirt
setblock ~28 ~124 ~90 dirt
setblock ~28 ~124 ~91 dirt
setblock ~28 ~124 ~92 dirt
setblock ~28 ~124 ~93 dirt
setblock ~28 ~124 ~94 dirt
setblock ~28 ~124 ~95 dirt
setblock ~28 ~124 ~96 dirt
setblock ~28 ~124 ~97 dirt
setblock ~28 ~124 ~98 dirt
setblock ~28 ~124 ~99 dirt
setblock ~28 ~124 ~100 dirt
setblock ~28 ~124 ~101 dirt
setblock ~28 ~124 ~102 dirt
setblock ~28 ~124 ~103 dirt
setblock ~28 ~124 ~104 dirt
setblock ~28 ~124 ~105 dirt
setblock ~28 ~124 ~106 dirt
setblock ~28 ~124 ~107 dirt
setblock ~28 ~124 ~108 dirt
setblock ~28 ~124 ~109 dirt
setblock ~28 ~124 ~110 dirt
setblock ~28 ~124 ~111 dirt
setblock ~28 ~124 ~112 dirt
setblock ~28 ~124 ~113 dirt
setblock ~28 ~124 ~114 dirt
setblock ~28 ~124 ~115 dirt
setblock ~28 ~125 ~79 grass_block
setblock ~28 ~125 ~80 grass_block
setblock ~28 ~125 ~81 grass_block
setblock ~28 ~125 ~82 grass_block
setblock ~28 ~125 ~83 grass_block
setblock ~28 ~125 ~84 dirt
setblock ~28 ~125 ~85 dirt
setblock ~28 ~125 ~86 dirt
setblock ~28 ~125 ~87 dirt
setblock ~28 ~125 ~88 dirt
setblock ~28 ~125 ~89 dirt
setblock ~28 ~125 ~90 dirt
setblock ~28 ~125 ~91 dirt
setblock ~28 ~125 ~92 dirt
setblock ~28 ~125 ~93 dirt
setblock ~28 ~125 ~94 dirt
setblock ~28 ~125 ~95 dirt
setblock ~28 ~125 ~96 dirt
setblock ~28 ~125 ~97 dirt
setblock ~28 ~125 ~98 dirt
setblock ~28 ~125 ~99 dirt
setblock ~28 ~125 ~100 grass_block
setblock ~28 ~125 ~101 dirt
setblock ~28 ~125 ~102 dirt
setblock ~28 ~125 ~103 dirt
setblock ~28 ~125 ~104 dirt
setblock ~28 ~125 ~105 dirt
setblock ~28 ~125 ~106 dirt
setblock ~28 ~125 ~107 dirt
setblock ~28 ~125 ~108 dirt
setblock ~28 ~125 ~109 dirt
setblock ~28 ~125 ~110 dirt
setblock ~28 ~125 ~111 dirt
setblock ~28 ~125 ~112 dirt
setblock ~28 ~125 ~113 dirt
setblock ~28 ~125 ~114 dirt
setblock ~28 ~125 ~115 dirt
setblock ~28 ~126 ~79 short_grass
setblock ~28 ~126 ~81 short_grass
setblock ~28 ~126 ~84 grass_block
setblock ~28 ~126 ~85 grass_block
setblock ~28 ~126 ~86 grass_block
setblock ~28 ~126 ~87 grass_block
setblock ~28 ~126 ~88 grass_block
setblock ~28 ~126 ~89 dirt
setblock ~28 ~126 ~90 dirt
setblock ~28 ~126 ~91 dirt
setblock ~28 ~126 ~92 dirt
setblock ~28 ~126 ~93 grass_block
setblock ~28 ~126 ~94 grass_block
setblock ~28 ~126 ~95 grass_block
setblock ~28 ~126 ~96 grass_block
setblock ~28 ~126 ~97 grass_block
setblock ~28 ~126 ~98 grass_block
setblock ~28 ~126 ~99 grass_block
setblock ~28 ~126 ~101 grass_block
setblock ~28 ~126 ~102 grass_block
setblock ~28 ~126 ~103 grass_block
setblock ~28 ~126 ~104 dirt
setblock ~28 ~126 ~105 dirt
setblock ~28 ~126 ~106 dirt
setblock ~28 ~126 ~107 dirt
setblock ~28 ~126 ~108 dirt
setblock ~28 ~126 ~109 dirt
setblock ~28 ~126 ~110 dirt
setblock ~28 ~126 ~111 dirt
setblock ~28 ~126 ~112 dirt
setblock ~28 ~126 ~113 dirt
setblock ~28 ~126 ~114 grass_block
setblock ~28 ~126 ~115 grass_block
setblock ~28 ~127 ~84 short_grass
setblock ~28 ~127 ~85 short_grass
setblock ~28 ~127 ~89 grass_block
setblock ~28 ~127 ~90 grass_block
setblock ~28 ~127 ~91 grass_block
setblock ~28 ~127 ~92 grass_block
setblock ~28 ~127 ~93 poppy
setblock ~28 ~127 ~97 short_grass
setblock ~28 ~127 ~98 fern
setblock ~28 ~127 ~101 short_grass
setblock ~28 ~127 ~102 short_grass
setblock ~28 ~127 ~104 grass_block
setblock ~28 ~127 ~105 grass_block
setblock ~28 ~127 ~106 grass_block
setblock ~28 ~127 ~107 grass_block
setblock ~28 ~127 ~108 dirt
setblock ~28 ~127 ~109 dirt
setblock ~28 ~127 ~110 dirt
setblock ~28 ~127 ~111 dirt
setblock ~28 ~127 ~112 grass_block
setblock ~28 ~127 ~113 grass_block
setblock ~28 ~128 ~90 short_grass
setblock ~28 ~128 ~105 poppy
setblock ~28 ~128 ~106 short_grass
setblock ~28 ~128 ~108 grass_block
setblock ~28 ~128 ~109 grass_block
setblock ~28 ~128 ~110 grass_block
setblock ~28 ~128 ~111 grass_block
setblock ~28 ~129 ~108 short_grass
setblock ~28 ~129 ~111 short_grass
setblock ~29 ~103 ~99 dirt
setblock ~29 ~104 ~98 dirt
setblock ~29 ~104 ~99 dirt
setblock ~29 ~104 ~100 dirt
setblock ~29 ~105 ~98 dirt
setblock ~29 ~105 ~99 dirt
setblock ~29 ~105 ~100 dirt
setblock ~29 ~105 ~102 dirt
setblock ~29 ~106 ~92 dirt
setblock ~29 ~106 ~95 dirt
setblock ~29 ~106 ~96 dirt
setblock ~29 ~106 ~97 dirt
setblock ~29 ~106 ~98 dirt
setblock ~29 ~106 ~99 dirt
setblock ~29 ~106 ~100 dirt
setblock ~29 ~106 ~101 dirt
setblock ~29 ~106 ~102 dirt
setblock ~29 ~107 ~90 dirt
setblock ~29 ~107 ~92 dirt
setblock ~29 ~107 ~94 dirt
setblock ~29 ~107 ~95 dirt
setblock ~29 ~107 ~96 dirt
setblock ~29 ~107 ~97 dirt
setblock ~29 ~107 ~98 dirt
setblock ~29 ~107 ~99 dirt
setblock ~29 ~107 ~100 dirt
setblock ~29 ~107 ~101 dirt
setblock ~29 ~107 ~102 dirt
setblock ~29 ~108 ~87 dirt
setblock ~29 ~108 ~89 dirt
setblock ~29 ~108 ~90 dirt
setblock ~29 ~108 ~91 dirt
setblock ~29 ~108 ~92 dirt
setblock ~29 ~108 ~93 dirt
setblock ~29 ~108 ~94 dirt
setblock ~29 ~108 ~95 dirt
setblock ~29 ~108 ~96 dirt
setblock ~29 ~108 ~97 dirt
setblock ~29 ~108 ~98 dirt
setblock ~29 ~108 ~99 dirt
setblock ~29 ~108 ~100 dirt
setblock ~29 ~108 ~101 dirt
setblock ~29 ~108 ~102 dirt
setblock ~29 ~108 ~103 dirt
setblock ~29 ~109 ~86 dirt
setblock ~29 ~109 ~87 dirt
setblock ~29 ~109 ~88 dirt
setblock ~29 ~109 ~89 dirt
setblock ~29 ~109 ~90 dirt
setblock ~29 ~109 ~91 dirt
setblock ~29 ~109 ~92 dirt
setblock ~29 ~109 ~93 dirt
setblock ~29 ~109 ~94 dirt
setblock ~29 ~109 ~95 dirt
setblock ~29 ~109 ~96 dirt
setblock ~29 ~109 ~97 dirt
setblock ~29 ~109 ~98 dirt
setblock ~29 ~109 ~99 dirt
setblock ~29 ~109 ~100 dirt
setblock ~29 ~109 ~101 dirt
setblock ~29 ~109 ~102 dirt
setblock ~29 ~109 ~103 dirt
setblock ~29 ~109 ~104 dirt
setblock ~29 ~109 ~105 dirt
setblock ~29 ~110 ~85 dirt
setblock ~29 ~110 ~86 dirt
setblock ~29 ~110 ~87 dirt
setblock ~29 ~110 ~88 dirt
setblock ~29 ~110 ~89 dirt
setblock ~29 ~110 ~90 dirt
setblock ~29 ~110 ~91 dirt
setblock ~29 ~110 ~92 dirt
setblock ~29 ~110 ~93 dirt
setblock ~29 ~110 ~94 dirt
setblock ~29 ~110 ~95 dirt
setblock ~29 ~110 ~96 dirt
setblock ~29 ~110 ~97 dirt
setblock ~29 ~110 ~98 dirt
setblock ~29 ~110 ~99 dirt
setblock ~29 ~110 ~100 dirt
setblock ~29 ~110 ~101 dirt
setblock ~29 ~110 ~102 dirt
setblock ~29 ~110 ~103 dirt
setblock ~29 ~110 ~104 dirt
setblock ~29 ~110 ~105 dirt
setblock ~29 ~110 ~106 dirt
setblock ~29 ~111 ~85 dirt
setblock ~29 ~111 ~86 dirt
setblock ~29 ~111 ~87 dirt
setblock ~29 ~111 ~88 dirt
setblock ~29 ~111 ~89 dirt
setblock ~29 ~111 ~90 dirt
setblock ~29 ~111 ~91 dirt
setblock ~29 ~111 ~92 dirt
setblock ~29 ~111 ~93 dirt
setblock ~29 ~111 ~94 dirt
setblock ~29 ~111 ~95 dirt
setblock ~29 ~111 ~96 dirt
setblock ~29 ~111 ~97 dirt
setblock ~29 ~111 ~98 dirt
setblock ~29 ~111 ~99 dirt
setblock ~29 ~111 ~100 dirt
setblock ~29 ~111 ~101 dirt
setblock ~29 ~111 ~102 dirt
setblock ~29 ~111 ~103 dirt
setblock ~29 ~111 ~104 dirt
setblock ~29 ~111 ~105 dirt
setblock ~29 ~111 ~106 dirt
setblock ~29 ~111 ~108 dirt
setblock ~29 ~111 ~109 dirt
setblock ~29 ~112 ~84 dirt
setblock ~29 ~112 ~85 dirt
setblock ~29 ~112 ~86 dirt
setblock ~29 ~112 ~87 dirt
setblock ~29 ~112 ~88 dirt
setblock ~29 ~112 ~89 dirt
setblock ~29 ~112 ~90 dirt
setblock ~29 ~112 ~91 dirt
setblock ~29 ~112 ~92 dirt
setblock ~29 ~112 ~93 dirt
setblock ~29 ~112 ~94 dirt
setblock ~29 ~112 ~95 dirt
setblock ~29 ~112 ~96 dirt
setblock ~29 ~112 ~97 dirt
setblock ~29 ~112 ~98 dirt
setblock ~29 ~112 ~99 dirt
setblock ~29 ~112 ~100 dirt
setblock ~29 ~112 ~101 dirt
setblock ~29 ~112 ~102 dirt
setblock ~29 ~112 ~103 dirt
setblock ~29 ~112 ~104 dirt
setblock ~29 ~112 ~105 dirt
setblock ~29 ~112 ~106 dirt
setblock ~29 ~112 ~107 dirt
setblock ~29 ~112 ~108 dirt
setblock ~29 ~112 ~109 dirt
setblock ~29 ~112 ~110 dirt
setblock ~29 ~113 ~83 dirt
setblock ~29 ~113 ~84 dirt
setblock ~29 ~113 ~85 dirt
setblock ~29 ~113 ~86 dirt
setblock ~29 ~113 ~87 dirt
setblock ~29 ~113 ~88 dirt
setblock ~29 ~113 ~89 dirt
setblock ~29 ~113 ~90 dirt
setblock ~29 ~113 ~91 dirt
setblock ~29 ~113 ~92 dirt
setblock ~29 ~113 ~93 dirt
setblock ~29 ~113 ~94 dirt
setblock ~29 ~113 ~95 dirt
setblock ~29 ~113 ~96 dirt
setblock ~29 ~113 ~97 dirt
setblock ~29 ~113 ~98 dirt
setblock ~29 ~113 ~99 dirt
setblock ~29 ~113 ~100 dirt
setblock ~29 ~113 ~101 dirt
setblock ~29 ~113 ~102 dirt
setblock ~29 ~113 ~103 dirt
setblock ~29 ~113 ~104 dirt
setblock ~29 ~113 ~105 dirt
setblock ~29 ~113 ~106 dirt
setblock ~29 ~113 ~107 dirt
setblock ~29 ~113 ~108 dirt
setblock ~29 ~113 ~109 dirt
setblock ~29 ~113 ~110 dirt
setblock ~29 ~114 ~83 dirt
setblock ~29 ~114 ~84 dirt
setblock ~29 ~114 ~85 dirt
setblock ~29 ~114 ~86 dirt
setblock ~29 ~114 ~87 dirt
setblock ~29 ~114 ~88 dirt
setblock ~29 ~114 ~89 dirt
setblock ~29 ~114 ~90 dirt
setblock ~29 ~114 ~91 dirt
setblock ~29 ~114 ~92 dirt
setblock ~29 ~114 ~93 dirt
setblock ~29 ~114 ~94 dirt
setblock ~29 ~114 ~95 dirt
setblock ~29 ~114 ~96 dirt
setblock ~29 ~114 ~97 dirt
setblock ~29 ~114 ~98 dirt
setblock ~29 ~114 ~99 dirt
setblock ~29 ~114 ~100 dirt
setblock ~29 ~114 ~101 dirt
setblock ~29 ~114 ~102 dirt
setblock ~29 ~114 ~103 dirt
setblock ~29 ~114 ~104 dirt
setblock ~29 ~114 ~105 dirt
setblock ~29 ~114 ~106 dirt
setblock ~29 ~114 ~107 dirt
setblock ~29 ~114 ~108 dirt
setblock ~29 ~114 ~109 dirt
setblock ~29 ~114 ~110 dirt
setblock ~29 ~115 ~82 dirt
setblock ~29 ~115 ~83 dirt
setblock ~29 ~115 ~84 dirt
setblock ~29 ~115 ~85 dirt
setblock ~29 ~115 ~86 dirt
setblock ~29 ~115 ~87 dirt
setblock ~29 ~115 ~88 dirt
setblock ~29 ~115 ~89 dirt
setblock ~29 ~115 ~90 dirt
setblock ~29 ~115 ~91 dirt
setblock ~29 ~115 ~92 dirt
setblock ~29 ~115 ~93 dirt
setblock ~29 ~115 ~94 dirt
setblock ~29 ~115 ~95 dirt
setblock ~29 ~115 ~96 dirt
setblock ~29 ~115 ~97 dirt
setblock ~29 ~115 ~98 dirt
setblock ~29 ~115 ~99 dirt
setblock ~29 ~115 ~100 dirt
setblock ~29 ~115 ~101 dirt
setblock ~29 ~115 ~102 dirt
setblock ~29 ~115 ~103 dirt
setblock ~29 ~115 ~104 dirt
setblock ~29 ~115 ~105 dirt
setblock ~29 ~115 ~106 dirt
setblock ~29 ~115 ~107 dirt
setblock ~29 ~115 ~108 dirt
setblock ~29 ~115 ~109 dirt
setblock ~29 ~115 ~110 dirt
setblock ~29 ~115 ~111 dirt
setblock ~29 ~116 ~82 dirt
setblock ~29 ~116 ~83 dirt
setblock ~29 ~116 ~84 dirt
setblock ~29 ~116 ~85 dirt
setblock ~29 ~116 ~86 dirt
setblock ~29 ~116 ~87 dirt
setblock ~29 ~116 ~88 dirt
setblock ~29 ~116 ~89 dirt
setblock ~29 ~116 ~90 dirt
setblock ~29 ~116 ~91 dirt
setblock ~29 ~116 ~92 dirt
setblock ~29 ~116 ~93 dirt
setblock ~29 ~116 ~94 dirt
setblock ~29 ~116 ~95 dirt
setblock ~29 ~116 ~96 dirt
setblock ~29 ~116 ~97 dirt
setblock ~29 ~116 ~98 dirt
setblock ~29 ~116 ~99 dirt
setblock ~29 ~116 ~100 dirt
setblock ~29 ~116 ~101 dirt
setblock ~29 ~116 ~102 dirt
setblock ~29 ~116 ~103 dirt
setblock ~29 ~116 ~104 dirt
setblock ~29 ~116 ~105 dirt
setblock ~29 ~116 ~106 dirt
setblock ~29 ~116 ~107 dirt
setblock ~29 ~116 ~108 dirt
setblock ~29 ~116 ~109 dirt
setblock ~29 ~116 ~110 dirt
setblock ~29 ~116 ~111 dirt
setblock ~29 ~117 ~81 dirt
setblock ~29 ~117 ~82 dirt
setblock ~29 ~117 ~83 dirt
setblock ~29 ~117 ~84 dirt
setblock ~29 ~117 ~85 dirt
setblock ~29 ~117 ~86 dirt
setblock ~29 ~117 ~87 dirt
setblock ~29 ~117 ~88 dirt
setblock ~29 ~117 ~89 dirt
setblock ~29 ~117 ~90 dirt
setblock ~29 ~117 ~91 dirt
setblock ~29 ~117 ~92 dirt
setblock ~29 ~117 ~93 dirt
setblock ~29 ~117 ~94 dirt
setblock ~29 ~117 ~95 dirt
setblock ~29 ~117 ~96 dirt
setblock ~29 ~117 ~97 dirt
setblock ~29 ~117 ~98 dirt
setblock ~29 ~117 ~99 dirt
setblock ~29 ~117 ~100 dirt
setblock ~29 ~117 ~101 dirt
setblock ~29 ~117 ~102 dirt
setblock ~29 ~117 ~103 dirt
setblock ~29 ~117 ~104 dirt
setblock ~29 ~117 ~105 dirt
setblock ~29 ~117 ~106 dirt
setblock ~29 ~117 ~107 dirt
setblock ~29 ~117 ~108 dirt
setblock ~29 ~117 ~109 dirt
setblock ~29 ~117 ~110 dirt
setblock ~29 ~117 ~111 dirt
setblock ~29 ~117 ~113 dirt
setblock ~29 ~118 ~80 dirt
setblock ~29 ~118 ~81 dirt
setblock ~29 ~118 ~82 dirt
setblock ~29 ~118 ~83 dirt
setblock ~29 ~118 ~84 dirt
setblock ~29 ~118 ~85 dirt
setblock ~29 ~118 ~86 dirt
setblock ~29 ~118 ~87 dirt
setblock ~29 ~118 ~88 dirt
setblock ~29 ~118 ~89 dirt
setblock ~29 ~118 ~90 dirt
setblock ~29 ~118 ~91 dirt
setblock ~29 ~118 ~92 dirt
setblock ~29 ~118 ~93 dirt
setblock ~29 ~118 ~94 dirt
setblock ~29 ~118 ~95 dirt
setblock ~29 ~118 ~96 dirt
setblock ~29 ~118 ~97 dirt
setblock ~29 ~118 ~98 dirt
setblock ~29 ~118 ~99 dirt
setblock ~29 ~118 ~100 dirt
setblock ~29 ~118 ~101 dirt
setblock ~29 ~118 ~102 dirt
setblock ~29 ~118 ~103 dirt
setblock ~29 ~118 ~104 dirt
setblock ~29 ~118 ~105 dirt
setblock ~29 ~118 ~106 dirt
setblock ~29 ~118 ~107 dirt
setblock ~29 ~118 ~108 dirt
setblock ~29 ~118 ~109 dirt
setblock ~29 ~118 ~110 dirt
setblock ~29 ~118 ~111 dirt
setblock ~29 ~118 ~112 dirt
setblock ~29 ~118 ~113 dirt
setblock ~29 ~119 ~79 dirt
setblock ~29 ~119 ~80 dirt
setblock ~29 ~119 ~81 dirt
setblock ~29 ~119 ~82 dirt
setblock ~29 ~119 ~83 dirt
setblock ~29 ~119 ~84 dirt
setblock ~29 ~119 ~85 dirt
setblock ~29 ~119 ~86 dirt
setblock ~29 ~119 ~87 dirt
setblock ~29 ~119 ~88 dirt
setblock ~29 ~119 ~89 dirt
setblock ~29 ~119 ~90 dirt
setblock ~29 ~119 ~91 dirt
setblock ~29 ~119 ~92 dirt
setblock ~29 ~119 ~93 dirt
setblock ~29 ~119 ~94 dirt
setblock ~29 ~119 ~95 dirt
setblock ~29 ~119 ~96 dirt
setblock ~29 ~119 ~97 dirt
setblock ~29 ~119 ~98 dirt
setblock ~29 ~119 ~99 dirt
setblock ~29 ~119 ~100 dirt
setblock ~29 ~119 ~101 dirt
setblock ~29 ~119 ~102 dirt
setblock ~29 ~119 ~103 dirt
setblock ~29 ~119 ~104 dirt
setblock ~29 ~119 ~105 dirt
setblock ~29 ~119 ~106 dirt
setblock ~29 ~119 ~107 dirt
setblock ~29 ~119 ~108 dirt
setblock ~29 ~119 ~109 dirt
setblock ~29 ~119 ~110 dirt
setblock ~29 ~119 ~111 dirt
setblock ~29 ~119 ~112 dirt
setblock ~29 ~119 ~113 dirt
setblock ~29 ~119 ~114 dirt
setblock ~29 ~120 ~78 dirt
setblock ~29 ~120 ~79 dirt
setblock ~29 ~120 ~80 dirt
setblock ~29 ~120 ~81 dirt
setblock ~29 ~120 ~82 dirt
setblock ~29 ~120 ~83 dirt
setblock ~29 ~120 ~84 dirt
setblock ~29 ~120 ~85 dirt
setblock ~29 ~120 ~86 dirt
setblock ~29 ~120 ~87 dirt
setblock ~29 ~120 ~88 dirt
setblock ~29 ~120 ~89 dirt
setblock ~29 ~120 ~90 dirt
setblock ~29 ~120 ~91 dirt
setblock ~29 ~120 ~92 dirt
setblock ~29 ~120 ~93 dirt
setblock ~29 ~120 ~94 dirt
setblock ~29 ~120 ~95 dirt
setblock ~29 ~120 ~96 dirt
setblock ~29 ~120 ~97 dirt
setblock ~29 ~120 ~98 dirt
setblock ~29 ~120 ~99 dirt
setblock ~29 ~120 ~100 dirt
setblock ~29 ~120 ~101 dirt
setblock ~29 ~120 ~102 dirt
setblock ~29 ~120 ~103 dirt
setblock ~29 ~120 ~104 dirt
setblock ~29 ~120 ~105 dirt
setblock ~29 ~120 ~106 dirt
setblock ~29 ~120 ~107 dirt
setblock ~29 ~120 ~108 dirt
setblock ~29 ~120 ~109 dirt
setblock ~29 ~120 ~110 dirt
setblock ~29 ~120 ~111 dirt
setblock ~29 ~120 ~112 dirt
setblock ~29 ~120 ~113 dirt
setblock ~29 ~120 ~114 dirt
setblock ~29 ~120 ~115 dirt
setblock ~29 ~120 ~117 dirt
setblock ~29 ~121 ~78 dirt
setblock ~29 ~121 ~79 dirt
setblock ~29 ~121 ~80 dirt
setblock ~29 ~121 ~81 dirt
setblock ~29 ~121 ~82 dirt
setblock ~29 ~121 ~83 dirt
setblock ~29 ~121 ~84 dirt
setblock ~29 ~121 ~85 dirt
setblock ~29 ~121 ~86 dirt
setblock ~29 ~121 ~87 dirt
setblock ~29 ~121 ~88 dirt
setblock ~29 ~121 ~89 dirt
setblock ~29 ~121 ~90 dirt
setblock ~29 ~121 ~91 dirt
setblock ~29 ~121 ~92 dirt
setblock ~29 ~121 ~93 dirt
setblock ~29 ~121 ~94 dirt
setblock ~29 ~121 ~95 dirt
setblock ~29 ~121 ~96 dirt
setblock ~29 ~121 ~97 dirt
setblock ~29 ~121 ~98 dirt
setblock ~29 ~121 ~99 dirt
setblock ~29 ~121 ~100 dirt
setblock ~29 ~121 ~101 dirt
setblock ~29 ~121 ~102 dirt
setblock ~29 ~121 ~103 dirt
setblock ~29 ~121 ~104 dirt
setblock ~29 ~121 ~105 dirt
setblock ~29 ~121 ~106 dirt
setblock ~29 ~121 ~107 dirt
setblock ~29 ~121 ~108 dirt
setblock ~29 ~121 ~109 dirt
setblock ~29 ~121 ~110 dirt
setblock ~29 ~121 ~111 dirt
setblock ~29 ~121 ~112 dirt
setblock ~29 ~121 ~113 dirt
setblock ~29 ~121 ~114 dirt
setblock ~29 ~121 ~115 dirt
setblock ~29 ~121 ~116 dirt
setblock ~29 ~121 ~117 dirt
setblock ~29 ~121 ~118 dirt
setblock ~29 ~122 ~78 dirt
setblock ~29 ~122 ~79 dirt
setblock ~29 ~122 ~80 dirt
setblock ~29 ~122 ~81 dirt
setblock ~29 ~122 ~82 dirt
setblock ~29 ~122 ~83 dirt
setblock ~29 ~122 ~84 dirt
setblock ~29 ~122 ~85 dirt
setblock ~29 ~122 ~86 dirt
setblock ~29 ~122 ~87 dirt
setblock ~29 ~122 ~88 dirt
setblock ~29 ~122 ~89 dirt
setblock ~29 ~122 ~90 dirt
setblock ~29 ~122 ~91 dirt
setblock ~29 ~122 ~92 dirt
setblock ~29 ~122 ~93 dirt
setblock ~29 ~122 ~94 dirt
setblock ~29 ~122 ~95 dirt
setblock ~29 ~122 ~96 dirt
setblock ~29 ~122 ~97 dirt
setblock ~29 ~122 ~98 dirt
setblock ~29 ~122 ~99 dirt
setblock ~29 ~122 ~100 dirt
setblock ~29 ~122 ~101 dirt
setblock ~29 ~122 ~102 dirt
setblock ~29 ~122 ~103 dirt
setblock ~29 ~122 ~104 dirt
setblock ~29 ~122 ~105 dirt
setblock ~29 ~122 ~106 dirt
setblock ~29 ~122 ~107 dirt
setblock ~29 ~122 ~108 dirt
setblock ~29 ~122 ~109 dirt
setblock ~29 ~122 ~110 dirt
setblock ~29 ~122 ~111 dirt
setblock ~29 ~122 ~112 dirt
setblock ~29 ~122 ~113 dirt
setblock ~29 ~122 ~114 dirt
setblock ~29 ~122 ~115 dirt
setblock ~29 ~122 ~116 dirt
setblock ~29 ~122 ~117 dirt
setblock ~29 ~122 ~118 dirt
setblock ~29 ~123 ~78 dirt
setblock ~29 ~123 ~79 dirt
setblock ~29 ~123 ~80 dirt
setblock ~29 ~123 ~81 dirt
setblock ~29 ~123 ~82 dirt
setblock ~29 ~123 ~83 dirt
setblock ~29 ~123 ~84 dirt
setblock ~29 ~123 ~85 dirt
setblock ~29 ~123 ~86 dirt
setblock ~29 ~123 ~87 dirt
setblock ~29 ~123 ~88 dirt
setblock ~29 ~123 ~89 dirt
setblock ~29 ~123 ~90 dirt
setblock ~29 ~123 ~91 dirt
setblock ~29 ~123 ~92 dirt
setblock ~29 ~123 ~93 dirt
setblock ~29 ~123 ~94 dirt
setblock ~29 ~123 ~95 dirt
setblock ~29 ~123 ~96 dirt
setblock ~29 ~123 ~97 dirt
setblock ~29 ~123 ~98 dirt
setblock ~29 ~123 ~99 dirt
setblock ~29 ~123 ~100 dirt
setblock ~29 ~123 ~101 dirt
setblock ~29 ~123 ~102 dirt
setblock ~29 ~123 ~103 dirt
setblock ~29 ~123 ~104 dirt
setblock ~29 ~123 ~105 dirt
setblock ~29 ~123 ~106 dirt
setblock ~29 ~123 ~107 dirt
setblock ~29 ~123 ~108 dirt
setblock ~29 ~123 ~109 dirt
setblock ~29 ~123 ~110 dirt
setblock ~29 ~123 ~111 dirt
setblock ~29 ~123 ~112 dirt
setblock ~29 ~123 ~113 dirt
setblock ~29 ~123 ~114 dirt
setblock ~29 ~123 ~115 dirt
setblock ~29 ~123 ~116 dirt
setblock ~29 ~123 ~117 dirt
setblock ~29 ~123 ~118 dirt
setblock ~29 ~124 ~78 dirt
setblock ~29 ~124 ~79 dirt
setblock ~29 ~124 ~80 dirt
setblock ~29 ~124 ~81 dirt
setblock ~29 ~124 ~82 dirt
setblock ~29 ~124 ~83 dirt
setblock ~29 ~124 ~84 dirt
setblock ~29 ~124 ~85 dirt
setblock ~29 ~124 ~86 dirt
setblock ~29 ~124 ~87 dirt
setblock ~29 ~124 ~88 dirt
setblock ~29 ~124 ~89 dirt
setblock ~29 ~124 ~90 dirt
setblock ~29 ~124 ~91 dirt
setblock ~29 ~124 ~92 dirt
setblock ~29 ~124 ~93 dirt
setblock ~29 ~124 ~94 dirt
setblock ~29 ~124 ~95 dirt
setblock ~29 ~124 ~96 dirt
setblock ~29 ~124 ~97 dirt
setblock ~29 ~124 ~98 dirt
setblock ~29 ~124 ~99 dirt
setblock ~29 ~124 ~100 dirt
setblock ~29 ~124 ~101 dirt
setblock ~29 ~124 ~102 dirt
setblock ~29 ~124 ~103 dirt
setblock ~29 ~124 ~104 dirt
setblock ~29 ~124 ~105 dirt
setblock ~29 ~124 ~106 dirt
setblock ~29 ~124 ~107 dirt
setblock ~29 ~124 ~108 dirt
setblock ~29 ~124 ~109 dirt
setblock ~29 ~124 ~110 dirt
setblock ~29 ~124 ~111 dirt
setblock ~29 ~124 ~112 dirt
setblock ~29 ~124 ~113 dirt
setblock ~29 ~124 ~114 dirt
setblock ~29 ~124 ~115 dirt
setblock ~29 ~124 ~116 dirt
setblock ~29 ~124 ~117 dirt
setblock ~29 ~124 ~118 dirt
setblock ~29 ~125 ~78 grass_block
setblock ~29 ~125 ~79 grass_block
setblock ~29 ~125 ~80 grass_block
setblock ~29 ~125 ~81 grass_block
setblock ~29 ~125 ~82 grass_block
setblock ~29 ~125 ~83 grass_block
setblock ~29 ~125 ~84 grass_block
setblock ~29 ~125 ~85 dirt
setblock ~29 ~125 ~86 dirt
setblock ~29 ~125 ~87 dirt
setblock ~29 ~125 ~88 dirt
setblock ~29 ~125 ~89 dirt
setblock ~29 ~125 ~90 dirt
setblock ~29 ~125 ~91 dirt
setblock ~29 ~125 ~92 dirt
setblock ~29 ~125 ~93 dirt
setblock ~29 ~125 ~94 dirt
setblock ~29 ~125 ~95 dirt
setblock ~29 ~125 ~96 dirt
setblock ~29 ~125 ~97 dirt
setblock ~29 ~125 ~98 dirt
setblock ~29 ~125 ~99 dirt
setblock ~29 ~125 ~100 dirt
setblock ~29 ~125 ~101 dirt
setblock ~29 ~125 ~102 dirt
setblock ~29 ~125 ~103 dirt
setblock ~29 ~125 ~104 dirt
setblock ~29 ~125 ~105 dirt
setblock ~29 ~125 ~106 dirt
setblock ~29 ~125 ~107 dirt
setblock ~29 ~125 ~108 dirt
setblock ~29 ~125 ~109 dirt
setblock ~29 ~125 ~110 dirt
setblock ~29 ~125 ~111 dirt
setblock ~29 ~125 ~112 dirt
setblock ~29 ~125 ~113 dirt
setblock ~29 ~125 ~114 dirt
setblock ~29 ~125 ~115 dirt
setblock ~29 ~125 ~116 grass_block
setblock ~29 ~125 ~117 grass_block
setblock ~29 ~125 ~118 grass_block
setblock ~29 ~126 ~78 fern
setblock ~29 ~126 ~81 short_grass
setblock ~29 ~126 ~85 grass_block
setblock ~29 ~126 ~86 grass_block
setblock ~29 ~126 ~87 grass_block
setblock ~29 ~126 ~88 dirt
setblock ~29 ~126 ~89 dirt
setblock ~29 ~126 ~90 dirt
setblock ~29 ~126 ~91 dirt
setblock ~29 ~126 ~92 dirt
setblock ~29 ~126 ~93 dirt
setblock ~29 ~126 ~94 dirt
setblock ~29 ~126 ~95 grass_block
setblock ~29 ~126 ~96 grass_block
setblock ~29 ~126 ~97 grass_block
setblock ~29 ~126 ~98 grass_block
setblock ~29 ~126 ~99 grass_block
setblock ~29 ~126 ~100 grass_block
setblock ~29 ~126 ~101 grass_block
setblock ~29 ~126 ~102 grass_block
setblock ~29 ~126 ~103 grass_block
setblock ~29 ~126 ~104 dirt
setblock ~29 ~126 ~105 dirt
setblock ~29 ~126 ~106 dirt
setblock ~29 ~126 ~107 dirt
setblock ~29 ~126 ~108 dirt
setblock ~29 ~126 ~109 dirt
setblock ~29 ~126 ~110 dirt
setblock ~29 ~126 ~111 dirt
setblock ~29 ~126 ~112 dirt
setblock ~29 ~126 ~113 dirt
setblock ~29 ~126 ~114 grass_block
setblock ~29 ~126 ~115 grass_block
setblock ~29 ~126 ~116 short_grass
setblock ~29 ~127 ~88 grass_block
setblock ~29 ~127 ~89 grass_block
setblock ~29 ~127 ~90 dirt
setblock ~29 ~127 ~91 grass_block
setblock ~29 ~127 ~92 grass_block
setblock ~29 ~127 ~93 grass_block
setblock ~29 ~127 ~94 grass_block
setblock ~29 ~127 ~95 short_grass
setblock ~29 ~127 ~98 short_grass
setblock ~29 ~127 ~99 fern
setblock ~29 ~127 ~101 fern
setblock ~29 ~127 ~104 grass_block
setblock ~29 ~127 ~105 grass_block
setblock ~29 ~127 ~106 grass_block
setblock ~29 ~127 ~107 dirt
setblock ~29 ~127 ~108 dirt
setblock ~29 ~127 ~109 dirt
setblock ~29 ~127 ~110 dirt
setblock ~29 ~127 ~111 dirt
setblock ~29 ~127 ~112 grass_block
setblock ~29 ~127 ~113 grass_block
setblock ~29 ~127 ~114 short_grass
setblock ~29 ~127 ~115 short_grass
setblock ~29 ~128 ~89 fern
setblock ~29 ~128 ~90 grass_block
setblock ~29 ~128 ~93 poppy
setblock ~29 ~128 ~106 poppy
setblock ~29 ~128 ~107 grass_block
setblock ~29 ~128 ~108 grass_block
setblock ~29 ~128 ~109 grass_block
setblock ~29 ~128 ~110 dirt
setblock ~29 ~128 ~111 grass_block
setblock ~29 ~129 ~90 fern
setblock ~29 ~129 ~107 short_grass
setblock ~29 ~129 ~110 grass_block
setblock ~30 ~102 ~99 dirt
setblock ~30 ~102 ~100 dirt
setblock ~30 ~103 ~95 dirt
setblock ~30 ~103 ~98 dirt
setblock ~30 ~103 ~99 dirt
setblock ~30 ~103 ~100 dirt
setblock ~30 ~104 ~92 dirt
setblock ~30 ~104 ~93 dirt
setblock ~30 ~104 ~95 dirt
setblock ~30 ~104 ~97 dirt
setblock ~30 ~104 ~98 dirt
setblock ~30 ~104 ~99 dirt
setblock ~30 ~104 ~100 dirt
setblock ~30 ~104 ~101 dirt
setblock ~30 ~104 ~102 dirt
setblock ~30 ~105 ~91 dirt
setblock ~30 ~105 ~92 dirt
setblock ~30 ~105 ~93 dirt
setblock ~30 ~105 ~95 dirt
setblock ~30 ~105 ~96 dirt
setblock ~30 ~105 ~97 dirt
setblock ~30 ~105 ~98 dirt
setblock ~30 ~105 ~99 dirt
setblock ~30 ~105 ~100 dirt
setblock ~30 ~105 ~101 dirt
setblock ~30 ~105 ~102 dirt
setblock ~30 ~105 ~103 dirt
setblock ~30 ~106 ~87 dirt
setblock ~30 ~106 ~90 dirt
setblock ~30 ~106 ~91 dirt
setblock ~30 ~106 ~92 dirt
setblock ~30 ~106 ~93 dirt
setblock ~30 ~106 ~94 dirt
setblock ~30 ~106 ~95 dirt
setblock ~30 ~106 ~96 dirt
setblock ~30 ~106 ~97 dirt
setblock ~30 ~106 ~98 dirt
setblock ~30 ~106 ~99 dirt
setblock ~30 ~106 ~100 dirt
setblock ~30 ~106 ~101 dirt
setblock ~30 ~106 ~102 dirt
setblock ~30 ~106 ~103 dirt
setblock ~30 ~106 ~104 dirt
setblock ~30 ~107 ~86 dirt
setblock ~30 ~107 ~87 dirt
setblock ~30 ~107 ~88 dirt
setblock ~30 ~107 ~89 dirt
setblock ~30 ~107 ~90 dirt
setblock ~30 ~107 ~91 dirt
setblock ~30 ~107 ~92 dirt
setblock ~30 ~107 ~93 dirt
setblock ~30 ~107 ~94 dirt
setblock ~30 ~107 ~95 dirt
setblock ~30 ~107 ~96 dirt
setblock ~30 ~107 ~97 dirt
setblock ~30 ~107 ~98 dirt
setblock ~30 ~107 ~99 dirt
setblock ~30 ~107 ~100 dirt
setblock ~30 ~107 ~101 dirt
setblock ~30 ~107 ~102 dirt
setblock ~30 ~107 ~103 dirt
setblock ~30 ~107 ~104 dirt
setblock ~30 ~108 ~86 dirt
setblock ~30 ~108 ~87 dirt
setblock ~30 ~108 ~88 dirt
setblock ~30 ~108 ~89 dirt
setblock ~30 ~108 ~90 dirt
setblock ~30 ~108 ~91 dirt
setblock ~30 ~108 ~92 dirt
setblock ~30 ~108 ~93 dirt
setblock ~30 ~108 ~94 dirt
setblock ~30 ~108 ~95 dirt
setblock ~30 ~108 ~96 dirt
setblock ~30 ~108 ~97 dirt
setblock ~30 ~108 ~98 dirt
setblock ~30 ~108 ~99 dirt
setblock ~30 ~108 ~100 dirt
setblock ~30 ~108 ~101 dirt
setblock ~30 ~108 ~102 dirt
setblock ~30 ~108 ~103 dirt
setblock ~30 ~108 ~104 dirt
setblock ~30 ~108 ~105 dirt
setblock ~30 ~109 ~85 dirt
setblock ~30 ~109 ~86 dirt
setblock ~30 ~109 ~87 dirt
setblock ~30 ~109 ~88 dirt
setblock ~30 ~109 ~89 dirt
setblock ~30 ~109 ~90 dirt
setblock ~30 ~109 ~91 dirt
setblock ~30 ~109 ~92 dirt
setblock ~30 ~109 ~93 dirt
setblock ~30 ~109 ~94 dirt
setblock ~30 ~109 ~95 dirt
setblock ~30 ~109 ~96 dirt
setblock ~30 ~109 ~97 dirt
setblock ~30 ~109 ~98 dirt
setblock ~30 ~109 ~99 dirt
setblock ~30 ~109 ~100 dirt
setblock ~30 ~109 ~101 dirt
setblock ~30 ~109 ~102 dirt
setblock ~30 ~109 ~103 dirt
setblock ~30 ~109 ~104 dirt
setblock ~30 ~109 ~105 dirt
setblock ~30 ~109 ~106 dirt
setblock ~30 ~109 ~109 dirt
setblock ~30 ~110 ~85 dirt
setblock ~30 ~110 ~86 dirt
setblock ~30 ~110 ~87 dirt
setblock ~30 ~110 ~88 dirt
setblock ~30 ~110 ~89 dirt
setblock ~30 ~110 ~90 dirt
setblock ~30 ~110 ~91 dirt
setblock ~30 ~110 ~92 dirt
setblock ~30 ~110 ~93 dirt
setblock ~30 ~110 ~94 dirt
setblock ~30 ~110 ~95 dirt
setblock ~30 ~110 ~96 dirt
setblock ~30 ~110 ~97 dirt
setblock ~30 ~110 ~98 dirt
setblock ~30 ~110 ~99 dirt
setblock ~30 ~110 ~100 dirt
setblock ~30 ~110 ~101 dirt
setblock ~30 ~110 ~102 dirt
setblock ~30 ~110 ~103 dirt
setblock ~30 ~110 ~104 dirt
setblock ~30 ~110 ~105 dirt
setblock ~30 ~110 ~106 dirt
setblock ~30 ~110 ~107 dirt
setblock ~30 ~110 ~108 dirt
setblock ~30 ~110 ~109 dirt
setblock ~30 ~111 ~85 dirt
setblock ~30 ~111 ~86 dirt
setblock ~30 ~111 ~87 dirt
setblock ~30 ~111 ~88 dirt
setblock ~30 ~111 ~89 dirt
setblock ~30 ~111 ~90 dirt
setblock ~30 ~111 ~91 dirt
setblock ~30 ~111 ~92 dirt
setblock ~30 ~111 ~93 dirt
setblock ~30 ~111 ~94 dirt
setblock ~30 ~111 ~95 dirt
setblock ~30 ~111 ~96 dirt
setblock ~30 ~111 ~97 dirt
setblock ~30 ~111 ~98 dirt
setblock ~30 ~111 ~99 dirt
setblock ~30 ~111 ~100 dirt
setblock ~30 ~111 ~101 dirt
setblock ~30 ~111 ~102 dirt
setblock ~30 ~111 ~103 dirt
setblock ~30 ~111 ~104 dirt
setblock ~30 ~111 ~105 dirt
setblock ~30 ~111 ~106 dirt
setblock ~30 ~111 ~107 dirt
setblock ~30 ~111 ~108 dirt
setblock ~30 ~111 ~109 dirt
setblock ~30 ~111 ~110 dirt
setblock ~30 ~112 ~84 dirt
setblock ~30 ~112 ~85 dirt
setblock ~30 ~112 ~86 dirt
setblock ~30 ~112 ~87 dirt
setblock ~30 ~112 ~88 dirt
setblock ~30 ~112 ~89 dirt
setblock ~30 ~112 ~90 dirt
setblock ~30 ~112 ~91 dirt
setblock ~30 ~112 ~92 dirt
setblock ~30 ~112 ~93 dirt
setblock ~30 ~112 ~94 dirt
setblock ~30 ~112 ~95 dirt
setblock ~30 ~112 ~96 dirt
setblock ~30 ~112 ~97 dirt
setblock ~30 ~112 ~98 dirt
setblock ~30 ~112 ~99 dirt
setblock ~30 ~112 ~100 dirt
setblock ~30 ~112 ~101 dirt
setblock ~30 ~112 ~102 dirt
setblock ~30 ~112 ~103 dirt
setblock ~30 ~112 ~104 dirt
setblock ~30 ~112 ~105 dirt
setblock ~30 ~112 ~106 dirt
setblock ~30 ~112 ~107 dirt
setblock ~30 ~112 ~108 dirt
setblock ~30 ~112 ~109 dirt
setblock ~30 ~112 ~110 dirt
setblock ~30 ~112 ~111 dirt
setblock ~30 ~113 ~83 dirt
setblock ~30 ~113 ~84 dirt
setblock ~30 ~113 ~85 dirt
setblock ~30 ~113 ~86 dirt
setblock ~30 ~113 ~87 dirt
setblock ~30 ~113 ~88 dirt
setblock ~30 ~113 ~89 dirt
setblock ~30 ~113 ~90 dirt
setblock ~30 ~113 ~91 dirt
setblock ~30 ~113 ~92 dirt
setblock ~30 ~113 ~93 dirt
setblock ~30 ~113 ~94 dirt
setblock ~30 ~113 ~95 dirt
setblock ~30 ~113 ~96 dirt
setblock ~30 ~113 ~97 dirt
setblock ~30 ~113 ~98 dirt
setblock ~30 ~113 ~99 dirt
setblock ~30 ~113 ~100 dirt
setblock ~30 ~113 ~101 dirt
setblock ~30 ~113 ~102 dirt
setblock ~30 ~113 ~103 dirt
setblock ~30 ~113 ~104 dirt
setblock ~30 ~113 ~105 dirt
setblock ~30 ~113 ~106 dirt
setblock ~30 ~113 ~107 dirt
setblock ~30 ~113 ~108 dirt
setblock ~30 ~113 ~109 dirt
setblock ~30 ~113 ~110 dirt
setblock ~30 ~113 ~111 dirt
setblock ~30 ~114 ~82 dirt
setblock ~30 ~114 ~83 dirt
setblock ~30 ~114 ~84 dirt
setblock ~30 ~114 ~85 dirt
setblock ~30 ~114 ~86 dirt
setblock ~30 ~114 ~87 dirt
setblock ~30 ~114 ~88 dirt
setblock ~30 ~114 ~89 dirt
setblock ~30 ~114 ~90 dirt
setblock ~30 ~114 ~91 dirt
setblock ~30 ~114 ~92 dirt
setblock ~30 ~114 ~93 dirt
setblock ~30 ~114 ~94 dirt
setblock ~30 ~114 ~95 dirt
setblock ~30 ~114 ~96 dirt
setblock ~30 ~114 ~97 dirt
setblock ~30 ~114 ~98 dirt
setblock ~30 ~114 ~99 dirt
setblock ~30 ~114 ~100 dirt
setblock ~30 ~114 ~101 dirt
setblock ~30 ~114 ~102 dirt
setblock ~30 ~114 ~103 dirt
setblock ~30 ~114 ~104 dirt
setblock ~30 ~114 ~105 dirt
setblock ~30 ~114 ~106 dirt
setblock ~30 ~114 ~107 dirt
setblock ~30 ~114 ~108 dirt
setblock ~30 ~114 ~109 dirt
setblock ~30 ~114 ~110 dirt
setblock ~30 ~114 ~111 dirt
setblock ~30 ~115 ~81 dirt
setblock ~30 ~115 ~82 dirt
setblock ~30 ~115 ~83 dirt
setblock ~30 ~115 ~84 dirt
setblock ~30 ~115 ~85 dirt
setblock ~30 ~115 ~86 dirt
setblock ~30 ~115 ~87 dirt
setblock ~30 ~115 ~88 dirt
setblock ~30 ~115 ~89 dirt
setblock ~30 ~115 ~90 dirt
setblock ~30 ~115 ~91 dirt
setblock ~30 ~115 ~92 dirt
setblock ~30 ~115 ~93 dirt
setblock ~30 ~115 ~94 dirt
setblock ~30 ~115 ~95 dirt
setblock ~30 ~115 ~96 dirt
setblock ~30 ~115 ~97 dirt
setblock ~30 ~115 ~98 dirt
setblock ~30 ~115 ~99 dirt
setblock ~30 ~115 ~100 dirt
setblock ~30 ~115 ~101 dirt
setblock ~30 ~115 ~102 dirt
setblock ~30 ~115 ~103 dirt
setblock ~30 ~115 ~104 dirt
setblock ~30 ~115 ~105 dirt
setblock ~30 ~115 ~106 dirt
setblock ~30 ~115 ~107 dirt
setblock ~30 ~115 ~108 dirt
setblock ~30 ~115 ~109 dirt
setblock ~30 ~115 ~110 dirt
setblock ~30 ~115 ~111 dirt
setblock ~30 ~115 ~112 dirt
setblock ~30 ~116 ~81 dirt
setblock ~30 ~116 ~82 dirt
setblock ~30 ~116 ~83 dirt
setblock ~30 ~116 ~84 dirt
setblock ~30 ~116 ~85 dirt
setblock ~30 ~116 ~86 dirt
setblock ~30 ~116 ~87 dirt
setblock ~30 ~116 ~88 dirt
setblock ~30 ~116 ~89 dirt
setblock ~30 ~116 ~90 dirt
setblock ~30 ~116 ~91 dirt
setblock ~30 ~116 ~92 dirt
setblock ~30 ~116 ~93 dirt
setblock ~30 ~116 ~94 dirt
setblock ~30 ~116 ~95 dirt
setblock ~30 ~116 ~96 dirt
setblock ~30 ~116 ~97 dirt
setblock ~30 ~116 ~98 dirt
setblock ~30 ~116 ~99 dirt
setblock ~30 ~116 ~100 dirt
setblock ~30 ~116 ~101 dirt
setblock ~30 ~116 ~102 dirt
setblock ~30 ~116 ~103 dirt
setblock ~30 ~116 ~104 dirt
setblock ~30 ~116 ~105 dirt
setblock ~30 ~116 ~106 dirt
setblock ~30 ~116 ~107 dirt
setblock ~30 ~116 ~108 dirt
setblock ~30 ~116 ~109 dirt
setblock ~30 ~116 ~110 dirt
setblock ~30 ~116 ~111 dirt
setblock ~30 ~116 ~112 dirt
setblock ~30 ~116 ~113 dirt
setblock ~30 ~117 ~80 dirt
setblock ~30 ~117 ~81 dirt
setblock ~30 ~117 ~82 dirt
setblock ~30 ~117 ~83 dirt
setblock ~30 ~117 ~84 dirt
setblock ~30 ~117 ~85 dirt
setblock ~30 ~117 ~86 dirt
setblock ~30 ~117 ~87 dirt
setblock ~30 ~117 ~88 dirt
setblock ~30 ~117 ~89 dirt
setblock ~30 ~117 ~90 dirt
setblock ~30 ~117 ~91 dirt
setblock ~30 ~117 ~92 dirt
setblock ~30 ~117 ~93 dirt
setblock ~30 ~117 ~94 dirt
setblock ~30 ~117 ~95 dirt
setblock ~30 ~117 ~96 dirt
setblock ~30 ~117 ~97 dirt
setblock ~30 ~117 ~98 dirt
setblock ~30 ~117 ~99 dirt
setblock ~30 ~117 ~100 dirt
setblock ~30 ~117 ~101 dirt
setblock ~30 ~117 ~102 dirt
setblock ~30 ~117 ~103 dirt
setblock ~30 ~117 ~104 dirt
setblock ~30 ~117 ~105 dirt
setblock ~30 ~117 ~106 dirt
setblock ~30 ~117 ~107 dirt
setblock ~30 ~117 ~108 dirt
setblock ~30 ~117 ~109 dirt
setblock ~30 ~117 ~110 dirt
setblock ~30 ~117 ~111 dirt
setblock ~30 ~117 ~112 dirt
setblock ~30 ~117 ~113 dirt
setblock ~30 ~117 ~114 dirt
setblock ~30 ~118 ~79 dirt
setblock ~30 ~118 ~80 dirt
setblock ~30 ~118 ~81 dirt
setblock ~30 ~118 ~82 dirt
setblock ~30 ~118 ~83 dirt
setblock ~30 ~118 ~84 dirt
setblock ~30 ~118 ~85 dirt
setblock ~30 ~118 ~86 dirt
setblock ~30 ~118 ~87 dirt
setblock ~30 ~118 ~88 dirt
setblock ~30 ~118 ~89 dirt
setblock ~30 ~118 ~90 dirt
setblock ~30 ~118 ~91 dirt
setblock ~30 ~118 ~92 dirt
setblock ~30 ~118 ~93 dirt
setblock ~30 ~118 ~94 dirt
setblock ~30 ~118 ~95 dirt
setblock ~30 ~118 ~96 dirt
setblock ~30 ~118 ~97 dirt
setblock ~30 ~118 ~98 dirt
setblock ~30 ~118 ~99 dirt
setblock ~30 ~118 ~100 dirt
setblock ~30 ~118 ~101 dirt
setblock ~30 ~118 ~102 dirt
setblock ~30 ~118 ~103 dirt
setblock ~30 ~118 ~104 dirt
setblock ~30 ~118 ~105 dirt
setblock ~30 ~118 ~106 dirt
setblock ~30 ~118 ~107 dirt
setblock ~30 ~118 ~108 dirt
setblock ~30 ~118 ~109 dirt
setblock ~30 ~118 ~110 dirt
setblock ~30 ~118 ~111 dirt
setblock ~30 ~118 ~112 dirt
setblock ~30 ~118 ~113 dirt
setblock ~30 ~118 ~114 dirt
setblock ~30 ~118 ~116 dirt
setblock ~30 ~118 ~117 dirt
setblock ~30 ~119 ~79 dirt
setblock ~30 ~119 ~80 dirt
setblock ~30 ~119 ~81 dirt
setblock ~30 ~119 ~82 dirt
setblock ~30 ~119 ~83 dirt
setblock ~30 ~119 ~84 dirt
setblock ~30 ~119 ~85 dirt
setblock ~30 ~119 ~86 dirt
setblock ~30 ~119 ~87 dirt
setblock ~30 ~119 ~88 dirt
setblock ~30 ~119 ~89 dirt
setblock ~30 ~119 ~90 dirt
setblock ~30 ~119 ~91 dirt
setblock ~30 ~119 ~92 dirt
setblock ~30 ~119 ~93 dirt
setblock ~30 ~119 ~94 dirt
setblock ~30 ~119 ~95 dirt
setblock ~30 ~119 ~96 dirt
setblock ~30 ~119 ~97 dirt
setblock ~30 ~119 ~98 dirt
setblock ~30 ~119 ~99 dirt
setblock ~30 ~119 ~100 dirt
setblock ~30 ~119 ~101 dirt
setblock ~30 ~119 ~102 dirt
setblock ~30 ~119 ~103 dirt
setblock ~30 ~119 ~104 dirt
setblock ~30 ~119 ~105 dirt
setblock ~30 ~119 ~106 dirt
setblock ~30 ~119 ~107 dirt
setblock ~30 ~119 ~108 dirt
setblock ~30 ~119 ~109 dirt
setblock ~30 ~119 ~110 dirt
setblock ~30 ~119 ~111 dirt
setblock ~30 ~119 ~112 dirt
setblock ~30 ~119 ~113 dirt
setblock ~30 ~119 ~114 dirt
setblock ~30 ~119 ~115 dirt
setblock ~30 ~119 ~116 dirt
setblock ~30 ~119 ~117 dirt
setblock ~30 ~120 ~75 dirt
setblock ~30 ~120 ~79 dirt
setblock ~30 ~120 ~80 dirt
setblock ~30 ~120 ~81 dirt
setblock ~30 ~120 ~82 dirt
setblock ~30 ~120 ~83 dirt
setblock ~30 ~120 ~84 dirt
setblock ~30 ~120 ~85 dirt
setblock ~30 ~120 ~86 dirt
setblock ~30 ~120 ~87 dirt
setblock ~30 ~120 ~88 dirt
setblock ~30 ~120 ~89 dirt
setblock ~30 ~120 ~90 dirt
setblock ~30 ~120 ~91 dirt
setblock ~30 ~120 ~92 dirt
setblock ~30 ~120 ~93 dirt
setblock ~30 ~120 ~94 dirt
setblock ~30 ~120 ~95 dirt
setblock ~30 ~120 ~96 dirt
setblock ~30 ~120 ~97 dirt
setblock ~30 ~120 ~98 dirt
setblock ~30 ~120 ~99 dirt
setblock ~30 ~120 ~100 dirt
setblock ~30 ~120 ~101 dirt
setblock ~30 ~120 ~102 dirt
setblock ~30 ~120 ~103 dirt
setblock ~30 ~120 ~104 dirt
setblock ~30 ~120 ~105 dirt
setblock ~30 ~120 ~106 dirt
setblock ~30 ~120 ~107 dirt
setblock ~30 ~120 ~108 dirt
setblock ~30 ~120 ~109 dirt
setblock ~30 ~120 ~110 dirt
setblock ~30 ~120 ~111 dirt
setblock ~30 ~120 ~112 dirt
setblock ~30 ~120 ~113 dirt
setblock ~30 ~120 ~114 dirt
setblock ~30 ~120 ~115 dirt
setblock ~30 ~120 ~116 dirt
setblock ~30 ~120 ~117 dirt
setblock ~30 ~120 ~118 dirt
setblock ~30 ~121 ~73 dirt
setblock ~30 ~121 ~74 dirt
setblock ~30 ~121 ~75 dirt
setblock ~30 ~121 ~76 dirt
setblock ~30 ~121 ~79 dirt
setblock ~30 ~121 ~80 dirt
setblock ~30 ~121 ~81 dirt
setblock ~30 ~121 ~82 dirt
setblock ~30 ~121 ~83 dirt
setblock ~30 ~121 ~84 dirt
setblock ~30 ~121 ~85 dirt
setblock ~30 ~121 ~86 dirt
setblock ~30 ~121 ~87 dirt
setblock ~30 ~121 ~88 dirt
setblock ~30 ~121 ~89 dirt
setblock ~30 ~121 ~90 dirt
setblock ~30 ~121 ~91 dirt
setblock ~30 ~121 ~92 dirt
setblock ~30 ~121 ~93 dirt
setblock ~30 ~121 ~94 dirt
setblock ~30 ~121 ~95 dirt
setblock ~30 ~121 ~96 dirt
setblock ~30 ~121 ~97 dirt
setblock ~30 ~121 ~98 dirt
setblock ~30 ~121 ~99 dirt
setblock ~30 ~121 ~100 dirt
setblock ~30 ~121 ~101 dirt
setblock ~30 ~121 ~102 dirt
setblock ~30 ~121 ~103 dirt
setblock ~30 ~121 ~104 dirt
setblock ~30 ~121 ~105 dirt
setblock ~30 ~121 ~106 dirt
setblock ~30 ~121 ~107 dirt
setblock ~30 ~121 ~108 dirt
setblock ~30 ~121 ~109 dirt
setblock ~30 ~121 ~110 dirt
setblock ~30 ~121 ~111 dirt
setblock ~30 ~121 ~112 dirt
setblock ~30 ~121 ~113 dirt
setblock ~30 ~121 ~114 dirt
setblock ~30 ~121 ~115 dirt
setblock ~30 ~121 ~116 dirt
setblock ~30 ~121 ~117 dirt
setblock ~30 ~121 ~118 dirt
setblock ~30 ~121 ~119 dirt
setblock ~30 ~122 ~73 dirt
setblock ~30 ~122 ~74 dirt
setblock ~30 ~122 ~75 dirt
setblock ~30 ~122 ~76 dirt
setblock ~30 ~122 ~79 dirt
setblock ~30 ~122 ~80 dirt
setblock ~30 ~122 ~81 dirt
setblock ~30 ~122 ~82 dirt
setblock ~30 ~122 ~83 dirt
setblock ~30 ~122 ~84 dirt
setblock ~30 ~122 ~85 dirt
setblock ~30 ~122 ~86 dirt
setblock ~30 ~122 ~87 dirt
setblock ~30 ~122 ~88 dirt
setblock ~30 ~122 ~89 dirt
setblock ~30 ~122 ~90 dirt
setblock ~30 ~122 ~91 dirt
setblock ~30 ~122 ~92 dirt
setblock ~30 ~122 ~93 dirt
setblock ~30 ~122 ~94 dirt
setblock ~30 ~122 ~95 dirt
setblock ~30 ~122 ~96 dirt
setblock ~30 ~122 ~97 dirt
setblock ~30 ~122 ~98 dirt
setblock ~30 ~122 ~99 dirt
setblock ~30 ~122 ~100 dirt
setblock ~30 ~122 ~101 dirt
setblock ~30 ~122 ~102 dirt
setblock ~30 ~122 ~103 dirt
setblock ~30 ~122 ~104 dirt
setblock ~30 ~122 ~105 dirt
setblock ~30 ~122 ~106 dirt
setblock ~30 ~122 ~107 dirt
setblock ~30 ~122 ~108 dirt
setblock ~30 ~122 ~109 dirt
setblock ~30 ~122 ~110 dirt
setblock ~30 ~122 ~111 dirt
setblock ~30 ~122 ~112 dirt
setblock ~30 ~122 ~113 dirt
setblock ~30 ~122 ~114 dirt
setblock ~30 ~122 ~115 dirt
setblock ~30 ~122 ~116 dirt
setblock ~30 ~122 ~117 dirt
setblock ~30 ~122 ~118 dirt
setblock ~30 ~122 ~119 dirt
setblock ~30 ~123 ~73 dirt
setblock ~30 ~123 ~74 dirt
setblock ~30 ~123 ~75 dirt
setblock ~30 ~123 ~76 dirt
setblock ~30 ~123 ~79 dirt
setblock ~30 ~123 ~80 dirt
setblock ~30 ~123 ~81 dirt
setblock ~30 ~123 ~82 dirt
setblock ~30 ~123 ~83 dirt
setblock ~30 ~123 ~84 dirt
setblock ~30 ~123 ~85 dirt
setblock ~30 ~123 ~86 dirt
setblock ~30 ~123 ~87 dirt
setblock ~30 ~123 ~88 dirt
setblock ~30 ~123 ~89 dirt
setblock ~30 ~123 ~90 dirt
setblock ~30 ~123 ~91 dirt
setblock ~30 ~123 ~92 dirt
setblock ~30 ~123 ~93 dirt
setblock ~30 ~123 ~94 dirt
setblock ~30 ~123 ~95 dirt
setblock ~30 ~123 ~96 dirt
setblock ~30 ~123 ~97 dirt
setblock ~30 ~123 ~98 dirt
setblock ~30 ~123 ~99 dirt
setblock ~30 ~123 ~100 dirt
setblock ~30 ~123 ~101 dirt
setblock ~30 ~123 ~102 dirt
setblock ~30 ~123 ~103 dirt
setblock ~30 ~123 ~104 dirt
setblock ~30 ~123 ~105 dirt
setblock ~30 ~123 ~106 dirt
setblock ~30 ~123 ~107 dirt
setblock ~30 ~123 ~108 dirt
setblock ~30 ~123 ~109 dirt
setblock ~30 ~123 ~110 dirt
setblock ~30 ~123 ~111 dirt
setblock ~30 ~123 ~112 dirt
setblock ~30 ~123 ~113 dirt
setblock ~30 ~123 ~114 dirt
setblock ~30 ~123 ~115 dirt
setblock ~30 ~123 ~116 dirt
setblock ~30 ~123 ~117 dirt
setblock ~30 ~123 ~118 dirt
setblock ~30 ~123 ~119 dirt
setblock ~30 ~124 ~73 grass_block
setblock ~30 ~124 ~74 grass_block
setblock ~30 ~124 ~75 grass_block
setblock ~30 ~124 ~76 grass_block
setblock ~30 ~124 ~79 grass_block
setblock ~30 ~124 ~80 grass_block
setblock ~30 ~124 ~81 grass_block
setblock ~30 ~124 ~82 dirt
setblock ~30 ~124 ~83 dirt
setblock ~30 ~124 ~84 dirt
setblock ~30 ~124 ~85 dirt
setblock ~30 ~124 ~86 dirt
setblock ~30 ~124 ~87 dirt
setblock ~30 ~124 ~88 dirt
setblock ~30 ~124 ~89 dirt
setblock ~30 ~124 ~90 dirt
setblock ~30 ~124 ~91 dirt
setblock ~30 ~124 ~92 dirt
setblock ~30 ~124 ~93 dirt
setblock ~30 ~124 ~94 dirt
setblock ~30 ~124 ~95 dirt
setblock ~30 ~124 ~96 dirt
setblock ~30 ~124 ~97 dirt
setblock ~30 ~124 ~98 dirt
setblock ~30 ~124 ~99 dirt
setblock ~30 ~124 ~100 dirt
setblock ~30 ~124 ~101 dirt
setblock ~30 ~124 ~102 dirt
setblock ~30 ~124 ~103 dirt
setblock ~30 ~124 ~104 dirt
setblock ~30 ~124 ~105 dirt
setblock ~30 ~124 ~106 dirt
setblock ~30 ~124 ~107 dirt
setblock ~30 ~124 ~108 dirt
setblock ~30 ~124 ~109 dirt
setblock ~30 ~124 ~110 dirt
setblock ~30 ~124 ~111 dirt
setblock ~30 ~124 ~112 dirt
setblock ~30 ~124 ~113 dirt
setblock ~30 ~124 ~114 dirt
setblock ~30 ~124 ~115 dirt
setblock ~30 ~124 ~116 dirt
setblock ~30 ~124 ~117 dirt
setblock ~30 ~124 ~118 dirt
setblock ~30 ~124 ~119 grass_block
setblock ~30 ~125 ~75 short_grass
setblock ~30 ~125 ~82 grass_block
setblock ~30 ~125 ~83 grass_block
setblock ~30 ~125 ~84 grass_block
setblock ~30 ~125 ~85 grass_block
setblock ~30 ~125 ~86 dirt
setblock ~30 ~125 ~87 dirt
setblock ~30 ~125 ~88 dirt
setblock ~30 ~125 ~89 dirt
setblock ~30 ~125 ~90 dirt
setblock ~30 ~125 ~91 dirt
setblock ~30 ~125 ~92 dirt
setblock ~30 ~125 ~93 dirt
setblock ~30 ~125 ~94 dirt
setblock ~30 ~125 ~95 dirt
setblock ~30 ~125 ~96 dirt
setblock ~30 ~125 ~97 dirt
setblock ~30 ~125 ~98 dirt
setblock ~30 ~125 ~99 dirt
setblock ~30 ~125 ~100 dirt
setblock ~30 ~125 ~101 dirt
setblock ~30 ~125 ~102 dirt
setblock ~30 ~125 ~103 dirt
setblock ~30 ~125 ~104 dirt
setblock ~30 ~125 ~105 dirt
setblock ~30 ~125 ~106 dirt
setblock ~30 ~125 ~107 dirt
setblock ~30 ~125 ~108 dirt
setblock ~30 ~125 ~109 dirt
setblock ~30 ~125 ~110 dirt
setblock ~30 ~125 ~111 dirt
setblock ~30 ~125 ~112 dirt
setblock ~30 ~125 ~113 dirt
setblock ~30 ~125 ~114 dirt
setblock ~30 ~125 ~115 dirt
setblock ~30 ~125 ~116 grass_block
setblock ~30 ~125 ~117 grass_block
setblock ~30 ~125 ~118 grass_block
setblock ~30 ~126 ~83 short_grass
setblock ~30 ~126 ~85 short_grass
setblock ~30 ~126 ~86 grass_block
setblock ~30 ~126 ~87 grass_block
setblock ~30 ~126 ~88 dirt
setblock ~30 ~126 ~89 dirt
setblock ~30 ~126 ~90 dirt
setblock ~30 ~126 ~91 dirt
setblock ~30 ~126 ~92 dirt
setblock ~30 ~126 ~93 dirt
setblock ~30 ~126 ~94 dirt
setblock ~30 ~126 ~95 dirt
setblock ~30 ~126 ~96 grass_block
setblock ~30 ~126 ~97 grass_block
setblock ~30 ~126 ~98 grass_block
setblock ~30 ~126 ~99 grass_block
setblock ~30 ~126 ~100 grass_block
setblock ~30 ~126 ~101 grass_block
setblock ~30 ~126 ~102 grass_block
setblock ~30 ~126 ~103 dirt
setblock ~30 ~126 ~104 dirt
setblock ~30 ~126 ~105 dirt
setblock ~30 ~126 ~106 dirt
setblock ~30 ~126 ~107 dirt
setblock ~30 ~126 ~108 dirt
setblock ~30 ~126 ~109 dirt
setblock ~30 ~126 ~110 dirt
setblock ~30 ~126 ~111 dirt
setblock ~30 ~126 ~112 dirt
setblock ~30 ~126 ~113 dirt
setblock ~30 ~126 ~114 grass_block
setblock ~30 ~126 ~115 grass_block
setblock ~30 ~126 ~116 short_grass
setblock ~30 ~127 ~88 grass_block
setblock ~30 ~127 ~89 grass_block
setblock ~30 ~127 ~90 dirt
setblock ~30 ~127 ~91 dirt
setblock ~30 ~127 ~92 grass_block
setblock ~30 ~127 ~93 grass_block
setblock ~30 ~127 ~94 grass_block
setblock ~30 ~127 ~95 grass_block
setblock ~30 ~127 ~102 poppy
setblock ~30 ~127 ~103 grass_block
setblock ~30 ~127 ~104 grass_block
setblock ~30 ~127 ~105 grass_block
setblock ~30 ~127 ~106 dirt
setblock ~30 ~127 ~107 dirt
setblock ~30 ~127 ~108 dirt
setblock ~30 ~127 ~109 dirt
setblock ~30 ~127 ~110 dirt
setblock ~30 ~127 ~111 dirt
setblock ~30 ~127 ~112 grass_block
setblock ~30 ~127 ~113 grass_block
setblock ~30 ~127 ~114 short_grass
setblock ~30 ~128 ~88 short_grass
setblock ~30 ~128 ~89 short_grass
setblock ~30 ~128 ~90 grass_block
setblock ~30 ~128 ~91 grass_block
setblock ~30 ~128 ~94 short_grass
setblock ~30 ~128 ~95 short_grass
setblock ~30 ~128 ~104 poppy
setblock ~30 ~128 ~106 grass_block
setblock ~30 ~128 ~107 grass_block
setblock ~30 ~128 ~108 grass_block
setblock ~30 ~128 ~109 dirt
setblock ~30 ~128 ~110 dirt
setblock ~30 ~128 ~111 grass_block
setblock ~30 ~128 ~112 fern
setblock ~30 ~128 ~113 fern
setblock ~30 ~129 ~106 fern
setblock ~30 ~129 ~109 grass_block
setblock ~30 ~129 ~110 grass_block
setblock ~31 ~99 ~99 dirt
setblock ~31 ~99 ~100 dirt
setblock ~31 ~100 ~99 dirt
setblock ~31 ~100 ~100 dirt
setblock ~31 ~101 ~93 dirt
setblock ~31 ~101 ~95 dirt
setblock ~31 ~101 ~99 dirt
setblock ~31 ~101 ~100 dirt
setblock ~31 ~101 ~101 dirt
setblock ~31 ~102 ~92 dirt
setblock ~31 ~102 ~93 dirt
setblock ~31 ~102 ~95 dirt
setblock ~31 ~102 ~98 dirt
setblock ~31 ~102 ~99 dirt
setblock ~31 ~102 ~100 dirt
setblock ~31 ~102 ~101 dirt
setblock ~31 ~102 ~102 dirt
setblock ~31 ~103 ~91 dirt
setblock ~31 ~103 ~92 dirt
setblock ~31 ~103 ~93 dirt
setblock ~31 ~103 ~94 dirt
setblock ~31 ~103 ~95 dirt
setblock ~31 ~103 ~96 dirt
setblock ~31 ~103 ~97 dirt
setblock ~31 ~103 ~98 dirt
setblock ~31 ~103 ~99 dirt
setblock ~31 ~103 ~100 dirt
setblock ~31 ~103 ~101 dirt
setblock ~31 ~103 ~102 dirt
setblock ~31 ~104 ~88 dirt
setblock ~31 ~104 ~91 dirt
setblock ~31 ~104 ~92 dirt
setblock ~31 ~104 ~93 dirt
setblock ~31 ~104 ~94 dirt
setblock ~31 ~104 ~95 dirt
setblock ~31 ~104 ~96 dirt
setblock ~31 ~104 ~97 dirt
setblock ~31 ~104 ~98 dirt
setblock ~31 ~104 ~99 dirt
setblock ~31 ~104 ~100 dirt
setblock ~31 ~104 ~101 dirt
setblock ~31 ~104 ~102 dirt
setblock ~31 ~104 ~103 dirt
setblock ~31 ~105 ~87 dirt
setblock ~31 ~105 ~88 dirt
setblock ~31 ~105 ~89 dirt
setblock ~31 ~105 ~90 dirt
setblock ~31 ~105 ~91 dirt
setblock ~31 ~105 ~92 dirt
setblock ~31 ~105 ~93 dirt
setblock ~31 ~105 ~94 dirt
setblock ~31 ~105 ~95 dirt
setblock ~31 ~105 ~96 dirt
setblock ~31 ~105 ~97 dirt
setblock ~31 ~105 ~98 dirt
setblock ~31 ~105 ~99 dirt
setblock ~31 ~105 ~100 dirt
setblock ~31 ~105 ~101 dirt
setblock ~31 ~105 ~102 dirt
setblock ~31 ~105 ~103 dirt
setblock ~31 ~105 ~104 dirt
setblock ~31 ~106 ~86 dirt
setblock ~31 ~106 ~87 dirt
setblock ~31 ~106 ~88 dirt
setblock ~31 ~106 ~89 dirt
setblock ~31 ~106 ~90 dirt
setblock ~31 ~106 ~91 dirt
setblock ~31 ~106 ~92 dirt
setblock ~31 ~106 ~93 dirt
setblock ~31 ~106 ~94 dirt
setblock ~31 ~106 ~95 dirt
setblock ~31 ~106 ~96 dirt
setblock ~31 ~106 ~97 dirt
setblock ~31 ~106 ~98 dirt
setblock ~31 ~106 ~99 dirt
setblock ~31 ~106 ~100 dirt
setblock ~31 ~106 ~101 dirt
setblock ~31 ~106 ~102 dirt
setblock ~31 ~106 ~103 dirt
setblock ~31 ~106 ~104 dirt
setblock ~31 ~106 ~105 dirt
setblock ~31 ~107 ~85 dirt
setblock ~31 ~107 ~86 dirt
setblock ~31 ~107 ~87 dirt
setblock ~31 ~107 ~88 dirt
setblock ~31 ~107 ~89 dirt
setblock ~31 ~107 ~90 dirt
setblock ~31 ~107 ~91 dirt
setblock ~31 ~107 ~92 dirt
setblock ~31 ~107 ~93 dirt
setblock ~31 ~107 ~94 dirt
setblock ~31 ~107 ~95 dirt
setblock ~31 ~107 ~96 dirt
setblock ~31 ~107 ~97 dirt
setblock ~31 ~107 ~98 dirt
setblock ~31 ~107 ~99 dirt
setblock ~31 ~107 ~100 dirt
setblock ~31 ~107 ~101 dirt
setblock ~31 ~107 ~102 dirt
setblock ~31 ~107 ~103 dirt
setblock ~31 ~107 ~104 dirt
setblock ~31 ~107 ~105 dirt
setblock ~31 ~108 ~85 dirt
setblock ~31 ~108 ~86 dirt
setblock ~31 ~108 ~87 dirt
setblock ~31 ~108 ~88 dirt
setblock ~31 ~108 ~89 dirt
setblock ~31 ~108 ~90 dirt
setblock ~31 ~108 ~91 dirt
setblock ~31 ~108 ~92 dirt
setblock ~31 ~108 ~93 dirt
setblock ~31 ~108 ~94 dirt
setblock ~31 ~108 ~95 dirt
setblock ~31 ~108 ~96 dirt
setblock ~31 ~108 ~97 dirt
setblock ~31 ~108 ~98 dirt
setblock ~31 ~108 ~99 dirt
setblock ~31 ~108 ~100 dirt
setblock ~31 ~108 ~101 dirt
setblock ~31 ~108 ~102 dirt
setblock ~31 ~108 ~103 dirt
setblock ~31 ~108 ~104 dirt
setblock ~31 ~108 ~105 dirt
setblock ~31 ~108 ~106 dirt
setblock ~31 ~108 ~109 dirt
setblock ~31 ~109 ~85 dirt
setblock ~31 ~109 ~86 dirt
setblock ~31 ~109 ~87 dirt
setblock ~31 ~109 ~88 dirt
setblock ~31 ~109 ~89 dirt
setblock ~31 ~109 ~90 dirt
setblock ~31 ~109 ~91 dirt
setblock ~31 ~109 ~92 dirt
setblock ~31 ~109 ~93 dirt
setblock ~31 ~109 ~94 dirt
setblock ~31 ~109 ~95 dirt
setblock ~31 ~109 ~96 dirt
setblock ~31 ~109 ~97 dirt
setblock ~31 ~109 ~98 dirt
setblock ~31 ~109 ~99 dirt
setblock ~31 ~109 ~100 dirt
setblock ~31 ~109 ~101 dirt
setblock ~31 ~109 ~102 dirt
setblock ~31 ~109 ~103 dirt
setblock ~31 ~109 ~104 dirt
setblock ~31 ~109 ~105 dirt
setblock ~31 ~109 ~106 dirt
setblock ~31 ~109 ~107 dirt
setblock ~31 ~109 ~108 dirt
setblock ~31 ~109 ~109 dirt
setblock ~31 ~109 ~110 dirt
setblock ~31 ~110 ~85 dirt
setblock ~31 ~110 ~86 dirt
setblock ~31 ~110 ~87 dirt
setblock ~31 ~110 ~88 dirt
setblock ~31 ~110 ~89 dirt
setblock ~31 ~110 ~90 dirt
setblock ~31 ~110 ~91 dirt
setblock ~31 ~110 ~92 dirt
setblock ~31 ~110 ~93 dirt
setblock ~31 ~110 ~94 dirt
setblock ~31 ~110 ~95 dirt
setblock ~31 ~110 ~96 dirt
setblock ~31 ~110 ~97 dirt
setblock ~31 ~110 ~98 dirt
setblock ~31 ~110 ~99 dirt
setblock ~31 ~110 ~100 dirt
setblock ~31 ~110 ~101 dirt
setblock ~31 ~110 ~102 dirt
setblock ~31 ~110 ~103 dirt
setblock ~31 ~110 ~104 dirt
setblock ~31 ~110 ~105 dirt
setblock ~31 ~110 ~106 dirt
setblock ~31 ~110 ~107 dirt
setblock ~31 ~110 ~108 dirt
setblock ~31 ~110 ~109 dirt
setblock ~31 ~110 ~110 dirt
setblock ~31 ~111 ~84 dirt
setblock ~31 ~111 ~85 dirt
setblock ~31 ~111 ~86 dirt
setblock ~31 ~111 ~87 dirt
setblock ~31 ~111 ~88 dirt
setblock ~31 ~111 ~89 dirt
setblock ~31 ~111 ~90 dirt
setblock ~31 ~111 ~91 dirt
setblock ~31 ~111 ~92 dirt
setblock ~31 ~111 ~93 dirt
setblock ~31 ~111 ~94 dirt
setblock ~31 ~111 ~95 dirt
setblock ~31 ~111 ~96 dirt
setblock ~31 ~111 ~97 dirt
setblock ~31 ~111 ~98 dirt
setblock ~31 ~111 ~99 dirt
setblock ~31 ~111 ~100 dirt
setblock ~31 ~111 ~101 dirt
setblock ~31 ~111 ~102 dirt
setblock ~31 ~111 ~103 dirt
setblock ~31 ~111 ~104 dirt
setblock ~31 ~111 ~105 dirt
setblock ~31 ~111 ~106 dirt
setblock ~31 ~111 ~107 dirt
setblock ~31 ~111 ~108 dirt
setblock ~31 ~111 ~109 dirt
setblock ~31 ~111 ~110 dirt
setblock ~31 ~111 ~111 dirt
setblock ~31 ~112 ~83 dirt
setblock ~31 ~112 ~84 dirt
setblock ~31 ~112 ~85 dirt
setblock ~31 ~112 ~86 dirt
setblock ~31 ~112 ~87 dirt
