setblock ~170 ~124 ~151 dirt
setblock ~170 ~124 ~152 dirt
setblock ~170 ~124 ~153 dirt
setblock ~170 ~124 ~154 dirt
setblock ~170 ~124 ~155 dirt
setblock ~170 ~124 ~156 grass_block
setblock ~170 ~124 ~157 grass_block
setblock ~170 ~124 ~162 grass_block
setblock ~170 ~124 ~163 grass_block
setblock ~170 ~124 ~164 dirt
setblock ~170 ~124 ~165 dirt
setblock ~170 ~124 ~166 dirt
setblock ~170 ~124 ~167 dirt
setblock ~170 ~124 ~168 dirt
setblock ~170 ~124 ~169 dirt
setblock ~170 ~124 ~170 dirt
setblock ~170 ~124 ~171 dirt
setblock ~170 ~124 ~172 dirt
setblock ~170 ~124 ~173 dirt
setblock ~170 ~124 ~174 dirt
setblock ~170 ~124 ~175 dirt
setblock ~170 ~124 ~176 dirt
setblock ~170 ~124 ~177 dirt
setblock ~170 ~124 ~178 dirt
setblock ~170 ~124 ~179 dirt
setblock ~170 ~124 ~180 dirt
setblock ~170 ~124 ~181 dirt
setblock ~170 ~124 ~182 dirt
setblock ~170 ~124 ~183 dirt
setblock ~170 ~124 ~184 dirt
setblock ~170 ~124 ~185 dirt
setblock ~170 ~124 ~186 dirt
setblock ~170 ~124 ~187 dirt
setblock ~170 ~124 ~188 dirt
setblock ~170 ~124 ~189 dirt
setblock ~170 ~124 ~190 dirt
setblock ~170 ~124 ~191 dirt
setblock ~170 ~124 ~192 dirt
setblock ~170 ~124 ~193 dirt
setblock ~170 ~124 ~194 dirt
setblock ~170 ~124 ~195 dirt
setblock ~170 ~124 ~196 dirt
setblock ~170 ~124 ~197 dirt
setblock ~170 ~124 ~198 dirt
setblock ~170 ~124 ~199 dirt
setblock ~170 ~125 ~3 poppy
setblock ~170 ~125 ~4 short_grass
setblock ~170 ~125 ~7 short_grass
setblock ~170 ~125 ~12 short_grass
setblock ~170 ~125 ~22 short_grass
setblock ~170 ~125 ~27 short_grass
setblock ~170 ~125 ~28 short_grass
setblock ~170 ~125 ~29 short_grass
setblock ~170 ~125 ~30 short_grass
setblock ~170 ~125 ~32 grass_block
setblock ~170 ~125 ~33 grass_block
setblock ~170 ~125 ~34 grass_block
setblock ~170 ~125 ~35 grass_block
setblock ~170 ~125 ~36 grass_block
setblock ~170 ~125 ~37 dirt
setblock ~170 ~125 ~38 dirt
setblock ~170 ~125 ~39 dirt
setblock ~170 ~125 ~40 dirt
setblock ~170 ~125 ~41 grass_block
setblock ~170 ~125 ~42 grass_block
setblock ~170 ~125 ~43 grass_block
setblock ~170 ~125 ~65 short_grass
setblock ~170 ~125 ~66 grass_block
setblock ~170 ~125 ~67 grass_block
setblock ~170 ~125 ~68 dirt
setblock ~170 ~125 ~69 dirt
setblock ~170 ~125 ~70 dirt
setblock ~170 ~125 ~71 dirt
setblock ~170 ~125 ~72 dirt
setblock ~170 ~125 ~73 grass_block
setblock ~170 ~125 ~74 grass_block
setblock ~170 ~125 ~76 short_grass
setblock ~170 ~125 ~87 short_grass
setblock ~170 ~125 ~89 fern
setblock ~170 ~125 ~90 grass_block
setblock ~170 ~125 ~91 grass_block
setblock ~170 ~125 ~92 grass_block
setblock ~170 ~125 ~93 grass_block
setblock ~170 ~125 ~94 grass_block
setblock ~170 ~125 ~95 grass_block
setblock ~170 ~125 ~96 grass_block
setblock ~170 ~125 ~97 grass_block
setblock ~170 ~125 ~98 grass_block
setblock ~170 ~125 ~99 grass_block
setblock ~170 ~125 ~100 grass_block
setblock ~170 ~125 ~101 grass_block
setblock ~170 ~125 ~102 grass_block
setblock ~170 ~125 ~103 grass_block
setblock ~170 ~125 ~104 grass_block
setblock ~170 ~125 ~107 short_grass
setblock ~170 ~125 ~108 poppy
setblock ~170 ~125 ~116 short_grass
setblock ~170 ~125 ~117 grass_block
setblock ~170 ~125 ~118 grass_block
setblock ~170 ~125 ~119 grass_block
setblock ~170 ~125 ~120 grass_block
setblock ~170 ~125 ~121 grass_block
setblock ~170 ~125 ~122 grass_block
setblock ~170 ~125 ~123 dirt
setblock ~170 ~125 ~124 dirt
setblock ~170 ~125 ~125 dirt
setblock ~170 ~125 ~126 dirt
setblock ~170 ~125 ~127 dirt
setblock ~170 ~125 ~128 dirt
setblock ~170 ~125 ~129 dirt
setblock ~170 ~125 ~130 dirt
setblock ~170 ~125 ~131 dirt
setblock ~170 ~125 ~132 dirt
setblock ~170 ~125 ~133 dirt
setblock ~170 ~125 ~134 grass_block
setblock ~170 ~125 ~136 fern
setblock ~170 ~125 ~143 short_grass
setblock ~170 ~125 ~145 grass_block
setblock ~170 ~125 ~146 grass_block
setblock ~170 ~125 ~147 dirt
setblock ~170 ~125 ~148 dirt
setblock ~170 ~125 ~149 dirt
setblock ~170 ~125 ~150 dirt
setblock ~170 ~125 ~151 dirt
setblock ~170 ~125 ~152 dirt
setblock ~170 ~125 ~153 dirt
setblock ~170 ~125 ~154 grass_block
setblock ~170 ~125 ~155 grass_block
setblock ~170 ~125 ~156 short_grass
setblock ~170 ~125 ~157 fern
setblock ~170 ~125 ~162 fern
setblock ~170 ~125 ~163 short_grass
setblock ~170 ~125 ~164 grass_block
setblock ~170 ~125 ~165 dirt
setblock ~170 ~125 ~166 dirt
setblock ~170 ~125 ~167 dirt
setblock ~170 ~125 ~168 dirt
setblock ~170 ~125 ~169 dirt
setblock ~170 ~125 ~170 dirt
setblock ~170 ~125 ~171 dirt
setblock ~170 ~125 ~172 dirt
setblock ~170 ~125 ~173 dirt
setblock ~170 ~125 ~174 dirt
setblock ~170 ~125 ~175 dirt
setblock ~170 ~125 ~176 dirt
setblock ~170 ~125 ~177 dirt
setblock ~170 ~125 ~178 dirt
setblock ~170 ~125 ~179 grass_block
setblock ~170 ~125 ~180 grass_block
setblock ~170 ~125 ~181 grass_block
setblock ~170 ~125 ~182 grass_block
setblock ~170 ~125 ~183 dirt
setblock ~170 ~125 ~184 dirt
setblock ~170 ~125 ~185 dirt
setblock ~170 ~125 ~186 dirt
setblock ~170 ~125 ~187 dirt
setblock ~170 ~125 ~188 dirt
setblock ~170 ~125 ~189 dirt
setblock ~170 ~125 ~190 dirt
setblock ~170 ~125 ~191 dirt
setblock ~170 ~125 ~192 dirt
setblock ~170 ~125 ~193 dirt
setblock ~170 ~125 ~194 dirt
setblock ~170 ~125 ~195 dirt
setblock ~170 ~125 ~196 dirt
setblock ~170 ~125 ~197 dirt
setblock ~170 ~125 ~198 dirt
setblock ~170 ~125 ~199 dirt
setblock ~170 ~126 ~34 short_grass
setblock ~170 ~126 ~35 short_grass
setblock ~170 ~126 ~37 grass_block
setblock ~170 ~126 ~38 grass_block
setblock ~170 ~126 ~39 grass_block
setblock ~170 ~126 ~40 grass_block
setblock ~170 ~126 ~42 poppy
setblock ~170 ~126 ~43 short_grass
setblock ~170 ~126 ~66 poppy
setblock ~170 ~126 ~67 short_grass
setblock ~170 ~126 ~68 grass_block
setblock ~170 ~126 ~69 dirt
setblock ~170 ~126 ~70 dirt
setblock ~170 ~126 ~71 dirt
setblock ~170 ~126 ~72 grass_block
setblock ~170 ~126 ~73 short_grass
setblock ~170 ~126 ~74 short_grass
setblock ~170 ~126 ~90 short_grass
setblock ~170 ~126 ~94 short_grass
setblock ~170 ~126 ~95 short_grass
setblock ~170 ~126 ~97 short_grass
setblock ~170 ~126 ~118 short_grass
setblock ~170 ~126 ~120 short_grass
setblock ~170 ~126 ~122 short_grass
setblock ~170 ~126 ~123 grass_block
setblock ~170 ~126 ~124 grass_block
setblock ~170 ~126 ~125 grass_block
setblock ~170 ~126 ~126 grass_block
setblock ~170 ~126 ~127 dirt
setblock ~170 ~126 ~128 dirt
setblock ~170 ~126 ~129 dirt
setblock ~170 ~126 ~130 dirt
setblock ~170 ~126 ~131 dirt
setblock ~170 ~126 ~132 grass_block
setblock ~170 ~126 ~133 grass_block
setblock ~170 ~126 ~147 grass_block
setblock ~170 ~126 ~148 grass_block
setblock ~170 ~126 ~149 grass_block
setblock ~170 ~126 ~150 dirt
setblock ~170 ~126 ~151 grass_block
setblock ~170 ~126 ~152 grass_block
setblock ~170 ~126 ~153 grass_block
setblock ~170 ~126 ~154 fern
setblock ~170 ~126 ~165 grass_block
setblock ~170 ~126 ~166 grass_block
setblock ~170 ~126 ~167 dirt
setblock ~170 ~126 ~168 dirt
setblock ~170 ~126 ~169 dirt
setblock ~170 ~126 ~170 dirt
setblock ~170 ~126 ~171 dirt
setblock ~170 ~126 ~172 dirt
setblock ~170 ~126 ~173 dirt
setblock ~170 ~126 ~174 dirt
setblock ~170 ~126 ~175 grass_block
setblock ~170 ~126 ~176 grass_block
setblock ~170 ~126 ~177 grass_block
setblock ~170 ~126 ~178 grass_block
setblock ~170 ~126 ~180 short_grass
setblock ~170 ~126 ~183 grass_block
setblock ~170 ~126 ~184 grass_block
setblock ~170 ~126 ~185 grass_block
setblock ~170 ~126 ~186 grass_block
setblock ~170 ~126 ~187 dirt
setblock ~170 ~126 ~188 dirt
setblock ~170 ~126 ~189 dirt
setblock ~170 ~126 ~190 dirt
setblock ~170 ~126 ~191 dirt
setblock ~170 ~126 ~192 dirt
setblock ~170 ~126 ~193 dirt
setblock ~170 ~126 ~194 dirt
setblock ~170 ~126 ~195 dirt
setblock ~170 ~126 ~196 dirt
setblock ~170 ~126 ~197 dirt
setblock ~170 ~126 ~198 dirt
setblock ~170 ~126 ~199 dirt
setblock ~170 ~127 ~38 poppy
setblock ~170 ~127 ~69 grass_block
setblock ~170 ~127 ~70 dirt
setblock ~170 ~127 ~71 grass_block
setblock ~170 ~127 ~126 short_grass
setblock ~170 ~127 ~127 grass_block
setblock ~170 ~127 ~128 grass_block
setblock ~170 ~127 ~129 dirt
setblock ~170 ~127 ~130 dirt
setblock ~170 ~127 ~131 grass_block
setblock ~170 ~127 ~132 short_grass
setblock ~170 ~127 ~148 short_grass
setblock ~170 ~127 ~149 short_grass
setblock ~170 ~127 ~150 grass_block
setblock ~170 ~127 ~165 short_grass
setblock ~170 ~127 ~167 grass_block
setblock ~170 ~127 ~168 grass_block
setblock ~170 ~127 ~169 dirt
setblock ~170 ~127 ~170 dirt
setblock ~170 ~127 ~171 dirt
setblock ~170 ~127 ~172 dirt
setblock ~170 ~127 ~173 grass_block
setblock ~170 ~127 ~174 grass_block
setblock ~170 ~127 ~178 short_grass
setblock ~170 ~127 ~183 poppy
setblock ~170 ~127 ~186 short_grass
setblock ~170 ~127 ~187 grass_block
setblock ~170 ~127 ~188 grass_block
setblock ~170 ~127 ~189 grass_block
setblock ~170 ~127 ~190 grass_block
setblock ~170 ~127 ~191 grass_block
setblock ~170 ~127 ~192 dirt
setblock ~170 ~127 ~193 dirt
setblock ~170 ~127 ~194 dirt
setblock ~170 ~127 ~195 dirt
setblock ~170 ~127 ~196 dirt
setblock ~170 ~127 ~197 dirt
setblock ~170 ~127 ~198 dirt
setblock ~170 ~127 ~199 dirt
setblock ~170 ~128 ~70 grass_block
setblock ~170 ~128 ~129 grass_block
setblock ~170 ~128 ~130 dirt
setblock ~170 ~128 ~150 poppy
setblock ~170 ~128 ~168 short_grass
setblock ~170 ~128 ~169 grass_block
setblock ~170 ~128 ~170 grass_block
setblock ~170 ~128 ~171 grass_block
setblock ~170 ~128 ~172 grass_block
setblock ~170 ~128 ~191 short_grass
setblock ~170 ~128 ~192 grass_block
setblock ~170 ~128 ~193 grass_block
setblock ~170 ~128 ~194 grass_block
setblock ~170 ~128 ~195 grass_block
setblock ~170 ~128 ~196 dirt
setblock ~170 ~128 ~197 dirt
setblock ~170 ~128 ~198 dirt
setblock ~170 ~128 ~199 dirt
setblock ~170 ~129 ~70 short_grass
setblock ~170 ~129 ~130 grass_block
setblock ~170 ~129 ~169 short_grass
setblock ~170 ~129 ~172 short_grass
setblock ~170 ~129 ~193 short_grass
setblock ~170 ~129 ~196 grass_block
setblock ~170 ~129 ~197 grass_block
setblock ~170 ~129 ~198 grass_block
setblock ~170 ~129 ~199 dirt
setblock ~170 ~130 ~130 short_grass
setblock ~170 ~130 ~196 short_grass
setblock ~170 ~130 ~198 short_grass
setblock ~170 ~130 ~199 grass_block
setblock ~171 ~122 ~0 dirt
setblock ~171 ~122 ~1 dirt
setblock ~171 ~122 ~2 dirt
setblock ~171 ~122 ~3 dirt
setblock ~171 ~122 ~4 dirt
setblock ~171 ~122 ~5 dirt
setblock ~171 ~122 ~6 dirt
setblock ~171 ~122 ~7 dirt
setblock ~171 ~122 ~8 dirt
setblock ~171 ~122 ~9 dirt
setblock ~171 ~122 ~10 dirt
setblock ~171 ~122 ~11 dirt
setblock ~171 ~122 ~12 dirt
setblock ~171 ~122 ~13 dirt
setblock ~171 ~122 ~14 dirt
setblock ~171 ~122 ~15 dirt
setblock ~171 ~122 ~16 dirt
setblock ~171 ~122 ~17 dirt
setblock ~171 ~122 ~18 dirt
setblock ~171 ~122 ~19 dirt
setblock ~171 ~122 ~20 dirt
setblock ~171 ~122 ~21 dirt
setblock ~171 ~122 ~22 dirt
setblock ~171 ~122 ~23 dirt
setblock ~171 ~122 ~24 dirt
setblock ~171 ~122 ~25 dirt
setblock ~171 ~122 ~26 dirt
setblock ~171 ~122 ~27 dirt
setblock ~171 ~122 ~28 dirt
setblock ~171 ~122 ~29 dirt
setblock ~171 ~122 ~30 dirt
setblock ~171 ~122 ~31 dirt
setblock ~171 ~122 ~32 dirt
setblock ~171 ~122 ~33 dirt
setblock ~171 ~122 ~34 dirt
setblock ~171 ~122 ~35 dirt
setblock ~171 ~122 ~36 dirt
setblock ~171 ~122 ~37 dirt
setblock ~171 ~122 ~38 dirt
setblock ~171 ~122 ~39 dirt
setblock ~171 ~122 ~40 dirt
setblock ~171 ~122 ~41 dirt
setblock ~171 ~122 ~42 dirt
setblock ~171 ~122 ~43 dirt
setblock ~171 ~122 ~44 dirt
setblock ~171 ~122 ~45 dirt
setblock ~171 ~122 ~46 dirt
setblock ~171 ~122 ~47 dirt
setblock ~171 ~122 ~48 dirt
setblock ~171 ~122 ~49 dirt
setblock ~171 ~122 ~50 dirt
setblock ~171 ~122 ~51 dirt
setblock ~171 ~122 ~52 grass_block
setblock ~171 ~122 ~53 grass_block
setblock ~171 ~122 ~54 grass_block
setblock ~171 ~122 ~55 grass_block
setblock ~171 ~122 ~56 grass_block
setblock ~171 ~122 ~57 grass_block
setblock ~171 ~122 ~58 grass_block
setblock ~171 ~122 ~59 grass_block
setblock ~171 ~122 ~60 grass_block
setblock ~171 ~122 ~61 grass_block
setblock ~171 ~122 ~62 dirt
setblock ~171 ~122 ~63 dirt
setblock ~171 ~122 ~64 dirt
setblock ~171 ~122 ~65 dirt
setblock ~171 ~122 ~66 dirt
setblock ~171 ~122 ~67 dirt
setblock ~171 ~122 ~68 dirt
setblock ~171 ~122 ~69 dirt
setblock ~171 ~122 ~70 dirt
setblock ~171 ~122 ~71 dirt
setblock ~171 ~122 ~72 dirt
setblock ~171 ~122 ~73 dirt
setblock ~171 ~122 ~74 dirt
setblock ~171 ~122 ~75 dirt
setblock ~171 ~122 ~76 dirt
setblock ~171 ~122 ~77 dirt
setblock ~171 ~122 ~78 dirt
setblock ~171 ~122 ~79 dirt
setblock ~171 ~122 ~80 dirt
setblock ~171 ~122 ~81 dirt
setblock ~171 ~122 ~82 dirt
setblock ~171 ~122 ~83 dirt
setblock ~171 ~122 ~84 dirt
setblock ~171 ~122 ~85 dirt
setblock ~171 ~122 ~86 dirt
setblock ~171 ~122 ~87 dirt
setblock ~171 ~122 ~88 dirt
setblock ~171 ~122 ~89 dirt
setblock ~171 ~122 ~90 dirt
setblock ~171 ~122 ~91 dirt
setblock ~171 ~122 ~92 dirt
setblock ~171 ~122 ~93 dirt
setblock ~171 ~122 ~94 dirt
setblock ~171 ~122 ~95 dirt
setblock ~171 ~122 ~96 dirt
setblock ~171 ~122 ~97 dirt
setblock ~171 ~122 ~98 dirt
setblock ~171 ~122 ~99 dirt
setblock ~171 ~122 ~100 dirt
setblock ~171 ~122 ~101 dirt
setblock ~171 ~122 ~102 dirt
setblock ~171 ~122 ~103 dirt
setblock ~171 ~122 ~104 dirt
setblock ~171 ~122 ~105 dirt
setblock ~171 ~122 ~106 dirt
setblock ~171 ~122 ~107 dirt
setblock ~171 ~122 ~108 dirt
setblock ~171 ~122 ~109 dirt
setblock ~171 ~122 ~110 dirt
setblock ~171 ~122 ~111 dirt
setblock ~171 ~122 ~112 dirt
setblock ~171 ~122 ~113 dirt
setblock ~171 ~122 ~114 dirt
setblock ~171 ~122 ~115 dirt
setblock ~171 ~122 ~116 dirt
setblock ~171 ~122 ~117 dirt
setblock ~171 ~122 ~118 dirt
setblock ~171 ~122 ~119 dirt
setblock ~171 ~122 ~120 dirt
setblock ~171 ~122 ~121 dirt
setblock ~171 ~122 ~122 dirt
setblock ~171 ~122 ~123 dirt
setblock ~171 ~122 ~124 dirt
setblock ~171 ~122 ~125 dirt
setblock ~171 ~122 ~126 dirt
setblock ~171 ~122 ~127 dirt
setblock ~171 ~122 ~128 dirt
setblock ~171 ~122 ~129 dirt
setblock ~171 ~122 ~130 dirt
setblock ~171 ~122 ~131 dirt
setblock ~171 ~122 ~132 dirt
setblock ~171 ~122 ~133 dirt
setblock ~171 ~122 ~134 dirt
setblock ~171 ~122 ~135 dirt
setblock ~171 ~122 ~136 dirt
setblock ~171 ~122 ~137 dirt
setblock ~171 ~122 ~138 dirt
setblock ~171 ~122 ~139 dirt
setblock ~171 ~122 ~140 dirt
setblock ~171 ~122 ~141 dirt
setblock ~171 ~122 ~142 dirt
setblock ~171 ~122 ~143 dirt
setblock ~171 ~122 ~144 dirt
setblock ~171 ~122 ~145 dirt
setblock ~171 ~122 ~146 dirt
setblock ~171 ~122 ~147 dirt
setblock ~171 ~122 ~148 dirt
setblock ~171 ~122 ~149 dirt
setblock ~171 ~122 ~150 dirt
setblock ~171 ~122 ~151 dirt
setblock ~171 ~122 ~152 dirt
setblock ~171 ~122 ~153 dirt
setblock ~171 ~122 ~154 dirt
setblock ~171 ~122 ~155 dirt
setblock ~171 ~122 ~156 dirt
setblock ~171 ~122 ~157 dirt
setblock ~171 ~122 ~158 dirt
setblock ~171 ~122 ~159 dirt
setblock ~171 ~122 ~160 dirt
setblock ~171 ~122 ~161 dirt
setblock ~171 ~122 ~162 dirt
setblock ~171 ~122 ~163 dirt
setblock ~171 ~122 ~164 dirt
setblock ~171 ~122 ~165 dirt
setblock ~171 ~122 ~166 dirt
setblock ~171 ~122 ~167 dirt
setblock ~171 ~122 ~168 dirt
setblock ~171 ~122 ~169 dirt
setblock ~171 ~122 ~170 dirt
setblock ~171 ~122 ~171 dirt
setblock ~171 ~122 ~172 dirt
setblock ~171 ~122 ~173 dirt
setblock ~171 ~122 ~174 dirt
setblock ~171 ~122 ~175 dirt
setblock ~171 ~122 ~176 dirt
setblock ~171 ~122 ~177 dirt
setblock ~171 ~122 ~178 dirt
setblock ~171 ~122 ~179 dirt
setblock ~171 ~122 ~180 dirt
setblock ~171 ~122 ~181 dirt
setblock ~171 ~122 ~182 dirt
setblock ~171 ~122 ~183 dirt
setblock ~171 ~122 ~184 dirt
setblock ~171 ~122 ~185 dirt
setblock ~171 ~122 ~186 dirt
setblock ~171 ~122 ~187 dirt
setblock ~171 ~122 ~188 dirt
setblock ~171 ~122 ~189 dirt
setblock ~171 ~122 ~190 dirt
setblock ~171 ~122 ~191 dirt
setblock ~171 ~122 ~192 dirt
setblock ~171 ~122 ~193 dirt
setblock ~171 ~122 ~194 dirt
setblock ~171 ~122 ~195 dirt
setblock ~171 ~122 ~196 dirt
setblock ~171 ~122 ~197 dirt
setblock ~171 ~122 ~198 dirt
setblock ~171 ~122 ~199 dirt
setblock ~171 ~123 ~0 dirt
setblock ~171 ~123 ~1 dirt
setblock ~171 ~123 ~2 dirt
setblock ~171 ~123 ~3 dirt
setblock ~171 ~123 ~4 dirt
setblock ~171 ~123 ~5 dirt
setblock ~171 ~123 ~6 dirt
setblock ~171 ~123 ~7 dirt
setblock ~171 ~123 ~8 dirt
setblock ~171 ~123 ~9 dirt
setblock ~171 ~123 ~10 dirt
setblock ~171 ~123 ~11 dirt
setblock ~171 ~123 ~12 dirt
setblock ~171 ~123 ~13 dirt
setblock ~171 ~123 ~14 dirt
setblock ~171 ~123 ~15 dirt
setblock ~171 ~123 ~16 dirt
setblock ~171 ~123 ~17 dirt
setblock ~171 ~123 ~18 dirt
setblock ~171 ~123 ~19 dirt
setblock ~171 ~123 ~20 dirt
setblock ~171 ~123 ~21 dirt
setblock ~171 ~123 ~22 dirt
setblock ~171 ~123 ~23 dirt
setblock ~171 ~123 ~24 dirt
setblock ~171 ~123 ~25 dirt
setblock ~171 ~123 ~26 dirt
setblock ~171 ~123 ~27 dirt
setblock ~171 ~123 ~28 dirt
setblock ~171 ~123 ~29 dirt
setblock ~171 ~123 ~30 dirt
setblock ~171 ~123 ~31 dirt
setblock ~171 ~123 ~32 dirt
setblock ~171 ~123 ~33 dirt
setblock ~171 ~123 ~34 dirt
setblock ~171 ~123 ~35 dirt
setblock ~171 ~123 ~36 dirt
setblock ~171 ~123 ~37 dirt
setblock ~171 ~123 ~38 dirt
setblock ~171 ~123 ~39 dirt
setblock ~171 ~123 ~40 dirt
setblock ~171 ~123 ~41 dirt
setblock ~171 ~123 ~42 dirt
setblock ~171 ~123 ~43 dirt
setblock ~171 ~123 ~44 dirt
setblock ~171 ~123 ~45 dirt
setblock ~171 ~123 ~46 dirt
setblock ~171 ~123 ~47 grass_block
setblock ~171 ~123 ~48 grass_block
setblock ~171 ~123 ~49 grass_block
setblock ~171 ~123 ~50 grass_block
setblock ~171 ~123 ~51 grass_block
setblock ~171 ~123 ~60 short_grass
setblock ~171 ~123 ~62 grass_block
setblock ~171 ~123 ~63 grass_block
setblock ~171 ~123 ~64 dirt
setblock ~171 ~123 ~65 dirt
setblock ~171 ~123 ~66 dirt
setblock ~171 ~123 ~67 dirt
setblock ~171 ~123 ~68 dirt
setblock ~171 ~123 ~69 dirt
setblock ~171 ~123 ~70 dirt
setblock ~171 ~123 ~71 dirt
setblock ~171 ~123 ~72 dirt
setblock ~171 ~123 ~73 dirt
setblock ~171 ~123 ~74 dirt
setblock ~171 ~123 ~75 dirt
setblock ~171 ~123 ~76 dirt
setblock ~171 ~123 ~77 dirt
setblock ~171 ~123 ~78 grass_block
setblock ~171 ~123 ~79 grass_block
setblock ~171 ~123 ~80 grass_block
setblock ~171 ~123 ~81 grass_block
setblock ~171 ~123 ~82 grass_block
setblock ~171 ~123 ~83 grass_block
setblock ~171 ~123 ~84 grass_block
setblock ~171 ~123 ~85 dirt
setblock ~171 ~123 ~86 dirt
setblock ~171 ~123 ~87 dirt
setblock ~171 ~123 ~88 dirt
setblock ~171 ~123 ~89 dirt
setblock ~171 ~123 ~90 dirt
setblock ~171 ~123 ~91 dirt
setblock ~171 ~123 ~92 dirt
setblock ~171 ~123 ~93 dirt
setblock ~171 ~123 ~94 dirt
setblock ~171 ~123 ~95 dirt
setblock ~171 ~123 ~96 dirt
setblock ~171 ~123 ~97 dirt
setblock ~171 ~123 ~98 dirt
setblock ~171 ~123 ~99 dirt
setblock ~171 ~123 ~100 dirt
setblock ~171 ~123 ~101 dirt
setblock ~171 ~123 ~102 dirt
setblock ~171 ~123 ~103 dirt
setblock ~171 ~123 ~104 dirt
setblock ~171 ~123 ~105 dirt
setblock ~171 ~123 ~106 dirt
setblock ~171 ~123 ~107 dirt
setblock ~171 ~123 ~108 dirt
setblock ~171 ~123 ~109 grass_block
setblock ~171 ~123 ~110 grass_block
setblock ~171 ~123 ~111 grass_block
setblock ~171 ~123 ~112 grass_block
setblock ~171 ~123 ~113 dirt
setblock ~171 ~123 ~114 dirt
setblock ~171 ~123 ~115 dirt
setblock ~171 ~123 ~116 dirt
setblock ~171 ~123 ~117 dirt
setblock ~171 ~123 ~118 dirt
setblock ~171 ~123 ~119 dirt
setblock ~171 ~123 ~120 dirt
setblock ~171 ~123 ~121 dirt
setblock ~171 ~123 ~122 dirt
setblock ~171 ~123 ~123 dirt
setblock ~171 ~123 ~124 dirt
setblock ~171 ~123 ~125 dirt
setblock ~171 ~123 ~126 dirt
setblock ~171 ~123 ~127 dirt
setblock ~171 ~123 ~128 dirt
setblock ~171 ~123 ~129 dirt
setblock ~171 ~123 ~130 dirt
setblock ~171 ~123 ~131 dirt
setblock ~171 ~123 ~132 dirt
setblock ~171 ~123 ~133 dirt
setblock ~171 ~123 ~134 dirt
setblock ~171 ~123 ~135 dirt
setblock ~171 ~123 ~136 dirt
setblock ~171 ~123 ~137 dirt
setblock ~171 ~123 ~138 grass_block
setblock ~171 ~123 ~139 grass_block
setblock ~171 ~123 ~140 grass_block
setblock ~171 ~123 ~141 grass_block
setblock ~171 ~123 ~142 dirt
setblock ~171 ~123 ~143 dirt
setblock ~171 ~123 ~144 dirt
setblock ~171 ~123 ~145 dirt
setblock ~171 ~123 ~146 dirt
setblock ~171 ~123 ~147 dirt
setblock ~171 ~123 ~148 dirt
setblock ~171 ~123 ~149 dirt
setblock ~171 ~123 ~150 dirt
setblock ~171 ~123 ~151 dirt
setblock ~171 ~123 ~152 dirt
setblock ~171 ~123 ~153 dirt
setblock ~171 ~123 ~154 dirt
setblock ~171 ~123 ~155 dirt
setblock ~171 ~123 ~156 dirt
setblock ~171 ~123 ~157 dirt
setblock ~171 ~123 ~158 dirt
setblock ~171 ~123 ~159 grass_block
setblock ~171 ~123 ~160 grass_block
setblock ~171 ~123 ~161 grass_block
setblock ~171 ~123 ~162 dirt
setblock ~171 ~123 ~163 dirt
setblock ~171 ~123 ~164 dirt
setblock ~171 ~123 ~165 dirt
setblock ~171 ~123 ~166 dirt
setblock ~171 ~123 ~167 dirt
setblock ~171 ~123 ~168 dirt
setblock ~171 ~123 ~169 dirt
setblock ~171 ~123 ~170 dirt
setblock ~171 ~123 ~171 dirt
setblock ~171 ~123 ~172 dirt
setblock ~171 ~123 ~173 dirt
setblock ~171 ~123 ~174 dirt
setblock ~171 ~123 ~175 dirt
setblock ~171 ~123 ~176 dirt
setblock ~171 ~123 ~177 dirt
setblock ~171 ~123 ~178 dirt
setblock ~171 ~123 ~179 dirt
setblock ~171 ~123 ~180 dirt
setblock ~171 ~123 ~181 dirt
setblock ~171 ~123 ~182 dirt
setblock ~171 ~123 ~183 dirt
setblock ~171 ~123 ~184 dirt
setblock ~171 ~123 ~185 dirt
setblock ~171 ~123 ~186 dirt
setblock ~171 ~123 ~187 dirt
setblock ~171 ~123 ~188 dirt
setblock ~171 ~123 ~189 dirt
setblock ~171 ~123 ~190 dirt
setblock ~171 ~123 ~191 dirt
setblock ~171 ~123 ~192 dirt
setblock ~171 ~123 ~193 dirt
setblock ~171 ~123 ~194 dirt
setblock ~171 ~123 ~195 dirt
setblock ~171 ~123 ~196 dirt
setblock ~171 ~123 ~197 dirt
setblock ~171 ~123 ~198 dirt
setblock ~171 ~123 ~199 dirt
setblock ~171 ~124 ~0 grass_block
setblock ~171 ~124 ~1 grass_block
setblock ~171 ~124 ~2 grass_block
setblock ~171 ~124 ~3 grass_block
setblock ~171 ~124 ~4 grass_block
setblock ~171 ~124 ~5 grass_block
setblock ~171 ~124 ~6 grass_block
setblock ~171 ~124 ~7 grass_block
setblock ~171 ~124 ~8 grass_block
setblock ~171 ~124 ~9 grass_block
setblock ~171 ~124 ~10 grass_block
setblock ~171 ~124 ~11 grass_block
setblock ~171 ~124 ~12 grass_block
setblock ~171 ~124 ~13 grass_block
setblock ~171 ~124 ~14 grass_block
setblock ~171 ~124 ~15 grass_block
setblock ~171 ~124 ~16 grass_block
setblock ~171 ~124 ~17 grass_block
setblock ~171 ~124 ~18 grass_block
setblock ~171 ~124 ~19 grass_block
setblock ~171 ~124 ~20 grass_block
setblock ~171 ~124 ~21 grass_block
setblock ~171 ~124 ~22 grass_block
setblock ~171 ~124 ~23 grass_block
setblock ~171 ~124 ~24 grass_block
setblock ~171 ~124 ~25 grass_block
setblock ~171 ~124 ~26 grass_block
setblock ~171 ~124 ~27 grass_block
setblock ~171 ~124 ~28 grass_block
setblock ~171 ~124 ~29 grass_block
setblock ~171 ~124 ~30 grass_block
setblock ~171 ~124 ~31 grass_block
setblock ~171 ~124 ~32 dirt
setblock ~171 ~124 ~33 dirt
setblock ~171 ~124 ~34 dirt
setblock ~171 ~124 ~35 dirt
setblock ~171 ~124 ~36 dirt
setblock ~171 ~124 ~37 dirt
setblock ~171 ~124 ~38 dirt
setblock ~171 ~124 ~39 dirt
setblock ~171 ~124 ~40 dirt
setblock ~171 ~124 ~41 dirt
setblock ~171 ~124 ~42 dirt
setblock ~171 ~124 ~43 grass_block
setblock ~171 ~124 ~44 grass_block
setblock ~171 ~124 ~45 grass_block
setblock ~171 ~124 ~46 grass_block
setblock ~171 ~124 ~49 short_grass
setblock ~171 ~124 ~50 short_grass
setblock ~171 ~124 ~51 short_grass
setblock ~171 ~124 ~62 short_grass
setblock ~171 ~124 ~63 short_grass
setblock ~171 ~124 ~64 grass_block
setblock ~171 ~124 ~65 grass_block
setblock ~171 ~124 ~66 dirt
setblock ~171 ~124 ~67 dirt
setblock ~171 ~124 ~68 dirt
setblock ~171 ~124 ~69 dirt
setblock ~171 ~124 ~70 dirt
setblock ~171 ~124 ~71 dirt
setblock ~171 ~124 ~72 dirt
setblock ~171 ~124 ~73 dirt
setblock ~171 ~124 ~74 dirt
setblock ~171 ~124 ~75 grass_block
setblock ~171 ~124 ~76 grass_block
setblock ~171 ~124 ~77 grass_block
setblock ~171 ~124 ~79 short_grass
setblock ~171 ~124 ~80 short_grass
setblock ~171 ~124 ~83 short_grass
setblock ~171 ~124 ~85 grass_block
setblock ~171 ~124 ~86 grass_block
setblock ~171 ~124 ~87 grass_block
setblock ~171 ~124 ~88 dirt
setblock ~171 ~124 ~89 dirt
setblock ~171 ~124 ~90 dirt
setblock ~171 ~124 ~91 dirt
setblock ~171 ~124 ~92 dirt
setblock ~171 ~124 ~93 dirt
setblock ~171 ~124 ~94 dirt
setblock ~171 ~124 ~95 dirt
setblock ~171 ~124 ~96 dirt
setblock ~171 ~124 ~97 dirt
setblock ~171 ~124 ~98 dirt
setblock ~171 ~124 ~99 dirt
setblock ~171 ~124 ~100 dirt
setblock ~171 ~124 ~101 dirt
setblock ~171 ~124 ~102 dirt
setblock ~171 ~124 ~103 dirt
setblock ~171 ~124 ~104 dirt
setblock ~171 ~124 ~105 grass_block
setblock ~171 ~124 ~106 grass_block
setblock ~171 ~124 ~107 grass_block
setblock ~171 ~124 ~108 grass_block
setblock ~171 ~124 ~109 short_grass
setblock ~171 ~124 ~110 short_grass
setblock ~171 ~124 ~113 grass_block
setblock ~171 ~124 ~114 grass_block
setblock ~171 ~124 ~115 grass_block
setblock ~171 ~124 ~116 grass_block
setblock ~171 ~124 ~117 dirt
setblock ~171 ~124 ~118 dirt
setblock ~171 ~124 ~119 dirt
setblock ~171 ~124 ~120 dirt
setblock ~171 ~124 ~121 dirt
setblock ~171 ~124 ~122 dirt
setblock ~171 ~124 ~123 dirt
setblock ~171 ~124 ~124 dirt
setblock ~171 ~124 ~125 dirt
setblock ~171 ~124 ~126 dirt
setblock ~171 ~124 ~127 dirt
setblock ~171 ~124 ~128 dirt
setblock ~171 ~124 ~129 dirt
setblock ~171 ~124 ~130 dirt
setblock ~171 ~124 ~131 dirt
setblock ~171 ~124 ~132 dirt
setblock ~171 ~124 ~133 dirt
setblock ~171 ~124 ~134 dirt
setblock ~171 ~124 ~135 dirt
setblock ~171 ~124 ~136 grass_block
setblock ~171 ~124 ~137 grass_block
setblock ~171 ~124 ~138 short_grass
setblock ~171 ~124 ~139 poppy
setblock ~171 ~124 ~140 poppy
setblock ~171 ~124 ~142 grass_block
setblock ~171 ~124 ~143 grass_block
setblock ~171 ~124 ~144 grass_block
setblock ~171 ~124 ~145 dirt
setblock ~171 ~124 ~146 dirt
setblock ~171 ~124 ~147 dirt
setblock ~171 ~124 ~148 dirt
setblock ~171 ~124 ~149 dirt
setblock ~171 ~124 ~150 dirt
setblock ~171 ~124 ~151 dirt
setblock ~171 ~124 ~152 dirt
setblock ~171 ~124 ~153 dirt
setblock ~171 ~124 ~154 dirt
setblock ~171 ~124 ~155 dirt
setblock ~171 ~124 ~156 grass_block
setblock ~171 ~124 ~157 grass_block
setblock ~171 ~124 ~158 grass_block
setblock ~171 ~124 ~162 grass_block
setblock ~171 ~124 ~163 grass_block
setblock ~171 ~124 ~164 dirt
setblock ~171 ~124 ~165 dirt
setblock ~171 ~124 ~166 dirt
setblock ~171 ~124 ~167 dirt
setblock ~171 ~124 ~168 dirt
setblock ~171 ~124 ~169 dirt
setblock ~171 ~124 ~170 dirt
setblock ~171 ~124 ~171 dirt
setblock ~171 ~124 ~172 dirt
setblock ~171 ~124 ~173 dirt
setblock ~171 ~124 ~174 dirt
setblock ~171 ~124 ~175 dirt
setblock ~171 ~124 ~176 dirt
setblock ~171 ~124 ~177 dirt
setblock ~171 ~124 ~178 dirt
setblock ~171 ~124 ~179 dirt
setblock ~171 ~124 ~180 dirt
setblock ~171 ~124 ~181 dirt
setblock ~171 ~124 ~182 dirt
setblock ~171 ~124 ~183 dirt
setblock ~171 ~124 ~184 dirt
setblock ~171 ~124 ~185 dirt
setblock ~171 ~124 ~186 dirt
setblock ~171 ~124 ~187 dirt
setblock ~171 ~124 ~188 dirt
setblock ~171 ~124 ~189 dirt
setblock ~171 ~124 ~190 dirt
setblock ~171 ~124 ~191 dirt
setblock ~171 ~124 ~192 dirt
setblock ~171 ~124 ~193 dirt
setblock ~171 ~124 ~194 dirt
setblock ~171 ~124 ~195 dirt
setblock ~171 ~124 ~196 dirt
setblock ~171 ~124 ~197 dirt
setblock ~171 ~124 ~198 dirt
setblock ~171 ~124 ~199 dirt
setblock ~171 ~125 ~0 poppy
setblock ~171 ~125 ~4 short_grass
setblock ~171 ~125 ~5 short_grass
setblock ~171 ~125 ~6 short_grass
setblock ~171 ~125 ~9 fern
setblock ~171 ~125 ~11 short_grass
setblock ~171 ~125 ~13 short_grass
setblock ~171 ~125 ~16 fern
setblock ~171 ~125 ~20 short_grass
setblock ~171 ~125 ~22 short_grass
setblock ~171 ~125 ~23 short_grass
setblock ~171 ~125 ~28 short_grass
setblock ~171 ~125 ~31 short_grass
setblock ~171 ~125 ~32 grass_block
setblock ~171 ~125 ~33 grass_block
setblock ~171 ~125 ~34 grass_block
setblock ~171 ~125 ~35 grass_block
setblock ~171 ~125 ~36 grass_block
setblock ~171 ~125 ~37 grass_block
setblock ~171 ~125 ~38 grass_block
setblock ~171 ~125 ~39 grass_block
setblock ~171 ~125 ~40 grass_block
setblock ~171 ~125 ~41 grass_block
setblock ~171 ~125 ~42 grass_block
setblock ~171 ~125 ~44 short_grass
setblock ~171 ~125 ~46 short_grass
setblock ~171 ~125 ~65 short_grass
setblock ~171 ~125 ~66 grass_block
setblock ~171 ~125 ~67 dirt
setblock ~171 ~125 ~68 dirt
setblock ~171 ~125 ~69 dirt
setblock ~171 ~125 ~70 dirt
setblock ~171 ~125 ~71 dirt
setblock ~171 ~125 ~72 dirt
setblock ~171 ~125 ~73 grass_block
setblock ~171 ~125 ~74 grass_block
setblock ~171 ~125 ~76 short_grass
setblock ~171 ~125 ~77 poppy
setblock ~171 ~125 ~88 grass_block
setblock ~171 ~125 ~89 grass_block
setblock ~171 ~125 ~90 grass_block
setblock ~171 ~125 ~91 grass_block
setblock ~171 ~125 ~92 grass_block
setblock ~171 ~125 ~93 grass_block
setblock ~171 ~125 ~94 grass_block
setblock ~171 ~125 ~95 grass_block
setblock ~171 ~125 ~96 grass_block
setblock ~171 ~125 ~97 grass_block
setblock ~171 ~125 ~98 grass_block
setblock ~171 ~125 ~99 grass_block
setblock ~171 ~125 ~100 grass_block
setblock ~171 ~125 ~101 grass_block
setblock ~171 ~125 ~102 grass_block
setblock ~171 ~125 ~103 grass_block
setblock ~171 ~125 ~104 grass_block
setblock ~171 ~125 ~106 short_grass
setblock ~171 ~125 ~115 short_grass
setblock ~171 ~125 ~117 grass_block
setblock ~171 ~125 ~118 grass_block
setblock ~171 ~125 ~119 grass_block
setblock ~171 ~125 ~120 grass_block
setblock ~171 ~125 ~121 grass_block
setblock ~171 ~125 ~122 grass_block
setblock ~171 ~125 ~123 grass_block
setblock ~171 ~125 ~124 dirt
setblock ~171 ~125 ~125 dirt
setblock ~171 ~125 ~126 dirt
setblock ~171 ~125 ~127 dirt
setblock ~171 ~125 ~128 dirt
setblock ~171 ~125 ~129 dirt
setblock ~171 ~125 ~130 dirt
setblock ~171 ~125 ~131 dirt
setblock ~171 ~125 ~132 dirt
setblock ~171 ~125 ~133 dirt
setblock ~171 ~125 ~134 grass_block
setblock ~171 ~125 ~135 grass_block
setblock ~171 ~125 ~137 short_grass
setblock ~171 ~125 ~143 short_grass
setblock ~171 ~125 ~145 grass_block
setblock ~171 ~125 ~146 grass_block
setblock ~171 ~125 ~147 grass_block
setblock ~171 ~125 ~148 dirt
setblock ~171 ~125 ~149 dirt
setblock ~171 ~125 ~150 dirt
setblock ~171 ~125 ~151 dirt
setblock ~171 ~125 ~152 dirt
setblock ~171 ~125 ~153 grass_block
setblock ~171 ~125 ~154 grass_block
setblock ~171 ~125 ~155 grass_block
setblock ~171 ~125 ~157 fern
setblock ~171 ~125 ~164 grass_block
setblock ~171 ~125 ~165 grass_block
setblock ~171 ~125 ~166 dirt
setblock ~171 ~125 ~167 dirt
setblock ~171 ~125 ~168 dirt
setblock ~171 ~125 ~169 dirt
setblock ~171 ~125 ~170 dirt
setblock ~171 ~125 ~171 dirt
setblock ~171 ~125 ~172 dirt
setblock ~171 ~125 ~173 dirt
setblock ~171 ~125 ~174 dirt
setblock ~171 ~125 ~175 dirt
setblock ~171 ~125 ~176 dirt
setblock ~171 ~125 ~177 dirt
setblock ~171 ~125 ~178 dirt
setblock ~171 ~125 ~179 grass_block
setblock ~171 ~125 ~180 grass_block
setblock ~171 ~125 ~181 grass_block
setblock ~171 ~125 ~182 dirt
setblock ~171 ~125 ~183 dirt
setblock ~171 ~125 ~184 dirt
setblock ~171 ~125 ~185 dirt
setblock ~171 ~125 ~186 dirt
setblock ~171 ~125 ~187 dirt
setblock ~171 ~125 ~188 dirt
setblock ~171 ~125 ~189 dirt
setblock ~171 ~125 ~190 dirt
setblock ~171 ~125 ~191 dirt
setblock ~171 ~125 ~192 dirt
setblock ~171 ~125 ~193 dirt
setblock ~171 ~125 ~194 dirt
setblock ~171 ~125 ~195 dirt
setblock ~171 ~125 ~196 dirt
setblock ~171 ~125 ~197 dirt
setblock ~171 ~125 ~198 dirt
setblock ~171 ~125 ~199 dirt
setblock ~171 ~126 ~35 short_grass
setblock ~171 ~126 ~36 short_grass
setblock ~171 ~126 ~38 short_grass
setblock ~171 ~126 ~42 short_grass
setblock ~171 ~126 ~67 grass_block
setblock ~171 ~126 ~68 grass_block
setblock ~171 ~126 ~69 dirt
setblock ~171 ~126 ~70 dirt
setblock ~171 ~126 ~71 dirt
setblock ~171 ~126 ~72 grass_block
setblock ~171 ~126 ~73 short_grass
setblock ~171 ~126 ~88 short_grass
setblock ~171 ~126 ~94 short_grass
setblock ~171 ~126 ~97 short_grass
setblock ~171 ~126 ~98 short_grass
setblock ~171 ~126 ~100 short_grass
setblock ~171 ~126 ~103 fern
setblock ~171 ~126 ~104 fern
setblock ~171 ~126 ~120 short_grass
setblock ~171 ~126 ~121 short_grass
setblock ~171 ~126 ~124 grass_block
setblock ~171 ~126 ~125 grass_block
setblock ~171 ~126 ~126 grass_block
setblock ~171 ~126 ~127 grass_block
setblock ~171 ~126 ~128 dirt
setblock ~171 ~126 ~129 dirt
setblock ~171 ~126 ~130 dirt
setblock ~171 ~126 ~131 dirt
setblock ~171 ~126 ~132 grass_block
setblock ~171 ~126 ~133 grass_block
setblock ~171 ~126 ~146 fern
setblock ~171 ~126 ~147 short_grass
setblock ~171 ~126 ~148 grass_block
setblock ~171 ~126 ~149 grass_block
setblock ~171 ~126 ~150 grass_block
setblock ~171 ~126 ~151 grass_block
setblock ~171 ~126 ~152 grass_block
setblock ~171 ~126 ~153 short_grass
setblock ~171 ~126 ~166 grass_block
setblock ~171 ~126 ~167 grass_block
setblock ~171 ~126 ~168 dirt
setblock ~171 ~126 ~169 dirt
setblock ~171 ~126 ~170 dirt
setblock ~171 ~126 ~171 dirt
setblock ~171 ~126 ~172 dirt
setblock ~171 ~126 ~173 dirt
setblock ~171 ~126 ~174 grass_block
setblock ~171 ~126 ~175 grass_block
setblock ~171 ~126 ~176 grass_block
setblock ~171 ~126 ~177 grass_block
setblock ~171 ~126 ~178 grass_block
setblock ~171 ~126 ~182 grass_block
setblock ~171 ~126 ~183 grass_block
setblock ~171 ~126 ~184 grass_block
setblock ~171 ~126 ~185 grass_block
setblock ~171 ~126 ~186 grass_block
setblock ~171 ~126 ~187 dirt
setblock ~171 ~126 ~188 dirt
setblock ~171 ~126 ~189 dirt
setblock ~171 ~126 ~190 dirt
setblock ~171 ~126 ~191 dirt
setblock ~171 ~126 ~192 dirt
setblock ~171 ~126 ~193 dirt
setblock ~171 ~126 ~194 dirt
setblock ~171 ~126 ~195 dirt
setblock ~171 ~126 ~196 dirt
setblock ~171 ~126 ~197 dirt
setblock ~171 ~126 ~198 dirt
setblock ~171 ~126 ~199 dirt
setblock ~171 ~127 ~67 short_grass
setblock ~171 ~127 ~68 short_grass
setblock ~171 ~127 ~69 grass_block
setblock ~171 ~127 ~70 dirt
setblock ~171 ~127 ~71 grass_block
setblock ~171 ~127 ~125 fern
setblock ~171 ~127 ~127 poppy
setblock ~171 ~127 ~128 grass_block
setblock ~171 ~127 ~129 grass_block
setblock ~171 ~127 ~130 dirt
setblock ~171 ~127 ~131 grass_block
setblock ~171 ~127 ~132 short_grass
setblock ~171 ~127 ~151 poppy
setblock ~171 ~127 ~152 short_grass
setblock ~171 ~127 ~166 short_grass
setblock ~171 ~127 ~168 grass_block
setblock ~171 ~127 ~169 grass_block
setblock ~171 ~127 ~170 dirt
setblock ~171 ~127 ~171 grass_block
setblock ~171 ~127 ~172 grass_block
setblock ~171 ~127 ~173 grass_block
setblock ~171 ~127 ~187 grass_block
setblock ~171 ~127 ~188 grass_block
setblock ~171 ~127 ~189 grass_block
setblock ~171 ~127 ~190 grass_block
setblock ~171 ~127 ~191 grass_block
setblock ~171 ~127 ~192 grass_block
setblock ~171 ~127 ~193 dirt
setblock ~171 ~127 ~194 dirt
setblock ~171 ~127 ~195 dirt
setblock ~171 ~127 ~196 dirt
setblock ~171 ~127 ~197 dirt
setblock ~171 ~127 ~198 dirt
setblock ~171 ~127 ~199 dirt
setblock ~171 ~128 ~69 short_grass
setblock ~171 ~128 ~70 grass_block
setblock ~171 ~128 ~128 short_grass
setblock ~171 ~128 ~129 short_grass
setblock ~171 ~128 ~130 grass_block
setblock ~171 ~128 ~131 short_grass
setblock ~171 ~128 ~168 short_grass
setblock ~171 ~128 ~170 grass_block
setblock ~171 ~128 ~171 poppy
setblock ~171 ~128 ~193 grass_block
setblock ~171 ~128 ~194 grass_block
setblock ~171 ~128 ~195 grass_block
setblock ~171 ~128 ~196 grass_block
setblock ~171 ~128 ~197 grass_block
setblock ~171 ~128 ~198 grass_block
setblock ~171 ~128 ~199 grass_block
setblock ~171 ~129 ~170 short_grass
setblock ~172 ~122 ~0 dirt
setblock ~172 ~122 ~1 dirt
setblock ~172 ~122 ~2 dirt
setblock ~172 ~122 ~3 dirt
setblock ~172 ~122 ~4 dirt
setblock ~172 ~122 ~5 dirt
setblock ~172 ~122 ~6 dirt
setblock ~172 ~122 ~7 dirt
setblock ~172 ~122 ~8 dirt
setblock ~172 ~122 ~9 dirt
setblock ~172 ~122 ~10 dirt
setblock ~172 ~122 ~11 dirt
setblock ~172 ~122 ~12 dirt
setblock ~172 ~122 ~13 dirt
setblock ~172 ~122 ~14 dirt
setblock ~172 ~122 ~15 dirt
setblock ~172 ~122 ~16 dirt
setblock ~172 ~122 ~17 dirt
setblock ~172 ~122 ~18 dirt
setblock ~172 ~122 ~19 dirt
setblock ~172 ~122 ~20 dirt
setblock ~172 ~122 ~21 dirt
setblock ~172 ~122 ~22 dirt
setblock ~172 ~122 ~23 dirt
setblock ~172 ~122 ~24 dirt
setblock ~172 ~122 ~25 dirt
setblock ~172 ~122 ~26 dirt
setblock ~172 ~122 ~27 dirt
setblock ~172 ~122 ~28 dirt
setblock ~172 ~122 ~29 dirt
setblock ~172 ~122 ~30 dirt
setblock ~172 ~122 ~31 dirt
setblock ~172 ~122 ~32 dirt
setblock ~172 ~122 ~33 dirt
setblock ~172 ~122 ~34 dirt
setblock ~172 ~122 ~35 dirt
setblock ~172 ~122 ~36 dirt
setblock ~172 ~122 ~37 dirt
setblock ~172 ~122 ~38 dirt
setblock ~172 ~122 ~39 dirt
setblock ~172 ~122 ~40 dirt
setblock ~172 ~122 ~41 dirt
setblock ~172 ~122 ~42 dirt
setblock ~172 ~122 ~43 dirt
setblock ~172 ~122 ~44 dirt
setblock ~172 ~122 ~45 dirt
setblock ~172 ~122 ~46 dirt
setblock ~172 ~122 ~47 dirt
setblock ~172 ~122 ~48 dirt
setblock ~172 ~122 ~49 dirt
setblock ~172 ~122 ~50 dirt
setblock ~172 ~122 ~51 dirt
setblock ~172 ~122 ~52 dirt
setblock ~172 ~122 ~53 dirt
setblock ~172 ~122 ~54 dirt
setblock ~172 ~122 ~55 dirt
setblock ~172 ~122 ~56 dirt
setblock ~172 ~122 ~57 grass_block
setblock ~172 ~122 ~58 grass_block
setblock ~172 ~122 ~59 grass_block
setblock ~172 ~122 ~60 grass_block
setblock ~172 ~122 ~61 dirt
setblock ~172 ~122 ~62 dirt
setblock ~172 ~122 ~63 dirt
setblock ~172 ~122 ~64 dirt
setblock ~172 ~122 ~65 dirt
setblock ~172 ~122 ~66 dirt
setblock ~172 ~122 ~67 dirt
setblock ~172 ~122 ~68 dirt
setblock ~172 ~122 ~69 dirt
setblock ~172 ~122 ~70 dirt
setblock ~172 ~122 ~71 dirt
setblock ~172 ~122 ~72 dirt
setblock ~172 ~122 ~73 dirt
setblock ~172 ~122 ~74 dirt
setblock ~172 ~122 ~75 dirt
setblock ~172 ~122 ~76 dirt
setblock ~172 ~122 ~77 dirt
setblock ~172 ~122 ~78 dirt
setblock ~172 ~122 ~79 dirt
setblock ~172 ~122 ~80 dirt
setblock ~172 ~122 ~81 dirt
setblock ~172 ~122 ~82 dirt
setblock ~172 ~122 ~83 dirt
setblock ~172 ~122 ~84 dirt
setblock ~172 ~122 ~85 dirt
setblock ~172 ~122 ~86 dirt
setblock ~172 ~122 ~87 dirt
setblock ~172 ~122 ~88 dirt
setblock ~172 ~122 ~89 dirt
setblock ~172 ~122 ~90 dirt
setblock ~172 ~122 ~91 dirt
setblock ~172 ~122 ~92 dirt
setblock ~172 ~122 ~93 dirt
setblock ~172 ~122 ~94 dirt
setblock ~172 ~122 ~95 dirt
setblock ~172 ~122 ~96 dirt
setblock ~172 ~122 ~97 dirt
setblock ~172 ~122 ~98 dirt
setblock ~172 ~122 ~99 dirt
setblock ~172 ~122 ~100 dirt
setblock ~172 ~122 ~101 dirt
setblock ~172 ~122 ~102 dirt
setblock ~172 ~122 ~103 dirt
setblock ~172 ~122 ~104 dirt
setblock ~172 ~122 ~105 dirt
setblock ~172 ~122 ~106 dirt
setblock ~172 ~122 ~107 dirt
setblock ~172 ~122 ~108 dirt
setblock ~172 ~122 ~109 dirt
setblock ~172 ~122 ~110 dirt
setblock ~172 ~122 ~111 dirt
setblock ~172 ~122 ~112 dirt
setblock ~172 ~122 ~113 dirt
setblock ~172 ~122 ~114 dirt
setblock ~172 ~122 ~115 dirt
setblock ~172 ~122 ~116 dirt
setblock ~172 ~122 ~117 dirt
setblock ~172 ~122 ~118 dirt
setblock ~172 ~122 ~119 dirt
setblock ~172 ~122 ~120 dirt
setblock ~172 ~122 ~121 dirt
setblock ~172 ~122 ~122 dirt
setblock ~172 ~122 ~123 dirt
setblock ~172 ~122 ~124 dirt
setblock ~172 ~122 ~125 dirt
setblock ~172 ~122 ~126 dirt
setblock ~172 ~122 ~127 dirt
setblock ~172 ~122 ~128 dirt
setblock ~172 ~122 ~129 dirt
setblock ~172 ~122 ~130 dirt
setblock ~172 ~122 ~131 dirt
setblock ~172 ~122 ~132 dirt
setblock ~172 ~122 ~133 dirt
setblock ~172 ~122 ~134 dirt
setblock ~172 ~122 ~135 dirt
setblock ~172 ~122 ~136 dirt
setblock ~172 ~122 ~137 dirt
setblock ~172 ~122 ~138 dirt
setblock ~172 ~122 ~139 dirt
setblock ~172 ~122 ~140 dirt
setblock ~172 ~122 ~141 dirt
setblock ~172 ~122 ~142 dirt
setblock ~172 ~122 ~143 dirt
setblock ~172 ~122 ~144 dirt
setblock ~172 ~122 ~145 dirt
setblock ~172 ~122 ~146 dirt
setblock ~172 ~122 ~147 dirt
setblock ~172 ~122 ~148 dirt
setblock ~172 ~122 ~149 dirt
setblock ~172 ~122 ~150 dirt
setblock ~172 ~122 ~151 dirt
setblock ~172 ~122 ~152 dirt
setblock ~172 ~122 ~153 dirt
setblock ~172 ~122 ~154 dirt
setblock ~172 ~122 ~155 dirt
setblock ~172 ~122 ~156 dirt
setblock ~172 ~122 ~157 dirt
setblock ~172 ~122 ~158 dirt
setblock ~172 ~122 ~159 dirt
setblock ~172 ~122 ~160 dirt
setblock ~172 ~122 ~161 dirt
setblock ~172 ~122 ~162 dirt
setblock ~172 ~122 ~163 dirt
setblock ~172 ~122 ~164 dirt
setblock ~172 ~122 ~165 dirt
setblock ~172 ~122 ~166 dirt
setblock ~172 ~122 ~167 dirt
setblock ~172 ~122 ~168 dirt
setblock ~172 ~122 ~169 dirt
setblock ~172 ~122 ~170 dirt
setblock ~172 ~122 ~171 dirt
setblock ~172 ~122 ~172 dirt
setblock ~172 ~122 ~173 dirt
setblock ~172 ~122 ~174 dirt
setblock ~172 ~122 ~175 dirt
setblock ~172 ~122 ~176 dirt
setblock ~172 ~122 ~177 dirt
setblock ~172 ~122 ~178 dirt
setblock ~172 ~122 ~179 dirt
setblock ~172 ~122 ~180 dirt
setblock ~172 ~122 ~181 dirt
setblock ~172 ~122 ~182 dirt
setblock ~172 ~122 ~183 dirt
setblock ~172 ~122 ~184 dirt
setblock ~172 ~122 ~185 dirt
setblock ~172 ~122 ~186 dirt
setblock ~172 ~122 ~187 dirt
setblock ~172 ~122 ~188 dirt
setblock ~172 ~122 ~189 dirt
setblock ~172 ~122 ~190 dirt
setblock ~172 ~122 ~191 dirt
setblock ~172 ~122 ~192 dirt
setblock ~172 ~122 ~193 dirt
setblock ~172 ~122 ~194 dirt
setblock ~172 ~122 ~195 dirt
setblock ~172 ~122 ~196 dirt
setblock ~172 ~122 ~197 dirt
setblock ~172 ~122 ~198 dirt
setblock ~172 ~122 ~199 dirt
setblock ~172 ~123 ~0 dirt
setblock ~172 ~123 ~1 dirt
setblock ~172 ~123 ~2 dirt
setblock ~172 ~123 ~3 dirt
setblock ~172 ~123 ~4 dirt
setblock ~172 ~123 ~5 dirt
setblock ~172 ~123 ~6 dirt
setblock ~172 ~123 ~7 dirt
setblock ~172 ~123 ~8 dirt
setblock ~172 ~123 ~9 dirt
setblock ~172 ~123 ~10 dirt
setblock ~172 ~123 ~11 dirt
setblock ~172 ~123 ~12 dirt
setblock ~172 ~123 ~13 dirt
setblock ~172 ~123 ~14 dirt
setblock ~172 ~123 ~15 dirt
setblock ~172 ~123 ~16 dirt
setblock ~172 ~123 ~17 dirt
setblock ~172 ~123 ~18 dirt
setblock ~172 ~123 ~19 dirt
setblock ~172 ~123 ~20 dirt
setblock ~172 ~123 ~21 dirt
setblock ~172 ~123 ~22 dirt
setblock ~172 ~123 ~23 dirt
setblock ~172 ~123 ~24 dirt
setblock ~172 ~123 ~25 dirt
setblock ~172 ~123 ~26 dirt
setblock ~172 ~123 ~27 dirt
setblock ~172 ~123 ~28 dirt
setblock ~172 ~123 ~29 dirt
setblock ~172 ~123 ~30 dirt
setblock ~172 ~123 ~31 dirt
setblock ~172 ~123 ~32 dirt
setblock ~172 ~123 ~33 dirt
setblock ~172 ~123 ~34 dirt
setblock ~172 ~123 ~35 dirt
setblock ~172 ~123 ~36 dirt
setblock ~172 ~123 ~37 dirt
setblock ~172 ~123 ~38 dirt
setblock ~172 ~123 ~39 dirt
setblock ~172 ~123 ~40 dirt
setblock ~172 ~123 ~41 dirt
setblock ~172 ~123 ~42 dirt
setblock ~172 ~123 ~43 dirt
setblock ~172 ~123 ~44 dirt
setblock ~172 ~123 ~45 dirt
setblock ~172 ~123 ~46 dirt
setblock ~172 ~123 ~47 dirt
setblock ~172 ~123 ~48 grass_block
setblock ~172 ~123 ~49 grass_block
setblock ~172 ~123 ~50 grass_block
setblock ~172 ~123 ~51 grass_block
setblock ~172 ~123 ~52 grass_block
setblock ~172 ~123 ~53 grass_block
setblock ~172 ~123 ~54 grass_block
setblock ~172 ~123 ~55 grass_block
setblock ~172 ~123 ~56 grass_block
setblock ~172 ~123 ~61 grass_block
setblock ~172 ~123 ~62 grass_block
setblock ~172 ~123 ~63 grass_block
setblock ~172 ~123 ~64 dirt
setblock ~172 ~123 ~65 dirt
setblock ~172 ~123 ~66 dirt
setblock ~172 ~123 ~67 dirt
setblock ~172 ~123 ~68 dirt
setblock ~172 ~123 ~69 dirt
setblock ~172 ~123 ~70 dirt
setblock ~172 ~123 ~71 dirt
setblock ~172 ~123 ~72 dirt
setblock ~172 ~123 ~73 dirt
setblock ~172 ~123 ~74 dirt
setblock ~172 ~123 ~75 dirt
setblock ~172 ~123 ~76 dirt
setblock ~172 ~123 ~77 dirt
setblock ~172 ~123 ~78 dirt
setblock ~172 ~123 ~79 grass_block
setblock ~172 ~123 ~80 grass_block
setblock ~172 ~123 ~81 grass_block
setblock ~172 ~123 ~82 grass_block
setblock ~172 ~123 ~83 dirt
setblock ~172 ~123 ~84 dirt
setblock ~172 ~123 ~85 dirt
setblock ~172 ~123 ~86 dirt
setblock ~172 ~123 ~87 dirt
setblock ~172 ~123 ~88 dirt
setblock ~172 ~123 ~89 dirt
setblock ~172 ~123 ~90 dirt
setblock ~172 ~123 ~91 dirt
setblock ~172 ~123 ~92 dirt
setblock ~172 ~123 ~93 dirt
setblock ~172 ~123 ~94 dirt
setblock ~172 ~123 ~95 dirt
setblock ~172 ~123 ~96 dirt
setblock ~172 ~123 ~97 dirt
setblock ~172 ~123 ~98 dirt
setblock ~172 ~123 ~99 dirt
setblock ~172 ~123 ~100 dirt
setblock ~172 ~123 ~101 dirt
setblock ~172 ~123 ~102 dirt
setblock ~172 ~123 ~103 dirt
setblock ~172 ~123 ~104 dirt
setblock ~172 ~123 ~105 dirt
setblock ~172 ~123 ~106 dirt
setblock ~172 ~123 ~107 dirt
setblock ~172 ~123 ~108 dirt
setblock ~172 ~123 ~109 grass_block
setblock ~172 ~123 ~110 grass_block
setblock ~172 ~123 ~111 grass_block
setblock ~172 ~123 ~112 dirt
setblock ~172 ~123 ~113 dirt
setblock ~172 ~123 ~114 dirt
setblock ~172 ~123 ~115 dirt
setblock ~172 ~123 ~116 dirt
setblock ~172 ~123 ~117 dirt
setblock ~172 ~123 ~118 dirt
setblock ~172 ~123 ~119 dirt
setblock ~172 ~123 ~120 dirt
setblock ~172 ~123 ~121 dirt
setblock ~172 ~123 ~122 dirt
setblock ~172 ~123 ~123 dirt
setblock ~172 ~123 ~124 dirt
setblock ~172 ~123 ~125 dirt
setblock ~172 ~123 ~126 dirt
setblock ~172 ~123 ~127 dirt
setblock ~172 ~123 ~128 dirt
setblock ~172 ~123 ~129 dirt
setblock ~172 ~123 ~130 dirt
setblock ~172 ~123 ~131 dirt
setblock ~172 ~123 ~132 dirt
setblock ~172 ~123 ~133 dirt
setblock ~172 ~123 ~134 dirt
setblock ~172 ~123 ~135 dirt
setblock ~172 ~123 ~136 dirt
setblock ~172 ~123 ~137 dirt
setblock ~172 ~123 ~138 dirt
setblock ~172 ~123 ~139 grass_block
setblock ~172 ~123 ~140 grass_block
setblock ~172 ~123 ~141 grass_block
setblock ~172 ~123 ~142 dirt
setblock ~172 ~123 ~143 dirt
setblock ~172 ~123 ~144 dirt
setblock ~172 ~123 ~145 dirt
setblock ~172 ~123 ~146 dirt
setblock ~172 ~123 ~147 dirt
setblock ~172 ~123 ~148 dirt
setblock ~172 ~123 ~149 dirt
setblock ~172 ~123 ~150 dirt
setblock ~172 ~123 ~151 dirt
setblock ~172 ~123 ~152 dirt
setblock ~172 ~123 ~153 dirt
setblock ~172 ~123 ~154 dirt
setblock ~172 ~123 ~155 dirt
setblock ~172 ~123 ~156 dirt
setblock ~172 ~123 ~157 dirt
setblock ~172 ~123 ~158 dirt
setblock ~172 ~123 ~159 grass_block
setblock ~172 ~123 ~160 grass_block
setblock ~172 ~123 ~161 dirt
setblock ~172 ~123 ~162 dirt
setblock ~172 ~123 ~163 dirt
setblock ~172 ~123 ~164 dirt
setblock ~172 ~123 ~165 dirt
setblock ~172 ~123 ~166 dirt
setblock ~172 ~123 ~167 dirt
setblock ~172 ~123 ~168 dirt
setblock ~172 ~123 ~169 dirt
setblock ~172 ~123 ~170 dirt
setblock ~172 ~123 ~171 dirt
setblock ~172 ~123 ~172 dirt
setblock ~172 ~123 ~173 dirt
setblock ~172 ~123 ~174 dirt
setblock ~172 ~123 ~175 dirt
setblock ~172 ~123 ~176 dirt
setblock ~172 ~123 ~177 dirt
setblock ~172 ~123 ~178 dirt
setblock ~172 ~123 ~179 dirt
setblock ~172 ~123 ~180 dirt
setblock ~172 ~123 ~181 dirt
setblock ~172 ~123 ~182 dirt
setblock ~172 ~123 ~183 dirt
setblock ~172 ~123 ~184 dirt
setblock ~172 ~123 ~185 dirt
setblock ~172 ~123 ~186 dirt
setblock ~172 ~123 ~187 dirt
setblock ~172 ~123 ~188 dirt
setblock ~172 ~123 ~189 dirt
setblock ~172 ~123 ~190 dirt
setblock ~172 ~123 ~191 dirt
setblock ~172 ~123 ~192 dirt
setblock ~172 ~123 ~193 dirt
setblock ~172 ~123 ~194 dirt
setblock ~172 ~123 ~195 dirt
setblock ~172 ~123 ~196 dirt
setblock ~172 ~123 ~197 dirt
setblock ~172 ~123 ~198 dirt
setblock ~172 ~123 ~199 dirt
setblock ~172 ~124 ~0 grass_block
setblock ~172 ~124 ~1 grass_block
setblock ~172 ~124 ~2 grass_block
setblock ~172 ~124 ~3 grass_block
setblock ~172 ~124 ~4 grass_block
setblock ~172 ~124 ~5 grass_block
setblock ~172 ~124 ~6 grass_block
setblock ~172 ~124 ~7 grass_block
setblock ~172 ~124 ~8 grass_block
setblock ~172 ~124 ~9 grass_block
setblock ~172 ~124 ~10 grass_block
setblock ~172 ~124 ~11 grass_block
setblock ~172 ~124 ~12 grass_block
setblock ~172 ~124 ~13 grass_block
setblock ~172 ~124 ~14 grass_block
setblock ~172 ~124 ~15 grass_block
setblock ~172 ~124 ~16 grass_block
setblock ~172 ~124 ~17 grass_block
setblock ~172 ~124 ~18 grass_block
setblock ~172 ~124 ~19 grass_block
setblock ~172 ~124 ~20 grass_block
setblock ~172 ~124 ~21 grass_block
setblock ~172 ~124 ~22 grass_block
setblock ~172 ~124 ~23 grass_block
setblock ~172 ~124 ~24 grass_block
setblock ~172 ~124 ~25 grass_block
setblock ~172 ~124 ~26 grass_block
setblock ~172 ~124 ~27 grass_block
setblock ~172 ~124 ~28 grass_block
setblock ~172 ~124 ~29 grass_block
setblock ~172 ~124 ~30 grass_block
setblock ~172 ~124 ~31 grass_block
setblock ~172 ~124 ~32 dirt
setblock ~172 ~124 ~33 dirt
setblock ~172 ~124 ~34 dirt
setblock ~172 ~124 ~35 dirt
setblock ~172 ~124 ~36 dirt
setblock ~172 ~124 ~37 dirt
setblock ~172 ~124 ~38 dirt
setblock ~172 ~124 ~39 dirt
setblock ~172 ~124 ~40 dirt
setblock ~172 ~124 ~41 dirt
setblock ~172 ~124 ~42 dirt
setblock ~172 ~124 ~43 grass_block
setblock ~172 ~124 ~44 grass_block
setblock ~172 ~124 ~45 grass_block
setblock ~172 ~124 ~46 grass_block
setblock ~172 ~124 ~47 grass_block
setblock ~172 ~124 ~50 short_grass
setblock ~172 ~124 ~53 short_grass
setblock ~172 ~124 ~54 short_grass
setblock ~172 ~124 ~55 short_grass
setblock ~172 ~124 ~61 short_grass
setblock ~172 ~124 ~62 short_grass
setblock ~172 ~124 ~63 short_grass
setblock ~172 ~124 ~64 grass_block
setblock ~172 ~124 ~65 grass_block
setblock ~172 ~124 ~66 dirt
setblock ~172 ~124 ~67 dirt
setblock ~172 ~124 ~68 dirt
setblock ~172 ~124 ~69 dirt
setblock ~172 ~124 ~70 dirt
setblock ~172 ~124 ~71 dirt
setblock ~172 ~124 ~72 dirt
setblock ~172 ~124 ~73 dirt
setblock ~172 ~124 ~74 dirt
setblock ~172 ~124 ~75 dirt
setblock ~172 ~124 ~76 grass_block
setblock ~172 ~124 ~77 grass_block
setblock ~172 ~124 ~78 grass_block
setblock ~172 ~124 ~80 short_grass
setblock ~172 ~124 ~83 grass_block
setblock ~172 ~124 ~84 grass_block
setblock ~172 ~124 ~85 grass_block
setblock ~172 ~124 ~86 grass_block
setblock ~172 ~124 ~87 dirt
setblock ~172 ~124 ~88 dirt
setblock ~172 ~124 ~89 dirt
setblock ~172 ~124 ~90 dirt
setblock ~172 ~124 ~91 dirt
setblock ~172 ~124 ~92 dirt
setblock ~172 ~124 ~93 dirt
setblock ~172 ~124 ~94 dirt
setblock ~172 ~124 ~95 dirt
setblock ~172 ~124 ~96 dirt
setblock ~172 ~124 ~97 dirt
setblock ~172 ~124 ~98 dirt
setblock ~172 ~124 ~99 dirt
setblock ~172 ~124 ~100 dirt
setblock ~172 ~124 ~101 dirt
setblock ~172 ~124 ~102 dirt
setblock ~172 ~124 ~103 dirt
setblock ~172 ~124 ~104 grass_block
setblock ~172 ~124 ~105 grass_block
setblock ~172 ~124 ~106 grass_block
setblock ~172 ~124 ~107 grass_block
setblock ~172 ~124 ~108 grass_block
setblock ~172 ~124 ~109 short_grass
setblock ~172 ~124 ~111 short_grass
setblock ~172 ~124 ~112 grass_block
setblock ~172 ~124 ~113 grass_block
setblock ~172 ~124 ~114 grass_block
setblock ~172 ~124 ~115 grass_block
setblock ~172 ~124 ~116 grass_block
setblock ~172 ~124 ~117 grass_block
setblock ~172 ~124 ~118 dirt
setblock ~172 ~124 ~119 dirt
setblock ~172 ~124 ~120 dirt
setblock ~172 ~124 ~121 dirt
setblock ~172 ~124 ~122 dirt
setblock ~172 ~124 ~123 dirt
setblock ~172 ~124 ~124 dirt
setblock ~172 ~124 ~125 dirt
setblock ~172 ~124 ~126 dirt
setblock ~172 ~124 ~127 dirt
setblock ~172 ~124 ~128 dirt
setblock ~172 ~124 ~129 dirt
setblock ~172 ~124 ~130 dirt
setblock ~172 ~124 ~131 dirt
setblock ~172 ~124 ~132 dirt
setblock ~172 ~124 ~133 dirt
setblock ~172 ~124 ~134 dirt
setblock ~172 ~124 ~135 dirt
setblock ~172 ~124 ~136 grass_block
setblock ~172 ~124 ~137 grass_block
setblock ~172 ~124 ~138 grass_block
setblock ~172 ~124 ~139 short_grass
setblock ~172 ~124 ~142 grass_block
setblock ~172 ~124 ~143 grass_block
setblock ~172 ~124 ~144 grass_block
setblock ~172 ~124 ~145 dirt
setblock ~172 ~124 ~146 dirt
setblock ~172 ~124 ~147 dirt
setblock ~172 ~124 ~148 dirt
setblock ~172 ~124 ~149 dirt
setblock ~172 ~124 ~150 dirt
setblock ~172 ~124 ~151 dirt
setblock ~172 ~124 ~152 dirt
setblock ~172 ~124 ~153 dirt
setblock ~172 ~124 ~154 dirt
setblock ~172 ~124 ~155 dirt
setblock ~172 ~124 ~156 grass_block
setblock ~172 ~124 ~157 grass_block
setblock ~172 ~124 ~158 grass_block
setblock ~172 ~124 ~159 fern
setblock ~172 ~124 ~161 grass_block
setblock ~172 ~124 ~162 grass_block
setblock ~172 ~124 ~163 grass_block
setblock ~172 ~124 ~164 dirt
setblock ~172 ~124 ~165 dirt
setblock ~172 ~124 ~166 dirt
setblock ~172 ~124 ~167 dirt
setblock ~172 ~124 ~168 dirt
setblock ~172 ~124 ~169 dirt
setblock ~172 ~124 ~170 dirt
setblock ~172 ~124 ~171 dirt
setblock ~172 ~124 ~172 dirt
setblock ~172 ~124 ~173 dirt
setblock ~172 ~124 ~174 dirt
setblock ~172 ~124 ~175 dirt
setblock ~172 ~124 ~176 dirt
setblock ~172 ~124 ~177 dirt
setblock ~172 ~124 ~178 dirt
setblock ~172 ~124 ~179 dirt
setblock ~172 ~124 ~180 dirt
setblock ~172 ~124 ~181 dirt
setblock ~172 ~124 ~182 dirt
setblock ~172 ~124 ~183 dirt
setblock ~172 ~124 ~184 dirt
setblock ~172 ~124 ~185 dirt
setblock ~172 ~124 ~186 dirt
setblock ~172 ~124 ~187 dirt
setblock ~172 ~124 ~188 dirt
setblock ~172 ~124 ~189 dirt
setblock ~172 ~124 ~190 dirt
setblock ~172 ~124 ~191 dirt
setblock ~172 ~124 ~192 dirt
setblock ~172 ~124 ~193 dirt
setblock ~172 ~124 ~194 dirt
setblock ~172 ~124 ~195 dirt
setblock ~172 ~124 ~196 dirt
setblock ~172 ~124 ~197 dirt
setblock ~172 ~124 ~198 dirt
setblock ~172 ~124 ~199 dirt
setblock ~172 ~125 ~0 short_grass
setblock ~172 ~125 ~2 poppy
setblock ~172 ~125 ~6 short_grass
setblock ~172 ~125 ~9 short_grass
setblock ~172 ~125 ~11 short_grass
setblock ~172 ~125 ~14 poppy
setblock ~172 ~125 ~18 short_grass
setblock ~172 ~125 ~22 short_grass
setblock ~172 ~125 ~25 short_grass
setblock ~172 ~125 ~28 fern
setblock ~172 ~125 ~29 short_grass
setblock ~172 ~125 ~32 grass_block
setblock ~172 ~125 ~33 grass_block
setblock ~172 ~125 ~34 grass_block
setblock ~172 ~125 ~35 grass_block
setblock ~172 ~125 ~36 grass_block
setblock ~172 ~125 ~37 grass_block
setblock ~172 ~125 ~38 grass_block
setblock ~172 ~125 ~39 grass_block
setblock ~172 ~125 ~40 grass_block
setblock ~172 ~125 ~41 grass_block
setblock ~172 ~125 ~42 grass_block
setblock ~172 ~125 ~47 short_grass
setblock ~172 ~125 ~66 grass_block
setblock ~172 ~125 ~67 dirt
setblock ~172 ~125 ~68 dirt
setblock ~172 ~125 ~69 dirt
setblock ~172 ~125 ~70 dirt
setblock ~172 ~125 ~71 dirt
setblock ~172 ~125 ~72 dirt
setblock ~172 ~125 ~73 dirt
setblock ~172 ~125 ~74 grass_block
setblock ~172 ~125 ~75 grass_block
setblock ~172 ~125 ~77 short_grass
setblock ~172 ~125 ~84 short_grass
setblock ~172 ~125 ~85 short_grass
setblock ~172 ~125 ~86 short_grass
setblock ~172 ~125 ~87 grass_block
setblock ~172 ~125 ~88 grass_block
setblock ~172 ~125 ~89 grass_block
setblock ~172 ~125 ~90 dirt
setblock ~172 ~125 ~91 dirt
setblock ~172 ~125 ~92 dirt
setblock ~172 ~125 ~93 dirt
setblock ~172 ~125 ~94 dirt
setblock ~172 ~125 ~95 dirt
setblock ~172 ~125 ~96 grass_block
setblock ~172 ~125 ~97 grass_block
setblock ~172 ~125 ~98 grass_block
setblock ~172 ~125 ~99 grass_block
setblock ~172 ~125 ~100 grass_block
setblock ~172 ~125 ~101 grass_block
setblock ~172 ~125 ~102 grass_block
setblock ~172 ~125 ~103 grass_block
setblock ~172 ~125 ~105 fern
setblock ~172 ~125 ~113 short_grass
setblock ~172 ~125 ~114 short_grass
setblock ~172 ~125 ~116 poppy
setblock ~172 ~125 ~118 grass_block
setblock ~172 ~125 ~119 grass_block
setblock ~172 ~125 ~120 grass_block
setblock ~172 ~125 ~121 grass_block
setblock ~172 ~125 ~122 grass_block
setblock ~172 ~125 ~123 grass_block
setblock ~172 ~125 ~124 grass_block
setblock ~172 ~125 ~125 dirt
setblock ~172 ~125 ~126 dirt
setblock ~172 ~125 ~127 dirt
setblock ~172 ~125 ~128 dirt
setblock ~172 ~125 ~129 dirt
setblock ~172 ~125 ~130 dirt
setblock ~172 ~125 ~131 dirt
setblock ~172 ~125 ~132 dirt
setblock ~172 ~125 ~133 grass_block
setblock ~172 ~125 ~134 grass_block
setblock ~172 ~125 ~135 grass_block
setblock ~172 ~125 ~142 short_grass
setblock ~172 ~125 ~144 short_grass
setblock ~172 ~125 ~145 grass_block
setblock ~172 ~125 ~146 grass_block
setblock ~172 ~125 ~147 grass_block
setblock ~172 ~125 ~148 grass_block
setblock ~172 ~125 ~149 dirt
setblock ~172 ~125 ~150 dirt
setblock ~172 ~125 ~151 dirt
setblock ~172 ~125 ~152 grass_block
setblock ~172 ~125 ~153 grass_block
setblock ~172 ~125 ~154 grass_block
setblock ~172 ~125 ~155 grass_block
setblock ~172 ~125 ~157 fern
setblock ~172 ~125 ~161 fern
setblock ~172 ~125 ~162 short_grass
setblock ~172 ~125 ~163 poppy
setblock ~172 ~125 ~164 grass_block
setblock ~172 ~125 ~165 grass_block
setblock ~172 ~125 ~166 dirt
setblock ~172 ~125 ~167 dirt
setblock ~172 ~125 ~168 dirt
setblock ~172 ~125 ~169 dirt
setblock ~172 ~125 ~170 dirt
setblock ~172 ~125 ~171 dirt
setblock ~172 ~125 ~172 dirt
setblock ~172 ~125 ~173 dirt
setblock ~172 ~125 ~174 dirt
setblock ~172 ~125 ~175 dirt
setblock ~172 ~125 ~176 dirt
setblock ~172 ~125 ~177 dirt
setblock ~172 ~125 ~178 grass_block
setblock ~172 ~125 ~179 grass_block
setblock ~172 ~125 ~180 grass_block
setblock ~172 ~125 ~181 grass_block
setblock ~172 ~125 ~182 dirt
setblock ~172 ~125 ~183 dirt
setblock ~172 ~125 ~184 dirt
setblock ~172 ~125 ~185 dirt
setblock ~172 ~125 ~186 dirt
setblock ~172 ~125 ~187 dirt
setblock ~172 ~125 ~188 dirt
setblock ~172 ~125 ~189 dirt
setblock ~172 ~125 ~190 dirt
setblock ~172 ~125 ~191 dirt
setblock ~172 ~125 ~192 dirt
setblock ~172 ~125 ~193 dirt
setblock ~172 ~125 ~194 dirt
setblock ~172 ~125 ~195 dirt
setblock ~172 ~125 ~196 dirt
setblock ~172 ~125 ~197 dirt
setblock ~172 ~125 ~198 dirt
setblock ~172 ~125 ~199 dirt
setblock ~172 ~126 ~36 short_grass
setblock ~172 ~126 ~37 short_grass
setblock ~172 ~126 ~39 short_grass
setblock ~172 ~126 ~67 grass_block
setblock ~172 ~126 ~68 grass_block
setblock ~172 ~126 ~69 dirt
setblock ~172 ~126 ~70 dirt
setblock ~172 ~126 ~71 dirt
setblock ~172 ~126 ~72 grass_block
setblock ~172 ~126 ~73 grass_block
setblock ~172 ~126 ~74 short_grass
setblock ~172 ~126 ~75 short_grass
setblock ~172 ~126 ~88 short_grass
setblock ~172 ~126 ~90 grass_block
setblock ~172 ~126 ~91 grass_block
setblock ~172 ~126 ~92 grass_block
setblock ~172 ~126 ~93 grass_block
setblock ~172 ~126 ~94 grass_block
setblock ~172 ~126 ~95 grass_block
setblock ~172 ~126 ~98 poppy
setblock ~172 ~126 ~102 short_grass
setblock ~172 ~126 ~103 fern
setblock ~172 ~126 ~125 grass_block
setblock ~172 ~126 ~126 grass_block
setblock ~172 ~126 ~127 grass_block
setblock ~172 ~126 ~128 grass_block
setblock ~172 ~126 ~129 dirt
setblock ~172 ~126 ~130 dirt
setblock ~172 ~126 ~131 grass_block
setblock ~172 ~126 ~132 grass_block
setblock ~172 ~126 ~133 short_grass
setblock ~172 ~126 ~145 fern
setblock ~172 ~126 ~148 short_grass
setblock ~172 ~126 ~149 grass_block
setblock ~172 ~126 ~150 grass_block
setblock ~172 ~126 ~151 grass_block
setblock ~172 ~126 ~155 short_grass
setblock ~172 ~126 ~166 grass_block
setblock ~172 ~126 ~167 grass_block
setblock ~172 ~126 ~168 grass_block
setblock ~172 ~126 ~169 dirt
setblock ~172 ~126 ~170 dirt
setblock ~172 ~126 ~171 dirt
setblock ~172 ~126 ~172 dirt
setblock ~172 ~126 ~173 grass_block
setblock ~172 ~126 ~174 grass_block
setblock ~172 ~126 ~175 grass_block
setblock ~172 ~126 ~176 grass_block
setblock ~172 ~126 ~177 grass_block
setblock ~172 ~126 ~182 grass_block
setblock ~172 ~126 ~183 grass_block
setblock ~172 ~126 ~184 grass_block
setblock ~172 ~126 ~185 grass_block
setblock ~172 ~126 ~186 grass_block
setblock ~172 ~126 ~187 dirt
setblock ~172 ~126 ~188 dirt
setblock ~172 ~126 ~189 dirt
setblock ~172 ~126 ~190 dirt
setblock ~172 ~126 ~191 dirt
setblock ~172 ~126 ~192 dirt
setblock ~172 ~126 ~193 dirt
setblock ~172 ~126 ~194 dirt
setblock ~172 ~126 ~195 dirt
setblock ~172 ~126 ~196 dirt
setblock ~172 ~126 ~197 dirt
setblock ~172 ~126 ~198 dirt
setblock ~172 ~126 ~199 dirt
setblock ~172 ~127 ~69 grass_block
setblock ~172 ~127 ~70 dirt
setblock ~172 ~127 ~71 grass_block
setblock ~172 ~127 ~91 fern
setblock ~172 ~127 ~94 short_grass
setblock ~172 ~127 ~95 short_grass
setblock ~172 ~127 ~125 short_grass
setblock ~172 ~127 ~129 grass_block
setblock ~172 ~127 ~130 grass_block
setblock ~172 ~127 ~132 short_grass
setblock ~172 ~127 ~149 short_grass
setblock ~172 ~127 ~167 short_grass
setblock ~172 ~127 ~169 grass_block
setblock ~172 ~127 ~170 grass_block
setblock ~172 ~127 ~171 grass_block
setblock ~172 ~127 ~172 grass_block
setblock ~172 ~127 ~175 short_grass
setblock ~172 ~127 ~184 short_grass
setblock ~172 ~127 ~187 grass_block
setblock ~172 ~127 ~188 grass_block
setblock ~172 ~127 ~189 grass_block
setblock ~172 ~127 ~190 grass_block
setblock ~172 ~127 ~191 grass_block
setblock ~172 ~127 ~192 grass_block
setblock ~172 ~127 ~193 grass_block
setblock ~172 ~127 ~194 grass_block
setblock ~172 ~127 ~195 grass_block
setblock ~172 ~127 ~196 grass_block
setblock ~172 ~127 ~197 grass_block
setblock ~172 ~127 ~198 grass_block
setblock ~172 ~127 ~199 grass_block
setblock ~172 ~128 ~70 grass_block
setblock ~172 ~128 ~188 short_grass
setblock ~172 ~128 ~191 short_grass
setblock ~172 ~128 ~193 fern
setblock ~172 ~128 ~195 short_grass
setblock ~172 ~128 ~196 short_grass
setblock ~172 ~128 ~199 short_grass
setblock ~173 ~122 ~0 dirt
setblock ~173 ~122 ~1 dirt
setblock ~173 ~122 ~2 dirt
setblock ~173 ~122 ~3 dirt
setblock ~173 ~122 ~4 dirt
setblock ~173 ~122 ~5 dirt
setblock ~173 ~122 ~6 dirt
setblock ~173 ~122 ~7 dirt
setblock ~173 ~122 ~8 dirt
setblock ~173 ~122 ~9 dirt
setblock ~173 ~122 ~10 dirt
setblock ~173 ~122 ~11 dirt
setblock ~173 ~122 ~12 dirt
setblock ~173 ~122 ~13 dirt
setblock ~173 ~122 ~14 dirt
setblock ~173 ~122 ~15 dirt
setblock ~173 ~122 ~16 dirt
setblock ~173 ~122 ~17 dirt
setblock ~173 ~122 ~18 dirt
setblock ~173 ~122 ~19 dirt
setblock ~173 ~122 ~20 dirt
setblock ~173 ~122 ~21 dirt
setblock ~173 ~122 ~22 dirt
setblock ~173 ~122 ~23 dirt
setblock ~173 ~122 ~24 dirt
setblock ~173 ~122 ~25 dirt
setblock ~173 ~122 ~26 dirt
setblock ~173 ~122 ~27 dirt
setblock ~173 ~122 ~28 dirt
setblock ~173 ~122 ~29 dirt
setblock ~173 ~122 ~30 dirt
setblock ~173 ~122 ~31 dirt
setblock ~173 ~122 ~32 dirt
setblock ~173 ~122 ~33 dirt
setblock ~173 ~122 ~34 dirt
setblock ~173 ~122 ~35 dirt
setblock ~173 ~122 ~36 dirt
setblock ~173 ~122 ~37 dirt
setblock ~173 ~122 ~38 dirt
setblock ~173 ~122 ~39 dirt
setblock ~173 ~122 ~40 dirt
setblock ~173 ~122 ~41 dirt
setblock ~173 ~122 ~42 dirt
setblock ~173 ~122 ~43 dirt
setblock ~173 ~122 ~44 dirt
setblock ~173 ~122 ~45 dirt
setblock ~173 ~122 ~46 dirt
setblock ~173 ~122 ~47 dirt
setblock ~173 ~122 ~48 dirt
setblock ~173 ~122 ~49 dirt
setblock ~173 ~122 ~50 dirt
setblock ~173 ~122 ~51 dirt
setblock ~173 ~122 ~52 dirt
setblock ~173 ~122 ~53 dirt
setblock ~173 ~122 ~54 dirt
setblock ~173 ~122 ~55 dirt
setblock ~173 ~122 ~56 dirt
setblock ~173 ~122 ~57 dirt
setblock ~173 ~122 ~58 dirt
