setblock ~185 ~124 ~115 grass_block
setblock ~185 ~124 ~120 dirt
setblock ~185 ~124 ~121 dirt
setblock ~185 ~124 ~130 dirt
setblock ~185 ~125 ~71 short_grass
setblock ~185 ~125 ~72 short_grass
setblock ~185 ~125 ~85 grass_block
setblock ~185 ~125 ~86 grass_block
setblock ~185 ~125 ~87 grass_block
setblock ~185 ~125 ~88 grass_block
setblock ~185 ~125 ~89 grass_block
setblock ~185 ~125 ~90 grass_block
setblock ~185 ~125 ~91 grass_block
setblock ~185 ~125 ~92 grass_block
setblock ~185 ~125 ~93 grass_block
setblock ~185 ~125 ~94 grass_block
setblock ~185 ~125 ~95 grass_block
setblock ~185 ~125 ~96 grass_block
setblock ~185 ~125 ~97 grass_block
setblock ~185 ~125 ~98 grass_block
setblock ~185 ~125 ~99 grass_block
setblock ~185 ~125 ~100 grass_block
setblock ~185 ~125 ~101 grass_block
setblock ~185 ~125 ~102 grass_block
setblock ~185 ~125 ~103 grass_block
setblock ~185 ~125 ~104 grass_block
setblock ~185 ~125 ~105 short_grass
setblock ~185 ~125 ~106 poppy
setblock ~185 ~125 ~120 grass_block
setblock ~185 ~125 ~121 grass_block
setblock ~185 ~125 ~130 grass_block
setblock ~185 ~126 ~89 short_grass
setblock ~185 ~126 ~90 short_grass
setblock ~185 ~126 ~97 short_grass
setblock ~185 ~126 ~98 short_grass
setblock ~185 ~126 ~102 short_grass
setblock ~185 ~126 ~104 short_grass
setblock ~185 ~126 ~120 short_grass
setblock ~185 ~126 ~121 short_grass
setblock ~186 ~113 ~94 dirt
setblock ~186 ~113 ~95 dirt
setblock ~186 ~113 ~96 dirt
setblock ~186 ~113 ~97 dirt
setblock ~186 ~113 ~98 dirt
setblock ~186 ~113 ~99 dirt
setblock ~186 ~114 ~93 dirt
setblock ~186 ~114 ~94 dirt
setblock ~186 ~114 ~95 dirt
setblock ~186 ~114 ~96 dirt
setblock ~186 ~114 ~97 dirt
setblock ~186 ~114 ~98 dirt
setblock ~186 ~114 ~99 dirt
setblock ~186 ~114 ~100 dirt
setblock ~186 ~115 ~92 dirt
setblock ~186 ~115 ~93 dirt
setblock ~186 ~115 ~94 dirt
setblock ~186 ~115 ~95 dirt
setblock ~186 ~115 ~96 dirt
setblock ~186 ~115 ~97 dirt
setblock ~186 ~115 ~98 dirt
setblock ~186 ~115 ~99 dirt
setblock ~186 ~115 ~100 dirt
setblock ~186 ~115 ~101 dirt
setblock ~186 ~116 ~91 dirt
setblock ~186 ~116 ~92 dirt
setblock ~186 ~116 ~93 dirt
setblock ~186 ~116 ~94 dirt
setblock ~186 ~116 ~95 dirt
setblock ~186 ~116 ~96 dirt
setblock ~186 ~116 ~97 dirt
setblock ~186 ~116 ~98 dirt
setblock ~186 ~116 ~99 dirt
setblock ~186 ~116 ~100 dirt
setblock ~186 ~116 ~101 dirt
setblock ~186 ~116 ~102 dirt
setblock ~186 ~117 ~89 dirt
setblock ~186 ~117 ~90 dirt
setblock ~186 ~117 ~91 dirt
setblock ~186 ~117 ~92 dirt
setblock ~186 ~117 ~93 dirt
setblock ~186 ~117 ~94 dirt
setblock ~186 ~117 ~95 dirt
setblock ~186 ~117 ~96 dirt
setblock ~186 ~117 ~97 dirt
setblock ~186 ~117 ~98 dirt
setblock ~186 ~117 ~99 dirt
setblock ~186 ~117 ~100 dirt
setblock ~186 ~117 ~101 dirt
setblock ~186 ~117 ~102 dirt
setblock ~186 ~117 ~103 dirt
setblock ~186 ~118 ~88 dirt
setblock ~186 ~118 ~89 dirt
setblock ~186 ~118 ~90 dirt
setblock ~186 ~118 ~91 dirt
setblock ~186 ~118 ~92 dirt
setblock ~186 ~118 ~93 dirt
setblock ~186 ~118 ~94 dirt
setblock ~186 ~118 ~95 dirt
setblock ~186 ~118 ~96 dirt
setblock ~186 ~118 ~97 dirt
setblock ~186 ~118 ~98 dirt
setblock ~186 ~118 ~99 dirt
setblock ~186 ~118 ~100 dirt
setblock ~186 ~118 ~101 dirt
setblock ~186 ~118 ~102 dirt
setblock ~186 ~118 ~103 dirt
setblock ~186 ~118 ~104 dirt
setblock ~186 ~118 ~105 dirt
setblock ~186 ~118 ~106 dirt
setblock ~186 ~119 ~87 dirt
setblock ~186 ~119 ~88 dirt
setblock ~186 ~119 ~89 dirt
setblock ~186 ~119 ~90 dirt
setblock ~186 ~119 ~91 dirt
setblock ~186 ~119 ~92 dirt
setblock ~186 ~119 ~93 dirt
setblock ~186 ~119 ~94 dirt
setblock ~186 ~119 ~95 dirt
setblock ~186 ~119 ~96 dirt
setblock ~186 ~119 ~97 dirt
setblock ~186 ~119 ~98 dirt
setblock ~186 ~119 ~99 dirt
setblock ~186 ~119 ~100 dirt
setblock ~186 ~119 ~101 dirt
setblock ~186 ~119 ~102 dirt
setblock ~186 ~119 ~103 dirt
setblock ~186 ~119 ~104 dirt
setblock ~186 ~119 ~105 dirt
setblock ~186 ~119 ~106 dirt
setblock ~186 ~119 ~107 dirt
setblock ~186 ~119 ~115 dirt
setblock ~186 ~120 ~72 dirt
setblock ~186 ~120 ~86 dirt
setblock ~186 ~120 ~87 dirt
setblock ~186 ~120 ~88 dirt
setblock ~186 ~120 ~89 dirt
setblock ~186 ~120 ~90 dirt
setblock ~186 ~120 ~91 dirt
setblock ~186 ~120 ~92 dirt
setblock ~186 ~120 ~93 dirt
setblock ~186 ~120 ~94 dirt
setblock ~186 ~120 ~95 dirt
setblock ~186 ~120 ~96 dirt
setblock ~186 ~120 ~97 dirt
setblock ~186 ~120 ~98 dirt
setblock ~186 ~120 ~99 dirt
setblock ~186 ~120 ~100 dirt
setblock ~186 ~120 ~101 dirt
setblock ~186 ~120 ~102 dirt
setblock ~186 ~120 ~103 dirt
setblock ~186 ~120 ~104 dirt
setblock ~186 ~120 ~105 dirt
setblock ~186 ~120 ~106 dirt
setblock ~186 ~120 ~107 dirt
setblock ~186 ~120 ~108 dirt
setblock ~186 ~120 ~109 dirt
setblock ~186 ~120 ~114 dirt
setblock ~186 ~120 ~115 dirt
setblock ~186 ~120 ~116 dirt
setblock ~186 ~121 ~71 dirt
setblock ~186 ~121 ~72 dirt
setblock ~186 ~121 ~85 dirt
setblock ~186 ~121 ~86 dirt
setblock ~186 ~121 ~87 dirt
setblock ~186 ~121 ~88 dirt
setblock ~186 ~121 ~89 dirt
setblock ~186 ~121 ~90 dirt
setblock ~186 ~121 ~91 dirt
setblock ~186 ~121 ~92 dirt
setblock ~186 ~121 ~93 dirt
setblock ~186 ~121 ~94 dirt
setblock ~186 ~121 ~95 dirt
setblock ~186 ~121 ~96 dirt
setblock ~186 ~121 ~97 dirt
setblock ~186 ~121 ~98 dirt
setblock ~186 ~121 ~99 dirt
setblock ~186 ~121 ~100 dirt
setblock ~186 ~121 ~101 dirt
setblock ~186 ~121 ~102 dirt
setblock ~186 ~121 ~103 dirt
setblock ~186 ~121 ~104 dirt
setblock ~186 ~121 ~105 dirt
setblock ~186 ~121 ~106 dirt
setblock ~186 ~121 ~107 dirt
setblock ~186 ~121 ~108 dirt
setblock ~186 ~121 ~109 dirt
setblock ~186 ~121 ~110 dirt
setblock ~186 ~121 ~114 dirt
setblock ~186 ~121 ~115 dirt
setblock ~186 ~121 ~116 dirt
setblock ~186 ~122 ~71 dirt
setblock ~186 ~122 ~72 dirt
setblock ~186 ~122 ~85 dirt
setblock ~186 ~122 ~86 dirt
setblock ~186 ~122 ~87 dirt
setblock ~186 ~122 ~88 dirt
setblock ~186 ~122 ~89 dirt
setblock ~186 ~122 ~90 dirt
setblock ~186 ~122 ~91 dirt
setblock ~186 ~122 ~92 dirt
setblock ~186 ~122 ~93 dirt
setblock ~186 ~122 ~94 dirt
setblock ~186 ~122 ~95 dirt
setblock ~186 ~122 ~96 dirt
setblock ~186 ~122 ~97 dirt
setblock ~186 ~122 ~98 dirt
setblock ~186 ~122 ~99 dirt
setblock ~186 ~122 ~100 dirt
setblock ~186 ~122 ~101 dirt
setblock ~186 ~122 ~102 dirt
setblock ~186 ~122 ~103 dirt
setblock ~186 ~122 ~104 dirt
setblock ~186 ~122 ~105 dirt
setblock ~186 ~122 ~106 dirt
setblock ~186 ~122 ~107 dirt
setblock ~186 ~122 ~108 dirt
setblock ~186 ~122 ~109 dirt
setblock ~186 ~122 ~110 dirt
setblock ~186 ~122 ~114 dirt
setblock ~186 ~122 ~115 dirt
setblock ~186 ~122 ~116 dirt
setblock ~186 ~123 ~71 dirt
setblock ~186 ~123 ~72 dirt
setblock ~186 ~123 ~85 dirt
setblock ~186 ~123 ~86 dirt
setblock ~186 ~123 ~87 dirt
setblock ~186 ~123 ~88 dirt
setblock ~186 ~123 ~89 dirt
setblock ~186 ~123 ~90 dirt
setblock ~186 ~123 ~91 dirt
setblock ~186 ~123 ~92 dirt
setblock ~186 ~123 ~93 dirt
setblock ~186 ~123 ~94 dirt
setblock ~186 ~123 ~95 dirt
setblock ~186 ~123 ~96 dirt
setblock ~186 ~123 ~97 dirt
setblock ~186 ~123 ~98 dirt
setblock ~186 ~123 ~99 dirt
setblock ~186 ~123 ~100 dirt
setblock ~186 ~123 ~101 dirt
setblock ~186 ~123 ~102 dirt
setblock ~186 ~123 ~103 dirt
setblock ~186 ~123 ~104 dirt
setblock ~186 ~123 ~105 dirt
setblock ~186 ~123 ~106 dirt
setblock ~186 ~123 ~107 dirt
setblock ~186 ~123 ~108 grass_block
setblock ~186 ~123 ~109 grass_block
setblock ~186 ~123 ~110 grass_block
setblock ~186 ~123 ~114 dirt
setblock ~186 ~123 ~115 dirt
setblock ~186 ~123 ~116 dirt
setblock ~186 ~124 ~71 grass_block
setblock ~186 ~124 ~72 grass_block
setblock ~186 ~124 ~85 dirt
setblock ~186 ~124 ~86 dirt
setblock ~186 ~124 ~87 dirt
setblock ~186 ~124 ~88 dirt
setblock ~186 ~124 ~89 dirt
setblock ~186 ~124 ~90 dirt
setblock ~186 ~124 ~91 dirt
setblock ~186 ~124 ~92 dirt
setblock ~186 ~124 ~93 dirt
setblock ~186 ~124 ~94 dirt
setblock ~186 ~124 ~95 dirt
setblock ~186 ~124 ~96 dirt
setblock ~186 ~124 ~97 dirt
setblock ~186 ~124 ~98 dirt
setblock ~186 ~124 ~99 dirt
setblock ~186 ~124 ~100 dirt
setblock ~186 ~124 ~101 dirt
setblock ~186 ~124 ~102 dirt
setblock ~186 ~124 ~103 dirt
setblock ~186 ~124 ~104 grass_block
setblock ~186 ~124 ~105 grass_block
setblock ~186 ~124 ~106 grass_block
setblock ~186 ~124 ~107 grass_block
setblock ~186 ~124 ~108 short_grass
setblock ~186 ~124 ~109 short_grass
setblock ~186 ~124 ~114 grass_block
setblock ~186 ~124 ~115 grass_block
setblock ~186 ~124 ~116 grass_block
setblock ~186 ~125 ~85 grass_block
setblock ~186 ~125 ~86 grass_block
setblock ~186 ~125 ~87 grass_block
setblock ~186 ~125 ~88 grass_block
setblock ~186 ~125 ~89 dirt
setblock ~186 ~125 ~90 dirt
setblock ~186 ~125 ~91 dirt
setblock ~186 ~125 ~92 dirt
setblock ~186 ~125 ~93 grass_block
setblock ~186 ~125 ~94 grass_block
setblock ~186 ~125 ~95 grass_block
setblock ~186 ~125 ~96 grass_block
setblock ~186 ~125 ~97 grass_block
setblock ~186 ~125 ~98 grass_block
setblock ~186 ~125 ~99 grass_block
setblock ~186 ~125 ~100 grass_block
setblock ~186 ~125 ~101 grass_block
setblock ~186 ~125 ~102 grass_block
setblock ~186 ~125 ~103 grass_block
setblock ~186 ~125 ~107 short_grass
setblock ~186 ~126 ~86 short_grass
setblock ~186 ~126 ~89 grass_block
setblock ~186 ~126 ~90 grass_block
setblock ~186 ~126 ~91 grass_block
setblock ~186 ~126 ~92 grass_block
setblock ~186 ~126 ~102 poppy
setblock ~186 ~127 ~89 poppy
setblock ~187 ~114 ~94 dirt
setblock ~187 ~114 ~95 dirt
setblock ~187 ~114 ~96 dirt
setblock ~187 ~114 ~98 dirt
setblock ~187 ~114 ~99 dirt
setblock ~187 ~115 ~93 dirt
setblock ~187 ~115 ~94 dirt
setblock ~187 ~115 ~95 dirt
setblock ~187 ~115 ~96 dirt
setblock ~187 ~115 ~97 dirt
setblock ~187 ~115 ~98 dirt
setblock ~187 ~115 ~99 dirt
setblock ~187 ~115 ~100 dirt
setblock ~187 ~116 ~92 dirt
setblock ~187 ~116 ~93 dirt
setblock ~187 ~116 ~94 dirt
setblock ~187 ~116 ~95 dirt
setblock ~187 ~116 ~96 dirt
setblock ~187 ~116 ~97 dirt
setblock ~187 ~116 ~98 dirt
setblock ~187 ~116 ~99 dirt
setblock ~187 ~116 ~100 dirt
setblock ~187 ~116 ~101 dirt
setblock ~187 ~117 ~91 dirt
setblock ~187 ~117 ~92 dirt
setblock ~187 ~117 ~93 dirt
setblock ~187 ~117 ~94 dirt
setblock ~187 ~117 ~95 dirt
setblock ~187 ~117 ~96 dirt
setblock ~187 ~117 ~97 dirt
setblock ~187 ~117 ~98 dirt
setblock ~187 ~117 ~99 dirt
setblock ~187 ~117 ~100 dirt
setblock ~187 ~117 ~101 dirt
setblock ~187 ~117 ~102 dirt
setblock ~187 ~117 ~116 dirt
setblock ~187 ~118 ~90 dirt
setblock ~187 ~118 ~91 dirt
setblock ~187 ~118 ~92 dirt
setblock ~187 ~118 ~93 dirt
setblock ~187 ~118 ~94 dirt
setblock ~187 ~118 ~95 dirt
setblock ~187 ~118 ~96 dirt
setblock ~187 ~118 ~97 dirt
setblock ~187 ~118 ~98 dirt
setblock ~187 ~118 ~99 dirt
setblock ~187 ~118 ~100 dirt
setblock ~187 ~118 ~101 dirt
setblock ~187 ~118 ~102 dirt
setblock ~187 ~118 ~103 dirt
setblock ~187 ~118 ~115 dirt
setblock ~187 ~118 ~116 dirt
setblock ~187 ~119 ~88 dirt
setblock ~187 ~119 ~89 dirt
setblock ~187 ~119 ~90 dirt
setblock ~187 ~119 ~91 dirt
setblock ~187 ~119 ~92 dirt
setblock ~187 ~119 ~93 dirt
setblock ~187 ~119 ~94 dirt
setblock ~187 ~119 ~95 dirt
setblock ~187 ~119 ~96 dirt
setblock ~187 ~119 ~97 dirt
setblock ~187 ~119 ~98 dirt
setblock ~187 ~119 ~99 dirt
setblock ~187 ~119 ~100 dirt
setblock ~187 ~119 ~101 dirt
setblock ~187 ~119 ~102 dirt
setblock ~187 ~119 ~103 dirt
setblock ~187 ~119 ~104 dirt
setblock ~187 ~119 ~105 dirt
setblock ~187 ~119 ~106 dirt
setblock ~187 ~119 ~114 dirt
setblock ~187 ~119 ~115 dirt
setblock ~187 ~119 ~116 dirt
setblock ~187 ~120 ~87 dirt
setblock ~187 ~120 ~88 dirt
setblock ~187 ~120 ~89 dirt
setblock ~187 ~120 ~90 dirt
setblock ~187 ~120 ~91 dirt
setblock ~187 ~120 ~92 dirt
setblock ~187 ~120 ~93 dirt
setblock ~187 ~120 ~94 dirt
setblock ~187 ~120 ~95 dirt
setblock ~187 ~120 ~96 dirt
setblock ~187 ~120 ~97 dirt
setblock ~187 ~120 ~98 dirt
setblock ~187 ~120 ~99 dirt
setblock ~187 ~120 ~100 dirt
setblock ~187 ~120 ~101 dirt
setblock ~187 ~120 ~102 dirt
setblock ~187 ~120 ~103 dirt
setblock ~187 ~120 ~104 dirt
setblock ~187 ~120 ~105 dirt
setblock ~187 ~120 ~106 dirt
setblock ~187 ~120 ~107 dirt
setblock ~187 ~120 ~114 dirt
setblock ~187 ~120 ~115 dirt
setblock ~187 ~120 ~116 dirt
setblock ~187 ~121 ~86 dirt
setblock ~187 ~121 ~87 dirt
setblock ~187 ~121 ~88 dirt
setblock ~187 ~121 ~89 dirt
setblock ~187 ~121 ~90 dirt
setblock ~187 ~121 ~91 dirt
setblock ~187 ~121 ~92 dirt
setblock ~187 ~121 ~93 dirt
setblock ~187 ~121 ~94 dirt
setblock ~187 ~121 ~95 dirt
setblock ~187 ~121 ~96 dirt
setblock ~187 ~121 ~97 dirt
setblock ~187 ~121 ~98 dirt
setblock ~187 ~121 ~99 dirt
setblock ~187 ~121 ~100 dirt
setblock ~187 ~121 ~101 dirt
setblock ~187 ~121 ~102 dirt
setblock ~187 ~121 ~103 dirt
setblock ~187 ~121 ~104 dirt
setblock ~187 ~121 ~105 dirt
setblock ~187 ~121 ~106 dirt
setblock ~187 ~121 ~107 dirt
setblock ~187 ~121 ~108 dirt
setblock ~187 ~121 ~109 dirt
setblock ~187 ~121 ~114 dirt
setblock ~187 ~121 ~115 dirt
setblock ~187 ~121 ~116 dirt
setblock ~187 ~121 ~117 dirt
setblock ~187 ~122 ~86 dirt
setblock ~187 ~122 ~87 dirt
setblock ~187 ~122 ~88 dirt
setblock ~187 ~122 ~89 dirt
setblock ~187 ~122 ~90 dirt
setblock ~187 ~122 ~91 dirt
setblock ~187 ~122 ~92 dirt
setblock ~187 ~122 ~93 dirt
setblock ~187 ~122 ~94 dirt
setblock ~187 ~122 ~95 dirt
setblock ~187 ~122 ~96 dirt
setblock ~187 ~122 ~97 dirt
setblock ~187 ~122 ~98 dirt
setblock ~187 ~122 ~99 dirt
setblock ~187 ~122 ~100 dirt
setblock ~187 ~122 ~101 dirt
setblock ~187 ~122 ~102 dirt
setblock ~187 ~122 ~103 dirt
setblock ~187 ~122 ~104 dirt
setblock ~187 ~122 ~105 dirt
setblock ~187 ~122 ~106 dirt
setblock ~187 ~122 ~107 dirt
setblock ~187 ~122 ~108 dirt
setblock ~187 ~122 ~109 dirt
setblock ~187 ~122 ~114 dirt
setblock ~187 ~122 ~115 dirt
setblock ~187 ~122 ~116 dirt
setblock ~187 ~122 ~117 dirt
setblock ~187 ~123 ~86 dirt
setblock ~187 ~123 ~87 dirt
setblock ~187 ~123 ~88 dirt
setblock ~187 ~123 ~89 dirt
setblock ~187 ~123 ~90 dirt
setblock ~187 ~123 ~91 dirt
setblock ~187 ~123 ~92 dirt
setblock ~187 ~123 ~93 dirt
setblock ~187 ~123 ~94 dirt
setblock ~187 ~123 ~95 dirt
setblock ~187 ~123 ~96 dirt
setblock ~187 ~123 ~97 dirt
setblock ~187 ~123 ~98 dirt
setblock ~187 ~123 ~99 dirt
setblock ~187 ~123 ~100 dirt
setblock ~187 ~123 ~101 dirt
setblock ~187 ~123 ~102 dirt
setblock ~187 ~123 ~103 dirt
setblock ~187 ~123 ~104 dirt
setblock ~187 ~123 ~105 dirt
setblock ~187 ~123 ~106 dirt
setblock ~187 ~123 ~107 grass_block
setblock ~187 ~123 ~108 grass_block
setblock ~187 ~123 ~109 grass_block
setblock ~187 ~123 ~114 grass_block
setblock ~187 ~123 ~115 grass_block
setblock ~187 ~123 ~116 dirt
setblock ~187 ~123 ~117 dirt
setblock ~187 ~124 ~86 dirt
setblock ~187 ~124 ~87 dirt
setblock ~187 ~124 ~88 dirt
setblock ~187 ~124 ~89 dirt
setblock ~187 ~124 ~90 dirt
setblock ~187 ~124 ~91 dirt
setblock ~187 ~124 ~92 dirt
setblock ~187 ~124 ~93 dirt
setblock ~187 ~124 ~94 dirt
setblock ~187 ~124 ~95 dirt
setblock ~187 ~124 ~96 dirt
setblock ~187 ~124 ~97 dirt
setblock ~187 ~124 ~98 dirt
setblock ~187 ~124 ~99 dirt
setblock ~187 ~124 ~100 dirt
setblock ~187 ~124 ~101 dirt
setblock ~187 ~124 ~102 grass_block
setblock ~187 ~124 ~103 grass_block
setblock ~187 ~124 ~104 grass_block
setblock ~187 ~124 ~105 grass_block
setblock ~187 ~124 ~106 grass_block
setblock ~187 ~124 ~114 short_grass
setblock ~187 ~124 ~115 short_grass
setblock ~187 ~124 ~116 grass_block
setblock ~187 ~124 ~117 grass_block
setblock ~187 ~125 ~86 grass_block
setblock ~187 ~125 ~87 dirt
setblock ~187 ~125 ~88 dirt
setblock ~187 ~125 ~89 dirt
setblock ~187 ~125 ~90 dirt
setblock ~187 ~125 ~91 dirt
setblock ~187 ~125 ~92 dirt
setblock ~187 ~125 ~93 dirt
setblock ~187 ~125 ~94 dirt
setblock ~187 ~125 ~95 grass_block
setblock ~187 ~125 ~96 grass_block
setblock ~187 ~125 ~97 grass_block
setblock ~187 ~125 ~98 grass_block
setblock ~187 ~125 ~99 grass_block
setblock ~187 ~125 ~100 grass_block
setblock ~187 ~125 ~101 grass_block
setblock ~187 ~125 ~105 poppy
setblock ~187 ~126 ~86 short_grass
setblock ~187 ~126 ~87 grass_block
setblock ~187 ~126 ~88 grass_block
setblock ~187 ~126 ~89 grass_block
setblock ~187 ~126 ~90 grass_block
setblock ~187 ~126 ~91 grass_block
setblock ~187 ~126 ~92 grass_block
setblock ~187 ~126 ~93 grass_block
setblock ~187 ~126 ~94 grass_block
setblock ~187 ~126 ~100 short_grass
setblock ~187 ~127 ~89 short_grass
setblock ~188 ~113 ~116 dirt
setblock ~188 ~114 ~116 dirt
setblock ~188 ~115 ~94 dirt
setblock ~188 ~115 ~95 dirt
setblock ~188 ~115 ~98 dirt
setblock ~188 ~115 ~116 dirt
setblock ~188 ~116 ~93 dirt
setblock ~188 ~116 ~94 dirt
setblock ~188 ~116 ~95 dirt
setblock ~188 ~116 ~96 dirt
setblock ~188 ~116 ~97 dirt
setblock ~188 ~116 ~98 dirt
setblock ~188 ~116 ~99 dirt
setblock ~188 ~116 ~100 dirt
setblock ~188 ~116 ~116 dirt
setblock ~188 ~117 ~93 dirt
setblock ~188 ~117 ~94 dirt
setblock ~188 ~117 ~95 dirt
setblock ~188 ~117 ~96 dirt
setblock ~188 ~117 ~97 dirt
setblock ~188 ~117 ~98 dirt
setblock ~188 ~117 ~99 dirt
setblock ~188 ~117 ~100 dirt
setblock ~188 ~117 ~101 dirt
setblock ~188 ~117 ~115 dirt
setblock ~188 ~117 ~116 dirt
setblock ~188 ~117 ~117 dirt
setblock ~188 ~118 ~92 dirt
setblock ~188 ~118 ~93 dirt
setblock ~188 ~118 ~94 dirt
setblock ~188 ~118 ~95 dirt
setblock ~188 ~118 ~96 dirt
setblock ~188 ~118 ~97 dirt
setblock ~188 ~118 ~98 dirt
setblock ~188 ~118 ~99 dirt
setblock ~188 ~118 ~100 dirt
setblock ~188 ~118 ~101 dirt
setblock ~188 ~118 ~114 dirt
setblock ~188 ~118 ~115 dirt
setblock ~188 ~118 ~116 dirt
setblock ~188 ~118 ~117 dirt
setblock ~188 ~119 ~90 dirt
setblock ~188 ~119 ~91 dirt
setblock ~188 ~119 ~92 dirt
setblock ~188 ~119 ~93 dirt
setblock ~188 ~119 ~94 dirt
setblock ~188 ~119 ~95 dirt
setblock ~188 ~119 ~96 dirt
setblock ~188 ~119 ~97 dirt
setblock ~188 ~119 ~98 dirt
setblock ~188 ~119 ~99 dirt
setblock ~188 ~119 ~100 dirt
setblock ~188 ~119 ~101 dirt
setblock ~188 ~119 ~102 dirt
setblock ~188 ~119 ~103 dirt
setblock ~188 ~119 ~114 dirt
setblock ~188 ~119 ~115 dirt
setblock ~188 ~119 ~116 dirt
setblock ~188 ~119 ~117 dirt
setblock ~188 ~120 ~88 dirt
setblock ~188 ~120 ~89 dirt
setblock ~188 ~120 ~90 dirt
setblock ~188 ~120 ~91 dirt
setblock ~188 ~120 ~92 dirt
setblock ~188 ~120 ~93 dirt
setblock ~188 ~120 ~94 dirt
setblock ~188 ~120 ~95 dirt
setblock ~188 ~120 ~96 dirt
setblock ~188 ~120 ~97 dirt
setblock ~188 ~120 ~98 dirt
setblock ~188 ~120 ~99 dirt
setblock ~188 ~120 ~100 dirt
setblock ~188 ~120 ~101 dirt
setblock ~188 ~120 ~102 dirt
setblock ~188 ~120 ~103 dirt
setblock ~188 ~120 ~104 dirt
setblock ~188 ~120 ~105 dirt
setblock ~188 ~120 ~106 dirt
setblock ~188 ~120 ~114 dirt
setblock ~188 ~120 ~115 dirt
setblock ~188 ~120 ~116 dirt
setblock ~188 ~120 ~117 dirt
setblock ~188 ~121 ~87 dirt
setblock ~188 ~121 ~88 dirt
setblock ~188 ~121 ~89 dirt
setblock ~188 ~121 ~90 dirt
setblock ~188 ~121 ~91 dirt
setblock ~188 ~121 ~92 dirt
setblock ~188 ~121 ~93 dirt
setblock ~188 ~121 ~94 dirt
setblock ~188 ~121 ~95 dirt
setblock ~188 ~121 ~96 dirt
setblock ~188 ~121 ~97 dirt
setblock ~188 ~121 ~98 dirt
setblock ~188 ~121 ~99 dirt
setblock ~188 ~121 ~100 dirt
setblock ~188 ~121 ~101 dirt
setblock ~188 ~121 ~102 dirt
setblock ~188 ~121 ~103 dirt
setblock ~188 ~121 ~104 dirt
setblock ~188 ~121 ~105 dirt
setblock ~188 ~121 ~106 dirt
setblock ~188 ~121 ~107 dirt
setblock ~188 ~121 ~113 dirt
setblock ~188 ~121 ~114 dirt
setblock ~188 ~121 ~115 dirt
setblock ~188 ~121 ~116 dirt
setblock ~188 ~121 ~117 dirt
setblock ~188 ~121 ~118 dirt
setblock ~188 ~122 ~87 dirt
setblock ~188 ~122 ~88 dirt
setblock ~188 ~122 ~89 dirt
setblock ~188 ~122 ~90 dirt
setblock ~188 ~122 ~91 dirt
setblock ~188 ~122 ~92 dirt
setblock ~188 ~122 ~93 dirt
setblock ~188 ~122 ~94 dirt
setblock ~188 ~122 ~95 dirt
setblock ~188 ~122 ~96 dirt
setblock ~188 ~122 ~97 dirt
setblock ~188 ~122 ~98 dirt
setblock ~188 ~122 ~99 dirt
setblock ~188 ~122 ~100 dirt
setblock ~188 ~122 ~101 dirt
setblock ~188 ~122 ~102 dirt
setblock ~188 ~122 ~103 dirt
setblock ~188 ~122 ~104 dirt
setblock ~188 ~122 ~105 dirt
setblock ~188 ~122 ~106 dirt
setblock ~188 ~122 ~107 dirt
setblock ~188 ~122 ~113 dirt
setblock ~188 ~122 ~114 dirt
setblock ~188 ~122 ~115 dirt
setblock ~188 ~122 ~116 dirt
setblock ~188 ~122 ~117 dirt
setblock ~188 ~122 ~118 dirt
setblock ~188 ~123 ~87 dirt
setblock ~188 ~123 ~88 dirt
setblock ~188 ~123 ~89 dirt
setblock ~188 ~123 ~90 dirt
setblock ~188 ~123 ~91 dirt
setblock ~188 ~123 ~92 dirt
setblock ~188 ~123 ~93 dirt
setblock ~188 ~123 ~94 dirt
setblock ~188 ~123 ~95 dirt
setblock ~188 ~123 ~96 dirt
setblock ~188 ~123 ~97 dirt
setblock ~188 ~123 ~98 dirt
setblock ~188 ~123 ~99 dirt
setblock ~188 ~123 ~100 dirt
setblock ~188 ~123 ~101 dirt
setblock ~188 ~123 ~102 dirt
setblock ~188 ~123 ~103 dirt
setblock ~188 ~123 ~104 dirt
setblock ~188 ~123 ~105 dirt
setblock ~188 ~123 ~106 grass_block
setblock ~188 ~123 ~107 grass_block
setblock ~188 ~123 ~113 grass_block
setblock ~188 ~123 ~114 grass_block
setblock ~188 ~123 ~115 grass_block
setblock ~188 ~123 ~116 grass_block
setblock ~188 ~123 ~117 grass_block
setblock ~188 ~123 ~118 grass_block
setblock ~188 ~124 ~87 dirt
setblock ~188 ~124 ~88 dirt
setblock ~188 ~124 ~89 dirt
setblock ~188 ~124 ~90 dirt
setblock ~188 ~124 ~91 dirt
setblock ~188 ~124 ~92 dirt
setblock ~188 ~124 ~93 dirt
setblock ~188 ~124 ~94 dirt
setblock ~188 ~124 ~95 dirt
setblock ~188 ~124 ~96 dirt
setblock ~188 ~124 ~97 dirt
setblock ~188 ~124 ~98 dirt
setblock ~188 ~124 ~99 dirt
setblock ~188 ~124 ~100 dirt
setblock ~188 ~124 ~101 grass_block
setblock ~188 ~124 ~102 grass_block
setblock ~188 ~124 ~103 grass_block
setblock ~188 ~124 ~104 grass_block
setblock ~188 ~124 ~105 grass_block
setblock ~188 ~124 ~107 poppy
setblock ~188 ~124 ~118 short_grass
setblock ~188 ~125 ~87 dirt
setblock ~188 ~125 ~88 dirt
setblock ~188 ~125 ~89 dirt
setblock ~188 ~125 ~90 dirt
setblock ~188 ~125 ~91 dirt
setblock ~188 ~125 ~92 dirt
setblock ~188 ~125 ~93 dirt
setblock ~188 ~125 ~94 dirt
setblock ~188 ~125 ~95 grass_block
setblock ~188 ~125 ~96 grass_block
setblock ~188 ~125 ~97 grass_block
setblock ~188 ~125 ~98 grass_block
setblock ~188 ~125 ~99 grass_block
setblock ~188 ~125 ~100 grass_block
setblock ~188 ~125 ~101 poppy
setblock ~188 ~126 ~87 grass_block
setblock ~188 ~126 ~88 grass_block
setblock ~188 ~126 ~89 grass_block
setblock ~188 ~126 ~90 grass_block
setblock ~188 ~126 ~91 grass_block
setblock ~188 ~126 ~92 grass_block
setblock ~188 ~126 ~93 grass_block
setblock ~188 ~126 ~94 grass_block
setblock ~188 ~126 ~100 short_grass
setblock ~188 ~127 ~87 short_grass
setblock ~188 ~127 ~90 fern
setblock ~188 ~127 ~93 short_grass
setblock ~189 ~116 ~98 dirt
setblock ~189 ~117 ~94 dirt
setblock ~189 ~117 ~95 dirt
setblock ~189 ~117 ~97 dirt
setblock ~189 ~117 ~98 dirt
setblock ~189 ~117 ~99 dirt
setblock ~189 ~117 ~100 dirt
setblock ~189 ~117 ~116 dirt
setblock ~189 ~118 ~93 dirt
setblock ~189 ~118 ~94 dirt
setblock ~189 ~118 ~95 dirt
setblock ~189 ~118 ~96 dirt
setblock ~189 ~118 ~97 dirt
setblock ~189 ~118 ~98 dirt
setblock ~189 ~118 ~99 dirt
setblock ~189 ~118 ~100 dirt
setblock ~189 ~118 ~101 dirt
setblock ~189 ~118 ~115 dirt
setblock ~189 ~118 ~116 dirt
setblock ~189 ~118 ~117 dirt
setblock ~189 ~119 ~92 dirt
setblock ~189 ~119 ~93 dirt
setblock ~189 ~119 ~94 dirt
setblock ~189 ~119 ~95 dirt
setblock ~189 ~119 ~96 dirt
setblock ~189 ~119 ~97 dirt
setblock ~189 ~119 ~98 dirt
setblock ~189 ~119 ~99 dirt
setblock ~189 ~119 ~100 dirt
setblock ~189 ~119 ~101 dirt
setblock ~189 ~119 ~102 dirt
setblock ~189 ~119 ~115 dirt
setblock ~189 ~119 ~116 dirt
setblock ~189 ~119 ~117 dirt
setblock ~189 ~120 ~90 dirt
setblock ~189 ~120 ~91 dirt
setblock ~189 ~120 ~92 dirt
setblock ~189 ~120 ~93 dirt
setblock ~189 ~120 ~94 dirt
setblock ~189 ~120 ~95 dirt
setblock ~189 ~120 ~96 dirt
setblock ~189 ~120 ~97 dirt
setblock ~189 ~120 ~98 dirt
setblock ~189 ~120 ~99 dirt
setblock ~189 ~120 ~100 dirt
setblock ~189 ~120 ~101 dirt
setblock ~189 ~120 ~102 dirt
setblock ~189 ~120 ~103 dirt
setblock ~189 ~120 ~114 dirt
setblock ~189 ~120 ~115 dirt
setblock ~189 ~120 ~116 dirt
setblock ~189 ~120 ~117 dirt
setblock ~189 ~121 ~88 dirt
setblock ~189 ~121 ~89 dirt
setblock ~189 ~121 ~90 dirt
setblock ~189 ~121 ~91 dirt
setblock ~189 ~121 ~92 dirt
setblock ~189 ~121 ~93 dirt
setblock ~189 ~121 ~94 dirt
setblock ~189 ~121 ~95 dirt
setblock ~189 ~121 ~96 dirt
setblock ~189 ~121 ~97 dirt
setblock ~189 ~121 ~98 dirt
setblock ~189 ~121 ~99 dirt
setblock ~189 ~121 ~100 dirt
setblock ~189 ~121 ~101 dirt
setblock ~189 ~121 ~102 dirt
setblock ~189 ~121 ~103 dirt
setblock ~189 ~121 ~104 dirt
setblock ~189 ~121 ~105 dirt
setblock ~189 ~121 ~114 dirt
setblock ~189 ~121 ~115 dirt
setblock ~189 ~121 ~116 dirt
setblock ~189 ~121 ~117 dirt
setblock ~189 ~121 ~118 dirt
setblock ~189 ~122 ~88 dirt
setblock ~189 ~122 ~89 dirt
setblock ~189 ~122 ~90 dirt
setblock ~189 ~122 ~91 dirt
setblock ~189 ~122 ~92 dirt
setblock ~189 ~122 ~93 dirt
setblock ~189 ~122 ~94 dirt
setblock ~189 ~122 ~95 dirt
setblock ~189 ~122 ~96 dirt
setblock ~189 ~122 ~97 dirt
setblock ~189 ~122 ~98 dirt
setblock ~189 ~122 ~99 dirt
setblock ~189 ~122 ~100 dirt
setblock ~189 ~122 ~101 dirt
setblock ~189 ~122 ~102 dirt
setblock ~189 ~122 ~103 dirt
setblock ~189 ~122 ~104 dirt
setblock ~189 ~122 ~105 dirt
setblock ~189 ~122 ~114 dirt
setblock ~189 ~122 ~115 dirt
setblock ~189 ~122 ~116 dirt
setblock ~189 ~122 ~117 dirt
setblock ~189 ~122 ~118 dirt
setblock ~189 ~123 ~88 dirt
setblock ~189 ~123 ~89 dirt
setblock ~189 ~123 ~90 dirt
setblock ~189 ~123 ~91 dirt
setblock ~189 ~123 ~92 dirt
setblock ~189 ~123 ~93 dirt
setblock ~189 ~123 ~94 dirt
setblock ~189 ~123 ~95 dirt
setblock ~189 ~123 ~96 dirt
setblock ~189 ~123 ~97 dirt
setblock ~189 ~123 ~98 dirt
setblock ~189 ~123 ~99 dirt
setblock ~189 ~123 ~100 dirt
setblock ~189 ~123 ~101 dirt
setblock ~189 ~123 ~102 dirt
setblock ~189 ~123 ~103 dirt
setblock ~189 ~123 ~104 dirt
setblock ~189 ~123 ~105 grass_block
setblock ~189 ~123 ~114 grass_block
setblock ~189 ~123 ~115 grass_block
setblock ~189 ~123 ~116 grass_block
setblock ~189 ~123 ~117 grass_block
setblock ~189 ~123 ~118 grass_block
setblock ~189 ~124 ~88 dirt
setblock ~189 ~124 ~89 dirt
setblock ~189 ~124 ~90 dirt
setblock ~189 ~124 ~91 dirt
setblock ~189 ~124 ~92 dirt
setblock ~189 ~124 ~93 dirt
setblock ~189 ~124 ~94 dirt
setblock ~189 ~124 ~95 dirt
setblock ~189 ~124 ~96 dirt
setblock ~189 ~124 ~97 dirt
setblock ~189 ~124 ~98 dirt
setblock ~189 ~124 ~99 dirt
setblock ~189 ~124 ~100 grass_block
setblock ~189 ~124 ~101 grass_block
setblock ~189 ~124 ~102 grass_block
setblock ~189 ~124 ~103 grass_block
setblock ~189 ~124 ~104 grass_block
setblock ~189 ~124 ~115 short_grass
setblock ~189 ~125 ~88 dirt
setblock ~189 ~125 ~89 dirt
setblock ~189 ~125 ~90 dirt
setblock ~189 ~125 ~91 dirt
setblock ~189 ~125 ~92 dirt
setblock ~189 ~125 ~93 dirt
setblock ~189 ~125 ~94 dirt
setblock ~189 ~125 ~95 dirt
setblock ~189 ~125 ~96 grass_block
setblock ~189 ~125 ~97 grass_block
setblock ~189 ~125 ~98 grass_block
setblock ~189 ~125 ~99 grass_block
setblock ~189 ~125 ~103 short_grass
setblock ~189 ~126 ~88 grass_block
setblock ~189 ~126 ~89 dirt
setblock ~189 ~126 ~90 dirt
setblock ~189 ~126 ~91 dirt
setblock ~189 ~126 ~92 grass_block
setblock ~189 ~126 ~93 grass_block
setblock ~189 ~126 ~94 grass_block
setblock ~189 ~126 ~95 grass_block
setblock ~189 ~126 ~99 short_grass
setblock ~189 ~127 ~88 short_grass
setblock ~189 ~127 ~89 grass_block
setblock ~189 ~127 ~90 grass_block
setblock ~189 ~127 ~91 grass_block
setblock ~189 ~128 ~91 short_grass
setblock ~190 ~117 ~98 dirt
setblock ~190 ~118 ~94 dirt
setblock ~190 ~118 ~97 dirt
setblock ~190 ~118 ~98 dirt
setblock ~190 ~118 ~99 dirt
setblock ~190 ~118 ~100 dirt
setblock ~190 ~118 ~116 dirt
setblock ~190 ~119 ~93 dirt
setblock ~190 ~119 ~94 dirt
setblock ~190 ~119 ~95 dirt
setblock ~190 ~119 ~96 dirt
setblock ~190 ~119 ~97 dirt
setblock ~190 ~119 ~98 dirt
setblock ~190 ~119 ~99 dirt
setblock ~190 ~119 ~100 dirt
setblock ~190 ~119 ~101 dirt
setblock ~190 ~119 ~116 dirt
setblock ~190 ~120 ~92 dirt
setblock ~190 ~120 ~93 dirt
setblock ~190 ~120 ~94 dirt
setblock ~190 ~120 ~95 dirt
setblock ~190 ~120 ~96 dirt
setblock ~190 ~120 ~97 dirt
setblock ~190 ~120 ~98 dirt
setblock ~190 ~120 ~99 dirt
setblock ~190 ~120 ~100 dirt
setblock ~190 ~120 ~101 dirt
setblock ~190 ~120 ~102 dirt
setblock ~190 ~120 ~115 dirt
setblock ~190 ~120 ~116 dirt
setblock ~190 ~121 ~90 dirt
setblock ~190 ~121 ~91 dirt
setblock ~190 ~121 ~92 dirt
setblock ~190 ~121 ~93 dirt
setblock ~190 ~121 ~94 dirt
setblock ~190 ~121 ~95 dirt
setblock ~190 ~121 ~96 dirt
setblock ~190 ~121 ~97 dirt
setblock ~190 ~121 ~98 dirt
setblock ~190 ~121 ~99 dirt
setblock ~190 ~121 ~100 dirt
setblock ~190 ~121 ~101 dirt
setblock ~190 ~121 ~102 dirt
setblock ~190 ~121 ~103 dirt
setblock ~190 ~121 ~114 dirt
setblock ~190 ~121 ~115 dirt
setblock ~190 ~121 ~116 dirt
setblock ~190 ~121 ~117 dirt
setblock ~190 ~122 ~90 dirt
setblock ~190 ~122 ~91 dirt
setblock ~190 ~122 ~92 dirt
setblock ~190 ~122 ~93 dirt
setblock ~190 ~122 ~94 dirt
setblock ~190 ~122 ~95 dirt
setblock ~190 ~122 ~96 dirt
setblock ~190 ~122 ~97 dirt
setblock ~190 ~122 ~98 dirt
setblock ~190 ~122 ~99 dirt
setblock ~190 ~122 ~100 dirt
setblock ~190 ~122 ~101 dirt
setblock ~190 ~122 ~102 dirt
setblock ~190 ~122 ~103 dirt
setblock ~190 ~122 ~114 dirt
setblock ~190 ~122 ~115 dirt
setblock ~190 ~122 ~116 dirt
setblock ~190 ~122 ~117 dirt
setblock ~190 ~123 ~90 dirt
setblock ~190 ~123 ~91 dirt
setblock ~190 ~123 ~92 dirt
setblock ~190 ~123 ~93 dirt
setblock ~190 ~123 ~94 dirt
setblock ~190 ~123 ~95 dirt
setblock ~190 ~123 ~96 dirt
setblock ~190 ~123 ~97 dirt
setblock ~190 ~123 ~98 dirt
setblock ~190 ~123 ~99 dirt
setblock ~190 ~123 ~100 dirt
setblock ~190 ~123 ~101 dirt
setblock ~190 ~123 ~102 dirt
setblock ~190 ~123 ~103 grass_block
setblock ~190 ~123 ~114 grass_block
setblock ~190 ~123 ~115 grass_block
setblock ~190 ~123 ~116 grass_block
setblock ~190 ~123 ~117 grass_block
setblock ~190 ~124 ~90 dirt
setblock ~190 ~124 ~91 dirt
setblock ~190 ~124 ~92 dirt
setblock ~190 ~124 ~93 dirt
setblock ~190 ~124 ~94 dirt
setblock ~190 ~124 ~95 dirt
setblock ~190 ~124 ~96 dirt
setblock ~190 ~124 ~97 dirt
setblock ~190 ~124 ~98 dirt
setblock ~190 ~124 ~99 grass_block
setblock ~190 ~124 ~100 grass_block
setblock ~190 ~124 ~101 grass_block
setblock ~190 ~124 ~102 grass_block
setblock ~190 ~125 ~90 dirt
setblock ~190 ~125 ~91 dirt
setblock ~190 ~125 ~92 dirt
setblock ~190 ~125 ~93 dirt
setblock ~190 ~125 ~94 dirt
setblock ~190 ~125 ~95 dirt
setblock ~190 ~125 ~96 grass_block
setblock ~190 ~125 ~97 grass_block
setblock ~190 ~125 ~98 grass_block
setblock ~190 ~125 ~100 short_grass
setblock ~190 ~126 ~90 dirt
setblock ~190 ~126 ~91 dirt
setblock ~190 ~126 ~92 grass_block
setblock ~190 ~126 ~93 grass_block
setblock ~190 ~126 ~94 grass_block
setblock ~190 ~126 ~95 grass_block
setblock ~190 ~126 ~98 short_grass
setblock ~190 ~127 ~90 grass_block
setblock ~190 ~127 ~91 grass_block
setblock ~190 ~127 ~92 short_grass
setblock ~190 ~128 ~90 fern
setblock ~191 ~119 ~97 dirt
setblock ~191 ~119 ~98 dirt
setblock ~191 ~119 ~100 dirt
setblock ~191 ~120 ~93 dirt
setblock ~191 ~120 ~94 dirt
setblock ~191 ~120 ~96 dirt
setblock ~191 ~120 ~97 dirt
setblock ~191 ~120 ~98 dirt
setblock ~191 ~120 ~99 dirt
setblock ~191 ~120 ~100 dirt
setblock ~191 ~120 ~101 dirt
setblock ~191 ~121 ~92 dirt
setblock ~191 ~121 ~93 dirt
setblock ~191 ~121 ~94 dirt
setblock ~191 ~121 ~95 dirt
setblock ~191 ~121 ~96 dirt
setblock ~191 ~121 ~97 dirt
setblock ~191 ~121 ~98 dirt
setblock ~191 ~121 ~99 dirt
setblock ~191 ~121 ~100 dirt
setblock ~191 ~121 ~101 dirt
setblock ~191 ~121 ~102 dirt
setblock ~191 ~121 ~115 dirt
setblock ~191 ~122 ~92 dirt
setblock ~191 ~122 ~93 dirt
setblock ~191 ~122 ~94 dirt
setblock ~191 ~122 ~95 dirt
setblock ~191 ~122 ~96 dirt
setblock ~191 ~122 ~97 dirt
setblock ~191 ~122 ~98 dirt
setblock ~191 ~122 ~99 dirt
setblock ~191 ~122 ~100 dirt
setblock ~191 ~122 ~101 dirt
setblock ~191 ~122 ~102 dirt
setblock ~191 ~122 ~115 dirt
setblock ~191 ~123 ~92 dirt
setblock ~191 ~123 ~93 dirt
setblock ~191 ~123 ~94 dirt
setblock ~191 ~123 ~95 dirt
setblock ~191 ~123 ~96 dirt
setblock ~191 ~123 ~97 dirt
setblock ~191 ~123 ~98 dirt
setblock ~191 ~123 ~99 dirt
setblock ~191 ~123 ~100 dirt
setblock ~191 ~123 ~101 dirt
setblock ~191 ~123 ~102 dirt
setblock ~191 ~123 ~115 grass_block
setblock ~191 ~124 ~92 dirt
setblock ~191 ~124 ~93 dirt
setblock ~191 ~124 ~94 dirt
setblock ~191 ~124 ~95 dirt
setblock ~191 ~124 ~96 dirt
setblock ~191 ~124 ~97 dirt
setblock ~191 ~124 ~98 dirt
setblock ~191 ~124 ~99 dirt
setblock ~191 ~124 ~100 grass_block
setblock ~191 ~124 ~101 grass_block
setblock ~191 ~124 ~102 grass_block
setblock ~191 ~125 ~92 dirt
setblock ~191 ~125 ~93 dirt
setblock ~191 ~125 ~94 dirt
setblock ~191 ~125 ~95 dirt
setblock ~191 ~125 ~96 grass_block
setblock ~191 ~125 ~97 grass_block
setblock ~191 ~125 ~98 grass_block
setblock ~191 ~125 ~99 grass_block
setblock ~191 ~125 ~101 poppy
setblock ~191 ~126 ~92 grass_block
setblock ~191 ~126 ~93 grass_block
setblock ~191 ~126 ~94 grass_block
setblock ~191 ~126 ~95 grass_block
setblock ~191 ~126 ~99 short_grass
setblock ~192 ~121 ~93 dirt
setblock ~192 ~121 ~94 dirt
setblock ~192 ~121 ~97 dirt
setblock ~192 ~121 ~98 dirt
setblock ~192 ~121 ~99 dirt
setblock ~192 ~121 ~100 dirt
setblock ~192 ~121 ~101 dirt
setblock ~192 ~122 ~93 dirt
setblock ~192 ~122 ~94 dirt
setblock ~192 ~122 ~97 dirt
setblock ~192 ~122 ~98 dirt
setblock ~192 ~122 ~99 dirt
setblock ~192 ~122 ~100 dirt
setblock ~192 ~122 ~101 dirt
setblock ~192 ~123 ~93 dirt
setblock ~192 ~123 ~94 dirt
setblock ~192 ~123 ~97 dirt
setblock ~192 ~123 ~98 dirt
setblock ~192 ~123 ~99 dirt
setblock ~192 ~123 ~100 dirt
setblock ~192 ~123 ~101 dirt
setblock ~192 ~124 ~93 dirt
setblock ~192 ~124 ~94 dirt
setblock ~192 ~124 ~97 dirt
setblock ~192 ~124 ~98 dirt
setblock ~192 ~124 ~99 dirt
setblock ~192 ~124 ~100 dirt
setblock ~192 ~124 ~101 dirt
setblock ~192 ~125 ~93 dirt
setblock ~192 ~125 ~94 dirt
setblock ~192 ~125 ~97 grass_block
setblock ~192 ~125 ~98 grass_block
setblock ~192 ~125 ~99 grass_block
setblock ~192 ~125 ~100 grass_block
setblock ~192 ~125 ~101 grass_block
setblock ~192 ~126 ~93 grass_block
setblock ~192 ~126 ~94 grass_block
setblock ~192 ~126 ~98 short_grass
setblock ~192 ~127 ~93 short_grass
setblock ~192 ~127 ~94 poppy
setblock ~199 ~200 ~199 gold_block
