setblock ~165 ~112 ~122 dirt
setblock ~165 ~112 ~123 dirt
setblock ~165 ~113 ~91 dirt
setblock ~165 ~113 ~92 dirt
setblock ~165 ~113 ~93 dirt
setblock ~165 ~113 ~94 dirt
setblock ~165 ~113 ~95 dirt
setblock ~165 ~113 ~96 dirt
setblock ~165 ~113 ~97 dirt
setblock ~165 ~113 ~98 dirt
setblock ~165 ~113 ~99 dirt
setblock ~165 ~113 ~100 dirt
setblock ~165 ~113 ~102 dirt
setblock ~165 ~113 ~103 dirt
setblock ~165 ~113 ~104 dirt
setblock ~165 ~113 ~105 dirt
setblock ~165 ~113 ~115 dirt
setblock ~165 ~113 ~116 dirt
setblock ~165 ~113 ~117 dirt
setblock ~165 ~113 ~118 dirt
setblock ~165 ~113 ~119 dirt
setblock ~165 ~113 ~120 dirt
setblock ~165 ~113 ~121 dirt
setblock ~165 ~113 ~122 dirt
setblock ~165 ~113 ~123 dirt
setblock ~165 ~114 ~90 dirt
setblock ~165 ~114 ~91 dirt
setblock ~165 ~114 ~92 dirt
setblock ~165 ~114 ~93 dirt
setblock ~165 ~114 ~94 dirt
setblock ~165 ~114 ~95 dirt
setblock ~165 ~114 ~96 dirt
setblock ~165 ~114 ~97 dirt
setblock ~165 ~114 ~98 dirt
setblock ~165 ~114 ~99 dirt
setblock ~165 ~114 ~100 dirt
setblock ~165 ~114 ~101 dirt
setblock ~165 ~114 ~102 dirt
setblock ~165 ~114 ~103 dirt
setblock ~165 ~114 ~104 dirt
setblock ~165 ~114 ~105 dirt
setblock ~165 ~114 ~106 dirt
setblock ~165 ~114 ~114 dirt
setblock ~165 ~114 ~115 dirt
setblock ~165 ~114 ~116 dirt
setblock ~165 ~114 ~117 dirt
setblock ~165 ~114 ~118 dirt
setblock ~165 ~114 ~119 dirt
setblock ~165 ~114 ~120 dirt
setblock ~165 ~114 ~121 dirt
setblock ~165 ~114 ~122 dirt
setblock ~165 ~114 ~123 dirt
setblock ~165 ~114 ~124 dirt
setblock ~165 ~115 ~89 dirt
setblock ~165 ~115 ~90 dirt
setblock ~165 ~115 ~91 dirt
setblock ~165 ~115 ~92 dirt
setblock ~165 ~115 ~93 dirt
setblock ~165 ~115 ~94 dirt
setblock ~165 ~115 ~95 dirt
setblock ~165 ~115 ~96 dirt
setblock ~165 ~115 ~97 dirt
setblock ~165 ~115 ~98 dirt
setblock ~165 ~115 ~99 dirt
setblock ~165 ~115 ~100 dirt
setblock ~165 ~115 ~101 dirt
setblock ~165 ~115 ~102 dirt
setblock ~165 ~115 ~103 dirt
setblock ~165 ~115 ~104 dirt
setblock ~165 ~115 ~105 dirt
setblock ~165 ~115 ~106 dirt
setblock ~165 ~115 ~107 dirt
setblock ~165 ~115 ~114 dirt
setblock ~165 ~115 ~115 dirt
setblock ~165 ~115 ~116 dirt
setblock ~165 ~115 ~117 dirt
setblock ~165 ~115 ~118 dirt
setblock ~165 ~115 ~119 dirt
setblock ~165 ~115 ~120 dirt
setblock ~165 ~115 ~121 dirt
setblock ~165 ~115 ~122 dirt
setblock ~165 ~115 ~123 dirt
setblock ~165 ~115 ~124 dirt
setblock ~165 ~115 ~125 dirt
setblock ~165 ~116 ~88 dirt
setblock ~165 ~116 ~89 dirt
setblock ~165 ~116 ~90 dirt
setblock ~165 ~116 ~91 dirt
setblock ~165 ~116 ~92 dirt
setblock ~165 ~116 ~93 dirt
setblock ~165 ~116 ~94 dirt
setblock ~165 ~116 ~95 dirt
setblock ~165 ~116 ~96 dirt
setblock ~165 ~116 ~97 dirt
setblock ~165 ~116 ~98 dirt
setblock ~165 ~116 ~99 dirt
setblock ~165 ~116 ~100 dirt
setblock ~165 ~116 ~101 dirt
setblock ~165 ~116 ~102 dirt
setblock ~165 ~116 ~103 dirt
setblock ~165 ~116 ~104 dirt
setblock ~165 ~116 ~105 dirt
setblock ~165 ~116 ~106 dirt
setblock ~165 ~116 ~107 dirt
setblock ~165 ~116 ~108 dirt
setblock ~165 ~116 ~113 dirt
setblock ~165 ~116 ~114 dirt
setblock ~165 ~116 ~115 dirt
setblock ~165 ~116 ~116 dirt
setblock ~165 ~116 ~117 dirt
setblock ~165 ~116 ~118 dirt
setblock ~165 ~116 ~119 dirt
setblock ~165 ~116 ~120 dirt
setblock ~165 ~116 ~121 dirt
setblock ~165 ~116 ~122 dirt
setblock ~165 ~116 ~123 dirt
setblock ~165 ~116 ~124 dirt
setblock ~165 ~116 ~125 dirt
setblock ~165 ~117 ~87 dirt
setblock ~165 ~117 ~88 dirt
setblock ~165 ~117 ~89 dirt
setblock ~165 ~117 ~90 dirt
setblock ~165 ~117 ~91 dirt
setblock ~165 ~117 ~92 dirt
setblock ~165 ~117 ~93 dirt
setblock ~165 ~117 ~94 dirt
setblock ~165 ~117 ~95 dirt
setblock ~165 ~117 ~96 dirt
setblock ~165 ~117 ~97 dirt
setblock ~165 ~117 ~98 dirt
setblock ~165 ~117 ~99 dirt
setblock ~165 ~117 ~100 dirt
setblock ~165 ~117 ~101 dirt
setblock ~165 ~117 ~102 dirt
setblock ~165 ~117 ~103 dirt
setblock ~165 ~117 ~104 dirt
setblock ~165 ~117 ~105 dirt
setblock ~165 ~117 ~106 dirt
setblock ~165 ~117 ~107 dirt
setblock ~165 ~117 ~108 dirt
setblock ~165 ~117 ~113 dirt
setblock ~165 ~117 ~114 dirt
setblock ~165 ~117 ~115 dirt
setblock ~165 ~117 ~116 dirt
setblock ~165 ~117 ~117 dirt
setblock ~165 ~117 ~118 dirt
setblock ~165 ~117 ~119 dirt
setblock ~165 ~117 ~120 dirt
setblock ~165 ~117 ~121 dirt
setblock ~165 ~117 ~122 dirt
setblock ~165 ~117 ~123 dirt
setblock ~165 ~117 ~124 dirt
setblock ~165 ~117 ~125 dirt
setblock ~165 ~117 ~126 dirt
setblock ~165 ~118 ~86 dirt
setblock ~165 ~118 ~87 dirt
setblock ~165 ~118 ~88 dirt
setblock ~165 ~118 ~89 dirt
setblock ~165 ~118 ~90 dirt
setblock ~165 ~118 ~91 dirt
setblock ~165 ~118 ~92 dirt
setblock ~165 ~118 ~93 dirt
setblock ~165 ~118 ~94 dirt
setblock ~165 ~118 ~95 dirt
setblock ~165 ~118 ~96 dirt
setblock ~165 ~118 ~97 dirt
setblock ~165 ~118 ~98 dirt
setblock ~165 ~118 ~99 dirt
setblock ~165 ~118 ~100 dirt
setblock ~165 ~118 ~101 dirt
setblock ~165 ~118 ~102 dirt
setblock ~165 ~118 ~103 dirt
setblock ~165 ~118 ~104 dirt
setblock ~165 ~118 ~105 dirt
setblock ~165 ~118 ~106 dirt
setblock ~165 ~118 ~107 dirt
setblock ~165 ~118 ~108 dirt
setblock ~165 ~118 ~109 dirt
setblock ~165 ~118 ~112 dirt
setblock ~165 ~118 ~113 dirt
setblock ~165 ~118 ~114 dirt
setblock ~165 ~118 ~115 dirt
setblock ~165 ~118 ~116 dirt
setblock ~165 ~118 ~117 dirt
setblock ~165 ~118 ~118 dirt
setblock ~165 ~118 ~119 dirt
setblock ~165 ~118 ~120 dirt
setblock ~165 ~118 ~121 dirt
setblock ~165 ~118 ~122 dirt
setblock ~165 ~118 ~123 dirt
setblock ~165 ~118 ~124 dirt
setblock ~165 ~118 ~125 dirt
setblock ~165 ~118 ~126 dirt
setblock ~165 ~118 ~127 dirt
setblock ~165 ~119 ~86 dirt
setblock ~165 ~119 ~87 dirt
setblock ~165 ~119 ~88 dirt
setblock ~165 ~119 ~89 dirt
setblock ~165 ~119 ~90 dirt
setblock ~165 ~119 ~91 dirt
setblock ~165 ~119 ~92 dirt
setblock ~165 ~119 ~93 dirt
setblock ~165 ~119 ~94 dirt
setblock ~165 ~119 ~95 dirt
setblock ~165 ~119 ~96 dirt
setblock ~165 ~119 ~97 dirt
setblock ~165 ~119 ~98 dirt
setblock ~165 ~119 ~99 dirt
setblock ~165 ~119 ~100 dirt
setblock ~165 ~119 ~101 dirt
setblock ~165 ~119 ~102 dirt
setblock ~165 ~119 ~103 dirt
setblock ~165 ~119 ~104 dirt
setblock ~165 ~119 ~105 dirt
setblock ~165 ~119 ~106 dirt
setblock ~165 ~119 ~107 dirt
setblock ~165 ~119 ~108 dirt
setblock ~165 ~119 ~109 dirt
setblock ~165 ~119 ~112 dirt
setblock ~165 ~119 ~113 dirt
setblock ~165 ~119 ~114 dirt
setblock ~165 ~119 ~115 dirt
setblock ~165 ~119 ~116 dirt
setblock ~165 ~119 ~117 dirt
setblock ~165 ~119 ~118 dirt
setblock ~165 ~119 ~119 dirt
setblock ~165 ~119 ~120 dirt
setblock ~165 ~119 ~121 dirt
setblock ~165 ~119 ~122 dirt
setblock ~165 ~119 ~123 dirt
setblock ~165 ~119 ~124 dirt
setblock ~165 ~119 ~125 dirt
setblock ~165 ~119 ~126 dirt
setblock ~165 ~119 ~127 dirt
setblock ~165 ~120 ~81 dirt
setblock ~165 ~120 ~86 dirt
setblock ~165 ~120 ~87 dirt
setblock ~165 ~120 ~88 dirt
setblock ~165 ~120 ~89 dirt
setblock ~165 ~120 ~90 dirt
setblock ~165 ~120 ~91 dirt
setblock ~165 ~120 ~92 dirt
setblock ~165 ~120 ~93 dirt
setblock ~165 ~120 ~94 dirt
setblock ~165 ~120 ~95 dirt
setblock ~165 ~120 ~96 dirt
setblock ~165 ~120 ~97 dirt
setblock ~165 ~120 ~98 dirt
setblock ~165 ~120 ~99 dirt
setblock ~165 ~120 ~100 dirt
setblock ~165 ~120 ~101 dirt
setblock ~165 ~120 ~102 dirt
setblock ~165 ~120 ~103 dirt
setblock ~165 ~120 ~104 dirt
setblock ~165 ~120 ~105 dirt
setblock ~165 ~120 ~106 dirt
setblock ~165 ~120 ~107 dirt
setblock ~165 ~120 ~108 dirt
setblock ~165 ~120 ~109 dirt
setblock ~165 ~120 ~110 dirt
setblock ~165 ~120 ~111 dirt
setblock ~165 ~120 ~112 dirt
setblock ~165 ~120 ~113 dirt
setblock ~165 ~120 ~114 dirt
setblock ~165 ~120 ~115 dirt
setblock ~165 ~120 ~116 dirt
setblock ~165 ~120 ~117 dirt
setblock ~165 ~120 ~118 dirt
setblock ~165 ~120 ~119 dirt
setblock ~165 ~120 ~120 dirt
setblock ~165 ~120 ~121 dirt
setblock ~165 ~120 ~122 dirt
setblock ~165 ~120 ~123 dirt
setblock ~165 ~120 ~124 dirt
setblock ~165 ~120 ~125 dirt
setblock ~165 ~120 ~126 dirt
setblock ~165 ~120 ~127 dirt
setblock ~165 ~120 ~128 dirt
setblock ~165 ~121 ~80 dirt
setblock ~165 ~121 ~81 dirt
setblock ~165 ~121 ~82 dirt
setblock ~165 ~121 ~84 dirt
setblock ~165 ~121 ~86 dirt
setblock ~165 ~121 ~87 dirt
setblock ~165 ~121 ~88 dirt
setblock ~165 ~121 ~89 dirt
setblock ~165 ~121 ~90 dirt
setblock ~165 ~121 ~91 dirt
setblock ~165 ~121 ~92 dirt
setblock ~165 ~121 ~93 dirt
setblock ~165 ~121 ~94 dirt
setblock ~165 ~121 ~95 dirt
setblock ~165 ~121 ~96 dirt
setblock ~165 ~121 ~97 dirt
setblock ~165 ~121 ~98 dirt
setblock ~165 ~121 ~99 dirt
setblock ~165 ~121 ~100 dirt
setblock ~165 ~121 ~101 dirt
setblock ~165 ~121 ~102 dirt
setblock ~165 ~121 ~103 dirt
setblock ~165 ~121 ~104 dirt
setblock ~165 ~121 ~105 dirt
setblock ~165 ~121 ~106 dirt
setblock ~165 ~121 ~107 dirt
setblock ~165 ~121 ~108 dirt
setblock ~165 ~121 ~109 dirt
setblock ~165 ~121 ~110 dirt
setblock ~165 ~121 ~111 dirt
setblock ~165 ~121 ~112 dirt
setblock ~165 ~121 ~113 dirt
setblock ~165 ~121 ~114 dirt
setblock ~165 ~121 ~115 dirt
setblock ~165 ~121 ~116 dirt
setblock ~165 ~121 ~117 dirt
setblock ~165 ~121 ~118 dirt
setblock ~165 ~121 ~119 dirt
setblock ~165 ~121 ~120 dirt
setblock ~165 ~121 ~121 dirt
setblock ~165 ~121 ~122 dirt
setblock ~165 ~121 ~123 dirt
setblock ~165 ~121 ~124 dirt
setblock ~165 ~121 ~125 dirt
setblock ~165 ~121 ~126 dirt
setblock ~165 ~121 ~127 dirt
setblock ~165 ~121 ~128 dirt
setblock ~165 ~121 ~129 dirt
setblock ~165 ~122 ~80 grass_block
setblock ~165 ~122 ~81 dirt
setblock ~165 ~122 ~82 dirt
setblock ~165 ~122 ~84 dirt
setblock ~165 ~122 ~86 dirt
setblock ~165 ~122 ~87 dirt
setblock ~165 ~122 ~88 dirt
setblock ~165 ~122 ~89 dirt
setblock ~165 ~122 ~90 dirt
setblock ~165 ~122 ~91 dirt
setblock ~165 ~122 ~92 dirt
setblock ~165 ~122 ~93 dirt
setblock ~165 ~122 ~94 dirt
setblock ~165 ~122 ~95 dirt
setblock ~165 ~122 ~96 dirt
setblock ~165 ~122 ~97 dirt
setblock ~165 ~122 ~98 dirt
setblock ~165 ~122 ~99 dirt
setblock ~165 ~122 ~100 dirt
setblock ~165 ~122 ~101 dirt
setblock ~165 ~122 ~102 dirt
setblock ~165 ~122 ~103 dirt
setblock ~165 ~122 ~104 dirt
setblock ~165 ~122 ~105 dirt
setblock ~165 ~122 ~106 dirt
setblock ~165 ~122 ~107 dirt
setblock ~165 ~122 ~108 dirt
setblock ~165 ~122 ~109 dirt
setblock ~165 ~122 ~110 dirt
setblock ~165 ~122 ~111 dirt
setblock ~165 ~122 ~112 dirt
setblock ~165 ~122 ~113 dirt
setblock ~165 ~122 ~114 dirt
setblock ~165 ~122 ~115 dirt
setblock ~165 ~122 ~116 dirt
setblock ~165 ~122 ~117 dirt
setblock ~165 ~122 ~118 dirt
setblock ~165 ~122 ~119 dirt
setblock ~165 ~122 ~120 dirt
setblock ~165 ~122 ~121 dirt
setblock ~165 ~122 ~122 dirt
setblock ~165 ~122 ~123 dirt
setblock ~165 ~122 ~124 dirt
setblock ~165 ~122 ~125 dirt
setblock ~165 ~122 ~126 dirt
setblock ~165 ~122 ~127 dirt
setblock ~165 ~122 ~128 dirt
setblock ~165 ~122 ~129 dirt
setblock ~165 ~123 ~80 short_grass
setblock ~165 ~123 ~81 grass_block
setblock ~165 ~123 ~82 grass_block
setblock ~165 ~123 ~84 dirt
setblock ~165 ~123 ~86 dirt
setblock ~165 ~123 ~87 dirt
setblock ~165 ~123 ~88 dirt
setblock ~165 ~123 ~89 dirt
setblock ~165 ~123 ~90 dirt
setblock ~165 ~123 ~91 dirt
setblock ~165 ~123 ~92 dirt
setblock ~165 ~123 ~93 dirt
setblock ~165 ~123 ~94 dirt
setblock ~165 ~123 ~95 dirt
setblock ~165 ~123 ~96 dirt
setblock ~165 ~123 ~97 dirt
setblock ~165 ~123 ~98 dirt
setblock ~165 ~123 ~99 dirt
setblock ~165 ~123 ~100 dirt
setblock ~165 ~123 ~101 dirt
setblock ~165 ~123 ~102 dirt
setblock ~165 ~123 ~103 dirt
setblock ~165 ~123 ~104 dirt
setblock ~165 ~123 ~105 dirt
setblock ~165 ~123 ~106 dirt
setblock ~165 ~123 ~107 dirt
setblock ~165 ~123 ~108 grass_block
setblock ~165 ~123 ~109 grass_block
setblock ~165 ~123 ~110 grass_block
setblock ~165 ~123 ~111 grass_block
setblock ~165 ~123 ~112 grass_block
setblock ~165 ~123 ~113 dirt
setblock ~165 ~123 ~114 dirt
setblock ~165 ~123 ~115 dirt
setblock ~165 ~123 ~116 dirt
setblock ~165 ~123 ~117 dirt
setblock ~165 ~123 ~118 dirt
setblock ~165 ~123 ~119 dirt
setblock ~165 ~123 ~120 dirt
setblock ~165 ~123 ~121 dirt
setblock ~165 ~123 ~122 dirt
setblock ~165 ~123 ~123 dirt
setblock ~165 ~123 ~124 dirt
setblock ~165 ~123 ~125 dirt
setblock ~165 ~123 ~126 grass_block
setblock ~165 ~123 ~127 grass_block
setblock ~165 ~123 ~128 grass_block
setblock ~165 ~123 ~129 grass_block
setblock ~165 ~124 ~84 grass_block
setblock ~165 ~124 ~86 dirt
setblock ~165 ~124 ~87 dirt
setblock ~165 ~124 ~88 dirt
setblock ~165 ~124 ~89 dirt
setblock ~165 ~124 ~90 dirt
setblock ~165 ~124 ~91 dirt
setblock ~165 ~124 ~92 dirt
setblock ~165 ~124 ~93 dirt
setblock ~165 ~124 ~94 dirt
setblock ~165 ~124 ~95 dirt
setblock ~165 ~124 ~96 dirt
setblock ~165 ~124 ~97 dirt
setblock ~165 ~124 ~98 dirt
setblock ~165 ~124 ~99 dirt
setblock ~165 ~124 ~100 dirt
setblock ~165 ~124 ~101 dirt
setblock ~165 ~124 ~102 dirt
setblock ~165 ~124 ~103 grass_block
setblock ~165 ~124 ~104 grass_block
setblock ~165 ~124 ~105 grass_block
setblock ~165 ~124 ~106 grass_block
setblock ~165 ~124 ~107 grass_block
setblock ~165 ~124 ~108 poppy
setblock ~165 ~124 ~111 fern
setblock ~165 ~124 ~113 grass_block
setblock ~165 ~124 ~114 grass_block
setblock ~165 ~124 ~115 grass_block
setblock ~165 ~124 ~116 grass_block
setblock ~165 ~124 ~117 grass_block
setblock ~165 ~124 ~118 grass_block
setblock ~165 ~124 ~119 dirt
setblock ~165 ~124 ~120 dirt
setblock ~165 ~124 ~121 dirt
setblock ~165 ~124 ~122 grass_block
setblock ~165 ~124 ~123 grass_block
setblock ~165 ~124 ~124 grass_block
setblock ~165 ~124 ~125 grass_block
setblock ~165 ~124 ~126 fern
setblock ~165 ~124 ~129 short_grass
setblock ~165 ~125 ~86 grass_block
setblock ~165 ~125 ~87 grass_block
setblock ~165 ~125 ~88 dirt
setblock ~165 ~125 ~89 dirt
setblock ~165 ~125 ~90 dirt
setblock ~165 ~125 ~91 dirt
setblock ~165 ~125 ~92 dirt
setblock ~165 ~125 ~93 dirt
setblock ~165 ~125 ~94 dirt
setblock ~165 ~125 ~95 dirt
setblock ~165 ~125 ~96 dirt
setblock ~165 ~125 ~97 dirt
setblock ~165 ~125 ~98 grass_block
setblock ~165 ~125 ~99 grass_block
setblock ~165 ~125 ~100 grass_block
setblock ~165 ~125 ~101 grass_block
setblock ~165 ~125 ~102 grass_block
setblock ~165 ~125 ~106 poppy
setblock ~165 ~125 ~107 short_grass
setblock ~165 ~125 ~114 fern
setblock ~165 ~125 ~116 short_grass
setblock ~165 ~125 ~117 short_grass
setblock ~165 ~125 ~119 grass_block
setblock ~165 ~125 ~120 grass_block
setblock ~165 ~125 ~121 grass_block
setblock ~165 ~125 ~125 short_grass
setblock ~165 ~126 ~88 grass_block
setblock ~165 ~126 ~89 grass_block
setblock ~165 ~126 ~90 dirt
setblock ~165 ~126 ~91 dirt
setblock ~165 ~126 ~92 grass_block
setblock ~165 ~126 ~93 grass_block
setblock ~165 ~126 ~94 grass_block
setblock ~165 ~126 ~95 grass_block
setblock ~165 ~126 ~96 grass_block
setblock ~165 ~126 ~97 grass_block
setblock ~165 ~126 ~99 short_grass
setblock ~165 ~126 ~100 short_grass
setblock ~165 ~126 ~101 short_grass
setblock ~165 ~126 ~119 short_grass
setblock ~165 ~127 ~90 grass_block
setblock ~165 ~127 ~91 grass_block
setblock ~165 ~127 ~94 short_grass
setblock ~165 ~127 ~95 poppy
setblock ~165 ~127 ~96 short_grass
setblock ~166 ~110 ~122 dirt
setblock ~166 ~111 ~98 dirt
setblock ~166 ~111 ~120 dirt
setblock ~166 ~111 ~122 dirt
setblock ~166 ~112 ~95 dirt
setblock ~166 ~112 ~97 dirt
setblock ~166 ~112 ~98 dirt
setblock ~166 ~112 ~99 dirt
setblock ~166 ~112 ~117 dirt
setblock ~166 ~112 ~119 dirt
setblock ~166 ~112 ~120 dirt
setblock ~166 ~112 ~121 dirt
setblock ~166 ~112 ~122 dirt
setblock ~166 ~112 ~123 dirt
setblock ~166 ~113 ~93 dirt
setblock ~166 ~113 ~94 dirt
setblock ~166 ~113 ~95 dirt
setblock ~166 ~113 ~97 dirt
setblock ~166 ~113 ~98 dirt
setblock ~166 ~113 ~99 dirt
setblock ~166 ~113 ~104 dirt
setblock ~166 ~113 ~116 dirt
setblock ~166 ~113 ~117 dirt
setblock ~166 ~113 ~119 dirt
setblock ~166 ~113 ~120 dirt
setblock ~166 ~113 ~121 dirt
setblock ~166 ~113 ~122 dirt
setblock ~166 ~113 ~123 dirt
setblock ~166 ~113 ~124 dirt
setblock ~166 ~114 ~93 dirt
setblock ~166 ~114 ~94 dirt
setblock ~166 ~114 ~95 dirt
setblock ~166 ~114 ~97 dirt
setblock ~166 ~114 ~98 dirt
setblock ~166 ~114 ~99 dirt
setblock ~166 ~114 ~103 dirt
setblock ~166 ~114 ~104 dirt
setblock ~166 ~114 ~115 dirt
setblock ~166 ~114 ~116 dirt
setblock ~166 ~114 ~117 dirt
setblock ~166 ~114 ~119 dirt
setblock ~166 ~114 ~120 dirt
setblock ~166 ~114 ~121 dirt
setblock ~166 ~114 ~122 dirt
setblock ~166 ~114 ~123 dirt
setblock ~166 ~114 ~124 dirt
setblock ~166 ~115 ~90 dirt
setblock ~166 ~115 ~92 dirt
setblock ~166 ~115 ~93 dirt
setblock ~166 ~115 ~94 dirt
setblock ~166 ~115 ~95 dirt
setblock ~166 ~115 ~96 dirt
setblock ~166 ~115 ~97 dirt
setblock ~166 ~115 ~98 dirt
setblock ~166 ~115 ~99 dirt
setblock ~166 ~115 ~100 dirt
setblock ~166 ~115 ~102 dirt
setblock ~166 ~115 ~103 dirt
setblock ~166 ~115 ~104 dirt
setblock ~166 ~115 ~105 dirt
setblock ~166 ~115 ~114 dirt
setblock ~166 ~115 ~115 dirt
setblock ~166 ~115 ~116 dirt
setblock ~166 ~115 ~117 dirt
setblock ~166 ~115 ~118 dirt
setblock ~166 ~115 ~119 dirt
setblock ~166 ~115 ~120 dirt
setblock ~166 ~115 ~121 dirt
setblock ~166 ~115 ~122 dirt
setblock ~166 ~115 ~123 dirt
setblock ~166 ~115 ~124 dirt
setblock ~166 ~116 ~89 dirt
setblock ~166 ~116 ~90 dirt
setblock ~166 ~116 ~91 dirt
setblock ~166 ~116 ~92 dirt
setblock ~166 ~116 ~93 dirt
setblock ~166 ~116 ~94 dirt
setblock ~166 ~116 ~95 dirt
setblock ~166 ~116 ~96 dirt
setblock ~166 ~116 ~97 dirt
setblock ~166 ~116 ~98 dirt
setblock ~166 ~116 ~99 dirt
setblock ~166 ~116 ~100 dirt
setblock ~166 ~116 ~101 dirt
setblock ~166 ~116 ~102 dirt
setblock ~166 ~116 ~103 dirt
setblock ~166 ~116 ~104 dirt
setblock ~166 ~116 ~105 dirt
setblock ~166 ~116 ~107 dirt
setblock ~166 ~116 ~114 dirt
setblock ~166 ~116 ~115 dirt
setblock ~166 ~116 ~116 dirt
setblock ~166 ~116 ~117 dirt
setblock ~166 ~116 ~118 dirt
setblock ~166 ~116 ~119 dirt
setblock ~166 ~116 ~120 dirt
setblock ~166 ~116 ~121 dirt
setblock ~166 ~116 ~122 dirt
setblock ~166 ~116 ~123 dirt
setblock ~166 ~116 ~124 dirt
setblock ~166 ~117 ~88 dirt
setblock ~166 ~117 ~89 dirt
setblock ~166 ~117 ~90 dirt
setblock ~166 ~117 ~91 dirt
setblock ~166 ~117 ~92 dirt
setblock ~166 ~117 ~93 dirt
setblock ~166 ~117 ~94 dirt
setblock ~166 ~117 ~95 dirt
setblock ~166 ~117 ~96 dirt
setblock ~166 ~117 ~97 dirt
setblock ~166 ~117 ~98 dirt
setblock ~166 ~117 ~99 dirt
setblock ~166 ~117 ~100 dirt
setblock ~166 ~117 ~101 dirt
setblock ~166 ~117 ~102 dirt
setblock ~166 ~117 ~103 dirt
setblock ~166 ~117 ~104 dirt
setblock ~166 ~117 ~105 dirt
setblock ~166 ~117 ~106 dirt
setblock ~166 ~117 ~107 dirt
setblock ~166 ~117 ~114 dirt
setblock ~166 ~117 ~115 dirt
setblock ~166 ~117 ~116 dirt
setblock ~166 ~117 ~117 dirt
setblock ~166 ~117 ~118 dirt
setblock ~166 ~117 ~119 dirt
setblock ~166 ~117 ~120 dirt
setblock ~166 ~117 ~121 dirt
setblock ~166 ~117 ~122 dirt
setblock ~166 ~117 ~123 dirt
setblock ~166 ~117 ~124 dirt
setblock ~166 ~117 ~125 dirt
setblock ~166 ~118 ~87 dirt
setblock ~166 ~118 ~88 dirt
setblock ~166 ~118 ~89 dirt
setblock ~166 ~118 ~90 dirt
setblock ~166 ~118 ~91 dirt
setblock ~166 ~118 ~92 dirt
setblock ~166 ~118 ~93 dirt
setblock ~166 ~118 ~94 dirt
setblock ~166 ~118 ~95 dirt
setblock ~166 ~118 ~96 dirt
setblock ~166 ~118 ~97 dirt
setblock ~166 ~118 ~98 dirt
setblock ~166 ~118 ~99 dirt
setblock ~166 ~118 ~100 dirt
setblock ~166 ~118 ~101 dirt
setblock ~166 ~118 ~102 dirt
setblock ~166 ~118 ~103 dirt
setblock ~166 ~118 ~104 dirt
setblock ~166 ~118 ~105 dirt
setblock ~166 ~118 ~106 dirt
setblock ~166 ~118 ~107 dirt
setblock ~166 ~118 ~113 dirt
setblock ~166 ~118 ~114 dirt
setblock ~166 ~118 ~115 dirt
setblock ~166 ~118 ~116 dirt
setblock ~166 ~118 ~117 dirt
setblock ~166 ~118 ~118 dirt
setblock ~166 ~118 ~119 dirt
setblock ~166 ~118 ~120 dirt
setblock ~166 ~118 ~121 dirt
setblock ~166 ~118 ~122 dirt
setblock ~166 ~118 ~123 dirt
setblock ~166 ~118 ~124 dirt
setblock ~166 ~118 ~125 dirt
setblock ~166 ~118 ~126 dirt
setblock ~166 ~119 ~87 dirt
setblock ~166 ~119 ~88 dirt
setblock ~166 ~119 ~89 dirt
setblock ~166 ~119 ~90 dirt
setblock ~166 ~119 ~91 dirt
setblock ~166 ~119 ~92 dirt
setblock ~166 ~119 ~93 dirt
setblock ~166 ~119 ~94 dirt
setblock ~166 ~119 ~95 dirt
setblock ~166 ~119 ~96 dirt
setblock ~166 ~119 ~97 dirt
setblock ~166 ~119 ~98 dirt
setblock ~166 ~119 ~99 dirt
setblock ~166 ~119 ~100 dirt
setblock ~166 ~119 ~101 dirt
setblock ~166 ~119 ~102 dirt
setblock ~166 ~119 ~103 dirt
setblock ~166 ~119 ~104 dirt
setblock ~166 ~119 ~105 dirt
setblock ~166 ~119 ~106 dirt
setblock ~166 ~119 ~107 dirt
setblock ~166 ~119 ~108 dirt
setblock ~166 ~119 ~113 dirt
setblock ~166 ~119 ~114 dirt
setblock ~166 ~119 ~115 dirt
setblock ~166 ~119 ~116 dirt
setblock ~166 ~119 ~117 dirt
setblock ~166 ~119 ~118 dirt
setblock ~166 ~119 ~119 dirt
setblock ~166 ~119 ~120 dirt
setblock ~166 ~119 ~121 dirt
setblock ~166 ~119 ~122 dirt
setblock ~166 ~119 ~123 dirt
setblock ~166 ~119 ~124 dirt
setblock ~166 ~119 ~125 dirt
setblock ~166 ~119 ~126 dirt
setblock ~166 ~119 ~127 dirt
setblock ~166 ~120 ~87 dirt
setblock ~166 ~120 ~88 dirt
setblock ~166 ~120 ~89 dirt
setblock ~166 ~120 ~90 dirt
setblock ~166 ~120 ~91 dirt
setblock ~166 ~120 ~92 dirt
setblock ~166 ~120 ~93 dirt
setblock ~166 ~120 ~94 dirt
setblock ~166 ~120 ~95 dirt
setblock ~166 ~120 ~96 dirt
setblock ~166 ~120 ~97 dirt
setblock ~166 ~120 ~98 dirt
setblock ~166 ~120 ~99 dirt
setblock ~166 ~120 ~100 dirt
setblock ~166 ~120 ~101 dirt
setblock ~166 ~120 ~102 dirt
setblock ~166 ~120 ~103 dirt
setblock ~166 ~120 ~104 dirt
setblock ~166 ~120 ~105 dirt
setblock ~166 ~120 ~106 dirt
setblock ~166 ~120 ~107 dirt
setblock ~166 ~120 ~108 dirt
setblock ~166 ~120 ~112 dirt
setblock ~166 ~120 ~113 dirt
setblock ~166 ~120 ~114 dirt
setblock ~166 ~120 ~115 dirt
setblock ~166 ~120 ~116 dirt
setblock ~166 ~120 ~117 dirt
setblock ~166 ~120 ~118 dirt
setblock ~166 ~120 ~119 dirt
setblock ~166 ~120 ~120 dirt
setblock ~166 ~120 ~121 dirt
setblock ~166 ~120 ~122 dirt
setblock ~166 ~120 ~123 dirt
setblock ~166 ~120 ~124 dirt
setblock ~166 ~120 ~125 dirt
setblock ~166 ~120 ~126 dirt
setblock ~166 ~120 ~127 dirt
setblock ~166 ~121 ~81 dirt
setblock ~166 ~121 ~87 dirt
setblock ~166 ~121 ~88 dirt
setblock ~166 ~121 ~89 dirt
setblock ~166 ~121 ~90 dirt
setblock ~166 ~121 ~91 dirt
setblock ~166 ~121 ~92 dirt
setblock ~166 ~121 ~93 dirt
setblock ~166 ~121 ~94 dirt
setblock ~166 ~121 ~95 dirt
setblock ~166 ~121 ~96 dirt
setblock ~166 ~121 ~97 dirt
setblock ~166 ~121 ~98 dirt
setblock ~166 ~121 ~99 dirt
setblock ~166 ~121 ~100 dirt
setblock ~166 ~121 ~101 dirt
setblock ~166 ~121 ~102 dirt
setblock ~166 ~121 ~103 dirt
setblock ~166 ~121 ~104 dirt
setblock ~166 ~121 ~105 dirt
setblock ~166 ~121 ~106 dirt
setblock ~166 ~121 ~107 dirt
setblock ~166 ~121 ~108 dirt
setblock ~166 ~121 ~109 dirt
setblock ~166 ~121 ~110 dirt
setblock ~166 ~121 ~111 dirt
setblock ~166 ~121 ~112 dirt
setblock ~166 ~121 ~113 dirt
setblock ~166 ~121 ~114 dirt
setblock ~166 ~121 ~115 dirt
setblock ~166 ~121 ~116 dirt
setblock ~166 ~121 ~117 dirt
setblock ~166 ~121 ~118 dirt
setblock ~166 ~121 ~119 dirt
setblock ~166 ~121 ~120 dirt
setblock ~166 ~121 ~121 dirt
setblock ~166 ~121 ~122 dirt
setblock ~166 ~121 ~123 dirt
setblock ~166 ~121 ~124 dirt
setblock ~166 ~121 ~125 dirt
setblock ~166 ~121 ~126 dirt
setblock ~166 ~121 ~127 dirt
setblock ~166 ~121 ~128 dirt
setblock ~166 ~122 ~81 dirt
setblock ~166 ~122 ~87 dirt
setblock ~166 ~122 ~88 dirt
setblock ~166 ~122 ~89 dirt
setblock ~166 ~122 ~90 dirt
setblock ~166 ~122 ~91 dirt
setblock ~166 ~122 ~92 dirt
setblock ~166 ~122 ~93 dirt
setblock ~166 ~122 ~94 dirt
setblock ~166 ~122 ~95 dirt
setblock ~166 ~122 ~96 dirt
setblock ~166 ~122 ~97 dirt
setblock ~166 ~122 ~98 dirt
setblock ~166 ~122 ~99 dirt
setblock ~166 ~122 ~100 dirt
setblock ~166 ~122 ~101 dirt
setblock ~166 ~122 ~102 dirt
setblock ~166 ~122 ~103 dirt
setblock ~166 ~122 ~104 dirt
setblock ~166 ~122 ~105 dirt
setblock ~166 ~122 ~106 dirt
setblock ~166 ~122 ~107 dirt
setblock ~166 ~122 ~108 dirt
setblock ~166 ~122 ~109 dirt
setblock ~166 ~122 ~110 dirt
setblock ~166 ~122 ~111 dirt
setblock ~166 ~122 ~112 dirt
setblock ~166 ~122 ~113 dirt
setblock ~166 ~122 ~114 dirt
setblock ~166 ~122 ~115 dirt
setblock ~166 ~122 ~116 dirt
setblock ~166 ~122 ~117 dirt
setblock ~166 ~122 ~118 dirt
setblock ~166 ~122 ~119 dirt
setblock ~166 ~122 ~120 dirt
setblock ~166 ~122 ~121 dirt
setblock ~166 ~122 ~122 dirt
setblock ~166 ~122 ~123 dirt
setblock ~166 ~122 ~124 dirt
setblock ~166 ~122 ~125 dirt
setblock ~166 ~122 ~126 dirt
setblock ~166 ~122 ~127 dirt
setblock ~166 ~122 ~128 dirt
setblock ~166 ~123 ~81 grass_block
setblock ~166 ~123 ~87 dirt
setblock ~166 ~123 ~88 dirt
setblock ~166 ~123 ~89 dirt
setblock ~166 ~123 ~90 dirt
setblock ~166 ~123 ~91 dirt
setblock ~166 ~123 ~92 dirt
setblock ~166 ~123 ~93 dirt
setblock ~166 ~123 ~94 dirt
setblock ~166 ~123 ~95 dirt
setblock ~166 ~123 ~96 dirt
setblock ~166 ~123 ~97 dirt
setblock ~166 ~123 ~98 dirt
setblock ~166 ~123 ~99 dirt
setblock ~166 ~123 ~100 dirt
setblock ~166 ~123 ~101 dirt
setblock ~166 ~123 ~102 dirt
setblock ~166 ~123 ~103 dirt
setblock ~166 ~123 ~104 dirt
setblock ~166 ~123 ~105 dirt
setblock ~166 ~123 ~106 grass_block
setblock ~166 ~123 ~107 grass_block
setblock ~166 ~123 ~108 grass_block
setblock ~166 ~123 ~109 grass_block
setblock ~166 ~123 ~110 grass_block
setblock ~166 ~123 ~111 grass_block
setblock ~166 ~123 ~112 grass_block
setblock ~166 ~123 ~113 grass_block
setblock ~166 ~123 ~114 grass_block
setblock ~166 ~123 ~115 dirt
setblock ~166 ~123 ~116 dirt
setblock ~166 ~123 ~117 dirt
setblock ~166 ~123 ~118 dirt
setblock ~166 ~123 ~119 dirt
setblock ~166 ~123 ~120 dirt
setblock ~166 ~123 ~121 dirt
setblock ~166 ~123 ~122 dirt
setblock ~166 ~123 ~123 dirt
setblock ~166 ~123 ~124 dirt
setblock ~166 ~123 ~125 grass_block
setblock ~166 ~123 ~126 grass_block
setblock ~166 ~123 ~127 grass_block
setblock ~166 ~123 ~128 grass_block
setblock ~166 ~124 ~87 dirt
setblock ~166 ~124 ~88 dirt
setblock ~166 ~124 ~89 dirt
setblock ~166 ~124 ~90 dirt
setblock ~166 ~124 ~91 dirt
setblock ~166 ~124 ~92 dirt
setblock ~166 ~124 ~93 dirt
setblock ~166 ~124 ~94 dirt
setblock ~166 ~124 ~95 dirt
setblock ~166 ~124 ~96 dirt
setblock ~166 ~124 ~97 dirt
setblock ~166 ~124 ~98 dirt
setblock ~166 ~124 ~99 dirt
setblock ~166 ~124 ~100 dirt
setblock ~166 ~124 ~101 grass_block
setblock ~166 ~124 ~102 grass_block
setblock ~166 ~124 ~103 grass_block
setblock ~166 ~124 ~104 grass_block
setblock ~166 ~124 ~105 grass_block
setblock ~166 ~124 ~112 short_grass
setblock ~166 ~124 ~114 short_grass
setblock ~166 ~124 ~115 grass_block
setblock ~166 ~124 ~116 grass_block
setblock ~166 ~124 ~117 grass_block
setblock ~166 ~124 ~118 grass_block
setblock ~166 ~124 ~119 grass_block
setblock ~166 ~124 ~120 grass_block
setblock ~166 ~124 ~121 grass_block
setblock ~166 ~124 ~122 grass_block
setblock ~166 ~124 ~123 grass_block
setblock ~166 ~124 ~124 grass_block
setblock ~166 ~124 ~127 short_grass
setblock ~166 ~125 ~87 dirt
setblock ~166 ~125 ~88 dirt
setblock ~166 ~125 ~89 dirt
setblock ~166 ~125 ~90 dirt
setblock ~166 ~125 ~91 dirt
setblock ~166 ~125 ~92 dirt
setblock ~166 ~125 ~93 dirt
setblock ~166 ~125 ~94 dirt
setblock ~166 ~125 ~95 dirt
setblock ~166 ~125 ~96 dirt
setblock ~166 ~125 ~97 grass_block
setblock ~166 ~125 ~98 grass_block
setblock ~166 ~125 ~99 grass_block
setblock ~166 ~125 ~100 grass_block
setblock ~166 ~125 ~102 short_grass
setblock ~166 ~125 ~104 short_grass
setblock ~166 ~125 ~105 short_grass
setblock ~166 ~125 ~116 fern
setblock ~166 ~125 ~122 poppy
setblock ~166 ~125 ~124 short_grass
setblock ~166 ~126 ~87 grass_block
setblock ~166 ~126 ~88 dirt
setblock ~166 ~126 ~89 dirt
setblock ~166 ~126 ~90 dirt
setblock ~166 ~126 ~91 dirt
setblock ~166 ~126 ~92 dirt
setblock ~166 ~126 ~93 dirt
setblock ~166 ~126 ~94 grass_block
setblock ~166 ~126 ~95 grass_block
setblock ~166 ~126 ~96 grass_block
setblock ~166 ~126 ~98 short_grass
setblock ~166 ~127 ~87 short_grass
setblock ~166 ~127 ~88 grass_block
setblock ~166 ~127 ~89 grass_block
setblock ~166 ~127 ~90 dirt
setblock ~166 ~127 ~91 grass_block
setblock ~166 ~127 ~92 grass_block
setblock ~166 ~127 ~93 grass_block
setblock ~166 ~127 ~96 short_grass
setblock ~166 ~128 ~90 grass_block
setblock ~166 ~128 ~91 short_grass
setblock ~166 ~129 ~90 short_grass
setblock ~167 ~112 ~98 dirt
setblock ~167 ~112 ~122 dirt
setblock ~167 ~113 ~98 dirt
setblock ~167 ~113 ~121 dirt
setblock ~167 ~113 ~122 dirt
setblock ~167 ~113 ~123 dirt
setblock ~167 ~114 ~94 dirt
setblock ~167 ~114 ~98 dirt
setblock ~167 ~114 ~120 dirt
setblock ~167 ~114 ~121 dirt
setblock ~167 ~114 ~122 dirt
setblock ~167 ~114 ~123 dirt
setblock ~167 ~115 ~93 dirt
setblock ~167 ~115 ~94 dirt
setblock ~167 ~115 ~95 dirt
setblock ~167 ~115 ~97 dirt
setblock ~167 ~115 ~98 dirt
setblock ~167 ~115 ~99 dirt
setblock ~167 ~115 ~115 dirt
setblock ~167 ~115 ~117 dirt
setblock ~167 ~115 ~119 dirt
setblock ~167 ~115 ~120 dirt
setblock ~167 ~115 ~121 dirt
setblock ~167 ~115 ~122 dirt
setblock ~167 ~115 ~123 dirt
setblock ~167 ~115 ~124 dirt
setblock ~167 ~116 ~90 dirt
setblock ~167 ~116 ~92 dirt
setblock ~167 ~116 ~93 dirt
setblock ~167 ~116 ~94 dirt
setblock ~167 ~116 ~95 dirt
setblock ~167 ~116 ~96 dirt
setblock ~167 ~116 ~97 dirt
setblock ~167 ~116 ~98 dirt
setblock ~167 ~116 ~99 dirt
setblock ~167 ~116 ~100 dirt
setblock ~167 ~116 ~102 dirt
setblock ~167 ~116 ~103 dirt
setblock ~167 ~116 ~115 dirt
setblock ~167 ~116 ~116 dirt
setblock ~167 ~116 ~117 dirt
setblock ~167 ~116 ~118 dirt
setblock ~167 ~116 ~119 dirt
setblock ~167 ~116 ~120 dirt
setblock ~167 ~116 ~121 dirt
setblock ~167 ~116 ~122 dirt
setblock ~167 ~116 ~123 dirt
setblock ~167 ~116 ~124 dirt
setblock ~167 ~117 ~89 dirt
setblock ~167 ~117 ~90 dirt
setblock ~167 ~117 ~91 dirt
setblock ~167 ~117 ~92 dirt
setblock ~167 ~117 ~93 dirt
setblock ~167 ~117 ~94 dirt
setblock ~167 ~117 ~95 dirt
setblock ~167 ~117 ~96 dirt
setblock ~167 ~117 ~97 dirt
setblock ~167 ~117 ~98 dirt
setblock ~167 ~117 ~99 dirt
setblock ~167 ~117 ~100 dirt
setblock ~167 ~117 ~101 dirt
setblock ~167 ~117 ~102 dirt
setblock ~167 ~117 ~103 dirt
setblock ~167 ~117 ~104 dirt
setblock ~167 ~117 ~105 dirt
setblock ~167 ~117 ~114 dirt
setblock ~167 ~117 ~115 dirt
setblock ~167 ~117 ~116 dirt
setblock ~167 ~117 ~117 dirt
setblock ~167 ~117 ~118 dirt
setblock ~167 ~117 ~119 dirt
setblock ~167 ~117 ~120 dirt
setblock ~167 ~117 ~121 dirt
setblock ~167 ~117 ~122 dirt
setblock ~167 ~117 ~123 dirt
setblock ~167 ~117 ~124 dirt
setblock ~167 ~117 ~125 dirt
setblock ~167 ~118 ~88 dirt
setblock ~167 ~118 ~89 dirt
setblock ~167 ~118 ~90 dirt
setblock ~167 ~118 ~91 dirt
setblock ~167 ~118 ~92 dirt
setblock ~167 ~118 ~93 dirt
setblock ~167 ~118 ~94 dirt
setblock ~167 ~118 ~95 dirt
setblock ~167 ~118 ~96 dirt
setblock ~167 ~118 ~97 dirt
setblock ~167 ~118 ~98 dirt
setblock ~167 ~118 ~99 dirt
setblock ~167 ~118 ~100 dirt
setblock ~167 ~118 ~101 dirt
setblock ~167 ~118 ~102 dirt
setblock ~167 ~118 ~103 dirt
setblock ~167 ~118 ~104 dirt
setblock ~167 ~118 ~105 dirt
setblock ~167 ~118 ~106 dirt
setblock ~167 ~118 ~114 dirt
setblock ~167 ~118 ~115 dirt
setblock ~167 ~118 ~116 dirt
setblock ~167 ~118 ~117 dirt
setblock ~167 ~118 ~118 dirt
setblock ~167 ~118 ~119 dirt
setblock ~167 ~118 ~120 dirt
setblock ~167 ~118 ~121 dirt
setblock ~167 ~118 ~122 dirt
setblock ~167 ~118 ~123 dirt
setblock ~167 ~118 ~124 dirt
setblock ~167 ~118 ~125 dirt
setblock ~167 ~119 ~87 dirt
setblock ~167 ~119 ~88 dirt
setblock ~167 ~119 ~89 dirt
setblock ~167 ~119 ~90 dirt
setblock ~167 ~119 ~91 dirt
setblock ~167 ~119 ~92 dirt
setblock ~167 ~119 ~93 dirt
setblock ~167 ~119 ~94 dirt
setblock ~167 ~119 ~95 dirt
setblock ~167 ~119 ~96 dirt
setblock ~167 ~119 ~97 dirt
setblock ~167 ~119 ~98 dirt
setblock ~167 ~119 ~99 dirt
setblock ~167 ~119 ~100 dirt
setblock ~167 ~119 ~101 dirt
setblock ~167 ~119 ~102 dirt
setblock ~167 ~119 ~103 dirt
setblock ~167 ~119 ~104 dirt
setblock ~167 ~119 ~105 dirt
setblock ~167 ~119 ~106 dirt
setblock ~167 ~119 ~107 dirt
setblock ~167 ~119 ~113 dirt
setblock ~167 ~119 ~114 dirt
setblock ~167 ~119 ~115 dirt
setblock ~167 ~119 ~116 dirt
setblock ~167 ~119 ~117 dirt
setblock ~167 ~119 ~118 dirt
setblock ~167 ~119 ~119 dirt
setblock ~167 ~119 ~120 dirt
setblock ~167 ~119 ~121 dirt
setblock ~167 ~119 ~122 dirt
setblock ~167 ~119 ~123 dirt
setblock ~167 ~119 ~124 dirt
setblock ~167 ~119 ~125 dirt
setblock ~167 ~119 ~126 dirt
setblock ~167 ~120 ~87 dirt
setblock ~167 ~120 ~88 dirt
setblock ~167 ~120 ~89 dirt
setblock ~167 ~120 ~90 dirt
setblock ~167 ~120 ~91 dirt
setblock ~167 ~120 ~92 dirt
setblock ~167 ~120 ~93 dirt
setblock ~167 ~120 ~94 dirt
setblock ~167 ~120 ~95 dirt
setblock ~167 ~120 ~96 dirt
setblock ~167 ~120 ~97 dirt
setblock ~167 ~120 ~98 dirt
setblock ~167 ~120 ~99 dirt
setblock ~167 ~120 ~100 dirt
setblock ~167 ~120 ~101 dirt
setblock ~167 ~120 ~102 dirt
setblock ~167 ~120 ~103 dirt
setblock ~167 ~120 ~104 dirt
setblock ~167 ~120 ~105 dirt
setblock ~167 ~120 ~106 dirt
setblock ~167 ~120 ~107 dirt
setblock ~167 ~120 ~113 dirt
setblock ~167 ~120 ~114 dirt
setblock ~167 ~120 ~115 dirt
setblock ~167 ~120 ~116 dirt
setblock ~167 ~120 ~117 dirt
setblock ~167 ~120 ~118 dirt
setblock ~167 ~120 ~119 dirt
setblock ~167 ~120 ~120 dirt
setblock ~167 ~120 ~121 dirt
setblock ~167 ~120 ~122 dirt
setblock ~167 ~120 ~123 dirt
setblock ~167 ~120 ~124 dirt
setblock ~167 ~120 ~125 dirt
setblock ~167 ~120 ~126 dirt
setblock ~167 ~121 ~87 dirt
setblock ~167 ~121 ~88 dirt
setblock ~167 ~121 ~89 dirt
setblock ~167 ~121 ~90 dirt
setblock ~167 ~121 ~91 dirt
setblock ~167 ~121 ~92 dirt
setblock ~167 ~121 ~93 dirt
setblock ~167 ~121 ~94 dirt
setblock ~167 ~121 ~95 dirt
setblock ~167 ~121 ~96 dirt
setblock ~167 ~121 ~97 dirt
setblock ~167 ~121 ~98 dirt
setblock ~167 ~121 ~99 dirt
setblock ~167 ~121 ~100 dirt
setblock ~167 ~121 ~101 dirt
setblock ~167 ~121 ~102 dirt
setblock ~167 ~121 ~103 dirt
setblock ~167 ~121 ~104 dirt
setblock ~167 ~121 ~105 dirt
setblock ~167 ~121 ~106 dirt
setblock ~167 ~121 ~107 dirt
setblock ~167 ~121 ~108 dirt
setblock ~167 ~121 ~112 dirt
setblock ~167 ~121 ~113 dirt
setblock ~167 ~121 ~114 dirt
setblock ~167 ~121 ~115 dirt
setblock ~167 ~121 ~116 dirt
setblock ~167 ~121 ~117 dirt
setblock ~167 ~121 ~118 dirt
setblock ~167 ~121 ~119 dirt
setblock ~167 ~121 ~120 dirt
setblock ~167 ~121 ~121 dirt
setblock ~167 ~121 ~122 dirt
setblock ~167 ~121 ~123 dirt
setblock ~167 ~121 ~124 dirt
setblock ~167 ~121 ~125 dirt
setblock ~167 ~121 ~126 dirt
setblock ~167 ~121 ~127 dirt
setblock ~167 ~122 ~87 dirt
setblock ~167 ~122 ~88 dirt
setblock ~167 ~122 ~89 dirt
setblock ~167 ~122 ~90 dirt
setblock ~167 ~122 ~91 dirt
setblock ~167 ~122 ~92 dirt
setblock ~167 ~122 ~93 dirt
setblock ~167 ~122 ~94 dirt
setblock ~167 ~122 ~95 dirt
setblock ~167 ~122 ~96 dirt
setblock ~167 ~122 ~97 dirt
setblock ~167 ~122 ~98 dirt
setblock ~167 ~122 ~99 dirt
setblock ~167 ~122 ~100 dirt
setblock ~167 ~122 ~101 dirt
setblock ~167 ~122 ~102 dirt
setblock ~167 ~122 ~103 dirt
setblock ~167 ~122 ~104 dirt
setblock ~167 ~122 ~105 dirt
setblock ~167 ~122 ~106 dirt
setblock ~167 ~122 ~107 dirt
setblock ~167 ~122 ~108 dirt
setblock ~167 ~122 ~112 dirt
setblock ~167 ~122 ~113 dirt
setblock ~167 ~122 ~114 dirt
setblock ~167 ~122 ~115 dirt
setblock ~167 ~122 ~116 dirt
setblock ~167 ~122 ~117 dirt
setblock ~167 ~122 ~118 dirt
setblock ~167 ~122 ~119 dirt
setblock ~167 ~122 ~120 dirt
setblock ~167 ~122 ~121 dirt
setblock ~167 ~122 ~122 dirt
setblock ~167 ~122 ~123 dirt
setblock ~167 ~122 ~124 dirt
setblock ~167 ~122 ~125 dirt
setblock ~167 ~122 ~126 dirt
setblock ~167 ~122 ~127 dirt
setblock ~167 ~123 ~87 dirt
setblock ~167 ~123 ~88 dirt
setblock ~167 ~123 ~89 dirt
setblock ~167 ~123 ~90 dirt
setblock ~167 ~123 ~91 dirt
setblock ~167 ~123 ~92 dirt
setblock ~167 ~123 ~93 dirt
setblock ~167 ~123 ~94 dirt
setblock ~167 ~123 ~95 dirt
setblock ~167 ~123 ~96 dirt
setblock ~167 ~123 ~97 dirt
setblock ~167 ~123 ~98 dirt
setblock ~167 ~123 ~99 dirt
setblock ~167 ~123 ~100 dirt
setblock ~167 ~123 ~101 dirt
setblock ~167 ~123 ~102 dirt
setblock ~167 ~123 ~103 dirt
setblock ~167 ~123 ~104 grass_block
setblock ~167 ~123 ~105 grass_block
setblock ~167 ~123 ~106 grass_block
setblock ~167 ~123 ~107 grass_block
setblock ~167 ~123 ~108 grass_block
setblock ~167 ~123 ~112 grass_block
setblock ~167 ~123 ~113 grass_block
setblock ~167 ~123 ~114 grass_block
setblock ~167 ~123 ~115 grass_block
setblock ~167 ~123 ~116 grass_block
setblock ~167 ~123 ~117 grass_block
setblock ~167 ~123 ~118 grass_block
setblock ~167 ~123 ~119 dirt
setblock ~167 ~123 ~120 dirt
setblock ~167 ~123 ~121 dirt
setblock ~167 ~123 ~122 grass_block
setblock ~167 ~123 ~123 grass_block
setblock ~167 ~123 ~124 grass_block
setblock ~167 ~123 ~125 grass_block
setblock ~167 ~123 ~126 grass_block
setblock ~167 ~123 ~127 grass_block
setblock ~167 ~124 ~87 dirt
setblock ~167 ~124 ~88 dirt
setblock ~167 ~124 ~89 dirt
setblock ~167 ~124 ~90 dirt
setblock ~167 ~124 ~91 dirt
setblock ~167 ~124 ~92 dirt
setblock ~167 ~124 ~93 dirt
setblock ~167 ~124 ~94 dirt
setblock ~167 ~124 ~95 dirt
setblock ~167 ~124 ~96 dirt
setblock ~167 ~124 ~97 dirt
setblock ~167 ~124 ~98 dirt
setblock ~167 ~124 ~99 grass_block
setblock ~167 ~124 ~100 grass_block
setblock ~167 ~124 ~101 grass_block
setblock ~167 ~124 ~102 grass_block
setblock ~167 ~124 ~103 grass_block
setblock ~167 ~124 ~107 fern
setblock ~167 ~124 ~116 short_grass
setblock ~167 ~124 ~117 short_grass
setblock ~167 ~124 ~118 poppy
setblock ~167 ~124 ~119 grass_block
setblock ~167 ~124 ~120 grass_block
setblock ~167 ~124 ~121 grass_block
setblock ~167 ~124 ~124 short_grass
setblock ~167 ~124 ~126 short_grass
setblock ~167 ~125 ~87 dirt
setblock ~167 ~125 ~88 dirt
setblock ~167 ~125 ~89 dirt
setblock ~167 ~125 ~90 dirt
setblock ~167 ~125 ~91 dirt
setblock ~167 ~125 ~92 dirt
setblock ~167 ~125 ~93 dirt
setblock ~167 ~125 ~94 dirt
setblock ~167 ~125 ~95 dirt
setblock ~167 ~125 ~96 dirt
setblock ~167 ~125 ~97 grass_block
setblock ~167 ~125 ~98 grass_block
setblock ~167 ~126 ~87 dirt
setblock ~167 ~126 ~88 dirt
setblock ~167 ~126 ~89 dirt
setblock ~167 ~126 ~90 dirt
setblock ~167 ~126 ~91 dirt
setblock ~167 ~126 ~92 dirt
setblock ~167 ~126 ~93 dirt
setblock ~167 ~126 ~94 dirt
setblock ~167 ~126 ~95 grass_block
setblock ~167 ~126 ~96 grass_block
setblock ~167 ~126 ~97 short_grass
setblock ~167 ~127 ~87 grass_block
setblock ~167 ~127 ~88 grass_block
setblock ~167 ~127 ~89 dirt
setblock ~167 ~127 ~90 dirt
setblock ~167 ~127 ~91 dirt
setblock ~167 ~127 ~92 dirt
setblock ~167 ~127 ~93 grass_block
setblock ~167 ~127 ~94 grass_block
setblock ~167 ~127 ~96 fern
setblock ~167 ~128 ~89 grass_block
setblock ~167 ~128 ~90 dirt
setblock ~167 ~128 ~91 grass_block
setblock ~167 ~128 ~92 grass_block
setblock ~167 ~129 ~90 grass_block
setblock ~167 ~129 ~92 short_grass
setblock ~168 ~113 ~122 dirt
setblock ~168 ~114 ~121 dirt
setblock ~168 ~114 ~122 dirt
setblock ~168 ~114 ~123 dirt
setblock ~168 ~115 ~98 dirt
setblock ~168 ~115 ~120 dirt
setblock ~168 ~115 ~121 dirt
setblock ~168 ~115 ~122 dirt
setblock ~168 ~115 ~123 dirt
setblock ~168 ~116 ~97 dirt
setblock ~168 ~116 ~98 dirt
setblock ~168 ~116 ~99 dirt
setblock ~168 ~116 ~120 dirt
setblock ~168 ~116 ~121 dirt
setblock ~168 ~116 ~122 dirt
setblock ~168 ~116 ~123 dirt
setblock ~168 ~117 ~92 dirt
setblock ~168 ~117 ~95 dirt
setblock ~168 ~117 ~96 dirt
setblock ~168 ~117 ~97 dirt
setblock ~168 ~117 ~98 dirt
setblock ~168 ~117 ~99 dirt
setblock ~168 ~117 ~100 dirt
setblock ~168 ~117 ~103 dirt
setblock ~168 ~117 ~115 dirt
setblock ~168 ~117 ~118 dirt
setblock ~168 ~117 ~119 dirt
setblock ~168 ~117 ~120 dirt
setblock ~168 ~117 ~121 dirt
setblock ~168 ~117 ~122 dirt
setblock ~168 ~117 ~123 dirt
setblock ~168 ~117 ~124 dirt
setblock ~168 ~118 ~89 dirt
setblock ~168 ~118 ~92 dirt
setblock ~168 ~118 ~93 dirt
setblock ~168 ~118 ~94 dirt
setblock ~168 ~118 ~95 dirt
setblock ~168 ~118 ~96 dirt
setblock ~168 ~118 ~97 dirt
setblock ~168 ~118 ~98 dirt
setblock ~168 ~118 ~99 dirt
setblock ~168 ~118 ~100 dirt
setblock ~168 ~118 ~102 dirt
setblock ~168 ~118 ~103 dirt
setblock ~168 ~118 ~104 dirt
setblock ~168 ~118 ~105 dirt
setblock ~168 ~118 ~115 dirt
setblock ~168 ~118 ~116 dirt
setblock ~168 ~118 ~117 dirt
setblock ~168 ~118 ~118 dirt
setblock ~168 ~118 ~119 dirt
setblock ~168 ~118 ~120 dirt
setblock ~168 ~118 ~121 dirt
setblock ~168 ~118 ~122 dirt
setblock ~168 ~118 ~123 dirt
setblock ~168 ~118 ~124 dirt
setblock ~168 ~118 ~125 dirt
setblock ~168 ~119 ~88 dirt
setblock ~168 ~119 ~89 dirt
setblock ~168 ~119 ~90 dirt
setblock ~168 ~119 ~91 dirt
setblock ~168 ~119 ~92 dirt
setblock ~168 ~119 ~93 dirt
setblock ~168 ~119 ~94 dirt
setblock ~168 ~119 ~95 dirt
setblock ~168 ~119 ~96 dirt
setblock ~168 ~119 ~97 dirt
setblock ~168 ~119 ~98 dirt
setblock ~168 ~119 ~99 dirt
setblock ~168 ~119 ~100 dirt
setblock ~168 ~119 ~101 dirt
setblock ~168 ~119 ~102 dirt
setblock ~168 ~119 ~103 dirt
setblock ~168 ~119 ~104 dirt
setblock ~168 ~119 ~105 dirt
setblock ~168 ~119 ~114 dirt
setblock ~168 ~119 ~115 dirt
setblock ~168 ~119 ~116 dirt
setblock ~168 ~119 ~117 dirt
setblock ~168 ~119 ~118 dirt
setblock ~168 ~119 ~119 dirt
setblock ~168 ~119 ~120 dirt
setblock ~168 ~119 ~121 dirt
setblock ~168 ~119 ~122 dirt
setblock ~168 ~119 ~123 dirt
setblock ~168 ~119 ~124 dirt
setblock ~168 ~119 ~125 dirt
setblock ~168 ~120 ~88 dirt
setblock ~168 ~120 ~89 dirt
setblock ~168 ~120 ~90 dirt
setblock ~168 ~120 ~91 dirt
setblock ~168 ~120 ~92 dirt
setblock ~168 ~120 ~93 dirt
setblock ~168 ~120 ~94 dirt
setblock ~168 ~120 ~95 dirt
setblock ~168 ~120 ~96 dirt
setblock ~168 ~120 ~97 dirt
setblock ~168 ~120 ~98 dirt
setblock ~168 ~120 ~99 dirt
setblock ~168 ~120 ~100 dirt
setblock ~168 ~120 ~101 dirt
setblock ~168 ~120 ~102 dirt
setblock ~168 ~120 ~103 dirt
setblock ~168 ~120 ~104 dirt
setblock ~168 ~120 ~105 dirt
setblock ~168 ~120 ~113 dirt
setblock ~168 ~120 ~114 dirt
setblock ~168 ~120 ~115 dirt
setblock ~168 ~120 ~116 dirt
setblock ~168 ~120 ~117 dirt
setblock ~168 ~120 ~118 dirt
setblock ~168 ~120 ~119 dirt
setblock ~168 ~120 ~120 dirt
setblock ~168 ~120 ~121 dirt
setblock ~168 ~120 ~122 dirt
setblock ~168 ~120 ~123 dirt
setblock ~168 ~120 ~124 dirt
setblock ~168 ~120 ~125 dirt
setblock ~168 ~120 ~126 dirt
setblock ~168 ~121 ~88 dirt
setblock ~168 ~121 ~89 dirt
setblock ~168 ~121 ~90 dirt
setblock ~168 ~121 ~91 dirt
setblock ~168 ~121 ~92 dirt
setblock ~168 ~121 ~93 dirt
setblock ~168 ~121 ~94 dirt
setblock ~168 ~121 ~95 dirt
setblock ~168 ~121 ~96 dirt
setblock ~168 ~121 ~97 dirt
setblock ~168 ~121 ~98 dirt
setblock ~168 ~121 ~99 dirt
setblock ~168 ~121 ~100 dirt
setblock ~168 ~121 ~101 dirt
setblock ~168 ~121 ~102 dirt
setblock ~168 ~121 ~103 dirt
setblock ~168 ~121 ~104 dirt
setblock ~168 ~121 ~105 dirt
setblock ~168 ~121 ~106 dirt
setblock ~168 ~121 ~113 dirt
setblock ~168 ~121 ~114 dirt
setblock ~168 ~121 ~115 dirt
setblock ~168 ~121 ~116 dirt
setblock ~168 ~121 ~117 dirt
setblock ~168 ~121 ~118 dirt
setblock ~168 ~121 ~119 dirt
setblock ~168 ~121 ~120 dirt
setblock ~168 ~121 ~121 dirt
setblock ~168 ~121 ~122 dirt
setblock ~168 ~121 ~123 dirt
setblock ~168 ~121 ~124 dirt
setblock ~168 ~121 ~125 dirt
setblock ~168 ~121 ~126 dirt
setblock ~168 ~121 ~127 dirt
setblock ~168 ~122 ~88 dirt
setblock ~168 ~122 ~89 dirt
setblock ~168 ~122 ~90 dirt
setblock ~168 ~122 ~91 dirt
setblock ~168 ~122 ~92 dirt
setblock ~168 ~122 ~93 dirt
setblock ~168 ~122 ~94 dirt
setblock ~168 ~122 ~95 dirt
setblock ~168 ~122 ~96 dirt
setblock ~168 ~122 ~97 dirt
setblock ~168 ~122 ~98 dirt
setblock ~168 ~122 ~99 dirt
setblock ~168 ~122 ~100 dirt
setblock ~168 ~122 ~101 dirt
setblock ~168 ~122 ~102 dirt
setblock ~168 ~122 ~103 dirt
setblock ~168 ~122 ~104 dirt
setblock ~168 ~122 ~105 dirt
setblock ~168 ~122 ~106 dirt
setblock ~168 ~122 ~113 dirt
setblock ~168 ~122 ~114 dirt
setblock ~168 ~122 ~115 dirt
setblock ~168 ~122 ~116 dirt
setblock ~168 ~122 ~117 dirt
setblock ~168 ~122 ~118 dirt
setblock ~168 ~122 ~119 dirt
setblock ~168 ~122 ~120 dirt
setblock ~168 ~122 ~121 dirt
setblock ~168 ~122 ~122 dirt
setblock ~168 ~122 ~123 dirt
setblock ~168 ~122 ~124 dirt
setblock ~168 ~122 ~125 dirt
setblock ~168 ~122 ~126 dirt
setblock ~168 ~122 ~127 dirt
setblock ~168 ~123 ~88 dirt
setblock ~168 ~123 ~89 dirt
setblock ~168 ~123 ~90 dirt
setblock ~168 ~123 ~91 dirt
setblock ~168 ~123 ~92 dirt
setblock ~168 ~123 ~93 dirt
setblock ~168 ~123 ~94 dirt
setblock ~168 ~123 ~95 dirt
setblock ~168 ~123 ~96 dirt
setblock ~168 ~123 ~97 dirt
setblock ~168 ~123 ~98 dirt
setblock ~168 ~123 ~99 dirt
setblock ~168 ~123 ~100 dirt
setblock ~168 ~123 ~101 dirt
setblock ~168 ~123 ~102 grass_block
setblock ~168 ~123 ~103 grass_block
setblock ~168 ~123 ~104 grass_block
setblock ~168 ~123 ~105 grass_block
setblock ~168 ~123 ~106 grass_block
setblock ~168 ~123 ~113 grass_block
setblock ~168 ~123 ~114 grass_block
setblock ~168 ~123 ~115 grass_block
setblock ~168 ~123 ~116 grass_block
setblock ~168 ~123 ~117 grass_block
setblock ~168 ~123 ~118 grass_block
setblock ~168 ~123 ~119 grass_block
setblock ~168 ~123 ~120 grass_block
setblock ~168 ~123 ~121 grass_block
setblock ~168 ~123 ~122 grass_block
setblock ~168 ~123 ~123 grass_block
setblock ~168 ~123 ~124 grass_block
setblock ~168 ~123 ~125 grass_block
setblock ~168 ~123 ~126 grass_block
setblock ~168 ~123 ~127 grass_block
setblock ~168 ~124 ~88 dirt
setblock ~168 ~124 ~89 dirt
setblock ~168 ~124 ~90 dirt
setblock ~168 ~124 ~91 dirt
setblock ~168 ~124 ~92 dirt
setblock ~168 ~124 ~93 dirt
setblock ~168 ~124 ~94 dirt
setblock ~168 ~124 ~95 dirt
setblock ~168 ~124 ~96 dirt
setblock ~168 ~124 ~97 dirt
setblock ~168 ~124 ~98 dirt
setblock ~168 ~124 ~99 grass_block
setblock ~168 ~124 ~100 grass_block
setblock ~168 ~124 ~101 grass_block
setblock ~168 ~124 ~102 short_grass
setblock ~168 ~124 ~104 short_grass
setblock ~168 ~124 ~105 short_grass
setblock ~168 ~124 ~119 short_grass
setblock ~168 ~124 ~122 short_grass
setblock ~168 ~124 ~125 short_grass
setblock ~168 ~124 ~126 short_grass
setblock ~168 ~125 ~88 dirt
setblock ~168 ~125 ~89 dirt
setblock ~168 ~125 ~90 dirt
setblock ~168 ~125 ~91 dirt
setblock ~168 ~125 ~92 dirt
setblock ~168 ~125 ~93 dirt
setblock ~168 ~125 ~94 dirt
setblock ~168 ~125 ~95 dirt
setblock ~168 ~125 ~96 dirt
setblock ~168 ~125 ~97 grass_block
setblock ~168 ~125 ~98 grass_block
setblock ~168 ~125 ~100 short_grass
setblock ~168 ~126 ~88 dirt
setblock ~168 ~126 ~89 dirt
setblock ~168 ~126 ~90 dirt
setblock ~168 ~126 ~91 dirt
setblock ~168 ~126 ~92 dirt
setblock ~168 ~126 ~93 dirt
setblock ~168 ~126 ~94 dirt
setblock ~168 ~126 ~95 grass_block
setblock ~168 ~126 ~96 grass_block
setblock ~168 ~126 ~97 short_grass
setblock ~168 ~127 ~88 dirt
setblock ~168 ~127 ~89 dirt
setblock ~168 ~127 ~90 dirt
setblock ~168 ~127 ~91 dirt
setblock ~168 ~127 ~92 dirt
setblock ~168 ~127 ~93 dirt
setblock ~168 ~127 ~94 grass_block
setblock ~168 ~128 ~88 dirt
setblock ~168 ~128 ~89 dirt
setblock ~168 ~128 ~90 dirt
setblock ~168 ~128 ~91 dirt
setblock ~168 ~128 ~92 grass_block
setblock ~168 ~128 ~93 grass_block
setblock ~168 ~129 ~88 grass_block
setblock ~168 ~129 ~89 grass_block
setblock ~168 ~129 ~90 dirt
setblock ~168 ~129 ~91 grass_block
setblock ~168 ~130 ~88 short_grass
setblock ~168 ~130 ~90 grass_block
setblock ~169 ~114 ~122 dirt
setblock ~169 ~115 ~121 dirt
setblock ~169 ~115 ~122 dirt
setblock ~169 ~115 ~123 dirt
setblock ~169 ~116 ~98 dirt
setblock ~169 ~116 ~121 dirt
setblock ~169 ~116 ~122 dirt
setblock ~169 ~116 ~123 dirt
setblock ~169 ~117 ~97 dirt
setblock ~169 ~117 ~98 dirt
setblock ~169 ~117 ~99 dirt
setblock ~169 ~117 ~120 dirt
setblock ~169 ~117 ~121 dirt
setblock ~169 ~117 ~122 dirt
setblock ~169 ~117 ~123 dirt
setblock ~169 ~118 ~97 dirt
setblock ~169 ~118 ~98 dirt
setblock ~169 ~118 ~99 dirt
setblock ~169 ~118 ~103 dirt
setblock ~169 ~118 ~118 dirt
setblock ~169 ~118 ~119 dirt
setblock ~169 ~118 ~120 dirt
setblock ~169 ~118 ~121 dirt
setblock ~169 ~118 ~122 dirt
setblock ~169 ~118 ~123 dirt
setblock ~169 ~118 ~124 dirt
setblock ~169 ~119 ~93 dirt
setblock ~169 ~119 ~97 dirt
setblock ~169 ~119 ~98 dirt
setblock ~169 ~119 ~99 dirt
setblock ~169 ~119 ~103 dirt
setblock ~169 ~119 ~118 dirt
setblock ~169 ~119 ~119 dirt
setblock ~169 ~119 ~120 dirt
setblock ~169 ~119 ~121 dirt
setblock ~169 ~119 ~122 dirt
setblock ~169 ~119 ~123 dirt
setblock ~169 ~119 ~124 dirt
setblock ~169 ~119 ~125 dirt
setblock ~169 ~120 ~92 dirt
setblock ~169 ~120 ~93 dirt
setblock ~169 ~120 ~94 dirt
setblock ~169 ~120 ~95 dirt
setblock ~169 ~120 ~96 dirt
setblock ~169 ~120 ~97 dirt
setblock ~169 ~120 ~98 dirt
setblock ~169 ~120 ~99 dirt
setblock ~169 ~120 ~100 dirt
setblock ~169 ~120 ~102 dirt
setblock ~169 ~120 ~103 dirt
setblock ~169 ~120 ~104 dirt
setblock ~169 ~120 ~114 dirt
setblock ~169 ~120 ~116 dirt
setblock ~169 ~120 ~117 dirt
setblock ~169 ~120 ~118 dirt
setblock ~169 ~120 ~119 dirt
setblock ~169 ~120 ~120 dirt
setblock ~169 ~120 ~121 dirt
setblock ~169 ~120 ~122 dirt
setblock ~169 ~120 ~123 dirt
setblock ~169 ~120 ~124 dirt
setblock ~169 ~120 ~125 dirt
setblock ~169 ~120 ~126 dirt
setblock ~169 ~121 ~89 dirt
setblock ~169 ~121 ~90 dirt
setblock ~169 ~121 ~92 dirt
setblock ~169 ~121 ~93 dirt
setblock ~169 ~121 ~94 dirt
setblock ~169 ~121 ~95 dirt
setblock ~169 ~121 ~96 dirt
setblock ~169 ~121 ~97 dirt
setblock ~169 ~121 ~98 dirt
setblock ~169 ~121 ~99 dirt
setblock ~169 ~121 ~100 dirt
setblock ~169 ~121 ~101 dirt
setblock ~169 ~121 ~102 dirt
setblock ~169 ~121 ~103 dirt
setblock ~169 ~121 ~104 dirt
setblock ~169 ~121 ~113 dirt
setblock ~169 ~121 ~114 dirt
setblock ~169 ~121 ~115 dirt
setblock ~169 ~121 ~116 dirt
setblock ~169 ~121 ~117 dirt
setblock ~169 ~121 ~118 dirt
setblock ~169 ~121 ~119 dirt
setblock ~169 ~121 ~120 dirt
setblock ~169 ~121 ~121 dirt
setblock ~169 ~121 ~122 dirt
setblock ~169 ~121 ~123 dirt
setblock ~169 ~121 ~124 dirt
setblock ~169 ~121 ~125 dirt
setblock ~169 ~121 ~126 dirt
setblock ~169 ~122 ~89 dirt
setblock ~169 ~122 ~90 dirt
setblock ~169 ~122 ~92 dirt
setblock ~169 ~122 ~93 dirt
setblock ~169 ~122 ~94 dirt
setblock ~169 ~122 ~95 dirt
setblock ~169 ~122 ~96 dirt
setblock ~169 ~122 ~97 dirt
setblock ~169 ~122 ~98 dirt
setblock ~169 ~122 ~99 dirt
setblock ~169 ~122 ~100 dirt
setblock ~169 ~122 ~101 dirt
setblock ~169 ~122 ~102 dirt
setblock ~169 ~122 ~103 dirt
setblock ~169 ~122 ~104 dirt
setblock ~169 ~122 ~113 grass_block
setblock ~169 ~122 ~114 grass_block
setblock ~169 ~122 ~115 grass_block
setblock ~169 ~122 ~116 dirt
setblock ~169 ~122 ~117 dirt
setblock ~169 ~122 ~118 dirt
setblock ~169 ~122 ~119 dirt
setblock ~169 ~122 ~120 dirt
setblock ~169 ~122 ~121 dirt
setblock ~169 ~122 ~122 dirt
setblock ~169 ~122 ~123 dirt
setblock ~169 ~122 ~124 dirt
setblock ~169 ~122 ~125 dirt
setblock ~169 ~122 ~126 dirt
setblock ~169 ~123 ~89 dirt
setblock ~169 ~123 ~90 dirt
setblock ~169 ~123 ~92 dirt
setblock ~169 ~123 ~93 dirt
setblock ~169 ~123 ~94 dirt
setblock ~169 ~123 ~95 dirt
setblock ~169 ~123 ~96 dirt
setblock ~169 ~123 ~97 dirt
setblock ~169 ~123 ~98 dirt
setblock ~169 ~123 ~99 dirt
setblock ~169 ~123 ~100 grass_block
setblock ~169 ~123 ~101 grass_block
setblock ~169 ~123 ~102 grass_block
setblock ~169 ~123 ~103 grass_block
setblock ~169 ~123 ~104 grass_block
setblock ~169 ~123 ~116 grass_block
setblock ~169 ~123 ~117 grass_block
setblock ~169 ~123 ~118 grass_block
setblock ~169 ~123 ~119 grass_block
setblock ~169 ~123 ~120 grass_block
setblock ~169 ~123 ~121 grass_block
setblock ~169 ~123 ~122 grass_block
setblock ~169 ~123 ~123 grass_block
setblock ~169 ~123 ~124 grass_block
setblock ~169 ~123 ~125 grass_block
setblock ~169 ~123 ~126 grass_block
setblock ~169 ~124 ~89 dirt
setblock ~169 ~124 ~90 dirt
setblock ~169 ~124 ~92 dirt
setblock ~169 ~124 ~93 dirt
setblock ~169 ~124 ~94 dirt
setblock ~169 ~124 ~95 dirt
setblock ~169 ~124 ~96 dirt
setblock ~169 ~124 ~97 dirt
setblock ~169 ~124 ~98 grass_block
setblock ~169 ~124 ~99 grass_block
setblock ~169 ~124 ~100 short_grass
setblock ~169 ~124 ~101 fern
setblock ~169 ~124 ~116 short_grass
setblock ~169 ~124 ~118 short_grass
setblock ~169 ~124 ~119 short_grass
setblock ~169 ~124 ~122 short_grass
setblock ~169 ~124 ~123 fern
setblock ~169 ~125 ~89 dirt
setblock ~169 ~125 ~90 dirt
setblock ~169 ~125 ~92 dirt
setblock ~169 ~125 ~93 dirt
setblock ~169 ~125 ~94 dirt
setblock ~169 ~125 ~95 dirt
setblock ~169 ~125 ~96 dirt
setblock ~169 ~125 ~97 grass_block
setblock ~169 ~126 ~89 dirt
setblock ~169 ~126 ~90 dirt
setblock ~169 ~126 ~92 dirt
setblock ~169 ~126 ~93 dirt
setblock ~169 ~126 ~94 dirt
setblock ~169 ~126 ~95 grass_block
setblock ~169 ~126 ~96 grass_block
setblock ~169 ~127 ~89 dirt
setblock ~169 ~127 ~90 dirt
setblock ~169 ~127 ~92 dirt
setblock ~169 ~127 ~93 dirt
setblock ~169 ~127 ~94 grass_block
setblock ~169 ~127 ~95 short_grass
setblock ~169 ~128 ~89 dirt
setblock ~169 ~128 ~90 dirt
setblock ~169 ~128 ~92 dirt
setblock ~169 ~128 ~93 grass_block
setblock ~169 ~129 ~89 dirt
setblock ~169 ~129 ~90 dirt
setblock ~169 ~129 ~92 grass_block
setblock ~169 ~129 ~93 short_grass
setblock ~169 ~130 ~89 dirt
setblock ~169 ~130 ~90 dirt
setblock ~169 ~131 ~89 grass_block
setblock ~169 ~131 ~90 dirt
setblock ~169 ~132 ~90 grass_block
setblock ~170 ~115 ~122 dirt
setblock ~170 ~116 ~122 dirt
setblock ~170 ~117 ~121 dirt
setblock ~170 ~117 ~122 dirt
setblock ~170 ~117 ~123 dirt
setblock ~170 ~118 ~120 dirt
setblock ~170 ~118 ~121 dirt
setblock ~170 ~118 ~122 dirt
setblock ~170 ~118 ~123 dirt
setblock ~170 ~119 ~98 dirt
setblock ~170 ~119 ~120 dirt
setblock ~170 ~119 ~121 dirt
setblock ~170 ~119 ~122 dirt
setblock ~170 ~119 ~123 dirt
setblock ~170 ~119 ~124 dirt
setblock ~170 ~120 ~97 dirt
setblock ~170 ~120 ~98 dirt
setblock ~170 ~120 ~99 dirt
setblock ~170 ~120 ~103 dirt
setblock ~170 ~120 ~118 dirt
setblock ~170 ~120 ~119 dirt
setblock ~170 ~120 ~120 dirt
setblock ~170 ~120 ~121 dirt
setblock ~170 ~120 ~122 dirt
setblock ~170 ~120 ~123 dirt
setblock ~170 ~120 ~124 dirt
setblock ~170 ~120 ~125 dirt
setblock ~170 ~121 ~96 dirt
setblock ~170 ~121 ~97 dirt
setblock ~170 ~121 ~98 dirt
setblock ~170 ~121 ~99 dirt
setblock ~170 ~121 ~100 dirt
setblock ~170 ~121 ~103 dirt
setblock ~170 ~121 ~114 dirt
setblock ~170 ~121 ~116 dirt
setblock ~170 ~121 ~117 dirt
setblock ~170 ~121 ~118 dirt
setblock ~170 ~121 ~119 dirt
setblock ~170 ~121 ~120 dirt
setblock ~170 ~121 ~121 dirt
setblock ~170 ~121 ~122 dirt
setblock ~170 ~121 ~123 dirt
setblock ~170 ~121 ~124 dirt
setblock ~170 ~121 ~125 dirt
setblock ~170 ~122 ~96 dirt
setblock ~170 ~122 ~97 dirt
setblock ~170 ~122 ~98 dirt
setblock ~170 ~122 ~99 dirt
setblock ~170 ~122 ~100 dirt
setblock ~170 ~122 ~103 dirt
setblock ~170 ~122 ~114 grass_block
setblock ~170 ~122 ~116 grass_block
setblock ~170 ~122 ~117 grass_block
setblock ~170 ~122 ~118 grass_block
setblock ~170 ~122 ~119 grass_block
setblock ~170 ~122 ~120 grass_block
setblock ~170 ~122 ~121 grass_block
setblock ~170 ~122 ~122 grass_block
setblock ~170 ~122 ~123 dirt
setblock ~170 ~122 ~124 dirt
setblock ~170 ~122 ~125 dirt
setblock ~170 ~123 ~96 dirt
setblock ~170 ~123 ~97 dirt
setblock ~170 ~123 ~98 dirt
setblock ~170 ~123 ~99 grass_block
setblock ~170 ~123 ~100 grass_block
setblock ~170 ~123 ~103 grass_block
setblock ~170 ~123 ~120 short_grass
setblock ~170 ~123 ~123 grass_block
setblock ~170 ~123 ~124 grass_block
setblock ~170 ~123 ~125 grass_block
setblock ~170 ~124 ~96 dirt
setblock ~170 ~124 ~97 dirt
setblock ~170 ~124 ~98 grass_block
setblock ~170 ~124 ~103 short_grass
setblock ~170 ~124 ~125 short_grass
setblock ~170 ~125 ~96 grass_block
setblock ~170 ~125 ~97 grass_block
setblock ~170 ~125 ~98 short_grass
setblock ~170 ~126 ~96 fern
setblock ~171 ~117 ~122 dirt
setblock ~171 ~118 ~121 dirt
setblock ~171 ~118 ~122 dirt
setblock ~171 ~119 ~121 dirt
setblock ~171 ~119 ~122 dirt
setblock ~171 ~119 ~123 dirt
setblock ~171 ~120 ~98 dirt
setblock ~171 ~120 ~120 dirt
setblock ~171 ~120 ~121 dirt
setblock ~171 ~120 ~122 dirt
setblock ~171 ~120 ~123 dirt
setblock ~171 ~121 ~97 dirt
setblock ~171 ~121 ~98 dirt
setblock ~171 ~121 ~118 dirt
setblock ~171 ~121 ~119 dirt
setblock ~171 ~121 ~120 dirt
setblock ~171 ~121 ~121 dirt
setblock ~171 ~121 ~122 dirt
setblock ~171 ~121 ~123 dirt
setblock ~171 ~121 ~124 dirt
setblock ~171 ~122 ~97 dirt
setblock ~171 ~122 ~98 dirt
setblock ~171 ~122 ~118 dirt
setblock ~171 ~122 ~119 dirt
setblock ~171 ~122 ~120 dirt
setblock ~171 ~122 ~121 dirt
setblock ~171 ~122 ~122 dirt
setblock ~171 ~122 ~123 dirt
setblock ~171 ~122 ~124 dirt
setblock ~171 ~123 ~97 dirt
setblock ~171 ~123 ~98 dirt
setblock ~171 ~123 ~118 grass_block
setblock ~171 ~123 ~119 grass_block
setblock ~171 ~123 ~120 grass_block
setblock ~171 ~123 ~121 grass_block
setblock ~171 ~123 ~122 grass_block
setblock ~171 ~123 ~123 grass_block
setblock ~171 ~123 ~124 grass_block
setblock ~171 ~124 ~97 dirt
setblock ~171 ~124 ~98 grass_block
setblock ~171 ~124 ~118 short_grass
setblock ~171 ~124 ~120 poppy
setblock ~171 ~125 ~97 grass_block
setblock ~171 ~125 ~98 short_grass
setblock ~172 ~120 ~121 dirt
setblock ~172 ~121 ~120 dirt
setblock ~172 ~121 ~121 dirt
setblock ~172 ~121 ~122 dirt
setblock ~172 ~122 ~120 dirt
setblock ~172 ~122 ~121 dirt
setblock ~172 ~122 ~122 dirt
setblock ~172 ~123 ~120 grass_block
setblock ~172 ~123 ~121 grass_block
setblock ~172 ~123 ~122 grass_block
setblock ~172 ~124 ~121 short_grass
setblock ~199 ~200 ~199 gold_block
