setblock ~0 ~1 ~0 gold_block
setblock ~19 ~121 ~116 dirt
setblock ~19 ~122 ~116 dirt
setblock ~19 ~123 ~116 dirt
setblock ~19 ~124 ~116 dirt
setblock ~19 ~125 ~116 dirt
setblock ~19 ~126 ~116 grass_block
setblock ~20 ~119 ~116 dirt
setblock ~20 ~120 ~116 dirt
setblock ~20 ~120 ~127 dirt
setblock ~20 ~121 ~115 dirt
setblock ~20 ~121 ~116 dirt
setblock ~20 ~121 ~117 dirt
setblock ~20 ~121 ~127 dirt
setblock ~20 ~122 ~115 dirt
setblock ~20 ~122 ~116 dirt
setblock ~20 ~122 ~117 dirt
setblock ~20 ~122 ~127 dirt
setblock ~20 ~123 ~115 dirt
setblock ~20 ~123 ~116 dirt
setblock ~20 ~123 ~117 dirt
setblock ~20 ~123 ~127 dirt
setblock ~20 ~124 ~115 dirt
setblock ~20 ~124 ~116 dirt
setblock ~20 ~124 ~117 dirt
setblock ~20 ~124 ~127 dirt
setblock ~20 ~125 ~115 dirt
setblock ~20 ~125 ~116 dirt
setblock ~20 ~125 ~117 dirt
setblock ~20 ~125 ~127 grass_block
setblock ~20 ~126 ~115 grass_block
setblock ~20 ~126 ~116 grass_block
setblock ~20 ~126 ~117 grass_block
setblock ~20 ~127 ~116 short_grass
setblock ~20 ~127 ~117 short_grass
setblock ~21 ~117 ~116 dirt
setblock ~21 ~118 ~116 dirt
setblock ~21 ~119 ~115 dirt
setblock ~21 ~119 ~116 dirt
setblock ~21 ~119 ~117 dirt
setblock ~21 ~119 ~127 dirt
setblock ~21 ~120 ~114 dirt
setblock ~21 ~120 ~115 dirt
setblock ~21 ~120 ~116 dirt
setblock ~21 ~120 ~117 dirt
setblock ~21 ~120 ~126 dirt
setblock ~21 ~120 ~127 dirt
setblock ~21 ~120 ~128 dirt
setblock ~21 ~121 ~114 dirt
setblock ~21 ~121 ~115 dirt
setblock ~21 ~121 ~116 dirt
setblock ~21 ~121 ~117 dirt
setblock ~21 ~121 ~126 dirt
setblock ~21 ~121 ~127 dirt
setblock ~21 ~121 ~128 dirt
setblock ~21 ~122 ~114 dirt
setblock ~21 ~122 ~115 dirt
setblock ~21 ~122 ~116 dirt
setblock ~21 ~122 ~117 dirt
setblock ~21 ~122 ~126 dirt
setblock ~21 ~122 ~127 dirt
setblock ~21 ~122 ~128 dirt
setblock ~21 ~123 ~114 dirt
setblock ~21 ~123 ~115 dirt
setblock ~21 ~123 ~116 dirt
setblock ~21 ~123 ~117 dirt
setblock ~21 ~123 ~126 dirt
setblock ~21 ~123 ~127 dirt
setblock ~21 ~123 ~128 dirt
setblock ~21 ~124 ~114 dirt
setblock ~21 ~124 ~115 dirt
setblock ~21 ~124 ~116 dirt
setblock ~21 ~124 ~117 dirt
setblock ~21 ~124 ~126 dirt
setblock ~21 ~124 ~127 dirt
setblock ~21 ~124 ~128 dirt
setblock ~21 ~125 ~114 dirt
setblock ~21 ~125 ~115 dirt
setblock ~21 ~125 ~116 dirt
setblock ~21 ~125 ~117 dirt
setblock ~21 ~125 ~126 dirt
setblock ~21 ~125 ~127 dirt
setblock ~21 ~125 ~128 dirt
setblock ~21 ~126 ~114 grass_block
setblock ~21 ~126 ~115 grass_block
setblock ~21 ~126 ~116 grass_block
setblock ~21 ~126 ~117 grass_block
setblock ~21 ~126 ~126 grass_block
setblock ~21 ~126 ~127 grass_block
setblock ~21 ~126 ~128 grass_block
setblock ~21 ~127 ~114 short_grass
setblock ~21 ~127 ~126 short_grass
setblock ~21 ~127 ~128 short_grass
setblock ~22 ~116 ~116 dirt
setblock ~22 ~117 ~115 dirt
setblock ~22 ~117 ~116 dirt
setblock ~22 ~117 ~117 dirt
setblock ~22 ~118 ~115 dirt
setblock ~22 ~118 ~116 dirt
setblock ~22 ~118 ~117 dirt
setblock ~22 ~118 ~127 dirt
setblock ~22 ~119 ~114 dirt
setblock ~22 ~119 ~115 dirt
setblock ~22 ~119 ~116 dirt
setblock ~22 ~119 ~117 dirt
setblock ~22 ~119 ~126 dirt
setblock ~22 ~119 ~127 dirt
setblock ~22 ~119 ~128 dirt
setblock ~22 ~120 ~113 dirt
setblock ~22 ~120 ~114 dirt
setblock ~22 ~120 ~115 dirt
setblock ~22 ~120 ~116 dirt
setblock ~22 ~120 ~117 dirt
setblock ~22 ~120 ~118 dirt
setblock ~22 ~120 ~125 dirt
setblock ~22 ~120 ~126 dirt
setblock ~22 ~120 ~127 dirt
setblock ~22 ~120 ~128 dirt
setblock ~22 ~121 ~113 dirt
setblock ~22 ~121 ~114 dirt
setblock ~22 ~121 ~115 dirt
setblock ~22 ~121 ~116 dirt
setblock ~22 ~121 ~117 dirt
setblock ~22 ~121 ~118 dirt
setblock ~22 ~121 ~125 dirt
setblock ~22 ~121 ~126 dirt
setblock ~22 ~121 ~127 dirt
setblock ~22 ~121 ~128 dirt
setblock ~22 ~121 ~129 dirt
setblock ~22 ~122 ~113 dirt
setblock ~22 ~122 ~114 dirt
setblock ~22 ~122 ~115 dirt
setblock ~22 ~122 ~116 dirt
setblock ~22 ~122 ~117 dirt
setblock ~22 ~122 ~118 dirt
setblock ~22 ~122 ~125 dirt
setblock ~22 ~122 ~126 dirt
setblock ~22 ~122 ~127 dirt
setblock ~22 ~122 ~128 dirt
setblock ~22 ~122 ~129 dirt
setblock ~22 ~123 ~113 dirt
setblock ~22 ~123 ~114 dirt
setblock ~22 ~123 ~115 dirt
setblock ~22 ~123 ~116 dirt
setblock ~22 ~123 ~117 dirt
setblock ~22 ~123 ~118 dirt
setblock ~22 ~123 ~125 dirt
setblock ~22 ~123 ~126 dirt
setblock ~22 ~123 ~127 dirt
setblock ~22 ~123 ~128 dirt
setblock ~22 ~123 ~129 dirt
setblock ~22 ~124 ~113 dirt
setblock ~22 ~124 ~114 dirt
setblock ~22 ~124 ~115 dirt
setblock ~22 ~124 ~116 dirt
setblock ~22 ~124 ~117 dirt
setblock ~22 ~124 ~118 dirt
setblock ~22 ~124 ~125 dirt
setblock ~22 ~124 ~126 dirt
setblock ~22 ~124 ~127 dirt
setblock ~22 ~124 ~128 dirt
setblock ~22 ~124 ~129 dirt
setblock ~22 ~125 ~113 dirt
setblock ~22 ~125 ~114 dirt
setblock ~22 ~125 ~115 dirt
setblock ~22 ~125 ~116 dirt
setblock ~22 ~125 ~117 dirt
setblock ~22 ~125 ~118 dirt
setblock ~22 ~125 ~125 dirt
setblock ~22 ~125 ~126 dirt
setblock ~22 ~125 ~127 dirt
setblock ~22 ~125 ~128 dirt
setblock ~22 ~125 ~129 dirt
setblock ~22 ~126 ~113 grass_block
setblock ~22 ~126 ~114 grass_block
setblock ~22 ~126 ~115 grass_block
setblock ~22 ~126 ~116 grass_block
setblock ~22 ~126 ~117 grass_block
setblock ~22 ~126 ~118 grass_block
setblock ~22 ~126 ~125 grass_block
setblock ~22 ~126 ~126 grass_block
setblock ~22 ~126 ~127 grass_block
setblock ~22 ~126 ~128 grass_block
setblock ~22 ~126 ~129 grass_block
setblock ~22 ~127 ~128 short_grass
setblock ~22 ~127 ~129 short_grass
setblock ~23 ~117 ~116 dirt
setblock ~23 ~117 ~127 dirt
setblock ~23 ~117 ~128 dirt
setblock ~23 ~118 ~115 dirt
setblock ~23 ~118 ~116 dirt
setblock ~23 ~118 ~117 dirt
setblock ~23 ~118 ~126 dirt
setblock ~23 ~118 ~127 dirt
setblock ~23 ~118 ~128 dirt
setblock ~23 ~119 ~114 dirt
setblock ~23 ~119 ~115 dirt
setblock ~23 ~119 ~116 dirt
setblock ~23 ~119 ~117 dirt
setblock ~23 ~119 ~126 dirt
setblock ~23 ~119 ~127 dirt
setblock ~23 ~119 ~128 dirt
setblock ~23 ~119 ~129 dirt
setblock ~23 ~120 ~114 dirt
setblock ~23 ~120 ~115 dirt
setblock ~23 ~120 ~116 dirt
setblock ~23 ~120 ~117 dirt
setblock ~23 ~120 ~118 dirt
setblock ~23 ~120 ~126 dirt
setblock ~23 ~120 ~127 dirt
setblock ~23 ~120 ~128 dirt
setblock ~23 ~120 ~129 dirt
setblock ~23 ~121 ~113 dirt
setblock ~23 ~121 ~114 dirt
setblock ~23 ~121 ~115 dirt
setblock ~23 ~121 ~116 dirt
setblock ~23 ~121 ~117 dirt
setblock ~23 ~121 ~118 dirt
setblock ~23 ~121 ~125 dirt
setblock ~23 ~121 ~126 dirt
setblock ~23 ~121 ~127 dirt
setblock ~23 ~121 ~128 dirt
setblock ~23 ~121 ~129 dirt
setblock ~23 ~121 ~130 dirt
setblock ~23 ~122 ~113 dirt
setblock ~23 ~122 ~114 dirt
setblock ~23 ~122 ~115 dirt
setblock ~23 ~122 ~116 dirt
setblock ~23 ~122 ~117 dirt
setblock ~23 ~122 ~118 dirt
setblock ~23 ~122 ~125 dirt
setblock ~23 ~122 ~126 dirt
setblock ~23 ~122 ~127 dirt
setblock ~23 ~122 ~128 dirt
setblock ~23 ~122 ~129 dirt
setblock ~23 ~122 ~130 dirt
setblock ~23 ~123 ~113 dirt
setblock ~23 ~123 ~114 dirt
setblock ~23 ~123 ~115 dirt
setblock ~23 ~123 ~116 dirt
setblock ~23 ~123 ~117 dirt
setblock ~23 ~123 ~118 dirt
setblock ~23 ~123 ~125 dirt
setblock ~23 ~123 ~126 dirt
setblock ~23 ~123 ~127 dirt
setblock ~23 ~123 ~128 dirt
setblock ~23 ~123 ~129 dirt
setblock ~23 ~123 ~130 dirt
setblock ~23 ~124 ~113 dirt
setblock ~23 ~124 ~114 dirt
setblock ~23 ~124 ~115 dirt
setblock ~23 ~124 ~116 dirt
setblock ~23 ~124 ~117 dirt
setblock ~23 ~124 ~118 dirt
setblock ~23 ~124 ~125 dirt
setblock ~23 ~124 ~126 dirt
setblock ~23 ~124 ~127 dirt
setblock ~23 ~124 ~128 dirt
setblock ~23 ~124 ~129 dirt
setblock ~23 ~124 ~130 dirt
setblock ~23 ~125 ~113 dirt
setblock ~23 ~125 ~114 dirt
setblock ~23 ~125 ~115 dirt
setblock ~23 ~125 ~116 dirt
setblock ~23 ~125 ~117 dirt
setblock ~23 ~125 ~118 dirt
setblock ~23 ~125 ~125 dirt
setblock ~23 ~125 ~126 dirt
setblock ~23 ~125 ~127 dirt
setblock ~23 ~125 ~128 dirt
setblock ~23 ~125 ~129 dirt
setblock ~23 ~125 ~130 grass_block
setblock ~23 ~126 ~113 grass_block
setblock ~23 ~126 ~114 grass_block
setblock ~23 ~126 ~115 grass_block
setblock ~23 ~126 ~116 grass_block
setblock ~23 ~126 ~117 grass_block
setblock ~23 ~126 ~118 grass_block
setblock ~23 ~126 ~125 grass_block
setblock ~23 ~126 ~126 grass_block
setblock ~23 ~126 ~127 grass_block
setblock ~23 ~126 ~128 grass_block
setblock ~23 ~126 ~129 grass_block
setblock ~23 ~126 ~130 short_grass
setblock ~23 ~127 ~114 fern
setblock ~23 ~127 ~126 fern
setblock ~23 ~127 ~128 fern
setblock ~24 ~115 ~127 dirt
setblock ~24 ~116 ~127 dirt
setblock ~24 ~116 ~128 dirt
setblock ~24 ~117 ~126 dirt
setblock ~24 ~117 ~127 dirt
setblock ~24 ~117 ~128 dirt
setblock ~24 ~117 ~129 dirt
setblock ~24 ~118 ~116 dirt
setblock ~24 ~118 ~126 dirt
setblock ~24 ~118 ~127 dirt
setblock ~24 ~118 ~128 dirt
setblock ~24 ~118 ~129 dirt
setblock ~24 ~119 ~115 dirt
setblock ~24 ~119 ~116 dirt
setblock ~24 ~119 ~126 dirt
setblock ~24 ~119 ~127 dirt
setblock ~24 ~119 ~128 dirt
setblock ~24 ~119 ~129 dirt
setblock ~24 ~119 ~130 dirt
setblock ~24 ~120 ~101 dirt
setblock ~24 ~120 ~103 dirt
setblock ~24 ~120 ~115 dirt
setblock ~24 ~120 ~116 dirt
setblock ~24 ~120 ~117 dirt
setblock ~24 ~120 ~126 dirt
setblock ~24 ~120 ~127 dirt
setblock ~24 ~120 ~128 dirt
setblock ~24 ~120 ~129 dirt
setblock ~24 ~120 ~130 dirt
setblock ~24 ~121 ~101 dirt
setblock ~24 ~121 ~102 dirt
setblock ~24 ~121 ~103 dirt
setblock ~24 ~121 ~104 dirt
setblock ~24 ~121 ~114 dirt
setblock ~24 ~121 ~115 dirt
setblock ~24 ~121 ~116 dirt
setblock ~24 ~121 ~117 dirt
setblock ~24 ~121 ~125 dirt
setblock ~24 ~121 ~126 dirt
setblock ~24 ~121 ~127 dirt
setblock ~24 ~121 ~128 dirt
setblock ~24 ~121 ~129 dirt
setblock ~24 ~121 ~130 dirt
setblock ~24 ~121 ~131 dirt
setblock ~24 ~122 ~101 dirt
setblock ~24 ~122 ~102 dirt
setblock ~24 ~122 ~103 dirt
setblock ~24 ~122 ~104 dirt
setblock ~24 ~122 ~114 dirt
setblock ~24 ~122 ~115 dirt
setblock ~24 ~122 ~116 dirt
setblock ~24 ~122 ~117 dirt
setblock ~24 ~122 ~125 dirt
setblock ~24 ~122 ~126 dirt
setblock ~24 ~122 ~127 dirt
setblock ~24 ~122 ~128 dirt
setblock ~24 ~122 ~129 dirt
setblock ~24 ~122 ~130 dirt
setblock ~24 ~122 ~131 dirt
setblock ~24 ~123 ~101 dirt
setblock ~24 ~123 ~102 dirt
setblock ~24 ~123 ~103 dirt
setblock ~24 ~123 ~104 dirt
setblock ~24 ~123 ~114 dirt
setblock ~24 ~123 ~115 dirt
setblock ~24 ~123 ~116 dirt
setblock ~24 ~123 ~117 dirt
setblock ~24 ~123 ~125 dirt
setblock ~24 ~123 ~126 dirt
setblock ~24 ~123 ~127 dirt
setblock ~24 ~123 ~128 dirt
setblock ~24 ~123 ~129 dirt
setblock ~24 ~123 ~130 dirt
setblock ~24 ~123 ~131 dirt
setblock ~24 ~124 ~101 grass_block
setblock ~24 ~124 ~102 dirt
setblock ~24 ~124 ~103 dirt
setblock ~24 ~124 ~104 dirt
setblock ~24 ~124 ~114 dirt
setblock ~24 ~124 ~115 dirt
setblock ~24 ~124 ~116 dirt
setblock ~24 ~124 ~117 dirt
setblock ~24 ~124 ~125 dirt
setblock ~24 ~124 ~126 dirt
setblock ~24 ~124 ~127 dirt
setblock ~24 ~124 ~128 dirt
setblock ~24 ~124 ~129 dirt
setblock ~24 ~124 ~130 dirt
setblock ~24 ~124 ~131 dirt
setblock ~24 ~125 ~101 short_grass
setblock ~24 ~125 ~102 grass_block
setblock ~24 ~125 ~103 grass_block
setblock ~24 ~125 ~104 grass_block
setblock ~24 ~125 ~114 dirt
setblock ~24 ~125 ~115 dirt
setblock ~24 ~125 ~116 dirt
setblock ~24 ~125 ~117 dirt
setblock ~24 ~125 ~125 dirt
setblock ~24 ~125 ~126 dirt
setblock ~24 ~125 ~127 dirt
setblock ~24 ~125 ~128 dirt
setblock ~24 ~125 ~129 dirt
setblock ~24 ~125 ~130 grass_block
setblock ~24 ~125 ~131 dirt
setblock ~24 ~126 ~103 short_grass
setblock ~24 ~126 ~114 grass_block
setblock ~24 ~126 ~115 grass_block
setblock ~24 ~126 ~116 grass_block
setblock ~24 ~126 ~117 dirt
setblock ~24 ~126 ~125 grass_block
setblock ~24 ~126 ~126 grass_block
setblock ~24 ~126 ~127 grass_block
setblock ~24 ~126 ~128 grass_block
setblock ~24 ~126 ~129 grass_block
setblock ~24 ~126 ~130 short_grass
setblock ~24 ~126 ~131 grass_block
setblock ~24 ~127 ~114 short_grass
setblock ~24 ~127 ~116 short_grass
setblock ~24 ~127 ~117 grass_block
setblock ~24 ~127 ~125 short_grass
setblock ~24 ~127 ~126 short_grass
setblock ~24 ~127 ~131 short_grass
setblock ~25 ~112 ~127 dirt
setblock ~25 ~113 ~127 dirt
setblock ~25 ~114 ~127 dirt
setblock ~25 ~115 ~126 dirt
setblock ~25 ~115 ~127 dirt
setblock ~25 ~115 ~128 dirt
setblock ~25 ~116 ~126 dirt
setblock ~25 ~116 ~127 dirt
setblock ~25 ~116 ~128 dirt
setblock ~25 ~116 ~129 dirt
setblock ~25 ~117 ~126 dirt
setblock ~25 ~117 ~127 dirt
setblock ~25 ~117 ~128 dirt
setblock ~25 ~117 ~129 dirt
setblock ~25 ~118 ~101 dirt
setblock ~25 ~118 ~126 dirt
setblock ~25 ~118 ~127 dirt
setblock ~25 ~118 ~128 dirt
setblock ~25 ~118 ~129 dirt
setblock ~25 ~119 ~100 dirt
setblock ~25 ~119 ~101 dirt
setblock ~25 ~119 ~102 dirt
setblock ~25 ~119 ~103 dirt
setblock ~25 ~119 ~125 dirt
setblock ~25 ~119 ~126 dirt
setblock ~25 ~119 ~127 dirt
setblock ~25 ~119 ~128 dirt
setblock ~25 ~119 ~129 dirt
setblock ~25 ~120 ~99 dirt
setblock ~25 ~120 ~100 dirt
setblock ~25 ~120 ~101 dirt
setblock ~25 ~120 ~102 dirt
setblock ~25 ~120 ~103 dirt
setblock ~25 ~120 ~104 dirt
setblock ~25 ~120 ~125 dirt
setblock ~25 ~120 ~126 dirt
setblock ~25 ~120 ~127 dirt
setblock ~25 ~120 ~128 dirt
setblock ~25 ~120 ~129 dirt
setblock ~25 ~120 ~130 dirt
setblock ~25 ~121 ~98 dirt
setblock ~25 ~121 ~99 dirt
setblock ~25 ~121 ~100 dirt
setblock ~25 ~121 ~101 dirt
setblock ~25 ~121 ~102 dirt
setblock ~25 ~121 ~103 dirt
setblock ~25 ~121 ~104 dirt
setblock ~25 ~121 ~105 dirt
setblock ~25 ~121 ~116 dirt
setblock ~25 ~121 ~124 dirt
setblock ~25 ~121 ~125 dirt
setblock ~25 ~121 ~126 dirt
setblock ~25 ~121 ~127 dirt
setblock ~25 ~121 ~128 dirt
setblock ~25 ~121 ~129 dirt
setblock ~25 ~121 ~130 dirt
setblock ~25 ~122 ~98 dirt
setblock ~25 ~122 ~99 dirt
setblock ~25 ~122 ~100 dirt
setblock ~25 ~122 ~101 dirt
setblock ~25 ~122 ~102 dirt
setblock ~25 ~122 ~103 dirt
setblock ~25 ~122 ~104 dirt
setblock ~25 ~122 ~105 dirt
setblock ~25 ~122 ~116 dirt
setblock ~25 ~122 ~124 dirt
setblock ~25 ~122 ~125 dirt
setblock ~25 ~122 ~126 dirt
setblock ~25 ~122 ~127 dirt
setblock ~25 ~122 ~128 dirt
setblock ~25 ~122 ~129 dirt
setblock ~25 ~122 ~130 dirt
setblock ~25 ~123 ~98 dirt
setblock ~25 ~123 ~99 dirt
setblock ~25 ~123 ~100 dirt
setblock ~25 ~123 ~101 dirt
setblock ~25 ~123 ~102 dirt
setblock ~25 ~123 ~103 dirt
setblock ~25 ~123 ~104 dirt
setblock ~25 ~123 ~105 dirt
setblock ~25 ~123 ~116 dirt
setblock ~25 ~123 ~124 dirt
setblock ~25 ~123 ~125 dirt
setblock ~25 ~123 ~126 dirt
setblock ~25 ~123 ~127 dirt
setblock ~25 ~123 ~128 dirt
setblock ~25 ~123 ~129 dirt
setblock ~25 ~123 ~130 dirt
setblock ~25 ~124 ~98 grass_block
setblock ~25 ~124 ~99 grass_block
setblock ~25 ~124 ~100 grass_block
setblock ~25 ~124 ~101 grass_block
setblock ~25 ~124 ~102 dirt
setblock ~25 ~124 ~103 dirt
setblock ~25 ~124 ~104 dirt
setblock ~25 ~124 ~105 dirt
setblock ~25 ~124 ~116 dirt
setblock ~25 ~124 ~124 dirt
setblock ~25 ~124 ~125 dirt
setblock ~25 ~124 ~126 dirt
setblock ~25 ~124 ~127 dirt
setblock ~25 ~124 ~128 dirt
setblock ~25 ~124 ~129 dirt
setblock ~25 ~124 ~130 dirt
setblock ~25 ~125 ~99 fern
setblock ~25 ~125 ~100 short_grass
setblock ~25 ~125 ~101 poppy
setblock ~25 ~125 ~102 grass_block
setblock ~25 ~125 ~103 grass_block
setblock ~25 ~125 ~104 grass_block
setblock ~25 ~125 ~105 grass_block
setblock ~25 ~125 ~116 dirt
setblock ~25 ~125 ~124 dirt
setblock ~25 ~125 ~125 dirt
setblock ~25 ~125 ~126 dirt
setblock ~25 ~125 ~127 dirt
setblock ~25 ~125 ~128 dirt
setblock ~25 ~125 ~129 dirt
setblock ~25 ~125 ~130 grass_block
setblock ~25 ~126 ~116 dirt
setblock ~25 ~126 ~124 dirt
setblock ~25 ~126 ~125 grass_block
setblock ~25 ~126 ~126 grass_block
setblock ~25 ~126 ~127 grass_block
setblock ~25 ~126 ~128 grass_block
setblock ~25 ~126 ~129 grass_block
setblock ~25 ~127 ~116 grass_block
setblock ~25 ~127 ~124 grass_block
setblock ~25 ~127 ~125 short_grass
setblock ~25 ~127 ~126 poppy
setblock ~25 ~127 ~129 short_grass
setblock ~25 ~128 ~116 short_grass
setblock ~26 ~115 ~127 dirt
setblock ~26 ~116 ~101 dirt
setblock ~26 ~116 ~126 dirt
setblock ~26 ~116 ~127 dirt
setblock ~26 ~116 ~128 dirt
setblock ~26 ~117 ~99 dirt
setblock ~26 ~117 ~101 dirt
setblock ~26 ~117 ~102 dirt
setblock ~26 ~117 ~125 dirt
setblock ~26 ~117 ~126 dirt
setblock ~26 ~117 ~127 dirt
setblock ~26 ~117 ~128 dirt
setblock ~26 ~117 ~129 dirt
setblock ~26 ~118 ~99 dirt
setblock ~26 ~118 ~100 dirt
setblock ~26 ~118 ~101 dirt
setblock ~26 ~118 ~102 dirt
setblock ~26 ~118 ~103 dirt
setblock ~26 ~118 ~104 dirt
setblock ~26 ~118 ~125 dirt
setblock ~26 ~118 ~126 dirt
setblock ~26 ~118 ~127 dirt
setblock ~26 ~118 ~128 dirt
setblock ~26 ~118 ~129 dirt
setblock ~26 ~119 ~98 dirt
setblock ~26 ~119 ~99 dirt
setblock ~26 ~119 ~100 dirt
setblock ~26 ~119 ~101 dirt
setblock ~26 ~119 ~102 dirt
setblock ~26 ~119 ~103 dirt
setblock ~26 ~119 ~104 dirt
setblock ~26 ~119 ~125 dirt
setblock ~26 ~119 ~126 dirt
setblock ~26 ~119 ~127 dirt
setblock ~26 ~119 ~128 dirt
setblock ~26 ~119 ~129 dirt
setblock ~26 ~120 ~98 dirt
setblock ~26 ~120 ~99 dirt
setblock ~26 ~120 ~100 dirt
setblock ~26 ~120 ~101 dirt
setblock ~26 ~120 ~102 dirt
setblock ~26 ~120 ~103 dirt
setblock ~26 ~120 ~104 dirt
setblock ~26 ~120 ~105 dirt
setblock ~26 ~120 ~125 dirt
setblock ~26 ~120 ~126 dirt
setblock ~26 ~120 ~127 dirt
setblock ~26 ~120 ~128 dirt
setblock ~26 ~120 ~129 dirt
setblock ~26 ~121 ~97 dirt
setblock ~26 ~121 ~98 dirt
setblock ~26 ~121 ~99 dirt
setblock ~26 ~121 ~100 dirt
setblock ~26 ~121 ~101 dirt
setblock ~26 ~121 ~102 dirt
setblock ~26 ~121 ~103 dirt
setblock ~26 ~121 ~104 dirt
setblock ~26 ~121 ~105 dirt
setblock ~26 ~121 ~106 dirt
setblock ~26 ~121 ~124 dirt
setblock ~26 ~121 ~125 dirt
setblock ~26 ~121 ~126 dirt
setblock ~26 ~121 ~127 dirt
setblock ~26 ~121 ~128 dirt
setblock ~26 ~121 ~129 dirt
setblock ~26 ~121 ~130 dirt
setblock ~26 ~122 ~97 dirt
setblock ~26 ~122 ~98 dirt
setblock ~26 ~122 ~99 dirt
setblock ~26 ~122 ~100 dirt
setblock ~26 ~122 ~101 dirt
setblock ~26 ~122 ~102 dirt
setblock ~26 ~122 ~103 dirt
setblock ~26 ~122 ~104 dirt
setblock ~26 ~122 ~105 dirt
setblock ~26 ~122 ~106 dirt
setblock ~26 ~122 ~124 dirt
setblock ~26 ~122 ~125 dirt
setblock ~26 ~122 ~126 dirt
setblock ~26 ~122 ~127 dirt
setblock ~26 ~122 ~128 dirt
setblock ~26 ~122 ~129 dirt
setblock ~26 ~122 ~130 dirt
setblock ~26 ~123 ~97 dirt
setblock ~26 ~123 ~98 dirt
setblock ~26 ~123 ~99 dirt
setblock ~26 ~123 ~100 dirt
setblock ~26 ~123 ~101 dirt
setblock ~26 ~123 ~102 dirt
setblock ~26 ~123 ~103 dirt
setblock ~26 ~123 ~104 dirt
setblock ~26 ~123 ~105 dirt
setblock ~26 ~123 ~106 dirt
setblock ~26 ~123 ~124 dirt
setblock ~26 ~123 ~125 dirt
setblock ~26 ~123 ~126 dirt
setblock ~26 ~123 ~127 dirt
setblock ~26 ~123 ~128 dirt
setblock ~26 ~123 ~129 dirt
setblock ~26 ~123 ~130 dirt
setblock ~26 ~124 ~97 grass_block
setblock ~26 ~124 ~98 grass_block
setblock ~26 ~124 ~99 grass_block
setblock ~26 ~124 ~100 grass_block
setblock ~26 ~124 ~101 grass_block
setblock ~26 ~124 ~102 dirt
setblock ~26 ~124 ~103 dirt
setblock ~26 ~124 ~104 dirt
setblock ~26 ~124 ~105 dirt
setblock ~26 ~124 ~106 dirt
setblock ~26 ~124 ~124 dirt
setblock ~26 ~124 ~125 dirt
setblock ~26 ~124 ~126 dirt
setblock ~26 ~124 ~127 dirt
setblock ~26 ~124 ~128 dirt
setblock ~26 ~124 ~129 dirt
setblock ~26 ~124 ~130 dirt
setblock ~26 ~125 ~100 short_grass
setblock ~26 ~125 ~101 poppy
setblock ~26 ~125 ~102 grass_block
setblock ~26 ~125 ~103 grass_block
setblock ~26 ~125 ~104 grass_block
setblock ~26 ~125 ~105 grass_block
setblock ~26 ~125 ~106 grass_block
setblock ~26 ~125 ~124 dirt
setblock ~26 ~125 ~125 dirt
setblock ~26 ~125 ~126 dirt
setblock ~26 ~125 ~127 dirt
setblock ~26 ~125 ~128 dirt
setblock ~26 ~125 ~129 dirt
setblock ~26 ~125 ~130 grass_block
setblock ~26 ~126 ~102 fern
setblock ~26 ~126 ~103 poppy
setblock ~26 ~126 ~104 fern
setblock ~26 ~126 ~124 dirt
setblock ~26 ~126 ~125 dirt
setblock ~26 ~126 ~126 grass_block
setblock ~26 ~126 ~127 grass_block
setblock ~26 ~126 ~128 grass_block
setblock ~26 ~126 ~129 grass_block
setblock ~26 ~127 ~124 grass_block
setblock ~26 ~127 ~125 grass_block
setblock ~27 ~115 ~101 dirt
setblock ~27 ~116 ~99 dirt
setblock ~27 ~116 ~100 dirt
setblock ~27 ~116 ~101 dirt
setblock ~27 ~116 ~102 dirt
setblock ~27 ~116 ~103 dirt
setblock ~27 ~116 ~127 dirt
setblock ~27 ~117 ~98 dirt
setblock ~27 ~117 ~99 dirt
setblock ~27 ~117 ~100 dirt
setblock ~27 ~117 ~101 dirt
setblock ~27 ~117 ~102 dirt
setblock ~27 ~117 ~103 dirt
setblock ~27 ~117 ~104 dirt
setblock ~27 ~117 ~126 dirt
setblock ~27 ~117 ~127 dirt
setblock ~27 ~117 ~128 dirt
setblock ~27 ~118 ~98 dirt
setblock ~27 ~118 ~99 dirt
setblock ~27 ~118 ~100 dirt
setblock ~27 ~118 ~101 dirt
setblock ~27 ~118 ~102 dirt
setblock ~27 ~118 ~103 dirt
setblock ~27 ~118 ~104 dirt
setblock ~27 ~118 ~105 dirt
setblock ~27 ~118 ~126 dirt
setblock ~27 ~118 ~127 dirt
setblock ~27 ~118 ~128 dirt
setblock ~27 ~118 ~129 dirt
setblock ~27 ~119 ~97 dirt
setblock ~27 ~119 ~98 dirt
setblock ~27 ~119 ~99 dirt
setblock ~27 ~119 ~100 dirt
setblock ~27 ~119 ~101 dirt
setblock ~27 ~119 ~102 dirt
setblock ~27 ~119 ~103 dirt
setblock ~27 ~119 ~104 dirt
setblock ~27 ~119 ~105 dirt
setblock ~27 ~119 ~126 dirt
setblock ~27 ~119 ~127 dirt
setblock ~27 ~119 ~128 dirt
setblock ~27 ~119 ~129 dirt
setblock ~27 ~120 ~97 dirt
setblock ~27 ~120 ~98 dirt
setblock ~27 ~120 ~99 dirt
setblock ~27 ~120 ~100 dirt
setblock ~27 ~120 ~101 dirt
setblock ~27 ~120 ~102 dirt
setblock ~27 ~120 ~103 dirt
setblock ~27 ~120 ~104 dirt
setblock ~27 ~120 ~105 dirt
setblock ~27 ~120 ~106 dirt
setblock ~27 ~120 ~126 dirt
setblock ~27 ~120 ~127 dirt
setblock ~27 ~120 ~128 dirt
setblock ~27 ~120 ~129 dirt
setblock ~27 ~121 ~97 dirt
setblock ~27 ~121 ~98 dirt
setblock ~27 ~121 ~99 dirt
setblock ~27 ~121 ~100 dirt
setblock ~27 ~121 ~101 dirt
setblock ~27 ~121 ~102 dirt
setblock ~27 ~121 ~103 dirt
setblock ~27 ~121 ~104 dirt
setblock ~27 ~121 ~105 dirt
setblock ~27 ~121 ~106 dirt
setblock ~27 ~121 ~125 dirt
setblock ~27 ~121 ~126 dirt
setblock ~27 ~121 ~127 dirt
setblock ~27 ~121 ~128 dirt
setblock ~27 ~121 ~129 dirt
setblock ~27 ~121 ~130 dirt
setblock ~27 ~122 ~97 dirt
setblock ~27 ~122 ~98 dirt
setblock ~27 ~122 ~99 dirt
setblock ~27 ~122 ~100 dirt
setblock ~27 ~122 ~101 dirt
setblock ~27 ~122 ~102 dirt
setblock ~27 ~122 ~103 dirt
setblock ~27 ~122 ~104 dirt
setblock ~27 ~122 ~105 dirt
setblock ~27 ~122 ~106 dirt
setblock ~27 ~122 ~125 dirt
setblock ~27 ~122 ~126 dirt
setblock ~27 ~122 ~127 dirt
setblock ~27 ~122 ~128 dirt
setblock ~27 ~122 ~129 dirt
setblock ~27 ~122 ~130 dirt
setblock ~27 ~123 ~97 dirt
setblock ~27 ~123 ~98 dirt
setblock ~27 ~123 ~99 dirt
setblock ~27 ~123 ~100 dirt
setblock ~27 ~123 ~101 dirt
setblock ~27 ~123 ~102 dirt
setblock ~27 ~123 ~103 dirt
setblock ~27 ~123 ~104 dirt
setblock ~27 ~123 ~105 dirt
setblock ~27 ~123 ~106 dirt
setblock ~27 ~123 ~125 dirt
setblock ~27 ~123 ~126 dirt
setblock ~27 ~123 ~127 dirt
setblock ~27 ~123 ~128 dirt
setblock ~27 ~123 ~129 dirt
setblock ~27 ~123 ~130 dirt
setblock ~27 ~124 ~97 grass_block
setblock ~27 ~124 ~98 grass_block
setblock ~27 ~124 ~99 grass_block
setblock ~27 ~124 ~100 grass_block
setblock ~27 ~124 ~101 dirt
setblock ~27 ~124 ~102 dirt
setblock ~27 ~124 ~103 dirt
setblock ~27 ~124 ~104 dirt
setblock ~27 ~124 ~105 dirt
setblock ~27 ~124 ~106 dirt
setblock ~27 ~124 ~125 dirt
setblock ~27 ~124 ~126 dirt
setblock ~27 ~124 ~127 dirt
setblock ~27 ~124 ~128 dirt
setblock ~27 ~124 ~129 dirt
setblock ~27 ~124 ~130 dirt
setblock ~27 ~125 ~99 fern
setblock ~27 ~125 ~101 grass_block
setblock ~27 ~125 ~102 grass_block
setblock ~27 ~125 ~103 grass_block
setblock ~27 ~125 ~104 grass_block
setblock ~27 ~125 ~105 grass_block
setblock ~27 ~125 ~106 grass_block
setblock ~27 ~125 ~125 dirt
setblock ~27 ~125 ~126 dirt
setblock ~27 ~125 ~127 dirt
setblock ~27 ~125 ~128 dirt
setblock ~27 ~125 ~129 dirt
setblock ~27 ~125 ~130 grass_block
setblock ~27 ~126 ~102 short_grass
setblock ~27 ~126 ~106 short_grass
setblock ~27 ~126 ~125 dirt
setblock ~27 ~126 ~126 grass_block
setblock ~27 ~126 ~127 grass_block
setblock ~27 ~126 ~128 grass_block
setblock ~27 ~126 ~129 grass_block
setblock ~27 ~126 ~130 poppy
setblock ~27 ~127 ~125 grass_block
setblock ~27 ~128 ~125 short_grass
setblock ~28 ~113 ~101 dirt
setblock ~28 ~113 ~103 dirt
setblock ~28 ~114 ~100 dirt
setblock ~28 ~114 ~101 dirt
setblock ~28 ~114 ~102 dirt
setblock ~28 ~114 ~103 dirt
setblock ~28 ~115 ~99 dirt
setblock ~28 ~115 ~100 dirt
setblock ~28 ~115 ~101 dirt
setblock ~28 ~115 ~102 dirt
setblock ~28 ~115 ~103 dirt
setblock ~28 ~116 ~98 dirt
setblock ~28 ~116 ~99 dirt
setblock ~28 ~116 ~100 dirt
setblock ~28 ~116 ~101 dirt
setblock ~28 ~116 ~102 dirt
setblock ~28 ~116 ~103 dirt
setblock ~28 ~116 ~104 dirt
setblock ~28 ~117 ~98 dirt
setblock ~28 ~117 ~99 dirt
setblock ~28 ~117 ~100 dirt
setblock ~28 ~117 ~101 dirt
setblock ~28 ~117 ~102 dirt
setblock ~28 ~117 ~103 dirt
setblock ~28 ~117 ~104 dirt
setblock ~28 ~117 ~105 dirt
setblock ~28 ~118 ~98 dirt
setblock ~28 ~118 ~99 dirt
setblock ~28 ~118 ~100 dirt
setblock ~28 ~118 ~101 dirt
setblock ~28 ~118 ~102 dirt
setblock ~28 ~118 ~103 dirt
setblock ~28 ~118 ~104 dirt
setblock ~28 ~118 ~105 dirt
setblock ~28 ~118 ~128 dirt
setblock ~28 ~119 ~97 dirt
setblock ~28 ~119 ~98 dirt
setblock ~28 ~119 ~99 dirt
setblock ~28 ~119 ~100 dirt
setblock ~28 ~119 ~101 dirt
setblock ~28 ~119 ~102 dirt
setblock ~28 ~119 ~103 dirt
setblock ~28 ~119 ~104 dirt
setblock ~28 ~119 ~105 dirt
setblock ~28 ~119 ~106 dirt
setblock ~28 ~119 ~127 dirt
setblock ~28 ~119 ~128 dirt
setblock ~28 ~120 ~94 dirt
setblock ~28 ~120 ~97 dirt
setblock ~28 ~120 ~98 dirt
setblock ~28 ~120 ~99 dirt
setblock ~28 ~120 ~100 dirt
setblock ~28 ~120 ~101 dirt
setblock ~28 ~120 ~102 dirt
setblock ~28 ~120 ~103 dirt
setblock ~28 ~120 ~104 dirt
setblock ~28 ~120 ~105 dirt
setblock ~28 ~120 ~106 dirt
setblock ~28 ~120 ~127 dirt
setblock ~28 ~120 ~128 dirt
setblock ~28 ~120 ~129 dirt
setblock ~28 ~121 ~92 dirt
setblock ~28 ~121 ~94 dirt
setblock ~28 ~121 ~95 dirt
setblock ~28 ~121 ~96 dirt
setblock ~28 ~121 ~97 dirt
setblock ~28 ~121 ~98 dirt
setblock ~28 ~121 ~99 dirt
setblock ~28 ~121 ~100 dirt
setblock ~28 ~121 ~101 dirt
setblock ~28 ~121 ~102 dirt
setblock ~28 ~121 ~103 dirt
setblock ~28 ~121 ~104 dirt
setblock ~28 ~121 ~105 dirt
setblock ~28 ~121 ~106 dirt
setblock ~28 ~121 ~107 dirt
setblock ~28 ~121 ~108 dirt
setblock ~28 ~121 ~126 dirt
setblock ~28 ~121 ~127 dirt
setblock ~28 ~121 ~128 dirt
setblock ~28 ~121 ~129 dirt
setblock ~28 ~122 ~92 dirt
setblock ~28 ~122 ~94 dirt
setblock ~28 ~122 ~95 dirt
setblock ~28 ~122 ~96 dirt
setblock ~28 ~122 ~97 dirt
setblock ~28 ~122 ~98 dirt
setblock ~28 ~122 ~99 dirt
setblock ~28 ~122 ~100 dirt
setblock ~28 ~122 ~101 dirt
setblock ~28 ~122 ~102 dirt
setblock ~28 ~122 ~103 dirt
setblock ~28 ~122 ~104 dirt
setblock ~28 ~122 ~105 dirt
setblock ~28 ~122 ~106 dirt
setblock ~28 ~122 ~107 dirt
setblock ~28 ~122 ~108 dirt
setblock ~28 ~122 ~126 dirt
setblock ~28 ~122 ~127 dirt
setblock ~28 ~122 ~128 dirt
setblock ~28 ~122 ~129 dirt
setblock ~28 ~123 ~92 grass_block
setblock ~28 ~123 ~94 dirt
setblock ~28 ~123 ~95 dirt
setblock ~28 ~123 ~96 dirt
setblock ~28 ~123 ~97 dirt
setblock ~28 ~123 ~98 dirt
setblock ~28 ~123 ~99 dirt
setblock ~28 ~123 ~100 dirt
setblock ~28 ~123 ~101 dirt
setblock ~28 ~123 ~102 dirt
setblock ~28 ~123 ~103 dirt
setblock ~28 ~123 ~104 dirt
setblock ~28 ~123 ~105 dirt
setblock ~28 ~123 ~106 dirt
setblock ~28 ~123 ~107 dirt
setblock ~28 ~123 ~108 dirt
setblock ~28 ~123 ~126 dirt
setblock ~28 ~123 ~127 dirt
setblock ~28 ~123 ~128 dirt
setblock ~28 ~123 ~129 dirt
setblock ~28 ~124 ~94 grass_block
setblock ~28 ~124 ~95 grass_block
setblock ~28 ~124 ~96 grass_block
setblock ~28 ~124 ~97 grass_block
setblock ~28 ~124 ~98 grass_block
setblock ~28 ~124 ~99 grass_block
setblock ~28 ~124 ~100 dirt
setblock ~28 ~124 ~101 dirt
setblock ~28 ~124 ~102 dirt
setblock ~28 ~124 ~103 dirt
setblock ~28 ~124 ~104 dirt
setblock ~28 ~124 ~105 dirt
setblock ~28 ~124 ~106 grass_block
setblock ~28 ~124 ~107 grass_block
setblock ~28 ~124 ~108 grass_block
setblock ~28 ~124 ~126 dirt
setblock ~28 ~124 ~127 dirt
setblock ~28 ~124 ~128 dirt
setblock ~28 ~124 ~129 dirt
setblock ~28 ~125 ~94 short_grass
setblock ~28 ~125 ~100 grass_block
setblock ~28 ~125 ~101 grass_block
setblock ~28 ~125 ~102 grass_block
setblock ~28 ~125 ~103 grass_block
setblock ~28 ~125 ~104 grass_block
setblock ~28 ~125 ~105 grass_block
setblock ~28 ~125 ~106 short_grass
setblock ~28 ~125 ~108 short_grass
setblock ~28 ~125 ~126 dirt
setblock ~28 ~125 ~127 dirt
setblock ~28 ~125 ~128 dirt
setblock ~28 ~125 ~129 dirt
setblock ~28 ~126 ~101 fern
setblock ~28 ~126 ~102 short_grass
setblock ~28 ~126 ~126 dirt
setblock ~28 ~126 ~127 grass_block
setblock ~28 ~126 ~128 grass_block
setblock ~28 ~126 ~129 grass_block
setblock ~28 ~127 ~126 grass_block
setblock ~28 ~128 ~126 short_grass
setblock ~29 ~111 ~102 dirt
setblock ~29 ~112 ~101 dirt
setblock ~29 ~112 ~102 dirt
setblock ~29 ~112 ~103 dirt
setblock ~29 ~113 ~99 dirt
setblock ~29 ~113 ~100 dirt
setblock ~29 ~113 ~101 dirt
setblock ~29 ~113 ~102 dirt
setblock ~29 ~113 ~103 dirt
setblock ~29 ~113 ~104 dirt
setblock ~29 ~114 ~99 dirt
setblock ~29 ~114 ~100 dirt
setblock ~29 ~114 ~101 dirt
setblock ~29 ~114 ~102 dirt
setblock ~29 ~114 ~103 dirt
setblock ~29 ~114 ~104 dirt
setblock ~29 ~115 ~98 dirt
setblock ~29 ~115 ~99 dirt
setblock ~29 ~115 ~100 dirt
setblock ~29 ~115 ~101 dirt
setblock ~29 ~115 ~102 dirt
setblock ~29 ~115 ~103 dirt
setblock ~29 ~115 ~104 dirt
setblock ~29 ~115 ~105 dirt
setblock ~29 ~116 ~98 dirt
setblock ~29 ~116 ~99 dirt
setblock ~29 ~116 ~100 dirt
setblock ~29 ~116 ~101 dirt
setblock ~29 ~116 ~102 dirt
setblock ~29 ~116 ~103 dirt
setblock ~29 ~116 ~104 dirt
setblock ~29 ~116 ~105 dirt
setblock ~29 ~117 ~97 dirt
setblock ~29 ~117 ~98 dirt
setblock ~29 ~117 ~99 dirt
setblock ~29 ~117 ~100 dirt
setblock ~29 ~117 ~101 dirt
setblock ~29 ~117 ~102 dirt
setblock ~29 ~117 ~103 dirt
setblock ~29 ~117 ~104 dirt
setblock ~29 ~117 ~105 dirt
setblock ~29 ~117 ~106 dirt
setblock ~29 ~118 ~94 dirt
setblock ~29 ~118 ~96 dirt
setblock ~29 ~118 ~97 dirt
setblock ~29 ~118 ~98 dirt
setblock ~29 ~118 ~99 dirt
setblock ~29 ~118 ~100 dirt
setblock ~29 ~118 ~101 dirt
setblock ~29 ~118 ~102 dirt
setblock ~29 ~118 ~103 dirt
setblock ~29 ~118 ~104 dirt
setblock ~29 ~118 ~105 dirt
setblock ~29 ~118 ~106 dirt
setblock ~29 ~118 ~107 dirt
setblock ~29 ~119 ~94 dirt
setblock ~29 ~119 ~96 dirt
setblock ~29 ~119 ~97 dirt
setblock ~29 ~119 ~98 dirt
setblock ~29 ~119 ~99 dirt
setblock ~29 ~119 ~100 dirt
setblock ~29 ~119 ~101 dirt
setblock ~29 ~119 ~102 dirt
setblock ~29 ~119 ~103 dirt
setblock ~29 ~119 ~104 dirt
setblock ~29 ~119 ~105 dirt
setblock ~29 ~119 ~106 dirt
setblock ~29 ~119 ~107 dirt
setblock ~29 ~120 ~92 dirt
setblock ~29 ~120 ~93 dirt
setblock ~29 ~120 ~94 dirt
setblock ~29 ~120 ~95 dirt
setblock ~29 ~120 ~96 dirt
setblock ~29 ~120 ~97 dirt
setblock ~29 ~120 ~98 dirt
setblock ~29 ~120 ~99 dirt
setblock ~29 ~120 ~100 dirt
setblock ~29 ~120 ~101 dirt
setblock ~29 ~120 ~102 dirt
setblock ~29 ~120 ~103 dirt
setblock ~29 ~120 ~104 dirt
setblock ~29 ~120 ~105 dirt
setblock ~29 ~120 ~106 dirt
setblock ~29 ~120 ~107 dirt
setblock ~29 ~120 ~108 dirt
setblock ~29 ~120 ~128 dirt
setblock ~29 ~121 ~89 dirt
setblock ~29 ~121 ~91 dirt
setblock ~29 ~121 ~92 dirt
setblock ~29 ~121 ~93 dirt
setblock ~29 ~121 ~94 dirt
setblock ~29 ~121 ~95 dirt
setblock ~29 ~121 ~96 dirt
setblock ~29 ~121 ~97 dirt
setblock ~29 ~121 ~98 dirt
setblock ~29 ~121 ~99 dirt
setblock ~29 ~121 ~100 dirt
setblock ~29 ~121 ~101 dirt
setblock ~29 ~121 ~102 dirt
setblock ~29 ~121 ~103 dirt
setblock ~29 ~121 ~104 dirt
setblock ~29 ~121 ~105 dirt
setblock ~29 ~121 ~106 dirt
setblock ~29 ~121 ~107 dirt
setblock ~29 ~121 ~108 dirt
setblock ~29 ~121 ~109 dirt
setblock ~29 ~121 ~118 dirt
setblock ~29 ~121 ~127 dirt
setblock ~29 ~121 ~128 dirt
setblock ~29 ~122 ~89 dirt
setblock ~29 ~122 ~91 dirt
setblock ~29 ~122 ~92 dirt
setblock ~29 ~122 ~93 dirt
setblock ~29 ~122 ~94 dirt
setblock ~29 ~122 ~95 dirt
setblock ~29 ~122 ~96 dirt
setblock ~29 ~122 ~97 dirt
setblock ~29 ~122 ~98 dirt
setblock ~29 ~122 ~99 dirt
setblock ~29 ~122 ~100 dirt
setblock ~29 ~122 ~101 dirt
setblock ~29 ~122 ~102 dirt
setblock ~29 ~122 ~103 dirt
setblock ~29 ~122 ~104 dirt
setblock ~29 ~122 ~105 dirt
setblock ~29 ~122 ~106 dirt
setblock ~29 ~122 ~107 dirt
setblock ~29 ~122 ~108 dirt
setblock ~29 ~122 ~109 dirt
setblock ~29 ~122 ~118 dirt
setblock ~29 ~122 ~127 dirt
setblock ~29 ~122 ~128 dirt
setblock ~29 ~123 ~89 grass_block
setblock ~29 ~123 ~91 grass_block
setblock ~29 ~123 ~92 grass_block
setblock ~29 ~123 ~93 dirt
setblock ~29 ~123 ~94 dirt
setblock ~29 ~123 ~95 dirt
setblock ~29 ~123 ~96 dirt
setblock ~29 ~123 ~97 dirt
setblock ~29 ~123 ~98 dirt
setblock ~29 ~123 ~99 dirt
setblock ~29 ~123 ~100 dirt
setblock ~29 ~123 ~101 dirt
setblock ~29 ~123 ~102 dirt
setblock ~29 ~123 ~103 dirt
setblock ~29 ~123 ~104 dirt
setblock ~29 ~123 ~105 dirt
setblock ~29 ~123 ~106 dirt
setblock ~29 ~123 ~107 dirt
setblock ~29 ~123 ~108 dirt
setblock ~29 ~123 ~109 dirt
setblock ~29 ~123 ~118 dirt
setblock ~29 ~123 ~127 dirt
setblock ~29 ~123 ~128 dirt
setblock ~29 ~124 ~89 short_grass
setblock ~29 ~124 ~93 grass_block
setblock ~29 ~124 ~94 grass_block
setblock ~29 ~124 ~95 grass_block
setblock ~29 ~124 ~96 grass_block
setblock ~29 ~124 ~97 grass_block
setblock ~29 ~124 ~98 grass_block
setblock ~29 ~124 ~99 dirt
setblock ~29 ~124 ~100 dirt
setblock ~29 ~124 ~101 dirt
setblock ~29 ~124 ~102 dirt
setblock ~29 ~124 ~103 dirt
setblock ~29 ~124 ~104 dirt
setblock ~29 ~124 ~105 grass_block
setblock ~29 ~124 ~106 grass_block
setblock ~29 ~124 ~107 grass_block
setblock ~29 ~124 ~108 grass_block
setblock ~29 ~124 ~109 grass_block
setblock ~29 ~124 ~118 dirt
setblock ~29 ~124 ~127 dirt
setblock ~29 ~124 ~128 dirt
setblock ~29 ~125 ~93 fern
setblock ~29 ~125 ~94 short_grass
setblock ~29 ~125 ~99 grass_block
setblock ~29 ~125 ~100 grass_block
setblock ~29 ~125 ~101 grass_block
setblock ~29 ~125 ~102 grass_block
setblock ~29 ~125 ~103 grass_block
setblock ~29 ~125 ~104 grass_block
setblock ~29 ~125 ~105 short_grass
setblock ~29 ~125 ~118 dirt
setblock ~29 ~125 ~127 dirt
setblock ~29 ~125 ~128 dirt
setblock ~29 ~126 ~99 short_grass
setblock ~29 ~126 ~103 short_grass
setblock ~29 ~126 ~104 short_grass
setblock ~29 ~126 ~118 dirt
setblock ~29 ~126 ~127 grass_block
setblock ~29 ~126 ~128 grass_block
setblock ~29 ~127 ~118 dirt
setblock ~29 ~128 ~118 dirt
setblock ~29 ~129 ~118 grass_block
setblock ~30 ~108 ~101 dirt
setblock ~30 ~108 ~103 dirt
setblock ~30 ~109 ~101 dirt
setblock ~30 ~109 ~102 dirt
setblock ~30 ~109 ~103 dirt
setblock ~30 ~110 ~101 dirt
setblock ~30 ~110 ~102 dirt
setblock ~30 ~110 ~103 dirt
setblock ~30 ~110 ~104 dirt
setblock ~30 ~111 ~100 dirt
setblock ~30 ~111 ~101 dirt
setblock ~30 ~111 ~102 dirt
setblock ~30 ~111 ~103 dirt
setblock ~30 ~111 ~104 dirt
setblock ~30 ~112 ~99 dirt
setblock ~30 ~112 ~100 dirt
setblock ~30 ~112 ~101 dirt
setblock ~30 ~112 ~102 dirt
setblock ~30 ~112 ~103 dirt
setblock ~30 ~112 ~104 dirt
setblock ~30 ~113 ~98 dirt
setblock ~30 ~113 ~99 dirt
setblock ~30 ~113 ~100 dirt
setblock ~30 ~113 ~101 dirt
setblock ~30 ~113 ~102 dirt
setblock ~30 ~113 ~103 dirt
setblock ~30 ~113 ~104 dirt
setblock ~30 ~113 ~105 dirt
setblock ~30 ~114 ~98 dirt
setblock ~30 ~114 ~99 dirt
setblock ~30 ~114 ~100 dirt
setblock ~30 ~114 ~101 dirt
setblock ~30 ~114 ~102 dirt
setblock ~30 ~114 ~103 dirt
setblock ~30 ~114 ~104 dirt
setblock ~30 ~114 ~105 dirt
setblock ~30 ~115 ~98 dirt
setblock ~30 ~115 ~99 dirt
setblock ~30 ~115 ~100 dirt
setblock ~30 ~115 ~101 dirt
setblock ~30 ~115 ~102 dirt
setblock ~30 ~115 ~103 dirt
setblock ~30 ~115 ~104 dirt
setblock ~30 ~115 ~105 dirt
setblock ~30 ~115 ~106 dirt
setblock ~30 ~116 ~97 dirt
setblock ~30 ~116 ~98 dirt
setblock ~30 ~116 ~99 dirt
setblock ~30 ~116 ~100 dirt
setblock ~30 ~116 ~101 dirt
setblock ~30 ~116 ~102 dirt
setblock ~30 ~116 ~103 dirt
setblock ~30 ~116 ~104 dirt
setblock ~30 ~116 ~105 dirt
setblock ~30 ~116 ~106 dirt
setblock ~30 ~117 ~92 dirt
setblock ~30 ~117 ~94 dirt
setblock ~30 ~117 ~96 dirt
setblock ~30 ~117 ~97 dirt
setblock ~30 ~117 ~98 dirt
setblock ~30 ~117 ~99 dirt
setblock ~30 ~117 ~100 dirt
setblock ~30 ~117 ~101 dirt
setblock ~30 ~117 ~102 dirt
setblock ~30 ~117 ~103 dirt
setblock ~30 ~117 ~104 dirt
setblock ~30 ~117 ~105 dirt
setblock ~30 ~117 ~106 dirt
setblock ~30 ~117 ~107 dirt
setblock ~30 ~118 ~89 dirt
setblock ~30 ~118 ~92 dirt
setblock ~30 ~118 ~93 dirt
setblock ~30 ~118 ~94 dirt
setblock ~30 ~118 ~95 dirt
setblock ~30 ~118 ~96 dirt
setblock ~30 ~118 ~97 dirt
setblock ~30 ~118 ~98 dirt
setblock ~30 ~118 ~99 dirt
setblock ~30 ~118 ~100 dirt
setblock ~30 ~118 ~101 dirt
setblock ~30 ~118 ~102 dirt
setblock ~30 ~118 ~103 dirt
setblock ~30 ~118 ~104 dirt
setblock ~30 ~118 ~105 dirt
setblock ~30 ~118 ~106 dirt
setblock ~30 ~118 ~107 dirt
setblock ~30 ~118 ~108 dirt
setblock ~30 ~119 ~89 dirt
setblock ~30 ~119 ~92 dirt
setblock ~30 ~119 ~93 dirt
setblock ~30 ~119 ~94 dirt
setblock ~30 ~119 ~95 dirt
setblock ~30 ~119 ~96 dirt
setblock ~30 ~119 ~97 dirt
setblock ~30 ~119 ~98 dirt
setblock ~30 ~119 ~99 dirt
setblock ~30 ~119 ~100 dirt
setblock ~30 ~119 ~101 dirt
setblock ~30 ~119 ~102 dirt
setblock ~30 ~119 ~103 dirt
setblock ~30 ~119 ~104 dirt
setblock ~30 ~119 ~105 dirt
setblock ~30 ~119 ~106 dirt
setblock ~30 ~119 ~107 dirt
setblock ~30 ~119 ~108 dirt
setblock ~30 ~119 ~119 dirt
setblock ~30 ~120 ~89 dirt
setblock ~30 ~120 ~90 dirt
setblock ~30 ~120 ~91 dirt
setblock ~30 ~120 ~92 dirt
setblock ~30 ~120 ~93 dirt
setblock ~30 ~120 ~94 dirt
setblock ~30 ~120 ~95 dirt
setblock ~30 ~120 ~96 dirt
setblock ~30 ~120 ~97 dirt
setblock ~30 ~120 ~98 dirt
setblock ~30 ~120 ~99 dirt
setblock ~30 ~120 ~100 dirt
setblock ~30 ~120 ~101 dirt
setblock ~30 ~120 ~102 dirt
setblock ~30 ~120 ~103 dirt
setblock ~30 ~120 ~104 dirt
setblock ~30 ~120 ~105 dirt
setblock ~30 ~120 ~106 dirt
setblock ~30 ~120 ~107 dirt
setblock ~30 ~120 ~108 dirt
setblock ~30 ~120 ~109 dirt
setblock ~30 ~120 ~117 dirt
setblock ~30 ~120 ~118 dirt
setblock ~30 ~120 ~119 dirt
setblock ~30 ~120 ~120 dirt
setblock ~30 ~121 ~88 dirt
setblock ~30 ~121 ~89 dirt
setblock ~30 ~121 ~90 dirt
setblock ~30 ~121 ~91 dirt
setblock ~30 ~121 ~92 dirt
setblock ~30 ~121 ~93 dirt
setblock ~30 ~121 ~94 dirt
setblock ~30 ~121 ~95 dirt
setblock ~30 ~121 ~96 dirt
setblock ~30 ~121 ~97 dirt
setblock ~30 ~121 ~98 dirt
setblock ~30 ~121 ~99 dirt
setblock ~30 ~121 ~100 dirt
setblock ~30 ~121 ~101 dirt
setblock ~30 ~121 ~102 dirt
setblock ~30 ~121 ~103 dirt
setblock ~30 ~121 ~104 dirt
setblock ~30 ~121 ~105 dirt
setblock ~30 ~121 ~106 dirt
setblock ~30 ~121 ~107 dirt
setblock ~30 ~121 ~108 dirt
setblock ~30 ~121 ~109 dirt
setblock ~30 ~121 ~110 dirt
setblock ~30 ~121 ~116 dirt
setblock ~30 ~121 ~117 dirt
setblock ~30 ~121 ~118 dirt
setblock ~30 ~121 ~119 dirt
setblock ~30 ~121 ~120 dirt
setblock ~30 ~121 ~121 dirt
setblock ~30 ~122 ~88 dirt
setblock ~30 ~122 ~89 dirt
setblock ~30 ~122 ~90 dirt
setblock ~30 ~122 ~91 dirt
setblock ~30 ~122 ~92 dirt
setblock ~30 ~122 ~93 dirt
setblock ~30 ~122 ~94 dirt
setblock ~30 ~122 ~95 dirt
setblock ~30 ~122 ~96 dirt
setblock ~30 ~122 ~97 dirt
setblock ~30 ~122 ~98 dirt
setblock ~30 ~122 ~99 dirt
setblock ~30 ~122 ~100 dirt
setblock ~30 ~122 ~101 dirt
setblock ~30 ~122 ~102 dirt
setblock ~30 ~122 ~103 dirt
setblock ~30 ~122 ~104 dirt
setblock ~30 ~122 ~105 dirt
setblock ~30 ~122 ~106 dirt
setblock ~30 ~122 ~107 dirt
setblock ~30 ~122 ~108 dirt
setblock ~30 ~122 ~109 dirt
setblock ~30 ~122 ~110 dirt
setblock ~30 ~122 ~116 dirt
setblock ~30 ~122 ~117 dirt
setblock ~30 ~122 ~118 dirt
setblock ~30 ~122 ~119 dirt
setblock ~30 ~122 ~120 dirt
setblock ~30 ~122 ~121 dirt
setblock ~30 ~123 ~88 grass_block
setblock ~30 ~123 ~89 grass_block
setblock ~30 ~123 ~90 grass_block
setblock ~30 ~123 ~91 grass_block
setblock ~30 ~123 ~92 grass_block
setblock ~30 ~123 ~93 dirt
setblock ~30 ~123 ~94 dirt
setblock ~30 ~123 ~95 dirt
setblock ~30 ~123 ~96 dirt
setblock ~30 ~123 ~97 dirt
setblock ~30 ~123 ~98 dirt
setblock ~30 ~123 ~99 dirt
setblock ~30 ~123 ~100 dirt
setblock ~30 ~123 ~101 dirt
setblock ~30 ~123 ~102 dirt
setblock ~30 ~123 ~103 dirt
setblock ~30 ~123 ~104 dirt
setblock ~30 ~123 ~105 dirt
setblock ~30 ~123 ~106 dirt
setblock ~30 ~123 ~107 dirt
setblock ~30 ~123 ~108 dirt
setblock ~30 ~123 ~109 dirt
setblock ~30 ~123 ~110 grass_block
setblock ~30 ~123 ~116 dirt
setblock ~30 ~123 ~117 dirt
setblock ~30 ~123 ~118 dirt
setblock ~30 ~123 ~119 dirt
setblock ~30 ~123 ~120 dirt
setblock ~30 ~123 ~121 dirt
setblock ~30 ~124 ~88 short_grass
setblock ~30 ~124 ~90 short_grass
setblock ~30 ~124 ~92 short_grass
setblock ~30 ~124 ~93 grass_block
setblock ~30 ~124 ~94 grass_block
setblock ~30 ~124 ~95 grass_block
setblock ~30 ~124 ~96 grass_block
setblock ~30 ~124 ~97 grass_block
setblock ~30 ~124 ~98 dirt
setblock ~30 ~124 ~99 dirt
setblock ~30 ~124 ~100 dirt
setblock ~30 ~124 ~101 dirt
setblock ~30 ~124 ~102 dirt
setblock ~30 ~124 ~103 dirt
setblock ~30 ~124 ~104 grass_block
setblock ~30 ~124 ~105 grass_block
setblock ~30 ~124 ~106 grass_block
setblock ~30 ~124 ~107 grass_block
setblock ~30 ~124 ~108 grass_block
setblock ~30 ~124 ~109 grass_block
setblock ~30 ~124 ~116 dirt
setblock ~30 ~124 ~117 dirt
setblock ~30 ~124 ~118 dirt
setblock ~30 ~124 ~119 dirt
setblock ~30 ~124 ~120 dirt
setblock ~30 ~124 ~121 dirt
setblock ~30 ~125 ~95 short_grass
setblock ~30 ~125 ~96 short_grass
setblock ~30 ~125 ~97 short_grass
setblock ~30 ~125 ~98 grass_block
setblock ~30 ~125 ~99 grass_block
setblock ~30 ~125 ~100 grass_block
setblock ~30 ~125 ~101 grass_block
setblock ~30 ~125 ~102 grass_block
setblock ~30 ~125 ~103 grass_block
setblock ~30 ~125 ~107 fern
setblock ~30 ~125 ~108 short_grass
setblock ~30 ~125 ~116 dirt
setblock ~30 ~125 ~117 dirt
setblock ~30 ~125 ~118 dirt
setblock ~30 ~125 ~119 dirt
setblock ~30 ~125 ~120 dirt
setblock ~30 ~125 ~121 dirt
setblock ~30 ~126 ~98 short_grass
setblock ~30 ~126 ~99 short_grass
setblock ~30 ~126 ~101 short_grass
setblock ~30 ~126 ~116 dirt
setblock ~30 ~126 ~117 dirt
setblock ~30 ~126 ~118 dirt
setblock ~30 ~126 ~119 dirt
setblock ~30 ~126 ~120 dirt
setblock ~30 ~126 ~121 dirt
setblock ~30 ~127 ~116 grass_block
setblock ~30 ~127 ~117 dirt
setblock ~30 ~127 ~118 dirt
setblock ~30 ~127 ~119 dirt
setblock ~30 ~127 ~120 dirt
setblock ~30 ~127 ~121 dirt
setblock ~30 ~128 ~117 grass_block
setblock ~30 ~128 ~118 dirt
setblock ~30 ~128 ~119 dirt
setblock ~30 ~128 ~120 dirt
setblock ~30 ~128 ~121 dirt
setblock ~30 ~129 ~117 short_grass
setblock ~30 ~129 ~118 grass_block
setblock ~30 ~129 ~119 dirt
setblock ~30 ~129 ~120 dirt
setblock ~30 ~129 ~121 dirt
setblock ~30 ~130 ~119 grass_block
setblock ~30 ~130 ~120 dirt
setblock ~30 ~130 ~121 grass_block
setblock ~30 ~131 ~119 short_grass
setblock ~30 ~131 ~120 grass_block
setblock ~30 ~131 ~121 short_grass
setblock ~31 ~104 ~101 dirt
setblock ~31 ~105 ~101 dirt
setblock ~31 ~106 ~101 dirt
setblock ~31 ~107 ~101 dirt
setblock ~31 ~107 ~103 dirt
setblock ~31 ~108 ~100 dirt
setblock ~31 ~108 ~101 dirt
setblock ~31 ~108 ~102 dirt
setblock ~31 ~108 ~103 dirt
setblock ~31 ~108 ~104 dirt
setblock ~31 ~109 ~100 dirt
setblock ~31 ~109 ~101 dirt
setblock ~31 ~109 ~102 dirt
setblock ~31 ~109 ~103 dirt
setblock ~31 ~109 ~104 dirt
setblock ~31 ~110 ~100 dirt
setblock ~31 ~110 ~101 dirt
setblock ~31 ~110 ~102 dirt
setblock ~31 ~110 ~103 dirt
setblock ~31 ~110 ~104 dirt
setblock ~31 ~110 ~105 dirt
setblock ~31 ~111 ~99 dirt
setblock ~31 ~111 ~100 dirt
setblock ~31 ~111 ~101 dirt
setblock ~31 ~111 ~102 dirt
setblock ~31 ~111 ~103 dirt
setblock ~31 ~111 ~104 dirt
setblock ~31 ~111 ~105 dirt
setblock ~31 ~112 ~98 dirt
setblock ~31 ~112 ~99 dirt
setblock ~31 ~112 ~100 dirt
setblock ~31 ~112 ~101 dirt
setblock ~31 ~112 ~102 dirt
setblock ~31 ~112 ~103 dirt
setblock ~31 ~112 ~104 dirt
setblock ~31 ~112 ~105 dirt
setblock ~31 ~113 ~98 dirt
setblock ~31 ~113 ~99 dirt
setblock ~31 ~113 ~100 dirt
setblock ~31 ~113 ~101 dirt
setblock ~31 ~113 ~102 dirt
setblock ~31 ~113 ~103 dirt
setblock ~31 ~113 ~104 dirt
setblock ~31 ~113 ~105 dirt
setblock ~31 ~114 ~93 dirt
setblock ~31 ~114 ~97 dirt
setblock ~31 ~114 ~98 dirt
setblock ~31 ~114 ~99 dirt
setblock ~31 ~114 ~100 dirt
setblock ~31 ~114 ~101 dirt
setblock ~31 ~114 ~102 dirt
setblock ~31 ~114 ~103 dirt
setblock ~31 ~114 ~104 dirt
setblock ~31 ~114 ~105 dirt
setblock ~31 ~114 ~106 dirt
setblock ~31 ~115 ~92 dirt
setblock ~31 ~115 ~93 dirt
setblock ~31 ~115 ~97 dirt
setblock ~31 ~115 ~98 dirt
setblock ~31 ~115 ~99 dirt
setblock ~31 ~115 ~100 dirt
setblock ~31 ~115 ~101 dirt
setblock ~31 ~115 ~102 dirt
setblock ~31 ~115 ~103 dirt
setblock ~31 ~115 ~104 dirt
setblock ~31 ~115 ~105 dirt
setblock ~31 ~115 ~106 dirt
setblock ~31 ~116 ~92 dirt
setblock ~31 ~116 ~93 dirt
setblock ~31 ~116 ~94 dirt
setblock ~31 ~116 ~96 dirt
setblock ~31 ~116 ~97 dirt
setblock ~31 ~116 ~98 dirt
setblock ~31 ~116 ~99 dirt
setblock ~31 ~116 ~100 dirt
setblock ~31 ~116 ~101 dirt
setblock ~31 ~116 ~102 dirt
setblock ~31 ~116 ~103 dirt
setblock ~31 ~116 ~104 dirt
setblock ~31 ~116 ~105 dirt
setblock ~31 ~116 ~106 dirt
setblock ~31 ~116 ~118 dirt
setblock ~31 ~117 ~89 dirt
setblock ~31 ~117 ~91 dirt
setblock ~31 ~117 ~92 dirt
setblock ~31 ~117 ~93 dirt
setblock ~31 ~117 ~94 dirt
setblock ~31 ~117 ~95 dirt
setblock ~31 ~117 ~96 dirt
setblock ~31 ~117 ~97 dirt
setblock ~31 ~117 ~98 dirt
setblock ~31 ~117 ~99 dirt
setblock ~31 ~117 ~100 dirt
setblock ~31 ~117 ~101 dirt
setblock ~31 ~117 ~102 dirt
setblock ~31 ~117 ~103 dirt
setblock ~31 ~117 ~104 dirt
setblock ~31 ~117 ~105 dirt
setblock ~31 ~117 ~106 dirt
setblock ~31 ~117 ~107 dirt
setblock ~31 ~117 ~117 dirt
setblock ~31 ~117 ~118 dirt
setblock ~31 ~117 ~119 dirt
setblock ~31 ~118 ~88 dirt
setblock ~31 ~118 ~89 dirt
setblock ~31 ~118 ~90 dirt
setblock ~31 ~118 ~91 dirt
setblock ~31 ~118 ~92 dirt
setblock ~31 ~118 ~93 dirt
setblock ~31 ~118 ~94 dirt
setblock ~31 ~118 ~95 dirt
setblock ~31 ~118 ~96 dirt
setblock ~31 ~118 ~97 dirt
setblock ~31 ~118 ~98 dirt
setblock ~31 ~118 ~99 dirt
setblock ~31 ~118 ~100 dirt
setblock ~31 ~118 ~101 dirt
setblock ~31 ~118 ~102 dirt
setblock ~31 ~118 ~103 dirt
setblock ~31 ~118 ~104 dirt
setblock ~31 ~118 ~105 dirt
setblock ~31 ~118 ~106 dirt
setblock ~31 ~118 ~107 dirt
setblock ~31 ~118 ~117 dirt
setblock ~31 ~118 ~118 dirt
setblock ~31 ~118 ~119 dirt
setblock ~31 ~119 ~88 dirt
setblock ~31 ~119 ~89 dirt
setblock ~31 ~119 ~90 dirt
setblock ~31 ~119 ~91 dirt
setblock ~31 ~119 ~92 dirt
setblock ~31 ~119 ~93 dirt
setblock ~31 ~119 ~94 dirt
setblock ~31 ~119 ~95 dirt
setblock ~31 ~119 ~96 dirt
setblock ~31 ~119 ~97 dirt
setblock ~31 ~119 ~98 dirt
setblock ~31 ~119 ~99 dirt
setblock ~31 ~119 ~100 dirt
setblock ~31 ~119 ~101 dirt
setblock ~31 ~119 ~102 dirt
setblock ~31 ~119 ~103 dirt
setblock ~31 ~119 ~104 dirt
setblock ~31 ~119 ~105 dirt
setblock ~31 ~119 ~106 dirt
setblock ~31 ~119 ~107 dirt
setblock ~31 ~119 ~108 dirt
setblock ~31 ~119 ~117 dirt
setblock ~31 ~119 ~118 dirt
setblock ~31 ~119 ~119 dirt
setblock ~31 ~119 ~120 dirt
setblock ~31 ~120 ~66 dirt
setblock ~31 ~120 ~88 dirt
setblock ~31 ~120 ~89 dirt
setblock ~31 ~120 ~90 dirt
setblock ~31 ~120 ~91 dirt
setblock ~31 ~120 ~92 dirt
setblock ~31 ~120 ~93 dirt
setblock ~31 ~120 ~94 dirt
setblock ~31 ~120 ~95 dirt
setblock ~31 ~120 ~96 dirt
setblock ~31 ~120 ~97 dirt
setblock ~31 ~120 ~98 dirt
setblock ~31 ~120 ~99 dirt
setblock ~31 ~120 ~100 dirt
setblock ~31 ~120 ~101 dirt
setblock ~31 ~120 ~102 dirt
setblock ~31 ~120 ~103 dirt
setblock ~31 ~120 ~104 dirt
setblock ~31 ~120 ~105 dirt
setblock ~31 ~120 ~106 dirt
setblock ~31 ~120 ~107 dirt
setblock ~31 ~120 ~108 dirt
setblock ~31 ~120 ~109 dirt
setblock ~31 ~120 ~115 dirt
setblock ~31 ~120 ~116 dirt
setblock ~31 ~120 ~117 dirt
setblock ~31 ~120 ~118 dirt
setblock ~31 ~120 ~119 dirt
setblock ~31 ~120 ~120 dirt
setblock ~31 ~120 ~121 dirt
setblock ~31 ~121 ~62 dirt
setblock ~31 ~121 ~66 dirt
setblock ~31 ~121 ~84 dirt
setblock ~31 ~121 ~86 dirt
setblock ~31 ~121 ~87 dirt
setblock ~31 ~121 ~88 dirt
setblock ~31 ~121 ~89 dirt
setblock ~31 ~121 ~90 dirt
setblock ~31 ~121 ~91 dirt
setblock ~31 ~121 ~92 dirt
setblock ~31 ~121 ~93 dirt
setblock ~31 ~121 ~94 dirt
setblock ~31 ~121 ~95 dirt
setblock ~31 ~121 ~96 dirt
setblock ~31 ~121 ~97 dirt
setblock ~31 ~121 ~98 dirt
setblock ~31 ~121 ~99 dirt
setblock ~31 ~121 ~100 dirt
setblock ~31 ~121 ~101 dirt
setblock ~31 ~121 ~102 dirt
setblock ~31 ~121 ~103 dirt
setblock ~31 ~121 ~104 dirt
setblock ~31 ~121 ~105 dirt
setblock ~31 ~121 ~106 dirt
setblock ~31 ~121 ~107 dirt
setblock ~31 ~121 ~108 dirt
setblock ~31 ~121 ~109 dirt
setblock ~31 ~121 ~110 dirt
setblock ~31 ~121 ~114 dirt
setblock ~31 ~121 ~115 dirt
setblock ~31 ~121 ~116 dirt
setblock ~31 ~121 ~117 dirt
setblock ~31 ~121 ~118 dirt
setblock ~31 ~121 ~119 dirt
setblock ~31 ~121 ~120 dirt
setblock ~31 ~121 ~121 dirt
setblock ~31 ~121 ~122 dirt
setblock ~31 ~122 ~62 dirt
setblock ~31 ~122 ~66 dirt
setblock ~31 ~122 ~84 dirt
setblock ~31 ~122 ~86 dirt
setblock ~31 ~122 ~87 dirt
setblock ~31 ~122 ~88 dirt
setblock ~31 ~122 ~89 dirt
setblock ~31 ~122 ~90 dirt
setblock ~31 ~122 ~91 dirt
setblock ~31 ~122 ~92 dirt
setblock ~31 ~122 ~93 dirt
setblock ~31 ~122 ~94 dirt
setblock ~31 ~122 ~95 dirt
setblock ~31 ~122 ~96 dirt
setblock ~31 ~122 ~97 dirt
setblock ~31 ~122 ~98 dirt
setblock ~31 ~122 ~99 dirt
setblock ~31 ~122 ~100 dirt
setblock ~31 ~122 ~101 dirt
setblock ~31 ~122 ~102 dirt
setblock ~31 ~122 ~103 dirt
setblock ~31 ~122 ~104 dirt
setblock ~31 ~122 ~105 dirt
setblock ~31 ~122 ~106 dirt
setblock ~31 ~122 ~107 dirt
setblock ~31 ~122 ~108 dirt
setblock ~31 ~122 ~109 dirt
setblock ~31 ~122 ~110 dirt
setblock ~31 ~122 ~114 dirt
setblock ~31 ~122 ~115 dirt
setblock ~31 ~122 ~116 dirt
setblock ~31 ~122 ~117 dirt
setblock ~31 ~122 ~118 dirt
setblock ~31 ~122 ~119 dirt
setblock ~31 ~122 ~120 dirt
setblock ~31 ~122 ~121 dirt
setblock ~31 ~122 ~122 dirt
setblock ~31 ~123 ~62 dirt
setblock ~31 ~123 ~66 dirt
setblock ~31 ~123 ~84 dirt
setblock ~31 ~123 ~86 dirt
setblock ~31 ~123 ~87 dirt
setblock ~31 ~123 ~88 grass_block
setblock ~31 ~123 ~89 grass_block
setblock ~31 ~123 ~90 grass_block
setblock ~31 ~123 ~91 grass_block
setblock ~31 ~123 ~92 dirt
setblock ~31 ~123 ~93 dirt
setblock ~31 ~123 ~94 dirt
setblock ~31 ~123 ~95 dirt
setblock ~31 ~123 ~96 dirt
setblock ~31 ~123 ~97 dirt
setblock ~31 ~123 ~98 dirt
setblock ~31 ~123 ~99 dirt
setblock ~31 ~123 ~100 dirt
setblock ~31 ~123 ~101 dirt
setblock ~31 ~123 ~102 dirt
setblock ~31 ~123 ~103 dirt
setblock ~31 ~123 ~104 dirt
setblock ~31 ~123 ~105 dirt
setblock ~31 ~123 ~106 dirt
setblock ~31 ~123 ~107 dirt
setblock ~31 ~123 ~108 dirt
setblock ~31 ~123 ~109 dirt
setblock ~31 ~123 ~110 grass_block
setblock ~31 ~123 ~114 dirt
setblock ~31 ~123 ~115 dirt
setblock ~31 ~123 ~116 dirt
setblock ~31 ~123 ~117 dirt
setblock ~31 ~123 ~118 dirt
setblock ~31 ~123 ~119 dirt
setblock ~31 ~123 ~120 dirt
setblock ~31 ~123 ~121 dirt
setblock ~31 ~123 ~122 dirt
setblock ~31 ~124 ~62 dirt
setblock ~31 ~124 ~66 dirt
setblock ~31 ~124 ~84 grass_block
setblock ~31 ~124 ~86 grass_block
setblock ~31 ~124 ~87 grass_block
setblock ~31 ~124 ~92 grass_block
setblock ~31 ~124 ~93 grass_block
setblock ~31 ~124 ~94 grass_block
setblock ~31 ~124 ~95 grass_block
setblock ~31 ~124 ~96 grass_block
setblock ~31 ~124 ~97 grass_block
setblock ~31 ~124 ~98 dirt
setblock ~31 ~124 ~99 dirt
setblock ~31 ~124 ~100 dirt
setblock ~31 ~124 ~101 dirt
setblock ~31 ~124 ~102 dirt
setblock ~31 ~124 ~103 dirt
setblock ~31 ~124 ~104 grass_block
setblock ~31 ~124 ~105 grass_block
setblock ~31 ~124 ~106 grass_block
setblock ~31 ~124 ~107 grass_block
setblock ~31 ~124 ~108 grass_block
setblock ~31 ~124 ~109 grass_block
setblock ~31 ~124 ~114 dirt
setblock ~31 ~124 ~115 dirt
setblock ~31 ~124 ~116 dirt
setblock ~31 ~124 ~117 dirt
setblock ~31 ~124 ~118 dirt
setblock ~31 ~124 ~119 dirt
setblock ~31 ~124 ~120 dirt
setblock ~31 ~124 ~121 dirt
setblock ~31 ~124 ~122 dirt
setblock ~31 ~125 ~62 dirt
setblock ~31 ~125 ~66 dirt
setblock ~31 ~125 ~84 fern
setblock ~31 ~125 ~93 short_grass
setblock ~31 ~125 ~94 short_grass
setblock ~31 ~125 ~96 poppy
setblock ~31 ~125 ~97 short_grass
setblock ~31 ~125 ~98 grass_block
setblock ~31 ~125 ~99 grass_block
setblock ~31 ~125 ~100 grass_block
setblock ~31 ~125 ~101 grass_block
setblock ~31 ~125 ~102 grass_block
setblock ~31 ~125 ~103 grass_block
setblock ~31 ~125 ~107 short_grass
setblock ~31 ~125 ~109 short_grass
setblock ~31 ~125 ~114 dirt
setblock ~31 ~125 ~115 dirt
setblock ~31 ~125 ~116 dirt
setblock ~31 ~125 ~117 dirt
setblock ~31 ~125 ~118 dirt
setblock ~31 ~125 ~119 dirt
setblock ~31 ~125 ~120 dirt
setblock ~31 ~125 ~121 dirt
setblock ~31 ~125 ~122 dirt
setblock ~31 ~126 ~62 dirt
setblock ~31 ~126 ~66 dirt
setblock ~31 ~126 ~114 grass_block
setblock ~31 ~126 ~115 grass_block
setblock ~31 ~126 ~116 dirt
setblock ~31 ~126 ~117 dirt
setblock ~31 ~126 ~118 dirt
setblock ~31 ~126 ~119 dirt
setblock ~31 ~126 ~120 dirt
setblock ~31 ~126 ~121 dirt
setblock ~31 ~126 ~122 dirt
setblock ~31 ~127 ~62 grass_block
setblock ~31 ~127 ~66 grass_block
setblock ~31 ~127 ~116 grass_block
setblock ~31 ~127 ~117 grass_block
setblock ~31 ~127 ~118 dirt
setblock ~31 ~127 ~119 dirt
setblock ~31 ~127 ~120 dirt
setblock ~31 ~127 ~121 dirt
setblock ~31 ~127 ~122 dirt
setblock ~31 ~128 ~66 short_grass
setblock ~31 ~128 ~118 grass_block
setblock ~31 ~128 ~119 dirt
setblock ~31 ~128 ~120 dirt
setblock ~31 ~128 ~121 dirt
setblock ~31 ~128 ~122 dirt
setblock ~31 ~129 ~119 grass_block
setblock ~31 ~129 ~120 dirt
setblock ~31 ~129 ~121 grass_block
setblock ~31 ~129 ~122 grass_block
setblock ~31 ~130 ~119 short_grass
setblock ~31 ~130 ~120 grass_block
setblock ~32 ~108 ~101 dirt
setblock ~32 ~108 ~103 dirt
setblock ~32 ~109 ~101 dirt
setblock ~32 ~109 ~102 dirt
setblock ~32 ~109 ~103 dirt
setblock ~32 ~110 ~101 dirt
setblock ~32 ~110 ~102 dirt
setblock ~32 ~110 ~103 dirt
setblock ~32 ~110 ~104 dirt
setblock ~32 ~111 ~100 dirt
setblock ~32 ~111 ~101 dirt
setblock ~32 ~111 ~102 dirt
setblock ~32 ~111 ~103 dirt
setblock ~32 ~111 ~104 dirt
setblock ~32 ~112 ~99 dirt
setblock ~32 ~112 ~100 dirt
setblock ~32 ~112 ~101 dirt
setblock ~32 ~112 ~102 dirt
setblock ~32 ~112 ~103 dirt
setblock ~32 ~112 ~104 dirt
setblock ~32 ~113 ~93 dirt
setblock ~32 ~113 ~99 dirt
setblock ~32 ~113 ~100 dirt
setblock ~32 ~113 ~101 dirt
setblock ~32 ~113 ~102 dirt
setblock ~32 ~113 ~103 dirt
setblock ~32 ~113 ~104 dirt
setblock ~32 ~113 ~118 dirt
setblock ~32 ~114 ~91 dirt
setblock ~32 ~114 ~92 dirt
setblock ~32 ~114 ~93 dirt
setblock ~32 ~114 ~94 dirt
setblock ~32 ~114 ~98 dirt
setblock ~32 ~114 ~99 dirt
setblock ~32 ~114 ~100 dirt
setblock ~32 ~114 ~101 dirt
setblock ~32 ~114 ~102 dirt
setblock ~32 ~114 ~103 dirt
setblock ~32 ~114 ~104 dirt
setblock ~32 ~114 ~105 dirt
setblock ~32 ~114 ~118 dirt
setblock ~32 ~115 ~90 dirt
setblock ~32 ~115 ~91 dirt
setblock ~32 ~115 ~92 dirt
setblock ~32 ~115 ~93 dirt
setblock ~32 ~115 ~94 dirt
setblock ~32 ~115 ~95 dirt
setblock ~32 ~115 ~97 dirt
setblock ~32 ~115 ~98 dirt
setblock ~32 ~115 ~99 dirt
setblock ~32 ~115 ~100 dirt
setblock ~32 ~115 ~101 dirt
setblock ~32 ~115 ~102 dirt
setblock ~32 ~115 ~103 dirt
setblock ~32 ~115 ~104 dirt
setblock ~32 ~115 ~105 dirt
setblock ~32 ~115 ~106 dirt
setblock ~32 ~115 ~118 dirt
setblock ~32 ~116 ~89 dirt
setblock ~32 ~116 ~90 dirt
setblock ~32 ~116 ~91 dirt
setblock ~32 ~116 ~92 dirt
setblock ~32 ~116 ~93 dirt
setblock ~32 ~116 ~94 dirt
setblock ~32 ~116 ~95 dirt
setblock ~32 ~116 ~97 dirt
setblock ~32 ~116 ~98 dirt
setblock ~32 ~116 ~99 dirt
setblock ~32 ~116 ~100 dirt
setblock ~32 ~116 ~101 dirt
setblock ~32 ~116 ~102 dirt
setblock ~32 ~116 ~103 dirt
setblock ~32 ~116 ~104 dirt
setblock ~32 ~116 ~105 dirt
setblock ~32 ~116 ~106 dirt
setblock ~32 ~116 ~107 dirt
setblock ~32 ~116 ~117 dirt
setblock ~32 ~116 ~118 dirt
setblock ~32 ~116 ~119 dirt
setblock ~32 ~117 ~88 dirt
setblock ~32 ~117 ~89 dirt
setblock ~32 ~117 ~90 dirt
setblock ~32 ~117 ~91 dirt
setblock ~32 ~117 ~92 dirt
setblock ~32 ~117 ~93 dirt
setblock ~32 ~117 ~94 dirt
setblock ~32 ~117 ~95 dirt
setblock ~32 ~117 ~96 dirt
setblock ~32 ~117 ~97 dirt
setblock ~32 ~117 ~98 dirt
setblock ~32 ~117 ~99 dirt
setblock ~32 ~117 ~100 dirt
setblock ~32 ~117 ~101 dirt
setblock ~32 ~117 ~102 dirt
setblock ~32 ~117 ~103 dirt
setblock ~32 ~117 ~104 dirt
setblock ~32 ~117 ~105 dirt
setblock ~32 ~117 ~106 dirt
setblock ~32 ~117 ~107 dirt
setblock ~32 ~117 ~116 dirt
setblock ~32 ~117 ~117 dirt
setblock ~32 ~117 ~118 dirt
setblock ~32 ~117 ~119 dirt
setblock ~32 ~117 ~120 dirt
setblock ~32 ~118 ~66 dirt
setblock ~32 ~118 ~88 dirt
setblock ~32 ~118 ~89 dirt
setblock ~32 ~118 ~90 dirt
setblock ~32 ~118 ~91 dirt
setblock ~32 ~118 ~92 dirt
setblock ~32 ~118 ~93 dirt
setblock ~32 ~118 ~94 dirt
setblock ~32 ~118 ~95 dirt
setblock ~32 ~118 ~96 dirt
setblock ~32 ~118 ~97 dirt
setblock ~32 ~118 ~98 dirt
setblock ~32 ~118 ~99 dirt
setblock ~32 ~118 ~100 dirt
setblock ~32 ~118 ~101 dirt
setblock ~32 ~118 ~102 dirt
setblock ~32 ~118 ~103 dirt
setblock ~32 ~118 ~104 dirt
setblock ~32 ~118 ~105 dirt
setblock ~32 ~118 ~106 dirt
setblock ~32 ~118 ~107 dirt
setblock ~32 ~118 ~108 dirt
setblock ~32 ~118 ~116 dirt
setblock ~32 ~118 ~117 dirt
setblock ~32 ~118 ~118 dirt
setblock ~32 ~118 ~119 dirt
setblock ~32 ~118 ~120 dirt
setblock ~32 ~119 ~62 dirt
setblock ~32 ~119 ~66 dirt
setblock ~32 ~119 ~84 dirt
setblock ~32 ~119 ~86 dirt
setblock ~32 ~119 ~87 dirt
setblock ~32 ~119 ~88 dirt
setblock ~32 ~119 ~89 dirt
setblock ~32 ~119 ~90 dirt
setblock ~32 ~119 ~91 dirt
setblock ~32 ~119 ~92 dirt
setblock ~32 ~119 ~93 dirt
setblock ~32 ~119 ~94 dirt
setblock ~32 ~119 ~95 dirt
setblock ~32 ~119 ~96 dirt
